{"channel":"book","type":"snapshot","data":[{"symbol":"ADA/USD","bids":[{"price":0.449289,"qty":1900.00000000},{"price":0.449278,"qty":11126.72682191},{"price":0.449260,"qty":5876.59157689},{"price":0.449257,"qty":11126.70208381},{"price":0.449254,"qty":5564.77683268},{"price":0.449238,"qty":1089.62134756},{"price":0.449210,"qty":450.00000000},{"price":0.449200,"qty":5145.46693554},{"price":0.449172,"qty":33.79805661},{"price":0.449169,"qty":33.79805661}],"asks":[{"price":0.449423,"qty":5562.69249002},{"price":0.449424,"qty":6925.00000000},{"price":0.449461,"qty":91.63597432},{"price":0.449499,"qty":1900.00000000},{"price":0.449510,"qty":2100.00000000},{"price":0.449546,"qty":16685.00873320},{"price":0.449555,"qty":1484.40000000},{"price":0.449579,"qty":513.81600897},{"price":0.449611,"qty":33.79805661},{"price":0.449613,"qty":33.79805661}],"checksum":4098854232}]}
{"channel":"book","type":"update","data":[{"symbol":"ADA/USD","bids":[],"asks":[{"price":0.449424,"qty":0.00000000},{"price":0.449629,"qty":92.70695664}],"checksum":926516341,"timestamp":"2024-06-01T18:05:55.433820Z"}]}
{"channel":"book","type":"update","data":[{"symbol":"ADA/USD","bids":[],"asks":[{"price":0.449425,"qty":6925.00000000}],"checksum":3895241507,"timestamp":"2024-06-01T18:05:55.493647Z"}]}
{"channel":"book","type":"update","data":[{"symbol":"ADA/USD","bids":[],"asks":[{"price":0.449425,"qty":0.00000000},{"price":0.449629,"qty":92.70695664}],"checksum":926516341,"timestamp":"2024-06-01T18:05:56.265510Z"}]}
{"channel":"book","type":"update","data":[{"symbol":"ADA/USD","bids":[],"asks":[{"price":0.449423,"qty":12487.69249002}],"checksum":3014429469,"timestamp":"2024-06-01T18:05:59.889245Z"}]}
{"channel":"book","type":"update","data":[{"symbol":"ADA/USD","bids":[],"asks":[{"price":0.449423,"qty":5562.69249002}],"checksum":926516341,"timestamp":"2024-06-01T18:06:00.418090Z"}]}
{"channel":"book","type":"update","data":[{"symbol":"ADA/USD","bids":[{"price":0.449238,"qty":0.00000000},{"price":0.449163,"qty":17962.14870902}],"asks":[],"checksum":1700406759,"timestamp":"2024-06-01T18:06:01.186899Z"}]}
{"channel":"book","type":"update","data":[{"symbol":"ADA/USD","bids":[{"price":0.449240,"qty":1102.45297778}],"asks":[],"checksum":3096796091,"timestamp":"2024-06-01T18:06:01.311272Z"}]}
{"channel":"book","type":"update","data":[{"symbol":"ADA/USD","bids":[{"price":0.449261,"qty":17962.14870902}],"asks":[],"checksum":2413131473,"timestamp":"2024-06-01T18:06:02.890254Z"}]}
{"channel":"book","type":"update","data":[{"symbol":"ADA/USD","bids":[],"asks":[{"price":0.449611,"qty":0.00000000},{"price":0.449632,"qty":33.79805661}],"checksum":760203861,"timestamp":"2024-06-01T18:06:02.890477Z"}]}
{"channel":"book","type":"update","data":[{"symbol":"ADA/USD","bids":[],"asks":[{"price":0.449629,"qty":58.90890003}],"checksum":3156320217,"timestamp":"2024-06-01T18:06:02.890623Z"}]}
{"channel":"book","type":"update","data":[{"symbol":"ADA/USD","bids":[],"asks":[{"price":0.449632,"qty":0.00000000},{"price":0.449645,"qty":1739.14628709}],"checksum":895240076,"timestamp":"2024-06-01T18:06:02.890707Z"}]}
{"channel":"book","type":"update","data":[{"symbol":"ADA/USD","bids":[{"price":0.449290,"qty":11126.72682191}],"asks":[],"checksum":939765444,"timestamp":"2024-06-01T18:06:02.893996Z"}]}
{"channel":"book","type":"update","data":[{"symbol":"ADA/USD","bids":[{"price":0.449290,"qty":17003.31839880}],"asks":[],"checksum":97081152,"timestamp":"2024-06-01T18:06:02.894982Z"}]}
{"channel":"book","type":"update","data":[{"symbol":"ADA/USD","bids":[{"price":0.449290,"qty":17037.11645541}],"asks":[],"checksum":1326247197,"timestamp":"2024-06-01T18:06:02.895040Z"}]}
{"channel":"book","type":"update","data":[{"symbol":"ADA/USD","bids":[{"price":0.449290,"qty":17070.91451202}],"asks":[],"checksum":2040894861,"timestamp":"2024-06-01T18:06:02.895663Z"}]}
{"channel":"book","type":"update","data":[{"symbol":"ADA/USD","bids":[{"price":0.449290,"qty":17104.71256863}],"asks":[],"checksum":3836541466,"timestamp":"2024-06-01T18:06:02.895685Z"}]}
{"channel":"book","type":"update","data":[{"symbol":"ADA/USD","bids":[],"asks":[{"price":0.449613,"qty":0.00000000},{"price":0.449700,"qty":12047.63357024}],"checksum":1673816032,"timestamp":"2024-06-01T18:06:02.896585Z"}]}
{"channel":"book","type":"update","data":[{"symbol":"ADA/USD","bids":[{"price":0.449290,"qty":17138.51062524}],"asks":[],"checksum":761233020,"timestamp":"2024-06-01T18:06:02.896661Z"}]}
{"channel":"book","type":"update","data":[{"symbol":"ADA/USD","bids":[{"price":0.449289,"qty":0.00000000},{"price":0.449172,"qty":33.79805661}],"asks":[],"checksum":659393521,"timestamp":"2024-06-01T18:06:02.896725Z"}]}
{"channel":"book","type":"update","data":[{"symbol":"ADA/USD","bids":[{"price":0.449307,"qty":1900.00000000}],"asks":[],"checksum":619623122,"timestamp":"2024-06-01T18:06:02.896905Z"}]}
{"channel":"book","type":"update","data":[{"symbol":"ADA/USD","bids":[{"price":0.449278,"qty":0.00000000},{"price":0.449172,"qty":33.79805661}],"asks":[],"checksum":1958963186,"timestamp":"2024-06-01T18:06:02.899027Z"}]}
{"channel":"book","type":"update","data":[{"symbol":"ADA/USD","bids":[],"asks":[{"price":0.449546,"qty":11122.34075037}],"checksum":926802306,"timestamp":"2024-06-01T18:06:02.977369Z"}]}
{"channel":"book","type":"update","data":[{"symbol":"ADA/USD","bids":[{"price":0.449260,"qty":0.00000000},{"price":0.449169,"qty":33.79805661}],"asks":[],"checksum":2031996446,"timestamp":"2024-06-01T18:06:02.981109Z"}]}
{"channel":"book","type":"update","data":[{"symbol":"ADA/USD","bids":[{"price":0.449169,"qty":0.00000000},{"price":0.449157,"qty":1631.72064942}],"asks":[],"checksum":2299071276,"timestamp":"2024-06-01T18:06:02.981417Z"}]}
{"channel":"book","type":"update","data":[{"symbol":"ADA/USD","bids":[{"price":0.449308,"qty":33.79805661}],"asks":[],"checksum":3872318393,"timestamp":"2024-06-01T18:06:02.981471Z"}]}
{"channel":"book","type":"update","data":[{"symbol":"ADA/USD","bids":[{"price":0.449172,"qty":0.00000000},{"price":0.449157,"qty":1631.72064942}],"asks":[],"checksum":1465302129,"timestamp":"2024-06-01T18:06:02.982527Z"}]}
{"channel":"book","type":"update","data":[{"symbol":"ADA/USD","bids":[{"price":0.449308,"qty":67.59611322}],"asks":[],"checksum":3847987997,"timestamp":"2024-06-01T18:06:02.982601Z"}]}
{"channel":"book","type":"update","data":[{"symbol":"ADA/USD","bids":[{"price":0.449308,"qty":5944.18769011}],"asks":[],"checksum":3802383200,"timestamp":"2024-06-01T18:06:03.011842Z"}]}
{"channel":"book","type":"update","data":[{"symbol":"ADA/USD","bids":[{"price":0.449307,"qty":0.00000000},{"price":0.449156,"qty":10000.00000000}],"asks":[],"checksum":3972610824,"timestamp":"2024-06-01T18:06:03.014476Z"}]}
{"channel":"book","type":"update","data":[{"symbol":"ADA/USD","bids":[{"price":0.449325,"qty":1900.00000000}],"asks":[],"checksum":3320187549,"timestamp":"2024-06-01T18:06:03.014772Z"}]}
{"channel":"book","type":"update","data":[{"symbol":"ADA/USD","bids":[{"price":0.449290,"qty":17104.71256863}],"asks":[],"checksum":202572188,"timestamp":"2024-06-01T18:06:03.015690Z"}]}
{"channel":"book","type":"update","data":[{"symbol":"ADA/USD","bids":[{"price":0.449290,"qty":17070.91451202}],"asks":[],"checksum":4145454446,"timestamp":"2024-06-01T18:06:03.017924Z"}]}
{"channel":"book","type":"update","data":[{"symbol":"ADA/USD","bids":[{"price":0.449324,"qty":460.00000000}],"asks":[],"checksum":3252004803,"timestamp":"2024-06-01T18:06:03.263538Z"}]}
{"channel":"book","type":"update","data":[{"symbol":"ADA/USD","bids":[{"price":0.449290,"qty":11194.32293513}],"asks":[],"checksum":501181506,"timestamp":"2024-06-01T18:06:03.267275Z"}]}
{"channel":"book","type":"update","data":[{"symbol":"ADA/USD","bids":[],"asks":[{"price":0.449567,"qty":5562.69249002}],"checksum":470444585,"timestamp":"2024-06-01T18:06:03.272592Z"}]}
{"channel":"book","type":"update","data":[{"symbol":"ADA/USD","bids":[],"asks":[{"price":0.449499,"qty":0.00000000},{"price":0.449700,"qty":12047.63357024}],"checksum":1066267353,"timestamp":"2024-06-01T18:06:03.287882Z"}]}
{"channel":"book","type":"update","data":[{"symbol":"ADA/USD","bids":[{"price":0.449326,"qty":5876.59157689}],"asks":[],"checksum":4183601040,"timestamp":"2024-06-01T18:06:03.508240Z"}]}
{"channel":"book","type":"update","data":[{"symbol":"ADA/USD","bids":[{"price":0.449325,"qty":0.00000000},{"price":0.449200,"qty":5145.46693554}],"asks":[],"checksum":2195060153,"timestamp":"2024-06-01T18:06:03.511778Z"}]}
{"channel":"book","type":"update","data":[{"symbol":"ADA/USD","bids":[{"price":0.449333,"qty":1900.00000000}],"asks":[],"checksum":586269479,"timestamp":"2024-06-01T18:06:03.511958Z"}]}
{"channel":"book","type":"update","data":[{"symbol":"ADA/USD","bids":[],"asks":[{"price":0.449567,"qty":0.00000000},{"price":0.449755,"qty":43814.26275347}],"checksum":3341496435,"timestamp":"2024-06-01T18:06:03.569428Z"}]}
{"channel":"book","type":"update","data":[{"symbol":"ADA/USD","bids":[],"asks":[{"price":0.449461,"qty":0.00000000},{"price":0.449771,"qty":11116.76932586}],"checksum":3485646539,"timestamp":"2024-06-01T18:06:03.695080Z"}]}
{"channel":"book","type":"update","data":[{"symbol":"ADA/USD","bids":[{"price":0.449308,"qty":67.59611322}],"asks":[],"checksum":761051507,"timestamp":"2024-06-01T18:06:03.699539Z"}]}
{"channel":"book","type":"update","data":[{"symbol":"ADA/USD","bids":[],"asks":[{"price":0.449568,"qty":5562.69249002}],"checksum":2319477454,"timestamp":"2024-06-01T18:06:03.845782Z"}]}
{"channel":"book","type":"update","data":[{"symbol":"ADA/USD","bids":[{"price":0.449334,"qty":5876.59157689}],"asks":[],"checksum":3948216030,"timestamp":"2024-06-01T18:06:03.849689Z"}]}
{"channel":"book","type":"update","data":[{"symbol":"ADA/USD","bids":[{"price":0.449254,"qty":0.00000000},{"price":0.449210,"qty":450.00000000}],"asks":[],"checksum":1029508343,"timestamp":"2024-06-01T18:06:03.905743Z"}]}
{"channel":"book","type":"update","data":[{"symbol":"ADA/USD","bids":[{"price":0.449295,"qty":5564.27129966}],"asks":[],"checksum":2078757319,"timestamp":"2024-06-01T18:06:03.911163Z"}]}
{"channel":"book","type":"update","data":[{"symbol":"ADA/USD","bids":[{"price":0.449326,"qty":0.00000000},{"price":0.449210,"qty":450.00000000}],"asks":[],"checksum":2077955994,"timestamp":"2024-06-01T18:06:04.021758Z"}]}
{"channel":"book","type":"update","data":[{"symbol":"ADA/USD","bids":[],"asks":[{"price":0.449555,"qty":0.00000000},{"price":0.449771,"qty":11116.76932586}],"checksum":2628457015,"timestamp":"2024-06-01T18:06:04.606663Z"}]}
{"channel":"book","type":"update","data":[{"symbol":"ADA/USD","bids":[],"asks":[{"price":0.449657,"qty":1482.80000000}],"checksum":3380853268,"timestamp":"2024-06-01T18:06:04.609046Z"}]}
{"channel":"book","type":"update","data":[{"symbol":"ADA/USD","bids":[{"price":0.449261,"qty":0.00000000},{"price":0.449200,"qty":5145.46693554},{"price":0.449258,"qty":17962.14870902}],"asks":[],"checksum":2546888033,"timestamp":"2024-06-01T18:06:04.610097Z"}]}
{"channel":"book","type":"update","data":[{"symbol":"ADA/USD","bids":[],"asks":[{"price":0.449755,"qty":0.00000000},{"price":0.449771,"qty":11116.76932586},{"price":0.449770,"qty":43814.26275347}],"checksum":3010715074,"timestamp":"2024-06-01T18:06:04.610517Z"}]}
{"channel":"book","type":"update","data":[{"symbol":"ADA/USD","bids":[],"asks":[{"price":0.449465,"qty":91.63597432}],"checksum":273247787,"timestamp":"2024-06-01T18:06:04.873555Z"}]}
{"channel":"book","type":"update","data":[{"symbol":"ADA/USD","bids":[{"price":0.449304,"qty":11125.78685148}],"asks":[],"checksum":3039550132,"timestamp":"2024-06-01T18:06:08.208324Z"}]}
{"channel":"book","type":"update","data":[{"symbol":"ADA/USD","bids":[{"price":0.449290,"qty":67.59611322}],"asks":[],"checksum":2468117255,"timestamp":"2024-06-01T18:06:08.212030Z"}]}
{"channel":"book","type":"update","data":[{"symbol":"ADA/USD","bids":[],"asks":[{"price":0.449568,"qty":0.00000000},{"price":0.449755,"qty":43814.26275347}],"checksum":2433891865,"timestamp":"2024-06-01T18:06:11.277784Z"}]}
{"channel":"book","type":"update","data":[{"symbol":"ADA/USD","bids":[{"price":0.449335,"qty":1900.00000000}],"asks":[],"checksum":1442592172,"timestamp":"2024-06-01T18:06:11.543476Z"}]}
{"channel":"book","type":"update","data":[{"symbol":"ADA/USD","bids":[{"price":0.449333,"qty":0.00000000},{"price":0.449240,"qty":1102.45297778}],"asks":[],"checksum":2295375844,"timestamp":"2024-06-01T18:06:11.543523Z"}]}
{"channel":"book","type":"update","data":[{"symbol":"ADA/USD","bids":[],"asks":[{"price":0.449700,"qty":0.00000000},{"price":0.449771,"qty":11116.76932586}],"checksum":4194674939,"timestamp":"2024-06-01T18:06:11.546247Z"}]}
{"channel":"book","type":"update","data":[{"symbol":"ADA/USD","bids":[{"price":0.449336,"qty":5876.59157689}],"asks":[],"checksum":3889771289,"timestamp":"2024-06-01T18:06:11.547700Z"}]}
{"channel":"book","type":"update","data":[{"symbol":"ADA/USD","bids":[],"asks":[{"price":0.449700,"qty":8129.23357024}],"checksum":2722971889,"timestamp":"2024-06-01T18:06:11.549017Z"}]}
{"channel":"book","type":"update","data":[{"symbol":"ADA/USD","bids":[],"asks":[{"price":0.449755,"qty":0.00000000},{"price":0.449771,"qty":11116.76932586},{"price":0.449770,"qty":43814.26275347}],"checksum":2875081986,"timestamp":"2024-06-01T18:06:11.549914Z"}]}
{"channel":"book","type":"update","data":[{"symbol":"ADA/USD","bids":[{"price":0.449337,"qty":1900.00000000}],"asks":[],"checksum":3800141316,"timestamp":"2024-06-01T18:06:11.550511Z"}]}
{"channel":"book","type":"update","data":[{"symbol":"ADA/USD","bids":[{"price":0.449335,"qty":0.00000000},{"price":0.449257,"qty":11126.70208381}],"asks":[],"checksum":2936426557,"timestamp":"2024-06-01T18:06:11.550524Z"}]}
{"channel":"book","type":"update","data":[{"symbol":"ADA/USD","bids":[{"price":0.449258,"qty":0.00000000},{"price":0.449240,"qty":1102.45297778},{"price":0.449263,"qty":17962.14870902}],"asks":[],"checksum":4117926827,"timestamp":"2024-06-01T18:06:11.554188Z"}]}
{"channel":"book","type":"update","data":[{"symbol":"ADA/USD","bids":[],"asks":[{"price":0.449569,"qty":5562.69249002}],"checksum":2060415041,"timestamp":"2024-06-01T18:06:11.579815Z"}]}
{"channel":"book","type":"update","data":[{"symbol":"ADA/USD","bids":[{"price":0.449334,"qty":0.00000000},{"price":0.449240,"qty":1102.45297778}],"asks":[],"checksum":2340815674,"timestamp":"2024-06-01T18:06:11.583553Z"}]}
{"channel":"book","type":"update","data":[{"symbol":"ADA/USD","bids":[],"asks":[{"price":0.449465,"qty":0.00000000},{"price":0.449770,"qty":43814.26275347}],"checksum":3615381116,"timestamp":"2024-06-01T18:06:11.889156Z"}]}
{"channel":"book","type":"update","data":[{"symbol":"ADA/USD","bids":[{"price":0.449338,"qty":5876.59157689}],"asks":[],"checksum":1892173376,"timestamp":"2024-06-01T18:06:11.894134Z"}]}
{"channel":"book","type":"update","data":[{"symbol":"ADA/USD","bids":[{"price":0.449337,"qty":0.00000000},{"price":0.449240,"qty":1102.45297778}],"asks":[],"checksum":4170400042,"timestamp":"2024-06-01T18:06:12.011121Z"}]}
{"channel":"book","type":"update","data":[{"symbol":"ADA/USD","bids":[{"price":0.449336,"qty":0.00000000},{"price":0.449210,"qty":450.00000000}],"asks":[],"checksum":3621218423,"timestamp":"2024-06-01T18:06:12.013632Z"}]}
{"channel":"book","type":"update","data":[{"symbol":"ADA/USD","bids":[{"price":0.449340,"qty":1900.00000000}],"asks":[],"checksum":1577066690,"timestamp":"2024-06-01T18:06:12.016388Z"}]}
{"channel":"book","type":"update","data":[{"symbol":"ADA/USD","bids":[{"price":0.449240,"qty":0.00000000},{"price":0.449210,"qty":450.00000000}],"asks":[],"checksum":2166732955,"timestamp":"2024-06-01T18:06:12.040267Z"}]}
{"channel":"book","type":"update","data":[{"symbol":"ADA/USD","bids":[],"asks":[{"price":0.449519,"qty":91.63597432}],"checksum":2367493786,"timestamp":"2024-06-01T18:06:12.053439Z"}]}
{"channel":"book","type":"update","data":[{"symbol":"ADA/USD","bids":[],"asks":[{"price":0.449519,"qty":0.00000000},{"price":0.449770,"qty":43814.26275347}],"checksum":2166732955,"timestamp":"2024-06-01T18:06:12.064367Z"}]}
{"channel":"book","type":"update","data":[{"symbol":"ADA/USD","bids":[{"price":0.449341,"qty":5876.59157689}],"asks":[],"checksum":262399955,"timestamp":"2024-06-01T18:06:12.070304Z"}]}
{"channel":"book","type":"update","data":[{"symbol":"ADA/USD","bids":[{"price":0.449340,"qty":0.00000000},{"price":0.449210,"qty":450.00000000}],"asks":[],"checksum":2761303272,"timestamp":"2024-06-01T18:06:12.080081Z"}]}
{"channel":"book","type":"update","data":[{"symbol":"ADA/USD","bids":[{"price":0.449344,"qty":1900.00000000}],"asks":[],"checksum":3449122387,"timestamp":"2024-06-01T18:06:12.080235Z"}]}
{"channel":"book","type":"update","data":[{"symbol":"ADA/USD","bids":[],"asks":[{"price":0.449579,"qty":0.00000000},{"price":0.449771,"qty":11116.76932586}],"checksum":293665728,"timestamp":"2024-06-01T18:06:12.142222Z"}]}
{"channel":"book","type":"update","data":[{"symbol":"ADA/USD","bids":[{"price":0.449341,"qty":0.00000000},{"price":0.449210,"qty":450.00000000}],"asks":[],"checksum":909556359,"timestamp":"2024-06-01T18:06:12.145961Z"}]}
{"channel":"book","type":"update","data":[{"symbol":"ADA/USD","bids":[{"price":0.449258,"qty":1102.40880683}],"asks":[],"checksum":2457072401,"timestamp":"2024-06-01T18:06:12.158750Z"}]}
{"channel":"book","type":"update","data":[{"symbol":"ADA/USD","bids":[],"asks":[{"price":0.449576,"qty":91.63597432}],"checksum":3272279351,"timestamp":"2024-06-01T18:06:12.182387Z"}]}
{"channel":"book","type":"update","data":[{"symbol":"ADA/USD","bids":[{"price":0.449345,"qty":5876.59157689}],"asks":[],"checksum":124133150,"timestamp":"2024-06-01T18:06:12.186114Z"}]}
{"channel":"book","type":"update","data":[{"symbol":"ADA/USD","bids":[{"price":0.449344,"qty":0.00000000},{"price":0.449257,"qty":11126.70208381}],"asks":[],"checksum":170038829,"timestamp":"2024-06-01T18:06:12.188919Z"}]}
{"channel":"book","type":"update","data":[{"symbol":"ADA/USD","bids":[{"price":0.449353,"qty":1900.00000000}],"asks":[],"checksum":4083136128,"timestamp":"2024-06-01T18:06:12.189037Z"}]}
{"channel":"book","type":"update","data":[{"symbol":"ADA/USD","bids":[],"asks":[{"price":0.449611,"qty":513.81600897}],"checksum":3352516563,"timestamp":"2024-06-01T18:06:12.234997Z"}]}
{"channel":"book","type":"update","data":[{"symbol":"ADA/USD","bids":[],"asks":[{"price":0.449569,"qty":0.00000000},{"price":0.449770,"qty":43814.26275347}],"checksum":3008407619,"timestamp":"2024-06-01T18:06:12.262620Z"}]}
{"channel":"book","type":"update","data":[{"symbol":"ADA/USD","bids":[{"price":0.449345,"qty":0.00000000},{"price":0.449257,"qty":11126.70208381}],"asks":[],"checksum":3706736023,"timestamp":"2024-06-01T18:06:12.266433Z"}]}
{"channel":"book","type":"update","data":[{"symbol":"ADA/USD","bids":[{"price":0.449354,"qty":5876.59157689}],"asks":[],"checksum":2995313770,"timestamp":"2024-06-01T18:06:12.509663Z"}]}
{"channel":"book","type":"update","data":[{"symbol":"ADA/USD","bids":[{"price":0.449353,"qty":0.00000000},{"price":0.449257,"qty":11126.70208381}],"asks":[],"checksum":3106662716,"timestamp":"2024-06-01T18:06:12.512404Z"}]}
{"channel":"book","type":"update","data":[{"symbol":"ADA/USD","bids":[{"price":0.449357,"qty":1900.00000000}],"asks":[],"checksum":644022245,"timestamp":"2024-06-01T18:06:12.512664Z"}]}
{"channel":"book","type":"update","data":[{"symbol":"ADA/USD","bids":[],"asks":[{"price":0.449584,"qty":5876.59157689}],"checksum":3032633605,"timestamp":"2024-06-01T18:06:12.531106Z"}]}
{"channel":"book","type":"update","data":[{"symbol":"ADA/USD","bids":[{"price":0.449354,"qty":0.00000000},{"price":0.449257,"qty":11126.70208381}],"asks":[],"checksum":3033257375,"timestamp":"2024-06-01T18:06:13.010367Z"}]}
{"channel":"book","type":"update","data":[{"symbol":"ADA/USD","bids":[{"price":0.449358,"qty":5876.59157689}],"asks":[],"checksum":2418620108,"timestamp":"2024-06-01T18:06:13.509022Z"}]}
{"channel":"book","type":"update","data":[{"symbol":"ADA/USD","bids":[{"price":0.449263,"qty":0.00000000},{"price":0.449257,"qty":11126.70208381},{"price":0.449259,"qty":17962.14870902}],"asks":[],"checksum":284147352,"timestamp":"2024-06-01T18:06:13.512731Z"}]}
{"channel":"book","type":"update","data":[{"symbol":"ADA/USD","bids":[{"price":0.449338,"qty":0.00000000},{"price":0.449257,"qty":11126.70208381}],"asks":[],"checksum":758059679,"timestamp":"2024-06-01T18:06:13.520524Z"}]}
{"channel":"book","type":"update","data":[{"symbol":"ADA/USD","bids":[],"asks":[{"price":0.449645,"qty":0.00000000},{"price":0.449755,"qty":43814.26275347}],"checksum":3842506932,"timestamp":"2024-06-01T18:06:13.625362Z"}]}
{"channel":"book","type":"update","data":[{"symbol":"ADA/USD","bids":[],"asks":[{"price":0.449754,"qty":44.49597335}],"checksum":2862884077,"timestamp":"2024-06-01T18:06:15.794698Z"}]}
{"channel":"book","type":"update","data":[{"symbol":"ADA/USD","bids":[{"price":0.449306,"qty":11126.03419672}],"asks":[],"checksum":3746627531,"timestamp":"2024-06-01T18:06:18.478064Z"}]}
{"channel":"book","type":"update","data":[{"symbol":"ADA/USD","bids":[{"price":0.449304,"qty":0.00000000},{"price":0.449257,"qty":11126.70208381}],"asks":[],"checksum":3597831072,"timestamp":"2024-06-01T18:06:18.481617Z"}]}
{"channel":"book","type":"update","data":[{"symbol":"ADA/USD","bids":[],"asks":[{"price":0.449584,"qty":0.00000000},{"price":0.449755,"qty":43814.26275347}],"checksum":2647843255,"timestamp":"2024-06-01T18:06:19.271155Z"}]}
{"channel":"book","type":"update","data":[{"symbol":"ADA/USD","bids":[],"asks":[{"price":0.449589,"qty":5876.59157689}],"checksum":3828863770,"timestamp":"2024-06-01T18:06:19.570950Z"}]}
{"channel":"book","type":"update","data":[{"symbol":"ADA/USD","bids":[],"asks":[{"price":0.449576,"qty":0.00000000},{"price":0.449755,"qty":43814.26275347}],"checksum":1297327159,"timestamp":"2024-06-01T18:06:19.809345Z"}]}
{"channel":"book","type":"update","data":[{"symbol":"ADA/USD","bids":[],"asks":[{"price":0.449480,"qty":91.63597432}],"checksum":1019224421,"timestamp":"2024-06-01T18:06:19.933318Z"}]}
