{"channel":"book","type":"snapshot","data":[{"symbol":"ADA/BTC","bids":[{"price":0.00000663,"qty":32127.66574709},{"price":0.00000662,"qty":93101.05604833},{"price":0.00000661,"qty":181855.28195917},{"price":0.00000660,"qty":19148.82561343},{"price":0.00000659,"qty":8994.04000000},{"price":0.00000657,"qty":51110.37252171},{"price":0.00000656,"qty":362575.74479918},{"price":0.00000655,"qty":251202.24738019},{"price":0.00000654,"qty":2380.69721555},{"price":0.00000653,"qty":583.15987423}],"asks":[{"price":0.00000664,"qty":9899.52768969},{"price":0.00000665,"qty":46262.26826440},{"price":0.00000666,"qty":173734.15044595},{"price":0.00000667,"qty":15568.38979768},{"price":0.00000668,"qty":97.11714273},{"price":0.00000669,"qty":8691.76000000},{"price":0.00000670,"qty":2192.19221047},{"price":0.00000671,"qty":4395.60000000},{"price":0.00000672,"qty":120282.83534405},{"price":0.00000673,"qty":3409.43866637}],"checksum":1086878548}]}
{"channel":"book","type":"update","data":[{"symbol":"ADA/BTC","bids":[],"asks":[{"price":0.00000666,"qty":170718.04183424}],"checksum":240949049,"timestamp":"2024-06-01T18:05:51.464999Z"}]}
{"channel":"book","type":"update","data":[{"symbol":"ADA/BTC","bids":[{"price":0.00000662,"qty":92179.85663044}],"asks":[],"checksum":1708926179,"timestamp":"2024-06-01T18:05:51.543585Z"}]}
{"channel":"book","type":"update","data":[{"symbol":"ADA/BTC","bids":[{"price":0.00000662,"qty":93182.32314386}],"asks":[],"checksum":3616856669,"timestamp":"2024-06-01T18:05:51.546359Z"}]}
{"channel":"book","type":"update","data":[{"symbol":"ADA/BTC","bids":[],"asks":[{"price":0.00000666,"qty":173734.15044595}],"checksum":2566929968,"timestamp":"2024-06-01T18:05:51.563812Z"}]}
{"channel":"book","type":"update","data":[{"symbol":"ADA/BTC","bids":[{"price":0.00000653,"qty":334.39888526}],"asks":[],"checksum":2317767183,"timestamp":"2024-06-01T18:05:51.821399Z"}]}
{"channel":"book","type":"update","data":[{"symbol":"ADA/BTC","bids":[{"price":0.00000653,"qty":447.49406768}],"asks":[],"checksum":1437903309,"timestamp":"2024-06-01T18:05:51.922353Z"}]}
{"channel":"book","type":"update","data":[{"symbol":"ADA/BTC","bids":[],"asks":[{"price":0.00000665,"qty":45094.61092083}],"checksum":2844130268,"timestamp":"2024-06-01T18:05:52.216180Z"}]}
{"channel":"book","type":"update","data":[{"symbol":"ADA/BTC","bids":[],"asks":[{"price":0.00000665,"qty":46177.78826440}],"checksum":1842659120,"timestamp":"2024-06-01T18:05:52.314653Z"}]}
{"channel":"book","type":"update","data":[{"symbol":"ADA/BTC","bids":[{"price":0.00000662,"qty":88145.88322051},{"price":0.00000662,"qty":95344.21187143}],"asks":[],"checksum":3221184084,"timestamp":"2024-06-01T18:05:52.962868Z"}]}
{"channel":"book","type":"update","data":[{"symbol":"ADA/BTC","bids":[{"price":0.00000662,"qty":94501.13014054}],"asks":[],"checksum":2500240660,"timestamp":"2024-06-01T18:05:52.979207Z"}]}
{"channel":"book","type":"update","data":[{"symbol":"ADA/BTC","bids":[{"price":0.00000662,"qty":95428.69187143}],"asks":[],"checksum":1621248427,"timestamp":"2024-06-01T18:05:53.101352Z"}]}
{"channel":"book","type":"update","data":[{"symbol":"ADA/BTC","bids":[{"price":0.00000663,"qty":31482.97650943}],"asks":[],"checksum":3865974239,"timestamp":"2024-06-01T18:05:56.081808Z"}]}
{"channel":"book","type":"update","data":[{"symbol":"ADA/BTC","bids":[{"price":0.00000662,"qty":94426.22535801}],"asks":[],"checksum":4252382482,"timestamp":"2024-06-01T18:05:56.081819Z"}]}
{"channel":"book","type":"update","data":[{"symbol":"ADA/BTC","bids":[{"price":0.00000663,"qty":32187.68408417}],"asks":[],"checksum":3325610904,"timestamp":"2024-06-01T18:05:56.086724Z"}]}
{"channel":"book","type":"update","data":[{"symbol":"ADA/BTC","bids":[{"price":0.00000662,"qty":95287.14268636}],"asks":[],"checksum":3383394735,"timestamp":"2024-06-01T18:05:56.086833Z"}]}
{"channel":"book","type":"update","data":[{"symbol":"ADA/BTC","bids":[{"price":0.00000662,"qty":57884.51268636}],"asks":[],"checksum":2150511425,"timestamp":"2024-06-01T18:05:57.442899Z"}]}
{"channel":"book","type":"update","data":[{"symbol":"ADA/BTC","bids":[],"asks":[{"price":0.00000666,"qty":137670.44044595}],"checksum":2794128060,"timestamp":"2024-06-01T18:05:57.445039Z"}]}
{"channel":"book","type":"update","data":[{"symbol":"ADA/BTC","bids":[{"price":0.00000662,"qty":56494.33268636}],"asks":[],"checksum":809427579,"timestamp":"2024-06-01T18:05:57.464868Z"}]}
{"channel":"book","type":"update","data":[{"symbol":"ADA/BTC","bids":[],"asks":[{"price":0.00000665,"qty":44948.59826440}],"checksum":2451966888,"timestamp":"2024-06-01T18:05:57.491302Z"}]}
{"channel":"book","type":"update","data":[{"symbol":"ADA/BTC","bids":[{"price":0.00000662,"qty":97518.70268636}],"asks":[],"checksum":735818394,"timestamp":"2024-06-01T18:05:57.508167Z"}]}
{"channel":"book","type":"update","data":[{"symbol":"ADA/BTC","bids":[],"asks":[{"price":0.00000666,"qty":174129.84044595}],"checksum":2229370159,"timestamp":"2024-06-01T18:05:57.511163Z"}]}
{"channel":"book","type":"update","data":[{"symbol":"ADA/BTC","bids":[{"price":0.00000662,"qty":99004.99268636}],"asks":[],"checksum":3534013522,"timestamp":"2024-06-01T18:05:57.535720Z"}]}
{"channel":"book","type":"update","data":[{"symbol":"ADA/BTC","bids":[],"asks":[{"price":0.00000665,"qty":46276.16826440}],"checksum":545099030,"timestamp":"2024-06-01T18:05:57.563080Z"}]}
{"channel":"book","type":"update","data":[{"symbol":"ADA/BTC","bids":[],"asks":[{"price":0.00000665,"qty":42940.15750194}],"checksum":73943028,"timestamp":"2024-06-01T18:05:57.938393Z"}]}
{"channel":"book","type":"update","data":[{"symbol":"ADA/BTC","bids":[],"asks":[{"price":0.00000664,"qty":13235.95343775}],"checksum":2014734327,"timestamp":"2024-06-01T18:05:57.943669Z"}]}
{"channel":"book","type":"update","data":[{"symbol":"ADA/BTC","bids":[{"price":0.00000663,"qty":31482.97650943}],"asks":[],"checksum":1129879933,"timestamp":"2024-06-01T18:06:00.471048Z"}]}
{"channel":"book","type":"update","data":[{"symbol":"ADA/BTC","bids":[{"price":0.00000662,"qty":98144.07535801}],"asks":[],"checksum":1850092546,"timestamp":"2024-06-01T18:06:00.471319Z"}]}
{"channel":"book","type":"update","data":[{"symbol":"ADA/BTC","bids":[{"price":0.00000663,"qty":32247.70242125}],"asks":[],"checksum":2567019189,"timestamp":"2024-06-01T18:06:00.475515Z"}]}
{"channel":"book","type":"update","data":[{"symbol":"ADA/BTC","bids":[{"price":0.00000662,"qty":98885.51282294}],"asks":[],"checksum":1205544733,"timestamp":"2024-06-01T18:06:00.475717Z"}]}
{"channel":"book","type":"update","data":[{"symbol":"ADA/BTC","bids":[],"asks":[{"price":0.00000665,"qty":42721.97444378}],"checksum":3698033176,"timestamp":"2024-06-01T18:06:03.088667Z"}]}
{"channel":"book","type":"update","data":[{"symbol":"ADA/BTC","bids":[],"asks":[{"price":0.00000665,"qty":42853.31890628}],"checksum":2546126447,"timestamp":"2024-06-01T18:06:03.089441Z"}]}
{"channel":"book","type":"update","data":[{"symbol":"ADA/BTC","bids":[{"price":0.00000662,"qty":98144.07535801}],"asks":[],"checksum":1226339271,"timestamp":"2024-06-01T18:06:04.334882Z"}]}
{"channel":"book","type":"update","data":[{"symbol":"ADA/BTC","bids":[{"price":0.00000662,"qty":98796.37533345}],"asks":[],"checksum":3508580122,"timestamp":"2024-06-01T18:06:04.340950Z"}]}
{"channel":"book","type":"update","data":[{"symbol":"ADA/BTC","bids":[{"price":0.00000663,"qty":30247.70242125}],"asks":[],"checksum":3756910971,"timestamp":"2024-06-01T18:06:04.901115Z"}]}
{"channel":"book","type":"update","data":[{"symbol":"ADA/BTC","bids":[{"price":0.00000663,"qty":32247.70242125}],"asks":[],"checksum":3508580122,"timestamp":"2024-06-01T18:06:04.907482Z"}]}
{"channel":"book","type":"update","data":[{"symbol":"ADA/BTC","bids":[{"price":0.00000663,"qty":27247.70242125}],"asks":[],"checksum":993643916,"timestamp":"2024-06-01T18:06:04.919576Z"}]}
{"channel":"book","type":"update","data":[{"symbol":"ADA/BTC","bids":[{"price":0.00000663,"qty":25442.48534390}],"asks":[],"checksum":636856997,"timestamp":"2024-06-01T18:06:05.031171Z"}]}
{"channel":"book","type":"update","data":[{"symbol":"ADA/BTC","bids":[{"price":0.00000663,"qty":30442.48534390}],"asks":[],"checksum":3488401459,"timestamp":"2024-06-01T18:06:05.035887Z"}]}
{"channel":"book","type":"update","data":[{"symbol":"ADA/BTC","bids":[{"price":0.00000663,"qty":32247.70242125}],"asks":[],"checksum":3508580122,"timestamp":"2024-06-01T18:06:05.037282Z"}]}
{"channel":"book","type":"update","data":[{"symbol":"ADA/BTC","bids":[{"price":0.00000663,"qty":31482.97650943}],"asks":[],"checksum":644290989,"timestamp":"2024-06-01T18:06:06.760835Z"}]}
{"channel":"book","type":"update","data":[{"symbol":"ADA/BTC","bids":[{"price":0.00000663,"qty":32277.38576945}],"asks":[],"checksum":3636919739,"timestamp":"2024-06-01T18:06:06.763365Z"}]}
{"channel":"book","type":"update","data":[{"symbol":"ADA/BTC","bids":[],"asks":[{"price":0.00000665,"qty":42721.97444378}],"checksum":2473570764,"timestamp":"2024-06-01T18:06:07.613805Z"}]}
{"channel":"book","type":"update","data":[{"symbol":"ADA/BTC","bids":[],"asks":[{"price":0.00000665,"qty":42896.71785758}],"checksum":557764008,"timestamp":"2024-06-01T18:06:07.614257Z"}]}
{"channel":"book","type":"update","data":[{"symbol":"ADA/BTC","bids":[{"price":0.00000662,"qty":98144.07535801}],"asks":[],"checksum":3104182645,"timestamp":"2024-06-01T18:06:09.173410Z"}]}
{"channel":"book","type":"update","data":[{"symbol":"ADA/BTC","bids":[{"price":0.00000662,"qty":98707.45714973}],"asks":[],"checksum":1201254580,"timestamp":"2024-06-01T18:06:09.178406Z"}]}
{"channel":"book","type":"update","data":[{"symbol":"ADA/BTC","bids":[{"price":0.00000662,"qty":93714.03555709}],"asks":[],"checksum":3733335109,"timestamp":"2024-06-01T18:06:10.562815Z"}]}
{"channel":"book","type":"update","data":[{"symbol":"ADA/BTC","bids":[{"price":0.00000662,"qty":98707.45714973}],"asks":[],"checksum":1201254580,"timestamp":"2024-06-01T18:06:10.685658Z"}]}
{"channel":"book","type":"update","data":[{"symbol":"ADA/BTC","bids":[],"asks":[{"price":0.00000666,"qty":170180.17189445}],"checksum":1417267102,"timestamp":"2024-06-01T18:06:10.994554Z"}]}
{"channel":"book","type":"update","data":[{"symbol":"ADA/BTC","bids":[],"asks":[{"price":0.00000666,"qty":174129.84044595}],"checksum":1201254580,"timestamp":"2024-06-01T18:06:11.095589Z"}]}
{"channel":"book","type":"update","data":[{"symbol":"ADA/BTC","bids":[{"price":0.00000663,"qty":31482.97650943}],"asks":[],"checksum":3107476642,"timestamp":"2024-06-01T18:06:11.364615Z"}]}
{"channel":"book","type":"update","data":[{"symbol":"ADA/BTC","bids":[{"price":0.00000662,"qty":98144.07535801}],"asks":[],"checksum":1202189667,"timestamp":"2024-06-01T18:06:11.364793Z"}]}
{"channel":"book","type":"update","data":[{"symbol":"ADA/BTC","bids":[{"price":0.00000663,"qty":31787.96265169}],"asks":[],"checksum":2067875371,"timestamp":"2024-06-01T18:06:11.366268Z"}]}
{"channel":"book","type":"update","data":[{"symbol":"ADA/BTC","bids":[{"price":0.00000662,"qty":99395.71137027}],"asks":[],"checksum":3151194385,"timestamp":"2024-06-01T18:06:11.366590Z"}]}
{"channel":"book","type":"update","data":[{"symbol":"ADA/BTC","bids":[],"asks":[{"price":0.00000665,"qty":41505.58160819}],"checksum":2773784691,"timestamp":"2024-06-01T18:06:11.752597Z"}]}
{"channel":"book","type":"update","data":[{"symbol":"ADA/BTC","bids":[],"asks":[{"price":0.00000665,"qty":42896.71785758}],"checksum":3151194385,"timestamp":"2024-06-01T18:06:11.849696Z"}]}
{"channel":"book","type":"update","data":[{"symbol":"ADA/BTC","bids":[],"asks":[{"price":0.00000664,"qty":13216.68129332}],"checksum":376108411,"timestamp":"2024-06-01T18:06:12.558786Z"}]}
{"channel":"book","type":"update","data":[{"symbol":"ADA/BTC","bids":[],"asks":[{"price":0.00000665,"qty":42916.00237895}],"checksum":2618869084,"timestamp":"2024-06-01T18:06:12.668395Z"}]}
{"channel":"book","type":"update","data":[{"symbol":"ADA/BTC","bids":[{"price":0.00000663,"qty":31482.97650943}],"asks":[],"checksum":2701030932,"timestamp":"2024-06-01T18:06:14.002659Z"}]}
{"channel":"book","type":"update","data":[{"symbol":"ADA/BTC","bids":[{"price":0.00000662,"qty":98144.07535801}],"asks":[],"checksum":1617713454,"timestamp":"2024-06-01T18:06:14.002686Z"}]}
{"channel":"book","type":"update","data":[{"symbol":"ADA/BTC","bids":[{"price":0.00000663,"qty":32307.63597289}],"asks":[],"checksum":3415038852,"timestamp":"2024-06-01T18:06:14.007284Z"}]}
{"channel":"book","type":"update","data":[{"symbol":"ADA/BTC","bids":[{"price":0.00000662,"qty":98647.70628892}],"asks":[],"checksum":2952801247,"timestamp":"2024-06-01T18:06:14.007422Z"}]}
{"channel":"book","type":"update","data":[{"symbol":"ADA/BTC","bids":[{"price":0.00000663,"qty":31482.97650943}],"asks":[],"checksum":467741045,"timestamp":"2024-06-01T18:06:16.442248Z"}]}
{"channel":"book","type":"update","data":[{"symbol":"ADA/BTC","bids":[{"price":0.00000662,"qty":98144.07535801}],"asks":[],"checksum":1617713454,"timestamp":"2024-06-01T18:06:16.442513Z"}]}
{"channel":"book","type":"update","data":[{"symbol":"ADA/BTC","bids":[{"price":0.00000663,"qty":32037.63811083}],"asks":[],"checksum":3388135868,"timestamp":"2024-06-01T18:06:16.444971Z"}]}
{"channel":"book","type":"update","data":[{"symbol":"ADA/BTC","bids":[{"price":0.00000662,"qty":98828.56372176}],"asks":[],"checksum":1341027788,"timestamp":"2024-06-01T18:06:16.445118Z"}]}
{"channel":"book","type":"update","data":[{"symbol":"ADA/BTC","bids":[{"price":0.00000661,"qty":181836.94367377}],"asks":[],"checksum":2815450639,"timestamp":"2024-06-01T18:06:16.590811Z"}]}
{"channel":"book","type":"update","data":[{"symbol":"ADA/BTC","bids":[{"price":0.00000661,"qty":181855.29192869}],"asks":[],"checksum":3427888025,"timestamp":"2024-06-01T18:06:16.664212Z"}]}
{"channel":"book","type":"update","data":[{"symbol":"ADA/BTC","bids":[{"price":0.00000663,"qty":31482.97650943}],"asks":[],"checksum":1708124939,"timestamp":"2024-06-01T18:06:18.915849Z"}]}
{"channel":"book","type":"update","data":[{"symbol":"ADA/BTC","bids":[{"price":0.00000662,"qty":98144.07535801}],"asks":[],"checksum":3822274427,"timestamp":"2024-06-01T18:06:18.915989Z"}]}
{"channel":"book","type":"update","data":[{"symbol":"ADA/BTC","bids":[{"price":0.00000663,"qty":31965.10961396}],"asks":[],"checksum":316363983,"timestamp":"2024-06-01T18:06:18.917765Z"}]}
{"channel":"book","type":"update","data":[{"symbol":"ADA/BTC","bids":[{"price":0.00000662,"qty":99012.92956526}],"asks":[],"checksum":3939590933,"timestamp":"2024-06-01T18:06:18.918048Z"}]}
{"channel":"book","type":"update","data":[{"symbol":"ADA/BTC","bids":[{"price":0.00000662,"qty":98144.07535801}],"asks":[],"checksum":316363983,"timestamp":"2024-06-01T18:06:21.346142Z"}]}
{"channel":"book","type":"update","data":[{"symbol":"ADA/BTC","bids":[{"price":0.00000663,"qty":31482.97650943}],"asks":[],"checksum":3822274427,"timestamp":"2024-06-01T18:06:21.346176Z"}]}
{"channel":"book","type":"update","data":[{"symbol":"ADA/BTC","bids":[{"price":0.00000663,"qty":32037.62639702}],"asks":[],"checksum":3963346278,"timestamp":"2024-06-01T18:06:21.348387Z"}]}
{"channel":"book","type":"update","data":[{"symbol":"ADA/BTC","bids":[{"price":0.00000662,"qty":98917.82704615}],"asks":[],"checksum":2550453256,"timestamp":"2024-06-01T18:06:21.348403Z"}]}
{"channel":"book","type":"update","data":[{"symbol":"ADA/BTC","bids":[{"price":0.00000662,"qty":57893.45704615}],"asks":[],"checksum":2715345043,"timestamp":"2024-06-01T18:06:21.546313Z"}]}
{"channel":"book","type":"update","data":[{"symbol":"ADA/BTC","bids":[],"asks":[{"price":0.00000666,"qty":137670.44044595}],"checksum":249704230,"timestamp":"2024-06-01T18:06:21.547300Z"}]}
{"channel":"book","type":"update","data":[{"symbol":"ADA/BTC","bids":[{"price":0.00000662,"qty":56407.16704615}],"asks":[],"checksum":3748310051,"timestamp":"2024-06-01T18:06:21.586627Z"}]}
{"channel":"book","type":"update","data":[{"symbol":"ADA/BTC","bids":[],"asks":[{"price":0.00000665,"qty":41588.43237895}],"checksum":3560751137,"timestamp":"2024-06-01T18:06:21.588179Z"}]}
