{"channel":"book","type":"snapshot","data":[{"symbol":"ADA/USDT","bids":[{"price":0.449651,"qty":6901.49650402},{"price":0.449645,"qty":800.00000000},{"price":0.449636,"qty":5564.68809943},{"price":0.449586,"qty":500.00000000},{"price":0.449521,"qty":68.03028288},{"price":0.449520,"qty":5876.59157689},{"price":0.449504,"qty":11132.67840838},{"price":0.449500,"qty":6951.94578970},{"price":0.449454,"qty":360.00000000},{"price":0.449400,"qty":207.99003531}],"asks":[{"price":0.449805,"qty":5562.61091428},{"price":0.449859,"qty":800.00000000},{"price":0.449869,"qty":600.00000000},{"price":0.449892,"qty":14.33807458},{"price":0.449897,"qty":1486.30000000},{"price":0.449899,"qty":11122.89209299},{"price":0.449923,"qty":65.39121081},{"price":0.449981,"qty":5876.59157689},{"price":0.450067,"qty":2126.00000000},{"price":0.450068,"qty":5562.61091428}],"checksum":2450889246}]}
{"channel":"book","type":"update","data":[{"symbol":"ADA/USDT","bids":[{"price":0.449643,"qty":3330.52756358}],"asks":[],"checksum":2648303263,"timestamp":"2024-06-01T18:05:51.787291Z"}]}
{"channel":"book","type":"update","data":[{"symbol":"ADA/USDT","bids":[{"price":0.449643,"qty":0.00000000},{"price":0.449400,"qty":232.70119513}],"asks":[],"checksum":4129172076,"timestamp":"2024-06-01T18:05:52.297877Z"}]}
{"channel":"book","type":"update","data":[{"symbol":"ADA/USDT","bids":[{"price":0.449640,"qty":3330.62967594}],"asks":[],"checksum":2370755586,"timestamp":"2024-06-01T18:05:52.338178Z"}]}
{"channel":"book","type":"update","data":[{"symbol":"ADA/USDT","bids":[{"price":0.449640,"qty":0.00000000},{"price":0.449400,"qty":232.70119513}],"asks":[],"checksum":4129172076,"timestamp":"2024-06-01T18:05:52.851735Z"}]}
{"channel":"book","type":"update","data":[{"symbol":"ADA/USDT","bids":[{"price":0.449643,"qty":3330.54892986}],"asks":[],"checksum":912558336,"timestamp":"2024-06-01T18:05:52.891952Z"}]}
{"channel":"book","type":"update","data":[{"symbol":"ADA/USDT","bids":[{"price":0.449643,"qty":0.00000000},{"price":0.449400,"qty":232.70119513}],"asks":[],"checksum":4129172076,"timestamp":"2024-06-01T18:05:53.338258Z"}]}
{"channel":"book","type":"update","data":[{"symbol":"ADA/USDT","bids":[{"price":0.449646,"qty":3330.39705476}],"asks":[],"checksum":2866786744,"timestamp":"2024-06-01T18:05:53.378618Z"}]}
{"channel":"book","type":"update","data":[{"symbol":"ADA/USDT","bids":[],"asks":[{"price":0.449923,"qty":0.00000000},{"price":0.450083,"qty":11118.36361663}],"checksum":3659071135,"timestamp":"2024-06-01T18:05:55.287470Z"}]}
{"channel":"book","type":"update","data":[{"symbol":"ADA/USDT","bids":[{"price":0.449521,"qty":0.00000000},{"price":0.449400,"qty":232.70119513}],"asks":[],"checksum":2301792221,"timestamp":"2024-06-01T18:05:55.959616Z"}]}
{"channel":"book","type":"update","data":[{"symbol":"ADA/USDT","bids":[{"price":0.449400,"qty":0.00000000},{"price":0.449399,"qty":1484.40000000}],"asks":[],"checksum":934850390,"timestamp":"2024-06-01T18:05:55.959627Z"}]}
{"channel":"book","type":"update","data":[{"symbol":"ADA/USDT","bids":[{"price":0.449521,"qty":91.55469892}],"asks":[],"checksum":1567342914,"timestamp":"2024-06-01T18:05:55.966436Z"}]}
{"channel":"book","type":"update","data":[{"symbol":"ADA/USDT","bids":[{"price":0.449646,"qty":0.00000000},{"price":0.449400,"qty":209.17677910}],"asks":[],"checksum":3218000150,"timestamp":"2024-06-01T18:05:57.512508Z"}]}
{"channel":"book","type":"update","data":[{"symbol":"ADA/USDT","bids":[{"price":0.449647,"qty":3330.50413199}],"asks":[],"checksum":72187652,"timestamp":"2024-06-01T18:05:57.551205Z"}]}
{"channel":"book","type":"update","data":[{"symbol":"ADA/USDT","bids":[{"price":0.449647,"qty":0.00000000},{"price":0.449400,"qty":209.17677910}],"asks":[],"checksum":3218000150,"timestamp":"2024-06-01T18:05:59.226842Z"}]}
{"channel":"book","type":"update","data":[{"symbol":"ADA/USDT","bids":[{"price":0.449644,"qty":3330.55691890}],"asks":[],"checksum":1630260084,"timestamp":"2024-06-01T18:05:59.267221Z"}]}
{"channel":"book","type":"update","data":[{"symbol":"ADA/USDT","bids":[{"price":0.449644,"qty":0.00000000},{"price":0.449400,"qty":209.17677910}],"asks":[],"checksum":3218000150,"timestamp":"2024-06-01T18:05:59.849499Z"}]}
{"channel":"book","type":"update","data":[{"symbol":"ADA/USDT","bids":[{"price":0.449645,"qty":4130.51710366}],"asks":[],"checksum":2373613321,"timestamp":"2024-06-01T18:05:59.890023Z"}]}
{"channel":"book","type":"update","data":[{"symbol":"ADA/USDT","bids":[{"price":0.449521,"qty":0.00000000},{"price":0.449399,"qty":1484.40000000}],"asks":[],"checksum":7227182,"timestamp":"2024-06-01T18:05:59.907645Z"}]}
{"channel":"book","type":"update","data":[{"symbol":"ADA/USDT","bids":[{"price":0.449521,"qty":115.07911495}],"asks":[],"checksum":2432546258,"timestamp":"2024-06-01T18:05:59.912979Z"}]}
{"channel":"book","type":"update","data":[{"symbol":"ADA/USDT","bids":[{"price":0.449645,"qty":800.00000000}],"asks":[],"checksum":499584153,"timestamp":"2024-06-01T18:06:00.400261Z"}]}
{"channel":"book","type":"update","data":[{"symbol":"ADA/USDT","bids":[{"price":0.449647,"qty":3330.45445086}],"asks":[],"checksum":1085160307,"timestamp":"2024-06-01T18:06:00.505097Z"}]}
{"channel":"book","type":"update","data":[{"symbol":"ADA/USDT","bids":[{"price":0.449647,"qty":0.00000000},{"price":0.449400,"qty":209.17677910}],"asks":[],"checksum":499584153,"timestamp":"2024-06-01T18:06:01.697265Z"}]}
{"channel":"book","type":"update","data":[{"symbol":"ADA/USDT","bids":[{"price":0.449644,"qty":3330.55691890}],"asks":[],"checksum":3107770176,"timestamp":"2024-06-01T18:06:01.737504Z"}]}
{"channel":"book","type":"update","data":[{"symbol":"ADA/USDT","bids":[{"price":0.449644,"qty":0.00000000},{"price":0.449400,"qty":209.17677910}],"asks":[],"checksum":499584153,"timestamp":"2024-06-01T18:06:02.281569Z"}]}
{"channel":"book","type":"update","data":[{"symbol":"ADA/USDT","bids":[{"price":0.449648,"qty":3330.45445086}],"asks":[],"checksum":732081103,"timestamp":"2024-06-01T18:06:02.321649Z"}]}
{"channel":"book","type":"update","data":[{"symbol":"ADA/USDT","bids":[],"asks":[{"price":0.449981,"qty":0.00000000},{"price":0.450131,"qty":32.15746714}],"checksum":1782896541,"timestamp":"2024-06-01T18:06:02.890578Z"}]}
{"channel":"book","type":"update","data":[{"symbol":"ADA/USDT","bids":[{"price":0.449648,"qty":0.00000000},{"price":0.449400,"qty":209.17677910}],"asks":[],"checksum":4290854450,"timestamp":"2024-06-01T18:06:02.942970Z"}]}
{"channel":"book","type":"update","data":[{"symbol":"ADA/USDT","bids":[{"price":0.449652,"qty":5876.59157689}],"asks":[],"checksum":2699203074,"timestamp":"2024-06-01T18:06:02.947026Z"}]}
{"channel":"book","type":"update","data":[{"symbol":"ADA/USDT","bids":[{"price":0.449651,"qty":6301.49650402}],"asks":[],"checksum":30312239,"timestamp":"2024-06-01T18:06:02.949937Z"}]}
{"channel":"book","type":"update","data":[{"symbol":"ADA/USDT","bids":[{"price":0.449665,"qty":600.00000000}],"asks":[],"checksum":3010319657,"timestamp":"2024-06-01T18:06:02.950153Z"}]}
{"channel":"book","type":"update","data":[{"symbol":"ADA/USDT","bids":[],"asks":[{"price":0.450068,"qty":0.00000000},{"price":0.450149,"qty":18.84631480}],"checksum":4240168502,"timestamp":"2024-06-01T18:06:02.971132Z"}]}
{"channel":"book","type":"update","data":[{"symbol":"ADA/USDT","bids":[],"asks":[{"price":0.450067,"qty":0.00000000},{"price":0.450229,"qty":71.64292799},{"price":0.450082,"qty":2126.00000000}],"checksum":3544891370,"timestamp":"2024-06-01T18:06:02.974410Z"}]}
{"channel":"book","type":"update","data":[{"symbol":"ADA/USDT","bids":[{"price":0.449653,"qty":3330.35896396}],"asks":[],"checksum":2366494022,"timestamp":"2024-06-01T18:06:02.983147Z"}]}
{"channel":"book","type":"update","data":[{"symbol":"ADA/USDT","bids":[{"price":0.449651,"qty":20374.10633694}],"asks":[],"checksum":4193130664,"timestamp":"2024-06-01T18:06:02.983316Z"}]}
{"channel":"book","type":"update","data":[{"symbol":"ADA/USDT","bids":[{"price":0.449520,"qty":0.00000000},{"price":0.449500,"qty":6951.94578970}],"asks":[],"checksum":4107763223,"timestamp":"2024-06-01T18:06:02.986910Z"}]}
{"channel":"book","type":"update","data":[{"symbol":"ADA/USDT","bids":[{"price":0.449654,"qty":5876.59157689}],"asks":[],"checksum":1122485304,"timestamp":"2024-06-01T18:06:03.020395Z"}]}
{"channel":"book","type":"update","data":[{"symbol":"ADA/USDT","bids":[],"asks":[{"price":0.450087,"qty":5562.61091428}],"checksum":2859109070,"timestamp":"2024-06-01T18:06:03.274632Z"}]}
{"channel":"book","type":"update","data":[{"symbol":"ADA/USDT","bids":[{"price":0.449652,"qty":0.00000000},{"price":0.449500,"qty":6951.94578970}],"asks":[],"checksum":132549767,"timestamp":"2024-06-01T18:06:03.518892Z"}]}
{"channel":"book","type":"update","data":[{"symbol":"ADA/USDT","bids":[],"asks":[{"price":0.450087,"qty":0.00000000},{"price":0.450149,"qty":18.84631480}],"checksum":4016816753,"timestamp":"2024-06-01T18:06:03.578657Z"}]}
{"channel":"book","type":"update","data":[{"symbol":"ADA/USDT","bids":[{"price":0.449653,"qty":0.00000000},{"price":0.449454,"qty":360.00000000}],"asks":[],"checksum":3355872776,"timestamp":"2024-06-01T18:06:03.599320Z"}]}
{"channel":"book","type":"update","data":[{"symbol":"ADA/USDT","bids":[{"price":0.449654,"qty":0.00000000},{"price":0.449400,"qty":209.17677910}],"asks":[],"checksum":1595559909,"timestamp":"2024-06-01T18:06:03.604659Z"}]}
{"channel":"book","type":"update","data":[{"symbol":"ADA/USDT","bids":[{"price":0.449652,"qty":5876.59157689}],"asks":[],"checksum":3679536299,"timestamp":"2024-06-01T18:06:03.604793Z"}]}
{"channel":"book","type":"update","data":[{"symbol":"ADA/USDT","bids":[{"price":0.449669,"qty":3329.99676930}],"asks":[],"checksum":690066201,"timestamp":"2024-06-01T18:06:03.639539Z"}]}
{"channel":"book","type":"update","data":[{"symbol":"ADA/USDT","bids":[{"price":0.449682,"qty":600.00000000}],"asks":[],"checksum":2923801930,"timestamp":"2024-06-01T18:06:03.642119Z"}]}
{"channel":"book","type":"update","data":[{"symbol":"ADA/USDT","bids":[{"price":0.449665,"qty":0.00000000},{"price":0.449500,"qty":6951.94578970}],"asks":[],"checksum":2935756319,"timestamp":"2024-06-01T18:06:03.642134Z"}]}
{"channel":"book","type":"update","data":[{"symbol":"ADA/USDT","bids":[{"price":0.449521,"qty":0.00000000},{"price":0.449454,"qty":360.00000000}],"asks":[],"checksum":1925488214,"timestamp":"2024-06-01T18:06:03.792412Z"}]}
{"channel":"book","type":"update","data":[{"symbol":"ADA/USDT","bids":[{"price":0.449505,"qty":91.97384089}],"asks":[],"checksum":2524883802,"timestamp":"2024-06-01T18:06:03.796447Z"}]}
{"channel":"book","type":"update","data":[{"symbol":"ADA/USDT","bids":[],"asks":[{"price":0.450088,"qty":5562.61091428}],"checksum":3803875352,"timestamp":"2024-06-01T18:06:03.895579Z"}]}
{"channel":"book","type":"update","data":[{"symbol":"ADA/USDT","bids":[{"price":0.449669,"qty":0.00000000},{"price":0.449454,"qty":360.00000000}],"asks":[],"checksum":2371514390,"timestamp":"2024-06-01T18:06:04.254243Z"}]}
{"channel":"book","type":"update","data":[{"symbol":"ADA/USDT","bids":[{"price":0.449666,"qty":3330.09011776}],"asks":[],"checksum":1430124773,"timestamp":"2024-06-01T18:06:04.294348Z"}]}
{"channel":"book","type":"update","data":[{"symbol":"ADA/USDT","bids":[{"price":0.449666,"qty":0.00000000},{"price":0.449454,"qty":360.00000000}],"asks":[],"checksum":2371514390,"timestamp":"2024-06-01T18:06:05.493623Z"}]}
{"channel":"book","type":"update","data":[{"symbol":"ADA/USDT","bids":[{"price":0.449670,"qty":3329.98766149}],"asks":[],"checksum":1856916992,"timestamp":"2024-06-01T18:06:05.533876Z"}]}
{"channel":"book","type":"update","data":[{"symbol":"ADA/USDT","bids":[],"asks":[{"price":0.450088,"qty":0.00000000},{"price":0.450149,"qty":18.84631480}],"checksum":443182402,"timestamp":"2024-06-01T18:06:06.344961Z"}]}
{"channel":"book","type":"update","data":[{"symbol":"ADA/USDT","bids":[],"asks":[{"price":0.450089,"qty":5562.61091428}],"checksum":3107964885,"timestamp":"2024-06-01T18:06:06.621721Z"}]}
{"channel":"book","type":"update","data":[{"symbol":"ADA/USDT","bids":[],"asks":[{"price":0.449897,"qty":0.00000000},{"price":0.450149,"qty":18.84631480}],"checksum":2817139013,"timestamp":"2024-06-01T18:06:07.210205Z"}]}
{"channel":"book","type":"update","data":[{"symbol":"ADA/USDT","bids":[],"asks":[{"price":0.449960,"qty":1482.60000000}],"checksum":2092790592,"timestamp":"2024-06-01T18:06:07.212469Z"}]}
{"channel":"book","type":"update","data":[{"symbol":"ADA/USDT","bids":[{"price":0.449670,"qty":0.00000000},{"price":0.449454,"qty":360.00000000}],"asks":[],"checksum":697196623,"timestamp":"2024-06-01T18:06:07.301563Z"}]}
{"channel":"book","type":"update","data":[{"symbol":"ADA/USDT","bids":[{"price":0.449671,"qty":3330.03637603}],"asks":[],"checksum":3074708124,"timestamp":"2024-06-01T18:06:07.341541Z"}]}
{"channel":"book","type":"update","data":[{"symbol":"ADA/USDT","bids":[{"price":0.449505,"qty":0.00000000},{"price":0.449454,"qty":360.00000000}],"asks":[],"checksum":14861098,"timestamp":"2024-06-01T18:06:07.817886Z"}]}
{"channel":"book","type":"update","data":[{"symbol":"ADA/USDT","bids":[{"price":0.449505,"qty":115.06571709}],"asks":[],"checksum":107506954,"timestamp":"2024-06-01T18:06:07.823595Z"}]}
{"channel":"book","type":"update","data":[{"symbol":"ADA/USDT","bids":[{"price":0.449651,"qty":14072.60983292}],"asks":[],"checksum":2338308561,"timestamp":"2024-06-01T18:06:07.878562Z"}]}
{"channel":"book","type":"update","data":[{"symbol":"ADA/USDT","bids":[{"price":0.449682,"qty":6900.96251763}],"asks":[],"checksum":1000805184,"timestamp":"2024-06-01T18:06:07.918574Z"}]}
{"channel":"book","type":"update","data":[{"symbol":"ADA/USDT","bids":[{"price":0.449651,"qty":0.00000000},{"price":0.449454,"qty":360.00000000}],"asks":[],"checksum":3597755353,"timestamp":"2024-06-01T18:06:09.107912Z"}]}
{"channel":"book","type":"update","data":[{"symbol":"ADA/USDT","bids":[{"price":0.449671,"qty":0.00000000},{"price":0.449399,"qty":1484.40000000}],"asks":[],"checksum":145943548,"timestamp":"2024-06-01T18:06:09.851692Z"}]}
{"channel":"book","type":"update","data":[{"symbol":"ADA/USDT","bids":[{"price":0.449668,"qty":3330.08915102}],"asks":[],"checksum":1400002095,"timestamp":"2024-06-01T18:06:09.892025Z"}]}
{"channel":"book","type":"update","data":[{"symbol":"ADA/USDT","bids":[{"price":0.449668,"qty":0.00000000},{"price":0.449399,"qty":1484.40000000}],"asks":[],"checksum":145943548,"timestamp":"2024-06-01T18:06:10.433195Z"}]}
{"channel":"book","type":"update","data":[{"symbol":"ADA/USDT","bids":[{"price":0.449669,"qty":3330.08915102}],"asks":[],"checksum":1477803947,"timestamp":"2024-06-01T18:06:10.473287Z"}]}
{"channel":"book","type":"update","data":[{"symbol":"ADA/USDT","bids":[{"price":0.449505,"qty":0.00000000},{"price":0.449399,"qty":1484.40000000}],"asks":[],"checksum":1065372853,"timestamp":"2024-06-01T18:06:10.699367Z"}]}
{"channel":"book","type":"update","data":[{"symbol":"ADA/USDT","bids":[{"price":0.449505,"qty":162.10907159}],"asks":[],"checksum":2937863625,"timestamp":"2024-06-01T18:06:10.705233Z"}]}
{"channel":"book","type":"update","data":[{"symbol":"ADA/USDT","bids":[{"price":0.449669,"qty":0.00000000},{"price":0.449400,"qty":256.19578060}],"asks":[],"checksum":1027585401,"timestamp":"2024-06-01T18:06:11.114229Z"}]}
{"channel":"book","type":"update","data":[{"symbol":"ADA/USDT","bids":[{"price":0.449672,"qty":3329.98631443}],"asks":[],"checksum":3749729184,"timestamp":"2024-06-01T18:06:11.153468Z"}]}
{"channel":"book","type":"update","data":[{"symbol":"ADA/USDT","bids":[{"price":0.449672,"qty":0.00000000},{"price":0.449400,"qty":256.19578060}],"asks":[],"checksum":1027585401,"timestamp":"2024-06-01T18:06:11.783545Z"}]}
{"channel":"book","type":"update","data":[{"symbol":"ADA/USDT","bids":[{"price":0.449674,"qty":3329.97040093}],"asks":[],"checksum":733251791,"timestamp":"2024-06-01T18:06:11.823658Z"}]}
{"channel":"book","type":"update","data":[{"symbol":"ADA/USDT","bids":[],"asks":[{"price":0.449869,"qty":0.00000000},{"price":0.450149,"qty":18.84631480}],"checksum":995810484,"timestamp":"2024-06-01T18:06:12.082240Z"}]}
{"channel":"book","type":"update","data":[{"symbol":"ADA/USDT","bids":[],"asks":[{"price":0.450089,"qty":0.00000000},{"price":0.450230,"qty":11114.82076529}],"checksum":1433377512,"timestamp":"2024-06-01T18:06:12.261058Z"}]}
{"channel":"book","type":"update","data":[{"symbol":"ADA/USDT","bids":[{"price":0.449674,"qty":0.00000000},{"price":0.449400,"qty":256.19578060}],"asks":[],"checksum":1464938356,"timestamp":"2024-06-01T18:06:12.467792Z"}]}
{"channel":"book","type":"update","data":[{"symbol":"ADA/USDT","bids":[{"price":0.449679,"qty":3329.88552932}],"asks":[],"checksum":4286727058,"timestamp":"2024-06-01T18:06:12.508066Z"}]}
{"channel":"book","type":"update","data":[{"symbol":"ADA/USDT","bids":[],"asks":[{"price":0.450099,"qty":5562.61091428}],"checksum":1722746794,"timestamp":"2024-06-01T18:06:12.533626Z"}]}
{"channel":"book","type":"update","data":[{"symbol":"ADA/USDT","bids":[{"price":0.449679,"qty":0.00000000},{"price":0.449400,"qty":256.19578060}],"asks":[],"checksum":1933880695,"timestamp":"2024-06-01T18:06:13.067376Z"}]}
{"channel":"book","type":"update","data":[{"symbol":"ADA/USDT","bids":[{"price":0.449680,"qty":3330.35447836}],"asks":[],"checksum":271297239,"timestamp":"2024-06-01T18:06:13.107702Z"}]}
{"channel":"book","type":"update","data":[{"symbol":"ADA/USDT","bids":[{"price":0.449680,"qty":0.00000000},{"price":0.449400,"qty":256.19578060}],"asks":[],"checksum":1933880695,"timestamp":"2024-06-01T18:06:13.747685Z"}]}
{"channel":"book","type":"update","data":[{"symbol":"ADA/USDT","bids":[{"price":0.449681,"qty":3330.32405744}],"asks":[],"checksum":464773058,"timestamp":"2024-06-01T18:06:13.787908Z"}]}
{"channel":"book","type":"update","data":[{"symbol":"ADA/USDT","bids":[{"price":0.449681,"qty":0.00000000},{"price":0.449400,"qty":256.19578060}],"asks":[],"checksum":1933880695,"timestamp":"2024-06-01T18:06:16.364285Z"}]}
{"channel":"book","type":"update","data":[{"symbol":"ADA/USDT","bids":[{"price":0.449682,"qty":20974.69801144}],"asks":[],"checksum":1205149894,"timestamp":"2024-06-01T18:06:16.404518Z"}]}
{"channel":"book","type":"update","data":[{"symbol":"ADA/USDT","bids":[{"price":0.449685,"qty":3330.59636722}],"asks":[],"checksum":1418837528,"timestamp":"2024-06-01T18:06:16.404604Z"}]}
{"channel":"book","type":"update","data":[{"symbol":"ADA/USDT","bids":[{"price":0.449682,"qty":20374.69801144}],"asks":[],"checksum":4122848053,"timestamp":"2024-06-01T18:06:16.407301Z"}]}
{"channel":"book","type":"update","data":[{"symbol":"ADA/USDT","bids":[{"price":0.449698,"qty":600.00000000}],"asks":[],"checksum":2243804978,"timestamp":"2024-06-01T18:06:16.407415Z"}]}
{"channel":"book","type":"update","data":[{"symbol":"ADA/USDT","bids":[{"price":0.449500,"qty":0.00000000},{"price":0.449454,"qty":360.00000000}],"asks":[],"checksum":1210682910,"timestamp":"2024-06-01T18:06:16.410144Z"}]}
{"channel":"book","type":"update","data":[{"symbol":"ADA/USDT","bids":[{"price":0.449500,"qty":10718.99550117}],"asks":[],"checksum":2218995600,"timestamp":"2024-06-01T18:06:16.413078Z"}]}
{"channel":"book","type":"update","data":[{"symbol":"ADA/USDT","bids":[{"price":0.449685,"qty":0.00000000},{"price":0.449454,"qty":360.00000000}],"asks":[],"checksum":3254505376,"timestamp":"2024-06-01T18:06:17.541974Z"}]}
{"channel":"book","type":"update","data":[{"symbol":"ADA/USDT","bids":[{"price":0.449682,"qty":6300.96251763}],"asks":[],"checksum":1016495178,"timestamp":"2024-06-01T18:06:17.542017Z"}]}
{"channel":"book","type":"update","data":[{"symbol":"ADA/USDT","bids":[{"price":0.449678,"qty":3330.78811598}],"asks":[],"checksum":3317814616,"timestamp":"2024-06-01T18:06:17.582079Z"}]}
{"channel":"book","type":"update","data":[{"symbol":"ADA/USDT","bids":[{"price":0.449678,"qty":0.00000000},{"price":0.449454,"qty":360.00000000}],"asks":[],"checksum":1016495178,"timestamp":"2024-06-01T18:06:18.189201Z"}]}
{"channel":"book","type":"update","data":[{"symbol":"ADA/USDT","bids":[{"price":0.449682,"qty":9631.60842867}],"asks":[],"checksum":1496393014,"timestamp":"2024-06-01T18:06:18.229496Z"}]}
