{"channel":"book","type":"snapshot","data":[{"symbol":"ADA/EUR","bids":[{"price":0.414409,"qty":2100.00000000},{"price":0.414404,"qty":870.00000000},{"price":0.414403,"qty":7786.99694628},{"price":0.414385,"qty":1138.42267614},{"price":0.414384,"qty":410.00000000},{"price":0.414379,"qty":820.26269232},{"price":0.414342,"qty":1128.45058124},{"price":0.414317,"qty":11126.67734582},{"price":0.414308,"qty":1694.89750520},{"price":0.414302,"qty":1628.00162800}],"asks":[{"price":0.414544,"qty":870.00000000},{"price":0.414548,"qty":7784.29555820},{"price":0.414623,"qty":40.14520316},{"price":0.414636,"qty":71.01033538},{"price":0.414642,"qty":7782.51853077},{"price":0.414688,"qty":5876.59157689},{"price":0.414693,"qty":67.59611322},{"price":0.414700,"qty":33.79805661},{"price":0.414701,"qty":33.79805661},{"price":0.414713,"qty":7781.18946749}],"checksum":2754758791}]}
{"channel":"book","type":"update","data":[{"symbol":"ADA/EUR","bids":[{"price":0.414318,"qty":78.99571658}],"asks":[],"checksum":2197846834,"timestamp":"2024-06-01T18:05:54.255254Z"}]}
{"channel":"book","type":"update","data":[{"symbol":"ADA/EUR","bids":[],"asks":[{"price":0.414544,"qty":0.00000000},{"price":0.414770,"qty":15346.73357024}],"checksum":454053685,"timestamp":"2024-06-01T18:05:55.790454Z"}]}
{"channel":"book","type":"update","data":[{"symbol":"ADA/EUR","bids":[{"price":0.414404,"qty":0.00000000},{"price":0.414302,"qty":1628.00162800}],"asks":[],"checksum":4138549132,"timestamp":"2024-06-01T18:05:55.790469Z"}]}
{"channel":"book","type":"update","data":[{"symbol":"ADA/EUR","bids":[{"price":0.414410,"qty":870.00000000}],"asks":[],"checksum":1858418374,"timestamp":"2024-06-01T18:05:55.790665Z"}]}
{"channel":"book","type":"update","data":[{"symbol":"ADA/EUR","bids":[{"price":0.414337,"qty":11126.72682191}],"asks":[],"checksum":3606716799,"timestamp":"2024-06-01T18:05:59.768953Z"}]}
{"channel":"book","type":"update","data":[{"symbol":"ADA/EUR","bids":[{"price":0.414318,"qty":24464.37081570}],"asks":[],"checksum":3259473142,"timestamp":"2024-06-01T18:05:59.771990Z"}]}
{"channel":"book","type":"update","data":[{"symbol":"ADA/EUR","bids":[{"price":0.414403,"qty":0.00000000},{"price":0.414308,"qty":1694.89750520}],"asks":[],"checksum":3902885557,"timestamp":"2024-06-01T18:06:00.182917Z"}]}
{"channel":"book","type":"update","data":[{"symbol":"ADA/EUR","bids":[{"price":0.414318,"qty":78.99571658}],"asks":[],"checksum":3146757271,"timestamp":"2024-06-01T18:06:00.186067Z"}]}
{"channel":"book","type":"update","data":[{"symbol":"ADA/EUR","bids":[{"price":0.414394,"qty":7787.15995923}],"asks":[],"checksum":1285834358,"timestamp":"2024-06-01T18:06:00.186429Z"}]}
{"channel":"book","type":"update","data":[{"symbol":"ADA/EUR","bids":[{"price":0.414391,"qty":2100.00000000}],"asks":[],"checksum":2824197621,"timestamp":"2024-06-01T18:06:00.189192Z"}]}
{"channel":"book","type":"update","data":[{"symbol":"ADA/EUR","bids":[{"price":0.414409,"qty":0.00000000},{"price":0.414317,"qty":11126.67734582}],"asks":[],"checksum":3270658687,"timestamp":"2024-06-01T18:06:00.189274Z"}]}
{"channel":"book","type":"update","data":[{"symbol":"ADA/EUR","bids":[{"price":0.414400,"qty":2100.00000000}],"asks":[],"checksum":4161515601,"timestamp":"2024-06-01T18:06:00.591620Z"}]}
{"channel":"book","type":"update","data":[{"symbol":"ADA/EUR","bids":[{"price":0.414391,"qty":0.00000000},{"price":0.414317,"qty":11126.67734582}],"asks":[],"checksum":2639232994,"timestamp":"2024-06-01T18:06:00.596672Z"}]}
{"channel":"book","type":"update","data":[{"symbol":"ADA/EUR","bids":[{"price":0.414379,"qty":0.00000000},{"price":0.414308,"qty":1694.89750520}],"asks":[],"checksum":895933634,"timestamp":"2024-06-01T18:06:01.186883Z"}]}
{"channel":"book","type":"update","data":[{"symbol":"ADA/EUR","bids":[{"price":0.414382,"qty":820.25675387}],"asks":[],"checksum":3342168172,"timestamp":"2024-06-01T18:06:01.318254Z"}]}
{"channel":"book","type":"update","data":[{"symbol":"ADA/EUR","bids":[],"asks":[{"price":0.414635,"qty":1123.55583009}],"checksum":3724111361,"timestamp":"2024-06-01T18:06:01.322203Z"}]}
{"channel":"book","type":"update","data":[{"symbol":"ADA/EUR","bids":[],"asks":[{"price":0.414548,"qty":0.00000000},{"price":0.414770,"qty":15346.73357024}],"checksum":2214667364,"timestamp":"2024-06-01T18:06:02.144762Z"}]}
{"channel":"book","type":"update","data":[{"symbol":"ADA/EUR","bids":[],"asks":[{"price":0.414611,"qty":870.00000000}],"checksum":3803321647,"timestamp":"2024-06-01T18:06:02.147643Z"}]}
{"channel":"book","type":"update","data":[{"symbol":"ADA/EUR","bids":[{"price":0.414338,"qty":24385.37509912}],"asks":[],"checksum":906882903,"timestamp":"2024-06-01T18:06:02.148207Z"}]}
{"channel":"book","type":"update","data":[{"symbol":"ADA/EUR","bids":[],"asks":[{"price":0.414540,"qty":7784.43526547}],"checksum":1797214363,"timestamp":"2024-06-01T18:06:02.148913Z"}]}
{"channel":"book","type":"update","data":[{"symbol":"ADA/EUR","bids":[{"price":0.414385,"qty":0.00000000},{"price":0.414317,"qty":11126.67734582}],"asks":[],"checksum":3618420825,"timestamp":"2024-06-01T18:06:02.472332Z"}]}
{"channel":"book","type":"update","data":[{"symbol":"ADA/EUR","bids":[],"asks":[{"price":0.414635,"qty":0.00000000},{"price":0.414713,"qty":7781.18946749}],"checksum":420459912,"timestamp":"2024-06-01T18:06:02.472522Z"}]}
{"channel":"book","type":"update","data":[{"symbol":"ADA/EUR","bids":[{"price":0.414338,"qty":0.00000000},{"price":0.414308,"qty":4785.66566290}],"asks":[],"checksum":2216811477,"timestamp":"2024-06-01T18:06:02.475466Z"}]}
{"channel":"book","type":"update","data":[{"symbol":"ADA/EUR","bids":[{"price":0.414318,"qty":0.00000000},{"price":0.414302,"qty":1628.00162800}],"asks":[],"checksum":2932574844,"timestamp":"2024-06-01T18:06:02.594921Z"}]}
{"channel":"book","type":"update","data":[{"symbol":"ADA/EUR","bids":[],"asks":[{"price":0.414688,"qty":0.00000000},{"price":0.414769,"qty":1112.10864047}],"checksum":1597002064,"timestamp":"2024-06-01T18:06:02.890561Z"}]}
{"channel":"book","type":"update","data":[{"symbol":"ADA/EUR","bids":[],"asks":[{"price":0.414701,"qty":0.00000000},{"price":0.414770,"qty":11292.58357024}],"checksum":2828939841,"timestamp":"2024-06-01T18:06:02.890680Z"}]}
{"channel":"book","type":"update","data":[{"symbol":"ADA/EUR","bids":[],"asks":[{"price":0.414693,"qty":33.79805661}],"checksum":1089225436,"timestamp":"2024-06-01T18:06:02.890731Z"}]}
{"channel":"book","type":"update","data":[{"symbol":"ADA/EUR","bids":[],"asks":[{"price":0.414700,"qty":0.00000000},{"price":0.414801,"qty":44.50586684}],"checksum":2354119193,"timestamp":"2024-06-01T18:06:02.890740Z"}]}
{"channel":"book","type":"update","data":[{"symbol":"ADA/EUR","bids":[],"asks":[{"price":0.414693,"qty":0.00000000},{"price":0.414802,"qty":1486.20000000}],"checksum":1969429498,"timestamp":"2024-06-01T18:06:02.896457Z"}]}
{"channel":"book","type":"update","data":[{"symbol":"ADA/EUR","bids":[{"price":0.414361,"qty":33.79805661}],"asks":[],"checksum":3088362964,"timestamp":"2024-06-01T18:06:02.896615Z"}]}
{"channel":"book","type":"update","data":[{"symbol":"ADA/EUR","bids":[{"price":0.414368,"qty":33.79805661}],"asks":[],"checksum":1508306053,"timestamp":"2024-06-01T18:06:02.954969Z"}]}
{"channel":"book","type":"update","data":[{"symbol":"ADA/EUR","bids":[{"price":0.414395,"qty":1098.53235717}],"asks":[],"checksum":2666168092,"timestamp":"2024-06-01T18:06:03.006749Z"}]}
{"channel":"book","type":"update","data":[{"symbol":"ADA/EUR","bids":[{"price":0.414367,"qty":33.79805661}],"asks":[],"checksum":1532290466,"timestamp":"2024-06-01T18:06:03.010624Z"}]}
{"channel":"book","type":"update","data":[{"symbol":"ADA/EUR","bids":[{"price":0.414361,"qty":67.59611322}],"asks":[],"checksum":3980865806,"timestamp":"2024-06-01T18:06:03.011557Z"}]}
{"channel":"book","type":"update","data":[{"symbol":"ADA/EUR","bids":[{"price":0.414401,"qty":2100.00000000}],"asks":[],"checksum":509841484,"timestamp":"2024-06-01T18:06:03.011991Z"}]}
{"channel":"book","type":"update","data":[{"symbol":"ADA/EUR","bids":[],"asks":[{"price":0.414801,"qty":0.00000000},{"price":0.414804,"qty":87.92516467}],"checksum":4090839517,"timestamp":"2024-06-01T18:06:03.088326Z"}]}
{"channel":"book","type":"update","data":[{"symbol":"ADA/EUR","bids":[],"asks":[{"price":0.414804,"qty":0.00000000},{"price":0.414854,"qty":30.00000000}],"checksum":2949116455,"timestamp":"2024-06-01T18:06:03.088459Z"}]}
{"channel":"book","type":"update","data":[{"symbol":"ADA/EUR","bids":[{"price":0.414400,"qty":0.00000000},{"price":0.414356,"qty":5876.59157689}],"asks":[],"checksum":1585008188,"timestamp":"2024-06-01T18:06:03.091466Z"}]}
{"channel":"book","type":"update","data":[{"symbol":"ADA/EUR","bids":[],"asks":[{"price":0.414636,"qty":0.00000000},{"price":0.414860,"qty":144.56469923}],"checksum":4215991363,"timestamp":"2024-06-01T18:06:03.694888Z"}]}
{"channel":"book","type":"update","data":[{"symbol":"ADA/EUR","bids":[],"asks":[{"price":0.414639,"qty":71.01033538}],"checksum":2349374564,"timestamp":"2024-06-01T18:06:03.840933Z"}]}
{"channel":"book","type":"update","data":[{"symbol":"ADA/EUR","bids":[],"asks":[{"price":0.414540,"qty":0.00000000},{"price":0.414860,"qty":144.56469923}],"checksum":4029013604,"timestamp":"2024-06-01T18:06:03.905482Z"}]}
{"channel":"book","type":"update","data":[{"symbol":"ADA/EUR","bids":[{"price":0.414394,"qty":0.00000000},{"price":0.414342,"qty":1128.45058124}],"asks":[],"checksum":3979411449,"timestamp":"2024-06-01T18:06:03.905498Z"}]}
{"channel":"book","type":"update","data":[{"symbol":"ADA/EUR","bids":[],"asks":[{"price":0.414642,"qty":0.00000000},{"price":0.414861,"qty":398.13041528}],"checksum":1371079072,"timestamp":"2024-06-01T18:06:03.905526Z"}]}
{"channel":"book","type":"update","data":[{"symbol":"ADA/EUR","bids":[],"asks":[{"price":0.414777,"qty":5876.59157689}],"checksum":1996750243,"timestamp":"2024-06-01T18:06:03.909746Z"}]}
{"channel":"book","type":"update","data":[{"symbol":"ADA/EUR","bids":[],"asks":[{"price":0.414792,"qty":33.79805661}],"checksum":1777093928,"timestamp":"2024-06-01T18:06:03.909791Z"}]}
{"channel":"book","type":"update","data":[{"symbol":"ADA/EUR","bids":[],"asks":[{"price":0.414793,"qty":33.79805661}],"checksum":1049540942,"timestamp":"2024-06-01T18:06:03.910215Z"}]}
{"channel":"book","type":"update","data":[{"symbol":"ADA/EUR","bids":[],"asks":[{"price":0.414786,"qty":33.79805661}],"checksum":3830887071,"timestamp":"2024-06-01T18:06:03.910366Z"}]}
{"channel":"book","type":"update","data":[{"symbol":"ADA/EUR","bids":[],"asks":[{"price":0.414578,"qty":7783.72120582}],"checksum":1588023518,"timestamp":"2024-06-01T18:06:03.910851Z"}]}
{"channel":"book","type":"update","data":[{"symbol":"ADA/EUR","bids":[{"price":0.414429,"qty":7786.51260196}],"asks":[],"checksum":2453351707,"timestamp":"2024-06-01T18:06:03.910883Z"}]}
{"channel":"book","type":"update","data":[{"symbol":"ADA/EUR","bids":[],"asks":[{"price":0.414783,"qty":7779.88873979}],"checksum":3032010648,"timestamp":"2024-06-01T18:06:03.910928Z"}]}
{"channel":"book","type":"update","data":[{"symbol":"ADA/EUR","bids":[],"asks":[{"price":0.414786,"qty":67.59611322}],"checksum":1170545639,"timestamp":"2024-06-01T18:06:03.911285Z"}]}
{"channel":"book","type":"update","data":[{"symbol":"ADA/EUR","bids":[{"price":0.414435,"qty":870.00000000}],"asks":[],"checksum":853089895,"timestamp":"2024-06-01T18:06:03.913792Z"}]}
{"channel":"book","type":"update","data":[{"symbol":"ADA/EUR","bids":[{"price":0.414410,"qty":0.00000000},{"price":0.414356,"qty":5876.59157689}],"asks":[],"checksum":2590327114,"timestamp":"2024-06-01T18:06:03.913819Z"}]}
{"channel":"book","type":"update","data":[{"symbol":"ADA/EUR","bids":[{"price":0.414435,"qty":2970.00000000}],"asks":[],"checksum":674821433,"timestamp":"2024-06-01T18:06:04.092465Z"}]}
{"channel":"book","type":"update","data":[{"symbol":"ADA/EUR","bids":[{"price":0.414401,"qty":0.00000000},{"price":0.414342,"qty":1128.45058124}],"asks":[],"checksum":1713732054,"timestamp":"2024-06-01T18:06:04.098039Z"}]}
{"channel":"book","type":"update","data":[{"symbol":"ADA/EUR","bids":[],"asks":[{"price":0.414578,"qty":0.00000000},{"price":0.414792,"qty":33.79805661}],"checksum":1914424838,"timestamp":"2024-06-01T18:06:05.917050Z"}]}
{"channel":"book","type":"update","data":[{"symbol":"ADA/EUR","bids":[],"asks":[{"price":0.414571,"qty":7783.86171172}],"checksum":2731306282,"timestamp":"2024-06-01T18:06:05.921589Z"}]}
{"channel":"book","type":"update","data":[{"symbol":"ADA/EUR","bids":[{"price":0.414429,"qty":0.00000000},{"price":0.414338,"qty":24385.37509912}],"asks":[],"checksum":3533929900,"timestamp":"2024-06-01T18:06:06.919954Z"}]}
{"channel":"book","type":"update","data":[{"symbol":"ADA/EUR","bids":[{"price":0.414421,"qty":7786.65826526}],"asks":[],"checksum":799690988,"timestamp":"2024-06-01T18:06:06.924848Z"}]}
{"channel":"book","type":"update","data":[{"symbol":"ADA/EUR","bids":[{"price":0.414435,"qty":870.00000000}],"asks":[],"checksum":3510678682,"timestamp":"2024-06-01T18:06:06.926210Z"}]}
{"channel":"book","type":"update","data":[{"symbol":"ADA/EUR","bids":[{"price":0.414401,"qty":2100.00000000}],"asks":[],"checksum":2673686645,"timestamp":"2024-06-01T18:06:06.926395Z"}]}
{"channel":"book","type":"update","data":[{"symbol":"ADA/EUR","bids":[{"price":0.414427,"qty":2100.00000000}],"asks":[],"checksum":2712036548,"timestamp":"2024-06-01T18:06:07.094324Z"}]}
{"channel":"book","type":"update","data":[{"symbol":"ADA/EUR","bids":[{"price":0.414401,"qty":0.00000000},{"price":0.414356,"qty":5876.59157689}],"asks":[],"checksum":275803512,"timestamp":"2024-06-01T18:06:07.099464Z"}]}
{"channel":"book","type":"update","data":[{"symbol":"ADA/EUR","bids":[],"asks":[{"price":0.414571,"qty":0.00000000},{"price":0.414792,"qty":33.79805661}],"checksum":2814752413,"timestamp":"2024-06-01T18:06:08.922580Z"}]}
{"channel":"book","type":"update","data":[{"symbol":"ADA/EUR","bids":[],"asks":[{"price":0.414564,"qty":7783.99006139}],"checksum":2036226380,"timestamp":"2024-06-01T18:06:08.926859Z"}]}
{"channel":"book","type":"update","data":[{"symbol":"ADA/EUR","bids":[],"asks":[{"price":0.414639,"qty":0.00000000},{"price":0.414792,"qty":33.79805661}],"checksum":3153312982,"timestamp":"2024-06-01T18:06:11.887729Z"}]}
{"channel":"book","type":"update","data":[{"symbol":"ADA/EUR","bids":[{"price":0.414421,"qty":0.00000000},{"price":0.414342,"qty":1128.45058124}],"asks":[],"checksum":3404412547,"timestamp":"2024-06-01T18:06:12.037802Z"}]}
{"channel":"book","type":"update","data":[{"symbol":"ADA/EUR","bids":[{"price":0.414382,"qty":0.00000000},{"price":0.414338,"qty":24385.37509912}],"asks":[],"checksum":1502544328,"timestamp":"2024-06-01T18:06:12.040008Z"}]}
{"channel":"book","type":"update","data":[{"symbol":"ADA/EUR","bids":[{"price":0.414413,"qty":7786.81108640}],"asks":[],"checksum":1147070683,"timestamp":"2024-06-01T18:06:12.042958Z"}]}
{"channel":"book","type":"update","data":[{"symbol":"ADA/EUR","bids":[],"asks":[{"price":0.414690,"qty":71.01033538}],"checksum":533683230,"timestamp":"2024-06-01T18:06:12.055877Z"}]}
{"channel":"book","type":"update","data":[{"symbol":"ADA/EUR","bids":[],"asks":[{"price":0.414690,"qty":0.00000000},{"price":0.414792,"qty":33.79805661}],"checksum":1147070683,"timestamp":"2024-06-01T18:06:12.062614Z"}]}
{"channel":"book","type":"update","data":[{"symbol":"ADA/EUR","bids":[{"price":0.414427,"qty":0.00000000},{"price":0.414337,"qty":11126.72682191}],"asks":[],"checksum":1980255586,"timestamp":"2024-06-01T18:06:12.065372Z"}]}
{"channel":"book","type":"update","data":[{"symbol":"ADA/EUR","bids":[{"price":0.414401,"qty":2100.00000000}],"asks":[],"checksum":1199535595,"timestamp":"2024-06-01T18:06:12.065437Z"}]}
{"channel":"book","type":"update","data":[{"symbol":"ADA/EUR","bids":[{"price":0.414419,"qty":2100.00000000}],"asks":[],"checksum":4285780191,"timestamp":"2024-06-01T18:06:12.091614Z"}]}
{"channel":"book","type":"update","data":[{"symbol":"ADA/EUR","bids":[{"price":0.414399,"qty":820.22310426}],"asks":[],"checksum":2298787807,"timestamp":"2024-06-01T18:06:12.165119Z"}]}
{"channel":"book","type":"update","data":[{"symbol":"ADA/EUR","bids":[{"price":0.414401,"qty":0.00000000},{"price":0.414356,"qty":5876.59157689}],"asks":[],"checksum":1764627933,"timestamp":"2024-06-01T18:06:12.170576Z"}]}
{"channel":"book","type":"update","data":[{"symbol":"ADA/EUR","bids":[{"price":0.414388,"qty":118.40410000}],"asks":[],"checksum":2209310578,"timestamp":"2024-06-01T18:06:12.180465Z"}]}
{"channel":"book","type":"update","data":[{"symbol":"ADA/EUR","bids":[],"asks":[{"price":0.414737,"qty":71.01033538}],"checksum":4049211940,"timestamp":"2024-06-01T18:06:12.256072Z"}]}
{"channel":"book","type":"update","data":[{"symbol":"ADA/EUR","bids":[{"price":0.414363,"qty":11126.03419672}],"asks":[],"checksum":2800854222,"timestamp":"2024-06-01T18:06:15.417966Z"}]}
{"channel":"book","type":"update","data":[{"symbol":"ADA/EUR","bids":[],"asks":[{"price":0.414564,"qty":0.00000000},{"price":0.414792,"qty":33.79805661}],"checksum":4289440112,"timestamp":"2024-06-01T18:06:15.934022Z"}]}
{"channel":"book","type":"update","data":[{"symbol":"ADA/EUR","bids":[],"asks":[{"price":0.414557,"qty":7784.12440032}],"checksum":2859764965,"timestamp":"2024-06-01T18:06:15.938179Z"}]}
{"channel":"book","type":"update","data":[{"symbol":"ADA/EUR","bids":[],"asks":[{"price":0.414737,"qty":0.00000000},{"price":0.414792,"qty":33.79805661}],"checksum":1574589877,"timestamp":"2024-06-01T18:06:19.334001Z"}]}
{"channel":"book","type":"update","data":[{"symbol":"ADA/EUR","bids":[],"asks":[{"price":0.414688,"qty":71.01033538}],"checksum":3707919892,"timestamp":"2024-06-01T18:06:19.452787Z"}]}
{"channel":"book","type":"update","data":[{"symbol":"ADA/EUR","bids":[{"price":0.414399,"qty":0.00000000},{"price":0.414361,"qty":67.59611322}],"asks":[],"checksum":630222626,"timestamp":"2024-06-01T18:06:20.336720Z"}]}
