{"channel":"book","type":"snapshot","data":[{"symbol":"AUD/USD","bids":[{"price":0.66456,"qty":5597.50208947},{"price":0.66455,"qty":3735.19790000},{"price":0.66454,"qty":2727.38811437},{"price":0.66432,"qty":5184.58590000},{"price":0.66378,"qty":1030.79604688},{"price":0.66377,"qty":513.95633058},{"price":0.66376,"qty":28936.71095863},{"price":0.66375,"qty":53001.00000000},{"price":0.66361,"qty":47002.00000000},{"price":0.66358,"qty":3003.00000000}],"asks":[{"price":0.66477,"qty":5597.04322019},{"price":0.66478,"qty":5436.00000000},{"price":0.66500,"qty":4258.83710000},{"price":0.66501,"qty":298.14569990},{"price":0.66527,"qty":466.07172610},{"price":0.66557,"qty":294.01313515},{"price":0.66560,"qty":35267.16262833},{"price":0.66561,"qty":72701.00000000},{"price":0.66567,"qty":3013.00000000},{"price":0.66573,"qty":4434.00000000}],"checksum":535393531}]}
{"channel":"book","type":"update","data":[{"symbol":"AUD/USD","bids":[{"price":0.66376,"qty":0.00000000},{"price":0.66352,"qty":2804.00000000}],"asks":[],"checksum":3608425120,"timestamp":"2024-06-01T18:05:48.775260Z"}]}
{"channel":"book","type":"update","data":[{"symbol":"AUD/USD","bids":[{"price":0.66379,"qty":26775.83569701}],"asks":[],"checksum":21858,"timestamp":"2024-06-01T18:05:48.780346Z"}]}
{"channel":"book","type":"update","data":[{"symbol":"AUD/USD","bids":[{"price":0.66378,"qty":0.00000000},{"price":0.66352,"qty":2804.00000000}],"asks":[],"checksum":2985525671,"timestamp":"2024-06-01T18:05:48.787387Z"}]}
{"channel":"book","type":"update","data":[{"symbol":"AUD/USD","bids":[{"price":0.66380,"qty":1030.76498945}],"asks":[],"checksum":3223415479,"timestamp":"2024-06-01T18:05:48.787397Z"}]}
{"channel":"book","type":"update","data":[{"symbol":"AUD/USD","bids":[{"price":0.66377,"qty":0.00000000},{"price":0.66352,"qty":2804.00000000}],"asks":[],"checksum":184276757,"timestamp":"2024-06-01T18:05:51.331981Z"}]}
{"channel":"book","type":"update","data":[{"symbol":"AUD/USD","bids":[{"price":0.66381,"qty":513.95633058}],"asks":[],"checksum":897241557,"timestamp":"2024-06-01T18:05:51.338097Z"}]}
{"channel":"book","type":"update","data":[{"symbol":"AUD/USD","bids":[],"asks":[{"price":0.66557,"qty":0.00000000},{"price":0.66583,"qty":5032.00000000}],"checksum":3122615207,"timestamp":"2024-06-01T18:05:51.754659Z"}]}
{"channel":"book","type":"update","data":[{"symbol":"AUD/USD","bids":[],"asks":[{"price":0.66559,"qty":294.01313515}],"checksum":3576318496,"timestamp":"2024-06-01T18:05:51.755552Z"}]}
{"channel":"book","type":"update","data":[{"symbol":"AUD/USD","bids":[{"price":0.66379,"qty":0.00000000},{"price":0.66352,"qty":2804.00000000}],"asks":[],"checksum":657932060,"timestamp":"2024-06-01T18:05:52.250427Z"}]}
{"channel":"book","type":"update","data":[{"symbol":"AUD/USD","bids":[{"price":0.66382,"qty":20175.42845742}],"asks":[],"checksum":1540412233,"timestamp":"2024-06-01T18:05:52.257533Z"}]}
{"channel":"book","type":"update","data":[{"symbol":"AUD/USD","bids":[{"price":0.66380,"qty":0.00000000},{"price":0.66352,"qty":2804.00000000}],"asks":[],"checksum":1066404109,"timestamp":"2024-06-01T18:05:52.266349Z"}]}
{"channel":"book","type":"update","data":[{"symbol":"AUD/USD","bids":[{"price":0.66383,"qty":1030.71840682}],"asks":[],"checksum":3987852650,"timestamp":"2024-06-01T18:05:52.266547Z"}]}
{"channel":"book","type":"update","data":[{"symbol":"AUD/USD","bids":[],"asks":[{"price":0.66560,"qty":0.00000000},{"price":0.66583,"qty":5032.00000000}],"checksum":710907210,"timestamp":"2024-06-01T18:05:53.857831Z"}]}
{"channel":"book","type":"update","data":[{"symbol":"AUD/USD","bids":[],"asks":[{"price":0.66558,"qty":5939.02189271}],"checksum":2046992173,"timestamp":"2024-06-01T18:05:53.859269Z"}]}
{"channel":"book","type":"update","data":[{"symbol":"AUD/USD","bids":[],"asks":[{"price":0.66560,"qty":29299.49997318}],"checksum":64361552,"timestamp":"2024-06-01T18:05:53.859473Z"}]}
{"channel":"book","type":"update","data":[{"symbol":"AUD/USD","bids":[{"price":0.66381,"qty":0.00000000},{"price":0.66352,"qty":2804.00000000}],"asks":[],"checksum":4267457023,"timestamp":"2024-06-01T18:05:55.243947Z"}]}
{"channel":"book","type":"update","data":[{"symbol":"AUD/USD","bids":[{"price":0.66384,"qty":513.95633058}],"asks":[],"checksum":1134370247,"timestamp":"2024-06-01T18:05:55.252922Z"}]}
{"channel":"book","type":"update","data":[{"symbol":"AUD/USD","bids":[{"price":0.66382,"qty":0.00000000},{"price":0.66352,"qty":2804.00000000}],"asks":[],"checksum":3543844597,"timestamp":"2024-06-01T18:05:55.762370Z"}]}
{"channel":"book","type":"update","data":[{"symbol":"AUD/USD","bids":[{"price":0.66384,"qty":7841.91467297}],"asks":[],"checksum":1038453676,"timestamp":"2024-06-01T18:05:55.768441Z"}]}
{"channel":"book","type":"update","data":[{"symbol":"AUD/USD","bids":[{"price":0.66376,"qty":12958.92088050}],"asks":[],"checksum":909628515,"timestamp":"2024-06-01T18:05:55.768492Z"}]}
{"channel":"book","type":"update","data":[{"symbol":"AUD/USD","bids":[{"price":0.66383,"qty":0.00000000},{"price":0.66352,"qty":2804.00000000}],"asks":[],"checksum":2966058868,"timestamp":"2024-06-01T18:05:55.791283Z"}]}
{"channel":"book","type":"update","data":[{"symbol":"AUD/USD","bids":[{"price":0.66385,"qty":1030.68735407}],"asks":[],"checksum":373979929,"timestamp":"2024-06-01T18:05:55.791630Z"}]}
{"channel":"book","type":"update","data":[{"symbol":"AUD/USD","bids":[],"asks":[{"price":0.66476,"qty":298.14569990}],"checksum":2800112855,"timestamp":"2024-06-01T18:05:55.923902Z"}]}
{"channel":"book","type":"update","data":[{"symbol":"AUD/USD","bids":[],"asks":[{"price":0.66477,"qty":0.00000000},{"price":0.66567,"qty":3013.00000000},{"price":0.66475,"qty":5596.06291684}],"checksum":2390808682,"timestamp":"2024-06-01T18:05:55.926981Z"}]}
{"channel":"book","type":"update","data":[{"symbol":"AUD/USD","bids":[],"asks":[{"price":0.66475,"qty":0.00000000},{"price":0.66567,"qty":3013.00000000},{"price":0.66474,"qty":5596.06291684}],"checksum":220559915,"timestamp":"2024-06-01T18:05:55.930136Z"}]}
{"channel":"book","type":"update","data":[{"symbol":"AUD/USD","bids":[],"asks":[{"price":0.66474,"qty":0.00000000},{"price":0.66567,"qty":3013.00000000},{"price":0.66475,"qty":5596.06291684}],"checksum":2390808682,"timestamp":"2024-06-01T18:05:55.933752Z"}]}
{"channel":"book","type":"update","data":[{"symbol":"AUD/USD","bids":[],"asks":[{"price":0.66475,"qty":0.00000000},{"price":0.66567,"qty":3013.00000000},{"price":0.66474,"qty":5596.06291684}],"checksum":220559915,"timestamp":"2024-06-01T18:05:55.937130Z"}]}
{"channel":"book","type":"update","data":[{"symbol":"AUD/USD","bids":[],"asks":[{"price":0.66474,"qty":0.00000000},{"price":0.66567,"qty":3013.00000000},{"price":0.66473,"qty":5596.06291684}],"checksum":834607470,"timestamp":"2024-06-01T18:05:55.940247Z"}]}
{"channel":"book","type":"update","data":[{"symbol":"AUD/USD","bids":[],"asks":[{"price":0.66473,"qty":0.00000000},{"price":0.66567,"qty":3013.00000000},{"price":0.66472,"qty":5596.06291684}],"checksum":2988096303,"timestamp":"2024-06-01T18:05:55.943619Z"}]}
{"channel":"book","type":"update","data":[{"symbol":"AUD/USD","bids":[],"asks":[{"price":0.66472,"qty":0.00000000},{"price":0.66567,"qty":3013.00000000},{"price":0.66475,"qty":5596.06291684}],"checksum":2390808682,"timestamp":"2024-06-01T18:05:55.946917Z"}]}
{"channel":"book","type":"update","data":[{"symbol":"AUD/USD","bids":[],"asks":[{"price":0.66478,"qty":0.00000000},{"price":0.66567,"qty":3013.00000000},{"price":0.66474,"qty":5436.00000000}],"checksum":983243989,"timestamp":"2024-06-01T18:05:55.957080Z"}]}
{"channel":"book","type":"update","data":[{"symbol":"AUD/USD","bids":[],"asks":[{"price":0.66475,"qty":0.00000000},{"price":0.66567,"qty":3013.00000000},{"price":0.66473,"qty":5596.06291684}],"checksum":1259196981,"timestamp":"2024-06-01T18:05:55.960574Z"}]}
{"channel":"book","type":"update","data":[{"symbol":"AUD/USD","bids":[],"asks":[{"price":0.66501,"qty":0.00000000},{"price":0.66567,"qty":3013.00000000}],"checksum":925277579,"timestamp":"2024-06-01T18:05:56.099669Z"}]}
{"channel":"book","type":"update","data":[{"symbol":"AUD/USD","bids":[],"asks":[{"price":0.66500,"qty":0.00000000},{"price":0.66573,"qty":4434.00000000}],"checksum":2808752416,"timestamp":"2024-06-01T18:05:56.122277Z"}]}
{"channel":"book","type":"update","data":[{"symbol":"AUD/USD","bids":[],"asks":[{"price":0.66526,"qty":4258.83710000}],"checksum":1620852225,"timestamp":"2024-06-01T18:05:56.122338Z"}]}
{"channel":"book","type":"update","data":[{"symbol":"AUD/USD","bids":[],"asks":[{"price":0.66559,"qty":0.00000000},{"price":0.66573,"qty":4434.00000000}],"checksum":1519220083,"timestamp":"2024-06-01T18:05:56.606444Z"}]}
{"channel":"book","type":"update","data":[{"symbol":"AUD/USD","bids":[],"asks":[{"price":0.66557,"qty":234.39423819}],"checksum":3142412099,"timestamp":"2024-06-01T18:05:56.606925Z"}]}
{"channel":"book","type":"update","data":[{"symbol":"AUD/USD","bids":[],"asks":[{"price":0.66525,"qty":59.38977258}],"checksum":1906969294,"timestamp":"2024-06-01T18:05:56.606979Z"}]}
{"channel":"book","type":"update","data":[{"symbol":"AUD/USD","bids":[],"asks":[{"price":0.66558,"qty":0.00000000},{"price":0.66567,"qty":3013.00000000}],"checksum":2743287055,"timestamp":"2024-06-01T18:05:56.870916Z"}]}
{"channel":"book","type":"update","data":[{"symbol":"AUD/USD","bids":[],"asks":[{"price":0.66525,"qty":5998.41166529}],"checksum":2475420171,"timestamp":"2024-06-01T18:05:56.871755Z"}]}
{"channel":"book","type":"update","data":[{"symbol":"AUD/USD","bids":[],"asks":[{"price":0.66526,"qty":0.00000000},{"price":0.66573,"qty":4434.00000000}],"checksum":3564249243,"timestamp":"2024-06-01T18:05:56.877969Z"}]}
{"channel":"book","type":"update","data":[{"symbol":"AUD/USD","bids":[],"asks":[{"price":0.66524,"qty":4258.83710000}],"checksum":210259682,"timestamp":"2024-06-01T18:05:56.878072Z"}]}
{"channel":"book","type":"update","data":[{"symbol":"AUD/USD","bids":[{"price":0.66384,"qty":7327.95834239}],"asks":[],"checksum":115964970,"timestamp":"2024-06-01T18:05:59.207476Z"}]}
{"channel":"book","type":"update","data":[{"symbol":"AUD/USD","bids":[{"price":0.66386,"qty":513.95633058}],"asks":[],"checksum":1143534443,"timestamp":"2024-06-01T18:05:59.219870Z"}]}
{"channel":"book","type":"update","data":[{"symbol":"AUD/USD","bids":[{"price":0.66384,"qty":0.00000000},{"price":0.66358,"qty":3003.00000000}],"asks":[],"checksum":1821077548,"timestamp":"2024-06-01T18:05:59.276219Z"}]}
{"channel":"book","type":"update","data":[{"symbol":"AUD/USD","bids":[{"price":0.66376,"qty":0.00000000},{"price":0.66352,"qty":2804.00000000}],"asks":[],"checksum":2225004370,"timestamp":"2024-06-01T18:05:59.276332Z"}]}
{"channel":"book","type":"update","data":[{"symbol":"AUD/USD","bids":[{"price":0.66386,"qty":7841.91467297}],"asks":[],"checksum":4276485943,"timestamp":"2024-06-01T18:05:59.281821Z"}]}
{"channel":"book","type":"update","data":[{"symbol":"AUD/USD","bids":[{"price":0.66376,"qty":21598.20146750}],"asks":[],"checksum":2816494500,"timestamp":"2024-06-01T18:05:59.281947Z"}]}
{"channel":"book","type":"update","data":[{"symbol":"AUD/USD","bids":[{"price":0.66385,"qty":0.00000000},{"price":0.66352,"qty":2804.00000000}],"asks":[],"checksum":1140075048,"timestamp":"2024-06-01T18:05:59.291940Z"}]}
{"channel":"book","type":"update","data":[{"symbol":"AUD/USD","bids":[{"price":0.66387,"qty":1030.65630319}],"asks":[],"checksum":3328430437,"timestamp":"2024-06-01T18:05:59.292316Z"}]}
{"channel":"book","type":"update","data":[{"symbol":"AUD/USD","bids":[],"asks":[{"price":0.66525,"qty":59.38977258}],"checksum":22076362,"timestamp":"2024-06-01T18:05:59.868493Z"}]}
{"channel":"book","type":"update","data":[{"symbol":"AUD/USD","bids":[],"asks":[{"price":0.66523,"qty":5939.02189271}],"checksum":3984388633,"timestamp":"2024-06-01T18:05:59.869186Z"}]}
{"channel":"book","type":"update","data":[{"symbol":"AUD/USD","bids":[],"asks":[{"price":0.66524,"qty":0.00000000},{"price":0.66567,"qty":3013.00000000}],"checksum":79964268,"timestamp":"2024-06-01T18:05:59.875861Z"}]}
{"channel":"book","type":"update","data":[{"symbol":"AUD/USD","bids":[],"asks":[{"price":0.66522,"qty":4258.83710000}],"checksum":3487130606,"timestamp":"2024-06-01T18:05:59.875874Z"}]}
{"channel":"book","type":"update","data":[{"symbol":"AUD/USD","bids":[],"asks":[{"price":0.66557,"qty":0.00000000},{"price":0.66567,"qty":3013.00000000}],"checksum":2531635271,"timestamp":"2024-06-01T18:06:01.421128Z"}]}
{"channel":"book","type":"update","data":[{"symbol":"AUD/USD","bids":[],"asks":[{"price":0.66525,"qty":0.00000000},{"price":0.66573,"qty":4434.00000000}],"checksum":1327087890,"timestamp":"2024-06-01T18:06:01.421215Z"}]}
{"channel":"book","type":"update","data":[{"symbol":"AUD/USD","bids":[],"asks":[{"price":0.66521,"qty":235.35729451}],"checksum":1851385066,"timestamp":"2024-06-01T18:06:01.421926Z"}]}
{"channel":"book","type":"update","data":[{"symbol":"AUD/USD","bids":[{"price":0.66376,"qty":0.00000000},{"price":0.66352,"qty":2804.00000000}],"asks":[],"checksum":1265252164,"timestamp":"2024-06-01T18:06:02.822917Z"}]}
{"channel":"book","type":"update","data":[{"symbol":"AUD/USD","bids":[{"price":0.66386,"qty":513.95633058}],"asks":[],"checksum":1375815233,"timestamp":"2024-06-01T18:06:02.822970Z"}]}
{"channel":"book","type":"update","data":[{"symbol":"AUD/USD","bids":[{"price":0.66388,"qty":5167.08308077}],"asks":[],"checksum":1085445235,"timestamp":"2024-06-01T18:06:02.828687Z"}]}
{"channel":"book","type":"update","data":[{"symbol":"AUD/USD","bids":[{"price":0.66376,"qty":23763.82474606}],"asks":[],"checksum":2319613762,"timestamp":"2024-06-01T18:06:02.828928Z"}]}
{"channel":"book","type":"update","data":[{"symbol":"AUD/USD","bids":[{"price":0.66387,"qty":0.00000000},{"price":0.66358,"qty":3003.00000000}],"asks":[],"checksum":3834582416,"timestamp":"2024-06-01T18:06:02.832398Z"}]}
{"channel":"book","type":"update","data":[{"symbol":"AUD/USD","bids":[{"price":0.66389,"qty":1030.62525418}],"asks":[],"checksum":3271825742,"timestamp":"2024-06-01T18:06:02.832417Z"}]}
{"channel":"book","type":"update","data":[{"symbol":"AUD/USD","bids":[],"asks":[{"price":0.66523,"qty":0.00000000},{"price":0.66573,"qty":4434.00000000}],"checksum":3687206604,"timestamp":"2024-06-01T18:06:02.862205Z"}]}
{"channel":"book","type":"update","data":[{"symbol":"AUD/USD","bids":[],"asks":[{"price":0.66560,"qty":0.00000000},{"price":0.66583,"qty":5032.00000000}],"checksum":3896099729,"timestamp":"2024-06-01T18:06:02.862774Z"}]}
{"channel":"book","type":"update","data":[{"symbol":"AUD/USD","bids":[],"asks":[{"price":0.66560,"qty":35267.16262833}],"checksum":832315101,"timestamp":"2024-06-01T18:06:02.862838Z"}]}
{"channel":"book","type":"update","data":[{"symbol":"AUD/USD","bids":[{"price":0.66386,"qty":0.00000000},{"price":0.66358,"qty":3003.00000000}],"asks":[],"checksum":2650322204,"timestamp":"2024-06-01T18:06:03.047173Z"}]}
{"channel":"book","type":"update","data":[{"symbol":"AUD/USD","bids":[{"price":0.66388,"qty":5681.03941135}],"asks":[],"checksum":1000343595,"timestamp":"2024-06-01T18:06:03.056797Z"}]}
{"channel":"book","type":"update","data":[{"symbol":"AUD/USD","bids":[],"asks":[{"price":0.66521,"qty":0.00000000},{"price":0.66583,"qty":5032.00000000}],"checksum":3778144573,"timestamp":"2024-06-01T18:06:06.254808Z"}]}
{"channel":"book","type":"update","data":[{"symbol":"AUD/USD","bids":[],"asks":[{"price":0.66559,"qty":294.01313515}],"checksum":3788943665,"timestamp":"2024-06-01T18:06:06.255496Z"}]}
{"channel":"book","type":"update","data":[{"symbol":"AUD/USD","bids":[{"price":0.66376,"qty":0.00000000},{"price":0.66352,"qty":2804.00000000}],"asks":[],"checksum":866161216,"timestamp":"2024-06-01T18:06:06.385175Z"}]}
{"channel":"book","type":"update","data":[{"symbol":"AUD/USD","bids":[{"price":0.66388,"qty":513.95633058}],"asks":[],"checksum":2078500589,"timestamp":"2024-06-01T18:06:06.385216Z"}]}
{"channel":"book","type":"update","data":[{"symbol":"AUD/USD","bids":[{"price":0.66376,"qty":28936.71095863}],"asks":[],"checksum":388546178,"timestamp":"2024-06-01T18:06:06.395018Z"}]}
{"channel":"book","type":"update","data":[{"symbol":"AUD/USD","bids":[{"price":0.66388,"qty":0.00000000},{"price":0.66352,"qty":2804.00000000}],"asks":[],"checksum":222547702,"timestamp":"2024-06-01T18:06:06.967295Z"}]}
{"channel":"book","type":"update","data":[{"symbol":"AUD/USD","bids":[{"price":0.66377,"qty":1030.81157853}],"asks":[],"checksum":2121854968,"timestamp":"2024-06-01T18:06:06.973912Z"}]}
{"channel":"book","type":"update","data":[{"symbol":"AUD/USD","bids":[{"price":0.66389,"qty":0.00000000},{"price":0.66352,"qty":2804.00000000}],"asks":[],"checksum":2103034038,"timestamp":"2024-06-01T18:06:06.973972Z"}]}
{"channel":"book","type":"update","data":[{"symbol":"AUD/USD","bids":[{"price":0.66390,"qty":513.95633058}],"asks":[],"checksum":98240320,"timestamp":"2024-06-01T18:06:06.976224Z"}]}
{"channel":"book","type":"update","data":[{"symbol":"AUD/USD","bids":[],"asks":[{"price":0.66560,"qty":0.00000000},{"price":0.66583,"qty":5032.00000000}],"checksum":2809806520,"timestamp":"2024-06-01T18:06:08.935230Z"}]}
{"channel":"book","type":"update","data":[{"symbol":"AUD/USD","bids":[],"asks":[{"price":0.66558,"qty":5939.02189271}],"checksum":4146541791,"timestamp":"2024-06-01T18:06:08.936305Z"}]}
{"channel":"book","type":"update","data":[{"symbol":"AUD/USD","bids":[],"asks":[{"price":0.66560,"qty":29299.49997318}],"checksum":3955023482,"timestamp":"2024-06-01T18:06:08.936567Z"}]}
{"channel":"book","type":"update","data":[{"symbol":"AUD/USD","bids":[{"price":0.66378,"qty":126.92998508}],"asks":[],"checksum":1512501313,"timestamp":"2024-06-01T18:06:09.100988Z"}]}
{"channel":"book","type":"update","data":[{"symbol":"AUD/USD","bids":[{"price":0.66376,"qty":0.00000000},{"price":0.66358,"qty":3003.00000000}],"asks":[],"checksum":1919197925,"timestamp":"2024-06-01T18:06:10.006603Z"}]}
{"channel":"book","type":"update","data":[{"symbol":"AUD/USD","bids":[{"price":0.66379,"qty":7327.95834239}],"asks":[],"checksum":632549094,"timestamp":"2024-06-01T18:06:10.011878Z"}]}
{"channel":"book","type":"update","data":[{"symbol":"AUD/USD","bids":[{"price":0.66378,"qty":21725.13145258}],"asks":[],"checksum":2478072054,"timestamp":"2024-06-01T18:06:10.012041Z"}]}
{"channel":"book","type":"update","data":[{"symbol":"AUD/USD","bids":[{"price":0.66377,"qty":0.00000000},{"price":0.66358,"qty":3003.00000000}],"asks":[],"checksum":4128230437,"timestamp":"2024-06-01T18:06:10.030105Z"}]}
{"channel":"book","type":"update","data":[{"symbol":"AUD/USD","bids":[{"price":0.66391,"qty":1030.59428772}],"asks":[],"checksum":4160037641,"timestamp":"2024-06-01T18:06:10.030389Z"}]}
{"channel":"book","type":"update","data":[{"symbol":"AUD/USD","bids":[{"price":0.66390,"qty":0.00000000},{"price":0.66358,"qty":3003.00000000}],"asks":[],"checksum":2087307957,"timestamp":"2024-06-01T18:06:10.140731Z"}]}
{"channel":"book","type":"update","data":[{"symbol":"AUD/USD","bids":[{"price":0.66379,"qty":7411.78624780}],"asks":[],"checksum":554249696,"timestamp":"2024-06-01T18:06:10.149852Z"}]}
{"channel":"book","type":"update","data":[{"symbol":"AUD/USD","bids":[{"price":0.66378,"qty":22155.04985411}],"asks":[],"checksum":497806491,"timestamp":"2024-06-01T18:06:10.149922Z"}]}
{"channel":"book","type":"update","data":[{"symbol":"AUD/USD","bids":[{"price":0.66380,"qty":1030.76510350}],"asks":[],"checksum":143137109,"timestamp":"2024-06-01T18:06:10.154574Z"}]}
{"channel":"book","type":"update","data":[{"symbol":"AUD/USD","bids":[{"price":0.66391,"qty":0.00000000},{"price":0.66358,"qty":3003.00000000}],"asks":[],"checksum":1499473143,"timestamp":"2024-06-01T18:06:10.154738Z"}]}
{"channel":"book","type":"update","data":[{"symbol":"AUD/USD","bids":[],"asks":[{"price":0.66559,"qty":0.00000000},{"price":0.66573,"qty":4434.00000000}],"checksum":1978212120,"timestamp":"2024-06-01T18:06:10.364174Z"}]}
{"channel":"book","type":"update","data":[{"symbol":"AUD/USD","bids":[],"asks":[{"price":0.66557,"qty":294.01313515}],"checksum":3697191723,"timestamp":"2024-06-01T18:06:10.364410Z"}]}
{"channel":"book","type":"update","data":[{"symbol":"AUD/USD","bids":[{"price":0.66378,"qty":22028.11986903}],"asks":[],"checksum":755060274,"timestamp":"2024-06-01T18:06:10.491465Z"}]}
{"channel":"book","type":"update","data":[{"symbol":"AUD/USD","bids":[],"asks":[{"price":0.66560,"qty":0.00000000},{"price":0.66573,"qty":4434.00000000}],"checksum":1428162865,"timestamp":"2024-06-01T18:06:11.940129Z"}]}
{"channel":"book","type":"update","data":[{"symbol":"AUD/USD","bids":[],"asks":[{"price":0.66558,"qty":0.00000000},{"price":0.66583,"qty":5032.00000000}],"checksum":1028210535,"timestamp":"2024-06-01T18:06:11.940166Z"}]}
{"channel":"book","type":"update","data":[{"symbol":"AUD/USD","bids":[],"asks":[{"price":0.66560,"qty":32334.34855477}],"checksum":236361263,"timestamp":"2024-06-01T18:06:11.940904Z"}]}
{"channel":"book","type":"update","data":[{"symbol":"AUD/USD","bids":[{"price":0.66379,"qty":7327.95834239}],"asks":[],"checksum":1400271226,"timestamp":"2024-06-01T18:06:12.855684Z"}]}
{"channel":"book","type":"update","data":[{"symbol":"AUD/USD","bids":[{"price":0.66378,"qty":21598.20146750}],"asks":[],"checksum":3160651014,"timestamp":"2024-06-01T18:06:12.855800Z"}]}
{"channel":"book","type":"update","data":[{"symbol":"AUD/USD","bids":[{"price":0.66381,"qty":509.16586587}],"asks":[],"checksum":2708030927,"timestamp":"2024-06-01T18:06:12.861686Z"}]}
{"channel":"book","type":"update","data":[{"symbol":"AUD/USD","bids":[],"asks":[{"price":0.66557,"qty":0.00000000},{"price":0.66583,"qty":5032.00000000}],"checksum":810407003,"timestamp":"2024-06-01T18:06:13.564620Z"}]}
{"channel":"book","type":"update","data":[{"symbol":"AUD/USD","bids":[],"asks":[{"price":0.66559,"qty":294.01313515}],"checksum":1094311482,"timestamp":"2024-06-01T18:06:13.566088Z"}]}
{"channel":"book","type":"update","data":[{"symbol":"AUD/USD","bids":[{"price":0.66379,"qty":0.00000000},{"price":0.66358,"qty":3003.00000000}],"asks":[],"checksum":3869132624,"timestamp":"2024-06-01T18:06:13.600475Z"}]}
{"channel":"book","type":"update","data":[{"symbol":"AUD/USD","bids":[{"price":0.66378,"qty":0.00000000},{"price":0.66352,"qty":2804.00000000}],"asks":[],"checksum":3377062308,"timestamp":"2024-06-01T18:06:13.600488Z"}]}
{"channel":"book","type":"update","data":[{"symbol":"AUD/USD","bids":[{"price":0.66382,"qty":24614.96043578}],"asks":[],"checksum":1880493251,"timestamp":"2024-06-01T18:06:13.606457Z"}]}
{"channel":"book","type":"update","data":[{"symbol":"AUD/USD","bids":[{"price":0.66380,"qty":0.00000000},{"price":0.66352,"qty":2804.00000000}],"asks":[],"checksum":1901409125,"timestamp":"2024-06-01T18:06:13.617596Z"}]}
{"channel":"book","type":"update","data":[{"symbol":"AUD/USD","bids":[{"price":0.66383,"qty":1030.71848620}],"asks":[],"checksum":525690451,"timestamp":"2024-06-01T18:06:13.618389Z"}]}
{"channel":"book","type":"update","data":[{"symbol":"AUD/USD","bids":[],"asks":[{"price":0.66560,"qty":0.00000000},{"price":0.66583,"qty":5032.00000000}],"checksum":650361793,"timestamp":"2024-06-01T18:06:14.957059Z"}]}
{"channel":"book","type":"update","data":[{"symbol":"AUD/USD","bids":[],"asks":[{"price":0.66560,"qty":29299.49997318}],"checksum":1849217576,"timestamp":"2024-06-01T18:06:14.958055Z"}]}
{"channel":"book","type":"update","data":[{"symbol":"AUD/USD","bids":[],"asks":[{"price":0.66558,"qty":5939.02189271}],"checksum":1778735875,"timestamp":"2024-06-01T18:06:14.958122Z"}]}
{"channel":"book","type":"update","data":[{"symbol":"AUD/USD","bids":[{"price":0.66381,"qty":0.00000000},{"price":0.66352,"qty":2804.00000000}],"asks":[],"checksum":1562695895,"timestamp":"2024-06-01T18:06:15.761947Z"}]}
{"channel":"book","type":"update","data":[{"symbol":"AUD/USD","bids":[{"price":0.66384,"qty":513.06629079}],"asks":[],"checksum":3274715946,"timestamp":"2024-06-01T18:06:15.771890Z"}]}
{"channel":"book","type":"update","data":[{"symbol":"AUD/USD","bids":[],"asks":[{"price":0.66559,"qty":0.00000000},{"price":0.66573,"qty":4434.00000000}],"checksum":2476038036,"timestamp":"2024-06-01T18:06:16.764559Z"}]}
{"channel":"book","type":"update","data":[{"symbol":"AUD/USD","bids":[],"asks":[{"price":0.66557,"qty":294.01313515}],"checksum":2559522680,"timestamp":"2024-06-01T18:06:16.765329Z"}]}
{"channel":"book","type":"update","data":[{"symbol":"AUD/USD","bids":[{"price":0.66382,"qty":0.00000000},{"price":0.66352,"qty":2804.00000000}],"asks":[],"checksum":2017308498,"timestamp":"2024-06-01T18:06:17.294129Z"}]}
{"channel":"book","type":"update","data":[{"symbol":"AUD/USD","bids":[{"price":0.66385,"qty":7327.95834247}],"asks":[],"checksum":1160431510,"timestamp":"2024-06-01T18:06:17.299229Z"}]}
{"channel":"book","type":"update","data":[{"symbol":"AUD/USD","bids":[{"price":0.66376,"qty":17278.56117432}],"asks":[],"checksum":2739692919,"timestamp":"2024-06-01T18:06:17.299325Z"}]}
{"channel":"book","type":"update","data":[{"symbol":"AUD/USD","bids":[{"price":0.66383,"qty":0.00000000},{"price":0.66358,"qty":3003.00000000}],"asks":[],"checksum":4178497793,"timestamp":"2024-06-01T18:06:17.309748Z"}]}
{"channel":"book","type":"update","data":[{"symbol":"AUD/USD","bids":[{"price":0.66386,"qty":1030.67182839}],"asks":[],"checksum":3829653661,"timestamp":"2024-06-01T18:06:17.309777Z"}]}
{"channel":"book","type":"update","data":[{"symbol":"AUD/USD","bids":[],"asks":[{"price":0.66472,"qty":298.14569990}],"checksum":3952392375,"timestamp":"2024-06-01T18:06:17.467397Z"}]}
{"channel":"book","type":"update","data":[{"symbol":"AUD/USD","bids":[],"asks":[{"price":0.66473,"qty":0.00000000},{"price":0.66567,"qty":3013.00000000},{"price":0.66471,"qty":5596.04351255}],"checksum":1457855259,"timestamp":"2024-06-01T18:06:17.470532Z"}]}
{"channel":"book","type":"update","data":[{"symbol":"AUD/USD","bids":[],"asks":[{"price":0.66471,"qty":0.00000000},{"price":0.66567,"qty":3013.00000000},{"price":0.66470,"qty":5596.04351255}],"checksum":549625100,"timestamp":"2024-06-01T18:06:17.473791Z"}]}
{"channel":"book","type":"update","data":[{"symbol":"AUD/USD","bids":[],"asks":[{"price":0.66470,"qty":0.00000000},{"price":0.66567,"qty":3013.00000000},{"price":0.66471,"qty":5596.04351255}],"checksum":1457855259,"timestamp":"2024-06-01T18:06:17.478593Z"}]}
{"channel":"book","type":"update","data":[{"symbol":"AUD/USD","bids":[],"asks":[{"price":0.66474,"qty":0.00000000},{"price":0.66567,"qty":3013.00000000},{"price":0.66470,"qty":5436.00000000}],"checksum":1298345948,"timestamp":"2024-06-01T18:06:17.503842Z"}]}
{"channel":"book","type":"update","data":[{"symbol":"AUD/USD","bids":[],"asks":[{"price":0.66471,"qty":0.00000000},{"price":0.66567,"qty":3013.00000000},{"price":0.66469,"qty":5596.04351255}],"checksum":944547378,"timestamp":"2024-06-01T18:06:17.507591Z"}]}
{"channel":"book","type":"update","data":[{"symbol":"AUD/USD","bids":[],"asks":[{"price":0.66469,"qty":0.00000000},{"price":0.66567,"qty":3013.00000000},{"price":0.66468,"qty":5596.04351255}],"checksum":1315643429,"timestamp":"2024-06-01T18:06:17.510776Z"}]}
{"channel":"book","type":"update","data":[{"symbol":"AUD/USD","bids":[],"asks":[{"price":0.66468,"qty":0.00000000},{"price":0.66567,"qty":3013.00000000},{"price":0.66467,"qty":5596.04351255}],"checksum":3492972603,"timestamp":"2024-06-01T18:06:17.514831Z"}]}
{"channel":"book","type":"update","data":[{"symbol":"AUD/USD","bids":[],"asks":[{"price":0.66467,"qty":0.00000000},{"price":0.66567,"qty":3013.00000000},{"price":0.66466,"qty":5596.04351255}],"checksum":2786397740,"timestamp":"2024-06-01T18:06:17.518072Z"}]}
{"channel":"book","type":"update","data":[{"symbol":"AUD/USD","bids":[],"asks":[{"price":0.66466,"qty":0.00000000},{"price":0.66567,"qty":3013.00000000},{"price":0.66465,"qty":5596.04351255}],"checksum":1014858773,"timestamp":"2024-06-01T18:06:17.521900Z"}]}
{"channel":"book","type":"update","data":[{"symbol":"AUD/USD","bids":[],"asks":[{"price":0.66465,"qty":0.00000000},{"price":0.66567,"qty":3013.00000000},{"price":0.66464,"qty":5596.04351255}],"checksum":1247412738,"timestamp":"2024-06-01T18:06:17.525876Z"}]}
{"channel":"book","type":"update","data":[{"symbol":"AUD/USD","bids":[],"asks":[{"price":0.66464,"qty":0.00000000},{"price":0.66567,"qty":3013.00000000},{"price":0.66463,"qty":5596.04429510}],"checksum":608206920,"timestamp":"2024-06-01T18:06:17.529962Z"}]}
{"channel":"book","type":"update","data":[{"symbol":"AUD/USD","bids":[],"asks":[{"price":0.66463,"qty":0.00000000},{"price":0.66567,"qty":3013.00000000},{"price":0.66469,"qty":5596.04429510}],"checksum":3486625884,"timestamp":"2024-06-01T18:06:17.533816Z"}]}
{"channel":"book","type":"update","data":[{"symbol":"AUD/USD","bids":[],"asks":[{"price":0.66470,"qty":0.00000000},{"price":0.66567,"qty":3013.00000000},{"price":0.66468,"qty":5436.00000000}],"checksum":1985911338,"timestamp":"2024-06-01T18:06:17.567428Z"}]}
{"channel":"book","type":"update","data":[{"symbol":"AUD/USD","bids":[],"asks":[{"price":0.66469,"qty":0.00000000},{"price":0.66567,"qty":3013.00000000},{"price":0.66468,"qty":11032.04429510}],"checksum":411369466,"timestamp":"2024-06-01T18:06:17.567607Z"}]}
{"channel":"book","type":"update","data":[{"symbol":"AUD/USD","bids":[],"asks":[{"price":0.66468,"qty":5596.04429510},{"price":0.66467,"qty":5436.00000000}],"checksum":2824522812,"timestamp":"2024-06-01T18:06:17.599013Z"}]}
{"channel":"book","type":"update","data":[{"symbol":"AUD/USD","bids":[],"asks":[{"price":0.66476,"qty":0.00000000},{"price":0.66567,"qty":3013.00000000}],"checksum":1194840767,"timestamp":"2024-06-01T18:06:17.630877Z"}]}
{"channel":"book","type":"update","data":[{"symbol":"AUD/USD","bids":[],"asks":[{"price":0.66468,"qty":0.00000000},{"price":0.66573,"qty":4434.00000000},{"price":0.66466,"qty":5596.04429510}],"checksum":1265393786,"timestamp":"2024-06-01T18:06:17.635251Z"}]}
{"channel":"book","type":"update","data":[{"symbol":"AUD/USD","bids":[],"asks":[{"price":0.66467,"qty":0.00000000},{"price":0.66573,"qty":4434.00000000},{"price":0.66521,"qty":5436.00000000}],"checksum":2774046090,"timestamp":"2024-06-01T18:06:17.663624Z"}]}
{"channel":"book","type":"update","data":[{"symbol":"AUD/USD","bids":[],"asks":[{"price":0.66466,"qty":0.00000000},{"price":0.66573,"qty":4434.00000000},{"price":0.66520,"qty":5596.04429510}],"checksum":1007858364,"timestamp":"2024-06-01T18:06:17.666844Z"}]}
{"channel":"book","type":"update","data":[{"symbol":"AUD/USD","bids":[],"asks":[{"price":0.66522,"qty":0.00000000},{"price":0.66573,"qty":4434.00000000}],"checksum":4150436320,"timestamp":"2024-06-01T18:06:17.676909Z"}]}
{"channel":"book","type":"update","data":[{"symbol":"AUD/USD","bids":[],"asks":[{"price":0.66519,"qty":4258.83710000}],"checksum":2764966859,"timestamp":"2024-06-01T18:06:17.677128Z"}]}
{"channel":"book","type":"update","data":[{"symbol":"AUD/USD","bids":[],"asks":[{"price":0.66521,"qty":0.00000000},{"price":0.66573,"qty":4434.00000000},{"price":0.66518,"qty":5436.00000000}],"checksum":2122080852,"timestamp":"2024-06-01T18:06:17.693868Z"}]}
{"channel":"book","type":"update","data":[{"symbol":"AUD/USD","bids":[],"asks":[{"price":0.66519,"qty":0.00000000},{"price":0.66573,"qty":4434.00000000}],"checksum":2998794040,"timestamp":"2024-06-01T18:06:17.710586Z"}]}
{"channel":"book","type":"update","data":[{"symbol":"AUD/USD","bids":[],"asks":[{"price":0.66517,"qty":4258.83710000}],"checksum":2745635313,"timestamp":"2024-06-01T18:06:17.710813Z"}]}
{"channel":"book","type":"update","data":[{"symbol":"AUD/USD","bids":[],"asks":[{"price":0.66518,"qty":0.00000000},{"price":0.66573,"qty":4434.00000000},{"price":0.66516,"qty":5436.00000000}],"checksum":180558765,"timestamp":"2024-06-01T18:06:17.725968Z"}]}
{"channel":"book","type":"update","data":[{"symbol":"AUD/USD","bids":[],"asks":[{"price":0.66515,"qty":4258.83710000}],"checksum":3115596411,"timestamp":"2024-06-01T18:06:17.730658Z"}]}
{"channel":"book","type":"update","data":[{"symbol":"AUD/USD","bids":[],"asks":[{"price":0.66517,"qty":0.00000000},{"price":0.66567,"qty":3013.00000000}],"checksum":3158149125,"timestamp":"2024-06-01T18:06:17.730768Z"}]}
{"channel":"book","type":"update","data":[{"symbol":"AUD/USD","bids":[],"asks":[{"price":0.66520,"qty":0.00000000},{"price":0.66573,"qty":4434.00000000},{"price":0.66514,"qty":5596.04482471}],"checksum":2394057739,"timestamp":"2024-06-01T18:06:17.736403Z"}]}
{"channel":"book","type":"update","data":[{"symbol":"AUD/USD","bids":[],"asks":[{"price":0.66515,"qty":0.00000000},{"price":0.66573,"qty":4434.00000000}],"checksum":3251327494,"timestamp":"2024-06-01T18:06:17.756194Z"}]}
{"channel":"book","type":"update","data":[{"symbol":"AUD/USD","bids":[],"asks":[{"price":0.66513,"qty":4258.83710000}],"checksum":3925075471,"timestamp":"2024-06-01T18:06:17.756500Z"}]}
{"channel":"book","type":"update","data":[{"symbol":"AUD/USD","bids":[],"asks":[{"price":0.66516,"qty":0.00000000},{"price":0.66573,"qty":4434.00000000},{"price":0.66513,"qty":9694.83710000}],"checksum":2684691913,"timestamp":"2024-06-01T18:06:17.757353Z"}]}
{"channel":"book","type":"update","data":[{"symbol":"AUD/USD","bids":[],"asks":[{"price":0.66514,"qty":0.00000000},{"price":0.66583,"qty":5032.00000000},{"price":0.66515,"qty":5596.04482471}],"checksum":2461357813,"timestamp":"2024-06-01T18:06:17.760209Z"}]}
{"channel":"book","type":"update","data":[{"symbol":"AUD/USD","bids":[],"asks":[{"price":0.66513,"qty":4258.83710000},{"price":0.66512,"qty":5436.00000000}],"checksum":3173430705,"timestamp":"2024-06-01T18:06:17.789064Z"}]}
{"channel":"book","type":"update","data":[{"symbol":"AUD/USD","bids":[],"asks":[{"price":0.66513,"qty":0.00000000},{"price":0.66573,"qty":4434.00000000}],"checksum":3110990387,"timestamp":"2024-06-01T18:06:17.793998Z"}]}
{"channel":"book","type":"update","data":[{"symbol":"AUD/USD","bids":[],"asks":[{"price":0.66511,"qty":4258.83710000}],"checksum":198714905,"timestamp":"2024-06-01T18:06:17.794236Z"}]}
{"channel":"book","type":"update","data":[{"symbol":"AUD/USD","bids":[],"asks":[{"price":0.66512,"qty":0.00000000},{"price":0.66573,"qty":4434.00000000},{"price":0.66510,"qty":5436.00000000}],"checksum":646938388,"timestamp":"2024-06-01T18:06:17.820936Z"}]}
{"channel":"book","type":"update","data":[{"symbol":"AUD/USD","bids":[],"asks":[{"price":0.66511,"qty":0.00000000},{"price":0.66573,"qty":4434.00000000}],"checksum":1201987310,"timestamp":"2024-06-01T18:06:17.853237Z"}]}
{"channel":"book","type":"update","data":[{"symbol":"AUD/USD","bids":[],"asks":[{"price":0.66509,"qty":4258.83710000}],"checksum":2995310357,"timestamp":"2024-06-01T18:06:17.853323Z"}]}
{"channel":"book","type":"update","data":[{"symbol":"AUD/USD","bids":[],"asks":[{"price":0.66510,"qty":0.00000000},{"price":0.66573,"qty":4434.00000000},{"price":0.66508,"qty":5436.00000000}],"checksum":2601526069,"timestamp":"2024-06-01T18:06:17.884468Z"}]}
{"channel":"book","type":"update","data":[{"symbol":"AUD/USD","bids":[],"asks":[{"price":0.66509,"qty":0.00000000},{"price":0.66573,"qty":4434.00000000}],"checksum":2610221466,"timestamp":"2024-06-01T18:06:17.894991Z"}]}
{"channel":"book","type":"update","data":[{"symbol":"AUD/USD","bids":[],"asks":[{"price":0.66507,"qty":4258.83710000}],"checksum":1187729552,"timestamp":"2024-06-01T18:06:17.895002Z"}]}
{"channel":"book","type":"update","data":[{"symbol":"AUD/USD","bids":[],"asks":[{"price":0.66515,"qty":0.00000000},{"price":0.66573,"qty":4434.00000000},{"price":0.66506,"qty":5596.04482471}],"checksum":2259779473,"timestamp":"2024-06-01T18:06:17.904296Z"}]}
{"channel":"book","type":"update","data":[{"symbol":"AUD/USD","bids":[],"asks":[{"price":0.66507,"qty":0.00000000},{"price":0.66573,"qty":4434.00000000}],"checksum":1627043716,"timestamp":"2024-06-01T18:06:17.913364Z"}]}
{"channel":"book","type":"update","data":[{"symbol":"AUD/USD","bids":[],"asks":[{"price":0.66505,"qty":4258.83710000}],"checksum":3339954798,"timestamp":"2024-06-01T18:06:17.913488Z"}]}
{"channel":"book","type":"update","data":[{"symbol":"AUD/USD","bids":[],"asks":[{"price":0.66506,"qty":0.00000000},{"price":0.66573,"qty":4434.00000000},{"price":0.66507,"qty":5596.04482471}],"checksum":4121155922,"timestamp":"2024-06-01T18:06:17.916233Z"}]}
{"channel":"book","type":"update","data":[{"symbol":"AUD/USD","bids":[],"asks":[{"price":0.66508,"qty":0.00000000},{"price":0.66573,"qty":4434.00000000},{"price":0.66505,"qty":9694.83710000}],"checksum":2438250461,"timestamp":"2024-06-01T18:06:17.916379Z"}]}
{"channel":"book","type":"update","data":[{"symbol":"AUD/USD","bids":[],"asks":[{"price":0.66505,"qty":4258.83710000},{"price":0.66504,"qty":5436.00000000}],"checksum":2534765933,"timestamp":"2024-06-01T18:06:17.948893Z"}]}
{"channel":"book","type":"update","data":[{"symbol":"AUD/USD","bids":[],"asks":[{"price":0.66503,"qty":4258.83710000}],"checksum":155617883,"timestamp":"2024-06-01T18:06:17.969782Z"}]}
{"channel":"book","type":"update","data":[{"symbol":"AUD/USD","bids":[],"asks":[{"price":0.66505,"qty":0.00000000},{"price":0.66567,"qty":3013.00000000}],"checksum":118012222,"timestamp":"2024-06-01T18:06:17.969971Z"}]}
{"channel":"book","type":"update","data":[{"symbol":"AUD/USD","bids":[],"asks":[{"price":0.66560,"qty":0.00000000},{"price":0.66573,"qty":4434.00000000}],"checksum":3936350301,"timestamp":"2024-06-01T18:06:17.980249Z"}]}
{"channel":"book","type":"update","data":[{"symbol":"AUD/USD","bids":[],"asks":[{"price":0.66558,"qty":0.00000000},{"price":0.66583,"qty":5032.00000000}],"checksum":1578786447,"timestamp":"2024-06-01T18:06:17.980598Z"}]}
{"channel":"book","type":"update","data":[{"symbol":"AUD/USD","bids":[],"asks":[{"price":0.66512,"qty":35267.16262833}],"checksum":536081195,"timestamp":"2024-06-01T18:06:17.980668Z"}]}
{"channel":"book","type":"update","data":[{"symbol":"AUD/USD","bids":[],"asks":[{"price":0.66504,"qty":0.00000000},{"price":0.66583,"qty":5032.00000000},{"price":0.66502,"qty":5436.00000000}],"checksum":4167395030,"timestamp":"2024-06-01T18:06:17.980900Z"}]}
{"channel":"book","type":"update","data":[{"symbol":"AUD/USD","bids":[],"asks":[{"price":0.66503,"qty":0.00000000},{"price":0.66583,"qty":5032.00000000}],"checksum":568375672,"timestamp":"2024-06-01T18:06:17.996393Z"}]}
{"channel":"book","type":"update","data":[{"symbol":"AUD/USD","bids":[],"asks":[{"price":0.66501,"qty":4258.83710000}],"checksum":1318843774,"timestamp":"2024-06-01T18:06:17.996451Z"}]}
{"channel":"book","type":"update","data":[{"symbol":"AUD/USD","bids":[],"asks":[{"price":0.66502,"qty":0.00000000},{"price":0.66583,"qty":5032.00000000},{"price":0.66500,"qty":5436.00000000}],"checksum":1674357875,"timestamp":"2024-06-01T18:06:18.012534Z"}]}
{"channel":"book","type":"update","data":[{"symbol":"AUD/USD","bids":[],"asks":[{"price":0.66499,"qty":4258.83710000}],"checksum":1177893565,"timestamp":"2024-06-01T18:06:18.031532Z"}]}
{"channel":"book","type":"update","data":[{"symbol":"AUD/USD","bids":[],"asks":[{"price":0.66501,"qty":0.00000000},{"price":0.66573,"qty":4434.00000000}],"checksum":2692716888,"timestamp":"2024-06-01T18:06:18.031898Z"}]}
{"channel":"book","type":"update","data":[{"symbol":"AUD/USD","bids":[],"asks":[{"price":0.66500,"qty":0.00000000},{"price":0.66583,"qty":5032.00000000},{"price":0.66498,"qty":5436.00000000}],"checksum":2458353488,"timestamp":"2024-06-01T18:06:18.044695Z"}]}
{"channel":"book","type":"update","data":[{"symbol":"AUD/USD","bids":[],"asks":[{"price":0.66499,"qty":0.00000000},{"price":0.66583,"qty":5032.00000000}],"checksum":1420632059,"timestamp":"2024-06-01T18:06:18.065649Z"}]}
{"channel":"book","type":"update","data":[{"symbol":"AUD/USD","bids":[],"asks":[{"price":0.66497,"qty":4258.83710000}],"checksum":1331432693,"timestamp":"2024-06-01T18:06:18.065735Z"}]}
{"channel":"book","type":"update","data":[{"symbol":"AUD/USD","bids":[],"asks":[{"price":0.66498,"qty":0.00000000},{"price":0.66583,"qty":5032.00000000},{"price":0.66496,"qty":5436.00000000}],"checksum":3862431401,"timestamp":"2024-06-01T18:06:18.076841Z"}]}
{"channel":"book","type":"update","data":[{"symbol":"AUD/USD","bids":[],"asks":[{"price":0.66495,"qty":4258.83710000}],"checksum":4138401756,"timestamp":"2024-06-01T18:06:18.101075Z"}]}
{"channel":"book","type":"update","data":[{"symbol":"AUD/USD","bids":[],"asks":[{"price":0.66497,"qty":0.00000000},{"price":0.66573,"qty":4434.00000000}],"checksum":1355191553,"timestamp":"2024-06-01T18:06:18.101168Z"}]}
{"channel":"book","type":"update","data":[{"symbol":"AUD/USD","bids":[],"asks":[{"price":0.66496,"qty":0.00000000},{"price":0.66583,"qty":5032.00000000},{"price":0.66494,"qty":5436.00000000}],"checksum":2106706956,"timestamp":"2024-06-01T18:06:18.109342Z"}]}
{"channel":"book","type":"update","data":[{"symbol":"AUD/USD","bids":[],"asks":[{"price":0.66495,"qty":0.00000000},{"price":0.66583,"qty":5032.00000000}],"checksum":1065943030,"timestamp":"2024-06-01T18:06:18.130542Z"}]}
{"channel":"book","type":"update","data":[{"symbol":"AUD/USD","bids":[],"asks":[{"price":0.66493,"qty":4258.83710000}],"checksum":3985375327,"timestamp":"2024-06-01T18:06:18.130820Z"}]}
{"channel":"book","type":"update","data":[{"symbol":"AUD/USD","bids":[],"asks":[{"price":0.66507,"qty":0.00000000},{"price":0.66583,"qty":5032.00000000},{"price":0.66492,"qty":5596.04542394}],"checksum":4043081377,"timestamp":"2024-06-01T18:06:18.140171Z"}]}
{"channel":"book","type":"update","data":[{"symbol":"AUD/USD","bids":[],"asks":[{"price":0.66494,"qty":0.00000000},{"price":0.66583,"qty":5032.00000000},{"price":0.66492,"qty":11032.04542394}],"checksum":1903211450,"timestamp":"2024-06-01T18:06:18.141400Z"}]}
{"channel":"book","type":"update","data":[{"symbol":"AUD/USD","bids":[],"asks":[{"price":0.66493,"qty":0.00000000},{"price":0.66604,"qty":2955.00000000}],"checksum":4246682258,"timestamp":"2024-06-01T18:06:18.156068Z"}]}
{"channel":"book","type":"update","data":[{"symbol":"AUD/USD","bids":[],"asks":[{"price":0.66491,"qty":4258.83710000}],"checksum":4256540854,"timestamp":"2024-06-01T18:06:18.156152Z"}]}
{"channel":"book","type":"update","data":[{"symbol":"AUD/USD","bids":[],"asks":[{"price":0.66492,"qty":5596.04542394},{"price":0.66490,"qty":5436.00000000}],"checksum":260657695,"timestamp":"2024-06-01T18:06:18.173458Z"}]}
{"channel":"book","type":"update","data":[{"symbol":"AUD/USD","bids":[],"asks":[{"price":0.66489,"qty":4258.83710000}],"checksum":1453264805,"timestamp":"2024-06-01T18:06:18.182755Z"}]}
{"channel":"book","type":"update","data":[{"symbol":"AUD/USD","bids":[],"asks":[{"price":0.66491,"qty":0.00000000},{"price":0.66573,"qty":4434.00000000}],"checksum":2609832478,"timestamp":"2024-06-01T18:06:18.184720Z"}]}
{"channel":"book","type":"update","data":[{"symbol":"AUD/USD","bids":[],"asks":[{"price":0.66490,"qty":0.00000000},{"price":0.66583,"qty":5032.00000000},{"price":0.66488,"qty":5436.00000000}],"checksum":2987789886,"timestamp":"2024-06-01T18:06:18.206011Z"}]}
{"channel":"book","type":"update","data":[{"symbol":"AUD/USD","bids":[],"asks":[{"price":0.66487,"qty":4258.83710000}],"checksum":91002479,"timestamp":"2024-06-01T18:06:18.221307Z"}]}
{"channel":"book","type":"update","data":[{"symbol":"AUD/USD","bids":[],"asks":[{"price":0.66489,"qty":0.00000000},{"price":0.66573,"qty":4434.00000000}],"checksum":1875738011,"timestamp":"2024-06-01T18:06:18.221406Z"}]}
{"channel":"book","type":"update","data":[{"symbol":"AUD/USD","bids":[],"asks":[{"price":0.66488,"qty":0.00000000},{"price":0.66583,"qty":5032.00000000},{"price":0.66486,"qty":5436.00000000}],"checksum":3332995015,"timestamp":"2024-06-01T18:06:18.237835Z"}]}
{"channel":"book","type":"update","data":[{"symbol":"AUD/USD","bids":[],"asks":[{"price":0.66485,"qty":4258.83710000}],"checksum":463744235,"timestamp":"2024-06-01T18:06:18.252089Z"}]}
{"channel":"book","type":"update","data":[{"symbol":"AUD/USD","bids":[],"asks":[{"price":0.66487,"qty":0.00000000},{"price":0.66573,"qty":4434.00000000}],"checksum":1884808303,"timestamp":"2024-06-01T18:06:18.252141Z"}]}
{"channel":"book","type":"update","data":[{"symbol":"AUD/USD","bids":[],"asks":[{"price":0.66486,"qty":0.00000000},{"price":0.66583,"qty":5032.00000000},{"price":0.66484,"qty":5436.00000000}],"checksum":1560329570,"timestamp":"2024-06-01T18:06:18.269960Z"}]}
{"channel":"book","type":"update","data":[{"symbol":"AUD/USD","bids":[],"asks":[{"price":0.66485,"qty":0.00000000},{"price":0.66583,"qty":5032.00000000}],"checksum":3548872967,"timestamp":"2024-06-01T18:06:18.281012Z"}]}
{"channel":"book","type":"update","data":[{"symbol":"AUD/USD","bids":[],"asks":[{"price":0.66491,"qty":4258.83710000}],"checksum":3097279846,"timestamp":"2024-06-01T18:06:18.281177Z"}]}
{"channel":"book","type":"update","data":[{"symbol":"AUD/USD","bids":[],"asks":[{"price":0.66492,"qty":0.00000000},{"price":0.66583,"qty":5032.00000000},{"price":0.66483,"qty":5596.04542394}],"checksum":1823422157,"timestamp":"2024-06-01T18:06:18.366807Z"}]}
{"channel":"book","type":"update","data":[{"symbol":"AUD/USD","bids":[],"asks":[{"price":0.66484,"qty":0.00000000},{"price":0.66583,"qty":5032.00000000},{"price":0.66482,"qty":5436.00000000}],"checksum":1373991466,"timestamp":"2024-06-01T18:06:18.393568Z"}]}
{"channel":"book","type":"update","data":[{"symbol":"AUD/USD","bids":[],"asks":[{"price":0.66491,"qty":0.00000000},{"price":0.66583,"qty":5032.00000000}],"checksum":373313001,"timestamp":"2024-06-01T18:06:18.404575Z"}]}
{"channel":"book","type":"update","data":[{"symbol":"AUD/USD","bids":[],"asks":[{"price":0.66511,"qty":4258.83710000}],"checksum":3072433709,"timestamp":"2024-06-01T18:06:18.404798Z"}]}
{"channel":"book","type":"update","data":[{"symbol":"AUD/USD","bids":[{"price":0.66384,"qty":0.00000000},{"price":0.66358,"qty":3003.00000000}],"asks":[],"checksum":138394528,"timestamp":"2024-06-01T18:06:18.486689Z"}]}
{"channel":"book","type":"update","data":[{"symbol":"AUD/USD","bids":[{"price":0.66456,"qty":0.00000000},{"price":0.66352,"qty":2804.00000000},{"price":0.66433,"qty":5598.46789514}],"asks":[],"checksum":714398543,"timestamp":"2024-06-01T18:06:18.489876Z"}]}
{"channel":"book","type":"update","data":[{"symbol":"AUD/USD","bids":[{"price":0.66387,"qty":509.22352961}],"asks":[],"checksum":3466613614,"timestamp":"2024-06-01T18:06:18.495305Z"}]}
{"channel":"book","type":"update","data":[{"symbol":"AUD/USD","bids":[],"asks":[{"price":0.66483,"qty":0.00000000},{"price":0.66583,"qty":5032.00000000},{"price":0.66481,"qty":5596.04558736}],"checksum":3759835581,"timestamp":"2024-06-01T18:06:18.626741Z"}]}
{"channel":"book","type":"update","data":[{"symbol":"AUD/USD","bids":[],"asks":[{"price":0.66482,"qty":0.00000000},{"price":0.66583,"qty":5032.00000000},{"price":0.66480,"qty":5436.00000000}],"checksum":3528245699,"timestamp":"2024-06-01T18:06:18.638779Z"}]}
{"channel":"book","type":"update","data":[{"symbol":"AUD/USD","bids":[],"asks":[{"price":0.66481,"qty":0.00000000},{"price":0.66583,"qty":5032.00000000},{"price":0.66479,"qty":5596.04569802}],"checksum":4044275572,"timestamp":"2024-06-01T18:06:18.953319Z"}]}
{"channel":"book","type":"update","data":[{"symbol":"AUD/USD","bids":[],"asks":[{"price":0.66480,"qty":0.00000000},{"price":0.66583,"qty":5032.00000000},{"price":0.66478,"qty":5436.00000000}],"checksum":3199033808,"timestamp":"2024-06-01T18:06:18.973124Z"}]}
{"channel":"book","type":"update","data":[{"symbol":"AUD/USD","bids":[],"asks":[{"price":0.66479,"qty":0.00000000},{"price":0.66583,"qty":5032.00000000},{"price":0.66477,"qty":5596.04582385}],"checksum":1267468476,"timestamp":"2024-06-01T18:06:19.315274Z"}]}
{"channel":"book","type":"update","data":[{"symbol":"AUD/USD","bids":[],"asks":[{"price":0.66478,"qty":0.00000000},{"price":0.66583,"qty":5032.00000000},{"price":0.66476,"qty":5436.00000000}],"checksum":2109925238,"timestamp":"2024-06-01T18:06:19.338132Z"}]}
{"channel":"book","type":"update","data":[{"symbol":"AUD/USD","bids":[],"asks":[{"price":0.66477,"qty":0.00000000},{"price":0.66583,"qty":5032.00000000},{"price":0.66475,"qty":5596.08518842}],"checksum":3919389694,"timestamp":"2024-06-01T18:06:19.631451Z"}]}
{"channel":"book","type":"update","data":[{"symbol":"AUD/USD","bids":[],"asks":[{"price":0.66476,"qty":0.00000000},{"price":0.66583,"qty":5032.00000000},{"price":0.66474,"qty":5436.00000000}],"checksum":20965438,"timestamp":"2024-06-01T18:06:19.642236Z"}]}
{"channel":"book","type":"update","data":[{"symbol":"AUD/USD","bids":[],"asks":[{"price":0.66475,"qty":0.00000000},{"price":0.66583,"qty":5032.00000000},{"price":0.66471,"qty":5596.09076932}],"checksum":1851283494,"timestamp":"2024-06-01T18:06:19.982290Z"}]}
{"channel":"book","type":"update","data":[{"symbol":"AUD/USD","bids":[],"asks":[{"price":0.66557,"qty":0.00000000},{"price":0.66583,"qty":5032.00000000}],"checksum":3563451880,"timestamp":"2024-06-01T18:06:19.984664Z"}]}
{"channel":"book","type":"update","data":[{"symbol":"AUD/USD","bids":[],"asks":[{"price":0.66510,"qty":206.02937419}],"checksum":3552620050,"timestamp":"2024-06-01T18:06:19.986394Z"}]}
{"channel":"book","type":"update","data":[{"symbol":"AUD/USD","bids":[],"asks":[{"price":0.66474,"qty":0.00000000},{"price":0.66583,"qty":5032.00000000},{"price":0.66470,"qty":5436.00000000}],"checksum":1092096203,"timestamp":"2024-06-01T18:06:20.007583Z"}]}
{"channel":"book","type":"update","data":[{"symbol":"AUD/USD","bids":[],"asks":[{"price":0.66471,"qty":0.00000000},{"price":0.66583,"qty":5032.00000000},{"price":0.66469,"qty":5596.09329189}],"checksum":2245287838,"timestamp":"2024-06-01T18:06:20.366821Z"}]}
{"channel":"book","type":"update","data":[{"symbol":"AUD/USD","bids":[{"price":0.66385,"qty":0.00000000},{"price":0.66358,"qty":3003.00000000}],"asks":[],"checksum":3307052696,"timestamp":"2024-06-01T18:06:20.869591Z"}]}
{"channel":"book","type":"update","data":[{"symbol":"AUD/USD","bids":[{"price":0.66376,"qty":0.00000000},{"price":0.66352,"qty":2804.00000000}],"asks":[],"checksum":2263429728,"timestamp":"2024-06-01T18:06:20.869622Z"}]}
{"channel":"book","type":"update","data":[{"symbol":"AUD/USD","bids":[{"price":0.66434,"qty":3006.20781915}],"asks":[],"checksum":910248585,"timestamp":"2024-06-01T18:06:20.879655Z"}]}
{"channel":"book","type":"update","data":[{"symbol":"AUD/USD","bids":[{"price":0.66388,"qty":5167.08308081}],"asks":[],"checksum":1186171730,"timestamp":"2024-06-01T18:06:20.879749Z"}]}
{"channel":"book","type":"update","data":[{"symbol":"AUD/USD","bids":[{"price":0.66376,"qty":22917.96463157}],"asks":[],"checksum":909357664,"timestamp":"2024-06-01T18:06:20.879895Z"}]}
{"channel":"book","type":"update","data":[{"symbol":"AUD/USD","bids":[{"price":0.66433,"qty":0.00000000},{"price":0.66361,"qty":47002.00000000},{"price":0.66435,"qty":5598.29935542}],"asks":[],"checksum":15499471,"timestamp":"2024-06-01T18:06:20.882714Z"}]}
{"channel":"book","type":"update","data":[{"symbol":"AUD/USD","bids":[{"price":0.66386,"qty":0.00000000},{"price":0.66361,"qty":47002.00000000}],"asks":[],"checksum":2083472335,"timestamp":"2024-06-01T18:06:20.905761Z"}]}
{"channel":"book","type":"update","data":[{"symbol":"AUD/USD","bids":[{"price":0.66389,"qty":1030.62525418}],"asks":[],"checksum":928750598,"timestamp":"2024-06-01T18:06:20.905790Z"}]}
{"channel":"book","type":"update","data":[{"symbol":"AUD/USD","bids":[],"asks":[{"price":0.66512,"qty":0.00000000},{"price":0.66583,"qty":5032.00000000}],"checksum":1526914024,"timestamp":"2024-06-01T18:06:20.985632Z"}]}
{"channel":"book","type":"update","data":[{"symbol":"AUD/USD","bids":[],"asks":[{"price":0.66560,"qty":35267.16262833}],"checksum":3603821188,"timestamp":"2024-06-01T18:06:20.986560Z"}]}
{"channel":"book","type":"update","data":[{"symbol":"AUD/USD","bids":[],"asks":[{"price":0.66470,"qty":0.00000000},{"price":0.66583,"qty":5032.00000000},{"price":0.66509,"qty":5436.00000000}],"checksum":1801327785,"timestamp":"2024-06-01T18:06:21.012492Z"}]}
{"channel":"book","type":"update","data":[{"symbol":"AUD/USD","bids":[],"asks":[{"price":0.66469,"qty":0.00000000},{"price":0.66583,"qty":5032.00000000},{"price":0.66508,"qty":5596.09511422}],"checksum":488855585,"timestamp":"2024-06-01T18:06:21.015897Z"}]}
{"channel":"book","type":"update","data":[{"symbol":"AUD/USD","bids":[],"asks":[{"price":0.66507,"qty":4258.83710000}],"checksum":1005452515,"timestamp":"2024-06-01T18:06:21.021690Z"}]}
{"channel":"book","type":"update","data":[{"symbol":"AUD/USD","bids":[],"asks":[{"price":0.66511,"qty":0.00000000},{"price":0.66573,"qty":4434.00000000}],"checksum":3838269289,"timestamp":"2024-06-01T18:06:21.021730Z"}]}
{"channel":"book","type":"update","data":[{"symbol":"AUD/USD","bids":[],"asks":[{"price":0.66509,"qty":0.00000000},{"price":0.66583,"qty":5032.00000000},{"price":0.66506,"qty":5436.00000000}],"checksum":2356598411,"timestamp":"2024-06-01T18:06:21.043732Z"}]}
{"channel":"book","type":"update","data":[{"symbol":"AUD/USD","bids":[],"asks":[{"price":0.66505,"qty":4258.83710000}],"checksum":3090393682,"timestamp":"2024-06-01T18:06:21.065137Z"}]}
{"channel":"book","type":"update","data":[{"symbol":"AUD/USD","bids":[],"asks":[{"price":0.66507,"qty":0.00000000},{"price":0.66573,"qty":4434.00000000}],"checksum":348668852,"timestamp":"2024-06-01T18:06:21.065276Z"}]}
{"channel":"book","type":"update","data":[{"symbol":"AUD/USD","bids":[],"asks":[{"price":0.66506,"qty":0.00000000},{"price":0.66583,"qty":5032.00000000},{"price":0.66504,"qty":5436.00000000}],"checksum":1098826571,"timestamp":"2024-06-01T18:06:21.075460Z"}]}
{"channel":"book","type":"update","data":[{"symbol":"AUD/USD","bids":[],"asks":[{"price":0.66505,"qty":0.00000000},{"price":0.66583,"qty":5032.00000000}],"checksum":1669622488,"timestamp":"2024-06-01T18:06:21.094764Z"}]}
{"channel":"book","type":"update","data":[{"symbol":"AUD/USD","bids":[],"asks":[{"price":0.66503,"qty":4258.83710000}],"checksum":3819897156,"timestamp":"2024-06-01T18:06:21.094982Z"}]}
{"channel":"book","type":"update","data":[{"symbol":"AUD/USD","bids":[],"asks":[{"price":0.66504,"qty":0.00000000},{"price":0.66583,"qty":5032.00000000},{"price":0.66502,"qty":5436.00000000}],"checksum":3440900938,"timestamp":"2024-06-01T18:06:21.107555Z"}]}
{"channel":"book","type":"update","data":[{"symbol":"AUD/USD","bids":[],"asks":[{"price":0.66503,"qty":0.00000000},{"price":0.66583,"qty":5032.00000000}],"checksum":1155307120,"timestamp":"2024-06-01T18:06:21.115781Z"}]}
{"channel":"book","type":"update","data":[{"symbol":"AUD/USD","bids":[],"asks":[{"price":0.66501,"qty":4258.83710000}],"checksum":1437167221,"timestamp":"2024-06-01T18:06:21.115899Z"}]}
{"channel":"book","type":"update","data":[{"symbol":"AUD/USD","bids":[],"asks":[{"price":0.66502,"qty":0.00000000},{"price":0.66583,"qty":5032.00000000},{"price":0.66500,"qty":5436.00000000}],"checksum":2092682,"timestamp":"2024-06-01T18:06:21.139573Z"}]}
{"channel":"book","type":"update","data":[{"symbol":"AUD/USD","bids":[],"asks":[{"price":0.66501,"qty":0.00000000},{"price":0.66583,"qty":5032.00000000}],"checksum":1508589032,"timestamp":"2024-06-01T18:06:21.159352Z"}]}
{"channel":"book","type":"update","data":[{"symbol":"AUD/USD","bids":[],"asks":[{"price":0.66499,"qty":4258.83710000}],"checksum":3215221879,"timestamp":"2024-06-01T18:06:21.159496Z"}]}
{"channel":"book","type":"update","data":[{"symbol":"AUD/USD","bids":[],"asks":[{"price":0.66500,"qty":0.00000000},{"price":0.66583,"qty":5032.00000000},{"price":0.66498,"qty":5436.00000000}],"checksum":2670628699,"timestamp":"2024-06-01T18:06:21.171204Z"}]}
{"channel":"book","type":"update","data":[{"symbol":"AUD/USD","bids":[],"asks":[{"price":0.66499,"qty":0.00000000},{"price":0.66583,"qty":5032.00000000}],"checksum":1675200946,"timestamp":"2024-06-01T18:06:21.181137Z"}]}
{"channel":"book","type":"update","data":[{"symbol":"AUD/USD","bids":[],"asks":[{"price":0.66497,"qty":4258.83710000}],"checksum":1226957620,"timestamp":"2024-06-01T18:06:21.181257Z"}]}
{"channel":"book","type":"update","data":[{"symbol":"AUD/USD","bids":[],"asks":[{"price":0.66498,"qty":0.00000000},{"price":0.66583,"qty":5032.00000000},{"price":0.66496,"qty":5436.00000000}],"checksum":2441473240,"timestamp":"2024-06-01T18:06:21.202587Z"}]}
{"channel":"book","type":"update","data":[{"symbol":"AUD/USD","bids":[],"asks":[{"price":0.66497,"qty":0.00000000},{"price":0.66583,"qty":5032.00000000}],"checksum":811588474,"timestamp":"2024-06-01T18:06:21.209816Z"}]}
{"channel":"book","type":"update","data":[{"symbol":"AUD/USD","bids":[],"asks":[{"price":0.66495,"qty":4258.83710000}],"checksum":154892775,"timestamp":"2024-06-01T18:06:21.210141Z"}]}
{"channel":"book","type":"update","data":[{"symbol":"AUD/USD","bids":[],"asks":[{"price":0.66496,"qty":0.00000000},{"price":0.66583,"qty":5032.00000000},{"price":0.66494,"qty":5436.00000000}],"checksum":1552808216,"timestamp":"2024-06-01T18:06:21.235061Z"}]}
{"channel":"book","type":"update","data":[{"symbol":"AUD/USD","bids":[{"price":0.66387,"qty":0.00000000},{"price":0.66361,"qty":47002.00000000}],"asks":[],"checksum":2440924456,"timestamp":"2024-06-01T18:06:21.241012Z"}]}
{"channel":"book","type":"update","data":[{"symbol":"AUD/USD","bids":[{"price":0.66387,"qty":463.32280483}],"asks":[],"checksum":4086747168,"timestamp":"2024-06-01T18:06:21.246582Z"}]}
{"channel":"book","type":"update","data":[{"symbol":"AUD/USD","bids":[{"price":0.66434,"qty":3036.26967141}],"asks":[],"checksum":3103443692,"timestamp":"2024-06-01T18:06:21.246601Z"}]}
{"channel":"book","type":"update","data":[{"symbol":"AUD/USD","bids":[],"asks":[{"price":0.66508,"qty":0.00000000},{"price":0.66583,"qty":5032.00000000},{"price":0.66493,"qty":5596.09511422}],"checksum":2041779090,"timestamp":"2024-06-01T18:06:21.257624Z"}]}
{"channel":"book","type":"update","data":[{"symbol":"AUD/USD","bids":[],"asks":[{"price":0.66495,"qty":0.00000000},{"price":0.66583,"qty":5032.00000000}],"checksum":886403967,"timestamp":"2024-06-01T18:06:21.259576Z"}]}
{"channel":"book","type":"update","data":[{"symbol":"AUD/USD","bids":[],"asks":[{"price":0.66493,"qty":9854.93221422}],"checksum":2661086759,"timestamp":"2024-06-01T18:06:21.259820Z"}]}
{"channel":"book","type":"update","data":[{"symbol":"AUD/USD","bids":[],"asks":[{"price":0.66494,"qty":0.00000000},{"price":0.66604,"qty":2955.00000000},{"price":0.66492,"qty":5436.00000000}],"checksum":2247611218,"timestamp":"2024-06-01T18:06:21.266268Z"}]}
{"channel":"book","type":"update","data":[{"symbol":"AUD/USD","bids":[],"asks":[{"price":0.66493,"qty":5596.09511422}],"checksum":4083419969,"timestamp":"2024-06-01T18:06:21.282755Z"}]}
{"channel":"book","type":"update","data":[{"symbol":"AUD/USD","bids":[],"asks":[{"price":0.66491,"qty":4258.83710000}],"checksum":1529919828,"timestamp":"2024-06-01T18:06:21.282819Z"}]}
{"channel":"book","type":"update","data":[{"symbol":"AUD/USD","bids":[],"asks":[{"price":0.66492,"qty":0.00000000},{"price":0.66583,"qty":5032.00000000},{"price":0.66490,"qty":5436.00000000}],"checksum":243677611,"timestamp":"2024-06-01T18:06:21.298013Z"}]}
{"channel":"book","type":"update","data":[{"symbol":"AUD/USD","bids":[],"asks":[{"price":0.66491,"qty":0.00000000},{"price":0.66583,"qty":5032.00000000}],"checksum":3998458073,"timestamp":"2024-06-01T18:06:21.314589Z"}]}
{"channel":"book","type":"update","data":[{"symbol":"AUD/USD","bids":[],"asks":[{"price":0.66489,"qty":4258.83710000}],"checksum":1829616674,"timestamp":"2024-06-01T18:06:21.314632Z"}]}
{"channel":"book","type":"update","data":[{"symbol":"AUD/USD","bids":[],"asks":[{"price":0.66490,"qty":0.00000000},{"price":0.66583,"qty":5032.00000000},{"price":0.66488,"qty":5436.00000000}],"checksum":740820059,"timestamp":"2024-06-01T18:06:21.329922Z"}]}
{"channel":"book","type":"update","data":[{"symbol":"AUD/USD","bids":[],"asks":[{"price":0.66489,"qty":0.00000000},{"price":0.66583,"qty":5032.00000000}],"checksum":139533303,"timestamp":"2024-06-01T18:06:21.334906Z"}]}
{"channel":"book","type":"update","data":[{"symbol":"AUD/USD","bids":[],"asks":[{"price":0.66487,"qty":4258.83710000}],"checksum":4196886580,"timestamp":"2024-06-01T18:06:21.334954Z"}]}
{"channel":"book","type":"update","data":[{"symbol":"AUD/USD","bids":[],"asks":[{"price":0.66488,"qty":0.00000000},{"price":0.66583,"qty":5032.00000000},{"price":0.66486,"qty":5436.00000000}],"checksum":579037144,"timestamp":"2024-06-01T18:06:21.367111Z"}]}
{"channel":"book","type":"update","data":[{"symbol":"AUD/USD","bids":[],"asks":[{"price":0.66493,"qty":0.00000000},{"price":0.66583,"qty":5032.00000000},{"price":0.66485,"qty":5596.12480796}],"checksum":2631265087,"timestamp":"2024-06-01T18:06:21.622655Z"}]}
{"channel":"book","type":"update","data":[{"symbol":"AUD/USD","bids":[],"asks":[{"price":0.66486,"qty":0.00000000},{"price":0.66583,"qty":5032.00000000},{"price":0.66484,"qty":5436.00000000}],"checksum":1812327309,"timestamp":"2024-06-01T18:06:21.635993Z"}]}
{"channel":"book","type":"update","data":[{"symbol":"AUD/USD","bids":[],"asks":[{"price":0.66485,"qty":0.00000000},{"price":0.66583,"qty":5032.00000000},{"price":0.66483,"qty":5596.13131961}],"checksum":1685526444,"timestamp":"2024-06-01T18:06:22.021524Z"}]}
{"channel":"book","type":"update","data":[{"symbol":"AUD/USD","bids":[],"asks":[{"price":0.66484,"qty":0.00000000},{"price":0.66583,"qty":5032.00000000},{"price":0.66482,"qty":5436.00000000}],"checksum":1630799549,"timestamp":"2024-06-01T18:06:22.031766Z"}]}
{"channel":"book","type":"update","data":[{"symbol":"AUD/USD","bids":[],"asks":[{"price":0.66483,"qty":0.00000000},{"price":0.66583,"qty":5032.00000000},{"price":0.66481,"qty":5596.13313393}],"checksum":2155731729,"timestamp":"2024-06-01T18:06:22.453621Z"}]}
{"channel":"book","type":"update","data":[{"symbol":"AUD/USD","bids":[],"asks":[{"price":0.66482,"qty":0.00000000},{"price":0.66583,"qty":5032.00000000},{"price":0.66480,"qty":5436.00000000}],"checksum":526825710,"timestamp":"2024-06-01T18:06:22.487675Z"}]}
{"channel":"book","type":"update","data":[{"symbol":"AUD/USD","bids":[],"asks":[{"price":0.66487,"qty":0.00000000},{"price":0.66583,"qty":5032.00000000}],"checksum":586075787,"timestamp":"2024-06-01T18:06:22.672930Z"}]}
{"channel":"book","type":"update","data":[{"symbol":"AUD/USD","bids":[],"asks":[{"price":0.66509,"qty":4258.83710000}],"checksum":830785760,"timestamp":"2024-06-01T18:06:22.672945Z"}]}
{"channel":"book","type":"update","data":[{"symbol":"AUD/USD","bids":[],"asks":[{"price":0.66481,"qty":0.00000000},{"price":0.66583,"qty":5032.00000000},{"price":0.66479,"qty":5596.13577709}],"checksum":1957993576,"timestamp":"2024-06-01T18:06:22.842964Z"}]}
{"channel":"book","type":"update","data":[{"symbol":"AUD/USD","bids":[],"asks":[{"price":0.66480,"qty":0.00000000},{"price":0.66583,"qty":5032.00000000},{"price":0.66478,"qty":5436.00000000}],"checksum":241054901,"timestamp":"2024-06-01T18:06:22.852981Z"}]}
{"channel":"book","type":"update","data":[{"symbol":"AUD/USD","bids":[],"asks":[{"price":0.66510,"qty":0.00000000},{"price":0.66583,"qty":5032.00000000}],"checksum":3796865078,"timestamp":"2024-06-01T18:06:23.181308Z"}]}
{"channel":"book","type":"update","data":[{"symbol":"AUD/USD","bids":[],"asks":[{"price":0.66559,"qty":294.01313515}],"checksum":412402640,"timestamp":"2024-06-01T18:06:23.182138Z"}]}
{"channel":"book","type":"update","data":[{"symbol":"AUD/USD","bids":[],"asks":[{"price":0.66509,"qty":0.00000000},{"price":0.66583,"qty":5032.00000000}],"checksum":2568924878,"timestamp":"2024-06-01T18:06:23.192891Z"}]}
{"channel":"book","type":"update","data":[{"symbol":"AUD/USD","bids":[],"asks":[{"price":0.66526,"qty":4258.83710000}],"checksum":603817143,"timestamp":"2024-06-01T18:06:23.193015Z"}]}
{"channel":"book","type":"update","data":[{"symbol":"AUD/USD","bids":[],"asks":[{"price":0.66479,"qty":0.00000000},{"price":0.66583,"qty":5032.00000000},{"price":0.66477,"qty":5596.13642581}],"checksum":1864632366,"timestamp":"2024-06-01T18:06:23.265763Z"}]}
{"channel":"book","type":"update","data":[{"symbol":"AUD/USD","bids":[],"asks":[{"price":0.66478,"qty":0.00000000},{"price":0.66583,"qty":5032.00000000},{"price":0.66476,"qty":5436.00000000}],"checksum":4020729597,"timestamp":"2024-06-01T18:06:23.280286Z"}]}
{"channel":"book","type":"update","data":[{"symbol":"AUD/USD","bids":[],"asks":[{"price":0.66477,"qty":0.00000000},{"price":0.66583,"qty":5032.00000000},{"price":0.66471,"qty":5596.13660375}],"checksum":48675515,"timestamp":"2024-06-01T18:06:23.722231Z"}]}
{"channel":"book","type":"update","data":[{"symbol":"AUD/USD","bids":[{"price":0.66434,"qty":3006.20781915}],"asks":[],"checksum":1233821815,"timestamp":"2024-06-01T18:06:23.912030Z"}]}
{"channel":"book","type":"update","data":[{"symbol":"AUD/USD","bids":[{"price":0.66387,"qty":0.00000000},{"price":0.66361,"qty":47002.00000000}],"asks":[],"checksum":880971163,"timestamp":"2024-06-01T18:06:23.912118Z"}]}
{"channel":"book","type":"update","data":[{"symbol":"AUD/USD","bids":[{"price":0.66436,"qty":56.94487883}],"asks":[],"checksum":3049195568,"timestamp":"2024-06-01T18:06:23.921657Z"}]}
{"channel":"book","type":"update","data":[{"symbol":"AUD/USD","bids":[{"price":0.66390,"qty":430.02341335}],"asks":[],"checksum":1926813649,"timestamp":"2024-06-01T18:06:23.921729Z"}]}
{"channel":"book","type":"update","data":[{"symbol":"AUD/USD","bids":[],"asks":[{"price":0.66560,"qty":0.00000000},{"price":0.66583,"qty":5032.00000000}],"checksum":2280797803,"timestamp":"2024-06-01T18:06:23.959965Z"}]}
{"channel":"book","type":"update","data":[{"symbol":"AUD/USD","bids":[],"asks":[{"price":0.66560,"qty":29299.49997318}],"checksum":1701328362,"timestamp":"2024-06-01T18:06:23.960808Z"}]}
{"channel":"book","type":"update","data":[{"symbol":"AUD/USD","bids":[],"asks":[{"price":0.66525,"qty":5939.02189271}],"checksum":3311201199,"timestamp":"2024-06-01T18:06:23.960879Z"}]}
{"channel":"book","type":"update","data":[{"symbol":"AUD/USD","bids":[],"asks":[{"price":0.66526,"qty":0.00000000},{"price":0.66573,"qty":4434.00000000}],"checksum":1105086782,"timestamp":"2024-06-01T18:06:23.970184Z"}]}
{"channel":"book","type":"update","data":[{"symbol":"AUD/USD","bids":[],"asks":[{"price":0.66524,"qty":4258.83710000}],"checksum":220092167,"timestamp":"2024-06-01T18:06:23.970372Z"}]}
{"channel":"book","type":"update","data":[{"symbol":"AUD/USD","bids":[{"price":0.66434,"qty":0.00000000},{"price":0.66375,"qty":53001.00000000}],"asks":[],"checksum":969424295,"timestamp":"2024-06-01T18:06:24.543356Z"}]}
{"channel":"book","type":"update","data":[{"symbol":"AUD/USD","bids":[{"price":0.66388,"qty":0.00000000},{"price":0.66361,"qty":47002.00000000}],"asks":[],"checksum":813724139,"timestamp":"2024-06-01T18:06:24.543480Z"}]}
{"channel":"book","type":"update","data":[{"symbol":"AUD/USD","bids":[{"price":0.66376,"qty":0.00000000},{"price":0.66358,"qty":3003.00000000}],"asks":[],"checksum":2187241981,"timestamp":"2024-06-01T18:06:24.543495Z"}]}
{"channel":"book","type":"update","data":[{"symbol":"AUD/USD","bids":[{"price":0.66435,"qty":0.00000000},{"price":0.66352,"qty":2804.00000000},{"price":0.66433,"qty":5598.46789514}],"asks":[],"checksum":2461487921,"timestamp":"2024-06-01T18:06:24.547249Z"}]}
{"channel":"book","type":"update","data":[{"symbol":"AUD/USD","bids":[{"price":0.66436,"qty":3063.15269798}],"asks":[],"checksum":2349455610,"timestamp":"2024-06-01T18:06:24.547508Z"}]}
{"channel":"book","type":"update","data":[{"symbol":"AUD/USD","bids":[{"price":0.66376,"qty":30252.25366329}],"asks":[],"checksum":144902287,"timestamp":"2024-06-01T18:06:24.547692Z"}]}
{"channel":"book","type":"update","data":[{"symbol":"AUD/USD","bids":[{"price":0.66433,"qty":0.00000000},{"price":0.66358,"qty":3003.00000000},{"price":0.66437,"qty":5598.13082586}],"asks":[],"checksum":2722449908,"timestamp":"2024-06-01T18:06:24.917360Z"}]}
{"channel":"book","type":"update","data":[{"symbol":"AUD/USD","bids":[{"price":0.66437,"qty":0.00000000},{"price":0.66358,"qty":3003.00000000},{"price":0.66438,"qty":5598.04656488}],"asks":[],"checksum":1582325817,"timestamp":"2024-06-01T18:06:25.321065Z"}]}
{"channel":"book","type":"update","data":[{"symbol":"AUD/USD","bids":[{"price":0.66438,"qty":0.00000000},{"price":0.66358,"qty":3003.00000000},{"price":0.66439,"qty":5597.96230644}],"asks":[],"checksum":1603133374,"timestamp":"2024-06-01T18:06:25.758332Z"}]}
{"channel":"book","type":"update","data":[{"symbol":"AUD/USD","bids":[{"price":0.66439,"qty":0.00000000},{"price":0.66358,"qty":3003.00000000},{"price":0.66437,"qty":5598.13082586}],"asks":[],"checksum":2722449908,"timestamp":"2024-06-01T18:06:25.761631Z"}]}
{"channel":"book","type":"update","data":[{"symbol":"AUD/USD","bids":[],"asks":[{"price":0.66559,"qty":0.00000000},{"price":0.66573,"qty":4434.00000000}],"checksum":1753031555,"timestamp":"2024-06-01T18:06:26.408692Z"}]}
{"channel":"book","type":"update","data":[{"symbol":"AUD/USD","bids":[],"asks":[{"price":0.66523,"qty":268.35120487}],"checksum":2751729972,"timestamp":"2024-06-01T18:06:26.409077Z"}]}
{"channel":"book","type":"update","data":[{"symbol":"AUD/USD","bids":[{"price":0.66436,"qty":3006.20781915}],"asks":[],"checksum":381641975,"timestamp":"2024-06-01T18:06:26.845260Z"}]}
{"channel":"book","type":"update","data":[{"symbol":"AUD/USD","bids":[{"price":0.66390,"qty":0.00000000},{"price":0.66358,"qty":3003.00000000}],"asks":[],"checksum":1676400418,"timestamp":"2024-06-01T18:06:26.845396Z"}]}
{"channel":"book","type":"update","data":[{"symbol":"AUD/USD","bids":[{"price":0.66389,"qty":0.00000000},{"price":0.66352,"qty":2804.00000000}],"asks":[],"checksum":962420865,"timestamp":"2024-06-01T18:06:26.849585Z"}]}
{"channel":"book","type":"update","data":[{"symbol":"AUD/USD","bids":[{"price":0.66377,"qty":1030.81157629}],"asks":[],"checksum":3426796206,"timestamp":"2024-06-01T18:06:26.849894Z"}]}
{"channel":"book","type":"update","data":[{"symbol":"AUD/USD","bids":[{"price":0.66438,"qty":30.06185226}],"asks":[],"checksum":4290795357,"timestamp":"2024-06-01T18:06:26.851276Z"}]}
{"channel":"book","type":"update","data":[{"symbol":"AUD/USD","bids":[{"price":0.66377,"qty":1487.82302804}],"asks":[],"checksum":3103218224,"timestamp":"2024-06-01T18:06:26.851422Z"}]}
{"channel":"book","type":"update","data":[{"symbol":"AUD/USD","bids":[],"asks":[{"price":0.66525,"qty":0.00000000},{"price":0.66573,"qty":4434.00000000}],"checksum":1541804920,"timestamp":"2024-06-01T18:06:26.980564Z"}]}
{"channel":"book","type":"update","data":[{"symbol":"AUD/USD","bids":[],"asks":[{"price":0.66560,"qty":0.00000000},{"price":0.66583,"qty":5032.00000000}],"checksum":1848370353,"timestamp":"2024-06-01T18:06:26.980715Z"}]}
{"channel":"book","type":"update","data":[{"symbol":"AUD/USD","bids":[],"asks":[{"price":0.66560,"qty":35267.16262833}],"checksum":3572579324,"timestamp":"2024-06-01T18:06:26.981695Z"}]}
{"channel":"book","type":"update","data":[{"symbol":"AUD/USD","bids":[{"price":0.66378,"qty":126.92998508}],"asks":[],"checksum":2836163785,"timestamp":"2024-06-01T18:06:27.162185Z"}]}
{"channel":"book","type":"update","data":[{"symbol":"AUD/USD","bids":[{"price":0.66436,"qty":0.00000000},{"price":0.66361,"qty":47002.00000000}],"asks":[],"checksum":1605855331,"timestamp":"2024-06-01T18:06:28.032979Z"}]}
{"channel":"book","type":"update","data":[{"symbol":"AUD/USD","bids":[{"price":0.66376,"qty":0.00000000},{"price":0.66358,"qty":3003.00000000}],"asks":[],"checksum":4040954254,"timestamp":"2024-06-01T18:06:28.033058Z"}]}
{"channel":"book","type":"update","data":[{"symbol":"AUD/USD","bids":[{"price":0.66437,"qty":0.00000000},{"price":0.66352,"qty":2804.00000000},{"price":0.66379,"qty":5603.02230642}],"asks":[],"checksum":33116346,"timestamp":"2024-06-01T18:06:28.036870Z"}]}
{"channel":"book","type":"update","data":[{"symbol":"AUD/USD","bids":[{"price":0.66378,"qty":19565.31130619}],"asks":[],"checksum":250482448,"timestamp":"2024-06-01T18:06:28.038846Z"}]}
{"channel":"book","type":"update","data":[{"symbol":"AUD/USD","bids":[{"price":0.66379,"qty":12930.98064889}],"asks":[],"checksum":1852511997,"timestamp":"2024-06-01T18:06:28.039009Z"}]}
{"channel":"book","type":"update","data":[{"symbol":"AUD/USD","bids":[{"price":0.66380,"qty":1030.76498945}],"asks":[],"checksum":3537036198,"timestamp":"2024-06-01T18:06:28.044193Z"}]}
{"channel":"book","type":"update","data":[{"symbol":"AUD/USD","bids":[{"price":0.66377,"qty":457.01145175}],"asks":[],"checksum":2667268391,"timestamp":"2024-06-01T18:06:28.044212Z"}]}
{"channel":"book","type":"update","data":[{"symbol":"AUD/USD","bids":[{"price":0.66379,"qty":7327.95834247},{"price":0.66381,"qty":5602.85349238}],"asks":[],"checksum":1633425328,"timestamp":"2024-06-01T18:06:28.346814Z"}]}
{"channel":"book","type":"update","data":[{"symbol":"AUD/USD","bids":[{"price":0.66380,"qty":0.00000000},{"price":0.66361,"qty":47002.00000000}],"asks":[],"checksum":3815766832,"timestamp":"2024-06-01T18:06:28.375798Z"}]}
{"channel":"book","type":"update","data":[{"symbol":"AUD/USD","bids":[{"price":0.66382,"qty":1030.73393389}],"asks":[],"checksum":229666908,"timestamp":"2024-06-01T18:06:28.376056Z"}]}
{"channel":"book","type":"update","data":[{"symbol":"AUD/USD","bids":[{"price":0.66381,"qty":0.00000000},{"price":0.66361,"qty":47002.00000000},{"price":0.66380,"qty":5602.93789813}],"asks":[],"checksum":2026698872,"timestamp":"2024-06-01T18:06:28.378816Z"}]}
{"channel":"book","type":"update","data":[{"symbol":"AUD/USD","bids":[{"price":0.66380,"qty":0.00000000},{"price":0.66361,"qty":47002.00000000},{"price":0.66433,"qty":5598.46789514}],"asks":[],"checksum":4217264042,"timestamp":"2024-06-01T18:06:28.687423Z"}]}
{"channel":"book","type":"update","data":[{"symbol":"AUD/USD","bids":[{"price":0.66433,"qty":0.00000000},{"price":0.66361,"qty":47002.00000000},{"price":0.66434,"qty":5598.38362401}],"asks":[],"checksum":3468835665,"timestamp":"2024-06-01T18:06:29.019598Z"}]}
{"channel":"book","type":"update","data":[{"symbol":"AUD/USD","bids":[{"price":0.66434,"qty":0.00000000},{"price":0.66361,"qty":47002.00000000},{"price":0.66435,"qty":5598.29935542}],"asks":[],"checksum":3954683238,"timestamp":"2024-06-01T18:06:29.385267Z"}]}
{"channel":"book","type":"update","data":[{"symbol":"AUD/USD","bids":[{"price":0.66435,"qty":0.00000000},{"price":0.66361,"qty":47002.00000000},{"price":0.66433,"qty":5598.46789514}],"asks":[],"checksum":4217264042,"timestamp":"2024-06-01T18:06:29.388760Z"}]}
{"channel":"book","type":"update","data":[{"symbol":"AUD/USD","bids":[{"price":0.66438,"qty":0.00000000},{"price":0.66361,"qty":47002.00000000}],"asks":[],"checksum":682178541,"timestamp":"2024-06-01T18:06:29.390452Z"}]}
{"channel":"book","type":"update","data":[{"symbol":"AUD/USD","bids":[{"price":0.66377,"qty":0.00000000},{"price":0.66358,"qty":3003.00000000}],"asks":[],"checksum":2505950816,"timestamp":"2024-06-01T18:06:29.390538Z"}]}
{"channel":"book","type":"update","data":[{"symbol":"AUD/USD","bids":[{"price":0.66434,"qty":30.06185226}],"asks":[],"checksum":3366940323,"timestamp":"2024-06-01T18:06:29.401807Z"}]}
{"channel":"book","type":"update","data":[{"symbol":"AUD/USD","bids":[{"price":0.66380,"qty":50.29188171}],"asks":[],"checksum":1737645327,"timestamp":"2024-06-01T18:06:29.401826Z"}]}
{"channel":"book","type":"update","data":[{"symbol":"AUD/USD","bids":[{"price":0.66383,"qty":433.30725086}],"asks":[],"checksum":2643552337,"timestamp":"2024-06-01T18:06:29.401984Z"}]}
{"channel":"book","type":"update","data":[{"symbol":"AUD/USD","bids":[],"asks":[{"price":0.66523,"qty":0.00000000},{"price":0.66583,"qty":5032.00000000}],"checksum":3997975220,"timestamp":"2024-06-01T18:06:29.630261Z"}]}
{"channel":"book","type":"update","data":[{"symbol":"AUD/USD","bids":[],"asks":[{"price":0.66559,"qty":294.01313515}],"checksum":1243632796,"timestamp":"2024-06-01T18:06:29.630787Z"}]}
{"channel":"book","type":"update","data":[{"symbol":"AUD/USD","bids":[],"asks":[{"price":0.66560,"qty":0.00000000},{"price":0.66583,"qty":5032.00000000}],"checksum":3325644712,"timestamp":"2024-06-01T18:06:30.001699Z"}]}
{"channel":"book","type":"update","data":[{"symbol":"AUD/USD","bids":[],"asks":[{"price":0.66523,"qty":5939.02189271}],"checksum":3187308607,"timestamp":"2024-06-01T18:06:30.002732Z"}]}
{"channel":"book","type":"update","data":[{"symbol":"AUD/USD","bids":[],"asks":[{"price":0.66560,"qty":29299.49997318}],"checksum":3415103704,"timestamp":"2024-06-01T18:06:30.002749Z"}]}
{"channel":"book","type":"update","data":[{"symbol":"AUD/USD","bids":[],"asks":[{"price":0.66524,"qty":0.00000000},{"price":0.66573,"qty":4434.00000000}],"checksum":2187713075,"timestamp":"2024-06-01T18:06:30.026712Z"}]}
{"channel":"book","type":"update","data":[{"symbol":"AUD/USD","bids":[],"asks":[{"price":0.66522,"qty":4258.83710000}],"checksum":270364623,"timestamp":"2024-06-01T18:06:30.026810Z"}]}
{"channel":"book","type":"update","data":[{"symbol":"AUD/USD","bids":[{"price":0.66378,"qty":19438.38132111}],"asks":[],"checksum":4075851763,"timestamp":"2024-06-01T18:06:30.166958Z"}]}
{"channel":"book","type":"update","data":[{"symbol":"AUD/USD","bids":[{"price":0.66379,"qty":0.00000000},{"price":0.66375,"qty":53001.00000000}],"asks":[],"checksum":1661057796,"timestamp":"2024-06-01T18:06:31.352885Z"}]}
{"channel":"book","type":"update","data":[{"symbol":"AUD/USD","bids":[{"price":0.66378,"qty":0.00000000},{"price":0.66361,"qty":47002.00000000}],"asks":[],"checksum":4010416673,"timestamp":"2024-06-01T18:06:31.352900Z"}]}
{"channel":"book","type":"update","data":[{"symbol":"AUD/USD","bids":[{"price":0.66376,"qty":17579.69998391}],"asks":[],"checksum":3391016502,"timestamp":"2024-06-01T18:06:31.358224Z"}]}
{"channel":"book","type":"update","data":[{"symbol":"AUD/USD","bids":[{"price":0.66384,"qty":5939.02189271}],"asks":[],"checksum":1916318388,"timestamp":"2024-06-01T18:06:31.358237Z"}]}
{"channel":"book","type":"update","data":[{"symbol":"AUD/USD","bids":[{"price":0.66382,"qty":0.00000000},{"price":0.66375,"qty":53001.00000000}],"asks":[],"checksum":3189050135,"timestamp":"2024-06-01T18:06:31.376337Z"}]}
{"channel":"book","type":"update","data":[{"symbol":"AUD/USD","bids":[{"price":0.66385,"qty":1030.68738420}],"asks":[],"checksum":3169648034,"timestamp":"2024-06-01T18:06:31.376645Z"}]}
{"channel":"book","type":"update","data":[{"symbol":"AUD/USD","bids":[{"price":0.66383,"qty":0.00000000},{"price":0.66375,"qty":53001.00000000}],"asks":[],"checksum":4185632932,"timestamp":"2024-06-01T18:06:32.628197Z"}]}
{"channel":"book","type":"update","data":[{"symbol":"AUD/USD","bids":[{"price":0.66380,"qty":0.00000000},{"price":0.66361,"qty":47002.00000000}],"asks":[],"checksum":734221525,"timestamp":"2024-06-01T18:06:32.628262Z"}]}
{"channel":"book","type":"update","data":[{"symbol":"AUD/USD","bids":[],"asks":[{"price":0.66559,"qty":0.00000000},{"price":0.66573,"qty":4434.00000000}],"checksum":3903998158,"timestamp":"2024-06-01T18:06:32.883927Z"}]}
{"channel":"book","type":"update","data":[{"symbol":"AUD/USD","bids":[],"asks":[{"price":0.66521,"qty":293.78401077}],"checksum":2265892315,"timestamp":"2024-06-01T18:06:32.884877Z"}]}
{"channel":"book","type":"update","data":[{"symbol":"AUD/USD","bids":[{"price":0.66386,"qty":483.89447832}],"asks":[],"checksum":1489447057,"timestamp":"2024-06-01T18:06:32.949172Z"}]}
{"channel":"book","type":"update","data":[{"symbol":"AUD/USD","bids":[],"asks":[{"price":0.66523,"qty":0.00000000},{"price":0.66573,"qty":4434.00000000}],"checksum":1691763226,"timestamp":"2024-06-01T18:06:32.995320Z"}]}
{"channel":"book","type":"update","data":[{"symbol":"AUD/USD","bids":[],"asks":[{"price":0.66558,"qty":5939.02189271}],"checksum":3074161678,"timestamp":"2024-06-01T18:06:32.996179Z"}]}
{"channel":"book","type":"update","data":[{"symbol":"AUD/USD","bids":[{"price":0.66376,"qty":0.00000000},{"price":0.66361,"qty":47002.00000000}],"asks":[],"checksum":2452563993,"timestamp":"2024-06-01T18:06:35.357252Z"}]}
{"channel":"book","type":"update","data":[{"symbol":"AUD/USD","bids":[{"price":0.66384,"qty":0.00000000},{"price":0.66358,"qty":3003.00000000}],"asks":[],"checksum":2446792586,"timestamp":"2024-06-01T18:06:35.357428Z"}]}
{"channel":"book","type":"update","data":[{"symbol":"AUD/USD","bids":[{"price":0.66434,"qty":3036.26967141}],"asks":[],"checksum":3299031157,"timestamp":"2024-06-01T18:06:35.367326Z"}]}
{"channel":"book","type":"update","data":[{"symbol":"AUD/USD","bids":[{"price":0.66376,"qty":20751.81379554}],"asks":[],"checksum":4220447132,"timestamp":"2024-06-01T18:06:35.367372Z"}]}
{"channel":"book","type":"update","data":[{"symbol":"AUD/USD","bids":[{"price":0.66387,"qty":7327.95834247}],"asks":[],"checksum":90941653,"timestamp":"2024-06-01T18:06:35.367427Z"}]}
{"channel":"book","type":"update","data":[{"symbol":"AUD/USD","bids":[{"price":0.66433,"qty":0.00000000},{"price":0.66361,"qty":47002.00000000},{"price":0.66435,"qty":5598.29935542}],"asks":[],"checksum":299164242,"timestamp":"2024-06-01T18:06:35.371129Z"}]}
{"channel":"book","type":"update","data":[{"symbol":"AUD/USD","bids":[{"price":0.66388,"qty":1030.64087473}],"asks":[],"checksum":3861350416,"timestamp":"2024-06-01T18:06:35.374222Z"}]}
{"channel":"book","type":"update","data":[{"symbol":"AUD/USD","bids":[{"price":0.66385,"qty":0.00000000},{"price":0.66375,"qty":53001.00000000}],"asks":[],"checksum":3960219160,"timestamp":"2024-06-01T18:06:35.374243Z"}]}
{"channel":"book","type":"update","data":[{"symbol":"AUD/USD","bids":[],"asks":[{"price":0.66560,"qty":0.00000000},{"price":0.66573,"qty":4434.00000000}],"checksum":3018363284,"timestamp":"2024-06-01T18:06:36.021938Z"}]}
