{"channel":"book","type":"snapshot","data":[{"symbol":"BCH/USD","bids":[{"price":461.51,"qty":1.76240000},{"price":461.49,"qty":1.03326318},{"price":461.48,"qty":8.71512088},{"price":461.47,"qty":0.43328066},{"price":461.41,"qty":0.88120000},{"price":461.40,"qty":1.90083308},{"price":461.38,"qty":12.48847144},{"price":461.37,"qty":1.45100000},{"price":461.36,"qty":0.47629027},{"price":461.35,"qty":0.88120000}],"asks":[{"price":461.69,"qty":5.56215765},{"price":461.70,"qty":1.48120000},{"price":461.75,"qty":0.88120000},{"price":461.77,"qty":1.76240000},{"price":461.80,"qty":0.50682788},{"price":461.81,"qty":7.07000000},{"price":461.82,"qty":14.74332295},{"price":461.83,"qty":0.88120000},{"price":461.85,"qty":18.66000905},{"price":461.88,"qty":0.88120000}],"checksum":831299230}]}
{"channel":"book","type":"update","data":[{"symbol":"BCH/USD","bids":[{"price":461.51,"qty":0.88120000}],"asks":[],"checksum":1629740622,"timestamp":"2024-06-01T18:05:48.493462Z"}]}
{"channel":"book","type":"update","data":[{"symbol":"BCH/USD","bids":[{"price":461.50,"qty":7.83392088}],"asks":[],"checksum":978232895,"timestamp":"2024-06-01T18:05:48.497917Z"}]}
{"channel":"book","type":"update","data":[{"symbol":"BCH/USD","bids":[{"price":461.48,"qty":0.88120000}],"asks":[],"checksum":3645128782,"timestamp":"2024-06-01T18:05:48.511655Z"}]}
{"channel":"book","type":"update","data":[{"symbol":"BCH/USD","bids":[{"price":461.51,"qty":1.76240000}],"asks":[],"checksum":2313879710,"timestamp":"2024-06-01T18:05:48.541097Z"}]}
{"channel":"book","type":"update","data":[{"symbol":"BCH/USD","bids":[{"price":461.51,"qty":0.88120000}],"asks":[],"checksum":3645128782,"timestamp":"2024-06-01T18:05:48.714304Z"}]}
{"channel":"book","type":"update","data":[{"symbol":"BCH/USD","bids":[{"price":461.49,"qty":0.60000000}],"asks":[],"checksum":947048430,"timestamp":"2024-06-01T18:05:48.854407Z"}]}
{"channel":"book","type":"update","data":[{"symbol":"BCH/USD","bids":[],"asks":[{"price":461.82,"qty":3.89332295},{"price":461.81,"qty":17.92000000}],"checksum":3950712321,"timestamp":"2024-06-01T18:05:49.591133Z"}]}
{"channel":"book","type":"update","data":[{"symbol":"BCH/USD","bids":[{"price":461.51,"qty":1.76240000}],"asks":[],"checksum":2720388526,"timestamp":"2024-06-01T18:05:49.875020Z"}]}
{"channel":"book","type":"update","data":[{"symbol":"BCH/USD","bids":[{"price":461.51,"qty":0.88120000}],"asks":[],"checksum":3950712321,"timestamp":"2024-06-01T18:05:50.047431Z"}]}
{"channel":"book","type":"update","data":[{"symbol":"BCH/USD","bids":[{"price":461.51,"qty":1.76240000}],"asks":[],"checksum":2720388526,"timestamp":"2024-06-01T18:05:50.099013Z"}]}
{"channel":"book","type":"update","data":[{"symbol":"BCH/USD","bids":[{"price":461.41,"qty":1.28120000}],"asks":[],"checksum":1321605474,"timestamp":"2024-06-01T18:05:50.143531Z"}]}
{"channel":"book","type":"update","data":[{"symbol":"BCH/USD","bids":[{"price":461.47,"qty":0.00000000},{"price":461.35,"qty":0.88120000}],"asks":[],"checksum":1518708332,"timestamp":"2024-06-01T18:05:50.153320Z"}]}
{"channel":"book","type":"update","data":[{"symbol":"BCH/USD","bids":[{"price":461.42,"qty":0.43326553}],"asks":[],"checksum":728535152,"timestamp":"2024-06-01T18:05:50.153595Z"}]}
{"channel":"book","type":"update","data":[{"symbol":"BCH/USD","bids":[{"price":461.48,"qty":1.31446549}],"asks":[],"checksum":2376863905,"timestamp":"2024-06-01T18:05:50.699247Z"}]}
{"channel":"book","type":"update","data":[{"symbol":"BCH/USD","bids":[{"price":461.51,"qty":2.19566373}],"asks":[],"checksum":1639442985,"timestamp":"2024-06-01T18:05:50.756589Z"}]}
{"channel":"book","type":"update","data":[{"symbol":"BCH/USD","bids":[{"price":461.42,"qty":0.00000000},{"price":461.35,"qty":0.88120000}],"asks":[],"checksum":274652213,"timestamp":"2024-06-01T18:05:50.756618Z"}]}
{"channel":"book","type":"update","data":[{"symbol":"BCH/USD","bids":[{"price":461.53,"qty":0.88120000}],"asks":[],"checksum":1130087743,"timestamp":"2024-06-01T18:05:50.760562Z"}]}
{"channel":"book","type":"update","data":[{"symbol":"BCH/USD","bids":[{"price":461.48,"qty":0.43326549}],"asks":[],"checksum":2156944847,"timestamp":"2024-06-01T18:05:50.760959Z"}]}
{"channel":"book","type":"update","data":[{"symbol":"BCH/USD","bids":[{"price":461.52,"qty":7.83392088}],"asks":[],"checksum":1037482407,"timestamp":"2024-06-01T18:05:50.761023Z"}]}
{"channel":"book","type":"update","data":[{"symbol":"BCH/USD","bids":[{"price":461.48,"qty":0.00000000},{"price":461.36,"qty":0.47629027}],"asks":[],"checksum":3659490833,"timestamp":"2024-06-01T18:05:50.765384Z"}]}
{"channel":"book","type":"update","data":[{"symbol":"BCH/USD","bids":[{"price":461.53,"qty":1.31444954}],"asks":[],"checksum":4056136162,"timestamp":"2024-06-01T18:05:50.765549Z"}]}
{"channel":"book","type":"update","data":[{"symbol":"BCH/USD","bids":[{"price":461.49,"qty":0.00000000},{"price":461.35,"qty":0.88120000}],"asks":[],"checksum":3554027657,"timestamp":"2024-06-01T18:05:50.768974Z"}]}
{"channel":"book","type":"update","data":[{"symbol":"BCH/USD","bids":[{"price":461.56,"qty":0.88120000}],"asks":[],"checksum":676978718,"timestamp":"2024-06-01T18:05:50.770536Z"}]}
{"channel":"book","type":"update","data":[{"symbol":"BCH/USD","bids":[{"price":461.40,"qty":3.74112557}],"asks":[],"checksum":327106983,"timestamp":"2024-06-01T18:05:50.770781Z"}]}
{"channel":"book","type":"update","data":[{"symbol":"BCH/USD","bids":[{"price":461.56,"qty":0.00000000},{"price":461.35,"qty":0.88120000}],"asks":[],"checksum":3996724853,"timestamp":"2024-06-01T18:05:50.773948Z"}]}
{"channel":"book","type":"update","data":[{"symbol":"BCH/USD","bids":[{"price":461.56,"qty":0.88120000}],"asks":[],"checksum":327106983,"timestamp":"2024-06-01T18:05:50.774189Z"}]}
{"channel":"book","type":"update","data":[{"symbol":"BCH/USD","bids":[{"price":461.51,"qty":1.31446373}],"asks":[],"checksum":1578665492,"timestamp":"2024-06-01T18:05:50.774313Z"}]}
{"channel":"book","type":"update","data":[{"symbol":"BCH/USD","bids":[{"price":461.56,"qty":1.76240000}],"asks":[],"checksum":3999042407,"timestamp":"2024-06-01T18:05:50.777869Z"}]}
{"channel":"book","type":"update","data":[{"symbol":"BCH/USD","bids":[],"asks":[{"price":461.70,"qty":0.60000000}],"checksum":853710057,"timestamp":"2024-06-01T18:05:50.778920Z"}]}
{"channel":"book","type":"update","data":[{"symbol":"BCH/USD","bids":[],"asks":[{"price":461.70,"qty":0.00000000},{"price":461.89,"qty":1.80493541}],"checksum":2487127071,"timestamp":"2024-06-01T18:05:50.781532Z"}]}
{"channel":"book","type":"update","data":[{"symbol":"BCH/USD","bids":[{"price":461.38,"qty":7.07000000}],"asks":[],"checksum":3556697355,"timestamp":"2024-06-01T18:05:50.786648Z"}]}
{"channel":"book","type":"update","data":[{"symbol":"BCH/USD","bids":[{"price":461.41,"qty":6.69926718}],"asks":[],"checksum":3360128858,"timestamp":"2024-06-01T18:05:50.790844Z"}]}
{"channel":"book","type":"update","data":[{"symbol":"BCH/USD","bids":[],"asks":[{"price":461.69,"qty":5.41488877}],"checksum":3620540922,"timestamp":"2024-06-01T18:05:50.800427Z"}]}
{"channel":"book","type":"update","data":[{"symbol":"BCH/USD","bids":[],"asks":[{"price":461.81,"qty":7.07000000}],"checksum":1036589146,"timestamp":"2024-06-01T18:05:50.800524Z"}]}
{"channel":"book","type":"update","data":[{"symbol":"BCH/USD","bids":[{"price":461.52,"qty":0.00000000},{"price":461.35,"qty":0.88120000}],"asks":[],"checksum":3330735403,"timestamp":"2024-06-01T18:05:50.804266Z"}]}
{"channel":"book","type":"update","data":[{"symbol":"BCH/USD","bids":[],"asks":[{"price":461.85,"qty":29.51000905}],"checksum":2400624068,"timestamp":"2024-06-01T18:05:50.807498Z"}]}
{"channel":"book","type":"update","data":[{"symbol":"BCH/USD","bids":[{"price":461.53,"qty":0.88120000}],"asks":[],"checksum":3138164652,"timestamp":"2024-06-01T18:05:50.850675Z"}]}
{"channel":"book","type":"update","data":[{"symbol":"BCH/USD","bids":[{"price":461.54,"qty":0.43324854}],"asks":[],"checksum":2788181839,"timestamp":"2024-06-01T18:05:50.850694Z"}]}
{"channel":"book","type":"update","data":[{"symbol":"BCH/USD","bids":[],"asks":[{"price":461.72,"qty":0.14726888}],"checksum":2317149312,"timestamp":"2024-06-01T18:05:50.923462Z"}]}
{"channel":"book","type":"update","data":[{"symbol":"BCH/USD","bids":[],"asks":[{"price":461.77,"qty":0.00000000},{"price":461.89,"qty":1.80493541}],"checksum":3456303486,"timestamp":"2024-06-01T18:05:50.964214Z"}]}
{"channel":"book","type":"update","data":[{"symbol":"BCH/USD","bids":[],"asks":[{"price":461.69,"qty":6.29608877}],"checksum":796675186,"timestamp":"2024-06-01T18:05:50.976733Z"}]}
{"channel":"book","type":"update","data":[{"symbol":"BCH/USD","bids":[],"asks":[{"price":461.69,"qty":5.41488877}],"checksum":3456303486,"timestamp":"2024-06-01T18:05:51.019380Z"}]}
{"channel":"book","type":"update","data":[{"symbol":"BCH/USD","bids":[],"asks":[{"price":461.69,"qty":6.29608877}],"checksum":796675186,"timestamp":"2024-06-01T18:05:51.041851Z"}]}
{"channel":"book","type":"update","data":[{"symbol":"BCH/USD","bids":[{"price":461.55,"qty":0.40000000}],"asks":[],"checksum":2983496007,"timestamp":"2024-06-01T18:05:51.048106Z"}]}
{"channel":"book","type":"update","data":[{"symbol":"BCH/USD","bids":[{"price":461.56,"qty":0.88120000}],"asks":[],"checksum":4236562270,"timestamp":"2024-06-01T18:05:51.058800Z"}]}
{"channel":"book","type":"update","data":[{"symbol":"BCH/USD","bids":[{"price":461.54,"qty":0.84324854}],"asks":[],"checksum":1418599974,"timestamp":"2024-06-01T18:05:51.169524Z"}]}
{"channel":"book","type":"update","data":[{"symbol":"BCH/USD","bids":[{"price":461.56,"qty":1.76240000}],"asks":[],"checksum":434001983,"timestamp":"2024-06-01T18:05:51.172495Z"}]}
{"channel":"book","type":"update","data":[{"symbol":"BCH/USD","bids":[],"asks":[{"price":461.76,"qty":1.76240000}],"checksum":2437069256,"timestamp":"2024-06-01T18:05:51.264412Z"}]}
{"channel":"book","type":"update","data":[{"symbol":"BCH/USD","bids":[{"price":461.55,"qty":0.00000000},{"price":461.36,"qty":0.47629027}],"asks":[],"checksum":3626920270,"timestamp":"2024-06-01T18:05:51.301844Z"}]}
{"channel":"book","type":"update","data":[{"symbol":"BCH/USD","bids":[{"price":461.56,"qty":0.88120000}],"asks":[],"checksum":2304368504,"timestamp":"2024-06-01T18:05:51.762242Z"}]}
{"channel":"book","type":"update","data":[{"symbol":"BCH/USD","bids":[{"price":461.54,"qty":0.41000000}],"asks":[],"checksum":2754881254,"timestamp":"2024-06-01T18:05:52.212918Z"}]}
{"channel":"book","type":"update","data":[{"symbol":"BCH/USD","bids":[{"price":461.56,"qty":0.00000000},{"price":461.30,"qty":0.88120000}],"asks":[],"checksum":1575049920,"timestamp":"2024-06-01T18:05:53.440556Z"}]}
{"channel":"book","type":"update","data":[{"symbol":"BCH/USD","bids":[{"price":461.54,"qty":8.24392088}],"asks":[],"checksum":1119456055,"timestamp":"2024-06-01T18:05:53.444641Z"}]}
{"channel":"book","type":"update","data":[{"symbol":"BCH/USD","bids":[{"price":461.50,"qty":0.00000000},{"price":461.27,"qty":0.44000000}],"asks":[],"checksum":2865305877,"timestamp":"2024-06-01T18:05:53.513169Z"}]}
{"channel":"book","type":"update","data":[{"symbol":"BCH/USD","bids":[{"price":461.51,"qty":0.88120000}],"asks":[],"checksum":32550112,"timestamp":"2024-06-01T18:05:53.517036Z"}]}
{"channel":"book","type":"update","data":[{"symbol":"BCH/USD","bids":[{"price":461.42,"qty":0.43323733}],"asks":[],"checksum":3469380639,"timestamp":"2024-06-01T18:05:53.517325Z"}]}
{"channel":"book","type":"update","data":[{"symbol":"BCH/USD","bids":[{"price":461.54,"qty":7.83392088}],"asks":[],"checksum":3027152363,"timestamp":"2024-06-01T18:05:53.688534Z"}]}
{"channel":"book","type":"update","data":[{"symbol":"BCH/USD","bids":[{"price":461.54,"qty":0.00000000},{"price":461.27,"qty":0.44000000}],"asks":[],"checksum":3307352589,"timestamp":"2024-06-01T18:05:54.019565Z"}]}
{"channel":"book","type":"update","data":[{"symbol":"BCH/USD","bids":[{"price":461.52,"qty":7.83392088}],"asks":[],"checksum":1056123100,"timestamp":"2024-06-01T18:05:54.019822Z"}]}
{"channel":"book","type":"update","data":[{"symbol":"BCH/USD","bids":[],"asks":[{"price":461.69,"qty":6.89608877}],"checksum":407620153,"timestamp":"2024-06-01T18:05:54.022341Z"}]}
{"channel":"book","type":"update","data":[{"symbol":"BCH/USD","bids":[],"asks":[{"price":461.80,"qty":0.00000000},{"price":461.89,"qty":1.80493541}],"checksum":3399984153,"timestamp":"2024-06-01T18:05:59.286456Z"}]}
{"channel":"book","type":"update","data":[{"symbol":"BCH/USD","bids":[],"asks":[{"price":461.77,"qty":0.50682788}],"checksum":860614866,"timestamp":"2024-06-01T18:05:59.384721Z"}]}
{"channel":"book","type":"update","data":[{"symbol":"BCH/USD","bids":[{"price":461.51,"qty":0.00000000},{"price":461.27,"qty":0.44000000}],"asks":[],"checksum":207107258,"timestamp":"2024-06-01T18:05:59.798415Z"}]}
{"channel":"book","type":"update","data":[{"symbol":"BCH/USD","bids":[{"price":461.52,"qty":0.00000000},{"price":461.25,"qty":0.88120000}],"asks":[],"checksum":3058386140,"timestamp":"2024-06-01T18:05:59.802652Z"}]}
{"channel":"book","type":"update","data":[{"symbol":"BCH/USD","bids":[{"price":461.43,"qty":7.83392088}],"asks":[],"checksum":1420615397,"timestamp":"2024-06-01T18:05:59.802811Z"}]}
{"channel":"book","type":"update","data":[{"symbol":"BCH/USD","bids":[{"price":461.48,"qty":0.88120000}],"asks":[],"checksum":3226116510,"timestamp":"2024-06-01T18:05:59.803718Z"}]}
{"channel":"book","type":"update","data":[{"symbol":"BCH/USD","bids":[],"asks":[{"price":461.68,"qty":0.60000000}],"checksum":1072274745,"timestamp":"2024-06-01T18:05:59.805453Z"}]}
{"channel":"book","type":"update","data":[{"symbol":"BCH/USD","bids":[],"asks":[{"price":461.69,"qty":6.29608877}],"checksum":668315367,"timestamp":"2024-06-01T18:05:59.805479Z"}]}
{"channel":"book","type":"update","data":[{"symbol":"BCH/USD","bids":[{"price":461.43,"qty":8.43392088}],"asks":[],"checksum":11145848,"timestamp":"2024-06-01T18:05:59.805568Z"}]}
{"channel":"book","type":"update","data":[{"symbol":"BCH/USD","bids":[{"price":461.43,"qty":7.83392088}],"asks":[],"checksum":668315367,"timestamp":"2024-06-01T18:05:59.805586Z"}]}
{"channel":"book","type":"update","data":[{"symbol":"BCH/USD","bids":[{"price":461.44,"qty":0.60000000}],"asks":[],"checksum":2777697837,"timestamp":"2024-06-01T18:05:59.806001Z"}]}
{"channel":"book","type":"update","data":[{"symbol":"BCH/USD","bids":[{"price":461.44,"qty":1.03324010}],"asks":[],"checksum":2483016231,"timestamp":"2024-06-01T18:05:59.806361Z"}]}
{"channel":"book","type":"update","data":[{"symbol":"BCH/USD","bids":[{"price":461.53,"qty":0.00000000},{"price":461.30,"qty":0.88120000}],"asks":[],"checksum":204588648,"timestamp":"2024-06-01T18:05:59.806421Z"}]}
{"channel":"book","type":"update","data":[{"symbol":"BCH/USD","bids":[{"price":461.42,"qty":0.00000000},{"price":461.27,"qty":0.44000000}],"asks":[],"checksum":3272337047,"timestamp":"2024-06-01T18:05:59.807862Z"}]}
{"channel":"book","type":"update","data":[{"symbol":"BCH/USD","bids":[{"price":461.48,"qty":1.31444010}],"asks":[],"checksum":3888270385,"timestamp":"2024-06-01T18:05:59.808053Z"}]}
{"channel":"book","type":"update","data":[{"symbol":"BCH/USD","bids":[{"price":461.48,"qty":0.88120000}],"asks":[],"checksum":3272337047,"timestamp":"2024-06-01T18:05:59.810776Z"}]}
{"channel":"book","type":"update","data":[{"symbol":"BCH/USD","bids":[{"price":461.49,"qty":0.43324010}],"asks":[],"checksum":4269378950,"timestamp":"2024-06-01T18:05:59.810949Z"}]}
{"channel":"book","type":"update","data":[{"symbol":"BCH/USD","bids":[],"asks":[{"price":461.85,"qty":18.66000905},{"price":461.81,"qty":17.92000000}],"checksum":3152109238,"timestamp":"2024-06-01T18:05:59.984185Z"}]}
{"channel":"book","type":"update","data":[{"symbol":"BCH/USD","bids":[{"price":461.49,"qty":0.00000000},{"price":461.27,"qty":0.44000000}],"asks":[],"checksum":2257794471,"timestamp":"2024-06-01T18:05:59.985298Z"}]}
{"channel":"book","type":"update","data":[{"symbol":"BCH/USD","bids":[{"price":461.48,"qty":0.00000000},{"price":461.25,"qty":0.88120000}],"asks":[],"checksum":4171731426,"timestamp":"2024-06-01T18:05:59.988737Z"}]}
{"channel":"book","type":"update","data":[{"symbol":"BCH/USD","bids":[{"price":461.48,"qty":0.88120000}],"asks":[],"checksum":2257794471,"timestamp":"2024-06-01T18:05:59.991259Z"}]}
{"channel":"book","type":"update","data":[{"symbol":"BCH/USD","bids":[],"asks":[{"price":461.69,"qty":0.88120000}],"checksum":269535590,"timestamp":"2024-06-01T18:05:59.998696Z"}]}
{"channel":"book","type":"update","data":[{"symbol":"BCH/USD","bids":[{"price":461.44,"qty":0.43324010}],"asks":[],"checksum":3583214846,"timestamp":"2024-06-01T18:06:00.001421Z"}]}
{"channel":"book","type":"update","data":[{"symbol":"BCH/USD","bids":[{"price":461.49,"qty":0.60000000}],"asks":[],"checksum":2793530931,"timestamp":"2024-06-01T18:06:00.001611Z"}]}
{"channel":"book","type":"update","data":[{"symbol":"BCH/USD","bids":[],"asks":[{"price":461.67,"qty":5.41512335}],"checksum":2664186872,"timestamp":"2024-06-01T18:06:00.002835Z"}]}
{"channel":"book","type":"update","data":[{"symbol":"BCH/USD","bids":[{"price":461.41,"qty":1.28120000}],"asks":[],"checksum":934346088,"timestamp":"2024-06-01T18:06:00.013373Z"}]}
{"channel":"book","type":"update","data":[{"symbol":"BCH/USD","bids":[{"price":461.35,"qty":5.41880015}],"asks":[],"checksum":265687683,"timestamp":"2024-06-01T18:06:00.017692Z"}]}
{"channel":"book","type":"update","data":[{"symbol":"BCH/USD","bids":[{"price":461.36,"qty":0.00000000},{"price":461.30,"qty":0.88120000}],"asks":[],"checksum":2475416138,"timestamp":"2024-06-01T18:06:00.020219Z"}]}
{"channel":"book","type":"update","data":[{"symbol":"BCH/USD","bids":[{"price":461.48,"qty":0.00000000},{"price":461.27,"qty":0.44000000}],"asks":[],"checksum":607308341,"timestamp":"2024-06-01T18:06:00.031445Z"}]}
{"channel":"book","type":"update","data":[{"symbol":"BCH/USD","bids":[{"price":461.49,"qty":0.00000000},{"price":461.25,"qty":0.88120000}],"asks":[],"checksum":1965080811,"timestamp":"2024-06-01T18:06:00.034129Z"}]}
{"channel":"book","type":"update","data":[{"symbol":"BCH/USD","bids":[{"price":461.45,"qty":0.60000000}],"asks":[],"checksum":1461712950,"timestamp":"2024-06-01T18:06:00.034376Z"}]}
{"channel":"book","type":"update","data":[{"symbol":"BCH/USD","bids":[{"price":461.43,"qty":0.00000000},{"price":461.25,"qty":0.88120000}],"asks":[],"checksum":1412918785,"timestamp":"2024-06-01T18:06:00.035322Z"}]}
{"channel":"book","type":"update","data":[{"symbol":"BCH/USD","bids":[{"price":461.36,"qty":0.88120000}],"asks":[],"checksum":1956758150,"timestamp":"2024-06-01T18:06:00.037434Z"}]}
{"channel":"book","type":"update","data":[{"symbol":"BCH/USD","bids":[],"asks":[{"price":461.68,"qty":0.00000000},{"price":461.84,"qty":10.83000000}],"checksum":636995530,"timestamp":"2024-06-01T18:06:00.038080Z"}]}
{"channel":"book","type":"update","data":[{"symbol":"BCH/USD","bids":[],"asks":[{"price":461.66,"qty":0.60000000}],"checksum":3748833059,"timestamp":"2024-06-01T18:06:00.038204Z"}]}
{"channel":"book","type":"update","data":[{"symbol":"BCH/USD","bids":[{"price":461.46,"qty":0.88120000}],"asks":[],"checksum":3831012216,"timestamp":"2024-06-01T18:06:00.038722Z"}]}
{"channel":"book","type":"update","data":[{"symbol":"BCH/USD","bids":[{"price":461.44,"qty":0.00000000},{"price":461.27,"qty":0.44000000}],"asks":[],"checksum":3088811222,"timestamp":"2024-06-01T18:06:00.038905Z"}]}
{"channel":"book","type":"update","data":[{"symbol":"BCH/USD","bids":[{"price":461.42,"qty":0.43332019}],"asks":[],"checksum":1215902094,"timestamp":"2024-06-01T18:06:00.039009Z"}]}
{"channel":"book","type":"update","data":[{"symbol":"BCH/USD","bids":[{"price":461.44,"qty":0.43332019}],"asks":[],"checksum":3405408453,"timestamp":"2024-06-01T18:06:00.043661Z"}]}
{"channel":"book","type":"update","data":[{"symbol":"BCH/USD","bids":[],"asks":[{"price":461.67,"qty":0.00000000},{"price":461.84,"qty":10.83000000}],"checksum":1742355431,"timestamp":"2024-06-01T18:06:00.044045Z"}]}
{"channel":"book","type":"update","data":[{"symbol":"BCH/USD","bids":[{"price":461.45,"qty":0.00000000},{"price":461.30,"qty":0.88120000}],"asks":[],"checksum":971544015,"timestamp":"2024-06-01T18:06:00.046781Z"}]}
{"channel":"book","type":"update","data":[{"symbol":"BCH/USD","bids":[{"price":461.47,"qty":0.60000000}],"asks":[],"checksum":2879499609,"timestamp":"2024-06-01T18:06:00.046946Z"}]}
{"channel":"book","type":"update","data":[{"symbol":"BCH/USD","bids":[{"price":461.44,"qty":0.00000000},{"price":461.30,"qty":0.88120000}],"asks":[],"checksum":690156562,"timestamp":"2024-06-01T18:06:00.047102Z"}]}
{"channel":"book","type":"update","data":[{"symbol":"BCH/USD","bids":[{"price":461.45,"qty":0.43332017}],"asks":[],"checksum":2291495281,"timestamp":"2024-06-01T18:06:00.050371Z"}]}
{"channel":"book","type":"update","data":[{"symbol":"BCH/USD","bids":[{"price":461.45,"qty":0.00000000},{"price":461.30,"qty":0.88120000}],"asks":[],"checksum":690156562,"timestamp":"2024-06-01T18:06:00.053965Z"}]}
{"channel":"book","type":"update","data":[{"symbol":"BCH/USD","bids":[{"price":461.46,"qty":1.31452017}],"asks":[],"checksum":178874691,"timestamp":"2024-06-01T18:06:00.057369Z"}]}
{"channel":"book","type":"update","data":[{"symbol":"BCH/USD","bids":[{"price":461.49,"qty":0.88120000}],"asks":[],"checksum":2047332485,"timestamp":"2024-06-01T18:06:00.061293Z"}]}
{"channel":"book","type":"update","data":[{"symbol":"BCH/USD","bids":[{"price":461.46,"qty":0.88120000}],"asks":[],"checksum":3975516371,"timestamp":"2024-06-01T18:06:00.065043Z"}]}
{"channel":"book","type":"update","data":[{"symbol":"BCH/USD","bids":[],"asks":[{"price":461.84,"qty":0.00000000},{"price":461.85,"qty":18.66000905}],"checksum":2280333144,"timestamp":"2024-06-01T18:06:00.065547Z"}]}
{"channel":"book","type":"update","data":[{"symbol":"BCH/USD","bids":[{"price":461.35,"qty":5.90071191}],"asks":[],"checksum":2723174338,"timestamp":"2024-06-01T18:06:00.136730Z"}]}
{"channel":"book","type":"update","data":[{"symbol":"BCH/USD","bids":[{"price":461.38,"qty":0.00000000},{"price":461.30,"qty":0.88120000}],"asks":[],"checksum":3080634055,"timestamp":"2024-06-01T18:06:00.295791Z"}]}
{"channel":"book","type":"update","data":[{"symbol":"BCH/USD","bids":[{"price":461.40,"qty":1.90083308}],"asks":[],"checksum":2148373922,"timestamp":"2024-06-01T18:06:00.296465Z"}]}
{"channel":"book","type":"update","data":[{"symbol":"BCH/USD","bids":[{"price":461.30,"qty":2.72189142}],"asks":[],"checksum":4046006821,"timestamp":"2024-06-01T18:06:00.301353Z"}]}
{"channel":"book","type":"update","data":[{"symbol":"BCH/USD","bids":[{"price":461.35,"qty":0.48191176}],"asks":[],"checksum":1983647392,"timestamp":"2024-06-01T18:06:00.302480Z"}]}
{"channel":"book","type":"update","data":[{"symbol":"BCH/USD","bids":[],"asks":[{"price":461.85,"qty":7.83392088}],"checksum":3018751665,"timestamp":"2024-06-01T18:06:00.302536Z"}]}
{"channel":"book","type":"update","data":[{"symbol":"BCH/USD","bids":[{"price":461.49,"qty":0.00000000},{"price":461.27,"qty":0.44000000}],"asks":[],"checksum":1434223286,"timestamp":"2024-06-01T18:06:00.306414Z"}]}
{"channel":"book","type":"update","data":[{"symbol":"BCH/USD","bids":[{"price":461.31,"qty":5.41930728}],"asks":[],"checksum":2066686897,"timestamp":"2024-06-01T18:06:00.307433Z"}]}
{"channel":"book","type":"update","data":[{"symbol":"BCH/USD","bids":[],"asks":[{"price":461.61,"qty":5.41593135}],"checksum":1537106036,"timestamp":"2024-06-01T18:06:00.307533Z"}]}
{"channel":"book","type":"update","data":[{"symbol":"BCH/USD","bids":[],"asks":[{"price":461.77,"qty":11.33477994}],"checksum":3481797623,"timestamp":"2024-06-01T18:06:00.307605Z"}]}
{"channel":"book","type":"update","data":[{"symbol":"BCH/USD","bids":[{"price":461.46,"qty":0.00000000},{"price":461.27,"qty":0.44000000}],"asks":[],"checksum":2404630434,"timestamp":"2024-06-01T18:06:00.310496Z"}]}
{"channel":"book","type":"update","data":[{"symbol":"BCH/USD","bids":[],"asks":[{"price":461.68,"qty":7.07000000}],"checksum":3902732378,"timestamp":"2024-06-01T18:06:00.311871Z"}]}
{"channel":"book","type":"update","data":[{"symbol":"BCH/USD","bids":[],"asks":[{"price":461.72,"qty":4.04059183}],"checksum":4245513165,"timestamp":"2024-06-01T18:06:00.311958Z"}]}
{"channel":"book","type":"update","data":[{"symbol":"BCH/USD","bids":[],"asks":[{"price":461.61,"qty":6.29713135}],"checksum":4099559595,"timestamp":"2024-06-01T18:06:00.312073Z"}]}
{"channel":"book","type":"update","data":[{"symbol":"BCH/USD","bids":[{"price":461.47,"qty":0.00000000},{"price":461.25,"qty":0.88120000}],"asks":[],"checksum":592445466,"timestamp":"2024-06-01T18:06:00.313249Z"}]}
{"channel":"book","type":"update","data":[{"symbol":"BCH/USD","bids":[{"price":461.43,"qty":0.60000000}],"asks":[],"checksum":2763641046,"timestamp":"2024-06-01T18:06:00.313358Z"}]}
{"channel":"book","type":"update","data":[{"symbol":"BCH/USD","bids":[{"price":461.44,"qty":0.88120000}],"asks":[],"checksum":268742968,"timestamp":"2024-06-01T18:06:00.316543Z"}]}
{"channel":"book","type":"update","data":[{"symbol":"BCH/USD","bids":[{"price":461.35,"qty":0.00000000},{"price":461.27,"qty":0.44000000}],"asks":[],"checksum":4143197991,"timestamp":"2024-06-01T18:06:00.316636Z"}]}
{"channel":"book","type":"update","data":[{"symbol":"BCH/USD","bids":[{"price":461.33,"qty":0.88120000}],"asks":[],"checksum":12223063,"timestamp":"2024-06-01T18:06:00.348259Z"}]}
{"channel":"book","type":"update","data":[{"symbol":"BCH/USD","bids":[{"price":461.44,"qty":1.31452576}],"asks":[],"checksum":1003211508,"timestamp":"2024-06-01T18:06:00.353598Z"}]}
{"channel":"book","type":"update","data":[{"symbol":"BCH/USD","bids":[{"price":461.44,"qty":0.88120000}],"asks":[],"checksum":12223063,"timestamp":"2024-06-01T18:06:00.357144Z"}]}
{"channel":"book","type":"update","data":[{"symbol":"BCH/USD","bids":[],"asks":[{"price":461.81,"qty":10.85000000}],"checksum":3563737502,"timestamp":"2024-06-01T18:06:00.357919Z"}]}
{"channel":"book","type":"update","data":[{"symbol":"BCH/USD","bids":[],"asks":[{"price":461.82,"qty":0.00000000},{"price":461.83,"qty":0.88120000}],"checksum":4062377472,"timestamp":"2024-06-01T18:06:00.358625Z"}]}
{"channel":"book","type":"update","data":[{"symbol":"BCH/USD","bids":[{"price":461.32,"qty":0.48194310}],"asks":[],"checksum":550470571,"timestamp":"2024-06-01T18:06:00.434288Z"}]}
{"channel":"book","type":"update","data":[{"symbol":"BCH/USD","bids":[{"price":461.38,"qty":7.83392088}],"asks":[],"checksum":1884687019,"timestamp":"2024-06-01T18:06:00.512581Z"}]}
{"channel":"book","type":"update","data":[{"symbol":"BCH/USD","bids":[],"asks":[{"price":461.83,"qty":11.71120000}],"checksum":453297955,"timestamp":"2024-06-01T18:06:00.515982Z"}]}
{"channel":"book","type":"update","data":[{"symbol":"BCH/USD","bids":[],"asks":[{"price":461.81,"qty":0.00000000},{"price":461.85,"qty":7.83392088},{"price":461.75,"qty":11.73120000}],"checksum":1143300982,"timestamp":"2024-06-01T18:06:00.516062Z"}]}
{"channel":"book","type":"update","data":[{"symbol":"BCH/USD","bids":[{"price":461.33,"qty":0.00000000},{"price":461.31,"qty":5.41930728}],"asks":[],"checksum":1557375059,"timestamp":"2024-06-01T18:06:00.640211Z"}]}
{"channel":"book","type":"update","data":[{"symbol":"BCH/USD","bids":[],"asks":[{"price":461.74,"qty":1.90097336}],"checksum":3001570437,"timestamp":"2024-06-01T18:06:00.924949Z"}]}
{"channel":"book","type":"update","data":[{"symbol":"BCH/USD","bids":[],"asks":[{"price":461.61,"qty":5.41593135}],"checksum":1050669285,"timestamp":"2024-06-01T18:06:01.168758Z"}]}
{"channel":"book","type":"update","data":[{"symbol":"BCH/USD","bids":[],"asks":[{"price":461.72,"qty":3.89332295}],"checksum":649465534,"timestamp":"2024-06-01T18:06:01.177864Z"}]}
{"channel":"book","type":"update","data":[{"symbol":"BCH/USD","bids":[],"asks":[{"price":461.61,"qty":6.29713135}],"checksum":2864818910,"timestamp":"2024-06-01T18:06:01.222591Z"}]}
{"channel":"book","type":"update","data":[{"symbol":"BCH/USD","bids":[],"asks":[{"price":461.61,"qty":5.41593135}],"checksum":649465534,"timestamp":"2024-06-01T18:06:01.265805Z"}]}
{"channel":"book","type":"update","data":[{"symbol":"BCH/USD","bids":[],"asks":[{"price":461.75,"qty":0.88120000}],"checksum":839155907,"timestamp":"2024-06-01T18:06:01.270464Z"}]}
{"channel":"book","type":"update","data":[{"symbol":"BCH/USD","bids":[],"asks":[{"price":461.83,"qty":0.88120000}],"checksum":3361580507,"timestamp":"2024-06-01T18:06:01.273612Z"}]}
{"channel":"book","type":"update","data":[{"symbol":"BCH/USD","bids":[],"asks":[{"price":461.78,"qty":10.85000000}],"checksum":4064924902,"timestamp":"2024-06-01T18:06:01.277225Z"}]}
{"channel":"book","type":"update","data":[{"symbol":"BCH/USD","bids":[{"price":461.45,"qty":0.43329552}],"asks":[],"checksum":2238594978,"timestamp":"2024-06-01T18:06:01.300136Z"}]}
{"channel":"book","type":"update","data":[{"symbol":"BCH/USD","bids":[{"price":461.47,"qty":0.88120000}],"asks":[],"checksum":397379426,"timestamp":"2024-06-01T18:06:01.304348Z"}]}
{"channel":"book","type":"update","data":[{"symbol":"BCH/USD","bids":[{"price":461.45,"qty":8.26721640}],"asks":[],"checksum":1170996889,"timestamp":"2024-06-01T18:06:01.304423Z"}]}
{"channel":"book","type":"update","data":[{"symbol":"BCH/USD","bids":[{"price":461.48,"qty":0.88120000}],"asks":[],"checksum":1585255047,"timestamp":"2024-06-01T18:06:01.304672Z"}]}
{"channel":"book","type":"update","data":[{"symbol":"BCH/USD","bids":[{"price":461.47,"qty":1.31449400}],"asks":[],"checksum":2232865674,"timestamp":"2024-06-01T18:06:01.307764Z"}]}
{"channel":"book","type":"update","data":[{"symbol":"BCH/USD","bids":[{"price":461.42,"qty":0.00000000},{"price":461.36,"qty":0.88120000}],"asks":[],"checksum":3316667614,"timestamp":"2024-06-01T18:06:01.307817Z"}]}
{"channel":"book","type":"update","data":[{"symbol":"BCH/USD","bids":[{"price":461.48,"qty":1.76240000}],"asks":[],"checksum":1976834426,"timestamp":"2024-06-01T18:06:01.309232Z"}]}
{"channel":"book","type":"update","data":[{"symbol":"BCH/USD","bids":[{"price":461.44,"qty":0.00000000},{"price":461.32,"qty":0.48194310}],"asks":[],"checksum":685050962,"timestamp":"2024-06-01T18:06:01.309247Z"}]}
{"channel":"book","type":"update","data":[{"symbol":"BCH/USD","bids":[{"price":461.47,"qty":0.43329400}],"asks":[],"checksum":471181553,"timestamp":"2024-06-01T18:06:01.309879Z"}]}
{"channel":"book","type":"update","data":[{"symbol":"BCH/USD","bids":[{"price":461.47,"qty":0.00000000},{"price":461.31,"qty":5.41930728}],"asks":[],"checksum":3035992410,"timestamp":"2024-06-01T18:06:01.313408Z"}]}
{"channel":"book","type":"update","data":[{"symbol":"BCH/USD","bids":[],"asks":[{"price":461.70,"qty":0.14726888}],"checksum":3561543928,"timestamp":"2024-06-01T18:06:01.318760Z"}]}
{"channel":"book","type":"update","data":[{"symbol":"BCH/USD","bids":[],"asks":[{"price":461.72,"qty":0.00000000},{"price":461.78,"qty":10.85000000}],"checksum":1143780438,"timestamp":"2024-06-01T18:06:01.347185Z"}]}
{"channel":"book","type":"update","data":[{"symbol":"BCH/USD","bids":[],"asks":[{"price":461.68,"qty":0.00000000},{"price":461.83,"qty":0.88120000}],"checksum":3741346009,"timestamp":"2024-06-01T18:06:01.347632Z"}]}
{"channel":"book","type":"update","data":[{"symbol":"BCH/USD","bids":[{"price":461.38,"qty":0.00000000},{"price":461.30,"qty":2.72189142}],"asks":[],"checksum":681043377,"timestamp":"2024-06-01T18:06:01.352838Z"}]}
{"channel":"book","type":"update","data":[{"symbol":"BCH/USD","bids":[{"price":461.49,"qty":0.43329398}],"asks":[],"checksum":1598421851,"timestamp":"2024-06-01T18:06:01.354216Z"}]}
{"channel":"book","type":"update","data":[{"symbol":"BCH/USD","bids":[{"price":461.51,"qty":0.88120000}],"asks":[],"checksum":43747367,"timestamp":"2024-06-01T18:06:01.358451Z"}]}
{"channel":"book","type":"update","data":[{"symbol":"BCH/USD","bids":[{"price":461.34,"qty":5.41891693}],"asks":[],"checksum":3361252192,"timestamp":"2024-06-01T18:06:01.412375Z"}]}
{"channel":"book","type":"update","data":[{"symbol":"BCH/USD","bids":[],"asks":[{"price":461.72,"qty":3.89332295}],"checksum":1379372864,"timestamp":"2024-06-01T18:06:01.559856Z"}]}
{"channel":"book","type":"update","data":[{"symbol":"BCH/USD","bids":[],"asks":[{"price":461.71,"qty":7.07000000}],"checksum":2678846769,"timestamp":"2024-06-01T18:06:01.564732Z"}]}
{"channel":"book","type":"update","data":[{"symbol":"BCH/USD","bids":[{"price":461.50,"qty":7.83392088}],"asks":[],"checksum":667165327,"timestamp":"2024-06-01T18:06:02.014648Z"}]}
{"channel":"book","type":"update","data":[{"symbol":"BCH/USD","bids":[{"price":461.45,"qty":0.43329552}],"asks":[],"checksum":238516246,"timestamp":"2024-06-01T18:06:02.018178Z"}]}
{"channel":"book","type":"update","data":[{"symbol":"BCH/USD","bids":[],"asks":[{"price":461.72,"qty":0.00000000},{"price":461.81,"qty":10.85000000}],"checksum":1782274575,"timestamp":"2024-06-01T18:06:02.876926Z"}]}
{"channel":"book","type":"update","data":[{"symbol":"BCH/USD","bids":[{"price":461.40,"qty":0.00000000},{"price":461.34,"qty":5.41891693}],"asks":[],"checksum":4222888627,"timestamp":"2024-06-01T18:06:02.876940Z"}]}
{"channel":"book","type":"update","data":[{"symbol":"BCH/USD","bids":[],"asks":[{"price":461.74,"qty":0.00000000},{"price":461.83,"qty":0.88120000}],"checksum":1843986025,"timestamp":"2024-06-01T18:06:02.877084Z"}]}
{"channel":"book","type":"update","data":[{"symbol":"BCH/USD","bids":[],"asks":[{"price":461.71,"qty":0.00000000},{"price":461.85,"qty":7.83392088}],"checksum":1586393803,"timestamp":"2024-06-01T18:06:02.877265Z"}]}
{"channel":"book","type":"update","data":[{"symbol":"BCH/USD","bids":[{"price":461.34,"qty":0.00000000},{"price":461.32,"qty":0.48194310}],"asks":[],"checksum":3722620269,"timestamp":"2024-06-01T18:06:02.883002Z"}]}
{"channel":"book","type":"update","data":[{"symbol":"BCH/USD","bids":[],"asks":[{"price":461.61,"qty":0.00000000},{"price":461.88,"qty":0.88120000}],"checksum":2088629555,"timestamp":"2024-06-01T18:06:02.883201Z"}]}
{"channel":"book","type":"update","data":[{"symbol":"BCH/USD","bids":[],"asks":[{"price":461.80,"qty":1.93648492}],"checksum":2402213120,"timestamp":"2024-06-01T18:06:02.887015Z"}]}
{"channel":"book","type":"update","data":[{"symbol":"BCH/USD","bids":[{"price":461.37,"qty":6.86956845}],"asks":[],"checksum":1123204772,"timestamp":"2024-06-01T18:06:02.888243Z"}]}
{"channel":"book","type":"update","data":[{"symbol":"BCH/USD","bids":[],"asks":[{"price":461.67,"qty":5.41519924}],"checksum":2942346600,"timestamp":"2024-06-01T18:06:02.888315Z"}]}
{"channel":"book","type":"update","data":[{"symbol":"BCH/USD","bids":[],"asks":[{"price":461.81,"qty":0.00000000},{"price":461.85,"qty":7.83392088},{"price":461.80,"qty":12.78648492}],"checksum":2526877490,"timestamp":"2024-06-01T18:06:02.890495Z"}]}
{"channel":"book","type":"update","data":[{"symbol":"BCH/USD","bids":[],"asks":[{"price":461.67,"qty":0.00000000},{"price":461.88,"qty":0.88120000}],"checksum":2334776298,"timestamp":"2024-06-01T18:06:02.895720Z"}]}
{"channel":"book","type":"update","data":[{"symbol":"BCH/USD","bids":[],"asks":[{"price":461.70,"qty":0.00000000},{"price":461.90,"qty":1.49448039}],"checksum":2786192928,"timestamp":"2024-06-01T18:06:02.901495Z"}]}
{"channel":"book","type":"update","data":[{"symbol":"BCH/USD","bids":[],"asks":[{"price":461.89,"qty":10.83000000}],"checksum":884200585,"timestamp":"2024-06-01T18:06:03.015210Z"}]}
{"channel":"book","type":"update","data":[{"symbol":"BCH/USD","bids":[],"asks":[{"price":461.68,"qty":0.14726888}],"checksum":110686276,"timestamp":"2024-06-01T18:06:03.025436Z"}]}
{"channel":"book","type":"update","data":[{"symbol":"BCH/USD","bids":[],"asks":[{"price":461.81,"qty":7.07000000}],"checksum":2905385461,"timestamp":"2024-06-01T18:06:03.030578Z"}]}
{"channel":"book","type":"update","data":[{"symbol":"BCH/USD","bids":[],"asks":[{"price":461.82,"qty":3.89332295}],"checksum":3487726060,"timestamp":"2024-06-01T18:06:03.030656Z"}]}
{"channel":"book","type":"update","data":[{"symbol":"BCH/USD","bids":[],"asks":[{"price":461.64,"qty":0.88120000}],"checksum":1181983903,"timestamp":"2024-06-01T18:06:03.057618Z"}]}
{"channel":"book","type":"update","data":[{"symbol":"BCH/USD","bids":[],"asks":[{"price":461.64,"qty":0.00000000},{"price":461.83,"qty":0.88120000}],"checksum":3487726060,"timestamp":"2024-06-01T18:06:03.061615Z"}]}
{"channel":"book","type":"update","data":[{"symbol":"BCH/USD","bids":[],"asks":[{"price":461.64,"qty":0.88120000}],"checksum":1181983903,"timestamp":"2024-06-01T18:06:03.070017Z"}]}
{"channel":"book","type":"update","data":[{"symbol":"BCH/USD","bids":[],"asks":[{"price":461.64,"qty":0.00000000},{"price":461.83,"qty":0.88120000}],"checksum":3487726060,"timestamp":"2024-06-01T18:06:03.073366Z"}]}
{"channel":"book","type":"update","data":[{"symbol":"BCH/USD","bids":[],"asks":[{"price":461.64,"qty":0.88120000}],"checksum":1181983903,"timestamp":"2024-06-01T18:06:03.076249Z"}]}
{"channel":"book","type":"update","data":[{"symbol":"BCH/USD","bids":[],"asks":[{"price":461.64,"qty":0.00000000},{"price":461.83,"qty":0.88120000}],"checksum":3487726060,"timestamp":"2024-06-01T18:06:03.080308Z"}]}
{"channel":"book","type":"update","data":[{"symbol":"BCH/USD","bids":[],"asks":[{"price":461.64,"qty":0.88120000}],"checksum":1181983903,"timestamp":"2024-06-01T18:06:03.083277Z"}]}
{"channel":"book","type":"update","data":[{"symbol":"BCH/USD","bids":[],"asks":[{"price":461.64,"qty":0.00000000},{"price":461.83,"qty":0.88120000}],"checksum":3487726060,"timestamp":"2024-06-01T18:06:03.086369Z"}]}
{"channel":"book","type":"update","data":[{"symbol":"BCH/USD","bids":[],"asks":[{"price":461.64,"qty":0.88120000}],"checksum":1181983903,"timestamp":"2024-06-01T18:06:03.089852Z"}]}
{"channel":"book","type":"update","data":[{"symbol":"BCH/USD","bids":[],"asks":[{"price":461.64,"qty":0.00000000},{"price":461.83,"qty":0.88120000}],"checksum":3487726060,"timestamp":"2024-06-01T18:06:03.093977Z"}]}
{"channel":"book","type":"update","data":[{"symbol":"BCH/USD","bids":[],"asks":[{"price":461.64,"qty":0.88120000}],"checksum":1181983903,"timestamp":"2024-06-01T18:06:03.100885Z"}]}
{"channel":"book","type":"update","data":[{"symbol":"BCH/USD","bids":[],"asks":[{"price":461.64,"qty":0.00000000},{"price":461.83,"qty":0.88120000}],"checksum":3487726060,"timestamp":"2024-06-01T18:06:03.104837Z"}]}
{"channel":"book","type":"update","data":[{"symbol":"BCH/USD","bids":[],"asks":[{"price":461.64,"qty":0.88120000}],"checksum":1181983903,"timestamp":"2024-06-01T18:06:03.107792Z"}]}
{"channel":"book","type":"update","data":[{"symbol":"BCH/USD","bids":[],"asks":[{"price":461.64,"qty":0.00000000},{"price":461.83,"qty":0.88120000}],"checksum":3487726060,"timestamp":"2024-06-01T18:06:03.111696Z"}]}
{"channel":"book","type":"update","data":[{"symbol":"BCH/USD","bids":[],"asks":[{"price":461.64,"qty":0.88120000}],"checksum":1181983903,"timestamp":"2024-06-01T18:06:03.115077Z"}]}
{"channel":"book","type":"update","data":[{"symbol":"BCH/USD","bids":[],"asks":[{"price":461.64,"qty":0.00000000},{"price":461.83,"qty":0.88120000}],"checksum":3487726060,"timestamp":"2024-06-01T18:06:03.118740Z"}]}
{"channel":"book","type":"update","data":[{"symbol":"BCH/USD","bids":[],"asks":[{"price":461.64,"qty":0.88120000}],"checksum":1181983903,"timestamp":"2024-06-01T18:06:03.121252Z"}]}
{"channel":"book","type":"update","data":[{"symbol":"BCH/USD","bids":[],"asks":[{"price":461.64,"qty":0.00000000},{"price":461.83,"qty":0.88120000}],"checksum":3487726060,"timestamp":"2024-06-01T18:06:03.125085Z"}]}
{"channel":"book","type":"update","data":[{"symbol":"BCH/USD","bids":[],"asks":[{"price":461.64,"qty":0.88120000}],"checksum":1181983903,"timestamp":"2024-06-01T18:06:03.128189Z"}]}
{"channel":"book","type":"update","data":[{"symbol":"BCH/USD","bids":[],"asks":[{"price":461.64,"qty":0.00000000},{"price":461.83,"qty":0.88120000}],"checksum":3487726060,"timestamp":"2024-06-01T18:06:03.131231Z"}]}
{"channel":"book","type":"update","data":[{"symbol":"BCH/USD","bids":[],"asks":[{"price":461.64,"qty":0.88120000}],"checksum":1181983903,"timestamp":"2024-06-01T18:06:03.136113Z"}]}
{"channel":"book","type":"update","data":[{"symbol":"BCH/USD","bids":[],"asks":[{"price":461.64,"qty":0.00000000},{"price":461.83,"qty":0.88120000}],"checksum":3487726060,"timestamp":"2024-06-01T18:06:03.140681Z"}]}
{"channel":"book","type":"update","data":[{"symbol":"BCH/USD","bids":[],"asks":[{"price":461.64,"qty":0.88120000}],"checksum":1181983903,"timestamp":"2024-06-01T18:06:03.144134Z"}]}
{"channel":"book","type":"update","data":[{"symbol":"BCH/USD","bids":[],"asks":[{"price":461.64,"qty":0.00000000},{"price":461.83,"qty":0.88120000}],"checksum":3487726060,"timestamp":"2024-06-01T18:06:03.147796Z"}]}
{"channel":"book","type":"update","data":[{"symbol":"BCH/USD","bids":[],"asks":[{"price":461.64,"qty":0.88120000}],"checksum":1181983903,"timestamp":"2024-06-01T18:06:03.150884Z"}]}
{"channel":"book","type":"update","data":[{"symbol":"BCH/USD","bids":[],"asks":[{"price":461.64,"qty":0.00000000},{"price":461.83,"qty":0.88120000}],"checksum":3487726060,"timestamp":"2024-06-01T18:06:03.154290Z"}]}
{"channel":"book","type":"update","data":[{"symbol":"BCH/USD","bids":[],"asks":[{"price":461.64,"qty":0.88120000}],"checksum":1181983903,"timestamp":"2024-06-01T18:06:03.158011Z"}]}
{"channel":"book","type":"update","data":[{"symbol":"BCH/USD","bids":[],"asks":[{"price":461.64,"qty":0.00000000},{"price":461.83,"qty":0.88120000}],"checksum":3487726060,"timestamp":"2024-06-01T18:06:03.161821Z"}]}
{"channel":"book","type":"update","data":[{"symbol":"BCH/USD","bids":[],"asks":[{"price":461.64,"qty":0.88120000}],"checksum":1181983903,"timestamp":"2024-06-01T18:06:03.165043Z"}]}
{"channel":"book","type":"update","data":[{"symbol":"BCH/USD","bids":[],"asks":[{"price":461.64,"qty":0.00000000},{"price":461.83,"qty":0.88120000}],"checksum":3487726060,"timestamp":"2024-06-01T18:06:03.169080Z"}]}
{"channel":"book","type":"update","data":[{"symbol":"BCH/USD","bids":[],"asks":[{"price":461.64,"qty":0.88120000}],"checksum":1181983903,"timestamp":"2024-06-01T18:06:03.171546Z"}]}
{"channel":"book","type":"update","data":[{"symbol":"BCH/USD","bids":[],"asks":[{"price":461.64,"qty":0.00000000},{"price":461.83,"qty":0.88120000}],"checksum":3487726060,"timestamp":"2024-06-01T18:06:03.174849Z"}]}
{"channel":"book","type":"update","data":[{"symbol":"BCH/USD","bids":[],"asks":[{"price":461.64,"qty":0.88120000}],"checksum":1181983903,"timestamp":"2024-06-01T18:06:03.177893Z"}]}
{"channel":"book","type":"update","data":[{"symbol":"BCH/USD","bids":[],"asks":[{"price":461.64,"qty":0.00000000},{"price":461.83,"qty":0.88120000}],"checksum":3487726060,"timestamp":"2024-06-01T18:06:03.181568Z"}]}
{"channel":"book","type":"update","data":[{"symbol":"BCH/USD","bids":[],"asks":[{"price":461.64,"qty":0.88120000}],"checksum":1181983903,"timestamp":"2024-06-01T18:06:03.184417Z"}]}
{"channel":"book","type":"update","data":[{"symbol":"BCH/USD","bids":[],"asks":[{"price":461.64,"qty":0.00000000},{"price":461.83,"qty":0.88120000}],"checksum":3487726060,"timestamp":"2024-06-01T18:06:03.188044Z"}]}
{"channel":"book","type":"update","data":[{"symbol":"BCH/USD","bids":[],"asks":[{"price":461.64,"qty":0.88120000}],"checksum":1181983903,"timestamp":"2024-06-01T18:06:03.191475Z"}]}
{"channel":"book","type":"update","data":[{"symbol":"BCH/USD","bids":[],"asks":[{"price":461.64,"qty":0.00000000},{"price":461.83,"qty":0.88120000}],"checksum":3487726060,"timestamp":"2024-06-01T18:06:03.195795Z"}]}
{"channel":"book","type":"update","data":[{"symbol":"BCH/USD","bids":[],"asks":[{"price":461.64,"qty":0.88120000}],"checksum":1181983903,"timestamp":"2024-06-01T18:06:03.198694Z"}]}
{"channel":"book","type":"update","data":[{"symbol":"BCH/USD","bids":[],"asks":[{"price":461.64,"qty":0.00000000},{"price":461.83,"qty":0.88120000}],"checksum":3487726060,"timestamp":"2024-06-01T18:06:03.203229Z"}]}
{"channel":"book","type":"update","data":[{"symbol":"BCH/USD","bids":[],"asks":[{"price":461.64,"qty":0.88120000}],"checksum":1181983903,"timestamp":"2024-06-01T18:06:03.322738Z"}]}
{"channel":"book","type":"update","data":[{"symbol":"BCH/USD","bids":[],"asks":[{"price":461.64,"qty":0.00000000},{"price":461.83,"qty":0.88120000}],"checksum":3487726060,"timestamp":"2024-06-01T18:06:03.326503Z"}]}
