{"channel":"book","type":"snapshot","data":[{"symbol":"BCH/USDT","bids":[{"price":461.81,"qty":0.90000000},{"price":461.76,"qty":7.83392088},{"price":461.75,"qty":6.80879832},{"price":461.67,"qty":0.60087018},{"price":461.60,"qty":5.87074462},{"price":461.02,"qty":6.49382922},{"price":461.01,"qty":0.76032560},{"price":461.00,"qty":1.25032000},{"price":460.77,"qty":1.13015634},{"price":460.75,"qty":1.12000000}],"asks":[{"price":462.07,"qty":0.90000000},{"price":462.08,"qty":0.76032560},{"price":462.15,"qty":7.83392088},{"price":462.16,"qty":0.04431792},{"price":462.17,"qty":0.08972479},{"price":462.18,"qty":0.06585657},{"price":462.19,"qty":6.80879832},{"price":462.20,"qty":1.31097891},{"price":462.47,"qty":0.07227727},{"price":462.49,"qty":0.08963605}],"checksum":3669253694}]}
{"channel":"book","type":"update","data":[{"symbol":"BCH/USDT","bids":[{"price":461.81,"qty":0.00000000},{"price":460.54,"qty":1.36603240}],"asks":[],"checksum":3521124757,"timestamp":"2024-06-01T18:05:40.087866Z"}]}
{"channel":"book","type":"update","data":[{"symbol":"BCH/USDT","bids":[{"price":461.77,"qty":0.90000000}],"asks":[],"checksum":2696220271,"timestamp":"2024-06-01T18:05:40.093010Z"}]}
{"channel":"book","type":"update","data":[{"symbol":"BCH/USDT","bids":[{"price":461.78,"qty":1.01816978}],"asks":[],"checksum":2904050485,"timestamp":"2024-06-01T18:05:40.549621Z"}]}
{"channel":"book","type":"update","data":[{"symbol":"BCH/USDT","bids":[{"price":461.78,"qty":8.85209066}],"asks":[],"checksum":1888826382,"timestamp":"2024-06-01T18:05:40.553500Z"}]}
{"channel":"book","type":"update","data":[{"symbol":"BCH/USDT","bids":[{"price":461.79,"qty":0.90000000}],"asks":[],"checksum":273668002,"timestamp":"2024-06-01T18:05:40.554934Z"}]}
{"channel":"book","type":"update","data":[{"symbol":"BCH/USDT","bids":[{"price":461.78,"qty":7.83392088}],"asks":[],"checksum":467705927,"timestamp":"2024-06-01T18:05:40.559050Z"}]}
{"channel":"book","type":"update","data":[{"symbol":"BCH/USDT","bids":[{"price":461.77,"qty":0.00000000},{"price":460.77,"qty":1.13015634}],"asks":[],"checksum":4130396624,"timestamp":"2024-06-01T18:05:40.588966Z"}]}
{"channel":"book","type":"update","data":[{"symbol":"BCH/USDT","bids":[{"price":461.78,"qty":0.00000000},{"price":460.75,"qty":1.12000000}],"asks":[],"checksum":39557339,"timestamp":"2024-06-01T18:05:40.592678Z"}]}
{"channel":"book","type":"update","data":[{"symbol":"BCH/USDT","bids":[{"price":461.79,"qty":0.00000000},{"price":460.54,"qty":1.36603240}],"asks":[],"checksum":3521124757,"timestamp":"2024-06-01T18:05:41.089309Z"}]}
{"channel":"book","type":"update","data":[{"symbol":"BCH/USDT","bids":[{"price":461.77,"qty":0.90000000}],"asks":[],"checksum":2696220271,"timestamp":"2024-06-01T18:05:41.587127Z"}]}
{"channel":"book","type":"update","data":[{"symbol":"BCH/USDT","bids":[{"price":461.78,"qty":1.01850727}],"asks":[],"checksum":2997048674,"timestamp":"2024-06-01T18:05:41.591983Z"}]}
{"channel":"book","type":"update","data":[{"symbol":"BCH/USDT","bids":[{"price":461.78,"qty":8.85242815}],"asks":[],"checksum":2791084777,"timestamp":"2024-06-01T18:05:42.012998Z"}]}
{"channel":"book","type":"update","data":[{"symbol":"BCH/USDT","bids":[{"price":461.76,"qty":0.00000000},{"price":460.75,"qty":1.12000000}],"asks":[],"checksum":3517110888,"timestamp":"2024-06-01T18:05:42.016201Z"}]}
{"channel":"book","type":"update","data":[{"symbol":"BCH/USDT","bids":[{"price":461.79,"qty":0.90000000}],"asks":[],"checksum":2281538357,"timestamp":"2024-06-01T18:05:42.018047Z"}]}
{"channel":"book","type":"update","data":[{"symbol":"BCH/USDT","bids":[{"price":461.78,"qty":7.83392088}],"asks":[],"checksum":499925798,"timestamp":"2024-06-01T18:05:42.022495Z"}]}
{"channel":"book","type":"update","data":[{"symbol":"BCH/USDT","bids":[{"price":461.80,"qty":1.01850727}],"asks":[],"checksum":754635150,"timestamp":"2024-06-01T18:05:42.022619Z"}]}
{"channel":"book","type":"update","data":[{"symbol":"BCH/USDT","bids":[{"price":461.79,"qty":0.00000000},{"price":460.77,"qty":1.13015634}],"asks":[],"checksum":2385087007,"timestamp":"2024-06-01T18:05:42.087430Z"}]}
{"channel":"book","type":"update","data":[{"symbol":"BCH/USDT","bids":[{"price":461.79,"qty":7.83392088}],"asks":[],"checksum":1159913106,"timestamp":"2024-06-01T18:05:42.091392Z"}]}
{"channel":"book","type":"update","data":[{"symbol":"BCH/USDT","bids":[{"price":461.78,"qty":0.00000000},{"price":460.77,"qty":1.13015634}],"asks":[],"checksum":3836468305,"timestamp":"2024-06-01T18:05:42.511401Z"}]}
{"channel":"book","type":"update","data":[{"symbol":"BCH/USDT","bids":[{"price":461.81,"qty":0.90000000}],"asks":[],"checksum":3472326949,"timestamp":"2024-06-01T18:05:42.517030Z"}]}
{"channel":"book","type":"update","data":[{"symbol":"BCH/USDT","bids":[{"price":461.80,"qty":0.00000000},{"price":460.77,"qty":1.13015634}],"asks":[],"checksum":2510498496,"timestamp":"2024-06-01T18:05:42.521933Z"}]}
{"channel":"book","type":"update","data":[{"symbol":"BCH/USDT","bids":[{"price":461.82,"qty":1.03771474}],"asks":[],"checksum":1112783210,"timestamp":"2024-06-01T18:05:42.521956Z"}]}
{"channel":"book","type":"update","data":[{"symbol":"BCH/USDT","bids":[{"price":461.81,"qty":0.00000000},{"price":460.77,"qty":1.13015634}],"asks":[],"checksum":3279767886,"timestamp":"2024-06-01T18:05:42.589095Z"}]}
{"channel":"book","type":"update","data":[{"symbol":"BCH/USDT","bids":[{"price":461.79,"qty":0.00000000},{"price":460.75,"qty":1.12000000}],"asks":[],"checksum":979652121,"timestamp":"2024-06-01T18:05:42.592896Z"}]}
{"channel":"book","type":"update","data":[{"symbol":"BCH/USDT","bids":[{"price":461.78,"qty":7.83392088}],"asks":[],"checksum":2852069120,"timestamp":"2024-06-01T18:05:42.593047Z"}]}
{"channel":"book","type":"update","data":[{"symbol":"BCH/USDT","bids":[{"price":461.83,"qty":0.90000000}],"asks":[],"checksum":3774541015,"timestamp":"2024-06-01T18:05:43.588947Z"}]}
{"channel":"book","type":"update","data":[{"symbol":"BCH/USDT","bids":[{"price":461.77,"qty":0.00000000},{"price":460.77,"qty":1.13015634}],"asks":[],"checksum":4113803684,"timestamp":"2024-06-01T18:05:43.593440Z"}]}
{"channel":"book","type":"update","data":[{"symbol":"BCH/USDT","bids":[{"price":461.82,"qty":0.00000000},{"price":460.75,"qty":1.12000000}],"asks":[],"checksum":1656077704,"timestamp":"2024-06-01T18:05:43.593966Z"}]}
{"channel":"book","type":"update","data":[{"symbol":"BCH/USDT","bids":[{"price":461.84,"qty":0.89141466}],"asks":[],"checksum":3933875818,"timestamp":"2024-06-01T18:05:43.594011Z"}]}
{"channel":"book","type":"update","data":[{"symbol":"BCH/USDT","bids":[],"asks":[{"price":462.14,"qty":0.60407019}],"checksum":2849972106,"timestamp":"2024-06-01T18:05:48.855104Z"}]}
{"channel":"book","type":"update","data":[{"symbol":"BCH/USDT","bids":[],"asks":[{"price":462.14,"qty":0.00000000},{"price":462.49,"qty":0.08963605}],"checksum":3933875818,"timestamp":"2024-06-01T18:05:48.859181Z"}]}
{"channel":"book","type":"update","data":[{"symbol":"BCH/USDT","bids":[],"asks":[{"price":462.14,"qty":0.60407019}],"checksum":2849972106,"timestamp":"2024-06-01T18:05:48.863569Z"}]}
{"channel":"book","type":"update","data":[{"symbol":"BCH/USDT","bids":[],"asks":[{"price":462.14,"qty":0.00000000},{"price":462.49,"qty":0.08963605}],"checksum":3933875818,"timestamp":"2024-06-01T18:05:48.868549Z"}]}
{"channel":"book","type":"update","data":[{"symbol":"BCH/USDT","bids":[],"asks":[{"price":462.14,"qty":0.60407019}],"checksum":2849972106,"timestamp":"2024-06-01T18:05:48.873257Z"}]}
{"channel":"book","type":"update","data":[{"symbol":"BCH/USDT","bids":[],"asks":[{"price":462.14,"qty":0.00000000},{"price":462.49,"qty":0.08963605}],"checksum":3933875818,"timestamp":"2024-06-01T18:05:48.878105Z"}]}
{"channel":"book","type":"update","data":[{"symbol":"BCH/USDT","bids":[],"asks":[{"price":462.14,"qty":0.60407019}],"checksum":2849972106,"timestamp":"2024-06-01T18:05:48.882637Z"}]}
{"channel":"book","type":"update","data":[{"symbol":"BCH/USDT","bids":[],"asks":[{"price":462.14,"qty":0.00000000},{"price":462.49,"qty":0.08963605}],"checksum":3933875818,"timestamp":"2024-06-01T18:05:48.887295Z"}]}
{"channel":"book","type":"update","data":[{"symbol":"BCH/USDT","bids":[],"asks":[{"price":462.14,"qty":0.60407019}],"checksum":2849972106,"timestamp":"2024-06-01T18:05:48.891235Z"}]}
{"channel":"book","type":"update","data":[{"symbol":"BCH/USDT","bids":[],"asks":[{"price":462.14,"qty":0.00000000},{"price":462.49,"qty":0.08963605}],"checksum":3933875818,"timestamp":"2024-06-01T18:05:48.895123Z"}]}
{"channel":"book","type":"update","data":[{"symbol":"BCH/USDT","bids":[],"asks":[{"price":462.14,"qty":0.60407019}],"checksum":2849972106,"timestamp":"2024-06-01T18:05:48.899601Z"}]}
{"channel":"book","type":"update","data":[{"symbol":"BCH/USDT","bids":[],"asks":[{"price":462.14,"qty":0.00000000},{"price":462.49,"qty":0.08963605}],"checksum":3933875818,"timestamp":"2024-06-01T18:05:48.904224Z"}]}
{"channel":"book","type":"update","data":[{"symbol":"BCH/USDT","bids":[],"asks":[{"price":462.07,"qty":1.50407019}],"checksum":3328466695,"timestamp":"2024-06-01T18:05:48.908768Z"}]}
{"channel":"book","type":"update","data":[{"symbol":"BCH/USDT","bids":[],"asks":[{"price":462.07,"qty":0.90000000}],"checksum":3933875818,"timestamp":"2024-06-01T18:05:49.643265Z"}]}
{"channel":"book","type":"update","data":[{"symbol":"BCH/USDT","bids":[{"price":461.84,"qty":0.00000000},{"price":460.75,"qty":1.12000000}],"asks":[],"checksum":1656077704,"timestamp":"2024-06-01T18:05:49.647922Z"}]}
{"channel":"book","type":"update","data":[{"symbol":"BCH/USDT","bids":[{"price":461.60,"qty":0.00000000},{"price":460.54,"qty":1.36603240}],"asks":[],"checksum":3675907581,"timestamp":"2024-06-01T18:05:49.651358Z"}]}
{"channel":"book","type":"update","data":[{"symbol":"BCH/USDT","bids":[{"price":461.70,"qty":0.84150546}],"asks":[],"checksum":1822952079,"timestamp":"2024-06-01T18:05:49.654340Z"}]}
{"channel":"book","type":"update","data":[{"symbol":"BCH/USDT","bids":[{"price":461.76,"qty":7.83392088}],"asks":[],"checksum":1221976863,"timestamp":"2024-06-01T18:05:50.009693Z"}]}
{"channel":"book","type":"update","data":[{"symbol":"BCH/USDT","bids":[{"price":461.78,"qty":0.00000000},{"price":460.75,"qty":1.12000000}],"asks":[],"checksum":707020696,"timestamp":"2024-06-01T18:05:50.009921Z"}]}
{"channel":"book","type":"update","data":[{"symbol":"BCH/USDT","bids":[{"price":461.79,"qty":0.90000000}],"asks":[],"checksum":3170362278,"timestamp":"2024-06-01T18:05:50.015154Z"}]}
{"channel":"book","type":"update","data":[{"symbol":"BCH/USDT","bids":[{"price":461.83,"qty":0.00000000},{"price":460.75,"qty":1.12000000}],"asks":[],"checksum":839093264,"timestamp":"2024-06-01T18:05:50.015186Z"}]}
{"channel":"book","type":"update","data":[{"symbol":"BCH/USDT","bids":[{"price":461.79,"qty":0.00000000},{"price":460.54,"qty":1.36603240}],"asks":[],"checksum":2662685227,"timestamp":"2024-06-01T18:05:50.086636Z"}]}
{"channel":"book","type":"update","data":[{"symbol":"BCH/USDT","bids":[{"price":461.77,"qty":0.90000000}],"asks":[],"checksum":3152300595,"timestamp":"2024-06-01T18:05:50.086814Z"}]}
{"channel":"book","type":"update","data":[{"symbol":"BCH/USDT","bids":[{"price":461.78,"qty":0.89954499}],"asks":[],"checksum":2207493961,"timestamp":"2024-06-01T18:05:50.674049Z"}]}
{"channel":"book","type":"update","data":[{"symbol":"BCH/USDT","bids":[{"price":461.78,"qty":8.73346587}],"asks":[],"checksum":4188744900,"timestamp":"2024-06-01T18:05:50.679687Z"}]}
{"channel":"book","type":"update","data":[{"symbol":"BCH/USDT","bids":[{"price":461.79,"qty":0.90000000}],"asks":[],"checksum":1211922993,"timestamp":"2024-06-01T18:05:50.682035Z"}]}
{"channel":"book","type":"update","data":[{"symbol":"BCH/USDT","bids":[],"asks":[{"price":462.20,"qty":0.00000000},{"price":462.58,"qty":1.36603240}],"checksum":2103311612,"timestamp":"2024-06-01T18:05:50.683530Z"}]}
{"channel":"book","type":"update","data":[{"symbol":"BCH/USDT","bids":[{"price":461.80,"qty":0.91878736}],"asks":[],"checksum":3271300332,"timestamp":"2024-06-01T18:05:50.687034Z"}]}
{"channel":"book","type":"update","data":[{"symbol":"BCH/USDT","bids":[],"asks":[{"price":462.14,"qty":0.60407019}],"checksum":1199858429,"timestamp":"2024-06-01T18:05:50.698928Z"}]}
{"channel":"book","type":"update","data":[{"symbol":"BCH/USDT","bids":[],"asks":[{"price":462.14,"qty":0.00000000},{"price":462.58,"qty":1.36603240}],"checksum":3271300332,"timestamp":"2024-06-01T18:05:50.703162Z"}]}
{"channel":"book","type":"update","data":[{"symbol":"BCH/USDT","bids":[],"asks":[{"price":462.14,"qty":0.60407019}],"checksum":1199858429,"timestamp":"2024-06-01T18:05:50.712479Z"}]}
{"channel":"book","type":"update","data":[{"symbol":"BCH/USDT","bids":[],"asks":[{"price":462.14,"qty":0.00000000},{"price":462.58,"qty":1.36603240}],"checksum":3271300332,"timestamp":"2024-06-01T18:05:50.717067Z"}]}
{"channel":"book","type":"update","data":[{"symbol":"BCH/USDT","bids":[{"price":461.78,"qty":0.89954499}],"asks":[],"checksum":3828257772,"timestamp":"2024-06-01T18:05:50.717273Z"}]}
{"channel":"book","type":"update","data":[{"symbol":"BCH/USDT","bids":[{"price":461.79,"qty":0.00000000},{"price":461.00,"qty":1.25032000}],"asks":[],"checksum":405909379,"timestamp":"2024-06-01T18:05:50.725458Z"}]}
{"channel":"book","type":"update","data":[{"symbol":"BCH/USDT","bids":[{"price":461.81,"qty":0.90000000}],"asks":[],"checksum":3705283804,"timestamp":"2024-06-01T18:05:50.725534Z"}]}
{"channel":"book","type":"update","data":[{"symbol":"BCH/USDT","bids":[{"price":461.80,"qty":0.00000000},{"price":461.00,"qty":1.25032000}],"asks":[],"checksum":1926603942,"timestamp":"2024-06-01T18:05:50.730193Z"}]}
{"channel":"book","type":"update","data":[{"symbol":"BCH/USDT","bids":[{"price":461.79,"qty":7.83392088}],"asks":[],"checksum":2231147888,"timestamp":"2024-06-01T18:05:51.012959Z"}]}
{"channel":"book","type":"update","data":[{"symbol":"BCH/USDT","bids":[{"price":461.77,"qty":0.00000000},{"price":461.00,"qty":1.25032000}],"asks":[],"checksum":439764829,"timestamp":"2024-06-01T18:05:51.017920Z"}]}
{"channel":"book","type":"update","data":[{"symbol":"BCH/USDT","bids":[{"price":461.76,"qty":0.00000000},{"price":460.77,"qty":1.13015634}],"asks":[],"checksum":212478839,"timestamp":"2024-06-01T18:05:51.510299Z"}]}
{"channel":"book","type":"update","data":[{"symbol":"BCH/USDT","bids":[{"price":461.81,"qty":0.00000000},{"price":460.75,"qty":1.12000000}],"asks":[],"checksum":2076669859,"timestamp":"2024-06-01T18:05:51.515351Z"}]}
{"channel":"book","type":"update","data":[{"symbol":"BCH/USDT","bids":[{"price":461.80,"qty":0.90000000}],"asks":[],"checksum":1850641144,"timestamp":"2024-06-01T18:05:51.515381Z"}]}
{"channel":"book","type":"update","data":[{"symbol":"BCH/USDT","bids":[{"price":461.81,"qty":0.87249109}],"asks":[],"checksum":1964767214,"timestamp":"2024-06-01T18:05:51.728851Z"}]}
{"channel":"book","type":"update","data":[{"symbol":"BCH/USDT","bids":[{"price":461.81,"qty":8.70641197}],"asks":[],"checksum":1096175606,"timestamp":"2024-06-01T18:05:51.732999Z"}]}
{"channel":"book","type":"update","data":[{"symbol":"BCH/USDT","bids":[{"price":461.82,"qty":0.90000000}],"asks":[],"checksum":823550753,"timestamp":"2024-06-01T18:05:51.733713Z"}]}
{"channel":"book","type":"update","data":[{"symbol":"BCH/USDT","bids":[{"price":461.81,"qty":7.83392088}],"asks":[],"checksum":3559810405,"timestamp":"2024-06-01T18:05:51.738184Z"}]}
{"channel":"book","type":"update","data":[{"symbol":"BCH/USDT","bids":[{"price":461.78,"qty":0.00000000},{"price":461.00,"qty":1.25032000}],"asks":[],"checksum":2914449610,"timestamp":"2024-06-01T18:05:51.738212Z"}]}
{"channel":"book","type":"update","data":[{"symbol":"BCH/USDT","bids":[{"price":461.81,"qty":0.00000000},{"price":460.77,"qty":1.13015634}],"asks":[],"checksum":2320789712,"timestamp":"2024-06-01T18:05:52.010221Z"}]}
{"channel":"book","type":"update","data":[{"symbol":"BCH/USDT","bids":[{"price":461.82,"qty":0.00000000},{"price":460.75,"qty":1.12000000}],"asks":[],"checksum":1684344186,"timestamp":"2024-06-01T18:05:52.014918Z"}]}
{"channel":"book","type":"update","data":[{"symbol":"BCH/USDT","bids":[{"price":461.79,"qty":0.00000000},{"price":460.54,"qty":1.36603240}],"asks":[],"checksum":2865160267,"timestamp":"2024-06-01T18:05:52.510318Z"}]}
{"channel":"book","type":"update","data":[{"symbol":"BCH/USDT","bids":[{"price":461.76,"qty":7.83392088}],"asks":[],"checksum":1214977571,"timestamp":"2024-06-01T18:05:52.510570Z"}]}
{"channel":"book","type":"update","data":[{"symbol":"BCH/USDT","bids":[{"price":461.80,"qty":0.00000000},{"price":460.54,"qty":1.36603240}],"asks":[],"checksum":3829063772,"timestamp":"2024-06-01T18:05:52.515493Z"}]}
{"channel":"book","type":"update","data":[{"symbol":"BCH/USDT","bids":[{"price":461.76,"qty":8.73392088}],"asks":[],"checksum":1186020985,"timestamp":"2024-06-01T18:05:52.515533Z"}]}
{"channel":"book","type":"update","data":[{"symbol":"BCH/USDT","bids":[],"asks":[{"price":462.08,"qty":0.00000000},{"price":462.79,"qty":2.58370377}],"checksum":3253365081,"timestamp":"2024-06-01T18:05:52.802588Z"}]}
{"channel":"book","type":"update","data":[{"symbol":"BCH/USDT","bids":[],"asks":[{"price":462.23,"qty":0.76032560}],"checksum":2951750638,"timestamp":"2024-06-01T18:05:52.806173Z"}]}
{"channel":"book","type":"update","data":[{"symbol":"BCH/USDT","bids":[],"asks":[{"price":462.15,"qty":0.00000000},{"price":462.79,"qty":2.58370377}],"checksum":4078183311,"timestamp":"2024-06-01T18:05:52.806695Z"}]}
{"channel":"book","type":"update","data":[{"symbol":"BCH/USDT","bids":[],"asks":[{"price":462.07,"qty":0.00000000},{"price":462.80,"qty":1.19723000}],"checksum":2332542750,"timestamp":"2024-06-01T18:05:52.807798Z"}]}
{"channel":"book","type":"update","data":[{"symbol":"BCH/USDT","bids":[],"asks":[{"price":462.14,"qty":0.90000000}],"checksum":1997613516,"timestamp":"2024-06-01T18:05:52.808027Z"}]}
{"channel":"book","type":"update","data":[{"symbol":"BCH/USDT","bids":[],"asks":[{"price":462.15,"qty":0.90000000}],"checksum":1942525988,"timestamp":"2024-06-01T18:05:53.087016Z"}]}
{"channel":"book","type":"update","data":[{"symbol":"BCH/USDT","bids":[],"asks":[{"price":462.14,"qty":0.00000000},{"price":462.79,"qty":2.58370377}],"checksum":1224972022,"timestamp":"2024-06-01T18:05:53.087092Z"}]}
{"channel":"book","type":"update","data":[{"symbol":"BCH/USDT","bids":[],"asks":[{"price":462.16,"qty":3.04431792}],"checksum":182017556,"timestamp":"2024-06-01T18:05:53.208936Z"}]}
{"channel":"book","type":"update","data":[{"symbol":"BCH/USDT","bids":[],"asks":[{"price":462.19,"qty":3.80879832}],"checksum":3496343565,"timestamp":"2024-06-01T18:05:53.708527Z"}]}
{"channel":"book","type":"update","data":[{"symbol":"BCH/USDT","bids":[{"price":461.77,"qty":0.89068273}],"asks":[],"checksum":3146058245,"timestamp":"2024-06-01T18:05:53.765760Z"}]}
{"channel":"book","type":"update","data":[{"symbol":"BCH/USDT","bids":[{"price":461.78,"qty":0.90000000}],"asks":[],"checksum":994756610,"timestamp":"2024-06-01T18:05:53.770911Z"}]}
{"channel":"book","type":"update","data":[{"symbol":"BCH/USDT","bids":[{"price":461.79,"qty":0.89068273}],"asks":[],"checksum":536352261,"timestamp":"2024-06-01T18:05:53.776198Z"}]}
{"channel":"book","type":"update","data":[{"symbol":"BCH/USDT","bids":[{"price":461.79,"qty":8.72460361}],"asks":[],"checksum":3523547651,"timestamp":"2024-06-01T18:05:54.019623Z"}]}
{"channel":"book","type":"update","data":[{"symbol":"BCH/USDT","bids":[{"price":461.76,"qty":0.90000000}],"asks":[],"checksum":189273170,"timestamp":"2024-06-01T18:05:54.024045Z"}]}
{"channel":"book","type":"update","data":[{"symbol":"BCH/USDT","bids":[{"price":461.78,"qty":0.00000000},{"price":460.77,"qty":1.13015634}],"asks":[],"checksum":3835538732,"timestamp":"2024-06-01T18:05:54.024793Z"}]}
{"channel":"book","type":"update","data":[{"symbol":"BCH/USDT","bids":[{"price":461.80,"qty":0.90000000}],"asks":[],"checksum":1009037555,"timestamp":"2024-06-01T18:05:54.024945Z"}]}
{"channel":"book","type":"update","data":[{"symbol":"BCH/USDT","bids":[{"price":461.81,"qty":0.91388023}],"asks":[],"checksum":783675318,"timestamp":"2024-06-01T18:05:54.030208Z"}]}
{"channel":"book","type":"update","data":[{"symbol":"BCH/USDT","bids":[{"price":461.77,"qty":0.00000000},{"price":461.00,"qty":1.25032000}],"asks":[],"checksum":2670746425,"timestamp":"2024-06-01T18:05:54.030325Z"}]}
{"channel":"book","type":"update","data":[{"symbol":"BCH/USDT","bids":[{"price":461.80,"qty":0.00000000},{"price":460.77,"qty":1.13015634}],"asks":[],"checksum":1944826218,"timestamp":"2024-06-01T18:05:54.088392Z"}]}
{"channel":"book","type":"update","data":[{"symbol":"BCH/USDT","bids":[{"price":461.82,"qty":0.90000000}],"asks":[],"checksum":2110449500,"timestamp":"2024-06-01T18:05:54.088626Z"}]}
{"channel":"book","type":"update","data":[{"symbol":"BCH/USDT","bids":[{"price":461.81,"qty":0.00000000},{"price":460.77,"qty":1.13015634}],"asks":[],"checksum":3099597780,"timestamp":"2024-06-01T18:05:54.092390Z"}]}
{"channel":"book","type":"update","data":[{"symbol":"BCH/USDT","bids":[{"price":461.80,"qty":7.83392088}],"asks":[],"checksum":296594302,"timestamp":"2024-06-01T18:05:54.092552Z"}]}
{"channel":"book","type":"update","data":[{"symbol":"BCH/USDT","bids":[{"price":461.76,"qty":0.00000000},{"price":460.77,"qty":1.13015634}],"asks":[],"checksum":937803020,"timestamp":"2024-06-01T18:05:54.092865Z"}]}
{"channel":"book","type":"update","data":[{"symbol":"BCH/USDT","bids":[{"price":461.83,"qty":0.90693523}],"asks":[],"checksum":2596920779,"timestamp":"2024-06-01T18:05:54.093184Z"}]}
{"channel":"book","type":"update","data":[{"symbol":"BCH/USDT","bids":[],"asks":[{"price":462.14,"qty":0.60407019}],"checksum":3065671793,"timestamp":"2024-06-01T18:05:54.149027Z"}]}
{"channel":"book","type":"update","data":[{"symbol":"BCH/USDT","bids":[{"price":461.79,"qty":0.89068273}],"asks":[],"checksum":828516967,"timestamp":"2024-06-01T18:05:54.152763Z"}]}
{"channel":"book","type":"update","data":[{"symbol":"BCH/USDT","bids":[{"price":461.84,"qty":0.90000000}],"asks":[],"checksum":578149799,"timestamp":"2024-06-01T18:05:54.154267Z"}]}
{"channel":"book","type":"update","data":[{"symbol":"BCH/USDT","bids":[],"asks":[{"price":462.13,"qty":0.90000000}],"checksum":3917124008,"timestamp":"2024-06-01T18:05:54.154321Z"}]}
{"channel":"book","type":"update","data":[{"symbol":"BCH/USDT","bids":[{"price":461.79,"qty":0.00000000},{"price":461.00,"qty":1.25032000}],"asks":[],"checksum":733349382,"timestamp":"2024-06-01T18:05:54.158437Z"}]}
{"channel":"book","type":"update","data":[{"symbol":"BCH/USDT","bids":[],"asks":[{"price":462.14,"qty":0.00000000},{"price":462.58,"qty":1.36603240}],"checksum":3367423299,"timestamp":"2024-06-01T18:05:54.158662Z"}]}
{"channel":"book","type":"update","data":[{"symbol":"BCH/USDT","bids":[{"price":461.84,"qty":8.73392088}],"asks":[],"checksum":3669942851,"timestamp":"2024-06-01T18:05:54.512886Z"}]}
{"channel":"book","type":"update","data":[{"symbol":"BCH/USDT","bids":[],"asks":[{"price":462.13,"qty":0.00000000},{"price":462.79,"qty":2.58370377}],"checksum":141172822,"timestamp":"2024-06-01T18:05:54.517732Z"}]}
{"channel":"book","type":"update","data":[{"symbol":"BCH/USDT","bids":[{"price":461.82,"qty":0.00000000},{"price":460.77,"qty":1.13015634}],"asks":[],"checksum":3650403096,"timestamp":"2024-06-01T18:05:54.517853Z"}]}
{"channel":"book","type":"update","data":[{"symbol":"BCH/USDT","bids":[{"price":461.83,"qty":0.00000000},{"price":460.75,"qty":1.12000000}],"asks":[],"checksum":2298978018,"timestamp":"2024-06-01T18:05:54.522607Z"}]}
{"channel":"book","type":"update","data":[{"symbol":"BCH/USDT","bids":[{"price":461.84,"qty":0.90000000}],"asks":[],"checksum":218502854,"timestamp":"2024-06-01T18:05:55.010902Z"}]}
{"channel":"book","type":"update","data":[{"symbol":"BCH/USDT","bids":[{"price":461.84,"qty":0.00000000},{"price":460.54,"qty":1.36603240}],"asks":[],"checksum":149911161,"timestamp":"2024-06-01T18:05:55.017717Z"}]}
{"channel":"book","type":"update","data":[{"symbol":"BCH/USDT","bids":[{"price":461.81,"qty":0.90000000}],"asks":[],"checksum":1585939159,"timestamp":"2024-06-01T18:05:55.017805Z"}]}
{"channel":"book","type":"update","data":[{"symbol":"BCH/USDT","bids":[{"price":461.80,"qty":0.00000000},{"price":460.54,"qty":1.36603240}],"asks":[],"checksum":181231633,"timestamp":"2024-06-01T18:05:55.510902Z"}]}
{"channel":"book","type":"update","data":[{"symbol":"BCH/USDT","bids":[{"price":461.76,"qty":7.83392088}],"asks":[],"checksum":3898644089,"timestamp":"2024-06-01T18:05:55.511059Z"}]}
{"channel":"book","type":"update","data":[{"symbol":"BCH/USDT","bids":[{"price":461.81,"qty":0.00000000},{"price":460.54,"qty":1.36603240}],"asks":[],"checksum":1928209960,"timestamp":"2024-06-01T18:05:55.516079Z"}]}
{"channel":"book","type":"update","data":[{"symbol":"BCH/USDT","bids":[{"price":461.77,"qty":0.90000000}],"asks":[],"checksum":2204790770,"timestamp":"2024-06-01T18:05:55.516108Z"}]}
{"channel":"book","type":"update","data":[{"symbol":"BCH/USDT","bids":[{"price":461.78,"qty":0.89253523}],"asks":[],"checksum":2934483611,"timestamp":"2024-06-01T18:05:57.190862Z"}]}
{"channel":"book","type":"update","data":[{"symbol":"BCH/USDT","bids":[{"price":461.78,"qty":8.72645611}],"asks":[],"checksum":1286025169,"timestamp":"2024-06-01T18:05:57.194722Z"}]}
{"channel":"book","type":"update","data":[{"symbol":"BCH/USDT","bids":[{"price":461.79,"qty":0.90000000}],"asks":[],"checksum":3429378739,"timestamp":"2024-06-01T18:05:57.195809Z"}]}
{"channel":"book","type":"update","data":[{"symbol":"BCH/USDT","bids":[{"price":461.78,"qty":7.83392088}],"asks":[],"checksum":3794110682,"timestamp":"2024-06-01T18:05:57.200294Z"}]}
{"channel":"book","type":"update","data":[{"symbol":"BCH/USDT","bids":[{"price":461.80,"qty":0.89385523}],"asks":[],"checksum":3949956107,"timestamp":"2024-06-01T18:05:57.200538Z"}]}
{"channel":"book","type":"update","data":[{"symbol":"BCH/USDT","bids":[],"asks":[{"price":462.79,"qty":0.00000000},{"price":462.82,"qty":2.58370377}],"checksum":2466433756,"timestamp":"2024-06-01T18:05:57.487111Z"}]}
{"channel":"book","type":"update","data":[{"symbol":"BCH/USDT","bids":[{"price":461.76,"qty":0.00000000},{"price":460.77,"qty":1.13015634}],"asks":[],"checksum":3055913072,"timestamp":"2024-06-01T18:05:57.511747Z"}]}
{"channel":"book","type":"update","data":[{"symbol":"BCH/USDT","bids":[{"price":461.80,"qty":8.72777611}],"asks":[],"checksum":2192019366,"timestamp":"2024-06-01T18:05:57.520624Z"}]}
{"channel":"book","type":"update","data":[{"symbol":"BCH/USDT","bids":[{"price":461.79,"qty":0.00000000},{"price":460.75,"qty":1.12000000}],"asks":[],"checksum":497721655,"timestamp":"2024-06-01T18:05:57.526624Z"}]}
{"channel":"book","type":"update","data":[{"symbol":"BCH/USDT","bids":[{"price":461.81,"qty":0.90000000}],"asks":[],"checksum":1230389378,"timestamp":"2024-06-01T18:05:57.526824Z"}]}
{"channel":"book","type":"update","data":[{"symbol":"BCH/USDT","bids":[{"price":461.80,"qty":7.83392088}],"asks":[],"checksum":2070270123,"timestamp":"2024-06-01T18:05:57.530836Z"}]}
{"channel":"book","type":"update","data":[{"symbol":"BCH/USDT","bids":[{"price":461.10,"qty":1.28772000}],"asks":[],"checksum":3333966508,"timestamp":"2024-06-01T18:05:57.542384Z"}]}
{"channel":"book","type":"update","data":[{"symbol":"BCH/USDT","bids":[{"price":461.77,"qty":0.00000000},{"price":460.77,"qty":1.13015634}],"asks":[],"checksum":2582156936,"timestamp":"2024-06-01T18:05:57.587096Z"}]}
{"channel":"book","type":"update","data":[{"symbol":"BCH/USDT","bids":[{"price":461.78,"qty":0.00000000},{"price":460.75,"qty":1.12000000}],"asks":[],"checksum":2220425708,"timestamp":"2024-06-01T18:05:57.590796Z"}]}
{"channel":"book","type":"update","data":[{"symbol":"BCH/USDT","bids":[{"price":461.80,"qty":0.00000000},{"price":460.54,"qty":1.36603240}],"asks":[],"checksum":2696211901,"timestamp":"2024-06-01T18:05:58.011431Z"}]}
{"channel":"book","type":"update","data":[{"symbol":"BCH/USDT","bids":[{"price":461.76,"qty":7.83392088}],"asks":[],"checksum":851318082,"timestamp":"2024-06-01T18:05:58.011549Z"}]}
{"channel":"book","type":"update","data":[{"symbol":"BCH/USDT","bids":[{"price":461.81,"qty":0.00000000},{"price":460.54,"qty":1.36603240}],"asks":[],"checksum":2495066687,"timestamp":"2024-06-01T18:05:58.088920Z"}]}
{"channel":"book","type":"update","data":[{"symbol":"BCH/USDT","bids":[{"price":461.77,"qty":0.90000000}],"asks":[],"checksum":1505029321,"timestamp":"2024-06-01T18:05:58.089104Z"}]}
{"channel":"book","type":"update","data":[{"symbol":"BCH/USDT","bids":[{"price":461.78,"qty":0.89904523}],"asks":[],"checksum":689054930,"timestamp":"2024-06-01T18:05:58.592319Z"}]}
{"channel":"book","type":"update","data":[{"symbol":"BCH/USDT","bids":[{"price":461.78,"qty":8.73296611}],"asks":[],"checksum":4132263771,"timestamp":"2024-06-01T18:05:58.596240Z"}]}
{"channel":"book","type":"update","data":[{"symbol":"BCH/USDT","bids":[{"price":461.79,"qty":0.90000000}],"asks":[],"checksum":2579320780,"timestamp":"2024-06-01T18:05:58.597514Z"}]}
{"channel":"book","type":"update","data":[{"symbol":"BCH/USDT","bids":[{"price":461.78,"qty":7.83392088}],"asks":[],"checksum":904972305,"timestamp":"2024-06-01T18:05:58.601629Z"}]}
{"channel":"book","type":"update","data":[{"symbol":"BCH/USDT","bids":[{"price":461.76,"qty":0.00000000},{"price":460.77,"qty":1.13015634}],"asks":[],"checksum":3079612846,"timestamp":"2024-06-01T18:05:59.018218Z"}]}
{"channel":"book","type":"update","data":[{"symbol":"BCH/USDT","bids":[{"price":461.79,"qty":8.73392088}],"asks":[],"checksum":2539716638,"timestamp":"2024-06-01T18:05:59.021904Z"}]}
{"channel":"book","type":"update","data":[{"symbol":"BCH/USDT","bids":[{"price":461.77,"qty":0.00000000},{"price":460.75,"qty":1.12000000}],"asks":[],"checksum":1570650712,"timestamp":"2024-06-01T18:05:59.022896Z"}]}
{"channel":"book","type":"update","data":[{"symbol":"BCH/USDT","bids":[{"price":461.78,"qty":0.00000000},{"price":460.54,"qty":1.36603240}],"asks":[],"checksum":2300088240,"timestamp":"2024-06-01T18:05:59.509636Z"}]}
{"channel":"book","type":"update","data":[{"symbol":"BCH/USDT","bids":[{"price":461.76,"qty":7.83392088}],"asks":[],"checksum":454195023,"timestamp":"2024-06-01T18:05:59.514793Z"}]}
{"channel":"book","type":"update","data":[{"symbol":"BCH/USDT","bids":[{"price":461.79,"qty":0.90000000}],"asks":[],"checksum":3495111402,"timestamp":"2024-06-01T18:05:59.514832Z"}]}
{"channel":"book","type":"update","data":[{"symbol":"BCH/USDT","bids":[{"price":461.79,"qty":0.00000000},{"price":460.54,"qty":1.36603240}],"asks":[],"checksum":2495066687,"timestamp":"2024-06-01T18:05:59.589367Z"}]}
{"channel":"book","type":"update","data":[{"symbol":"BCH/USDT","bids":[{"price":461.77,"qty":0.90000000}],"asks":[],"checksum":1505029321,"timestamp":"2024-06-01T18:05:59.589503Z"}]}
{"channel":"book","type":"update","data":[{"symbol":"BCH/USDT","bids":[{"price":461.78,"qty":0.90066523}],"asks":[],"checksum":3794438467,"timestamp":"2024-06-01T18:05:59.682485Z"}]}
{"channel":"book","type":"update","data":[{"symbol":"BCH/USDT","bids":[{"price":461.78,"qty":8.73458611}],"asks":[],"checksum":1247311659,"timestamp":"2024-06-01T18:05:59.686552Z"}]}
{"channel":"book","type":"update","data":[{"symbol":"BCH/USDT","bids":[{"price":461.79,"qty":0.90000000}],"asks":[],"checksum":2958782622,"timestamp":"2024-06-01T18:05:59.687806Z"}]}
{"channel":"book","type":"update","data":[{"symbol":"BCH/USDT","bids":[{"price":461.78,"qty":7.83392088}],"asks":[],"checksum":904972305,"timestamp":"2024-06-01T18:05:59.692493Z"}]}
{"channel":"book","type":"update","data":[{"symbol":"BCH/USDT","bids":[],"asks":[{"price":462.17,"qty":0.00000000},{"price":462.83,"qty":0.06152197}],"checksum":497353960,"timestamp":"2024-06-01T18:05:59.925431Z"}]}
{"channel":"book","type":"update","data":[{"symbol":"BCH/USDT","bids":[{"price":461.76,"qty":0.00000000},{"price":460.77,"qty":1.13015634}],"asks":[],"checksum":2681922903,"timestamp":"2024-06-01T18:05:59.928614Z"}]}
{"channel":"book","type":"update","data":[{"symbol":"BCH/USDT","bids":[{"price":461.77,"qty":0.00000000},{"price":460.75,"qty":1.12000000}],"asks":[],"checksum":1385592969,"timestamp":"2024-06-01T18:05:59.930031Z"}]}
{"channel":"book","type":"update","data":[{"symbol":"BCH/USDT","bids":[],"asks":[{"price":462.16,"qty":0.04431792}],"checksum":3786928353,"timestamp":"2024-06-01T18:05:59.930187Z"}]}
{"channel":"book","type":"update","data":[{"symbol":"BCH/USDT","bids":[],"asks":[{"price":462.17,"qty":3.00000000}],"checksum":2323722029,"timestamp":"2024-06-01T18:05:59.930264Z"}]}
{"channel":"book","type":"update","data":[{"symbol":"BCH/USDT","bids":[{"price":461.78,"qty":0.00000000},{"price":460.54,"qty":1.36603240}],"asks":[],"checksum":1577556677,"timestamp":"2024-06-01T18:05:59.983163Z"}]}
{"channel":"book","type":"update","data":[{"symbol":"BCH/USDT","bids":[{"price":461.75,"qty":3.00000000}],"asks":[],"checksum":2181964504,"timestamp":"2024-06-01T18:06:00.295606Z"}]}
{"channel":"book","type":"update","data":[{"symbol":"BCH/USDT","bids":[{"price":461.75,"qty":0.00000000},{"price":460.53,"qty":2.44000000}],"asks":[],"checksum":2074098952,"timestamp":"2024-06-01T18:06:00.295632Z"}]}
{"channel":"book","type":"update","data":[{"symbol":"BCH/USDT","bids":[{"price":461.79,"qty":0.00000000},{"price":460.51,"qty":2.34000000}],"asks":[],"checksum":233584953,"timestamp":"2024-06-01T18:06:00.295779Z"}]}
{"channel":"book","type":"update","data":[{"symbol":"BCH/USDT","bids":[{"price":461.70,"qty":0.00000000},{"price":460.24,"qty":1.12000000}],"asks":[],"checksum":1020953367,"timestamp":"2024-06-01T18:06:00.296618Z"}]}
{"channel":"book","type":"update","data":[{"symbol":"BCH/USDT","bids":[{"price":461.60,"qty":1.51956156}],"asks":[],"checksum":1415587767,"timestamp":"2024-06-01T18:06:00.301368Z"}]}
{"channel":"book","type":"update","data":[{"symbol":"BCH/USDT","bids":[{"price":461.11,"qty":6.49256175}],"asks":[],"checksum":66573912,"timestamp":"2024-06-01T18:06:00.302821Z"}]}
{"channel":"book","type":"update","data":[{"symbol":"BCH/USDT","bids":[{"price":461.02,"qty":0.00000000},{"price":460.51,"qty":2.34000000}],"asks":[],"checksum":1411633459,"timestamp":"2024-06-01T18:06:00.302881Z"}]}
{"channel":"book","type":"update","data":[{"symbol":"BCH/USDT","bids":[],"asks":[{"price":462.14,"qty":3.80879832}],"checksum":1987999317,"timestamp":"2024-06-01T18:06:00.453094Z"}]}
{"channel":"book","type":"update","data":[{"symbol":"BCH/USDT","bids":[{"price":461.61,"qty":3.80879832}],"asks":[],"checksum":3714369320,"timestamp":"2024-06-01T18:06:00.453150Z"}]}
{"channel":"book","type":"update","data":[{"symbol":"BCH/USDT","bids":[],"asks":[{"price":462.19,"qty":0.00000000},{"price":462.82,"qty":2.58370377}],"checksum":2944517205,"timestamp":"2024-06-01T18:06:00.457627Z"}]}
{"channel":"book","type":"update","data":[{"symbol":"BCH/USDT","bids":[{"price":461.61,"qty":11.64271920}],"asks":[],"checksum":1548761428,"timestamp":"2024-06-01T18:06:00.458024Z"}]}
{"channel":"book","type":"update","data":[{"symbol":"BCH/USDT","bids":[],"asks":[{"price":462.13,"qty":3.00000000}],"checksum":3526695162,"timestamp":"2024-06-01T18:06:00.458058Z"}]}
{"channel":"book","type":"update","data":[{"symbol":"BCH/USDT","bids":[{"price":461.61,"qty":14.64271920}],"asks":[],"checksum":1788037116,"timestamp":"2024-06-01T18:06:00.458101Z"}]}
{"channel":"book","type":"update","data":[{"symbol":"BCH/USDT","bids":[{"price":461.62,"qty":7.83392088}],"asks":[],"checksum":1804561995,"timestamp":"2024-06-01T18:06:00.512649Z"}]}
{"channel":"book","type":"update","data":[{"symbol":"BCH/USDT","bids":[{"price":461.61,"qty":6.80879832}],"asks":[],"checksum":585312678,"timestamp":"2024-06-01T18:06:00.516546Z"}]}
{"channel":"book","type":"update","data":[{"symbol":"BCH/USDT","bids":[],"asks":[{"price":462.17,"qty":0.00000000},{"price":462.82,"qty":2.58370377}],"checksum":1331596911,"timestamp":"2024-06-01T18:06:00.517680Z"}]}
{"channel":"book","type":"update","data":[{"symbol":"BCH/USDT","bids":[{"price":461.61,"qty":3.80879832}],"asks":[],"checksum":642434365,"timestamp":"2024-06-01T18:06:00.517769Z"}]}
{"channel":"book","type":"update","data":[{"symbol":"BCH/USDT","bids":[],"asks":[{"price":462.12,"qty":3.80879832}],"checksum":2527923986,"timestamp":"2024-06-01T18:06:00.517941Z"}]}
{"channel":"book","type":"update","data":[{"symbol":"BCH/USDT","bids":[{"price":461.68,"qty":0.90000000}],"asks":[],"checksum":2397011839,"timestamp":"2024-06-01T18:06:00.518880Z"}]}
{"channel":"book","type":"update","data":[{"symbol":"BCH/USDT","bids":[],"asks":[{"price":462.12,"qty":4.70879832}],"checksum":541705896,"timestamp":"2024-06-01T18:06:00.519019Z"}]}
{"channel":"book","type":"update","data":[{"symbol":"BCH/USDT","bids":[],"asks":[{"price":462.15,"qty":0.00000000},{"price":462.82,"qty":2.58370377}],"checksum":726939699,"timestamp":"2024-06-01T18:06:00.589228Z"}]}
{"channel":"book","type":"update","data":[{"symbol":"BCH/USDT","bids":[{"price":461.68,"qty":8.73392088}],"asks":[],"checksum":134577195,"timestamp":"2024-06-01T18:06:00.593484Z"}]}
{"channel":"book","type":"update","data":[{"symbol":"BCH/USDT","bids":[],"asks":[{"price":462.14,"qty":0.00000000},{"price":462.83,"qty":0.06152197}],"checksum":166977890,"timestamp":"2024-06-01T18:06:00.594355Z"}]}
{"channel":"book","type":"update","data":[{"symbol":"BCH/USDT","bids":[],"asks":[{"price":462.11,"qty":3.00000000}],"checksum":1076118141,"timestamp":"2024-06-01T18:06:00.596530Z"}]}
{"channel":"book","type":"update","data":[{"symbol":"BCH/USDT","bids":[],"asks":[{"price":462.13,"qty":0.00000000},{"price":462.83,"qty":0.06152197}],"checksum":4155070634,"timestamp":"2024-06-01T18:06:00.708800Z"}]}
{"channel":"book","type":"update","data":[{"symbol":"BCH/USDT","bids":[{"price":461.62,"qty":0.00000000},{"price":460.54,"qty":1.36603240}],"asks":[],"checksum":2674880026,"timestamp":"2024-06-01T18:06:00.713007Z"}]}
{"channel":"book","type":"update","data":[{"symbol":"BCH/USDT","bids":[{"price":461.69,"qty":1.01250598}],"asks":[],"checksum":1412457346,"timestamp":"2024-06-01T18:06:00.713894Z"}]}
{"channel":"book","type":"update","data":[{"symbol":"BCH/USDT","bids":[],"asks":[{"price":462.10,"qty":3.80879832}],"checksum":2071230263,"timestamp":"2024-06-01T18:06:00.714717Z"}]}
{"channel":"book","type":"update","data":[{"symbol":"BCH/USDT","bids":[],"asks":[{"price":462.12,"qty":0.90000000}],"checksum":1501033847,"timestamp":"2024-06-01T18:06:00.953423Z"}]}
{"channel":"book","type":"update","data":[{"symbol":"BCH/USDT","bids":[{"price":461.69,"qty":8.84642686}],"asks":[],"checksum":435411739,"timestamp":"2024-06-01T18:06:00.957781Z"}]}
{"channel":"book","type":"update","data":[{"symbol":"BCH/USDT","bids":[],"asks":[{"price":462.09,"qty":3.00000000}],"checksum":2729409084,"timestamp":"2024-06-01T18:06:00.957898Z"}]}
{"channel":"book","type":"update","data":[{"symbol":"BCH/USDT","bids":[{"price":461.68,"qty":0.90000000}],"asks":[],"checksum":2779222045,"timestamp":"2024-06-01T18:06:01.012016Z"}]}
{"channel":"book","type":"update","data":[{"symbol":"BCH/USDT","bids":[],"asks":[{"price":462.11,"qty":0.00000000},{"price":462.82,"qty":2.58370377}],"checksum":3387653081,"timestamp":"2024-06-01T18:06:01.016459Z"}]}
{"channel":"book","type":"update","data":[{"symbol":"BCH/USDT","bids":[],"asks":[{"price":462.08,"qty":3.80879832}],"checksum":3058971626,"timestamp":"2024-06-01T18:06:01.017533Z"}]}
{"channel":"book","type":"update","data":[{"symbol":"BCH/USDT","bids":[],"asks":[{"price":462.07,"qty":3.00000000}],"checksum":915241518,"timestamp":"2024-06-01T18:06:01.210150Z"}]}
{"channel":"book","type":"update","data":[{"symbol":"BCH/USDT","bids":[],"asks":[{"price":462.09,"qty":0.00000000},{"price":462.58,"qty":1.36603240}],"checksum":3936681129,"timestamp":"2024-06-01T18:06:01.214271Z"}]}
{"channel":"book","type":"update","data":[{"symbol":"BCH/USDT","bids":[],"asks":[{"price":462.06,"qty":3.80879832}],"checksum":815351018,"timestamp":"2024-06-01T18:06:01.215212Z"}]}
{"channel":"book","type":"update","data":[{"symbol":"BCH/USDT","bids":[],"asks":[{"price":462.10,"qty":0.00000000},{"price":462.58,"qty":1.36603240}],"checksum":1932183946,"timestamp":"2024-06-01T18:06:01.215272Z"}]}
