{"channel":"book","type":"snapshot","data":[{"symbol":"BCH/EUR","bids":[{"price":425.59,"qty":2.45000000},{"price":425.58,"qty":13.41606776},{"price":425.57,"qty":7.83392088},{"price":425.56,"qty":3.98631435},{"price":425.47,"qty":5.41241363},{"price":425.40,"qty":2.33530309},{"price":425.30,"qty":0.47000000},{"price":425.24,"qty":26.80804300},{"price":425.22,"qty":12.24000000},{"price":425.21,"qty":5.42073130}],"asks":[{"price":425.83,"qty":0.45000000},{"price":425.86,"qty":0.38220281},{"price":425.87,"qty":5.41241363},{"price":425.91,"qty":0.03152465},{"price":425.94,"qty":15.96804300},{"price":425.97,"qty":1.42847891},{"price":425.98,"qty":3.88726919},{"price":425.99,"qty":0.10000000},{"price":426.05,"qty":24.84732600},{"price":426.10,"qty":5.40954674}],"checksum":2790700527}]}
{"channel":"book","type":"update","data":[{"symbol":"BCH/EUR","bids":[],"asks":[{"price":425.86,"qty":0.00000000},{"price":426.15,"qty":8.00000000}],"checksum":1905916246,"timestamp":"2024-06-01T18:05:46.388213Z"}]}
{"channel":"book","type":"update","data":[{"symbol":"BCH/EUR","bids":[],"asks":[{"price":425.86,"qty":0.38441081}],"checksum":3073875101,"timestamp":"2024-06-01T18:05:47.136878Z"}]}
{"channel":"book","type":"update","data":[{"symbol":"BCH/EUR","bids":[],"asks":[{"price":425.86,"qty":0.00000000},{"price":426.15,"qty":8.00000000}],"checksum":1905916246,"timestamp":"2024-06-01T18:05:50.153373Z"}]}
{"channel":"book","type":"update","data":[{"symbol":"BCH/EUR","bids":[],"asks":[{"price":425.86,"qty":0.34607701}],"checksum":214744169,"timestamp":"2024-06-01T18:05:50.319993Z"}]}
{"channel":"book","type":"update","data":[{"symbol":"BCH/EUR","bids":[],"asks":[{"price":425.86,"qty":0.00000000},{"price":426.15,"qty":8.00000000}],"checksum":1905916246,"timestamp":"2024-06-01T18:05:50.698495Z"}]}
{"channel":"book","type":"update","data":[{"symbol":"BCH/EUR","bids":[{"price":425.47,"qty":5.77241363}],"asks":[],"checksum":3452640952,"timestamp":"2024-06-01T18:05:50.730510Z"}]}
{"channel":"book","type":"update","data":[{"symbol":"BCH/EUR","bids":[{"price":425.58,"qty":8.00000000}],"asks":[],"checksum":2326653408,"timestamp":"2024-06-01T18:05:50.786181Z"}]}
{"channel":"book","type":"update","data":[{"symbol":"BCH/EUR","bids":[{"price":425.60,"qty":5.41581324}],"asks":[],"checksum":2588672361,"timestamp":"2024-06-01T18:05:50.790079Z"}]}
{"channel":"book","type":"update","data":[{"symbol":"BCH/EUR","bids":[{"price":425.58,"qty":0.00000000},{"price":425.21,"qty":5.42073130}],"asks":[],"checksum":1515332449,"timestamp":"2024-06-01T18:05:50.790717Z"}]}
{"channel":"book","type":"update","data":[{"symbol":"BCH/EUR","bids":[{"price":425.59,"qty":2.00000000}],"asks":[],"checksum":3890054085,"timestamp":"2024-06-01T18:05:50.792771Z"}]}
{"channel":"book","type":"update","data":[{"symbol":"BCH/EUR","bids":[{"price":425.61,"qty":0.45000000}],"asks":[],"checksum":4208712014,"timestamp":"2024-06-01T18:05:50.792870Z"}]}
{"channel":"book","type":"update","data":[{"symbol":"BCH/EUR","bids":[{"price":425.40,"qty":0.00000000},{"price":425.21,"qty":5.42073130}],"asks":[],"checksum":211961917,"timestamp":"2024-06-01T18:05:50.795786Z"}]}
{"channel":"book","type":"update","data":[{"symbol":"BCH/EUR","bids":[],"asks":[{"price":425.91,"qty":0.00000000},{"price":426.27,"qty":16.24740803}],"checksum":1669702816,"timestamp":"2024-06-01T18:05:50.799921Z"}]}
{"channel":"book","type":"update","data":[{"symbol":"BCH/EUR","bids":[{"price":425.50,"qty":1.84029761}],"asks":[],"checksum":2914743902,"timestamp":"2024-06-01T18:05:50.800511Z"}]}
{"channel":"book","type":"update","data":[{"symbol":"BCH/EUR","bids":[{"price":425.61,"qty":2.45000000}],"asks":[],"checksum":2711834524,"timestamp":"2024-06-01T18:05:50.825753Z"}]}
{"channel":"book","type":"update","data":[{"symbol":"BCH/EUR","bids":[],"asks":[{"price":425.86,"qty":0.39749133}],"checksum":3755111286,"timestamp":"2024-06-01T18:05:50.830091Z"}]}
{"channel":"book","type":"update","data":[{"symbol":"BCH/EUR","bids":[],"asks":[{"price":425.95,"qty":0.03152465}],"checksum":2223360445,"timestamp":"2024-06-01T18:05:50.918431Z"}]}
{"channel":"book","type":"update","data":[{"symbol":"BCH/EUR","bids":[{"price":425.59,"qty":0.00000000},{"price":425.21,"qty":5.42073130}],"asks":[],"checksum":2285621768,"timestamp":"2024-06-01T18:05:50.923356Z"}]}
{"channel":"book","type":"update","data":[{"symbol":"BCH/EUR","bids":[],"asks":[{"price":425.86,"qty":0.00000000},{"price":426.15,"qty":8.00000000}],"checksum":1766304553,"timestamp":"2024-06-01T18:05:51.162547Z"}]}
{"channel":"book","type":"update","data":[{"symbol":"BCH/EUR","bids":[{"price":425.53,"qty":8.00000000}],"asks":[],"checksum":12794847,"timestamp":"2024-06-01T18:05:51.635129Z"}]}
{"channel":"book","type":"update","data":[{"symbol":"BCH/EUR","bids":[],"asks":[{"price":425.86,"qty":0.46889802}],"checksum":623921482,"timestamp":"2024-06-01T18:05:53.317075Z"}]}
{"channel":"book","type":"update","data":[{"symbol":"BCH/EUR","bids":[],"asks":[{"price":425.93,"qty":7.83392088}],"checksum":1277408736,"timestamp":"2024-06-01T18:05:54.507490Z"}]}
{"channel":"book","type":"update","data":[{"symbol":"BCH/EUR","bids":[],"asks":[{"price":425.86,"qty":0.00000000},{"price":426.10,"qty":5.40954674}],"checksum":2508580944,"timestamp":"2024-06-01T18:05:55.136470Z"}]}
{"channel":"book","type":"update","data":[{"symbol":"BCH/EUR","bids":[],"asks":[{"price":425.86,"qty":0.46032410}],"checksum":3937380786,"timestamp":"2024-06-01T18:05:55.330442Z"}]}
{"channel":"book","type":"update","data":[{"symbol":"BCH/EUR","bids":[],"asks":[{"price":425.86,"qty":0.00000000},{"price":426.10,"qty":5.40954674}],"checksum":2508580944,"timestamp":"2024-06-01T18:05:55.382184Z"}]}
{"channel":"book","type":"update","data":[{"symbol":"BCH/EUR","bids":[],"asks":[{"price":425.86,"qty":0.45441425}],"checksum":2882614295,"timestamp":"2024-06-01T18:05:55.951279Z"}]}
{"channel":"book","type":"update","data":[{"symbol":"BCH/EUR","bids":[],"asks":[{"price":425.86,"qty":0.00000000},{"price":426.10,"qty":5.40954674}],"checksum":2508580944,"timestamp":"2024-06-01T18:05:56.541410Z"}]}
{"channel":"book","type":"update","data":[{"symbol":"BCH/EUR","bids":[],"asks":[{"price":425.86,"qty":0.46578200}],"checksum":2716878832,"timestamp":"2024-06-01T18:05:56.824370Z"}]}
{"channel":"book","type":"update","data":[{"symbol":"BCH/EUR","bids":[],"asks":[{"price":425.86,"qty":0.00000000},{"price":426.10,"qty":5.40954674}],"checksum":2508580944,"timestamp":"2024-06-01T18:05:57.136306Z"}]}
{"channel":"book","type":"update","data":[{"symbol":"BCH/EUR","bids":[{"price":425.57,"qty":0.00000000},{"price":425.21,"qty":5.42073130}],"asks":[],"checksum":1531863657,"timestamp":"2024-06-01T18:05:59.983121Z"}]}
{"channel":"book","type":"update","data":[{"symbol":"BCH/EUR","bids":[{"price":425.22,"qty":0.00000000},{"price":425.11,"qty":1.08400000}],"asks":[],"checksum":629900429,"timestamp":"2024-06-01T18:05:59.985390Z"}]}
{"channel":"book","type":"update","data":[{"symbol":"BCH/EUR","bids":[],"asks":[{"price":425.93,"qty":0.00000000},{"price":426.15,"qty":8.00000000}],"checksum":3692202309,"timestamp":"2024-06-01T18:05:59.986879Z"}]}
{"channel":"book","type":"update","data":[{"symbol":"BCH/EUR","bids":[{"price":425.53,"qty":0.00000000},{"price":425.10,"qty":3.44865588}],"asks":[],"checksum":1218934913,"timestamp":"2024-06-01T18:05:59.988294Z"}]}
{"channel":"book","type":"update","data":[{"symbol":"BCH/EUR","bids":[{"price":425.60,"qty":0.00000000},{"price":425.09,"qty":5.42229613}],"asks":[],"checksum":4289966295,"timestamp":"2024-06-01T18:06:00.013304Z"}]}
{"channel":"book","type":"update","data":[{"symbol":"BCH/EUR","bids":[],"asks":[{"price":425.87,"qty":0.00000000},{"price":426.27,"qty":16.24740803}],"checksum":137442506,"timestamp":"2024-06-01T18:06:00.013461Z"}]}
{"channel":"book","type":"update","data":[{"symbol":"BCH/EUR","bids":[{"price":425.56,"qty":3.88726919}],"asks":[],"checksum":443432681,"timestamp":"2024-06-01T18:06:00.014865Z"}]}
{"channel":"book","type":"update","data":[{"symbol":"BCH/EUR","bids":[],"asks":[{"price":425.83,"qty":0.00000000},{"price":426.28,"qty":5.41241363}],"checksum":3833182498,"timestamp":"2024-06-01T18:06:00.016379Z"}]}
{"channel":"book","type":"update","data":[{"symbol":"BCH/EUR","bids":[],"asks":[{"price":425.92,"qty":0.45000000}],"checksum":2231999326,"timestamp":"2024-06-01T18:06:00.016781Z"}]}
{"channel":"book","type":"update","data":[{"symbol":"BCH/EUR","bids":[],"asks":[{"price":425.84,"qty":5.41287536}],"checksum":2523967280,"timestamp":"2024-06-01T18:06:00.017413Z"}]}
{"channel":"book","type":"update","data":[{"symbol":"BCH/EUR","bids":[{"price":425.54,"qty":5.41648080}],"asks":[],"checksum":4237662244,"timestamp":"2024-06-01T18:06:00.017497Z"}]}
{"channel":"book","type":"update","data":[{"symbol":"BCH/EUR","bids":[{"price":425.53,"qty":8.00000000}],"asks":[],"checksum":1746954720,"timestamp":"2024-06-01T18:06:00.018820Z"}]}
{"channel":"book","type":"update","data":[{"symbol":"BCH/EUR","bids":[],"asks":[{"price":425.97,"qty":0.00000000},{"price":426.27,"qty":16.24740803}],"checksum":2656198294,"timestamp":"2024-06-01T18:06:00.019474Z"}]}
{"channel":"book","type":"update","data":[{"symbol":"BCH/EUR","bids":[{"price":425.61,"qty":0.45000000}],"asks":[],"checksum":3147581481,"timestamp":"2024-06-01T18:06:00.019819Z"}]}
{"channel":"book","type":"update","data":[{"symbol":"BCH/EUR","bids":[{"price":425.57,"qty":2.00000000}],"asks":[],"checksum":3682633978,"timestamp":"2024-06-01T18:06:00.020000Z"}]}
{"channel":"book","type":"update","data":[{"symbol":"BCH/EUR","bids":[],"asks":[{"price":425.92,"qty":0.00000000},{"price":426.28,"qty":5.41241363}],"checksum":3012233802,"timestamp":"2024-06-01T18:06:00.020037Z"}]}
{"channel":"book","type":"update","data":[{"symbol":"BCH/EUR","bids":[],"asks":[{"price":425.82,"qty":0.45000000}],"checksum":2019101915,"timestamp":"2024-06-01T18:06:00.020047Z"}]}
{"channel":"book","type":"update","data":[{"symbol":"BCH/EUR","bids":[],"asks":[{"price":425.97,"qty":1.89047891}],"checksum":3938039384,"timestamp":"2024-06-01T18:06:00.022790Z"}]}
{"channel":"book","type":"update","data":[{"symbol":"BCH/EUR","bids":[{"price":425.55,"qty":0.09904749}],"asks":[],"checksum":2060060353,"timestamp":"2024-06-01T18:06:00.132108Z"}]}
{"channel":"book","type":"update","data":[{"symbol":"BCH/EUR","bids":[{"price":425.51,"qty":7.83392088}],"asks":[],"checksum":1940156708,"timestamp":"2024-06-01T18:06:00.135884Z"}]}
{"channel":"book","type":"update","data":[{"symbol":"BCH/EUR","bids":[{"price":425.70,"qty":1.50000000}],"asks":[],"checksum":524445640,"timestamp":"2024-06-01T18:06:00.191512Z"}]}
{"channel":"book","type":"update","data":[{"symbol":"BCH/EUR","bids":[{"price":425.53,"qty":0.00000000},{"price":425.30,"qty":0.47000000}],"asks":[],"checksum":104971916,"timestamp":"2024-06-01T18:06:00.196116Z"}]}
{"channel":"book","type":"update","data":[{"symbol":"BCH/EUR","bids":[{"price":425.50,"qty":0.00000000},{"price":425.24,"qty":26.80804300}],"asks":[],"checksum":1884889054,"timestamp":"2024-06-01T18:06:00.294322Z"}]}
{"channel":"book","type":"update","data":[{"symbol":"BCH/EUR","bids":[{"price":425.56,"qty":0.00000000},{"price":425.21,"qty":5.42073130}],"asks":[],"checksum":4140807910,"timestamp":"2024-06-01T18:06:00.296060Z"}]}
{"channel":"book","type":"update","data":[{"symbol":"BCH/EUR","bids":[{"price":425.40,"qty":1.84069603}],"asks":[],"checksum":2025640298,"timestamp":"2024-06-01T18:06:00.298877Z"}]}
{"channel":"book","type":"update","data":[{"symbol":"BCH/EUR","bids":[],"asks":[{"price":425.83,"qty":7.83392088}],"checksum":3206208286,"timestamp":"2024-06-01T18:06:00.300087Z"}]}
{"channel":"book","type":"update","data":[{"symbol":"BCH/EUR","bids":[],"asks":[{"price":425.89,"qty":3.88726919}],"checksum":403029798,"timestamp":"2024-06-01T18:06:00.301265Z"}]}
{"channel":"book","type":"update","data":[{"symbol":"BCH/EUR","bids":[{"price":425.51,"qty":0.00000000},{"price":425.21,"qty":5.42073130}],"asks":[],"checksum":590900133,"timestamp":"2024-06-01T18:06:00.301570Z"}]}
{"channel":"book","type":"update","data":[{"symbol":"BCH/EUR","bids":[],"asks":[{"price":426.05,"qty":32.84732600}],"checksum":1720631022,"timestamp":"2024-06-01T18:06:00.302056Z"}]}
{"channel":"book","type":"update","data":[{"symbol":"BCH/EUR","bids":[],"asks":[{"price":425.84,"qty":0.00000000},{"price":426.10,"qty":5.40954674}],"checksum":3879912003,"timestamp":"2024-06-01T18:06:00.302284Z"}]}
{"channel":"book","type":"update","data":[{"symbol":"BCH/EUR","bids":[{"price":425.55,"qty":0.00000000},{"price":425.17,"qty":12.24000000}],"asks":[],"checksum":1798442505,"timestamp":"2024-06-01T18:06:00.320171Z"}]}
{"channel":"book","type":"update","data":[{"symbol":"BCH/EUR","bids":[{"price":425.61,"qty":0.00000000},{"price":425.11,"qty":1.08400000}],"asks":[],"checksum":3548791314,"timestamp":"2024-06-01T18:06:00.322738Z"}]}
{"channel":"book","type":"update","data":[{"symbol":"BCH/EUR","bids":[{"price":425.54,"qty":0.00000000},{"price":425.10,"qty":2.91767000}],"asks":[],"checksum":3662393713,"timestamp":"2024-06-01T18:06:00.328017Z"}]}
{"channel":"book","type":"update","data":[{"symbol":"BCH/EUR","bids":[{"price":425.48,"qty":8.00000000}],"asks":[],"checksum":1996715393,"timestamp":"2024-06-01T18:06:00.331437Z"}]}
{"channel":"book","type":"update","data":[{"symbol":"BCH/EUR","bids":[],"asks":[{"price":425.83,"qty":0.00000000},{"price":426.27,"qty":16.24740803}],"checksum":2475943251,"timestamp":"2024-06-01T18:06:00.332376Z"}]}
{"channel":"book","type":"update","data":[{"symbol":"BCH/EUR","bids":[],"asks":[{"price":425.88,"qty":7.83392088}],"checksum":1627810298,"timestamp":"2024-06-01T18:06:00.332474Z"}]}
{"channel":"book","type":"update","data":[{"symbol":"BCH/EUR","bids":[],"asks":[{"price":425.98,"qty":0.00000000},{"price":426.27,"qty":16.24740803}],"checksum":2017323910,"timestamp":"2024-06-01T18:06:00.333030Z"}]}
{"channel":"book","type":"update","data":[{"symbol":"BCH/EUR","bids":[],"asks":[{"price":425.87,"qty":0.45000000}],"checksum":3001091699,"timestamp":"2024-06-01T18:06:00.335084Z"}]}
{"channel":"book","type":"update","data":[{"symbol":"BCH/EUR","bids":[],"asks":[{"price":425.82,"qty":0.00000000},{"price":426.27,"qty":16.24740803}],"checksum":3245147480,"timestamp":"2024-06-01T18:06:00.335114Z"}]}
{"channel":"book","type":"update","data":[{"symbol":"BCH/EUR","bids":[{"price":425.24,"qty":15.96804300}],"asks":[],"checksum":2620095163,"timestamp":"2024-06-01T18:06:00.379896Z"}]}
{"channel":"book","type":"update","data":[{"symbol":"BCH/EUR","bids":[{"price":425.17,"qty":0.00000000},{"price":425.10,"qty":2.91767000}],"asks":[],"checksum":3134825780,"timestamp":"2024-06-01T18:06:00.382819Z"}]}
{"channel":"book","type":"update","data":[{"symbol":"BCH/EUR","bids":[{"price":425.47,"qty":0.36000000}],"asks":[],"checksum":4222841212,"timestamp":"2024-06-01T18:06:00.401661Z"}]}
{"channel":"book","type":"update","data":[{"symbol":"BCH/EUR","bids":[],"asks":[{"price":425.86,"qty":3.88726919}],"checksum":3430291592,"timestamp":"2024-06-01T18:06:00.406775Z"}]}
{"channel":"book","type":"update","data":[{"symbol":"BCH/EUR","bids":[],"asks":[{"price":425.87,"qty":0.00000000},{"price":426.27,"qty":16.24740803}],"checksum":4112267389,"timestamp":"2024-06-01T18:06:00.409232Z"}]}
{"channel":"book","type":"update","data":[{"symbol":"BCH/EUR","bids":[],"asks":[{"price":425.84,"qty":0.45000000}],"checksum":2676630234,"timestamp":"2024-06-01T18:06:00.409437Z"}]}
{"channel":"book","type":"update","data":[{"symbol":"BCH/EUR","bids":[{"price":425.53,"qty":0.09905215}],"asks":[],"checksum":2189261028,"timestamp":"2024-06-01T18:06:00.440332Z"}]}
{"channel":"book","type":"update","data":[{"symbol":"BCH/EUR","bids":[],"asks":[{"price":425.86,"qty":0.00000000},{"price":426.27,"qty":16.24740803}],"checksum":592603306,"timestamp":"2024-06-01T18:06:00.445168Z"}]}
{"channel":"book","type":"update","data":[{"symbol":"BCH/EUR","bids":[{"price":425.70,"qty":0.00000000},{"price":425.10,"qty":2.91767000}],"asks":[],"checksum":2391051903,"timestamp":"2024-06-01T18:06:00.568117Z"}]}
{"channel":"book","type":"update","data":[{"symbol":"BCH/EUR","bids":[{"price":425.53,"qty":0.54905215}],"asks":[],"checksum":2975048284,"timestamp":"2024-06-01T18:06:00.571141Z"}]}
{"channel":"book","type":"update","data":[{"symbol":"BCH/EUR","bids":[{"price":425.21,"qty":16.26073130}],"asks":[],"checksum":4291939212,"timestamp":"2024-06-01T18:06:00.571180Z"}]}
{"channel":"book","type":"update","data":[{"symbol":"BCH/EUR","bids":[{"price":425.46,"qty":7.83392088}],"asks":[],"checksum":232352734,"timestamp":"2024-06-01T18:06:00.571829Z"}]}
{"channel":"book","type":"update","data":[{"symbol":"BCH/EUR","bids":[{"price":425.44,"qty":3.88726919}],"asks":[],"checksum":2236425703,"timestamp":"2024-06-01T18:06:00.573794Z"}]}
{"channel":"book","type":"update","data":[{"symbol":"BCH/EUR","bids":[{"price":425.57,"qty":0.00000000},{"price":425.11,"qty":1.08400000}],"asks":[],"checksum":2497299408,"timestamp":"2024-06-01T18:06:00.574656Z"}]}
{"channel":"book","type":"update","data":[{"symbol":"BCH/EUR","bids":[{"price":425.49,"qty":2.00000000}],"asks":[],"checksum":765831599,"timestamp":"2024-06-01T18:06:00.574747Z"}]}
{"channel":"book","type":"update","data":[{"symbol":"BCH/EUR","bids":[{"price":425.36,"qty":7.83392088}],"asks":[],"checksum":1758082650,"timestamp":"2024-06-01T18:06:00.672140Z"}]}
{"channel":"book","type":"update","data":[{"symbol":"BCH/EUR","bids":[],"asks":[{"price":425.80,"qty":0.48000000}],"checksum":422994184,"timestamp":"2024-06-01T18:06:00.685602Z"}]}
{"channel":"book","type":"update","data":[{"symbol":"BCH/EUR","bids":[{"price":425.50,"qty":7.83392088}],"asks":[],"checksum":3975260865,"timestamp":"2024-06-01T18:06:00.689480Z"}]}
{"channel":"book","type":"update","data":[{"symbol":"BCH/EUR","bids":[],"asks":[{"price":425.79,"qty":0.34154391}],"checksum":1234929818,"timestamp":"2024-06-01T18:06:00.886461Z"}]}
{"channel":"book","type":"update","data":[{"symbol":"BCH/EUR","bids":[],"asks":[{"price":425.84,"qty":0.00000000},{"price":426.10,"qty":5.40954674}],"checksum":1212770546,"timestamp":"2024-06-01T18:06:00.889248Z"}]}
{"channel":"book","type":"update","data":[{"symbol":"BCH/EUR","bids":[],"asks":[{"price":425.77,"qty":0.45000000}],"checksum":617038893,"timestamp":"2024-06-01T18:06:00.889308Z"}]}
{"channel":"book","type":"update","data":[{"symbol":"BCH/EUR","bids":[{"price":425.46,"qty":0.00000000},{"price":425.24,"qty":15.96804300}],"asks":[],"checksum":987742331,"timestamp":"2024-06-01T18:06:00.890527Z"}]}
{"channel":"book","type":"update","data":[{"symbol":"BCH/EUR","bids":[],"asks":[{"price":426.05,"qty":24.84732600}],"checksum":3683970742,"timestamp":"2024-06-01T18:06:00.891003Z"}]}
{"channel":"book","type":"update","data":[{"symbol":"BCH/EUR","bids":[{"price":425.51,"qty":2.00000000}],"asks":[],"checksum":3723543990,"timestamp":"2024-06-01T18:06:00.892104Z"}]}
{"channel":"book","type":"update","data":[{"symbol":"BCH/EUR","bids":[],"asks":[{"price":425.79,"qty":0.00000000},{"price":426.10,"qty":5.40954674}],"checksum":4003810705,"timestamp":"2024-06-01T18:06:00.894012Z"}]}
{"channel":"book","type":"update","data":[{"symbol":"BCH/EUR","bids":[],"asks":[{"price":425.76,"qty":0.32404214}],"checksum":1281499438,"timestamp":"2024-06-01T18:06:00.898372Z"}]}
{"channel":"book","type":"update","data":[{"symbol":"BCH/EUR","bids":[],"asks":[{"price":425.76,"qty":0.00000000},{"price":426.10,"qty":5.40954674}],"checksum":4003810705,"timestamp":"2024-06-01T18:06:01.037276Z"}]}
{"channel":"book","type":"update","data":[{"symbol":"BCH/EUR","bids":[],"asks":[{"price":426.05,"qty":32.84732600}],"checksum":1747413329,"timestamp":"2024-06-01T18:06:01.043431Z"}]}
{"channel":"book","type":"update","data":[{"symbol":"BCH/EUR","bids":[{"price":425.49,"qty":0.00000000},{"price":425.24,"qty":15.96804300}],"asks":[],"checksum":1524587760,"timestamp":"2024-06-01T18:06:01.046221Z"}]}
{"channel":"book","type":"update","data":[{"symbol":"BCH/EUR","bids":[],"asks":[{"price":425.95,"qty":0.00000000},{"price":426.27,"qty":16.24740803}],"checksum":1879145923,"timestamp":"2024-06-01T18:06:01.186635Z"}]}
{"channel":"book","type":"update","data":[{"symbol":"BCH/EUR","bids":[{"price":425.51,"qty":7.41685246}],"asks":[],"checksum":2944479014,"timestamp":"2024-06-01T18:06:01.217777Z"}]}
{"channel":"book","type":"update","data":[{"symbol":"BCH/EUR","bids":[],"asks":[{"price":425.80,"qty":5.89337672}],"checksum":2197045098,"timestamp":"2024-06-01T18:06:01.217797Z"}]}
{"channel":"book","type":"update","data":[{"symbol":"BCH/EUR","bids":[],"asks":[{"price":425.80,"qty":5.41337672}],"checksum":1517370237,"timestamp":"2024-06-01T18:06:01.221565Z"}]}
{"channel":"book","type":"update","data":[{"symbol":"BCH/EUR","bids":[{"price":425.24,"qty":26.80804300}],"asks":[],"checksum":665946399,"timestamp":"2024-06-01T18:06:01.259374Z"}]}
{"channel":"book","type":"update","data":[{"symbol":"BCH/EUR","bids":[],"asks":[{"price":425.93,"qty":0.03152465}],"checksum":862171795,"timestamp":"2024-06-01T18:06:01.318579Z"}]}
{"channel":"book","type":"update","data":[{"symbol":"BCH/EUR","bids":[{"price":425.52,"qty":7.83392088}],"asks":[],"checksum":1444816234,"timestamp":"2024-06-01T18:06:01.322447Z"}]}
{"channel":"book","type":"update","data":[{"symbol":"BCH/EUR","bids":[],"asks":[{"price":425.79,"qty":0.39339089}],"checksum":475994307,"timestamp":"2024-06-01T18:06:01.322834Z"}]}
{"channel":"book","type":"update","data":[{"symbol":"BCH/EUR","bids":[],"asks":[{"price":426.05,"qty":24.84732600}],"checksum":1508494728,"timestamp":"2024-06-01T18:06:01.347437Z"}]}
{"channel":"book","type":"update","data":[{"symbol":"BCH/EUR","bids":[],"asks":[{"price":425.89,"qty":0.00000000},{"price":426.10,"qty":5.40954674}],"checksum":969668833,"timestamp":"2024-06-01T18:06:01.347858Z"}]}
{"channel":"book","type":"update","data":[{"symbol":"BCH/EUR","bids":[{"price":425.50,"qty":0.00000000},{"price":425.24,"qty":26.80804300}],"asks":[],"checksum":1769965175,"timestamp":"2024-06-01T18:06:01.352952Z"}]}
{"channel":"book","type":"update","data":[{"symbol":"BCH/EUR","bids":[{"price":425.53,"qty":2.54905215}],"asks":[],"checksum":4058302457,"timestamp":"2024-06-01T18:06:01.354299Z"}]}
{"channel":"book","type":"update","data":[{"symbol":"BCH/EUR","bids":[{"price":425.54,"qty":7.83392088}],"asks":[],"checksum":93255545,"timestamp":"2024-06-01T18:06:01.510045Z"}]}
{"channel":"book","type":"update","data":[{"symbol":"BCH/EUR","bids":[{"price":425.53,"qty":2.09905215}],"asks":[],"checksum":4042394068,"timestamp":"2024-06-01T18:06:01.512554Z"}]}
{"channel":"book","type":"update","data":[{"symbol":"BCH/EUR","bids":[{"price":425.55,"qty":0.45000000}],"asks":[],"checksum":2440098323,"timestamp":"2024-06-01T18:06:01.512865Z"}]}
{"channel":"book","type":"update","data":[{"symbol":"BCH/EUR","bids":[],"asks":[{"price":425.89,"qty":3.88726919}],"checksum":2776500698,"timestamp":"2024-06-01T18:06:01.515476Z"}]}
{"channel":"book","type":"update","data":[{"symbol":"BCH/EUR","bids":[{"price":425.53,"qty":0.09905215}],"asks":[],"checksum":68924521,"timestamp":"2024-06-01T18:06:01.516224Z"}]}
{"channel":"book","type":"update","data":[{"symbol":"BCH/EUR","bids":[],"asks":[{"price":426.05,"qty":32.84732600}],"checksum":1838320196,"timestamp":"2024-06-01T18:06:01.632500Z"}]}
{"channel":"book","type":"update","data":[{"symbol":"BCH/EUR","bids":[{"price":425.55,"qty":2.45000000}],"asks":[],"checksum":601015127,"timestamp":"2024-06-01T18:06:01.633017Z"}]}
{"channel":"book","type":"update","data":[{"symbol":"BCH/EUR","bids":[{"price":425.54,"qty":0.00000000},{"price":425.30,"qty":0.47000000}],"asks":[],"checksum":2830476277,"timestamp":"2024-06-01T18:06:01.636887Z"}]}
{"channel":"book","type":"update","data":[{"symbol":"BCH/EUR","bids":[{"price":425.51,"qty":5.41685246}],"asks":[],"checksum":4084626048,"timestamp":"2024-06-01T18:06:01.638129Z"}]}
{"channel":"book","type":"update","data":[{"symbol":"BCH/EUR","bids":[{"price":425.56,"qty":7.83392088}],"asks":[],"checksum":979926525,"timestamp":"2024-06-01T18:06:02.011357Z"}]}
{"channel":"book","type":"update","data":[{"symbol":"BCH/EUR","bids":[{"price":425.57,"qty":2.00000000}],"asks":[],"checksum":1448605030,"timestamp":"2024-06-01T18:06:02.016542Z"}]}
{"channel":"book","type":"update","data":[{"symbol":"BCH/EUR","bids":[{"price":425.55,"qty":0.45000000}],"asks":[],"checksum":1754770244,"timestamp":"2024-06-01T18:06:02.130272Z"}]}
{"channel":"book","type":"update","data":[{"symbol":"BCH/EUR","bids":[{"price":425.56,"qty":0.00000000},{"price":425.36,"qty":7.83392088}],"asks":[],"checksum":1513982025,"timestamp":"2024-06-01T18:06:02.133952Z"}]}
{"channel":"book","type":"update","data":[{"symbol":"BCH/EUR","bids":[{"price":425.57,"qty":0.00000000},{"price":425.30,"qty":0.47000000}],"asks":[],"checksum":3082564962,"timestamp":"2024-06-01T18:06:02.628283Z"}]}
{"channel":"book","type":"update","data":[{"symbol":"BCH/EUR","bids":[{"price":425.48,"qty":0.00000000},{"price":425.24,"qty":26.80804300}],"asks":[],"checksum":1765495083,"timestamp":"2024-06-01T18:06:02.637026Z"}]}
{"channel":"book","type":"update","data":[{"symbol":"BCH/EUR","bids":[],"asks":[{"price":426.05,"qty":24.84732600}],"checksum":11693830,"timestamp":"2024-06-01T18:06:02.877300Z"}]}
{"channel":"book","type":"update","data":[{"symbol":"BCH/EUR","bids":[],"asks":[{"price":425.89,"qty":0.00000000},{"price":426.10,"qty":5.40954674}],"checksum":2450117529,"timestamp":"2024-06-01T18:06:02.877650Z"}]}
{"channel":"book","type":"update","data":[{"symbol":"BCH/EUR","bids":[{"price":425.51,"qty":0.00000000},{"price":425.21,"qty":5.42073130}],"asks":[],"checksum":1616404186,"timestamp":"2024-06-01T18:06:02.882582Z"}]}
{"channel":"book","type":"update","data":[{"symbol":"BCH/EUR","bids":[],"asks":[{"price":425.80,"qty":0.00000000},{"price":426.12,"qty":2.00000000}],"checksum":1754045802,"timestamp":"2024-06-01T18:06:02.882610Z"}]}
{"channel":"book","type":"update","data":[{"symbol":"BCH/EUR","bids":[{"price":425.53,"qty":8.09905215}],"asks":[],"checksum":889728213,"timestamp":"2024-06-01T18:06:02.882765Z"}]}
{"channel":"book","type":"update","data":[{"symbol":"BCH/EUR","bids":[{"price":425.56,"qty":3.88726919}],"asks":[],"checksum":740708805,"timestamp":"2024-06-01T18:06:02.883483Z"}]}
{"channel":"book","type":"update","data":[{"symbol":"BCH/EUR","bids":[],"asks":[{"price":425.77,"qty":0.00000000},{"price":426.27,"qty":16.24740803}],"checksum":1397097747,"timestamp":"2024-06-01T18:06:02.886304Z"}]}
{"channel":"book","type":"update","data":[{"symbol":"BCH/EUR","bids":[{"price":425.55,"qty":0.00000000},{"price":425.21,"qty":5.42073130}],"asks":[],"checksum":2177988621,"timestamp":"2024-06-01T18:06:02.886502Z"}]}
{"channel":"book","type":"update","data":[{"symbol":"BCH/EUR","bids":[],"asks":[{"price":425.86,"qty":0.45000000}],"checksum":1871914168,"timestamp":"2024-06-01T18:06:02.886718Z"}]}
{"channel":"book","type":"update","data":[{"symbol":"BCH/EUR","bids":[{"price":425.57,"qty":0.45000000}],"asks":[],"checksum":2742106401,"timestamp":"2024-06-01T18:06:02.886970Z"}]}
{"channel":"book","type":"update","data":[{"symbol":"BCH/EUR","bids":[],"asks":[{"price":425.79,"qty":0.00000000},{"price":426.27,"qty":16.24740803}],"checksum":799085445,"timestamp":"2024-06-01T18:06:02.887475Z"}]}
{"channel":"book","type":"update","data":[{"symbol":"BCH/EUR","bids":[],"asks":[{"price":425.85,"qty":5.41268749}],"checksum":2680860783,"timestamp":"2024-06-01T18:06:02.887861Z"}]}
{"channel":"book","type":"update","data":[{"symbol":"BCH/EUR","bids":[{"price":425.56,"qty":9.30359149}],"asks":[],"checksum":3508957525,"timestamp":"2024-06-01T18:06:02.888007Z"}]}
{"channel":"book","type":"update","data":[{"symbol":"BCH/EUR","bids":[],"asks":[{"price":425.86,"qty":0.00000000},{"price":426.27,"qty":16.24740803}],"checksum":1530791085,"timestamp":"2024-06-01T18:06:02.890529Z"}]}
{"channel":"book","type":"update","data":[{"symbol":"BCH/EUR","bids":[],"asks":[{"price":425.83,"qty":0.45000000}],"checksum":2165652633,"timestamp":"2024-06-01T18:06:02.890720Z"}]}
{"channel":"book","type":"update","data":[{"symbol":"BCH/EUR","bids":[],"asks":[{"price":425.85,"qty":5.77512625}],"checksum":2261157752,"timestamp":"2024-06-01T18:06:02.891497Z"}]}
{"channel":"book","type":"update","data":[{"symbol":"BCH/EUR","bids":[],"asks":[{"price":425.85,"qty":5.41268749}],"checksum":2165652633,"timestamp":"2024-06-01T18:06:02.894533Z"}]}
{"channel":"book","type":"update","data":[{"symbol":"BCH/EUR","bids":[],"asks":[{"price":425.93,"qty":0.00000000},{"price":426.27,"qty":16.24740803}],"checksum":1099032258,"timestamp":"2024-06-01T18:06:02.901078Z"}]}
{"channel":"book","type":"update","data":[{"symbol":"BCH/EUR","bids":[],"asks":[{"price":426.12,"qty":0.00000000},{"price":426.31,"qty":1.08400000}],"checksum":3886649072,"timestamp":"2024-06-01T18:06:02.954889Z"}]}
{"channel":"book","type":"update","data":[{"symbol":"BCH/EUR","bids":[{"price":425.57,"qty":8.28392088}],"asks":[],"checksum":466432811,"timestamp":"2024-06-01T18:06:03.011791Z"}]}
{"channel":"book","type":"update","data":[{"symbol":"BCH/EUR","bids":[],"asks":[{"price":426.14,"qty":8.00000000}],"checksum":141432512,"timestamp":"2024-06-01T18:06:03.016756Z"}]}
{"channel":"book","type":"update","data":[{"symbol":"BCH/EUR","bids":[{"price":425.44,"qty":0.00000000},{"price":425.21,"qty":5.42073130}],"asks":[],"checksum":2414728907,"timestamp":"2024-06-01T18:06:03.017387Z"}]}
{"channel":"book","type":"update","data":[{"symbol":"BCH/EUR","bids":[],"asks":[{"price":425.98,"qty":3.88726919}],"checksum":532558795,"timestamp":"2024-06-01T18:06:03.017633Z"}]}
{"channel":"book","type":"update","data":[{"symbol":"BCH/EUR","bids":[],"asks":[{"price":425.91,"qty":0.03152465}],"checksum":3864504906,"timestamp":"2024-06-01T18:06:03.029295Z"}]}
{"channel":"book","type":"update","data":[{"symbol":"BCH/EUR","bids":[],"asks":[{"price":425.80,"qty":1.21000000}],"checksum":3436885979,"timestamp":"2024-06-01T18:06:03.046584Z"}]}
{"channel":"book","type":"update","data":[{"symbol":"BCH/EUR","bids":[{"price":425.52,"qty":0.00000000},{"price":425.15,"qty":12.24000000}],"asks":[],"checksum":2550141251,"timestamp":"2024-06-01T18:06:03.050409Z"}]}
{"channel":"book","type":"update","data":[{"symbol":"BCH/EUR","bids":[{"price":425.57,"qty":16.28392088}],"asks":[],"checksum":1346671350,"timestamp":"2024-06-01T18:06:03.053759Z"}]}
{"channel":"book","type":"update","data":[{"symbol":"BCH/EUR","bids":[{"price":425.53,"qty":0.09905215}],"asks":[],"checksum":2490475491,"timestamp":"2024-06-01T18:06:03.135989Z"}]}
{"channel":"book","type":"update","data":[{"symbol":"BCH/EUR","bids":[],"asks":[{"price":425.91,"qty":0.00000000},{"price":426.10,"qty":5.40954674}],"checksum":1806472699,"timestamp":"2024-06-01T18:06:03.495120Z"}]}
{"channel":"book","type":"update","data":[{"symbol":"BCH/EUR","bids":[{"price":425.16,"qty":0.53091095}],"asks":[],"checksum":3250111158,"timestamp":"2024-06-01T18:06:03.514202Z"}]}
{"channel":"book","type":"update","data":[{"symbol":"BCH/EUR","bids":[{"price":425.56,"qty":3.88726919}],"asks":[],"checksum":1951721128,"timestamp":"2024-06-01T18:06:03.533015Z"}]}
{"channel":"book","type":"update","data":[{"symbol":"BCH/EUR","bids":[{"price":425.58,"qty":5.41606776}],"asks":[],"checksum":3495767053,"timestamp":"2024-06-01T18:06:03.538104Z"}]}
{"channel":"book","type":"update","data":[{"symbol":"BCH/EUR","bids":[{"price":425.57,"qty":15.83392088}],"asks":[],"checksum":2024609016,"timestamp":"2024-06-01T18:06:03.541452Z"}]}
{"channel":"book","type":"update","data":[{"symbol":"BCH/EUR","bids":[{"price":425.59,"qty":0.45000000}],"asks":[],"checksum":3069209121,"timestamp":"2024-06-01T18:06:03.541620Z"}]}
{"channel":"book","type":"update","data":[{"symbol":"BCH/EUR","bids":[{"price":425.58,"qty":7.41606776}],"asks":[],"checksum":1676986045,"timestamp":"2024-06-01T18:06:03.552016Z"}]}
{"channel":"book","type":"update","data":[{"symbol":"BCH/EUR","bids":[],"asks":[{"price":425.92,"qty":0.03152465}],"checksum":3941099549,"timestamp":"2024-06-01T18:06:03.619887Z"}]}
{"channel":"book","type":"update","data":[{"symbol":"BCH/EUR","bids":[],"asks":[{"price":425.80,"qty":0.00000000},{"price":426.10,"qty":5.40954674}],"checksum":928399794,"timestamp":"2024-06-01T18:06:03.696051Z"}]}
{"channel":"book","type":"update","data":[{"symbol":"BCH/EUR","bids":[{"price":425.52,"qty":7.83392088}],"asks":[],"checksum":2323586995,"timestamp":"2024-06-01T18:06:05.010918Z"}]}
{"channel":"book","type":"update","data":[{"symbol":"BCH/EUR","bids":[],"asks":[{"price":425.88,"qty":0.00000000},{"price":426.14,"qty":8.00000000}],"checksum":1962908359,"timestamp":"2024-06-01T18:06:05.010986Z"}]}
{"channel":"book","type":"update","data":[{"symbol":"BCH/EUR","bids":[{"price":425.57,"qty":8.00000000}],"asks":[],"checksum":1738255537,"timestamp":"2024-06-01T18:06:05.011017Z"}]}
{"channel":"book","type":"update","data":[{"symbol":"BCH/EUR","bids":[{"price":425.57,"qty":0.00000000},{"price":425.24,"qty":26.80804300}],"asks":[],"checksum":2337026472,"timestamp":"2024-06-01T18:06:05.135025Z"}]}
{"channel":"book","type":"update","data":[{"symbol":"BCH/EUR","bids":[{"price":425.53,"qty":8.09905215}],"asks":[],"checksum":4178422210,"timestamp":"2024-06-01T18:06:05.139914Z"}]}
{"channel":"book","type":"update","data":[{"symbol":"BCH/EUR","bids":[],"asks":[{"price":425.84,"qty":7.83392088}],"checksum":1474342833,"timestamp":"2024-06-01T18:06:06.512744Z"}]}
{"channel":"book","type":"update","data":[{"symbol":"BCH/EUR","bids":[],"asks":[{"price":425.82,"qty":0.44395702}],"checksum":1379429970,"timestamp":"2024-06-01T18:06:11.088463Z"}]}
{"channel":"book","type":"update","data":[{"symbol":"BCH/EUR","bids":[],"asks":[{"price":425.82,"qty":0.00000000},{"price":426.10,"qty":5.40954674}],"checksum":1474342833,"timestamp":"2024-06-01T18:06:11.667358Z"}]}
{"channel":"book","type":"update","data":[{"symbol":"BCH/EUR","bids":[],"asks":[{"price":425.84,"qty":0.00000000},{"price":426.14,"qty":8.00000000}],"checksum":4178422210,"timestamp":"2024-06-01T18:06:11.714114Z"}]}
{"channel":"book","type":"update","data":[{"symbol":"BCH/EUR","bids":[{"price":425.59,"qty":8.28392088}],"asks":[],"checksum":4139275274,"timestamp":"2024-06-01T18:06:11.718822Z"}]}
{"channel":"book","type":"update","data":[{"symbol":"BCH/EUR","bids":[{"price":425.59,"qty":0.45000000}],"asks":[],"checksum":4178422210,"timestamp":"2024-06-01T18:06:11.728279Z"}]}
{"channel":"book","type":"update","data":[{"symbol":"BCH/EUR","bids":[],"asks":[{"price":425.92,"qty":0.00000000},{"price":426.27,"qty":16.24740803}],"checksum":2475037721,"timestamp":"2024-06-01T18:06:11.733262Z"}]}
{"channel":"book","type":"update","data":[{"symbol":"BCH/EUR","bids":[{"price":425.58,"qty":2.00000000}],"asks":[],"checksum":3642669728,"timestamp":"2024-06-01T18:06:11.766378Z"}]}
{"channel":"book","type":"update","data":[{"symbol":"BCH/EUR","bids":[],"asks":[{"price":425.85,"qty":0.00000000},{"price":426.31,"qty":1.08400000}],"checksum":594903632,"timestamp":"2024-06-01T18:06:11.766496Z"}]}
{"channel":"book","type":"update","data":[{"symbol":"BCH/EUR","bids":[],"asks":[{"price":425.83,"qty":0.00000000},{"price":426.34,"qty":8.25392088}],"checksum":652890470,"timestamp":"2024-06-01T18:06:11.769803Z"}]}
{"channel":"book","type":"update","data":[{"symbol":"BCH/EUR","bids":[],"asks":[{"price":425.92,"qty":0.45000000}],"checksum":3155306471,"timestamp":"2024-06-01T18:06:11.770101Z"}]}
{"channel":"book","type":"update","data":[{"symbol":"BCH/EUR","bids":[{"price":425.60,"qty":5.41581324}],"asks":[],"checksum":1193704990,"timestamp":"2024-06-01T18:06:11.771966Z"}]}
{"channel":"book","type":"update","data":[{"symbol":"BCH/EUR","bids":[],"asks":[{"price":425.89,"qty":5.41214725}],"checksum":3891324725,"timestamp":"2024-06-01T18:06:11.772042Z"}]}
{"channel":"book","type":"update","data":[{"symbol":"BCH/EUR","bids":[{"price":425.58,"qty":0.00000000},{"price":425.24,"qty":26.80804300}],"asks":[],"checksum":4281975436,"timestamp":"2024-06-01T18:06:11.774950Z"}]}
{"channel":"book","type":"update","data":[{"symbol":"BCH/EUR","bids":[{"price":425.57,"qty":2.00000000}],"asks":[],"checksum":1556888259,"timestamp":"2024-06-01T18:06:11.775071Z"}]}
{"channel":"book","type":"update","data":[{"symbol":"BCH/EUR","bids":[],"asks":[{"price":425.92,"qty":0.00000000},{"price":426.31,"qty":1.08400000}],"checksum":2074053067,"timestamp":"2024-06-01T18:06:11.775583Z"}]}
{"channel":"book","type":"update","data":[{"symbol":"BCH/EUR","bids":[],"asks":[{"price":425.87,"qty":0.45000000}],"checksum":4172160033,"timestamp":"2024-06-01T18:06:11.775727Z"}]}
{"channel":"book","type":"update","data":[{"symbol":"BCH/EUR","bids":[{"price":425.53,"qty":0.09905215}],"asks":[],"checksum":3340787495,"timestamp":"2024-06-01T18:06:11.779398Z"}]}
{"channel":"book","type":"update","data":[{"symbol":"BCH/EUR","bids":[{"price":425.59,"qty":0.00000000},{"price":425.24,"qty":26.80804300}],"asks":[],"checksum":3993427912,"timestamp":"2024-06-01T18:06:11.799160Z"}]}
{"channel":"book","type":"update","data":[{"symbol":"BCH/EUR","bids":[{"price":425.61,"qty":0.45000000}],"asks":[],"checksum":985501448,"timestamp":"2024-06-01T18:06:11.799560Z"}]}
{"channel":"book","type":"update","data":[{"symbol":"BCH/EUR","bids":[{"price":425.61,"qty":2.45000000}],"asks":[],"checksum":3303604908,"timestamp":"2024-06-01T18:06:11.806070Z"}]}
{"channel":"book","type":"update","data":[{"symbol":"BCH/EUR","bids":[{"price":425.53,"qty":8.09905215}],"asks":[],"checksum":889418529,"timestamp":"2024-06-01T18:06:11.810376Z"}]}
{"channel":"book","type":"update","data":[{"symbol":"BCH/EUR","bids":[],"asks":[{"price":425.86,"qty":0.46889802}],"checksum":2536316028,"timestamp":"2024-06-01T18:06:11.814084Z"}]}
{"channel":"book","type":"update","data":[{"symbol":"BCH/EUR","bids":[{"price":425.57,"qty":0.00000000},{"price":425.24,"qty":26.80804300}],"asks":[],"checksum":2754383287,"timestamp":"2024-06-01T18:06:11.837081Z"}]}
{"channel":"book","type":"update","data":[{"symbol":"BCH/EUR","bids":[],"asks":[{"price":425.93,"qty":0.03152465}],"checksum":3153523298,"timestamp":"2024-06-01T18:06:11.852098Z"}]}
{"channel":"book","type":"update","data":[{"symbol":"BCH/EUR","bids":[{"price":425.60,"qty":0.00000000},{"price":425.21,"qty":5.42073130}],"asks":[],"checksum":1190750418,"timestamp":"2024-06-01T18:06:12.014022Z"}]}
{"channel":"book","type":"update","data":[{"symbol":"BCH/EUR","bids":[],"asks":[{"price":425.97,"qty":0.00000000},{"price":426.14,"qty":8.00000000}],"checksum":2502984747,"timestamp":"2024-06-01T18:06:12.089040Z"}]}
{"channel":"book","type":"update","data":[{"symbol":"BCH/EUR","bids":[],"asks":[{"price":426.14,"qty":0.00000000},{"price":426.27,"qty":16.24740803}],"checksum":3487170063,"timestamp":"2024-06-01T18:06:12.090164Z"}]}
{"channel":"book","type":"update","data":[{"symbol":"BCH/EUR","bids":[],"asks":[{"price":425.98,"qty":0.00000000},{"price":426.31,"qty":1.08400000}],"checksum":1268750910,"timestamp":"2024-06-01T18:06:12.090831Z"}]}
{"channel":"book","type":"update","data":[{"symbol":"BCH/EUR","bids":[],"asks":[{"price":426.06,"qty":4.34547891}],"checksum":3231623040,"timestamp":"2024-06-01T18:06:12.094040Z"}]}
{"channel":"book","type":"update","data":[{"symbol":"BCH/EUR","bids":[],"asks":[{"price":425.89,"qty":0.00000000},{"price":426.31,"qty":1.08400000}],"checksum":326166786,"timestamp":"2024-06-01T18:06:12.095683Z"}]}
{"channel":"book","type":"update","data":[{"symbol":"BCH/EUR","bids":[{"price":425.70,"qty":0.84000000}],"asks":[],"checksum":3898148129,"timestamp":"2024-06-01T18:06:12.096826Z"}]}
{"channel":"book","type":"update","data":[{"symbol":"BCH/EUR","bids":[],"asks":[{"price":425.87,"qty":0.00000000},{"price":426.34,"qty":0.42000000}],"checksum":27000086,"timestamp":"2024-06-01T18:06:12.098456Z"}]}
{"channel":"book","type":"update","data":[{"symbol":"BCH/EUR","bids":[],"asks":[{"price":425.91,"qty":0.45000000}],"checksum":3971221090,"timestamp":"2024-06-01T18:06:12.098693Z"}]}
{"channel":"book","type":"update","data":[{"symbol":"BCH/EUR","bids":[],"asks":[{"price":425.86,"qty":0.00000000},{"price":426.34,"qty":0.42000000}],"checksum":670933503,"timestamp":"2024-06-01T18:06:12.102638Z"}]}
{"channel":"book","type":"update","data":[{"symbol":"BCH/EUR","bids":[],"asks":[{"price":425.90,"qty":0.46889802}],"checksum":2116511533,"timestamp":"2024-06-01T18:06:12.106279Z"}]}
