{"channel":"book","type":"snapshot","data":[{"symbol":"BCH/AUD","bids":[{"price":693.36,"qty":6.00000000},{"price":693.35,"qty":1.00000000},{"price":693.13,"qty":6.14435558},{"price":693.12,"qty":0.26329050},{"price":692.60,"qty":2.00000000},{"price":692.23,"qty":2.74650750},{"price":692.22,"qty":1.00000000},{"price":691.85,"qty":10.93257000},{"price":691.84,"qty":0.03285025},{"price":691.48,"qty":0.26329050}],"asks":[{"price":695.34,"qty":6.26329050},{"price":695.35,"qty":4.00000000},{"price":695.60,"qty":0.02500000},{"price":695.87,"qty":2.58370377},{"price":695.88,"qty":2.74650750},{"price":696.39,"qty":10.93257000},{"price":697.18,"qty":0.26329050},{"price":698.63,"qty":7.88802300},{"price":698.96,"qty":0.02510049},{"price":698.97,"qty":5.41950750}],"checksum":614591339}]}
{"channel":"book","type":"update","data":[{"symbol":"BCH/AUD","bids":[{"price":693.13,"qty":0.00000000},{"price":691.13,"qty":7.88802300}],"asks":[],"checksum":817733454,"timestamp":"2024-06-01T18:05:42.535059Z"}]}
{"channel":"book","type":"update","data":[{"symbol":"BCH/AUD","bids":[{"price":693.37,"qty":6.14222875}],"asks":[],"checksum":1919759420,"timestamp":"2024-06-01T18:05:42.535211Z"}]}
{"channel":"book","type":"update","data":[{"symbol":"BCH/AUD","bids":[{"price":693.38,"qty":6.00000000}],"asks":[],"checksum":1599363510,"timestamp":"2024-06-01T18:05:42.642713Z"}]}
{"channel":"book","type":"update","data":[{"symbol":"BCH/AUD","bids":[{"price":693.36,"qty":0.00000000},{"price":691.48,"qty":0.26329050}],"asks":[],"checksum":226753414,"timestamp":"2024-06-01T18:05:42.647879Z"}]}
{"channel":"book","type":"update","data":[{"symbol":"BCH/AUD","bids":[{"price":693.39,"qty":6.14205152}],"asks":[],"checksum":1399144842,"timestamp":"2024-06-01T18:05:43.601561Z"}]}
{"channel":"book","type":"update","data":[{"symbol":"BCH/AUD","bids":[{"price":693.37,"qty":0.00000000},{"price":691.48,"qty":0.26329050}],"asks":[],"checksum":2432080624,"timestamp":"2024-06-01T18:05:43.601792Z"}]}
{"channel":"book","type":"update","data":[{"symbol":"BCH/AUD","bids":[{"price":693.40,"qty":6.00000000}],"asks":[],"checksum":480192687,"timestamp":"2024-06-01T18:05:43.609718Z"}]}
{"channel":"book","type":"update","data":[{"symbol":"BCH/AUD","bids":[{"price":693.38,"qty":0.00000000},{"price":691.48,"qty":0.26329050}],"asks":[],"checksum":1177967966,"timestamp":"2024-06-01T18:05:43.649710Z"}]}
{"channel":"book","type":"update","data":[{"symbol":"BCH/AUD","bids":[{"price":693.39,"qty":0.00000000},{"price":691.13,"qty":7.88802300}],"asks":[],"checksum":4159663787,"timestamp":"2024-06-01T18:05:43.666423Z"}]}
{"channel":"book","type":"update","data":[{"symbol":"BCH/AUD","bids":[{"price":693.36,"qty":6.14231739}],"asks":[],"checksum":2162580900,"timestamp":"2024-06-01T18:05:43.666505Z"}]}
{"channel":"book","type":"update","data":[{"symbol":"BCH/AUD","bids":[{"price":693.40,"qty":0.00000000},{"price":691.13,"qty":7.88802300}],"asks":[],"checksum":3968629347,"timestamp":"2024-06-01T18:05:44.643231Z"}]}
{"channel":"book","type":"update","data":[{"symbol":"BCH/AUD","bids":[{"price":693.37,"qty":6.00000000}],"asks":[],"checksum":1518262623,"timestamp":"2024-06-01T18:05:44.643411Z"}]}
{"channel":"book","type":"update","data":[{"symbol":"BCH/AUD","bids":[{"price":693.36,"qty":0.00000000},{"price":691.13,"qty":7.88802300}],"asks":[],"checksum":762833488,"timestamp":"2024-06-01T18:05:44.666314Z"}]}
{"channel":"book","type":"update","data":[{"symbol":"BCH/AUD","bids":[{"price":693.38,"qty":6.14214014}],"asks":[],"checksum":2982826378,"timestamp":"2024-06-01T18:05:44.666533Z"}]}
{"channel":"book","type":"update","data":[{"symbol":"BCH/AUD","bids":[{"price":693.39,"qty":6.00000000}],"asks":[],"checksum":1567952437,"timestamp":"2024-06-01T18:05:45.143530Z"}]}
{"channel":"book","type":"update","data":[{"symbol":"BCH/AUD","bids":[{"price":693.37,"qty":0.00000000},{"price":691.48,"qty":0.26329050}],"asks":[],"checksum":2683327040,"timestamp":"2024-06-01T18:05:45.148853Z"}]}
{"channel":"book","type":"update","data":[{"symbol":"BCH/AUD","bids":[{"price":693.38,"qty":0.00000000},{"price":691.13,"qty":7.88802300}],"asks":[],"checksum":2409200868,"timestamp":"2024-06-01T18:05:45.163713Z"}]}
{"channel":"book","type":"update","data":[{"symbol":"BCH/AUD","bids":[{"price":693.40,"qty":6.14196304}],"asks":[],"checksum":2624751926,"timestamp":"2024-06-01T18:05:45.163848Z"}]}
{"channel":"book","type":"update","data":[{"symbol":"BCH/AUD","bids":[{"price":693.41,"qty":6.00000000}],"asks":[],"checksum":2299600406,"timestamp":"2024-06-01T18:05:45.643685Z"}]}
{"channel":"book","type":"update","data":[{"symbol":"BCH/AUD","bids":[{"price":693.39,"qty":0.00000000},{"price":691.48,"qty":0.26329050}],"asks":[],"checksum":2851948179,"timestamp":"2024-06-01T18:05:45.648609Z"}]}
{"channel":"book","type":"update","data":[{"symbol":"BCH/AUD","bids":[{"price":693.40,"qty":0.00000000},{"price":691.13,"qty":7.88802300}],"asks":[],"checksum":3928300469,"timestamp":"2024-06-01T18:05:45.672224Z"}]}
{"channel":"book","type":"update","data":[{"symbol":"BCH/AUD","bids":[{"price":693.36,"qty":6.14231739}],"asks":[],"checksum":2636916922,"timestamp":"2024-06-01T18:05:45.672240Z"}]}
{"channel":"book","type":"update","data":[{"symbol":"BCH/AUD","bids":[{"price":693.41,"qty":0.00000000},{"price":691.13,"qty":7.88802300}],"asks":[],"checksum":3968629347,"timestamp":"2024-06-01T18:05:47.143382Z"}]}
{"channel":"book","type":"update","data":[{"symbol":"BCH/AUD","bids":[{"price":693.37,"qty":6.00000000}],"asks":[],"checksum":1518262623,"timestamp":"2024-06-01T18:05:47.143508Z"}]}
{"channel":"book","type":"update","data":[{"symbol":"BCH/AUD","bids":[{"price":693.36,"qty":0.00000000},{"price":691.13,"qty":7.88802300}],"asks":[],"checksum":762833488,"timestamp":"2024-06-01T18:05:47.163785Z"}]}
{"channel":"book","type":"update","data":[{"symbol":"BCH/AUD","bids":[{"price":693.38,"qty":6.14214014}],"asks":[],"checksum":2982826378,"timestamp":"2024-06-01T18:05:47.163966Z"}]}
{"channel":"book","type":"update","data":[{"symbol":"BCH/AUD","bids":[{"price":693.39,"qty":6.00000000}],"asks":[],"checksum":1567952437,"timestamp":"2024-06-01T18:05:47.642764Z"}]}
{"channel":"book","type":"update","data":[{"symbol":"BCH/AUD","bids":[{"price":693.37,"qty":0.00000000},{"price":691.48,"qty":0.26329050}],"asks":[],"checksum":2683327040,"timestamp":"2024-06-01T18:05:47.648870Z"}]}
{"channel":"book","type":"update","data":[{"symbol":"BCH/AUD","bids":[{"price":693.38,"qty":0.00000000},{"price":691.13,"qty":7.88802300}],"asks":[],"checksum":2409200868,"timestamp":"2024-06-01T18:05:47.653674Z"}]}
{"channel":"book","type":"update","data":[{"symbol":"BCH/AUD","bids":[{"price":693.40,"qty":6.14196304}],"asks":[],"checksum":2624751926,"timestamp":"2024-06-01T18:05:47.653989Z"}]}
{"channel":"book","type":"update","data":[{"symbol":"BCH/AUD","bids":[{"price":693.41,"qty":6.00000000}],"asks":[],"checksum":2299600406,"timestamp":"2024-06-01T18:05:48.142800Z"}]}
{"channel":"book","type":"update","data":[{"symbol":"BCH/AUD","bids":[{"price":693.39,"qty":0.00000000},{"price":691.48,"qty":0.26329050}],"asks":[],"checksum":2851948179,"timestamp":"2024-06-01T18:05:48.147983Z"}]}
{"channel":"book","type":"update","data":[{"symbol":"BCH/AUD","bids":[{"price":693.40,"qty":0.00000000},{"price":691.13,"qty":7.88802300}],"asks":[],"checksum":3928300469,"timestamp":"2024-06-01T18:05:48.161378Z"}]}
{"channel":"book","type":"update","data":[{"symbol":"BCH/AUD","bids":[{"price":693.36,"qty":6.14231739}],"asks":[],"checksum":2636916922,"timestamp":"2024-06-01T18:05:48.161447Z"}]}
{"channel":"book","type":"update","data":[{"symbol":"BCH/AUD","bids":[{"price":693.41,"qty":0.00000000},{"price":691.13,"qty":7.88802300}],"asks":[],"checksum":3968629347,"timestamp":"2024-06-01T18:05:49.644721Z"}]}
{"channel":"book","type":"update","data":[{"symbol":"BCH/AUD","bids":[{"price":693.37,"qty":6.00000000}],"asks":[],"checksum":1518262623,"timestamp":"2024-06-01T18:05:49.644812Z"}]}
{"channel":"book","type":"update","data":[{"symbol":"BCH/AUD","bids":[{"price":693.36,"qty":0.00000000},{"price":691.13,"qty":7.88802300}],"asks":[],"checksum":762833488,"timestamp":"2024-06-01T18:05:49.649117Z"}]}
{"channel":"book","type":"update","data":[{"symbol":"BCH/AUD","bids":[{"price":693.38,"qty":6.14214017}],"asks":[],"checksum":767647285,"timestamp":"2024-06-01T18:05:49.649302Z"}]}
{"channel":"book","type":"update","data":[{"symbol":"BCH/AUD","bids":[{"price":693.38,"qty":0.00000000},{"price":691.13,"qty":7.88802300}],"asks":[],"checksum":762833488,"timestamp":"2024-06-01T18:05:50.025596Z"}]}
{"channel":"book","type":"update","data":[{"symbol":"BCH/AUD","bids":[{"price":693.36,"qty":6.14231735}],"asks":[],"checksum":1369129763,"timestamp":"2024-06-01T18:05:50.025731Z"}]}
{"channel":"book","type":"update","data":[{"symbol":"BCH/AUD","bids":[{"price":693.36,"qty":0.00000000},{"price":691.13,"qty":7.88802300}],"asks":[],"checksum":762833488,"timestamp":"2024-06-01T18:05:50.765244Z"}]}
{"channel":"book","type":"update","data":[{"symbol":"BCH/AUD","bids":[{"price":693.38,"qty":6.14214017}],"asks":[],"checksum":767647285,"timestamp":"2024-06-01T18:05:50.765485Z"}]}
{"channel":"book","type":"update","data":[{"symbol":"BCH/AUD","bids":[{"price":693.37,"qty":0.00000000},{"price":691.13,"qty":7.88802300}],"asks":[],"checksum":3544117276,"timestamp":"2024-06-01T18:05:50.771494Z"}]}
{"channel":"book","type":"update","data":[{"symbol":"BCH/AUD","bids":[{"price":693.36,"qty":6.00000000}],"asks":[],"checksum":1195575419,"timestamp":"2024-06-01T18:05:50.771717Z"}]}
{"channel":"book","type":"update","data":[{"symbol":"BCH/AUD","bids":[{"price":693.39,"qty":6.00000000}],"asks":[],"checksum":1299397161,"timestamp":"2024-06-01T18:05:51.143651Z"}]}
{"channel":"book","type":"update","data":[{"symbol":"BCH/AUD","bids":[{"price":693.36,"qty":0.00000000},{"price":691.48,"qty":0.26329050}],"asks":[],"checksum":2634626271,"timestamp":"2024-06-01T18:05:51.149527Z"}]}
{"channel":"book","type":"update","data":[{"symbol":"BCH/AUD","bids":[{"price":693.38,"qty":0.00000000},{"price":691.13,"qty":7.88802300}],"asks":[],"checksum":2409200868,"timestamp":"2024-06-01T18:05:51.153790Z"}]}
{"channel":"book","type":"update","data":[{"symbol":"BCH/AUD","bids":[{"price":693.40,"qty":6.14196300}],"asks":[],"checksum":2534958371,"timestamp":"2024-06-01T18:05:51.153977Z"}]}
{"channel":"book","type":"update","data":[{"symbol":"BCH/AUD","bids":[{"price":693.41,"qty":6.00000000}],"asks":[],"checksum":3195623021,"timestamp":"2024-06-01T18:05:51.644016Z"}]}
{"channel":"book","type":"update","data":[{"symbol":"BCH/AUD","bids":[{"price":693.39,"qty":0.00000000},{"price":691.48,"qty":0.26329050}],"asks":[],"checksum":428789112,"timestamp":"2024-06-01T18:05:51.649003Z"}]}
{"channel":"book","type":"update","data":[{"symbol":"BCH/AUD","bids":[{"price":693.40,"qty":0.00000000},{"price":691.13,"qty":7.88802300}],"asks":[],"checksum":3928300469,"timestamp":"2024-06-01T18:05:51.652832Z"}]}
{"channel":"book","type":"update","data":[{"symbol":"BCH/AUD","bids":[{"price":693.42,"qty":6.14178586}],"asks":[],"checksum":170136880,"timestamp":"2024-06-01T18:05:51.652948Z"}]}
{"channel":"book","type":"update","data":[{"symbol":"BCH/AUD","bids":[{"price":693.43,"qty":6.00000000}],"asks":[],"checksum":2037149522,"timestamp":"2024-06-01T18:05:52.144458Z"}]}
{"channel":"book","type":"update","data":[{"symbol":"BCH/AUD","bids":[{"price":693.41,"qty":0.00000000},{"price":691.48,"qty":0.26329050}],"asks":[],"checksum":275748194,"timestamp":"2024-06-01T18:05:52.149601Z"}]}
{"channel":"book","type":"update","data":[{"symbol":"BCH/AUD","bids":[{"price":693.44,"qty":6.14160872}],"asks":[],"checksum":3353359570,"timestamp":"2024-06-01T18:05:52.165460Z"}]}
{"channel":"book","type":"update","data":[{"symbol":"BCH/AUD","bids":[{"price":693.42,"qty":0.00000000},{"price":691.48,"qty":0.26329050}],"asks":[],"checksum":3834106324,"timestamp":"2024-06-01T18:05:52.165483Z"}]}
{"channel":"book","type":"update","data":[{"symbol":"BCH/AUD","bids":[{"price":693.45,"qty":6.00000000}],"asks":[],"checksum":2058578966,"timestamp":"2024-06-01T18:05:52.643422Z"}]}
{"channel":"book","type":"update","data":[{"symbol":"BCH/AUD","bids":[{"price":693.43,"qty":0.00000000},{"price":691.48,"qty":0.26329050}],"asks":[],"checksum":529636267,"timestamp":"2024-06-01T18:05:52.648721Z"}]}
{"channel":"book","type":"update","data":[{"symbol":"BCH/AUD","bids":[{"price":693.44,"qty":0.00000000},{"price":691.13,"qty":7.88802300}],"asks":[],"checksum":2634862541,"timestamp":"2024-06-01T18:05:52.682173Z"}]}
{"channel":"book","type":"update","data":[{"symbol":"BCH/AUD","bids":[{"price":693.36,"qty":6.14231731}],"asks":[],"checksum":1368649045,"timestamp":"2024-06-01T18:05:52.682372Z"}]}
{"channel":"book","type":"update","data":[{"symbol":"BCH/AUD","bids":[{"price":693.45,"qty":0.00000000},{"price":691.13,"qty":7.88802300}],"asks":[],"checksum":4200178249,"timestamp":"2024-06-01T18:05:54.143100Z"}]}
{"channel":"book","type":"update","data":[{"symbol":"BCH/AUD","bids":[{"price":693.37,"qty":6.00000000}],"asks":[],"checksum":3790129352,"timestamp":"2024-06-01T18:05:54.143172Z"}]}
{"channel":"book","type":"update","data":[{"symbol":"BCH/AUD","bids":[{"price":693.37,"qty":6.23123105}],"asks":[],"checksum":1183020186,"timestamp":"2024-06-01T18:05:54.149714Z"}]}
{"channel":"book","type":"update","data":[{"symbol":"BCH/AUD","bids":[{"price":693.36,"qty":0.00000000},{"price":691.13,"qty":7.88802300}],"asks":[],"checksum":2317112834,"timestamp":"2024-06-01T18:05:54.159923Z"}]}
{"channel":"book","type":"update","data":[{"symbol":"BCH/AUD","bids":[{"price":693.38,"qty":6.14214010}],"asks":[],"checksum":3065753319,"timestamp":"2024-06-01T18:05:54.160049Z"}]}
{"channel":"book","type":"update","data":[{"symbol":"BCH/AUD","bids":[{"price":693.39,"qty":6.00000000}],"asks":[],"checksum":164938954,"timestamp":"2024-06-01T18:05:54.643264Z"}]}
{"channel":"book","type":"update","data":[{"symbol":"BCH/AUD","bids":[{"price":693.40,"qty":6.14196300}],"asks":[],"checksum":3201184619,"timestamp":"2024-06-01T18:05:54.646880Z"}]}
{"channel":"book","type":"update","data":[{"symbol":"BCH/AUD","bids":[{"price":693.38,"qty":0.00000000},{"price":691.84,"qty":0.03285025}],"asks":[],"checksum":3926873188,"timestamp":"2024-06-01T18:05:54.646909Z"}]}
{"channel":"book","type":"update","data":[{"symbol":"BCH/AUD","bids":[{"price":693.37,"qty":0.23123105}],"asks":[],"checksum":1327128349,"timestamp":"2024-06-01T18:05:54.648969Z"}]}
{"channel":"book","type":"update","data":[{"symbol":"BCH/AUD","bids":[{"price":693.40,"qty":0.00000000},{"price":691.48,"qty":0.26329050}],"asks":[],"checksum":2426525420,"timestamp":"2024-06-01T18:05:55.045453Z"}]}
{"channel":"book","type":"update","data":[{"symbol":"BCH/AUD","bids":[{"price":693.38,"qty":6.14214017}],"asks":[],"checksum":1158352609,"timestamp":"2024-06-01T18:05:55.045649Z"}]}
{"channel":"book","type":"update","data":[{"symbol":"BCH/AUD","bids":[{"price":693.38,"qty":0.00000000},{"price":691.48,"qty":0.26329050}],"asks":[],"checksum":2426525420,"timestamp":"2024-06-01T18:05:55.935106Z"}]}
{"channel":"book","type":"update","data":[{"symbol":"BCH/AUD","bids":[{"price":693.40,"qty":6.14196305}],"asks":[],"checksum":813058461,"timestamp":"2024-06-01T18:05:55.935282Z"}]}
{"channel":"book","type":"update","data":[{"symbol":"BCH/AUD","bids":[{"price":693.41,"qty":6.00000000}],"asks":[],"checksum":2189026359,"timestamp":"2024-06-01T18:05:55.941173Z"}]}
{"channel":"book","type":"update","data":[{"symbol":"BCH/AUD","bids":[{"price":693.40,"qty":0.00000000},{"price":691.84,"qty":0.03285025}],"asks":[],"checksum":2320810677,"timestamp":"2024-06-01T18:05:55.962063Z"}]}
{"channel":"book","type":"update","data":[{"symbol":"BCH/AUD","bids":[{"price":693.42,"qty":6.14178579}],"asks":[],"checksum":1607134146,"timestamp":"2024-06-01T18:05:55.962263Z"}]}
{"channel":"book","type":"update","data":[{"symbol":"BCH/AUD","bids":[{"price":693.41,"qty":0.00000000},{"price":691.84,"qty":0.03285025}],"asks":[],"checksum":496048546,"timestamp":"2024-06-01T18:05:56.143695Z"}]}
{"channel":"book","type":"update","data":[{"symbol":"BCH/AUD","bids":[{"price":693.43,"qty":6.00000000}],"asks":[],"checksum":1728623874,"timestamp":"2024-06-01T18:05:56.143728Z"}]}
{"channel":"book","type":"update","data":[{"symbol":"BCH/AUD","bids":[{"price":693.39,"qty":0.00000000},{"price":691.84,"qty":0.03285025}],"asks":[],"checksum":4168875137,"timestamp":"2024-06-01T18:05:56.149909Z"}]}
{"channel":"book","type":"update","data":[{"symbol":"BCH/AUD","bids":[{"price":693.38,"qty":6.14214017}],"asks":[],"checksum":116454987,"timestamp":"2024-06-01T18:05:56.153550Z"}]}
{"channel":"book","type":"update","data":[{"symbol":"BCH/AUD","bids":[{"price":693.42,"qty":0.00000000},{"price":691.84,"qty":0.03285025}],"asks":[],"checksum":455312268,"timestamp":"2024-06-01T18:05:56.153730Z"}]}
{"channel":"book","type":"update","data":[{"symbol":"BCH/AUD","bids":[{"price":693.39,"qty":6.00000000}],"asks":[],"checksum":1335305013,"timestamp":"2024-06-01T18:05:57.642922Z"}]}
{"channel":"book","type":"update","data":[{"symbol":"BCH/AUD","bids":[{"price":693.43,"qty":0.00000000},{"price":691.84,"qty":0.03285025}],"asks":[],"checksum":1158352609,"timestamp":"2024-06-01T18:05:57.642961Z"}]}
{"channel":"book","type":"update","data":[{"symbol":"BCH/AUD","bids":[{"price":693.40,"qty":6.14196305}],"asks":[],"checksum":1535910936,"timestamp":"2024-06-01T18:05:57.647779Z"}]}
{"channel":"book","type":"update","data":[{"symbol":"BCH/AUD","bids":[{"price":693.38,"qty":0.00000000},{"price":691.84,"qty":0.03285025}],"asks":[],"checksum":813058461,"timestamp":"2024-06-01T18:05:57.648232Z"}]}
{"channel":"book","type":"update","data":[{"symbol":"BCH/AUD","bids":[{"price":693.41,"qty":6.00000000}],"asks":[],"checksum":2189026359,"timestamp":"2024-06-01T18:05:58.143088Z"}]}
{"channel":"book","type":"update","data":[{"symbol":"BCH/AUD","bids":[{"price":693.39,"qty":0.00000000},{"price":691.84,"qty":0.03285025}],"asks":[],"checksum":3330759911,"timestamp":"2024-06-01T18:05:58.147991Z"}]}
{"channel":"book","type":"update","data":[{"symbol":"BCH/AUD","bids":[{"price":693.40,"qty":0.00000000},{"price":691.48,"qty":0.26329050}],"asks":[],"checksum":2619294132,"timestamp":"2024-06-01T18:05:58.183008Z"}]}
{"channel":"book","type":"update","data":[{"symbol":"BCH/AUD","bids":[{"price":693.42,"qty":6.14178579}],"asks":[],"checksum":3198886805,"timestamp":"2024-06-01T18:05:58.183020Z"}]}
{"channel":"book","type":"update","data":[{"symbol":"BCH/AUD","bids":[{"price":693.43,"qty":6.00000000}],"asks":[],"checksum":70559738,"timestamp":"2024-06-01T18:05:58.188525Z"}]}
{"channel":"book","type":"update","data":[{"symbol":"BCH/AUD","bids":[{"price":693.41,"qty":0.00000000},{"price":691.84,"qty":0.03285025}],"asks":[],"checksum":4168875137,"timestamp":"2024-06-01T18:05:58.643974Z"}]}
{"channel":"book","type":"update","data":[{"symbol":"BCH/AUD","bids":[{"price":693.42,"qty":0.00000000},{"price":691.48,"qty":0.26329050}],"asks":[],"checksum":1725281684,"timestamp":"2024-06-01T18:05:58.666655Z"}]}
{"channel":"book","type":"update","data":[{"symbol":"BCH/AUD","bids":[{"price":693.38,"qty":6.14214017}],"asks":[],"checksum":455312268,"timestamp":"2024-06-01T18:05:58.666817Z"}]}
{"channel":"book","type":"update","data":[{"symbol":"BCH/AUD","bids":[{"price":693.43,"qty":0.00000000},{"price":691.48,"qty":0.26329050}],"asks":[],"checksum":2219256407,"timestamp":"2024-06-01T18:05:59.643054Z"}]}
{"channel":"book","type":"update","data":[{"symbol":"BCH/AUD","bids":[{"price":693.39,"qty":6.00000000}],"asks":[],"checksum":1158352609,"timestamp":"2024-06-01T18:05:59.643085Z"}]}
{"channel":"book","type":"update","data":[{"symbol":"BCH/AUD","bids":[{"price":693.38,"qty":0.00000000},{"price":691.48,"qty":0.26329050}],"asks":[],"checksum":2426525420,"timestamp":"2024-06-01T18:05:59.670692Z"}]}
{"channel":"book","type":"update","data":[{"symbol":"BCH/AUD","bids":[{"price":693.40,"qty":6.14196305}],"asks":[],"checksum":813058461,"timestamp":"2024-06-01T18:05:59.670783Z"}]}
{"channel":"book","type":"update","data":[{"symbol":"BCH/AUD","bids":[{"price":693.40,"qty":0.00000000},{"price":691.48,"qty":0.26329050}],"asks":[],"checksum":2426525420,"timestamp":"2024-06-01T18:05:59.816881Z"}]}
{"channel":"book","type":"update","data":[{"symbol":"BCH/AUD","bids":[{"price":693.36,"qty":6.14231739}],"asks":[],"checksum":544263989,"timestamp":"2024-06-01T18:05:59.816988Z"}]}
{"channel":"book","type":"update","data":[{"symbol":"BCH/AUD","bids":[{"price":693.39,"qty":0.00000000},{"price":691.48,"qty":0.26329050}],"asks":[],"checksum":3436371035,"timestamp":"2024-06-01T18:05:59.823165Z"}]}
{"channel":"book","type":"update","data":[{"symbol":"BCH/AUD","bids":[{"price":693.37,"qty":6.23123105}],"asks":[],"checksum":4246037773,"timestamp":"2024-06-01T18:05:59.823278Z"}]}
{"channel":"book","type":"update","data":[{"symbol":"BCH/AUD","bids":[{"price":693.13,"qty":6.14435557}],"asks":[],"checksum":1824451090,"timestamp":"2024-06-01T18:06:00.049388Z"}]}
{"channel":"book","type":"update","data":[{"symbol":"BCH/AUD","bids":[{"price":693.36,"qty":0.00000000},{"price":691.48,"qty":0.26329050}],"asks":[],"checksum":2684614911,"timestamp":"2024-06-01T18:06:00.049448Z"}]}
{"channel":"book","type":"update","data":[{"symbol":"BCH/AUD","bids":[{"price":693.36,"qty":6.00000000}],"asks":[],"checksum":791967667,"timestamp":"2024-06-01T18:06:00.056098Z"}]}
{"channel":"book","type":"update","data":[{"symbol":"BCH/AUD","bids":[{"price":693.37,"qty":0.23123105}],"asks":[],"checksum":2903327947,"timestamp":"2024-06-01T18:06:00.056127Z"}]}
{"channel":"book","type":"update","data":[{"symbol":"BCH/AUD","bids":[{"price":693.13,"qty":0.00000000},{"price":691.48,"qty":0.26329050}],"asks":[],"checksum":799414067,"timestamp":"2024-06-01T18:06:00.068402Z"}]}
{"channel":"book","type":"update","data":[{"symbol":"BCH/AUD","bids":[{"price":693.37,"qty":6.37345985}],"asks":[],"checksum":3454871567,"timestamp":"2024-06-01T18:06:00.068416Z"}]}
{"channel":"book","type":"update","data":[{"symbol":"BCH/AUD","bids":[{"price":693.38,"qty":6.00000000}],"asks":[],"checksum":2504728798,"timestamp":"2024-06-01T18:06:00.142861Z"}]}
{"channel":"book","type":"update","data":[{"symbol":"BCH/AUD","bids":[{"price":693.36,"qty":0.00000000},{"price":691.48,"qty":0.26329050}],"asks":[],"checksum":2822248823,"timestamp":"2024-06-01T18:06:00.148123Z"}]}
{"channel":"book","type":"update","data":[{"symbol":"BCH/AUD","bids":[{"price":693.37,"qty":0.23123105}],"asks":[],"checksum":3989089532,"timestamp":"2024-06-01T18:06:00.302606Z"}]}
{"channel":"book","type":"update","data":[{"symbol":"BCH/AUD","bids":[{"price":693.36,"qty":6.14231727}],"asks":[],"checksum":2868695889,"timestamp":"2024-06-01T18:06:00.302843Z"}]}
{"channel":"book","type":"update","data":[{"symbol":"BCH/AUD","bids":[{"price":693.36,"qty":0.00000000},{"price":691.48,"qty":0.26329050}],"asks":[],"checksum":3989089532,"timestamp":"2024-06-01T18:06:00.322041Z"}]}
{"channel":"book","type":"update","data":[{"symbol":"BCH/AUD","bids":[{"price":693.13,"qty":6.14435555}],"asks":[],"checksum":2867548333,"timestamp":"2024-06-01T18:06:00.322281Z"}]}
{"channel":"book","type":"update","data":[{"symbol":"BCH/AUD","bids":[{"price":693.37,"qty":0.00000000},{"price":691.48,"qty":0.26329050}],"asks":[],"checksum":3710958274,"timestamp":"2024-06-01T18:06:00.327026Z"}]}
{"channel":"book","type":"update","data":[{"symbol":"BCH/AUD","bids":[{"price":693.13,"qty":0.00000000},{"price":691.13,"qty":7.88802300}],"asks":[],"checksum":2454915578,"timestamp":"2024-06-01T18:06:01.361553Z"}]}
{"channel":"book","type":"update","data":[{"symbol":"BCH/AUD","bids":[{"price":693.39,"qty":6.14205153}],"asks":[],"checksum":3840958565,"timestamp":"2024-06-01T18:06:01.361751Z"}]}
{"channel":"book","type":"update","data":[{"symbol":"BCH/AUD","bids":[{"price":693.38,"qty":0.00000000},{"price":691.13,"qty":7.88802300}],"asks":[],"checksum":906089749,"timestamp":"2024-06-01T18:06:01.367409Z"}]}
{"channel":"book","type":"update","data":[{"symbol":"BCH/AUD","bids":[{"price":693.36,"qty":6.00000000}],"asks":[],"checksum":2726047090,"timestamp":"2024-06-01T18:06:01.367737Z"}]}
{"channel":"book","type":"update","data":[{"symbol":"BCH/AUD","bids":[{"price":693.39,"qty":0.00000000},{"price":691.13,"qty":7.88802300}],"asks":[],"checksum":817733454,"timestamp":"2024-06-01T18:06:01.384911Z"}]}
{"channel":"book","type":"update","data":[{"symbol":"BCH/AUD","bids":[{"price":693.37,"qty":6.14222879}],"asks":[],"checksum":1876033539,"timestamp":"2024-06-01T18:06:01.385006Z"}]}
{"channel":"book","type":"update","data":[{"symbol":"BCH/AUD","bids":[{"price":693.38,"qty":6.00000000}],"asks":[],"checksum":116162875,"timestamp":"2024-06-01T18:06:01.644105Z"}]}
{"channel":"book","type":"update","data":[{"symbol":"BCH/AUD","bids":[{"price":693.36,"qty":0.00000000},{"price":691.48,"qty":0.26329050}],"asks":[],"checksum":107373050,"timestamp":"2024-06-01T18:06:01.649572Z"}]}
{"channel":"book","type":"update","data":[{"symbol":"BCH/AUD","bids":[{"price":693.39,"qty":6.14205153}],"asks":[],"checksum":3315373748,"timestamp":"2024-06-01T18:06:01.669520Z"}]}
{"channel":"book","type":"update","data":[{"symbol":"BCH/AUD","bids":[{"price":693.37,"qty":0.00000000},{"price":691.48,"qty":0.26329050}],"asks":[],"checksum":3840958565,"timestamp":"2024-06-01T18:06:01.669582Z"}]}
{"channel":"book","type":"update","data":[{"symbol":"BCH/AUD","bids":[{"price":693.40,"qty":6.00000000}],"asks":[],"checksum":2317481985,"timestamp":"2024-06-01T18:06:02.143183Z"}]}
{"channel":"book","type":"update","data":[{"symbol":"BCH/AUD","bids":[{"price":693.38,"qty":0.00000000},{"price":691.48,"qty":0.26329050}],"asks":[],"checksum":4048452884,"timestamp":"2024-06-01T18:06:02.148635Z"}]}
{"channel":"book","type":"update","data":[{"symbol":"BCH/AUD","bids":[{"price":693.39,"qty":0.00000000},{"price":691.13,"qty":7.88802300}],"asks":[],"checksum":4159663787,"timestamp":"2024-06-01T18:06:02.157453Z"}]}
{"channel":"book","type":"update","data":[{"symbol":"BCH/AUD","bids":[{"price":693.36,"qty":6.14231731}],"asks":[],"checksum":997215283,"timestamp":"2024-06-01T18:06:02.157888Z"}]}
{"channel":"book","type":"update","data":[{"symbol":"BCH/AUD","bids":[{"price":693.41,"qty":6.14187436}],"asks":[],"checksum":2979213462,"timestamp":"2024-06-01T18:06:03.514013Z"}]}
{"channel":"book","type":"update","data":[{"symbol":"BCH/AUD","bids":[{"price":693.36,"qty":0.00000000},{"price":691.48,"qty":0.26329050}],"asks":[],"checksum":1504941047,"timestamp":"2024-06-01T18:06:03.514059Z"}]}
{"channel":"book","type":"update","data":[{"symbol":"BCH/AUD","bids":[{"price":693.42,"qty":6.00000000}],"asks":[],"checksum":2881657034,"timestamp":"2024-06-01T18:06:03.521705Z"}]}
{"channel":"book","type":"update","data":[{"symbol":"BCH/AUD","bids":[{"price":693.43,"qty":6.14169726}],"asks":[],"checksum":155514234,"timestamp":"2024-06-01T18:06:03.529663Z"}]}
{"channel":"book","type":"update","data":[{"symbol":"BCH/AUD","bids":[{"price":693.41,"qty":0.00000000},{"price":691.84,"qty":0.03285025}],"asks":[],"checksum":4122277463,"timestamp":"2024-06-01T18:06:03.529805Z"}]}
{"channel":"book","type":"update","data":[{"symbol":"BCH/AUD","bids":[{"price":693.42,"qty":0.00000000},{"price":691.48,"qty":0.26329050}],"asks":[],"checksum":272232357,"timestamp":"2024-06-01T18:06:03.644631Z"}]}
{"channel":"book","type":"update","data":[{"symbol":"BCH/AUD","bids":[{"price":693.44,"qty":6.00000000}],"asks":[],"checksum":2931262248,"timestamp":"2024-06-01T18:06:03.644796Z"}]}
{"channel":"book","type":"update","data":[{"symbol":"BCH/AUD","bids":[{"price":693.40,"qty":0.00000000},{"price":691.48,"qty":0.26329050}],"asks":[],"checksum":417735046,"timestamp":"2024-06-01T18:06:03.650280Z"}]}
{"channel":"book","type":"update","data":[{"symbol":"BCH/AUD","bids":[{"price":693.43,"qty":0.00000000},{"price":691.13,"qty":7.88802300}],"asks":[],"checksum":2160507603,"timestamp":"2024-06-01T18:06:03.654729Z"}]}
{"channel":"book","type":"update","data":[{"symbol":"BCH/AUD","bids":[{"price":693.45,"qty":6.14152012}],"asks":[],"checksum":284524176,"timestamp":"2024-06-01T18:06:03.654940Z"}]}
{"channel":"book","type":"update","data":[{"symbol":"BCH/AUD","bids":[{"price":693.46,"qty":6.00000000}],"asks":[],"checksum":2571644574,"timestamp":"2024-06-01T18:06:04.143363Z"}]}
{"channel":"book","type":"update","data":[{"symbol":"BCH/AUD","bids":[{"price":693.44,"qty":0.00000000},{"price":691.48,"qty":0.26329050}],"asks":[],"checksum":4082035707,"timestamp":"2024-06-01T18:06:04.148983Z"}]}
{"channel":"book","type":"update","data":[{"symbol":"BCH/AUD","bids":[{"price":693.45,"qty":0.00000000},{"price":691.13,"qty":7.88802300}],"asks":[],"checksum":3142734063,"timestamp":"2024-06-01T18:06:04.163791Z"}]}
{"channel":"book","type":"update","data":[{"symbol":"BCH/AUD","bids":[{"price":693.36,"qty":6.14231729}],"asks":[],"checksum":1525003086,"timestamp":"2024-06-01T18:06:04.163972Z"}]}
{"channel":"book","type":"update","data":[{"symbol":"BCH/AUD","bids":[{"price":693.46,"qty":0.00000000},{"price":691.13,"qty":7.88802300}],"asks":[],"checksum":1822235474,"timestamp":"2024-06-01T18:06:05.644429Z"}]}
{"channel":"book","type":"update","data":[{"symbol":"BCH/AUD","bids":[{"price":693.37,"qty":6.00000000}],"asks":[],"checksum":3435137521,"timestamp":"2024-06-01T18:06:05.644481Z"}]}
{"channel":"book","type":"update","data":[{"symbol":"BCH/AUD","bids":[{"price":693.36,"qty":0.00000000},{"price":691.13,"qty":7.88802300}],"asks":[],"checksum":762833488,"timestamp":"2024-06-01T18:06:05.677415Z"}]}
{"channel":"book","type":"update","data":[{"symbol":"BCH/AUD","bids":[{"price":693.38,"qty":6.14214014}],"asks":[],"checksum":2982826378,"timestamp":"2024-06-01T18:06:05.677457Z"}]}
{"channel":"book","type":"update","data":[{"symbol":"BCH/AUD","bids":[{"price":693.37,"qty":0.00000000},{"price":691.13,"qty":7.88802300}],"asks":[],"checksum":1328938915,"timestamp":"2024-06-01T18:06:05.682958Z"}]}
{"channel":"book","type":"update","data":[{"symbol":"BCH/AUD","bids":[{"price":693.36,"qty":6.00000000}],"asks":[],"checksum":3678930884,"timestamp":"2024-06-01T18:06:05.683056Z"}]}
{"channel":"book","type":"update","data":[{"symbol":"BCH/AUD","bids":[{"price":693.39,"qty":6.00000000}],"asks":[],"checksum":767643034,"timestamp":"2024-06-01T18:06:06.142343Z"}]}
{"channel":"book","type":"update","data":[{"symbol":"BCH/AUD","bids":[{"price":693.36,"qty":0.00000000},{"price":691.48,"qty":0.26329050}],"asks":[],"checksum":2683327040,"timestamp":"2024-06-01T18:06:06.147893Z"}]}
{"channel":"book","type":"update","data":[{"symbol":"BCH/AUD","bids":[{"price":693.38,"qty":0.00000000},{"price":691.13,"qty":7.88802300}],"asks":[],"checksum":2409200868,"timestamp":"2024-06-01T18:06:06.178323Z"}]}
{"channel":"book","type":"update","data":[{"symbol":"BCH/AUD","bids":[{"price":693.40,"qty":6.14196300}],"asks":[],"checksum":2534958371,"timestamp":"2024-06-01T18:06:06.178604Z"}]}
{"channel":"book","type":"update","data":[{"symbol":"BCH/AUD","bids":[{"price":693.41,"qty":6.00000000}],"asks":[],"checksum":3195623021,"timestamp":"2024-06-01T18:06:06.644727Z"}]}
{"channel":"book","type":"update","data":[{"symbol":"BCH/AUD","bids":[{"price":693.39,"qty":0.00000000},{"price":691.48,"qty":0.26329050}],"asks":[],"checksum":428789112,"timestamp":"2024-06-01T18:06:06.649648Z"}]}
{"channel":"book","type":"update","data":[{"symbol":"BCH/AUD","bids":[{"price":693.40,"qty":0.00000000},{"price":691.13,"qty":7.88802300}],"asks":[],"checksum":3928300469,"timestamp":"2024-06-01T18:06:06.675725Z"}]}
{"channel":"book","type":"update","data":[{"symbol":"BCH/AUD","bids":[{"price":693.42,"qty":6.14178587}],"asks":[],"checksum":2116218789,"timestamp":"2024-06-01T18:06:06.676018Z"}]}
{"channel":"book","type":"update","data":[{"symbol":"BCH/AUD","bids":[{"price":693.43,"qty":6.00000000}],"asks":[],"checksum":4023566332,"timestamp":"2024-06-01T18:06:06.681513Z"}]}
{"channel":"book","type":"update","data":[{"symbol":"BCH/AUD","bids":[{"price":693.44,"qty":6.14160875}],"asks":[],"checksum":747050982,"timestamp":"2024-06-01T18:06:06.699676Z"}]}
{"channel":"book","type":"update","data":[{"symbol":"BCH/AUD","bids":[{"price":693.42,"qty":0.00000000},{"price":691.84,"qty":0.03285025}],"asks":[],"checksum":1829681850,"timestamp":"2024-06-01T18:06:06.699695Z"}]}
{"channel":"book","type":"update","data":[{"symbol":"BCH/AUD","bids":[{"price":693.43,"qty":0.00000000},{"price":691.48,"qty":0.26329050}],"asks":[],"checksum":2799869666,"timestamp":"2024-06-01T18:06:07.142877Z"}]}
{"channel":"book","type":"update","data":[{"symbol":"BCH/AUD","bids":[{"price":693.45,"qty":6.00000000}],"asks":[],"checksum":3422672000,"timestamp":"2024-06-01T18:06:07.142900Z"}]}
{"channel":"book","type":"update","data":[{"symbol":"BCH/AUD","bids":[{"price":693.41,"qty":0.00000000},{"price":691.48,"qty":0.26329050}],"asks":[],"checksum":2904258271,"timestamp":"2024-06-01T18:06:07.148244Z"}]}
{"channel":"book","type":"update","data":[{"symbol":"BCH/AUD","bids":[{"price":693.44,"qty":0.00000000},{"price":691.13,"qty":7.88802300}],"asks":[],"checksum":2634862541,"timestamp":"2024-06-01T18:06:07.148656Z"}]}
{"channel":"book","type":"update","data":[{"symbol":"BCH/AUD","bids":[{"price":693.46,"qty":6.14143164}],"asks":[],"checksum":395556819,"timestamp":"2024-06-01T18:06:07.148832Z"}]}
{"channel":"book","type":"update","data":[{"symbol":"BCH/AUD","bids":[{"price":693.47,"qty":6.00000000}],"asks":[],"checksum":2756165850,"timestamp":"2024-06-01T18:06:07.643747Z"}]}
{"channel":"book","type":"update","data":[{"symbol":"BCH/AUD","bids":[{"price":693.45,"qty":0.00000000},{"price":691.48,"qty":0.26329050}],"asks":[],"checksum":4202846363,"timestamp":"2024-06-01T18:06:07.649654Z"}]}
{"channel":"book","type":"update","data":[{"symbol":"BCH/AUD","bids":[{"price":693.46,"qty":0.00000000},{"price":691.13,"qty":7.88802300}],"asks":[],"checksum":2794989041,"timestamp":"2024-06-01T18:06:07.659946Z"}]}
{"channel":"book","type":"update","data":[{"symbol":"BCH/AUD","bids":[{"price":693.36,"qty":6.14231729}],"asks":[],"checksum":1194313296,"timestamp":"2024-06-01T18:06:07.660064Z"}]}
{"channel":"book","type":"update","data":[{"symbol":"BCH/AUD","bids":[{"price":693.47,"qty":0.00000000},{"price":691.13,"qty":7.88802300}],"asks":[],"checksum":1822235474,"timestamp":"2024-06-01T18:06:09.143095Z"}]}
{"channel":"book","type":"update","data":[{"symbol":"BCH/AUD","bids":[{"price":693.37,"qty":6.00000000}],"asks":[],"checksum":3435137521,"timestamp":"2024-06-01T18:06:09.143621Z"}]}
{"channel":"book","type":"update","data":[{"symbol":"BCH/AUD","bids":[{"price":693.38,"qty":6.14214020}],"asks":[],"checksum":1886472290,"timestamp":"2024-06-01T18:06:09.159803Z"}]}
{"channel":"book","type":"update","data":[{"symbol":"BCH/AUD","bids":[{"price":693.36,"qty":0.00000000},{"price":691.48,"qty":0.26329050}],"asks":[],"checksum":3789691021,"timestamp":"2024-06-01T18:06:09.159821Z"}]}
{"channel":"book","type":"update","data":[{"symbol":"BCH/AUD","bids":[{"price":693.39,"qty":6.00000000}],"asks":[],"checksum":940905999,"timestamp":"2024-06-01T18:06:09.643733Z"}]}
{"channel":"book","type":"update","data":[{"symbol":"BCH/AUD","bids":[{"price":693.37,"qty":0.00000000},{"price":691.48,"qty":0.26329050}],"asks":[],"checksum":1328655896,"timestamp":"2024-06-01T18:06:09.648791Z"}]}
{"channel":"book","type":"update","data":[{"symbol":"BCH/AUD","bids":[{"price":693.40,"qty":6.14196297}],"asks":[],"checksum":2172943504,"timestamp":"2024-06-01T18:06:09.650496Z"}]}
{"channel":"book","type":"update","data":[{"symbol":"BCH/AUD","bids":[{"price":693.38,"qty":0.00000000},{"price":691.48,"qty":0.26329050}],"asks":[],"checksum":177990381,"timestamp":"2024-06-01T18:06:09.650724Z"}]}
{"channel":"book","type":"update","data":[{"symbol":"BCH/AUD","bids":[{"price":693.41,"qty":6.00000000}],"asks":[],"checksum":985402158,"timestamp":"2024-06-01T18:06:10.142592Z"}]}
{"channel":"book","type":"update","data":[{"symbol":"BCH/AUD","bids":[{"price":693.39,"qty":0.00000000},{"price":691.48,"qty":0.26329050}],"asks":[],"checksum":1653756011,"timestamp":"2024-06-01T18:06:10.150150Z"}]}
{"channel":"book","type":"update","data":[{"symbol":"BCH/AUD","bids":[{"price":693.40,"qty":0.00000000},{"price":691.13,"qty":7.88802300}],"asks":[],"checksum":3928300469,"timestamp":"2024-06-01T18:06:10.157847Z"}]}
{"channel":"book","type":"update","data":[{"symbol":"BCH/AUD","bids":[{"price":693.42,"qty":6.14178586}],"asks":[],"checksum":170136880,"timestamp":"2024-06-01T18:06:10.157903Z"}]}
{"channel":"book","type":"update","data":[{"symbol":"BCH/AUD","bids":[{"price":693.43,"qty":6.00000000}],"asks":[],"checksum":2037149522,"timestamp":"2024-06-01T18:06:10.643734Z"}]}
{"channel":"book","type":"update","data":[{"symbol":"BCH/AUD","bids":[{"price":693.41,"qty":0.00000000},{"price":691.48,"qty":0.26329050}],"asks":[],"checksum":275748194,"timestamp":"2024-06-01T18:06:10.648961Z"}]}
{"channel":"book","type":"update","data":[{"symbol":"BCH/AUD","bids":[{"price":693.42,"qty":0.00000000},{"price":691.13,"qty":7.88802300}],"asks":[],"checksum":3518099849,"timestamp":"2024-06-01T18:06:10.657853Z"}]}
{"channel":"book","type":"update","data":[{"symbol":"BCH/AUD","bids":[{"price":693.44,"qty":6.14160868}],"asks":[],"checksum":2588843493,"timestamp":"2024-06-01T18:06:10.657932Z"}]}
{"channel":"book","type":"update","data":[{"symbol":"BCH/AUD","bids":[{"price":693.45,"qty":6.00000000}],"asks":[],"checksum":3549916098,"timestamp":"2024-06-01T18:06:11.142965Z"}]}
{"channel":"book","type":"update","data":[{"symbol":"BCH/AUD","bids":[{"price":693.43,"qty":0.00000000},{"price":691.48,"qty":0.26329050}],"asks":[],"checksum":2268601415,"timestamp":"2024-06-01T18:06:11.148636Z"}]}
{"channel":"book","type":"update","data":[{"symbol":"BCH/AUD","bids":[{"price":693.46,"qty":6.14143160}],"asks":[],"checksum":2967519774,"timestamp":"2024-06-01T18:06:11.150337Z"}]}
{"channel":"book","type":"update","data":[{"symbol":"BCH/AUD","bids":[{"price":693.44,"qty":0.00000000},{"price":691.48,"qty":0.26329050}],"asks":[],"checksum":486104006,"timestamp":"2024-06-01T18:06:11.150412Z"}]}
{"channel":"book","type":"update","data":[{"symbol":"BCH/AUD","bids":[{"price":693.47,"qty":6.00000000}],"asks":[],"checksum":2469365921,"timestamp":"2024-06-01T18:06:11.643575Z"}]}
{"channel":"book","type":"update","data":[{"symbol":"BCH/AUD","bids":[{"price":693.45,"qty":0.00000000},{"price":691.48,"qty":0.26329050}],"asks":[],"checksum":1257362288,"timestamp":"2024-06-01T18:06:11.649121Z"}]}
{"channel":"book","type":"update","data":[{"symbol":"BCH/AUD","bids":[{"price":693.46,"qty":0.00000000},{"price":691.13,"qty":7.88802300}],"asks":[],"checksum":2794989041,"timestamp":"2024-06-01T18:06:11.673282Z"}]}
{"channel":"book","type":"update","data":[{"symbol":"BCH/AUD","bids":[{"price":693.36,"qty":6.14231734}],"asks":[],"checksum":1829547208,"timestamp":"2024-06-01T18:06:11.673388Z"}]}
{"channel":"book","type":"update","data":[{"symbol":"BCH/AUD","bids":[{"price":693.36,"qty":0.00000000},{"price":691.13,"qty":7.88802300}],"asks":[],"checksum":2794989041,"timestamp":"2024-06-01T18:06:12.056906Z"}]}
{"channel":"book","type":"update","data":[{"symbol":"BCH/AUD","bids":[{"price":693.48,"qty":6.14125453}],"asks":[],"checksum":2901170226,"timestamp":"2024-06-01T18:06:12.057004Z"}]}
{"channel":"book","type":"update","data":[{"symbol":"BCH/AUD","bids":[{"price":693.49,"qty":6.00000000}],"asks":[],"checksum":2201988488,"timestamp":"2024-06-01T18:06:12.144008Z"}]}
{"channel":"book","type":"update","data":[{"symbol":"BCH/AUD","bids":[{"price":693.50,"qty":6.14107739}],"asks":[],"checksum":3984991478,"timestamp":"2024-06-01T18:06:12.151398Z"}]}
{"channel":"book","type":"update","data":[{"symbol":"BCH/AUD","bids":[{"price":693.48,"qty":0.00000000},{"price":691.84,"qty":0.03285025}],"asks":[],"checksum":30484977,"timestamp":"2024-06-01T18:06:12.151471Z"}]}
{"channel":"book","type":"update","data":[{"symbol":"BCH/AUD","bids":[{"price":693.47,"qty":0.00000000},{"price":691.48,"qty":0.26329050}],"asks":[],"checksum":12672759,"timestamp":"2024-06-01T18:06:12.195652Z"}]}
{"channel":"book","type":"update","data":[{"symbol":"BCH/AUD","bids":[{"price":693.51,"qty":6.00000000}],"asks":[],"checksum":4178431720,"timestamp":"2024-06-01T18:06:12.643956Z"}]}
{"channel":"book","type":"update","data":[{"symbol":"BCH/AUD","bids":[{"price":693.49,"qty":0.00000000},{"price":691.48,"qty":0.26329050}],"asks":[],"checksum":1470495642,"timestamp":"2024-06-01T18:06:12.649612Z"}]}
