{"channel":"book","type":"snapshot","data":[{"symbol":"BTC/USDT","bids":[{"price":67757.6,"qty":0.01926586},{"price":67757.1,"qty":0.19849783},{"price":67756.2,"qty":0.05000000},{"price":67750.7,"qty":0.00841365},{"price":67750.5,"qty":0.75566884},{"price":67749.4,"qty":0.04405954},{"price":67748.0,"qty":0.05320580},{"price":67747.9,"qty":0.97196358},{"price":67747.7,"qty":0.11799300},{"price":67743.3,"qty":0.15000000}],"asks":[{"price":67757.7,"qty":0.05000000},{"price":67764.2,"qty":0.07424317},{"price":67765.7,"qty":0.14769111},{"price":67766.1,"qty":0.19869379},{"price":67770.5,"qty":0.04290000},{"price":67770.6,"qty":0.16787482},{"price":67771.0,"qty":0.09000000},{"price":67773.0,"qty":0.04908000},{"price":67774.7,"qty":0.11801200},{"price":67775.5,"qty":0.20066005}],"checksum":123440939}]}
{"channel":"book","type":"update","data":[{"symbol":"BTC/USDT","bids":[],"asks":[{"price":67764.2,"qty":0.03947498},{"price":67764.1,"qty":0.03476740}],"checksum":2109455253,"timestamp":"2024-06-01T18:06:32.360210Z"}]}
{"channel":"book","type":"update","data":[{"symbol":"BTC/USDT","bids":[],"asks":[{"price":67770.6,"qty":0.00000000},{"price":67775.5,"qty":0.20066005}],"checksum":3887138417,"timestamp":"2024-06-01T18:06:32.650418Z"}]}
{"channel":"book","type":"update","data":[{"symbol":"BTC/USDT","bids":[],"asks":[{"price":67774.6,"qty":0.79039917}],"checksum":4140112344,"timestamp":"2024-06-01T18:06:32.652821Z"}]}
{"channel":"book","type":"update","data":[{"symbol":"BTC/USDT","bids":[],"asks":[{"price":67765.6,"qty":0.14482048}],"checksum":3019672846,"timestamp":"2024-06-01T18:06:32.652919Z"}]}
{"channel":"book","type":"update","data":[{"symbol":"BTC/USDT","bids":[{"price":67747.9,"qty":0.00000000},{"price":67741.9,"qty":0.02208989}],"asks":[],"checksum":3980196321,"timestamp":"2024-06-01T18:06:32.675375Z"}]}
{"channel":"book","type":"update","data":[{"symbol":"BTC/USDT","bids":[{"price":67750.5,"qty":0.00000000},{"price":67741.2,"qty":0.09000000}],"asks":[],"checksum":2209468636,"timestamp":"2024-06-01T18:06:32.675394Z"}]}
{"channel":"book","type":"update","data":[{"symbol":"BTC/USDT","bids":[{"price":67741.3,"qty":1.38919942}],"asks":[],"checksum":414639905,"timestamp":"2024-06-01T18:06:32.680512Z"}]}
{"channel":"book","type":"update","data":[{"symbol":"BTC/USDT","bids":[{"price":67743.4,"qty":0.30765101}],"asks":[],"checksum":1158182795,"timestamp":"2024-06-01T18:06:32.680653Z"}]}
{"channel":"book","type":"update","data":[{"symbol":"BTC/USDT","bids":[{"price":67748.0,"qty":0.00000000},{"price":67741.3,"qty":1.38919942},{"price":67747.8,"qty":0.05320625}],"asks":[],"checksum":1416488249,"timestamp":"2024-06-01T18:06:32.719339Z"}]}
{"channel":"book","type":"update","data":[{"symbol":"BTC/USDT","bids":[{"price":67750.7,"qty":0.00000000},{"price":67741.3,"qty":1.38919942}],"asks":[],"checksum":3694342150,"timestamp":"2024-06-01T18:06:32.951685Z"}]}
{"channel":"book","type":"update","data":[{"symbol":"BTC/USDT","bids":[{"price":67741.3,"qty":1.38996320}],"asks":[],"checksum":31664365,"timestamp":"2024-06-01T18:06:32.957848Z"}]}
{"channel":"book","type":"update","data":[{"symbol":"BTC/USDT","bids":[{"price":67741.9,"qty":0.00000000},{"price":67741.2,"qty":0.09000000}],"asks":[],"checksum":2949197012,"timestamp":"2024-06-01T18:06:32.996613Z"}]}
{"channel":"book","type":"update","data":[{"symbol":"BTC/USDT","bids":[{"price":67741.8,"qty":0.02208992}],"asks":[],"checksum":1206723271,"timestamp":"2024-06-01T18:06:33.036792Z"}]}
{"channel":"book","type":"update","data":[{"symbol":"BTC/USDT","bids":[],"asks":[{"price":67764.0,"qty":0.00101400}],"checksum":3954879600,"timestamp":"2024-06-01T18:06:33.057507Z"}]}
{"channel":"book","type":"update","data":[{"symbol":"BTC/USDT","bids":[],"asks":[{"price":67771.3,"qty":0.19976708}],"checksum":3666824469,"timestamp":"2024-06-01T18:06:33.227895Z"}]}
{"channel":"book","type":"update","data":[{"symbol":"BTC/USDT","bids":[{"price":67747.8,"qty":0.00000000},{"price":67741.2,"qty":0.09000000},{"price":67757.2,"qty":0.05319852}],"asks":[],"checksum":2767826836,"timestamp":"2024-06-01T18:06:33.368864Z"}]}
{"channel":"book","type":"update","data":[{"symbol":"BTC/USDT","bids":[{"price":67757.2,"qty":0.00000000},{"price":67741.2,"qty":0.09000000},{"price":67747.8,"qty":0.05320590}],"asks":[],"checksum":1157069590,"timestamp":"2024-06-01T18:06:33.427178Z"}]}
{"channel":"book","type":"update","data":[{"symbol":"BTC/USDT","bids":[{"price":67741.8,"qty":0.00000000},{"price":67741.2,"qty":0.09000000}],"asks":[],"checksum":2899539205,"timestamp":"2024-06-01T18:06:33.604413Z"}]}
{"channel":"book","type":"update","data":[{"symbol":"BTC/USDT","bids":[{"price":67741.6,"qty":0.02209009}],"asks":[],"checksum":3171450271,"timestamp":"2024-06-01T18:06:33.644659Z"}]}
{"channel":"book","type":"update","data":[{"symbol":"BTC/USDT","bids":[{"price":67741.6,"qty":0.00000000},{"price":67741.2,"qty":0.09000000}],"asks":[],"checksum":2899539205,"timestamp":"2024-06-01T18:06:34.294720Z"}]}
{"channel":"book","type":"update","data":[{"symbol":"BTC/USDT","bids":[{"price":67749.4,"qty":0.00000000},{"price":67740.6,"qty":0.04867983}],"asks":[],"checksum":396767568,"timestamp":"2024-06-01T18:06:34.323346Z"}]}
{"channel":"book","type":"update","data":[{"symbol":"BTC/USDT","bids":[{"price":67756.2,"qty":0.00000000},{"price":67740.2,"qty":1.51137082}],"asks":[],"checksum":1466464572,"timestamp":"2024-06-01T18:06:34.323507Z"}]}
{"channel":"book","type":"update","data":[{"symbol":"BTC/USDT","bids":[{"price":67741.1,"qty":0.02209071}],"asks":[],"checksum":3882316927,"timestamp":"2024-06-01T18:06:34.334882Z"}]}
{"channel":"book","type":"update","data":[{"symbol":"BTC/USDT","bids":[],"asks":[{"price":67770.5,"qty":0.00000000},{"price":67772.9,"qty":0.22170000}],"checksum":1858637471,"timestamp":"2024-06-01T18:06:34.364554Z"}]}
{"channel":"book","type":"update","data":[{"symbol":"BTC/USDT","bids":[],"asks":[{"price":67764.2,"qty":0.08237498}],"checksum":3368304712,"timestamp":"2024-06-01T18:06:34.364766Z"}]}
{"channel":"book","type":"update","data":[{"symbol":"BTC/USDT","bids":[],"asks":[{"price":67764.2,"qty":0.03947498}],"checksum":1858637471,"timestamp":"2024-06-01T18:06:34.365578Z"}]}
{"channel":"book","type":"update","data":[{"symbol":"BTC/USDT","bids":[],"asks":[{"price":67764.1,"qty":0.07766740}],"checksum":4153367560,"timestamp":"2024-06-01T18:06:34.365637Z"}]}
{"channel":"book","type":"update","data":[{"symbol":"BTC/USDT","bids":[],"asks":[{"price":67757.7,"qty":0.08947498}],"checksum":3301245624,"timestamp":"2024-06-01T18:06:34.369113Z"}]}
{"channel":"book","type":"update","data":[{"symbol":"BTC/USDT","bids":[{"price":67740.6,"qty":0.00000000},{"price":67740.2,"qty":1.51137082}],"asks":[],"checksum":2274485508,"timestamp":"2024-06-01T18:06:34.374590Z"}]}
{"channel":"book","type":"update","data":[{"symbol":"BTC/USDT","bids":[],"asks":[{"price":67764.1,"qty":0.04290000},{"price":67763.9,"qty":0.03476672}],"checksum":10340865,"timestamp":"2024-06-01T18:06:34.415465Z"}]}
{"channel":"book","type":"update","data":[{"symbol":"BTC/USDT","bids":[],"asks":[{"price":67764.2,"qty":0.00000000},{"price":67772.9,"qty":0.22170000}],"checksum":1194996501,"timestamp":"2024-06-01T18:06:34.419572Z"}]}
{"channel":"book","type":"update","data":[{"symbol":"BTC/USDT","bids":[{"price":67740.2,"qty":0.14774658}],"asks":[],"checksum":2577047864,"timestamp":"2024-06-01T18:06:34.452568Z"}]}
{"channel":"book","type":"update","data":[{"symbol":"BTC/USDT","bids":[],"asks":[{"price":67762.8,"qty":0.05989000}],"checksum":199183951,"timestamp":"2024-06-01T18:06:34.493471Z"}]}
{"channel":"book","type":"update","data":[{"symbol":"BTC/USDT","bids":[{"price":67745.7,"qty":0.05000000}],"asks":[],"checksum":1672168889,"timestamp":"2024-06-01T18:06:34.498364Z"}]}
{"channel":"book","type":"update","data":[{"symbol":"BTC/USDT","bids":[{"price":67747.8,"qty":0.00000000},{"price":67740.2,"qty":0.14774658},{"price":67741.4,"qty":0.05321092}],"asks":[],"checksum":3530785860,"timestamp":"2024-06-01T18:06:34.521998Z"}]}
{"channel":"book","type":"update","data":[{"symbol":"BTC/USDT","bids":[],"asks":[{"price":67764.0,"qty":0.00000000},{"price":67772.9,"qty":0.22170000},{"price":67762.7,"qty":0.00101400}],"checksum":2353614178,"timestamp":"2024-06-01T18:06:34.658773Z"}]}
{"channel":"book","type":"update","data":[{"symbol":"BTC/USDT","bids":[{"price":67741.4,"qty":0.00000000},{"price":67740.2,"qty":0.14774658}],"asks":[],"checksum":1249879997,"timestamp":"2024-06-01T18:06:35.001727Z"}]}
{"channel":"book","type":"update","data":[{"symbol":"BTC/USDT","bids":[{"price":67741.1,"qty":0.00000000},{"price":67738.8,"qty":0.04405954}],"asks":[],"checksum":1931327391,"timestamp":"2024-06-01T18:06:35.020002Z"}]}
{"channel":"book","type":"update","data":[{"symbol":"BTC/USDT","bids":[{"price":67747.8,"qty":0.05320590}],"asks":[],"checksum":3915684821,"timestamp":"2024-06-01T18:06:35.262844Z"}]}
{"channel":"book","type":"update","data":[{"symbol":"BTC/USDT","bids":[],"asks":[{"price":67763.9,"qty":0.00000000},{"price":67772.9,"qty":0.22170000},{"price":67757.7,"qty":0.12424170}],"checksum":2916371969,"timestamp":"2024-06-01T18:06:35.263089Z"}]}
{"channel":"book","type":"update","data":[{"symbol":"BTC/USDT","bids":[],"asks":[{"price":67765.6,"qty":0.00000000},{"price":67773.0,"qty":0.04908000}],"checksum":2405059972,"timestamp":"2024-06-01T18:06:35.470596Z"}]}
{"channel":"book","type":"update","data":[{"symbol":"BTC/USDT","bids":[],"asks":[{"price":67762.7,"qty":0.07666741}],"checksum":2622056710,"timestamp":"2024-06-01T18:06:35.474188Z"}]}
{"channel":"book","type":"update","data":[{"symbol":"BTC/USDT","bids":[],"asks":[{"price":67765.6,"qty":0.42149914}],"checksum":2586638053,"timestamp":"2024-06-01T18:06:35.474238Z"}]}
{"channel":"book","type":"update","data":[{"symbol":"BTC/USDT","bids":[],"asks":[{"price":67770.9,"qty":2.74851127}],"checksum":3070142642,"timestamp":"2024-06-01T18:06:35.474489Z"}]}
{"channel":"book","type":"update","data":[{"symbol":"BTC/USDT","bids":[],"asks":[{"price":67770.9,"qty":2.75597683}],"checksum":268441162,"timestamp":"2024-06-01T18:06:35.571097Z"}]}
{"channel":"book","type":"update","data":[{"symbol":"BTC/USDT","bids":[],"asks":[{"price":67757.7,"qty":0.08947498},{"price":67762.6,"qty":0.03476579}],"checksum":1888020438,"timestamp":"2024-06-01T18:06:35.782994Z"}]}
{"channel":"book","type":"update","data":[{"symbol":"BTC/USDT","bids":[{"price":67741.3,"qty":0.00076378}],"asks":[],"checksum":2827151473,"timestamp":"2024-06-01T18:06:36.177267Z"}]}
{"channel":"book","type":"update","data":[{"symbol":"BTC/USDT","bids":[{"price":67743.4,"qty":0.00000000},{"price":67738.8,"qty":0.04405954}],"asks":[],"checksum":1109292078,"timestamp":"2024-06-01T18:06:36.177321Z"}]}
{"channel":"book","type":"update","data":[{"symbol":"BTC/USDT","bids":[],"asks":[{"price":67762.6,"qty":0.00000000},{"price":67771.3,"qty":0.19976708},{"price":67757.7,"qty":0.12424077}],"checksum":2049508114,"timestamp":"2024-06-01T18:06:36.181740Z"}]}
{"channel":"book","type":"update","data":[{"symbol":"BTC/USDT","bids":[],"asks":[{"price":67757.7,"qty":0.08947498},{"price":67762.6,"qty":0.03476578}],"checksum":1242429448,"timestamp":"2024-06-01T18:06:36.577973Z"}]}
{"channel":"book","type":"update","data":[{"symbol":"BTC/USDT","bids":[{"price":67747.8,"qty":0.00000000},{"price":67735.5,"qty":1.46054360},{"price":67741.3,"qty":0.05397462}],"asks":[],"checksum":1119558617,"timestamp":"2024-06-01T18:06:36.656847Z"}]}
{"channel":"book","type":"update","data":[{"symbol":"BTC/USDT","bids":[],"asks":[{"price":67762.7,"qty":0.07565341},{"price":67762.5,"qty":0.00101400}],"checksum":2992738175,"timestamp":"2024-06-01T18:06:36.900749Z"}]}
{"channel":"book","type":"update","data":[{"symbol":"BTC/USDT","bids":[{"price":67741.3,"qty":0.00076378},{"price":67747.8,"qty":0.05320573}],"asks":[],"checksum":588290785,"timestamp":"2024-06-01T18:06:37.086521Z"}]}
{"channel":"book","type":"update","data":[{"symbol":"BTC/USDT","bids":[{"price":67747.8,"qty":0.00000000},{"price":67735.5,"qty":1.46054360},{"price":67741.3,"qty":0.05397460}],"asks":[],"checksum":2303437009,"timestamp":"2024-06-01T18:06:37.606847Z"}]}
{"channel":"book","type":"update","data":[{"symbol":"BTC/USDT","bids":[],"asks":[{"price":67770.9,"qty":2.74851127}],"checksum":1277200130,"timestamp":"2024-06-01T18:06:37.942673Z"}]}
{"channel":"book","type":"update","data":[{"symbol":"BTC/USDT","bids":[],"asks":[{"price":67770.8,"qty":0.00219088}],"checksum":2541554498,"timestamp":"2024-06-01T18:06:37.947371Z"}]}
{"channel":"book","type":"update","data":[{"symbol":"BTC/USDT","bids":[],"asks":[{"price":67765.5,"qty":0.00029541}],"checksum":1435534326,"timestamp":"2024-06-01T18:06:37.947587Z"}]}
{"channel":"book","type":"update","data":[{"symbol":"BTC/USDT","bids":[{"price":67741.3,"qty":0.00076378},{"price":67747.8,"qty":0.05320571}],"asks":[],"checksum":2543017731,"timestamp":"2024-06-01T18:06:38.084828Z"}]}
{"channel":"book","type":"update","data":[{"symbol":"BTC/USDT","bids":[{"price":67747.8,"qty":0.00000000},{"price":67735.5,"qty":1.46054360},{"price":67741.3,"qty":0.05397460}],"asks":[],"checksum":1435534326,"timestamp":"2024-06-01T18:06:38.194855Z"}]}
{"channel":"book","type":"update","data":[{"symbol":"BTC/USDT","bids":[],"asks":[{"price":67762.7,"qty":0.00000000},{"price":67770.8,"qty":0.00219088}],"checksum":1405673556,"timestamp":"2024-06-01T18:06:38.233604Z"}]}
{"channel":"book","type":"update","data":[{"symbol":"BTC/USDT","bids":[],"asks":[{"price":67765.6,"qty":0.00000000},{"price":67770.9,"qty":2.74851127}],"checksum":1239217573,"timestamp":"2024-06-01T18:06:38.233664Z"}]}
{"channel":"book","type":"update","data":[{"symbol":"BTC/USDT","bids":[],"asks":[{"price":67770.9,"qty":0.00000000},{"price":67771.0,"qty":0.09000000}],"checksum":1276646450,"timestamp":"2024-06-01T18:06:38.233698Z"}]}
{"channel":"book","type":"update","data":[{"symbol":"BTC/USDT","bids":[],"asks":[{"price":67762.5,"qty":0.05361102}],"checksum":1594834604,"timestamp":"2024-06-01T18:06:38.236017Z"}]}
{"channel":"book","type":"update","data":[{"symbol":"BTC/USDT","bids":[],"asks":[{"price":67765.6,"qty":0.44455550}],"checksum":1518548466,"timestamp":"2024-06-01T18:06:38.236069Z"}]}
{"channel":"book","type":"update","data":[{"symbol":"BTC/USDT","bids":[],"asks":[{"price":67770.8,"qty":2.88784148}],"checksum":3398018513,"timestamp":"2024-06-01T18:06:38.236088Z"}]}
{"channel":"book","type":"update","data":[{"symbol":"BTC/USDT","bids":[{"price":67741.3,"qty":0.05321082}],"asks":[],"checksum":1603477632,"timestamp":"2024-06-01T18:06:38.379844Z"}]}
{"channel":"book","type":"update","data":[{"symbol":"BTC/USDT","bids":[{"price":67735.6,"qty":0.01497282}],"asks":[],"checksum":2335581319,"timestamp":"2024-06-01T18:06:38.385799Z"}]}
{"channel":"book","type":"update","data":[{"symbol":"BTC/USDT","bids":[],"asks":[{"price":67762.5,"qty":0.05259702}],"checksum":3281253562,"timestamp":"2024-06-01T18:06:38.767665Z"}]}
{"channel":"book","type":"update","data":[{"symbol":"BTC/USDT","bids":[{"price":67741.3,"qty":0.00000000},{"price":67735.5,"qty":1.46054360},{"price":67740.3,"qty":0.05321160}],"asks":[],"checksum":219248473,"timestamp":"2024-06-01T18:06:39.053286Z"}]}
{"channel":"book","type":"update","data":[{"symbol":"BTC/USDT","bids":[{"price":67741.3,"qty":0.04499243}],"asks":[],"checksum":2684144517,"timestamp":"2024-06-01T18:06:39.814153Z"}]}
{"channel":"book","type":"update","data":[{"symbol":"BTC/USDT","bids":[],"asks":[{"price":67762.6,"qty":0.00000000},{"price":67771.0,"qty":0.09000000},{"price":67757.7,"qty":0.12424162}],"checksum":3475582061,"timestamp":"2024-06-01T18:06:40.036286Z"}]}
{"channel":"book","type":"update","data":[{"symbol":"BTC/USDT","bids":[],"asks":[{"price":67770.8,"qty":2.88565060}],"checksum":3087582650,"timestamp":"2024-06-01T18:06:40.355957Z"}]}
{"channel":"book","type":"update","data":[{"symbol":"BTC/USDT","bids":[],"asks":[{"price":67765.5,"qty":0.00000000},{"price":67771.3,"qty":0.19976708}],"checksum":794675167,"timestamp":"2024-06-01T18:06:40.356176Z"}]}
{"channel":"book","type":"update","data":[{"symbol":"BTC/USDT","bids":[],"asks":[{"price":67770.7,"qty":0.00039776}],"checksum":1671431081,"timestamp":"2024-06-01T18:06:40.360757Z"}]}
{"channel":"book","type":"update","data":[{"symbol":"BTC/USDT","bids":[],"asks":[{"price":67765.5,"qty":0.00089292}],"checksum":2416579968,"timestamp":"2024-06-01T18:06:40.360831Z"}]}
{"channel":"book","type":"update","data":[{"symbol":"BTC/USDT","bids":[],"asks":[{"price":67757.7,"qty":0.08947498},{"price":67762.4,"qty":0.03476664}],"checksum":1319624912,"timestamp":"2024-06-01T18:06:40.477778Z"}]}
{"channel":"book","type":"update","data":[{"symbol":"BTC/USDT","bids":[{"price":67740.3,"qty":0.00000000},{"price":67735.8,"qty":0.01060082},{"price":67747.8,"qty":0.05320560}],"asks":[],"checksum":1125415300,"timestamp":"2024-06-01T18:06:40.977056Z"}]}
{"channel":"book","type":"update","data":[{"symbol":"BTC/USDT","bids":[],"asks":[{"price":67762.5,"qty":0.00000000},{"price":67771.0,"qty":0.09000000}],"checksum":2755452377,"timestamp":"2024-06-01T18:06:41.057397Z"}]}
{"channel":"book","type":"update","data":[{"symbol":"BTC/USDT","bids":[],"asks":[{"price":67770.9,"qty":2.86269555}],"checksum":3362345175,"timestamp":"2024-06-01T18:06:41.059680Z"}]}
{"channel":"book","type":"update","data":[{"symbol":"BTC/USDT","bids":[],"asks":[{"price":67762.3,"qty":0.05259702}],"checksum":2368778829,"timestamp":"2024-06-01T18:06:41.059773Z"}]}
{"channel":"book","type":"update","data":[{"symbol":"BTC/USDT","bids":[{"price":67747.8,"qty":0.00000000},{"price":67735.8,"qty":0.01060082},{"price":67740.3,"qty":0.05321148}],"asks":[],"checksum":1260614073,"timestamp":"2024-06-01T18:06:41.173601Z"}]}
{"channel":"book","type":"update","data":[{"symbol":"BTC/USDT","bids":[{"price":67750.8,"qty":0.09000000}],"asks":[],"checksum":66786530,"timestamp":"2024-06-01T18:06:41.708122Z"}]}
{"channel":"book","type":"update","data":[{"symbol":"BTC/USDT","bids":[],"asks":[{"price":67767.4,"qty":0.11787900}],"checksum":801081815,"timestamp":"2024-06-01T18:06:41.798416Z"}]}
{"channel":"book","type":"update","data":[{"symbol":"BTC/USDT","bids":[{"price":67740.3,"qty":0.00000000},{"price":67738.8,"qty":0.04405954},{"price":67750.9,"qty":0.05320324}],"asks":[],"checksum":2969439126,"timestamp":"2024-06-01T18:06:41.907289Z"}]}
{"channel":"book","type":"update","data":[{"symbol":"BTC/USDT","bids":[],"asks":[{"price":67762.4,"qty":0.00000000},{"price":67770.7,"qty":0.00039776},{"price":67757.7,"qty":0.12424166}],"checksum":2853578392,"timestamp":"2024-06-01T18:06:41.907328Z"}]}
{"channel":"book","type":"update","data":[{"symbol":"BTC/USDT","bids":[{"price":67750.8,"qty":0.00000000},{"price":67738.8,"qty":0.04405954}],"asks":[],"checksum":1426386683,"timestamp":"2024-06-01T18:06:42.113970Z"}]}
{"channel":"book","type":"update","data":[{"symbol":"BTC/USDT","bids":[{"price":67750.9,"qty":0.00000000},{"price":67735.9,"qty":0.02209469},{"price":67747.8,"qty":0.05320567}],"asks":[],"checksum":1405288563,"timestamp":"2024-06-01T18:06:42.164508Z"}]}
{"channel":"book","type":"update","data":[{"symbol":"BTC/USDT","bids":[],"asks":[{"price":67770.7,"qty":0.00000000},{"price":67770.9,"qty":2.86269555}],"checksum":1569987780,"timestamp":"2024-06-01T18:06:42.776246Z"}]}
{"channel":"book","type":"update","data":[{"symbol":"BTC/USDT","bids":[],"asks":[{"price":67765.5,"qty":0.00000000},{"price":67771.0,"qty":0.09000000}],"checksum":919204941,"timestamp":"2024-06-01T18:06:42.776405Z"}]}
{"channel":"book","type":"update","data":[{"symbol":"BTC/USDT","bids":[],"asks":[{"price":67765.5,"qty":0.00129126}],"checksum":1527571233,"timestamp":"2024-06-01T18:06:42.778703Z"}]}
{"channel":"book","type":"update","data":[{"symbol":"BTC/USDT","bids":[{"price":67741.3,"qty":0.00000000},{"price":67735.8,"qty":0.01060082}],"asks":[],"checksum":1569133690,"timestamp":"2024-06-01T18:06:43.410161Z"}]}
{"channel":"book","type":"update","data":[{"symbol":"BTC/USDT","bids":[],"asks":[{"price":67770.9,"qty":0.00000000},{"price":67771.0,"qty":0.09000000}],"checksum":1846347997,"timestamp":"2024-06-01T18:06:43.819893Z"}]}
{"channel":"book","type":"update","data":[{"symbol":"BTC/USDT","bids":[],"asks":[{"price":67765.6,"qty":0.00000000},{"price":67771.3,"qty":0.19976708}],"checksum":1715825693,"timestamp":"2024-06-01T18:06:43.819970Z"}]}
{"channel":"book","type":"update","data":[{"symbol":"BTC/USDT","bids":[],"asks":[{"price":67762.3,"qty":0.00000000},{"price":67772.9,"qty":0.22170000}],"checksum":2379755290,"timestamp":"2024-06-01T18:06:43.820035Z"}]}
{"channel":"book","type":"update","data":[{"symbol":"BTC/USDT","bids":[],"asks":[{"price":67765.6,"qty":0.88262677}],"checksum":3758158068,"timestamp":"2024-06-01T18:06:43.824398Z"}]}
{"channel":"book","type":"update","data":[{"symbol":"BTC/USDT","bids":[],"asks":[{"price":67770.9,"qty":0.90568315}],"checksum":4191870335,"timestamp":"2024-06-01T18:06:43.824686Z"}]}
{"channel":"book","type":"update","data":[{"symbol":"BTC/USDT","bids":[{"price":67735.8,"qty":0.00000000},{"price":67735.7,"qty":1.35498252}],"asks":[],"checksum":2736248279,"timestamp":"2024-06-01T18:06:43.904315Z"}]}
{"channel":"book","type":"update","data":[{"symbol":"BTC/USDT","bids":[],"asks":[{"price":67757.7,"qty":0.08947498},{"price":67762.7,"qty":0.03476674}],"checksum":564625883,"timestamp":"2024-06-01T18:06:44.261059Z"}]}
{"channel":"book","type":"update","data":[{"symbol":"BTC/USDT","bids":[],"asks":[{"price":67762.7,"qty":0.00000000},{"price":67771.0,"qty":0.09000000},{"price":67757.7,"qty":0.12424172}],"checksum":2334884201,"timestamp":"2024-06-01T18:06:45.124674Z"}]}
{"channel":"book","type":"update","data":[{"symbol":"BTC/USDT","bids":[],"asks":[{"price":67765.5,"qty":0.00000000},{"price":67771.3,"qty":0.19976708}],"checksum":1698844431,"timestamp":"2024-06-01T18:06:45.195276Z"}]}
{"channel":"book","type":"update","data":[{"symbol":"BTC/USDT","bids":[],"asks":[{"price":67765.5,"qty":0.00212529}],"checksum":3551126088,"timestamp":"2024-06-01T18:06:45.197684Z"}]}
{"channel":"book","type":"update","data":[{"symbol":"BTC/USDT","bids":[],"asks":[{"price":67765.5,"qty":0.00313929}],"checksum":2638280840,"timestamp":"2024-06-01T18:06:46.217849Z"}]}
{"channel":"book","type":"update","data":[{"symbol":"BTC/USDT","bids":[{"price":67747.7,"qty":0.00000000},{"price":67735.6,"qty":0.01466053}],"asks":[],"checksum":2470008584,"timestamp":"2024-06-01T18:06:46.293547Z"}]}
{"channel":"book","type":"update","data":[{"symbol":"BTC/USDT","bids":[{"price":67742.2,"qty":0.11788200}],"asks":[],"checksum":356901033,"timestamp":"2024-06-01T18:06:46.295771Z"}]}
{"channel":"book","type":"update","data":[{"symbol":"BTC/USDT","bids":[{"price":67747.8,"qty":0.00000000},{"price":67735.6,"qty":0.01466053},{"price":67745.8,"qty":0.05320697}],"asks":[],"checksum":2556684347,"timestamp":"2024-06-01T18:06:46.356819Z"}]}
{"channel":"book","type":"update","data":[{"symbol":"BTC/USDT","bids":[{"price":67757.6,"qty":0.01783586}],"asks":[],"checksum":3411771592,"timestamp":"2024-06-01T18:06:46.554082Z"}]}
{"channel":"book","type":"update","data":[{"symbol":"BTC/USDT","bids":[{"price":67750.8,"qty":0.09000000}],"asks":[],"checksum":3196455847,"timestamp":"2024-06-01T18:06:46.560387Z"}]}
{"channel":"book","type":"update","data":[{"symbol":"BTC/USDT","bids":[{"price":67750.8,"qty":0.00000000},{"price":67735.7,"qty":1.35498252}],"asks":[],"checksum":3411771592,"timestamp":"2024-06-01T18:06:46.563658Z"}]}
{"channel":"book","type":"update","data":[{"symbol":"BTC/USDT","bids":[],"asks":[{"price":67765.5,"qty":0.00212529}],"checksum":2243074568,"timestamp":"2024-06-01T18:06:46.587475Z"}]}
{"channel":"book","type":"update","data":[{"symbol":"BTC/USDT","bids":[],"asks":[{"price":67765.6,"qty":0.00000000},{"price":67771.3,"qty":0.19976708}],"checksum":2780804519,"timestamp":"2024-06-01T18:06:46.666508Z"}]}
{"channel":"book","type":"update","data":[{"symbol":"BTC/USDT","bids":[],"asks":[{"price":67770.9,"qty":0.00000000},{"price":67772.9,"qty":0.22170000}],"checksum":3465274072,"timestamp":"2024-06-01T18:06:46.666709Z"}]}
{"channel":"book","type":"update","data":[{"symbol":"BTC/USDT","bids":[],"asks":[{"price":67765.6,"qty":0.90568315}],"checksum":320428594,"timestamp":"2024-06-01T18:06:46.669067Z"}]}
{"channel":"book","type":"update","data":[{"symbol":"BTC/USDT","bids":[{"price":67735.8,"qty":0.01512896}],"asks":[],"checksum":218252122,"timestamp":"2024-06-01T18:06:46.714576Z"}]}
{"channel":"book","type":"update","data":[{"symbol":"BTC/USDT","bids":[{"price":67743.4,"qty":0.15315490}],"asks":[],"checksum":613862831,"timestamp":"2024-06-01T18:06:47.048311Z"}]}
{"channel":"book","type":"update","data":[{"symbol":"BTC/USDT","bids":[],"asks":[{"price":67757.7,"qty":0.08947498},{"price":67762.7,"qty":0.03476670}],"checksum":1072103290,"timestamp":"2024-06-01T18:06:49.289617Z"}]}
{"channel":"book","type":"update","data":[{"symbol":"BTC/USDT","bids":[{"price":67743.5,"qty":0.00060769}],"asks":[],"checksum":4206977492,"timestamp":"2024-06-01T18:06:49.507820Z"}]}
{"channel":"book","type":"update","data":[{"symbol":"BTC/USDT","bids":[],"asks":[{"price":67765.6,"qty":0.00000000},{"price":67771.3,"qty":0.19976708}],"checksum":2119106648,"timestamp":"2024-06-01T18:06:49.563952Z"}]}
{"channel":"book","type":"update","data":[{"symbol":"BTC/USDT","bids":[],"asks":[{"price":67762.7,"qty":0.06430742}],"checksum":3853871939,"timestamp":"2024-06-01T18:06:49.568446Z"}]}
{"channel":"book","type":"update","data":[{"symbol":"BTC/USDT","bids":[],"asks":[{"price":67765.6,"qty":0.92873960}],"checksum":2036957355,"timestamp":"2024-06-01T18:06:49.568464Z"}]}
{"channel":"book","type":"update","data":[{"symbol":"BTC/USDT","bids":[{"price":67757.6,"qty":0.01350000}],"asks":[],"checksum":1025299016,"timestamp":"2024-06-01T18:06:49.837011Z"}]}
{"channel":"book","type":"update","data":[{"symbol":"BTC/USDT","bids":[],"asks":[{"price":67762.7,"qty":0.02954072},{"price":67757.7,"qty":0.12424167}],"checksum":3418462107,"timestamp":"2024-06-01T18:06:49.871660Z"}]}
{"channel":"book","type":"update","data":[{"symbol":"BTC/USDT","bids":[],"asks":[{"price":67757.7,"qty":0.08947498},{"price":67762.6,"qty":0.03476669}],"checksum":3768163580,"timestamp":"2024-06-01T18:06:49.944034Z"}]}
{"channel":"book","type":"update","data":[{"symbol":"BTC/USDT","bids":[],"asks":[{"price":67765.5,"qty":0.00000000},{"price":67771.0,"qty":0.09000000}],"checksum":2359607456,"timestamp":"2024-06-01T18:06:50.031319Z"}]}
{"channel":"book","type":"update","data":[{"symbol":"BTC/USDT","bids":[],"asks":[{"price":67765.5,"qty":0.00272280}],"checksum":1816907063,"timestamp":"2024-06-01T18:06:50.035884Z"}]}
{"channel":"book","type":"update","data":[{"symbol":"BTC/USDT","bids":[{"price":67757.6,"qty":0.04424411}],"asks":[],"checksum":1298500053,"timestamp":"2024-06-01T18:06:50.086439Z"}]}
{"channel":"book","type":"update","data":[{"symbol":"BTC/USDT","bids":[{"price":67743.4,"qty":0.00000000},{"price":67738.8,"qty":0.04405954}],"asks":[],"checksum":2340252547,"timestamp":"2024-06-01T18:06:50.652284Z"}]}
{"channel":"book","type":"update","data":[{"symbol":"BTC/USDT","bids":[{"price":67743.4,"qty":0.13770312}],"asks":[],"checksum":1991529321,"timestamp":"2024-06-01T18:06:50.656510Z"}]}
{"channel":"book","type":"update","data":[{"symbol":"BTC/USDT","bids":[],"asks":[{"price":67762.6,"qty":0.00000000},{"price":67771.0,"qty":0.09000000},{"price":67757.7,"qty":0.12424167}],"checksum":667200588,"timestamp":"2024-06-01T18:06:51.021200Z"}]}
{"channel":"book","type":"update","data":[{"symbol":"BTC/USDT","bids":[],"asks":[{"price":67757.7,"qty":0.08947498},{"price":67762.6,"qty":0.03476669}],"checksum":1991529321,"timestamp":"2024-06-01T18:06:51.079987Z"}]}
{"channel":"book","type":"update","data":[{"symbol":"BTC/USDT","bids":[],"asks":[{"price":67762.6,"qty":0.00000000},{"price":67771.0,"qty":0.09000000},{"price":67757.7,"qty":0.12424191}],"checksum":3628081498,"timestamp":"2024-06-01T18:06:51.633749Z"}]}
{"channel":"book","type":"update","data":[{"symbol":"BTC/USDT","bids":[],"asks":[{"price":67765.6,"qty":0.00000000},{"price":67771.3,"qty":0.19976708}],"checksum":1151126194,"timestamp":"2024-06-01T18:06:52.242171Z"}]}
{"channel":"book","type":"update","data":[{"symbol":"BTC/USDT","bids":[],"asks":[{"price":67765.6,"qty":0.97485229}],"checksum":3754072120,"timestamp":"2024-06-01T18:06:52.244942Z"}]}
{"channel":"book","type":"update","data":[{"symbol":"BTC/USDT","bids":[],"asks":[{"price":67765.5,"qty":0.00000000},{"price":67771.3,"qty":0.19976708}],"checksum":3117095321,"timestamp":"2024-06-01T18:06:52.382339Z"}]}
{"channel":"book","type":"update","data":[{"symbol":"BTC/USDT","bids":[],"asks":[{"price":67765.5,"qty":0.00304646}],"checksum":3490239401,"timestamp":"2024-06-01T18:06:52.384213Z"}]}
{"channel":"book","type":"update","data":[{"symbol":"BTC/USDT","bids":[{"price":67745.8,"qty":0.00000000},{"price":67738.8,"qty":0.04405954},{"price":67741.3,"qty":0.05321068}],"asks":[],"checksum":1998002257,"timestamp":"2024-06-01T18:06:52.594448Z"}]}
{"channel":"book","type":"update","data":[{"symbol":"BTC/USDT","bids":[],"asks":[{"price":67757.7,"qty":0.08947498},{"price":67762.6,"qty":0.03476718}],"checksum":1201282350,"timestamp":"2024-06-01T18:06:52.985088Z"}]}
{"channel":"book","type":"update","data":[{"symbol":"BTC/USDT","bids":[{"price":67741.3,"qty":0.00000000},{"price":67738.8,"qty":0.04405954},{"price":67745.8,"qty":0.05320715}],"asks":[],"checksum":1912969026,"timestamp":"2024-06-01T18:06:53.151617Z"}]}
{"channel":"book","type":"update","data":[{"symbol":"BTC/USDT","bids":[],"asks":[{"price":67762.6,"qty":0.00000000},{"price":67771.0,"qty":0.09000000},{"price":67757.7,"qty":0.12424169}],"checksum":1566344414,"timestamp":"2024-06-01T18:06:53.773136Z"}]}
{"channel":"book","type":"update","data":[{"symbol":"BTC/USDT","bids":[],"asks":[{"price":67757.7,"qty":0.08947498},{"price":67762.6,"qty":0.03476671}],"checksum":2914153536,"timestamp":"2024-06-01T18:06:53.840780Z"}]}
{"channel":"book","type":"update","data":[{"symbol":"BTC/USDT","bids":[{"price":67757.6,"qty":0.03074411}],"asks":[],"checksum":1165357467,"timestamp":"2024-06-01T18:06:53.872591Z"}]}
{"channel":"book","type":"update","data":[{"symbol":"BTC/USDT","bids":[{"price":67743.4,"qty":0.00000000},{"price":67738.8,"qty":0.04405954}],"asks":[],"checksum":1237482734,"timestamp":"2024-06-01T18:06:54.105274Z"}]}
{"channel":"book","type":"update","data":[{"symbol":"BTC/USDT","bids":[{"price":67743.4,"qty":0.16860668}],"asks":[],"checksum":1487283541,"timestamp":"2024-06-01T18:06:54.110980Z"}]}
{"channel":"book","type":"update","data":[{"symbol":"BTC/USDT","bids":[{"price":67745.8,"qty":0.00000000},{"price":67738.8,"qty":0.04405954},{"price":67741.3,"qty":0.05321052}],"asks":[],"checksum":661663796,"timestamp":"2024-06-01T18:06:54.323672Z"}]}
{"channel":"book","type":"update","data":[{"symbol":"BTC/USDT","bids":[{"price":67741.3,"qty":0.00000000},{"price":67738.8,"qty":0.04405954},{"price":67745.8,"qty":0.05320698}],"asks":[],"checksum":3133237460,"timestamp":"2024-06-01T18:06:54.405511Z"}]}
{"channel":"book","type":"update","data":[{"symbol":"BTC/USDT","bids":[],"asks":[{"price":67765.5,"qty":0.00000000},{"price":67771.0,"qty":0.09000000}],"checksum":2259897821,"timestamp":"2024-06-01T18:06:54.750670Z"}]}
{"channel":"book","type":"update","data":[{"symbol":"BTC/USDT","bids":[],"asks":[{"price":67765.5,"qty":0.00275196}],"checksum":2705057658,"timestamp":"2024-06-01T18:06:54.753277Z"}]}
{"channel":"book","type":"update","data":[{"symbol":"BTC/USDT","bids":[],"asks":[{"price":67762.8,"qty":0.06039000}],"checksum":3586385809,"timestamp":"2024-06-01T18:06:54.944900Z"}]}
{"channel":"book","type":"update","data":[{"symbol":"BTC/USDT","bids":[],"asks":[{"price":67762.6,"qty":0.00000000},{"price":67771.0,"qty":0.09000000},{"price":67757.7,"qty":0.12424169}],"checksum":2153688159,"timestamp":"2024-06-01T18:06:55.003271Z"}]}
{"channel":"book","type":"update","data":[{"symbol":"BTC/USDT","bids":[],"asks":[{"price":67765.6,"qty":0.00000000},{"price":67771.3,"qty":0.19976708}],"checksum":453050069,"timestamp":"2024-06-01T18:06:55.105264Z"}]}
{"channel":"book","type":"update","data":[{"symbol":"BTC/USDT","bids":[],"asks":[{"price":67762.7,"qty":0.00000000},{"price":67772.7,"qty":0.22170000}],"checksum":1960866591,"timestamp":"2024-06-01T18:06:55.105340Z"}]}
{"channel":"book","type":"update","data":[{"symbol":"BTC/USDT","bids":[],"asks":[{"price":67762.5,"qty":0.14482267}],"checksum":3066199172,"timestamp":"2024-06-01T18:06:55.108531Z"}]}
{"channel":"book","type":"update","data":[{"symbol":"BTC/USDT","bids":[],"asks":[{"price":67765.6,"qty":1.02096517}],"checksum":3931804400,"timestamp":"2024-06-01T18:06:55.108911Z"}]}
{"channel":"book","type":"update","data":[{"symbol":"BTC/USDT","bids":[{"price":67742.2,"qty":0.00000000},{"price":67738.8,"qty":0.04405954}],"asks":[],"checksum":3059547901,"timestamp":"2024-06-01T18:06:55.752007Z"}]}
{"channel":"book","type":"update","data":[{"symbol":"BTC/USDT","bids":[{"price":67741.4,"qty":0.11788400}],"asks":[],"checksum":4038660188,"timestamp":"2024-06-01T18:06:55.754094Z"}]}
{"channel":"book","type":"update","data":[{"symbol":"BTC/USDT","bids":[],"asks":[{"price":67765.5,"qty":0.00000000},{"price":67771.3,"qty":0.19976708}],"checksum":452749547,"timestamp":"2024-06-01T18:06:57.198863Z"}]}
{"channel":"book","type":"update","data":[{"symbol":"BTC/USDT","bids":[],"asks":[{"price":67765.5,"qty":0.00410456}],"checksum":3785034342,"timestamp":"2024-06-01T18:06:57.201353Z"}]}
{"channel":"book","type":"update","data":[{"symbol":"BTC/USDT","bids":[{"price":67743.4,"qty":0.00000000},{"price":67738.8,"qty":0.04405954}],"asks":[],"checksum":2691065197,"timestamp":"2024-06-01T18:06:57.579969Z"}]}
{"channel":"book","type":"update","data":[{"symbol":"BTC/USDT","bids":[{"price":67743.5,"qty":0.00000000},{"price":67735.5,"qty":1.01849214}],"asks":[],"checksum":2262759160,"timestamp":"2024-06-01T18:06:57.776309Z"}]}
{"channel":"book","type":"update","data":[{"symbol":"BTC/USDT","bids":[{"price":67735.8,"qty":0.03045158}],"asks":[],"checksum":1344180088,"timestamp":"2024-06-01T18:06:57.783618Z"}]}
{"channel":"book","type":"update","data":[{"symbol":"BTC/USDT","bids":[],"asks":[{"price":67762.5,"qty":0.00000000},{"price":67771.3,"qty":0.19976708}],"checksum":774216300,"timestamp":"2024-06-01T18:06:57.897041Z"}]}
{"channel":"book","type":"update","data":[{"symbol":"BTC/USDT","bids":[],"asks":[{"price":67765.6,"qty":0.00000000},{"price":67772.7,"qty":0.22170000}],"checksum":3403886951,"timestamp":"2024-06-01T18:06:57.897171Z"}]}
{"channel":"book","type":"update","data":[{"symbol":"BTC/USDT","bids":[],"asks":[{"price":67762.7,"qty":0.16789228}],"checksum":2679115543,"timestamp":"2024-06-01T18:06:57.901261Z"}]}
{"channel":"book","type":"update","data":[{"symbol":"BTC/USDT","bids":[],"asks":[{"price":67765.6,"qty":1.20552135}],"checksum":4169321015,"timestamp":"2024-06-01T18:06:57.901300Z"}]}
{"channel":"book","type":"update","data":[{"symbol":"BTC/USDT","bids":[],"asks":[{"price":67762.6,"qty":0.00101400}],"checksum":3894392317,"timestamp":"2024-06-01T18:06:59.146094Z"}]}
{"channel":"book","type":"update","data":[{"symbol":"BTC/USDT","bids":[],"asks":[{"price":67765.5,"qty":0.00000000},{"price":67771.0,"qty":0.09000000}],"checksum":537821535,"timestamp":"2024-06-01T18:06:59.518112Z"}]}
{"channel":"book","type":"update","data":[{"symbol":"BTC/USDT","bids":[],"asks":[{"price":67765.5,"qty":0.00463361}],"checksum":4176638970,"timestamp":"2024-06-01T18:06:59.520671Z"}]}
{"channel":"book","type":"update","data":[{"symbol":"BTC/USDT","bids":[],"asks":[{"price":67757.7,"qty":0.08947498},{"price":67762.5,"qty":0.03485581}],"checksum":3192771447,"timestamp":"2024-06-01T18:07:00.158257Z"}]}
{"channel":"book","type":"update","data":[{"symbol":"BTC/USDT","bids":[],"asks":[{"price":67762.6,"qty":0.00000000},{"price":67767.4,"qty":0.11787900},{"price":67762.4,"qty":0.00101400}],"checksum":3195270123,"timestamp":"2024-06-01T18:07:00.274709Z"}]}
{"channel":"book","type":"update","data":[{"symbol":"BTC/USDT","bids":[],"asks":[{"price":67762.5,"qty":0.00000000},{"price":67767.4,"qty":0.11787900},{"price":67757.7,"qty":0.12433079}],"checksum":3140431397,"timestamp":"2024-06-01T18:07:00.447414Z"}]}
{"channel":"book","type":"update","data":[{"symbol":"BTC/USDT","bids":[],"asks":[{"price":67767.4,"qty":0.00000000},{"price":67771.0,"qty":0.09000000}],"checksum":3122906012,"timestamp":"2024-06-01T18:07:00.481194Z"}]}
{"channel":"book","type":"update","data":[{"symbol":"BTC/USDT","bids":[],"asks":[{"price":67766.5,"qty":0.11788500}],"checksum":2028286974,"timestamp":"2024-06-01T18:07:00.483288Z"}]}
{"channel":"book","type":"update","data":[{"symbol":"BTC/USDT","bids":[{"price":67735.8,"qty":0.00000000},{"price":67735.5,"qty":1.01849214}],"asks":[],"checksum":701505129,"timestamp":"2024-06-01T18:07:00.672452Z"}]}
{"channel":"book","type":"update","data":[{"symbol":"BTC/USDT","bids":[{"price":67735.6,"qty":0.01138196}],"asks":[],"checksum":988513670,"timestamp":"2024-06-01T18:07:00.677690Z"}]}
{"channel":"book","type":"update","data":[{"symbol":"BTC/USDT","bids":[],"asks":[{"price":67762.7,"qty":0.00000000},{"price":67771.0,"qty":0.09000000}],"checksum":234056401,"timestamp":"2024-06-01T18:07:00.720442Z"}]}
{"channel":"book","type":"update","data":[{"symbol":"BTC/USDT","bids":[],"asks":[{"price":67762.4,"qty":0.23808157}],"checksum":3364677423,"timestamp":"2024-06-01T18:07:00.723095Z"}]}
{"channel":"book","type":"update","data":[{"symbol":"BTC/USDT","bids":[],"asks":[{"price":67762.4,"qty":0.23706757},{"price":67762.3,"qty":0.00101400}],"checksum":2978403745,"timestamp":"2024-06-01T18:07:00.735334Z"}]}
{"channel":"book","type":"update","data":[{"symbol":"BTC/USDT","bids":[{"price":67745.8,"qty":0.00000000},{"price":67735.5,"qty":1.01849214},{"price":67741.5,"qty":0.05320986}],"asks":[],"checksum":2355304513,"timestamp":"2024-06-01T18:07:00.818470Z"}]}
{"channel":"book","type":"update","data":[{"symbol":"BTC/USDT","bids":[],"asks":[{"price":67757.7,"qty":0.08947498},{"price":67762.2,"qty":0.03485581}],"checksum":4101175433,"timestamp":"2024-06-01T18:07:01.034188Z"}]}
{"channel":"book","type":"update","data":[{"symbol":"BTC/USDT","bids":[],"asks":[{"price":67762.3,"qty":0.00000000},{"price":67766.5,"qty":0.11788500},{"price":67762.1,"qty":0.00101400}],"checksum":2664010391,"timestamp":"2024-06-01T18:07:01.051219Z"}]}
{"channel":"book","type":"update","data":[{"symbol":"BTC/USDT","bids":[],"asks":[{"price":67762.2,"qty":0.00000000},{"price":67766.5,"qty":0.11788500},{"price":67757.7,"qty":0.12433078}],"checksum":303746701,"timestamp":"2024-06-01T18:07:01.096212Z"}]}
{"channel":"book","type":"update","data":[{"symbol":"BTC/USDT","bids":[],"asks":[{"price":67757.7,"qty":0.08947498},{"price":67762.3,"qty":0.03485580}],"checksum":3088643491,"timestamp":"2024-06-01T18:07:01.145673Z"}]}
{"channel":"book","type":"update","data":[{"symbol":"BTC/USDT","bids":[{"price":67741.5,"qty":0.00000000},{"price":67735.5,"qty":1.04111041},{"price":67745.8,"qty":0.05320648}],"asks":[],"checksum":3733127006,"timestamp":"2024-06-01T18:07:01.439527Z"}]}
{"channel":"book","type":"update","data":[{"symbol":"BTC/USDT","bids":[{"price":67745.8,"qty":0.00000000},{"price":67735.5,"qty":1.04111041},{"price":67741.5,"qty":0.05320976}],"asks":[],"checksum":3759109809,"timestamp":"2024-06-01T18:07:01.588499Z"}]}
{"channel":"book","type":"update","data":[{"symbol":"BTC/USDT","bids":[],"asks":[{"price":67762.3,"qty":0.00000000},{"price":67766.5,"qty":0.11788500},{"price":67757.7,"qty":0.12433161}],"checksum":1080296476,"timestamp":"2024-06-01T18:07:01.856660Z"}]}
{"channel":"book","type":"update","data":[{"symbol":"BTC/USDT","bids":[{"price":67741.5,"qty":0.00000000},{"price":67735.5,"qty":1.04111041},{"price":67745.8,"qty":0.05320638}],"asks":[],"checksum":241903230,"timestamp":"2024-06-01T18:07:01.856697Z"}]}
{"channel":"book","type":"update","data":[{"symbol":"BTC/USDT","bids":[{"price":67745.8,"qty":0.00000000},{"price":67735.5,"qty":1.04111041},{"price":67741.5,"qty":0.05320975}],"asks":[],"checksum":4012027002,"timestamp":"2024-06-01T18:07:01.916019Z"}]}
{"channel":"book","type":"update","data":[{"symbol":"BTC/USDT","bids":[],"asks":[{"price":67765.5,"qty":0.00000000},{"price":67771.0,"qty":0.09000000}],"checksum":4059944847,"timestamp":"2024-06-01T18:07:01.931742Z"}]}
{"channel":"book","type":"update","data":[{"symbol":"BTC/USDT","bids":[],"asks":[{"price":67762.2,"qty":0.00188879}],"checksum":158394649,"timestamp":"2024-06-01T18:07:01.933971Z"}]}
{"channel":"book","type":"update","data":[{"symbol":"BTC/USDT","bids":[],"asks":[{"price":67765.5,"qty":0.00365977}],"checksum":3409185911,"timestamp":"2024-06-01T18:07:01.934243Z"}]}
{"channel":"book","type":"update","data":[{"symbol":"BTC/USDT","bids":[{"price":67741.5,"qty":0.00000000},{"price":67735.5,"qty":1.04111041},{"price":67745.8,"qty":0.05320637}],"asks":[],"checksum":1204848020,"timestamp":"2024-06-01T18:07:02.372747Z"}]}
{"channel":"book","type":"update","data":[{"symbol":"BTC/USDT","bids":[],"asks":[{"price":67762.1,"qty":0.00000000},{"price":67766.5,"qty":0.11788500}],"checksum":417256549,"timestamp":"2024-06-01T18:07:02.400982Z"}]}
{"channel":"book","type":"update","data":[{"symbol":"BTC/USDT","bids":[{"price":67745.8,"qty":0.00000000},{"price":67735.5,"qty":1.04111041},{"price":67741.5,"qty":0.05320975}],"asks":[],"checksum":2486852998,"timestamp":"2024-06-01T18:07:02.748114Z"}]}
{"channel":"book","type":"update","data":[{"symbol":"BTC/USDT","bids":[{"price":67741.5,"qty":0.00000000},{"price":67735.5,"qty":1.04111041},{"price":67741.6,"qty":0.05320967}],"asks":[],"checksum":1423335256,"timestamp":"2024-06-01T18:07:02.877364Z"}]}
{"channel":"book","type":"update","data":[{"symbol":"BTC/USDT","bids":[{"price":67741.6,"qty":0.00000000},{"price":67735.5,"qty":1.04111041},{"price":67741.5,"qty":0.05320975}],"asks":[],"checksum":2486852998,"timestamp":"2024-06-01T18:07:02.934777Z"}]}
{"channel":"book","type":"update","data":[{"symbol":"BTC/USDT","bids":[],"asks":[{"price":67766.5,"qty":0.00000000},{"price":67771.0,"qty":0.09000000}],"checksum":1007667049,"timestamp":"2024-06-01T18:07:03.313506Z"}]}
{"channel":"book","type":"update","data":[{"symbol":"BTC/USDT","bids":[{"price":67750.8,"qty":0.09000000}],"asks":[],"checksum":804129584,"timestamp":"2024-06-01T18:07:03.388947Z"}]}
{"channel":"book","type":"update","data":[{"symbol":"BTC/USDT","bids":[],"asks":[{"price":67766.6,"qty":0.11788600}],"checksum":1071599568,"timestamp":"2024-06-01T18:07:03.430949Z"}]}
{"channel":"book","type":"update","data":[{"symbol":"BTC/USDT","bids":[{"price":67741.5,"qty":0.00000000},{"price":67735.6,"qty":0.01138196},{"price":67745.8,"qty":0.05320642}],"asks":[],"checksum":3248762107,"timestamp":"2024-06-01T18:07:03.443267Z"}]}
{"channel":"book","type":"update","data":[{"symbol":"BTC/USDT","bids":[],"asks":[{"price":67765.6,"qty":0.00000000},{"price":67771.0,"qty":0.09000000}],"checksum":2958828942,"timestamp":"2024-06-01T18:07:03.482710Z"}]}
{"channel":"book","type":"update","data":[{"symbol":"BTC/USDT","bids":[],"asks":[{"price":67762.4,"qty":0.00000000},{"price":67771.3,"qty":0.19976708}],"checksum":750937803,"timestamp":"2024-06-01T18:07:03.482889Z"}]}
{"channel":"book","type":"update","data":[{"symbol":"BTC/USDT","bids":[],"asks":[{"price":67762.7,"qty":0.19095099}],"checksum":160242387,"timestamp":"2024-06-01T18:07:03.487244Z"}]}
{"channel":"book","type":"update","data":[{"symbol":"BTC/USDT","bids":[],"asks":[{"price":67770.9,"qty":2.24377311}],"checksum":4105176840,"timestamp":"2024-06-01T18:07:03.487289Z"}]}
{"channel":"book","type":"update","data":[{"symbol":"BTC/USDT","bids":[],"asks":[{"price":67765.6,"qty":1.27469691}],"checksum":3508020687,"timestamp":"2024-06-01T18:07:03.487380Z"}]}
{"channel":"book","type":"update","data":[{"symbol":"BTC/USDT","bids":[],"asks":[{"price":67757.7,"qty":0.08947498},{"price":67762.6,"qty":0.03485657}],"checksum":196765680,"timestamp":"2024-06-01T18:07:03.538152Z"}]}
{"channel":"book","type":"update","data":[{"symbol":"BTC/USDT","bids":[{"price":67745.8,"qty":0.00000000},{"price":67735.6,"qty":0.01122592},{"price":67750.9,"qty":0.05320241}],"asks":[],"checksum":1952215991,"timestamp":"2024-06-01T18:07:04.185638Z"}]}
{"channel":"book","type":"update","data":[{"symbol":"BTC/USDT","bids":[{"price":67750.8,"qty":0.00000000},{"price":67735.6,"qty":0.01122592}],"asks":[],"checksum":1518828054,"timestamp":"2024-06-01T18:07:04.234613Z"}]}
{"channel":"book","type":"update","data":[{"symbol":"BTC/USDT","bids":[],"asks":[{"price":67762.2,"qty":0.00000000},{"price":67768.0,"qty":0.11788700}],"checksum":1779751862,"timestamp":"2024-06-01T18:07:04.268508Z"}]}
{"channel":"book","type":"update","data":[{"symbol":"BTC/USDT","bids":[],"asks":[{"price":67762.5,"qty":0.00162115}],"checksum":2584564670,"timestamp":"2024-06-01T18:07:04.271198Z"}]}
{"channel":"book","type":"update","data":[{"symbol":"BTC/USDT","bids":[{"price":67750.9,"qty":0.00000000},{"price":67735.5,"qty":1.04111041},{"price":67745.8,"qty":0.05320641}],"asks":[],"checksum":105407996,"timestamp":"2024-06-01T18:07:04.278296Z"}]}
{"channel":"book","type":"update","data":[{"symbol":"BTC/USDT","bids":[],"asks":[{"price":67762.6,"qty":0.00000000},{"price":67768.0,"qty":0.11788700},{"price":67757.7,"qty":0.12433155}],"checksum":1751444001,"timestamp":"2024-06-01T18:07:05.075433Z"}]}
{"channel":"book","type":"update","data":[{"symbol":"BTC/USDT","bids":[],"asks":[{"price":67757.7,"qty":0.08947498},{"price":67762.6,"qty":0.03485657}],"checksum":105407996,"timestamp":"2024-06-01T18:07:05.121553Z"}]}
{"channel":"book","type":"update","data":[{"symbol":"BTC/USDT","bids":[{"price":67750.8,"qty":0.09000000}],"asks":[],"checksum":1273195478,"timestamp":"2024-06-01T18:07:05.635530Z"}]}
{"channel":"book","type":"update","data":[{"symbol":"BTC/USDT","bids":[],"asks":[{"price":67757.7,"qty":0.03947498}],"checksum":573592841,"timestamp":"2024-06-01T18:07:05.675913Z"}]}
{"channel":"book","type":"update","data":[{"symbol":"BTC/USDT","bids":[],"asks":[{"price":67757.7,"qty":0.00000000},{"price":67770.9,"qty":2.24377311}],"checksum":19854861,"timestamp":"2024-06-01T18:07:05.680027Z"}]}
{"channel":"book","type":"update","data":[{"symbol":"BTC/USDT","bids":[],"asks":[{"price":67762.5,"qty":0.04109613}],"checksum":1584839286,"timestamp":"2024-06-01T18:07:05.680198Z"}]}
{"channel":"book","type":"update","data":[{"symbol":"BTC/USDT","bids":[],"asks":[{"price":67762.5,"qty":0.09109613}],"checksum":2785908497,"timestamp":"2024-06-01T18:07:05.687420Z"}]}
{"channel":"book","type":"update","data":[{"symbol":"BTC/USDT","bids":[],"asks":[{"price":67769.3,"qty":0.09000000}],"checksum":2790339014,"timestamp":"2024-06-01T18:07:05.688774Z"}]}
{"channel":"book","type":"update","data":[{"symbol":"BTC/USDT","bids":[],"asks":[{"price":67762.6,"qty":0.00000000},{"price":67770.9,"qty":2.24377311},{"price":67762.4,"qty":0.03485747}],"checksum":1251593780,"timestamp":"2024-06-01T18:07:05.728709Z"}]}
{"channel":"book","type":"update","data":[{"symbol":"BTC/USDT","bids":[],"asks":[{"price":67769.3,"qty":0.00000000},{"price":67770.9,"qty":2.24377311}],"checksum":2911180651,"timestamp":"2024-06-01T18:07:05.732178Z"}]}
{"channel":"book","type":"update","data":[{"symbol":"BTC/USDT","bids":[],"asks":[{"price":67762.3,"qty":0.03947498}],"checksum":2230962167,"timestamp":"2024-06-01T18:07:05.733165Z"}]}
{"channel":"book","type":"update","data":[{"symbol":"BTC/USDT","bids":[],"asks":[{"price":67762.5,"qty":0.04109613},{"price":67762.4,"qty":0.08485747}],"checksum":4187493484,"timestamp":"2024-06-01T18:07:05.735575Z"}]}
{"channel":"book","type":"update","data":[{"symbol":"BTC/USDT","bids":[],"asks":[{"price":67762.4,"qty":0.03485747},{"price":67762.3,"qty":0.08947498}],"checksum":1669973342,"timestamp":"2024-06-01T18:07:05.739519Z"}]}
{"channel":"book","type":"update","data":[{"symbol":"BTC/USDT","bids":[{"price":67750.8,"qty":0.00000000},{"price":67735.6,"qty":0.01122592}],"asks":[],"checksum":774032244,"timestamp":"2024-06-01T18:07:06.015057Z"}]}
{"channel":"book","type":"update","data":[{"symbol":"BTC/USDT","bids":[],"asks":[{"price":67762.5,"qty":0.00162115}],"checksum":3419746855,"timestamp":"2024-06-01T18:07:06.019133Z"}]}
{"channel":"book","type":"update","data":[{"symbol":"BTC/USDT","bids":[{"price":67750.8,"qty":0.09000000}],"asks":[],"checksum":2256419853,"timestamp":"2024-06-01T18:07:06.033427Z"}]}
{"channel":"book","type":"update","data":[{"symbol":"BTC/USDT","bids":[],"asks":[{"price":67762.3,"qty":0.03947498},{"price":67757.7,"qty":0.05000000}],"checksum":2909391951,"timestamp":"2024-06-01T18:07:06.056383Z"}]}
{"channel":"book","type":"update","data":[{"symbol":"BTC/USDT","bids":[{"price":67750.8,"qty":0.00000000},{"price":67735.6,"qty":0.01122592}],"asks":[],"checksum":3770860133,"timestamp":"2024-06-01T18:07:06.059881Z"}]}
{"channel":"book","type":"update","data":[{"symbol":"BTC/USDT","bids":[],"asks":[{"price":67757.7,"qty":0.00000000},{"price":67766.1,"qty":0.19869379},{"price":67762.3,"qty":0.08947498}],"checksum":3419746855,"timestamp":"2024-06-01T18:07:06.060593Z"}]}
{"channel":"book","type":"update","data":[{"symbol":"BTC/USDT","bids":[],"asks":[{"price":67757.7,"qty":0.03947498}],"checksum":1606435586,"timestamp":"2024-06-01T18:07:06.060658Z"}]}
{"channel":"book","type":"update","data":[{"symbol":"BTC/USDT","bids":[],"asks":[{"price":67762.3,"qty":0.03947498}],"checksum":970107257,"timestamp":"2024-06-01T18:07:06.071607Z"}]}
{"channel":"book","type":"update","data":[{"symbol":"BTC/USDT","bids":[],"asks":[{"price":67762.3,"qty":0.08947498}],"checksum":1606435586,"timestamp":"2024-06-01T18:07:06.079762Z"}]}
{"channel":"book","type":"update","data":[{"symbol":"BTC/USDT","bids":[],"asks":[{"price":67762.3,"qty":0.03947498}],"checksum":970107257,"timestamp":"2024-06-01T18:07:06.079980Z"}]}
{"channel":"book","type":"update","data":[{"symbol":"BTC/USDT","bids":[],"asks":[{"price":67762.3,"qty":0.00000000},{"price":67766.1,"qty":0.19869379}],"checksum":1085062697,"timestamp":"2024-06-01T18:07:06.093485Z"}]}
{"channel":"book","type":"update","data":[{"symbol":"BTC/USDT","bids":[],"asks":[{"price":67765.6,"qty":0.00000000},{"price":67769.2,"qty":0.09000000}],"checksum":2850568554,"timestamp":"2024-06-01T18:07:06.324376Z"}]}
{"channel":"book","type":"update","data":[{"symbol":"BTC/USDT","bids":[],"asks":[{"price":67762.7,"qty":0.00000000},{"price":67769.5,"qty":0.11788700}],"checksum":238388902,"timestamp":"2024-06-01T18:07:06.324399Z"}]}
{"channel":"book","type":"update","data":[{"symbol":"BTC/USDT","bids":[],"asks":[{"price":67765.6,"qty":1.04411184}],"checksum":463049693,"timestamp":"2024-06-01T18:07:06.330292Z"}]}
{"channel":"book","type":"update","data":[{"symbol":"BTC/USDT","bids":[],"asks":[{"price":67762.2,"qty":0.65211864}],"checksum":3321559933,"timestamp":"2024-06-01T18:07:06.330394Z"}]}
{"channel":"book","type":"update","data":[{"symbol":"BTC/USDT","bids":[],"asks":[{"price":67762.4,"qty":0.00000000},{"price":67769.2,"qty":0.09000000},{"price":67762.1,"qty":0.03485747}],"checksum":2112478880,"timestamp":"2024-06-01T18:07:06.378206Z"}]}
{"channel":"book","type":"update","data":[{"symbol":"BTC/USDT","bids":[],"asks":[{"price":67762.0,"qty":0.03947498}],"checksum":2393479563,"timestamp":"2024-06-01T18:07:06.382521Z"}]}
{"channel":"book","type":"update","data":[{"symbol":"BTC/USDT","bids":[],"asks":[{"price":67757.7,"qty":0.00000000},{"price":67766.1,"qty":0.19869379}],"checksum":241514279,"timestamp":"2024-06-01T18:07:06.382750Z"}]}
{"channel":"book","type":"update","data":[{"symbol":"BTC/USDT","bids":[],"asks":[{"price":67762.0,"qty":0.08947498}],"checksum":1739983352,"timestamp":"2024-06-01T18:07:06.390294Z"}]}
{"channel":"book","type":"update","data":[{"symbol":"BTC/USDT","bids":[{"price":67750.8,"qty":0.09000000}],"asks":[],"checksum":706545618,"timestamp":"2024-06-01T18:07:06.472868Z"}]}
{"channel":"book","type":"update","data":[{"symbol":"BTC/USDT","bids":[],"asks":[{"price":67762.8,"qty":0.00050000}],"checksum":3119549686,"timestamp":"2024-06-01T18:07:06.602972Z"}]}
{"channel":"book","type":"update","data":[{"symbol":"BTC/USDT","bids":[],"asks":[{"price":67765.5,"qty":0.00000000},{"price":67769.5,"qty":0.11788700}],"checksum":3356205781,"timestamp":"2024-06-01T18:07:06.657712Z"}]}
{"channel":"book","type":"update","data":[{"symbol":"BTC/USDT","bids":[],"asks":[{"price":67762.5,"qty":0.00000000},{"price":67771.3,"qty":0.19976708}],"checksum":507461736,"timestamp":"2024-06-01T18:07:06.657760Z"}]}
{"channel":"book","type":"update","data":[{"symbol":"BTC/USDT","bids":[],"asks":[{"price":67765.5,"qty":0.00317094}],"checksum":3491721066,"timestamp":"2024-06-01T18:07:06.662490Z"}]}
{"channel":"book","type":"update","data":[{"symbol":"BTC/USDT","bids":[],"asks":[{"price":67768.8,"qty":0.09000000}],"checksum":3537194943,"timestamp":"2024-06-01T18:07:06.738713Z"}]}
{"channel":"book","type":"update","data":[{"symbol":"BTC/USDT","bids":[],"asks":[{"price":67768.8,"qty":0.00000000},{"price":67771.3,"qty":0.19976708}],"checksum":2550216412,"timestamp":"2024-06-01T18:07:06.792731Z"}]}
{"channel":"book","type":"update","data":[{"symbol":"BTC/USDT","bids":[],"asks":[{"price":67762.0,"qty":0.03947498}],"checksum":4057073667,"timestamp":"2024-06-01T18:07:06.803113Z"}]}
{"channel":"book","type":"update","data":[{"symbol":"BTC/USDT","bids":[{"price":67757.6,"qty":0.08074411}],"asks":[],"checksum":3780950159,"timestamp":"2024-06-01T18:07:06.803291Z"}]}
{"channel":"book","type":"update","data":[{"symbol":"BTC/USDT","bids":[],"asks":[{"price":67762.0,"qty":0.08947498}],"checksum":2291107408,"timestamp":"2024-06-01T18:07:06.807106Z"}]}
{"channel":"book","type":"update","data":[{"symbol":"BTC/USDT","bids":[],"asks":[{"price":67762.0,"qty":0.03947498}],"checksum":3780950159,"timestamp":"2024-06-01T18:07:06.807300Z"}]}
{"channel":"book","type":"update","data":[{"symbol":"BTC/USDT","bids":[],"asks":[{"price":67762.0,"qty":0.08947498}],"checksum":2291107408,"timestamp":"2024-06-01T18:07:06.810708Z"}]}
{"channel":"book","type":"update","data":[{"symbol":"BTC/USDT","bids":[],"asks":[{"price":67762.0,"qty":0.03947498}],"checksum":3780950159,"timestamp":"2024-06-01T18:07:06.828832Z"}]}
{"channel":"book","type":"update","data":[{"symbol":"BTC/USDT","bids":[{"price":67757.6,"qty":0.03074411}],"asks":[],"checksum":4057073667,"timestamp":"2024-06-01T18:07:06.838086Z"}]}
{"channel":"book","type":"update","data":[{"symbol":"BTC/USDT","bids":[{"price":67757.6,"qty":0.08074411}],"asks":[],"checksum":3780950159,"timestamp":"2024-06-01T18:07:06.845094Z"}]}
{"channel":"book","type":"update","data":[{"symbol":"BTC/USDT","bids":[],"asks":[{"price":67770.9,"qty":0.11788700}],"checksum":2650256947,"timestamp":"2024-06-01T18:07:06.877783Z"}]}
{"channel":"book","type":"update","data":[{"symbol":"BTC/USDT","bids":[],"asks":[{"price":67762.0,"qty":0.08947498}],"checksum":4096035052,"timestamp":"2024-06-01T18:07:06.934831Z"}]}
{"channel":"book","type":"update","data":[{"symbol":"BTC/USDT","bids":[{"price":67745.8,"qty":0.00000000},{"price":67735.6,"qty":0.01122592},{"price":67750.9,"qty":0.05320271}],"asks":[],"checksum":2976590114,"timestamp":"2024-06-01T18:07:06.948630Z"}]}
{"channel":"book","type":"update","data":[{"symbol":"BTC/USDT","bids":[],"asks":[{"price":67762.1,"qty":0.00000000},{"price":67771.3,"qty":0.19976708},{"price":67761.9,"qty":0.03485747}],"checksum":2781668784,"timestamp":"2024-06-01T18:07:06.948658Z"}]}
{"channel":"book","type":"update","data":[{"symbol":"BTC/USDT","bids":[],"asks":[{"price":67762.0,"qty":0.03947498},{"price":67761.9,"qty":0.08485747}],"checksum":195977521,"timestamp":"2024-06-01T18:07:06.958729Z"}]}
{"channel":"book","type":"update","data":[{"symbol":"BTC/USDT","bids":[],"asks":[{"price":67768.7,"qty":0.09000000}],"checksum":1053941462,"timestamp":"2024-06-01T18:07:07.047966Z"}]}
{"channel":"book","type":"update","data":[{"symbol":"BTC/USDT","bids":[],"asks":[{"price":67761.8,"qty":0.03947498}],"checksum":3095181828,"timestamp":"2024-06-01T18:07:07.166200Z"}]}
{"channel":"book","type":"update","data":[{"symbol":"BTC/USDT","bids":[],"asks":[{"price":67761.9,"qty":0.03485747},{"price":67761.8,"qty":0.08947498}],"checksum":194146796,"timestamp":"2024-06-01T18:07:07.175232Z"}]}
{"channel":"book","type":"update","data":[{"symbol":"BTC/USDT","bids":[],"asks":[{"price":67761.9,"qty":0.00000000},{"price":67768.6,"qty":0.09000000},{"price":67761.7,"qty":0.03485747}],"checksum":3091952954,"timestamp":"2024-06-01T18:07:07.585587Z"}]}
{"channel":"book","type":"update","data":[{"symbol":"BTC/USDT","bids":[{"price":67750.8,"qty":0.00000000},{"price":67735.6,"qty":0.01122592}],"asks":[],"checksum":2526051483,"timestamp":"2024-06-01T18:07:07.588742Z"}]}
{"channel":"book","type":"update","data":[{"symbol":"BTC/USDT","bids":[],"asks":[{"price":67762.0,"qty":0.00000000},{"price":67770.9,"qty":0.11788700}],"checksum":2230814708,"timestamp":"2024-06-01T18:07:07.590449Z"}]}
{"channel":"book","type":"update","data":[{"symbol":"BTC/USDT","bids":[],"asks":[{"price":67768.5,"qty":0.09000000}],"checksum":3965281016,"timestamp":"2024-06-01T18:07:07.592944Z"}]}
{"channel":"book","type":"update","data":[{"symbol":"BTC/USDT","bids":[{"price":67750.8,"qty":0.09000000}],"asks":[],"checksum":3263327065,"timestamp":"2024-06-01T18:07:07.593552Z"}]}
{"channel":"book","type":"update","data":[{"symbol":"BTC/USDT","bids":[],"asks":[{"price":67761.8,"qty":0.03947498},{"price":67761.7,"qty":0.08485747}],"checksum":1902944433,"timestamp":"2024-06-01T18:07:07.595209Z"}]}
{"channel":"book","type":"update","data":[{"symbol":"BTC/USDT","bids":[{"price":67750.8,"qty":0.00000000},{"price":67735.6,"qty":0.01122592}],"asks":[],"checksum":1605871888,"timestamp":"2024-06-01T18:07:07.932926Z"}]}
{"channel":"book","type":"update","data":[{"symbol":"BTC/USDT","bids":[],"asks":[{"price":67761.6,"qty":0.03947498}],"checksum":1018994116,"timestamp":"2024-06-01T18:07:07.937140Z"}]}
{"channel":"book","type":"update","data":[{"symbol":"BTC/USDT","bids":[],"asks":[{"price":67761.7,"qty":0.03485747},{"price":67761.6,"qty":0.08947498}],"checksum":2404537900,"timestamp":"2024-06-01T18:07:07.943552Z"}]}
{"channel":"book","type":"update","data":[{"symbol":"BTC/USDT","bids":[{"price":67750.9,"qty":0.00000000},{"price":67735.5,"qty":1.09581539},{"price":67745.8,"qty":0.05320680}],"asks":[],"checksum":1266072346,"timestamp":"2024-06-01T18:07:07.989708Z"}]}
{"channel":"book","type":"update","data":[{"symbol":"BTC/USDT","bids":[],"asks":[{"price":67761.8,"qty":0.00000000},{"price":67768.5,"qty":0.09000000}],"checksum":156244860,"timestamp":"2024-06-01T18:07:07.993625Z"}]}
{"channel":"book","type":"update","data":[{"symbol":"BTC/USDT","bids":[{"price":67757.6,"qty":0.03074411}],"asks":[],"checksum":434023408,"timestamp":"2024-06-01T18:07:08.119061Z"}]}
{"channel":"book","type":"update","data":[{"symbol":"BTC/USDT","bids":[],"asks":[{"price":67761.7,"qty":0.00000000},{"price":67770.9,"qty":0.11788700},{"price":67761.5,"qty":0.03485608}],"checksum":995643471,"timestamp":"2024-06-01T18:07:08.178770Z"}]}
{"channel":"book","type":"update","data":[{"symbol":"BTC/USDT","bids":[],"asks":[{"price":67761.4,"qty":0.03947498}],"checksum":1962719431,"timestamp":"2024-06-01T18:07:08.182879Z"}]}
{"channel":"book","type":"update","data":[{"symbol":"BTC/USDT","bids":[],"asks":[{"price":67761.6,"qty":0.03947498},{"price":67761.5,"qty":0.08485608}],"checksum":709578387,"timestamp":"2024-06-01T18:07:08.187652Z"}]}
{"channel":"book","type":"update","data":[{"symbol":"BTC/USDT","bids":[],"asks":[{"price":67761.5,"qty":0.03485608},{"price":67761.4,"qty":0.08947498}],"checksum":2577761659,"timestamp":"2024-06-01T18:07:08.194682Z"}]}
{"channel":"book","type":"update","data":[{"symbol":"BTC/USDT","bids":[{"price":67741.5,"qty":0.06044658}],"asks":[],"checksum":428701444,"timestamp":"2024-06-01T18:07:08.416657Z"}]}
