{"channel":"book","type":"snapshot","data":[{"symbol":"BTC/JPY","bids":[{"price":10636486,"qty":0.00309882},{"price":10635411,"qty":0.59860932},{"price":10631960,"qty":0.00153024},{"price":10631959,"qty":0.26132317},{"price":10630087,"qty":0.48668914},{"price":10623057,"qty":0.00032120},{"price":10620742,"qty":0.48668914},{"price":10612934,"qty":1.20677396},{"price":10604007,"qty":1.31226123},{"price":10604006,"qty":0.98399545}],"asks":[{"price":10669036,"qty":0.03538142},{"price":10670647,"qty":0.00039518},{"price":10681684,"qty":0.01129070},{"price":10681687,"qty":0.19158588},{"price":10681693,"qty":0.26132317},{"price":10687029,"qty":0.48668914},{"price":10690999,"qty":0.48668914},{"price":10691000,"qty":0.00010000},{"price":10693447,"qty":1.21099321},{"price":10697794,"qty":0.00030785}],"checksum":483181345}]}
{"channel":"book","type":"update","data":[{"symbol":"BTC/JPY","bids":[{"price":10631959,"qty":0.00000000},{"price":10598800,"qty":0.00011000}],"asks":[],"checksum":644543776,"timestamp":"2024-06-01T18:06:34.319345Z"}]}
{"channel":"book","type":"update","data":[{"symbol":"BTC/JPY","bids":[{"price":10630087,"qty":0.00000000},{"price":10598456,"qty":2.41431039}],"asks":[],"checksum":605196181,"timestamp":"2024-06-01T18:06:34.319514Z"}]}
{"channel":"book","type":"update","data":[{"symbol":"BTC/JPY","bids":[{"price":10620742,"qty":0.00000000},{"price":10556416,"qty":0.65329189}],"asks":[],"checksum":1123359506,"timestamp":"2024-06-01T18:06:34.319524Z"}]}
{"channel":"book","type":"update","data":[{"symbol":"BTC/JPY","bids":[],"asks":[{"price":10687029,"qty":0.00000000},{"price":10707028,"qty":0.03404784}],"checksum":1822931408,"timestamp":"2024-06-01T18:06:34.319539Z"}]}
{"channel":"book","type":"update","data":[{"symbol":"BTC/JPY","bids":[{"price":10604007,"qty":0.00000000},{"price":10556415,"qty":0.00012087}],"asks":[],"checksum":3672432572,"timestamp":"2024-06-01T18:06:34.319577Z"}]}
{"channel":"book","type":"update","data":[{"symbol":"BTC/JPY","bids":[],"asks":[{"price":10690999,"qty":0.00000000},{"price":10707029,"qty":1.31226123}],"checksum":3602395689,"timestamp":"2024-06-01T18:06:34.319590Z"}]}
{"channel":"book","type":"update","data":[{"symbol":"BTC/JPY","bids":[],"asks":[{"price":10681693,"qty":0.00000000},{"price":10707030,"qty":2.42190826}],"checksum":3563588328,"timestamp":"2024-06-01T18:06:34.319676Z"}]}
{"channel":"book","type":"update","data":[{"symbol":"BTC/JPY","bids":[],"asks":[{"price":10707029,"qty":0.00000000},{"price":10709568,"qty":0.00014358}],"checksum":4055830833,"timestamp":"2024-06-01T18:06:34.319928Z"}]}
{"channel":"book","type":"update","data":[{"symbol":"BTC/JPY","bids":[{"price":10643468,"qty":0.26132317}],"asks":[],"checksum":3070478059,"timestamp":"2024-06-01T18:06:34.322106Z"}]}
{"channel":"book","type":"update","data":[{"symbol":"BTC/JPY","bids":[{"price":10631961,"qty":0.48668914}],"asks":[],"checksum":3062805492,"timestamp":"2024-06-01T18:06:34.322245Z"}]}
{"channel":"book","type":"update","data":[{"symbol":"BTC/JPY","bids":[{"price":10638141,"qty":0.48668914}],"asks":[],"checksum":2596967219,"timestamp":"2024-06-01T18:06:34.322262Z"}]}
{"channel":"book","type":"update","data":[{"symbol":"BTC/JPY","bids":[],"asks":[{"price":10670119,"qty":0.48668914}],"checksum":3374897755,"timestamp":"2024-06-01T18:06:34.322286Z"}]}
{"channel":"book","type":"update","data":[{"symbol":"BTC/JPY","bids":[{"price":10620743,"qty":1.31226123}],"asks":[],"checksum":924761732,"timestamp":"2024-06-01T18:06:34.322377Z"}]}
{"channel":"book","type":"update","data":[{"symbol":"BTC/JPY","bids":[],"asks":[{"price":10664792,"qty":0.26132317}],"checksum":3504579066,"timestamp":"2024-06-01T18:06:34.322399Z"}]}
{"channel":"book","type":"update","data":[{"symbol":"BTC/JPY","bids":[],"asks":[{"price":10681682,"qty":0.48668914}],"checksum":1682700670,"timestamp":"2024-06-01T18:06:34.322456Z"}]}
{"channel":"book","type":"update","data":[{"symbol":"BTC/JPY","bids":[],"asks":[{"price":10687028,"qty":1.31226123}],"checksum":2293858333,"timestamp":"2024-06-01T18:06:34.322686Z"}]}
{"channel":"book","type":"update","data":[{"symbol":"BTC/JPY","bids":[{"price":10620743,"qty":0.00000000},{"price":10598800,"qty":0.00011000}],"asks":[],"checksum":770312634,"timestamp":"2024-06-01T18:06:34.325224Z"}]}
{"channel":"book","type":"update","data":[{"symbol":"BTC/JPY","bids":[{"price":10638141,"qty":0.00000000},{"price":10598456,"qty":2.41431039}],"asks":[],"checksum":576563434,"timestamp":"2024-06-01T18:06:34.325249Z"}]}
{"channel":"book","type":"update","data":[{"symbol":"BTC/JPY","bids":[],"asks":[{"price":10664792,"qty":0.00000000},{"price":10697794,"qty":0.00030785}],"checksum":3068098180,"timestamp":"2024-06-01T18:06:34.325297Z"}]}
{"channel":"book","type":"update","data":[{"symbol":"BTC/JPY","bids":[],"asks":[{"price":10687028,"qty":0.00000000},{"price":10707028,"qty":0.03404784}],"checksum":1085523309,"timestamp":"2024-06-01T18:06:34.325358Z"}]}
{"channel":"book","type":"update","data":[{"symbol":"BTC/JPY","bids":[{"price":10631961,"qty":0.00000000},{"price":10556416,"qty":0.65329189}],"asks":[],"checksum":1094627442,"timestamp":"2024-06-01T18:06:34.325414Z"}]}
{"channel":"book","type":"update","data":[{"symbol":"BTC/JPY","bids":[{"price":10643468,"qty":0.00000000},{"price":10556415,"qty":0.00012087}],"asks":[],"checksum":2094345779,"timestamp":"2024-06-01T18:06:34.325427Z"}]}
{"channel":"book","type":"update","data":[{"symbol":"BTC/JPY","bids":[],"asks":[{"price":10670119,"qty":0.00000000},{"price":10707030,"qty":2.42190826}],"checksum":4032709937,"timestamp":"2024-06-01T18:06:34.325827Z"}]}
{"channel":"book","type":"update","data":[{"symbol":"BTC/JPY","bids":[{"price":10604007,"qty":1.31226123}],"asks":[],"checksum":1182885364,"timestamp":"2024-06-01T18:06:34.328149Z"}]}
{"channel":"book","type":"update","data":[{"symbol":"BTC/JPY","bids":[],"asks":[{"price":10707027,"qty":1.31226123}],"checksum":3754088273,"timestamp":"2024-06-01T18:06:34.328255Z"}]}
{"channel":"book","type":"update","data":[{"symbol":"BTC/JPY","bids":[{"price":10625791,"qty":0.48668914}],"asks":[],"checksum":380477324,"timestamp":"2024-06-01T18:06:34.328270Z"}]}
{"channel":"book","type":"update","data":[{"symbol":"BTC/JPY","bids":[],"asks":[{"price":10677172,"qty":0.26132317}],"checksum":1751783291,"timestamp":"2024-06-01T18:06:34.328676Z"}]}
{"channel":"book","type":"update","data":[{"symbol":"BTC/JPY","bids":[{"price":10631112,"qty":0.26132317}],"asks":[],"checksum":3737135710,"timestamp":"2024-06-01T18:06:34.328761Z"}]}
{"channel":"book","type":"update","data":[{"symbol":"BTC/JPY","bids":[],"asks":[{"price":10682506,"qty":0.48668914}],"checksum":3805015022,"timestamp":"2024-06-01T18:06:34.328801Z"}]}
{"channel":"book","type":"update","data":[{"symbol":"BTC/JPY","bids":[{"price":10612935,"qty":0.48668914}],"asks":[],"checksum":463168408,"timestamp":"2024-06-01T18:06:34.328857Z"}]}
{"channel":"book","type":"update","data":[{"symbol":"BTC/JPY","bids":[{"price":10623058,"qty":0.01171219}],"asks":[],"checksum":504037195,"timestamp":"2024-06-01T18:06:34.329267Z"}]}
{"channel":"book","type":"update","data":[{"symbol":"BTC/JPY","bids":[{"price":10631960,"qty":0.00000000},{"price":10604006,"qty":0.98399545}],"asks":[],"checksum":4142690743,"timestamp":"2024-06-01T18:06:34.329362Z"}]}
{"channel":"book","type":"update","data":[{"symbol":"BTC/JPY","bids":[],"asks":[{"price":10681681,"qty":0.01129070}],"checksum":3427218513,"timestamp":"2024-06-01T18:06:34.329381Z"}]}
{"channel":"book","type":"update","data":[{"symbol":"BTC/JPY","bids":[],"asks":[{"price":10681684,"qty":0.00000000},{"price":10697794,"qty":0.00030785}],"checksum":377490576,"timestamp":"2024-06-01T18:06:34.329401Z"}]}
{"channel":"book","type":"update","data":[{"symbol":"BTC/JPY","bids":[{"price":10623058,"qty":0.00000000},{"price":10598800,"qty":0.00011000}],"asks":[],"checksum":2941307175,"timestamp":"2024-06-01T18:06:34.341987Z"}]}
{"channel":"book","type":"update","data":[{"symbol":"BTC/JPY","bids":[{"price":10631113,"qty":0.01170331}],"asks":[],"checksum":550244311,"timestamp":"2024-06-01T18:06:34.342059Z"}]}
{"channel":"book","type":"update","data":[{"symbol":"BTC/JPY","bids":[],"asks":[{"price":10669036,"qty":0.00000000},{"price":10707027,"qty":1.31226123},{"price":10667997,"qty":0.03539499}],"checksum":3789192913,"timestamp":"2024-06-01T18:06:34.345658Z"}]}
{"channel":"book","type":"update","data":[{"symbol":"BTC/JPY","bids":[],"asks":[{"price":10681687,"qty":0.00000000},{"price":10707027,"qty":1.31226123},{"price":10681680,"qty":0.24104705}],"checksum":965789414,"timestamp":"2024-06-01T18:06:34.395463Z"}]}
{"channel":"book","type":"update","data":[{"symbol":"BTC/JPY","bids":[],"asks":[{"price":10681681,"qty":0.00000000},{"price":10707027,"qty":1.31226123}],"checksum":1740738713,"timestamp":"2024-06-01T18:06:34.404295Z"}]}
{"channel":"book","type":"update","data":[{"symbol":"BTC/JPY","bids":[],"asks":[{"price":10681679,"qty":0.01129070}],"checksum":960404994,"timestamp":"2024-06-01T18:06:34.404306Z"}]}
{"channel":"book","type":"update","data":[{"symbol":"BTC/JPY","bids":[],"asks":[{"price":10681680,"qty":0.00000000},{"price":10707027,"qty":1.31226123},{"price":10681678,"qty":0.24129914}],"checksum":2294922857,"timestamp":"2024-06-01T18:06:34.458214Z"}]}
{"channel":"book","type":"update","data":[{"symbol":"BTC/JPY","bids":[],"asks":[{"price":10681677,"qty":0.01129070}],"checksum":2663726986,"timestamp":"2024-06-01T18:06:34.467630Z"}]}
{"channel":"book","type":"update","data":[{"symbol":"BTC/JPY","bids":[],"asks":[{"price":10681679,"qty":0.00000000},{"price":10697794,"qty":0.00030785}],"checksum":624950838,"timestamp":"2024-06-01T18:06:34.467778Z"}]}
{"channel":"book","type":"update","data":[{"symbol":"BTC/JPY","bids":[],"asks":[{"price":10681678,"qty":0.00000000},{"price":10707027,"qty":1.31226123},{"price":10681676,"qty":0.24198378}],"checksum":3482071849,"timestamp":"2024-06-01T18:06:34.536002Z"}]}
{"channel":"book","type":"update","data":[{"symbol":"BTC/JPY","bids":[],"asks":[{"price":10681677,"qty":0.00000000},{"price":10707027,"qty":1.31226123}],"checksum":1111839674,"timestamp":"2024-06-01T18:06:34.557933Z"}]}
{"channel":"book","type":"update","data":[{"symbol":"BTC/JPY","bids":[],"asks":[{"price":10681675,"qty":0.01129070}],"checksum":4151700915,"timestamp":"2024-06-01T18:06:34.558126Z"}]}
{"channel":"book","type":"update","data":[{"symbol":"BTC/JPY","bids":[{"price":10631113,"qty":0.01333355}],"asks":[],"checksum":1980667033,"timestamp":"2024-06-01T18:06:34.593948Z"}]}
{"channel":"book","type":"update","data":[{"symbol":"BTC/JPY","bids":[{"price":10631113,"qty":0.00163024}],"asks":[],"checksum":3752032605,"timestamp":"2024-06-01T18:06:34.593990Z"}]}
{"channel":"book","type":"update","data":[{"symbol":"BTC/JPY","bids":[],"asks":[{"price":10681676,"qty":0.00000000},{"price":10707027,"qty":1.31226123},{"price":10681674,"qty":0.23999770}],"checksum":3546976943,"timestamp":"2024-06-01T18:06:34.607814Z"}]}
{"channel":"book","type":"update","data":[{"symbol":"BTC/JPY","bids":[],"asks":[{"price":10681675,"qty":0.00000000},{"price":10707027,"qty":1.31226123}],"checksum":1049466488,"timestamp":"2024-06-01T18:06:34.620129Z"}]}
{"channel":"book","type":"update","data":[{"symbol":"BTC/JPY","bids":[],"asks":[{"price":10681673,"qty":0.01129070}],"checksum":3604041698,"timestamp":"2024-06-01T18:06:34.620364Z"}]}
{"channel":"book","type":"update","data":[{"symbol":"BTC/JPY","bids":[],"asks":[{"price":10681674,"qty":0.00000000},{"price":10707027,"qty":1.31226123},{"price":10681672,"qty":0.24009286}],"checksum":2376903941,"timestamp":"2024-06-01T18:06:34.676141Z"}]}
{"channel":"book","type":"update","data":[{"symbol":"BTC/JPY","bids":[],"asks":[{"price":10681673,"qty":0.00000000},{"price":10707027,"qty":1.31226123}],"checksum":3711144398,"timestamp":"2024-06-01T18:06:34.692832Z"}]}
{"channel":"book","type":"update","data":[{"symbol":"BTC/JPY","bids":[],"asks":[{"price":10681671,"qty":0.01129070}],"checksum":2248452458,"timestamp":"2024-06-01T18:06:34.693193Z"}]}
{"channel":"book","type":"update","data":[{"symbol":"BTC/JPY","bids":[],"asks":[{"price":10681672,"qty":0.00000000},{"price":10707027,"qty":1.31226123},{"price":10681670,"qty":0.24006919}],"checksum":1209319075,"timestamp":"2024-06-01T18:06:34.753786Z"}]}
{"channel":"book","type":"update","data":[{"symbol":"BTC/JPY","bids":[],"asks":[{"price":10681671,"qty":0.00000000},{"price":10707027,"qty":1.31226123}],"checksum":2705321693,"timestamp":"2024-06-01T18:06:34.788962Z"}]}
{"channel":"book","type":"update","data":[{"symbol":"BTC/JPY","bids":[],"asks":[{"price":10681669,"qty":0.01129070}],"checksum":1329593578,"timestamp":"2024-06-01T18:06:34.789009Z"}]}
{"channel":"book","type":"update","data":[{"symbol":"BTC/JPY","bids":[],"asks":[{"price":10677171,"qty":0.00529396}],"checksum":661708143,"timestamp":"2024-06-01T18:06:34.823826Z"}]}
{"channel":"book","type":"update","data":[{"symbol":"BTC/JPY","bids":[],"asks":[{"price":10681670,"qty":0.00000000},{"price":10697794,"qty":0.00030785},{"price":10681668,"qty":0.24001438}],"checksum":613137422,"timestamp":"2024-06-01T18:06:34.849100Z"}]}
{"channel":"book","type":"update","data":[{"symbol":"BTC/JPY","bids":[],"asks":[{"price":10681669,"qty":0.00000000},{"price":10697794,"qty":0.00030785}],"checksum":3561762851,"timestamp":"2024-06-01T18:06:34.865317Z"}]}
{"channel":"book","type":"update","data":[{"symbol":"BTC/JPY","bids":[],"asks":[{"price":10681667,"qty":0.01129070}],"checksum":2068922228,"timestamp":"2024-06-01T18:06:34.865573Z"}]}
{"channel":"book","type":"update","data":[{"symbol":"BTC/JPY","bids":[],"asks":[{"price":10681668,"qty":0.00000000},{"price":10697794,"qty":0.00030785},{"price":10681666,"qty":0.24264445}],"checksum":4226466799,"timestamp":"2024-06-01T18:06:34.957296Z"}]}
{"channel":"book","type":"update","data":[{"symbol":"BTC/JPY","bids":[],"asks":[{"price":10681667,"qty":0.00000000},{"price":10697794,"qty":0.00030785}],"checksum":366516189,"timestamp":"2024-06-01T18:06:34.986222Z"}]}
{"channel":"book","type":"update","data":[{"symbol":"BTC/JPY","bids":[],"asks":[{"price":10681665,"qty":0.01129070}],"checksum":3992498475,"timestamp":"2024-06-01T18:06:34.986607Z"}]}
{"channel":"book","type":"update","data":[{"symbol":"BTC/JPY","bids":[],"asks":[{"price":10681666,"qty":0.00000000},{"price":10697794,"qty":0.00030785},{"price":10681664,"qty":0.24343165}],"checksum":2051428091,"timestamp":"2024-06-01T18:06:35.034084Z"}]}
{"channel":"book","type":"update","data":[{"symbol":"BTC/JPY","bids":[],"asks":[{"price":10681665,"qty":0.00000000},{"price":10697794,"qty":0.00030785}],"checksum":212406541,"timestamp":"2024-06-01T18:06:35.048796Z"}]}
{"channel":"book","type":"update","data":[{"symbol":"BTC/JPY","bids":[],"asks":[{"price":10681663,"qty":0.01129070}],"checksum":1763172922,"timestamp":"2024-06-01T18:06:35.049013Z"}]}
{"channel":"book","type":"update","data":[{"symbol":"BTC/JPY","bids":[],"asks":[{"price":10681664,"qty":0.00000000},{"price":10697794,"qty":0.00030785},{"price":10681662,"qty":0.24453107}],"checksum":1670295472,"timestamp":"2024-06-01T18:06:35.115874Z"}]}
{"channel":"book","type":"update","data":[{"symbol":"BTC/JPY","bids":[],"asks":[{"price":10681663,"qty":0.00000000},{"price":10697794,"qty":0.00030785}],"checksum":1435823600,"timestamp":"2024-06-01T18:06:35.136116Z"}]}
{"channel":"book","type":"update","data":[{"symbol":"BTC/JPY","bids":[],"asks":[{"price":10681661,"qty":0.01129070}],"checksum":188038280,"timestamp":"2024-06-01T18:06:35.136269Z"}]}
{"channel":"book","type":"update","data":[{"symbol":"BTC/JPY","bids":[],"asks":[{"price":10681662,"qty":0.00000000},{"price":10697794,"qty":0.00030785},{"price":10681660,"qty":0.24527528}],"checksum":277301222,"timestamp":"2024-06-01T18:06:35.185714Z"}]}
{"channel":"book","type":"update","data":[{"symbol":"BTC/JPY","bids":[],"asks":[{"price":10681661,"qty":0.00000000},{"price":10697794,"qty":0.00030785}],"checksum":4265708635,"timestamp":"2024-06-01T18:06:35.229131Z"}]}
{"channel":"book","type":"update","data":[{"symbol":"BTC/JPY","bids":[],"asks":[{"price":10681659,"qty":0.01129070}],"checksum":4004242691,"timestamp":"2024-06-01T18:06:35.229288Z"}]}
{"channel":"book","type":"update","data":[{"symbol":"BTC/JPY","bids":[],"asks":[{"price":10681660,"qty":0.00000000},{"price":10697794,"qty":0.00030785},{"price":10681658,"qty":0.24548398}],"checksum":1669467096,"timestamp":"2024-06-01T18:06:35.285867Z"}]}
{"channel":"book","type":"update","data":[{"symbol":"BTC/JPY","bids":[],"asks":[{"price":10681659,"qty":0.00000000},{"price":10697794,"qty":0.00030785}],"checksum":2044402259,"timestamp":"2024-06-01T18:06:35.316208Z"}]}
{"channel":"book","type":"update","data":[{"symbol":"BTC/JPY","bids":[],"asks":[{"price":10681657,"qty":0.01129070}],"checksum":2920682043,"timestamp":"2024-06-01T18:06:35.316392Z"}]}
{"channel":"book","type":"update","data":[{"symbol":"BTC/JPY","bids":[],"asks":[{"price":10681658,"qty":0.00000000},{"price":10697794,"qty":0.00030785},{"price":10681656,"qty":0.24564111}],"checksum":3205428769,"timestamp":"2024-06-01T18:06:35.362950Z"}]}
{"channel":"book","type":"update","data":[{"symbol":"BTC/JPY","bids":[],"asks":[{"price":10681655,"qty":0.01129070}],"checksum":4184816726,"timestamp":"2024-06-01T18:06:35.372285Z"}]}
{"channel":"book","type":"update","data":[{"symbol":"BTC/JPY","bids":[],"asks":[{"price":10681657,"qty":0.00000000},{"price":10693447,"qty":1.21099321}],"checksum":2172884227,"timestamp":"2024-06-01T18:06:35.372344Z"}]}
{"channel":"book","type":"update","data":[{"symbol":"BTC/JPY","bids":[],"asks":[{"price":10681656,"qty":0.00000000},{"price":10697794,"qty":0.00030785},{"price":10681654,"qty":0.24412247}],"checksum":1688238963,"timestamp":"2024-06-01T18:06:35.427407Z"}]}
{"channel":"book","type":"update","data":[{"symbol":"BTC/JPY","bids":[],"asks":[{"price":10681655,"qty":0.00000000},{"price":10697794,"qty":0.00030785}],"checksum":2904376262,"timestamp":"2024-06-01T18:06:35.461424Z"}]}
{"channel":"book","type":"update","data":[{"symbol":"BTC/JPY","bids":[],"asks":[{"price":10681653,"qty":0.01129070}],"checksum":3242272684,"timestamp":"2024-06-01T18:06:35.461617Z"}]}
{"channel":"book","type":"update","data":[{"symbol":"BTC/JPY","bids":[],"asks":[{"price":10681654,"qty":0.00000000},{"price":10697794,"qty":0.00030785},{"price":10681652,"qty":0.24514746}],"checksum":1133585890,"timestamp":"2024-06-01T18:06:35.536596Z"}]}
{"channel":"book","type":"update","data":[{"symbol":"BTC/JPY","bids":[],"asks":[{"price":10681651,"qty":0.01129070}],"checksum":1670918083,"timestamp":"2024-06-01T18:06:35.553623Z"}]}
{"channel":"book","type":"update","data":[{"symbol":"BTC/JPY","bids":[],"asks":[{"price":10681653,"qty":0.00000000},{"price":10693447,"qty":1.21099321}],"checksum":1519807638,"timestamp":"2024-06-01T18:06:35.553699Z"}]}
{"channel":"book","type":"update","data":[{"symbol":"BTC/JPY","bids":[],"asks":[{"price":10681652,"qty":0.00000000},{"price":10697794,"qty":0.00030785},{"price":10681650,"qty":0.24501528}],"checksum":4090790544,"timestamp":"2024-06-01T18:06:35.616425Z"}]}
{"channel":"book","type":"update","data":[{"symbol":"BTC/JPY","bids":[],"asks":[{"price":10681649,"qty":0.01129070}],"checksum":472458764,"timestamp":"2024-06-01T18:06:35.628857Z"}]}
{"channel":"book","type":"update","data":[{"symbol":"BTC/JPY","bids":[],"asks":[{"price":10681651,"qty":0.00000000},{"price":10693447,"qty":1.21099321}],"checksum":2875084115,"timestamp":"2024-06-01T18:06:35.629003Z"}]}
{"channel":"book","type":"update","data":[{"symbol":"BTC/JPY","bids":[],"asks":[{"price":10681650,"qty":0.00000000},{"price":10697794,"qty":0.00030785},{"price":10681648,"qty":0.24484201}],"checksum":668874108,"timestamp":"2024-06-01T18:06:35.672933Z"}]}
{"channel":"book","type":"update","data":[{"symbol":"BTC/JPY","bids":[],"asks":[{"price":10681649,"qty":0.00000000},{"price":10697794,"qty":0.00030785}],"checksum":1214831149,"timestamp":"2024-06-01T18:06:35.684068Z"}]}
{"channel":"book","type":"update","data":[{"symbol":"BTC/JPY","bids":[],"asks":[{"price":10681647,"qty":0.01129070}],"checksum":71972590,"timestamp":"2024-06-01T18:06:35.684534Z"}]}
{"channel":"book","type":"update","data":[{"symbol":"BTC/JPY","bids":[],"asks":[{"price":10681648,"qty":0.00000000},{"price":10697794,"qty":0.00030785},{"price":10681646,"qty":0.24475460}],"checksum":1362878684,"timestamp":"2024-06-01T18:06:35.756553Z"}]}
{"channel":"book","type":"update","data":[{"symbol":"BTC/JPY","bids":[],"asks":[{"price":10681647,"qty":0.00000000},{"price":10697794,"qty":0.00030785}],"checksum":1428968817,"timestamp":"2024-06-01T18:06:35.775080Z"}]}
{"channel":"book","type":"update","data":[{"symbol":"BTC/JPY","bids":[],"asks":[{"price":10681645,"qty":0.01129070}],"checksum":1751658588,"timestamp":"2024-06-01T18:06:35.775391Z"}]}
{"channel":"book","type":"update","data":[{"symbol":"BTC/JPY","bids":[],"asks":[{"price":10681646,"qty":0.00000000},{"price":10697794,"qty":0.00030785},{"price":10681644,"qty":0.24471074}],"checksum":3862281539,"timestamp":"2024-06-01T18:06:35.818064Z"}]}
{"channel":"book","type":"update","data":[{"symbol":"BTC/JPY","bids":[],"asks":[{"price":10681645,"qty":0.00000000},{"price":10697794,"qty":0.00030785}],"checksum":129173248,"timestamp":"2024-06-01T18:06:35.849213Z"}]}
{"channel":"book","type":"update","data":[{"symbol":"BTC/JPY","bids":[],"asks":[{"price":10681643,"qty":0.01129070}],"checksum":2711995740,"timestamp":"2024-06-01T18:06:35.849233Z"}]}
{"channel":"book","type":"update","data":[{"symbol":"BTC/JPY","bids":[],"asks":[{"price":10681644,"qty":0.00000000},{"price":10697794,"qty":0.00030785},{"price":10681642,"qty":0.24483589}],"checksum":2625947162,"timestamp":"2024-06-01T18:06:35.918936Z"}]}
{"channel":"book","type":"update","data":[{"symbol":"BTC/JPY","bids":[],"asks":[{"price":10681643,"qty":0.00000000},{"price":10697794,"qty":0.00030785}],"checksum":3259522481,"timestamp":"2024-06-01T18:06:35.939299Z"}]}
{"channel":"book","type":"update","data":[{"symbol":"BTC/JPY","bids":[],"asks":[{"price":10681641,"qty":0.01129070}],"checksum":1357097295,"timestamp":"2024-06-01T18:06:35.939404Z"}]}
{"channel":"book","type":"update","data":[{"symbol":"BTC/JPY","bids":[],"asks":[{"price":10681642,"qty":0.00000000},{"price":10697794,"qty":0.00030785},{"price":10681640,"qty":0.24472847}],"checksum":785743780,"timestamp":"2024-06-01T18:06:35.987015Z"}]}
{"channel":"book","type":"update","data":[{"symbol":"BTC/JPY","bids":[],"asks":[{"price":10681641,"qty":0.00000000},{"price":10697794,"qty":0.00030785}],"checksum":644727033,"timestamp":"2024-06-01T18:06:36.021444Z"}]}
{"channel":"book","type":"update","data":[{"symbol":"BTC/JPY","bids":[],"asks":[{"price":10681639,"qty":0.01129070}],"checksum":2393700264,"timestamp":"2024-06-01T18:06:36.021482Z"}]}
{"channel":"book","type":"update","data":[{"symbol":"BTC/JPY","bids":[],"asks":[{"price":10681640,"qty":0.00000000},{"price":10697794,"qty":0.00030785},{"price":10681638,"qty":0.24497440}],"checksum":4023659625,"timestamp":"2024-06-01T18:06:36.068167Z"}]}
{"channel":"book","type":"update","data":[{"symbol":"BTC/JPY","bids":[],"asks":[{"price":10681639,"qty":0.00000000},{"price":10697794,"qty":0.00030785}],"checksum":539694538,"timestamp":"2024-06-01T18:06:36.091809Z"}]}
{"channel":"book","type":"update","data":[{"symbol":"BTC/JPY","bids":[],"asks":[{"price":10681637,"qty":0.01129070}],"checksum":1867141333,"timestamp":"2024-06-01T18:06:36.091853Z"}]}
{"channel":"book","type":"update","data":[{"symbol":"BTC/JPY","bids":[],"asks":[{"price":10681638,"qty":0.00000000},{"price":10697794,"qty":0.00030785},{"price":10681636,"qty":0.24486506}],"checksum":652453788,"timestamp":"2024-06-01T18:06:36.144721Z"}]}
{"channel":"book","type":"update","data":[{"symbol":"BTC/JPY","bids":[],"asks":[{"price":10681637,"qty":0.00000000},{"price":10697794,"qty":0.00030785}],"checksum":1874830165,"timestamp":"2024-06-01T18:06:36.150085Z"}]}
{"channel":"book","type":"update","data":[{"symbol":"BTC/JPY","bids":[],"asks":[{"price":10681635,"qty":0.01129070}],"checksum":3151407369,"timestamp":"2024-06-01T18:06:36.150387Z"}]}
{"channel":"book","type":"update","data":[{"symbol":"BTC/JPY","bids":[],"asks":[{"price":10681636,"qty":0.00000000},{"price":10697794,"qty":0.00030785},{"price":10681634,"qty":0.24498304}],"checksum":3337186426,"timestamp":"2024-06-01T18:06:36.198054Z"}]}
{"channel":"book","type":"update","data":[{"symbol":"BTC/JPY","bids":[],"asks":[{"price":10681635,"qty":0.00000000},{"price":10697794,"qty":0.00030785}],"checksum":417949808,"timestamp":"2024-06-01T18:06:36.211090Z"}]}
{"channel":"book","type":"update","data":[{"symbol":"BTC/JPY","bids":[],"asks":[{"price":10681633,"qty":0.01129070}],"checksum":209256763,"timestamp":"2024-06-01T18:06:36.211184Z"}]}
{"channel":"book","type":"update","data":[{"symbol":"BTC/JPY","bids":[],"asks":[{"price":10681634,"qty":0.00000000},{"price":10697794,"qty":0.00030785},{"price":10681632,"qty":0.23867408}],"checksum":110053399,"timestamp":"2024-06-01T18:06:36.274634Z"}]}
{"channel":"book","type":"update","data":[{"symbol":"BTC/JPY","bids":[],"asks":[{"price":10681631,"qty":0.01129070}],"checksum":2182953244,"timestamp":"2024-06-01T18:06:36.286300Z"}]}
{"channel":"book","type":"update","data":[{"symbol":"BTC/JPY","bids":[],"asks":[{"price":10681633,"qty":0.00000000},{"price":10693447,"qty":1.21099321}],"checksum":2367346755,"timestamp":"2024-06-01T18:06:36.286344Z"}]}
