{"channel":"book","type":"snapshot","data":[{"symbol":"BTC/GBP","bids":[{"price":53155.9,"qty":0.01008016},{"price":53150.0,"qty":0.01836312},{"price":53113.4,"qty":0.00097300},{"price":53110.5,"qty":0.39829456},{"price":53109.5,"qty":0.36930158},{"price":53105.7,"qty":0.36932791},{"price":53105.4,"qty":0.34522384},{"price":53104.7,"qty":0.36933494},{"price":53100.3,"qty":0.00135200},{"price":53100.0,"qty":0.04239626}],"asks":[{"price":53156.0,"qty":3.37960186},{"price":53158.3,"qty":0.00097300},{"price":53159.3,"qty":0.01526000},{"price":53160.4,"qty":0.00032928},{"price":53161.6,"qty":0.36894054},{"price":53166.9,"qty":0.07381000},{"price":53168.9,"qty":0.01464000},{"price":53171.6,"qty":0.01540367},{"price":53175.5,"qty":0.36884278},{"price":53178.5,"qty":0.01862000}],"checksum":3033935111}]}
{"channel":"book","type":"update","data":[{"symbol":"BTC/GBP","bids":[{"price":53104.7,"qty":0.00000000},{"price":53092.4,"qty":0.36942068}],"asks":[],"checksum":2455571265,"timestamp":"2024-06-01T18:06:30.690522Z"}]}
{"channel":"book","type":"update","data":[{"symbol":"BTC/GBP","bids":[{"price":53110.5,"qty":0.02900000}],"asks":[],"checksum":2766837003,"timestamp":"2024-06-01T18:06:30.727643Z"}]}
{"channel":"book","type":"update","data":[{"symbol":"BTC/GBP","bids":[{"price":53092.4,"qty":0.00000000},{"price":53071.1,"qty":0.01747000}],"asks":[],"checksum":127847650,"timestamp":"2024-06-01T18:06:30.754979Z"}]}
{"channel":"book","type":"update","data":[{"symbol":"BTC/GBP","bids":[{"price":53109.5,"qty":0.00000000},{"price":53070.4,"qty":0.36957266}],"asks":[],"checksum":337717029,"timestamp":"2024-06-01T18:06:30.755123Z"}]}
{"channel":"book","type":"update","data":[{"symbol":"BTC/GBP","bids":[{"price":53110.5,"qty":0.00000000},{"price":53066.7,"qty":0.01540367}],"asks":[],"checksum":2342774131,"timestamp":"2024-06-01T18:06:30.763260Z"}]}
{"channel":"book","type":"update","data":[{"symbol":"BTC/GBP","bids":[{"price":53106.7,"qty":0.02900000}],"asks":[],"checksum":3679775513,"timestamp":"2024-06-01T18:06:30.763272Z"}]}
{"channel":"book","type":"update","data":[{"symbol":"BTC/GBP","bids":[{"price":53085.6,"qty":0.36946740}],"asks":[],"checksum":1065790816,"timestamp":"2024-06-01T18:06:30.771645Z"}]}
{"channel":"book","type":"update","data":[{"symbol":"BTC/GBP","bids":[{"price":53107.2,"qty":0.36931715}],"asks":[],"checksum":2633471507,"timestamp":"2024-06-01T18:06:30.771715Z"}]}
{"channel":"book","type":"update","data":[{"symbol":"BTC/GBP","bids":[{"price":53101.5,"qty":0.36935674}],"asks":[],"checksum":3821629664,"timestamp":"2024-06-01T18:06:30.771797Z"}]}
{"channel":"book","type":"update","data":[{"symbol":"BTC/GBP","bids":[{"price":53106.7,"qty":0.00000000},{"price":53085.6,"qty":0.36946740}],"asks":[],"checksum":3316128067,"timestamp":"2024-06-01T18:06:30.775832Z"}]}
{"channel":"book","type":"update","data":[{"symbol":"BTC/GBP","bids":[{"price":53114.4,"qty":0.02900000}],"asks":[],"checksum":36440797,"timestamp":"2024-06-01T18:06:30.776508Z"}]}
{"channel":"book","type":"update","data":[{"symbol":"BTC/GBP","bids":[],"asks":[{"price":53178.4,"qty":0.01541670}],"checksum":120363276,"timestamp":"2024-06-01T18:06:30.802265Z"}]}
{"channel":"book","type":"update","data":[{"symbol":"BTC/GBP","bids":[{"price":53113.4,"qty":0.00000000},{"price":53085.6,"qty":0.36946740},{"price":53108.4,"qty":0.00097300}],"asks":[],"checksum":1223059108,"timestamp":"2024-06-01T18:06:30.806843Z"}]}
{"channel":"book","type":"update","data":[{"symbol":"BTC/GBP","bids":[{"price":53105.4,"qty":0.00000000},{"price":53085.6,"qty":0.36946740}],"asks":[],"checksum":4006023561,"timestamp":"2024-06-01T18:06:30.810181Z"}]}
{"channel":"book","type":"update","data":[{"symbol":"BTC/GBP","bids":[{"price":53114.4,"qty":0.00000000},{"price":53071.1,"qty":0.01747000}],"asks":[],"checksum":1346377498,"timestamp":"2024-06-01T18:06:30.810232Z"}]}
{"channel":"book","type":"update","data":[{"symbol":"BTC/GBP","bids":[{"price":53109.4,"qty":0.02900000}],"asks":[],"checksum":757586362,"timestamp":"2024-06-01T18:06:30.810588Z"}]}
{"channel":"book","type":"update","data":[{"symbol":"BTC/GBP","bids":[{"price":53100.6,"qty":0.34525504}],"asks":[],"checksum":1745850795,"timestamp":"2024-06-01T18:06:30.814152Z"}]}
{"channel":"book","type":"update","data":[{"symbol":"BTC/GBP","bids":[],"asks":[{"price":53178.4,"qty":0.00000000},{"price":53178.5,"qty":0.01862000}],"checksum":1829700218,"timestamp":"2024-06-01T18:06:32.590839Z"}]}
{"channel":"book","type":"update","data":[{"symbol":"BTC/GBP","bids":[{"price":53108.4,"qty":0.00000000},{"price":53098.9,"qty":0.36937501},{"price":53112.6,"qty":0.00097300}],"asks":[],"checksum":412948199,"timestamp":"2024-06-01T18:06:33.339824Z"}]}
{"channel":"book","type":"update","data":[{"symbol":"BTC/GBP","bids":[],"asks":[{"price":53166.9,"qty":0.00000000},{"price":53186.8,"qty":0.14370791},{"price":53156.0,"qty":3.45341186}],"checksum":972135954,"timestamp":"2024-06-01T18:06:34.303473Z"}]}
{"channel":"book","type":"update","data":[{"symbol":"BTC/GBP","bids":[{"price":53107.2,"qty":0.00000000},{"price":53085.6,"qty":0.36946740}],"asks":[],"checksum":1278218082,"timestamp":"2024-06-01T18:06:34.321877Z"}]}
{"channel":"book","type":"update","data":[{"symbol":"BTC/GBP","bids":[],"asks":[{"price":53168.8,"qty":0.51434826}],"checksum":247205080,"timestamp":"2024-06-01T18:06:34.322413Z"}]}
{"channel":"book","type":"update","data":[{"symbol":"BTC/GBP","bids":[{"price":53105.7,"qty":0.00000000},{"price":53071.1,"qty":0.01747000}],"asks":[],"checksum":1145658181,"timestamp":"2024-06-01T18:06:34.328338Z"}]}
{"channel":"book","type":"update","data":[{"symbol":"BTC/GBP","bids":[],"asks":[{"price":53161.6,"qty":0.00000000},{"price":53186.8,"qty":0.14370791}],"checksum":4242606276,"timestamp":"2024-06-01T18:06:34.328356Z"}]}
{"channel":"book","type":"update","data":[{"symbol":"BTC/GBP","bids":[{"price":53109.4,"qty":0.00000000},{"price":53070.4,"qty":0.36957266}],"asks":[],"checksum":2051427390,"timestamp":"2024-06-01T18:06:34.331316Z"}]}
{"channel":"book","type":"update","data":[{"symbol":"BTC/GBP","bids":[{"price":53102.6,"qty":0.02900000}],"asks":[],"checksum":1747865260,"timestamp":"2024-06-01T18:06:34.331827Z"}]}
{"channel":"book","type":"update","data":[{"symbol":"BTC/GBP","bids":[],"asks":[{"price":53156.0,"qty":3.82239059}],"checksum":662730090,"timestamp":"2024-06-01T18:06:34.333216Z"}]}
{"channel":"book","type":"update","data":[{"symbol":"BTC/GBP","bids":[{"price":53104.8,"qty":0.36933441}],"asks":[],"checksum":2084565166,"timestamp":"2024-06-01T18:06:34.333237Z"}]}
{"channel":"book","type":"update","data":[{"symbol":"BTC/GBP","bids":[{"price":53098.8,"qty":0.36937558}],"asks":[],"checksum":2656413988,"timestamp":"2024-06-01T18:06:34.333401Z"}]}
{"channel":"book","type":"update","data":[{"symbol":"BTC/GBP","bids":[{"price":53102.6,"qty":0.00000000},{"price":53085.6,"qty":0.36946740}],"asks":[],"checksum":2432450419,"timestamp":"2024-06-01T18:06:34.336573Z"}]}
{"channel":"book","type":"update","data":[{"symbol":"BTC/GBP","bids":[{"price":53113.7,"qty":0.02900000}],"asks":[],"checksum":3344021133,"timestamp":"2024-06-01T18:06:34.336890Z"}]}
{"channel":"book","type":"update","data":[{"symbol":"BTC/GBP","bids":[{"price":53112.6,"qty":0.00000000},{"price":53085.6,"qty":0.36946740},{"price":53107.4,"qty":0.00097300}],"asks":[],"checksum":4031237008,"timestamp":"2024-06-01T18:06:34.441095Z"}]}
{"channel":"book","type":"update","data":[{"symbol":"BTC/GBP","bids":[{"price":53113.7,"qty":0.00000000},{"price":53085.6,"qty":0.36946740}],"asks":[],"checksum":1578662205,"timestamp":"2024-06-01T18:06:34.443821Z"}]}
{"channel":"book","type":"update","data":[{"symbol":"BTC/GBP","bids":[{"price":53108.5,"qty":0.02900000}],"asks":[],"checksum":1220649625,"timestamp":"2024-06-01T18:06:34.444021Z"}]}
{"channel":"book","type":"update","data":[{"symbol":"BTC/GBP","bids":[{"price":53100.6,"qty":0.00000000},{"price":53085.6,"qty":0.36946740}],"asks":[],"checksum":1843260043,"timestamp":"2024-06-01T18:06:34.452418Z"}]}
{"channel":"book","type":"update","data":[{"symbol":"BTC/GBP","bids":[{"price":53096.9,"qty":0.34527910}],"asks":[],"checksum":949345089,"timestamp":"2024-06-01T18:06:34.457792Z"}]}
{"channel":"book","type":"update","data":[{"symbol":"BTC/GBP","bids":[],"asks":[{"price":53175.4,"qty":0.01541670}],"checksum":3840773803,"timestamp":"2024-06-01T18:06:37.778064Z"}]}
{"channel":"book","type":"update","data":[{"symbol":"BTC/GBP","bids":[],"asks":[{"price":53175.4,"qty":0.00000000},{"price":53186.8,"qty":0.14370791}],"checksum":949345089,"timestamp":"2024-06-01T18:06:38.601874Z"}]}
{"channel":"book","type":"update","data":[{"symbol":"BTC/GBP","bids":[],"asks":[{"price":53175.4,"qty":0.01541670}],"checksum":3840773803,"timestamp":"2024-06-01T18:06:38.846130Z"}]}
{"channel":"book","type":"update","data":[{"symbol":"BTC/GBP","bids":[{"price":53108.6,"qty":0.00812515}],"asks":[],"checksum":305554376,"timestamp":"2024-06-01T18:06:39.137065Z"}]}
{"channel":"book","type":"update","data":[{"symbol":"BTC/GBP","bids":[],"asks":[{"price":53175.4,"qty":0.00000000},{"price":53186.8,"qty":0.14370791}],"checksum":2608400160,"timestamp":"2024-06-01T18:06:39.615573Z"}]}
{"channel":"book","type":"update","data":[{"symbol":"BTC/GBP","bids":[],"asks":[{"price":53168.8,"qty":0.00000000},{"price":53187.1,"qty":0.16769151}],"checksum":791510004,"timestamp":"2024-06-01T18:06:39.985113Z"}]}
{"channel":"book","type":"update","data":[{"symbol":"BTC/GBP","bids":[],"asks":[{"price":53168.7,"qty":0.51434826}],"checksum":3253035659,"timestamp":"2024-06-01T18:06:39.988200Z"}]}
{"channel":"book","type":"update","data":[{"symbol":"BTC/GBP","bids":[],"asks":[{"price":53186.7,"qty":0.01541670}],"checksum":1312132516,"timestamp":"2024-06-01T18:06:40.015351Z"}]}
{"channel":"book","type":"update","data":[{"symbol":"BTC/GBP","bids":[],"asks":[{"price":53186.6,"qty":0.16335834}],"checksum":2261622357,"timestamp":"2024-06-01T18:06:40.073541Z"}]}
{"channel":"book","type":"update","data":[{"symbol":"BTC/GBP","bids":[{"price":53108.6,"qty":0.00000000},{"price":53096.9,"qty":0.34527910}],"asks":[],"checksum":3809370278,"timestamp":"2024-06-01T18:06:40.662783Z"}]}
{"channel":"book","type":"update","data":[{"symbol":"BTC/GBP","bids":[{"price":53108.6,"qty":0.00812516}],"asks":[],"checksum":3068394246,"timestamp":"2024-06-01T18:06:42.195230Z"}]}
{"channel":"book","type":"update","data":[{"symbol":"BTC/GBP","bids":[],"asks":[{"price":53175.4,"qty":0.01541670}],"checksum":3148002917,"timestamp":"2024-06-01T18:06:45.748314Z"}]}
{"channel":"book","type":"update","data":[{"symbol":"BTC/GBP","bids":[],"asks":[{"price":53168.7,"qty":0.00000000},{"price":53186.6,"qty":0.16335834}],"checksum":1926741667,"timestamp":"2024-06-01T18:06:45.868840Z"}]}
{"channel":"book","type":"update","data":[{"symbol":"BTC/GBP","bids":[],"asks":[{"price":53168.6,"qty":0.51434826}],"checksum":3919576737,"timestamp":"2024-06-01T18:06:45.871860Z"}]}
{"channel":"book","type":"update","data":[{"symbol":"BTC/GBP","bids":[],"asks":[{"price":53175.4,"qty":0.00000000},{"price":53186.6,"qty":0.16335834}],"checksum":716751079,"timestamp":"2024-06-01T18:06:47.024798Z"}]}
{"channel":"book","type":"update","data":[{"symbol":"BTC/GBP","bids":[],"asks":[{"price":53186.6,"qty":0.00000000},{"price":53187.1,"qty":0.16769151},{"price":53187.0,"qty":0.16288247}],"checksum":18302070,"timestamp":"2024-06-01T18:06:48.127360Z"}]}
{"channel":"book","type":"update","data":[{"symbol":"BTC/GBP","bids":[],"asks":[{"price":53187.0,"qty":0.00000000},{"price":53187.1,"qty":0.16769151},{"price":53186.5,"qty":0.16239220}],"checksum":2669993500,"timestamp":"2024-06-01T18:06:48.172922Z"}]}
{"channel":"book","type":"update","data":[{"symbol":"BTC/GBP","bids":[],"asks":[{"price":53175.4,"qty":0.01541670}],"checksum":3919576737,"timestamp":"2024-06-01T18:06:48.214469Z"}]}
{"channel":"book","type":"update","data":[{"symbol":"BTC/GBP","bids":[],"asks":[{"price":53168.6,"qty":0.00000000},{"price":53186.5,"qty":0.16239220}],"checksum":3343622232,"timestamp":"2024-06-01T18:06:51.752959Z"}]}
{"channel":"book","type":"update","data":[{"symbol":"BTC/GBP","bids":[],"asks":[{"price":53168.8,"qty":0.51434826}],"checksum":571999899,"timestamp":"2024-06-01T18:06:51.756074Z"}]}
{"channel":"book","type":"update","data":[{"symbol":"BTC/GBP","bids":[],"asks":[{"price":53175.4,"qty":0.00000000},{"price":53186.5,"qty":0.16239220}],"checksum":1508081750,"timestamp":"2024-06-01T18:06:52.804670Z"}]}
{"channel":"book","type":"update","data":[{"symbol":"BTC/GBP","bids":[],"asks":[{"price":53171.5,"qty":0.01541670}],"checksum":2060483905,"timestamp":"2024-06-01T18:06:52.862036Z"}]}
{"channel":"book","type":"update","data":[{"symbol":"BTC/GBP","bids":[],"asks":[{"price":53171.5,"qty":0.00000000},{"price":53186.5,"qty":0.16239220}],"checksum":1508081750,"timestamp":"2024-06-01T18:06:53.077030Z"}]}
{"channel":"book","type":"update","data":[{"symbol":"BTC/GBP","bids":[],"asks":[{"price":53175.4,"qty":0.01541670}],"checksum":571999899,"timestamp":"2024-06-01T18:06:53.610566Z"}]}
{"channel":"book","type":"update","data":[{"symbol":"BTC/GBP","bids":[{"price":53107.4,"qty":0.00000000},{"price":53097.0,"qty":0.32902270},{"price":53100.9,"qty":0.00097400}],"asks":[],"checksum":2788593681,"timestamp":"2024-06-01T18:06:54.374485Z"}]}
{"channel":"book","type":"update","data":[{"symbol":"BTC/GBP","bids":[{"price":53108.6,"qty":0.00000000},{"price":53097.0,"qty":0.32902270}],"asks":[],"checksum":2004576808,"timestamp":"2024-06-01T18:06:54.484285Z"}]}
{"channel":"book","type":"update","data":[{"symbol":"BTC/GBP","bids":[{"price":53104.8,"qty":0.00000000},{"price":53096.7,"qty":0.36939036}],"asks":[],"checksum":1215911071,"timestamp":"2024-06-01T18:06:55.651695Z"}]}
{"channel":"book","type":"update","data":[{"symbol":"BTC/GBP","bids":[{"price":53108.5,"qty":0.00000000},{"price":53085.6,"qty":0.36946740}],"asks":[],"checksum":3229572008,"timestamp":"2024-06-01T18:06:55.654494Z"}]}
{"channel":"book","type":"update","data":[{"symbol":"BTC/GBP","bids":[{"price":53102.6,"qty":0.02900000}],"asks":[],"checksum":3175312761,"timestamp":"2024-06-01T18:06:55.654586Z"}]}
{"channel":"book","type":"update","data":[{"symbol":"BTC/GBP","bids":[{"price":53102.8,"qty":0.36934796}],"asks":[],"checksum":3349555742,"timestamp":"2024-06-01T18:06:55.655286Z"}]}
{"channel":"book","type":"update","data":[{"symbol":"BTC/GBP","bids":[{"price":53103.9,"qty":0.02900000}],"asks":[],"checksum":1917291818,"timestamp":"2024-06-01T18:06:55.657830Z"}]}
{"channel":"book","type":"update","data":[{"symbol":"BTC/GBP","bids":[{"price":53102.6,"qty":0.00000000},{"price":53097.0,"qty":0.32902270}],"asks":[],"checksum":2922932620,"timestamp":"2024-06-01T18:06:55.657844Z"}]}
{"channel":"book","type":"update","data":[{"symbol":"BTC/GBP","bids":[{"price":53104.0,"qty":0.00812504}],"asks":[],"checksum":2908895862,"timestamp":"2024-06-01T18:06:56.173462Z"}]}
{"channel":"book","type":"update","data":[{"symbol":"BTC/GBP","bids":[{"price":53104.0,"qty":0.00000000},{"price":53097.0,"qty":0.32902270}],"asks":[],"checksum":2922932620,"timestamp":"2024-06-01T18:06:56.279307Z"}]}
{"channel":"book","type":"update","data":[{"symbol":"BTC/GBP","bids":[{"price":53104.0,"qty":0.00812508}],"asks":[],"checksum":1843113786,"timestamp":"2024-06-01T18:06:56.331317Z"}]}
{"channel":"book","type":"update","data":[{"symbol":"BTC/GBP","bids":[],"asks":[{"price":53175.4,"qty":0.00000000},{"price":53186.5,"qty":0.16239220}],"checksum":371206647,"timestamp":"2024-06-01T18:06:56.874048Z"}]}
{"channel":"book","type":"update","data":[{"symbol":"BTC/GBP","bids":[],"asks":[{"price":53171.5,"qty":0.01541670}],"checksum":890492128,"timestamp":"2024-06-01T18:06:56.905626Z"}]}
{"channel":"book","type":"update","data":[{"symbol":"BTC/GBP","bids":[{"price":53100.9,"qty":0.00000000},{"price":53097.0,"qty":0.32902270},{"price":53103.5,"qty":0.00097300}],"asks":[],"checksum":1825586659,"timestamp":"2024-06-01T18:06:57.081995Z"}]}
{"channel":"book","type":"update","data":[{"symbol":"BTC/GBP","bids":[],"asks":[{"price":53168.8,"qty":0.00000000},{"price":53186.5,"qty":0.16239220}],"checksum":1860980662,"timestamp":"2024-06-01T18:06:57.637485Z"}]}
{"channel":"book","type":"update","data":[{"symbol":"BTC/GBP","bids":[],"asks":[{"price":53168.7,"qty":0.51434826}],"checksum":4117400861,"timestamp":"2024-06-01T18:06:57.640739Z"}]}
{"channel":"book","type":"update","data":[{"symbol":"BTC/GBP","bids":[],"asks":[{"price":53171.5,"qty":0.00000000},{"price":53186.5,"qty":0.16239220}],"checksum":360686943,"timestamp":"2024-06-01T18:06:57.864312Z"}]}
{"channel":"book","type":"update","data":[{"symbol":"BTC/GBP","bids":[{"price":53104.0,"qty":0.00000000},{"price":53097.0,"qty":0.32902270}],"asks":[],"checksum":3577220659,"timestamp":"2024-06-01T18:06:58.489688Z"}]}
{"channel":"book","type":"update","data":[{"symbol":"BTC/GBP","bids":[{"price":53104.0,"qty":0.00812498}],"asks":[],"checksum":3278373783,"timestamp":"2024-06-01T18:06:58.602723Z"}]}
{"channel":"book","type":"update","data":[{"symbol":"BTC/GBP","bids":[{"price":53101.5,"qty":0.00000000},{"price":53097.0,"qty":0.32902270}],"asks":[],"checksum":3716949230,"timestamp":"2024-06-01T18:06:58.658614Z"}]}
{"channel":"book","type":"update","data":[{"symbol":"BTC/GBP","bids":[{"price":53103.7,"qty":0.36934179}],"asks":[],"checksum":2142144529,"timestamp":"2024-06-01T18:06:58.662183Z"}]}
{"channel":"book","type":"update","data":[{"symbol":"BTC/GBP","bids":[],"asks":[{"price":53156.0,"qty":3.77548407}],"checksum":3414526607,"timestamp":"2024-06-01T18:06:59.362063Z"}]}
{"channel":"book","type":"update","data":[{"symbol":"BTC/GBP","bids":[],"asks":[{"price":53156.0,"qty":3.82239059}],"checksum":2142144529,"timestamp":"2024-06-01T18:06:59.373383Z"}]}
{"channel":"book","type":"update","data":[{"symbol":"BTC/GBP","bids":[{"price":53104.0,"qty":0.00000000},{"price":53097.0,"qty":0.32902270}],"asks":[],"checksum":52601191,"timestamp":"2024-06-01T18:07:00.295681Z"}]}
{"channel":"book","type":"update","data":[{"symbol":"BTC/GBP","bids":[{"price":53100.3,"qty":0.00000000},{"price":53096.7,"qty":0.36939036}],"asks":[],"checksum":306116780,"timestamp":"2024-06-01T18:07:00.962864Z"}]}
{"channel":"book","type":"update","data":[{"symbol":"BTC/GBP","bids":[],"asks":[{"price":53171.6,"qty":0.00000000},{"price":53187.1,"qty":0.16769151}],"checksum":1890527082,"timestamp":"2024-06-01T18:07:02.482510Z"}]}
{"channel":"book","type":"update","data":[{"symbol":"BTC/GBP","bids":[],"asks":[{"price":53159.8,"qty":0.01540688}],"checksum":1409573006,"timestamp":"2024-06-01T18:07:02.813474Z"}]}
{"channel":"book","type":"update","data":[{"symbol":"BTC/GBP","bids":[{"price":53104.0,"qty":0.00812511}],"asks":[],"checksum":52059714,"timestamp":"2024-06-01T18:07:03.390053Z"}]}
{"channel":"book","type":"update","data":[{"symbol":"BTC/GBP","bids":[],"asks":[{"price":53175.4,"qty":0.01541670}],"checksum":2868709881,"timestamp":"2024-06-01T18:07:03.426308Z"}]}
{"channel":"book","type":"update","data":[{"symbol":"BTC/GBP","bids":[{"price":53098.8,"qty":0.00000000},{"price":53096.7,"qty":0.36939036}],"asks":[],"checksum":360274982,"timestamp":"2024-06-01T18:07:03.442162Z"}]}
{"channel":"book","type":"update","data":[{"symbol":"BTC/GBP","bids":[{"price":53104.8,"qty":0.36933441}],"asks":[],"checksum":1852110312,"timestamp":"2024-06-01T18:07:03.446029Z"}]}
{"channel":"book","type":"update","data":[{"symbol":"BTC/GBP","bids":[{"price":53103.9,"qty":0.00000000},{"price":53096.7,"qty":0.36939036}],"asks":[],"checksum":309968247,"timestamp":"2024-06-01T18:07:03.448612Z"}]}
{"channel":"book","type":"update","data":[{"symbol":"BTC/GBP","bids":[{"price":53105.9,"qty":0.02900000}],"asks":[],"checksum":874168966,"timestamp":"2024-06-01T18:07:03.448980Z"}]}
{"channel":"book","type":"update","data":[{"symbol":"BTC/GBP","bids":[{"price":53104.0,"qty":0.00000000},{"price":53096.7,"qty":0.36939036}],"asks":[],"checksum":3747711396,"timestamp":"2024-06-01T18:07:03.450143Z"}]}
{"channel":"book","type":"update","data":[{"symbol":"BTC/GBP","bids":[{"price":53104.9,"qty":0.00812487}],"asks":[],"checksum":3188861505,"timestamp":"2024-06-01T18:07:03.450222Z"}]}
{"channel":"book","type":"update","data":[{"symbol":"BTC/GBP","bids":[{"price":53104.9,"qty":0.00000000},{"price":53096.7,"qty":0.36939036}],"asks":[],"checksum":3747711396,"timestamp":"2024-06-01T18:07:03.453715Z"}]}
{"channel":"book","type":"update","data":[{"symbol":"BTC/GBP","bids":[],"asks":[{"price":53168.7,"qty":0.00000000},{"price":53186.5,"qty":0.16239220}],"checksum":4125368954,"timestamp":"2024-06-01T18:07:03.521360Z"}]}
{"channel":"book","type":"update","data":[{"symbol":"BTC/GBP","bids":[],"asks":[{"price":53168.6,"qty":0.51434826}],"checksum":4122948415,"timestamp":"2024-06-01T18:07:03.524143Z"}]}
{"channel":"book","type":"update","data":[{"symbol":"BTC/GBP","bids":[{"price":53104.8,"qty":0.00000000},{"price":53086.1,"qty":0.00135200}],"asks":[],"checksum":2768489151,"timestamp":"2024-06-01T18:07:03.697339Z"}]}
{"channel":"book","type":"update","data":[{"symbol":"BTC/GBP","bids":[{"price":53100.3,"qty":0.36936512}],"asks":[],"checksum":1345087518,"timestamp":"2024-06-01T18:07:03.701622Z"}]}
{"channel":"book","type":"update","data":[{"symbol":"BTC/GBP","bids":[{"price":53106.0,"qty":0.00812486}],"asks":[],"checksum":3342514730,"timestamp":"2024-06-01T18:07:04.462095Z"}]}
{"channel":"book","type":"update","data":[{"symbol":"BTC/GBP","bids":[{"price":53097.0,"qty":0.00000000},{"price":53096.7,"qty":0.36939036}],"asks":[],"checksum":2801586496,"timestamp":"2024-06-01T18:07:04.535002Z"}]}
{"channel":"book","type":"update","data":[{"symbol":"BTC/GBP","bids":[{"price":53097.1,"qty":0.32902208}],"asks":[],"checksum":2447093916,"timestamp":"2024-06-01T18:07:04.539665Z"}]}
{"channel":"book","type":"update","data":[{"symbol":"BTC/GBP","bids":[{"price":53106.0,"qty":0.00000000},{"price":53096.7,"qty":0.36939036}],"asks":[],"checksum":4180653624,"timestamp":"2024-06-01T18:07:05.182746Z"}]}
{"channel":"book","type":"update","data":[{"symbol":"BTC/GBP","bids":[{"price":53106.0,"qty":0.00812490}],"asks":[],"checksum":1951785389,"timestamp":"2024-06-01T18:07:05.357333Z"}]}
{"channel":"book","type":"update","data":[{"symbol":"BTC/GBP","bids":[{"price":53102.8,"qty":0.00000000},{"price":53096.7,"qty":0.36939036}],"asks":[],"checksum":3417944009,"timestamp":"2024-06-01T18:07:05.682722Z"}]}
