{"channel":"book","type":"snapshot","data":[{"symbol":"BTC/EUR","bids":[{"price":62441.7,"qty":0.18734041},{"price":62441.6,"qty":0.37144257},{"price":62441.5,"qty":1.47656293},{"price":62440.1,"qty":1.47659406},{"price":62439.7,"qty":0.12499360},{"price":62438.4,"qty":0.00024454},{"price":62438.3,"qty":0.17000000},{"price":62437.4,"qty":0.13091661},{"price":62437.3,"qty":1.47666085},{"price":62437.2,"qty":0.00853100}],"asks":[{"price":62446.1,"qty":0.03947498},{"price":62446.2,"qty":0.11000000},{"price":62446.4,"qty":1.47644707},{"price":62449.0,"qty":1.47638672},{"price":62449.2,"qty":1.47638119},{"price":62453.5,"qty":0.22150000},{"price":62453.6,"qty":1.47627745},{"price":62456.3,"qty":0.17000000},{"price":62458.2,"qty":0.00852900},{"price":62458.8,"qty":0.00039896}],"checksum":2112362228}]}
{"channel":"book","type":"update","data":[{"symbol":"BTC/EUR","bids":[],"asks":[{"price":62458.2,"qty":0.00000000},{"price":62458.9,"qty":0.13060759},{"price":62453.8,"qty":0.00853000}],"checksum":1906475595,"timestamp":"2024-06-01T18:06:33.340852Z"}]}
{"channel":"book","type":"update","data":[{"symbol":"BTC/EUR","bids":[{"price":62437.2,"qty":0.00000000},{"price":62434.6,"qty":0.25000000},{"price":62441.8,"qty":0.00853000}],"asks":[],"checksum":3728852182,"timestamp":"2024-06-01T18:06:33.342086Z"}]}
{"channel":"book","type":"update","data":[{"symbol":"BTC/EUR","bids":[{"price":62440.2,"qty":0.40000000}],"asks":[],"checksum":1076566639,"timestamp":"2024-06-01T18:06:33.635076Z"}]}
{"channel":"book","type":"update","data":[{"symbol":"BTC/EUR","bids":[{"price":62440.2,"qty":0.00000000},{"price":62437.3,"qty":1.47666085}],"asks":[],"checksum":3728852182,"timestamp":"2024-06-01T18:06:33.642754Z"}]}
{"channel":"book","type":"update","data":[{"symbol":"BTC/EUR","bids":[{"price":62438.4,"qty":0.00000000},{"price":62434.6,"qty":0.25000000},{"price":62440.2,"qty":0.00024455}],"asks":[],"checksum":3030696515,"timestamp":"2024-06-01T18:06:33.768783Z"}]}
{"channel":"book","type":"update","data":[{"symbol":"BTC/EUR","bids":[{"price":62441.6,"qty":0.00000000},{"price":62434.6,"qty":0.25000000}],"asks":[],"checksum":4160664567,"timestamp":"2024-06-01T18:06:34.299096Z"}]}
{"channel":"book","type":"update","data":[{"symbol":"BTC/EUR","bids":[{"price":62441.7,"qty":0.00000000},{"price":62432.0,"qty":0.05906211}],"asks":[],"checksum":3267046247,"timestamp":"2024-06-01T18:06:34.299133Z"}]}
{"channel":"book","type":"update","data":[{"symbol":"BTC/EUR","bids":[],"asks":[{"price":62453.5,"qty":0.00000000},{"price":62458.9,"qty":0.13060759},{"price":62448.9,"qty":0.22150000}],"checksum":4189183226,"timestamp":"2024-06-01T18:06:34.303417Z"}]}
{"channel":"book","type":"update","data":[{"symbol":"BTC/EUR","bids":[],"asks":[{"price":62450.4,"qty":0.52796633}],"checksum":1257172417,"timestamp":"2024-06-01T18:06:34.303454Z"}]}
{"channel":"book","type":"update","data":[{"symbol":"BTC/EUR","bids":[{"price":62441.6,"qty":0.63444564}],"asks":[],"checksum":4201268890,"timestamp":"2024-06-01T18:06:34.303854Z"}]}
{"channel":"book","type":"update","data":[{"symbol":"BTC/EUR","bids":[{"price":62437.4,"qty":0.00000000},{"price":62432.0,"qty":0.05906211}],"asks":[],"checksum":1443409316,"timestamp":"2024-06-01T18:06:34.304535Z"}]}
{"channel":"book","type":"update","data":[{"symbol":"BTC/EUR","bids":[],"asks":[{"price":62449.0,"qty":0.00000000},{"price":62458.8,"qty":0.00039896}],"checksum":3871386820,"timestamp":"2024-06-01T18:06:34.312249Z"}]}
{"channel":"book","type":"update","data":[{"symbol":"BTC/EUR","bids":[{"price":62441.5,"qty":0.00000000},{"price":62431.8,"qty":1.47679128}],"asks":[],"checksum":2086997711,"timestamp":"2024-06-01T18:06:34.312263Z"}]}
{"channel":"book","type":"update","data":[{"symbol":"BTC/EUR","bids":[{"price":62435.2,"qty":1.47671056}],"asks":[],"checksum":3275073960,"timestamp":"2024-06-01T18:06:34.325787Z"}]}
{"channel":"book","type":"update","data":[{"symbol":"BTC/EUR","bids":[],"asks":[{"price":62446.4,"qty":0.00000000},{"price":62458.9,"qty":0.13060759}],"checksum":2515960821,"timestamp":"2024-06-01T18:06:34.325982Z"}]}
{"channel":"book","type":"update","data":[{"symbol":"BTC/EUR","bids":[],"asks":[{"price":62446.0,"qty":1.47645653}],"checksum":1439461974,"timestamp":"2024-06-01T18:06:34.326185Z"}]}
{"channel":"book","type":"update","data":[{"symbol":"BTC/EUR","bids":[{"price":62440.1,"qty":0.00000000},{"price":62431.8,"qty":1.47679128}],"asks":[],"checksum":1897255086,"timestamp":"2024-06-01T18:06:34.326701Z"}]}
{"channel":"book","type":"update","data":[{"symbol":"BTC/EUR","bids":[{"price":62439.7,"qty":0.00000000},{"price":62428.8,"qty":0.37663335}],"asks":[],"checksum":1020105153,"timestamp":"2024-06-01T18:06:34.328178Z"}]}
{"channel":"book","type":"update","data":[{"symbol":"BTC/EUR","bids":[{"price":62432.1,"qty":0.13257793}],"asks":[],"checksum":3136027011,"timestamp":"2024-06-01T18:06:34.330967Z"}]}
{"channel":"book","type":"update","data":[{"symbol":"BTC/EUR","bids":[],"asks":[{"price":62446.0,"qty":0.00000000},{"price":62458.9,"qty":0.13060759}],"checksum":2060519456,"timestamp":"2024-06-01T18:06:34.332058Z"}]}
{"channel":"book","type":"update","data":[{"symbol":"BTC/EUR","bids":[],"asks":[{"price":62456.3,"qty":0.00000000},{"price":62459.1,"qty":0.01000000}],"checksum":1066793890,"timestamp":"2024-06-01T18:06:34.335386Z"}]}
{"channel":"book","type":"update","data":[{"symbol":"BTC/EUR","bids":[],"asks":[{"price":62449.1,"qty":0.17000000}],"checksum":2478830529,"timestamp":"2024-06-01T18:06:34.335503Z"}]}
{"channel":"book","type":"update","data":[{"symbol":"BTC/EUR","bids":[],"asks":[{"price":62449.1,"qty":0.00000000},{"price":62459.1,"qty":0.01000000}],"checksum":1066793890,"timestamp":"2024-06-01T18:06:34.335945Z"}]}
{"channel":"book","type":"update","data":[{"symbol":"BTC/EUR","bids":[],"asks":[{"price":62448.7,"qty":0.17000000}],"checksum":3473673567,"timestamp":"2024-06-01T18:06:34.336366Z"}]}
{"channel":"book","type":"update","data":[{"symbol":"BTC/EUR","bids":[],"asks":[{"price":62444.5,"qty":1.47649423}],"checksum":137327983,"timestamp":"2024-06-01T18:06:34.337803Z"}]}
{"channel":"book","type":"update","data":[{"symbol":"BTC/EUR","bids":[{"price":62438.3,"qty":0.00000000},{"price":62429.4,"qty":1.47684731}],"asks":[],"checksum":64826883,"timestamp":"2024-06-01T18:06:34.341926Z"}]}
{"channel":"book","type":"update","data":[{"symbol":"BTC/EUR","bids":[],"asks":[{"price":62444.5,"qty":0.00000000},{"price":62458.9,"qty":0.13060759}],"checksum":633552343,"timestamp":"2024-06-01T18:06:34.346916Z"}]}
{"channel":"book","type":"update","data":[{"symbol":"BTC/EUR","bids":[],"asks":[{"price":62453.6,"qty":0.00000000},{"price":62459.1,"qty":0.01000000}],"checksum":510850586,"timestamp":"2024-06-01T18:06:34.350190Z"}]}
{"channel":"book","type":"update","data":[{"symbol":"BTC/EUR","bids":[],"asks":[{"price":62451.2,"qty":1.47633413}],"checksum":2225992433,"timestamp":"2024-06-01T18:06:34.357655Z"}]}
{"channel":"book","type":"update","data":[{"symbol":"BTC/EUR","bids":[],"asks":[{"price":62449.2,"qty":0.00000000},{"price":62459.1,"qty":0.01000000}],"checksum":2119853047,"timestamp":"2024-06-01T18:06:34.357702Z"}]}
{"channel":"book","type":"update","data":[{"symbol":"BTC/EUR","bids":[{"price":62440.2,"qty":0.00000000},{"price":62428.8,"qty":0.37663335},{"price":62438.4,"qty":0.00024456}],"asks":[],"checksum":2184196992,"timestamp":"2024-06-01T18:06:34.384011Z"}]}
{"channel":"book","type":"update","data":[{"symbol":"BTC/EUR","bids":[],"asks":[{"price":62446.5,"qty":1.47644501}],"checksum":2487371453,"timestamp":"2024-06-01T18:06:34.401351Z"}]}
{"channel":"book","type":"update","data":[{"symbol":"BTC/EUR","bids":[],"asks":[{"price":62448.7,"qty":0.00000000},{"price":62459.1,"qty":0.01000000}],"checksum":1308549861,"timestamp":"2024-06-01T18:06:34.403938Z"}]}
{"channel":"book","type":"update","data":[{"symbol":"BTC/EUR","bids":[],"asks":[{"price":62446.2,"qty":0.28000000}],"checksum":1470019838,"timestamp":"2024-06-01T18:06:34.404127Z"}]}
{"channel":"book","type":"update","data":[{"symbol":"BTC/EUR","bids":[],"asks":[{"price":62446.2,"qty":0.11000000}],"checksum":1308549861,"timestamp":"2024-06-01T18:06:34.422258Z"}]}
{"channel":"book","type":"update","data":[{"symbol":"BTC/EUR","bids":[],"asks":[{"price":62446.0,"qty":0.17000000}],"checksum":4271849746,"timestamp":"2024-06-01T18:06:34.422269Z"}]}
{"channel":"book","type":"update","data":[{"symbol":"BTC/EUR","bids":[{"price":62441.8,"qty":0.00000000},{"price":62428.8,"qty":0.37663335},{"price":62436.1,"qty":0.00853100}],"asks":[],"checksum":1494962912,"timestamp":"2024-06-01T18:06:34.442979Z"}]}
{"channel":"book","type":"update","data":[{"symbol":"BTC/EUR","bids":[{"price":62436.4,"qty":0.12500020}],"asks":[],"checksum":509746945,"timestamp":"2024-06-01T18:06:34.444823Z"}]}
{"channel":"book","type":"update","data":[{"symbol":"BTC/EUR","bids":[],"asks":[{"price":62458.9,"qty":0.00000000},{"price":62459.1,"qty":0.01000000}],"checksum":3964766158,"timestamp":"2024-06-01T18:06:34.446814Z"}]}
{"channel":"book","type":"update","data":[{"symbol":"BTC/EUR","bids":[],"asks":[{"price":62458.8,"qty":0.00000000},{"price":62460.4,"qty":1.10758816},{"price":62460.3,"qty":0.00039896}],"checksum":2208831825,"timestamp":"2024-06-01T18:06:34.456346Z"}]}
{"channel":"book","type":"update","data":[{"symbol":"BTC/EUR","bids":[],"asks":[{"price":62446.5,"qty":0.00000000},{"price":62460.4,"qty":1.10758816}],"checksum":1249732392,"timestamp":"2024-06-01T18:06:34.497550Z"}]}
{"channel":"book","type":"update","data":[{"symbol":"BTC/EUR","bids":[],"asks":[{"price":62445.9,"qty":0.03947498}],"checksum":829072061,"timestamp":"2024-06-01T18:06:34.502002Z"}]}
{"channel":"book","type":"update","data":[{"symbol":"BTC/EUR","bids":[{"price":62438.4,"qty":0.00000000},{"price":62429.4,"qty":1.47684731},{"price":62432.2,"qty":0.00024458}],"asks":[],"checksum":575109849,"timestamp":"2024-06-01T18:06:34.521834Z"}]}
{"channel":"book","type":"update","data":[{"symbol":"BTC/EUR","bids":[],"asks":[{"price":62453.8,"qty":0.00000000},{"price":62460.4,"qty":1.10758816},{"price":62447.7,"qty":0.00853000}],"checksum":1350164883,"timestamp":"2024-06-01T18:06:34.527045Z"}]}
{"channel":"book","type":"update","data":[{"symbol":"BTC/EUR","bids":[{"price":62441.6,"qty":0.00000000},{"price":62429.4,"qty":1.47684731}],"asks":[],"checksum":597026250,"timestamp":"2024-06-01T18:06:34.587072Z"}]}
{"channel":"book","type":"update","data":[{"symbol":"BTC/EUR","bids":[],"asks":[{"price":62447.6,"qty":0.13059236}],"checksum":384522652,"timestamp":"2024-06-01T18:06:34.590829Z"}]}
{"channel":"book","type":"update","data":[{"symbol":"BTC/EUR","bids":[],"asks":[{"price":62446.1,"qty":0.00000000},{"price":62460.3,"qty":0.00039896}],"checksum":478435850,"timestamp":"2024-06-01T18:06:34.595213Z"}]}
{"channel":"book","type":"update","data":[{"symbol":"BTC/EUR","bids":[],"asks":[{"price":62444.4,"qty":0.27000000}],"checksum":155441184,"timestamp":"2024-06-01T18:06:34.600658Z"}]}
{"channel":"book","type":"update","data":[{"symbol":"BTC/EUR","bids":[],"asks":[{"price":62446.2,"qty":0.00000000},{"price":62460.3,"qty":0.00039896}],"checksum":2061304789,"timestamp":"2024-06-01T18:06:34.609602Z"}]}
{"channel":"book","type":"update","data":[{"symbol":"BTC/EUR","bids":[],"asks":[{"price":62460.3,"qty":0.00000000},{"price":62460.4,"qty":1.10758816},{"price":62448.8,"qty":0.00039896}],"checksum":104105481,"timestamp":"2024-06-01T18:06:34.615874Z"}]}
{"channel":"book","type":"update","data":[{"symbol":"BTC/EUR","bids":[],"asks":[{"price":62448.8,"qty":0.00000000},{"price":62460.4,"qty":1.10758816},{"price":62450.3,"qty":0.00039896}],"checksum":2219479884,"timestamp":"2024-06-01T18:06:34.684958Z"}]}
{"channel":"book","type":"update","data":[{"symbol":"BTC/EUR","bids":[],"asks":[{"price":62444.4,"qty":0.00000000},{"price":62460.4,"qty":1.10758816}],"checksum":120565969,"timestamp":"2024-06-01T18:06:34.856472Z"}]}
{"channel":"book","type":"update","data":[{"symbol":"BTC/EUR","bids":[],"asks":[{"price":62448.9,"qty":0.00000000},{"price":62462.5,"qty":0.04523000},{"price":62447.5,"qty":0.22150000}],"checksum":2674032809,"timestamp":"2024-06-01T18:06:34.859454Z"}]}
{"channel":"book","type":"update","data":[{"symbol":"BTC/EUR","bids":[],"asks":[{"price":62442.7,"qty":1.47653482}],"checksum":659636394,"timestamp":"2024-06-01T18:06:34.942501Z"}]}
{"channel":"book","type":"update","data":[{"symbol":"BTC/EUR","bids":[],"asks":[{"price":62445.9,"qty":1.51593387}],"checksum":544184743,"timestamp":"2024-06-01T18:06:34.942529Z"}]}
{"channel":"book","type":"update","data":[{"symbol":"BTC/EUR","bids":[],"asks":[{"price":62442.6,"qty":0.03947498}],"checksum":3748204572,"timestamp":"2024-06-01T18:06:34.946796Z"}]}
{"channel":"book","type":"update","data":[{"symbol":"BTC/EUR","bids":[],"asks":[{"price":62442.5,"qty":1.47653929}],"checksum":1490354854,"timestamp":"2024-06-01T18:06:34.951626Z"}]}
{"channel":"book","type":"update","data":[{"symbol":"BTC/EUR","bids":[],"asks":[{"price":62442.6,"qty":0.00000000},{"price":62451.2,"qty":1.47633413}],"checksum":1439447421,"timestamp":"2024-06-01T18:06:35.093047Z"}]}
{"channel":"book","type":"update","data":[{"symbol":"BTC/EUR","bids":[],"asks":[{"price":62442.4,"qty":0.03947498}],"checksum":3883204165,"timestamp":"2024-06-01T18:06:35.097405Z"}]}
{"channel":"book","type":"update","data":[{"symbol":"BTC/EUR","bids":[],"asks":[{"price":62442.5,"qty":0.00000000},{"price":62451.2,"qty":1.47633413}],"checksum":714726118,"timestamp":"2024-06-01T18:06:35.102452Z"}]}
{"channel":"book","type":"update","data":[{"symbol":"BTC/EUR","bids":[],"asks":[{"price":62442.3,"qty":1.47654402}],"checksum":2255632137,"timestamp":"2024-06-01T18:06:35.106842Z"}]}
{"channel":"book","type":"update","data":[{"symbol":"BTC/EUR","bids":[{"price":62432.2,"qty":0.00000000},{"price":62429.1,"qty":0.04443074},{"price":62437.4,"qty":0.00024456}],"asks":[],"checksum":1618564946,"timestamp":"2024-06-01T18:06:35.521769Z"}]}
{"channel":"book","type":"update","data":[{"symbol":"BTC/EUR","bids":[],"asks":[{"price":62442.4,"qty":0.00000000},{"price":62451.2,"qty":1.47633413}],"checksum":3558585110,"timestamp":"2024-06-01T18:06:35.525850Z"}]}
{"channel":"book","type":"update","data":[{"symbol":"BTC/EUR","bids":[],"asks":[{"price":62450.3,"qty":0.00000000},{"price":62456.7,"qty":1.10765523},{"price":62456.6,"qty":0.00039896}],"checksum":3447980139,"timestamp":"2024-06-01T18:06:35.589519Z"}]}
{"channel":"book","type":"update","data":[{"symbol":"BTC/EUR","bids":[],"asks":[{"price":62442.2,"qty":0.03947498}],"checksum":1075619499,"timestamp":"2024-06-01T18:06:35.595134Z"}]}
{"channel":"book","type":"update","data":[{"symbol":"BTC/EUR","bids":[],"asks":[{"price":62445.9,"qty":1.47645889}],"checksum":2731142864,"timestamp":"2024-06-01T18:06:35.599661Z"}]}
{"channel":"book","type":"update","data":[{"symbol":"BTC/EUR","bids":[],"asks":[{"price":62442.3,"qty":0.00000000},{"price":62456.6,"qty":0.00039896}],"checksum":3748062214,"timestamp":"2024-06-01T18:06:35.600007Z"}]}
{"channel":"book","type":"update","data":[{"symbol":"BTC/EUR","bids":[],"asks":[{"price":62442.1,"qty":1.47654875}],"checksum":3461464638,"timestamp":"2024-06-01T18:06:35.603877Z"}]}
{"channel":"book","type":"update","data":[{"symbol":"BTC/EUR","bids":[],"asks":[{"price":62442.0,"qty":0.03947498}],"checksum":3092204703,"timestamp":"2024-06-01T18:06:36.095294Z"}]}
{"channel":"book","type":"update","data":[{"symbol":"BTC/EUR","bids":[],"asks":[{"price":62442.2,"qty":0.00000000},{"price":62451.2,"qty":1.47633413}],"checksum":4219277473,"timestamp":"2024-06-01T18:06:36.100044Z"}]}
{"channel":"book","type":"update","data":[{"symbol":"BTC/EUR","bids":[],"asks":[{"price":62442.1,"qty":0.00000000},{"price":62456.6,"qty":0.00039896}],"checksum":714485500,"timestamp":"2024-06-01T18:06:36.100276Z"}]}
{"channel":"book","type":"update","data":[{"symbol":"BTC/EUR","bids":[],"asks":[{"price":62441.9,"qty":1.47655348}],"checksum":3884626022,"timestamp":"2024-06-01T18:06:36.104331Z"}]}
{"channel":"book","type":"update","data":[{"symbol":"BTC/EUR","bids":[],"asks":[{"price":62450.3,"qty":0.00039896}],"checksum":450646300,"timestamp":"2024-06-01T18:06:36.420303Z"}]}
{"channel":"book","type":"update","data":[{"symbol":"BTC/EUR","bids":[],"asks":[{"price":62441.8,"qty":0.03947498}],"checksum":2026002849,"timestamp":"2024-06-01T18:06:36.592891Z"}]}
{"channel":"book","type":"update","data":[{"symbol":"BTC/EUR","bids":[],"asks":[{"price":62441.9,"qty":0.00000000},{"price":62450.4,"qty":0.52796633}],"checksum":1418979674,"timestamp":"2024-06-01T18:06:36.597815Z"}]}
{"channel":"book","type":"update","data":[{"symbol":"BTC/EUR","bids":[{"price":62435.3,"qty":0.40000000}],"asks":[],"checksum":3432695389,"timestamp":"2024-06-01T18:06:36.598326Z"}]}
{"channel":"book","type":"update","data":[{"symbol":"BTC/EUR","bids":[],"asks":[{"price":62441.7,"qty":1.47655820}],"checksum":3661939112,"timestamp":"2024-06-01T18:06:36.601997Z"}]}
{"channel":"book","type":"update","data":[{"symbol":"BTC/EUR","bids":[{"price":62435.3,"qty":0.00000000},{"price":62429.4,"qty":1.47684731}],"asks":[],"checksum":2572300750,"timestamp":"2024-06-01T18:06:36.635379Z"}]}
{"channel":"book","type":"update","data":[{"symbol":"BTC/EUR","bids":[],"asks":[{"price":62441.8,"qty":0.00000000},{"price":62450.4,"qty":0.52796633}],"checksum":2877672941,"timestamp":"2024-06-01T18:06:36.639403Z"}]}
{"channel":"book","type":"update","data":[{"symbol":"BTC/EUR","bids":[{"price":62437.4,"qty":0.00000000},{"price":62429.1,"qty":0.04443074},{"price":62432.2,"qty":0.00024465}],"asks":[],"checksum":2002510432,"timestamp":"2024-06-01T18:06:36.656869Z"}]}
{"channel":"book","type":"update","data":[{"symbol":"BTC/EUR","bids":[],"asks":[{"price":62441.6,"qty":0.03947498}],"checksum":2318667251,"timestamp":"2024-06-01T18:06:37.095709Z"}]}
{"channel":"book","type":"update","data":[{"symbol":"BTC/EUR","bids":[],"asks":[{"price":62442.0,"qty":0.00000000},{"price":62450.4,"qty":0.52796633}],"checksum":3437810840,"timestamp":"2024-06-01T18:06:37.100625Z"}]}
{"channel":"book","type":"update","data":[{"symbol":"BTC/EUR","bids":[],"asks":[{"price":62441.7,"qty":0.00000000},{"price":62451.2,"qty":1.47633413}],"checksum":1508177263,"timestamp":"2024-06-01T18:06:37.100885Z"}]}
{"channel":"book","type":"update","data":[{"symbol":"BTC/EUR","bids":[],"asks":[{"price":62441.5,"qty":1.47656293}],"checksum":3260915350,"timestamp":"2024-06-01T18:06:37.105365Z"}]}
{"channel":"book","type":"update","data":[{"symbol":"BTC/EUR","bids":[{"price":62432.2,"qty":0.00000000},{"price":62429.1,"qty":0.04443074},{"price":62437.4,"qty":0.00024463}],"asks":[],"checksum":4191565184,"timestamp":"2024-06-01T18:06:37.304141Z"}]}
{"channel":"book","type":"update","data":[{"symbol":"BTC/EUR","bids":[],"asks":[{"price":62441.4,"qty":0.03947498}],"checksum":1946523361,"timestamp":"2024-06-01T18:06:37.308424Z"}]}
{"channel":"book","type":"update","data":[{"symbol":"BTC/EUR","bids":[],"asks":[{"price":62441.3,"qty":0.40000000}],"checksum":759942094,"timestamp":"2024-06-01T18:06:37.593722Z"}]}
{"channel":"book","type":"update","data":[{"symbol":"BTC/EUR","bids":[],"asks":[{"price":62441.6,"qty":0.00000000},{"price":62450.3,"qty":0.00039896}],"checksum":1977784904,"timestamp":"2024-06-01T18:06:37.596271Z"}]}
{"channel":"book","type":"update","data":[{"symbol":"BTC/EUR","bids":[{"price":62437.4,"qty":0.00000000},{"price":62429.1,"qty":0.04443074},{"price":62432.2,"qty":0.00024457}],"asks":[],"checksum":1613963371,"timestamp":"2024-06-01T18:06:37.606888Z"}]}
{"channel":"book","type":"update","data":[{"symbol":"BTC/EUR","bids":[],"asks":[{"price":62441.2,"qty":0.03947498}],"checksum":597999244,"timestamp":"2024-06-01T18:06:38.107622Z"}]}
{"channel":"book","type":"update","data":[{"symbol":"BTC/EUR","bids":[],"asks":[{"price":62447.4,"qty":0.00039896}],"checksum":1987847336,"timestamp":"2024-06-01T18:06:38.170385Z"}]}
{"channel":"book","type":"update","data":[{"symbol":"BTC/EUR","bids":[],"asks":[{"price":62441.4,"qty":0.00000000},{"price":62447.7,"qty":0.00853000}],"checksum":1776451366,"timestamp":"2024-06-01T18:06:38.595747Z"}]}
{"channel":"book","type":"update","data":[{"symbol":"BTC/EUR","bids":[],"asks":[{"price":62447.4,"qty":0.00000000},{"price":62450.4,"qty":0.52796633},{"price":62450.3,"qty":0.00039896}],"checksum":3748718231,"timestamp":"2024-06-01T18:06:38.648954Z"}]}
{"channel":"book","type":"update","data":[{"symbol":"BTC/EUR","bids":[{"price":62437.4,"qty":0.16105147}],"asks":[],"checksum":190121174,"timestamp":"2024-06-01T18:06:39.344039Z"}]}
{"channel":"book","type":"update","data":[{"symbol":"BTC/EUR","bids":[{"price":62435.3,"qty":0.40000000}],"asks":[],"checksum":3394374982,"timestamp":"2024-06-01T18:06:39.635439Z"}]}
{"channel":"book","type":"update","data":[{"symbol":"BTC/EUR","bids":[{"price":62435.3,"qty":0.00000000},{"price":62431.8,"qty":1.47679128}],"asks":[],"checksum":190121174,"timestamp":"2024-06-01T18:06:39.640314Z"}]}
{"channel":"book","type":"update","data":[{"symbol":"BTC/EUR","bids":[{"price":62432.2,"qty":0.00000000},{"price":62429.4,"qty":1.47684731},{"price":62437.5,"qty":0.00024464}],"asks":[],"checksum":3771020312,"timestamp":"2024-06-01T18:06:40.836973Z"}]}
{"channel":"book","type":"update","data":[{"symbol":"BTC/EUR","bids":[{"price":62437.5,"qty":0.00000000},{"price":62429.4,"qty":1.47684731},{"price":62432.2,"qty":0.00024466}],"asks":[],"checksum":842971787,"timestamp":"2024-06-01T18:06:41.173790Z"}]}
{"channel":"book","type":"update","data":[{"symbol":"BTC/EUR","bids":[{"price":62432.2,"qty":0.00000000},{"price":62429.4,"qty":1.47684731},{"price":62437.5,"qty":0.00024460}],"asks":[],"checksum":2776916270,"timestamp":"2024-06-01T18:06:41.627097Z"}]}
{"channel":"book","type":"update","data":[{"symbol":"BTC/EUR","bids":[{"price":62437.5,"qty":0.00000000},{"price":62429.4,"qty":1.47684731},{"price":62432.2,"qty":0.00024462}],"asks":[],"checksum":4110444326,"timestamp":"2024-06-01T18:06:41.696874Z"}]}
{"channel":"book","type":"update","data":[{"symbol":"BTC/EUR","bids":[],"asks":[{"price":62447.6,"qty":0.00000000},{"price":62450.4,"qty":0.52796633}],"checksum":2790617656,"timestamp":"2024-06-01T18:06:41.742695Z"}]}
{"channel":"book","type":"update","data":[{"symbol":"BTC/EUR","bids":[],"asks":[{"price":62450.3,"qty":0.00000000},{"price":62451.2,"qty":1.47633413},{"price":62451.1,"qty":0.00039896}],"checksum":3081793401,"timestamp":"2024-06-01T18:06:41.796048Z"}]}
{"channel":"book","type":"update","data":[{"symbol":"BTC/EUR","bids":[{"price":62437.4,"qty":0.00000000},{"price":62429.4,"qty":1.47684731}],"asks":[],"checksum":630727543,"timestamp":"2024-06-01T18:06:41.817161Z"}]}
{"channel":"book","type":"update","data":[{"symbol":"BTC/EUR","bids":[{"price":62437.4,"qty":0.23995796}],"asks":[],"checksum":959662791,"timestamp":"2024-06-01T18:06:41.821775Z"}]}
{"channel":"book","type":"update","data":[{"symbol":"BTC/EUR","bids":[],"asks":[{"price":62441.5,"qty":0.00000000},{"price":62451.2,"qty":1.47633413}],"checksum":3288805782,"timestamp":"2024-06-01T18:06:41.825167Z"}]}
{"channel":"book","type":"update","data":[{"symbol":"BTC/EUR","bids":[{"price":62435.2,"qty":0.00000000},{"price":62429.4,"qty":1.47684731}],"asks":[],"checksum":1945750100,"timestamp":"2024-06-01T18:06:41.826986Z"}]}
{"channel":"book","type":"update","data":[{"symbol":"BTC/EUR","bids":[],"asks":[{"price":62447.0,"qty":1.47643440}],"checksum":1518141713,"timestamp":"2024-06-01T18:06:41.831278Z"}]}
{"channel":"book","type":"update","data":[{"symbol":"BTC/EUR","bids":[],"asks":[{"price":62451.1,"qty":0.00000000},{"price":62451.2,"qty":1.47633413}],"checksum":299222120,"timestamp":"2024-06-01T18:06:41.870057Z"}]}
{"channel":"book","type":"update","data":[{"symbol":"BTC/EUR","bids":[{"price":62432.2,"qty":0.00000000},{"price":62429.1,"qty":0.04443074},{"price":62441.1,"qty":0.00024458}],"asks":[],"checksum":3663968232,"timestamp":"2024-06-01T18:06:42.394908Z"}]}
{"channel":"book","type":"update","data":[{"symbol":"BTC/EUR","bids":[],"asks":[{"price":62451.1,"qty":0.00039896}],"checksum":2446029457,"timestamp":"2024-06-01T18:06:42.394939Z"}]}
{"channel":"book","type":"update","data":[{"symbol":"BTC/EUR","bids":[],"asks":[{"price":62451.1,"qty":0.00000000},{"price":62451.2,"qty":1.47633413}],"checksum":3663968232,"timestamp":"2024-06-01T18:06:42.463616Z"}]}
{"channel":"book","type":"update","data":[{"symbol":"BTC/EUR","bids":[],"asks":[{"price":62447.0,"qty":0.00000000},{"price":62456.4,"qty":0.00039896}],"checksum":300979785,"timestamp":"2024-06-01T18:06:44.201744Z"}]}
{"channel":"book","type":"update","data":[{"symbol":"BTC/EUR","bids":[],"asks":[{"price":62443.2,"qty":1.47652456}],"checksum":331289082,"timestamp":"2024-06-01T18:06:44.206516Z"}]}
{"channel":"book","type":"update","data":[{"symbol":"BTC/EUR","bids":[{"price":62437.4,"qty":0.00000000},{"price":62429.1,"qty":0.04443074}],"asks":[],"checksum":1081390054,"timestamp":"2024-06-01T18:06:44.279998Z"}]}
{"channel":"book","type":"update","data":[{"symbol":"BTC/EUR","bids":[{"price":62437.4,"qty":0.08214498}],"asks":[],"checksum":2017607891,"timestamp":"2024-06-01T18:06:44.285286Z"}]}
{"channel":"book","type":"update","data":[{"symbol":"BTC/EUR","bids":[{"price":62432.2,"qty":0.37146877}],"asks":[],"checksum":88864764,"timestamp":"2024-06-01T18:06:44.285344Z"}]}
{"channel":"book","type":"update","data":[{"symbol":"BTC/EUR","bids":[{"price":62437.5,"qty":1.47665753}],"asks":[],"checksum":3120171406,"timestamp":"2024-06-01T18:06:45.153359Z"}]}
{"channel":"book","type":"update","data":[{"symbol":"BTC/EUR","bids":[{"price":62437.4,"qty":0.48214498}],"asks":[],"checksum":2809558214,"timestamp":"2024-06-01T18:06:45.635483Z"}]}
{"channel":"book","type":"update","data":[{"symbol":"BTC/EUR","bids":[{"price":62432.2,"qty":0.00000000},{"price":62431.8,"qty":1.47679128}],"asks":[],"checksum":3405094504,"timestamp":"2024-06-01T18:06:46.815864Z"}]}
{"channel":"book","type":"update","data":[{"symbol":"BTC/EUR","bids":[{"price":62437.4,"qty":0.40000000}],"asks":[],"checksum":2158735933,"timestamp":"2024-06-01T18:06:46.815917Z"}]}
{"channel":"book","type":"update","data":[{"symbol":"BTC/EUR","bids":[{"price":62437.6,"qty":0.18735363}],"asks":[],"checksum":1548252683,"timestamp":"2024-06-01T18:06:46.823050Z"}]}
{"channel":"book","type":"update","data":[{"symbol":"BTC/EUR","bids":[{"price":62437.6,"qty":0.00000000},{"price":62431.8,"qty":1.47679128}],"asks":[],"checksum":2158735933,"timestamp":"2024-06-01T18:06:49.319311Z"}]}
{"channel":"book","type":"update","data":[{"symbol":"BTC/EUR","bids":[{"price":62437.6,"qty":0.34516661}],"asks":[],"checksum":1980772839,"timestamp":"2024-06-01T18:06:49.324546Z"}]}
{"channel":"book","type":"update","data":[{"symbol":"BTC/EUR","bids":[{"price":62432.2,"qty":0.39777093}],"asks":[],"checksum":1933976518,"timestamp":"2024-06-01T18:06:49.324667Z"}]}
{"channel":"book","type":"update","data":[{"symbol":"BTC/EUR","bids":[{"price":62437.6,"qty":0.00000000},{"price":62432.0,"qty":0.05906211}],"asks":[],"checksum":1918530797,"timestamp":"2024-06-01T18:06:51.809203Z"}]}
{"channel":"book","type":"update","data":[{"symbol":"BTC/EUR","bids":[{"price":62432.2,"qty":0.00000000},{"price":62431.8,"qty":1.47679128}],"asks":[],"checksum":2158735933,"timestamp":"2024-06-01T18:06:51.809343Z"}]}
{"channel":"book","type":"update","data":[{"symbol":"BTC/EUR","bids":[{"price":62437.6,"qty":0.42407310}],"asks":[],"checksum":542241208,"timestamp":"2024-06-01T18:06:51.812745Z"}]}
{"channel":"book","type":"update","data":[{"symbol":"BTC/EUR","bids":[{"price":62432.2,"qty":0.58188607}],"asks":[],"checksum":2753529019,"timestamp":"2024-06-01T18:06:51.812852Z"}]}
{"channel":"book","type":"update","data":[{"symbol":"BTC/EUR","bids":[{"price":62441.1,"qty":0.00000000},{"price":62432.0,"qty":0.05906211},{"price":62432.3,"qty":0.00024470}],"asks":[],"checksum":756768137,"timestamp":"2024-06-01T18:06:52.594732Z"}]}
{"channel":"book","type":"update","data":[{"symbol":"BTC/EUR","bids":[],"asks":[{"price":62443.2,"qty":0.00000000},{"price":62453.7,"qty":0.00039896}],"checksum":561665443,"timestamp":"2024-06-01T18:06:52.600495Z"}]}
{"channel":"book","type":"update","data":[{"symbol":"BTC/EUR","bids":[],"asks":[{"price":62441.1,"qty":1.47657239}],"checksum":3770252086,"timestamp":"2024-06-01T18:06:52.604984Z"}]}
{"channel":"book","type":"update","data":[{"symbol":"BTC/EUR","bids":[],"asks":[{"price":62441.1,"qty":1.67657239}],"checksum":3173290238,"timestamp":"2024-06-01T18:06:52.783588Z"}]}
{"channel":"book","type":"update","data":[{"symbol":"BTC/EUR","bids":[],"asks":[{"price":62441.0,"qty":0.03947498}],"checksum":3710886899,"timestamp":"2024-06-01T18:06:52.787694Z"}]}
{"channel":"book","type":"update","data":[{"symbol":"BTC/EUR","bids":[],"asks":[{"price":62441.3,"qty":0.00000000},{"price":62451.2,"qty":1.47633413}],"checksum":2745253816,"timestamp":"2024-06-01T18:06:52.848251Z"}]}
{"channel":"book","type":"update","data":[{"symbol":"BTC/EUR","bids":[],"asks":[{"price":62441.2,"qty":0.00000000},{"price":62453.6,"qty":0.00039896}],"checksum":172571408,"timestamp":"2024-06-01T18:06:52.852220Z"}]}
{"channel":"book","type":"update","data":[{"symbol":"BTC/EUR","bids":[],"asks":[{"price":62441.1,"qty":0.20000000}],"checksum":3276895072,"timestamp":"2024-06-01T18:06:52.890905Z"}]}
{"channel":"book","type":"update","data":[{"symbol":"BTC/EUR","bids":[{"price":62437.5,"qty":0.00000000},{"price":62432.0,"qty":0.05906211}],"asks":[],"checksum":3179167379,"timestamp":"2024-06-01T18:06:52.891032Z"}]}
{"channel":"book","type":"update","data":[{"symbol":"BTC/EUR","bids":[],"asks":[{"price":62451.2,"qty":2.37633413}],"checksum":1767408766,"timestamp":"2024-06-01T18:06:52.891825Z"}]}
{"channel":"book","type":"update","data":[{"symbol":"BTC/EUR","bids":[],"asks":[{"price":62447.6,"qty":1.47641923}],"checksum":2016327440,"timestamp":"2024-06-01T18:06:52.896202Z"}]}
{"channel":"book","type":"update","data":[{"symbol":"BTC/EUR","bids":[{"price":62437.7,"qty":1.47665280}],"asks":[],"checksum":690608475,"timestamp":"2024-06-01T18:06:52.896359Z"}]}
{"channel":"book","type":"update","data":[{"symbol":"BTC/EUR","bids":[],"asks":[{"price":62451.1,"qty":0.00039896}],"checksum":3741587901,"timestamp":"2024-06-01T18:06:53.069550Z"}]}
{"channel":"book","type":"update","data":[{"symbol":"BTC/EUR","bids":[{"price":62432.3,"qty":0.00000000},{"price":62432.0,"qty":0.05906211},{"price":62440.9,"qty":0.00024467}],"asks":[],"checksum":2577976761,"timestamp":"2024-06-01T18:06:53.579656Z"}]}
{"channel":"book","type":"update","data":[{"symbol":"BTC/EUR","bids":[],"asks":[{"price":62447.6,"qty":0.00000000},{"price":62451.2,"qty":2.37633413}],"checksum":3583608899,"timestamp":"2024-06-01T18:06:54.200003Z"}]}
{"channel":"book","type":"update","data":[{"symbol":"BTC/EUR","bids":[],"asks":[{"price":62443.1,"qty":1.47652709}],"checksum":2532733727,"timestamp":"2024-06-01T18:06:54.204771Z"}]}
{"channel":"book","type":"update","data":[{"symbol":"BTC/EUR","bids":[{"price":62436.4,"qty":0.00000000},{"price":62432.0,"qty":0.05906211}],"asks":[],"checksum":3527629294,"timestamp":"2024-06-01T18:06:54.250051Z"}]}
{"channel":"book","type":"update","data":[{"symbol":"BTC/EUR","bids":[{"price":62437.6,"qty":0.00000000},{"price":62431.8,"qty":1.47679128}],"asks":[],"checksum":2482547705,"timestamp":"2024-06-01T18:06:54.285979Z"}]}
{"channel":"book","type":"update","data":[{"symbol":"BTC/EUR","bids":[{"price":62432.2,"qty":0.00000000},{"price":62429.4,"qty":1.47684731}],"asks":[],"checksum":3614334145,"timestamp":"2024-06-01T18:06:54.286195Z"}]}
{"channel":"book","type":"update","data":[{"symbol":"BTC/EUR","bids":[{"price":62437.8,"qty":0.34516661}],"asks":[],"checksum":1328315786,"timestamp":"2024-06-01T18:06:54.291052Z"}]}
{"channel":"book","type":"update","data":[{"symbol":"BTC/EUR","bids":[{"price":62440.9,"qty":0.00000000},{"price":62429.4,"qty":1.47684731},{"price":62432.3,"qty":0.00024472}],"asks":[],"checksum":705215550,"timestamp":"2024-06-01T18:06:54.323767Z"}]}
{"channel":"book","type":"update","data":[{"symbol":"BTC/EUR","bids":[{"price":62436.1,"qty":0.00000000},{"price":62429.4,"qty":1.47684731}],"asks":[],"checksum":3255552349,"timestamp":"2024-06-01T18:06:54.348813Z"}]}
{"channel":"book","type":"update","data":[{"symbol":"BTC/EUR","bids":[{"price":62432.3,"qty":0.00000000},{"price":62429.3,"qty":0.00853100},{"price":62432.2,"qty":0.00024472}],"asks":[],"checksum":2461574017,"timestamp":"2024-06-01T18:06:54.377850Z"}]}
{"channel":"book","type":"update","data":[{"symbol":"BTC/EUR","bids":[{"price":62437.7,"qty":0.00000000},{"price":62429.3,"qty":0.00853100}],"asks":[],"checksum":1734074925,"timestamp":"2024-06-01T18:06:54.384532Z"}]}
{"channel":"book","type":"update","data":[{"symbol":"BTC/EUR","bids":[{"price":62437.4,"qty":0.00000000},{"price":62429.1,"qty":0.04443074}],"asks":[],"checksum":278916173,"timestamp":"2024-06-01T18:06:54.392462Z"}]}
{"channel":"book","type":"update","data":[{"symbol":"BTC/EUR","bids":[{"price":62432.2,"qty":0.00000000},{"price":62424.5,"qty":0.38868768}],"asks":[],"checksum":2190991664,"timestamp":"2024-06-01T18:06:54.432675Z"}]}
{"channel":"book","type":"update","data":[{"symbol":"BTC/EUR","bids":[{"price":62437.5,"qty":0.12499800}],"asks":[],"checksum":509899746,"timestamp":"2024-06-01T18:06:54.466136Z"}]}
{"channel":"book","type":"update","data":[{"symbol":"BTC/EUR","bids":[{"price":62434.7,"qty":0.40000000}],"asks":[],"checksum":1948860189,"timestamp":"2024-06-01T18:06:54.634965Z"}]}
{"channel":"book","type":"update","data":[{"symbol":"BTC/EUR","bids":[{"price":62440.9,"qty":0.00024468}],"asks":[],"checksum":3452337984,"timestamp":"2024-06-01T18:06:54.819715Z"}]}
{"channel":"book","type":"update","data":[{"symbol":"BTC/EUR","bids":[{"price":62434.7,"qty":0.00000000},{"price":62429.3,"qty":0.00853100}],"asks":[],"checksum":1179099487,"timestamp":"2024-06-01T18:06:54.825237Z"}]}
{"channel":"book","type":"update","data":[{"symbol":"BTC/EUR","bids":[{"price":62434.7,"qty":0.40000000}],"asks":[],"checksum":3452337984,"timestamp":"2024-06-01T18:06:55.134970Z"}]}
{"channel":"book","type":"update","data":[{"symbol":"BTC/EUR","bids":[],"asks":[{"price":62441.0,"qty":0.18447498}],"checksum":977407249,"timestamp":"2024-06-01T18:06:55.161344Z"}]}
{"channel":"book","type":"update","data":[{"symbol":"BTC/EUR","bids":[{"price":62440.9,"qty":0.00000000},{"price":62429.3,"qty":0.00853100},{"price":62437.8,"qty":0.34098340}],"asks":[],"checksum":2936535080,"timestamp":"2024-06-01T18:06:55.225642Z"}]}
{"channel":"book","type":"update","data":[{"symbol":"BTC/EUR","bids":[],"asks":[{"price":62441.1,"qty":0.00000000},{"price":62451.2,"qty":2.37633413}],"checksum":3676780677,"timestamp":"2024-06-01T18:06:55.257910Z"}]}
{"channel":"book","type":"update","data":[{"symbol":"BTC/EUR","bids":[{"price":62440.9,"qty":0.00024468}],"asks":[],"checksum":752002567,"timestamp":"2024-06-01T18:06:55.340905Z"}]}
{"channel":"book","type":"update","data":[{"symbol":"BTC/EUR","bids":[{"price":62437.3,"qty":0.00000000},{"price":62429.3,"qty":0.00853100}],"asks":[],"checksum":1797846165,"timestamp":"2024-06-01T18:06:55.649802Z"}]}
{"channel":"book","type":"update","data":[{"symbol":"BTC/EUR","bids":[{"price":62434.8,"qty":1.47671905}],"asks":[],"checksum":1459484389,"timestamp":"2024-06-01T18:06:55.653973Z"}]}
{"channel":"book","type":"update","data":[{"symbol":"BTC/EUR","bids":[{"price":62437.8,"qty":0.00000000},{"price":62429.3,"qty":0.00853100}],"asks":[],"checksum":2063559446,"timestamp":"2024-06-01T18:06:56.008214Z"}]}
{"channel":"book","type":"update","data":[{"symbol":"BTC/EUR","bids":[{"price":62434.6,"qty":0.00000000},{"price":62429.1,"qty":0.04443074}],"asks":[],"checksum":3688645976,"timestamp":"2024-06-01T18:06:56.013885Z"}]}
{"channel":"book","type":"update","data":[{"symbol":"BTC/EUR","bids":[{"price":62437.5,"qty":0.00000000},{"price":62424.5,"qty":0.38868768}],"asks":[],"checksum":2423463974,"timestamp":"2024-06-01T18:06:56.051273Z"}]}
{"channel":"book","type":"update","data":[{"symbol":"BTC/EUR","bids":[{"price":62434.9,"qty":0.12500321}],"asks":[],"checksum":2550601496,"timestamp":"2024-06-01T18:06:56.171512Z"}]}
{"channel":"book","type":"update","data":[{"symbol":"BTC/EUR","bids":[{"price":62434.7,"qty":0.00000000},{"price":62424.5,"qty":0.38868768}],"asks":[],"checksum":3431820044,"timestamp":"2024-06-01T18:06:56.176294Z"}]}
{"channel":"book","type":"update","data":[{"symbol":"BTC/EUR","bids":[{"price":62435.0,"qty":0.26623374}],"asks":[],"checksum":2610519907,"timestamp":"2024-06-01T18:06:56.786511Z"}]}
{"channel":"book","type":"update","data":[{"symbol":"BTC/EUR","bids":[{"price":62434.6,"qty":1.47672574}],"asks":[],"checksum":1971062507,"timestamp":"2024-06-01T18:06:57.152861Z"}]}
{"channel":"book","type":"update","data":[{"symbol":"BTC/EUR","bids":[{"price":62434.7,"qty":0.40000000}],"asks":[],"checksum":1858260533,"timestamp":"2024-06-01T18:06:57.634355Z"}]}
{"channel":"book","type":"update","data":[{"symbol":"BTC/EUR","bids":[{"price":62434.7,"qty":0.00000000},{"price":62429.3,"qty":0.00853100}],"asks":[],"checksum":1971062507,"timestamp":"2024-06-01T18:06:57.639173Z"}]}
{"channel":"book","type":"update","data":[{"symbol":"BTC/EUR","bids":[{"price":62434.7,"qty":0.40000000}],"asks":[],"checksum":1858260533,"timestamp":"2024-06-01T18:06:58.134471Z"}]}
{"channel":"book","type":"update","data":[{"symbol":"BTC/EUR","bids":[],"asks":[{"price":62451.1,"qty":0.00000000},{"price":62453.8,"qty":1.10776320},{"price":62450.3,"qty":0.00039925}],"checksum":3050489370,"timestamp":"2024-06-01T18:06:58.217023Z"}]}
{"channel":"book","type":"update","data":[{"symbol":"BTC/EUR","bids":[],"asks":[{"price":62441.0,"qty":0.18431720}],"checksum":1490222852,"timestamp":"2024-06-01T18:06:59.032992Z"}]}
{"channel":"book","type":"update","data":[{"symbol":"BTC/EUR","bids":[{"price":62435.1,"qty":0.25000000}],"asks":[],"checksum":1771539521,"timestamp":"2024-06-01T18:06:59.038620Z"}]}
{"channel":"book","type":"update","data":[{"symbol":"BTC/EUR","bids":[{"price":62435.0,"qty":0.00000000},{"price":62429.4,"qty":1.47684731}],"asks":[],"checksum":2804705253,"timestamp":"2024-06-01T18:06:59.231661Z"}]}
{"channel":"book","type":"update","data":[{"symbol":"BTC/EUR","bids":[{"price":62435.0,"qty":0.45032644}],"asks":[],"checksum":1521277542,"timestamp":"2024-06-01T18:06:59.236744Z"}]}
{"channel":"book","type":"update","data":[{"symbol":"BTC/EUR","bids":[{"price":62434.7,"qty":0.00000000},{"price":62429.4,"qty":1.47684731}],"asks":[],"checksum":1589747544,"timestamp":"2024-06-01T18:06:59.237108Z"}]}
{"channel":"book","type":"update","data":[{"symbol":"BTC/EUR","bids":[{"price":62435.1,"qty":0.00000000},{"price":62429.3,"qty":0.00853100}],"asks":[],"checksum":4159159761,"timestamp":"2024-06-01T18:06:59.237404Z"}]}
{"channel":"book","type":"update","data":[{"symbol":"BTC/EUR","bids":[{"price":62434.9,"qty":0.37500321}],"asks":[],"checksum":314696439,"timestamp":"2024-06-01T18:06:59.237513Z"}]}
{"channel":"book","type":"update","data":[{"symbol":"BTC/EUR","bids":[{"price":62434.6,"qty":0.00000000},{"price":62429.1,"qty":0.04443074}],"asks":[],"checksum":2244415996,"timestamp":"2024-06-01T18:06:59.604193Z"}]}
{"channel":"book","type":"update","data":[{"symbol":"BTC/EUR","bids":[{"price":62437.2,"qty":1.47666248}],"asks":[],"checksum":1264976883,"timestamp":"2024-06-01T18:06:59.608852Z"}]}
{"channel":"book","type":"update","data":[{"symbol":"BTC/EUR","bids":[{"price":62435.1,"qty":0.25000000}],"asks":[],"checksum":137398076,"timestamp":"2024-06-01T18:06:59.609402Z"}]}
{"channel":"book","type":"update","data":[{"symbol":"BTC/EUR","bids":[{"price":62435.1,"qty":0.00000000},{"price":62429.3,"qty":0.00853100}],"asks":[],"checksum":1264976883,"timestamp":"2024-06-01T18:06:59.633718Z"}]}
{"channel":"book","type":"update","data":[{"symbol":"BTC/EUR","bids":[{"price":62435.0,"qty":0.85032644}],"asks":[],"checksum":1636178676,"timestamp":"2024-06-01T18:07:00.134563Z"}]}
{"channel":"book","type":"update","data":[{"symbol":"BTC/EUR","bids":[],"asks":[{"price":62447.4,"qty":0.12517130}],"checksum":116921654,"timestamp":"2024-06-01T18:07:00.138089Z"}]}
{"channel":"book","type":"update","data":[{"symbol":"BTC/EUR","bids":[{"price":62434.9,"qty":0.25000000}],"asks":[],"checksum":1547107770,"timestamp":"2024-06-01T18:07:00.783292Z"}]}
{"channel":"book","type":"update","data":[{"symbol":"BTC/EUR","bids":[{"price":62440.9,"qty":0.00000000},{"price":62429.1,"qty":0.04443074},{"price":62432.1,"qty":0.13282212}],"asks":[],"checksum":508364,"timestamp":"2024-06-01T18:07:00.818537Z"}]}
{"channel":"book","type":"update","data":[{"symbol":"BTC/EUR","bids":[{"price":62436.9,"qty":0.12499920}],"asks":[],"checksum":3792963066,"timestamp":"2024-06-01T18:07:00.905806Z"}]}
{"channel":"book","type":"update","data":[{"symbol":"BTC/EUR","bids":[{"price":62432.1,"qty":0.13257793},{"price":62437.3,"qty":0.00024417}],"asks":[],"checksum":248785361,"timestamp":"2024-06-01T18:07:01.046758Z"}]}
{"channel":"book","type":"update","data":[{"symbol":"BTC/EUR","bids":[],"asks":[{"price":62443.1,"qty":0.00000000},{"price":62451.2,"qty":2.37633413}],"checksum":1608272008,"timestamp":"2024-06-01T18:07:01.051951Z"}]}
{"channel":"book","type":"update","data":[{"symbol":"BTC/EUR","bids":[],"asks":[{"price":62440.9,"qty":1.47657712}],"checksum":1666428084,"timestamp":"2024-06-01T18:07:01.056343Z"}]}
{"channel":"book","type":"update","data":[{"symbol":"BTC/EUR","bids":[],"asks":[{"price":62440.8,"qty":0.03947498}],"checksum":2443241666,"timestamp":"2024-06-01T18:07:01.095277Z"}]}
{"channel":"book","type":"update","data":[{"symbol":"BTC/EUR","bids":[],"asks":[{"price":62441.0,"qty":0.14500000}],"checksum":4010475228,"timestamp":"2024-06-01T18:07:01.099540Z"}]}
{"channel":"book","type":"update","data":[{"symbol":"BTC/EUR","bids":[{"price":62437.2,"qty":0.00000000},{"price":62429.3,"qty":0.00853100}],"asks":[],"checksum":2062524260,"timestamp":"2024-06-01T18:07:01.187533Z"}]}
{"channel":"book","type":"update","data":[{"symbol":"BTC/EUR","bids":[{"price":62434.4,"qty":1.47672857}],"asks":[],"checksum":2022825203,"timestamp":"2024-06-01T18:07:01.191727Z"}]}
{"channel":"book","type":"update","data":[{"symbol":"BTC/EUR","bids":[{"price":62435.0,"qty":0.45032644}],"asks":[],"checksum":1188331836,"timestamp":"2024-06-01T18:07:01.192497Z"}]}
{"channel":"book","type":"update","data":[{"symbol":"BTC/EUR","bids":[{"price":62434.9,"qty":0.00000000},{"price":62429.3,"qty":0.00853100}],"asks":[],"checksum":1298935758,"timestamp":"2024-06-01T18:07:01.194544Z"}]}
{"channel":"book","type":"update","data":[{"symbol":"BTC/EUR","bids":[{"price":62437.3,"qty":0.00000000},{"price":62429.1,"qty":0.04443074},{"price":62437.0,"qty":0.00024417}],"asks":[],"checksum":1798484204,"timestamp":"2024-06-01T18:07:01.248022Z"}]}
{"channel":"book","type":"update","data":[{"symbol":"BTC/EUR","bids":[{"price":62437.0,"qty":0.00000000},{"price":62429.1,"qty":0.04443074},{"price":62431.9,"qty":0.00024410}],"asks":[],"checksum":2311142285,"timestamp":"2024-06-01T18:07:01.588597Z"}]}
{"channel":"book","type":"update","data":[{"symbol":"BTC/EUR","bids":[{"price":62435.0,"qty":0.00000000},{"price":62429.1,"qty":0.04443074}],"asks":[],"checksum":2573849166,"timestamp":"2024-06-01T18:07:01.700559Z"}]}
{"channel":"book","type":"update","data":[{"symbol":"BTC/EUR","bids":[{"price":62434.9,"qty":0.29253505}],"asks":[],"checksum":3781892409,"timestamp":"2024-06-01T18:07:01.705346Z"}]}
{"channel":"book","type":"update","data":[{"symbol":"BTC/EUR","bids":[{"price":62436.9,"qty":0.00000000},{"price":62429.1,"qty":0.04443074}],"asks":[],"checksum":2435485209,"timestamp":"2024-06-01T18:07:01.710724Z"}]}
{"channel":"book","type":"update","data":[{"symbol":"BTC/EUR","bids":[{"price":62434.8,"qty":0.00000000},{"price":62424.5,"qty":0.38868768}],"asks":[],"checksum":2229239983,"timestamp":"2024-06-01T18:07:01.715750Z"}]}
{"channel":"book","type":"update","data":[{"symbol":"BTC/EUR","bids":[{"price":62434.4,"qty":0.00000000},{"price":62420.6,"qty":0.05896100}],"asks":[],"checksum":279061934,"timestamp":"2024-06-01T18:07:01.716099Z"}]}
{"channel":"book","type":"update","data":[{"symbol":"BTC/EUR","bids":[{"price":62431.8,"qty":1.64679128}],"asks":[],"checksum":3251603833,"timestamp":"2024-06-01T18:07:01.718878Z"}]}
{"channel":"book","type":"update","data":[{"symbol":"BTC/EUR","bids":[{"price":62435.0,"qty":1.47671666}],"asks":[],"checksum":800898895,"timestamp":"2024-06-01T18:07:01.720756Z"}]}
{"channel":"book","type":"update","data":[{"symbol":"BTC/EUR","bids":[{"price":62435.1,"qty":0.04443074}],"asks":[],"checksum":1024667781,"timestamp":"2024-06-01T18:07:01.732840Z"}]}
{"channel":"book","type":"update","data":[{"symbol":"BTC/EUR","bids":[{"price":62429.1,"qty":0.00000000},{"price":62424.5,"qty":0.38868768}],"asks":[],"checksum":1245220667,"timestamp":"2024-06-01T18:07:01.738770Z"}]}
{"channel":"book","type":"update","data":[{"symbol":"BTC/EUR","bids":[{"price":62431.9,"qty":0.00000000},{"price":62420.6,"qty":0.05896100},{"price":62435.2,"qty":0.00024409}],"asks":[],"checksum":3954722947,"timestamp":"2024-06-01T18:07:01.821541Z"}]}
{"channel":"book","type":"update","data":[{"symbol":"BTC/EUR","bids":[{"price":62435.3,"qty":0.04443074}],"asks":[],"checksum":1546150711,"timestamp":"2024-06-01T18:07:01.827482Z"}]}
{"channel":"book","type":"update","data":[{"symbol":"BTC/EUR","bids":[{"price":62435.4,"qty":1.47670720}],"asks":[],"checksum":2200299917,"timestamp":"2024-06-01T18:07:01.832536Z"}]}
{"channel":"book","type":"update","data":[{"symbol":"BTC/EUR","bids":[{"price":62435.2,"qty":0.12524670}],"asks":[],"checksum":1962900252,"timestamp":"2024-06-01T18:07:01.835206Z"}]}
{"channel":"book","type":"update","data":[{"symbol":"BTC/EUR","bids":[{"price":62435.2,"qty":0.12500261}],"asks":[],"checksum":59345087,"timestamp":"2024-06-01T18:07:01.892169Z"}]}
{"channel":"book","type":"update","data":[{"symbol":"BTC/EUR","bids":[{"price":62435.3,"qty":0.00000000},{"price":62429.3,"qty":0.00853100}],"asks":[],"checksum":2987917146,"timestamp":"2024-06-01T18:07:01.897157Z"}]}
{"channel":"book","type":"update","data":[{"symbol":"BTC/EUR","bids":[{"price":62435.5,"qty":0.00024409}],"asks":[],"checksum":4077116148,"timestamp":"2024-06-01T18:07:02.088806Z"}]}
{"channel":"book","type":"update","data":[{"symbol":"BTC/EUR","bids":[{"price":62435.4,"qty":0.00000000},{"price":62429.3,"qty":0.00853100}],"asks":[],"checksum":2403431225,"timestamp":"2024-06-01T18:07:02.094666Z"}]}
{"channel":"book","type":"update","data":[{"symbol":"BTC/EUR","bids":[{"price":62435.5,"qty":0.25024409}],"asks":[],"checksum":2246033892,"timestamp":"2024-06-01T18:07:02.096329Z"}]}
{"channel":"book","type":"update","data":[{"symbol":"BTC/EUR","bids":[{"price":62435.1,"qty":0.44443074}],"asks":[],"checksum":2710684987,"timestamp":"2024-06-01T18:07:02.096978Z"}]}
{"channel":"book","type":"update","data":[{"symbol":"BTC/EUR","bids":[{"price":62435.6,"qty":1.47670247}],"asks":[],"checksum":1949072593,"timestamp":"2024-06-01T18:07:02.099919Z"}]}
{"channel":"book","type":"update","data":[{"symbol":"BTC/EUR","bids":[{"price":62435.7,"qty":0.25000000}],"asks":[],"checksum":420079225,"timestamp":"2024-06-01T18:07:02.134934Z"}]}
{"channel":"book","type":"update","data":[{"symbol":"BTC/EUR","bids":[{"price":62435.5,"qty":0.25000000},{"price":62431.9,"qty":0.00024410}],"asks":[],"checksum":2128624858,"timestamp":"2024-06-01T18:07:02.138968Z"}]}
{"channel":"book","type":"update","data":[{"symbol":"BTC/EUR","bids":[{"price":62435.5,"qty":0.00000000},{"price":62431.8,"qty":1.64679128}],"asks":[],"checksum":581856953,"timestamp":"2024-06-01T18:07:02.139813Z"}]}
{"channel":"book","type":"update","data":[{"symbol":"BTC/EUR","bids":[{"price":62435.6,"qty":0.00000000},{"price":62429.4,"qty":1.47684731}],"asks":[],"checksum":4190095061,"timestamp":"2024-06-01T18:07:02.140250Z"}]}
{"channel":"book","type":"update","data":[{"symbol":"BTC/EUR","bids":[{"price":62435.1,"qty":0.04443074}],"asks":[],"checksum":4207668814,"timestamp":"2024-06-01T18:07:02.142846Z"}]}
{"channel":"book","type":"update","data":[{"symbol":"BTC/EUR","bids":[{"price":62431.9,"qty":0.00000000},{"price":62429.3,"qty":0.00853100},{"price":62435.8,"qty":0.00024408}],"asks":[],"checksum":4043997681,"timestamp":"2024-06-01T18:07:02.349856Z"}]}
{"channel":"book","type":"update","data":[{"symbol":"BTC/EUR","bids":[{"price":62435.8,"qty":0.00000000},{"price":62429.3,"qty":0.00853100},{"price":62435.9,"qty":0.00024408}],"asks":[],"checksum":3972068591,"timestamp":"2024-06-01T18:07:02.677186Z"}]}
{"channel":"book","type":"update","data":[{"symbol":"BTC/EUR","bids":[{"price":62435.7,"qty":0.00000000},{"price":62429.3,"qty":0.00853100}],"asks":[],"checksum":792453861,"timestamp":"2024-06-01T18:07:02.682244Z"}]}
{"channel":"book","type":"update","data":[{"symbol":"BTC/EUR","bids":[{"price":62435.1,"qty":0.29443074}],"asks":[],"checksum":2138123731,"timestamp":"2024-06-01T18:07:02.682264Z"}]}
{"channel":"book","type":"update","data":[{"symbol":"BTC/EUR","bids":[{"price":62435.9,"qty":0.00000000},{"price":62424.5,"qty":0.38868768},{"price":62431.9,"qty":0.00024410}],"asks":[],"checksum":2840392316,"timestamp":"2024-06-01T18:07:02.748260Z"}]}
{"channel":"book","type":"update","data":[{"symbol":"BTC/EUR","bids":[{"price":62435.3,"qty":0.04443074}],"asks":[],"checksum":864611507,"timestamp":"2024-06-01T18:07:02.754375Z"}]}
{"channel":"book","type":"update","data":[{"symbol":"BTC/EUR","bids":[{"price":62435.0,"qty":1.87671666}],"asks":[],"checksum":2089525041,"timestamp":"2024-06-01T18:07:02.754829Z"}]}
{"channel":"book","type":"update","data":[{"symbol":"BTC/EUR","bids":[{"price":62431.9,"qty":0.00000000},{"price":62429.3,"qty":0.00853100},{"price":62429.5,"qty":0.00024411}],"asks":[],"checksum":2487731640,"timestamp":"2024-06-01T18:07:02.843021Z"}]}
{"channel":"book","type":"update","data":[{"symbol":"BTC/EUR","bids":[{"price":62429.5,"qty":0.00000000},{"price":62429.3,"qty":0.00853100},{"price":62431.9,"qty":0.00024410}],"asks":[],"checksum":2089525041,"timestamp":"2024-06-01T18:07:03.037021Z"}]}
{"channel":"book","type":"update","data":[{"symbol":"BTC/EUR","bids":[{"price":62431.9,"qty":0.00000000},{"price":62429.3,"qty":0.00853100},{"price":62429.5,"qty":0.00024411}],"asks":[],"checksum":2487731640,"timestamp":"2024-06-01T18:07:03.083486Z"}]}
{"channel":"book","type":"update","data":[{"symbol":"BTC/EUR","bids":[{"price":62435.2,"qty":0.37500261}],"asks":[],"checksum":3136234865,"timestamp":"2024-06-01T18:07:03.135257Z"}]}
{"channel":"book","type":"update","data":[{"symbol":"BTC/EUR","bids":[{"price":62435.1,"qty":0.04443074}],"asks":[],"checksum":2330840344,"timestamp":"2024-06-01T18:07:03.139628Z"}]}
{"channel":"book","type":"update","data":[{"symbol":"BTC/EUR","bids":[{"price":62435.1,"qty":0.00000000},{"price":62429.3,"qty":0.00853100}],"asks":[],"checksum":1052261262,"timestamp":"2024-06-01T18:07:03.140706Z"}]}
{"channel":"book","type":"update","data":[{"symbol":"BTC/EUR","bids":[{"price":62435.1,"qty":0.40000000}],"asks":[],"checksum":1933190754,"timestamp":"2024-06-01T18:07:03.140961Z"}]}
{"channel":"book","type":"update","data":[{"symbol":"BTC/EUR","bids":[{"price":62435.8,"qty":1.47669773}],"asks":[],"checksum":312215985,"timestamp":"2024-06-01T18:07:03.152110Z"}]}
{"channel":"book","type":"update","data":[{"symbol":"BTC/EUR","bids":[],"asks":[{"price":62440.9,"qty":0.00000000},{"price":62450.4,"qty":0.52796633}],"checksum":814780748,"timestamp":"2024-06-01T18:07:03.156697Z"}]}
{"channel":"book","type":"update","data":[{"symbol":"BTC/EUR","bids":[],"asks":[{"price":62440.7,"qty":1.47658185}],"checksum":1937755965,"timestamp":"2024-06-01T18:07:03.160692Z"}]}
{"channel":"book","type":"update","data":[{"symbol":"BTC/EUR","bids":[{"price":62429.5,"qty":0.00000000},{"price":62429.4,"qty":1.47684731}],"asks":[],"checksum":3560410596,"timestamp":"2024-06-01T18:07:03.196146Z"}]}
{"channel":"book","type":"update","data":[{"symbol":"BTC/EUR","bids":[],"asks":[{"price":62440.7,"qty":0.00000000},{"price":62450.4,"qty":0.52796633}],"checksum":1470477998,"timestamp":"2024-06-01T18:07:03.391620Z"}]}
{"channel":"book","type":"update","data":[{"symbol":"BTC/EUR","bids":[{"price":62435.0,"qty":0.40000000}],"asks":[],"checksum":1192227235,"timestamp":"2024-06-01T18:07:03.391641Z"}]}
{"channel":"book","type":"update","data":[{"symbol":"BTC/EUR","bids":[],"asks":[{"price":62440.9,"qty":0.03947498}],"checksum":1980685579,"timestamp":"2024-06-01T18:07:03.395948Z"}]}
{"channel":"book","type":"update","data":[{"symbol":"BTC/EUR","bids":[],"asks":[{"price":62440.8,"qty":0.00000000},{"price":62450.4,"qty":0.52796633}],"checksum":3762690359,"timestamp":"2024-06-01T18:07:03.395983Z"}]}
{"channel":"book","type":"update","data":[{"symbol":"BTC/EUR","bids":[{"price":62435.9,"qty":0.25000000}],"asks":[],"checksum":881523447,"timestamp":"2024-06-01T18:07:03.396485Z"}]}
{"channel":"book","type":"update","data":[{"symbol":"BTC/EUR","bids":[{"price":62435.1,"qty":0.00000000},{"price":62429.4,"qty":1.47684731}],"asks":[],"checksum":3410225542,"timestamp":"2024-06-01T18:07:03.397909Z"}]}
{"channel":"book","type":"update","data":[{"symbol":"BTC/EUR","bids":[{"price":62435.8,"qty":0.00000000},{"price":62429.3,"qty":0.00853100}],"asks":[],"checksum":60823666,"timestamp":"2024-06-01T18:07:03.403773Z"}]}
{"channel":"book","type":"update","data":[{"symbol":"BTC/EUR","bids":[],"asks":[{"price":62446.7,"qty":1.47644107}],"checksum":1444508628,"timestamp":"2024-06-01T18:07:03.407955Z"}]}
{"channel":"book","type":"update","data":[{"symbol":"BTC/EUR","bids":[{"price":62435.9,"qty":1.72669368}],"asks":[],"checksum":2908299121,"timestamp":"2024-06-01T18:07:03.407971Z"}]}
{"channel":"book","type":"update","data":[{"symbol":"BTC/EUR","bids":[],"asks":[{"price":62445.9,"qty":0.00000000},{"price":62450.4,"qty":0.52796633}],"checksum":1842609214,"timestamp":"2024-06-01T18:07:03.433753Z"}]}
{"channel":"book","type":"update","data":[{"symbol":"BTC/EUR","bids":[],"asks":[{"price":62443.3,"qty":1.47652130}],"checksum":3169823731,"timestamp":"2024-06-01T18:07:03.438331Z"}]}
{"channel":"book","type":"update","data":[{"symbol":"BTC/EUR","bids":[{"price":62435.9,"qty":1.47669368}],"asks":[],"checksum":155649073,"timestamp":"2024-06-01T18:07:03.438956Z"}]}
{"channel":"book","type":"update","data":[{"symbol":"BTC/EUR","bids":[{"price":62435.1,"qty":0.40000000}],"asks":[],"checksum":114780034,"timestamp":"2024-06-01T18:07:03.439270Z"}]}
{"channel":"book","type":"update","data":[{"symbol":"BTC/EUR","bids":[{"price":62438.1,"qty":1.47664165}],"asks":[],"checksum":1652444063,"timestamp":"2024-06-01T18:07:03.443125Z"}]}
{"channel":"book","type":"update","data":[{"symbol":"BTC/EUR","bids":[],"asks":[{"price":62447.4,"qty":0.00000000},{"price":62450.4,"qty":0.52796633}],"checksum":897610390,"timestamp":"2024-06-01T18:07:03.539781Z"}]}
{"channel":"book","type":"update","data":[{"symbol":"BTC/EUR","bids":[{"price":62435.1,"qty":0.00000000},{"price":62429.4,"qty":1.47684731}],"asks":[],"checksum":4059542208,"timestamp":"2024-06-01T18:07:03.634742Z"}]}
{"channel":"book","type":"update","data":[{"symbol":"BTC/EUR","bids":[{"price":62435.0,"qty":0.00000000},{"price":62429.3,"qty":0.00853100}],"asks":[],"checksum":702209833,"timestamp":"2024-06-01T18:07:03.642939Z"}]}
{"channel":"book","type":"update","data":[{"symbol":"BTC/EUR","bids":[{"price":62440.8,"qty":0.00024570}],"asks":[],"checksum":2129188567,"timestamp":"2024-06-01T18:07:03.913368Z"}]}
{"channel":"book","type":"update","data":[{"symbol":"BTC/EUR","bids":[{"price":62434.9,"qty":0.00000000},{"price":62429.3,"qty":0.00853100}],"asks":[],"checksum":4046343217,"timestamp":"2024-06-01T18:07:04.256266Z"}]}
{"channel":"book","type":"update","data":[{"symbol":"BTC/EUR","bids":[],"asks":[{"price":62441.0,"qty":0.00000000},{"price":62451.1,"qty":0.12991331}],"checksum":2475537909,"timestamp":"2024-06-01T18:07:04.425990Z"}]}
{"channel":"book","type":"update","data":[{"symbol":"BTC/EUR","bids":[],"asks":[{"price":62440.9,"qty":0.00000000},{"price":62451.2,"qty":2.37633413}],"checksum":4141808240,"timestamp":"2024-06-01T18:07:04.430454Z"}]}
{"channel":"book","type":"update","data":[{"symbol":"BTC/EUR","bids":[],"asks":[{"price":62442.6,"qty":0.03947498}],"checksum":1694032610,"timestamp":"2024-06-01T18:07:04.430545Z"}]}
{"channel":"book","type":"update","data":[{"symbol":"BTC/EUR","bids":[],"asks":[{"price":62442.7,"qty":0.00000000},{"price":62451.2,"qty":2.37633413}],"checksum":1013665377,"timestamp":"2024-06-01T18:07:04.437781Z"}]}
{"channel":"book","type":"update","data":[{"symbol":"BTC/EUR","bids":[],"asks":[{"price":62447.5,"qty":0.00000000},{"price":62453.4,"qty":0.05721000},{"price":62447.6,"qty":0.22150000}],"checksum":2838184060,"timestamp":"2024-06-01T18:07:04.440916Z"}]}
{"channel":"book","type":"update","data":[{"symbol":"BTC/EUR","bids":[],"asks":[{"price":62442.5,"qty":1.47653929}],"checksum":2845835066,"timestamp":"2024-06-01T18:07:04.442178Z"}]}
{"channel":"book","type":"update","data":[{"symbol":"BTC/EUR","bids":[{"price":62438.1,"qty":0.00000000},{"price":62424.5,"qty":0.38868768}],"asks":[],"checksum":1461514138,"timestamp":"2024-06-01T18:07:04.513597Z"}]}
{"channel":"book","type":"update","data":[{"symbol":"BTC/EUR","bids":[],"asks":[{"price":62442.4,"qty":0.03947498}],"checksum":982406192,"timestamp":"2024-06-01T18:07:04.517896Z"}]}
{"channel":"book","type":"update","data":[{"symbol":"BTC/EUR","bids":[{"price":62435.3,"qty":1.52113896}],"asks":[],"checksum":3593805084,"timestamp":"2024-06-01T18:07:04.518189Z"}]}
{"channel":"book","type":"update","data":[{"symbol":"BTC/EUR","bids":[{"price":62435.2,"qty":0.12500261}],"asks":[],"checksum":1410280040,"timestamp":"2024-06-01T18:07:04.520430Z"}]}
{"channel":"book","type":"update","data":[{"symbol":"BTC/EUR","bids":[{"price":62431.8,"qty":1.47679128}],"asks":[],"checksum":3608954731,"timestamp":"2024-06-01T18:07:04.520802Z"}]}
{"channel":"book","type":"update","data":[{"symbol":"BTC/EUR","bids":[{"price":62436.1,"qty":0.17000000}],"asks":[],"checksum":17973641,"timestamp":"2024-06-01T18:07:04.520936Z"}]}
{"channel":"book","type":"update","data":[{"symbol":"BTC/EUR","bids":[],"asks":[{"price":62443.3,"qty":0.00000000},{"price":62451.1,"qty":0.12991331}],"checksum":1062892864,"timestamp":"2024-06-01T18:07:04.522750Z"}]}
{"channel":"book","type":"update","data":[{"symbol":"BTC/EUR","bids":[],"asks":[{"price":62450.3,"qty":0.00000000},{"price":62451.2,"qty":2.37633413},{"price":62451.0,"qty":0.00039925}],"checksum":2076083869,"timestamp":"2024-06-01T18:07:04.523862Z"}]}
{"channel":"book","type":"update","data":[{"symbol":"BTC/EUR","bids":[],"asks":[{"price":62442.3,"qty":1.47654402}],"checksum":44267575,"timestamp":"2024-06-01T18:07:04.527257Z"}]}
{"channel":"book","type":"update","data":[{"symbol":"BTC/EUR","bids":[],"asks":[{"price":62442.4,"qty":0.00000000},{"price":62451.1,"qty":0.12991331}],"checksum":1528138362,"timestamp":"2024-06-01T18:07:04.592768Z"}]}
{"channel":"book","type":"update","data":[{"symbol":"BTC/EUR","bids":[],"asks":[{"price":62442.2,"qty":0.03947498}],"checksum":2050509187,"timestamp":"2024-06-01T18:07:04.596909Z"}]}
{"channel":"book","type":"update","data":[{"symbol":"BTC/EUR","bids":[],"asks":[{"price":62442.3,"qty":0.00000000},{"price":62451.1,"qty":0.12991331}],"checksum":2046291702,"timestamp":"2024-06-01T18:07:04.602150Z"}]}
{"channel":"book","type":"update","data":[{"symbol":"BTC/EUR","bids":[],"asks":[{"price":62442.1,"qty":1.47654875}],"checksum":2750915520,"timestamp":"2024-06-01T18:07:04.606495Z"}]}
{"channel":"book","type":"update","data":[{"symbol":"BTC/EUR","bids":[],"asks":[{"price":62442.0,"qty":0.10000000}],"checksum":469388838,"timestamp":"2024-06-01T18:07:04.673666Z"}]}
{"channel":"book","type":"update","data":[{"symbol":"BTC/EUR","bids":[],"asks":[{"price":62442.2,"qty":0.00000000},{"price":62451.0,"qty":0.00039925}],"checksum":3289049793,"timestamp":"2024-06-01T18:07:04.677463Z"}]}
{"channel":"book","type":"update","data":[{"symbol":"BTC/EUR","bids":[],"asks":[{"price":62442.1,"qty":0.00000000},{"price":62451.1,"qty":0.12991331}],"checksum":1611662784,"timestamp":"2024-06-01T18:07:04.678638Z"}]}
{"channel":"book","type":"update","data":[{"symbol":"BTC/EUR","bids":[],"asks":[{"price":62441.9,"qty":1.47655348}],"checksum":3786892875,"timestamp":"2024-06-01T18:07:04.683319Z"}]}
{"channel":"book","type":"update","data":[{"symbol":"BTC/EUR","bids":[],"asks":[{"price":62442.0,"qty":0.00000000},{"price":62451.1,"qty":0.12991331}],"checksum":1548916433,"timestamp":"2024-06-01T18:07:04.924095Z"}]}
{"channel":"book","type":"update","data":[{"symbol":"BTC/EUR","bids":[],"asks":[{"price":62441.8,"qty":0.10000000}],"checksum":1264805142,"timestamp":"2024-06-01T18:07:04.924261Z"}]}
{"channel":"book","type":"update","data":[{"symbol":"BTC/EUR","bids":[],"asks":[{"price":62441.8,"qty":0.13947498}],"checksum":2149587360,"timestamp":"2024-06-01T18:07:04.928414Z"}]}
