{"channel":"book","type":"snapshot","data":[{"symbol":"BTC/AUD","bids":[{"price":101864.9,"qty":0.00075700},{"price":101864.8,"qty":0.00474900},{"price":101846.4,"qty":0.00135100},{"price":101831.4,"qty":0.05376803},{"price":101831.3,"qty":0.24353306},{"price":101796.6,"qty":0.05056249},{"price":101790.8,"qty":0.02932000},{"price":101787.7,"qty":0.00561000},{"price":101760.1,"qty":0.00153024},{"price":101760.0,"qty":0.09768924}],"asks":[{"price":101896.4,"qty":0.05372919},{"price":101896.5,"qty":0.04717373},{"price":101907.6,"qty":0.00474700},{"price":101910.4,"qty":0.00075700},{"price":101932.3,"qty":0.00135100},{"price":101941.9,"qty":0.03271411},{"price":101942.0,"qty":0.44455141},{"price":101943.7,"qty":0.25294473},{"price":101943.8,"qty":0.62654093},{"price":101961.2,"qty":0.05000000}],"checksum":3658670437}]}
{"channel":"book","type":"update","data":[{"symbol":"BTC/AUD","bids":[{"price":101790.8,"qty":0.00000000},{"price":101755.5,"qty":0.00540000},{"price":101787.8,"qty":0.02932000}],"asks":[],"checksum":1145649519,"timestamp":"2024-06-01T18:06:31.959960Z"}]}
{"channel":"book","type":"update","data":[{"symbol":"BTC/AUD","bids":[],"asks":[{"price":101896.3,"qty":0.04717373}],"checksum":1936894164,"timestamp":"2024-06-01T18:06:32.179230Z"}]}
{"channel":"book","type":"update","data":[{"symbol":"BTC/AUD","bids":[{"price":101831.1,"qty":0.04717373}],"asks":[],"checksum":1062385580,"timestamp":"2024-06-01T18:06:32.179275Z"}]}
{"channel":"book","type":"update","data":[{"symbol":"BTC/AUD","bids":[],"asks":[{"price":101896.5,"qty":0.00000000},{"price":101961.2,"qty":0.05000000}],"checksum":2574002899,"timestamp":"2024-06-01T18:06:32.183480Z"}]}
{"channel":"book","type":"update","data":[{"symbol":"BTC/AUD","bids":[],"asks":[{"price":101896.4,"qty":0.00000000},{"price":101961.3,"qty":0.00525000},{"price":101896.2,"qty":0.05372978}],"checksum":2905198274,"timestamp":"2024-06-01T18:06:32.225042Z"}]}
{"channel":"book","type":"update","data":[{"symbol":"BTC/AUD","bids":[],"asks":[{"price":101961.2,"qty":0.00000000},{"price":101961.3,"qty":0.00525000}],"checksum":4036124754,"timestamp":"2024-06-01T18:06:32.590539Z"}]}
{"channel":"book","type":"update","data":[{"symbol":"BTC/AUD","bids":[],"asks":[{"price":101942.0,"qty":0.00000000},{"price":101993.0,"qty":0.09768924}],"checksum":3717026354,"timestamp":"2024-06-01T18:06:32.650783Z"}]}
{"channel":"book","type":"update","data":[{"symbol":"BTC/AUD","bids":[],"asks":[{"price":101943.7,"qty":0.00000000},{"price":101993.1,"qty":0.00651000}],"checksum":440544799,"timestamp":"2024-06-01T18:06:32.650992Z"}]}
{"channel":"book","type":"update","data":[{"symbol":"BTC/AUD","bids":[],"asks":[{"price":101941.9,"qty":0.00339411},{"price":101943.6,"qty":0.02932000}],"checksum":4114254154,"timestamp":"2024-06-01T18:06:32.653932Z"}]}
{"channel":"book","type":"update","data":[{"symbol":"BTC/AUD","bids":[],"asks":[{"price":101943.7,"qty":0.20750744}],"checksum":400293075,"timestamp":"2024-06-01T18:06:32.654065Z"}]}
{"channel":"book","type":"update","data":[{"symbol":"BTC/AUD","bids":[],"asks":[{"price":101941.8,"qty":0.53677897}],"checksum":2020243377,"timestamp":"2024-06-01T18:06:32.654121Z"}]}
{"channel":"book","type":"update","data":[{"symbol":"BTC/AUD","bids":[{"price":101796.7,"qty":0.00051152}],"asks":[],"checksum":1727117245,"timestamp":"2024-06-01T18:06:32.885143Z"}]}
{"channel":"book","type":"update","data":[{"symbol":"BTC/AUD","bids":[{"price":101831.5,"qty":0.11599080}],"asks":[],"checksum":2770464650,"timestamp":"2024-06-01T18:06:32.996262Z"}]}
{"channel":"book","type":"update","data":[{"symbol":"BTC/AUD","bids":[],"asks":[{"price":101896.1,"qty":0.04717373}],"checksum":2546290277,"timestamp":"2024-06-01T18:06:33.002065Z"}]}
{"channel":"book","type":"update","data":[{"symbol":"BTC/AUD","bids":[{"price":101831.4,"qty":0.00000000},{"price":101787.7,"qty":0.00561000},{"price":101831.6,"qty":0.05376895}],"asks":[],"checksum":3024073676,"timestamp":"2024-06-01T18:06:33.045918Z"}]}
{"channel":"book","type":"update","data":[{"symbol":"BTC/AUD","bids":[],"asks":[{"price":101896.3,"qty":0.00000000},{"price":101943.8,"qty":0.62654093}],"checksum":4136861025,"timestamp":"2024-06-01T18:06:33.050627Z"}]}
{"channel":"book","type":"update","data":[{"symbol":"BTC/AUD","bids":[],"asks":[{"price":101941.9,"qty":0.00000000},{"price":101948.3,"qty":0.05000000}],"checksum":2739153955,"timestamp":"2024-06-01T18:06:33.228975Z"}]}
{"channel":"book","type":"update","data":[{"symbol":"BTC/AUD","bids":[],"asks":[{"price":101943.6,"qty":0.00000000},{"price":101961.3,"qty":0.00525000},{"price":101941.7,"qty":0.02932000}],"checksum":3455706673,"timestamp":"2024-06-01T18:06:33.232486Z"}]}
{"channel":"book","type":"update","data":[{"symbol":"BTC/AUD","bids":[],"asks":[{"price":101941.7,"qty":0.03325305}],"checksum":4199833864,"timestamp":"2024-06-01T18:06:33.233646Z"}]}
{"channel":"book","type":"update","data":[{"symbol":"BTC/AUD","bids":[],"asks":[{"price":101910.4,"qty":0.00000000},{"price":101961.3,"qty":0.00525000},{"price":101903.5,"qty":0.00075700}],"checksum":861847795,"timestamp":"2024-06-01T18:06:33.339786Z"}]}
{"channel":"book","type":"update","data":[{"symbol":"BTC/AUD","bids":[],"asks":[{"price":101896.2,"qty":0.00000000},{"price":101961.3,"qty":0.00525000},{"price":101896.0,"qty":0.05372979}],"checksum":938108564,"timestamp":"2024-06-01T18:06:33.570941Z"}]}
{"channel":"book","type":"update","data":[{"symbol":"BTC/AUD","bids":[],"asks":[{"price":101895.9,"qty":0.04717373}],"checksum":3104373894,"timestamp":"2024-06-01T18:06:34.179974Z"}]}
{"channel":"book","type":"update","data":[{"symbol":"BTC/AUD","bids":[],"asks":[{"price":101896.1,"qty":0.00000000},{"price":101948.3,"qty":0.05000000}],"checksum":3136842805,"timestamp":"2024-06-01T18:06:34.184094Z"}]}
{"channel":"book","type":"update","data":[{"symbol":"BTC/AUD","bids":[],"asks":[{"price":101896.0,"qty":0.00000000},{"price":101961.3,"qty":0.00525000},{"price":101895.8,"qty":0.05373024}],"checksum":2823812859,"timestamp":"2024-06-01T18:06:34.214683Z"}]}
{"channel":"book","type":"update","data":[{"symbol":"BTC/AUD","bids":[{"price":101787.8,"qty":0.00000000},{"price":101787.7,"qty":0.00561000}],"asks":[],"checksum":3889370590,"timestamp":"2024-06-01T18:06:34.303537Z"}]}
{"channel":"book","type":"update","data":[{"symbol":"BTC/AUD","bids":[],"asks":[{"price":101941.7,"qty":0.00393305},{"price":101907.5,"qty":0.02932000}],"checksum":276422413,"timestamp":"2024-06-01T18:06:34.303711Z"}]}
{"channel":"book","type":"update","data":[{"symbol":"BTC/AUD","bids":[],"asks":[{"price":101907.6,"qty":0.00000000},{"price":101948.3,"qty":0.05000000},{"price":101897.5,"qty":0.00474800}],"checksum":3500331225,"timestamp":"2024-06-01T18:06:34.439656Z"}]}
{"channel":"book","type":"update","data":[{"symbol":"BTC/AUD","bids":[{"price":101831.3,"qty":0.00000000},{"price":101780.6,"qty":0.02932000}],"asks":[],"checksum":3540862986,"timestamp":"2024-06-01T18:06:34.452389Z"}]}
{"channel":"book","type":"update","data":[{"symbol":"BTC/AUD","bids":[{"price":101824.1,"qty":0.24355028}],"asks":[],"checksum":2250650900,"timestamp":"2024-06-01T18:06:34.457582Z"}]}
{"channel":"book","type":"update","data":[{"symbol":"BTC/AUD","bids":[{"price":101846.4,"qty":0.00000000},{"price":101780.6,"qty":0.02932000},{"price":101833.1,"qty":0.00135100}],"asks":[],"checksum":580294354,"timestamp":"2024-06-01T18:06:34.627972Z"}]}
{"channel":"book","type":"update","data":[{"symbol":"BTC/AUD","bids":[{"price":101831.5,"qty":0.00000000},{"price":101780.6,"qty":0.02932000}],"asks":[],"checksum":2272506049,"timestamp":"2024-06-01T18:06:34.739209Z"}]}
{"channel":"book","type":"update","data":[{"symbol":"BTC/AUD","bids":[{"price":101831.6,"qty":0.00000000},{"price":101760.1,"qty":0.00153024},{"price":101833.2,"qty":0.05376811}],"asks":[],"checksum":2519836792,"timestamp":"2024-06-01T18:06:34.794584Z"}]}
{"channel":"book","type":"update","data":[{"symbol":"BTC/AUD","bids":[],"asks":[{"price":101895.7,"qty":0.04717373}],"checksum":4040296161,"timestamp":"2024-06-01T18:06:35.178620Z"}]}
{"channel":"book","type":"update","data":[{"symbol":"BTC/AUD","bids":[],"asks":[{"price":101895.9,"qty":0.00000000},{"price":101943.8,"qty":0.62654093}],"checksum":321425,"timestamp":"2024-06-01T18:06:35.183022Z"}]}
{"channel":"book","type":"update","data":[{"symbol":"BTC/AUD","bids":[],"asks":[{"price":101941.6,"qty":0.05000000}],"checksum":1888372633,"timestamp":"2024-06-01T18:06:35.215881Z"}]}
{"channel":"book","type":"update","data":[{"symbol":"BTC/AUD","bids":[],"asks":[{"price":101895.8,"qty":0.00000000},{"price":101943.8,"qty":0.62654093},{"price":101895.6,"qty":0.05373024}],"checksum":274263402,"timestamp":"2024-06-01T18:06:35.296339Z"}]}
{"channel":"book","type":"update","data":[{"symbol":"BTC/AUD","bids":[],"asks":[{"price":101895.5,"qty":0.04717373}],"checksum":3022438973,"timestamp":"2024-06-01T18:06:35.301111Z"}]}
{"channel":"book","type":"update","data":[{"symbol":"BTC/AUD","bids":[],"asks":[{"price":101907.5,"qty":0.00000000},{"price":101943.7,"qty":0.20750744},{"price":101941.5,"qty":0.02932000}],"checksum":770801902,"timestamp":"2024-06-01T18:06:35.303934Z"}]}
{"channel":"book","type":"update","data":[{"symbol":"BTC/AUD","bids":[{"price":101780.6,"qty":0.00000000},{"price":101760.1,"qty":0.00153024},{"price":101760.1,"qty":0.03085024}],"asks":[],"checksum":1742294027,"timestamp":"2024-06-01T18:06:35.339465Z"}]}
{"channel":"book","type":"update","data":[{"symbol":"BTC/AUD","bids":[],"asks":[{"price":101903.5,"qty":0.00000000},{"price":101943.7,"qty":0.20750744},{"price":101895.6,"qty":0.05448724}],"checksum":2063271505,"timestamp":"2024-06-01T18:06:35.352095Z"}]}
{"channel":"book","type":"update","data":[{"symbol":"BTC/AUD","bids":[],"asks":[{"price":101895.7,"qty":0.00000000},{"price":101943.8,"qty":0.62654093}],"checksum":974151238,"timestamp":"2024-06-01T18:06:35.356828Z"}]}
{"channel":"book","type":"update","data":[{"symbol":"BTC/AUD","bids":[],"asks":[{"price":101941.8,"qty":0.00000000},{"price":101961.3,"qty":0.00525000}],"checksum":483656580,"timestamp":"2024-06-01T18:06:35.470840Z"}]}
{"channel":"book","type":"update","data":[{"symbol":"BTC/AUD","bids":[],"asks":[{"price":101943.7,"qty":0.00000000},{"price":101993.0,"qty":0.09768924}],"checksum":3061067294,"timestamp":"2024-06-01T18:06:35.470976Z"}]}
{"channel":"book","type":"update","data":[{"symbol":"BTC/AUD","bids":[],"asks":[{"price":101943.7,"qty":0.85957039}],"checksum":2317301267,"timestamp":"2024-06-01T18:06:35.475360Z"}]}
{"channel":"book","type":"update","data":[{"symbol":"BTC/AUD","bids":[],"asks":[{"price":101941.7,"qty":0.00000000},{"price":101993.0,"qty":0.09768924}],"checksum":3545940111,"timestamp":"2024-06-01T18:06:35.565586Z"}]}
{"channel":"book","type":"update","data":[{"symbol":"BTC/AUD","bids":[],"asks":[{"price":101941.7,"qty":0.00473319}],"checksum":1476955171,"timestamp":"2024-06-01T18:06:35.571504Z"}]}
{"channel":"book","type":"update","data":[{"symbol":"BTC/AUD","bids":[],"asks":[{"price":101895.6,"qty":0.00075700},{"price":101895.4,"qty":0.05373024}],"checksum":1630623651,"timestamp":"2024-06-01T18:06:35.804882Z"}]}
{"channel":"book","type":"update","data":[{"symbol":"BTC/AUD","bids":[{"price":101824.2,"qty":0.02954064}],"asks":[],"checksum":1843943584,"timestamp":"2024-06-01T18:06:36.022983Z"}]}
{"channel":"book","type":"update","data":[{"symbol":"BTC/AUD","bids":[{"price":101796.7,"qty":0.00000000},{"price":101760.3,"qty":0.02932000}],"asks":[],"checksum":1984870444,"timestamp":"2024-06-01T18:06:36.059594Z"}]}
{"channel":"book","type":"update","data":[{"symbol":"BTC/AUD","bids":[{"price":101760.4,"qty":0.00153024}],"asks":[],"checksum":764354434,"timestamp":"2024-06-01T18:06:36.062885Z"}]}
{"channel":"book","type":"update","data":[{"symbol":"BTC/AUD","bids":[],"asks":[{"price":101895.3,"qty":0.04717373}],"checksum":909291074,"timestamp":"2024-06-01T18:06:36.178577Z"}]}
{"channel":"book","type":"update","data":[{"symbol":"BTC/AUD","bids":[],"asks":[{"price":101895.5,"qty":0.00000000},{"price":101943.8,"qty":0.62654093}],"checksum":1363336495,"timestamp":"2024-06-01T18:06:36.183111Z"}]}
{"channel":"book","type":"update","data":[{"symbol":"BTC/AUD","bids":[],"asks":[{"price":101895.4,"qty":0.00000000},{"price":101961.3,"qty":0.00525000},{"price":101895.2,"qty":0.05373052}],"checksum":3212257899,"timestamp":"2024-06-01T18:06:36.351265Z"}]}
{"channel":"book","type":"update","data":[{"symbol":"BTC/AUD","bids":[],"asks":[{"price":101895.1,"qty":0.04717373}],"checksum":1132479894,"timestamp":"2024-06-01T18:06:37.178159Z"}]}
{"channel":"book","type":"update","data":[{"symbol":"BTC/AUD","bids":[],"asks":[{"price":101895.3,"qty":0.00000000},{"price":101943.8,"qty":0.62654093}],"checksum":2409039820,"timestamp":"2024-06-01T18:06:37.184177Z"}]}
{"channel":"book","type":"update","data":[{"symbol":"BTC/AUD","bids":[],"asks":[{"price":101895.2,"qty":0.00000000},{"price":101961.3,"qty":0.00525000},{"price":101895.0,"qty":0.05373052}],"checksum":2184903164,"timestamp":"2024-06-01T18:06:37.225720Z"}]}
{"channel":"book","type":"update","data":[{"symbol":"BTC/AUD","bids":[],"asks":[{"price":101941.7,"qty":0.00000000},{"price":101961.3,"qty":0.00525000}],"checksum":2355796199,"timestamp":"2024-06-01T18:06:37.943053Z"}]}
{"channel":"book","type":"update","data":[{"symbol":"BTC/AUD","bids":[],"asks":[{"price":101941.4,"qty":0.00432862}],"checksum":3190750330,"timestamp":"2024-06-01T18:06:37.947607Z"}]}
{"channel":"book","type":"update","data":[{"symbol":"BTC/AUD","bids":[],"asks":[{"price":101894.9,"qty":0.04717373}],"checksum":3832834329,"timestamp":"2024-06-01T18:06:38.177116Z"}]}
{"channel":"book","type":"update","data":[{"symbol":"BTC/AUD","bids":[],"asks":[{"price":101895.1,"qty":0.00000000},{"price":101943.8,"qty":0.62654093}],"checksum":3172701000,"timestamp":"2024-06-01T18:06:38.181199Z"}]}
{"channel":"book","type":"update","data":[{"symbol":"BTC/AUD","bids":[],"asks":[{"price":101895.0,"qty":0.00000000},{"price":101961.3,"qty":0.00525000},{"price":101894.8,"qty":0.05373053}],"checksum":1748813682,"timestamp":"2024-06-01T18:06:38.229988Z"}]}
{"channel":"book","type":"update","data":[{"symbol":"BTC/AUD","bids":[],"asks":[{"price":101943.7,"qty":0.00000000},{"price":101961.3,"qty":0.00525000}],"checksum":909572489,"timestamp":"2024-06-01T18:06:38.233880Z"}]}
{"channel":"book","type":"update","data":[{"symbol":"BTC/AUD","bids":[],"asks":[{"price":101894.7,"qty":0.04717373}],"checksum":4033884734,"timestamp":"2024-06-01T18:06:38.234974Z"}]}
{"channel":"book","type":"update","data":[{"symbol":"BTC/AUD","bids":[],"asks":[{"price":101941.4,"qty":0.86101694}],"checksum":2618417741,"timestamp":"2024-06-01T18:06:38.236424Z"}]}
{"channel":"book","type":"update","data":[{"symbol":"BTC/AUD","bids":[],"asks":[{"price":101941.5,"qty":0.00000000},{"price":101961.3,"qty":0.00525000},{"price":101941.3,"qty":0.02932000}],"checksum":1158143086,"timestamp":"2024-06-01T18:06:38.239454Z"}]}
{"channel":"book","type":"update","data":[{"symbol":"BTC/AUD","bids":[],"asks":[{"price":101943.8,"qty":0.00000000},{"price":101961.3,"qty":0.00525000}],"checksum":1772362487,"timestamp":"2024-06-01T18:06:38.434301Z"}]}
{"channel":"book","type":"update","data":[{"symbol":"BTC/AUD","bids":[],"asks":[{"price":101926.1,"qty":0.62655356}],"checksum":3711710454,"timestamp":"2024-06-01T18:06:38.437198Z"}]}
{"channel":"book","type":"update","data":[{"symbol":"BTC/AUD","bids":[],"asks":[{"price":101941.6,"qty":0.00000000},{"price":101961.3,"qty":0.00525000}],"checksum":3057208566,"timestamp":"2024-06-01T18:06:38.601765Z"}]}
{"channel":"book","type":"update","data":[{"symbol":"BTC/AUD","bids":[],"asks":[{"price":101961.2,"qty":0.05000000}],"checksum":237142093,"timestamp":"2024-06-01T18:06:38.634238Z"}]}
{"channel":"book","type":"update","data":[{"symbol":"BTC/AUD","bids":[],"asks":[{"price":101894.8,"qty":0.00000000},{"price":101961.3,"qty":0.00525000},{"price":101894.6,"qty":0.05373053}],"checksum":2702071841,"timestamp":"2024-06-01T18:06:38.648819Z"}]}
{"channel":"book","type":"update","data":[{"symbol":"BTC/AUD","bids":[],"asks":[{"price":101894.9,"qty":0.00000000},{"price":101961.3,"qty":0.00525000}],"checksum":339452876,"timestamp":"2024-06-01T18:06:38.653882Z"}]}
{"channel":"book","type":"update","data":[{"symbol":"BTC/AUD","bids":[{"price":101760.5,"qty":0.08645834}],"asks":[],"checksum":2046731984,"timestamp":"2024-06-01T18:06:39.052972Z"}]}
{"channel":"book","type":"update","data":[{"symbol":"BTC/AUD","bids":[],"asks":[{"price":101941.3,"qty":0.00000000},{"price":101993.0,"qty":0.09768924},{"price":101926.0,"qty":0.02932000}],"checksum":551776974,"timestamp":"2024-06-01T18:06:39.055259Z"}]}
{"channel":"book","type":"update","data":[{"symbol":"BTC/AUD","bids":[],"asks":[{"price":101894.5,"qty":0.04717373}],"checksum":2281517451,"timestamp":"2024-06-01T18:06:39.061159Z"}]}
{"channel":"book","type":"update","data":[{"symbol":"BTC/AUD","bids":[],"asks":[{"price":101894.6,"qty":0.00000000},{"price":101961.3,"qty":0.00525000},{"price":101894.4,"qty":0.05373053}],"checksum":52113138,"timestamp":"2024-06-01T18:06:39.112269Z"}]}
{"channel":"book","type":"update","data":[{"symbol":"BTC/AUD","bids":[],"asks":[{"price":101894.7,"qty":0.00000000},{"price":101961.3,"qty":0.00525000}],"checksum":1320499706,"timestamp":"2024-06-01T18:06:39.117328Z"}]}
{"channel":"book","type":"update","data":[{"symbol":"BTC/AUD","bids":[],"asks":[{"price":101961.2,"qty":0.00000000},{"price":101993.0,"qty":0.09768924}],"checksum":3617561790,"timestamp":"2024-06-01T18:06:39.615410Z"}]}
{"channel":"book","type":"update","data":[{"symbol":"BTC/AUD","bids":[{"price":101760.6,"qty":0.02932000}],"asks":[],"checksum":26366989,"timestamp":"2024-06-01T18:06:39.618008Z"}]}
{"channel":"book","type":"update","data":[{"symbol":"BTC/AUD","bids":[{"price":101760.7,"qty":0.00153024}],"asks":[],"checksum":2508430777,"timestamp":"2024-06-01T18:06:39.629969Z"}]}
{"channel":"book","type":"update","data":[{"symbol":"BTC/AUD","bids":[],"asks":[{"price":101961.2,"qty":0.05000000}],"checksum":3061277626,"timestamp":"2024-06-01T18:06:39.754247Z"}]}
{"channel":"book","type":"update","data":[{"symbol":"BTC/AUD","bids":[],"asks":[{"price":101894.3,"qty":0.04717373}],"checksum":1262779263,"timestamp":"2024-06-01T18:06:40.178534Z"}]}
{"channel":"book","type":"update","data":[{"symbol":"BTC/AUD","bids":[],"asks":[{"price":101894.5,"qty":0.00000000},{"price":101961.3,"qty":0.00525000}],"checksum":3366843570,"timestamp":"2024-06-01T18:06:40.183378Z"}]}
{"channel":"book","type":"update","data":[{"symbol":"BTC/AUD","bids":[],"asks":[{"price":101894.4,"qty":0.00000000},{"price":101993.0,"qty":0.09768924},{"price":101894.2,"qty":0.05373047}],"checksum":3713054172,"timestamp":"2024-06-01T18:06:40.229786Z"}]}
{"channel":"book","type":"update","data":[{"symbol":"BTC/AUD","bids":[],"asks":[{"price":101961.2,"qty":0.00000000},{"price":101993.0,"qty":0.09768924}],"checksum":4272180191,"timestamp":"2024-06-01T18:06:40.232172Z"}]}
{"channel":"book","type":"update","data":[{"symbol":"BTC/AUD","bids":[],"asks":[{"price":101941.4,"qty":0.85668832}],"checksum":4115866824,"timestamp":"2024-06-01T18:06:40.356414Z"}]}
{"channel":"book","type":"update","data":[{"symbol":"BTC/AUD","bids":[],"asks":[{"price":101925.9,"qty":0.00328297}],"checksum":3477443226,"timestamp":"2024-06-01T18:06:40.360915Z"}]}
{"channel":"book","type":"update","data":[{"symbol":"BTC/AUD","bids":[],"asks":[{"price":101961.2,"qty":0.05000000}],"checksum":4114140318,"timestamp":"2024-06-01T18:06:40.763057Z"}]}
{"channel":"book","type":"update","data":[{"symbol":"BTC/AUD","bids":[],"asks":[{"price":101941.4,"qty":0.00000000},{"price":101961.3,"qty":0.00525000}],"checksum":3490906292,"timestamp":"2024-06-01T18:06:41.057576Z"}]}
{"channel":"book","type":"update","data":[{"symbol":"BTC/AUD","bids":[],"asks":[{"price":101925.8,"qty":0.44455550}],"checksum":1632456003,"timestamp":"2024-06-01T18:06:41.060004Z"}]}
{"channel":"book","type":"update","data":[{"symbol":"BTC/AUD","bids":[],"asks":[{"price":101926.0,"qty":0.00000000},{"price":101961.3,"qty":0.00525000},{"price":101925.7,"qty":0.02932000}],"checksum":1107322629,"timestamp":"2024-06-01T18:06:41.063169Z"}]}
{"channel":"book","type":"update","data":[{"symbol":"BTC/AUD","bids":[],"asks":[{"price":101894.1,"qty":0.04717373}],"checksum":400060985,"timestamp":"2024-06-01T18:06:41.065121Z"}]}
{"channel":"book","type":"update","data":[{"symbol":"BTC/AUD","bids":[],"asks":[{"price":101894.2,"qty":0.00000000},{"price":101961.2,"qty":0.05000000},{"price":101894.0,"qty":0.05373047}],"checksum":2997009009,"timestamp":"2024-06-01T18:06:41.115988Z"}]}
{"channel":"book","type":"update","data":[{"symbol":"BTC/AUD","bids":[],"asks":[{"price":101894.3,"qty":0.00000000},{"price":101961.2,"qty":0.05000000}],"checksum":2135798930,"timestamp":"2024-06-01T18:06:41.120969Z"}]}
{"channel":"book","type":"update","data":[{"symbol":"BTC/AUD","bids":[],"asks":[{"price":101893.9,"qty":0.04717373}],"checksum":145860795,"timestamp":"2024-06-01T18:06:41.179039Z"}]}
{"channel":"book","type":"update","data":[{"symbol":"BTC/AUD","bids":[],"asks":[{"price":101894.1,"qty":0.00000000},{"price":101961.2,"qty":0.05000000}],"checksum":4032072731,"timestamp":"2024-06-01T18:06:41.183237Z"}]}
{"channel":"book","type":"update","data":[{"symbol":"BTC/AUD","bids":[],"asks":[{"price":101894.0,"qty":0.00000000},{"price":101961.3,"qty":0.00525000},{"price":101893.8,"qty":0.05373047}],"checksum":262865416,"timestamp":"2024-06-01T18:06:41.513301Z"}]}
{"channel":"book","type":"update","data":[{"symbol":"BTC/AUD","bids":[{"price":101760.8,"qty":0.08645834}],"asks":[],"checksum":4033225450,"timestamp":"2024-06-01T18:06:42.081845Z"}]}
{"channel":"book","type":"update","data":[{"symbol":"BTC/AUD","bids":[],"asks":[{"price":101893.7,"qty":0.04717373}],"checksum":1903160159,"timestamp":"2024-06-01T18:06:42.178988Z"}]}
{"channel":"book","type":"update","data":[{"symbol":"BTC/AUD","bids":[],"asks":[{"price":101893.9,"qty":0.00000000},{"price":101961.2,"qty":0.05000000}],"checksum":2942572850,"timestamp":"2024-06-01T18:06:42.183588Z"}]}
{"channel":"book","type":"update","data":[{"symbol":"BTC/AUD","bids":[],"asks":[{"price":101893.8,"qty":0.00000000},{"price":101961.3,"qty":0.00525000},{"price":101893.6,"qty":0.05373051}],"checksum":3479513102,"timestamp":"2024-06-01T18:06:42.231041Z"}]}
{"channel":"book","type":"update","data":[{"symbol":"BTC/AUD","bids":[],"asks":[{"price":101893.6,"qty":0.00000000},{"price":101961.3,"qty":0.00525000},{"price":101893.5,"qty":0.05373051}],"checksum":815799247,"timestamp":"2024-06-01T18:06:42.622568Z"}]}
{"channel":"book","type":"update","data":[{"symbol":"BTC/AUD","bids":[{"price":101760.9,"qty":0.02932000}],"asks":[],"checksum":2760430593,"timestamp":"2024-06-01T18:06:42.625687Z"}]}
{"channel":"book","type":"update","data":[{"symbol":"BTC/AUD","bids":[{"price":101761.0,"qty":0.00153024}],"asks":[],"checksum":2062791783,"timestamp":"2024-06-01T18:06:42.638137Z"}]}
{"channel":"book","type":"update","data":[{"symbol":"BTC/AUD","bids":[],"asks":[{"price":101893.5,"qty":0.00000000},{"price":101961.3,"qty":0.00525000},{"price":101893.6,"qty":0.05373051}],"checksum":2963932606,"timestamp":"2024-06-01T18:06:42.680638Z"}]}
{"channel":"book","type":"update","data":[{"symbol":"BTC/AUD","bids":[],"asks":[{"price":101925.9,"qty":0.00000000},{"price":101961.3,"qty":0.00525000}],"checksum":3425178493,"timestamp":"2024-06-01T18:06:42.776558Z"}]}
{"channel":"book","type":"update","data":[{"symbol":"BTC/AUD","bids":[],"asks":[{"price":101925.6,"qty":0.00330787}],"checksum":3099798573,"timestamp":"2024-06-01T18:06:42.778905Z"}]}
{"channel":"book","type":"update","data":[{"symbol":"BTC/AUD","bids":[],"asks":[{"price":101961.2,"qty":0.00000000},{"price":101961.3,"qty":0.00525000}],"checksum":884702438,"timestamp":"2024-06-01T18:06:42.988250Z"}]}
{"channel":"book","type":"update","data":[{"symbol":"BTC/AUD","bids":[],"asks":[{"price":101893.5,"qty":0.04717373}],"checksum":1346720219,"timestamp":"2024-06-01T18:06:43.178290Z"}]}
{"channel":"book","type":"update","data":[{"symbol":"BTC/AUD","bids":[],"asks":[{"price":101893.7,"qty":0.00000000},{"price":101961.3,"qty":0.00525000}],"checksum":403471721,"timestamp":"2024-06-01T18:06:43.182373Z"}]}
{"channel":"book","type":"update","data":[{"symbol":"BTC/AUD","bids":[],"asks":[{"price":101893.6,"qty":0.00000000},{"price":101993.0,"qty":0.09768924},{"price":101893.4,"qty":0.05373028}],"checksum":3133015829,"timestamp":"2024-06-01T18:06:43.243870Z"}]}
{"channel":"book","type":"update","data":[{"symbol":"BTC/AUD","bids":[],"asks":[{"price":101893.3,"qty":0.04717373}],"checksum":2899189829,"timestamp":"2024-06-01T18:06:43.249005Z"}]}
{"channel":"book","type":"update","data":[{"symbol":"BTC/AUD","bids":[],"asks":[{"price":101893.4,"qty":0.00000000},{"price":101961.2,"qty":0.05000000},{"price":101893.2,"qty":0.05373028}],"checksum":2072543308,"timestamp":"2024-06-01T18:06:43.655512Z"}]}
{"channel":"book","type":"update","data":[{"symbol":"BTC/AUD","bids":[],"asks":[{"price":101893.5,"qty":0.00000000},{"price":101961.2,"qty":0.05000000}],"checksum":3677355593,"timestamp":"2024-06-01T18:06:43.660704Z"}]}
{"channel":"book","type":"update","data":[{"symbol":"BTC/AUD","bids":[],"asks":[{"price":101925.8,"qty":0.00000000},{"price":101961.3,"qty":0.00525000}],"checksum":586520270,"timestamp":"2024-06-01T18:06:43.820424Z"}]}
{"channel":"book","type":"update","data":[{"symbol":"BTC/AUD","bids":[],"asks":[{"price":101925.5,"qty":0.46761190}],"checksum":3874031895,"timestamp":"2024-06-01T18:06:43.824965Z"}]}
{"channel":"book","type":"update","data":[{"symbol":"BTC/AUD","bids":[],"asks":[{"price":101893.2,"qty":0.08327093}],"checksum":2393473321,"timestamp":"2024-06-01T18:06:43.824978Z"}]}
{"channel":"book","type":"update","data":[{"symbol":"BTC/AUD","bids":[],"asks":[{"price":101925.7,"qty":0.00000000},{"price":101961.3,"qty":0.00525000},{"price":101925.4,"qty":0.02932000}],"checksum":1004920805,"timestamp":"2024-06-01T18:06:43.828006Z"}]}
{"channel":"book","type":"update","data":[{"symbol":"BTC/AUD","bids":[],"asks":[{"price":101893.2,"qty":0.02954065},{"price":101893.1,"qty":0.05373026}],"checksum":408406383,"timestamp":"2024-06-01T18:06:44.019011Z"}]}
{"channel":"book","type":"update","data":[{"symbol":"BTC/AUD","bids":[],"asks":[{"price":101893.0,"qty":0.04717373}],"checksum":90866519,"timestamp":"2024-06-01T18:06:44.024003Z"}]}
{"channel":"book","type":"update","data":[{"symbol":"BTC/AUD","bids":[],"asks":[{"price":101893.3,"qty":0.00000000},{"price":101932.3,"qty":0.00135100}],"checksum":4206761114,"timestamp":"2024-06-01T18:06:44.178333Z"}]}
{"channel":"book","type":"update","data":[{"symbol":"BTC/AUD","bids":[],"asks":[{"price":101893.1,"qty":0.00000000},{"price":101961.2,"qty":0.05000000},{"price":101892.9,"qty":0.05373025}],"checksum":2319833928,"timestamp":"2024-06-01T18:06:44.426122Z"}]}
{"channel":"book","type":"update","data":[{"symbol":"BTC/AUD","bids":[{"price":101761.1,"qty":0.08645834}],"asks":[],"checksum":2478153617,"timestamp":"2024-06-01T18:06:45.070666Z"}]}
{"channel":"book","type":"update","data":[{"symbol":"BTC/AUD","bids":[],"asks":[{"price":101892.8,"qty":0.04717373}],"checksum":2035196409,"timestamp":"2024-06-01T18:06:45.178882Z"}]}
{"channel":"book","type":"update","data":[{"symbol":"BTC/AUD","bids":[],"asks":[{"price":101893.0,"qty":0.00000000},{"price":101932.3,"qty":0.00135100}],"checksum":2400895138,"timestamp":"2024-06-01T18:06:45.183115Z"}]}
{"channel":"book","type":"update","data":[{"symbol":"BTC/AUD","bids":[],"asks":[{"price":101925.6,"qty":0.00000000},{"price":101961.2,"qty":0.05000000}],"checksum":4232202365,"timestamp":"2024-06-01T18:06:45.195569Z"}]}
{"channel":"book","type":"update","data":[{"symbol":"BTC/AUD","bids":[],"asks":[{"price":101925.3,"qty":0.00317094}],"checksum":1525599278,"timestamp":"2024-06-01T18:06:45.197748Z"}]}
{"channel":"book","type":"update","data":[{"symbol":"BTC/AUD","bids":[],"asks":[{"price":101892.9,"qty":0.00000000},{"price":101961.2,"qty":0.05000000},{"price":101892.7,"qty":0.05373025}],"checksum":4247034364,"timestamp":"2024-06-01T18:06:45.227974Z"}]}
{"channel":"book","type":"update","data":[{"symbol":"BTC/AUD","bids":[{"price":101761.2,"qty":0.02932000}],"asks":[],"checksum":724128079,"timestamp":"2024-06-01T18:06:45.907561Z"}]}
{"channel":"book","type":"update","data":[{"symbol":"BTC/AUD","bids":[{"price":101761.3,"qty":0.00153024}],"asks":[],"checksum":1101876034,"timestamp":"2024-06-01T18:06:45.936823Z"}]}
{"channel":"book","type":"update","data":[{"symbol":"BTC/AUD","bids":[],"asks":[{"price":101892.6,"qty":0.04717373}],"checksum":2647804324,"timestamp":"2024-06-01T18:06:46.178454Z"}]}
{"channel":"book","type":"update","data":[{"symbol":"BTC/AUD","bids":[],"asks":[{"price":101892.8,"qty":0.00000000},{"price":101932.3,"qty":0.00135100}],"checksum":1581236803,"timestamp":"2024-06-01T18:06:46.182916Z"}]}
{"channel":"book","type":"update","data":[{"symbol":"BTC/AUD","bids":[],"asks":[{"price":101892.7,"qty":0.00000000},{"price":101947.0,"qty":0.09768924},{"price":101892.5,"qty":0.05373029}],"checksum":2625863433,"timestamp":"2024-06-01T18:06:46.232192Z"}]}
{"channel":"book","type":"update","data":[{"symbol":"BTC/AUD","bids":[],"asks":[{"price":101892.4,"qty":0.04717373}],"checksum":178978299,"timestamp":"2024-06-01T18:06:46.237169Z"}]}
{"channel":"book","type":"update","data":[{"symbol":"BTC/AUD","bids":[],"asks":[{"price":101892.5,"qty":0.00000000},{"price":101932.3,"qty":0.00135100},{"price":101892.3,"qty":0.05373029}],"checksum":3218203874,"timestamp":"2024-06-01T18:06:46.584951Z"}]}
{"channel":"book","type":"update","data":[{"symbol":"BTC/AUD","bids":[],"asks":[{"price":101892.6,"qty":0.00000000},{"price":101932.3,"qty":0.00135100}],"checksum":3568495164,"timestamp":"2024-06-01T18:06:46.590274Z"}]}
{"channel":"book","type":"update","data":[{"symbol":"BTC/AUD","bids":[],"asks":[{"price":101925.5,"qty":0.00000000},{"price":101947.0,"qty":0.09768924}],"checksum":2163020936,"timestamp":"2024-06-01T18:06:46.667102Z"}]}
{"channel":"book","type":"update","data":[{"symbol":"BTC/AUD","bids":[],"asks":[{"price":101893.2,"qty":0.00000000},{"price":101961.2,"qty":0.05000000}],"checksum":1695623081,"timestamp":"2024-06-01T18:06:46.667263Z"}]}
{"channel":"book","type":"update","data":[{"symbol":"BTC/AUD","bids":[],"asks":[{"price":101892.3,"qty":0.08327094}],"checksum":3657557811,"timestamp":"2024-06-01T18:06:46.669513Z"}]}
{"channel":"book","type":"update","data":[{"symbol":"BTC/AUD","bids":[],"asks":[{"price":101925.2,"qty":0.46761190}],"checksum":260502750,"timestamp":"2024-06-01T18:06:46.669761Z"}]}
{"channel":"book","type":"update","data":[{"symbol":"BTC/AUD","bids":[],"asks":[{"price":101925.4,"qty":0.00000000},{"price":101961.2,"qty":0.05000000},{"price":101926.0,"qty":0.02932000}],"checksum":720654323,"timestamp":"2024-06-01T18:06:46.670689Z"}]}
{"channel":"book","type":"update","data":[{"symbol":"BTC/AUD","bids":[],"asks":[{"price":101946.9,"qty":0.05000000}],"checksum":826743916,"timestamp":"2024-06-01T18:06:46.729846Z"}]}
{"channel":"book","type":"update","data":[{"symbol":"BTC/AUD","bids":[],"asks":[{"price":101892.3,"qty":0.02954065},{"price":101892.2,"qty":0.05373029}],"checksum":1544465481,"timestamp":"2024-06-01T18:06:46.964015Z"}]}
{"channel":"book","type":"update","data":[{"symbol":"BTC/AUD","bids":[],"asks":[{"price":101892.1,"qty":0.04717373}],"checksum":2836585216,"timestamp":"2024-06-01T18:06:46.969048Z"}]}
{"channel":"book","type":"update","data":[{"symbol":"BTC/AUD","bids":[],"asks":[{"price":101892.4,"qty":0.00000000},{"price":101932.3,"qty":0.00135100}],"checksum":2099433188,"timestamp":"2024-06-01T18:06:47.176973Z"}]}
{"channel":"book","type":"update","data":[{"symbol":"BTC/AUD","bids":[],"asks":[{"price":101926.0,"qty":0.00000000},{"price":101940.6,"qty":0.05000000},{"price":101925.1,"qty":0.02932000}],"checksum":2411202746,"timestamp":"2024-06-01T18:06:47.179579Z"}]}
{"channel":"book","type":"update","data":[{"symbol":"BTC/AUD","bids":[],"asks":[{"price":101892.2,"qty":0.00000000},{"price":101940.6,"qty":0.05000000},{"price":101892.0,"qty":0.05373029}],"checksum":1818211634,"timestamp":"2024-06-01T18:06:47.307831Z"}]}
{"channel":"book","type":"update","data":[{"symbol":"BTC/AUD","bids":[],"asks":[{"price":101925.3,"qty":0.00000000},{"price":101940.6,"qty":0.05000000}],"checksum":3058187917,"timestamp":"2024-06-01T18:06:47.637061Z"}]}
{"channel":"book","type":"update","data":[{"symbol":"BTC/AUD","bids":[],"asks":[{"price":101925.0,"qty":0.00290953}],"checksum":2610566561,"timestamp":"2024-06-01T18:06:47.641937Z"}]}
{"channel":"book","type":"update","data":[{"symbol":"BTC/AUD","bids":[],"asks":[{"price":101892.0,"qty":0.00000000},{"price":101940.6,"qty":0.05000000},{"price":101891.9,"qty":0.05373033}],"checksum":2330394535,"timestamp":"2024-06-01T18:06:47.678622Z"}]}
{"channel":"book","type":"update","data":[{"symbol":"BTC/AUD","bids":[],"asks":[{"price":101891.9,"qty":0.00000000},{"price":101940.6,"qty":0.05000000},{"price":101892.0,"qty":0.05373033}],"checksum":1866257322,"timestamp":"2024-06-01T18:06:47.727801Z"}]}
{"channel":"book","type":"update","data":[{"symbol":"BTC/AUD","bids":[{"price":101761.4,"qty":0.08645834}],"asks":[],"checksum":456879178,"timestamp":"2024-06-01T18:06:48.099168Z"}]}
{"channel":"book","type":"update","data":[{"symbol":"BTC/AUD","bids":[],"asks":[{"price":101891.9,"qty":0.04717373}],"checksum":4215420637,"timestamp":"2024-06-01T18:06:48.178659Z"}]}
{"channel":"book","type":"update","data":[{"symbol":"BTC/AUD","bids":[],"asks":[{"price":101892.1,"qty":0.00000000},{"price":101932.3,"qty":0.00135100}],"checksum":2843611061,"timestamp":"2024-06-01T18:06:48.182909Z"}]}
{"channel":"book","type":"update","data":[{"symbol":"BTC/AUD","bids":[],"asks":[{"price":101892.0,"qty":0.00000000},{"price":101940.6,"qty":0.05000000},{"price":101891.8,"qty":0.05373033}],"checksum":1210365274,"timestamp":"2024-06-01T18:06:48.237333Z"}]}
{"channel":"book","type":"update","data":[{"symbol":"BTC/AUD","bids":[],"asks":[{"price":101891.8,"qty":0.00000000},{"price":101940.6,"qty":0.05000000},{"price":101891.7,"qty":0.05373033}],"checksum":4262937885,"timestamp":"2024-06-01T18:06:48.631661Z"}]}
{"channel":"book","type":"update","data":[{"symbol":"BTC/AUD","bids":[{"price":101761.5,"qty":0.02932000}],"asks":[],"checksum":1782549203,"timestamp":"2024-06-01T18:06:48.634349Z"}]}
{"channel":"book","type":"update","data":[{"symbol":"BTC/AUD","bids":[{"price":101761.6,"qty":0.00153024}],"asks":[],"checksum":3298010816,"timestamp":"2024-06-01T18:06:48.642081Z"}]}
{"channel":"book","type":"update","data":[{"symbol":"BTC/AUD","bids":[],"asks":[{"price":101891.7,"qty":0.00000000},{"price":101940.6,"qty":0.05000000},{"price":101891.8,"qty":0.05373033}],"checksum":2437864703,"timestamp":"2024-06-01T18:06:48.676565Z"}]}
{"channel":"book","type":"update","data":[{"symbol":"BTC/AUD","bids":[],"asks":[{"price":101891.8,"qty":0.00000000},{"price":101940.6,"qty":0.05000000},{"price":101891.7,"qty":0.05373033}],"checksum":3298010816,"timestamp":"2024-06-01T18:06:49.065857Z"}]}
{"channel":"book","type":"update","data":[{"symbol":"BTC/AUD","bids":[],"asks":[{"price":101891.6,"qty":0.04717373}],"checksum":2976661700,"timestamp":"2024-06-01T18:06:49.071256Z"}]}
{"channel":"book","type":"update","data":[{"symbol":"BTC/AUD","bids":[],"asks":[{"price":101891.7,"qty":0.00000000},{"price":101932.3,"qty":0.00135100},{"price":101891.8,"qty":0.05373033}],"checksum":3769000660,"timestamp":"2024-06-01T18:06:49.129672Z"}]}
{"channel":"book","type":"update","data":[{"symbol":"BTC/AUD","bids":[],"asks":[{"price":101891.9,"qty":0.00000000},{"price":101932.3,"qty":0.00135100}],"checksum":700895228,"timestamp":"2024-06-01T18:06:49.134472Z"}]}
{"channel":"book","type":"update","data":[{"symbol":"BTC/AUD","bids":[],"asks":[{"price":101891.8,"qty":0.00000000},{"price":101940.6,"qty":0.05000000},{"price":101891.5,"qty":0.05373033}],"checksum":3926896544,"timestamp":"2024-06-01T18:06:49.482994Z"}]}
{"channel":"book","type":"update","data":[{"symbol":"BTC/AUD","bids":[],"asks":[{"price":101891.4,"qty":0.04717373}],"checksum":1257851443,"timestamp":"2024-06-01T18:06:49.489626Z"}]}
{"channel":"book","type":"update","data":[{"symbol":"BTC/AUD","bids":[],"asks":[{"price":101892.3,"qty":0.00000000},{"price":101932.3,"qty":0.00135100}],"checksum":2676795558,"timestamp":"2024-06-01T18:06:49.564153Z"}]}
{"channel":"book","type":"update","data":[{"symbol":"BTC/AUD","bids":[],"asks":[{"price":101925.2,"qty":0.00000000},{"price":101940.6,"qty":0.05000000}],"checksum":1039855369,"timestamp":"2024-06-01T18:06:49.564379Z"}]}
{"channel":"book","type":"update","data":[{"symbol":"BTC/AUD","bids":[],"asks":[{"price":101924.9,"qty":0.46761197}],"checksum":269783408,"timestamp":"2024-06-01T18:06:49.568962Z"}]}
{"channel":"book","type":"update","data":[{"symbol":"BTC/AUD","bids":[],"asks":[{"price":101891.6,"qty":0.00000000},{"price":101940.6,"qty":0.05000000}],"checksum":187045927,"timestamp":"2024-06-01T18:06:49.569500Z"}]}
{"channel":"book","type":"update","data":[{"symbol":"BTC/AUD","bids":[],"asks":[{"price":101925.1,"qty":0.00000000},{"price":101947.0,"qty":0.09768924},{"price":101926.0,"qty":0.02932000}],"checksum":2860414566,"timestamp":"2024-06-01T18:06:49.572069Z"}]}
{"channel":"book","type":"update","data":[{"symbol":"BTC/AUD","bids":[],"asks":[{"price":101891.5,"qty":0.00000000},{"price":101947.0,"qty":0.09768924},{"price":101891.3,"qty":0.05373032}],"checksum":484911719,"timestamp":"2024-06-01T18:06:49.968310Z"}]}
{"channel":"book","type":"update","data":[{"symbol":"BTC/AUD","bids":[],"asks":[{"price":101891.2,"qty":0.04717373}],"checksum":311980140,"timestamp":"2024-06-01T18:06:49.973441Z"}]}
{"channel":"book","type":"update","data":[{"symbol":"BTC/AUD","bids":[],"asks":[{"price":101925.0,"qty":0.00000000},{"price":101940.6,"qty":0.05000000}],"checksum":184104633,"timestamp":"2024-06-01T18:06:50.031482Z"}]}
{"channel":"book","type":"update","data":[{"symbol":"BTC/AUD","bids":[],"asks":[{"price":101924.8,"qty":0.00330787}],"checksum":3095608008,"timestamp":"2024-06-01T18:06:50.036102Z"}]}
{"channel":"book","type":"update","data":[{"symbol":"BTC/AUD","bids":[],"asks":[{"price":101891.4,"qty":0.00000000},{"price":101940.6,"qty":0.05000000}],"checksum":2094131854,"timestamp":"2024-06-01T18:06:50.179170Z"}]}
{"channel":"book","type":"update","data":[{"symbol":"BTC/AUD","bids":[],"asks":[{"price":101926.0,"qty":0.00000000},{"price":101947.0,"qty":0.09768924},{"price":101924.8,"qty":0.03262787}],"checksum":239084714,"timestamp":"2024-06-01T18:06:50.181981Z"}]}
{"channel":"book","type":"update","data":[{"symbol":"BTC/AUD","bids":[],"asks":[{"price":101891.3,"qty":0.00000000},{"price":101961.3,"qty":0.00525000},{"price":101891.1,"qty":0.05373031}],"checksum":3326593645,"timestamp":"2024-06-01T18:06:50.489456Z"}]}
{"channel":"book","type":"update","data":[{"symbol":"BTC/AUD","bids":[{"price":101761.7,"qty":0.08645834}],"asks":[],"checksum":3640478151,"timestamp":"2024-06-01T18:06:51.104117Z"}]}
{"channel":"book","type":"update","data":[{"symbol":"BTC/AUD","bids":[],"asks":[{"price":101891.0,"qty":0.04717373}],"checksum":3660591077,"timestamp":"2024-06-01T18:06:51.178736Z"}]}
{"channel":"book","type":"update","data":[{"symbol":"BTC/AUD","bids":[],"asks":[{"price":101891.2,"qty":0.00000000},{"price":101947.0,"qty":0.09768924}],"checksum":3157686222,"timestamp":"2024-06-01T18:06:51.183528Z"}]}
{"channel":"book","type":"update","data":[{"symbol":"BTC/AUD","bids":[],"asks":[{"price":101891.1,"qty":0.00000000},{"price":101961.3,"qty":0.00525000},{"price":101890.9,"qty":0.05373031}],"checksum":1841530383,"timestamp":"2024-06-01T18:06:51.231576Z"}]}
{"channel":"book","type":"update","data":[{"symbol":"BTC/AUD","bids":[],"asks":[{"price":101890.8,"qty":0.04717373}],"checksum":2636105211,"timestamp":"2024-06-01T18:06:52.178592Z"}]}
{"channel":"book","type":"update","data":[{"symbol":"BTC/AUD","bids":[{"price":101761.8,"qty":0.02932000}],"asks":[],"checksum":482154503,"timestamp":"2024-06-01T18:06:52.181633Z"}]}
{"channel":"book","type":"update","data":[{"symbol":"BTC/AUD","bids":[],"asks":[{"price":101891.0,"qty":0.00000000},{"price":101947.0,"qty":0.09768924}],"checksum":2052366390,"timestamp":"2024-06-01T18:06:52.183761Z"}]}
{"channel":"book","type":"update","data":[{"symbol":"BTC/AUD","bids":[{"price":101761.9,"qty":0.00153024}],"asks":[],"checksum":3797682291,"timestamp":"2024-06-01T18:06:52.185677Z"}]}
{"channel":"book","type":"update","data":[{"symbol":"BTC/AUD","bids":[],"asks":[{"price":101924.9,"qty":0.00000000},{"price":101961.3,"qty":0.00525000}],"checksum":732927156,"timestamp":"2024-06-01T18:06:52.242640Z"}]}
{"channel":"book","type":"update","data":[{"symbol":"BTC/AUD","bids":[],"asks":[{"price":101924.7,"qty":0.46761190}],"checksum":1137858235,"timestamp":"2024-06-01T18:06:52.245461Z"}]}
{"channel":"book","type":"update","data":[{"symbol":"BTC/AUD","bids":[],"asks":[{"price":101924.8,"qty":0.00330787},{"price":101926.0,"qty":0.02932000}],"checksum":4211838405,"timestamp":"2024-06-01T18:06:52.246336Z"}]}
{"channel":"book","type":"update","data":[{"symbol":"BTC/AUD","bids":[],"asks":[{"price":101890.9,"qty":0.00000000},{"price":101947.0,"qty":0.09768924},{"price":101890.7,"qty":0.05373031}],"checksum":3320443988,"timestamp":"2024-06-01T18:06:52.249530Z"}]}
{"channel":"book","type":"update","data":[{"symbol":"BTC/AUD","bids":[],"asks":[{"price":101924.8,"qty":0.00000000},{"price":101947.0,"qty":0.09768924}],"checksum":2962033263,"timestamp":"2024-06-01T18:06:52.382386Z"}]}
{"channel":"book","type":"update","data":[{"symbol":"BTC/AUD","bids":[],"asks":[{"price":101924.7,"qty":0.47104425}],"checksum":2329307579,"timestamp":"2024-06-01T18:06:52.384471Z"}]}
{"channel":"book","type":"update","data":[{"symbol":"BTC/AUD","bids":[],"asks":[{"price":101890.6,"qty":0.04717373}],"checksum":4265930292,"timestamp":"2024-06-01T18:06:52.390286Z"}]}
{"channel":"book","type":"update","data":[{"symbol":"BTC/AUD","bids":[],"asks":[{"price":101890.7,"qty":0.00000000},{"price":101947.0,"qty":0.09768924},{"price":101890.5,"qty":0.05373031}],"checksum":813984793,"timestamp":"2024-06-01T18:06:52.648663Z"}]}
{"channel":"book","type":"update","data":[{"symbol":"BTC/AUD","bids":[],"asks":[{"price":101890.8,"qty":0.00000000},{"price":101947.0,"qty":0.09768924}],"checksum":334650864,"timestamp":"2024-06-01T18:06:52.654485Z"}]}
{"channel":"book","type":"update","data":[{"symbol":"BTC/AUD","bids":[],"asks":[{"price":101926.0,"qty":0.00000000},{"price":101961.3,"qty":0.00525000},{"price":101924.6,"qty":0.02932000}],"checksum":2370295929,"timestamp":"2024-06-01T18:06:52.807422Z"}]}
{"channel":"book","type":"update","data":[{"symbol":"BTC/AUD","bids":[],"asks":[{"price":101890.4,"qty":0.04717373}],"checksum":1769937282,"timestamp":"2024-06-01T18:06:53.179395Z"}]}
{"channel":"book","type":"update","data":[{"symbol":"BTC/AUD","bids":[],"asks":[{"price":101926.1,"qty":0.00000000},{"price":101947.0,"qty":0.09768924}],"checksum":3152806525,"timestamp":"2024-06-01T18:06:53.182028Z"}]}
{"channel":"book","type":"update","data":[{"symbol":"BTC/AUD","bids":[],"asks":[{"price":101890.6,"qty":0.00000000},{"price":101961.3,"qty":0.00525000}],"checksum":812570658,"timestamp":"2024-06-01T18:06:53.183856Z"}]}
{"channel":"book","type":"update","data":[{"symbol":"BTC/AUD","bids":[],"asks":[{"price":101926.2,"qty":0.62656681}],"checksum":1449909395,"timestamp":"2024-06-01T18:06:53.185288Z"}]}
{"channel":"book","type":"update","data":[{"symbol":"BTC/AUD","bids":[],"asks":[{"price":101890.5,"qty":0.00000000},{"price":101961.3,"qty":0.00525000},{"price":101890.3,"qty":0.05373031}],"checksum":2684805180,"timestamp":"2024-06-01T18:06:53.234775Z"}]}
{"channel":"book","type":"update","data":[{"symbol":"BTC/AUD","bids":[{"price":101763.8,"qty":0.02932000}],"asks":[],"checksum":2994966105,"timestamp":"2024-06-01T18:06:53.984438Z"}]}
{"channel":"book","type":"update","data":[{"symbol":"BTC/AUD","bids":[],"asks":[{"price":101890.2,"qty":0.04717373}],"checksum":2580688698,"timestamp":"2024-06-01T18:06:54.179572Z"}]}
{"channel":"book","type":"update","data":[{"symbol":"BTC/AUD","bids":[],"asks":[{"price":101890.4,"qty":0.00000000},{"price":101947.0,"qty":0.09768924}],"checksum":2524166686,"timestamp":"2024-06-01T18:06:54.183850Z"}]}
{"channel":"book","type":"update","data":[{"symbol":"BTC/AUD","bids":[],"asks":[{"price":101890.3,"qty":0.00000000},{"price":101961.3,"qty":0.00525000},{"price":101890.1,"qty":0.05373037}],"checksum":1460511861,"timestamp":"2024-06-01T18:06:54.225756Z"}]}
{"channel":"book","type":"update","data":[{"symbol":"BTC/AUD","bids":[{"price":101864.8,"qty":0.00000000},{"price":101761.9,"qty":0.00153024},{"price":101854.6,"qty":0.00474900}],"asks":[],"checksum":3667722200,"timestamp":"2024-06-01T18:06:54.344181Z"}]}
{"channel":"book","type":"update","data":[{"symbol":"BTC/AUD","bids":[{"price":101864.9,"qty":0.00000000},{"price":101761.9,"qty":0.00153024},{"price":101855.4,"qty":0.00075700}],"asks":[],"checksum":4127802858,"timestamp":"2024-06-01T18:06:54.366998Z"}]}
{"channel":"book","type":"update","data":[{"symbol":"BTC/AUD","bids":[],"asks":[{"price":101924.7,"qty":0.46761190}],"checksum":2576913923,"timestamp":"2024-06-01T18:06:54.750882Z"}]}
{"channel":"book","type":"update","data":[{"symbol":"BTC/AUD","bids":[],"asks":[{"price":101924.5,"qty":0.00334202}],"checksum":1350745300,"timestamp":"2024-06-01T18:06:54.753513Z"}]}
{"channel":"book","type":"update","data":[{"symbol":"BTC/AUD","bids":[{"price":101763.8,"qty":0.00000000},{"price":101761.9,"qty":0.00153024}],"asks":[],"checksum":424573429,"timestamp":"2024-06-01T18:06:55.063836Z"}]}
{"channel":"book","type":"update","data":[{"symbol":"BTC/AUD","bids":[],"asks":[{"price":101897.5,"qty":0.00000000},{"price":101947.0,"qty":0.09768924},{"price":101890.3,"qty":0.00474800}],"checksum":3170264236,"timestamp":"2024-06-01T18:06:55.088371Z"}]}
{"channel":"book","type":"update","data":[{"symbol":"BTC/AUD","bids":[],"asks":[{"price":101890.0,"qty":0.04717373}],"checksum":2872396829,"timestamp":"2024-06-01T18:06:55.093955Z"}]}
{"channel":"book","type":"update","data":[{"symbol":"BTC/AUD","bids":[],"asks":[{"price":101924.7,"qty":0.00000000},{"price":101940.6,"qty":0.05000000}],"checksum":1893285016,"timestamp":"2024-06-01T18:06:55.105493Z"}]}
{"channel":"book","type":"update","data":[{"symbol":"BTC/AUD","bids":[],"asks":[{"price":101924.6,"qty":0.00000000},{"price":101947.0,"qty":0.09768924},{"price":101926.1,"qty":0.02932000}],"checksum":2336776816,"timestamp":"2024-06-01T18:06:55.108879Z"}]}
{"channel":"book","type":"update","data":[{"symbol":"BTC/AUD","bids":[],"asks":[{"price":101924.5,"qty":0.47095404}],"checksum":1405184006,"timestamp":"2024-06-01T18:06:55.109025Z"}]}
{"channel":"book","type":"update","data":[{"symbol":"BTC/AUD","bids":[],"asks":[{"price":101926.1,"qty":0.30481449}],"checksum":3783683870,"timestamp":"2024-06-01T18:06:55.109053Z"}]}
{"channel":"book","type":"update","data":[{"symbol":"BTC/AUD","bids":[],"asks":[{"price":101890.1,"qty":0.00000000},{"price":101947.0,"qty":0.09768924},{"price":101889.9,"qty":0.05373037}],"checksum":93280500,"timestamp":"2024-06-01T18:06:55.150079Z"}]}
{"channel":"book","type":"update","data":[{"symbol":"BTC/AUD","bids":[],"asks":[{"price":101890.2,"qty":0.00000000},{"price":101947.0,"qty":0.09768924}],"checksum":357003973,"timestamp":"2024-06-01T18:06:55.155759Z"}]}
{"channel":"book","type":"update","data":[{"symbol":"BTC/AUD","bids":[],"asks":[{"price":101889.8,"qty":0.04717373}],"checksum":2709750035,"timestamp":"2024-06-01T18:06:55.178318Z"}]}
{"channel":"book","type":"update","data":[{"symbol":"BTC/AUD","bids":[],"asks":[{"price":101889.9,"qty":0.00000000},{"price":101947.0,"qty":0.09768924},{"price":101889.7,"qty":0.05373048}],"checksum":1263169133,"timestamp":"2024-06-01T18:06:55.519672Z"}]}
{"channel":"book","type":"update","data":[{"symbol":"BTC/AUD","bids":[],"asks":[{"price":101890.0,"qty":0.00000000},{"price":101947.0,"qty":0.09768924}],"checksum":1533912134,"timestamp":"2024-06-01T18:06:55.525249Z"}]}
{"channel":"book","type":"update","data":[{"symbol":"BTC/AUD","bids":[],"asks":[{"price":101889.6,"qty":0.04717373}],"checksum":423179255,"timestamp":"2024-06-01T18:06:56.178607Z"}]}
{"channel":"book","type":"update","data":[{"symbol":"BTC/AUD","bids":[],"asks":[{"price":101926.1,"qty":0.27549449},{"price":101924.4,"qty":0.02932000}],"checksum":1418199598,"timestamp":"2024-06-01T18:06:56.181640Z"}]}
{"channel":"book","type":"update","data":[{"symbol":"BTC/AUD","bids":[],"asks":[{"price":101889.8,"qty":0.00000000},{"price":101940.6,"qty":0.05000000}],"checksum":3355314433,"timestamp":"2024-06-01T18:06:56.182845Z"}]}
{"channel":"book","type":"update","data":[{"symbol":"BTC/AUD","bids":[],"asks":[{"price":101889.7,"qty":0.00000000},{"price":101947.0,"qty":0.09768924},{"price":101889.5,"qty":0.05373051}],"checksum":2443784952,"timestamp":"2024-06-01T18:06:56.235227Z"}]}
{"channel":"book","type":"update","data":[{"symbol":"BTC/AUD","bids":[],"asks":[{"price":101889.5,"qty":0.00000000},{"price":101947.0,"qty":0.09768924},{"price":101889.4,"qty":0.05373051}],"checksum":2096243252,"timestamp":"2024-06-01T18:06:56.595769Z"}]}
{"channel":"book","type":"update","data":[{"symbol":"BTC/AUD","bids":[],"asks":[{"price":101889.4,"qty":0.00000000},{"price":101947.0,"qty":0.09768924},{"price":101889.5,"qty":0.05373052}],"checksum":3550409654,"timestamp":"2024-06-01T18:06:56.655378Z"}]}
{"channel":"book","type":"update","data":[{"symbol":"BTC/AUD","bids":[],"asks":[{"price":101889.5,"qty":0.00000000},{"price":101947.0,"qty":0.09768924},{"price":101889.4,"qty":0.05373052}],"checksum":1053156218,"timestamp":"2024-06-01T18:06:56.914065Z"}]}
{"channel":"book","type":"update","data":[{"symbol":"BTC/AUD","bids":[],"asks":[{"price":101889.3,"qty":0.04717373}],"checksum":3581969806,"timestamp":"2024-06-01T18:06:56.919453Z"}]}
{"channel":"book","type":"update","data":[{"symbol":"BTC/AUD","bids":[{"price":101824.2,"qty":0.00000000},{"price":101760.2,"qty":0.02932000}],"asks":[],"checksum":3122394581,"timestamp":"2024-06-01T18:06:57.124150Z"}]}
{"channel":"book","type":"update","data":[{"symbol":"BTC/AUD","bids":[{"price":101760.3,"qty":0.08718275}],"asks":[],"checksum":3239693911,"timestamp":"2024-06-01T18:06:57.125178Z"}]}
{"channel":"book","type":"update","data":[{"symbol":"BTC/AUD","bids":[{"price":101760.4,"qty":0.02932000}],"asks":[],"checksum":2088041554,"timestamp":"2024-06-01T18:06:57.127897Z"}]}
{"channel":"book","type":"update","data":[{"symbol":"BTC/AUD","bids":[],"asks":[{"price":101889.6,"qty":0.00000000},{"price":101940.6,"qty":0.05000000}],"checksum":3985463099,"timestamp":"2024-06-01T18:06:57.177945Z"}]}
{"channel":"book","type":"update","data":[{"symbol":"BTC/AUD","bids":[],"asks":[{"price":101924.5,"qty":0.46761202}],"checksum":2492923966,"timestamp":"2024-06-01T18:06:57.198736Z"}]}
{"channel":"book","type":"update","data":[{"symbol":"BTC/AUD","bids":[],"asks":[{"price":101924.3,"qty":0.00358174}],"checksum":1348894650,"timestamp":"2024-06-01T18:06:57.201870Z"}]}
{"channel":"book","type":"update","data":[{"symbol":"BTC/AUD","bids":[],"asks":[{"price":101889.4,"qty":0.00000000},{"price":101940.6,"qty":0.05000000},{"price":101889.2,"qty":0.05373052}],"checksum":2461256194,"timestamp":"2024-06-01T18:06:57.298931Z"}]}
{"channel":"book","type":"update","data":[{"symbol":"BTC/AUD","bids":[],"asks":[{"price":101889.2,"qty":0.00000000},{"price":101940.6,"qty":0.05000000},{"price":101889.1,"qty":0.05373059}],"checksum":3096107088,"timestamp":"2024-06-01T18:06:57.703114Z"}]}
{"channel":"book","type":"update","data":[{"symbol":"BTC/AUD","bids":[],"asks":[{"price":101889.1,"qty":0.00000000},{"price":101940.6,"qty":0.05000000},{"price":101889.2,"qty":0.05373059}],"checksum":1196419985,"timestamp":"2024-06-01T18:06:57.747109Z"}]}
{"channel":"book","type":"update","data":[{"symbol":"BTC/AUD","bids":[],"asks":[{"price":101924.5,"qty":0.00000000},{"price":101947.0,"qty":0.09768924}],"checksum":1311527509,"timestamp":"2024-06-01T18:06:57.897474Z"}]}
{"channel":"book","type":"update","data":[{"symbol":"BTC/AUD","bids":[],"asks":[{"price":101924.4,"qty":0.00000000},{"price":101961.3,"qty":0.00525000},{"price":101926.0,"qty":0.02932000}],"checksum":3653701874,"timestamp":"2024-06-01T18:06:57.900716Z"}]}
{"channel":"book","type":"update","data":[{"symbol":"BTC/AUD","bids":[],"asks":[{"price":101924.2,"qty":0.46782256}],"checksum":2358400184,"timestamp":"2024-06-01T18:06:57.901686Z"}]}
{"channel":"book","type":"update","data":[{"symbol":"BTC/AUD","bids":[],"asks":[{"price":101889.1,"qty":0.04717373}],"checksum":2892127700,"timestamp":"2024-06-01T18:06:58.178428Z"}]}
{"channel":"book","type":"update","data":[{"symbol":"BTC/AUD","bids":[],"asks":[{"price":101889.3,"qty":0.00000000},{"price":101932.3,"qty":0.00135100}],"checksum":87888535,"timestamp":"2024-06-01T18:06:58.184534Z"}]}
{"channel":"book","type":"update","data":[{"symbol":"BTC/AUD","bids":[],"asks":[{"price":101889.2,"qty":0.00000000},{"price":101947.0,"qty":0.09768924},{"price":101889.0,"qty":0.05373060}],"checksum":2359180447,"timestamp":"2024-06-01T18:06:58.216796Z"}]}
{"channel":"book","type":"update","data":[{"symbol":"BTC/AUD","bids":[],"asks":[{"price":101888.9,"qty":0.04717373}],"checksum":3764002979,"timestamp":"2024-06-01T18:06:58.221556Z"}]}
{"channel":"book","type":"update","data":[{"symbol":"BTC/AUD","bids":[{"price":101760.5,"qty":0.00058362}],"asks":[],"checksum":2187488123,"timestamp":"2024-06-01T18:06:58.586996Z"}]}
{"channel":"book","type":"update","data":[{"symbol":"BTC/AUD","bids":[],"asks":[{"price":101926.0,"qty":0.00000000},{"price":101932.3,"qty":0.00135100},{"price":101924.1,"qty":0.02932000}],"checksum":836193388,"timestamp":"2024-06-01T18:06:58.589758Z"}]}
{"channel":"book","type":"update","data":[{"symbol":"BTC/AUD","bids":[],"asks":[{"price":101889.0,"qty":0.00000000},{"price":101932.3,"qty":0.00135100},{"price":101888.8,"qty":0.05373060}],"checksum":99483201,"timestamp":"2024-06-01T18:06:58.656451Z"}]}
{"channel":"book","type":"update","data":[{"symbol":"BTC/AUD","bids":[],"asks":[{"price":101889.1,"qty":0.00000000},{"price":101932.3,"qty":0.00135100}],"checksum":4179134837,"timestamp":"2024-06-01T18:06:58.662246Z"}]}
{"channel":"book","type":"update","data":[{"symbol":"BTC/AUD","bids":[],"asks":[{"price":101888.7,"qty":0.04717373}],"checksum":4232186581,"timestamp":"2024-06-01T18:06:59.179116Z"}]}
{"channel":"book","type":"update","data":[{"symbol":"BTC/AUD","bids":[],"asks":[{"price":101888.9,"qty":0.00000000},{"price":101932.3,"qty":0.00135100}],"checksum":2341931659,"timestamp":"2024-06-01T18:06:59.184700Z"}]}
{"channel":"book","type":"update","data":[{"symbol":"BTC/AUD","bids":[],"asks":[{"price":101888.8,"qty":0.00000000},{"price":101947.0,"qty":0.09768924},{"price":101888.6,"qty":0.05373060}],"checksum":2770945228,"timestamp":"2024-06-01T18:06:59.229592Z"}]}
{"channel":"book","type":"update","data":[{"symbol":"BTC/AUD","bids":[],"asks":[{"price":101924.3,"qty":0.00000000},{"price":101947.0,"qty":0.09768924}],"checksum":868622420,"timestamp":"2024-06-01T18:06:59.518474Z"}]}
{"channel":"book","type":"update","data":[{"symbol":"BTC/AUD","bids":[],"asks":[{"price":101924.0,"qty":0.00373112}],"checksum":4171536220,"timestamp":"2024-06-01T18:06:59.521024Z"}]}
{"channel":"book","type":"update","data":[{"symbol":"BTC/AUD","bids":[],"asks":[{"price":101929.4,"qty":0.00623000}],"checksum":3947587732,"timestamp":"2024-06-01T18:07:00.095668Z"}]}
{"channel":"book","type":"update","data":[{"symbol":"BTC/AUD","bids":[{"price":101760.5,"qty":0.11658694}],"asks":[],"checksum":799346785,"timestamp":"2024-06-01T18:07:00.169337Z"}]}
{"channel":"book","type":"update","data":[{"symbol":"BTC/AUD","bids":[],"asks":[{"price":101888.5,"qty":0.04717373}],"checksum":1172514500,"timestamp":"2024-06-01T18:07:00.178839Z"}]}
{"channel":"book","type":"update","data":[{"symbol":"BTC/AUD","bids":[],"asks":[{"price":101888.7,"qty":0.00000000},{"price":101929.4,"qty":0.00623000}],"checksum":4190423846,"timestamp":"2024-06-01T18:07:00.183003Z"}]}
{"channel":"book","type":"update","data":[{"symbol":"BTC/AUD","bids":[],"asks":[{"price":101888.6,"qty":0.00000000},{"price":101932.3,"qty":0.00135100},{"price":101888.4,"qty":0.05373054}],"checksum":1729303841,"timestamp":"2024-06-01T18:07:00.230187Z"}]}
{"channel":"book","type":"update","data":[{"symbol":"BTC/AUD","bids":[],"asks":[{"price":101895.6,"qty":0.00000000},{"price":101932.3,"qty":0.00135100},{"price":101888.4,"qty":0.05448754}],"checksum":1080101042,"timestamp":"2024-06-01T18:07:00.354615Z"}]}
{"channel":"book","type":"update","data":[{"symbol":"BTC/AUD","bids":[],"asks":[{"price":101888.4,"qty":0.00075700},{"price":101888.3,"qty":0.05373053}],"checksum":3060044889,"timestamp":"2024-06-01T18:07:00.617331Z"}]}
{"channel":"book","type":"update","data":[{"symbol":"BTC/AUD","bids":[],"asks":[{"price":101926.1,"qty":0.00000000},{"price":101932.3,"qty":0.00135100}],"checksum":2752663962,"timestamp":"2024-06-01T18:07:00.720583Z"}]}
{"channel":"book","type":"update","data":[{"symbol":"BTC/AUD","bids":[],"asks":[{"price":101924.2,"qty":0.00000000},{"price":101947.0,"qty":0.09768924}],"checksum":4284877076,"timestamp":"2024-06-01T18:07:00.720964Z"}]}
{"channel":"book","type":"update","data":[{"symbol":"BTC/AUD","bids":[],"asks":[{"price":101926.1,"qty":0.29845910}],"checksum":300079312,"timestamp":"2024-06-01T18:07:00.723477Z"}]}
{"channel":"book","type":"update","data":[{"symbol":"BTC/AUD","bids":[],"asks":[{"price":101923.9,"qty":0.46765181}],"checksum":1528141837,"timestamp":"2024-06-01T18:07:00.723501Z"}]}
{"channel":"book","type":"update","data":[{"symbol":"BTC/AUD","bids":[{"price":101760.6,"qty":0.02932000}],"asks":[],"checksum":3821668077,"timestamp":"2024-06-01T18:07:00.723737Z"}]}
{"channel":"book","type":"update","data":[{"symbol":"BTC/AUD","bids":[],"asks":[{"price":101924.1,"qty":0.00000000},{"price":101932.3,"qty":0.00135100},{"price":101926.1,"qty":0.32777910}],"checksum":3848604367,"timestamp":"2024-06-01T18:07:00.724136Z"}]}
{"channel":"book","type":"update","data":[{"symbol":"BTC/AUD","bids":[{"price":101833.1,"qty":0.00000000},{"price":101760.5,"qty":0.11658694},{"price":101825.7,"qty":0.00135100}],"asks":[],"checksum":3144745620,"timestamp":"2024-06-01T18:07:00.962982Z"}]}
{"channel":"book","type":"update","data":[{"symbol":"BTC/AUD","bids":[],"asks":[{"price":101888.2,"qty":0.04717373}],"checksum":1622183413,"timestamp":"2024-06-01T18:07:00.968531Z"}]}
{"channel":"book","type":"update","data":[{"symbol":"BTC/AUD","bids":[{"price":101833.2,"qty":0.00000000},{"price":101760.5,"qty":0.11658694},{"price":101831.2,"qty":0.05376721}],"asks":[],"checksum":3634719966,"timestamp":"2024-06-01T18:07:01.009201Z"}]}
{"channel":"book","type":"update","data":[{"symbol":"BTC/AUD","bids":[],"asks":[{"price":101888.5,"qty":0.00000000},{"price":101932.3,"qty":0.00135100}],"checksum":887271819,"timestamp":"2024-06-01T18:07:01.014131Z"}]}
{"channel":"book","type":"update","data":[{"symbol":"BTC/AUD","bids":[],"asks":[{"price":101888.3,"qty":0.00000000},{"price":101947.0,"qty":0.09768924},{"price":101888.1,"qty":0.05373053}],"checksum":1061445665,"timestamp":"2024-06-01T18:07:01.046859Z"}]}
{"channel":"book","type":"update","data":[{"symbol":"BTC/AUD","bids":[],"asks":[{"price":101888.0,"qty":0.04717373}],"checksum":2486449976,"timestamp":"2024-06-01T18:07:01.051892Z"}]}
