{"channel":"book","type":"snapshot","data":[{"symbol":"BTC/USD","bids":[{"price":67732.5,"qty":0.00153024},{"price":67707.9,"qty":0.00010000},{"price":67705.4,"qty":0.00576586},{"price":67703.2,"qty":0.07991487},{"price":67699.4,"qty":0.00120000},{"price":67698.5,"qty":0.33750000},{"price":67696.8,"qty":0.00188900},{"price":67691.5,"qty":0.02951977},{"price":67690.5,"qty":0.24000000},{"price":67690.4,"qty":0.44383720}],"asks":[{"price":67732.6,"qty":19.03737786},{"price":67732.9,"qty":0.57919679},{"price":67733.0,"qty":0.00010000},{"price":67733.3,"qty":0.17716100},{"price":67733.9,"qty":0.87444314},{"price":67734.4,"qty":0.06403000},{"price":67734.7,"qty":0.02665858},{"price":67736.2,"qty":0.02309133},{"price":67738.4,"qty":0.07515247},{"price":67739.4,"qty":1.07092233}],"checksum":1421740250}]}
{"channel":"book","type":"update","data":[{"symbol":"BTC/USD","bids":[{"price":67693.0,"qty":0.06910000}],"asks":[],"checksum":3663751606,"timestamp":"2024-06-01T18:06:34.502543Z"}]}
{"channel":"book","type":"update","data":[{"symbol":"BTC/USD","bids":[{"price":67690.6,"qty":0.91892883}],"asks":[],"checksum":4164338719,"timestamp":"2024-06-01T18:06:34.631665Z"}]}
{"channel":"book","type":"update","data":[{"symbol":"BTC/USD","bids":[{"price":67690.7,"qty":0.24000000}],"asks":[],"checksum":4103487792,"timestamp":"2024-06-01T18:06:34.635003Z"}]}
{"channel":"book","type":"update","data":[{"symbol":"BTC/USD","bids":[{"price":67693.1,"qty":0.00111667}],"asks":[],"checksum":1155286814,"timestamp":"2024-06-01T18:06:34.723657Z"}]}
{"channel":"book","type":"update","data":[{"symbol":"BTC/USD","bids":[{"price":67691.9,"qty":0.06910000}],"asks":[],"checksum":1962184460,"timestamp":"2024-06-01T18:06:34.875667Z"}]}
{"channel":"book","type":"update","data":[{"symbol":"BTC/USD","bids":[{"price":67693.0,"qty":0.00000000},{"price":67691.5,"qty":0.02951977},{"price":67691.9,"qty":0.13820000}],"asks":[],"checksum":284487528,"timestamp":"2024-06-01T18:06:34.875867Z"}]}
{"channel":"book","type":"update","data":[{"symbol":"BTC/USD","bids":[],"asks":[{"price":67732.9,"qty":0.00000000},{"price":67741.5,"qty":0.71000000},{"price":67732.6,"qty":19.61657465}],"checksum":4185064313,"timestamp":"2024-06-01T18:06:34.878852Z"}]}
{"channel":"book","type":"update","data":[{"symbol":"BTC/USD","bids":[{"price":67693.1,"qty":0.00000000},{"price":67690.7,"qty":0.24000000},{"price":67692.0,"qty":0.00111668}],"asks":[],"checksum":466181692,"timestamp":"2024-06-01T18:06:34.932578Z"}]}
{"channel":"book","type":"update","data":[{"symbol":"BTC/USD","bids":[{"price":67691.9,"qty":0.06910000}],"asks":[],"checksum":919237049,"timestamp":"2024-06-01T18:06:34.954233Z"}]}
{"channel":"book","type":"update","data":[{"symbol":"BTC/USD","bids":[{"price":67692.0,"qty":0.00000000},{"price":67690.7,"qty":0.24000000}],"asks":[],"checksum":1787101064,"timestamp":"2024-06-01T18:06:35.001467Z"}]}
{"channel":"book","type":"update","data":[{"symbol":"BTC/USD","bids":[{"price":67690.8,"qty":0.00111670}],"asks":[],"checksum":2668412689,"timestamp":"2024-06-01T18:06:35.149558Z"}]}
{"channel":"book","type":"update","data":[{"symbol":"BTC/USD","bids":[],"asks":[{"price":67739.3,"qty":8.16844333}],"checksum":900503942,"timestamp":"2024-06-01T18:06:35.474017Z"}]}
{"channel":"book","type":"update","data":[{"symbol":"BTC/USD","bids":[],"asks":[{"price":67739.3,"qty":8.20857294}],"checksum":2870275513,"timestamp":"2024-06-01T18:06:35.570859Z"}]}
{"channel":"book","type":"update","data":[{"symbol":"BTC/USD","bids":[],"asks":[{"price":67733.2,"qty":0.71000000}],"checksum":2574799761,"timestamp":"2024-06-01T18:06:35.642766Z"}]}
{"channel":"book","type":"update","data":[{"symbol":"BTC/USD","bids":[{"price":67691.9,"qty":0.00000000},{"price":67690.7,"qty":0.24000000},{"price":67692.9,"qty":0.06910000}],"asks":[],"checksum":4110328011,"timestamp":"2024-06-01T18:06:36.408198Z"}]}
{"channel":"book","type":"update","data":[{"symbol":"BTC/USD","bids":[{"price":67692.9,"qty":0.13820000}],"asks":[],"checksum":2438500688,"timestamp":"2024-06-01T18:06:36.409720Z"}]}
{"channel":"book","type":"update","data":[{"symbol":"BTC/USD","bids":[],"asks":[{"price":67732.6,"qty":19.03737786},{"price":67732.9,"qty":0.57919679}],"checksum":1129160685,"timestamp":"2024-06-01T18:06:36.411545Z"}]}
{"channel":"book","type":"update","data":[{"symbol":"BTC/USD","bids":[{"price":67692.9,"qty":0.06910000}],"asks":[],"checksum":3967148269,"timestamp":"2024-06-01T18:06:36.503043Z"}]}
{"channel":"book","type":"update","data":[{"symbol":"BTC/USD","bids":[{"price":67690.8,"qty":0.00000000},{"price":67690.7,"qty":0.24000000}],"asks":[],"checksum":693726757,"timestamp":"2024-06-01T18:06:36.656812Z"}]}
{"channel":"book","type":"update","data":[{"symbol":"BTC/USD","bids":[{"price":67692.9,"qty":0.00000000},{"price":67690.4,"qty":0.44383720}],"asks":[],"checksum":2970124883,"timestamp":"2024-06-01T18:06:36.738127Z"}]}
{"channel":"book","type":"update","data":[{"symbol":"BTC/USD","bids":[{"price":67690.8,"qty":0.00111674}],"asks":[],"checksum":3445858526,"timestamp":"2024-06-01T18:06:36.827248Z"}]}
{"channel":"book","type":"update","data":[{"symbol":"BTC/USD","bids":[{"price":67692.7,"qty":0.06910000}],"asks":[],"checksum":835897095,"timestamp":"2024-06-01T18:06:36.954865Z"}]}
{"channel":"book","type":"update","data":[{"symbol":"BTC/USD","bids":[],"asks":[{"price":67732.6,"qty":19.03707945}],"checksum":3132746784,"timestamp":"2024-06-01T18:06:37.263546Z"}]}
{"channel":"book","type":"update","data":[{"symbol":"BTC/USD","bids":[{"price":67692.7,"qty":0.00000000},{"price":67690.7,"qty":0.24000000},{"price":67691.6,"qty":0.06910000}],"asks":[],"checksum":3788345225,"timestamp":"2024-06-01T18:06:37.437683Z"}]}
{"channel":"book","type":"update","data":[{"symbol":"BTC/USD","bids":[{"price":67691.6,"qty":0.13820000}],"asks":[],"checksum":1788773342,"timestamp":"2024-06-01T18:06:37.440630Z"}]}
{"channel":"book","type":"update","data":[{"symbol":"BTC/USD","bids":[{"price":67690.8,"qty":0.00000000},{"price":67690.7,"qty":0.24000000}],"asks":[],"checksum":243275200,"timestamp":"2024-06-01T18:06:37.607024Z"}]}
{"channel":"book","type":"update","data":[{"symbol":"BTC/USD","bids":[{"price":67691.6,"qty":0.06910000}],"asks":[],"checksum":4073462059,"timestamp":"2024-06-01T18:06:37.610735Z"}]}
{"channel":"book","type":"update","data":[{"symbol":"BTC/USD","bids":[{"price":67690.8,"qty":0.00111659}],"asks":[],"checksum":2907345334,"timestamp":"2024-06-01T18:06:37.764932Z"}]}
{"channel":"book","type":"update","data":[{"symbol":"BTC/USD","bids":[{"price":67690.8,"qty":0.00000000},{"price":67690.7,"qty":0.24000000}],"asks":[],"checksum":4073462059,"timestamp":"2024-06-01T18:06:38.195081Z"}]}
{"channel":"book","type":"update","data":[{"symbol":"BTC/USD","bids":[],"asks":[{"price":67732.9,"qty":0.00000000},{"price":67739.2,"qty":0.13388508},{"price":67732.6,"qty":19.61627624}],"checksum":2509380577,"timestamp":"2024-06-01T18:06:38.198614Z"}]}
{"channel":"book","type":"update","data":[{"symbol":"BTC/USD","bids":[],"asks":[{"price":67732.6,"qty":19.61657733}],"checksum":2046260814,"timestamp":"2024-06-01T18:06:38.457240Z"}]}
{"channel":"book","type":"update","data":[{"symbol":"BTC/USD","bids":[],"asks":[{"price":67732.6,"qty":19.61627624}],"checksum":2509380577,"timestamp":"2024-06-01T18:06:39.707015Z"}]}
{"channel":"book","type":"update","data":[{"symbol":"BTC/USD","bids":[],"asks":[{"price":67732.6,"qty":19.03707945},{"price":67732.9,"qty":0.57919679}],"checksum":4073462059,"timestamp":"2024-06-01T18:06:39.710271Z"}]}
{"channel":"book","type":"update","data":[{"symbol":"BTC/USD","bids":[],"asks":[{"price":67732.6,"qty":19.03738729}],"checksum":3547468787,"timestamp":"2024-06-01T18:06:40.710829Z"}]}
{"channel":"book","type":"update","data":[{"symbol":"BTC/USD","bids":[{"price":67690.8,"qty":0.00111674}],"asks":[],"checksum":521051143,"timestamp":"2024-06-01T18:06:40.837002Z"}]}
{"channel":"book","type":"update","data":[{"symbol":"BTC/USD","bids":[{"price":67690.8,"qty":0.00000000},{"price":67690.7,"qty":0.24000000}],"asks":[],"checksum":3547468787,"timestamp":"2024-06-01T18:06:41.173739Z"}]}
{"channel":"book","type":"update","data":[{"symbol":"BTC/USD","bids":[{"price":67690.8,"qty":0.00111674}],"asks":[],"checksum":521051143,"timestamp":"2024-06-01T18:06:41.242506Z"}]}
{"channel":"book","type":"update","data":[{"symbol":"BTC/USD","bids":[],"asks":[{"price":67732.9,"qty":0.00000000},{"price":67739.4,"qty":1.07092233},{"price":67732.6,"qty":19.61658408}],"checksum":421691431,"timestamp":"2024-06-01T18:06:41.245842Z"}]}
{"channel":"book","type":"update","data":[{"symbol":"BTC/USD","bids":[{"price":67690.8,"qty":0.00000000},{"price":67690.7,"qty":0.24000000}],"asks":[],"checksum":1391947058,"timestamp":"2024-06-01T18:06:41.513338Z"}]}
{"channel":"book","type":"update","data":[{"symbol":"BTC/USD","bids":[{"price":67690.8,"qty":0.00111678}],"asks":[],"checksum":278187020,"timestamp":"2024-06-01T18:06:41.626954Z"}]}
{"channel":"book","type":"update","data":[{"symbol":"BTC/USD","bids":[],"asks":[{"price":67733.2,"qty":0.00000000},{"price":67741.7,"qty":0.73083685},{"price":67734.2,"qty":0.71000000}],"checksum":997126484,"timestamp":"2024-06-01T18:06:41.644309Z"}]}
{"channel":"book","type":"update","data":[{"symbol":"BTC/USD","bids":[],"asks":[{"price":67732.6,"qty":19.49857508}],"checksum":2832056075,"timestamp":"2024-06-01T18:06:41.645746Z"}]}
{"channel":"book","type":"update","data":[{"symbol":"BTC/USD","bids":[{"price":67690.8,"qty":0.00000000},{"price":67690.7,"qty":0.24000000}],"asks":[],"checksum":3568984874,"timestamp":"2024-06-01T18:06:41.696775Z"}]}
{"channel":"book","type":"update","data":[{"symbol":"BTC/USD","bids":[{"price":67691.6,"qty":0.00000000},{"price":67690.4,"qty":0.44383720},{"price":67693.0,"qty":0.06910000}],"asks":[],"checksum":3925718578,"timestamp":"2024-06-01T18:06:41.711107Z"}]}
{"channel":"book","type":"update","data":[{"symbol":"BTC/USD","bids":[{"price":67693.0,"qty":0.13820000}],"asks":[],"checksum":1794149551,"timestamp":"2024-06-01T18:06:41.714245Z"}]}
{"channel":"book","type":"update","data":[{"symbol":"BTC/USD","bids":[{"price":67693.0,"qty":0.06910000},{"price":67693.9,"qty":0.06910000}],"asks":[],"checksum":1339517812,"timestamp":"2024-06-01T18:06:41.792617Z"}]}
{"channel":"book","type":"update","data":[{"symbol":"BTC/USD","bids":[{"price":67693.0,"qty":0.00000000},{"price":67690.7,"qty":0.24000000}],"asks":[],"checksum":3961913599,"timestamp":"2024-06-01T18:06:41.792717Z"}]}
{"channel":"book","type":"update","data":[{"symbol":"BTC/USD","bids":[],"asks":[{"price":67732.6,"qty":19.61646608}],"checksum":707369462,"timestamp":"2024-06-01T18:06:41.798712Z"}]}
{"channel":"book","type":"update","data":[{"symbol":"BTC/USD","bids":[{"price":67693.9,"qty":0.13820000}],"asks":[],"checksum":4131020329,"timestamp":"2024-06-01T18:06:41.800354Z"}]}
{"channel":"book","type":"update","data":[{"symbol":"BTC/USD","bids":[{"price":67693.9,"qty":0.06910000}],"asks":[],"checksum":707369462,"timestamp":"2024-06-01T18:06:41.803243Z"}]}
{"channel":"book","type":"update","data":[{"symbol":"BTC/USD","bids":[{"price":67691.6,"qty":0.00111676}],"asks":[],"checksum":3175450535,"timestamp":"2024-06-01T18:06:41.870013Z"}]}
{"channel":"book","type":"update","data":[{"symbol":"BTC/USD","bids":[{"price":67691.6,"qty":0.00000000},{"price":67690.7,"qty":0.24000000},{"price":67698.6,"qty":0.00111665}],"asks":[],"checksum":1769125268,"timestamp":"2024-06-01T18:06:42.026061Z"}]}
{"channel":"book","type":"update","data":[{"symbol":"BTC/USD","bids":[],"asks":[{"price":67732.6,"qty":19.60982268}],"checksum":305489930,"timestamp":"2024-06-01T18:06:43.203869Z"}]}
{"channel":"book","type":"update","data":[{"symbol":"BTC/USD","bids":[],"asks":[{"price":67732.6,"qty":19.03062589},{"price":67732.9,"qty":0.57919679}],"checksum":3586559460,"timestamp":"2024-06-01T18:06:43.207633Z"}]}
{"channel":"book","type":"update","data":[{"symbol":"BTC/USD","bids":[],"asks":[{"price":67737.5,"qty":0.91730373}],"checksum":327134494,"timestamp":"2024-06-01T18:06:44.309590Z"}]}
{"channel":"book","type":"update","data":[{"symbol":"BTC/USD","bids":[],"asks":[{"price":67732.6,"qty":19.03031805}],"checksum":2718730910,"timestamp":"2024-06-01T18:06:44.463147Z"}]}
{"channel":"book","type":"update","data":[{"symbol":"BTC/USD","bids":[],"asks":[{"price":67732.8,"qty":0.00328297}],"checksum":4066924356,"timestamp":"2024-06-01T18:06:45.197202Z"}]}
{"channel":"book","type":"update","data":[{"symbol":"BTC/USD","bids":[],"asks":[{"price":67732.9,"qty":0.00000000},{"price":67737.5,"qty":0.91730373},{"price":67732.6,"qty":19.60951484}],"checksum":1065359053,"timestamp":"2024-06-01T18:06:45.200206Z"}]}
{"channel":"book","type":"update","data":[{"symbol":"BTC/USD","bids":[{"price":67693.9,"qty":0.00000000},{"price":67691.3,"qty":0.24000000}],"asks":[],"checksum":1118708824,"timestamp":"2024-06-01T18:06:45.751649Z"}]}
{"channel":"book","type":"update","data":[{"symbol":"BTC/USD","bids":[{"price":67693.5,"qty":0.06910000}],"asks":[],"checksum":143334144,"timestamp":"2024-06-01T18:06:45.983320Z"}]}
{"channel":"book","type":"update","data":[{"symbol":"BTC/USD","bids":[{"price":67698.6,"qty":0.00000000},{"price":67691.3,"qty":0.24000000},{"price":67693.6,"qty":0.00111660}],"asks":[],"checksum":171392657,"timestamp":"2024-06-01T18:06:46.162168Z"}]}
{"channel":"book","type":"update","data":[{"symbol":"BTC/USD","bids":[{"price":67693.6,"qty":0.00000000},{"price":67691.3,"qty":0.24000000},{"price":67698.6,"qty":0.00111652}],"asks":[],"checksum":2837444188,"timestamp":"2024-06-01T18:06:46.220510Z"}]}
{"channel":"book","type":"update","data":[{"symbol":"BTC/USD","bids":[],"asks":[{"price":67732.6,"qty":22.33251484}],"checksum":2751412887,"timestamp":"2024-06-01T18:06:46.402312Z"}]}
{"channel":"book","type":"update","data":[{"symbol":"BTC/USD","bids":[],"asks":[{"price":67732.6,"qty":19.54551484}],"checksum":2547136722,"timestamp":"2024-06-01T18:06:46.412243Z"}]}
{"channel":"book","type":"update","data":[{"symbol":"BTC/USD","bids":[],"asks":[{"price":67732.8,"qty":0.00000000},{"price":67738.4,"qty":0.07515247}],"checksum":1732864580,"timestamp":"2024-06-01T18:06:47.636963Z"}]}
{"channel":"book","type":"update","data":[{"symbol":"BTC/USD","bids":[],"asks":[{"price":67732.6,"qty":18.96631805},{"price":67732.9,"qty":0.57919679}],"checksum":2764089004,"timestamp":"2024-06-01T18:06:47.640418Z"}]}
{"channel":"book","type":"update","data":[{"symbol":"BTC/USD","bids":[],"asks":[{"price":67734.2,"qty":0.00000000},{"price":67738.4,"qty":0.07515247},{"price":67736.0,"qty":0.71000000}],"checksum":2532188891,"timestamp":"2024-06-01T18:06:47.644775Z"}]}
{"channel":"book","type":"update","data":[{"symbol":"BTC/USD","bids":[{"price":67707.9,"qty":0.00000000},{"price":67691.3,"qty":0.24000000},{"price":67702.9,"qty":0.00010000}],"asks":[],"checksum":1793038617,"timestamp":"2024-06-01T18:06:49.399938Z"}]}
{"channel":"book","type":"update","data":[{"symbol":"BTC/USD","bids":[],"asks":[{"price":67732.9,"qty":0.00000000},{"price":67738.4,"qty":0.07515247},{"price":67732.6,"qty":19.54551484}],"checksum":2278689041,"timestamp":"2024-06-01T18:06:49.403232Z"}]}
{"channel":"book","type":"update","data":[{"symbol":"BTC/USD","bids":[],"asks":[{"price":67732.8,"qty":3.81078728}],"checksum":2577918754,"timestamp":"2024-06-01T18:06:49.568101Z"}]}
{"channel":"book","type":"update","data":[{"symbol":"BTC/USD","bids":[{"price":67705.4,"qty":0.00000000},{"price":67691.3,"qty":0.24000000}],"asks":[],"checksum":1618393940,"timestamp":"2024-06-01T18:06:49.839070Z"}]}
{"channel":"book","type":"update","data":[{"symbol":"BTC/USD","bids":[],"asks":[{"price":67732.7,"qty":0.09888505}],"checksum":673819885,"timestamp":"2024-06-01T18:06:50.035715Z"}]}
{"channel":"book","type":"update","data":[{"symbol":"BTC/USD","bids":[{"price":67701.8,"qty":0.03074411}],"asks":[],"checksum":3893305387,"timestamp":"2024-06-01T18:06:50.093970Z"}]}
{"channel":"book","type":"update","data":[{"symbol":"BTC/USD","bids":[],"asks":[{"price":67732.8,"qty":0.00000000},{"price":67737.5,"qty":0.91730373}],"checksum":4026614417,"timestamp":"2024-06-01T18:06:52.241936Z"}]}
{"channel":"book","type":"update","data":[{"symbol":"BTC/USD","bids":[],"asks":[{"price":67733.8,"qty":0.95179591}],"checksum":3577616700,"timestamp":"2024-06-01T18:06:52.244677Z"}]}
{"channel":"book","type":"update","data":[{"symbol":"BTC/USD","bids":[],"asks":[{"price":67732.7,"qty":0.00000000},{"price":67737.5,"qty":0.91730373}],"checksum":2955596187,"timestamp":"2024-06-01T18:06:52.382183Z"}]}
{"channel":"book","type":"update","data":[{"symbol":"BTC/USD","bids":[],"asks":[{"price":67732.7,"qty":0.09968174}],"checksum":1867682369,"timestamp":"2024-06-01T18:06:52.384102Z"}]}
{"channel":"book","type":"update","data":[{"symbol":"BTC/USD","bids":[],"asks":[{"price":67732.6,"qty":18.96631805},{"price":67732.9,"qty":0.57919679}],"checksum":1750616741,"timestamp":"2024-06-01T18:06:52.385363Z"}]}
{"channel":"book","type":"update","data":[{"symbol":"BTC/USD","bids":[{"price":67698.6,"qty":0.00000000},{"price":67691.3,"qty":0.24000000}],"asks":[],"checksum":4191647690,"timestamp":"2024-06-01T18:06:52.594580Z"}]}
{"channel":"book","type":"update","data":[{"symbol":"BTC/USD","bids":[{"price":67698.6,"qty":0.00111657}],"asks":[],"checksum":915619233,"timestamp":"2024-06-01T18:06:52.837799Z"}]}
{"channel":"book","type":"update","data":[{"symbol":"BTC/USD","bids":[{"price":67691.7,"qty":1.47728523}],"asks":[],"checksum":931212934,"timestamp":"2024-06-01T18:06:52.894513Z"}]}
{"channel":"book","type":"update","data":[{"symbol":"BTC/USD","bids":[{"price":67691.8,"qty":0.24000000}],"asks":[],"checksum":2668572222,"timestamp":"2024-06-01T18:06:52.898057Z"}]}
{"channel":"book","type":"update","data":[{"symbol":"BTC/USD","bids":[{"price":67698.6,"qty":0.00000000},{"price":67691.5,"qty":0.02951977}],"asks":[],"checksum":2604668851,"timestamp":"2024-06-01T18:06:52.972870Z"}]}
{"channel":"book","type":"update","data":[{"symbol":"BTC/USD","bids":[{"price":67698.6,"qty":0.00111657}],"asks":[],"checksum":2668572222,"timestamp":"2024-06-01T18:06:53.020922Z"}]}
{"channel":"book","type":"update","data":[{"symbol":"BTC/USD","bids":[{"price":67693.5,"qty":0.00000000},{"price":67691.5,"qty":0.02951977}],"asks":[],"checksum":2178338681,"timestamp":"2024-06-01T18:06:53.992997Z"}]}
{"channel":"book","type":"update","data":[{"symbol":"BTC/USD","bids":[],"asks":[{"price":67732.9,"qty":0.00000000},{"price":67736.2,"qty":0.02309133},{"price":67732.6,"qty":19.54551484}],"checksum":649520064,"timestamp":"2024-06-01T18:06:53.996396Z"}]}
{"channel":"book","type":"update","data":[{"symbol":"BTC/USD","bids":[{"price":67693.4,"qty":0.06910000}],"asks":[],"checksum":793208391,"timestamp":"2024-06-01T18:06:54.155300Z"}]}
{"channel":"book","type":"update","data":[{"symbol":"BTC/USD","bids":[{"price":67693.4,"qty":0.00000000},{"price":67691.5,"qty":0.02951977}],"asks":[],"checksum":649520064,"timestamp":"2024-06-01T18:06:54.196619Z"}]}
{"channel":"book","type":"update","data":[{"symbol":"BTC/USD","bids":[{"price":67698.6,"qty":0.00000000},{"price":67690.5,"qty":0.15694470}],"asks":[],"checksum":725377405,"timestamp":"2024-06-01T18:06:54.323710Z"}]}
{"channel":"book","type":"update","data":[{"symbol":"BTC/USD","bids":[{"price":67693.3,"qty":0.06910000}],"asks":[],"checksum":3851224772,"timestamp":"2024-06-01T18:06:54.427810Z"}]}
{"channel":"book","type":"update","data":[{"symbol":"BTC/USD","bids":[{"price":67693.0,"qty":0.44382015}],"asks":[],"checksum":927229101,"timestamp":"2024-06-01T18:06:54.469739Z"}]}
{"channel":"book","type":"update","data":[{"symbol":"BTC/USD","bids":[{"price":67698.6,"qty":0.00111651}],"asks":[],"checksum":1134420539,"timestamp":"2024-06-01T18:06:54.509138Z"}]}
{"channel":"book","type":"update","data":[{"symbol":"BTC/USD","bids":[],"asks":[{"price":67732.7,"qty":0.00000000},{"price":67737.5,"qty":0.91730373}],"checksum":625254834,"timestamp":"2024-06-01T18:06:54.750616Z"}]}
{"channel":"book","type":"update","data":[{"symbol":"BTC/USD","bids":[],"asks":[{"price":67733.7,"qty":0.04229767}],"checksum":3847601658,"timestamp":"2024-06-01T18:06:54.753265Z"}]}
{"channel":"book","type":"update","data":[{"symbol":"BTC/USD","bids":[{"price":67698.6,"qty":0.00000000},{"price":67691.8,"qty":0.24000000},{"price":67693.4,"qty":0.00111660}],"asks":[],"checksum":1271493513,"timestamp":"2024-06-01T18:06:54.854099Z"}]}
{"channel":"book","type":"update","data":[{"symbol":"BTC/USD","bids":[{"price":67693.4,"qty":0.00000000},{"price":67691.8,"qty":0.24000000},{"price":67698.6,"qty":0.00111651}],"asks":[],"checksum":3847601658,"timestamp":"2024-06-01T18:06:55.076872Z"}]}
{"channel":"book","type":"update","data":[{"symbol":"BTC/USD","bids":[],"asks":[{"price":67733.8,"qty":0.00000000},{"price":67737.5,"qty":0.91730373}],"checksum":1293377012,"timestamp":"2024-06-01T18:06:55.104979Z"}]}
{"channel":"book","type":"update","data":[{"symbol":"BTC/USD","bids":[],"asks":[{"price":67733.8,"qty":1.43598004}],"checksum":2591797785,"timestamp":"2024-06-01T18:06:55.108249Z"}]}
{"channel":"book","type":"update","data":[{"symbol":"BTC/USD","bids":[{"price":67698.6,"qty":0.00000000},{"price":67691.8,"qty":0.24000000},{"price":67693.4,"qty":0.00111660}],"asks":[],"checksum":887585898,"timestamp":"2024-06-01T18:06:55.125879Z"}]}
{"channel":"book","type":"update","data":[{"symbol":"BTC/USD","bids":[{"price":67693.4,"qty":0.00000000},{"price":67691.8,"qty":0.24000000},{"price":67698.6,"qty":0.00111651}],"asks":[],"checksum":2591797785,"timestamp":"2024-06-01T18:06:55.260484Z"}]}
{"channel":"book","type":"update","data":[{"symbol":"BTC/USD","bids":[{"price":67698.6,"qty":0.00000000},{"price":67691.8,"qty":0.24000000},{"price":67693.4,"qty":0.00111655}],"asks":[],"checksum":2525830767,"timestamp":"2024-06-01T18:06:55.306947Z"}]}
{"channel":"book","type":"update","data":[{"symbol":"BTC/USD","bids":[{"price":67693.4,"qty":0.00000000},{"price":67691.8,"qty":0.24000000},{"price":67698.6,"qty":0.00111646}],"asks":[],"checksum":3154140427,"timestamp":"2024-06-01T18:06:55.508346Z"}]}
{"channel":"book","type":"update","data":[{"symbol":"BTC/USD","bids":[],"asks":[{"price":67732.6,"qty":18.96631805},{"price":67732.9,"qty":0.57919679}],"checksum":3889031567,"timestamp":"2024-06-01T18:06:55.511705Z"}]}
{"channel":"book","type":"update","data":[{"symbol":"BTC/USD","bids":[{"price":67698.6,"qty":0.00000000},{"price":67691.8,"qty":0.24000000},{"price":67693.4,"qty":0.00111655}],"asks":[],"checksum":3443567339,"timestamp":"2024-06-01T18:06:55.554181Z"}]}
{"channel":"book","type":"update","data":[{"symbol":"BTC/USD","bids":[{"price":67693.3,"qty":0.00000000},{"price":67691.8,"qty":0.24000000}],"asks":[],"checksum":2059288237,"timestamp":"2024-06-01T18:06:55.673186Z"}]}
{"channel":"book","type":"update","data":[{"symbol":"BTC/USD","bids":[{"price":67693.4,"qty":0.00000000},{"price":67691.5,"qty":0.02951977},{"price":67693.1,"qty":0.00111655}],"asks":[],"checksum":1035631303,"timestamp":"2024-06-01T18:06:55.736801Z"}]}
{"channel":"book","type":"update","data":[{"symbol":"BTC/USD","bids":[{"price":67693.1,"qty":0.00000000},{"price":67691.5,"qty":0.02951977},{"price":67698.6,"qty":0.00111646}],"asks":[],"checksum":810227375,"timestamp":"2024-06-01T18:06:55.795781Z"}]}
{"channel":"book","type":"update","data":[{"symbol":"BTC/USD","bids":[{"price":67698.6,"qty":0.00000000},{"price":67691.5,"qty":0.02951977},{"price":67693.1,"qty":0.00111655}],"asks":[],"checksum":1035631303,"timestamp":"2024-06-01T18:06:55.842064Z"}]}
{"channel":"book","type":"update","data":[{"symbol":"BTC/USD","bids":[{"price":67693.1,"qty":0.00000000},{"price":67691.5,"qty":0.02951977},{"price":67698.6,"qty":0.00111646}],"asks":[],"checksum":810227375,"timestamp":"2024-06-01T18:06:55.912356Z"}]}
{"channel":"book","type":"update","data":[{"symbol":"BTC/USD","bids":[{"price":67692.3,"qty":0.06910000}],"asks":[],"checksum":3772057623,"timestamp":"2024-06-01T18:06:55.979983Z"}]}
{"channel":"book","type":"update","data":[{"symbol":"BTC/USD","bids":[{"price":67698.6,"qty":0.00000000},{"price":67691.8,"qty":0.24000000},{"price":67693.1,"qty":0.00111655}],"asks":[],"checksum":2094227101,"timestamp":"2024-06-01T18:06:56.051139Z"}]}
{"channel":"book","type":"update","data":[{"symbol":"BTC/USD","bids":[],"asks":[{"price":67733.3,"qty":0.00000000},{"price":67736.2,"qty":0.02309133}],"checksum":225174626,"timestamp":"2024-06-01T18:06:56.347461Z"}]}
{"channel":"book","type":"update","data":[{"symbol":"BTC/USD","bids":[],"asks":[{"price":67732.6,"qty":19.14349705}],"checksum":507707432,"timestamp":"2024-06-01T18:06:56.349711Z"}]}
{"channel":"book","type":"update","data":[{"symbol":"BTC/USD","bids":[{"price":67693.1,"qty":0.00000000},{"price":67691.8,"qty":0.24000000},{"price":67698.6,"qty":0.00111644}],"asks":[],"checksum":2165179854,"timestamp":"2024-06-01T18:06:56.377495Z"}]}
{"channel":"book","type":"update","data":[{"symbol":"BTC/USD","bids":[{"price":67698.6,"qty":0.00000000},{"price":67691.8,"qty":0.24000000},{"price":67693.1,"qty":0.00111653}],"asks":[],"checksum":469700198,"timestamp":"2024-06-01T18:06:56.444559Z"}]}
{"channel":"book","type":"update","data":[{"symbol":"BTC/USD","bids":[{"price":67693.1,"qty":0.00000000},{"price":67691.8,"qty":0.24000000},{"price":67698.6,"qty":0.00111644}],"asks":[],"checksum":2165179854,"timestamp":"2024-06-01T18:06:56.607859Z"}]}
{"channel":"book","type":"update","data":[{"symbol":"BTC/USD","bids":[{"price":67698.6,"qty":0.00000000},{"price":67691.8,"qty":0.24000000},{"price":67693.1,"qty":0.00111653}],"asks":[],"checksum":469700198,"timestamp":"2024-06-01T18:06:56.681389Z"}]}
{"channel":"book","type":"update","data":[{"symbol":"BTC/USD","bids":[{"price":67693.1,"qty":0.00000000},{"price":67691.8,"qty":0.24000000},{"price":67698.6,"qty":0.00111644}],"asks":[],"checksum":2165179854,"timestamp":"2024-06-01T18:06:56.781848Z"}]}
{"channel":"book","type":"update","data":[{"symbol":"BTC/USD","bids":[{"price":67698.6,"qty":0.00000000},{"price":67691.8,"qty":0.24000000},{"price":67693.1,"qty":0.00111653}],"asks":[],"checksum":469700198,"timestamp":"2024-06-01T18:06:56.831705Z"}]}
{"channel":"book","type":"update","data":[{"symbol":"BTC/USD","bids":[{"price":67693.1,"qty":0.00000000},{"price":67691.8,"qty":0.24000000},{"price":67698.6,"qty":0.00111644}],"asks":[],"checksum":2165179854,"timestamp":"2024-06-01T18:06:57.075153Z"}]}
{"channel":"book","type":"update","data":[{"symbol":"BTC/USD","bids":[],"asks":[{"price":67732.9,"qty":0.00000000},{"price":67736.8,"qty":1.47630335},{"price":67732.6,"qty":19.72269384}],"checksum":1005584666,"timestamp":"2024-06-01T18:06:57.078458Z"}]}
{"channel":"book","type":"update","data":[{"symbol":"BTC/USD","bids":[{"price":67698.6,"qty":0.00000000},{"price":67691.8,"qty":0.24000000},{"price":67693.1,"qty":0.00111653}],"asks":[],"checksum":2701200050,"timestamp":"2024-06-01T18:06:57.134555Z"}]}
{"channel":"book","type":"update","data":[{"symbol":"BTC/USD","bids":[],"asks":[{"price":67733.7,"qty":0.00000000},{"price":67737.5,"qty":0.91730373}],"checksum":733606578,"timestamp":"2024-06-01T18:06:57.198704Z"}]}
{"channel":"book","type":"update","data":[{"symbol":"BTC/USD","bids":[],"asks":[{"price":67732.8,"qty":0.07339117}],"checksum":277822937,"timestamp":"2024-06-01T18:06:57.201277Z"}]}
{"channel":"book","type":"update","data":[{"symbol":"BTC/USD","bids":[],"asks":[{"price":67733.7,"qty":0.05869126}],"checksum":1416719266,"timestamp":"2024-06-01T18:06:57.201293Z"}]}
{"channel":"book","type":"update","data":[{"symbol":"BTC/USD","bids":[{"price":67693.1,"qty":0.00000000},{"price":67691.8,"qty":0.24000000},{"price":67698.6,"qty":0.00111650}],"asks":[],"checksum":3927274946,"timestamp":"2024-06-01T18:06:57.460058Z"}]}
{"channel":"book","type":"update","data":[{"symbol":"BTC/USD","bids":[],"asks":[{"price":67733.8,"qty":0.00000000},{"price":67736.8,"qty":1.47630335}],"checksum":3623346997,"timestamp":"2024-06-01T18:06:57.896699Z"}]}
{"channel":"book","type":"update","data":[{"symbol":"BTC/USD","bids":[],"asks":[{"price":67733.8,"qty":5.70191400}],"checksum":468978309,"timestamp":"2024-06-01T18:06:57.900931Z"}]}
{"channel":"book","type":"update","data":[{"symbol":"BTC/USD","bids":[],"asks":[{"price":67735.9,"qty":6.76260150}],"checksum":1737642828,"timestamp":"2024-06-01T18:06:57.901036Z"}]}
{"channel":"book","type":"update","data":[{"symbol":"BTC/USD","bids":[{"price":67692.3,"qty":0.00000000},{"price":67691.8,"qty":0.24000000}],"asks":[],"checksum":3430275464,"timestamp":"2024-06-01T18:06:58.073915Z"}]}
{"channel":"book","type":"update","data":[{"symbol":"BTC/USD","bids":[{"price":67698.6,"qty":0.00000000},{"price":67691.5,"qty":0.02951977},{"price":67693.1,"qty":0.00111659}],"asks":[],"checksum":3920276260,"timestamp":"2024-06-01T18:06:58.272817Z"}]}
{"channel":"book","type":"update","data":[{"symbol":"BTC/USD","bids":[{"price":67692.1,"qty":0.06910000}],"asks":[],"checksum":2501335171,"timestamp":"2024-06-01T18:06:58.414161Z"}]}
{"channel":"book","type":"update","data":[{"symbol":"BTC/USD","bids":[{"price":67693.1,"qty":0.00000000},{"price":67691.8,"qty":0.24000000},{"price":67698.6,"qty":0.00111649}],"asks":[],"checksum":188482343,"timestamp":"2024-06-01T18:06:58.576817Z"}]}
{"channel":"book","type":"update","data":[{"symbol":"BTC/USD","bids":[],"asks":[{"price":67732.6,"qty":19.14349705},{"price":67732.7,"qty":0.57919679}],"checksum":4124971759,"timestamp":"2024-06-01T18:06:58.580136Z"}]}
{"channel":"book","type":"update","data":[{"symbol":"BTC/USD","bids":[],"asks":[{"price":67732.6,"qty":19.04349705}],"checksum":2806728344,"timestamp":"2024-06-01T18:06:59.308502Z"}]}
{"channel":"book","type":"update","data":[{"symbol":"BTC/USD","bids":[],"asks":[{"price":67732.6,"qty":19.14349705}],"checksum":4124971759,"timestamp":"2024-06-01T18:06:59.313624Z"}]}
{"channel":"book","type":"update","data":[{"symbol":"BTC/USD","bids":[],"asks":[{"price":67732.8,"qty":0.00000000},{"price":67736.0,"qty":0.71000000}],"checksum":2370532836,"timestamp":"2024-06-01T18:06:59.518012Z"}]}
{"channel":"book","type":"update","data":[{"symbol":"BTC/USD","bids":[],"asks":[{"price":67733.7,"qty":0.00000000},{"price":67736.2,"qty":0.02309133}],"checksum":3787089210,"timestamp":"2024-06-01T18:06:59.518099Z"}]}
{"channel":"book","type":"update","data":[{"symbol":"BTC/USD","bids":[],"asks":[{"price":67732.6,"qty":19.18661423}],"checksum":150723933,"timestamp":"2024-06-01T18:06:59.520518Z"}]}
{"channel":"book","type":"update","data":[{"symbol":"BTC/USD","bids":[],"asks":[{"price":67733.7,"qty":0.08808026}],"checksum":3391435808,"timestamp":"2024-06-01T18:06:59.520651Z"}]}
{"channel":"book","type":"update","data":[{"symbol":"BTC/USD","bids":[],"asks":[{"price":67736.0,"qty":0.00000000},{"price":67736.2,"qty":0.02309133},{"price":67734.2,"qty":0.71000000}],"checksum":1527979893,"timestamp":"2024-06-01T18:06:59.645637Z"}]}
{"channel":"book","type":"update","data":[{"symbol":"BTC/USD","bids":[{"price":67692.1,"qty":0.00000000},{"price":67691.8,"qty":0.24000000}],"asks":[],"checksum":3183147082,"timestamp":"2024-06-01T18:07:00.180674Z"}]}
{"channel":"book","type":"update","data":[{"symbol":"BTC/USD","bids":[],"asks":[{"price":67732.7,"qty":0.00000000},{"price":67736.2,"qty":0.02309133},{"price":67732.6,"qty":19.76581102}],"checksum":2549569128,"timestamp":"2024-06-01T18:07:00.183847Z"}]}
{"channel":"book","type":"update","data":[{"symbol":"BTC/USD","bids":[],"asks":[{"price":67733.9,"qty":0.00000000},{"price":67736.6,"qty":0.91730373}],"checksum":1216802556,"timestamp":"2024-06-01T18:07:00.322679Z"}]}
{"channel":"book","type":"update","data":[{"symbol":"BTC/USD","bids":[],"asks":[{"price":67732.6,"qty":19.76531102}],"checksum":4249740294,"timestamp":"2024-06-01T18:07:00.413809Z"}]}
{"channel":"book","type":"update","data":[{"symbol":"BTC/USD","bids":[{"price":67698.6,"qty":0.00000000},{"price":67691.5,"qty":0.02951977},{"price":67693.1,"qty":0.00111555}],"asks":[],"checksum":3337762476,"timestamp":"2024-06-01T18:07:00.605909Z"}]}
{"channel":"book","type":"update","data":[{"symbol":"BTC/USD","bids":[],"asks":[{"price":67732.6,"qty":21.00560258}],"checksum":2881138760,"timestamp":"2024-06-01T18:07:00.610555Z"}]}
{"channel":"book","type":"update","data":[{"symbol":"BTC/USD","bids":[],"asks":[{"price":67735.9,"qty":0.00000000},{"price":67736.8,"qty":1.47630335}],"checksum":3496394866,"timestamp":"2024-06-01T18:07:00.720280Z"}]}
{"channel":"book","type":"update","data":[{"symbol":"BTC/USD","bids":[],"asks":[{"price":67733.8,"qty":0.00000000},{"price":67738.4,"qty":0.07515247}],"checksum":4032533673,"timestamp":"2024-06-01T18:07:00.720380Z"}]}
{"channel":"book","type":"update","data":[{"symbol":"BTC/USD","bids":[],"asks":[{"price":67733.6,"qty":2.08174148}],"checksum":2244802917,"timestamp":"2024-06-01T18:07:00.722951Z"}]}
{"channel":"book","type":"update","data":[{"symbol":"BTC/USD","bids":[],"asks":[{"price":67733.8,"qty":7.29294526}],"checksum":3181555266,"timestamp":"2024-06-01T18:07:00.723040Z"}]}
{"channel":"book","type":"update","data":[{"symbol":"BTC/USD","bids":[{"price":67698.5,"qty":0.00000000},{"price":67691.5,"qty":0.02951977}],"asks":[],"checksum":2522867635,"timestamp":"2024-06-01T18:07:00.724690Z"}]}
{"channel":"book","type":"update","data":[{"symbol":"BTC/USD","bids":[{"price":67693.0,"qty":0.00000000},{"price":67688.5,"qty":0.33750000}],"asks":[],"checksum":3253660702,"timestamp":"2024-06-01T18:07:00.783304Z"}]}
{"channel":"book","type":"update","data":[{"symbol":"BTC/USD","bids":[{"price":67688.8,"qty":1.47734725}],"asks":[],"checksum":499214981,"timestamp":"2024-06-01T18:07:00.787430Z"}]}
{"channel":"book","type":"update","data":[{"symbol":"BTC/USD","bids":[{"price":67693.1,"qty":0.00000000},{"price":67688.5,"qty":0.33750000}],"asks":[],"checksum":3986896531,"timestamp":"2024-06-01T18:07:00.818620Z"}]}
{"channel":"book","type":"update","data":[{"symbol":"BTC/USD","bids":[{"price":67689.7,"qty":0.06910000}],"asks":[],"checksum":3398458680,"timestamp":"2024-06-01T18:07:00.901102Z"}]}
{"channel":"book","type":"update","data":[{"symbol":"BTC/USD","bids":[{"price":67692.1,"qty":0.44382605}],"asks":[],"checksum":2606572880,"timestamp":"2024-06-01T18:07:00.907452Z"}]}
{"channel":"book","type":"update","data":[{"symbol":"BTC/USD","bids":[{"price":67692.2,"qty":0.00111556}],"asks":[],"checksum":2552964649,"timestamp":"2024-06-01T18:07:01.224965Z"}]}
{"channel":"book","type":"update","data":[{"symbol":"BTC/USD","bids":[{"price":67692.2,"qty":0.00000000},{"price":67689.7,"qty":0.06910000}],"asks":[],"checksum":2606572880,"timestamp":"2024-06-01T18:07:01.588347Z"}]}
{"channel":"book","type":"update","data":[{"symbol":"BTC/USD","bids":[{"price":67692.2,"qty":0.00111565}],"asks":[],"checksum":1764013655,"timestamp":"2024-06-01T18:07:01.881364Z"}]}
{"channel":"book","type":"update","data":[{"symbol":"BTC/USD","bids":[],"asks":[{"price":67732.6,"qty":20.42640579},{"price":67732.9,"qty":0.57919679}],"checksum":94701226,"timestamp":"2024-06-01T18:07:01.885013Z"}]}
{"channel":"book","type":"update","data":[{"symbol":"BTC/USD","bids":[],"asks":[{"price":67732.6,"qty":20.38328861}],"checksum":287582648,"timestamp":"2024-06-01T18:07:01.931668Z"}]}
{"channel":"book","type":"update","data":[{"symbol":"BTC/USD","bids":[],"asks":[{"price":67733.7,"qty":0.00000000},{"price":67736.6,"qty":0.91730373}],"checksum":893995544,"timestamp":"2024-06-01T18:07:01.931973Z"}]}
{"channel":"book","type":"update","data":[{"symbol":"BTC/USD","bids":[],"asks":[{"price":67733.5,"qty":0.12822330}],"checksum":2386649343,"timestamp":"2024-06-01T18:07:01.933791Z"}]}
{"channel":"book","type":"update","data":[{"symbol":"BTC/USD","bids":[{"price":67692.2,"qty":0.00000000},{"price":67691.1,"qty":0.13820000}],"asks":[],"checksum":3296511956,"timestamp":"2024-06-01T18:07:01.938851Z"}]}
{"channel":"book","type":"update","data":[{"symbol":"BTC/USD","bids":[{"price":67691.1,"qty":0.06910000}],"asks":[],"checksum":3519196157,"timestamp":"2024-06-01T18:07:02.050451Z"}]}
{"channel":"book","type":"update","data":[{"symbol":"BTC/USD","bids":[{"price":67692.2,"qty":0.00111565}],"asks":[],"checksum":2386649343,"timestamp":"2024-06-01T18:07:02.163102Z"}]}
{"channel":"book","type":"update","data":[{"symbol":"BTC/USD","bids":[{"price":67692.1,"qty":0.51292605}],"asks":[],"checksum":813496192,"timestamp":"2024-06-01T18:07:02.442092Z"}]}
{"channel":"book","type":"update","data":[{"symbol":"BTC/USD","bids":[{"price":67692.1,"qty":0.58202605}],"asks":[],"checksum":4182972601,"timestamp":"2024-06-01T18:07:02.445125Z"}]}
{"channel":"book","type":"update","data":[{"symbol":"BTC/USD","bids":[{"price":67692.1,"qty":0.51292605}],"asks":[],"checksum":813496192,"timestamp":"2024-06-01T18:07:02.602388Z"}]}
{"channel":"book","type":"update","data":[{"symbol":"BTC/USD","bids":[{"price":67692.2,"qty":0.00000000},{"price":67688.8,"qty":1.47734895}],"asks":[],"checksum":2906099813,"timestamp":"2024-06-01T18:07:02.748221Z"}]}
{"channel":"book","type":"update","data":[{"symbol":"BTC/USD","bids":[{"price":67688.8,"qty":0.00000000},{"price":67688.5,"qty":0.33750000}],"asks":[],"checksum":4157008675,"timestamp":"2024-06-01T18:07:02.871062Z"}]}
{"channel":"book","type":"update","data":[{"symbol":"BTC/USD","bids":[{"price":67688.6,"qty":0.91895652}],"asks":[],"checksum":1553505338,"timestamp":"2024-06-01T18:07:03.030042Z"}]}
{"channel":"book","type":"update","data":[{"symbol":"BTC/USD","bids":[{"price":67692.1,"qty":0.44382605},{"price":67691.1,"qty":0.06910000}],"asks":[],"checksum":3519196157,"timestamp":"2024-06-01T18:07:03.137398Z"}]}
{"channel":"book","type":"update","data":[{"symbol":"BTC/USD","bids":[{"price":67691.1,"qty":0.13820000}],"asks":[],"checksum":3296511956,"timestamp":"2024-06-01T18:07:03.140429Z"}]}
{"channel":"book","type":"update","data":[{"symbol":"BTC/USD","bids":[],"asks":[{"price":67732.6,"qty":20.26539761}],"checksum":3060853915,"timestamp":"2024-06-01T18:07:03.313681Z"}]}
{"channel":"book","type":"update","data":[{"symbol":"BTC/USD","bids":[{"price":67691.1,"qty":0.06910000}],"asks":[],"checksum":3666764091,"timestamp":"2024-06-01T18:07:03.412636Z"}]}
{"channel":"book","type":"update","data":[{"symbol":"BTC/USD","bids":[],"asks":[{"price":67732.9,"qty":0.00000000},{"price":67736.6,"qty":0.91730373},{"price":67732.6,"qty":20.84459440}],"checksum":3546081213,"timestamp":"2024-06-01T18:07:03.415805Z"}]}
{"channel":"book","type":"update","data":[{"symbol":"BTC/USD","bids":[{"price":67691.1,"qty":0.00000000},{"price":67689.9,"qty":1.47732386},{"price":67692.6,"qty":0.06910000}],"asks":[],"checksum":3381157969,"timestamp":"2024-06-01T18:07:03.420817Z"}]}
{"channel":"book","type":"update","data":[{"symbol":"BTC/USD","bids":[{"price":67692.6,"qty":0.13820000}],"asks":[],"checksum":3880003169,"timestamp":"2024-06-01T18:07:03.424474Z"}]}
{"channel":"book","type":"update","data":[{"symbol":"BTC/USD","bids":[],"asks":[{"price":67732.6,"qty":20.96249140}],"checksum":1538026513,"timestamp":"2024-06-01T18:07:03.431084Z"}]}
{"channel":"book","type":"update","data":[{"symbol":"BTC/USD","bids":[{"price":67692.6,"qty":0.06910000}],"asks":[],"checksum":1195444960,"timestamp":"2024-06-01T18:07:03.438788Z"}]}
{"channel":"book","type":"update","data":[{"symbol":"BTC/USD","bids":[],"asks":[{"price":67732.6,"qty":20.39264255}],"checksum":3516537949,"timestamp":"2024-06-01T18:07:03.457578Z"}]}
{"channel":"book","type":"update","data":[{"symbol":"BTC/USD","bids":[],"asks":[{"price":67733.6,"qty":0.00000000},{"price":67736.8,"qty":1.47630335}],"checksum":828082610,"timestamp":"2024-06-01T18:07:03.482526Z"}]}
{"channel":"book","type":"update","data":[{"symbol":"BTC/USD","bids":[],"asks":[{"price":67733.8,"qty":0.00000000},{"price":67738.4,"qty":0.07515247}],"checksum":2009391384,"timestamp":"2024-06-01T18:07:03.482631Z"}]}
{"channel":"book","type":"update","data":[{"symbol":"BTC/USD","bids":[],"asks":[{"price":67732.8,"qty":1.82809908}],"checksum":258672496,"timestamp":"2024-06-01T18:07:03.487028Z"}]}
{"channel":"book","type":"update","data":[{"symbol":"BTC/USD","bids":[],"asks":[{"price":67736.5,"qty":3.71888983}],"checksum":3683337294,"timestamp":"2024-06-01T18:07:03.487064Z"}]}
{"channel":"book","type":"update","data":[{"symbol":"BTC/USD","bids":[{"price":67692.2,"qty":0.91892033}],"asks":[],"checksum":3196030114,"timestamp":"2024-06-01T18:07:03.548701Z"}]}
{"channel":"book","type":"update","data":[{"symbol":"BTC/USD","bids":[{"price":67691.8,"qty":0.00000000},{"price":67691.5,"qty":0.02951977},{"price":67692.7,"qty":0.24000000}],"asks":[],"checksum":265103444,"timestamp":"2024-06-01T18:07:03.552604Z"}]}
{"channel":"book","type":"update","data":[{"symbol":"BTC/USD","bids":[],"asks":[{"price":67732.6,"qty":20.96249140}],"checksum":3129687155,"timestamp":"2024-06-01T18:07:03.577895Z"}]}
{"channel":"book","type":"update","data":[{"symbol":"BTC/USD","bids":[],"asks":[{"price":67732.6,"qty":20.84459440}],"checksum":107181571,"timestamp":"2024-06-01T18:07:03.689010Z"}]}
{"channel":"book","type":"update","data":[{"symbol":"BTC/USD","bids":[{"price":67692.2,"qty":0.00000000},{"price":67691.5,"qty":0.02951977}],"asks":[],"checksum":2229935950,"timestamp":"2024-06-01T18:07:03.716986Z"}]}
{"channel":"book","type":"update","data":[{"symbol":"BTC/USD","bids":[{"price":67692.8,"qty":0.00111465}],"asks":[],"checksum":1879432745,"timestamp":"2024-06-01T18:07:03.742421Z"}]}
{"channel":"book","type":"update","data":[{"symbol":"BTC/USD","bids":[],"asks":[{"price":67732.6,"qty":20.96249140}],"checksum":125867700,"timestamp":"2024-06-01T18:07:03.787527Z"}]}
{"channel":"book","type":"update","data":[{"symbol":"BTC/USD","bids":[],"asks":[{"price":67732.6,"qty":20.84459440}],"checksum":1879432745,"timestamp":"2024-06-01T18:07:03.984762Z"}]}
{"channel":"book","type":"update","data":[{"symbol":"BTC/USD","bids":[],"asks":[{"price":67732.6,"qty":20.96249340}],"checksum":2578729392,"timestamp":"2024-06-01T18:07:04.083619Z"}]}
{"channel":"book","type":"update","data":[{"symbol":"BTC/USD","bids":[],"asks":[{"price":67733.5,"qty":0.00000000},{"price":67736.8,"qty":1.47630335}],"checksum":1920146645,"timestamp":"2024-06-01T18:07:04.268224Z"}]}
{"channel":"book","type":"update","data":[{"symbol":"BTC/USD","bids":[],"asks":[{"price":67732.7,"qty":0.10008009}],"checksum":3567892668,"timestamp":"2024-06-01T18:07:04.270774Z"}]}
{"channel":"book","type":"update","data":[{"symbol":"BTC/USD","bids":[],"asks":[{"price":67736.4,"qty":0.02504108}],"checksum":4276084891,"timestamp":"2024-06-01T18:07:04.270979Z"}]}
{"channel":"book","type":"update","data":[{"symbol":"BTC/USD","bids":[{"price":67692.8,"qty":0.92003421}],"asks":[],"checksum":2110455213,"timestamp":"2024-06-01T18:07:04.672787Z"}]}
{"channel":"book","type":"update","data":[{"symbol":"BTC/USD","bids":[{"price":67692.7,"qty":0.00000000},{"price":67691.5,"qty":0.02951977},{"price":67692.9,"qty":0.24000000}],"asks":[],"checksum":3033428754,"timestamp":"2024-06-01T18:07:04.676242Z"}]}
{"channel":"book","type":"update","data":[{"symbol":"BTC/USD","bids":[{"price":67692.8,"qty":0.00111465}],"asks":[],"checksum":4133492074,"timestamp":"2024-06-01T18:07:04.681101Z"}]}
{"channel":"book","type":"update","data":[{"symbol":"BTC/USD","bids":[{"price":67692.8,"qty":0.00000000},{"price":67691.5,"qty":0.02951977},{"price":67693.0,"qty":0.00111464}],"asks":[],"checksum":1595960597,"timestamp":"2024-06-01T18:07:04.734914Z"}]}
{"channel":"book","type":"update","data":[{"symbol":"BTC/USD","bids":[],"asks":[{"price":67732.6,"qty":20.84459440}],"checksum":2366816531,"timestamp":"2024-06-01T18:07:05.634434Z"}]}
{"channel":"book","type":"update","data":[{"symbol":"BTC/USD","bids":[],"asks":[{"price":67734.2,"qty":0.00000000},{"price":67736.6,"qty":0.91730373},{"price":67736.0,"qty":0.71000000}],"checksum":179071643,"timestamp":"2024-06-01T18:07:05.646172Z"}]}
{"channel":"book","type":"update","data":[{"symbol":"BTC/USD","bids":[],"asks":[{"price":67732.6,"qty":20.27474555}],"checksum":689792104,"timestamp":"2024-06-01T18:07:05.667361Z"}]}
{"channel":"book","type":"update","data":[{"symbol":"BTC/USD","bids":[],"asks":[{"price":67732.6,"qty":20.09464555}],"checksum":1872670480,"timestamp":"2024-06-01T18:07:05.681421Z"}]}
{"channel":"book","type":"update","data":[{"symbol":"BTC/USD","bids":[{"price":67692.6,"qty":0.00000000},{"price":67691.5,"qty":0.02951977},{"price":67693.6,"qty":0.06910000}],"asks":[],"checksum":3908599298,"timestamp":"2024-06-01T18:07:05.697529Z"}]}
{"channel":"book","type":"update","data":[{"symbol":"BTC/USD","bids":[],"asks":[{"price":67732.6,"qty":20.27474555}],"checksum":2927342970,"timestamp":"2024-06-01T18:07:05.701587Z"}]}
{"channel":"book","type":"update","data":[{"symbol":"BTC/USD","bids":[{"price":67693.6,"qty":0.13820000}],"asks":[],"checksum":897208737,"timestamp":"2024-06-01T18:07:05.701756Z"}]}
{"channel":"book","type":"update","data":[{"symbol":"BTC/USD","bids":[{"price":67693.0,"qty":0.00000000},{"price":67691.5,"qty":0.02951977},{"price":67693.7,"qty":0.00111461}],"asks":[],"checksum":2880211637,"timestamp":"2024-06-01T18:07:05.755838Z"}]}
{"channel":"book","type":"update","data":[{"symbol":"BTC/USD","bids":[],"asks":[{"price":67732.6,"qty":20.39264455}],"checksum":1395426439,"timestamp":"2024-06-01T18:07:05.775208Z"}]}
{"channel":"book","type":"update","data":[{"symbol":"BTC/USD","bids":[],"asks":[{"price":67732.6,"qty":20.96249340}],"checksum":1720323972,"timestamp":"2024-06-01T18:07:05.785566Z"}]}
{"channel":"book","type":"update","data":[{"symbol":"BTC/USD","bids":[{"price":67693.6,"qty":0.06910000}],"asks":[],"checksum":2124795345,"timestamp":"2024-06-01T18:07:05.826660Z"}]}
{"channel":"book","type":"update","data":[{"symbol":"BTC/USD","bids":[],"asks":[{"price":67732.6,"qty":20.84459440}],"checksum":2895602135,"timestamp":"2024-06-01T18:07:06.033051Z"}]}
{"channel":"book","type":"update","data":[{"symbol":"BTC/USD","bids":[],"asks":[{"price":67732.6,"qty":20.96249340}],"checksum":2124795345,"timestamp":"2024-06-01T18:07:06.131562Z"}]}
{"channel":"book","type":"update","data":[{"symbol":"BTC/USD","bids":[],"asks":[{"price":67736.5,"qty":0.00000000},{"price":67736.6,"qty":0.91730373}],"checksum":3330722450,"timestamp":"2024-06-01T18:07:06.324215Z"}]}
{"channel":"book","type":"update","data":[{"symbol":"BTC/USD","bids":[],"asks":[{"price":67732.8,"qty":0.00000000},{"price":67736.8,"qty":1.47630335}],"checksum":2410819435,"timestamp":"2024-06-01T18:07:06.324244Z"}]}
{"channel":"book","type":"update","data":[{"symbol":"BTC/USD","bids":[],"asks":[{"price":67735.9,"qty":5.65579664}],"checksum":3397956347,"timestamp":"2024-06-01T18:07:06.329949Z"}]}
{"channel":"book","type":"update","data":[{"symbol":"BTC/USD","bids":[],"asks":[{"price":67732.6,"qty":20.88404709},{"price":67732.6,"qty":20.58404709},{"price":67732.6,"qty":20.27304709},{"price":67732.6,"qty":19.97304709},{"price":67732.6,"qty":18.96249340}],"checksum":3130363804,"timestamp":"2024-06-01T18:07:06.345257Z"}]}
{"channel":"book","type":"update","data":[{"symbol":"BTC/USD","bids":[],"asks":[{"price":67732.6,"qty":19.02343899}],"checksum":4037742994,"timestamp":"2024-06-01T18:07:06.350527Z"}]}
{"channel":"book","type":"update","data":[{"symbol":"BTC/USD","bids":[{"price":67693.6,"qty":0.00000000},{"price":67691.5,"qty":0.02951977},{"price":67692.1,"qty":0.51292605}],"asks":[],"checksum":4004544098,"timestamp":"2024-06-01T18:07:06.443001Z"}]}
{"channel":"book","type":"update","data":[{"symbol":"BTC/USD","bids":[{"price":67692.1,"qty":0.58202605}],"asks":[],"checksum":3993996155,"timestamp":"2024-06-01T18:07:06.446010Z"}]}
{"channel":"book","type":"update","data":[{"symbol":"BTC/USD","bids":[{"price":67693.7,"qty":0.00000000},{"price":67690.3,"qty":1.47731563},{"price":67693.0,"qty":0.00111461}],"asks":[],"checksum":1578765679,"timestamp":"2024-06-01T18:07:06.501052Z"}]}
{"channel":"book","type":"update","data":[{"symbol":"BTC/USD","bids":[{"price":67693.7,"qty":0.91891209}],"asks":[],"checksum":4199623790,"timestamp":"2024-06-01T18:07:06.560900Z"}]}
{"channel":"book","type":"update","data":[{"symbol":"BTC/USD","bids":[{"price":67692.1,"qty":0.51292605},{"price":67693.5,"qty":0.06910000}],"asks":[],"checksum":3413010908,"timestamp":"2024-06-01T18:07:06.641322Z"}]}
{"channel":"book","type":"update","data":[{"symbol":"BTC/USD","bids":[{"price":67692.9,"qty":0.00000000},{"price":67692.1,"qty":0.44382605},{"price":67693.8,"qty":0.24000000}],"asks":[],"checksum":217718955,"timestamp":"2024-06-01T18:07:06.647597Z"}]}
{"channel":"book","type":"update","data":[{"symbol":"BTC/USD","bids":[],"asks":[{"price":67732.7,"qty":0.00000000},{"price":67736.8,"qty":1.47630335}],"checksum":1020206875,"timestamp":"2024-06-01T18:07:06.657632Z"}]}
{"channel":"book","type":"update","data":[{"symbol":"BTC/USD","bids":[],"asks":[{"price":67736.4,"qty":0.00000000},{"price":67738.4,"qty":0.07515247}],"checksum":3500718661,"timestamp":"2024-06-01T18:07:06.657662Z"}]}
{"channel":"book","type":"update","data":[{"symbol":"BTC/USD","bids":[],"asks":[{"price":67732.7,"qty":0.06203842}],"checksum":3667305871,"timestamp":"2024-06-01T18:07:06.662400Z"}]}
{"channel":"book","type":"update","data":[{"symbol":"BTC/USD","bids":[],"asks":[{"price":67735.9,"qty":5.71990831}],"checksum":3727756844,"timestamp":"2024-06-01T18:07:06.662427Z"}]}
{"channel":"book","type":"update","data":[{"symbol":"BTC/USD","bids":[],"asks":[{"price":67732.6,"qty":18.44424220},{"price":67732.9,"qty":0.57919679}],"checksum":2841760808,"timestamp":"2024-06-01T18:07:06.662501Z"}]}
{"channel":"book","type":"update","data":[{"symbol":"BTC/USD","bids":[{"price":67693.5,"qty":0.00000000},{"price":67692.1,"qty":0.44382605},{"price":67694.5,"qty":0.06910000}],"asks":[],"checksum":2695689322,"timestamp":"2024-06-01T18:07:06.680466Z"}]}
{"channel":"book","type":"update","data":[{"symbol":"BTC/USD","bids":[{"price":67694.5,"qty":0.13820000}],"asks":[],"checksum":2340850323,"timestamp":"2024-06-01T18:07:06.681032Z"}]}
{"channel":"book","type":"update","data":[{"symbol":"BTC/USD","bids":[],"asks":[{"price":67732.6,"qty":17.88374323}],"checksum":2287740947,"timestamp":"2024-06-01T18:07:06.734201Z"}]}
{"channel":"book","type":"update","data":[{"symbol":"BTC/USD","bids":[],"asks":[{"price":67732.6,"qty":18.44425798}],"checksum":178535545,"timestamp":"2024-06-01T18:07:06.751741Z"}]}
{"channel":"book","type":"update","data":[{"symbol":"BTC/USD","bids":[],"asks":[{"price":67732.6,"qty":18.32635898}],"checksum":3539589109,"timestamp":"2024-06-01T18:07:06.771125Z"}]}
{"channel":"book","type":"update","data":[{"symbol":"BTC/USD","bids":[{"price":67693.0,"qty":0.00000000},{"price":67692.1,"qty":0.44382605},{"price":67694.6,"qty":0.00111459}],"asks":[],"checksum":1657039254,"timestamp":"2024-06-01T18:07:06.774191Z"}]}
{"channel":"book","type":"update","data":[{"symbol":"BTC/USD","bids":[],"asks":[{"price":67732.6,"qty":18.44425798}],"checksum":3130622490,"timestamp":"2024-06-01T18:07:06.877914Z"}]}
{"channel":"book","type":"update","data":[{"symbol":"BTC/USD","bids":[{"price":67694.5,"qty":0.06910000}],"asks":[],"checksum":2049500962,"timestamp":"2024-06-01T18:07:07.204069Z"}]}
{"channel":"book","type":"update","data":[{"symbol":"BTC/USD","bids":[{"price":67732.5,"qty":0.00147639},{"price":67732.5,"qty":0.00000000},{"price":67692.1,"qty":0.44382605},{"price":67703.2,"qty":0.05833391}],"asks":[],"checksum":562811714,"timestamp":"2024-06-01T18:07:07.851926Z"}]}
{"channel":"book","type":"update","data":[{"symbol":"BTC/USD","bids":[],"asks":[{"price":67729.3,"qty":0.33750000}],"checksum":1753910859,"timestamp":"2024-06-01T18:07:07.855542Z"}]}
{"channel":"book","type":"update","data":[{"symbol":"BTC/USD","bids":[],"asks":[{"price":67732.5,"qty":0.10000000}],"checksum":3278728776,"timestamp":"2024-06-01T18:07:07.857086Z"}]}
{"channel":"book","type":"update","data":[{"symbol":"BTC/USD","bids":[],"asks":[{"price":67703.3,"qty":0.06910000}],"checksum":2162359734,"timestamp":"2024-06-01T18:07:07.857341Z"}]}
{"channel":"book","type":"update","data":[{"symbol":"BTC/USD","bids":[],"asks":[{"price":67732.6,"qty":16.96786405}],"checksum":2221228538,"timestamp":"2024-06-01T18:07:07.857373Z"}]}
{"channel":"book","type":"update","data":[{"symbol":"BTC/USD","bids":[{"price":67694.7,"qty":0.00295408}],"asks":[],"checksum":2960047097,"timestamp":"2024-06-01T18:07:07.857384Z"}]}
{"channel":"book","type":"update","data":[{"symbol":"BTC/USD","bids":[],"asks":[{"price":67732.6,"qty":16.90691846}],"checksum":2997496617,"timestamp":"2024-06-01T18:07:07.857419Z"}]}
{"channel":"book","type":"update","data":[{"symbol":"BTC/USD","bids":[],"asks":[{"price":67732.6,"qty":15.43052453}],"checksum":2561171591,"timestamp":"2024-06-01T18:07:07.857436Z"}]}
{"channel":"book","type":"update","data":[{"symbol":"BTC/USD","bids":[],"asks":[{"price":67732.6,"qty":13.95413060}],"checksum":259372528,"timestamp":"2024-06-01T18:07:07.857445Z"}]}
{"channel":"book","type":"update","data":[{"symbol":"BTC/USD","bids":[],"asks":[{"price":67732.5,"qty":0.13947498}],"checksum":3559520357,"timestamp":"2024-06-01T18:07:07.857485Z"}]}
{"channel":"book","type":"update","data":[{"symbol":"BTC/USD","bids":[],"asks":[{"price":67732.6,"qty":13.48829036}],"checksum":304397557,"timestamp":"2024-06-01T18:07:07.857502Z"}]}
{"channel":"book","type":"update","data":[{"symbol":"BTC/USD","bids":[],"asks":[{"price":67703.3,"qty":0.13004559}],"checksum":422426342,"timestamp":"2024-06-01T18:07:07.857572Z"}]}
{"channel":"book","type":"update","data":[{"symbol":"BTC/USD","bids":[],"asks":[{"price":67732.6,"qty":12.01189643}],"checksum":10589691,"timestamp":"2024-06-01T18:07:07.857680Z"}]}
{"channel":"book","type":"update","data":[{"symbol":"BTC/USD","bids":[],"asks":[{"price":67732.6,"qty":11.99687262},{"price":67732.5,"qty":0.15449879}],"checksum":3062496300,"timestamp":"2024-06-01T18:07:07.858293Z"}]}
{"channel":"book","type":"update","data":[{"symbol":"BTC/USD","bids":[],"asks":[{"price":67732.6,"qty":11.56687262}],"checksum":1315403163,"timestamp":"2024-06-01T18:07:07.858445Z"}]}
{"channel":"book","type":"update","data":[{"symbol":"BTC/USD","bids":[],"asks":[{"price":67728.0,"qty":0.43000000}],"checksum":3886755090,"timestamp":"2024-06-01T18:07:07.858783Z"}]}
{"channel":"book","type":"update","data":[{"symbol":"BTC/USD","bids":[],"asks":[{"price":67732.6,"qty":11.34517262},{"price":67729.2,"qty":0.22170000}],"checksum":2813301784,"timestamp":"2024-06-01T18:07:07.858871Z"}]}
{"channel":"book","type":"update","data":[{"symbol":"BTC/USD","bids":[],"asks":[{"price":67732.5,"qty":0.40449879}],"checksum":2015711950,"timestamp":"2024-06-01T18:07:07.858918Z"}]}
{"channel":"book","type":"update","data":[{"symbol":"BTC/USD","bids":[{"price":67694.7,"qty":0.01746617}],"asks":[],"checksum":696428790,"timestamp":"2024-06-01T18:07:07.858943Z"}]}
{"channel":"book","type":"update","data":[{"symbol":"BTC/USD","bids":[],"asks":[{"price":67732.6,"qty":11.05017262},{"price":67729.2,"qty":0.51670000}],"checksum":1006829905,"timestamp":"2024-06-01T18:07:07.859001Z"}]}
{"channel":"book","type":"update","data":[{"symbol":"BTC/USD","bids":[{"price":67694.6,"qty":0.01542452}],"asks":[],"checksum":4111441209,"timestamp":"2024-06-01T18:07:07.859035Z"}]}
{"channel":"book","type":"update","data":[{"symbol":"BTC/USD","bids":[],"asks":[{"price":67732.5,"qty":0.44904628}],"checksum":1297846291,"timestamp":"2024-06-01T18:07:07.859097Z"}]}
{"channel":"book","type":"update","data":[{"symbol":"BTC/USD","bids":[],"asks":[{"price":67732.6,"qty":10.82887262},{"price":67729.2,"qty":0.73800000}],"checksum":3596840899,"timestamp":"2024-06-01T18:07:07.859420Z"}]}
{"channel":"book","type":"update","data":[{"symbol":"BTC/USD","bids":[],"asks":[{"price":67704.0,"qty":0.18020000}],"checksum":2087830783,"timestamp":"2024-06-01T18:07:07.860216Z"}]}
{"channel":"book","type":"update","data":[{"symbol":"BTC/USD","bids":[],"asks":[{"price":67732.6,"qty":10.71097362}],"checksum":260193558,"timestamp":"2024-06-01T18:07:07.860310Z"}]}
{"channel":"book","type":"update","data":[{"symbol":"BTC/USD","bids":[],"asks":[{"price":67732.6,"qty":10.53087362}],"checksum":595400141,"timestamp":"2024-06-01T18:07:07.860492Z"}]}
{"channel":"book","type":"update","data":[{"symbol":"BTC/USD","bids":[{"price":67693.8,"qty":0.00000000},{"price":67692.1,"qty":0.44382605}],"asks":[],"checksum":1219035822,"timestamp":"2024-06-01T18:07:07.860812Z"}]}
{"channel":"book","type":"update","data":[{"symbol":"BTC/USD","bids":[],"asks":[{"price":67732.6,"qty":10.51387362}],"checksum":3861320820,"timestamp":"2024-06-01T18:07:07.860968Z"}]}
{"channel":"book","type":"update","data":[{"symbol":"BTC/USD","bids":[],"asks":[{"price":67732.6,"qty":10.20187362},{"price":67703.3,"qty":0.44204559}],"checksum":4146395437,"timestamp":"2024-06-01T18:07:07.860988Z"}]}
{"channel":"book","type":"update","data":[{"symbol":"BTC/USD","bids":[],"asks":[{"price":67732.5,"qty":0.45282055}],"checksum":263509410,"timestamp":"2024-06-01T18:07:07.861102Z"}]}
{"channel":"book","type":"update","data":[{"symbol":"BTC/USD","bids":[],"asks":[{"price":67732.5,"qty":0.43779674},{"price":67729.2,"qty":0.75302381}],"checksum":877281876,"timestamp":"2024-06-01T18:07:07.862016Z"}]}
{"channel":"book","type":"update","data":[{"symbol":"BTC/USD","bids":[{"price":67703.2,"qty":0.35833391}],"asks":[],"checksum":1036781594,"timestamp":"2024-06-01T18:07:07.862193Z"}]}
{"channel":"book","type":"update","data":[{"symbol":"BTC/USD","bids":[],"asks":[{"price":67732.6,"qty":9.86787362},{"price":67703.3,"qty":0.77604559}],"checksum":1999730069,"timestamp":"2024-06-01T18:07:07.862428Z"}]}
{"channel":"book","type":"update","data":[{"symbol":"BTC/USD","bids":[],"asks":[{"price":67711.9,"qty":0.11774500}],"checksum":1579119880,"timestamp":"2024-06-01T18:07:07.862848Z"}]}
{"channel":"book","type":"update","data":[{"symbol":"BTC/USD","bids":[],"asks":[{"price":67703.3,"qty":2.25307846}],"checksum":105107752,"timestamp":"2024-06-01T18:07:07.863096Z"}]}
{"channel":"book","type":"update","data":[{"symbol":"BTC/USD","bids":[],"asks":[{"price":67703.3,"qty":3.73011133}],"checksum":1316723462,"timestamp":"2024-06-01T18:07:07.863168Z"}]}
{"channel":"book","type":"update","data":[{"symbol":"BTC/USD","bids":[],"asks":[{"price":67711.7,"qty":0.02526409}],"checksum":3030903559,"timestamp":"2024-06-01T18:07:07.863272Z"}]}
{"channel":"book","type":"update","data":[{"symbol":"BTC/USD","bids":[],"asks":[{"price":67714.0,"qty":0.73083685}],"checksum":3001086043,"timestamp":"2024-06-01T18:07:07.863340Z"}]}
{"channel":"book","type":"update","data":[{"symbol":"BTC/USD","bids":[],"asks":[{"price":67703.3,"qty":5.20714420}],"checksum":394529435,"timestamp":"2024-06-01T18:07:07.863445Z"}]}
{"channel":"book","type":"update","data":[{"symbol":"BTC/USD","bids":[],"asks":[{"price":67706.6,"qty":1.47696225}],"checksum":636758914,"timestamp":"2024-06-01T18:07:07.863489Z"}]}
{"channel":"book","type":"update","data":[{"symbol":"BTC/USD","bids":[],"asks":[{"price":67723.9,"qty":1.47658370}],"checksum":3709373093,"timestamp":"2024-06-01T18:07:07.863556Z"}]}
{"channel":"book","type":"update","data":[{"symbol":"BTC/USD","bids":[{"price":67693.9,"qty":0.01442423}],"asks":[],"checksum":391176277,"timestamp":"2024-06-01T18:07:07.864724Z"}]}
{"channel":"book","type":"update","data":[{"symbol":"BTC/USD","bids":[],"asks":[{"price":67710.1,"qty":0.33750000}],"checksum":4133739448,"timestamp":"2024-06-01T18:07:07.865269Z"}]}
{"channel":"book","type":"update","data":[{"symbol":"BTC/USD","bids":[{"price":67694.7,"qty":0.01451209}],"asks":[],"checksum":277061964,"timestamp":"2024-06-01T18:07:07.865560Z"}]}
{"channel":"book","type":"update","data":[{"symbol":"BTC/USD","bids":[{"price":67703.2,"qty":0.54501391}],"asks":[],"checksum":98991738,"timestamp":"2024-06-01T18:07:07.866360Z"}]}
{"channel":"book","type":"update","data":[{"symbol":"BTC/USD","bids":[{"price":67694.8,"qty":0.01401858}],"asks":[],"checksum":2616988664,"timestamp":"2024-06-01T18:07:07.867656Z"}]}
{"channel":"book","type":"update","data":[{"symbol":"BTC/USD","bids":[],"asks":[{"price":67711.7,"qty":0.00000000},{"price":67729.3,"qty":0.33750000}],"checksum":4128120338,"timestamp":"2024-06-01T18:07:07.869309Z"}]}
{"channel":"book","type":"update","data":[{"symbol":"BTC/USD","bids":[],"asks":[{"price":67716.9,"qty":0.33750000}],"checksum":134724301,"timestamp":"2024-06-01T18:07:07.870541Z"}]}
{"channel":"book","type":"update","data":[{"symbol":"BTC/USD","bids":[],"asks":[{"price":67729.2,"qty":0.75328512}],"checksum":400722344,"timestamp":"2024-06-01T18:07:07.885784Z"}]}
{"channel":"book","type":"update","data":[{"symbol":"BTC/USD","bids":[{"price":67694.6,"qty":0.01430993},{"price":67694.8,"qty":0.01513312}],"asks":[],"checksum":908087511,"timestamp":"2024-06-01T18:07:07.885812Z"}]}
{"channel":"book","type":"update","data":[{"symbol":"BTC/USD","bids":[],"asks":[{"price":67729.2,"qty":2.12528512}],"checksum":4044904452,"timestamp":"2024-06-01T18:07:07.888065Z"}]}
{"channel":"book","type":"update","data":[{"symbol":"BTC/USD","bids":[],"asks":[{"price":67729.2,"qty":0.75328512}],"checksum":908087511,"timestamp":"2024-06-01T18:07:07.916632Z"}]}
{"channel":"book","type":"update","data":[{"symbol":"BTC/USD","bids":[],"asks":[{"price":67703.3,"qty":5.22814420}],"checksum":4037870267,"timestamp":"2024-06-01T18:07:07.963654Z"}]}
{"channel":"book","type":"update","data":[{"symbol":"BTC/USD","bids":[],"asks":[{"price":67705.2,"qty":0.56984885}],"checksum":2216906556,"timestamp":"2024-06-01T18:07:08.004624Z"}]}
{"channel":"book","type":"update","data":[{"symbol":"BTC/USD","bids":[],"asks":[{"price":67717.2,"qty":0.03947498}],"checksum":1208920856,"timestamp":"2024-06-01T18:07:08.008897Z"}]}
{"channel":"book","type":"update","data":[{"symbol":"BTC/USD","bids":[],"asks":[{"price":67711.7,"qty":0.02300005}],"checksum":2878494993,"timestamp":"2024-06-01T18:07:08.015944Z"}]}
{"channel":"book","type":"update","data":[{"symbol":"BTC/USD","bids":[],"asks":[{"price":67711.8,"qty":0.91889689}],"checksum":2315781214,"timestamp":"2024-06-01T18:07:08.021998Z"}]}
{"channel":"book","type":"update","data":[{"symbol":"BTC/USD","bids":[{"price":67702.9,"qty":0.00000000},{"price":67693.7,"qty":0.91891209},{"price":67696.9,"qty":0.00010000}],"asks":[],"checksum":3397752801,"timestamp":"2024-06-01T18:07:08.022153Z"}]}
{"channel":"book","type":"update","data":[{"symbol":"BTC/USD","bids":[],"asks":[{"price":67711.7,"qty":0.00000000},{"price":67717.2,"qty":0.03947498}],"checksum":1420716584,"timestamp":"2024-06-01T18:07:08.024529Z"}]}
{"channel":"book","type":"update","data":[{"symbol":"BTC/USD","bids":[{"price":67703.2,"qty":0.54425691}],"asks":[],"checksum":2347268991,"timestamp":"2024-06-01T18:07:08.099552Z"}]}
{"channel":"book","type":"update","data":[{"symbol":"BTC/USD","bids":[],"asks":[{"price":67703.3,"qty":5.42814420}],"checksum":260569571,"timestamp":"2024-06-01T18:07:08.117614Z"}]}
{"channel":"book","type":"update","data":[{"symbol":"BTC/USD","bids":[],"asks":[{"price":67703.3,"qty":5.72814420}],"checksum":1303394477,"timestamp":"2024-06-01T18:07:08.120019Z"}]}
{"channel":"book","type":"update","data":[{"symbol":"BTC/USD","bids":[],"asks":[{"price":67711.7,"qty":0.02480052}],"checksum":572163358,"timestamp":"2024-06-01T18:07:08.161973Z"}]}
{"channel":"book","type":"update","data":[{"symbol":"BTC/USD","bids":[],"asks":[{"price":67713.9,"qty":0.57919679}],"checksum":3789971081,"timestamp":"2024-06-01T18:07:08.165374Z"}]}
{"channel":"book","type":"update","data":[{"symbol":"BTC/USD","bids":[],"asks":[{"price":67711.7,"qty":0.00000000},{"price":67716.9,"qty":0.33750000}],"checksum":2021627916,"timestamp":"2024-06-01T18:07:08.168065Z"}]}
{"channel":"book","type":"update","data":[{"symbol":"BTC/USD","bids":[{"price":67696.9,"qty":0.00000000},{"price":67693.7,"qty":0.91891209}],"asks":[],"checksum":3668646223,"timestamp":"2024-06-01T18:07:08.179847Z"}]}
{"channel":"book","type":"update","data":[{"symbol":"BTC/USD","bids":[],"asks":[{"price":67711.7,"qty":0.02379218}],"checksum":1309000044,"timestamp":"2024-06-01T18:07:08.312563Z"}]}
{"channel":"book","type":"update","data":[{"symbol":"BTC/USD","bids":[],"asks":[{"price":67711.7,"qty":0.00000000},{"price":67716.9,"qty":0.33750000}],"checksum":3668646223,"timestamp":"2024-06-01T18:07:08.318744Z"}]}
{"channel":"book","type":"update","data":[{"symbol":"BTC/USD","bids":[],"asks":[{"price":67703.3,"qty":6.02814420}],"checksum":3848586661,"timestamp":"2024-06-01T18:07:08.351755Z"}]}
{"channel":"book","type":"update","data":[{"symbol":"BTC/USD","bids":[],"asks":[{"price":67703.3,"qty":6.32814420}],"checksum":102209108,"timestamp":"2024-06-01T18:07:08.360052Z"}]}
{"channel":"book","type":"update","data":[{"symbol":"BTC/USD","bids":[],"asks":[{"price":67711.7,"qty":0.02273565}],"checksum":2095167802,"timestamp":"2024-06-01T18:07:08.463781Z"}]}
{"channel":"book","type":"update","data":[{"symbol":"BTC/USD","bids":[],"asks":[{"price":67711.7,"qty":0.00000000},{"price":67716.9,"qty":0.33750000}],"checksum":102209108,"timestamp":"2024-06-01T18:07:08.469952Z"}]}
{"channel":"book","type":"update","data":[{"symbol":"BTC/USD","bids":[],"asks":[{"price":67716.8,"qty":0.00026211}],"checksum":2588966476,"timestamp":"2024-06-01T18:07:08.486954Z"}]}
{"channel":"book","type":"update","data":[{"symbol":"BTC/USD","bids":[{"price":67694.8,"qty":0.01401858},{"price":67694.9,"qty":0.00111453}],"asks":[],"checksum":215062560,"timestamp":"2024-06-01T18:07:08.487096Z"}]}
{"channel":"book","type":"update","data":[{"symbol":"BTC/USD","bids":[],"asks":[{"price":67711.7,"qty":0.02621433}],"checksum":681413246,"timestamp":"2024-06-01T18:07:08.614213Z"}]}
{"channel":"book","type":"update","data":[{"symbol":"BTC/USD","bids":[],"asks":[{"price":67711.7,"qty":0.00000000},{"price":67716.8,"qty":0.00026211}],"checksum":215062560,"timestamp":"2024-06-01T18:07:08.621912Z"}]}
{"channel":"book","type":"update","data":[{"symbol":"BTC/USD","bids":[{"price":67696.4,"qty":0.33750000}],"asks":[],"checksum":916332652,"timestamp":"2024-06-01T18:07:08.670743Z"}]}
