{"channel":"book","type":"snapshot","data":[{"symbol":"BTC/CAD","bids":[{"price":92515.7,"qty":0.03010000},{"price":92506.5,"qty":0.39047034},{"price":92462.8,"qty":0.00075700},{"price":92458.9,"qty":0.00135200},{"price":92437.1,"qty":0.00450800},{"price":92403.4,"qty":0.03283920},{"price":92383.6,"qty":0.04134020},{"price":92354.6,"qty":0.01663175},{"price":92354.5,"qty":0.05824046},{"price":92354.3,"qty":0.19632769}],"asks":[{"price":92515.8,"qty":0.52029400},{"price":92517.3,"qty":0.00450600},{"price":92520.7,"qty":0.00654000},{"price":92526.8,"qty":0.00058300},{"price":92540.9,"qty":0.04134020},{"price":92544.2,"qty":0.00567000},{"price":92567.7,"qty":0.00685000},{"price":92570.7,"qty":0.07393000},{"price":92570.8,"qty":0.53753810},{"price":92571.4,"qty":0.32905872}],"checksum":2061644687}]}
{"channel":"book","type":"update","data":[{"symbol":"BTC/CAD","bids":[],"asks":[{"price":92570.8,"qty":0.53677594}],"checksum":4024698426,"timestamp":"2024-06-01T18:06:28.446121Z"}]}
{"channel":"book","type":"update","data":[{"symbol":"BTC/CAD","bids":[],"asks":[{"price":92570.6,"qty":0.00076217}],"checksum":2083537934,"timestamp":"2024-06-01T18:06:28.448817Z"}]}
{"channel":"book","type":"update","data":[{"symbol":"BTC/CAD","bids":[{"price":92462.8,"qty":0.00000000},{"price":92354.2,"qty":0.60582423},{"price":92471.6,"qty":0.00075700}],"asks":[],"checksum":1764649328,"timestamp":"2024-06-01T18:06:28.798780Z"}]}
{"channel":"book","type":"update","data":[{"symbol":"BTC/CAD","bids":[{"price":92354.7,"qty":0.00360464}],"asks":[],"checksum":64635900,"timestamp":"2024-06-01T18:06:28.836912Z"}]}
{"channel":"book","type":"update","data":[{"symbol":"BTC/CAD","bids":[{"price":92354.6,"qty":0.00000000},{"price":92354.3,"qty":0.19632769},{"price":92354.8,"qty":0.01662459}],"asks":[],"checksum":2476260700,"timestamp":"2024-06-01T18:06:29.067213Z"}]}
{"channel":"book","type":"update","data":[{"symbol":"BTC/CAD","bids":[{"price":92354.9,"qty":0.51939867}],"asks":[],"checksum":1468383902,"timestamp":"2024-06-01T18:06:29.288153Z"}]}
{"channel":"book","type":"update","data":[{"symbol":"BTC/CAD","bids":[{"price":92355.0,"qty":0.19632769}],"asks":[],"checksum":216728136,"timestamp":"2024-06-01T18:06:29.291349Z"}]}
{"channel":"book","type":"update","data":[{"symbol":"BTC/CAD","bids":[{"price":92354.8,"qty":0.00000000},{"price":92354.7,"qty":0.00360464},{"price":92355.1,"qty":0.01662494}],"asks":[],"checksum":4259170984,"timestamp":"2024-06-01T18:06:29.777878Z"}]}
{"channel":"book","type":"update","data":[{"symbol":"BTC/CAD","bids":[],"asks":[{"price":92570.8,"qty":0.00000000},{"price":92571.4,"qty":0.32905872}],"checksum":4174914945,"timestamp":"2024-06-01T18:06:29.844966Z"}]}
{"channel":"book","type":"update","data":[{"symbol":"BTC/CAD","bids":[],"asks":[{"price":92570.7,"qty":0.00000000},{"price":92627.1,"qty":0.01129070},{"price":92571.3,"qty":0.07393000}],"checksum":1649244879,"timestamp":"2024-06-01T18:06:29.849015Z"}]}
{"channel":"book","type":"update","data":[{"symbol":"BTC/CAD","bids":[],"asks":[{"price":92570.6,"qty":0.53753911}],"checksum":4003034136,"timestamp":"2024-06-01T18:06:29.887738Z"}]}
{"channel":"book","type":"update","data":[{"symbol":"BTC/CAD","bids":[{"price":92437.1,"qty":0.00000000},{"price":92354.7,"qty":0.00360464},{"price":92445.9,"qty":0.00450800}],"asks":[],"checksum":2277635463,"timestamp":"2024-06-01T18:06:29.949569Z"}]}
{"channel":"book","type":"update","data":[{"symbol":"BTC/CAD","bids":[],"asks":[{"price":92571.3,"qty":0.00000000},{"price":92627.1,"qty":0.01129070},{"price":92570.5,"qty":0.07393000}],"checksum":3854594491,"timestamp":"2024-06-01T18:06:30.668041Z"}]}
{"channel":"book","type":"update","data":[{"symbol":"BTC/CAD","bids":[],"asks":[{"price":92567.6,"qty":0.01129070}],"checksum":301324875,"timestamp":"2024-06-01T18:06:30.726904Z"}]}
{"channel":"book","type":"update","data":[{"symbol":"BTC/CAD","bids":[{"price":92445.9,"qty":0.00000000},{"price":92354.7,"qty":0.00360464},{"price":92437.1,"qty":0.00450800}],"asks":[],"checksum":2024627156,"timestamp":"2024-06-01T18:06:30.796370Z"}]}
{"channel":"book","type":"update","data":[{"symbol":"BTC/CAD","bids":[{"price":92471.6,"qty":0.00000000},{"price":92354.7,"qty":0.00360464},{"price":92462.8,"qty":0.00075700}],"asks":[],"checksum":3473217986,"timestamp":"2024-06-01T18:06:30.804225Z"}]}
{"channel":"book","type":"update","data":[{"symbol":"BTC/CAD","bids":[{"price":92403.4,"qty":0.00000000},{"price":92354.7,"qty":0.00360464}],"asks":[],"checksum":2954315268,"timestamp":"2024-06-01T18:06:30.810244Z"}]}
{"channel":"book","type":"update","data":[{"symbol":"BTC/CAD","bids":[{"price":92395.1,"qty":0.03283869}],"asks":[],"checksum":1785093722,"timestamp":"2024-06-01T18:06:30.814310Z"}]}
{"channel":"book","type":"update","data":[{"symbol":"BTC/CAD","bids":[],"asks":[{"price":92570.6,"qty":0.53677694}],"checksum":1279092748,"timestamp":"2024-06-01T18:06:30.864339Z"}]}
{"channel":"book","type":"update","data":[{"symbol":"BTC/CAD","bids":[],"asks":[{"price":92570.5,"qty":0.07500924}],"checksum":1008012085,"timestamp":"2024-06-01T18:06:30.869062Z"}]}
{"channel":"book","type":"update","data":[{"symbol":"BTC/CAD","bids":[{"price":92355.2,"qty":0.00299702}],"asks":[],"checksum":2666328014,"timestamp":"2024-06-01T18:06:32.049445Z"}]}
{"channel":"book","type":"update","data":[{"symbol":"BTC/CAD","bids":[{"price":92355.3,"qty":0.51943456}],"asks":[],"checksum":3909519644,"timestamp":"2024-06-01T18:06:32.291068Z"}]}
{"channel":"book","type":"update","data":[{"symbol":"BTC/CAD","bids":[{"price":92355.4,"qty":0.19632769}],"asks":[],"checksum":1572250347,"timestamp":"2024-06-01T18:06:32.294751Z"}]}
{"channel":"book","type":"update","data":[{"symbol":"BTC/CAD","bids":[{"price":92437.1,"qty":0.00000000},{"price":92355.1,"qty":0.01662494},{"price":92444.5,"qty":0.00450800}],"asks":[],"checksum":1590667245,"timestamp":"2024-06-01T18:06:32.462427Z"}]}
{"channel":"book","type":"update","data":[{"symbol":"BTC/CAD","bids":[{"price":92462.8,"qty":0.00000000},{"price":92355.1,"qty":0.01662494},{"price":92470.2,"qty":0.00075700}],"asks":[],"checksum":4103869448,"timestamp":"2024-06-01T18:06:32.469032Z"}]}
{"channel":"book","type":"update","data":[{"symbol":"BTC/CAD","bids":[{"price":92355.5,"qty":0.01662572}],"asks":[],"checksum":3779084505,"timestamp":"2024-06-01T18:06:32.492390Z"}]}
{"channel":"book","type":"update","data":[{"symbol":"BTC/CAD","bids":[],"asks":[{"price":92570.6,"qty":0.00000000},{"price":92571.4,"qty":0.32905872}],"checksum":566956717,"timestamp":"2024-06-01T18:06:32.650710Z"}]}
{"channel":"book","type":"update","data":[{"symbol":"BTC/CAD","bids":[],"asks":[{"price":92567.5,"qty":0.55983535}],"checksum":1442300915,"timestamp":"2024-06-01T18:06:32.653242Z"}]}
{"channel":"book","type":"update","data":[{"symbol":"BTC/CAD","bids":[],"asks":[{"price":92570.5,"qty":0.00107924}],"checksum":1169548610,"timestamp":"2024-06-01T18:06:32.653965Z"}]}
{"channel":"book","type":"update","data":[{"symbol":"BTC/CAD","bids":[],"asks":[{"price":92567.6,"qty":0.00000000},{"price":92571.3,"qty":0.07393000}],"checksum":3159341489,"timestamp":"2024-06-01T18:06:32.669788Z"}]}
{"channel":"book","type":"update","data":[{"symbol":"BTC/CAD","bids":[],"asks":[{"price":92567.4,"qty":0.01129070}],"checksum":2475575574,"timestamp":"2024-06-01T18:06:32.669915Z"}]}
{"channel":"book","type":"update","data":[{"symbol":"BTC/CAD","bids":[],"asks":[{"price":92570.5,"qty":0.00000000},{"price":92571.3,"qty":0.07393000}],"checksum":4198434592,"timestamp":"2024-06-01T18:06:33.228957Z"}]}
{"channel":"book","type":"update","data":[{"symbol":"BTC/CAD","bids":[],"asks":[{"price":92571.3,"qty":0.00000000},{"price":92571.4,"qty":0.32905872},{"price":92567.4,"qty":0.08522070}],"checksum":1657781100,"timestamp":"2024-06-01T18:06:33.232327Z"}]}
{"channel":"book","type":"update","data":[{"symbol":"BTC/CAD","bids":[],"asks":[{"price":92567.3,"qty":0.00152019}],"checksum":478579604,"timestamp":"2024-06-01T18:06:33.233469Z"}]}
{"channel":"book","type":"update","data":[{"symbol":"BTC/CAD","bids":[{"price":92470.2,"qty":0.00000000},{"price":92355.2,"qty":0.00299702},{"price":92461.1,"qty":0.00075700}],"asks":[],"checksum":502853682,"timestamp":"2024-06-01T18:06:34.439512Z"}]}
{"channel":"book","type":"update","data":[{"symbol":"BTC/CAD","bids":[{"price":92444.5,"qty":0.00000000},{"price":92355.2,"qty":0.00299702},{"price":92435.4,"qty":0.00450800}],"asks":[],"checksum":466013644,"timestamp":"2024-06-01T18:06:34.443472Z"}]}
{"channel":"book","type":"update","data":[{"symbol":"BTC/CAD","bids":[{"price":92395.1,"qty":0.00000000},{"price":92355.2,"qty":0.00299702}],"asks":[],"checksum":4236832906,"timestamp":"2024-06-01T18:06:34.452446Z"}]}
{"channel":"book","type":"update","data":[{"symbol":"BTC/CAD","bids":[{"price":92388.6,"qty":0.03283796}],"asks":[],"checksum":376576117,"timestamp":"2024-06-01T18:06:34.457622Z"}]}
{"channel":"book","type":"update","data":[{"symbol":"BTC/CAD","bids":[{"price":92458.9,"qty":0.00000000},{"price":92355.2,"qty":0.00299702},{"price":92436.8,"qty":0.00135200}],"asks":[],"checksum":2457528789,"timestamp":"2024-06-01T18:06:34.620833Z"}]}
{"channel":"book","type":"update","data":[{"symbol":"BTC/CAD","bids":[{"price":92355.6,"qty":0.00297021}],"asks":[],"checksum":3793854106,"timestamp":"2024-06-01T18:06:35.232809Z"}]}
{"channel":"book","type":"update","data":[{"symbol":"BTC/CAD","bids":[{"price":92355.6,"qty":0.49425498}],"asks":[],"checksum":2253850152,"timestamp":"2024-06-01T18:06:35.306959Z"}]}
{"channel":"book","type":"update","data":[{"symbol":"BTC/CAD","bids":[{"price":92355.4,"qty":0.00000000},{"price":92337.7,"qty":0.05824046},{"price":92355.7,"qty":0.19632769}],"asks":[],"checksum":1592544767,"timestamp":"2024-06-01T18:06:35.310170Z"}]}
{"channel":"book","type":"update","data":[{"symbol":"BTC/CAD","bids":[],"asks":[{"price":92567.5,"qty":0.00000000},{"price":92571.4,"qty":0.32905872}],"checksum":2750981569,"timestamp":"2024-06-01T18:06:35.470771Z"}]}
{"channel":"book","type":"update","data":[{"symbol":"BTC/CAD","bids":[],"asks":[{"price":92567.4,"qty":0.01129070},{"price":92571.3,"qty":0.07393000}],"checksum":3432189748,"timestamp":"2024-06-01T18:06:35.474452Z"}]}
{"channel":"book","type":"update","data":[{"symbol":"BTC/CAD","bids":[],"asks":[{"price":92567.3,"qty":0.58441400}],"checksum":1207922590,"timestamp":"2024-06-01T18:06:35.474572Z"}]}
{"channel":"book","type":"update","data":[{"symbol":"BTC/CAD","bids":[],"asks":[{"price":92567.4,"qty":0.00000000},{"price":92571.4,"qty":0.32905872}],"checksum":1968041412,"timestamp":"2024-06-01T18:06:35.482690Z"}]}
{"channel":"book","type":"update","data":[{"symbol":"BTC/CAD","bids":[],"asks":[{"price":92567.2,"qty":0.01129070}],"checksum":914669609,"timestamp":"2024-06-01T18:06:35.482871Z"}]}
{"channel":"book","type":"update","data":[{"symbol":"BTC/CAD","bids":[],"asks":[{"price":92567.3,"qty":0.58289381}],"checksum":173181299,"timestamp":"2024-06-01T18:06:35.565837Z"}]}
{"channel":"book","type":"update","data":[{"symbol":"BTC/CAD","bids":[],"asks":[{"price":92567.3,"qty":0.58567885}],"checksum":2675536245,"timestamp":"2024-06-01T18:06:35.571364Z"}]}
{"channel":"book","type":"update","data":[{"symbol":"BTC/CAD","bids":[{"price":92355.5,"qty":0.00000000},{"price":92337.7,"qty":0.05824046},{"price":92355.8,"qty":0.01662758}],"asks":[],"checksum":490561801,"timestamp":"2024-06-01T18:06:35.782902Z"}]}
{"channel":"book","type":"update","data":[{"symbol":"BTC/CAD","bids":[],"asks":[{"price":92571.3,"qty":0.00000000},{"price":92571.4,"qty":0.32905872},{"price":92567.2,"qty":0.08522070}],"checksum":1671912544,"timestamp":"2024-06-01T18:06:37.780303Z"}]}
{"channel":"book","type":"update","data":[{"symbol":"BTC/CAD","bids":[],"asks":[{"price":92567.3,"qty":0.58289381}],"checksum":2320618157,"timestamp":"2024-06-01T18:06:37.942847Z"}]}
{"channel":"book","type":"update","data":[{"symbol":"BTC/CAD","bids":[],"asks":[{"price":92567.1,"qty":0.00169583}],"checksum":840460328,"timestamp":"2024-06-01T18:06:37.947597Z"}]}
{"channel":"book","type":"update","data":[{"symbol":"BTC/CAD","bids":[],"asks":[{"price":92567.3,"qty":0.00000000},{"price":92571.4,"qty":0.32905872}],"checksum":3848161680,"timestamp":"2024-06-01T18:06:38.233734Z"}]}
{"channel":"book","type":"update","data":[{"symbol":"BTC/CAD","bids":[],"asks":[{"price":92567.1,"qty":0.65375877}],"checksum":294127820,"timestamp":"2024-06-01T18:06:38.236377Z"}]}
{"channel":"book","type":"update","data":[{"symbol":"BTC/CAD","bids":[],"asks":[{"price":92567.2,"qty":0.07393000}],"checksum":2739008334,"timestamp":"2024-06-01T18:06:38.266430Z"}]}
{"channel":"book","type":"update","data":[{"symbol":"BTC/CAD","bids":[],"asks":[{"price":92567.0,"qty":0.01129070}],"checksum":1533323349,"timestamp":"2024-06-01T18:06:38.266642Z"}]}
{"channel":"book","type":"update","data":[{"symbol":"BTC/CAD","bids":[{"price":92355.6,"qty":0.00297021}],"asks":[],"checksum":1272846967,"timestamp":"2024-06-01T18:06:38.333330Z"}]}
{"channel":"book","type":"update","data":[{"symbol":"BTC/CAD","bids":[{"price":92355.9,"qty":0.49128477}],"asks":[],"checksum":1262195884,"timestamp":"2024-06-01T18:06:38.334181Z"}]}
{"channel":"book","type":"update","data":[{"symbol":"BTC/CAD","bids":[],"asks":[{"price":92567.2,"qty":0.00000000},{"price":92571.4,"qty":0.32905872},{"price":92567.0,"qty":0.08522070}],"checksum":1054460402,"timestamp":"2024-06-01T18:06:38.336528Z"}]}
{"channel":"book","type":"update","data":[{"symbol":"BTC/CAD","bids":[{"price":92355.7,"qty":0.00000000},{"price":92355.6,"qty":0.00297021},{"price":92356.0,"qty":0.19632769}],"asks":[],"checksum":2872584502,"timestamp":"2024-06-01T18:06:38.337626Z"}]}
{"channel":"book","type":"update","data":[{"symbol":"BTC/CAD","bids":[{"price":92355.9,"qty":0.49401182}],"asks":[],"checksum":1537358644,"timestamp":"2024-06-01T18:06:38.445625Z"}]}
{"channel":"book","type":"update","data":[{"symbol":"BTC/CAD","bids":[{"price":92355.8,"qty":0.00000000},{"price":92337.7,"qty":0.05824046},{"price":92356.1,"qty":0.01662758}],"asks":[],"checksum":1787727620,"timestamp":"2024-06-01T18:06:38.928914Z"}]}
{"channel":"book","type":"update","data":[{"symbol":"BTC/CAD","bids":[],"asks":[{"price":92567.1,"qty":0.65206294}],"checksum":2510087634,"timestamp":"2024-06-01T18:06:40.356290Z"}]}
{"channel":"book","type":"update","data":[{"symbol":"BTC/CAD","bids":[],"asks":[{"price":92566.9,"qty":0.00154023}],"checksum":3963249004,"timestamp":"2024-06-01T18:06:40.360727Z"}]}
{"channel":"book","type":"update","data":[{"symbol":"BTC/CAD","bids":[],"asks":[{"price":92567.1,"qty":0.00000000},{"price":92571.4,"qty":0.32905872}],"checksum":3671078428,"timestamp":"2024-06-01T18:06:41.057552Z"}]}
{"channel":"book","type":"update","data":[{"symbol":"BTC/CAD","bids":[],"asks":[{"price":92566.9,"qty":0.60749040}],"checksum":119102061,"timestamp":"2024-06-01T18:06:41.059940Z"}]}
{"channel":"book","type":"update","data":[{"symbol":"BTC/CAD","bids":[],"asks":[{"price":92567.0,"qty":0.01129070},{"price":92571.3,"qty":0.07393000}],"checksum":2052547867,"timestamp":"2024-06-01T18:06:41.061074Z"}]}
{"channel":"book","type":"update","data":[{"symbol":"BTC/CAD","bids":[],"asks":[{"price":92566.8,"qty":0.01129070}],"checksum":2620263902,"timestamp":"2024-06-01T18:06:41.077344Z"}]}
{"channel":"book","type":"update","data":[{"symbol":"BTC/CAD","bids":[],"asks":[{"price":92567.0,"qty":0.00000000},{"price":92571.3,"qty":0.07393000}],"checksum":726363514,"timestamp":"2024-06-01T18:06:41.077367Z"}]}
{"channel":"book","type":"update","data":[{"symbol":"BTC/CAD","bids":[{"price":92355.9,"qty":0.00272705}],"asks":[],"checksum":173702131,"timestamp":"2024-06-01T18:06:41.380752Z"}]}
{"channel":"book","type":"update","data":[{"symbol":"BTC/CAD","bids":[{"price":92356.2,"qty":0.49065176}],"asks":[],"checksum":2945214202,"timestamp":"2024-06-01T18:06:41.380992Z"}]}
{"channel":"book","type":"update","data":[{"symbol":"BTC/CAD","bids":[{"price":92356.0,"qty":0.00000000},{"price":92355.9,"qty":0.00272705},{"price":92356.3,"qty":0.19632769}],"asks":[],"checksum":2007231753,"timestamp":"2024-06-01T18:06:41.383999Z"}]}
{"channel":"book","type":"update","data":[{"symbol":"BTC/CAD","bids":[{"price":92356.4,"qty":0.00272705}],"asks":[],"checksum":2312377059,"timestamp":"2024-06-01T18:06:41.656479Z"}]}
{"channel":"book","type":"update","data":[{"symbol":"BTC/CAD","bids":[],"asks":[{"price":92571.3,"qty":0.00000000},{"price":92571.4,"qty":0.32905872},{"price":92566.8,"qty":0.08522070}],"checksum":2851752276,"timestamp":"2024-06-01T18:06:41.659160Z"}]}
{"channel":"book","type":"update","data":[{"symbol":"BTC/CAD","bids":[{"price":92356.5,"qty":0.01662752}],"asks":[],"checksum":3932792178,"timestamp":"2024-06-01T18:06:42.014194Z"}]}
{"channel":"book","type":"update","data":[{"symbol":"BTC/CAD","bids":[],"asks":[{"price":92566.9,"qty":0.60595017}],"checksum":3015626834,"timestamp":"2024-06-01T18:06:42.776533Z"}]}
{"channel":"book","type":"update","data":[{"symbol":"BTC/CAD","bids":[],"asks":[{"price":92566.7,"qty":0.00122902}],"checksum":528947450,"timestamp":"2024-06-01T18:06:42.778924Z"}]}
{"channel":"book","type":"update","data":[{"symbol":"BTC/CAD","bids":[],"asks":[{"price":92566.9,"qty":0.00000000},{"price":92571.4,"qty":0.32905872}],"checksum":3273571404,"timestamp":"2024-06-01T18:06:43.819979Z"}]}
{"channel":"book","type":"update","data":[{"symbol":"BTC/CAD","bids":[],"asks":[{"price":92566.8,"qty":0.01129070},{"price":92571.3,"qty":0.07393000}],"checksum":2471992823,"timestamp":"2024-06-01T18:06:43.823317Z"}]}
{"channel":"book","type":"update","data":[{"symbol":"BTC/CAD","bids":[],"asks":[{"price":92566.7,"qty":0.65329197}],"checksum":225798288,"timestamp":"2024-06-01T18:06:43.824666Z"}]}
{"channel":"book","type":"update","data":[{"symbol":"BTC/CAD","bids":[],"asks":[{"price":92566.6,"qty":0.01129070}],"checksum":3991783350,"timestamp":"2024-06-01T18:06:43.838831Z"}]}
{"channel":"book","type":"update","data":[{"symbol":"BTC/CAD","bids":[],"asks":[{"price":92566.8,"qty":0.00000000},{"price":92571.3,"qty":0.07393000}],"checksum":2955339505,"timestamp":"2024-06-01T18:06:43.839056Z"}]}
{"channel":"book","type":"update","data":[{"symbol":"BTC/CAD","bids":[],"asks":[{"price":92571.3,"qty":0.00000000},{"price":92571.4,"qty":0.32905872},{"price":92566.6,"qty":0.08522070}],"checksum":3198968604,"timestamp":"2024-06-01T18:06:44.358032Z"}]}
{"channel":"book","type":"update","data":[{"symbol":"BTC/CAD","bids":[{"price":92356.6,"qty":0.49065176}],"asks":[],"checksum":2711615948,"timestamp":"2024-06-01T18:06:44.358642Z"}]}
{"channel":"book","type":"update","data":[{"symbol":"BTC/CAD","bids":[{"price":92356.7,"qty":0.19632769}],"asks":[],"checksum":2878454887,"timestamp":"2024-06-01T18:06:44.361906Z"}]}
{"channel":"book","type":"update","data":[{"symbol":"BTC/CAD","bids":[{"price":92356.8,"qty":0.00272705}],"asks":[],"checksum":483115765,"timestamp":"2024-06-01T18:06:44.883253Z"}]}
{"channel":"book","type":"update","data":[{"symbol":"BTC/CAD","bids":[{"price":92356.9,"qty":0.01662745}],"asks":[],"checksum":1782665071,"timestamp":"2024-06-01T18:06:44.985866Z"}]}
{"channel":"book","type":"update","data":[{"symbol":"BTC/CAD","bids":[],"asks":[{"price":92566.7,"qty":0.65206295}],"checksum":3523840666,"timestamp":"2024-06-01T18:06:45.195503Z"}]}
{"channel":"book","type":"update","data":[{"symbol":"BTC/CAD","bids":[],"asks":[{"price":92566.5,"qty":0.00169583}],"checksum":3187817695,"timestamp":"2024-06-01T18:06:45.197560Z"}]}
{"channel":"book","type":"update","data":[{"symbol":"BTC/CAD","bids":[],"asks":[{"price":92566.7,"qty":0.00000000},{"price":92571.4,"qty":0.32905872}],"checksum":1221415459,"timestamp":"2024-06-01T18:06:46.666801Z"}]}
{"channel":"book","type":"update","data":[{"symbol":"BTC/CAD","bids":[],"asks":[{"price":92566.5,"qty":0.60764602}],"checksum":3894606812,"timestamp":"2024-06-01T18:06:46.669501Z"}]}
{"channel":"book","type":"update","data":[{"symbol":"BTC/CAD","bids":[],"asks":[{"price":92566.6,"qty":0.01129070},{"price":92571.3,"qty":0.07393000}],"checksum":2579178077,"timestamp":"2024-06-01T18:06:46.670537Z"}]}
{"channel":"book","type":"update","data":[{"symbol":"BTC/CAD","bids":[],"asks":[{"price":92566.4,"qty":0.01129070}],"checksum":430278028,"timestamp":"2024-06-01T18:06:46.684637Z"}]}
{"channel":"book","type":"update","data":[{"symbol":"BTC/CAD","bids":[],"asks":[{"price":92566.6,"qty":0.00000000},{"price":92571.3,"qty":0.07393000}],"checksum":3378122729,"timestamp":"2024-06-01T18:06:46.684738Z"}]}
{"channel":"book","type":"update","data":[{"symbol":"BTC/CAD","bids":[{"price":92357.0,"qty":0.49065176}],"asks":[],"checksum":3808295047,"timestamp":"2024-06-01T18:06:47.382385Z"}]}
{"channel":"book","type":"update","data":[{"symbol":"BTC/CAD","bids":[],"asks":[{"price":92571.3,"qty":0.00000000},{"price":92571.4,"qty":0.32905872},{"price":92566.4,"qty":0.08522070}],"checksum":2603323668,"timestamp":"2024-06-01T18:06:47.385254Z"}]}
{"channel":"book","type":"update","data":[{"symbol":"BTC/CAD","bids":[{"price":92357.1,"qty":0.19632769}],"asks":[],"checksum":2935290312,"timestamp":"2024-06-01T18:06:47.385525Z"}]}
{"channel":"book","type":"update","data":[{"symbol":"BTC/CAD","bids":[],"asks":[{"price":92566.5,"qty":0.60595019}],"checksum":314371826,"timestamp":"2024-06-01T18:06:47.636938Z"}]}
{"channel":"book","type":"update","data":[{"symbol":"BTC/CAD","bids":[],"asks":[{"price":92566.3,"qty":0.00138462}],"checksum":1919467915,"timestamp":"2024-06-01T18:06:47.641788Z"}]}
{"channel":"book","type":"update","data":[{"symbol":"BTC/CAD","bids":[{"price":92356.9,"qty":0.00000000},{"price":92356.8,"qty":0.00272705},{"price":92357.2,"qty":0.01662760}],"asks":[],"checksum":4188475752,"timestamp":"2024-06-01T18:06:47.774955Z"}]}
{"channel":"book","type":"update","data":[{"symbol":"BTC/CAD","bids":[{"price":92357.3,"qty":0.00272705}],"asks":[],"checksum":4092290102,"timestamp":"2024-06-01T18:06:48.083994Z"}]}
{"channel":"book","type":"update","data":[{"symbol":"BTC/CAD","bids":[{"price":92357.2,"qty":0.00000000},{"price":92357.0,"qty":0.49065176},{"price":92357.4,"qty":0.01662756}],"asks":[],"checksum":3152980470,"timestamp":"2024-06-01T18:06:48.372574Z"}]}
{"channel":"book","type":"update","data":[{"symbol":"BTC/CAD","bids":[{"price":92388.6,"qty":0.00000000},{"price":92357.0,"qty":0.49065176}],"asks":[],"checksum":3201967289,"timestamp":"2024-06-01T18:06:49.464981Z"}]}
{"channel":"book","type":"update","data":[{"symbol":"BTC/CAD","bids":[{"price":92388.9,"qty":0.03295728}],"asks":[],"checksum":2247902484,"timestamp":"2024-06-01T18:06:49.470949Z"}]}
{"channel":"book","type":"update","data":[{"symbol":"BTC/CAD","bids":[],"asks":[{"price":92566.5,"qty":0.00000000},{"price":92571.4,"qty":0.32905872}],"checksum":112159492,"timestamp":"2024-06-01T18:06:49.564188Z"}]}
{"channel":"book","type":"update","data":[{"symbol":"BTC/CAD","bids":[],"asks":[{"price":92566.4,"qty":0.01129070},{"price":92571.3,"qty":0.07393000}],"checksum":4239414265,"timestamp":"2024-06-01T18:06:49.568653Z"}]}
{"channel":"book","type":"update","data":[{"symbol":"BTC/CAD","bids":[],"asks":[{"price":92566.3,"qty":0.65344764}],"checksum":404317086,"timestamp":"2024-06-01T18:06:49.568858Z"}]}
{"channel":"book","type":"update","data":[{"symbol":"BTC/CAD","bids":[],"asks":[{"price":92566.4,"qty":0.00000000},{"price":92571.4,"qty":0.32905872}],"checksum":95548948,"timestamp":"2024-06-01T18:06:49.585686Z"}]}
{"channel":"book","type":"update","data":[{"symbol":"BTC/CAD","bids":[],"asks":[{"price":92566.2,"qty":0.01129070}],"checksum":778758630,"timestamp":"2024-06-01T18:06:49.585952Z"}]}
{"channel":"book","type":"update","data":[{"symbol":"BTC/CAD","bids":[],"asks":[{"price":92566.3,"qty":0.65206302}],"checksum":4224172834,"timestamp":"2024-06-01T18:06:50.031423Z"}]}
{"channel":"book","type":"update","data":[{"symbol":"BTC/CAD","bids":[],"asks":[{"price":92566.1,"qty":0.00200703}],"checksum":4049425314,"timestamp":"2024-06-01T18:06:50.035951Z"}]}
{"channel":"book","type":"update","data":[{"symbol":"BTC/CAD","bids":[{"price":92357.5,"qty":0.49065176}],"asks":[],"checksum":1255755045,"timestamp":"2024-06-01T18:06:50.384617Z"}]}
{"channel":"book","type":"update","data":[{"symbol":"BTC/CAD","bids":[],"asks":[{"price":92566.2,"qty":0.08522070}],"checksum":2874858642,"timestamp":"2024-06-01T18:06:50.385972Z"}]}
{"channel":"book","type":"update","data":[{"symbol":"BTC/CAD","bids":[{"price":92357.6,"qty":0.19632769}],"asks":[],"checksum":3322857348,"timestamp":"2024-06-01T18:06:50.387616Z"}]}
{"channel":"book","type":"update","data":[{"symbol":"BTC/CAD","bids":[{"price":92357.4,"qty":0.00000000},{"price":92357.3,"qty":0.00272705},{"price":92357.7,"qty":0.01662745}],"asks":[],"checksum":2335346337,"timestamp":"2024-06-01T18:06:50.636300Z"}]}
{"channel":"book","type":"update","data":[{"symbol":"BTC/CAD","bids":[{"price":92357.7,"qty":0.00000000},{"price":92357.3,"qty":0.00272705},{"price":92357.8,"qty":0.01662743}],"asks":[],"checksum":910412927,"timestamp":"2024-06-01T18:06:51.243210Z"}]}
{"channel":"book","type":"update","data":[{"symbol":"BTC/CAD","bids":[{"price":92357.8,"qty":0.01959764}],"asks":[],"checksum":3440686687,"timestamp":"2024-06-01T18:06:51.284199Z"}]}
{"channel":"book","type":"update","data":[{"symbol":"BTC/CAD","bids":[{"price":92357.8,"qty":0.00297021},{"price":92357.7,"qty":0.01662745}],"asks":[],"checksum":3140023653,"timestamp":"2024-06-01T18:06:51.301821Z"}]}
{"channel":"book","type":"update","data":[{"symbol":"BTC/CAD","bids":[{"price":92357.7,"qty":0.00000000},{"price":92357.5,"qty":0.49065176},{"price":92357.9,"qty":0.01662741}],"asks":[],"checksum":3977400055,"timestamp":"2024-06-01T18:06:51.833112Z"}]}
{"channel":"book","type":"update","data":[{"symbol":"BTC/CAD","bids":[],"asks":[{"price":92566.3,"qty":0.00000000},{"price":92571.4,"qty":0.32905872}],"checksum":4021830443,"timestamp":"2024-06-01T18:06:52.242435Z"}]}
{"channel":"book","type":"update","data":[{"symbol":"BTC/CAD","bids":[],"asks":[{"price":92566.0,"qty":0.62900657}],"checksum":3353691984,"timestamp":"2024-06-01T18:06:52.245319Z"}]}
{"channel":"book","type":"update","data":[{"symbol":"BTC/CAD","bids":[],"asks":[{"price":92566.2,"qty":0.01129070}],"checksum":3349259399,"timestamp":"2024-06-01T18:06:52.246054Z"}]}
{"channel":"book","type":"update","data":[{"symbol":"BTC/CAD","bids":[],"asks":[{"price":92566.2,"qty":0.00000000},{"price":92571.3,"qty":0.07393000}],"checksum":4121976184,"timestamp":"2024-06-01T18:06:52.262394Z"}]}
{"channel":"book","type":"update","data":[{"symbol":"BTC/CAD","bids":[],"asks":[{"price":92565.9,"qty":0.01129070}],"checksum":2378938700,"timestamp":"2024-06-01T18:06:52.262467Z"}]}
{"channel":"book","type":"update","data":[{"symbol":"BTC/CAD","bids":[],"asks":[{"price":92566.1,"qty":0.00000000},{"price":92571.3,"qty":0.07393000}],"checksum":2660329876,"timestamp":"2024-06-01T18:06:52.382506Z"}]}
{"channel":"book","type":"update","data":[{"symbol":"BTC/CAD","bids":[],"asks":[{"price":92566.1,"qty":0.00185143}],"checksum":3876008466,"timestamp":"2024-06-01T18:06:52.384277Z"}]}
{"channel":"book","type":"update","data":[{"symbol":"BTC/CAD","bids":[],"asks":[{"price":92565.9,"qty":0.08522070}],"checksum":3751250759,"timestamp":"2024-06-01T18:06:52.807814Z"}]}
{"channel":"book","type":"update","data":[{"symbol":"BTC/CAD","bids":[],"asks":[{"price":92565.9,"qty":0.07393000}],"checksum":4224126377,"timestamp":"2024-06-01T18:06:52.955407Z"}]}
{"channel":"book","type":"update","data":[{"symbol":"BTC/CAD","bids":[],"asks":[{"price":92566.0,"qty":0.64029727}],"checksum":3470785178,"timestamp":"2024-06-01T18:06:52.955743Z"}]}
{"channel":"book","type":"update","data":[{"symbol":"BTC/CAD","bids":[],"asks":[{"price":92515.8,"qty":0.47310316}],"checksum":2587315613,"timestamp":"2024-06-01T18:06:53.318917Z"}]}
{"channel":"book","type":"update","data":[{"symbol":"BTC/CAD","bids":[],"asks":[{"price":92515.8,"qty":0.52029400}],"checksum":3470785178,"timestamp":"2024-06-01T18:06:53.324597Z"}]}
{"channel":"book","type":"update","data":[{"symbol":"BTC/CAD","bids":[{"price":92358.0,"qty":0.49065176}],"asks":[],"checksum":465631899,"timestamp":"2024-06-01T18:06:53.418290Z"}]}
{"channel":"book","type":"update","data":[{"symbol":"BTC/CAD","bids":[{"price":92358.1,"qty":0.19632769}],"asks":[],"checksum":1334246533,"timestamp":"2024-06-01T18:06:53.421658Z"}]}
{"channel":"book","type":"update","data":[{"symbol":"BTC/CAD","bids":[{"price":92357.9,"qty":0.00000000},{"price":92357.8,"qty":0.00297021},{"price":92358.2,"qty":0.01662731}],"asks":[],"checksum":514179580,"timestamp":"2024-06-01T18:06:53.875025Z"}]}
{"channel":"book","type":"update","data":[{"symbol":"BTC/CAD","bids":[{"price":92435.4,"qty":0.00000000},{"price":92357.8,"qty":0.00297021},{"price":92425.5,"qty":0.00450800}],"asks":[],"checksum":2007536025,"timestamp":"2024-06-01T18:06:54.344831Z"}]}
{"channel":"book","type":"update","data":[{"symbol":"BTC/CAD","bids":[{"price":92461.1,"qty":0.00000000},{"price":92357.8,"qty":0.00297021},{"price":92449.7,"qty":0.00075700}],"asks":[],"checksum":1074915905,"timestamp":"2024-06-01T18:06:54.366063Z"}]}
{"channel":"book","type":"update","data":[{"symbol":"BTC/CAD","bids":[{"price":92358.3,"qty":0.00272705}],"asks":[],"checksum":2485156844,"timestamp":"2024-06-01T18:06:54.513925Z"}]}
{"channel":"book","type":"update","data":[{"symbol":"BTC/CAD","bids":[],"asks":[{"price":92566.1,"qty":0.00000000},{"price":92571.4,"qty":0.32905872}],"checksum":1533211961,"timestamp":"2024-06-01T18:06:54.750995Z"}]}
{"channel":"book","type":"update","data":[{"symbol":"BTC/CAD","bids":[],"asks":[{"price":92565.8,"qty":0.00165012}],"checksum":2190994224,"timestamp":"2024-06-01T18:06:54.753414Z"}]}
{"channel":"book","type":"update","data":[{"symbol":"BTC/CAD","bids":[],"asks":[{"price":92566.0,"qty":0.01129070}],"checksum":3283533650,"timestamp":"2024-06-01T18:06:55.105571Z"}]}
{"channel":"book","type":"update","data":[{"symbol":"BTC/CAD","bids":[],"asks":[{"price":92565.8,"qty":0.67676957}],"checksum":713290548,"timestamp":"2024-06-01T18:06:55.109002Z"}]}
{"channel":"book","type":"update","data":[{"symbol":"BTC/CAD","bids":[],"asks":[{"price":92565.9,"qty":0.00000000},{"price":92571.4,"qty":0.32905872},{"price":92571.3,"qty":0.07393000}],"checksum":919559814,"timestamp":"2024-06-01T18:06:55.109175Z"}]}
{"channel":"book","type":"update","data":[{"symbol":"BTC/CAD","bids":[{"price":92358.2,"qty":0.00000000},{"price":92358.0,"qty":0.49065176},{"price":92358.4,"qty":0.01660075}],"asks":[],"checksum":766135844,"timestamp":"2024-06-01T18:06:55.901183Z"}]}
{"channel":"book","type":"update","data":[{"symbol":"BTC/CAD","bids":[],"asks":[{"price":92571.3,"qty":0.00000000},{"price":92571.4,"qty":0.32905872},{"price":92565.7,"qty":0.07393000}],"checksum":1735207377,"timestamp":"2024-06-01T18:06:55.904700Z"}]}
{"channel":"book","type":"update","data":[{"symbol":"BTC/CAD","bids":[{"price":92449.7,"qty":0.00000000},{"price":92358.0,"qty":0.49065176},{"price":92454.3,"qty":0.00075700}],"asks":[],"checksum":190729004,"timestamp":"2024-06-01T18:06:56.076262Z"}]}
{"channel":"book","type":"update","data":[{"symbol":"BTC/CAD","bids":[{"price":92358.5,"qty":0.49067094}],"asks":[],"checksum":3725106909,"timestamp":"2024-06-01T18:06:56.476577Z"}]}
{"channel":"book","type":"update","data":[{"symbol":"BTC/CAD","bids":[{"price":92358.6,"qty":0.19632769}],"asks":[],"checksum":3680362557,"timestamp":"2024-06-01T18:06:56.480173Z"}]}
{"channel":"book","type":"update","data":[{"symbol":"BTC/CAD","bids":[{"price":92358.4,"qty":0.00000000},{"price":92358.3,"qty":0.00272705},{"price":92358.7,"qty":0.01660060}],"asks":[],"checksum":3630881124,"timestamp":"2024-06-01T18:06:56.548360Z"}]}
{"channel":"book","type":"update","data":[{"symbol":"BTC/CAD","bids":[],"asks":[{"price":92565.8,"qty":0.67511945}],"checksum":1882739778,"timestamp":"2024-06-01T18:06:57.198909Z"}]}
{"channel":"book","type":"update","data":[{"symbol":"BTC/CAD","bids":[],"asks":[{"price":92565.6,"qty":0.00154024}],"checksum":2148538895,"timestamp":"2024-06-01T18:06:57.201541Z"}]}
{"channel":"book","type":"update","data":[{"symbol":"BTC/CAD","bids":[{"price":92358.8,"qty":0.00263708}],"asks":[],"checksum":2259799481,"timestamp":"2024-06-01T18:06:57.755590Z"}]}
{"channel":"book","type":"update","data":[{"symbol":"BTC/CAD","bids":[{"price":92358.7,"qty":0.00000000},{"price":92358.5,"qty":0.49067094},{"price":92358.9,"qty":0.01660037}],"asks":[],"checksum":1608113269,"timestamp":"2024-06-01T18:06:57.802422Z"}]}
{"channel":"book","type":"update","data":[{"symbol":"BTC/CAD","bids":[],"asks":[{"price":92565.8,"qty":0.00000000},{"price":92567.7,"qty":0.00685000}],"checksum":1305956463,"timestamp":"2024-06-01T18:06:57.897074Z"}]}
{"channel":"book","type":"update","data":[{"symbol":"BTC/CAD","bids":[],"asks":[{"price":92565.7,"qty":0.00000000},{"price":92571.4,"qty":0.32905872},{"price":92571.3,"qty":0.07393000}],"checksum":9808218,"timestamp":"2024-06-01T18:06:57.900878Z"}]}
{"channel":"book","type":"update","data":[{"symbol":"BTC/CAD","bids":[],"asks":[{"price":92565.6,"qty":0.63060100}],"checksum":611511691,"timestamp":"2024-06-01T18:06:57.901758Z"}]}
{"channel":"book","type":"update","data":[{"symbol":"BTC/CAD","bids":[],"asks":[{"price":92571.3,"qty":0.00000000},{"price":92571.4,"qty":0.32905872},{"price":92565.5,"qty":0.07393000}],"checksum":2848245862,"timestamp":"2024-06-01T18:06:59.100742Z"}]}
{"channel":"book","type":"update","data":[{"symbol":"BTC/CAD","bids":[{"price":92359.0,"qty":0.49066857}],"asks":[],"checksum":1617223205,"timestamp":"2024-06-01T18:06:59.435673Z"}]}
{"channel":"book","type":"update","data":[{"symbol":"BTC/CAD","bids":[{"price":92359.1,"qty":0.19632769}],"asks":[],"checksum":686686220,"timestamp":"2024-06-01T18:06:59.439148Z"}]}
{"channel":"book","type":"update","data":[{"symbol":"BTC/CAD","bids":[],"asks":[{"price":92565.6,"qty":0.62906076}],"checksum":2178549018,"timestamp":"2024-06-01T18:06:59.518229Z"}]}
{"channel":"book","type":"update","data":[{"symbol":"BTC/CAD","bids":[],"asks":[{"price":92565.4,"qty":0.00185144}],"checksum":1615329801,"timestamp":"2024-06-01T18:06:59.520880Z"}]}
{"channel":"book","type":"update","data":[{"symbol":"BTC/CAD","bids":[{"price":92358.9,"qty":0.00000000},{"price":92358.8,"qty":0.00263708},{"price":92359.2,"qty":0.01660009}],"asks":[],"checksum":186627520,"timestamp":"2024-06-01T18:07:00.311907Z"}]}
{"channel":"book","type":"update","data":[{"symbol":"BTC/CAD","bids":[],"asks":[{"price":92565.6,"qty":0.00000000},{"price":92567.7,"qty":0.00685000}],"checksum":1577643556,"timestamp":"2024-06-01T18:07:00.720641Z"}]}
{"channel":"book","type":"update","data":[{"symbol":"BTC/CAD","bids":[],"asks":[{"price":92565.3,"qty":0.65211920}],"checksum":2348213163,"timestamp":"2024-06-01T18:07:00.723332Z"}]}
{"channel":"book","type":"update","data":[{"symbol":"BTC/CAD","bids":[],"asks":[{"price":92565.5,"qty":0.00000000},{"price":92567.7,"qty":0.00685000}],"checksum":3307446512,"timestamp":"2024-06-01T18:07:00.724184Z"}]}
{"channel":"book","type":"update","data":[{"symbol":"BTC/CAD","bids":[{"price":92359.3,"qty":0.00277218}],"asks":[],"checksum":1670606572,"timestamp":"2024-06-01T18:07:00.929169Z"}]}
