{"channel":"book","type":"snapshot","data":[{"symbol":"BTC/USDC","bids":[{"price":67699.98,"qty":0.02100000},{"price":67693.93,"qty":0.02953653},{"price":67693.92,"qty":0.00058352},{"price":67693.89,"qty":0.08716737},{"price":67692.83,"qty":0.00021288},{"price":67687.45,"qty":0.03693446},{"price":67686.81,"qty":0.08707248},{"price":67680.73,"qty":2.55878607},{"price":67680.72,"qty":0.01820000},{"price":67672.13,"qty":0.03692142}],"asks":[{"price":67704.76,"qty":0.03640000},{"price":67711.53,"qty":0.14770791},{"price":67711.64,"qty":0.01820000},{"price":67711.87,"qty":0.03692115},{"price":67718.42,"qty":0.01820000},{"price":67729.73,"qty":0.05259291},{"price":67729.74,"qty":0.00248625},{"price":67729.76,"qty":0.01820000},{"price":67730.18,"qty":0.02233000},{"price":67734.39,"qty":0.98345353}],"checksum":1815902782}]}
{"channel":"book","type":"update","data":[{"symbol":"BTC/USDC","bids":[],"asks":[{"price":67729.74,"qty":0.00000000},{"price":67734.50,"qty":0.54189700}],"checksum":3659476738,"timestamp":"2024-06-01T18:06:30.864410Z"}]}
{"channel":"book","type":"update","data":[{"symbol":"BTC/USDC","bids":[],"asks":[{"price":67729.72,"qty":0.00284295}],"checksum":1101986126,"timestamp":"2024-06-01T18:06:30.868827Z"}]}
{"channel":"book","type":"update","data":[{"symbol":"BTC/USDC","bids":[{"price":67693.92,"qty":0.00000000},{"price":67671.91,"qty":0.01820000}],"asks":[],"checksum":4288660627,"timestamp":"2024-06-01T18:06:30.868900Z"}]}
{"channel":"book","type":"update","data":[{"symbol":"BTC/USDC","bids":[],"asks":[{"price":67734.38,"qty":0.00331031}],"checksum":1867246624,"timestamp":"2024-06-01T18:06:30.868933Z"}]}
{"channel":"book","type":"update","data":[{"symbol":"BTC/USDC","bids":[{"price":67683.55,"qty":0.05074021}],"asks":[],"checksum":10053856,"timestamp":"2024-06-01T18:06:30.887471Z"}]}
{"channel":"book","type":"update","data":[{"symbol":"BTC/USDC","bids":[],"asks":[{"price":67727.82,"qty":0.04716959}],"checksum":3933971421,"timestamp":"2024-06-01T18:06:31.458474Z"}]}
{"channel":"book","type":"update","data":[{"symbol":"BTC/USDC","bids":[],"asks":[{"price":67727.82,"qty":0.00000000},{"price":67734.38,"qty":0.00331031}],"checksum":10053856,"timestamp":"2024-06-01T18:06:31.466820Z"}]}
{"channel":"book","type":"update","data":[{"symbol":"BTC/USDC","bids":[],"asks":[{"price":67727.82,"qty":0.05439762}],"checksum":3844721491,"timestamp":"2024-06-01T18:06:31.610422Z"}]}
{"channel":"book","type":"update","data":[{"symbol":"BTC/USDC","bids":[],"asks":[{"price":67727.82,"qty":0.00000000},{"price":67734.38,"qty":0.00331031}],"checksum":10053856,"timestamp":"2024-06-01T18:06:31.617743Z"}]}
{"channel":"book","type":"update","data":[{"symbol":"BTC/USDC","bids":[],"asks":[{"price":67734.38,"qty":0.00360192}],"checksum":247606605,"timestamp":"2024-06-01T18:06:31.698107Z"}]}
{"channel":"book","type":"update","data":[{"symbol":"BTC/USDC","bids":[{"price":67680.73,"qty":2.55907213}],"asks":[],"checksum":2710407934,"timestamp":"2024-06-01T18:06:31.698633Z"}]}
{"channel":"book","type":"update","data":[{"symbol":"BTC/USDC","bids":[],"asks":[{"price":67727.82,"qty":0.04927795}],"checksum":986261118,"timestamp":"2024-06-01T18:06:31.758204Z"}]}
{"channel":"book","type":"update","data":[{"symbol":"BTC/USDC","bids":[],"asks":[{"price":67727.82,"qty":0.00000000},{"price":67734.38,"qty":0.00360192}],"checksum":2710407934,"timestamp":"2024-06-01T18:06:31.764220Z"}]}
{"channel":"book","type":"update","data":[{"symbol":"BTC/USDC","bids":[],"asks":[{"price":67727.82,"qty":0.04748295}],"checksum":3900611910,"timestamp":"2024-06-01T18:06:31.908811Z"}]}
{"channel":"book","type":"update","data":[{"symbol":"BTC/USDC","bids":[],"asks":[{"price":67727.82,"qty":0.00000000},{"price":67734.38,"qty":0.00360192}],"checksum":2710407934,"timestamp":"2024-06-01T18:06:31.916822Z"}]}
{"channel":"book","type":"update","data":[{"symbol":"BTC/USDC","bids":[],"asks":[{"price":67727.82,"qty":0.04503814}],"checksum":2506118613,"timestamp":"2024-06-01T18:06:32.059061Z"}]}
{"channel":"book","type":"update","data":[{"symbol":"BTC/USDC","bids":[],"asks":[{"price":67727.82,"qty":0.00000000},{"price":67734.38,"qty":0.00360192}],"checksum":2710407934,"timestamp":"2024-06-01T18:06:32.064754Z"}]}
{"channel":"book","type":"update","data":[{"symbol":"BTC/USDC","bids":[],"asks":[{"price":67727.82,"qty":0.05021901}],"checksum":2303360983,"timestamp":"2024-06-01T18:06:32.208829Z"}]}
{"channel":"book","type":"update","data":[{"symbol":"BTC/USDC","bids":[],"asks":[{"price":67727.82,"qty":0.00000000},{"price":67734.38,"qty":0.00360192}],"checksum":2710407934,"timestamp":"2024-06-01T18:06:32.218017Z"}]}
{"channel":"book","type":"update","data":[{"symbol":"BTC/USDC","bids":[],"asks":[{"price":67727.82,"qty":0.04847577}],"checksum":2369424963,"timestamp":"2024-06-01T18:06:32.359292Z"}]}
{"channel":"book","type":"update","data":[{"symbol":"BTC/USDC","bids":[],"asks":[{"price":67727.82,"qty":0.00000000},{"price":67734.38,"qty":0.00360192}],"checksum":2710407934,"timestamp":"2024-06-01T18:06:32.365543Z"}]}
{"channel":"book","type":"update","data":[{"symbol":"BTC/USDC","bids":[],"asks":[{"price":67727.82,"qty":0.04647154}],"checksum":835982129,"timestamp":"2024-06-01T18:06:32.509781Z"}]}
{"channel":"book","type":"update","data":[{"symbol":"BTC/USDC","bids":[],"asks":[{"price":67727.82,"qty":0.00000000},{"price":67734.38,"qty":0.00360192}],"checksum":2710407934,"timestamp":"2024-06-01T18:06:32.516237Z"}]}
{"channel":"book","type":"update","data":[{"symbol":"BTC/USDC","bids":[],"asks":[{"price":67729.73,"qty":0.00000000},{"price":67734.39,"qty":0.98345353}],"checksum":3488365493,"timestamp":"2024-06-01T18:06:32.650433Z"}]}
{"channel":"book","type":"update","data":[{"symbol":"BTC/USDC","bids":[],"asks":[{"price":67734.39,"qty":0.17000000}],"checksum":2923690910,"timestamp":"2024-06-01T18:06:32.650566Z"}]}
{"channel":"book","type":"update","data":[{"symbol":"BTC/USDC","bids":[],"asks":[{"price":67734.37,"qty":1.17501425}],"checksum":3518471407,"timestamp":"2024-06-01T18:06:32.653048Z"}]}
{"channel":"book","type":"update","data":[{"symbol":"BTC/USDC","bids":[],"asks":[{"price":67727.81,"qty":0.09870771}],"checksum":3786074967,"timestamp":"2024-06-01T18:06:32.653132Z"}]}
{"channel":"book","type":"update","data":[{"symbol":"BTC/USDC","bids":[],"asks":[{"price":67727.82,"qty":0.04778888}],"checksum":959262349,"timestamp":"2024-06-01T18:06:32.659788Z"}]}
{"channel":"book","type":"update","data":[{"symbol":"BTC/USDC","bids":[],"asks":[{"price":67727.82,"qty":0.00000000},{"price":67734.37,"qty":1.17501425}],"checksum":3786074967,"timestamp":"2024-06-01T18:06:32.665479Z"}]}
{"channel":"book","type":"update","data":[{"symbol":"BTC/USDC","bids":[],"asks":[{"price":67727.82,"qty":0.05482329}],"checksum":979291797,"timestamp":"2024-06-01T18:06:32.811328Z"}]}
{"channel":"book","type":"update","data":[{"symbol":"BTC/USDC","bids":[],"asks":[{"price":67727.82,"qty":0.00000000},{"price":67734.37,"qty":1.17501425}],"checksum":3786074967,"timestamp":"2024-06-01T18:06:32.818146Z"}]}
{"channel":"book","type":"update","data":[{"symbol":"BTC/USDC","bids":[],"asks":[{"price":67727.74,"qty":0.05124648}],"checksum":2814728607,"timestamp":"2024-06-01T18:06:32.960735Z"}]}
{"channel":"book","type":"update","data":[{"symbol":"BTC/USDC","bids":[],"asks":[{"price":67727.74,"qty":0.00000000},{"price":67734.37,"qty":1.17501425}],"checksum":3786074967,"timestamp":"2024-06-01T18:06:32.966469Z"}]}
{"channel":"book","type":"update","data":[{"symbol":"BTC/USDC","bids":[{"price":67672.13,"qty":0.00000000},{"price":67671.91,"qty":0.01820000}],"asks":[],"checksum":143438573,"timestamp":"2024-06-01T18:06:33.071082Z"}]}
{"channel":"book","type":"update","data":[{"symbol":"BTC/USDC","bids":[],"asks":[{"price":67727.82,"qty":0.04548338}],"checksum":1322109058,"timestamp":"2024-06-01T18:06:33.111181Z"}]}
{"channel":"book","type":"update","data":[{"symbol":"BTC/USDC","bids":[],"asks":[{"price":67727.82,"qty":0.00000000},{"price":67734.37,"qty":1.17501425}],"checksum":143438573,"timestamp":"2024-06-01T18:06:33.116859Z"}]}
{"channel":"book","type":"update","data":[{"symbol":"BTC/USDC","bids":[],"asks":[{"price":67729.72,"qty":0.00000000},{"price":67734.38,"qty":0.00360192}],"checksum":2071648031,"timestamp":"2024-06-01T18:06:33.228597Z"}]}
{"channel":"book","type":"update","data":[{"symbol":"BTC/USDC","bids":[],"asks":[{"price":67734.38,"qty":0.00029161}],"checksum":773812496,"timestamp":"2024-06-01T18:06:33.228726Z"}]}
{"channel":"book","type":"update","data":[{"symbol":"BTC/USDC","bids":[],"asks":[{"price":67727.80,"qty":0.00507211}],"checksum":633947340,"timestamp":"2024-06-01T18:06:33.233317Z"}]}
{"channel":"book","type":"update","data":[{"symbol":"BTC/USDC","bids":[],"asks":[{"price":67726.74,"qty":0.04710810}],"checksum":1659653972,"timestamp":"2024-06-01T18:06:33.260766Z"}]}
{"channel":"book","type":"update","data":[{"symbol":"BTC/USDC","bids":[],"asks":[{"price":67726.74,"qty":0.00000000},{"price":67734.37,"qty":1.17501425}],"checksum":633947340,"timestamp":"2024-06-01T18:06:33.267426Z"}]}
{"channel":"book","type":"update","data":[{"symbol":"BTC/USDC","bids":[],"asks":[{"price":67726.74,"qty":0.05160037}],"checksum":1012666235,"timestamp":"2024-06-01T18:06:33.411063Z"}]}
{"channel":"book","type":"update","data":[{"symbol":"BTC/USDC","bids":[],"asks":[{"price":67726.74,"qty":0.00000000},{"price":67734.37,"qty":1.17501425}],"checksum":633947340,"timestamp":"2024-06-01T18:06:33.417730Z"}]}
{"channel":"book","type":"update","data":[{"symbol":"BTC/USDC","bids":[],"asks":[{"price":67729.75,"qty":0.17000000}],"checksum":2324699968,"timestamp":"2024-06-01T18:06:33.459315Z"}]}
{"channel":"book","type":"update","data":[{"symbol":"BTC/USDC","bids":[],"asks":[{"price":67727.63,"qty":0.04921341}],"checksum":867799251,"timestamp":"2024-06-01T18:06:33.562062Z"}]}
{"channel":"book","type":"update","data":[{"symbol":"BTC/USDC","bids":[],"asks":[{"price":67727.63,"qty":0.00000000},{"price":67730.18,"qty":0.02233000}],"checksum":2324699968,"timestamp":"2024-06-01T18:06:33.569033Z"}]}
{"channel":"book","type":"update","data":[{"symbol":"BTC/USDC","bids":[{"price":67680.74,"qty":0.02565471}],"asks":[],"checksum":2294237001,"timestamp":"2024-06-01T18:06:33.648839Z"}]}
{"channel":"book","type":"update","data":[{"symbol":"BTC/USDC","bids":[{"price":67680.73,"qty":0.00028606}],"asks":[],"checksum":3631921207,"timestamp":"2024-06-01T18:06:33.699093Z"}]}
{"channel":"book","type":"update","data":[{"symbol":"BTC/USDC","bids":[{"price":67693.93,"qty":0.00000000},{"price":67671.91,"qty":0.01820000}],"asks":[],"checksum":1199300660,"timestamp":"2024-06-01T18:06:33.699184Z"}]}
{"channel":"book","type":"update","data":[{"symbol":"BTC/USDC","bids":[{"price":67693.89,"qty":0.00000000},{"price":67669.24,"qty":0.07388880}],"asks":[],"checksum":163826104,"timestamp":"2024-06-01T18:06:33.699229Z"}]}
{"channel":"book","type":"update","data":[{"symbol":"BTC/USDC","bids":[{"price":67687.46,"qty":0.02953857}],"asks":[],"checksum":4167051532,"timestamp":"2024-06-01T18:06:33.700333Z"}]}
{"channel":"book","type":"update","data":[{"symbol":"BTC/USDC","bids":[{"price":67680.73,"qty":0.00000000},{"price":67669.25,"qty":1.38395690}],"asks":[],"checksum":994436298,"timestamp":"2024-06-01T18:06:33.703948Z"}]}
{"channel":"book","type":"update","data":[{"symbol":"BTC/USDC","bids":[],"asks":[{"price":67727.77,"qty":0.04688864}],"checksum":4103452634,"timestamp":"2024-06-01T18:06:33.710420Z"}]}
{"channel":"book","type":"update","data":[{"symbol":"BTC/USDC","bids":[],"asks":[{"price":67727.77,"qty":0.00000000},{"price":67730.18,"qty":0.02233000}],"checksum":994436298,"timestamp":"2024-06-01T18:06:33.717174Z"}]}
{"channel":"book","type":"update","data":[{"symbol":"BTC/USDC","bids":[],"asks":[{"price":67727.78,"qty":0.05293579}],"checksum":2609103799,"timestamp":"2024-06-01T18:06:33.860571Z"}]}
{"channel":"book","type":"update","data":[{"symbol":"BTC/USDC","bids":[],"asks":[{"price":67727.78,"qty":0.00000000},{"price":67730.18,"qty":0.02233000}],"checksum":994436298,"timestamp":"2024-06-01T18:06:33.867345Z"}]}
{"channel":"book","type":"update","data":[{"symbol":"BTC/USDC","bids":[{"price":67669.26,"qty":0.00030484}],"asks":[],"checksum":3104245942,"timestamp":"2024-06-01T18:06:33.955423Z"}]}
{"channel":"book","type":"update","data":[{"symbol":"BTC/USDC","bids":[{"price":67674.87,"qty":0.02953857}],"asks":[],"checksum":3503487934,"timestamp":"2024-06-01T18:06:33.997339Z"}]}
{"channel":"book","type":"update","data":[{"symbol":"BTC/USDC","bids":[],"asks":[{"price":67727.79,"qty":0.05447230}],"checksum":3050125285,"timestamp":"2024-06-01T18:06:34.010564Z"}]}
{"channel":"book","type":"update","data":[{"symbol":"BTC/USDC","bids":[],"asks":[{"price":67727.79,"qty":0.00000000},{"price":67730.18,"qty":0.02233000}],"checksum":3503487934,"timestamp":"2024-06-01T18:06:34.017365Z"}]}
{"channel":"book","type":"update","data":[{"symbol":"BTC/USDC","bids":[],"asks":[{"price":67727.80,"qty":0.05030264}],"checksum":3218798328,"timestamp":"2024-06-01T18:06:34.161356Z"}]}
{"channel":"book","type":"update","data":[{"symbol":"BTC/USDC","bids":[],"asks":[{"price":67727.80,"qty":0.00507211}],"checksum":3503487934,"timestamp":"2024-06-01T18:06:34.168241Z"}]}
{"channel":"book","type":"update","data":[{"symbol":"BTC/USDC","bids":[{"price":67674.87,"qty":0.00000000},{"price":67669.26,"qty":0.00030484}],"asks":[],"checksum":3104245942,"timestamp":"2024-06-01T18:06:34.278574Z"}]}
{"channel":"book","type":"update","data":[{"symbol":"BTC/USDC","bids":[],"asks":[{"price":67727.80,"qty":0.05264135}],"checksum":2032439705,"timestamp":"2024-06-01T18:06:34.310463Z"}]}
{"channel":"book","type":"update","data":[{"symbol":"BTC/USDC","bids":[],"asks":[{"price":67727.80,"qty":0.00507211}],"checksum":3104245942,"timestamp":"2024-06-01T18:06:34.316171Z"}]}
{"channel":"book","type":"update","data":[{"symbol":"BTC/USDC","bids":[{"price":67687.45,"qty":0.00000000},{"price":67669.25,"qty":1.38395690}],"asks":[],"checksum":1761004761,"timestamp":"2024-06-01T18:06:34.328327Z"}]}
{"channel":"book","type":"update","data":[{"symbol":"BTC/USDC","bids":[],"asks":[{"price":67704.08,"qty":0.14772692}],"checksum":1847038384,"timestamp":"2024-06-01T18:06:34.331533Z"}]}
{"channel":"book","type":"update","data":[{"symbol":"BTC/USDC","bids":[],"asks":[{"price":67711.53,"qty":0.00000000},{"price":67730.18,"qty":0.02233000}],"checksum":662618898,"timestamp":"2024-06-01T18:06:34.331845Z"}]}
{"channel":"book","type":"update","data":[{"symbol":"BTC/USDC","bids":[],"asks":[{"price":67724.00,"qty":0.07382907}],"checksum":2033459349,"timestamp":"2024-06-01T18:06:34.333784Z"}]}
{"channel":"book","type":"update","data":[{"symbol":"BTC/USDC","bids":[{"price":67680.93,"qty":0.03693802}],"asks":[],"checksum":4059662202,"timestamp":"2024-06-01T18:06:34.333937Z"}]}
{"channel":"book","type":"update","data":[{"symbol":"BTC/USDC","bids":[],"asks":[{"price":67700.70,"qty":0.01820000}],"checksum":3438917952,"timestamp":"2024-06-01T18:06:34.336752Z"}]}
{"channel":"book","type":"update","data":[{"symbol":"BTC/USDC","bids":[],"asks":[{"price":67711.87,"qty":0.00000000},{"price":67729.76,"qty":0.01820000}],"checksum":3170511243,"timestamp":"2024-06-01T18:06:34.342924Z"}]}
{"channel":"book","type":"update","data":[{"symbol":"BTC/USDC","bids":[],"asks":[{"price":67705.28,"qty":0.03692474}],"checksum":3330725042,"timestamp":"2024-06-01T18:06:34.347304Z"}]}
{"channel":"book","type":"update","data":[{"symbol":"BTC/USDC","bids":[{"price":67683.55,"qty":0.00000000},{"price":67669.25,"qty":1.38395690}],"asks":[],"checksum":2750724688,"timestamp":"2024-06-01T18:06:34.373120Z"}]}
{"channel":"book","type":"update","data":[{"symbol":"BTC/USDC","bids":[{"price":67675.25,"qty":0.04544522}],"asks":[],"checksum":2112002506,"timestamp":"2024-06-01T18:06:34.374041Z"}]}
{"channel":"book","type":"update","data":[{"symbol":"BTC/USDC","bids":[{"price":67675.25,"qty":0.00000000},{"price":67669.25,"qty":1.38395690}],"asks":[],"checksum":2750724688,"timestamp":"2024-06-01T18:06:34.379867Z"}]}
{"channel":"book","type":"update","data":[{"symbol":"BTC/USDC","bids":[{"price":67680.72,"qty":0.00000000},{"price":67669.24,"qty":0.07388880}],"asks":[],"checksum":3018290195,"timestamp":"2024-06-01T18:06:34.390870Z"}]}
{"channel":"book","type":"update","data":[{"symbol":"BTC/USDC","bids":[],"asks":[{"price":67711.64,"qty":0.00000000},{"price":67729.76,"qty":0.01820000}],"checksum":947991033,"timestamp":"2024-06-01T18:06:34.391511Z"}]}
{"channel":"book","type":"update","data":[{"symbol":"BTC/USDC","bids":[{"price":67699.98,"qty":0.00000000},{"price":67668.68,"qty":0.02180000}],"asks":[],"checksum":2489875269,"timestamp":"2024-06-01T18:06:34.417993Z"}]}
{"channel":"book","type":"update","data":[{"symbol":"BTC/USDC","bids":[{"price":67686.81,"qty":0.00000000},{"price":67667.72,"qty":0.02309162}],"asks":[],"checksum":1251619644,"timestamp":"2024-06-01T18:06:34.452502Z"}]}
{"channel":"book","type":"update","data":[{"symbol":"BTC/USDC","bids":[{"price":67692.83,"qty":0.01821288}],"asks":[],"checksum":3838590750,"timestamp":"2024-06-01T18:06:34.454512Z"}]}
{"channel":"book","type":"update","data":[{"symbol":"BTC/USDC","bids":[{"price":67682.03,"qty":0.08707863}],"asks":[],"checksum":2874362144,"timestamp":"2024-06-01T18:06:34.460017Z"}]}
{"channel":"book","type":"update","data":[{"symbol":"BTC/USDC","bids":[],"asks":[{"price":67721.65,"qty":0.04865924}],"checksum":4060747773,"timestamp":"2024-06-01T18:06:34.461153Z"}]}
{"channel":"book","type":"update","data":[{"symbol":"BTC/USDC","bids":[],"asks":[{"price":67721.65,"qty":0.00000000},{"price":67729.76,"qty":0.01820000}],"checksum":2874362144,"timestamp":"2024-06-01T18:06:34.467174Z"}]}
{"channel":"book","type":"update","data":[{"symbol":"BTC/USDC","bids":[{"price":67674.36,"qty":0.04520597}],"asks":[],"checksum":1812245931,"timestamp":"2024-06-01T18:06:34.523371Z"}]}
{"channel":"book","type":"update","data":[{"symbol":"BTC/USDC","bids":[{"price":67679.29,"qty":0.01820000}],"asks":[],"checksum":898877700,"timestamp":"2024-06-01T18:06:34.527434Z"}]}
{"channel":"book","type":"update","data":[{"symbol":"BTC/USDC","bids":[{"price":67674.36,"qty":0.00000000},{"price":67669.24,"qty":0.07388880}],"asks":[],"checksum":2512247114,"timestamp":"2024-06-01T18:06:34.531511Z"}]}
{"channel":"book","type":"update","data":[{"symbol":"BTC/USDC","bids":[{"price":67670.89,"qty":0.02953857}],"asks":[],"checksum":3183153321,"timestamp":"2024-06-01T18:06:34.532409Z"}]}
{"channel":"book","type":"update","data":[{"symbol":"BTC/USDC","bids":[{"price":67670.89,"qty":0.00000000},{"price":67669.24,"qty":0.07388880}],"asks":[],"checksum":2512247114,"timestamp":"2024-06-01T18:06:34.781708Z"}]}
{"channel":"book","type":"update","data":[{"symbol":"BTC/USDC","bids":[],"asks":[{"price":67727.81,"qty":0.00000000},{"price":67730.18,"qty":0.02233000}],"checksum":1356087010,"timestamp":"2024-06-01T18:06:35.470561Z"}]}
{"channel":"book","type":"update","data":[{"symbol":"BTC/USDC","bids":[],"asks":[{"price":67729.74,"qty":1.24413270}],"checksum":4009114920,"timestamp":"2024-06-01T18:06:35.474344Z"}]}
{"channel":"book","type":"update","data":[{"symbol":"BTC/USDC","bids":[],"asks":[{"price":67723.99,"qty":0.09870980}],"checksum":689723047,"timestamp":"2024-06-01T18:06:35.474368Z"}]}
{"channel":"book","type":"update","data":[{"symbol":"BTC/USDC","bids":[],"asks":[{"price":67729.74,"qty":1.24442430}],"checksum":3291218729,"timestamp":"2024-06-01T18:06:35.478817Z"}]}
{"channel":"book","type":"update","data":[{"symbol":"BTC/USDC","bids":[],"asks":[{"price":67727.80,"qty":0.00000000},{"price":67729.76,"qty":0.01820000}],"checksum":2108105882,"timestamp":"2024-06-01T18:06:35.565785Z"}]}
{"channel":"book","type":"update","data":[{"symbol":"BTC/USDC","bids":[],"asks":[{"price":67723.99,"qty":0.10498034}],"checksum":861362834,"timestamp":"2024-06-01T18:06:35.571271Z"}]}
{"channel":"book","type":"update","data":[{"symbol":"BTC/USDC","bids":[],"asks":[{"price":67727.80,"qty":0.00117752}],"checksum":832692098,"timestamp":"2024-06-01T18:06:35.571378Z"}]}
{"channel":"book","type":"update","data":[{"symbol":"BTC/USDC","bids":[{"price":67680.74,"qty":0.00000000},{"price":67668.68,"qty":0.02180000}],"asks":[],"checksum":1550541439,"timestamp":"2024-06-01T18:06:36.379196Z"}]}
{"channel":"book","type":"update","data":[{"symbol":"BTC/USDC","bids":[{"price":67669.26,"qty":0.02913148}],"asks":[],"checksum":1385154748,"timestamp":"2024-06-01T18:06:36.380110Z"}]}
{"channel":"book","type":"update","data":[{"symbol":"BTC/USDC","bids":[{"price":67669.25,"qty":0.00000000},{"price":67667.72,"qty":0.02309162}],"asks":[],"checksum":3043278866,"timestamp":"2024-06-01T18:06:37.321543Z"}]}
{"channel":"book","type":"update","data":[{"symbol":"BTC/USDC","bids":[{"price":67687.46,"qty":0.00000000},{"price":67665.86,"qty":0.04452580}],"asks":[],"checksum":1802692914,"timestamp":"2024-06-01T18:06:37.321620Z"}]}
{"channel":"book","type":"update","data":[{"symbol":"BTC/USDC","bids":[{"price":67669.27,"qty":0.57710978}],"asks":[],"checksum":4223337305,"timestamp":"2024-06-01T18:06:37.322277Z"}]}
{"channel":"book","type":"update","data":[{"symbol":"BTC/USDC","bids":[{"price":67682.04,"qty":0.05836006}],"asks":[],"checksum":96392261,"timestamp":"2024-06-01T18:06:37.322343Z"}]}
{"channel":"book","type":"update","data":[{"symbol":"BTC/USDC","bids":[{"price":67669.26,"qty":0.02882664}],"asks":[],"checksum":590703271,"timestamp":"2024-06-01T18:06:37.325803Z"}]}
{"channel":"book","type":"update","data":[{"symbol":"BTC/USDC","bids":[],"asks":[{"price":67729.75,"qty":0.00000000},{"price":67729.76,"qty":0.01820000},{"price":67729.73,"qty":0.17000000}],"checksum":4260787996,"timestamp":"2024-06-01T18:06:37.459943Z"}]}
{"channel":"book","type":"update","data":[{"symbol":"BTC/USDC","bids":[],"asks":[{"price":67727.79,"qty":0.59074945}],"checksum":2797360224,"timestamp":"2024-06-01T18:06:37.592876Z"}]}
{"channel":"book","type":"update","data":[{"symbol":"BTC/USDC","bids":[],"asks":[{"price":67727.78,"qty":0.00029398}],"checksum":2403821670,"timestamp":"2024-06-01T18:06:37.596821Z"}]}
{"channel":"book","type":"update","data":[{"symbol":"BTC/USDC","bids":[{"price":67669.28,"qty":0.00029915}],"asks":[],"checksum":2907489922,"timestamp":"2024-06-01T18:06:37.915103Z"}]}
{"channel":"book","type":"update","data":[{"symbol":"BTC/USDC","bids":[],"asks":[{"price":67723.99,"qty":0.09870980}],"checksum":3381230642,"timestamp":"2024-06-01T18:06:37.942809Z"}]}
{"channel":"book","type":"update","data":[{"symbol":"BTC/USDC","bids":[],"asks":[{"price":67727.80,"qty":0.00000000},{"price":67729.73,"qty":0.17000000}],"checksum":1659488909,"timestamp":"2024-06-01T18:06:37.943487Z"}]}
{"channel":"book","type":"update","data":[{"symbol":"BTC/USDC","bids":[],"asks":[{"price":67723.98,"qty":0.00531203}],"checksum":3599520755,"timestamp":"2024-06-01T18:06:37.947566Z"}]}
{"channel":"book","type":"update","data":[{"symbol":"BTC/USDC","bids":[],"asks":[{"price":67723.99,"qty":0.00000000},{"price":67729.73,"qty":0.17000000}],"checksum":911890831,"timestamp":"2024-06-01T18:06:38.233894Z"}]}
{"channel":"book","type":"update","data":[{"symbol":"BTC/USDC","bids":[],"asks":[{"price":67727.78,"qty":0.71050483}],"checksum":2485680071,"timestamp":"2024-06-01T18:06:38.236310Z"}]}
{"channel":"book","type":"update","data":[{"symbol":"BTC/USDC","bids":[],"asks":[{"price":67723.98,"qty":0.63431859}],"checksum":2111377769,"timestamp":"2024-06-01T18:06:38.236350Z"}]}
{"channel":"book","type":"update","data":[{"symbol":"BTC/USDC","bids":[],"asks":[{"price":67727.78,"qty":0.71021085}],"checksum":3422664066,"timestamp":"2024-06-01T18:06:38.240004Z"}]}
{"channel":"book","type":"update","data":[{"symbol":"BTC/USDC","bids":[],"asks":[{"price":67723.97,"qty":0.00029398}],"checksum":753603266,"timestamp":"2024-06-01T18:06:38.240864Z"}]}
{"channel":"book","type":"update","data":[{"symbol":"BTC/USDC","bids":[{"price":67669.26,"qty":0.00000000},{"price":67668.68,"qty":0.02180000}],"asks":[],"checksum":3183098688,"timestamp":"2024-06-01T18:06:39.046554Z"}]}
{"channel":"book","type":"update","data":[{"symbol":"BTC/USDC","bids":[{"price":67682.05,"qty":0.00029541}],"asks":[],"checksum":1238331552,"timestamp":"2024-06-01T18:06:39.087595Z"}]}
{"channel":"book","type":"update","data":[{"symbol":"BTC/USDC","bids":[{"price":67669.28,"qty":0.02076817}],"asks":[],"checksum":3182654160,"timestamp":"2024-06-01T18:06:39.087792Z"}]}
{"channel":"book","type":"update","data":[{"symbol":"BTC/USDC","bids":[],"asks":[{"price":67704.08,"qty":0.00000000},{"price":67729.73,"qty":0.17000000}],"checksum":3314398013,"timestamp":"2024-06-01T18:06:39.273901Z"}]}
{"channel":"book","type":"update","data":[{"symbol":"BTC/USDC","bids":[{"price":67679.29,"qty":0.00000000},{"price":67668.68,"qty":0.02180000}],"asks":[],"checksum":2102106168,"timestamp":"2024-06-01T18:06:39.721749Z"}]}
{"channel":"book","type":"update","data":[{"symbol":"BTC/USDC","bids":[],"asks":[{"price":67725.36,"qty":0.00400000}],"checksum":3305041500,"timestamp":"2024-06-01T18:06:39.772491Z"}]}
{"channel":"book","type":"update","data":[{"symbol":"BTC/USDC","bids":[],"asks":[{"price":67723.98,"qty":0.62900656}],"checksum":1232593450,"timestamp":"2024-06-01T18:06:40.356194Z"}]}
{"channel":"book","type":"update","data":[{"symbol":"BTC/USDC","bids":[],"asks":[{"price":67723.97,"qty":0.00656452}],"checksum":1315862112,"timestamp":"2024-06-01T18:06:40.360771Z"}]}
{"channel":"book","type":"update","data":[{"symbol":"BTC/USDC","bids":[{"price":67682.04,"qty":0.00000000},{"price":67667.72,"qty":0.02309162}],"asks":[],"checksum":3663378769,"timestamp":"2024-06-01T18:06:40.897839Z"}]}
{"channel":"book","type":"update","data":[{"symbol":"BTC/USDC","bids":[{"price":67669.27,"qty":0.00000000},{"price":67665.86,"qty":0.04452580}],"asks":[],"checksum":529307784,"timestamp":"2024-06-01T18:06:40.897933Z"}]}
{"channel":"book","type":"update","data":[{"symbol":"BTC/USDC","bids":[{"price":67682.06,"qty":0.02954064}],"asks":[],"checksum":1276110997,"timestamp":"2024-06-01T18:06:40.898325Z"}]}
{"channel":"book","type":"update","data":[{"symbol":"BTC/USDC","bids":[{"price":67669.29,"qty":0.57710978}],"asks":[],"checksum":1896998203,"timestamp":"2024-06-01T18:06:40.898418Z"}]}
{"channel":"book","type":"update","data":[{"symbol":"BTC/USDC","bids":[{"price":67669.28,"qty":0.02046902}],"asks":[],"checksum":753460226,"timestamp":"2024-06-01T18:06:40.902761Z"}]}
{"channel":"book","type":"update","data":[{"symbol":"BTC/USDC","bids":[],"asks":[{"price":67727.78,"qty":0.00000000},{"price":67729.73,"qty":0.17000000}],"checksum":117210517,"timestamp":"2024-06-01T18:06:41.057516Z"}]}
{"channel":"book","type":"update","data":[{"symbol":"BTC/USDC","bids":[],"asks":[{"price":67723.98,"qty":0.00000000},{"price":67729.76,"qty":0.01820000}],"checksum":3619317937,"timestamp":"2024-06-01T18:06:41.057532Z"}]}
{"channel":"book","type":"update","data":[{"symbol":"BTC/USDC","bids":[],"asks":[{"price":67727.78,"qty":0.64037749}],"checksum":4174339761,"timestamp":"2024-06-01T18:06:41.059847Z"}]}
{"channel":"book","type":"update","data":[{"symbol":"BTC/USDC","bids":[],"asks":[{"price":67723.96,"qty":0.79040123}],"checksum":1887465957,"timestamp":"2024-06-01T18:06:41.059868Z"}]}
{"channel":"book","type":"update","data":[{"symbol":"BTC/USDC","bids":[],"asks":[{"price":67727.78,"qty":0.64066438}],"checksum":1493176995,"timestamp":"2024-06-01T18:06:41.062160Z"}]}
{"channel":"book","type":"update","data":[{"symbol":"BTC/USDC","bids":[],"asks":[{"price":67723.97,"qty":0.00627054}],"checksum":1892984271,"timestamp":"2024-06-01T18:06:41.062287Z"}]}
{"channel":"book","type":"update","data":[{"symbol":"BTC/USDC","bids":[],"asks":[{"price":67727.78,"qty":0.64037749}],"checksum":1498728073,"timestamp":"2024-06-01T18:06:41.156882Z"}]}
{"channel":"book","type":"update","data":[{"symbol":"BTC/USDC","bids":[],"asks":[{"price":67723.96,"qty":0.79070917}],"checksum":3259239715,"timestamp":"2024-06-01T18:06:41.157013Z"}]}
{"channel":"book","type":"update","data":[{"symbol":"BTC/USDC","bids":[{"price":67669.29,"qty":0.57741150}],"asks":[],"checksum":3084593784,"timestamp":"2024-06-01T18:06:41.167325Z"}]}
{"channel":"book","type":"update","data":[{"symbol":"BTC/USDC","bids":[],"asks":[{"price":67727.77,"qty":0.17000000}],"checksum":3850007759,"timestamp":"2024-06-01T18:06:41.460515Z"}]}
{"channel":"book","type":"update","data":[{"symbol":"BTC/USDC","bids":[],"asks":[{"price":67700.70,"qty":0.00000000},{"price":67727.79,"qty":0.59074945}],"checksum":467087769,"timestamp":"2024-06-01T18:06:41.651766Z"}]}
{"channel":"book","type":"update","data":[{"symbol":"BTC/USDC","bids":[],"asks":[{"price":67704.76,"qty":0.01820000}],"checksum":1558769097,"timestamp":"2024-06-01T18:06:41.655936Z"}]}
{"channel":"book","type":"update","data":[{"symbol":"BTC/USDC","bids":[],"asks":[{"price":67703.88,"qty":0.01820000}],"checksum":3856271501,"timestamp":"2024-06-01T18:06:41.659487Z"}]}
{"channel":"book","type":"update","data":[{"symbol":"BTC/USDC","bids":[],"asks":[{"price":67701.94,"qty":0.01820000}],"checksum":1381193174,"timestamp":"2024-06-01T18:06:41.659765Z"}]}
{"channel":"book","type":"update","data":[{"symbol":"BTC/USDC","bids":[],"asks":[{"price":67704.76,"qty":0.00000000},{"price":67727.78,"qty":0.64037749}],"checksum":3598716073,"timestamp":"2024-06-01T18:06:41.659786Z"}]}
{"channel":"book","type":"update","data":[{"symbol":"BTC/USDC","bids":[],"asks":[{"price":67703.88,"qty":0.00000000},{"price":67727.79,"qty":0.59074945}],"checksum":370893453,"timestamp":"2024-06-01T18:06:41.662949Z"}]}
{"channel":"book","type":"update","data":[{"symbol":"BTC/USDC","bids":[{"price":67682.05,"qty":0.00000000},{"price":67667.72,"qty":0.02309162}],"asks":[],"checksum":214851625,"timestamp":"2024-06-01T18:06:41.743509Z"}]}
{"channel":"book","type":"update","data":[{"symbol":"BTC/USDC","bids":[{"price":67669.28,"qty":0.00000000},{"price":67665.86,"qty":0.04452580}],"asks":[],"checksum":1299371670,"timestamp":"2024-06-01T18:06:41.743876Z"}]}
{"channel":"book","type":"update","data":[{"symbol":"BTC/USDC","bids":[{"price":67669.30,"qty":0.02104541}],"asks":[],"checksum":2210440103,"timestamp":"2024-06-01T18:06:41.745889Z"}]}
{"channel":"book","type":"update","data":[{"symbol":"BTC/USDC","bids":[],"asks":[{"price":67723.97,"qty":0.00000000},{"price":67729.76,"qty":0.01820000}],"checksum":1469030524,"timestamp":"2024-06-01T18:06:42.776422Z"}]}
{"channel":"book","type":"update","data":[{"symbol":"BTC/USDC","bids":[],"asks":[{"price":67723.95,"qty":0.00666888}],"checksum":4179770628,"timestamp":"2024-06-01T18:06:42.778847Z"}]}
{"channel":"book","type":"update","data":[{"symbol":"BTC/USDC","bids":[],"asks":[{"price":67701.94,"qty":0.03640000}],"checksum":3439114640,"timestamp":"2024-06-01T18:06:42.920185Z"}]}
{"channel":"book","type":"update","data":[{"symbol":"BTC/USDC","bids":[],"asks":[{"price":67701.94,"qty":0.01820000}],"checksum":4179770628,"timestamp":"2024-06-01T18:06:43.305315Z"}]}
{"channel":"book","type":"update","data":[{"symbol":"BTC/USDC","bids":[],"asks":[{"price":67701.94,"qty":0.03640000}],"checksum":3439114640,"timestamp":"2024-06-01T18:06:43.331498Z"}]}
{"channel":"book","type":"update","data":[{"symbol":"BTC/USDC","bids":[],"asks":[{"price":67727.78,"qty":0.00000000},{"price":67729.76,"qty":0.01820000}],"checksum":4180006281,"timestamp":"2024-06-01T18:06:43.820017Z"}]}
{"channel":"book","type":"update","data":[{"symbol":"BTC/USDC","bids":[],"asks":[{"price":67723.96,"qty":0.00030794}],"checksum":1964959017,"timestamp":"2024-06-01T18:06:43.820046Z"}]}
{"channel":"book","type":"update","data":[{"symbol":"BTC/USDC","bids":[],"asks":[{"price":67723.94,"qty":0.79040124}],"checksum":525927943,"timestamp":"2024-06-01T18:06:43.824697Z"}]}
{"channel":"book","type":"update","data":[{"symbol":"BTC/USDC","bids":[],"asks":[{"price":67727.76,"qty":0.75473061}],"checksum":3448280204,"timestamp":"2024-06-01T18:06:43.824745Z"}]}
{"channel":"book","type":"update","data":[{"symbol":"BTC/USDC","bids":[],"asks":[{"price":67723.96,"qty":0.00000000},{"price":67727.78,"qty":0.00030918}],"checksum":4039855185,"timestamp":"2024-06-01T18:06:43.825143Z"}]}
{"channel":"book","type":"update","data":[{"symbol":"BTC/USDC","bids":[],"asks":[{"price":67723.94,"qty":0.79069780}],"checksum":3381030233,"timestamp":"2024-06-01T18:06:44.208717Z"}]}
{"channel":"book","type":"update","data":[{"symbol":"BTC/USDC","bids":[],"asks":[{"price":67727.78,"qty":0.00000000},{"price":67727.79,"qty":0.59074945}],"checksum":294309522,"timestamp":"2024-06-01T18:06:44.210286Z"}]}
{"channel":"book","type":"update","data":[{"symbol":"BTC/USDC","bids":[],"asks":[{"price":67701.94,"qty":0.01820000}],"checksum":609503750,"timestamp":"2024-06-01T18:06:44.245876Z"}]}
{"channel":"book","type":"update","data":[{"symbol":"BTC/USDC","bids":[],"asks":[{"price":67701.94,"qty":0.03640000}],"checksum":294309522,"timestamp":"2024-06-01T18:06:44.320569Z"}]}
{"channel":"book","type":"update","data":[{"symbol":"BTC/USDC","bids":[],"asks":[{"price":67723.94,"qty":0.79040124}],"checksum":2607527901,"timestamp":"2024-06-01T18:06:44.377831Z"}]}
{"channel":"book","type":"update","data":[{"symbol":"BTC/USDC","bids":[{"price":67669.29,"qty":0.57710978}],"asks":[],"checksum":4009005190,"timestamp":"2024-06-01T18:06:44.377897Z"}]}
{"channel":"book","type":"update","data":[{"symbol":"BTC/USDC","bids":[{"price":67669.30,"qty":0.00000000},{"price":67665.86,"qty":0.04452580}],"asks":[],"checksum":1658428653,"timestamp":"2024-06-01T18:06:44.514465Z"}]}
{"channel":"book","type":"update","data":[{"symbol":"BTC/USDC","bids":[{"price":67669.30,"qty":0.02219818}],"asks":[],"checksum":1896639450,"timestamp":"2024-06-01T18:06:44.515175Z"}]}
{"channel":"book","type":"update","data":[{"symbol":"BTC/USDC","bids":[],"asks":[{"price":67701.94,"qty":0.01820000}],"checksum":1154674510,"timestamp":"2024-06-01T18:06:44.518745Z"}]}
{"channel":"book","type":"update","data":[{"symbol":"BTC/USDC","bids":[{"price":67682.06,"qty":0.00000000},{"price":67665.86,"qty":0.04452580}],"asks":[],"checksum":541981979,"timestamp":"2024-06-01T18:06:44.528348Z"}]}
{"channel":"book","type":"update","data":[{"symbol":"BTC/USDC","bids":[{"price":67669.29,"qty":0.00000000},{"price":67665.13,"qty":0.01820000}],"asks":[],"checksum":146138242,"timestamp":"2024-06-01T18:06:44.528665Z"}]}
{"channel":"book","type":"update","data":[{"symbol":"BTC/USDC","bids":[{"price":67682.04,"qty":0.02954065}],"asks":[],"checksum":3902712043,"timestamp":"2024-06-01T18:06:44.530381Z"}]}
{"channel":"book","type":"update","data":[{"symbol":"BTC/USDC","bids":[{"price":67669.31,"qty":0.57711009}],"asks":[],"checksum":1963950986,"timestamp":"2024-06-01T18:06:44.530409Z"}]}
{"channel":"book","type":"update","data":[{"symbol":"BTC/USDC","bids":[],"asks":[{"price":67701.94,"qty":0.03640000}],"checksum":1087440670,"timestamp":"2024-06-01T18:06:44.530790Z"}]}
{"channel":"book","type":"update","data":[{"symbol":"BTC/USDC","bids":[],"asks":[{"price":67725.36,"qty":0.00000000},{"price":67729.76,"qty":0.01820000}],"checksum":3137488972,"timestamp":"2024-06-01T18:06:44.899018Z"}]}
{"channel":"book","type":"update","data":[{"symbol":"BTC/USDC","bids":[],"asks":[{"price":67701.94,"qty":0.01820000}],"checksum":1280688533,"timestamp":"2024-06-01T18:06:45.005768Z"}]}
{"channel":"book","type":"update","data":[{"symbol":"BTC/USDC","bids":[{"price":67680.94,"qty":0.59080704}],"asks":[],"checksum":1834623433,"timestamp":"2024-06-01T18:06:45.010219Z"}]}
{"channel":"book","type":"update","data":[{"symbol":"BTC/USDC","bids":[],"asks":[{"price":67727.79,"qty":0.00000000},{"price":67730.18,"qty":0.02233000}],"checksum":2662825317,"timestamp":"2024-06-01T18:06:45.011024Z"}]}
{"channel":"book","type":"update","data":[{"symbol":"BTC/USDC","bids":[],"asks":[{"price":67701.94,"qty":0.03640000}],"checksum":1776350396,"timestamp":"2024-06-01T18:06:45.172106Z"}]}
{"channel":"book","type":"update","data":[{"symbol":"BTC/USDC","bids":[],"asks":[{"price":67723.95,"qty":0.00000000},{"price":67731.55,"qty":0.03692474}],"checksum":2558957859,"timestamp":"2024-06-01T18:06:45.195331Z"}]}
{"channel":"book","type":"update","data":[{"symbol":"BTC/USDC","bids":[],"asks":[{"price":67723.93,"qty":0.00666888}],"checksum":1700953826,"timestamp":"2024-06-01T18:06:45.197446Z"}]}
{"channel":"book","type":"update","data":[{"symbol":"BTC/USDC","bids":[],"asks":[{"price":67727.77,"qty":0.00000000},{"price":67731.55,"qty":0.03692474},{"price":67727.75,"qty":0.17000000}],"checksum":3821545702,"timestamp":"2024-06-01T18:06:45.461496Z"}]}
{"channel":"book","type":"update","data":[{"symbol":"BTC/USDC","bids":[{"price":67668.69,"qty":0.00350000}],"asks":[],"checksum":4183216800,"timestamp":"2024-06-01T18:06:45.461672Z"}]}
{"channel":"book","type":"update","data":[{"symbol":"BTC/USDC","bids":[],"asks":[{"price":67725.18,"qty":0.00400000}],"checksum":3122608887,"timestamp":"2024-06-01T18:06:45.520492Z"}]}
{"channel":"book","type":"update","data":[{"symbol":"BTC/USDC","bids":[{"price":67692.83,"qty":0.00021288}],"asks":[],"checksum":1366676262,"timestamp":"2024-06-01T18:06:46.433743Z"}]}
{"channel":"book","type":"update","data":[{"symbol":"BTC/USDC","bids":[],"asks":[{"price":67701.94,"qty":0.01820000}],"checksum":3697736904,"timestamp":"2024-06-01T18:06:46.437615Z"}]}
{"channel":"book","type":"update","data":[{"symbol":"BTC/USDC","bids":[],"asks":[{"price":67723.94,"qty":0.00000000},{"price":67730.18,"qty":0.02233000}],"checksum":31042055,"timestamp":"2024-06-01T18:06:46.666633Z"}]}
{"channel":"book","type":"update","data":[{"symbol":"BTC/USDC","bids":[],"asks":[{"price":67727.76,"qty":0.00000000},{"price":67731.55,"qty":0.03692474}],"checksum":568697569,"timestamp":"2024-06-01T18:06:46.666652Z"}]}
{"channel":"book","type":"update","data":[{"symbol":"BTC/USDC","bids":[],"asks":[{"price":67723.92,"qty":0.76734486}],"checksum":3740427360,"timestamp":"2024-06-01T18:06:46.669269Z"}]}
{"channel":"book","type":"update","data":[{"symbol":"BTC/USDC","bids":[{"price":67669.30,"qty":0.00000000},{"price":67668.68,"qty":0.02180000}],"asks":[],"checksum":2767911059,"timestamp":"2024-06-01T18:06:47.469461Z"}]}
{"channel":"book","type":"update","data":[{"symbol":"BTC/USDC","bids":[{"price":67682.05,"qty":0.00634749}],"asks":[],"checksum":2015999086,"timestamp":"2024-06-01T18:06:47.470352Z"}]}
{"channel":"book","type":"update","data":[{"symbol":"BTC/USDC","bids":[{"price":67669.32,"qty":0.02258274}],"asks":[],"checksum":344481523,"timestamp":"2024-06-01T18:06:47.470433Z"}]}
{"channel":"book","type":"update","data":[{"symbol":"BTC/USDC","bids":[],"asks":[{"price":67723.93,"qty":0.00000000},{"price":67731.55,"qty":0.03692474}],"checksum":86037058,"timestamp":"2024-06-01T18:06:47.636951Z"}]}
{"channel":"book","type":"update","data":[{"symbol":"BTC/USDC","bids":[],"asks":[{"price":67723.91,"qty":0.00646971}],"checksum":3538599352,"timestamp":"2024-06-01T18:06:47.641717Z"}]}
{"channel":"book","type":"update","data":[{"symbol":"BTC/USDC","bids":[{"price":67682.04,"qty":0.00000000},{"price":67668.69,"qty":0.00350000}],"asks":[],"checksum":855025686,"timestamp":"2024-06-01T18:06:48.118673Z"}]}
{"channel":"book","type":"update","data":[{"symbol":"BTC/USDC","bids":[{"price":67669.31,"qty":0.00000000},{"price":67668.68,"qty":0.02180000}],"asks":[],"checksum":3221420778,"timestamp":"2024-06-01T18:06:48.118711Z"}]}
{"channel":"book","type":"update","data":[{"symbol":"BTC/USDC","bids":[{"price":67682.06,"qty":1.15349898}],"asks":[],"checksum":1745385983,"timestamp":"2024-06-01T18:06:48.119814Z"}]}
{"channel":"book","type":"update","data":[{"symbol":"BTC/USDC","bids":[],"asks":[{"price":67701.94,"qty":0.00000000},{"price":67731.55,"qty":0.03692474}],"checksum":4221273053,"timestamp":"2024-06-01T18:06:48.563273Z"}]}
{"channel":"book","type":"update","data":[{"symbol":"BTC/USDC","bids":[],"asks":[{"price":67702.33,"qty":0.01820000}],"checksum":356359054,"timestamp":"2024-06-01T18:06:48.567239Z"}]}
{"channel":"book","type":"update","data":[{"symbol":"BTC/USDC","bids":[],"asks":[{"price":67727.49,"qty":1.09715923}],"checksum":1440877709,"timestamp":"2024-06-01T18:06:48.569412Z"}]}
{"channel":"book","type":"update","data":[{"symbol":"BTC/USDC","bids":[],"asks":[{"price":67704.28,"qty":0.01820000}],"checksum":1720529567,"timestamp":"2024-06-01T18:06:48.570056Z"}]}
{"channel":"book","type":"update","data":[{"symbol":"BTC/USDC","bids":[],"asks":[{"price":67704.28,"qty":0.00000000},{"price":67729.76,"qty":0.01820000}],"checksum":1440877709,"timestamp":"2024-06-01T18:06:48.573180Z"}]}
{"channel":"book","type":"update","data":[{"symbol":"BTC/USDC","bids":[],"asks":[{"price":67702.33,"qty":0.00000000},{"price":67730.18,"qty":0.02233000}],"checksum":1958978258,"timestamp":"2024-06-01T18:06:49.102260Z"}]}
{"channel":"book","type":"update","data":[{"symbol":"BTC/USDC","bids":[],"asks":[{"price":67703.11,"qty":0.01820000}],"checksum":421279172,"timestamp":"2024-06-01T18:06:49.106265Z"}]}
{"channel":"book","type":"update","data":[{"symbol":"BTC/USDC","bids":[],"asks":[{"price":67727.75,"qty":0.00000000},{"price":67730.18,"qty":0.02233000},{"price":67729.75,"qty":0.17000000}],"checksum":2160619974,"timestamp":"2024-06-01T18:06:49.462223Z"}]}
{"channel":"book","type":"update","data":[{"symbol":"BTC/USDC","bids":[{"price":67668.69,"qty":0.00000000},{"price":67668.68,"qty":0.02180000},{"price":67669.33,"qty":0.00350000}],"asks":[],"checksum":2558067810,"timestamp":"2024-06-01T18:06:49.462328Z"}]}
{"channel":"book","type":"update","data":[{"symbol":"BTC/USDC","bids":[],"asks":[{"price":67723.92,"qty":0.00000000},{"price":67730.18,"qty":0.02233000}],"checksum":4264597,"timestamp":"2024-06-01T18:06:49.564068Z"}]}
{"channel":"book","type":"update","data":[{"symbol":"BTC/USDC","bids":[],"asks":[{"price":67727.48,"qty":0.59080704}],"checksum":3402386698,"timestamp":"2024-06-01T18:06:49.568556Z"}]}
{"channel":"book","type":"update","data":[{"symbol":"BTC/USDC","bids":[],"asks":[{"price":67723.90,"qty":0.81345769}],"checksum":2560820651,"timestamp":"2024-06-01T18:06:49.568624Z"}]}
{"channel":"book","type":"update","data":[{"symbol":"BTC/USDC","bids":[],"asks":[{"price":67727.48,"qty":1.25389191}],"checksum":270468749,"timestamp":"2024-06-01T18:06:49.568731Z"}]}
{"channel":"book","type":"update","data":[{"symbol":"BTC/USDC","bids":[{"price":67680.94,"qty":0.00000000},{"price":67668.68,"qty":0.02180000}],"asks":[],"checksum":3861283916,"timestamp":"2024-06-01T18:06:49.569052Z"}]}
{"channel":"book","type":"update","data":[{"symbol":"BTC/USDC","bids":[],"asks":[{"price":67723.91,"qty":0.00000000},{"price":67729.76,"qty":0.01820000}],"checksum":3604853885,"timestamp":"2024-06-01T18:06:50.031182Z"}]}
{"channel":"book","type":"update","data":[{"symbol":"BTC/USDC","bids":[{"price":67680.94,"qty":0.59080704}],"asks":[],"checksum":1106378119,"timestamp":"2024-06-01T18:06:50.035751Z"}]}
{"channel":"book","type":"update","data":[{"symbol":"BTC/USDC","bids":[],"asks":[{"price":67723.89,"qty":0.00726639}],"checksum":1466866782,"timestamp":"2024-06-01T18:06:50.036065Z"}]}
{"channel":"book","type":"update","data":[{"symbol":"BTC/USDC","bids":[],"asks":[{"price":67727.48,"qty":0.66308487}],"checksum":3781526489,"timestamp":"2024-06-01T18:06:50.036140Z"}]}
{"channel":"book","type":"update","data":[{"symbol":"BTC/USDC","bids":[{"price":67682.05,"qty":0.00000000},{"price":67668.68,"qty":0.02180000}],"asks":[],"checksum":2355251289,"timestamp":"2024-06-01T18:06:50.163476Z"}]}
{"channel":"book","type":"update","data":[{"symbol":"BTC/USDC","bids":[{"price":67669.32,"qty":0.00000000},{"price":67667.72,"qty":0.02309162}],"asks":[],"checksum":4168157657,"timestamp":"2024-06-01T18:06:50.163649Z"}]}
{"channel":"book","type":"update","data":[{"symbol":"BTC/USDC","bids":[{"price":67682.07,"qty":0.00750027}],"asks":[],"checksum":1958555264,"timestamp":"2024-06-01T18:06:50.164534Z"}]}
{"channel":"book","type":"update","data":[{"symbol":"BTC/USDC","bids":[],"asks":[{"price":67725.18,"qty":0.00000000},{"price":67729.76,"qty":0.01820000}],"checksum":60663875,"timestamp":"2024-06-01T18:06:50.650125Z"}]}
{"channel":"book","type":"update","data":[{"symbol":"BTC/USDC","bids":[],"asks":[{"price":67725.28,"qty":0.00400000}],"checksum":15157644,"timestamp":"2024-06-01T18:06:51.280808Z"}]}
{"channel":"book","type":"update","data":[{"symbol":"BTC/USDC","bids":[{"price":67682.06,"qty":0.00000000},{"price":67667.72,"qty":0.02309162}],"asks":[],"checksum":2541892568,"timestamp":"2024-06-01T18:06:51.716848Z"}]}
{"channel":"book","type":"update","data":[{"symbol":"BTC/USDC","bids":[{"price":67682.08,"qty":1.06704065}],"asks":[],"checksum":220228403,"timestamp":"2024-06-01T18:06:51.717840Z"}]}
{"channel":"book","type":"update","data":[{"symbol":"BTC/USDC","bids":[],"asks":[{"price":67727.47,"qty":0.59080704}],"checksum":3540664523,"timestamp":"2024-06-01T18:06:51.721067Z"}]}
{"channel":"book","type":"update","data":[{"symbol":"BTC/USDC","bids":[{"price":67680.94,"qty":0.00000000},{"price":67667.72,"qty":0.02309162}],"asks":[],"checksum":1781648301,"timestamp":"2024-06-01T18:06:51.721782Z"}]}
{"channel":"book","type":"update","data":[{"symbol":"BTC/USDC","bids":[],"asks":[{"price":67727.47,"qty":1.18161408}],"checksum":276272682,"timestamp":"2024-06-01T18:06:51.722187Z"}]}
{"channel":"book","type":"update","data":[{"symbol":"BTC/USDC","bids":[],"asks":[{"price":67723.90,"qty":0.00000000},{"price":67729.75,"qty":0.17000000}],"checksum":785092551,"timestamp":"2024-06-01T18:06:52.242337Z"}]}
{"channel":"book","type":"update","data":[{"symbol":"BTC/USDC","bids":[],"asks":[{"price":67727.48,"qty":0.00000000},{"price":67729.76,"qty":0.01820000}],"checksum":1958439771,"timestamp":"2024-06-01T18:06:52.242402Z"}]}
{"channel":"book","type":"update","data":[{"symbol":"BTC/USDC","bids":[],"asks":[{"price":67723.88,"qty":0.83651400}],"checksum":1136392731,"timestamp":"2024-06-01T18:06:52.245086Z"}]}
{"channel":"book","type":"update","data":[{"symbol":"BTC/USDC","bids":[],"asks":[{"price":67727.46,"qty":0.66292163}],"checksum":2435176732,"timestamp":"2024-06-01T18:06:52.245193Z"}]}
{"channel":"book","type":"update","data":[{"symbol":"BTC/USDC","bids":[],"asks":[{"price":67703.11,"qty":0.03640000}],"checksum":4194940724,"timestamp":"2024-06-01T18:06:52.707131Z"}]}
{"channel":"book","type":"update","data":[{"symbol":"BTC/USDC","bids":[],"asks":[{"price":67703.11,"qty":0.01820000}],"checksum":2435176732,"timestamp":"2024-06-01T18:06:52.883827Z"}]}
{"channel":"book","type":"update","data":[{"symbol":"BTC/USDC","bids":[],"asks":[{"price":67703.11,"qty":0.00000000},{"price":67729.75,"qty":0.17000000}],"checksum":3579817758,"timestamp":"2024-06-01T18:06:52.932767Z"}]}
{"channel":"book","type":"update","data":[{"symbol":"BTC/USDC","bids":[],"asks":[{"price":67703.59,"qty":0.01820000}],"checksum":3533878307,"timestamp":"2024-06-01T18:06:52.936136Z"}]}
{"channel":"book","type":"update","data":[{"symbol":"BTC/USDC","bids":[],"asks":[{"price":67703.59,"qty":0.00000000},{"price":67729.75,"qty":0.17000000}],"checksum":3579817758,"timestamp":"2024-06-01T18:06:52.939096Z"}]}
{"channel":"book","type":"update","data":[{"symbol":"BTC/USDC","bids":[],"asks":[{"price":67703.76,"qty":0.01820000}],"checksum":1272147853,"timestamp":"2024-06-01T18:06:52.942984Z"}]}
{"channel":"book","type":"update","data":[{"symbol":"BTC/USDC","bids":[{"price":67682.07,"qty":0.00000000},{"price":67667.19,"qty":0.03692474}],"asks":[],"checksum":3823570531,"timestamp":"2024-06-01T18:06:53.053831Z"}]}
{"channel":"book","type":"update","data":[{"symbol":"BTC/USDC","bids":[{"price":67682.09,"qty":0.00692389}],"asks":[],"checksum":3745139215,"timestamp":"2024-06-01T18:06:53.054557Z"}]}
{"channel":"book","type":"update","data":[{"symbol":"BTC/USDC","bids":[],"asks":[{"price":67703.76,"qty":0.03640000}],"checksum":3021349927,"timestamp":"2024-06-01T18:06:53.405459Z"}]}
{"channel":"book","type":"update","data":[{"symbol":"BTC/USDC","bids":[],"asks":[{"price":67727.45,"qty":0.17000000}],"checksum":3765675866,"timestamp":"2024-06-01T18:06:53.462946Z"}]}
{"channel":"book","type":"update","data":[{"symbol":"BTC/USDC","bids":[{"price":67669.33,"qty":0.00000000},{"price":67667.19,"qty":0.03692474},{"price":67669.25,"qty":0.00350000}],"asks":[],"checksum":4050669635,"timestamp":"2024-06-01T18:06:53.463005Z"}]}
{"channel":"book","type":"update","data":[{"symbol":"BTC/USDC","bids":[],"asks":[{"price":67703.76,"qty":0.01820000}],"checksum":3058666515,"timestamp":"2024-06-01T18:06:53.660429Z"}]}
{"channel":"book","type":"update","data":[{"symbol":"BTC/USDC","bids":[],"asks":[{"price":67703.76,"qty":0.03640000}],"checksum":4050669635,"timestamp":"2024-06-01T18:06:53.815759Z"}]}
{"channel":"book","type":"update","data":[{"symbol":"BTC/USDC","bids":[],"asks":[{"price":67703.76,"qty":0.01820000}],"checksum":3058666515,"timestamp":"2024-06-01T18:06:54.166285Z"}]}
{"channel":"book","type":"update","data":[{"symbol":"BTC/USDC","bids":[],"asks":[{"price":67703.76,"qty":0.03640000}],"checksum":4050669635,"timestamp":"2024-06-01T18:06:54.196679Z"}]}
{"channel":"book","type":"update","data":[{"symbol":"BTC/USDC","bids":[],"asks":[{"price":67723.89,"qty":0.00000000},{"price":67727.49,"qty":1.09715923}],"checksum":2739722086,"timestamp":"2024-06-01T18:06:54.750845Z"}]}
{"channel":"book","type":"update","data":[{"symbol":"BTC/USDC","bids":[],"asks":[{"price":67723.87,"qty":0.00684622}],"checksum":2493511282,"timestamp":"2024-06-01T18:06:54.753299Z"}]}
{"channel":"book","type":"update","data":[{"symbol":"BTC/USDC","bids":[],"asks":[{"price":67723.88,"qty":0.00000000},{"price":67727.49,"qty":1.09715923}],"checksum":1064891751,"timestamp":"2024-06-01T18:06:55.105216Z"}]}
{"channel":"book","type":"update","data":[{"symbol":"BTC/USDC","bids":[],"asks":[{"price":67727.46,"qty":0.00000000},{"price":67729.76,"qty":0.01820000}],"checksum":96478409,"timestamp":"2024-06-01T18:06:55.105542Z"}]}
{"channel":"book","type":"update","data":[{"symbol":"BTC/USDC","bids":[],"asks":[{"price":67727.44,"qty":0.75454485}],"checksum":4216912509,"timestamp":"2024-06-01T18:06:55.108799Z"}]}
{"channel":"book","type":"update","data":[{"symbol":"BTC/USDC","bids":[],"asks":[{"price":67723.88,"qty":0.81345774}],"checksum":3213443322,"timestamp":"2024-06-01T18:06:55.108815Z"}]}
{"channel":"book","type":"update","data":[{"symbol":"BTC/USDC","bids":[{"price":67682.08,"qty":0.00000000},{"price":67665.86,"qty":0.04452580}],"asks":[],"checksum":3259001656,"timestamp":"2024-06-01T18:06:55.211367Z"}]}
{"channel":"book","type":"update","data":[{"symbol":"BTC/USDC","bids":[{"price":67682.10,"qty":0.05836032}],"asks":[],"checksum":2004643648,"timestamp":"2024-06-01T18:06:55.212977Z"}]}
{"channel":"book","type":"update","data":[{"symbol":"BTC/USDC","bids":[{"price":67669.26,"qty":0.57711235}],"asks":[],"checksum":2923706905,"timestamp":"2024-06-01T18:06:55.213139Z"}]}
{"channel":"book","type":"update","data":[{"symbol":"BTC/USDC","bids":[{"price":67682.09,"qty":0.00000000},{"price":67667.72,"qty":0.02309162}],"asks":[],"checksum":1457463190,"timestamp":"2024-06-01T18:06:55.740382Z"}]}
{"channel":"book","type":"update","data":[{"symbol":"BTC/USDC","bids":[{"price":67669.27,"qty":0.01556977}],"asks":[],"checksum":3878409326,"timestamp":"2024-06-01T18:06:55.780712Z"}]}
{"channel":"book","type":"update","data":[{"symbol":"BTC/USDC","bids":[{"price":67682.11,"qty":0.00029541}],"asks":[],"checksum":3722791088,"timestamp":"2024-06-01T18:06:55.780729Z"}]}
{"channel":"book","type":"update","data":[{"symbol":"BTC/USDC","bids":[],"asks":[{"price":67725.28,"qty":0.00000000},{"price":67727.49,"qty":1.09715923}],"checksum":3163431374,"timestamp":"2024-06-01T18:06:56.416063Z"}]}
{"channel":"book","type":"update","data":[{"symbol":"BTC/USDC","bids":[],"asks":[{"price":67724.03,"qty":0.00400000}],"checksum":2657522898,"timestamp":"2024-06-01T18:06:57.073738Z"}]}
{"channel":"book","type":"update","data":[{"symbol":"BTC/USDC","bids":[],"asks":[{"price":67723.87,"qty":0.00000000},{"price":67727.49,"qty":1.09715923}],"checksum":2729365047,"timestamp":"2024-06-01T18:06:57.198685Z"}]}
{"channel":"book","type":"update","data":[{"symbol":"BTC/USDC","bids":[],"asks":[{"price":67723.87,"qty":0.00706723}],"checksum":164682781,"timestamp":"2024-06-01T18:06:57.201408Z"}]}
{"channel":"book","type":"update","data":[{"symbol":"BTC/USDC","bids":[{"price":67669.25,"qty":0.00000000},{"price":67668.68,"qty":0.02180000}],"asks":[],"checksum":3328535773,"timestamp":"2024-06-01T18:06:57.462506Z"}]}
{"channel":"book","type":"update","data":[{"symbol":"BTC/USDC","bids":[],"asks":[{"price":67727.45,"qty":0.00000000},{"price":67727.49,"qty":1.09715923},{"price":67727.43,"qty":0.17000000}],"checksum":1407071348,"timestamp":"2024-06-01T18:06:57.462688Z"}]}
{"channel":"book","type":"update","data":[{"symbol":"BTC/USDC","bids":[],"asks":[{"price":67727.44,"qty":0.00000000},{"price":67727.49,"qty":1.09715923}],"checksum":1740370786,"timestamp":"2024-06-01T18:06:57.897059Z"}]}
{"channel":"book","type":"update","data":[{"symbol":"BTC/USDC","bids":[],"asks":[{"price":67723.88,"qty":0.00000000},{"price":67729.76,"qty":0.01820000}],"checksum":881709075,"timestamp":"2024-06-01T18:06:57.897252Z"}]}
{"channel":"book","type":"update","data":[{"symbol":"BTC/USDC","bids":[],"asks":[{"price":67723.86,"qty":0.81352815}],"checksum":1205088583,"timestamp":"2024-06-01T18:06:57.901476Z"}]}
{"channel":"book","type":"update","data":[{"symbol":"BTC/USDC","bids":[],"asks":[{"price":67727.44,"qty":0.70887765}],"checksum":2126152313,"timestamp":"2024-06-01T18:06:57.901585Z"}]}
{"channel":"book","type":"update","data":[{"symbol":"BTC/USDC","bids":[{"price":67669.27,"qty":0.00000000},{"price":67667.72,"qty":0.02309162}],"asks":[],"checksum":800447160,"timestamp":"2024-06-01T18:06:58.492781Z"}]}
{"channel":"book","type":"update","data":[{"symbol":"BTC/USDC","bids":[{"price":67682.11,"qty":0.00000000},{"price":67665.87,"qty":0.00350000}],"asks":[],"checksum":3159518670,"timestamp":"2024-06-01T18:06:58.493261Z"}]}
{"channel":"book","type":"update","data":[{"symbol":"BTC/USDC","bids":[{"price":67669.27,"qty":0.01412926}],"asks":[],"checksum":4237176996,"timestamp":"2024-06-01T18:06:58.493487Z"}]}
{"channel":"book","type":"update","data":[{"symbol":"BTC/USDC","bids":[{"price":67682.10,"qty":0.00000000},{"price":67666.55,"qty":0.03692474}],"asks":[],"checksum":1188921063,"timestamp":"2024-06-01T18:06:58.623305Z"}]}
{"channel":"book","type":"update","data":[{"symbol":"BTC/USDC","bids":[{"price":67669.26,"qty":0.00000000},{"price":67665.87,"qty":0.00350000}],"asks":[],"checksum":969584694,"timestamp":"2024-06-01T18:06:58.623397Z"}]}
{"channel":"book","type":"update","data":[{"symbol":"BTC/USDC","bids":[{"price":67682.04,"qty":0.02954174}],"asks":[],"checksum":384212140,"timestamp":"2024-06-01T18:06:58.624346Z"}]}
{"channel":"book","type":"update","data":[{"symbol":"BTC/USDC","bids":[{"price":67669.28,"qty":0.54831082}],"asks":[],"checksum":3915316489,"timestamp":"2024-06-01T18:06:58.624662Z"}]}
{"channel":"book","type":"update","data":[{"symbol":"BTC/USDC","bids":[],"asks":[{"price":67723.87,"qty":0.00000000},{"price":67727.49,"qty":1.09715923}],"checksum":779517103,"timestamp":"2024-06-01T18:06:59.518209Z"}]}
{"channel":"book","type":"update","data":[{"symbol":"BTC/USDC","bids":[],"asks":[{"price":67723.85,"qty":0.00746557}],"checksum":3865075706,"timestamp":"2024-06-01T18:06:59.520859Z"}]}
{"channel":"book","type":"update","data":[{"symbol":"BTC/USDC","bids":[],"asks":[{"price":67714.99,"qty":0.05284625}],"checksum":2292215127,"timestamp":"2024-06-01T18:06:59.622125Z"}]}
{"channel":"book","type":"update","data":[{"symbol":"BTC/USDC","bids":[],"asks":[{"price":67714.99,"qty":0.00000000},{"price":67727.47,"qty":1.18161408}],"checksum":3865075706,"timestamp":"2024-06-01T18:06:59.631390Z"}]}
{"channel":"book","type":"update","data":[{"symbol":"BTC/USDC","bids":[],"asks":[{"price":67714.99,"qty":0.04979153}],"checksum":2143845478,"timestamp":"2024-06-01T18:06:59.771748Z"}]}
{"channel":"book","type":"update","data":[{"symbol":"BTC/USDC","bids":[],"asks":[{"price":67714.99,"qty":0.00000000},{"price":67727.47,"qty":1.18161408}],"checksum":3865075706,"timestamp":"2024-06-01T18:06:59.779498Z"}]}
{"channel":"book","type":"update","data":[{"symbol":"BTC/USDC","bids":[],"asks":[{"price":67714.99,"qty":0.04665107}],"checksum":3670295250,"timestamp":"2024-06-01T18:06:59.922625Z"}]}
{"channel":"book","type":"update","data":[{"symbol":"BTC/USDC","bids":[],"asks":[{"price":67714.99,"qty":0.00000000},{"price":67727.47,"qty":1.18161408}],"checksum":3865075706,"timestamp":"2024-06-01T18:06:59.929414Z"}]}
{"channel":"book","type":"update","data":[{"symbol":"BTC/USDC","bids":[],"asks":[{"price":67714.99,"qty":0.04701950}],"checksum":2193033729,"timestamp":"2024-06-01T18:07:00.073083Z"}]}
{"channel":"book","type":"update","data":[{"symbol":"BTC/USDC","bids":[],"asks":[{"price":67714.99,"qty":0.00000000},{"price":67727.47,"qty":1.18161408}],"checksum":3865075706,"timestamp":"2024-06-01T18:07:00.082157Z"}]}
{"channel":"book","type":"update","data":[{"symbol":"BTC/USDC","bids":[],"asks":[{"price":67714.99,"qty":0.05042415}],"checksum":3539874557,"timestamp":"2024-06-01T18:07:00.223362Z"}]}
{"channel":"book","type":"update","data":[{"symbol":"BTC/USDC","bids":[],"asks":[{"price":67714.99,"qty":0.00000000},{"price":67727.47,"qty":1.18161408}],"checksum":3865075706,"timestamp":"2024-06-01T18:07:00.230210Z"}]}
{"channel":"book","type":"update","data":[{"symbol":"BTC/USDC","bids":[],"asks":[{"price":67714.99,"qty":0.05403379}],"checksum":366852898,"timestamp":"2024-06-01T18:07:00.372251Z"}]}
{"channel":"book","type":"update","data":[{"symbol":"BTC/USDC","bids":[],"asks":[{"price":67714.99,"qty":0.00000000},{"price":67727.47,"qty":1.18161408}],"checksum":3865075706,"timestamp":"2024-06-01T18:07:00.378278Z"}]}
{"channel":"book","type":"update","data":[{"symbol":"BTC/USDC","bids":[],"asks":[{"price":67714.99,"qty":0.05425121}],"checksum":2942761844,"timestamp":"2024-06-01T18:07:00.522217Z"}]}
{"channel":"book","type":"update","data":[{"symbol":"BTC/USDC","bids":[],"asks":[{"price":67714.99,"qty":0.00000000},{"price":67727.47,"qty":1.18161408}],"checksum":3865075706,"timestamp":"2024-06-01T18:07:00.528504Z"}]}
{"channel":"book","type":"update","data":[{"symbol":"BTC/USDC","bids":[],"asks":[{"price":67714.99,"qty":0.05212846}],"checksum":1254630164,"timestamp":"2024-06-01T18:07:00.672587Z"}]}
{"channel":"book","type":"update","data":[{"symbol":"BTC/USDC","bids":[],"asks":[{"price":67714.99,"qty":0.00000000},{"price":67727.47,"qty":1.18161408}],"checksum":3865075706,"timestamp":"2024-06-01T18:07:00.679566Z"}]}
{"channel":"book","type":"update","data":[{"symbol":"BTC/USDC","bids":[],"asks":[{"price":67727.44,"qty":0.00000000},{"price":67727.49,"qty":1.09715923}],"checksum":3729301544,"timestamp":"2024-06-01T18:07:00.720462Z"}]}
{"channel":"book","type":"update","data":[{"symbol":"BTC/USDC","bids":[],"asks":[{"price":67723.86,"qty":0.00000000},{"price":67729.76,"qty":0.01820000}],"checksum":736313194,"timestamp":"2024-06-01T18:07:00.720552Z"}]}
{"channel":"book","type":"update","data":[{"symbol":"BTC/USDC","bids":[],"asks":[{"price":67723.84,"qty":0.81352817}],"checksum":3784072516,"timestamp":"2024-06-01T18:07:00.723283Z"}]}
{"channel":"book","type":"update","data":[{"symbol":"BTC/USDC","bids":[],"asks":[{"price":67727.42,"qty":0.73174467}],"checksum":3313439116,"timestamp":"2024-06-01T18:07:00.723314Z"}]}
{"channel":"book","type":"update","data":[{"symbol":"BTC/USDC","bids":[{"price":67668.68,"qty":0.00000000},{"price":67667.63,"qty":0.04542023}],"asks":[],"checksum":866583389,"timestamp":"2024-06-01T18:07:00.804953Z"}]}
{"channel":"book","type":"update","data":[{"symbol":"BTC/USDC","bids":[],"asks":[{"price":67718.81,"qty":0.02143000}],"checksum":3074866028,"timestamp":"2024-06-01T18:07:00.813508Z"}]}
{"channel":"book","type":"update","data":[{"symbol":"BTC/USDC","bids":[{"price":67671.92,"qty":0.59080704}],"asks":[],"checksum":2898987558,"timestamp":"2024-06-01T18:07:00.819056Z"}]}
{"channel":"book","type":"update","data":[{"symbol":"BTC/USDC","bids":[],"asks":[{"price":67714.99,"qty":0.04721091}],"checksum":1802715083,"timestamp":"2024-06-01T18:07:00.822824Z"}]}
{"channel":"book","type":"update","data":[{"symbol":"BTC/USDC","bids":[{"price":67679.29,"qty":0.01820000}],"asks":[],"checksum":2798810054,"timestamp":"2024-06-01T18:07:00.823747Z"}]}
{"channel":"book","type":"update","data":[{"symbol":"BTC/USDC","bids":[],"asks":[{"price":67714.99,"qty":0.00000000},{"price":67727.43,"qty":0.17000000}],"checksum":1634354731,"timestamp":"2024-06-01T18:07:00.829521Z"}]}
{"channel":"book","type":"update","data":[{"symbol":"BTC/USDC","bids":[],"asks":[{"price":67712.91,"qty":0.04725915}],"checksum":3020166661,"timestamp":"2024-06-01T18:07:00.972353Z"}]}
{"channel":"book","type":"update","data":[{"symbol":"BTC/USDC","bids":[],"asks":[{"price":67712.91,"qty":0.00000000},{"price":67727.43,"qty":0.17000000}],"checksum":1634354731,"timestamp":"2024-06-01T18:07:00.979881Z"}]}
{"channel":"book","type":"update","data":[{"symbol":"BTC/USDC","bids":[],"asks":[{"price":67712.91,"qty":0.04568819}],"checksum":519260987,"timestamp":"2024-06-01T18:07:01.122678Z"}]}
{"channel":"book","type":"update","data":[{"symbol":"BTC/USDC","bids":[],"asks":[{"price":67712.91,"qty":0.00000000},{"price":67727.43,"qty":0.17000000}],"checksum":1634354731,"timestamp":"2024-06-01T18:07:01.129233Z"}]}
{"channel":"book","type":"update","data":[{"symbol":"BTC/USDC","bids":[],"asks":[{"price":67712.91,"qty":0.05036687}],"checksum":2875747908,"timestamp":"2024-06-01T18:07:01.273704Z"}]}
{"channel":"book","type":"update","data":[{"symbol":"BTC/USDC","bids":[],"asks":[{"price":67712.91,"qty":0.00000000},{"price":67727.43,"qty":0.17000000}],"checksum":1634354731,"timestamp":"2024-06-01T18:07:01.281222Z"}]}
{"channel":"book","type":"update","data":[{"symbol":"BTC/USDC","bids":[{"price":67669.27,"qty":0.00000000},{"price":67667.63,"qty":0.04542023}],"asks":[],"checksum":3148595514,"timestamp":"2024-06-01T18:07:01.356129Z"}]}
{"channel":"book","type":"update","data":[{"symbol":"BTC/USDC","bids":[{"price":67671.93,"qty":0.01384119}],"asks":[],"checksum":3304959250,"timestamp":"2024-06-01T18:07:01.361912Z"}]}
{"channel":"book","type":"update","data":[{"symbol":"BTC/USDC","bids":[],"asks":[{"price":67712.91,"qty":0.04767923}],"checksum":344557664,"timestamp":"2024-06-01T18:07:01.422344Z"}]}
{"channel":"book","type":"update","data":[{"symbol":"BTC/USDC","bids":[],"asks":[{"price":67727.41,"qty":0.17000000}],"checksum":1092946780,"timestamp":"2024-06-01T18:07:01.463167Z"}]}
{"channel":"book","type":"update","data":[{"symbol":"BTC/USDC","bids":[],"asks":[{"price":67723.85,"qty":0.00000000},{"price":67727.42,"qty":0.73174467}],"checksum":1651027535,"timestamp":"2024-06-01T18:07:01.931835Z"}]}
{"channel":"book","type":"update","data":[{"symbol":"BTC/USDC","bids":[],"asks":[{"price":67723.83,"qty":0.00686806}],"checksum":3944633884,"timestamp":"2024-06-01T18:07:01.934096Z"}]}
{"channel":"book","type":"update","data":[{"symbol":"BTC/USDC","bids":[],"asks":[{"price":67724.03,"qty":0.00000000},{"price":67727.42,"qty":0.73174467}],"checksum":521497314,"timestamp":"2024-06-01T18:07:02.200301Z"}]}
{"channel":"book","type":"update","data":[{"symbol":"BTC/USDC","bids":[{"price":67679.30,"qty":0.59082275}],"asks":[],"checksum":2771571611,"timestamp":"2024-06-01T18:07:02.257891Z"}]}
{"channel":"book","type":"update","data":[{"symbol":"BTC/USDC","bids":[{"price":67669.28,"qty":0.00000000},{"price":67669.24,"qty":0.07388880}],"asks":[],"checksum":4109044313,"timestamp":"2024-06-01T18:07:02.260837Z"}]}
{"channel":"book","type":"update","data":[{"symbol":"BTC/USDC","bids":[{"price":67682.04,"qty":0.00000000},{"price":67667.63,"qty":0.04542023}],"asks":[],"checksum":2870911088,"timestamp":"2024-06-01T18:07:02.260855Z"}]}
{"channel":"book","type":"update","data":[{"symbol":"BTC/USDC","bids":[{"price":67682.04,"qty":0.05836282}],"asks":[],"checksum":1060169678,"timestamp":"2024-06-01T18:07:02.262604Z"}]}
{"channel":"book","type":"update","data":[{"symbol":"BTC/USDC","bids":[{"price":67671.94,"qty":1.61468535}],"asks":[],"checksum":138026340,"timestamp":"2024-06-01T18:07:02.262744Z"}]}
{"channel":"book","type":"update","data":[{"symbol":"BTC/USDC","bids":[],"asks":[{"price":67723.29,"qty":0.00400000}],"checksum":2676167720,"timestamp":"2024-06-01T18:07:02.812424Z"}]}
{"channel":"book","type":"update","data":[{"symbol":"BTC/USDC","bids":[],"asks":[{"price":67703.76,"qty":0.01820000}],"checksum":4105140736,"timestamp":"2024-06-01T18:07:03.321844Z"}]}
{"channel":"book","type":"update","data":[{"symbol":"BTC/USDC","bids":[],"asks":[{"price":67710.53,"qty":0.01820000}],"checksum":2702402987,"timestamp":"2024-06-01T18:07:03.327906Z"}]}
{"channel":"book","type":"update","data":[{"symbol":"BTC/USDC","bids":[],"asks":[{"price":67703.76,"qty":0.00000000},{"price":67727.41,"qty":0.17000000}],"checksum":841331161,"timestamp":"2024-06-01T18:07:03.335188Z"}]}
{"channel":"book","type":"update","data":[{"symbol":"BTC/USDC","bids":[],"asks":[{"price":67704.43,"qty":0.01820000}],"checksum":2702551832,"timestamp":"2024-06-01T18:07:03.339200Z"}]}
{"channel":"book","type":"update","data":[{"symbol":"BTC/USDC","bids":[],"asks":[{"price":67704.43,"qty":0.00000000},{"price":67727.41,"qty":0.17000000}],"checksum":841331161,"timestamp":"2024-06-01T18:07:03.394338Z"}]}
{"channel":"book","type":"update","data":[{"symbol":"BTC/USDC","bids":[],"asks":[{"price":67705.19,"qty":0.01820000}],"checksum":3715145548,"timestamp":"2024-06-01T18:07:03.398143Z"}]}
{"channel":"book","type":"update","data":[{"symbol":"BTC/USDC","bids":[{"price":67693.12,"qty":0.01820000}],"asks":[],"checksum":2900482146,"timestamp":"2024-06-01T18:07:03.433819Z"}]}
{"channel":"book","type":"update","data":[{"symbol":"BTC/USDC","bids":[{"price":67693.12,"qty":0.00000000},{"price":67671.91,"qty":0.01820000}],"asks":[],"checksum":3715145548,"timestamp":"2024-06-01T18:07:03.438125Z"}]}
{"channel":"book","type":"update","data":[{"symbol":"BTC/USDC","bids":[],"asks":[{"price":67705.28,"qty":0.00000000},{"price":67727.41,"qty":0.17000000}],"checksum":2089850013,"timestamp":"2024-06-01T18:07:03.438757Z"}]}
{"channel":"book","type":"update","data":[{"symbol":"BTC/USDC","bids":[],"asks":[{"price":67705.19,"qty":0.00000000},{"price":67727.42,"qty":0.73174467}],"checksum":1474869274,"timestamp":"2024-06-01T18:07:03.441556Z"}]}
{"channel":"book","type":"update","data":[{"symbol":"BTC/USDC","bids":[{"price":67693.55,"qty":0.01820000}],"asks":[],"checksum":882002105,"timestamp":"2024-06-01T18:07:03.441705Z"}]}
{"channel":"book","type":"update","data":[{"symbol":"BTC/USDC","bids":[],"asks":[{"price":67705.16,"qty":0.03692480}],"checksum":1717673193,"timestamp":"2024-06-01T18:07:03.442657Z"}]}
{"channel":"book","type":"update","data":[{"symbol":"BTC/USDC","bids":[{"price":67693.55,"qty":0.00000000},{"price":67671.91,"qty":0.01820000}],"asks":[],"checksum":85683274,"timestamp":"2024-06-01T18:07:03.445286Z"}]}
{"channel":"book","type":"update","data":[{"symbol":"BTC/USDC","bids":[],"asks":[{"price":67710.53,"qty":0.03640000}],"checksum":2155721011,"timestamp":"2024-06-01T18:07:03.445331Z"}]}
{"channel":"book","type":"update","data":[{"symbol":"BTC/USDC","bids":[],"asks":[{"price":67703.87,"qty":0.01820000}],"checksum":2784578478,"timestamp":"2024-06-01T18:07:03.446960Z"}]}
{"channel":"book","type":"update","data":[{"symbol":"BTC/USDC","bids":[],"asks":[{"price":67703.87,"qty":0.00000000},{"price":67727.41,"qty":0.17000000}],"checksum":2155721011,"timestamp":"2024-06-01T18:07:03.450594Z"}]}
{"channel":"book","type":"update","data":[{"symbol":"BTC/USDC","bids":[],"asks":[{"price":67704.71,"qty":0.01820000}],"checksum":3483785382,"timestamp":"2024-06-01T18:07:03.454365Z"}]}
{"channel":"book","type":"update","data":[{"symbol":"BTC/USDC","bids":[{"price":67692.90,"qty":0.01820000}],"asks":[],"checksum":2818150956,"timestamp":"2024-06-01T18:07:03.467812Z"}]}
{"channel":"book","type":"update","data":[{"symbol":"BTC/USDC","bids":[],"asks":[{"price":67704.71,"qty":0.00000000},{"price":67727.41,"qty":0.17000000}],"checksum":3894574009,"timestamp":"2024-06-01T18:07:03.468171Z"}]}
{"channel":"book","type":"update","data":[{"symbol":"BTC/USDC","bids":[{"price":67692.90,"qty":0.00000000},{"price":67671.91,"qty":0.01820000}],"asks":[],"checksum":2155721011,"timestamp":"2024-06-01T18:07:03.471222Z"}]}
{"channel":"book","type":"update","data":[{"symbol":"BTC/USDC","bids":[],"asks":[{"price":67703.77,"qty":0.01820000}],"checksum":3044638349,"timestamp":"2024-06-01T18:07:03.472073Z"}]}
{"channel":"book","type":"update","data":[{"symbol":"BTC/USDC","bids":[{"price":67693.11,"qty":0.01820000}],"asks":[],"checksum":2234204461,"timestamp":"2024-06-01T18:07:03.475307Z"}]}
{"channel":"book","type":"update","data":[{"symbol":"BTC/USDC","bids":[],"asks":[{"price":67703.77,"qty":0.00000000},{"price":67727.41,"qty":0.17000000}],"checksum":2955906707,"timestamp":"2024-06-01T18:07:03.475542Z"}]}
{"channel":"book","type":"update","data":[{"symbol":"BTC/USDC","bids":[{"price":67693.11,"qty":0.00000000},{"price":67671.91,"qty":0.01820000}],"asks":[],"checksum":2155721011,"timestamp":"2024-06-01T18:07:03.479104Z"}]}
{"channel":"book","type":"update","data":[{"symbol":"BTC/USDC","bids":[],"asks":[{"price":67703.37,"qty":0.01820000}],"checksum":4042499519,"timestamp":"2024-06-01T18:07:03.480041Z"}]}
{"channel":"book","type":"update","data":[{"symbol":"BTC/USDC","bids":[],"asks":[{"price":67723.84,"qty":0.00000000},{"price":67727.41,"qty":0.17000000}],"checksum":3739655947,"timestamp":"2024-06-01T18:07:03.483294Z"}]}
{"channel":"book","type":"update","data":[{"symbol":"BTC/USDC","bids":[],"asks":[{"price":67703.37,"qty":0.00000000},{"price":67727.49,"qty":1.09715923}],"checksum":3838413809,"timestamp":"2024-06-01T18:07:03.484638Z"}]}
{"channel":"book","type":"update","data":[{"symbol":"BTC/USDC","bids":[],"asks":[{"price":67727.40,"qty":0.73228510}],"checksum":1109035110,"timestamp":"2024-06-01T18:07:03.487589Z"}]}
{"channel":"book","type":"update","data":[{"symbol":"BTC/USDC","bids":[],"asks":[{"price":67723.82,"qty":0.74435317}],"checksum":3289739861,"timestamp":"2024-06-01T18:07:03.487661Z"}]}
{"channel":"book","type":"update","data":[{"symbol":"BTC/USDC","bids":[],"asks":[{"price":67704.25,"qty":0.01820000}],"checksum":474388624,"timestamp":"2024-06-01T18:07:03.490744Z"}]}
{"channel":"book","type":"update","data":[{"symbol":"BTC/USDC","bids":[],"asks":[{"price":67704.25,"qty":0.00000000},{"price":67727.40,"qty":0.73228510}],"checksum":3289739861,"timestamp":"2024-06-01T18:07:03.984935Z"}]}
{"channel":"book","type":"update","data":[{"symbol":"BTC/USDC","bids":[],"asks":[{"price":67704.89,"qty":0.01820000}],"checksum":1260358170,"timestamp":"2024-06-01T18:07:03.989042Z"}]}
{"channel":"book","type":"update","data":[{"symbol":"BTC/USDC","bids":[{"price":67692.89,"qty":0.01820000}],"asks":[],"checksum":2375480433,"timestamp":"2024-06-01T18:07:04.156469Z"}]}
{"channel":"book","type":"update","data":[{"symbol":"BTC/USDC","bids":[{"price":67671.93,"qty":0.00000000},{"price":67671.91,"qty":0.01820000}],"asks":[],"checksum":2056558054,"timestamp":"2024-06-01T18:07:04.156768Z"}]}
{"channel":"book","type":"update","data":[{"symbol":"BTC/USDC","bids":[{"price":67679.31,"qty":0.00548315}],"asks":[],"checksum":1992522252,"timestamp":"2024-06-01T18:07:04.158610Z"}]}
{"channel":"book","type":"update","data":[{"symbol":"BTC/USDC","bids":[{"price":67682.05,"qty":0.00144825}],"asks":[],"checksum":3408553037,"timestamp":"2024-06-01T18:07:04.158653Z"}]}
{"channel":"book","type":"update","data":[{"symbol":"BTC/USDC","bids":[{"price":67671.95,"qty":0.01950418}],"asks":[],"checksum":1562325055,"timestamp":"2024-06-01T18:07:04.158705Z"}]}
{"channel":"book","type":"update","data":[{"symbol":"BTC/USDC","bids":[{"price":67692.89,"qty":0.00000000},{"price":67671.94,"qty":1.61468535}],"asks":[],"checksum":767750309,"timestamp":"2024-06-01T18:07:04.159980Z"}]}
{"channel":"book","type":"update","data":[{"symbol":"BTC/USDC","bids":[{"price":67692.93,"qty":0.01820000}],"asks":[],"checksum":1148455371,"timestamp":"2024-06-01T18:07:04.163706Z"}]}
{"channel":"book","type":"update","data":[{"symbol":"BTC/USDC","bids":[{"price":67692.93,"qty":0.00000000},{"price":67671.94,"qty":1.61468535}],"asks":[],"checksum":767750309,"timestamp":"2024-06-01T18:07:04.166988Z"}]}
{"channel":"book","type":"update","data":[{"symbol":"BTC/USDC","bids":[{"price":67692.90,"qty":0.01820000}],"asks":[],"checksum":3814320986,"timestamp":"2024-06-01T18:07:04.170874Z"}]}
{"channel":"book","type":"update","data":[{"symbol":"BTC/USDC","bids":[{"price":67692.90,"qty":0.00000000},{"price":67671.94,"qty":1.61468535}],"asks":[],"checksum":767750309,"timestamp":"2024-06-01T18:07:04.174945Z"}]}
{"channel":"book","type":"update","data":[{"symbol":"BTC/USDC","bids":[{"price":67692.99,"qty":0.01820000}],"asks":[],"checksum":544885295,"timestamp":"2024-06-01T18:07:04.178114Z"}]}
{"channel":"book","type":"update","data":[{"symbol":"BTC/USDC","bids":[{"price":67692.99,"qty":0.00000000},{"price":67671.94,"qty":1.61468535}],"asks":[],"checksum":767750309,"timestamp":"2024-06-01T18:07:04.181741Z"}]}
{"channel":"book","type":"update","data":[{"symbol":"BTC/USDC","bids":[{"price":67693.03,"qty":0.01820000}],"asks":[],"checksum":2031278791,"timestamp":"2024-06-01T18:07:04.184946Z"}]}
{"channel":"book","type":"update","data":[{"symbol":"BTC/USDC","bids":[],"asks":[{"price":67704.89,"qty":0.00000000},{"price":67727.40,"qty":0.73228510}],"checksum":4077560961,"timestamp":"2024-06-01T18:07:04.185703Z"}]}
{"channel":"book","type":"update","data":[{"symbol":"BTC/USDC","bids":[{"price":67693.03,"qty":0.00000000},{"price":67671.94,"qty":1.61468535}],"asks":[],"checksum":1012715013,"timestamp":"2024-06-01T18:07:04.188422Z"}]}
{"channel":"book","type":"update","data":[{"symbol":"BTC/USDC","bids":[],"asks":[{"price":67703.82,"qty":0.01820000}],"checksum":2959350510,"timestamp":"2024-06-01T18:07:04.189196Z"}]}
{"channel":"book","type":"update","data":[{"symbol":"BTC/USDC","bids":[{"price":67693.21,"qty":0.01820000}],"asks":[],"checksum":1780970106,"timestamp":"2024-06-01T18:07:04.191747Z"}]}
{"channel":"book","type":"update","data":[{"symbol":"BTC/USDC","bids":[],"asks":[{"price":67703.82,"qty":0.00000000},{"price":67727.40,"qty":0.73228510}],"checksum":3423146943,"timestamp":"2024-06-01T18:07:04.192434Z"}]}
{"channel":"book","type":"update","data":[{"symbol":"BTC/USDC","bids":[{"price":67693.21,"qty":0.00000000},{"price":67671.94,"qty":1.61468535}],"asks":[],"checksum":1012715013,"timestamp":"2024-06-01T18:07:04.195295Z"}]}
{"channel":"book","type":"update","data":[{"symbol":"BTC/USDC","bids":[],"asks":[{"price":67703.57,"qty":0.01820000}],"checksum":2856771238,"timestamp":"2024-06-01T18:07:04.196142Z"}]}
{"channel":"book","type":"update","data":[{"symbol":"BTC/USDC","bids":[],"asks":[{"price":67703.57,"qty":0.00000000},{"price":67727.40,"qty":0.73228510}],"checksum":1012715013,"timestamp":"2024-06-01T18:07:04.199040Z"}]}
{"channel":"book","type":"update","data":[{"symbol":"BTC/USDC","bids":[],"asks":[{"price":67705.10,"qty":0.01820000}],"checksum":793132882,"timestamp":"2024-06-01T18:07:04.204010Z"}]}
{"channel":"book","type":"update","data":[{"symbol":"BTC/USDC","bids":[],"asks":[{"price":67723.83,"qty":0.00000000},{"price":67727.40,"qty":0.73228510}],"checksum":1591494718,"timestamp":"2024-06-01T18:07:04.268527Z"}]}
{"channel":"book","type":"update","data":[{"symbol":"BTC/USDC","bids":[],"asks":[{"price":67723.81,"qty":0.00646972}],"checksum":2728588248,"timestamp":"2024-06-01T18:07:04.271051Z"}]}
{"channel":"book","type":"update","data":[{"symbol":"BTC/USDC","bids":[],"asks":[{"price":67705.10,"qty":0.00000000},{"price":67727.39,"qty":0.17000000}],"checksum":2665854743,"timestamp":"2024-06-01T18:07:05.630369Z"}]}
{"channel":"book","type":"update","data":[{"symbol":"BTC/USDC","bids":[{"price":67693.82,"qty":0.01820000}],"asks":[],"checksum":2144944097,"timestamp":"2024-06-01T18:07:05.630806Z"}]}
{"channel":"book","type":"update","data":[{"symbol":"BTC/USDC","bids":[{"price":67694.05,"qty":0.01820000}],"asks":[],"checksum":3792603335,"timestamp":"2024-06-01T18:07:05.633092Z"}]}
{"channel":"book","type":"update","data":[{"symbol":"BTC/USDC","bids":[],"asks":[{"price":67710.53,"qty":0.01820000}],"checksum":134788209,"timestamp":"2024-06-01T18:07:05.634770Z"}]}
{"channel":"book","type":"update","data":[{"symbol":"BTC/USDC","bids":[{"price":67693.82,"qty":0.00000000},{"price":67671.95,"qty":0.01950418}],"asks":[],"checksum":1857025763,"timestamp":"2024-06-01T18:07:05.635884Z"}]}
{"channel":"book","type":"update","data":[{"symbol":"BTC/USDC","bids":[{"price":67694.05,"qty":0.00000000},{"price":67671.94,"qty":1.61468535}],"asks":[],"checksum":51718312,"timestamp":"2024-06-01T18:07:05.636674Z"}]}
{"channel":"book","type":"update","data":[{"symbol":"BTC/USDC","bids":[],"asks":[{"price":67705.15,"qty":0.01820000}],"checksum":638053751,"timestamp":"2024-06-01T18:07:05.637234Z"}]}
{"channel":"book","type":"update","data":[{"symbol":"BTC/USDC","bids":[{"price":67694.05,"qty":0.01820000}],"asks":[],"checksum":2119103852,"timestamp":"2024-06-01T18:07:05.637389Z"}]}
{"channel":"book","type":"update","data":[{"symbol":"BTC/USDC","bids":[],"asks":[{"price":67705.15,"qty":0.00000000},{"price":67727.39,"qty":0.17000000}],"checksum":1857025763,"timestamp":"2024-06-01T18:07:05.640664Z"}]}
{"channel":"book","type":"update","data":[{"symbol":"BTC/USDC","bids":[{"price":67694.05,"qty":0.00000000},{"price":67671.94,"qty":1.61468535}],"asks":[],"checksum":51718312,"timestamp":"2024-06-01T18:07:05.641602Z"}]}
{"channel":"book","type":"update","data":[{"symbol":"BTC/USDC","bids":[],"asks":[{"price":67705.16,"qty":0.00000000},{"price":67727.40,"qty":0.73228510}],"checksum":4264377051,"timestamp":"2024-06-01T18:07:05.643351Z"}]}
{"channel":"book","type":"update","data":[{"symbol":"BTC/USDC","bids":[{"price":67695.21,"qty":0.01820000}],"asks":[],"checksum":932902494,"timestamp":"2024-06-01T18:07:05.645783Z"}]}
{"channel":"book","type":"update","data":[{"symbol":"BTC/USDC","bids":[{"price":67693.13,"qty":0.01820000}],"asks":[],"checksum":2237602872,"timestamp":"2024-06-01T18:07:05.646221Z"}]}
{"channel":"book","type":"update","data":[{"symbol":"BTC/USDC","bids":[],"asks":[{"price":67710.53,"qty":0.03640000}],"checksum":2799794285,"timestamp":"2024-06-01T18:07:05.647597Z"}]}
{"channel":"book","type":"update","data":[{"symbol":"BTC/USDC","bids":[{"price":67695.21,"qty":0.00000000},{"price":67671.95,"qty":0.01950418}],"asks":[],"checksum":452944225,"timestamp":"2024-06-01T18:07:05.649006Z"}]}
{"channel":"book","type":"update","data":[{"symbol":"BTC/USDC","bids":[{"price":67693.13,"qty":0.00000000},{"price":67671.94,"qty":1.61468535}],"asks":[],"checksum":1933448501,"timestamp":"2024-06-01T18:07:05.649679Z"}]}
{"channel":"book","type":"update","data":[{"symbol":"BTC/USDC","bids":[],"asks":[{"price":67705.04,"qty":0.03692487}],"checksum":2932341082,"timestamp":"2024-06-01T18:07:05.651059Z"}]}
{"channel":"book","type":"update","data":[{"symbol":"BTC/USDC","bids":[{"price":67695.68,"qty":0.01820000}],"asks":[],"checksum":3186680681,"timestamp":"2024-06-01T18:07:05.654091Z"}]}
{"channel":"book","type":"update","data":[{"symbol":"BTC/USDC","bids":[{"price":67692.86,"qty":0.01820000}],"asks":[],"checksum":1728394694,"timestamp":"2024-06-01T18:07:05.654478Z"}]}
{"channel":"book","type":"update","data":[{"symbol":"BTC/USDC","bids":[],"asks":[{"price":67710.53,"qty":0.01820000}],"checksum":2365786480,"timestamp":"2024-06-01T18:07:05.654845Z"}]}
{"channel":"book","type":"update","data":[{"symbol":"BTC/USDC","bids":[{"price":67695.68,"qty":0.00000000},{"price":67671.95,"qty":0.01950418}],"asks":[],"checksum":3146486079,"timestamp":"2024-06-01T18:07:05.657315Z"}]}
{"channel":"book","type":"update","data":[{"symbol":"BTC/USDC","bids":[{"price":67692.86,"qty":0.00000000},{"price":67671.94,"qty":1.61468535}],"asks":[],"checksum":859268837,"timestamp":"2024-06-01T18:07:05.658180Z"}]}
{"channel":"book","type":"update","data":[{"symbol":"BTC/USDC","bids":[],"asks":[{"price":67705.03,"qty":0.01820000}],"checksum":2293618177,"timestamp":"2024-06-01T18:07:05.658258Z"}]}
{"channel":"book","type":"update","data":[{"symbol":"BTC/USDC","bids":[],"asks":[{"price":67705.03,"qty":0.00000000},{"price":67727.39,"qty":0.17000000}],"checksum":859268837,"timestamp":"2024-06-01T18:07:05.661637Z"}]}
{"channel":"book","type":"update","data":[{"symbol":"BTC/USDC","bids":[{"price":67694.12,"qty":0.01820000}],"asks":[],"checksum":2272889108,"timestamp":"2024-06-01T18:07:05.662618Z"}]}
{"channel":"book","type":"update","data":[{"symbol":"BTC/USDC","bids":[{"price":67694.12,"qty":0.00000000},{"price":67671.94,"qty":1.61468535}],"asks":[],"checksum":859268837,"timestamp":"2024-06-01T18:07:05.666161Z"}]}
{"channel":"book","type":"update","data":[{"symbol":"BTC/USDC","bids":[],"asks":[{"price":67704.02,"qty":0.01820000}],"checksum":2483076232,"timestamp":"2024-06-01T18:07:05.667015Z"}]}
{"channel":"book","type":"update","data":[{"symbol":"BTC/USDC","bids":[{"price":67693.29,"qty":0.01820000}],"asks":[],"checksum":2922804837,"timestamp":"2024-06-01T18:07:05.669337Z"}]}
{"channel":"book","type":"update","data":[{"symbol":"BTC/USDC","bids":[],"asks":[{"price":67704.02,"qty":0.00000000},{"price":67727.39,"qty":0.17000000}],"checksum":1464577557,"timestamp":"2024-06-01T18:07:05.670827Z"}]}
{"channel":"book","type":"update","data":[{"symbol":"BTC/USDC","bids":[{"price":67693.29,"qty":0.00000000},{"price":67671.94,"qty":1.61468535}],"asks":[],"checksum":859268837,"timestamp":"2024-06-01T18:07:05.672522Z"}]}
{"channel":"book","type":"update","data":[{"symbol":"BTC/USDC","bids":[],"asks":[{"price":67710.79,"qty":0.01820000}],"checksum":2957249887,"timestamp":"2024-06-01T18:07:05.673377Z"}]}
{"channel":"book","type":"update","data":[{"symbol":"BTC/USDC","bids":[],"asks":[{"price":67704.56,"qty":0.01820000}],"checksum":2221728302,"timestamp":"2024-06-01T18:07:05.674863Z"}]}
{"channel":"book","type":"update","data":[{"symbol":"BTC/USDC","bids":[{"price":67694.76,"qty":0.01820000}],"asks":[],"checksum":3088608263,"timestamp":"2024-06-01T18:07:05.676608Z"}]}
{"channel":"book","type":"update","data":[{"symbol":"BTC/USDC","bids":[],"asks":[{"price":67704.56,"qty":0.00000000},{"price":67724.00,"qty":0.07382907}],"checksum":3878386856,"timestamp":"2024-06-01T18:07:05.678000Z"}]}
{"channel":"book","type":"update","data":[{"symbol":"BTC/USDC","bids":[{"price":67694.76,"qty":0.00000000},{"price":67671.94,"qty":1.61468535}],"asks":[],"checksum":2957249887,"timestamp":"2024-06-01T18:07:05.680245Z"}]}
{"channel":"book","type":"update","data":[{"symbol":"BTC/USDC","bids":[],"asks":[{"price":67704.55,"qty":0.01820000}],"checksum":3066551763,"timestamp":"2024-06-01T18:07:05.680944Z"}]}
{"channel":"book","type":"update","data":[{"symbol":"BTC/USDC","bids":[{"price":67693.68,"qty":0.01820000}],"asks":[],"checksum":804204883,"timestamp":"2024-06-01T18:07:05.683986Z"}]}
{"channel":"book","type":"update","data":[{"symbol":"BTC/USDC","bids":[],"asks":[{"price":67704.55,"qty":0.00000000},{"price":67724.00,"qty":0.07382907}],"checksum":4292120187,"timestamp":"2024-06-01T18:07:05.684116Z"}]}
{"channel":"book","type":"update","data":[{"symbol":"BTC/USDC","bids":[{"price":67693.68,"qty":0.00000000},{"price":67671.94,"qty":1.61468535}],"asks":[],"checksum":2957249887,"timestamp":"2024-06-01T18:07:05.687372Z"}]}
{"channel":"book","type":"update","data":[{"symbol":"BTC/USDC","bids":[],"asks":[{"price":67704.62,"qty":0.01820000}],"checksum":3085332259,"timestamp":"2024-06-01T18:07:05.688482Z"}]}
{"channel":"book","type":"update","data":[{"symbol":"BTC/USDC","bids":[{"price":67693.97,"qty":0.01820000}],"asks":[],"checksum":1102040424,"timestamp":"2024-06-01T18:07:05.691489Z"}]}
{"channel":"book","type":"update","data":[{"symbol":"BTC/USDC","bids":[],"asks":[{"price":67704.62,"qty":0.00000000},{"price":67724.00,"qty":0.07382907}],"checksum":1566527582,"timestamp":"2024-06-01T18:07:05.692167Z"}]}
{"channel":"book","type":"update","data":[{"symbol":"BTC/USDC","bids":[{"price":67693.97,"qty":0.00000000},{"price":67671.94,"qty":1.61468535}],"asks":[],"checksum":2957249887,"timestamp":"2024-06-01T18:07:05.694928Z"}]}
{"channel":"book","type":"update","data":[{"symbol":"BTC/USDC","bids":[],"asks":[{"price":67704.61,"qty":0.01820000}],"checksum":2236436702,"timestamp":"2024-06-01T18:07:05.695658Z"}]}
{"channel":"book","type":"update","data":[{"symbol":"BTC/USDC","bids":[{"price":67693.85,"qty":0.01820000}],"asks":[],"checksum":1980455905,"timestamp":"2024-06-01T18:07:05.699127Z"}]}
{"channel":"book","type":"update","data":[{"symbol":"BTC/USDC","bids":[],"asks":[{"price":67704.61,"qty":0.00000000},{"price":67724.00,"qty":0.07382907}],"checksum":3857934672,"timestamp":"2024-06-01T18:07:05.699172Z"}]}
{"channel":"book","type":"update","data":[{"symbol":"BTC/USDC","bids":[],"asks":[{"price":67704.61,"qty":0.01820000}],"checksum":1980455905,"timestamp":"2024-06-01T18:07:05.702583Z"}]}
{"channel":"book","type":"update","data":[{"symbol":"BTC/USDC","bids":[{"price":67693.85,"qty":0.00000000},{"price":67671.94,"qty":1.61468535}],"asks":[],"checksum":2236436702,"timestamp":"2024-06-01T18:07:05.703500Z"}]}
{"channel":"book","type":"update","data":[{"symbol":"BTC/USDC","bids":[{"price":67693.85,"qty":0.01820000}],"asks":[],"checksum":1980455905,"timestamp":"2024-06-01T18:07:05.706778Z"}]}
{"channel":"book","type":"update","data":[{"symbol":"BTC/USDC","bids":[],"asks":[{"price":67704.61,"qty":0.00000000},{"price":67724.00,"qty":0.07382907}],"checksum":3857934672,"timestamp":"2024-06-01T18:07:05.707502Z"}]}
{"channel":"book","type":"update","data":[{"symbol":"BTC/USDC","bids":[{"price":67693.85,"qty":0.00000000},{"price":67671.94,"qty":1.61468535}],"asks":[],"checksum":2957249887,"timestamp":"2024-06-01T18:07:05.709922Z"}]}
{"channel":"book","type":"update","data":[{"symbol":"BTC/USDC","bids":[],"asks":[{"price":67704.61,"qty":0.01820000}],"checksum":2236436702,"timestamp":"2024-06-01T18:07:05.711264Z"}]}
{"channel":"book","type":"update","data":[{"symbol":"BTC/USDC","bids":[{"price":67693.87,"qty":0.01820000}],"asks":[],"checksum":3015842047,"timestamp":"2024-06-01T18:07:05.713550Z"}]}
{"channel":"book","type":"update","data":[{"symbol":"BTC/USDC","bids":[],"asks":[{"price":67704.61,"qty":0.00000000},{"price":67724.00,"qty":0.07382907}],"checksum":540682830,"timestamp":"2024-06-01T18:07:05.714830Z"}]}
{"channel":"book","type":"update","data":[{"symbol":"BTC/USDC","bids":[{"price":67693.87,"qty":0.00000000},{"price":67671.94,"qty":1.61468535}],"asks":[],"checksum":2957249887,"timestamp":"2024-06-01T18:07:05.716829Z"}]}
{"channel":"book","type":"update","data":[{"symbol":"BTC/USDC","bids":[],"asks":[{"price":67704.64,"qty":0.01820000}],"checksum":3534754009,"timestamp":"2024-06-01T18:07:05.718391Z"}]}
{"channel":"book","type":"update","data":[{"symbol":"BTC/USDC","bids":[{"price":67693.84,"qty":0.01820000}],"asks":[],"checksum":1585908902,"timestamp":"2024-06-01T18:07:05.720727Z"}]}
{"channel":"book","type":"update","data":[{"symbol":"BTC/USDC","bids":[],"asks":[{"price":67704.64,"qty":0.00000000},{"price":67724.00,"qty":0.07382907}],"checksum":2266482911,"timestamp":"2024-06-01T18:07:05.721321Z"}]}
{"channel":"book","type":"update","data":[{"symbol":"BTC/USDC","bids":[{"price":67693.84,"qty":0.00000000},{"price":67671.94,"qty":1.61468535}],"asks":[],"checksum":2957249887,"timestamp":"2024-06-01T18:07:05.724884Z"}]}
{"channel":"book","type":"update","data":[{"symbol":"BTC/USDC","bids":[],"asks":[{"price":67704.52,"qty":0.01820000}],"checksum":1960331965,"timestamp":"2024-06-01T18:07:05.725126Z"}]}
{"channel":"book","type":"update","data":[{"symbol":"BTC/USDC","bids":[{"price":67693.76,"qty":0.01820000}],"asks":[],"checksum":3657413864,"timestamp":"2024-06-01T18:07:05.728693Z"}]}
{"channel":"book","type":"update","data":[{"symbol":"BTC/USDC","bids":[],"asks":[{"price":67704.52,"qty":0.00000000},{"price":67724.00,"qty":0.07382907}],"checksum":3059496946,"timestamp":"2024-06-01T18:07:05.729251Z"}]}
{"channel":"book","type":"update","data":[{"symbol":"BTC/USDC","bids":[{"price":67693.76,"qty":0.00000000},{"price":67671.94,"qty":1.61468535}],"asks":[],"checksum":2957249887,"timestamp":"2024-06-01T18:07:05.732062Z"}]}
{"channel":"book","type":"update","data":[{"symbol":"BTC/USDC","bids":[],"asks":[{"price":67704.55,"qty":0.01820000}],"checksum":3066551763,"timestamp":"2024-06-01T18:07:05.733272Z"}]}
{"channel":"book","type":"update","data":[{"symbol":"BTC/USDC","bids":[{"price":67693.92,"qty":0.01820000}],"asks":[],"checksum":3210989188,"timestamp":"2024-06-01T18:07:05.736122Z"}]}
{"channel":"book","type":"update","data":[{"symbol":"BTC/USDC","bids":[],"asks":[{"price":67704.55,"qty":0.00000000},{"price":67724.00,"qty":0.07382907}],"checksum":1868067244,"timestamp":"2024-06-01T18:07:05.736686Z"}]}
{"channel":"book","type":"update","data":[{"symbol":"BTC/USDC","bids":[{"price":67693.92,"qty":0.00000000},{"price":67671.94,"qty":1.61468535}],"asks":[],"checksum":2957249887,"timestamp":"2024-06-01T18:07:05.739905Z"}]}
{"channel":"book","type":"update","data":[{"symbol":"BTC/USDC","bids":[],"asks":[{"price":67704.72,"qty":0.01820000}],"checksum":1076064662,"timestamp":"2024-06-01T18:07:05.740489Z"}]}
{"channel":"book","type":"update","data":[{"symbol":"BTC/USDC","bids":[{"price":67693.97,"qty":0.01820000}],"asks":[],"checksum":1868642444,"timestamp":"2024-06-01T18:07:05.743988Z"}]}
{"channel":"book","type":"update","data":[{"symbol":"BTC/USDC","bids":[],"asks":[{"price":67704.72,"qty":0.00000000},{"price":67724.00,"qty":0.07382907}],"checksum":1566527582,"timestamp":"2024-06-01T18:07:05.744251Z"}]}
{"channel":"book","type":"update","data":[{"symbol":"BTC/USDC","bids":[],"asks":[{"price":67704.73,"qty":0.01820000}],"checksum":362372593,"timestamp":"2024-06-01T18:07:05.747783Z"}]}
{"channel":"book","type":"update","data":[{"symbol":"BTC/USDC","bids":[{"price":67693.97,"qty":0.00000000},{"price":67671.94,"qty":1.61468535}],"asks":[],"checksum":3882522882,"timestamp":"2024-06-01T18:07:05.748055Z"}]}
{"channel":"book","type":"update","data":[{"symbol":"BTC/USDC","bids":[{"price":67694.00,"qty":0.01820000}],"asks":[],"checksum":2475479637,"timestamp":"2024-06-01T18:07:05.751461Z"}]}
{"channel":"book","type":"update","data":[{"symbol":"BTC/USDC","bids":[],"asks":[{"price":67704.73,"qty":0.00000000},{"price":67724.00,"qty":0.07382907}],"checksum":3679117306,"timestamp":"2024-06-01T18:07:05.751752Z"}]}
{"channel":"book","type":"update","data":[{"symbol":"BTC/USDC","bids":[{"price":67694.00,"qty":0.00000000},{"price":67671.94,"qty":1.61468535}],"asks":[],"checksum":2957249887,"timestamp":"2024-06-01T18:07:05.754800Z"}]}
{"channel":"book","type":"update","data":[{"symbol":"BTC/USDC","bids":[],"asks":[{"price":67704.73,"qty":0.01820000}],"checksum":3882522882,"timestamp":"2024-06-01T18:07:05.755802Z"}]}
{"channel":"book","type":"update","data":[{"symbol":"BTC/USDC","bids":[{"price":67693.82,"qty":0.01820000}],"asks":[],"checksum":1526400531,"timestamp":"2024-06-01T18:07:05.758686Z"}]}
{"channel":"book","type":"update","data":[{"symbol":"BTC/USDC","bids":[],"asks":[{"price":67704.73,"qty":0.00000000},{"price":67724.00,"qty":0.07382907}],"checksum":305990588,"timestamp":"2024-06-01T18:07:05.759497Z"}]}
{"channel":"book","type":"update","data":[{"symbol":"BTC/USDC","bids":[{"price":67693.82,"qty":0.00000000},{"price":67671.94,"qty":1.61468535}],"asks":[],"checksum":2957249887,"timestamp":"2024-06-01T18:07:05.762041Z"}]}
{"channel":"book","type":"update","data":[{"symbol":"BTC/USDC","bids":[],"asks":[{"price":67704.16,"qty":0.01820000}],"checksum":3986330744,"timestamp":"2024-06-01T18:07:05.763165Z"}]}
{"channel":"book","type":"update","data":[{"symbol":"BTC/USDC","bids":[{"price":67693.33,"qty":0.01820000}],"asks":[],"checksum":1320632126,"timestamp":"2024-06-01T18:07:05.766331Z"}]}
{"channel":"book","type":"update","data":[{"symbol":"BTC/USDC","bids":[],"asks":[{"price":67704.16,"qty":0.00000000},{"price":67724.00,"qty":0.07382907}],"checksum":2864707585,"timestamp":"2024-06-01T18:07:05.766970Z"}]}
{"channel":"book","type":"update","data":[{"symbol":"BTC/USDC","bids":[{"price":67693.33,"qty":0.00000000},{"price":67671.94,"qty":1.61468535}],"asks":[],"checksum":2957249887,"timestamp":"2024-06-01T18:07:05.770364Z"}]}
{"channel":"book","type":"update","data":[{"symbol":"BTC/USDC","bids":[],"asks":[{"price":67704.43,"qty":0.01820000}],"checksum":609533084,"timestamp":"2024-06-01T18:07:05.770865Z"}]}
{"channel":"book","type":"update","data":[{"symbol":"BTC/USDC","bids":[],"asks":[{"price":67704.43,"qty":0.00000000},{"price":67724.00,"qty":0.07382907}],"checksum":2957249887,"timestamp":"2024-06-01T18:07:05.773907Z"}]}
{"channel":"book","type":"update","data":[{"symbol":"BTC/USDC","bids":[{"price":67693.61,"qty":0.01820000}],"asks":[],"checksum":1022832398,"timestamp":"2024-06-01T18:07:05.773942Z"}]}
{"channel":"book","type":"update","data":[{"symbol":"BTC/USDC","bids":[{"price":67693.61,"qty":0.00000000},{"price":67671.94,"qty":1.61468535}],"asks":[],"checksum":2957249887,"timestamp":"2024-06-01T18:07:05.777808Z"}]}
{"channel":"book","type":"update","data":[{"symbol":"BTC/USDC","bids":[],"asks":[{"price":67704.05,"qty":0.01820000}],"checksum":687125808,"timestamp":"2024-06-01T18:07:05.777886Z"}]}
{"channel":"book","type":"update","data":[{"symbol":"BTC/USDC","bids":[],"asks":[{"price":67704.05,"qty":0.00000000},{"price":67724.00,"qty":0.07382907}],"checksum":2957249887,"timestamp":"2024-06-01T18:07:05.781301Z"}]}
{"channel":"book","type":"update","data":[{"symbol":"BTC/USDC","bids":[{"price":67692.87,"qty":0.01820000}],"asks":[],"checksum":1039163216,"timestamp":"2024-06-01T18:07:05.781403Z"}]}
{"channel":"book","type":"update","data":[{"symbol":"BTC/USDC","bids":[{"price":67692.87,"qty":0.00000000},{"price":67671.94,"qty":1.61468535}],"asks":[],"checksum":2957249887,"timestamp":"2024-06-01T18:07:05.785183Z"}]}
{"channel":"book","type":"update","data":[{"symbol":"BTC/USDC","bids":[],"asks":[{"price":67704.98,"qty":0.01820000}],"checksum":1631080521,"timestamp":"2024-06-01T18:07:05.785289Z"}]}
{"channel":"book","type":"update","data":[{"symbol":"BTC/USDC","bids":[{"price":67693.03,"qty":0.01820000}],"asks":[],"checksum":3227477578,"timestamp":"2024-06-01T18:07:05.789356Z"}]}
{"channel":"book","type":"update","data":[{"symbol":"BTC/USDC","bids":[],"asks":[{"price":67705.04,"qty":0.00000000},{"price":67724.00,"qty":0.07382907}],"checksum":1746508557,"timestamp":"2024-06-01T18:07:05.790455Z"}]}
{"channel":"book","type":"update","data":[{"symbol":"BTC/USDC","bids":[{"price":67693.03,"qty":0.00000000},{"price":67671.94,"qty":1.61468535}],"asks":[],"checksum":487370604,"timestamp":"2024-06-01T18:07:05.792767Z"}]}
{"channel":"book","type":"update","data":[{"symbol":"BTC/USDC","bids":[],"asks":[{"price":67710.53,"qty":0.00000000},{"price":67727.39,"qty":0.17000000}],"checksum":4256541555,"timestamp":"2024-06-01T18:07:05.794392Z"}]}
{"channel":"book","type":"update","data":[{"symbol":"BTC/USDC","bids":[],"asks":[{"price":67718.81,"qty":0.00000000},{"price":67727.40,"qty":0.73228510}],"checksum":1495993623,"timestamp":"2024-06-01T18:07:05.797587Z"}]}
{"channel":"book","type":"update","data":[{"symbol":"BTC/USDC","bids":[{"price":67671.94,"qty":0.00000000},{"price":67671.92,"qty":0.59080704}],"asks":[],"checksum":1439314005,"timestamp":"2024-06-01T18:07:05.819575Z"}]}
{"channel":"book","type":"update","data":[{"symbol":"BTC/USDC","bids":[{"price":67682.04,"qty":0.00000000},{"price":67671.91,"qty":0.01820000}],"asks":[],"checksum":3428861867,"timestamp":"2024-06-01T18:07:05.819690Z"}]}
{"channel":"book","type":"update","data":[{"symbol":"BTC/USDC","bids":[{"price":67682.06,"qty":0.69241800}],"asks":[],"checksum":4066822146,"timestamp":"2024-06-01T18:07:05.820851Z"}]}
{"channel":"book","type":"update","data":[{"symbol":"BTC/USDC","bids":[{"price":67679.32,"qty":1.21677385}],"asks":[],"checksum":3284000187,"timestamp":"2024-06-01T18:07:05.820894Z"}]}
{"channel":"book","type":"update","data":[{"symbol":"BTC/USDC","bids":[{"price":67692.92,"qty":0.01820000}],"asks":[],"checksum":2270141482,"timestamp":"2024-06-01T18:07:05.820918Z"}]}
{"channel":"book","type":"update","data":[{"symbol":"BTC/USDC","bids":[],"asks":[{"price":67704.98,"qty":0.00000000},{"price":67727.49,"qty":1.09715923}],"checksum":216978820,"timestamp":"2024-06-01T18:07:05.823671Z"}]}
{"channel":"book","type":"update","data":[{"symbol":"BTC/USDC","bids":[{"price":67692.92,"qty":0.00000000},{"price":67671.95,"qty":0.01950418}],"asks":[],"checksum":1209832469,"timestamp":"2024-06-01T18:07:05.824459Z"}]}
{"channel":"book","type":"update","data":[{"symbol":"BTC/USDC","bids":[],"asks":[{"price":67710.79,"qty":0.03640000}],"checksum":2109870209,"timestamp":"2024-06-01T18:07:05.826888Z"}]}
{"channel":"book","type":"update","data":[{"symbol":"BTC/USDC","bids":[],"asks":[{"price":67727.40,"qty":0.00000000},{"price":67729.76,"qty":0.01820000}],"checksum":3943632222,"timestamp":"2024-06-01T18:07:06.324582Z"}]}
{"channel":"book","type":"update","data":[{"symbol":"BTC/USDC","bids":[],"asks":[{"price":67723.82,"qty":0.00000000},{"price":67730.18,"qty":0.02233000}],"checksum":2112217048,"timestamp":"2024-06-01T18:07:06.324613Z"}]}
{"channel":"book","type":"update","data":[{"symbol":"BTC/USDC","bids":[],"asks":[{"price":67723.80,"qty":1.30752089}],"checksum":878829719,"timestamp":"2024-06-01T18:07:06.330326Z"}]}
