{"channel":"book","type":"snapshot","data":[{"symbol":"DOT/GBP","bids":[{"price":5.5599,"qty":9.00000000},{"price":5.5595,"qty":14.17854757},{"price":5.5585,"qty":35.28495495},{"price":5.5566,"qty":75.51904529},{"price":5.5565,"qty":49.41702453},{"price":5.5539,"qty":115.03000000},{"price":5.5536,"qty":147.06141293},{"price":5.5524,"qty":26.41196980},{"price":5.5522,"qty":252.41000000},{"price":5.5497,"qty":47.85093369}],"asks":[{"price":5.5653,"qty":31.74952189},{"price":5.5654,"qty":9.00000000},{"price":5.5658,"qty":26.41196980},{"price":5.5661,"qty":35.23729984},{"price":5.5667,"qty":646.84754856},{"price":5.5698,"qty":49.29992727},{"price":5.5731,"qty":47.85093369},{"price":5.5738,"qty":155.13765357},{"price":5.5739,"qty":100.00000000},{"price":5.5745,"qty":147.04173577}],"checksum":2502043527}]}
{"channel":"book","type":"update","data":[{"symbol":"DOT/GBP","bids":[{"price":5.5595,"qty":0.00000000},{"price":5.5494,"qty":70.68592550}],"asks":[],"checksum":260663375,"timestamp":"2024-06-01T18:06:45.847823Z"}]}
{"channel":"book","type":"update","data":[{"symbol":"DOT/GBP","bids":[],"asks":[{"price":5.5667,"qty":0.00000000},{"price":5.5756,"qty":77.74457776}],"checksum":1262918972,"timestamp":"2024-06-01T18:06:45.849136Z"}]}
{"channel":"book","type":"update","data":[{"symbol":"DOT/GBP","bids":[{"price":5.5599,"qty":0.00000000},{"price":5.5491,"qty":119.15000000}],"asks":[],"checksum":4020448961,"timestamp":"2024-06-01T18:06:45.850594Z"}]}
{"channel":"book","type":"update","data":[{"symbol":"DOT/GBP","bids":[{"price":5.5589,"qty":9.00000000}],"asks":[],"checksum":1542337794,"timestamp":"2024-06-01T18:06:45.850830Z"}]}
{"channel":"book","type":"update","data":[{"symbol":"DOT/GBP","bids":[{"price":5.5586,"qty":31.74254542}],"asks":[],"checksum":1374291426,"timestamp":"2024-06-01T18:06:45.853413Z"}]}
{"channel":"book","type":"update","data":[{"symbol":"DOT/GBP","bids":[{"price":5.5590,"qty":31.74254542}],"asks":[],"checksum":1321672460,"timestamp":"2024-06-01T18:06:45.853604Z"}]}
{"channel":"book","type":"update","data":[{"symbol":"DOT/GBP","bids":[],"asks":[{"price":5.5659,"qty":699.79004856}],"checksum":599771073,"timestamp":"2024-06-01T18:06:45.853679Z"}]}
{"channel":"book","type":"update","data":[{"symbol":"DOT/GBP","bids":[{"price":5.5595,"qty":72.28396553}],"asks":[],"checksum":4205557210,"timestamp":"2024-06-01T18:06:45.853717Z"}]}
{"channel":"book","type":"update","data":[{"symbol":"DOT/GBP","bids":[{"price":5.5586,"qty":0.00000000},{"price":5.5522,"qty":252.41000000}],"asks":[],"checksum":3505794363,"timestamp":"2024-06-01T18:06:45.856045Z"}]}
{"channel":"book","type":"update","data":[{"symbol":"DOT/GBP","bids":[{"price":5.5589,"qty":0.00000000},{"price":5.5497,"qty":47.85093369}],"asks":[],"checksum":1156430797,"timestamp":"2024-06-01T18:06:45.856405Z"}]}
{"channel":"book","type":"update","data":[{"symbol":"DOT/GBP","bids":[{"price":5.5594,"qty":9.00000000}],"asks":[],"checksum":563523186,"timestamp":"2024-06-01T18:06:45.856718Z"}]}
{"channel":"book","type":"update","data":[{"symbol":"DOT/GBP","bids":[{"price":5.5594,"qty":0.00000000},{"price":5.5497,"qty":47.85093369}],"asks":[],"checksum":1156430797,"timestamp":"2024-06-01T18:06:45.856821Z"}]}
{"channel":"book","type":"update","data":[{"symbol":"DOT/GBP","bids":[{"price":5.5597,"qty":9.00000000}],"asks":[],"checksum":1736893483,"timestamp":"2024-06-01T18:06:45.856969Z"}]}
{"channel":"book","type":"update","data":[{"symbol":"DOT/GBP","bids":[{"price":5.5597,"qty":40.73898613}],"asks":[],"checksum":581206031,"timestamp":"2024-06-01T18:06:52.204832Z"}]}
{"channel":"book","type":"update","data":[{"symbol":"DOT/GBP","bids":[{"price":5.5590,"qty":0.00000000},{"price":5.5497,"qty":47.85093369}],"asks":[],"checksum":1297856005,"timestamp":"2024-06-01T18:06:52.496552Z"}]}
{"channel":"book","type":"update","data":[{"symbol":"DOT/GBP","bids":[{"price":5.5597,"qty":9.00000000}],"asks":[],"checksum":142201377,"timestamp":"2024-06-01T18:06:53.726915Z"}]}
{"channel":"book","type":"update","data":[{"symbol":"DOT/GBP","bids":[],"asks":[{"price":5.5654,"qty":0.00000000},{"price":5.5756,"qty":77.74457776}],"checksum":4275170050,"timestamp":"2024-06-01T18:06:55.009226Z"}]}
{"channel":"book","type":"update","data":[{"symbol":"DOT/GBP","bids":[],"asks":[{"price":5.5652,"qty":9.00000000}],"checksum":1525373606,"timestamp":"2024-06-01T18:06:55.009483Z"}]}
{"channel":"book","type":"update","data":[{"symbol":"DOT/GBP","bids":[],"asks":[{"price":5.5651,"qty":31.74467866}],"checksum":2465256245,"timestamp":"2024-06-01T18:06:55.012439Z"}]}
{"channel":"book","type":"update","data":[{"symbol":"DOT/GBP","bids":[],"asks":[{"price":5.5653,"qty":0.00000000},{"price":5.5745,"qty":147.04173577}],"checksum":896457390,"timestamp":"2024-06-01T18:06:55.015096Z"}]}
{"channel":"book","type":"update","data":[{"symbol":"DOT/GBP","bids":[],"asks":[{"price":5.5730,"qty":77.74457776}],"checksum":1758287585,"timestamp":"2024-06-01T18:07:03.370489Z"}]}
{"channel":"book","type":"update","data":[{"symbol":"DOT/GBP","bids":[],"asks":[{"price":5.5722,"qty":147.10596491}],"checksum":2242251901,"timestamp":"2024-06-01T18:07:05.549118Z"}]}
{"channel":"book","type":"update","data":[{"symbol":"DOT/GBP","bids":[],"asks":[{"price":5.5738,"qty":0.00000000},{"price":5.5739,"qty":100.00000000}],"checksum":2940070627,"timestamp":"2024-06-01T18:07:05.566795Z"}]}
{"channel":"book","type":"update","data":[{"symbol":"DOT/GBP","bids":[],"asks":[{"price":5.5721,"qty":155.13765357}],"checksum":3717432616,"timestamp":"2024-06-01T18:07:05.567115Z"}]}
{"channel":"book","type":"update","data":[{"symbol":"DOT/GBP","bids":[],"asks":[{"price":5.5730,"qty":0.00000000},{"price":5.5739,"qty":100.00000000},{"price":5.5720,"qty":77.74457776}],"checksum":3135978414,"timestamp":"2024-06-01T18:07:05.613216Z"}]}
{"channel":"book","type":"update","data":[{"symbol":"DOT/GBP","bids":[{"price":5.5598,"qty":31.73872723}],"asks":[],"checksum":3871571567,"timestamp":"2024-06-01T18:07:06.648568Z"}]}
{"channel":"book","type":"update","data":[{"symbol":"DOT/GBP","bids":[{"price":5.5601,"qty":9.00000000}],"asks":[],"checksum":1047683337,"timestamp":"2024-06-01T18:07:06.652074Z"}]}
{"channel":"book","type":"update","data":[{"symbol":"DOT/GBP","bids":[{"price":5.5597,"qty":0.00000000},{"price":5.5522,"qty":252.41000000}],"asks":[],"checksum":1162627347,"timestamp":"2024-06-01T18:07:06.652159Z"}]}
{"channel":"book","type":"update","data":[{"symbol":"DOT/GBP","bids":[{"price":5.5595,"qty":0.00000000},{"price":5.5497,"qty":47.85093369}],"asks":[],"checksum":482235363,"timestamp":"2024-06-01T18:07:06.652599Z"}]}
{"channel":"book","type":"update","data":[{"symbol":"DOT/GBP","bids":[],"asks":[{"price":5.5659,"qty":0.00000000},{"price":5.5739,"qty":100.00000000}],"checksum":1421525656,"timestamp":"2024-06-01T18:07:06.654968Z"}]}
{"channel":"book","type":"update","data":[{"symbol":"DOT/GBP","bids":[{"price":5.5595,"qty":152.96705668}],"asks":[],"checksum":642768072,"timestamp":"2024-06-01T18:07:06.657265Z"}]}
{"channel":"book","type":"update","data":[{"symbol":"DOT/GBP","bids":[],"asks":[{"price":5.5659,"qty":485.64754856}],"checksum":2689096208,"timestamp":"2024-06-01T18:07:06.659660Z"}]}
{"channel":"book","type":"update","data":[{"symbol":"DOT/GBP","bids":[],"asks":[{"price":5.5721,"qty":0.00000000},{"price":5.5739,"qty":100.00000000}],"checksum":2979742698,"timestamp":"2024-06-01T18:07:06.661600Z"}]}
{"channel":"book","type":"update","data":[{"symbol":"DOT/GBP","bids":[],"asks":[{"price":5.5719,"qty":155.13765357}],"checksum":1235127638,"timestamp":"2024-06-01T18:07:06.663919Z"}]}
{"channel":"book","type":"update","data":[{"symbol":"DOT/GBP","bids":[{"price":5.5602,"qty":31.73493754}],"asks":[],"checksum":896871457,"timestamp":"2024-06-01T18:07:06.678837Z"}]}
{"channel":"book","type":"update","data":[{"symbol":"DOT/GBP","bids":[{"price":5.5598,"qty":0.00000000},{"price":5.5522,"qty":252.41000000}],"asks":[],"checksum":704408147,"timestamp":"2024-06-01T18:07:06.681811Z"}]}
{"channel":"book","type":"update","data":[{"symbol":"DOT/GBP","bids":[{"price":5.5603,"qty":9.00000000}],"asks":[],"checksum":935798136,"timestamp":"2024-06-01T18:07:06.682270Z"}]}
{"channel":"book","type":"update","data":[{"symbol":"DOT/GBP","bids":[{"price":5.5601,"qty":0.00000000},{"price":5.5522,"qty":252.41000000}],"asks":[],"checksum":3525866887,"timestamp":"2024-06-01T18:07:06.682312Z"}]}
{"channel":"book","type":"update","data":[{"symbol":"DOT/GBP","bids":[{"price":5.5604,"qty":31.73397808}],"asks":[],"checksum":1399256974,"timestamp":"2024-06-01T18:07:06.690443Z"}]}
{"channel":"book","type":"update","data":[{"symbol":"DOT/GBP","bids":[{"price":5.5602,"qty":0.00000000},{"price":5.5522,"qty":252.41000000}],"asks":[],"checksum":794286143,"timestamp":"2024-06-01T18:07:06.691401Z"}]}
{"channel":"book","type":"update","data":[{"symbol":"DOT/GBP","bids":[{"price":5.5603,"qty":0.00000000},{"price":5.5497,"qty":47.85093369}],"asks":[],"checksum":1390207257,"timestamp":"2024-06-01T18:07:06.693588Z"}]}
{"channel":"book","type":"update","data":[{"symbol":"DOT/GBP","bids":[{"price":5.5605,"qty":9.00000000}],"asks":[],"checksum":4022499487,"timestamp":"2024-06-01T18:07:06.693915Z"}]}
{"channel":"book","type":"update","data":[{"symbol":"DOT/GBP","bids":[{"price":5.5606,"qty":31.73201768}],"asks":[],"checksum":2692904371,"timestamp":"2024-06-01T18:07:06.696889Z"}]}
{"channel":"book","type":"update","data":[{"symbol":"DOT/GBP","bids":[{"price":5.5604,"qty":0.00000000},{"price":5.5522,"qty":252.41000000}],"asks":[],"checksum":1790565492,"timestamp":"2024-06-01T18:07:06.699980Z"}]}
{"channel":"book","type":"update","data":[{"symbol":"DOT/GBP","bids":[],"asks":[{"price":5.5722,"qty":0.00000000},{"price":5.5739,"qty":100.00000000}],"checksum":465350215,"timestamp":"2024-06-01T18:07:06.731320Z"}]}
{"channel":"book","type":"update","data":[{"symbol":"DOT/GBP","bids":[{"price":5.5605,"qty":0.00000000},{"price":5.5497,"qty":47.85093369}],"asks":[],"checksum":1497507958,"timestamp":"2024-06-01T18:07:06.751984Z"}]}
{"channel":"book","type":"update","data":[{"symbol":"DOT/GBP","bids":[{"price":5.5607,"qty":9.00000000}],"asks":[],"checksum":1888544032,"timestamp":"2024-06-01T18:07:06.752096Z"}]}
{"channel":"book","type":"update","data":[{"symbol":"DOT/GBP","bids":[{"price":5.5608,"qty":31.73220132}],"asks":[],"checksum":1300407343,"timestamp":"2024-06-01T18:07:06.755224Z"}]}
{"channel":"book","type":"update","data":[{"symbol":"DOT/GBP","bids":[{"price":5.5606,"qty":0.00000000},{"price":5.5522,"qty":252.41000000}],"asks":[],"checksum":308559916,"timestamp":"2024-06-01T18:07:06.758076Z"}]}
