{"channel":"book","type":"snapshot","data":[{"symbol":"DOT/USD","bids":[{"price":7.0920,"qty":323.00000000},{"price":7.0898,"qty":321.64683178},{"price":7.0888,"qty":169.09000000},{"price":7.0886,"qty":352.67860094},{"price":7.0880,"qty":75.00000000},{"price":7.0874,"qty":1786.94800000},{"price":7.0873,"qty":3526.00031984},{"price":7.0871,"qty":164.76423866},{"price":7.0866,"qty":705.55001829},{"price":7.0860,"qty":1004.42148087}],"asks":[{"price":7.0921,"qty":1470.14358687},{"price":7.0922,"qty":291.86609000},{"price":7.0925,"qty":705.20006397},{"price":7.0928,"qty":75.77219192},{"price":7.0929,"qty":4.29474228},{"price":7.0930,"qty":33.59571380},{"price":7.0932,"qty":1027.90431644},{"price":7.0936,"qty":75.00000000},{"price":7.0937,"qty":2.54372019},{"price":7.0938,"qty":2.54372019}],"checksum":3533495589}]}
{"channel":"book","type":"update","data":[{"symbol":"DOT/USD","bids":[{"price":7.0888,"qty":94.09000000}],"asks":[],"checksum":2289131152,"timestamp":"2024-06-01T18:06:44.083626Z"}]}
{"channel":"book","type":"update","data":[{"symbol":"DOT/USD","bids":[{"price":7.0888,"qty":169.09000000}],"asks":[],"checksum":3533495589,"timestamp":"2024-06-01T18:06:44.312094Z"}]}
{"channel":"book","type":"update","data":[{"symbol":"DOT/USD","bids":[],"asks":[{"price":7.0921,"qty":764.81332362}],"checksum":589991937,"timestamp":"2024-06-01T18:06:47.482069Z"}]}
{"channel":"book","type":"update","data":[{"symbol":"DOT/USD","bids":[],"asks":[{"price":7.0921,"qty":664.81332362}],"checksum":375349397,"timestamp":"2024-06-01T18:06:48.930203Z"}]}
{"channel":"book","type":"update","data":[{"symbol":"DOT/USD","bids":[],"asks":[{"price":7.0921,"qty":700.07011574}],"checksum":3322793232,"timestamp":"2024-06-01T18:06:48.934547Z"}]}
{"channel":"book","type":"update","data":[{"symbol":"DOT/USD","bids":[],"asks":[{"price":7.0921,"qty":800.07011574}],"checksum":1016765469,"timestamp":"2024-06-01T18:06:49.388347Z"}]}
{"channel":"book","type":"update","data":[{"symbol":"DOT/USD","bids":[],"asks":[{"price":7.0921,"qty":1505.40037899}],"checksum":2849085980,"timestamp":"2024-06-01T18:06:50.134877Z"}]}
{"channel":"book","type":"update","data":[{"symbol":"DOT/USD","bids":[],"asks":[{"price":7.0937,"qty":0.00000000},{"price":7.0940,"qty":5.08744038}],"checksum":1083412111,"timestamp":"2024-06-01T18:06:52.028041Z"}]}
{"channel":"book","type":"update","data":[{"symbol":"DOT/USD","bids":[],"asks":[{"price":7.0940,"qty":2.54372019}],"checksum":4263865524,"timestamp":"2024-06-01T18:06:52.028110Z"}]}
{"channel":"book","type":"update","data":[{"symbol":"DOT/USD","bids":[],"asks":[{"price":7.0940,"qty":0.00000000},{"price":7.0942,"qty":24.83760501}],"checksum":3164505711,"timestamp":"2024-06-01T18:06:52.028210Z"}]}
{"channel":"book","type":"update","data":[{"symbol":"DOT/USD","bids":[],"asks":[{"price":7.0940,"qty":2.54372019}],"checksum":4263865524,"timestamp":"2024-06-01T18:06:52.241402Z"}]}
{"channel":"book","type":"update","data":[{"symbol":"DOT/USD","bids":[],"asks":[{"price":7.0940,"qty":5.08744038}],"checksum":1083412111,"timestamp":"2024-06-01T18:06:52.342330Z"}]}
{"channel":"book","type":"update","data":[{"symbol":"DOT/USD","bids":[],"asks":[{"price":7.0937,"qty":2.54372019}],"checksum":2849085980,"timestamp":"2024-06-01T18:06:52.451896Z"}]}
{"channel":"book","type":"update","data":[{"symbol":"DOT/USD","bids":[],"asks":[{"price":7.0938,"qty":0.00000000},{"price":7.0940,"qty":5.08744038}],"checksum":2366867045,"timestamp":"2024-06-01T18:06:52.491430Z"}]}
{"channel":"book","type":"update","data":[{"symbol":"DOT/USD","bids":[{"price":7.0875,"qty":3526.55688202}],"asks":[],"checksum":3367784202,"timestamp":"2024-06-01T18:06:53.687990Z"}]}
{"channel":"book","type":"update","data":[{"symbol":"DOT/USD","bids":[{"price":7.0874,"qty":0.00000000},{"price":7.0860,"qty":1004.42148087},{"price":7.0876,"qty":1786.94800000}],"asks":[],"checksum":117881671,"timestamp":"2024-06-01T18:06:53.691146Z"}]}
{"channel":"book","type":"update","data":[{"symbol":"DOT/USD","bids":[{"price":7.0888,"qty":94.09000000}],"asks":[],"checksum":2293705611,"timestamp":"2024-06-01T18:06:54.232965Z"}]}
{"channel":"book","type":"update","data":[{"symbol":"DOT/USD","bids":[],"asks":[{"price":7.0938,"qty":2.54372019}],"checksum":4261999736,"timestamp":"2024-06-01T18:06:54.238360Z"}]}
{"channel":"book","type":"update","data":[{"symbol":"DOT/USD","bids":[{"price":7.0888,"qty":169.09000000}],"asks":[],"checksum":600090430,"timestamp":"2024-06-01T18:06:54.249599Z"}]}
{"channel":"book","type":"update","data":[{"symbol":"DOT/USD","bids":[{"price":7.0888,"qty":94.09000000}],"asks":[],"checksum":4261999736,"timestamp":"2024-06-01T18:06:54.277713Z"}]}
{"channel":"book","type":"update","data":[{"symbol":"DOT/USD","bids":[{"price":7.0871,"qty":75.00000000}],"asks":[],"checksum":1618105646,"timestamp":"2024-06-01T18:06:54.297237Z"}]}
{"channel":"book","type":"update","data":[{"symbol":"DOT/USD","bids":[{"price":7.0888,"qty":0.00000000},{"price":7.0860,"qty":1004.42148087}],"asks":[],"checksum":1757592104,"timestamp":"2024-06-01T18:06:54.414090Z"}]}
{"channel":"book","type":"update","data":[{"symbol":"DOT/USD","bids":[{"price":7.0868,"qty":94.04000000}],"asks":[],"checksum":248180201,"timestamp":"2024-06-01T18:06:54.416812Z"}]}
{"channel":"book","type":"update","data":[{"symbol":"DOT/USD","bids":[{"price":7.0868,"qty":183.80803858}],"asks":[],"checksum":190467273,"timestamp":"2024-06-01T18:06:54.417767Z"}]}
{"channel":"book","type":"update","data":[{"symbol":"DOT/USD","bids":[{"price":7.0888,"qty":75.00000000}],"asks":[],"checksum":1544803498,"timestamp":"2024-06-01T18:06:54.533384Z"}]}
{"channel":"book","type":"update","data":[{"symbol":"DOT/USD","bids":[{"price":7.0888,"qty":0.00000000},{"price":7.0866,"qty":705.55001829}],"asks":[],"checksum":190467273,"timestamp":"2024-06-01T18:06:54.719168Z"}]}
{"channel":"book","type":"update","data":[{"symbol":"DOT/USD","bids":[{"price":7.0888,"qty":75.00000000}],"asks":[],"checksum":1544803498,"timestamp":"2024-06-01T18:06:54.926843Z"}]}
{"channel":"book","type":"update","data":[{"symbol":"DOT/USD","bids":[{"price":7.0888,"qty":0.00000000},{"price":7.0866,"qty":705.55001829}],"asks":[],"checksum":190467273,"timestamp":"2024-06-01T18:06:54.962641Z"}]}
{"channel":"book","type":"update","data":[{"symbol":"DOT/USD","bids":[{"price":7.0888,"qty":75.00000000}],"asks":[],"checksum":1544803498,"timestamp":"2024-06-01T18:06:56.790471Z"}]}
{"channel":"book","type":"update","data":[{"symbol":"DOT/USD","bids":[],"asks":[{"price":7.0931,"qty":2.82101524}],"checksum":2786033921,"timestamp":"2024-06-01T18:06:57.688656Z"}]}
{"channel":"book","type":"update","data":[{"symbol":"DOT/USD","bids":[{"price":7.0888,"qty":0.00000000},{"price":7.0866,"qty":705.55001829}],"asks":[],"checksum":1252272892,"timestamp":"2024-06-01T18:06:58.243592Z"}]}
{"channel":"book","type":"update","data":[{"symbol":"DOT/USD","bids":[{"price":7.0868,"qty":94.04000000}],"asks":[],"checksum":4107712578,"timestamp":"2024-06-01T18:06:58.272258Z"}]}
{"channel":"book","type":"update","data":[{"symbol":"DOT/USD","bids":[{"price":7.0868,"qty":183.80803858}],"asks":[],"checksum":1252272892,"timestamp":"2024-06-01T18:06:58.392030Z"}]}
{"channel":"book","type":"update","data":[{"symbol":"DOT/USD","bids":[{"price":7.0868,"qty":89.76803858}],"asks":[],"checksum":2698636095,"timestamp":"2024-06-01T18:06:59.143226Z"}]}
{"channel":"book","type":"update","data":[{"symbol":"DOT/USD","bids":[{"price":7.0888,"qty":75.00000000}],"asks":[],"checksum":2323371974,"timestamp":"2024-06-01T18:06:59.424905Z"}]}
{"channel":"book","type":"update","data":[{"symbol":"DOT/USD","bids":[{"price":7.0888,"qty":0.00000000},{"price":7.0866,"qty":705.55001829}],"asks":[],"checksum":2698636095,"timestamp":"2024-06-01T18:06:59.930552Z"}]}
{"channel":"book","type":"update","data":[{"symbol":"DOT/USD","bids":[],"asks":[{"price":7.0931,"qty":0.00000000},{"price":7.0938,"qty":2.54372019}],"checksum":1522908820,"timestamp":"2024-06-01T18:07:00.207868Z"}]}
{"channel":"book","type":"update","data":[{"symbol":"DOT/USD","bids":[],"asks":[{"price":7.0931,"qty":5.57315803}],"checksum":308846222,"timestamp":"2024-06-01T18:07:00.208509Z"}]}
{"channel":"book","type":"update","data":[{"symbol":"DOT/USD","bids":[{"price":7.0888,"qty":75.00000000}],"asks":[],"checksum":2248494719,"timestamp":"2024-06-01T18:07:02.658089Z"}]}
{"channel":"book","type":"update","data":[{"symbol":"DOT/USD","bids":[],"asks":[{"price":7.0931,"qty":0.00000000},{"price":7.0938,"qty":2.54372019}],"checksum":2568167384,"timestamp":"2024-06-01T18:07:02.835616Z"}]}
{"channel":"book","type":"update","data":[{"symbol":"DOT/USD","bids":[],"asks":[{"price":7.0931,"qty":8.32530083}],"checksum":4162458349,"timestamp":"2024-06-01T18:07:02.836863Z"}]}
{"channel":"book","type":"update","data":[{"symbol":"DOT/USD","bids":[],"asks":[{"price":7.0931,"qty":0.00000000},{"price":7.0938,"qty":2.54372019}],"checksum":2568167384,"timestamp":"2024-06-01T18:07:05.391048Z"}]}
{"channel":"book","type":"update","data":[{"symbol":"DOT/USD","bids":[],"asks":[{"price":7.0921,"qty":1405.37288909}],"checksum":613638996,"timestamp":"2024-06-01T18:07:06.588284Z"}]}
{"channel":"book","type":"update","data":[{"symbol":"DOT/USD","bids":[],"asks":[{"price":7.0921,"qty":1330.37288909}],"checksum":1058707065,"timestamp":"2024-06-01T18:07:06.652121Z"}]}
{"channel":"book","type":"update","data":[{"symbol":"DOT/USD","bids":[],"asks":[{"price":7.0938,"qty":0.00000000},{"price":7.0940,"qty":271.22748894}],"checksum":3136766037,"timestamp":"2024-06-01T18:07:06.654668Z"}]}
{"channel":"book","type":"update","data":[{"symbol":"DOT/USD","bids":[],"asks":[{"price":7.0940,"qty":268.68376875}],"checksum":1639120772,"timestamp":"2024-06-01T18:07:06.655557Z"}]}
{"channel":"book","type":"update","data":[{"symbol":"DOT/USD","bids":[],"asks":[{"price":7.0940,"qty":266.14004856}],"checksum":424369078,"timestamp":"2024-06-01T18:07:06.655592Z"}]}
{"channel":"book","type":"update","data":[{"symbol":"DOT/USD","bids":[],"asks":[{"price":7.0937,"qty":0.00000000},{"price":7.0942,"qty":19.33344188}],"checksum":3983123413,"timestamp":"2024-06-01T18:07:06.656236Z"}]}
{"channel":"book","type":"update","data":[{"symbol":"DOT/USD","bids":[],"asks":[{"price":7.0921,"qty":1405.37288909}],"checksum":542332929,"timestamp":"2024-06-01T18:07:06.656375Z"}]}
{"channel":"book","type":"update","data":[{"symbol":"DOT/USD","bids":[{"price":7.0877,"qty":3526.70102051}],"asks":[],"checksum":3068372259,"timestamp":"2024-06-01T18:07:06.658675Z"}]}
{"channel":"book","type":"update","data":[{"symbol":"DOT/USD","bids":[{"price":7.0904,"qty":75.00000000}],"asks":[],"checksum":4087268801,"timestamp":"2024-06-01T18:07:06.661493Z"}]}
{"channel":"book","type":"update","data":[{"symbol":"DOT/USD","bids":[{"price":7.0876,"qty":0.00000000},{"price":7.0871,"qty":75.00000000},{"price":7.0878,"qty":1786.94800000}],"asks":[],"checksum":1039071033,"timestamp":"2024-06-01T18:07:06.662093Z"}]}
{"channel":"book","type":"update","data":[{"symbol":"DOT/USD","bids":[],"asks":[{"price":7.0921,"qty":1370.11609697}],"checksum":1374675741,"timestamp":"2024-06-01T18:07:06.665969Z"}]}
{"channel":"book","type":"update","data":[{"symbol":"DOT/USD","bids":[{"price":7.0873,"qty":0.00000000},{"price":7.0871,"qty":75.00000000}],"asks":[],"checksum":4206466233,"timestamp":"2024-06-01T18:07:06.672974Z"}]}
{"channel":"book","type":"update","data":[{"symbol":"DOT/USD","bids":[],"asks":[{"price":7.0932,"qty":704.90431644}],"checksum":939314538,"timestamp":"2024-06-01T18:07:06.678933Z"}]}
{"channel":"book","type":"update","data":[{"symbol":"DOT/USD","bids":[],"asks":[{"price":7.0921,"qty":1306.63516306}],"checksum":1788669926,"timestamp":"2024-06-01T18:07:06.679326Z"}]}
{"channel":"book","type":"update","data":[{"symbol":"DOT/USD","bids":[{"price":7.0904,"qty":0.00000000},{"price":7.0869,"qty":883.05746218}],"asks":[],"checksum":3928807119,"timestamp":"2024-06-01T18:07:06.690140Z"}]}
{"channel":"book","type":"update","data":[{"symbol":"DOT/USD","bids":[{"price":7.0907,"qty":321.64683178}],"asks":[],"checksum":1846990885,"timestamp":"2024-06-01T18:07:06.694128Z"}]}
{"channel":"book","type":"update","data":[{"symbol":"DOT/USD","bids":[],"asks":[{"price":7.0930,"qty":0.00000000},{"price":7.0943,"qty":705.60000000}],"checksum":1926395096,"timestamp":"2024-06-01T18:07:06.697867Z"}]}
{"channel":"book","type":"update","data":[{"symbol":"DOT/USD","bids":[{"price":7.0904,"qty":75.00000000}],"asks":[],"checksum":1211795416,"timestamp":"2024-06-01T18:07:06.703860Z"}]}
{"channel":"book","type":"update","data":[{"symbol":"DOT/USD","bids":[],"asks":[{"price":7.0921,"qty":1406.66265296}],"checksum":2490822451,"timestamp":"2024-06-01T18:07:06.705959Z"}]}
{"channel":"book","type":"update","data":[{"symbol":"DOT/USD","bids":[{"price":7.0898,"qty":0.00000000},{"price":7.0871,"qty":75.00000000}],"asks":[],"checksum":1896103413,"timestamp":"2024-06-01T18:07:06.719787Z"}]}
{"channel":"book","type":"update","data":[{"symbol":"DOT/USD","bids":[],"asks":[{"price":7.0921,"qty":1306.63516306}],"checksum":3949009371,"timestamp":"2024-06-01T18:07:06.730111Z"}]}
{"channel":"book","type":"update","data":[{"symbol":"DOT/USD","bids":[{"price":7.0886,"qty":0.00000000},{"price":7.0869,"qty":883.05746218}],"asks":[],"checksum":1120825474,"timestamp":"2024-06-01T18:07:06.738448Z"}]}
{"channel":"book","type":"update","data":[{"symbol":"DOT/USD","bids":[],"asks":[{"price":7.0921,"qty":954.13026325}],"checksum":1768332099,"timestamp":"2024-06-01T18:07:06.738535Z"}]}
{"channel":"book","type":"update","data":[{"symbol":"DOT/USD","bids":[],"asks":[{"price":7.0932,"qty":0.00000000},{"price":7.0944,"qty":75.00000000}],"checksum":1625866557,"timestamp":"2024-06-01T18:07:06.738561Z"}]}
{"channel":"book","type":"update","data":[{"symbol":"DOT/USD","bids":[],"asks":[{"price":7.0929,"qty":356.76289254}],"checksum":2787394445,"timestamp":"2024-06-01T18:07:06.744513Z"}]}
{"channel":"book","type":"update","data":[{"symbol":"DOT/USD","bids":[{"price":7.0895,"qty":352.63065619}],"asks":[],"checksum":1142668708,"timestamp":"2024-06-01T18:07:06.744530Z"}]}
{"channel":"book","type":"update","data":[{"symbol":"DOT/USD","bids":[{"price":7.0877,"qty":4232.14314300}],"asks":[],"checksum":496695125,"timestamp":"2024-06-01T18:07:06.744743Z"}]}
{"channel":"book","type":"update","data":[{"symbol":"DOT/USD","bids":[],"asks":[{"price":7.0943,"qty":0.00000000},{"price":7.0947,"qty":709.46888672}],"checksum":4175890202,"timestamp":"2024-06-01T18:07:06.752454Z"}]}
{"channel":"book","type":"update","data":[{"symbol":"DOT/USD","bids":[],"asks":[{"price":7.0940,"qty":299.73576236}],"checksum":3571602664,"timestamp":"2024-06-01T18:07:06.791701Z"}]}
{"channel":"book","type":"update","data":[{"symbol":"DOT/USD","bids":[],"asks":[{"price":7.0921,"qty":1054.15775315}],"checksum":947389627,"timestamp":"2024-06-01T18:07:06.850058Z"}]}
{"channel":"book","type":"update","data":[{"symbol":"DOT/USD","bids":[{"price":7.0904,"qty":0.00000000},{"price":7.0869,"qty":883.05746218}],"asks":[],"checksum":4231571764,"timestamp":"2024-06-01T18:07:06.850147Z"}]}
{"channel":"book","type":"update","data":[{"symbol":"DOT/USD","bids":[],"asks":[{"price":7.0947,"qty":712.01260691}],"checksum":1995877921,"timestamp":"2024-06-01T18:07:06.855118Z"}]}
{"channel":"book","type":"update","data":[{"symbol":"DOT/USD","bids":[{"price":7.0896,"qty":75.00000000}],"asks":[],"checksum":3293947753,"timestamp":"2024-06-01T18:07:06.855791Z"}]}
{"channel":"book","type":"update","data":[{"symbol":"DOT/USD","bids":[{"price":7.0895,"qty":0.00000000},{"price":7.0869,"qty":883.05746218}],"asks":[],"checksum":1871702443,"timestamp":"2024-06-01T18:07:06.878278Z"}]}
{"channel":"book","type":"update","data":[{"symbol":"DOT/USD","bids":[],"asks":[{"price":7.0937,"qty":323.00000000}],"checksum":1201338747,"timestamp":"2024-06-01T18:07:06.965946Z"}]}
{"channel":"book","type":"update","data":[{"symbol":"DOT/USD","bids":[{"price":7.0884,"qty":33.59571380}],"asks":[],"checksum":2622564140,"timestamp":"2024-06-01T18:07:07.028802Z"}]}
{"channel":"book","type":"update","data":[{"symbol":"DOT/USD","bids":[],"asks":[{"price":7.0942,"qty":0.00000000},{"price":7.0947,"qty":712.01260691}],"checksum":199100424,"timestamp":"2024-06-01T18:07:07.897506Z"}]}
{"channel":"book","type":"update","data":[{"symbol":"DOT/USD","bids":[{"price":7.0896,"qty":0.00000000},{"price":7.0869,"qty":883.05746218}],"asks":[],"checksum":2456872374,"timestamp":"2024-06-01T18:07:08.293655Z"}]}
{"channel":"book","type":"update","data":[{"symbol":"DOT/USD","bids":[{"price":7.0869,"qty":0.00000000},{"price":7.0868,"qty":89.76803858},{"price":7.0870,"qty":883.05746218}],"asks":[],"checksum":3528394402,"timestamp":"2024-06-01T18:07:08.297138Z"}]}
{"channel":"book","type":"update","data":[{"symbol":"DOT/USD","bids":[{"price":7.0880,"qty":168.94000000}],"asks":[],"checksum":2729187040,"timestamp":"2024-06-01T18:07:08.604189Z"}]}
{"channel":"book","type":"update","data":[{"symbol":"DOT/USD","bids":[{"price":7.0901,"qty":352.60088554}],"asks":[],"checksum":1024994475,"timestamp":"2024-06-01T18:07:08.633125Z"}]}
{"channel":"book","type":"update","data":[{"symbol":"DOT/USD","bids":[{"price":7.0884,"qty":0.00000000},{"price":7.0870,"qty":883.05746218}],"asks":[],"checksum":1787215900,"timestamp":"2024-06-01T18:07:08.816115Z"}]}
{"channel":"book","type":"update","data":[{"symbol":"DOT/USD","bids":[{"price":7.0888,"qty":0.00000000},{"price":7.0868,"qty":89.76803858}],"asks":[],"checksum":3411018549,"timestamp":"2024-06-01T18:07:11.218580Z"}]}
{"channel":"book","type":"update","data":[{"symbol":"DOT/USD","bids":[{"price":7.0868,"qty":0.00000000},{"price":7.0860,"qty":121.36401869}],"asks":[],"checksum":41518347,"timestamp":"2024-06-01T18:07:11.221326Z"}]}
{"channel":"book","type":"update","data":[{"symbol":"DOT/USD","bids":[{"price":7.0870,"qty":0.00000000},{"price":7.0857,"qty":75.00000000},{"price":7.0869,"qty":883.05746218}],"asks":[],"checksum":1835289050,"timestamp":"2024-06-01T18:07:11.223992Z"}]}
{"channel":"book","type":"update","data":[{"symbol":"DOT/USD","bids":[],"asks":[{"price":7.0929,"qty":4.29474228}],"checksum":3926181551,"timestamp":"2024-06-01T18:07:11.229966Z"}]}
{"channel":"book","type":"update","data":[{"symbol":"DOT/USD","bids":[],"asks":[{"price":7.0923,"qty":352.49943342}],"checksum":2968622389,"timestamp":"2024-06-01T18:07:11.233963Z"}]}
{"channel":"book","type":"update","data":[{"symbol":"DOT/USD","bids":[],"asks":[{"price":7.0921,"qty":1117.63401968}],"checksum":4146586408,"timestamp":"2024-06-01T18:07:11.242885Z"}]}
{"channel":"book","type":"update","data":[{"symbol":"DOT/USD","bids":[{"price":7.0907,"qty":0.00000000},{"price":7.0857,"qty":75.00000000}],"asks":[],"checksum":1080115103,"timestamp":"2024-06-01T18:07:11.255861Z"}]}
{"channel":"book","type":"update","data":[{"symbol":"DOT/USD","bids":[],"asks":[{"price":7.0938,"qty":2.54372019}],"checksum":1908440258,"timestamp":"2024-06-01T18:07:11.257226Z"}]}
{"channel":"book","type":"update","data":[{"symbol":"DOT/USD","bids":[{"price":7.0901,"qty":0.00000000},{"price":7.0855,"qty":564.23016211}],"asks":[],"checksum":1063584940,"timestamp":"2024-06-01T18:07:11.259735Z"}]}
{"channel":"book","type":"update","data":[{"symbol":"DOT/USD","bids":[],"asks":[{"price":7.0940,"qty":302.27948255}],"checksum":2864056539,"timestamp":"2024-06-01T18:07:11.260512Z"}]}
{"channel":"book","type":"update","data":[{"symbol":"DOT/USD","bids":[],"asks":[{"price":7.0937,"qty":325.54372019}],"checksum":2646200649,"timestamp":"2024-06-01T18:07:11.262207Z"}]}
{"channel":"book","type":"update","data":[{"symbol":"DOT/USD","bids":[{"price":7.0894,"qty":352.63626370}],"asks":[],"checksum":1557678694,"timestamp":"2024-06-01T18:07:11.263485Z"}]}
{"channel":"book","type":"update","data":[{"symbol":"DOT/USD","bids":[{"price":7.0879,"qty":28.20553268}],"asks":[],"checksum":289402915,"timestamp":"2024-06-01T18:07:11.264522Z"}]}
{"channel":"book","type":"update","data":[{"symbol":"DOT/USD","bids":[],"asks":[{"price":7.0940,"qty":304.82320274}],"checksum":3064839952,"timestamp":"2024-06-01T18:07:11.265298Z"}]}
{"channel":"book","type":"update","data":[{"symbol":"DOT/USD","bids":[{"price":7.0879,"qty":0.00000000},{"price":7.0857,"qty":75.00000000}],"asks":[],"checksum":4215932245,"timestamp":"2024-06-01T18:07:11.267409Z"}]}
{"channel":"book","type":"update","data":[{"symbol":"DOT/USD","bids":[{"price":7.0869,"qty":0.00000000},{"price":7.0855,"qty":564.23016211},{"price":7.0869,"qty":883.05746218}],"asks":[],"checksum":4215932245,"timestamp":"2024-06-01T18:07:11.318360Z"}]}
{"channel":"book","type":"update","data":[{"symbol":"DOT/USD","bids":[{"price":7.0874,"qty":89.76043906}],"asks":[],"checksum":2560375543,"timestamp":"2024-06-01T18:07:11.373457Z"}]}
{"channel":"book","type":"update","data":[{"symbol":"DOT/USD","bids":[{"price":7.0888,"qty":75.00000000}],"asks":[],"checksum":3914309078,"timestamp":"2024-06-01T18:07:11.465033Z"}]}
{"channel":"book","type":"update","data":[{"symbol":"DOT/USD","bids":[{"price":7.0897,"qty":321.64683178}],"asks":[],"checksum":348269199,"timestamp":"2024-06-01T18:07:11.469110Z"}]}
{"channel":"book","type":"update","data":[{"symbol":"DOT/USD","bids":[{"price":7.0888,"qty":0.00000000},{"price":7.0869,"qty":883.05746218}],"asks":[],"checksum":2023684106,"timestamp":"2024-06-01T18:07:11.470862Z"}]}
{"channel":"book","type":"update","data":[{"symbol":"DOT/USD","bids":[{"price":7.0888,"qty":75.00000000}],"asks":[],"checksum":348269199,"timestamp":"2024-06-01T18:07:11.508173Z"}]}
{"channel":"book","type":"update","data":[{"symbol":"DOT/USD","bids":[],"asks":[{"price":7.0937,"qty":1030.40151463}],"checksum":1396545175,"timestamp":"2024-06-01T18:07:11.716367Z"}]}
{"channel":"book","type":"update","data":[{"symbol":"DOT/USD","bids":[],"asks":[{"price":7.0940,"qty":38.68315418}],"checksum":2561690961,"timestamp":"2024-06-01T18:07:12.054502Z"}]}
{"channel":"book","type":"update","data":[{"symbol":"DOT/USD","bids":[],"asks":[{"price":7.0940,"qty":160.32320274}],"checksum":14479281,"timestamp":"2024-06-01T18:07:12.057579Z"}]}
{"channel":"book","type":"update","data":[{"symbol":"DOT/USD","bids":[{"price":7.0880,"qty":75.00000000}],"asks":[],"checksum":1444696759,"timestamp":"2024-06-01T18:07:13.330827Z"}]}
