{"channel":"book","type":"snapshot","data":[{"symbol":"DOT/USDT","bids":[{"price":7.0946,"qty":321.64683178},{"price":7.0945,"qty":352.67872368},{"price":7.0940,"qty":9.00000000},{"price":7.0933,"qty":23.90620000},{"price":7.0929,"qty":23.90620000},{"price":7.0924,"qty":1115.76887059},{"price":7.0921,"qty":23.90620000},{"price":7.0920,"qty":131.05277931},{"price":7.0916,"qty":94.01000000},{"price":7.0913,"qty":23.90620000}],"asks":[{"price":7.0966,"qty":23.90620000},{"price":7.0971,"qty":33.00000000},{"price":7.0973,"qty":352.54201111},{"price":7.0982,"qty":23.90620000},{"price":7.0991,"qty":5.57315803},{"price":7.0992,"qty":704.90452354},{"price":7.0998,"qty":23.90620000},{"price":7.1000,"qty":1.34828500},{"price":7.1006,"qty":81.60122000},{"price":7.1007,"qty":56.40370025}],"checksum":3157789521}]}
{"channel":"book","type":"update","data":[{"symbol":"DOT/USDT","bids":[],"asks":[{"price":7.1007,"qty":0.00000000},{"price":7.1011,"qty":22.80000000}],"checksum":1106851726,"timestamp":"2024-06-01T18:06:40.576507Z"}]}
{"channel":"book","type":"update","data":[{"symbol":"DOT/USDT","bids":[],"asks":[{"price":7.0998,"qty":376.44821111}],"checksum":1022864105,"timestamp":"2024-06-01T18:06:40.861552Z"}]}
{"channel":"book","type":"update","data":[{"symbol":"DOT/USDT","bids":[],"asks":[{"price":7.0998,"qty":23.90620000}],"checksum":1106851726,"timestamp":"2024-06-01T18:06:41.950487Z"}]}
{"channel":"book","type":"update","data":[{"symbol":"DOT/USDT","bids":[{"price":7.0947,"qty":23.90620000}],"asks":[],"checksum":3902620130,"timestamp":"2024-06-01T18:06:41.982096Z"}]}
{"channel":"book","type":"update","data":[{"symbol":"DOT/USDT","bids":[{"price":7.0947,"qty":0.00000000},{"price":7.0913,"qty":23.90620000}],"asks":[],"checksum":1106851726,"timestamp":"2024-06-01T18:06:41.985800Z"}]}
{"channel":"book","type":"update","data":[{"symbol":"DOT/USDT","bids":[{"price":7.0947,"qty":23.90620000}],"asks":[],"checksum":3902620130,"timestamp":"2024-06-01T18:06:41.988509Z"}]}
{"channel":"book","type":"update","data":[{"symbol":"DOT/USDT","bids":[{"price":7.0947,"qty":0.00000000},{"price":7.0913,"qty":23.90620000}],"asks":[],"checksum":1106851726,"timestamp":"2024-06-01T18:06:41.991835Z"}]}
{"channel":"book","type":"update","data":[{"symbol":"DOT/USDT","bids":[{"price":7.0946,"qty":345.55303178}],"asks":[],"checksum":3494526393,"timestamp":"2024-06-01T18:06:41.997673Z"}]}
{"channel":"book","type":"update","data":[{"symbol":"DOT/USDT","bids":[],"asks":[{"price":7.1000,"qty":353.89029611}],"checksum":677938140,"timestamp":"2024-06-01T18:06:42.293936Z"}]}
{"channel":"book","type":"update","data":[{"symbol":"DOT/USDT","bids":[],"asks":[{"price":7.0991,"qty":0.00000000},{"price":7.1013,"qty":704.68605816}],"checksum":3253489062,"timestamp":"2024-06-01T18:06:42.595577Z"}]}
{"channel":"book","type":"update","data":[{"symbol":"DOT/USDT","bids":[{"price":7.0946,"qty":321.64683178}],"asks":[],"checksum":1348421521,"timestamp":"2024-06-01T18:06:42.718655Z"}]}
{"channel":"book","type":"update","data":[{"symbol":"DOT/USDT","bids":[],"asks":[{"price":7.1001,"qty":94.04000000}],"checksum":2211323088,"timestamp":"2024-06-01T18:06:43.305753Z"}]}
{"channel":"book","type":"update","data":[{"symbol":"DOT/USDT","bids":[{"price":7.0946,"qty":345.55303178}],"asks":[],"checksum":310187751,"timestamp":"2024-06-01T18:06:43.532185Z"}]}
{"channel":"book","type":"update","data":[{"symbol":"DOT/USDT","bids":[{"price":7.0946,"qty":321.64683178}],"asks":[],"checksum":2211323088,"timestamp":"2024-06-01T18:06:43.701214Z"}]}
{"channel":"book","type":"update","data":[{"symbol":"DOT/USDT","bids":[],"asks":[{"price":7.0991,"qty":7.29308502}],"checksum":1709455884,"timestamp":"2024-06-01T18:06:45.127222Z"}]}
{"channel":"book","type":"update","data":[{"symbol":"DOT/USDT","bids":[{"price":7.0945,"qty":0.00000000},{"price":7.0906,"qty":417.14000000}],"asks":[],"checksum":3636458877,"timestamp":"2024-06-01T18:06:47.854870Z"}]}
{"channel":"book","type":"update","data":[{"symbol":"DOT/USDT","bids":[{"price":7.0947,"qty":352.67310295}],"asks":[],"checksum":3386524802,"timestamp":"2024-06-01T18:06:47.858558Z"}]}
{"channel":"book","type":"update","data":[{"symbol":"DOT/USDT","bids":[{"price":7.0946,"qty":0.00000000},{"price":7.0906,"qty":417.14000000}],"asks":[],"checksum":3086651006,"timestamp":"2024-06-01T18:06:47.859269Z"}]}
{"channel":"book","type":"update","data":[{"symbol":"DOT/USDT","bids":[{"price":7.0930,"qty":321.64683178}],"asks":[],"checksum":3268336765,"timestamp":"2024-06-01T18:06:47.859283Z"}]}
{"channel":"book","type":"update","data":[{"symbol":"DOT/USDT","bids":[{"price":7.0920,"qty":0.00000000},{"price":7.0906,"qty":417.14000000}],"asks":[],"checksum":2475703299,"timestamp":"2024-06-01T18:06:47.861451Z"}]}
{"channel":"book","type":"update","data":[{"symbol":"DOT/USDT","bids":[{"price":7.0920,"qty":69.59777931}],"asks":[],"checksum":2864144610,"timestamp":"2024-06-01T18:06:47.864406Z"}]}
{"channel":"book","type":"update","data":[{"symbol":"DOT/USDT","bids":[{"price":7.0939,"qty":23.90620000}],"asks":[],"checksum":3571588452,"timestamp":"2024-06-01T18:06:47.864554Z"}]}
{"channel":"book","type":"update","data":[{"symbol":"DOT/USDT","bids":[{"price":7.0948,"qty":321.64683178}],"asks":[],"checksum":3307106256,"timestamp":"2024-06-01T18:06:48.218059Z"}]}
{"channel":"book","type":"update","data":[{"symbol":"DOT/USDT","bids":[{"price":7.0930,"qty":0.00000000},{"price":7.0916,"qty":94.01000000}],"asks":[],"checksum":2094167835,"timestamp":"2024-06-01T18:06:48.221535Z"}]}
{"channel":"book","type":"update","data":[{"symbol":"DOT/USDT","bids":[{"price":7.0939,"qty":0.00000000},{"price":7.0913,"qty":23.90620000}],"asks":[],"checksum":728197662,"timestamp":"2024-06-01T18:06:48.810287Z"}]}
{"channel":"book","type":"update","data":[{"symbol":"DOT/USDT","bids":[{"price":7.0949,"qty":23.90620000}],"asks":[],"checksum":374889761,"timestamp":"2024-06-01T18:06:49.088233Z"}]}
{"channel":"book","type":"update","data":[{"symbol":"DOT/USDT","bids":[{"price":7.0949,"qty":0.00000000},{"price":7.0913,"qty":23.90620000}],"asks":[],"checksum":728197662,"timestamp":"2024-06-01T18:06:49.093286Z"}]}
{"channel":"book","type":"update","data":[{"symbol":"DOT/USDT","bids":[],"asks":[{"price":7.0991,"qty":0.00000000},{"price":7.1011,"qty":22.80000000}],"checksum":1646114641,"timestamp":"2024-06-01T18:06:50.126812Z"}]}
{"channel":"book","type":"update","data":[{"symbol":"DOT/USDT","bids":[],"asks":[{"price":7.0991,"qty":2.82095248}],"checksum":3889265604,"timestamp":"2024-06-01T18:06:50.127513Z"}]}
{"channel":"book","type":"update","data":[{"symbol":"DOT/USDT","bids":[{"price":7.0948,"qty":345.55303178}],"asks":[],"checksum":817355658,"timestamp":"2024-06-01T18:06:52.062046Z"}]}
{"channel":"book","type":"update","data":[{"symbol":"DOT/USDT","bids":[{"price":7.0948,"qty":321.64683178}],"asks":[],"checksum":3889265604,"timestamp":"2024-06-01T18:06:52.210243Z"}]}
{"channel":"book","type":"update","data":[{"symbol":"DOT/USDT","bids":[],"asks":[{"price":7.0991,"qty":0.00000000},{"price":7.1011,"qty":22.80000000}],"checksum":1646114641,"timestamp":"2024-06-01T18:06:52.633569Z"}]}
{"channel":"book","type":"update","data":[{"symbol":"DOT/USDT","bids":[{"price":7.0913,"qty":0.00000000},{"price":7.0905,"qty":23.90620000}],"asks":[],"checksum":286077309,"timestamp":"2024-06-01T18:06:53.370815Z"}]}
{"channel":"book","type":"update","data":[{"symbol":"DOT/USDT","bids":[],"asks":[{"price":7.0966,"qty":55.65012959}],"checksum":1499819569,"timestamp":"2024-06-01T18:06:54.297784Z"}]}
{"channel":"book","type":"update","data":[{"symbol":"DOT/USDT","bids":[{"price":7.0933,"qty":0.00000000},{"price":7.0899,"qty":10.27629088}],"asks":[],"checksum":2404816195,"timestamp":"2024-06-01T18:06:54.301562Z"}]}
{"channel":"book","type":"update","data":[{"symbol":"DOT/USDT","bids":[],"asks":[{"price":7.0971,"qty":0.00000000},{"price":7.1013,"qty":704.68605816}],"checksum":1620810771,"timestamp":"2024-06-01T18:06:55.006065Z"}]}
{"channel":"book","type":"update","data":[{"symbol":"DOT/USDT","bids":[],"asks":[{"price":7.0965,"qty":33.00000000}],"checksum":2183625145,"timestamp":"2024-06-01T18:06:55.006458Z"}]}
{"channel":"book","type":"update","data":[{"symbol":"DOT/USDT","bids":[],"asks":[{"price":7.0965,"qty":64.74467866}],"checksum":2751106481,"timestamp":"2024-06-01T18:06:55.009367Z"}]}
{"channel":"book","type":"update","data":[{"symbol":"DOT/USDT","bids":[],"asks":[{"price":7.0958,"qty":23.90620000}],"checksum":1382931887,"timestamp":"2024-06-01T18:06:55.009993Z"}]}
{"channel":"book","type":"update","data":[{"symbol":"DOT/USDT","bids":[],"asks":[{"price":7.0966,"qty":23.90620000}],"checksum":983930819,"timestamp":"2024-06-01T18:06:55.012755Z"}]}
{"channel":"book","type":"update","data":[{"symbol":"DOT/USDT","bids":[],"asks":[{"price":7.0991,"qty":5.57315803}],"checksum":3626572587,"timestamp":"2024-06-01T18:06:55.171184Z"}]}
{"channel":"book","type":"update","data":[{"symbol":"DOT/USDT","bids":[{"price":7.0924,"qty":763.25939113}],"asks":[],"checksum":530786301,"timestamp":"2024-06-01T18:06:55.236735Z"}]}
{"channel":"book","type":"update","data":[{"symbol":"DOT/USDT","bids":[{"price":7.0938,"qty":64.74467866}],"asks":[],"checksum":2717794918,"timestamp":"2024-06-01T18:06:55.529950Z"}]}
{"channel":"book","type":"update","data":[{"symbol":"DOT/USDT","bids":[{"price":7.0940,"qty":32.90620000}],"asks":[],"checksum":3052207384,"timestamp":"2024-06-01T18:06:56.884883Z"}]}
{"channel":"book","type":"update","data":[{"symbol":"DOT/USDT","bids":[],"asks":[{"price":7.0958,"qty":0.00000000},{"price":7.1006,"qty":81.60122000}],"checksum":1371398042,"timestamp":"2024-06-01T18:06:57.084844Z"}]}
{"channel":"book","type":"update","data":[{"symbol":"DOT/USDT","bids":[],"asks":[{"price":7.0958,"qty":23.90620000}],"checksum":3052207384,"timestamp":"2024-06-01T18:06:57.128635Z"}]}
{"channel":"book","type":"update","data":[{"symbol":"DOT/USDT","bids":[],"asks":[{"price":7.0958,"qty":0.00000000},{"price":7.1006,"qty":81.60122000}],"checksum":1371398042,"timestamp":"2024-06-01T18:06:57.363373Z"}]}
{"channel":"book","type":"update","data":[{"symbol":"DOT/USDT","bids":[],"asks":[{"price":7.0958,"qty":23.90620000}],"checksum":3052207384,"timestamp":"2024-06-01T18:06:57.493028Z"}]}
{"channel":"book","type":"update","data":[{"symbol":"DOT/USDT","bids":[],"asks":[{"price":7.0958,"qty":0.00000000},{"price":7.1006,"qty":81.60122000}],"checksum":1371398042,"timestamp":"2024-06-01T18:06:57.497006Z"}]}
{"channel":"book","type":"update","data":[{"symbol":"DOT/USDT","bids":[],"asks":[{"price":7.0958,"qty":23.90620000}],"checksum":3052207384,"timestamp":"2024-06-01T18:06:57.615326Z"}]}
{"channel":"book","type":"update","data":[{"symbol":"DOT/USDT","bids":[],"asks":[{"price":7.0958,"qty":0.00000000},{"price":7.1006,"qty":81.60122000}],"checksum":1371398042,"timestamp":"2024-06-01T18:06:57.618937Z"}]}
{"channel":"book","type":"update","data":[{"symbol":"DOT/USDT","bids":[],"asks":[{"price":7.0958,"qty":23.90620000}],"checksum":3052207384,"timestamp":"2024-06-01T18:06:57.622036Z"}]}
{"channel":"book","type":"update","data":[{"symbol":"DOT/USDT","bids":[],"asks":[{"price":7.0958,"qty":0.00000000},{"price":7.1006,"qty":81.60122000}],"checksum":1371398042,"timestamp":"2024-06-01T18:06:57.625511Z"}]}
{"channel":"book","type":"update","data":[{"symbol":"DOT/USDT","bids":[],"asks":[{"price":7.0958,"qty":23.90620000}],"checksum":3052207384,"timestamp":"2024-06-01T18:06:57.628468Z"}]}
{"channel":"book","type":"update","data":[{"symbol":"DOT/USDT","bids":[{"price":7.0940,"qty":9.00000000}],"asks":[],"checksum":2717794918,"timestamp":"2024-06-01T18:06:58.272126Z"}]}
{"channel":"book","type":"update","data":[{"symbol":"DOT/USDT","bids":[{"price":7.0940,"qty":32.90620000}],"asks":[],"checksum":3052207384,"timestamp":"2024-06-01T18:06:58.704871Z"}]}
{"channel":"book","type":"update","data":[{"symbol":"DOT/USDT","bids":[{"price":7.0940,"qty":9.00000000}],"asks":[],"checksum":2717794918,"timestamp":"2024-06-01T18:06:59.128109Z"}]}
{"channel":"book","type":"update","data":[{"symbol":"DOT/USDT","bids":[{"price":7.0940,"qty":32.90620000}],"asks":[],"checksum":3052207384,"timestamp":"2024-06-01T18:06:59.191669Z"}]}
{"channel":"book","type":"update","data":[{"symbol":"DOT/USDT","bids":[{"price":7.0940,"qty":9.00000000}],"asks":[],"checksum":2717794918,"timestamp":"2024-06-01T18:06:59.928771Z"}]}
{"channel":"book","type":"update","data":[{"symbol":"DOT/USDT","bids":[{"price":7.0940,"qty":32.90620000}],"asks":[],"checksum":3052207384,"timestamp":"2024-06-01T18:07:00.262946Z"}]}
{"channel":"book","type":"update","data":[{"symbol":"DOT/USDT","bids":[{"price":7.0940,"qty":9.00000000}],"asks":[],"checksum":2717794918,"timestamp":"2024-06-01T18:07:00.448253Z"}]}
{"channel":"book","type":"update","data":[{"symbol":"DOT/USDT","bids":[{"price":7.0940,"qty":32.90620000}],"asks":[],"checksum":3052207384,"timestamp":"2024-06-01T18:07:00.504176Z"}]}
{"channel":"book","type":"update","data":[{"symbol":"DOT/USDT","bids":[{"price":7.0940,"qty":9.00000000}],"asks":[],"checksum":2717794918,"timestamp":"2024-06-01T18:07:00.726769Z"}]}
{"channel":"book","type":"update","data":[{"symbol":"DOT/USDT","bids":[],"asks":[{"price":7.0988,"qty":32.50000000}],"checksum":4200096157,"timestamp":"2024-06-01T18:07:00.910640Z"}]}
{"channel":"book","type":"update","data":[{"symbol":"DOT/USDT","bids":[],"asks":[{"price":7.0990,"qty":23.90620000}],"checksum":1353436767,"timestamp":"2024-06-01T18:07:00.920755Z"}]}
{"channel":"book","type":"update","data":[{"symbol":"DOT/USDT","bids":[{"price":7.0938,"qty":0.00000000},{"price":7.0899,"qty":11.76762037}],"asks":[],"checksum":2374798441,"timestamp":"2024-06-01T18:07:01.079213Z"}]}
{"channel":"book","type":"update","data":[{"symbol":"DOT/USDT","bids":[{"price":7.0938,"qty":64.74467866}],"asks":[],"checksum":1353436767,"timestamp":"2024-06-01T18:07:01.372796Z"}]}
{"channel":"book","type":"update","data":[{"symbol":"DOT/USDT","bids":[{"price":7.0940,"qty":32.90620000}],"asks":[],"checksum":3927449756,"timestamp":"2024-06-01T18:07:02.598549Z"}]}
{"channel":"book","type":"update","data":[{"symbol":"DOT/USDT","bids":[],"asks":[{"price":7.0991,"qty":0.00000000},{"price":7.1000,"qty":353.89029611}],"checksum":4050910126,"timestamp":"2024-06-01T18:07:02.835662Z"}]}
{"channel":"book","type":"update","data":[{"symbol":"DOT/USDT","bids":[],"asks":[{"price":7.0991,"qty":8.32530083}],"checksum":2764604792,"timestamp":"2024-06-01T18:07:02.837144Z"}]}
{"channel":"book","type":"update","data":[{"symbol":"DOT/USDT","bids":[],"asks":[{"price":7.0958,"qty":0.00000000},{"price":7.1000,"qty":353.89029611}],"checksum":194841593,"timestamp":"2024-06-01T18:07:03.332529Z"}]}
{"channel":"book","type":"update","data":[{"symbol":"DOT/USDT","bids":[{"price":7.0920,"qty":0.00000000},{"price":7.0899,"qty":11.76762037}],"asks":[],"checksum":4078743201,"timestamp":"2024-06-01T18:07:03.335666Z"}]}
{"channel":"book","type":"update","data":[{"symbol":"DOT/USDT","bids":[{"price":7.0920,"qty":15.86277931}],"asks":[],"checksum":767767900,"timestamp":"2024-06-01T18:07:03.338620Z"}]}
{"channel":"book","type":"update","data":[{"symbol":"DOT/USDT","bids":[],"asks":[{"price":7.0965,"qty":31.74467866}],"checksum":2140696029,"timestamp":"2024-06-01T18:07:03.465240Z"}]}
{"channel":"book","type":"update","data":[{"symbol":"DOT/USDT","bids":[],"asks":[{"price":7.0971,"qty":33.00000000}],"checksum":3107576702,"timestamp":"2024-06-01T18:07:03.465373Z"}]}
{"channel":"book","type":"update","data":[{"symbol":"DOT/USDT","bids":[{"price":7.0948,"qty":345.55303178}],"asks":[],"checksum":1851751216,"timestamp":"2024-06-01T18:07:03.467877Z"}]}
{"channel":"book","type":"update","data":[{"symbol":"DOT/USDT","bids":[{"price":7.0948,"qty":321.64683178}],"asks":[],"checksum":3107576702,"timestamp":"2024-06-01T18:07:03.561233Z"}]}
{"channel":"book","type":"update","data":[{"symbol":"DOT/USDT","bids":[{"price":7.0949,"qty":23.90620000}],"asks":[],"checksum":3221464656,"timestamp":"2024-06-01T18:07:03.764910Z"}]}
{"channel":"book","type":"update","data":[{"symbol":"DOT/USDT","bids":[{"price":7.0949,"qty":0.00000000},{"price":7.0905,"qty":23.90620000}],"asks":[],"checksum":3107576702,"timestamp":"2024-06-01T18:07:03.767986Z"}]}
{"channel":"book","type":"update","data":[{"symbol":"DOT/USDT","bids":[{"price":7.0948,"qty":345.55303178}],"asks":[],"checksum":1851751216,"timestamp":"2024-06-01T18:07:03.775377Z"}]}
{"channel":"book","type":"update","data":[{"symbol":"DOT/USDT","bids":[{"price":7.0948,"qty":321.64683178}],"asks":[],"checksum":3107576702,"timestamp":"2024-06-01T18:07:03.876207Z"}]}
{"channel":"book","type":"update","data":[{"symbol":"DOT/USDT","bids":[{"price":7.0948,"qty":345.55303178}],"asks":[],"checksum":1851751216,"timestamp":"2024-06-01T18:07:04.082005Z"}]}
{"channel":"book","type":"update","data":[{"symbol":"DOT/USDT","bids":[{"price":7.0948,"qty":321.64683178}],"asks":[],"checksum":3107576702,"timestamp":"2024-06-01T18:07:04.341289Z"}]}
{"channel":"book","type":"update","data":[{"symbol":"DOT/USDT","bids":[{"price":7.0948,"qty":345.55303178}],"asks":[],"checksum":1851751216,"timestamp":"2024-06-01T18:07:04.429524Z"}]}
{"channel":"book","type":"update","data":[{"symbol":"DOT/USDT","bids":[{"price":7.0948,"qty":369.45923178}],"asks":[],"checksum":153887479,"timestamp":"2024-06-01T18:07:04.508923Z"}]}
{"channel":"book","type":"update","data":[{"symbol":"DOT/USDT","bids":[{"price":7.0948,"qty":345.55303178}],"asks":[],"checksum":1851751216,"timestamp":"2024-06-01T18:07:04.738239Z"}]}
{"channel":"book","type":"update","data":[{"symbol":"DOT/USDT","bids":[{"price":7.0948,"qty":321.64683178}],"asks":[],"checksum":3107576702,"timestamp":"2024-06-01T18:07:04.741579Z"}]}
{"channel":"book","type":"update","data":[{"symbol":"DOT/USDT","bids":[{"price":7.0948,"qty":345.55303178}],"asks":[],"checksum":1851751216,"timestamp":"2024-06-01T18:07:05.232930Z"}]}
{"channel":"book","type":"update","data":[{"symbol":"DOT/USDT","bids":[],"asks":[{"price":7.0991,"qty":0.00000000},{"price":7.1000,"qty":353.89029611}],"checksum":3369324696,"timestamp":"2024-06-01T18:07:05.391257Z"}]}
{"channel":"book","type":"update","data":[{"symbol":"DOT/USDT","bids":[],"asks":[{"price":7.0991,"qty":5.57303404}],"checksum":1298068746,"timestamp":"2024-06-01T18:07:05.393221Z"}]}
{"channel":"book","type":"update","data":[{"symbol":"DOT/USDT","bids":[],"asks":[{"price":7.0966,"qty":0.00000000},{"price":7.1000,"qty":353.89029611}],"checksum":4052846028,"timestamp":"2024-06-01T18:07:05.632609Z"}]}
{"channel":"book","type":"update","data":[{"symbol":"DOT/USDT","bids":[{"price":7.0948,"qty":369.45923178}],"asks":[],"checksum":2531449867,"timestamp":"2024-06-01T18:07:05.632820Z"}]}
{"channel":"book","type":"update","data":[{"symbol":"DOT/USDT","bids":[{"price":7.0949,"qty":23.90620000}],"asks":[],"checksum":1797713083,"timestamp":"2024-06-01T18:07:05.636528Z"}]}
{"channel":"book","type":"update","data":[{"symbol":"DOT/USDT","bids":[],"asks":[{"price":7.0965,"qty":55.65087866}],"checksum":1189431438,"timestamp":"2024-06-01T18:07:05.647673Z"}]}
{"channel":"book","type":"update","data":[{"symbol":"DOT/USDT","bids":[],"asks":[{"price":7.0965,"qty":31.74467866}],"checksum":1797713083,"timestamp":"2024-06-01T18:07:05.653989Z"}]}
{"channel":"book","type":"update","data":[{"symbol":"DOT/USDT","bids":[],"asks":[{"price":7.0964,"qty":23.90620000}],"checksum":1536694804,"timestamp":"2024-06-01T18:07:05.656959Z"}]}
{"channel":"book","type":"update","data":[{"symbol":"DOT/USDT","bids":[],"asks":[{"price":7.0964,"qty":0.00000000},{"price":7.1000,"qty":353.89029611}],"checksum":1797713083,"timestamp":"2024-06-01T18:07:05.660755Z"}]}
{"channel":"book","type":"update","data":[{"symbol":"DOT/USDT","bids":[{"price":7.0948,"qty":345.55303178}],"asks":[],"checksum":1487218532,"timestamp":"2024-06-01T18:07:05.661156Z"}]}
{"channel":"book","type":"update","data":[{"symbol":"DOT/USDT","bids":[],"asks":[{"price":7.0964,"qty":23.90620000}],"checksum":1746653643,"timestamp":"2024-06-01T18:07:05.663786Z"}]}
{"channel":"book","type":"update","data":[{"symbol":"DOT/USDT","bids":[],"asks":[{"price":7.0964,"qty":0.00000000},{"price":7.1000,"qty":353.89029611}],"checksum":1487218532,"timestamp":"2024-06-01T18:07:05.667068Z"}]}
{"channel":"book","type":"update","data":[{"symbol":"DOT/USDT","bids":[],"asks":[{"price":7.0963,"qty":23.90620000}],"checksum":2290544576,"timestamp":"2024-06-01T18:07:05.669646Z"}]}
{"channel":"book","type":"update","data":[{"symbol":"DOT/USDT","bids":[{"price":7.0949,"qty":0.00000000},{"price":7.0905,"qty":23.90620000}],"asks":[],"checksum":565333352,"timestamp":"2024-06-01T18:07:05.670963Z"}]}
{"channel":"book","type":"update","data":[{"symbol":"DOT/USDT","bids":[],"asks":[{"price":7.0963,"qty":0.00000000},{"price":7.1000,"qty":353.89029611}],"checksum":4052846028,"timestamp":"2024-06-01T18:07:05.672146Z"}]}
{"channel":"book","type":"update","data":[{"symbol":"DOT/USDT","bids":[{"price":7.0948,"qty":321.64683178}],"asks":[],"checksum":653731202,"timestamp":"2024-06-01T18:07:05.672800Z"}]}
{"channel":"book","type":"update","data":[{"symbol":"DOT/USDT","bids":[],"asks":[{"price":7.0964,"qty":23.90620000}],"checksum":373936941,"timestamp":"2024-06-01T18:07:05.675542Z"}]}
{"channel":"book","type":"update","data":[{"symbol":"DOT/USDT","bids":[],"asks":[{"price":7.0972,"qty":23.90620000}],"checksum":142857362,"timestamp":"2024-06-01T18:07:05.684584Z"}]}
{"channel":"book","type":"update","data":[{"symbol":"DOT/USDT","bids":[{"price":7.0948,"qty":345.55303178}],"asks":[],"checksum":3756356828,"timestamp":"2024-06-01T18:07:05.688418Z"}]}
{"channel":"book","type":"update","data":[{"symbol":"DOT/USDT","bids":[],"asks":[{"price":7.0964,"qty":0.00000000},{"price":7.0998,"qty":23.90620000}],"checksum":4219077050,"timestamp":"2024-06-01T18:07:05.705299Z"}]}
{"channel":"book","type":"update","data":[{"symbol":"DOT/USDT","bids":[{"price":7.0948,"qty":369.45923178}],"asks":[],"checksum":2617858173,"timestamp":"2024-06-01T18:07:05.707739Z"}]}
{"channel":"book","type":"update","data":[{"symbol":"DOT/USDT","bids":[{"price":7.0949,"qty":23.90620000}],"asks":[],"checksum":1640851661,"timestamp":"2024-06-01T18:07:05.730665Z"}]}
{"channel":"book","type":"update","data":[{"symbol":"DOT/USDT","bids":[],"asks":[{"price":7.0965,"qty":0.00000000},{"price":7.1000,"qty":353.89029611}],"checksum":3676333167,"timestamp":"2024-06-01T18:07:05.731559Z"}]}
{"channel":"book","type":"update","data":[{"symbol":"DOT/USDT","bids":[],"asks":[{"price":7.0964,"qty":23.90620000}],"checksum":3980181100,"timestamp":"2024-06-01T18:07:05.768855Z"}]}
{"channel":"book","type":"update","data":[{"symbol":"DOT/USDT","bids":[{"price":7.0948,"qty":345.55303178}],"asks":[],"checksum":3737089459,"timestamp":"2024-06-01T18:07:05.772271Z"}]}
{"channel":"book","type":"update","data":[{"symbol":"DOT/USDT","bids":[],"asks":[{"price":7.0964,"qty":0.00000000},{"price":7.1000,"qty":353.89029611}],"checksum":3903041456,"timestamp":"2024-06-01T18:07:05.772482Z"}]}
{"channel":"book","type":"update","data":[{"symbol":"DOT/USDT","bids":[],"asks":[{"price":7.0964,"qty":23.90620000}],"checksum":3737089459,"timestamp":"2024-06-01T18:07:05.775103Z"}]}
{"channel":"book","type":"update","data":[{"symbol":"DOT/USDT","bids":[{"price":7.0949,"qty":0.00000000},{"price":7.0905,"qty":23.90620000}],"asks":[],"checksum":2005653275,"timestamp":"2024-06-01T18:07:05.775650Z"}]}
{"channel":"book","type":"update","data":[{"symbol":"DOT/USDT","bids":[],"asks":[{"price":7.0964,"qty":0.00000000},{"price":7.1000,"qty":353.89029611}],"checksum":1100418328,"timestamp":"2024-06-01T18:07:05.778121Z"}]}
{"channel":"book","type":"update","data":[{"symbol":"DOT/USDT","bids":[],"asks":[{"price":7.0964,"qty":23.90620000}],"checksum":2005653275,"timestamp":"2024-06-01T18:07:05.780823Z"}]}
{"channel":"book","type":"update","data":[{"symbol":"DOT/USDT","bids":[],"asks":[{"price":7.0964,"qty":0.00000000},{"price":7.1000,"qty":353.89029611}],"checksum":1100418328,"timestamp":"2024-06-01T18:07:05.784668Z"}]}
{"channel":"book","type":"update","data":[{"symbol":"DOT/USDT","bids":[],"asks":[{"price":7.0964,"qty":23.90620000}],"checksum":2005653275,"timestamp":"2024-06-01T18:07:05.787340Z"}]}
{"channel":"book","type":"update","data":[{"symbol":"DOT/USDT","bids":[],"asks":[{"price":7.0964,"qty":0.00000000},{"price":7.1000,"qty":353.89029611}],"checksum":1100418328,"timestamp":"2024-06-01T18:07:05.790927Z"}]}
{"channel":"book","type":"update","data":[{"symbol":"DOT/USDT","bids":[],"asks":[{"price":7.0964,"qty":23.90620000}],"checksum":2005653275,"timestamp":"2024-06-01T18:07:05.793552Z"}]}
{"channel":"book","type":"update","data":[{"symbol":"DOT/USDT","bids":[],"asks":[{"price":7.0964,"qty":0.00000000},{"price":7.1000,"qty":353.89029611}],"checksum":1100418328,"timestamp":"2024-06-01T18:07:05.795921Z"}]}
{"channel":"book","type":"update","data":[{"symbol":"DOT/USDT","bids":[],"asks":[{"price":7.0964,"qty":23.90620000}],"checksum":2005653275,"timestamp":"2024-06-01T18:07:05.798462Z"}]}
{"channel":"book","type":"update","data":[{"symbol":"DOT/USDT","bids":[],"asks":[{"price":7.0964,"qty":0.00000000},{"price":7.1000,"qty":353.89029611}],"checksum":1100418328,"timestamp":"2024-06-01T18:07:05.801567Z"}]}
{"channel":"book","type":"update","data":[{"symbol":"DOT/USDT","bids":[{"price":7.0948,"qty":369.45923178}],"asks":[],"checksum":652498143,"timestamp":"2024-06-01T18:07:05.804191Z"}]}
{"channel":"book","type":"update","data":[{"symbol":"DOT/USDT","bids":[],"asks":[{"price":7.0968,"qty":9.00000000}],"checksum":1384517694,"timestamp":"2024-06-01T18:07:05.806326Z"}]}
{"channel":"book","type":"update","data":[{"symbol":"DOT/USDT","bids":[{"price":7.0948,"qty":345.55303178}],"asks":[],"checksum":905267705,"timestamp":"2024-06-01T18:07:05.806708Z"}]}
{"channel":"book","type":"update","data":[{"symbol":"DOT/USDT","bids":[],"asks":[{"price":7.0964,"qty":23.90620000}],"checksum":603812685,"timestamp":"2024-06-01T18:07:05.807754Z"}]}
{"channel":"book","type":"update","data":[{"symbol":"DOT/USDT","bids":[{"price":7.0949,"qty":23.90620000}],"asks":[],"checksum":2328482277,"timestamp":"2024-06-01T18:07:05.809628Z"}]}
{"channel":"book","type":"update","data":[{"symbol":"DOT/USDT","bids":[],"asks":[{"price":7.0964,"qty":0.00000000},{"price":7.0998,"qty":23.90620000}],"checksum":2629954385,"timestamp":"2024-06-01T18:07:05.810285Z"}]}
{"channel":"book","type":"update","data":[{"symbol":"DOT/USDT","bids":[{"price":7.0949,"qty":0.00000000},{"price":7.0905,"qty":23.90620000}],"asks":[],"checksum":905267705,"timestamp":"2024-06-01T18:07:05.812115Z"}]}
{"channel":"book","type":"update","data":[{"symbol":"DOT/USDT","bids":[{"price":7.0948,"qty":369.45923178}],"asks":[],"checksum":1384517694,"timestamp":"2024-06-01T18:07:05.818493Z"}]}
{"channel":"book","type":"update","data":[{"symbol":"DOT/USDT","bids":[],"asks":[{"price":7.0964,"qty":23.90620000}],"checksum":1150167690,"timestamp":"2024-06-01T18:07:05.818584Z"}]}
{"channel":"book","type":"update","data":[{"symbol":"DOT/USDT","bids":[{"price":7.0948,"qty":345.55303178}],"asks":[],"checksum":603812685,"timestamp":"2024-06-01T18:07:05.822410Z"}]}
{"channel":"book","type":"update","data":[{"symbol":"DOT/USDT","bids":[],"asks":[{"price":7.0964,"qty":0.00000000},{"price":7.0998,"qty":23.90620000}],"checksum":905267705,"timestamp":"2024-06-01T18:07:05.822789Z"}]}
{"channel":"book","type":"update","data":[{"symbol":"DOT/USDT","bids":[{"price":7.0948,"qty":369.45923178}],"asks":[],"checksum":1384517694,"timestamp":"2024-06-01T18:07:05.825439Z"}]}
{"channel":"book","type":"update","data":[{"symbol":"DOT/USDT","bids":[],"asks":[{"price":7.0964,"qty":23.90620000}],"checksum":1150167690,"timestamp":"2024-06-01T18:07:05.826028Z"}]}
{"channel":"book","type":"update","data":[{"symbol":"DOT/USDT","bids":[{"price":7.0948,"qty":345.55303178}],"asks":[],"checksum":603812685,"timestamp":"2024-06-01T18:07:05.829694Z"}]}
{"channel":"book","type":"update","data":[{"symbol":"DOT/USDT","bids":[],"asks":[{"price":7.0964,"qty":0.00000000},{"price":7.0998,"qty":23.90620000}],"checksum":905267705,"timestamp":"2024-06-01T18:07:05.829933Z"}]}
{"channel":"book","type":"update","data":[{"symbol":"DOT/USDT","bids":[],"asks":[{"price":7.0963,"qty":23.90620000}],"checksum":1797940807,"timestamp":"2024-06-01T18:07:05.833056Z"}]}
{"channel":"book","type":"update","data":[{"symbol":"DOT/USDT","bids":[],"asks":[{"price":7.0963,"qty":0.00000000},{"price":7.0998,"qty":23.90620000}],"checksum":905267705,"timestamp":"2024-06-01T18:07:05.836626Z"}]}
{"channel":"book","type":"update","data":[{"symbol":"DOT/USDT","bids":[],"asks":[{"price":7.0968,"qty":0.00000000},{"price":7.1000,"qty":353.89029611}],"checksum":1100418328,"timestamp":"2024-06-01T18:07:05.837592Z"}]}
{"channel":"book","type":"update","data":[{"symbol":"DOT/USDT","bids":[],"asks":[{"price":7.0963,"qty":23.90620000}],"checksum":2534861072,"timestamp":"2024-06-01T18:07:05.839127Z"}]}
{"channel":"book","type":"update","data":[{"symbol":"DOT/USDT","bids":[],"asks":[{"price":7.0963,"qty":0.00000000},{"price":7.1000,"qty":353.89029611}],"checksum":1100418328,"timestamp":"2024-06-01T18:07:05.842622Z"}]}
{"channel":"book","type":"update","data":[{"symbol":"DOT/USDT","bids":[],"asks":[{"price":7.0963,"qty":23.90620000}],"checksum":2534861072,"timestamp":"2024-06-01T18:07:05.845134Z"}]}
{"channel":"book","type":"update","data":[{"symbol":"DOT/USDT","bids":[],"asks":[{"price":7.0963,"qty":0.00000000},{"price":7.1000,"qty":353.89029611}],"checksum":1100418328,"timestamp":"2024-06-01T18:07:05.848210Z"}]}
{"channel":"book","type":"update","data":[{"symbol":"DOT/USDT","bids":[],"asks":[{"price":7.0963,"qty":23.90620000}],"checksum":2534861072,"timestamp":"2024-06-01T18:07:05.850717Z"}]}
{"channel":"book","type":"update","data":[{"symbol":"DOT/USDT","bids":[{"price":7.0948,"qty":321.64683178}],"asks":[],"checksum":1081100638,"timestamp":"2024-06-01T18:07:05.851983Z"}]}
{"channel":"book","type":"update","data":[{"symbol":"DOT/USDT","bids":[],"asks":[{"price":7.0963,"qty":0.00000000},{"price":7.1000,"qty":353.89029611}],"checksum":2532420950,"timestamp":"2024-06-01T18:07:05.853928Z"}]}
{"channel":"book","type":"update","data":[{"symbol":"DOT/USDT","bids":[],"asks":[{"price":7.0963,"qty":23.90620000}],"checksum":1081100638,"timestamp":"2024-06-01T18:07:05.856407Z"}]}
{"channel":"book","type":"update","data":[{"symbol":"DOT/USDT","bids":[],"asks":[{"price":7.0963,"qty":0.00000000},{"price":7.1000,"qty":353.89029611}],"checksum":2532420950,"timestamp":"2024-06-01T18:07:05.859550Z"}]}
{"channel":"book","type":"update","data":[{"symbol":"DOT/USDT","bids":[],"asks":[{"price":7.0963,"qty":23.90620000}],"checksum":1081100638,"timestamp":"2024-06-01T18:07:05.862073Z"}]}
{"channel":"book","type":"update","data":[{"symbol":"DOT/USDT","bids":[],"asks":[{"price":7.0963,"qty":0.00000000},{"price":7.1000,"qty":353.89029611}],"checksum":2532420950,"timestamp":"2024-06-01T18:07:05.865150Z"}]}
{"channel":"book","type":"update","data":[{"symbol":"DOT/USDT","bids":[],"asks":[{"price":7.0963,"qty":23.90620000}],"checksum":1081100638,"timestamp":"2024-06-01T18:07:05.867823Z"}]}
{"channel":"book","type":"update","data":[{"symbol":"DOT/USDT","bids":[],"asks":[{"price":7.0968,"qty":9.00000000}],"checksum":3159148041,"timestamp":"2024-06-01T18:07:05.870478Z"}]}
{"channel":"book","type":"update","data":[{"symbol":"DOT/USDT","bids":[{"price":7.0948,"qty":345.55303178}],"asks":[],"checksum":1797940807,"timestamp":"2024-06-01T18:07:06.033070Z"}]}
{"channel":"book","type":"update","data":[{"symbol":"DOT/USDT","bids":[],"asks":[{"price":7.0968,"qty":0.00000000},{"price":7.0998,"qty":23.90620000}],"checksum":2534861072,"timestamp":"2024-06-01T18:07:06.038092Z"}]}
{"channel":"book","type":"update","data":[{"symbol":"DOT/USDT","bids":[{"price":7.0948,"qty":321.64683178}],"asks":[],"checksum":1081100638,"timestamp":"2024-06-01T18:07:06.068743Z"}]}
{"channel":"book","type":"update","data":[{"symbol":"DOT/USDT","bids":[{"price":7.0949,"qty":23.90620000}],"asks":[],"checksum":961164400,"timestamp":"2024-06-01T18:07:06.558997Z"}]}
{"channel":"book","type":"update","data":[{"symbol":"DOT/USDT","bids":[],"asks":[{"price":7.0963,"qty":0.00000000},{"price":7.1000,"qty":353.89029611}],"checksum":4023111800,"timestamp":"2024-06-01T18:07:06.560060Z"}]}
{"channel":"book","type":"update","data":[{"symbol":"DOT/USDT","bids":[{"price":7.0949,"qty":0.00000000},{"price":7.0905,"qty":23.90620000}],"asks":[],"checksum":2532420950,"timestamp":"2024-06-01T18:07:06.564461Z"}]}
{"channel":"book","type":"update","data":[{"symbol":"DOT/USDT","bids":[],"asks":[{"price":7.0964,"qty":23.90620000}],"checksum":2699917141,"timestamp":"2024-06-01T18:07:06.565095Z"}]}
{"channel":"book","type":"update","data":[{"symbol":"DOT/USDT","bids":[{"price":7.0948,"qty":345.55303178}],"asks":[],"checksum":2005653275,"timestamp":"2024-06-01T18:07:06.580491Z"}]}
{"channel":"book","type":"update","data":[{"symbol":"DOT/USDT","bids":[{"price":7.0948,"qty":369.45923178}],"asks":[],"checksum":284724956,"timestamp":"2024-06-01T18:07:06.592533Z"}]}
{"channel":"book","type":"update","data":[{"symbol":"DOT/USDT","bids":[{"price":7.0949,"qty":23.90620000}],"asks":[],"checksum":3980181100,"timestamp":"2024-06-01T18:07:06.598467Z"}]}
{"channel":"book","type":"update","data":[{"symbol":"DOT/USDT","bids":[],"asks":[{"price":7.0964,"qty":0.00000000},{"price":7.1000,"qty":353.89029611}],"checksum":3676333167,"timestamp":"2024-06-01T18:07:06.598649Z"}]}
{"channel":"book","type":"update","data":[{"symbol":"DOT/USDT","bids":[{"price":7.0947,"qty":0.00000000},{"price":7.0905,"qty":23.90620000}],"asks":[],"checksum":2542423338,"timestamp":"2024-06-01T18:07:06.684321Z"}]}
{"channel":"book","type":"update","data":[{"symbol":"DOT/USDT","bids":[{"price":7.0950,"qty":352.65836586}],"asks":[],"checksum":4037082435,"timestamp":"2024-06-01T18:07:06.688295Z"}]}
{"channel":"book","type":"update","data":[{"symbol":"DOT/USDT","bids":[{"price":7.0930,"qty":28.20314094}],"asks":[],"checksum":4210565853,"timestamp":"2024-06-01T18:07:06.689719Z"}]}
{"channel":"book","type":"update","data":[{"symbol":"DOT/USDT","bids":[],"asks":[{"price":7.0968,"qty":9.00000000}],"checksum":2392483388,"timestamp":"2024-06-01T18:07:06.689854Z"}]}
{"channel":"book","type":"update","data":[{"symbol":"DOT/USDT","bids":[],"asks":[{"price":7.0971,"qty":0.00000000},{"price":7.1000,"qty":353.89029611}],"checksum":1844072683,"timestamp":"2024-06-01T18:07:06.691675Z"}]}
{"channel":"book","type":"update","data":[{"symbol":"DOT/USDT","bids":[{"price":7.0951,"qty":23.90620000}],"asks":[],"checksum":453692490,"timestamp":"2024-06-01T18:07:06.691810Z"}]}
{"channel":"book","type":"update","data":[{"symbol":"DOT/USDT","bids":[{"price":7.0948,"qty":345.55303178}],"asks":[],"checksum":2864872453,"timestamp":"2024-06-01T18:07:06.692481Z"}]}
{"channel":"book","type":"update","data":[{"symbol":"DOT/USDT","bids":[{"price":7.0930,"qty":0.00000000},{"price":7.0920,"qty":15.86277931}],"asks":[],"checksum":2386123890,"timestamp":"2024-06-01T18:07:06.693608Z"}]}
{"channel":"book","type":"update","data":[{"symbol":"DOT/USDT","bids":[],"asks":[{"price":7.0973,"qty":0.00000000},{"price":7.1001,"qty":94.04000000}],"checksum":3216226453,"timestamp":"2024-06-01T18:07:06.699050Z"}]}
{"channel":"book","type":"update","data":[{"symbol":"DOT/USDT","bids":[],"asks":[{"price":7.0992,"qty":0.00000000},{"price":7.1006,"qty":81.60122000}],"checksum":2498226550,"timestamp":"2024-06-01T18:07:06.699290Z"}]}
{"channel":"book","type":"update","data":[{"symbol":"DOT/USDT","bids":[],"asks":[{"price":7.0980,"qty":33.00000000}],"checksum":37595630,"timestamp":"2024-06-01T18:07:06.702191Z"}]}
{"channel":"book","type":"update","data":[{"symbol":"DOT/USDT","bids":[],"asks":[{"price":7.0985,"qty":352.48628552}],"checksum":4058373781,"timestamp":"2024-06-01T18:07:06.707715Z"}]}
{"channel":"book","type":"update","data":[{"symbol":"DOT/USDT","bids":[],"asks":[{"price":7.0972,"qty":0.00000000},{"price":7.1001,"qty":94.04000000}],"checksum":896930977,"timestamp":"2024-06-01T18:07:06.709108Z"}]}
{"channel":"book","type":"update","data":[{"symbol":"DOT/USDT","bids":[{"price":7.0951,"qty":345.55303178}],"asks":[],"checksum":3754122410,"timestamp":"2024-06-01T18:07:06.717546Z"}]}
{"channel":"book","type":"update","data":[{"symbol":"DOT/USDT","bids":[{"price":7.0950,"qty":0.00000000},{"price":7.0916,"qty":94.01000000}],"asks":[],"checksum":1031267708,"timestamp":"2024-06-01T18:07:06.719760Z"}]}
{"channel":"book","type":"update","data":[{"symbol":"DOT/USDT","bids":[{"price":7.0956,"qty":23.90620000}],"asks":[],"checksum":749091529,"timestamp":"2024-06-01T18:07:06.721355Z"}]}
{"channel":"book","type":"update","data":[{"symbol":"DOT/USDT","bids":[{"price":7.0956,"qty":0.00000000},{"price":7.0916,"qty":94.01000000}],"asks":[],"checksum":1031267708,"timestamp":"2024-06-01T18:07:06.724978Z"}]}
{"channel":"book","type":"update","data":[{"symbol":"DOT/USDT","bids":[{"price":7.0956,"qty":23.90620000}],"asks":[],"checksum":749091529,"timestamp":"2024-06-01T18:07:06.728374Z"}]}
{"channel":"book","type":"update","data":[{"symbol":"DOT/USDT","bids":[{"price":7.0956,"qty":0.00000000},{"price":7.0916,"qty":94.01000000}],"asks":[],"checksum":1031267708,"timestamp":"2024-06-01T18:07:06.732054Z"}]}
{"channel":"book","type":"update","data":[{"symbol":"DOT/USDT","bids":[{"price":7.0956,"qty":23.90620000}],"asks":[],"checksum":749091529,"timestamp":"2024-06-01T18:07:06.735190Z"}]}
{"channel":"book","type":"update","data":[{"symbol":"DOT/USDT","bids":[{"price":7.0956,"qty":0.00000000},{"price":7.0916,"qty":94.01000000}],"asks":[],"checksum":1031267708,"timestamp":"2024-06-01T18:07:06.739410Z"}]}
{"channel":"book","type":"update","data":[{"symbol":"DOT/USDT","bids":[{"price":7.0956,"qty":23.90620000}],"asks":[],"checksum":749091529,"timestamp":"2024-06-01T18:07:06.742616Z"}]}
{"channel":"book","type":"update","data":[{"symbol":"DOT/USDT","bids":[],"asks":[{"price":7.0988,"qty":0.00000000},{"price":7.1006,"qty":81.60122000}],"checksum":849904273,"timestamp":"2024-06-01T18:07:06.742635Z"}]}
{"channel":"book","type":"update","data":[{"symbol":"DOT/USDT","bids":[{"price":7.0939,"qty":705.42096191}],"asks":[],"checksum":1254135208,"timestamp":"2024-06-01T18:07:06.745202Z"}]}
{"channel":"book","type":"update","data":[{"symbol":"DOT/USDT","bids":[{"price":7.0956,"qty":0.00000000},{"price":7.0920,"qty":15.86277931}],"asks":[],"checksum":1313516275,"timestamp":"2024-06-01T18:07:06.747327Z"}]}
{"channel":"book","type":"update","data":[{"symbol":"DOT/USDT","bids":[{"price":7.0956,"qty":23.90620000}],"asks":[],"checksum":1254135208,"timestamp":"2024-06-01T18:07:06.750411Z"}]}
{"channel":"book","type":"update","data":[{"symbol":"DOT/USDT","bids":[{"price":7.0948,"qty":23.90620000}],"asks":[],"checksum":2771725687,"timestamp":"2024-06-01T18:07:06.752410Z"}]}
{"channel":"book","type":"update","data":[{"symbol":"DOT/USDT","bids":[{"price":7.0956,"qty":0.00000000},{"price":7.0920,"qty":15.86277931}],"asks":[],"checksum":3804160805,"timestamp":"2024-06-01T18:07:06.754555Z"}]}
{"channel":"book","type":"update","data":[{"symbol":"DOT/USDT","bids":[{"price":7.0941,"qty":28.20131061}],"asks":[],"checksum":661462790,"timestamp":"2024-06-01T18:07:06.757400Z"}]}
{"channel":"book","type":"update","data":[{"symbol":"DOT/USDT","bids":[{"price":7.0957,"qty":23.90620000}],"asks":[],"checksum":1816228092,"timestamp":"2024-06-01T18:07:06.757489Z"}]}
{"channel":"book","type":"update","data":[{"symbol":"DOT/USDT","bids":[{"price":7.0957,"qty":0.00000000},{"price":7.0921,"qty":23.90620000}],"asks":[],"checksum":661462790,"timestamp":"2024-06-01T18:07:06.761252Z"}]}
{"channel":"book","type":"update","data":[{"symbol":"DOT/USDT","bids":[{"price":7.0957,"qty":23.90620000}],"asks":[],"checksum":1816228092,"timestamp":"2024-06-01T18:07:06.769046Z"}]}
{"channel":"book","type":"update","data":[{"symbol":"DOT/USDT","bids":[{"price":7.0957,"qty":0.00000000},{"price":7.0921,"qty":23.90620000}],"asks":[],"checksum":661462790,"timestamp":"2024-06-01T18:07:06.772427Z"}]}
{"channel":"book","type":"update","data":[{"symbol":"DOT/USDT","bids":[{"price":7.0956,"qty":23.90620000}],"asks":[],"checksum":2095700162,"timestamp":"2024-06-01T18:07:06.777228Z"}]}
{"channel":"book","type":"update","data":[{"symbol":"DOT/USDT","bids":[],"asks":[{"price":7.1000,"qty":1.34828500}],"checksum":274928133,"timestamp":"2024-06-01T18:07:06.796897Z"}]}
{"channel":"book","type":"update","data":[{"symbol":"DOT/USDT","bids":[{"price":7.0956,"qty":0.00000000},{"price":7.0921,"qty":23.90620000}],"asks":[],"checksum":1273484737,"timestamp":"2024-06-01T18:07:06.853151Z"}]}
{"channel":"book","type":"update","data":[{"symbol":"DOT/USDT","bids":[{"price":7.0956,"qty":23.90620000}],"asks":[],"checksum":274928133,"timestamp":"2024-06-01T18:07:07.033403Z"}]}
{"channel":"book","type":"update","data":[{"symbol":"DOT/USDT","bids":[{"price":7.0956,"qty":0.00000000},{"price":7.0921,"qty":23.90620000}],"asks":[],"checksum":1273484737,"timestamp":"2024-06-01T18:07:07.037599Z"}]}
{"channel":"book","type":"update","data":[{"symbol":"DOT/USDT","bids":[{"price":7.0952,"qty":321.64683178}],"asks":[],"checksum":2459675135,"timestamp":"2024-06-01T18:07:07.037875Z"}]}
{"channel":"book","type":"update","data":[{"symbol":"DOT/USDT","bids":[{"price":7.0952,"qty":345.55303178}],"asks":[],"checksum":52995016,"timestamp":"2024-06-01T18:07:07.042096Z"}]}
{"channel":"book","type":"update","data":[{"symbol":"DOT/USDT","bids":[{"price":7.0949,"qty":0.00000000},{"price":7.0921,"qty":23.90620000}],"asks":[],"checksum":1892839167,"timestamp":"2024-06-01T18:07:07.042507Z"}]}
{"channel":"book","type":"update","data":[{"symbol":"DOT/USDT","bids":[{"price":7.0953,"qty":23.90620000}],"asks":[],"checksum":1204724440,"timestamp":"2024-06-01T18:07:07.064836Z"}]}
{"channel":"book","type":"update","data":[{"symbol":"DOT/USDT","bids":[{"price":7.0951,"qty":321.64683178}],"asks":[],"checksum":4240116986,"timestamp":"2024-06-01T18:07:07.064925Z"}]}
{"channel":"book","type":"update","data":[{"symbol":"DOT/USDT","bids":[{"price":7.0951,"qty":0.00000000},{"price":7.0921,"qty":23.90620000}],"asks":[],"checksum":3839215759,"timestamp":"2024-06-01T18:07:07.068645Z"}]}
{"channel":"book","type":"update","data":[{"symbol":"DOT/USDT","bids":[],"asks":[{"price":7.0989,"qty":56.41860224}],"checksum":750628826,"timestamp":"2024-06-01T18:07:07.095544Z"}]}
{"channel":"book","type":"update","data":[{"symbol":"DOT/USDT","bids":[],"asks":[{"price":7.0985,"qty":0.00000000},{"price":7.1006,"qty":81.60122000}],"checksum":3743877711,"timestamp":"2024-06-01T18:07:07.191177Z"}]}
{"channel":"book","type":"update","data":[{"symbol":"DOT/USDT","bids":[],"asks":[{"price":7.0992,"qty":352.45222809}],"checksum":877938411,"timestamp":"2024-06-01T18:07:07.195240Z"}]}
{"channel":"book","type":"update","data":[{"symbol":"DOT/USDT","bids":[{"price":7.0963,"qty":352.59030971}],"asks":[],"checksum":3521919109,"timestamp":"2024-06-01T18:07:07.195271Z"}]}
{"channel":"book","type":"update","data":[{"symbol":"DOT/USDT","bids":[],"asks":[{"price":7.0977,"qty":9.00000000}],"checksum":439076166,"timestamp":"2024-06-01T18:07:07.196251Z"}]}
{"channel":"book","type":"update","data":[{"symbol":"DOT/USDT","bids":[],"asks":[{"price":7.0968,"qty":0.00000000},{"price":7.1001,"qty":94.04000000}],"checksum":344836676,"timestamp":"2024-06-01T18:07:07.196422Z"}]}
{"channel":"book","type":"update","data":[{"symbol":"DOT/USDT","bids":[{"price":7.0941,"qty":0.00000000},{"price":7.0921,"qty":23.90620000}],"asks":[],"checksum":3444654065,"timestamp":"2024-06-01T18:07:07.199792Z"}]}
{"channel":"book","type":"update","data":[{"symbol":"DOT/USDT","bids":[],"asks":[{"price":7.0974,"qty":23.90620000}],"checksum":2486471218,"timestamp":"2024-06-01T18:07:07.200085Z"}]}
{"channel":"book","type":"update","data":[{"symbol":"DOT/USDT","bids":[],"asks":[{"price":7.0971,"qty":9.00000000}],"checksum":150153701,"timestamp":"2024-06-01T18:07:07.588981Z"}]}
{"channel":"book","type":"update","data":[{"symbol":"DOT/USDT","bids":[],"asks":[{"price":7.0977,"qty":0.00000000},{"price":7.1000,"qty":1.34828500}],"checksum":3516289638,"timestamp":"2024-06-01T18:07:07.596100Z"}]}
{"channel":"book","type":"update","data":[{"symbol":"DOT/USDT","bids":[{"price":7.0953,"qty":0.00000000},{"price":7.0920,"qty":15.86277931}],"asks":[],"checksum":4282653647,"timestamp":"2024-06-01T18:07:07.767509Z"}]}
{"channel":"book","type":"update","data":[{"symbol":"DOT/USDT","bids":[],"asks":[{"price":7.0991,"qty":0.00000000},{"price":7.1001,"qty":94.04000000}],"checksum":3137892148,"timestamp":"2024-06-01T18:07:07.897928Z"}]}
{"channel":"book","type":"update","data":[{"symbol":"DOT/USDT","bids":[{"price":7.0952,"qty":321.64683178}],"asks":[],"checksum":3160412412,"timestamp":"2024-06-01T18:07:09.718902Z"}]}
{"channel":"book","type":"update","data":[{"symbol":"DOT/USDT","bids":[{"price":7.0941,"qty":28.20284481}],"asks":[],"checksum":11945065,"timestamp":"2024-06-01T18:07:09.723557Z"}]}
{"channel":"book","type":"update","data":[{"symbol":"DOT/USDT","bids":[],"asks":[{"price":7.0966,"qty":23.90620000}],"checksum":4037353948,"timestamp":"2024-06-01T18:07:10.255728Z"}]}
{"channel":"book","type":"update","data":[{"symbol":"DOT/USDT","bids":[],"asks":[{"price":7.0966,"qty":0.00000000},{"price":7.1001,"qty":94.04000000}],"checksum":11945065,"timestamp":"2024-06-01T18:07:10.259229Z"}]}
{"channel":"book","type":"update","data":[{"symbol":"DOT/USDT","bids":[],"asks":[{"price":7.0966,"qty":23.90620000}],"checksum":4037353948,"timestamp":"2024-06-01T18:07:10.849055Z"}]}
{"channel":"book","type":"update","data":[{"symbol":"DOT/USDT","bids":[],"asks":[{"price":7.0966,"qty":0.00000000},{"price":7.1001,"qty":94.04000000}],"checksum":11945065,"timestamp":"2024-06-01T18:07:10.852719Z"}]}
{"channel":"book","type":"update","data":[{"symbol":"DOT/USDT","bids":[],"asks":[{"price":7.0966,"qty":23.90620000}],"checksum":4037353948,"timestamp":"2024-06-01T18:07:10.862762Z"}]}
{"channel":"book","type":"update","data":[{"symbol":"DOT/USDT","bids":[],"asks":[{"price":7.0966,"qty":0.00000000},{"price":7.1001,"qty":94.04000000}],"checksum":11945065,"timestamp":"2024-06-01T18:07:10.866161Z"}]}
{"channel":"book","type":"update","data":[{"symbol":"DOT/USDT","bids":[],"asks":[{"price":7.0966,"qty":23.90620000}],"checksum":4037353948,"timestamp":"2024-06-01T18:07:10.869436Z"}]}
{"channel":"book","type":"update","data":[{"symbol":"DOT/USDT","bids":[],"asks":[{"price":7.0966,"qty":0.00000000},{"price":7.1001,"qty":94.04000000}],"checksum":11945065,"timestamp":"2024-06-01T18:07:10.873762Z"}]}
{"channel":"book","type":"update","data":[{"symbol":"DOT/USDT","bids":[],"asks":[{"price":7.0966,"qty":23.90620000}],"checksum":4037353948,"timestamp":"2024-06-01T18:07:10.877321Z"}]}
{"channel":"book","type":"update","data":[{"symbol":"DOT/USDT","bids":[],"asks":[{"price":7.0966,"qty":0.00000000},{"price":7.1001,"qty":94.04000000}],"checksum":11945065,"timestamp":"2024-06-01T18:07:10.880990Z"}]}
{"channel":"book","type":"update","data":[{"symbol":"DOT/USDT","bids":[],"asks":[{"price":7.0966,"qty":23.90620000}],"checksum":4037353948,"timestamp":"2024-06-01T18:07:10.884107Z"}]}
{"channel":"book","type":"update","data":[{"symbol":"DOT/USDT","bids":[],"asks":[{"price":7.0966,"qty":0.00000000},{"price":7.1001,"qty":94.04000000}],"checksum":11945065,"timestamp":"2024-06-01T18:07:10.887189Z"}]}
{"channel":"book","type":"update","data":[{"symbol":"DOT/USDT","bids":[],"asks":[{"price":7.0966,"qty":23.90620000}],"checksum":4037353948,"timestamp":"2024-06-01T18:07:10.890214Z"}]}
{"channel":"book","type":"update","data":[{"symbol":"DOT/USDT","bids":[],"asks":[{"price":7.0966,"qty":0.00000000},{"price":7.1001,"qty":94.04000000}],"checksum":11945065,"timestamp":"2024-06-01T18:07:10.893057Z"}]}
{"channel":"book","type":"update","data":[{"symbol":"DOT/USDT","bids":[],"asks":[{"price":7.0966,"qty":23.90620000}],"checksum":4037353948,"timestamp":"2024-06-01T18:07:10.901440Z"}]}
{"channel":"book","type":"update","data":[{"symbol":"DOT/USDT","bids":[],"asks":[{"price":7.0966,"qty":0.00000000},{"price":7.1001,"qty":94.04000000}],"checksum":11945065,"timestamp":"2024-06-01T18:07:10.905883Z"}]}
{"channel":"book","type":"update","data":[{"symbol":"DOT/USDT","bids":[],"asks":[{"price":7.0966,"qty":23.90620000}],"checksum":4037353948,"timestamp":"2024-06-01T18:07:10.918133Z"}]}
{"channel":"book","type":"update","data":[{"symbol":"DOT/USDT","bids":[],"asks":[{"price":7.0966,"qty":0.00000000},{"price":7.1001,"qty":94.04000000}],"checksum":11945065,"timestamp":"2024-06-01T18:07:10.921531Z"}]}
{"channel":"book","type":"update","data":[{"symbol":"DOT/USDT","bids":[],"asks":[{"price":7.0966,"qty":23.90620000}],"checksum":4037353948,"timestamp":"2024-06-01T18:07:11.053005Z"}]}
{"channel":"book","type":"update","data":[{"symbol":"DOT/USDT","bids":[],"asks":[{"price":7.0966,"qty":0.00000000},{"price":7.1001,"qty":94.04000000}],"checksum":11945065,"timestamp":"2024-06-01T18:07:11.057089Z"}]}
{"channel":"book","type":"update","data":[{"symbol":"DOT/USDT","bids":[],"asks":[{"price":7.0966,"qty":23.90620000}],"checksum":4037353948,"timestamp":"2024-06-01T18:07:11.067687Z"}]}
{"channel":"book","type":"update","data":[{"symbol":"DOT/USDT","bids":[],"asks":[{"price":7.0966,"qty":0.00000000},{"price":7.1001,"qty":94.04000000}],"checksum":11945065,"timestamp":"2024-06-01T18:07:11.071466Z"}]}
{"channel":"book","type":"update","data":[{"symbol":"DOT/USDT","bids":[],"asks":[{"price":7.0966,"qty":23.90620000}],"checksum":4037353948,"timestamp":"2024-06-01T18:07:11.083822Z"}]}
{"channel":"book","type":"update","data":[{"symbol":"DOT/USDT","bids":[],"asks":[{"price":7.0966,"qty":0.00000000},{"price":7.1001,"qty":94.04000000}],"checksum":11945065,"timestamp":"2024-06-01T18:07:11.087522Z"}]}
{"channel":"book","type":"update","data":[{"symbol":"DOT/USDT","bids":[],"asks":[{"price":7.0966,"qty":23.90620000}],"checksum":4037353948,"timestamp":"2024-06-01T18:07:11.099263Z"}]}
{"channel":"book","type":"update","data":[{"symbol":"DOT/USDT","bids":[],"asks":[{"price":7.0966,"qty":0.00000000},{"price":7.1001,"qty":94.04000000}],"checksum":11945065,"timestamp":"2024-06-01T18:07:11.103106Z"}]}
{"channel":"book","type":"update","data":[{"symbol":"DOT/USDT","bids":[],"asks":[{"price":7.0966,"qty":23.90620000}],"checksum":4037353948,"timestamp":"2024-06-01T18:07:11.148980Z"}]}
{"channel":"book","type":"update","data":[{"symbol":"DOT/USDT","bids":[],"asks":[{"price":7.0966,"qty":0.00000000},{"price":7.1001,"qty":94.04000000}],"checksum":11945065,"timestamp":"2024-06-01T18:07:11.152175Z"}]}
{"channel":"book","type":"update","data":[{"symbol":"DOT/USDT","bids":[],"asks":[{"price":7.0966,"qty":23.90620000}],"checksum":4037353948,"timestamp":"2024-06-01T18:07:11.194847Z"}]}
{"channel":"book","type":"update","data":[{"symbol":"DOT/USDT","bids":[{"price":7.0948,"qty":0.00000000},{"price":7.0920,"qty":15.86277931}],"asks":[],"checksum":3610629964,"timestamp":"2024-06-01T18:07:11.198338Z"}]}
{"channel":"book","type":"update","data":[{"symbol":"DOT/USDT","bids":[],"asks":[{"price":7.0992,"qty":0.00000000},{"price":7.1001,"qty":94.04000000}],"checksum":3834303261,"timestamp":"2024-06-01T18:07:11.217611Z"}]}
{"channel":"book","type":"update","data":[{"symbol":"DOT/USDT","bids":[],"asks":[{"price":7.0986,"qty":352.48420782}],"checksum":1995831857,"timestamp":"2024-06-01T18:07:11.221830Z"}]}
{"channel":"book","type":"update","data":[{"symbol":"DOT/USDT","bids":[{"price":7.0963,"qty":0.00000000},{"price":7.0916,"qty":94.01000000}],"asks":[],"checksum":1418487101,"timestamp":"2024-06-01T18:07:11.302673Z"}]}
{"channel":"book","type":"update","data":[{"symbol":"DOT/USDT","bids":[{"price":7.0952,"qty":0.00000000},{"price":7.0905,"qty":23.90620000}],"asks":[],"checksum":894903342,"timestamp":"2024-06-01T18:07:11.306636Z"}]}
{"channel":"book","type":"update","data":[{"symbol":"DOT/USDT","bids":[{"price":7.0955,"qty":352.63175053}],"asks":[],"checksum":3575752945,"timestamp":"2024-06-01T18:07:11.308468Z"}]}
{"channel":"book","type":"update","data":[{"symbol":"DOT/USDT","bids":[],"asks":[{"price":7.0990,"qty":0.00000000},{"price":7.1001,"qty":94.04000000}],"checksum":2320779664,"timestamp":"2024-06-01T18:07:11.491428Z"}]}
{"channel":"book","type":"update","data":[{"symbol":"DOT/USDT","bids":[{"price":7.0945,"qty":321.64683178}],"asks":[],"checksum":1016377993,"timestamp":"2024-06-01T18:07:11.715618Z"}]}
{"channel":"book","type":"update","data":[{"symbol":"DOT/USDT","bids":[],"asks":[{"price":7.1000,"qty":4.16926571}],"checksum":525997309,"timestamp":"2024-06-01T18:07:12.914093Z"}]}
{"channel":"book","type":"update","data":[{"symbol":"DOT/USDT","bids":[{"price":7.0941,"qty":0.00000000},{"price":7.0916,"qty":94.01000000}],"asks":[],"checksum":3699322013,"timestamp":"2024-06-01T18:07:12.918262Z"}]}
{"channel":"book","type":"update","data":[{"symbol":"DOT/USDT","bids":[],"asks":[{"price":7.0986,"qty":0.00000000},{"price":7.1002,"qty":704.80477096}],"checksum":2601675548,"timestamp":"2024-06-01T18:07:13.813381Z"}]}
{"channel":"book","type":"update","data":[{"symbol":"DOT/USDT","bids":[],"asks":[{"price":7.0980,"qty":385.51403177}],"checksum":3348127661,"timestamp":"2024-06-01T18:07:13.816525Z"}]}
{"channel":"book","type":"update","data":[{"symbol":"DOT/USDT","bids":[],"asks":[{"price":7.0966,"qty":55.65051843}],"checksum":3253939460,"timestamp":"2024-06-01T18:07:14.750600Z"}]}
{"channel":"book","type":"update","data":[{"symbol":"DOT/USDT","bids":[{"price":7.0940,"qty":9.00000000}],"asks":[],"checksum":2623859014,"timestamp":"2024-06-01T18:07:14.852733Z"}]}
{"channel":"book","type":"update","data":[{"symbol":"DOT/USDT","bids":[],"asks":[{"price":7.0980,"qty":352.51403177}],"checksum":3024336394,"timestamp":"2024-06-01T18:07:15.088901Z"}]}
{"channel":"book","type":"update","data":[{"symbol":"DOT/USDT","bids":[],"asks":[{"price":7.0970,"qty":33.00000000}],"checksum":4013446796,"timestamp":"2024-06-01T18:07:15.089236Z"}]}
{"channel":"book","type":"update","data":[{"symbol":"DOT/USDT","bids":[],"asks":[{"price":7.1000,"qty":1.34828500}],"checksum":4177108347,"timestamp":"2024-06-01T18:07:15.418529Z"}]}
{"channel":"book","type":"update","data":[{"symbol":"DOT/USDT","bids":[],"asks":[{"price":7.1000,"qty":9.67098148}],"checksum":2147852715,"timestamp":"2024-06-01T18:07:15.420358Z"}]}
{"channel":"book","type":"update","data":[{"symbol":"DOT/USDT","bids":[{"price":7.0939,"qty":729.32716191}],"asks":[],"checksum":731930661,"timestamp":"2024-06-01T18:07:15.883662Z"}]}
{"channel":"book","type":"update","data":[{"symbol":"DOT/USDT","bids":[{"price":7.0939,"qty":705.42096191}],"asks":[],"checksum":2147852715,"timestamp":"2024-06-01T18:07:16.807037Z"}]}
{"channel":"book","type":"update","data":[{"symbol":"DOT/USDT","bids":[{"price":7.0939,"qty":729.32716191}],"asks":[],"checksum":731930661,"timestamp":"2024-06-01T18:07:16.837709Z"}]}
{"channel":"book","type":"update","data":[{"symbol":"DOT/USDT","bids":[],"asks":[{"price":7.1001,"qty":0.00000000},{"price":7.1002,"qty":704.80477096}],"checksum":1261363672,"timestamp":"2024-06-01T18:07:21.138046Z"}]}
{"channel":"book","type":"update","data":[{"symbol":"DOT/USDT","bids":[],"asks":[{"price":7.0997,"qty":93.94000000}],"checksum":3991983415,"timestamp":"2024-06-01T18:07:21.140364Z"}]}
{"channel":"book","type":"update","data":[{"symbol":"DOT/USDT","bids":[],"asks":[{"price":7.0990,"qty":23.90620000}],"checksum":2719368913,"timestamp":"2024-06-01T18:07:21.148594Z"}]}
{"channel":"book","type":"update","data":[{"symbol":"DOT/USDT","bids":[{"price":7.0939,"qty":705.42096191}],"asks":[],"checksum":162760543,"timestamp":"2024-06-01T18:07:21.435407Z"}]}
{"channel":"book","type":"update","data":[{"symbol":"DOT/USDT","bids":[{"price":7.0945,"qty":0.00000000},{"price":7.0905,"qty":23.90620000}],"asks":[],"checksum":2555898145,"timestamp":"2024-06-01T18:07:21.464004Z"}]}
{"channel":"book","type":"update","data":[{"symbol":"DOT/USDT","bids":[{"price":7.0955,"qty":0.00000000},{"price":7.0898,"qty":84.75558000}],"asks":[],"checksum":976804212,"timestamp":"2024-06-01T18:07:21.490416Z"}]}
{"channel":"book","type":"update","data":[{"symbol":"DOT/USDT","bids":[],"asks":[{"price":7.0980,"qty":0.00000000},{"price":7.1000,"qty":9.67098148}],"checksum":3521982875,"timestamp":"2024-06-01T18:07:21.490517Z"}]}
{"channel":"book","type":"update","data":[{"symbol":"DOT/USDT","bids":[{"price":7.0939,"qty":0.00000000},{"price":7.0897,"qty":23.90620000}],"asks":[],"checksum":3358064430,"timestamp":"2024-06-01T18:07:21.490759Z"}]}
{"channel":"book","type":"update","data":[{"symbol":"DOT/USDT","bids":[{"price":7.0920,"qty":0.00000000},{"price":7.0883,"qty":27.62172694}],"asks":[],"checksum":429315467,"timestamp":"2024-06-01T18:07:21.496089Z"}]}
{"channel":"book","type":"update","data":[{"symbol":"DOT/USDT","bids":[{"price":7.0942,"qty":9.00000000}],"asks":[],"checksum":696716043,"timestamp":"2024-06-01T18:07:21.496240Z"}]}
{"channel":"book","type":"update","data":[{"symbol":"DOT/USDT","bids":[{"price":7.0945,"qty":352.68504513}],"asks":[],"checksum":3699203151,"timestamp":"2024-06-01T18:07:21.498181Z"}]}
{"channel":"book","type":"update","data":[{"symbol":"DOT/USDT","bids":[],"asks":[{"price":7.0971,"qty":361.55639195}],"checksum":3065536952,"timestamp":"2024-06-01T18:07:21.498266Z"}]}
{"channel":"book","type":"update","data":[{"symbol":"DOT/USDT","bids":[],"asks":[{"price":7.0990,"qty":728.83730186}],"checksum":2208543319,"timestamp":"2024-06-01T18:07:21.498311Z"}]}
{"channel":"book","type":"update","data":[{"symbol":"DOT/USDT","bids":[{"price":7.0901,"qty":705.80430440}],"asks":[],"checksum":609591531,"timestamp":"2024-06-01T18:07:21.498526Z"}]}
{"channel":"book","type":"update","data":[{"symbol":"DOT/USDT","bids":[],"asks":[{"price":7.0970,"qty":0.00000000},{"price":7.1002,"qty":704.80477096}],"checksum":316209650,"timestamp":"2024-06-01T18:07:21.505428Z"}]}
{"channel":"book","type":"update","data":[{"symbol":"DOT/USDT","bids":[],"asks":[{"price":7.0964,"qty":33.00000000}],"checksum":800491599,"timestamp":"2024-06-01T18:07:21.505560Z"}]}
{"channel":"book","type":"update","data":[{"symbol":"DOT/USDT","bids":[],"asks":[{"price":7.0964,"qty":64.74523319}],"checksum":1024842871,"timestamp":"2024-06-01T18:07:21.509761Z"}]}
{"channel":"book","type":"update","data":[{"symbol":"DOT/USDT","bids":[],"asks":[{"price":7.0957,"qty":23.90620000}],"checksum":245134304,"timestamp":"2024-06-01T18:07:21.511325Z"}]}
{"channel":"book","type":"update","data":[{"symbol":"DOT/USDT","bids":[],"asks":[{"price":7.0966,"qty":23.90620000}],"checksum":392072425,"timestamp":"2024-06-01T18:07:21.514527Z"}]}
{"channel":"book","type":"update","data":[{"symbol":"DOT/USDT","bids":[],"asks":[{"price":7.0988,"qty":28.30000000}],"checksum":2092730605,"timestamp":"2024-06-01T18:07:21.523548Z"}]}
{"channel":"book","type":"update","data":[{"symbol":"DOT/USDT","bids":[{"price":7.0938,"qty":0.00000000},{"price":7.0898,"qty":84.75558000}],"asks":[],"checksum":4187057506,"timestamp":"2024-06-01T18:07:21.561659Z"}]}
{"channel":"book","type":"update","data":[{"symbol":"DOT/USDT","bids":[{"price":7.0935,"qty":321.64683178}],"asks":[],"checksum":2418244816,"timestamp":"2024-06-01T18:07:21.567244Z"}]}
{"channel":"book","type":"update","data":[{"symbol":"DOT/USDT","bids":[{"price":7.0942,"qty":0.00000000},{"price":7.0898,"qty":84.75558000}],"asks":[],"checksum":1828162606,"timestamp":"2024-06-01T18:07:21.567276Z"}]}
{"channel":"book","type":"update","data":[{"symbol":"DOT/USDT","bids":[{"price":7.0937,"qty":23.90620000}],"asks":[],"checksum":37455139,"timestamp":"2024-06-01T18:07:21.573679Z"}]}
{"channel":"book","type":"update","data":[{"symbol":"DOT/USDT","bids":[],"asks":[{"price":7.0957,"qty":55.65443059}],"checksum":720228035,"timestamp":"2024-06-01T18:07:21.622702Z"}]}
{"channel":"book","type":"update","data":[{"symbol":"DOT/USDT","bids":[],"asks":[{"price":7.0964,"qty":33.00000000}],"checksum":3639026957,"timestamp":"2024-06-01T18:07:21.727547Z"}]}
{"channel":"book","type":"update","data":[{"symbol":"DOT/USDT","bids":[{"price":7.0935,"qty":386.39206497}],"asks":[],"checksum":751003002,"timestamp":"2024-06-01T18:07:21.864299Z"}]}
{"channel":"book","type":"update","data":[{"symbol":"DOT/USDT","bids":[{"price":7.0935,"qty":321.64683178}],"asks":[],"checksum":3639026957,"timestamp":"2024-06-01T18:07:22.172259Z"}]}
{"channel":"book","type":"update","data":[{"symbol":"DOT/USDT","bids":[{"price":7.0935,"qty":378.07352318}],"asks":[],"checksum":817310381,"timestamp":"2024-06-01T18:07:22.483236Z"}]}
{"channel":"book","type":"update","data":[{"symbol":"DOT/USDT","bids":[],"asks":[{"price":7.0957,"qty":31.74823059}],"checksum":1057387462,"timestamp":"2024-06-01T18:07:22.927293Z"}]}
{"channel":"book","type":"update","data":[{"symbol":"DOT/USDT","bids":[],"asks":[{"price":7.0957,"qty":0.00000000},{"price":7.0998,"qty":23.90620000}],"checksum":245019609,"timestamp":"2024-06-01T18:07:22.952949Z"}]}
{"channel":"book","type":"update","data":[{"symbol":"DOT/USDT","bids":[],"asks":[{"price":7.0958,"qty":23.90620000}],"checksum":1449106396,"timestamp":"2024-06-01T18:07:22.960713Z"}]}
{"channel":"book","type":"update","data":[{"symbol":"DOT/USDT","bids":[],"asks":[{"price":7.0958,"qty":0.00000000},{"price":7.0998,"qty":23.90620000}],"checksum":245019609,"timestamp":"2024-06-01T18:07:22.965219Z"}]}
{"channel":"book","type":"update","data":[{"symbol":"DOT/USDT","bids":[],"asks":[{"price":7.0958,"qty":23.90620000}],"checksum":1449106396,"timestamp":"2024-06-01T18:07:22.967890Z"}]}
{"channel":"book","type":"update","data":[{"symbol":"DOT/USDT","bids":[],"asks":[{"price":7.0958,"qty":0.00000000},{"price":7.0998,"qty":23.90620000}],"checksum":245019609,"timestamp":"2024-06-01T18:07:22.971435Z"}]}
{"channel":"book","type":"update","data":[{"symbol":"DOT/USDT","bids":[],"asks":[{"price":7.0958,"qty":23.90620000}],"checksum":1449106396,"timestamp":"2024-06-01T18:07:22.974057Z"}]}
{"channel":"book","type":"update","data":[{"symbol":"DOT/USDT","bids":[],"asks":[{"price":7.0958,"qty":0.00000000},{"price":7.0998,"qty":23.90620000}],"checksum":245019609,"timestamp":"2024-06-01T18:07:22.977250Z"}]}
{"channel":"book","type":"update","data":[{"symbol":"DOT/USDT","bids":[],"asks":[{"price":7.0958,"qty":23.90620000}],"checksum":1449106396,"timestamp":"2024-06-01T18:07:22.979948Z"}]}
{"channel":"book","type":"update","data":[{"symbol":"DOT/USDT","bids":[],"asks":[{"price":7.0958,"qty":0.00000000},{"price":7.0998,"qty":23.90620000}],"checksum":245019609,"timestamp":"2024-06-01T18:07:22.983871Z"}]}
{"channel":"book","type":"update","data":[{"symbol":"DOT/USDT","bids":[],"asks":[{"price":7.0958,"qty":23.90620000}],"checksum":1449106396,"timestamp":"2024-06-01T18:07:22.986493Z"}]}
