{"channel":"book","type":"snapshot","data":[{"symbol":"DOT/EUR","bids":[{"price":6.5437,"qty":94.14000000},{"price":6.5407,"qty":85.80186000},{"price":6.5387,"qty":130.32990000},{"price":6.5383,"qty":130.32990000},{"price":6.5382,"qty":352.53809676},{"price":6.5375,"qty":352.57534505},{"price":6.5366,"qty":14.55489263},{"price":6.5361,"qty":1410.40012794},{"price":6.5359,"qty":281.96000000},{"price":6.5358,"qty":266.30904000}],"asks":[{"price":6.5438,"qty":1354.47956642},{"price":6.5439,"qty":704.46856603},{"price":6.5440,"qty":700.00754856},{"price":6.5446,"qty":352.19587341},{"price":6.5450,"qty":23.50000000},{"price":6.5453,"qty":705.15833086},{"price":6.5456,"qty":352.14054931},{"price":6.5459,"qty":130.32990000},{"price":6.5473,"qty":23.60000000},{"price":6.5481,"qty":70.44000000}],"checksum":177911965}]}
{"channel":"book","type":"update","data":[{"symbol":"DOT/EUR","bids":[],"asks":[{"price":6.5438,"qty":1337.21019498}],"checksum":1883503973,"timestamp":"2024-06-01T18:06:42.595594Z"}]}
{"channel":"book","type":"update","data":[{"symbol":"DOT/EUR","bids":[],"asks":[{"price":6.5438,"qty":1352.07078776}],"checksum":974456693,"timestamp":"2024-06-01T18:06:42.595846Z"}]}
{"channel":"book","type":"update","data":[{"symbol":"DOT/EUR","bids":[],"asks":[{"price":6.5438,"qty":1337.21019498}],"checksum":1883503973,"timestamp":"2024-06-01T18:06:45.125923Z"}]}
{"channel":"book","type":"update","data":[{"symbol":"DOT/EUR","bids":[],"asks":[{"price":6.5438,"qty":1359.29571842}],"checksum":3899311838,"timestamp":"2024-06-01T18:06:45.127211Z"}]}
{"channel":"book","type":"update","data":[{"symbol":"DOT/EUR","bids":[{"price":6.5366,"qty":0.00000000},{"price":6.5357,"qty":200.00000000}],"asks":[],"checksum":1183460265,"timestamp":"2024-06-01T18:06:45.847041Z"}]}
{"channel":"book","type":"update","data":[{"symbol":"DOT/EUR","bids":[{"price":6.5366,"qty":72.66031441}],"asks":[],"checksum":3661534796,"timestamp":"2024-06-01T18:06:45.851200Z"}]}
{"channel":"book","type":"update","data":[{"symbol":"DOT/EUR","bids":[{"price":6.5363,"qty":1410.66052650}],"asks":[],"checksum":1160259708,"timestamp":"2024-06-01T18:06:49.328088Z"}]}
{"channel":"book","type":"update","data":[{"symbol":"DOT/EUR","bids":[],"asks":[{"price":6.5438,"qty":1337.21019498}],"checksum":419654467,"timestamp":"2024-06-01T18:06:50.126626Z"}]}
{"channel":"book","type":"update","data":[{"symbol":"DOT/EUR","bids":[],"asks":[{"price":6.5438,"qty":1354.47957568}],"checksum":185345691,"timestamp":"2024-06-01T18:06:50.127287Z"}]}
{"channel":"book","type":"update","data":[{"symbol":"DOT/EUR","bids":[],"asks":[{"price":6.5440,"qty":0.00000000},{"price":6.5482,"qty":704.00263807}],"checksum":2411165654,"timestamp":"2024-06-01T18:06:51.577167Z"}]}
{"channel":"book","type":"update","data":[{"symbol":"DOT/EUR","bids":[],"asks":[{"price":6.5440,"qty":696.96004856}],"checksum":1197374014,"timestamp":"2024-06-01T18:06:51.580033Z"}]}
{"channel":"book","type":"update","data":[{"symbol":"DOT/EUR","bids":[{"price":6.5437,"qty":0.00000000},{"price":6.5358,"qty":266.30904000}],"asks":[],"checksum":3839807038,"timestamp":"2024-06-01T18:06:51.756935Z"}]}
{"channel":"book","type":"update","data":[{"symbol":"DOT/EUR","bids":[{"price":6.5421,"qty":94.04000000}],"asks":[],"checksum":3648170856,"timestamp":"2024-06-01T18:06:51.759258Z"}]}
{"channel":"book","type":"update","data":[{"symbol":"DOT/EUR","bids":[],"asks":[{"price":6.5438,"qty":1307.67957568}],"checksum":1103414366,"timestamp":"2024-06-01T18:06:51.759569Z"}]}
{"channel":"book","type":"update","data":[{"symbol":"DOT/EUR","bids":[{"price":6.5389,"qty":46.80000000}],"asks":[],"checksum":1403214608,"timestamp":"2024-06-01T18:06:51.759606Z"}]}
{"channel":"book","type":"update","data":[{"symbol":"DOT/EUR","bids":[],"asks":[{"price":6.5436,"qty":46.80000000}],"checksum":1573426220,"timestamp":"2024-06-01T18:06:51.759773Z"}]}
{"channel":"book","type":"update","data":[{"symbol":"DOT/EUR","bids":[{"price":6.5378,"qty":321.64683178}],"asks":[],"checksum":3493297348,"timestamp":"2024-06-01T18:06:51.761205Z"}]}
{"channel":"book","type":"update","data":[{"symbol":"DOT/EUR","bids":[],"asks":[{"price":6.5439,"qty":352.23669840}],"checksum":892302314,"timestamp":"2024-06-01T18:06:51.761269Z"}]}
{"channel":"book","type":"update","data":[{"symbol":"DOT/EUR","bids":[],"asks":[{"price":6.5437,"qty":321.64683178}],"checksum":1269132087,"timestamp":"2024-06-01T18:06:51.761284Z"}]}
{"channel":"book","type":"update","data":[{"symbol":"DOT/EUR","bids":[],"asks":[{"price":6.5446,"qty":0.00000000},{"price":6.5473,"qty":23.60000000}],"checksum":2397156690,"timestamp":"2024-06-01T18:06:51.761337Z"}]}
{"channel":"book","type":"update","data":[{"symbol":"DOT/EUR","bids":[],"asks":[{"price":6.5439,"qty":0.00000000},{"price":6.5481,"qty":70.44000000}],"checksum":2228980736,"timestamp":"2024-06-01T18:06:51.761430Z"}]}
{"channel":"book","type":"update","data":[{"symbol":"DOT/EUR","bids":[],"asks":[{"price":6.5437,"qty":521.64683178}],"checksum":3619728769,"timestamp":"2024-06-01T18:06:51.761869Z"}]}
{"channel":"book","type":"update","data":[{"symbol":"DOT/EUR","bids":[{"price":6.5376,"qty":140.92550145}],"asks":[],"checksum":4133705385,"timestamp":"2024-06-01T18:06:51.762080Z"}]}
{"channel":"book","type":"update","data":[{"symbol":"DOT/EUR","bids":[],"asks":[{"price":6.5435,"qty":63.48184488}],"checksum":2028203210,"timestamp":"2024-06-01T18:06:51.762665Z"}]}
{"channel":"book","type":"update","data":[{"symbol":"DOT/EUR","bids":[],"asks":[{"price":6.5435,"qty":103.48184488}],"checksum":706371940,"timestamp":"2024-06-01T18:06:51.763580Z"}]}
{"channel":"book","type":"update","data":[{"symbol":"DOT/EUR","bids":[],"asks":[{"price":6.5438,"qty":1244.20770909}],"checksum":2680335289,"timestamp":"2024-06-01T18:06:51.763713Z"}]}
{"channel":"book","type":"update","data":[{"symbol":"DOT/EUR","bids":[],"asks":[{"price":6.5436,"qty":0.00000000},{"price":6.5481,"qty":70.44000000}],"checksum":458590581,"timestamp":"2024-06-01T18:06:51.765207Z"}]}
{"channel":"book","type":"update","data":[{"symbol":"DOT/EUR","bids":[],"asks":[{"price":6.5433,"qty":46.80000000}],"checksum":2014284290,"timestamp":"2024-06-01T18:06:51.765414Z"}]}
{"channel":"book","type":"update","data":[{"symbol":"DOT/EUR","bids":[{"price":6.5376,"qty":0.00000000},{"price":6.5363,"qty":1410.66052650}],"asks":[],"checksum":2521479997,"timestamp":"2024-06-01T18:06:51.765721Z"}]}
{"channel":"book","type":"update","data":[{"symbol":"DOT/EUR","bids":[],"asks":[{"price":6.5422,"qty":352.32339558}],"checksum":3423707016,"timestamp":"2024-06-01T18:06:51.768210Z"}]}
{"channel":"book","type":"update","data":[{"symbol":"DOT/EUR","bids":[],"asks":[{"price":6.5435,"qty":455.73524422}],"checksum":3588088975,"timestamp":"2024-06-01T18:06:51.768269Z"}]}
{"channel":"book","type":"update","data":[{"symbol":"DOT/EUR","bids":[],"asks":[{"price":6.5422,"qty":704.64679116}],"checksum":3744649296,"timestamp":"2024-06-01T18:06:51.768373Z"}]}
{"channel":"book","type":"update","data":[{"symbol":"DOT/EUR","bids":[],"asks":[{"price":6.5432,"qty":63.48184488}],"checksum":362672530,"timestamp":"2024-06-01T18:06:51.768411Z"}]}
{"channel":"book","type":"update","data":[{"symbol":"DOT/EUR","bids":[],"asks":[{"price":6.5435,"qty":392.25339934}],"checksum":1604712372,"timestamp":"2024-06-01T18:06:51.768581Z"}]}
{"channel":"book","type":"update","data":[{"symbol":"DOT/EUR","bids":[],"asks":[{"price":6.5422,"qty":768.12863604}],"checksum":2265462549,"timestamp":"2024-06-01T18:06:51.771058Z"}]}
{"channel":"book","type":"update","data":[{"symbol":"DOT/EUR","bids":[],"asks":[{"price":6.5432,"qty":0.00000000},{"price":6.5459,"qty":130.32990000}],"checksum":120751498,"timestamp":"2024-06-01T18:06:51.771192Z"}]}
{"channel":"book","type":"update","data":[{"symbol":"DOT/EUR","bids":[],"asks":[{"price":6.5435,"qty":40.00000000}],"checksum":2489694430,"timestamp":"2024-06-01T18:06:51.772375Z"}]}
{"channel":"book","type":"update","data":[{"symbol":"DOT/EUR","bids":[],"asks":[{"price":6.5438,"qty":1044.20770909}],"checksum":3943379154,"timestamp":"2024-06-01T18:06:51.933942Z"}]}
{"channel":"book","type":"update","data":[{"symbol":"DOT/EUR","bids":[],"asks":[{"price":6.5437,"qty":200.00000000}],"checksum":3629407465,"timestamp":"2024-06-01T18:06:51.937775Z"}]}
{"channel":"book","type":"update","data":[{"symbol":"DOT/EUR","bids":[],"asks":[{"price":6.5438,"qty":722.56087731}],"checksum":1315266123,"timestamp":"2024-06-01T18:06:52.027939Z"}]}
{"channel":"book","type":"update","data":[{"symbol":"DOT/EUR","bids":[],"asks":[{"price":6.5440,"qty":1018.60688034}],"checksum":3852562274,"timestamp":"2024-06-01T18:06:52.212139Z"}]}
{"channel":"book","type":"update","data":[{"symbol":"DOT/EUR","bids":[],"asks":[{"price":6.5438,"qty":705.29149661}],"checksum":359021520,"timestamp":"2024-06-01T18:06:52.633643Z"}]}
{"channel":"book","type":"update","data":[{"symbol":"DOT/EUR","bids":[],"asks":[{"price":6.5436,"qty":16.58056082}],"checksum":1696317827,"timestamp":"2024-06-01T18:06:52.634274Z"}]}
{"channel":"book","type":"update","data":[{"symbol":"DOT/EUR","bids":[],"asks":[{"price":6.5434,"qty":352.25878268}],"checksum":2231718700,"timestamp":"2024-06-01T18:06:53.535486Z"}]}
{"channel":"book","type":"update","data":[{"symbol":"DOT/EUR","bids":[],"asks":[{"price":6.5436,"qty":0.00000000},{"price":6.5456,"qty":352.14054931}],"checksum":2287397028,"timestamp":"2024-06-01T18:06:55.170409Z"}]}
{"channel":"book","type":"update","data":[{"symbol":"DOT/EUR","bids":[],"asks":[{"price":6.5433,"qty":66.47788986}],"checksum":3852679021,"timestamp":"2024-06-01T18:06:55.171084Z"}]}
{"channel":"book","type":"update","data":[{"symbol":"DOT/EUR","bids":[],"asks":[{"price":6.5436,"qty":705.33921000}],"checksum":3620377158,"timestamp":"2024-06-01T18:06:57.693543Z"}]}
{"channel":"book","type":"update","data":[{"symbol":"DOT/EUR","bids":[],"asks":[{"price":6.5438,"qty":0.00000000},{"price":6.5456,"qty":352.14054931}],"checksum":433250387,"timestamp":"2024-06-01T18:06:57.708594Z"}]}
{"channel":"book","type":"update","data":[{"symbol":"DOT/EUR","bids":[{"price":6.5383,"qty":0.00000000},{"price":6.5361,"qty":1410.40012794}],"asks":[],"checksum":3694927282,"timestamp":"2024-06-01T18:06:58.411115Z"}]}
{"channel":"book","type":"update","data":[{"symbol":"DOT/EUR","bids":[{"price":6.5384,"qty":94.04000000}],"asks":[],"checksum":280460890,"timestamp":"2024-06-01T18:06:58.712301Z"}]}
{"channel":"book","type":"update","data":[{"symbol":"DOT/EUR","bids":[],"asks":[{"price":6.5433,"qty":46.80000000}],"checksum":948722767,"timestamp":"2024-06-01T18:07:02.835632Z"}]}
{"channel":"book","type":"update","data":[{"symbol":"DOT/EUR","bids":[],"asks":[{"price":6.5433,"qty":71.63815760}],"checksum":3449597307,"timestamp":"2024-06-01T18:07:02.836808Z"}]}
{"channel":"book","type":"update","data":[{"symbol":"DOT/EUR","bids":[],"asks":[{"price":6.5436,"qty":0.00000000},{"price":6.5459,"qty":130.32990000}],"checksum":3812906305,"timestamp":"2024-06-01T18:07:03.498528Z"}]}
{"channel":"book","type":"update","data":[{"symbol":"DOT/EUR","bids":[],"asks":[{"price":6.5433,"qty":46.80000000}],"checksum":374645877,"timestamp":"2024-06-01T18:07:05.391226Z"}]}
{"channel":"book","type":"update","data":[{"symbol":"DOT/EUR","bids":[],"asks":[{"price":6.5433,"qty":57.87719718}],"checksum":3844549982,"timestamp":"2024-06-01T18:07:05.392816Z"}]}
{"channel":"book","type":"update","data":[{"symbol":"DOT/EUR","bids":[],"asks":[{"price":6.5439,"qty":19.33344188}],"checksum":1336477817,"timestamp":"2024-06-01T18:07:05.392869Z"}]}
{"channel":"book","type":"update","data":[{"symbol":"DOT/EUR","bids":[],"asks":[{"price":6.5439,"qty":724.64481828}],"checksum":19960467,"timestamp":"2024-06-01T18:07:06.611360Z"}]}
{"channel":"book","type":"update","data":[{"symbol":"DOT/EUR","bids":[],"asks":[{"price":6.5440,"qty":696.96004856}],"checksum":3013237363,"timestamp":"2024-06-01T18:07:06.655071Z"}]}
{"channel":"book","type":"update","data":[{"symbol":"DOT/EUR","bids":[{"price":6.5384,"qty":234.96474650}],"asks":[],"checksum":1472911451,"timestamp":"2024-06-01T18:07:06.674785Z"}]}
{"channel":"book","type":"update","data":[{"symbol":"DOT/EUR","bids":[{"price":6.5375,"qty":0.00000000},{"price":6.5361,"qty":1410.40012794}],"asks":[],"checksum":2407419192,"timestamp":"2024-06-01T18:07:06.683598Z"}]}
{"channel":"book","type":"update","data":[{"symbol":"DOT/EUR","bids":[{"price":6.5389,"qty":399.30116243}],"asks":[],"checksum":1204762245,"timestamp":"2024-06-01T18:07:06.687524Z"}]}
{"channel":"book","type":"update","data":[{"symbol":"DOT/EUR","bids":[{"price":6.5364,"qty":352.63530978}],"asks":[],"checksum":988933238,"timestamp":"2024-06-01T18:07:06.687646Z"}]}
{"channel":"book","type":"update","data":[{"symbol":"DOT/EUR","bids":[],"asks":[{"price":6.5422,"qty":704.64679116}],"checksum":3797691607,"timestamp":"2024-06-01T18:07:06.695084Z"}]}
{"channel":"book","type":"update","data":[{"symbol":"DOT/EUR","bids":[],"asks":[{"price":6.5434,"qty":0.00000000},{"price":6.5459,"qty":130.32990000}],"checksum":1162863199,"timestamp":"2024-06-01T18:07:06.697187Z"}]}
{"channel":"book","type":"update","data":[{"symbol":"DOT/EUR","bids":[],"asks":[{"price":6.5444,"qty":352.20638678}],"checksum":2021441051,"timestamp":"2024-06-01T18:07:06.701738Z"}]}
{"channel":"book","type":"update","data":[{"symbol":"DOT/EUR","bids":[],"asks":[{"price":6.5439,"qty":19.33344188}],"checksum":3845905284,"timestamp":"2024-06-01T18:07:06.701953Z"}]}
{"channel":"book","type":"update","data":[{"symbol":"DOT/EUR","bids":[{"price":6.5389,"qty":352.50116243}],"asks":[],"checksum":2561437840,"timestamp":"2024-06-01T18:07:06.709027Z"}]}
{"channel":"book","type":"update","data":[{"symbol":"DOT/EUR","bids":[{"price":6.5408,"qty":46.80000000}],"asks":[],"checksum":2091892961,"timestamp":"2024-06-01T18:07:06.709312Z"}]}
{"channel":"book","type":"update","data":[{"symbol":"DOT/EUR","bids":[],"asks":[{"price":6.5422,"qty":352.32339558}],"checksum":4068840202,"timestamp":"2024-06-01T18:07:06.738021Z"}]}
{"channel":"book","type":"update","data":[{"symbol":"DOT/EUR","bids":[{"price":6.5389,"qty":0.00000000},{"price":6.5363,"qty":1410.66052650}],"asks":[],"checksum":2773320854,"timestamp":"2024-06-01T18:07:06.738176Z"}]}
{"channel":"book","type":"update","data":[{"symbol":"DOT/EUR","bids":[{"price":6.5384,"qty":94.04000000}],"asks":[],"checksum":2533486320,"timestamp":"2024-06-01T18:07:06.742071Z"}]}
{"channel":"book","type":"update","data":[{"symbol":"DOT/EUR","bids":[{"price":6.5387,"qty":271.23178995}],"asks":[],"checksum":517831629,"timestamp":"2024-06-01T18:07:06.742103Z"}]}
{"channel":"book","type":"update","data":[{"symbol":"DOT/EUR","bids":[],"asks":[{"price":6.5433,"qty":410.14235416}],"checksum":389722030,"timestamp":"2024-06-01T18:07:06.743652Z"}]}
{"channel":"book","type":"update","data":[{"symbol":"DOT/EUR","bids":[{"price":6.5366,"qty":0.00000000},{"price":6.5361,"qty":2115.10012794}],"asks":[],"checksum":1986337750,"timestamp":"2024-06-01T18:07:06.939886Z"}]}
{"channel":"book","type":"update","data":[{"symbol":"DOT/EUR","bids":[],"asks":[{"price":6.5440,"qty":0.00000000},{"price":6.5473,"qty":23.60000000}],"checksum":929126587,"timestamp":"2024-06-01T18:07:06.942114Z"}]}
{"channel":"book","type":"update","data":[{"symbol":"DOT/EUR","bids":[{"price":6.5366,"qty":48.63992095}],"asks":[],"checksum":1433757792,"timestamp":"2024-06-01T18:07:06.944604Z"}]}
{"channel":"book","type":"update","data":[{"symbol":"DOT/EUR","bids":[],"asks":[{"price":6.5431,"qty":175.08254856}],"checksum":1178557549,"timestamp":"2024-06-01T18:07:06.947325Z"}]}
{"channel":"book","type":"update","data":[{"symbol":"DOT/EUR","bids":[],"asks":[{"price":6.5450,"qty":345.14683178}],"checksum":50478860,"timestamp":"2024-06-01T18:07:06.951701Z"}]}
{"channel":"book","type":"update","data":[{"symbol":"DOT/EUR","bids":[],"asks":[{"price":6.5444,"qty":0.00000000},{"price":6.5471,"qty":352.50116243}],"checksum":3354318561,"timestamp":"2024-06-01T18:07:07.190206Z"}]}
{"channel":"book","type":"update","data":[{"symbol":"DOT/EUR","bids":[{"price":6.5399,"qty":352.44651561}],"asks":[],"checksum":321359890,"timestamp":"2024-06-01T18:07:07.193507Z"}]}
{"channel":"book","type":"update","data":[{"symbol":"DOT/EUR","bids":[],"asks":[{"price":6.5449,"qty":705.24080819}],"checksum":4288142276,"timestamp":"2024-06-01T18:07:07.424695Z"}]}
{"channel":"book","type":"update","data":[{"symbol":"DOT/EUR","bids":[],"asks":[{"price":6.5456,"qty":0.00000000},{"price":6.5460,"qty":94.04000000}],"checksum":4275883570,"timestamp":"2024-06-01T18:07:07.841703Z"}]}
{"channel":"book","type":"update","data":[{"symbol":"DOT/EUR","bids":[],"asks":[{"price":6.5447,"qty":352.19016483}],"checksum":2432319734,"timestamp":"2024-06-01T18:07:07.845611Z"}]}
{"channel":"book","type":"update","data":[{"symbol":"DOT/EUR","bids":[{"price":6.5394,"qty":352.47414576}],"asks":[],"checksum":946565347,"timestamp":"2024-06-01T18:07:07.845698Z"}]}
{"channel":"book","type":"update","data":[{"symbol":"DOT/EUR","bids":[{"price":6.5387,"qty":130.32990000}],"asks":[],"checksum":1428079207,"timestamp":"2024-06-01T18:07:07.850180Z"}]}
{"channel":"book","type":"update","data":[{"symbol":"DOT/EUR","bids":[{"price":6.5382,"qty":0.00000000},{"price":6.5364,"qty":352.63530978}],"asks":[],"checksum":2017683290,"timestamp":"2024-06-01T18:07:07.861543Z"}]}
{"channel":"book","type":"update","data":[{"symbol":"DOT/EUR","bids":[],"asks":[{"price":6.5433,"qty":399.06515698}],"checksum":2794361733,"timestamp":"2024-06-01T18:07:07.897629Z"}]}
{"channel":"book","type":"update","data":[{"symbol":"DOT/EUR","bids":[],"asks":[{"price":6.5439,"qty":0.00000000},{"price":6.5460,"qty":94.04000000}],"checksum":1011153193,"timestamp":"2024-06-01T18:07:07.897706Z"}]}
{"channel":"book","type":"update","data":[{"symbol":"DOT/EUR","bids":[],"asks":[{"price":6.5448,"qty":19.32978565}],"checksum":3757983964,"timestamp":"2024-06-01T18:07:07.898989Z"}]}
{"channel":"book","type":"update","data":[{"symbol":"DOT/EUR","bids":[{"price":6.5387,"qty":0.00000000},{"price":6.5363,"qty":1410.66052650}],"asks":[],"checksum":42143879,"timestamp":"2024-06-01T18:07:08.980051Z"}]}
{"channel":"book","type":"update","data":[{"symbol":"DOT/EUR","bids":[{"price":6.5408,"qty":177.12990000}],"asks":[],"checksum":234615261,"timestamp":"2024-06-01T18:07:08.982713Z"}]}
{"channel":"book","type":"update","data":[{"symbol":"DOT/EUR","bids":[{"price":6.5370,"qty":1410.48161639}],"asks":[],"checksum":712761449,"timestamp":"2024-06-01T18:07:10.189438Z"}]}
{"channel":"book","type":"update","data":[{"symbol":"DOT/EUR","bids":[],"asks":[{"price":6.5448,"qty":0.00000000},{"price":6.5460,"qty":94.04000000}],"checksum":4292252977,"timestamp":"2024-06-01T18:07:10.374416Z"}]}
{"channel":"book","type":"update","data":[{"symbol":"DOT/EUR","bids":[],"asks":[{"price":6.5446,"qty":18.30113243}],"checksum":162964887,"timestamp":"2024-06-01T18:07:10.375761Z"}]}
{"channel":"book","type":"update","data":[{"symbol":"DOT/EUR","bids":[{"price":6.5399,"qty":0.00000000},{"price":6.5363,"qty":1410.66052650}],"asks":[],"checksum":3968328617,"timestamp":"2024-06-01T18:07:11.061160Z"}]}
{"channel":"book","type":"update","data":[{"symbol":"DOT/EUR","bids":[{"price":6.5387,"qty":352.50751412}],"asks":[],"checksum":1652577763,"timestamp":"2024-06-01T18:07:11.064916Z"}]}
{"channel":"book","type":"update","data":[{"symbol":"DOT/EUR","bids":[],"asks":[{"price":6.5422,"qty":415.79610111}],"checksum":1656711924,"timestamp":"2024-06-01T18:07:11.222762Z"}]}
{"channel":"book","type":"update","data":[{"symbol":"DOT/EUR","bids":[{"price":6.5408,"qty":130.32990000}],"asks":[],"checksum":297099200,"timestamp":"2024-06-01T18:07:11.234025Z"}]}
{"channel":"book","type":"update","data":[{"symbol":"DOT/EUR","bids":[],"asks":[{"price":6.5433,"qty":46.80000000}],"checksum":2212570527,"timestamp":"2024-06-01T18:07:11.262133Z"}]}
{"channel":"book","type":"update","data":[{"symbol":"DOT/EUR","bids":[],"asks":[{"price":6.5426,"qty":352.30681603}],"checksum":25797073,"timestamp":"2024-06-01T18:07:11.265550Z"}]}
{"channel":"book","type":"update","data":[{"symbol":"DOT/EUR","bids":[],"asks":[{"price":6.5440,"qty":321.64683178}],"checksum":3362751995,"timestamp":"2024-06-01T18:07:11.266148Z"}]}
