{"channel":"book","type":"snapshot","data":[{"symbol":"ETH/AUD","bids":[{"price":5716.53,"qty":1.03599864},{"price":5716.52,"qty":0.06653400},{"price":5715.79,"qty":0.07347674},{"price":5715.78,"qty":3.12363012},{"price":5715.35,"qty":0.90387105},{"price":5712.09,"qty":0.02406309},{"price":5712.08,"qty":2.12927000},{"price":5710.06,"qty":0.08300000},{"price":5709.81,"qty":0.81788582},{"price":5709.80,"qty":9.25422691}],"asks":[{"price":5718.50,"qty":0.01292326},{"price":5719.19,"qty":0.45805256},{"price":5719.20,"qty":0.90387105},{"price":5719.46,"qty":0.06651200},{"price":5721.39,"qty":0.52250000},{"price":5721.40,"qty":10.92294707},{"price":5721.41,"qty":0.06783012},{"price":5721.53,"qty":11.16971605},{"price":5724.84,"qty":0.83372964},{"price":5724.85,"qty":0.09900000}],"checksum":3663854377}]}
{"channel":"book","type":"update","data":[{"symbol":"ETH/AUD","bids":[],"asks":[{"price":5719.46,"qty":0.00000000},{"price":5726.77,"qty":1.60677000},{"price":5719.95,"qty":0.06650800}],"checksum":2558802113,"timestamp":"2024-06-01T18:06:01.558982Z"}]}
{"channel":"book","type":"update","data":[{"symbol":"ETH/AUD","bids":[{"price":5709.82,"qty":0.02406309}],"asks":[],"checksum":2345426059,"timestamp":"2024-06-01T18:06:01.594390Z"}]}
{"channel":"book","type":"update","data":[{"symbol":"ETH/AUD","bids":[{"price":5712.09,"qty":0.00000000},{"price":5709.80,"qty":9.25422691}],"asks":[],"checksum":727319654,"timestamp":"2024-06-01T18:06:01.772852Z"}]}
{"channel":"book","type":"update","data":[{"symbol":"ETH/AUD","bids":[],"asks":[{"price":5721.40,"qty":0.00000000},{"price":5726.77,"qty":1.60677000}],"checksum":3607123293,"timestamp":"2024-06-01T18:06:02.125066Z"}]}
{"channel":"book","type":"update","data":[{"symbol":"ETH/AUD","bids":[],"asks":[{"price":5721.39,"qty":0.00000000},{"price":5728.07,"qty":0.10100000},{"price":5721.52,"qty":0.52250000}],"checksum":2594683659,"timestamp":"2024-06-01T18:06:02.128369Z"}]}
{"channel":"book","type":"update","data":[{"symbol":"ETH/AUD","bids":[],"asks":[{"price":5721.52,"qty":3.08913221}],"checksum":2099395497,"timestamp":"2024-06-01T18:06:02.129944Z"}]}
{"channel":"book","type":"update","data":[{"symbol":"ETH/AUD","bids":[],"asks":[{"price":5721.38,"qty":7.24211117}],"checksum":2050126893,"timestamp":"2024-06-01T18:06:02.130158Z"}]}
{"channel":"book","type":"update","data":[{"symbol":"ETH/AUD","bids":[],"asks":[{"price":5721.41,"qty":0.00000000},{"price":5726.77,"qty":1.60677000}],"checksum":1703694529,"timestamp":"2024-06-01T18:06:02.607137Z"}]}
{"channel":"book","type":"update","data":[{"symbol":"ETH/AUD","bids":[],"asks":[{"price":5721.37,"qty":0.06011049}],"checksum":4031548106,"timestamp":"2024-06-01T18:06:02.609404Z"}]}
{"channel":"book","type":"update","data":[{"symbol":"ETH/AUD","bids":[{"price":5709.80,"qty":0.00000000},{"price":5709.79,"qty":2.35323000}],"asks":[],"checksum":3601820469,"timestamp":"2024-06-01T18:06:02.862387Z"}]}
{"channel":"book","type":"update","data":[{"symbol":"ETH/AUD","bids":[{"price":5709.83,"qty":9.76715060}],"asks":[],"checksum":4003788099,"timestamp":"2024-06-01T18:06:02.863030Z"}]}
{"channel":"book","type":"update","data":[{"symbol":"ETH/AUD","bids":[],"asks":[{"price":5721.52,"qty":2.56663221},{"price":5721.37,"qty":0.58261049}],"checksum":1700834766,"timestamp":"2024-06-01T18:06:02.865355Z"}]}
{"channel":"book","type":"update","data":[{"symbol":"ETH/AUD","bids":[{"price":5709.81,"qty":0.07200511}],"asks":[],"checksum":3443417095,"timestamp":"2024-06-01T18:06:02.867792Z"}]}
{"channel":"book","type":"update","data":[{"symbol":"ETH/AUD","bids":[{"price":5710.07,"qty":0.74584675}],"asks":[],"checksum":3245314643,"timestamp":"2024-06-01T18:06:02.867920Z"}]}
{"channel":"book","type":"update","data":[{"symbol":"ETH/AUD","bids":[],"asks":[{"price":5721.53,"qty":0.00000000},{"price":5726.77,"qty":1.60677000}],"checksum":3791161042,"timestamp":"2024-06-01T18:06:03.619291Z"}]}
{"channel":"book","type":"update","data":[{"symbol":"ETH/AUD","bids":[],"asks":[{"price":5721.68,"qty":11.16970627}],"checksum":2702349772,"timestamp":"2024-06-01T18:06:03.623411Z"}]}
{"channel":"book","type":"update","data":[{"symbol":"ETH/AUD","bids":[],"asks":[{"price":5721.52,"qty":0.00000000},{"price":5726.77,"qty":1.60677000}],"checksum":2457373552,"timestamp":"2024-06-01T18:06:04.571428Z"}]}
{"channel":"book","type":"update","data":[{"symbol":"ETH/AUD","bids":[],"asks":[{"price":5721.38,"qty":0.00000000},{"price":5728.07,"qty":0.10100000}],"checksum":250147721,"timestamp":"2024-06-01T18:06:04.572827Z"}]}
{"channel":"book","type":"update","data":[{"symbol":"ETH/AUD","bids":[],"asks":[{"price":5721.37,"qty":0.06011049},{"price":5721.67,"qty":0.52250000}],"checksum":2339371300,"timestamp":"2024-06-01T18:06:04.576226Z"}]}
{"channel":"book","type":"update","data":[{"symbol":"ETH/AUD","bids":[],"asks":[{"price":5721.36,"qty":3.10926704}],"checksum":25264381,"timestamp":"2024-06-01T18:06:04.578792Z"}]}
{"channel":"book","type":"update","data":[{"symbol":"ETH/AUD","bids":[],"asks":[{"price":5721.67,"qty":7.73732205}],"checksum":4270489506,"timestamp":"2024-06-01T18:06:04.578874Z"}]}
{"channel":"book","type":"update","data":[{"symbol":"ETH/AUD","bids":[],"asks":[{"price":5719.95,"qty":0.00000000},{"price":5726.77,"qty":1.60677000},{"price":5719.64,"qty":0.06651000}],"checksum":1113138896,"timestamp":"2024-06-01T18:06:04.748758Z"}]}
{"channel":"book","type":"update","data":[{"symbol":"ETH/AUD","bids":[],"asks":[{"price":5721.67,"qty":7.21482205},{"price":5721.35,"qty":0.52250000}],"checksum":4040090524,"timestamp":"2024-06-01T18:06:05.213497Z"}]}
{"channel":"book","type":"update","data":[{"symbol":"ETH/AUD","bids":[{"price":5709.83,"qty":0.00000000},{"price":5709.81,"qty":0.07200511}],"asks":[],"checksum":2213334147,"timestamp":"2024-06-01T18:06:05.885828Z"}]}
{"channel":"book","type":"update","data":[{"symbol":"ETH/AUD","bids":[{"price":5710.08,"qty":9.25388629}],"asks":[],"checksum":1452361371,"timestamp":"2024-06-01T18:06:05.886240Z"}]}
{"channel":"book","type":"update","data":[{"symbol":"ETH/AUD","bids":[{"price":5710.07,"qty":0.00000000},{"price":5709.81,"qty":0.07200511}],"asks":[],"checksum":2219266324,"timestamp":"2024-06-01T18:06:05.898558Z"}]}
{"channel":"book","type":"update","data":[{"symbol":"ETH/AUD","bids":[{"price":5710.09,"qty":0.74584414}],"asks":[],"checksum":2638620765,"timestamp":"2024-06-01T18:06:05.899176Z"}]}
{"channel":"book","type":"update","data":[{"symbol":"ETH/AUD","bids":[{"price":5710.10,"qty":0.07200322}],"asks":[],"checksum":1122981938,"timestamp":"2024-06-01T18:06:06.255645Z"}]}
{"channel":"book","type":"update","data":[{"symbol":"ETH/AUD","bids":[],"asks":[{"price":5721.36,"qty":0.00000000},{"price":5724.85,"qty":0.09900000}],"checksum":2861182302,"timestamp":"2024-06-01T18:06:06.916293Z"}]}
{"channel":"book","type":"update","data":[{"symbol":"ETH/AUD","bids":[],"asks":[{"price":5721.67,"qty":0.00000000},{"price":5726.77,"qty":1.60677000}],"checksum":3481839599,"timestamp":"2024-06-01T18:06:06.916489Z"}]}
{"channel":"book","type":"update","data":[{"symbol":"ETH/AUD","bids":[],"asks":[{"price":5721.35,"qty":0.00000000},{"price":5728.07,"qty":0.10100000},{"price":5721.66,"qty":0.52250000}],"checksum":2063244777,"timestamp":"2024-06-01T18:06:06.919929Z"}]}
{"channel":"book","type":"update","data":[{"symbol":"ETH/AUD","bids":[],"asks":[{"price":5721.34,"qty":3.10926704}],"checksum":672363886,"timestamp":"2024-06-01T18:06:06.921722Z"}]}
{"channel":"book","type":"update","data":[{"symbol":"ETH/AUD","bids":[],"asks":[{"price":5721.67,"qty":6.69947761}],"checksum":128148945,"timestamp":"2024-06-01T18:06:06.921807Z"}]}
{"channel":"book","type":"update","data":[{"symbol":"ETH/AUD","bids":[],"asks":[{"price":5721.37,"qty":0.00000000},{"price":5724.85,"qty":0.09900000}],"checksum":3448378297,"timestamp":"2024-06-01T18:06:07.163282Z"}]}
{"channel":"book","type":"update","data":[{"symbol":"ETH/AUD","bids":[],"asks":[{"price":5721.34,"qty":3.17465927}],"checksum":2708101527,"timestamp":"2024-06-01T18:06:07.164706Z"}]}
{"channel":"book","type":"update","data":[{"symbol":"ETH/AUD","bids":[{"price":5710.08,"qty":0.00000000},{"price":5709.82,"qty":0.02406309}],"asks":[],"checksum":2231800036,"timestamp":"2024-06-01T18:06:08.935209Z"}]}
{"channel":"book","type":"update","data":[{"symbol":"ETH/AUD","bids":[{"price":5710.11,"qty":9.25388629}],"asks":[],"checksum":1186954526,"timestamp":"2024-06-01T18:06:08.936497Z"}]}
{"channel":"book","type":"update","data":[{"symbol":"ETH/AUD","bids":[],"asks":[{"price":5721.66,"qty":0.00000000},{"price":5726.77,"qty":1.60677000},{"price":5721.33,"qty":0.52250000}],"checksum":783247001,"timestamp":"2024-06-01T18:06:08.938255Z"}]}
{"channel":"book","type":"update","data":[{"symbol":"ETH/AUD","bids":[{"price":5710.09,"qty":0.00000000},{"price":5709.82,"qty":0.02406309}],"asks":[],"checksum":3346893397,"timestamp":"2024-06-01T18:06:08.970248Z"}]}
{"channel":"book","type":"update","data":[{"symbol":"ETH/AUD","bids":[{"price":5710.12,"qty":0.74584022}],"asks":[],"checksum":3395786745,"timestamp":"2024-06-01T18:06:08.970294Z"}]}
{"channel":"book","type":"update","data":[{"symbol":"ETH/AUD","bids":[],"asks":[{"price":5721.34,"qty":0.06539223}],"checksum":3977905287,"timestamp":"2024-06-01T18:06:09.366137Z"}]}
{"channel":"book","type":"update","data":[{"symbol":"ETH/AUD","bids":[],"asks":[{"price":5721.67,"qty":0.00000000},{"price":5726.77,"qty":1.60677000}],"checksum":1121280820,"timestamp":"2024-06-01T18:06:09.366468Z"}]}
{"channel":"book","type":"update","data":[{"symbol":"ETH/AUD","bids":[],"asks":[{"price":5721.67,"qty":6.18413318}],"checksum":3332933742,"timestamp":"2024-06-01T18:06:09.371957Z"}]}
{"channel":"book","type":"update","data":[{"symbol":"ETH/AUD","bids":[],"asks":[{"price":5721.32,"qty":3.10926704}],"checksum":523309042,"timestamp":"2024-06-01T18:06:09.372011Z"}]}
{"channel":"book","type":"update","data":[{"symbol":"ETH/AUD","bids":[],"asks":[{"price":5721.33,"qty":0.00000000},{"price":5724.85,"qty":0.09900000},{"price":5721.31,"qty":0.52250000}],"checksum":3414167627,"timestamp":"2024-06-01T18:06:09.551525Z"}]}
{"channel":"book","type":"update","data":[{"symbol":"ETH/AUD","bids":[],"asks":[{"price":5721.68,"qty":0.00000000},{"price":5724.85,"qty":0.09900000}],"checksum":3796952670,"timestamp":"2024-06-01T18:06:09.561040Z"}]}
{"channel":"book","type":"update","data":[{"symbol":"ETH/AUD","bids":[],"asks":[{"price":5721.76,"qty":11.16970627}],"checksum":174702906,"timestamp":"2024-06-01T18:06:09.565630Z"}]}
{"channel":"book","type":"update","data":[{"symbol":"ETH/AUD","bids":[],"asks":[{"price":5721.76,"qty":0.00000000},{"price":5724.85,"qty":0.09900000}],"checksum":3796952670,"timestamp":"2024-06-01T18:06:09.568254Z"}]}
{"channel":"book","type":"update","data":[{"symbol":"ETH/AUD","bids":[],"asks":[{"price":5721.82,"qty":11.16970627}],"checksum":586326796,"timestamp":"2024-06-01T18:06:09.573137Z"}]}
{"channel":"book","type":"update","data":[{"symbol":"ETH/AUD","bids":[{"price":5716.54,"qty":0.90387105}],"asks":[],"checksum":2498051942,"timestamp":"2024-06-01T18:06:09.676072Z"}]}
{"channel":"book","type":"update","data":[{"symbol":"ETH/AUD","bids":[{"price":5715.35,"qty":0.00000000},{"price":5710.06,"qty":0.08300000}],"asks":[],"checksum":478889741,"timestamp":"2024-06-01T18:06:09.683336Z"}]}
{"channel":"book","type":"update","data":[{"symbol":"ETH/AUD","bids":[{"price":5716.53,"qty":0.00000000},{"price":5709.82,"qty":0.02406309},{"price":5716.55,"qty":1.03598640}],"asks":[],"checksum":1874945130,"timestamp":"2024-06-01T18:06:09.734518Z"}]}
{"channel":"book","type":"update","data":[{"symbol":"ETH/AUD","bids":[{"price":5716.56,"qty":0.90387105}],"asks":[],"checksum":2469136463,"timestamp":"2024-06-01T18:06:09.740859Z"}]}
{"channel":"book","type":"update","data":[{"symbol":"ETH/AUD","bids":[{"price":5716.55,"qty":0.00000000},{"price":5710.06,"qty":0.08300000},{"price":5716.57,"qty":1.03598278}],"asks":[],"checksum":2868798837,"timestamp":"2024-06-01T18:06:09.796416Z"}]}
{"channel":"book","type":"update","data":[{"symbol":"ETH/AUD","bids":[{"price":5716.56,"qty":0.00000000},{"price":5710.06,"qty":0.08300000}],"asks":[],"checksum":2855863622,"timestamp":"2024-06-01T18:06:09.801627Z"}]}
{"channel":"book","type":"update","data":[{"symbol":"ETH/AUD","bids":[{"price":5716.58,"qty":0.90387105}],"asks":[],"checksum":667595565,"timestamp":"2024-06-01T18:06:09.801670Z"}]}
{"channel":"book","type":"update","data":[{"symbol":"ETH/AUD","bids":[{"price":5716.57,"qty":0.00000000},{"price":5710.06,"qty":0.08300000},{"price":5716.59,"qty":1.03597915}],"asks":[],"checksum":3229437404,"timestamp":"2024-06-01T18:06:09.867899Z"}]}
{"channel":"book","type":"update","data":[{"symbol":"ETH/AUD","bids":[{"price":5716.60,"qty":0.90387105}],"asks":[],"checksum":3261686363,"timestamp":"2024-06-01T18:06:09.872952Z"}]}
{"channel":"book","type":"update","data":[{"symbol":"ETH/AUD","bids":[{"price":5716.58,"qty":0.00000000},{"price":5710.10,"qty":0.07200322}],"asks":[],"checksum":1665945767,"timestamp":"2024-06-01T18:06:09.873058Z"}]}
{"channel":"book","type":"update","data":[{"symbol":"ETH/AUD","bids":[{"price":5716.59,"qty":0.00000000},{"price":5710.06,"qty":0.08300000},{"price":5716.61,"qty":1.03597542}],"asks":[],"checksum":2412628282,"timestamp":"2024-06-01T18:06:09.943004Z"}]}
{"channel":"book","type":"update","data":[{"symbol":"ETH/AUD","bids":[{"price":5716.60,"qty":0.00000000},{"price":5710.06,"qty":0.08300000}],"asks":[],"checksum":3370484713,"timestamp":"2024-06-01T18:06:09.948037Z"}]}
{"channel":"book","type":"update","data":[{"symbol":"ETH/AUD","bids":[{"price":5716.62,"qty":0.90387105}],"asks":[],"checksum":609329223,"timestamp":"2024-06-01T18:06:09.948214Z"}]}
{"channel":"book","type":"update","data":[{"symbol":"ETH/AUD","bids":[{"price":5716.61,"qty":0.00000000},{"price":5710.06,"qty":0.08300000},{"price":5716.63,"qty":1.03597180}],"asks":[],"checksum":3357001438,"timestamp":"2024-06-01T18:06:10.017020Z"}]}
{"channel":"book","type":"update","data":[{"symbol":"ETH/AUD","bids":[{"price":5716.62,"qty":0.00000000},{"price":5710.06,"qty":0.08300000}],"asks":[],"checksum":1498006468,"timestamp":"2024-06-01T18:06:10.022303Z"}]}
{"channel":"book","type":"update","data":[{"symbol":"ETH/AUD","bids":[{"price":5716.63,"qty":0.00000000},{"price":5709.82,"qty":0.02406309},{"price":5716.55,"qty":1.03598630}],"asks":[],"checksum":4106767786,"timestamp":"2024-06-01T18:06:10.080855Z"}]}
{"channel":"book","type":"update","data":[{"symbol":"ETH/AUD","bids":[{"price":5716.56,"qty":0.90387105}],"asks":[],"checksum":843636246,"timestamp":"2024-06-01T18:06:10.085975Z"}]}
{"channel":"book","type":"update","data":[{"symbol":"ETH/AUD","bids":[{"price":5716.55,"qty":0.00000000},{"price":5710.06,"qty":0.08300000},{"price":5716.57,"qty":1.03598260}],"asks":[],"checksum":327367210,"timestamp":"2024-06-01T18:06:10.142412Z"}]}
{"channel":"book","type":"update","data":[{"symbol":"ETH/AUD","bids":[{"price":5716.56,"qty":0.00000000},{"price":5710.06,"qty":0.08300000}],"asks":[],"checksum":2981253936,"timestamp":"2024-06-01T18:06:10.149233Z"}]}
{"channel":"book","type":"update","data":[{"symbol":"ETH/AUD","bids":[{"price":5716.58,"qty":0.90387105}],"asks":[],"checksum":3945014250,"timestamp":"2024-06-01T18:06:10.149247Z"}]}
{"channel":"book","type":"update","data":[{"symbol":"ETH/AUD","bids":[{"price":5716.54,"qty":0.00000000},{"price":5710.06,"qty":0.08300000}],"asks":[],"checksum":2372477230,"timestamp":"2024-06-01T18:06:10.176182Z"}]}
{"channel":"book","type":"update","data":[{"symbol":"ETH/AUD","bids":[{"price":5716.57,"qty":0.00000000},{"price":5709.82,"qty":0.02406309},{"price":5716.59,"qty":1.03597898}],"asks":[],"checksum":4044621990,"timestamp":"2024-06-01T18:06:10.257582Z"}]}
{"channel":"book","type":"update","data":[{"symbol":"ETH/AUD","bids":[{"price":5716.60,"qty":0.90387105}],"asks":[],"checksum":1220324555,"timestamp":"2024-06-01T18:06:10.262343Z"}]}
{"channel":"book","type":"update","data":[{"symbol":"ETH/AUD","bids":[{"price":5716.59,"qty":0.00000000},{"price":5710.06,"qty":0.08300000},{"price":5716.61,"qty":1.03597535}],"asks":[],"checksum":292904665,"timestamp":"2024-06-01T18:06:10.334362Z"}]}
{"channel":"book","type":"update","data":[{"symbol":"ETH/AUD","bids":[{"price":5716.60,"qty":0.00000000},{"price":5710.06,"qty":0.08300000}],"asks":[],"checksum":1157499040,"timestamp":"2024-06-01T18:06:10.339920Z"}]}
{"channel":"book","type":"update","data":[{"symbol":"ETH/AUD","bids":[{"price":5716.62,"qty":0.90387105}],"asks":[],"checksum":2923308037,"timestamp":"2024-06-01T18:06:10.340138Z"}]}
{"channel":"book","type":"update","data":[{"symbol":"ETH/AUD","bids":[{"price":5710.10,"qty":0.00000000},{"price":5710.06,"qty":0.08300000}],"asks":[],"checksum":2621450106,"timestamp":"2024-06-01T18:06:10.364024Z"}]}
{"channel":"book","type":"update","data":[{"symbol":"ETH/AUD","bids":[{"price":5710.13,"qty":0.06686773}],"asks":[],"checksum":1469828876,"timestamp":"2024-06-01T18:06:10.364254Z"}]}
{"channel":"book","type":"update","data":[{"symbol":"ETH/AUD","bids":[{"price":5716.61,"qty":0.00000000},{"price":5710.06,"qty":0.08300000},{"price":5716.63,"qty":1.03597168}],"asks":[],"checksum":3387974514,"timestamp":"2024-06-01T18:06:10.442197Z"}]}
{"channel":"book","type":"update","data":[{"symbol":"ETH/AUD","bids":[{"price":5716.62,"qty":0.00000000},{"price":5710.06,"qty":0.08300000}],"asks":[],"checksum":4216444928,"timestamp":"2024-06-01T18:06:10.447747Z"}]}
{"channel":"book","type":"update","data":[{"symbol":"ETH/AUD","bids":[{"price":5716.63,"qty":0.00000000},{"price":5709.82,"qty":0.02406309},{"price":5716.59,"qty":1.03597893}],"asks":[],"checksum":930391815,"timestamp":"2024-06-01T18:06:10.502608Z"}]}
{"channel":"book","type":"update","data":[{"symbol":"ETH/AUD","bids":[{"price":5716.60,"qty":0.90387105}],"asks":[],"checksum":41518395,"timestamp":"2024-06-01T18:06:10.508351Z"}]}
{"channel":"book","type":"update","data":[{"symbol":"ETH/AUD","bids":[{"price":5716.59,"qty":0.00000000},{"price":5710.06,"qty":0.08300000},{"price":5716.61,"qty":1.03597527}],"asks":[],"checksum":4186958456,"timestamp":"2024-06-01T18:06:10.574403Z"}]}
{"channel":"book","type":"update","data":[{"symbol":"ETH/AUD","bids":[{"price":5716.60,"qty":0.00000000},{"price":5710.06,"qty":0.08300000}],"asks":[],"checksum":3360415788,"timestamp":"2024-06-01T18:06:10.580353Z"}]}
{"channel":"book","type":"update","data":[{"symbol":"ETH/AUD","bids":[{"price":5716.62,"qty":0.90387105}],"asks":[],"checksum":2655143999,"timestamp":"2024-06-01T18:06:10.580526Z"}]}
{"channel":"book","type":"update","data":[{"symbol":"ETH/AUD","bids":[{"price":5716.58,"qty":0.00000000},{"price":5710.06,"qty":0.08300000}],"asks":[],"checksum":1704200992,"timestamp":"2024-06-01T18:06:10.677702Z"}]}
{"channel":"book","type":"update","data":[{"symbol":"ETH/AUD","bids":[{"price":5716.61,"qty":0.00000000},{"price":5709.82,"qty":0.02406309},{"price":5716.63,"qty":1.03597164}],"asks":[],"checksum":3328221282,"timestamp":"2024-06-01T18:06:10.710963Z"}]}
{"channel":"book","type":"update","data":[{"symbol":"ETH/AUD","bids":[],"asks":[{"price":5721.34,"qty":0.00000000},{"price":5724.85,"qty":0.09900000}],"checksum":930995731,"timestamp":"2024-06-01T18:06:10.983655Z"}]}
{"channel":"book","type":"update","data":[{"symbol":"ETH/AUD","bids":[],"asks":[{"price":5721.30,"qty":0.05889158}],"checksum":950248256,"timestamp":"2024-06-01T18:06:10.985173Z"}]}
{"channel":"book","type":"update","data":[{"symbol":"ETH/AUD","bids":[],"asks":[{"price":5721.67,"qty":0.00000000},{"price":5724.85,"qty":0.09900000}],"checksum":2828757665,"timestamp":"2024-06-01T18:06:11.818319Z"}]}
{"channel":"book","type":"update","data":[{"symbol":"ETH/AUD","bids":[],"asks":[{"price":5721.32,"qty":0.00000000},{"price":5726.77,"qty":1.60677000}],"checksum":1793384444,"timestamp":"2024-06-01T18:06:11.818383Z"}]}
{"channel":"book","type":"update","data":[{"symbol":"ETH/AUD","bids":[],"asks":[{"price":5721.81,"qty":10.34173417}],"checksum":123436663,"timestamp":"2024-06-01T18:06:11.823622Z"}]}
{"channel":"book","type":"update","data":[{"symbol":"ETH/AUD","bids":[],"asks":[{"price":5721.31,"qty":0.00000000},{"price":5726.77,"qty":1.60677000},{"price":5721.80,"qty":0.52250000}],"checksum":3280182009,"timestamp":"2024-06-01T18:06:11.827040Z"}]}
{"channel":"book","type":"update","data":[{"symbol":"ETH/AUD","bids":[],"asks":[{"price":5721.82,"qty":0.00000000},{"price":5726.77,"qty":1.60677000}],"checksum":3048481784,"timestamp":"2024-06-01T18:06:11.920595Z"}]}
{"channel":"book","type":"update","data":[{"symbol":"ETH/AUD","bids":[],"asks":[{"price":5721.94,"qty":11.16960848}],"checksum":2093008661,"timestamp":"2024-06-01T18:06:11.925818Z"}]}
{"channel":"book","type":"update","data":[{"symbol":"ETH/AUD","bids":[{"price":5710.11,"qty":0.00000000},{"price":5709.82,"qty":0.02406309}],"asks":[],"checksum":2909499432,"timestamp":"2024-06-01T18:06:11.940320Z"}]}
{"channel":"book","type":"update","data":[{"symbol":"ETH/AUD","bids":[{"price":5712.09,"qty":0.52622483}],"asks":[],"checksum":2257554580,"timestamp":"2024-06-01T18:06:11.941058Z"}]}
{"channel":"book","type":"update","data":[{"symbol":"ETH/AUD","bids":[{"price":5710.14,"qty":8.21404064}],"asks":[],"checksum":2494120387,"timestamp":"2024-06-01T18:06:11.941166Z"}]}
{"channel":"book","type":"update","data":[{"symbol":"ETH/AUD","bids":[{"price":5712.08,"qty":1.60677000},{"price":5712.10,"qty":0.52250000}],"asks":[],"checksum":637087232,"timestamp":"2024-06-01T18:06:11.943990Z"}]}
{"channel":"book","type":"update","data":[{"symbol":"ETH/AUD","bids":[{"price":5710.15,"qty":0.74583629}],"asks":[],"checksum":1578724241,"timestamp":"2024-06-01T18:06:11.954957Z"}]}
{"channel":"book","type":"update","data":[{"symbol":"ETH/AUD","bids":[],"asks":[{"price":5719.20,"qty":0.00000000},{"price":5726.77,"qty":1.60677000}],"checksum":2832298572,"timestamp":"2024-06-01T18:06:11.977409Z"}]}
{"channel":"book","type":"update","data":[{"symbol":"ETH/AUD","bids":[],"asks":[{"price":5721.94,"qty":0.00000000},{"price":5728.07,"qty":0.10100000}],"checksum":4101551986,"timestamp":"2024-06-01T18:06:11.977540Z"}]}
{"channel":"book","type":"update","data":[{"symbol":"ETH/AUD","bids":[],"asks":[{"price":5722.12,"qty":11.16960848}],"checksum":3476693186,"timestamp":"2024-06-01T18:06:11.981201Z"}]}
{"channel":"book","type":"update","data":[{"symbol":"ETH/AUD","bids":[{"price":5716.64,"qty":0.90387105}],"asks":[],"checksum":2655506703,"timestamp":"2024-06-01T18:06:11.986737Z"}]}
{"channel":"book","type":"update","data":[{"symbol":"ETH/AUD","bids":[],"asks":[{"price":5719.64,"qty":0.00000000},{"price":5728.07,"qty":0.10100000},{"price":5720.71,"qty":0.06650200}],"checksum":1376306196,"timestamp":"2024-06-01T18:06:11.995474Z"}]}
{"channel":"book","type":"update","data":[{"symbol":"ETH/AUD","bids":[{"price":5716.62,"qty":0.00000000},{"price":5710.14,"qty":8.21404064}],"asks":[],"checksum":876464268,"timestamp":"2024-06-01T18:06:12.038435Z"}]}
{"channel":"book","type":"update","data":[{"symbol":"ETH/AUD","bids":[{"price":5715.79,"qty":0.00000000},{"price":5710.13,"qty":0.06686773},{"price":5716.65,"qty":0.07347674}],"asks":[],"checksum":1632315327,"timestamp":"2024-06-01T18:06:12.052628Z"}]}
{"channel":"book","type":"update","data":[{"symbol":"ETH/AUD","bids":[{"price":5716.63,"qty":0.00000000},{"price":5710.13,"qty":0.06686773},{"price":5716.65,"qty":1.10944298}],"asks":[],"checksum":1326904092,"timestamp":"2024-06-01T18:06:12.054691Z"}]}
{"channel":"book","type":"update","data":[{"symbol":"ETH/AUD","bids":[],"asks":[{"price":5719.19,"qty":0.00000000},{"price":5728.07,"qty":0.10100000},{"price":5720.70,"qty":0.46284930}],"checksum":697440812,"timestamp":"2024-06-01T18:06:12.054789Z"}]}
{"channel":"book","type":"update","data":[{"symbol":"ETH/AUD","bids":[],"asks":[{"price":5718.50,"qty":0.00000000},{"price":5728.07,"qty":0.10100000},{"price":5720.70,"qty":0.47577256}],"checksum":3850373127,"timestamp":"2024-06-01T18:06:12.084820Z"}]}
{"channel":"book","type":"update","data":[{"symbol":"ETH/AUD","bids":[],"asks":[{"price":5724.85,"qty":0.00000000},{"price":5728.79,"qty":0.20717085}],"checksum":1017678737,"timestamp":"2024-06-01T18:06:12.133113Z"}]}
{"channel":"book","type":"update","data":[{"symbol":"ETH/AUD","bids":[{"price":5712.11,"qty":0.02406309}],"asks":[],"checksum":4205372695,"timestamp":"2024-06-01T18:06:12.144761Z"}]}
{"channel":"book","type":"update","data":[{"symbol":"ETH/AUD","bids":[{"price":5716.65,"qty":1.03596624},{"price":5715.79,"qty":0.07347674}],"asks":[],"checksum":2951291866,"timestamp":"2024-06-01T18:06:12.147212Z"}]}
{"channel":"book","type":"update","data":[{"symbol":"ETH/AUD","bids":[],"asks":[{"price":5719.86,"qty":0.90387105}],"checksum":3387200636,"timestamp":"2024-06-01T18:06:12.149731Z"}]}
{"channel":"book","type":"update","data":[{"symbol":"ETH/AUD","bids":[],"asks":[{"price":5720.70,"qty":0.46284930},{"price":5720.69,"qty":0.01292326}],"checksum":2427863760,"timestamp":"2024-06-01T18:06:12.179827Z"}]}
{"channel":"book","type":"update","data":[{"symbol":"ETH/AUD","bids":[{"price":5716.66,"qty":0.90387105}],"asks":[],"checksum":490933638,"timestamp":"2024-06-01T18:06:12.180898Z"}]}
{"channel":"book","type":"update","data":[{"symbol":"ETH/AUD","bids":[{"price":5715.79,"qty":0.00000000},{"price":5710.15,"qty":0.74583629},{"price":5716.67,"qty":0.07347674}],"asks":[],"checksum":3627633403,"timestamp":"2024-06-01T18:06:12.212261Z"}]}
{"channel":"book","type":"update","data":[{"symbol":"ETH/AUD","bids":[],"asks":[{"price":5720.70,"qty":0.00000000},{"price":5728.07,"qty":0.10100000},{"price":5719.85,"qty":0.46284929}],"checksum":138388657,"timestamp":"2024-06-01T18:06:12.212330Z"}]}
{"channel":"book","type":"update","data":[{"symbol":"ETH/AUD","bids":[],"asks":[{"price":5721.30,"qty":0.00000000},{"price":5728.07,"qty":0.10100000}],"checksum":3917835136,"timestamp":"2024-06-01T18:06:12.212636Z"}]}
{"channel":"book","type":"update","data":[{"symbol":"ETH/AUD","bids":[],"asks":[{"price":5720.69,"qty":0.00000000},{"price":5728.79,"qty":0.20717085},{"price":5719.84,"qty":0.01292326}],"checksum":2006669146,"timestamp":"2024-06-01T18:06:12.244553Z"}]}
{"channel":"book","type":"update","data":[{"symbol":"ETH/AUD","bids":[],"asks":[{"price":5719.86,"qty":0.00000000},{"price":5728.79,"qty":0.20717085}],"checksum":1053676809,"timestamp":"2024-06-01T18:06:12.247031Z"}]}
{"channel":"book","type":"update","data":[{"symbol":"ETH/AUD","bids":[{"price":5716.64,"qty":0.00000000},{"price":5710.15,"qty":0.74583629}],"asks":[],"checksum":700146317,"timestamp":"2024-06-01T18:06:12.247078Z"}]}
{"channel":"book","type":"update","data":[{"symbol":"ETH/AUD","bids":[],"asks":[{"price":5720.69,"qty":0.90387105}],"checksum":1310725771,"timestamp":"2024-06-01T18:06:12.247150Z"}]}
{"channel":"book","type":"update","data":[{"symbol":"ETH/AUD","bids":[],"asks":[{"price":5719.85,"qty":0.00000000},{"price":5728.79,"qty":0.20717085},{"price":5720.68,"qty":0.46284929}],"checksum":1180751739,"timestamp":"2024-06-01T18:06:12.308512Z"}]}
{"channel":"book","type":"update","data":[{"symbol":"ETH/AUD","bids":[{"price":5716.68,"qty":0.90387105}],"asks":[],"checksum":1125863655,"timestamp":"2024-06-01T18:06:12.372155Z"}]}
{"channel":"book","type":"update","data":[{"symbol":"ETH/AUD","bids":[],"asks":[{"price":5719.84,"qty":0.91679431}],"checksum":3661256440,"timestamp":"2024-06-01T18:06:12.372355Z"}]}
{"channel":"book","type":"update","data":[{"symbol":"ETH/AUD","bids":[{"price":5716.65,"qty":0.00000000},{"price":5710.15,"qty":0.74583629},{"price":5716.68,"qty":1.93983184}],"asks":[],"checksum":323302776,"timestamp":"2024-06-01T18:06:12.400932Z"}]}
{"channel":"book","type":"update","data":[{"symbol":"ETH/AUD","bids":[{"price":5716.67,"qty":0.00000000},{"price":5710.14,"qty":8.21404064},{"price":5716.69,"qty":0.07347674}],"asks":[],"checksum":2267060909,"timestamp":"2024-06-01T18:06:12.402219Z"}]}
{"channel":"book","type":"update","data":[{"symbol":"ETH/AUD","bids":[],"asks":[{"price":5720.69,"qty":0.00000000},{"price":5728.79,"qty":0.20717085}],"checksum":3770412715,"timestamp":"2024-06-01T18:06:12.440743Z"}]}
{"channel":"book","type":"update","data":[{"symbol":"ETH/AUD","bids":[{"price":5716.66,"qty":0.00000000},{"price":5710.14,"qty":8.21404064}],"asks":[],"checksum":311975193,"timestamp":"2024-06-01T18:06:12.440998Z"}]}
{"channel":"book","type":"update","data":[{"symbol":"ETH/AUD","bids":[],"asks":[{"price":5720.68,"qty":0.00000000},{"price":5729.62,"qty":2.35323000},{"price":5719.83,"qty":0.47531160}],"checksum":2571182471,"timestamp":"2024-06-01T18:06:12.659820Z"}]}
{"channel":"book","type":"update","data":[{"symbol":"ETH/AUD","bids":[{"price":5716.68,"qty":0.90387105},{"price":5716.70,"qty":1.03595715}],"asks":[],"checksum":4087170339,"timestamp":"2024-06-01T18:06:12.659924Z"}]}
{"channel":"book","type":"update","data":[{"symbol":"ETH/AUD","bids":[],"asks":[{"price":5719.82,"qty":0.90387105}],"checksum":2865707612,"timestamp":"2024-06-01T18:06:12.665426Z"}]}
{"channel":"book","type":"update","data":[{"symbol":"ETH/AUD","bids":[{"price":5716.71,"qty":0.90387105}],"asks":[],"checksum":2359521768,"timestamp":"2024-06-01T18:06:12.665447Z"}]}
{"channel":"book","type":"update","data":[{"symbol":"ETH/AUD","bids":[],"asks":[{"price":5719.84,"qty":0.01292326}],"checksum":2592452373,"timestamp":"2024-06-01T18:06:12.676767Z"}]}
{"channel":"book","type":"update","data":[{"symbol":"ETH/AUD","bids":[{"price":5716.68,"qty":0.00000000},{"price":5710.15,"qty":0.74583629}],"asks":[],"checksum":4065963199,"timestamp":"2024-06-01T18:06:12.676833Z"}]}
{"channel":"book","type":"update","data":[{"symbol":"ETH/AUD","bids":[{"price":5716.69,"qty":0.00000000},{"price":5710.14,"qty":8.21404064},{"price":5716.72,"qty":0.07347674}],"asks":[],"checksum":2677337711,"timestamp":"2024-06-01T18:06:12.677317Z"}]}
{"channel":"book","type":"update","data":[{"symbol":"ETH/AUD","bids":[],"asks":[{"price":5719.84,"qty":0.00000000},{"price":5728.79,"qty":0.20717085},{"price":5719.81,"qty":0.01292326}],"checksum":1719861618,"timestamp":"2024-06-01T18:06:12.709195Z"}]}
{"channel":"book","type":"update","data":[{"symbol":"ETH/AUD","bids":[{"price":5716.73,"qty":0.90387105}],"asks":[],"checksum":3157912353,"timestamp":"2024-06-01T18:06:12.715087Z"}]}
{"channel":"book","type":"update","data":[{"symbol":"ETH/AUD","bids":[],"asks":[{"price":5719.80,"qty":0.90387105}],"checksum":3733851473,"timestamp":"2024-06-01T18:06:12.715125Z"}]}
{"channel":"book","type":"update","data":[{"symbol":"ETH/AUD","bids":[{"price":5716.72,"qty":0.00000000},{"price":5710.15,"qty":0.74583629},{"price":5716.74,"qty":0.07347674}],"asks":[],"checksum":3927583837,"timestamp":"2024-06-01T18:06:12.741620Z"}]}
{"channel":"book","type":"update","data":[{"symbol":"ETH/AUD","bids":[],"asks":[{"price":5719.82,"qty":0.00000000},{"price":5728.07,"qty":0.10100000}],"checksum":2220886463,"timestamp":"2024-06-01T18:06:12.746590Z"}]}
{"channel":"book","type":"update","data":[{"symbol":"ETH/AUD","bids":[{"price":5716.73,"qty":0.00000000},{"price":5710.15,"qty":0.74583629}],"asks":[],"checksum":1060772343,"timestamp":"2024-06-01T18:06:12.746676Z"}]}
{"channel":"book","type":"update","data":[{"symbol":"ETH/AUD","bids":[{"price":5716.75,"qty":0.90387105}],"asks":[],"checksum":3795710935,"timestamp":"2024-06-01T18:06:12.746731Z"}]}
{"channel":"book","type":"update","data":[{"symbol":"ETH/AUD","bids":[],"asks":[{"price":5719.83,"qty":0.00000000},{"price":5728.79,"qty":0.20717085},{"price":5719.79,"qty":0.44083709}],"checksum":4071822340,"timestamp":"2024-06-01T18:06:12.980772Z"}]}
{"channel":"book","type":"update","data":[{"symbol":"ETH/AUD","bids":[{"price":5716.70,"qty":0.00000000},{"price":5710.15,"qty":0.74583629},{"price":5716.76,"qty":1.03594627}],"asks":[],"checksum":3116582305,"timestamp":"2024-06-01T18:06:12.980793Z"}]}
{"channel":"book","type":"update","data":[{"symbol":"ETH/AUD","bids":[{"price":5716.71,"qty":0.00000000},{"price":5710.15,"qty":0.74583629}],"asks":[],"checksum":118022339,"timestamp":"2024-06-01T18:06:12.985819Z"}]}
{"channel":"book","type":"update","data":[{"symbol":"ETH/AUD","bids":[],"asks":[{"price":5719.78,"qty":0.90387105}],"checksum":3866022006,"timestamp":"2024-06-01T18:06:12.985977Z"}]}
{"channel":"book","type":"update","data":[{"symbol":"ETH/AUD","bids":[{"price":5716.74,"qty":0.00000000},{"price":5710.14,"qty":8.21404064},{"price":5716.77,"qty":0.07347674}],"asks":[],"checksum":693510642,"timestamp":"2024-06-01T18:06:13.015264Z"}]}
{"channel":"book","type":"update","data":[{"symbol":"ETH/AUD","bids":[{"price":5716.78,"qty":0.90387105}],"asks":[],"checksum":2758789841,"timestamp":"2024-06-01T18:06:13.020458Z"}]}
{"channel":"book","type":"update","data":[{"symbol":"ETH/AUD","bids":[],"asks":[{"price":5719.80,"qty":0.00000000},{"price":5728.07,"qty":0.10100000}],"checksum":301137394,"timestamp":"2024-06-01T18:06:13.020495Z"}]}
{"channel":"book","type":"update","data":[{"symbol":"ETH/AUD","bids":[{"price":5716.77,"qty":0.00000000},{"price":5710.15,"qty":0.74583629},{"price":5716.79,"qty":0.07347674}],"asks":[],"checksum":2365004854,"timestamp":"2024-06-01T18:06:13.109500Z"}]}
{"channel":"book","type":"update","data":[{"symbol":"ETH/AUD","bids":[{"price":5716.78,"qty":0.00000000},{"price":5710.15,"qty":0.74583629}],"asks":[],"checksum":84863474,"timestamp":"2024-06-01T18:06:13.115766Z"}]}
{"channel":"book","type":"update","data":[{"symbol":"ETH/AUD","bids":[{"price":5716.80,"qty":0.90387105}],"asks":[],"checksum":1293072902,"timestamp":"2024-06-01T18:06:13.115841Z"}]}
{"channel":"book","type":"update","data":[{"symbol":"ETH/AUD","bids":[{"price":5716.75,"qty":0.00000000},{"price":5710.15,"qty":0.74583629}],"asks":[],"checksum":1871737153,"timestamp":"2024-06-01T18:06:13.176133Z"}]}
{"channel":"book","type":"update","data":[{"symbol":"ETH/AUD","bids":[{"price":5716.79,"qty":0.00000000},{"price":5710.14,"qty":8.21404064},{"price":5716.81,"qty":0.07347674}],"asks":[],"checksum":2230187024,"timestamp":"2024-06-01T18:06:13.202250Z"}]}
{"channel":"book","type":"update","data":[{"symbol":"ETH/AUD","bids":[],"asks":[{"price":5719.81,"qty":0.00000000},{"price":5728.79,"qty":0.20717085},{"price":5719.77,"qty":0.01292326}],"checksum":230622566,"timestamp":"2024-06-01T18:06:13.234263Z"}]}
{"channel":"book","type":"update","data":[{"symbol":"ETH/AUD","bids":[{"price":5716.82,"qty":0.90387105}],"asks":[],"checksum":2705799167,"timestamp":"2024-06-01T18:06:13.239948Z"}]}
{"channel":"book","type":"update","data":[{"symbol":"ETH/AUD","bids":[],"asks":[{"price":5719.76,"qty":0.90387105}],"checksum":1060517552,"timestamp":"2024-06-01T18:06:13.239974Z"}]}
{"channel":"book","type":"update","data":[{"symbol":"ETH/AUD","bids":[{"price":5716.81,"qty":0.00000000},{"price":5710.15,"qty":0.74583629},{"price":5716.83,"qty":0.07347674}],"asks":[],"checksum":36555158,"timestamp":"2024-06-01T18:06:13.265970Z"}]}
{"channel":"book","type":"update","data":[{"symbol":"ETH/AUD","bids":[{"price":5716.82,"qty":0.00000000},{"price":5710.15,"qty":0.74583629}],"asks":[],"checksum":2699185444,"timestamp":"2024-06-01T18:06:13.270858Z"}]}
{"channel":"book","type":"update","data":[{"symbol":"ETH/AUD","bids":[],"asks":[{"price":5719.78,"qty":0.00000000},{"price":5728.07,"qty":0.10100000}],"checksum":3117858948,"timestamp":"2024-06-01T18:06:13.270930Z"}]}
{"channel":"book","type":"update","data":[{"symbol":"ETH/AUD","bids":[{"price":5716.84,"qty":0.90387105}],"asks":[],"checksum":1910677462,"timestamp":"2024-06-01T18:06:13.271084Z"}]}
{"channel":"book","type":"update","data":[{"symbol":"ETH/AUD","bids":[{"price":5716.76,"qty":0.00000000},{"price":5710.15,"qty":0.74583629},{"price":5716.83,"qty":1.10941032}],"asks":[],"checksum":3554419799,"timestamp":"2024-06-01T18:06:13.298893Z"}]}
{"channel":"book","type":"update","data":[{"symbol":"ETH/AUD","bids":[],"asks":[{"price":5719.79,"qty":0.00000000},{"price":5728.79,"qty":0.20717085},{"price":5719.75,"qty":0.44083709}],"checksum":3199175343,"timestamp":"2024-06-01T18:06:13.298918Z"}]}
{"channel":"book","type":"update","data":[{"symbol":"ETH/AUD","bids":[{"price":5716.80,"qty":0.00000000},{"price":5710.14,"qty":8.21404064}],"asks":[],"checksum":2185936197,"timestamp":"2024-06-01T18:06:13.303848Z"}]}
{"channel":"book","type":"update","data":[{"symbol":"ETH/AUD","bids":[],"asks":[{"price":5719.74,"qty":0.90387105}],"checksum":2441697062,"timestamp":"2024-06-01T18:06:13.304076Z"}]}
{"channel":"book","type":"update","data":[{"symbol":"ETH/AUD","bids":[{"price":5716.83,"qty":1.03593358},{"price":5716.85,"qty":0.07347674}],"asks":[],"checksum":1573911464,"timestamp":"2024-06-01T18:06:13.329038Z"}]}
{"channel":"book","type":"update","data":[{"symbol":"ETH/AUD","bids":[],"asks":[{"price":5719.76,"qty":0.00000000},{"price":5728.07,"qty":0.10100000}],"checksum":3365204240,"timestamp":"2024-06-01T18:06:13.334008Z"}]}
{"channel":"book","type":"update","data":[{"symbol":"ETH/AUD","bids":[],"asks":[{"price":5719.77,"qty":0.00000000},{"price":5728.79,"qty":0.20717085},{"price":5719.73,"qty":0.01292326}],"checksum":971548544,"timestamp":"2024-06-01T18:06:13.360760Z"}]}
{"channel":"book","type":"update","data":[{"symbol":"ETH/AUD","bids":[{"price":5716.86,"qty":0.90387105}],"asks":[],"checksum":203579960,"timestamp":"2024-06-01T18:06:13.366501Z"}]}
{"channel":"book","type":"update","data":[{"symbol":"ETH/AUD","bids":[{"price":5716.85,"qty":0.00000000},{"price":5710.15,"qty":0.74583629},{"price":5716.87,"qty":0.07347674}],"asks":[],"checksum":214796679,"timestamp":"2024-06-01T18:06:13.393438Z"}]}
{"channel":"book","type":"update","data":[{"symbol":"ETH/AUD","bids":[{"price":5716.86,"qty":0.00000000},{"price":5710.15,"qty":0.74583629}],"asks":[],"checksum":180678285,"timestamp":"2024-06-01T18:06:13.398738Z"}]}
{"channel":"book","type":"update","data":[{"symbol":"ETH/AUD","bids":[],"asks":[{"price":5721.79,"qty":0.05401565}],"checksum":4119998958,"timestamp":"2024-06-01T18:06:13.535785Z"}]}
{"channel":"book","type":"update","data":[{"symbol":"ETH/AUD","bids":[{"price":5712.12,"qty":0.02066151}],"asks":[],"checksum":1934816100,"timestamp":"2024-06-01T18:06:13.566119Z"}]}
{"channel":"book","type":"update","data":[{"symbol":"ETH/AUD","bids":[],"asks":[{"price":5719.75,"qty":0.00000000},{"price":5728.07,"qty":0.10100000},{"price":5719.72,"qty":0.44083709}],"checksum":4286239854,"timestamp":"2024-06-01T18:06:13.677094Z"}]}
{"channel":"book","type":"update","data":[{"symbol":"ETH/AUD","bids":[{"price":5716.83,"qty":0.00000000},{"price":5710.16,"qty":0.05118224},{"price":5716.88,"qty":1.03592452}],"asks":[],"checksum":3800704745,"timestamp":"2024-06-01T18:06:13.677271Z"}]}
{"channel":"book","type":"update","data":[{"symbol":"ETH/AUD","bids":[{"price":5716.87,"qty":0.00000000},{"price":5710.16,"qty":0.05118224},{"price":5716.89,"qty":0.07347674}],"asks":[],"checksum":2147751556,"timestamp":"2024-06-01T18:06:13.699232Z"}]}
{"channel":"book","type":"update","data":[{"symbol":"ETH/AUD","bids":[],"asks":[{"price":5719.73,"qty":0.00000000},{"price":5728.07,"qty":0.10100000},{"price":5719.71,"qty":0.01292326}],"checksum":1639196782,"timestamp":"2024-06-01T18:06:13.730852Z"}]}
{"channel":"book","type":"update","data":[{"symbol":"ETH/AUD","bids":[{"price":5716.88,"qty":0.00000000},{"price":5710.16,"qty":0.05118224},{"price":5716.90,"qty":1.03593369}],"asks":[],"checksum":3610248452,"timestamp":"2024-06-01T18:06:14.121125Z"}]}
{"channel":"book","type":"update","data":[{"symbol":"ETH/AUD","bids":[],"asks":[{"price":5719.72,"qty":0.00000000},{"price":5728.07,"qty":0.10100000},{"price":5719.70,"qty":0.44087915}],"checksum":3397806788,"timestamp":"2024-06-01T18:06:14.121148Z"}]}
{"channel":"book","type":"update","data":[{"symbol":"ETH/AUD","bids":[],"asks":[{"price":5719.70,"qty":1.34475020}],"checksum":2283118488,"timestamp":"2024-06-01T18:06:14.126547Z"}]}
{"channel":"book","type":"update","data":[{"symbol":"ETH/AUD","bids":[],"asks":[{"price":5721.81,"qty":0.00000000},{"price":5728.07,"qty":0.10100000}],"checksum":4207575482,"timestamp":"2024-06-01T18:06:14.151558Z"}]}
{"channel":"book","type":"update","data":[{"symbol":"ETH/AUD","bids":[],"asks":[{"price":5721.80,"qty":0.00000000},{"price":5728.79,"qty":0.20717085},{"price":5722.11,"qty":0.52250000}],"checksum":1650430968,"timestamp":"2024-06-01T18:06:14.154831Z"}]}
{"channel":"book","type":"update","data":[{"symbol":"ETH/AUD","bids":[],"asks":[{"price":5721.78,"qty":3.10920291}],"checksum":1631679623,"timestamp":"2024-06-01T18:06:14.156130Z"}]}
{"channel":"book","type":"update","data":[{"symbol":"ETH/AUD","bids":[],"asks":[{"price":5722.11,"qty":6.19128909}],"checksum":4133084449,"timestamp":"2024-06-01T18:06:14.156189Z"}]}
{"channel":"book","type":"update","data":[{"symbol":"ETH/AUD","bids":[{"price":5716.89,"qty":0.00000000},{"price":5710.16,"qty":0.05118224},{"price":5716.91,"qty":0.07347674}],"asks":[],"checksum":1944201173,"timestamp":"2024-06-01T18:06:14.157898Z"}]}
{"channel":"book","type":"update","data":[{"symbol":"ETH/AUD","bids":[],"asks":[{"price":5719.74,"qty":0.00000000},{"price":5728.07,"qty":0.10100000}],"checksum":2938544489,"timestamp":"2024-06-01T18:06:14.161555Z"}]}
{"channel":"book","type":"update","data":[{"symbol":"ETH/AUD","bids":[{"price":5716.90,"qty":0.00000000},{"price":5710.16,"qty":0.05118224},{"price":5716.92,"qty":1.03592939}],"asks":[],"checksum":582829169,"timestamp":"2024-06-01T18:06:14.562445Z"}]}
{"channel":"book","type":"update","data":[{"symbol":"ETH/AUD","bids":[],"asks":[{"price":5719.70,"qty":0.90387105},{"price":5719.69,"qty":0.44087904}],"checksum":1744073086,"timestamp":"2024-06-01T18:06:14.562577Z"}]}
{"channel":"book","type":"update","data":[{"symbol":"ETH/AUD","bids":[{"price":5716.91,"qty":0.00000000},{"price":5710.16,"qty":0.05118224},{"price":5716.93,"qty":0.07347674}],"asks":[],"checksum":1022814067,"timestamp":"2024-06-01T18:06:14.584538Z"}]}
{"channel":"book","type":"update","data":[{"symbol":"ETH/AUD","bids":[],"asks":[{"price":5719.71,"qty":0.00000000},{"price":5728.07,"qty":0.10100000},{"price":5719.68,"qty":0.01292326}],"checksum":2312068258,"timestamp":"2024-06-01T18:06:14.616142Z"}]}
{"channel":"book","type":"update","data":[{"symbol":"ETH/AUD","bids":[{"price":5712.09,"qty":0.00000000},{"price":5710.16,"qty":0.05118224}],"asks":[],"checksum":1767036425,"timestamp":"2024-06-01T18:06:14.957645Z"}]}
{"channel":"book","type":"update","data":[{"symbol":"ETH/AUD","bids":[{"price":5712.13,"qty":1.03950269}],"asks":[],"checksum":2060236544,"timestamp":"2024-06-01T18:06:14.958251Z"}]}
{"channel":"book","type":"update","data":[{"symbol":"ETH/AUD","bids":[],"asks":[{"price":5722.11,"qty":5.66878909},{"price":5721.77,"qty":0.52250000}],"checksum":2270356725,"timestamp":"2024-06-01T18:06:14.960384Z"}]}
{"channel":"book","type":"update","data":[{"symbol":"ETH/AUD","bids":[{"price":5712.10,"qty":0.00000000},{"price":5710.17,"qty":8.20523237},{"price":5712.09,"qty":0.52250000}],"asks":[],"checksum":1911631202,"timestamp":"2024-06-01T18:06:14.960676Z"}]}
{"channel":"book","type":"update","data":[{"symbol":"ETH/AUD","bids":[{"price":5716.94,"qty":0.90387105}],"asks":[],"checksum":974823880,"timestamp":"2024-06-01T18:06:14.965083Z"}]}
{"channel":"book","type":"update","data":[{"symbol":"ETH/AUD","bids":[],"asks":[{"price":5719.67,"qty":0.90387105}],"checksum":1936649558,"timestamp":"2024-06-01T18:06:14.965206Z"}]}
{"channel":"book","type":"update","data":[{"symbol":"ETH/AUD","bids":[{"price":5716.93,"qty":0.00000000},{"price":5712.08,"qty":1.60677000},{"price":5716.95,"qty":0.07347674}],"asks":[],"checksum":930382645,"timestamp":"2024-06-01T18:06:14.983498Z"}]}
{"channel":"book","type":"update","data":[{"symbol":"ETH/AUD","bids":[],"asks":[{"price":5719.68,"qty":0.00000000},{"price":5724.84,"qty":0.83372964},{"price":5719.66,"qty":0.01292326}],"checksum":674903857,"timestamp":"2024-06-01T18:06:15.014818Z"}]}
{"channel":"book","type":"update","data":[{"symbol":"ETH/AUD","bids":[],"asks":[{"price":5719.67,"qty":0.00000000},{"price":5724.84,"qty":0.83372964}],"checksum":1207051882,"timestamp":"2024-06-01T18:06:15.019897Z"}]}
{"channel":"book","type":"update","data":[{"symbol":"ETH/AUD","bids":[{"price":5716.94,"qty":0.00000000},{"price":5712.08,"qty":1.60677000}],"asks":[],"checksum":3370120890,"timestamp":"2024-06-01T18:06:15.019931Z"}]}
{"channel":"book","type":"update","data":[{"symbol":"ETH/AUD","bids":[{"price":5716.92,"qty":0.00000000},{"price":5710.18,"qty":0.74583237},{"price":5716.96,"qty":1.03592185}],"asks":[],"checksum":3315583534,"timestamp":"2024-06-01T18:06:15.029581Z"}]}
{"channel":"book","type":"update","data":[{"symbol":"ETH/AUD","bids":[{"price":5716.95,"qty":0.00000000},{"price":5710.18,"qty":0.74583237},{"price":5716.97,"qty":0.07347674}],"asks":[],"checksum":1962271589,"timestamp":"2024-06-01T18:06:15.046511Z"}]}
{"channel":"book","type":"update","data":[{"symbol":"ETH/AUD","bids":[{"price":5716.52,"qty":0.00000000},{"price":5710.18,"qty":0.74583237},{"price":5716.98,"qty":0.06652700}],"asks":[],"checksum":115850223,"timestamp":"2024-06-01T18:06:15.221253Z"}]}
{"channel":"book","type":"update","data":[{"symbol":"ETH/AUD","bids":[{"price":5716.97,"qty":0.00000000},{"price":5710.18,"qty":0.74583237},{"price":5716.99,"qty":0.07347674}],"asks":[],"checksum":3355408074,"timestamp":"2024-06-01T18:06:15.232104Z"}]}
{"channel":"book","type":"update","data":[{"symbol":"ETH/AUD","bids":[{"price":5716.96,"qty":0.00000000},{"price":5710.18,"qty":0.74583237},{"price":5717.00,"qty":1.03591460}],"asks":[],"checksum":3108569289,"timestamp":"2024-06-01T18:06:15.484869Z"}]}
{"channel":"book","type":"update","data":[{"symbol":"ETH/AUD","bids":[{"price":5712.09,"qty":0.00000000},{"price":5710.18,"qty":0.74583237},{"price":5712.14,"qty":0.52250000}],"asks":[],"checksum":273510025,"timestamp":"2024-06-01T18:06:15.487760Z"}]}
{"channel":"book","type":"update","data":[{"symbol":"ETH/AUD","bids":[{"price":5716.99,"qty":0.00000000},{"price":5710.18,"qty":0.74583237},{"price":5717.01,"qty":0.07347674}],"asks":[],"checksum":2688535261,"timestamp":"2024-06-01T18:06:15.507584Z"}]}
{"channel":"book","type":"update","data":[{"symbol":"ETH/AUD","bids":[],"asks":[{"price":5720.71,"qty":0.00000000},{"price":5726.77,"qty":1.60677000},{"price":5720.25,"qty":0.06650800}],"checksum":4157702503,"timestamp":"2024-06-01T18:06:15.571028Z"}]}
{"channel":"book","type":"update","data":[{"symbol":"ETH/AUD","bids":[],"asks":[{"price":5719.69,"qty":0.00000000},{"price":5726.77,"qty":1.60677000},{"price":5719.65,"qty":0.44087891}],"checksum":2294691401,"timestamp":"2024-06-01T18:06:15.983428Z"}]}
{"channel":"book","type":"update","data":[{"symbol":"ETH/AUD","bids":[{"price":5717.00,"qty":0.00000000},{"price":5710.18,"qty":0.74583237},{"price":5717.02,"qty":1.03589724}],"asks":[],"checksum":1652866721,"timestamp":"2024-06-01T18:06:15.983488Z"}]}
{"channel":"book","type":"update","data":[{"symbol":"ETH/AUD","bids":[],"asks":[{"price":5719.64,"qty":0.90387105}],"checksum":499267812,"timestamp":"2024-06-01T18:06:15.988809Z"}]}
{"channel":"book","type":"update","data":[{"symbol":"ETH/AUD","bids":[{"price":5717.01,"qty":0.00000000},{"price":5710.18,"qty":0.74583237},{"price":5717.03,"qty":0.07347674}],"asks":[],"checksum":3320876293,"timestamp":"2024-06-01T18:06:15.995900Z"}]}
{"channel":"book","type":"update","data":[{"symbol":"ETH/AUD","bids":[],"asks":[{"price":5719.66,"qty":0.00000000},{"price":5724.84,"qty":0.83372964},{"price":5719.63,"qty":0.01292326}],"checksum":3776009149,"timestamp":"2024-06-01T18:06:16.028086Z"}]}
{"channel":"book","type":"update","data":[{"symbol":"ETH/AUD","bids":[],"asks":[{"price":5719.64,"qty":0.00000000},{"price":5724.84,"qty":0.83372964}],"checksum":3721517422,"timestamp":"2024-06-01T18:06:16.033292Z"}]}
{"channel":"book","type":"update","data":[{"symbol":"ETH/AUD","bids":[],"asks":[{"price":5721.79,"qty":0.00000000},{"price":5726.77,"qty":1.60677000}],"checksum":2719972320,"timestamp":"2024-06-01T18:06:16.080172Z"}]}
{"channel":"book","type":"update","data":[{"symbol":"ETH/AUD","bids":[],"asks":[{"price":5721.76,"qty":0.05726616}],"checksum":3125757721,"timestamp":"2024-06-01T18:06:16.082661Z"}]}
{"channel":"book","type":"update","data":[{"symbol":"ETH/AUD","bids":[],"asks":[{"price":5719.65,"qty":0.00000000},{"price":5726.77,"qty":1.60677000},{"price":5719.62,"qty":0.44086507}],"checksum":4052737459,"timestamp":"2024-06-01T18:06:16.469758Z"}]}
{"channel":"book","type":"update","data":[{"symbol":"ETH/AUD","bids":[{"price":5717.02,"qty":0.00000000},{"price":5710.18,"qty":0.74583237},{"price":5717.04,"qty":1.03589323}],"asks":[],"checksum":665963658,"timestamp":"2024-06-01T18:06:16.469790Z"}]}
{"channel":"book","type":"update","data":[{"symbol":"ETH/AUD","bids":[{"price":5717.03,"qty":0.00000000},{"price":5710.18,"qty":0.74583237},{"price":5717.05,"qty":0.07347674}],"asks":[],"checksum":261817286,"timestamp":"2024-06-01T18:06:16.485993Z"}]}
{"channel":"book","type":"update","data":[{"symbol":"ETH/AUD","bids":[{"price":5715.78,"qty":0.00000000},{"price":5710.18,"qty":0.74583237}],"asks":[],"checksum":1601985802,"timestamp":"2024-06-01T18:06:16.491238Z"}]}
{"channel":"book","type":"update","data":[{"symbol":"ETH/AUD","bids":[{"price":5716.37,"qty":3.12330990}],"asks":[],"checksum":620184653,"timestamp":"2024-06-01T18:06:16.493993Z"}]}
{"channel":"book","type":"update","data":[{"symbol":"ETH/AUD","bids":[],"asks":[{"price":5719.63,"qty":0.00000000},{"price":5726.77,"qty":1.60677000},{"price":5719.61,"qty":0.01292326}],"checksum":2172718049,"timestamp":"2024-06-01T18:06:16.516904Z"}]}
{"channel":"book","type":"update","data":[{"symbol":"ETH/AUD","bids":[],"asks":[{"price":5721.78,"qty":0.00000000},{"price":5726.77,"qty":1.60677000}],"checksum":854420926,"timestamp":"2024-06-01T18:06:16.614221Z"}]}
{"channel":"book","type":"update","data":[{"symbol":"ETH/AUD","bids":[],"asks":[{"price":5722.11,"qty":0.00000000},{"price":5728.07,"qty":0.10100000}],"checksum":4049087831,"timestamp":"2024-06-01T18:06:16.614231Z"}]}
{"channel":"book","type":"update","data":[{"symbol":"ETH/AUD","bids":[],"asks":[{"price":5721.77,"qty":0.00000000},{"price":5728.79,"qty":0.20717085},{"price":5722.10,"qty":0.52250000}],"checksum":1084734249,"timestamp":"2024-06-01T18:06:16.617748Z"}]}
{"channel":"book","type":"update","data":[{"symbol":"ETH/AUD","bids":[],"asks":[{"price":5721.75,"qty":3.10922564}],"checksum":2054312769,"timestamp":"2024-06-01T18:06:16.619462Z"}]}
{"channel":"book","type":"update","data":[{"symbol":"ETH/AUD","bids":[],"asks":[{"price":5722.11,"qty":6.18413342}],"checksum":3761316140,"timestamp":"2024-06-01T18:06:16.619525Z"}]}
{"channel":"book","type":"update","data":[{"symbol":"ETH/AUD","bids":[{"price":5712.12,"qty":0.00000000},{"price":5710.18,"qty":0.74583237}],"asks":[],"checksum":3355304403,"timestamp":"2024-06-01T18:06:16.764683Z"}]}
{"channel":"book","type":"update","data":[{"symbol":"ETH/AUD","bids":[{"price":5712.15,"qty":0.03606300}],"asks":[],"checksum":3456118026,"timestamp":"2024-06-01T18:06:16.765316Z"}]}
{"channel":"book","type":"update","data":[{"symbol":"ETH/AUD","bids":[{"price":5717.04,"qty":0.00000000},{"price":5710.19,"qty":0.03062056},{"price":5717.06,"qty":1.03588938}],"asks":[],"checksum":1899593608,"timestamp":"2024-06-01T18:06:17.025310Z"}]}
{"channel":"book","type":"update","data":[{"symbol":"ETH/AUD","bids":[],"asks":[{"price":5719.62,"qty":0.00000000},{"price":5726.77,"qty":1.60677000},{"price":5719.60,"qty":0.44086501}],"checksum":2748818829,"timestamp":"2024-06-01T18:06:17.025404Z"}]}
{"channel":"book","type":"update","data":[{"symbol":"ETH/AUD","bids":[],"asks":[{"price":5719.60,"qty":1.34473606}],"checksum":3694386055,"timestamp":"2024-06-01T18:06:17.030854Z"}]}
{"channel":"book","type":"update","data":[{"symbol":"ETH/AUD","bids":[{"price":5717.05,"qty":0.00000000},{"price":5710.19,"qty":0.03062056},{"price":5717.07,"qty":0.07347674}],"asks":[],"checksum":2651626885,"timestamp":"2024-06-01T18:06:17.035599Z"}]}
{"channel":"book","type":"update","data":[{"symbol":"ETH/AUD","bids":[],"asks":[{"price":5719.61,"qty":0.00000000},{"price":5726.77,"qty":1.60677000},{"price":5719.59,"qty":0.01292326}],"checksum":1122577751,"timestamp":"2024-06-01T18:06:17.067513Z"}]}
{"channel":"book","type":"update","data":[{"symbol":"ETH/AUD","bids":[],"asks":[{"price":5719.60,"qty":0.44086501}],"checksum":1346533018,"timestamp":"2024-06-01T18:06:17.072826Z"}]}
{"channel":"book","type":"update","data":[{"symbol":"ETH/AUD","bids":[],"asks":[{"price":5722.10,"qty":0.00000000},{"price":5726.77,"qty":1.60677000},{"price":5721.74,"qty":0.52250000}],"checksum":4162007993,"timestamp":"2024-06-01T18:06:17.473742Z"}]}
{"channel":"book","type":"update","data":[{"symbol":"ETH/AUD","bids":[{"price":5717.06,"qty":0.00000000},{"price":5710.19,"qty":0.03062056},{"price":5717.08,"qty":1.03588569}],"asks":[],"checksum":3104028750,"timestamp":"2024-06-01T18:06:17.645181Z"}]}
{"channel":"book","type":"update","data":[{"symbol":"ETH/AUD","bids":[],"asks":[{"price":5719.60,"qty":0.00000000},{"price":5726.77,"qty":1.60677000},{"price":5719.58,"qty":0.44086498}],"checksum":4008645347,"timestamp":"2024-06-01T18:06:17.645346Z"}]}
{"channel":"book","type":"update","data":[{"symbol":"ETH/AUD","bids":[{"price":5712.14,"qty":0.00000000},{"price":5710.19,"qty":0.03062056}],"asks":[],"checksum":4233558418,"timestamp":"2024-06-01T18:06:17.669758Z"}]}
{"channel":"book","type":"update","data":[{"symbol":"ETH/AUD","bids":[{"price":5717.07,"qty":0.00000000},{"price":5710.18,"qty":0.74583237},{"price":5717.09,"qty":0.07347674}],"asks":[],"checksum":2134003691,"timestamp":"2024-06-01T18:06:17.677022Z"}]}
{"channel":"book","type":"update","data":[{"symbol":"ETH/AUD","bids":[],"asks":[{"price":5719.59,"qty":0.00000000},{"price":5726.77,"qty":1.60677000},{"price":5719.57,"qty":0.01292326}],"checksum":3745145345,"timestamp":"2024-06-01T18:06:17.707765Z"}]}
{"channel":"book","type":"update","data":[{"symbol":"ETH/AUD","bids":[],"asks":[{"price":5719.58,"qty":0.00000000},{"price":5726.77,"qty":1.60677000},{"price":5719.69,"qty":0.44085371}],"checksum":954556376,"timestamp":"2024-06-01T18:06:17.759149Z"}]}
{"channel":"book","type":"update","data":[{"symbol":"ETH/AUD","bids":[{"price":5712.13,"qty":0.00000000},{"price":5710.18,"qty":0.74583237}],"asks":[],"checksum":830268509,"timestamp":"2024-06-01T18:06:17.980339Z"}]}
{"channel":"book","type":"update","data":[{"symbol":"ETH/AUD","bids":[{"price":5710.20,"qty":9.25315649}],"asks":[],"checksum":1708358607,"timestamp":"2024-06-01T18:06:17.980796Z"}]}
{"channel":"book","type":"update","data":[{"symbol":"ETH/AUD","bids":[{"price":5710.21,"qty":0.74582846}],"asks":[],"checksum":254395917,"timestamp":"2024-06-01T18:06:17.993990Z"}]}
{"channel":"book","type":"update","data":[{"symbol":"ETH/AUD","bids":[{"price":5717.09,"qty":0.00000000},{"price":5710.19,"qty":0.03062056}],"asks":[],"checksum":3521657770,"timestamp":"2024-06-01T18:06:18.014363Z"}]}
{"channel":"book","type":"update","data":[{"symbol":"ETH/AUD","bids":[],"asks":[{"price":5719.56,"qty":0.90387105}],"checksum":96688616,"timestamp":"2024-06-01T18:06:18.019265Z"}]}
{"channel":"book","type":"update","data":[{"symbol":"ETH/AUD","bids":[],"asks":[{"price":5719.57,"qty":0.00000000},{"price":5724.84,"qty":0.83372964},{"price":5719.55,"qty":0.01292326}],"checksum":1961819509,"timestamp":"2024-06-01T18:06:18.046444Z"}]}
{"channel":"book","type":"update","data":[{"symbol":"ETH/AUD","bids":[],"asks":[{"price":5719.56,"qty":0.00000000},{"price":5724.84,"qty":0.83372964}],"checksum":4079834675,"timestamp":"2024-06-01T18:06:18.052476Z"}]}
{"channel":"book","type":"update","data":[{"symbol":"ETH/AUD","bids":[{"price":5717.08,"qty":0.00000000},{"price":5710.06,"qty":0.08300000},{"price":5716.99,"qty":1.03590451}],"asks":[],"checksum":1710684201,"timestamp":"2024-06-01T18:06:18.077772Z"}]}
{"channel":"book","type":"update","data":[{"symbol":"ETH/AUD","bids":[],"asks":[{"price":5719.54,"qty":0.90387105}],"checksum":3871935024,"timestamp":"2024-06-01T18:06:18.082860Z"}]}
{"channel":"book","type":"update","data":[{"symbol":"ETH/AUD","bids":[],"asks":[{"price":5719.55,"qty":0.00000000},{"price":5724.84,"qty":0.83372964},{"price":5719.53,"qty":0.01292326}],"checksum":2039773480,"timestamp":"2024-06-01T18:06:18.109766Z"}]}
{"channel":"book","type":"update","data":[{"symbol":"ETH/AUD","bids":[],"asks":[{"price":5719.54,"qty":0.00000000},{"price":5724.84,"qty":0.83372964}],"checksum":45698690,"timestamp":"2024-06-01T18:06:18.114622Z"}]}
{"channel":"book","type":"update","data":[{"symbol":"ETH/AUD","bids":[{"price":5711.28,"qty":0.52250000}],"asks":[],"checksum":4149399751,"timestamp":"2024-06-01T18:06:18.134239Z"}]}
{"channel":"book","type":"update","data":[{"symbol":"ETH/AUD","bids":[{"price":5716.38,"qty":0.07347674}],"asks":[],"checksum":2299699046,"timestamp":"2024-06-01T18:06:18.142351Z"}]}
{"channel":"book","type":"update","data":[{"symbol":"ETH/AUD","bids":[],"asks":[{"price":5720.25,"qty":0.00000000},{"price":5726.77,"qty":1.60677000},{"price":5719.73,"qty":0.06651200}],"checksum":3471257024,"timestamp":"2024-06-01T18:06:18.521878Z"}]}
{"channel":"book","type":"update","data":[{"symbol":"ETH/AUD","bids":[],"asks":[{"price":5721.76,"qty":0.00000000},{"price":5726.77,"qty":1.60677000}],"checksum":1043146693,"timestamp":"2024-06-01T18:06:18.632062Z"}]}
{"channel":"book","type":"update","data":[{"symbol":"ETH/AUD","bids":[],"asks":[{"price":5721.73,"qty":0.05401590}],"checksum":2412070391,"timestamp":"2024-06-01T18:06:18.634057Z"}]}
{"channel":"book","type":"update","data":[{"symbol":"ETH/AUD","bids":[{"price":5711.28,"qty":0.00000000},{"price":5710.20,"qty":9.25315649},{"price":5712.09,"qty":0.52250000}],"asks":[],"checksum":259915702,"timestamp":"2024-06-01T18:06:18.636037Z"}]}
{"channel":"book","type":"update","data":[{"symbol":"ETH/AUD","bids":[],"asks":[{"price":5722.11,"qty":0.00000000},{"price":5726.77,"qty":1.60677000}],"checksum":4089193527,"timestamp":"2024-06-01T18:06:19.023230Z"}]}
{"channel":"book","type":"update","data":[{"symbol":"ETH/AUD","bids":[],"asks":[{"price":5721.75,"qty":0.00000000},{"price":5728.07,"qty":0.10100000}],"checksum":1615664246,"timestamp":"2024-06-01T18:06:19.023348Z"}]}
{"channel":"book","type":"update","data":[{"symbol":"ETH/AUD","bids":[],"asks":[{"price":5721.74,"qty":0.00000000},{"price":5728.79,"qty":0.20717085},{"price":5722.11,"qty":0.52250000}],"checksum":2745051048,"timestamp":"2024-06-01T18:06:19.026369Z"}]}
{"channel":"book","type":"update","data":[{"symbol":"ETH/AUD","bids":[],"asks":[{"price":5722.11,"qty":5.67594452}],"checksum":21946008,"timestamp":"2024-06-01T18:06:19.028255Z"}]}
{"channel":"book","type":"update","data":[{"symbol":"ETH/AUD","bids":[],"asks":[{"price":5721.72,"qty":3.10922564}],"checksum":677506021,"timestamp":"2024-06-01T18:06:19.028381Z"}]}
{"channel":"book","type":"update","data":[{"symbol":"ETH/AUD","bids":[],"asks":[{"price":5719.52,"qty":0.90387105}],"checksum":1180165989,"timestamp":"2024-06-01T18:06:19.034007Z"}]}
{"channel":"book","type":"update","data":[{"symbol":"ETH/AUD","bids":[],"asks":[{"price":5719.53,"qty":0.00000000},{"price":5726.77,"qty":1.60677000},{"price":5719.51,"qty":0.01292326}],"checksum":2350198655,"timestamp":"2024-06-01T18:06:19.055425Z"}]}
{"channel":"book","type":"update","data":[{"symbol":"ETH/AUD","bids":[],"asks":[{"price":5719.69,"qty":0.00000000},{"price":5726.77,"qty":1.60677000},{"price":5719.51,"qty":0.45377706}],"checksum":3074731030,"timestamp":"2024-06-01T18:06:19.092273Z"}]}
{"channel":"book","type":"update","data":[{"symbol":"ETH/AUD","bids":[],"asks":[{"price":5719.52,"qty":0.00000000},{"price":5728.07,"qty":0.10100000}],"checksum":3562144536,"timestamp":"2024-06-01T18:06:19.097315Z"}]}
{"channel":"book","type":"update","data":[{"symbol":"ETH/AUD","bids":[{"price":5716.38,"qty":0.00000000},{"price":5710.20,"qty":9.25315649},{"price":5717.00,"qty":0.07347674}],"asks":[],"checksum":2089013367,"timestamp":"2024-06-01T18:06:19.118677Z"}]}
{"channel":"book","type":"update","data":[{"symbol":"ETH/AUD","bids":[],"asks":[{"price":5719.51,"qty":0.01292326},{"price":5719.69,"qty":0.44085380}],"checksum":818270155,"timestamp":"2024-06-01T18:06:19.152173Z"}]}
{"channel":"book","type":"update","data":[{"symbol":"ETH/AUD","bids":[],"asks":[{"price":5722.11,"qty":5.15344452},{"price":5721.71,"qty":0.52250000}],"checksum":3833316250,"timestamp":"2024-06-01T18:06:19.634788Z"}]}
{"channel":"book","type":"update","data":[{"symbol":"ETH/AUD","bids":[{"price":5716.99,"qty":0.00000000},{"price":5710.20,"qty":9.25315649},{"price":5717.01,"qty":1.03590100}],"asks":[],"checksum":2424110599,"timestamp":"2024-06-01T18:06:19.732453Z"}]}
{"channel":"book","type":"update","data":[{"symbol":"ETH/AUD","bids":[{"price":5712.15,"qty":0.00000000},{"price":5710.20,"qty":9.25315649}],"asks":[],"checksum":4199657727,"timestamp":"2024-06-01T18:06:19.984702Z"}]}
{"channel":"book","type":"update","data":[{"symbol":"ETH/AUD","bids":[{"price":5712.12,"qty":0.00526197}],"asks":[],"checksum":46778387,"timestamp":"2024-06-01T18:06:19.986721Z"}]}
{"channel":"book","type":"update","data":[{"symbol":"ETH/AUD","bids":[{"price":5710.22,"qty":0.06673557}],"asks":[],"checksum":1244146076,"timestamp":"2024-06-01T18:06:19.986862Z"}]}
{"channel":"book","type":"update","data":[{"symbol":"ETH/AUD","bids":[],"asks":[{"price":5719.50,"qty":0.90387105}],"checksum":4184283984,"timestamp":"2024-06-01T18:06:20.176573Z"}]}
{"channel":"book","type":"update","data":[{"symbol":"ETH/AUD","bids":[],"asks":[{"price":5719.70,"qty":0.00000000},{"price":5724.84,"qty":0.83372964}],"checksum":3101327380,"timestamp":"2024-06-01T18:06:20.181065Z"}]}
{"channel":"book","type":"update","data":[{"symbol":"ETH/AUD","bids":[],"asks":[{"price":5719.51,"qty":0.00000000},{"price":5726.77,"qty":1.60677000},{"price":5719.49,"qty":0.01292326}],"checksum":1568812801,"timestamp":"2024-06-01T18:06:20.215836Z"}]}
{"channel":"book","type":"update","data":[{"symbol":"ETH/AUD","bids":[],"asks":[{"price":5719.48,"qty":0.90387105}],"checksum":3150157636,"timestamp":"2024-06-01T18:06:20.222922Z"}]}
{"channel":"book","type":"update","data":[{"symbol":"ETH/AUD","bids":[{"price":5717.00,"qty":0.00000000},{"price":5710.21,"qty":0.74582846},{"price":5716.38,"qty":0.07347674}],"asks":[],"checksum":692042123,"timestamp":"2024-06-01T18:06:20.247971Z"}]}
{"channel":"book","type":"update","data":[{"symbol":"ETH/AUD","bids":[],"asks":[{"price":5719.50,"qty":0.00000000},{"price":5724.84,"qty":0.83372964}],"checksum":2660018173,"timestamp":"2024-06-01T18:06:20.252817Z"}]}
{"channel":"book","type":"update","data":[{"symbol":"ETH/AUD","bids":[{"price":5717.01,"qty":0.00000000},{"price":5710.21,"qty":0.74582846},{"price":5716.99,"qty":1.03591354}],"asks":[],"checksum":2392630832,"timestamp":"2024-06-01T18:06:20.298824Z"}]}
{"channel":"book","type":"update","data":[{"symbol":"ETH/AUD","bids":[{"price":5716.84,"qty":0.00000000},{"price":5710.21,"qty":0.74582846}],"asks":[],"checksum":1143431365,"timestamp":"2024-06-01T18:06:20.328604Z"}]}
{"channel":"book","type":"update","data":[{"symbol":"ETH/AUD","bids":[{"price":5716.37,"qty":0.00000000},{"price":5710.20,"qty":9.25315649}],"asks":[],"checksum":2796560657,"timestamp":"2024-06-01T18:06:20.329684Z"}]}
{"channel":"book","type":"update","data":[{"symbol":"ETH/AUD","bids":[{"price":5716.29,"qty":3.12335095}],"asks":[],"checksum":2483558876,"timestamp":"2024-06-01T18:06:20.334350Z"}]}
{"channel":"book","type":"update","data":[{"symbol":"ETH/AUD","bids":[{"price":5716.29,"qty":0.00000000},{"price":5710.20,"qty":9.25315649}],"asks":[],"checksum":2796560657,"timestamp":"2024-06-01T18:06:20.338565Z"}]}
{"channel":"book","type":"update","data":[{"symbol":"ETH/AUD","bids":[{"price":5716.13,"qty":3.12344127}],"asks":[],"checksum":423305100,"timestamp":"2024-06-01T18:06:20.343485Z"}]}
{"channel":"book","type":"update","data":[{"symbol":"ETH/AUD","bids":[{"price":5710.21,"qty":0.00000000},{"price":5710.20,"qty":9.25315649}],"asks":[],"checksum":1723911832,"timestamp":"2024-06-01T18:06:20.371040Z"}]}
{"channel":"book","type":"update","data":[{"symbol":"ETH/AUD","bids":[{"price":5716.99,"qty":0.00000000},{"price":5710.06,"qty":0.08300000},{"price":5717.00,"qty":1.03591173}],"asks":[],"checksum":3367561037,"timestamp":"2024-06-01T18:06:20.384257Z"}]}
{"channel":"book","type":"update","data":[{"symbol":"ETH/AUD","bids":[],"asks":[{"price":5719.69,"qty":0.00000000},{"price":5726.77,"qty":1.60677000},{"price":5719.47,"qty":0.44081866}],"checksum":237962130,"timestamp":"2024-06-01T18:06:20.384333Z"}]}
{"channel":"book","type":"update","data":[{"symbol":"ETH/AUD","bids":[{"price":5716.13,"qty":0.00000000},{"price":5710.06,"qty":0.08300000}],"asks":[],"checksum":496060911,"timestamp":"2024-06-01T18:06:20.386556Z"}]}
{"channel":"book","type":"update","data":[{"symbol":"ETH/AUD","bids":[{"price":5715.95,"qty":3.12353980}],"asks":[],"checksum":3107295334,"timestamp":"2024-06-01T18:06:20.390707Z"}]}
{"channel":"book","type":"update","data":[{"symbol":"ETH/AUD","bids":[{"price":5715.95,"qty":0.00000000},{"price":5710.06,"qty":0.08300000}],"asks":[],"checksum":496060911,"timestamp":"2024-06-01T18:06:20.453468Z"}]}
{"channel":"book","type":"update","data":[{"symbol":"ETH/AUD","bids":[{"price":5715.92,"qty":3.12355622}],"asks":[],"checksum":1272237913,"timestamp":"2024-06-01T18:06:20.458222Z"}]}
{"channel":"book","type":"update","data":[{"symbol":"ETH/AUD","bids":[{"price":5717.00,"qty":0.00000000},{"price":5710.06,"qty":0.08300000},{"price":5716.99,"qty":1.03591363}],"asks":[],"checksum":697278516,"timestamp":"2024-06-01T18:06:20.498880Z"}]}
{"channel":"book","type":"update","data":[{"symbol":"ETH/AUD","bids":[{"price":5712.13,"qty":0.02406309}],"asks":[],"checksum":2439796599,"timestamp":"2024-06-01T18:06:20.499078Z"}]}
{"channel":"book","type":"update","data":[{"symbol":"ETH/AUD","bids":[{"price":5712.11,"qty":0.00000000},{"price":5710.20,"qty":9.25315649}],"asks":[],"checksum":2171276125,"timestamp":"2024-06-01T18:06:20.670270Z"}]}
{"channel":"book","type":"update","data":[{"symbol":"ETH/AUD","bids":[{"price":5715.92,"qty":0.00000000},{"price":5710.06,"qty":0.08300000}],"asks":[],"checksum":294689695,"timestamp":"2024-06-01T18:06:20.825165Z"}]}
{"channel":"book","type":"update","data":[{"symbol":"ETH/AUD","bids":[{"price":5715.83,"qty":3.12360549}],"asks":[],"checksum":1387985467,"timestamp":"2024-06-01T18:06:20.829323Z"}]}
{"channel":"book","type":"update","data":[{"symbol":"ETH/AUD","bids":[],"asks":[{"price":5719.49,"qty":0.00000000},{"price":5726.77,"qty":1.60677000},{"price":5719.46,"qty":0.01292326}],"checksum":2610206962,"timestamp":"2024-06-01T18:06:20.836774Z"}]}
{"channel":"book","type":"update","data":[{"symbol":"ETH/AUD","bids":[{"price":5715.83,"qty":0.00000000},{"price":5710.06,"qty":0.08300000}],"asks":[],"checksum":1372148009,"timestamp":"2024-06-01T18:06:20.907850Z"}]}
{"channel":"book","type":"update","data":[{"symbol":"ETH/AUD","bids":[{"price":5715.75,"qty":3.12364655}],"asks":[],"checksum":502479486,"timestamp":"2024-06-01T18:06:20.912483Z"}]}
{"channel":"book","type":"update","data":[{"symbol":"ETH/AUD","bids":[],"asks":[{"price":5719.45,"qty":0.90387105}],"checksum":2069404222,"timestamp":"2024-06-01T18:06:20.913087Z"}]}
{"channel":"book","type":"update","data":[{"symbol":"ETH/AUD","bids":[{"price":5710.20,"qty":0.00000000},{"price":5710.06,"qty":0.08300000}],"asks":[],"checksum":2112308884,"timestamp":"2024-06-01T18:06:20.985776Z"}]}
{"channel":"book","type":"update","data":[{"symbol":"ETH/AUD","bids":[{"price":5712.10,"qty":0.52624696}],"asks":[],"checksum":3661211776,"timestamp":"2024-06-01T18:06:20.986685Z"}]}
{"channel":"book","type":"update","data":[{"symbol":"ETH/AUD","bids":[{"price":5712.09,"qty":0.00000000},{"price":5710.06,"qty":0.08300000},{"price":5712.11,"qty":0.52250000}],"asks":[],"checksum":2428056200,"timestamp":"2024-06-01T18:06:20.989741Z"}]}
{"channel":"book","type":"update","data":[{"symbol":"ETH/AUD","bids":[{"price":5712.11,"qty":0.00000000},{"price":5710.06,"qty":0.08300000}],"asks":[],"checksum":1854799404,"timestamp":"2024-06-01T18:06:21.019212Z"}]}
{"channel":"book","type":"update","data":[{"symbol":"ETH/AUD","bids":[],"asks":[{"price":5719.47,"qty":0.00000000},{"price":5724.84,"qty":0.83372964},{"price":5719.44,"qty":0.44081874}],"checksum":1671019994,"timestamp":"2024-06-01T18:06:21.019565Z"}]}
{"channel":"book","type":"update","data":[{"symbol":"ETH/AUD","bids":[],"asks":[{"price":5719.48,"qty":0.00000000},{"price":5724.84,"qty":0.83372964}],"checksum":4171525579,"timestamp":"2024-06-01T18:06:21.025384Z"}]}
{"channel":"book","type":"update","data":[{"symbol":"ETH/AUD","bids":[],"asks":[{"price":5721.73,"qty":0.00000000},{"price":5726.77,"qty":1.60677000}],"checksum":138317537,"timestamp":"2024-06-01T18:06:21.259710Z"}]}
{"channel":"book","type":"update","data":[{"symbol":"ETH/AUD","bids":[],"asks":[{"price":5721.70,"qty":0.06072013}],"checksum":1677646494,"timestamp":"2024-06-01T18:06:21.264658Z"}]}
{"channel":"book","type":"update","data":[{"symbol":"ETH/AUD","bids":[{"price":5715.75,"qty":0.00000000},{"price":5709.80,"qty":9.75458358}],"asks":[],"checksum":1478700272,"timestamp":"2024-06-01T18:06:21.382766Z"}]}
{"channel":"book","type":"update","data":[{"symbol":"ETH/AUD","bids":[{"price":5715.52,"qty":3.12376973}],"asks":[],"checksum":2650527968,"timestamp":"2024-06-01T18:06:21.386790Z"}]}
{"channel":"book","type":"update","data":[{"symbol":"ETH/AUD","bids":[],"asks":[{"price":5721.72,"qty":0.00000000},{"price":5726.77,"qty":1.60677000}],"checksum":1070096739,"timestamp":"2024-06-01T18:06:21.406895Z"}]}
{"channel":"book","type":"update","data":[{"symbol":"ETH/AUD","bids":[],"asks":[{"price":5722.11,"qty":0.00000000},{"price":5728.07,"qty":0.10100000}],"checksum":54517776,"timestamp":"2024-06-01T18:06:21.406997Z"}]}
{"channel":"book","type":"update","data":[{"symbol":"ETH/AUD","bids":[],"asks":[{"price":5721.71,"qty":0.00000000},{"price":5728.79,"qty":0.20717085},{"price":5722.10,"qty":0.52250000}],"checksum":234463278,"timestamp":"2024-06-01T18:06:21.410379Z"}]}
{"channel":"book","type":"update","data":[{"symbol":"ETH/AUD","bids":[],"asks":[{"price":5721.70,"qty":2.13679102}],"checksum":322920370,"timestamp":"2024-06-01T18:06:21.411673Z"}]}
{"channel":"book","type":"update","data":[{"symbol":"ETH/AUD","bids":[],"asks":[{"price":5722.11,"qty":6.19018707}],"checksum":3987798955,"timestamp":"2024-06-01T18:06:21.411784Z"}]}
{"channel":"book","type":"update","data":[{"symbol":"ETH/AUD","bids":[],"asks":[{"price":5719.46,"qty":0.00000000},{"price":5728.07,"qty":0.10100000},{"price":5719.43,"qty":0.01292326}],"checksum":3768552538,"timestamp":"2024-06-01T18:06:21.427217Z"}]}
{"channel":"book","type":"update","data":[{"symbol":"ETH/AUD","bids":[],"asks":[{"price":5724.84,"qty":0.00000000},{"price":5728.07,"qty":0.10100000}],"checksum":2281326096,"timestamp":"2024-06-01T18:06:21.529618Z"}]}
{"channel":"book","type":"update","data":[{"symbol":"ETH/AUD","bids":[],"asks":[{"price":5722.09,"qty":0.83372964}],"checksum":2689189314,"timestamp":"2024-06-01T18:06:21.560732Z"}]}
{"channel":"book","type":"update","data":[{"symbol":"ETH/AUD","bids":[],"asks":[{"price":5719.44,"qty":0.00000000},{"price":5728.07,"qty":0.10100000},{"price":5719.42,"qty":0.44077846}],"checksum":3994648465,"timestamp":"2024-06-01T18:06:21.733913Z"}]}
{"channel":"book","type":"update","data":[{"symbol":"ETH/AUD","bids":[],"asks":[{"price":5722.10,"qty":0.00000000},{"price":5728.07,"qty":0.10100000},{"price":5721.69,"qty":0.52250000}],"checksum":1944401647,"timestamp":"2024-06-01T18:06:22.024614Z"}]}
{"channel":"book","type":"update","data":[{"symbol":"ETH/AUD","bids":[],"asks":[{"price":5719.41,"qty":0.90387105}],"checksum":1197010201,"timestamp":"2024-06-01T18:06:22.030206Z"}]}
{"channel":"book","type":"update","data":[{"symbol":"ETH/AUD","bids":[{"price":5711.29,"qty":0.52250000}],"asks":[],"checksum":1180063717,"timestamp":"2024-06-01T18:06:22.034852Z"}]}
{"channel":"book","type":"update","data":[{"symbol":"ETH/AUD","bids":[],"asks":[{"price":5719.43,"qty":0.00000000},{"price":5726.77,"qty":1.60677000},{"price":5719.40,"qty":0.01292326}],"checksum":2426996670,"timestamp":"2024-06-01T18:06:22.039082Z"}]}
{"channel":"book","type":"update","data":[{"symbol":"ETH/AUD","bids":[],"asks":[{"price":5719.45,"qty":0.00000000},{"price":5726.77,"qty":1.60677000}],"checksum":2038771945,"timestamp":"2024-06-01T18:06:22.176437Z"}]}
{"channel":"book","type":"update","data":[{"symbol":"ETH/AUD","bids":[],"asks":[{"price":5719.42,"qty":0.00000000},{"price":5728.07,"qty":0.10100000},{"price":5719.39,"qty":0.44077883}],"checksum":149423675,"timestamp":"2024-06-01T18:06:22.391470Z"}]}
{"channel":"book","type":"update","data":[{"symbol":"ETH/AUD","bids":[],"asks":[{"price":5719.40,"qty":0.00000000},{"price":5728.07,"qty":0.10100000},{"price":5719.38,"qty":0.01292326}],"checksum":1446241895,"timestamp":"2024-06-01T18:06:22.709356Z"}]}
{"channel":"book","type":"update","data":[{"symbol":"ETH/AUD","bids":[],"asks":[{"price":5722.09,"qty":0.00000000},{"price":5728.07,"qty":0.10100000}],"checksum":1830991452,"timestamp":"2024-06-01T18:06:22.955860Z"}]}
{"channel":"book","type":"update","data":[{"symbol":"ETH/AUD","bids":[],"asks":[{"price":5726.76,"qty":0.83372964}],"checksum":3213062465,"timestamp":"2024-06-01T18:06:22.987917Z"}]}
{"channel":"book","type":"update","data":[{"symbol":"ETH/AUD","bids":[],"asks":[{"price":5719.39,"qty":0.00000000},{"price":5728.07,"qty":0.10100000},{"price":5719.37,"qty":0.44077875}],"checksum":11827885,"timestamp":"2024-06-01T18:06:23.096076Z"}]}
{"channel":"book","type":"update","data":[{"symbol":"ETH/AUD","bids":[{"price":5711.29,"qty":0.00000000},{"price":5710.06,"qty":0.08300000},{"price":5710.07,"qty":0.52250000}],"asks":[],"checksum":2033460761,"timestamp":"2024-06-01T18:06:23.099141Z"}]}
{"channel":"book","type":"update","data":[{"symbol":"ETH/AUD","bids":[{"price":5715.53,"qty":0.90387105}],"asks":[],"checksum":897564824,"timestamp":"2024-06-01T18:06:23.101312Z"}]}
{"channel":"book","type":"update","data":[{"symbol":"ETH/AUD","bids":[],"asks":[{"price":5719.36,"qty":0.90387105}],"checksum":3187702554,"timestamp":"2024-06-01T18:06:23.101402Z"}]}
{"channel":"book","type":"update","data":[{"symbol":"ETH/AUD","bids":[],"asks":[{"price":5719.41,"qty":0.00000000},{"price":5726.77,"qty":1.60677000}],"checksum":605298807,"timestamp":"2024-06-01T18:06:23.176214Z"}]}
{"channel":"book","type":"update","data":[{"symbol":"ETH/AUD","bids":[],"asks":[{"price":5719.73,"qty":0.00000000},{"price":5728.07,"qty":0.10100000},{"price":5719.37,"qty":0.50729275}],"checksum":769876329,"timestamp":"2024-06-01T18:06:23.176902Z"}]}
{"channel":"book","type":"update","data":[{"symbol":"ETH/AUD","bids":[{"price":5712.12,"qty":0.00000000},{"price":5710.07,"qty":0.52250000}],"asks":[],"checksum":2694565554,"timestamp":"2024-06-01T18:06:23.181347Z"}]}
{"channel":"book","type":"update","data":[{"symbol":"ETH/AUD","bids":[{"price":5710.22,"qty":0.00000000},{"price":5710.06,"qty":0.08300000}],"asks":[],"checksum":2434352169,"timestamp":"2024-06-01T18:06:23.181445Z"}]}
{"channel":"book","type":"update","data":[{"symbol":"ETH/AUD","bids":[{"price":5712.11,"qty":0.00526275}],"asks":[],"checksum":3048984477,"timestamp":"2024-06-01T18:06:23.182050Z"}]}
{"channel":"book","type":"update","data":[{"symbol":"ETH/AUD","bids":[{"price":5716.38,"qty":0.00000000},{"price":5710.06,"qty":0.08300000},{"price":5717.00,"qty":0.07347674}],"asks":[],"checksum":2384479490,"timestamp":"2024-06-01T18:06:23.201852Z"}]}
{"channel":"book","type":"update","data":[{"symbol":"ETH/AUD","bids":[],"asks":[{"price":5722.11,"qty":0.00000000},{"price":5728.79,"qty":0.20717085}],"checksum":3043157590,"timestamp":"2024-06-01T18:06:23.667398Z"}]}
{"channel":"book","type":"update","data":[{"symbol":"ETH/AUD","bids":[],"asks":[{"price":5721.70,"qty":0.06072013}],"checksum":3817532583,"timestamp":"2024-06-01T18:06:23.667665Z"}]}
{"channel":"book","type":"update","data":[{"symbol":"ETH/AUD","bids":[],"asks":[{"price":5721.69,"qty":0.00000000},{"price":5729.62,"qty":2.35323000},{"price":5722.11,"qty":0.52250000}],"checksum":2567279785,"timestamp":"2024-06-01T18:06:23.671410Z"}]}
{"channel":"book","type":"update","data":[{"symbol":"ETH/AUD","bids":[],"asks":[{"price":5721.68,"qty":3.10930293}],"checksum":217161398,"timestamp":"2024-06-01T18:06:23.673737Z"}]}
{"channel":"book","type":"update","data":[{"symbol":"ETH/AUD","bids":[],"asks":[{"price":5722.11,"qty":8.76801063}],"checksum":953082873,"timestamp":"2024-06-01T18:06:23.673766Z"}]}
{"channel":"book","type":"update","data":[{"symbol":"ETH/AUD","bids":[],"asks":[{"price":5721.70,"qty":0.00000000},{"price":5728.79,"qty":0.20717085}],"checksum":3936277715,"timestamp":"2024-06-01T18:06:23.707903Z"}]}
{"channel":"book","type":"update","data":[{"symbol":"ETH/AUD","bids":[],"asks":[{"price":5721.68,"qty":3.18688400}],"checksum":4019085164,"timestamp":"2024-06-01T18:06:23.709995Z"}]}
{"channel":"book","type":"update","data":[{"symbol":"ETH/AUD","bids":[{"price":5715.52,"qty":0.00000000},{"price":5710.06,"qty":0.08300000}],"asks":[],"checksum":683882192,"timestamp":"2024-06-01T18:06:23.723938Z"}]}
{"channel":"book","type":"update","data":[{"symbol":"ETH/AUD","bids":[{"price":5710.07,"qty":0.00000000},{"price":5709.81,"qty":0.06674540},{"price":5712.11,"qty":0.52776275}],"asks":[],"checksum":843244276,"timestamp":"2024-06-01T18:06:23.725598Z"}]}
{"channel":"book","type":"update","data":[{"symbol":"ETH/AUD","bids":[{"price":5715.46,"qty":3.12380258}],"asks":[],"checksum":876656264,"timestamp":"2024-06-01T18:06:23.728021Z"}]}
{"channel":"book","type":"update","data":[{"symbol":"ETH/AUD","bids":[{"price":5715.46,"qty":0.00000000},{"price":5709.81,"qty":0.06674540}],"asks":[],"checksum":843244276,"timestamp":"2024-06-01T18:06:23.728148Z"}]}
{"channel":"book","type":"update","data":[{"symbol":"ETH/AUD","bids":[{"price":5715.27,"qty":3.12390934}],"asks":[],"checksum":537587619,"timestamp":"2024-06-01T18:06:23.733594Z"}]}
{"channel":"book","type":"update","data":[{"symbol":"ETH/AUD","bids":[],"asks":[{"price":5719.38,"qty":0.00000000},{"price":5729.62,"qty":2.35323000},{"price":5721.67,"qty":0.01292326}],"checksum":2657486312,"timestamp":"2024-06-01T18:06:23.747959Z"}]}
{"channel":"book","type":"update","data":[{"symbol":"ETH/AUD","bids":[],"asks":[{"price":5719.37,"qty":0.06651400},{"price":5719.35,"qty":0.44077879}],"checksum":1525555533,"timestamp":"2024-06-01T18:06:23.757786Z"}]}
{"channel":"book","type":"update","data":[{"symbol":"ETH/AUD","bids":[{"price":5716.99,"qty":0.00000000},{"price":5709.81,"qty":0.06674540},{"price":5717.01,"qty":1.03591781}],"asks":[],"checksum":2643449428,"timestamp":"2024-06-01T18:06:23.757914Z"}]}
{"channel":"book","type":"update","data":[{"symbol":"ETH/AUD","bids":[{"price":5712.10,"qty":0.00000000},{"price":5709.81,"qty":0.06674540}],"asks":[],"checksum":2518199510,"timestamp":"2024-06-01T18:06:23.959977Z"}]}
{"channel":"book","type":"update","data":[{"symbol":"ETH/AUD","bids":[{"price":5709.82,"qty":9.25465508}],"asks":[],"checksum":1611871119,"timestamp":"2024-06-01T18:06:23.961069Z"}]}
{"channel":"book","type":"update","data":[{"symbol":"ETH/AUD","bids":[],"asks":[{"price":5719.34,"qty":0.90387105}],"checksum":3699881024,"timestamp":"2024-06-01T18:06:24.178756Z"}]}
{"channel":"book","type":"update","data":[{"symbol":"ETH/AUD","bids":[],"asks":[{"price":5722.11,"qty":8.24551063},{"price":5721.67,"qty":0.53542326}],"checksum":3551586768,"timestamp":"2024-06-01T18:06:24.181780Z"}]}
{"channel":"book","type":"update","data":[{"symbol":"ETH/AUD","bids":[],"asks":[{"price":5719.36,"qty":0.00000000},{"price":5728.07,"qty":0.10100000}],"checksum":4225343085,"timestamp":"2024-06-01T18:06:24.183134Z"}]}
{"channel":"book","type":"update","data":[{"symbol":"ETH/AUD","bids":[],"asks":[{"price":5719.35,"qty":0.00000000},{"price":5728.79,"qty":0.20717085},{"price":5719.33,"qty":0.44077789}],"checksum":2711908247,"timestamp":"2024-06-01T18:06:24.403239Z"}]}
{"channel":"book","type":"update","data":[{"symbol":"ETH/AUD","bids":[{"price":5717.00,"qty":0.00000000},{"price":5709.81,"qty":0.06674540},{"price":5717.02,"qty":0.07347674}],"asks":[],"checksum":82713343,"timestamp":"2024-06-01T18:06:24.428007Z"}]}
{"channel":"book","type":"update","data":[{"symbol":"ETH/AUD","bids":[{"price":5712.11,"qty":0.00526275},{"price":5712.09,"qty":0.52250000}],"asks":[],"checksum":32954723,"timestamp":"2024-06-01T18:06:24.890613Z"}]}
{"channel":"book","type":"update","data":[{"symbol":"ETH/AUD","bids":[{"price":5717.01,"qty":0.00000000},{"price":5709.82,"qty":9.25465508},{"price":5717.03,"qty":1.03592251}],"asks":[],"checksum":3635567096,"timestamp":"2024-06-01T18:06:25.088554Z"}]}
{"channel":"book","type":"update","data":[{"symbol":"ETH/AUD","bids":[],"asks":[{"price":5719.33,"qty":0.00000000},{"price":5728.79,"qty":0.20717085},{"price":5719.32,"qty":0.44077793}],"checksum":2961965346,"timestamp":"2024-06-01T18:06:25.088755Z"}]}
{"channel":"book","type":"update","data":[{"symbol":"ETH/AUD","bids":[],"asks":[{"price":5719.32,"qty":1.34464898}],"checksum":2974596467,"timestamp":"2024-06-01T18:06:25.095843Z"}]}
{"channel":"book","type":"update","data":[{"symbol":"ETH/AUD","bids":[{"price":5717.02,"qty":0.00000000},{"price":5709.82,"qty":9.25465508},{"price":5717.04,"qty":0.07347674}],"asks":[],"checksum":1370819299,"timestamp":"2024-06-01T18:06:25.115285Z"}]}
{"channel":"book","type":"update","data":[{"symbol":"ETH/AUD","bids":[],"asks":[{"price":5719.34,"qty":0.00000000},{"price":5728.79,"qty":0.20717085}],"checksum":1331090784,"timestamp":"2024-06-01T18:06:25.177560Z"}]}
{"channel":"book","type":"update","data":[{"symbol":"ETH/AUD","bids":[{"price":5712.09,"qty":0.00000000},{"price":5709.82,"qty":9.25465508}],"asks":[],"checksum":538920542,"timestamp":"2024-06-01T18:06:25.435605Z"}]}
{"channel":"book","type":"update","data":[{"symbol":"ETH/AUD","bids":[],"asks":[{"price":5721.67,"qty":0.01292326},{"price":5719.31,"qty":0.52250000}],"checksum":3881306687,"timestamp":"2024-06-01T18:06:25.435908Z"}]}
{"channel":"book","type":"update","data":[{"symbol":"ETH/AUD","bids":[{"price":5711.75,"qty":0.52250000}],"asks":[],"checksum":1804210185,"timestamp":"2024-06-01T18:06:25.442442Z"}]}
{"channel":"book","type":"update","data":[{"symbol":"ETH/AUD","bids":[{"price":5715.27,"qty":0.00000000},{"price":5709.82,"qty":9.25465508}],"asks":[],"checksum":4124270324,"timestamp":"2024-06-01T18:06:25.474219Z"}]}
{"channel":"book","type":"update","data":[{"symbol":"ETH/AUD","bids":[{"price":5715.10,"qty":3.12399969}],"asks":[],"checksum":2701475640,"timestamp":"2024-06-01T18:06:25.478951Z"}]}
{"channel":"book","type":"update","data":[{"symbol":"ETH/AUD","bids":[],"asks":[{"price":5721.67,"qty":0.00000000},{"price":5728.79,"qty":0.20717085},{"price":5719.30,"qty":0.01292326}],"checksum":1039646813,"timestamp":"2024-06-01T18:06:25.482697Z"}]}
{"channel":"book","type":"update","data":[{"symbol":"ETH/AUD","bids":[{"price":5717.03,"qty":0.00000000},{"price":5709.82,"qty":9.25465508},{"price":5715.54,"qty":1.03619500}],"asks":[],"checksum":3862122640,"timestamp":"2024-06-01T18:06:25.588214Z"}]}
{"channel":"book","type":"update","data":[{"symbol":"ETH/AUD","bids":[],"asks":[{"price":5719.32,"qty":0.90387105},{"price":5719.29,"qty":0.44076750}],"checksum":2983994771,"timestamp":"2024-06-01T18:06:25.769519Z"}]}
{"channel":"book","type":"update","data":[{"symbol":"ETH/AUD","bids":[],"asks":[{"price":5721.68,"qty":3.10930293}],"checksum":3443274846,"timestamp":"2024-06-01T18:06:26.035830Z"}]}
{"channel":"book","type":"update","data":[{"symbol":"ETH/AUD","bids":[],"asks":[{"price":5721.67,"qty":0.08712911}],"checksum":3781274563,"timestamp":"2024-06-01T18:06:26.037665Z"}]}
{"channel":"book","type":"update","data":[{"symbol":"ETH/AUD","bids":[],"asks":[{"price":5719.31,"qty":0.00000000},{"price":5726.77,"qty":1.60677000},{"price":5719.28,"qty":0.52250000}],"checksum":167607176,"timestamp":"2024-06-01T18:06:26.038710Z"}]}
{"channel":"book","type":"update","data":[{"symbol":"ETH/AUD","bids":[{"price":5711.75,"qty":0.00000000},{"price":5709.82,"qty":9.25465508},{"price":5710.07,"qty":0.52250000}],"asks":[],"checksum":3492892545,"timestamp":"2024-06-01T18:06:26.038870Z"}]}
{"channel":"book","type":"update","data":[{"symbol":"ETH/AUD","bids":[],"asks":[{"price":5719.27,"qty":0.90387105}],"checksum":3797001717,"timestamp":"2024-06-01T18:06:26.044565Z"}]}
{"channel":"book","type":"update","data":[{"symbol":"ETH/AUD","bids":[],"asks":[{"price":5721.68,"qty":0.00000000},{"price":5726.77,"qty":1.60677000}],"checksum":398130362,"timestamp":"2024-06-01T18:06:26.069447Z"}]}
{"channel":"book","type":"update","data":[{"symbol":"ETH/AUD","bids":[],"asks":[{"price":5722.11,"qty":0.00000000},{"price":5728.07,"qty":0.10100000}],"checksum":161559872,"timestamp":"2024-06-01T18:06:26.069460Z"}]}
{"channel":"book","type":"update","data":[{"symbol":"ETH/AUD","bids":[],"asks":[{"price":5722.11,"qty":12.40824446}],"checksum":4066808212,"timestamp":"2024-06-01T18:06:26.074658Z"}]}
{"channel":"book","type":"update","data":[{"symbol":"ETH/AUD","bids":[{"price":5717.04,"qty":0.00000000},{"price":5709.82,"qty":9.25465508},{"price":5715.55,"qty":0.07347674}],"asks":[],"checksum":884981624,"timestamp":"2024-06-01T18:06:26.092595Z"}]}
{"channel":"book","type":"update","data":[{"symbol":"ETH/AUD","bids":[],"asks":[{"price":5719.32,"qty":0.00000000},{"price":5728.07,"qty":0.10100000}],"checksum":3056100426,"timestamp":"2024-06-01T18:06:26.097438Z"}]}
{"channel":"book","type":"update","data":[{"symbol":"ETH/AUD","bids":[],"asks":[{"price":5721.66,"qty":0.83372964}],"checksum":2210424978,"timestamp":"2024-06-01T18:06:26.099816Z"}]}
{"channel":"book","type":"update","data":[{"symbol":"ETH/AUD","bids":[{"price":5712.11,"qty":0.00000000},{"price":5709.82,"qty":9.25465508}],"asks":[],"checksum":3567917070,"timestamp":"2024-06-01T18:06:26.408744Z"}]}
{"channel":"book","type":"update","data":[{"symbol":"ETH/AUD","bids":[{"price":5710.08,"qty":0.06302799}],"asks":[],"checksum":292476564,"timestamp":"2024-06-01T18:06:26.409115Z"}]}
{"channel":"book","type":"update","data":[{"symbol":"ETH/AUD","bids":[{"price":5715.54,"qty":0.00000000},{"price":5709.82,"qty":9.25465508},{"price":5715.56,"qty":1.03619172}],"asks":[],"checksum":1366269962,"timestamp":"2024-06-01T18:06:26.443069Z"}]}
{"channel":"book","type":"update","data":[{"symbol":"ETH/AUD","bids":[],"asks":[{"price":5719.29,"qty":0.00000000},{"price":5728.07,"qty":0.10100000},{"price":5719.26,"qty":0.44076766}],"checksum":1071836595,"timestamp":"2024-06-01T18:06:26.443093Z"}]}
{"channel":"book","type":"update","data":[{"symbol":"ETH/AUD","bids":[],"asks":[{"price":5719.25,"qty":0.90387105}],"checksum":2716854941,"timestamp":"2024-06-01T18:06:26.448396Z"}]}
{"channel":"book","type":"update","data":[{"symbol":"ETH/AUD","bids":[{"price":5715.53,"qty":0.00000000},{"price":5709.82,"qty":9.25465508}],"asks":[],"checksum":3762719049,"timestamp":"2024-06-01T18:06:26.655613Z"}]}
{"channel":"book","type":"update","data":[{"symbol":"ETH/AUD","bids":[{"price":5715.10,"qty":0.00000000},{"price":5709.79,"qty":2.35323000}],"asks":[],"checksum":3259745065,"timestamp":"2024-06-01T18:06:26.656889Z"}]}
{"channel":"book","type":"update","data":[{"symbol":"ETH/AUD","bids":[],"asks":[{"price":5719.28,"qty":0.00000000},{"price":5726.77,"qty":1.60677000},{"price":5719.24,"qty":0.52250000}],"checksum":3342861448,"timestamp":"2024-06-01T18:06:26.658502Z"}]}
{"channel":"book","type":"update","data":[{"symbol":"ETH/AUD","bids":[],"asks":[{"price":5719.27,"qty":0.00000000},{"price":5726.77,"qty":1.60677000}],"checksum":2096020700,"timestamp":"2024-06-01T18:06:26.660208Z"}]}
{"channel":"book","type":"update","data":[{"symbol":"ETH/AUD","bids":[{"price":5714.89,"qty":3.12411468}],"asks":[],"checksum":3944153095,"timestamp":"2024-06-01T18:06:26.661242Z"}]}
{"channel":"book","type":"update","data":[{"symbol":"ETH/AUD","bids":[{"price":5715.55,"qty":0.00000000},{"price":5709.79,"qty":2.35323000},{"price":5715.57,"qty":0.07347674}],"asks":[],"checksum":1564172218,"timestamp":"2024-06-01T18:06:26.675285Z"}]}
{"channel":"book","type":"update","data":[{"symbol":"ETH/AUD","bids":[{"price":5716.98,"qty":0.00000000},{"price":5709.79,"qty":2.35323000},{"price":5715.57,"qty":0.14001874}],"asks":[],"checksum":811218598,"timestamp":"2024-06-01T18:06:26.796818Z"}]}
{"channel":"book","type":"update","data":[{"symbol":"ETH/AUD","bids":[{"price":5709.82,"qty":0.00000000},{"price":5709.48,"qty":1.28000000}],"asks":[],"checksum":2486729892,"timestamp":"2024-06-01T18:06:26.980693Z"}]}
{"channel":"book","type":"update","data":[{"symbol":"ETH/AUD","bids":[{"price":5710.09,"qty":9.38393632}],"asks":[],"checksum":2147562804,"timestamp":"2024-06-01T18:06:26.981645Z"}]}
{"channel":"book","type":"update","data":[{"symbol":"ETH/AUD","bids":[{"price":5710.07,"qty":0.00000000},{"price":5709.48,"qty":1.28000000},{"price":5710.10,"qty":0.52250000}],"asks":[],"checksum":4122346541,"timestamp":"2024-06-01T18:06:26.984604Z"}]}
{"channel":"book","type":"update","data":[{"symbol":"ETH/AUD","bids":[],"asks":[{"price":5719.23,"qty":0.90387105}],"checksum":3325512685,"timestamp":"2024-06-01T18:06:27.175947Z"}]}
{"channel":"book","type":"update","data":[{"symbol":"ETH/AUD","bids":[],"asks":[{"price":5719.24,"qty":0.00000000},{"price":5726.77,"qty":1.60677000},{"price":5719.22,"qty":0.52250000}],"checksum":2959701637,"timestamp":"2024-06-01T18:06:27.178853Z"}]}
{"channel":"book","type":"update","data":[{"symbol":"ETH/AUD","bids":[],"asks":[{"price":5722.12,"qty":0.00000000},{"price":5726.77,"qty":1.60677000}],"checksum":2282602775,"timestamp":"2024-06-01T18:06:27.179064Z"}]}
{"channel":"book","type":"update","data":[{"symbol":"ETH/AUD","bids":[{"price":5715.56,"qty":0.00000000},{"price":5709.48,"qty":1.28000000},{"price":5715.58,"qty":1.03618820}],"asks":[],"checksum":66855825,"timestamp":"2024-06-01T18:06:27.179655Z"}]}
{"channel":"book","type":"update","data":[{"symbol":"ETH/AUD","bids":[],"asks":[{"price":5719.26,"qty":0.00000000},{"price":5728.07,"qty":0.10100000},{"price":5719.23,"qty":1.34463876}],"checksum":3862163008,"timestamp":"2024-06-01T18:06:27.179692Z"}]}
{"channel":"book","type":"update","data":[{"symbol":"ETH/AUD","bids":[],"asks":[{"price":5719.25,"qty":0.00000000},{"price":5728.79,"qty":0.20717085}],"checksum":2503765286,"timestamp":"2024-06-01T18:06:27.180465Z"}]}
{"channel":"book","type":"update","data":[{"symbol":"ETH/AUD","bids":[],"asks":[{"price":5720.64,"qty":11.16994099}],"checksum":887333689,"timestamp":"2024-06-01T18:06:27.181928Z"}]}
{"channel":"book","type":"update","data":[{"symbol":"ETH/AUD","bids":[{"price":5715.57,"qty":0.06654200},{"price":5715.59,"qty":0.07347674}],"asks":[],"checksum":2263711785,"timestamp":"2024-06-01T18:06:27.499176Z"}]}
{"channel":"book","type":"update","data":[{"symbol":"ETH/AUD","bids":[],"asks":[{"price":5724.89,"qty":0.10400000}],"checksum":1809264548,"timestamp":"2024-06-01T18:06:27.568135Z"}]}
{"channel":"book","type":"update","data":[{"symbol":"ETH/AUD","bids":[],"asks":[{"price":5719.30,"qty":0.00000000},{"price":5728.07,"qty":0.10100000},{"price":5719.21,"qty":0.01292326}],"checksum":3874194269,"timestamp":"2024-06-01T18:06:27.896551Z"}]}
{"channel":"book","type":"update","data":[{"symbol":"ETH/AUD","bids":[],"asks":[{"price":5719.20,"qty":0.90387105}],"checksum":40461294,"timestamp":"2024-06-01T18:06:27.902179Z"}]}
{"channel":"book","type":"update","data":[{"symbol":"ETH/AUD","bids":[],"asks":[{"price":5719.23,"qty":0.90387105},{"price":5719.21,"qty":0.45369099}],"checksum":102667346,"timestamp":"2024-06-01T18:06:27.904768Z"}]}
{"channel":"book","type":"update","data":[{"symbol":"ETH/AUD","bids":[{"price":5715.58,"qty":0.00000000},{"price":5709.79,"qty":2.35323000},{"price":5715.60,"qty":1.03617443}],"asks":[],"checksum":2145613631,"timestamp":"2024-06-01T18:06:27.904815Z"}]}
{"channel":"book","type":"update","data":[{"symbol":"ETH/AUD","bids":[],"asks":[{"price":5719.22,"qty":0.00000000},{"price":5726.77,"qty":1.60677000},{"price":5719.19,"qty":0.52250000}],"checksum":737699410,"timestamp":"2024-06-01T18:06:27.905112Z"}]}
{"channel":"book","type":"update","data":[{"symbol":"ETH/AUD","bids":[],"asks":[{"price":5719.23,"qty":0.00000000},{"price":5726.77,"qty":1.60677000}],"checksum":3376233915,"timestamp":"2024-06-01T18:06:28.176842Z"}]}
{"channel":"book","type":"update","data":[{"symbol":"ETH/AUD","bids":[],"asks":[{"price":5722.11,"qty":0.00000000},{"price":5728.07,"qty":0.10100000}],"checksum":2473084877,"timestamp":"2024-06-01T18:06:28.380349Z"}]}
{"channel":"book","type":"update","data":[{"symbol":"ETH/AUD","bids":[],"asks":[{"price":5720.63,"qty":7.22894733}],"checksum":435343410,"timestamp":"2024-06-01T18:06:28.385186Z"}]}
{"channel":"book","type":"update","data":[{"symbol":"ETH/AUD","bids":[],"asks":[{"price":5719.18,"qty":1.04293977}],"checksum":607509359,"timestamp":"2024-06-01T18:06:28.385239Z"}]}
{"channel":"book","type":"update","data":[{"symbol":"ETH/AUD","bids":[{"price":5715.59,"qty":0.00000000},{"price":5709.79,"qty":2.35323000},{"price":5715.61,"qty":0.07347674}],"asks":[],"checksum":450489625,"timestamp":"2024-06-01T18:06:28.413175Z"}]}
{"channel":"book","type":"update","data":[{"symbol":"ETH/AUD","bids":[],"asks":[{"price":5719.19,"qty":0.00000000},{"price":5726.77,"qty":1.60677000},{"price":5719.17,"qty":0.52250000}],"checksum":135154685,"timestamp":"2024-06-01T18:06:28.416227Z"}]}
{"channel":"book","type":"update","data":[{"symbol":"ETH/AUD","bids":[],"asks":[{"price":5721.67,"qty":0.00000000},{"price":5726.77,"qty":1.60677000}],"checksum":1916339861,"timestamp":"2024-06-01T18:06:28.474153Z"}]}
{"channel":"book","type":"update","data":[{"symbol":"ETH/AUD","bids":[],"asks":[{"price":5720.63,"qty":7.29596564}],"checksum":3422880983,"timestamp":"2024-06-01T18:06:28.476209Z"}]}
{"channel":"book","type":"update","data":[{"symbol":"ETH/AUD","bids":[],"asks":[{"price":5719.21,"qty":0.01292326},{"price":5719.16,"qty":0.44077895}],"checksum":3521386424,"timestamp":"2024-06-01T18:06:28.625048Z"}]}
{"channel":"book","type":"update","data":[{"symbol":"ETH/AUD","bids":[{"price":5715.60,"qty":0.00000000},{"price":5709.79,"qty":2.35323000},{"price":5715.62,"qty":1.03617134}],"asks":[],"checksum":2820184797,"timestamp":"2024-06-01T18:06:28.625171Z"}]}
{"channel":"book","type":"update","data":[{"symbol":"ETH/AUD","bids":[{"price":5714.89,"qty":4.02798573}],"asks":[],"checksum":1728457553,"timestamp":"2024-06-01T18:06:29.176420Z"}]}
{"channel":"book","type":"update","data":[{"symbol":"ETH/AUD","bids":[],"asks":[{"price":5719.15,"qty":0.90387105}],"checksum":2738284612,"timestamp":"2024-06-01T18:06:29.176539Z"}]}
{"channel":"book","type":"update","data":[{"symbol":"ETH/AUD","bids":[],"asks":[{"price":5719.17,"qty":0.00000000},{"price":5724.89,"qty":0.10400000},{"price":5719.15,"qty":1.42637105}],"checksum":56985992,"timestamp":"2024-06-01T18:06:29.179700Z"}]}
{"channel":"book","type":"update","data":[{"symbol":"ETH/AUD","bids":[],"asks":[{"price":5719.20,"qty":0.00000000},{"price":5726.77,"qty":1.60677000}],"checksum":2067634832,"timestamp":"2024-06-01T18:06:29.180917Z"}]}
{"channel":"book","type":"update","data":[{"symbol":"ETH/AUD","bids":[{"price":5715.61,"qty":0.00000000},{"price":5709.79,"qty":2.35323000},{"price":5715.63,"qty":0.07347674}],"asks":[],"checksum":1388722140,"timestamp":"2024-06-01T18:06:29.204179Z"}]}
{"channel":"book","type":"update","data":[{"symbol":"ETH/AUD","bids":[{"price":5715.62,"qty":0.00000000},{"price":5709.79,"qty":2.35323000},{"price":5715.64,"qty":1.03616713}],"asks":[],"checksum":535956870,"timestamp":"2024-06-01T18:06:29.404290Z"}]}
{"channel":"book","type":"update","data":[{"symbol":"ETH/AUD","bids":[],"asks":[{"price":5719.16,"qty":0.00000000},{"price":5728.07,"qty":0.10100000},{"price":5719.14,"qty":0.44077897}],"checksum":2370531939,"timestamp":"2024-06-01T18:06:29.404493Z"}]}
{"channel":"book","type":"update","data":[{"symbol":"ETH/AUD","bids":[{"price":5710.08,"qty":0.00000000},{"price":5709.79,"qty":2.35323000}],"asks":[],"checksum":4143185110,"timestamp":"2024-06-01T18:06:29.630332Z"}]}
