{"channel":"book","type":"snapshot","data":[{"symbol":"ETH/USDT","bids":[{"price":3802.95,"qty":0.25000000},{"price":3802.94,"qty":0.34000000},{"price":3802.84,"qty":1.31576177},{"price":3802.50,"qty":0.06693358},{"price":3802.41,"qty":2.63210689},{"price":3802.37,"qty":5.00000000},{"price":3802.33,"qty":0.73120000},{"price":3802.24,"qty":0.19703363},{"price":3802.23,"qty":0.84627249},{"price":3802.22,"qty":1.31570984}],"asks":[{"price":3803.69,"qty":1.46240000},{"price":3803.70,"qty":1.25745803},{"price":3803.90,"qty":2.63107706},{"price":3804.01,"qty":2.11700000},{"price":3804.11,"qty":0.25000000},{"price":3804.28,"qty":0.73120000},{"price":3804.37,"qty":0.33678927},{"price":3804.38,"qty":2.59268070},{"price":3804.39,"qty":0.72912968},{"price":3804.43,"qty":0.21644072}],"checksum":1411393024}]}
{"channel":"book","type":"update","data":[{"symbol":"ETH/USDT","bids":[{"price":3802.37,"qty":0.00000000},{"price":3802.14,"qty":0.19804353}],"asks":[],"checksum":1049876881,"timestamp":"2024-06-01T18:05:59.207932Z"}]}
{"channel":"book","type":"update","data":[{"symbol":"ETH/USDT","bids":[{"price":3802.50,"qty":0.00000000},{"price":3802.09,"qty":0.72912968}],"asks":[],"checksum":756155672,"timestamp":"2024-06-01T18:05:59.302864Z"}]}
{"channel":"book","type":"update","data":[{"symbol":"ETH/USDT","bids":[{"price":3802.94,"qty":0.00000000},{"price":3802.02,"qty":2.11800000}],"asks":[],"checksum":4018460063,"timestamp":"2024-06-01T18:05:59.305880Z"}]}
{"channel":"book","type":"update","data":[{"symbol":"ETH/USDT","bids":[{"price":3802.46,"qty":0.06693358}],"asks":[],"checksum":3399880328,"timestamp":"2024-06-01T18:05:59.406851Z"}]}
{"channel":"book","type":"update","data":[{"symbol":"ETH/USDT","bids":[{"price":3802.95,"qty":0.00000000},{"price":3802.02,"qty":2.11800000}],"asks":[],"checksum":1890011499,"timestamp":"2024-06-01T18:05:59.412024Z"}]}
{"channel":"book","type":"update","data":[{"symbol":"ETH/USDT","bids":[{"price":3802.85,"qty":0.25000000}],"asks":[],"checksum":717424719,"timestamp":"2024-06-01T18:05:59.412180Z"}]}
{"channel":"book","type":"update","data":[{"symbol":"ETH/USDT","bids":[{"price":3802.86,"qty":1.31569253}],"asks":[],"checksum":4280568139,"timestamp":"2024-06-01T18:05:59.738132Z"}]}
{"channel":"book","type":"update","data":[{"symbol":"ETH/USDT","bids":[{"price":3802.84,"qty":0.00000000},{"price":3802.09,"qty":0.72912968}],"asks":[],"checksum":3902735906,"timestamp":"2024-06-01T18:05:59.742025Z"}]}
{"channel":"book","type":"update","data":[{"symbol":"ETH/USDT","bids":[],"asks":[{"price":3804.38,"qty":0.00000000},{"price":3804.44,"qty":0.03706060}],"checksum":2422031268,"timestamp":"2024-06-01T18:05:59.760986Z"}]}
{"channel":"book","type":"update","data":[{"symbol":"ETH/USDT","bids":[],"asks":[{"price":3803.70,"qty":0.73120000}],"checksum":112219998,"timestamp":"2024-06-01T18:05:59.761165Z"}]}
{"channel":"book","type":"update","data":[{"symbol":"ETH/USDT","bids":[],"asks":[{"price":3803.68,"qty":1.04286370}],"checksum":1704617421,"timestamp":"2024-06-01T18:05:59.764468Z"}]}
{"channel":"book","type":"update","data":[{"symbol":"ETH/USDT","bids":[{"price":3802.87,"qty":0.25000000}],"asks":[],"checksum":1390717177,"timestamp":"2024-06-01T18:05:59.766715Z"}]}
{"channel":"book","type":"update","data":[{"symbol":"ETH/USDT","bids":[],"asks":[{"price":3803.70,"qty":0.00000000},{"price":3804.44,"qty":0.03706060}],"checksum":2068864207,"timestamp":"2024-06-01T18:05:59.768228Z"}]}
{"channel":"book","type":"update","data":[{"symbol":"ETH/USDT","bids":[],"asks":[{"price":3803.56,"qty":0.73120000}],"checksum":3159555030,"timestamp":"2024-06-01T18:05:59.768918Z"}]}
{"channel":"book","type":"update","data":[{"symbol":"ETH/USDT","bids":[{"price":3802.24,"qty":0.00000000},{"price":3802.09,"qty":0.72912968}],"asks":[],"checksum":3654796740,"timestamp":"2024-06-01T18:06:00.048370Z"}]}
{"channel":"book","type":"update","data":[{"symbol":"ETH/USDT","bids":[],"asks":[{"price":3803.55,"qty":0.40000000}],"checksum":1683779678,"timestamp":"2024-06-01T18:06:00.049251Z"}]}
{"channel":"book","type":"update","data":[{"symbol":"ETH/USDT","bids":[],"asks":[{"price":3803.47,"qty":0.73120000}],"checksum":464949605,"timestamp":"2024-06-01T18:06:00.052801Z"}]}
{"channel":"book","type":"update","data":[{"symbol":"ETH/USDT","bids":[],"asks":[{"price":3803.69,"qty":0.73120000}],"checksum":287196920,"timestamp":"2024-06-01T18:06:00.053210Z"}]}
{"channel":"book","type":"update","data":[{"symbol":"ETH/USDT","bids":[{"price":3802.85,"qty":0.00000000},{"price":3802.02,"qty":2.11800000}],"asks":[],"checksum":1979998795,"timestamp":"2024-06-01T18:06:00.085517Z"}]}
{"channel":"book","type":"update","data":[{"symbol":"ETH/USDT","bids":[{"price":3802.18,"qty":0.19702463}],"asks":[],"checksum":3892904161,"timestamp":"2024-06-01T18:06:00.088632Z"}]}
{"channel":"book","type":"update","data":[{"symbol":"ETH/USDT","bids":[{"price":3802.46,"qty":0.00000000},{"price":3802.02,"qty":2.11800000}],"asks":[],"checksum":3479820734,"timestamp":"2024-06-01T18:06:00.113196Z"}]}
{"channel":"book","type":"update","data":[{"symbol":"ETH/USDT","bids":[{"price":3802.36,"qty":0.06693358}],"asks":[],"checksum":1161238125,"timestamp":"2024-06-01T18:06:00.217046Z"}]}
{"channel":"book","type":"update","data":[{"symbol":"ETH/USDT","bids":[{"price":3802.18,"qty":0.00000000},{"price":3802.02,"qty":2.11800000}],"asks":[],"checksum":2460455766,"timestamp":"2024-06-01T18:06:00.744952Z"}]}
{"channel":"book","type":"update","data":[{"symbol":"ETH/USDT","bids":[{"price":3802.15,"qty":0.19701365}],"asks":[],"checksum":133937314,"timestamp":"2024-06-01T18:06:00.785345Z"}]}
{"channel":"book","type":"update","data":[{"symbol":"ETH/USDT","bids":[],"asks":[{"price":3803.56,"qty":0.00000000},{"price":3804.39,"qty":0.72912968}],"checksum":1292389298,"timestamp":"2024-06-01T18:06:01.128059Z"}]}
{"channel":"book","type":"update","data":[{"symbol":"ETH/USDT","bids":[],"asks":[{"price":3803.47,"qty":0.00000000},{"price":3804.43,"qty":0.21644072}],"checksum":1232567526,"timestamp":"2024-06-01T18:06:01.128375Z"}]}
{"channel":"book","type":"update","data":[{"symbol":"ETH/USDT","bids":[{"price":3802.87,"qty":0.98120000}],"asks":[],"checksum":3062713691,"timestamp":"2024-06-01T18:06:01.129330Z"}]}
{"channel":"book","type":"update","data":[{"symbol":"ETH/USDT","bids":[{"price":3802.87,"qty":0.25000000}],"asks":[],"checksum":1232567526,"timestamp":"2024-06-01T18:06:01.132404Z"}]}
{"channel":"book","type":"update","data":[{"symbol":"ETH/USDT","bids":[{"price":3802.89,"qty":0.73120000}],"asks":[],"checksum":78745097,"timestamp":"2024-06-01T18:06:01.134294Z"}]}
{"channel":"book","type":"update","data":[{"symbol":"ETH/USDT","bids":[{"price":3802.89,"qty":0.00000000},{"price":3802.09,"qty":0.72912968}],"asks":[],"checksum":1232567526,"timestamp":"2024-06-01T18:06:01.137184Z"}]}
{"channel":"book","type":"update","data":[{"symbol":"ETH/USDT","bids":[],"asks":[{"price":3803.69,"qty":0.00000000},{"price":3804.44,"qty":0.03706060}],"checksum":910890537,"timestamp":"2024-06-01T18:06:01.140134Z"}]}
{"channel":"book","type":"update","data":[{"symbol":"ETH/USDT","bids":[{"price":3802.87,"qty":0.98120000}],"asks":[],"checksum":3383830420,"timestamp":"2024-06-01T18:06:01.148427Z"}]}
{"channel":"book","type":"update","data":[{"symbol":"ETH/USDT","bids":[{"price":3802.91,"qty":0.73120000}],"asks":[],"checksum":2927468368,"timestamp":"2024-06-01T18:06:01.152849Z"}]}
{"channel":"book","type":"update","data":[{"symbol":"ETH/USDT","bids":[{"price":3802.91,"qty":0.00000000},{"price":3802.09,"qty":0.72912968}],"asks":[],"checksum":3383830420,"timestamp":"2024-06-01T18:06:01.156471Z"}]}
{"channel":"book","type":"update","data":[{"symbol":"ETH/USDT","bids":[{"price":3802.92,"qty":0.25000000}],"asks":[],"checksum":4069244320,"timestamp":"2024-06-01T18:06:01.158295Z"}]}
{"channel":"book","type":"update","data":[{"symbol":"ETH/USDT","bids":[{"price":3802.92,"qty":0.98120000}],"asks":[],"checksum":225545245,"timestamp":"2024-06-01T18:06:01.181019Z"}]}
{"channel":"book","type":"update","data":[{"symbol":"ETH/USDT","bids":[{"price":3802.88,"qty":0.34000000}],"asks":[],"checksum":1870112950,"timestamp":"2024-06-01T18:06:01.183869Z"}]}
{"channel":"book","type":"update","data":[{"symbol":"ETH/USDT","bids":[{"price":3802.87,"qty":0.73120000}],"asks":[],"checksum":2227797565,"timestamp":"2024-06-01T18:06:01.189572Z"}]}
{"channel":"book","type":"update","data":[{"symbol":"ETH/USDT","bids":[{"price":3802.93,"qty":0.73120000}],"asks":[],"checksum":1533521185,"timestamp":"2024-06-01T18:06:01.191640Z"}]}
{"channel":"book","type":"update","data":[{"symbol":"ETH/USDT","bids":[{"price":3802.87,"qty":0.00000000},{"price":3802.15,"qty":0.19701365}],"asks":[],"checksum":883573813,"timestamp":"2024-06-01T18:06:01.191859Z"}]}
{"channel":"book","type":"update","data":[{"symbol":"ETH/USDT","bids":[{"price":3802.93,"qty":1.46240000}],"asks":[],"checksum":3799015640,"timestamp":"2024-06-01T18:06:01.202281Z"}]}
{"channel":"book","type":"update","data":[{"symbol":"ETH/USDT","bids":[{"price":3802.88,"qty":0.00000000},{"price":3802.14,"qty":0.19804353}],"asks":[],"checksum":2954153521,"timestamp":"2024-06-01T18:06:01.238124Z"}]}
{"channel":"book","type":"update","data":[{"symbol":"ETH/USDT","bids":[{"price":3802.93,"qty":1.80240000}],"asks":[],"checksum":958198111,"timestamp":"2024-06-01T18:06:01.238494Z"}]}
{"channel":"book","type":"update","data":[{"symbol":"ETH/USDT","bids":[{"price":3802.94,"qty":0.25000000}],"asks":[],"checksum":978451446,"timestamp":"2024-06-01T18:06:01.243424Z"}]}
{"channel":"book","type":"update","data":[{"symbol":"ETH/USDT","bids":[{"price":3802.92,"qty":0.25000000}],"asks":[],"checksum":3789610142,"timestamp":"2024-06-01T18:06:01.246923Z"}]}
{"channel":"book","type":"update","data":[{"symbol":"ETH/USDT","bids":[{"price":3803.00,"qty":0.73120000}],"asks":[],"checksum":3859411677,"timestamp":"2024-06-01T18:06:01.247352Z"}]}
{"channel":"book","type":"update","data":[{"symbol":"ETH/USDT","bids":[{"price":3802.93,"qty":1.07120000}],"asks":[],"checksum":1344919187,"timestamp":"2024-06-01T18:06:01.247791Z"}]}
{"channel":"book","type":"update","data":[{"symbol":"ETH/USDT","bids":[{"price":3803.00,"qty":1.46240000}],"asks":[],"checksum":1981543366,"timestamp":"2024-06-01T18:06:01.288639Z"}]}
{"channel":"book","type":"update","data":[{"symbol":"ETH/USDT","bids":[{"price":3803.01,"qty":0.25000000}],"asks":[],"checksum":123792566,"timestamp":"2024-06-01T18:06:01.293556Z"}]}
{"channel":"book","type":"update","data":[{"symbol":"ETH/USDT","bids":[{"price":3802.94,"qty":0.00000000},{"price":3802.22,"qty":1.31570984}],"asks":[],"checksum":789773118,"timestamp":"2024-06-01T18:06:01.293674Z"}]}
{"channel":"book","type":"update","data":[{"symbol":"ETH/USDT","bids":[{"price":3803.00,"qty":0.73120000}],"asks":[],"checksum":762697938,"timestamp":"2024-06-01T18:06:01.293683Z"}]}
{"channel":"book","type":"update","data":[{"symbol":"ETH/USDT","bids":[{"price":3803.00,"qty":1.46240000}],"asks":[],"checksum":789773118,"timestamp":"2024-06-01T18:06:01.297145Z"}]}
{"channel":"book","type":"update","data":[{"symbol":"ETH/USDT","bids":[{"price":3803.06,"qty":0.73120000}],"asks":[],"checksum":2211737270,"timestamp":"2024-06-01T18:06:01.297766Z"}]}
{"channel":"book","type":"update","data":[{"symbol":"ETH/USDT","bids":[{"price":3802.93,"qty":0.34000000}],"asks":[],"checksum":420947405,"timestamp":"2024-06-01T18:06:01.298693Z"}]}
{"channel":"book","type":"update","data":[{"symbol":"ETH/USDT","bids":[{"price":3802.36,"qty":0.26392111}],"asks":[],"checksum":1642117774,"timestamp":"2024-06-01T18:06:01.341323Z"}]}
{"channel":"book","type":"update","data":[{"symbol":"ETH/USDT","bids":[],"asks":[{"price":3803.55,"qty":0.00000000},{"price":3804.46,"qty":0.84627249}],"checksum":1156166197,"timestamp":"2024-06-01T18:06:01.372513Z"}]}
{"channel":"book","type":"update","data":[{"symbol":"ETH/USDT","bids":[{"price":3803.02,"qty":0.07894515}],"asks":[],"checksum":3465117037,"timestamp":"2024-06-01T18:06:01.404964Z"}]}
{"channel":"book","type":"update","data":[{"symbol":"ETH/USDT","bids":[{"price":3803.07,"qty":1.31570984}],"asks":[],"checksum":1078798348,"timestamp":"2024-06-01T18:06:01.407609Z"}]}
{"channel":"book","type":"update","data":[{"symbol":"ETH/USDT","bids":[{"price":3803.17,"qty":0.73120000}],"asks":[],"checksum":2765979898,"timestamp":"2024-06-01T18:06:01.411369Z"}]}
{"channel":"book","type":"update","data":[{"symbol":"ETH/USDT","bids":[{"price":3802.86,"qty":0.00000000},{"price":3802.36,"qty":0.26392111}],"asks":[],"checksum":2795194220,"timestamp":"2024-06-01T18:06:01.411455Z"}]}
{"channel":"book","type":"update","data":[{"symbol":"ETH/USDT","bids":[{"price":3803.00,"qty":0.73120000}],"asks":[],"checksum":1042758110,"timestamp":"2024-06-01T18:06:01.411796Z"}]}
{"channel":"book","type":"update","data":[{"symbol":"ETH/USDT","bids":[{"price":3803.02,"qty":0.00000000},{"price":3802.33,"qty":0.73120000}],"asks":[],"checksum":1080682863,"timestamp":"2024-06-01T18:06:01.412084Z"}]}
{"channel":"book","type":"update","data":[{"symbol":"ETH/USDT","bids":[{"price":3802.41,"qty":0.00000000},{"price":3802.23,"qty":0.84627249}],"asks":[],"checksum":2811432173,"timestamp":"2024-06-01T18:06:01.416573Z"}]}
{"channel":"book","type":"update","data":[{"symbol":"ETH/USDT","bids":[{"price":3802.76,"qty":2.63185955}],"asks":[],"checksum":1640300461,"timestamp":"2024-06-01T18:06:01.421707Z"}]}
{"channel":"book","type":"update","data":[{"symbol":"ETH/USDT","bids":[{"price":3802.36,"qty":0.06693358}],"asks":[],"checksum":2676466325,"timestamp":"2024-06-01T18:06:01.433666Z"}]}
{"channel":"book","type":"update","data":[{"symbol":"ETH/USDT","bids":[{"price":3802.45,"qty":0.19697168}],"asks":[],"checksum":1344610913,"timestamp":"2024-06-01T18:06:01.473898Z"}]}
{"channel":"book","type":"update","data":[{"symbol":"ETH/USDT","bids":[{"price":3803.01,"qty":0.00000000},{"price":3802.33,"qty":0.73120000}],"asks":[],"checksum":1285216882,"timestamp":"2024-06-01T18:06:01.586959Z"}]}
{"channel":"book","type":"update","data":[{"symbol":"ETH/USDT","bids":[{"price":3803.18,"qty":0.25000000}],"asks":[],"checksum":3522402458,"timestamp":"2024-06-01T18:06:01.587102Z"}]}
{"channel":"book","type":"update","data":[{"symbol":"ETH/USDT","bids":[{"price":3803.06,"qty":0.00000000},{"price":3802.33,"qty":0.73120000}],"asks":[],"checksum":874385538,"timestamp":"2024-06-01T18:06:01.590787Z"}]}
{"channel":"book","type":"update","data":[{"symbol":"ETH/USDT","bids":[{"price":3803.24,"qty":0.73120000}],"asks":[],"checksum":557869670,"timestamp":"2024-06-01T18:06:01.590872Z"}]}
{"channel":"book","type":"update","data":[{"symbol":"ETH/USDT","bids":[{"price":3802.43,"qty":5.00000000}],"asks":[],"checksum":2065135141,"timestamp":"2024-06-01T18:06:01.591578Z"}]}
{"channel":"book","type":"update","data":[{"symbol":"ETH/USDT","bids":[{"price":3802.92,"qty":0.00000000},{"price":3802.36,"qty":0.06693358}],"asks":[],"checksum":3288758740,"timestamp":"2024-06-01T18:06:01.591878Z"}]}
{"channel":"book","type":"update","data":[{"symbol":"ETH/USDT","bids":[],"asks":[{"price":3803.68,"qty":0.00000000},{"price":3804.48,"qty":15.78897508}],"checksum":2169192156,"timestamp":"2024-06-01T18:06:02.124614Z"}]}
{"channel":"book","type":"update","data":[{"symbol":"ETH/USDT","bids":[{"price":3803.24,"qty":0.00000000},{"price":3802.33,"qty":0.73120000}],"asks":[],"checksum":2643130102,"timestamp":"2024-06-01T18:06:02.128266Z"}]}
{"channel":"book","type":"update","data":[{"symbol":"ETH/USDT","bids":[],"asks":[{"price":3803.89,"qty":1.04284305}],"checksum":3442835512,"timestamp":"2024-06-01T18:06:02.129260Z"}]}
{"channel":"book","type":"update","data":[{"symbol":"ETH/USDT","bids":[],"asks":[{"price":3804.36,"qty":2.07605440}],"checksum":2051810320,"timestamp":"2024-06-01T18:06:02.129396Z"}]}
{"channel":"book","type":"update","data":[{"symbol":"ETH/USDT","bids":[{"price":3802.93,"qty":0.00000000},{"price":3802.25,"qty":19.19567925}],"asks":[],"checksum":726561623,"timestamp":"2024-06-01T18:06:02.131175Z"}]}
{"channel":"book","type":"update","data":[{"symbol":"ETH/USDT","bids":[{"price":3803.10,"qty":0.34000000}],"asks":[],"checksum":2647171325,"timestamp":"2024-06-01T18:06:02.131341Z"}]}
{"channel":"book","type":"update","data":[{"symbol":"ETH/USDT","bids":[{"price":3803.23,"qty":0.73120000}],"asks":[],"checksum":3254306703,"timestamp":"2024-06-01T18:06:02.132335Z"}]}
{"channel":"book","type":"update","data":[{"symbol":"ETH/USDT","bids":[],"asks":[{"price":3804.37,"qty":0.00000000},{"price":3804.45,"qty":55.18469034}],"checksum":3359520633,"timestamp":"2024-06-01T18:06:02.606825Z"}]}
{"channel":"book","type":"update","data":[{"symbol":"ETH/USDT","bids":[],"asks":[{"price":3804.44,"qty":0.00000000},{"price":3804.46,"qty":0.84627249}],"checksum":1502676366,"timestamp":"2024-06-01T18:06:02.606951Z"}]}
{"channel":"book","type":"update","data":[{"symbol":"ETH/USDT","bids":[],"asks":[{"price":3804.44,"qty":0.33353876}],"checksum":2881756739,"timestamp":"2024-06-01T18:06:02.608992Z"}]}
{"channel":"book","type":"update","data":[{"symbol":"ETH/USDT","bids":[{"price":3802.45,"qty":0.00000000},{"price":3802.33,"qty":0.73120000}],"asks":[],"checksum":272296862,"timestamp":"2024-06-01T18:06:02.633074Z"}]}
{"channel":"book","type":"update","data":[{"symbol":"ETH/USDT","bids":[{"price":3802.44,"qty":0.19695708}],"asks":[],"checksum":3169008799,"timestamp":"2024-06-01T18:06:02.673053Z"}]}
{"channel":"book","type":"update","data":[{"symbol":"ETH/USDT","bids":[{"price":3803.17,"qty":0.00000000},{"price":3802.33,"qty":0.73120000}],"asks":[],"checksum":2234153266,"timestamp":"2024-06-01T18:06:02.761050Z"}]}
{"channel":"book","type":"update","data":[{"symbol":"ETH/USDT","bids":[{"price":3803.23,"qty":0.00000000},{"price":3802.25,"qty":19.19567925}],"asks":[],"checksum":2494492198,"timestamp":"2024-06-01T18:06:02.761121Z"}]}
{"channel":"book","type":"update","data":[{"symbol":"ETH/USDT","bids":[],"asks":[{"price":3803.89,"qty":1.77404305}],"checksum":1958518015,"timestamp":"2024-06-01T18:06:02.761201Z"}]}
{"channel":"book","type":"update","data":[{"symbol":"ETH/USDT","bids":[],"asks":[{"price":3803.89,"qty":1.04284305}],"checksum":2494492198,"timestamp":"2024-06-01T18:06:02.763830Z"}]}
{"channel":"book","type":"update","data":[{"symbol":"ETH/USDT","bids":[{"price":3803.26,"qty":0.73120000}],"asks":[],"checksum":2615791315,"timestamp":"2024-06-01T18:06:02.765030Z"}]}
{"channel":"book","type":"update","data":[{"symbol":"ETH/USDT","bids":[],"asks":[{"price":3804.28,"qty":0.00000000},{"price":3804.46,"qty":0.84627249}],"checksum":2362881641,"timestamp":"2024-06-01T18:06:03.512877Z"}]}
{"channel":"book","type":"update","data":[{"symbol":"ETH/USDT","bids":[],"asks":[{"price":3804.28,"qty":0.73120000}],"checksum":2615791315,"timestamp":"2024-06-01T18:06:03.519499Z"}]}
{"channel":"book","type":"update","data":[{"symbol":"ETH/USDT","bids":[],"asks":[{"price":3803.90,"qty":0.00000000},{"price":3804.46,"qty":0.84627249}],"checksum":1849236697,"timestamp":"2024-06-01T18:06:03.524164Z"}]}
{"channel":"book","type":"update","data":[{"symbol":"ETH/USDT","bids":[],"asks":[{"price":3804.26,"qty":2.63082865}],"checksum":3809867029,"timestamp":"2024-06-01T18:06:03.529005Z"}]}
{"channel":"book","type":"update","data":[{"symbol":"ETH/USDT","bids":[{"price":3803.19,"qty":0.07894240}],"asks":[],"checksum":2752507978,"timestamp":"2024-06-01T18:06:03.530056Z"}]}
{"channel":"book","type":"update","data":[{"symbol":"ETH/USDT","bids":[{"price":3803.19,"qty":0.00000000},{"price":3802.33,"qty":0.73120000}],"asks":[],"checksum":3809867029,"timestamp":"2024-06-01T18:06:03.534468Z"}]}
{"channel":"book","type":"update","data":[{"symbol":"ETH/USDT","bids":[{"price":3803.27,"qty":0.07893820}],"asks":[],"checksum":2732512453,"timestamp":"2024-06-01T18:06:03.534650Z"}]}
{"channel":"book","type":"update","data":[{"symbol":"ETH/USDT","bids":[],"asks":[{"price":3804.28,"qty":0.00000000},{"price":3804.46,"qty":0.84627249}],"checksum":706227547,"timestamp":"2024-06-01T18:06:03.538420Z"}]}
{"channel":"book","type":"update","data":[{"symbol":"ETH/USDT","bids":[{"price":3803.39,"qty":0.73120000}],"asks":[],"checksum":3593341123,"timestamp":"2024-06-01T18:06:03.540448Z"}]}
{"channel":"book","type":"update","data":[{"symbol":"ETH/USDT","bids":[{"price":3803.39,"qty":1.46240000}],"asks":[],"checksum":425301257,"timestamp":"2024-06-01T18:06:03.544785Z"}]}
{"channel":"book","type":"update","data":[{"symbol":"ETH/USDT","bids":[{"price":3803.27,"qty":0.00000000},{"price":3802.36,"qty":0.06693358}],"asks":[],"checksum":2487086656,"timestamp":"2024-06-01T18:06:03.549746Z"}]}
{"channel":"book","type":"update","data":[{"symbol":"ETH/USDT","bids":[],"asks":[{"price":3804.28,"qty":0.73120000}],"checksum":3214838698,"timestamp":"2024-06-01T18:06:03.551940Z"}]}
{"channel":"book","type":"update","data":[{"symbol":"ETH/USDT","bids":[{"price":3803.39,"qty":0.73120000}],"asks":[],"checksum":1282738992,"timestamp":"2024-06-01T18:06:03.643817Z"}]}
{"channel":"book","type":"update","data":[{"symbol":"ETH/USDT","bids":[{"price":3803.26,"qty":0.00000000},{"price":3802.33,"qty":0.73120000}],"asks":[],"checksum":540290033,"timestamp":"2024-06-01T18:06:03.648064Z"}]}
{"channel":"book","type":"update","data":[{"symbol":"ETH/USDT","bids":[{"price":3803.19,"qty":0.07893846}],"asks":[],"checksum":3072295609,"timestamp":"2024-06-01T18:06:03.652480Z"}]}
{"channel":"book","type":"update","data":[{"symbol":"ETH/USDT","bids":[{"price":3803.39,"qty":0.00000000},{"price":3802.33,"qty":0.73120000}],"asks":[],"checksum":3305277142,"timestamp":"2024-06-01T18:06:03.698095Z"}]}
{"channel":"book","type":"update","data":[{"symbol":"ETH/USDT","bids":[{"price":3803.35,"qty":0.73120000}],"asks":[],"checksum":1801676480,"timestamp":"2024-06-01T18:06:03.701930Z"}]}
{"channel":"book","type":"update","data":[{"symbol":"ETH/USDT","bids":[{"price":3803.20,"qty":0.25000000}],"asks":[],"checksum":3835734449,"timestamp":"2024-06-01T18:06:03.705416Z"}]}
{"channel":"book","type":"update","data":[{"symbol":"ETH/USDT","bids":[{"price":3803.21,"qty":0.07893846}],"asks":[],"checksum":3724782409,"timestamp":"2024-06-01T18:06:03.709878Z"}]}
{"channel":"book","type":"update","data":[{"symbol":"ETH/USDT","bids":[{"price":3803.19,"qty":0.00000000},{"price":3802.43,"qty":5.00000000}],"asks":[],"checksum":2241261466,"timestamp":"2024-06-01T18:06:03.709917Z"}]}
{"channel":"book","type":"update","data":[{"symbol":"ETH/USDT","bids":[{"price":3802.44,"qty":0.00000000},{"price":3802.36,"qty":0.06693358}],"asks":[],"checksum":2694551892,"timestamp":"2024-06-01T18:06:03.838078Z"}]}
{"channel":"book","type":"update","data":[{"symbol":"ETH/USDT","bids":[{"price":3802.60,"qty":0.19693720}],"asks":[],"checksum":1174754051,"timestamp":"2024-06-01T18:06:03.878431Z"}]}
{"channel":"book","type":"update","data":[{"symbol":"ETH/USDT","bids":[{"price":3803.35,"qty":0.00000000},{"price":3802.36,"qty":0.06693358}],"asks":[],"checksum":1496321421,"timestamp":"2024-06-01T18:06:03.944526Z"}]}
{"channel":"book","type":"update","data":[{"symbol":"ETH/USDT","bids":[{"price":3803.31,"qty":0.73120000}],"asks":[],"checksum":3895016936,"timestamp":"2024-06-01T18:06:03.948626Z"}]}
{"channel":"book","type":"update","data":[{"symbol":"ETH/USDT","bids":[{"price":3803.20,"qty":0.00000000},{"price":3802.36,"qty":0.06693358}],"asks":[],"checksum":3568613421,"timestamp":"2024-06-01T18:06:03.950419Z"}]}
{"channel":"book","type":"update","data":[{"symbol":"ETH/USDT","bids":[{"price":3803.22,"qty":0.25000000}],"asks":[],"checksum":2744225966,"timestamp":"2024-06-01T18:06:03.950597Z"}]}
{"channel":"book","type":"update","data":[{"symbol":"ETH/USDT","bids":[{"price":3803.21,"qty":0.00000000},{"price":3802.36,"qty":0.06693358}],"asks":[],"checksum":2771864244,"timestamp":"2024-06-01T18:06:03.955288Z"}]}
{"channel":"book","type":"update","data":[{"symbol":"ETH/USDT","bids":[{"price":3803.23,"qty":0.07893846}],"asks":[],"checksum":3901317754,"timestamp":"2024-06-01T18:06:03.955360Z"}]}
{"channel":"book","type":"update","data":[{"symbol":"ETH/USDT","bids":[{"price":3803.22,"qty":0.00000000},{"price":3802.36,"qty":0.06693358}],"asks":[],"checksum":627232400,"timestamp":"2024-06-01T18:06:04.086495Z"}]}
{"channel":"book","type":"update","data":[{"symbol":"ETH/USDT","bids":[{"price":3802.60,"qty":0.00000000},{"price":3802.33,"qty":0.73120000}],"asks":[],"checksum":3101337126,"timestamp":"2024-06-01T18:06:04.497595Z"}]}
{"channel":"book","type":"update","data":[{"symbol":"ETH/USDT","bids":[{"price":3802.56,"qty":0.19693972}],"asks":[],"checksum":2261473593,"timestamp":"2024-06-01T18:06:04.538049Z"}]}
{"channel":"book","type":"update","data":[{"symbol":"ETH/USDT","bids":[],"asks":[{"price":3804.45,"qty":0.00000000},{"price":3804.67,"qty":0.73120000}],"checksum":4091804780,"timestamp":"2024-06-01T18:06:04.570979Z"}]}
{"channel":"book","type":"update","data":[{"symbol":"ETH/USDT","bids":[],"asks":[{"price":3804.36,"qty":0.00000000},{"price":3804.68,"qty":15.78864270}],"checksum":836709806,"timestamp":"2024-06-01T18:06:04.570997Z"}]}
{"channel":"book","type":"update","data":[{"symbol":"ETH/USDT","bids":[],"asks":[{"price":3803.89,"qty":0.00000000},{"price":3804.85,"qty":0.84627249}],"checksum":1943256818,"timestamp":"2024-06-01T18:06:04.572116Z"}]}
{"channel":"book","type":"update","data":[{"symbol":"ETH/USDT","bids":[],"asks":[{"price":3804.25,"qty":3.10926704}],"checksum":1991968749,"timestamp":"2024-06-01T18:06:04.578016Z"}]}
{"channel":"book","type":"update","data":[{"symbol":"ETH/USDT","bids":[],"asks":[{"price":3804.00,"qty":2.07605569}],"checksum":3854632721,"timestamp":"2024-06-01T18:06:04.578042Z"}]}
{"channel":"book","type":"update","data":[{"symbol":"ETH/USDT","bids":[],"asks":[{"price":3804.66,"qty":64.91872045}],"checksum":3329671573,"timestamp":"2024-06-01T18:06:04.578264Z"}]}
{"channel":"book","type":"update","data":[{"symbol":"ETH/USDT","bids":[{"price":3803.23,"qty":0.00000000},{"price":3802.33,"qty":0.73120000}],"asks":[],"checksum":3954881842,"timestamp":"2024-06-01T18:06:05.103332Z"}]}
{"channel":"book","type":"update","data":[{"symbol":"ETH/USDT","bids":[{"price":3803.19,"qty":0.07893844}],"asks":[],"checksum":3258821400,"timestamp":"2024-06-01T18:06:05.103506Z"}]}
{"channel":"book","type":"update","data":[{"symbol":"ETH/USDT","bids":[{"price":3802.56,"qty":0.00000000},{"price":3802.33,"qty":0.73120000}],"asks":[],"checksum":4230763527,"timestamp":"2024-06-01T18:06:05.188662Z"}]}
{"channel":"book","type":"update","data":[{"symbol":"ETH/USDT","bids":[{"price":3802.55,"qty":0.19692330}],"asks":[],"checksum":888813712,"timestamp":"2024-06-01T18:06:05.228934Z"}]}
{"channel":"book","type":"update","data":[{"symbol":"ETH/USDT","bids":[{"price":3803.31,"qty":0.00000000},{"price":3802.33,"qty":0.73120000}],"asks":[],"checksum":3997806741,"timestamp":"2024-06-01T18:06:05.302203Z"}]}
{"channel":"book","type":"update","data":[{"symbol":"ETH/USDT","bids":[{"price":3803.29,"qty":0.73120000}],"asks":[],"checksum":2775426059,"timestamp":"2024-06-01T18:06:05.305618Z"}]}
{"channel":"book","type":"update","data":[{"symbol":"ETH/USDT","bids":[{"price":3803.20,"qty":0.25000000}],"asks":[],"checksum":32632613,"timestamp":"2024-06-01T18:06:05.307639Z"}]}
{"channel":"book","type":"update","data":[{"symbol":"ETH/USDT","bids":[{"price":3803.19,"qty":0.00000000},{"price":3802.36,"qty":0.06693358}],"asks":[],"checksum":4246001881,"timestamp":"2024-06-01T18:06:05.312196Z"}]}
{"channel":"book","type":"update","data":[{"symbol":"ETH/USDT","bids":[{"price":3803.21,"qty":0.07893844}],"asks":[],"checksum":3579293189,"timestamp":"2024-06-01T18:06:05.312601Z"}]}
{"channel":"book","type":"update","data":[{"symbol":"ETH/USDT","bids":[{"price":3803.20,"qty":0.00000000},{"price":3802.36,"qty":0.06693358}],"asks":[],"checksum":3604964537,"timestamp":"2024-06-01T18:06:05.587678Z"}]}
{"channel":"book","type":"update","data":[{"symbol":"ETH/USDT","bids":[{"price":3803.30,"qty":0.25000000}],"asks":[],"checksum":4283181005,"timestamp":"2024-06-01T18:06:05.587795Z"}]}
{"channel":"book","type":"update","data":[{"symbol":"ETH/USDT","bids":[{"price":3803.18,"qty":0.00000000},{"price":3802.36,"qty":0.06693358}],"asks":[],"checksum":1037224552,"timestamp":"2024-06-01T18:06:05.592120Z"}]}
{"channel":"book","type":"update","data":[{"symbol":"ETH/USDT","bids":[{"price":3802.43,"qty":0.00000000},{"price":3802.33,"qty":0.73120000}],"asks":[],"checksum":1079412657,"timestamp":"2024-06-01T18:06:05.592790Z"}]}
{"channel":"book","type":"update","data":[{"symbol":"ETH/USDT","bids":[{"price":3802.53,"qty":5.00000000}],"asks":[],"checksum":3170348879,"timestamp":"2024-06-01T18:06:05.706395Z"}]}
{"channel":"book","type":"update","data":[{"symbol":"ETH/USDT","bids":[{"price":3803.29,"qty":0.00000000},{"price":3802.33,"qty":0.73120000}],"asks":[],"checksum":4180931379,"timestamp":"2024-06-01T18:06:05.941575Z"}]}
{"channel":"book","type":"update","data":[{"symbol":"ETH/USDT","bids":[{"price":3803.31,"qty":0.73120000}],"asks":[],"checksum":3817680265,"timestamp":"2024-06-01T18:06:06.062763Z"}]}
{"channel":"book","type":"update","data":[{"symbol":"ETH/USDT","bids":[{"price":3803.11,"qty":0.07893848}],"asks":[],"checksum":2296684800,"timestamp":"2024-06-01T18:06:06.364818Z"}]}
{"channel":"book","type":"update","data":[{"symbol":"ETH/USDT","bids":[{"price":3803.21,"qty":0.00000000},{"price":3802.36,"qty":0.06693358}],"asks":[],"checksum":2361124363,"timestamp":"2024-06-01T18:06:06.364846Z"}]}
{"channel":"book","type":"update","data":[{"symbol":"ETH/USDT","bids":[{"price":3802.53,"qty":0.00000000},{"price":3802.33,"qty":0.73120000}],"asks":[],"checksum":3118475870,"timestamp":"2024-06-01T18:06:06.369830Z"}]}
{"channel":"book","type":"update","data":[{"symbol":"ETH/USDT","bids":[{"price":3802.55,"qty":0.00000000},{"price":3802.26,"qty":1.64660029}],"asks":[],"checksum":174835633,"timestamp":"2024-06-01T18:06:06.390624Z"}]}
{"channel":"book","type":"update","data":[{"symbol":"ETH/USDT","bids":[{"price":3802.58,"qty":0.19687360}],"asks":[],"checksum":2494292664,"timestamp":"2024-06-01T18:06:06.430699Z"}]}
{"channel":"book","type":"update","data":[{"symbol":"ETH/USDT","bids":[{"price":3803.31,"qty":0.00000000},{"price":3802.26,"qty":1.64660029}],"asks":[],"checksum":412705792,"timestamp":"2024-06-01T18:06:06.563758Z"}]}
{"channel":"book","type":"update","data":[{"symbol":"ETH/USDT","bids":[{"price":3803.30,"qty":0.00000000},{"price":3802.25,"qty":21.31167925}],"asks":[],"checksum":2541523144,"timestamp":"2024-06-01T18:06:06.569048Z"}]}
{"channel":"book","type":"update","data":[{"symbol":"ETH/USDT","bids":[{"price":3803.12,"qty":0.25000000}],"asks":[],"checksum":3702882465,"timestamp":"2024-06-01T18:06:06.569070Z"}]}
{"channel":"book","type":"update","data":[{"symbol":"ETH/USDT","bids":[],"asks":[{"price":3804.00,"qty":2.80725569}],"checksum":745178082,"timestamp":"2024-06-01T18:06:06.571010Z"}]}
{"channel":"book","type":"update","data":[{"symbol":"ETH/USDT","bids":[{"price":3803.25,"qty":0.73120000}],"asks":[],"checksum":3999323684,"timestamp":"2024-06-01T18:06:06.573034Z"}]}
{"channel":"book","type":"update","data":[{"symbol":"ETH/USDT","bids":[{"price":3803.11,"qty":0.00000000},{"price":3802.26,"qty":1.64660029}],"asks":[],"checksum":3591265619,"timestamp":"2024-06-01T18:06:06.574146Z"}]}
{"channel":"book","type":"update","data":[{"symbol":"ETH/USDT","bids":[{"price":3803.13,"qty":0.07893848}],"asks":[],"checksum":3294380201,"timestamp":"2024-06-01T18:06:06.574314Z"}]}
{"channel":"book","type":"update","data":[{"symbol":"ETH/USDT","bids":[{"price":3803.26,"qty":0.25000000}],"asks":[],"checksum":3731699154,"timestamp":"2024-06-01T18:06:06.585920Z"}]}
{"channel":"book","type":"update","data":[{"symbol":"ETH/USDT","bids":[{"price":3803.25,"qty":0.00000000},{"price":3802.33,"qty":0.73120000}],"asks":[],"checksum":1408536196,"timestamp":"2024-06-01T18:06:06.596562Z"}]}
{"channel":"book","type":"update","data":[{"symbol":"ETH/USDT","bids":[],"asks":[{"price":3803.97,"qty":0.73120000}],"checksum":4095830668,"timestamp":"2024-06-01T18:06:06.597030Z"}]}
{"channel":"book","type":"update","data":[{"symbol":"ETH/USDT","bids":[{"price":3803.12,"qty":0.00000000},{"price":3802.26,"qty":1.64660029}],"asks":[],"checksum":612721726,"timestamp":"2024-06-01T18:06:06.601322Z"}]}
{"channel":"book","type":"update","data":[{"symbol":"ETH/USDT","bids":[],"asks":[{"price":3803.97,"qty":0.00000000},{"price":3804.66,"qty":64.91872045}],"checksum":720976360,"timestamp":"2024-06-01T18:06:06.602876Z"}]}
{"channel":"book","type":"update","data":[{"symbol":"ETH/USDT","bids":[],"asks":[{"price":3803.99,"qty":0.73120000}],"checksum":3812852195,"timestamp":"2024-06-01T18:06:06.666394Z"}]}
{"channel":"book","type":"update","data":[{"symbol":"ETH/USDT","bids":[],"asks":[{"price":3803.99,"qty":0.00000000},{"price":3804.66,"qty":64.91872045}],"checksum":720976360,"timestamp":"2024-06-01T18:06:06.742039Z"}]}
{"channel":"book","type":"update","data":[{"symbol":"ETH/USDT","bids":[],"asks":[{"price":3804.00,"qty":2.07605569}],"checksum":3659938475,"timestamp":"2024-06-01T18:06:06.744021Z"}]}
{"channel":"book","type":"update","data":[{"symbol":"ETH/USDT","bids":[{"price":3803.26,"qty":0.98120000}],"asks":[],"checksum":796784498,"timestamp":"2024-06-01T18:06:06.744578Z"}]}
{"channel":"book","type":"update","data":[{"symbol":"ETH/USDT","bids":[{"price":3803.27,"qty":0.73120000}],"asks":[],"checksum":2531066605,"timestamp":"2024-06-01T18:06:06.747889Z"}]}
{"channel":"book","type":"update","data":[{"symbol":"ETH/USDT","bids":[{"price":3803.13,"qty":0.00000000},{"price":3802.26,"qty":1.64660029}],"asks":[],"checksum":469875609,"timestamp":"2024-06-01T18:06:06.752140Z"}]}
{"channel":"book","type":"update","data":[{"symbol":"ETH/USDT","bids":[],"asks":[{"price":3804.25,"qty":0.00000000},{"price":3804.67,"qty":0.73120000}],"checksum":4050873762,"timestamp":"2024-06-01T18:06:06.915855Z"}]}
{"channel":"book","type":"update","data":[{"symbol":"ETH/USDT","bids":[],"asks":[{"price":3804.66,"qty":0.00000000},{"price":3804.68,"qty":15.78864270}],"checksum":1355508460,"timestamp":"2024-06-01T18:06:06.915870Z"}]}
{"channel":"book","type":"update","data":[{"symbol":"ETH/USDT","bids":[],"asks":[{"price":3804.00,"qty":0.00000000},{"price":3804.85,"qty":0.84627249}],"checksum":3479366173,"timestamp":"2024-06-01T18:06:06.915995Z"}]}
{"channel":"book","type":"update","data":[{"symbol":"ETH/USDT","bids":[{"price":3803.28,"qty":0.25000000}],"asks":[],"checksum":384914117,"timestamp":"2024-06-01T18:06:06.921261Z"}]}
{"channel":"book","type":"update","data":[{"symbol":"ETH/USDT","bids":[],"asks":[{"price":3804.66,"qty":49.49728135}],"checksum":2523214003,"timestamp":"2024-06-01T18:06:06.921310Z"}]}
{"channel":"book","type":"update","data":[{"symbol":"ETH/USDT","bids":[],"asks":[{"price":3803.99,"qty":2.59266137}],"checksum":1045283287,"timestamp":"2024-06-01T18:06:06.922657Z"}]}
{"channel":"book","type":"update","data":[{"symbol":"ETH/USDT","bids":[{"price":3803.28,"qty":0.98120000}],"asks":[],"checksum":3407219726,"timestamp":"2024-06-01T18:06:06.925068Z"}]}
{"channel":"book","type":"update","data":[{"symbol":"ETH/USDT","bids":[{"price":3803.30,"qty":0.73120000}],"asks":[],"checksum":938399912,"timestamp":"2024-06-01T18:06:06.925463Z"}]}
{"channel":"book","type":"update","data":[{"symbol":"ETH/USDT","bids":[{"price":3803.27,"qty":0.00000000},{"price":3802.33,"qty":0.73120000}],"asks":[],"checksum":2960100172,"timestamp":"2024-06-01T18:06:06.925829Z"}]}
{"channel":"book","type":"update","data":[{"symbol":"ETH/USDT","bids":[{"price":3803.26,"qty":0.25000000}],"asks":[],"checksum":3129029990,"timestamp":"2024-06-01T18:06:06.926227Z"}]}
{"channel":"book","type":"update","data":[{"symbol":"ETH/USDT","bids":[{"price":3803.28,"qty":0.25000000}],"asks":[],"checksum":3140279263,"timestamp":"2024-06-01T18:06:06.927986Z"}]}
{"channel":"book","type":"update","data":[{"symbol":"ETH/USDT","bids":[{"price":3802.58,"qty":0.00000000},{"price":3802.26,"qty":1.64660029}],"asks":[],"checksum":3650270323,"timestamp":"2024-06-01T18:06:07.046003Z"}]}
{"channel":"book","type":"update","data":[{"symbol":"ETH/USDT","bids":[{"price":3803.28,"qty":0.00000000},{"price":3802.25,"qty":21.31167925}],"asks":[],"checksum":2803381912,"timestamp":"2024-06-01T18:06:07.085911Z"}]}
{"channel":"book","type":"update","data":[{"symbol":"ETH/USDT","bids":[{"price":3803.31,"qty":0.25000000}],"asks":[],"checksum":484615927,"timestamp":"2024-06-01T18:06:07.085921Z"}]}
{"channel":"book","type":"update","data":[{"symbol":"ETH/USDT","bids":[{"price":3802.56,"qty":0.19687137}],"asks":[],"checksum":2160339203,"timestamp":"2024-06-01T18:06:07.086225Z"}]}
{"channel":"book","type":"update","data":[{"symbol":"ETH/USDT","bids":[{"price":3803.26,"qty":0.00000000},{"price":3802.26,"qty":1.64660029}],"asks":[],"checksum":2495233351,"timestamp":"2024-06-01T18:06:07.090650Z"}]}
{"channel":"book","type":"update","data":[{"symbol":"ETH/USDT","bids":[{"price":3803.11,"qty":0.07893848}],"asks":[],"checksum":1445405236,"timestamp":"2024-06-01T18:06:07.095812Z"}]}
{"channel":"book","type":"update","data":[{"symbol":"ETH/USDT","bids":[{"price":3803.35,"qty":0.73120000}],"asks":[],"checksum":3191548412,"timestamp":"2024-06-01T18:06:07.144702Z"}]}
{"channel":"book","type":"update","data":[{"symbol":"ETH/USDT","bids":[{"price":3803.11,"qty":0.00000000},{"price":3802.33,"qty":0.73120000}],"asks":[],"checksum":1547110752,"timestamp":"2024-06-01T18:06:07.149242Z"}]}
{"channel":"book","type":"update","data":[{"symbol":"ETH/USDT","bids":[],"asks":[{"price":3804.44,"qty":0.00000000},{"price":3804.68,"qty":15.78864270}],"checksum":1831464063,"timestamp":"2024-06-01T18:06:07.163111Z"}]}
{"channel":"book","type":"update","data":[{"symbol":"ETH/USDT","bids":[],"asks":[{"price":3804.65,"qty":0.53505505}],"checksum":3628822126,"timestamp":"2024-06-01T18:06:07.164526Z"}]}
{"channel":"book","type":"update","data":[{"symbol":"ETH/USDT","bids":[{"price":3803.35,"qty":0.00000000},{"price":3802.26,"qty":1.64660029}],"asks":[],"checksum":1938189351,"timestamp":"2024-06-01T18:06:07.216928Z"}]}
{"channel":"book","type":"update","data":[{"symbol":"ETH/USDT","bids":[{"price":3802.26,"qty":0.29454964}],"asks":[],"checksum":1888889077,"timestamp":"2024-06-01T18:06:07.296500Z"}]}
{"channel":"book","type":"update","data":[{"symbol":"ETH/USDT","bids":[{"price":3802.26,"qty":25.59408166}],"asks":[],"checksum":1564186064,"timestamp":"2024-06-01T18:06:07.298762Z"}]}
{"channel":"book","type":"update","data":[{"symbol":"ETH/USDT","bids":[{"price":3803.31,"qty":0.00000000},{"price":3802.25,"qty":21.31167925}],"asks":[],"checksum":601479783,"timestamp":"2024-06-01T18:06:07.309576Z"}]}
{"channel":"book","type":"update","data":[{"symbol":"ETH/USDT","bids":[{"price":3803.11,"qty":0.07893847}],"asks":[],"checksum":1600210377,"timestamp":"2024-06-01T18:06:07.314388Z"}]}
{"channel":"book","type":"update","data":[{"symbol":"ETH/USDT","bids":[{"price":3803.30,"qty":0.00000000},{"price":3802.25,"qty":21.31167925}],"asks":[],"checksum":2999065383,"timestamp":"2024-06-01T18:06:07.403114Z"}]}
{"channel":"book","type":"update","data":[{"symbol":"ETH/USDT","bids":[{"price":3803.25,"qty":0.73120000}],"asks":[],"checksum":2714236143,"timestamp":"2024-06-01T18:06:07.409715Z"}]}
{"channel":"book","type":"update","data":[{"symbol":"ETH/USDT","bids":[{"price":3803.26,"qty":0.25000000}],"asks":[],"checksum":4280316416,"timestamp":"2024-06-01T18:06:07.586394Z"}]}
{"channel":"book","type":"update","data":[{"symbol":"ETH/USDT","bids":[{"price":3802.53,"qty":5.00000000}],"asks":[],"checksum":3037856,"timestamp":"2024-06-01T18:06:07.591009Z"}]}
{"channel":"book","type":"update","data":[{"symbol":"ETH/USDT","bids":[{"price":3803.26,"qty":0.98120000}],"asks":[],"checksum":4118124409,"timestamp":"2024-06-01T18:06:07.596699Z"}]}
{"channel":"book","type":"update","data":[{"symbol":"ETH/USDT","bids":[{"price":3803.25,"qty":0.00000000},{"price":3802.33,"qty":0.73120000}],"asks":[],"checksum":3302474742,"timestamp":"2024-06-01T18:06:07.596899Z"}]}
{"channel":"book","type":"update","data":[{"symbol":"ETH/USDT","bids":[{"price":3803.27,"qty":0.73120000}],"asks":[],"checksum":1773967767,"timestamp":"2024-06-01T18:06:07.600274Z"}]}
{"channel":"book","type":"update","data":[{"symbol":"ETH/USDT","bids":[{"price":3803.11,"qty":0.00000000},{"price":3802.33,"qty":0.73120000}],"asks":[],"checksum":3219933865,"timestamp":"2024-06-01T18:06:07.601556Z"}]}
{"channel":"book","type":"update","data":[{"symbol":"ETH/USDT","bids":[{"price":3802.56,"qty":0.00000000},{"price":3802.26,"qty":25.59408166}],"asks":[],"checksum":1949997533,"timestamp":"2024-06-01T18:06:07.627804Z"}]}
{"channel":"book","type":"update","data":[{"symbol":"ETH/USDT","bids":[{"price":3802.54,"qty":0.19687324}],"asks":[],"checksum":2409750136,"timestamp":"2024-06-01T18:06:07.667995Z"}]}
{"channel":"book","type":"update","data":[{"symbol":"ETH/USDT","bids":[{"price":3803.28,"qty":0.25000000}],"asks":[],"checksum":3950785588,"timestamp":"2024-06-01T18:06:08.087946Z"}]}
{"channel":"book","type":"update","data":[{"symbol":"ETH/USDT","bids":[{"price":3803.26,"qty":0.25000000}],"asks":[],"checksum":818746204,"timestamp":"2024-06-01T18:06:08.091361Z"}]}
{"channel":"book","type":"update","data":[{"symbol":"ETH/USDT","bids":[{"price":3803.29,"qty":0.73120000}],"asks":[],"checksum":2215206282,"timestamp":"2024-06-01T18:06:08.091948Z"}]}
{"channel":"book","type":"update","data":[{"symbol":"ETH/USDT","bids":[{"price":3803.26,"qty":0.00000000},{"price":3802.36,"qty":0.06693358}],"asks":[],"checksum":3354548699,"timestamp":"2024-06-01T18:06:08.092485Z"}]}
{"channel":"book","type":"update","data":[{"symbol":"ETH/USDT","bids":[{"price":3803.30,"qty":0.25000000}],"asks":[],"checksum":3732141231,"timestamp":"2024-06-01T18:06:08.587721Z"}]}
{"channel":"book","type":"update","data":[{"symbol":"ETH/USDT","bids":[{"price":3803.28,"qty":0.00000000},{"price":3802.36,"qty":0.06693358}],"asks":[],"checksum":536284358,"timestamp":"2024-06-01T18:06:08.592431Z"}]}
{"channel":"book","type":"update","data":[{"symbol":"ETH/USDT","bids":[{"price":3803.27,"qty":0.00000000},{"price":3802.33,"qty":0.73120000}],"asks":[],"checksum":3417730781,"timestamp":"2024-06-01T18:06:08.600138Z"}]}
{"channel":"book","type":"update","data":[{"symbol":"ETH/USDT","bids":[{"price":3803.30,"qty":0.98120000}],"asks":[],"checksum":877420384,"timestamp":"2024-06-01T18:06:08.603531Z"}]}
{"channel":"book","type":"update","data":[{"symbol":"ETH/USDT","bids":[{"price":3803.11,"qty":0.07893689}],"asks":[],"checksum":2572069727,"timestamp":"2024-06-01T18:06:08.604585Z"}]}
{"channel":"book","type":"update","data":[{"symbol":"ETH/USDT","bids":[{"price":3803.29,"qty":0.00000000},{"price":3802.33,"qty":0.73120000}],"asks":[],"checksum":3484183056,"timestamp":"2024-06-01T18:06:08.604673Z"}]}
{"channel":"book","type":"update","data":[{"symbol":"ETH/USDT","bids":[{"price":3803.31,"qty":0.73120000}],"asks":[],"checksum":851577593,"timestamp":"2024-06-01T18:06:08.607609Z"}]}
{"channel":"book","type":"update","data":[{"symbol":"ETH/USDT","bids":[{"price":3803.11,"qty":0.00000000},{"price":3802.33,"qty":0.73120000}],"asks":[],"checksum":189977884,"timestamp":"2024-06-01T18:06:08.608498Z"}]}
{"channel":"book","type":"update","data":[{"symbol":"ETH/USDT","bids":[{"price":3803.31,"qty":0.00000000},{"price":3802.27,"qty":0.29732343}],"asks":[],"checksum":981554908,"timestamp":"2024-06-01T18:06:08.722635Z"}]}
{"channel":"book","type":"update","data":[{"symbol":"ETH/USDT","bids":[{"price":3803.11,"qty":0.07893689}],"asks":[],"checksum":3484183056,"timestamp":"2024-06-01T18:06:08.727235Z"}]}
{"channel":"book","type":"update","data":[{"symbol":"ETH/USDT","bids":[{"price":3803.31,"qty":0.73120000}],"asks":[],"checksum":851577593,"timestamp":"2024-06-01T18:06:08.737015Z"}]}
{"channel":"book","type":"update","data":[{"symbol":"ETH/USDT","bids":[{"price":3803.40,"qty":0.73120000}],"asks":[],"checksum":1166746729,"timestamp":"2024-06-01T18:06:08.739182Z"}]}
{"channel":"book","type":"update","data":[{"symbol":"ETH/USDT","bids":[],"asks":[{"price":3804.28,"qty":0.00000000},{"price":3804.85,"qty":0.84627249}],"checksum":2823652353,"timestamp":"2024-06-01T18:06:08.740238Z"}]}
{"channel":"book","type":"update","data":[{"symbol":"ETH/USDT","bids":[{"price":3803.11,"qty":0.00000000},{"price":3802.36,"qty":0.06693358}],"asks":[],"checksum":3458188965,"timestamp":"2024-06-01T18:06:08.741012Z"}]}
{"channel":"book","type":"update","data":[{"symbol":"ETH/USDT","bids":[{"price":3803.40,"qty":1.46240000}],"asks":[],"checksum":2916659900,"timestamp":"2024-06-01T18:06:08.743368Z"}]}
{"channel":"book","type":"update","data":[{"symbol":"ETH/USDT","bids":[{"price":3803.31,"qty":0.00000000},{"price":3802.33,"qty":0.73120000}],"asks":[],"checksum":4178887409,"timestamp":"2024-06-01T18:06:08.743522Z"}]}
{"channel":"book","type":"update","data":[{"symbol":"ETH/USDT","bids":[{"price":3803.30,"qty":0.25000000}],"asks":[],"checksum":1269326903,"timestamp":"2024-06-01T18:06:08.743601Z"}]}
{"channel":"book","type":"update","data":[{"symbol":"ETH/USDT","bids":[{"price":3803.40,"qty":0.73120000}],"asks":[],"checksum":678367278,"timestamp":"2024-06-01T18:06:08.743839Z"}]}
{"channel":"book","type":"update","data":[{"symbol":"ETH/USDT","bids":[{"price":3803.41,"qty":0.73120000}],"asks":[],"checksum":2231948526,"timestamp":"2024-06-01T18:06:08.747122Z"}]}
{"channel":"book","type":"update","data":[{"symbol":"ETH/USDT","bids":[{"price":3803.48,"qty":0.73120000}],"asks":[],"checksum":2628759791,"timestamp":"2024-06-01T18:06:08.747617Z"}]}
{"channel":"book","type":"update","data":[{"symbol":"ETH/USDT","bids":[{"price":3803.40,"qty":0.00000000},{"price":3802.36,"qty":0.06693358}],"asks":[],"checksum":99015152,"timestamp":"2024-06-01T18:06:08.748012Z"}]}
{"channel":"book","type":"update","data":[{"symbol":"ETH/USDT","bids":[{"price":3803.41,"qty":0.00000000},{"price":3802.33,"qty":0.73120000}],"asks":[],"checksum":2940652473,"timestamp":"2024-06-01T18:06:08.750459Z"}]}
{"channel":"book","type":"update","data":[{"symbol":"ETH/USDT","bids":[{"price":3803.48,"qty":0.00000000},{"price":3802.27,"qty":0.29732343}],"asks":[],"checksum":683525897,"timestamp":"2024-06-01T18:06:08.795039Z"}]}
{"channel":"book","type":"update","data":[{"symbol":"ETH/USDT","bids":[{"price":3803.41,"qty":0.73120000}],"asks":[],"checksum":2558576932,"timestamp":"2024-06-01T18:06:08.798547Z"}]}
{"channel":"book","type":"update","data":[{"symbol":"ETH/USDT","bids":[{"price":3803.41,"qty":1.46240000}],"asks":[],"checksum":2882364144,"timestamp":"2024-06-01T18:06:08.806109Z"}]}
{"channel":"book","type":"update","data":[{"symbol":"ETH/USDT","bids":[{"price":3803.41,"qty":0.73120000}],"asks":[],"checksum":2558576932,"timestamp":"2024-06-01T18:06:08.817909Z"}]}
{"channel":"book","type":"update","data":[{"symbol":"ETH/USDT","bids":[{"price":3803.41,"qty":0.00000000},{"price":3802.27,"qty":0.29732343}],"asks":[],"checksum":683525897,"timestamp":"2024-06-01T18:06:08.818153Z"}]}
{"channel":"book","type":"update","data":[{"symbol":"ETH/USDT","bids":[{"price":3803.36,"qty":0.73120000}],"asks":[],"checksum":4031107078,"timestamp":"2024-06-01T18:06:08.821599Z"}]}
{"channel":"book","type":"update","data":[{"symbol":"ETH/USDT","bids":[{"price":3803.11,"qty":0.07893689}],"asks":[],"checksum":4052448678,"timestamp":"2024-06-01T18:06:08.831234Z"}]}
{"channel":"book","type":"update","data":[{"symbol":"ETH/USDT","bids":[{"price":3803.36,"qty":0.00000000},{"price":3802.33,"qty":0.73120000}],"asks":[],"checksum":1154805577,"timestamp":"2024-06-01T18:06:08.864399Z"}]}
{"channel":"book","type":"update","data":[{"symbol":"ETH/USDT","bids":[{"price":3803.32,"qty":0.73120000}],"asks":[],"checksum":210752590,"timestamp":"2024-06-01T18:06:08.868046Z"}]}
{"channel":"book","type":"update","data":[{"symbol":"ETH/USDT","bids":[{"price":3802.54,"qty":0.00000000},{"price":3802.33,"qty":0.73120000}],"asks":[],"checksum":2510829993,"timestamp":"2024-06-01T18:06:08.903688Z"}]}
{"channel":"book","type":"update","data":[{"symbol":"ETH/USDT","bids":[{"price":3803.32,"qty":0.00000000},{"price":3802.27,"qty":0.29732343}],"asks":[],"checksum":3915121674,"timestamp":"2024-06-01T18:06:08.904424Z"}]}
{"channel":"book","type":"update","data":[{"symbol":"ETH/USDT","bids":[{"price":3803.31,"qty":0.73120000}],"asks":[],"checksum":3563798823,"timestamp":"2024-06-01T18:06:08.907877Z"}]}
{"channel":"book","type":"update","data":[{"symbol":"ETH/USDT","bids":[{"price":3802.62,"qty":0.19686344}],"asks":[],"checksum":3439238653,"timestamp":"2024-06-01T18:06:08.944046Z"}]}
{"channel":"book","type":"update","data":[{"symbol":"ETH/USDT","bids":[],"asks":[{"price":3804.66,"qty":0.00000000},{"price":3804.89,"qty":0.06693358}],"checksum":3356164288,"timestamp":"2024-06-01T18:06:09.365679Z"}]}
{"channel":"book","type":"update","data":[{"symbol":"ETH/USDT","bids":[],"asks":[{"price":3803.99,"qty":0.00000000},{"price":3805.01,"qty":2.79300000}],"checksum":2357599711,"timestamp":"2024-06-01T18:06:09.365774Z"}]}
{"channel":"book","type":"update","data":[{"symbol":"ETH/USDT","bids":[],"asks":[{"price":3804.00,"qty":1.55945001}],"checksum":1591961382,"timestamp":"2024-06-01T18:06:09.370991Z"}]}
{"channel":"book","type":"update","data":[{"symbol":"ETH/USDT","bids":[{"price":3802.62,"qty":0.00000000},{"price":3802.33,"qty":0.73120000}],"asks":[],"checksum":1182186492,"timestamp":"2024-06-01T18:06:09.483861Z"}]}
{"channel":"book","type":"update","data":[{"symbol":"ETH/USDT","bids":[{"price":3802.56,"qty":0.19686720}],"asks":[],"checksum":2565585499,"timestamp":"2024-06-01T18:06:09.524033Z"}]}
{"channel":"book","type":"update","data":[{"symbol":"ETH/USDT","bids":[],"asks":[{"price":3804.01,"qty":0.00000000},{"price":3805.00,"qty":44.43772114}],"checksum":3298381047,"timestamp":"2024-06-01T18:06:09.550218Z"}]}
{"channel":"book","type":"update","data":[{"symbol":"ETH/USDT","bids":[],"asks":[{"price":3804.39,"qty":0.00000000},{"price":3805.01,"qty":2.79300000}],"checksum":3769472184,"timestamp":"2024-06-01T18:06:09.551886Z"}]}
{"channel":"book","type":"update","data":[{"symbol":"ETH/USDT","bids":[{"price":3803.31,"qty":2.04681290}],"asks":[],"checksum":1502745612,"timestamp":"2024-06-01T18:06:09.559747Z"}]}
{"channel":"book","type":"update","data":[{"symbol":"ETH/USDT","bids":[{"price":3803.11,"qty":0.00000000},{"price":3802.33,"qty":0.73120000}],"asks":[],"checksum":2756015175,"timestamp":"2024-06-01T18:06:09.559786Z"}]}
{"channel":"book","type":"update","data":[{"symbol":"ETH/USDT","bids":[],"asks":[{"price":3804.11,"qty":0.00000000},{"price":3805.15,"qty":5.26000000}],"checksum":272930110,"timestamp":"2024-06-01T18:06:09.562392Z"}]}
{"channel":"book","type":"update","data":[{"symbol":"ETH/USDT","bids":[{"price":3803.41,"qty":0.73120000}],"asks":[],"checksum":1842043545,"timestamp":"2024-06-01T18:06:09.563510Z"}]}
{"channel":"book","type":"update","data":[{"symbol":"ETH/USDT","bids":[{"price":3803.07,"qty":0.00000000},{"price":3802.33,"qty":0.73120000}],"asks":[],"checksum":2162818811,"timestamp":"2024-06-01T18:06:09.563598Z"}]}
{"channel":"book","type":"update","data":[{"symbol":"ETH/USDT","bids":[{"price":3803.41,"qty":1.46240000}],"asks":[],"checksum":3006486925,"timestamp":"2024-06-01T18:06:09.567923Z"}]}
{"channel":"book","type":"update","data":[{"symbol":"ETH/USDT","bids":[{"price":3803.41,"qty":0.73120000}],"asks":[],"checksum":2162818811,"timestamp":"2024-06-01T18:06:09.568477Z"}]}
{"channel":"book","type":"update","data":[{"symbol":"ETH/USDT","bids":[{"price":3803.47,"qty":0.73120000}],"asks":[],"checksum":1749340791,"timestamp":"2024-06-01T18:06:09.571802Z"}]}
{"channel":"book","type":"update","data":[{"symbol":"ETH/USDT","bids":[{"price":3803.31,"qty":1.31561290}],"asks":[],"checksum":2886542250,"timestamp":"2024-06-01T18:06:09.572140Z"}]}
{"channel":"book","type":"update","data":[{"symbol":"ETH/USDT","bids":[{"price":3803.41,"qty":0.00000000},{"price":3802.33,"qty":0.73120000}],"asks":[],"checksum":4233831140,"timestamp":"2024-06-01T18:06:09.572288Z"}]}
{"channel":"book","type":"update","data":[{"symbol":"ETH/USDT","bids":[{"price":3803.41,"qty":0.73120000}],"asks":[],"checksum":2886542250,"timestamp":"2024-06-01T18:06:09.572882Z"}]}
{"channel":"book","type":"update","data":[{"symbol":"ETH/USDT","bids":[{"price":3803.41,"qty":0.00000000},{"price":3802.33,"qty":0.73120000}],"asks":[],"checksum":4233831140,"timestamp":"2024-06-01T18:06:09.576223Z"}]}
{"channel":"book","type":"update","data":[{"symbol":"ETH/USDT","bids":[{"price":3803.47,"qty":1.46240000}],"asks":[],"checksum":4157490045,"timestamp":"2024-06-01T18:06:09.580216Z"}]}
{"channel":"book","type":"update","data":[{"symbol":"ETH/USDT","bids":[{"price":3802.51,"qty":0.72912968}],"asks":[],"checksum":3900862434,"timestamp":"2024-06-01T18:06:09.588833Z"}]}
{"channel":"book","type":"update","data":[{"symbol":"ETH/USDT","bids":[],"asks":[{"price":3804.43,"qty":0.00000000},{"price":3805.21,"qty":5.00000000}],"checksum":2523120757,"timestamp":"2024-06-01T18:06:09.591596Z"}]}
{"channel":"book","type":"update","data":[{"symbol":"ETH/USDT","bids":[{"price":3802.36,"qty":0.27517853}],"asks":[],"checksum":1342211312,"timestamp":"2024-06-01T18:06:09.592065Z"}]}
{"channel":"book","type":"update","data":[{"symbol":"ETH/USDT","bids":[],"asks":[{"price":3804.65,"qty":0.72605248}],"checksum":2735581033,"timestamp":"2024-06-01T18:06:09.592345Z"}]}
{"channel":"book","type":"update","data":[{"symbol":"ETH/USDT","bids":[{"price":3803.47,"qty":0.73120000}],"asks":[],"checksum":2105452472,"timestamp":"2024-06-01T18:06:09.595595Z"}]}
{"channel":"book","type":"update","data":[{"symbol":"ETH/USDT","bids":[{"price":3802.63,"qty":0.84627249}],"asks":[],"checksum":3281807237,"timestamp":"2024-06-01T18:06:09.596992Z"}]}
{"channel":"book","type":"update","data":[{"symbol":"ETH/USDT","bids":[],"asks":[{"price":3804.65,"qty":0.53505505}],"checksum":2010035863,"timestamp":"2024-06-01T18:06:09.598889Z"}]}
{"channel":"book","type":"update","data":[{"symbol":"ETH/USDT","bids":[{"price":3803.47,"qty":1.46240000}],"asks":[],"checksum":4007806157,"timestamp":"2024-06-01T18:06:09.603535Z"}]}
{"channel":"book","type":"update","data":[{"symbol":"ETH/USDT","bids":[],"asks":[{"price":3805.01,"qty":0.00000000},{"price":3805.34,"qty":0.73120000}],"checksum":1090626773,"timestamp":"2024-06-01T18:06:09.610400Z"}]}
{"channel":"book","type":"update","data":[{"symbol":"ETH/USDT","bids":[],"asks":[{"price":3804.15,"qty":2.11600000}],"checksum":1148130897,"timestamp":"2024-06-01T18:06:09.648354Z"}]}
{"channel":"book","type":"update","data":[{"symbol":"ETH/USDT","bids":[],"asks":[{"price":3805.15,"qty":8.05300000}],"checksum":3594522674,"timestamp":"2024-06-01T18:06:09.651259Z"}]}
{"channel":"book","type":"update","data":[{"symbol":"ETH/USDT","bids":[],"asks":[{"price":3804.66,"qty":0.18281174}],"checksum":2592726678,"timestamp":"2024-06-01T18:06:09.743484Z"}]}
{"channel":"book","type":"update","data":[{"symbol":"ETH/USDT","bids":[],"asks":[{"price":3804.81,"qty":0.72912968}],"checksum":1219900408,"timestamp":"2024-06-01T18:06:09.747766Z"}]}
{"channel":"book","type":"update","data":[{"symbol":"ETH/USDT","bids":[],"asks":[{"price":3804.56,"qty":0.25000000}],"checksum":1748300562,"timestamp":"2024-06-01T18:06:09.748216Z"}]}
{"channel":"book","type":"update","data":[{"symbol":"ETH/USDT","bids":[],"asks":[{"price":3804.66,"qty":0.00000000},{"price":3805.00,"qty":44.43772114}],"checksum":2958771462,"timestamp":"2024-06-01T18:06:09.750175Z"}]}
{"channel":"book","type":"update","data":[{"symbol":"ETH/USDT","bids":[],"asks":[{"price":3804.66,"qty":0.21814571}],"checksum":3345208143,"timestamp":"2024-06-01T18:06:09.892730Z"}]}
{"channel":"book","type":"update","data":[{"symbol":"ETH/USDT","bids":[],"asks":[{"price":3804.66,"qty":0.00000000},{"price":3805.00,"qty":44.43772114}],"checksum":2958771462,"timestamp":"2024-06-01T18:06:09.901310Z"}]}
{"channel":"book","type":"update","data":[{"symbol":"ETH/USDT","bids":[{"price":3803.47,"qty":0.73120000}],"asks":[],"checksum":272004079,"timestamp":"2024-06-01T18:06:09.989376Z"}]}
{"channel":"book","type":"update","data":[{"symbol":"ETH/USDT","bids":[],"asks":[{"price":3804.66,"qty":0.18017489}],"checksum":801529701,"timestamp":"2024-06-01T18:06:10.042053Z"}]}
{"channel":"book","type":"update","data":[{"symbol":"ETH/USDT","bids":[],"asks":[{"price":3804.66,"qty":0.00000000},{"price":3805.00,"qty":44.43772114}],"checksum":272004079,"timestamp":"2024-06-01T18:06:10.049319Z"}]}
{"channel":"book","type":"update","data":[{"symbol":"ETH/USDT","bids":[{"price":3803.47,"qty":0.00000000},{"price":3802.36,"qty":0.06693358}],"asks":[],"checksum":3641745190,"timestamp":"2024-06-01T18:06:10.086517Z"}]}
{"channel":"book","type":"update","data":[{"symbol":"ETH/USDT","bids":[{"price":3803.36,"qty":0.73120000}],"asks":[],"checksum":3925076803,"timestamp":"2024-06-01T18:06:10.090143Z"}]}
{"channel":"book","type":"update","data":[{"symbol":"ETH/USDT","bids":[{"price":3803.32,"qty":0.25000000}],"asks":[],"checksum":2416960165,"timestamp":"2024-06-01T18:06:10.091921Z"}]}
{"channel":"book","type":"update","data":[{"symbol":"ETH/USDT","bids":[{"price":3803.36,"qty":0.00000000},{"price":3802.51,"qty":0.72912968}],"asks":[],"checksum":2562389483,"timestamp":"2024-06-01T18:06:10.093654Z"}]}
{"channel":"book","type":"update","data":[{"symbol":"ETH/USDT","bids":[],"asks":[{"price":3804.00,"qty":2.29065001}],"checksum":4150513763,"timestamp":"2024-06-01T18:06:10.105188Z"}]}
{"channel":"book","type":"update","data":[{"symbol":"ETH/USDT","bids":[],"asks":[{"price":3804.00,"qty":3.02185001}],"checksum":2492237725,"timestamp":"2024-06-01T18:06:10.106290Z"}]}
{"channel":"book","type":"update","data":[{"symbol":"ETH/USDT","bids":[],"asks":[{"price":3803.99,"qty":0.73120000}],"checksum":1623057720,"timestamp":"2024-06-01T18:06:10.120226Z"}]}
{"channel":"book","type":"update","data":[{"symbol":"ETH/USDT","bids":[],"asks":[{"price":3804.00,"qty":2.29065001}],"checksum":2407822031,"timestamp":"2024-06-01T18:06:10.123440Z"}]}
{"channel":"book","type":"update","data":[{"symbol":"ETH/USDT","bids":[],"asks":[{"price":3803.99,"qty":0.00000000},{"price":3805.00,"qty":44.43772114}],"checksum":4150513763,"timestamp":"2024-06-01T18:06:10.124286Z"}]}
{"channel":"book","type":"update","data":[{"symbol":"ETH/USDT","bids":[{"price":3803.30,"qty":0.00000000},{"price":3802.36,"qty":0.06693358}],"asks":[],"checksum":3481937851,"timestamp":"2024-06-01T18:06:10.124914Z"}]}
{"channel":"book","type":"update","data":[{"symbol":"ETH/USDT","bids":[],"asks":[{"price":3804.00,"qty":3.02185001}],"checksum":649134246,"timestamp":"2024-06-01T18:06:10.131513Z"}]}
{"channel":"book","type":"update","data":[{"symbol":"ETH/USDT","bids":[],"asks":[{"price":3803.99,"qty":0.73120000}],"checksum":3278304432,"timestamp":"2024-06-01T18:06:10.141953Z"}]}
{"channel":"book","type":"update","data":[{"symbol":"ETH/USDT","bids":[],"asks":[{"price":3804.00,"qty":2.29065001}],"checksum":803285491,"timestamp":"2024-06-01T18:06:10.145833Z"}]}
{"channel":"book","type":"update","data":[{"symbol":"ETH/USDT","bids":[],"asks":[{"price":3803.99,"qty":1.46240000}],"checksum":1471010558,"timestamp":"2024-06-01T18:06:10.148312Z"}]}
{"channel":"book","type":"update","data":[{"symbol":"ETH/USDT","bids":[],"asks":[{"price":3804.00,"qty":1.55945001}],"checksum":581778571,"timestamp":"2024-06-01T18:06:10.149703Z"}]}
{"channel":"book","type":"update","data":[{"symbol":"ETH/USDT","bids":[],"asks":[{"price":3803.99,"qty":0.73120000}],"checksum":1524745094,"timestamp":"2024-06-01T18:06:10.150642Z"}]}
{"channel":"book","type":"update","data":[{"symbol":"ETH/USDT","bids":[],"asks":[{"price":3803.99,"qty":1.46240000}],"checksum":581778571,"timestamp":"2024-06-01T18:06:10.162006Z"}]}
{"channel":"book","type":"update","data":[{"symbol":"ETH/USDT","bids":[],"asks":[{"price":3803.99,"qty":0.73120000}],"checksum":1524745094,"timestamp":"2024-06-01T18:06:10.169225Z"}]}
{"channel":"book","type":"update","data":[{"symbol":"ETH/USDT","bids":[],"asks":[{"price":3803.99,"qty":0.00000000},{"price":3805.00,"qty":44.43772114}],"checksum":2799193709,"timestamp":"2024-06-01T18:06:10.171937Z"}]}
{"channel":"book","type":"update","data":[{"symbol":"ETH/USDT","bids":[{"price":3803.33,"qty":1.31561290}],"asks":[],"checksum":2593400788,"timestamp":"2024-06-01T18:06:10.189321Z"}]}
{"channel":"book","type":"update","data":[{"symbol":"ETH/USDT","bids":[],"asks":[{"price":3804.66,"qty":0.18731983}],"checksum":891682980,"timestamp":"2024-06-01T18:06:10.192535Z"}]}
{"channel":"book","type":"update","data":[{"symbol":"ETH/USDT","bids":[{"price":3803.31,"qty":0.00000000},{"price":3802.37,"qty":0.19712775}],"asks":[],"checksum":3613352074,"timestamp":"2024-06-01T18:06:10.193102Z"}]}
{"channel":"book","type":"update","data":[{"symbol":"ETH/USDT","bids":[{"price":3803.34,"qty":0.25000000}],"asks":[],"checksum":3050292356,"timestamp":"2024-06-01T18:06:10.194554Z"}]}
{"channel":"book","type":"update","data":[{"symbol":"ETH/USDT","bids":[],"asks":[{"price":3804.66,"qty":0.00000000},{"price":3805.00,"qty":44.43772114}],"checksum":234092589,"timestamp":"2024-06-01T18:06:10.199503Z"}]}
{"channel":"book","type":"update","data":[{"symbol":"ETH/USDT","bids":[{"price":3802.56,"qty":0.00000000},{"price":3802.36,"qty":0.06693358}],"asks":[],"checksum":4107712298,"timestamp":"2024-06-01T18:06:10.256706Z"}]}
{"channel":"book","type":"update","data":[{"symbol":"ETH/USDT","bids":[{"price":3803.34,"qty":0.98120000}],"asks":[],"checksum":187467415,"timestamp":"2024-06-01T18:06:10.263625Z"}]}
{"channel":"book","type":"update","data":[{"symbol":"ETH/USDT","bids":[{"price":3803.32,"qty":0.00000000},{"price":3802.33,"qty":0.73120000}],"asks":[],"checksum":741239692,"timestamp":"2024-06-01T18:06:10.268648Z"}]}
{"channel":"book","type":"update","data":[{"symbol":"ETH/USDT","bids":[{"price":3803.36,"qty":0.73120000}],"asks":[],"checksum":2849447906,"timestamp":"2024-06-01T18:06:10.274157Z"}]}
{"channel":"book","type":"update","data":[{"symbol":"ETH/USDT","bids":[{"price":3802.61,"qty":0.19685881}],"asks":[],"checksum":198488358,"timestamp":"2024-06-01T18:06:10.296672Z"}]}
{"channel":"book","type":"update","data":[{"symbol":"ETH/USDT","bids":[],"asks":[{"price":3804.66,"qty":0.19358800}],"checksum":114953968,"timestamp":"2024-06-01T18:06:10.341526Z"}]}
{"channel":"book","type":"update","data":[{"symbol":"ETH/USDT","bids":[],"asks":[{"price":3804.66,"qty":0.00000000},{"price":3805.00,"qty":44.43772114}],"checksum":198488358,"timestamp":"2024-06-01T18:06:10.350029Z"}]}
{"channel":"book","type":"update","data":[{"symbol":"ETH/USDT","bids":[{"price":3803.36,"qty":0.00000000},{"price":3802.36,"qty":0.06693358}],"asks":[],"checksum":2150630174,"timestamp":"2024-06-01T18:06:10.404647Z"}]}
{"channel":"book","type":"update","data":[{"symbol":"ETH/USDT","bids":[{"price":3803.35,"qty":0.73120000}],"asks":[],"checksum":4027235374,"timestamp":"2024-06-01T18:06:10.418816Z"}]}
{"channel":"book","type":"update","data":[{"symbol":"ETH/USDT","bids":[],"asks":[{"price":3804.66,"qty":0.19794651}],"checksum":3437087066,"timestamp":"2024-06-01T18:06:10.493600Z"}]}
{"channel":"book","type":"update","data":[{"symbol":"ETH/USDT","bids":[],"asks":[{"price":3804.66,"qty":0.00000000},{"price":3805.00,"qty":44.43772114}],"checksum":4027235374,"timestamp":"2024-06-01T18:06:10.500246Z"}]}
{"channel":"book","type":"update","data":[{"symbol":"ETH/USDT","bids":[{"price":3803.36,"qty":0.25000000}],"asks":[],"checksum":3756907233,"timestamp":"2024-06-01T18:06:10.587226Z"}]}
{"channel":"book","type":"update","data":[{"symbol":"ETH/USDT","bids":[{"price":3803.34,"qty":0.73120000}],"asks":[],"checksum":2775334559,"timestamp":"2024-06-01T18:06:10.592106Z"}]}
{"channel":"book","type":"update","data":[{"symbol":"ETH/USDT","bids":[{"price":3803.34,"qty":0.00000000},{"price":3802.51,"qty":0.72912968}],"asks":[],"checksum":2446727271,"timestamp":"2024-06-01T18:06:10.596461Z"}]}
{"channel":"book","type":"update","data":[{"symbol":"ETH/USDT","bids":[{"price":3803.36,"qty":0.98120000}],"asks":[],"checksum":620309863,"timestamp":"2024-06-01T18:06:10.600279Z"}]}
{"channel":"book","type":"update","data":[{"symbol":"ETH/USDT","bids":[{"price":3803.35,"qty":0.00000000},{"price":3802.37,"qty":0.19978223}],"asks":[],"checksum":3123788361,"timestamp":"2024-06-01T18:06:10.601270Z"}]}
{"channel":"book","type":"update","data":[{"symbol":"ETH/USDT","bids":[],"asks":[{"price":3804.66,"qty":0.21689602}],"checksum":2126719512,"timestamp":"2024-06-01T18:06:10.642619Z"}]}
{"channel":"book","type":"update","data":[{"symbol":"ETH/USDT","bids":[],"asks":[{"price":3804.66,"qty":0.00000000},{"price":3805.00,"qty":44.43772114}],"checksum":3123788361,"timestamp":"2024-06-01T18:06:10.652738Z"}]}
{"channel":"book","type":"update","data":[{"symbol":"ETH/USDT","bids":[{"price":3802.54,"qty":0.01082520}],"asks":[],"checksum":1316319444,"timestamp":"2024-06-01T18:06:10.704417Z"}]}
{"channel":"book","type":"update","data":[{"symbol":"ETH/USDT","bids":[{"price":3803.36,"qty":0.25000000}],"asks":[],"checksum":2978955625,"timestamp":"2024-06-01T18:06:10.717044Z"}]}
{"channel":"book","type":"update","data":[{"symbol":"ETH/USDT","bids":[{"price":3803.33,"qty":0.00000000},{"price":3802.37,"qty":0.19978223}],"asks":[],"checksum":2109931645,"timestamp":"2024-06-01T18:06:10.789524Z"}]}
{"channel":"book","type":"update","data":[{"symbol":"ETH/USDT","bids":[],"asks":[{"price":3804.66,"qty":0.18660175}],"checksum":3457408192,"timestamp":"2024-06-01T18:06:10.791744Z"}]}
{"channel":"book","type":"update","data":[{"symbol":"ETH/USDT","bids":[{"price":3802.77,"qty":5.00000000}],"asks":[],"checksum":2731195770,"timestamp":"2024-06-01T18:06:10.795167Z"}]}
{"channel":"book","type":"update","data":[{"symbol":"ETH/USDT","bids":[],"asks":[{"price":3804.66,"qty":0.00000000},{"price":3805.00,"qty":44.43772114}],"checksum":396993175,"timestamp":"2024-06-01T18:06:10.797814Z"}]}
{"channel":"book","type":"update","data":[{"symbol":"ETH/USDT","bids":[],"asks":[{"price":3804.66,"qty":0.19461886}],"checksum":2684980357,"timestamp":"2024-06-01T18:06:10.942148Z"}]}
{"channel":"book","type":"update","data":[{"symbol":"ETH/USDT","bids":[],"asks":[{"price":3804.66,"qty":0.00000000},{"price":3805.00,"qty":44.43772114}],"checksum":396993175,"timestamp":"2024-06-01T18:06:10.949739Z"}]}
{"channel":"book","type":"update","data":[{"symbol":"ETH/USDT","bids":[],"asks":[{"price":3804.65,"qty":0.00000000},{"price":3805.15,"qty":8.05300000}],"checksum":1686259041,"timestamp":"2024-06-01T18:06:10.983177Z"}]}
{"channel":"book","type":"update","data":[{"symbol":"ETH/USDT","bids":[],"asks":[{"price":3804.99,"qty":0.58055860}],"checksum":3838274199,"timestamp":"2024-06-01T18:06:10.984756Z"}]}
{"channel":"book","type":"update","data":[{"symbol":"ETH/USDT","bids":[{"price":3802.53,"qty":0.00000000},{"price":3802.37,"qty":0.19978223}],"asks":[],"checksum":1498124761,"timestamp":"2024-06-01T18:06:10.987784Z"}]}
{"channel":"book","type":"update","data":[{"symbol":"ETH/USDT","bids":[],"asks":[{"price":3804.66,"qty":0.21074300}],"checksum":3358884859,"timestamp":"2024-06-01T18:06:11.092329Z"}]}
{"channel":"book","type":"update","data":[{"symbol":"ETH/USDT","bids":[{"price":3803.11,"qty":0.25000000}],"asks":[],"checksum":318733679,"timestamp":"2024-06-01T18:06:11.097294Z"}]}
{"channel":"book","type":"update","data":[{"symbol":"ETH/USDT","bids":[{"price":3803.36,"qty":0.00000000},{"price":3802.37,"qty":0.19978223}],"asks":[],"checksum":3462262472,"timestamp":"2024-06-01T18:06:11.097342Z"}]}
{"channel":"book","type":"update","data":[{"symbol":"ETH/USDT","bids":[],"asks":[{"price":3804.66,"qty":0.00000000},{"price":3805.00,"qty":44.43772114}],"checksum":1596128490,"timestamp":"2024-06-01T18:06:11.098897Z"}]}
{"channel":"book","type":"update","data":[{"symbol":"ETH/USDT","bids":[{"price":3803.29,"qty":0.73120000}],"asks":[],"checksum":2858133125,"timestamp":"2024-06-01T18:06:11.101170Z"}]}
{"channel":"book","type":"update","data":[{"symbol":"ETH/USDT","bids":[],"asks":[{"price":3804.66,"qty":0.19348700}],"checksum":2258781307,"timestamp":"2024-06-01T18:06:11.242459Z"}]}
{"channel":"book","type":"update","data":[{"symbol":"ETH/USDT","bids":[{"price":3803.30,"qty":0.25000000}],"asks":[],"checksum":67296124,"timestamp":"2024-06-01T18:06:11.249191Z"}]}
{"channel":"book","type":"update","data":[{"symbol":"ETH/USDT","bids":[],"asks":[{"price":3804.66,"qty":0.00000000},{"price":3805.00,"qty":44.43772114}],"checksum":687552898,"timestamp":"2024-06-01T18:06:11.251109Z"}]}
{"channel":"book","type":"update","data":[{"symbol":"ETH/USDT","bids":[{"price":3803.49,"qty":0.73120000}],"asks":[],"checksum":4143785207,"timestamp":"2024-06-01T18:06:11.253316Z"}]}
{"channel":"book","type":"update","data":[{"symbol":"ETH/USDT","bids":[{"price":3803.43,"qty":0.73120000}],"asks":[],"checksum":3708598941,"timestamp":"2024-06-01T18:06:11.254120Z"}]}
{"channel":"book","type":"update","data":[{"symbol":"ETH/USDT","bids":[{"price":3803.43,"qty":0.00000000},{"price":3802.61,"qty":0.19685881}],"asks":[],"checksum":4143785207,"timestamp":"2024-06-01T18:06:11.256931Z"}]}
{"channel":"book","type":"update","data":[{"symbol":"ETH/USDT","bids":[{"price":3803.49,"qty":0.00000000},{"price":3802.54,"qty":0.01082520}],"asks":[],"checksum":687552898,"timestamp":"2024-06-01T18:06:11.322382Z"}]}
{"channel":"book","type":"update","data":[{"symbol":"ETH/USDT","bids":[{"price":3803.42,"qty":0.73120000}],"asks":[],"checksum":2073399871,"timestamp":"2024-06-01T18:06:11.326138Z"}]}
{"channel":"book","type":"update","data":[{"symbol":"ETH/USDT","bids":[{"price":3803.11,"qty":0.00000000},{"price":3802.54,"qty":0.01082520}],"asks":[],"checksum":943146455,"timestamp":"2024-06-01T18:06:11.327233Z"}]}
{"channel":"book","type":"update","data":[{"symbol":"ETH/USDT","bids":[{"price":3803.42,"qty":1.46240000}],"asks":[],"checksum":3384661805,"timestamp":"2024-06-01T18:06:11.339011Z"}]}
{"channel":"book","type":"update","data":[{"symbol":"ETH/USDT","bids":[],"asks":[{"price":3804.66,"qty":0.19938275}],"checksum":46513969,"timestamp":"2024-06-01T18:06:11.393028Z"}]}
{"channel":"book","type":"update","data":[{"symbol":"ETH/USDT","bids":[{"price":3803.42,"qty":0.73120000}],"asks":[],"checksum":569169255,"timestamp":"2024-06-01T18:06:11.403914Z"}]}
{"channel":"book","type":"update","data":[{"symbol":"ETH/USDT","bids":[{"price":3802.61,"qty":0.00000000},{"price":3802.51,"qty":0.72912968}],"asks":[],"checksum":1222391565,"timestamp":"2024-06-01T18:06:11.549572Z"}]}
{"channel":"book","type":"update","data":[{"symbol":"ETH/USDT","bids":[{"price":3802.69,"qty":0.19684865}],"asks":[],"checksum":3478752372,"timestamp":"2024-06-01T18:06:11.589526Z"}]}
{"channel":"book","type":"update","data":[{"symbol":"ETH/USDT","bids":[{"price":3803.42,"qty":1.46240000}],"asks":[],"checksum":3966821922,"timestamp":"2024-06-01T18:06:11.649334Z"}]}
{"channel":"book","type":"update","data":[{"symbol":"ETH/USDT","bids":[{"price":3803.42,"qty":0.73120000}],"asks":[],"checksum":3478752372,"timestamp":"2024-06-01T18:06:11.694188Z"}]}
{"channel":"book","type":"update","data":[{"symbol":"ETH/USDT","bids":[{"price":3803.43,"qty":0.73120000}],"asks":[],"checksum":3830527923,"timestamp":"2024-06-01T18:06:11.697922Z"}]}
{"channel":"book","type":"update","data":[{"symbol":"ETH/USDT","bids":[{"price":3803.43,"qty":1.46240000}],"asks":[],"checksum":921712085,"timestamp":"2024-06-01T18:06:11.704238Z"}]}
{"channel":"book","type":"update","data":[{"symbol":"ETH/USDT","bids":[{"price":3803.29,"qty":0.00000000},{"price":3802.54,"qty":0.01082520}],"asks":[],"checksum":349736240,"timestamp":"2024-06-01T18:06:11.704736Z"}]}
{"channel":"book","type":"update","data":[{"symbol":"ETH/USDT","bids":[{"price":3803.43,"qty":0.73120000}],"asks":[],"checksum":3093239318,"timestamp":"2024-06-01T18:06:11.705214Z"}]}
{"channel":"book","type":"update","data":[{"symbol":"ETH/USDT","bids":[{"price":3803.42,"qty":0.00000000},{"price":3802.51,"qty":0.72912968}],"asks":[],"checksum":3578321580,"timestamp":"2024-06-01T18:06:11.705516Z"}]}
{"channel":"book","type":"update","data":[{"symbol":"ETH/USDT","bids":[{"price":3803.43,"qty":1.46240000}],"asks":[],"checksum":2043625866,"timestamp":"2024-06-01T18:06:11.711165Z"}]}
{"channel":"book","type":"update","data":[{"symbol":"ETH/USDT","bids":[{"price":3803.49,"qty":0.73120000}],"asks":[],"checksum":382501872,"timestamp":"2024-06-01T18:06:11.711505Z"}]}
{"channel":"book","type":"update","data":[{"symbol":"ETH/USDT","bids":[{"price":3803.43,"qty":0.73120000}],"asks":[],"checksum":1928772365,"timestamp":"2024-06-01T18:06:11.712524Z"}]}
{"channel":"book","type":"update","data":[{"symbol":"ETH/USDT","bids":[{"price":3803.43,"qty":0.00000000},{"price":3802.51,"qty":0.72912968}],"asks":[],"checksum":2326974409,"timestamp":"2024-06-01T18:06:11.716643Z"}]}
{"channel":"book","type":"update","data":[{"symbol":"ETH/USDT","bids":[{"price":3803.49,"qty":1.46240000}],"asks":[],"checksum":1145581128,"timestamp":"2024-06-01T18:06:11.734670Z"}]}
{"channel":"book","type":"update","data":[{"symbol":"ETH/USDT","bids":[{"price":3802.76,"qty":0.00000000},{"price":3802.37,"qty":0.19978223}],"asks":[],"checksum":3242074326,"timestamp":"2024-06-01T18:06:11.797307Z"}]}
{"channel":"book","type":"update","data":[{"symbol":"ETH/USDT","bids":[{"price":3803.16,"qty":2.63158614}],"asks":[],"checksum":377986369,"timestamp":"2024-06-01T18:06:11.801485Z"}]}
{"channel":"book","type":"update","data":[{"symbol":"ETH/USDT","bids":[],"asks":[{"price":3804.00,"qty":0.00000000},{"price":3805.15,"qty":5.26000000}],"checksum":3337258728,"timestamp":"2024-06-01T18:06:11.817798Z"}]}
{"channel":"book","type":"update","data":[{"symbol":"ETH/USDT","bids":[{"price":3803.49,"qty":0.73120000}],"asks":[],"checksum":3580895781,"timestamp":"2024-06-01T18:06:11.822052Z"}]}
{"channel":"book","type":"update","data":[{"symbol":"ETH/USDT","bids":[],"asks":[{"price":3804.14,"qty":2.07604326}],"checksum":1421741433,"timestamp":"2024-06-01T18:06:11.822739Z"}]}
{"channel":"book","type":"update","data":[{"symbol":"ETH/USDT","bids":[{"price":3803.10,"qty":0.00000000},{"price":3802.37,"qty":0.19978223}],"asks":[],"checksum":2689608818,"timestamp":"2024-06-01T18:06:11.824682Z"}]}
{"channel":"book","type":"update","data":[{"symbol":"ETH/USDT","bids":[{"price":3803.38,"qty":0.34000000}],"asks":[],"checksum":4048879288,"timestamp":"2024-06-01T18:06:11.824897Z"}]}
{"channel":"book","type":"update","data":[{"symbol":"ETH/USDT","bids":[{"price":3803.53,"qty":0.73120000}],"asks":[],"checksum":2028497231,"timestamp":"2024-06-01T18:06:11.825096Z"}]}
{"channel":"book","type":"update","data":[{"symbol":"ETH/USDT","bids":[{"price":3803.49,"qty":0.00000000},{"price":3802.51,"qty":0.72912968}],"asks":[],"checksum":507589335,"timestamp":"2024-06-01T18:06:11.828686Z"}]}
{"channel":"book","type":"update","data":[{"symbol":"ETH/USDT","bids":[{"price":3803.53,"qty":1.46240000}],"asks":[],"checksum":3703492572,"timestamp":"2024-06-01T18:06:11.828787Z"}]}
{"channel":"book","type":"update","data":[{"symbol":"ETH/USDT","bids":[{"price":3803.53,"qty":0.73120000}],"asks":[],"checksum":507589335,"timestamp":"2024-06-01T18:06:11.829054Z"}]}
{"channel":"book","type":"update","data":[{"symbol":"ETH/USDT","bids":[{"price":3803.53,"qty":1.46240000}],"asks":[],"checksum":3703492572,"timestamp":"2024-06-01T18:06:11.832366Z"}]}
{"channel":"book","type":"update","data":[{"symbol":"ETH/USDT","bids":[],"asks":[{"price":3804.89,"qty":0.00000000},{"price":3805.14,"qty":45.98752625}],"checksum":1626136126,"timestamp":"2024-06-01T18:06:11.913555Z"}]}
{"channel":"book","type":"update","data":[{"symbol":"ETH/USDT","bids":[],"asks":[{"price":3804.26,"qty":0.00000000},{"price":3805.15,"qty":5.26000000}],"checksum":458971643,"timestamp":"2024-06-01T18:06:11.914397Z"}]}
{"channel":"book","type":"update","data":[{"symbol":"ETH/USDT","bids":[],"asks":[{"price":3804.61,"qty":2.63058936}],"checksum":1448406047,"timestamp":"2024-06-01T18:06:11.918979Z"}]}
{"channel":"book","type":"update","data":[{"symbol":"ETH/USDT","bids":[{"price":3803.62,"qty":0.06693358}],"asks":[],"checksum":1609984438,"timestamp":"2024-06-01T18:06:11.962012Z"}]}
{"channel":"book","type":"update","data":[{"symbol":"ETH/USDT","bids":[{"price":3803.70,"qty":0.73120000}],"asks":[],"checksum":865473591,"timestamp":"2024-06-01T18:06:11.965669Z"}]}
{"channel":"book","type":"update","data":[{"symbol":"ETH/USDT","bids":[],"asks":[{"price":3804.67,"qty":0.00000000},{"price":3805.15,"qty":5.26000000}],"checksum":630967711,"timestamp":"2024-06-01T18:06:11.976661Z"}]}
{"channel":"book","type":"update","data":[{"symbol":"ETH/USDT","bids":[],"asks":[{"price":3804.15,"qty":0.00000000},{"price":3805.21,"qty":5.00000000}],"checksum":2776039365,"timestamp":"2024-06-01T18:06:11.977110Z"}]}
{"channel":"book","type":"update","data":[{"symbol":"ETH/USDT","bids":[],"asks":[{"price":3804.92,"qty":0.73120000}],"checksum":1434682212,"timestamp":"2024-06-01T18:06:11.981017Z"}]}
{"channel":"book","type":"update","data":[{"symbol":"ETH/USDT","bids":[{"price":3803.54,"qty":0.07893092}],"asks":[],"checksum":293457993,"timestamp":"2024-06-01T18:06:11.983051Z"}]}
{"channel":"book","type":"update","data":[{"symbol":"ETH/USDT","bids":[{"price":3803.54,"qty":0.00000000},{"price":3802.63,"qty":0.84627249}],"asks":[],"checksum":1434682212,"timestamp":"2024-06-01T18:06:11.988831Z"}]}
{"channel":"book","type":"update","data":[{"symbol":"ETH/USDT","bids":[{"price":3803.71,"qty":0.07892733}],"asks":[],"checksum":3162934381,"timestamp":"2024-06-01T18:06:12.007979Z"}]}
{"channel":"book","type":"update","data":[{"symbol":"ETH/USDT","bids":[],"asks":[{"price":3804.66,"qty":0.00000000},{"price":3805.21,"qty":5.00000000}],"checksum":4256486331,"timestamp":"2024-06-01T18:06:12.014688Z"}]}
{"channel":"book","type":"update","data":[{"symbol":"ETH/USDT","bids":[],"asks":[{"price":3804.86,"qty":0.18636949}],"checksum":1152199521,"timestamp":"2024-06-01T18:06:12.015198Z"}]}
{"channel":"book","type":"update","data":[{"symbol":"ETH/USDT","bids":[],"asks":[{"price":3804.53,"qty":0.73120000}],"checksum":3302559330,"timestamp":"2024-06-01T18:06:12.016123Z"}]}
{"channel":"book","type":"update","data":[{"symbol":"ETH/USDT","bids":[{"price":3803.38,"qty":0.00000000},{"price":3802.63,"qty":0.84627249}],"asks":[],"checksum":2468959246,"timestamp":"2024-06-01T18:06:12.018756Z"}]}
{"channel":"book","type":"update","data":[{"symbol":"ETH/USDT","bids":[{"price":3803.54,"qty":0.34000000}],"asks":[],"checksum":3354319808,"timestamp":"2024-06-01T18:06:12.025780Z"}]}
{"channel":"book","type":"update","data":[{"symbol":"ETH/USDT","bids":[],"asks":[{"price":3804.53,"qty":0.00000000},{"price":3805.15,"qty":5.26000000}],"checksum":1201340099,"timestamp":"2024-06-01T18:06:12.031372Z"}]}
{"channel":"book","type":"update","data":[{"symbol":"ETH/USDT","bids":[],"asks":[{"price":3804.52,"qty":2.11600000}],"checksum":4102283994,"timestamp":"2024-06-01T18:06:12.123496Z"}]}
{"channel":"book","type":"update","data":[{"symbol":"ETH/USDT","bids":[{"price":3803.71,"qty":0.00000000},{"price":3802.63,"qty":0.84627249}],"asks":[],"checksum":3673169500,"timestamp":"2024-06-01T18:06:12.151980Z"}]}
{"channel":"book","type":"update","data":[{"symbol":"ETH/USDT","bids":[{"price":3802.69,"qty":0.00000000},{"price":3802.57,"qty":0.19869515}],"asks":[],"checksum":3222755652,"timestamp":"2024-06-01T18:06:12.159245Z"}]}
{"channel":"book","type":"update","data":[{"symbol":"ETH/USDT","bids":[{"price":3802.60,"qty":0.22029361}],"asks":[],"checksum":2528892502,"timestamp":"2024-06-01T18:06:12.197165Z"}]}
{"channel":"book","type":"update","data":[{"symbol":"ETH/USDT","bids":[{"price":3802.91,"qty":0.19681607}],"asks":[],"checksum":1501559666,"timestamp":"2024-06-01T18:06:12.199627Z"}]}
{"channel":"book","type":"update","data":[{"symbol":"ETH/USDT","bids":[],"asks":[{"price":3804.53,"qty":0.73120000}],"checksum":1844993132,"timestamp":"2024-06-01T18:06:12.217397Z"}]}
{"channel":"book","type":"update","data":[{"symbol":"ETH/USDT","bids":[],"asks":[{"price":3804.52,"qty":0.00000000},{"price":3805.14,"qty":45.98752625}],"checksum":2754506545,"timestamp":"2024-06-01T18:06:12.262316Z"}]}
{"channel":"book","type":"update","data":[{"symbol":"ETH/USDT","bids":[],"asks":[{"price":3804.81,"qty":0.00000000},{"price":3805.15,"qty":5.26000000}],"checksum":640521522,"timestamp":"2024-06-01T18:06:12.263783Z"}]}
{"channel":"book","type":"update","data":[{"symbol":"ETH/USDT","bids":[{"price":3803.16,"qty":0.00000000},{"price":3802.60,"qty":0.22029361}],"asks":[],"checksum":2076302316,"timestamp":"2024-06-01T18:06:12.270555Z"}]}
{"channel":"book","type":"update","data":[{"symbol":"ETH/USDT","bids":[{"price":3803.51,"qty":2.63135384}],"asks":[],"checksum":2582613193,"timestamp":"2024-06-01T18:06:12.275780Z"}]}
{"channel":"book","type":"update","data":[{"symbol":"ETH/USDT","bids":[],"asks":[{"price":3804.61,"qty":0.00000000},{"price":3805.21,"qty":5.00000000}],"checksum":2039215926,"timestamp":"2024-06-01T18:06:12.277430Z"}]}
{"channel":"book","type":"update","data":[{"symbol":"ETH/USDT","bids":[],"asks":[{"price":3804.97,"qty":2.63035340}],"checksum":3287681056,"timestamp":"2024-06-01T18:06:12.281647Z"}]}
{"channel":"book","type":"update","data":[{"symbol":"ETH/USDT","bids":[],"asks":[{"price":3804.53,"qty":0.00000000},{"price":3805.21,"qty":5.00000000}],"checksum":2165740209,"timestamp":"2024-06-01T18:06:12.306152Z"}]}
{"channel":"book","type":"update","data":[{"symbol":"ETH/USDT","bids":[{"price":3803.02,"qty":0.72912968}],"asks":[],"checksum":85759546,"timestamp":"2024-06-01T18:06:12.310229Z"}]}
{"channel":"book","type":"update","data":[{"symbol":"ETH/USDT","bids":[],"asks":[{"price":3804.68,"qty":2.11600000}],"checksum":3238410869,"timestamp":"2024-06-01T18:06:12.360519Z"}]}
{"channel":"book","type":"update","data":[{"symbol":"ETH/USDT","bids":[],"asks":[{"price":3804.53,"qty":0.73120000}],"checksum":1677142033,"timestamp":"2024-06-01T18:06:12.393444Z"}]}
{"channel":"book","type":"update","data":[{"symbol":"ETH/USDT","bids":[],"asks":[{"price":3804.53,"qty":0.00000000},{"price":3805.15,"qty":5.26000000}],"checksum":3238410869,"timestamp":"2024-06-01T18:06:12.585783Z"}]}
{"channel":"book","type":"update","data":[{"symbol":"ETH/USDT","bids":[],"asks":[{"price":3804.53,"qty":0.73120000}],"checksum":1677142033,"timestamp":"2024-06-01T18:06:12.661963Z"}]}
{"channel":"book","type":"update","data":[{"symbol":"ETH/USDT","bids":[{"price":3803.09,"qty":2.11600000}],"asks":[],"checksum":3802752486,"timestamp":"2024-06-01T18:06:12.831269Z"}]}
{"channel":"book","type":"update","data":[{"symbol":"ETH/USDT","bids":[{"price":3802.91,"qty":0.00000000},{"price":3802.77,"qty":5.00000000}],"asks":[],"checksum":2018670483,"timestamp":"2024-06-01T18:06:12.841753Z"}]}
{"channel":"book","type":"update","data":[{"symbol":"ETH/USDT","bids":[{"price":3802.95,"qty":0.19679707}],"asks":[],"checksum":4184072675,"timestamp":"2024-06-01T18:06:12.882059Z"}]}
{"channel":"book","type":"update","data":[{"symbol":"ETH/USDT","bids":[{"price":3803.70,"qty":0.00000000},{"price":3802.77,"qty":5.00000000}],"asks":[],"checksum":269737663,"timestamp":"2024-06-01T18:06:12.888949Z"}]}
{"channel":"book","type":"update","data":[{"symbol":"ETH/USDT","bids":[{"price":3803.67,"qty":0.73120000}],"asks":[],"checksum":3177964688,"timestamp":"2024-06-01T18:06:12.892427Z"}]}
{"channel":"book","type":"update","data":[{"symbol":"ETH/USDT","bids":[{"price":3803.09,"qty":0.00000000},{"price":3802.77,"qty":5.00000000}],"asks":[],"checksum":3566561400,"timestamp":"2024-06-01T18:06:12.987914Z"}]}
{"channel":"book","type":"update","data":[{"symbol":"ETH/USDT","bids":[{"price":3803.67,"qty":0.00000000},{"price":3802.63,"qty":0.84627249}],"asks":[],"checksum":3033712848,"timestamp":"2024-06-01T18:06:12.987950Z"}]}
{"channel":"book","type":"update","data":[{"symbol":"ETH/USDT","bids":[{"price":3803.53,"qty":0.73120000}],"asks":[],"checksum":2819393373,"timestamp":"2024-06-01T18:06:12.992071Z"}]}
{"channel":"book","type":"update","data":[{"symbol":"ETH/USDT","bids":[{"price":3803.63,"qty":0.73120000}],"asks":[],"checksum":2472722356,"timestamp":"2024-06-01T18:06:12.992149Z"}]}
{"channel":"book","type":"update","data":[{"symbol":"ETH/USDT","bids":[{"price":3803.06,"qty":2.11600000}],"asks":[],"checksum":3289263572,"timestamp":"2024-06-01T18:06:13.092725Z"}]}
{"channel":"book","type":"update","data":[{"symbol":"ETH/USDT","bids":[{"price":3803.63,"qty":0.00000000},{"price":3802.77,"qty":5.00000000}],"asks":[],"checksum":638089505,"timestamp":"2024-06-01T18:06:13.190128Z"}]}
{"channel":"book","type":"update","data":[{"symbol":"ETH/USDT","bids":[{"price":3803.62,"qty":0.00000000},{"price":3802.63,"qty":0.84627249}],"asks":[],"checksum":1492868101,"timestamp":"2024-06-01T18:06:13.396590Z"}]}
{"channel":"book","type":"update","data":[{"symbol":"ETH/USDT","bids":[{"price":3803.53,"qty":0.00000000},{"price":3802.60,"qty":0.22029361}],"asks":[],"checksum":1284901838,"timestamp":"2024-06-01T18:06:13.400985Z"}]}
{"channel":"book","type":"update","data":[{"symbol":"ETH/USDT","bids":[{"price":3803.54,"qty":1.07120000}],"asks":[],"checksum":1028268441,"timestamp":"2024-06-01T18:06:13.401162Z"}]}
{"channel":"book","type":"update","data":[{"symbol":"ETH/USDT","bids":[{"price":3803.55,"qty":0.25000000}],"asks":[],"checksum":1161115331,"timestamp":"2024-06-01T18:06:13.402679Z"}]}
{"channel":"book","type":"update","data":[{"symbol":"ETH/USDT","bids":[{"price":3803.55,"qty":0.98120000}],"asks":[],"checksum":1166023158,"timestamp":"2024-06-01T18:06:13.406036Z"}]}
{"channel":"book","type":"update","data":[{"symbol":"ETH/USDT","bids":[{"price":3803.41,"qty":0.06693358}],"asks":[],"checksum":494310860,"timestamp":"2024-06-01T18:06:13.501105Z"}]}
{"channel":"book","type":"update","data":[{"symbol":"ETH/USDT","bids":[{"price":3803.30,"qty":0.00000000},{"price":3802.63,"qty":0.84627249}],"asks":[],"checksum":983424633,"timestamp":"2024-06-01T18:06:13.505664Z"}]}
{"channel":"book","type":"update","data":[{"symbol":"ETH/USDT","bids":[{"price":3802.95,"qty":0.00000000},{"price":3802.60,"qty":0.22029361}],"asks":[],"checksum":859484694,"timestamp":"2024-06-01T18:06:13.525554Z"}]}
{"channel":"book","type":"update","data":[{"symbol":"ETH/USDT","bids":[],"asks":[{"price":3804.99,"qty":0.00000000},{"price":3805.15,"qty":5.26000000}],"checksum":139462530,"timestamp":"2024-06-01T18:06:13.533365Z"}]}
{"channel":"book","type":"update","data":[{"symbol":"ETH/USDT","bids":[],"asks":[{"price":3805.13,"qty":0.60656021}],"checksum":2215344886,"timestamp":"2024-06-01T18:06:13.535544Z"}]}
{"channel":"book","type":"update","data":[{"symbol":"ETH/USDT","bids":[{"price":3802.91,"qty":0.19678461}],"asks":[],"checksum":2263042888,"timestamp":"2024-06-01T18:06:13.565825Z"}]}
{"channel":"book","type":"update","data":[{"symbol":"ETH/USDT","bids":[{"price":3803.55,"qty":0.25000000}],"asks":[],"checksum":869039688,"timestamp":"2024-06-01T18:06:13.601846Z"}]}
{"channel":"book","type":"update","data":[{"symbol":"ETH/USDT","bids":[{"price":3803.54,"qty":0.34000000}],"asks":[],"checksum":775024326,"timestamp":"2024-06-01T18:06:13.601872Z"}]}
{"channel":"book","type":"update","data":[{"symbol":"ETH/USDT","bids":[{"price":3803.06,"qty":0.00000000},{"price":3802.60,"qty":0.22029361}],"asks":[],"checksum":742301114,"timestamp":"2024-06-01T18:06:13.602607Z"}]}
{"channel":"book","type":"update","data":[{"symbol":"ETH/USDT","bids":[{"price":3803.01,"qty":2.11600000}],"asks":[],"checksum":1444273742,"timestamp":"2024-06-01T18:06:13.719294Z"}]}
{"channel":"book","type":"update","data":[{"symbol":"ETH/USDT","bids":[{"price":3803.55,"qty":0.98120000}],"asks":[],"checksum":2851074035,"timestamp":"2024-06-01T18:06:13.791530Z"}]}
{"channel":"book","type":"update","data":[{"symbol":"ETH/USDT","bids":[{"price":3803.55,"qty":1.71240000}],"asks":[],"checksum":3954335947,"timestamp":"2024-06-01T18:06:13.792619Z"}]}
{"channel":"book","type":"update","data":[{"symbol":"ETH/USDT","bids":[{"price":3803.55,"qty":0.98120000}],"asks":[],"checksum":2851074035,"timestamp":"2024-06-01T18:06:13.795968Z"}]}
{"channel":"book","type":"update","data":[{"symbol":"ETH/USDT","bids":[{"price":3803.56,"qty":0.73120000}],"asks":[],"checksum":1656937665,"timestamp":"2024-06-01T18:06:13.837694Z"}]}
{"channel":"book","type":"update","data":[{"symbol":"ETH/USDT","bids":[{"price":3803.57,"qty":0.25000000}],"asks":[],"checksum":928442125,"timestamp":"2024-06-01T18:06:13.843581Z"}]}
{"channel":"book","type":"update","data":[{"symbol":"ETH/USDT","bids":[{"price":3803.57,"qty":0.98120000}],"asks":[],"checksum":3255642836,"timestamp":"2024-06-01T18:06:13.847169Z"}]}
{"channel":"book","type":"update","data":[{"symbol":"ETH/USDT","bids":[{"price":3803.55,"qty":0.25000000}],"asks":[],"checksum":3370358014,"timestamp":"2024-06-01T18:06:13.847289Z"}]}
{"channel":"book","type":"update","data":[{"symbol":"ETH/USDT","bids":[{"price":3803.56,"qty":0.00000000},{"price":3802.77,"qty":5.00000000}],"asks":[],"checksum":3386694943,"timestamp":"2024-06-01T18:06:13.848510Z"}]}
{"channel":"book","type":"update","data":[{"symbol":"ETH/USDT","bids":[{"price":3803.58,"qty":0.73120000}],"asks":[],"checksum":117594144,"timestamp":"2024-06-01T18:06:13.851706Z"}]}
{"channel":"book","type":"update","data":[{"symbol":"ETH/USDT","bids":[{"price":3803.59,"qty":0.25000000}],"asks":[],"checksum":2180960642,"timestamp":"2024-06-01T18:06:14.086614Z"}]}
{"channel":"book","type":"update","data":[{"symbol":"ETH/USDT","bids":[{"price":3803.57,"qty":0.73120000}],"asks":[],"checksum":824075591,"timestamp":"2024-06-01T18:06:14.086741Z"}]}
{"channel":"book","type":"update","data":[{"symbol":"ETH/USDT","bids":[{"price":3803.55,"qty":0.00000000},{"price":3802.91,"qty":0.19678461}],"asks":[],"checksum":3390843780,"timestamp":"2024-06-01T18:06:14.091318Z"}]}
{"channel":"book","type":"update","data":[{"symbol":"ETH/USDT","bids":[{"price":3803.57,"qty":0.00000000},{"price":3802.77,"qty":5.00000000}],"asks":[],"checksum":4105742451,"timestamp":"2024-06-01T18:06:14.091964Z"}]}
{"channel":"book","type":"update","data":[{"symbol":"ETH/USDT","bids":[{"price":3802.91,"qty":0.00000000},{"price":3802.63,"qty":0.84627249}],"asks":[],"checksum":3161199890,"timestamp":"2024-06-01T18:06:14.130030Z"}]}
{"channel":"book","type":"update","data":[{"symbol":"ETH/USDT","bids":[],"asks":[{"price":3804.14,"qty":0.00000000},{"price":3805.15,"qty":5.26000000}],"checksum":211261974,"timestamp":"2024-06-01T18:06:14.150802Z"}]}
{"channel":"book","type":"update","data":[{"symbol":"ETH/USDT","bids":[],"asks":[{"price":3805.14,"qty":0.00000000},{"price":3805.21,"qty":5.00000000}],"checksum":4275435322,"timestamp":"2024-06-01T18:06:14.150843Z"}]}
{"channel":"book","type":"update","data":[{"symbol":"ETH/USDT","bids":[],"asks":[{"price":3804.67,"qty":0.34000000}],"checksum":1539246596,"timestamp":"2024-06-01T18:06:14.153733Z"}]}
{"channel":"book","type":"update","data":[{"symbol":"ETH/USDT","bids":[],"asks":[{"price":3804.53,"qty":1.46240000}],"checksum":2693480217,"timestamp":"2024-06-01T18:06:14.154565Z"}]}
{"channel":"book","type":"update","data":[{"symbol":"ETH/USDT","bids":[],"asks":[{"price":3804.52,"qty":1.04278008}],"checksum":549888775,"timestamp":"2024-06-01T18:06:14.155531Z"}]}
{"channel":"book","type":"update","data":[{"symbol":"ETH/USDT","bids":[],"asks":[{"price":3804.67,"qty":5.51562574}],"checksum":3362960871,"timestamp":"2024-06-01T18:06:14.155574Z"}]}
{"channel":"book","type":"update","data":[{"symbol":"ETH/USDT","bids":[],"asks":[{"price":3804.52,"qty":1.29278008}],"checksum":2546284770,"timestamp":"2024-06-01T18:06:14.155651Z"}]}
{"channel":"book","type":"update","data":[{"symbol":"ETH/USDT","bids":[],"asks":[{"price":3804.96,"qty":45.76174747}],"checksum":2607022385,"timestamp":"2024-06-01T18:06:14.155746Z"}]}
{"channel":"book","type":"update","data":[{"symbol":"ETH/USDT","bids":[],"asks":[{"price":3804.33,"qty":0.73120000}],"checksum":1923419787,"timestamp":"2024-06-01T18:06:14.159175Z"}]}
{"channel":"book","type":"update","data":[{"symbol":"ETH/USDT","bids":[{"price":3802.85,"qty":0.19679550}],"asks":[],"checksum":868106519,"timestamp":"2024-06-01T18:06:14.170349Z"}]}
{"channel":"book","type":"update","data":[{"symbol":"ETH/USDT","bids":[{"price":3803.58,"qty":0.00000000},{"price":3802.63,"qty":0.84627249}],"asks":[],"checksum":1283508587,"timestamp":"2024-06-01T18:06:14.179482Z"}]}
{"channel":"book","type":"update","data":[{"symbol":"ETH/USDT","bids":[],"asks":[{"price":3804.52,"qty":1.04278008}],"checksum":1068846916,"timestamp":"2024-06-01T18:06:14.587045Z"}]}
{"channel":"book","type":"update","data":[{"symbol":"ETH/USDT","bids":[{"price":3803.59,"qty":0.00000000},{"price":3802.60,"qty":0.22029361}],"asks":[],"checksum":3018346306,"timestamp":"2024-06-01T18:06:14.591664Z"}]}
{"channel":"book","type":"update","data":[{"symbol":"ETH/USDT","bids":[{"price":3803.55,"qty":0.25000000}],"asks":[],"checksum":380697144,"timestamp":"2024-06-01T18:06:14.591876Z"}]}
{"channel":"book","type":"update","data":[{"symbol":"ETH/USDT","bids":[{"price":3803.56,"qty":0.73120000}],"asks":[],"checksum":1682773324,"timestamp":"2024-06-01T18:06:14.606800Z"}]}
{"channel":"book","type":"update","data":[{"symbol":"ETH/USDT","bids":[{"price":3803.56,"qty":0.00000000},{"price":3802.63,"qty":0.84627249}],"asks":[],"checksum":380697144,"timestamp":"2024-06-01T18:06:14.709079Z"}]}
{"channel":"book","type":"update","data":[{"symbol":"ETH/USDT","bids":[{"price":3803.57,"qty":0.73120000}],"asks":[],"checksum":3567438918,"timestamp":"2024-06-01T18:06:14.762036Z"}]}
{"channel":"book","type":"update","data":[{"symbol":"ETH/USDT","bids":[{"price":3803.58,"qty":0.25000000}],"asks":[],"checksum":591496043,"timestamp":"2024-06-01T18:06:14.766717Z"}]}
{"channel":"book","type":"update","data":[{"symbol":"ETH/USDT","bids":[{"price":3802.85,"qty":0.00000000},{"price":3802.77,"qty":5.00000000}],"asks":[],"checksum":3118865796,"timestamp":"2024-06-01T18:06:14.865576Z"}]}
{"channel":"book","type":"update","data":[{"symbol":"ETH/USDT","bids":[{"price":3802.84,"qty":0.19679544}],"asks":[],"checksum":709649008,"timestamp":"2024-06-01T18:06:14.906026Z"}]}
{"channel":"book","type":"update","data":[{"symbol":"ETH/USDT","bids":[{"price":3803.57,"qty":0.00000000},{"price":3802.77,"qty":5.00000000}],"asks":[],"checksum":1944303913,"timestamp":"2024-06-01T18:06:14.907152Z"}]}
{"channel":"book","type":"update","data":[{"symbol":"ETH/USDT","bids":[{"price":3803.58,"qty":0.00000000},{"price":3802.63,"qty":0.84627249}],"asks":[],"checksum":1683776299,"timestamp":"2024-06-01T18:06:14.911662Z"}]}
{"channel":"book","type":"update","data":[{"symbol":"ETH/USDT","bids":[],"asks":[{"price":3804.33,"qty":0.00000000},{"price":3804.97,"qty":2.63035340}],"checksum":282509009,"timestamp":"2024-06-01T18:06:15.122993Z"}]}
{"channel":"book","type":"update","data":[{"symbol":"ETH/USDT","bids":[{"price":3803.60,"qty":0.73120000}],"asks":[],"checksum":757726691,"timestamp":"2024-06-01T18:06:15.123077Z"}]}
{"channel":"book","type":"update","data":[{"symbol":"ETH/USDT","bids":[],"asks":[{"price":3804.40,"qty":0.73120000}],"checksum":1389244828,"timestamp":"2024-06-01T18:06:15.127103Z"}]}
{"channel":"book","type":"update","data":[{"symbol":"ETH/USDT","bids":[{"price":3803.61,"qty":0.25000000}],"asks":[],"checksum":3601593655,"timestamp":"2024-06-01T18:06:15.128381Z"}]}
{"channel":"book","type":"update","data":[{"symbol":"ETH/USDT","bids":[],"asks":[{"price":3804.51,"qty":0.25000000}],"checksum":4251294981,"timestamp":"2024-06-01T18:06:15.128532Z"}]}
{"channel":"book","type":"update","data":[{"symbol":"ETH/USDT","bids":[{"price":3803.60,"qty":0.00000000},{"price":3802.77,"qty":5.00000000}],"asks":[],"checksum":2087336145,"timestamp":"2024-06-01T18:06:15.205666Z"}]}
{"channel":"book","type":"update","data":[{"symbol":"ETH/USDT","bids":[{"price":3803.61,"qty":0.00000000},{"price":3802.63,"qty":0.84627249}],"asks":[],"checksum":2815290694,"timestamp":"2024-06-01T18:06:15.211031Z"}]}
{"channel":"book","type":"update","data":[{"symbol":"ETH/USDT","bids":[],"asks":[{"price":3804.39,"qty":0.25000000}],"checksum":2991209123,"timestamp":"2024-06-01T18:06:15.211052Z"}]}
{"channel":"book","type":"update","data":[{"symbol":"ETH/USDT","bids":[],"asks":[{"price":3804.51,"qty":0.00000000},{"price":3804.92,"qty":0.73120000}],"checksum":2925713858,"timestamp":"2024-06-01T18:06:15.211074Z"}]}
{"channel":"book","type":"update","data":[{"symbol":"ETH/USDT","bids":[],"asks":[{"price":3804.53,"qty":0.73120000}],"checksum":561642871,"timestamp":"2024-06-01T18:06:15.214773Z"}]}
{"channel":"book","type":"update","data":[{"symbol":"ETH/USDT","bids":[],"asks":[{"price":3804.34,"qty":0.73120000}],"checksum":848549252,"timestamp":"2024-06-01T18:06:15.214972Z"}]}
{"channel":"book","type":"update","data":[{"symbol":"ETH/USDT","bids":[{"price":3803.01,"qty":0.00000000},{"price":3802.60,"qty":0.22029361}],"asks":[],"checksum":1913659011,"timestamp":"2024-06-01T18:06:15.283877Z"}]}
{"channel":"book","type":"update","data":[{"symbol":"ETH/USDT","bids":[{"price":3803.51,"qty":0.00000000},{"price":3802.57,"qty":0.19869515}],"asks":[],"checksum":1937083128,"timestamp":"2024-06-01T18:06:15.295400Z"}]}
{"channel":"book","type":"update","data":[{"symbol":"ETH/USDT","bids":[{"price":3803.54,"qty":0.00000000},{"price":3802.35,"qty":22.68838534}],"asks":[],"checksum":2426747889,"timestamp":"2024-06-01T18:06:15.298226Z"}]}
{"channel":"book","type":"update","data":[{"symbol":"ETH/USDT","bids":[{"price":3803.10,"qty":0.34000000}],"asks":[],"checksum":8509870,"timestamp":"2024-06-01T18:06:15.298299Z"}]}
{"channel":"book","type":"update","data":[{"symbol":"ETH/USDT","bids":[{"price":3803.11,"qty":2.63163167}],"asks":[],"checksum":2029651192,"timestamp":"2024-06-01T18:06:15.301678Z"}]}
{"channel":"book","type":"update","data":[{"symbol":"ETH/USDT","bids":[],"asks":[{"price":3804.63,"qty":2.63058573}],"checksum":1286770604,"timestamp":"2024-06-01T18:06:15.301694Z"}]}
{"channel":"book","type":"update","data":[{"symbol":"ETH/USDT","bids":[{"price":3803.10,"qty":0.00000000},{"price":3802.57,"qty":0.19869515}],"asks":[],"checksum":1821325209,"timestamp":"2024-06-01T18:06:15.304354Z"}]}
{"channel":"book","type":"update","data":[{"symbol":"ETH/USDT","bids":[{"price":3803.19,"qty":0.34000000}],"asks":[],"checksum":2484218974,"timestamp":"2024-06-01T18:06:15.304471Z"}]}
{"channel":"book","type":"update","data":[{"symbol":"ETH/USDT","bids":[],"asks":[{"price":3804.67,"qty":5.17562574}],"checksum":1310964978,"timestamp":"2024-06-01T18:06:15.328326Z"}]}
{"channel":"book","type":"update","data":[{"symbol":"ETH/USDT","bids":[],"asks":[{"price":3804.40,"qty":1.07120000}],"checksum":1372962567,"timestamp":"2024-06-01T18:06:15.328596Z"}]}
{"channel":"book","type":"update","data":[{"symbol":"ETH/USDT","bids":[],"asks":[{"price":3804.39,"qty":0.00000000},{"price":3804.86,"qty":0.18636949}],"checksum":3560891034,"timestamp":"2024-06-01T18:06:15.333201Z"}]}
{"channel":"book","type":"update","data":[{"symbol":"ETH/USDT","bids":[{"price":3803.12,"qty":5.00000000}],"asks":[],"checksum":2394866604,"timestamp":"2024-06-01T18:06:15.333487Z"}]}
{"channel":"book","type":"update","data":[{"symbol":"ETH/USDT","bids":[{"price":3802.99,"qty":2.11600000}],"asks":[],"checksum":2677322585,"timestamp":"2024-06-01T18:06:15.382367Z"}]}
{"channel":"book","type":"update","data":[{"symbol":"ETH/USDT","bids":[{"price":3803.41,"qty":0.00000000},{"price":3802.63,"qty":0.84627249}],"asks":[],"checksum":3917430917,"timestamp":"2024-06-01T18:06:15.488841Z"}]}
{"channel":"book","type":"update","data":[{"symbol":"ETH/USDT","bids":[{"price":3802.77,"qty":0.00000000},{"price":3802.60,"qty":0.22029361}],"asks":[],"checksum":1761583710,"timestamp":"2024-06-01T18:06:15.494408Z"}]}
{"channel":"book","type":"update","data":[{"symbol":"ETH/USDT","bids":[{"price":3802.84,"qty":0.00000000},{"price":3802.57,"qty":0.19869515}],"asks":[],"checksum":4268381355,"timestamp":"2024-06-01T18:06:15.550471Z"}]}
{"channel":"book","type":"update","data":[{"symbol":"ETH/USDT","bids":[{"price":3802.72,"qty":0.19680926}],"asks":[],"checksum":2149549166,"timestamp":"2024-06-01T18:06:15.590637Z"}]}
{"channel":"book","type":"update","data":[{"symbol":"ETH/USDT","bids":[{"price":3803.18,"qty":0.06693358}],"asks":[],"checksum":4098207559,"timestamp":"2024-06-01T18:06:15.593429Z"}]}
{"channel":"book","type":"update","data":[{"symbol":"ETH/USDT","bids":[],"asks":[{"price":3804.62,"qty":0.02476354}],"checksum":2411180858,"timestamp":"2024-06-01T18:06:16.082194Z"}]}
{"channel":"book","type":"update","data":[{"symbol":"ETH/USDT","bids":[{"price":3803.55,"qty":0.00000000},{"price":3802.60,"qty":0.22029361}],"asks":[],"checksum":3996158502,"timestamp":"2024-06-01T18:06:16.086211Z"}]}
{"channel":"book","type":"update","data":[{"symbol":"ETH/USDT","bids":[{"price":3803.20,"qty":0.25000000}],"asks":[],"checksum":1574706765,"timestamp":"2024-06-01T18:06:16.086365Z"}]}
{"channel":"book","type":"update","data":[{"symbol":"ETH/USDT","bids":[{"price":3803.39,"qty":0.73120000}],"asks":[],"checksum":593509700,"timestamp":"2024-06-01T18:06:16.090267Z"}]}
{"channel":"book","type":"update","data":[{"symbol":"ETH/USDT","bids":[{"price":3803.21,"qty":0.84627249}],"asks":[],"checksum":3859483889,"timestamp":"2024-06-01T18:06:16.092860Z"}]}
{"channel":"book","type":"update","data":[{"symbol":"ETH/USDT","bids":[{"price":3803.20,"qty":0.97912968}],"asks":[],"checksum":413270210,"timestamp":"2024-06-01T18:06:16.094247Z"}]}
{"channel":"book","type":"update","data":[{"symbol":"ETH/USDT","bids":[{"price":3803.19,"qty":0.00000000},{"price":3802.72,"qty":0.19680926}],"asks":[],"checksum":4042602237,"timestamp":"2024-06-01T18:06:16.095468Z"}]}
{"channel":"book","type":"update","data":[{"symbol":"ETH/USDT","bids":[{"price":3803.29,"qty":0.34000000}],"asks":[],"checksum":99151070,"timestamp":"2024-06-01T18:06:16.095716Z"}]}
{"channel":"book","type":"update","data":[{"symbol":"ETH/USDT","bids":[{"price":3803.20,"qty":1.37912968}],"asks":[],"checksum":3306978831,"timestamp":"2024-06-01T18:06:16.128143Z"}]}
{"channel":"book","type":"update","data":[{"symbol":"ETH/USDT","bids":[{"price":3803.20,"qty":0.65000000}],"asks":[],"checksum":739485279,"timestamp":"2024-06-01T18:06:16.131947Z"}]}
{"channel":"book","type":"update","data":[{"symbol":"ETH/USDT","bids":[{"price":3803.40,"qty":0.25000000}],"asks":[],"checksum":1516649115,"timestamp":"2024-06-01T18:06:16.133156Z"}]}
{"channel":"book","type":"update","data":[{"symbol":"ETH/USDT","bids":[{"price":3803.21,"qty":5.84627249}],"asks":[],"checksum":2962182083,"timestamp":"2024-06-01T18:06:16.133172Z"}]}
{"channel":"book","type":"update","data":[{"symbol":"ETH/USDT","bids":[{"price":3803.20,"qty":0.25000000}],"asks":[],"checksum":1142658246,"timestamp":"2024-06-01T18:06:16.160464Z"}]}
{"channel":"book","type":"update","data":[{"symbol":"ETH/USDT","bids":[{"price":3803.21,"qty":0.84627249}],"asks":[],"checksum":2935153054,"timestamp":"2024-06-01T18:06:16.164780Z"}]}
{"channel":"book","type":"update","data":[{"symbol":"ETH/USDT","bids":[{"price":3803.20,"qty":0.00000000},{"price":3802.99,"qty":2.11600000}],"asks":[],"checksum":2242254192,"timestamp":"2024-06-01T18:06:16.164803Z"}]}
{"channel":"book","type":"update","data":[{"symbol":"ETH/USDT","bids":[{"price":3803.21,"qty":0.00000000},{"price":3802.63,"qty":0.84627249}],"asks":[],"checksum":2209806245,"timestamp":"2024-06-01T18:06:16.166562Z"}]}
{"channel":"book","type":"update","data":[{"symbol":"ETH/USDT","bids":[{"price":3802.86,"qty":0.19679989}],"asks":[],"checksum":565157916,"timestamp":"2024-06-01T18:06:16.191902Z"}]}
{"channel":"book","type":"update","data":[{"symbol":"ETH/USDT","bids":[{"price":3803.39,"qty":0.00000000},{"price":3802.63,"qty":0.84627249}],"asks":[],"checksum":368332907,"timestamp":"2024-06-01T18:06:16.207221Z"}]}
{"channel":"book","type":"update","data":[{"symbol":"ETH/USDT","bids":[],"asks":[{"price":3804.52,"qty":0.00000000},{"price":3804.86,"qty":0.18636949}],"checksum":4071226057,"timestamp":"2024-06-01T18:06:16.613486Z"}]}
{"channel":"book","type":"update","data":[{"symbol":"ETH/USDT","bids":[],"asks":[{"price":3804.67,"qty":0.00000000},{"price":3804.92,"qty":0.73120000}],"checksum":3418992710,"timestamp":"2024-06-01T18:06:16.613592Z"}]}
{"channel":"book","type":"update","data":[{"symbol":"ETH/USDT","bids":[],"asks":[{"price":3804.33,"qty":2.07601425}],"checksum":3757004491,"timestamp":"2024-06-01T18:06:16.618632Z"}]}
{"channel":"book","type":"update","data":[{"symbol":"ETH/USDT","bids":[],"asks":[{"price":3804.62,"qty":3.65059488}],"checksum":1239362268,"timestamp":"2024-06-01T18:06:16.618914Z"}]}
{"channel":"book","type":"update","data":[{"symbol":"ETH/USDT","bids":[],"asks":[{"price":3804.40,"qty":0.34000000}],"checksum":629998063,"timestamp":"2024-06-01T18:06:16.622876Z"}]}
{"channel":"book","type":"update","data":[{"symbol":"ETH/USDT","bids":[],"asks":[{"price":3804.14,"qty":0.73120000}],"checksum":2481712665,"timestamp":"2024-06-01T18:06:16.623000Z"}]}
{"channel":"book","type":"update","data":[{"symbol":"ETH/USDT","bids":[{"price":3802.65,"qty":19.37734353}],"asks":[],"checksum":1330302888,"timestamp":"2024-06-01T18:06:16.625644Z"}]}
{"channel":"book","type":"update","data":[{"symbol":"ETH/USDT","bids":[],"asks":[{"price":3804.14,"qty":1.46240000}],"checksum":2861747992,"timestamp":"2024-06-01T18:06:16.626519Z"}]}
{"channel":"book","type":"update","data":[{"symbol":"ETH/USDT","bids":[{"price":3802.99,"qty":0.00000000},{"price":3802.63,"qty":0.84627249}],"asks":[],"checksum":591810055,"timestamp":"2024-06-01T18:06:16.803848Z"}]}
{"channel":"book","type":"update","data":[{"symbol":"ETH/USDT","bids":[{"price":3802.86,"qty":0.00000000},{"price":3802.60,"qty":0.22029361}],"asks":[],"checksum":810517194,"timestamp":"2024-06-01T18:06:16.808341Z"}]}
{"channel":"book","type":"update","data":[{"symbol":"ETH/USDT","bids":[{"price":3802.75,"qty":0.19681972}],"asks":[],"checksum":2037004833,"timestamp":"2024-06-01T18:06:16.848465Z"}]}
{"channel":"book","type":"update","data":[{"symbol":"ETH/USDT","bids":[{"price":3802.79,"qty":2.11600000}],"asks":[],"checksum":2956210998,"timestamp":"2024-06-01T18:06:16.902523Z"}]}
{"channel":"book","type":"update","data":[{"symbol":"ETH/USDT","bids":[{"price":3803.02,"qty":0.00000000},{"price":3802.63,"qty":0.84627249}],"asks":[],"checksum":1830645964,"timestamp":"2024-06-01T18:06:16.944256Z"}]}
{"channel":"book","type":"update","data":[{"symbol":"ETH/USDT","bids":[{"price":3802.79,"qty":0.00000000},{"price":3802.60,"qty":0.22029361}],"asks":[],"checksum":1060280837,"timestamp":"2024-06-01T18:06:16.945164Z"}]}
{"channel":"book","type":"update","data":[{"symbol":"ETH/USDT","bids":[],"asks":[{"price":3804.63,"qty":0.00000000},{"price":3804.86,"qty":0.18636949}],"checksum":4151106167,"timestamp":"2024-06-01T18:06:16.958617Z"}]}
{"channel":"book","type":"update","data":[{"symbol":"ETH/USDT","bids":[],"asks":[{"price":3804.27,"qty":2.63083072}],"checksum":431697911,"timestamp":"2024-06-01T18:06:16.964051Z"}]}
{"channel":"book","type":"update","data":[{"symbol":"ETH/USDT","bids":[{"price":3802.78,"qty":2.11600000}],"asks":[],"checksum":1059963903,"timestamp":"2024-06-01T18:06:17.045125Z"}]}
{"channel":"book","type":"update","data":[{"symbol":"ETH/USDT","bids":[{"price":3803.30,"qty":0.25000000}],"asks":[],"checksum":1723756960,"timestamp":"2024-06-01T18:06:17.088292Z"}]}
{"channel":"book","type":"update","data":[{"symbol":"ETH/USDT","bids":[{"price":3803.40,"qty":0.00000000},{"price":3802.63,"qty":0.84627249}],"asks":[],"checksum":3847543729,"timestamp":"2024-06-01T18:06:17.088306Z"}]}
{"channel":"book","type":"update","data":[{"symbol":"ETH/USDT","bids":[],"asks":[{"price":3804.83,"qty":0.72912968}],"checksum":3323370987,"timestamp":"2024-06-01T18:06:17.091615Z"}]}
{"channel":"book","type":"update","data":[{"symbol":"ETH/USDT","bids":[{"price":3803.12,"qty":0.00000000},{"price":3802.57,"qty":0.19869515}],"asks":[],"checksum":1805159037,"timestamp":"2024-06-01T18:06:17.093412Z"}]}
{"channel":"book","type":"update","data":[{"symbol":"ETH/USDT","bids":[{"price":3803.12,"qty":5.00000000}],"asks":[],"checksum":3323370987,"timestamp":"2024-06-01T18:06:17.209640Z"}]}
{"channel":"book","type":"update","data":[{"symbol":"ETH/USDT","bids":[{"price":3802.75,"qty":0.00000000},{"price":3802.57,"qty":0.19869515}],"asks":[],"checksum":3651119634,"timestamp":"2024-06-01T18:06:17.460199Z"}]}
{"channel":"book","type":"update","data":[{"symbol":"ETH/USDT","bids":[{"price":3802.72,"qty":0.19682380}],"asks":[],"checksum":3725594099,"timestamp":"2024-06-01T18:06:17.500273Z"}]}
{"channel":"book","type":"update","data":[{"symbol":"ETH/USDT","bids":[{"price":3802.72,"qty":0.00000000},{"price":3802.57,"qty":0.19869515}],"asks":[],"checksum":3651119634,"timestamp":"2024-06-01T18:06:18.034826Z"}]}
{"channel":"book","type":"update","data":[{"symbol":"ETH/USDT","bids":[{"price":3802.71,"qty":0.19680845}],"asks":[],"checksum":3566986819,"timestamp":"2024-06-01T18:06:18.074826Z"}]}
{"channel":"book","type":"update","data":[{"symbol":"ETH/USDT","bids":[{"price":3802.71,"qty":0.00000000},{"price":3802.57,"qty":0.19869515}],"asks":[],"checksum":3651119634,"timestamp":"2024-06-01T18:06:18.156936Z"}]}
{"channel":"book","type":"update","data":[{"symbol":"ETH/USDT","bids":[{"price":3802.72,"qty":0.19681251}],"asks":[],"checksum":3905400159,"timestamp":"2024-06-01T18:06:18.197229Z"}]}
{"channel":"book","type":"update","data":[{"symbol":"ETH/USDT","bids":[{"price":3802.78,"qty":0.00000000},{"price":3802.57,"qty":0.19869515}],"asks":[],"checksum":3893743433,"timestamp":"2024-06-01T18:06:18.322557Z"}]}
{"channel":"book","type":"update","data":[{"symbol":"ETH/USDT","bids":[{"price":3803.00,"qty":0.00000000},{"price":3802.53,"qty":0.72912968}],"asks":[],"checksum":66279016,"timestamp":"2024-06-01T18:06:18.323338Z"}]}
{"channel":"book","type":"update","data":[{"symbol":"ETH/USDT","bids":[{"price":3802.91,"qty":0.73120000}],"asks":[],"checksum":1247937245,"timestamp":"2024-06-01T18:06:18.326162Z"}]}
{"channel":"book","type":"update","data":[{"symbol":"ETH/USDT","bids":[{"price":3802.68,"qty":2.11600000}],"asks":[],"checksum":4179510930,"timestamp":"2024-06-01T18:06:18.420982Z"}]}
{"channel":"book","type":"update","data":[{"symbol":"ETH/USDT","bids":[],"asks":[{"price":3804.62,"qty":3.62583134}],"checksum":1194420719,"timestamp":"2024-06-01T18:06:18.631775Z"}]}
{"channel":"book","type":"update","data":[{"symbol":"ETH/USDT","bids":[{"price":3802.72,"qty":0.00000000},{"price":3802.57,"qty":0.19869515}],"asks":[],"checksum":2993886959,"timestamp":"2024-06-01T18:06:18.732374Z"}]}
{"channel":"book","type":"update","data":[{"symbol":"ETH/USDT","bids":[{"price":3802.73,"qty":0.19681192}],"asks":[],"checksum":61023735,"timestamp":"2024-06-01T18:06:18.772404Z"}]}
{"channel":"book","type":"update","data":[{"symbol":"ETH/USDT","bids":[{"price":3802.69,"qty":0.14026700}],"asks":[],"checksum":390963636,"timestamp":"2024-06-01T18:06:18.929563Z"}]}
{"channel":"book","type":"update","data":[{"symbol":"ETH/USDT","bids":[],"asks":[{"price":3804.33,"qty":0.00000000},{"price":3804.85,"qty":0.84627249}],"checksum":3413940704,"timestamp":"2024-06-01T18:06:19.022731Z"}]}
{"channel":"book","type":"update","data":[{"symbol":"ETH/USDT","bids":[],"asks":[{"price":3804.62,"qty":0.00000000},{"price":3804.86,"qty":0.18636949}],"checksum":2643488110,"timestamp":"2024-06-01T18:06:19.022800Z"}]}
{"channel":"book","type":"update","data":[{"symbol":"ETH/USDT","bids":[],"asks":[{"price":3804.13,"qty":1.04280286}],"checksum":3593548935,"timestamp":"2024-06-01T18:06:19.027622Z"}]}
{"channel":"book","type":"update","data":[{"symbol":"ETH/USDT","bids":[],"asks":[{"price":3804.34,"qty":0.00000000},{"price":3804.86,"qty":0.18636949}],"checksum":2053185822,"timestamp":"2024-06-01T18:06:19.031148Z"}]}
{"channel":"book","type":"update","data":[{"symbol":"ETH/USDT","bids":[],"asks":[{"price":3803.96,"qty":0.73120000}],"checksum":1445976306,"timestamp":"2024-06-01T18:06:19.031731Z"}]}
{"channel":"book","type":"update","data":[{"symbol":"ETH/USDT","bids":[],"asks":[{"price":3803.96,"qty":0.00000000},{"price":3804.86,"qty":0.18636949}],"checksum":2053185822,"timestamp":"2024-06-01T18:06:19.168008Z"}]}
{"channel":"book","type":"update","data":[{"symbol":"ETH/USDT","bids":[],"asks":[{"price":3804.04,"qty":0.73120000}],"checksum":2359384789,"timestamp":"2024-06-01T18:06:19.171731Z"}]}
{"channel":"book","type":"update","data":[{"symbol":"ETH/USDT","bids":[{"price":3802.73,"qty":0.00000000},{"price":3802.63,"qty":0.84627249}],"asks":[],"checksum":1569167638,"timestamp":"2024-06-01T18:06:19.382592Z"}]}
{"channel":"book","type":"update","data":[{"symbol":"ETH/USDT","bids":[{"price":3802.72,"qty":0.19685524}],"asks":[],"checksum":3059082162,"timestamp":"2024-06-01T18:06:19.422834Z"}]}
{"channel":"book","type":"update","data":[{"symbol":"ETH/USDT","bids":[{"price":3802.72,"qty":0.00000000},{"price":3802.63,"qty":0.84627249}],"asks":[],"checksum":1569167638,"timestamp":"2024-06-01T18:06:20.087957Z"}]}
{"channel":"book","type":"update","data":[{"symbol":"ETH/USDT","bids":[{"price":3802.71,"qty":0.19689181}],"asks":[],"checksum":3341730679,"timestamp":"2024-06-01T18:06:20.127968Z"}]}
{"channel":"book","type":"update","data":[{"symbol":"ETH/USDT","bids":[{"price":3802.68,"qty":0.00000000},{"price":3802.63,"qty":0.84627249}],"asks":[],"checksum":1188687430,"timestamp":"2024-06-01T18:06:20.132573Z"}]}
{"channel":"book","type":"update","data":[{"symbol":"ETH/USDT","bids":[{"price":3803.11,"qty":0.00000000},{"price":3802.57,"qty":0.19869515}],"asks":[],"checksum":1794369263,"timestamp":"2024-06-01T18:06:20.260040Z"}]}
{"channel":"book","type":"update","data":[{"symbol":"ETH/USDT","bids":[{"price":3802.76,"qty":2.63186902}],"asks":[],"checksum":2114774970,"timestamp":"2024-06-01T18:06:20.265183Z"}]}
{"channel":"book","type":"update","data":[{"symbol":"ETH/USDT","bids":[{"price":3802.91,"qty":0.00000000},{"price":3802.57,"qty":0.19869515}],"asks":[],"checksum":674087223,"timestamp":"2024-06-01T18:06:20.267584Z"}]}
{"channel":"book","type":"update","data":[{"symbol":"ETH/USDT","bids":[{"price":3802.77,"qty":5.00000000}],"asks":[],"checksum":1616429204,"timestamp":"2024-06-01T18:06:20.273127Z"}]}
{"channel":"book","type":"update","data":[{"symbol":"ETH/USDT","bids":[{"price":3803.12,"qty":0.00000000},{"price":3802.57,"qty":0.19869515}],"asks":[],"checksum":11963986,"timestamp":"2024-06-01T18:06:20.273175Z"}]}
{"channel":"book","type":"update","data":[{"symbol":"ETH/USDT","bids":[{"price":3803.29,"qty":0.00000000},{"price":3802.53,"qty":0.72912968}],"asks":[],"checksum":816763020,"timestamp":"2024-06-01T18:06:20.277030Z"}]}
{"channel":"book","type":"update","data":[{"symbol":"ETH/USDT","bids":[{"price":3802.85,"qty":0.34000000}],"asks":[],"checksum":1275699153,"timestamp":"2024-06-01T18:06:20.277119Z"}]}
{"channel":"book","type":"update","data":[{"symbol":"ETH/USDT","bids":[{"price":3803.18,"qty":0.00000000},{"price":3802.53,"qty":0.72912968}],"asks":[],"checksum":3059633202,"timestamp":"2024-06-01T18:06:20.301363Z"}]}
{"channel":"book","type":"update","data":[{"symbol":"ETH/USDT","bids":[],"asks":[{"price":3804.27,"qty":0.00000000},{"price":3804.86,"qty":0.18636949}],"checksum":4139060036,"timestamp":"2024-06-01T18:06:20.329208Z"}]}
{"channel":"book","type":"update","data":[{"symbol":"ETH/USDT","bids":[{"price":3802.65,"qty":0.00000000},{"price":3802.33,"qty":0.73120000}],"asks":[],"checksum":3196518533,"timestamp":"2024-06-01T18:06:20.329651Z"}]}
{"channel":"book","type":"update","data":[{"symbol":"ETH/USDT","bids":[{"price":3802.53,"qty":0.00000000},{"price":3802.27,"qty":0.22029361}],"asks":[],"checksum":2657173993,"timestamp":"2024-06-01T18:06:20.329824Z"}]}
{"channel":"book","type":"update","data":[{"symbol":"ETH/USDT","bids":[{"price":3802.60,"qty":7.01482981}],"asks":[],"checksum":3556446446,"timestamp":"2024-06-01T18:06:20.334506Z"}]}
{"channel":"book","type":"update","data":[{"symbol":"ETH/USDT","bids":[],"asks":[{"price":3804.03,"qty":2.63099579}],"checksum":367466954,"timestamp":"2024-06-01T18:06:20.336491Z"}]}
{"channel":"book","type":"update","data":[{"symbol":"ETH/USDT","bids":[{"price":3802.60,"qty":0.00000000},{"price":3802.27,"qty":0.22029361}],"asks":[],"checksum":2394019795,"timestamp":"2024-06-01T18:06:20.338611Z"}]}
{"channel":"book","type":"update","data":[{"symbol":"ETH/USDT","bids":[],"asks":[{"price":3804.14,"qty":0.73120000}],"checksum":3549768454,"timestamp":"2024-06-01T18:06:20.340906Z"}]}
{"channel":"book","type":"update","data":[{"symbol":"ETH/USDT","bids":[],"asks":[{"price":3804.02,"qty":0.72912968}],"checksum":1771972657,"timestamp":"2024-06-01T18:06:20.341574Z"}]}
{"channel":"book","type":"update","data":[{"symbol":"ETH/USDT","bids":[],"asks":[{"price":3803.84,"qty":0.73120000}],"checksum":1439383611,"timestamp":"2024-06-01T18:06:20.341720Z"}]}
{"channel":"book","type":"update","data":[{"symbol":"ETH/USDT","bids":[{"price":3802.49,"qty":5.92417964}],"asks":[],"checksum":4199468385,"timestamp":"2024-06-01T18:06:20.343337Z"}]}
{"channel":"book","type":"update","data":[{"symbol":"ETH/USDT","bids":[],"asks":[{"price":3804.03,"qty":0.00000000},{"price":3804.83,"qty":0.72912968}],"checksum":3300263822,"timestamp":"2024-06-01T18:06:20.347684Z"}]}
{"channel":"book","type":"update","data":[{"symbol":"ETH/USDT","bids":[{"price":3803.30,"qty":0.00000000},{"price":3802.27,"qty":0.22029361}],"asks":[],"checksum":2773350733,"timestamp":"2024-06-01T18:06:20.362774Z"}]}
{"channel":"book","type":"update","data":[{"symbol":"ETH/USDT","bids":[{"price":3802.86,"qty":0.25000000}],"asks":[],"checksum":2760038801,"timestamp":"2024-06-01T18:06:20.362840Z"}]}
{"channel":"book","type":"update","data":[{"symbol":"ETH/USDT","bids":[{"price":3802.57,"qty":0.00000000},{"price":3802.27,"qty":0.22029361}],"asks":[],"checksum":3818164179,"timestamp":"2024-06-01T18:06:20.363824Z"}]}
{"channel":"book","type":"update","data":[{"symbol":"ETH/USDT","bids":[{"price":3802.37,"qty":0.18307855}],"asks":[],"checksum":4139328459,"timestamp":"2024-06-01T18:06:20.364272Z"}]}
{"channel":"book","type":"update","data":[{"symbol":"ETH/USDT","bids":[{"price":3802.37,"qty":0.00000000},{"price":3802.27,"qty":0.22029361}],"asks":[],"checksum":3818164179,"timestamp":"2024-06-01T18:06:20.371930Z"}]}
{"channel":"book","type":"update","data":[{"symbol":"ETH/USDT","bids":[{"price":3802.49,"qty":0.00000000},{"price":3801.94,"qty":0.00473443}],"asks":[],"checksum":3950774625,"timestamp":"2024-06-01T18:06:20.386539Z"}]}
{"channel":"book","type":"update","data":[{"symbol":"ETH/USDT","bids":[{"price":3802.37,"qty":13.77312712}],"asks":[],"checksum":3698734843,"timestamp":"2024-06-01T18:06:20.390618Z"}]}
{"channel":"book","type":"update","data":[{"symbol":"ETH/USDT","bids":[{"price":3802.78,"qty":0.06693358}],"asks":[],"checksum":401890069,"timestamp":"2024-06-01T18:06:20.405607Z"}]}
{"channel":"book","type":"update","data":[{"symbol":"ETH/USDT","bids":[],"asks":[{"price":3804.83,"qty":0.00000000},{"price":3804.85,"qty":0.84627249}],"checksum":2362818274,"timestamp":"2024-06-01T18:06:20.409723Z"}]}
{"channel":"book","type":"update","data":[{"symbol":"ETH/USDT","bids":[{"price":3802.87,"qty":0.84627249}],"asks":[],"checksum":1265575869,"timestamp":"2024-06-01T18:06:20.411154Z"}]}
{"channel":"book","type":"update","data":[{"symbol":"ETH/USDT","bids":[{"price":3802.85,"qty":0.00000000},{"price":3802.33,"qty":0.73120000}],"asks":[],"checksum":2119671647,"timestamp":"2024-06-01T18:06:20.414043Z"}]}
{"channel":"book","type":"update","data":[{"symbol":"ETH/USDT","bids":[{"price":3802.94,"qty":0.34000000}],"asks":[],"checksum":4119658528,"timestamp":"2024-06-01T18:06:20.414159Z"}]}
{"channel":"book","type":"update","data":[{"symbol":"ETH/USDT","bids":[{"price":3802.42,"qty":2.11600000}],"asks":[],"checksum":1430678313,"timestamp":"2024-06-01T18:06:20.431311Z"}]}
{"channel":"book","type":"update","data":[{"symbol":"ETH/USDT","bids":[{"price":3802.87,"qty":0.00000000},{"price":3802.37,"qty":13.77312712}],"asks":[],"checksum":160002003,"timestamp":"2024-06-01T18:06:20.453173Z"}]}
{"channel":"book","type":"update","data":[{"symbol":"ETH/USDT","bids":[{"price":3802.37,"qty":0.00000000},{"price":3802.33,"qty":0.73120000}],"asks":[],"checksum":3372386278,"timestamp":"2024-06-01T18:06:20.453479Z"}]}
{"channel":"book","type":"update","data":[{"symbol":"ETH/USDT","bids":[{"price":3802.35,"qty":8.58977941}],"asks":[],"checksum":1705096030,"timestamp":"2024-06-01T18:06:20.458081Z"}]}
{"channel":"book","type":"update","data":[{"symbol":"ETH/USDT","bids":[{"price":3802.95,"qty":0.25000000}],"asks":[],"checksum":1643959495,"timestamp":"2024-06-01T18:06:20.469680Z"}]}
{"channel":"book","type":"update","data":[{"symbol":"ETH/USDT","bids":[{"price":3802.86,"qty":0.47000000}],"asks":[],"checksum":367217120,"timestamp":"2024-06-01T18:06:20.512186Z"}]}
{"channel":"book","type":"update","data":[{"symbol":"ETH/USDT","bids":[{"price":3802.86,"qty":0.22000000}],"asks":[],"checksum":1757602848,"timestamp":"2024-06-01T18:06:20.587213Z"}]}
{"channel":"book","type":"update","data":[{"symbol":"ETH/USDT","bids":[{"price":3802.77,"qty":0.00000000},{"price":3802.35,"qty":8.58977941}],"asks":[],"checksum":4097496396,"timestamp":"2024-06-01T18:06:20.592974Z"}]}
{"channel":"book","type":"update","data":[{"symbol":"ETH/USDT","bids":[{"price":3802.86,"qty":0.00000000},{"price":3802.33,"qty":0.73120000}],"asks":[],"checksum":3880757123,"timestamp":"2024-06-01T18:06:20.619713Z"}]}
{"channel":"book","type":"update","data":[{"symbol":"ETH/USDT","bids":[{"price":3802.77,"qty":5.00000000}],"asks":[],"checksum":1074620175,"timestamp":"2024-06-01T18:06:20.625426Z"}]}
{"channel":"book","type":"update","data":[{"symbol":"ETH/USDT","bids":[{"price":3802.71,"qty":0.00000000},{"price":3802.33,"qty":0.73120000}],"asks":[],"checksum":847441672,"timestamp":"2024-06-01T18:06:20.663357Z"}]}
{"channel":"book","type":"update","data":[{"symbol":"ETH/USDT","bids":[{"price":3802.36,"qty":0.19695105}],"asks":[],"checksum":2295506864,"timestamp":"2024-06-01T18:06:20.708753Z"}]}
{"channel":"book","type":"update","data":[{"symbol":"ETH/USDT","bids":[{"price":3802.35,"qty":0.00000000},{"price":3802.33,"qty":0.73120000}],"asks":[],"checksum":43338086,"timestamp":"2024-06-01T18:06:20.825153Z"}]}
{"channel":"book","type":"update","data":[{"symbol":"ETH/USDT","bids":[],"asks":[{"price":3804.63,"qty":0.21867096}],"checksum":2899840090,"timestamp":"2024-06-01T18:06:20.849944Z"}]}
{"channel":"book","type":"update","data":[{"symbol":"ETH/USDT","bids":[],"asks":[{"price":3804.63,"qty":0.00000000},{"price":3804.85,"qty":0.84627249}],"checksum":43338086,"timestamp":"2024-06-01T18:06:20.856653Z"}]}
{"channel":"book","type":"update","data":[{"symbol":"ETH/USDT","bids":[{"price":3802.69,"qty":0.00000000},{"price":3802.29,"qty":9.14342932}],"asks":[],"checksum":1503219517,"timestamp":"2024-06-01T18:06:20.905776Z"}]}
{"channel":"book","type":"update","data":[{"symbol":"ETH/USDT","bids":[{"price":3802.77,"qty":0.00000000},{"price":3802.17,"qty":0.19753935}],"asks":[],"checksum":3887343607,"timestamp":"2024-06-01T18:06:20.907118Z"}]}
{"channel":"book","type":"update","data":[{"symbol":"ETH/USDT","bids":[{"price":3802.95,"qty":0.00000000},{"price":3802.08,"qty":0.72912968}],"asks":[],"checksum":4110729914,"timestamp":"2024-06-01T18:06:20.907396Z"}]}
{"channel":"book","type":"update","data":[{"symbol":"ETH/USDT","bids":[{"price":3802.29,"qty":0.00000000},{"price":3801.94,"qty":0.00473443}],"asks":[],"checksum":2812369697,"timestamp":"2024-06-01T18:06:20.907905Z"}]}
{"channel":"book","type":"update","data":[{"symbol":"ETH/USDT","bids":[],"asks":[{"price":3803.83,"qty":2.63113412}],"checksum":400585447,"timestamp":"2024-06-01T18:06:20.909251Z"}]}
{"channel":"book","type":"update","data":[{"symbol":"ETH/USDT","bids":[],"asks":[{"price":3804.40,"qty":0.00000000},{"price":3804.85,"qty":0.84627249}],"checksum":200109950,"timestamp":"2024-06-01T18:06:20.910239Z"}]}
{"channel":"book","type":"update","data":[{"symbol":"ETH/USDT","bids":[],"asks":[{"price":3804.02,"qty":1.06912968}],"checksum":3799641710,"timestamp":"2024-06-01T18:06:20.910651Z"}]}
{"channel":"book","type":"update","data":[{"symbol":"ETH/USDT","bids":[{"price":3802.24,"qty":9.14354955}],"asks":[],"checksum":4206376551,"timestamp":"2024-06-01T18:06:20.912040Z"}]}
{"channel":"book","type":"update","data":[{"symbol":"ETH/USDT","bids":[],"asks":[{"price":3803.64,"qty":0.73120000}],"checksum":2893031445,"timestamp":"2024-06-01T18:06:20.912847Z"}]}
{"channel":"book","type":"update","data":[{"symbol":"ETH/USDT","bids":[],"asks":[{"price":3804.04,"qty":0.00000000},{"price":3804.85,"qty":0.84627249}],"checksum":3069688585,"timestamp":"2024-06-01T18:06:20.914104Z"}]}
{"channel":"book","type":"update","data":[{"symbol":"ETH/USDT","bids":[],"asks":[{"price":3803.64,"qty":1.46240000}],"checksum":2335724792,"timestamp":"2024-06-01T18:06:20.917217Z"}]}
{"channel":"book","type":"update","data":[{"symbol":"ETH/USDT","bids":[{"price":3802.76,"qty":0.00000000},{"price":3801.94,"qty":0.00473443}],"asks":[],"checksum":212954615,"timestamp":"2024-06-01T18:06:20.918265Z"}]}
{"channel":"book","type":"update","data":[{"symbol":"ETH/USDT","bids":[{"price":3802.41,"qty":2.63211146}],"asks":[],"checksum":564784346,"timestamp":"2024-06-01T18:06:20.922892Z"}]}
{"channel":"book","type":"update","data":[{"symbol":"ETH/USDT","bids":[{"price":3802.94,"qty":0.00000000},{"price":3801.94,"qty":0.00473443}],"asks":[],"checksum":1931124022,"timestamp":"2024-06-01T18:06:20.923404Z"}]}
{"channel":"book","type":"update","data":[{"symbol":"ETH/USDT","bids":[{"price":3802.71,"qty":0.34000000}],"asks":[],"checksum":1181849832,"timestamp":"2024-06-01T18:06:20.923672Z"}]}
{"channel":"book","type":"update","data":[{"symbol":"ETH/USDT","bids":[],"asks":[{"price":3804.68,"qty":0.00000000},{"price":3804.92,"qty":0.73120000}],"checksum":1354972887,"timestamp":"2024-06-01T18:06:20.929350Z"}]}
{"channel":"book","type":"update","data":[{"symbol":"ETH/USDT","bids":[],"asks":[{"price":3803.85,"qty":2.11600000}],"checksum":2768874740,"timestamp":"2024-06-01T18:06:20.931564Z"}]}
{"channel":"book","type":"update","data":[{"symbol":"ETH/USDT","bids":[{"price":3802.79,"qty":0.84627249}],"asks":[],"checksum":756952182,"timestamp":"2024-06-01T18:06:20.936644Z"}]}
{"channel":"book","type":"update","data":[{"symbol":"ETH/USDT","bids":[{"price":3802.63,"qty":0.00000000},{"price":3802.08,"qty":0.72912968}],"asks":[],"checksum":851222888,"timestamp":"2024-06-01T18:06:20.952323Z"}]}
{"channel":"book","type":"update","data":[{"symbol":"ETH/USDT","bids":[{"price":3802.71,"qty":0.00000000},{"price":3801.94,"qty":0.00473443}],"asks":[],"checksum":932009042,"timestamp":"2024-06-01T18:06:20.955259Z"}]}
{"channel":"book","type":"update","data":[{"symbol":"ETH/USDT","bids":[{"price":3802.50,"qty":0.34000000}],"asks":[],"checksum":1942496831,"timestamp":"2024-06-01T18:06:20.955398Z"}]}
{"channel":"book","type":"update","data":[{"symbol":"ETH/USDT","bids":[{"price":3802.78,"qty":0.00000000},{"price":3801.94,"qty":0.00473443}],"asks":[],"checksum":4224730739,"timestamp":"2024-06-01T18:06:20.975347Z"}]}
{"channel":"book","type":"update","data":[{"symbol":"ETH/USDT","bids":[],"asks":[{"price":3804.58,"qty":0.19694357}],"checksum":928167956,"timestamp":"2024-06-01T18:06:21.001843Z"}]}
{"channel":"book","type":"update","data":[{"symbol":"ETH/USDT","bids":[],"asks":[{"price":3804.58,"qty":0.00000000},{"price":3804.85,"qty":0.84627249}],"checksum":4224730739,"timestamp":"2024-06-01T18:06:21.008532Z"}]}
{"channel":"book","type":"update","data":[{"symbol":"ETH/USDT","bids":[],"asks":[{"price":3804.10,"qty":0.06693358}],"checksum":3101504598,"timestamp":"2024-06-01T18:06:21.017153Z"}]}
{"channel":"book","type":"update","data":[{"symbol":"ETH/USDT","bids":[{"price":3802.67,"qty":0.06693358}],"asks":[],"checksum":1185171531,"timestamp":"2024-06-01T18:06:21.079296Z"}]}
{"channel":"book","type":"update","data":[{"symbol":"ETH/USDT","bids":[{"price":3802.36,"qty":0.00000000},{"price":3801.94,"qty":0.00473443}],"asks":[],"checksum":1440363367,"timestamp":"2024-06-01T18:06:21.317955Z"}]}
{"channel":"book","type":"update","data":[{"symbol":"ETH/USDT","bids":[],"asks":[{"price":3804.14,"qty":0.00000000},{"price":3804.58,"qty":0.20343388}],"checksum":2113152859,"timestamp":"2024-06-01T18:06:21.337839Z"}]}
{"channel":"book","type":"update","data":[{"symbol":"ETH/USDT","bids":[{"price":3802.28,"qty":0.19697642}],"asks":[],"checksum":3058910438,"timestamp":"2024-06-01T18:06:21.358298Z"}]}
{"channel":"book","type":"update","data":[{"symbol":"ETH/USDT","bids":[{"price":3802.24,"qty":0.00000000},{"price":3801.94,"qty":0.00473443}],"asks":[],"checksum":2042186367,"timestamp":"2024-06-01T18:06:21.382864Z"}]}
{"channel":"book","type":"update","data":[{"symbol":"ETH/USDT","bids":[{"price":3802.79,"qty":0.00000000},{"price":3801.88,"qty":0.22029361}],"asks":[],"checksum":3003823159,"timestamp":"2024-06-01T18:06:21.383996Z"}]}
{"channel":"book","type":"update","data":[{"symbol":"ETH/USDT","bids":[{"price":3802.09,"qty":9.14391029}],"asks":[],"checksum":2845736248,"timestamp":"2024-06-01T18:06:21.386668Z"}]}
{"channel":"book","type":"update","data":[{"symbol":"ETH/USDT","bids":[{"price":3802.10,"qty":0.00542412}],"asks":[],"checksum":1435891986,"timestamp":"2024-06-01T18:06:21.392062Z"}]}
{"channel":"book","type":"update","data":[{"symbol":"ETH/USDT","bids":[],"asks":[{"price":3804.13,"qty":0.00000000},{"price":3804.67,"qty":0.01501332}],"checksum":3014905792,"timestamp":"2024-06-01T18:06:21.406211Z"}]}
{"channel":"book","type":"update","data":[{"symbol":"ETH/USDT","bids":[{"price":3802.10,"qty":0.00000000},{"price":3801.94,"qty":0.00473443}],"asks":[],"checksum":1337478122,"timestamp":"2024-06-01T18:06:21.409278Z"}]}
{"channel":"book","type":"update","data":[{"symbol":"ETH/USDT","bids":[{"price":3802.17,"qty":0.00000000},{"price":3801.88,"qty":0.22029361}],"asks":[],"checksum":196970247,"timestamp":"2024-06-01T18:06:21.410151Z"}]}
{"channel":"book","type":"update","data":[{"symbol":"ETH/USDT","bids":[{"price":3801.92,"qty":0.18325699}],"asks":[],"checksum":409249034,"timestamp":"2024-06-01T18:06:21.410900Z"}]}
{"channel":"book","type":"update","data":[{"symbol":"ETH/USDT","bids":[{"price":3802.67,"qty":0.00000000},{"price":3801.88,"qty":0.22029361}],"asks":[],"checksum":449684333,"timestamp":"2024-06-01T18:06:21.449033Z"}]}
{"channel":"book","type":"update","data":[{"symbol":"ETH/USDT","bids":[{"price":3802.51,"qty":0.48000000}],"asks":[],"checksum":119489518,"timestamp":"2024-06-01T18:06:21.480086Z"}]}
{"channel":"book","type":"update","data":[{"symbol":"ETH/USDT","bids":[{"price":3802.50,"qty":0.00000000},{"price":3801.88,"qty":0.22029361}],"asks":[],"checksum":1730971336,"timestamp":"2024-06-01T18:06:21.482771Z"}]}
{"channel":"book","type":"update","data":[{"symbol":"ETH/USDT","bids":[{"price":3802.59,"qty":0.34000000}],"asks":[],"checksum":1612881196,"timestamp":"2024-06-01T18:06:21.483081Z"}]}
{"channel":"book","type":"update","data":[{"symbol":"ETH/USDT","bids":[{"price":3802.52,"qty":0.84627249}],"asks":[],"checksum":3817203593,"timestamp":"2024-06-01T18:06:21.484988Z"}]}
{"channel":"book","type":"update","data":[{"symbol":"ETH/USDT","bids":[{"price":3802.40,"qty":0.06693358}],"asks":[],"checksum":3106873203,"timestamp":"2024-06-01T18:06:21.553220Z"}]}
{"channel":"book","type":"update","data":[{"symbol":"ETH/USDT","bids":[{"price":3802.51,"qty":0.00000000},{"price":3801.94,"qty":0.00473443}],"asks":[],"checksum":1454506813,"timestamp":"2024-06-01T18:06:21.598126Z"}]}
{"channel":"book","type":"update","data":[{"symbol":"ETH/USDT","bids":[{"price":3802.60,"qty":0.84627249}],"asks":[],"checksum":190462134,"timestamp":"2024-06-01T18:06:21.603211Z"}]}
{"channel":"book","type":"update","data":[{"symbol":"ETH/USDT","bids":[{"price":3802.59,"qty":0.00000000},{"price":3801.94,"qty":0.00473443}],"asks":[],"checksum":3876207887,"timestamp":"2024-06-01T18:06:21.606382Z"}]}
{"channel":"book","type":"update","data":[{"symbol":"ETH/USDT","bids":[{"price":3802.68,"qty":0.34000000}],"asks":[],"checksum":3346759260,"timestamp":"2024-06-01T18:06:21.606541Z"}]}
{"channel":"book","type":"update","data":[{"symbol":"ETH/USDT","bids":[{"price":3802.28,"qty":0.00000000},{"price":3801.94,"qty":0.00473443}],"asks":[],"checksum":3889433736,"timestamp":"2024-06-01T18:06:21.899524Z"}]}
{"channel":"book","type":"update","data":[{"symbol":"ETH/USDT","bids":[{"price":3802.08,"qty":0.92614698}],"asks":[],"checksum":1507785992,"timestamp":"2024-06-01T18:06:21.940043Z"}]}
{"channel":"book","type":"update","data":[{"symbol":"ETH/USDT","bids":[{"price":3802.60,"qty":0.00000000},{"price":3801.92,"qty":0.18325699}],"asks":[],"checksum":658262300,"timestamp":"2024-06-01T18:06:21.952317Z"}]}
{"channel":"book","type":"update","data":[{"symbol":"ETH/USDT","bids":[{"price":3802.43,"qty":5.00000000}],"asks":[],"checksum":1027601871,"timestamp":"2024-06-01T18:06:22.207942Z"}]}
{"channel":"book","type":"update","data":[{"symbol":"ETH/USDT","bids":[{"price":3802.69,"qty":0.25000000}],"asks":[],"checksum":2638454252,"timestamp":"2024-06-01T18:06:22.212800Z"}]}
{"channel":"book","type":"update","data":[{"symbol":"ETH/USDT","bids":[{"price":3802.08,"qty":0.72912968}],"asks":[],"checksum":3492821285,"timestamp":"2024-06-01T18:06:22.410898Z"}]}
{"channel":"book","type":"update","data":[{"symbol":"ETH/USDT","bids":[{"price":3802.11,"qty":0.19701874}],"asks":[],"checksum":1594660853,"timestamp":"2024-06-01T18:06:22.451229Z"}]}
{"channel":"book","type":"update","data":[{"symbol":"ETH/USDT","bids":[{"price":3802.11,"qty":0.00000000},{"price":3802.08,"qty":0.72912968}],"asks":[],"checksum":3492821285,"timestamp":"2024-06-01T18:06:22.987642Z"}]}
{"channel":"book","type":"update","data":[{"symbol":"ETH/USDT","bids":[{"price":3802.10,"qty":0.19702024}],"asks":[],"checksum":2659202811,"timestamp":"2024-06-01T18:06:23.028783Z"}]}
{"channel":"book","type":"update","data":[{"symbol":"ETH/USDT","bids":[{"price":3802.42,"qty":0.00000000},{"price":3802.08,"qty":0.72912968}],"asks":[],"checksum":1797123284,"timestamp":"2024-06-01T18:06:23.499642Z"}]}
{"channel":"book","type":"update","data":[{"symbol":"ETH/USDT","bids":[{"price":3802.42,"qty":5.00000000}],"asks":[],"checksum":2514245499,"timestamp":"2024-06-01T18:06:23.505539Z"}]}
{"channel":"book","type":"update","data":[{"symbol":"ETH/USDT","bids":[{"price":3802.43,"qty":0.00000000},{"price":3802.08,"qty":0.72912968}],"asks":[],"checksum":226487672,"timestamp":"2024-06-01T18:06:23.505558Z"}]}
{"channel":"book","type":"update","data":[{"symbol":"ETH/USDT","bids":[],"asks":[{"price":3803.63,"qty":0.52627463}],"checksum":1242690099,"timestamp":"2024-06-01T18:06:23.672757Z"}]}
{"channel":"book","type":"update","data":[{"symbol":"ETH/USDT","bids":[],"asks":[{"price":3803.44,"qty":0.73120000}],"checksum":582032440,"timestamp":"2024-06-01T18:06:23.676401Z"}]}
{"channel":"book","type":"update","data":[{"symbol":"ETH/USDT","bids":[],"asks":[{"price":3803.84,"qty":0.00000000},{"price":3804.58,"qty":0.20343388}],"checksum":401359880,"timestamp":"2024-06-01T18:06:23.676967Z"}]}
{"channel":"book","type":"update","data":[{"symbol":"ETH/USDT","bids":[{"price":3802.09,"qty":0.00000000},{"price":3801.94,"qty":0.00473443}],"asks":[],"checksum":4054638123,"timestamp":"2024-06-01T18:06:23.724023Z"}]}
{"channel":"book","type":"update","data":[{"symbol":"ETH/USDT","bids":[{"price":3802.04,"qty":9.14403054}],"asks":[],"checksum":2813869768,"timestamp":"2024-06-01T18:06:23.727974Z"}]}
{"channel":"book","type":"update","data":[{"symbol":"ETH/USDT","bids":[{"price":3802.04,"qty":0.00000000},{"price":3801.94,"qty":0.00473443}],"asks":[],"checksum":4054638123,"timestamp":"2024-06-01T18:06:23.728096Z"}]}
{"channel":"book","type":"update","data":[{"symbol":"ETH/USDT","bids":[{"price":3802.52,"qty":0.00000000},{"price":3801.92,"qty":0.18325699}],"asks":[],"checksum":4210366471,"timestamp":"2024-06-01T18:06:23.728183Z"}]}
{"channel":"book","type":"update","data":[{"symbol":"ETH/USDT","bids":[{"price":3802.05,"qty":0.00534478}],"asks":[],"checksum":1027649536,"timestamp":"2024-06-01T18:06:23.733147Z"}]}
{"channel":"book","type":"update","data":[{"symbol":"ETH/USDT","bids":[{"price":3802.05,"qty":0.00000000},{"price":3801.92,"qty":0.18325699}],"asks":[],"checksum":4210366471,"timestamp":"2024-06-01T18:06:23.749530Z"}]}
{"channel":"book","type":"update","data":[{"symbol":"ETH/USDT","bids":[],"asks":[{"price":3804.58,"qty":0.00000000},{"price":3804.83,"qty":0.52933494}],"checksum":3256903685,"timestamp":"2024-06-01T18:06:23.750080Z"}]}
{"channel":"book","type":"update","data":[{"symbol":"ETH/USDT","bids":[],"asks":[{"price":3804.38,"qty":0.19080047}],"checksum":116899294,"timestamp":"2024-06-01T18:06:23.753186Z"}]}
{"channel":"book","type":"update","data":[{"symbol":"ETH/USDT","bids":[],"asks":[{"price":3804.38,"qty":0.00000000},{"price":3804.83,"qty":0.52933494}],"checksum":3256903685,"timestamp":"2024-06-01T18:06:23.759421Z"}]}
{"channel":"book","type":"update","data":[{"symbol":"ETH/USDT","bids":[{"price":3802.33,"qty":0.00000000},{"price":3801.91,"qty":9.14434320}],"asks":[],"checksum":1913583138,"timestamp":"2024-06-01T18:06:23.802135Z"}]}
{"channel":"book","type":"update","data":[{"symbol":"ETH/USDT","bids":[{"price":3802.30,"qty":0.73120000}],"asks":[],"checksum":871749473,"timestamp":"2024-06-01T18:06:23.806489Z"}]}
{"channel":"book","type":"update","data":[{"symbol":"ETH/USDT","bids":[{"price":3801.92,"qty":0.18830953}],"asks":[],"checksum":347086607,"timestamp":"2024-06-01T18:06:23.806805Z"}]}
{"channel":"book","type":"update","data":[{"symbol":"ETH/USDT","bids":[{"price":3802.40,"qty":0.00000000},{"price":3801.91,"qty":9.14434320}],"asks":[],"checksum":892100768,"timestamp":"2024-06-01T18:06:23.863719Z"}]}
{"channel":"book","type":"update","data":[{"symbol":"ETH/USDT","bids":[],"asks":[{"price":3804.03,"qty":0.25000000}],"checksum":2370626301,"timestamp":"2024-06-01T18:06:23.868555Z"}]}
{"channel":"book","type":"update","data":[{"symbol":"ETH/USDT","bids":[],"asks":[{"price":3804.40,"qty":0.84627249}],"checksum":74495143,"timestamp":"2024-06-01T18:06:23.869495Z"}]}
{"channel":"book","type":"update","data":[{"symbol":"ETH/USDT","bids":[{"price":3802.11,"qty":0.84627249}],"asks":[],"checksum":302501838,"timestamp":"2024-06-01T18:06:23.869514Z"}]}
{"channel":"book","type":"update","data":[{"symbol":"ETH/USDT","bids":[],"asks":[{"price":3804.25,"qty":0.21675121}],"checksum":2491439127,"timestamp":"2024-06-01T18:06:23.900157Z"}]}
{"channel":"book","type":"update","data":[{"symbol":"ETH/USDT","bids":[],"asks":[{"price":3804.25,"qty":0.00000000},{"price":3804.53,"qty":0.73120000}],"checksum":302501838,"timestamp":"2024-06-01T18:06:23.906014Z"}]}
{"channel":"book","type":"update","data":[{"symbol":"ETH/USDT","bids":[{"price":3802.41,"qty":2.69904504}],"asks":[],"checksum":3339023820,"timestamp":"2024-06-01T18:06:23.915178Z"}]}
{"channel":"book","type":"update","data":[{"symbol":"ETH/USDT","bids":[{"price":3802.10,"qty":0.00000000},{"price":3801.91,"qty":9.14434320}],"asks":[],"checksum":189121846,"timestamp":"2024-06-01T18:06:24.040777Z"}]}
{"channel":"book","type":"update","data":[{"symbol":"ETH/USDT","bids":[],"asks":[{"price":3804.25,"qty":0.18272672}],"checksum":177897121,"timestamp":"2024-06-01T18:06:24.050098Z"}]}
{"channel":"book","type":"update","data":[{"symbol":"ETH/USDT","bids":[],"asks":[{"price":3804.25,"qty":0.00000000},{"price":3804.53,"qty":0.73120000}],"checksum":189121846,"timestamp":"2024-06-01T18:06:24.056947Z"}]}
{"channel":"book","type":"update","data":[{"symbol":"ETH/USDT","bids":[{"price":3802.00,"qty":0.19704525}],"asks":[],"checksum":3773433212,"timestamp":"2024-06-01T18:06:24.081100Z"}]}
{"channel":"book","type":"update","data":[{"symbol":"ETH/USDT","bids":[],"asks":[{"price":3804.25,"qty":0.18954906}],"checksum":3879060417,"timestamp":"2024-06-01T18:06:24.200186Z"}]}
{"channel":"book","type":"update","data":[{"symbol":"ETH/USDT","bids":[],"asks":[{"price":3804.25,"qty":0.00000000},{"price":3804.53,"qty":0.73120000}],"checksum":3773433212,"timestamp":"2024-06-01T18:06:24.206880Z"}]}
{"channel":"book","type":"update","data":[{"symbol":"ETH/USDT","bids":[],"asks":[{"price":3804.25,"qty":0.21210871}],"checksum":812722427,"timestamp":"2024-06-01T18:06:24.350425Z"}]}
{"channel":"book","type":"update","data":[{"symbol":"ETH/USDT","bids":[],"asks":[{"price":3804.25,"qty":0.00000000},{"price":3804.53,"qty":0.73120000}],"checksum":3773433212,"timestamp":"2024-06-01T18:06:24.356721Z"}]}
{"channel":"book","type":"update","data":[{"symbol":"ETH/USDT","bids":[],"asks":[{"price":3804.25,"qty":0.20792639}],"checksum":2872449585,"timestamp":"2024-06-01T18:06:24.499623Z"}]}
{"channel":"book","type":"update","data":[{"symbol":"ETH/USDT","bids":[],"asks":[{"price":3804.25,"qty":0.00000000},{"price":3804.53,"qty":0.73120000}],"checksum":3773433212,"timestamp":"2024-06-01T18:06:24.506903Z"}]}
{"channel":"book","type":"update","data":[{"symbol":"ETH/USDT","bids":[],"asks":[{"price":3804.25,"qty":0.18333161}],"checksum":1158134455,"timestamp":"2024-06-01T18:06:24.651295Z"}]}
{"channel":"book","type":"update","data":[{"symbol":"ETH/USDT","bids":[],"asks":[{"price":3804.25,"qty":0.00000000},{"price":3804.53,"qty":0.73120000}],"checksum":3773433212,"timestamp":"2024-06-01T18:06:24.664420Z"}]}
{"channel":"book","type":"update","data":[{"symbol":"ETH/USDT","bids":[{"price":3802.00,"qty":0.00000000},{"price":3801.91,"qty":9.14434320}],"asks":[],"checksum":189121846,"timestamp":"2024-06-01T18:06:24.695841Z"}]}
{"channel":"book","type":"update","data":[{"symbol":"ETH/USDT","bids":[{"price":3801.99,"qty":0.19704277}],"asks":[],"checksum":1922883388,"timestamp":"2024-06-01T18:06:24.736271Z"}]}
{"channel":"book","type":"update","data":[{"symbol":"ETH/USDT","bids":[],"asks":[{"price":3804.25,"qty":0.21717648}],"checksum":3189651514,"timestamp":"2024-06-01T18:06:24.799751Z"}]}
{"channel":"book","type":"update","data":[{"symbol":"ETH/USDT","bids":[],"asks":[{"price":3804.25,"qty":0.00000000},{"price":3804.53,"qty":0.73120000}],"checksum":1922883388,"timestamp":"2024-06-01T18:06:24.806036Z"}]}
{"channel":"book","type":"update","data":[{"symbol":"ETH/USDT","bids":[],"asks":[{"price":3804.25,"qty":0.21721511}],"checksum":3546255634,"timestamp":"2024-06-01T18:06:24.950512Z"}]}
{"channel":"book","type":"update","data":[{"symbol":"ETH/USDT","bids":[],"asks":[{"price":3804.25,"qty":0.00000000},{"price":3804.53,"qty":0.73120000}],"checksum":1922883388,"timestamp":"2024-06-01T18:06:24.959261Z"}]}
{"channel":"book","type":"update","data":[{"symbol":"ETH/USDT","bids":[],"asks":[{"price":3804.25,"qty":0.20470001}],"checksum":4281490477,"timestamp":"2024-06-01T18:06:25.099624Z"}]}
{"channel":"book","type":"update","data":[{"symbol":"ETH/USDT","bids":[],"asks":[{"price":3804.25,"qty":0.00000000},{"price":3804.53,"qty":0.73120000}],"checksum":1922883388,"timestamp":"2024-06-01T18:06:25.107664Z"}]}
{"channel":"book","type":"update","data":[{"symbol":"ETH/USDT","bids":[],"asks":[{"price":3804.25,"qty":0.18780159}],"checksum":698204760,"timestamp":"2024-06-01T18:06:25.249647Z"}]}
{"channel":"book","type":"update","data":[{"symbol":"ETH/USDT","bids":[],"asks":[{"price":3804.25,"qty":0.00000000},{"price":3804.53,"qty":0.73120000}],"checksum":1922883388,"timestamp":"2024-06-01T18:06:25.257775Z"}]}
{"channel":"book","type":"update","data":[{"symbol":"ETH/USDT","bids":[],"asks":[{"price":3804.25,"qty":0.21737763}],"checksum":1146021392,"timestamp":"2024-06-01T18:06:25.401980Z"}]}
{"channel":"book","type":"update","data":[{"symbol":"ETH/USDT","bids":[],"asks":[{"price":3804.25,"qty":0.00000000},{"price":3804.53,"qty":0.73120000}],"checksum":1922883388,"timestamp":"2024-06-01T18:06:25.410179Z"}]}
{"channel":"book","type":"update","data":[{"symbol":"ETH/USDT","bids":[{"price":3802.08,"qty":0.00000000},{"price":3801.91,"qty":9.14434320}],"asks":[],"checksum":3353330188,"timestamp":"2024-06-01T18:06:25.437950Z"}]}
{"channel":"book","type":"update","data":[{"symbol":"ETH/USDT","bids":[{"price":3802.30,"qty":0.00000000},{"price":3801.76,"qty":2.11600000}],"asks":[],"checksum":3901653674,"timestamp":"2024-06-01T18:06:25.441662Z"}]}
{"channel":"book","type":"update","data":[{"symbol":"ETH/USDT","bids":[],"asks":[{"price":3803.83,"qty":0.00000000},{"price":3804.77,"qty":5.00000000}],"checksum":3809453181,"timestamp":"2024-06-01T18:06:25.446661Z"}]}
{"channel":"book","type":"update","data":[{"symbol":"ETH/USDT","bids":[{"price":3802.41,"qty":0.06693358}],"asks":[],"checksum":1756273410,"timestamp":"2024-06-01T18:06:25.450165Z"}]}
{"channel":"book","type":"update","data":[{"symbol":"ETH/USDT","bids":[],"asks":[{"price":3803.48,"qty":2.63137536}],"checksum":1335257577,"timestamp":"2024-06-01T18:06:25.455229Z"}]}
{"channel":"book","type":"update","data":[{"symbol":"ETH/USDT","bids":[{"price":3802.05,"qty":2.63236034}],"asks":[],"checksum":853134966,"timestamp":"2024-06-01T18:06:25.455365Z"}]}
{"channel":"book","type":"update","data":[{"symbol":"ETH/USDT","bids":[{"price":3802.42,"qty":0.00000000},{"price":3801.76,"qty":2.11600000}],"asks":[],"checksum":3450273825,"timestamp":"2024-06-01T18:06:25.472619Z"}]}
{"channel":"book","type":"update","data":[{"symbol":"ETH/USDT","bids":[{"price":3801.91,"qty":0.00000000},{"price":3801.67,"qty":0.73120000}],"asks":[],"checksum":2526505103,"timestamp":"2024-06-01T18:06:25.474167Z"}]}
{"channel":"book","type":"update","data":[{"symbol":"ETH/USDT","bids":[{"price":3802.68,"qty":0.00000000},{"price":3801.54,"qty":0.22029361}],"asks":[],"checksum":423433791,"timestamp":"2024-06-01T18:06:25.475667Z"}]}
{"channel":"book","type":"update","data":[{"symbol":"ETH/USDT","bids":[{"price":3802.48,"qty":0.34000000}],"asks":[],"checksum":2483263326,"timestamp":"2024-06-01T18:06:25.475803Z"}]}
{"channel":"book","type":"update","data":[{"symbol":"ETH/USDT","bids":[],"asks":[{"price":3803.48,"qty":0.00000000},{"price":3804.77,"qty":5.00000000}],"checksum":2930824751,"timestamp":"2024-06-01T18:06:25.476835Z"}]}
{"channel":"book","type":"update","data":[{"symbol":"ETH/USDT","bids":[{"price":3801.80,"qty":9.14460778}],"asks":[],"checksum":388549590,"timestamp":"2024-06-01T18:06:25.478381Z"}]}
{"channel":"book","type":"update","data":[{"symbol":"ETH/USDT","bids":[{"price":3801.92,"qty":0.18325699}],"asks":[],"checksum":1848363380,"timestamp":"2024-06-01T18:06:25.478398Z"}]}
{"channel":"book","type":"update","data":[{"symbol":"ETH/USDT","bids":[],"asks":[{"price":3804.02,"qty":0.72912968}],"checksum":2611506857,"timestamp":"2024-06-01T18:06:25.479471Z"}]}
{"channel":"book","type":"update","data":[{"symbol":"ETH/USDT","bids":[{"price":3802.30,"qty":0.73120000}],"asks":[],"checksum":71097768,"timestamp":"2024-06-01T18:06:25.479689Z"}]}
{"channel":"book","type":"update","data":[{"symbol":"ETH/USDT","bids":[],"asks":[{"price":3803.61,"qty":0.34000000}],"checksum":3993696954,"timestamp":"2024-06-01T18:06:25.479902Z"}]}
{"channel":"book","type":"update","data":[{"symbol":"ETH/USDT","bids":[],"asks":[{"price":3804.39,"qty":2.63074886}],"checksum":2272099775,"timestamp":"2024-06-01T18:06:25.481736Z"}]}
{"channel":"book","type":"update","data":[{"symbol":"ETH/USDT","bids":[{"price":3802.41,"qty":0.00000000},{"price":3801.76,"qty":2.11600000}],"asks":[],"checksum":591812988,"timestamp":"2024-06-01T18:06:25.491083Z"}]}
{"channel":"book","type":"update","data":[{"symbol":"ETH/USDT","bids":[{"price":3801.92,"qty":0.00000000},{"price":3801.67,"qty":0.73120000}],"asks":[],"checksum":3365454737,"timestamp":"2024-06-01T18:06:25.497961Z"}]}
{"channel":"book","type":"update","data":[{"symbol":"ETH/USDT","bids":[{"price":3801.70,"qty":0.21841364}],"asks":[],"checksum":3754345696,"timestamp":"2024-06-01T18:06:25.501819Z"}]}
{"channel":"book","type":"update","data":[{"symbol":"ETH/USDT","bids":[{"price":3801.70,"qty":0.00000000},{"price":3801.67,"qty":0.73120000}],"asks":[],"checksum":3365454737,"timestamp":"2024-06-01T18:06:25.511096Z"}]}
{"channel":"book","type":"update","data":[{"symbol":"ETH/USDT","bids":[{"price":3802.30,"qty":0.00000000},{"price":3801.54,"qty":0.22029361}],"asks":[],"checksum":2029292340,"timestamp":"2024-06-01T18:06:25.511294Z"}]}
{"channel":"book","type":"update","data":[{"symbol":"ETH/USDT","bids":[{"price":3802.48,"qty":0.00000000},{"price":3801.27,"qty":40.44212640}],"asks":[],"checksum":1127096747,"timestamp":"2024-06-01T18:06:25.513874Z"}]}
{"channel":"book","type":"update","data":[{"symbol":"ETH/USDT","bids":[{"price":3802.19,"qty":0.34000000}],"asks":[],"checksum":3954968582,"timestamp":"2024-06-01T18:06:25.514054Z"}]}
{"channel":"book","type":"update","data":[{"symbol":"ETH/USDT","bids":[{"price":3802.69,"qty":0.00000000},{"price":3801.27,"qty":40.44212640}],"asks":[],"checksum":3575664304,"timestamp":"2024-06-01T18:06:25.516345Z"}]}
{"channel":"book","type":"update","data":[{"symbol":"ETH/USDT","bids":[{"price":3802.49,"qty":0.25000000}],"asks":[],"checksum":1360182355,"timestamp":"2024-06-01T18:06:25.516502Z"}]}
