{"channel":"book","type":"snapshot","data":[{"symbol":"ETH/USDC","bids":[{"price":3799.06,"qty":0.33750000},{"price":3798.87,"qty":0.33750000},{"price":3798.70,"qty":1.55307684},{"price":3798.69,"qty":1.31560570},{"price":3798.65,"qty":0.67500000},{"price":3798.43,"qty":0.01039668},{"price":3798.41,"qty":0.78658582},{"price":3798.33,"qty":0.41146002},{"price":3798.22,"qty":0.33750000},{"price":3798.13,"qty":0.33750000}],"asks":[{"price":3800.59,"qty":0.67500000},{"price":3800.78,"qty":0.65776062},{"price":3801.43,"qty":0.33750000},{"price":3801.59,"qty":0.06701755},{"price":3801.66,"qty":1.55946936},{"price":3801.67,"qty":1.31521212},{"price":3801.81,"qty":0.33750000},{"price":3802.13,"qty":21.67624910},{"price":3802.14,"qty":0.14990686},{"price":3802.16,"qty":19.54938893}],"checksum":3370420878}]}
{"channel":"book","type":"update","data":[{"symbol":"ETH/USDC","bids":[],"asks":[{"price":3801.59,"qty":0.00000000},{"price":3802.19,"qty":0.33750000}],"checksum":3762173995,"timestamp":"2024-06-01T18:05:58.077062Z"}]}
{"channel":"book","type":"update","data":[{"symbol":"ETH/USDC","bids":[],"asks":[{"price":3802.14,"qty":0.00500201}],"checksum":3924092372,"timestamp":"2024-06-01T18:05:58.077124Z"}]}
{"channel":"book","type":"update","data":[{"symbol":"ETH/USDC","bids":[],"asks":[{"price":3802.12,"qty":0.13511122}],"checksum":1258102116,"timestamp":"2024-06-01T18:05:58.079292Z"}]}
{"channel":"book","type":"update","data":[{"symbol":"ETH/USDC","bids":[],"asks":[{"price":3801.65,"qty":0.07351808}],"checksum":1767358552,"timestamp":"2024-06-01T18:05:58.079311Z"}]}
{"channel":"book","type":"update","data":[{"symbol":"ETH/USDC","bids":[{"price":3799.07,"qty":0.65805486}],"asks":[],"checksum":3519056152,"timestamp":"2024-06-01T18:05:58.960989Z"}]}
{"channel":"book","type":"update","data":[{"symbol":"ETH/USDC","bids":[{"price":3799.06,"qty":0.00000000},{"price":3798.13,"qty":0.33750000}],"asks":[],"checksum":3666159717,"timestamp":"2024-06-01T18:05:59.738184Z"}]}
{"channel":"book","type":"update","data":[{"symbol":"ETH/USDC","bids":[],"asks":[{"price":3800.78,"qty":0.00000000},{"price":3802.16,"qty":19.54938893}],"checksum":2688672578,"timestamp":"2024-06-01T18:05:59.739188Z"}]}
{"channel":"book","type":"update","data":[{"symbol":"ETH/USDC","bids":[],"asks":[{"price":3800.58,"qty":0.65779523}],"checksum":1376420625,"timestamp":"2024-06-01T18:05:59.743509Z"}]}
{"channel":"book","type":"update","data":[{"symbol":"ETH/USDC","bids":[],"asks":[{"price":3800.59,"qty":0.33750000}],"checksum":2147304570,"timestamp":"2024-06-01T18:05:59.744907Z"}]}
{"channel":"book","type":"update","data":[{"symbol":"ETH/USDC","bids":[],"asks":[{"price":3800.40,"qty":0.33750000}],"checksum":1954014093,"timestamp":"2024-06-01T18:05:59.747590Z"}]}
{"channel":"book","type":"update","data":[{"symbol":"ETH/USDC","bids":[],"asks":[{"price":3800.21,"qty":0.33750000}],"checksum":2252568456,"timestamp":"2024-06-01T18:05:59.748414Z"}]}
{"channel":"book","type":"update","data":[{"symbol":"ETH/USDC","bids":[{"price":3798.87,"qty":0.00000000},{"price":3798.07,"qty":1.31645616}],"asks":[],"checksum":31172001,"timestamp":"2024-06-01T18:05:59.752441Z"}]}
{"channel":"book","type":"update","data":[{"symbol":"ETH/USDC","bids":[],"asks":[{"price":3800.21,"qty":0.67500000}],"checksum":3680858546,"timestamp":"2024-06-01T18:05:59.752651Z"}]}
{"channel":"book","type":"update","data":[{"symbol":"ETH/USDC","bids":[],"asks":[{"price":3800.59,"qty":0.00000000},{"price":3802.13,"qty":21.67624910}],"checksum":2443811,"timestamp":"2024-06-01T18:05:59.752869Z"}]}
{"channel":"book","type":"update","data":[{"symbol":"ETH/USDC","bids":[],"asks":[{"price":3800.40,"qty":0.00000000},{"price":3802.14,"qty":0.00500201}],"checksum":309790545,"timestamp":"2024-06-01T18:05:59.754395Z"}]}
{"channel":"book","type":"update","data":[{"symbol":"ETH/USDC","bids":[],"asks":[{"price":3802.13,"qty":0.00000000},{"price":3802.16,"qty":19.54938893}],"checksum":3288182879,"timestamp":"2024-06-01T18:05:59.761084Z"}]}
{"channel":"book","type":"update","data":[{"symbol":"ETH/USDC","bids":[],"asks":[{"price":3801.66,"qty":0.00000000},{"price":3802.19,"qty":0.33750000}],"checksum":328115520,"timestamp":"2024-06-01T18:05:59.761156Z"}]}
{"channel":"book","type":"update","data":[{"symbol":"ETH/USDC","bids":[],"asks":[{"price":3801.66,"qty":6.20892036}],"checksum":112779117,"timestamp":"2024-06-01T18:05:59.764555Z"}]}
{"channel":"book","type":"update","data":[{"symbol":"ETH/USDC","bids":[],"asks":[{"price":3801.64,"qty":1.04286370}],"checksum":1174158623,"timestamp":"2024-06-01T18:05:59.764637Z"}]}
{"channel":"book","type":"update","data":[{"symbol":"ETH/USDC","bids":[{"price":3798.69,"qty":0.00000000},{"price":3797.88,"qty":0.40100000}],"asks":[],"checksum":2694429433,"timestamp":"2024-06-01T18:06:00.895812Z"}]}
{"channel":"book","type":"update","data":[{"symbol":"ETH/USDC","bids":[],"asks":[{"price":3802.14,"qty":0.00000000},{"price":3802.15,"qty":16.42738790}],"checksum":3484152690,"timestamp":"2024-06-01T18:06:00.904434Z"}]}
{"channel":"book","type":"update","data":[{"symbol":"ETH/USDC","bids":[{"price":3798.43,"qty":0.00000000},{"price":3797.48,"qty":0.33750000}],"asks":[],"checksum":1323045531,"timestamp":"2024-06-01T18:06:01.023592Z"}]}
{"channel":"book","type":"update","data":[{"symbol":"ETH/USDC","bids":[{"price":3798.71,"qty":0.02066488}],"asks":[],"checksum":3437937734,"timestamp":"2024-06-01T18:06:01.025171Z"}]}
{"channel":"book","type":"update","data":[{"symbol":"ETH/USDC","bids":[{"price":3799.13,"qty":0.33750000}],"asks":[],"checksum":2696530307,"timestamp":"2024-06-01T18:06:01.127379Z"}]}
{"channel":"book","type":"update","data":[{"symbol":"ETH/USDC","bids":[],"asks":[{"price":3800.21,"qty":0.33750000}],"checksum":1088963682,"timestamp":"2024-06-01T18:06:01.127973Z"}]}
{"channel":"book","type":"update","data":[{"symbol":"ETH/USDC","bids":[],"asks":[{"price":3800.06,"qty":0.33750000}],"checksum":2634912786,"timestamp":"2024-06-01T18:06:01.131347Z"}]}
{"channel":"book","type":"update","data":[{"symbol":"ETH/USDC","bids":[],"asks":[{"price":3800.21,"qty":0.00000000},{"price":3802.15,"qty":16.42738790}],"checksum":3946827160,"timestamp":"2024-06-01T18:06:01.132577Z"}]}
{"channel":"book","type":"update","data":[{"symbol":"ETH/USDC","bids":[],"asks":[{"price":3800.06,"qty":0.00000000},{"price":3802.19,"qty":0.33750000}],"checksum":3572571119,"timestamp":"2024-06-01T18:06:01.134614Z"}]}
{"channel":"book","type":"update","data":[{"symbol":"ETH/USDC","bids":[{"price":3799.07,"qty":0.00000000},{"price":3797.88,"qty":0.40100000}],"asks":[],"checksum":2044374671,"timestamp":"2024-06-01T18:06:01.135750Z"}]}
{"channel":"book","type":"update","data":[{"symbol":"ETH/USDC","bids":[],"asks":[{"price":3800.06,"qty":0.33750000}],"checksum":1175746808,"timestamp":"2024-06-01T18:06:01.139254Z"}]}
{"channel":"book","type":"update","data":[{"symbol":"ETH/USDC","bids":[{"price":3799.14,"qty":0.65804352}],"asks":[],"checksum":3180785602,"timestamp":"2024-06-01T18:06:01.140040Z"}]}
{"channel":"book","type":"update","data":[{"symbol":"ETH/USDC","bids":[],"asks":[{"price":3800.49,"qty":0.33750000}],"checksum":513875476,"timestamp":"2024-06-01T18:06:01.140057Z"}]}
{"channel":"book","type":"update","data":[{"symbol":"ETH/USDC","bids":[{"price":3799.13,"qty":0.00000000},{"price":3797.88,"qty":0.40100000}],"asks":[],"checksum":116154283,"timestamp":"2024-06-01T18:06:01.143707Z"}]}
{"channel":"book","type":"update","data":[{"symbol":"ETH/USDC","bids":[{"price":3799.20,"qty":0.33750000}],"asks":[],"checksum":3091638341,"timestamp":"2024-06-01T18:06:01.147631Z"}]}
{"channel":"book","type":"update","data":[{"symbol":"ETH/USDC","bids":[{"price":3799.14,"qty":0.00000000},{"price":3797.88,"qty":0.40100000}],"asks":[],"checksum":2929827071,"timestamp":"2024-06-01T18:06:01.152027Z"}]}
{"channel":"book","type":"update","data":[{"symbol":"ETH/USDC","bids":[],"asks":[{"price":3800.06,"qty":0.00000000},{"price":3802.15,"qty":16.42738790}],"checksum":4036833989,"timestamp":"2024-06-01T18:06:01.182673Z"}]}
{"channel":"book","type":"update","data":[{"symbol":"ETH/USDC","bids":[{"price":3799.20,"qty":0.67500000}],"asks":[],"checksum":1415031182,"timestamp":"2024-06-01T18:06:01.182754Z"}]}
{"channel":"book","type":"update","data":[{"symbol":"ETH/USDC","bids":[],"asks":[{"price":3800.49,"qty":0.67500000}],"checksum":3020301423,"timestamp":"2024-06-01T18:06:01.186686Z"}]}
{"channel":"book","type":"update","data":[{"symbol":"ETH/USDC","bids":[],"asks":[{"price":3800.49,"qty":0.33750000}],"checksum":1415031182,"timestamp":"2024-06-01T18:06:01.262565Z"}]}
{"channel":"book","type":"update","data":[{"symbol":"ETH/USDC","bids":[],"asks":[{"price":3800.31,"qty":0.33750000}],"checksum":1823664053,"timestamp":"2024-06-01T18:06:01.265240Z"}]}
{"channel":"book","type":"update","data":[{"symbol":"ETH/USDC","bids":[],"asks":[{"price":3800.49,"qty":0.00000000},{"price":3802.15,"qty":16.42738790}],"checksum":273499010,"timestamp":"2024-06-01T18:06:01.266871Z"}]}
{"channel":"book","type":"update","data":[{"symbol":"ETH/USDC","bids":[],"asks":[{"price":3800.31,"qty":0.00000000},{"price":3802.19,"qty":0.33750000}],"checksum":2526158869,"timestamp":"2024-06-01T18:06:01.311334Z"}]}
{"channel":"book","type":"update","data":[{"symbol":"ETH/USDC","bids":[],"asks":[{"price":3800.40,"qty":0.33750000}],"checksum":499826077,"timestamp":"2024-06-01T18:06:01.316028Z"}]}
{"channel":"book","type":"update","data":[{"symbol":"ETH/USDC","bids":[],"asks":[{"price":3800.58,"qty":0.00000000},{"price":3802.19,"qty":0.33750000}],"checksum":718747232,"timestamp":"2024-06-01T18:06:01.409472Z"}]}
{"channel":"book","type":"update","data":[{"symbol":"ETH/USDC","bids":[],"asks":[{"price":3800.94,"qty":0.65773371}],"checksum":395601861,"timestamp":"2024-06-01T18:06:01.414514Z"}]}
{"channel":"book","type":"update","data":[{"symbol":"ETH/USDC","bids":[{"price":3799.55,"qty":0.65797157}],"asks":[],"checksum":2914620665,"timestamp":"2024-06-01T18:06:01.414560Z"}]}
{"channel":"book","type":"update","data":[{"symbol":"ETH/USDC","bids":[{"price":3798.41,"qty":0.00000000},{"price":3797.88,"qty":0.40100000}],"asks":[],"checksum":2991367050,"timestamp":"2024-06-01T18:06:01.417818Z"}]}
{"channel":"book","type":"update","data":[{"symbol":"ETH/USDC","bids":[],"asks":[{"price":3800.40,"qty":0.00000000},{"price":3802.19,"qty":0.33750000}],"checksum":2202178599,"timestamp":"2024-06-01T18:06:01.419701Z"}]}
{"channel":"book","type":"update","data":[{"symbol":"ETH/USDC","bids":[{"price":3799.61,"qty":0.33750000}],"asks":[],"checksum":997683860,"timestamp":"2024-06-01T18:06:01.419809Z"}]}
{"channel":"book","type":"update","data":[{"symbol":"ETH/USDC","bids":[{"price":3798.87,"qty":0.78649057}],"asks":[],"checksum":1015583894,"timestamp":"2024-06-01T18:06:01.420654Z"}]}
{"channel":"book","type":"update","data":[{"symbol":"ETH/USDC","bids":[{"price":3798.65,"qty":0.33750000}],"asks":[],"checksum":4187140071,"timestamp":"2024-06-01T18:06:01.421424Z"}]}
{"channel":"book","type":"update","data":[{"symbol":"ETH/USDC","bids":[{"price":3799.59,"qty":0.33750000}],"asks":[],"checksum":2375121734,"timestamp":"2024-06-01T18:06:01.421501Z"}]}
{"channel":"book","type":"update","data":[{"symbol":"ETH/USDC","bids":[],"asks":[{"price":3800.91,"qty":0.33750000}],"checksum":3697201818,"timestamp":"2024-06-01T18:06:01.423518Z"}]}
{"channel":"book","type":"update","data":[{"symbol":"ETH/USDC","bids":[],"asks":[{"price":3800.75,"qty":0.33750000}],"checksum":1290422177,"timestamp":"2024-06-01T18:06:01.423784Z"}]}
{"channel":"book","type":"update","data":[{"symbol":"ETH/USDC","bids":[],"asks":[{"price":3800.94,"qty":0.00000000},{"price":3802.15,"qty":16.42738790}],"checksum":2812807099,"timestamp":"2024-06-01T18:06:01.429121Z"}]}
{"channel":"book","type":"update","data":[{"symbol":"ETH/USDC","bids":[{"price":3799.55,"qty":0.00000000},{"price":3798.13,"qty":0.33750000}],"asks":[],"checksum":3489285690,"timestamp":"2024-06-01T18:06:01.984688Z"}]}
{"channel":"book","type":"update","data":[{"symbol":"ETH/USDC","bids":[{"price":3799.62,"qty":0.65796029}],"asks":[],"checksum":1275207949,"timestamp":"2024-06-01T18:06:01.989415Z"}]}
{"channel":"book","type":"update","data":[{"symbol":"ETH/USDC","bids":[],"asks":[{"price":3800.90,"qty":0.65773947}],"checksum":2502446209,"timestamp":"2024-06-01T18:06:01.989526Z"}]}
{"channel":"book","type":"update","data":[{"symbol":"ETH/USDC","bids":[{"price":3798.65,"qty":1.65375450}],"asks":[],"checksum":4252756789,"timestamp":"2024-06-01T18:06:01.989642Z"}]}
{"channel":"book","type":"update","data":[{"symbol":"ETH/USDC","bids":[{"price":3799.61,"qty":0.00000000},{"price":3798.13,"qty":0.33750000}],"asks":[],"checksum":475931422,"timestamp":"2024-06-01T18:06:01.989871Z"}]}
{"channel":"book","type":"update","data":[{"symbol":"ETH/USDC","bids":[{"price":3799.64,"qty":0.33750000}],"asks":[],"checksum":2596386381,"timestamp":"2024-06-01T18:06:01.994104Z"}]}
{"channel":"book","type":"update","data":[{"symbol":"ETH/USDC","bids":[],"asks":[{"price":3801.64,"qty":0.00000000},{"price":3802.15,"qty":16.42738790}],"checksum":4216802823,"timestamp":"2024-06-01T18:06:02.124700Z"}]}
{"channel":"book","type":"update","data":[{"symbol":"ETH/USDC","bids":[],"asks":[{"price":3801.66,"qty":0.00000000},{"price":3802.19,"qty":0.33750000}],"checksum":1556154375,"timestamp":"2024-06-01T18:06:02.124837Z"}]}
{"channel":"book","type":"update","data":[{"symbol":"ETH/USDC","bids":[],"asks":[{"price":3802.15,"qty":0.00000000},{"price":3802.20,"qty":19.54700929}],"checksum":332599793,"timestamp":"2024-06-01T18:06:02.124973Z"}]}
{"channel":"book","type":"update","data":[{"symbol":"ETH/USDC","bids":[],"asks":[{"price":3801.64,"qty":1.55944873}],"checksum":1975200991,"timestamp":"2024-06-01T18:06:02.129576Z"}]}
{"channel":"book","type":"update","data":[{"symbol":"ETH/USDC","bids":[],"asks":[{"price":3802.18,"qty":22.19235070}],"checksum":3763743113,"timestamp":"2024-06-01T18:06:02.129696Z"}]}
{"channel":"book","type":"update","data":[{"symbol":"ETH/USDC","bids":[{"price":3798.33,"qty":0.00000000},{"price":3798.13,"qty":0.33750000}],"asks":[],"checksum":1919559326,"timestamp":"2024-06-01T18:06:02.164565Z"}]}
{"channel":"book","type":"update","data":[{"symbol":"ETH/USDC","bids":[],"asks":[{"price":3802.17,"qty":0.00529704}],"checksum":86362858,"timestamp":"2024-06-01T18:06:02.168690Z"}]}
{"channel":"book","type":"update","data":[{"symbol":"ETH/USDC","bids":[],"asks":[{"price":3800.91,"qty":0.00000000},{"price":3802.18,"qty":22.19235070}],"checksum":1004032559,"timestamp":"2024-06-01T18:06:02.276349Z"}]}
{"channel":"book","type":"update","data":[{"symbol":"ETH/USDC","bids":[{"price":3798.50,"qty":0.41138460}],"asks":[],"checksum":3023065133,"timestamp":"2024-06-01T18:06:02.419559Z"}]}
{"channel":"book","type":"update","data":[{"symbol":"ETH/USDC","bids":[],"asks":[{"price":3802.12,"qty":0.00000000},{"price":3802.19,"qty":0.33750000}],"checksum":852111600,"timestamp":"2024-06-01T18:06:02.606915Z"}]}
{"channel":"book","type":"update","data":[{"symbol":"ETH/USDC","bids":[],"asks":[{"price":3801.65,"qty":0.00000000},{"price":3802.20,"qty":19.54700929}],"checksum":1574886461,"timestamp":"2024-06-01T18:06:02.606962Z"}]}
{"channel":"book","type":"update","data":[{"symbol":"ETH/USDC","bids":[],"asks":[{"price":3802.17,"qty":0.17935427}],"checksum":3401308070,"timestamp":"2024-06-01T18:06:02.609019Z"}]}
{"channel":"book","type":"update","data":[{"symbol":"ETH/USDC","bids":[],"asks":[{"price":3801.63,"qty":0.06051677}],"checksum":1098152122,"timestamp":"2024-06-01T18:06:02.609037Z"}]}
{"channel":"book","type":"update","data":[{"symbol":"ETH/USDC","bids":[{"price":3799.20,"qty":0.33750000}],"asks":[],"checksum":1319221046,"timestamp":"2024-06-01T18:06:03.513181Z"}]}
{"channel":"book","type":"update","data":[{"symbol":"ETH/USDC","bids":[],"asks":[{"price":3800.75,"qty":0.00000000},{"price":3802.20,"qty":19.54700929}],"checksum":3648964561,"timestamp":"2024-06-01T18:06:03.513891Z"}]}
{"channel":"book","type":"update","data":[{"symbol":"ETH/USDC","bids":[{"price":3799.64,"qty":0.67500000}],"asks":[],"checksum":2108972186,"timestamp":"2024-06-01T18:06:03.513944Z"}]}
{"channel":"book","type":"update","data":[{"symbol":"ETH/USDC","bids":[],"asks":[{"price":3800.71,"qty":0.33750000}],"checksum":2720361260,"timestamp":"2024-06-01T18:06:03.518721Z"}]}
{"channel":"book","type":"update","data":[{"symbol":"ETH/USDC","bids":[{"price":3799.62,"qty":0.00000000},{"price":3798.13,"qty":0.33750000}],"asks":[],"checksum":946162848,"timestamp":"2024-06-01T18:06:03.526721Z"}]}
{"channel":"book","type":"update","data":[{"symbol":"ETH/USDC","bids":[{"price":3799.65,"qty":0.65795521}],"asks":[],"checksum":2720606524,"timestamp":"2024-06-01T18:06:03.531655Z"}]}
{"channel":"book","type":"update","data":[{"symbol":"ETH/USDC","bids":[{"price":3799.64,"qty":0.33750000}],"asks":[],"checksum":1290959704,"timestamp":"2024-06-01T18:06:03.533388Z"}]}
{"channel":"book","type":"update","data":[{"symbol":"ETH/USDC","bids":[{"price":3799.86,"qty":0.33750000}],"asks":[],"checksum":1337955133,"timestamp":"2024-06-01T18:06:03.536813Z"}]}
{"channel":"book","type":"update","data":[{"symbol":"ETH/USDC","bids":[{"price":3799.84,"qty":0.33750000}],"asks":[],"checksum":3384129963,"timestamp":"2024-06-01T18:06:03.536830Z"}]}
{"channel":"book","type":"update","data":[{"symbol":"ETH/USDC","bids":[{"price":3799.59,"qty":0.00000000},{"price":3798.50,"qty":0.41138460}],"asks":[],"checksum":1050367988,"timestamp":"2024-06-01T18:06:03.537596Z"}]}
{"channel":"book","type":"update","data":[{"symbol":"ETH/USDC","bids":[],"asks":[{"price":3801.67,"qty":0.00000000},{"price":3802.20,"qty":19.54700929}],"checksum":222115367,"timestamp":"2024-06-01T18:06:03.539442Z"}]}
{"channel":"book","type":"update","data":[{"symbol":"ETH/USDC","bids":[{"price":3799.64,"qty":0.00000000},{"price":3798.22,"qty":0.33750000}],"asks":[],"checksum":4154333486,"timestamp":"2024-06-01T18:06:03.540978Z"}]}
{"channel":"book","type":"update","data":[{"symbol":"ETH/USDC","bids":[],"asks":[{"price":3800.71,"qty":0.00000000},{"price":3802.51,"qty":1.31492311}],"checksum":1770098077,"timestamp":"2024-06-01T18:06:03.541104Z"}]}
{"channel":"book","type":"update","data":[{"symbol":"ETH/USDC","bids":[{"price":3799.86,"qty":0.67500000}],"asks":[],"checksum":3444250326,"timestamp":"2024-06-01T18:06:03.541351Z"}]}
{"channel":"book","type":"update","data":[{"symbol":"ETH/USDC","bids":[{"price":3799.84,"qty":0.00000000},{"price":3798.13,"qty":0.33750000}],"asks":[],"checksum":206210698,"timestamp":"2024-06-01T18:06:03.541360Z"}]}
{"channel":"book","type":"update","data":[{"symbol":"ETH/USDC","bids":[],"asks":[{"price":3800.89,"qty":0.33750000}],"checksum":1082005733,"timestamp":"2024-06-01T18:06:03.574164Z"}]}
{"channel":"book","type":"update","data":[{"symbol":"ETH/USDC","bids":[],"asks":[{"price":3802.20,"qty":0.00000000},{"price":3802.51,"qty":1.31492311}],"checksum":3083671721,"timestamp":"2024-06-01T18:06:03.619333Z"}]}
{"channel":"book","type":"update","data":[{"symbol":"ETH/USDC","bids":[],"asks":[{"price":3802.30,"qty":19.54948100}],"checksum":1012625103,"timestamp":"2024-06-01T18:06:03.623399Z"}]}
{"channel":"book","type":"update","data":[{"symbol":"ETH/USDC","bids":[{"price":3799.86,"qty":0.33750000}],"asks":[],"checksum":2559702404,"timestamp":"2024-06-01T18:06:03.680266Z"}]}
{"channel":"book","type":"update","data":[{"symbol":"ETH/USDC","bids":[{"price":3799.86,"qty":0.00000000},{"price":3798.07,"qty":1.31645616}],"asks":[],"checksum":2843656326,"timestamp":"2024-06-01T18:06:04.305852Z"}]}
{"channel":"book","type":"update","data":[{"symbol":"ETH/USDC","bids":[],"asks":[{"price":3800.89,"qty":0.67500000}],"checksum":2123580389,"timestamp":"2024-06-01T18:06:04.306094Z"}]}
{"channel":"book","type":"update","data":[{"symbol":"ETH/USDC","bids":[],"asks":[{"price":3800.89,"qty":0.33750000}],"checksum":2843656326,"timestamp":"2024-06-01T18:06:04.309243Z"}]}
{"channel":"book","type":"update","data":[{"symbol":"ETH/USDC","bids":[{"price":3799.67,"qty":0.33750000}],"asks":[],"checksum":880532695,"timestamp":"2024-06-01T18:06:04.310100Z"}]}
{"channel":"book","type":"update","data":[{"symbol":"ETH/USDC","bids":[],"asks":[{"price":3800.83,"qty":0.33750000}],"checksum":2866423053,"timestamp":"2024-06-01T18:06:04.312117Z"}]}
{"channel":"book","type":"update","data":[{"symbol":"ETH/USDC","bids":[{"price":3799.65,"qty":0.00000000},{"price":3798.07,"qty":1.31645616}],"asks":[],"checksum":3592309589,"timestamp":"2024-06-01T18:06:04.314712Z"}]}
{"channel":"book","type":"update","data":[{"symbol":"ETH/USDC","bids":[{"price":3799.68,"qty":0.65794976}],"asks":[],"checksum":927009616,"timestamp":"2024-06-01T18:06:04.318913Z"}]}
{"channel":"book","type":"update","data":[{"symbol":"ETH/USDC","bids":[],"asks":[{"price":3800.83,"qty":0.67500000}],"checksum":3992969027,"timestamp":"2024-06-01T18:06:04.319848Z"}]}
{"channel":"book","type":"update","data":[{"symbol":"ETH/USDC","bids":[{"price":3799.67,"qty":0.00000000},{"price":3798.07,"qty":1.31645616}],"asks":[],"checksum":137164377,"timestamp":"2024-06-01T18:06:04.319865Z"}]}
{"channel":"book","type":"update","data":[{"symbol":"ETH/USDC","bids":[],"asks":[{"price":3800.89,"qty":0.00000000},{"price":3802.30,"qty":19.54948100}],"checksum":2390788327,"timestamp":"2024-06-01T18:06:04.321268Z"}]}
{"channel":"book","type":"update","data":[{"symbol":"ETH/USDC","bids":[{"price":3799.69,"qty":0.33750000}],"asks":[],"checksum":3761009633,"timestamp":"2024-06-01T18:06:04.325954Z"}]}
{"channel":"book","type":"update","data":[{"symbol":"ETH/USDC","bids":[{"price":3799.69,"qty":0.00000000},{"price":3798.07,"qty":1.31645616}],"asks":[],"checksum":2390788327,"timestamp":"2024-06-01T18:06:04.330326Z"}]}
{"channel":"book","type":"update","data":[{"symbol":"ETH/USDC","bids":[{"price":3799.70,"qty":0.33750000}],"asks":[],"checksum":1325057792,"timestamp":"2024-06-01T18:06:04.332861Z"}]}
{"channel":"book","type":"update","data":[{"symbol":"ETH/USDC","bids":[],"asks":[{"price":3800.83,"qty":0.33750000}],"checksum":2930461409,"timestamp":"2024-06-01T18:06:04.333987Z"}]}
{"channel":"book","type":"update","data":[{"symbol":"ETH/USDC","bids":[{"price":3799.70,"qty":0.00000000},{"price":3798.07,"qty":1.31645616}],"asks":[],"checksum":1500318596,"timestamp":"2024-06-01T18:06:04.335905Z"}]}
{"channel":"book","type":"update","data":[{"symbol":"ETH/USDC","bids":[],"asks":[{"price":3800.64,"qty":0.33750000}],"checksum":2284337654,"timestamp":"2024-06-01T18:06:04.337124Z"}]}
{"channel":"book","type":"update","data":[{"symbol":"ETH/USDC","bids":[],"asks":[{"price":3800.81,"qty":0.33750000}],"checksum":479607876,"timestamp":"2024-06-01T18:06:04.337164Z"}]}
{"channel":"book","type":"update","data":[{"symbol":"ETH/USDC","bids":[],"asks":[{"price":3800.83,"qty":0.00000000},{"price":3802.19,"qty":0.33750000}],"checksum":2203756183,"timestamp":"2024-06-01T18:06:04.339028Z"}]}
{"channel":"book","type":"update","data":[{"symbol":"ETH/USDC","bids":[],"asks":[{"price":3800.81,"qty":0.00000000},{"price":3802.30,"qty":19.54948100}],"checksum":3251230113,"timestamp":"2024-06-01T18:06:04.339990Z"}]}
{"channel":"book","type":"update","data":[{"symbol":"ETH/USDC","bids":[{"price":3799.68,"qty":0.99544976}],"asks":[],"checksum":1568349827,"timestamp":"2024-06-01T18:06:04.505220Z"}]}
{"channel":"book","type":"update","data":[{"symbol":"ETH/USDC","bids":[],"asks":[{"price":3801.64,"qty":0.00000000},{"price":3802.51,"qty":1.31492311}],"checksum":1761058435,"timestamp":"2024-06-01T18:06:04.571092Z"}]}
{"channel":"book","type":"update","data":[{"symbol":"ETH/USDC","bids":[],"asks":[{"price":3802.18,"qty":0.00000000},{"price":3802.76,"qty":0.03955500}],"checksum":3557962247,"timestamp":"2024-06-01T18:06:04.571108Z"}]}
{"channel":"book","type":"update","data":[{"symbol":"ETH/USDC","bids":[],"asks":[{"price":3802.17,"qty":0.17405723}],"checksum":2894102136,"timestamp":"2024-06-01T18:06:04.576863Z"}]}
{"channel":"book","type":"update","data":[{"symbol":"ETH/USDC","bids":[],"asks":[{"price":3802.16,"qty":7.24211245}],"checksum":3977212130,"timestamp":"2024-06-01T18:06:04.578331Z"}]}
{"channel":"book","type":"update","data":[{"symbol":"ETH/USDC","bids":[],"asks":[{"price":3802.29,"qty":17.96642543}],"checksum":4011384196,"timestamp":"2024-06-01T18:06:04.578634Z"}]}
{"channel":"book","type":"update","data":[{"symbol":"ETH/USDC","bids":[],"asks":[{"price":3802.29,"qty":17.97186738}],"checksum":690759192,"timestamp":"2024-06-01T18:06:04.579062Z"}]}
{"channel":"book","type":"update","data":[{"symbol":"ETH/USDC","bids":[{"price":3798.70,"qty":0.00000000},{"price":3797.88,"qty":0.40100000}],"asks":[],"checksum":2155585344,"timestamp":"2024-06-01T18:06:04.743096Z"}]}
{"channel":"book","type":"update","data":[{"symbol":"ETH/USDC","bids":[{"price":3798.66,"qty":0.52623866}],"asks":[],"checksum":1923197251,"timestamp":"2024-06-01T18:06:04.744074Z"}]}
{"channel":"book","type":"update","data":[{"symbol":"ETH/USDC","bids":[{"price":3798.71,"qty":0.00000000},{"price":3797.88,"qty":0.40100000}],"asks":[],"checksum":1667458065,"timestamp":"2024-06-01T18:06:04.896143Z"}]}
{"channel":"book","type":"update","data":[{"symbol":"ETH/USDC","bids":[{"price":3798.88,"qty":0.01039630}],"asks":[],"checksum":2637664762,"timestamp":"2024-06-01T18:06:04.896664Z"}]}
{"channel":"book","type":"update","data":[{"symbol":"ETH/USDC","bids":[{"price":3799.68,"qty":0.65794976}],"asks":[],"checksum":653924926,"timestamp":"2024-06-01T18:06:05.191869Z"}]}
{"channel":"book","type":"update","data":[{"symbol":"ETH/USDC","bids":[],"asks":[{"price":3800.64,"qty":0.67500000}],"checksum":3333134303,"timestamp":"2024-06-01T18:06:05.335649Z"}]}
{"channel":"book","type":"update","data":[{"symbol":"ETH/USDC","bids":[],"asks":[{"price":3800.64,"qty":0.33750000}],"checksum":653924926,"timestamp":"2024-06-01T18:06:06.146277Z"}]}
{"channel":"book","type":"update","data":[{"symbol":"ETH/USDC","bids":[],"asks":[{"price":3800.64,"qty":0.67500000}],"checksum":3333134303,"timestamp":"2024-06-01T18:06:06.564349Z"}]}
{"channel":"book","type":"update","data":[{"symbol":"ETH/USDC","bids":[],"asks":[{"price":3802.29,"qty":0.00544195}],"checksum":3904799335,"timestamp":"2024-06-01T18:06:06.916254Z"}]}
{"channel":"book","type":"update","data":[{"symbol":"ETH/USDC","bids":[],"asks":[{"price":3802.29,"qty":14.37858230}],"checksum":825543085,"timestamp":"2024-06-01T18:06:06.921381Z"}]}
{"channel":"book","type":"update","data":[{"symbol":"ETH/USDC","bids":[],"asks":[{"price":3800.64,"qty":0.33750000}],"checksum":3513074764,"timestamp":"2024-06-01T18:06:06.950180Z"}]}
{"channel":"book","type":"update","data":[{"symbol":"ETH/USDC","bids":[{"price":3799.69,"qty":0.33750000}],"asks":[],"checksum":3573234490,"timestamp":"2024-06-01T18:06:07.146996Z"}]}
{"channel":"book","type":"update","data":[{"symbol":"ETH/USDC","bids":[{"price":3799.69,"qty":0.00000000},{"price":3798.07,"qty":1.31645616}],"asks":[],"checksum":3513074764,"timestamp":"2024-06-01T18:06:07.150877Z"}]}
{"channel":"book","type":"update","data":[{"symbol":"ETH/USDC","bids":[{"price":3799.69,"qty":0.33750000}],"asks":[],"checksum":3573234490,"timestamp":"2024-06-01T18:06:07.158277Z"}]}
{"channel":"book","type":"update","data":[{"symbol":"ETH/USDC","bids":[{"price":3799.69,"qty":0.00000000},{"price":3798.07,"qty":1.31645616}],"asks":[],"checksum":3513074764,"timestamp":"2024-06-01T18:06:07.162433Z"}]}
{"channel":"book","type":"update","data":[{"symbol":"ETH/USDC","bids":[],"asks":[{"price":3801.63,"qty":0.00000000},{"price":3802.51,"qty":1.31492311}],"checksum":3784358685,"timestamp":"2024-06-01T18:06:07.162939Z"}]}
{"channel":"book","type":"update","data":[{"symbol":"ETH/USDC","bids":[],"asks":[{"price":3802.17,"qty":0.00000000},{"price":3802.76,"qty":0.03955500}],"checksum":1187753211,"timestamp":"2024-06-01T18:06:07.163000Z"}]}
{"channel":"book","type":"update","data":[{"symbol":"ETH/USDC","bids":[],"asks":[{"price":3802.15,"qty":0.28478490}],"checksum":4279164019,"timestamp":"2024-06-01T18:06:07.164662Z"}]}
{"channel":"book","type":"update","data":[{"symbol":"ETH/USDC","bids":[{"price":3799.69,"qty":0.33750000}],"asks":[],"checksum":191792455,"timestamp":"2024-06-01T18:06:07.167564Z"}]}
{"channel":"book","type":"update","data":[{"symbol":"ETH/USDC","bids":[{"price":3799.69,"qty":0.00000000},{"price":3798.07,"qty":1.31645616}],"asks":[],"checksum":4279164019,"timestamp":"2024-06-01T18:06:07.171275Z"}]}
{"channel":"book","type":"update","data":[{"symbol":"ETH/USDC","bids":[{"price":3799.72,"qty":0.33750000}],"asks":[],"checksum":1067214754,"timestamp":"2024-06-01T18:06:07.174257Z"}]}
{"channel":"book","type":"update","data":[{"symbol":"ETH/USDC","bids":[{"price":3799.72,"qty":0.00000000},{"price":3798.07,"qty":1.31645616}],"asks":[],"checksum":4279164019,"timestamp":"2024-06-01T18:06:07.178088Z"}]}
{"channel":"book","type":"update","data":[{"symbol":"ETH/USDC","bids":[{"price":3799.73,"qty":0.33750000}],"asks":[],"checksum":3417489412,"timestamp":"2024-06-01T18:06:07.187244Z"}]}
{"channel":"book","type":"update","data":[{"symbol":"ETH/USDC","bids":[{"price":3799.73,"qty":0.00000000},{"price":3798.07,"qty":1.31645616}],"asks":[],"checksum":4279164019,"timestamp":"2024-06-01T18:06:07.191132Z"}]}
{"channel":"book","type":"update","data":[{"symbol":"ETH/USDC","bids":[{"price":3799.74,"qty":0.33750000}],"asks":[],"checksum":1793637557,"timestamp":"2024-06-01T18:06:07.194619Z"}]}
{"channel":"book","type":"update","data":[{"symbol":"ETH/USDC","bids":[{"price":3799.74,"qty":0.00000000},{"price":3798.07,"qty":1.31645616}],"asks":[],"checksum":4279164019,"timestamp":"2024-06-01T18:06:07.198292Z"}]}
{"channel":"book","type":"update","data":[{"symbol":"ETH/USDC","bids":[{"price":3799.69,"qty":0.33750000}],"asks":[],"checksum":191792455,"timestamp":"2024-06-01T18:06:07.228449Z"}]}
{"channel":"book","type":"update","data":[{"symbol":"ETH/USDC","bids":[],"asks":[{"price":3801.43,"qty":0.00000000},{"price":3802.76,"qty":0.03955500}],"checksum":459291118,"timestamp":"2024-06-01T18:06:07.230910Z"}]}
{"channel":"book","type":"update","data":[{"symbol":"ETH/USDC","bids":[{"price":3799.69,"qty":0.00000000},{"price":3798.07,"qty":1.31645616}],"asks":[],"checksum":1343539587,"timestamp":"2024-06-01T18:06:07.232209Z"}]}
{"channel":"book","type":"update","data":[{"symbol":"ETH/USDC","bids":[],"asks":[{"price":3802.58,"qty":0.33750000}],"checksum":2033333038,"timestamp":"2024-06-01T18:06:07.235361Z"}]}
{"channel":"book","type":"update","data":[{"symbol":"ETH/USDC","bids":[{"price":3799.71,"qty":0.33750000}],"asks":[],"checksum":396558553,"timestamp":"2024-06-01T18:06:07.235541Z"}]}
{"channel":"book","type":"update","data":[{"symbol":"ETH/USDC","bids":[{"price":3799.71,"qty":0.00000000},{"price":3798.07,"qty":1.31645616}],"asks":[],"checksum":2033333038,"timestamp":"2024-06-01T18:06:07.239898Z"}]}
{"channel":"book","type":"update","data":[{"symbol":"ETH/USDC","bids":[{"price":3799.74,"qty":0.33750000}],"asks":[],"checksum":2245342565,"timestamp":"2024-06-01T18:06:07.242428Z"}]}
{"channel":"book","type":"update","data":[{"symbol":"ETH/USDC","bids":[{"price":3799.74,"qty":0.00000000},{"price":3798.07,"qty":1.31645616}],"asks":[],"checksum":2033333038,"timestamp":"2024-06-01T18:06:07.244899Z"}]}
{"channel":"book","type":"update","data":[{"symbol":"ETH/USDC","bids":[{"price":3799.72,"qty":0.33750000}],"asks":[],"checksum":3500273266,"timestamp":"2024-06-01T18:06:07.253423Z"}]}
{"channel":"book","type":"update","data":[{"symbol":"ETH/USDC","bids":[{"price":3799.72,"qty":0.00000000},{"price":3798.07,"qty":1.31645616}],"asks":[],"checksum":2033333038,"timestamp":"2024-06-01T18:06:07.257359Z"}]}
{"channel":"book","type":"update","data":[{"symbol":"ETH/USDC","bids":[{"price":3799.73,"qty":0.33750000}],"asks":[],"checksum":613370324,"timestamp":"2024-06-01T18:06:07.276712Z"}]}
{"channel":"book","type":"update","data":[{"symbol":"ETH/USDC","bids":[{"price":3799.73,"qty":0.00000000},{"price":3798.07,"qty":1.31645616}],"asks":[],"checksum":2033333038,"timestamp":"2024-06-01T18:06:07.280675Z"}]}
{"channel":"book","type":"update","data":[{"symbol":"ETH/USDC","bids":[{"price":3799.71,"qty":0.33750000}],"asks":[],"checksum":396558553,"timestamp":"2024-06-01T18:06:07.292221Z"}]}
{"channel":"book","type":"update","data":[{"symbol":"ETH/USDC","bids":[{"price":3799.71,"qty":0.00000000},{"price":3798.07,"qty":1.31645616}],"asks":[],"checksum":2033333038,"timestamp":"2024-06-01T18:06:07.296681Z"}]}
{"channel":"book","type":"update","data":[{"symbol":"ETH/USDC","bids":[{"price":3799.70,"qty":0.33750000}],"asks":[],"checksum":3817711487,"timestamp":"2024-06-01T18:06:07.310916Z"}]}
{"channel":"book","type":"update","data":[{"symbol":"ETH/USDC","bids":[{"price":3799.70,"qty":0.00000000},{"price":3798.07,"qty":1.31645616}],"asks":[],"checksum":2033333038,"timestamp":"2024-06-01T18:06:07.314942Z"}]}
{"channel":"book","type":"update","data":[{"symbol":"ETH/USDC","bids":[{"price":3799.68,"qty":0.99544976}],"asks":[],"checksum":3271538922,"timestamp":"2024-06-01T18:06:07.322015Z"}]}
{"channel":"book","type":"update","data":[{"symbol":"ETH/USDC","bids":[{"price":3798.66,"qty":0.00000000},{"price":3797.88,"qty":0.40100000}],"asks":[],"checksum":807767785,"timestamp":"2024-06-01T18:06:08.303949Z"}]}
{"channel":"book","type":"update","data":[{"symbol":"ETH/USDC","bids":[{"price":3798.88,"qty":0.00000000},{"price":3797.48,"qty":0.33750000}],"asks":[],"checksum":4261033778,"timestamp":"2024-06-01T18:06:08.466541Z"}]}
{"channel":"book","type":"update","data":[{"symbol":"ETH/USDC","bids":[{"price":3798.67,"qty":0.00526239}],"asks":[],"checksum":473433648,"timestamp":"2024-06-01T18:06:08.468722Z"}]}
{"channel":"book","type":"update","data":[{"symbol":"ETH/USDC","bids":[],"asks":[{"price":3800.64,"qty":0.00000000},{"price":3802.76,"qty":0.03955500}],"checksum":2036510144,"timestamp":"2024-06-01T18:06:08.812023Z"}]}
{"channel":"book","type":"update","data":[{"symbol":"ETH/USDC","bids":[],"asks":[{"price":3800.71,"qty":0.33750000}],"checksum":3096900868,"timestamp":"2024-06-01T18:06:08.816013Z"}]}
{"channel":"book","type":"update","data":[{"symbol":"ETH/USDC","bids":[],"asks":[{"price":3800.85,"qty":0.33750000}],"checksum":179214058,"timestamp":"2024-06-01T18:06:08.818033Z"}]}
{"channel":"book","type":"update","data":[{"symbol":"ETH/USDC","bids":[{"price":3799.68,"qty":0.65794976}],"asks":[],"checksum":3428995423,"timestamp":"2024-06-01T18:06:08.820317Z"}]}
{"channel":"book","type":"update","data":[{"symbol":"ETH/USDC","bids":[{"price":3799.70,"qty":0.33750000}],"asks":[],"checksum":2539513820,"timestamp":"2024-06-01T18:06:08.823264Z"}]}
{"channel":"book","type":"update","data":[{"symbol":"ETH/USDC","bids":[],"asks":[{"price":3800.85,"qty":0.00000000},{"price":3802.58,"qty":0.33750000}],"checksum":627409970,"timestamp":"2024-06-01T18:06:08.827909Z"}]}
{"channel":"book","type":"update","data":[{"symbol":"ETH/USDC","bids":[],"asks":[{"price":3802.16,"qty":0.00000000},{"price":3802.76,"qty":0.03955500}],"checksum":3073663631,"timestamp":"2024-06-01T18:06:09.365882Z"}]}
{"channel":"book","type":"update","data":[{"symbol":"ETH/USDC","bids":[],"asks":[{"price":3802.29,"qty":0.00544195}],"checksum":506387860,"timestamp":"2024-06-01T18:06:09.365955Z"}]}
{"channel":"book","type":"update","data":[{"symbol":"ETH/USDC","bids":[],"asks":[{"price":3802.14,"qty":7.75871813}],"checksum":3154970830,"timestamp":"2024-06-01T18:06:09.371216Z"}]}
{"channel":"book","type":"update","data":[{"symbol":"ETH/USDC","bids":[],"asks":[{"price":3802.29,"qty":12.83229675}],"checksum":1387132802,"timestamp":"2024-06-01T18:06:09.371735Z"}]}
{"channel":"book","type":"update","data":[{"symbol":"ETH/USDC","bids":[{"price":3799.70,"qty":0.67500000}],"asks":[],"checksum":1240650212,"timestamp":"2024-06-01T18:06:09.550852Z"}]}
{"channel":"book","type":"update","data":[{"symbol":"ETH/USDC","bids":[],"asks":[{"price":3800.71,"qty":0.00000000},{"price":3802.76,"qty":0.03955500}],"checksum":83243640,"timestamp":"2024-06-01T18:06:09.551810Z"}]}
{"channel":"book","type":"update","data":[{"symbol":"ETH/USDC","bids":[],"asks":[{"price":3800.78,"qty":0.33750000}],"checksum":3439660334,"timestamp":"2024-06-01T18:06:09.556208Z"}]}
{"channel":"book","type":"update","data":[{"symbol":"ETH/USDC","bids":[{"price":3799.68,"qty":0.00000000},{"price":3797.88,"qty":0.40100000}],"asks":[],"checksum":649011604,"timestamp":"2024-06-01T18:06:09.558249Z"}]}
{"channel":"book","type":"update","data":[{"symbol":"ETH/USDC","bids":[],"asks":[{"price":3800.78,"qty":0.00000000},{"price":3802.76,"qty":0.03955500}],"checksum":4015791810,"timestamp":"2024-06-01T18:06:09.559218Z"}]}
{"channel":"book","type":"update","data":[{"symbol":"ETH/USDC","bids":[],"asks":[{"price":3802.30,"qty":0.00000000},{"price":3803.00,"qty":0.00932482}],"checksum":3632201256,"timestamp":"2024-06-01T18:06:09.560771Z"}]}
{"channel":"book","type":"update","data":[{"symbol":"ETH/USDC","bids":[{"price":3799.70,"qty":0.33750000}],"asks":[],"checksum":3273775182,"timestamp":"2024-06-01T18:06:09.563804Z"}]}
{"channel":"book","type":"update","data":[{"symbol":"ETH/USDC","bids":[{"price":3799.71,"qty":0.65794493}],"asks":[],"checksum":2846121644,"timestamp":"2024-06-01T18:06:09.563995Z"}]}
{"channel":"book","type":"update","data":[{"symbol":"ETH/USDC","bids":[],"asks":[{"price":3802.35,"qty":19.54866674}],"checksum":111777555,"timestamp":"2024-06-01T18:06:09.565653Z"}]}
{"channel":"book","type":"update","data":[{"symbol":"ETH/USDC","bids":[{"price":3799.89,"qty":0.33750000}],"asks":[],"checksum":777183743,"timestamp":"2024-06-01T18:06:09.566923Z"}]}
{"channel":"book","type":"update","data":[{"symbol":"ETH/USDC","bids":[],"asks":[{"price":3802.35,"qty":0.00000000},{"price":3803.00,"qty":0.00932482}],"checksum":696259158,"timestamp":"2024-06-01T18:06:09.568283Z"}]}
{"channel":"book","type":"update","data":[{"symbol":"ETH/USDC","bids":[{"price":3799.94,"qty":0.33750000}],"asks":[],"checksum":822077122,"timestamp":"2024-06-01T18:06:09.568592Z"}]}
{"channel":"book","type":"update","data":[{"symbol":"ETH/USDC","bids":[],"asks":[{"price":3800.90,"qty":0.00000000},{"price":3803.17,"qty":0.27442150}],"checksum":3710289853,"timestamp":"2024-06-01T18:06:09.569934Z"}]}
{"channel":"book","type":"update","data":[{"symbol":"ETH/USDC","bids":[],"asks":[{"price":3800.89,"qty":0.33750000}],"checksum":2928863763,"timestamp":"2024-06-01T18:06:09.571560Z"}]}
{"channel":"book","type":"update","data":[{"symbol":"ETH/USDC","bids":[],"asks":[{"price":3800.90,"qty":0.33750000}],"checksum":3143743675,"timestamp":"2024-06-01T18:06:09.571598Z"}]}
{"channel":"book","type":"update","data":[{"symbol":"ETH/USDC","bids":[],"asks":[{"price":3801.77,"qty":1.31549112}],"checksum":2138425766,"timestamp":"2024-06-01T18:06:09.572997Z"}]}
{"channel":"book","type":"update","data":[{"symbol":"ETH/USDC","bids":[],"asks":[{"price":3802.39,"qty":19.54866870}],"checksum":4250326108,"timestamp":"2024-06-01T18:06:09.573411Z"}]}
{"channel":"book","type":"update","data":[{"symbol":"ETH/USDC","bids":[],"asks":[{"price":3801.26,"qty":0.65767753}],"checksum":1056089348,"timestamp":"2024-06-01T18:06:09.574447Z"}]}
{"channel":"book","type":"update","data":[{"symbol":"ETH/USDC","bids":[],"asks":[{"price":3800.90,"qty":0.00000000},{"price":3802.51,"qty":1.31492311}],"checksum":1467856984,"timestamp":"2024-06-01T18:06:09.575584Z"}]}
{"channel":"book","type":"update","data":[{"symbol":"ETH/USDC","bids":[{"price":3799.94,"qty":0.00000000},{"price":3798.13,"qty":0.33750000}],"asks":[],"checksum":1308773580,"timestamp":"2024-06-01T18:06:09.575739Z"}]}
{"channel":"book","type":"update","data":[{"symbol":"ETH/USDC","bids":[{"price":3800.10,"qty":0.33750000}],"asks":[],"checksum":1323177578,"timestamp":"2024-06-01T18:06:09.578493Z"}]}
{"channel":"book","type":"update","data":[{"symbol":"ETH/USDC","bids":[],"asks":[{"price":3801.28,"qty":0.33750000}],"checksum":3794829809,"timestamp":"2024-06-01T18:06:09.579179Z"}]}
{"channel":"book","type":"update","data":[{"symbol":"ETH/USDC","bids":[{"price":3800.10,"qty":0.00000000},{"price":3798.13,"qty":0.33750000}],"asks":[],"checksum":3807173463,"timestamp":"2024-06-01T18:06:09.582328Z"}]}
{"channel":"book","type":"update","data":[{"symbol":"ETH/USDC","bids":[{"price":3799.89,"qty":0.67500000}],"asks":[],"checksum":3161441794,"timestamp":"2024-06-01T18:06:09.586382Z"}]}
{"channel":"book","type":"update","data":[{"symbol":"ETH/USDC","bids":[],"asks":[{"price":3800.89,"qty":0.00000000},{"price":3802.51,"qty":1.31492311}],"checksum":1012772715,"timestamp":"2024-06-01T18:06:09.602940Z"}]}
{"channel":"book","type":"update","data":[{"symbol":"ETH/USDC","bids":[],"asks":[{"price":3801.28,"qty":0.00000000},{"price":3802.58,"qty":0.33750000}],"checksum":1401690241,"timestamp":"2024-06-01T18:06:09.606531Z"}]}
{"channel":"book","type":"update","data":[{"symbol":"ETH/USDC","bids":[],"asks":[{"price":3801.07,"qty":0.33750000}],"checksum":4045622971,"timestamp":"2024-06-01T18:06:09.607359Z"}]}
{"channel":"book","type":"update","data":[{"symbol":"ETH/USDC","bids":[],"asks":[{"price":3801.25,"qty":0.33750000}],"checksum":869792941,"timestamp":"2024-06-01T18:06:09.609686Z"}]}
{"channel":"book","type":"update","data":[{"symbol":"ETH/USDC","bids":[{"price":3799.89,"qty":0.33750000}],"asks":[],"checksum":1834279416,"timestamp":"2024-06-01T18:06:10.004453Z"}]}
{"channel":"book","type":"update","data":[{"symbol":"ETH/USDC","bids":[{"price":3799.89,"qty":0.00000000},{"price":3798.07,"qty":1.31645616}],"asks":[],"checksum":2559444144,"timestamp":"2024-06-01T18:06:10.090955Z"}]}
{"channel":"book","type":"update","data":[{"symbol":"ETH/USDC","bids":[{"price":3799.70,"qty":0.00000000},{"price":3797.88,"qty":0.40100000}],"asks":[],"checksum":3268586200,"timestamp":"2024-06-01T18:06:10.097479Z"}]}
{"channel":"book","type":"update","data":[{"symbol":"ETH/USDC","bids":[{"price":3799.72,"qty":0.33750000}],"asks":[],"checksum":592008401,"timestamp":"2024-06-01T18:06:10.097842Z"}]}
{"channel":"book","type":"update","data":[{"symbol":"ETH/USDC","bids":[{"price":3799.72,"qty":0.00000000},{"price":3797.88,"qty":0.40100000}],"asks":[],"checksum":3268586200,"timestamp":"2024-06-01T18:06:10.101937Z"}]}
{"channel":"book","type":"update","data":[{"symbol":"ETH/USDC","bids":[{"price":3799.74,"qty":0.33750000}],"asks":[],"checksum":1983745990,"timestamp":"2024-06-01T18:06:10.169649Z"}]}
{"channel":"book","type":"update","data":[{"symbol":"ETH/USDC","bids":[{"price":3799.74,"qty":0.00000000},{"price":3797.88,"qty":0.40100000}],"asks":[],"checksum":3268586200,"timestamp":"2024-06-01T18:06:10.174047Z"}]}
{"channel":"book","type":"update","data":[{"symbol":"ETH/USDC","bids":[{"price":3799.72,"qty":0.33750000}],"asks":[],"checksum":592008401,"timestamp":"2024-06-01T18:06:10.244563Z"}]}
{"channel":"book","type":"update","data":[{"symbol":"ETH/USDC","bids":[{"price":3799.72,"qty":0.00000000},{"price":3797.88,"qty":0.40100000}],"asks":[],"checksum":3268586200,"timestamp":"2024-06-01T18:06:10.248846Z"}]}
{"channel":"book","type":"update","data":[{"symbol":"ETH/USDC","bids":[{"price":3799.72,"qty":0.33750000}],"asks":[],"checksum":592008401,"timestamp":"2024-06-01T18:06:10.252166Z"}]}
{"channel":"book","type":"update","data":[{"symbol":"ETH/USDC","bids":[{"price":3799.72,"qty":0.00000000},{"price":3797.88,"qty":0.40100000}],"asks":[],"checksum":3268586200,"timestamp":"2024-06-01T18:06:10.256007Z"}]}
{"channel":"book","type":"update","data":[{"symbol":"ETH/USDC","bids":[{"price":3799.72,"qty":0.33750000}],"asks":[],"checksum":592008401,"timestamp":"2024-06-01T18:06:10.259121Z"}]}
{"channel":"book","type":"update","data":[{"symbol":"ETH/USDC","bids":[{"price":3799.72,"qty":0.00000000},{"price":3797.88,"qty":0.40100000}],"asks":[],"checksum":3268586200,"timestamp":"2024-06-01T18:06:10.262905Z"}]}
{"channel":"book","type":"update","data":[{"symbol":"ETH/USDC","bids":[{"price":3799.75,"qty":0.33750000}],"asks":[],"checksum":2182293600,"timestamp":"2024-06-01T18:06:10.287731Z"}]}
{"channel":"book","type":"update","data":[{"symbol":"ETH/USDC","bids":[{"price":3799.75,"qty":0.00000000},{"price":3797.88,"qty":0.40100000}],"asks":[],"checksum":3268586200,"timestamp":"2024-06-01T18:06:10.292189Z"}]}
{"channel":"book","type":"update","data":[{"symbol":"ETH/USDC","bids":[{"price":3799.75,"qty":0.33750000}],"asks":[],"checksum":2182293600,"timestamp":"2024-06-01T18:06:10.304911Z"}]}
{"channel":"book","type":"update","data":[{"symbol":"ETH/USDC","bids":[{"price":3799.75,"qty":0.00000000},{"price":3797.88,"qty":0.40100000}],"asks":[],"checksum":3268586200,"timestamp":"2024-06-01T18:06:10.309018Z"}]}
{"channel":"book","type":"update","data":[{"symbol":"ETH/USDC","bids":[{"price":3799.76,"qty":0.33750000}],"asks":[],"checksum":1158792907,"timestamp":"2024-06-01T18:06:10.327724Z"}]}
{"channel":"book","type":"update","data":[{"symbol":"ETH/USDC","bids":[{"price":3799.76,"qty":0.00000000},{"price":3797.88,"qty":0.40100000}],"asks":[],"checksum":3268586200,"timestamp":"2024-06-01T18:06:10.331347Z"}]}
{"channel":"book","type":"update","data":[{"symbol":"ETH/USDC","bids":[{"price":3799.75,"qty":0.33750000}],"asks":[],"checksum":2182293600,"timestamp":"2024-06-01T18:06:10.343641Z"}]}
{"channel":"book","type":"update","data":[{"symbol":"ETH/USDC","bids":[{"price":3799.75,"qty":0.00000000},{"price":3797.88,"qty":0.40100000}],"asks":[],"checksum":3268586200,"timestamp":"2024-06-01T18:06:10.348299Z"}]}
{"channel":"book","type":"update","data":[{"symbol":"ETH/USDC","bids":[{"price":3799.74,"qty":0.33750000}],"asks":[],"checksum":1983745990,"timestamp":"2024-06-01T18:06:10.397551Z"}]}
{"channel":"book","type":"update","data":[{"symbol":"ETH/USDC","bids":[{"price":3799.74,"qty":0.00000000},{"price":3797.88,"qty":0.40100000}],"asks":[],"checksum":3268586200,"timestamp":"2024-06-01T18:06:10.402112Z"}]}
{"channel":"book","type":"update","data":[{"symbol":"ETH/USDC","bids":[{"price":3799.73,"qty":0.33750000}],"asks":[],"checksum":3613913975,"timestamp":"2024-06-01T18:06:10.410564Z"}]}
{"channel":"book","type":"update","data":[{"symbol":"ETH/USDC","bids":[{"price":3799.73,"qty":0.00000000},{"price":3797.88,"qty":0.40100000}],"asks":[],"checksum":3268586200,"timestamp":"2024-06-01T18:06:10.414130Z"}]}
{"channel":"book","type":"update","data":[{"symbol":"ETH/USDC","bids":[{"price":3799.76,"qty":0.33750000}],"asks":[],"checksum":1158792907,"timestamp":"2024-06-01T18:06:10.421277Z"}]}
{"channel":"book","type":"update","data":[{"symbol":"ETH/USDC","bids":[],"asks":[{"price":3802.15,"qty":0.00000000},{"price":3802.51,"qty":1.31492311}],"checksum":504705897,"timestamp":"2024-06-01T18:06:10.983372Z"}]}
{"channel":"book","type":"update","data":[{"symbol":"ETH/USDC","bids":[],"asks":[{"price":3801.76,"qty":0.01501305}],"checksum":3362222251,"timestamp":"2024-06-01T18:06:10.984800Z"}]}
{"channel":"book","type":"update","data":[{"symbol":"ETH/USDC","bids":[],"asks":[{"price":3802.13,"qty":0.21420305}],"checksum":1568520251,"timestamp":"2024-06-01T18:06:10.984840Z"}]}
{"channel":"book","type":"update","data":[{"symbol":"ETH/USDC","bids":[{"price":3798.13,"qty":0.00000000},{"price":3797.88,"qty":0.40100000}],"asks":[],"checksum":2581291560,"timestamp":"2024-06-01T18:06:11.180647Z"}]}
{"channel":"book","type":"update","data":[{"symbol":"ETH/USDC","bids":[{"price":3798.67,"qty":0.00000000},{"price":3797.61,"qty":0.25101585}],"asks":[],"checksum":2051052611,"timestamp":"2024-06-01T18:06:11.257625Z"}]}
{"channel":"book","type":"update","data":[{"symbol":"ETH/USDC","bids":[{"price":3798.88,"qty":0.00526226}],"asks":[],"checksum":928541556,"timestamp":"2024-06-01T18:06:11.259529Z"}]}
{"channel":"book","type":"update","data":[{"symbol":"ETH/USDC","bids":[{"price":3798.57,"qty":0.65767753}],"asks":[],"checksum":252325118,"timestamp":"2024-06-01T18:06:11.465318Z"}]}
{"channel":"book","type":"update","data":[{"symbol":"ETH/USDC","bids":[{"price":3799.71,"qty":0.00000000},{"price":3797.88,"qty":0.40100000}],"asks":[],"checksum":1571730446,"timestamp":"2024-06-01T18:06:11.687303Z"}]}
{"channel":"book","type":"update","data":[{"symbol":"ETH/USDC","bids":[{"price":3799.77,"qty":0.65793402}],"asks":[],"checksum":2817526002,"timestamp":"2024-06-01T18:06:11.691742Z"}]}
{"channel":"book","type":"update","data":[{"symbol":"ETH/USDC","bids":[{"price":3799.76,"qty":0.00000000},{"price":3797.88,"qty":0.40100000}],"asks":[],"checksum":1255907735,"timestamp":"2024-06-01T18:06:11.696270Z"}]}
{"channel":"book","type":"update","data":[{"symbol":"ETH/USDC","bids":[{"price":3799.94,"qty":0.33750000}],"asks":[],"checksum":321341490,"timestamp":"2024-06-01T18:06:11.699531Z"}]}
{"channel":"book","type":"update","data":[{"symbol":"ETH/USDC","bids":[{"price":3799.94,"qty":0.00000000},{"price":3797.88,"qty":0.40100000}],"asks":[],"checksum":1255907735,"timestamp":"2024-06-01T18:06:11.707704Z"}]}
{"channel":"book","type":"update","data":[{"symbol":"ETH/USDC","bids":[{"price":3799.97,"qty":0.33750000}],"asks":[],"checksum":3559237273,"timestamp":"2024-06-01T18:06:11.712306Z"}]}
{"channel":"book","type":"update","data":[{"symbol":"ETH/USDC","bids":[{"price":3799.97,"qty":0.00000000},{"price":3797.88,"qty":0.40100000}],"asks":[],"checksum":1255907735,"timestamp":"2024-06-01T18:06:11.717067Z"}]}
{"channel":"book","type":"update","data":[{"symbol":"ETH/USDC","bids":[{"price":3799.99,"qty":0.33750000}],"asks":[],"checksum":1306548666,"timestamp":"2024-06-01T18:06:11.720856Z"}]}
{"channel":"book","type":"update","data":[{"symbol":"ETH/USDC","bids":[{"price":3799.99,"qty":0.00000000},{"price":3797.88,"qty":0.40100000}],"asks":[],"checksum":1255907735,"timestamp":"2024-06-01T18:06:11.725315Z"}]}
{"channel":"book","type":"update","data":[{"symbol":"ETH/USDC","bids":[{"price":3799.85,"qty":0.33750000}],"asks":[],"checksum":3628648430,"timestamp":"2024-06-01T18:06:11.729153Z"}]}
{"channel":"book","type":"update","data":[{"symbol":"ETH/USDC","bids":[{"price":3799.77,"qty":0.00000000},{"price":3797.88,"qty":0.40100000}],"asks":[],"checksum":118736466,"timestamp":"2024-06-01T18:06:11.734142Z"}]}
{"channel":"book","type":"update","data":[{"symbol":"ETH/USDC","bids":[{"price":3798.57,"qty":0.00000000},{"price":3797.61,"qty":0.25101585}],"asks":[],"checksum":4105794003,"timestamp":"2024-06-01T18:06:11.749454Z"}]}
{"channel":"book","type":"update","data":[{"symbol":"ETH/USDC","bids":[],"asks":[{"price":3801.25,"qty":0.00000000},{"price":3802.39,"qty":19.54866870}],"checksum":2696000340,"timestamp":"2024-06-01T18:06:11.763297Z"}]}
{"channel":"book","type":"update","data":[{"symbol":"ETH/USDC","bids":[{"price":3799.85,"qty":0.67500000}],"asks":[],"checksum":3152975154,"timestamp":"2024-06-01T18:06:11.763940Z"}]}
{"channel":"book","type":"update","data":[{"symbol":"ETH/USDC","bids":[],"asks":[{"price":3801.07,"qty":0.00000000},{"price":3802.51,"qty":1.31492311}],"checksum":2756394879,"timestamp":"2024-06-01T18:06:11.772345Z"}]}
{"channel":"book","type":"update","data":[{"symbol":"ETH/USDC","bids":[],"asks":[{"price":3802.39,"qty":0.00000000},{"price":3802.58,"qty":0.33750000}],"checksum":2696412008,"timestamp":"2024-06-01T18:06:11.774549Z"}]}
{"channel":"book","type":"update","data":[{"symbol":"ETH/USDC","bids":[],"asks":[{"price":3802.44,"qty":17.20869515}],"checksum":3328581056,"timestamp":"2024-06-01T18:06:11.780932Z"}]}
{"channel":"book","type":"update","data":[{"symbol":"ETH/USDC","bids":[],"asks":[{"price":3802.14,"qty":0.00000000},{"price":3802.58,"qty":0.33750000}],"checksum":36678435,"timestamp":"2024-06-01T18:06:11.817769Z"}]}
{"channel":"book","type":"update","data":[{"symbol":"ETH/USDC","bids":[],"asks":[{"price":3802.29,"qty":0.00544195}],"checksum":2828915654,"timestamp":"2024-06-01T18:06:11.817820Z"}]}
{"channel":"book","type":"update","data":[{"symbol":"ETH/USDC","bids":[],"asks":[{"price":3802.29,"qty":0.00000000},{"price":3802.76,"qty":0.03955500}],"checksum":120823568,"timestamp":"2024-06-01T18:06:11.823075Z"}]}
{"channel":"book","type":"update","data":[{"symbol":"ETH/USDC","bids":[],"asks":[{"price":3801.76,"qty":1.57445062}],"checksum":1010930086,"timestamp":"2024-06-01T18:06:11.823178Z"}]}
{"channel":"book","type":"update","data":[{"symbol":"ETH/USDC","bids":[],"asks":[{"price":3802.38,"qty":21.16014857}],"checksum":3260728618,"timestamp":"2024-06-01T18:06:11.823313Z"}]}
{"channel":"book","type":"update","data":[{"symbol":"ETH/USDC","bids":[],"asks":[{"price":3802.43,"qty":0.00529585}],"checksum":273893612,"timestamp":"2024-06-01T18:06:11.823802Z"}]}
{"channel":"book","type":"update","data":[{"symbol":"ETH/USDC","bids":[{"price":3799.85,"qty":0.33750000}],"asks":[],"checksum":185364106,"timestamp":"2024-06-01T18:06:11.884741Z"}]}
{"channel":"book","type":"update","data":[{"symbol":"ETH/USDC","bids":[],"asks":[{"price":3802.44,"qty":0.00000000},{"price":3802.58,"qty":0.33750000}],"checksum":774336390,"timestamp":"2024-06-01T18:06:11.920586Z"}]}
{"channel":"book","type":"update","data":[{"symbol":"ETH/USDC","bids":[],"asks":[{"price":3802.48,"qty":11.61179515}],"checksum":3143821703,"timestamp":"2024-06-01T18:06:11.925789Z"}]}
{"channel":"book","type":"update","data":[{"symbol":"ETH/USDC","bids":[{"price":3798.83,"qty":0.37000000}],"asks":[],"checksum":3995961398,"timestamp":"2024-06-01T18:06:11.927154Z"}]}
{"channel":"book","type":"update","data":[{"symbol":"ETH/USDC","bids":[{"price":3798.88,"qty":1.55824217}],"asks":[],"checksum":3865950761,"timestamp":"2024-06-01T18:06:11.969561Z"}]}
{"channel":"book","type":"update","data":[{"symbol":"ETH/USDC","bids":[],"asks":[{"price":3802.48,"qty":0.00000000},{"price":3802.58,"qty":0.33750000}],"checksum":2361416281,"timestamp":"2024-06-01T18:06:11.977235Z"}]}
{"channel":"book","type":"update","data":[{"symbol":"ETH/USDC","bids":[{"price":3798.65,"qty":0.33750000}],"asks":[],"checksum":87977176,"timestamp":"2024-06-01T18:06:11.994825Z"}]}
{"channel":"book","type":"update","data":[{"symbol":"ETH/USDC","bids":[],"asks":[{"price":3801.26,"qty":0.00000000},{"price":3802.59,"qty":19.39189515}],"checksum":217182279,"timestamp":"2024-06-01T18:06:11.994976Z"}]}
{"channel":"book","type":"update","data":[{"symbol":"ETH/USDC","bids":[],"asks":[{"price":3801.57,"qty":0.33750000}],"checksum":1562012540,"timestamp":"2024-06-01T18:06:12.001053Z"}]}
{"channel":"book","type":"update","data":[{"symbol":"ETH/USDC","bids":[],"asks":[{"price":3801.64,"qty":0.65761228}],"checksum":1376580453,"timestamp":"2024-06-01T18:06:12.006188Z"}]}
{"channel":"book","type":"update","data":[{"symbol":"ETH/USDC","bids":[{"price":3800.23,"qty":0.65785430}],"asks":[],"checksum":2037771568,"timestamp":"2024-06-01T18:06:12.006203Z"}]}
{"channel":"book","type":"update","data":[{"symbol":"ETH/USDC","bids":[{"price":3799.19,"qty":1.31606678}],"asks":[],"checksum":2184541569,"timestamp":"2024-06-01T18:06:12.006242Z"}]}
{"channel":"book","type":"update","data":[{"symbol":"ETH/USDC","bids":[{"price":3800.43,"qty":0.33750000}],"asks":[],"checksum":2791171307,"timestamp":"2024-06-01T18:06:12.012916Z"}]}
{"channel":"book","type":"update","data":[{"symbol":"ETH/USDC","bids":[{"price":3800.23,"qty":0.00000000},{"price":3798.22,"qty":0.33750000}],"asks":[],"checksum":4108310091,"timestamp":"2024-06-01T18:06:12.023669Z"}]}
{"channel":"book","type":"update","data":[{"symbol":"ETH/USDC","bids":[{"price":3798.60,"qty":0.67500000}],"asks":[],"checksum":844178485,"timestamp":"2024-06-01T18:06:12.039364Z"}]}
{"channel":"book","type":"update","data":[{"symbol":"ETH/USDC","bids":[{"price":3800.43,"qty":0.00000000},{"price":3798.22,"qty":0.33750000}],"asks":[],"checksum":2633334677,"timestamp":"2024-06-01T18:06:12.168290Z"}]}
{"channel":"book","type":"update","data":[{"symbol":"ETH/USDC","bids":[],"asks":[{"price":3801.64,"qty":0.00000000},{"price":3802.58,"qty":0.33750000}],"checksum":2481186700,"timestamp":"2024-06-01T18:06:12.225725Z"}]}
{"channel":"book","type":"update","data":[{"symbol":"ETH/USDC","bids":[],"asks":[{"price":3801.76,"qty":1.55943757}],"checksum":290467270,"timestamp":"2024-06-01T18:06:13.533418Z"}]}
{"channel":"book","type":"update","data":[{"symbol":"ETH/USDC","bids":[],"asks":[{"price":3802.13,"qty":0.00000000},{"price":3802.66,"qty":14.71069515}],"checksum":2371064325,"timestamp":"2024-06-01T18:06:13.533552Z"}]}
{"channel":"book","type":"update","data":[{"symbol":"ETH/USDC","bids":[],"asks":[{"price":3801.75,"qty":0.02151303}],"checksum":2723711611,"timestamp":"2024-06-01T18:06:13.535373Z"}]}
{"channel":"book","type":"update","data":[{"symbol":"ETH/USDC","bids":[],"asks":[{"price":3802.37,"qty":0.24317451}],"checksum":4184675702,"timestamp":"2024-06-01T18:06:13.535443Z"}]}
{"channel":"book","type":"update","data":[{"symbol":"ETH/USDC","bids":[],"asks":[{"price":3801.55,"qty":1.31545697}],"checksum":3151254517,"timestamp":"2024-06-01T18:06:13.626338Z"}]}
{"channel":"book","type":"update","data":[{"symbol":"ETH/USDC","bids":[],"asks":[{"price":3801.77,"qty":0.00000000},{"price":3802.51,"qty":1.31492311}],"checksum":3703706770,"timestamp":"2024-06-01T18:06:13.627475Z"}]}
{"channel":"book","type":"update","data":[{"symbol":"ETH/USDC","bids":[],"asks":[{"price":3801.36,"qty":0.33750000}],"checksum":1776616988,"timestamp":"2024-06-01T18:06:13.630402Z"}]}
{"channel":"book","type":"update","data":[{"symbol":"ETH/USDC","bids":[],"asks":[{"price":3801.19,"qty":0.33750000}],"checksum":637593131,"timestamp":"2024-06-01T18:06:13.630633Z"}]}
{"channel":"book","type":"update","data":[{"symbol":"ETH/USDC","bids":[],"asks":[{"price":3801.54,"qty":0.65762943}],"checksum":2736780205,"timestamp":"2024-06-01T18:06:13.631949Z"}]}
{"channel":"book","type":"update","data":[{"symbol":"ETH/USDC","bids":[{"price":3800.21,"qty":0.65785739}],"asks":[],"checksum":645539647,"timestamp":"2024-06-01T18:06:13.632157Z"}]}
{"channel":"book","type":"update","data":[{"symbol":"ETH/USDC","bids":[],"asks":[{"price":3801.19,"qty":0.67500000}],"checksum":4240765740,"timestamp":"2024-06-01T18:06:13.634564Z"}]}
{"channel":"book","type":"update","data":[{"symbol":"ETH/USDC","bids":[],"asks":[{"price":3801.57,"qty":0.00000000},{"price":3802.38,"qty":21.16014857}],"checksum":2461665293,"timestamp":"2024-06-01T18:06:13.635319Z"}]}
{"channel":"book","type":"update","data":[{"symbol":"ETH/USDC","bids":[],"asks":[{"price":3801.36,"qty":0.00000000},{"price":3802.43,"qty":0.00529585}],"checksum":1046687491,"timestamp":"2024-06-01T18:06:13.635565Z"}]}
{"channel":"book","type":"update","data":[{"symbol":"ETH/USDC","bids":[{"price":3800.21,"qty":0.00000000},{"price":3798.22,"qty":0.33750000}],"asks":[],"checksum":3137797009,"timestamp":"2024-06-01T18:06:13.637075Z"}]}
{"channel":"book","type":"update","data":[{"symbol":"ETH/USDC","bids":[{"price":3799.85,"qty":0.00000000},{"price":3798.07,"qty":1.31645616}],"asks":[],"checksum":1249546276,"timestamp":"2024-06-01T18:06:13.661889Z"}]}
{"channel":"book","type":"update","data":[{"symbol":"ETH/USDC","bids":[{"price":3799.24,"qty":1.31544283}],"asks":[],"checksum":2946596703,"timestamp":"2024-06-01T18:06:13.664821Z"}]}
{"channel":"book","type":"update","data":[{"symbol":"ETH/USDC","bids":[{"price":3799.62,"qty":0.33750000}],"asks":[],"checksum":2468204036,"timestamp":"2024-06-01T18:06:13.669190Z"}]}
{"channel":"book","type":"update","data":[{"symbol":"ETH/USDC","bids":[],"asks":[{"price":3801.76,"qty":0.00000000},{"price":3802.51,"qty":1.31492311}],"checksum":79241017,"timestamp":"2024-06-01T18:06:14.151003Z"}]}
{"channel":"book","type":"update","data":[{"symbol":"ETH/USDC","bids":[],"asks":[{"price":3802.38,"qty":0.00000000},{"price":3802.58,"qty":0.33750000}],"checksum":4133109976,"timestamp":"2024-06-01T18:06:14.151169Z"}]}
{"channel":"book","type":"update","data":[{"symbol":"ETH/USDC","bids":[],"asks":[{"price":3801.53,"qty":0.52617437}],"checksum":1372705846,"timestamp":"2024-06-01T18:06:14.155825Z"}]}
{"channel":"book","type":"update","data":[{"symbol":"ETH/USDC","bids":[],"asks":[{"price":3802.50,"qty":18.59780547}],"checksum":1509633717,"timestamp":"2024-06-01T18:06:14.155880Z"}]}
{"channel":"book","type":"update","data":[{"symbol":"ETH/USDC","bids":[],"asks":[{"price":3802.43,"qty":0.00000000},{"price":3802.51,"qty":1.31492311}],"checksum":4025517853,"timestamp":"2024-06-01T18:06:14.156069Z"}]}
{"channel":"book","type":"update","data":[{"symbol":"ETH/USDC","bids":[{"price":3798.88,"qty":1.55297991}],"asks":[],"checksum":4072630531,"timestamp":"2024-06-01T18:06:14.214115Z"}]}
{"channel":"book","type":"update","data":[{"symbol":"ETH/USDC","bids":[{"price":3799.25,"qty":0.02579488}],"asks":[],"checksum":3688270226,"timestamp":"2024-06-01T18:06:14.215254Z"}]}
{"channel":"book","type":"update","data":[{"symbol":"ETH/USDC","bids":[{"price":3798.89,"qty":0.07712771}],"asks":[],"checksum":1714980128,"timestamp":"2024-06-01T18:06:14.215403Z"}]}
{"channel":"book","type":"update","data":[{"symbol":"ETH/USDC","bids":[],"asks":[{"price":3802.49,"qty":0.00545210}],"checksum":1254073839,"timestamp":"2024-06-01T18:06:14.218669Z"}]}
{"channel":"book","type":"update","data":[{"symbol":"ETH/USDC","bids":[{"price":3799.86,"qty":0.65791809}],"asks":[],"checksum":428898189,"timestamp":"2024-06-01T18:06:14.961162Z"}]}
{"channel":"book","type":"update","data":[{"symbol":"ETH/USDC","bids":[{"price":3800.02,"qty":0.33750000}],"asks":[],"checksum":886776662,"timestamp":"2024-06-01T18:06:15.007552Z"}]}
{"channel":"book","type":"update","data":[{"symbol":"ETH/USDC","bids":[{"price":3800.02,"qty":0.00000000},{"price":3798.83,"qty":0.37000000}],"asks":[],"checksum":428898189,"timestamp":"2024-06-01T18:06:15.011106Z"}]}
{"channel":"book","type":"update","data":[{"symbol":"ETH/USDC","bids":[{"price":3799.86,"qty":0.00000000},{"price":3798.65,"qty":0.33750000}],"asks":[],"checksum":1254073839,"timestamp":"2024-06-01T18:06:15.012548Z"}]}
{"channel":"book","type":"update","data":[{"symbol":"ETH/USDC","bids":[{"price":3799.63,"qty":0.65795781}],"asks":[],"checksum":436076920,"timestamp":"2024-06-01T18:06:15.295413Z"}]}
{"channel":"book","type":"update","data":[{"symbol":"ETH/USDC","bids":[{"price":3798.88,"qty":0.00000000},{"price":3798.65,"qty":0.33750000}],"asks":[],"checksum":1021819582,"timestamp":"2024-06-01T18:06:15.600615Z"}]}
{"channel":"book","type":"update","data":[{"symbol":"ETH/USDC","bids":[{"price":3799.25,"qty":1.57862590}],"asks":[],"checksum":2811200753,"timestamp":"2024-06-01T18:06:15.601862Z"}]}
{"channel":"book","type":"update","data":[{"symbol":"ETH/USDC","bids":[{"price":3799.63,"qty":0.00000000},{"price":3798.60,"qty":0.67500000}],"asks":[],"checksum":3566443420,"timestamp":"2024-06-01T18:06:15.764839Z"}]}
{"channel":"book","type":"update","data":[{"symbol":"ETH/USDC","bids":[{"price":3799.97,"qty":0.65789912}],"asks":[],"checksum":3315018413,"timestamp":"2024-06-01T18:06:15.769340Z"}]}
{"channel":"book","type":"update","data":[{"symbol":"ETH/USDC","bids":[],"asks":[{"price":3801.75,"qty":0.00000000},{"price":3802.51,"qty":1.31492311}],"checksum":2871013602,"timestamp":"2024-06-01T18:06:16.079778Z"}]}
{"channel":"book","type":"update","data":[{"symbol":"ETH/USDC","bids":[],"asks":[{"price":3802.37,"qty":0.00000000},{"price":3802.58,"qty":0.33750000}],"checksum":2121885806,"timestamp":"2024-06-01T18:06:16.079956Z"}]}
{"channel":"book","type":"update","data":[{"symbol":"ETH/USDC","bids":[],"asks":[{"price":3801.52,"qty":0.00526197}],"checksum":2126703147,"timestamp":"2024-06-01T18:06:16.082263Z"}]}
{"channel":"book","type":"update","data":[{"symbol":"ETH/USDC","bids":[],"asks":[{"price":3802.49,"qty":0.20696834}],"checksum":2691739376,"timestamp":"2024-06-01T18:06:16.082405Z"}]}
{"channel":"book","type":"update","data":[{"symbol":"ETH/USDC","bids":[],"asks":[{"price":3801.81,"qty":0.00000000},{"price":3802.58,"qty":0.33750000}],"checksum":919511055,"timestamp":"2024-06-01T18:06:16.368699Z"}]}
{"channel":"book","type":"update","data":[{"symbol":"ETH/USDC","bids":[],"asks":[{"price":3801.53,"qty":0.00000000},{"price":3802.66,"qty":14.71069515}],"checksum":3469425106,"timestamp":"2024-06-01T18:06:16.613764Z"}]}
{"channel":"book","type":"update","data":[{"symbol":"ETH/USDC","bids":[],"asks":[{"price":3802.50,"qty":0.00000000},{"price":3802.76,"qty":0.03955500}],"checksum":771128597,"timestamp":"2024-06-01T18:06:16.613857Z"}]}
{"channel":"book","type":"update","data":[{"symbol":"ETH/USDC","bids":[],"asks":[{"price":3802.65,"qty":0.00515264}],"checksum":1559202978,"timestamp":"2024-06-01T18:06:16.618473Z"}]}
{"channel":"book","type":"update","data":[{"symbol":"ETH/USDC","bids":[],"asks":[{"price":3802.49,"qty":0.20151624}],"checksum":3577338763,"timestamp":"2024-06-01T18:06:16.618781Z"}]}
{"channel":"book","type":"update","data":[{"symbol":"ETH/USDC","bids":[],"asks":[{"price":3802.48,"qty":18.07237066}],"checksum":5121249,"timestamp":"2024-06-01T18:06:16.619029Z"}]}
{"channel":"book","type":"update","data":[{"symbol":"ETH/USDC","bids":[],"asks":[{"price":3801.53,"qty":1.04280286}],"checksum":3388871793,"timestamp":"2024-06-01T18:06:16.619137Z"}]}
{"channel":"book","type":"update","data":[{"symbol":"ETH/USDC","bids":[],"asks":[{"price":3802.47,"qty":0.00543322}],"checksum":3385389552,"timestamp":"2024-06-01T18:06:16.689323Z"}]}
{"channel":"book","type":"update","data":[{"symbol":"ETH/USDC","bids":[],"asks":[{"price":3801.54,"qty":0.00000000},{"price":3802.58,"qty":0.33750000}],"checksum":108290462,"timestamp":"2024-06-01T18:06:16.723030Z"}]}
{"channel":"book","type":"update","data":[{"symbol":"ETH/USDC","bids":[],"asks":[{"price":3801.19,"qty":1.33268932}],"checksum":59781670,"timestamp":"2024-06-01T18:06:16.727065Z"}]}
{"channel":"book","type":"update","data":[{"symbol":"ETH/USDC","bids":[],"asks":[{"price":3801.00,"qty":0.33750000}],"checksum":2861774920,"timestamp":"2024-06-01T18:06:16.730988Z"}]}
{"channel":"book","type":"update","data":[{"symbol":"ETH/USDC","bids":[{"price":3798.87,"qty":0.00000000},{"price":3798.60,"qty":0.67500000}],"asks":[],"checksum":701332104,"timestamp":"2024-06-01T18:06:16.734295Z"}]}
{"channel":"book","type":"update","data":[{"symbol":"ETH/USDC","bids":[{"price":3799.62,"qty":0.00000000},{"price":3798.50,"qty":0.41138460}],"asks":[],"checksum":3427945685,"timestamp":"2024-06-01T18:06:16.734949Z"}]}
{"channel":"book","type":"update","data":[{"symbol":"ETH/USDC","bids":[{"price":3799.27,"qty":0.78640776}],"asks":[],"checksum":2831188769,"timestamp":"2024-06-01T18:06:16.737165Z"}]}
{"channel":"book","type":"update","data":[{"symbol":"ETH/USDC","bids":[{"price":3799.25,"qty":1.55283102}],"asks":[],"checksum":1420424984,"timestamp":"2024-06-01T18:06:16.929274Z"}]}
{"channel":"book","type":"update","data":[{"symbol":"ETH/USDC","bids":[{"price":3798.89,"qty":0.00000000},{"price":3798.50,"qty":0.41138460}],"asks":[],"checksum":662343862,"timestamp":"2024-06-01T18:06:16.929505Z"}]}
{"channel":"book","type":"update","data":[{"symbol":"ETH/USDC","bids":[{"price":3799.26,"qty":0.01552898}],"asks":[],"checksum":4177311489,"timestamp":"2024-06-01T18:06:16.930624Z"}]}
{"channel":"book","type":"update","data":[{"symbol":"ETH/USDC","bids":[{"price":3798.83,"qty":0.00000000},{"price":3798.50,"qty":0.41138460}],"asks":[],"checksum":1320014267,"timestamp":"2024-06-01T18:06:16.982814Z"}]}
{"channel":"book","type":"update","data":[{"symbol":"ETH/USDC","bids":[{"price":3798.60,"qty":0.00000000},{"price":3798.22,"qty":0.33750000}],"asks":[],"checksum":2284004293,"timestamp":"2024-06-01T18:06:17.090202Z"}]}
{"channel":"book","type":"update","data":[{"symbol":"ETH/USDC","bids":[{"price":3798.33,"qty":0.78640776}],"asks":[],"checksum":2743523802,"timestamp":"2024-06-01T18:06:17.377996Z"}]}
{"channel":"book","type":"update","data":[{"symbol":"ETH/USDC","bids":[{"price":3798.33,"qty":0.00000000},{"price":3798.22,"qty":0.33750000}],"asks":[],"checksum":2284004293,"timestamp":"2024-06-01T18:06:17.663016Z"}]}
{"channel":"book","type":"update","data":[{"symbol":"ETH/USDC","bids":[{"price":3798.32,"qty":0.78640776}],"asks":[],"checksum":3036532121,"timestamp":"2024-06-01T18:06:17.927764Z"}]}
{"channel":"book","type":"update","data":[{"symbol":"ETH/USDC","bids":[{"price":3799.24,"qty":0.00000000},{"price":3798.22,"qty":0.33750000}],"asks":[],"checksum":3263515613,"timestamp":"2024-06-01T18:06:18.346945Z"}]}
{"channel":"book","type":"update","data":[{"symbol":"ETH/USDC","bids":[{"price":3799.97,"qty":0.00000000},{"price":3798.10,"qty":0.49697747}],"asks":[],"checksum":2695407281,"timestamp":"2024-06-01T18:06:18.413091Z"}]}
{"channel":"book","type":"update","data":[{"symbol":"ETH/USDC","bids":[{"price":3799.62,"qty":0.65795929}],"asks":[],"checksum":2753492243,"timestamp":"2024-06-01T18:06:18.418187Z"}]}
{"channel":"book","type":"update","data":[{"symbol":"ETH/USDC","bids":[{"price":3798.32,"qty":0.00000000},{"price":3798.10,"qty":0.49697747}],"asks":[],"checksum":1831528094,"timestamp":"2024-06-01T18:06:18.476759Z"}]}
{"channel":"book","type":"update","data":[{"symbol":"ETH/USDC","bids":[],"asks":[{"price":3802.49,"qty":0.00000000},{"price":3802.58,"qty":0.33750000}],"checksum":3401105519,"timestamp":"2024-06-01T18:06:18.631822Z"}]}
{"channel":"book","type":"update","data":[{"symbol":"ETH/USDC","bids":[],"asks":[{"price":3801.52,"qty":0.00000000},{"price":3802.66,"qty":14.71069515}],"checksum":3479300555,"timestamp":"2024-06-01T18:06:18.631935Z"}]}
{"channel":"book","type":"update","data":[{"symbol":"ETH/USDC","bids":[],"asks":[{"price":3802.47,"qty":0.18945960}],"checksum":2638347298,"timestamp":"2024-06-01T18:06:18.633891Z"}]}
{"channel":"book","type":"update","data":[{"symbol":"ETH/USDC","bids":[{"price":3798.30,"qty":0.78640776}],"asks":[],"checksum":3118677062,"timestamp":"2024-06-01T18:06:18.754942Z"}]}
{"channel":"book","type":"update","data":[{"symbol":"ETH/USDC","bids":[],"asks":[{"price":3802.48,"qty":0.00000000},{"price":3802.76,"qty":0.03955500}],"checksum":2884542710,"timestamp":"2024-06-01T18:06:19.022890Z"}]}
{"channel":"book","type":"update","data":[{"symbol":"ETH/USDC","bids":[],"asks":[{"price":3801.53,"qty":0.00000000},{"price":3803.00,"qty":0.00932482}],"checksum":2858442592,"timestamp":"2024-06-01T18:06:19.023053Z"}]}
{"channel":"book","type":"update","data":[{"symbol":"ETH/USDC","bids":[],"asks":[{"price":3802.65,"qty":0.00506973}],"checksum":1551797819,"timestamp":"2024-06-01T18:06:19.027059Z"}]}
{"channel":"book","type":"update","data":[{"symbol":"ETH/USDC","bids":[],"asks":[{"price":3802.47,"qty":0.18402638}],"checksum":868230502,"timestamp":"2024-06-01T18:06:19.027141Z"}]}
{"channel":"book","type":"update","data":[{"symbol":"ETH/USDC","bids":[],"asks":[{"price":3802.46,"qty":6.20885982}],"checksum":3757575563,"timestamp":"2024-06-01T18:06:19.028012Z"}]}
{"channel":"book","type":"update","data":[{"symbol":"ETH/USDC","bids":[],"asks":[{"price":3802.50,"qty":10.79045013}],"checksum":1785980333,"timestamp":"2024-06-01T18:06:19.028352Z"}]}
{"channel":"book","type":"update","data":[{"symbol":"ETH/USDC","bids":[{"price":3799.63,"qty":0.33750000}],"asks":[],"checksum":2746642316,"timestamp":"2024-06-01T18:06:19.032816Z"}]}
{"channel":"book","type":"update","data":[{"symbol":"ETH/USDC","bids":[{"price":3799.63,"qty":0.00000000},{"price":3798.22,"qty":0.33750000}],"asks":[],"checksum":1785980333,"timestamp":"2024-06-01T18:06:19.036445Z"}]}
{"channel":"book","type":"update","data":[{"symbol":"ETH/USDC","bids":[{"price":3799.62,"qty":0.00000000},{"price":3798.11,"qty":3.55776000}],"asks":[],"checksum":1514866599,"timestamp":"2024-06-01T18:06:19.038368Z"}]}
{"channel":"book","type":"update","data":[{"symbol":"ETH/USDC","bids":[{"price":3799.64,"qty":0.65795642}],"asks":[],"checksum":1970723776,"timestamp":"2024-06-01T18:06:19.042967Z"}]}
{"channel":"book","type":"update","data":[{"symbol":"ETH/USDC","bids":[{"price":3799.68,"qty":0.33750000}],"asks":[],"checksum":2548007280,"timestamp":"2024-06-01T18:06:19.056424Z"}]}
{"channel":"book","type":"update","data":[{"symbol":"ETH/USDC","bids":[{"price":3799.68,"qty":0.00000000},{"price":3798.22,"qty":0.33750000}],"asks":[],"checksum":1970723776,"timestamp":"2024-06-01T18:06:19.060364Z"}]}
{"channel":"book","type":"update","data":[{"symbol":"ETH/USDC","bids":[{"price":3799.68,"qty":0.33750000}],"asks":[],"checksum":2548007280,"timestamp":"2024-06-01T18:06:19.063872Z"}]}
{"channel":"book","type":"update","data":[{"symbol":"ETH/USDC","bids":[{"price":3799.68,"qty":0.00000000},{"price":3798.22,"qty":0.33750000}],"asks":[],"checksum":1970723776,"timestamp":"2024-06-01T18:06:19.067996Z"}]}
{"channel":"book","type":"update","data":[{"symbol":"ETH/USDC","bids":[{"price":3798.30,"qty":0.00000000},{"price":3798.10,"qty":0.49697747}],"asks":[],"checksum":1372855204,"timestamp":"2024-06-01T18:06:19.076430Z"}]}
{"channel":"book","type":"update","data":[{"symbol":"ETH/USDC","bids":[{"price":3799.72,"qty":0.33750000}],"asks":[],"checksum":1793231813,"timestamp":"2024-06-01T18:06:19.078038Z"}]}
{"channel":"book","type":"update","data":[{"symbol":"ETH/USDC","bids":[{"price":3799.72,"qty":0.00000000},{"price":3798.10,"qty":0.49697747}],"asks":[],"checksum":1372855204,"timestamp":"2024-06-01T18:06:19.082436Z"}]}
{"channel":"book","type":"update","data":[{"symbol":"ETH/USDC","bids":[{"price":3799.74,"qty":0.33750000}],"asks":[],"checksum":3915676377,"timestamp":"2024-06-01T18:06:19.085628Z"}]}
{"channel":"book","type":"update","data":[{"symbol":"ETH/USDC","bids":[{"price":3799.74,"qty":0.00000000},{"price":3798.10,"qty":0.49697747}],"asks":[],"checksum":1372855204,"timestamp":"2024-06-01T18:06:19.088657Z"}]}
{"channel":"book","type":"update","data":[{"symbol":"ETH/USDC","bids":[{"price":3799.70,"qty":0.33750000}],"asks":[],"checksum":341891889,"timestamp":"2024-06-01T18:06:19.099374Z"}]}
{"channel":"book","type":"update","data":[{"symbol":"ETH/USDC","bids":[{"price":3799.70,"qty":0.00000000},{"price":3798.10,"qty":0.49697747}],"asks":[],"checksum":1372855204,"timestamp":"2024-06-01T18:06:19.103444Z"}]}
{"channel":"book","type":"update","data":[{"symbol":"ETH/USDC","bids":[{"price":3799.71,"qty":0.33750000}],"asks":[],"checksum":723645259,"timestamp":"2024-06-01T18:06:19.106617Z"}]}
{"channel":"book","type":"update","data":[{"symbol":"ETH/USDC","bids":[{"price":3799.71,"qty":0.00000000},{"price":3798.10,"qty":0.49697747}],"asks":[],"checksum":1372855204,"timestamp":"2024-06-01T18:06:19.110440Z"}]}
{"channel":"book","type":"update","data":[{"symbol":"ETH/USDC","bids":[{"price":3799.71,"qty":0.33750000}],"asks":[],"checksum":723645259,"timestamp":"2024-06-01T18:06:19.127141Z"}]}
{"channel":"book","type":"update","data":[{"symbol":"ETH/USDC","bids":[{"price":3799.71,"qty":0.00000000},{"price":3798.10,"qty":0.49697747}],"asks":[],"checksum":1372855204,"timestamp":"2024-06-01T18:06:19.130572Z"}]}
{"channel":"book","type":"update","data":[{"symbol":"ETH/USDC","bids":[],"asks":[{"price":3802.49,"qty":0.00519130}],"checksum":3193179059,"timestamp":"2024-06-01T18:06:19.153572Z"}]}
{"channel":"book","type":"update","data":[{"symbol":"ETH/USDC","bids":[{"price":3799.71,"qty":0.33750000}],"asks":[],"checksum":3298943836,"timestamp":"2024-06-01T18:06:19.156151Z"}]}
{"channel":"book","type":"update","data":[{"symbol":"ETH/USDC","bids":[{"price":3799.71,"qty":0.00000000},{"price":3798.10,"qty":0.49697747}],"asks":[],"checksum":3193179059,"timestamp":"2024-06-01T18:06:19.160151Z"}]}
{"channel":"book","type":"update","data":[{"symbol":"ETH/USDC","bids":[{"price":3799.73,"qty":0.33750000}],"asks":[],"checksum":3122901928,"timestamp":"2024-06-01T18:06:19.167575Z"}]}
{"channel":"book","type":"update","data":[{"symbol":"ETH/USDC","bids":[{"price":3799.73,"qty":0.00000000},{"price":3798.10,"qty":0.49697747}],"asks":[],"checksum":3193179059,"timestamp":"2024-06-01T18:06:19.172034Z"}]}
{"channel":"book","type":"update","data":[{"symbol":"ETH/USDC","bids":[{"price":3799.70,"qty":0.33750000}],"asks":[],"checksum":4225813286,"timestamp":"2024-06-01T18:06:19.180611Z"}]}
{"channel":"book","type":"update","data":[{"symbol":"ETH/USDC","bids":[{"price":3799.70,"qty":0.00000000},{"price":3798.10,"qty":0.49697747}],"asks":[],"checksum":3193179059,"timestamp":"2024-06-01T18:06:19.184013Z"}]}
{"channel":"book","type":"update","data":[{"symbol":"ETH/USDC","bids":[{"price":3799.70,"qty":0.33750000}],"asks":[],"checksum":4225813286,"timestamp":"2024-06-01T18:06:19.187063Z"}]}
{"channel":"book","type":"update","data":[{"symbol":"ETH/USDC","bids":[{"price":3799.70,"qty":0.00000000},{"price":3798.10,"qty":0.49697747}],"asks":[],"checksum":3193179059,"timestamp":"2024-06-01T18:06:19.190156Z"}]}
{"channel":"book","type":"update","data":[{"symbol":"ETH/USDC","bids":[{"price":3799.68,"qty":0.33750000}],"asks":[],"checksum":1786206141,"timestamp":"2024-06-01T18:06:19.196925Z"}]}
{"channel":"book","type":"update","data":[{"symbol":"ETH/USDC","bids":[{"price":3799.68,"qty":0.00000000},{"price":3798.10,"qty":0.49697747}],"asks":[],"checksum":3193179059,"timestamp":"2024-06-01T18:06:19.200283Z"}]}
{"channel":"book","type":"update","data":[{"symbol":"ETH/USDC","bids":[{"price":3799.72,"qty":0.33750000}],"asks":[],"checksum":2237832146,"timestamp":"2024-06-01T18:06:19.202841Z"}]}
{"channel":"book","type":"update","data":[{"symbol":"ETH/USDC","bids":[{"price":3799.72,"qty":0.00000000},{"price":3798.10,"qty":0.49697747}],"asks":[],"checksum":3193179059,"timestamp":"2024-06-01T18:06:19.205735Z"}]}
{"channel":"book","type":"update","data":[{"symbol":"ETH/USDC","bids":[{"price":3799.71,"qty":0.33750000}],"asks":[],"checksum":3298943836,"timestamp":"2024-06-01T18:06:19.212315Z"}]}
{"channel":"book","type":"update","data":[{"symbol":"ETH/USDC","bids":[{"price":3799.25,"qty":0.00000000},{"price":3798.10,"qty":0.49697747}],"asks":[],"checksum":1219050031,"timestamp":"2024-06-01T18:06:19.213450Z"}]}
{"channel":"book","type":"update","data":[{"symbol":"ETH/USDC","bids":[{"price":3798.31,"qty":10.79320814}],"asks":[],"checksum":1461578565,"timestamp":"2024-06-01T18:06:19.215225Z"}]}
{"channel":"book","type":"update","data":[{"symbol":"ETH/USDC","bids":[{"price":3799.71,"qty":0.00000000},{"price":3798.10,"qty":0.49697747}],"asks":[],"checksum":854369119,"timestamp":"2024-06-01T18:06:19.215965Z"}]}
{"channel":"book","type":"update","data":[{"symbol":"ETH/USDC","bids":[{"price":3799.65,"qty":0.33750000}],"asks":[],"checksum":424969065,"timestamp":"2024-06-01T18:06:19.222635Z"}]}
{"channel":"book","type":"update","data":[{"symbol":"ETH/USDC","bids":[{"price":3799.65,"qty":0.00000000},{"price":3798.10,"qty":0.49697747}],"asks":[],"checksum":854369119,"timestamp":"2024-06-01T18:06:19.227007Z"}]}
{"channel":"book","type":"update","data":[{"symbol":"ETH/USDC","bids":[{"price":3799.64,"qty":0.00000000},{"price":3798.07,"qty":1.31645616}],"asks":[],"checksum":2894676017,"timestamp":"2024-06-01T18:06:19.227205Z"}]}
{"channel":"book","type":"update","data":[{"symbol":"ETH/USDC","bids":[{"price":3799.65,"qty":0.33750000}],"asks":[],"checksum":144996829,"timestamp":"2024-06-01T18:06:19.230643Z"}]}
{"channel":"book","type":"update","data":[{"symbol":"ETH/USDC","bids":[{"price":3799.65,"qty":0.00000000},{"price":3798.07,"qty":1.31645616}],"asks":[],"checksum":2894676017,"timestamp":"2024-06-01T18:06:19.234430Z"}]}
{"channel":"book","type":"update","data":[{"symbol":"ETH/USDC","bids":[{"price":3799.67,"qty":0.33750000}],"asks":[],"checksum":2987052424,"timestamp":"2024-06-01T18:06:19.237605Z"}]}
{"channel":"book","type":"update","data":[{"symbol":"ETH/USDC","bids":[{"price":3799.67,"qty":0.00000000},{"price":3798.07,"qty":1.31645616}],"asks":[],"checksum":2894676017,"timestamp":"2024-06-01T18:06:19.241075Z"}]}
{"channel":"book","type":"update","data":[{"symbol":"ETH/USDC","bids":[{"price":3799.67,"qty":0.33750000}],"asks":[],"checksum":2987052424,"timestamp":"2024-06-01T18:06:19.244456Z"}]}
{"channel":"book","type":"update","data":[{"symbol":"ETH/USDC","bids":[{"price":3799.67,"qty":0.00000000},{"price":3798.07,"qty":1.31645616}],"asks":[],"checksum":2894676017,"timestamp":"2024-06-01T18:06:19.247482Z"}]}
{"channel":"book","type":"update","data":[{"symbol":"ETH/USDC","bids":[{"price":3799.60,"qty":0.33750000}],"asks":[],"checksum":375901756,"timestamp":"2024-06-01T18:06:19.262284Z"}]}
{"channel":"book","type":"update","data":[{"symbol":"ETH/USDC","bids":[{"price":3799.60,"qty":0.00000000},{"price":3798.07,"qty":1.31645616}],"asks":[],"checksum":2894676017,"timestamp":"2024-06-01T18:06:19.266746Z"}]}
{"channel":"book","type":"update","data":[{"symbol":"ETH/USDC","bids":[{"price":3799.60,"qty":0.33750000}],"asks":[],"checksum":375901756,"timestamp":"2024-06-01T18:06:19.273476Z"}]}
{"channel":"book","type":"update","data":[{"symbol":"ETH/USDC","bids":[{"price":3799.60,"qty":0.00000000},{"price":3798.07,"qty":1.31645616}],"asks":[],"checksum":2894676017,"timestamp":"2024-06-01T18:06:19.277331Z"}]}
{"channel":"book","type":"update","data":[{"symbol":"ETH/USDC","bids":[{"price":3799.63,"qty":0.33750000}],"asks":[],"checksum":472294243,"timestamp":"2024-06-01T18:06:19.280253Z"}]}
{"channel":"book","type":"update","data":[{"symbol":"ETH/USDC","bids":[{"price":3799.63,"qty":0.00000000},{"price":3798.07,"qty":1.31645616}],"asks":[],"checksum":2894676017,"timestamp":"2024-06-01T18:06:19.284107Z"}]}
{"channel":"book","type":"update","data":[{"symbol":"ETH/USDC","bids":[{"price":3799.65,"qty":0.33750000}],"asks":[],"checksum":144996829,"timestamp":"2024-06-01T18:06:19.287079Z"}]}
{"channel":"book","type":"update","data":[{"symbol":"ETH/USDC","bids":[{"price":3799.65,"qty":0.00000000},{"price":3798.07,"qty":1.31645616}],"asks":[],"checksum":2894676017,"timestamp":"2024-06-01T18:06:19.291127Z"}]}
{"channel":"book","type":"update","data":[{"symbol":"ETH/USDC","bids":[{"price":3799.65,"qty":0.33750000}],"asks":[],"checksum":144996829,"timestamp":"2024-06-01T18:06:19.294752Z"}]}
{"channel":"book","type":"update","data":[{"symbol":"ETH/USDC","bids":[{"price":3799.28,"qty":0.65801814}],"asks":[],"checksum":956430237,"timestamp":"2024-06-01T18:06:19.296080Z"}]}
{"channel":"book","type":"update","data":[{"symbol":"ETH/USDC","bids":[{"price":3799.65,"qty":0.00000000},{"price":3798.10,"qty":0.49697747}],"asks":[],"checksum":441828410,"timestamp":"2024-06-01T18:06:19.299049Z"}]}
{"channel":"book","type":"update","data":[{"symbol":"ETH/USDC","bids":[{"price":3799.28,"qty":0.00000000},{"price":3798.07,"qty":1.31645616}],"asks":[],"checksum":2894676017,"timestamp":"2024-06-01T18:06:19.300061Z"}]}
{"channel":"book","type":"update","data":[{"symbol":"ETH/USDC","bids":[{"price":3799.67,"qty":0.33750000}],"asks":[],"checksum":2987052424,"timestamp":"2024-06-01T18:06:19.301994Z"}]}
{"channel":"book","type":"update","data":[{"symbol":"ETH/USDC","bids":[{"price":3799.67,"qty":0.00000000},{"price":3798.07,"qty":1.31645616}],"asks":[],"checksum":2894676017,"timestamp":"2024-06-01T18:06:19.305355Z"}]}
{"channel":"book","type":"update","data":[{"symbol":"ETH/USDC","bids":[{"price":3799.61,"qty":0.33750000}],"asks":[],"checksum":2793936694,"timestamp":"2024-06-01T18:06:19.310951Z"}]}
{"channel":"book","type":"update","data":[{"symbol":"ETH/USDC","bids":[{"price":3799.61,"qty":0.00000000},{"price":3798.07,"qty":1.31645616}],"asks":[],"checksum":2894676017,"timestamp":"2024-06-01T18:06:19.314716Z"}]}
{"channel":"book","type":"update","data":[{"symbol":"ETH/USDC","bids":[{"price":3799.64,"qty":0.33750000}],"asks":[],"checksum":3091964119,"timestamp":"2024-06-01T18:06:19.317569Z"}]}
{"channel":"book","type":"update","data":[{"symbol":"ETH/USDC","bids":[{"price":3799.64,"qty":0.00000000},{"price":3798.07,"qty":1.31645616}],"asks":[],"checksum":2894676017,"timestamp":"2024-06-01T18:06:19.321456Z"}]}
{"channel":"book","type":"update","data":[{"symbol":"ETH/USDC","bids":[{"price":3798.30,"qty":0.78640776}],"asks":[],"checksum":584003556,"timestamp":"2024-06-01T18:06:19.323675Z"}]}
{"channel":"book","type":"update","data":[{"symbol":"ETH/USDC","bids":[{"price":3799.59,"qty":0.33750000}],"asks":[],"checksum":4275896781,"timestamp":"2024-06-01T18:06:19.327674Z"}]}
{"channel":"book","type":"update","data":[{"symbol":"ETH/USDC","bids":[{"price":3799.59,"qty":0.00000000},{"price":3798.10,"qty":0.49697747}],"asks":[],"checksum":584003556,"timestamp":"2024-06-01T18:06:19.331152Z"}]}
{"channel":"book","type":"update","data":[{"symbol":"ETH/USDC","bids":[{"price":3799.62,"qty":0.33750000}],"asks":[],"checksum":2288761357,"timestamp":"2024-06-01T18:06:19.334889Z"}]}
{"channel":"book","type":"update","data":[{"symbol":"ETH/USDC","bids":[{"price":3799.62,"qty":0.00000000},{"price":3798.10,"qty":0.49697747}],"asks":[],"checksum":584003556,"timestamp":"2024-06-01T18:06:19.339086Z"}]}
{"channel":"book","type":"update","data":[{"symbol":"ETH/USDC","bids":[{"price":3799.63,"qty":0.33750000}],"asks":[],"checksum":948200199,"timestamp":"2024-06-01T18:06:19.342001Z"}]}
{"channel":"book","type":"update","data":[{"symbol":"ETH/USDC","bids":[{"price":3799.63,"qty":0.00000000},{"price":3798.10,"qty":0.49697747}],"asks":[],"checksum":584003556,"timestamp":"2024-06-01T18:06:19.346538Z"}]}
{"channel":"book","type":"update","data":[{"symbol":"ETH/USDC","bids":[{"price":3799.59,"qty":0.33750000}],"asks":[],"checksum":4275896781,"timestamp":"2024-06-01T18:06:19.351998Z"}]}
{"channel":"book","type":"update","data":[{"symbol":"ETH/USDC","bids":[{"price":3798.32,"qty":0.00546008}],"asks":[],"checksum":668915756,"timestamp":"2024-06-01T18:06:19.519512Z"}]}
{"channel":"book","type":"update","data":[{"symbol":"ETH/USDC","bids":[{"price":3798.30,"qty":0.00000000},{"price":3798.22,"qty":0.33750000}],"asks":[],"checksum":905322230,"timestamp":"2024-06-01T18:06:19.668014Z"}]}
{"channel":"book","type":"update","data":[{"symbol":"ETH/USDC","bids":[{"price":3799.26,"qty":0.00000000},{"price":3798.10,"qty":0.49697747}],"asks":[],"checksum":1101693347,"timestamp":"2024-06-01T18:06:19.714114Z"}]}
{"channel":"book","type":"update","data":[{"symbol":"ETH/USDC","bids":[{"price":3798.10,"qty":0.00000000},{"price":3798.07,"qty":1.31645616}],"asks":[],"checksum":648409617,"timestamp":"2024-06-01T18:06:19.714237Z"}]}
{"channel":"book","type":"update","data":[{"symbol":"ETH/USDC","bids":[{"price":3798.32,"qty":0.57027415}],"asks":[],"checksum":2145536698,"timestamp":"2024-06-01T18:06:19.714732Z"}]}
{"channel":"book","type":"update","data":[{"symbol":"ETH/USDC","bids":[{"price":3798.31,"qty":11.57961590}],"asks":[],"checksum":1586521206,"timestamp":"2024-06-01T18:06:19.919640Z"}]}
{"channel":"book","type":"update","data":[{"symbol":"ETH/USDC","bids":[{"price":3799.59,"qty":0.00000000},{"price":3797.88,"qty":0.40100000}],"asks":[],"checksum":3725953860,"timestamp":"2024-06-01T18:06:20.132103Z"}]}
{"channel":"book","type":"update","data":[{"symbol":"ETH/USDC","bids":[{"price":3798.31,"qty":10.79320814}],"asks":[],"checksum":4040231491,"timestamp":"2024-06-01T18:06:20.201399Z"}]}
{"channel":"book","type":"update","data":[{"symbol":"ETH/USDC","bids":[{"price":3799.28,"qty":0.65801814}],"asks":[],"checksum":1441048518,"timestamp":"2024-06-01T18:06:20.237306Z"}]}
{"channel":"book","type":"update","data":[{"symbol":"ETH/USDC","bids":[{"price":3799.28,"qty":0.00000000},{"price":3797.88,"qty":0.40100000}],"asks":[],"checksum":4040231491,"timestamp":"2024-06-01T18:06:20.242243Z"}]}
{"channel":"book","type":"update","data":[{"symbol":"ETH/USDC","bids":[{"price":3799.19,"qty":0.00000000},{"price":3797.61,"qty":0.25101585}],"asks":[],"checksum":2256906519,"timestamp":"2024-06-01T18:06:20.251641Z"}]}
{"channel":"book","type":"update","data":[{"symbol":"ETH/USDC","bids":[],"asks":[{"price":3802.51,"qty":0.00000000},{"price":3802.66,"qty":14.71069515}],"checksum":1648114604,"timestamp":"2024-06-01T18:06:20.251697Z"}]}
{"channel":"book","type":"update","data":[{"symbol":"ETH/USDC","bids":[],"asks":[{"price":3801.19,"qty":0.67500000}],"checksum":417853672,"timestamp":"2024-06-01T18:06:20.251738Z"}]}
{"channel":"book","type":"update","data":[{"symbol":"ETH/USDC","bids":[],"asks":[{"price":3800.99,"qty":0.65772464}],"checksum":3860958223,"timestamp":"2024-06-01T18:06:20.257619Z"}]}
{"channel":"book","type":"update","data":[{"symbol":"ETH/USDC","bids":[],"asks":[{"price":3801.96,"qty":1.31511411}],"checksum":1004004944,"timestamp":"2024-06-01T18:06:20.257714Z"}]}
{"channel":"book","type":"update","data":[{"symbol":"ETH/USDC","bids":[{"price":3798.62,"qty":1.31626466}],"asks":[],"checksum":2742286610,"timestamp":"2024-06-01T18:06:20.257807Z"}]}
{"channel":"book","type":"update","data":[{"symbol":"ETH/USDC","bids":[],"asks":[{"price":3800.61,"qty":0.33750000}],"checksum":3846164853,"timestamp":"2024-06-01T18:06:20.261280Z"}]}
{"channel":"book","type":"update","data":[{"symbol":"ETH/USDC","bids":[],"asks":[{"price":3801.19,"qty":0.33750000}],"checksum":345205356,"timestamp":"2024-06-01T18:06:20.261623Z"}]}
{"channel":"book","type":"update","data":[{"symbol":"ETH/USDC","bids":[{"price":3799.20,"qty":0.00000000},{"price":3797.61,"qty":0.25101585}],"asks":[],"checksum":383380074,"timestamp":"2024-06-01T18:06:20.261668Z"}]}
{"channel":"book","type":"update","data":[{"symbol":"ETH/USDC","bids":[],"asks":[{"price":3800.80,"qty":0.33750000}],"checksum":3950734222,"timestamp":"2024-06-01T18:06:20.261862Z"}]}
{"channel":"book","type":"update","data":[{"symbol":"ETH/USDC","bids":[],"asks":[{"price":3800.61,"qty":0.67500000}],"checksum":1058518767,"timestamp":"2024-06-01T18:06:20.265082Z"}]}
{"channel":"book","type":"update","data":[{"symbol":"ETH/USDC","bids":[],"asks":[{"price":3801.00,"qty":0.00000000},{"price":3802.49,"qty":0.00519130}],"checksum":3958230123,"timestamp":"2024-06-01T18:06:20.265100Z"}]}
{"channel":"book","type":"update","data":[{"symbol":"ETH/USDC","bids":[],"asks":[{"price":3800.80,"qty":0.00000000},{"price":3802.50,"qty":10.79045013}],"checksum":507982630,"timestamp":"2024-06-01T18:06:20.265845Z"}]}
{"channel":"book","type":"update","data":[{"symbol":"ETH/USDC","bids":[],"asks":[{"price":3801.57,"qty":0.33750000}],"checksum":582465429,"timestamp":"2024-06-01T18:06:20.266432Z"}]}
{"channel":"book","type":"update","data":[{"symbol":"ETH/USDC","bids":[{"price":3799.27,"qty":0.00000000},{"price":3797.56,"qty":3.55776000}],"asks":[],"checksum":212943608,"timestamp":"2024-06-01T18:06:20.329519Z"}]}
{"channel":"book","type":"update","data":[{"symbol":"ETH/USDC","bids":[{"price":3798.07,"qty":0.00000000},{"price":3797.55,"qty":13.87331143}],"asks":[],"checksum":3998870704,"timestamp":"2024-06-01T18:06:20.332003Z"}]}
{"channel":"book","type":"update","data":[{"symbol":"ETH/USDC","bids":[{"price":3798.66,"qty":1.31566355}],"asks":[],"checksum":2149572513,"timestamp":"2024-06-01T18:06:20.333309Z"}]}
{"channel":"book","type":"update","data":[{"symbol":"ETH/USDC","bids":[{"price":3799.00,"qty":0.78646366}],"asks":[],"checksum":2081411429,"timestamp":"2024-06-01T18:06:20.334252Z"}]}
{"channel":"book","type":"update","data":[{"symbol":"ETH/USDC","bids":[{"price":3799.05,"qty":0.33750000}],"asks":[],"checksum":159275829,"timestamp":"2024-06-01T18:06:20.340444Z"}]}
{"channel":"book","type":"update","data":[{"symbol":"ETH/USDC","bids":[],"asks":[{"price":3800.99,"qty":0.00000000},{"price":3802.50,"qty":10.79045013}],"checksum":741393709,"timestamp":"2024-06-01T18:06:20.346976Z"}]}
{"channel":"book","type":"update","data":[{"symbol":"ETH/USDC","bids":[{"price":3799.00,"qty":0.00000000},{"price":3797.61,"qty":0.25101585}],"asks":[],"checksum":754443617,"timestamp":"2024-06-01T18:06:20.386595Z"}]}
{"channel":"book","type":"update","data":[{"symbol":"ETH/USDC","bids":[{"price":3798.87,"qty":0.78649057}],"asks":[],"checksum":1417253832,"timestamp":"2024-06-01T18:06:20.390741Z"}]}
{"channel":"book","type":"update","data":[{"symbol":"ETH/USDC","bids":[],"asks":[{"price":3802.43,"qty":0.39700000}],"checksum":1928380804,"timestamp":"2024-06-01T18:06:20.394847Z"}]}
{"channel":"book","type":"update","data":[{"symbol":"ETH/USDC","bids":[],"asks":[{"price":3800.61,"qty":0.33750000}],"checksum":2460044389,"timestamp":"2024-06-01T18:06:20.414639Z"}]}
{"channel":"book","type":"update","data":[{"symbol":"ETH/USDC","bids":[],"asks":[{"price":3800.43,"qty":0.33750000}],"checksum":878086827,"timestamp":"2024-06-01T18:06:20.419165Z"}]}
{"channel":"book","type":"update","data":[{"symbol":"ETH/USDC","bids":[],"asks":[{"price":3800.61,"qty":0.00000000},{"price":3802.49,"qty":0.00519130}],"checksum":1418174691,"timestamp":"2024-06-01T18:06:20.421380Z"}]}
{"channel":"book","type":"update","data":[{"symbol":"ETH/USDC","bids":[{"price":3799.05,"qty":0.00000000},{"price":3797.61,"qty":0.25101585}],"asks":[],"checksum":2465637515,"timestamp":"2024-06-01T18:06:20.423258Z"}]}
{"channel":"book","type":"update","data":[{"symbol":"ETH/USDC","bids":[{"price":3799.06,"qty":0.33750000}],"asks":[],"checksum":1520957148,"timestamp":"2024-06-01T18:06:20.426239Z"}]}
{"channel":"book","type":"update","data":[{"symbol":"ETH/USDC","bids":[{"price":3799.06,"qty":0.00000000},{"price":3797.61,"qty":0.25101585}],"asks":[],"checksum":2465637515,"timestamp":"2024-06-01T18:06:20.430112Z"}]}
{"channel":"book","type":"update","data":[{"symbol":"ETH/USDC","bids":[{"price":3799.07,"qty":0.33750000}],"asks":[],"checksum":1598538953,"timestamp":"2024-06-01T18:06:20.433302Z"}]}
{"channel":"book","type":"update","data":[{"symbol":"ETH/USDC","bids":[{"price":3799.07,"qty":0.00000000},{"price":3797.61,"qty":0.25101585}],"asks":[],"checksum":2465637515,"timestamp":"2024-06-01T18:06:20.437457Z"}]}
{"channel":"book","type":"update","data":[{"symbol":"ETH/USDC","bids":[{"price":3799.11,"qty":0.33750000}],"asks":[],"checksum":786394222,"timestamp":"2024-06-01T18:06:20.440432Z"}]}
{"channel":"book","type":"update","data":[{"symbol":"ETH/USDC","bids":[{"price":3799.11,"qty":0.00000000},{"price":3797.61,"qty":0.25101585}],"asks":[],"checksum":2465637515,"timestamp":"2024-06-01T18:06:20.444488Z"}]}
{"channel":"book","type":"update","data":[{"symbol":"ETH/USDC","bids":[{"price":3799.03,"qty":0.33750000}],"asks":[],"checksum":1221004445,"timestamp":"2024-06-01T18:06:20.450607Z"}]}
{"channel":"book","type":"update","data":[{"symbol":"ETH/USDC","bids":[],"asks":[{"price":3802.28,"qty":0.27442312}],"checksum":1536826048,"timestamp":"2024-06-01T18:06:20.473948Z"}]}
{"channel":"book","type":"update","data":[{"symbol":"ETH/USDC","bids":[{"price":3798.21,"qty":0.67500000}],"asks":[],"checksum":1878045553,"timestamp":"2024-06-01T18:06:20.583541Z"}]}
{"channel":"book","type":"update","data":[{"symbol":"ETH/USDC","bids":[{"price":3798.21,"qty":0.00000000},{"price":3797.88,"qty":0.40100000}],"asks":[],"checksum":1536826048,"timestamp":"2024-06-01T18:06:20.843123Z"}]}
{"channel":"book","type":"update","data":[{"symbol":"ETH/USDC","bids":[{"price":3798.87,"qty":0.00000000},{"price":3797.56,"qty":3.55776000}],"asks":[],"checksum":2869465234,"timestamp":"2024-06-01T18:06:20.907798Z"}]}
{"channel":"book","type":"update","data":[{"symbol":"ETH/USDC","bids":[{"price":3798.79,"qty":0.78650713}],"asks":[],"checksum":1130584618,"timestamp":"2024-06-01T18:06:20.911942Z"}]}
{"channel":"book","type":"update","data":[{"symbol":"ETH/USDC","bids":[],"asks":[{"price":3800.66,"qty":0.65778216}],"checksum":3487235925,"timestamp":"2024-06-01T18:06:20.926442Z"}]}
{"channel":"book","type":"update","data":[{"symbol":"ETH/USDC","bids":[{"price":3799.12,"qty":0.65804657}],"asks":[],"checksum":3009330335,"timestamp":"2024-06-01T18:06:20.926661Z"}]}
{"channel":"book","type":"update","data":[{"symbol":"ETH/USDC","bids":[{"price":3799.03,"qty":0.00000000},{"price":3797.88,"qty":0.40100000}],"asks":[],"checksum":3722556246,"timestamp":"2024-06-01T18:06:20.930142Z"}]}
{"channel":"book","type":"update","data":[{"symbol":"ETH/USDC","bids":[],"asks":[{"price":3800.43,"qty":0.67500000}],"checksum":160263735,"timestamp":"2024-06-01T18:06:20.930882Z"}]}
{"channel":"book","type":"update","data":[{"symbol":"ETH/USDC","bids":[],"asks":[{"price":3801.95,"qty":0.06051699}],"checksum":2177986827,"timestamp":"2024-06-01T18:06:21.264158Z"}]}
{"channel":"book","type":"update","data":[{"symbol":"ETH/USDC","bids":[],"asks":[{"price":3801.54,"qty":0.02151385}],"checksum":2839247190,"timestamp":"2024-06-01T18:06:21.264203Z"}]}
{"channel":"book","type":"update","data":[{"symbol":"ETH/USDC","bids":[{"price":3798.79,"qty":0.00000000},{"price":3797.56,"qty":3.55776000}],"asks":[],"checksum":4065457574,"timestamp":"2024-06-01T18:06:21.385195Z"}]}
{"channel":"book","type":"update","data":[{"symbol":"ETH/USDC","bids":[{"price":3798.71,"qty":0.78652370}],"asks":[],"checksum":2142599601,"timestamp":"2024-06-01T18:06:21.388902Z"}]}
{"channel":"book","type":"update","data":[{"symbol":"ETH/USDC","bids":[{"price":3798.66,"qty":0.00000000},{"price":3797.56,"qty":3.55776000}],"asks":[],"checksum":570375178,"timestamp":"2024-06-01T18:06:21.406746Z"}]}
{"channel":"book","type":"update","data":[{"symbol":"ETH/USDC","bids":[{"price":3797.56,"qty":0.00000000},{"price":3797.55,"qty":13.87331143},{"price":3798.33,"qty":3.55776000}],"asks":[],"checksum":1480142650,"timestamp":"2024-06-01T18:06:21.410432Z"}]}
{"channel":"book","type":"update","data":[{"symbol":"ETH/USDC","bids":[],"asks":[{"price":3801.54,"qty":1.06437340}],"checksum":1719159094,"timestamp":"2024-06-01T18:06:21.411324Z"}]}
{"channel":"book","type":"update","data":[{"symbol":"ETH/USDC","bids":[],"asks":[{"price":3801.95,"qty":4.71961622}],"checksum":1861961143,"timestamp":"2024-06-01T18:06:21.411389Z"}]}
{"channel":"book","type":"update","data":[{"symbol":"ETH/USDC","bids":[{"price":3798.33,"qty":0.00000000},{"price":3797.55,"qty":13.87331143},{"price":3797.56,"qty":3.55776000}],"asks":[],"checksum":389895815,"timestamp":"2024-06-01T18:06:21.533365Z"}]}
{"channel":"book","type":"update","data":[{"symbol":"ETH/USDC","bids":[{"price":3797.98,"qty":0.67500000}],"asks":[],"checksum":3638024639,"timestamp":"2024-06-01T18:06:21.655706Z"}]}
{"channel":"book","type":"update","data":[{"symbol":"ETH/USDC","bids":[{"price":3798.32,"qty":0.00546008}],"asks":[],"checksum":309188797,"timestamp":"2024-06-01T18:06:22.450055Z"}]}
{"channel":"book","type":"update","data":[{"symbol":"ETH/USDC","bids":[{"price":3798.32,"qty":0.17501919}],"asks":[],"checksum":3530312429,"timestamp":"2024-06-01T18:06:22.450995Z"}]}
{"channel":"book","type":"update","data":[{"symbol":"ETH/USDC","bids":[{"price":3798.72,"qty":0.01553127}],"asks":[],"checksum":1978829798,"timestamp":"2024-06-01T18:06:22.451121Z"}]}
{"channel":"book","type":"update","data":[{"symbol":"ETH/USDC","bids":[{"price":3798.31,"qty":0.00000000},{"price":3797.88,"qty":0.40100000}],"asks":[],"checksum":127193597,"timestamp":"2024-06-01T18:06:22.772792Z"}]}
{"channel":"book","type":"update","data":[{"symbol":"ETH/USDC","bids":[{"price":3798.32,"qty":0.16955911}],"asks":[],"checksum":776132761,"timestamp":"2024-06-01T18:06:22.777072Z"}]}
{"channel":"book","type":"update","data":[{"symbol":"ETH/USDC","bids":[],"asks":[{"price":3801.95,"qty":0.06051699}],"checksum":1314184401,"timestamp":"2024-06-01T18:06:23.667177Z"}]}
{"channel":"book","type":"update","data":[{"symbol":"ETH/USDC","bids":[],"asks":[{"price":3801.54,"qty":0.02151385}],"checksum":2281811141,"timestamp":"2024-06-01T18:06:23.667263Z"}]}
{"channel":"book","type":"update","data":[{"symbol":"ETH/USDC","bids":[],"asks":[{"price":3801.54,"qty":5.19723941}],"checksum":1551916921,"timestamp":"2024-06-01T18:06:23.673130Z"}]}
{"channel":"book","type":"update","data":[{"symbol":"ETH/USDC","bids":[],"asks":[{"price":3801.53,"qty":1.04288029}],"checksum":737728125,"timestamp":"2024-06-01T18:06:23.673260Z"}]}
{"channel":"book","type":"update","data":[{"symbol":"ETH/USDC","bids":[],"asks":[{"price":3801.95,"qty":0.00000000},{"price":3802.28,"qty":0.27442312}],"checksum":1946014381,"timestamp":"2024-06-01T18:06:23.707548Z"}]}
{"channel":"book","type":"update","data":[{"symbol":"ETH/USDC","bids":[],"asks":[{"price":3801.54,"qty":5.17572556}],"checksum":3503254397,"timestamp":"2024-06-01T18:06:23.707564Z"}]}
{"channel":"book","type":"update","data":[{"symbol":"ETH/USDC","bids":[],"asks":[{"price":3801.53,"qty":1.11314827}],"checksum":3254438960,"timestamp":"2024-06-01T18:06:23.709641Z"}]}
{"channel":"book","type":"update","data":[{"symbol":"ETH/USDC","bids":[],"asks":[{"price":3801.94,"qty":0.12552231}],"checksum":1155240776,"timestamp":"2024-06-01T18:06:23.709700Z"}]}
{"channel":"book","type":"update","data":[{"symbol":"ETH/USDC","bids":[{"price":3798.71,"qty":0.00000000},{"price":3797.59,"qty":3.55776000}],"asks":[],"checksum":87435362,"timestamp":"2024-06-01T18:06:23.724045Z"}]}
{"channel":"book","type":"update","data":[{"symbol":"ETH/USDC","bids":[{"price":3798.66,"qty":0.78653405}],"asks":[],"checksum":1734363104,"timestamp":"2024-06-01T18:06:23.727911Z"}]}
{"channel":"book","type":"update","data":[{"symbol":"ETH/USDC","bids":[{"price":3798.66,"qty":0.00000000},{"price":3797.59,"qty":3.55776000}],"asks":[],"checksum":87435362,"timestamp":"2024-06-01T18:06:23.728139Z"}]}
{"channel":"book","type":"update","data":[{"symbol":"ETH/USDC","bids":[{"price":3798.53,"qty":0.78656097}],"asks":[],"checksum":1391195439,"timestamp":"2024-06-01T18:06:23.731442Z"}]}
{"channel":"book","type":"update","data":[{"symbol":"ETH/USDC","bids":[],"asks":[{"price":3801.96,"qty":0.00000000},{"price":3802.28,"qty":0.27442312}],"checksum":112881538,"timestamp":"2024-06-01T18:06:23.810040Z"}]}
{"channel":"book","type":"update","data":[{"symbol":"ETH/USDC","bids":[],"asks":[{"price":3800.66,"qty":0.00000000},{"price":3802.43,"qty":0.39700000}],"checksum":2905849541,"timestamp":"2024-06-01T18:06:23.813399Z"}]}
{"channel":"book","type":"update","data":[{"symbol":"ETH/USDC","bids":[{"price":3798.62,"qty":0.00000000},{"price":3797.59,"qty":3.55776000}],"asks":[],"checksum":2000219456,"timestamp":"2024-06-01T18:06:23.813421Z"}]}
{"channel":"book","type":"update","data":[{"symbol":"ETH/USDC","bids":[],"asks":[{"price":3800.43,"qty":0.33750000}],"checksum":2911254867,"timestamp":"2024-06-01T18:06:23.817933Z"}]}
{"channel":"book","type":"update","data":[{"symbol":"ETH/USDC","bids":[],"asks":[{"price":3800.42,"qty":0.65782256}],"checksum":2945407530,"timestamp":"2024-06-01T18:06:23.818761Z"}]}
{"channel":"book","type":"update","data":[{"symbol":"ETH/USDC","bids":[{"price":3798.04,"qty":1.31646606}],"asks":[],"checksum":1683012389,"timestamp":"2024-06-01T18:06:23.818819Z"}]}
{"channel":"book","type":"update","data":[{"symbol":"ETH/USDC","bids":[],"asks":[{"price":3801.40,"qty":1.31530498}],"checksum":3641192892,"timestamp":"2024-06-01T18:06:23.818977Z"}]}
{"channel":"book","type":"update","data":[{"symbol":"ETH/USDC","bids":[],"asks":[{"price":3800.24,"qty":0.33750000}],"checksum":2585489718,"timestamp":"2024-06-01T18:06:23.822655Z"}]}
{"channel":"book","type":"update","data":[{"symbol":"ETH/USDC","bids":[],"asks":[{"price":3800.05,"qty":0.33750000}],"checksum":3973761231,"timestamp":"2024-06-01T18:06:23.822979Z"}]}
{"channel":"book","type":"update","data":[{"symbol":"ETH/USDC","bids":[],"asks":[{"price":3800.05,"qty":0.67500000}],"checksum":1757296581,"timestamp":"2024-06-01T18:06:23.826773Z"}]}
{"channel":"book","type":"update","data":[{"symbol":"ETH/USDC","bids":[{"price":3798.65,"qty":0.00000000},{"price":3797.59,"qty":3.55776000}],"asks":[],"checksum":3749951320,"timestamp":"2024-06-01T18:06:23.826994Z"}]}
{"channel":"book","type":"update","data":[{"symbol":"ETH/USDC","bids":[],"asks":[{"price":3800.43,"qty":0.00000000},{"price":3801.94,"qty":0.12552231}],"checksum":1235196105,"timestamp":"2024-06-01T18:06:23.827681Z"}]}
{"channel":"book","type":"update","data":[{"symbol":"ETH/USDC","bids":[],"asks":[{"price":3800.24,"qty":0.00000000},{"price":3802.19,"qty":0.33750000}],"checksum":276302198,"timestamp":"2024-06-01T18:06:23.828146Z"}]}
{"channel":"book","type":"update","data":[{"symbol":"ETH/USDC","bids":[{"price":3797.98,"qty":0.00000000},{"price":3797.58,"qty":14.90220633}],"asks":[],"checksum":1340088251,"timestamp":"2024-06-01T18:06:23.828436Z"}]}
{"channel":"book","type":"update","data":[{"symbol":"ETH/USDC","bids":[{"price":3798.74,"qty":0.33750000}],"asks":[],"checksum":3829358975,"timestamp":"2024-06-01T18:06:23.831209Z"}]}
{"channel":"book","type":"update","data":[{"symbol":"ETH/USDC","bids":[{"price":3797.84,"qty":0.67500000}],"asks":[],"checksum":3463507755,"timestamp":"2024-06-01T18:06:24.110833Z"}]}
{"channel":"book","type":"update","data":[{"symbol":"ETH/USDC","bids":[{"price":3798.72,"qty":0.00000000},{"price":3797.59,"qty":3.55776000}],"asks":[],"checksum":4285658964,"timestamp":"2024-06-01T18:06:25.212946Z"}]}
{"channel":"book","type":"update","data":[{"symbol":"ETH/USDC","bids":[{"price":3798.32,"qty":0.00000000},{"price":3797.58,"qty":14.90220633}],"asks":[],"checksum":2284141010,"timestamp":"2024-06-01T18:06:25.212967Z"}]}
{"channel":"book","type":"update","data":[{"symbol":"ETH/USDC","bids":[{"price":3797.60,"qty":0.50992389}],"asks":[],"checksum":533145112,"timestamp":"2024-06-01T18:06:25.214146Z"}]}
{"channel":"book","type":"update","data":[{"symbol":"ETH/USDC","bids":[{"price":3798.05,"qty":0.04120318}],"asks":[],"checksum":456667139,"timestamp":"2024-06-01T18:06:25.214174Z"}]}
{"channel":"book","type":"update","data":[{"symbol":"ETH/USDC","bids":[{"price":3798.74,"qty":0.00000000},{"price":3797.59,"qty":3.55776000}],"asks":[],"checksum":3888542514,"timestamp":"2024-06-01T18:06:25.437984Z"}]}
{"channel":"book","type":"update","data":[{"symbol":"ETH/USDC","bids":[{"price":3798.53,"qty":0.00000000},{"price":3797.58,"qty":14.90220633}],"asks":[],"checksum":550170276,"timestamp":"2024-06-01T18:06:25.474247Z"}]}
{"channel":"book","type":"update","data":[{"symbol":"ETH/USDC","bids":[{"price":3798.42,"qty":0.78658374}],"asks":[],"checksum":1538655642,"timestamp":"2024-06-01T18:06:25.479041Z"}]}
{"channel":"book","type":"update","data":[{"symbol":"ETH/USDC","bids":[{"price":3797.84,"qty":0.00000000},{"price":3797.58,"qty":14.90220633}],"asks":[],"checksum":116020687,"timestamp":"2024-06-01T18:06:25.537085Z"}]}
{"channel":"book","type":"update","data":[{"symbol":"ETH/USDC","bids":[{"price":3797.69,"qty":0.67500000}],"asks":[],"checksum":1601410969,"timestamp":"2024-06-01T18:06:25.916988Z"}]}
{"channel":"book","type":"update","data":[{"symbol":"ETH/USDC","bids":[],"asks":[{"price":3801.53,"qty":1.04288029}],"checksum":7990800,"timestamp":"2024-06-01T18:06:26.035367Z"}]}
{"channel":"book","type":"update","data":[{"symbol":"ETH/USDC","bids":[],"asks":[{"price":3801.94,"qty":0.00000000},{"price":3802.28,"qty":0.27442312}],"checksum":2428507526,"timestamp":"2024-06-01T18:06:26.035478Z"}]}
{"channel":"book","type":"update","data":[{"symbol":"ETH/USDC","bids":[],"asks":[{"price":3801.39,"qty":0.21327988}],"checksum":1919010414,"timestamp":"2024-06-01T18:06:26.037396Z"}]}
{"channel":"book","type":"update","data":[{"symbol":"ETH/USDC","bids":[],"asks":[{"price":3801.54,"qty":0.00000000},{"price":3802.28,"qty":0.27442312}],"checksum":525120643,"timestamp":"2024-06-01T18:06:26.068810Z"}]}
{"channel":"book","type":"update","data":[{"symbol":"ETH/USDC","bids":[],"asks":[{"price":3801.53,"qty":0.00000000},{"price":3802.43,"qty":0.39700000}],"checksum":868456001,"timestamp":"2024-06-01T18:06:26.069053Z"}]}
{"channel":"book","type":"update","data":[{"symbol":"ETH/USDC","bids":[],"asks":[{"price":3801.18,"qty":1.04292040}],"checksum":3264036681,"timestamp":"2024-06-01T18:06:26.073946Z"}]}
{"channel":"book","type":"update","data":[{"symbol":"ETH/USDC","bids":[],"asks":[{"price":3801.39,"qty":5.38904539}],"checksum":3514867587,"timestamp":"2024-06-01T18:06:26.074053Z"}]}
{"channel":"book","type":"update","data":[{"symbol":"ETH/USDC","bids":[],"asks":[{"price":3802.19,"qty":0.00000000},{"price":3802.43,"qty":0.39700000}],"checksum":4261076950,"timestamp":"2024-06-01T18:06:26.079361Z"}]}
{"channel":"book","type":"update","data":[{"symbol":"ETH/USDC","bids":[],"asks":[{"price":3800.43,"qty":0.33750000}],"checksum":1328260462,"timestamp":"2024-06-01T18:06:26.082987Z"}]}
{"channel":"book","type":"update","data":[{"symbol":"ETH/USDC","bids":[{"price":3797.69,"qty":0.00000000},{"price":3797.58,"qty":14.90220633}],"asks":[],"checksum":2512413549,"timestamp":"2024-06-01T18:06:26.190377Z"}]}
{"channel":"book","type":"update","data":[{"symbol":"ETH/USDC","bids":[{"price":3797.58,"qty":0.00000000},{"price":3797.56,"qty":0.00544627}],"asks":[],"checksum":928503644,"timestamp":"2024-06-01T18:06:26.356766Z"}]}
{"channel":"book","type":"update","data":[{"symbol":"ETH/USDC","bids":[{"price":3798.06,"qty":0.52631476}],"asks":[],"checksum":1857753513,"timestamp":"2024-06-01T18:06:26.357188Z"}]}
{"channel":"book","type":"update","data":[{"symbol":"ETH/USDC","bids":[{"price":3797.61,"qty":34.17621628}],"asks":[],"checksum":888511090,"timestamp":"2024-06-01T18:06:26.357420Z"}]}
{"channel":"book","type":"update","data":[{"symbol":"ETH/USDC","bids":[{"price":3797.70,"qty":11.30908569}],"asks":[],"checksum":788929531,"timestamp":"2024-06-01T18:06:26.357441Z"}]}
{"channel":"book","type":"update","data":[{"symbol":"ETH/USDC","bids":[{"price":3797.71,"qty":0.00529236}],"asks":[],"checksum":1698422275,"timestamp":"2024-06-01T18:06:26.454207Z"}]}
{"channel":"book","type":"update","data":[{"symbol":"ETH/USDC","bids":[{"price":3797.71,"qty":3.56305236}],"asks":[],"checksum":1468230209,"timestamp":"2024-06-01T18:06:26.457549Z"}]}
{"channel":"book","type":"update","data":[{"symbol":"ETH/USDC","bids":[{"price":3799.12,"qty":0.00000000},{"price":3797.68,"qty":0.67500000}],"asks":[],"checksum":4210301176,"timestamp":"2024-06-01T18:06:26.505930Z"}]}
{"channel":"book","type":"update","data":[{"symbol":"ETH/USDC","bids":[{"price":3798.75,"qty":0.65810999}],"asks":[],"checksum":3778323139,"timestamp":"2024-06-01T18:06:26.511082Z"}]}
{"channel":"book","type":"update","data":[{"symbol":"ETH/USDC","bids":[{"price":3798.65,"qty":0.33750000}],"asks":[],"checksum":950031939,"timestamp":"2024-06-01T18:06:26.512944Z"}]}
{"channel":"book","type":"update","data":[{"symbol":"ETH/USDC","bids":[{"price":3798.65,"qty":0.00000000},{"price":3797.70,"qty":11.30908569}],"asks":[],"checksum":3778323139,"timestamp":"2024-06-01T18:06:26.515520Z"}]}
{"channel":"book","type":"update","data":[{"symbol":"ETH/USDC","bids":[{"price":3798.42,"qty":0.00000000},{"price":3797.68,"qty":0.67500000}],"asks":[],"checksum":1845322322,"timestamp":"2024-06-01T18:06:26.656810Z"}]}
{"channel":"book","type":"update","data":[{"symbol":"ETH/USDC","bids":[{"price":3798.28,"qty":0.78661274}],"asks":[],"checksum":782115219,"timestamp":"2024-06-01T18:06:26.661377Z"}]}
{"channel":"book","type":"update","data":[{"symbol":"ETH/USDC","bids":[],"asks":[{"price":3800.42,"qty":0.00000000},{"price":3802.43,"qty":0.39700000}],"checksum":2414815484,"timestamp":"2024-06-01T18:06:26.667513Z"}]}
{"channel":"book","type":"update","data":[{"symbol":"ETH/USDC","bids":[],"asks":[{"price":3800.05,"qty":0.33750000}],"checksum":1535374749,"timestamp":"2024-06-01T18:06:26.672428Z"}]}
{"channel":"book","type":"update","data":[{"symbol":"ETH/USDC","bids":[],"asks":[{"price":3800.06,"qty":0.65788485}],"checksum":4101907190,"timestamp":"2024-06-01T18:06:26.674092Z"}]}
{"channel":"book","type":"update","data":[{"symbol":"ETH/USDC","bids":[],"asks":[{"price":3799.87,"qty":0.33750000}],"checksum":4001962657,"timestamp":"2024-06-01T18:06:26.675928Z"}]}
{"channel":"book","type":"update","data":[{"symbol":"ETH/USDC","bids":[],"asks":[{"price":3800.05,"qty":0.00000000},{"price":3802.28,"qty":0.27442312}],"checksum":3201549308,"timestamp":"2024-06-01T18:06:26.676880Z"}]}
{"channel":"book","type":"update","data":[{"symbol":"ETH/USDC","bids":[],"asks":[{"price":3799.87,"qty":0.67500000}],"checksum":1790910109,"timestamp":"2024-06-01T18:06:26.680494Z"}]}
{"channel":"book","type":"update","data":[{"symbol":"ETH/USDC","bids":[{"price":3798.05,"qty":0.00000000},{"price":3797.61,"qty":34.17621628}],"asks":[],"checksum":3085053459,"timestamp":"2024-06-01T18:06:27.991898Z"}]}
{"channel":"book","type":"update","data":[{"symbol":"ETH/USDC","bids":[{"price":3798.29,"qty":0.00526334}],"asks":[],"checksum":3262665343,"timestamp":"2024-06-01T18:06:27.992773Z"}]}
{"channel":"book","type":"update","data":[{"symbol":"ETH/USDC","bids":[{"price":3797.72,"qty":0.54942808}],"asks":[],"checksum":3143122640,"timestamp":"2024-06-01T18:06:27.992835Z"}]}
{"channel":"book","type":"update","data":[{"symbol":"ETH/USDC","bids":[{"price":3797.71,"qty":0.00529236}],"asks":[],"checksum":693949864,"timestamp":"2024-06-01T18:06:27.996070Z"}]}
{"channel":"book","type":"update","data":[{"symbol":"ETH/USDC","bids":[{"price":3797.71,"qty":3.56305236}],"asks":[],"checksum":3143122640,"timestamp":"2024-06-01T18:06:27.999098Z"}]}
{"channel":"book","type":"update","data":[{"symbol":"ETH/USDC","bids":[{"price":3797.71,"qty":0.00529236}],"asks":[],"checksum":693949864,"timestamp":"2024-06-01T18:06:28.346960Z"}]}
{"channel":"book","type":"update","data":[{"symbol":"ETH/USDC","bids":[{"price":3797.71,"qty":3.56305236}],"asks":[],"checksum":3143122640,"timestamp":"2024-06-01T18:06:28.349999Z"}]}
{"channel":"book","type":"update","data":[{"symbol":"ETH/USDC","bids":[],"asks":[{"price":3801.39,"qty":0.21327988}],"checksum":3956999604,"timestamp":"2024-06-01T18:06:28.379839Z"}]}
{"channel":"book","type":"update","data":[{"symbol":"ETH/USDC","bids":[],"asks":[{"price":3801.38,"qty":5.69239043}],"checksum":1255771885,"timestamp":"2024-06-01T18:06:28.384631Z"}]}
{"channel":"book","type":"update","data":[{"symbol":"ETH/USDC","bids":[{"price":3797.71,"qty":0.00529236}],"asks":[],"checksum":404178908,"timestamp":"2024-06-01T18:06:28.388135Z"}]}
{"channel":"book","type":"update","data":[{"symbol":"ETH/USDC","bids":[],"asks":[{"price":3801.39,"qty":0.00000000},{"price":3802.28,"qty":0.27442312}],"checksum":3722062057,"timestamp":"2024-06-01T18:06:28.474165Z"}]}
{"channel":"book","type":"update","data":[{"symbol":"ETH/USDC","bids":[],"asks":[{"price":3801.17,"qty":0.07351883}],"checksum":3956000008,"timestamp":"2024-06-01T18:06:28.476019Z"}]}
{"channel":"book","type":"update","data":[{"symbol":"ETH/USDC","bids":[],"asks":[{"price":3801.38,"qty":5.87253870}],"checksum":1492052666,"timestamp":"2024-06-01T18:06:28.476067Z"}]}
{"channel":"book","type":"update","data":[{"symbol":"ETH/USDC","bids":[{"price":3798.06,"qty":0.00000000},{"price":3797.70,"qty":11.30908569}],"asks":[],"checksum":354952565,"timestamp":"2024-06-01T18:06:29.926029Z"}]}
{"channel":"book","type":"update","data":[{"symbol":"ETH/USDC","bids":[{"price":3797.70,"qty":0.00000000},{"price":3797.54,"qty":0.65810999}],"asks":[],"checksum":2644456493,"timestamp":"2024-06-01T18:06:29.926077Z"}]}
{"channel":"book","type":"update","data":[{"symbol":"ETH/USDC","bids":[{"price":3797.71,"qty":3.56305236}],"asks":[],"checksum":2682760009,"timestamp":"2024-06-01T18:06:29.929399Z"}]}
{"channel":"book","type":"update","data":[{"symbol":"ETH/USDC","bids":[{"price":3797.71,"qty":3.55776000}],"asks":[],"checksum":3584189469,"timestamp":"2024-06-01T18:06:29.930207Z"}]}
{"channel":"book","type":"update","data":[{"symbol":"ETH/USDC","bids":[{"price":3797.71,"qty":0.00000000},{"price":3797.48,"qty":0.33750000}],"asks":[],"checksum":2199525510,"timestamp":"2024-06-01T18:06:30.038031Z"}]}
{"channel":"book","type":"update","data":[{"symbol":"ETH/USDC","bids":[{"price":3797.54,"qty":0.00000000},{"price":3797.10,"qty":0.33750000}],"asks":[],"checksum":3185042657,"timestamp":"2024-06-01T18:06:30.534283Z"}]}
{"channel":"book","type":"update","data":[{"symbol":"ETH/USDC","bids":[{"price":3798.22,"qty":0.00000000},{"price":3796.94,"qty":3.56287457}],"asks":[],"checksum":3714253302,"timestamp":"2024-06-01T18:06:30.662963Z"}]}
{"channel":"book","type":"update","data":[{"symbol":"ETH/USDC","bids":[{"price":3798.28,"qty":0.00000000},{"price":3796.93,"qty":14.90389130}],"asks":[],"checksum":1839298899,"timestamp":"2024-06-01T18:06:30.667476Z"}]}
{"channel":"book","type":"update","data":[{"symbol":"ETH/USDC","bids":[{"price":3797.99,"qty":0.33750000}],"asks":[],"checksum":3243863766,"timestamp":"2024-06-01T18:06:30.668303Z"}]}
{"channel":"book","type":"update","data":[{"symbol":"ETH/USDC","bids":[{"price":3798.24,"qty":0.78662102}],"asks":[],"checksum":3773581392,"timestamp":"2024-06-01T18:06:30.676103Z"}]}
{"channel":"book","type":"update","data":[{"symbol":"ETH/USDC","bids":[{"price":3798.24,"qty":0.00000000},{"price":3796.94,"qty":3.56287457}],"asks":[],"checksum":3243863766,"timestamp":"2024-06-01T18:06:30.682090Z"}]}
{"channel":"book","type":"update","data":[{"symbol":"ETH/USDC","bids":[{"price":3798.75,"qty":0.00000000},{"price":3796.93,"qty":14.90389130}],"asks":[],"checksum":2301136325,"timestamp":"2024-06-01T18:06:30.686858Z"}]}
{"channel":"book","type":"update","data":[{"symbol":"ETH/USDC","bids":[],"asks":[{"price":3801.40,"qty":0.00000000},{"price":3801.59,"qty":0.00536160}],"checksum":2892353954,"timestamp":"2024-06-01T18:06:30.686937Z"}]}
{"channel":"book","type":"update","data":[{"symbol":"ETH/USDC","bids":[],"asks":[{"price":3800.06,"qty":0.00000000},{"price":3801.60,"qty":19.55410999}],"checksum":416865744,"timestamp":"2024-06-01T18:06:30.686946Z"}]}
{"channel":"book","type":"update","data":[{"symbol":"ETH/USDC","bids":[{"price":3798.04,"qty":0.00000000},{"price":3796.92,"qty":4.16106147}],"asks":[],"checksum":1306543220,"timestamp":"2024-06-01T18:06:30.687041Z"}]}
{"channel":"book","type":"update","data":[{"symbol":"ETH/USDC","bids":[{"price":3797.48,"qty":0.00000000},{"price":3796.89,"qty":0.40400000}],"asks":[],"checksum":3407412507,"timestamp":"2024-06-01T18:06:30.690550Z"}]}
{"channel":"book","type":"update","data":[{"symbol":"ETH/USDC","bids":[{"price":3798.22,"qty":0.78662516}],"asks":[],"checksum":1696692462,"timestamp":"2024-06-01T18:06:30.695983Z"}]}
{"channel":"book","type":"update","data":[{"symbol":"ETH/USDC","bids":[{"price":3797.61,"qty":0.33750000}],"asks":[],"checksum":3970764907,"timestamp":"2024-06-01T18:06:30.697744Z"}]}
{"channel":"book","type":"update","data":[{"symbol":"ETH/USDC","bids":[],"asks":[{"price":3799.86,"qty":0.65791918}],"checksum":1637273530,"timestamp":"2024-06-01T18:06:30.698583Z"}]}
{"channel":"book","type":"update","data":[{"symbol":"ETH/USDC","bids":[{"price":3798.39,"qty":0.65817235}],"asks":[],"checksum":3332112834,"timestamp":"2024-06-01T18:06:30.698684Z"}]}
{"channel":"book","type":"update","data":[{"symbol":"ETH/USDC","bids":[{"price":3797.41,"qty":1.31668578}],"asks":[],"checksum":2842193937,"timestamp":"2024-06-01T18:06:30.698718Z"}]}
{"channel":"book","type":"update","data":[{"symbol":"ETH/USDC","bids":[],"asks":[{"price":3800.80,"qty":1.31551286}],"checksum":1773379472,"timestamp":"2024-06-01T18:06:30.698743Z"}]}
{"channel":"book","type":"update","data":[{"symbol":"ETH/USDC","bids":[],"asks":[{"price":3801.55,"qty":0.00000000},{"price":3801.59,"qty":0.00536160}],"checksum":2315298273,"timestamp":"2024-06-01T18:06:30.698995Z"}]}
{"channel":"book","type":"update","data":[{"symbol":"ETH/USDC","bids":[],"asks":[{"price":3799.83,"qty":1.31604982}],"checksum":2831945383,"timestamp":"2024-06-01T18:06:30.699113Z"}]}
{"channel":"book","type":"update","data":[{"symbol":"ETH/USDC","bids":[],"asks":[{"price":3799.87,"qty":0.33750000}],"checksum":2259499371,"timestamp":"2024-06-01T18:06:30.700015Z"}]}
{"channel":"book","type":"update","data":[{"symbol":"ETH/USDC","bids":[],"asks":[{"price":3799.68,"qty":0.33750000}],"checksum":2195240985,"timestamp":"2024-06-01T18:06:30.709304Z"}]}
{"channel":"book","type":"update","data":[{"symbol":"ETH/USDC","bids":[],"asks":[{"price":3799.49,"qty":0.33750000}],"checksum":30198540,"timestamp":"2024-06-01T18:06:30.709442Z"}]}
{"channel":"book","type":"update","data":[{"symbol":"ETH/USDC","bids":[],"asks":[{"price":3799.86,"qty":0.00000000},{"price":3801.38,"qty":5.87253870}],"checksum":1869197975,"timestamp":"2024-06-01T18:06:30.710093Z"}]}
{"channel":"book","type":"update","data":[{"symbol":"ETH/USDC","bids":[],"asks":[{"price":3800.81,"qty":0.33750000}],"checksum":433846944,"timestamp":"2024-06-01T18:06:30.715773Z"}]}
