{"channel":"book","type":"update","data":[{"symbol":"ETH/GBP","bids":[],"asks":[{"price":2981.12,"qty":6.57922090}],"checksum":2942487604,"timestamp":"2024-06-01T18:06:23.092733Z"}]}
{"channel":"book","type":"update","data":[{"symbol":"ETH/GBP","bids":[],"asks":[{"price":2981.12,"qty":0.00000000},{"price":2984.03,"qty":1.31456248}],"checksum":3353914733,"timestamp":"2024-06-01T18:06:23.641943Z"}]}
{"channel":"book","type":"update","data":[{"symbol":"ETH/GBP","bids":[{"price":2980.91,"qty":0.00000000},{"price":2977.45,"qty":0.14093574}],"asks":[],"checksum":1461951215,"timestamp":"2024-06-01T18:06:23.641968Z"}]}
{"channel":"book","type":"update","data":[{"symbol":"ETH/GBP","bids":[{"price":2980.71,"qty":0.31000000}],"asks":[],"checksum":2479486186,"timestamp":"2024-06-01T18:06:23.645127Z"}]}
{"channel":"book","type":"update","data":[{"symbol":"ETH/GBP","bids":[],"asks":[{"price":2981.10,"qty":6.57926564}],"checksum":105137178,"timestamp":"2024-06-01T18:06:23.647159Z"}]}
{"channel":"book","type":"update","data":[{"symbol":"ETH/GBP","bids":[],"asks":[{"price":2981.54,"qty":0.00000000},{"price":2984.03,"qty":1.31456248}],"checksum":2629499175,"timestamp":"2024-06-01T18:06:23.647176Z"}]}
{"channel":"book","type":"update","data":[{"symbol":"ETH/GBP","bids":[{"price":2980.88,"qty":6.57973514}],"asks":[],"checksum":1119084783,"timestamp":"2024-06-01T18:06:23.647389Z"}]}
{"channel":"book","type":"update","data":[{"symbol":"ETH/GBP","bids":[],"asks":[{"price":2981.53,"qty":13.15662325}],"checksum":1434146248,"timestamp":"2024-06-01T18:06:23.652630Z"}]}
{"channel":"book","type":"update","data":[{"symbol":"ETH/GBP","bids":[],"asks":[{"price":2983.16,"qty":0.00000000},{"price":2984.03,"qty":1.31456248}],"checksum":3617215531,"timestamp":"2024-06-01T18:06:23.667159Z"}]}
{"channel":"book","type":"update","data":[{"symbol":"ETH/GBP","bids":[{"price":2980.40,"qty":0.00000000},{"price":2977.74,"qty":0.21600000}],"asks":[],"checksum":811626632,"timestamp":"2024-06-01T18:06:23.721697Z"}]}
{"channel":"book","type":"update","data":[{"symbol":"ETH/GBP","bids":[{"price":2980.36,"qty":5.92990577}],"asks":[],"checksum":2495475328,"timestamp":"2024-06-01T18:06:23.725736Z"}]}
{"channel":"book","type":"update","data":[{"symbol":"ETH/GBP","bids":[{"price":2980.36,"qty":0.00000000},{"price":2977.74,"qty":0.21600000}],"asks":[],"checksum":811626632,"timestamp":"2024-06-01T18:06:23.727967Z"}]}
{"channel":"book","type":"update","data":[{"symbol":"ETH/GBP","bids":[],"asks":[{"price":2981.10,"qty":0.00000000},{"price":2984.35,"qty":0.30200000}],"checksum":2824275411,"timestamp":"2024-06-01T18:06:23.731201Z"}]}
{"channel":"book","type":"update","data":[{"symbol":"ETH/GBP","bids":[],"asks":[{"price":2983.71,"qty":1.00000000}],"checksum":3324646565,"timestamp":"2024-06-01T18:06:23.731242Z"}]}
{"channel":"book","type":"update","data":[{"symbol":"ETH/GBP","bids":[{"price":2980.26,"qty":5.93010474}],"asks":[],"checksum":1726619241,"timestamp":"2024-06-01T18:06:23.731473Z"}]}
{"channel":"book","type":"update","data":[{"symbol":"ETH/GBP","bids":[],"asks":[{"price":2981.53,"qty":0.00000000},{"price":2984.35,"qty":0.30200000}],"checksum":2566535792,"timestamp":"2024-06-01T18:06:23.735646Z"}]}
{"channel":"book","type":"update","data":[{"symbol":"ETH/GBP","bids":[],"asks":[{"price":2982.30,"qty":0.00000000},{"price":2984.40,"qty":2.94416492}],"checksum":3843517255,"timestamp":"2024-06-01T18:06:23.740203Z"}]}
{"channel":"book","type":"update","data":[{"symbol":"ETH/GBP","bids":[],"asks":[{"price":2983.12,"qty":1.31577700}],"checksum":2862746433,"timestamp":"2024-06-01T18:06:23.742949Z"}]}
{"channel":"book","type":"update","data":[{"symbol":"ETH/GBP","bids":[],"asks":[{"price":2983.17,"qty":0.00000000},{"price":2984.40,"qty":2.94416492}],"checksum":2456178636,"timestamp":"2024-06-01T18:06:23.744749Z"}]}
{"channel":"book","type":"update","data":[{"symbol":"ETH/GBP","bids":[],"asks":[{"price":2982.29,"qty":1.31532889}],"checksum":480985118,"timestamp":"2024-06-01T18:06:23.744759Z"}]}
{"channel":"book","type":"update","data":[{"symbol":"ETH/GBP","bids":[],"asks":[{"price":2982.29,"qty":0.00000000},{"price":2984.40,"qty":2.94416492}],"checksum":2456178636,"timestamp":"2024-06-01T18:06:23.751339Z"}]}
{"channel":"book","type":"update","data":[{"symbol":"ETH/GBP","bids":[],"asks":[{"price":2981.09,"qty":6.57929507}],"checksum":1621485495,"timestamp":"2024-06-01T18:06:23.755764Z"}]}
{"channel":"book","type":"update","data":[{"symbol":"ETH/GBP","bids":[],"asks":[{"price":2983.10,"qty":1.31497095}],"checksum":3079272619,"timestamp":"2024-06-01T18:06:23.755888Z"}]}
{"channel":"book","type":"update","data":[{"symbol":"ETH/GBP","bids":[],"asks":[{"price":2984.02,"qty":0.00000000},{"price":2984.35,"qty":0.30200000}],"checksum":2308782120,"timestamp":"2024-06-01T18:06:23.761070Z"}]}
{"channel":"book","type":"update","data":[{"symbol":"ETH/GBP","bids":[],"asks":[{"price":2981.09,"qty":0.00000000},{"price":2984.40,"qty":2.94416492}],"checksum":2279622296,"timestamp":"2024-06-01T18:06:23.809894Z"}]}
{"channel":"book","type":"update","data":[{"symbol":"ETH/GBP","bids":[{"price":2980.48,"qty":0.00000000},{"price":2977.45,"qty":0.14093574}],"asks":[],"checksum":2361259487,"timestamp":"2024-06-01T18:06:23.809963Z"}]}
{"channel":"book","type":"update","data":[{"symbol":"ETH/GBP","bids":[{"price":2978.12,"qty":0.00000000},{"price":2977.44,"qty":1.31746928}],"asks":[],"checksum":2480078293,"timestamp":"2024-06-01T18:06:23.812588Z"}]}
{"channel":"book","type":"update","data":[{"symbol":"ETH/GBP","bids":[],"asks":[{"price":2983.07,"qty":1.31578995}],"checksum":722576316,"timestamp":"2024-06-01T18:06:23.812967Z"}]}
{"channel":"book","type":"update","data":[{"symbol":"ETH/GBP","bids":[],"asks":[{"price":2983.12,"qty":0.00000000},{"price":2984.40,"qty":2.94416492}],"checksum":2461841710,"timestamp":"2024-06-01T18:06:23.813114Z"}]}
{"channel":"book","type":"update","data":[{"symbol":"ETH/GBP","bids":[{"price":2977.79,"qty":1.33800000}],"asks":[],"checksum":1682922951,"timestamp":"2024-06-01T18:06:23.816916Z"}]}
{"channel":"book","type":"update","data":[{"symbol":"ETH/GBP","bids":[],"asks":[{"price":2983.10,"qty":0.00000000},{"price":2984.60,"qty":1.33800000}],"checksum":2249134761,"timestamp":"2024-06-01T18:06:23.819977Z"}]}
{"channel":"book","type":"update","data":[{"symbol":"ETH/GBP","bids":[{"price":2979.31,"qty":0.00000000},{"price":2977.44,"qty":1.31746928}],"asks":[],"checksum":262734827,"timestamp":"2024-06-01T18:06:23.820065Z"}]}
{"channel":"book","type":"update","data":[{"symbol":"ETH/GBP","bids":[{"price":2980.36,"qty":13.16178478}],"asks":[],"checksum":988036953,"timestamp":"2024-06-01T18:06:23.825914Z"}]}
{"channel":"book","type":"update","data":[{"symbol":"ETH/GBP","bids":[{"price":2978.90,"qty":1.31682252}],"asks":[],"checksum":697126750,"timestamp":"2024-06-01T18:06:23.825934Z"}]}
{"channel":"book","type":"update","data":[{"symbol":"ETH/GBP","bids":[{"price":2980.73,"qty":6.58006923}],"asks":[],"checksum":1153244332,"timestamp":"2024-06-01T18:06:23.825945Z"}]}
{"channel":"book","type":"update","data":[{"symbol":"ETH/GBP","bids":[{"price":2980.73,"qty":0.00000000},{"price":2977.74,"qty":0.21600000}],"asks":[],"checksum":697126750,"timestamp":"2024-06-01T18:06:23.831008Z"}]}
{"channel":"book","type":"update","data":[{"symbol":"ETH/GBP","bids":[],"asks":[{"price":2983.05,"qty":6.57496761}],"checksum":773569357,"timestamp":"2024-06-01T18:06:23.863414Z"}]}
{"channel":"book","type":"update","data":[{"symbol":"ETH/GBP","bids":[],"asks":[{"price":2983.05,"qty":19.72490283}],"checksum":2487514786,"timestamp":"2024-06-01T18:06:23.863538Z"}]}
{"channel":"book","type":"update","data":[{"symbol":"ETH/GBP","bids":[],"asks":[{"price":2983.02,"qty":1.31580569}],"checksum":821946300,"timestamp":"2024-06-01T18:06:23.866490Z"}]}
{"channel":"book","type":"update","data":[{"symbol":"ETH/GBP","bids":[],"asks":[{"price":2983.05,"qty":13.14993522}],"checksum":1826650856,"timestamp":"2024-06-01T18:06:23.868260Z"}]}
{"channel":"book","type":"update","data":[{"symbol":"ETH/GBP","bids":[],"asks":[{"price":2983.05,"qty":0.00000000},{"price":2984.40,"qty":2.94416492}],"checksum":1944823564,"timestamp":"2024-06-01T18:06:23.868306Z"}]}
{"channel":"book","type":"update","data":[{"symbol":"ETH/GBP","bids":[],"asks":[{"price":2983.07,"qty":0.00000000},{"price":2984.60,"qty":1.33800000}],"checksum":148510386,"timestamp":"2024-06-01T18:06:23.869542Z"}]}
{"channel":"book","type":"update","data":[{"symbol":"ETH/GBP","bids":[],"asks":[{"price":2983.00,"qty":6.57507671}],"checksum":1404089233,"timestamp":"2024-06-01T18:06:24.272019Z"}]}
{"channel":"book","type":"update","data":[{"symbol":"ETH/GBP","bids":[{"price":2980.81,"qty":6.57989467}],"asks":[],"checksum":587878654,"timestamp":"2024-06-01T18:06:24.272056Z"}]}
{"channel":"book","type":"update","data":[{"symbol":"ETH/GBP","bids":[],"asks":[{"price":2983.00,"qty":19.72523014}],"checksum":1610861946,"timestamp":"2024-06-01T18:06:24.272174Z"}]}
{"channel":"book","type":"update","data":[{"symbol":"ETH/GBP","bids":[],"asks":[{"price":2982.97,"qty":1.31582053}],"checksum":1751528357,"timestamp":"2024-06-01T18:06:24.274960Z"}]}
{"channel":"book","type":"update","data":[{"symbol":"ETH/GBP","bids":[],"asks":[{"price":2983.02,"qty":0.00000000},{"price":2984.40,"qty":2.94416492}],"checksum":2463471101,"timestamp":"2024-06-01T18:06:24.275160Z"}]}
{"channel":"book","type":"update","data":[{"symbol":"ETH/GBP","bids":[],"asks":[{"price":2983.00,"qty":6.57507671}],"checksum":3103000744,"timestamp":"2024-06-01T18:06:24.277256Z"}]}
{"channel":"book","type":"update","data":[{"symbol":"ETH/GBP","bids":[],"asks":[{"price":2983.00,"qty":0.00000000},{"price":2984.60,"qty":1.33800000}],"checksum":3180788861,"timestamp":"2024-06-01T18:06:24.277356Z"}]}
{"channel":"book","type":"update","data":[{"symbol":"ETH/GBP","bids":[{"price":2980.81,"qty":0.00000000},{"price":2977.74,"qty":0.21600000}],"asks":[],"checksum":2877920150,"timestamp":"2024-06-01T18:06:24.475284Z"}]}
{"channel":"book","type":"update","data":[{"symbol":"ETH/GBP","bids":[],"asks":[{"price":2981.04,"qty":6.57940887}],"checksum":3726435056,"timestamp":"2024-06-01T18:06:24.480534Z"}]}
{"channel":"book","type":"update","data":[{"symbol":"ETH/GBP","bids":[{"price":2980.82,"qty":6.57987361}],"asks":[],"checksum":2928878496,"timestamp":"2024-06-01T18:06:24.480710Z"}]}
{"channel":"book","type":"update","data":[{"symbol":"ETH/GBP","bids":[],"asks":[{"price":2981.47,"qty":13.15691518}],"checksum":1678779133,"timestamp":"2024-06-01T18:06:24.480779Z"}]}
{"channel":"book","type":"update","data":[{"symbol":"ETH/GBP","bids":[{"price":2980.82,"qty":0.00000000},{"price":2977.74,"qty":0.21600000}],"asks":[],"checksum":3890164993,"timestamp":"2024-06-01T18:06:24.816597Z"}]}
{"channel":"book","type":"update","data":[{"symbol":"ETH/GBP","bids":[{"price":2980.71,"qty":0.00000000},{"price":2977.45,"qty":0.14093574}],"asks":[],"checksum":390833015,"timestamp":"2024-06-01T18:06:24.819391Z"}]}
{"channel":"book","type":"update","data":[{"symbol":"ETH/GBP","bids":[],"asks":[{"price":2982.23,"qty":1.31535484}],"checksum":3871981849,"timestamp":"2024-06-01T18:06:24.821042Z"}]}
{"channel":"book","type":"update","data":[{"symbol":"ETH/GBP","bids":[{"price":2980.83,"qty":6.57983780}],"asks":[],"checksum":466755876,"timestamp":"2024-06-01T18:06:24.821138Z"}]}
