{"channel":"book","type":"snapshot","data":[{"symbol":"ETH/EUR","bids":[{"price":3505.50,"qty":0.00220000},{"price":3505.40,"qty":0.00220000},{"price":3505.36,"qty":26.30217609},{"price":3505.33,"qty":26.33773642},{"price":3505.32,"qty":0.63360987},{"price":3505.31,"qty":0.10520315},{"price":3505.20,"qty":0.00220000},{"price":3505.08,"qty":26.30429617},{"price":3505.07,"qty":0.08553700},{"price":3505.00,"qty":0.00220000}],"asks":[{"price":3505.52,"qty":1.80000000},{"price":3505.65,"qty":26.30012624},{"price":3505.70,"qty":0.01599905},{"price":3505.71,"qty":15.78864270},{"price":3505.87,"qty":1.05900000},{"price":3505.99,"qty":26.29752592},{"price":3506.01,"qty":0.72912968},{"price":3506.03,"qty":0.08552600},{"price":3506.16,"qty":26.29629268},{"price":3506.34,"qty":3.94500000}],"checksum":4226541806}]}
{"channel":"book","type":"update","data":[{"symbol":"ETH/EUR","bids":[],"asks":[{"price":3505.65,"qty":0.00000000},{"price":3506.39,"qty":3.01305282}],"checksum":2342751127,"timestamp":"2024-06-01T18:06:03.985454Z"}]}
{"channel":"book","type":"update","data":[{"symbol":"ETH/EUR","bids":[],"asks":[{"price":3505.64,"qty":26.30017619}],"checksum":3699456563,"timestamp":"2024-06-01T18:06:03.988865Z"}]}
{"channel":"book","type":"update","data":[{"symbol":"ETH/EUR","bids":[],"asks":[{"price":3505.75,"qty":26.29932405}],"checksum":1993024407,"timestamp":"2024-06-01T18:06:03.989022Z"}]}
{"channel":"book","type":"update","data":[{"symbol":"ETH/EUR","bids":[],"asks":[{"price":3505.99,"qty":0.00000000},{"price":3506.34,"qty":3.94500000}],"checksum":3852610519,"timestamp":"2024-06-01T18:06:03.994871Z"}]}
{"channel":"book","type":"update","data":[{"symbol":"ETH/EUR","bids":[],"asks":[{"price":3505.64,"qty":0.00000000},{"price":3506.39,"qty":3.01305282}],"checksum":1911532824,"timestamp":"2024-06-01T18:06:03.996529Z"}]}
{"channel":"book","type":"update","data":[{"symbol":"ETH/EUR","bids":[{"price":3505.36,"qty":0.00000000},{"price":3504.80,"qty":1.60220000}],"asks":[],"checksum":3277147510,"timestamp":"2024-06-01T18:06:03.996609Z"}]}
{"channel":"book","type":"update","data":[{"symbol":"ETH/EUR","bids":[],"asks":[{"price":3505.88,"qty":26.29836179}],"checksum":923552363,"timestamp":"2024-06-01T18:06:04.000264Z"}]}
{"channel":"book","type":"update","data":[{"symbol":"ETH/EUR","bids":[],"asks":[{"price":3505.65,"qty":26.30012624}],"checksum":2873149599,"timestamp":"2024-06-01T18:06:04.047128Z"}]}
{"channel":"book","type":"update","data":[{"symbol":"ETH/EUR","bids":[],"asks":[{"price":3505.75,"qty":0.00000000},{"price":3506.34,"qty":3.94500000}],"checksum":3302028293,"timestamp":"2024-06-01T18:06:04.252863Z"}]}
{"channel":"book","type":"update","data":[{"symbol":"ETH/EUR","bids":[],"asks":[{"price":3505.61,"qty":26.30038651}],"checksum":1297372343,"timestamp":"2024-06-01T18:06:04.257057Z"}]}
{"channel":"book","type":"update","data":[{"symbol":"ETH/EUR","bids":[{"price":3505.33,"qty":0.03529173}],"asks":[],"checksum":2672664893,"timestamp":"2024-06-01T18:06:04.367644Z"}]}
{"channel":"book","type":"update","data":[{"symbol":"ETH/EUR","bids":[],"asks":[{"price":3505.61,"qty":0.00000000},{"price":3506.34,"qty":3.94500000}],"checksum":469419957,"timestamp":"2024-06-01T18:06:04.367685Z"}]}
{"channel":"book","type":"update","data":[{"symbol":"ETH/EUR","bids":[],"asks":[{"price":3505.59,"qty":26.30054834}],"checksum":938782227,"timestamp":"2024-06-01T18:06:04.373015Z"}]}
{"channel":"book","type":"update","data":[{"symbol":"ETH/EUR","bids":[],"asks":[{"price":3505.59,"qty":0.00000000},{"price":3506.34,"qty":3.94500000}],"checksum":469419957,"timestamp":"2024-06-01T18:06:04.376578Z"}]}
{"channel":"book","type":"update","data":[{"symbol":"ETH/EUR","bids":[],"asks":[{"price":3505.70,"qty":0.00000000},{"price":3506.39,"qty":3.01305282},{"price":3505.64,"qty":0.01599901}],"checksum":2725671787,"timestamp":"2024-06-01T18:06:04.512212Z"}]}
{"channel":"book","type":"update","data":[{"symbol":"ETH/EUR","bids":[],"asks":[{"price":3505.60,"qty":26.30047806}],"checksum":4199000191,"timestamp":"2024-06-01T18:06:04.553191Z"}]}
{"channel":"book","type":"update","data":[{"symbol":"ETH/EUR","bids":[],"asks":[{"price":3505.64,"qty":29.02012557}],"checksum":2209580427,"timestamp":"2024-06-01T18:06:04.577964Z"}]}
{"channel":"book","type":"update","data":[{"symbol":"ETH/EUR","bids":[],"asks":[{"price":3505.52,"qty":1.78875805}],"checksum":3122112597,"timestamp":"2024-06-01T18:06:05.078206Z"}]}
{"channel":"book","type":"update","data":[{"symbol":"ETH/EUR","bids":[],"asks":[{"price":3505.60,"qty":0.00000000},{"price":3506.34,"qty":3.94500000}],"checksum":5049549,"timestamp":"2024-06-01T18:06:05.318633Z"}]}
{"channel":"book","type":"update","data":[{"symbol":"ETH/EUR","bids":[],"asks":[{"price":3505.58,"qty":26.30062830}],"checksum":3476852810,"timestamp":"2024-06-01T18:06:05.322803Z"}]}
{"channel":"book","type":"update","data":[{"symbol":"ETH/EUR","bids":[{"price":3505.30,"qty":26.30263160}],"asks":[],"checksum":1512425448,"timestamp":"2024-06-01T18:06:05.323035Z"}]}
{"channel":"book","type":"update","data":[{"symbol":"ETH/EUR","bids":[{"price":3505.25,"qty":26.30302044}],"asks":[],"checksum":2584429728,"timestamp":"2024-06-01T18:06:05.323140Z"}]}
{"channel":"book","type":"update","data":[{"symbol":"ETH/EUR","bids":[],"asks":[{"price":3505.64,"qty":29.00412656},{"price":3505.63,"qty":0.01577777}],"checksum":3363149982,"timestamp":"2024-06-01T18:06:05.392270Z"}]}
{"channel":"book","type":"update","data":[{"symbol":"ETH/EUR","bids":[],"asks":[{"price":3505.90,"qty":15.78735486}],"checksum":4028818737,"timestamp":"2024-06-01T18:06:05.550608Z"}]}
{"channel":"book","type":"update","data":[{"symbol":"ETH/EUR","bids":[],"asks":[{"price":3505.58,"qty":0.00000000},{"price":3506.03,"qty":0.08552600}],"checksum":2292273743,"timestamp":"2024-06-01T18:06:05.850211Z"}]}
{"channel":"book","type":"update","data":[{"symbol":"ETH/EUR","bids":[],"asks":[{"price":3505.57,"qty":26.30072032}],"checksum":1144014906,"timestamp":"2024-06-01T18:06:05.853816Z"}]}
{"channel":"book","type":"update","data":[{"symbol":"ETH/EUR","bids":[],"asks":[{"price":3505.57,"qty":0.00000000},{"price":3506.03,"qty":0.08552600}],"checksum":2292273743,"timestamp":"2024-06-01T18:06:05.858732Z"}]}
{"channel":"book","type":"update","data":[{"symbol":"ETH/EUR","bids":[{"price":3505.30,"qty":0.00000000},{"price":3505.00,"qty":0.00220000}],"asks":[],"checksum":4093109389,"timestamp":"2024-06-01T18:06:06.138686Z"}]}
{"channel":"book","type":"update","data":[{"symbol":"ETH/EUR","bids":[],"asks":[{"price":3505.59,"qty":26.30056752}],"checksum":1954348847,"timestamp":"2024-06-01T18:06:06.142693Z"}]}
{"channel":"book","type":"update","data":[{"symbol":"ETH/EUR","bids":[],"asks":[{"price":3505.78,"qty":0.08552800}],"checksum":1577936654,"timestamp":"2024-06-01T18:06:06.173344Z"}]}
{"channel":"book","type":"update","data":[{"symbol":"ETH/EUR","bids":[],"asks":[{"price":3505.59,"qty":0.00000000},{"price":3506.01,"qty":0.72912968}],"checksum":1197673393,"timestamp":"2024-06-01T18:06:06.173366Z"}]}
{"channel":"book","type":"update","data":[{"symbol":"ETH/EUR","bids":[],"asks":[{"price":3505.52,"qty":0.00000000},{"price":3506.16,"qty":26.29629268}],"checksum":295621604,"timestamp":"2024-06-01T18:06:06.263816Z"}]}
{"channel":"book","type":"update","data":[{"symbol":"ETH/EUR","bids":[],"asks":[{"price":3505.57,"qty":26.30068320}],"checksum":808092967,"timestamp":"2024-06-01T18:06:06.299945Z"}]}
{"channel":"book","type":"update","data":[{"symbol":"ETH/EUR","bids":[{"price":3505.51,"qty":4.06000000}],"asks":[],"checksum":809414381,"timestamp":"2024-06-01T18:06:06.358517Z"}]}
{"channel":"book","type":"update","data":[{"symbol":"ETH/EUR","bids":[],"asks":[{"price":3505.57,"qty":0.00000000},{"price":3506.16,"qty":26.29629268}],"checksum":2201619346,"timestamp":"2024-06-01T18:06:06.391155Z"}]}
{"channel":"book","type":"update","data":[{"symbol":"ETH/EUR","bids":[],"asks":[{"price":3505.56,"qty":26.30076999}],"checksum":1795002722,"timestamp":"2024-06-01T18:06:06.395887Z"}]}
{"channel":"book","type":"update","data":[{"symbol":"ETH/EUR","bids":[],"asks":[{"price":3505.56,"qty":0.00000000},{"price":3506.16,"qty":26.29629268}],"checksum":2201619346,"timestamp":"2024-06-01T18:06:06.404087Z"}]}
{"channel":"book","type":"update","data":[{"symbol":"ETH/EUR","bids":[],"asks":[{"price":3505.65,"qty":0.00000000},{"price":3506.34,"qty":3.94500000}],"checksum":45621866,"timestamp":"2024-06-01T18:06:06.404133Z"}]}
{"channel":"book","type":"update","data":[{"symbol":"ETH/EUR","bids":[{"price":3505.33,"qty":0.00000000},{"price":3505.00,"qty":0.00220000},{"price":3505.52,"qty":0.03536876}],"asks":[],"checksum":2476641064,"timestamp":"2024-06-01T18:06:06.419930Z"}]}
{"channel":"book","type":"update","data":[{"symbol":"ETH/EUR","bids":[{"price":3505.51,"qty":0.00000000},{"price":3505.00,"qty":0.00220000}],"asks":[],"checksum":1647144593,"timestamp":"2024-06-01T18:06:06.478429Z"}]}
{"channel":"book","type":"update","data":[{"symbol":"ETH/EUR","bids":[{"price":3505.52,"qty":0.00000000},{"price":3504.80,"qty":1.60220000},{"price":3505.33,"qty":0.03537067}],"asks":[],"checksum":3090082993,"timestamp":"2024-06-01T18:06:06.522914Z"}]}
{"channel":"book","type":"update","data":[{"symbol":"ETH/EUR","bids":[],"asks":[{"price":3505.64,"qty":0.00000000},{"price":3506.39,"qty":3.01305282}],"checksum":507081454,"timestamp":"2024-06-01T18:06:06.915879Z"}]}
{"channel":"book","type":"update","data":[{"symbol":"ETH/EUR","bids":[],"asks":[{"price":3505.70,"qty":14.47459192}],"checksum":1836131605,"timestamp":"2024-06-01T18:06:06.921104Z"}]}
{"channel":"book","type":"update","data":[{"symbol":"ETH/EUR","bids":[],"asks":[{"price":3505.86,"qty":35.50957727}],"checksum":76233631,"timestamp":"2024-06-01T18:06:06.922726Z"}]}
{"channel":"book","type":"update","data":[{"symbol":"ETH/EUR","bids":[],"asks":[{"price":3505.63,"qty":0.00000000},{"price":3506.34,"qty":3.94500000},{"price":3505.69,"qty":0.01577772}],"checksum":1096456580,"timestamp":"2024-06-01T18:06:06.981475Z"}]}
{"channel":"book","type":"update","data":[{"symbol":"ETH/EUR","bids":[{"price":3505.31,"qty":26.40777682}],"asks":[],"checksum":610796630,"timestamp":"2024-06-01T18:06:06.989333Z"}]}
{"channel":"book","type":"update","data":[{"symbol":"ETH/EUR","bids":[],"asks":[{"price":3505.62,"qty":26.30028489}],"checksum":2112850813,"timestamp":"2024-06-01T18:06:06.989373Z"}]}
{"channel":"book","type":"update","data":[{"symbol":"ETH/EUR","bids":[],"asks":[{"price":3505.62,"qty":0.00000000},{"price":3506.16,"qty":26.29629268}],"checksum":610796630,"timestamp":"2024-06-01T18:06:06.994042Z"}]}
{"channel":"book","type":"update","data":[{"symbol":"ETH/EUR","bids":[],"asks":[{"price":3506.15,"qty":0.04101527}],"checksum":3067040956,"timestamp":"2024-06-01T18:06:07.164351Z"}]}
{"channel":"book","type":"update","data":[{"symbol":"ETH/EUR","bids":[{"price":3505.31,"qty":0.10520315}],"asks":[],"checksum":4119382342,"timestamp":"2024-06-01T18:06:07.328238Z"}]}
{"channel":"book","type":"update","data":[{"symbol":"ETH/EUR","bids":[],"asks":[{"price":3505.57,"qty":26.30068620}],"checksum":1002827231,"timestamp":"2024-06-01T18:06:07.332030Z"}]}
{"channel":"book","type":"update","data":[{"symbol":"ETH/EUR","bids":[{"price":3505.29,"qty":26.30274169}],"asks":[],"checksum":3706316178,"timestamp":"2024-06-01T18:06:07.332130Z"}]}
{"channel":"book","type":"update","data":[{"symbol":"ETH/EUR","bids":[{"price":3505.51,"qty":1.27500000}],"asks":[],"checksum":461489315,"timestamp":"2024-06-01T18:06:07.476573Z"}]}
{"channel":"book","type":"update","data":[{"symbol":"ETH/EUR","bids":[{"price":3505.33,"qty":0.00000000},{"price":3505.07,"qty":0.08553700},{"price":3505.52,"qty":0.03536547}],"asks":[],"checksum":2892671752,"timestamp":"2024-06-01T18:06:07.533166Z"}]}
{"channel":"book","type":"update","data":[{"symbol":"ETH/EUR","bids":[{"price":3505.51,"qty":0.00000000},{"price":3505.07,"qty":0.08553700}],"asks":[],"checksum":3839430336,"timestamp":"2024-06-01T18:06:07.655876Z"}]}
{"channel":"book","type":"update","data":[{"symbol":"ETH/EUR","bids":[{"price":3505.52,"qty":0.00000000},{"price":3505.00,"qty":0.00220000},{"price":3505.33,"qty":0.03536745}],"asks":[],"checksum":2188502617,"timestamp":"2024-06-01T18:06:07.682441Z"}]}
{"channel":"book","type":"update","data":[{"symbol":"ETH/EUR","bids":[],"asks":[{"price":3505.90,"qty":0.00000000},{"price":3506.15,"qty":0.04101527}],"checksum":1566065520,"timestamp":"2024-06-01T18:06:07.833367Z"}]}
{"channel":"book","type":"update","data":[{"symbol":"ETH/EUR","bids":[],"asks":[{"price":3505.71,"qty":0.00000000},{"price":3506.16,"qty":26.29629268}],"checksum":4098951270,"timestamp":"2024-06-01T18:06:07.833527Z"}]}
{"channel":"book","type":"update","data":[{"symbol":"ETH/EUR","bids":[],"asks":[{"price":3505.69,"qty":0.00000000},{"price":3506.34,"qty":3.94500000},{"price":3505.85,"qty":0.01577742}],"checksum":1598416294,"timestamp":"2024-06-01T18:06:07.895871Z"}]}
{"channel":"book","type":"update","data":[{"symbol":"ETH/EUR","bids":[],"asks":[{"price":3505.68,"qty":26.29983476}],"checksum":798448758,"timestamp":"2024-06-01T18:06:08.241100Z"}]}
{"channel":"book","type":"update","data":[{"symbol":"ETH/EUR","bids":[{"price":3505.29,"qty":0.00000000},{"price":3505.00,"qty":0.00220000}],"asks":[],"checksum":2773416754,"timestamp":"2024-06-01T18:06:08.264040Z"}]}
{"channel":"book","type":"update","data":[{"symbol":"ETH/EUR","bids":[],"asks":[{"price":3505.57,"qty":0.00000000},{"price":3506.16,"qty":26.29629268}],"checksum":878380673,"timestamp":"2024-06-01T18:06:08.333398Z"}]}
{"channel":"book","type":"update","data":[{"symbol":"ETH/EUR","bids":[],"asks":[{"price":3505.56,"qty":26.30075376}],"checksum":1962155211,"timestamp":"2024-06-01T18:06:08.340293Z"}]}
{"channel":"book","type":"update","data":[{"symbol":"ETH/EUR","bids":[],"asks":[{"price":3505.68,"qty":0.00000000},{"price":3506.16,"qty":26.29629268}],"checksum":3796097948,"timestamp":"2024-06-01T18:06:08.340423Z"}]}
{"channel":"book","type":"update","data":[{"symbol":"ETH/EUR","bids":[],"asks":[{"price":3505.67,"qty":26.29990978}],"checksum":636873188,"timestamp":"2024-06-01T18:06:08.344504Z"}]}
{"channel":"book","type":"update","data":[{"symbol":"ETH/EUR","bids":[],"asks":[{"price":3505.85,"qty":0.00000000},{"price":3506.16,"qty":26.29629268},{"price":3505.67,"qty":26.31568721}],"checksum":3916380853,"timestamp":"2024-06-01T18:06:08.347410Z"}]}
{"channel":"book","type":"update","data":[{"symbol":"ETH/EUR","bids":[{"price":3505.51,"qty":1.44000000}],"asks":[],"checksum":2578580341,"timestamp":"2024-06-01T18:06:08.432715Z"}]}
{"channel":"book","type":"update","data":[{"symbol":"ETH/EUR","bids":[],"asks":[{"price":3505.56,"qty":0.00000000},{"price":3506.34,"qty":3.94500000}],"checksum":3630122054,"timestamp":"2024-06-01T18:06:08.610004Z"}]}
{"channel":"book","type":"update","data":[{"symbol":"ETH/EUR","bids":[],"asks":[{"price":3505.67,"qty":0.01577743}],"checksum":2667615803,"timestamp":"2024-06-01T18:06:08.614669Z"}]}
{"channel":"book","type":"update","data":[{"symbol":"ETH/EUR","bids":[],"asks":[{"price":3505.67,"qty":0.00000000},{"price":3506.38,"qty":0.15840741},{"price":3505.69,"qty":0.01577743}],"checksum":2387476288,"timestamp":"2024-06-01T18:06:08.618057Z"}]}
{"channel":"book","type":"update","data":[{"symbol":"ETH/EUR","bids":[],"asks":[{"price":3505.59,"qty":26.30055658}],"checksum":3079969288,"timestamp":"2024-06-01T18:06:08.618158Z"}]}
{"channel":"book","type":"update","data":[{"symbol":"ETH/EUR","bids":[],"asks":[{"price":3505.66,"qty":26.29998480}],"checksum":3517328674,"timestamp":"2024-06-01T18:06:08.618237Z"}]}
{"channel":"book","type":"update","data":[{"symbol":"ETH/EUR","bids":[{"price":3505.51,"qty":0.00000000},{"price":3505.00,"qty":0.00220000}],"asks":[],"checksum":1936454355,"timestamp":"2024-06-01T18:06:08.735738Z"}]}
{"channel":"book","type":"update","data":[{"symbol":"ETH/EUR","bids":[],"asks":[{"price":3505.59,"qty":0.00000000},{"price":3506.16,"qty":26.29629268}],"checksum":1070892250,"timestamp":"2024-06-01T18:06:08.869820Z"}]}
{"channel":"book","type":"update","data":[{"symbol":"ETH/EUR","bids":[],"asks":[{"price":3505.66,"qty":0.00000000},{"price":3506.34,"qty":3.94500000}],"checksum":2787760421,"timestamp":"2024-06-01T18:06:08.874341Z"}]}
{"channel":"book","type":"update","data":[{"symbol":"ETH/EUR","bids":[],"asks":[{"price":3505.57,"qty":26.30066174}],"checksum":87522300,"timestamp":"2024-06-01T18:06:08.874462Z"}]}
{"channel":"book","type":"update","data":[{"symbol":"ETH/EUR","bids":[],"asks":[{"price":3505.65,"qty":26.30005983}],"checksum":3410454590,"timestamp":"2024-06-01T18:06:08.879488Z"}]}
{"channel":"book","type":"update","data":[{"symbol":"ETH/EUR","bids":[],"asks":[{"price":3505.57,"qty":0.00000000},{"price":3506.16,"qty":26.29629268}],"checksum":3073269658,"timestamp":"2024-06-01T18:06:08.909447Z"}]}
{"channel":"book","type":"update","data":[{"symbol":"ETH/EUR","bids":[],"asks":[{"price":3505.65,"qty":0.00000000},{"price":3506.34,"qty":3.94500000}],"checksum":2787760421,"timestamp":"2024-06-01T18:06:08.913938Z"}]}
{"channel":"book","type":"update","data":[{"symbol":"ETH/EUR","bids":[{"price":3505.28,"qty":26.30279964}],"asks":[],"checksum":1731306790,"timestamp":"2024-06-01T18:06:09.010923Z"}]}
{"channel":"book","type":"update","data":[{"symbol":"ETH/EUR","bids":[],"asks":[{"price":3505.68,"qty":26.29983476}],"checksum":3102682603,"timestamp":"2024-06-01T18:06:09.011023Z"}]}
{"channel":"book","type":"update","data":[{"symbol":"ETH/EUR","bids":[],"asks":[{"price":3505.68,"qty":0.00000000},{"price":3506.34,"qty":3.94500000}],"checksum":1731306790,"timestamp":"2024-06-01T18:06:09.015615Z"}]}
{"channel":"book","type":"update","data":[{"symbol":"ETH/EUR","bids":[{"price":3505.28,"qty":0.00000000},{"price":3505.00,"qty":0.00220000}],"asks":[],"checksum":2787760421,"timestamp":"2024-06-01T18:06:09.037849Z"}]}
{"channel":"book","type":"update","data":[{"symbol":"ETH/EUR","bids":[],"asks":[{"price":3505.59,"qty":26.30056440}],"checksum":506585090,"timestamp":"2024-06-01T18:06:09.149926Z"}]}
{"channel":"book","type":"update","data":[{"symbol":"ETH/EUR","bids":[{"price":3505.32,"qty":26.93614133}],"asks":[],"checksum":761187981,"timestamp":"2024-06-01T18:06:09.150104Z"}]}
{"channel":"book","type":"update","data":[{"symbol":"ETH/EUR","bids":[{"price":3505.51,"qty":3.15000000}],"asks":[],"checksum":656685725,"timestamp":"2024-06-01T18:06:09.168929Z"}]}
{"channel":"book","type":"update","data":[{"symbol":"ETH/EUR","bids":[],"asks":[{"price":3505.59,"qty":0.00000000},{"price":3506.34,"qty":3.94500000}],"checksum":3889146074,"timestamp":"2024-06-01T18:06:09.233369Z"}]}
{"channel":"book","type":"update","data":[{"symbol":"ETH/EUR","bids":[],"asks":[{"price":3505.58,"qty":26.30063012}],"checksum":3150002149,"timestamp":"2024-06-01T18:06:09.237843Z"}]}
{"channel":"book","type":"update","data":[{"symbol":"ETH/EUR","bids":[],"asks":[{"price":3505.69,"qty":0.00000000},{"price":3506.34,"qty":3.94500000},{"price":3505.58,"qty":26.31640755}],"checksum":2619710462,"timestamp":"2024-06-01T18:06:09.268183Z"}]}
{"channel":"book","type":"update","data":[{"symbol":"ETH/EUR","bids":[],"asks":[{"price":3505.58,"qty":26.30063012},{"price":3505.85,"qty":0.01577769}],"checksum":841248730,"timestamp":"2024-06-01T18:06:09.331747Z"}]}
{"channel":"book","type":"update","data":[{"symbol":"ETH/EUR","bids":[],"asks":[{"price":3505.70,"qty":0.00000000},{"price":3506.34,"qty":3.94500000}],"checksum":3039433292,"timestamp":"2024-06-01T18:06:09.365608Z"}]}
{"channel":"book","type":"update","data":[{"symbol":"ETH/EUR","bids":[],"asks":[{"price":3505.86,"qty":0.00000000},{"price":3506.38,"qty":0.15840741}],"checksum":3081152746,"timestamp":"2024-06-01T18:06:09.365914Z"}]}
{"channel":"book","type":"update","data":[{"symbol":"ETH/EUR","bids":[],"asks":[{"price":3505.86,"qty":54.25322898}],"checksum":848521272,"timestamp":"2024-06-01T18:06:09.370789Z"}]}
{"channel":"book","type":"update","data":[{"symbol":"ETH/EUR","bids":[],"asks":[{"price":3506.15,"qty":8.37733577}],"checksum":1972503923,"timestamp":"2024-06-01T18:06:09.370857Z"}]}
{"channel":"book","type":"update","data":[{"symbol":"ETH/EUR","bids":[{"price":3505.32,"qty":0.63360987}],"asks":[],"checksum":1837498445,"timestamp":"2024-06-01T18:06:09.415560Z"}]}
{"channel":"book","type":"update","data":[{"symbol":"ETH/EUR","bids":[],"asks":[{"price":3505.68,"qty":26.29983476}],"checksum":3929107036,"timestamp":"2024-06-01T18:06:09.419398Z"}]}
{"channel":"book","type":"update","data":[{"symbol":"ETH/EUR","bids":[],"asks":[{"price":3505.87,"qty":0.00000000},{"price":3506.34,"qty":3.94500000}],"checksum":831960368,"timestamp":"2024-06-01T18:06:09.549863Z"}]}
{"channel":"book","type":"update","data":[{"symbol":"ETH/EUR","bids":[],"asks":[{"price":3506.01,"qty":0.00000000},{"price":3506.38,"qty":0.15840741}],"checksum":1226292020,"timestamp":"2024-06-01T18:06:09.551710Z"}]}
{"channel":"book","type":"update","data":[{"symbol":"ETH/EUR","bids":[],"asks":[{"price":3505.58,"qty":0.00000000},{"price":3506.39,"qty":3.01305282}],"checksum":568660050,"timestamp":"2024-06-01T18:06:09.559260Z"}]}
{"channel":"book","type":"update","data":[{"symbol":"ETH/EUR","bids":[{"price":3505.25,"qty":0.00000000},{"price":3505.00,"qty":0.00220000}],"asks":[],"checksum":1387501440,"timestamp":"2024-06-01T18:06:09.559405Z"}]}
{"channel":"book","type":"update","data":[{"symbol":"ETH/EUR","bids":[],"asks":[{"price":3505.68,"qty":0.00000000},{"price":3506.54,"qty":0.60552358}],"checksum":2150764268,"timestamp":"2024-06-01T18:06:09.561777Z"}]}
{"channel":"book","type":"update","data":[{"symbol":"ETH/EUR","bids":[],"asks":[{"price":3505.86,"qty":55.85322898}],"checksum":2836799638,"timestamp":"2024-06-01T18:06:09.565714Z"}]}
{"channel":"book","type":"update","data":[{"symbol":"ETH/EUR","bids":[],"asks":[{"price":3506.00,"qty":26.29746739}],"checksum":197073094,"timestamp":"2024-06-01T18:06:09.567323Z"}]}
{"channel":"book","type":"update","data":[{"symbol":"ETH/EUR","bids":[],"asks":[{"price":3505.75,"qty":26.29935702}],"checksum":2581541444,"timestamp":"2024-06-01T18:06:09.567420Z"}]}
{"channel":"book","type":"update","data":[{"symbol":"ETH/EUR","bids":[],"asks":[{"price":3505.75,"qty":0.00000000},{"price":3506.39,"qty":3.01305282}],"checksum":197073094,"timestamp":"2024-06-01T18:06:09.572442Z"}]}
{"channel":"book","type":"update","data":[{"symbol":"ETH/EUR","bids":[],"asks":[{"price":3505.77,"qty":26.29915959}],"checksum":1731179630,"timestamp":"2024-06-01T18:06:09.575957Z"}]}
{"channel":"book","type":"update","data":[{"symbol":"ETH/EUR","bids":[],"asks":[{"price":3506.34,"qty":0.00000000},{"price":3506.39,"qty":3.01305282}],"checksum":3705349293,"timestamp":"2024-06-01T18:06:09.610577Z"}]}
{"channel":"book","type":"update","data":[{"symbol":"ETH/EUR","bids":[],"asks":[{"price":3506.39,"qty":0.00000000},{"price":3506.54,"qty":0.60552358}],"checksum":4283486476,"timestamp":"2024-06-01T18:06:09.630369Z"}]}
{"channel":"book","type":"update","data":[{"symbol":"ETH/EUR","bids":[],"asks":[{"price":3506.47,"qty":3.94500000}],"checksum":2730249187,"timestamp":"2024-06-01T18:06:09.636205Z"}]}
{"channel":"book","type":"update","data":[{"symbol":"ETH/EUR","bids":[],"asks":[{"price":3506.28,"qty":1.05800000}],"checksum":2362109045,"timestamp":"2024-06-01T18:06:09.648481Z"}]}
{"channel":"book","type":"update","data":[{"symbol":"ETH/EUR","bids":[{"price":3505.51,"qty":0.00000000},{"price":3504.80,"qty":1.60220000}],"asks":[],"checksum":2004278869,"timestamp":"2024-06-01T18:06:09.696863Z"}]}
{"channel":"book","type":"update","data":[{"symbol":"ETH/EUR","bids":[],"asks":[{"price":3506.29,"qty":0.72912968}],"checksum":1152785276,"timestamp":"2024-06-01T18:06:09.701196Z"}]}
{"channel":"book","type":"update","data":[{"symbol":"ETH/EUR","bids":[],"asks":[{"price":3505.77,"qty":0.00000000},{"price":3506.38,"qty":0.15840741}],"checksum":330998290,"timestamp":"2024-06-01T18:06:09.719204Z"}]}
{"channel":"book","type":"update","data":[{"symbol":"ETH/EUR","bids":[],"asks":[{"price":3505.76,"qty":26.29925472}],"checksum":3986846748,"timestamp":"2024-06-01T18:06:09.723367Z"}]}
{"channel":"book","type":"update","data":[{"symbol":"ETH/EUR","bids":[],"asks":[{"price":3505.88,"qty":0.00000000},{"price":3506.38,"qty":0.15840741}],"checksum":1893759089,"timestamp":"2024-06-01T18:06:09.771193Z"}]}
{"channel":"book","type":"update","data":[{"symbol":"ETH/EUR","bids":[],"asks":[{"price":3505.75,"qty":26.29934935}],"checksum":3277665435,"timestamp":"2024-06-01T18:06:09.775186Z"}]}
{"channel":"book","type":"update","data":[{"symbol":"ETH/EUR","bids":[],"asks":[{"price":3505.75,"qty":0.00000000},{"price":3506.38,"qty":0.15840741}],"checksum":1893759089,"timestamp":"2024-06-01T18:06:10.091157Z"}]}
{"channel":"book","type":"update","data":[{"symbol":"ETH/EUR","bids":[],"asks":[{"price":3505.68,"qty":26.29986199}],"checksum":1497573641,"timestamp":"2024-06-01T18:06:10.101081Z"}]}
{"channel":"book","type":"update","data":[{"symbol":"ETH/EUR","bids":[],"asks":[{"price":3505.76,"qty":0.00000000},{"price":3506.38,"qty":0.15840741}],"checksum":1473177264,"timestamp":"2024-06-01T18:06:10.101097Z"}]}
{"channel":"book","type":"update","data":[{"symbol":"ETH/EUR","bids":[],"asks":[{"price":3505.68,"qty":0.00000000},{"price":3506.47,"qty":3.94500000}],"checksum":3389041916,"timestamp":"2024-06-01T18:06:10.105492Z"}]}
{"channel":"book","type":"update","data":[{"symbol":"ETH/EUR","bids":[],"asks":[{"price":3505.75,"qty":26.29930963}],"checksum":2582213135,"timestamp":"2024-06-01T18:06:10.108721Z"}]}
{"channel":"book","type":"update","data":[{"symbol":"ETH/EUR","bids":[],"asks":[{"price":3506.00,"qty":0.00000000},{"price":3506.47,"qty":3.94500000}],"checksum":1111696681,"timestamp":"2024-06-01T18:06:10.114063Z"}]}
{"channel":"book","type":"update","data":[{"symbol":"ETH/EUR","bids":[],"asks":[{"price":3505.75,"qty":0.00000000},{"price":3506.54,"qty":0.60552358}],"checksum":2542077783,"timestamp":"2024-06-01T18:06:10.114092Z"}]}
{"channel":"book","type":"update","data":[{"symbol":"ETH/EUR","bids":[],"asks":[{"price":3505.89,"qty":26.29832439}],"checksum":4187370062,"timestamp":"2024-06-01T18:06:10.118279Z"}]}
{"channel":"book","type":"update","data":[{"symbol":"ETH/EUR","bids":[],"asks":[{"price":3505.85,"qty":0.00000000},{"price":3506.54,"qty":0.60552358},{"price":3505.77,"qty":0.01577767}],"checksum":217366402,"timestamp":"2024-06-01T18:06:10.168645Z"}]}
{"channel":"book","type":"update","data":[{"symbol":"ETH/EUR","bids":[],"asks":[{"price":3505.76,"qty":26.29923461}],"checksum":1574904831,"timestamp":"2024-06-01T18:06:10.175619Z"}]}
{"channel":"book","type":"update","data":[{"symbol":"ETH/EUR","bids":[],"asks":[{"price":3505.76,"qty":0.00000000},{"price":3506.47,"qty":3.94500000}],"checksum":217366402,"timestamp":"2024-06-01T18:06:10.179726Z"}]}
{"channel":"book","type":"update","data":[{"symbol":"ETH/EUR","bids":[],"asks":[{"price":3505.64,"qty":26.30018410}],"checksum":2691217037,"timestamp":"2024-06-01T18:06:10.224541Z"}]}
{"channel":"book","type":"update","data":[{"symbol":"ETH/EUR","bids":[],"asks":[{"price":3505.77,"qty":0.00000000},{"price":3506.47,"qty":3.94500000},{"price":3505.85,"qty":0.01577767}],"checksum":3919198905,"timestamp":"2024-06-01T18:06:10.296836Z"}]}
{"channel":"book","type":"update","data":[{"symbol":"ETH/EUR","bids":[],"asks":[{"price":3505.64,"qty":0.00000000},{"price":3506.47,"qty":3.94500000}],"checksum":882992198,"timestamp":"2024-06-01T18:06:10.427165Z"}]}
{"channel":"book","type":"update","data":[{"symbol":"ETH/EUR","bids":[],"asks":[{"price":3505.67,"qty":26.29993960}],"checksum":3065001022,"timestamp":"2024-06-01T18:06:10.432652Z"}]}
{"channel":"book","type":"update","data":[{"symbol":"ETH/EUR","bids":[{"price":3505.38,"qty":26.30204161}],"asks":[],"checksum":2663905201,"timestamp":"2024-06-01T18:06:10.432685Z"}]}
{"channel":"book","type":"update","data":[{"symbol":"ETH/EUR","bids":[],"asks":[{"price":3505.74,"qty":26.29938465}],"checksum":416001390,"timestamp":"2024-06-01T18:06:10.432900Z"}]}
{"channel":"book","type":"update","data":[{"symbol":"ETH/EUR","bids":[{"price":3505.38,"qty":0.00000000},{"price":3504.80,"qty":1.60220000}],"asks":[],"checksum":1765294062,"timestamp":"2024-06-01T18:06:10.457489Z"}]}
{"channel":"book","type":"update","data":[{"symbol":"ETH/EUR","bids":[],"asks":[{"price":3505.67,"qty":0.00000000},{"price":3506.38,"qty":0.15840741}],"checksum":512041103,"timestamp":"2024-06-01T18:06:10.498031Z"}]}
{"channel":"book","type":"update","data":[{"symbol":"ETH/EUR","bids":[{"price":3505.43,"qty":26.30168580}],"asks":[],"checksum":223420930,"timestamp":"2024-06-01T18:06:10.502546Z"}]}
{"channel":"book","type":"update","data":[{"symbol":"ETH/EUR","bids":[],"asks":[{"price":3505.71,"qty":26.29961583}],"checksum":4095505238,"timestamp":"2024-06-01T18:06:10.502645Z"}]}
{"channel":"book","type":"update","data":[{"symbol":"ETH/EUR","bids":[],"asks":[{"price":3505.71,"qty":0.00000000},{"price":3506.38,"qty":0.15840741}],"checksum":223420930,"timestamp":"2024-06-01T18:06:10.567598Z"}]}
{"channel":"book","type":"update","data":[{"symbol":"ETH/EUR","bids":[{"price":3505.43,"qty":0.00000000},{"price":3504.80,"qty":1.60220000}],"asks":[],"checksum":512041103,"timestamp":"2024-06-01T18:06:10.567768Z"}]}
{"channel":"book","type":"update","data":[{"symbol":"ETH/EUR","bids":[],"asks":[{"price":3505.70,"qty":26.29974728}],"checksum":3613991912,"timestamp":"2024-06-01T18:06:10.573028Z"}]}
{"channel":"book","type":"update","data":[{"symbol":"ETH/EUR","bids":[{"price":3505.41,"qty":26.30181725}],"asks":[],"checksum":4232497972,"timestamp":"2024-06-01T18:06:10.573045Z"}]}
{"channel":"book","type":"update","data":[{"symbol":"ETH/EUR","bids":[],"asks":[{"price":3505.70,"qty":0.00000000},{"price":3506.38,"qty":0.15840741}],"checksum":794416076,"timestamp":"2024-06-01T18:06:10.578662Z"}]}
{"channel":"book","type":"update","data":[{"symbol":"ETH/EUR","bids":[],"asks":[{"price":3505.68,"qty":26.29990502}],"checksum":2128687926,"timestamp":"2024-06-01T18:06:10.759436Z"}]}
{"channel":"book","type":"update","data":[{"symbol":"ETH/EUR","bids":[{"price":3505.40,"qty":26.30412856}],"asks":[],"checksum":4125191464,"timestamp":"2024-06-01T18:06:10.759452Z"}]}
{"channel":"book","type":"update","data":[{"symbol":"ETH/EUR","bids":[],"asks":[{"price":3506.15,"qty":8.33632050}],"checksum":3446761150,"timestamp":"2024-06-01T18:06:10.983115Z"}]}
{"channel":"book","type":"update","data":[{"symbol":"ETH/EUR","bids":[],"asks":[{"price":3505.85,"qty":0.00000000},{"price":3506.47,"qty":3.94500000},{"price":3505.67,"qty":0.01577767}],"checksum":1422347213,"timestamp":"2024-06-01T18:06:11.084492Z"}]}
{"channel":"book","type":"update","data":[{"symbol":"ETH/EUR","bids":[{"price":3505.33,"qty":0.00000000},{"price":3504.80,"qty":1.60220000},{"price":3505.42,"qty":0.03535429}],"asks":[],"checksum":3638951451,"timestamp":"2024-06-01T18:06:11.084524Z"}]}
{"channel":"book","type":"update","data":[{"symbol":"ETH/EUR","bids":[],"asks":[{"price":3505.68,"qty":0.00000000},{"price":3506.47,"qty":3.94500000}],"checksum":3508074497,"timestamp":"2024-06-01T18:06:11.204857Z"}]}
{"channel":"book","type":"update","data":[{"symbol":"ETH/EUR","bids":[],"asks":[{"price":3505.70,"qty":26.29972220}],"checksum":964475084,"timestamp":"2024-06-01T18:06:11.208663Z"}]}
{"channel":"book","type":"update","data":[{"symbol":"ETH/EUR","bids":[],"asks":[{"price":3505.67,"qty":0.00000000},{"price":3506.47,"qty":3.94500000},{"price":3505.73,"qty":0.01577855}],"checksum":3009002055,"timestamp":"2024-06-01T18:06:11.250980Z"}]}
{"channel":"book","type":"update","data":[{"symbol":"ETH/EUR","bids":[],"asks":[{"price":3505.70,"qty":0.00000000},{"price":3506.47,"qty":3.94500000}],"checksum":3060470917,"timestamp":"2024-06-01T18:06:11.260262Z"}]}
{"channel":"book","type":"update","data":[{"symbol":"ETH/EUR","bids":[{"price":3505.40,"qty":0.00220000}],"asks":[],"checksum":1543418675,"timestamp":"2024-06-01T18:06:11.260396Z"}]}
{"channel":"book","type":"update","data":[{"symbol":"ETH/EUR","bids":[],"asks":[{"price":3505.74,"qty":0.00000000},{"price":3506.54,"qty":0.60552358}],"checksum":2239762966,"timestamp":"2024-06-01T18:06:11.260450Z"}]}
{"channel":"book","type":"update","data":[{"symbol":"ETH/EUR","bids":[{"price":3505.49,"qty":26.30119261}],"asks":[],"checksum":36336053,"timestamp":"2024-06-01T18:06:11.266118Z"}]}
{"channel":"book","type":"update","data":[{"symbol":"ETH/EUR","bids":[],"asks":[{"price":3505.78,"qty":26.38465345}],"checksum":653595238,"timestamp":"2024-06-01T18:06:11.266206Z"}]}
{"channel":"book","type":"update","data":[{"symbol":"ETH/EUR","bids":[],"asks":[{"price":3506.03,"qty":26.29727770}],"checksum":188854653,"timestamp":"2024-06-01T18:06:11.266218Z"}]}
{"channel":"book","type":"update","data":[{"symbol":"ETH/EUR","bids":[],"asks":[{"price":3505.78,"qty":0.08552800}],"checksum":1978610588,"timestamp":"2024-06-01T18:06:11.282299Z"}]}
{"channel":"book","type":"update","data":[{"symbol":"ETH/EUR","bids":[],"asks":[{"price":3505.89,"qty":0.00000000},{"price":3506.54,"qty":0.60552358}],"checksum":3318777935,"timestamp":"2024-06-01T18:06:11.313660Z"}]}
{"channel":"book","type":"update","data":[{"symbol":"ETH/EUR","bids":[{"price":3505.49,"qty":0.00000000},{"price":3505.00,"qty":0.00220000}],"asks":[],"checksum":1470541903,"timestamp":"2024-06-01T18:06:11.313836Z"}]}
{"channel":"book","type":"update","data":[{"symbol":"ETH/EUR","bids":[],"asks":[{"price":3505.73,"qty":26.31525889}],"checksum":1930188937,"timestamp":"2024-06-01T18:06:11.318000Z"}]}
{"channel":"book","type":"update","data":[{"symbol":"ETH/EUR","bids":[{"price":3505.45,"qty":26.30154754}],"asks":[],"checksum":1800151993,"timestamp":"2024-06-01T18:06:11.318264Z"}]}
{"channel":"book","type":"update","data":[{"symbol":"ETH/EUR","bids":[],"asks":[{"price":3505.73,"qty":26.29948034},{"price":3505.77,"qty":0.01577855}],"checksum":1859511911,"timestamp":"2024-06-01T18:06:11.338982Z"}]}
{"channel":"book","type":"update","data":[{"symbol":"ETH/EUR","bids":[{"price":3505.45,"qty":0.00000000},{"price":3505.00,"qty":0.00220000}],"asks":[],"checksum":2920411476,"timestamp":"2024-06-01T18:06:11.340798Z"}]}
{"channel":"book","type":"update","data":[{"symbol":"ETH/EUR","bids":[],"asks":[{"price":3505.73,"qty":0.00000000},{"price":3506.54,"qty":0.60552358}],"checksum":304900989,"timestamp":"2024-06-01T18:06:11.475209Z"}]}
{"channel":"book","type":"update","data":[{"symbol":"ETH/EUR","bids":[],"asks":[{"price":3505.75,"qty":26.29933839}],"checksum":1430397651,"timestamp":"2024-06-01T18:06:11.479491Z"}]}
{"channel":"book","type":"update","data":[{"symbol":"ETH/EUR","bids":[{"price":3505.46,"qty":26.30143974}],"asks":[],"checksum":4101231859,"timestamp":"2024-06-01T18:06:11.479533Z"}]}
{"channel":"book","type":"update","data":[{"symbol":"ETH/EUR","bids":[{"price":3505.51,"qty":5.90000000}],"asks":[],"checksum":3721169364,"timestamp":"2024-06-01T18:06:11.486386Z"}]}
{"channel":"book","type":"update","data":[{"symbol":"ETH/EUR","bids":[{"price":3505.52,"qty":1.53500000}],"asks":[],"checksum":3534983125,"timestamp":"2024-06-01T18:06:11.660410Z"}]}
{"channel":"book","type":"update","data":[{"symbol":"ETH/EUR","bids":[{"price":3505.46,"qty":0.00000000},{"price":3505.08,"qty":26.30429617}],"asks":[],"checksum":809975235,"timestamp":"2024-06-01T18:06:11.726374Z"}]}
{"channel":"book","type":"update","data":[{"symbol":"ETH/EUR","bids":[],"asks":[{"price":3505.77,"qty":26.31496446}],"checksum":3912604884,"timestamp":"2024-06-01T18:06:11.730600Z"}]}
{"channel":"book","type":"update","data":[{"symbol":"ETH/EUR","bids":[{"price":3505.49,"qty":26.30122495}],"asks":[],"checksum":2732602906,"timestamp":"2024-06-01T18:06:11.730752Z"}]}
{"channel":"book","type":"update","data":[{"symbol":"ETH/EUR","bids":[],"asks":[{"price":3505.86,"qty":54.25322898}],"checksum":875739221,"timestamp":"2024-06-01T18:06:11.742305Z"}]}
{"channel":"book","type":"update","data":[{"symbol":"ETH/EUR","bids":[{"price":3505.49,"qty":0.00000000},{"price":3505.08,"qty":26.30429617}],"asks":[],"checksum":2145850011,"timestamp":"2024-06-01T18:06:11.766625Z"}]}
{"channel":"book","type":"update","data":[{"symbol":"ETH/EUR","bids":[],"asks":[{"price":3505.75,"qty":0.00000000},{"price":3506.54,"qty":0.60552358}],"checksum":1485391446,"timestamp":"2024-06-01T18:06:11.770025Z"}]}
{"channel":"book","type":"update","data":[{"symbol":"ETH/EUR","bids":[{"price":3505.41,"qty":0.00000000},{"price":3505.07,"qty":0.08553700}],"asks":[],"checksum":1507585308,"timestamp":"2024-06-01T18:06:11.770092Z"}]}
{"channel":"book","type":"update","data":[{"symbol":"ETH/EUR","bids":[],"asks":[{"price":3505.77,"qty":0.01577855}],"checksum":746436373,"timestamp":"2024-06-01T18:06:11.770190Z"}]}
{"channel":"book","type":"update","data":[{"symbol":"ETH/EUR","bids":[],"asks":[{"price":3506.47,"qty":0.00000000},{"price":3506.57,"qty":10.00000000}],"checksum":3836474375,"timestamp":"2024-06-01T18:06:11.772261Z"}]}
{"channel":"book","type":"update","data":[{"symbol":"ETH/EUR","bids":[],"asks":[{"price":3505.89,"qty":26.29833151}],"checksum":3310718629,"timestamp":"2024-06-01T18:06:11.776527Z"}]}
{"channel":"book","type":"update","data":[{"symbol":"ETH/EUR","bids":[{"price":3505.54,"qty":26.30087546}],"asks":[],"checksum":4030250903,"timestamp":"2024-06-01T18:06:11.782980Z"}]}
{"channel":"book","type":"update","data":[{"symbol":"ETH/EUR","bids":[],"asks":[{"price":3505.81,"qty":26.29886302}],"checksum":2462624778,"timestamp":"2024-06-01T18:06:11.783029Z"}]}
{"channel":"book","type":"update","data":[{"symbol":"ETH/EUR","bids":[],"asks":[{"price":3505.81,"qty":0.00000000},{"price":3506.54,"qty":0.60552358}],"checksum":4030250903,"timestamp":"2024-06-01T18:06:11.796622Z"}]}
{"channel":"book","type":"update","data":[{"symbol":"ETH/EUR","bids":[],"asks":[{"price":3506.03,"qty":0.00000000},{"price":3506.57,"qty":10.00000000}],"checksum":4034114285,"timestamp":"2024-06-01T18:06:11.796709Z"}]}
{"channel":"book","type":"update","data":[{"symbol":"ETH/EUR","bids":[],"asks":[{"price":3506.39,"qty":26.29458026}],"checksum":4160697632,"timestamp":"2024-06-01T18:06:11.801219Z"}]}
{"channel":"book","type":"update","data":[{"symbol":"ETH/EUR","bids":[{"price":3505.54,"qty":0.00000000},{"price":3505.07,"qty":0.08553700}],"asks":[],"checksum":589534153,"timestamp":"2024-06-01T18:06:11.813944Z"}]}
{"channel":"book","type":"update","data":[{"symbol":"ETH/EUR","bids":[],"asks":[{"price":3505.86,"qty":0.00000000},{"price":3506.57,"qty":10.00000000}],"checksum":2616586937,"timestamp":"2024-06-01T18:06:11.817512Z"}]}
{"channel":"book","type":"update","data":[{"symbol":"ETH/EUR","bids":[],"asks":[{"price":3506.15,"qty":0.00000000},{"price":3506.59,"qty":3.94500000}],"checksum":3975752952,"timestamp":"2024-06-01T18:06:11.817555Z"}]}
{"channel":"book","type":"update","data":[{"symbol":"ETH/EUR","bids":[],"asks":[{"price":3506.15,"qty":38.85944266}],"checksum":2669109085,"timestamp":"2024-06-01T18:06:11.822592Z"}]}
{"channel":"book","type":"update","data":[{"symbol":"ETH/EUR","bids":[],"asks":[{"price":3505.72,"qty":11.37494554}],"checksum":3902652764,"timestamp":"2024-06-01T18:06:11.822604Z"}]}
{"channel":"book","type":"update","data":[{"symbol":"ETH/EUR","bids":[],"asks":[{"price":3505.88,"qty":26.29835829}],"checksum":1315730064,"timestamp":"2024-06-01T18:06:11.837797Z"}]}
{"channel":"book","type":"update","data":[{"symbol":"ETH/EUR","bids":[{"price":3505.60,"qty":26.30037070}],"asks":[],"checksum":3418611320,"timestamp":"2024-06-01T18:06:11.837911Z"}]}
{"channel":"book","type":"update","data":[{"symbol":"ETH/EUR","bids":[{"price":3505.60,"qty":0.00000000},{"price":3505.07,"qty":0.08553700}],"asks":[],"checksum":1315730064,"timestamp":"2024-06-01T18:06:11.846359Z"}]}
{"channel":"book","type":"update","data":[{"symbol":"ETH/EUR","bids":[],"asks":[{"price":3505.88,"qty":0.00000000},{"price":3506.54,"qty":0.60552358}],"checksum":3902652764,"timestamp":"2024-06-01T18:06:11.858381Z"}]}
{"channel":"book","type":"update","data":[{"symbol":"ETH/EUR","bids":[{"price":3505.53,"qty":26.30096012}],"asks":[],"checksum":3312538375,"timestamp":"2024-06-01T18:06:11.862825Z"}]}
{"channel":"book","type":"update","data":[{"symbol":"ETH/EUR","bids":[{"price":3505.53,"qty":0.00000000},{"price":3505.07,"qty":0.08553700}],"asks":[],"checksum":3902652764,"timestamp":"2024-06-01T18:06:11.880383Z"}]}
{"channel":"book","type":"update","data":[{"symbol":"ETH/EUR","bids":[{"price":3505.62,"qty":26.30022102}],"asks":[],"checksum":2095177578,"timestamp":"2024-06-01T18:06:11.889193Z"}]}
{"channel":"book","type":"update","data":[{"symbol":"ETH/EUR","bids":[],"asks":[{"price":3505.91,"qty":26.29814074}],"checksum":2062916581,"timestamp":"2024-06-01T18:06:11.889329Z"}]}
{"channel":"book","type":"update","data":[{"symbol":"ETH/EUR","bids":[{"price":3505.62,"qty":0.00000000},{"price":3505.07,"qty":0.08553700}],"asks":[],"checksum":158742,"timestamp":"2024-06-01T18:06:11.897799Z"}]}
{"channel":"book","type":"update","data":[{"symbol":"ETH/EUR","bids":[],"asks":[{"price":3505.89,"qty":0.00000000},{"price":3506.54,"qty":0.60552358}],"checksum":3721002052,"timestamp":"2024-06-01T18:06:11.915993Z"}]}
{"channel":"book","type":"update","data":[{"symbol":"ETH/EUR","bids":[{"price":3505.40,"qty":1.60220000}],"asks":[],"checksum":2324355468,"timestamp":"2024-06-01T18:06:11.940477Z"}]}
{"channel":"book","type":"update","data":[{"symbol":"ETH/EUR","bids":[],"asks":[{"price":3505.78,"qty":0.00000000},{"price":3506.57,"qty":10.00000000},{"price":3506.43,"qty":0.08552000}],"checksum":4128628367,"timestamp":"2024-06-01T18:06:11.955013Z"}]}
{"channel":"book","type":"update","data":[{"symbol":"ETH/EUR","bids":[{"price":3505.51,"qty":0.00000000},{"price":3505.00,"qty":0.00220000}],"asks":[],"checksum":3685830555,"timestamp":"2024-06-01T18:06:11.968685Z"}]}
{"channel":"book","type":"update","data":[{"symbol":"ETH/EUR","bids":[],"asks":[{"price":3506.28,"qty":0.00000000},{"price":3506.57,"qty":10.00000000}],"checksum":1190911275,"timestamp":"2024-06-01T18:06:11.976833Z"}]}
{"channel":"book","type":"update","data":[{"symbol":"ETH/EUR","bids":[],"asks":[{"price":3506.54,"qty":0.00000000},{"price":3506.59,"qty":3.94500000}],"checksum":533649198,"timestamp":"2024-06-01T18:06:11.987028Z"}]}
{"channel":"book","type":"update","data":[{"symbol":"ETH/EUR","bids":[],"asks":[{"price":3505.93,"qty":26.29796500}],"checksum":3974251775,"timestamp":"2024-06-01T18:06:11.988362Z"}]}
{"channel":"book","type":"update","data":[{"symbol":"ETH/EUR","bids":[{"price":3505.53,"qty":26.30096012}],"asks":[],"checksum":1028550394,"timestamp":"2024-06-01T18:06:11.988375Z"}]}
{"channel":"book","type":"update","data":[{"symbol":"ETH/EUR","bids":[],"asks":[{"price":3505.91,"qty":0.00000000},{"price":3506.59,"qty":3.94500000}],"checksum":3174292228,"timestamp":"2024-06-01T18:06:11.988399Z"}]}
{"channel":"book","type":"update","data":[{"symbol":"ETH/EUR","bids":[{"price":3505.08,"qty":0.00000000},{"price":3505.00,"qty":0.00220000}],"asks":[],"checksum":4162381307,"timestamp":"2024-06-01T18:06:11.989609Z"}]}
{"channel":"book","type":"update","data":[{"symbol":"ETH/EUR","bids":[],"asks":[{"price":3505.93,"qty":0.00000000},{"price":3506.75,"qty":0.84644082}],"checksum":2604582658,"timestamp":"2024-06-01T18:06:11.999038Z"}]}
{"channel":"book","type":"update","data":[{"symbol":"ETH/EUR","bids":[],"asks":[{"price":3506.16,"qty":0.00000000},{"price":3506.99,"qty":3.01305282}],"checksum":968744010,"timestamp":"2024-06-01T18:06:11.999091Z"}]}
{"channel":"book","type":"update","data":[{"symbol":"ETH/EUR","bids":[{"price":3505.53,"qty":0.00000000},{"price":3504.80,"qty":0.00220000}],"asks":[],"checksum":728422869,"timestamp":"2024-06-01T18:06:12.013963Z"}]}
{"channel":"book","type":"update","data":[{"symbol":"ETH/EUR","bids":[{"price":3505.42,"qty":0.00000000},{"price":3504.69,"qty":1.35563703},{"price":3505.53,"qty":0.03535457}],"asks":[],"checksum":744370598,"timestamp":"2024-06-01T18:06:12.033902Z"}]}
{"channel":"book","type":"update","data":[{"symbol":"ETH/EUR","bids":[],"asks":[{"price":3505.77,"qty":0.00000000},{"price":3507.10,"qty":6.00000000},{"price":3505.71,"qty":0.01577855}],"checksum":3952721207,"timestamp":"2024-06-01T18:06:12.034074Z"}]}
{"channel":"book","type":"update","data":[{"symbol":"ETH/EUR","bids":[{"price":3505.54,"qty":26.30088509}],"asks":[],"checksum":413405688,"timestamp":"2024-06-01T18:06:12.045426Z"}]}
{"channel":"book","type":"update","data":[{"symbol":"ETH/EUR","bids":[],"asks":[{"price":3506.09,"qty":26.29681307}],"checksum":3363063619,"timestamp":"2024-06-01T18:06:12.045582Z"}]}
{"channel":"book","type":"update","data":[{"symbol":"ETH/EUR","bids":[],"asks":[{"price":3506.09,"qty":0.00000000},{"price":3506.98,"qty":0.61651667}],"checksum":351988345,"timestamp":"2024-06-01T18:06:12.062606Z"}]}
{"channel":"book","type":"update","data":[{"symbol":"ETH/EUR","bids":[{"price":3505.40,"qty":0.00220000}],"asks":[],"checksum":1799940753,"timestamp":"2024-06-01T18:06:12.071906Z"}]}
{"channel":"book","type":"update","data":[{"symbol":"ETH/EUR","bids":[{"price":3505.70,"qty":26.29968472}],"asks":[],"checksum":1692260301,"timestamp":"2024-06-01T18:06:12.072036Z"}]}
{"channel":"book","type":"update","data":[{"symbol":"ETH/EUR","bids":[{"price":3505.55,"qty":1.60000000}],"asks":[],"checksum":3118853785,"timestamp":"2024-06-01T18:06:12.072149Z"}]}
{"channel":"book","type":"update","data":[{"symbol":"ETH/EUR","bids":[],"asks":[{"price":3506.06,"qty":26.29703126}],"checksum":2654178568,"timestamp":"2024-06-01T18:06:12.091667Z"}]}
{"channel":"book","type":"update","data":[{"symbol":"ETH/EUR","bids":[],"asks":[{"price":3505.71,"qty":0.00000000},{"price":3506.98,"qty":0.61651667},{"price":3506.14,"qty":0.01577854}],"checksum":999367478,"timestamp":"2024-06-01T18:06:12.114645Z"}]}
{"channel":"book","type":"update","data":[{"symbol":"ETH/EUR","bids":[],"asks":[{"price":3506.59,"qty":0.00000000},{"price":3506.98,"qty":0.61651667}],"checksum":1070552944,"timestamp":"2024-06-01T18:06:12.123155Z"}]}
{"channel":"book","type":"update","data":[{"symbol":"ETH/EUR","bids":[],"asks":[{"price":3506.70,"qty":1.05800000}],"checksum":2661578254,"timestamp":"2024-06-01T18:06:12.123724Z"}]}
{"channel":"book","type":"update","data":[{"symbol":"ETH/EUR","bids":[],"asks":[{"price":3506.06,"qty":0.00000000},{"price":3506.98,"qty":0.61651667}],"checksum":3091279287,"timestamp":"2024-06-01T18:06:12.160489Z"}]}
{"channel":"book","type":"update","data":[{"symbol":"ETH/EUR","bids":[],"asks":[{"price":3506.05,"qty":26.29712345}],"checksum":1023722525,"timestamp":"2024-06-01T18:06:12.164753Z"}]}
{"channel":"book","type":"update","data":[{"symbol":"ETH/EUR","bids":[{"price":3505.70,"qty":52.59936944}],"asks":[],"checksum":875239892,"timestamp":"2024-06-01T18:06:12.164818Z"}]}
{"channel":"book","type":"update","data":[{"symbol":"ETH/EUR","bids":[],"asks":[{"price":3506.05,"qty":0.00000000},{"price":3506.98,"qty":0.61651667}],"checksum":2976837758,"timestamp":"2024-06-01T18:06:12.179267Z"}]}
{"channel":"book","type":"update","data":[{"symbol":"ETH/EUR","bids":[],"asks":[{"price":3506.43,"qty":0.00000000},{"price":3506.99,"qty":3.01305282},{"price":3506.81,"qty":0.08551600}],"checksum":2134319102,"timestamp":"2024-06-01T18:06:12.222807Z"}]}
{"channel":"book","type":"update","data":[{"symbol":"ETH/EUR","bids":[],"asks":[{"price":3506.05,"qty":26.29712084}],"checksum":3450230464,"timestamp":"2024-06-01T18:06:12.225776Z"}]}
{"channel":"book","type":"update","data":[{"symbol":"ETH/EUR","bids":[],"asks":[{"price":3506.05,"qty":0.00000000},{"price":3506.98,"qty":0.61651667}],"checksum":2134319102,"timestamp":"2024-06-01T18:06:12.229656Z"}]}
{"channel":"book","type":"update","data":[{"symbol":"ETH/EUR","bids":[],"asks":[{"price":3506.70,"qty":0.00000000},{"price":3506.99,"qty":3.01305282}],"checksum":1345413120,"timestamp":"2024-06-01T18:06:12.261768Z"}]}
{"channel":"book","type":"update","data":[{"symbol":"ETH/EUR","bids":[],"asks":[{"price":3506.29,"qty":0.00000000},{"price":3507.10,"qty":6.00000000}],"checksum":3535763100,"timestamp":"2024-06-01T18:06:12.263708Z"}]}
{"channel":"book","type":"update","data":[{"symbol":"ETH/EUR","bids":[{"price":3505.54,"qty":0.00000000},{"price":3505.07,"qty":0.08553700}],"asks":[],"checksum":3541057755,"timestamp":"2024-06-01T18:06:12.270704Z"}]}
{"channel":"book","type":"update","data":[{"symbol":"ETH/EUR","bids":[],"asks":[{"price":3506.24,"qty":26.29564967}],"checksum":1616856909,"timestamp":"2024-06-01T18:06:12.270879Z"}]}
{"channel":"book","type":"update","data":[{"symbol":"ETH/EUR","bids":[],"asks":[{"price":3506.39,"qty":0.00000000},{"price":3507.10,"qty":6.00000000}],"checksum":3410800831,"timestamp":"2024-06-01T18:06:12.280648Z"}]}
{"channel":"book","type":"update","data":[{"symbol":"ETH/EUR","bids":[],"asks":[{"price":3506.49,"qty":26.29379479}],"checksum":1075955924,"timestamp":"2024-06-01T18:06:12.280789Z"}]}
{"channel":"book","type":"update","data":[{"symbol":"ETH/EUR","bids":[],"asks":[{"price":3506.18,"qty":26.29613598}],"checksum":3013466272,"timestamp":"2024-06-01T18:06:12.284410Z"}]}
{"channel":"book","type":"update","data":[{"symbol":"ETH/EUR","bids":[],"asks":[{"price":3505.72,"qty":0.00000000},{"price":3506.99,"qty":3.01305282}],"checksum":2584837051,"timestamp":"2024-06-01T18:06:12.284463Z"}]}
{"channel":"book","type":"update","data":[{"symbol":"ETH/EUR","bids":[{"price":3505.70,"qty":26.29968472}],"asks":[],"checksum":4219979001,"timestamp":"2024-06-01T18:06:12.288995Z"}]}
{"channel":"book","type":"update","data":[{"symbol":"ETH/EUR","bids":[{"price":3505.70,"qty":0.00000000},{"price":3505.00,"qty":0.00220000}],"asks":[],"checksum":1076343728,"timestamp":"2024-06-01T18:06:12.289050Z"}]}
{"channel":"book","type":"update","data":[{"symbol":"ETH/EUR","bids":[{"price":3505.81,"qty":26.29879731}],"asks":[],"checksum":471510364,"timestamp":"2024-06-01T18:06:12.294840Z"}]}
{"channel":"book","type":"update","data":[{"symbol":"ETH/EUR","bids":[{"price":3505.89,"qty":26.29825568}],"asks":[],"checksum":3108850086,"timestamp":"2024-06-01T18:06:12.294866Z"}]}
{"channel":"book","type":"update","data":[{"symbol":"ETH/EUR","bids":[{"price":3505.44,"qty":0.08553200}],"asks":[],"checksum":3362421052,"timestamp":"2024-06-01T18:06:12.300340Z"}]}
{"channel":"book","type":"update","data":[{"symbol":"ETH/EUR","bids":[{"price":3505.89,"qty":0.00000000},{"price":3505.20,"qty":0.00220000}],"asks":[],"checksum":60740710,"timestamp":"2024-06-01T18:06:12.303609Z"}]}
{"channel":"book","type":"update","data":[{"symbol":"ETH/EUR","bids":[{"price":3505.81,"qty":0.00000000},{"price":3505.00,"qty":0.00220000}],"asks":[],"checksum":2814453112,"timestamp":"2024-06-01T18:06:12.303628Z"}]}
{"channel":"book","type":"update","data":[{"symbol":"ETH/EUR","bids":[],"asks":[{"price":3506.18,"qty":0.00000000},{"price":3507.10,"qty":6.00000000}],"checksum":1627671266,"timestamp":"2024-06-01T18:06:12.303692Z"}]}
{"channel":"book","type":"update","data":[{"symbol":"ETH/EUR","bids":[],"asks":[{"price":3506.72,"qty":26.29207648}],"checksum":2883489860,"timestamp":"2024-06-01T18:06:12.309314Z"}]}
{"channel":"book","type":"update","data":[{"symbol":"ETH/EUR","bids":[],"asks":[{"price":3506.49,"qty":0.00000000},{"price":3507.10,"qty":6.00000000}],"checksum":3335879649,"timestamp":"2024-06-01T18:06:12.334469Z"}]}
{"channel":"book","type":"update","data":[{"symbol":"ETH/EUR","bids":[],"asks":[{"price":3506.24,"qty":0.00000000},{"price":3507.19,"qty":1.82966454}],"checksum":2969536494,"timestamp":"2024-06-01T18:06:12.334809Z"}]}
{"channel":"book","type":"update","data":[{"symbol":"ETH/EUR","bids":[],"asks":[{"price":3506.13,"qty":26.29645927}],"checksum":2744885004,"timestamp":"2024-06-01T18:06:12.339338Z"}]}
{"channel":"book","type":"update","data":[{"symbol":"ETH/EUR","bids":[{"price":3505.67,"qty":26.29986942}],"asks":[],"checksum":1175885210,"timestamp":"2024-06-01T18:06:12.339505Z"}]}
{"channel":"book","type":"update","data":[{"symbol":"ETH/EUR","bids":[{"price":3505.67,"qty":0.00000000},{"price":3505.00,"qty":0.00220000}],"asks":[],"checksum":2744885004,"timestamp":"2024-06-01T18:06:12.345573Z"}]}
{"channel":"book","type":"update","data":[{"symbol":"ETH/EUR","bids":[{"price":3505.84,"qty":26.29863287}],"asks":[],"checksum":811968485,"timestamp":"2024-06-01T18:06:12.349956Z"}]}
{"channel":"book","type":"update","data":[{"symbol":"ETH/EUR","bids":[],"asks":[{"price":3506.85,"qty":1.05800000}],"checksum":469517793,"timestamp":"2024-06-01T18:06:12.360443Z"}]}
{"channel":"book","type":"update","data":[{"symbol":"ETH/EUR","bids":[],"asks":[{"price":3506.13,"qty":0.00000000},{"price":3507.10,"qty":6.00000000}],"checksum":3690132536,"timestamp":"2024-06-01T18:06:12.374985Z"}]}
{"channel":"book","type":"update","data":[{"symbol":"ETH/EUR","bids":[{"price":3505.84,"qty":0.00000000},{"price":3505.00,"qty":0.00220000}],"asks":[],"checksum":2579167921,"timestamp":"2024-06-01T18:06:12.375101Z"}]}
{"channel":"book","type":"update","data":[{"symbol":"ETH/EUR","bids":[],"asks":[{"price":3506.76,"qty":0.72912968}],"checksum":1498169430,"timestamp":"2024-06-01T18:06:12.379488Z"}]}
{"channel":"book","type":"update","data":[{"symbol":"ETH/EUR","bids":[],"asks":[{"price":3506.15,"qty":65.15580274}],"checksum":1788458102,"timestamp":"2024-06-01T18:06:12.400421Z"}]}
{"channel":"book","type":"update","data":[{"symbol":"ETH/EUR","bids":[],"asks":[{"price":3506.15,"qty":38.85944266}],"checksum":1498169430,"timestamp":"2024-06-01T18:06:12.406552Z"}]}
{"channel":"book","type":"update","data":[{"symbol":"ETH/EUR","bids":[{"price":3505.85,"qty":26.29854552}],"asks":[],"checksum":2835493265,"timestamp":"2024-06-01T18:06:12.411159Z"}]}
{"channel":"book","type":"update","data":[{"symbol":"ETH/EUR","bids":[{"price":3505.85,"qty":0.00000000},{"price":3505.00,"qty":0.00220000}],"asks":[],"checksum":1498169430,"timestamp":"2024-06-01T18:06:12.434392Z"}]}
{"channel":"book","type":"update","data":[{"symbol":"ETH/EUR","bids":[],"asks":[{"price":3506.11,"qty":26.29667903}],"checksum":18322092,"timestamp":"2024-06-01T18:06:12.450728Z"}]}
{"channel":"book","type":"update","data":[{"symbol":"ETH/EUR","bids":[],"asks":[{"price":3506.11,"qty":0.00000000},{"price":3506.99,"qty":3.01305282}],"checksum":1498169430,"timestamp":"2024-06-01T18:06:12.455509Z"}]}
{"channel":"book","type":"update","data":[{"symbol":"ETH/EUR","bids":[{"price":3505.56,"qty":26.30073504}],"asks":[],"checksum":1150346885,"timestamp":"2024-06-01T18:06:12.470868Z"}]}
{"channel":"book","type":"update","data":[{"symbol":"ETH/EUR","bids":[{"price":3505.56,"qty":0.00000000},{"price":3505.00,"qty":0.00220000}],"asks":[],"checksum":1498169430,"timestamp":"2024-06-01T18:06:12.486632Z"}]}
{"channel":"book","type":"update","data":[{"symbol":"ETH/EUR","bids":[{"price":3505.57,"qty":26.30066001}],"asks":[],"checksum":919144605,"timestamp":"2024-06-01T18:06:12.498274Z"}]}
{"channel":"book","type":"update","data":[{"symbol":"ETH/EUR","bids":[],"asks":[{"price":3506.10,"qty":26.29672372}],"checksum":3404977615,"timestamp":"2024-06-01T18:06:12.503543Z"}]}
{"channel":"book","type":"update","data":[{"symbol":"ETH/EUR","bids":[{"price":3505.52,"qty":0.00000000},{"price":3505.00,"qty":0.00220000}],"asks":[],"checksum":388603510,"timestamp":"2024-06-01T18:06:12.507455Z"}]}
{"channel":"book","type":"update","data":[{"symbol":"ETH/EUR","bids":[],"asks":[{"price":3506.16,"qty":26.29625493}],"checksum":953564604,"timestamp":"2024-06-01T18:06:12.559427Z"}]}
{"channel":"book","type":"update","data":[{"symbol":"ETH/EUR","bids":[{"price":3505.82,"qty":26.29875057}],"asks":[],"checksum":3012889304,"timestamp":"2024-06-01T18:06:12.559589Z"}]}
{"channel":"book","type":"update","data":[{"symbol":"ETH/EUR","bids":[{"price":3505.82,"qty":0.00000000},{"price":3505.00,"qty":0.00220000}],"asks":[],"checksum":953564604,"timestamp":"2024-06-01T18:06:12.571310Z"}]}
{"channel":"book","type":"update","data":[{"symbol":"ETH/EUR","bids":[],"asks":[{"price":3506.10,"qty":0.00000000},{"price":3506.98,"qty":0.61651667}],"checksum":3360656822,"timestamp":"2024-06-01T18:06:12.571369Z"}]}
{"channel":"book","type":"update","data":[{"symbol":"ETH/EUR","bids":[],"asks":[{"price":3506.38,"qty":26.29462601}],"checksum":178253034,"timestamp":"2024-06-01T18:06:12.577432Z"}]}
{"channel":"book","type":"update","data":[{"symbol":"ETH/EUR","bids":[],"asks":[{"price":3506.16,"qty":0.00000000},{"price":3506.98,"qty":0.61651667}],"checksum":1664046134,"timestamp":"2024-06-01T18:06:12.603069Z"}]}
{"channel":"book","type":"update","data":[{"symbol":"ETH/EUR","bids":[],"asks":[{"price":3506.72,"qty":0.00000000},{"price":3506.99,"qty":3.01305282}],"checksum":1378490878,"timestamp":"2024-06-01T18:06:12.603083Z"}]}
{"channel":"book","type":"update","data":[{"symbol":"ETH/EUR","bids":[{"price":3505.36,"qty":26.30221464}],"asks":[],"checksum":377165105,"timestamp":"2024-06-01T18:06:12.640102Z"}]}
{"channel":"book","type":"update","data":[{"symbol":"ETH/EUR","bids":[{"price":3505.76,"qty":26.29920056}],"asks":[],"checksum":836451134,"timestamp":"2024-06-01T18:06:12.640200Z"}]}
{"channel":"book","type":"update","data":[{"symbol":"ETH/EUR","bids":[],"asks":[{"price":3506.04,"qty":26.29718814}],"checksum":1246539796,"timestamp":"2024-06-01T18:06:12.640214Z"}]}
{"channel":"book","type":"update","data":[{"symbol":"ETH/EUR","bids":[],"asks":[{"price":3506.04,"qty":0.00000000},{"price":3506.99,"qty":3.01305282}],"checksum":836451134,"timestamp":"2024-06-01T18:06:12.678333Z"}]}
{"channel":"book","type":"update","data":[{"symbol":"ETH/EUR","bids":[{"price":3505.76,"qty":0.00000000},{"price":3505.20,"qty":0.00220000}],"asks":[],"checksum":377165105,"timestamp":"2024-06-01T18:06:12.716873Z"}]}
{"channel":"book","type":"update","data":[{"symbol":"ETH/EUR","bids":[],"asks":[{"price":3506.03,"qty":26.29725649}],"checksum":2732241611,"timestamp":"2024-06-01T18:06:12.721972Z"}]}
{"channel":"book","type":"update","data":[{"symbol":"ETH/EUR","bids":[{"price":3505.69,"qty":26.29969489}],"asks":[],"checksum":2188513204,"timestamp":"2024-06-01T18:06:12.722113Z"}]}
{"channel":"book","type":"update","data":[{"symbol":"ETH/EUR","bids":[{"price":3505.69,"qty":0.00000000},{"price":3505.20,"qty":0.00220000}],"asks":[],"checksum":2732241611,"timestamp":"2024-06-01T18:06:12.726566Z"}]}
{"channel":"book","type":"update","data":[{"symbol":"ETH/EUR","bids":[],"asks":[{"price":3506.03,"qty":0.00000000},{"price":3506.99,"qty":3.01305282}],"checksum":377165105,"timestamp":"2024-06-01T18:06:12.732999Z"}]}
{"channel":"book","type":"update","data":[{"symbol":"ETH/EUR","bids":[],"asks":[{"price":3506.38,"qty":0.00000000},{"price":3507.10,"qty":6.00000000}],"checksum":3327342802,"timestamp":"2024-06-01T18:06:12.733116Z"}]}
{"channel":"book","type":"update","data":[{"symbol":"ETH/EUR","bids":[{"price":3505.55,"qty":0.00000000},{"price":3505.00,"qty":0.00220000}],"asks":[],"checksum":3654054173,"timestamp":"2024-06-01T18:06:12.736513Z"}]}
{"channel":"book","type":"update","data":[{"symbol":"ETH/EUR","bids":[{"price":3505.58,"qty":1.60000000}],"asks":[],"checksum":507789240,"timestamp":"2024-06-01T18:06:12.736607Z"}]}
{"channel":"book","type":"update","data":[{"symbol":"ETH/EUR","bids":[],"asks":[{"price":3506.02,"qty":26.29732015}],"checksum":751192983,"timestamp":"2024-06-01T18:06:12.800825Z"}]}
{"channel":"book","type":"update","data":[{"symbol":"ETH/EUR","bids":[],"asks":[{"price":3506.81,"qty":4.03051600}],"checksum":1114338314,"timestamp":"2024-06-01T18:06:12.804562Z"}]}
{"channel":"book","type":"update","data":[{"symbol":"ETH/EUR","bids":[],"asks":[{"price":3506.56,"qty":26.29326770}],"checksum":2626086928,"timestamp":"2024-06-01T18:06:12.845306Z"}]}
{"channel":"book","type":"update","data":[{"symbol":"ETH/EUR","bids":[],"asks":[{"price":3506.02,"qty":0.00000000},{"price":3506.99,"qty":3.01305282}],"checksum":3934945062,"timestamp":"2024-06-01T18:06:12.992875Z"}]}
{"channel":"book","type":"update","data":[{"symbol":"ETH/EUR","bids":[],"asks":[{"price":3506.00,"qty":26.29747516}],"checksum":2629210497,"timestamp":"2024-06-01T18:06:12.997593Z"}]}
{"channel":"book","type":"update","data":[{"symbol":"ETH/EUR","bids":[],"asks":[{"price":3506.27,"qty":26.29545985}],"checksum":364872336,"timestamp":"2024-06-01T18:06:12.997711Z"}]}
{"channel":"book","type":"update","data":[{"symbol":"ETH/EUR","bids":[{"price":3505.53,"qty":0.00000000},{"price":3505.00,"qty":0.00220000},{"price":3505.59,"qty":0.03536060}],"asks":[],"checksum":457100155,"timestamp":"2024-06-01T18:06:13.015769Z"}]}
{"channel":"book","type":"update","data":[{"symbol":"ETH/EUR","bids":[],"asks":[{"price":3506.14,"qty":0.00000000},{"price":3506.98,"qty":0.61651667},{"price":3506.01,"qty":0.01502815}],"checksum":1823179010,"timestamp":"2024-06-01T18:06:13.016128Z"}]}
{"channel":"book","type":"update","data":[{"symbol":"ETH/EUR","bids":[],"asks":[{"price":3506.08,"qty":26.29686744}],"checksum":2531440828,"timestamp":"2024-06-01T18:06:13.050806Z"}]}
{"channel":"book","type":"update","data":[{"symbol":"ETH/EUR","bids":[],"asks":[{"price":3506.01,"qty":0.00000000},{"price":3506.85,"qty":1.05800000},{"price":3506.07,"qty":0.01502815}],"checksum":2494288087,"timestamp":"2024-06-01T18:06:13.210347Z"}]}
{"channel":"book","type":"update","data":[{"symbol":"ETH/EUR","bids":[{"price":3505.57,"qty":0.00000000},{"price":3505.00,"qty":0.00220000}],"asks":[],"checksum":2463465590,"timestamp":"2024-06-01T18:06:13.241203Z"}]}
{"channel":"book","type":"update","data":[{"symbol":"ETH/EUR","bids":[],"asks":[{"price":3506.00,"qty":0.00000000},{"price":3506.85,"qty":1.05800000}],"checksum":2700561540,"timestamp":"2024-06-01T18:06:13.241262Z"}]}
{"channel":"book","type":"update","data":[{"symbol":"ETH/EUR","bids":[{"price":3505.58,"qty":0.00000000},{"price":3504.94,"qty":1.35554034}],"asks":[],"checksum":1290814451,"timestamp":"2024-06-01T18:06:13.244248Z"}]}
{"channel":"book","type":"update","data":[{"symbol":"ETH/EUR","bids":[{"price":3505.44,"qty":1.68553200}],"asks":[],"checksum":1318413665,"timestamp":"2024-06-01T18:06:13.244502Z"}]}
{"channel":"book","type":"update","data":[{"symbol":"ETH/EUR","bids":[],"asks":[{"price":3506.08,"qty":0.00000000},{"price":3506.98,"qty":0.61651667}],"checksum":549250065,"timestamp":"2024-06-01T18:06:13.247518Z"}]}
{"channel":"book","type":"update","data":[{"symbol":"ETH/EUR","bids":[],"asks":[{"price":3506.06,"qty":26.29698429}],"checksum":539483631,"timestamp":"2024-06-01T18:06:13.251453Z"}]}
{"channel":"book","type":"update","data":[{"symbol":"ETH/EUR","bids":[],"asks":[{"price":3505.99,"qty":26.29754351}],"checksum":1944979757,"timestamp":"2024-06-01T18:06:13.251482Z"}]}
{"channel":"book","type":"update","data":[{"symbol":"ETH/EUR","bids":[{"price":3505.36,"qty":0.00000000},{"price":3504.80,"qty":0.00220000}],"asks":[],"checksum":1479707780,"timestamp":"2024-06-01T18:06:13.275231Z"}]}
{"channel":"book","type":"update","data":[{"symbol":"ETH/EUR","bids":[{"price":3505.59,"qty":0.00000000},{"price":3504.65,"qty":0.84644082},{"price":3505.45,"qty":0.03536202}],"asks":[],"checksum":376449865,"timestamp":"2024-06-01T18:06:13.298774Z"}]}
{"channel":"book","type":"update","data":[{"symbol":"ETH/EUR","bids":[],"asks":[{"price":3505.99,"qty":0.00000000},{"price":3506.85,"qty":1.05800000}],"checksum":2839186215,"timestamp":"2024-06-01T18:06:13.389593Z"}]}
{"channel":"book","type":"update","data":[{"symbol":"ETH/EUR","bids":[],"asks":[{"price":3506.05,"qty":1.60000000}],"checksum":3194993349,"timestamp":"2024-06-01T18:06:13.392678Z"}]}
{"channel":"book","type":"update","data":[{"symbol":"ETH/EUR","bids":[],"asks":[{"price":3506.01,"qty":26.29739105}],"checksum":3468230114,"timestamp":"2024-06-01T18:06:13.394869Z"}]}
{"channel":"book","type":"update","data":[{"symbol":"ETH/EUR","bids":[],"asks":[{"price":3506.01,"qty":0.00000000},{"price":3506.81,"qty":4.03051600}],"checksum":3194993349,"timestamp":"2024-06-01T18:06:13.400931Z"}]}
{"channel":"book","type":"update","data":[{"symbol":"ETH/EUR","bids":[],"asks":[{"price":3506.81,"qty":3.94500000},{"price":3506.30,"qty":0.08552300}],"checksum":4023333605,"timestamp":"2024-06-01T18:06:13.419543Z"}]}
{"channel":"book","type":"update","data":[{"symbol":"ETH/EUR","bids":[],"asks":[{"price":3506.01,"qty":26.29743157}],"checksum":1575403598,"timestamp":"2024-06-01T18:06:13.530161Z"}]}
{"channel":"book","type":"update","data":[{"symbol":"ETH/EUR","bids":[],"asks":[{"price":3506.55,"qty":0.13527221}],"checksum":4090255715,"timestamp":"2024-06-01T18:06:13.535341Z"}]}
{"channel":"book","type":"update","data":[{"symbol":"ETH/EUR","bids":[],"asks":[{"price":3506.57,"qty":0.00000000},{"price":3506.75,"qty":0.84644082}],"checksum":3656449857,"timestamp":"2024-06-01T18:06:13.569641Z"}]}
{"channel":"book","type":"update","data":[{"symbol":"ETH/EUR","bids":[],"asks":[{"price":3506.01,"qty":0.00000000},{"price":3506.76,"qty":0.72912968}],"checksum":3141548122,"timestamp":"2024-06-01T18:06:13.701440Z"}]}
{"channel":"book","type":"update","data":[{"symbol":"ETH/EUR","bids":[],"asks":[{"price":3505.99,"qty":26.29753821}],"checksum":2277866159,"timestamp":"2024-06-01T18:06:13.706419Z"}]}
{"channel":"book","type":"update","data":[{"symbol":"ETH/EUR","bids":[{"price":3505.44,"qty":0.08553200}],"asks":[],"checksum":3536051644,"timestamp":"2024-06-01T18:06:13.709444Z"}]}
{"channel":"book","type":"update","data":[{"symbol":"ETH/EUR","bids":[],"asks":[{"price":3506.06,"qty":0.00000000},{"price":3506.76,"qty":0.72912968}],"checksum":640701525,"timestamp":"2024-06-01T18:06:13.711919Z"}]}
{"channel":"book","type":"update","data":[{"symbol":"ETH/EUR","bids":[{"price":3505.70,"qty":26.29966460}],"asks":[],"checksum":2883764027,"timestamp":"2024-06-01T18:06:13.755230Z"}]}
{"channel":"book","type":"update","data":[{"symbol":"ETH/EUR","bids":[],"asks":[{"price":3505.97,"qty":26.29768328}],"checksum":994541848,"timestamp":"2024-06-01T18:06:13.760216Z"}]}
{"channel":"book","type":"update","data":[{"symbol":"ETH/EUR","bids":[],"asks":[{"price":3506.07,"qty":0.00000000},{"price":3506.76,"qty":0.72912968},{"price":3506.14,"qty":0.01503109}],"checksum":55619754,"timestamp":"2024-06-01T18:06:13.818961Z"}]}
{"channel":"book","type":"update","data":[{"symbol":"ETH/EUR","bids":[{"price":3505.70,"qty":0.00000000},{"price":3504.80,"qty":0.00220000}],"asks":[],"checksum":4061528546,"timestamp":"2024-06-01T18:06:13.933217Z"}]}
{"channel":"book","type":"update","data":[{"symbol":"ETH/EUR","bids":[{"price":3505.71,"qty":26.29955676}],"asks":[],"checksum":2224393640,"timestamp":"2024-06-01T18:06:13.937823Z"}]}
{"channel":"book","type":"update","data":[{"symbol":"ETH/EUR","bids":[{"price":3505.45,"qty":0.00000000},{"price":3504.80,"qty":0.00220000},{"price":3505.72,"qty":0.03535490}],"asks":[],"checksum":329456315,"timestamp":"2024-06-01T18:06:14.036510Z"}]}
{"channel":"book","type":"update","data":[{"symbol":"ETH/EUR","bids":[],"asks":[{"price":3506.15,"qty":0.00000000},{"price":3506.76,"qty":0.72912968}],"checksum":3561809671,"timestamp":"2024-06-01T18:06:14.150926Z"}]}
{"channel":"book","type":"update","data":[{"symbol":"ETH/EUR","bids":[],"asks":[{"price":3506.55,"qty":19.77585776}],"checksum":2426043716,"timestamp":"2024-06-01T18:06:14.155312Z"}]}
{"channel":"book","type":"update","data":[{"symbol":"ETH/EUR","bids":[],"asks":[{"price":3506.14,"qty":0.00000000},{"price":3506.81,"qty":3.94500000},{"price":3506.26,"qty":0.01503108}],"checksum":891542100,"timestamp":"2024-06-01T18:06:14.205090Z"}]}
{"channel":"book","type":"update","data":[{"symbol":"ETH/EUR","bids":[],"asks":[{"price":3506.05,"qty":0.00000000},{"price":3506.81,"qty":3.94500000}],"checksum":2976275067,"timestamp":"2024-06-01T18:06:14.208054Z"}]}
{"channel":"book","type":"update","data":[{"symbol":"ETH/EUR","bids":[{"price":3505.71,"qty":0.00000000},{"price":3504.82,"qty":6.00000000}],"asks":[],"checksum":3514282184,"timestamp":"2024-06-01T18:06:14.905812Z"}]}
{"channel":"book","type":"update","data":[{"symbol":"ETH/EUR","bids":[{"price":3505.69,"qty":26.29971306}],"asks":[],"checksum":920798744,"timestamp":"2024-06-01T18:06:14.909721Z"}]}
{"channel":"book","type":"update","data":[{"symbol":"ETH/EUR","bids":[{"price":3505.60,"qty":26.30043494}],"asks":[],"checksum":2679462822,"timestamp":"2024-06-01T18:06:14.909851Z"}]}
{"channel":"book","type":"update","data":[{"symbol":"ETH/EUR","bids":[{"price":3505.69,"qty":0.00000000},{"price":3504.94,"qty":1.35554034}],"asks":[],"checksum":711304995,"timestamp":"2024-06-01T18:06:14.925130Z"}]}
{"channel":"book","type":"update","data":[{"symbol":"ETH/EUR","bids":[{"price":3505.72,"qty":0.00000000},{"price":3504.80,"qty":0.00220000},{"price":3505.45,"qty":0.03535761}],"asks":[],"checksum":3758963837,"timestamp":"2024-06-01T18:06:14.959186Z"}]}
{"channel":"book","type":"update","data":[{"symbol":"ETH/EUR","bids":[{"price":3505.60,"qty":0.00000000},{"price":3504.80,"qty":0.00220000}],"asks":[],"checksum":1495281936,"timestamp":"2024-06-01T18:06:14.963643Z"}]}
{"channel":"book","type":"update","data":[{"symbol":"ETH/EUR","bids":[{"price":3505.70,"qty":26.29965522}],"asks":[],"checksum":607638789,"timestamp":"2024-06-01T18:06:14.967878Z"}]}
{"channel":"book","type":"update","data":[{"symbol":"ETH/EUR","bids":[{"price":3505.45,"qty":0.00000000},{"price":3504.80,"qty":0.00220000},{"price":3505.71,"qty":0.03535499}],"asks":[],"checksum":3139757226,"timestamp":"2024-06-01T18:06:15.099186Z"}]}
{"channel":"book","type":"update","data":[{"symbol":"ETH/EUR","bids":[],"asks":[{"price":3506.26,"qty":0.00000000},{"price":3506.85,"qty":1.05800000},{"price":3505.96,"qty":0.01503107}],"checksum":3145660760,"timestamp":"2024-06-01T18:06:15.099236Z"}]}
{"channel":"book","type":"update","data":[{"symbol":"ETH/EUR","bids":[{"price":3505.70,"qty":0.00000000},{"price":3504.80,"qty":0.00220000}],"asks":[],"checksum":2028377486,"timestamp":"2024-06-01T18:06:15.291609Z"}]}
{"channel":"book","type":"update","data":[{"symbol":"ETH/EUR","bids":[],"asks":[{"price":3505.97,"qty":0.00000000},{"price":3506.85,"qty":1.05800000}],"checksum":172892913,"timestamp":"2024-06-01T18:06:15.291737Z"}]}
{"channel":"book","type":"update","data":[{"symbol":"ETH/EUR","bids":[{"price":3505.32,"qty":2.23360987}],"asks":[],"checksum":2508365894,"timestamp":"2024-06-01T18:06:15.295461Z"}]}
{"channel":"book","type":"update","data":[{"symbol":"ETH/EUR","bids":[],"asks":[{"price":3506.56,"qty":0.00000000},{"price":3506.98,"qty":0.61651667}],"checksum":3427947910,"timestamp":"2024-06-01T18:06:15.299086Z"}]}
{"channel":"book","type":"update","data":[{"symbol":"ETH/EUR","bids":[],"asks":[{"price":3505.81,"qty":26.29889388}],"checksum":1002496157,"timestamp":"2024-06-01T18:06:15.303780Z"}]}
{"channel":"book","type":"update","data":[{"symbol":"ETH/EUR","bids":[],"asks":[{"price":3505.81,"qty":0.00000000},{"price":3506.98,"qty":0.61651667}],"checksum":3427947910,"timestamp":"2024-06-01T18:06:15.343956Z"}]}
{"channel":"book","type":"update","data":[{"symbol":"ETH/EUR","bids":[],"asks":[{"price":3505.98,"qty":1.60000000}],"checksum":3774513667,"timestamp":"2024-06-01T18:06:15.346839Z"}]}
{"channel":"book","type":"update","data":[{"symbol":"ETH/EUR","bids":[],"asks":[{"price":3505.83,"qty":26.29873368}],"checksum":3998731319,"timestamp":"2024-06-01T18:06:15.393091Z"}]}
{"channel":"book","type":"update","data":[{"symbol":"ETH/EUR","bids":[{"price":3505.32,"qty":0.63360987}],"asks":[],"checksum":1846148411,"timestamp":"2024-06-01T18:06:15.428455Z"}]}
{"channel":"book","type":"update","data":[{"symbol":"ETH/EUR","bids":[{"price":3505.44,"qty":0.00000000},{"price":3504.65,"qty":0.84644082},{"price":3504.76,"qty":0.08554000}],"asks":[],"checksum":3726170369,"timestamp":"2024-06-01T18:06:15.431621Z"}]}
{"channel":"book","type":"update","data":[{"symbol":"ETH/EUR","bids":[],"asks":[{"price":3505.79,"qty":26.29903861}],"checksum":1694316264,"timestamp":"2024-06-01T18:06:15.661675Z"}]}
{"channel":"book","type":"update","data":[{"symbol":"ETH/EUR","bids":[],"asks":[{"price":3505.79,"qty":0.00000000},{"price":3506.81,"qty":3.94500000}],"checksum":3726170369,"timestamp":"2024-06-01T18:06:15.715010Z"}]}
{"channel":"book","type":"update","data":[{"symbol":"ETH/EUR","bids":[],"asks":[{"price":3505.82,"qty":26.29884933}],"checksum":967479411,"timestamp":"2024-06-01T18:06:15.719702Z"}]}
{"channel":"book","type":"update","data":[{"symbol":"ETH/EUR","bids":[],"asks":[{"price":3505.99,"qty":0.00000000},{"price":3506.81,"qty":3.94500000}],"checksum":3618887061,"timestamp":"2024-06-01T18:06:15.769118Z"}]}
{"channel":"book","type":"update","data":[{"symbol":"ETH/EUR","bids":[],"asks":[{"price":3505.82,"qty":0.00000000},{"price":3506.85,"qty":1.05800000}],"checksum":3993575949,"timestamp":"2024-06-01T18:06:15.769242Z"}]}
{"channel":"book","type":"update","data":[{"symbol":"ETH/EUR","bids":[],"asks":[{"price":3505.83,"qty":0.00000000},{"price":3506.98,"qty":0.61651667}],"checksum":3599667028,"timestamp":"2024-06-01T18:06:15.769330Z"}]}
{"channel":"book","type":"update","data":[{"symbol":"ETH/EUR","bids":[],"asks":[{"price":3505.98,"qty":0.00000000},{"price":3506.99,"qty":3.01305282}],"checksum":1954397723,"timestamp":"2024-06-01T18:06:15.771973Z"}]}
{"channel":"book","type":"update","data":[{"symbol":"ETH/EUR","bids":[],"asks":[{"price":3506.22,"qty":1.60000000}],"checksum":820724265,"timestamp":"2024-06-01T18:06:15.772369Z"}]}
{"channel":"book","type":"update","data":[{"symbol":"ETH/EUR","bids":[],"asks":[{"price":3505.95,"qty":26.29780936}],"checksum":4281642894,"timestamp":"2024-06-01T18:06:15.774537Z"}]}
{"channel":"book","type":"update","data":[{"symbol":"ETH/EUR","bids":[],"asks":[{"price":3505.80,"qty":26.29897019}],"checksum":623294424,"timestamp":"2024-06-01T18:06:15.774621Z"}]}
{"channel":"book","type":"update","data":[{"symbol":"ETH/EUR","bids":[],"asks":[{"price":3506.09,"qty":26.29680617}],"checksum":2903954566,"timestamp":"2024-06-01T18:06:15.774661Z"}]}
{"channel":"book","type":"update","data":[{"symbol":"ETH/EUR","bids":[],"asks":[{"price":3505.95,"qty":0.00000000},{"price":3506.81,"qty":3.94500000}],"checksum":731863293,"timestamp":"2024-06-01T18:06:15.793748Z"}]}
{"channel":"book","type":"update","data":[{"symbol":"ETH/EUR","bids":[{"price":3504.95,"qty":2.60000000}],"asks":[],"checksum":879438567,"timestamp":"2024-06-01T18:06:15.847407Z"}]}
{"channel":"book","type":"update","data":[{"symbol":"ETH/EUR","bids":[],"asks":[{"price":3505.78,"qty":26.29913743}],"checksum":320953639,"timestamp":"2024-06-01T18:06:15.975087Z"}]}
{"channel":"book","type":"update","data":[{"symbol":"ETH/EUR","bids":[],"asks":[{"price":3505.96,"qty":0.00000000},{"price":3506.81,"qty":3.94500000},{"price":3506.54,"qty":0.01503035}],"checksum":3937350318,"timestamp":"2024-06-01T18:06:16.043042Z"}]}
{"channel":"book","type":"update","data":[{"symbol":"ETH/EUR","bids":[],"asks":[{"price":3506.55,"qty":19.64058555}],"checksum":1968365477,"timestamp":"2024-06-01T18:06:16.079717Z"}]}
{"channel":"book","type":"update","data":[{"symbol":"ETH/EUR","bids":[],"asks":[{"price":3506.09,"qty":0.00000000},{"price":3506.81,"qty":3.94500000}],"checksum":1461283202,"timestamp":"2024-06-01T18:06:16.136875Z"}]}
{"channel":"book","type":"update","data":[{"symbol":"ETH/EUR","bids":[],"asks":[{"price":3505.78,"qty":0.00000000},{"price":3506.85,"qty":1.05800000}],"checksum":528342716,"timestamp":"2024-06-01T18:06:16.136961Z"}]}
{"channel":"book","type":"update","data":[{"symbol":"ETH/EUR","bids":[],"asks":[{"price":3505.73,"qty":26.29948410}],"checksum":3681573747,"timestamp":"2024-06-01T18:06:16.142001Z"}]}
{"channel":"book","type":"update","data":[{"symbol":"ETH/EUR","bids":[],"asks":[{"price":3505.98,"qty":26.29761438}],"checksum":4086736683,"timestamp":"2024-06-01T18:06:16.142101Z"}]}
{"channel":"book","type":"update","data":[{"symbol":"ETH/EUR","bids":[],"asks":[{"price":3506.54,"qty":0.00000000},{"price":3506.81,"qty":3.94500000},{"price":3506.80,"qty":0.01503034}],"checksum":1132005147,"timestamp":"2024-06-01T18:06:16.142483Z"}]}
{"channel":"book","type":"update","data":[{"symbol":"ETH/EUR","bids":[{"price":3504.95,"qty":0.00000000},{"price":3504.76,"qty":0.08554000}],"asks":[],"checksum":3973583008,"timestamp":"2024-06-01T18:06:16.311630Z"}]}
{"channel":"book","type":"update","data":[{"symbol":"ETH/EUR","bids":[{"price":3505.32,"qty":26.93609523}],"asks":[],"checksum":845721997,"timestamp":"2024-06-01T18:06:16.351065Z"}]}
{"channel":"book","type":"update","data":[{"symbol":"ETH/EUR","bids":[{"price":3505.45,"qty":26.30150842}],"asks":[],"checksum":4210356069,"timestamp":"2024-06-01T18:06:16.351082Z"}]}
{"channel":"book","type":"update","data":[{"symbol":"ETH/EUR","bids":[{"price":3505.03,"qty":26.30463795}],"asks":[],"checksum":4240296677,"timestamp":"2024-06-01T18:06:16.351264Z"}]}
{"channel":"book","type":"update","data":[{"symbol":"ETH/EUR","bids":[{"price":3505.32,"qty":0.63360987}],"asks":[],"checksum":4006479727,"timestamp":"2024-06-01T18:06:16.355027Z"}]}
{"channel":"book","type":"update","data":[{"symbol":"ETH/EUR","bids":[{"price":3505.48,"qty":26.30129039}],"asks":[],"checksum":1594891293,"timestamp":"2024-06-01T18:06:16.509943Z"}]}
{"channel":"book","type":"update","data":[{"symbol":"ETH/EUR","bids":[],"asks":[{"price":3506.55,"qty":0.00000000},{"price":3506.81,"qty":3.94500000}],"checksum":2359547150,"timestamp":"2024-06-01T18:06:16.613554Z"}]}
{"channel":"book","type":"update","data":[{"symbol":"ETH/EUR","bids":[],"asks":[{"price":3505.73,"qty":0.00000000},{"price":3506.85,"qty":1.05800000}],"checksum":878309280,"timestamp":"2024-06-01T18:06:16.717234Z"}]}
{"channel":"book","type":"update","data":[{"symbol":"ETH/EUR","bids":[{"price":3505.48,"qty":0.00000000},{"price":3504.94,"qty":1.35554034}],"asks":[],"checksum":3429649983,"timestamp":"2024-06-01T18:06:16.717272Z"}]}
{"channel":"book","type":"update","data":[{"symbol":"ETH/EUR","bids":[{"price":3505.50,"qty":26.30334316}],"asks":[],"checksum":3520781856,"timestamp":"2024-06-01T18:06:16.725078Z"}]}
{"channel":"book","type":"update","data":[{"symbol":"ETH/EUR","bids":[],"asks":[{"price":3505.76,"qty":26.29924750}],"checksum":1551715682,"timestamp":"2024-06-01T18:06:16.725096Z"}]}
{"channel":"book","type":"update","data":[{"symbol":"ETH/EUR","bids":[],"asks":[{"price":3505.80,"qty":0.00000000},{"price":3506.85,"qty":1.05800000}],"checksum":3242878091,"timestamp":"2024-06-01T18:06:16.725194Z"}]}
{"channel":"book","type":"update","data":[{"symbol":"ETH/EUR","bids":[{"price":3505.50,"qty":0.00220000}],"asks":[],"checksum":713647266,"timestamp":"2024-06-01T18:06:16.730328Z"}]}
{"channel":"book","type":"update","data":[{"symbol":"ETH/EUR","bids":[],"asks":[{"price":3505.72,"qty":26.29953468}],"checksum":2054754820,"timestamp":"2024-06-01T18:06:16.787048Z"}]}
{"channel":"book","type":"update","data":[{"symbol":"ETH/EUR","bids":[{"price":3505.14,"qty":0.08553500}],"asks":[],"checksum":2621634330,"timestamp":"2024-06-01T18:06:16.810197Z"}]}
{"channel":"book","type":"update","data":[{"symbol":"ETH/EUR","bids":[{"price":3505.51,"qty":3.06500000}],"asks":[],"checksum":2832794105,"timestamp":"2024-06-01T18:06:16.844749Z"}]}
{"channel":"book","type":"update","data":[{"symbol":"ETH/EUR","bids":[{"price":3505.45,"qty":0.00000000},{"price":3505.00,"qty":0.00220000}],"asks":[],"checksum":1402556710,"timestamp":"2024-06-01T18:06:16.949034Z"}]}
{"channel":"book","type":"update","data":[{"symbol":"ETH/EUR","bids":[],"asks":[{"price":3506.37,"qty":0.72912968}],"checksum":4084722765,"timestamp":"2024-06-01T18:06:16.953853Z"}]}
{"channel":"book","type":"update","data":[{"symbol":"ETH/EUR","bids":[],"asks":[{"price":3506.27,"qty":0.00000000},{"price":3506.81,"qty":3.94500000}],"checksum":3070511570,"timestamp":"2024-06-01T18:06:16.957809Z"}]}
{"channel":"book","type":"update","data":[{"symbol":"ETH/EUR","bids":[],"asks":[{"price":3505.85,"qty":26.29856884}],"checksum":3781442023,"timestamp":"2024-06-01T18:06:16.962318Z"}]}
{"channel":"book","type":"update","data":[{"symbol":"ETH/EUR","bids":[{"price":3505.71,"qty":0.00000000},{"price":3504.94,"qty":1.35554034},{"price":3505.52,"qty":0.03536165}],"asks":[],"checksum":2841369262,"timestamp":"2024-06-01T18:06:17.077136Z"}]}
{"channel":"book","type":"update","data":[{"symbol":"ETH/EUR","bids":[],"asks":[{"price":3506.76,"qty":0.00000000},{"price":3506.81,"qty":3.94500000}],"checksum":4164830788,"timestamp":"2024-06-01T18:06:17.081256Z"}]}
{"channel":"book","type":"update","data":[{"symbol":"ETH/EUR","bids":[],"asks":[{"price":3505.76,"qty":0.00000000},{"price":3506.85,"qty":1.05800000}],"checksum":2512840291,"timestamp":"2024-06-01T18:06:17.082067Z"}]}
{"channel":"book","type":"update","data":[{"symbol":"ETH/EUR","bids":[],"asks":[{"price":3505.60,"qty":26.30048993}],"checksum":11080251,"timestamp":"2024-06-01T18:06:17.085620Z"}]}
{"channel":"book","type":"update","data":[{"symbol":"ETH/EUR","bids":[],"asks":[{"price":3505.72,"qty":0.00000000},{"price":3506.85,"qty":1.05800000}],"checksum":3649110921,"timestamp":"2024-06-01T18:06:17.176320Z"}]}
{"channel":"book","type":"update","data":[{"symbol":"ETH/EUR","bids":[],"asks":[{"price":3505.59,"qty":26.30052937}],"checksum":2660554103,"timestamp":"2024-06-01T18:06:17.179741Z"}]}
{"channel":"book","type":"update","data":[{"symbol":"ETH/EUR","bids":[],"asks":[{"price":3506.29,"qty":0.64969477}],"checksum":274612038,"timestamp":"2024-06-01T18:06:17.183270Z"}]}
{"channel":"book","type":"update","data":[{"symbol":"ETH/EUR","bids":[{"price":3505.51,"qty":0.00000000},{"price":3504.94,"qty":1.35554034}],"asks":[],"checksum":672162354,"timestamp":"2024-06-01T18:06:17.207342Z"}]}
{"channel":"book","type":"update","data":[{"symbol":"ETH/EUR","bids":[],"asks":[{"price":3506.80,"qty":0.00000000},{"price":3506.81,"qty":3.94500000}],"checksum":2561058261,"timestamp":"2024-06-01T18:06:17.227290Z"}]}
{"channel":"book","type":"update","data":[{"symbol":"ETH/EUR","bids":[],"asks":[{"price":3505.59,"qty":0.00000000},{"price":3506.85,"qty":1.05800000}],"checksum":2654578849,"timestamp":"2024-06-01T18:06:17.401431Z"}]}
{"channel":"book","type":"update","data":[{"symbol":"ETH/EUR","bids":[],"asks":[{"price":3505.62,"qty":26.30032693}],"checksum":591172542,"timestamp":"2024-06-01T18:06:17.405846Z"}]}
{"channel":"book","type":"update","data":[{"symbol":"ETH/EUR","bids":[],"asks":[{"price":3505.60,"qty":0.00000000},{"price":3506.85,"qty":1.05800000}],"checksum":1589381696,"timestamp":"2024-06-01T18:06:17.573229Z"}]}
{"channel":"book","type":"update","data":[{"symbol":"ETH/EUR","bids":[],"asks":[{"price":3505.62,"qty":0.00000000},{"price":3506.98,"qty":0.01503034}],"checksum":1762067352,"timestamp":"2024-06-01T18:06:17.573364Z"}]}
{"channel":"book","type":"update","data":[{"symbol":"ETH/EUR","bids":[],"asks":[{"price":3505.61,"qty":26.30039791}],"checksum":1890558122,"timestamp":"2024-06-01T18:06:17.581816Z"}]}
{"channel":"book","type":"update","data":[{"symbol":"ETH/EUR","bids":[],"asks":[{"price":3505.84,"qty":26.29863449}],"checksum":1028159086,"timestamp":"2024-06-01T18:06:17.581839Z"}]}
{"channel":"book","type":"update","data":[{"symbol":"ETH/EUR","bids":[],"asks":[{"price":3505.84,"qty":0.00000000},{"price":3506.85,"qty":1.05800000}],"checksum":1890558122,"timestamp":"2024-06-01T18:06:17.586756Z"}]}
{"channel":"book","type":"update","data":[{"symbol":"ETH/EUR","bids":[],"asks":[{"price":3506.30,"qty":0.00000000},{"price":3506.98,"qty":0.01503034},{"price":3505.94,"qty":0.08552500}],"checksum":464783323,"timestamp":"2024-06-01T18:06:17.667407Z"}]}
{"channel":"book","type":"update","data":[{"symbol":"ETH/EUR","bids":[],"asks":[{"price":3505.61,"qty":0.00000000},{"price":3506.98,"qty":0.01503034}],"checksum":2799388422,"timestamp":"2024-06-01T18:06:17.753285Z"}]}
{"channel":"book","type":"update","data":[{"symbol":"ETH/EUR","bids":[],"asks":[{"price":3505.63,"qty":26.30022290}],"checksum":2052195275,"timestamp":"2024-06-01T18:06:17.758321Z"}]}
{"channel":"book","type":"update","data":[{"symbol":"ETH/EUR","bids":[{"price":3505.37,"qty":26.30214925}],"asks":[],"checksum":3540502469,"timestamp":"2024-06-01T18:06:17.758491Z"}]}
{"channel":"book","type":"update","data":[{"symbol":"ETH/EUR","bids":[{"price":3505.37,"qty":0.00000000},{"price":3504.94,"qty":1.35554034}],"asks":[],"checksum":2052195275,"timestamp":"2024-06-01T18:06:17.963156Z"}]}
{"channel":"book","type":"update","data":[{"symbol":"ETH/EUR","bids":[],"asks":[{"price":3505.70,"qty":26.29975377}],"checksum":1778841014,"timestamp":"2024-06-01T18:06:17.966805Z"}]}
{"channel":"book","type":"update","data":[{"symbol":"ETH/EUR","bids":[{"price":3505.35,"qty":26.30225471}],"asks":[],"checksum":2058122039,"timestamp":"2024-06-01T18:06:17.966923Z"}]}
{"channel":"book","type":"update","data":[{"symbol":"ETH/EUR","bids":[{"price":3505.52,"qty":0.00000000},{"price":3504.94,"qty":1.35554034},{"price":3505.36,"qty":0.03535688}],"asks":[],"checksum":2554895054,"timestamp":"2024-06-01T18:06:18.153035Z"}]}
{"channel":"book","type":"update","data":[{"symbol":"ETH/EUR","bids":[],"asks":[{"price":3506.80,"qty":0.01502991}],"checksum":2862662320,"timestamp":"2024-06-01T18:06:18.153134Z"}]}
{"channel":"book","type":"update","data":[{"symbol":"ETH/EUR","bids":[],"asks":[{"price":3505.63,"qty":0.00000000},{"price":3506.81,"qty":3.94500000}],"checksum":3413877765,"timestamp":"2024-06-01T18:06:18.223500Z"}]}
{"channel":"book","type":"update","data":[{"symbol":"ETH/EUR","bids":[],"asks":[{"price":3505.62,"qty":26.30030495}],"checksum":1415480119,"timestamp":"2024-06-01T18:06:18.229562Z"}]}
{"channel":"book","type":"update","data":[{"symbol":"ETH/EUR","bids":[],"asks":[{"price":3505.70,"qty":0.00000000},{"price":3506.81,"qty":3.94500000}],"checksum":1830534749,"timestamp":"2024-06-01T18:06:18.229598Z"}]}
{"channel":"book","type":"update","data":[{"symbol":"ETH/EUR","bids":[],"asks":[{"price":3505.69,"qty":26.29975974}],"checksum":3419052586,"timestamp":"2024-06-01T18:06:18.234647Z"}]}
{"channel":"book","type":"update","data":[{"symbol":"ETH/EUR","bids":[{"price":3505.35,"qty":0.00000000},{"price":3504.94,"qty":1.35554034}],"asks":[],"checksum":117886093,"timestamp":"2024-06-01T18:06:18.281752Z"}]}
{"channel":"book","type":"update","data":[{"symbol":"ETH/EUR","bids":[],"asks":[{"price":3505.62,"qty":0.00000000},{"price":3506.81,"qty":3.94500000}],"checksum":1909768057,"timestamp":"2024-06-01T18:06:18.281892Z"}]}
{"channel":"book","type":"update","data":[{"symbol":"ETH/EUR","bids":[],"asks":[{"price":3505.61,"qty":26.30035992}],"checksum":317088043,"timestamp":"2024-06-01T18:06:18.287123Z"}]}
{"channel":"book","type":"update","data":[{"symbol":"ETH/EUR","bids":[],"asks":[{"price":3505.69,"qty":0.00000000},{"price":3506.81,"qty":3.94500000}],"checksum":1358246773,"timestamp":"2024-06-01T18:06:18.287184Z"}]}
{"channel":"book","type":"update","data":[{"symbol":"ETH/EUR","bids":[],"asks":[{"price":3505.61,"qty":0.00000000},{"price":3506.85,"qty":1.05800000}],"checksum":2626863472,"timestamp":"2024-06-01T18:06:18.291589Z"}]}
{"channel":"book","type":"update","data":[{"symbol":"ETH/EUR","bids":[],"asks":[{"price":3505.85,"qty":27.89856884}],"checksum":646830340,"timestamp":"2024-06-01T18:06:18.294266Z"}]}
{"channel":"book","type":"update","data":[{"symbol":"ETH/EUR","bids":[],"asks":[{"price":3506.22,"qty":0.00000000},{"price":3506.99,"qty":3.01305282}],"checksum":2352902739,"timestamp":"2024-06-01T18:06:18.294337Z"}]}
{"channel":"book","type":"update","data":[{"symbol":"ETH/EUR","bids":[],"asks":[{"price":3505.85,"qty":1.60000000}],"checksum":2458854892,"timestamp":"2024-06-01T18:06:18.295801Z"}]}
{"channel":"book","type":"update","data":[{"symbol":"ETH/EUR","bids":[],"asks":[{"price":3505.84,"qty":26.29863449}],"checksum":256323091,"timestamp":"2024-06-01T18:06:18.299303Z"}]}
{"channel":"book","type":"update","data":[{"symbol":"ETH/EUR","bids":[{"price":3505.37,"qty":2.47000000}],"asks":[],"checksum":1368823431,"timestamp":"2024-06-01T18:06:18.311829Z"}]}
{"channel":"book","type":"update","data":[{"symbol":"ETH/EUR","bids":[],"asks":[{"price":3505.84,"qty":0.00000000},{"price":3506.99,"qty":3.01305282}],"checksum":3428752760,"timestamp":"2024-06-01T18:06:18.329838Z"}]}
{"channel":"book","type":"update","data":[{"symbol":"ETH/EUR","bids":[],"asks":[{"price":3505.58,"qty":26.30065307}],"checksum":1985260,"timestamp":"2024-06-01T18:06:18.408374Z"}]}
{"channel":"book","type":"update","data":[{"symbol":"ETH/EUR","bids":[],"asks":[{"price":3505.58,"qty":0.00000000},{"price":3506.99,"qty":3.01305282}],"checksum":3428752760,"timestamp":"2024-06-01T18:06:18.414164Z"}]}
{"channel":"book","type":"update","data":[{"symbol":"ETH/EUR","bids":[{"price":3505.37,"qty":0.00000000},{"price":3504.94,"qty":1.35554034}],"asks":[],"checksum":2458854892,"timestamp":"2024-06-01T18:06:18.422506Z"}]}
{"channel":"book","type":"update","data":[{"symbol":"ETH/EUR","bids":[],"asks":[{"price":3505.56,"qty":26.30075843}],"checksum":1448683802,"timestamp":"2024-06-01T18:06:18.480421Z"}]}
{"channel":"book","type":"update","data":[{"symbol":"ETH/EUR","bids":[],"asks":[{"price":3505.83,"qty":26.29870950}],"checksum":909650851,"timestamp":"2024-06-01T18:06:18.480464Z"}]}
{"channel":"book","type":"update","data":[{"symbol":"ETH/EUR","bids":[],"asks":[{"price":3505.56,"qty":0.00000000},{"price":3506.85,"qty":1.05800000}],"checksum":3713809751,"timestamp":"2024-06-01T18:06:18.560527Z"}]}
{"channel":"book","type":"update","data":[{"symbol":"ETH/EUR","bids":[],"asks":[{"price":3505.58,"qty":26.30063223}],"checksum":3272824569,"timestamp":"2024-06-01T18:06:18.565648Z"}]}
{"channel":"book","type":"update","data":[{"symbol":"ETH/EUR","bids":[],"asks":[{"price":3505.83,"qty":0.00000000},{"price":3506.85,"qty":1.05800000}],"checksum":1927291981,"timestamp":"2024-06-01T18:06:18.570532Z"}]}
{"channel":"book","type":"update","data":[{"symbol":"ETH/EUR","bids":[],"asks":[{"price":3505.58,"qty":0.00000000},{"price":3506.98,"qty":0.73169552}],"checksum":2961926205,"timestamp":"2024-06-01T18:06:18.704545Z"}]}
{"channel":"book","type":"update","data":[{"symbol":"ETH/EUR","bids":[],"asks":[{"price":3505.60,"qty":26.30044294}],"checksum":1844733897,"timestamp":"2024-06-01T18:06:18.709738Z"}]}
{"channel":"book","type":"update","data":[{"symbol":"ETH/EUR","bids":[],"asks":[{"price":3505.65,"qty":26.30009627}],"checksum":364595169,"timestamp":"2024-06-01T18:06:18.709857Z"}]}
{"channel":"book","type":"update","data":[{"symbol":"ETH/EUR","bids":[],"asks":[{"price":3505.65,"qty":0.00000000},{"price":3506.85,"qty":1.05800000}],"checksum":1844733897,"timestamp":"2024-06-01T18:06:18.715343Z"}]}
{"channel":"book","type":"update","data":[{"symbol":"ETH/EUR","bids":[],"asks":[{"price":3505.85,"qty":27.89858611}],"checksum":1054368439,"timestamp":"2024-06-01T18:06:18.719858Z"}]}
{"channel":"book","type":"update","data":[{"symbol":"ETH/EUR","bids":[],"asks":[{"price":3505.60,"qty":0.00000000},{"price":3506.98,"qty":0.73169552}],"checksum":2338617240,"timestamp":"2024-06-01T18:06:18.804869Z"}]}
{"channel":"book","type":"update","data":[{"symbol":"ETH/EUR","bids":[],"asks":[{"price":3505.85,"qty":1.60000000}],"checksum":2961926205,"timestamp":"2024-06-01T18:06:18.810146Z"}]}
{"channel":"book","type":"update","data":[{"symbol":"ETH/EUR","bids":[],"asks":[{"price":3505.59,"qty":26.30057971}],"checksum":220387738,"timestamp":"2024-06-01T18:06:18.810209Z"}]}
{"channel":"book","type":"update","data":[{"symbol":"ETH/EUR","bids":[],"asks":[{"price":3505.59,"qty":0.00000000},{"price":3506.98,"qty":0.73169552}],"checksum":2961926205,"timestamp":"2024-06-01T18:06:18.859225Z"}]}
{"channel":"book","type":"update","data":[{"symbol":"ETH/EUR","bids":[],"asks":[{"price":3505.58,"qty":26.30063934}],"checksum":2775860348,"timestamp":"2024-06-01T18:06:18.863872Z"}]}
{"channel":"book","type":"update","data":[{"symbol":"ETH/EUR","bids":[],"asks":[{"price":3506.80,"qty":4.15746694}],"checksum":337335900,"timestamp":"2024-06-01T18:06:19.027489Z"}]}
{"channel":"book","type":"update","data":[{"symbol":"ETH/EUR","bids":[],"asks":[{"price":3505.65,"qty":26.30010449}],"checksum":186305220,"timestamp":"2024-06-01T18:06:19.222861Z"}]}
{"channel":"book","type":"update","data":[{"symbol":"ETH/EUR","bids":[],"asks":[{"price":3505.84,"qty":26.29863449}],"checksum":2773647011,"timestamp":"2024-06-01T18:06:19.222901Z"}]}
{"channel":"book","type":"update","data":[{"symbol":"ETH/EUR","bids":[],"asks":[{"price":3506.80,"qty":4.14243703},{"price":3506.79,"qty":0.01502991}],"checksum":1865269388,"timestamp":"2024-06-01T18:06:19.255243Z"}]}
{"channel":"book","type":"update","data":[{"symbol":"ETH/EUR","bids":[{"price":3505.36,"qty":0.00000000},{"price":3504.88,"qty":26.30582933},{"price":3505.33,"qty":0.03535719}],"asks":[],"checksum":1538495595,"timestamp":"2024-06-01T18:06:19.255342Z"}]}
{"channel":"book","type":"update","data":[{"symbol":"ETH/EUR","bids":[],"asks":[{"price":3505.58,"qty":0.00000000},{"price":3506.80,"qty":4.14243703}],"checksum":4100513209,"timestamp":"2024-06-01T18:06:19.342974Z"}]}
{"channel":"book","type":"update","data":[{"symbol":"ETH/EUR","bids":[],"asks":[{"price":3505.65,"qty":0.00000000},{"price":3506.81,"qty":3.94500000}],"checksum":2079738253,"timestamp":"2024-06-01T18:06:19.349707Z"}]}
{"channel":"book","type":"update","data":[{"symbol":"ETH/EUR","bids":[],"asks":[{"price":3505.81,"qty":1.60000000}],"checksum":2887021250,"timestamp":"2024-06-01T18:06:19.352392Z"}]}
{"channel":"book","type":"update","data":[{"symbol":"ETH/EUR","bids":[],"asks":[{"price":3505.85,"qty":0.00000000},{"price":3506.81,"qty":3.94500000}],"checksum":184972583,"timestamp":"2024-06-01T18:06:19.352423Z"}]}
{"channel":"book","type":"update","data":[{"symbol":"ETH/EUR","bids":[],"asks":[{"price":3505.57,"qty":26.30069707}],"checksum":1159225974,"timestamp":"2024-06-01T18:06:19.354444Z"}]}
{"channel":"book","type":"update","data":[{"symbol":"ETH/EUR","bids":[{"price":3505.30,"qty":26.30262875}],"asks":[],"checksum":1642809696,"timestamp":"2024-06-01T18:06:19.354509Z"}]}
{"channel":"book","type":"update","data":[{"symbol":"ETH/EUR","bids":[],"asks":[{"price":3505.84,"qty":0.00000000},{"price":3506.81,"qty":3.94500000}],"checksum":3684023417,"timestamp":"2024-06-01T18:06:19.354549Z"}]}
{"channel":"book","type":"update","data":[{"symbol":"ETH/EUR","bids":[],"asks":[{"price":3505.57,"qty":0.00000000},{"price":3506.85,"qty":1.05800000}],"checksum":1964627341,"timestamp":"2024-06-01T18:06:19.359328Z"}]}
{"channel":"book","type":"update","data":[{"symbol":"ETH/EUR","bids":[],"asks":[{"price":3505.58,"qty":26.30061263}],"checksum":4053119701,"timestamp":"2024-06-01T18:06:19.404951Z"}]}
{"channel":"book","type":"update","data":[{"symbol":"ETH/EUR","bids":[],"asks":[{"price":3505.58,"qty":0.00000000},{"price":3506.85,"qty":1.05800000}],"checksum":1964627341,"timestamp":"2024-06-01T18:06:19.413880Z"}]}
{"channel":"book","type":"update","data":[{"symbol":"ETH/EUR","bids":[],"asks":[{"price":3505.80,"qty":26.29893454}],"checksum":228428844,"timestamp":"2024-06-01T18:06:19.463004Z"}]}
{"channel":"book","type":"update","data":[{"symbol":"ETH/EUR","bids":[],"asks":[{"price":3505.57,"qty":26.30069219}],"checksum":376169563,"timestamp":"2024-06-01T18:06:19.463113Z"}]}
{"channel":"book","type":"update","data":[{"symbol":"ETH/EUR","bids":[],"asks":[{"price":3505.57,"qty":0.00000000},{"price":3506.81,"qty":3.94500000}],"checksum":228428844,"timestamp":"2024-06-01T18:06:19.468729Z"}]}
{"channel":"book","type":"update","data":[{"symbol":"ETH/EUR","bids":[],"asks":[{"price":3505.57,"qty":26.30069062}],"checksum":2074206740,"timestamp":"2024-06-01T18:06:19.514028Z"}]}
{"channel":"book","type":"update","data":[{"symbol":"ETH/EUR","bids":[{"price":3505.41,"qty":2.38000000}],"asks":[],"checksum":445854936,"timestamp":"2024-06-01T18:06:19.625221Z"}]}
{"channel":"book","type":"update","data":[{"symbol":"ETH/EUR","bids":[{"price":3505.30,"qty":0.00000000},{"price":3505.00,"qty":0.00220000}],"asks":[],"checksum":2377334534,"timestamp":"2024-06-01T18:06:19.635814Z"}]}
{"channel":"book","type":"update","data":[{"symbol":"ETH/EUR","bids":[],"asks":[{"price":3505.57,"qty":0.00000000},{"price":3506.81,"qty":3.94500000}],"checksum":1838978886,"timestamp":"2024-06-01T18:06:19.635930Z"}]}
{"channel":"book","type":"update","data":[{"symbol":"ETH/EUR","bids":[],"asks":[{"price":3505.59,"qty":26.30054603}],"checksum":3512550369,"timestamp":"2024-06-01T18:06:19.641211Z"}]}
{"channel":"book","type":"update","data":[{"symbol":"ETH/EUR","bids":[],"asks":[{"price":3505.59,"qty":0.00000000},{"price":3506.81,"qty":3.94500000}],"checksum":1838978886,"timestamp":"2024-06-01T18:06:19.768145Z"}]}
{"channel":"book","type":"update","data":[{"symbol":"ETH/EUR","bids":[],"asks":[{"price":3505.67,"qty":26.29998345}],"checksum":2543457761,"timestamp":"2024-06-01T18:06:19.775178Z"}]}
{"channel":"book","type":"update","data":[{"symbol":"ETH/EUR","bids":[],"asks":[{"price":3505.58,"qty":26.30063016}],"checksum":2809296214,"timestamp":"2024-06-01T18:06:19.775204Z"}]}
{"channel":"book","type":"update","data":[{"symbol":"ETH/EUR","bids":[],"asks":[{"price":3505.67,"qty":0.00000000},{"price":3506.80,"qty":4.14243703}],"checksum":3598710353,"timestamp":"2024-06-01T18:06:19.780655Z"}]}
{"channel":"book","type":"update","data":[{"symbol":"ETH/EUR","bids":[],"asks":[{"price":3505.58,"qty":26.26733016}],"checksum":2606309815,"timestamp":"2024-06-01T18:06:19.796871Z"}]}
{"channel":"book","type":"update","data":[{"symbol":"ETH/EUR","bids":[],"asks":[{"price":3505.58,"qty":0.00000000},{"price":3506.81,"qty":3.94500000}],"checksum":1838978886,"timestamp":"2024-06-01T18:06:19.814989Z"}]}
{"channel":"book","type":"update","data":[{"symbol":"ETH/EUR","bids":[{"price":3505.41,"qty":0.00000000},{"price":3504.94,"qty":1.35554034}],"asks":[],"checksum":893960994,"timestamp":"2024-06-01T18:06:19.880543Z"}]}
{"channel":"book","type":"update","data":[{"symbol":"ETH/EUR","bids":[],"asks":[{"price":3505.80,"qty":0.00000000},{"price":3506.85,"qty":1.05800000}],"checksum":3067658346,"timestamp":"2024-06-01T18:06:20.235919Z"}]}
{"channel":"book","type":"update","data":[{"symbol":"ETH/EUR","bids":[],"asks":[{"price":3505.55,"qty":26.30088046}],"checksum":2021093244,"timestamp":"2024-06-01T18:06:20.244104Z"}]}
{"channel":"book","type":"update","data":[{"symbol":"ETH/EUR","bids":[],"asks":[{"price":3505.79,"qty":26.29900956}],"checksum":1235334010,"timestamp":"2024-06-01T18:06:20.244158Z"}]}
{"channel":"book","type":"update","data":[{"symbol":"ETH/EUR","bids":[],"asks":[{"price":3505.80,"qty":26.29893454}],"checksum":3330067259,"timestamp":"2024-06-01T18:06:20.244254Z"}]}
{"channel":"book","type":"update","data":[{"symbol":"ETH/EUR","bids":[{"price":3505.32,"qty":0.00000000},{"price":3504.88,"qty":26.30582933}],"asks":[],"checksum":802916394,"timestamp":"2024-06-01T18:06:20.251411Z"}]}
{"channel":"book","type":"update","data":[{"symbol":"ETH/EUR","bids":[],"asks":[{"price":3505.80,"qty":0.00000000},{"price":3506.80,"qty":4.14243703}],"checksum":2556919997,"timestamp":"2024-06-01T18:06:20.252693Z"}]}
{"channel":"book","type":"update","data":[{"symbol":"ETH/EUR","bids":[],"asks":[{"price":3505.55,"qty":0.00000000},{"price":3506.81,"qty":3.94500000}],"checksum":2376597324,"timestamp":"2024-06-01T18:06:20.252795Z"}]}
{"channel":"book","type":"update","data":[{"symbol":"ETH/EUR","bids":[],"asks":[{"price":3505.79,"qty":0.00000000},{"price":3506.85,"qty":1.05800000}],"checksum":464080147,"timestamp":"2024-06-01T18:06:20.255662Z"}]}
{"channel":"book","type":"update","data":[{"symbol":"ETH/EUR","bids":[{"price":3505.03,"qty":0.00000000},{"price":3504.80,"qty":0.00220000}],"asks":[],"checksum":820857925,"timestamp":"2024-06-01T18:06:20.255765Z"}]}
{"channel":"book","type":"update","data":[{"symbol":"ETH/EUR","bids":[],"asks":[{"price":3506.81,"qty":0.00000000},{"price":3506.97,"qty":50.96915548},{"price":3506.28,"qty":3.94500000}],"checksum":4197863565,"timestamp":"2024-06-01T18:06:20.258788Z"}]}
{"channel":"book","type":"update","data":[{"symbol":"ETH/EUR","bids":[{"price":3504.94,"qty":0.00000000},{"price":3504.65,"qty":0.84644082}],"asks":[],"checksum":1503004630,"timestamp":"2024-06-01T18:06:20.279111Z"}]}
{"channel":"book","type":"update","data":[{"symbol":"ETH/EUR","bids":[{"price":3505.33,"qty":0.00000000},{"price":3504.50,"qty":0.00220000},{"price":3505.32,"qty":0.03535774}],"asks":[],"checksum":3790845409,"timestamp":"2024-06-01T18:06:20.298956Z"}]}
{"channel":"book","type":"update","data":[{"symbol":"ETH/EUR","bids":[],"asks":[{"price":3505.52,"qty":26.30105823}],"checksum":3300411558,"timestamp":"2024-06-01T18:06:20.300376Z"}]}
{"channel":"book","type":"update","data":[{"symbol":"ETH/EUR","bids":[],"asks":[{"price":3505.80,"qty":0.72912968}],"checksum":904104015,"timestamp":"2024-06-01T18:06:20.304008Z"}]}
{"channel":"book","type":"update","data":[{"symbol":"ETH/EUR","bids":[{"price":3504.66,"qty":0.61211200}],"asks":[],"checksum":169904897,"timestamp":"2024-06-01T18:06:20.336060Z"}]}
{"channel":"book","type":"update","data":[{"symbol":"ETH/EUR","bids":[],"asks":[{"price":3505.98,"qty":0.00000000},{"price":3506.80,"qty":4.14243703}],"checksum":3150751228,"timestamp":"2024-06-01T18:06:20.337797Z"}]}
{"channel":"book","type":"update","data":[{"symbol":"ETH/EUR","bids":[],"asks":[{"price":3505.52,"qty":0.00000000},{"price":3506.85,"qty":1.05800000}],"checksum":2655727405,"timestamp":"2024-06-01T18:06:20.339703Z"}]}
{"channel":"book","type":"update","data":[{"symbol":"ETH/EUR","bids":[],"asks":[{"price":3506.37,"qty":0.00000000},{"price":3506.97,"qty":50.96915548}],"checksum":2184591405,"timestamp":"2024-06-01T18:06:20.342884Z"}]}
{"channel":"book","type":"update","data":[{"symbol":"ETH/EUR","bids":[],"asks":[{"price":3506.96,"qty":3.94900000}],"checksum":2151845107,"timestamp":"2024-06-01T18:06:20.344087Z"}]}
{"channel":"book","type":"update","data":[{"symbol":"ETH/EUR","bids":[],"asks":[{"price":3506.75,"qty":40.28423830}],"checksum":2641964310,"timestamp":"2024-06-01T18:06:20.346632Z"}]}
{"channel":"book","type":"update","data":[{"symbol":"ETH/EUR","bids":[],"asks":[{"price":3506.74,"qty":0.52520000}],"checksum":1137033243,"timestamp":"2024-06-01T18:06:20.347420Z"}]}
{"channel":"book","type":"update","data":[{"symbol":"ETH/EUR","bids":[],"asks":[{"price":3506.79,"qty":0.00000000},{"price":3506.96,"qty":3.94900000},{"price":3506.27,"qty":0.01501642}],"checksum":184973351,"timestamp":"2024-06-01T18:06:20.415897Z"}]}
{"channel":"book","type":"update","data":[{"symbol":"ETH/EUR","bids":[],"asks":[{"price":3505.51,"qty":26.30111017}],"checksum":1437355106,"timestamp":"2024-06-01T18:06:20.445355Z"}]}
{"channel":"book","type":"update","data":[{"symbol":"ETH/EUR","bids":[{"price":3505.14,"qty":0.00000000},{"price":3504.65,"qty":0.84644082},{"price":3504.75,"qty":0.08553800}],"asks":[],"checksum":1069931813,"timestamp":"2024-06-01T18:06:20.476515Z"}]}
{"channel":"book","type":"update","data":[{"symbol":"ETH/EUR","bids":[{"price":3504.94,"qty":26.30537320}],"asks":[],"checksum":2056652254,"timestamp":"2024-06-01T18:06:20.527502Z"}]}
{"channel":"book","type":"update","data":[{"symbol":"ETH/EUR","bids":[{"price":3505.32,"qty":0.00000000},{"price":3504.66,"qty":0.61211200},{"price":3504.89,"qty":0.03536208}],"asks":[],"checksum":3631342863,"timestamp":"2024-06-01T18:06:20.543018Z"}]}
{"channel":"book","type":"update","data":[{"symbol":"ETH/EUR","bids":[{"price":3504.94,"qty":0.00000000},{"price":3504.66,"qty":0.61211200}],"asks":[],"checksum":2477804285,"timestamp":"2024-06-01T18:06:20.628874Z"}]}
{"channel":"book","type":"update","data":[{"symbol":"ETH/EUR","bids":[],"asks":[{"price":3505.51,"qty":52.60222034}],"checksum":2341686720,"timestamp":"2024-06-01T18:06:20.632930Z"}]}
{"channel":"book","type":"update","data":[{"symbol":"ETH/EUR","bids":[{"price":3504.92,"qty":26.30550729}],"asks":[],"checksum":2421920889,"timestamp":"2024-06-01T18:06:20.633109Z"}]}
{"channel":"book","type":"update","data":[{"symbol":"ETH/EUR","bids":[{"price":3504.92,"qty":0.00000000},{"price":3504.67,"qty":26.30740400}],"asks":[],"checksum":3810054760,"timestamp":"2024-06-01T18:06:20.820851Z"}]}
{"channel":"book","type":"update","data":[{"symbol":"ETH/EUR","bids":[{"price":3504.93,"qty":26.30543792}],"asks":[],"checksum":3251319531,"timestamp":"2024-06-01T18:06:20.826930Z"}]}
{"channel":"book","type":"update","data":[{"symbol":"ETH/EUR","bids":[{"price":3504.93,"qty":0.00000000},{"price":3504.67,"qty":26.30740400}],"asks":[],"checksum":3810054760,"timestamp":"2024-06-01T18:06:20.908394Z"}]}
{"channel":"book","type":"update","data":[{"symbol":"ETH/EUR","bids":[{"price":3504.91,"qty":26.30557645}],"asks":[],"checksum":4085687741,"timestamp":"2024-06-01T18:06:20.912383Z"}]}
{"channel":"book","type":"update","data":[{"symbol":"ETH/EUR","bids":[{"price":3504.88,"qty":0.00000000},{"price":3504.67,"qty":26.30740400}],"asks":[],"checksum":1794166627,"timestamp":"2024-06-01T18:06:20.923469Z"}]}
{"channel":"book","type":"update","data":[{"symbol":"ETH/EUR","bids":[{"price":3504.91,"qty":0.00000000},{"price":3504.66,"qty":0.61211200}],"asks":[],"checksum":3119606658,"timestamp":"2024-06-01T18:06:20.923606Z"}]}
{"channel":"book","type":"update","data":[{"symbol":"ETH/EUR","bids":[],"asks":[{"price":3506.75,"qty":0.84644082}],"checksum":4060690302,"timestamp":"2024-06-01T18:06:20.923655Z"}]}
{"channel":"book","type":"update","data":[{"symbol":"ETH/EUR","bids":[],"asks":[{"price":3505.51,"qty":78.90333051}],"checksum":722012948,"timestamp":"2024-06-01T18:06:20.932735Z"}]}
{"channel":"book","type":"update","data":[{"symbol":"ETH/EUR","bids":[],"asks":[{"price":3505.51,"qty":79.63246019}],"checksum":3164034879,"timestamp":"2024-06-01T18:06:20.936780Z"}]}
{"channel":"book","type":"update","data":[{"symbol":"ETH/EUR","bids":[{"price":3504.67,"qty":0.00000000},{"price":3504.65,"qty":0.84644082}],"asks":[],"checksum":671446727,"timestamp":"2024-06-01T18:06:20.939839Z"}]}
{"channel":"book","type":"update","data":[{"symbol":"ETH/EUR","bids":[{"price":3504.80,"qty":26.30861311}],"asks":[],"checksum":317898372,"timestamp":"2024-06-01T18:06:20.967076Z"}]}
{"channel":"book","type":"update","data":[{"symbol":"ETH/EUR","bids":[{"price":3504.78,"qty":26.30656050}],"asks":[],"checksum":2565202603,"timestamp":"2024-06-01T18:06:21.018964Z"}]}
{"channel":"book","type":"update","data":[{"symbol":"ETH/EUR","bids":[{"price":3505.31,"qty":0.00000000},{"price":3504.65,"qty":0.84644082}],"asks":[],"checksum":3251254703,"timestamp":"2024-06-01T18:06:21.022817Z"}]}
{"channel":"book","type":"update","data":[{"symbol":"ETH/EUR","bids":[],"asks":[{"price":3505.80,"qty":0.00000000},{"price":3506.85,"qty":1.05800000}],"checksum":503843336,"timestamp":"2024-06-01T18:06:21.027444Z"}]}
{"channel":"book","type":"update","data":[{"symbol":"ETH/EUR","bids":[],"asks":[{"price":3505.67,"qty":26.29995206}],"checksum":710750007,"timestamp":"2024-06-01T18:06:21.252462Z"}]}
{"channel":"book","type":"update","data":[{"symbol":"ETH/EUR","bids":[],"asks":[{"price":3505.81,"qty":0.00000000},{"price":3506.85,"qty":1.05800000}],"checksum":1589931727,"timestamp":"2024-06-01T18:06:21.255060Z"}]}
{"channel":"book","type":"update","data":[{"symbol":"ETH/EUR","bids":[],"asks":[{"price":3505.51,"qty":81.23246019}],"checksum":2797818204,"timestamp":"2024-06-01T18:06:21.255264Z"}]}
{"channel":"book","type":"update","data":[{"symbol":"ETH/EUR","bids":[],"asks":[{"price":3506.29,"qty":0.00000000},{"price":3506.96,"qty":3.94900000}],"checksum":691361533,"timestamp":"2024-06-01T18:06:21.256003Z"}]}
{"channel":"book","type":"update","data":[{"symbol":"ETH/EUR","bids":[],"asks":[{"price":3506.73,"qty":0.13852327}],"checksum":3518870101,"timestamp":"2024-06-01T18:06:21.263790Z"}]}
{"channel":"book","type":"update","data":[{"symbol":"ETH/EUR","bids":[],"asks":[{"price":3506.74,"qty":0.82779333}],"checksum":3023632695,"timestamp":"2024-06-01T18:06:21.263945Z"}]}
{"channel":"book","type":"update","data":[{"symbol":"ETH/EUR","bids":[{"price":3505.30,"qty":0.10520272}],"asks":[],"checksum":4031777649,"timestamp":"2024-06-01T18:06:21.305999Z"}]}
{"channel":"book","type":"update","data":[{"symbol":"ETH/EUR","bids":[],"asks":[{"price":3506.49,"qty":39.44064431}],"checksum":1609855894,"timestamp":"2024-06-01T18:06:21.356273Z"}]}
{"channel":"book","type":"update","data":[{"symbol":"ETH/EUR","bids":[],"asks":[{"price":3505.66,"qty":0.65393184}],"checksum":943484476,"timestamp":"2024-06-01T18:06:21.359661Z"}]}
{"channel":"book","type":"update","data":[{"symbol":"ETH/EUR","bids":[{"price":3504.80,"qty":0.00220000}],"asks":[],"checksum":3560038077,"timestamp":"2024-06-01T18:06:21.387093Z"}]}
{"channel":"book","type":"update","data":[{"symbol":"ETH/EUR","bids":[],"asks":[{"price":3505.51,"qty":84.19746019}],"checksum":3951291973,"timestamp":"2024-06-01T18:06:21.388131Z"}]}
{"channel":"book","type":"update","data":[{"symbol":"ETH/EUR","bids":[{"price":3504.78,"qty":0.00000000},{"price":3504.65,"qty":0.84644082}],"asks":[],"checksum":3634969712,"timestamp":"2024-06-01T18:06:21.414637Z"}]}
{"channel":"book","type":"update","data":[{"symbol":"ETH/EUR","bids":[],"asks":[{"price":3506.27,"qty":0.00000000},{"price":3506.85,"qty":1.05800000},{"price":3506.48,"qty":0.01501411}],"checksum":2423344077,"timestamp":"2024-06-01T18:06:21.423437Z"}]}
{"channel":"book","type":"update","data":[{"symbol":"ETH/EUR","bids":[{"price":3504.89,"qty":0.00000000},{"price":3504.57,"qty":26.30813354},{"price":3504.79,"qty":0.03537609}],"asks":[],"checksum":4164198262,"timestamp":"2024-06-01T18:06:21.435531Z"}]}
