{"channel":"book","type":"snapshot","data":[{"symbol":"ETH/GBP","bids":[{"price":2981.11,"qty":6.57921181},{"price":2980.96,"qty":0.31000000},{"price":2980.93,"qty":0.08553300},{"price":2980.65,"qty":13.16044122},{"price":2980.49,"qty":1.31568759},{"price":2980.15,"qty":5.37308502},{"price":2979.79,"qty":1.31642568},{"price":2978.88,"qty":1.31682781},{"price":2978.60,"qty":0.27443647},{"price":2978.12,"qty":1.33500000}],"asks":[{"price":2981.73,"qty":13.15571278},{"price":2981.74,"qty":4.65910336},{"price":2982.27,"qty":0.31000000},{"price":2982.39,"qty":0.08550800},{"price":2982.57,"qty":1.31520257},{"price":2983.08,"qty":24.18562076},{"price":2983.09,"qty":15.45274662},{"price":2983.16,"qty":1.31494178},{"price":2983.61,"qty":1.31474323},{"price":2983.72,"qty":1.00000000}],"checksum":1163814451}]}
{"channel":"book","type":"update","data":[{"symbol":"ETH/GBP","bids":[],"asks":[{"price":2981.33,"qty":6.57876070}],"checksum":1168906896,"timestamp":"2024-06-01T18:05:56.488695Z"}]}
{"channel":"book","type":"update","data":[{"symbol":"ETH/GBP","bids":[{"price":2981.11,"qty":0.00000000},{"price":2978.11,"qty":1.31717030}],"asks":[],"checksum":2148959875,"timestamp":"2024-06-01T18:05:56.592703Z"}]}
{"channel":"book","type":"update","data":[{"symbol":"ETH/GBP","bids":[{"price":2981.12,"qty":6.57920063}],"asks":[],"checksum":2168561354,"timestamp":"2024-06-01T18:05:56.599432Z"}]}
{"channel":"book","type":"update","data":[{"symbol":"ETH/GBP","bids":[],"asks":[{"price":2981.33,"qty":0.00000000},{"price":2983.72,"qty":1.00000000}],"checksum":2176049769,"timestamp":"2024-06-01T18:05:56.604972Z"}]}
{"channel":"book","type":"update","data":[{"symbol":"ETH/GBP","bids":[{"price":2981.12,"qty":0.00000000},{"price":2978.11,"qty":1.31717030}],"asks":[],"checksum":2162489888,"timestamp":"2024-06-01T18:05:56.605019Z"}]}
{"channel":"book","type":"update","data":[{"symbol":"ETH/GBP","bids":[],"asks":[{"price":2981.34,"qty":6.57873044}],"checksum":3978075788,"timestamp":"2024-06-01T18:05:56.609727Z"}]}
{"channel":"book","type":"update","data":[{"symbol":"ETH/GBP","bids":[],"asks":[{"price":2981.34,"qty":0.00000000},{"price":2983.72,"qty":1.00000000}],"checksum":2162489888,"timestamp":"2024-06-01T18:05:56.626041Z"}]}
{"channel":"book","type":"update","data":[{"symbol":"ETH/GBP","bids":[{"price":2981.10,"qty":6.57923945}],"asks":[],"checksum":875126898,"timestamp":"2024-06-01T18:05:56.729111Z"}]}
{"channel":"book","type":"update","data":[{"symbol":"ETH/GBP","bids":[],"asks":[{"price":2981.33,"qty":6.57875514}],"checksum":2531141121,"timestamp":"2024-06-01T18:05:56.729216Z"}]}
{"channel":"book","type":"update","data":[{"symbol":"ETH/GBP","bids":[{"price":2981.10,"qty":6.57752015}],"asks":[],"checksum":3556219644,"timestamp":"2024-06-01T18:05:56.970689Z"}]}
{"channel":"book","type":"update","data":[{"symbol":"ETH/GBP","bids":[],"asks":[{"price":2981.33,"qty":0.00000000},{"price":2983.72,"qty":1.00000000}],"checksum":1895881871,"timestamp":"2024-06-01T18:05:57.027854Z"}]}
{"channel":"book","type":"update","data":[{"symbol":"ETH/GBP","bids":[{"price":2981.10,"qty":0.00000000},{"price":2978.11,"qty":1.31717030}],"asks":[],"checksum":2162489888,"timestamp":"2024-06-01T18:05:57.028006Z"}]}
{"channel":"book","type":"update","data":[{"symbol":"ETH/GBP","bids":[],"asks":[{"price":2981.72,"qty":0.10990113}],"checksum":3070607935,"timestamp":"2024-06-01T18:05:57.032398Z"}]}
{"channel":"book","type":"update","data":[{"symbol":"ETH/GBP","bids":[{"price":2980.65,"qty":0.00000000},{"price":2977.74,"qty":0.21600000}],"asks":[],"checksum":2869494402,"timestamp":"2024-06-01T18:05:57.032914Z"}]}
{"channel":"book","type":"update","data":[{"symbol":"ETH/GBP","bids":[{"price":2980.70,"qty":13.16023491}],"asks":[],"checksum":1902183977,"timestamp":"2024-06-01T18:05:57.036717Z"}]}
{"channel":"book","type":"update","data":[{"symbol":"ETH/GBP","bids":[],"asks":[{"price":2981.35,"qty":6.57870317}],"checksum":2230796811,"timestamp":"2024-06-01T18:05:57.036782Z"}]}
{"channel":"book","type":"update","data":[{"symbol":"ETH/GBP","bids":[{"price":2981.13,"qty":6.57917138}],"asks":[],"checksum":2685335817,"timestamp":"2024-06-01T18:05:57.036860Z"}]}
{"channel":"book","type":"update","data":[{"symbol":"ETH/GBP","bids":[],"asks":[{"price":2981.72,"qty":0.00000000},{"price":2983.61,"qty":1.31474323}],"checksum":3983227472,"timestamp":"2024-06-01T18:05:57.041633Z"}]}
{"channel":"book","type":"update","data":[{"symbol":"ETH/GBP","bids":[],"asks":[{"price":2981.73,"qty":0.00000000},{"price":2983.72,"qty":1.00000000}],"checksum":3935849505,"timestamp":"2024-06-01T18:05:57.299361Z"}]}
{"channel":"book","type":"update","data":[{"symbol":"ETH/GBP","bids":[{"price":2981.13,"qty":0.00000000},{"price":2978.11,"qty":1.31717030}],"asks":[],"checksum":3462526755,"timestamp":"2024-06-01T18:05:57.299454Z"}]}
{"channel":"book","type":"update","data":[{"symbol":"ETH/GBP","bids":[{"price":2981.12,"qty":6.57918579}],"asks":[],"checksum":93008031,"timestamp":"2024-06-01T18:05:57.304744Z"}]}
{"channel":"book","type":"update","data":[{"symbol":"ETH/GBP","bids":[],"asks":[{"price":2981.79,"qty":13.15547053}],"checksum":2937300425,"timestamp":"2024-06-01T18:05:57.304828Z"}]}
{"channel":"book","type":"update","data":[{"symbol":"ETH/GBP","bids":[],"asks":[{"price":2983.08,"qty":0.00000000},{"price":2983.72,"qty":1.00000000}],"checksum":559022101,"timestamp":"2024-06-01T18:05:57.307208Z"}]}
{"channel":"book","type":"update","data":[{"symbol":"ETH/GBP","bids":[],"asks":[{"price":2981.74,"qty":0.00000000},{"price":2983.92,"qty":0.94850883}],"checksum":3571592032,"timestamp":"2024-06-01T18:05:57.307326Z"}]}
{"channel":"book","type":"update","data":[{"symbol":"ETH/GBP","bids":[],"asks":[{"price":2983.08,"qty":23.77351303}],"checksum":1810919479,"timestamp":"2024-06-01T18:05:57.309208Z"}]}
{"channel":"book","type":"update","data":[{"symbol":"ETH/GBP","bids":[],"asks":[{"price":2981.35,"qty":0.00000000},{"price":2983.92,"qty":0.94850883}],"checksum":272129120,"timestamp":"2024-06-01T18:05:57.329504Z"}]}
{"channel":"book","type":"update","data":[{"symbol":"ETH/GBP","bids":[],"asks":[{"price":2981.78,"qty":0.10990113}],"checksum":3223923754,"timestamp":"2024-06-01T18:05:57.333996Z"}]}
{"channel":"book","type":"update","data":[{"symbol":"ETH/GBP","bids":[],"asks":[{"price":2981.34,"qty":6.57872199}],"checksum":4178049080,"timestamp":"2024-06-01T18:05:57.334026Z"}]}
{"channel":"book","type":"update","data":[{"symbol":"ETH/GBP","bids":[],"asks":[{"price":2981.79,"qty":0.00000000},{"price":2983.72,"qty":1.00000000}],"checksum":3687598764,"timestamp":"2024-06-01T18:05:57.334163Z"}]}
{"channel":"book","type":"update","data":[{"symbol":"ETH/GBP","bids":[],"asks":[{"price":2981.78,"qty":0.00000000},{"price":2983.92,"qty":0.94850883}],"checksum":3667245056,"timestamp":"2024-06-01T18:05:57.338189Z"}]}
{"channel":"book","type":"update","data":[{"symbol":"ETH/GBP","bids":[{"price":2981.12,"qty":0.00000000},{"price":2978.11,"qty":1.31717030}],"asks":[],"checksum":293568444,"timestamp":"2024-06-01T18:05:57.353722Z"}]}
{"channel":"book","type":"update","data":[{"symbol":"ETH/GBP","bids":[],"asks":[{"price":2981.34,"qty":0.00000000},{"price":2984.26,"qty":1.61244212}],"checksum":1259197173,"timestamp":"2024-06-01T18:05:57.403796Z"}]}
{"channel":"book","type":"update","data":[{"symbol":"ETH/GBP","bids":[],"asks":[{"price":2982.26,"qty":0.10990113}],"checksum":97360407,"timestamp":"2024-06-01T18:05:57.408934Z"}]}
{"channel":"book","type":"update","data":[{"symbol":"ETH/GBP","bids":[{"price":2980.97,"qty":6.57952657}],"asks":[],"checksum":1178710242,"timestamp":"2024-06-01T18:05:57.409550Z"}]}
{"channel":"book","type":"update","data":[{"symbol":"ETH/GBP","bids":[{"price":2980.96,"qty":0.00000000},{"price":2978.11,"qty":1.31717030}],"asks":[],"checksum":3834005270,"timestamp":"2024-06-01T18:05:57.412481Z"}]}
{"channel":"book","type":"update","data":[{"symbol":"ETH/GBP","bids":[{"price":2981.06,"qty":0.31000000}],"asks":[],"checksum":1190670909,"timestamp":"2024-06-01T18:05:57.412616Z"}]}
{"channel":"book","type":"update","data":[{"symbol":"ETH/GBP","bids":[{"price":2980.97,"qty":0.00000000},{"price":2978.11,"qty":1.31717030}],"asks":[],"checksum":2319483416,"timestamp":"2024-06-01T18:05:57.413843Z"}]}
{"channel":"book","type":"update","data":[{"symbol":"ETH/GBP","bids":[],"asks":[{"price":2981.34,"qty":6.57873317}],"checksum":3035206888,"timestamp":"2024-06-01T18:05:57.462567Z"}]}
{"channel":"book","type":"update","data":[{"symbol":"ETH/GBP","bids":[],"asks":[{"price":2982.26,"qty":0.00000000},{"price":2983.92,"qty":0.94850883}],"checksum":363068336,"timestamp":"2024-06-01T18:05:57.466834Z"}]}
{"channel":"book","type":"update","data":[{"symbol":"ETH/GBP","bids":[],"asks":[{"price":2981.34,"qty":0.00000000},{"price":2984.26,"qty":1.61244212}],"checksum":3296774906,"timestamp":"2024-06-01T18:05:57.484420Z"}]}
{"channel":"book","type":"update","data":[{"symbol":"ETH/GBP","bids":[{"price":2980.70,"qty":0.00000000},{"price":2977.74,"qty":0.21600000}],"asks":[],"checksum":3328528428,"timestamp":"2024-06-01T18:05:57.487686Z"}]}
{"channel":"book","type":"update","data":[{"symbol":"ETH/GBP","bids":[],"asks":[{"price":2982.26,"qty":0.10990113}],"checksum":1821969109,"timestamp":"2024-06-01T18:05:57.488395Z"}]}
{"channel":"book","type":"update","data":[{"symbol":"ETH/GBP","bids":[{"price":2980.64,"qty":13.16050472}],"asks":[],"checksum":2308880530,"timestamp":"2024-06-01T18:05:57.493273Z"}]}
{"channel":"book","type":"update","data":[{"symbol":"ETH/GBP","bids":[],"asks":[{"price":2982.25,"qty":13.15342770}],"checksum":351307181,"timestamp":"2024-06-01T18:05:57.527797Z"}]}
{"channel":"book","type":"update","data":[{"symbol":"ETH/GBP","bids":[{"price":2981.08,"qty":6.57927856}],"asks":[],"checksum":3803176115,"timestamp":"2024-06-01T18:05:57.527888Z"}]}
{"channel":"book","type":"update","data":[{"symbol":"ETH/GBP","bids":[],"asks":[{"price":2982.27,"qty":0.00000000},{"price":2983.92,"qty":0.94850883}],"checksum":3844942478,"timestamp":"2024-06-01T18:05:57.530623Z"}]}
{"channel":"book","type":"update","data":[{"symbol":"ETH/GBP","bids":[],"asks":[{"price":2982.20,"qty":0.31000000}],"checksum":846882019,"timestamp":"2024-06-01T18:05:57.530767Z"}]}
{"channel":"book","type":"update","data":[{"symbol":"ETH/GBP","bids":[],"asks":[{"price":2982.26,"qty":0.00000000},{"price":2983.92,"qty":0.94850883}],"checksum":4148106674,"timestamp":"2024-06-01T18:05:57.531555Z"}]}
{"channel":"book","type":"update","data":[{"symbol":"ETH/GBP","bids":[],"asks":[{"price":2982.25,"qty":0.00000000},{"price":2984.26,"qty":1.61244212}],"checksum":111099546,"timestamp":"2024-06-01T18:05:57.533040Z"}]}
{"channel":"book","type":"update","data":[{"symbol":"ETH/GBP","bids":[{"price":2981.06,"qty":0.00000000},{"price":2978.11,"qty":1.31717030}],"asks":[],"checksum":528653476,"timestamp":"2024-06-01T18:05:57.535802Z"}]}
{"channel":"book","type":"update","data":[{"symbol":"ETH/GBP","bids":[{"price":2981.09,"qty":0.31000000}],"asks":[],"checksum":2091120207,"timestamp":"2024-06-01T18:05:57.536245Z"}]}
{"channel":"book","type":"update","data":[{"symbol":"ETH/GBP","bids":[{"price":2981.08,"qty":0.00000000},{"price":2978.11,"qty":1.31717030}],"asks":[],"checksum":1551626587,"timestamp":"2024-06-01T18:05:57.538556Z"}]}
{"channel":"book","type":"update","data":[{"symbol":"ETH/GBP","bids":[],"asks":[{"price":2982.19,"qty":6.57684418}],"checksum":2339599089,"timestamp":"2024-06-01T18:05:57.585384Z"}]}
{"channel":"book","type":"update","data":[{"symbol":"ETH/GBP","bids":[],"asks":[{"price":2982.20,"qty":0.00000000},{"price":2984.26,"qty":1.61244212}],"checksum":3624463772,"timestamp":"2024-06-01T18:05:57.587972Z"}]}
{"channel":"book","type":"update","data":[{"symbol":"ETH/GBP","bids":[],"asks":[{"price":2982.13,"qty":0.31000000}],"checksum":3026260434,"timestamp":"2024-06-01T18:05:57.588084Z"}]}
{"channel":"book","type":"update","data":[{"symbol":"ETH/GBP","bids":[],"asks":[{"price":2982.19,"qty":0.00000000},{"price":2984.26,"qty":1.61244212}],"checksum":1172856270,"timestamp":"2024-06-01T18:05:57.590243Z"}]}
{"channel":"book","type":"update","data":[{"symbol":"ETH/GBP","bids":[{"price":2981.06,"qty":6.57932791}],"asks":[],"checksum":3322143602,"timestamp":"2024-06-01T18:05:57.645686Z"}]}
{"channel":"book","type":"update","data":[{"symbol":"ETH/GBP","bids":[{"price":2981.06,"qty":0.00000000},{"price":2978.11,"qty":1.31717030}],"asks":[],"checksum":1172856270,"timestamp":"2024-06-01T18:05:57.649837Z"}]}
{"channel":"book","type":"update","data":[{"symbol":"ETH/GBP","bids":[],"asks":[{"price":2981.71,"qty":13.15583047}],"checksum":1598223880,"timestamp":"2024-06-01T18:05:57.772133Z"}]}
{"channel":"book","type":"update","data":[{"symbol":"ETH/GBP","bids":[{"price":2981.05,"qty":6.57935381}],"asks":[],"checksum":1087791994,"timestamp":"2024-06-01T18:05:57.772186Z"}]}
{"channel":"book","type":"update","data":[{"symbol":"ETH/GBP","bids":[],"asks":[{"price":2981.28,"qty":6.57886645}],"checksum":2042525797,"timestamp":"2024-06-01T18:05:57.772320Z"}]}
{"channel":"book","type":"update","data":[{"symbol":"ETH/GBP","bids":[{"price":2981.09,"qty":0.00000000},{"price":2978.11,"qty":1.31717030}],"asks":[],"checksum":1161021204,"timestamp":"2024-06-01T18:05:57.774878Z"}]}
{"channel":"book","type":"update","data":[{"symbol":"ETH/GBP","bids":[{"price":2980.73,"qty":0.31000000}],"asks":[],"checksum":2765271142,"timestamp":"2024-06-01T18:05:57.775054Z"}]}
{"channel":"book","type":"update","data":[{"symbol":"ETH/GBP","bids":[{"price":2981.05,"qty":0.00000000},{"price":2978.11,"qty":1.31717030}],"asks":[],"checksum":1384589988,"timestamp":"2024-06-01T18:05:57.829428Z"}]}
{"channel":"book","type":"update","data":[{"symbol":"ETH/GBP","bids":[],"asks":[{"price":2981.28,"qty":0.00000000},{"price":2983.92,"qty":0.94850883}],"checksum":1810837947,"timestamp":"2024-06-01T18:05:57.835695Z"}]}
{"channel":"book","type":"update","data":[{"symbol":"ETH/GBP","bids":[],"asks":[{"price":2981.71,"qty":0.00000000},{"price":2984.26,"qty":1.61244212}],"checksum":1900386941,"timestamp":"2024-06-01T18:05:57.839953Z"}]}
{"channel":"book","type":"update","data":[{"symbol":"ETH/GBP","bids":[],"asks":[{"price":2981.28,"qty":6.57886843}],"checksum":3363744323,"timestamp":"2024-06-01T18:05:57.879352Z"}]}
{"channel":"book","type":"update","data":[{"symbol":"ETH/GBP","bids":[{"price":2981.05,"qty":6.57934921}],"asks":[],"checksum":1827683355,"timestamp":"2024-06-01T18:05:57.879384Z"}]}
{"channel":"book","type":"update","data":[{"symbol":"ETH/GBP","bids":[],"asks":[{"price":2981.28,"qty":0.00000000},{"price":2984.26,"qty":1.61244212}],"checksum":3586853925,"timestamp":"2024-06-01T18:05:58.011722Z"}]}
{"channel":"book","type":"update","data":[{"symbol":"ETH/GBP","bids":[],"asks":[{"price":2982.12,"qty":13.15399581}],"checksum":1728634269,"timestamp":"2024-06-01T18:05:58.016732Z"}]}
{"channel":"book","type":"update","data":[{"symbol":"ETH/GBP","bids":[],"asks":[{"price":2981.27,"qty":6.57888147}],"checksum":1803128517,"timestamp":"2024-06-01T18:05:58.016819Z"}]}
{"channel":"book","type":"update","data":[{"symbol":"ETH/GBP","bids":[],"asks":[{"price":2982.13,"qty":0.00000000},{"price":2983.92,"qty":0.94850883}],"checksum":93839174,"timestamp":"2024-06-01T18:05:58.019351Z"}]}
{"channel":"book","type":"update","data":[{"symbol":"ETH/GBP","bids":[],"asks":[{"price":2982.10,"qty":0.31000000}],"checksum":1854134170,"timestamp":"2024-06-01T18:05:58.019670Z"}]}
{"channel":"book","type":"update","data":[{"symbol":"ETH/GBP","bids":[],"asks":[{"price":2982.12,"qty":0.00000000},{"price":2983.92,"qty":0.94850883}],"checksum":3146491282,"timestamp":"2024-06-01T18:05:58.021993Z"}]}
{"channel":"book","type":"update","data":[{"symbol":"ETH/GBP","bids":[{"price":2981.05,"qty":0.00000000},{"price":2978.11,"qty":1.31717030}],"asks":[],"checksum":520434634,"timestamp":"2024-06-01T18:05:58.168815Z"}]}
{"channel":"book","type":"update","data":[{"symbol":"ETH/GBP","bids":[{"price":2981.06,"qty":6.57933078}],"asks":[],"checksum":2420735485,"timestamp":"2024-06-01T18:05:58.173360Z"}]}
{"channel":"book","type":"update","data":[{"symbol":"ETH/GBP","bids":[{"price":2981.06,"qty":0.00000000},{"price":2978.11,"qty":1.31717030}],"asks":[],"checksum":520434634,"timestamp":"2024-06-01T18:05:58.180330Z"}]}
{"channel":"book","type":"update","data":[{"symbol":"ETH/GBP","bids":[],"asks":[{"price":2981.27,"qty":0.00000000},{"price":2984.26,"qty":1.61244212}],"checksum":1873089145,"timestamp":"2024-06-01T18:05:58.180509Z"}]}
{"channel":"book","type":"update","data":[{"symbol":"ETH/GBP","bids":[],"asks":[{"price":2981.30,"qty":6.57880844}],"checksum":2542395932,"timestamp":"2024-06-01T18:05:58.185322Z"}]}
{"channel":"book","type":"update","data":[{"symbol":"ETH/GBP","bids":[],"asks":[{"price":2981.30,"qty":0.00000000},{"price":2984.26,"qty":1.61244212}],"checksum":1873089145,"timestamp":"2024-06-01T18:05:58.192758Z"}]}
{"channel":"book","type":"update","data":[{"symbol":"ETH/GBP","bids":[],"asks":[{"price":2982.09,"qty":13.15413211}],"checksum":1100028851,"timestamp":"2024-06-01T18:05:58.236817Z"}]}
{"channel":"book","type":"update","data":[{"symbol":"ETH/GBP","bids":[],"asks":[{"price":2982.09,"qty":0.00000000},{"price":2984.26,"qty":1.61244212}],"checksum":1873089145,"timestamp":"2024-06-01T18:05:58.241114Z"}]}
{"channel":"book","type":"update","data":[{"symbol":"ETH/GBP","bids":[{"price":2980.94,"qty":6.57959588}],"asks":[],"checksum":804880157,"timestamp":"2024-06-01T18:05:58.281264Z"}]}
{"channel":"book","type":"update","data":[{"symbol":"ETH/GBP","bids":[{"price":2980.94,"qty":0.00000000},{"price":2978.11,"qty":1.31717030}],"asks":[],"checksum":1873089145,"timestamp":"2024-06-01T18:05:58.286251Z"}]}
{"channel":"book","type":"update","data":[{"symbol":"ETH/GBP","bids":[],"asks":[{"price":2981.27,"qty":6.57887752}],"checksum":3174357818,"timestamp":"2024-06-01T18:05:58.293064Z"}]}
{"channel":"book","type":"update","data":[{"symbol":"ETH/GBP","bids":[],"asks":[{"price":2981.27,"qty":0.00000000},{"price":2984.26,"qty":1.61244212}],"checksum":1873089145,"timestamp":"2024-06-01T18:05:58.298145Z"}]}
{"channel":"book","type":"update","data":[{"symbol":"ETH/GBP","bids":[{"price":2981.02,"qty":6.57940999}],"asks":[],"checksum":1771180262,"timestamp":"2024-06-01T18:05:58.425470Z"}]}
{"channel":"book","type":"update","data":[{"symbol":"ETH/GBP","bids":[],"asks":[{"price":2982.09,"qty":6.57706605}],"checksum":166349300,"timestamp":"2024-06-01T18:05:58.425597Z"}]}
{"channel":"book","type":"update","data":[{"symbol":"ETH/GBP","bids":[],"asks":[{"price":2982.09,"qty":0.00000000},{"price":2984.26,"qty":1.61244212}],"checksum":1771180262,"timestamp":"2024-06-01T18:05:58.431138Z"}]}
{"channel":"book","type":"update","data":[{"symbol":"ETH/GBP","bids":[{"price":2981.02,"qty":0.00000000},{"price":2978.11,"qty":1.31717030}],"asks":[],"checksum":1873089145,"timestamp":"2024-06-01T18:05:58.473211Z"}]}
{"channel":"book","type":"update","data":[{"symbol":"ETH/GBP","bids":[],"asks":[{"price":2982.09,"qty":13.15413211}],"checksum":1100028851,"timestamp":"2024-06-01T18:05:58.481745Z"}]}
{"channel":"book","type":"update","data":[{"symbol":"ETH/GBP","bids":[],"asks":[{"price":2982.10,"qty":0.00000000},{"price":2984.26,"qty":1.61244212}],"checksum":105922016,"timestamp":"2024-06-01T18:05:58.484509Z"}]}
{"channel":"book","type":"update","data":[{"symbol":"ETH/GBP","bids":[],"asks":[{"price":2982.03,"qty":0.31000000}],"checksum":3087197181,"timestamp":"2024-06-01T18:05:58.484602Z"}]}
{"channel":"book","type":"update","data":[{"symbol":"ETH/GBP","bids":[],"asks":[{"price":2982.09,"qty":0.00000000},{"price":2984.26,"qty":1.61244212}],"checksum":3309599693,"timestamp":"2024-06-01T18:05:58.486145Z"}]}
{"channel":"book","type":"update","data":[{"symbol":"ETH/GBP","bids":[],"asks":[{"price":2982.02,"qty":0.10990113}],"checksum":3584271563,"timestamp":"2024-06-01T18:05:58.489192Z"}]}
{"channel":"book","type":"update","data":[{"symbol":"ETH/GBP","bids":[],"asks":[{"price":2981.25,"qty":6.57892290}],"checksum":3173942778,"timestamp":"2024-06-01T18:05:58.530196Z"}]}
{"channel":"book","type":"update","data":[{"symbol":"ETH/GBP","bids":[{"price":2981.02,"qty":6.57940474}],"asks":[],"checksum":2915042936,"timestamp":"2024-06-01T18:05:58.530386Z"}]}
{"channel":"book","type":"update","data":[{"symbol":"ETH/GBP","bids":[],"asks":[{"price":2982.02,"qty":0.00000000},{"price":2983.92,"qty":0.94850883}],"checksum":2748581267,"timestamp":"2024-06-01T18:05:58.534243Z"}]}
{"channel":"book","type":"update","data":[{"symbol":"ETH/GBP","bids":[],"asks":[{"price":2981.25,"qty":0.00000000},{"price":2984.26,"qty":1.61244212}],"checksum":3584751695,"timestamp":"2024-06-01T18:05:58.547131Z"}]}
{"channel":"book","type":"update","data":[{"symbol":"ETH/GBP","bids":[],"asks":[{"price":2982.02,"qty":0.10990113}],"checksum":3310167881,"timestamp":"2024-06-01T18:05:58.551973Z"}]}
{"channel":"book","type":"update","data":[{"symbol":"ETH/GBP","bids":[],"asks":[{"price":2982.39,"qty":0.00000000},{"price":2984.26,"qty":1.61244212},{"price":2982.02,"qty":0.19541613}],"checksum":3096107368,"timestamp":"2024-06-01T18:05:58.658397Z"}]}
{"channel":"book","type":"update","data":[{"symbol":"ETH/GBP","bids":[],"asks":[{"price":2982.03,"qty":0.00000000},{"price":2984.35,"qty":0.30200000}],"checksum":2529976056,"timestamp":"2024-06-01T18:05:58.660993Z"}]}
{"channel":"book","type":"update","data":[{"symbol":"ETH/GBP","bids":[{"price":2981.02,"qty":0.00000000},{"price":2978.11,"qty":1.31717030}],"asks":[],"checksum":2250431866,"timestamp":"2024-06-01T18:05:58.700455Z"}]}
{"channel":"book","type":"update","data":[{"symbol":"ETH/GBP","bids":[],"asks":[{"price":2982.48,"qty":0.31000000}],"checksum":1055943249,"timestamp":"2024-06-01T18:05:58.703350Z"}]}
{"channel":"book","type":"update","data":[{"symbol":"ETH/GBP","bids":[],"asks":[{"price":2981.27,"qty":6.57888802}],"checksum":338050147,"timestamp":"2024-06-01T18:05:58.705469Z"}]}
{"channel":"book","type":"update","data":[{"symbol":"ETH/GBP","bids":[{"price":2981.04,"qty":6.57936921}],"asks":[],"checksum":2579311960,"timestamp":"2024-06-01T18:05:58.705525Z"}]}
{"channel":"book","type":"update","data":[{"symbol":"ETH/GBP","bids":[],"asks":[{"price":2981.70,"qty":13.15587360}],"checksum":3084525102,"timestamp":"2024-06-01T18:05:58.705581Z"}]}
{"channel":"book","type":"update","data":[{"symbol":"ETH/GBP","bids":[],"asks":[{"price":2982.02,"qty":0.08551500}],"checksum":3806935449,"timestamp":"2024-06-01T18:05:58.710180Z"}]}
{"channel":"book","type":"update","data":[{"symbol":"ETH/GBP","bids":[{"price":2981.04,"qty":0.00000000},{"price":2978.11,"qty":1.31717030}],"asks":[],"checksum":1869752482,"timestamp":"2024-06-01T18:05:58.841142Z"}]}
{"channel":"book","type":"update","data":[{"symbol":"ETH/GBP","bids":[{"price":2981.05,"qty":6.57935212}],"asks":[],"checksum":202824774,"timestamp":"2024-06-01T18:05:58.845940Z"}]}
{"channel":"book","type":"update","data":[{"symbol":"ETH/GBP","bids":[],"asks":[{"price":2982.02,"qty":0.00000000},{"price":2983.92,"qty":0.94850883},{"price":2982.47,"qty":0.08551000}],"checksum":612042055,"timestamp":"2024-06-01T18:05:58.881918Z"}]}
{"channel":"book","type":"update","data":[{"symbol":"ETH/GBP","bids":[{"price":2981.05,"qty":0.00000000},{"price":2978.11,"qty":1.31717030}],"asks":[],"checksum":1193275811,"timestamp":"2024-06-01T18:05:59.105104Z"}]}
{"channel":"book","type":"update","data":[{"symbol":"ETH/GBP","bids":[],"asks":[{"price":2981.27,"qty":0.00000000},{"price":2983.92,"qty":0.94850883}],"checksum":1001525269,"timestamp":"2024-06-01T18:05:59.105171Z"}]}
{"channel":"book","type":"update","data":[{"symbol":"ETH/GBP","bids":[],"asks":[{"price":2981.69,"qty":0.10990113}],"checksum":1883114159,"timestamp":"2024-06-01T18:05:59.109918Z"}]}
{"channel":"book","type":"update","data":[{"symbol":"ETH/GBP","bids":[],"asks":[{"price":2981.70,"qty":0.00000000},{"price":2983.92,"qty":0.94850883}],"checksum":3830533085,"timestamp":"2024-06-01T18:05:59.110323Z"}]}
{"channel":"book","type":"update","data":[{"symbol":"ETH/GBP","bids":[],"asks":[{"price":2981.26,"qty":6.57890237}],"checksum":612838140,"timestamp":"2024-06-01T18:05:59.114298Z"}]}
{"channel":"book","type":"update","data":[{"symbol":"ETH/GBP","bids":[{"price":2981.03,"qty":6.57938070}],"asks":[],"checksum":4154097326,"timestamp":"2024-06-01T18:05:59.114404Z"}]}
{"channel":"book","type":"update","data":[{"symbol":"ETH/GBP","bids":[],"asks":[{"price":2981.69,"qty":13.26579040}],"checksum":2684491122,"timestamp":"2024-06-01T18:05:59.114559Z"}]}
{"channel":"book","type":"update","data":[{"symbol":"ETH/GBP","bids":[],"asks":[{"price":2981.69,"qty":13.15588927}],"checksum":1981299799,"timestamp":"2024-06-01T18:05:59.115104Z"}]}
{"channel":"book","type":"update","data":[{"symbol":"ETH/GBP","bids":[{"price":2981.03,"qty":0.00000000},{"price":2978.11,"qty":1.31717030}],"asks":[],"checksum":2768594949,"timestamp":"2024-06-01T18:05:59.166663Z"}]}
{"channel":"book","type":"update","data":[{"symbol":"ETH/GBP","bids":[],"asks":[{"price":2981.26,"qty":0.00000000},{"price":2983.92,"qty":0.94850883}],"checksum":3967478378,"timestamp":"2024-06-01T18:05:59.235018Z"}]}
{"channel":"book","type":"update","data":[{"symbol":"ETH/GBP","bids":[],"asks":[{"price":2981.68,"qty":0.10990113}],"checksum":752510647,"timestamp":"2024-06-01T18:05:59.239553Z"}]}
{"channel":"book","type":"update","data":[{"symbol":"ETH/GBP","bids":[],"asks":[{"price":2981.27,"qty":6.57887338}],"checksum":3512778132,"timestamp":"2024-06-01T18:05:59.239742Z"}]}
{"channel":"book","type":"update","data":[{"symbol":"ETH/GBP","bids":[{"price":2981.05,"qty":6.57933793}],"asks":[],"checksum":57497978,"timestamp":"2024-06-01T18:05:59.239767Z"}]}
{"channel":"book","type":"update","data":[{"symbol":"ETH/GBP","bids":[],"asks":[{"price":2981.68,"qty":0.00000000},{"price":2983.72,"qty":1.00000000}],"checksum":2818952357,"timestamp":"2024-06-01T18:05:59.243525Z"}]}
{"channel":"book","type":"update","data":[{"symbol":"ETH/GBP","bids":[{"price":2981.05,"qty":0.00000000},{"price":2978.11,"qty":1.31717030}],"asks":[],"checksum":2047354955,"timestamp":"2024-06-01T18:05:59.247302Z"}]}
{"channel":"book","type":"update","data":[{"symbol":"ETH/GBP","bids":[],"asks":[{"price":2981.27,"qty":0.00000000},{"price":2983.92,"qty":0.94850883}],"checksum":3967478378,"timestamp":"2024-06-01T18:05:59.247311Z"}]}
{"channel":"book","type":"update","data":[{"symbol":"ETH/GBP","bids":[],"asks":[{"price":2981.68,"qty":6.57796669}],"checksum":1377869031,"timestamp":"2024-06-01T18:05:59.457578Z"}]}
{"channel":"book","type":"update","data":[{"symbol":"ETH/GBP","bids":[{"price":2981.05,"qty":6.57934342}],"asks":[],"checksum":1586544659,"timestamp":"2024-06-01T18:05:59.457746Z"}]}
{"channel":"book","type":"update","data":[{"symbol":"ETH/GBP","bids":[{"price":2981.05,"qty":0.00000000},{"price":2978.11,"qty":1.31717030}],"asks":[],"checksum":1377869031,"timestamp":"2024-06-01T18:05:59.462302Z"}]}
{"channel":"book","type":"update","data":[{"symbol":"ETH/GBP","bids":[],"asks":[{"price":2981.68,"qty":0.00000000},{"price":2983.92,"qty":0.94850883}],"checksum":3967478378,"timestamp":"2024-06-01T18:05:59.462524Z"}]}
{"channel":"book","type":"update","data":[{"symbol":"ETH/GBP","bids":[],"asks":[{"price":2981.69,"qty":0.00000000},{"price":2984.26,"qty":1.61244212}],"checksum":3778439225,"timestamp":"2024-06-01T18:05:59.504940Z"}]}
{"channel":"book","type":"update","data":[{"symbol":"ETH/GBP","bids":[],"asks":[{"price":2982.57,"qty":0.00000000},{"price":2984.35,"qty":0.30200000}],"checksum":1029046448,"timestamp":"2024-06-01T18:05:59.510088Z"}]}
{"channel":"book","type":"update","data":[{"symbol":"ETH/GBP","bids":[],"asks":[{"price":2981.68,"qty":13.15593339}],"checksum":944696693,"timestamp":"2024-06-01T18:05:59.510233Z"}]}
{"channel":"book","type":"update","data":[{"symbol":"ETH/GBP","bids":[],"asks":[{"price":2982.48,"qty":0.00000000},{"price":2984.35,"qty":0.30200000}],"checksum":1049525812,"timestamp":"2024-06-01T18:05:59.513051Z"}]}
{"channel":"book","type":"update","data":[{"symbol":"ETH/GBP","bids":[],"asks":[{"price":2982.99,"qty":0.31000000}],"checksum":3892258981,"timestamp":"2024-06-01T18:05:59.513228Z"}]}
{"channel":"book","type":"update","data":[{"symbol":"ETH/GBP","bids":[],"asks":[{"price":2981.68,"qty":0.00000000},{"price":2984.35,"qty":0.30200000}],"checksum":3926534806,"timestamp":"2024-06-01T18:05:59.515365Z"}]}
{"channel":"book","type":"update","data":[{"symbol":"ETH/GBP","bids":[],"asks":[{"price":2982.46,"qty":1.31525165}],"checksum":1604658682,"timestamp":"2024-06-01T18:05:59.520303Z"}]}
{"channel":"book","type":"update","data":[{"symbol":"ETH/GBP","bids":[],"asks":[{"price":2982.46,"qty":0.00000000},{"price":2984.35,"qty":0.30200000}],"checksum":3926534806,"timestamp":"2024-06-01T18:05:59.524758Z"}]}
{"channel":"book","type":"update","data":[{"symbol":"ETH/GBP","bids":[],"asks":[{"price":2981.25,"qty":6.57891874}],"checksum":646407678,"timestamp":"2024-06-01T18:05:59.608965Z"}]}
{"channel":"book","type":"update","data":[{"symbol":"ETH/GBP","bids":[{"price":2980.94,"qty":6.57958771}],"asks":[],"checksum":2945702422,"timestamp":"2024-06-01T18:05:59.609012Z"}]}
{"channel":"book","type":"update","data":[{"symbol":"ETH/GBP","bids":[{"price":2980.94,"qty":0.00000000},{"price":2978.11,"qty":1.31717030}],"asks":[],"checksum":646407678,"timestamp":"2024-06-01T18:05:59.614839Z"}]}
{"channel":"book","type":"update","data":[{"symbol":"ETH/GBP","bids":[],"asks":[{"price":2981.25,"qty":0.00000000},{"price":2984.35,"qty":0.30200000}],"checksum":3926534806,"timestamp":"2024-06-01T18:05:59.739516Z"}]}
{"channel":"book","type":"update","data":[{"symbol":"ETH/GBP","bids":[{"price":2980.64,"qty":0.00000000},{"price":2977.74,"qty":0.21600000}],"asks":[],"checksum":1087015961,"timestamp":"2024-06-01T18:05:59.739642Z"}]}
{"channel":"book","type":"update","data":[{"symbol":"ETH/GBP","bids":[],"asks":[{"price":2981.17,"qty":6.57909269}],"checksum":704225297,"timestamp":"2024-06-01T18:05:59.744602Z"}]}
{"channel":"book","type":"update","data":[{"symbol":"ETH/GBP","bids":[{"price":2980.94,"qty":6.57959963}],"asks":[],"checksum":2796374270,"timestamp":"2024-06-01T18:05:59.744771Z"}]}
{"channel":"book","type":"update","data":[{"symbol":"ETH/GBP","bids":[],"asks":[{"price":2982.46,"qty":13.15251654}],"checksum":1207230106,"timestamp":"2024-06-01T18:05:59.744841Z"}]}
{"channel":"book","type":"update","data":[{"symbol":"ETH/GBP","bids":[{"price":2980.53,"qty":13.16097827}],"asks":[],"checksum":3012407512,"timestamp":"2024-06-01T18:05:59.744918Z"}]}
{"channel":"book","type":"update","data":[{"symbol":"ETH/GBP","bids":[],"asks":[{"price":2982.46,"qty":0.00000000},{"price":2984.26,"qty":1.61244212}],"checksum":4189277199,"timestamp":"2024-06-01T18:05:59.750770Z"}]}
{"channel":"book","type":"update","data":[{"symbol":"ETH/GBP","bids":[{"price":2980.94,"qty":0.00000000},{"price":2978.11,"qty":1.31717030}],"asks":[],"checksum":3846440367,"timestamp":"2024-06-01T18:05:59.752925Z"}]}
{"channel":"book","type":"update","data":[{"symbol":"ETH/GBP","bids":[],"asks":[{"price":2983.08,"qty":0.00000000},{"price":2984.35,"qty":0.30200000}],"checksum":1217135687,"timestamp":"2024-06-01T18:05:59.761027Z"}]}
{"channel":"book","type":"update","data":[{"symbol":"ETH/GBP","bids":[],"asks":[{"price":2983.08,"qty":28.33006955}],"checksum":3686596785,"timestamp":"2024-06-01T18:05:59.764490Z"}]}
{"channel":"book","type":"update","data":[{"symbol":"ETH/GBP","bids":[],"asks":[{"price":2981.68,"qty":3.62589203}],"checksum":3545302959,"timestamp":"2024-06-01T18:05:59.764534Z"}]}
{"channel":"book","type":"update","data":[{"symbol":"ETH/GBP","bids":[{"price":2980.93,"qty":6.66513449}],"asks":[],"checksum":615966707,"timestamp":"2024-06-01T18:05:59.879127Z"}]}
{"channel":"book","type":"update","data":[{"symbol":"ETH/GBP","bids":[],"asks":[{"price":2982.47,"qty":0.00000000},{"price":2984.26,"qty":1.61244212},{"price":2982.98,"qty":0.08549100}],"checksum":3842745732,"timestamp":"2024-06-01T18:05:59.922059Z"}]}
{"channel":"book","type":"update","data":[{"symbol":"ETH/GBP","bids":[],"asks":[{"price":2981.17,"qty":0.00000000},{"price":2984.26,"qty":1.61244212}],"checksum":3698100772,"timestamp":"2024-06-01T18:05:59.979901Z"}]}
{"channel":"book","type":"update","data":[{"symbol":"ETH/GBP","bids":[],"asks":[{"price":2981.67,"qty":13.15597751}],"checksum":1404468020,"timestamp":"2024-06-01T18:05:59.985064Z"}]}
{"channel":"book","type":"update","data":[{"symbol":"ETH/GBP","bids":[],"asks":[{"price":2981.16,"qty":6.57911725}],"checksum":2654675913,"timestamp":"2024-06-01T18:05:59.985170Z"}]}
{"channel":"book","type":"update","data":[{"symbol":"ETH/GBP","bids":[],"asks":[{"price":2981.67,"qty":0.00000000},{"price":2983.92,"qty":0.94850883}],"checksum":3721278778,"timestamp":"2024-06-01T18:05:59.990676Z"}]}
{"channel":"book","type":"update","data":[{"symbol":"ETH/GBP","bids":[{"price":2980.93,"qty":0.08553300}],"asks":[],"checksum":3219796113,"timestamp":"2024-06-01T18:06:00.054200Z"}]}
{"channel":"book","type":"update","data":[{"symbol":"ETH/GBP","bids":[],"asks":[{"price":2981.16,"qty":0.00000000},{"price":2984.26,"qty":1.61244212}],"checksum":2907362712,"timestamp":"2024-06-01T18:06:00.054270Z"}]}
{"channel":"book","type":"update","data":[{"symbol":"ETH/GBP","bids":[{"price":2980.53,"qty":0.00000000},{"price":2977.74,"qty":0.21600000}],"asks":[],"checksum":2835750304,"timestamp":"2024-06-01T18:06:00.054412Z"}]}
{"channel":"book","type":"update","data":[{"symbol":"ETH/GBP","bids":[{"price":2980.47,"qty":13.16125553}],"asks":[],"checksum":2003995306,"timestamp":"2024-06-01T18:06:00.059551Z"}]}
{"channel":"book","type":"update","data":[{"symbol":"ETH/GBP","bids":[{"price":2980.88,"qty":6.57971801}],"asks":[],"checksum":1267122828,"timestamp":"2024-06-01T18:06:00.059675Z"}]}
{"channel":"book","type":"update","data":[{"symbol":"ETH/GBP","bids":[{"price":2980.88,"qty":0.00000000},{"price":2978.11,"qty":1.31717030}],"asks":[],"checksum":2003995306,"timestamp":"2024-06-01T18:06:00.063723Z"}]}
{"channel":"book","type":"update","data":[{"symbol":"ETH/GBP","bids":[],"asks":[{"price":2981.13,"qty":6.57919616}],"checksum":2956175072,"timestamp":"2024-06-01T18:06:00.096519Z"}]}
{"channel":"book","type":"update","data":[{"symbol":"ETH/GBP","bids":[],"asks":[{"price":2981.13,"qty":0.00000000},{"price":2984.26,"qty":1.61244212}],"checksum":2003995306,"timestamp":"2024-06-01T18:06:00.165860Z"}]}
{"channel":"book","type":"update","data":[{"symbol":"ETH/GBP","bids":[{"price":2980.90,"qty":6.57967984}],"asks":[],"checksum":3670260014,"timestamp":"2024-06-01T18:06:00.170661Z"}]}
{"channel":"book","type":"update","data":[{"symbol":"ETH/GBP","bids":[],"asks":[{"price":2981.12,"qty":6.57921183}],"checksum":1483069501,"timestamp":"2024-06-01T18:06:00.220283Z"}]}
{"channel":"book","type":"update","data":[{"symbol":"ETH/GBP","bids":[],"asks":[{"price":2981.67,"qty":13.15597751}],"checksum":1678028807,"timestamp":"2024-06-01T18:06:00.220434Z"}]}
{"channel":"book","type":"update","data":[{"symbol":"ETH/GBP","bids":[],"asks":[{"price":2981.67,"qty":0.00000000},{"price":2983.92,"qty":0.94850883}],"checksum":1483069501,"timestamp":"2024-06-01T18:06:00.225254Z"}]}
{"channel":"book","type":"update","data":[{"symbol":"ETH/GBP","bids":[],"asks":[{"price":2981.12,"qty":0.00000000},{"price":2984.26,"qty":1.61244212}],"checksum":3670260014,"timestamp":"2024-06-01T18:06:00.238217Z"}]}
{"channel":"book","type":"update","data":[{"symbol":"ETH/GBP","bids":[{"price":2980.90,"qty":0.00000000},{"price":2978.11,"qty":1.31717030}],"asks":[],"checksum":2003995306,"timestamp":"2024-06-01T18:06:00.238230Z"}]}
{"channel":"book","type":"update","data":[{"symbol":"ETH/GBP","bids":[],"asks":[{"price":2981.11,"qty":6.57923091}],"checksum":2348859849,"timestamp":"2024-06-01T18:06:00.346877Z"}]}
{"channel":"book","type":"update","data":[{"symbol":"ETH/GBP","bids":[{"price":2980.88,"qty":6.57972557}],"asks":[],"checksum":1473737590,"timestamp":"2024-06-01T18:06:00.346927Z"}]}
{"channel":"book","type":"update","data":[{"symbol":"ETH/GBP","bids":[{"price":2980.88,"qty":0.00000000},{"price":2978.11,"qty":1.31717030}],"asks":[],"checksum":2348859849,"timestamp":"2024-06-01T18:06:00.536240Z"}]}
{"channel":"book","type":"update","data":[{"symbol":"ETH/GBP","bids":[],"asks":[{"price":2981.54,"qty":13.15656114}],"checksum":1992594063,"timestamp":"2024-06-01T18:06:00.541846Z"}]}
{"channel":"book","type":"update","data":[{"symbol":"ETH/GBP","bids":[],"asks":[{"price":2982.45,"qty":1.31525602}],"checksum":3597783721,"timestamp":"2024-06-01T18:06:00.541885Z"}]}
{"channel":"book","type":"update","data":[{"symbol":"ETH/GBP","bids":[{"price":2980.89,"qty":6.57970304}],"asks":[],"checksum":1339444316,"timestamp":"2024-06-01T18:06:00.541912Z"}]}
{"channel":"book","type":"update","data":[{"symbol":"ETH/GBP","bids":[],"asks":[{"price":2981.11,"qty":0.00000000},{"price":2983.72,"qty":1.00000000}],"checksum":4044490509,"timestamp":"2024-06-01T18:06:00.742353Z"}]}
{"channel":"book","type":"update","data":[{"symbol":"ETH/GBP","bids":[{"price":2980.89,"qty":0.00000000},{"price":2978.11,"qty":1.31717030}],"asks":[],"checksum":1756731896,"timestamp":"2024-06-01T18:06:00.742451Z"}]}
{"channel":"book","type":"update","data":[{"symbol":"ETH/GBP","bids":[],"asks":[{"price":2981.14,"qty":6.57917564}],"checksum":3346177157,"timestamp":"2024-06-01T18:06:00.747794Z"}]}
{"channel":"book","type":"update","data":[{"symbol":"ETH/GBP","bids":[{"price":2980.90,"qty":6.57967409}],"asks":[],"checksum":1465051646,"timestamp":"2024-06-01T18:06:00.747883Z"}]}
{"channel":"book","type":"update","data":[{"symbol":"ETH/GBP","bids":[{"price":2980.90,"qty":0.00000000},{"price":2978.11,"qty":1.31717030}],"asks":[],"checksum":3346177157,"timestamp":"2024-06-01T18:06:00.840780Z"}]}
{"channel":"book","type":"update","data":[{"symbol":"ETH/GBP","bids":[],"asks":[{"price":2981.14,"qty":0.00000000},{"price":2983.72,"qty":1.00000000}],"checksum":1756731896,"timestamp":"2024-06-01T18:06:00.874110Z"}]}
{"channel":"book","type":"update","data":[{"symbol":"ETH/GBP","bids":[],"asks":[{"price":2981.11,"qty":6.57923683}],"checksum":4061805681,"timestamp":"2024-06-01T18:06:00.878886Z"}]}
{"channel":"book","type":"update","data":[{"symbol":"ETH/GBP","bids":[{"price":2980.88,"qty":6.57971028}],"asks":[],"checksum":2141114559,"timestamp":"2024-06-01T18:06:00.879036Z"}]}
{"channel":"book","type":"update","data":[{"symbol":"ETH/GBP","bids":[{"price":2980.49,"qty":0.00000000},{"price":2978.11,"qty":1.31717030}],"asks":[],"checksum":2905327845,"timestamp":"2024-06-01T18:06:00.895864Z"}]}
{"channel":"book","type":"update","data":[{"symbol":"ETH/GBP","bids":[],"asks":[{"price":2981.11,"qty":0.00000000},{"price":2983.72,"qty":1.00000000}],"checksum":931425644,"timestamp":"2024-06-01T18:06:01.120260Z"}]}
{"channel":"book","type":"update","data":[{"symbol":"ETH/GBP","bids":[{"price":2980.88,"qty":0.00000000},{"price":2977.74,"qty":0.21600000}],"asks":[],"checksum":2176348173,"timestamp":"2024-06-01T18:06:01.120405Z"}]}
{"channel":"book","type":"update","data":[{"symbol":"ETH/GBP","bids":[{"price":2980.15,"qty":0.00000000},{"price":2977.16,"qty":0.14094948}],"asks":[],"checksum":3197917370,"timestamp":"2024-06-01T18:06:01.123123Z"}]}
{"channel":"book","type":"update","data":[{"symbol":"ETH/GBP","bids":[],"asks":[{"price":2981.54,"qty":0.00000000},{"price":2983.92,"qty":0.94850883}],"checksum":2709454510,"timestamp":"2024-06-01T18:06:01.124915Z"}]}
{"channel":"book","type":"update","data":[{"symbol":"ETH/GBP","bids":[{"price":2980.52,"qty":6.14995865}],"asks":[],"checksum":2510573144,"timestamp":"2024-06-01T18:06:01.128101Z"}]}
{"channel":"book","type":"update","data":[{"symbol":"ETH/GBP","bids":[],"asks":[{"price":2981.53,"qty":6.57829763}],"checksum":1806357951,"timestamp":"2024-06-01T18:06:01.132672Z"}]}
{"channel":"book","type":"update","data":[{"symbol":"ETH/GBP","bids":[{"price":2980.88,"qty":6.57971736}],"asks":[],"checksum":2104308157,"timestamp":"2024-06-01T18:06:01.132734Z"}]}
{"channel":"book","type":"update","data":[{"symbol":"ETH/GBP","bids":[],"asks":[{"price":2981.53,"qty":19.73489289}],"checksum":1892991373,"timestamp":"2024-06-01T18:06:01.132764Z"}]}
{"channel":"book","type":"update","data":[{"symbol":"ETH/GBP","bids":[{"price":2980.47,"qty":0.00000000},{"price":2977.74,"qty":0.21600000}],"asks":[],"checksum":1979526954,"timestamp":"2024-06-01T18:06:01.134968Z"}]}
{"channel":"book","type":"update","data":[{"symbol":"ETH/GBP","bids":[],"asks":[{"price":2981.53,"qty":13.15659526}],"checksum":2061538341,"timestamp":"2024-06-01T18:06:01.139658Z"}]}
{"channel":"book","type":"update","data":[{"symbol":"ETH/GBP","bids":[],"asks":[{"price":2981.53,"qty":0.00000000},{"price":2983.92,"qty":0.94850883}],"checksum":2386810577,"timestamp":"2024-06-01T18:06:01.139665Z"}]}
{"channel":"book","type":"update","data":[{"symbol":"ETH/GBP","bids":[{"price":2980.88,"qty":0.00000000},{"price":2977.16,"qty":0.14094948}],"asks":[],"checksum":1118961793,"timestamp":"2024-06-01T18:06:01.139800Z"}]}
{"channel":"book","type":"update","data":[{"symbol":"ETH/GBP","bids":[{"price":2980.57,"qty":13.16082257}],"asks":[],"checksum":3202160698,"timestamp":"2024-06-01T18:06:01.144749Z"}]}
{"channel":"book","type":"update","data":[{"symbol":"ETH/GBP","bids":[{"price":2980.57,"qty":0.00000000},{"price":2977.16,"qty":0.14094948}],"asks":[],"checksum":1118961793,"timestamp":"2024-06-01T18:06:01.183207Z"}]}
{"channel":"book","type":"update","data":[{"symbol":"ETH/GBP","bids":[],"asks":[{"price":2981.67,"qty":0.10990113}],"checksum":804098156,"timestamp":"2024-06-01T18:06:01.254276Z"}]}
{"channel":"book","type":"update","data":[{"symbol":"ETH/GBP","bids":[{"price":2980.94,"qty":6.57959963}],"asks":[],"checksum":632818603,"timestamp":"2024-06-01T18:06:01.260984Z"}]}
{"channel":"book","type":"update","data":[{"symbol":"ETH/GBP","bids":[],"asks":[{"price":2981.32,"qty":6.57877573}],"checksum":3105458488,"timestamp":"2024-06-01T18:06:01.261015Z"}]}
{"channel":"book","type":"update","data":[{"symbol":"ETH/GBP","bids":[],"asks":[{"price":2981.67,"qty":0.00000000},{"price":2983.72,"qty":1.00000000}],"checksum":4116695369,"timestamp":"2024-06-01T18:06:01.264809Z"}]}
{"channel":"book","type":"update","data":[{"symbol":"ETH/GBP","bids":[{"price":2980.94,"qty":0.00000000},{"price":2977.16,"qty":0.14094948}],"asks":[],"checksum":2822342025,"timestamp":"2024-06-01T18:06:01.265967Z"}]}
{"channel":"book","type":"update","data":[{"symbol":"ETH/GBP","bids":[],"asks":[{"price":2981.32,"qty":0.00000000},{"price":2983.92,"qty":0.94850883}],"checksum":1118961793,"timestamp":"2024-06-01T18:06:01.273677Z"}]}
{"channel":"book","type":"update","data":[{"symbol":"ETH/GBP","bids":[],"asks":[{"price":2981.67,"qty":0.10990113}],"checksum":804098156,"timestamp":"2024-06-01T18:06:01.278635Z"}]}
{"channel":"book","type":"update","data":[{"symbol":"ETH/GBP","bids":[],"asks":[{"price":2981.67,"qty":0.00000000},{"price":2983.92,"qty":0.94850883}],"checksum":1118961793,"timestamp":"2024-06-01T18:06:01.319142Z"}]}
{"channel":"book","type":"update","data":[{"symbol":"ETH/GBP","bids":[],"asks":[{"price":2981.35,"qty":6.57870332}],"checksum":3829388810,"timestamp":"2024-06-01T18:06:01.367930Z"}]}
{"channel":"book","type":"update","data":[{"symbol":"ETH/GBP","bids":[{"price":2980.94,"qty":6.57959963}],"asks":[],"checksum":2174885248,"timestamp":"2024-06-01T18:06:01.368013Z"}]}
{"channel":"book","type":"update","data":[{"symbol":"ETH/GBP","bids":[],"asks":[{"price":2981.81,"qty":13.15537924}],"checksum":3780302753,"timestamp":"2024-06-01T18:06:01.368064Z"}]}
{"channel":"book","type":"update","data":[{"symbol":"ETH/GBP","bids":[{"price":2980.68,"qty":13.16032201}],"asks":[],"checksum":2915023530,"timestamp":"2024-06-01T18:06:01.368140Z"}]}
{"channel":"book","type":"update","data":[{"symbol":"ETH/GBP","bids":[{"price":2980.73,"qty":0.00000000},{"price":2977.74,"qty":0.21600000}],"asks":[],"checksum":1960280393,"timestamp":"2024-06-01T18:06:01.370874Z"}]}
{"channel":"book","type":"update","data":[{"symbol":"ETH/GBP","bids":[{"price":2980.96,"qty":0.31000000}],"asks":[],"checksum":309295413,"timestamp":"2024-06-01T18:06:01.371120Z"}]}
{"channel":"book","type":"update","data":[{"symbol":"ETH/GBP","bids":[{"price":2980.94,"qty":0.00000000},{"price":2977.74,"qty":0.21600000}],"asks":[],"checksum":1730250869,"timestamp":"2024-06-01T18:06:01.373638Z"}]}
{"channel":"book","type":"update","data":[{"symbol":"ETH/GBP","bids":[],"asks":[{"price":2981.35,"qty":0.00000000},{"price":2983.72,"qty":1.00000000}],"checksum":1125025175,"timestamp":"2024-06-01T18:06:01.379955Z"}]}
{"channel":"book","type":"update","data":[{"symbol":"ETH/GBP","bids":[{"price":2980.68,"qty":0.00000000},{"price":2977.16,"qty":0.14094948}],"asks":[],"checksum":1692753448,"timestamp":"2024-06-01T18:06:01.380076Z"}]}
{"channel":"book","type":"update","data":[{"symbol":"ETH/GBP","bids":[{"price":2980.96,"qty":0.00000000},{"price":2977.15,"qty":0.34390000}],"asks":[],"checksum":2581545902,"timestamp":"2024-06-01T18:06:01.382896Z"}]}
{"channel":"book","type":"update","data":[{"symbol":"ETH/GBP","bids":[{"price":2980.61,"qty":0.31000000}],"asks":[],"checksum":816420238,"timestamp":"2024-06-01T18:06:01.382976Z"}]}
{"channel":"book","type":"update","data":[{"symbol":"ETH/GBP","bids":[{"price":2979.79,"qty":0.00000000},{"price":2977.15,"qty":0.34390000}],"asks":[],"checksum":3789875941,"timestamp":"2024-06-01T18:06:01.408700Z"}]}
{"channel":"book","type":"update","data":[{"symbol":"ETH/GBP","bids":[],"asks":[{"price":2981.81,"qty":0.00000000},{"price":2983.92,"qty":0.94850883}],"checksum":1998304603,"timestamp":"2024-06-01T18:06:01.408817Z"}]}
{"channel":"book","type":"update","data":[{"symbol":"ETH/GBP","bids":[{"price":2977.15,"qty":0.00000000},{"price":2976.89,"qty":3.68970000},{"price":2976.90,"qty":0.34390000}],"asks":[],"checksum":4023742240,"timestamp":"2024-06-01T18:06:01.412457Z"}]}
{"channel":"book","type":"update","data":[{"symbol":"ETH/GBP","bids":[],"asks":[{"price":2983.16,"qty":0.00000000},{"price":2984.26,"qty":1.61244212}],"checksum":1903514843,"timestamp":"2024-06-01T18:06:01.415446Z"}]}
{"channel":"book","type":"update","data":[{"symbol":"ETH/GBP","bids":[],"asks":[{"price":2982.45,"qty":0.00000000},{"price":2984.35,"qty":0.30200000}],"checksum":2372936546,"timestamp":"2024-06-01T18:06:01.415604Z"}]}
{"channel":"book","type":"update","data":[{"symbol":"ETH/GBP","bids":[{"price":2979.33,"qty":1.31662758}],"asks":[],"checksum":2501563610,"timestamp":"2024-06-01T18:06:01.421165Z"}]}
{"channel":"book","type":"update","data":[{"symbol":"ETH/GBP","bids":[],"asks":[{"price":2984.09,"qty":1.31453299}],"checksum":1023170656,"timestamp":"2024-06-01T18:06:01.421201Z"}]}
{"channel":"book","type":"update","data":[{"symbol":"ETH/GBP","bids":[{"price":2980.04,"qty":1.31631558}],"asks":[],"checksum":3565562484,"timestamp":"2024-06-01T18:06:01.421298Z"}]}
{"channel":"book","type":"update","data":[{"symbol":"ETH/GBP","bids":[{"price":2980.94,"qty":6.57959963}],"asks":[],"checksum":1031589842,"timestamp":"2024-06-01T18:06:01.469148Z"}]}
{"channel":"book","type":"update","data":[{"symbol":"ETH/GBP","bids":[],"asks":[{"price":2981.46,"qty":6.57845383}],"checksum":2682263709,"timestamp":"2024-06-01T18:06:01.469274Z"}]}
{"channel":"book","type":"update","data":[{"symbol":"ETH/GBP","bids":[{"price":2980.61,"qty":0.00000000},{"price":2977.74,"qty":0.21600000}],"asks":[],"checksum":3622461672,"timestamp":"2024-06-01T18:06:01.472054Z"}]}
{"channel":"book","type":"update","data":[{"symbol":"ETH/GBP","bids":[{"price":2981.03,"qty":0.31000000}],"asks":[],"checksum":169316711,"timestamp":"2024-06-01T18:06:01.472337Z"}]}
{"channel":"book","type":"update","data":[{"symbol":"ETH/GBP","bids":[{"price":2980.94,"qty":0.00000000},{"price":2977.74,"qty":0.21600000}],"asks":[],"checksum":791454714,"timestamp":"2024-06-01T18:06:01.475196Z"}]}
{"channel":"book","type":"update","data":[{"symbol":"ETH/GBP","bids":[],"asks":[{"price":2981.46,"qty":0.00000000},{"price":2984.26,"qty":1.61244212}],"checksum":3565854425,"timestamp":"2024-06-01T18:06:01.475389Z"}]}
{"channel":"book","type":"update","data":[{"symbol":"ETH/GBP","bids":[],"asks":[{"price":2982.69,"qty":1.31514927}],"checksum":4004921705,"timestamp":"2024-06-01T18:06:01.563578Z"}]}
{"channel":"book","type":"update","data":[{"symbol":"ETH/GBP","bids":[],"asks":[{"price":2981.89,"qty":13.15503569}],"checksum":840205177,"timestamp":"2024-06-01T18:06:01.568001Z"}]}
{"channel":"book","type":"update","data":[{"symbol":"ETH/GBP","bids":[{"price":2980.80,"qty":13.15979314}],"asks":[],"checksum":2673249385,"timestamp":"2024-06-01T18:06:01.568177Z"}]}
{"channel":"book","type":"update","data":[{"symbol":"ETH/GBP","bids":[],"asks":[{"price":2981.45,"qty":6.57847614}],"checksum":1485613910,"timestamp":"2024-06-01T18:06:01.572561Z"}]}
{"channel":"book","type":"update","data":[{"symbol":"ETH/GBP","bids":[{"price":2981.22,"qty":6.57896151}],"asks":[],"checksum":1878695237,"timestamp":"2024-06-01T18:06:01.572712Z"}]}
{"channel":"book","type":"update","data":[{"symbol":"ETH/GBP","bids":[{"price":2981.22,"qty":0.00000000},{"price":2978.11,"qty":1.31717030}],"asks":[],"checksum":1485613910,"timestamp":"2024-06-01T18:06:01.579698Z"}]}
{"channel":"book","type":"update","data":[{"symbol":"ETH/GBP","bids":[],"asks":[{"price":2981.45,"qty":0.00000000},{"price":2983.92,"qty":0.94850883}],"checksum":2673249385,"timestamp":"2024-06-01T18:06:01.722890Z"}]}
{"channel":"book","type":"update","data":[{"symbol":"ETH/GBP","bids":[],"asks":[{"price":2981.67,"qty":0.10990113}],"checksum":2067095240,"timestamp":"2024-06-01T18:06:01.726928Z"}]}
{"channel":"book","type":"update","data":[{"symbol":"ETH/GBP","bids":[],"asks":[{"price":2981.47,"qty":6.57845081}],"checksum":3872982994,"timestamp":"2024-06-01T18:06:01.727257Z"}]}
{"channel":"book","type":"update","data":[{"symbol":"ETH/GBP","bids":[{"price":2981.23,"qty":6.57894901}],"asks":[],"checksum":2427499866,"timestamp":"2024-06-01T18:06:01.727394Z"}]}
{"channel":"book","type":"update","data":[{"symbol":"ETH/GBP","bids":[],"asks":[{"price":2981.67,"qty":0.00000000},{"price":2983.72,"qty":1.00000000}],"checksum":1420039327,"timestamp":"2024-06-01T18:06:01.730999Z"}]}
{"channel":"book","type":"update","data":[{"symbol":"ETH/GBP","bids":[{"price":2980.93,"qty":0.00000000},{"price":2978.11,"qty":1.31717030},{"price":2981.23,"qty":6.66447901}],"asks":[],"checksum":4161790917,"timestamp":"2024-06-01T18:06:01.749196Z"}]}
{"channel":"book","type":"update","data":[{"symbol":"ETH/GBP","bids":[],"asks":[{"price":2981.47,"qty":0.00000000},{"price":2983.92,"qty":0.94850883}],"checksum":2450047984,"timestamp":"2024-06-01T18:06:01.805663Z"}]}
{"channel":"book","type":"update","data":[{"symbol":"ETH/GBP","bids":[],"asks":[{"price":2981.67,"qty":0.10990113}],"checksum":1305024963,"timestamp":"2024-06-01T18:06:01.810442Z"}]}
{"channel":"book","type":"update","data":[{"symbol":"ETH/GBP","bids":[{"price":2981.23,"qty":0.08553000}],"asks":[],"checksum":2801714949,"timestamp":"2024-06-01T18:06:01.897506Z"}]}
{"channel":"book","type":"update","data":[{"symbol":"ETH/GBP","bids":[],"asks":[{"price":2981.66,"qty":6.57801081}],"checksum":3306618724,"timestamp":"2024-06-01T18:06:01.901397Z"}]}
{"channel":"book","type":"update","data":[{"symbol":"ETH/GBP","bids":[{"price":2981.24,"qty":6.57893190}],"asks":[],"checksum":1322878960,"timestamp":"2024-06-01T18:06:01.901444Z"}]}
{"channel":"book","type":"update","data":[{"symbol":"ETH/GBP","bids":[],"asks":[{"price":2981.67,"qty":0.00000000},{"price":2983.72,"qty":1.00000000}],"checksum":3017862043,"timestamp":"2024-06-01T18:06:01.905811Z"}]}
{"channel":"book","type":"update","data":[{"symbol":"ETH/GBP","bids":[],"asks":[{"price":2981.66,"qty":0.00000000},{"price":2983.92,"qty":0.94850883}],"checksum":3377622320,"timestamp":"2024-06-01T18:06:01.906081Z"}]}
{"channel":"book","type":"update","data":[{"symbol":"ETH/GBP","bids":[],"asks":[{"price":2981.89,"qty":0.00000000},{"price":2984.09,"qty":1.31453299}],"checksum":4143579231,"timestamp":"2024-06-01T18:06:01.985194Z"}]}
{"channel":"book","type":"update","data":[{"symbol":"ETH/GBP","bids":[{"price":2981.24,"qty":0.00000000},{"price":2978.11,"qty":1.31717030}],"asks":[],"checksum":2100656331,"timestamp":"2024-06-01T18:06:01.985205Z"}]}
{"channel":"book","type":"update","data":[{"symbol":"ETH/GBP","bids":[{"price":2980.80,"qty":0.00000000},{"price":2977.74,"qty":0.21600000}],"asks":[],"checksum":124492883,"timestamp":"2024-06-01T18:06:01.985286Z"}]}
{"channel":"book","type":"update","data":[{"symbol":"ETH/GBP","bids":[{"price":2981.03,"qty":0.00000000},{"price":2976.91,"qty":0.14096130}],"asks":[],"checksum":2802160055,"timestamp":"2024-06-01T18:06:01.988313Z"}]}
{"channel":"book","type":"update","data":[{"symbol":"ETH/GBP","bids":[{"price":2980.61,"qty":0.31000000}],"asks":[],"checksum":841520769,"timestamp":"2024-06-01T18:06:01.988397Z"}]}
{"channel":"book","type":"update","data":[{"symbol":"ETH/GBP","bids":[],"asks":[{"price":2981.89,"qty":13.15501868}],"checksum":614953465,"timestamp":"2024-06-01T18:06:01.990754Z"}]}
{"channel":"book","type":"update","data":[{"symbol":"ETH/GBP","bids":[{"price":2980.86,"qty":13.15954412}],"asks":[],"checksum":3520149618,"timestamp":"2024-06-01T18:06:01.990899Z"}]}
{"channel":"book","type":"update","data":[{"symbol":"ETH/GBP","bids":[{"price":2980.61,"qty":0.00000000},{"price":2977.74,"qty":0.21600000}],"asks":[],"checksum":2581282823,"timestamp":"2024-06-01T18:06:01.993430Z"}]}
{"channel":"book","type":"update","data":[{"symbol":"ETH/GBP","bids":[{"price":2980.95,"qty":0.31000000}],"asks":[],"checksum":2435480772,"timestamp":"2024-06-01T18:06:01.993658Z"}]}
{"channel":"book","type":"update","data":[{"symbol":"ETH/GBP","bids":[{"price":2981.24,"qty":6.57893753}],"asks":[],"checksum":8652839,"timestamp":"2024-06-01T18:06:02.091949Z"}]}
{"channel":"book","type":"update","data":[{"symbol":"ETH/GBP","bids":[],"asks":[{"price":2981.46,"qty":6.57845909}],"checksum":2224219470,"timestamp":"2024-06-01T18:06:02.092124Z"}]}
{"channel":"book","type":"update","data":[{"symbol":"ETH/GBP","bids":[],"asks":[{"price":2981.46,"qty":0.00000000},{"price":2983.92,"qty":0.94850883}],"checksum":8652839,"timestamp":"2024-06-01T18:06:02.097513Z"}]}
{"channel":"book","type":"update","data":[{"symbol":"ETH/GBP","bids":[],"asks":[{"price":2983.08,"qty":0.00000000},{"price":2984.09,"qty":1.31453299}],"checksum":2336194916,"timestamp":"2024-06-01T18:06:02.124691Z"}]}
{"channel":"book","type":"update","data":[{"symbol":"ETH/GBP","bids":[],"asks":[{"price":2981.68,"qty":0.00000000},{"price":2984.26,"qty":1.61244212}],"checksum":930079535,"timestamp":"2024-06-01T18:06:02.124729Z"}]}
{"channel":"book","type":"update","data":[{"symbol":"ETH/GBP","bids":[],"asks":[{"price":2983.08,"qty":24.80670418}],"checksum":2700652589,"timestamp":"2024-06-01T18:06:02.129531Z"}]}
{"channel":"book","type":"update","data":[{"symbol":"ETH/GBP","bids":[],"asks":[{"price":2982.98,"qty":0.00000000},{"price":2984.26,"qty":1.61244212},{"price":2982.68,"qty":0.08550200}],"checksum":1650575735,"timestamp":"2024-06-01T18:06:02.170316Z"}]}
{"channel":"book","type":"update","data":[{"symbol":"ETH/GBP","bids":[{"price":2981.24,"qty":0.00000000},{"price":2978.11,"qty":1.31717030}],"asks":[],"checksum":4090477972,"timestamp":"2024-06-01T18:06:02.299518Z"}]}
{"channel":"book","type":"update","data":[{"symbol":"ETH/GBP","bids":[],"asks":[{"price":2981.47,"qty":6.57843409}],"checksum":70927072,"timestamp":"2024-06-01T18:06:02.304418Z"}]}
{"channel":"book","type":"update","data":[{"symbol":"ETH/GBP","bids":[{"price":2981.25,"qty":6.57891087}],"asks":[],"checksum":1931124689,"timestamp":"2024-06-01T18:06:02.304558Z"}]}
{"channel":"book","type":"update","data":[{"symbol":"ETH/GBP","bids":[],"asks":[{"price":2981.47,"qty":0.00000000},{"price":2984.09,"qty":1.31453299}],"checksum":2230280357,"timestamp":"2024-06-01T18:06:02.424722Z"}]}
{"channel":"book","type":"update","data":[{"symbol":"ETH/GBP","bids":[{"price":2981.25,"qty":0.00000000},{"price":2978.11,"qty":1.31717030}],"asks":[],"checksum":4090477972,"timestamp":"2024-06-01T18:06:02.424758Z"}]}
{"channel":"book","type":"update","data":[{"symbol":"ETH/GBP","bids":[],"asks":[{"price":2981.49,"qty":6.57840646}],"checksum":105158150,"timestamp":"2024-06-01T18:06:02.430075Z"}]}
{"channel":"book","type":"update","data":[{"symbol":"ETH/GBP","bids":[{"price":2981.26,"qty":6.57888324}],"asks":[],"checksum":1414643519,"timestamp":"2024-06-01T18:06:02.430288Z"}]}
{"channel":"book","type":"update","data":[{"symbol":"ETH/GBP","bids":[],"asks":[{"price":2981.49,"qty":0.00000000},{"price":2984.09,"qty":1.31453299}],"checksum":2715456685,"timestamp":"2024-06-01T18:06:02.586179Z"}]}
{"channel":"book","type":"update","data":[{"symbol":"ETH/GBP","bids":[],"asks":[{"price":2981.48,"qty":6.57841435}],"checksum":181936467,"timestamp":"2024-06-01T18:06:02.590497Z"}]}
{"channel":"book","type":"update","data":[{"symbol":"ETH/GBP","bids":[{"price":2981.26,"qty":0.00000000},{"price":2978.11,"qty":1.31717030}],"asks":[],"checksum":1489832042,"timestamp":"2024-06-01T18:06:02.741078Z"}]}
{"channel":"book","type":"update","data":[{"symbol":"ETH/GBP","bids":[{"price":2981.27,"qty":6.57886238}],"asks":[],"checksum":1761046129,"timestamp":"2024-06-01T18:06:02.746597Z"}]}
{"channel":"book","type":"update","data":[{"symbol":"ETH/GBP","bids":[{"price":2981.27,"qty":0.00000000},{"price":2978.11,"qty":1.31717030}],"asks":[],"checksum":1489832042,"timestamp":"2024-06-01T18:06:02.770755Z"}]}
{"channel":"book","type":"update","data":[{"symbol":"ETH/GBP","bids":[],"asks":[{"price":2981.48,"qty":0.00000000},{"price":2984.09,"qty":1.31453299}],"checksum":4090477972,"timestamp":"2024-06-01T18:06:02.770763Z"}]}
{"channel":"book","type":"update","data":[{"symbol":"ETH/GBP","bids":[{"price":2980.86,"qty":0.00000000},{"price":2977.74,"qty":0.21600000}],"asks":[],"checksum":3134904365,"timestamp":"2024-06-01T18:06:02.770955Z"}]}
{"channel":"book","type":"update","data":[{"symbol":"ETH/GBP","bids":[],"asks":[{"price":2981.89,"qty":0.00000000},{"price":2984.26,"qty":1.61244212}],"checksum":2719614279,"timestamp":"2024-06-01T18:06:02.770968Z"}]}
{"channel":"book","type":"update","data":[{"symbol":"ETH/GBP","bids":[{"price":2980.95,"qty":0.00000000},{"price":2976.91,"qty":0.14096130}],"asks":[],"checksum":2902930183,"timestamp":"2024-06-01T18:06:02.773829Z"}]}
{"channel":"book","type":"update","data":[{"symbol":"ETH/GBP","bids":[{"price":2980.85,"qty":13.15956337}],"asks":[],"checksum":2132035909,"timestamp":"2024-06-01T18:06:02.777070Z"}]}
{"channel":"book","type":"update","data":[{"symbol":"ETH/GBP","bids":[],"asks":[{"price":2981.53,"qty":6.57830501}],"checksum":4247980680,"timestamp":"2024-06-01T18:06:02.777228Z"}]}
{"channel":"book","type":"update","data":[{"symbol":"ETH/GBP","bids":[],"asks":[{"price":2982.67,"qty":13.15158655}],"checksum":1330052761,"timestamp":"2024-06-01T18:06:02.777262Z"}]}
{"channel":"book","type":"update","data":[{"symbol":"ETH/GBP","bids":[],"asks":[{"price":2982.67,"qty":0.00000000},{"price":2984.09,"qty":1.31453299}],"checksum":4247980680,"timestamp":"2024-06-01T18:06:02.788172Z"}]}
{"channel":"book","type":"update","data":[{"symbol":"ETH/GBP","bids":[],"asks":[{"price":2981.53,"qty":0.00000000},{"price":2984.26,"qty":1.61244212}],"checksum":2132035909,"timestamp":"2024-06-01T18:06:02.808683Z"}]}
{"channel":"book","type":"update","data":[{"symbol":"ETH/GBP","bids":[{"price":2981.29,"qty":6.57881010}],"asks":[],"checksum":1157810797,"timestamp":"2024-06-01T18:06:02.848025Z"}]}
{"channel":"book","type":"update","data":[{"symbol":"ETH/GBP","bids":[],"asks":[{"price":2981.51,"qty":6.57834908}],"checksum":2204943173,"timestamp":"2024-06-01T18:06:02.883067Z"}]}
{"channel":"book","type":"update","data":[{"symbol":"ETH/GBP","bids":[],"asks":[{"price":2981.51,"qty":0.00000000},{"price":2984.26,"qty":1.61244212}],"checksum":1157810797,"timestamp":"2024-06-01T18:06:02.957361Z"}]}
{"channel":"book","type":"update","data":[{"symbol":"ETH/GBP","bids":[{"price":2981.23,"qty":0.00000000},{"price":2977.74,"qty":0.21600000},{"price":2980.86,"qty":0.08554800}],"asks":[],"checksum":4113950947,"timestamp":"2024-06-01T18:06:03.056545Z"}]}
{"channel":"book","type":"update","data":[{"symbol":"ETH/GBP","bids":[{"price":2981.29,"qty":0.00000000},{"price":2977.74,"qty":0.21600000}],"asks":[],"checksum":3689196689,"timestamp":"2024-06-01T18:06:03.130455Z"}]}
{"channel":"book","type":"update","data":[{"symbol":"ETH/GBP","bids":[{"price":2980.88,"qty":1.31551101}],"asks":[],"checksum":1911048851,"timestamp":"2024-06-01T18:06:03.133584Z"}]}
{"channel":"book","type":"update","data":[{"symbol":"ETH/GBP","bids":[{"price":2981.27,"qty":6.57885747}],"asks":[],"checksum":985992030,"timestamp":"2024-06-01T18:06:03.135246Z"}]}
{"channel":"book","type":"update","data":[{"symbol":"ETH/GBP","bids":[],"asks":[{"price":2982.67,"qty":13.15160286}],"checksum":3152833169,"timestamp":"2024-06-01T18:06:03.135338Z"}]}
{"channel":"book","type":"update","data":[{"symbol":"ETH/GBP","bids":[],"asks":[{"price":2981.50,"qty":6.57836703}],"checksum":3683258850,"timestamp":"2024-06-01T18:06:03.136062Z"}]}
{"channel":"book","type":"update","data":[{"symbol":"ETH/GBP","bids":[],"asks":[{"price":2982.67,"qty":0.00000000},{"price":2984.09,"qty":1.31453299}],"checksum":136332979,"timestamp":"2024-06-01T18:06:03.141346Z"}]}
{"channel":"book","type":"update","data":[{"symbol":"ETH/GBP","bids":[{"price":2981.27,"qty":0.00000000},{"price":2978.11,"qty":1.31717030}],"asks":[],"checksum":1124927358,"timestamp":"2024-06-01T18:06:03.170008Z"}]}
{"channel":"book","type":"update","data":[{"symbol":"ETH/GBP","bids":[],"asks":[{"price":2981.50,"qty":0.00000000},{"price":2984.26,"qty":1.61244212}],"checksum":1911048851,"timestamp":"2024-06-01T18:06:03.170057Z"}]}
{"channel":"book","type":"update","data":[{"symbol":"ETH/GBP","bids":[],"asks":[{"price":2982.69,"qty":0.00000000},{"price":2984.35,"qty":0.30200000}],"checksum":732436424,"timestamp":"2024-06-01T18:06:03.175330Z"}]}
{"channel":"book","type":"update","data":[{"symbol":"ETH/GBP","bids":[],"asks":[{"price":2982.67,"qty":1.31516019}],"checksum":3954948933,"timestamp":"2024-06-01T18:06:03.178976Z"}]}
{"channel":"book","type":"update","data":[{"symbol":"ETH/GBP","bids":[],"asks":[{"price":2982.67,"qty":0.00000000},{"price":2984.35,"qty":0.30200000}],"checksum":732436424,"timestamp":"2024-06-01T18:06:03.184691Z"}]}
{"channel":"book","type":"update","data":[{"symbol":"ETH/GBP","bids":[{"price":2981.26,"qty":6.57887911}],"asks":[],"checksum":4116892390,"timestamp":"2024-06-01T18:06:03.468357Z"}]}
{"channel":"book","type":"update","data":[{"symbol":"ETH/GBP","bids":[],"asks":[{"price":2982.67,"qty":6.57580099}],"checksum":573094936,"timestamp":"2024-06-01T18:06:03.468384Z"}]}
{"channel":"book","type":"update","data":[{"symbol":"ETH/GBP","bids":[],"asks":[{"price":2982.67,"qty":19.72740297}],"checksum":1464210465,"timestamp":"2024-06-01T18:06:03.468398Z"}]}
{"channel":"book","type":"update","data":[{"symbol":"ETH/GBP","bids":[],"asks":[{"price":2982.67,"qty":13.15160198}],"checksum":2486465204,"timestamp":"2024-06-01T18:06:03.475578Z"}]}
{"channel":"book","type":"update","data":[{"symbol":"ETH/GBP","bids":[],"asks":[{"price":2982.67,"qty":0.00000000},{"price":2984.35,"qty":0.30200000}],"checksum":4116892390,"timestamp":"2024-06-01T18:06:03.475649Z"}]}
{"channel":"book","type":"update","data":[{"symbol":"ETH/GBP","bids":[{"price":2981.26,"qty":0.00000000},{"price":2978.11,"qty":1.31717030}],"asks":[],"checksum":732436424,"timestamp":"2024-06-01T18:06:03.475791Z"}]}
{"channel":"book","type":"update","data":[{"symbol":"ETH/GBP","bids":[{"price":2980.85,"qty":0.00000000},{"price":2977.74,"qty":0.21600000}],"asks":[],"checksum":767727057,"timestamp":"2024-06-01T18:06:03.525955Z"}]}
{"channel":"book","type":"update","data":[{"symbol":"ETH/GBP","bids":[{"price":2980.97,"qty":0.31000000}],"asks":[],"checksum":3935537697,"timestamp":"2024-06-01T18:06:03.529508Z"}]}
{"channel":"book","type":"update","data":[{"symbol":"ETH/GBP","bids":[{"price":2980.89,"qty":13.15938468}],"asks":[],"checksum":2633694728,"timestamp":"2024-06-01T18:06:03.531264Z"}]}
{"channel":"book","type":"update","data":[{"symbol":"ETH/GBP","bids":[{"price":2981.00,"qty":1.31544054}],"asks":[],"checksum":885490403,"timestamp":"2024-06-01T18:06:03.538361Z"}]}
{"channel":"book","type":"update","data":[{"symbol":"ETH/GBP","bids":[{"price":2980.88,"qty":0.00000000},{"price":2978.12,"qty":1.33500000}],"asks":[],"checksum":2117474248,"timestamp":"2024-06-01T18:06:03.540177Z"}]}
{"channel":"book","type":"update","data":[{"symbol":"ETH/GBP","bids":[{"price":2980.97,"qty":0.00000000},{"price":2978.11,"qty":1.31717030}],"asks":[],"checksum":3685117259,"timestamp":"2024-06-01T18:06:03.541440Z"}]}
{"channel":"book","type":"update","data":[{"symbol":"ETH/GBP","bids":[{"price":2981.09,"qty":0.31000000}],"asks":[],"checksum":3610551284,"timestamp":"2024-06-01T18:06:03.542263Z"}]}
{"channel":"book","type":"update","data":[{"symbol":"ETH/GBP","bids":[{"price":2980.89,"qty":0.00000000},{"price":2978.11,"qty":1.31717030}],"asks":[],"checksum":2250759235,"timestamp":"2024-06-01T18:06:03.553878Z"}]}
{"channel":"book","type":"update","data":[{"symbol":"ETH/GBP","bids":[{"price":2981.37,"qty":6.57864055}],"asks":[],"checksum":1398922394,"timestamp":"2024-06-01T18:06:03.585174Z"}]}
{"channel":"book","type":"update","data":[{"symbol":"ETH/GBP","bids":[],"asks":[{"price":2981.62,"qty":6.57811766}],"checksum":1890036797,"timestamp":"2024-06-01T18:06:03.585196Z"}]}
{"channel":"book","type":"update","data":[{"symbol":"ETH/GBP","bids":[],"asks":[{"price":2981.62,"qty":0.00000000},{"price":2984.35,"qty":0.30200000}],"checksum":1398922394,"timestamp":"2024-06-01T18:06:03.602237Z"}]}
{"channel":"book","type":"update","data":[{"symbol":"ETH/GBP","bids":[],"asks":[{"price":2984.26,"qty":0.27444212}],"checksum":1881153465,"timestamp":"2024-06-01T18:06:03.609931Z"}]}
{"channel":"book","type":"update","data":[{"symbol":"ETH/GBP","bids":[],"asks":[{"price":2983.09,"qty":0.00000000},{"price":2984.40,"qty":2.94416492}],"checksum":3023427909,"timestamp":"2024-06-01T18:06:03.619352Z"}]}
{"channel":"book","type":"update","data":[{"symbol":"ETH/GBP","bids":[{"price":2981.37,"qty":0.00000000},{"price":2978.11,"qty":1.31717030}],"asks":[],"checksum":1634982300,"timestamp":"2024-06-01T18:06:03.622652Z"}]}
{"channel":"book","type":"update","data":[{"symbol":"ETH/GBP","bids":[],"asks":[{"price":2983.33,"qty":15.52560385}],"checksum":411620916,"timestamp":"2024-06-01T18:06:03.623388Z"}]}
{"channel":"book","type":"update","data":[{"symbol":"ETH/GBP","bids":[],"asks":[{"price":2983.72,"qty":0.00000000},{"price":2984.40,"qty":2.94416492}],"checksum":3965961933,"timestamp":"2024-06-01T18:06:03.629595Z"}]}
{"channel":"book","type":"update","data":[{"symbol":"ETH/GBP","bids":[],"asks":[{"price":2984.02,"qty":1.00000000}],"checksum":1949606579,"timestamp":"2024-06-01T18:06:03.629612Z"}]}
{"channel":"book","type":"update","data":[{"symbol":"ETH/GBP","bids":[{"price":2981.36,"qty":6.57865274}],"asks":[],"checksum":3281768441,"timestamp":"2024-06-01T18:06:03.709703Z"}]}
{"channel":"book","type":"update","data":[{"symbol":"ETH/GBP","bids":[],"asks":[{"price":2981.61,"qty":6.57812754}],"checksum":3815369112,"timestamp":"2024-06-01T18:06:03.709789Z"}]}
{"channel":"book","type":"update","data":[{"symbol":"ETH/GBP","bids":[],"asks":[{"price":2982.67,"qty":13.15159272}],"checksum":1615849220,"timestamp":"2024-06-01T18:06:03.709835Z"}]}
{"channel":"book","type":"update","data":[{"symbol":"ETH/GBP","bids":[],"asks":[{"price":2982.67,"qty":0.00000000},{"price":2984.26,"qty":0.27444212}],"checksum":3815369112,"timestamp":"2024-06-01T18:06:03.715578Z"}]}
{"channel":"book","type":"update","data":[{"symbol":"ETH/GBP","bids":[],"asks":[{"price":2982.68,"qty":0.00000000},{"price":2984.35,"qty":0.30200000},{"price":2982.98,"qty":0.08550700}],"checksum":1192900376,"timestamp":"2024-06-01T18:06:03.785697Z"}]}
{"channel":"book","type":"update","data":[{"symbol":"ETH/GBP","bids":[],"asks":[{"price":2981.61,"qty":0.00000000},{"price":2984.35,"qty":0.30200000}],"checksum":27173891,"timestamp":"2024-06-01T18:06:03.877040Z"}]}
{"channel":"book","type":"update","data":[{"symbol":"ETH/GBP","bids":[],"asks":[{"price":2981.60,"qty":6.57814530}],"checksum":2612444292,"timestamp":"2024-06-01T18:06:03.881658Z"}]}
{"channel":"book","type":"update","data":[{"symbol":"ETH/GBP","bids":[{"price":2980.95,"qty":13.15911237}],"asks":[],"checksum":1720311846,"timestamp":"2024-06-01T18:06:03.881846Z"}]}
{"channel":"book","type":"update","data":[{"symbol":"ETH/GBP","bids":[{"price":2981.36,"qty":0.00000000},{"price":2978.12,"qty":1.33500000}],"asks":[],"checksum":466248920,"timestamp":"2024-06-01T18:06:03.996900Z"}]}
{"channel":"book","type":"update","data":[{"symbol":"ETH/GBP","bids":[],"asks":[{"price":2981.60,"qty":0.00000000},{"price":2984.35,"qty":0.30200000}],"checksum":1754028611,"timestamp":"2024-06-01T18:06:03.996908Z"}]}
{"channel":"book","type":"update","data":[{"symbol":"ETH/GBP","bids":[],"asks":[{"price":2981.62,"qty":6.57811570}],"checksum":1633349533,"timestamp":"2024-06-01T18:06:04.002349Z"}]}
{"channel":"book","type":"update","data":[{"symbol":"ETH/GBP","bids":[{"price":2981.37,"qty":6.57864090}],"asks":[],"checksum":4234449144,"timestamp":"2024-06-01T18:06:04.002469Z"}]}
{"channel":"book","type":"update","data":[{"symbol":"ETH/GBP","bids":[],"asks":[{"price":2982.97,"qty":13.15028328}],"checksum":2061030825,"timestamp":"2024-06-01T18:06:04.002613Z"}]}
{"channel":"book","type":"update","data":[{"symbol":"ETH/GBP","bids":[],"asks":[{"price":2982.97,"qty":0.00000000},{"price":2984.26,"qty":0.27444212}],"checksum":4234449144,"timestamp":"2024-06-01T18:06:04.007265Z"}]}
{"channel":"book","type":"update","data":[{"symbol":"ETH/GBP","bids":[{"price":2981.37,"qty":0.00000000},{"price":2978.12,"qty":1.33500000}],"asks":[],"checksum":1633349533,"timestamp":"2024-06-01T18:06:04.034108Z"}]}
{"channel":"book","type":"update","data":[{"symbol":"ETH/GBP","bids":[],"asks":[{"price":2981.62,"qty":0.00000000},{"price":2984.35,"qty":0.30200000}],"checksum":1754028611,"timestamp":"2024-06-01T18:06:04.046302Z"}]}
{"channel":"book","type":"update","data":[{"symbol":"ETH/GBP","bids":[],"asks":[{"price":2981.58,"qty":6.57820517}],"checksum":443982444,"timestamp":"2024-06-01T18:06:04.253382Z"}]}
{"channel":"book","type":"update","data":[{"symbol":"ETH/GBP","bids":[{"price":2981.10,"qty":6.57922685}],"asks":[],"checksum":787336090,"timestamp":"2024-06-01T18:06:04.253481Z"}]}
{"channel":"book","type":"update","data":[{"symbol":"ETH/GBP","bids":[],"asks":[{"price":2982.97,"qty":13.15028328}],"checksum":3602339271,"timestamp":"2024-06-01T18:06:04.253589Z"}]}
{"channel":"book","type":"update","data":[{"symbol":"ETH/GBP","bids":[],"asks":[{"price":2982.97,"qty":14.46531041}],"checksum":178840142,"timestamp":"2024-06-01T18:06:04.253607Z"}]}
{"channel":"book","type":"update","data":[{"symbol":"ETH/GBP","bids":[{"price":2981.09,"qty":0.00000000},{"price":2978.12,"qty":1.33500000}],"asks":[],"checksum":866872053,"timestamp":"2024-06-01T18:06:04.256595Z"}]}
{"channel":"book","type":"update","data":[{"symbol":"ETH/GBP","bids":[{"price":2981.19,"qty":0.31000000}],"asks":[],"checksum":3682085813,"timestamp":"2024-06-01T18:06:04.256867Z"}]}
{"channel":"book","type":"update","data":[{"symbol":"ETH/GBP","bids":[{"price":2981.10,"qty":0.00000000},{"price":2978.12,"qty":1.33500000}],"asks":[],"checksum":1343167112,"timestamp":"2024-06-01T18:06:04.258736Z"}]}
{"channel":"book","type":"update","data":[{"symbol":"ETH/GBP","bids":[],"asks":[{"price":2982.97,"qty":1.31502713}],"checksum":1411191206,"timestamp":"2024-06-01T18:06:04.258783Z"}]}
{"channel":"book","type":"update","data":[{"symbol":"ETH/GBP","bids":[],"asks":[{"price":2981.58,"qty":0.00000000},{"price":2984.26,"qty":0.27444212}],"checksum":3177736510,"timestamp":"2024-06-01T18:06:04.367676Z"}]}
{"channel":"book","type":"update","data":[{"symbol":"ETH/GBP","bids":[],"asks":[{"price":2982.97,"qty":0.00000000},{"price":2984.35,"qty":0.30200000}],"checksum":112249715,"timestamp":"2024-06-01T18:06:04.367835Z"}]}
{"channel":"book","type":"update","data":[{"symbol":"ETH/GBP","bids":[{"price":2980.95,"qty":0.00000000},{"price":2978.11,"qty":1.31717030}],"asks":[],"checksum":3785760478,"timestamp":"2024-06-01T18:06:04.367904Z"}]}
{"channel":"book","type":"update","data":[{"symbol":"ETH/GBP","bids":[{"price":2981.32,"qty":6.57875975}],"asks":[],"checksum":2620349337,"timestamp":"2024-06-01T18:06:04.374800Z"}]}
{"channel":"book","type":"update","data":[{"symbol":"ETH/GBP","bids":[{"price":2980.89,"qty":13.15940344}],"asks":[],"checksum":216255551,"timestamp":"2024-06-01T18:06:04.374832Z"}]}
{"channel":"book","type":"update","data":[{"symbol":"ETH/GBP","bids":[],"asks":[{"price":2981.56,"qty":6.57824565}],"checksum":2082489753,"timestamp":"2024-06-01T18:06:04.375047Z"}]}
{"channel":"book","type":"update","data":[{"symbol":"ETH/GBP","bids":[{"price":2981.32,"qty":0.00000000},{"price":2978.12,"qty":1.33500000}],"asks":[],"checksum":453703426,"timestamp":"2024-06-01T18:06:04.380090Z"}]}
{"channel":"book","type":"update","data":[{"symbol":"ETH/GBP","bids":[],"asks":[{"price":2981.56,"qty":0.00000000},{"price":2984.35,"qty":0.30200000}],"checksum":1808367268,"timestamp":"2024-06-01T18:06:04.380263Z"}]}
{"channel":"book","type":"update","data":[{"symbol":"ETH/GBP","bids":[],"asks":[{"price":2982.97,"qty":6.57513943}],"checksum":2036272414,"timestamp":"2024-06-01T18:06:04.517095Z"}]}
{"channel":"book","type":"update","data":[{"symbol":"ETH/GBP","bids":[],"asks":[{"price":2982.97,"qty":19.72541830}],"checksum":2903148663,"timestamp":"2024-06-01T18:06:04.517174Z"}]}
{"channel":"book","type":"update","data":[{"symbol":"ETH/GBP","bids":[{"price":2981.31,"qty":6.57876896}],"asks":[],"checksum":1837472604,"timestamp":"2024-06-01T18:06:04.517337Z"}]}
{"channel":"book","type":"update","data":[{"symbol":"ETH/GBP","bids":[],"asks":[{"price":2982.97,"qty":13.15027887}],"checksum":1077087513,"timestamp":"2024-06-01T18:06:04.522628Z"}]}
{"channel":"book","type":"update","data":[{"symbol":"ETH/GBP","bids":[],"asks":[{"price":2982.97,"qty":0.00000000},{"price":2984.35,"qty":0.30200000}],"checksum":2873519503,"timestamp":"2024-06-01T18:06:04.522711Z"}]}
{"channel":"book","type":"update","data":[{"symbol":"ETH/GBP","bids":[{"price":2981.31,"qty":0.00000000},{"price":2978.12,"qty":1.33500000}],"asks":[],"checksum":1808367268,"timestamp":"2024-06-01T18:06:04.532438Z"}]}
{"channel":"book","type":"update","data":[{"symbol":"ETH/GBP","bids":[],"asks":[{"price":2983.08,"qty":0.00000000},{"price":2984.40,"qty":2.94416492}],"checksum":4259935558,"timestamp":"2024-06-01T18:06:04.571146Z"}]}
{"channel":"book","type":"update","data":[{"symbol":"ETH/GBP","bids":[],"asks":[{"price":2983.32,"qty":45.41690370}],"checksum":2987906567,"timestamp":"2024-06-01T18:06:04.578381Z"}]}
{"channel":"book","type":"update","data":[{"symbol":"ETH/GBP","bids":[],"asks":[{"price":2982.97,"qty":1.55945001}],"checksum":3048624122,"timestamp":"2024-06-01T18:06:04.578477Z"}]}
{"channel":"book","type":"update","data":[{"symbol":"ETH/GBP","bids":[{"price":2981.33,"qty":6.57873672}],"asks":[],"checksum":974243893,"timestamp":"2024-06-01T18:06:04.629402Z"}]}
{"channel":"book","type":"update","data":[{"symbol":"ETH/GBP","bids":[],"asks":[{"price":2981.57,"qty":6.57822017}],"checksum":2323062142,"timestamp":"2024-06-01T18:06:04.629454Z"}]}
{"channel":"book","type":"update","data":[{"symbol":"ETH/GBP","bids":[],"asks":[{"price":2981.57,"qty":0.00000000},{"price":2984.26,"qty":0.27444212}],"checksum":974243893,"timestamp":"2024-06-01T18:06:05.318383Z"}]}
{"channel":"book","type":"update","data":[{"symbol":"ETH/GBP","bids":[{"price":2981.33,"qty":0.00000000},{"price":2978.12,"qty":1.33500000}],"asks":[],"checksum":3048624122,"timestamp":"2024-06-01T18:06:05.318519Z"}]}
{"channel":"book","type":"update","data":[{"symbol":"ETH/GBP","bids":[],"asks":[{"price":2981.55,"qty":6.57826494}],"checksum":4058876352,"timestamp":"2024-06-01T18:06:05.324043Z"}]}
{"channel":"book","type":"update","data":[{"symbol":"ETH/GBP","bids":[],"asks":[{"price":2982.75,"qty":1.31512341}],"checksum":3036073072,"timestamp":"2024-06-01T18:06:05.324178Z"}]}
{"channel":"book","type":"update","data":[{"symbol":"ETH/GBP","bids":[],"asks":[{"price":2982.96,"qty":13.15032251}],"checksum":3322452937,"timestamp":"2024-06-01T18:06:05.324209Z"}]}
{"channel":"book","type":"update","data":[{"symbol":"ETH/GBP","bids":[{"price":2981.31,"qty":6.57876600}],"asks":[],"checksum":2495487783,"timestamp":"2024-06-01T18:06:05.324222Z"}]}
{"channel":"book","type":"update","data":[{"symbol":"ETH/GBP","bids":[],"asks":[{"price":2982.96,"qty":0.00000000},{"price":2984.02,"qty":1.00000000}],"checksum":3862972574,"timestamp":"2024-06-01T18:06:05.330753Z"}]}
{"channel":"book","type":"update","data":[{"symbol":"ETH/GBP","bids":[{"price":2980.86,"qty":0.00000000},{"price":2978.12,"qty":1.33500000},{"price":2981.20,"qty":0.08553800}],"asks":[],"checksum":3201565665,"timestamp":"2024-06-01T18:06:05.493322Z"}]}
{"channel":"book","type":"update","data":[{"symbol":"ETH/GBP","bids":[],"asks":[{"price":2981.55,"qty":0.00000000},{"price":2984.09,"qty":1.31453299}],"checksum":725516006,"timestamp":"2024-06-01T18:06:05.858786Z"}]}
{"channel":"book","type":"update","data":[{"symbol":"ETH/GBP","bids":[],"asks":[{"price":2982.74,"qty":0.10990113}],"checksum":1711407837,"timestamp":"2024-06-01T18:06:05.863424Z"}]}
{"channel":"book","type":"update","data":[{"symbol":"ETH/GBP","bids":[],"asks":[{"price":2981.54,"qty":6.57829652}],"checksum":897807993,"timestamp":"2024-06-01T18:06:05.863581Z"}]}
{"channel":"book","type":"update","data":[{"symbol":"ETH/GBP","bids":[],"asks":[{"price":2981.98,"qty":13.15463320}],"checksum":388398078,"timestamp":"2024-06-01T18:06:05.863743Z"}]}
{"channel":"book","type":"update","data":[{"symbol":"ETH/GBP","bids":[],"asks":[{"price":2982.75,"qty":0.00000000},{"price":2983.92,"qty":0.94850883}],"checksum":4157865809,"timestamp":"2024-06-01T18:06:05.863859Z"}]}
{"channel":"book","type":"update","data":[{"symbol":"ETH/GBP","bids":[],"asks":[{"price":2982.74,"qty":0.00000000},{"price":2984.02,"qty":1.00000000}],"checksum":625068629,"timestamp":"2024-06-01T18:06:05.868347Z"}]}
{"channel":"book","type":"update","data":[{"symbol":"ETH/GBP","bids":[],"asks":[{"price":2981.98,"qty":0.00000000},{"price":2984.09,"qty":1.31453299}],"checksum":1281693744,"timestamp":"2024-06-01T18:06:05.868924Z"}]}
{"channel":"book","type":"update","data":[{"symbol":"ETH/GBP","bids":[],"asks":[{"price":2982.98,"qty":0.00000000},{"price":2984.26,"qty":0.27444212},{"price":2981.97,"qty":0.08552000}],"checksum":1043506202,"timestamp":"2024-06-01T18:06:06.039216Z"}]}
{"channel":"book","type":"update","data":[{"symbol":"ETH/GBP","bids":[{"price":2981.31,"qty":0.00000000},{"price":2978.12,"qty":1.33500000}],"asks":[],"checksum":2263251727,"timestamp":"2024-06-01T18:06:06.139634Z"}]}
{"channel":"book","type":"update","data":[{"symbol":"ETH/GBP","bids":[],"asks":[{"price":2981.54,"qty":0.00000000},{"price":2984.26,"qty":0.27444212}],"checksum":3407336527,"timestamp":"2024-06-01T18:06:06.139679Z"}]}
{"channel":"book","type":"update","data":[{"symbol":"ETH/GBP","bids":[],"asks":[{"price":2982.96,"qty":0.10990113}],"checksum":2893801354,"timestamp":"2024-06-01T18:06:06.144117Z"}]}
{"channel":"book","type":"update","data":[{"symbol":"ETH/GBP","bids":[],"asks":[{"price":2981.56,"qty":6.57824973}],"checksum":870290010,"timestamp":"2024-06-01T18:06:06.148078Z"}]}
{"channel":"book","type":"update","data":[{"symbol":"ETH/GBP","bids":[{"price":2981.33,"qty":6.57875053}],"asks":[],"checksum":2994141462,"timestamp":"2024-06-01T18:06:06.148108Z"}]}
{"channel":"book","type":"update","data":[{"symbol":"ETH/GBP","bids":[],"asks":[{"price":2981.97,"qty":13.24021635}],"checksum":3645439854,"timestamp":"2024-06-01T18:06:06.148245Z"}]}
{"channel":"book","type":"update","data":[{"symbol":"ETH/GBP","bids":[],"asks":[{"price":2982.96,"qty":0.00000000},{"price":2984.09,"qty":1.31453299}],"checksum":3866612720,"timestamp":"2024-06-01T18:06:06.152462Z"}]}
{"channel":"book","type":"update","data":[{"symbol":"ETH/GBP","bids":[],"asks":[{"price":2981.97,"qty":13.15469635},{"price":2982.96,"qty":0.08549700}],"checksum":2599388435,"timestamp":"2024-06-01T18:06:06.210564Z"}]}
{"channel":"book","type":"update","data":[{"symbol":"ETH/GBP","bids":[],"asks":[{"price":2981.56,"qty":0.00000000},{"price":2984.09,"qty":1.31453299}],"checksum":2734772607,"timestamp":"2024-06-01T18:06:06.225894Z"}]}
{"channel":"book","type":"update","data":[{"symbol":"ETH/GBP","bids":[],"asks":[{"price":2981.96,"qty":0.10990113}],"checksum":3998792558,"timestamp":"2024-06-01T18:06:06.230874Z"}]}
{"channel":"book","type":"update","data":[{"symbol":"ETH/GBP","bids":[{"price":2981.33,"qty":0.00000000},{"price":2978.12,"qty":1.33500000}],"asks":[],"checksum":1878118434,"timestamp":"2024-06-01T18:06:06.300023Z"}]}
{"channel":"book","type":"update","data":[{"symbol":"ETH/GBP","bids":[],"asks":[{"price":2981.55,"qty":6.57827473}],"checksum":3207932546,"timestamp":"2024-06-01T18:06:06.304825Z"}]}
{"channel":"book","type":"update","data":[{"symbol":"ETH/GBP","bids":[{"price":2981.31,"qty":6.57877948}],"asks":[],"checksum":3853647170,"timestamp":"2024-06-01T18:06:06.304921Z"}]}
{"channel":"book","type":"update","data":[{"symbol":"ETH/GBP","bids":[],"asks":[{"price":2981.96,"qty":0.00000000},{"price":2984.02,"qty":1.00000000}],"checksum":278724377,"timestamp":"2024-06-01T18:06:06.309107Z"}]}
{"channel":"book","type":"update","data":[{"symbol":"ETH/GBP","bids":[],"asks":[{"price":2981.55,"qty":0.00000000},{"price":2984.09,"qty":1.31453299}],"checksum":2016210419,"timestamp":"2024-06-01T18:06:06.390999Z"}]}
{"channel":"book","type":"update","data":[{"symbol":"ETH/GBP","bids":[],"asks":[{"price":2982.73,"qty":1.31513358}],"checksum":3304285711,"timestamp":"2024-06-01T18:06:06.395541Z"}]}
{"channel":"book","type":"update","data":[{"symbol":"ETH/GBP","bids":[{"price":2981.31,"qty":0.00000000},{"price":2978.12,"qty":1.33500000}],"asks":[],"checksum":2658644431,"timestamp":"2024-06-01T18:06:06.403905Z"}]}
{"channel":"book","type":"update","data":[{"symbol":"ETH/GBP","bids":[{"price":2981.33,"qty":6.57875150}],"asks":[],"checksum":3450790407,"timestamp":"2024-06-01T18:06:06.408437Z"}]}
{"channel":"book","type":"update","data":[{"symbol":"ETH/GBP","bids":[],"asks":[{"price":2981.56,"qty":6.57825237}],"checksum":2790531137,"timestamp":"2024-06-01T18:06:06.408521Z"}]}
{"channel":"book","type":"update","data":[{"symbol":"ETH/GBP","bids":[],"asks":[{"price":2981.56,"qty":0.00000000},{"price":2984.02,"qty":1.00000000}],"checksum":3450790407,"timestamp":"2024-06-01T18:06:06.601474Z"}]}
{"channel":"book","type":"update","data":[{"symbol":"ETH/GBP","bids":[],"asks":[{"price":2981.55,"qty":6.57827294}],"checksum":1083803750,"timestamp":"2024-06-01T18:06:06.605949Z"}]}
{"channel":"book","type":"update","data":[{"symbol":"ETH/GBP","bids":[],"asks":[{"price":2983.32,"qty":0.00000000},{"price":2984.02,"qty":1.00000000}],"checksum":2027553584,"timestamp":"2024-06-01T18:06:06.916091Z"}]}
{"channel":"book","type":"update","data":[{"symbol":"ETH/GBP","bids":[],"asks":[{"price":2982.97,"qty":0.00000000},{"price":2984.09,"qty":1.31453299}],"checksum":2083103344,"timestamp":"2024-06-01T18:06:06.916122Z"}]}
{"channel":"book","type":"update","data":[{"symbol":"ETH/GBP","bids":[],"asks":[{"price":2983.32,"qty":19.64064868}],"checksum":3420530183,"timestamp":"2024-06-01T18:06:06.921369Z"}]}
{"channel":"book","type":"update","data":[{"symbol":"ETH/GBP","bids":[{"price":2981.33,"qty":0.00000000},{"price":2978.12,"qty":1.33500000}],"asks":[],"checksum":2553837007,"timestamp":"2024-06-01T18:06:07.327871Z"}]}
{"channel":"book","type":"update","data":[{"symbol":"ETH/GBP","bids":[{"price":2981.31,"qty":6.57879189}],"asks":[],"checksum":1388525254,"timestamp":"2024-06-01T18:06:07.332786Z"}]}
{"channel":"book","type":"update","data":[{"symbol":"ETH/GBP","bids":[{"price":2981.31,"qty":0.00000000},{"price":2978.12,"qty":1.33500000}],"asks":[],"checksum":2553837007,"timestamp":"2024-06-01T18:06:08.263901Z"}]}
{"channel":"book","type":"update","data":[{"symbol":"ETH/GBP","bids":[{"price":2981.32,"qty":6.57876765}],"asks":[],"checksum":929360916,"timestamp":"2024-06-01T18:06:08.268825Z"}]}
{"channel":"book","type":"update","data":[{"symbol":"ETH/GBP","bids":[],"asks":[{"price":2981.55,"qty":0.00000000},{"price":2984.09,"qty":1.31453299}],"checksum":878133884,"timestamp":"2024-06-01T18:06:08.324431Z"}]}
{"channel":"book","type":"update","data":[{"symbol":"ETH/GBP","bids":[],"asks":[{"price":2981.54,"qty":6.57829271}],"checksum":1748345961,"timestamp":"2024-06-01T18:06:08.328785Z"}]}
{"channel":"book","type":"update","data":[{"symbol":"ETH/GBP","bids":[{"price":2981.32,"qty":0.00000000},{"price":2978.12,"qty":1.33500000}],"asks":[],"checksum":3345563058,"timestamp":"2024-06-01T18:06:08.610311Z"}]}
{"channel":"book","type":"update","data":[{"symbol":"ETH/GBP","bids":[],"asks":[{"price":2981.54,"qty":0.00000000},{"price":2984.09,"qty":1.31453299}],"checksum":2601245607,"timestamp":"2024-06-01T18:06:08.610415Z"}]}
{"channel":"book","type":"update","data":[{"symbol":"ETH/GBP","bids":[{"price":2981.33,"qty":6.57874274}],"asks":[],"checksum":1760326315,"timestamp":"2024-06-01T18:06:08.615496Z"}]}
{"channel":"book","type":"update","data":[{"symbol":"ETH/GBP","bids":[],"asks":[{"price":2981.56,"qty":6.57824832}],"checksum":3979323227,"timestamp":"2024-06-01T18:06:08.615649Z"}]}
{"channel":"book","type":"update","data":[{"symbol":"ETH/GBP","bids":[],"asks":[{"price":2981.56,"qty":0.00000000},{"price":2984.09,"qty":1.31453299}],"checksum":1760326315,"timestamp":"2024-06-01T18:06:08.738695Z"}]}
{"channel":"book","type":"update","data":[{"symbol":"ETH/GBP","bids":[{"price":2981.33,"qty":0.00000000},{"price":2978.12,"qty":1.33500000}],"asks":[],"checksum":2601245607,"timestamp":"2024-06-01T18:06:08.738707Z"}]}
{"channel":"book","type":"update","data":[{"symbol":"ETH/GBP","bids":[{"price":2981.34,"qty":6.57870919}],"asks":[],"checksum":377489497,"timestamp":"2024-06-01T18:06:08.743903Z"}]}
{"channel":"book","type":"update","data":[{"symbol":"ETH/GBP","bids":[],"asks":[{"price":2981.58,"qty":6.57821477}],"checksum":75775745,"timestamp":"2024-06-01T18:06:08.743968Z"}]}
{"channel":"book","type":"update","data":[{"symbol":"ETH/GBP","bids":[],"asks":[{"price":2981.58,"qty":0.00000000},{"price":2984.09,"qty":1.31453299}],"checksum":377489497,"timestamp":"2024-06-01T18:06:08.823037Z"}]}
{"channel":"book","type":"update","data":[{"symbol":"ETH/GBP","bids":[{"price":2981.34,"qty":0.00000000},{"price":2978.12,"qty":1.33500000}],"asks":[],"checksum":2601245607,"timestamp":"2024-06-01T18:06:08.869838Z"}]}
{"channel":"book","type":"update","data":[{"symbol":"ETH/GBP","bids":[],"asks":[{"price":2981.55,"qty":6.57827464}],"checksum":2998646137,"timestamp":"2024-06-01T18:06:08.874969Z"}]}
{"channel":"book","type":"update","data":[{"symbol":"ETH/GBP","bids":[{"price":2981.32,"qty":6.57876906}],"asks":[],"checksum":3548476436,"timestamp":"2024-06-01T18:06:08.875005Z"}]}
{"channel":"book","type":"update","data":[{"symbol":"ETH/GBP","bids":[],"asks":[{"price":2981.55,"qty":0.00000000},{"price":2984.09,"qty":1.31453299}],"checksum":4197522122,"timestamp":"2024-06-01T18:06:08.909563Z"}]}
{"channel":"book","type":"update","data":[{"symbol":"ETH/GBP","bids":[{"price":2981.32,"qty":0.00000000},{"price":2978.12,"qty":1.33500000}],"asks":[],"checksum":2601245607,"timestamp":"2024-06-01T18:06:08.909674Z"}]}
{"channel":"book","type":"update","data":[{"symbol":"ETH/GBP","bids":[],"asks":[{"price":2981.97,"qty":0.00000000},{"price":2984.26,"qty":0.27444212}],"checksum":4008913149,"timestamp":"2024-06-01T18:06:08.914324Z"}]}
{"channel":"book","type":"update","data":[{"symbol":"ETH/GBP","bids":[],"asks":[{"price":2981.96,"qty":13.15472606}],"checksum":176888863,"timestamp":"2024-06-01T18:06:08.918542Z"}]}
{"channel":"book","type":"update","data":[{"symbol":"ETH/GBP","bids":[],"asks":[{"price":2982.73,"qty":0.00000000},{"price":2984.26,"qty":0.27444212}],"checksum":590654698,"timestamp":"2024-06-01T18:06:08.918702Z"}]}
{"channel":"book","type":"update","data":[{"symbol":"ETH/GBP","bids":[],"asks":[{"price":2982.72,"qty":1.31513975}],"checksum":483963606,"timestamp":"2024-06-01T18:06:08.922967Z"}]}
{"channel":"book","type":"update","data":[{"symbol":"ETH/GBP","bids":[],"asks":[{"price":2981.95,"qty":6.57738508}],"checksum":3685026125,"timestamp":"2024-06-01T18:06:09.038378Z"}]}
{"channel":"book","type":"update","data":[{"symbol":"ETH/GBP","bids":[{"price":2981.33,"qty":6.57874226}],"asks":[],"checksum":3077402033,"timestamp":"2024-06-01T18:06:09.038401Z"}]}
{"channel":"book","type":"update","data":[{"symbol":"ETH/GBP","bids":[],"asks":[{"price":2981.95,"qty":0.00000000},{"price":2984.09,"qty":1.31453299}],"checksum":1880151594,"timestamp":"2024-06-01T18:06:09.043279Z"}]}
{"channel":"book","type":"update","data":[{"symbol":"ETH/GBP","bids":[{"price":2981.33,"qty":0.00000000},{"price":2978.12,"qty":1.33500000}],"asks":[],"checksum":483963606,"timestamp":"2024-06-01T18:06:09.149833Z"}]}
{"channel":"book","type":"update","data":[{"symbol":"ETH/GBP","bids":[],"asks":[{"price":2981.56,"qty":6.57826473}],"checksum":4208490942,"timestamp":"2024-06-01T18:06:09.156269Z"}]}
{"channel":"book","type":"update","data":[{"symbol":"ETH/GBP","bids":[{"price":2981.34,"qty":6.57872779}],"asks":[],"checksum":3790159136,"timestamp":"2024-06-01T18:06:09.156389Z"}]}
{"channel":"book","type":"update","data":[{"symbol":"ETH/GBP","bids":[],"asks":[{"price":2983.32,"qty":0.00000000},{"price":2984.09,"qty":1.31453299}],"checksum":164633466,"timestamp":"2024-06-01T18:06:09.365837Z"}]}
{"channel":"book","type":"update","data":[{"symbol":"ETH/GBP","bids":[],"asks":[{"price":2981.95,"qty":5.69229542}],"checksum":1090540030,"timestamp":"2024-06-01T18:06:09.371187Z"}]}
{"channel":"book","type":"update","data":[{"symbol":"ETH/GBP","bids":[],"asks":[{"price":2983.32,"qty":16.45066200}],"checksum":2997603181,"timestamp":"2024-06-01T18:06:09.371199Z"}]}
{"channel":"book","type":"update","data":[{"symbol":"ETH/GBP","bids":[],"asks":[{"price":2981.56,"qty":0.00000000},{"price":2984.02,"qty":1.00000000}],"checksum":3160479466,"timestamp":"2024-06-01T18:06:09.531288Z"}]}
{"channel":"book","type":"update","data":[{"symbol":"ETH/GBP","bids":[],"asks":[{"price":2981.55,"qty":6.57827515}],"checksum":1318028084,"timestamp":"2024-06-01T18:06:09.536004Z"}]}
{"channel":"book","type":"update","data":[{"symbol":"ETH/GBP","bids":[],"asks":[{"price":2981.55,"qty":0.00000000},{"price":2984.02,"qty":1.00000000}],"checksum":3160479466,"timestamp":"2024-06-01T18:06:09.558182Z"}]}
{"channel":"book","type":"update","data":[{"symbol":"ETH/GBP","bids":[],"asks":[{"price":2981.96,"qty":0.00000000},{"price":2984.09,"qty":1.31453299}],"checksum":530812079,"timestamp":"2024-06-01T18:06:09.558195Z"}]}
{"channel":"book","type":"update","data":[{"symbol":"ETH/GBP","bids":[{"price":2981.34,"qty":0.00000000},{"price":2978.12,"qty":1.33500000}],"asks":[],"checksum":76728369,"timestamp":"2024-06-01T18:06:09.558263Z"}]}
{"channel":"book","type":"update","data":[{"symbol":"ETH/GBP","bids":[{"price":2980.89,"qty":0.00000000},{"price":2978.11,"qty":1.31717030}],"asks":[],"checksum":2273368218,"timestamp":"2024-06-01T18:06:09.558375Z"}]}
{"channel":"book","type":"update","data":[{"symbol":"ETH/GBP","bids":[{"price":2980.04,"qty":0.00000000},{"price":2977.74,"qty":0.21600000}],"asks":[],"checksum":553600863,"timestamp":"2024-06-01T18:06:09.562532Z"}]}
{"channel":"book","type":"update","data":[{"symbol":"ETH/GBP","bids":[{"price":2981.45,"qty":6.57847037}],"asks":[],"checksum":3941761905,"timestamp":"2024-06-01T18:06:09.567228Z"}]}
{"channel":"book","type":"update","data":[{"symbol":"ETH/GBP","bids":[{"price":2981.02,"qty":13.15883475}],"asks":[],"checksum":2944529388,"timestamp":"2024-06-01T18:06:09.567296Z"}]}
{"channel":"book","type":"update","data":[{"symbol":"ETH/GBP","bids":[],"asks":[{"price":2982.13,"qty":13.15398144}],"checksum":4232182670,"timestamp":"2024-06-01T18:06:09.567388Z"}]}
{"channel":"book","type":"update","data":[{"symbol":"ETH/GBP","bids":[{"price":2980.26,"qty":1.31621941}],"asks":[],"checksum":3968101383,"timestamp":"2024-06-01T18:06:09.567432Z"}]}
{"channel":"book","type":"update","data":[{"symbol":"ETH/GBP","bids":[{"price":2981.45,"qty":0.00000000},{"price":2978.12,"qty":1.33500000}],"asks":[],"checksum":3781344125,"timestamp":"2024-06-01T18:06:09.572343Z"}]}
{"channel":"book","type":"update","data":[{"symbol":"ETH/GBP","bids":[{"price":2978.12,"qty":0.00000000},{"price":2978.11,"qty":1.31717030},{"price":2978.60,"qty":1.60943647}],"asks":[],"checksum":1681403056,"timestamp":"2024-06-01T18:06:09.579068Z"}]}
{"channel":"book","type":"update","data":[{"symbol":"ETH/GBP","bids":[{"price":2978.60,"qty":1.33500000}],"asks":[],"checksum":2622671285,"timestamp":"2024-06-01T18:06:09.641324Z"}]}
{"channel":"book","type":"update","data":[{"symbol":"ETH/GBP","bids":[],"asks":[{"price":2981.72,"qty":6.57790288}],"checksum":2673963131,"timestamp":"2024-06-01T18:06:09.661613Z"}]}
{"channel":"book","type":"update","data":[{"symbol":"ETH/GBP","bids":[],"asks":[{"price":2981.72,"qty":0.00000000},{"price":2984.02,"qty":1.00000000}],"checksum":2622671285,"timestamp":"2024-06-01T18:06:09.672608Z"}]}
{"channel":"book","type":"update","data":[{"symbol":"ETH/GBP","bids":[{"price":2981.46,"qty":6.57844524}],"asks":[],"checksum":2831541677,"timestamp":"2024-06-01T18:06:09.676733Z"}]}
{"channel":"book","type":"update","data":[{"symbol":"ETH/GBP","bids":[],"asks":[{"price":2981.70,"qty":6.57794608}],"checksum":1675238104,"timestamp":"2024-06-01T18:06:09.770947Z"}]}
{"channel":"book","type":"update","data":[{"symbol":"ETH/GBP","bids":[{"price":2981.46,"qty":0.00000000},{"price":2978.11,"qty":1.31717030}],"asks":[],"checksum":1464678080,"timestamp":"2024-06-01T18:06:09.773089Z"}]}
{"channel":"book","type":"update","data":[{"symbol":"ETH/GBP","bids":[{"price":2981.45,"qty":6.57848274}],"asks":[],"checksum":3593203758,"timestamp":"2024-06-01T18:06:09.807234Z"}]}
{"channel":"book","type":"update","data":[{"symbol":"ETH/GBP","bids":[{"price":2978.76,"qty":0.27441483}],"asks":[],"checksum":3659631345,"timestamp":"2024-06-01T18:06:09.893016Z"}]}
{"channel":"book","type":"update","data":[{"symbol":"ETH/GBP","bids":[],"asks":[{"price":2981.70,"qty":0.00000000},{"price":2984.02,"qty":1.00000000}],"checksum":2758636353,"timestamp":"2024-06-01T18:06:10.091281Z"}]}
{"channel":"book","type":"update","data":[{"symbol":"ETH/GBP","bids":[{"price":2981.45,"qty":0.00000000},{"price":2978.60,"qty":1.33500000}],"asks":[],"checksum":3914593593,"timestamp":"2024-06-01T18:06:10.094940Z"}]}
{"channel":"book","type":"update","data":[{"symbol":"ETH/GBP","bids":[],"asks":[{"price":2982.13,"qty":0.00000000},{"price":2984.09,"qty":1.31453299}],"checksum":3130260827,"timestamp":"2024-06-01T18:06:10.095919Z"}]}
{"channel":"book","type":"update","data":[{"symbol":"ETH/GBP","bids":[{"price":2981.02,"qty":0.00000000},{"price":2978.11,"qty":1.31717030}],"asks":[],"checksum":2357554524,"timestamp":"2024-06-01T18:06:10.095942Z"}]}
{"channel":"book","type":"update","data":[{"symbol":"ETH/GBP","bids":[],"asks":[{"price":2982.07,"qty":13.15425511}],"checksum":1680468159,"timestamp":"2024-06-01T18:06:10.102204Z"}]}
{"channel":"book","type":"update","data":[{"symbol":"ETH/GBP","bids":[],"asks":[{"price":2981.63,"qty":6.57810133}],"checksum":2522128346,"timestamp":"2024-06-01T18:06:10.102281Z"}]}
{"channel":"book","type":"update","data":[{"symbol":"ETH/GBP","bids":[{"price":2981.37,"qty":6.57864393}],"asks":[],"checksum":956714357,"timestamp":"2024-06-01T18:06:10.102303Z"}]}
{"channel":"book","type":"update","data":[{"symbol":"ETH/GBP","bids":[{"price":2980.96,"qty":13.15912797}],"asks":[],"checksum":3428710891,"timestamp":"2024-06-01T18:06:10.102331Z"}]}
{"channel":"book","type":"update","data":[{"symbol":"ETH/GBP","bids":[],"asks":[{"price":2981.63,"qty":0.00000000},{"price":2984.02,"qty":1.00000000}],"checksum":4051112267,"timestamp":"2024-06-01T18:06:10.108333Z"}]}
{"channel":"book","type":"update","data":[{"symbol":"ETH/GBP","bids":[],"asks":[{"price":2982.07,"qty":0.00000000},{"price":2984.09,"qty":1.31453299}],"checksum":3365670412,"timestamp":"2024-06-01T18:06:10.113002Z"}]}
{"channel":"book","type":"update","data":[{"symbol":"ETH/GBP","bids":[{"price":2981.37,"qty":0.00000000},{"price":2978.60,"qty":1.33500000}],"asks":[],"checksum":3835010977,"timestamp":"2024-06-01T18:06:10.113013Z"}]}
{"channel":"book","type":"update","data":[{"symbol":"ETH/GBP","bids":[{"price":2980.96,"qty":0.00000000},{"price":2978.11,"qty":1.31717030}],"asks":[],"checksum":2357554524,"timestamp":"2024-06-01T18:06:10.113101Z"}]}
{"channel":"book","type":"update","data":[{"symbol":"ETH/GBP","bids":[{"price":2981.19,"qty":0.00000000},{"price":2977.74,"qty":0.21600000}],"asks":[],"checksum":448259973,"timestamp":"2024-06-01T18:06:10.115737Z"}]}
{"channel":"book","type":"update","data":[{"symbol":"ETH/GBP","bids":[{"price":2981.39,"qty":0.31000000}],"asks":[],"checksum":43711931,"timestamp":"2024-06-01T18:06:10.115864Z"}]}
{"channel":"book","type":"update","data":[{"symbol":"ETH/GBP","bids":[{"price":2981.39,"qty":0.00000000},{"price":2977.74,"qty":0.21600000}],"asks":[],"checksum":448259973,"timestamp":"2024-06-01T18:06:10.116637Z"}]}
{"channel":"book","type":"update","data":[{"symbol":"ETH/GBP","bids":[],"asks":[{"price":2981.94,"qty":6.57740714}],"checksum":28835845,"timestamp":"2024-06-01T18:06:10.212137Z"}]}
{"channel":"book","type":"update","data":[{"symbol":"ETH/GBP","bids":[{"price":2981.37,"qty":6.57865109}],"asks":[],"checksum":331685884,"timestamp":"2024-06-01T18:06:10.212213Z"}]}
{"channel":"book","type":"update","data":[{"symbol":"ETH/GBP","bids":[],"asks":[{"price":2981.94,"qty":0.00000000},{"price":2984.09,"qty":1.31453299}],"checksum":4268135227,"timestamp":"2024-06-01T18:06:10.217103Z"}]}
{"channel":"book","type":"update","data":[{"symbol":"ETH/GBP","bids":[{"price":2981.37,"qty":0.00000000},{"price":2977.74,"qty":0.21600000}],"asks":[],"checksum":448259973,"timestamp":"2024-06-01T18:06:10.217263Z"}]}
{"channel":"book","type":"update","data":[{"symbol":"ETH/GBP","bids":[],"asks":[{"price":2981.94,"qty":6.57740714}],"checksum":28835845,"timestamp":"2024-06-01T18:06:10.386163Z"}]}
{"channel":"book","type":"update","data":[{"symbol":"ETH/GBP","bids":[],"asks":[{"price":2982.00,"qty":13.15455043}],"checksum":3783436754,"timestamp":"2024-06-01T18:06:10.386295Z"}]}
{"channel":"book","type":"update","data":[{"symbol":"ETH/GBP","bids":[{"price":2981.37,"qty":6.57865372}],"asks":[],"checksum":2069680988,"timestamp":"2024-06-01T18:06:10.386321Z"}]}
{"channel":"book","type":"update","data":[{"symbol":"ETH/GBP","bids":[{"price":2980.90,"qty":13.15938970}],"asks":[],"checksum":4134115591,"timestamp":"2024-06-01T18:06:10.386482Z"}]}
{"channel":"book","type":"update","data":[{"symbol":"ETH/GBP","bids":[],"asks":[{"price":2981.94,"qty":0.00000000},{"price":2984.02,"qty":1.00000000}],"checksum":535657293,"timestamp":"2024-06-01T18:06:10.393343Z"}]}
{"channel":"book","type":"update","data":[{"symbol":"ETH/GBP","bids":[{"price":2981.37,"qty":0.00000000},{"price":2978.11,"qty":1.31717030}],"asks":[],"checksum":2568932154,"timestamp":"2024-06-01T18:06:10.427545Z"}]}
{"channel":"book","type":"update","data":[{"symbol":"ETH/GBP","bids":[{"price":2980.90,"qty":0.00000000},{"price":2977.74,"qty":0.21600000}],"asks":[],"checksum":516991196,"timestamp":"2024-06-01T18:06:10.427621Z"}]}
{"channel":"book","type":"update","data":[{"symbol":"ETH/GBP","bids":[],"asks":[{"price":2982.00,"qty":0.00000000},{"price":2984.09,"qty":1.31453299}],"checksum":448259973,"timestamp":"2024-06-01T18:06:10.427856Z"}]}
{"channel":"book","type":"update","data":[{"symbol":"ETH/GBP","bids":[{"price":2981.26,"qty":0.31000000}],"asks":[],"checksum":1382200583,"timestamp":"2024-06-01T18:06:10.431134Z"}]}
{"channel":"book","type":"update","data":[{"symbol":"ETH/GBP","bids":[],"asks":[{"price":2981.94,"qty":6.57740714}],"checksum":1231901319,"timestamp":"2024-06-01T18:06:10.497113Z"}]}
{"channel":"book","type":"update","data":[{"symbol":"ETH/GBP","bids":[{"price":2981.43,"qty":6.57853047}],"asks":[],"checksum":4149852162,"timestamp":"2024-06-01T18:06:10.497181Z"}]}
{"channel":"book","type":"update","data":[{"symbol":"ETH/GBP","bids":[],"asks":[{"price":2981.94,"qty":0.00000000},{"price":2984.09,"qty":1.31453299}],"checksum":3965083522,"timestamp":"2024-06-01T18:06:10.502457Z"}]}
{"channel":"book","type":"update","data":[{"symbol":"ETH/GBP","bids":[{"price":2981.43,"qty":0.00000000},{"price":2978.11,"qty":1.31717030}],"asks":[],"checksum":1382200583,"timestamp":"2024-06-01T18:06:10.567233Z"}]}
{"channel":"book","type":"update","data":[{"symbol":"ETH/GBP","bids":[],"asks":[{"price":2981.65,"qty":6.57805089}],"checksum":250959087,"timestamp":"2024-06-01T18:06:10.603390Z"}]}
{"channel":"book","type":"update","data":[{"symbol":"ETH/GBP","bids":[{"price":2981.41,"qty":6.57856337}],"asks":[],"checksum":2201140574,"timestamp":"2024-06-01T18:06:10.603471Z"}]}
{"channel":"book","type":"update","data":[{"symbol":"ETH/GBP","bids":[],"asks":[{"price":2982.06,"qty":13.15429389}],"checksum":3772541790,"timestamp":"2024-06-01T18:06:10.603540Z"}]}
{"channel":"book","type":"update","data":[{"symbol":"ETH/GBP","bids":[{"price":2980.96,"qty":13.15913307}],"asks":[],"checksum":196448522,"timestamp":"2024-06-01T18:06:10.603710Z"}]}
{"channel":"book","type":"update","data":[{"symbol":"ETH/GBP","bids":[{"price":2981.41,"qty":0.00000000},{"price":2978.12,"qty":1.33500000}],"asks":[],"checksum":4266891284,"timestamp":"2024-06-01T18:06:10.759256Z"}]}
{"channel":"book","type":"update","data":[{"symbol":"ETH/GBP","bids":[],"asks":[{"price":2981.65,"qty":0.00000000},{"price":2984.02,"qty":1.00000000}],"checksum":2151755864,"timestamp":"2024-06-01T18:06:10.759275Z"}]}
{"channel":"book","type":"update","data":[{"symbol":"ETH/GBP","bids":[],"asks":[{"price":2981.64,"qty":6.57808510}],"checksum":3662546404,"timestamp":"2024-06-01T18:06:10.764459Z"}]}
{"channel":"book","type":"update","data":[{"symbol":"ETH/GBP","bids":[{"price":2981.39,"qty":6.57860284}],"asks":[],"checksum":484528472,"timestamp":"2024-06-01T18:06:10.764657Z"}]}
{"channel":"book","type":"update","data":[{"symbol":"ETH/GBP","bids":[{"price":2981.39,"qty":0.00000000},{"price":2978.12,"qty":1.33500000}],"asks":[],"checksum":3662546404,"timestamp":"2024-06-01T18:06:11.110694Z"}]}
{"channel":"book","type":"update","data":[{"symbol":"ETH/GBP","bids":[{"price":2981.40,"qty":6.57858537}],"asks":[],"checksum":2411050231,"timestamp":"2024-06-01T18:06:11.115232Z"}]}
{"channel":"book","type":"update","data":[{"symbol":"ETH/GBP","bids":[],"asks":[{"price":2981.64,"qty":0.00000000},{"price":2984.02,"qty":1.00000000}],"checksum":3585769803,"timestamp":"2024-06-01T18:06:11.206535Z"}]}
{"channel":"book","type":"update","data":[{"symbol":"ETH/GBP","bids":[{"price":2981.40,"qty":0.00000000},{"price":2978.12,"qty":1.33500000}],"asks":[],"checksum":2151755864,"timestamp":"2024-06-01T18:06:11.206628Z"}]}
{"channel":"book","type":"update","data":[{"symbol":"ETH/GBP","bids":[],"asks":[{"price":2981.66,"qty":6.57803962}],"checksum":879614319,"timestamp":"2024-06-01T18:06:11.211381Z"}]}
{"channel":"book","type":"update","data":[{"symbol":"ETH/GBP","bids":[{"price":2981.41,"qty":6.57855642}],"asks":[],"checksum":4080202628,"timestamp":"2024-06-01T18:06:11.215883Z"}]}
{"channel":"book","type":"update","data":[{"symbol":"ETH/GBP","bids":[{"price":2981.20,"qty":0.00000000},{"price":2978.12,"qty":1.33500000},{"price":2981.40,"qty":0.08553300}],"asks":[],"checksum":15402967,"timestamp":"2024-06-01T18:06:11.230768Z"}]}
{"channel":"book","type":"update","data":[{"symbol":"ETH/GBP","bids":[{"price":2981.41,"qty":0.00000000},{"price":2978.12,"qty":1.33500000}],"asks":[],"checksum":3328155890,"timestamp":"2024-06-01T18:06:11.260142Z"}]}
{"channel":"book","type":"update","data":[{"symbol":"ETH/GBP","bids":[{"price":2980.96,"qty":0.00000000},{"price":2978.11,"qty":1.31717030}],"asks":[],"checksum":4047830326,"timestamp":"2024-06-01T18:06:11.260230Z"}]}
{"channel":"book","type":"update","data":[{"symbol":"ETH/GBP","bids":[],"asks":[{"price":2981.66,"qty":0.00000000},{"price":2984.02,"qty":1.00000000}],"checksum":3591634378,"timestamp":"2024-06-01T18:06:11.260241Z"}]}
{"channel":"book","type":"update","data":[{"symbol":"ETH/GBP","bids":[],"asks":[{"price":2982.06,"qty":0.00000000},{"price":2984.09,"qty":1.31453299}],"checksum":1253980975,"timestamp":"2024-06-01T18:06:11.260291Z"}]}
{"channel":"book","type":"update","data":[{"symbol":"ETH/GBP","bids":[{"price":2981.05,"qty":13.15870816}],"asks":[],"checksum":1848553608,"timestamp":"2024-06-01T18:06:11.265901Z"}]}
{"channel":"book","type":"update","data":[{"symbol":"ETH/GBP","bids":[],"asks":[{"price":2982.16,"qty":13.15388702}],"checksum":2338357331,"timestamp":"2024-06-01T18:06:11.266075Z"}]}
{"channel":"book","type":"update","data":[{"symbol":"ETH/GBP","bids":[],"asks":[{"price":2981.71,"qty":6.57792845}],"checksum":2571589093,"timestamp":"2024-06-01T18:06:11.312906Z"}]}
{"channel":"book","type":"update","data":[{"symbol":"ETH/GBP","bids":[],"asks":[{"price":2981.71,"qty":0.00000000},{"price":2984.02,"qty":1.00000000}],"checksum":2338357331,"timestamp":"2024-06-01T18:06:11.318482Z"}]}
{"channel":"book","type":"update","data":[{"symbol":"ETH/GBP","bids":[{"price":2981.44,"qty":6.57849590}],"asks":[],"checksum":1020255271,"timestamp":"2024-06-01T18:06:11.323377Z"}]}
{"channel":"book","type":"update","data":[{"symbol":"ETH/GBP","bids":[{"price":2981.44,"qty":0.00000000},{"price":2978.12,"qty":1.33500000}],"asks":[],"checksum":2338357331,"timestamp":"2024-06-01T18:06:11.340736Z"}]}
{"channel":"book","type":"update","data":[{"symbol":"ETH/GBP","bids":[],"asks":[{"price":2982.96,"qty":0.00000000},{"price":2984.09,"qty":1.31453299},{"price":2982.17,"qty":0.08551500}],"checksum":1109661533,"timestamp":"2024-06-01T18:06:11.386221Z"}]}
{"channel":"book","type":"update","data":[{"symbol":"ETH/GBP","bids":[],"asks":[{"price":2981.70,"qty":6.57795213}],"checksum":3446175342,"timestamp":"2024-06-01T18:06:11.475506Z"}]}
{"channel":"book","type":"update","data":[{"symbol":"ETH/GBP","bids":[{"price":2981.46,"qty":6.57846037}],"asks":[],"checksum":424750844,"timestamp":"2024-06-01T18:06:11.475668Z"}]}
{"channel":"book","type":"update","data":[{"symbol":"ETH/GBP","bids":[{"price":2981.46,"qty":0.00000000},{"price":2978.12,"qty":1.33500000}],"asks":[],"checksum":3446175342,"timestamp":"2024-06-01T18:06:11.726393Z"}]}
{"channel":"book","type":"update","data":[{"symbol":"ETH/GBP","bids":[{"price":2981.48,"qty":6.57841538}],"asks":[],"checksum":1944608964,"timestamp":"2024-06-01T18:06:11.730824Z"}]}
{"channel":"book","type":"update","data":[{"symbol":"ETH/GBP","bids":[],"asks":[{"price":2981.70,"qty":0.00000000},{"price":2984.02,"qty":1.00000000}],"checksum":4238606839,"timestamp":"2024-06-01T18:06:11.766390Z"}]}
{"channel":"book","type":"update","data":[{"symbol":"ETH/GBP","bids":[{"price":2981.48,"qty":0.00000000},{"price":2978.12,"qty":1.33500000}],"asks":[],"checksum":1109661533,"timestamp":"2024-06-01T18:06:11.766515Z"}]}
{"channel":"book","type":"update","data":[{"symbol":"ETH/GBP","bids":[],"asks":[{"price":2982.72,"qty":0.00000000},{"price":2984.09,"qty":1.31453299}],"checksum":1230439706,"timestamp":"2024-06-01T18:06:11.768691Z"}]}
{"channel":"book","type":"update","data":[{"symbol":"ETH/GBP","bids":[],"asks":[{"price":2981.76,"qty":6.57782468}],"checksum":1693538124,"timestamp":"2024-06-01T18:06:11.772861Z"}]}
{"channel":"book","type":"update","data":[{"symbol":"ETH/GBP","bids":[],"asks":[{"price":2982.94,"qty":1.31504059}],"checksum":3287342400,"timestamp":"2024-06-01T18:06:11.772982Z"}]}
{"channel":"book","type":"update","data":[{"symbol":"ETH/GBP","bids":[],"asks":[{"price":2981.76,"qty":0.00000000},{"price":2984.02,"qty":1.00000000}],"checksum":109662027,"timestamp":"2024-06-01T18:06:11.796343Z"}]}
{"channel":"book","type":"update","data":[{"symbol":"ETH/GBP","bids":[],"asks":[{"price":2982.16,"qty":0.00000000},{"price":2984.09,"qty":1.31453299}],"checksum":2801783818,"timestamp":"2024-06-01T18:06:11.796362Z"}]}
{"channel":"book","type":"update","data":[{"symbol":"ETH/GBP","bids":[{"price":2981.05,"qty":0.00000000},{"price":2978.11,"qty":1.31717030}],"asks":[],"checksum":1284192541,"timestamp":"2024-06-01T18:06:11.796370Z"}]}
{"channel":"book","type":"update","data":[{"symbol":"ETH/GBP","bids":[{"price":2981.15,"qty":13.15829365}],"asks":[],"checksum":604323780,"timestamp":"2024-06-01T18:06:11.801356Z"}]}
{"channel":"book","type":"update","data":[{"symbol":"ETH/GBP","bids":[],"asks":[{"price":2982.24,"qty":13.15350685}],"checksum":2858857855,"timestamp":"2024-06-01T18:06:11.801471Z"}]}
{"channel":"book","type":"update","data":[{"symbol":"ETH/GBP","bids":[],"asks":[{"price":2981.95,"qty":0.00000000},{"price":2984.09,"qty":1.31453299}],"checksum":628989735,"timestamp":"2024-06-01T18:06:11.817625Z"}]}
{"channel":"book","type":"update","data":[{"symbol":"ETH/GBP","bids":[],"asks":[{"price":2983.32,"qty":0.00000000},{"price":2984.26,"qty":0.27444212}],"checksum":1984421280,"timestamp":"2024-06-01T18:06:11.817787Z"}]}
{"channel":"book","type":"update","data":[{"symbol":"ETH/GBP","bids":[],"asks":[{"price":2982.15,"qty":6.72549440}],"checksum":721682920,"timestamp":"2024-06-01T18:06:11.823142Z"}]}
{"channel":"book","type":"update","data":[{"symbol":"ETH/GBP","bids":[],"asks":[{"price":2983.32,"qty":23.11104131}],"checksum":683230272,"timestamp":"2024-06-01T18:06:11.823212Z"}]}
{"channel":"book","type":"update","data":[{"symbol":"ETH/GBP","bids":[{"price":2981.41,"qty":6.57857640}],"asks":[],"checksum":1919945188,"timestamp":"2024-06-01T18:06:11.837217Z"}]}
{"channel":"book","type":"update","data":[{"symbol":"ETH/GBP","bids":[{"price":2981.26,"qty":0.00000000},{"price":2978.12,"qty":1.33500000}],"asks":[],"checksum":3345367378,"timestamp":"2024-06-01T18:06:11.840403Z"}]}
{"channel":"book","type":"update","data":[{"symbol":"ETH/GBP","bids":[{"price":2981.42,"qty":0.31000000}],"asks":[],"checksum":2294673981,"timestamp":"2024-06-01T18:06:11.840595Z"}]}
{"channel":"book","type":"update","data":[{"symbol":"ETH/GBP","bids":[{"price":2981.41,"qty":0.00000000},{"price":2978.12,"qty":1.33500000}],"asks":[],"checksum":1844066034,"timestamp":"2024-06-01T18:06:11.849413Z"}]}
{"channel":"book","type":"update","data":[{"symbol":"ETH/GBP","bids":[],"asks":[{"price":2982.14,"qty":6.57696602}],"checksum":583041531,"timestamp":"2024-06-01T18:06:11.880837Z"}]}
{"channel":"book","type":"update","data":[{"symbol":"ETH/GBP","bids":[],"asks":[{"price":2982.14,"qty":0.00000000},{"price":2984.02,"qty":1.00000000}],"checksum":1844066034,"timestamp":"2024-06-01T18:06:11.885540Z"}]}
{"channel":"book","type":"update","data":[{"symbol":"ETH/GBP","bids":[{"price":2979.33,"qty":0.00000000},{"price":2978.11,"qty":1.31717030}],"asks":[],"checksum":45835120,"timestamp":"2024-06-01T18:06:11.916121Z"}]}
{"channel":"book","type":"update","data":[{"symbol":"ETH/GBP","bids":[{"price":2979.73,"qty":1.31645679}],"asks":[],"checksum":2773233870,"timestamp":"2024-06-01T18:06:11.920844Z"}]}
{"channel":"book","type":"update","data":[{"symbol":"ETH/GBP","bids":[],"asks":[{"price":2983.33,"qty":0.00000000},{"price":2984.09,"qty":1.31453299}],"checksum":1266409008,"timestamp":"2024-06-01T18:06:11.976406Z"}]}
{"channel":"book","type":"update","data":[{"symbol":"ETH/GBP","bids":[],"asks":[{"price":2983.47,"qty":15.52712143}],"checksum":2860573766,"timestamp":"2024-06-01T18:06:11.981038Z"}]}
{"channel":"book","type":"update","data":[{"symbol":"ETH/GBP","bids":[{"price":2981.43,"qty":6.57853227}],"asks":[],"checksum":1960716741,"timestamp":"2024-06-01T18:06:11.984005Z"}]}
{"channel":"book","type":"update","data":[{"symbol":"ETH/GBP","bids":[{"price":2981.15,"qty":0.00000000},{"price":2978.12,"qty":1.33500000}],"asks":[],"checksum":3341108200,"timestamp":"2024-06-01T18:06:11.984049Z"}]}
{"channel":"book","type":"update","data":[{"symbol":"ETH/GBP","bids":[],"asks":[{"price":2982.24,"qty":0.00000000},{"price":2984.09,"qty":1.31453299}],"checksum":2332784947,"timestamp":"2024-06-01T18:06:11.984123Z"}]}
{"channel":"book","type":"update","data":[{"symbol":"ETH/GBP","bids":[],"asks":[{"price":2984.09,"qty":0.00000000},{"price":2984.26,"qty":0.27444212}],"checksum":2801617241,"timestamp":"2024-06-01T18:06:11.984502Z"}]}
{"channel":"book","type":"update","data":[{"symbol":"ETH/GBP","bids":[{"price":2980.26,"qty":0.00000000},{"price":2978.11,"qty":1.31717030}],"asks":[],"checksum":2405238447,"timestamp":"2024-06-01T18:06:11.984606Z"}]}
{"channel":"book","type":"update","data":[{"symbol":"ETH/GBP","bids":[],"asks":[{"price":2982.17,"qty":0.00000000},{"price":2984.35,"qty":0.30200000},{"price":2982.73,"qty":0.08550600}],"checksum":3068236459,"timestamp":"2024-06-01T18:06:11.995689Z"}]}
{"channel":"book","type":"update","data":[{"symbol":"ETH/GBP","bids":[{"price":2978.13,"qty":0.34390000}],"asks":[],"checksum":3796989526,"timestamp":"2024-06-01T18:06:11.996553Z"}]}
{"channel":"book","type":"update","data":[{"symbol":"ETH/GBP","bids":[{"price":2981.43,"qty":0.00000000},{"price":2978.11,"qty":1.31717030}],"asks":[],"checksum":1628542084,"timestamp":"2024-06-01T18:06:11.998102Z"}]}
{"channel":"book","type":"update","data":[{"symbol":"ETH/GBP","bids":[],"asks":[{"price":2982.94,"qty":0.00000000},{"price":2984.35,"qty":0.30200000}],"checksum":829208351,"timestamp":"2024-06-01T18:06:11.998193Z"}]}
{"channel":"book","type":"update","data":[{"symbol":"ETH/GBP","bids":[{"price":2981.34,"qty":13.15744770}],"asks":[],"checksum":580459696,"timestamp":"2024-06-01T18:06:12.007436Z"}]}
{"channel":"book","type":"update","data":[{"symbol":"ETH/GBP","bids":[],"asks":[{"price":2982.14,"qty":6.57696602}],"checksum":1460299473,"timestamp":"2024-06-01T18:06:12.007480Z"}]}
{"channel":"book","type":"update","data":[{"symbol":"ETH/GBP","bids":[],"asks":[{"price":2982.39,"qty":13.15287175}],"checksum":3805057282,"timestamp":"2024-06-01T18:06:12.007503Z"}]}
{"channel":"book","type":"update","data":[{"symbol":"ETH/GBP","bids":[{"price":2980.49,"qty":1.31611867}],"asks":[],"checksum":647191584,"timestamp":"2024-06-01T18:06:12.007555Z"}]}
{"channel":"book","type":"update","data":[{"symbol":"ETH/GBP","bids":[{"price":2978.14,"qty":1.33500000}],"asks":[],"checksum":2126419496,"timestamp":"2024-06-01T18:06:12.009824Z"}]}
{"channel":"book","type":"update","data":[{"symbol":"ETH/GBP","bids":[],"asks":[{"price":2982.14,"qty":0.00000000},{"price":2984.26,"qty":0.27444212}],"checksum":3739362950,"timestamp":"2024-06-01T18:06:12.023767Z"}]}
{"channel":"book","type":"update","data":[{"symbol":"ETH/GBP","bids":[{"price":2978.86,"qty":0.21300000}],"asks":[],"checksum":583697583,"timestamp":"2024-06-01T18:06:12.043161Z"}]}
{"channel":"book","type":"update","data":[{"symbol":"ETH/GBP","bids":[{"price":2981.43,"qty":6.57853227}],"asks":[],"checksum":2730193598,"timestamp":"2024-06-01T18:06:12.089278Z"}]}
{"channel":"book","type":"update","data":[{"symbol":"ETH/GBP","bids":[{"price":2981.43,"qty":0.00000000},{"price":2978.76,"qty":0.27441483}],"asks":[],"checksum":583697583,"timestamp":"2024-06-01T18:06:12.100345Z"}]}
{"channel":"book","type":"update","data":[{"symbol":"ETH/GBP","bids":[],"asks":[{"price":2981.97,"qty":6.57734743}],"checksum":2003198851,"timestamp":"2024-06-01T18:06:12.109344Z"}]}
{"channel":"book","type":"update","data":[{"symbol":"ETH/GBP","bids":[],"asks":[{"price":2981.97,"qty":0.00000000},{"price":2984.35,"qty":0.30200000}],"checksum":496492175,"timestamp":"2024-06-01T18:06:12.151623Z"}]}
{"channel":"book","type":"update","data":[{"symbol":"ETH/GBP","bids":[{"price":2981.34,"qty":0.00000000},{"price":2978.14,"qty":1.33500000}],"asks":[],"checksum":2728976893,"timestamp":"2024-06-01T18:06:12.151688Z"}]}
{"channel":"book","type":"update","data":[{"symbol":"ETH/GBP","bids":[],"asks":[{"price":2981.95,"qty":6.57738891}],"checksum":1494133816,"timestamp":"2024-06-01T18:06:12.226224Z"}]}
{"channel":"book","type":"update","data":[{"symbol":"ETH/GBP","bids":[{"price":2981.43,"qty":6.57853227}],"asks":[],"checksum":963771049,"timestamp":"2024-06-01T18:06:12.226290Z"}]}
{"channel":"book","type":"update","data":[{"symbol":"ETH/GBP","bids":[{"price":2981.27,"qty":13.15773085}],"asks":[],"checksum":3303566930,"timestamp":"2024-06-01T18:06:12.226306Z"}]}
{"channel":"book","type":"update","data":[{"symbol":"ETH/GBP","bids":[{"price":2981.43,"qty":0.00000000},{"price":2978.76,"qty":0.27441483}],"asks":[],"checksum":776949898,"timestamp":"2024-06-01T18:06:12.231256Z"}]}
{"channel":"book","type":"update","data":[{"symbol":"ETH/GBP","bids":[],"asks":[{"price":2981.95,"qty":0.00000000},{"price":2984.35,"qty":0.30200000}],"checksum":3317350648,"timestamp":"2024-06-01T18:06:12.266907Z"}]}
{"channel":"book","type":"update","data":[{"symbol":"ETH/GBP","bids":[],"asks":[{"price":2982.39,"qty":0.00000000},{"price":2984.40,"qty":2.94416492}],"checksum":2264186608,"timestamp":"2024-06-01T18:06:12.268985Z"}]}
{"channel":"book","type":"update","data":[{"symbol":"ETH/GBP","bids":[{"price":2981.27,"qty":0.00000000},{"price":2978.14,"qty":1.33500000}],"asks":[],"checksum":2235532181,"timestamp":"2024-06-01T18:06:12.268996Z"}]}
{"channel":"book","type":"update","data":[{"symbol":"ETH/GBP","bids":[],"asks":[{"price":2982.49,"qty":13.15239641}],"checksum":3682301052,"timestamp":"2024-06-01T18:06:12.273929Z"}]}
{"channel":"book","type":"update","data":[{"symbol":"ETH/GBP","bids":[],"asks":[{"price":2982.49,"qty":0.00000000},{"price":2984.40,"qty":2.94416492}],"checksum":2235532181,"timestamp":"2024-06-01T18:06:12.278193Z"}]}
{"channel":"book","type":"update","data":[{"symbol":"ETH/GBP","bids":[],"asks":[{"price":2983.61,"qty":0.00000000},{"price":2984.86,"qty":1.33800000}],"checksum":2189988837,"timestamp":"2024-06-01T18:06:12.278255Z"}]}
{"channel":"book","type":"update","data":[{"symbol":"ETH/GBP","bids":[],"asks":[{"price":2984.03,"qty":1.31456248}],"checksum":2971612164,"timestamp":"2024-06-01T18:06:12.284103Z"}]}
{"channel":"book","type":"update","data":[{"symbol":"ETH/GBP","bids":[{"price":2981.43,"qty":6.57853227}],"asks":[],"checksum":3512754837,"timestamp":"2024-06-01T18:06:12.334735Z"}]}
{"channel":"book","type":"update","data":[{"symbol":"ETH/GBP","bids":[],"asks":[{"price":2982.02,"qty":6.57723355}],"checksum":2607032994,"timestamp":"2024-06-01T18:06:12.334857Z"}]}
{"channel":"book","type":"update","data":[{"symbol":"ETH/GBP","bids":[{"price":2981.43,"qty":0.00000000},{"price":2978.14,"qty":1.33500000}],"asks":[],"checksum":4212882483,"timestamp":"2024-06-01T18:06:12.340548Z"}]}
{"channel":"book","type":"update","data":[{"symbol":"ETH/GBP","bids":[],"asks":[{"price":2982.02,"qty":0.00000000},{"price":2984.40,"qty":2.94416492}],"checksum":2971612164,"timestamp":"2024-06-01T18:06:12.340886Z"}]}
{"channel":"book","type":"update","data":[{"symbol":"ETH/GBP","bids":[{"price":2978.14,"qty":0.00000000},{"price":2978.13,"qty":0.34390000},{"price":2978.89,"qty":1.33500000}],"asks":[],"checksum":3807086347,"timestamp":"2024-06-01T18:06:12.418074Z"}]}
{"channel":"book","type":"update","data":[{"symbol":"ETH/GBP","bids":[{"price":2981.37,"qty":13.15732011}],"asks":[],"checksum":1504653269,"timestamp":"2024-06-01T18:06:12.427595Z"}]}
{"channel":"book","type":"update","data":[{"symbol":"ETH/GBP","bids":[],"asks":[{"price":2982.00,"qty":6.57728925}],"checksum":2415828573,"timestamp":"2024-06-01T18:06:12.441384Z"}]}
{"channel":"book","type":"update","data":[{"symbol":"ETH/GBP","bids":[{"price":2981.76,"qty":6.57778800}],"asks":[],"checksum":1315936045,"timestamp":"2024-06-01T18:06:12.441451Z"}]}
{"channel":"book","type":"update","data":[{"symbol":"ETH/GBP","bids":[],"asks":[{"price":2982.00,"qty":0.00000000},{"price":2984.40,"qty":2.94416492}],"checksum":2916797838,"timestamp":"2024-06-01T18:06:12.571066Z"}]}
{"channel":"book","type":"update","data":[{"symbol":"ETH/GBP","bids":[{"price":2981.37,"qty":0.00000000},{"price":2978.86,"qty":0.21300000}],"asks":[],"checksum":2825631840,"timestamp":"2024-06-01T18:06:12.571110Z"}]}
{"channel":"book","type":"update","data":[{"symbol":"ETH/GBP","bids":[{"price":2981.76,"qty":0.00000000},{"price":2978.76,"qty":0.27441483}],"asks":[],"checksum":3807086347,"timestamp":"2024-06-01T18:06:12.571121Z"}]}
{"channel":"book","type":"update","data":[{"symbol":"ETH/GBP","bids":[{"price":2981.74,"qty":6.57782782}],"asks":[],"checksum":3453491650,"timestamp":"2024-06-01T18:06:12.578114Z"}]}
{"channel":"book","type":"update","data":[{"symbol":"ETH/GBP","bids":[],"asks":[{"price":2982.43,"qty":13.15266210}],"checksum":2269310319,"timestamp":"2024-06-01T18:06:12.578271Z"}]}
{"channel":"book","type":"update","data":[{"symbol":"ETH/GBP","bids":[],"asks":[{"price":2981.98,"qty":6.57732448}],"checksum":2364316600,"timestamp":"2024-06-01T18:06:12.578287Z"}]}
{"channel":"book","type":"update","data":[{"symbol":"ETH/GBP","bids":[],"asks":[{"price":2981.98,"qty":0.00000000},{"price":2984.35,"qty":0.30200000}],"checksum":2269310319,"timestamp":"2024-06-01T18:06:12.600189Z"}]}
{"channel":"book","type":"update","data":[{"symbol":"ETH/GBP","bids":[{"price":2981.74,"qty":0.00000000},{"price":2978.76,"qty":0.27441483}],"asks":[],"checksum":2814012271,"timestamp":"2024-06-01T18:06:12.600253Z"}]}
{"channel":"book","type":"update","data":[{"symbol":"ETH/GBP","bids":[],"asks":[{"price":2982.43,"qty":0.00000000},{"price":2984.40,"qty":2.94416492}],"checksum":3807086347,"timestamp":"2024-06-01T18:06:12.638342Z"}]}
{"channel":"book","type":"update","data":[{"symbol":"ETH/GBP","bids":[{"price":2981.31,"qty":13.15757249}],"asks":[],"checksum":899542852,"timestamp":"2024-06-01T18:06:12.642601Z"}]}
{"channel":"book","type":"update","data":[{"symbol":"ETH/GBP","bids":[],"asks":[{"price":2981.94,"qty":6.57742184}],"checksum":4206860086,"timestamp":"2024-06-01T18:06:12.679133Z"}]}
{"channel":"book","type":"update","data":[{"symbol":"ETH/GBP","bids":[{"price":2981.43,"qty":6.57853227}],"asks":[],"checksum":1147474965,"timestamp":"2024-06-01T18:06:12.679150Z"}]}
{"channel":"book","type":"update","data":[{"symbol":"ETH/GBP","bids":[{"price":2981.43,"qty":0.00000000},{"price":2978.86,"qty":0.21300000}],"asks":[],"checksum":4206860086,"timestamp":"2024-06-01T18:06:12.684046Z"}]}
{"channel":"book","type":"update","data":[{"symbol":"ETH/GBP","bids":[],"asks":[{"price":2981.94,"qty":0.00000000},{"price":2984.40,"qty":2.94416492}],"checksum":899542852,"timestamp":"2024-06-01T18:06:12.714648Z"}]}
{"channel":"book","type":"update","data":[{"symbol":"ETH/GBP","bids":[{"price":2981.31,"qty":0.00000000},{"price":2978.76,"qty":0.27441483}],"asks":[],"checksum":3807086347,"timestamp":"2024-06-01T18:06:12.749332Z"}]}
{"channel":"book","type":"update","data":[{"symbol":"ETH/GBP","bids":[],"asks":[{"price":2981.94,"qty":6.57742657}],"checksum":3634261850,"timestamp":"2024-06-01T18:06:12.800929Z"}]}
{"channel":"book","type":"update","data":[{"symbol":"ETH/GBP","bids":[{"price":2981.69,"qty":6.57794164}],"asks":[],"checksum":3385483282,"timestamp":"2024-06-01T18:06:12.800943Z"}]}
{"channel":"book","type":"update","data":[{"symbol":"ETH/GBP","bids":[],"asks":[{"price":2983.21,"qty":1.31492538}],"checksum":1759727224,"timestamp":"2024-06-01T18:06:12.801049Z"}]}
{"channel":"book","type":"update","data":[{"symbol":"ETH/GBP","bids":[],"asks":[{"price":2982.38,"qty":13.15289302}],"checksum":796009160,"timestamp":"2024-06-01T18:06:12.801116Z"}]}
{"channel":"book","type":"update","data":[{"symbol":"ETH/GBP","bids":[{"price":2981.69,"qty":0.00000000},{"price":2978.76,"qty":0.27441483}],"asks":[],"checksum":58766357,"timestamp":"2024-06-01T18:06:12.806242Z"}]}
{"channel":"book","type":"update","data":[{"symbol":"ETH/GBP","bids":[],"asks":[{"price":2981.94,"qty":0.00000000},{"price":2984.03,"qty":1.31456248}],"checksum":1302984394,"timestamp":"2024-06-01T18:06:12.806357Z"}]}
{"channel":"book","type":"update","data":[{"symbol":"ETH/GBP","bids":[{"price":2981.25,"qty":13.15783965}],"asks":[],"checksum":3138538789,"timestamp":"2024-06-01T18:06:12.844701Z"}]}
{"channel":"book","type":"update","data":[{"symbol":"ETH/GBP","bids":[],"asks":[{"price":2981.91,"qty":6.57747653}],"checksum":995647675,"timestamp":"2024-06-01T18:06:12.993433Z"}]}
{"channel":"book","type":"update","data":[{"symbol":"ETH/GBP","bids":[{"price":2981.43,"qty":6.57853227}],"asks":[],"checksum":3956712473,"timestamp":"2024-06-01T18:06:12.993657Z"}]}
{"channel":"book","type":"update","data":[{"symbol":"ETH/GBP","bids":[{"price":2981.43,"qty":0.00000000},{"price":2978.86,"qty":0.21300000}],"asks":[],"checksum":995647675,"timestamp":"2024-06-01T18:06:12.998380Z"}]}
{"channel":"book","type":"update","data":[{"symbol":"ETH/GBP","bids":[{"price":2981.68,"qty":6.57797477}],"asks":[],"checksum":52172315,"timestamp":"2024-06-01T18:06:13.208044Z"}]}
{"channel":"book","type":"update","data":[{"symbol":"ETH/GBP","bids":[{"price":2981.68,"qty":0.00000000},{"price":2978.86,"qty":0.21300000}],"asks":[],"checksum":995647675,"timestamp":"2024-06-01T18:06:13.233382Z"}]}
{"channel":"book","type":"update","data":[{"symbol":"ETH/GBP","bids":[],"asks":[{"price":2981.91,"qty":0.00000000},{"price":2984.03,"qty":1.31456248}],"checksum":3138538789,"timestamp":"2024-06-01T18:06:13.233477Z"}]}
{"channel":"book","type":"update","data":[{"symbol":"ETH/GBP","bids":[],"asks":[{"price":2981.92,"qty":6.57745745}],"checksum":671495223,"timestamp":"2024-06-01T18:06:13.239651Z"}]}
{"channel":"book","type":"update","data":[{"symbol":"ETH/GBP","bids":[],"asks":[{"price":2981.92,"qty":0.00000000},{"price":2984.03,"qty":1.31456248}],"checksum":3138538789,"timestamp":"2024-06-01T18:06:13.243702Z"}]}
{"channel":"book","type":"update","data":[{"symbol":"ETH/GBP","bids":[{"price":2981.68,"qty":6.57797346}],"asks":[],"checksum":2516329134,"timestamp":"2024-06-01T18:06:13.385357Z"}]}
{"channel":"book","type":"update","data":[{"symbol":"ETH/GBP","bids":[],"asks":[{"price":2982.14,"qty":6.57696602}],"checksum":2325323583,"timestamp":"2024-06-01T18:06:13.385395Z"}]}
{"channel":"book","type":"update","data":[{"symbol":"ETH/GBP","bids":[],"asks":[{"price":2982.14,"qty":0.00000000},{"price":2984.03,"qty":1.31456248}],"checksum":2516329134,"timestamp":"2024-06-01T18:06:13.390492Z"}]}
{"channel":"book","type":"update","data":[{"symbol":"ETH/GBP","bids":[],"asks":[{"price":2981.92,"qty":6.57746560}],"checksum":3079887105,"timestamp":"2024-06-01T18:06:13.529680Z"}]}
{"channel":"book","type":"update","data":[{"symbol":"ETH/GBP","bids":[],"asks":[{"price":2981.92,"qty":0.00000000},{"price":2984.03,"qty":1.31456248}],"checksum":2516329134,"timestamp":"2024-06-01T18:06:13.701982Z"}]}
{"channel":"book","type":"update","data":[{"symbol":"ETH/GBP","bids":[],"asks":[{"price":2981.91,"qty":6.57749229}],"checksum":2529638581,"timestamp":"2024-06-01T18:06:13.706187Z"}]}
{"channel":"book","type":"update","data":[{"symbol":"ETH/GBP","bids":[{"price":2981.68,"qty":0.00000000},{"price":2978.86,"qty":0.21300000}],"asks":[],"checksum":921328295,"timestamp":"2024-06-01T18:06:13.711657Z"}]}
{"channel":"book","type":"update","data":[{"symbol":"ETH/GBP","bids":[],"asks":[{"price":2981.91,"qty":0.00000000},{"price":2984.03,"qty":1.31456248}],"checksum":3138538789,"timestamp":"2024-06-01T18:06:13.711725Z"}]}
{"channel":"book","type":"update","data":[{"symbol":"ETH/GBP","bids":[],"asks":[{"price":2982.38,"qty":0.00000000},{"price":2984.35,"qty":0.30200000}],"checksum":2622570478,"timestamp":"2024-06-01T18:06:13.711855Z"}]}
{"channel":"book","type":"update","data":[{"symbol":"ETH/GBP","bids":[],"asks":[{"price":2982.32,"qty":13.15314066}],"checksum":1732575717,"timestamp":"2024-06-01T18:06:13.716832Z"}]}
{"channel":"book","type":"update","data":[{"symbol":"ETH/GBP","bids":[{"price":2981.65,"qty":6.57803531}],"asks":[],"checksum":2076895806,"timestamp":"2024-06-01T18:06:13.716938Z"}]}
{"channel":"book","type":"update","data":[{"symbol":"ETH/GBP","bids":[{"price":2981.65,"qty":0.00000000},{"price":2978.86,"qty":0.21300000}],"asks":[],"checksum":1732575717,"timestamp":"2024-06-01T18:06:13.781291Z"}]}
{"channel":"book","type":"update","data":[{"symbol":"ETH/GBP","bids":[],"asks":[{"price":2982.14,"qty":6.57696602}],"checksum":1111299289,"timestamp":"2024-06-01T18:06:13.934207Z"}]}
{"channel":"book","type":"update","data":[{"symbol":"ETH/GBP","bids":[{"price":2981.67,"qty":6.57799714}],"asks":[],"checksum":3829643779,"timestamp":"2024-06-01T18:06:13.934335Z"}]}
{"channel":"book","type":"update","data":[{"symbol":"ETH/GBP","bids":[],"asks":[{"price":2982.14,"qty":0.00000000},{"price":2984.03,"qty":1.31456248}],"checksum":3406413457,"timestamp":"2024-06-01T18:06:13.939320Z"}]}
{"channel":"book","type":"update","data":[{"symbol":"ETH/GBP","bids":[],"asks":[{"price":2982.15,"qty":0.00000000},{"price":2984.35,"qty":0.30200000}],"checksum":1785020172,"timestamp":"2024-06-01T18:06:14.150851Z"}]}
{"channel":"book","type":"update","data":[{"symbol":"ETH/GBP","bids":[],"asks":[{"price":2983.32,"qty":0.00000000},{"price":2984.40,"qty":2.94416492}],"checksum":2663262550,"timestamp":"2024-06-01T18:06:14.150915Z"}]}
{"channel":"book","type":"update","data":[{"symbol":"ETH/GBP","bids":[],"asks":[{"price":2982.31,"qty":5.69223145}],"checksum":47866086,"timestamp":"2024-06-01T18:06:14.155637Z"}]}
{"channel":"book","type":"update","data":[{"symbol":"ETH/GBP","bids":[],"asks":[{"price":2983.46,"qty":17.99291266}],"checksum":3421347803,"timestamp":"2024-06-01T18:06:14.155724Z"}]}
{"channel":"book","type":"update","data":[{"symbol":"ETH/GBP","bids":[],"asks":[{"price":2982.30,"qty":0.10990113}],"checksum":571273968,"timestamp":"2024-06-01T18:06:14.259576Z"}]}
{"channel":"book","type":"update","data":[{"symbol":"ETH/GBP","bids":[],"asks":[{"price":2981.89,"qty":6.57751889}],"checksum":2523472279,"timestamp":"2024-06-01T18:06:14.471309Z"}]}
{"channel":"book","type":"update","data":[{"symbol":"ETH/GBP","bids":[],"asks":[{"price":2982.30,"qty":0.00000000},{"price":2984.02,"qty":1.00000000}],"checksum":3643765539,"timestamp":"2024-06-01T18:06:14.475398Z"}]}
{"channel":"book","type":"update","data":[{"symbol":"ETH/GBP","bids":[{"price":2981.67,"qty":0.00000000},{"price":2978.86,"qty":0.21300000}],"asks":[],"checksum":4133610428,"timestamp":"2024-06-01T18:06:14.874831Z"}]}
{"channel":"book","type":"update","data":[{"symbol":"ETH/GBP","bids":[{"price":2981.65,"qty":6.57802923}],"asks":[],"checksum":3724891444,"timestamp":"2024-06-01T18:06:14.879825Z"}]}
{"channel":"book","type":"update","data":[{"symbol":"ETH/GBP","bids":[{"price":2981.65,"qty":0.00000000},{"price":2978.86,"qty":0.21300000}],"asks":[],"checksum":4133610428,"timestamp":"2024-06-01T18:06:14.926500Z"}]}
{"channel":"book","type":"update","data":[{"symbol":"ETH/GBP","bids":[{"price":2981.66,"qty":6.57801608}],"asks":[],"checksum":2693259278,"timestamp":"2024-06-01T18:06:15.163501Z"}]}
{"channel":"book","type":"update","data":[{"symbol":"ETH/GBP","bids":[{"price":2981.66,"qty":0.00000000},{"price":2978.86,"qty":0.21300000}],"asks":[],"checksum":4133610428,"timestamp":"2024-06-01T18:06:15.293348Z"}]}
{"channel":"book","type":"update","data":[{"symbol":"ETH/GBP","bids":[],"asks":[{"price":2981.89,"qty":0.00000000},{"price":2984.03,"qty":1.31456248}],"checksum":2204388325,"timestamp":"2024-06-01T18:06:15.293359Z"}]}
{"channel":"book","type":"update","data":[{"symbol":"ETH/GBP","bids":[{"price":2981.25,"qty":0.00000000},{"price":2978.76,"qty":0.27441483}],"asks":[],"checksum":1489444386,"timestamp":"2024-06-01T18:06:15.293404Z"}]}
{"channel":"book","type":"update","data":[{"symbol":"ETH/GBP","bids":[],"asks":[{"price":2982.32,"qty":0.00000000},{"price":2984.35,"qty":0.30200000}],"checksum":2090589385,"timestamp":"2024-06-01T18:06:15.295676Z"}]}
{"channel":"book","type":"update","data":[{"symbol":"ETH/GBP","bids":[],"asks":[{"price":2983.21,"qty":0.00000000},{"price":2984.40,"qty":2.94416492}],"checksum":3264788941,"timestamp":"2024-06-01T18:06:15.295866Z"}]}
{"channel":"book","type":"update","data":[{"symbol":"ETH/GBP","bids":[],"asks":[{"price":2982.30,"qty":0.10990113}],"checksum":2616200612,"timestamp":"2024-06-01T18:06:15.298067Z"}]}
{"channel":"book","type":"update","data":[{"symbol":"ETH/GBP","bids":[],"asks":[{"price":2982.99,"qty":0.00000000},{"price":2984.40,"qty":2.94416492}],"checksum":1773626798,"timestamp":"2024-06-01T18:06:15.298670Z"}]}
{"channel":"book","type":"update","data":[{"symbol":"ETH/GBP","bids":[{"price":2981.53,"qty":6.57830388}],"asks":[],"checksum":3691510831,"timestamp":"2024-06-01T18:06:15.303648Z"}]}
{"channel":"book","type":"update","data":[{"symbol":"ETH/GBP","bids":[{"price":2981.11,"qty":13.15846967}],"asks":[],"checksum":1050187412,"timestamp":"2024-06-01T18:06:15.303667Z"}]}
{"channel":"book","type":"update","data":[{"symbol":"ETH/GBP","bids":[],"asks":[{"price":2981.75,"qty":6.57783243}],"checksum":1089792739,"timestamp":"2024-06-01T18:06:15.303685Z"}]}
{"channel":"book","type":"update","data":[{"symbol":"ETH/GBP","bids":[],"asks":[{"price":2982.97,"qty":1.31503124}],"checksum":2949079167,"timestamp":"2024-06-01T18:06:15.303748Z"}]}
{"channel":"book","type":"update","data":[{"symbol":"ETH/GBP","bids":[],"asks":[{"price":2982.30,"qty":13.26312747}],"checksum":368434557,"timestamp":"2024-06-01T18:06:15.303988Z"}]}
{"channel":"book","type":"update","data":[{"symbol":"ETH/GBP","bids":[],"asks":[{"price":2982.30,"qty":13.15322634}],"checksum":1255515216,"timestamp":"2024-06-01T18:06:15.307213Z"}]}
{"channel":"book","type":"update","data":[{"symbol":"ETH/GBP","bids":[],"asks":[{"price":2982.30,"qty":0.00000000},{"price":2984.35,"qty":0.30200000}],"checksum":3283507408,"timestamp":"2024-06-01T18:06:15.310543Z"}]}
{"channel":"book","type":"update","data":[{"symbol":"ETH/GBP","bids":[{"price":2978.89,"qty":0.00000000},{"price":2978.86,"qty":0.21300000}],"asks":[],"checksum":218832151,"timestamp":"2024-06-01T18:06:15.311395Z"}]}
{"channel":"book","type":"update","data":[{"symbol":"ETH/GBP","bids":[{"price":2981.53,"qty":0.00000000},{"price":2978.76,"qty":0.27441483}],"asks":[],"checksum":3996913898,"timestamp":"2024-06-01T18:06:15.334782Z"}]}
{"channel":"book","type":"update","data":[{"symbol":"ETH/GBP","bids":[],"asks":[{"price":2981.75,"qty":0.00000000},{"price":2984.40,"qty":2.94416492}],"checksum":313092914,"timestamp":"2024-06-01T18:06:15.343990Z"}]}
{"channel":"book","type":"update","data":[{"symbol":"ETH/GBP","bids":[],"asks":[{"price":2982.30,"qty":0.10990113}],"checksum":3302993367,"timestamp":"2024-06-01T18:06:15.347933Z"}]}
{"channel":"book","type":"update","data":[{"symbol":"ETH/GBP","bids":[{"price":2981.52,"qty":6.57831573}],"asks":[],"checksum":2522533766,"timestamp":"2024-06-01T18:06:15.421558Z"}]}
{"channel":"book","type":"update","data":[{"symbol":"ETH/GBP","bids":[],"asks":[{"price":2982.29,"qty":6.57663522}],"checksum":2865830560,"timestamp":"2024-06-01T18:06:15.421785Z"}]}
{"channel":"book","type":"update","data":[{"symbol":"ETH/GBP","bids":[],"asks":[{"price":2982.30,"qty":0.00000000},{"price":2984.35,"qty":0.30200000}],"checksum":3715913972,"timestamp":"2024-06-01T18:06:15.426495Z"}]}
{"channel":"book","type":"update","data":[{"symbol":"ETH/GBP","bids":[],"asks":[{"price":2982.29,"qty":0.00000000},{"price":2984.40,"qty":2.94416492}],"checksum":1189916599,"timestamp":"2024-06-01T18:06:15.427381Z"}]}
{"channel":"book","type":"update","data":[{"symbol":"ETH/GBP","bids":[{"price":2981.52,"qty":0.00000000},{"price":2978.76,"qty":0.27441483}],"asks":[],"checksum":313092914,"timestamp":"2024-06-01T18:06:15.427509Z"}]}
{"channel":"book","type":"update","data":[{"symbol":"ETH/GBP","bids":[],"asks":[{"price":2982.28,"qty":0.10990113}],"checksum":572211664,"timestamp":"2024-06-01T18:06:15.431179Z"}]}
{"channel":"book","type":"update","data":[{"symbol":"ETH/GBP","bids":[],"asks":[{"price":2982.27,"qty":13.15335866}],"checksum":3092255200,"timestamp":"2024-06-01T18:06:15.511668Z"}]}
{"channel":"book","type":"update","data":[{"symbol":"ETH/GBP","bids":[],"asks":[{"price":2982.28,"qty":0.00000000},{"price":2984.35,"qty":0.30200000}],"checksum":2922135701,"timestamp":"2024-06-01T18:06:15.515948Z"}]}
{"channel":"book","type":"update","data":[{"symbol":"ETH/GBP","bids":[],"asks":[{"price":2982.27,"qty":0.00000000},{"price":2984.40,"qty":2.94416492}],"checksum":313092914,"timestamp":"2024-06-01T18:06:15.516622Z"}]}
{"channel":"book","type":"update","data":[{"symbol":"ETH/GBP","bids":[],"asks":[{"price":2981.77,"qty":6.57780155}],"checksum":460381215,"timestamp":"2024-06-01T18:06:15.521111Z"}]}
{"channel":"book","type":"update","data":[{"symbol":"ETH/GBP","bids":[{"price":2981.51,"qty":6.57833865}],"asks":[],"checksum":1835588322,"timestamp":"2024-06-01T18:06:15.521139Z"}]}
{"channel":"book","type":"update","data":[{"symbol":"ETH/GBP","bids":[{"price":2981.51,"qty":0.00000000},{"price":2978.76,"qty":0.27441483}],"asks":[],"checksum":460381215,"timestamp":"2024-06-01T18:06:15.578446Z"}]}
{"channel":"book","type":"update","data":[{"symbol":"ETH/GBP","bids":[],"asks":[{"price":2981.77,"qty":0.00000000},{"price":2984.40,"qty":2.94416492}],"checksum":313092914,"timestamp":"2024-06-01T18:06:15.660035Z"}]}
{"channel":"book","type":"update","data":[{"symbol":"ETH/GBP","bids":[],"asks":[{"price":2981.74,"qty":6.57786860}],"checksum":787036787,"timestamp":"2024-06-01T18:06:15.664776Z"}]}
{"channel":"book","type":"update","data":[{"symbol":"ETH/GBP","bids":[{"price":2981.51,"qty":6.57835537}],"asks":[],"checksum":1798783763,"timestamp":"2024-06-01T18:06:15.664892Z"}]}
{"channel":"book","type":"update","data":[{"symbol":"ETH/GBP","bids":[{"price":2981.51,"qty":0.00000000},{"price":2978.76,"qty":0.27441483}],"asks":[],"checksum":787036787,"timestamp":"2024-06-01T18:06:15.715254Z"}]}
{"channel":"book","type":"update","data":[{"symbol":"ETH/GBP","bids":[],"asks":[{"price":2981.74,"qty":0.00000000},{"price":2984.40,"qty":2.94416492}],"checksum":313092914,"timestamp":"2024-06-01T18:06:15.715264Z"}]}
{"channel":"book","type":"update","data":[{"symbol":"ETH/GBP","bids":[],"asks":[{"price":2982.30,"qty":13.15322634}],"checksum":157016056,"timestamp":"2024-06-01T18:06:15.720314Z"}]}
{"channel":"book","type":"update","data":[{"symbol":"ETH/GBP","bids":[],"asks":[{"price":2982.30,"qty":0.00000000},{"price":2984.40,"qty":2.94416492}],"checksum":313092914,"timestamp":"2024-06-01T18:06:15.724323Z"}]}
{"channel":"book","type":"update","data":[{"symbol":"ETH/GBP","bids":[],"asks":[{"price":2982.30,"qty":6.57661317}],"checksum":4207646019,"timestamp":"2024-06-01T18:06:15.765660Z"}]}
{"channel":"book","type":"update","data":[{"symbol":"ETH/GBP","bids":[{"price":2981.57,"qty":6.57821424}],"asks":[],"checksum":45224275,"timestamp":"2024-06-01T18:06:15.765782Z"}]}
{"channel":"book","type":"update","data":[{"symbol":"ETH/GBP","bids":[],"asks":[{"price":2982.30,"qty":0.00000000},{"price":2984.40,"qty":2.94416492}],"checksum":626536967,"timestamp":"2024-06-01T18:06:15.770771Z"}]}
{"channel":"book","type":"update","data":[{"symbol":"ETH/GBP","bids":[{"price":2981.57,"qty":0.00000000},{"price":2978.76,"qty":0.27441483}],"asks":[],"checksum":313092914,"timestamp":"2024-06-01T18:06:15.770856Z"}]}
{"channel":"book","type":"update","data":[{"symbol":"ETH/GBP","bids":[],"asks":[{"price":2983.63,"qty":1.31473885}],"checksum":487665407,"timestamp":"2024-06-01T18:06:15.843531Z"}]}
{"channel":"book","type":"update","data":[{"symbol":"ETH/GBP","bids":[],"asks":[{"price":2982.29,"qty":13.15327045}],"checksum":768322987,"timestamp":"2024-06-01T18:06:15.975015Z"}]}
{"channel":"book","type":"update","data":[{"symbol":"ETH/GBP","bids":[{"price":2981.50,"qty":6.57835709}],"asks":[],"checksum":4029623351,"timestamp":"2024-06-01T18:06:15.975060Z"}]}
{"channel":"book","type":"update","data":[{"symbol":"ETH/GBP","bids":[],"asks":[{"price":2982.30,"qty":6.57661317}],"checksum":2871351829,"timestamp":"2024-06-01T18:06:15.975236Z"}]}
{"channel":"book","type":"update","data":[{"symbol":"ETH/GBP","bids":[],"asks":[{"price":2982.29,"qty":0.00000000},{"price":2984.03,"qty":1.31456248}],"checksum":3546070553,"timestamp":"2024-06-01T18:06:15.981359Z"}]}
{"channel":"book","type":"update","data":[{"symbol":"ETH/GBP","bids":[],"asks":[{"price":2982.30,"qty":0.00000000},{"price":2984.35,"qty":0.30200000}],"checksum":2618909529,"timestamp":"2024-06-01T18:06:15.981410Z"}]}
{"channel":"book","type":"update","data":[{"symbol":"ETH/GBP","bids":[{"price":2980.49,"qty":0.00000000},{"price":2978.76,"qty":0.27441483}],"asks":[],"checksum":3457889585,"timestamp":"2024-06-01T18:06:16.136767Z"}]}
{"channel":"book","type":"update","data":[{"symbol":"ETH/GBP","bids":[{"price":2981.50,"qty":0.00000000},{"price":2978.58,"qty":1.33800000}],"asks":[],"checksum":2055517673,"timestamp":"2024-06-01T18:06:16.136779Z"}]}
{"channel":"book","type":"update","data":[{"symbol":"ETH/GBP","bids":[{"price":2981.11,"qty":0.00000000},{"price":2978.12,"qty":0.34390000}],"asks":[],"checksum":2971149589,"timestamp":"2024-06-01T18:06:16.136840Z"}]}
{"channel":"book","type":"update","data":[{"symbol":"ETH/GBP","bids":[{"price":2981.42,"qty":0.00000000},{"price":2978.11,"qty":1.31717030}],"asks":[],"checksum":2291128209,"timestamp":"2024-06-01T18:06:16.139592Z"}]}
{"channel":"book","type":"update","data":[{"symbol":"ETH/GBP","bids":[{"price":2981.09,"qty":0.31000000}],"asks":[],"checksum":3222756175,"timestamp":"2024-06-01T18:06:16.139888Z"}]}
{"channel":"book","type":"update","data":[{"symbol":"ETH/GBP","bids":[{"price":2980.52,"qty":0.00000000},{"price":2978.11,"qty":1.31717030}],"asks":[],"checksum":1395988365,"timestamp":"2024-06-01T18:06:16.140635Z"}]}
{"channel":"book","type":"update","data":[{"symbol":"ETH/GBP","bids":[{"price":2981.46,"qty":6.57845256}],"asks":[],"checksum":1421924077,"timestamp":"2024-06-01T18:06:16.142301Z"}]}
{"channel":"book","type":"update","data":[{"symbol":"ETH/GBP","bids":[],"asks":[{"price":2981.69,"qty":6.57798003}],"checksum":399881001,"timestamp":"2024-06-01T18:06:16.142345Z"}]}
{"channel":"book","type":"update","data":[{"symbol":"ETH/GBP","bids":[{"price":2981.03,"qty":13.15881870}],"asks":[],"checksum":1200254968,"timestamp":"2024-06-01T18:06:16.142358Z"}]}
{"channel":"book","type":"update","data":[{"symbol":"ETH/GBP","bids":[{"price":2980.26,"qty":1.31621981}],"asks":[],"checksum":3754842872,"timestamp":"2024-06-01T18:06:16.142386Z"}]}
{"channel":"book","type":"update","data":[{"symbol":"ETH/GBP","bids":[],"asks":[{"price":2982.24,"qty":0.31000000}],"checksum":2056389057,"timestamp":"2024-06-01T18:06:16.143287Z"}]}
{"channel":"book","type":"update","data":[{"symbol":"ETH/GBP","bids":[{"price":2980.84,"qty":6.15412676}],"asks":[],"checksum":501525076,"timestamp":"2024-06-01T18:06:16.146021Z"}]}
{"channel":"book","type":"update","data":[{"symbol":"ETH/GBP","bids":[],"asks":[{"price":2981.69,"qty":0.00000000},{"price":2984.03,"qty":1.31456248}],"checksum":2935945014,"timestamp":"2024-06-01T18:06:16.164094Z"}]}
{"channel":"book","type":"update","data":[{"symbol":"ETH/GBP","bids":[],"asks":[{"price":2982.23,"qty":13.15353508}],"checksum":1129223987,"timestamp":"2024-06-01T18:06:16.177931Z"}]}
{"channel":"book","type":"update","data":[{"symbol":"ETH/GBP","bids":[],"asks":[{"price":2982.23,"qty":0.00000000},{"price":2984.03,"qty":1.31456248}],"checksum":2935945014,"timestamp":"2024-06-01T18:06:16.183021Z"}]}
{"channel":"book","type":"update","data":[{"symbol":"ETH/GBP","bids":[],"asks":[{"price":2981.68,"qty":6.57799188}],"checksum":3213018678,"timestamp":"2024-06-01T18:06:16.288163Z"}]}
{"channel":"book","type":"update","data":[{"symbol":"ETH/GBP","bids":[],"asks":[{"price":2981.68,"qty":0.00000000},{"price":2984.03,"qty":1.31456248}],"checksum":2935945014,"timestamp":"2024-06-01T18:06:16.294023Z"}]}
{"channel":"book","type":"update","data":[{"symbol":"ETH/GBP","bids":[],"asks":[{"price":2982.23,"qty":13.15353508}],"checksum":1129223987,"timestamp":"2024-06-01T18:06:16.378631Z"}]}
{"channel":"book","type":"update","data":[{"symbol":"ETH/GBP","bids":[],"asks":[{"price":2982.23,"qty":0.00000000},{"price":2984.03,"qty":1.31456248}],"checksum":2935945014,"timestamp":"2024-06-01T18:06:16.383368Z"}]}
{"channel":"book","type":"update","data":[{"symbol":"ETH/GBP","bids":[],"asks":[{"price":2982.23,"qty":6.57676754}],"checksum":3598907441,"timestamp":"2024-06-01T18:06:16.387733Z"}]}
{"channel":"book","type":"update","data":[{"symbol":"ETH/GBP","bids":[],"asks":[{"price":2982.23,"qty":0.00000000},{"price":2984.03,"qty":1.31456248}],"checksum":2935945014,"timestamp":"2024-06-01T18:06:16.392245Z"}]}
{"channel":"book","type":"update","data":[{"symbol":"ETH/GBP","bids":[{"price":2981.46,"qty":0.00000000},{"price":2978.76,"qty":0.27441483}],"asks":[],"checksum":111725085,"timestamp":"2024-06-01T18:06:16.509989Z"}]}
{"channel":"book","type":"update","data":[{"symbol":"ETH/GBP","bids":[{"price":2981.47,"qty":6.57843181}],"asks":[],"checksum":4117951028,"timestamp":"2024-06-01T18:06:16.514885Z"}]}
{"channel":"book","type":"update","data":[{"symbol":"ETH/GBP","bids":[],"asks":[{"price":2981.69,"qty":6.57796819}],"checksum":3391155574,"timestamp":"2024-06-01T18:06:16.515028Z"}]}
{"channel":"book","type":"update","data":[{"symbol":"ETH/GBP","bids":[],"asks":[{"price":2981.69,"qty":0.00000000},{"price":2984.03,"qty":1.31456248}],"checksum":4117951028,"timestamp":"2024-06-01T18:06:16.609692Z"}]}
{"channel":"book","type":"update","data":[{"symbol":"ETH/GBP","bids":[],"asks":[{"price":2982.31,"qty":0.00000000},{"price":2984.35,"qty":0.30200000}],"checksum":3990861629,"timestamp":"2024-06-01T18:06:16.613581Z"}]}
{"channel":"book","type":"update","data":[{"symbol":"ETH/GBP","bids":[],"asks":[{"price":2983.46,"qty":0.00000000},{"price":2984.40,"qty":2.94416492}],"checksum":4130613382,"timestamp":"2024-06-01T18:06:16.613792Z"}]}
{"channel":"book","type":"update","data":[{"symbol":"ETH/GBP","bids":[],"asks":[{"price":2982.12,"qty":13.15402324}],"checksum":2794076906,"timestamp":"2024-06-01T18:06:16.614408Z"}]}
{"channel":"book","type":"update","data":[{"symbol":"ETH/GBP","bids":[],"asks":[{"price":2982.24,"qty":0.00000000},{"price":2984.40,"qty":2.94416492}],"checksum":583492598,"timestamp":"2024-06-01T18:06:16.616515Z"}]}
{"channel":"book","type":"update","data":[{"symbol":"ETH/GBP","bids":[],"asks":[{"price":2982.64,"qty":0.31000000}],"checksum":619395165,"timestamp":"2024-06-01T18:06:16.616835Z"}]}
{"channel":"book","type":"update","data":[{"symbol":"ETH/GBP","bids":[],"asks":[{"price":2983.46,"qty":28.23295536}],"checksum":2473028798,"timestamp":"2024-06-01T18:06:16.618949Z"}]}
{"channel":"book","type":"update","data":[{"symbol":"ETH/GBP","bids":[],"asks":[{"price":2982.96,"qty":7.24207121}],"checksum":640814045,"timestamp":"2024-06-01T18:06:16.619041Z"}]}
{"channel":"book","type":"update","data":[{"symbol":"ETH/GBP","bids":[],"asks":[{"price":2982.12,"qty":0.00000000},{"price":2984.03,"qty":1.31456248}],"checksum":1017177281,"timestamp":"2024-06-01T18:06:16.619072Z"}]}
{"channel":"book","type":"update","data":[{"symbol":"ETH/GBP","bids":[],"asks":[{"price":2981.68,"qty":6.57799056}],"checksum":1376658423,"timestamp":"2024-06-01T18:06:16.624386Z"}]}
{"channel":"book","type":"update","data":[{"symbol":"ETH/GBP","bids":[{"price":2981.47,"qty":0.00000000},{"price":2978.76,"qty":0.27441483}],"asks":[],"checksum":492792057,"timestamp":"2024-06-01T18:06:16.717035Z"}]}
{"channel":"book","type":"update","data":[{"symbol":"ETH/GBP","bids":[],"asks":[{"price":2981.68,"qty":0.00000000},{"price":2984.03,"qty":1.31456248}],"checksum":3634280814,"timestamp":"2024-06-01T18:06:16.717046Z"}]}
{"channel":"book","type":"update","data":[{"symbol":"ETH/GBP","bids":[{"price":2981.49,"qty":6.57839497}],"asks":[],"checksum":415387574,"timestamp":"2024-06-01T18:06:16.724320Z"}]}
{"channel":"book","type":"update","data":[{"symbol":"ETH/GBP","bids":[{"price":2981.49,"qty":0.00000000},{"price":2978.76,"qty":0.27441483}],"asks":[],"checksum":3634280814,"timestamp":"2024-06-01T18:06:16.729209Z"}]}
{"channel":"book","type":"update","data":[{"symbol":"ETH/GBP","bids":[],"asks":[{"price":2981.66,"qty":6.57802954}],"checksum":1021433598,"timestamp":"2024-06-01T18:06:16.735749Z"}]}
{"channel":"book","type":"update","data":[{"symbol":"ETH/GBP","bids":[],"asks":[{"price":2981.66,"qty":0.00000000},{"price":2984.03,"qty":1.31456248}],"checksum":3634280814,"timestamp":"2024-06-01T18:06:16.740443Z"}]}
{"channel":"book","type":"update","data":[{"symbol":"ETH/GBP","bids":[],"asks":[{"price":2981.67,"qty":6.57801744}],"checksum":4014924006,"timestamp":"2024-06-01T18:06:16.838228Z"}]}
{"channel":"book","type":"update","data":[{"symbol":"ETH/GBP","bids":[],"asks":[{"price":2982.10,"qty":13.15412171}],"checksum":1661451428,"timestamp":"2024-06-01T18:06:16.838245Z"}]}
{"channel":"book","type":"update","data":[{"symbol":"ETH/GBP","bids":[{"price":2981.44,"qty":6.57850108}],"asks":[],"checksum":16053005,"timestamp":"2024-06-01T18:06:16.838538Z"}]}
{"channel":"book","type":"update","data":[{"symbol":"ETH/GBP","bids":[],"asks":[{"price":2981.67,"qty":0.00000000},{"price":2984.02,"qty":1.00000000}],"checksum":2896882895,"timestamp":"2024-06-01T18:06:16.856667Z"}]}
{"channel":"book","type":"update","data":[{"symbol":"ETH/GBP","bids":[],"asks":[{"price":2982.10,"qty":0.00000000},{"price":2984.03,"qty":1.31456248}],"checksum":2080260518,"timestamp":"2024-06-01T18:06:16.866246Z"}]}
{"channel":"book","type":"update","data":[{"symbol":"ETH/GBP","bids":[{"price":2981.44,"qty":0.00000000},{"price":2978.76,"qty":0.27441483}],"asks":[],"checksum":3634280814,"timestamp":"2024-06-01T18:06:16.932905Z"}]}
{"channel":"book","type":"update","data":[{"symbol":"ETH/GBP","bids":[{"price":2981.43,"qty":6.57852749}],"asks":[],"checksum":1862094629,"timestamp":"2024-06-01T18:06:16.939964Z"}]}
{"channel":"book","type":"update","data":[{"symbol":"ETH/GBP","bids":[],"asks":[{"price":2981.66,"qty":6.57804483}],"checksum":354735459,"timestamp":"2024-06-01T18:06:16.940039Z"}]}
{"channel":"book","type":"update","data":[{"symbol":"ETH/GBP","bids":[],"asks":[{"price":2981.66,"qty":0.00000000},{"price":2984.03,"qty":1.31456248}],"checksum":1862094629,"timestamp":"2024-06-01T18:06:16.949060Z"}]}
{"channel":"book","type":"update","data":[{"symbol":"ETH/GBP","bids":[{"price":2981.43,"qty":0.00000000},{"price":2978.76,"qty":0.27441483}],"asks":[],"checksum":3634280814,"timestamp":"2024-06-01T18:06:16.949103Z"}]}
{"channel":"book","type":"update","data":[{"symbol":"ETH/GBP","bids":[{"price":2981.03,"qty":0.00000000},{"price":2978.13,"qty":1.33800000}],"asks":[],"checksum":965981730,"timestamp":"2024-06-01T18:06:16.949173Z"}]}
{"channel":"book","type":"update","data":[{"symbol":"ETH/GBP","bids":[{"price":2980.96,"qty":13.15913420}],"asks":[],"checksum":22334031,"timestamp":"2024-06-01T18:06:16.958093Z"}]}
{"channel":"book","type":"update","data":[{"symbol":"ETH/GBP","bids":[],"asks":[{"price":2981.58,"qty":6.57820992}],"checksum":2437599691,"timestamp":"2024-06-01T18:06:17.056406Z"}]}
{"channel":"book","type":"update","data":[{"symbol":"ETH/GBP","bids":[{"price":2981.36,"qty":6.57867981}],"asks":[],"checksum":3136079915,"timestamp":"2024-06-01T18:06:17.056419Z"}]}
{"channel":"book","type":"update","data":[{"symbol":"ETH/GBP","bids":[],"asks":[{"price":2982.63,"qty":13.15178164}],"checksum":2863899905,"timestamp":"2024-06-01T18:06:17.056467Z"}]}
{"channel":"book","type":"update","data":[{"symbol":"ETH/GBP","bids":[],"asks":[{"price":2982.63,"qty":0.00000000},{"price":2984.02,"qty":1.00000000}],"checksum":3136079915,"timestamp":"2024-06-01T18:06:17.061408Z"}]}
{"channel":"book","type":"update","data":[{"symbol":"ETH/GBP","bids":[],"asks":[{"price":2981.58,"qty":0.00000000},{"price":2984.03,"qty":1.31456248}],"checksum":1353289993,"timestamp":"2024-06-01T18:06:17.065786Z"}]}
{"channel":"book","type":"update","data":[{"symbol":"ETH/GBP","bids":[{"price":2981.36,"qty":0.00000000},{"price":2978.76,"qty":0.27441483}],"asks":[],"checksum":22334031,"timestamp":"2024-06-01T18:06:17.176357Z"}]}
{"channel":"book","type":"update","data":[{"symbol":"ETH/GBP","bids":[{"price":2981.34,"qty":6.57871903}],"asks":[],"checksum":1999919380,"timestamp":"2024-06-01T18:06:17.180898Z"}]}
{"channel":"book","type":"update","data":[{"symbol":"ETH/GBP","bids":[],"asks":[{"price":2981.57,"qty":6.57823163}],"checksum":3803068697,"timestamp":"2024-06-01T18:06:17.180938Z"}]}
{"channel":"book","type":"update","data":[{"symbol":"ETH/GBP","bids":[{"price":2981.34,"qty":0.00000000},{"price":2978.76,"qty":0.27441483}],"asks":[],"checksum":612255111,"timestamp":"2024-06-01T18:06:17.299804Z"}]}
{"channel":"book","type":"update","data":[{"symbol":"ETH/GBP","bids":[{"price":2981.35,"qty":6.57870258}],"asks":[],"checksum":766764330,"timestamp":"2024-06-01T18:06:17.303655Z"}]}
{"channel":"book","type":"update","data":[{"symbol":"ETH/GBP","bids":[],"asks":[{"price":2982.00,"qty":13.15457325}],"checksum":3723247708,"timestamp":"2024-06-01T18:06:17.303832Z"}]}
{"channel":"book","type":"update","data":[{"symbol":"ETH/GBP","bids":[{"price":2981.35,"qty":0.00000000},{"price":2978.76,"qty":0.27441483}],"asks":[],"checksum":1950906135,"timestamp":"2024-06-01T18:06:17.380499Z"}]}
{"channel":"book","type":"update","data":[{"symbol":"ETH/GBP","bids":[],"asks":[{"price":2981.57,"qty":0.00000000},{"price":2984.02,"qty":1.00000000}],"checksum":1183717517,"timestamp":"2024-06-01T18:06:17.380562Z"}]}
{"channel":"book","type":"update","data":[{"symbol":"ETH/GBP","bids":[],"asks":[{"price":2981.59,"qty":6.57819939}],"checksum":274659308,"timestamp":"2024-06-01T18:06:17.384338Z"}]}
{"channel":"book","type":"update","data":[{"symbol":"ETH/GBP","bids":[],"asks":[{"price":2981.59,"qty":0.00000000},{"price":2984.02,"qty":1.00000000}],"checksum":1183717517,"timestamp":"2024-06-01T18:06:17.466078Z"}]}
{"channel":"book","type":"update","data":[{"symbol":"ETH/GBP","bids":[{"price":2981.36,"qty":6.57867692}],"asks":[],"checksum":2365051395,"timestamp":"2024-06-01T18:06:17.470357Z"}]}
{"channel":"book","type":"update","data":[{"symbol":"ETH/GBP","bids":[],"asks":[{"price":2982.73,"qty":0.00000000},{"price":2984.03,"qty":1.31456248},{"price":2982.33,"qty":0.08551700}],"checksum":932114398,"timestamp":"2024-06-01T18:06:17.477517Z"}]}
{"channel":"book","type":"update","data":[{"symbol":"ETH/GBP","bids":[],"asks":[{"price":2981.99,"qty":6.57729686}],"checksum":482432905,"timestamp":"2024-06-01T18:06:17.542326Z"}]}
{"channel":"book","type":"update","data":[{"symbol":"ETH/GBP","bids":[],"asks":[{"price":2981.99,"qty":0.00000000},{"price":2984.02,"qty":1.00000000}],"checksum":932114398,"timestamp":"2024-06-01T18:06:17.546913Z"}]}
{"channel":"book","type":"update","data":[{"symbol":"ETH/GBP","bids":[{"price":2981.36,"qty":0.00000000},{"price":2978.76,"qty":0.27441483}],"asks":[],"checksum":888456760,"timestamp":"2024-06-01T18:06:17.572533Z"}]}
{"channel":"book","type":"update","data":[{"symbol":"ETH/GBP","bids":[{"price":2981.35,"qty":6.57868873}],"asks":[],"checksum":44457320,"timestamp":"2024-06-01T18:06:17.577464Z"}]}
{"channel":"book","type":"update","data":[{"symbol":"ETH/GBP","bids":[],"asks":[{"price":2982.33,"qty":0.00000000},{"price":2984.03,"qty":1.31456248},{"price":2982.63,"qty":0.08550700}],"checksum":2503493202,"timestamp":"2024-06-01T18:06:17.652119Z"}]}
{"channel":"book","type":"update","data":[{"symbol":"ETH/GBP","bids":[{"price":2981.35,"qty":0.00000000},{"price":2978.76,"qty":0.27441483}],"asks":[],"checksum":2016834611,"timestamp":"2024-06-01T18:06:17.751011Z"}]}
{"channel":"book","type":"update","data":[{"symbol":"ETH/GBP","bids":[],"asks":[{"price":2981.59,"qty":6.57818191}],"checksum":1591815882,"timestamp":"2024-06-01T18:06:17.755369Z"}]}
{"channel":"book","type":"update","data":[{"symbol":"ETH/GBP","bids":[{"price":2981.37,"qty":6.57864305}],"asks":[],"checksum":3545773357,"timestamp":"2024-06-01T18:06:17.755471Z"}]}
{"channel":"book","type":"update","data":[{"symbol":"ETH/GBP","bids":[{"price":2981.37,"qty":0.00000000},{"price":2978.76,"qty":0.27441483}],"asks":[],"checksum":1591815882,"timestamp":"2024-06-01T18:06:17.816631Z"}]}
{"channel":"book","type":"update","data":[{"symbol":"ETH/GBP","bids":[{"price":2981.36,"qty":6.57867300}],"asks":[],"checksum":3591692812,"timestamp":"2024-06-01T18:06:17.963589Z"}]}
{"channel":"book","type":"update","data":[{"symbol":"ETH/GBP","bids":[{"price":2981.36,"qty":0.00000000},{"price":2978.76,"qty":0.27441483}],"asks":[],"checksum":1591815882,"timestamp":"2024-06-01T18:06:18.281716Z"}]}
{"channel":"book","type":"update","data":[{"symbol":"ETH/GBP","bids":[],"asks":[{"price":2981.59,"qty":0.00000000},{"price":2984.02,"qty":1.00000000}],"checksum":2016834611,"timestamp":"2024-06-01T18:06:18.281865Z"}]}
{"channel":"book","type":"update","data":[{"symbol":"ETH/GBP","bids":[{"price":2981.35,"qty":6.57869773}],"asks":[],"checksum":267631199,"timestamp":"2024-06-01T18:06:18.287282Z"}]}
{"channel":"book","type":"update","data":[{"symbol":"ETH/GBP","bids":[],"asks":[{"price":2981.99,"qty":6.57729686}],"checksum":3142134571,"timestamp":"2024-06-01T18:06:18.287464Z"}]}
{"channel":"book","type":"update","data":[{"symbol":"ETH/GBP","bids":[{"price":2981.35,"qty":0.00000000},{"price":2978.76,"qty":0.27441483}],"asks":[],"checksum":3373873103,"timestamp":"2024-06-01T18:06:18.291933Z"}]}
{"channel":"book","type":"update","data":[{"symbol":"ETH/GBP","bids":[],"asks":[{"price":2981.99,"qty":0.00000000},{"price":2984.02,"qty":1.00000000}],"checksum":2016834611,"timestamp":"2024-06-01T18:06:18.292003Z"}]}
{"channel":"book","type":"update","data":[{"symbol":"ETH/GBP","bids":[],"asks":[{"price":2982.00,"qty":0.00000000},{"price":2984.03,"qty":1.31456248}],"checksum":3358024475,"timestamp":"2024-06-01T18:06:18.329586Z"}]}
{"channel":"book","type":"update","data":[{"symbol":"ETH/GBP","bids":[],"asks":[{"price":2982.97,"qty":0.00000000},{"price":2984.35,"qty":0.30200000}],"checksum":2196592596,"timestamp":"2024-06-01T18:06:18.329632Z"}]}
{"channel":"book","type":"update","data":[{"symbol":"ETH/GBP","bids":[{"price":2980.96,"qty":0.00000000},{"price":2978.13,"qty":1.33800000}],"asks":[],"checksum":1401678389,"timestamp":"2024-06-01T18:06:18.329702Z"}]}
{"channel":"book","type":"update","data":[{"symbol":"ETH/GBP","bids":[],"asks":[{"price":2982.75,"qty":1.31512617}],"checksum":3218478635,"timestamp":"2024-06-01T18:06:18.334946Z"}]}
{"channel":"book","type":"update","data":[{"symbol":"ETH/GBP","bids":[{"price":2980.89,"qty":13.15941864}],"asks":[],"checksum":4091632497,"timestamp":"2024-06-01T18:06:18.335000Z"}]}
{"channel":"book","type":"update","data":[{"symbol":"ETH/GBP","bids":[],"asks":[{"price":2982.62,"qty":13.15182530}],"checksum":2337191245,"timestamp":"2024-06-01T18:06:18.335126Z"}]}
{"channel":"book","type":"update","data":[{"symbol":"ETH/GBP","bids":[],"asks":[{"price":2982.64,"qty":0.00000000},{"price":2984.03,"qty":1.31456248}],"checksum":2613171919,"timestamp":"2024-06-01T18:06:18.338172Z"}]}
{"channel":"book","type":"update","data":[{"symbol":"ETH/GBP","bids":[],"asks":[{"price":2982.53,"qty":0.31000000}],"checksum":1392232139,"timestamp":"2024-06-01T18:06:18.339037Z"}]}
{"channel":"book","type":"update","data":[{"symbol":"ETH/GBP","bids":[],"asks":[{"price":2982.62,"qty":0.00000000},{"price":2984.03,"qty":1.31456248}],"checksum":3841732187,"timestamp":"2024-06-01T18:06:18.340535Z"}]}
{"channel":"book","type":"update","data":[{"symbol":"ETH/GBP","bids":[{"price":2981.00,"qty":0.00000000},{"price":2978.13,"qty":1.33800000}],"asks":[],"checksum":959964842,"timestamp":"2024-06-01T18:06:18.346923Z"}]}
{"channel":"book","type":"update","data":[{"symbol":"ETH/GBP","bids":[],"asks":[{"price":2981.56,"qty":6.57826451}],"checksum":3794328872,"timestamp":"2024-06-01T18:06:18.390833Z"}]}
{"channel":"book","type":"update","data":[{"symbol":"ETH/GBP","bids":[{"price":2981.33,"qty":6.57875037}],"asks":[],"checksum":2413556957,"timestamp":"2024-06-01T18:06:18.391002Z"}]}
{"channel":"book","type":"update","data":[{"symbol":"ETH/GBP","bids":[],"asks":[{"price":2981.56,"qty":0.00000000},{"price":2984.03,"qty":1.31456248}],"checksum":1422184287,"timestamp":"2024-06-01T18:06:18.408394Z"}]}
{"channel":"book","type":"update","data":[{"symbol":"ETH/GBP","bids":[{"price":2981.33,"qty":0.00000000},{"price":2978.13,"qty":1.33800000}],"asks":[],"checksum":959964842,"timestamp":"2024-06-01T18:06:18.411308Z"}]}
{"channel":"book","type":"update","data":[{"symbol":"ETH/GBP","bids":[{"price":2981.30,"qty":6.57881504}],"asks":[],"checksum":202095199,"timestamp":"2024-06-01T18:06:18.550997Z"}]}
{"channel":"book","type":"update","data":[{"symbol":"ETH/GBP","bids":[],"asks":[{"price":2982.52,"qty":6.57613092}],"checksum":1166857734,"timestamp":"2024-06-01T18:06:18.551030Z"}]}
{"channel":"book","type":"update","data":[{"symbol":"ETH/GBP","bids":[],"asks":[{"price":2982.52,"qty":19.72839277}],"checksum":1516589235,"timestamp":"2024-06-01T18:06:18.551201Z"}]}
{"channel":"book","type":"update","data":[{"symbol":"ETH/GBP","bids":[],"asks":[{"price":2982.53,"qty":0.00000000},{"price":2984.03,"qty":1.31456248}],"checksum":635418156,"timestamp":"2024-06-01T18:06:18.553781Z"}]}
{"channel":"book","type":"update","data":[{"symbol":"ETH/GBP","bids":[],"asks":[{"price":2982.43,"qty":0.31000000}],"checksum":3758610151,"timestamp":"2024-06-01T18:06:18.553884Z"}]}
{"channel":"book","type":"update","data":[{"symbol":"ETH/GBP","bids":[],"asks":[{"price":2982.52,"qty":13.15226185}],"checksum":3839447962,"timestamp":"2024-06-01T18:06:18.556471Z"}]}
{"channel":"book","type":"update","data":[{"symbol":"ETH/GBP","bids":[],"asks":[{"price":2982.52,"qty":0.00000000},{"price":2984.03,"qty":1.31456248}],"checksum":106184099,"timestamp":"2024-06-01T18:06:18.556622Z"}]}
{"channel":"book","type":"update","data":[{"symbol":"ETH/GBP","bids":[{"price":2981.30,"qty":0.00000000},{"price":2978.13,"qty":1.33800000}],"asks":[],"checksum":862478678,"timestamp":"2024-06-01T18:06:18.560336Z"}]}
{"channel":"book","type":"update","data":[{"symbol":"ETH/GBP","bids":[],"asks":[{"price":2981.56,"qty":6.57825402}],"checksum":813884421,"timestamp":"2024-06-01T18:06:18.693160Z"}]}
{"channel":"book","type":"update","data":[{"symbol":"ETH/GBP","bids":[{"price":2981.31,"qty":6.57878449}],"asks":[],"checksum":3839136981,"timestamp":"2024-06-01T18:06:18.693179Z"}]}
{"channel":"book","type":"update","data":[{"symbol":"ETH/GBP","bids":[],"asks":[{"price":2981.56,"qty":0.00000000},{"price":2984.03,"qty":1.31456248}],"checksum":3879604614,"timestamp":"2024-06-01T18:06:18.704645Z"}]}
{"channel":"book","type":"update","data":[{"symbol":"ETH/GBP","bids":[{"price":2981.31,"qty":0.00000000},{"price":2978.13,"qty":1.33800000}],"asks":[],"checksum":862478678,"timestamp":"2024-06-01T18:06:18.704859Z"}]}
{"channel":"book","type":"update","data":[{"symbol":"ETH/GBP","bids":[],"asks":[{"price":2982.42,"qty":13.15269844}],"checksum":2158070398,"timestamp":"2024-06-01T18:06:18.752231Z"}]}
{"channel":"book","type":"update","data":[{"symbol":"ETH/GBP","bids":[],"asks":[{"price":2982.43,"qty":0.00000000},{"price":2984.03,"qty":1.31456248}],"checksum":3302268717,"timestamp":"2024-06-01T18:06:18.755004Z"}]}
{"channel":"book","type":"update","data":[{"symbol":"ETH/GBP","bids":[],"asks":[{"price":2982.33,"qty":0.31000000}],"checksum":2734752613,"timestamp":"2024-06-01T18:06:18.755063Z"}]}
{"channel":"book","type":"update","data":[{"symbol":"ETH/GBP","bids":[],"asks":[{"price":2982.42,"qty":0.00000000},{"price":2984.03,"qty":1.31456248}],"checksum":83293858,"timestamp":"2024-06-01T18:06:18.756968Z"}]}
{"channel":"book","type":"update","data":[{"symbol":"ETH/GBP","bids":[{"price":2981.33,"qty":6.57874997}],"asks":[],"checksum":2966084840,"timestamp":"2024-06-01T18:06:18.805890Z"}]}
{"channel":"book","type":"update","data":[{"symbol":"ETH/GBP","bids":[],"asks":[{"price":2981.56,"qty":6.57825404}],"checksum":2322694680,"timestamp":"2024-06-01T18:06:18.805972Z"}]}
{"channel":"book","type":"update","data":[{"symbol":"ETH/GBP","bids":[],"asks":[{"price":2981.56,"qty":0.00000000},{"price":2984.03,"qty":1.31456248}],"checksum":2966084840,"timestamp":"2024-06-01T18:06:18.858214Z"}]}
{"channel":"book","type":"update","data":[{"symbol":"ETH/GBP","bids":[],"asks":[{"price":2981.55,"qty":6.57826896}],"checksum":3011973043,"timestamp":"2024-06-01T18:06:18.930229Z"}]}
{"channel":"book","type":"update","data":[{"symbol":"ETH/GBP","bids":[],"asks":[{"price":2982.96,"qty":0.00000000},{"price":2984.03,"qty":1.31456248}],"checksum":781854859,"timestamp":"2024-06-01T18:06:19.022876Z"}]}
{"channel":"book","type":"update","data":[{"symbol":"ETH/GBP","bids":[],"asks":[{"price":2983.46,"qty":0.00000000},{"price":2984.35,"qty":0.30200000}],"checksum":2674383412,"timestamp":"2024-06-01T18:06:19.022916Z"}]}
{"channel":"book","type":"update","data":[{"symbol":"ETH/GBP","bids":[],"asks":[{"price":2982.74,"qty":1.04280286}],"checksum":2522143586,"timestamp":"2024-06-01T18:06:19.027738Z"}]}
{"channel":"book","type":"update","data":[{"symbol":"ETH/GBP","bids":[],"asks":[{"price":2982.42,"qty":0.52619716}],"checksum":4165743490,"timestamp":"2024-06-01T18:06:19.027809Z"}]}
{"channel":"book","type":"update","data":[{"symbol":"ETH/GBP","bids":[],"asks":[{"price":2983.46,"qty":29.42230280}],"checksum":4274024015,"timestamp":"2024-06-01T18:06:19.028069Z"}]}
{"channel":"book","type":"update","data":[{"symbol":"ETH/GBP","bids":[],"asks":[{"price":2981.55,"qty":0.00000000},{"price":2984.02,"qty":1.00000000}],"checksum":1446854461,"timestamp":"2024-06-01T18:06:19.222765Z"}]}
{"channel":"book","type":"update","data":[{"symbol":"ETH/GBP","bids":[],"asks":[{"price":2981.57,"qty":6.57823935}],"checksum":2084645583,"timestamp":"2024-06-01T18:06:19.227571Z"}]}
{"channel":"book","type":"update","data":[{"symbol":"ETH/GBP","bids":[],"asks":[{"price":2982.32,"qty":13.15313813}],"checksum":3673209119,"timestamp":"2024-06-01T18:06:19.227649Z"}]}
{"channel":"book","type":"update","data":[{"symbol":"ETH/GBP","bids":[],"asks":[{"price":2982.32,"qty":0.00000000},{"price":2983.92,"qty":0.94850883}],"checksum":2084645583,"timestamp":"2024-06-01T18:06:19.232199Z"}]}
{"channel":"book","type":"update","data":[{"symbol":"ETH/GBP","bids":[],"asks":[{"price":2981.57,"qty":0.00000000},{"price":2984.02,"qty":1.00000000}],"checksum":1446854461,"timestamp":"2024-06-01T18:06:19.246284Z"}]}
{"channel":"book","type":"update","data":[{"symbol":"ETH/GBP","bids":[],"asks":[{"price":2981.56,"qty":6.57825514}],"checksum":1760391663,"timestamp":"2024-06-01T18:06:19.329436Z"}]}
{"channel":"book","type":"update","data":[{"symbol":"ETH/GBP","bids":[{"price":2981.33,"qty":0.00000000},{"price":2978.13,"qty":1.33800000}],"asks":[],"checksum":3704708005,"timestamp":"2024-06-01T18:06:19.342747Z"}]}
{"channel":"book","type":"update","data":[{"symbol":"ETH/GBP","bids":[],"asks":[{"price":2981.56,"qty":0.00000000},{"price":2984.02,"qty":1.00000000}],"checksum":3791721847,"timestamp":"2024-06-01T18:06:19.342945Z"}]}
{"channel":"book","type":"update","data":[{"symbol":"ETH/GBP","bids":[{"price":2981.31,"qty":6.57878760}],"asks":[],"checksum":2838451649,"timestamp":"2024-06-01T18:06:19.347597Z"}]}
{"channel":"book","type":"update","data":[{"symbol":"ETH/GBP","bids":[{"price":2981.31,"qty":0.00000000},{"price":2978.13,"qty":1.33800000}],"asks":[],"checksum":3791721847,"timestamp":"2024-06-01T18:06:19.351474Z"}]}
{"channel":"book","type":"update","data":[{"symbol":"ETH/GBP","bids":[{"price":2981.32,"qty":6.57876654}],"asks":[],"checksum":2960627671,"timestamp":"2024-06-01T18:06:19.463131Z"}]}
{"channel":"book","type":"update","data":[{"symbol":"ETH/GBP","bids":[],"asks":[{"price":2982.32,"qty":13.15313813}],"checksum":4250702979,"timestamp":"2024-06-01T18:06:19.463219Z"}]}
{"channel":"book","type":"update","data":[{"symbol":"ETH/GBP","bids":[],"asks":[{"price":2981.55,"qty":6.57827083}],"checksum":3813798938,"timestamp":"2024-06-01T18:06:19.463319Z"}]}
{"channel":"book","type":"update","data":[{"symbol":"ETH/GBP","bids":[],"asks":[{"price":2982.32,"qty":0.00000000},{"price":2983.92,"qty":0.94850883}],"checksum":782222463,"timestamp":"2024-06-01T18:06:19.468862Z"}]}
{"channel":"book","type":"update","data":[{"symbol":"ETH/GBP","bids":[{"price":2981.32,"qty":0.00000000},{"price":2978.13,"qty":1.33800000}],"asks":[],"checksum":2095662815,"timestamp":"2024-06-01T18:06:19.608062Z"}]}
{"channel":"book","type":"update","data":[{"symbol":"ETH/GBP","bids":[{"price":2981.30,"qty":6.57879929}],"asks":[],"checksum":1029696872,"timestamp":"2024-06-01T18:06:19.612299Z"}]}
{"channel":"book","type":"update","data":[{"symbol":"ETH/GBP","bids":[{"price":2981.30,"qty":0.00000000},{"price":2978.13,"qty":1.33800000}],"asks":[],"checksum":2095662815,"timestamp":"2024-06-01T18:06:19.635878Z"}]}
{"channel":"book","type":"update","data":[{"symbol":"ETH/GBP","bids":[],"asks":[{"price":2981.55,"qty":0.00000000},{"price":2984.02,"qty":1.00000000}],"checksum":3791721847,"timestamp":"2024-06-01T18:06:19.638903Z"}]}
{"channel":"book","type":"update","data":[{"symbol":"ETH/GBP","bids":[],"asks":[{"price":2981.57,"qty":6.57823837}],"checksum":321166359,"timestamp":"2024-06-01T18:06:19.643708Z"}]}
{"channel":"book","type":"update","data":[{"symbol":"ETH/GBP","bids":[],"asks":[{"price":2981.57,"qty":0.00000000},{"price":2984.02,"qty":1.00000000}],"checksum":3791721847,"timestamp":"2024-06-01T18:06:19.697952Z"}]}
{"channel":"book","type":"update","data":[{"symbol":"ETH/GBP","bids":[],"asks":[{"price":2982.00,"qty":13.15458112}],"checksum":3561452491,"timestamp":"2024-06-01T18:06:19.702215Z"}]}
{"channel":"book","type":"update","data":[{"symbol":"ETH/GBP","bids":[],"asks":[{"price":2982.00,"qty":0.00000000},{"price":2984.02,"qty":1.00000000}],"checksum":3791721847,"timestamp":"2024-06-01T18:06:19.707070Z"}]}
{"channel":"book","type":"update","data":[{"symbol":"ETH/GBP","bids":[{"price":2981.33,"qty":6.57874797}],"asks":[],"checksum":1540603914,"timestamp":"2024-06-01T18:06:19.716497Z"}]}
{"channel":"book","type":"update","data":[{"symbol":"ETH/GBP","bids":[{"price":2981.33,"qty":0.00000000},{"price":2978.13,"qty":1.33800000}],"asks":[],"checksum":3791721847,"timestamp":"2024-06-01T18:06:19.767573Z"}]}
{"channel":"book","type":"update","data":[{"symbol":"ETH/GBP","bids":[],"asks":[{"price":2981.56,"qty":6.57826666}],"checksum":1891502406,"timestamp":"2024-06-01T18:06:19.773546Z"}]}
{"channel":"book","type":"update","data":[{"symbol":"ETH/GBP","bids":[],"asks":[{"price":2981.56,"qty":0.00000000},{"price":2984.02,"qty":1.00000000}],"checksum":3791721847,"timestamp":"2024-06-01T18:06:19.791867Z"}]}
{"channel":"book","type":"update","data":[{"symbol":"ETH/GBP","bids":[{"price":2981.32,"qty":6.57876902}],"asks":[],"checksum":1303460043,"timestamp":"2024-06-01T18:06:19.834048Z"}]}
{"channel":"book","type":"update","data":[{"symbol":"ETH/GBP","bids":[],"asks":[{"price":2981.55,"qty":6.57827192}],"checksum":3565538660,"timestamp":"2024-06-01T18:06:19.885686Z"}]}
{"channel":"book","type":"update","data":[{"symbol":"ETH/GBP","bids":[{"price":2981.32,"qty":0.00000000},{"price":2978.13,"qty":1.33800000}],"asks":[],"checksum":2067128536,"timestamp":"2024-06-01T18:06:20.235513Z"}]}
{"channel":"book","type":"update","data":[{"symbol":"ETH/GBP","bids":[],"asks":[{"price":2981.55,"qty":0.00000000},{"price":2984.02,"qty":1.00000000}],"checksum":3791721847,"timestamp":"2024-06-01T18:06:20.235534Z"}]}
{"channel":"book","type":"update","data":[{"symbol":"ETH/GBP","bids":[],"asks":[{"price":2982.32,"qty":13.15313813}],"checksum":2938770979,"timestamp":"2024-06-01T18:06:20.244054Z"}]}
{"channel":"book","type":"update","data":[{"symbol":"ETH/GBP","bids":[],"asks":[{"price":2981.53,"qty":6.57833251}],"checksum":1230067116,"timestamp":"2024-06-01T18:06:20.244140Z"}]}
{"channel":"book","type":"update","data":[{"symbol":"ETH/GBP","bids":[{"price":2981.29,"qty":6.57882969}],"asks":[],"checksum":4140752564,"timestamp":"2024-06-01T18:06:20.244181Z"}]}
{"channel":"book","type":"update","data":[{"symbol":"ETH/GBP","bids":[],"asks":[{"price":2981.53,"qty":0.00000000},{"price":2983.92,"qty":0.94850883}],"checksum":280337723,"timestamp":"2024-06-01T18:06:20.252118Z"}]}
{"channel":"book","type":"update","data":[{"symbol":"ETH/GBP","bids":[],"asks":[{"price":2982.32,"qty":0.00000000},{"price":2984.02,"qty":1.00000000}],"checksum":1570676335,"timestamp":"2024-06-01T18:06:20.252139Z"}]}
{"channel":"book","type":"update","data":[{"symbol":"ETH/GBP","bids":[{"price":2981.29,"qty":0.00000000},{"price":2978.13,"qty":1.33800000}],"asks":[],"checksum":3791721847,"timestamp":"2024-06-01T18:06:20.252175Z"}]}
{"channel":"book","type":"update","data":[{"symbol":"ETH/GBP","bids":[{"price":2980.89,"qty":0.00000000},{"price":2978.12,"qty":0.34390000}],"asks":[],"checksum":2743111021,"timestamp":"2024-06-01T18:06:20.255750Z"}]}
{"channel":"book","type":"update","data":[{"symbol":"ETH/GBP","bids":[{"price":2980.26,"qty":0.00000000},{"price":2978.11,"qty":1.31717030}],"asks":[],"checksum":4089275767,"timestamp":"2024-06-01T18:06:20.255780Z"}]}
{"channel":"book","type":"update","data":[{"symbol":"ETH/GBP","bids":[{"price":2979.73,"qty":0.00000000},{"price":2977.74,"qty":0.21600000}],"asks":[],"checksum":4141683608,"timestamp":"2024-06-01T18:06:20.255878Z"}]}
{"channel":"book","type":"update","data":[{"symbol":"ETH/GBP","bids":[{"price":2980.82,"qty":13.15972114}],"asks":[],"checksum":2530890915,"timestamp":"2024-06-01T18:06:20.262282Z"}]}
{"channel":"book","type":"update","data":[{"symbol":"ETH/GBP","bids":[{"price":2979.31,"qty":1.31663942}],"asks":[],"checksum":3039076032,"timestamp":"2024-06-01T18:06:20.262308Z"}]}
{"channel":"book","type":"update","data":[{"symbol":"ETH/GBP","bids":[{"price":2980.02,"qty":1.31632776}],"asks":[],"checksum":1527540347,"timestamp":"2024-06-01T18:06:20.262468Z"}]}
{"channel":"book","type":"update","data":[{"symbol":"ETH/GBP","bids":[{"price":2981.09,"qty":0.00000000},{"price":2978.12,"qty":0.34390000}],"asks":[],"checksum":3059630171,"timestamp":"2024-06-01T18:06:20.263480Z"}]}
{"channel":"book","type":"update","data":[{"symbol":"ETH/GBP","bids":[{"price":2980.91,"qty":0.31000000}],"asks":[],"checksum":1721167810,"timestamp":"2024-06-01T18:06:20.263654Z"}]}
{"channel":"book","type":"update","data":[{"symbol":"ETH/GBP","bids":[{"price":2978.13,"qty":0.00000000},{"price":2978.11,"qty":1.31717030},{"price":2978.12,"qty":1.33800000}],"asks":[],"checksum":2304017660,"timestamp":"2024-06-01T18:06:20.275155Z"}]}
{"channel":"book","type":"update","data":[{"symbol":"ETH/GBP","bids":[{"price":2980.82,"qty":0.00000000},{"price":2978.11,"qty":1.31717030}],"asks":[],"checksum":1602295491,"timestamp":"2024-06-01T18:06:20.299880Z"}]}
{"channel":"book","type":"update","data":[{"symbol":"ETH/GBP","bids":[{"price":2980.84,"qty":0.00000000},{"price":2977.74,"qty":0.21600000}],"asks":[],"checksum":1381112983,"timestamp":"2024-06-01T18:06:20.329581Z"}]}
{"channel":"book","type":"update","data":[{"symbol":"ETH/GBP","bids":[{"price":2980.91,"qty":0.00000000},{"price":2976.91,"qty":0.14096130}],"asks":[],"checksum":3016086190,"timestamp":"2024-06-01T18:06:20.333050Z"}]}
{"channel":"book","type":"update","data":[{"symbol":"ETH/GBP","bids":[{"price":2980.11,"qty":0.31000000}],"asks":[],"checksum":3637556987,"timestamp":"2024-06-01T18:06:20.333258Z"}]}
{"channel":"book","type":"update","data":[{"symbol":"ETH/GBP","bids":[{"price":2980.80,"qty":6.15420934}],"asks":[],"checksum":1135008387,"timestamp":"2024-06-01T18:06:20.334192Z"}]}
{"channel":"book","type":"update","data":[{"symbol":"ETH/GBP","bids":[],"asks":[{"price":2983.63,"qty":0.00000000},{"price":2984.03,"qty":1.31456248}],"checksum":2484657854,"timestamp":"2024-06-01T18:06:20.336034Z"}]}
{"channel":"book","type":"update","data":[{"symbol":"ETH/GBP","bids":[],"asks":[{"price":2982.75,"qty":0.00000000},{"price":2984.35,"qty":0.30200000}],"checksum":3583437417,"timestamp":"2024-06-01T18:06:20.336111Z"}]}
{"channel":"book","type":"update","data":[{"symbol":"ETH/GBP","bids":[{"price":2978.88,"qty":0.00000000},{"price":2977.74,"qty":0.21600000}],"asks":[],"checksum":3734303404,"timestamp":"2024-06-01T18:06:20.336295Z"}]}
{"channel":"book","type":"update","data":[{"symbol":"ETH/GBP","bids":[{"price":2980.11,"qty":0.00000000},{"price":2977.37,"qty":0.34450000}],"asks":[],"checksum":3136907535,"timestamp":"2024-06-01T18:06:20.337436Z"}]}
{"channel":"book","type":"update","data":[{"symbol":"ETH/GBP","bids":[{"price":2980.80,"qty":0.00000000},{"price":2976.91,"qty":0.14096130}],"asks":[],"checksum":182867872,"timestamp":"2024-06-01T18:06:20.338466Z"}]}
{"channel":"book","type":"update","data":[{"symbol":"ETH/GBP","bids":[{"price":2980.88,"qty":0.31000000}],"asks":[],"checksum":3325248973,"timestamp":"2024-06-01T18:06:20.338671Z"}]}
{"channel":"book","type":"update","data":[{"symbol":"ETH/GBP","bids":[{"price":2980.88,"qty":0.00000000},{"price":2976.91,"qty":0.14096130}],"asks":[],"checksum":182867872,"timestamp":"2024-06-01T18:06:20.341603Z"}]}
{"channel":"book","type":"update","data":[{"symbol":"ETH/GBP","bids":[{"price":2980.11,"qty":0.31000000}],"asks":[],"checksum":733129138,"timestamp":"2024-06-01T18:06:20.341950Z"}]}
{"channel":"book","type":"update","data":[{"symbol":"ETH/GBP","bids":[{"price":2980.72,"qty":5.92918958}],"asks":[],"checksum":4282065299,"timestamp":"2024-06-01T18:06:20.343231Z"}]}
{"channel":"book","type":"update","data":[{"symbol":"ETH/GBP","bids":[],"asks":[{"price":2982.54,"qty":1.31522012}],"checksum":2606683554,"timestamp":"2024-06-01T18:06:20.343505Z"}]}
{"channel":"book","type":"update","data":[{"symbol":"ETH/GBP","bids":[],"asks":[{"price":2983.17,"qty":1.31494337}],"checksum":3944003757,"timestamp":"2024-06-01T18:06:20.343522Z"}]}
{"channel":"book","type":"update","data":[{"symbol":"ETH/GBP","bids":[{"price":2981.02,"qty":6.57941859}],"asks":[],"checksum":18747675,"timestamp":"2024-06-01T18:06:20.343548Z"}]}
{"channel":"book","type":"update","data":[{"symbol":"ETH/GBP","bids":[],"asks":[{"price":2981.42,"qty":6.57855865}],"checksum":1872274756,"timestamp":"2024-06-01T18:06:20.343569Z"}]}
{"channel":"book","type":"update","data":[{"symbol":"ETH/GBP","bids":[{"price":2980.11,"qty":0.00000000},{"price":2977.74,"qty":0.21600000}],"asks":[],"checksum":1864857731,"timestamp":"2024-06-01T18:06:20.346819Z"}]}
{"channel":"book","type":"update","data":[{"symbol":"ETH/GBP","bids":[{"price":2980.81,"qty":0.31000000}],"asks":[],"checksum":2105455593,"timestamp":"2024-06-01T18:06:20.346847Z"}]}
{"channel":"book","type":"update","data":[{"symbol":"ETH/GBP","bids":[{"price":2980.72,"qty":0.00000000},{"price":2977.74,"qty":0.21600000}],"asks":[],"checksum":1680403305,"timestamp":"2024-06-01T18:06:20.386568Z"}]}
{"channel":"book","type":"update","data":[{"symbol":"ETH/GBP","bids":[{"price":2980.81,"qty":0.00000000},{"price":2977.44,"qty":1.31746928}],"asks":[],"checksum":2446128845,"timestamp":"2024-06-01T18:06:20.389994Z"}]}
{"channel":"book","type":"update","data":[{"symbol":"ETH/GBP","bids":[{"price":2980.62,"qty":5.92938850}],"asks":[],"checksum":3442161575,"timestamp":"2024-06-01T18:06:20.391136Z"}]}
{"channel":"book","type":"update","data":[{"symbol":"ETH/GBP","bids":[{"price":2981.02,"qty":0.00000000},{"price":2977.44,"qty":1.31746928}],"asks":[],"checksum":2089917772,"timestamp":"2024-06-01T18:06:20.391192Z"}]}
{"channel":"book","type":"update","data":[{"symbol":"ETH/GBP","bids":[{"price":2978.86,"qty":0.00000000},{"price":2977.37,"qty":0.34450000}],"asks":[],"checksum":777826925,"timestamp":"2024-06-01T18:06:20.391644Z"}]}
{"channel":"book","type":"update","data":[{"symbol":"ETH/GBP","bids":[{"price":2980.62,"qty":0.00000000},{"price":2976.91,"qty":0.14096130}],"asks":[],"checksum":3424500087,"timestamp":"2024-06-01T18:06:20.453368Z"}]}
{"channel":"book","type":"update","data":[{"symbol":"ETH/GBP","bids":[{"price":2980.61,"qty":5.92940839}],"asks":[],"checksum":2027011354,"timestamp":"2024-06-01T18:06:20.458040Z"}]}
{"channel":"book","type":"update","data":[{"symbol":"ETH/GBP","bids":[{"price":2977.45,"qty":0.14093574}],"asks":[],"checksum":2372689212,"timestamp":"2024-06-01T18:06:20.459995Z"}]}
{"channel":"book","type":"update","data":[{"symbol":"ETH/GBP","bids":[{"price":2981.40,"qty":0.00000000},{"price":2977.37,"qty":0.34450000},{"price":2980.92,"qty":0.08554600}],"asks":[],"checksum":220303937,"timestamp":"2024-06-01T18:06:20.476336Z"}]}
{"channel":"book","type":"update","data":[{"symbol":"ETH/GBP","bids":[],"asks":[{"price":2981.42,"qty":0.00000000},{"price":2984.02,"qty":1.00000000}],"checksum":1671898654,"timestamp":"2024-06-01T18:06:20.482476Z"}]}
{"channel":"book","type":"update","data":[{"symbol":"ETH/GBP","bids":[],"asks":[{"price":2981.24,"qty":6.57895283}],"checksum":239108136,"timestamp":"2024-06-01T18:06:20.487903Z"}]}
{"channel":"book","type":"update","data":[{"symbol":"ETH/GBP","bids":[],"asks":[{"price":2981.68,"qty":13.15598562}],"checksum":3011206457,"timestamp":"2024-06-01T18:06:20.488060Z"}]}
{"channel":"book","type":"update","data":[{"symbol":"ETH/GBP","bids":[{"price":2980.59,"qty":13.16076889}],"asks":[],"checksum":2051777375,"timestamp":"2024-06-01T18:06:20.488145Z"}]}
{"channel":"book","type":"update","data":[{"symbol":"ETH/GBP","bids":[{"price":2980.93,"qty":6.57963570}],"asks":[],"checksum":3452637373,"timestamp":"2024-06-01T18:06:20.488260Z"}]}
{"channel":"book","type":"update","data":[{"symbol":"ETH/GBP","bids":[],"asks":[{"price":2981.68,"qty":0.00000000},{"price":2983.92,"qty":0.94850883}],"checksum":1718624511,"timestamp":"2024-06-01T18:06:20.492505Z"}]}
{"channel":"book","type":"update","data":[{"symbol":"ETH/GBP","bids":[{"price":2980.93,"qty":0.00000000},{"price":2977.45,"qty":0.14093574}],"asks":[],"checksum":273070192,"timestamp":"2024-06-01T18:06:20.492553Z"}]}
{"channel":"book","type":"update","data":[{"symbol":"ETH/GBP","bids":[],"asks":[{"price":2981.24,"qty":0.00000000},{"price":2984.02,"qty":1.00000000}],"checksum":3750873679,"timestamp":"2024-06-01T18:06:20.504672Z"}]}
{"channel":"book","type":"update","data":[{"symbol":"ETH/GBP","bids":[],"asks":[{"price":2981.24,"qty":6.57896328}],"checksum":944764791,"timestamp":"2024-06-01T18:06:20.628519Z"}]}
{"channel":"book","type":"update","data":[{"symbol":"ETH/GBP","bids":[{"price":2980.93,"qty":6.57962665}],"asks":[],"checksum":2425236658,"timestamp":"2024-06-01T18:06:20.628545Z"}]}
{"channel":"book","type":"update","data":[{"symbol":"ETH/GBP","bids":[{"price":2980.93,"qty":6.88962665}],"asks":[],"checksum":2143558087,"timestamp":"2024-06-01T18:06:20.631171Z"}]}
{"channel":"book","type":"update","data":[{"symbol":"ETH/GBP","bids":[{"price":2980.93,"qty":0.31000000}],"asks":[],"checksum":2826237659,"timestamp":"2024-06-01T18:06:20.633570Z"}]}
{"channel":"book","type":"update","data":[{"symbol":"ETH/GBP","bids":[{"price":2980.92,"qty":0.00000000},{"price":2977.45,"qty":0.14093574},{"price":2980.62,"qty":0.08554800}],"asks":[],"checksum":3484801387,"timestamp":"2024-06-01T18:06:20.666578Z"}]}
{"channel":"book","type":"update","data":[{"symbol":"ETH/GBP","bids":[],"asks":[{"price":2982.63,"qty":0.00000000},{"price":2984.02,"qty":1.00000000},{"price":2982.32,"qty":0.08550900}],"checksum":16000052,"timestamp":"2024-06-01T18:06:20.666670Z"}]}
{"channel":"book","type":"update","data":[{"symbol":"ETH/GBP","bids":[{"price":2980.93,"qty":0.00000000},{"price":2977.45,"qty":0.14093574}],"asks":[],"checksum":4182452346,"timestamp":"2024-06-01T18:06:20.669153Z"}]}
{"channel":"book","type":"update","data":[{"symbol":"ETH/GBP","bids":[{"price":2980.02,"qty":0.00000000},{"price":2977.44,"qty":1.31746928}],"asks":[],"checksum":2346294872,"timestamp":"2024-06-01T18:06:20.676222Z"}]}
{"channel":"book","type":"update","data":[{"symbol":"ETH/GBP","bids":[{"price":2981.00,"qty":6.57947233}],"asks":[],"checksum":3750486373,"timestamp":"2024-06-01T18:06:20.756612Z"}]}
{"channel":"book","type":"update","data":[{"symbol":"ETH/GBP","bids":[],"asks":[{"price":2981.67,"qty":13.15603475}],"checksum":2163207909,"timestamp":"2024-06-01T18:06:20.756628Z"}]}
{"channel":"book","type":"update","data":[{"symbol":"ETH/GBP","bids":[{"price":2980.61,"qty":0.00000000},{"price":2977.44,"qty":1.31746928}],"asks":[],"checksum":3104718758,"timestamp":"2024-06-01T18:06:20.825061Z"}]}
{"channel":"book","type":"update","data":[{"symbol":"ETH/GBP","bids":[{"price":2980.56,"qty":5.92950786}],"asks":[],"checksum":901490808,"timestamp":"2024-06-01T18:06:20.829203Z"}]}
{"channel":"book","type":"update","data":[{"symbol":"ETH/GBP","bids":[{"price":2980.56,"qty":0.00000000},{"price":2977.44,"qty":1.31746928}],"asks":[],"checksum":3104718758,"timestamp":"2024-06-01T18:06:20.907820Z"}]}
{"channel":"book","type":"update","data":[{"symbol":"ETH/GBP","bids":[],"asks":[{"price":2981.24,"qty":0.00000000},{"price":2983.92,"qty":0.94850883}],"checksum":2567875519,"timestamp":"2024-06-01T18:06:20.908331Z"}]}
{"channel":"book","type":"update","data":[{"symbol":"ETH/GBP","bids":[{"price":2980.52,"qty":5.92958744}],"asks":[],"checksum":3748244832,"timestamp":"2024-06-01T18:06:20.911909Z"}]}
{"channel":"book","type":"update","data":[{"symbol":"ETH/GBP","bids":[],"asks":[{"price":2981.67,"qty":0.00000000},{"price":2984.02,"qty":1.00000000}],"checksum":3461280386,"timestamp":"2024-06-01T18:06:20.912926Z"}]}
{"channel":"book","type":"update","data":[{"symbol":"ETH/GBP","bids":[{"price":2981.00,"qty":0.00000000},{"price":2977.44,"qty":1.31746928}],"asks":[],"checksum":1030682307,"timestamp":"2024-06-01T18:06:20.919158Z"}]}
{"channel":"book","type":"update","data":[{"symbol":"ETH/GBP","bids":[{"price":2980.59,"qty":0.00000000},{"price":2977.37,"qty":0.34450000}],"asks":[],"checksum":3930226191,"timestamp":"2024-06-01T18:06:20.920942Z"}]}
{"channel":"book","type":"update","data":[{"symbol":"ETH/GBP","bids":[],"asks":[{"price":2982.54,"qty":0.00000000},{"price":2984.03,"qty":1.31456248}],"checksum":2178032687,"timestamp":"2024-06-01T18:06:20.922693Z"}]}
{"channel":"book","type":"update","data":[{"symbol":"ETH/GBP","bids":[{"price":2980.48,"qty":13.16125372}],"asks":[],"checksum":3618163890,"timestamp":"2024-06-01T18:06:20.927776Z"}]}
{"channel":"book","type":"update","data":[{"symbol":"ETH/GBP","bids":[{"price":2980.89,"qty":6.57970980}],"asks":[],"checksum":3888525476,"timestamp":"2024-06-01T18:06:20.927793Z"}]}
{"channel":"book","type":"update","data":[{"symbol":"ETH/GBP","bids":[],"asks":[{"price":2981.13,"qty":6.57919852}],"checksum":1591710491,"timestamp":"2024-06-01T18:06:20.927900Z"}]}
{"channel":"book","type":"update","data":[{"symbol":"ETH/GBP","bids":[],"asks":[{"price":2981.13,"qty":0.00000000},{"price":2984.03,"qty":1.31456248}],"checksum":3888525476,"timestamp":"2024-06-01T18:06:20.940098Z"}]}
{"channel":"book","type":"update","data":[{"symbol":"ETH/GBP","bids":[{"price":2980.89,"qty":0.00000000},{"price":2977.44,"qty":1.31746928}],"asks":[],"checksum":3618163890,"timestamp":"2024-06-01T18:06:20.940185Z"}]}
{"channel":"book","type":"update","data":[{"symbol":"ETH/GBP","bids":[],"asks":[{"price":2982.31,"qty":13.15320120}],"checksum":653935589,"timestamp":"2024-06-01T18:06:20.966810Z"}]}
{"channel":"book","type":"update","data":[{"symbol":"ETH/GBP","bids":[],"asks":[{"price":2982.31,"qty":0.00000000},{"price":2984.03,"qty":1.31456248}],"checksum":3618163890,"timestamp":"2024-06-01T18:06:20.971222Z"}]}
{"channel":"book","type":"update","data":[{"symbol":"ETH/GBP","bids":[],"asks":[{"price":2981.13,"qty":6.57919465}],"checksum":3304691395,"timestamp":"2024-06-01T18:06:21.029900Z"}]}
{"channel":"book","type":"update","data":[{"symbol":"ETH/GBP","bids":[{"price":2980.90,"qty":6.57969796}],"asks":[],"checksum":3358054470,"timestamp":"2024-06-01T18:06:21.029940Z"}]}
{"channel":"book","type":"update","data":[{"symbol":"ETH/GBP","bids":[{"price":2980.90,"qty":0.00000000},{"price":2977.44,"qty":1.31746928}],"asks":[],"checksum":3304691395,"timestamp":"2024-06-01T18:06:21.035919Z"}]}
{"channel":"book","type":"update","data":[{"symbol":"ETH/GBP","bids":[],"asks":[{"price":2981.13,"qty":0.00000000},{"price":2984.03,"qty":1.31456248}],"checksum":3618163890,"timestamp":"2024-06-01T18:06:21.041721Z"}]}
{"channel":"book","type":"update","data":[{"symbol":"ETH/GBP","bids":[],"asks":[{"price":2981.11,"qty":6.57923988}],"checksum":4110969455,"timestamp":"2024-06-01T18:06:21.130229Z"}]}
{"channel":"book","type":"update","data":[{"symbol":"ETH/GBP","bids":[{"price":2980.88,"qty":6.57974320}],"asks":[],"checksum":463256834,"timestamp":"2024-06-01T18:06:21.130244Z"}]}
{"channel":"book","type":"update","data":[{"symbol":"ETH/GBP","bids":[{"price":2980.52,"qty":0.00000000},{"price":2977.44,"qty":1.31746928}],"asks":[],"checksum":2279055576,"timestamp":"2024-06-01T18:06:21.382710Z"}]}
{"channel":"book","type":"update","data":[{"symbol":"ETH/GBP","bids":[{"price":2980.40,"qty":5.92982618}],"asks":[],"checksum":3831946071,"timestamp":"2024-06-01T18:06:21.386639Z"}]}
{"channel":"book","type":"update","data":[{"symbol":"ETH/GBP","bids":[],"asks":[{"price":2981.11,"qty":0.00000000},{"price":2984.03,"qty":1.31456248}],"checksum":3334897034,"timestamp":"2024-06-01T18:06:21.387331Z"}]}
{"channel":"book","type":"update","data":[{"symbol":"ETH/GBP","bids":[],"asks":[{"price":2981.10,"qty":6.57926199}],"checksum":4115458431,"timestamp":"2024-06-01T18:06:21.391597Z"}]}
{"channel":"book","type":"update","data":[{"symbol":"ETH/GBP","bids":[{"price":2979.80,"qty":1.31642477}],"asks":[],"checksum":3624415975,"timestamp":"2024-06-01T18:06:21.391636Z"}]}
{"channel":"book","type":"update","data":[{"symbol":"ETH/GBP","bids":[],"asks":[{"price":2982.31,"qty":1.31532012}],"checksum":1600929928,"timestamp":"2024-06-01T18:06:21.391829Z"}]}
{"channel":"book","type":"update","data":[{"symbol":"ETH/GBP","bids":[],"asks":[{"price":2981.55,"qty":13.15657594}],"checksum":1463721417,"timestamp":"2024-06-01T18:06:21.391850Z"}]}
{"channel":"book","type":"update","data":[{"symbol":"ETH/GBP","bids":[],"asks":[{"price":2981.55,"qty":0.00000000},{"price":2983.92,"qty":0.94850883}],"checksum":1600929928,"timestamp":"2024-06-01T18:06:21.396814Z"}]}
{"channel":"book","type":"update","data":[{"symbol":"ETH/GBP","bids":[],"asks":[{"price":2982.42,"qty":0.00000000},{"price":2984.02,"qty":1.00000000}],"checksum":3857314920,"timestamp":"2024-06-01T18:06:21.406334Z"}]}
{"channel":"book","type":"update","data":[{"symbol":"ETH/GBP","bids":[],"asks":[{"price":2982.74,"qty":0.00000000},{"price":2984.03,"qty":1.31456248}],"checksum":4067084804,"timestamp":"2024-06-01T18:06:21.406457Z"}]}
{"channel":"book","type":"update","data":[{"symbol":"ETH/GBP","bids":[],"asks":[{"price":2983.46,"qty":0.00000000},{"price":2984.35,"qty":0.30200000}],"checksum":4275074473,"timestamp":"2024-06-01T18:06:21.406529Z"}]}
{"channel":"book","type":"update","data":[{"symbol":"ETH/GBP","bids":[],"asks":[{"price":2983.16,"qty":7.75873324}],"checksum":3321035794,"timestamp":"2024-06-01T18:06:21.411114Z"}]}
{"channel":"book","type":"update","data":[{"symbol":"ETH/GBP","bids":[],"asks":[{"price":2983.46,"qty":22.06218994}],"checksum":3379285027,"timestamp":"2024-06-01T18:06:21.411173Z"}]}
{"channel":"book","type":"update","data":[{"symbol":"ETH/GBP","bids":[{"price":2980.88,"qty":0.00000000},{"price":2977.45,"qty":0.14093574}],"asks":[],"checksum":1140444464,"timestamp":"2024-06-01T18:06:21.414661Z"}]}
{"channel":"book","type":"update","data":[{"symbol":"ETH/GBP","bids":[{"price":2980.86,"qty":6.57977611}],"asks":[],"checksum":696166972,"timestamp":"2024-06-01T18:06:21.420092Z"}]}
{"channel":"book","type":"update","data":[{"symbol":"ETH/GBP","bids":[],"asks":[{"price":2981.10,"qty":0.00000000},{"price":2984.03,"qty":1.31456248}],"checksum":2902635697,"timestamp":"2024-06-01T18:06:21.428080Z"}]}
{"channel":"book","type":"update","data":[{"symbol":"ETH/GBP","bids":[{"price":2980.48,"qty":0.00000000},{"price":2977.45,"qty":0.14093574}],"asks":[],"checksum":18212201,"timestamp":"2024-06-01T18:06:21.430721Z"}]}
{"channel":"book","type":"update","data":[{"symbol":"ETH/GBP","bids":[],"asks":[{"price":2982.31,"qty":0.00000000},{"price":2984.35,"qty":0.30200000}],"checksum":2084572103,"timestamp":"2024-06-01T18:06:21.432497Z"}]}
{"channel":"book","type":"update","data":[{"symbol":"ETH/GBP","bids":[],"asks":[{"price":2982.33,"qty":0.00000000},{"price":2984.40,"qty":2.94416492}],"checksum":1772060154,"timestamp":"2024-06-01T18:06:21.435048Z"}]}
{"channel":"book","type":"update","data":[{"symbol":"ETH/GBP","bids":[{"price":2980.42,"qty":13.16150913}],"asks":[],"checksum":2092166762,"timestamp":"2024-06-01T18:06:21.436956Z"}]}
{"channel":"book","type":"update","data":[{"symbol":"ETH/GBP","bids":[],"asks":[{"price":2982.31,"qty":6.57660126}],"checksum":848662663,"timestamp":"2024-06-01T18:06:21.509080Z"}]}
{"channel":"book","type":"update","data":[{"symbol":"ETH/GBP","bids":[],"asks":[{"price":2982.31,"qty":0.00000000},{"price":2984.40,"qty":2.94416492}],"checksum":2092166762,"timestamp":"2024-06-01T18:06:21.513941Z"}]}
{"channel":"book","type":"update","data":[{"symbol":"ETH/GBP","bids":[],"asks":[{"price":2982.31,"qty":13.15320253}],"checksum":3320804489,"timestamp":"2024-06-01T18:06:21.649759Z"}]}
{"channel":"book","type":"update","data":[{"symbol":"ETH/GBP","bids":[],"asks":[{"price":2982.31,"qty":19.72980379}],"checksum":94327091,"timestamp":"2024-06-01T18:06:21.649897Z"}]}
{"channel":"book","type":"update","data":[{"symbol":"ETH/GBP","bids":[{"price":2980.86,"qty":0.00000000},{"price":2977.45,"qty":0.14093574}],"asks":[],"checksum":2987048920,"timestamp":"2024-06-01T18:06:21.652899Z"}]}
{"channel":"book","type":"update","data":[{"symbol":"ETH/GBP","bids":[],"asks":[{"price":2982.31,"qty":6.57660126}],"checksum":1626405683,"timestamp":"2024-06-01T18:06:21.655586Z"}]}
{"channel":"book","type":"update","data":[{"symbol":"ETH/GBP","bids":[],"asks":[{"price":2982.31,"qty":0.00000000},{"price":2984.40,"qty":2.94416492}],"checksum":1108165329,"timestamp":"2024-06-01T18:06:21.655612Z"}]}
{"channel":"book","type":"update","data":[{"symbol":"ETH/GBP","bids":[{"price":2980.63,"qty":6.58028271}],"asks":[],"checksum":4194771584,"timestamp":"2024-06-01T18:06:21.660408Z"}]}
{"channel":"book","type":"update","data":[{"symbol":"ETH/GBP","bids":[{"price":2980.63,"qty":0.00000000},{"price":2977.45,"qty":0.14093574}],"asks":[],"checksum":1108165329,"timestamp":"2024-06-01T18:06:21.664624Z"}]}
{"channel":"book","type":"update","data":[{"symbol":"ETH/GBP","bids":[],"asks":[{"price":2982.31,"qty":6.57660655}],"checksum":287188879,"timestamp":"2024-06-01T18:06:21.813066Z"}]}
{"channel":"book","type":"update","data":[{"symbol":"ETH/GBP","bids":[{"price":2980.87,"qty":6.57976335}],"asks":[],"checksum":1391359928,"timestamp":"2024-06-01T18:06:21.813102Z"}]}
{"channel":"book","type":"update","data":[{"symbol":"ETH/GBP","bids":[],"asks":[{"price":2982.31,"qty":0.00000000},{"price":2984.40,"qty":2.94416492}],"checksum":3731757102,"timestamp":"2024-06-01T18:06:21.818592Z"}]}
{"channel":"book","type":"update","data":[{"symbol":"ETH/GBP","bids":[{"price":2980.87,"qty":0.00000000},{"price":2977.45,"qty":0.14093574}],"asks":[],"checksum":1108165329,"timestamp":"2024-06-01T18:06:21.924976Z"}]}
{"channel":"book","type":"update","data":[{"symbol":"ETH/GBP","bids":[{"price":2980.88,"qty":6.57973966}],"asks":[],"checksum":3454587572,"timestamp":"2024-06-01T18:06:21.929942Z"}]}
{"channel":"book","type":"update","data":[{"symbol":"ETH/GBP","bids":[],"asks":[{"price":2981.55,"qty":13.15654664}],"checksum":1205353604,"timestamp":"2024-06-01T18:06:21.929974Z"}]}
{"channel":"book","type":"update","data":[{"symbol":"ETH/GBP","bids":[],"asks":[{"price":2981.12,"qty":6.57922457}],"checksum":3214506608,"timestamp":"2024-06-01T18:06:21.930073Z"}]}
{"channel":"book","type":"update","data":[{"symbol":"ETH/GBP","bids":[],"asks":[{"price":2981.12,"qty":0.00000000},{"price":2984.35,"qty":0.30200000}],"checksum":1205353604,"timestamp":"2024-06-01T18:06:22.044250Z"}]}
{"channel":"book","type":"update","data":[{"symbol":"ETH/GBP","bids":[],"asks":[{"price":2981.11,"qty":6.57925028}],"checksum":2197964419,"timestamp":"2024-06-01T18:06:22.049147Z"}]}
{"channel":"book","type":"update","data":[{"symbol":"ETH/GBP","bids":[],"asks":[{"price":2981.55,"qty":0.00000000},{"price":2984.35,"qty":0.30200000}],"checksum":1567561289,"timestamp":"2024-06-01T18:06:22.049171Z"}]}
{"channel":"book","type":"update","data":[{"symbol":"ETH/GBP","bids":[],"asks":[{"price":2982.32,"qty":0.00000000},{"price":2984.40,"qty":2.94416492},{"price":2983.15,"qty":0.08548300}],"checksum":3107279891,"timestamp":"2024-06-01T18:06:22.107768Z"}]}
{"channel":"book","type":"update","data":[{"symbol":"ETH/GBP","bids":[{"price":2980.88,"qty":0.00000000},{"price":2977.45,"qty":0.14093574}],"asks":[],"checksum":777617234,"timestamp":"2024-06-01T18:06:22.161092Z"}]}
{"channel":"book","type":"update","data":[{"symbol":"ETH/GBP","bids":[],"asks":[{"price":2981.54,"qty":13.15657912}],"checksum":3708603708,"timestamp":"2024-06-01T18:06:22.165751Z"}]}
{"channel":"book","type":"update","data":[{"symbol":"ETH/GBP","bids":[{"price":2980.89,"qty":6.57970613}],"asks":[],"checksum":2306856101,"timestamp":"2024-06-01T18:06:22.165785Z"}]}
{"channel":"book","type":"update","data":[{"symbol":"ETH/GBP","bids":[],"asks":[{"price":2981.11,"qty":0.00000000},{"price":2984.35,"qty":0.30200000}],"checksum":129311544,"timestamp":"2024-06-01T18:06:22.179203Z"}]}
{"channel":"book","type":"update","data":[{"symbol":"ETH/GBP","bids":[{"price":2980.42,"qty":0.00000000},{"price":2977.45,"qty":0.14093574}],"asks":[],"checksum":843025540,"timestamp":"2024-06-01T18:06:22.179271Z"}]}
{"channel":"book","type":"update","data":[{"symbol":"ETH/GBP","bids":[{"price":2980.89,"qty":0.00000000},{"price":2977.44,"qty":1.31746928}],"asks":[],"checksum":2801127988,"timestamp":"2024-06-01T18:06:22.179343Z"}]}
{"channel":"book","type":"update","data":[{"symbol":"ETH/GBP","bids":[],"asks":[{"price":2981.13,"qty":6.57920027}],"checksum":2697876783,"timestamp":"2024-06-01T18:06:22.184301Z"}]}
{"channel":"book","type":"update","data":[{"symbol":"ETH/GBP","bids":[{"price":2980.48,"qty":13.16125727}],"asks":[],"checksum":1078737915,"timestamp":"2024-06-01T18:06:22.184644Z"}]}
{"channel":"book","type":"update","data":[{"symbol":"ETH/GBP","bids":[],"asks":[{"price":2981.13,"qty":0.00000000},{"price":2984.35,"qty":0.30200000}],"checksum":3392129424,"timestamp":"2024-06-01T18:06:22.189451Z"}]}
{"channel":"book","type":"update","data":[{"symbol":"ETH/GBP","bids":[],"asks":[{"price":2982.30,"qty":1.31532273}],"checksum":1461951215,"timestamp":"2024-06-01T18:06:22.440236Z"}]}
{"channel":"book","type":"update","data":[{"symbol":"ETH/GBP","bids":[{"price":2980.89,"qty":6.57972192}],"asks":[],"checksum":4172688608,"timestamp":"2024-06-01T18:06:22.440269Z"}]}
{"channel":"book","type":"update","data":[{"symbol":"ETH/GBP","bids":[],"asks":[{"price":2981.53,"qty":6.57831162}],"checksum":3754358210,"timestamp":"2024-06-01T18:06:22.440368Z"}]}
{"channel":"book","type":"update","data":[{"symbol":"ETH/GBP","bids":[],"asks":[{"price":2981.53,"qty":0.00000000},{"price":2984.03,"qty":1.31456248}],"checksum":4172688608,"timestamp":"2024-06-01T18:06:22.445060Z"}]}
{"channel":"book","type":"update","data":[{"symbol":"ETH/GBP","bids":[],"asks":[{"price":2981.11,"qty":6.57924181}],"checksum":814903695,"timestamp":"2024-06-01T18:06:22.969879Z"}]}
{"channel":"book","type":"update","data":[{"symbol":"ETH/GBP","bids":[],"asks":[{"price":2981.11,"qty":0.00000000},{"price":2984.03,"qty":1.31456248}],"checksum":4172688608,"timestamp":"2024-06-01T18:06:22.992683Z"}]}
{"channel":"book","type":"update","data":[{"symbol":"ETH/GBP","bids":[{"price":2980.89,"qty":0.00000000},{"price":2977.45,"qty":0.14093574}],"asks":[],"checksum":1461951215,"timestamp":"2024-06-01T18:06:22.992732Z"}]}
{"channel":"book","type":"update","data":[{"symbol":"ETH/GBP","bids":[{"price":2980.91,"qty":6.57967816}],"asks":[],"checksum":3353914733,"timestamp":"2024-06-01T18:06:22.999152Z"}]}
