{"channel":"book","type":"snapshot","data":[{"symbol":"ETH/USD","bids":[{"price":3800.30,"qty":0.00903714},{"price":3800.29,"qty":0.52627562},{"price":3800.23,"qty":0.33536582},{"price":3800.22,"qty":39.46862917},{"price":3800.19,"qty":26.31442493},{"price":3800.06,"qty":1.54000000},{"price":3800.03,"qty":26.31555985},{"price":3799.86,"qty":3.94712952},{"price":3799.85,"qty":0.80086998},{"price":3799.73,"qty":26.31763316}],"asks":[{"price":3800.52,"qty":26.31222341},{"price":3800.64,"qty":7.24211245},{"price":3800.66,"qty":2.11700000},{"price":3800.70,"qty":1.54000000},{"price":3800.81,"qty":26.31024560},{"price":3800.93,"qty":47.29837341},{"price":3801.13,"qty":10.81226191},{"price":3801.14,"qty":26.30794116},{"price":3801.37,"qty":0.57405813},{"price":3801.40,"qty":3.00000000}],"checksum":4054006350}]}
{"channel":"book","type":"update","data":[{"symbol":"ETH/USD","bids":[{"price":3800.06,"qty":0.77000000}],"asks":[],"checksum":152852144,"timestamp":"2024-06-01T18:06:04.864940Z"}]}
{"channel":"book","type":"update","data":[{"symbol":"ETH/USD","bids":[],"asks":[{"price":3800.70,"qty":0.77000000}],"checksum":2462394571,"timestamp":"2024-06-01T18:06:04.867843Z"}]}
{"channel":"book","type":"update","data":[{"symbol":"ETH/USD","bids":[],"asks":[{"price":3800.52,"qty":0.00000000},{"price":3801.44,"qty":4.53808791}],"checksum":223453022,"timestamp":"2024-06-01T18:06:05.319020Z"}]}
{"channel":"book","type":"update","data":[{"symbol":"ETH/USD","bids":[],"asks":[{"price":3800.50,"qty":26.31233671}],"checksum":1766888550,"timestamp":"2024-06-01T18:06:05.323939Z"}]}
{"channel":"book","type":"update","data":[{"symbol":"ETH/USD","bids":[{"price":3800.31,"qty":3.94683871}],"asks":[],"checksum":2396473462,"timestamp":"2024-06-01T18:06:05.490305Z"}]}
{"channel":"book","type":"update","data":[{"symbol":"ETH/USD","bids":[{"price":3799.86,"qty":0.00000000},{"price":3799.73,"qty":26.31763316}],"asks":[],"checksum":2887394395,"timestamp":"2024-06-01T18:06:05.494194Z"}]}
{"channel":"book","type":"update","data":[{"symbol":"ETH/USD","bids":[{"price":3800.30,"qty":0.00000000},{"price":3799.71,"qty":4.02912968},{"price":3800.32,"qty":0.00903662}],"asks":[],"checksum":2046184151,"timestamp":"2024-06-01T18:06:05.534463Z"}]}
{"channel":"book","type":"update","data":[{"symbol":"ETH/USD","bids":[{"price":3800.22,"qty":13.15440537}],"asks":[],"checksum":1425426058,"timestamp":"2024-06-01T18:06:05.850676Z"}]}
{"channel":"book","type":"update","data":[{"symbol":"ETH/USD","bids":[],"asks":[{"price":3800.50,"qty":0.00000000},{"price":3801.44,"qty":4.53808791}],"checksum":821513650,"timestamp":"2024-06-01T18:06:05.850824Z"}]}
{"channel":"book","type":"update","data":[{"symbol":"ETH/USD","bids":[{"price":3800.32,"qty":3.95587533}],"asks":[],"checksum":491395469,"timestamp":"2024-06-01T18:06:05.855154Z"}]}
{"channel":"book","type":"update","data":[{"symbol":"ETH/USD","bids":[],"asks":[{"price":3800.49,"qty":26.31242880}],"checksum":1782255609,"timestamp":"2024-06-01T18:06:05.856212Z"}]}
{"channel":"book","type":"update","data":[{"symbol":"ETH/USD","bids":[{"price":3799.92,"qty":26.31628940}],"asks":[],"checksum":3284228905,"timestamp":"2024-06-01T18:06:05.856236Z"}]}
{"channel":"book","type":"update","data":[{"symbol":"ETH/USD","bids":[{"price":3800.31,"qty":0.00000000},{"price":3799.73,"qty":26.31763316}],"asks":[],"checksum":4248082999,"timestamp":"2024-06-01T18:06:05.858868Z"}]}
{"channel":"book","type":"update","data":[{"symbol":"ETH/USD","bids":[{"price":3800.29,"qty":0.00000000},{"price":3799.71,"qty":4.02912968}],"asks":[],"checksum":2200406807,"timestamp":"2024-06-01T18:06:06.055678Z"}]}
{"channel":"book","type":"update","data":[{"symbol":"ETH/USD","bids":[],"asks":[{"price":3800.49,"qty":0.00000000},{"price":3801.44,"qty":4.53808791}],"checksum":1017181637,"timestamp":"2024-06-01T18:06:06.138928Z"}]}
{"channel":"book","type":"update","data":[{"symbol":"ETH/USD","bids":[{"price":3800.03,"qty":0.00000000},{"price":3799.69,"qty":3.00000000}],"asks":[],"checksum":2486238054,"timestamp":"2024-06-01T18:06:06.139006Z"}]}
{"channel":"book","type":"update","data":[{"symbol":"ETH/USD","bids":[{"price":3800.23,"qty":0.00000000},{"price":3799.67,"qty":3.94712952}],"asks":[],"checksum":4174942448,"timestamp":"2024-06-01T18:06:06.139572Z"}]}
{"channel":"book","type":"update","data":[{"symbol":"ETH/USD","bids":[],"asks":[{"price":3800.63,"qty":0.52622854}],"checksum":489923496,"timestamp":"2024-06-01T18:06:06.143555Z"}]}
{"channel":"book","type":"update","data":[{"symbol":"ETH/USD","bids":[],"asks":[{"price":3800.51,"qty":26.31227588}],"checksum":206451619,"timestamp":"2024-06-01T18:06:06.145660Z"}]}
{"channel":"book","type":"update","data":[{"symbol":"ETH/USD","bids":[{"price":3800.21,"qty":26.31427902}],"asks":[],"checksum":4034752441,"timestamp":"2024-06-01T18:06:06.145678Z"}]}
{"channel":"book","type":"update","data":[{"symbol":"ETH/USD","bids":[],"asks":[{"price":3800.51,"qty":0.00000000},{"price":3801.40,"qty":3.00000000}],"checksum":1740557217,"timestamp":"2024-06-01T18:06:06.226414Z"}]}
{"channel":"book","type":"update","data":[{"symbol":"ETH/USD","bids":[],"asks":[{"price":3800.93,"qty":46.50414384}],"checksum":3011678901,"timestamp":"2024-06-01T18:06:06.229528Z"}]}
{"channel":"book","type":"update","data":[{"symbol":"ETH/USD","bids":[],"asks":[{"price":3800.50,"qty":26.31237587}],"checksum":1728719595,"timestamp":"2024-06-01T18:06:06.232133Z"}]}
{"channel":"book","type":"update","data":[{"symbol":"ETH/USD","bids":[{"price":3800.32,"qty":3.94683871},{"price":3800.33,"qty":0.00903660}],"asks":[],"checksum":3889404520,"timestamp":"2024-06-01T18:06:06.272133Z"}]}
{"channel":"book","type":"update","data":[{"symbol":"ETH/USD","bids":[],"asks":[{"price":3800.49,"qty":2.20000000}],"checksum":1791419047,"timestamp":"2024-06-01T18:06:06.290635Z"}]}
{"channel":"book","type":"update","data":[{"symbol":"ETH/USD","bids":[],"asks":[{"price":3800.50,"qty":0.00000000},{"price":3801.37,"qty":0.57405813}],"checksum":287282285,"timestamp":"2024-06-01T18:06:06.324205Z"}]}
{"channel":"book","type":"update","data":[{"symbol":"ETH/USD","bids":[],"asks":[{"price":3800.49,"qty":28.51243115}],"checksum":3382597361,"timestamp":"2024-06-01T18:06:06.328810Z"}]}
{"channel":"book","type":"update","data":[{"symbol":"ETH/USD","bids":[],"asks":[{"price":3800.63,"qty":1.34094808}],"checksum":2369431673,"timestamp":"2024-06-01T18:06:06.332178Z"}]}
{"channel":"book","type":"update","data":[{"symbol":"ETH/USD","bids":[],"asks":[{"price":3800.49,"qty":2.20000000}],"checksum":1952184020,"timestamp":"2024-06-01T18:06:06.404734Z"}]}
{"channel":"book","type":"update","data":[{"symbol":"ETH/USD","bids":[],"asks":[{"price":3800.51,"qty":26.31228642}],"checksum":1374947458,"timestamp":"2024-06-01T18:06:06.409401Z"}]}
{"channel":"book","type":"update","data":[{"symbol":"ETH/USD","bids":[],"asks":[{"price":3800.51,"qty":0.00000000},{"price":3801.37,"qty":0.57405813}],"checksum":1952184020,"timestamp":"2024-06-01T18:06:06.602239Z"}]}
{"channel":"book","type":"update","data":[{"symbol":"ETH/USD","bids":[],"asks":[{"price":3800.63,"qty":0.81471954}],"checksum":2785457911,"timestamp":"2024-06-01T18:06:06.606701Z"}]}
{"channel":"book","type":"update","data":[{"symbol":"ETH/USD","bids":[],"asks":[{"price":3800.50,"qty":26.31236870}],"checksum":1039762306,"timestamp":"2024-06-01T18:06:06.607330Z"}]}
{"channel":"book","type":"update","data":[{"symbol":"ETH/USD","bids":[],"asks":[{"price":3800.93,"qty":0.00000000},{"price":3801.37,"qty":0.57405813}],"checksum":2296076361,"timestamp":"2024-06-01T18:06:06.915712Z"}]}
{"channel":"book","type":"update","data":[{"symbol":"ETH/USD","bids":[],"asks":[{"price":3800.64,"qty":0.00000000},{"price":3801.40,"qty":3.00000000}],"checksum":185036096,"timestamp":"2024-06-01T18:06:06.915729Z"}]}
{"channel":"book","type":"update","data":[{"symbol":"ETH/USD","bids":[],"asks":[{"price":3800.49,"qty":0.00000000},{"price":3801.44,"qty":4.53808791}],"checksum":4036380036,"timestamp":"2024-06-01T18:06:06.918932Z"}]}
{"channel":"book","type":"update","data":[{"symbol":"ETH/USD","bids":[],"asks":[{"price":3801.12,"qty":27.90633950}],"checksum":3915180032,"timestamp":"2024-06-01T18:06:06.920872Z"}]}
{"channel":"book","type":"update","data":[{"symbol":"ETH/USD","bids":[],"asks":[{"price":3800.49,"qty":2.20000000}],"checksum":3607867422,"timestamp":"2024-06-01T18:06:07.025564Z"}]}
{"channel":"book","type":"update","data":[{"symbol":"ETH/USD","bids":[{"price":3800.34,"qty":0.33536582}],"asks":[],"checksum":760493668,"timestamp":"2024-06-01T18:06:07.087265Z"}]}
{"channel":"book","type":"update","data":[{"symbol":"ETH/USD","bids":[{"price":3800.33,"qty":0.00000000},{"price":3799.71,"qty":4.02912968},{"price":3800.35,"qty":0.00903656}],"asks":[],"checksum":613289040,"timestamp":"2024-06-01T18:06:07.137629Z"}]}
{"channel":"book","type":"update","data":[{"symbol":"ETH/USD","bids":[],"asks":[{"price":3801.37,"qty":0.00000000},{"price":3801.40,"qty":3.00000000}],"checksum":2167921679,"timestamp":"2024-06-01T18:06:07.162670Z"}]}
{"channel":"book","type":"update","data":[{"symbol":"ETH/USD","bids":[],"asks":[{"price":3800.58,"qty":26.31183714}],"checksum":2195921666,"timestamp":"2024-06-01T18:06:08.242403Z"}]}
{"channel":"book","type":"update","data":[{"symbol":"ETH/USD","bids":[],"asks":[{"price":3800.50,"qty":0.00000000},{"price":3801.40,"qty":3.00000000}],"checksum":2750216359,"timestamp":"2024-06-01T18:06:08.325225Z"}]}
{"channel":"book","type":"update","data":[{"symbol":"ETH/USD","bids":[],"asks":[{"price":3800.49,"qty":28.51244781}],"checksum":2802912073,"timestamp":"2024-06-01T18:06:08.329150Z"}]}
{"channel":"book","type":"update","data":[{"symbol":"ETH/USD","bids":[],"asks":[{"price":3800.49,"qty":2.20000000}],"checksum":2750216359,"timestamp":"2024-06-01T18:06:08.609948Z"}]}
{"channel":"book","type":"update","data":[{"symbol":"ETH/USD","bids":[],"asks":[{"price":3800.49,"qty":0.00000000},{"price":3801.44,"qty":4.53808791}],"checksum":1794707996,"timestamp":"2024-06-01T18:06:08.612564Z"}]}
{"channel":"book","type":"update","data":[{"symbol":"ETH/USD","bids":[],"asks":[{"price":3800.51,"qty":26.31227025}],"checksum":464580704,"timestamp":"2024-06-01T18:06:08.614328Z"}]}
{"channel":"book","type":"update","data":[{"symbol":"ETH/USD","bids":[],"asks":[{"price":3800.50,"qty":2.20000000}],"checksum":3066326173,"timestamp":"2024-06-01T18:06:08.726318Z"}]}
{"channel":"book","type":"update","data":[{"symbol":"ETH/USD","bids":[],"asks":[{"price":3800.70,"qty":0.00000000},{"price":3801.40,"qty":3.00000000}],"checksum":2629338424,"timestamp":"2024-06-01T18:06:08.733732Z"}]}
{"channel":"book","type":"update","data":[{"symbol":"ETH/USD","bids":[],"asks":[{"price":3800.51,"qty":0.00000000},{"price":3801.44,"qty":4.53808791}],"checksum":4153481064,"timestamp":"2024-06-01T18:06:08.738978Z"}]}
{"channel":"book","type":"update","data":[{"symbol":"ETH/USD","bids":[{"price":3800.21,"qty":0.00000000},{"price":3799.71,"qty":4.02912968}],"asks":[],"checksum":3730998082,"timestamp":"2024-06-01T18:06:08.739087Z"}]}
{"channel":"book","type":"update","data":[{"symbol":"ETH/USD","bids":[],"asks":[{"price":3800.53,"qty":26.31213605}],"checksum":572140638,"timestamp":"2024-06-01T18:06:08.744114Z"}]}
{"channel":"book","type":"update","data":[{"symbol":"ETH/USD","bids":[{"price":3800.24,"qty":26.31411366}],"asks":[],"checksum":2412451024,"timestamp":"2024-06-01T18:06:08.744147Z"}]}
{"channel":"book","type":"update","data":[{"symbol":"ETH/USD","bids":[{"price":3800.24,"qty":0.00000000},{"price":3799.71,"qty":4.02912968}],"asks":[],"checksum":572140638,"timestamp":"2024-06-01T18:06:08.823777Z"}]}
{"channel":"book","type":"update","data":[{"symbol":"ETH/USD","bids":[],"asks":[{"price":3800.53,"qty":0.00000000},{"price":3801.44,"qty":4.53808791}],"checksum":3730998082,"timestamp":"2024-06-01T18:06:08.823863Z"}]}
{"channel":"book","type":"update","data":[{"symbol":"ETH/USD","bids":[],"asks":[{"price":3800.51,"qty":26.31228604}],"checksum":1167092068,"timestamp":"2024-06-01T18:06:08.828449Z"}]}
{"channel":"book","type":"update","data":[{"symbol":"ETH/USD","bids":[{"price":3800.22,"qty":39.46866903}],"asks":[],"checksum":3358794317,"timestamp":"2024-06-01T18:06:08.828558Z"}]}
{"channel":"book","type":"update","data":[{"symbol":"ETH/USD","bids":[],"asks":[{"price":3800.65,"qty":0.77000000}],"checksum":74443822,"timestamp":"2024-06-01T18:06:08.866841Z"}]}
{"channel":"book","type":"update","data":[{"symbol":"ETH/USD","bids":[],"asks":[{"price":3800.51,"qty":0.00000000},{"price":3801.40,"qty":3.00000000}],"checksum":3445594751,"timestamp":"2024-06-01T18:06:08.870407Z"}]}
{"channel":"book","type":"update","data":[{"symbol":"ETH/USD","bids":[{"price":3800.22,"qty":13.15440537}],"asks":[],"checksum":1090310486,"timestamp":"2024-06-01T18:06:08.872604Z"}]}
{"channel":"book","type":"update","data":[{"symbol":"ETH/USD","bids":[],"asks":[{"price":3800.46,"qty":26.31260428}],"checksum":2181291192,"timestamp":"2024-06-01T18:06:08.909713Z"}]}
{"channel":"book","type":"update","data":[{"symbol":"ETH/USD","bids":[{"price":3800.20,"qty":26.31437418}],"asks":[],"checksum":4218406888,"timestamp":"2024-06-01T18:06:08.909898Z"}]}
{"channel":"book","type":"update","data":[{"symbol":"ETH/USD","bids":[],"asks":[{"price":3800.65,"qty":0.00000000},{"price":3801.40,"qty":3.00000000}],"checksum":3494370222,"timestamp":"2024-06-01T18:06:09.007608Z"}]}
{"channel":"book","type":"update","data":[{"symbol":"ETH/USD","bids":[{"price":3800.20,"qty":0.00000000},{"price":3799.71,"qty":4.02912968}],"asks":[],"checksum":507840514,"timestamp":"2024-06-01T18:06:09.038795Z"}]}
{"channel":"book","type":"update","data":[{"symbol":"ETH/USD","bids":[],"asks":[{"price":3800.46,"qty":0.00000000},{"price":3801.44,"qty":4.53808791}],"checksum":3730998082,"timestamp":"2024-06-01T18:06:09.038807Z"}]}
{"channel":"book","type":"update","data":[{"symbol":"ETH/USD","bids":[],"asks":[{"price":3800.50,"qty":28.51233589}],"checksum":470475584,"timestamp":"2024-06-01T18:06:09.044106Z"}]}
{"channel":"book","type":"update","data":[{"symbol":"ETH/USD","bids":[{"price":3800.22,"qty":39.46865133}],"asks":[],"checksum":1584185060,"timestamp":"2024-06-01T18:06:09.044310Z"}]}
{"channel":"book","type":"update","data":[{"symbol":"ETH/USD","bids":[],"asks":[{"price":3800.65,"qty":0.77000000}],"checksum":3171232078,"timestamp":"2024-06-01T18:06:09.122828Z"}]}
{"channel":"book","type":"update","data":[{"symbol":"ETH/USD","bids":[{"price":3800.34,"qty":0.00000000},{"price":3799.69,"qty":3.00000000}],"asks":[],"checksum":3807270258,"timestamp":"2024-06-01T18:06:09.244433Z"}]}
{"channel":"book","type":"update","data":[{"symbol":"ETH/USD","bids":[{"price":3800.35,"qty":0.00000000},{"price":3799.68,"qty":7.77842526},{"price":3800.33,"qty":0.00903354}],"asks":[],"checksum":791570383,"timestamp":"2024-06-01T18:06:09.305519Z"}]}
{"channel":"book","type":"update","data":[{"symbol":"ETH/USD","bids":[{"price":3800.22,"qty":13.15440537}],"asks":[],"checksum":2175753123,"timestamp":"2024-06-01T18:06:09.311598Z"}]}
{"channel":"book","type":"update","data":[{"symbol":"ETH/USD","bids":[{"price":3800.23,"qty":26.31416573}],"asks":[],"checksum":1680809830,"timestamp":"2024-06-01T18:06:09.315802Z"}]}
{"channel":"book","type":"update","data":[{"symbol":"ETH/USD","bids":[],"asks":[{"price":3801.12,"qty":0.00000000},{"price":3801.44,"qty":4.53808791}],"checksum":2892233297,"timestamp":"2024-06-01T18:06:09.365411Z"}]}
{"channel":"book","type":"update","data":[{"symbol":"ETH/USD","bids":[],"asks":[{"price":3801.12,"qty":1.04284434}],"checksum":1143477653,"timestamp":"2024-06-01T18:06:09.370668Z"}]}
{"channel":"book","type":"update","data":[{"symbol":"ETH/USD","bids":[{"price":3800.06,"qty":0.00000000},{"price":3799.69,"qty":3.00000000},{"price":3799.96,"qty":0.77000000}],"asks":[],"checksum":2378294639,"timestamp":"2024-06-01T18:06:09.432649Z"}]}
{"channel":"book","type":"update","data":[{"symbol":"ETH/USD","bids":[{"price":3799.96,"qty":1.54000000}],"asks":[],"checksum":316572700,"timestamp":"2024-06-01T18:06:09.435967Z"}]}
{"channel":"book","type":"update","data":[{"symbol":"ETH/USD","bids":[],"asks":[{"price":3800.66,"qty":0.00000000},{"price":3801.44,"qty":4.53808791}],"checksum":1849958017,"timestamp":"2024-06-01T18:06:09.549831Z"}]}
{"channel":"book","type":"update","data":[{"symbol":"ETH/USD","bids":[],"asks":[{"price":3800.63,"qty":0.00000000},{"price":3801.61,"qty":0.00517907}],"checksum":1584024642,"timestamp":"2024-06-01T18:06:09.550561Z"}]}
{"channel":"book","type":"update","data":[{"symbol":"ETH/USD","bids":[],"asks":[{"price":3800.65,"qty":0.00000000},{"price":3801.62,"qty":5.26000000}],"checksum":599932776,"timestamp":"2024-06-01T18:06:09.551725Z"}]}
{"channel":"book","type":"update","data":[{"symbol":"ETH/USD","bids":[],"asks":[{"price":3800.50,"qty":26.31233589}],"checksum":1096948388,"timestamp":"2024-06-01T18:06:09.553340Z"}]}
{"channel":"book","type":"update","data":[{"symbol":"ETH/USD","bids":[{"price":3800.33,"qty":3.00903354}],"asks":[],"checksum":3216440319,"timestamp":"2024-06-01T18:06:09.555291Z"}]}
{"channel":"book","type":"update","data":[{"symbol":"ETH/USD","bids":[{"price":3800.33,"qty":6.00903354}],"asks":[],"checksum":3713796940,"timestamp":"2024-06-01T18:06:09.555311Z"}]}
{"channel":"book","type":"update","data":[{"symbol":"ETH/USD","bids":[],"asks":[{"price":3801.40,"qty":0.00000000},{"price":3801.71,"qty":1.50038279}],"checksum":159003138,"timestamp":"2024-06-01T18:06:09.558819Z"}]}
{"channel":"book","type":"update","data":[{"symbol":"ETH/USD","bids":[],"asks":[{"price":3800.50,"qty":0.00000000},{"price":3801.72,"qty":0.57565183}],"checksum":1391690867,"timestamp":"2024-06-01T18:06:09.558847Z"}]}
{"channel":"book","type":"update","data":[{"symbol":"ETH/USD","bids":[{"price":3800.23,"qty":0.00000000},{"price":3799.69,"qty":3.00000000}],"asks":[],"checksum":404178502,"timestamp":"2024-06-01T18:06:09.558919Z"}]}
{"channel":"book","type":"update","data":[{"symbol":"ETH/USD","bids":[{"price":3800.34,"qty":3.94683871}],"asks":[],"checksum":823890431,"timestamp":"2024-06-01T18:06:09.560941Z"}]}
{"channel":"book","type":"update","data":[{"symbol":"ETH/USD","bids":[],"asks":[{"price":3800.58,"qty":0.00000000},{"price":3801.80,"qty":0.41139655}],"checksum":3365383692,"timestamp":"2024-06-01T18:06:09.561826Z"}]}
{"channel":"book","type":"update","data":[{"symbol":"ETH/USD","bids":[{"price":3799.73,"qty":0.00000000},{"price":3799.69,"qty":3.00000000}],"asks":[],"checksum":3536097571,"timestamp":"2024-06-01T18:06:09.562055Z"}]}
{"channel":"book","type":"update","data":[{"symbol":"ETH/USD","bids":[{"price":3799.96,"qty":0.77000000}],"asks":[],"checksum":282752119,"timestamp":"2024-06-01T18:06:09.564362Z"}]}
{"channel":"book","type":"update","data":[{"symbol":"ETH/USD","bids":[{"price":3800.41,"qty":3.00000000}],"asks":[],"checksum":3020070156,"timestamp":"2024-06-01T18:06:09.564830Z"}]}
{"channel":"book","type":"update","data":[{"symbol":"ETH/USD","bids":[{"price":3800.32,"qty":0.00000000},{"price":3799.69,"qty":3.00000000}],"asks":[],"checksum":1059845207,"timestamp":"2024-06-01T18:06:09.565554Z"}]}
{"channel":"book","type":"update","data":[{"symbol":"ETH/USD","bids":[{"price":3800.41,"qty":6.94683871}],"asks":[],"checksum":791474082,"timestamp":"2024-06-01T18:06:09.568831Z"}]}
{"channel":"book","type":"update","data":[{"symbol":"ETH/USD","bids":[],"asks":[{"price":3801.12,"qty":1.87286365}],"checksum":2233652413,"timestamp":"2024-06-01T18:06:09.568876Z"}]}
{"channel":"book","type":"update","data":[{"symbol":"ETH/USD","bids":[],"asks":[{"price":3800.81,"qty":0.00000000},{"price":3801.82,"qty":3.00000000}],"checksum":3569625476,"timestamp":"2024-06-01T18:06:09.570124Z"}]}
{"channel":"book","type":"update","data":[{"symbol":"ETH/USD","bids":[{"price":3800.34,"qty":0.00000000},{"price":3799.68,"qty":7.77842526}],"asks":[],"checksum":1051395722,"timestamp":"2024-06-01T18:06:09.574194Z"}]}
{"channel":"book","type":"update","data":[{"symbol":"ETH/USD","bids":[],"asks":[{"price":3801.11,"qty":26.30810473}],"checksum":3663156763,"timestamp":"2024-06-01T18:06:09.575990Z"}]}
{"channel":"book","type":"update","data":[{"symbol":"ETH/USD","bids":[],"asks":[{"price":3800.71,"qty":26.31088854}],"checksum":1346168563,"timestamp":"2024-06-01T18:06:09.576065Z"}]}
{"channel":"book","type":"update","data":[{"symbol":"ETH/USD","bids":[{"price":3800.39,"qty":26.31302372}],"asks":[],"checksum":1178347451,"timestamp":"2024-06-01T18:06:09.576136Z"}]}
{"channel":"book","type":"update","data":[{"symbol":"ETH/USD","bids":[],"asks":[{"price":3801.11,"qty":52.61620946}],"checksum":3548205592,"timestamp":"2024-06-01T18:06:09.576189Z"}]}
{"channel":"book","type":"update","data":[{"symbol":"ETH/USD","bids":[],"asks":[{"price":3801.11,"qty":26.30810473}],"checksum":1178347451,"timestamp":"2024-06-01T18:06:09.582704Z"}]}
{"channel":"book","type":"update","data":[{"symbol":"ETH/USD","bids":[],"asks":[{"price":3801.11,"qty":0.00000000},{"price":3801.80,"qty":0.41139655}],"checksum":4262810574,"timestamp":"2024-06-01T18:06:09.583889Z"}]}
{"channel":"book","type":"update","data":[{"symbol":"ETH/USD","bids":[],"asks":[{"price":3801.44,"qty":0.00000000},{"price":3801.82,"qty":3.00000000}],"checksum":1478466791,"timestamp":"2024-06-01T18:06:09.586134Z"}]}
{"channel":"book","type":"update","data":[{"symbol":"ETH/USD","bids":[{"price":3800.42,"qty":0.72912968}],"asks":[],"checksum":2035333177,"timestamp":"2024-06-01T18:06:09.587011Z"}]}
{"channel":"book","type":"update","data":[{"symbol":"ETH/USD","bids":[{"price":3799.96,"qty":0.00000000},{"price":3799.69,"qty":3.00000000},{"price":3800.10,"qty":0.77000000}],"asks":[],"checksum":2410627460,"timestamp":"2024-06-01T18:06:09.596922Z"}]}
{"channel":"book","type":"update","data":[{"symbol":"ETH/USD","bids":[{"price":3800.10,"qty":1.54000000}],"asks":[],"checksum":3936807646,"timestamp":"2024-06-01T18:06:09.600129Z"}]}
{"channel":"book","type":"update","data":[{"symbol":"ETH/USD","bids":[],"asks":[{"price":3801.62,"qty":0.00000000},{"price":3801.89,"qty":138.97655987}],"checksum":1899346553,"timestamp":"2024-06-01T18:06:09.610558Z"}]}
{"channel":"book","type":"update","data":[{"symbol":"ETH/USD","bids":[],"asks":[{"price":3801.61,"qty":0.00000000},{"price":3801.90,"qty":6.93000000}],"checksum":194924246,"timestamp":"2024-06-01T18:06:09.615145Z"}]}
{"channel":"book","type":"update","data":[{"symbol":"ETH/USD","bids":[],"asks":[{"price":3801.81,"qty":0.00531322}],"checksum":1796648252,"timestamp":"2024-06-01T18:06:09.615454Z"}]}
{"channel":"book","type":"update","data":[{"symbol":"ETH/USD","bids":[{"price":3800.10,"qty":0.77000000}],"asks":[],"checksum":2180935248,"timestamp":"2024-06-01T18:06:09.616205Z"}]}
{"channel":"book","type":"update","data":[{"symbol":"ETH/USD","bids":[],"asks":[{"price":3801.76,"qty":5.26000000}],"checksum":1018352881,"timestamp":"2024-06-01T18:06:09.618222Z"}]}
{"channel":"book","type":"update","data":[{"symbol":"ETH/USD","bids":[{"price":3799.71,"qty":3.30000000}],"asks":[],"checksum":2801077050,"timestamp":"2024-06-01T18:06:09.618984Z"}]}
{"channel":"book","type":"update","data":[{"symbol":"ETH/USD","bids":[],"asks":[{"price":3801.04,"qty":2.11600000}],"checksum":1697770820,"timestamp":"2024-06-01T18:06:09.648512Z"}]}
{"channel":"book","type":"update","data":[{"symbol":"ETH/USD","bids":[],"asks":[{"price":3800.78,"qty":0.77000000}],"checksum":1300421053,"timestamp":"2024-06-01T18:06:09.690285Z"}]}
{"channel":"book","type":"update","data":[{"symbol":"ETH/USD","bids":[],"asks":[{"price":3801.47,"qty":4.53808791}],"checksum":299322605,"timestamp":"2024-06-01T18:06:09.703719Z"}]}
{"channel":"book","type":"update","data":[{"symbol":"ETH/USD","bids":[{"price":3800.34,"qty":0.33536582}],"asks":[],"checksum":3358620299,"timestamp":"2024-06-01T18:06:09.707405Z"}]}
{"channel":"book","type":"update","data":[{"symbol":"ETH/USD","bids":[],"asks":[{"price":3800.71,"qty":0.00000000},{"price":3801.80,"qty":0.41139655}],"checksum":3604295861,"timestamp":"2024-06-01T18:06:09.719217Z"}]}
{"channel":"book","type":"update","data":[{"symbol":"ETH/USD","bids":[{"price":3800.41,"qty":3.94683871}],"asks":[],"checksum":160965017,"timestamp":"2024-06-01T18:06:09.722092Z"}]}
{"channel":"book","type":"update","data":[{"symbol":"ETH/USD","bids":[{"price":3800.33,"qty":3.00903354}],"asks":[],"checksum":740200220,"timestamp":"2024-06-01T18:06:09.722840Z"}]}
{"channel":"book","type":"update","data":[{"symbol":"ETH/USD","bids":[{"price":3800.30,"qty":26.31370275}],"asks":[],"checksum":3143753626,"timestamp":"2024-06-01T18:06:09.724224Z"}]}
{"channel":"book","type":"update","data":[{"symbol":"ETH/USD","bids":[],"asks":[{"price":3800.70,"qty":26.31096659}],"checksum":269903554,"timestamp":"2024-06-01T18:06:09.724293Z"}]}
{"channel":"book","type":"update","data":[{"symbol":"ETH/USD","bids":[],"asks":[{"price":3801.47,"qty":0.00000000},{"price":3801.80,"qty":0.41139655}],"checksum":1617006371,"timestamp":"2024-06-01T18:06:09.755537Z"}]}
{"channel":"book","type":"update","data":[{"symbol":"ETH/USD","bids":[{"price":3800.39,"qty":0.00000000},{"price":3799.85,"qty":0.80086998}],"asks":[],"checksum":1160573086,"timestamp":"2024-06-01T18:06:09.771082Z"}]}
{"channel":"book","type":"update","data":[{"symbol":"ETH/USD","bids":[],"asks":[{"price":3800.70,"qty":0.00000000},{"price":3801.81,"qty":0.00531322}],"checksum":3438681877,"timestamp":"2024-06-01T18:06:09.771332Z"}]}
{"channel":"book","type":"update","data":[{"symbol":"ETH/USD","bids":[],"asks":[{"price":3800.69,"qty":26.31106132}],"checksum":2926780870,"timestamp":"2024-06-01T18:06:09.777246Z"}]}
{"channel":"book","type":"update","data":[{"symbol":"ETH/USD","bids":[],"asks":[{"price":3800.77,"qty":26.31045814}],"checksum":1634652488,"timestamp":"2024-06-01T18:06:09.777308Z"}]}
{"channel":"book","type":"update","data":[{"symbol":"ETH/USD","bids":[{"price":3800.36,"qty":26.31323160}],"asks":[],"checksum":4273474386,"timestamp":"2024-06-01T18:06:09.777346Z"}]}
{"channel":"book","type":"update","data":[{"symbol":"ETH/USD","bids":[],"asks":[{"price":3801.51,"qty":4.53808791}],"checksum":3511937988,"timestamp":"2024-06-01T18:06:09.876009Z"}]}
{"channel":"book","type":"update","data":[{"symbol":"ETH/USD","bids":[{"price":3800.33,"qty":3.00000000},{"price":3800.43,"qty":0.00903331}],"asks":[],"checksum":2462784570,"timestamp":"2024-06-01T18:06:09.892698Z"}]}
{"channel":"book","type":"update","data":[{"symbol":"ETH/USD","bids":[{"price":3800.36,"qty":0.00000000},{"price":3799.92,"qty":26.31628940}],"asks":[],"checksum":1738601414,"timestamp":"2024-06-01T18:06:09.974323Z"}]}
{"channel":"book","type":"update","data":[{"symbol":"ETH/USD","bids":[{"price":3800.34,"qty":1.09344596}],"asks":[],"checksum":548842090,"timestamp":"2024-06-01T18:06:09.977939Z"}]}
{"channel":"book","type":"update","data":[{"symbol":"ETH/USD","bids":[{"price":3800.37,"qty":26.31319213}],"asks":[],"checksum":3716046572,"timestamp":"2024-06-01T18:06:09.979017Z"}]}
{"channel":"book","type":"update","data":[{"symbol":"ETH/USD","bids":[],"asks":[{"price":3800.98,"qty":26.30903996}],"checksum":4093063823,"timestamp":"2024-06-01T18:06:09.979039Z"}]}
{"channel":"book","type":"update","data":[{"symbol":"ETH/USD","bids":[{"price":3800.33,"qty":0.00000000},{"price":3799.92,"qty":26.31628940}],"asks":[],"checksum":1384776170,"timestamp":"2024-06-01T18:06:10.061254Z"}]}
{"channel":"book","type":"update","data":[{"symbol":"ETH/USD","bids":[],"asks":[{"price":3800.69,"qty":0.00000000},{"price":3801.72,"qty":0.57565183}],"checksum":4098753668,"timestamp":"2024-06-01T18:06:10.092291Z"}]}
{"channel":"book","type":"update","data":[{"symbol":"ETH/USD","bids":[{"price":3800.37,"qty":0.00000000},{"price":3799.71,"qty":3.30000000}],"asks":[],"checksum":22908513,"timestamp":"2024-06-01T18:06:10.095791Z"}]}
{"channel":"book","type":"update","data":[{"symbol":"ETH/USD","bids":[],"asks":[{"price":3800.77,"qty":0.00000000},{"price":3801.76,"qty":5.26000000}],"checksum":2066765130,"timestamp":"2024-06-01T18:06:10.095880Z"}]}
{"channel":"book","type":"update","data":[{"symbol":"ETH/USD","bids":[{"price":3800.30,"qty":0.00000000},{"price":3799.69,"qty":3.00000000}],"asks":[],"checksum":583067280,"timestamp":"2024-06-01T18:06:10.102765Z"}]}
{"channel":"book","type":"update","data":[{"symbol":"ETH/USD","bids":[],"asks":[{"price":3800.98,"qty":0.00000000},{"price":3801.80,"qty":0.41139655}],"checksum":2639354705,"timestamp":"2024-06-01T18:06:10.102792Z"}]}
{"channel":"book","type":"update","data":[{"symbol":"ETH/USD","bids":[],"asks":[{"price":3801.17,"qty":3.00000000}],"checksum":2745212407,"timestamp":"2024-06-01T18:06:10.102865Z"}]}
{"channel":"book","type":"update","data":[{"symbol":"ETH/USD","bids":[{"price":3799.74,"qty":26.31753273}],"asks":[],"checksum":549631592,"timestamp":"2024-06-01T18:06:10.108843Z"}]}
{"channel":"book","type":"update","data":[{"symbol":"ETH/USD","bids":[],"asks":[{"price":3800.58,"qty":26.31180860}],"checksum":80182022,"timestamp":"2024-06-01T18:06:10.108858Z"}]}
{"channel":"book","type":"update","data":[{"symbol":"ETH/USD","bids":[{"price":3800.27,"qty":26.31385263}],"asks":[],"checksum":3398249056,"timestamp":"2024-06-01T18:06:10.108904Z"}]}
{"channel":"book","type":"update","data":[{"symbol":"ETH/USD","bids":[],"asks":[{"price":3800.58,"qty":0.00000000},{"price":3801.76,"qty":5.26000000}],"checksum":1621320690,"timestamp":"2024-06-01T18:06:10.115339Z"}]}
{"channel":"book","type":"update","data":[{"symbol":"ETH/USD","bids":[{"price":3800.27,"qty":0.00000000},{"price":3799.71,"qty":3.30000000}],"asks":[],"checksum":549631592,"timestamp":"2024-06-01T18:06:10.115461Z"}]}
{"channel":"book","type":"update","data":[{"symbol":"ETH/USD","bids":[],"asks":[{"price":3800.73,"qty":2.20000000}],"checksum":1772448434,"timestamp":"2024-06-01T18:06:10.123705Z"}]}
{"channel":"book","type":"update","data":[{"symbol":"ETH/USD","bids":[{"price":3800.25,"qty":26.31404969}],"asks":[],"checksum":2725562891,"timestamp":"2024-06-01T18:06:10.176881Z"}]}
{"channel":"book","type":"update","data":[{"symbol":"ETH/USD","bids":[],"asks":[{"price":3800.67,"qty":26.31121393}],"checksum":2341077300,"timestamp":"2024-06-01T18:06:10.176905Z"}]}
{"channel":"book","type":"update","data":[{"symbol":"ETH/USD","bids":[],"asks":[{"price":3801.17,"qty":0.00000000},{"price":3801.72,"qty":0.57565183}],"checksum":2358181525,"timestamp":"2024-06-01T18:06:10.180566Z"}]}
{"channel":"book","type":"update","data":[{"symbol":"ETH/USD","bids":[],"asks":[{"price":3800.67,"qty":0.00000000},{"price":3801.76,"qty":5.26000000}],"checksum":3544000829,"timestamp":"2024-06-01T18:06:10.182126Z"}]}
{"channel":"book","type":"update","data":[{"symbol":"ETH/USD","bids":[],"asks":[{"price":3800.66,"qty":26.31121963}],"checksum":434207586,"timestamp":"2024-06-01T18:06:10.186776Z"}]}
{"channel":"book","type":"update","data":[{"symbol":"ETH/USD","bids":[],"asks":[{"price":3800.66,"qty":0.00000000},{"price":3801.76,"qty":5.26000000}],"checksum":3544000829,"timestamp":"2024-06-01T18:06:10.192242Z"}]}
{"channel":"book","type":"update","data":[{"symbol":"ETH/USD","bids":[{"price":3800.25,"qty":0.00000000},{"price":3799.71,"qty":3.30000000}],"asks":[],"checksum":2445530614,"timestamp":"2024-06-01T18:06:10.201522Z"}]}
{"channel":"book","type":"update","data":[{"symbol":"ETH/USD","bids":[],"asks":[{"price":3801.12,"qty":4.87286365}],"checksum":696565422,"timestamp":"2024-06-01T18:06:10.203366Z"}]}
{"channel":"book","type":"update","data":[{"symbol":"ETH/USD","bids":[],"asks":[{"price":3800.57,"qty":26.31189671}],"checksum":3462983293,"timestamp":"2024-06-01T18:06:10.226172Z"}]}
{"channel":"book","type":"update","data":[{"symbol":"ETH/USD","bids":[{"price":3800.27,"qty":26.31388127}],"asks":[],"checksum":2556866107,"timestamp":"2024-06-01T18:06:10.226322Z"}]}
{"channel":"book","type":"update","data":[{"symbol":"ETH/USD","bids":[],"asks":[{"price":3801.12,"qty":1.87286365}],"checksum":2541298405,"timestamp":"2024-06-01T18:06:10.230430Z"}]}
{"channel":"book","type":"update","data":[{"symbol":"ETH/USD","bids":[],"asks":[{"price":3801.35,"qty":3.00000000}],"checksum":1966910300,"timestamp":"2024-06-01T18:06:10.233805Z"}]}
{"channel":"book","type":"update","data":[{"symbol":"ETH/USD","bids":[],"asks":[{"price":3800.57,"qty":0.00000000},{"price":3801.72,"qty":0.57565183}],"checksum":3567738005,"timestamp":"2024-06-01T18:06:10.427684Z"}]}
{"channel":"book","type":"update","data":[{"symbol":"ETH/USD","bids":[{"price":3800.27,"qty":0.00000000},{"price":3799.71,"qty":3.30000000}],"asks":[],"checksum":1720327772,"timestamp":"2024-06-01T18:06:10.427820Z"}]}
{"channel":"book","type":"update","data":[{"symbol":"ETH/USD","bids":[],"asks":[{"price":3800.60,"qty":26.31165199}],"checksum":3861415170,"timestamp":"2024-06-01T18:06:10.434050Z"}]}
{"channel":"book","type":"update","data":[{"symbol":"ETH/USD","bids":[{"price":3800.29,"qty":26.31375496}],"asks":[],"checksum":1143515842,"timestamp":"2024-06-01T18:06:10.434081Z"}]}
{"channel":"book","type":"update","data":[{"symbol":"ETH/USD","bids":[],"asks":[{"price":3800.86,"qty":26.30986524}],"checksum":2997015259,"timestamp":"2024-06-01T18:06:10.434106Z"}]}
{"channel":"book","type":"update","data":[{"symbol":"ETH/USD","bids":[],"asks":[{"price":3800.60,"qty":0.00000000},{"price":3801.71,"qty":1.50038279}],"checksum":1904250416,"timestamp":"2024-06-01T18:06:10.457953Z"}]}
{"channel":"book","type":"update","data":[{"symbol":"ETH/USD","bids":[{"price":3799.92,"qty":0.00000000},{"price":3799.71,"qty":3.30000000}],"asks":[],"checksum":1147453589,"timestamp":"2024-06-01T18:06:10.457963Z"}]}
{"channel":"book","type":"update","data":[{"symbol":"ETH/USD","bids":[{"price":3800.29,"qty":0.00000000},{"price":3799.69,"qty":3.00000000}],"asks":[],"checksum":4081419788,"timestamp":"2024-06-01T18:06:10.458043Z"}]}
{"channel":"book","type":"update","data":[{"symbol":"ETH/USD","bids":[{"price":3800.04,"qty":26.31549070}],"asks":[],"checksum":3067015376,"timestamp":"2024-06-01T18:06:10.463813Z"}]}
{"channel":"book","type":"update","data":[{"symbol":"ETH/USD","bids":[{"price":3800.19,"qty":0.00000000},{"price":3799.69,"qty":3.00000000}],"asks":[],"checksum":660788693,"timestamp":"2024-06-01T18:06:10.497386Z"}]}
{"channel":"book","type":"update","data":[{"symbol":"ETH/USD","bids":[{"price":3800.34,"qty":27.40684478}],"asks":[],"checksum":2574160566,"timestamp":"2024-06-01T18:06:10.501879Z"}]}
{"channel":"book","type":"update","data":[{"symbol":"ETH/USD","bids":[],"asks":[{"price":3800.62,"qty":26.31153885}],"checksum":1334886141,"timestamp":"2024-06-01T18:06:10.501894Z"}]}
{"channel":"book","type":"update","data":[{"symbol":"ETH/USD","bids":[],"asks":[{"price":3800.62,"qty":0.00000000},{"price":3801.71,"qty":1.50038279}],"checksum":2574160566,"timestamp":"2024-06-01T18:06:10.507334Z"}]}
{"channel":"book","type":"update","data":[{"symbol":"ETH/USD","bids":[{"price":3800.34,"qty":1.09344596}],"asks":[],"checksum":660788693,"timestamp":"2024-06-01T18:06:10.567500Z"}]}
{"channel":"book","type":"update","data":[{"symbol":"ETH/USD","bids":[{"price":3800.44,"qty":3.94683871}],"asks":[],"checksum":3107228182,"timestamp":"2024-06-01T18:06:10.571793Z"}]}
{"channel":"book","type":"update","data":[{"symbol":"ETH/USD","bids":[],"asks":[{"price":3800.63,"qty":26.31145950}],"checksum":1185953297,"timestamp":"2024-06-01T18:06:10.572028Z"}]}
{"channel":"book","type":"update","data":[{"symbol":"ETH/USD","bids":[{"price":3800.32,"qty":26.31353040}],"asks":[],"checksum":2459411481,"timestamp":"2024-06-01T18:06:10.572237Z"}]}
{"channel":"book","type":"update","data":[{"symbol":"ETH/USD","bids":[{"price":3800.41,"qty":0.00000000},{"price":3799.71,"qty":3.30000000}],"asks":[],"checksum":648302467,"timestamp":"2024-06-01T18:06:10.575560Z"}]}
{"channel":"book","type":"update","data":[{"symbol":"ETH/USD","bids":[{"price":3800.45,"qty":0.72912968}],"asks":[],"checksum":4063239391,"timestamp":"2024-06-01T18:06:10.592753Z"}]}
{"channel":"book","type":"update","data":[{"symbol":"ETH/USD","bids":[{"price":3800.44,"qty":0.00000000},{"price":3799.71,"qty":3.30000000}],"asks":[],"checksum":56911715,"timestamp":"2024-06-01T18:06:10.605522Z"}]}
{"channel":"book","type":"update","data":[{"symbol":"ETH/USD","bids":[{"price":3800.45,"qty":0.00000000},{"price":3799.69,"qty":3.00000000}],"asks":[],"checksum":250304750,"timestamp":"2024-06-01T18:06:10.609859Z"}]}
{"channel":"book","type":"update","data":[{"symbol":"ETH/USD","bids":[{"price":3800.43,"qty":0.00000000},{"price":3799.68,"qty":7.77842526},{"price":3800.45,"qty":0.00903326}],"asks":[],"checksum":269572323,"timestamp":"2024-06-01T18:06:10.635847Z"}]}
{"channel":"book","type":"update","data":[{"symbol":"ETH/USD","bids":[],"asks":[{"price":3800.62,"qty":2.20000000}],"checksum":2386196250,"timestamp":"2024-06-01T18:06:10.659194Z"}]}
{"channel":"book","type":"update","data":[{"symbol":"ETH/USD","bids":[],"asks":[{"price":3800.73,"qty":0.00000000},{"price":3801.51,"qty":4.53808791}],"checksum":1550517403,"timestamp":"2024-06-01T18:06:10.659601Z"}]}
{"channel":"book","type":"update","data":[{"symbol":"ETH/USD","bids":[{"price":3800.45,"qty":0.00000000},{"price":3799.68,"qty":7.77842526},{"price":3800.43,"qty":0.00903331}],"asks":[],"checksum":1116800150,"timestamp":"2024-06-01T18:06:10.697112Z"}]}
{"channel":"book","type":"update","data":[{"symbol":"ETH/USD","bids":[],"asks":[{"price":3800.63,"qty":0.00000000},{"price":3801.71,"qty":1.50038279}],"checksum":445295232,"timestamp":"2024-06-01T18:06:10.759690Z"}]}
{"channel":"book","type":"update","data":[{"symbol":"ETH/USD","bids":[],"asks":[{"price":3800.61,"qty":26.31156577}],"checksum":3415345248,"timestamp":"2024-06-01T18:06:10.764337Z"}]}
{"channel":"book","type":"update","data":[{"symbol":"ETH/USD","bids":[{"price":3800.31,"qty":26.31364180}],"asks":[],"checksum":4012215456,"timestamp":"2024-06-01T18:06:10.764403Z"}]}
{"channel":"book","type":"update","data":[{"symbol":"ETH/USD","bids":[],"asks":[{"price":3801.12,"qty":1.04284434}],"checksum":3906137177,"timestamp":"2024-06-01T18:06:10.853937Z"}]}
{"channel":"book","type":"update","data":[{"symbol":"ETH/USD","bids":[{"price":3800.34,"qty":0.33536582}],"asks":[],"checksum":375784150,"timestamp":"2024-06-01T18:06:10.853964Z"}]}
{"channel":"book","type":"update","data":[{"symbol":"ETH/USD","bids":[],"asks":[{"price":3800.78,"qty":0.00000000},{"price":3801.71,"qty":1.50038279},{"price":3800.68,"qty":0.77000000}],"checksum":4126535254,"timestamp":"2024-06-01T18:06:10.867457Z"}]}
{"channel":"book","type":"update","data":[{"symbol":"ETH/USD","bids":[],"asks":[{"price":3800.68,"qty":1.54000000}],"checksum":1833268693,"timestamp":"2024-06-01T18:06:10.870958Z"}]}
{"channel":"book","type":"update","data":[{"symbol":"ETH/USD","bids":[{"price":3800.11,"qty":0.75808014}],"asks":[],"checksum":870239141,"timestamp":"2024-06-01T18:06:10.954733Z"}]}
{"channel":"book","type":"update","data":[{"symbol":"ETH/USD","bids":[],"asks":[{"price":3800.67,"qty":0.83001931}],"checksum":2066126795,"timestamp":"2024-06-01T18:06:10.954879Z"}]}
{"channel":"book","type":"update","data":[{"symbol":"ETH/USD","bids":[{"price":3800.42,"qty":0.00000000},{"price":3799.71,"qty":3.30000000}],"asks":[],"checksum":1003701346,"timestamp":"2024-06-01T18:06:10.959145Z"}]}
{"channel":"book","type":"update","data":[{"symbol":"ETH/USD","bids":[{"price":3800.35,"qty":0.72912968}],"asks":[],"checksum":631477526,"timestamp":"2024-06-01T18:06:10.959306Z"}]}
{"channel":"book","type":"update","data":[{"symbol":"ETH/USD","bids":[],"asks":[{"price":3800.62,"qty":0.00000000},{"price":3801.51,"qty":4.53808791}],"checksum":1151230012,"timestamp":"2024-06-01T18:06:10.978142Z"}]}
{"channel":"book","type":"update","data":[{"symbol":"ETH/USD","bids":[],"asks":[{"price":3800.60,"qty":2.20000000}],"checksum":1727936108,"timestamp":"2024-06-01T18:06:10.978234Z"}]}
{"channel":"book","type":"update","data":[{"symbol":"ETH/USD","bids":[{"price":3800.43,"qty":0.53528954}],"asks":[],"checksum":1632464109,"timestamp":"2024-06-01T18:06:11.001546Z"}]}
{"channel":"book","type":"update","data":[{"symbol":"ETH/USD","bids":[{"price":3800.44,"qty":0.72912968}],"asks":[],"checksum":3065483437,"timestamp":"2024-06-01T18:06:11.006225Z"}]}
{"channel":"book","type":"update","data":[{"symbol":"ETH/USD","bids":[{"price":3800.43,"qty":0.52625623},{"price":3800.36,"qty":0.00903347}],"asks":[],"checksum":345928722,"timestamp":"2024-06-01T18:06:11.023361Z"}]}
{"channel":"book","type":"update","data":[{"symbol":"ETH/USD","bids":[{"price":3800.35,"qty":0.00000000},{"price":3800.04,"qty":26.31549070}],"asks":[],"checksum":4237006288,"timestamp":"2024-06-01T18:06:11.092653Z"}]}
{"channel":"book","type":"update","data":[{"symbol":"ETH/USD","bids":[{"price":3800.36,"qty":0.00000000},{"price":3799.74,"qty":26.31753273},{"price":3800.45,"qty":0.00903326}],"asks":[],"checksum":1265413030,"timestamp":"2024-06-01T18:06:11.146646Z"}]}
{"channel":"book","type":"update","data":[{"symbol":"ETH/USD","bids":[],"asks":[{"price":3801.35,"qty":0.00000000},{"price":3801.51,"qty":4.53808791}],"checksum":306957493,"timestamp":"2024-06-01T18:06:11.149870Z"}]}
{"channel":"book","type":"update","data":[{"symbol":"ETH/USD","bids":[],"asks":[{"price":3801.38,"qty":3.00000000}],"checksum":3383242450,"timestamp":"2024-06-01T18:06:11.154029Z"}]}
{"channel":"book","type":"update","data":[{"symbol":"ETH/USD","bids":[],"asks":[{"price":3800.68,"qty":0.77000000}],"checksum":996084602,"timestamp":"2024-06-01T18:06:11.161756Z"}]}
{"channel":"book","type":"update","data":[{"symbol":"ETH/USD","bids":[],"asks":[{"price":3800.68,"qty":0.00000000},{"price":3801.51,"qty":4.53808791}],"checksum":504869743,"timestamp":"2024-06-01T18:06:11.164572Z"}]}
{"channel":"book","type":"update","data":[{"symbol":"ETH/USD","bids":[],"asks":[{"price":3801.51,"qty":0.00000000},{"price":3801.76,"qty":5.26000000}],"checksum":1146660966,"timestamp":"2024-06-01T18:06:11.171198Z"}]}
{"channel":"book","type":"update","data":[{"symbol":"ETH/USD","bids":[{"price":3800.43,"qty":0.00000000},{"price":3799.74,"qty":26.31753273}],"asks":[],"checksum":72358784,"timestamp":"2024-06-01T18:06:11.195081Z"}]}
{"channel":"book","type":"update","data":[{"symbol":"ETH/USD","bids":[],"asks":[{"price":3800.61,"qty":0.00000000},{"price":3801.80,"qty":0.41139655}],"checksum":1090719652,"timestamp":"2024-06-01T18:06:11.205335Z"}]}
{"channel":"book","type":"update","data":[{"symbol":"ETH/USD","bids":[],"asks":[{"price":3800.63,"qty":26.31143547}],"checksum":1230458040,"timestamp":"2024-06-01T18:06:11.210246Z"}]}
{"channel":"book","type":"update","data":[{"symbol":"ETH/USD","bids":[],"asks":[{"price":3800.63,"qty":0.00000000},{"price":3801.80,"qty":0.41139655}],"checksum":1090719652,"timestamp":"2024-06-01T18:06:11.260710Z"}]}
{"channel":"book","type":"update","data":[{"symbol":"ETH/USD","bids":[{"price":3800.31,"qty":0.00000000},{"price":3799.71,"qty":3.30000000}],"asks":[],"checksum":386861400,"timestamp":"2024-06-01T18:06:11.260774Z"}]}
{"channel":"book","type":"update","data":[{"symbol":"ETH/USD","bids":[],"asks":[{"price":3800.72,"qty":26.31080426}],"checksum":1127133582,"timestamp":"2024-06-01T18:06:11.266148Z"}]}
{"channel":"book","type":"update","data":[{"symbol":"ETH/USD","bids":[{"price":3800.41,"qty":26.31290529}],"asks":[],"checksum":2015908228,"timestamp":"2024-06-01T18:06:11.266180Z"}]}
{"channel":"book","type":"update","data":[{"symbol":"ETH/USD","bids":[],"asks":[{"price":3800.99,"qty":26.30898961}],"checksum":2264561183,"timestamp":"2024-06-01T18:06:11.266400Z"}]}
{"channel":"book","type":"update","data":[{"symbol":"ETH/USD","bids":[],"asks":[{"price":3800.86,"qty":0.00000000},{"price":3801.76,"qty":5.26000000}],"checksum":3885561500,"timestamp":"2024-06-01T18:06:11.282647Z"}]}
{"channel":"book","type":"update","data":[{"symbol":"ETH/USD","bids":[],"asks":[{"price":3801.47,"qty":4.53808791}],"checksum":2485859399,"timestamp":"2024-06-01T18:06:11.309971Z"}]}
{"channel":"book","type":"update","data":[{"symbol":"ETH/USD","bids":[{"price":3800.41,"qty":0.00000000},{"price":3799.71,"qty":3.30000000}],"asks":[],"checksum":599348303,"timestamp":"2024-06-01T18:06:11.313506Z"}]}
{"channel":"book","type":"update","data":[{"symbol":"ETH/USD","bids":[{"price":3800.44,"qty":0.00000000},{"price":3799.69,"qty":3.00000000}],"asks":[],"checksum":446410358,"timestamp":"2024-06-01T18:06:11.318194Z"}]}
{"channel":"book","type":"update","data":[{"symbol":"ETH/USD","bids":[{"price":3800.35,"qty":0.72912968}],"asks":[],"checksum":3989530367,"timestamp":"2024-06-01T18:06:11.318236Z"}]}
{"channel":"book","type":"update","data":[{"symbol":"ETH/USD","bids":[],"asks":[{"price":3800.67,"qty":27.14121270}],"checksum":3233725815,"timestamp":"2024-06-01T18:06:11.318343Z"}]}
{"channel":"book","type":"update","data":[{"symbol":"ETH/USD","bids":[{"price":3800.36,"qty":26.31326052}],"asks":[],"checksum":3708567998,"timestamp":"2024-06-01T18:06:11.318373Z"}]}
{"channel":"book","type":"update","data":[{"symbol":"ETH/USD","bids":[{"price":3800.36,"qty":0.00000000},{"price":3799.71,"qty":3.30000000}],"asks":[],"checksum":3233725815,"timestamp":"2024-06-01T18:06:11.341039Z"}]}
{"channel":"book","type":"update","data":[{"symbol":"ETH/USD","bids":[{"price":3800.45,"qty":0.00000000},{"price":3799.69,"qty":3.00000000},{"price":3800.37,"qty":0.00903394}],"asks":[],"checksum":1304233396,"timestamp":"2024-06-01T18:06:11.390696Z"}]}
{"channel":"book","type":"update","data":[{"symbol":"ETH/USD","bids":[],"asks":[{"price":3800.69,"qty":0.77000000}],"checksum":1734695042,"timestamp":"2024-06-01T18:06:11.413990Z"}]}
{"channel":"book","type":"update","data":[{"symbol":"ETH/USD","bids":[{"price":3800.37,"qty":0.00000000},{"price":3799.69,"qty":3.00000000},{"price":3800.36,"qty":0.00903397}],"asks":[],"checksum":1899100059,"timestamp":"2024-06-01T18:06:11.440475Z"}]}
{"channel":"book","type":"update","data":[{"symbol":"ETH/USD","bids":[],"asks":[{"price":3800.67,"qty":0.83001931}],"checksum":101053028,"timestamp":"2024-06-01T18:06:11.475927Z"}]}
{"channel":"book","type":"update","data":[{"symbol":"ETH/USD","bids":[{"price":3800.38,"qty":26.31315264}],"asks":[],"checksum":3749217724,"timestamp":"2024-06-01T18:06:11.480638Z"}]}
{"channel":"book","type":"update","data":[{"symbol":"ETH/USD","bids":[],"asks":[{"price":3800.69,"qty":27.08105131}],"checksum":4283810067,"timestamp":"2024-06-01T18:06:11.480693Z"}]}
{"channel":"book","type":"update","data":[{"symbol":"ETH/USD","bids":[{"price":3800.39,"qty":0.72912968}],"asks":[],"checksum":2405194681,"timestamp":"2024-06-01T18:06:11.595660Z"}]}
{"channel":"book","type":"update","data":[{"symbol":"ETH/USD","bids":[{"price":3800.35,"qty":0.00000000},{"price":3799.74,"qty":26.31753273}],"asks":[],"checksum":2518576859,"timestamp":"2024-06-01T18:06:11.600071Z"}]}
{"channel":"book","type":"update","data":[{"symbol":"ETH/USD","bids":[],"asks":[{"price":3800.60,"qty":0.00000000},{"price":3801.47,"qty":4.53808791}],"checksum":2160048109,"timestamp":"2024-06-01T18:06:11.649755Z"}]}
{"channel":"book","type":"update","data":[{"symbol":"ETH/USD","bids":[{"price":3800.38,"qty":0.00000000},{"price":3799.71,"qty":3.30000000}],"asks":[],"checksum":3523350886,"timestamp":"2024-06-01T18:06:11.726862Z"}]}
{"channel":"book","type":"update","data":[{"symbol":"ETH/USD","bids":[{"price":3800.40,"qty":26.31301968}],"asks":[],"checksum":3638013029,"timestamp":"2024-06-01T18:06:11.731632Z"}]}
{"channel":"book","type":"update","data":[{"symbol":"ETH/USD","bids":[{"price":3800.36,"qty":0.00000000},{"price":3799.71,"qty":3.30000000},{"price":3800.40,"qty":26.32205355}],"asks":[],"checksum":695634156,"timestamp":"2024-06-01T18:06:11.750240Z"}]}
{"channel":"book","type":"update","data":[{"symbol":"ETH/USD","bids":[{"price":3800.42,"qty":3.00000000}],"asks":[],"checksum":2759617918,"timestamp":"2024-06-01T18:06:11.763834Z"}]}
{"channel":"book","type":"update","data":[{"symbol":"ETH/USD","bids":[{"price":3800.43,"qty":3.00000000}],"asks":[],"checksum":1035461894,"timestamp":"2024-06-01T18:06:11.764078Z"}]}
{"channel":"book","type":"update","data":[{"symbol":"ETH/USD","bids":[],"asks":[{"price":3800.69,"qty":26.31105131}],"checksum":4209240797,"timestamp":"2024-06-01T18:06:11.765212Z"}]}
{"channel":"book","type":"update","data":[{"symbol":"ETH/USD","bids":[],"asks":[{"price":3801.38,"qty":0.00000000},{"price":3801.76,"qty":5.26000000}],"checksum":3413613845,"timestamp":"2024-06-01T18:06:11.765713Z"}]}
{"channel":"book","type":"update","data":[{"symbol":"ETH/USD","bids":[{"price":3800.32,"qty":0.00000000},{"price":3799.74,"qty":26.31753273}],"asks":[],"checksum":4096405964,"timestamp":"2024-06-01T18:06:11.766952Z"}]}
{"channel":"book","type":"update","data":[{"symbol":"ETH/USD","bids":[{"price":3799.74,"qty":0.00000000},{"price":3799.71,"qty":3.30000000}],"asks":[],"checksum":2567081986,"timestamp":"2024-06-01T18:06:11.767064Z"}]}
{"channel":"book","type":"update","data":[{"symbol":"ETH/USD","bids":[{"price":3800.43,"qty":0.00000000},{"price":3799.69,"qty":3.00000000}],"asks":[],"checksum":2027364024,"timestamp":"2024-06-01T18:06:11.768293Z"}]}
{"channel":"book","type":"update","data":[{"symbol":"ETH/USD","bids":[{"price":3800.43,"qty":3.00000000}],"asks":[],"checksum":2567081986,"timestamp":"2024-06-01T18:06:11.768462Z"}]}
{"channel":"book","type":"update","data":[{"symbol":"ETH/USD","bids":[{"price":3800.42,"qty":0.00000000},{"price":3799.69,"qty":3.00000000}],"asks":[],"checksum":1583354501,"timestamp":"2024-06-01T18:06:11.768547Z"}]}
{"channel":"book","type":"update","data":[{"symbol":"ETH/USD","bids":[{"price":3800.43,"qty":3.72912968}],"asks":[],"checksum":3574763636,"timestamp":"2024-06-01T18:06:11.768860Z"}]}
{"channel":"book","type":"update","data":[{"symbol":"ETH/USD","bids":[],"asks":[{"price":3800.69,"qty":0.00000000},{"price":3801.80,"qty":0.41139655}],"checksum":1160656284,"timestamp":"2024-06-01T18:06:11.771017Z"}]}
{"channel":"book","type":"update","data":[{"symbol":"ETH/USD","bids":[],"asks":[{"price":3800.72,"qty":0.00000000},{"price":3801.81,"qty":0.00531322}],"checksum":4215225619,"timestamp":"2024-06-01T18:06:11.771243Z"}]}
{"channel":"book","type":"update","data":[{"symbol":"ETH/USD","bids":[{"price":3800.43,"qty":6.72912968}],"asks":[],"checksum":4135644834,"timestamp":"2024-06-01T18:06:11.771699Z"}]}
{"channel":"book","type":"update","data":[{"symbol":"ETH/USD","bids":[],"asks":[{"price":3801.76,"qty":0.00000000},{"price":3801.82,"qty":3.00000000}],"checksum":3745279774,"timestamp":"2024-06-01T18:06:11.772215Z"}]}
{"channel":"book","type":"update","data":[{"symbol":"ETH/USD","bids":[],"asks":[{"price":3800.67,"qty":0.00000000},{"price":3801.88,"qty":1.66939631}],"checksum":650270321,"timestamp":"2024-06-01T18:06:11.774131Z"}]}
{"channel":"book","type":"update","data":[{"symbol":"ETH/USD","bids":[{"price":3800.17,"qty":26.31458775}],"asks":[],"checksum":3637112970,"timestamp":"2024-06-01T18:06:11.777695Z"}]}
{"channel":"book","type":"update","data":[{"symbol":"ETH/USD","bids":[],"asks":[{"price":3800.76,"qty":26.31057574}],"checksum":2898396444,"timestamp":"2024-06-01T18:06:11.777761Z"}]}
{"channel":"book","type":"update","data":[{"symbol":"ETH/USD","bids":[],"asks":[{"price":3800.83,"qty":26.31004399}],"checksum":1745353312,"timestamp":"2024-06-01T18:06:11.777818Z"}]}
{"channel":"book","type":"update","data":[{"symbol":"ETH/USD","bids":[{"price":3800.43,"qty":3.72912968}],"asks":[],"checksum":3563898537,"timestamp":"2024-06-01T18:06:11.778152Z"}]}
{"channel":"book","type":"update","data":[{"symbol":"ETH/USD","bids":[{"price":3800.46,"qty":26.31258883}],"asks":[],"checksum":2682403317,"timestamp":"2024-06-01T18:06:11.784532Z"}]}
{"channel":"book","type":"update","data":[{"symbol":"ETH/USD","bids":[{"price":3800.44,"qty":3.00000000}],"asks":[],"checksum":4922207,"timestamp":"2024-06-01T18:06:11.785358Z"}]}
{"channel":"book","type":"update","data":[{"symbol":"ETH/USD","bids":[{"price":3800.44,"qty":0.00000000},{"price":3800.04,"qty":26.31549070}],"asks":[],"checksum":2682403317,"timestamp":"2024-06-01T18:06:11.788820Z"}]}
{"channel":"book","type":"update","data":[{"symbol":"ETH/USD","bids":[{"price":3800.47,"qty":3.00000000}],"asks":[],"checksum":691901878,"timestamp":"2024-06-01T18:06:11.795135Z"}]}
{"channel":"book","type":"update","data":[{"symbol":"ETH/USD","bids":[{"price":3800.48,"qty":3.00000000}],"asks":[],"checksum":881978137,"timestamp":"2024-06-01T18:06:11.795297Z"}]}
{"channel":"book","type":"update","data":[{"symbol":"ETH/USD","bids":[{"price":3800.40,"qty":0.00903387}],"asks":[],"checksum":1637577001,"timestamp":"2024-06-01T18:06:11.796960Z"}]}
{"channel":"book","type":"update","data":[{"symbol":"ETH/USD","bids":[],"asks":[{"price":3800.76,"qty":0.00000000},{"price":3801.82,"qty":3.00000000}],"checksum":3723429716,"timestamp":"2024-06-01T18:06:11.797015Z"}]}
{"channel":"book","type":"update","data":[{"symbol":"ETH/USD","bids":[{"price":3800.43,"qty":3.00000000}],"asks":[],"checksum":1663399815,"timestamp":"2024-06-01T18:06:11.799150Z"}]}
{"channel":"book","type":"update","data":[{"symbol":"ETH/USD","bids":[{"price":3800.48,"qty":0.00000000},{"price":3800.10,"qty":0.77000000}],"asks":[],"checksum":715346103,"timestamp":"2024-06-01T18:06:11.799188Z"}]}
{"channel":"book","type":"update","data":[{"symbol":"ETH/USD","bids":[],"asks":[{"price":3801.47,"qty":0.00000000},{"price":3801.88,"qty":1.66939631}],"checksum":1006620312,"timestamp":"2024-06-01T18:06:11.800515Z"}]}
{"channel":"book","type":"update","data":[{"symbol":"ETH/USD","bids":[],"asks":[{"price":3801.38,"qty":26.30629085}],"checksum":2210028048,"timestamp":"2024-06-01T18:06:11.802352Z"}]}
{"channel":"book","type":"update","data":[{"symbol":"ETH/USD","bids":[{"price":3800.47,"qty":0.00000000},{"price":3800.09,"qty":3.00000000}],"asks":[],"checksum":438015541,"timestamp":"2024-06-01T18:06:11.804709Z"}]}
{"channel":"book","type":"update","data":[{"symbol":"ETH/USD","bids":[{"price":3800.46,"qty":29.31258883}],"asks":[],"checksum":750426358,"timestamp":"2024-06-01T18:06:11.812817Z"}]}
{"channel":"book","type":"update","data":[{"symbol":"ETH/USD","bids":[{"price":3800.46,"qty":3.00000000}],"asks":[],"checksum":191118749,"timestamp":"2024-06-01T18:06:11.813924Z"}]}
{"channel":"book","type":"update","data":[{"symbol":"ETH/USD","bids":[],"asks":[{"price":3800.83,"qty":0.00000000},{"price":3801.88,"qty":1.66939631}],"checksum":503377121,"timestamp":"2024-06-01T18:06:11.814001Z"}]}
{"channel":"book","type":"update","data":[{"symbol":"ETH/USD","bids":[],"asks":[{"price":3800.98,"qty":0.78503712}],"checksum":1377955049,"timestamp":"2024-06-01T18:06:11.816477Z"}]}
{"channel":"book","type":"update","data":[{"symbol":"ETH/USD","bids":[],"asks":[{"price":3801.12,"qty":0.00000000},{"price":3801.88,"qty":1.66939631}],"checksum":3410527579,"timestamp":"2024-06-01T18:06:11.817260Z"}]}
{"channel":"book","type":"update","data":[{"symbol":"ETH/USD","bids":[{"price":3800.43,"qty":0.00000000},{"price":3800.04,"qty":26.31549070}],"asks":[],"checksum":3087411818,"timestamp":"2024-06-01T18:06:11.817761Z"}]}
{"channel":"book","type":"update","data":[{"symbol":"ETH/USD","bids":[],"asks":[{"price":3800.99,"qty":0.00000000},{"price":3801.89,"qty":5.26000000}],"checksum":84663198,"timestamp":"2024-06-01T18:06:11.819560Z"}]}
{"channel":"book","type":"update","data":[{"symbol":"ETH/USD","bids":[],"asks":[{"price":3800.66,"qty":5.69228303}],"checksum":1697974157,"timestamp":"2024-06-01T18:06:11.822399Z"}]}
{"channel":"book","type":"update","data":[{"symbol":"ETH/USD","bids":[],"asks":[{"price":3800.98,"qty":18.87585653}],"checksum":2992097834,"timestamp":"2024-06-01T18:06:11.822467Z"}]}
{"channel":"book","type":"update","data":[{"symbol":"ETH/USD","bids":[],"asks":[{"price":3800.85,"qty":26.30993980}],"checksum":2909310558,"timestamp":"2024-06-01T18:06:11.830423Z"}]}
{"channel":"book","type":"update","data":[{"symbol":"ETH/USD","bids":[{"price":3800.53,"qty":26.31208362}],"asks":[],"checksum":3264238457,"timestamp":"2024-06-01T18:06:11.835006Z"}]}
{"channel":"book","type":"update","data":[{"symbol":"ETH/USD","bids":[{"price":3800.47,"qty":0.72912968}],"asks":[],"checksum":1605634302,"timestamp":"2024-06-01T18:06:11.836422Z"}]}
{"channel":"book","type":"update","data":[{"symbol":"ETH/USD","bids":[{"price":3800.10,"qty":0.00000000},{"price":3800.09,"qty":3.00000000},{"price":3800.31,"qty":0.77000000}],"asks":[],"checksum":1476747470,"timestamp":"2024-06-01T18:06:11.836436Z"}]}
{"channel":"book","type":"update","data":[{"symbol":"ETH/USD","bids":[{"price":3800.31,"qty":1.54000000}],"asks":[],"checksum":255211345,"timestamp":"2024-06-01T18:06:11.837965Z"}]}
{"channel":"book","type":"update","data":[{"symbol":"ETH/USD","bids":[],"asks":[{"price":3800.97,"qty":1.00000000}],"checksum":500845040,"timestamp":"2024-06-01T18:06:11.838082Z"}]}
{"channel":"book","type":"update","data":[{"symbol":"ETH/USD","bids":[{"price":3800.53,"qty":0.00000000},{"price":3800.09,"qty":3.00000000}],"asks":[],"checksum":4233489032,"timestamp":"2024-06-01T18:06:11.853587Z"}]}
{"channel":"book","type":"update","data":[{"symbol":"ETH/USD","bids":[{"price":3800.47,"qty":3.72912968}],"asks":[],"checksum":1417554658,"timestamp":"2024-06-01T18:06:11.858783Z"}]}
{"channel":"book","type":"update","data":[{"symbol":"ETH/USD","bids":[{"price":3800.46,"qty":0.00000000},{"price":3800.04,"qty":26.31549070}],"asks":[],"checksum":3833752142,"timestamp":"2024-06-01T18:06:11.859098Z"}]}
{"channel":"book","type":"update","data":[{"symbol":"ETH/USD","bids":[{"price":3800.17,"qty":0.00000000},{"price":3799.71,"qty":3.30000000}],"asks":[],"checksum":4246588001,"timestamp":"2024-06-01T18:06:11.859307Z"}]}
{"channel":"book","type":"update","data":[{"symbol":"ETH/USD","bids":[{"price":3800.34,"qty":0.00000000},{"price":3799.69,"qty":3.00000000}],"asks":[],"checksum":2246750220,"timestamp":"2024-06-01T18:06:11.861554Z"}]}
{"channel":"book","type":"update","data":[{"symbol":"ETH/USD","bids":[{"price":3800.51,"qty":3.00000000}],"asks":[],"checksum":433602336,"timestamp":"2024-06-01T18:06:11.862839Z"}]}
{"channel":"book","type":"update","data":[{"symbol":"ETH/USD","bids":[{"price":3800.47,"qty":3.00000000}],"asks":[],"checksum":1885232783,"timestamp":"2024-06-01T18:06:11.865465Z"}]}
{"channel":"book","type":"update","data":[{"symbol":"ETH/USD","bids":[{"price":3800.31,"qty":0.77000000}],"asks":[],"checksum":2375734941,"timestamp":"2024-06-01T18:06:11.866477Z"}]}
{"channel":"book","type":"update","data":[{"symbol":"ETH/USD","bids":[{"price":3800.51,"qty":6.00000000}],"asks":[],"checksum":2354300769,"timestamp":"2024-06-01T18:06:11.866864Z"}]}
{"channel":"book","type":"update","data":[{"symbol":"ETH/USD","bids":[{"price":3800.51,"qty":3.00000000}],"asks":[],"checksum":2375734941,"timestamp":"2024-06-01T18:06:11.867856Z"}]}
{"channel":"book","type":"update","data":[{"symbol":"ETH/USD","bids":[{"price":3800.47,"qty":0.00000000},{"price":3799.69,"qty":3.00000000}],"asks":[],"checksum":3764831351,"timestamp":"2024-06-01T18:06:11.869856Z"}]}
{"channel":"book","type":"update","data":[{"symbol":"ETH/USD","bids":[{"price":3800.51,"qty":6.00000000}],"asks":[],"checksum":3786397067,"timestamp":"2024-06-01T18:06:11.871068Z"}]}
{"channel":"book","type":"update","data":[{"symbol":"ETH/USD","bids":[{"price":3800.54,"qty":3.00000000}],"asks":[],"checksum":336263547,"timestamp":"2024-06-01T18:06:11.871195Z"}]}
{"channel":"book","type":"update","data":[{"symbol":"ETH/USD","bids":[{"price":3800.51,"qty":3.00000000}],"asks":[],"checksum":4190967373,"timestamp":"2024-06-01T18:06:11.871374Z"}]}
{"channel":"book","type":"update","data":[{"symbol":"ETH/USD","bids":[{"price":3800.51,"qty":0.00000000},{"price":3799.69,"qty":3.00000000}],"asks":[],"checksum":1416409937,"timestamp":"2024-06-01T18:06:11.875608Z"}]}
{"channel":"book","type":"update","data":[{"symbol":"ETH/USD","bids":[{"price":3800.54,"qty":6.00000000}],"asks":[],"checksum":1436918445,"timestamp":"2024-06-01T18:06:11.878499Z"}]}
{"channel":"book","type":"update","data":[{"symbol":"ETH/USD","bids":[],"asks":[{"price":3801.00,"qty":0.77000000}],"checksum":3217707915,"timestamp":"2024-06-01T18:06:11.881244Z"}]}
{"channel":"book","type":"update","data":[{"symbol":"ETH/USD","bids":[],"asks":[{"price":3800.83,"qty":26.31008714}],"checksum":2140279581,"timestamp":"2024-06-01T18:06:11.889524Z"}]}
{"channel":"book","type":"update","data":[{"symbol":"ETH/USD","bids":[{"price":3800.55,"qty":26.31193392}],"asks":[],"checksum":1420044909,"timestamp":"2024-06-01T18:06:11.889764Z"}]}
{"channel":"book","type":"update","data":[{"symbol":"ETH/USD","bids":[],"asks":[{"price":3801.00,"qty":0.00000000},{"price":3801.80,"qty":0.41139655}],"checksum":1425116473,"timestamp":"2024-06-01T18:06:11.892959Z"}]}
{"channel":"book","type":"update","data":[{"symbol":"ETH/USD","bids":[{"price":3800.54,"qty":3.00000000}],"asks":[],"checksum":3107349007,"timestamp":"2024-06-01T18:06:11.894099Z"}]}
{"channel":"book","type":"update","data":[{"symbol":"ETH/USD","bids":[{"price":3800.56,"qty":3.00000000}],"asks":[],"checksum":4262813526,"timestamp":"2024-06-01T18:06:11.894111Z"}]}
{"channel":"book","type":"update","data":[{"symbol":"ETH/USD","bids":[{"price":3800.55,"qty":0.00000000},{"price":3799.71,"qty":3.30000000}],"asks":[],"checksum":1824441122,"timestamp":"2024-06-01T18:06:11.896783Z"}]}
{"channel":"book","type":"update","data":[{"symbol":"ETH/USD","bids":[],"asks":[{"price":3800.85,"qty":0.00000000},{"price":3801.81,"qty":0.00531322}],"checksum":392699686,"timestamp":"2024-06-01T18:06:11.896804Z"}]}
{"channel":"book","type":"update","data":[{"symbol":"ETH/USD","bids":[],"asks":[{"price":3800.83,"qty":0.00000000},{"price":3801.82,"qty":3.00000000}],"checksum":2877234226,"timestamp":"2024-06-01T18:06:11.896824Z"}]}
{"channel":"book","type":"update","data":[{"symbol":"ETH/USD","bids":[{"price":3800.57,"qty":3.00000000}],"asks":[],"checksum":2475610243,"timestamp":"2024-06-01T18:06:11.897324Z"}]}
{"channel":"book","type":"update","data":[{"symbol":"ETH/USD","bids":[{"price":3800.31,"qty":0.00000000},{"price":3799.71,"qty":3.30000000},{"price":3800.42,"qty":0.77000000}],"asks":[],"checksum":3650888721,"timestamp":"2024-06-01T18:06:11.901059Z"}]}
{"channel":"book","type":"update","data":[{"symbol":"ETH/USD","bids":[{"price":3800.54,"qty":0.00000000},{"price":3799.71,"qty":3.30000000}],"asks":[],"checksum":712887593,"timestamp":"2024-06-01T18:06:11.901452Z"}]}
{"channel":"book","type":"update","data":[{"symbol":"ETH/USD","bids":[{"price":3800.57,"qty":0.00000000},{"price":3799.69,"qty":3.00000000}],"asks":[],"checksum":3384749513,"timestamp":"2024-06-01T18:06:11.901497Z"}]}
{"channel":"book","type":"update","data":[{"symbol":"ETH/USD","bids":[{"price":3800.42,"qty":1.54000000}],"asks":[],"checksum":2785760248,"timestamp":"2024-06-01T18:06:11.904140Z"}]}
{"channel":"book","type":"update","data":[{"symbol":"ETH/USD","bids":[{"price":3800.56,"qty":6.00000000}],"asks":[],"checksum":302064862,"timestamp":"2024-06-01T18:06:11.908232Z"}]}
{"channel":"book","type":"update","data":[{"symbol":"ETH/USD","bids":[],"asks":[{"price":3800.97,"qty":0.00000000},{"price":3801.88,"qty":1.66939631}],"checksum":853222253,"timestamp":"2024-06-01T18:06:11.910513Z"}]}
{"channel":"book","type":"update","data":[{"symbol":"ETH/USD","bids":[{"price":3799.79,"qty":0.06693358}],"asks":[],"checksum":1619909003,"timestamp":"2024-06-01T18:06:11.920051Z"}]}
{"channel":"book","type":"update","data":[{"symbol":"ETH/USD","bids":[],"asks":[{"price":3801.64,"qty":4.53808791}],"checksum":1014192049,"timestamp":"2024-06-01T18:06:11.921914Z"}]}
{"channel":"book","type":"update","data":[{"symbol":"ETH/USD","bids":[],"asks":[{"price":3801.63,"qty":0.00528887}],"checksum":205744301,"timestamp":"2024-06-01T18:06:11.926217Z"}]}
{"channel":"book","type":"update","data":[{"symbol":"ETH/USD","bids":[],"asks":[{"price":3801.81,"qty":0.00000000},{"price":3801.82,"qty":3.00000000}],"checksum":3253042384,"timestamp":"2024-06-01T18:06:11.926411Z"}]}
{"channel":"book","type":"update","data":[{"symbol":"ETH/USD","bids":[],"asks":[{"price":3801.64,"qty":0.00000000},{"price":3801.88,"qty":1.66939631}],"checksum":3724695551,"timestamp":"2024-06-01T18:06:11.939801Z"}]}
{"channel":"book","type":"update","data":[{"symbol":"ETH/USD","bids":[],"asks":[{"price":3801.63,"qty":0.00000000},{"price":3801.89,"qty":5.26000000}],"checksum":344472882,"timestamp":"2024-06-01T18:06:11.940040Z"}]}
{"channel":"book","type":"update","data":[{"symbol":"ETH/USD","bids":[],"asks":[{"price":3801.04,"qty":0.00000000},{"price":3801.91,"qty":0.65776958}],"checksum":1405909898,"timestamp":"2024-06-01T18:06:11.976934Z"}]}
{"channel":"book","type":"update","data":[{"symbol":"ETH/USD","bids":[{"price":3800.42,"qty":0.77000000}],"asks":[],"checksum":3235830390,"timestamp":"2024-06-01T18:06:11.978747Z"}]}
{"channel":"book","type":"update","data":[{"symbol":"ETH/USD","bids":[],"asks":[{"price":3801.13,"qty":0.00000000},{"price":3801.94,"qty":4.30610000}],"checksum":3830484180,"timestamp":"2024-06-01T18:06:11.979848Z"}]}
{"channel":"book","type":"update","data":[{"symbol":"ETH/USD","bids":[],"asks":[{"price":3801.81,"qty":0.00534747}],"checksum":789417117,"timestamp":"2024-06-01T18:06:11.981113Z"}]}
{"channel":"book","type":"update","data":[{"symbol":"ETH/USD","bids":[],"asks":[{"price":3800.88,"qty":26.30972710}],"checksum":3707778942,"timestamp":"2024-06-01T18:06:11.982779Z"}]}
{"channel":"book","type":"update","data":[{"symbol":"ETH/USD","bids":[],"asks":[{"price":3801.63,"qty":10.81226191}],"checksum":2479275796,"timestamp":"2024-06-01T18:06:11.982839Z"}]}
{"channel":"book","type":"update","data":[{"symbol":"ETH/USD","bids":[{"price":3800.57,"qty":26.31184269}],"asks":[],"checksum":413005500,"timestamp":"2024-06-01T18:06:11.982864Z"}]}
{"channel":"book","type":"update","data":[{"symbol":"ETH/USD","bids":[],"asks":[{"price":3800.94,"qty":26.30930280}],"checksum":3243015249,"timestamp":"2024-06-01T18:06:11.982878Z"}]}
{"channel":"book","type":"update","data":[{"symbol":"ETH/USD","bids":[],"asks":[{"price":3800.98,"qty":18.09081941}],"checksum":3598185631,"timestamp":"2024-06-01T18:06:11.988412Z"}]}
{"channel":"book","type":"update","data":[{"symbol":"ETH/USD","bids":[{"price":3800.64,"qty":3.00000000}],"asks":[],"checksum":945727792,"timestamp":"2024-06-01T18:06:11.990223Z"}]}
{"channel":"book","type":"update","data":[{"symbol":"ETH/USD","bids":[{"price":3800.22,"qty":0.00000000},{"price":3799.79,"qty":0.06693358}],"asks":[],"checksum":1476260372,"timestamp":"2024-06-01T18:06:12.003497Z"}]}
{"channel":"book","type":"update","data":[{"symbol":"ETH/USD","bids":[{"price":3800.65,"qty":13.15288873}],"asks":[],"checksum":2903359618,"timestamp":"2024-06-01T18:06:12.003507Z"}]}
{"channel":"book","type":"update","data":[{"symbol":"ETH/USD","bids":[],"asks":[{"price":3800.88,"qty":0.00000000},{"price":3801.88,"qty":1.66939631}],"checksum":3775761853,"timestamp":"2024-06-01T18:06:12.010528Z"}]}
{"channel":"book","type":"update","data":[{"symbol":"ETH/USD","bids":[],"asks":[{"price":3801.14,"qty":0.00000000},{"price":3801.89,"qty":5.26000000}],"checksum":1102219135,"timestamp":"2024-06-01T18:06:12.010537Z"}]}
{"channel":"book","type":"update","data":[{"symbol":"ETH/USD","bids":[],"asks":[{"price":3801.38,"qty":0.00000000},{"price":3801.91,"qty":0.65776958}],"checksum":3947749153,"timestamp":"2024-06-01T18:06:12.010573Z"}]}
{"channel":"book","type":"update","data":[{"symbol":"ETH/USD","bids":[],"asks":[{"price":3800.94,"qty":0.00000000},{"price":3801.94,"qty":4.30610000}],"checksum":3020929330,"timestamp":"2024-06-01T18:06:12.010644Z"}]}
{"channel":"book","type":"update","data":[{"symbol":"ETH/USD","bids":[{"price":3800.57,"qty":0.00000000},{"price":3799.79,"qty":0.06693358}],"asks":[],"checksum":1199348554,"timestamp":"2024-06-01T18:06:12.010652Z"}]}
{"channel":"book","type":"update","data":[{"symbol":"ETH/USD","bids":[{"price":3800.56,"qty":3.00000000}],"asks":[],"checksum":3262169049,"timestamp":"2024-06-01T18:06:12.011086Z"}]}
{"channel":"book","type":"update","data":[{"symbol":"ETH/USD","bids":[{"price":3800.65,"qty":16.15288873}],"asks":[],"checksum":3702720568,"timestamp":"2024-06-01T18:06:12.012123Z"}]}
{"channel":"book","type":"update","data":[{"symbol":"ETH/USD","bids":[{"price":3800.65,"qty":16.88201841}],"asks":[],"checksum":3166745050,"timestamp":"2024-06-01T18:06:12.022131Z"}]}
{"channel":"book","type":"update","data":[{"symbol":"ETH/USD","bids":[{"price":3800.04,"qty":0.00000000},{"price":3799.71,"qty":3.30000000}],"asks":[],"checksum":3865251118,"timestamp":"2024-06-01T18:06:12.024350Z"}]}
{"channel":"book","type":"update","data":[{"symbol":"ETH/USD","bids":[],"asks":[{"price":3801.62,"qty":0.78503712}],"checksum":266103248,"timestamp":"2024-06-01T18:06:12.024549Z"}]}
{"channel":"book","type":"update","data":[{"symbol":"ETH/USD","bids":[{"price":3800.42,"qty":0.00000000},{"price":3799.69,"qty":3.00000000},{"price":3800.57,"qty":0.77000000}],"asks":[],"checksum":605224465,"timestamp":"2024-06-01T18:06:12.027387Z"}]}
{"channel":"book","type":"update","data":[{"symbol":"ETH/USD","bids":[{"price":3800.57,"qty":1.54000000}],"asks":[],"checksum":4015186521,"timestamp":"2024-06-01T18:06:12.030646Z"}]}
{"channel":"book","type":"update","data":[{"symbol":"ETH/USD","bids":[{"price":3800.57,"qty":0.77000000}],"asks":[],"checksum":605224465,"timestamp":"2024-06-01T18:06:12.033636Z"}]}
{"channel":"book","type":"update","data":[{"symbol":"ETH/USD","bids":[],"asks":[{"price":3801.35,"qty":26.30648317}],"checksum":2886445545,"timestamp":"2024-06-01T18:06:12.048015Z"}]}
{"channel":"book","type":"update","data":[{"symbol":"ETH/USD","bids":[{"price":3800.65,"qty":43.19330726}],"asks":[],"checksum":1567821275,"timestamp":"2024-06-01T18:06:12.048080Z"}]}
{"channel":"book","type":"update","data":[{"symbol":"ETH/USD","bids":[{"price":3800.22,"qty":26.31421952}],"asks":[],"checksum":2824884218,"timestamp":"2024-06-01T18:06:12.048127Z"}]}
{"channel":"book","type":"update","data":[{"symbol":"ETH/USD","bids":[],"asks":[{"price":3801.05,"qty":26.30855891}],"checksum":974453001,"timestamp":"2024-06-01T18:06:12.048154Z"}]}
{"channel":"book","type":"update","data":[{"symbol":"ETH/USD","bids":[{"price":3800.39,"qty":0.00000000},{"price":3799.71,"qty":3.30000000}],"asks":[],"checksum":214901082,"timestamp":"2024-06-01T18:06:12.049724Z"}]}
{"channel":"book","type":"update","data":[{"symbol":"ETH/USD","bids":[],"asks":[{"price":3801.80,"qty":0.00000000},{"price":3801.89,"qty":5.26000000}],"checksum":3518551570,"timestamp":"2024-06-01T18:06:12.055620Z"}]}
{"channel":"book","type":"update","data":[{"symbol":"ETH/USD","bids":[],"asks":[{"price":3801.05,"qty":0.00000000},{"price":3801.91,"qty":0.65776958}],"checksum":2934659623,"timestamp":"2024-06-01T18:06:12.067503Z"}]}
{"channel":"book","type":"update","data":[{"symbol":"ETH/USD","bids":[],"asks":[{"price":3801.74,"qty":4.53808791}],"checksum":2888639007,"timestamp":"2024-06-01T18:06:12.070447Z"}]}
{"channel":"book","type":"update","data":[{"symbol":"ETH/USD","bids":[{"price":3800.41,"qty":26.31293284}],"asks":[],"checksum":3241034718,"timestamp":"2024-06-01T18:06:12.084891Z"}]}
{"channel":"book","type":"update","data":[{"symbol":"ETH/USD","bids":[{"price":3800.58,"qty":26.31177346}],"asks":[],"checksum":2865034369,"timestamp":"2024-06-01T18:06:12.097737Z"}]}
{"channel":"book","type":"update","data":[{"symbol":"ETH/USD","bids":[],"asks":[{"price":3801.03,"qty":26.30871414}],"checksum":2422586670,"timestamp":"2024-06-01T18:06:12.097841Z"}]}
{"channel":"book","type":"update","data":[{"symbol":"ETH/USD","bids":[{"price":3800.40,"qty":0.00000000},{"price":3799.79,"qty":0.06693358},{"price":3800.12,"qty":0.00903454}],"asks":[],"checksum":3002812378,"timestamp":"2024-06-01T18:06:12.098025Z"}]}
{"channel":"book","type":"update","data":[{"symbol":"ETH/USD","bids":[],"asks":[{"price":3801.39,"qty":2.11600000}],"checksum":1343072637,"timestamp":"2024-06-01T18:06:12.123531Z"}]}
{"channel":"book","type":"update","data":[{"symbol":"ETH/USD","bids":[{"price":3800.11,"qty":0.00000000},{"price":3799.79,"qty":0.06693358}],"asks":[],"checksum":329185146,"timestamp":"2024-06-01T18:06:12.126710Z"}]}
{"channel":"book","type":"update","data":[{"symbol":"ETH/USD","bids":[],"asks":[{"price":3801.03,"qty":0.00000000},{"price":3801.88,"qty":1.66939631}],"checksum":2352595252,"timestamp":"2024-06-01T18:06:12.152223Z"}]}
{"channel":"book","type":"update","data":[{"symbol":"ETH/USD","bids":[],"asks":[{"price":3801.02,"qty":26.30878537}],"checksum":4122745880,"timestamp":"2024-06-01T18:06:12.156700Z"}]}
{"channel":"book","type":"update","data":[{"symbol":"ETH/USD","bids":[],"asks":[{"price":3801.02,"qty":0.00000000},{"price":3801.88,"qty":1.66939631}],"checksum":2352595252,"timestamp":"2024-06-01T18:06:12.161186Z"}]}
{"channel":"book","type":"update","data":[{"symbol":"ETH/USD","bids":[],"asks":[{"price":3801.09,"qty":26.30826848}],"checksum":99806427,"timestamp":"2024-06-01T18:06:12.179375Z"}]}
{"channel":"book","type":"update","data":[{"symbol":"ETH/USD","bids":[],"asks":[{"price":3801.81,"qty":0.00000000},{"price":3801.88,"qty":1.66939631}],"checksum":3136290261,"timestamp":"2024-06-01T18:06:12.189063Z"}]}
{"channel":"book","type":"update","data":[{"symbol":"ETH/USD","bids":[],"asks":[{"price":3801.33,"qty":0.77000000}],"checksum":2593918689,"timestamp":"2024-06-01T18:06:12.215687Z"}]}
{"channel":"book","type":"update","data":[{"symbol":"ETH/USD","bids":[{"price":3800.64,"qty":0.00000000},{"price":3799.71,"qty":3.30000000}],"asks":[],"checksum":4207511320,"timestamp":"2024-06-01T18:06:12.217418Z"}]}
{"channel":"book","type":"update","data":[{"symbol":"ETH/USD","bids":[{"price":3800.65,"qty":40.19330726}],"asks":[],"checksum":538924997,"timestamp":"2024-06-01T18:06:12.217493Z"}]}
{"channel":"book","type":"update","data":[{"symbol":"ETH/USD","bids":[],"asks":[{"price":3801.01,"qty":26.30883271}],"checksum":3579550235,"timestamp":"2024-06-01T18:06:12.226043Z"}]}
{"channel":"book","type":"update","data":[{"symbol":"ETH/USD","bids":[{"price":3800.59,"qty":0.76246377}],"asks":[],"checksum":1813639177,"timestamp":"2024-06-01T18:06:12.229624Z"}]}
{"channel":"book","type":"update","data":[{"symbol":"ETH/USD","bids":[],"asks":[{"price":3801.01,"qty":0.00000000},{"price":3801.82,"qty":3.00000000}],"checksum":655391070,"timestamp":"2024-06-01T18:06:12.230740Z"}]}
{"channel":"book","type":"update","data":[{"symbol":"ETH/USD","bids":[],"asks":[{"price":3801.39,"qty":0.00000000},{"price":3801.88,"qty":1.66939631}],"checksum":1818572509,"timestamp":"2024-06-01T18:06:12.262019Z"}]}
{"channel":"book","type":"update","data":[{"symbol":"ETH/USD","bids":[],"asks":[{"price":3801.33,"qty":0.00000000},{"price":3801.91,"qty":0.52622854}],"checksum":1818130732,"timestamp":"2024-06-01T18:06:12.263481Z"}]}
{"channel":"book","type":"update","data":[{"symbol":"ETH/USD","bids":[],"asks":[{"price":3800.66,"qty":0.00000000},{"price":3801.93,"qty":0.00507247}],"checksum":1553709426,"timestamp":"2024-06-01T18:06:12.266857Z"}]}
{"channel":"book","type":"update","data":[{"symbol":"ETH/USD","bids":[{"price":3800.72,"qty":3.00000000}],"asks":[],"checksum":1753231797,"timestamp":"2024-06-01T18:06:12.270488Z"}]}
{"channel":"book","type":"update","data":[{"symbol":"ETH/USD","bids":[],"asks":[{"price":3801.09,"qty":0.00000000},{"price":3801.94,"qty":4.30610000}],"checksum":49487928,"timestamp":"2024-06-01T18:06:12.270869Z"}]}
{"channel":"book","type":"update","data":[{"symbol":"ETH/USD","bids":[{"price":3800.57,"qty":0.00000000},{"price":3799.79,"qty":0.06693358},{"price":3800.69,"qty":0.77000000}],"asks":[],"checksum":1936437117,"timestamp":"2024-06-01T18:06:12.270996Z"}]}
{"channel":"book","type":"update","data":[{"symbol":"ETH/USD","bids":[{"price":3800.41,"qty":0.00000000},{"price":3799.79,"qty":0.06693358}],"asks":[],"checksum":1336227733,"timestamp":"2024-06-01T18:06:12.271068Z"}]}
{"channel":"book","type":"update","data":[{"symbol":"ETH/USD","bids":[{"price":3800.69,"qty":1.54000000}],"asks":[],"checksum":498764713,"timestamp":"2024-06-01T18:06:12.274265Z"}]}
{"channel":"book","type":"update","data":[{"symbol":"ETH/USD","bids":[{"price":3800.65,"qty":13.88201841}],"asks":[],"checksum":4025071726,"timestamp":"2024-06-01T18:06:12.275309Z"}]}
{"channel":"book","type":"update","data":[{"symbol":"ETH/USD","bids":[{"price":3800.85,"qty":26.30983630}],"asks":[],"checksum":3510075289,"timestamp":"2024-06-01T18:06:12.284590Z"}]}
{"channel":"book","type":"update","data":[{"symbol":"ETH/USD","bids":[],"asks":[{"price":3801.17,"qty":26.30774221}],"checksum":3175711649,"timestamp":"2024-06-01T18:06:12.284737Z"}]}
{"channel":"book","type":"update","data":[{"symbol":"ETH/USD","bids":[{"price":3800.73,"qty":26.31073504}],"asks":[],"checksum":1150816922,"timestamp":"2024-06-01T18:06:12.284755Z"}]}
{"channel":"book","type":"update","data":[{"symbol":"ETH/USD","bids":[],"asks":[{"price":3801.17,"qty":0.00000000},{"price":3801.94,"qty":4.30610000}],"checksum":1828115704,"timestamp":"2024-06-01T18:06:12.290050Z"}]}
{"channel":"book","type":"update","data":[{"symbol":"ETH/USD","bids":[{"price":3800.85,"qty":0.00000000},{"price":3800.09,"qty":3.00000000}],"asks":[],"checksum":3590030148,"timestamp":"2024-06-01T18:06:12.290065Z"}]}
{"channel":"book","type":"update","data":[{"symbol":"ETH/USD","bids":[{"price":3800.79,"qty":3.00000000}],"asks":[],"checksum":2302588701,"timestamp":"2024-06-01T18:06:12.293938Z"}]}
{"channel":"book","type":"update","data":[{"symbol":"ETH/USD","bids":[],"asks":[{"price":3801.82,"qty":0.00000000},{"price":3801.95,"qty":271.69167149}],"checksum":2534808833,"timestamp":"2024-06-01T18:06:12.294093Z"}]}
{"channel":"book","type":"update","data":[{"symbol":"ETH/USD","bids":[{"price":3800.73,"qty":0.00000000},{"price":3800.09,"qty":3.00000000}],"asks":[],"checksum":3853706182,"timestamp":"2024-06-01T18:06:12.295859Z"}]}
{"channel":"book","type":"update","data":[{"symbol":"ETH/USD","bids":[{"price":3800.80,"qty":0.72912968}],"asks":[],"checksum":1848341314,"timestamp":"2024-06-01T18:06:12.298431Z"}]}
{"channel":"book","type":"update","data":[{"symbol":"ETH/USD","bids":[{"price":3800.72,"qty":0.00000000},{"price":3800.09,"qty":3.00000000}],"asks":[],"checksum":466023221,"timestamp":"2024-06-01T18:06:12.299034Z"}]}
{"channel":"book","type":"update","data":[{"symbol":"ETH/USD","bids":[],"asks":[{"price":3801.57,"qty":26.30498749}],"checksum":770577229,"timestamp":"2024-06-01T18:06:12.304321Z"}]}
{"channel":"book","type":"update","data":[{"symbol":"ETH/USD","bids":[],"asks":[{"price":3801.76,"qty":3.00000000}],"checksum":671225609,"timestamp":"2024-06-01T18:06:12.304502Z"}]}
{"channel":"book","type":"update","data":[{"symbol":"ETH/USD","bids":[],"asks":[{"price":3801.10,"qty":26.30821125}],"checksum":2578812808,"timestamp":"2024-06-01T18:06:12.335229Z"}]}
{"channel":"book","type":"update","data":[{"symbol":"ETH/USD","bids":[{"price":3800.78,"qty":26.31034545}],"asks":[],"checksum":3676225241,"timestamp":"2024-06-01T18:06:12.335285Z"}]}
{"channel":"book","type":"update","data":[{"symbol":"ETH/USD","bids":[{"price":3800.65,"qty":13.15288873}],"asks":[],"checksum":3510028523,"timestamp":"2024-06-01T18:06:12.339762Z"}]}
{"channel":"book","type":"update","data":[{"symbol":"ETH/USD","bids":[],"asks":[{"price":3801.56,"qty":2.11600000}],"checksum":2514470152,"timestamp":"2024-06-01T18:06:12.360535Z"}]}
{"channel":"book","type":"update","data":[{"symbol":"ETH/USD","bids":[{"price":3800.78,"qty":0.00000000},{"price":3800.09,"qty":3.00000000}],"asks":[],"checksum":22251438,"timestamp":"2024-06-01T18:06:12.368575Z"}]}
{"channel":"book","type":"update","data":[{"symbol":"ETH/USD","bids":[],"asks":[{"price":3801.10,"qty":0.00000000},{"price":3801.91,"qty":0.52622854}],"checksum":114128952,"timestamp":"2024-06-01T18:06:12.375291Z"}]}
{"channel":"book","type":"update","data":[{"symbol":"ETH/USD","bids":[{"price":3800.12,"qty":0.00000000},{"price":3799.79,"qty":0.06693358},{"price":3800.81,"qty":0.00903290}],"asks":[],"checksum":34617152,"timestamp":"2024-06-01T18:06:12.375653Z"}]}
{"channel":"book","type":"update","data":[{"symbol":"ETH/USD","bids":[],"asks":[{"price":3801.76,"qty":0.00000000},{"price":3801.93,"qty":0.00507247}],"checksum":315175107,"timestamp":"2024-06-01T18:06:12.379120Z"}]}
{"channel":"book","type":"update","data":[{"symbol":"ETH/USD","bids":[],"asks":[{"price":3801.33,"qty":0.77000000}],"checksum":2689851171,"timestamp":"2024-06-01T18:06:12.379712Z"}]}
{"channel":"book","type":"update","data":[{"symbol":"ETH/USD","bids":[],"asks":[{"price":3801.76,"qty":3.00000000}],"checksum":4059628775,"timestamp":"2024-06-01T18:06:12.393637Z"}]}
{"channel":"book","type":"update","data":[{"symbol":"ETH/USD","bids":[{"price":3800.79,"qty":0.00000000},{"price":3799.79,"qty":0.06693358}],"asks":[],"checksum":3431781201,"timestamp":"2024-06-01T18:06:12.393701Z"}]}
{"channel":"book","type":"update","data":[{"symbol":"ETH/USD","bids":[],"asks":[{"price":3801.10,"qty":26.30821994}],"checksum":534517965,"timestamp":"2024-06-01T18:06:12.400373Z"}]}
{"channel":"book","type":"update","data":[{"symbol":"ETH/USD","bids":[{"price":3800.79,"qty":26.31025797}],"asks":[],"checksum":551170012,"timestamp":"2024-06-01T18:06:12.400404Z"}]}
{"channel":"book","type":"update","data":[{"symbol":"ETH/USD","bids":[{"price":3800.79,"qty":0.00000000},{"price":3799.79,"qty":0.06693358}],"asks":[],"checksum":534517965,"timestamp":"2024-06-01T18:06:12.405917Z"}]}
{"channel":"book","type":"update","data":[{"symbol":"ETH/USD","bids":[{"price":3800.66,"qty":0.33536582}],"asks":[],"checksum":364634086,"timestamp":"2024-06-01T18:06:12.420967Z"}]}
{"channel":"book","type":"update","data":[{"symbol":"ETH/USD","bids":[{"price":3800.69,"qty":0.77000000}],"asks":[],"checksum":3696911942,"timestamp":"2024-06-01T18:06:12.433267Z"}]}
{"channel":"book","type":"update","data":[{"symbol":"ETH/USD","bids":[],"asks":[{"price":3801.10,"qty":0.00000000},{"price":3801.88,"qty":1.66939631}],"checksum":252358106,"timestamp":"2024-06-01T18:06:12.434369Z"}]}
{"channel":"book","type":"update","data":[{"symbol":"ETH/USD","bids":[{"price":3800.74,"qty":26.31066581}],"asks":[],"checksum":446870218,"timestamp":"2024-06-01T18:06:12.572796Z"}]}
{"channel":"book","type":"update","data":[{"symbol":"ETH/USD","bids":[],"asks":[{"price":3801.05,"qty":26.30857922}],"checksum":1162458437,"timestamp":"2024-06-01T18:06:12.572824Z"}]}
{"channel":"book","type":"update","data":[{"symbol":"ETH/USD","bids":[{"price":3800.47,"qty":26.31246704}],"asks":[],"checksum":2171072153,"timestamp":"2024-06-01T18:06:12.572915Z"}]}
{"channel":"book","type":"update","data":[{"symbol":"ETH/USD","bids":[],"asks":[{"price":3801.05,"qty":0.00000000},{"price":3801.88,"qty":1.66939631}],"checksum":3733776662,"timestamp":"2024-06-01T18:06:12.598862Z"}]}
{"channel":"book","type":"update","data":[{"symbol":"ETH/USD","bids":[{"price":3800.74,"qty":0.00000000},{"price":3800.22,"qty":26.31421952}],"asks":[],"checksum":2498197101,"timestamp":"2024-06-01T18:06:12.600354Z"}]}
{"channel":"book","type":"update","data":[{"symbol":"ETH/USD","bids":[{"price":3800.58,"qty":0.00000000},{"price":3800.09,"qty":3.00000000}],"asks":[],"checksum":3665792980,"timestamp":"2024-06-01T18:06:12.602490Z"}]}
{"channel":"book","type":"update","data":[{"symbol":"ETH/USD","bids":[{"price":3800.53,"qty":0.77000000}],"asks":[],"checksum":1136760742,"timestamp":"2024-06-01T18:06:12.610179Z"}]}
{"channel":"book","type":"update","data":[{"symbol":"ETH/USD","bids":[{"price":3800.69,"qty":0.00000000},{"price":3800.09,"qty":3.00000000},{"price":3800.53,"qty":1.54000000}],"asks":[],"checksum":343149427,"timestamp":"2024-06-01T18:06:12.610214Z"}]}
{"channel":"book","type":"update","data":[{"symbol":"ETH/USD","bids":[],"asks":[{"price":3801.17,"qty":0.77000000}],"checksum":2726086554,"timestamp":"2024-06-01T18:06:12.610295Z"}]}
{"channel":"book","type":"update","data":[{"symbol":"ETH/USD","bids":[],"asks":[{"price":3801.33,"qty":0.00000000},{"price":3801.88,"qty":1.66939631},{"price":3801.17,"qty":1.54000000}],"checksum":1584313737,"timestamp":"2024-06-01T18:06:12.610341Z"}]}
{"channel":"book","type":"update","data":[{"symbol":"ETH/USD","bids":[{"price":3800.80,"qty":0.00000000},{"price":3799.90,"qty":3.50159293}],"asks":[],"checksum":3574454722,"timestamp":"2024-06-01T18:06:12.614794Z"}]}
{"channel":"book","type":"update","data":[{"symbol":"ETH/USD","bids":[{"price":3800.67,"qty":0.72912968}],"asks":[],"checksum":3333867396,"timestamp":"2024-06-01T18:06:12.614820Z"}]}
{"channel":"book","type":"update","data":[{"symbol":"ETH/USD","bids":[{"price":3800.72,"qty":26.31075828}],"asks":[],"checksum":3463801382,"timestamp":"2024-06-01T18:06:12.639031Z"}]}
{"channel":"book","type":"update","data":[{"symbol":"ETH/USD","bids":[],"asks":[{"price":3801.00,"qty":26.30890021}],"checksum":1382280697,"timestamp":"2024-06-01T18:06:12.639086Z"}]}
{"channel":"book","type":"update","data":[{"symbol":"ETH/USD","bids":[{"price":3800.81,"qty":0.00000000},{"price":3800.09,"qty":3.00000000},{"price":3800.68,"qty":0.00903321}],"asks":[],"checksum":1707375341,"timestamp":"2024-06-01T18:06:12.672730Z"}]}
{"channel":"book","type":"update","data":[{"symbol":"ETH/USD","bids":[],"asks":[{"price":3801.62,"qty":0.00000000},{"price":3801.88,"qty":1.66939631}],"checksum":1362680903,"timestamp":"2024-06-01T18:06:12.675930Z"}]}
{"channel":"book","type":"update","data":[{"symbol":"ETH/USD","bids":[],"asks":[{"price":3801.00,"qty":0.00000000},{"price":3801.91,"qty":0.52622854}],"checksum":3961382020,"timestamp":"2024-06-01T18:06:12.678719Z"}]}
{"channel":"book","type":"update","data":[{"symbol":"ETH/USD","bids":[{"price":3800.72,"qty":0.00000000},{"price":3800.09,"qty":3.00000000}],"asks":[],"checksum":2139628707,"timestamp":"2024-06-01T18:06:12.678752Z"}]}
{"channel":"book","type":"update","data":[{"symbol":"ETH/USD","bids":[{"price":3800.53,"qty":0.77000000}],"asks":[],"checksum":3027128939,"timestamp":"2024-06-01T18:06:12.685251Z"}]}
{"channel":"book","type":"update","data":[{"symbol":"ETH/USD","bids":[],"asks":[{"price":3801.17,"qty":0.77000000}],"checksum":711408679,"timestamp":"2024-06-01T18:06:12.688396Z"}]}
{"channel":"book","type":"update","data":[{"symbol":"ETH/USD","bids":[],"asks":[{"price":3801.88,"qty":0.00000000},{"price":3801.93,"qty":0.00507247}],"checksum":4159638684,"timestamp":"2024-06-01T18:06:12.714806Z"}]}
{"channel":"book","type":"update","data":[{"symbol":"ETH/USD","bids":[{"price":3800.60,"qty":26.31161601}],"asks":[],"checksum":1975324982,"timestamp":"2024-06-01T18:06:12.716663Z"}]}
{"channel":"book","type":"update","data":[{"symbol":"ETH/USD","bids":[],"asks":[{"price":3800.99,"qty":26.30896862}],"checksum":3349652448,"timestamp":"2024-06-01T18:06:12.716682Z"}]}
{"channel":"book","type":"update","data":[{"symbol":"ETH/USD","bids":[{"price":3800.69,"qty":26.31098194}],"asks":[],"checksum":1807615807,"timestamp":"2024-06-01T18:06:12.716694Z"}]}
{"channel":"book","type":"update","data":[{"symbol":"ETH/USD","bids":[{"price":3800.56,"qty":0.00000000},{"price":3800.22,"qty":26.31421952}],"asks":[],"checksum":2811247525,"timestamp":"2024-06-01T18:06:12.720459Z"}]}
{"channel":"book","type":"update","data":[{"symbol":"ETH/USD","bids":[],"asks":[{"price":3800.99,"qty":0.00000000},{"price":3801.93,"qty":0.00507247}],"checksum":3365033718,"timestamp":"2024-06-01T18:06:12.733665Z"}]}
{"channel":"book","type":"update","data":[{"symbol":"ETH/USD","bids":[{"price":3800.69,"qty":0.00000000},{"price":3800.09,"qty":3.00000000}],"asks":[],"checksum":2011839068,"timestamp":"2024-06-01T18:06:12.749935Z"}]}
{"channel":"book","type":"update","data":[{"symbol":"ETH/USD","bids":[{"price":3800.68,"qty":26.32008101}],"asks":[],"checksum":3955475674,"timestamp":"2024-06-01T18:06:12.768708Z"}]}
{"channel":"book","type":"update","data":[{"symbol":"ETH/USD","bids":[],"asks":[{"price":3800.98,"qty":44.39986485}],"checksum":4077053346,"timestamp":"2024-06-01T18:06:12.768770Z"}]}
{"channel":"book","type":"update","data":[{"symbol":"ETH/USD","bids":[],"asks":[{"price":3800.98,"qty":26.30904544}],"checksum":2598091773,"timestamp":"2024-06-01T18:06:12.807167Z"}]}
{"channel":"book","type":"update","data":[{"symbol":"ETH/USD","bids":[],"asks":[{"price":3801.34,"qty":0.78503712}],"checksum":2816135963,"timestamp":"2024-06-01T18:06:12.810511Z"}]}
{"channel":"book","type":"update","data":[{"symbol":"ETH/USD","bids":[],"asks":[{"price":3801.35,"qty":0.00000000},{"price":3801.93,"qty":0.00507247}],"checksum":819335394,"timestamp":"2024-06-01T18:06:12.993631Z"}]}
{"channel":"book","type":"update","data":[{"symbol":"ETH/USD","bids":[{"price":3800.68,"qty":0.00903321}],"asks":[],"checksum":1758292100,"timestamp":"2024-06-01T18:06:12.993698Z"}]}
{"channel":"book","type":"update","data":[{"symbol":"ETH/USD","bids":[],"asks":[{"price":3800.98,"qty":0.00000000},{"price":3801.94,"qty":4.30610000}],"checksum":3408495291,"timestamp":"2024-06-01T18:06:12.993752Z"}]}
{"channel":"book","type":"update","data":[{"symbol":"ETH/USD","bids":[],"asks":[{"price":3801.94,"qty":0.00000000},{"price":3801.95,"qty":271.69167149}],"checksum":922822380,"timestamp":"2024-06-01T18:06:12.997269Z"}]}
{"channel":"book","type":"update","data":[{"symbol":"ETH/USD","bids":[],"asks":[{"price":3801.23,"qty":26.30731309}],"checksum":4262686582,"timestamp":"2024-06-01T18:06:12.999940Z"}]}
{"channel":"book","type":"update","data":[{"symbol":"ETH/USD","bids":[{"price":3800.65,"qty":39.46412166}],"asks":[],"checksum":742409926,"timestamp":"2024-06-01T18:06:13.000038Z"}]}
{"channel":"book","type":"update","data":[{"symbol":"ETH/USD","bids":[],"asks":[{"price":3801.16,"qty":26.30775868}],"checksum":1471495428,"timestamp":"2024-06-01T18:06:13.000053Z"}]}
{"channel":"book","type":"update","data":[{"symbol":"ETH/USD","bids":[],"asks":[{"price":3800.96,"qty":26.30918737}],"checksum":3528082745,"timestamp":"2024-06-01T18:06:13.000099Z"}]}
{"channel":"book","type":"update","data":[{"symbol":"ETH/USD","bids":[],"asks":[{"price":3801.16,"qty":26.83391385}],"checksum":1479404002,"timestamp":"2024-06-01T18:06:13.004577Z"}]}
{"channel":"book","type":"update","data":[{"symbol":"ETH/USD","bids":[],"asks":[{"price":3801.16,"qty":0.52615517}],"checksum":2019361635,"timestamp":"2024-06-01T18:06:13.006198Z"}]}
{"channel":"book","type":"update","data":[{"symbol":"ETH/USD","bids":[{"price":3800.65,"qty":13.15288873}],"asks":[],"checksum":2853055187,"timestamp":"2024-06-01T18:06:13.208276Z"}]}
{"channel":"book","type":"update","data":[{"symbol":"ETH/USD","bids":[],"asks":[{"price":3801.04,"qty":26.30864553}],"checksum":2644149725,"timestamp":"2024-06-01T18:06:13.213154Z"}]}
{"channel":"book","type":"update","data":[{"symbol":"ETH/USD","bids":[{"price":3800.66,"qty":26.64654612}],"asks":[],"checksum":3959379723,"timestamp":"2024-06-01T18:06:13.213181Z"}]}
{"channel":"book","type":"update","data":[{"symbol":"ETH/USD","bids":[{"price":3800.66,"qty":0.33536582}],"asks":[],"checksum":2644149725,"timestamp":"2024-06-01T18:06:13.235523Z"}]}
{"channel":"book","type":"update","data":[{"symbol":"ETH/USD","bids":[],"asks":[{"price":3800.96,"qty":0.00000000},{"price":3801.76,"qty":3.00000000}],"checksum":1258464032,"timestamp":"2024-06-01T18:06:13.242191Z"}]}
{"channel":"book","type":"update","data":[{"symbol":"ETH/USD","bids":[],"asks":[{"price":3801.04,"qty":0.00000000},{"price":3801.93,"qty":0.00507247}],"checksum":3562153098,"timestamp":"2024-06-01T18:06:13.247338Z"}]}
{"channel":"book","type":"update","data":[{"symbol":"ETH/USD","bids":[],"asks":[{"price":3800.95,"qty":26.30925578}],"checksum":1178650609,"timestamp":"2024-06-01T18:06:13.252981Z"}]}
{"channel":"book","type":"update","data":[{"symbol":"ETH/USD","bids":[{"price":3800.65,"qty":39.46411640}],"asks":[],"checksum":446899302,"timestamp":"2024-06-01T18:06:13.275453Z"}]}
{"channel":"book","type":"update","data":[{"symbol":"ETH/USD","bids":[{"price":3800.65,"qty":13.15288873}],"asks":[],"checksum":1178650609,"timestamp":"2024-06-01T18:06:13.384827Z"}]}
{"channel":"book","type":"update","data":[{"symbol":"ETH/USD","bids":[],"asks":[{"price":3800.95,"qty":0.00000000},{"price":3801.93,"qty":0.00507247}],"checksum":3562153098,"timestamp":"2024-06-01T18:06:13.390308Z"}]}
{"channel":"book","type":"update","data":[{"symbol":"ETH/USD","bids":[],"asks":[{"price":3800.97,"qty":26.30910318}],"checksum":2267738413,"timestamp":"2024-06-01T18:06:13.396395Z"}]}
{"channel":"book","type":"update","data":[{"symbol":"ETH/USD","bids":[{"price":3800.66,"qty":26.64654086}],"asks":[],"checksum":1513766836,"timestamp":"2024-06-01T18:06:13.396421Z"}]}
{"channel":"book","type":"update","data":[{"symbol":"ETH/USD","bids":[{"price":3800.66,"qty":0.33536582}],"asks":[],"checksum":2267738413,"timestamp":"2024-06-01T18:06:13.401148Z"}]}
{"channel":"book","type":"update","data":[{"symbol":"ETH/USD","bids":[],"asks":[{"price":3800.97,"qty":0.00000000},{"price":3801.93,"qty":0.00507247}],"checksum":3562153098,"timestamp":"2024-06-01T18:06:13.401208Z"}]}
{"channel":"book","type":"update","data":[{"symbol":"ETH/USD","bids":[],"asks":[{"price":3800.99,"qty":26.30900210}],"checksum":3175722305,"timestamp":"2024-06-01T18:06:13.461313Z"}]}
{"channel":"book","type":"update","data":[{"symbol":"ETH/USD","bids":[],"asks":[{"price":3801.15,"qty":26.30782789}],"checksum":2371325235,"timestamp":"2024-06-01T18:06:13.461410Z"}]}
{"channel":"book","type":"update","data":[{"symbol":"ETH/USD","bids":[{"price":3800.67,"qty":27.04024683}],"asks":[],"checksum":2624365785,"timestamp":"2024-06-01T18:06:13.461470Z"}]}
{"channel":"book","type":"update","data":[{"symbol":"ETH/USD","bids":[],"asks":[{"price":3800.98,"qty":2.20000000}],"checksum":783781222,"timestamp":"2024-06-01T18:06:13.522277Z"}]}
{"channel":"book","type":"update","data":[{"symbol":"ETH/USD","bids":[],"asks":[{"price":3801.15,"qty":0.00000000},{"price":3801.74,"qty":4.53808791}],"checksum":3735853906,"timestamp":"2024-06-01T18:06:13.530079Z"}]}
{"channel":"book","type":"update","data":[{"symbol":"ETH/USD","bids":[{"price":3800.67,"qty":0.72912968}],"asks":[],"checksum":769073653,"timestamp":"2024-06-01T18:06:13.530138Z"}]}
{"channel":"book","type":"update","data":[{"symbol":"ETH/USD","bids":[],"asks":[{"price":3800.97,"qty":26.30907373}],"checksum":2811245443,"timestamp":"2024-06-01T18:06:13.535021Z"}]}
{"channel":"book","type":"update","data":[{"symbol":"ETH/USD","bids":[{"price":3800.65,"qty":39.46414573}],"asks":[],"checksum":2983866719,"timestamp":"2024-06-01T18:06:13.535067Z"}]}
{"channel":"book","type":"update","data":[{"symbol":"ETH/USD","bids":[{"price":3800.65,"qty":26.31125700}],"asks":[],"checksum":3966337959,"timestamp":"2024-06-01T18:06:13.626146Z"}]}
{"channel":"book","type":"update","data":[{"symbol":"ETH/USD","bids":[{"price":3800.65,"qty":0.00000000},{"price":3799.90,"qty":3.50159293}],"asks":[],"checksum":3646125847,"timestamp":"2024-06-01T18:06:13.628631Z"}]}
{"channel":"book","type":"update","data":[{"symbol":"ETH/USD","bids":[{"price":3800.67,"qty":27.04027657}],"asks":[],"checksum":3317228587,"timestamp":"2024-06-01T18:06:13.633488Z"}]}
{"channel":"book","type":"update","data":[{"symbol":"ETH/USD","bids":[{"price":3800.67,"qty":0.72912968}],"asks":[],"checksum":3646125847,"timestamp":"2024-06-01T18:06:13.701742Z"}]}
{"channel":"book","type":"update","data":[{"symbol":"ETH/USD","bids":[],"asks":[{"price":3800.97,"qty":0.00000000},{"price":3801.74,"qty":4.53808791}],"checksum":4220054796,"timestamp":"2024-06-01T18:06:13.701809Z"}]}
{"channel":"book","type":"update","data":[{"symbol":"ETH/USD","bids":[],"asks":[{"price":3800.95,"qty":26.30925041}],"checksum":3675961604,"timestamp":"2024-06-01T18:06:13.707188Z"}]}
{"channel":"book","type":"update","data":[{"symbol":"ETH/USD","bids":[{"price":3800.64,"qty":26.31129424}],"asks":[],"checksum":1452048241,"timestamp":"2024-06-01T18:06:13.707378Z"}]}
{"channel":"book","type":"update","data":[{"symbol":"ETH/USD","bids":[],"asks":[{"price":3800.95,"qty":0.00000000},{"price":3801.74,"qty":4.53808791}],"checksum":1484219671,"timestamp":"2024-06-01T18:06:13.712402Z"}]}
{"channel":"book","type":"update","data":[{"symbol":"ETH/USD","bids":[],"asks":[{"price":3801.37,"qty":3.00000000}],"checksum":2929930938,"timestamp":"2024-06-01T18:06:13.721607Z"}]}
{"channel":"book","type":"update","data":[{"symbol":"ETH/USD","bids":[],"asks":[{"price":3800.97,"qty":26.30907373}],"checksum":1492955121,"timestamp":"2024-06-01T18:06:13.781924Z"}]}
{"channel":"book","type":"update","data":[{"symbol":"ETH/USD","bids":[],"asks":[{"price":3801.37,"qty":0.00000000},{"price":3801.63,"qty":10.81226191}],"checksum":3526391649,"timestamp":"2024-06-01T18:06:13.785394Z"}]}
{"channel":"book","type":"update","data":[{"symbol":"ETH/USD","bids":[],"asks":[{"price":3800.97,"qty":0.00000000},{"price":3801.74,"qty":4.53808791}],"checksum":1484219671,"timestamp":"2024-06-01T18:06:13.786646Z"}]}
{"channel":"book","type":"update","data":[{"symbol":"ETH/USD","bids":[{"price":3800.53,"qty":0.00000000},{"price":3799.90,"qty":3.50159293},{"price":3800.42,"qty":0.77000000}],"asks":[],"checksum":66327168,"timestamp":"2024-06-01T18:06:13.869303Z"}]}
{"channel":"book","type":"update","data":[{"symbol":"ETH/USD","bids":[{"price":3800.42,"qty":1.54000000}],"asks":[],"checksum":3545681623,"timestamp":"2024-06-01T18:06:13.871606Z"}]}
{"channel":"book","type":"update","data":[{"symbol":"ETH/USD","bids":[],"asks":[{"price":3801.17,"qty":0.00000000},{"price":3801.76,"qty":3.00000000},{"price":3801.05,"qty":0.77000000}],"checksum":3921910781,"timestamp":"2024-06-01T18:06:13.871873Z"}]}
{"channel":"book","type":"update","data":[{"symbol":"ETH/USD","bids":[],"asks":[{"price":3801.05,"qty":1.54000000}],"checksum":2123345198,"timestamp":"2024-06-01T18:06:13.871984Z"}]}
{"channel":"book","type":"update","data":[{"symbol":"ETH/USD","bids":[],"asks":[{"price":3800.94,"qty":26.30934029}],"checksum":4276106997,"timestamp":"2024-06-01T18:06:13.881556Z"}]}
{"channel":"book","type":"update","data":[{"symbol":"ETH/USD","bids":[{"price":3800.42,"qty":0.77000000}],"asks":[],"checksum":3085155711,"timestamp":"2024-06-01T18:06:13.925041Z"}]}
{"channel":"book","type":"update","data":[{"symbol":"ETH/USD","bids":[],"asks":[{"price":3801.05,"qty":0.77000000}],"checksum":979474110,"timestamp":"2024-06-01T18:06:13.928143Z"}]}
{"channel":"book","type":"update","data":[{"symbol":"ETH/USD","bids":[],"asks":[{"price":3800.93,"qty":2.20000000}],"checksum":1614273234,"timestamp":"2024-06-01T18:06:14.037476Z"}]}
{"channel":"book","type":"update","data":[{"symbol":"ETH/USD","bids":[],"asks":[{"price":3800.98,"qty":0.00000000},{"price":3801.63,"qty":10.81226191}],"checksum":1971479242,"timestamp":"2024-06-01T18:06:14.039121Z"}]}
{"channel":"book","type":"update","data":[{"symbol":"ETH/USD","bids":[],"asks":[{"price":3801.55,"qty":17.05755702}],"checksum":821317197,"timestamp":"2024-06-01T18:06:14.155220Z"}]}
{"channel":"book","type":"update","data":[{"symbol":"ETH/USD","bids":[{"price":3800.64,"qty":0.00000000},{"price":3799.90,"qty":3.50159293}],"asks":[],"checksum":3066432465,"timestamp":"2024-06-01T18:06:14.206299Z"}]}
{"channel":"book","type":"update","data":[{"symbol":"ETH/USD","bids":[{"price":3800.65,"qty":26.31124085}],"asks":[],"checksum":1015609502,"timestamp":"2024-06-01T18:06:14.210920Z"}]}
{"channel":"book","type":"update","data":[{"symbol":"ETH/USD","bids":[],"asks":[{"price":3800.93,"qty":2.19491497}],"checksum":2846039805,"timestamp":"2024-06-01T18:06:14.540114Z"}]}
{"channel":"book","type":"update","data":[{"symbol":"ETH/USD","bids":[{"price":3800.66,"qty":0.00000000},{"price":3799.90,"qty":3.50159293}],"asks":[],"checksum":2569755811,"timestamp":"2024-06-01T18:06:14.587065Z"}]}
{"channel":"book","type":"update","data":[{"symbol":"ETH/USD","bids":[{"price":3800.67,"qty":0.00000000},{"price":3799.89,"qty":2.11600000}],"asks":[],"checksum":1390863379,"timestamp":"2024-06-01T18:06:14.596009Z"}]}
{"channel":"book","type":"update","data":[{"symbol":"ETH/USD","bids":[{"price":3800.66,"qty":0.72912968}],"asks":[],"checksum":4224711980,"timestamp":"2024-06-01T18:06:14.596341Z"}]}
{"channel":"book","type":"update","data":[{"symbol":"ETH/USD","bids":[{"price":3800.68,"qty":0.00000000},{"price":3799.89,"qty":2.11600000},{"price":3800.67,"qty":0.00905008}],"asks":[],"checksum":2029242885,"timestamp":"2024-06-01T18:06:14.655267Z"}]}
{"channel":"book","type":"update","data":[{"symbol":"ETH/USD","bids":[{"price":3800.65,"qty":0.00000000},{"price":3799.89,"qty":2.11600000}],"asks":[],"checksum":942622140,"timestamp":"2024-06-01T18:06:14.875248Z"}]}
{"channel":"book","type":"update","data":[{"symbol":"ETH/USD","bids":[],"asks":[{"price":3800.94,"qty":0.00000000},{"price":3801.63,"qty":10.81226191}],"checksum":603487828,"timestamp":"2024-06-01T18:06:14.875306Z"}]}
{"channel":"book","type":"update","data":[{"symbol":"ETH/USD","bids":[{"price":3800.66,"qty":0.00000000},{"price":3799.75,"qty":6.22500000}],"asks":[],"checksum":2573706015,"timestamp":"2024-06-01T18:06:14.879799Z"}]}
{"channel":"book","type":"update","data":[{"symbol":"ETH/USD","bids":[],"asks":[{"price":3800.93,"qty":28.50432135}],"checksum":608272874,"timestamp":"2024-06-01T18:06:14.880033Z"}]}
{"channel":"book","type":"update","data":[{"symbol":"ETH/USD","bids":[{"price":3800.63,"qty":26.31139815}],"asks":[],"checksum":1373744090,"timestamp":"2024-06-01T18:06:14.880232Z"}]}
{"channel":"book","type":"update","data":[{"symbol":"ETH/USD","bids":[{"price":3800.67,"qty":0.00000000},{"price":3799.75,"qty":6.22500000},{"price":3800.64,"qty":0.00905015}],"asks":[],"checksum":2250748909,"timestamp":"2024-06-01T18:06:14.947230Z"}]}
{"channel":"book","type":"update","data":[{"symbol":"ETH/USD","bids":[{"price":3800.64,"qty":0.73817983}],"asks":[],"checksum":1969866428,"timestamp":"2024-06-01T18:06:14.951790Z"}]}
{"channel":"book","type":"update","data":[{"symbol":"ETH/USD","bids":[{"price":3800.65,"qty":0.33536582}],"asks":[],"checksum":992429600,"timestamp":"2024-06-01T18:06:15.168568Z"}]}
{"channel":"book","type":"update","data":[{"symbol":"ETH/USD","bids":[{"price":3800.66,"qty":0.72912968}],"asks":[],"checksum":4199783537,"timestamp":"2024-06-01T18:06:15.172932Z"}]}
{"channel":"book","type":"update","data":[{"symbol":"ETH/USD","bids":[{"price":3800.64,"qty":0.72912968},{"price":3800.67,"qty":0.00905008}],"asks":[],"checksum":1063424766,"timestamp":"2024-06-01T18:06:15.261728Z"}]}
{"channel":"book","type":"update","data":[{"symbol":"ETH/USD","bids":[{"price":3800.64,"qty":0.00000000},{"price":3800.09,"qty":3.00000000}],"asks":[],"checksum":2799826823,"timestamp":"2024-06-01T18:06:15.265750Z"}]}
{"channel":"book","type":"update","data":[{"symbol":"ETH/USD","bids":[{"price":3800.59,"qty":0.00000000},{"price":3799.90,"qty":3.50159293}],"asks":[],"checksum":568706283,"timestamp":"2024-06-01T18:06:15.289746Z"}]}
{"channel":"book","type":"update","data":[{"symbol":"ETH/USD","bids":[{"price":3800.42,"qty":0.00000000},{"price":3799.75,"qty":6.22500000}],"asks":[],"checksum":2429982513,"timestamp":"2024-06-01T18:06:15.290998Z"}]}
{"channel":"book","type":"update","data":[{"symbol":"ETH/USD","bids":[{"price":3800.63,"qty":0.00000000},{"price":3799.71,"qty":3.30000000}],"asks":[],"checksum":896006944,"timestamp":"2024-06-01T18:06:15.292031Z"}]}
{"channel":"book","type":"update","data":[{"symbol":"ETH/USD","bids":[],"asks":[{"price":3800.93,"qty":2.19491497}],"checksum":2286016981,"timestamp":"2024-06-01T18:06:15.292040Z"}]}
{"channel":"book","type":"update","data":[{"symbol":"ETH/USD","bids":[],"asks":[{"price":3801.32,"qty":3.00000000}],"checksum":1514053346,"timestamp":"2024-06-01T18:06:15.295097Z"}]}
{"channel":"book","type":"update","data":[{"symbol":"ETH/USD","bids":[],"asks":[{"price":3801.57,"qty":0.00000000},{"price":3801.63,"qty":10.81226191}],"checksum":2777905389,"timestamp":"2024-06-01T18:06:15.299426Z"}]}
{"channel":"book","type":"update","data":[{"symbol":"ETH/USD","bids":[{"price":3800.60,"qty":0.00000000},{"price":3799.69,"qty":3.00000000}],"asks":[],"checksum":3435640805,"timestamp":"2024-06-01T18:06:15.299465Z"}]}
{"channel":"book","type":"update","data":[{"symbol":"ETH/USD","bids":[],"asks":[{"price":3800.93,"qty":5.19491497}],"checksum":3531383333,"timestamp":"2024-06-01T18:06:15.304497Z"}]}
{"channel":"book","type":"update","data":[{"symbol":"ETH/USD","bids":[],"asks":[{"price":3800.75,"qty":26.31061095}],"checksum":136401223,"timestamp":"2024-06-01T18:06:15.304521Z"}]}
{"channel":"book","type":"update","data":[{"symbol":"ETH/USD","bids":[{"price":3800.49,"qty":26.31238656}],"asks":[],"checksum":3717556481,"timestamp":"2024-06-01T18:06:15.304616Z"}]}
{"channel":"book","type":"update","data":[{"symbol":"ETH/USD","bids":[{"price":3800.04,"qty":26.31547815}],"asks":[],"checksum":4179513921,"timestamp":"2024-06-01T18:06:15.304724Z"}]}
{"channel":"book","type":"update","data":[{"symbol":"ETH/USD","bids":[{"price":3800.09,"qty":0.00000000},{"price":3799.71,"qty":3.30000000}],"asks":[],"checksum":3627765207,"timestamp":"2024-06-01T18:06:15.309403Z"}]}
{"channel":"book","type":"update","data":[{"symbol":"ETH/USD","bids":[],"asks":[{"price":3800.75,"qty":0.00000000},{"price":3801.63,"qty":10.81226191}],"checksum":2873376009,"timestamp":"2024-06-01T18:06:15.335200Z"}]}
{"channel":"book","type":"update","data":[{"symbol":"ETH/USD","bids":[{"price":3800.49,"qty":0.00000000},{"price":3799.69,"qty":3.00000000}],"asks":[],"checksum":3494361214,"timestamp":"2024-06-01T18:06:15.342359Z"}]}
{"channel":"book","type":"update","data":[{"symbol":"ETH/USD","bids":[{"price":3799.86,"qty":2.11600000}],"asks":[],"checksum":3338832999,"timestamp":"2024-06-01T18:06:15.382518Z"}]}
{"channel":"book","type":"update","data":[{"symbol":"ETH/USD","bids":[{"price":3800.33,"qty":0.77000000}],"asks":[],"checksum":3868169076,"timestamp":"2024-06-01T18:06:15.395517Z"}]}
{"channel":"book","type":"update","data":[{"symbol":"ETH/USD","bids":[],"asks":[{"price":3800.77,"qty":26.31049006}],"checksum":568412814,"timestamp":"2024-06-01T18:06:15.424380Z"}]}
{"channel":"book","type":"update","data":[{"symbol":"ETH/USD","bids":[{"price":3800.45,"qty":26.31264938}],"asks":[],"checksum":2156138541,"timestamp":"2024-06-01T18:06:15.424398Z"}]}
{"channel":"book","type":"update","data":[{"symbol":"ETH/USD","bids":[],"asks":[{"price":3800.93,"qty":2.19491497}],"checksum":1755795869,"timestamp":"2024-06-01T18:06:15.427840Z"}]}
{"channel":"book","type":"update","data":[{"symbol":"ETH/USD","bids":[{"price":3800.28,"qty":3.00000000}],"asks":[],"checksum":3203618668,"timestamp":"2024-06-01T18:06:15.476615Z"}]}
{"channel":"book","type":"update","data":[{"symbol":"ETH/USD","bids":[],"asks":[{"price":3801.34,"qty":0.00000000},{"price":3801.63,"qty":10.81226191}],"checksum":1074631771,"timestamp":"2024-06-01T18:06:15.510250Z"}]}
{"channel":"book","type":"update","data":[{"symbol":"ETH/USD","bids":[{"price":3800.34,"qty":0.77196568}],"asks":[],"checksum":169492126,"timestamp":"2024-06-01T18:06:15.510330Z"}]}
{"channel":"book","type":"update","data":[{"symbol":"ETH/USD","bids":[],"asks":[{"price":3800.98,"qty":0.77171446}],"checksum":37913087,"timestamp":"2024-06-01T18:06:15.664089Z"}]}
{"channel":"book","type":"update","data":[{"symbol":"ETH/USD","bids":[],"asks":[{"price":3800.73,"qty":26.31075565}],"checksum":223385808,"timestamp":"2024-06-01T18:06:15.665061Z"}]}
{"channel":"book","type":"update","data":[{"symbol":"ETH/USD","bids":[{"price":3800.28,"qty":0.00000000},{"price":3799.90,"qty":3.50159293}],"asks":[],"checksum":3942604128,"timestamp":"2024-06-01T18:06:15.668341Z"}]}
{"channel":"book","type":"update","data":[{"symbol":"ETH/USD","bids":[],"asks":[{"price":3800.73,"qty":0.00000000},{"price":3801.56,"qty":2.11600000}],"checksum":3857531983,"timestamp":"2024-06-01T18:06:15.715915Z"}]}
{"channel":"book","type":"update","data":[{"symbol":"ETH/USD","bids":[],"asks":[{"price":3800.76,"qty":26.31056620}],"checksum":2662413142,"timestamp":"2024-06-01T18:06:15.720862Z"}]}
{"channel":"book","type":"update","data":[{"symbol":"ETH/USD","bids":[{"price":3800.47,"qty":0.00000000},{"price":3799.86,"qty":2.11600000}],"asks":[],"checksum":2766883498,"timestamp":"2024-06-01T18:06:15.766652Z"}]}
{"channel":"book","type":"update","data":[{"symbol":"ETH/USD","bids":[],"asks":[{"price":3800.76,"qty":0.00000000},{"price":3801.56,"qty":2.11600000}],"checksum":1236794720,"timestamp":"2024-06-01T18:06:15.766690Z"}]}
{"channel":"book","type":"update","data":[{"symbol":"ETH/USD","bids":[],"asks":[{"price":3800.77,"qty":0.00000000},{"price":3801.63,"qty":10.81226191}],"checksum":4056348880,"timestamp":"2024-06-01T18:06:15.768681Z"}]}
{"channel":"book","type":"update","data":[{"symbol":"ETH/USD","bids":[{"price":3800.48,"qty":26.31243290}],"asks":[],"checksum":3592466032,"timestamp":"2024-06-01T18:06:15.774051Z"}]}
{"channel":"book","type":"update","data":[{"symbol":"ETH/USD","bids":[],"asks":[{"price":3800.92,"qty":26.30941982}],"checksum":1601782597,"timestamp":"2024-06-01T18:06:15.774071Z"}]}
{"channel":"book","type":"update","data":[{"symbol":"ETH/USD","bids":[],"asks":[{"price":3800.75,"qty":26.31059659}],"checksum":1069067847,"timestamp":"2024-06-01T18:06:15.774084Z"}]}
{"channel":"book","type":"update","data":[{"symbol":"ETH/USD","bids":[],"asks":[{"price":3800.92,"qty":0.00000000},{"price":3801.56,"qty":2.11600000}],"checksum":1004945006,"timestamp":"2024-06-01T18:06:15.792504Z"}]}
{"channel":"book","type":"update","data":[{"symbol":"ETH/USD","bids":[{"price":3800.48,"qty":0.00000000},{"price":3799.86,"qty":2.11600000}],"asks":[],"checksum":2413151824,"timestamp":"2024-06-01T18:06:15.792522Z"}]}
{"channel":"book","type":"update","data":[{"symbol":"ETH/USD","bids":[{"price":3800.37,"qty":26.31320766}],"asks":[],"checksum":2691989502,"timestamp":"2024-06-01T18:06:15.796940Z"}]}
{"channel":"book","type":"update","data":[{"symbol":"ETH/USD","bids":[{"price":3800.45,"qty":0.00000000},{"price":3799.86,"qty":2.11600000}],"asks":[],"checksum":4250112247,"timestamp":"2024-06-01T18:06:15.817696Z"}]}
{"channel":"book","type":"update","data":[{"symbol":"ETH/USD","bids":[{"price":3800.28,"qty":3.00000000}],"asks":[],"checksum":721917446,"timestamp":"2024-06-01T18:06:15.825577Z"}]}
{"channel":"book","type":"update","data":[{"symbol":"ETH/USD","bids":[],"asks":[{"price":3800.93,"qty":0.00000000},{"price":3801.63,"qty":10.81226191}],"checksum":2589513526,"timestamp":"2024-06-01T18:06:15.847362Z"}]}
{"channel":"book","type":"update","data":[{"symbol":"ETH/USD","bids":[],"asks":[{"price":3800.74,"qty":2.20000000}],"checksum":493483922,"timestamp":"2024-06-01T18:06:15.847461Z"}]}
{"channel":"book","type":"update","data":[{"symbol":"ETH/USD","bids":[{"price":3800.28,"qty":0.00000000},{"price":3799.86,"qty":2.11600000}],"asks":[],"checksum":3409834339,"timestamp":"2024-06-01T18:06:15.850962Z"}]}
{"channel":"book","type":"update","data":[{"symbol":"ETH/USD","bids":[{"price":3800.44,"qty":26.31270954}],"asks":[],"checksum":2203837159,"timestamp":"2024-06-01T18:06:15.975257Z"}]}
{"channel":"book","type":"update","data":[{"symbol":"ETH/USD","bids":[],"asks":[{"price":3800.72,"qty":26.31080820}],"checksum":673499753,"timestamp":"2024-06-01T18:06:15.975334Z"}]}
{"channel":"book","type":"update","data":[{"symbol":"ETH/USD","bids":[{"price":3800.22,"qty":0.00000000},{"price":3799.86,"qty":2.11600000}],"asks":[],"checksum":429949328,"timestamp":"2024-06-01T18:06:16.137411Z"}]}
{"channel":"book","type":"update","data":[{"symbol":"ETH/USD","bids":[{"price":3800.44,"qty":0.00000000},{"price":3799.75,"qty":6.22500000}],"asks":[],"checksum":2579182073,"timestamp":"2024-06-01T18:06:16.137420Z"}]}
{"channel":"book","type":"update","data":[{"symbol":"ETH/USD","bids":[],"asks":[{"price":3800.72,"qty":0.00000000},{"price":3801.56,"qty":2.11600000}],"checksum":1560695825,"timestamp":"2024-06-01T18:06:16.137428Z"}]}
{"channel":"book","type":"update","data":[{"symbol":"ETH/USD","bids":[],"asks":[{"price":3800.73,"qty":26.31073504}],"checksum":1455201078,"timestamp":"2024-06-01T18:06:16.143917Z"}]}
{"channel":"book","type":"update","data":[{"symbol":"ETH/USD","bids":[{"price":3800.38,"qty":26.31309142}],"asks":[],"checksum":2229330385,"timestamp":"2024-06-01T18:06:16.143932Z"}]}
{"channel":"book","type":"update","data":[{"symbol":"ETH/USD","bids":[],"asks":[{"price":3800.73,"qty":0.00000000},{"price":3801.56,"qty":2.11600000}],"checksum":568454773,"timestamp":"2024-06-01T18:06:16.149819Z"}]}
{"channel":"book","type":"update","data":[{"symbol":"ETH/USD","bids":[],"asks":[{"price":3800.75,"qty":0.00000000},{"price":3801.63,"qty":10.81226191}],"checksum":1383603491,"timestamp":"2024-06-01T18:06:16.164768Z"}]}
{"channel":"book","type":"update","data":[{"symbol":"ETH/USD","bids":[],"asks":[{"price":3800.73,"qty":26.31073504}],"checksum":3023213155,"timestamp":"2024-06-01T18:06:16.196684Z"}]}
{"channel":"book","type":"update","data":[{"symbol":"ETH/USD","bids":[],"asks":[{"price":3801.16,"qty":0.00000000},{"price":3801.63,"qty":10.81226191},{"price":3800.73,"qty":26.83694974}],"checksum":3387342704,"timestamp":"2024-06-01T18:06:16.214516Z"}]}
{"channel":"book","type":"update","data":[{"symbol":"ETH/USD","bids":[],"asks":[{"price":3800.72,"qty":26.31080426}],"checksum":2387611474,"timestamp":"2024-06-01T18:06:16.292852Z"}]}
{"channel":"book","type":"update","data":[{"symbol":"ETH/USD","bids":[],"asks":[{"price":3800.73,"qty":0.52621470}],"checksum":3502988432,"timestamp":"2024-06-01T18:06:16.298112Z"}]}
{"channel":"book","type":"update","data":[{"symbol":"ETH/USD","bids":[{"price":3800.33,"qty":0.00000000},{"price":3799.83,"qty":26.31691846}],"asks":[],"checksum":177008641,"timestamp":"2024-06-01T18:06:16.306147Z"}]}
{"channel":"book","type":"update","data":[{"symbol":"ETH/USD","bids":[],"asks":[{"price":3800.71,"qty":26.31087349}],"checksum":3848531798,"timestamp":"2024-06-01T18:06:16.346549Z"}]}
{"channel":"book","type":"update","data":[{"symbol":"ETH/USD","bids":[],"asks":[{"price":3800.71,"qty":0.00000000},{"price":3801.56,"qty":2.11600000}],"checksum":177008641,"timestamp":"2024-06-01T18:06:16.351951Z"}]}
{"channel":"book","type":"update","data":[{"symbol":"ETH/USD","bids":[],"asks":[{"price":3800.68,"qty":26.31108117}],"checksum":833209084,"timestamp":"2024-06-01T18:06:16.403681Z"}]}
{"channel":"book","type":"update","data":[{"symbol":"ETH/USD","bids":[{"price":3800.34,"qty":1.54196568}],"asks":[],"checksum":3495838361,"timestamp":"2024-06-01T18:06:16.426079Z"}]}
{"channel":"book","type":"update","data":[{"symbol":"ETH/USD","bids":[{"price":3800.38,"qty":0.00000000},{"price":3799.75,"qty":6.22500000}],"asks":[],"checksum":180937140,"timestamp":"2024-06-01T18:06:16.509965Z"}]}
{"channel":"book","type":"update","data":[{"symbol":"ETH/USD","bids":[{"price":3800.40,"qty":26.31300842}],"asks":[],"checksum":1044632229,"timestamp":"2024-06-01T18:06:16.514359Z"}]}
{"channel":"book","type":"update","data":[{"symbol":"ETH/USD","bids":[],"asks":[{"price":3800.74,"qty":0.00000000},{"price":3801.56,"qty":2.11600000}],"checksum":4169695549,"timestamp":"2024-06-01T18:06:16.571926Z"}]}
{"channel":"book","type":"update","data":[{"symbol":"ETH/USD","bids":[],"asks":[{"price":3801.55,"qty":0.00000000},{"price":3801.63,"qty":10.81226191}],"checksum":459074785,"timestamp":"2024-06-01T18:06:16.613356Z"}]}
{"channel":"book","type":"update","data":[{"symbol":"ETH/USD","bids":[{"price":3800.40,"qty":0.00000000},{"price":3799.75,"qty":6.22500000}],"asks":[],"checksum":2049180934,"timestamp":"2024-06-01T18:06:16.715899Z"}]}
{"channel":"book","type":"update","data":[{"symbol":"ETH/USD","bids":[],"asks":[{"price":3800.68,"qty":0.00000000},{"price":3801.74,"qty":4.53808791}],"checksum":3515082488,"timestamp":"2024-06-01T18:06:16.716806Z"}]}
{"channel":"book","type":"update","data":[{"symbol":"ETH/USD","bids":[],"asks":[{"price":3800.70,"qty":26.31096455}],"checksum":3100078310,"timestamp":"2024-06-01T18:06:16.721408Z"}]}
{"channel":"book","type":"update","data":[{"symbol":"ETH/USD","bids":[{"price":3800.42,"qty":26.31286107}],"asks":[],"checksum":2907837564,"timestamp":"2024-06-01T18:06:16.721633Z"}]}
{"channel":"book","type":"update","data":[{"symbol":"ETH/USD","bids":[{"price":3800.37,"qty":0.00000000},{"price":3799.75,"qty":6.22500000}],"asks":[],"checksum":3710985375,"timestamp":"2024-06-01T18:06:16.724224Z"}]}
{"channel":"book","type":"update","data":[{"symbol":"ETH/USD","bids":[],"asks":[{"price":3800.70,"qty":0.00000000},{"price":3801.74,"qty":4.53808791}],"checksum":3027612289,"timestamp":"2024-06-01T18:06:16.727276Z"}]}
{"channel":"book","type":"update","data":[{"symbol":"ETH/USD","bids":[{"price":3800.42,"qty":0.00000000},{"price":3799.71,"qty":3.30000000}],"asks":[],"checksum":3051544214,"timestamp":"2024-06-01T18:06:16.727316Z"}]}
{"channel":"book","type":"update","data":[{"symbol":"ETH/USD","bids":[],"asks":[{"price":3800.72,"qty":0.00000000},{"price":3801.76,"qty":3.00000000}],"checksum":1935655760,"timestamp":"2024-06-01T18:06:16.727375Z"}]}
{"channel":"book","type":"update","data":[{"symbol":"ETH/USD","bids":[{"price":3800.29,"qty":26.31371747}],"asks":[],"checksum":4182605578,"timestamp":"2024-06-01T18:06:16.733392Z"}]}
{"channel":"book","type":"update","data":[{"symbol":"ETH/USD","bids":[],"asks":[{"price":3800.73,"qty":0.00000000},{"price":3802.05,"qty":75.95580199}],"checksum":1172525425,"timestamp":"2024-06-01T18:06:16.737487Z"}]}
{"channel":"book","type":"update","data":[{"symbol":"ETH/USD","bids":[],"asks":[{"price":3800.93,"qty":3.00000000}],"checksum":1949765651,"timestamp":"2024-06-01T18:06:16.741609Z"}]}
{"channel":"book","type":"update","data":[{"symbol":"ETH/USD","bids":[],"asks":[{"price":3800.99,"qty":0.00000000},{"price":3802.05,"qty":75.95580199}],"checksum":2920785085,"timestamp":"2024-06-01T18:06:16.741820Z"}]}
{"channel":"book","type":"update","data":[{"symbol":"ETH/USD","bids":[],"asks":[{"price":3800.92,"qty":26.30941982}],"checksum":1137266083,"timestamp":"2024-06-01T18:06:16.746307Z"}]}
{"channel":"book","type":"update","data":[{"symbol":"ETH/USD","bids":[],"asks":[{"price":3800.92,"qty":52.61883964}],"checksum":985972636,"timestamp":"2024-06-01T18:06:16.746324Z"}]}
{"channel":"book","type":"update","data":[{"symbol":"ETH/USD","bids":[],"asks":[{"price":3800.92,"qty":26.30941982}],"checksum":1137266083,"timestamp":"2024-06-01T18:06:16.751189Z"}]}
{"channel":"book","type":"update","data":[{"symbol":"ETH/USD","bids":[],"asks":[{"price":3800.92,"qty":0.00000000},{"price":3802.05,"qty":75.95580199}],"checksum":2920785085,"timestamp":"2024-06-01T18:06:16.751248Z"}]}
{"channel":"book","type":"update","data":[{"symbol":"ETH/USD","bids":[{"price":3799.86,"qty":0.00000000},{"price":3799.71,"qty":3.30000000}],"asks":[],"checksum":2615140318,"timestamp":"2024-06-01T18:06:16.803967Z"}]}
{"channel":"book","type":"update","data":[{"symbol":"ETH/USD","bids":[],"asks":[{"price":3801.05,"qty":0.00000000},{"price":3802.06,"qty":5.26000000},{"price":3800.95,"qty":0.77000000}],"checksum":2172631533,"timestamp":"2024-06-01T18:06:16.869510Z"}]}
{"channel":"book","type":"update","data":[{"symbol":"ETH/USD","bids":[],"asks":[{"price":3801.90,"qty":0.77000000}],"checksum":2643413258,"timestamp":"2024-06-01T18:06:16.872650Z"}]}
{"channel":"book","type":"update","data":[{"symbol":"ETH/USD","bids":[],"asks":[{"price":3800.92,"qty":2.20000000}],"checksum":2617830243,"timestamp":"2024-06-01T18:06:16.893694Z"}]}
{"channel":"book","type":"update","data":[{"symbol":"ETH/USD","bids":[],"asks":[{"price":3800.85,"qty":3.00000000}],"checksum":1438800699,"timestamp":"2024-06-01T18:06:16.897589Z"}]}
{"channel":"book","type":"update","data":[{"symbol":"ETH/USD","bids":[],"asks":[{"price":3800.69,"qty":26.31101194}],"checksum":4152349369,"timestamp":"2024-06-01T18:06:16.902763Z"}]}
{"channel":"book","type":"update","data":[{"symbol":"ETH/USD","bids":[{"price":3800.35,"qty":26.31334571}],"asks":[],"checksum":112199192,"timestamp":"2024-06-01T18:06:16.902806Z"}]}
{"channel":"book","type":"update","data":[{"symbol":"ETH/USD","bids":[],"asks":[{"price":3800.85,"qty":0.00000000},{"price":3801.74,"qty":4.53808791}],"checksum":3576917467,"timestamp":"2024-06-01T18:06:16.908170Z"}]}
{"channel":"book","type":"update","data":[{"symbol":"ETH/USD","bids":[{"price":3800.66,"qty":0.00000000},{"price":3799.71,"qty":3.30000000}],"asks":[],"checksum":1697917492,"timestamp":"2024-06-01T18:06:16.944245Z"}]}
{"channel":"book","type":"update","data":[{"symbol":"ETH/USD","bids":[{"price":3800.35,"qty":0.00000000},{"price":3799.69,"qty":3.00000000}],"asks":[],"checksum":3661702973,"timestamp":"2024-06-01T18:06:16.950077Z"}]}
{"channel":"book","type":"update","data":[{"symbol":"ETH/USD","bids":[{"price":3800.21,"qty":26.31426860}],"asks":[],"checksum":991184858,"timestamp":"2024-06-01T18:06:16.954836Z"}]}
{"channel":"book","type":"update","data":[{"symbol":"ETH/USD","bids":[],"asks":[{"price":3800.68,"qty":26.31108117}],"checksum":3857269,"timestamp":"2024-06-01T18:06:16.954855Z"}]}
{"channel":"book","type":"update","data":[{"symbol":"ETH/USD","bids":[],"asks":[{"price":3801.23,"qty":0.00000000},{"price":3801.74,"qty":4.53808791}],"checksum":2912302339,"timestamp":"2024-06-01T18:06:16.958228Z"}]}
{"channel":"book","type":"update","data":[{"symbol":"ETH/USD","bids":[{"price":3800.29,"qty":0.00000000},{"price":3799.69,"qty":3.00000000}],"asks":[],"checksum":457056271,"timestamp":"2024-06-01T18:06:16.958307Z"}]}
{"channel":"book","type":"update","data":[{"symbol":"ETH/USD","bids":[{"price":3800.25,"qty":26.31405565}],"asks":[],"checksum":4268856218,"timestamp":"2024-06-01T18:06:16.962636Z"}]}
{"channel":"book","type":"update","data":[{"symbol":"ETH/USD","bids":[],"asks":[{"price":3801.09,"qty":26.30827781}],"checksum":2556899220,"timestamp":"2024-06-01T18:06:16.967647Z"}]}
{"channel":"book","type":"update","data":[{"symbol":"ETH/USD","bids":[{"price":3800.67,"qty":0.00000000},{"price":3799.69,"qty":3.00000000},{"price":3800.66,"qty":0.00905201}],"asks":[],"checksum":3481015453,"timestamp":"2024-06-01T18:06:17.000178Z"}]}
{"channel":"book","type":"update","data":[{"symbol":"ETH/USD","bids":[],"asks":[{"price":3800.69,"qty":0.00000000},{"price":3801.74,"qty":4.53808791}],"checksum":3034007029,"timestamp":"2024-06-01T18:06:17.004882Z"}]}
{"channel":"book","type":"update","data":[{"symbol":"ETH/USD","bids":[],"asks":[{"price":3800.68,"qty":0.00000000},{"price":3801.76,"qty":3.00000000}],"checksum":707282688,"timestamp":"2024-06-01T18:06:17.016725Z"}]}
{"channel":"book","type":"update","data":[{"symbol":"ETH/USD","bids":[{"price":3800.25,"qty":0.00000000},{"price":3799.69,"qty":3.00000000}],"asks":[],"checksum":4191836268,"timestamp":"2024-06-01T18:06:17.016894Z"}]}
{"channel":"book","type":"update","data":[{"symbol":"ETH/USD","bids":[],"asks":[{"price":3800.83,"qty":3.00000000}],"checksum":3428285198,"timestamp":"2024-06-01T18:06:17.020672Z"}]}
{"channel":"book","type":"update","data":[{"symbol":"ETH/USD","bids":[{"price":3800.26,"qty":26.31393924}],"asks":[],"checksum":4122428243,"timestamp":"2024-06-01T18:06:17.021522Z"}]}
{"channel":"book","type":"update","data":[{"symbol":"ETH/USD","bids":[{"price":3800.34,"qty":0.77000000}],"asks":[],"checksum":2722728121,"timestamp":"2024-06-01T18:06:17.046982Z"}]}
{"channel":"book","type":"update","data":[{"symbol":"ETH/USD","bids":[{"price":3800.14,"qty":0.72912968}],"asks":[],"checksum":1082904632,"timestamp":"2024-06-01T18:06:17.051171Z"}]}
{"channel":"book","type":"update","data":[{"symbol":"ETH/USD","bids":[],"asks":[{"price":3800.79,"qty":26.31034098}],"checksum":1219740759,"timestamp":"2024-06-01T18:06:17.056181Z"}]}
{"channel":"book","type":"update","data":[{"symbol":"ETH/USD","bids":[],"asks":[{"price":3800.83,"qty":0.00000000},{"price":3801.74,"qty":4.53808791}],"checksum":623654629,"timestamp":"2024-06-01T18:06:17.059723Z"}]}
{"channel":"book","type":"update","data":[{"symbol":"ETH/USD","bids":[{"price":3800.26,"qty":0.00000000},{"price":3799.71,"qty":3.30000000}],"asks":[],"checksum":2174077595,"timestamp":"2024-06-01T18:06:17.065962Z"}]}
{"channel":"book","type":"update","data":[{"symbol":"ETH/USD","bids":[],"asks":[{"price":3800.79,"qty":26.17525821}],"checksum":3133183594,"timestamp":"2024-06-01T18:06:17.067274Z"}]}
{"channel":"book","type":"update","data":[{"symbol":"ETH/USD","bids":[],"asks":[{"price":3800.93,"qty":0.00000000},{"price":3801.76,"qty":3.00000000}],"checksum":601395078,"timestamp":"2024-06-01T18:06:17.070840Z"}]}
{"channel":"book","type":"update","data":[{"symbol":"ETH/USD","bids":[{"price":3800.24,"qty":26.31411555}],"asks":[],"checksum":2536916105,"timestamp":"2024-06-01T18:06:17.078220Z"}]}
{"channel":"book","type":"update","data":[{"symbol":"ETH/USD","bids":[],"asks":[{"price":3800.78,"qty":2.20000000}],"checksum":3673875138,"timestamp":"2024-06-01T18:06:17.167908Z"}]}
{"channel":"book","type":"update","data":[{"symbol":"ETH/USD","bids":[],"asks":[{"price":3800.92,"qty":0.00000000},{"price":3801.76,"qty":3.00000000}],"checksum":3082792839,"timestamp":"2024-06-01T18:06:17.167973Z"}]}
{"channel":"book","type":"update","data":[{"symbol":"ETH/USD","bids":[],"asks":[{"price":3800.98,"qty":0.00000000},{"price":3801.90,"qty":0.77000000}],"checksum":275569117,"timestamp":"2024-06-01T18:06:17.171227Z"}]}
{"channel":"book","type":"update","data":[{"symbol":"ETH/USD","bids":[{"price":3800.15,"qty":0.77196568}],"asks":[],"checksum":3527630622,"timestamp":"2024-06-01T18:06:17.171249Z"}]}
{"channel":"book","type":"update","data":[{"symbol":"ETH/USD","bids":[],"asks":[{"price":3800.67,"qty":26.31115040}],"checksum":1346530079,"timestamp":"2024-06-01T18:06:17.173026Z"}]}
{"channel":"book","type":"update","data":[{"symbol":"ETH/USD","bids":[{"price":3800.34,"qty":0.00000000},{"price":3799.75,"qty":6.22500000},{"price":3800.23,"qty":0.77000000}],"asks":[],"checksum":3741831761,"timestamp":"2024-06-01T18:06:17.173980Z"}]}
{"channel":"book","type":"update","data":[{"symbol":"ETH/USD","bids":[{"price":3800.23,"qty":1.54000000}],"asks":[],"checksum":816624825,"timestamp":"2024-06-01T18:06:17.178394Z"}]}
{"channel":"book","type":"update","data":[{"symbol":"ETH/USD","bids":[],"asks":[{"price":3800.78,"qty":2.97171446}],"checksum":90697408,"timestamp":"2024-06-01T18:06:17.298272Z"}]}
{"channel":"book","type":"update","data":[{"symbol":"ETH/USD","bids":[{"price":3800.65,"qty":0.00000000},{"price":3799.75,"qty":6.22500000}],"asks":[],"checksum":1358593847,"timestamp":"2024-06-01T18:06:17.320400Z"}]}
{"channel":"book","type":"update","data":[{"symbol":"ETH/USD","bids":[{"price":3800.66,"qty":0.00000000},{"price":3799.71,"qty":3.30000000},{"price":3800.25,"qty":0.00905206}],"asks":[],"checksum":1304533971,"timestamp":"2024-06-01T18:06:17.377517Z"}]}
{"channel":"book","type":"update","data":[{"symbol":"ETH/USD","bids":[{"price":3800.25,"qty":0.73818174}],"asks":[],"checksum":3155359252,"timestamp":"2024-06-01T18:06:17.381777Z"}]}
{"channel":"book","type":"update","data":[{"symbol":"ETH/USD","bids":[],"asks":[{"price":3800.67,"qty":52.62230080}],"checksum":1252989976,"timestamp":"2024-06-01T18:06:17.383458Z"}]}
{"channel":"book","type":"update","data":[{"symbol":"ETH/USD","bids":[{"price":3800.24,"qty":0.00000000},{"price":3799.71,"qty":3.30000000}],"asks":[],"checksum":943455925,"timestamp":"2024-06-01T18:06:17.383533Z"}]}
{"channel":"book","type":"update","data":[{"symbol":"ETH/USD","bids":[],"asks":[{"price":3800.67,"qty":26.31115040}],"checksum":1022863712,"timestamp":"2024-06-01T18:06:17.387866Z"}]}
{"channel":"book","type":"update","data":[{"symbol":"ETH/USD","bids":[],"asks":[{"price":3800.54,"qty":26.31207876}],"checksum":3821330452,"timestamp":"2024-06-01T18:06:17.391910Z"}]}
{"channel":"book","type":"update","data":[{"symbol":"ETH/USD","bids":[{"price":3800.26,"qty":26.31398883}],"asks":[],"checksum":482750350,"timestamp":"2024-06-01T18:06:17.392002Z"}]}
{"channel":"book","type":"update","data":[{"symbol":"ETH/USD","bids":[{"price":3800.25,"qty":0.72912968},{"price":3800.27,"qty":0.00905201}],"asks":[],"checksum":2131166046,"timestamp":"2024-06-01T18:06:17.555501Z"}]}
{"channel":"book","type":"update","data":[{"symbol":"ETH/USD","bids":[{"price":3800.25,"qty":0.00000000},{"price":3799.75,"qty":6.22500000}],"asks":[],"checksum":1560480232,"timestamp":"2024-06-01T18:06:17.559308Z"}]}
{"channel":"book","type":"update","data":[{"symbol":"ETH/USD","bids":[{"price":3800.26,"qty":0.00000000},{"price":3799.71,"qty":3.30000000}],"asks":[],"checksum":1447596439,"timestamp":"2024-06-01T18:06:17.573946Z"}]}
{"channel":"book","type":"update","data":[{"symbol":"ETH/USD","bids":[],"asks":[{"price":3800.67,"qty":0.00000000},{"price":3801.76,"qty":3.00000000}],"checksum":2628925143,"timestamp":"2024-06-01T18:06:17.573995Z"}]}
{"channel":"book","type":"update","data":[{"symbol":"ETH/USD","bids":[],"asks":[{"price":3800.54,"qty":0.00000000},{"price":3801.89,"qty":0.00545057}],"checksum":1692145665,"timestamp":"2024-06-01T18:06:17.574028Z"}]}
{"channel":"book","type":"update","data":[{"symbol":"ETH/USD","bids":[{"price":3800.25,"qty":26.31403606}],"asks":[],"checksum":2399328563,"timestamp":"2024-06-01T18:06:17.581570Z"}]}
{"channel":"book","type":"update","data":[{"symbol":"ETH/USD","bids":[],"asks":[{"price":3800.54,"qty":26.31211560}],"checksum":2739564863,"timestamp":"2024-06-01T18:06:17.581615Z"}]}
{"channel":"book","type":"update","data":[{"symbol":"ETH/USD","bids":[],"asks":[{"price":3800.61,"qty":26.31158163}],"checksum":2480104946,"timestamp":"2024-06-01T18:06:17.586696Z"}]}
{"channel":"book","type":"update","data":[{"symbol":"ETH/USD","bids":[{"price":3800.27,"qty":0.00000000},{"price":3799.71,"qty":3.30000000},{"price":3800.26,"qty":0.00905203}],"asks":[],"checksum":2933875200,"timestamp":"2024-06-01T18:06:17.645382Z"}]}
{"channel":"book","type":"update","data":[{"symbol":"ETH/USD","bids":[],"asks":[{"price":3800.78,"qty":0.77171446}],"checksum":2982365720,"timestamp":"2024-06-01T18:06:17.748222Z"}]}
{"channel":"book","type":"update","data":[{"symbol":"ETH/USD","bids":[],"asks":[{"price":3800.53,"qty":2.20000000}],"checksum":879134846,"timestamp":"2024-06-01T18:06:17.748382Z"}]}
{"channel":"book","type":"update","data":[{"symbol":"ETH/USD","bids":[],"asks":[{"price":3800.54,"qty":0.00000000},{"price":3801.74,"qty":4.53808791}],"checksum":1387292028,"timestamp":"2024-06-01T18:06:17.751667Z"}]}
{"channel":"book","type":"update","data":[{"symbol":"ETH/USD","bids":[{"price":3800.25,"qty":0.00000000},{"price":3799.71,"qty":3.30000000}],"asks":[],"checksum":3676085870,"timestamp":"2024-06-01T18:06:17.751800Z"}]}
{"channel":"book","type":"update","data":[{"symbol":"ETH/USD","bids":[{"price":3800.27,"qty":26.31391980}],"asks":[],"checksum":2236407429,"timestamp":"2024-06-01T18:06:17.755938Z"}]}
{"channel":"book","type":"update","data":[{"symbol":"ETH/USD","bids":[],"asks":[{"price":3800.55,"qty":26.31200884}],"checksum":435561393,"timestamp":"2024-06-01T18:06:17.755974Z"}]}
{"channel":"book","type":"update","data":[{"symbol":"ETH/USD","bids":[],"asks":[{"price":3800.93,"qty":0.55000000}],"checksum":3017492456,"timestamp":"2024-06-01T18:06:17.899690Z"}]}
{"channel":"book","type":"update","data":[{"symbol":"ETH/USD","bids":[{"price":3800.28,"qty":0.52627701}],"asks":[],"checksum":1308756116,"timestamp":"2024-06-01T18:06:18.001697Z"}]}
{"channel":"book","type":"update","data":[{"symbol":"ETH/USD","bids":[{"price":3800.29,"qty":0.72912968}],"asks":[],"checksum":1525856572,"timestamp":"2024-06-01T18:06:18.095563Z"}]}
{"channel":"book","type":"update","data":[{"symbol":"ETH/USD","bids":[{"price":3800.14,"qty":0.00000000},{"price":3799.83,"qty":26.31691846}],"asks":[],"checksum":3465000264,"timestamp":"2024-06-01T18:06:18.099361Z"}]}
{"channel":"book","type":"update","data":[{"symbol":"ETH/USD","bids":[{"price":3800.26,"qty":0.00000000},{"price":3799.75,"qty":6.22500000},{"price":3800.29,"qty":0.73818164}],"asks":[],"checksum":3262856948,"timestamp":"2024-06-01T18:06:18.102612Z"}]}
{"channel":"book","type":"update","data":[{"symbol":"ETH/USD","bids":[{"price":3800.27,"qty":0.00000000},{"price":3799.71,"qty":3.30000000}],"asks":[],"checksum":4171474096,"timestamp":"2024-06-01T18:06:18.278776Z"}]}
{"channel":"book","type":"update","data":[{"symbol":"ETH/USD","bids":[],"asks":[{"price":3800.55,"qty":0.00000000},{"price":3801.63,"qty":10.81226191}],"checksum":1184433290,"timestamp":"2024-06-01T18:06:18.279012Z"}]}
{"channel":"book","type":"update","data":[{"symbol":"ETH/USD","bids":[],"asks":[{"price":3800.52,"qty":26.31218885}],"checksum":2630272480,"timestamp":"2024-06-01T18:06:18.283967Z"}]}
{"channel":"book","type":"update","data":[{"symbol":"ETH/USD","bids":[{"price":3800.22,"qty":26.31421418}],"asks":[],"checksum":809617356,"timestamp":"2024-06-01T18:06:18.284007Z"}]}
{"channel":"book","type":"update","data":[{"symbol":"ETH/USD","bids":[{"price":3800.22,"qty":0.00000000},{"price":3799.71,"qty":3.30000000}],"asks":[],"checksum":2630272480,"timestamp":"2024-06-01T18:06:18.288623Z"}]}
{"channel":"book","type":"update","data":[{"symbol":"ETH/USD","bids":[],"asks":[{"price":3800.91,"qty":3.00000000}],"checksum":2791820831,"timestamp":"2024-06-01T18:06:18.292219Z"}]}
{"channel":"book","type":"update","data":[{"symbol":"ETH/USD","bids":[],"asks":[{"price":3800.52,"qty":0.00000000},{"price":3801.56,"qty":2.11600000}],"checksum":4177296138,"timestamp":"2024-06-01T18:06:18.330000Z"}]}
{"channel":"book","type":"update","data":[{"symbol":"ETH/USD","bids":[],"asks":[{"price":3800.91,"qty":0.00000000},{"price":3801.63,"qty":10.81226191}],"checksum":1184433290,"timestamp":"2024-06-01T18:06:18.333813Z"}]}
{"channel":"book","type":"update","data":[{"symbol":"ETH/USD","bids":[{"price":3800.23,"qty":27.85415365}],"asks":[],"checksum":636590727,"timestamp":"2024-06-01T18:06:18.335358Z"}]}
{"channel":"book","type":"update","data":[{"symbol":"ETH/USD","bids":[],"asks":[{"price":3800.50,"qty":26.31233938}],"checksum":1244869148,"timestamp":"2024-06-01T18:06:18.335440Z"}]}
{"channel":"book","type":"update","data":[{"symbol":"ETH/USD","bids":[{"price":3800.23,"qty":1.54000000}],"asks":[],"checksum":877035100,"timestamp":"2024-06-01T18:06:18.408893Z"}]}
{"channel":"book","type":"update","data":[{"symbol":"ETH/USD","bids":[{"price":3800.21,"qty":0.00000000},{"price":3799.69,"qty":3.00000000}],"asks":[],"checksum":1365658916,"timestamp":"2024-06-01T18:06:18.412784Z"}]}
{"channel":"book","type":"update","data":[{"symbol":"ETH/USD","bids":[],"asks":[{"price":3800.50,"qty":0.00000000},{"price":3801.63,"qty":10.81226191}],"checksum":2306547426,"timestamp":"2024-06-01T18:06:18.412933Z"}]}
{"channel":"book","type":"update","data":[{"symbol":"ETH/USD","bids":[{"price":3800.28,"qty":0.00000000},{"price":3799.68,"qty":7.77842526}],"asks":[],"checksum":2373278417,"timestamp":"2024-06-01T18:06:18.417267Z"}]}
{"channel":"book","type":"update","data":[{"symbol":"ETH/USD","bids":[{"price":3800.18,"qty":26.31454130}],"asks":[],"checksum":2519718697,"timestamp":"2024-06-01T18:06:18.418367Z"}]}
{"channel":"book","type":"update","data":[{"symbol":"ETH/USD","bids":[],"asks":[{"price":3800.48,"qty":26.31247636}],"checksum":4043713304,"timestamp":"2024-06-01T18:06:18.418446Z"}]}
{"channel":"book","type":"update","data":[{"symbol":"ETH/USD","bids":[],"asks":[{"price":3800.92,"qty":3.00000000}],"checksum":2097256501,"timestamp":"2024-06-01T18:06:18.422229Z"}]}
{"channel":"book","type":"update","data":[{"symbol":"ETH/USD","bids":[],"asks":[{"price":3800.53,"qty":0.00000000},{"price":3801.56,"qty":2.11600000}],"checksum":447058119,"timestamp":"2024-06-01T18:06:18.516027Z"}]}
{"channel":"book","type":"update","data":[{"symbol":"ETH/USD","bids":[],"asks":[{"price":3800.47,"qty":2.20000000}],"checksum":3830792281,"timestamp":"2024-06-01T18:06:18.516062Z"}]}
{"channel":"book","type":"update","data":[{"symbol":"ETH/USD","bids":[],"asks":[{"price":3800.92,"qty":0.00000000},{"price":3801.56,"qty":2.11600000}],"checksum":1750266740,"timestamp":"2024-06-01T18:06:18.519879Z"}]}
{"channel":"book","type":"update","data":[{"symbol":"ETH/USD","bids":[{"price":3800.29,"qty":0.00905196}],"asks":[],"checksum":1939783346,"timestamp":"2024-06-01T18:06:18.520556Z"}]}
{"channel":"book","type":"update","data":[{"symbol":"ETH/USD","bids":[],"asks":[{"price":3800.48,"qty":0.00000000},{"price":3801.63,"qty":10.81226191}],"checksum":1494456249,"timestamp":"2024-06-01T18:06:18.560759Z"}]}
{"channel":"book","type":"update","data":[{"symbol":"ETH/USD","bids":[{"price":3800.04,"qty":0.00000000},{"price":3799.68,"qty":7.77842526}],"asks":[],"checksum":2453896751,"timestamp":"2024-06-01T18:06:18.560770Z"}]}
{"channel":"book","type":"update","data":[{"symbol":"ETH/USD","bids":[{"price":3800.19,"qty":26.31441911}],"asks":[],"checksum":2237223763,"timestamp":"2024-06-01T18:06:18.565519Z"}]}
{"channel":"book","type":"update","data":[{"symbol":"ETH/USD","bids":[],"asks":[{"price":3800.50,"qty":26.31235005}],"checksum":3183046563,"timestamp":"2024-06-01T18:06:18.565694Z"}]}
{"channel":"book","type":"update","data":[{"symbol":"ETH/USD","bids":[{"price":3800.29,"qty":0.00000000},{"price":3799.68,"qty":7.77842526},{"price":3800.24,"qty":0.00905208}],"asks":[],"checksum":833857656,"timestamp":"2024-06-01T18:06:18.589685Z"}]}
{"channel":"book","type":"update","data":[{"symbol":"ETH/USD","bids":[],"asks":[{"price":3800.50,"qty":0.00000000},{"price":3801.63,"qty":10.81226191}],"checksum":156472456,"timestamp":"2024-06-01T18:06:18.704737Z"}]}
{"channel":"book","type":"update","data":[{"symbol":"ETH/USD","bids":[{"price":3800.19,"qty":0.00000000},{"price":3799.68,"qty":7.77842526}],"asks":[],"checksum":1274566257,"timestamp":"2024-06-01T18:06:18.704885Z"}]}
{"channel":"book","type":"update","data":[{"symbol":"ETH/USD","bids":[{"price":3799.83,"qty":0.00000000},{"price":3799.65,"qty":26.31814987}],"asks":[],"checksum":3923780589,"timestamp":"2024-06-01T18:06:18.705176Z"}]}
{"channel":"book","type":"update","data":[{"symbol":"ETH/USD","bids":[{"price":3799.95,"qty":26.31610220}],"asks":[],"checksum":3033788394,"timestamp":"2024-06-01T18:06:18.709305Z"}]}
{"channel":"book","type":"update","data":[{"symbol":"ETH/USD","bids":[],"asks":[{"price":3800.53,"qty":26.31216059}],"checksum":49396907,"timestamp":"2024-06-01T18:06:18.709324Z"}]}
{"channel":"book","type":"update","data":[{"symbol":"ETH/USD","bids":[{"price":3800.22,"qty":26.31424426}],"asks":[],"checksum":761309305,"timestamp":"2024-06-01T18:06:18.709460Z"}]}
{"channel":"book","type":"update","data":[{"symbol":"ETH/USD","bids":[{"price":3800.24,"qty":0.00000000},{"price":3799.68,"qty":7.77842526},{"price":3800.25,"qty":0.00905206}],"asks":[],"checksum":1240897321,"timestamp":"2024-06-01T18:06:18.715750Z"}]}
{"channel":"book","type":"update","data":[{"symbol":"ETH/USD","bids":[],"asks":[{"price":3800.53,"qty":0.00000000},{"price":3801.63,"qty":10.81226191}],"checksum":1218167932,"timestamp":"2024-06-01T18:06:18.754583Z"}]}
{"channel":"book","type":"update","data":[{"symbol":"ETH/USD","bids":[{"price":3800.25,"qty":0.00000000},{"price":3799.68,"qty":7.77842526},{"price":3800.24,"qty":0.00905208}],"asks":[],"checksum":739113772,"timestamp":"2024-06-01T18:06:18.779175Z"}]}
{"channel":"book","type":"update","data":[{"symbol":"ETH/USD","bids":[{"price":3800.22,"qty":0.00000000},{"price":3799.68,"qty":7.77842526}],"asks":[],"checksum":3033788394,"timestamp":"2024-06-01T18:06:18.806181Z"}]}
{"channel":"book","type":"update","data":[{"symbol":"ETH/USD","bids":[{"price":3800.20,"qty":26.31437577}],"asks":[],"checksum":3564903066,"timestamp":"2024-06-01T18:06:18.811084Z"}]}
{"channel":"book","type":"update","data":[{"symbol":"ETH/USD","bids":[],"asks":[{"price":3800.51,"qty":26.31229748}],"checksum":3468879240,"timestamp":"2024-06-01T18:06:18.811107Z"}]}
{"channel":"book","type":"update","data":[{"symbol":"ETH/USD","bids":[],"asks":[{"price":3800.51,"qty":0.00000000},{"price":3801.63,"qty":10.81226191}],"checksum":3564903066,"timestamp":"2024-06-01T18:06:18.860316Z"}]}
{"channel":"book","type":"update","data":[{"symbol":"ETH/USD","bids":[],"asks":[{"price":3800.50,"qty":26.31235717}],"checksum":4122840602,"timestamp":"2024-06-01T18:06:18.864393Z"}]}
{"channel":"book","type":"update","data":[{"symbol":"ETH/USD","bids":[{"price":3800.24,"qty":0.73818176}],"asks":[],"checksum":2207233234,"timestamp":"2024-06-01T18:06:19.093411Z"}]}
{"channel":"book","type":"update","data":[{"symbol":"ETH/USD","bids":[{"price":3800.20,"qty":0.00000000},{"price":3799.68,"qty":7.77842526}],"asks":[],"checksum":801669790,"timestamp":"2024-06-01T18:06:19.222793Z"}]}
{"channel":"book","type":"update","data":[{"symbol":"ETH/USD","bids":[{"price":3800.23,"qty":0.77000000}],"asks":[],"checksum":4079370653,"timestamp":"2024-06-01T18:06:19.226422Z"}]}
{"channel":"book","type":"update","data":[{"symbol":"ETH/USD","bids":[{"price":3800.22,"qty":26.31425735}],"asks":[],"checksum":3452404066,"timestamp":"2024-06-01T18:06:19.227451Z"}]}
{"channel":"book","type":"update","data":[{"symbol":"ETH/USD","bids":[],"asks":[{"price":3800.95,"qty":0.00000000},{"price":3801.63,"qty":10.81226191},{"price":3800.83,"qty":0.77000000}],"checksum":2899289336,"timestamp":"2024-06-01T18:06:19.229844Z"}]}
{"channel":"book","type":"update","data":[{"symbol":"ETH/USD","bids":[],"asks":[{"price":3800.83,"qty":1.54000000}],"checksum":3068772282,"timestamp":"2024-06-01T18:06:19.229980Z"}]}
{"channel":"book","type":"update","data":[{"symbol":"ETH/USD","bids":[{"price":3800.24,"qty":0.72912968},{"price":3800.25,"qty":0.00905205}],"asks":[],"checksum":1378476621,"timestamp":"2024-06-01T18:06:19.326255Z"}]}
{"channel":"book","type":"update","data":[{"symbol":"ETH/USD","bids":[{"price":3800.22,"qty":0.00000000},{"price":3799.69,"qty":3.00000000}],"asks":[],"checksum":1146753403,"timestamp":"2024-06-01T18:06:19.343114Z"}]}
{"channel":"book","type":"update","data":[{"symbol":"ETH/USD","bids":[{"price":3800.19,"qty":26.31443166}],"asks":[],"checksum":2749494589,"timestamp":"2024-06-01T18:06:19.347549Z"}]}
{"channel":"book","type":"update","data":[{"symbol":"ETH/USD","bids":[{"price":3800.19,"qty":0.00000000},{"price":3799.69,"qty":3.00000000}],"asks":[],"checksum":1146753403,"timestamp":"2024-06-01T18:06:19.351953Z"}]}
{"channel":"book","type":"update","data":[{"symbol":"ETH/USD","bids":[],"asks":[{"price":3800.83,"qty":0.77000000}],"checksum":113288491,"timestamp":"2024-06-01T18:06:19.406092Z"}]}
{"channel":"book","type":"update","data":[{"symbol":"ETH/USD","bids":[],"asks":[{"price":3800.50,"qty":0.00000000},{"price":3801.63,"qty":10.81226191}],"checksum":176798284,"timestamp":"2024-06-01T18:06:19.462864Z"}]}
{"channel":"book","type":"update","data":[{"symbol":"ETH/USD","bids":[],"asks":[{"price":3800.49,"qty":26.31242691}],"checksum":2273590017,"timestamp":"2024-06-01T18:06:19.467560Z"}]}
{"channel":"book","type":"update","data":[{"symbol":"ETH/USD","bids":[{"price":3800.20,"qty":26.31434745}],"asks":[],"checksum":2212864766,"timestamp":"2024-06-01T18:06:19.467580Z"}]}
{"channel":"book","type":"update","data":[{"symbol":"ETH/USD","bids":[],"asks":[{"price":3800.49,"qty":0.00000000},{"price":3801.63,"qty":10.81226191}],"checksum":2332398162,"timestamp":"2024-06-01T18:06:19.636007Z"}]}
{"channel":"book","type":"update","data":[{"symbol":"ETH/USD","bids":[{"price":3800.20,"qty":0.00000000},{"price":3799.69,"qty":3.00000000}],"asks":[],"checksum":176798284,"timestamp":"2024-06-01T18:06:19.636022Z"}]}
{"channel":"book","type":"update","data":[{"symbol":"ETH/USD","bids":[],"asks":[{"price":3800.51,"qty":26.31226376}],"checksum":3404747562,"timestamp":"2024-06-01T18:06:19.640765Z"}]}
{"channel":"book","type":"update","data":[{"symbol":"ETH/USD","bids":[{"price":3800.21,"qty":26.31430211}],"asks":[],"checksum":2034813537,"timestamp":"2024-06-01T18:06:19.640929Z"}]}
{"channel":"book","type":"update","data":[{"symbol":"ETH/USD","bids":[],"asks":[{"price":3800.51,"qty":0.00000000},{"price":3801.63,"qty":10.81226191}],"checksum":3713628133,"timestamp":"2024-06-01T18:06:19.792159Z"}]}
{"channel":"book","type":"update","data":[{"symbol":"ETH/USD","bids":[],"asks":[{"price":3800.50,"qty":26.31236901}],"checksum":1239881704,"timestamp":"2024-06-01T18:06:19.796737Z"}]}
{"channel":"book","type":"update","data":[{"symbol":"ETH/USD","bids":[{"price":3800.21,"qty":0.00000000},{"price":3799.69,"qty":3.00000000}],"asks":[],"checksum":3503436741,"timestamp":"2024-06-01T18:06:19.814937Z"}]}
{"channel":"book","type":"update","data":[{"symbol":"ETH/USD","bids":[{"price":3800.19,"qty":26.31443369}],"asks":[],"checksum":3075464767,"timestamp":"2024-06-01T18:06:19.819696Z"}]}
{"channel":"book","type":"update","data":[{"symbol":"ETH/USD","bids":[],"asks":[{"price":3800.50,"qty":0.00000000},{"price":3801.63,"qty":10.81226191}],"checksum":603045426,"timestamp":"2024-06-01T18:06:20.215970Z"}]}
{"channel":"book","type":"update","data":[{"symbol":"ETH/USD","bids":[],"asks":[{"price":3800.49,"qty":26.31244267}],"checksum":4260091125,"timestamp":"2024-06-01T18:06:20.221471Z"}]}
{"channel":"book","type":"update","data":[{"symbol":"ETH/USD","bids":[],"asks":[{"price":3800.61,"qty":0.00000000},{"price":3801.63,"qty":10.81226191}],"checksum":925990523,"timestamp":"2024-06-01T18:06:20.236648Z"}]}
{"channel":"book","type":"update","data":[{"symbol":"ETH/USD","bids":[{"price":3800.19,"qty":0.00000000},{"price":3799.69,"qty":3.00000000}],"asks":[],"checksum":3407199312,"timestamp":"2024-06-01T18:06:20.236662Z"}]}
{"channel":"book","type":"update","data":[{"symbol":"ETH/USD","bids":[],"asks":[{"price":3800.86,"qty":3.00000000}],"checksum":1653309346,"timestamp":"2024-06-01T18:06:20.240195Z"}]}
{"channel":"book","type":"update","data":[{"symbol":"ETH/USD","bids":[{"price":3800.16,"qty":26.31466056}],"asks":[],"checksum":2749074490,"timestamp":"2024-06-01T18:06:20.244472Z"}]}
{"channel":"book","type":"update","data":[{"symbol":"ETH/USD","bids":[{"price":3800.23,"qty":0.00000000},{"price":3799.69,"qty":3.00000000}],"asks":[],"checksum":3311276305,"timestamp":"2024-06-01T18:06:20.249421Z"}]}
{"channel":"book","type":"update","data":[{"symbol":"ETH/USD","bids":[{"price":3800.15,"qty":0.00000000},{"price":3799.68,"qty":7.77842526}],"asks":[],"checksum":1659155208,"timestamp":"2024-06-01T18:06:20.251110Z"}]}
{"channel":"book","type":"update","data":[{"symbol":"ETH/USD","bids":[{"price":3800.18,"qty":0.00000000},{"price":3799.65,"qty":26.31814987}],"asks":[],"checksum":424763629,"timestamp":"2024-06-01T18:06:20.253076Z"}]}
{"channel":"book","type":"update","data":[{"symbol":"ETH/USD","bids":[{"price":3800.24,"qty":0.00000000},{"price":3799.34,"qty":2.45696258}],"asks":[],"checksum":3983589292,"timestamp":"2024-06-01T18:06:20.253946Z"}]}
{"channel":"book","type":"update","data":[{"symbol":"ETH/USD","bids":[{"price":3800.19,"qty":0.72912968}],"asks":[],"checksum":826783708,"timestamp":"2024-06-01T18:06:20.254000Z"}]}
{"channel":"book","type":"update","data":[{"symbol":"ETH/USD","bids":[],"asks":[{"price":3800.49,"qty":0.00000000},{"price":3801.63,"qty":10.81226191}],"checksum":3245187373,"timestamp":"2024-06-01T18:06:20.255897Z"}]}
{"channel":"book","type":"update","data":[{"symbol":"ETH/USD","bids":[],"asks":[{"price":3801.09,"qty":0.00000000},{"price":3801.74,"qty":4.53808791}],"checksum":2075124163,"timestamp":"2024-06-01T18:06:20.255959Z"}]}
{"channel":"book","type":"update","data":[{"symbol":"ETH/USD","bids":[{"price":3800.16,"qty":0.00000000},{"price":3799.34,"qty":2.45696258}],"asks":[],"checksum":183972667,"timestamp":"2024-06-01T18:06:20.256061Z"}]}
{"channel":"book","type":"update","data":[{"symbol":"ETH/USD","bids":[],"asks":[{"price":3800.63,"qty":26.31146454}],"checksum":71772317,"timestamp":"2024-06-01T18:06:20.264633Z"}]}
{"channel":"book","type":"update","data":[{"symbol":"ETH/USD","bids":[{"price":3799.79,"qty":26.31718405}],"asks":[],"checksum":2017996137,"timestamp":"2024-06-01T18:06:20.264779Z"}]}
{"channel":"book","type":"update","data":[{"symbol":"ETH/USD","bids":[{"price":3799.69,"qty":0.00000000},{"price":3799.34,"qty":2.45696258}],"asks":[],"checksum":1683851753,"timestamp":"2024-06-01T18:06:20.266966Z"}]}
{"channel":"book","type":"update","data":[{"symbol":"ETH/USD","bids":[],"asks":[{"price":3800.46,"qty":3.00000000}],"checksum":803070203,"timestamp":"2024-06-01T18:06:20.267915Z"}]}
{"channel":"book","type":"update","data":[{"symbol":"ETH/USD","bids":[],"asks":[{"price":3800.83,"qty":0.00000000},{"price":3801.63,"qty":10.81226191},{"price":3800.72,"qty":0.77000000}],"checksum":2746109363,"timestamp":"2024-06-01T18:06:20.269617Z"}]}
{"channel":"book","type":"update","data":[{"symbol":"ETH/USD","bids":[],"asks":[{"price":3800.42,"qty":26.31292079}],"checksum":2764794040,"timestamp":"2024-06-01T18:06:20.271619Z"}]}
{"channel":"book","type":"update","data":[{"symbol":"ETH/USD","bids":[],"asks":[{"price":3800.72,"qty":1.54000000}],"checksum":3927490537,"timestamp":"2024-06-01T18:06:20.272765Z"}]}
{"channel":"book","type":"update","data":[{"symbol":"ETH/USD","bids":[{"price":3799.90,"qty":0.00000000},{"price":3799.33,"qty":0.06693358}],"asks":[],"checksum":1109503852,"timestamp":"2024-06-01T18:06:20.279649Z"}]}
{"channel":"book","type":"update","data":[{"symbol":"ETH/USD","bids":[{"price":3800.19,"qty":0.00000000},{"price":3799.29,"qty":0.00513950}],"asks":[],"checksum":4225667124,"timestamp":"2024-06-01T18:06:20.285971Z"}]}
{"channel":"book","type":"update","data":[{"symbol":"ETH/USD","bids":[],"asks":[{"price":3800.46,"qty":0.00000000},{"price":3801.56,"qty":2.11600000}],"checksum":3433652508,"timestamp":"2024-06-01T18:06:20.287278Z"}]}
{"channel":"book","type":"update","data":[{"symbol":"ETH/USD","bids":[{"price":3799.75,"qty":0.00000000},{"price":3799.28,"qty":2.62900000}],"asks":[],"checksum":3329494193,"timestamp":"2024-06-01T18:06:20.288397Z"}]}
{"channel":"book","type":"update","data":[{"symbol":"ETH/USD","bids":[{"price":3799.33,"qty":0.00000000},{"price":3799.25,"qty":3.00000000}],"asks":[],"checksum":214421766,"timestamp":"2024-06-01T18:06:20.291636Z"}]}
{"channel":"book","type":"update","data":[{"symbol":"ETH/USD","bids":[],"asks":[{"price":3800.42,"qty":0.00000000},{"price":3801.63,"qty":10.81226191}],"checksum":735755346,"timestamp":"2024-06-01T18:06:20.300284Z"}]}
{"channel":"book","type":"update","data":[{"symbol":"ETH/USD","bids":[{"price":3799.65,"qty":0.00000000},{"price":3799.09,"qty":26.30952513}],"asks":[],"checksum":948140995,"timestamp":"2024-06-01T18:06:20.300317Z"}]}
{"channel":"book","type":"update","data":[{"symbol":"ETH/USD","bids":[],"asks":[{"price":3800.72,"qty":0.77000000}],"checksum":2369496728,"timestamp":"2024-06-01T18:06:20.300959Z"}]}
{"channel":"book","type":"update","data":[{"symbol":"ETH/USD","bids":[],"asks":[{"price":3800.47,"qty":5.20000000}],"checksum":937168394,"timestamp":"2024-06-01T18:06:20.304928Z"}]}
{"channel":"book","type":"update","data":[{"symbol":"ETH/USD","bids":[{"price":3800.02,"qty":26.31560814}],"asks":[],"checksum":638439787,"timestamp":"2024-06-01T18:06:20.306445Z"}]}
{"channel":"book","type":"update","data":[{"symbol":"ETH/USD","bids":[],"asks":[{"price":3800.46,"qty":26.31260426}],"checksum":2784358011,"timestamp":"2024-06-01T18:06:20.306474Z"}]}
{"channel":"book","type":"update","data":[{"symbol":"ETH/USD","bids":[],"asks":[{"price":3800.72,"qty":0.00000000},{"price":3801.63,"qty":10.81226191},{"price":3800.62,"qty":0.77000000}],"checksum":1908459930,"timestamp":"2024-06-01T18:06:20.306559Z"}]}
{"channel":"book","type":"update","data":[{"symbol":"ETH/USD","bids":[{"price":3799.47,"qty":26.31939229}],"asks":[],"checksum":4153240518,"timestamp":"2024-06-01T18:06:20.306605Z"}]}
{"channel":"book","type":"update","data":[{"symbol":"ETH/USD","bids":[],"asks":[{"price":3800.62,"qty":1.54000000}],"checksum":553856428,"timestamp":"2024-06-01T18:06:20.308448Z"}]}
{"channel":"book","type":"update","data":[{"symbol":"ETH/USD","bids":[],"asks":[{"price":3800.46,"qty":0.00000000},{"price":3801.63,"qty":10.81226191}],"checksum":748644574,"timestamp":"2024-06-01T18:06:20.311800Z"}]}
{"channel":"book","type":"update","data":[{"symbol":"ETH/USD","bids":[{"price":3800.25,"qty":0.00000000},{"price":3799.25,"qty":3.00000000},{"price":3800.20,"qty":0.00905101}],"asks":[],"checksum":2167178171,"timestamp":"2024-06-01T18:06:20.312709Z"}]}
{"channel":"book","type":"update","data":[{"symbol":"ETH/USD","bids":[{"price":3800.02,"qty":0.00000000},{"price":3799.25,"qty":3.00000000}],"asks":[],"checksum":1332462375,"timestamp":"2024-06-01T18:06:20.314659Z"}]}
{"channel":"book","type":"update","data":[{"symbol":"ETH/USD","bids":[{"price":3800.03,"qty":0.72912968}],"asks":[],"checksum":2959730538,"timestamp":"2024-06-01T18:06:20.315818Z"}]}
{"channel":"book","type":"update","data":[{"symbol":"ETH/USD","bids":[],"asks":[{"price":3800.45,"qty":3.00000000}],"checksum":1414571420,"timestamp":"2024-06-01T18:06:20.325367Z"}]}
{"channel":"book","type":"update","data":[{"symbol":"ETH/USD","bids":[],"asks":[{"price":3800.62,"qty":0.77000000}],"checksum":2332088149,"timestamp":"2024-06-01T18:06:20.326717Z"}]}
{"channel":"book","type":"update","data":[{"symbol":"ETH/USD","bids":[],"asks":[{"price":3800.62,"qty":0.00000000},{"price":3801.63,"qty":10.81226191},{"price":3800.48,"qty":0.77000000}],"checksum":1578199381,"timestamp":"2024-06-01T18:06:20.335369Z"}]}
{"channel":"book","type":"update","data":[{"symbol":"ETH/USD","bids":[],"asks":[{"price":3800.48,"qty":1.54000000}],"checksum":1418048546,"timestamp":"2024-06-01T18:06:20.335481Z"}]}
{"channel":"book","type":"update","data":[{"symbol":"ETH/USD","bids":[],"asks":[{"price":3800.29,"qty":26.31382121}],"checksum":1811169923,"timestamp":"2024-06-01T18:06:20.335495Z"}]}
{"channel":"book","type":"update","data":[{"symbol":"ETH/USD","bids":[],"asks":[{"price":3800.63,"qty":0.00000000},{"price":3801.56,"qty":2.11600000}],"checksum":2106899853,"timestamp":"2024-06-01T18:06:20.335558Z"}]}
{"channel":"book","type":"update","data":[{"symbol":"ETH/USD","bids":[{"price":3799.95,"qty":0.00000000},{"price":3799.25,"qty":3.00000000}],"asks":[],"checksum":1338169561,"timestamp":"2024-06-01T18:06:20.336633Z"}]}
{"channel":"book","type":"update","data":[{"symbol":"ETH/USD","bids":[{"price":3799.34,"qty":0.00000000},{"price":3799.06,"qty":0.00235523}],"asks":[],"checksum":2220789179,"timestamp":"2024-06-01T18:06:20.336747Z"}]}
{"channel":"book","type":"update","data":[{"symbol":"ETH/USD","bids":[{"price":3799.48,"qty":0.77100402}],"asks":[],"checksum":3052804730,"timestamp":"2024-06-01T18:06:20.339299Z"}]}
{"channel":"book","type":"update","data":[{"symbol":"ETH/USD","bids":[],"asks":[{"price":3800.29,"qty":0.00000000},{"price":3801.63,"qty":10.81226191}],"checksum":3540727517,"timestamp":"2024-06-01T18:06:20.344710Z"}]}
{"channel":"book","type":"update","data":[{"symbol":"ETH/USD","bids":[{"price":3800.03,"qty":0.00000000},{"price":3799.06,"qty":0.00235523}],"asks":[],"checksum":2813449090,"timestamp":"2024-06-01T18:06:20.350756Z"}]}
{"channel":"book","type":"update","data":[{"symbol":"ETH/USD","bids":[{"price":3799.82,"qty":26.31703452}],"asks":[],"checksum":2258766117,"timestamp":"2024-06-01T18:06:20.356180Z"}]}
{"channel":"book","type":"update","data":[{"symbol":"ETH/USD","bids":[{"price":3799.29,"qty":0.00000000},{"price":3799.06,"qty":0.00235523}],"asks":[],"checksum":173633133,"timestamp":"2024-06-01T18:06:20.358988Z"}]}
{"channel":"book","type":"update","data":[{"symbol":"ETH/USD","bids":[],"asks":[{"price":3800.48,"qty":0.77000000},{"price":3800.39,"qty":0.77000000}],"checksum":1210496472,"timestamp":"2024-06-01T18:06:20.381443Z"}]}
{"channel":"book","type":"update","data":[{"symbol":"ETH/USD","bids":[],"asks":[{"price":3800.21,"qty":26.31433526}],"checksum":3407035514,"timestamp":"2024-06-01T18:06:20.383704Z"}]}
{"channel":"book","type":"update","data":[{"symbol":"ETH/USD","bids":[{"price":3800.20,"qty":0.00000000},{"price":3798.97,"qty":0.52627701},{"price":3800.04,"qty":0.00905139}],"asks":[],"checksum":2720402108,"timestamp":"2024-06-01T18:06:20.384198Z"}]}
{"channel":"book","type":"update","data":[{"symbol":"ETH/USD","bids":[],"asks":[{"price":3800.48,"qty":0.00000000},{"price":3801.56,"qty":2.11600000}],"checksum":3963762139,"timestamp":"2024-06-01T18:06:20.385185Z"}]}
{"channel":"book","type":"update","data":[{"symbol":"ETH/USD","bids":[],"asks":[{"price":3800.47,"qty":2.20000000}],"checksum":460581231,"timestamp":"2024-06-01T18:06:20.385415Z"}]}
{"channel":"book","type":"update","data":[{"symbol":"ETH/USD","bids":[],"asks":[{"price":3800.35,"qty":3.00000000}],"checksum":2389811389,"timestamp":"2024-06-01T18:06:20.385836Z"}]}
{"channel":"book","type":"update","data":[{"symbol":"ETH/USD","bids":[{"price":3799.71,"qty":0.00000000},{"price":3798.97,"qty":0.52627701}],"asks":[],"checksum":1095130732,"timestamp":"2024-06-01T18:06:20.386821Z"}]}
{"channel":"book","type":"update","data":[{"symbol":"ETH/USD","bids":[{"price":3799.82,"qty":0.00000000},{"price":3798.88,"qty":0.00545998}],"asks":[],"checksum":1501239369,"timestamp":"2024-06-01T18:06:20.390902Z"}]}
{"channel":"book","type":"update","data":[{"symbol":"ETH/USD","bids":[],"asks":[{"price":3800.39,"qty":0.00000000},{"price":3801.56,"qty":2.11600000},{"price":3800.49,"qty":0.77000000}],"checksum":1542883826,"timestamp":"2024-06-01T18:06:20.391279Z"}]}
{"channel":"book","type":"update","data":[{"symbol":"ETH/USD","bids":[],"asks":[{"price":3800.49,"qty":1.54000000}],"checksum":2062162836,"timestamp":"2024-06-01T18:06:20.391708Z"}]}
{"channel":"book","type":"update","data":[{"symbol":"ETH/USD","bids":[],"asks":[{"price":3800.49,"qty":0.77000000}],"checksum":1542883826,"timestamp":"2024-06-01T18:06:20.394405Z"}]}
{"channel":"book","type":"update","data":[{"symbol":"ETH/USD","bids":[],"asks":[{"price":3800.45,"qty":0.00000000},{"price":3801.56,"qty":2.11600000}],"checksum":2154591401,"timestamp":"2024-06-01T18:06:20.395421Z"}]}
{"channel":"book","type":"update","data":[{"symbol":"ETH/USD","bids":[{"price":3798.93,"qty":0.06693358}],"asks":[],"checksum":1909417302,"timestamp":"2024-06-01T18:06:20.398655Z"}]}
{"channel":"book","type":"update","data":[{"symbol":"ETH/USD","bids":[],"asks":[{"price":3800.21,"qty":0.00000000},{"price":3801.63,"qty":10.81226191}],"checksum":1947941377,"timestamp":"2024-06-01T18:06:20.416697Z"}]}
{"channel":"book","type":"update","data":[{"symbol":"ETH/USD","bids":[],"asks":[{"price":3800.78,"qty":4.07171446}],"checksum":2656776595,"timestamp":"2024-06-01T18:06:20.419703Z"}]}
{"channel":"book","type":"update","data":[{"symbol":"ETH/USD","bids":[{"price":3799.81,"qty":26.31708970}],"asks":[],"checksum":2021806977,"timestamp":"2024-06-01T18:06:20.422015Z"}]}
{"channel":"book","type":"update","data":[{"symbol":"ETH/USD","bids":[{"price":3799.06,"qty":2.11835523}],"asks":[],"checksum":2143608462,"timestamp":"2024-06-01T18:06:20.431376Z"}]}
{"channel":"book","type":"update","data":[{"symbol":"ETH/USD","bids":[{"price":3799.49,"qty":3.50197078}],"asks":[],"checksum":2565930746,"timestamp":"2024-06-01T18:06:20.435894Z"}]}
{"channel":"book","type":"update","data":[{"symbol":"ETH/USD","bids":[],"asks":[{"price":3800.11,"qty":26.31504257}],"checksum":1183668449,"timestamp":"2024-06-01T18:06:20.437901Z"}]}
{"channel":"book","type":"update","data":[{"symbol":"ETH/USD","bids":[{"price":3799.49,"qty":0.00000000},{"price":3798.97,"qty":0.52627701}],"asks":[],"checksum":3120300131,"timestamp":"2024-06-01T18:06:20.476305Z"}]}
{"channel":"book","type":"update","data":[{"symbol":"ETH/USD","bids":[{"price":3800.04,"qty":0.00000000},{"price":3798.93,"qty":0.06693358},{"price":3799.80,"qty":0.00905196}],"asks":[],"checksum":826296338,"timestamp":"2024-06-01T18:06:20.498957Z"}]}
{"channel":"book","type":"update","data":[{"symbol":"ETH/USD","bids":[{"price":3799.83,"qty":0.77000000}],"asks":[],"checksum":2008247934,"timestamp":"2024-06-01T18:06:20.528842Z"}]}
{"channel":"book","type":"update","data":[{"symbol":"ETH/USD","bids":[],"asks":[{"price":3800.35,"qty":0.00000000},{"price":3801.63,"qty":10.81226191}],"checksum":3750517212,"timestamp":"2024-06-01T18:06:20.547059Z"}]}
{"channel":"book","type":"update","data":[{"symbol":"ETH/USD","bids":[{"price":3799.23,"qty":3.50221044}],"asks":[],"checksum":2313377563,"timestamp":"2024-06-01T18:06:20.599642Z"}]}
{"channel":"book","type":"update","data":[{"symbol":"ETH/USD","bids":[],"asks":[{"price":3800.11,"qty":0.00000000},{"price":3801.74,"qty":4.53808791}],"checksum":1044987840,"timestamp":"2024-06-01T18:06:20.628118Z"}]}
{"channel":"book","type":"update","data":[{"symbol":"ETH/USD","bids":[],"asks":[{"price":3800.35,"qty":3.00000000}],"checksum":3890527828,"timestamp":"2024-06-01T18:06:20.631765Z"}]}
{"channel":"book","type":"update","data":[{"symbol":"ETH/USD","bids":[],"asks":[{"price":3800.46,"qty":26.31260426}],"checksum":1581114026,"timestamp":"2024-06-01T18:06:20.633709Z"}]}
{"channel":"book","type":"update","data":[{"symbol":"ETH/USD","bids":[],"asks":[{"price":3800.10,"qty":26.31513438}],"checksum":3446718774,"timestamp":"2024-06-01T18:06:20.633725Z"}]}
{"channel":"book","type":"update","data":[{"symbol":"ETH/USD","bids":[],"asks":[{"price":3800.46,"qty":52.62520852}],"checksum":1878452720,"timestamp":"2024-06-01T18:06:20.633787Z"}]}
{"channel":"book","type":"update","data":[{"symbol":"ETH/USD","bids":[],"asks":[{"price":3800.46,"qty":26.31260426}],"checksum":3446718774,"timestamp":"2024-06-01T18:06:20.639408Z"}]}
{"channel":"book","type":"update","data":[{"symbol":"ETH/USD","bids":[],"asks":[{"price":3800.46,"qty":0.00000000},{"price":3801.56,"qty":2.11600000}],"checksum":3393493893,"timestamp":"2024-06-01T18:06:20.639531Z"}]}
{"channel":"book","type":"update","data":[{"symbol":"ETH/USD","bids":[{"price":3799.23,"qty":0.00000000},{"price":3799.06,"qty":2.11835523}],"asks":[],"checksum":2620101954,"timestamp":"2024-06-01T18:06:20.649160Z"}]}
{"channel":"book","type":"update","data":[{"symbol":"ETH/USD","bids":[],"asks":[{"price":3801.56,"qty":0.00000000},{"price":3801.63,"qty":10.81226191}],"checksum":187835271,"timestamp":"2024-06-01T18:06:20.673051Z"}]}
{"channel":"book","type":"update","data":[{"symbol":"ETH/USD","bids":[],"asks":[{"price":3800.76,"qty":2.11600000}],"checksum":2873452711,"timestamp":"2024-06-01T18:06:20.675361Z"}]}
{"channel":"book","type":"update","data":[{"symbol":"ETH/USD","bids":[{"price":3799.68,"qty":0.00000000},{"price":3798.97,"qty":0.52627701}],"asks":[],"checksum":2195279360,"timestamp":"2024-06-01T18:06:20.825189Z"}]}
{"channel":"book","type":"update","data":[{"symbol":"ETH/USD","bids":[{"price":3799.63,"qty":7.77852762}],"asks":[],"checksum":840951267,"timestamp":"2024-06-01T18:06:20.829231Z"}]}
{"channel":"book","type":"update","data":[{"symbol":"ETH/USD","bids":[{"price":3799.23,"qty":3.50221044}],"asks":[],"checksum":1685121828,"timestamp":"2024-06-01T18:06:20.852488Z"}]}
{"channel":"book","type":"update","data":[{"symbol":"ETH/USD","bids":[{"price":3799.23,"qty":0.00000000},{"price":3799.06,"qty":2.11835523}],"asks":[],"checksum":840951267,"timestamp":"2024-06-01T18:06:20.860851Z"}]}
{"channel":"book","type":"update","data":[{"symbol":"ETH/USD","bids":[{"price":3799.80,"qty":0.00000000},{"price":3798.97,"qty":0.52627701},{"price":3799.84,"qty":0.00905187}],"asks":[],"checksum":1111966887,"timestamp":"2024-06-01T18:06:20.861967Z"}]}
{"channel":"book","type":"update","data":[{"symbol":"ETH/USD","bids":[{"price":3799.83,"qty":0.00000000},{"price":3798.97,"qty":0.52627701},{"price":3799.68,"qty":0.77000000}],"asks":[],"checksum":2068104064,"timestamp":"2024-06-01T18:06:20.896883Z"}]}
{"channel":"book","type":"update","data":[{"symbol":"ETH/USD","bids":[],"asks":[{"price":3800.49,"qty":0.00000000},{"price":3801.62,"qty":0.00537464},{"price":3800.32,"qty":0.77000000}],"checksum":2621494683,"timestamp":"2024-06-01T18:06:20.897101Z"}]}
{"channel":"book","type":"update","data":[{"symbol":"ETH/USD","bids":[{"price":3799.68,"qty":1.54000000}],"asks":[],"checksum":546660551,"timestamp":"2024-06-01T18:06:20.897154Z"}]}
{"channel":"book","type":"update","data":[{"symbol":"ETH/USD","bids":[],"asks":[{"price":3800.32,"qty":1.54000000}],"checksum":3767998715,"timestamp":"2024-06-01T18:06:20.899920Z"}]}
{"channel":"book","type":"update","data":[{"symbol":"ETH/USD","bids":[{"price":3799.68,"qty":0.77000000}],"asks":[],"checksum":609502436,"timestamp":"2024-06-01T18:06:20.906504Z"}]}
{"channel":"book","type":"update","data":[{"symbol":"ETH/USD","bids":[{"price":3799.68,"qty":0.00000000},{"price":3798.97,"qty":0.52627701}],"asks":[],"checksum":2044667703,"timestamp":"2024-06-01T18:06:20.906648Z"}]}
{"channel":"book","type":"update","data":[{"symbol":"ETH/USD","bids":[],"asks":[{"price":3800.48,"qty":3.00000000}],"checksum":425528854,"timestamp":"2024-06-01T18:06:20.907707Z"}]}
{"channel":"book","type":"update","data":[{"symbol":"ETH/USD","bids":[{"price":3799.63,"qty":0.00000000},{"price":3798.93,"qty":0.06693358}],"asks":[],"checksum":4128010764,"timestamp":"2024-06-01T18:06:20.907833Z"}]}
{"channel":"book","type":"update","data":[{"symbol":"ETH/USD","bids":[],"asks":[{"price":3800.10,"qty":0.00000000},{"price":3801.32,"qty":3.00000000}],"checksum":2009370835,"timestamp":"2024-06-01T18:06:20.909089Z"}]}
{"channel":"book","type":"update","data":[{"symbol":"ETH/USD","bids":[],"asks":[{"price":3800.79,"qty":0.00000000},{"price":3801.62,"qty":0.00537464}],"checksum":3543102274,"timestamp":"2024-06-01T18:06:20.909321Z"}]}
{"channel":"book","type":"update","data":[{"symbol":"ETH/USD","bids":[],"asks":[{"price":3800.78,"qty":0.77171446}],"checksum":3471772560,"timestamp":"2024-06-01T18:06:20.911930Z"}]}
{"channel":"book","type":"update","data":[{"symbol":"ETH/USD","bids":[{"price":3799.58,"qty":7.77862998}],"asks":[],"checksum":3451947868,"timestamp":"2024-06-01T18:06:20.911955Z"}]}
{"channel":"book","type":"update","data":[{"symbol":"ETH/USD","bids":[],"asks":[{"price":3800.76,"qty":5.41600000}],"checksum":2687008938,"timestamp":"2024-06-01T18:06:20.912119Z"}]}
{"channel":"book","type":"update","data":[{"symbol":"ETH/USD","bids":[],"asks":[{"price":3800.48,"qty":0.00000000},{"price":3801.63,"qty":10.81226191}],"checksum":1507352452,"timestamp":"2024-06-01T18:06:20.912240Z"}]}
{"channel":"book","type":"update","data":[{"symbol":"ETH/USD","bids":[],"asks":[{"price":3800.31,"qty":3.00000000}],"checksum":1128877790,"timestamp":"2024-06-01T18:06:20.913258Z"}]}
{"channel":"book","type":"update","data":[{"symbol":"ETH/USD","bids":[],"asks":[{"price":3801.31,"qty":5.26000000}],"checksum":229613198,"timestamp":"2024-06-01T18:06:20.913828Z"}]}
{"channel":"book","type":"update","data":[{"symbol":"ETH/USD","bids":[],"asks":[{"price":3800.07,"qty":26.31531701}],"checksum":4101279670,"timestamp":"2024-06-01T18:06:20.920073Z"}]}
{"channel":"book","type":"update","data":[{"symbol":"ETH/USD","bids":[{"price":3799.27,"qty":26.32081887}],"asks":[],"checksum":4099570981,"timestamp":"2024-06-01T18:06:20.920170Z"}]}
{"channel":"book","type":"update","data":[{"symbol":"ETH/USD","bids":[],"asks":[{"price":3800.62,"qty":26.31151223}],"checksum":3092192915,"timestamp":"2024-06-01T18:06:20.920234Z"}]}
{"channel":"book","type":"update","data":[{"symbol":"ETH/USD","bids":[{"price":3799.81,"qty":0.00000000},{"price":3798.97,"qty":0.52627701}],"asks":[],"checksum":104014020,"timestamp":"2024-06-01T18:06:20.920314Z"}]}
{"channel":"book","type":"update","data":[{"symbol":"ETH/USD","bids":[],"asks":[{"price":3800.31,"qty":29.31364283}],"checksum":1727717593,"timestamp":"2024-06-01T18:06:20.920352Z"}]}
{"channel":"book","type":"update","data":[{"symbol":"ETH/USD","bids":[{"price":3799.79,"qty":0.00000000},{"price":3798.93,"qty":0.06693358}],"asks":[],"checksum":1649870768,"timestamp":"2024-06-01T18:06:20.921879Z"}]}
{"channel":"book","type":"update","data":[{"symbol":"ETH/USD","bids":[],"asks":[{"price":3800.31,"qty":3.00000000}],"checksum":3236074876,"timestamp":"2024-06-01T18:06:20.928784Z"}]}
{"channel":"book","type":"update","data":[{"symbol":"ETH/USD","bids":[],"asks":[{"price":3800.07,"qty":0.00000000},{"price":3801.31,"qty":5.26000000}],"checksum":483176938,"timestamp":"2024-06-01T18:06:20.928857Z"}]}
{"channel":"book","type":"update","data":[{"symbol":"ETH/USD","bids":[],"asks":[{"price":3800.45,"qty":3.00000000}],"checksum":2320343197,"timestamp":"2024-06-01T18:06:20.930675Z"}]}
{"channel":"book","type":"update","data":[{"symbol":"ETH/USD","bids":[{"price":3799.66,"qty":26.31812517}],"asks":[],"checksum":899181351,"timestamp":"2024-06-01T18:06:20.934237Z"}]}
{"channel":"book","type":"update","data":[{"symbol":"ETH/USD","bids":[{"price":3799.60,"qty":26.31852410}],"asks":[],"checksum":4262596309,"timestamp":"2024-06-01T18:06:20.934284Z"}]}
{"channel":"book","type":"update","data":[{"symbol":"ETH/USD","bids":[],"asks":[{"price":3800.30,"qty":26.31371207}],"checksum":3907272548,"timestamp":"2024-06-01T18:06:20.934302Z"}]}
{"channel":"book","type":"update","data":[{"symbol":"ETH/USD","bids":[],"asks":[{"price":3800.28,"qty":3.00000000}],"checksum":3332107528,"timestamp":"2024-06-01T18:06:20.937945Z"}]}
{"channel":"book","type":"update","data":[{"symbol":"ETH/USD","bids":[],"asks":[{"price":3800.45,"qty":0.00000000},{"price":3800.86,"qty":3.00000000}],"checksum":3208385590,"timestamp":"2024-06-01T18:06:20.937990Z"}]}
{"channel":"book","type":"update","data":[{"symbol":"ETH/USD","bids":[],"asks":[{"price":3800.35,"qty":0.00000000},{"price":3800.93,"qty":0.55000000}],"checksum":1609643068,"timestamp":"2024-06-01T18:06:20.938697Z"}]}
{"channel":"book","type":"update","data":[{"symbol":"ETH/USD","bids":[{"price":3799.27,"qty":0.00000000},{"price":3798.97,"qty":0.52627701}],"asks":[],"checksum":3933079613,"timestamp":"2024-06-01T18:06:20.942647Z"}]}
{"channel":"book","type":"update","data":[{"symbol":"ETH/USD","bids":[],"asks":[{"price":3800.30,"qty":0.00000000},{"price":3801.31,"qty":5.26000000}],"checksum":3807270598,"timestamp":"2024-06-01T18:06:20.942676Z"}]}
{"channel":"book","type":"update","data":[{"symbol":"ETH/USD","bids":[{"price":3799.66,"qty":0.00000000},{"price":3798.93,"qty":0.06693358}],"asks":[],"checksum":2342926176,"timestamp":"2024-06-01T18:06:20.942715Z"}]}
{"channel":"book","type":"update","data":[{"symbol":"ETH/USD","bids":[{"price":3799.84,"qty":0.00000000},{"price":3798.74,"qty":0.00517963},{"price":3799.82,"qty":0.00905191}],"asks":[],"checksum":3117724902,"timestamp":"2024-06-01T18:06:20.944871Z"}]}
{"channel":"book","type":"update","data":[{"symbol":"ETH/USD","bids":[],"asks":[{"price":3800.31,"qty":0.00000000},{"price":3801.32,"qty":3.00000000}],"checksum":688141577,"timestamp":"2024-06-01T18:06:20.946906Z"}]}
{"channel":"book","type":"update","data":[{"symbol":"ETH/USD","bids":[],"asks":[{"price":3800.32,"qty":0.77000000}],"checksum":4024001274,"timestamp":"2024-06-01T18:06:20.966700Z"}]}
{"channel":"book","type":"update","data":[{"symbol":"ETH/USD","bids":[],"asks":[{"price":3799.97,"qty":26.31605145}],"checksum":1306791716,"timestamp":"2024-06-01T18:06:20.970722Z"}]}
{"channel":"book","type":"update","data":[{"symbol":"ETH/USD","bids":[],"asks":[{"price":3799.97,"qty":0.00000000},{"price":3801.32,"qty":3.00000000}],"checksum":4024001274,"timestamp":"2024-06-01T18:06:20.977485Z"}]}
{"channel":"book","type":"update","data":[{"symbol":"ETH/USD","bids":[],"asks":[{"price":3800.32,"qty":0.00000000},{"price":3801.62,"qty":0.00537464},{"price":3800.22,"qty":0.77000000}],"checksum":3809655804,"timestamp":"2024-06-01T18:06:20.983295Z"}]}
{"channel":"book","type":"update","data":[{"symbol":"ETH/USD","bids":[],"asks":[{"price":3800.22,"qty":1.54000000}],"checksum":1927502287,"timestamp":"2024-06-01T18:06:20.986297Z"}]}
{"channel":"book","type":"update","data":[{"symbol":"ETH/USD","bids":[],"asks":[{"price":3800.22,"qty":0.77000000}],"checksum":3809655804,"timestamp":"2024-06-01T18:06:20.986776Z"}]}
{"channel":"book","type":"update","data":[{"symbol":"ETH/USD","bids":[],"asks":[{"price":3800.22,"qty":3.77000000}],"checksum":1653194925,"timestamp":"2024-06-01T18:06:20.987345Z"}]}
{"channel":"book","type":"update","data":[{"symbol":"ETH/USD","bids":[],"asks":[{"price":3800.28,"qty":0.00000000},{"price":3801.62,"qty":0.00537464}],"checksum":1533442307,"timestamp":"2024-06-01T18:06:20.987598Z"}]}
{"channel":"book","type":"update","data":[{"symbol":"ETH/USD","bids":[{"price":3799.67,"qty":26.31806467}],"asks":[],"checksum":1594787204,"timestamp":"2024-06-01T18:06:20.988240Z"}]}
{"channel":"book","type":"update","data":[{"symbol":"ETH/USD","bids":[{"price":3799.82,"qty":0.00000000},{"price":3798.93,"qty":0.06693358},{"price":3799.61,"qty":0.00905241}],"asks":[],"checksum":3762591764,"timestamp":"2024-06-01T18:06:20.995882Z"}]}
{"channel":"book","type":"update","data":[{"symbol":"ETH/USD","bids":[{"price":3799.28,"qty":6.13116435}],"asks":[],"checksum":2327758250,"timestamp":"2024-06-01T18:06:21.000066Z"}]}
{"channel":"book","type":"update","data":[{"symbol":"ETH/USD","bids":[],"asks":[{"price":3801.20,"qty":0.06693358}],"checksum":212274267,"timestamp":"2024-06-01T18:06:21.008270Z"}]}
{"channel":"book","type":"update","data":[{"symbol":"ETH/USD","bids":[{"price":3799.28,"qty":2.62900000}],"asks":[],"checksum":1717391845,"timestamp":"2024-06-01T18:06:21.014078Z"}]}
{"channel":"book","type":"update","data":[{"symbol":"ETH/USD","bids":[{"price":3799.67,"qty":0.00000000},{"price":3798.74,"qty":0.00517963}],"asks":[],"checksum":1609830573,"timestamp":"2024-06-01T18:06:21.018955Z"}]}
{"channel":"book","type":"update","data":[{"symbol":"ETH/USD","bids":[{"price":3799.61,"qty":0.73818209}],"asks":[],"checksum":4039506945,"timestamp":"2024-06-01T18:06:21.024756Z"}]}
{"channel":"book","type":"update","data":[{"symbol":"ETH/USD","bids":[],"asks":[{"price":3800.21,"qty":2.20000000}],"checksum":421250081,"timestamp":"2024-06-01T18:06:21.025019Z"}]}
{"channel":"book","type":"update","data":[{"symbol":"ETH/USD","bids":[],"asks":[{"price":3800.47,"qty":0.00000000},{"price":3801.32,"qty":3.00000000}],"checksum":3441825235,"timestamp":"2024-06-01T18:06:21.025044Z"}]}
{"channel":"book","type":"update","data":[{"symbol":"ETH/USD","bids":[],"asks":[{"price":3800.21,"qty":28.51433526}],"checksum":3103285219,"timestamp":"2024-06-01T18:06:21.026218Z"}]}
{"channel":"book","type":"update","data":[{"symbol":"ETH/USD","bids":[{"price":3799.60,"qty":27.08852410}],"asks":[],"checksum":2866630961,"timestamp":"2024-06-01T18:06:21.026370Z"}]}
{"channel":"book","type":"update","data":[{"symbol":"ETH/USD","bids":[],"asks":[{"price":3800.20,"qty":3.00000000}],"checksum":1058259693,"timestamp":"2024-06-01T18:06:21.029076Z"}]}
{"channel":"book","type":"update","data":[{"symbol":"ETH/USD","bids":[],"asks":[{"price":3800.78,"qty":0.00000000},{"price":3801.32,"qty":3.00000000}],"checksum":3205782700,"timestamp":"2024-06-01T18:06:21.032298Z"}]}
{"channel":"book","type":"update","data":[{"symbol":"ETH/USD","bids":[],"asks":[{"price":3800.21,"qty":2.20000000}],"checksum":643457795,"timestamp":"2024-06-01T18:06:21.040342Z"}]}
{"channel":"book","type":"update","data":[{"symbol":"ETH/USD","bids":[{"price":3799.64,"qty":26.31825879}],"asks":[],"checksum":945554151,"timestamp":"2024-06-01T18:06:21.044821Z"}]}
{"channel":"book","type":"update","data":[{"symbol":"ETH/USD","bids":[{"price":3799.28,"qty":0.00000000},{"price":3798.74,"qty":0.00517963}],"asks":[],"checksum":2151397594,"timestamp":"2024-06-01T18:06:21.047021Z"}]}
{"channel":"book","type":"update","data":[{"symbol":"ETH/USD","bids":[],"asks":[{"price":3799.95,"qty":26.31620344}],"checksum":2528796191,"timestamp":"2024-06-01T18:06:21.077621Z"}]}
{"channel":"book","type":"update","data":[{"symbol":"ETH/USD","bids":[{"price":3798.92,"qty":2.62900000}],"asks":[],"checksum":3292708406,"timestamp":"2024-06-01T18:06:21.081080Z"}]}
{"channel":"book","type":"update","data":[{"symbol":"ETH/USD","bids":[],"asks":[{"price":3799.95,"qty":0.00000000},{"price":3801.32,"qty":3.00000000}],"checksum":3250392407,"timestamp":"2024-06-01T18:06:21.091897Z"}]}
{"channel":"book","type":"update","data":[{"symbol":"ETH/USD","bids":[],"asks":[{"price":3799.93,"qty":26.31629819}],"checksum":3420511356,"timestamp":"2024-06-01T18:06:21.127934Z"}]}
{"channel":"book","type":"update","data":[{"symbol":"ETH/USD","bids":[],"asks":[{"price":3800.19,"qty":26.31447374}],"checksum":2335789871,"timestamp":"2024-06-01T18:06:21.128049Z"}]}
{"channel":"book","type":"update","data":[{"symbol":"ETH/USD","bids":[{"price":3799.08,"qty":3.50234872}],"asks":[],"checksum":74015851,"timestamp":"2024-06-01T18:06:21.135069Z"}]}
{"channel":"book","type":"update","data":[{"symbol":"ETH/USD","bids":[],"asks":[{"price":3800.18,"qty":0.75329385}],"checksum":108312446,"timestamp":"2024-06-01T18:06:21.138684Z"}]}
{"channel":"book","type":"update","data":[{"symbol":"ETH/USD","bids":[{"price":3799.58,"qty":0.00000000},{"price":3798.92,"qty":2.62900000}],"asks":[],"checksum":1742027680,"timestamp":"2024-06-01T18:06:21.382873Z"}]}
{"channel":"book","type":"update","data":[{"symbol":"ETH/USD","bids":[{"price":3799.60,"qty":26.31852410}],"asks":[],"checksum":2078604980,"timestamp":"2024-06-01T18:06:21.383359Z"}]}
{"channel":"book","type":"update","data":[{"symbol":"ETH/USD","bids":[{"price":3799.43,"qty":7.77893707}],"asks":[],"checksum":1256436448,"timestamp":"2024-06-01T18:06:21.387272Z"}]}
{"channel":"book","type":"update","data":[{"symbol":"ETH/USD","bids":[{"price":3799.08,"qty":0.00000000},{"price":3798.92,"qty":2.62900000}],"asks":[],"checksum":3316876708,"timestamp":"2024-06-01T18:06:21.405576Z"}]}
{"channel":"book","type":"update","data":[{"symbol":"ETH/USD","bids":[{"price":3799.64,"qty":0.00000000},{"price":3798.79,"qty":0.06693358}],"asks":[],"checksum":4126188022,"timestamp":"2024-06-01T18:06:21.415099Z"}]}
{"channel":"book","type":"update","data":[{"symbol":"ETH/USD","bids":[],"asks":[{"price":3799.93,"qty":0.00000000},{"price":3801.20,"qty":0.06693358}],"checksum":756177321,"timestamp":"2024-06-01T18:06:21.415275Z"}]}
{"channel":"book","type":"update","data":[{"symbol":"ETH/USD","bids":[{"price":3799.25,"qty":0.00000000},{"price":3798.74,"qty":0.00517963}],"asks":[],"checksum":2578214011,"timestamp":"2024-06-01T18:06:21.418669Z"}]}
{"channel":"book","type":"update","data":[{"symbol":"ETH/USD","bids":[],"asks":[{"price":3800.11,"qty":3.00000000}],"checksum":2877346130,"timestamp":"2024-06-01T18:06:21.419280Z"}]}
{"channel":"book","type":"update","data":[{"symbol":"ETH/USD","bids":[],"asks":[{"price":3800.22,"qty":0.77000000}],"checksum":3444295331,"timestamp":"2024-06-01T18:06:21.419623Z"}]}
{"channel":"book","type":"update","data":[{"symbol":"ETH/USD","bids":[{"price":3799.62,"qty":26.31839039}],"asks":[],"checksum":2932961189,"timestamp":"2024-06-01T18:06:21.421434Z"}]}
{"channel":"book","type":"update","data":[{"symbol":"ETH/USD","bids":[],"asks":[{"price":3799.92,"qty":26.31637081}],"checksum":223390355,"timestamp":"2024-06-01T18:06:21.421468Z"}]}
{"channel":"book","type":"update","data":[{"symbol":"ETH/USD","bids":[],"asks":[{"price":3800.17,"qty":26.31461224}],"checksum":548920496,"timestamp":"2024-06-01T18:06:21.421487Z"}]}
{"channel":"book","type":"update","data":[{"symbol":"ETH/USD","bids":[{"price":3799.09,"qty":26.32207836}],"asks":[],"checksum":1334926668,"timestamp":"2024-06-01T18:06:21.421698Z"}]}
