{"channel":"book","type":"snapshot","data":[{"symbol":"ETH/BTC","bids":[{"price":0.05612,"qty":11.52386431},{"price":0.05611,"qty":15.61240031},{"price":0.05610,"qty":33.87425596},{"price":0.05609,"qty":2.05851962},{"price":0.05608,"qty":4.73266277},{"price":0.05607,"qty":16.60869553},{"price":0.05606,"qty":28.39109296},{"price":0.05605,"qty":11.54027853},{"price":0.05604,"qty":32.02104920},{"price":0.05603,"qty":7.88037232}],"asks":[{"price":0.05613,"qty":0.02182061},{"price":0.05614,"qty":7.06398658},{"price":0.05615,"qty":15.56766980},{"price":0.05616,"qty":2.33799535},{"price":0.05617,"qty":20.81771961},{"price":0.05618,"qty":1.95721321},{"price":0.05619,"qty":9.93547375},{"price":0.05620,"qty":32.46620301},{"price":0.05621,"qty":19.19196744},{"price":0.05622,"qty":3.54156000}],"checksum":2409093403}]}
{"channel":"book","type":"update","data":[{"symbol":"ETH/BTC","bids":[],"asks":[{"price":0.05620,"qty":32.28684074}],"checksum":69973235,"timestamp":"2024-06-01T18:05:59.242845Z"}]}
{"channel":"book","type":"update","data":[{"symbol":"ETH/BTC","bids":[],"asks":[{"price":0.05621,"qty":19.37129780}],"checksum":39246770,"timestamp":"2024-06-01T18:05:59.242859Z"}]}
{"channel":"book","type":"update","data":[{"symbol":"ETH/BTC","bids":[],"asks":[{"price":0.05621,"qty":19.19196744}],"checksum":69973235,"timestamp":"2024-06-01T18:05:59.511313Z"}]}
{"channel":"book","type":"update","data":[{"symbol":"ETH/BTC","bids":[],"asks":[{"price":0.05620,"qty":32.46620301}],"checksum":2409093403,"timestamp":"2024-06-01T18:05:59.685637Z"}]}
{"channel":"book","type":"update","data":[{"symbol":"ETH/BTC","bids":[{"price":0.05610,"qty":32.82226771}],"asks":[],"checksum":2415671621,"timestamp":"2024-06-01T18:05:59.822549Z"}]}
{"channel":"book","type":"update","data":[{"symbol":"ETH/BTC","bids":[{"price":0.05612,"qty":8.89202556}],"asks":[],"checksum":509158329,"timestamp":"2024-06-01T18:06:00.056424Z"}]}
{"channel":"book","type":"update","data":[{"symbol":"ETH/BTC","bids":[],"asks":[{"price":0.05620,"qty":19.32527912}],"checksum":703012186,"timestamp":"2024-06-01T18:06:00.056570Z"}]}
{"channel":"book","type":"update","data":[{"symbol":"ETH/BTC","bids":[],"asks":[{"price":0.05618,"qty":15.10230022}],"checksum":352769480,"timestamp":"2024-06-01T18:06:00.061098Z"}]}
{"channel":"book","type":"update","data":[{"symbol":"ETH/BTC","bids":[{"price":0.05611,"qty":18.24428669}],"asks":[],"checksum":4120661238,"timestamp":"2024-06-01T18:06:00.061383Z"}]}
{"channel":"book","type":"update","data":[{"symbol":"ETH/BTC","bids":[],"asks":[{"price":0.05620,"qty":19.14591685}],"checksum":1739010225,"timestamp":"2024-06-01T18:06:00.063443Z"}]}
{"channel":"book","type":"update","data":[{"symbol":"ETH/BTC","bids":[],"asks":[{"price":0.05621,"qty":19.37129780}],"checksum":2893901556,"timestamp":"2024-06-01T18:06:00.063551Z"}]}
{"channel":"book","type":"update","data":[{"symbol":"ETH/BTC","bids":[{"price":0.05609,"qty":3.11055370}],"asks":[],"checksum":229138217,"timestamp":"2024-06-01T18:06:00.083682Z"}]}
{"channel":"book","type":"update","data":[{"symbol":"ETH/BTC","bids":[{"price":0.05606,"qty":15.23680430}],"asks":[],"checksum":754662883,"timestamp":"2024-06-01T18:06:00.342069Z"}]}
{"channel":"book","type":"update","data":[{"symbol":"ETH/BTC","bids":[],"asks":[{"price":0.05616,"qty":9.23175895}],"checksum":3785731897,"timestamp":"2024-06-01T18:06:00.382298Z"}]}
{"channel":"book","type":"update","data":[{"symbol":"ETH/BTC","bids":[{"price":0.05607,"qty":29.76391312}],"asks":[],"checksum":2433083493,"timestamp":"2024-06-01T18:06:00.382332Z"}]}
{"channel":"book","type":"update","data":[{"symbol":"ETH/BTC","bids":[],"asks":[{"price":0.05621,"qty":5.28740268}],"checksum":235108239,"timestamp":"2024-06-01T18:06:01.046180Z"}]}
{"channel":"book","type":"update","data":[{"symbol":"ETH/BTC","bids":[],"asks":[{"price":0.05619,"qty":2.82964476}],"checksum":3059496878,"timestamp":"2024-06-01T18:06:01.046327Z"}]}
{"channel":"book","type":"update","data":[{"symbol":"ETH/BTC","bids":[],"asks":[{"price":0.05617,"qty":7.67653358}],"checksum":4164241559,"timestamp":"2024-06-01T18:06:01.056644Z"}]}
{"channel":"book","type":"update","data":[{"symbol":"ETH/BTC","bids":[],"asks":[{"price":0.05616,"qty":22.38144570}],"checksum":3613283655,"timestamp":"2024-06-01T18:06:01.060492Z"}]}
{"channel":"book","type":"update","data":[{"symbol":"ETH/BTC","bids":[],"asks":[{"price":0.05620,"qty":33.22769197}],"checksum":1711745864,"timestamp":"2024-06-01T18:06:01.086536Z"}]}
{"channel":"book","type":"update","data":[{"symbol":"ETH/BTC","bids":[],"asks":[{"price":0.05618,"qty":22.16886512}],"checksum":3015018032,"timestamp":"2024-06-01T18:06:01.086658Z"}]}
{"channel":"book","type":"update","data":[{"symbol":"ETH/BTC","bids":[],"asks":[{"price":0.05619,"qty":2.32433842}],"checksum":2013142796,"timestamp":"2024-06-01T18:06:01.298730Z"}]}
{"channel":"book","type":"update","data":[{"symbol":"ETH/BTC","bids":[],"asks":[{"price":0.05619,"qty":2.82964476}],"checksum":3015018032,"timestamp":"2024-06-01T18:06:01.358755Z"}]}
{"channel":"book","type":"update","data":[{"symbol":"ETH/BTC","bids":[{"price":0.05611,"qty":15.61240031}],"asks":[],"checksum":1395597070,"timestamp":"2024-06-01T18:06:01.408285Z"}]}
{"channel":"book","type":"update","data":[{"symbol":"ETH/BTC","bids":[{"price":0.05612,"qty":11.52386431}],"asks":[],"checksum":3412902673,"timestamp":"2024-06-01T18:06:01.413724Z"}]}
{"channel":"book","type":"update","data":[{"symbol":"ETH/BTC","bids":[],"asks":[{"price":0.05619,"qty":2.32433842}],"checksum":3838309391,"timestamp":"2024-06-01T18:06:01.518633Z"}]}
{"channel":"book","type":"update","data":[{"symbol":"ETH/BTC","bids":[],"asks":[{"price":0.05619,"qty":2.82964476}],"checksum":3412902673,"timestamp":"2024-06-01T18:06:01.559596Z"}]}
{"channel":"book","type":"update","data":[{"symbol":"ETH/BTC","bids":[],"asks":[{"price":0.05616,"qty":15.48768210}],"checksum":4276033339,"timestamp":"2024-06-01T18:06:01.620332Z"}]}
{"channel":"book","type":"update","data":[{"symbol":"ETH/BTC","bids":[],"asks":[{"price":0.05618,"qty":15.10230022}],"checksum":2698271896,"timestamp":"2024-06-01T18:06:01.620432Z"}]}
{"channel":"book","type":"update","data":[{"symbol":"ETH/BTC","bids":[],"asks":[{"price":0.05620,"qty":19.14591685}],"checksum":819599479,"timestamp":"2024-06-01T18:06:01.620471Z"}]}
{"channel":"book","type":"update","data":[{"symbol":"ETH/BTC","bids":[],"asks":[{"price":0.05614,"qty":6.24838658}],"checksum":3068184184,"timestamp":"2024-06-01T18:06:01.624705Z"}]}
{"channel":"book","type":"update","data":[{"symbol":"ETH/BTC","bids":[{"price":0.05610,"qty":43.34565245}],"asks":[],"checksum":137114522,"timestamp":"2024-06-01T18:06:01.660636Z"}]}
{"channel":"book","type":"update","data":[{"symbol":"ETH/BTC","bids":[],"asks":[{"price":0.05621,"qty":19.37139275}],"checksum":3027211551,"timestamp":"2024-06-01T18:06:01.660734Z"}]}
{"channel":"book","type":"update","data":[{"symbol":"ETH/BTC","bids":[{"price":0.05610,"qty":30.49624498}],"asks":[],"checksum":1970824659,"timestamp":"2024-06-01T18:06:01.826945Z"}]}
{"channel":"book","type":"update","data":[{"symbol":"ETH/BTC","bids":[{"price":0.05610,"qty":42.11321534}],"asks":[],"checksum":3569986673,"timestamp":"2024-06-01T18:06:01.831822Z"}]}
{"channel":"book","type":"update","data":[{"symbol":"ETH/BTC","bids":[],"asks":[{"price":0.05619,"qty":9.89501185}],"checksum":4275812120,"timestamp":"2024-06-01T18:06:02.333669Z"}]}
{"channel":"book","type":"update","data":[{"symbol":"ETH/BTC","bids":[],"asks":[{"price":0.05621,"qty":19.19206239}],"checksum":2869051105,"timestamp":"2024-06-01T18:06:02.774428Z"}]}
{"channel":"book","type":"update","data":[{"symbol":"ETH/BTC","bids":[],"asks":[{"price":0.05619,"qty":9.27106968}],"checksum":2852025860,"timestamp":"2024-06-01T18:06:02.973805Z"}]}
{"channel":"book","type":"update","data":[{"symbol":"ETH/BTC","bids":[],"asks":[{"price":0.05614,"qty":3.61710556}],"checksum":3318049173,"timestamp":"2024-06-01T18:06:03.518957Z"}]}
{"channel":"book","type":"update","data":[{"symbol":"ETH/BTC","bids":[],"asks":[{"price":0.05615,"qty":18.19831159}],"checksum":738276182,"timestamp":"2024-06-01T18:06:03.524045Z"}]}
{"channel":"book","type":"update","data":[{"symbol":"ETH/BTC","bids":[],"asks":[{"price":0.05619,"qty":9.89501185}],"checksum":788364211,"timestamp":"2024-06-01T18:06:03.582211Z"}]}
{"channel":"book","type":"update","data":[{"symbol":"ETH/BTC","bids":[],"asks":[{"price":0.05619,"qty":9.27106968}],"checksum":738276182,"timestamp":"2024-06-01T18:06:03.716811Z"}]}
{"channel":"book","type":"update","data":[{"symbol":"ETH/BTC","bids":[],"asks":[{"price":0.05619,"qty":9.89501185}],"checksum":788364211,"timestamp":"2024-06-01T18:06:03.783475Z"}]}
{"channel":"book","type":"update","data":[{"symbol":"ETH/BTC","bids":[],"asks":[{"price":0.05619,"qty":9.27106968}],"checksum":738276182,"timestamp":"2024-06-01T18:06:03.884701Z"}]}
{"channel":"book","type":"update","data":[{"symbol":"ETH/BTC","bids":[{"price":0.05612,"qty":12.52386431}],"asks":[],"checksum":2880355686,"timestamp":"2024-06-01T18:06:04.054491Z"}]}
{"channel":"book","type":"update","data":[{"symbol":"ETH/BTC","bids":[{"price":0.05612,"qty":20.41616066}],"asks":[],"checksum":3778706936,"timestamp":"2024-06-01T18:06:04.158577Z"}]}
{"channel":"book","type":"update","data":[{"symbol":"ETH/BTC","bids":[{"price":0.05610,"qty":30.49624498}],"asks":[],"checksum":1082897498,"timestamp":"2024-06-01T18:06:04.562999Z"}]}
{"channel":"book","type":"update","data":[{"symbol":"ETH/BTC","bids":[{"price":0.05612,"qty":12.52386431}],"asks":[],"checksum":169833668,"timestamp":"2024-06-01T18:06:05.976573Z"}]}
{"channel":"book","type":"update","data":[{"symbol":"ETH/BTC","bids":[{"price":0.05612,"qty":20.41615286}],"asks":[],"checksum":1364704304,"timestamp":"2024-06-01T18:06:07.341609Z"}]}
{"channel":"book","type":"update","data":[{"symbol":"ETH/BTC","bids":[],"asks":[{"price":0.05619,"qty":9.89501185}],"checksum":1403778261,"timestamp":"2024-06-01T18:06:08.325681Z"}]}
{"channel":"book","type":"update","data":[{"symbol":"ETH/BTC","bids":[],"asks":[{"price":0.05619,"qty":9.27106968}],"checksum":1364704304,"timestamp":"2024-06-01T18:06:08.671978Z"}]}
{"channel":"book","type":"update","data":[{"symbol":"ETH/BTC","bids":[],"asks":[{"price":0.05614,"qty":4.43270556}],"checksum":283343044,"timestamp":"2024-06-01T18:06:08.741448Z"}]}
{"channel":"book","type":"update","data":[{"symbol":"ETH/BTC","bids":[],"asks":[{"price":0.05615,"qty":15.56766980}],"checksum":4180091399,"timestamp":"2024-06-01T18:06:08.744206Z"}]}
{"channel":"book","type":"update","data":[{"symbol":"ETH/BTC","bids":[],"asks":[{"price":0.05614,"qty":7.06356175}],"checksum":3316933383,"timestamp":"2024-06-01T18:06:08.748495Z"}]}
{"channel":"book","type":"update","data":[{"symbol":"ETH/BTC","bids":[],"asks":[{"price":0.05619,"qty":9.89501185}],"checksum":3343395810,"timestamp":"2024-06-01T18:06:08.880590Z"}]}
{"channel":"book","type":"update","data":[{"symbol":"ETH/BTC","bids":[],"asks":[{"price":0.05619,"qty":9.27106968}],"checksum":3316933383,"timestamp":"2024-06-01T18:06:08.981067Z"}]}
{"channel":"book","type":"update","data":[{"symbol":"ETH/BTC","bids":[],"asks":[{"price":0.05619,"qty":9.89501185}],"checksum":3343395810,"timestamp":"2024-06-01T18:06:09.278029Z"}]}
{"channel":"book","type":"update","data":[{"symbol":"ETH/BTC","bids":[],"asks":[{"price":0.05619,"qty":9.27106968}],"checksum":3316933383,"timestamp":"2024-06-01T18:06:09.385316Z"}]}
{"channel":"book","type":"update","data":[{"symbol":"ETH/BTC","bids":[],"asks":[{"price":0.05619,"qty":9.89501185}],"checksum":3343395810,"timestamp":"2024-06-01T18:06:09.514673Z"}]}
{"channel":"book","type":"update","data":[{"symbol":"ETH/BTC","bids":[],"asks":[{"price":0.05614,"qty":6.24796175}],"checksum":981418449,"timestamp":"2024-06-01T18:06:09.560640Z"}]}
{"channel":"book","type":"update","data":[{"symbol":"ETH/BTC","bids":[],"asks":[{"price":0.05614,"qty":3.61710556}],"checksum":3127881238,"timestamp":"2024-06-01T18:06:09.561522Z"}]}
{"channel":"book","type":"update","data":[{"symbol":"ETH/BTC","bids":[],"asks":[{"price":0.05615,"qty":18.19818331}],"checksum":3015676504,"timestamp":"2024-06-01T18:06:09.567403Z"}]}
{"channel":"book","type":"update","data":[{"symbol":"ETH/BTC","bids":[{"price":0.05612,"qty":12.52386431}],"asks":[],"checksum":3908524716,"timestamp":"2024-06-01T18:06:09.667466Z"}]}
{"channel":"book","type":"update","data":[{"symbol":"ETH/BTC","bids":[],"asks":[{"price":0.05619,"qty":9.38970551}],"checksum":1715793068,"timestamp":"2024-06-01T18:06:09.777901Z"}]}
{"channel":"book","type":"update","data":[{"symbol":"ETH/BTC","bids":[],"asks":[{"price":0.05619,"qty":8.76576334}],"checksum":1660332120,"timestamp":"2024-06-01T18:06:09.780651Z"}]}
{"channel":"book","type":"update","data":[{"symbol":"ETH/BTC","bids":[],"asks":[{"price":0.05619,"qty":9.38970551}],"checksum":1715793068,"timestamp":"2024-06-01T18:06:09.785967Z"}]}
{"channel":"book","type":"update","data":[{"symbol":"ETH/BTC","bids":[],"asks":[{"price":0.05619,"qty":9.89501185}],"checksum":3908524716,"timestamp":"2024-06-01T18:06:09.798987Z"}]}
{"channel":"book","type":"update","data":[{"symbol":"ETH/BTC","bids":[],"asks":[{"price":0.05619,"qty":9.27106968}],"checksum":3926594121,"timestamp":"2024-06-01T18:06:09.903393Z"}]}
{"channel":"book","type":"update","data":[{"symbol":"ETH/BTC","bids":[],"asks":[{"price":0.05619,"qty":9.89501185}],"checksum":3908524716,"timestamp":"2024-06-01T18:06:09.920321Z"}]}
{"channel":"book","type":"update","data":[{"symbol":"ETH/BTC","bids":[],"asks":[{"price":0.05619,"qty":9.27106968}],"checksum":3926594121,"timestamp":"2024-06-01T18:06:10.020237Z"}]}
{"channel":"book","type":"update","data":[{"symbol":"ETH/BTC","bids":[],"asks":[{"price":0.05614,"qty":4.43270556}],"checksum":2881476285,"timestamp":"2024-06-01T18:06:11.158952Z"}]}
{"channel":"book","type":"update","data":[{"symbol":"ETH/BTC","bids":[],"asks":[{"price":0.05614,"qty":3.61710556}],"checksum":3926594121,"timestamp":"2024-06-01T18:06:11.832614Z"}]}
{"channel":"book","type":"update","data":[{"symbol":"ETH/BTC","bids":[{"price":0.05603,"qty":10.11037232}],"asks":[],"checksum":1188229569,"timestamp":"2024-06-01T18:06:11.914053Z"}]}
{"channel":"book","type":"update","data":[{"symbol":"ETH/BTC","bids":[],"asks":[{"price":0.05620,"qty":16.68591685},{"price":0.05621,"qty":21.78206239}],"checksum":2924495687,"timestamp":"2024-06-01T18:06:11.914140Z"}]}
{"channel":"book","type":"update","data":[{"symbol":"ETH/BTC","bids":[],"asks":[{"price":0.05614,"qty":0.98635040}],"checksum":3728103747,"timestamp":"2024-06-01T18:06:11.915981Z"}]}
{"channel":"book","type":"update","data":[{"symbol":"ETH/BTC","bids":[],"asks":[{"price":0.05621,"qty":19.41206239}],"checksum":152040172,"timestamp":"2024-06-01T18:06:11.916166Z"}]}
{"channel":"book","type":"update","data":[{"symbol":"ETH/BTC","bids":[{"price":0.05603,"qty":7.63037232},{"price":0.05605,"qty":14.07027853}],"asks":[],"checksum":2027229200,"timestamp":"2024-06-01T18:06:11.916534Z"}]}
{"channel":"book","type":"update","data":[{"symbol":"ETH/BTC","bids":[],"asks":[{"price":0.05615,"qty":20.82880245}],"checksum":475193937,"timestamp":"2024-06-01T18:06:11.919843Z"}]}
{"channel":"book","type":"update","data":[{"symbol":"ETH/BTC","bids":[{"price":0.05609,"qty":2.12420330}],"asks":[],"checksum":766694596,"timestamp":"2024-06-01T18:06:11.979927Z"}]}
{"channel":"book","type":"update","data":[{"symbol":"ETH/BTC","bids":[{"price":0.05610,"qty":31.48259538}],"asks":[],"checksum":2565507562,"timestamp":"2024-06-01T18:06:11.982973Z"}]}
{"channel":"book","type":"update","data":[{"symbol":"ETH/BTC","bids":[],"asks":[{"price":0.05619,"qty":9.89501185}],"checksum":2585182479,"timestamp":"2024-06-01T18:06:12.006225Z"}]}
{"channel":"book","type":"update","data":[{"symbol":"ETH/BTC","bids":[{"price":0.05608,"qty":4.55656091}],"asks":[],"checksum":3117610690,"timestamp":"2024-06-01T18:06:12.048978Z"}]}
{"channel":"book","type":"update","data":[{"symbol":"ETH/BTC","bids":[{"price":0.05609,"qty":2.30030516}],"asks":[],"checksum":3712954272,"timestamp":"2024-06-01T18:06:12.057080Z"}]}
{"channel":"book","type":"update","data":[{"symbol":"ETH/BTC","bids":[],"asks":[{"price":0.05615,"qty":18.19818331}],"checksum":3116948961,"timestamp":"2024-06-01T18:06:12.064087Z"}]}
{"channel":"book","type":"update","data":[{"symbol":"ETH/BTC","bids":[{"price":0.05605,"qty":13.51429885}],"asks":[],"checksum":1826446317,"timestamp":"2024-06-01T18:06:12.083841Z"}]}
{"channel":"book","type":"update","data":[{"symbol":"ETH/BTC","bids":[{"price":0.05612,"qty":11.52386431}],"asks":[],"checksum":3950171613,"timestamp":"2024-06-01T18:06:12.094075Z"}]}
{"channel":"book","type":"update","data":[{"symbol":"ETH/BTC","bids":[],"asks":[{"price":0.05619,"qty":9.38970551}],"checksum":1707172829,"timestamp":"2024-06-01T18:06:12.118677Z"}]}
{"channel":"book","type":"update","data":[{"symbol":"ETH/BTC","bids":[{"price":0.05606,"qty":15.79268480}],"asks":[],"checksum":2597720077,"timestamp":"2024-06-01T18:06:12.147974Z"}]}
{"channel":"book","type":"update","data":[{"symbol":"ETH/BTC","bids":[],"asks":[{"price":0.05620,"qty":17.19122319}],"checksum":2295381551,"timestamp":"2024-06-01T18:06:12.197271Z"}]}
{"channel":"book","type":"update","data":[{"symbol":"ETH/BTC","bids":[],"asks":[{"price":0.05615,"qty":15.56766980}],"checksum":2164294241,"timestamp":"2024-06-01T18:06:12.225574Z"}]}
{"channel":"book","type":"update","data":[{"symbol":"ETH/BTC","bids":[],"asks":[{"price":0.05615,"qty":18.19796834}],"checksum":79368906,"timestamp":"2024-06-01T18:06:12.250857Z"}]}
{"channel":"book","type":"update","data":[{"symbol":"ETH/BTC","bids":[{"price":0.05612,"qty":19.41543835}],"asks":[],"checksum":119603718,"timestamp":"2024-06-01T18:06:12.321956Z"}]}
{"channel":"book","type":"update","data":[{"symbol":"ETH/BTC","bids":[],"asks":[{"price":0.05620,"qty":16.68591685}],"checksum":354921508,"timestamp":"2024-06-01T18:06:12.458244Z"}]}
{"channel":"book","type":"update","data":[{"symbol":"ETH/BTC","bids":[],"asks":[{"price":0.05619,"qty":9.89501185}],"checksum":2610174500,"timestamp":"2024-06-01T18:06:12.518667Z"}]}
{"channel":"book","type":"update","data":[{"symbol":"ETH/BTC","bids":[],"asks":[{"price":0.05615,"qty":20.82837804}],"checksum":3429304382,"timestamp":"2024-06-01T18:06:12.570573Z"}]}
{"channel":"book","type":"update","data":[{"symbol":"ETH/BTC","bids":[],"asks":[{"price":0.05613,"qty":0.00000000},{"price":0.05623,"qty":2.94722350},{"price":0.05613,"qty":0.02038573}],"checksum":4026913294,"timestamp":"2024-06-01T18:06:12.794167Z"}]}
{"channel":"book","type":"update","data":[{"symbol":"ETH/BTC","bids":[],"asks":[{"price":0.05615,"qty":18.19796834}],"checksum":2817966100,"timestamp":"2024-06-01T18:06:13.711474Z"}]}
{"channel":"book","type":"update","data":[{"symbol":"ETH/BTC","bids":[],"asks":[{"price":0.05614,"qty":3.61682331}],"checksum":3428020997,"timestamp":"2024-06-01T18:06:13.715485Z"}]}
{"channel":"book","type":"update","data":[{"symbol":"ETH/BTC","bids":[],"asks":[{"price":0.05614,"qty":4.43242331}],"checksum":90891845,"timestamp":"2024-06-01T18:06:13.720438Z"}]}
{"channel":"book","type":"update","data":[{"symbol":"ETH/BTC","bids":[{"price":0.05606,"qty":24.96268480}],"asks":[],"checksum":3059189763,"timestamp":"2024-06-01T18:06:15.258839Z"}]}
{"channel":"book","type":"update","data":[{"symbol":"ETH/BTC","bids":[],"asks":[{"price":0.05615,"qty":15.56766980}],"checksum":871110824,"timestamp":"2024-06-01T18:06:15.293768Z"}]}
{"channel":"book","type":"update","data":[{"symbol":"ETH/BTC","bids":[],"asks":[{"price":0.05614,"qty":7.06300180}],"checksum":3081383306,"timestamp":"2024-06-01T18:06:15.299806Z"}]}
{"channel":"book","type":"update","data":[{"symbol":"ETH/BTC","bids":[{"price":0.05605,"qty":5.18429885}],"asks":[],"checksum":3777102545,"timestamp":"2024-06-01T18:06:15.350994Z"}]}
{"channel":"book","type":"update","data":[{"symbol":"ETH/BTC","bids":[{"price":0.05607,"qty":16.60869553}],"asks":[],"checksum":730976724,"timestamp":"2024-06-01T18:06:15.431021Z"}]}
{"channel":"book","type":"update","data":[{"symbol":"ETH/BTC","bids":[{"price":0.05612,"qty":11.52386431}],"asks":[],"checksum":123933014,"timestamp":"2024-06-01T18:06:15.431095Z"}]}
{"channel":"book","type":"update","data":[{"symbol":"ETH/BTC","bids":[{"price":0.05606,"qty":38.11545910}],"asks":[],"checksum":3435998499,"timestamp":"2024-06-01T18:06:15.471333Z"}]}
{"channel":"book","type":"update","data":[{"symbol":"ETH/BTC","bids":[],"asks":[{"price":0.05614,"qty":6.07665140}],"checksum":168752896,"timestamp":"2024-06-01T18:06:15.557580Z"}]}
{"channel":"book","type":"update","data":[{"symbol":"ETH/BTC","bids":[],"asks":[{"price":0.05615,"qty":16.55402020}],"checksum":3570939177,"timestamp":"2024-06-01T18:06:15.560101Z"}]}
{"channel":"book","type":"update","data":[{"symbol":"ETH/BTC","bids":[{"price":0.05604,"qty":8.90861902}],"asks":[],"checksum":1523648068,"timestamp":"2024-06-01T18:06:16.164503Z"}]}
{"channel":"book","type":"update","data":[{"symbol":"ETH/BTC","bids":[{"price":0.05605,"qty":28.29319720}],"asks":[],"checksum":1531780151,"timestamp":"2024-06-01T18:06:16.204813Z"}]}
{"channel":"book","type":"update","data":[{"symbol":"ETH/BTC","bids":[],"asks":[{"price":0.05619,"qty":2.82964476}],"checksum":645784012,"timestamp":"2024-06-01T18:06:16.823479Z"}]}
{"channel":"book","type":"update","data":[{"symbol":"ETH/BTC","bids":[{"price":0.05612,"qty":19.41566121}],"asks":[],"checksum":2045864646,"timestamp":"2024-06-01T18:06:18.701347Z"}]}
{"channel":"book","type":"update","data":[{"symbol":"ETH/BTC","bids":[{"price":0.05612,"qty":16.78382246}],"asks":[],"checksum":4125176936,"timestamp":"2024-06-01T18:06:20.254563Z"}]}
{"channel":"book","type":"update","data":[{"symbol":"ETH/BTC","bids":[{"price":0.05611,"qty":18.24401568}],"asks":[],"checksum":3452504434,"timestamp":"2024-06-01T18:06:20.258755Z"}]}
{"channel":"book","type":"update","data":[{"symbol":"ETH/BTC","bids":[{"price":0.05612,"qty":14.15198371}],"asks":[],"checksum":1054110452,"timestamp":"2024-06-01T18:06:20.335320Z"}]}
{"channel":"book","type":"update","data":[{"symbol":"ETH/BTC","bids":[],"asks":[{"price":0.05615,"qty":17.45730341}],"checksum":3867246523,"timestamp":"2024-06-01T18:06:20.341855Z"}]}
{"channel":"book","type":"update","data":[{"symbol":"ETH/BTC","bids":[{"price":0.05610,"qty":25.48259538}],"asks":[],"checksum":3377522810,"timestamp":"2024-06-01T18:06:20.342614Z"}]}
{"channel":"book","type":"update","data":[{"symbol":"ETH/BTC","bids":[],"asks":[{"price":0.05616,"qty":21.48768210}],"checksum":2452968739,"timestamp":"2024-06-01T18:06:20.342641Z"}]}
{"channel":"book","type":"update","data":[{"symbol":"ETH/BTC","bids":[{"price":0.05609,"qty":8.30030516}],"asks":[],"checksum":4206337888,"timestamp":"2024-06-01T18:06:20.342728Z"}]}
{"channel":"book","type":"update","data":[{"symbol":"ETH/BTC","bids":[],"asks":[{"price":0.05619,"qty":2.32433842}],"checksum":3575425150,"timestamp":"2024-06-01T18:06:20.351877Z"}]}
{"channel":"book","type":"update","data":[{"symbol":"ETH/BTC","bids":[],"asks":[{"price":0.05616,"qty":22.17468210}],"checksum":1387593960,"timestamp":"2024-06-01T18:06:20.387166Z"}]}
{"channel":"book","type":"update","data":[{"symbol":"ETH/BTC","bids":[],"asks":[{"price":0.05617,"qty":1.67653358}],"checksum":2509461830,"timestamp":"2024-06-01T18:06:20.393415Z"}]}
{"channel":"book","type":"update","data":[{"symbol":"ETH/BTC","bids":[{"price":0.05609,"qty":8.11066952}],"asks":[],"checksum":716612576,"timestamp":"2024-06-01T18:06:20.415963Z"}]}
{"channel":"book","type":"update","data":[{"symbol":"ETH/BTC","bids":[{"price":0.05605,"qty":5.18429885}],"asks":[],"checksum":283858944,"timestamp":"2024-06-01T18:06:20.489182Z"}]}
{"channel":"book","type":"update","data":[{"symbol":"ETH/BTC","bids":[{"price":0.05610,"qty":14.95921064}],"asks":[],"checksum":2473772863,"timestamp":"2024-06-01T18:06:20.489249Z"}]}
{"channel":"book","type":"update","data":[{"symbol":"ETH/BTC","bids":[{"price":0.05612,"qty":6.26018681}],"asks":[],"checksum":434904989,"timestamp":"2024-06-01T18:06:20.489348Z"}]}
{"channel":"book","type":"update","data":[{"symbol":"ETH/BTC","bids":[],"asks":[{"price":0.05620,"qty":16.86527912}],"checksum":1688928898,"timestamp":"2024-06-01T18:06:20.497026Z"}]}
{"channel":"book","type":"update","data":[{"symbol":"ETH/BTC","bids":[{"price":0.05610,"qty":15.86249385}],"asks":[],"checksum":2872468843,"timestamp":"2024-06-01T18:06:20.498078Z"}]}
{"channel":"book","type":"update","data":[{"symbol":"ETH/BTC","bids":[{"price":0.05611,"qty":17.34073247}],"asks":[],"checksum":1854193410,"timestamp":"2024-06-01T18:06:20.498278Z"}]}
{"channel":"book","type":"update","data":[{"symbol":"ETH/BTC","bids":[],"asks":[{"price":0.05618,"qty":15.60760656}],"checksum":2465325849,"timestamp":"2024-06-01T18:06:20.501730Z"}]}
{"channel":"book","type":"update","data":[{"symbol":"ETH/BTC","bids":[],"asks":[{"price":0.05620,"qty":16.68591685}],"checksum":4021747206,"timestamp":"2024-06-01T18:06:20.515839Z"}]}
{"channel":"book","type":"update","data":[{"symbol":"ETH/BTC","bids":[],"asks":[{"price":0.05622,"qty":3.74873085}],"checksum":2596174565,"timestamp":"2024-06-01T18:06:20.516342Z"}]}
{"channel":"book","type":"update","data":[{"symbol":"ETH/BTC","bids":[{"price":0.05604,"qty":32.02020006}],"asks":[],"checksum":1506341318,"timestamp":"2024-06-01T18:06:20.529530Z"}]}
{"channel":"book","type":"update","data":[{"symbol":"ETH/BTC","bids":[],"asks":[{"price":0.05618,"qty":22.40204635}],"checksum":3560293227,"timestamp":"2024-06-01T18:06:20.529570Z"}]}
{"channel":"book","type":"update","data":[{"symbol":"ETH/BTC","bids":[{"price":0.05606,"qty":37.55957860}],"asks":[],"checksum":3934810951,"timestamp":"2024-06-01T18:06:20.557722Z"}]}
{"channel":"book","type":"update","data":[{"symbol":"ETH/BTC","bids":[],"asks":[{"price":0.05622,"qty":3.54156000}],"checksum":3556689921,"timestamp":"2024-06-01T18:06:20.631347Z"}]}
{"channel":"book","type":"update","data":[{"symbol":"ETH/BTC","bids":[],"asks":[{"price":0.05622,"qty":3.72085847}],"checksum":1898469918,"timestamp":"2024-06-01T18:06:20.631783Z"}]}
{"channel":"book","type":"update","data":[{"symbol":"ETH/BTC","bids":[],"asks":[{"price":0.05622,"qty":3.54156000}],"checksum":3556689921,"timestamp":"2024-06-01T18:06:20.649484Z"}]}
{"channel":"book","type":"update","data":[{"symbol":"ETH/BTC","bids":[],"asks":[{"price":0.05620,"qty":16.86527912}],"checksum":1586201321,"timestamp":"2024-06-01T18:06:20.649651Z"}]}
{"channel":"book","type":"update","data":[{"symbol":"ETH/BTC","bids":[{"price":0.05605,"qty":5.74027853}],"asks":[],"checksum":3935974408,"timestamp":"2024-06-01T18:06:20.664740Z"}]}
{"channel":"book","type":"update","data":[{"symbol":"ETH/BTC","bids":[],"asks":[{"price":0.05619,"qty":1.44533842}],"checksum":1651156352,"timestamp":"2024-06-01T18:06:20.889141Z"}]}
{"channel":"book","type":"update","data":[{"symbol":"ETH/BTC","bids":[],"asks":[{"price":0.05614,"qty":3.44607291}],"checksum":593982094,"timestamp":"2024-06-01T18:06:20.917019Z"}]}
{"channel":"book","type":"update","data":[{"symbol":"ETH/BTC","bids":[],"asks":[{"price":0.05616,"qty":9.02499535}],"checksum":688824479,"timestamp":"2024-06-01T18:06:20.917122Z"}]}
{"channel":"book","type":"update","data":[{"symbol":"ETH/BTC","bids":[],"asks":[{"price":0.05620,"qty":16.68591685}],"checksum":2759584375,"timestamp":"2024-06-01T18:06:20.921489Z"}]}
{"channel":"book","type":"update","data":[{"symbol":"ETH/BTC","bids":[],"asks":[{"price":0.05622,"qty":3.74873085}],"checksum":2634895665,"timestamp":"2024-06-01T18:06:20.921976Z"}]}
{"channel":"book","type":"update","data":[{"symbol":"ETH/BTC","bids":[],"asks":[{"price":0.05615,"qty":30.61012586}],"checksum":1100296347,"timestamp":"2024-06-01T18:06:20.922340Z"}]}
{"channel":"book","type":"update","data":[{"symbol":"ETH/BTC","bids":[{"price":0.05611,"qty":19.97255303}],"asks":[],"checksum":3348140595,"timestamp":"2024-06-01T18:06:20.922364Z"}]}
{"channel":"book","type":"update","data":[{"symbol":"ETH/BTC","bids":[],"asks":[{"price":0.05613,"qty":2.65145456}],"checksum":1872525303,"timestamp":"2024-06-01T18:06:20.922393Z"}]}
{"channel":"book","type":"update","data":[{"symbol":"ETH/BTC","bids":[],"asks":[{"price":0.05620,"qty":16.86527912}],"checksum":3806936351,"timestamp":"2024-06-01T18:06:20.936535Z"}]}
{"channel":"book","type":"update","data":[{"symbol":"ETH/BTC","bids":[],"asks":[{"price":0.05622,"qty":3.54156000}],"checksum":3684664921,"timestamp":"2024-06-01T18:06:20.936559Z"}]}
{"channel":"book","type":"update","data":[{"symbol":"ETH/BTC","bids":[{"price":0.05611,"qty":6.81103593}],"asks":[],"checksum":2785291100,"timestamp":"2024-06-01T18:06:20.938584Z"}]}
{"channel":"book","type":"update","data":[{"symbol":"ETH/BTC","bids":[{"price":0.05609,"qty":21.27521134}],"asks":[],"checksum":4174857733,"timestamp":"2024-06-01T18:06:20.942260Z"}]}
{"channel":"book","type":"update","data":[{"symbol":"ETH/BTC","bids":[],"asks":[{"price":0.05620,"qty":16.68591685}],"checksum":1973554413,"timestamp":"2024-06-01T18:06:20.953964Z"}]}
{"channel":"book","type":"update","data":[{"symbol":"ETH/BTC","bids":[],"asks":[{"price":0.05622,"qty":3.74873085}],"checksum":1289009067,"timestamp":"2024-06-01T18:06:20.954411Z"}]}
{"channel":"book","type":"update","data":[{"symbol":"ETH/BTC","bids":[{"price":0.05609,"qty":21.09910948}],"asks":[],"checksum":1981851927,"timestamp":"2024-06-01T18:06:21.001723Z"}]}
{"channel":"book","type":"update","data":[{"symbol":"ETH/BTC","bids":[],"asks":[{"price":0.05620,"qty":16.86527912}],"checksum":4216710143,"timestamp":"2024-06-01T18:06:21.038297Z"}]}
{"channel":"book","type":"update","data":[{"symbol":"ETH/BTC","bids":[],"asks":[{"price":0.05622,"qty":3.54156000}],"checksum":3257096377,"timestamp":"2024-06-01T18:06:21.038321Z"}]}
{"channel":"book","type":"update","data":[{"symbol":"ETH/BTC","bids":[],"asks":[{"price":0.05620,"qty":16.68591685}],"checksum":1331040849,"timestamp":"2024-06-01T18:06:21.063616Z"}]}
{"channel":"book","type":"update","data":[{"symbol":"ETH/BTC","bids":[],"asks":[{"price":0.05622,"qty":3.74873085}],"checksum":1981851927,"timestamp":"2024-06-01T18:06:21.063973Z"}]}
{"channel":"book","type":"update","data":[{"symbol":"ETH/BTC","bids":[],"asks":[{"price":0.05622,"qty":3.54156000}],"checksum":1331040849,"timestamp":"2024-06-01T18:06:21.135215Z"}]}
{"channel":"book","type":"update","data":[{"symbol":"ETH/BTC","bids":[],"asks":[{"price":0.05620,"qty":16.86527912}],"checksum":3257096377,"timestamp":"2024-06-01T18:06:21.135672Z"}]}
{"channel":"book","type":"update","data":[{"symbol":"ETH/BTC","bids":[{"price":0.05611,"qty":14.70381571}],"asks":[],"checksum":2305077552,"timestamp":"2024-06-01T18:06:21.187080Z"}]}
{"channel":"book","type":"update","data":[{"symbol":"ETH/BTC","bids":[{"price":0.05607,"qty":27.13240190}],"asks":[],"checksum":844603021,"timestamp":"2024-06-01T18:06:21.187247Z"}]}
{"channel":"book","type":"update","data":[{"symbol":"ETH/BTC","bids":[],"asks":[{"price":0.05620,"qty":16.68591685}],"checksum":2617999757,"timestamp":"2024-06-01T18:06:21.394336Z"}]}
{"channel":"book","type":"update","data":[{"symbol":"ETH/BTC","bids":[],"asks":[{"price":0.05622,"qty":3.74873085}],"checksum":59577235,"timestamp":"2024-06-01T18:06:21.395663Z"}]}
{"channel":"book","type":"update","data":[{"symbol":"ETH/BTC","bids":[{"price":0.05612,"qty":5.44458681}],"asks":[],"checksum":1066556411,"timestamp":"2024-06-01T18:06:21.399066Z"}]}
{"channel":"book","type":"update","data":[{"symbol":"ETH/BTC","bids":[{"price":0.05612,"qty":6.26018681}],"asks":[],"checksum":59577235,"timestamp":"2024-06-01T18:06:21.412346Z"}]}
{"channel":"book","type":"update","data":[{"symbol":"ETH/BTC","bids":[],"asks":[{"price":0.05622,"qty":3.54156000}],"checksum":2617999757,"timestamp":"2024-06-01T18:06:21.414475Z"}]}
{"channel":"book","type":"update","data":[{"symbol":"ETH/BTC","bids":[],"asks":[{"price":0.05620,"qty":16.86527912}],"checksum":844603021,"timestamp":"2024-06-01T18:06:21.414574Z"}]}
{"channel":"book","type":"update","data":[{"symbol":"ETH/BTC","bids":[],"asks":[{"price":0.05620,"qty":16.68591685}],"checksum":2617999757,"timestamp":"2024-06-01T18:06:21.435755Z"}]}
{"channel":"book","type":"update","data":[{"symbol":"ETH/BTC","bids":[],"asks":[{"price":0.05622,"qty":3.74873085}],"checksum":59577235,"timestamp":"2024-06-01T18:06:21.436139Z"}]}
{"channel":"book","type":"update","data":[{"symbol":"ETH/BTC","bids":[{"price":0.05610,"qty":14.87614345}],"asks":[],"checksum":3521351415,"timestamp":"2024-06-01T18:06:21.465558Z"}]}
{"channel":"book","type":"update","data":[{"symbol":"ETH/BTC","bids":[],"asks":[{"price":0.05615,"qty":29.62377546}],"checksum":1215850383,"timestamp":"2024-06-01T18:06:21.465593Z"}]}
{"channel":"book","type":"update","data":[{"symbol":"ETH/BTC","bids":[],"asks":[{"price":0.05614,"qty":4.43242331}],"checksum":3492043622,"timestamp":"2024-06-01T18:06:21.468246Z"}]}
{"channel":"book","type":"update","data":[{"symbol":"ETH/BTC","bids":[{"price":0.05609,"qty":22.08545988}],"asks":[],"checksum":1580264519,"timestamp":"2024-06-01T18:06:21.468561Z"}]}
{"channel":"book","type":"update","data":[{"symbol":"ETH/BTC","bids":[{"price":0.05604,"qty":31.86880006}],"asks":[],"checksum":393444130,"timestamp":"2024-06-01T18:06:21.544463Z"}]}
{"channel":"book","type":"update","data":[{"symbol":"ETH/BTC","bids":[{"price":0.05608,"qty":4.35716000}],"asks":[],"checksum":541311305,"timestamp":"2024-06-01T18:06:21.547036Z"}]}
{"channel":"book","type":"update","data":[{"symbol":"ETH/BTC","bids":[],"asks":[{"price":0.05621,"qty":19.27076239}],"checksum":2951490047,"timestamp":"2024-06-01T18:06:21.550387Z"}]}
{"channel":"book","type":"update","data":[{"symbol":"ETH/BTC","bids":[{"price":0.05612,"qty":5.44458681}],"asks":[],"checksum":2482200983,"timestamp":"2024-06-01T18:06:21.553272Z"}]}
{"channel":"book","type":"update","data":[{"symbol":"ETH/BTC","bids":[],"asks":[{"price":0.05618,"qty":21.89674001}],"checksum":3963003909,"timestamp":"2024-06-01T18:06:21.553475Z"}]}
{"channel":"book","type":"update","data":[{"symbol":"ETH/BTC","bids":[{"price":0.05605,"qty":4.95357853}],"asks":[],"checksum":3100924240,"timestamp":"2024-06-01T18:06:21.559509Z"}]}
{"channel":"book","type":"update","data":[{"symbol":"ETH/BTC","bids":[{"price":0.05612,"qty":4.62898681}],"asks":[],"checksum":1943432979,"timestamp":"2024-06-01T18:06:21.561917Z"}]}
{"channel":"book","type":"update","data":[{"symbol":"ETH/BTC","bids":[{"price":0.05605,"qty":4.88307853}],"asks":[],"checksum":1978727748,"timestamp":"2024-06-01T18:06:21.574435Z"}]}
{"channel":"book","type":"update","data":[{"symbol":"ETH/BTC","bids":[],"asks":[{"price":0.05620,"qty":16.61491685}],"checksum":3682279174,"timestamp":"2024-06-01T18:06:21.577205Z"}]}
{"channel":"book","type":"update","data":[{"symbol":"ETH/BTC","bids":[{"price":0.05603,"qty":7.49537232}],"asks":[],"checksum":1843648134,"timestamp":"2024-06-01T18:06:21.582232Z"}]}
{"channel":"book","type":"update","data":[{"symbol":"ETH/BTC","bids":[],"asks":[{"price":0.05621,"qty":19.12376239}],"checksum":1932472170,"timestamp":"2024-06-01T18:06:21.609762Z"}]}
{"channel":"book","type":"update","data":[{"symbol":"ETH/BTC","bids":[{"price":0.05611,"qty":6.81103593}],"asks":[],"checksum":2599823964,"timestamp":"2024-06-01T18:06:21.679940Z"}]}
{"channel":"book","type":"update","data":[{"symbol":"ETH/BTC","bids":[{"price":0.05607,"qty":16.60869553}],"asks":[],"checksum":566560225,"timestamp":"2024-06-01T18:06:21.679982Z"}]}
{"channel":"book","type":"update","data":[{"symbol":"ETH/BTC","bids":[{"price":0.05612,"qty":4.07898681}],"asks":[],"checksum":2578582405,"timestamp":"2024-06-01T18:06:21.682763Z"}]}
{"channel":"book","type":"update","data":[{"symbol":"ETH/BTC","bids":[{"price":0.05609,"qty":32.60942551}],"asks":[],"checksum":2560753806,"timestamp":"2024-06-01T18:06:21.720074Z"}]}
{"channel":"book","type":"update","data":[{"symbol":"ETH/BTC","bids":[],"asks":[{"price":0.05618,"qty":22.40204635}],"checksum":929704386,"timestamp":"2024-06-01T18:06:21.807900Z"}]}
{"channel":"book","type":"update","data":[{"symbol":"ETH/BTC","bids":[],"asks":[{"price":0.05622,"qty":3.54156000}],"checksum":236753540,"timestamp":"2024-06-01T18:06:21.966094Z"}]}
{"channel":"book","type":"update","data":[{"symbol":"ETH/BTC","bids":[],"asks":[{"price":0.05620,"qty":16.79427912}],"checksum":717048229,"timestamp":"2024-06-01T18:06:21.966265Z"}]}
{"channel":"book","type":"update","data":[{"symbol":"ETH/BTC","bids":[{"price":0.05612,"qty":4.89458681}],"asks":[],"checksum":2977752924,"timestamp":"2024-06-01T18:06:22.133556Z"}]}
{"channel":"book","type":"update","data":[{"symbol":"ETH/BTC","bids":[],"asks":[{"price":0.05620,"qty":16.61491685}],"checksum":2514304125,"timestamp":"2024-06-01T18:06:22.217805Z"}]}
{"channel":"book","type":"update","data":[{"symbol":"ETH/BTC","bids":[],"asks":[{"price":0.05621,"qty":19.33093324}],"checksum":2986230394,"timestamp":"2024-06-01T18:06:22.217915Z"}]}
{"channel":"book","type":"update","data":[{"symbol":"ETH/BTC","bids":[],"asks":[{"price":0.05621,"qty":19.47893324}],"checksum":2781669700,"timestamp":"2024-06-01T18:06:22.620167Z"}]}
{"channel":"book","type":"update","data":[{"symbol":"ETH/BTC","bids":[{"price":0.05603,"qty":7.63527232}],"asks":[],"checksum":2130286791,"timestamp":"2024-06-01T18:06:22.626169Z"}]}
{"channel":"book","type":"update","data":[{"symbol":"ETH/BTC","bids":[{"price":0.05603,"qty":7.77207232}],"asks":[],"checksum":567926674,"timestamp":"2024-06-01T18:06:22.636862Z"}]}
{"channel":"book","type":"update","data":[{"symbol":"ETH/BTC","bids":[],"asks":[{"price":0.05619,"qty":1.52483842}],"checksum":2086793133,"timestamp":"2024-06-01T18:06:22.652886Z"}]}
{"channel":"book","type":"update","data":[{"symbol":"ETH/BTC","bids":[],"asks":[{"price":0.05620,"qty":16.76941685}],"checksum":1775136908,"timestamp":"2024-06-01T18:06:22.654310Z"}]}
{"channel":"book","type":"update","data":[{"symbol":"ETH/BTC","bids":[{"price":0.05604,"qty":32.65470006}],"asks":[],"checksum":979773625,"timestamp":"2024-06-01T18:06:22.654556Z"}]}
{"channel":"book","type":"update","data":[{"symbol":"ETH/BTC","bids":[{"price":0.05604,"qty":32.72810006}],"asks":[],"checksum":2857214294,"timestamp":"2024-06-01T18:06:22.662476Z"}]}
{"channel":"book","type":"update","data":[{"symbol":"ETH/BTC","bids":[],"asks":[{"price":0.05621,"qty":19.27176239}],"checksum":1546705273,"timestamp":"2024-06-01T18:06:22.977949Z"}]}
{"channel":"book","type":"update","data":[{"symbol":"ETH/BTC","bids":[],"asks":[{"price":0.05620,"qty":16.94877912}],"checksum":1076685680,"timestamp":"2024-06-01T18:06:22.978143Z"}]}
{"channel":"book","type":"update","data":[{"symbol":"ETH/BTC","bids":[],"asks":[{"price":0.05620,"qty":16.76941685}],"checksum":1546705273,"timestamp":"2024-06-01T18:06:23.008097Z"}]}
{"channel":"book","type":"update","data":[{"symbol":"ETH/BTC","bids":[],"asks":[{"price":0.05621,"qty":19.47893324}],"checksum":2857214294,"timestamp":"2024-06-01T18:06:23.008660Z"}]}
{"channel":"book","type":"update","data":[{"symbol":"ETH/BTC","bids":[{"price":0.05612,"qty":5.71018681}],"asks":[],"checksum":133845193,"timestamp":"2024-06-01T18:06:23.062206Z"}]}
{"channel":"book","type":"update","data":[{"symbol":"ETH/BTC","bids":[],"asks":[{"price":0.05620,"qty":16.94877912}],"checksum":468083392,"timestamp":"2024-06-01T18:06:23.099323Z"}]}
{"channel":"book","type":"update","data":[{"symbol":"ETH/BTC","bids":[],"asks":[{"price":0.05621,"qty":19.27176239}],"checksum":3986365167,"timestamp":"2024-06-01T18:06:23.099466Z"}]}
{"channel":"book","type":"update","data":[{"symbol":"ETH/BTC","bids":[{"price":0.05612,"qty":4.89458681}],"asks":[],"checksum":1076685680,"timestamp":"2024-06-01T18:06:23.720159Z"}]}
{"channel":"book","type":"update","data":[{"symbol":"ETH/BTC","bids":[{"price":0.05612,"qty":4.07898681}],"asks":[],"checksum":3689760137,"timestamp":"2024-06-01T18:06:23.727034Z"}]}
{"channel":"book","type":"update","data":[{"symbol":"ETH/BTC","bids":[],"asks":[{"price":0.05620,"qty":16.76941685}],"checksum":3354490752,"timestamp":"2024-06-01T18:06:23.749495Z"}]}
{"channel":"book","type":"update","data":[{"symbol":"ETH/BTC","bids":[],"asks":[{"price":0.05622,"qty":3.74873085}],"checksum":4270312646,"timestamp":"2024-06-01T18:06:23.749991Z"}]}
{"channel":"book","type":"update","data":[{"symbol":"ETH/BTC","bids":[],"asks":[{"price":0.05622,"qty":3.54156000}],"checksum":3354490752,"timestamp":"2024-06-01T18:06:23.767121Z"}]}
{"channel":"book","type":"update","data":[{"symbol":"ETH/BTC","bids":[],"asks":[{"price":0.05620,"qty":16.94877912}],"checksum":3689760137,"timestamp":"2024-06-01T18:06:23.767434Z"}]}
{"channel":"book","type":"update","data":[{"symbol":"ETH/BTC","bids":[],"asks":[{"price":0.05615,"qty":16.47095301}],"checksum":4063623152,"timestamp":"2024-06-01T18:06:23.812526Z"}]}
{"channel":"book","type":"update","data":[{"symbol":"ETH/BTC","bids":[],"asks":[{"price":0.05614,"qty":17.58569072}],"checksum":1777118192,"timestamp":"2024-06-01T18:06:23.817140Z"}]}
{"channel":"book","type":"update","data":[{"symbol":"ETH/BTC","bids":[],"asks":[{"price":0.05620,"qty":16.76941685}],"checksum":1978702329,"timestamp":"2024-06-01T18:06:23.824058Z"}]}
{"channel":"book","type":"update","data":[{"symbol":"ETH/BTC","bids":[],"asks":[{"price":0.05622,"qty":3.74873085}],"checksum":1283859135,"timestamp":"2024-06-01T18:06:23.824248Z"}]}
{"channel":"book","type":"update","data":[{"symbol":"ETH/BTC","bids":[],"asks":[{"price":0.05618,"qty":21.89674001}],"checksum":3813542899,"timestamp":"2024-06-01T18:06:23.852570Z"}]}
{"channel":"book","type":"update","data":[{"symbol":"ETH/BTC","bids":[],"asks":[{"price":0.05618,"qty":22.40204635}],"checksum":1283859135,"timestamp":"2024-06-01T18:06:23.900769Z"}]}
{"channel":"book","type":"update","data":[{"symbol":"ETH/BTC","bids":[],"asks":[{"price":0.05622,"qty":3.54156000}],"checksum":1978702329,"timestamp":"2024-06-01T18:06:24.488176Z"}]}
{"channel":"book","type":"update","data":[{"symbol":"ETH/BTC","bids":[],"asks":[{"price":0.05620,"qty":16.97658770}],"checksum":3685336660,"timestamp":"2024-06-01T18:06:24.488400Z"}]}
{"channel":"book","type":"update","data":[{"symbol":"ETH/BTC","bids":[],"asks":[{"price":0.05614,"qty":14.95521781}],"checksum":3984756618,"timestamp":"2024-06-01T18:06:25.449901Z"}]}
{"channel":"book","type":"update","data":[{"symbol":"ETH/BTC","bids":[],"asks":[{"price":0.05620,"qty":16.76941685}],"checksum":1138479143,"timestamp":"2024-06-01T18:06:25.453466Z"}]}
