{"channel":"book","type":"snapshot","data":[{"symbol":"ETH/CAD","bids":[{"price":5187.95,"qty":0.58849631},{"price":5187.94,"qty":1.03345202},{"price":5187.93,"qty":0.06653500},{"price":5187.92,"qty":0.90311190},{"price":5185.42,"qty":0.58888836},{"price":5184.44,"qty":0.00526258},{"price":5184.43,"qty":5.66035737},{"price":5184.42,"qty":0.92000000},{"price":5183.80,"qty":1.31700000},{"price":5183.79,"qty":2.21000000}],"asks":[{"price":5190.93,"qty":0.68092083},{"price":5190.94,"qty":0.90311190},{"price":5190.96,"qty":0.31150369},{"price":5191.17,"qty":7.75876673},{"price":5191.28,"qty":0.06651200},{"price":5193.03,"qty":0.12600000},{"price":5194.49,"qty":1.31700000},{"price":5194.50,"qty":1.84146195},{"price":5195.31,"qty":0.12100000},{"price":5196.69,"qty":0.20717085}],"checksum":3954718742}]}
{"channel":"book","type":"update","data":[{"symbol":"ETH/CAD","bids":[],"asks":[{"price":5190.96,"qty":0.00000000},{"price":5196.70,"qty":12.40818836},{"price":5190.92,"qty":0.31150369}],"checksum":3630026053,"timestamp":"2024-06-01T18:06:00.433960Z"}]}
{"channel":"book","type":"update","data":[{"symbol":"ETH/CAD","bids":[{"price":5187.96,"qty":0.90311190}],"asks":[],"checksum":1862357549,"timestamp":"2024-06-01T18:06:00.439967Z"}]}
{"channel":"book","type":"update","data":[{"symbol":"ETH/CAD","bids":[{"price":5187.95,"qty":0.00000000},{"price":5183.79,"qty":2.21000000},{"price":5187.97,"qty":0.58849631}],"asks":[],"checksum":1019383635,"timestamp":"2024-06-01T18:06:00.464981Z"}]}
{"channel":"book","type":"update","data":[{"symbol":"ETH/CAD","bids":[{"price":5187.92,"qty":0.00000000},{"price":5183.79,"qty":2.21000000}],"asks":[],"checksum":326260897,"timestamp":"2024-06-01T18:06:00.471101Z"}]}
{"channel":"book","type":"update","data":[{"symbol":"ETH/CAD","bids":[],"asks":[{"price":5190.93,"qty":0.00000000},{"price":5196.70,"qty":12.40818836},{"price":5190.91,"qty":0.68092102}],"checksum":3032002835,"timestamp":"2024-06-01T18:06:00.497556Z"}]}
{"channel":"book","type":"update","data":[{"symbol":"ETH/CAD","bids":[{"price":5187.94,"qty":0.00000000},{"price":5183.39,"qty":1.84146195},{"price":5187.97,"qty":1.62194282}],"asks":[],"checksum":968527780,"timestamp":"2024-06-01T18:06:00.497619Z"}]}
{"channel":"book","type":"update","data":[{"symbol":"ETH/CAD","bids":[{"price":5187.97,"qty":1.03344651},{"price":5187.98,"qty":0.58849631}],"asks":[],"checksum":3997408620,"timestamp":"2024-06-01T18:06:00.982729Z"}]}
{"channel":"book","type":"update","data":[{"symbol":"ETH/CAD","bids":[{"price":5185.42,"qty":0.00000000},{"price":5183.39,"qty":1.84146195}],"asks":[],"checksum":876626463,"timestamp":"2024-06-01T18:06:00.985712Z"}]}
{"channel":"book","type":"update","data":[{"symbol":"ETH/CAD","bids":[{"price":5186.04,"qty":0.58881413}],"asks":[],"checksum":174141960,"timestamp":"2024-06-01T18:06:00.988638Z"}]}
{"channel":"book","type":"update","data":[{"symbol":"ETH/CAD","bids":[],"asks":[{"price":5190.92,"qty":0.00000000},{"price":5196.70,"qty":12.40818836},{"price":5190.90,"qty":0.31150369}],"checksum":898967449,"timestamp":"2024-06-01T18:06:01.257132Z"}]}
{"channel":"book","type":"update","data":[{"symbol":"ETH/CAD","bids":[{"price":5187.99,"qty":0.90311190}],"asks":[],"checksum":228778352,"timestamp":"2024-06-01T18:06:01.262506Z"}]}
{"channel":"book","type":"update","data":[{"symbol":"ETH/CAD","bids":[{"price":5187.97,"qty":0.00000000},{"price":5183.79,"qty":2.21000000},{"price":5187.99,"qty":1.93655447}],"asks":[],"checksum":3230828397,"timestamp":"2024-06-01T18:06:01.266839Z"}]}
{"channel":"book","type":"update","data":[{"symbol":"ETH/CAD","bids":[{"price":5187.96,"qty":0.00000000},{"price":5183.39,"qty":1.84146195}],"asks":[],"checksum":194126654,"timestamp":"2024-06-01T18:06:01.678458Z"}]}
{"channel":"book","type":"update","data":[{"symbol":"ETH/CAD","bids":[{"price":5187.98,"qty":0.00000000},{"price":5182.04,"qty":2.22000000},{"price":5188.00,"qty":0.58849631}],"asks":[],"checksum":3439998533,"timestamp":"2024-06-01T18:06:01.713549Z"}]}
{"channel":"book","type":"update","data":[{"symbol":"ETH/CAD","bids":[],"asks":[{"price":5190.91,"qty":0.00000000},{"price":5196.70,"qty":12.40818836},{"price":5190.89,"qty":0.68087953}],"checksum":1358525350,"timestamp":"2024-06-01T18:06:01.984665Z"}]}
{"channel":"book","type":"update","data":[{"symbol":"ETH/CAD","bids":[{"price":5187.99,"qty":0.90311190},{"price":5188.01,"qty":1.03328287}],"asks":[],"checksum":1923287597,"timestamp":"2024-06-01T18:06:01.984757Z"}]}
{"channel":"book","type":"update","data":[{"symbol":"ETH/CAD","bids":[],"asks":[{"price":5196.69,"qty":0.00000000},{"price":5196.88,"qty":0.08976938}],"checksum":876621234,"timestamp":"2024-06-01T18:06:02.128953Z"}]}
{"channel":"book","type":"update","data":[{"symbol":"ETH/CAD","bids":[],"asks":[{"price":5196.87,"qty":0.20717085}],"checksum":3524841703,"timestamp":"2024-06-01T18:06:02.128987Z"}]}
{"channel":"book","type":"update","data":[{"symbol":"ETH/CAD","bids":[],"asks":[{"price":5196.87,"qty":13.13194447}],"checksum":3697313988,"timestamp":"2024-06-01T18:06:02.129800Z"}]}
{"channel":"book","type":"update","data":[{"symbol":"ETH/CAD","bids":[{"price":5188.00,"qty":0.00000000},{"price":5183.39,"qty":1.84146195},{"price":5188.02,"qty":0.58849631}],"asks":[],"checksum":4158025761,"timestamp":"2024-06-01T18:06:02.443012Z"}]}
{"channel":"book","type":"update","data":[{"symbol":"ETH/CAD","bids":[],"asks":[{"price":5190.88,"qty":0.90311190}],"checksum":1805195173,"timestamp":"2024-06-01T18:06:02.449115Z"}]}
{"channel":"book","type":"update","data":[{"symbol":"ETH/CAD","bids":[{"price":5188.03,"qty":0.90311190}],"asks":[],"checksum":2945844116,"timestamp":"2024-06-01T18:06:02.449196Z"}]}
{"channel":"book","type":"update","data":[{"symbol":"ETH/CAD","bids":[],"asks":[{"price":5190.90,"qty":0.00000000},{"price":5196.87,"qty":13.13194447},{"price":5190.87,"qty":0.31150369}],"checksum":27859892,"timestamp":"2024-06-01T18:06:02.475614Z"}]}
{"channel":"book","type":"update","data":[{"symbol":"ETH/CAD","bids":[{"price":5187.99,"qty":0.00000000},{"price":5183.79,"qty":2.21000000}],"asks":[],"checksum":1161867206,"timestamp":"2024-06-01T18:06:02.480722Z"}]}
{"channel":"book","type":"update","data":[{"symbol":"ETH/CAD","bids":[],"asks":[{"price":5190.88,"qty":0.00000000},{"price":5196.87,"qty":13.13194447}],"checksum":1431511690,"timestamp":"2024-06-01T18:06:02.480759Z"}]}
{"channel":"book","type":"update","data":[{"symbol":"ETH/CAD","bids":[],"asks":[{"price":5196.86,"qty":0.09301939}],"checksum":1735391112,"timestamp":"2024-06-01T18:06:02.609306Z"}]}
{"channel":"book","type":"update","data":[{"symbol":"ETH/CAD","bids":[],"asks":[{"price":5196.85,"qty":0.20717085}],"checksum":2834442434,"timestamp":"2024-06-01T18:06:02.625450Z"}]}
{"channel":"book","type":"update","data":[{"symbol":"ETH/CAD","bids":[],"asks":[{"price":5191.28,"qty":0.00000000},{"price":5196.86,"qty":0.09301939},{"price":5190.86,"qty":0.06651600}],"checksum":3314675538,"timestamp":"2024-06-01T18:06:02.650770Z"}]}
{"channel":"book","type":"update","data":[{"symbol":"ETH/CAD","bids":[],"asks":[{"price":5190.89,"qty":0.00000000},{"price":5196.86,"qty":0.09301939},{"price":5190.85,"qty":0.68087915}],"checksum":1428155485,"timestamp":"2024-06-01T18:06:02.693451Z"}]}
{"channel":"book","type":"update","data":[{"symbol":"ETH/CAD","bids":[{"price":5188.02,"qty":0.00000000},{"price":5183.39,"qty":1.84146195},{"price":5188.04,"qty":0.58849631}],"asks":[],"checksum":2426532890,"timestamp":"2024-06-01T18:06:03.025134Z"}]}
{"channel":"book","type":"update","data":[{"symbol":"ETH/CAD","bids":[{"price":5188.01,"qty":0.00000000},{"price":5183.39,"qty":1.84146195},{"price":5188.05,"qty":1.03327487}],"asks":[],"checksum":652267498,"timestamp":"2024-06-01T18:06:03.431502Z"}]}
{"channel":"book","type":"update","data":[{"symbol":"ETH/CAD","bids":[],"asks":[{"price":5190.84,"qty":0.90311190}],"checksum":3477870781,"timestamp":"2024-06-01T18:06:03.437484Z"}]}
{"channel":"book","type":"update","data":[{"symbol":"ETH/CAD","bids":[],"asks":[{"price":5191.17,"qty":0.00000000},{"price":5196.85,"qty":0.20717085}],"checksum":227910199,"timestamp":"2024-06-01T18:06:03.619199Z"}]}
{"channel":"book","type":"update","data":[{"symbol":"ETH/CAD","bids":[],"asks":[{"price":5190.84,"qty":0.00000000},{"price":5196.86,"qty":0.09301939}],"checksum":1615321373,"timestamp":"2024-06-01T18:06:03.619970Z"}]}
{"channel":"book","type":"update","data":[{"symbol":"ETH/CAD","bids":[],"asks":[{"price":5191.99,"qty":7.75819639}],"checksum":2644271250,"timestamp":"2024-06-01T18:06:03.623373Z"}]}
{"channel":"book","type":"update","data":[{"symbol":"ETH/CAD","bids":[{"price":5188.04,"qty":0.00000000},{"price":5183.39,"qty":1.84146195},{"price":5188.06,"qty":0.58849631}],"asks":[],"checksum":1591252748,"timestamp":"2024-06-01T18:06:03.661817Z"}]}
{"channel":"book","type":"update","data":[{"symbol":"ETH/CAD","bids":[{"price":5188.05,"qty":0.00000000},{"price":5183.39,"qty":1.84146195},{"price":5188.07,"qty":1.03325519}],"asks":[],"checksum":3070492359,"timestamp":"2024-06-01T18:06:04.144483Z"}]}
{"channel":"book","type":"update","data":[{"symbol":"ETH/CAD","bids":[{"price":5188.06,"qty":0.00000000},{"price":5183.39,"qty":1.84146195},{"price":5188.08,"qty":0.58849631}],"asks":[],"checksum":3304080132,"timestamp":"2024-06-01T18:06:04.180033Z"}]}
{"channel":"book","type":"update","data":[{"symbol":"ETH/CAD","bids":[{"price":5188.09,"qty":0.90311190}],"asks":[],"checksum":3106395572,"timestamp":"2024-06-01T18:06:04.184348Z"}]}
{"channel":"book","type":"update","data":[{"symbol":"ETH/CAD","bids":[],"asks":[{"price":5196.84,"qty":12.92477489}],"checksum":2137641978,"timestamp":"2024-06-01T18:06:04.578500Z"}]}
{"channel":"book","type":"update","data":[{"symbol":"ETH/CAD","bids":[],"asks":[{"price":5196.83,"qty":0.20717085}],"checksum":3671336240,"timestamp":"2024-06-01T18:06:04.586087Z"}]}
{"channel":"book","type":"update","data":[{"symbol":"ETH/CAD","bids":[{"price":5188.03,"qty":0.00000000},{"price":5183.79,"qty":2.21000000}],"asks":[],"checksum":1905730711,"timestamp":"2024-06-01T18:06:04.675619Z"}]}
{"channel":"book","type":"update","data":[{"symbol":"ETH/CAD","bids":[{"price":5188.07,"qty":0.00000000},{"price":5183.39,"qty":1.84146195},{"price":5188.10,"qty":1.03324894}],"asks":[],"checksum":3371551254,"timestamp":"2024-06-01T18:06:04.805829Z"}]}
{"channel":"book","type":"update","data":[{"symbol":"ETH/CAD","bids":[{"price":5188.11,"qty":0.90311190}],"asks":[],"checksum":1799981905,"timestamp":"2024-06-01T18:06:04.811933Z"}]}
{"channel":"book","type":"update","data":[{"symbol":"ETH/CAD","bids":[{"price":5184.44,"qty":0.00000000},{"price":5183.79,"qty":2.21000000}],"asks":[],"checksum":2873607920,"timestamp":"2024-06-01T18:06:05.068908Z"}]}
{"channel":"book","type":"update","data":[{"symbol":"ETH/CAD","bids":[{"price":5184.44,"qty":0.01039630}],"asks":[],"checksum":2697160819,"timestamp":"2024-06-01T18:06:05.070180Z"}]}
{"channel":"book","type":"update","data":[{"symbol":"ETH/CAD","bids":[{"price":5184.43,"qty":0.00000000},{"price":5183.79,"qty":2.21000000}],"asks":[],"checksum":986297395,"timestamp":"2024-06-01T18:06:05.164859Z"}]}
{"channel":"book","type":"update","data":[{"symbol":"ETH/CAD","bids":[{"price":5184.43,"qty":5.14675799}],"asks":[],"checksum":3766178679,"timestamp":"2024-06-01T18:06:05.166240Z"}]}
{"channel":"book","type":"update","data":[{"symbol":"ETH/CAD","bids":[{"price":5188.09,"qty":0.00000000},{"price":5183.79,"qty":2.21000000}],"asks":[],"checksum":3931576901,"timestamp":"2024-06-01T18:06:05.177625Z"}]}
{"channel":"book","type":"update","data":[{"symbol":"ETH/CAD","bids":[{"price":5188.10,"qty":0.00000000},{"price":5183.39,"qty":1.84146195},{"price":5188.12,"qty":1.03324481}],"asks":[],"checksum":517014282,"timestamp":"2024-06-01T18:06:05.486333Z"}]}
{"channel":"book","type":"update","data":[{"symbol":"ETH/CAD","bids":[{"price":5188.13,"qty":0.90311190}],"asks":[],"checksum":715164041,"timestamp":"2024-06-01T18:06:05.491796Z"}]}
{"channel":"book","type":"update","data":[{"symbol":"ETH/CAD","bids":[{"price":5188.08,"qty":0.00000000},{"price":5183.79,"qty":2.21000000},{"price":5188.14,"qty":0.58849631}],"asks":[],"checksum":1032091306,"timestamp":"2024-06-01T18:06:05.516743Z"}]}
{"channel":"book","type":"update","data":[{"symbol":"ETH/CAD","bids":[{"price":5188.11,"qty":0.00000000},{"price":5183.79,"qty":2.21000000}],"asks":[],"checksum":1347042815,"timestamp":"2024-06-01T18:06:05.521685Z"}]}
{"channel":"book","type":"update","data":[{"symbol":"ETH/CAD","bids":[],"asks":[{"price":5190.87,"qty":0.00000000},{"price":5196.84,"qty":12.92477489},{"price":5190.84,"qty":0.31150369}],"checksum":4166154566,"timestamp":"2024-06-01T18:06:05.548356Z"}]}
{"channel":"book","type":"update","data":[{"symbol":"ETH/CAD","bids":[{"price":5188.12,"qty":0.00000000},{"price":5183.39,"qty":1.84146195},{"price":5188.15,"qty":1.03323369}],"asks":[],"checksum":976143450,"timestamp":"2024-06-01T18:06:06.101466Z"}]}
{"channel":"book","type":"update","data":[{"symbol":"ETH/CAD","bids":[{"price":5188.14,"qty":0.00000000},{"price":5183.39,"qty":1.84146195},{"price":5188.16,"qty":0.58849631}],"asks":[],"checksum":1480623713,"timestamp":"2024-06-01T18:06:06.124734Z"}]}
{"channel":"book","type":"update","data":[{"symbol":"ETH/CAD","bids":[{"price":5187.93,"qty":0.00000000},{"price":5183.39,"qty":1.84146195},{"price":5188.15,"qty":1.09976769}],"asks":[],"checksum":1561151109,"timestamp":"2024-06-01T18:06:06.169290Z"}]}
{"channel":"book","type":"update","data":[{"symbol":"ETH/CAD","bids":[{"price":5188.17,"qty":0.90311190}],"asks":[],"checksum":3687879773,"timestamp":"2024-06-01T18:06:06.676448Z"}]}
{"channel":"book","type":"update","data":[{"symbol":"ETH/CAD","bids":[{"price":5188.13,"qty":0.00000000},{"price":5183.39,"qty":1.84146195}],"asks":[],"checksum":1707979821,"timestamp":"2024-06-01T18:06:06.680732Z"}]}
{"channel":"book","type":"update","data":[{"symbol":"ETH/CAD","bids":[{"price":5188.16,"qty":0.00000000},{"price":5182.04,"qty":2.22000000},{"price":5188.18,"qty":0.58849631}],"asks":[],"checksum":2447096279,"timestamp":"2024-06-01T18:06:06.702574Z"}]}
{"channel":"book","type":"update","data":[{"symbol":"ETH/CAD","bids":[{"price":5188.15,"qty":0.06653400},{"price":5188.19,"qty":1.03322536}],"asks":[],"checksum":2890362765,"timestamp":"2024-06-01T18:06:06.794770Z"}]}
{"channel":"book","type":"update","data":[{"symbol":"ETH/CAD","bids":[],"asks":[{"price":5190.85,"qty":0.00000000},{"price":5196.84,"qty":12.92477489},{"price":5190.83,"qty":0.68105054}],"checksum":2796522167,"timestamp":"2024-06-01T18:06:06.794862Z"}]}
{"channel":"book","type":"update","data":[{"symbol":"ETH/CAD","bids":[],"asks":[{"price":5196.82,"qty":11.37495786}],"checksum":2653744988,"timestamp":"2024-06-01T18:06:06.921845Z"}]}
{"channel":"book","type":"update","data":[{"symbol":"ETH/CAD","bids":[],"asks":[{"price":5196.81,"qty":0.20717085}],"checksum":1313787112,"timestamp":"2024-06-01T18:06:06.938179Z"}]}
{"channel":"book","type":"update","data":[{"symbol":"ETH/CAD","bids":[{"price":5188.18,"qty":0.00000000},{"price":5183.39,"qty":1.84146195},{"price":5188.20,"qty":0.58849631}],"asks":[],"checksum":1994274092,"timestamp":"2024-06-01T18:06:07.191260Z"}]}
{"channel":"book","type":"update","data":[{"symbol":"ETH/CAD","bids":[{"price":5188.21,"qty":0.90311190}],"asks":[],"checksum":1367257413,"timestamp":"2024-06-01T18:06:07.195990Z"}]}
{"channel":"book","type":"update","data":[{"symbol":"ETH/CAD","bids":[{"price":5188.19,"qty":0.00000000},{"price":5183.79,"qty":2.21000000},{"price":5188.22,"qty":1.03321526}],"asks":[],"checksum":2295251299,"timestamp":"2024-06-01T18:06:07.473252Z"}]}
{"channel":"book","type":"update","data":[{"symbol":"ETH/CAD","bids":[{"price":5188.17,"qty":0.00000000},{"price":5183.79,"qty":2.21000000}],"asks":[],"checksum":4024795746,"timestamp":"2024-06-01T18:06:07.478393Z"}]}
{"channel":"book","type":"update","data":[{"symbol":"ETH/CAD","bids":[{"price":5188.23,"qty":0.90311190}],"asks":[],"checksum":2048935852,"timestamp":"2024-06-01T18:06:07.676084Z"}]}
{"channel":"book","type":"update","data":[{"symbol":"ETH/CAD","bids":[{"price":5188.21,"qty":0.00000000},{"price":5183.79,"qty":2.21000000}],"asks":[],"checksum":2121772196,"timestamp":"2024-06-01T18:06:07.680639Z"}]}
{"channel":"book","type":"update","data":[{"symbol":"ETH/CAD","bids":[{"price":5188.20,"qty":0.00000000},{"price":5183.39,"qty":1.84146195},{"price":5188.24,"qty":0.58849631}],"asks":[],"checksum":1178474845,"timestamp":"2024-06-01T18:06:07.707714Z"}]}
{"channel":"book","type":"update","data":[{"symbol":"ETH/CAD","bids":[{"price":5188.22,"qty":0.00000000},{"price":5183.39,"qty":1.84146195},{"price":5188.25,"qty":1.03406598}],"asks":[],"checksum":2699802008,"timestamp":"2024-06-01T18:06:08.109326Z"}]}
{"channel":"book","type":"update","data":[{"symbol":"ETH/CAD","bids":[{"price":5184.45,"qty":0.51339104}],"asks":[],"checksum":4203216794,"timestamp":"2024-06-01T18:06:08.186350Z"}]}
{"channel":"book","type":"update","data":[{"symbol":"ETH/CAD","bids":[{"price":5188.24,"qty":0.00000000},{"price":5183.79,"qty":2.21000000},{"price":5188.26,"qty":0.58849631}],"asks":[],"checksum":2535986512,"timestamp":"2024-06-01T18:06:08.498190Z"}]}
{"channel":"book","type":"update","data":[{"symbol":"ETH/CAD","bids":[{"price":5188.27,"qty":0.90311190}],"asks":[],"checksum":2663601072,"timestamp":"2024-06-01T18:06:08.504743Z"}]}
{"channel":"book","type":"update","data":[{"symbol":"ETH/CAD","bids":[],"asks":[{"price":5190.84,"qty":0.00000000},{"price":5196.82,"qty":11.46797731},{"price":5190.82,"qty":0.31150369}],"checksum":2206984227,"timestamp":"2024-06-01T18:06:08.530309Z"}]}
{"channel":"book","type":"update","data":[{"symbol":"ETH/CAD","bids":[{"price":5188.23,"qty":0.00000000},{"price":5183.80,"qty":1.31700000}],"asks":[],"checksum":2332464653,"timestamp":"2024-06-01T18:06:08.535359Z"}]}
{"channel":"book","type":"update","data":[{"symbol":"ETH/CAD","bids":[{"price":5188.25,"qty":0.00000000},{"price":5183.79,"qty":2.21000000},{"price":5188.28,"qty":1.03407620}],"asks":[],"checksum":3498470041,"timestamp":"2024-06-01T18:06:08.750503Z"}]}
{"channel":"book","type":"update","data":[{"symbol":"ETH/CAD","bids":[{"price":5188.26,"qty":0.00000000},{"price":5183.79,"qty":2.21000000},{"price":5188.29,"qty":0.58849631}],"asks":[],"checksum":3459739014,"timestamp":"2024-06-01T18:06:09.076181Z"}]}
{"channel":"book","type":"update","data":[{"symbol":"ETH/CAD","bids":[],"asks":[{"price":5190.83,"qty":0.00000000},{"price":5196.82,"qty":0.09301945},{"price":5190.81,"qty":0.68104257}],"checksum":4180822267,"timestamp":"2024-06-01T18:06:09.369986Z"}]}
{"channel":"book","type":"update","data":[{"symbol":"ETH/CAD","bids":[],"asks":[{"price":5196.80,"qty":10.85835218}],"checksum":3878367894,"timestamp":"2024-06-01T18:06:09.371686Z"}]}
{"channel":"book","type":"update","data":[{"symbol":"ETH/CAD","bids":[{"price":5188.30,"qty":0.90311190}],"asks":[],"checksum":1404193435,"timestamp":"2024-06-01T18:06:09.375044Z"}]}
{"channel":"book","type":"update","data":[{"symbol":"ETH/CAD","bids":[],"asks":[{"price":5196.79,"qty":0.20717085}],"checksum":1484830830,"timestamp":"2024-06-01T18:06:09.397201Z"}]}
{"channel":"book","type":"update","data":[{"symbol":"ETH/CAD","bids":[{"price":5184.44,"qty":0.00000000},{"price":5183.80,"qty":1.31700000}],"asks":[],"checksum":1263987943,"timestamp":"2024-06-01T18:06:09.447537Z"}]}
{"channel":"book","type":"update","data":[{"symbol":"ETH/CAD","bids":[{"price":5183.80,"qty":0.00000000},{"price":5183.79,"qty":2.21000000},{"price":5184.46,"qty":1.31700000}],"asks":[],"checksum":694263207,"timestamp":"2024-06-01T18:06:09.556284Z"}]}
{"channel":"book","type":"update","data":[{"symbol":"ETH/CAD","bids":[],"asks":[{"price":5190.94,"qty":0.00000000},{"price":5196.80,"qty":10.85835218}],"checksum":1658765059,"timestamp":"2024-06-01T18:06:09.562751Z"}]}
{"channel":"book","type":"update","data":[{"symbol":"ETH/CAD","bids":[{"price":5188.27,"qty":0.00000000},{"price":5183.79,"qty":2.21000000}],"asks":[],"checksum":4087533129,"timestamp":"2024-06-01T18:06:09.570200Z"}]}
{"channel":"book","type":"update","data":[{"symbol":"ETH/CAD","bids":[{"price":5188.29,"qty":0.00000000},{"price":5183.60,"qty":2.18000000},{"price":5188.31,"qty":0.58849631}],"asks":[],"checksum":3858755369,"timestamp":"2024-06-01T18:06:09.575639Z"}]}
{"channel":"book","type":"update","data":[{"symbol":"ETH/CAD","bids":[{"price":5188.28,"qty":0.00000000},{"price":5183.60,"qty":2.18000000},{"price":5188.32,"qty":1.03406540}],"asks":[],"checksum":745824719,"timestamp":"2024-06-01T18:06:10.029399Z"}]}
{"channel":"book","type":"update","data":[{"symbol":"ETH/CAD","bids":[{"price":5188.31,"qty":0.00000000},{"price":5183.60,"qty":2.18000000},{"price":5188.33,"qty":0.58849631}],"asks":[],"checksum":1810609118,"timestamp":"2024-06-01T18:06:10.207114Z"}]}
{"channel":"book","type":"update","data":[{"symbol":"ETH/CAD","bids":[{"price":5188.34,"qty":0.90311190}],"asks":[],"checksum":3592154897,"timestamp":"2024-06-01T18:06:10.212317Z"}]}
{"channel":"book","type":"update","data":[{"symbol":"ETH/CAD","bids":[],"asks":[{"price":5191.53,"qty":0.90311190}],"checksum":941851583,"timestamp":"2024-06-01T18:06:10.212336Z"}]}
{"channel":"book","type":"update","data":[{"symbol":"ETH/CAD","bids":[],"asks":[{"price":5190.82,"qty":0.00000000},{"price":5196.80,"qty":10.85835218},{"price":5190.80,"qty":0.31150369}],"checksum":2484178002,"timestamp":"2024-06-01T18:06:10.238959Z"}]}
{"channel":"book","type":"update","data":[{"symbol":"ETH/CAD","bids":[{"price":5188.30,"qty":0.00000000},{"price":5183.79,"qty":2.21000000}],"asks":[],"checksum":3630297055,"timestamp":"2024-06-01T18:06:10.245012Z"}]}
{"channel":"book","type":"update","data":[{"symbol":"ETH/CAD","bids":[{"price":5188.32,"qty":0.00000000},{"price":5183.60,"qty":2.18000000},{"price":5188.35,"qty":1.03405928}],"asks":[],"checksum":235600621,"timestamp":"2024-06-01T18:06:10.647944Z"}]}
{"channel":"book","type":"update","data":[{"symbol":"ETH/CAD","bids":[],"asks":[{"price":5190.81,"qty":0.00000000},{"price":5196.80,"qty":10.85835218},{"price":5190.79,"qty":0.68103837}],"checksum":3892298819,"timestamp":"2024-06-01T18:06:10.647968Z"}]}
{"channel":"book","type":"update","data":[{"symbol":"ETH/CAD","bids":[{"price":5188.33,"qty":0.00000000},{"price":5183.60,"qty":2.18000000},{"price":5188.36,"qty":0.58849631}],"asks":[],"checksum":135137004,"timestamp":"2024-06-01T18:06:10.967885Z"}]}
{"channel":"book","type":"update","data":[{"symbol":"ETH/CAD","bids":[],"asks":[{"price":5196.78,"qty":0.09301933}],"checksum":1581192686,"timestamp":"2024-06-01T18:06:10.984901Z"}]}
{"channel":"book","type":"update","data":[{"symbol":"ETH/CAD","bids":[],"asks":[{"price":5190.80,"qty":0.00000000},{"price":5196.79,"qty":0.20717085},{"price":5190.78,"qty":0.31150369}],"checksum":2440178213,"timestamp":"2024-06-01T18:06:11.000066Z"}]}
{"channel":"book","type":"update","data":[{"symbol":"ETH/CAD","bids":[{"price":5184.43,"qty":0.00000000},{"price":5183.60,"qty":2.18000000}],"asks":[],"checksum":1147353139,"timestamp":"2024-06-01T18:06:11.215730Z"}]}
{"channel":"book","type":"update","data":[{"symbol":"ETH/CAD","bids":[{"price":5184.45,"qty":0.00000000},{"price":5183.39,"qty":1.84146195}],"asks":[],"checksum":2486258760,"timestamp":"2024-06-01T18:06:11.215746Z"}]}
{"channel":"book","type":"update","data":[{"symbol":"ETH/CAD","bids":[{"price":5184.47,"qty":6.17339400}],"asks":[],"checksum":98409831,"timestamp":"2024-06-01T18:06:11.217425Z"}]}
{"channel":"book","type":"update","data":[{"symbol":"ETH/CAD","bids":[{"price":5184.46,"qty":0.00000000},{"price":5183.39,"qty":1.84146195},{"price":5184.48,"qty":1.31700000}],"asks":[],"checksum":3639190057,"timestamp":"2024-06-01T18:06:11.221020Z"}]}
{"channel":"book","type":"update","data":[{"symbol":"ETH/CAD","bids":[{"price":5188.15,"qty":0.00000000},{"price":5183.39,"qty":1.84146195},{"price":5188.37,"qty":0.06653200}],"asks":[],"checksum":2498229109,"timestamp":"2024-06-01T18:06:11.230679Z"}]}
{"channel":"book","type":"update","data":[{"symbol":"ETH/CAD","bids":[{"price":5188.38,"qty":0.90311190}],"asks":[],"checksum":2518958703,"timestamp":"2024-06-01T18:06:11.235731Z"}]}
{"channel":"book","type":"update","data":[{"symbol":"ETH/CAD","bids":[{"price":5188.35,"qty":0.00000000},{"price":5183.60,"qty":2.18000000},{"price":5188.37,"qty":1.10058724}],"asks":[],"checksum":2888571272,"timestamp":"2024-06-01T18:06:11.269110Z"}]}
{"channel":"book","type":"update","data":[{"symbol":"ETH/CAD","bids":[],"asks":[{"price":5190.79,"qty":0.00000000},{"price":5196.79,"qty":0.20717085},{"price":5190.77,"qty":0.68103835}],"checksum":1733245981,"timestamp":"2024-06-01T18:06:11.269292Z"}]}
{"channel":"book","type":"update","data":[{"symbol":"ETH/CAD","bids":[{"price":5188.34,"qty":0.00000000},{"price":5183.39,"qty":1.84146195}],"asks":[],"checksum":2433835684,"timestamp":"2024-06-01T18:06:11.274456Z"}]}
{"channel":"book","type":"update","data":[{"symbol":"ETH/CAD","bids":[{"price":5188.36,"qty":0.00000000},{"price":5181.59,"qty":0.94000000},{"price":5188.39,"qty":0.58849631}],"asks":[],"checksum":2849942764,"timestamp":"2024-06-01T18:06:11.609157Z"}]}
{"channel":"book","type":"update","data":[{"symbol":"ETH/CAD","bids":[],"asks":[{"price":5196.77,"qty":12.92476258}],"checksum":2781098139,"timestamp":"2024-06-01T18:06:11.823379Z"}]}
{"channel":"book","type":"update","data":[{"symbol":"ETH/CAD","bids":[],"asks":[{"price":5196.76,"qty":0.20717085}],"checksum":2457199714,"timestamp":"2024-06-01T18:06:11.833128Z"}]}
{"channel":"book","type":"update","data":[{"symbol":"ETH/CAD","bids":[{"price":5188.37,"qty":0.06653200},{"price":5188.40,"qty":1.03405087}],"asks":[],"checksum":2723057738,"timestamp":"2024-06-01T18:06:11.937729Z"}]}
{"channel":"book","type":"update","data":[{"symbol":"ETH/CAD","bids":[],"asks":[{"price":5194.49,"qty":0.00000000},{"price":5196.77,"qty":12.92476258}],"checksum":2474573338,"timestamp":"2024-06-01T18:06:11.974265Z"}]}
{"channel":"book","type":"update","data":[{"symbol":"ETH/CAD","bids":[],"asks":[{"price":5195.28,"qty":1.31700000}],"checksum":2752211022,"timestamp":"2024-06-01T18:06:11.982403Z"}]}
{"channel":"book","type":"update","data":[{"symbol":"ETH/CAD","bids":[{"price":5188.39,"qty":0.00000000},{"price":5183.39,"qty":1.84146195},{"price":5188.41,"qty":0.58849631}],"asks":[],"checksum":2797356876,"timestamp":"2024-06-01T18:06:12.309483Z"}]}
{"channel":"book","type":"update","data":[{"symbol":"ETH/CAD","bids":[{"price":5188.42,"qty":0.90311190}],"asks":[],"checksum":1485452154,"timestamp":"2024-06-01T18:06:12.442081Z"}]}
{"channel":"book","type":"update","data":[{"symbol":"ETH/CAD","bids":[{"price":5188.38,"qty":0.00000000},{"price":5183.60,"qty":2.18000000}],"asks":[],"checksum":2765248514,"timestamp":"2024-06-01T18:06:12.494581Z"}]}
{"channel":"book","type":"update","data":[{"symbol":"ETH/CAD","bids":[{"price":5188.40,"qty":0.00000000},{"price":5183.39,"qty":1.84146195},{"price":5188.43,"qty":1.03262767}],"asks":[],"checksum":3445592688,"timestamp":"2024-06-01T18:06:12.563622Z"}]}
{"channel":"book","type":"update","data":[{"symbol":"ETH/CAD","bids":[{"price":5184.49,"qty":0.02066078}],"asks":[],"checksum":730695079,"timestamp":"2024-06-01T18:06:12.746092Z"}]}
{"channel":"book","type":"update","data":[{"symbol":"ETH/CAD","bids":[{"price":5188.41,"qty":0.00000000},{"price":5183.60,"qty":2.18000000},{"price":5188.44,"qty":0.58849631}],"asks":[],"checksum":2286670086,"timestamp":"2024-06-01T18:06:13.290887Z"}]}
{"channel":"book","type":"update","data":[{"symbol":"ETH/CAD","bids":[],"asks":[{"price":5195.28,"qty":0.00000000},{"price":5196.77,"qty":12.92476258},{"price":5196.76,"qty":1.52417085}],"checksum":2542031906,"timestamp":"2024-06-01T18:06:13.294111Z"}]}
{"channel":"book","type":"update","data":[{"symbol":"ETH/CAD","bids":[{"price":5188.45,"qty":0.90311190}],"asks":[],"checksum":3882321621,"timestamp":"2024-06-01T18:06:13.296451Z"}]}
{"channel":"book","type":"update","data":[{"symbol":"ETH/CAD","bids":[],"asks":[{"price":5190.78,"qty":0.00000000},{"price":5196.78,"qty":0.09301933},{"price":5190.76,"qty":0.31150369}],"checksum":2568261687,"timestamp":"2024-06-01T18:06:13.322377Z"}]}
{"channel":"book","type":"update","data":[{"symbol":"ETH/CAD","bids":[{"price":5188.42,"qty":0.00000000},{"price":5183.79,"qty":2.21000000}],"asks":[],"checksum":3396813437,"timestamp":"2024-06-01T18:06:13.327286Z"}]}
{"channel":"book","type":"update","data":[{"symbol":"ETH/CAD","bids":[{"price":5188.43,"qty":0.00000000},{"price":5183.60,"qty":2.18000000},{"price":5188.45,"qty":1.92763863}],"asks":[],"checksum":3314456242,"timestamp":"2024-06-01T18:06:13.336022Z"}]}
{"channel":"book","type":"update","data":[{"symbol":"ETH/CAD","bids":[],"asks":[{"price":5196.75,"qty":0.09301880}],"checksum":2122878600,"timestamp":"2024-06-01T18:06:13.535584Z"}]}
{"channel":"book","type":"update","data":[{"symbol":"ETH/CAD","bids":[{"price":5188.44,"qty":0.00000000},{"price":5183.39,"qty":1.84146195},{"price":5188.46,"qty":0.58849631}],"asks":[],"checksum":1054034209,"timestamp":"2024-06-01T18:06:13.869531Z"}]}
{"channel":"book","type":"update","data":[{"symbol":"ETH/CAD","bids":[{"price":5188.47,"qty":0.90311190}],"asks":[],"checksum":1207898680,"timestamp":"2024-06-01T18:06:13.874700Z"}]}
{"channel":"book","type":"update","data":[{"symbol":"ETH/CAD","bids":[{"price":5188.45,"qty":0.90311190},{"price":5188.47,"qty":1.92762448}],"asks":[],"checksum":1418859995,"timestamp":"2024-06-01T18:06:13.929888Z"}]}
{"channel":"book","type":"update","data":[{"symbol":"ETH/CAD","bids":[{"price":5188.45,"qty":0.00000000},{"price":5183.60,"qty":2.18000000}],"asks":[],"checksum":3409282964,"timestamp":"2024-06-01T18:06:13.934447Z"}]}
{"channel":"book","type":"update","data":[{"symbol":"ETH/CAD","bids":[{"price":5188.46,"qty":0.00000000},{"price":5183.39,"qty":1.84146195},{"price":5188.48,"qty":0.58849631}],"asks":[],"checksum":3048076411,"timestamp":"2024-06-01T18:06:13.963114Z"}]}
{"channel":"book","type":"update","data":[{"symbol":"ETH/CAD","bids":[],"asks":[{"price":5196.74,"qty":12.40810565}],"checksum":441808970,"timestamp":"2024-06-01T18:06:14.155995Z"}]}
{"channel":"book","type":"update","data":[{"symbol":"ETH/CAD","bids":[],"asks":[{"price":5196.73,"qty":1.31700000}],"checksum":4274683316,"timestamp":"2024-06-01T18:06:14.158908Z"}]}
{"channel":"book","type":"update","data":[{"symbol":"ETH/CAD","bids":[],"asks":[{"price":5196.73,"qty":1.52417085}],"checksum":2077344901,"timestamp":"2024-06-01T18:06:14.160152Z"}]}
{"channel":"book","type":"update","data":[{"symbol":"ETH/CAD","bids":[{"price":5184.47,"qty":0.00000000},{"price":5183.39,"qty":1.84146195}],"asks":[],"checksum":3122386314,"timestamp":"2024-06-01T18:06:14.244452Z"}]}
{"channel":"book","type":"update","data":[{"symbol":"ETH/CAD","bids":[{"price":5184.50,"qty":6.17278590}],"asks":[],"checksum":1114397522,"timestamp":"2024-06-01T18:06:14.245449Z"}]}
{"channel":"book","type":"update","data":[{"symbol":"ETH/CAD","bids":[{"price":5184.48,"qty":0.00000000},{"price":5183.39,"qty":1.84146195},{"price":5184.43,"qty":1.31700000}],"asks":[],"checksum":1303374904,"timestamp":"2024-06-01T18:06:14.247900Z"}]}
{"channel":"book","type":"update","data":[{"symbol":"ETH/CAD","bids":[{"price":5188.49,"qty":0.90311190}],"asks":[],"checksum":2824512388,"timestamp":"2024-06-01T18:06:14.250917Z"}]}
{"channel":"book","type":"update","data":[{"symbol":"ETH/CAD","bids":[],"asks":[{"price":5190.77,"qty":0.00000000},{"price":5196.75,"qty":0.09301880},{"price":5190.75,"qty":0.73412310}],"checksum":3941926937,"timestamp":"2024-06-01T18:06:14.502989Z"}]}
{"channel":"book","type":"update","data":[{"symbol":"ETH/CAD","bids":[{"price":5188.47,"qty":0.90311190},{"price":5188.50,"qty":1.02450644}],"asks":[],"checksum":2291285668,"timestamp":"2024-06-01T18:06:14.503048Z"}]}
{"channel":"book","type":"update","data":[{"symbol":"ETH/CAD","bids":[{"price":5188.47,"qty":0.00000000},{"price":5183.79,"qty":2.21000000}],"asks":[],"checksum":1855610645,"timestamp":"2024-06-01T18:06:14.509515Z"}]}
{"channel":"book","type":"update","data":[{"symbol":"ETH/CAD","bids":[{"price":5188.48,"qty":0.00000000},{"price":5183.60,"qty":2.18000000},{"price":5188.51,"qty":0.58849631}],"asks":[],"checksum":810495729,"timestamp":"2024-06-01T18:06:14.512148Z"}]}
{"channel":"book","type":"update","data":[{"symbol":"ETH/CAD","bids":[],"asks":[{"price":5190.76,"qty":0.00000000},{"price":5196.75,"qty":0.09301880},{"price":5190.74,"qty":0.31150369}],"checksum":700305888,"timestamp":"2024-06-01T18:06:14.665735Z"}]}
{"channel":"book","type":"update","data":[{"symbol":"ETH/CAD","bids":[],"asks":[{"price":5190.75,"qty":0.00000000},{"price":5196.75,"qty":0.09301880},{"price":5190.73,"qty":0.73415356}],"checksum":108311905,"timestamp":"2024-06-01T18:06:15.134228Z"}]}
{"channel":"book","type":"update","data":[{"symbol":"ETH/CAD","bids":[{"price":5188.50,"qty":0.00000000},{"price":5183.60,"qty":2.18000000},{"price":5188.52,"qty":1.02450244}],"asks":[],"checksum":2273772849,"timestamp":"2024-06-01T18:06:15.134309Z"}]}
{"channel":"book","type":"update","data":[{"symbol":"ETH/CAD","bids":[{"price":5184.43,"qty":0.00000000},{"price":5183.60,"qty":2.18000000},{"price":5184.51,"qty":1.31700000}],"asks":[],"checksum":4108558445,"timestamp":"2024-06-01T18:06:15.137249Z"}]}
{"channel":"book","type":"update","data":[{"symbol":"ETH/CAD","bids":[{"price":5188.51,"qty":0.00000000},{"price":5183.60,"qty":2.18000000},{"price":5188.53,"qty":0.58849631}],"asks":[],"checksum":2097030799,"timestamp":"2024-06-01T18:06:15.456187Z"}]}
{"channel":"book","type":"update","data":[{"symbol":"ETH/CAD","bids":[{"price":5188.54,"qty":0.90311190}],"asks":[],"checksum":1546425528,"timestamp":"2024-06-01T18:06:15.461160Z"}]}
{"channel":"book","type":"update","data":[{"symbol":"ETH/CAD","bids":[{"price":5188.49,"qty":0.00000000},{"price":5183.79,"qty":2.21000000}],"asks":[],"checksum":2016864017,"timestamp":"2024-06-01T18:06:15.683664Z"}]}
{"channel":"book","type":"update","data":[{"symbol":"ETH/CAD","bids":[{"price":5188.52,"qty":0.00000000},{"price":5183.60,"qty":2.18000000},{"price":5188.55,"qty":1.02449296}],"asks":[],"checksum":1675037690,"timestamp":"2024-06-01T18:06:15.772879Z"}]}
{"channel":"book","type":"update","data":[{"symbol":"ETH/CAD","bids":[{"price":5188.56,"qty":0.90311190}],"asks":[],"checksum":317017676,"timestamp":"2024-06-01T18:06:15.778264Z"}]}
{"channel":"book","type":"update","data":[{"symbol":"ETH/CAD","bids":[{"price":5188.53,"qty":0.00000000},{"price":5183.79,"qty":2.21000000},{"price":5188.57,"qty":0.58849631}],"asks":[],"checksum":1919398404,"timestamp":"2024-06-01T18:06:15.792470Z"}]}
{"channel":"book","type":"update","data":[{"symbol":"ETH/CAD","bids":[{"price":5184.49,"qty":0.00000000},{"price":5183.79,"qty":2.21000000}],"asks":[],"checksum":2066627917,"timestamp":"2024-06-01T18:06:16.012984Z"}]}
{"channel":"book","type":"update","data":[{"symbol":"ETH/CAD","bids":[{"price":5184.52,"qty":0.01552898}],"asks":[],"checksum":3756526666,"timestamp":"2024-06-01T18:06:16.013898Z"}]}
{"channel":"book","type":"update","data":[{"symbol":"ETH/CAD","bids":[],"asks":[{"price":5196.72,"qty":0.09301904}],"checksum":3685813441,"timestamp":"2024-06-01T18:06:16.082343Z"}]}
{"channel":"book","type":"update","data":[{"symbol":"ETH/CAD","bids":[{"price":5188.54,"qty":0.00000000},{"price":5183.79,"qty":2.21000000}],"asks":[],"checksum":3148171327,"timestamp":"2024-06-01T18:06:16.178318Z"}]}
{"channel":"book","type":"update","data":[{"symbol":"ETH/CAD","bids":[{"price":5188.58,"qty":0.90311190}],"asks":[],"checksum":1414670553,"timestamp":"2024-06-01T18:06:16.184273Z"}]}
{"channel":"book","type":"update","data":[{"symbol":"ETH/CAD","bids":[{"price":5186.04,"qty":0.00000000},{"price":5183.79,"qty":2.21000000}],"asks":[],"checksum":1025875009,"timestamp":"2024-06-01T18:06:16.187164Z"}]}
{"channel":"book","type":"update","data":[{"symbol":"ETH/CAD","bids":[{"price":5186.65,"qty":0.58546729}],"asks":[],"checksum":2605303644,"timestamp":"2024-06-01T18:06:16.190172Z"}]}
{"channel":"book","type":"update","data":[{"symbol":"ETH/CAD","bids":[],"asks":[{"price":5190.74,"qty":0.00000000},{"price":5196.74,"qty":12.40810565}],"checksum":3472113992,"timestamp":"2024-06-01T18:06:16.221099Z"}]}
{"channel":"book","type":"update","data":[{"symbol":"ETH/CAD","bids":[{"price":5188.56,"qty":0.00000000},{"price":5183.79,"qty":2.21000000}],"asks":[],"checksum":2612679789,"timestamp":"2024-06-01T18:06:16.225720Z"}]}
{"channel":"book","type":"update","data":[{"symbol":"ETH/CAD","bids":[],"asks":[{"price":5190.73,"qty":0.00000000},{"price":5196.90,"qty":1.17000000},{"price":5190.85,"qty":0.73414997}],"checksum":2206357517,"timestamp":"2024-06-01T18:06:16.279703Z"}]}
{"channel":"book","type":"update","data":[{"symbol":"ETH/CAD","bids":[{"price":5188.55,"qty":0.00000000},{"price":5183.60,"qty":2.18000000},{"price":5188.59,"qty":1.02448485}],"asks":[],"checksum":941307508,"timestamp":"2024-06-01T18:06:16.443994Z"}]}
{"channel":"book","type":"update","data":[{"symbol":"ETH/CAD","bids":[],"asks":[{"price":5190.85,"qty":0.00000000},{"price":5196.90,"qty":1.17000000},{"price":5190.84,"qty":0.73414997}],"checksum":1238268973,"timestamp":"2024-06-01T18:06:16.444209Z"}]}
{"channel":"book","type":"update","data":[{"symbol":"ETH/CAD","bids":[],"asks":[{"price":5190.84,"qty":0.00000000},{"price":5196.90,"qty":1.17000000},{"price":5191.52,"qty":0.73414996}],"checksum":371381265,"timestamp":"2024-06-01T18:06:16.524015Z"}]}
{"channel":"book","type":"update","data":[{"symbol":"ETH/CAD","bids":[],"asks":[{"price":5196.74,"qty":0.00000000},{"price":5196.90,"qty":1.17000000}],"checksum":2865638715,"timestamp":"2024-06-01T18:06:16.613991Z"}]}
{"channel":"book","type":"update","data":[{"symbol":"ETH/CAD","bids":[],"asks":[{"price":5196.73,"qty":0.20717085},{"price":5196.89,"qty":1.31700000}],"checksum":3941669180,"timestamp":"2024-06-01T18:06:16.617382Z"}]}
{"channel":"book","type":"update","data":[{"symbol":"ETH/CAD","bids":[],"asks":[{"price":5196.71,"qty":12.40812818}],"checksum":2320154660,"timestamp":"2024-06-01T18:06:16.619334Z"}]}
{"channel":"book","type":"update","data":[{"symbol":"ETH/CAD","bids":[],"asks":[{"price":5196.73,"qty":0.00000000},{"price":5196.89,"qty":1.31700000}],"checksum":2915364826,"timestamp":"2024-06-01T18:06:16.626144Z"}]}
{"channel":"book","type":"update","data":[{"symbol":"ETH/CAD","bids":[],"asks":[{"price":5196.70,"qty":0.20717085}],"checksum":3927124038,"timestamp":"2024-06-01T18:06:16.626442Z"}]}
{"channel":"book","type":"update","data":[{"symbol":"ETH/CAD","bids":[{"price":5188.57,"qty":0.00000000},{"price":5183.60,"qty":2.18000000},{"price":5188.60,"qty":0.58849631}],"asks":[],"checksum":4066078267,"timestamp":"2024-06-01T18:06:16.983237Z"}]}
{"channel":"book","type":"update","data":[{"symbol":"ETH/CAD","bids":[{"price":5188.59,"qty":0.00000000},{"price":5183.60,"qty":2.18000000},{"price":5188.61,"qty":1.02448086}],"asks":[],"checksum":1854086908,"timestamp":"2024-06-01T18:06:17.141459Z"}]}
{"channel":"book","type":"update","data":[{"symbol":"ETH/CAD","bids":[],"asks":[{"price":5196.70,"qty":1.52417085}],"checksum":3632510227,"timestamp":"2024-06-01T18:06:17.144565Z"}]}
{"channel":"book","type":"update","data":[{"symbol":"ETH/CAD","bids":[{"price":5184.50,"qty":0.00000000},{"price":5183.60,"qty":2.18000000}],"asks":[],"checksum":1842455416,"timestamp":"2024-06-01T18:06:17.267460Z"}]}
{"channel":"book","type":"update","data":[{"symbol":"ETH/CAD","bids":[{"price":5184.53,"qty":6.17305320}],"asks":[],"checksum":2609551574,"timestamp":"2024-06-01T18:06:17.268459Z"}]}
{"channel":"book","type":"update","data":[{"symbol":"ETH/CAD","bids":[{"price":5184.51,"qty":0.00000000},{"price":5183.60,"qty":2.18000000},{"price":5184.43,"qty":1.31700000}],"asks":[],"checksum":2849775043,"timestamp":"2024-06-01T18:06:17.270577Z"}]}
{"channel":"book","type":"update","data":[{"symbol":"ETH/CAD","bids":[{"price":5188.62,"qty":0.90311190}],"asks":[],"checksum":289668989,"timestamp":"2024-06-01T18:06:17.676636Z"}]}
{"channel":"book","type":"update","data":[{"symbol":"ETH/CAD","bids":[{"price":5188.58,"qty":0.00000000},{"price":5183.79,"qty":2.21000000}],"asks":[],"checksum":3668996160,"timestamp":"2024-06-01T18:06:17.681343Z"}]}
{"channel":"book","type":"update","data":[{"symbol":"ETH/CAD","bids":[{"price":5188.61,"qty":0.00000000},{"price":5183.60,"qty":2.18000000},{"price":5188.63,"qty":1.02448411}],"asks":[],"checksum":1286901092,"timestamp":"2024-06-01T18:06:17.822352Z"}]}
{"channel":"book","type":"update","data":[{"symbol":"ETH/CAD","bids":[{"price":5188.63,"qty":0.00000000},{"price":5183.60,"qty":2.18000000},{"price":5188.64,"qty":1.02448214}],"asks":[],"checksum":2169523943,"timestamp":"2024-06-01T18:06:18.540320Z"}]}
{"channel":"book","type":"update","data":[{"symbol":"ETH/CAD","bids":[{"price":5188.65,"qty":0.90311190}],"asks":[],"checksum":1247292135,"timestamp":"2024-06-01T18:06:18.545359Z"}]}
{"channel":"book","type":"update","data":[{"symbol":"ETH/CAD","bids":[],"asks":[{"price":5196.72,"qty":0.00000000},{"price":5196.90,"qty":1.17000000}],"checksum":3500933637,"timestamp":"2024-06-01T18:06:18.631833Z"}]}
{"channel":"book","type":"update","data":[{"symbol":"ETH/CAD","bids":[],"asks":[{"price":5196.69,"qty":0.07382218}],"checksum":3826561723,"timestamp":"2024-06-01T18:06:18.633963Z"}]}
{"channel":"book","type":"update","data":[{"symbol":"ETH/CAD","bids":[{"price":5188.62,"qty":0.00000000},{"price":5183.79,"qty":2.21000000}],"asks":[],"checksum":3551532149,"timestamp":"2024-06-01T18:06:18.677509Z"}]}
{"channel":"book","type":"update","data":[{"symbol":"ETH/CAD","bids":[],"asks":[{"price":5196.71,"qty":0.00000000},{"price":5196.90,"qty":1.17000000}],"checksum":2330158676,"timestamp":"2024-06-01T18:06:19.023024Z"}]}
{"channel":"book","type":"update","data":[{"symbol":"ETH/CAD","bids":[],"asks":[{"price":5196.70,"qty":0.20717085},{"price":5196.89,"qty":1.31700000}],"checksum":766163026,"timestamp":"2024-06-01T18:06:19.026212Z"}]}
{"channel":"book","type":"update","data":[{"symbol":"ETH/CAD","bids":[],"asks":[{"price":5196.68,"qty":8.79188830}],"checksum":127299279,"timestamp":"2024-06-01T18:06:19.028084Z"}]}
{"channel":"book","type":"update","data":[{"symbol":"ETH/CAD","bids":[],"asks":[{"price":5196.70,"qty":0.00000000},{"price":5196.89,"qty":1.31700000}],"checksum":2070621319,"timestamp":"2024-06-01T18:06:19.031708Z"}]}
{"channel":"book","type":"update","data":[{"symbol":"ETH/CAD","bids":[],"asks":[{"price":5196.67,"qty":0.20717085}],"checksum":1866875591,"timestamp":"2024-06-01T18:06:19.031892Z"}]}
{"channel":"book","type":"update","data":[{"symbol":"ETH/CAD","bids":[{"price":5188.60,"qty":0.00000000},{"price":5183.60,"qty":2.18000000},{"price":5188.66,"qty":0.58849631}],"asks":[],"checksum":2066474334,"timestamp":"2024-06-01T18:06:19.050653Z"}]}
{"channel":"book","type":"update","data":[{"symbol":"ETH/CAD","bids":[],"asks":[{"price":5191.99,"qty":0.00000000},{"price":5196.89,"qty":1.31700000}],"checksum":3474161265,"timestamp":"2024-06-01T18:06:19.053647Z"}]}
{"channel":"book","type":"update","data":[{"symbol":"ETH/CAD","bids":[{"price":5188.67,"qty":0.90311190}],"asks":[],"checksum":2172099094,"timestamp":"2024-06-01T18:06:19.055546Z"}]}
{"channel":"book","type":"update","data":[{"symbol":"ETH/CAD","bids":[],"asks":[{"price":5192.25,"qty":7.76003471}],"checksum":3848014923,"timestamp":"2024-06-01T18:06:19.056837Z"}]}
{"channel":"book","type":"update","data":[{"symbol":"ETH/CAD","bids":[],"asks":[{"price":5191.51,"qty":0.31150369}],"checksum":2910439561,"timestamp":"2024-06-01T18:06:19.081264Z"}]}
{"channel":"book","type":"update","data":[{"symbol":"ETH/CAD","bids":[{"price":5188.65,"qty":0.00000000},{"price":5183.79,"qty":2.21000000}],"asks":[],"checksum":3864090404,"timestamp":"2024-06-01T18:06:19.087046Z"}]}
{"channel":"book","type":"update","data":[{"symbol":"ETH/CAD","bids":[{"price":5188.66,"qty":0.00000000},{"price":5183.60,"qty":2.18000000},{"price":5188.68,"qty":0.58849631}],"asks":[],"checksum":2298865304,"timestamp":"2024-06-01T18:06:19.112949Z"}]}
{"channel":"book","type":"update","data":[{"symbol":"ETH/CAD","bids":[{"price":5184.52,"qty":0.00000000},{"price":5183.60,"qty":2.18000000}],"asks":[],"checksum":3867195056,"timestamp":"2024-06-01T18:06:19.188784Z"}]}
{"channel":"book","type":"update","data":[{"symbol":"ETH/CAD","bids":[{"price":5184.54,"qty":0.02066249}],"asks":[],"checksum":1189906520,"timestamp":"2024-06-01T18:06:19.189509Z"}]}
{"channel":"book","type":"update","data":[{"symbol":"ETH/CAD","bids":[],"asks":[{"price":5191.52,"qty":0.00000000},{"price":5196.69,"qty":0.07382218},{"price":5191.50,"qty":0.73413084}],"checksum":552706351,"timestamp":"2024-06-01T18:06:19.215283Z"}]}
{"channel":"book","type":"update","data":[{"symbol":"ETH/CAD","bids":[{"price":5188.64,"qty":0.00000000},{"price":5183.60,"qty":2.18000000},{"price":5188.69,"qty":1.02447234}],"asks":[],"checksum":1954210838,"timestamp":"2024-06-01T18:06:19.215309Z"}]}
{"channel":"book","type":"update","data":[{"symbol":"ETH/CAD","bids":[{"price":5188.69,"qty":1.92758424}],"asks":[],"checksum":1807589259,"timestamp":"2024-06-01T18:06:19.220461Z"}]}
{"channel":"book","type":"update","data":[{"symbol":"ETH/CAD","bids":[{"price":5188.68,"qty":0.00000000},{"price":5183.60,"qty":2.18000000},{"price":5188.70,"qty":0.58849631}],"asks":[],"checksum":580596565,"timestamp":"2024-06-01T18:06:19.237833Z"}]}
{"channel":"book","type":"update","data":[{"symbol":"ETH/CAD","bids":[],"asks":[{"price":5191.51,"qty":0.00000000},{"price":5196.69,"qty":0.07382218},{"price":5191.49,"qty":0.31150369}],"checksum":2225501471,"timestamp":"2024-06-01T18:06:19.269740Z"}]}
{"channel":"book","type":"update","data":[{"symbol":"ETH/CAD","bids":[{"price":5188.69,"qty":1.02447234}],"asks":[],"checksum":565303424,"timestamp":"2024-06-01T18:06:19.275464Z"}]}
{"channel":"book","type":"update","data":[{"symbol":"ETH/CAD","bids":[{"price":5188.69,"qty":0.00000000},{"price":5183.60,"qty":2.18000000},{"price":5188.71,"qty":1.02448966}],"asks":[],"checksum":868726112,"timestamp":"2024-06-01T18:06:19.887008Z"}]}
{"channel":"book","type":"update","data":[{"symbol":"ETH/CAD","bids":[],"asks":[{"price":5191.50,"qty":0.00000000},{"price":5196.69,"qty":0.07382218},{"price":5191.48,"qty":0.73410136}],"checksum":3948989791,"timestamp":"2024-06-01T18:06:19.887037Z"}]}
{"channel":"book","type":"update","data":[{"symbol":"ETH/CAD","bids":[],"asks":[{"price":5196.67,"qty":1.52417085}],"checksum":1978596434,"timestamp":"2024-06-01T18:06:19.889979Z"}]}
{"channel":"book","type":"update","data":[{"symbol":"ETH/CAD","bids":[{"price":5188.70,"qty":0.00000000},{"price":5183.60,"qty":2.18000000},{"price":5188.72,"qty":0.58849631}],"asks":[],"checksum":4269505504,"timestamp":"2024-06-01T18:06:19.908429Z"}]}
{"channel":"book","type":"update","data":[{"symbol":"ETH/CAD","bids":[],"asks":[{"price":5191.49,"qty":0.00000000},{"price":5196.69,"qty":0.07382218},{"price":5191.47,"qty":0.31150369}],"checksum":1724016588,"timestamp":"2024-06-01T18:06:20.243110Z"}]}
{"channel":"book","type":"update","data":[{"symbol":"ETH/CAD","bids":[{"price":5188.73,"qty":0.90311190}],"asks":[],"checksum":3030897717,"timestamp":"2024-06-01T18:06:20.248109Z"}]}
{"channel":"book","type":"update","data":[{"symbol":"ETH/CAD","bids":[{"price":5184.53,"qty":0.00000000},{"price":5183.79,"qty":2.21000000}],"asks":[],"checksum":2600480413,"timestamp":"2024-06-01T18:06:20.250854Z"}]}
{"channel":"book","type":"update","data":[{"symbol":"ETH/CAD","bids":[{"price":5184.44,"qty":6.17305320}],"asks":[],"checksum":690844268,"timestamp":"2024-06-01T18:06:20.252486Z"}]}
{"channel":"book","type":"update","data":[{"symbol":"ETH/CAD","bids":[{"price":5186.65,"qty":0.00000000},{"price":5183.79,"qty":2.21000000}],"asks":[],"checksum":3483552850,"timestamp":"2024-06-01T18:06:20.329604Z"}]}
{"channel":"book","type":"update","data":[{"symbol":"ETH/CAD","bids":[{"price":5186.58,"qty":0.58543658}],"asks":[],"checksum":3866543316,"timestamp":"2024-06-01T18:06:20.334677Z"}]}
{"channel":"book","type":"update","data":[{"symbol":"ETH/CAD","bids":[{"price":5186.58,"qty":0.00000000},{"price":5183.79,"qty":2.21000000}],"asks":[],"checksum":3483552850,"timestamp":"2024-06-01T18:06:20.338533Z"}]}
{"channel":"book","type":"update","data":[{"symbol":"ETH/CAD","bids":[{"price":5186.43,"qty":0.58543654}],"asks":[],"checksum":1477835712,"timestamp":"2024-06-01T18:06:20.343267Z"}]}
{"channel":"book","type":"update","data":[{"symbol":"ETH/CAD","bids":[{"price":5184.43,"qty":0.00000000},{"price":5183.79,"qty":2.21000000}],"asks":[],"checksum":1821239296,"timestamp":"2024-06-01T18:06:20.353943Z"}]}
{"channel":"book","type":"update","data":[{"symbol":"ETH/CAD","bids":[{"price":5186.43,"qty":0.00000000},{"price":5183.60,"qty":2.18000000}],"asks":[],"checksum":784381378,"timestamp":"2024-06-01T18:06:20.386582Z"}]}
{"channel":"book","type":"update","data":[{"symbol":"ETH/CAD","bids":[{"price":5183.85,"qty":1.31700000}],"asks":[],"checksum":4170860938,"timestamp":"2024-06-01T18:06:20.389784Z"}]}
{"channel":"book","type":"update","data":[{"symbol":"ETH/CAD","bids":[{"price":5186.27,"qty":0.58543649}],"asks":[],"checksum":2157401072,"timestamp":"2024-06-01T18:06:20.391117Z"}]}
{"channel":"book","type":"update","data":[{"symbol":"ETH/CAD","bids":[],"asks":[{"price":5196.67,"qty":0.20717085},{"price":5194.49,"qty":1.31700000}],"checksum":2500690727,"timestamp":"2024-06-01T18:06:20.393128Z"}]}
{"channel":"book","type":"update","data":[{"symbol":"ETH/CAD","bids":[{"price":5186.27,"qty":0.00000000},{"price":5183.79,"qty":2.21000000}],"asks":[],"checksum":3761804333,"timestamp":"2024-06-01T18:06:20.453493Z"}]}
{"channel":"book","type":"update","data":[{"symbol":"ETH/CAD","bids":[{"price":5186.24,"qty":0.58543649}],"asks":[],"checksum":1329034246,"timestamp":"2024-06-01T18:06:20.458107Z"}]}
{"channel":"book","type":"update","data":[{"symbol":"ETH/CAD","bids":[{"price":5188.71,"qty":0.00000000},{"price":5183.79,"qty":2.21000000},{"price":5188.74,"qty":1.02448466}],"asks":[],"checksum":2544963710,"timestamp":"2024-06-01T18:06:20.620715Z"}]}
{"channel":"book","type":"update","data":[{"symbol":"ETH/CAD","bids":[],"asks":[{"price":5191.48,"qty":0.00000000},{"price":5196.68,"qty":8.79188830},{"price":5191.46,"qty":0.73410675}],"checksum":3637552470,"timestamp":"2024-06-01T18:06:20.620958Z"}]}
{"channel":"book","type":"update","data":[{"symbol":"ETH/CAD","bids":[{"price":5188.73,"qty":0.00000000},{"price":5183.79,"qty":2.21000000}],"asks":[],"checksum":295007721,"timestamp":"2024-06-01T18:06:20.626170Z"}]}
{"channel":"book","type":"update","data":[{"symbol":"ETH/CAD","bids":[{"price":5188.74,"qty":0.00000000},{"price":5183.60,"qty":2.18000000},{"price":5188.73,"qty":1.02448669}],"asks":[],"checksum":435270309,"timestamp":"2024-06-01T18:06:20.683715Z"}]}
{"channel":"book","type":"update","data":[{"symbol":"ETH/CAD","bids":[{"price":5186.24,"qty":0.00000000},{"price":5183.60,"qty":2.18000000}],"asks":[],"checksum":2421066940,"timestamp":"2024-06-01T18:06:20.825012Z"}]}
{"channel":"book","type":"update","data":[{"symbol":"ETH/CAD","bids":[{"price":5186.17,"qty":0.58543157}],"asks":[],"checksum":3736622182,"timestamp":"2024-06-01T18:06:20.829166Z"}]}
{"channel":"book","type":"update","data":[{"symbol":"ETH/CAD","bids":[{"price":5188.67,"qty":0.00000000},{"price":5183.60,"qty":2.18000000}],"asks":[],"checksum":1891440905,"timestamp":"2024-06-01T18:06:20.905333Z"}]}
{"channel":"book","type":"update","data":[{"symbol":"ETH/CAD","bids":[{"price":5186.17,"qty":0.00000000},{"price":5183.39,"qty":1.84146195}],"asks":[],"checksum":732346660,"timestamp":"2024-06-01T18:06:20.907894Z"}]}
{"channel":"book","type":"update","data":[{"symbol":"ETH/CAD","bids":[{"price":5186.11,"qty":0.58543155}],"asks":[],"checksum":1890824052,"timestamp":"2024-06-01T18:06:20.912646Z"}]}
{"channel":"book","type":"update","data":[{"symbol":"ETH/CAD","bids":[{"price":5188.72,"qty":0.00000000},{"price":5183.39,"qty":1.84146195}],"asks":[],"checksum":2452180028,"timestamp":"2024-06-01T18:06:20.922141Z"}]}
{"channel":"book","type":"update","data":[{"symbol":"ETH/CAD","bids":[{"price":5188.73,"qty":0.00000000},{"price":5181.59,"qty":0.94000000},{"price":5186.12,"qty":1.02500229}],"asks":[],"checksum":136242662,"timestamp":"2024-06-01T18:06:20.983884Z"}]}
{"channel":"book","type":"update","data":[{"symbol":"ETH/CAD","bids":[],"asks":[{"price":5196.66,"qty":0.05462589}],"checksum":3302490122,"timestamp":"2024-06-01T18:06:21.264502Z"}]}
{"channel":"book","type":"update","data":[{"symbol":"ETH/CAD","bids":[],"asks":[{"price":5191.46,"qty":0.00000000},{"price":5196.67,"qty":0.20717085},{"price":5190.85,"qty":0.73410675}],"checksum":3119623728,"timestamp":"2024-06-01T18:06:21.337503Z"}]}
{"channel":"book","type":"update","data":[{"symbol":"ETH/CAD","bids":[],"asks":[{"price":5190.84,"qty":0.90311190}],"checksum":1468271121,"timestamp":"2024-06-01T18:06:21.343411Z"}]}
{"channel":"book","type":"update","data":[{"symbol":"ETH/CAD","bids":[{"price":5188.38,"qty":0.90311190}],"asks":[],"checksum":2495436061,"timestamp":"2024-06-01T18:06:21.343482Z"}]}
{"channel":"book","type":"update","data":[{"symbol":"ETH/CAD","bids":[{"price":5186.11,"qty":0.00000000},{"price":5183.39,"qty":1.84146195}],"asks":[],"checksum":523005474,"timestamp":"2024-06-01T18:06:21.382818Z"}]}
{"channel":"book","type":"update","data":[{"symbol":"ETH/CAD","bids":[{"price":5185.90,"qty":0.58545241}],"asks":[],"checksum":501097694,"timestamp":"2024-06-01T18:06:21.386705Z"}]}
{"channel":"book","type":"update","data":[{"symbol":"ETH/CAD","bids":[],"asks":[{"price":5191.53,"qty":0.00000000},{"price":5196.66,"qty":0.05462589}],"checksum":3228432345,"timestamp":"2024-06-01T18:06:21.389366Z"}]}
{"channel":"book","type":"update","data":[{"symbol":"ETH/CAD","bids":[{"price":5183.85,"qty":0.00000000},{"price":5183.39,"qty":1.84146195},{"price":5183.80,"qty":1.31700000}],"asks":[],"checksum":3215468097,"timestamp":"2024-06-01T18:06:21.397340Z"}]}
{"channel":"book","type":"update","data":[{"symbol":"ETH/CAD","bids":[{"price":5188.37,"qty":0.00000000},{"price":5183.39,"qty":1.84146195},{"price":5186.13,"qty":0.06654700}],"asks":[],"checksum":4000801285,"timestamp":"2024-06-01T18:06:21.440830Z"}]}
{"channel":"book","type":"update","data":[{"symbol":"ETH/CAD","bids":[{"price":5188.39,"qty":0.58849631}],"asks":[],"checksum":354075521,"timestamp":"2024-06-01T18:06:21.777810Z"}]}
{"channel":"book","type":"update","data":[{"symbol":"ETH/CAD","bids":[],"asks":[{"price":5191.47,"qty":0.00000000},{"price":5196.67,"qty":0.20717085},{"price":5190.83,"qty":0.31150369}],"checksum":941283860,"timestamp":"2024-06-01T18:06:22.052536Z"}]}
{"channel":"book","type":"update","data":[{"symbol":"ETH/CAD","bids":[],"asks":[{"price":5190.85,"qty":0.00000000},{"price":5196.67,"qty":0.20717085},{"price":5190.82,"qty":0.73404333}],"checksum":517282184,"timestamp":"2024-06-01T18:06:22.116854Z"}]}
{"channel":"book","type":"update","data":[{"symbol":"ETH/CAD","bids":[],"asks":[{"price":5190.83,"qty":0.00000000},{"price":5196.67,"qty":0.20717085},{"price":5190.81,"qty":0.31150369}],"checksum":401955516,"timestamp":"2024-06-01T18:06:22.145599Z"}]}
{"channel":"book","type":"update","data":[{"symbol":"ETH/CAD","bids":[{"price":5184.54,"qty":0.00000000},{"price":5183.60,"qty":2.18000000}],"asks":[],"checksum":1918278256,"timestamp":"2024-06-01T18:06:22.457679Z"}]}
{"channel":"book","type":"update","data":[{"symbol":"ETH/CAD","bids":[{"price":5184.45,"qty":0.01039701}],"asks":[],"checksum":3022666848,"timestamp":"2024-06-01T18:06:22.459038Z"}]}
{"channel":"book","type":"update","data":[{"symbol":"ETH/CAD","bids":[{"price":5186.13,"qty":0.00000000},{"price":5183.60,"qty":2.18000000},{"price":5188.30,"qty":0.06653200}],"asks":[],"checksum":1882831207,"timestamp":"2024-06-01T18:06:22.633492Z"}]}
{"channel":"book","type":"update","data":[{"symbol":"ETH/CAD","bids":[],"asks":[{"price":5190.80,"qty":0.90311190}],"checksum":3957514202,"timestamp":"2024-06-01T18:06:22.649452Z"}]}
{"channel":"book","type":"update","data":[{"symbol":"ETH/CAD","bids":[],"asks":[{"price":5190.81,"qty":0.00000000},{"price":5196.66,"qty":0.05462589},{"price":5190.79,"qty":0.31150369}],"checksum":95382023,"timestamp":"2024-06-01T18:06:22.662827Z"}]}
{"channel":"book","type":"update","data":[{"symbol":"ETH/CAD","bids":[],"asks":[{"price":5190.80,"qty":0.00000000},{"price":5196.66,"qty":0.05462589}],"checksum":640168791,"timestamp":"2024-06-01T18:06:22.678257Z"}]}
{"channel":"book","type":"update","data":[{"symbol":"ETH/CAD","bids":[{"price":5186.12,"qty":0.00000000},{"price":5183.60,"qty":2.18000000},{"price":5188.40,"qty":1.02455885}],"asks":[],"checksum":2334011955,"timestamp":"2024-06-01T18:06:22.899798Z"}]}
{"channel":"book","type":"update","data":[{"symbol":"ETH/CAD","bids":[{"price":5188.39,"qty":0.00000000},{"price":5183.60,"qty":2.18000000},{"price":5188.41,"qty":0.58849631}],"asks":[],"checksum":356446108,"timestamp":"2024-06-01T18:06:22.906779Z"}]}
{"channel":"book","type":"update","data":[{"symbol":"ETH/CAD","bids":[{"price":5184.44,"qty":0.00000000},{"price":5183.60,"qty":2.18000000}],"asks":[],"checksum":2158766308,"timestamp":"2024-06-01T18:06:23.238301Z"}]}
{"channel":"book","type":"update","data":[{"symbol":"ETH/CAD","bids":[{"price":5184.43,"qty":5.11502069}],"asks":[],"checksum":2110231053,"timestamp":"2024-06-01T18:06:23.239439Z"}]}
{"channel":"book","type":"update","data":[{"symbol":"ETH/CAD","bids":[{"price":5188.40,"qty":0.00000000},{"price":5183.60,"qty":2.18000000},{"price":5188.42,"qty":1.02534098}],"asks":[],"checksum":557208926,"timestamp":"2024-06-01T18:06:23.622565Z"}]}
{"channel":"book","type":"update","data":[{"symbol":"ETH/CAD","bids":[],"asks":[{"price":5190.82,"qty":0.00000000},{"price":5196.67,"qty":0.20717085},{"price":5190.78,"qty":0.73404337}],"checksum":847827499,"timestamp":"2024-06-01T18:06:23.622644Z"}]}
{"channel":"book","type":"update","data":[{"symbol":"ETH/CAD","bids":[],"asks":[{"price":5190.78,"qty":1.63715527}],"checksum":2099918088,"timestamp":"2024-06-01T18:06:23.629427Z"}]}
{"channel":"book","type":"update","data":[{"symbol":"ETH/CAD","bids":[{"price":5188.41,"qty":0.00000000},{"price":5183.60,"qty":2.18000000},{"price":5188.43,"qty":0.58849631}],"asks":[],"checksum":324304135,"timestamp":"2024-06-01T18:06:23.636391Z"}]}
{"channel":"book","type":"update","data":[{"symbol":"ETH/CAD","bids":[],"asks":[{"price":5192.24,"qty":0.52627463}],"checksum":1722934145,"timestamp":"2024-06-01T18:06:23.673223Z"}]}
{"channel":"book","type":"update","data":[{"symbol":"ETH/CAD","bids":[],"asks":[{"price":5190.78,"qty":0.73404337}],"checksum":3298373652,"timestamp":"2024-06-01T18:06:23.678459Z"}]}
{"channel":"book","type":"update","data":[{"symbol":"ETH/CAD","bids":[{"price":5185.90,"qty":0.00000000},{"price":5183.60,"qty":2.18000000}],"asks":[],"checksum":352377928,"timestamp":"2024-06-01T18:06:23.721852Z"}]}
{"channel":"book","type":"update","data":[{"symbol":"ETH/CAD","bids":[{"price":5188.38,"qty":0.00000000},{"price":5183.39,"qty":1.84146195}],"asks":[],"checksum":3279289944,"timestamp":"2024-06-01T18:06:23.722461Z"}]}
{"channel":"book","type":"update","data":[{"symbol":"ETH/CAD","bids":[{"price":5185.83,"qty":0.58544312}],"asks":[],"checksum":905895779,"timestamp":"2024-06-01T18:06:23.725861Z"}]}
{"channel":"book","type":"update","data":[{"symbol":"ETH/CAD","bids":[{"price":5185.83,"qty":0.00000000},{"price":5183.39,"qty":1.84146195}],"asks":[],"checksum":3279289944,"timestamp":"2024-06-01T18:06:23.728275Z"}]}
{"channel":"book","type":"update","data":[{"symbol":"ETH/CAD","bids":[{"price":5188.43,"qty":0.00000000},{"price":5181.59,"qty":0.94000000}],"asks":[],"checksum":911800912,"timestamp":"2024-06-01T18:06:23.731726Z"}]}
{"channel":"book","type":"update","data":[{"symbol":"ETH/CAD","bids":[{"price":5185.66,"qty":0.58544307}],"asks":[],"checksum":1710039179,"timestamp":"2024-06-01T18:06:23.733720Z"}]}
{"channel":"book","type":"update","data":[{"symbol":"ETH/CAD","bids":[{"price":5188.42,"qty":0.00000000},{"price":5181.59,"qty":0.94000000},{"price":5185.67,"qty":1.02588425}],"asks":[],"checksum":3264461842,"timestamp":"2024-06-01T18:06:23.784131Z"}]}
{"channel":"book","type":"update","data":[{"symbol":"ETH/CAD","bids":[],"asks":[{"price":5190.77,"qty":0.90311190}],"checksum":659906258,"timestamp":"2024-06-01T18:06:24.679843Z"}]}
{"channel":"book","type":"update","data":[{"symbol":"ETH/CAD","bids":[{"price":5187.64,"qty":0.90311190}],"asks":[],"checksum":2105587860,"timestamp":"2024-06-01T18:06:24.679900Z"}]}
{"channel":"book","type":"update","data":[{"symbol":"ETH/CAD","bids":[],"asks":[{"price":5190.84,"qty":0.00000000},{"price":5195.31,"qty":0.12100000}],"checksum":216073841,"timestamp":"2024-06-01T18:06:24.685626Z"}]}
{"channel":"book","type":"update","data":[{"symbol":"ETH/CAD","bids":[{"price":5187.65,"qty":0.58849631}],"asks":[],"checksum":3271934565,"timestamp":"2024-06-01T18:06:24.703492Z"}]}
{"channel":"book","type":"update","data":[{"symbol":"ETH/CAD","bids":[{"price":5185.67,"qty":0.00000000},{"price":5183.60,"qty":2.18000000},{"price":5188.31,"qty":1.02536244}],"asks":[],"checksum":2886334317,"timestamp":"2024-06-01T18:06:24.753041Z"}]}
{"channel":"book","type":"update","data":[{"symbol":"ETH/CAD","bids":[],"asks":[{"price":5190.78,"qty":0.00000000},{"price":5196.67,"qty":0.20717085},{"price":5190.76,"qty":0.73401674}],"checksum":2666069849,"timestamp":"2024-06-01T18:06:24.753074Z"}]}
{"channel":"book","type":"update","data":[{"symbol":"ETH/CAD","bids":[{"price":5188.30,"qty":0.00000000},{"price":5183.60,"qty":2.18000000},{"price":5187.65,"qty":0.65503331}],"asks":[],"checksum":4197524687,"timestamp":"2024-06-01T18:06:24.854505Z"}]}
