{"channel":"book","type":"snapshot","data":[{"symbol":"EUR/CAD","bids":[{"price":1.47888,"qty":4368.45582556},{"price":1.47887,"qty":215.97993738},{"price":1.47770,"qty":49.77700000},{"price":1.47498,"qty":3472.56233000},{"price":1.47497,"qty":1442.59428894},{"price":1.47333,"qty":50.00000000},{"price":1.47010,"qty":500.18604176},{"price":1.47000,"qty":77.70000000},{"price":1.46905,"qty":5761.14008739},{"price":1.46889,"qty":5.00000000}],"asks":[{"price":1.48220,"qty":225.72210000},{"price":1.48221,"qty":216.03373582},{"price":1.48383,"qty":364.76560904},{"price":1.48384,"qty":3254.42934136},{"price":1.48880,"qty":50.00000000},{"price":1.48975,"qty":13029.35968979},{"price":1.49000,"qty":55.99990000},{"price":1.49123,"qty":50.69794167},{"price":1.49486,"qty":5.00000000},{"price":1.49500,"qty":79.00000000}],"checksum":2908302097}]}
{"channel":"book","type":"update","data":[{"symbol":"EUR/CAD","bids":[{"price":1.47889,"qty":615.46908155}],"asks":[],"checksum":213296694,"timestamp":"2024-06-01T18:06:08.731477Z"}]}
{"channel":"book","type":"update","data":[{"symbol":"EUR/CAD","bids":[{"price":1.47888,"qty":0.00000000},{"price":1.46889,"qty":5.00000000}],"asks":[],"checksum":904070171,"timestamp":"2024-06-01T18:06:08.736514Z"}]}
{"channel":"book","type":"update","data":[{"symbol":"EUR/CAD","bids":[{"price":1.47890,"qty":4368.39674318}],"asks":[],"checksum":4149901812,"timestamp":"2024-06-01T18:06:08.736526Z"}]}
{"channel":"book","type":"update","data":[{"symbol":"EUR/CAD","bids":[{"price":1.47889,"qty":0.00000000},{"price":1.46889,"qty":5.00000000}],"asks":[],"checksum":3688023396,"timestamp":"2024-06-01T18:06:08.815339Z"}]}
{"channel":"book","type":"update","data":[{"symbol":"EUR/CAD","bids":[{"price":1.47891,"qty":578.57405511}],"asks":[],"checksum":22506333,"timestamp":"2024-06-01T18:06:08.911918Z"}]}
{"channel":"book","type":"update","data":[{"symbol":"EUR/CAD","bids":[{"price":1.47892,"qty":4368.33768605}],"asks":[],"checksum":1767569166,"timestamp":"2024-06-01T18:06:08.916078Z"}]}
{"channel":"book","type":"update","data":[{"symbol":"EUR/CAD","bids":[{"price":1.47890,"qty":0.00000000},{"price":1.46905,"qty":5761.14008739}],"asks":[],"checksum":2420486325,"timestamp":"2024-06-01T18:06:08.916096Z"}]}
{"channel":"book","type":"update","data":[{"symbol":"EUR/CAD","bids":[{"price":1.47891,"qty":0.00000000},{"price":1.46889,"qty":5.00000000}],"asks":[],"checksum":4277777855,"timestamp":"2024-06-01T18:06:09.011669Z"}]}
{"channel":"book","type":"update","data":[{"symbol":"EUR/CAD","bids":[{"price":1.47893,"qty":566.31785451}],"asks":[],"checksum":884267361,"timestamp":"2024-06-01T18:06:18.735861Z"}]}
{"channel":"book","type":"update","data":[{"symbol":"EUR/CAD","bids":[{"price":1.47894,"qty":4368.27859584}],"asks":[],"checksum":2878092186,"timestamp":"2024-06-01T18:06:18.745829Z"}]}
{"channel":"book","type":"update","data":[{"symbol":"EUR/CAD","bids":[{"price":1.47892,"qty":0.00000000},{"price":1.46905,"qty":5761.14008739}],"asks":[],"checksum":2620620071,"timestamp":"2024-06-01T18:06:18.745899Z"}]}
{"channel":"book","type":"update","data":[{"symbol":"EUR/CAD","bids":[{"price":1.47893,"qty":0.00000000},{"price":1.46889,"qty":5.00000000}],"asks":[],"checksum":2593639347,"timestamp":"2024-06-01T18:06:18.821550Z"}]}
{"channel":"book","type":"update","data":[{"symbol":"EUR/CAD","bids":[{"price":1.47895,"qty":608.58577096}],"asks":[],"checksum":2742256166,"timestamp":"2024-06-01T18:06:18.921850Z"}]}
{"channel":"book","type":"update","data":[{"symbol":"EUR/CAD","bids":[{"price":1.47894,"qty":0.00000000},{"price":1.46889,"qty":5.00000000}],"asks":[],"checksum":2079576892,"timestamp":"2024-06-01T18:06:18.934677Z"}]}
{"channel":"book","type":"update","data":[{"symbol":"EUR/CAD","bids":[{"price":1.47896,"qty":4368.21955182}],"asks":[],"checksum":949369095,"timestamp":"2024-06-01T18:06:18.934731Z"}]}
{"channel":"book","type":"update","data":[{"symbol":"EUR/CAD","bids":[{"price":1.47895,"qty":0.00000000},{"price":1.46889,"qty":5.00000000}],"asks":[],"checksum":439486601,"timestamp":"2024-06-01T18:06:19.022247Z"}]}
{"channel":"book","type":"update","data":[{"symbol":"EUR/CAD","bids":[{"price":1.47897,"qty":592.62524048}],"asks":[],"checksum":1058045055,"timestamp":"2024-06-01T18:06:19.122128Z"}]}
{"channel":"book","type":"update","data":[{"symbol":"EUR/CAD","bids":[{"price":1.47898,"qty":4368.16044178}],"asks":[],"checksum":3200675707,"timestamp":"2024-06-01T18:06:19.131864Z"}]}
{"channel":"book","type":"update","data":[{"symbol":"EUR/CAD","bids":[{"price":1.47896,"qty":0.00000000},{"price":1.46905,"qty":5761.14008739}],"asks":[],"checksum":251206847,"timestamp":"2024-06-01T18:06:19.131984Z"}]}
{"channel":"book","type":"update","data":[{"symbol":"EUR/CAD","bids":[{"price":1.47897,"qty":0.00000000},{"price":1.46889,"qty":5.00000000}],"asks":[],"checksum":1444716181,"timestamp":"2024-06-01T18:06:19.223423Z"}]}
{"channel":"book","type":"update","data":[{"symbol":"EUR/CAD","bids":[{"price":1.47888,"qty":4368.45580512}],"asks":[],"checksum":56323333,"timestamp":"2024-06-01T18:06:19.229679Z"}]}
{"channel":"book","type":"update","data":[{"symbol":"EUR/CAD","bids":[{"price":1.47898,"qty":0.00000000},{"price":1.46889,"qty":5.00000000}],"asks":[],"checksum":282438792,"timestamp":"2024-06-01T18:06:19.229821Z"}]}
{"channel":"book","type":"update","data":[{"symbol":"EUR/CAD","bids":[{"price":1.47889,"qty":599.33382009}],"asks":[],"checksum":4229868674,"timestamp":"2024-06-01T18:06:19.322232Z"}]}
{"channel":"book","type":"update","data":[{"symbol":"EUR/CAD","bids":[{"price":1.47888,"qty":0.00000000},{"price":1.46889,"qty":5.00000000}],"asks":[],"checksum":3042336790,"timestamp":"2024-06-01T18:06:19.333513Z"}]}
{"channel":"book","type":"update","data":[{"symbol":"EUR/CAD","bids":[{"price":1.47890,"qty":4368.39675630}],"asks":[],"checksum":1257016858,"timestamp":"2024-06-01T18:06:19.333649Z"}]}
{"channel":"book","type":"update","data":[{"symbol":"EUR/CAD","bids":[{"price":1.47889,"qty":0.00000000},{"price":1.46889,"qty":5.00000000}],"asks":[],"checksum":4017856305,"timestamp":"2024-06-01T18:06:19.422380Z"}]}
{"channel":"book","type":"update","data":[{"symbol":"EUR/CAD","bids":[{"price":1.47891,"qty":605.50775149}],"asks":[],"checksum":1906152767,"timestamp":"2024-06-01T18:06:23.738482Z"}]}
{"channel":"book","type":"update","data":[{"symbol":"EUR/CAD","bids":[{"price":1.47890,"qty":0.00000000},{"price":1.46889,"qty":5.00000000}],"asks":[],"checksum":2481713955,"timestamp":"2024-06-01T18:06:23.750868Z"}]}
{"channel":"book","type":"update","data":[{"symbol":"EUR/CAD","bids":[{"price":1.47892,"qty":4368.33764993}],"asks":[],"checksum":29384696,"timestamp":"2024-06-01T18:06:23.751065Z"}]}
{"channel":"book","type":"update","data":[{"symbol":"EUR/CAD","bids":[{"price":1.47891,"qty":0.00000000},{"price":1.46889,"qty":5.00000000}],"asks":[],"checksum":1048238353,"timestamp":"2024-06-01T18:06:23.826721Z"}]}
{"channel":"book","type":"update","data":[{"symbol":"EUR/CAD","bids":[{"price":1.47893,"qty":610.33958732}],"asks":[],"checksum":2223511594,"timestamp":"2024-06-01T18:06:23.926790Z"}]}
{"channel":"book","type":"update","data":[{"symbol":"EUR/CAD","bids":[{"price":1.47894,"qty":4368.27859226}],"asks":[],"checksum":3186836533,"timestamp":"2024-06-01T18:06:23.947737Z"}]}
{"channel":"book","type":"update","data":[{"symbol":"EUR/CAD","bids":[{"price":1.47892,"qty":0.00000000},{"price":1.46905,"qty":5761.14008739}],"asks":[],"checksum":1142246032,"timestamp":"2024-06-01T18:06:23.947797Z"}]}
{"channel":"book","type":"update","data":[{"symbol":"EUR/CAD","bids":[{"price":1.47893,"qty":0.00000000},{"price":1.46889,"qty":5.00000000}],"asks":[],"checksum":350276204,"timestamp":"2024-06-01T18:06:24.026754Z"}]}
{"channel":"book","type":"update","data":[{"symbol":"EUR/CAD","bids":[{"price":1.47895,"qty":570.09819748}],"asks":[],"checksum":3844754115,"timestamp":"2024-06-01T18:06:33.742317Z"}]}
{"channel":"book","type":"update","data":[{"symbol":"EUR/CAD","bids":[{"price":1.47896,"qty":4368.21951675}],"asks":[],"checksum":1433402272,"timestamp":"2024-06-01T18:06:33.759968Z"}]}
{"channel":"book","type":"update","data":[{"symbol":"EUR/CAD","bids":[{"price":1.47894,"qty":0.00000000},{"price":1.46905,"qty":5761.14008739}],"asks":[],"checksum":2657067691,"timestamp":"2024-06-01T18:06:33.760102Z"}]}
{"channel":"book","type":"update","data":[{"symbol":"EUR/CAD","bids":[{"price":1.47895,"qty":0.00000000},{"price":1.46889,"qty":5.00000000}],"asks":[],"checksum":374223890,"timestamp":"2024-06-01T18:06:33.836266Z"}]}
{"channel":"book","type":"update","data":[{"symbol":"EUR/CAD","bids":[{"price":1.47897,"qty":580.41005381}],"asks":[],"checksum":3252257808,"timestamp":"2024-06-01T18:06:33.936323Z"}]}
{"channel":"book","type":"update","data":[{"symbol":"EUR/CAD","bids":[{"price":1.47896,"qty":0.00000000},{"price":1.46889,"qty":5.00000000}],"asks":[],"checksum":3954628129,"timestamp":"2024-06-01T18:06:33.950360Z"}]}
{"channel":"book","type":"update","data":[{"symbol":"EUR/CAD","bids":[{"price":1.47898,"qty":4368.16046579}],"asks":[],"checksum":1173440109,"timestamp":"2024-06-01T18:06:33.950439Z"}]}
{"channel":"book","type":"update","data":[{"symbol":"EUR/CAD","bids":[{"price":1.47897,"qty":0.00000000},{"price":1.46889,"qty":5.00000000}],"asks":[],"checksum":3849038677,"timestamp":"2024-06-01T18:06:34.036541Z"}]}
{"channel":"book","type":"update","data":[{"symbol":"EUR/CAD","bids":[{"price":1.47898,"qty":0.00000000},{"price":1.46444,"qty":50.00000000}],"asks":[],"checksum":2246965875,"timestamp":"2024-06-01T18:06:34.041262Z"}]}
{"channel":"book","type":"update","data":[{"symbol":"EUR/CAD","bids":[{"price":1.47888,"qty":4368.45580185}],"asks":[],"checksum":542094973,"timestamp":"2024-06-01T18:06:34.041389Z"}]}
{"channel":"book","type":"update","data":[{"symbol":"EUR/CAD","bids":[{"price":1.47889,"qty":618.17499514}],"asks":[],"checksum":2867439846,"timestamp":"2024-06-01T18:06:34.136414Z"}]}
{"channel":"book","type":"update","data":[{"symbol":"EUR/CAD","bids":[{"price":1.47888,"qty":0.00000000},{"price":1.46889,"qty":5.00000000}],"asks":[],"checksum":4029569332,"timestamp":"2024-06-01T18:06:34.144784Z"}]}
{"channel":"book","type":"update","data":[{"symbol":"EUR/CAD","bids":[{"price":1.47890,"qty":4368.39673144}],"asks":[],"checksum":3412509128,"timestamp":"2024-06-01T18:06:34.144875Z"}]}
{"channel":"book","type":"update","data":[{"symbol":"EUR/CAD","bids":[{"price":1.47889,"qty":0.00000000},{"price":1.46889,"qty":5.00000000}],"asks":[],"checksum":1630707942,"timestamp":"2024-06-01T18:06:34.239829Z"}]}
{"channel":"book","type":"update","data":[{"symbol":"EUR/CAD","bids":[{"price":1.47891,"qty":588.70516678}],"asks":[],"checksum":1170333478,"timestamp":"2024-06-01T18:06:34.338914Z"}]}
{"channel":"book","type":"update","data":[{"symbol":"EUR/CAD","bids":[{"price":1.47890,"qty":0.00000000},{"price":1.46889,"qty":5.00000000}],"asks":[],"checksum":1224947637,"timestamp":"2024-06-01T18:06:34.342874Z"}]}
{"channel":"book","type":"update","data":[{"symbol":"EUR/CAD","bids":[{"price":1.47892,"qty":4368.33766263}],"asks":[],"checksum":3234763674,"timestamp":"2024-06-01T18:06:34.343128Z"}]}
{"channel":"book","type":"update","data":[{"symbol":"EUR/CAD","bids":[{"price":1.47891,"qty":0.00000000},{"price":1.46889,"qty":5.00000000}],"asks":[],"checksum":300343692,"timestamp":"2024-06-01T18:06:34.436832Z"}]}
{"channel":"book","type":"update","data":[{"symbol":"EUR/CAD","bids":[{"price":1.47893,"qty":619.31380019}],"asks":[],"checksum":3125035225,"timestamp":"2024-06-01T18:06:34.536911Z"}]}
{"channel":"book","type":"update","data":[{"symbol":"EUR/CAD","bids":[{"price":1.47892,"qty":0.00000000},{"price":1.46889,"qty":5.00000000}],"asks":[],"checksum":2000922391,"timestamp":"2024-06-01T18:06:34.559227Z"}]}
