{"channel":"book","type":"snapshot","data":[{"symbol":"EUR/GBP","bids":[{"price":0.85049,"qty":145.82255869},{"price":0.85048,"qty":250.80000000},{"price":0.85047,"qty":922.45852290},{"price":0.85042,"qty":922.52607352},{"price":0.85033,"qty":1383.93100450},{"price":0.85029,"qty":542.30355824},{"price":0.85025,"qty":2306.74101583},{"price":0.85003,"qty":493.66387068},{"price":0.85002,"qty":7239.99817929},{"price":0.85000,"qty":12554.33454840}],"asks":[{"price":0.85056,"qty":380.79155546},{"price":0.85060,"qty":922.33461036},{"price":0.85072,"qty":922.21381624},{"price":0.85083,"qty":225.72210000},{"price":0.85086,"qty":8204.95227889},{"price":0.85087,"qty":2305.11933298},{"price":0.85097,"qty":625.66181433},{"price":0.85098,"qty":826.02210000},{"price":0.85112,"qty":29696.99170066},{"price":0.85113,"qty":4610.06070893}],"checksum":3110333390}]}
{"channel":"book","type":"update","data":[{"symbol":"EUR/GBP","bids":[{"price":0.85003,"qty":0.00000000},{"price":0.84999,"qty":1833.00000000}],"asks":[],"checksum":1539682514,"timestamp":"2024-06-01T18:06:06.420414Z"}]}
{"channel":"book","type":"update","data":[{"symbol":"EUR/GBP","bids":[{"price":0.85026,"qty":493.53033189}],"asks":[],"checksum":2894332702,"timestamp":"2024-06-01T18:06:06.420665Z"}]}
{"channel":"book","type":"update","data":[{"symbol":"EUR/GBP","bids":[{"price":0.85026,"qty":0.00000000},{"price":0.84999,"qty":1833.00000000}],"asks":[],"checksum":1539682514,"timestamp":"2024-06-01T18:06:06.750626Z"}]}
{"channel":"book","type":"update","data":[{"symbol":"EUR/GBP","bids":[{"price":0.85003,"qty":493.66394954}],"asks":[],"checksum":3989091551,"timestamp":"2024-06-01T18:06:06.750875Z"}]}
{"channel":"book","type":"update","data":[{"symbol":"EUR/GBP","bids":[{"price":0.85026,"qty":493.53033189}],"asks":[],"checksum":4087474946,"timestamp":"2024-06-01T18:06:06.773211Z"}]}
{"channel":"book","type":"update","data":[{"symbol":"EUR/GBP","bids":[{"price":0.85003,"qty":0.00000000},{"price":0.85000,"qty":12554.33454840}],"asks":[],"checksum":2894332702,"timestamp":"2024-06-01T18:06:06.773442Z"}]}
{"channel":"book","type":"update","data":[{"symbol":"EUR/GBP","bids":[{"price":0.85000,"qty":0.00000000},{"price":0.84999,"qty":1833.00000000}],"asks":[],"checksum":1664604884,"timestamp":"2024-06-01T18:06:08.480649Z"}]}
{"channel":"book","type":"update","data":[{"symbol":"EUR/GBP","bids":[{"price":0.85002,"qty":0.00000000},{"price":0.84995,"qty":4615.04081268}],"asks":[],"checksum":1293024576,"timestamp":"2024-06-01T18:06:08.480785Z"}]}
{"channel":"book","type":"update","data":[{"symbol":"EUR/GBP","bids":[{"price":0.85034,"qty":1843.75979497}],"asks":[],"checksum":1275916233,"timestamp":"2024-06-01T18:06:08.482530Z"}]}
{"channel":"book","type":"update","data":[{"symbol":"EUR/GBP","bids":[{"price":0.85000,"qty":16188.71515294}],"asks":[],"checksum":1163482874,"timestamp":"2024-06-01T18:06:08.482665Z"}]}
{"channel":"book","type":"update","data":[{"symbol":"EUR/GBP","bids":[],"asks":[{"price":0.85112,"qty":0.00000000},{"price":0.85116,"qty":30832.00000000}],"checksum":586966922,"timestamp":"2024-06-01T18:06:12.004896Z"}]}
{"channel":"book","type":"update","data":[{"symbol":"EUR/GBP","bids":[],"asks":[{"price":0.85112,"qty":32290.89753311}],"checksum":254398596,"timestamp":"2024-06-01T18:06:12.009698Z"}]}
{"channel":"book","type":"update","data":[{"symbol":"EUR/GBP","bids":[{"price":0.85048,"qty":0.00000000},{"price":0.84999,"qty":1833.00000000},{"price":0.85050,"qty":250.80000000}],"asks":[],"checksum":584775921,"timestamp":"2024-06-01T18:06:12.035986Z"}]}
{"channel":"book","type":"update","data":[{"symbol":"EUR/GBP","bids":[{"price":0.85051,"qty":136.82326468}],"asks":[],"checksum":1598866117,"timestamp":"2024-06-01T18:06:12.228141Z"}]}
{"channel":"book","type":"update","data":[{"symbol":"EUR/GBP","bids":[{"price":0.85049,"qty":0.00000000},{"price":0.85000,"qty":16188.71515294}],"asks":[],"checksum":1051488156,"timestamp":"2024-06-01T18:06:12.395337Z"}]}
{"channel":"book","type":"update","data":[{"symbol":"EUR/GBP","bids":[],"asks":[{"price":0.85112,"qty":0.00000000},{"price":0.85116,"qty":30832.00000000}],"checksum":326752402,"timestamp":"2024-06-01T18:06:14.438803Z"}]}
{"channel":"book","type":"update","data":[{"symbol":"EUR/GBP","bids":[],"asks":[{"price":0.85112,"qty":31335.41710687}],"checksum":3492693991,"timestamp":"2024-06-01T18:06:14.443475Z"}]}
{"channel":"book","type":"update","data":[{"symbol":"EUR/GBP","bids":[],"asks":[{"price":0.85112,"qty":0.00000000},{"price":0.85116,"qty":30832.00000000}],"checksum":326752402,"timestamp":"2024-06-01T18:06:16.992253Z"}]}
{"channel":"book","type":"update","data":[{"symbol":"EUR/GBP","bids":[],"asks":[{"price":0.85112,"qty":32973.84251309}],"checksum":3744962600,"timestamp":"2024-06-01T18:06:16.997263Z"}]}
{"channel":"book","type":"update","data":[{"symbol":"EUR/GBP","bids":[],"asks":[{"price":0.85112,"qty":0.00000000},{"price":0.85116,"qty":30832.00000000}],"checksum":326752402,"timestamp":"2024-06-01T18:06:19.444409Z"}]}
{"channel":"book","type":"update","data":[{"symbol":"EUR/GBP","bids":[],"asks":[{"price":0.85112,"qty":30998.15213042}],"checksum":2066262344,"timestamp":"2024-06-01T18:06:19.448926Z"}]}
{"channel":"book","type":"update","data":[{"symbol":"EUR/GBP","bids":[],"asks":[{"price":0.85111,"qty":36.87519590}],"checksum":881050956,"timestamp":"2024-06-01T18:06:23.883501Z"}]}
{"channel":"book","type":"update","data":[{"symbol":"EUR/GBP","bids":[],"asks":[{"price":0.85111,"qty":0.00000000},{"price":0.85113,"qty":4610.06070893}],"checksum":2066262344,"timestamp":"2024-06-01T18:06:24.119171Z"}]}
{"channel":"book","type":"update","data":[{"symbol":"EUR/GBP","bids":[],"asks":[{"price":0.85112,"qty":0.00000000},{"price":0.85116,"qty":30832.00000000}],"checksum":326752402,"timestamp":"2024-06-01T18:06:24.476977Z"}]}
{"channel":"book","type":"update","data":[{"symbol":"EUR/GBP","bids":[],"asks":[{"price":0.85112,"qty":29696.99170066}],"checksum":1960634850,"timestamp":"2024-06-01T18:06:24.481849Z"}]}
{"channel":"book","type":"update","data":[{"symbol":"EUR/GBP","bids":[],"asks":[{"price":0.85112,"qty":0.00000000},{"price":0.85116,"qty":30832.00000000}],"checksum":326752402,"timestamp":"2024-06-01T18:06:26.825626Z"}]}
{"channel":"book","type":"update","data":[{"symbol":"EUR/GBP","bids":[],"asks":[{"price":0.85112,"qty":32973.84251309}],"checksum":3744962600,"timestamp":"2024-06-01T18:06:26.830381Z"}]}
{"channel":"book","type":"update","data":[{"symbol":"EUR/GBP","bids":[{"price":0.85001,"qty":493.67548617}],"asks":[],"checksum":3397123959,"timestamp":"2024-06-01T18:06:28.214938Z"}]}
{"channel":"book","type":"update","data":[{"symbol":"EUR/GBP","bids":[{"price":0.85026,"qty":0.00000000},{"price":0.85000,"qty":16188.71515294}],"asks":[],"checksum":2763000238,"timestamp":"2024-06-01T18:06:28.215035Z"}]}
{"channel":"book","type":"update","data":[{"symbol":"EUR/GBP","bids":[],"asks":[{"price":0.85112,"qty":0.00000000},{"price":0.85116,"qty":30832.00000000}],"checksum":1761495316,"timestamp":"2024-06-01T18:06:29.337673Z"}]}
{"channel":"book","type":"update","data":[{"symbol":"EUR/GBP","bids":[],"asks":[{"price":0.85112,"qty":39527.54413796}],"checksum":1996018667,"timestamp":"2024-06-01T18:06:29.342535Z"}]}
{"channel":"book","type":"update","data":[{"symbol":"EUR/GBP","bids":[{"price":0.85026,"qty":493.53033189}],"asks":[],"checksum":1251978330,"timestamp":"2024-06-01T18:06:29.379842Z"}]}
{"channel":"book","type":"update","data":[{"symbol":"EUR/GBP","bids":[{"price":0.85001,"qty":0.00000000},{"price":0.85000,"qty":16188.71515294}],"asks":[],"checksum":226443885,"timestamp":"2024-06-01T18:06:29.380087Z"}]}
{"channel":"book","type":"update","data":[{"symbol":"EUR/GBP","bids":[{"price":0.85026,"qty":0.00000000},{"price":0.84999,"qty":1833.00000000}],"asks":[],"checksum":2192853362,"timestamp":"2024-06-01T18:06:30.549962Z"}]}
{"channel":"book","type":"update","data":[{"symbol":"EUR/GBP","bids":[{"price":0.85001,"qty":493.67548617}],"asks":[],"checksum":1996018667,"timestamp":"2024-06-01T18:06:30.550025Z"}]}
{"channel":"book","type":"update","data":[{"symbol":"EUR/GBP","bids":[{"price":0.85034,"qty":0.00000000},{"price":0.84999,"qty":1833.00000000}],"asks":[],"checksum":17910837,"timestamp":"2024-06-01T18:06:30.792586Z"}]}
{"channel":"book","type":"update","data":[{"symbol":"EUR/GBP","bids":[{"price":0.85000,"qty":0.00000000},{"price":0.84995,"qty":4615.04081268}],"asks":[],"checksum":3737294830,"timestamp":"2024-06-01T18:06:30.792607Z"}]}
{"channel":"book","type":"update","data":[{"symbol":"EUR/GBP","bids":[{"price":0.85000,"qty":18032.47494791}],"asks":[],"checksum":4180026168,"timestamp":"2024-06-01T18:06:30.793701Z"}]}
{"channel":"book","type":"update","data":[{"symbol":"EUR/GBP","bids":[{"price":0.85050,"qty":0.00000000},{"price":0.84995,"qty":4615.04081268},{"price":0.85043,"qty":250.80000000}],"asks":[],"checksum":4276866521,"timestamp":"2024-06-01T18:06:30.887635Z"}]}
{"channel":"book","type":"update","data":[{"symbol":"EUR/GBP","bids":[{"price":0.85051,"qty":0.00000000},{"price":0.84995,"qty":4615.04081268}],"asks":[],"checksum":1222789749,"timestamp":"2024-06-01T18:06:31.134361Z"}]}
{"channel":"book","type":"update","data":[{"symbol":"EUR/GBP","bids":[],"asks":[{"price":0.85112,"qty":0.00000000},{"price":0.85116,"qty":30832.00000000}],"checksum":1711186786,"timestamp":"2024-06-01T18:06:31.790534Z"}]}
{"channel":"book","type":"update","data":[{"symbol":"EUR/GBP","bids":[],"asks":[{"price":0.85112,"qty":31335.41710687}],"checksum":1163030862,"timestamp":"2024-06-01T18:06:31.795670Z"}]}
{"channel":"book","type":"update","data":[{"symbol":"EUR/GBP","bids":[{"price":0.85001,"qty":0.00000000},{"price":0.84978,"qty":962.18683339}],"asks":[],"checksum":3572701026,"timestamp":"2024-06-01T18:06:31.959513Z"}]}
{"channel":"book","type":"update","data":[{"symbol":"EUR/GBP","bids":[{"price":0.85026,"qty":493.53033189}],"asks":[],"checksum":803831458,"timestamp":"2024-06-01T18:06:31.959673Z"}]}
{"channel":"book","type":"update","data":[{"symbol":"EUR/GBP","bids":[{"price":0.85047,"qty":0.00000000},{"price":0.84978,"qty":962.18683339},{"price":0.85043,"qty":0.00000000},{"price":0.84973,"qty":4617.55793608},{"price":0.85042,"qty":453.97459642}],"asks":[],"checksum":2291982670,"timestamp":"2024-06-01T18:06:32.638406Z"}]}
{"channel":"book","type":"update","data":[{"symbol":"EUR/GBP","bids":[{"price":0.85042,"qty":0.00000000},{"price":0.84970,"qty":2267.00000000}],"asks":[],"checksum":4240275210,"timestamp":"2024-06-01T18:06:32.644085Z"}]}
{"channel":"book","type":"update","data":[{"symbol":"EUR/GBP","bids":[{"price":0.85033,"qty":0.00000000},{"price":0.84967,"qty":4616.69752024}],"asks":[],"checksum":389848657,"timestamp":"2024-06-01T18:06:32.649107Z"}]}
{"channel":"book","type":"update","data":[{"symbol":"EUR/GBP","bids":[],"asks":[{"price":0.85055,"qty":250.80000000}],"checksum":3774684961,"timestamp":"2024-06-01T18:06:32.652360Z"}]}
{"channel":"book","type":"update","data":[{"symbol":"EUR/GBP","bids":[{"price":0.85034,"qty":1383.92408698}],"asks":[],"checksum":3446751560,"timestamp":"2024-06-01T18:06:32.653999Z"}]}
{"channel":"book","type":"update","data":[{"symbol":"EUR/GBP","bids":[{"price":0.85047,"qty":922.45852290}],"asks":[],"checksum":1365252634,"timestamp":"2024-06-01T18:06:32.654148Z"}]}
{"channel":"book","type":"update","data":[{"symbol":"EUR/GBP","bids":[{"price":0.85026,"qty":0.00000000},{"price":0.84970,"qty":2267.00000000}],"asks":[],"checksum":2011505209,"timestamp":"2024-06-01T18:06:32.654279Z"}]}
{"channel":"book","type":"update","data":[{"symbol":"EUR/GBP","bids":[{"price":0.85001,"qty":493.67548617}],"asks":[],"checksum":1450260006,"timestamp":"2024-06-01T18:06:32.654540Z"}]}
{"channel":"book","type":"update","data":[{"symbol":"EUR/GBP","bids":[{"price":0.85034,"qty":1529.74664567}],"asks":[],"checksum":368124008,"timestamp":"2024-06-01T18:06:32.814170Z"}]}
{"channel":"book","type":"update","data":[{"symbol":"EUR/GBP","bids":[{"price":0.84999,"qty":0.00000000},{"price":0.84970,"qty":2267.00000000}],"asks":[],"checksum":1197256362,"timestamp":"2024-06-01T18:06:32.840553Z"}]}
{"channel":"book","type":"update","data":[{"symbol":"EUR/GBP","bids":[{"price":0.84991,"qty":1833.00000000}],"asks":[],"checksum":3726595423,"timestamp":"2024-06-01T18:06:33.071015Z"}]}
