{"channel":"book","type":"snapshot","data":[{"symbol":"EUR/USD","bids":[{"price":1.08413,"qty":194.74054122},{"price":1.08410,"qty":3708.95349204},{"price":1.08409,"qty":1984.80000000},{"price":1.08407,"qty":3169.06235854},{"price":1.08405,"qty":7469.34013197},{"price":1.08404,"qty":2100.17167651},{"price":1.08385,"qty":2830.45000000},{"price":1.08379,"qty":631.32322682},{"price":1.08378,"qty":4613.45216905},{"price":1.08358,"qty":16662.23582757}],"asks":[{"price":1.08420,"qty":266.57355837},{"price":1.08421,"qty":3159.30144250},{"price":1.08422,"qty":2305.80509490},{"price":1.08438,"qty":11740.56415837},{"price":1.08439,"qty":962.24087722},{"price":1.08441,"qty":984.92496643},{"price":1.08447,"qty":4610.55811950},{"price":1.08456,"qty":2236.00627243},{"price":1.08459,"qty":41242.92103097},{"price":1.08460,"qty":4167.00000000}],"checksum":3121721150}]}
{"channel":"book","type":"update","data":[{"symbol":"EUR/USD","bids":[{"price":1.08359,"qty":23.07145691}],"asks":[],"checksum":3066732123,"timestamp":"2024-06-01T18:06:11.447564Z"}]}
{"channel":"book","type":"update","data":[{"symbol":"EUR/USD","bids":[{"price":1.08409,"qty":0.00000000},{"price":1.08358,"qty":16662.23582757},{"price":1.08411,"qty":1984.80000000}],"asks":[],"checksum":1294917036,"timestamp":"2024-06-01T18:06:11.472167Z"}]}
{"channel":"book","type":"update","data":[{"symbol":"EUR/USD","bids":[{"price":1.08410,"qty":0.00000000},{"price":1.08358,"qty":16662.23582757},{"price":1.08414,"qty":3708.81664796}],"asks":[],"checksum":2155176729,"timestamp":"2024-06-01T18:06:11.475480Z"}]}
{"channel":"book","type":"update","data":[{"symbol":"EUR/USD","bids":[],"asks":[{"price":1.08441,"qty":0.00000000},{"price":1.08464,"qty":84027.68683771}],"checksum":70742455,"timestamp":"2024-06-01T18:06:11.621909Z"}]}
{"channel":"book","type":"update","data":[{"symbol":"EUR/USD","bids":[],"asks":[{"price":1.08438,"qty":11693.55010397}],"checksum":4200470952,"timestamp":"2024-06-01T18:06:11.622071Z"}]}
{"channel":"book","type":"update","data":[{"symbol":"EUR/USD","bids":[],"asks":[{"price":1.08437,"qty":191.06615311}],"checksum":1904098680,"timestamp":"2024-06-01T18:06:11.626929Z"}]}
{"channel":"book","type":"update","data":[{"symbol":"EUR/USD","bids":[],"asks":[{"price":1.08458,"qty":625.80672709}],"checksum":2023600932,"timestamp":"2024-06-01T18:06:11.627052Z"}]}
{"channel":"book","type":"update","data":[{"symbol":"EUR/USD","bids":[],"asks":[{"price":1.08455,"qty":302.04165285}],"checksum":1223837718,"timestamp":"2024-06-01T18:06:11.627136Z"}]}
{"channel":"book","type":"update","data":[{"symbol":"EUR/USD","bids":[{"price":1.08411,"qty":0.00000000},{"price":1.08358,"qty":16662.23582757},{"price":1.08408,"qty":1984.80000000}],"asks":[],"checksum":3861183735,"timestamp":"2024-06-01T18:06:11.656039Z"}]}
{"channel":"book","type":"update","data":[{"symbol":"EUR/USD","bids":[{"price":1.08414,"qty":0.00000000},{"price":1.08358,"qty":16662.23582757},{"price":1.08409,"qty":3708.98770464}],"asks":[],"checksum":1643738334,"timestamp":"2024-06-01T18:06:11.659310Z"}]}
{"channel":"book","type":"update","data":[{"symbol":"EUR/USD","bids":[],"asks":[{"price":1.08438,"qty":0.00000000},{"price":1.08459,"qty":41242.92103097}],"checksum":1342576196,"timestamp":"2024-06-01T18:06:12.004450Z"}]}
{"channel":"book","type":"update","data":[{"symbol":"EUR/USD","bids":[],"asks":[{"price":1.08459,"qty":0.00000000},{"price":1.08460,"qty":4167.00000000}],"checksum":2039735829,"timestamp":"2024-06-01T18:06:12.004532Z"}]}
{"channel":"book","type":"update","data":[{"symbol":"EUR/USD","bids":[],"asks":[{"price":1.08438,"qty":3179.28888721}],"checksum":2140421842,"timestamp":"2024-06-01T18:06:12.009054Z"}]}
{"channel":"book","type":"update","data":[{"symbol":"EUR/USD","bids":[],"asks":[{"price":1.08446,"qty":15199.05071731}],"checksum":262029125,"timestamp":"2024-06-01T18:06:12.009203Z"}]}
{"channel":"book","type":"update","data":[{"symbol":"EUR/USD","bids":[],"asks":[{"price":1.08456,"qty":225.72210000}],"checksum":891228579,"timestamp":"2024-06-01T18:06:12.019970Z"}]}
{"channel":"book","type":"update","data":[{"symbol":"EUR/USD","bids":[],"asks":[{"price":1.08445,"qty":2010.28417243}],"checksum":3796112892,"timestamp":"2024-06-01T18:06:12.058715Z"}]}
{"channel":"book","type":"update","data":[{"symbol":"EUR/USD","bids":[{"price":1.08359,"qty":1861.08816214}],"asks":[],"checksum":114171572,"timestamp":"2024-06-01T18:06:12.861734Z"}]}
{"channel":"book","type":"update","data":[{"symbol":"EUR/USD","bids":[],"asks":[{"price":1.08421,"qty":0.00000000},{"price":1.08456,"qty":225.72210000},{"price":1.08419,"qty":3198.30787139}],"checksum":2273156855,"timestamp":"2024-06-01T18:06:13.162812Z"}]}
{"channel":"book","type":"update","data":[{"symbol":"EUR/USD","bids":[],"asks":[{"price":1.08419,"qty":0.00000000},{"price":1.08456,"qty":225.72210000},{"price":1.08421,"qty":3198.30787139}],"checksum":4205678697,"timestamp":"2024-06-01T18:06:13.304319Z"}]}
{"channel":"book","type":"update","data":[{"symbol":"EUR/USD","bids":[],"asks":[{"price":1.08421,"qty":0.00000000},{"price":1.08456,"qty":225.72210000},{"price":1.08419,"qty":3198.30787139}],"checksum":2273156855,"timestamp":"2024-06-01T18:06:13.309463Z"}]}
{"channel":"book","type":"update","data":[{"symbol":"EUR/USD","bids":[],"asks":[{"price":1.08419,"qty":0.00000000},{"price":1.08456,"qty":225.72210000},{"price":1.08421,"qty":3198.30787139}],"checksum":4205678697,"timestamp":"2024-06-01T18:06:13.314595Z"}]}
{"channel":"book","type":"update","data":[{"symbol":"EUR/USD","bids":[{"price":1.08407,"qty":0.00000000},{"price":1.08358,"qty":16662.23582757}],"asks":[],"checksum":3864753138,"timestamp":"2024-06-01T18:06:13.600546Z"}]}
{"channel":"book","type":"update","data":[{"symbol":"EUR/USD","bids":[{"price":1.08358,"qty":0.00000000},{"price":1.08350,"qty":962.24087722}],"asks":[],"checksum":2135738540,"timestamp":"2024-06-01T18:06:13.604595Z"}]}
{"channel":"book","type":"update","data":[{"symbol":"EUR/USD","bids":[{"price":1.08360,"qty":96699.84735366}],"asks":[],"checksum":871923266,"timestamp":"2024-06-01T18:06:13.606652Z"}]}
{"channel":"book","type":"update","data":[{"symbol":"EUR/USD","bids":[{"price":1.08410,"qty":4494.36492216}],"asks":[],"checksum":1902327273,"timestamp":"2024-06-01T18:06:13.606720Z"}]}
{"channel":"book","type":"update","data":[{"symbol":"EUR/USD","bids":[{"price":1.08409,"qty":0.00000000},{"price":1.08359,"qty":1861.08816214},{"price":1.08411,"qty":3708.91928007}],"asks":[],"checksum":4215975245,"timestamp":"2024-06-01T18:06:13.610694Z"}]}
{"channel":"book","type":"update","data":[{"symbol":"EUR/USD","bids":[{"price":1.08361,"qty":16662.23582757}],"asks":[],"checksum":3885177706,"timestamp":"2024-06-01T18:06:13.686770Z"}]}
{"channel":"book","type":"update","data":[{"symbol":"EUR/USD","bids":[],"asks":[{"price":1.08421,"qty":0.00000000},{"price":1.08456,"qty":225.72210000},{"price":1.08419,"qty":3197.63078440}],"checksum":1895872493,"timestamp":"2024-06-01T18:06:13.821372Z"}]}
{"channel":"book","type":"update","data":[{"symbol":"EUR/USD","bids":[],"asks":[{"price":1.08437,"qty":0.00000000},{"price":1.08456,"qty":225.72210000}],"checksum":1292679530,"timestamp":"2024-06-01T18:06:13.917672Z"}]}
{"channel":"book","type":"update","data":[{"symbol":"EUR/USD","bids":[],"asks":[{"price":1.08455,"qty":0.00000000},{"price":1.08459,"qty":125734.48265933}],"checksum":1298109005,"timestamp":"2024-06-01T18:06:13.917853Z"}]}
{"channel":"book","type":"update","data":[{"symbol":"EUR/USD","bids":[],"asks":[{"price":1.08437,"qty":132.74342374}],"checksum":3075007525,"timestamp":"2024-06-01T18:06:13.923545Z"}]}
{"channel":"book","type":"update","data":[{"symbol":"EUR/USD","bids":[],"asks":[{"price":1.08444,"qty":1138.59318657}],"checksum":2772209448,"timestamp":"2024-06-01T18:06:13.923661Z"}]}
{"channel":"book","type":"update","data":[{"symbol":"EUR/USD","bids":[],"asks":[{"price":1.08419,"qty":0.00000000},{"price":1.08456,"qty":225.72210000},{"price":1.08421,"qty":3197.63334153}],"checksum":694890409,"timestamp":"2024-06-01T18:06:14.091184Z"}]}
{"channel":"book","type":"update","data":[{"symbol":"EUR/USD","bids":[],"asks":[{"price":1.08438,"qty":0.00000000},{"price":1.08456,"qty":225.72210000}],"checksum":3568859075,"timestamp":"2024-06-01T18:06:14.438488Z"}]}
{"channel":"book","type":"update","data":[{"symbol":"EUR/USD","bids":[],"asks":[{"price":1.08446,"qty":0.00000000},{"price":1.08459,"qty":125734.48265933}],"checksum":2663132478,"timestamp":"2024-06-01T18:06:14.438723Z"}]}
{"channel":"book","type":"update","data":[{"symbol":"EUR/USD","bids":[],"asks":[{"price":1.08459,"qty":0.00000000},{"price":1.08460,"qty":4167.00000000}],"checksum":3548158764,"timestamp":"2024-06-01T18:06:14.438763Z"}]}
{"channel":"book","type":"update","data":[{"symbol":"EUR/USD","bids":[],"asks":[{"price":1.08445,"qty":0.00000000},{"price":1.08465,"qty":4167.00000000}],"checksum":121022699,"timestamp":"2024-06-01T18:06:14.441890Z"}]}
{"channel":"book","type":"update","data":[{"symbol":"EUR/USD","bids":[],"asks":[{"price":1.08443,"qty":14976.81354031}],"checksum":786084800,"timestamp":"2024-06-01T18:06:14.443301Z"}]}
{"channel":"book","type":"update","data":[{"symbol":"EUR/USD","bids":[],"asks":[{"price":1.08459,"qty":54375.97477630}],"checksum":1794805582,"timestamp":"2024-06-01T18:06:14.443392Z"}]}
{"channel":"book","type":"update","data":[{"symbol":"EUR/USD","bids":[{"price":1.08408,"qty":0.00000000},{"price":1.08360,"qty":96699.84735366},{"price":1.08412,"qty":1984.80000000}],"asks":[],"checksum":409388364,"timestamp":"2024-06-01T18:06:14.449602Z"}]}
{"channel":"book","type":"update","data":[{"symbol":"EUR/USD","bids":[{"price":1.08411,"qty":0.00000000},{"price":1.08360,"qty":96699.84735366},{"price":1.08413,"qty":3903.59139925}],"asks":[],"checksum":2464649229,"timestamp":"2024-06-01T18:06:14.452881Z"}]}
{"channel":"book","type":"update","data":[{"symbol":"EUR/USD","bids":[],"asks":[{"price":1.08442,"qty":2010.28417243}],"checksum":3357486999,"timestamp":"2024-06-01T18:06:14.487244Z"}]}
{"channel":"book","type":"update","data":[{"symbol":"EUR/USD","bids":[{"price":1.08412,"qty":0.00000000},{"price":1.08359,"qty":1861.08816214},{"price":1.08406,"qty":1984.80000000}],"asks":[],"checksum":3248968247,"timestamp":"2024-06-01T18:06:14.512622Z"}]}
{"channel":"book","type":"update","data":[{"symbol":"EUR/USD","bids":[{"price":1.08413,"qty":194.74054122},{"price":1.08411,"qty":3708.91928007}],"asks":[],"checksum":1701639267,"timestamp":"2024-06-01T18:06:14.515988Z"}]}
{"channel":"book","type":"update","data":[{"symbol":"EUR/USD","bids":[{"price":1.08362,"qty":23.07081818}],"asks":[],"checksum":3973680461,"timestamp":"2024-06-01T18:06:15.448179Z"}]}
{"channel":"book","type":"update","data":[{"symbol":"EUR/USD","bids":[],"asks":[{"price":1.08444,"qty":0.00000000},{"price":1.08459,"qty":54375.97477630}],"checksum":6180220,"timestamp":"2024-06-01T18:06:16.319637Z"}]}
{"channel":"book","type":"update","data":[{"symbol":"EUR/USD","bids":[],"asks":[{"price":1.08437,"qty":0.00000000},{"price":1.08460,"qty":4167.00000000}],"checksum":4050365688,"timestamp":"2024-06-01T18:06:16.319785Z"}]}
{"channel":"book","type":"update","data":[{"symbol":"EUR/USD","bids":[],"asks":[{"price":1.08438,"qty":44.42237239}],"checksum":3677788074,"timestamp":"2024-06-01T18:06:16.325544Z"}]}
{"channel":"book","type":"update","data":[{"symbol":"EUR/USD","bids":[],"asks":[{"price":1.08458,"qty":670.71719136}],"checksum":832580879,"timestamp":"2024-06-01T18:06:16.325631Z"}]}
{"channel":"book","type":"update","data":[{"symbol":"EUR/USD","bids":[],"asks":[{"price":1.08441,"qty":473.17115066}],"checksum":1032744535,"timestamp":"2024-06-01T18:06:16.325771Z"}]}
{"channel":"book","type":"update","data":[{"symbol":"EUR/USD","bids":[{"price":1.08406,"qty":0.00000000},{"price":1.08361,"qty":16662.23582757},{"price":1.08412,"qty":1984.80000000}],"asks":[],"checksum":4098657566,"timestamp":"2024-06-01T18:06:16.331929Z"}]}
{"channel":"book","type":"update","data":[{"symbol":"EUR/USD","bids":[{"price":1.08411,"qty":0.00000000},{"price":1.08361,"qty":16662.23582757},{"price":1.08414,"qty":3708.81664796}],"asks":[],"checksum":2372878901,"timestamp":"2024-06-01T18:06:16.335018Z"}]}
{"channel":"book","type":"update","data":[{"symbol":"EUR/USD","bids":[{"price":1.08412,"qty":0.00000000},{"price":1.08361,"qty":16662.23582757},{"price":1.08406,"qty":1984.80000000}],"asks":[],"checksum":2467183560,"timestamp":"2024-06-01T18:06:16.665714Z"}]}
{"channel":"book","type":"update","data":[{"symbol":"EUR/USD","bids":[{"price":1.08414,"qty":0.00000000},{"price":1.08361,"qty":16662.23582757},{"price":1.08411,"qty":3708.91928007}],"asks":[],"checksum":1032744535,"timestamp":"2024-06-01T18:06:16.668987Z"}]}
{"channel":"book","type":"update","data":[{"symbol":"EUR/USD","bids":[],"asks":[{"price":1.08443,"qty":0.00000000},{"price":1.08458,"qty":670.71719136}],"checksum":2596686830,"timestamp":"2024-06-01T18:06:16.991998Z"}]}
{"channel":"book","type":"update","data":[{"symbol":"EUR/USD","bids":[],"asks":[{"price":1.08442,"qty":0.00000000},{"price":1.08460,"qty":4167.00000000}],"checksum":3852867983,"timestamp":"2024-06-01T18:06:16.995539Z"}]}
{"channel":"book","type":"update","data":[{"symbol":"EUR/USD","bids":[],"asks":[{"price":1.08438,"qty":13379.60419453}],"checksum":1134847532,"timestamp":"2024-06-01T18:06:16.996933Z"}]}
{"channel":"book","type":"update","data":[{"symbol":"EUR/USD","bids":[],"asks":[{"price":1.08459,"qty":67509.02852163}],"checksum":1635752604,"timestamp":"2024-06-01T18:06:16.996981Z"}]}
{"channel":"book","type":"update","data":[{"symbol":"EUR/USD","bids":[],"asks":[{"price":1.08458,"qty":2681.00136379}],"checksum":659986507,"timestamp":"2024-06-01T18:06:17.086824Z"}]}
{"channel":"book","type":"update","data":[{"symbol":"EUR/USD","bids":[{"price":1.08412,"qty":194.74054122}],"asks":[],"checksum":931694897,"timestamp":"2024-06-01T18:06:17.158070Z"}]}
{"channel":"book","type":"update","data":[{"symbol":"EUR/USD","bids":[{"price":1.08411,"qty":0.00000000},{"price":1.08362,"qty":23.07081818},{"price":1.08414,"qty":3708.81664796}],"asks":[],"checksum":1860568879,"timestamp":"2024-06-01T18:06:17.161408Z"}]}
{"channel":"book","type":"update","data":[{"symbol":"EUR/USD","bids":[{"price":1.08410,"qty":0.00000000},{"price":1.08362,"qty":23.07081818}],"asks":[],"checksum":3404781119,"timestamp":"2024-06-01T18:06:17.294247Z"}]}
{"channel":"book","type":"update","data":[{"symbol":"EUR/USD","bids":[{"price":1.08414,"qty":0.00000000},{"price":1.08359,"qty":1838.01670523},{"price":1.08407,"qty":3709.05613173}],"asks":[],"checksum":87227955,"timestamp":"2024-06-01T18:06:17.298512Z"}]}
{"channel":"book","type":"update","data":[{"symbol":"EUR/USD","bids":[{"price":1.08407,"qty":6878.11849030}],"asks":[],"checksum":884894675,"timestamp":"2024-06-01T18:06:17.299355Z"}]}
{"channel":"book","type":"update","data":[{"symbol":"EUR/USD","bids":[{"price":1.08362,"qty":95421.55906276}],"asks":[],"checksum":2463789273,"timestamp":"2024-06-01T18:06:17.299630Z"}]}
{"channel":"book","type":"update","data":[{"symbol":"EUR/USD","bids":[{"price":1.08407,"qty":3169.06235857},{"price":1.08414,"qty":3708.81664796}],"asks":[],"checksum":3091745493,"timestamp":"2024-06-01T18:06:17.303994Z"}]}
{"channel":"book","type":"update","data":[{"symbol":"EUR/USD","bids":[{"price":1.08406,"qty":0.00000000},{"price":1.08362,"qty":95421.55906276},{"price":1.08408,"qty":1984.80000000}],"asks":[],"checksum":960057209,"timestamp":"2024-06-01T18:06:17.307561Z"}]}
{"channel":"book","type":"update","data":[{"symbol":"EUR/USD","bids":[{"price":1.08413,"qty":0.00000000},{"price":1.08362,"qty":95421.55906276}],"asks":[],"checksum":1544514648,"timestamp":"2024-06-01T18:06:17.331680Z"}]}
{"channel":"book","type":"update","data":[{"symbol":"EUR/USD","bids":[{"price":1.08363,"qty":16662.23582757}],"asks":[],"checksum":1722292732,"timestamp":"2024-06-01T18:06:17.334746Z"}]}
{"channel":"book","type":"update","data":[{"symbol":"EUR/USD","bids":[{"price":1.08414,"qty":0.00000000},{"price":1.08362,"qty":95421.55906276},{"price":1.08409,"qty":3708.98770464}],"asks":[],"checksum":702906600,"timestamp":"2024-06-01T18:06:17.337292Z"}]}
{"channel":"book","type":"update","data":[{"symbol":"EUR/USD","bids":[{"price":1.08409,"qty":0.00000000},{"price":1.08362,"qty":95421.55906276},{"price":1.08413,"qty":3708.85085803}],"asks":[],"checksum":2937765810,"timestamp":"2024-06-01T18:06:17.341765Z"}]}
{"channel":"book","type":"update","data":[{"symbol":"EUR/USD","bids":[{"price":1.08413,"qty":0.00000000},{"price":1.08362,"qty":95421.55906276},{"price":1.08409,"qty":3708.98770464}],"asks":[],"checksum":702906600,"timestamp":"2024-06-01T18:06:17.345686Z"}]}
{"channel":"book","type":"update","data":[{"symbol":"EUR/USD","bids":[{"price":1.08408,"qty":0.00000000},{"price":1.08362,"qty":95421.55906276},{"price":1.08410,"qty":1984.80000000}],"asks":[],"checksum":2642021256,"timestamp":"2024-06-01T18:06:17.370512Z"}]}
{"channel":"book","type":"update","data":[{"symbol":"EUR/USD","bids":[{"price":1.08409,"qty":0.00000000},{"price":1.08362,"qty":95421.55906276},{"price":1.08413,"qty":3708.85085803}],"asks":[],"checksum":3988990915,"timestamp":"2024-06-01T18:06:17.373959Z"}]}
{"channel":"book","type":"update","data":[{"symbol":"EUR/USD","bids":[{"price":1.08364,"qty":2059.27398457}],"asks":[],"checksum":3983098898,"timestamp":"2024-06-01T18:06:18.495396Z"}]}
{"channel":"book","type":"update","data":[{"symbol":"EUR/USD","bids":[],"asks":[{"price":1.08458,"qty":2010.28417243}],"checksum":3752149912,"timestamp":"2024-06-01T18:06:18.667022Z"}]}
{"channel":"book","type":"update","data":[{"symbol":"EUR/USD","bids":[],"asks":[{"price":1.08438,"qty":13335.18182214}],"checksum":2780267888,"timestamp":"2024-06-01T18:06:18.667047Z"}]}
{"channel":"book","type":"update","data":[{"symbol":"EUR/USD","bids":[],"asks":[{"price":1.08441,"qty":0.00000000},{"price":1.08460,"qty":4167.00000000}],"checksum":1561774103,"timestamp":"2024-06-01T18:06:18.667179Z"}]}
{"channel":"book","type":"update","data":[{"symbol":"EUR/USD","bids":[],"asks":[{"price":1.08437,"qty":204.18456486}],"checksum":2074815397,"timestamp":"2024-06-01T18:06:18.672380Z"}]}
{"channel":"book","type":"update","data":[{"symbol":"EUR/USD","bids":[],"asks":[{"price":1.08457,"qty":1079.01239115}],"checksum":3662607859,"timestamp":"2024-06-01T18:06:18.672530Z"}]}
{"channel":"book","type":"update","data":[{"symbol":"EUR/USD","bids":[{"price":1.08364,"qty":2082.34437695}],"asks":[],"checksum":508442780,"timestamp":"2024-06-01T18:06:19.436944Z"}]}
{"channel":"book","type":"update","data":[{"symbol":"EUR/USD","bids":[],"asks":[{"price":1.08438,"qty":0.00000000},{"price":1.08460,"qty":4167.00000000}],"checksum":2005411886,"timestamp":"2024-06-01T18:06:19.444379Z"}]}
{"channel":"book","type":"update","data":[{"symbol":"EUR/USD","bids":[],"asks":[{"price":1.08458,"qty":0.00000000},{"price":1.08465,"qty":4167.00000000}],"checksum":1455272450,"timestamp":"2024-06-01T18:06:19.447803Z"}]}
{"channel":"book","type":"update","data":[{"symbol":"EUR/USD","bids":[],"asks":[{"price":1.08446,"qty":16486.25873032}],"checksum":2025923519,"timestamp":"2024-06-01T18:06:19.448576Z"}]}
{"channel":"book","type":"update","data":[{"symbol":"EUR/USD","bids":[],"asks":[{"price":1.08456,"qty":124949.91157189}],"checksum":1214519064,"timestamp":"2024-06-01T18:06:19.448768Z"}]}
{"channel":"book","type":"update","data":[{"symbol":"EUR/USD","bids":[],"asks":[{"price":1.08445,"qty":2010.28417243}],"checksum":2054903390,"timestamp":"2024-06-01T18:06:19.486453Z"}]}
{"channel":"book","type":"update","data":[{"symbol":"EUR/USD","bids":[{"price":1.08413,"qty":0.00000000},{"price":1.08363,"qty":16662.23582757},{"price":1.08411,"qty":3708.91928007}],"asks":[],"checksum":476796548,"timestamp":"2024-06-01T18:06:20.386935Z"}]}
{"channel":"book","type":"update","data":[{"symbol":"EUR/USD","bids":[{"price":1.08411,"qty":0.00000000},{"price":1.08363,"qty":16662.23582757},{"price":1.08413,"qty":3708.85085803}],"asks":[],"checksum":2054903390,"timestamp":"2024-06-01T18:06:20.794337Z"}]}
{"channel":"book","type":"update","data":[{"symbol":"EUR/USD","bids":[{"price":1.08407,"qty":0.00000000},{"price":1.08363,"qty":16662.23582757}],"asks":[],"checksum":437980985,"timestamp":"2024-06-01T18:06:20.869881Z"}]}
{"channel":"book","type":"update","data":[{"symbol":"EUR/USD","bids":[{"price":1.08363,"qty":0.00000000},{"price":1.08350,"qty":962.24087722}],"asks":[],"checksum":4269552880,"timestamp":"2024-06-01T18:06:20.872876Z"}]}
{"channel":"book","type":"update","data":[{"symbol":"EUR/USD","bids":[{"price":1.08386,"qty":3169.06235857}],"asks":[],"checksum":4213620870,"timestamp":"2024-06-01T18:06:20.879922Z"}]}
{"channel":"book","type":"update","data":[{"symbol":"EUR/USD","bids":[{"price":1.08365,"qty":113948.19429214}],"asks":[],"checksum":2215745779,"timestamp":"2024-06-01T18:06:20.880235Z"}]}
{"channel":"book","type":"update","data":[{"symbol":"EUR/USD","bids":[{"price":1.08366,"qty":16662.23582757}],"asks":[],"checksum":1138565491,"timestamp":"2024-06-01T18:06:20.909276Z"}]}
{"channel":"book","type":"update","data":[{"symbol":"EUR/USD","bids":[],"asks":[{"price":1.08437,"qty":0.00000000},{"price":1.08460,"qty":4167.00000000}],"checksum":2607740124,"timestamp":"2024-06-01T18:06:21.092965Z"}]}
{"channel":"book","type":"update","data":[{"symbol":"EUR/USD","bids":[],"asks":[{"price":1.08457,"qty":0.00000000},{"price":1.08465,"qty":4167.00000000}],"checksum":2494344111,"timestamp":"2024-06-01T18:06:21.092994Z"}]}
{"channel":"book","type":"update","data":[{"symbol":"EUR/USD","bids":[],"asks":[{"price":1.08444,"qty":1104.34294295}],"checksum":2615770322,"timestamp":"2024-06-01T18:06:21.098481Z"}]}
{"channel":"book","type":"update","data":[{"symbol":"EUR/USD","bids":[{"price":1.08413,"qty":0.00000000},{"price":1.08365,"qty":113948.19429214},{"price":1.08411,"qty":3708.91928007}],"asks":[],"checksum":4253636376,"timestamp":"2024-06-01T18:06:21.161355Z"}]}
{"channel":"book","type":"update","data":[{"symbol":"EUR/USD","bids":[{"price":1.08410,"qty":0.00000000},{"price":1.08365,"qty":113948.19429214},{"price":1.08412,"qty":2179.54054122}],"asks":[],"checksum":1889575979,"timestamp":"2024-06-01T18:06:21.251921Z"}]}
{"channel":"book","type":"update","data":[{"symbol":"EUR/USD","bids":[{"price":1.08411,"qty":0.00000000},{"price":1.08364,"qty":1850.69888643},{"price":1.08406,"qty":3709.09034622}],"asks":[],"checksum":2807844343,"timestamp":"2024-06-01T18:06:21.255027Z"}]}
{"channel":"book","type":"update","data":[{"symbol":"EUR/USD","bids":[],"asks":[{"price":1.08444,"qty":1370.91650132}],"checksum":2211354859,"timestamp":"2024-06-01T18:06:21.260707Z"}]}
{"channel":"book","type":"update","data":[{"symbol":"EUR/USD","bids":[{"price":1.08367,"qty":23.06975370}],"asks":[],"checksum":2395845017,"timestamp":"2024-06-01T18:06:21.489210Z"}]}
{"channel":"book","type":"update","data":[{"symbol":"EUR/USD","bids":[],"asks":[{"price":1.08420,"qty":0.00000000},{"price":1.08465,"qty":4167.00000000}],"checksum":992442898,"timestamp":"2024-06-01T18:06:21.751179Z"}]}
{"channel":"book","type":"update","data":[{"symbol":"EUR/USD","bids":[{"price":1.08412,"qty":194.74054122},{"price":1.08413,"qty":1984.80000000}],"asks":[],"checksum":2475811580,"timestamp":"2024-06-01T18:06:21.769556Z"}]}
{"channel":"book","type":"update","data":[{"symbol":"EUR/USD","bids":[],"asks":[{"price":1.08446,"qty":0.00000000},{"price":1.08470,"qty":4167.00000000}],"checksum":3444142808,"timestamp":"2024-06-01T18:06:21.928428Z"}]}
{"channel":"book","type":"update","data":[{"symbol":"EUR/USD","bids":[],"asks":[{"price":1.08456,"qty":225.72210000}],"checksum":2979758286,"timestamp":"2024-06-01T18:06:21.928538Z"}]}
{"channel":"book","type":"update","data":[{"symbol":"EUR/USD","bids":[],"asks":[{"price":1.08445,"qty":0.00000000},{"price":1.08475,"qty":19982.10000000},{"price":1.08474,"qty":2010.28417243}],"checksum":69063527,"timestamp":"2024-06-01T18:06:21.931896Z"}]}
{"channel":"book","type":"update","data":[{"symbol":"EUR/USD","bids":[],"asks":[{"price":1.08443,"qty":14976.81354031}],"checksum":1270354783,"timestamp":"2024-06-01T18:06:21.935173Z"}]}
{"channel":"book","type":"update","data":[{"symbol":"EUR/USD","bids":[],"asks":[{"price":1.08459,"qty":77358.81883063}],"checksum":336538116,"timestamp":"2024-06-01T18:06:21.935287Z"}]}
{"channel":"book","type":"update","data":[{"symbol":"EUR/USD","bids":[],"asks":[{"price":1.08464,"qty":49213.55168956}],"checksum":2433511311,"timestamp":"2024-06-01T18:06:21.935363Z"}]}
{"channel":"book","type":"update","data":[{"symbol":"EUR/USD","bids":[],"asks":[{"price":1.08442,"qty":2010.28417243}],"checksum":1846954923,"timestamp":"2024-06-01T18:06:21.986591Z"}]}
{"channel":"book","type":"update","data":[{"symbol":"EUR/USD","bids":[],"asks":[{"price":1.08444,"qty":266.57355837}],"checksum":2950623847,"timestamp":"2024-06-01T18:06:23.795410Z"}]}
{"channel":"book","type":"update","data":[{"symbol":"EUR/USD","bids":[],"asks":[{"price":1.08438,"qty":36.87519590}],"checksum":3038516614,"timestamp":"2024-06-01T18:06:23.883258Z"}]}
{"channel":"book","type":"update","data":[{"symbol":"EUR/USD","bids":[{"price":1.08413,"qty":0.00000000},{"price":1.08366,"qty":16662.23582757},{"price":1.08407,"qty":1984.80000000}],"asks":[],"checksum":2693618991,"timestamp":"2024-06-01T18:06:23.920161Z"}]}
{"channel":"book","type":"update","data":[{"symbol":"EUR/USD","bids":[{"price":1.08387,"qty":34.92555190}],"asks":[],"checksum":3666513416,"timestamp":"2024-06-01T18:06:23.921836Z"}]}
{"channel":"book","type":"update","data":[{"symbol":"EUR/USD","bids":[{"price":1.08406,"qty":0.00000000},{"price":1.08367,"qty":2050.59296747},{"price":1.08408,"qty":3709.02191787}],"asks":[],"checksum":2631586228,"timestamp":"2024-06-01T18:06:23.923725Z"}]}
{"channel":"book","type":"update","data":[{"symbol":"EUR/USD","bids":[{"price":1.08407,"qty":0.00000000},{"price":1.08367,"qty":2050.59296747},{"price":1.08409,"qty":1984.80000000}],"asks":[],"checksum":1337946121,"timestamp":"2024-06-01T18:06:24.254590Z"}]}
{"channel":"book","type":"update","data":[{"symbol":"EUR/USD","bids":[{"price":1.08408,"qty":0.00000000},{"price":1.08367,"qty":2050.59296747},{"price":1.08410,"qty":3708.95349204}],"asks":[],"checksum":2551445422,"timestamp":"2024-06-01T18:06:24.257722Z"}]}
{"channel":"book","type":"update","data":[{"symbol":"EUR/USD","bids":[],"asks":[{"price":1.08443,"qty":0.00000000},{"price":1.08460,"qty":4167.00000000}],"checksum":2461507510,"timestamp":"2024-06-01T18:06:24.476544Z"}]}
{"channel":"book","type":"update","data":[{"symbol":"EUR/USD","bids":[],"asks":[{"price":1.08459,"qty":0.00000000},{"price":1.08464,"qty":49213.55168956}],"checksum":922061576,"timestamp":"2024-06-01T18:06:24.476644Z"}]}
{"channel":"book","type":"update","data":[{"symbol":"EUR/USD","bids":[],"asks":[{"price":1.08464,"qty":0.00000000},{"price":1.08465,"qty":4167.00000000}],"checksum":2865728311,"timestamp":"2024-06-01T18:06:24.476681Z"}]}
{"channel":"book","type":"update","data":[{"symbol":"EUR/USD","bids":[],"asks":[{"price":1.08442,"qty":0.00000000},{"price":1.08470,"qty":4167.00000000},{"price":1.08458,"qty":2010.28417243}],"checksum":1205836112,"timestamp":"2024-06-01T18:06:24.479814Z"}]}
{"channel":"book","type":"update","data":[{"symbol":"EUR/USD","bids":[],"asks":[{"price":1.08441,"qty":13335.18182214}],"checksum":3407289140,"timestamp":"2024-06-01T18:06:24.481442Z"}]}
{"channel":"book","type":"update","data":[{"symbol":"EUR/USD","bids":[],"asks":[{"price":1.08438,"qty":5163.89842721}],"checksum":1211867731,"timestamp":"2024-06-01T18:06:24.481466Z"}]}
{"channel":"book","type":"update","data":[{"symbol":"EUR/USD","bids":[],"asks":[{"price":1.08459,"qty":122482.58920457}],"checksum":1523091419,"timestamp":"2024-06-01T18:06:24.481609Z"}]}
{"channel":"book","type":"update","data":[{"symbol":"EUR/USD","bids":[{"price":1.08409,"qty":0.00000000},{"price":1.08367,"qty":2050.59296747},{"price":1.08411,"qty":1984.80000000}],"asks":[],"checksum":2704065580,"timestamp":"2024-06-01T18:06:24.499414Z"}]}
{"channel":"book","type":"update","data":[{"symbol":"EUR/USD","bids":[{"price":1.08410,"qty":0.00000000},{"price":1.08367,"qty":2050.59296747},{"price":1.08413,"qty":3708.85085803}],"asks":[],"checksum":2502471897,"timestamp":"2024-06-01T18:06:24.502455Z"}]}
{"channel":"book","type":"update","data":[{"symbol":"EUR/USD","bids":[{"price":1.08386,"qty":0.00000000},{"price":1.08367,"qty":2050.59296747}],"asks":[],"checksum":3197363764,"timestamp":"2024-06-01T18:06:24.543563Z"}]}
{"channel":"book","type":"update","data":[{"symbol":"EUR/USD","bids":[{"price":1.08407,"qty":5819.66748575}],"asks":[],"checksum":1390417255,"timestamp":"2024-06-01T18:06:24.547822Z"}]}
{"channel":"book","type":"update","data":[{"symbol":"EUR/USD","bids":[],"asks":[{"price":1.08438,"qty":5127.02323131}],"checksum":2369454247,"timestamp":"2024-06-01T18:06:25.842552Z"}]}
{"channel":"book","type":"update","data":[{"symbol":"EUR/USD","bids":[],"asks":[{"price":1.08437,"qty":418.50798821}],"checksum":2936157461,"timestamp":"2024-06-01T18:06:25.847354Z"}]}
{"channel":"book","type":"update","data":[{"symbol":"EUR/USD","bids":[],"asks":[{"price":1.08457,"qty":746.92271173}],"checksum":2726369050,"timestamp":"2024-06-01T18:06:25.847395Z"}]}
{"channel":"book","type":"update","data":[{"symbol":"EUR/USD","bids":[],"asks":[{"price":1.08441,"qty":0.00000000},{"price":1.08458,"qty":2010.28417243}],"checksum":432719922,"timestamp":"2024-06-01T18:06:26.825366Z"}]}
{"channel":"book","type":"update","data":[{"symbol":"EUR/USD","bids":[],"asks":[{"price":1.08438,"qty":0.00000000},{"price":1.08459,"qty":122482.58920457}],"checksum":3571279389,"timestamp":"2024-06-01T18:06:26.825659Z"}]}
{"channel":"book","type":"update","data":[{"symbol":"EUR/USD","bids":[],"asks":[{"price":1.08459,"qty":0.00000000},{"price":1.08460,"qty":4167.00000000}],"checksum":4024225005,"timestamp":"2024-06-01T18:06:26.825667Z"}]}
{"channel":"book","type":"update","data":[{"symbol":"EUR/USD","bids":[],"asks":[{"price":1.08458,"qty":0.00000000},{"price":1.08465,"qty":4167.00000000}],"checksum":1062417721,"timestamp":"2024-06-01T18:06:26.829090Z"}]}
{"channel":"book","type":"update","data":[{"symbol":"EUR/USD","bids":[],"asks":[{"price":1.08456,"qty":43110.27484914}],"checksum":1906253758,"timestamp":"2024-06-01T18:06:26.830128Z"}]}
{"channel":"book","type":"update","data":[{"symbol":"EUR/USD","bids":[],"asks":[{"price":1.08446,"qty":16618.44525847}],"checksum":4081842342,"timestamp":"2024-06-01T18:06:26.830177Z"}]}
{"channel":"book","type":"update","data":[{"symbol":"EUR/USD","bids":[],"asks":[{"price":1.08457,"qty":87910.38263610}],"checksum":1520402044,"timestamp":"2024-06-01T18:06:26.830284Z"}]}
{"channel":"book","type":"update","data":[{"symbol":"EUR/USD","bids":[{"price":1.08411,"qty":0.00000000},{"price":1.08369,"qty":23.06932794},{"price":1.08414,"qty":1984.80000000}],"asks":[],"checksum":3459467535,"timestamp":"2024-06-01T18:06:26.834198Z"}]}
{"channel":"book","type":"update","data":[{"symbol":"EUR/USD","bids":[{"price":1.08413,"qty":0.00000000},{"price":1.08369,"qty":23.06932794},{"price":1.08408,"qty":3709.02191787}],"asks":[],"checksum":1755097146,"timestamp":"2024-06-01T18:06:26.837549Z"}]}
{"channel":"book","type":"update","data":[{"symbol":"EUR/USD","bids":[{"price":1.08387,"qty":0.00000000},{"price":1.08369,"qty":23.06932794}],"asks":[],"checksum":3062627474,"timestamp":"2024-06-01T18:06:26.845630Z"}]}
{"channel":"book","type":"update","data":[{"symbol":"EUR/USD","bids":[{"price":1.08369,"qty":1987.08549159}],"asks":[],"checksum":2603262452,"timestamp":"2024-06-01T18:06:26.851351Z"}]}
{"channel":"book","type":"update","data":[{"symbol":"EUR/USD","bids":[],"asks":[{"price":1.08445,"qty":2010.28417243}],"checksum":1144336476,"timestamp":"2024-06-01T18:06:26.854600Z"}]}
{"channel":"book","type":"update","data":[{"symbol":"EUR/USD","bids":[{"price":1.08414,"qty":0.00000000},{"price":1.08368,"qty":16662.23582757},{"price":1.08409,"qty":1984.80000000}],"asks":[],"checksum":2511830609,"timestamp":"2024-06-01T18:06:26.866863Z"}]}
{"channel":"book","type":"update","data":[{"symbol":"EUR/USD","bids":[{"price":1.08408,"qty":0.00000000},{"price":1.08368,"qty":16662.23582757},{"price":1.08410,"qty":3708.95349204}],"asks":[],"checksum":120427856,"timestamp":"2024-06-01T18:06:26.870878Z"}]}
{"channel":"book","type":"update","data":[{"symbol":"EUR/USD","bids":[{"price":1.08410,"qty":0.00000000},{"price":1.08368,"qty":16662.23582757},{"price":1.08413,"qty":3708.85085803}],"asks":[],"checksum":3869933588,"timestamp":"2024-06-01T18:06:26.874932Z"}]}
{"channel":"book","type":"update","data":[{"symbol":"EUR/USD","bids":[{"price":1.08413,"qty":0.00000000},{"price":1.08368,"qty":16662.23582757},{"price":1.08410,"qty":3708.95349204}],"asks":[],"checksum":120427856,"timestamp":"2024-06-01T18:06:26.879085Z"}]}
{"channel":"book","type":"update","data":[{"symbol":"EUR/USD","bids":[{"price":1.08414,"qty":194.74054122}],"asks":[],"checksum":3122880961,"timestamp":"2024-06-01T18:06:26.989424Z"}]}
{"channel":"book","type":"update","data":[{"symbol":"EUR/USD","bids":[{"price":1.08409,"qty":0.00000000},{"price":1.08369,"qty":1987.08549159},{"price":1.08411,"qty":1984.80000000}],"asks":[],"checksum":2207179107,"timestamp":"2024-06-01T18:06:27.021000Z"}]}
{"channel":"book","type":"update","data":[{"symbol":"EUR/USD","bids":[{"price":1.08410,"qty":0.00000000},{"price":1.08369,"qty":1987.08549159},{"price":1.08413,"qty":3708.85085803}],"asks":[],"checksum":3444348322,"timestamp":"2024-06-01T18:06:27.024192Z"}]}
{"channel":"book","type":"update","data":[{"symbol":"EUR/USD","bids":[{"price":1.08412,"qty":0.00000000},{"price":1.08369,"qty":1987.08549159}],"asks":[],"checksum":413427384,"timestamp":"2024-06-01T18:06:27.155694Z"}]}
{"channel":"book","type":"update","data":[{"symbol":"EUR/USD","bids":[{"price":1.08413,"qty":0.00000000},{"price":1.08368,"qty":16662.23582757},{"price":1.08412,"qty":3708.88506874}],"asks":[],"checksum":3204953874,"timestamp":"2024-06-01T18:06:27.158955Z"}]}
{"channel":"book","type":"update","data":[{"symbol":"EUR/USD","bids":[{"price":1.08414,"qty":0.00000000},{"price":1.08368,"qty":16662.23582757},{"price":1.08412,"qty":3352.73487544}],"asks":[],"checksum":1138048652,"timestamp":"2024-06-01T18:06:27.891957Z"}]}
{"channel":"book","type":"update","data":[{"symbol":"EUR/USD","bids":[{"price":1.08407,"qty":0.00000000},{"price":1.08367,"qty":117865.53758741}],"asks":[],"checksum":1326348500,"timestamp":"2024-06-01T18:06:28.033183Z"}]}
{"channel":"book","type":"update","data":[{"symbol":"EUR/USD","bids":[{"price":1.08367,"qty":0.00000000},{"price":1.08350,"qty":962.24087722}],"asks":[],"checksum":2249338040,"timestamp":"2024-06-01T18:06:28.033252Z"}]}
{"channel":"book","type":"update","data":[{"symbol":"EUR/USD","bids":[{"price":1.08368,"qty":0.00000000},{"price":1.08346,"qty":4325.30000000}],"asks":[],"checksum":711755905,"timestamp":"2024-06-01T18:06:28.036418Z"}]}
{"channel":"book","type":"update","data":[{"symbol":"EUR/USD","bids":[{"price":1.08386,"qty":4494.36492216}],"asks":[],"checksum":2797193503,"timestamp":"2024-06-01T18:06:28.039032Z"}]}
{"channel":"book","type":"update","data":[{"symbol":"EUR/USD","bids":[{"price":1.08370,"qty":81566.17606039}],"asks":[],"checksum":682746941,"timestamp":"2024-06-01T18:06:28.039194Z"}]}
{"channel":"book","type":"update","data":[{"symbol":"EUR/USD","bids":[{"price":1.08380,"qty":7144.97004935}],"asks":[],"checksum":1927493020,"timestamp":"2024-06-01T18:06:28.039279Z"}]}
{"channel":"book","type":"update","data":[{"symbol":"EUR/USD","bids":[{"price":1.08381,"qty":631.31157675}],"asks":[],"checksum":3681459943,"timestamp":"2024-06-01T18:06:28.043938Z"}]}
{"channel":"book","type":"update","data":[{"symbol":"EUR/USD","bids":[{"price":1.08379,"qty":0.00000000},{"price":1.08370,"qty":81566.17606039}],"asks":[],"checksum":2881044096,"timestamp":"2024-06-01T18:06:28.043980Z"}]}
{"channel":"book","type":"update","data":[{"symbol":"EUR/USD","bids":[{"price":1.08371,"qty":16662.23582757}],"asks":[],"checksum":4133362256,"timestamp":"2024-06-01T18:06:28.086626Z"}]}
{"channel":"book","type":"update","data":[{"symbol":"EUR/USD","bids":[],"asks":[{"price":1.08457,"qty":87163.45992437}],"checksum":3594433364,"timestamp":"2024-06-01T18:06:28.101431Z"}]}
{"channel":"book","type":"update","data":[{"symbol":"EUR/USD","bids":[],"asks":[{"price":1.08437,"qty":0.00000000},{"price":1.08460,"qty":4167.00000000}],"checksum":1576358858,"timestamp":"2024-06-01T18:06:28.101563Z"}]}
{"channel":"book","type":"update","data":[{"symbol":"EUR/USD","bids":[],"asks":[{"price":1.08443,"qty":32.10882997}],"checksum":66030285,"timestamp":"2024-06-01T18:06:28.106750Z"}]}
{"channel":"book","type":"update","data":[{"symbol":"EUR/USD","bids":[],"asks":[{"price":1.08444,"qty":1510.04821008}],"checksum":551510148,"timestamp":"2024-06-01T18:06:28.106900Z"}]}
{"channel":"book","type":"update","data":[{"symbol":"EUR/USD","bids":[],"asks":[{"price":1.08420,"qty":266.57355837}],"checksum":1716399260,"timestamp":"2024-06-01T18:06:28.203566Z"}]}
{"channel":"book","type":"update","data":[{"symbol":"EUR/USD","bids":[],"asks":[{"price":1.08444,"qty":1243.47465171}],"checksum":2039814541,"timestamp":"2024-06-01T18:06:28.384851Z"}]}
{"channel":"book","type":"update","data":[{"symbol":"EUR/USD","bids":[],"asks":[{"price":1.08456,"qty":225.72210000}],"checksum":2962924190,"timestamp":"2024-06-01T18:06:29.337414Z"}]}
{"channel":"book","type":"update","data":[{"symbol":"EUR/USD","bids":[],"asks":[{"price":1.08446,"qty":0.00000000},{"price":1.08457,"qty":87163.45992437}],"checksum":3420885868,"timestamp":"2024-06-01T18:06:29.337427Z"}]}
{"channel":"book","type":"update","data":[{"symbol":"EUR/USD","bids":[],"asks":[{"price":1.08457,"qty":0.00000000},{"price":1.08460,"qty":4167.00000000}],"checksum":1490089670,"timestamp":"2024-06-01T18:06:29.337542Z"}]}
{"channel":"book","type":"update","data":[{"symbol":"EUR/USD","bids":[],"asks":[{"price":1.08445,"qty":0.00000000},{"price":1.08465,"qty":4167.00000000}],"checksum":1560603622,"timestamp":"2024-06-01T18:06:29.340793Z"}]}
{"channel":"book","type":"update","data":[{"symbol":"EUR/USD","bids":[],"asks":[{"price":1.08464,"qty":55279.89389810}],"checksum":1396766253,"timestamp":"2024-06-01T18:06:29.342226Z"}]}
{"channel":"book","type":"update","data":[{"symbol":"EUR/USD","bids":[],"asks":[{"price":1.08443,"qty":15008.92237028}],"checksum":1290584289,"timestamp":"2024-06-01T18:06:29.342252Z"}]}
{"channel":"book","type":"update","data":[{"symbol":"EUR/USD","bids":[],"asks":[{"price":1.08459,"qty":93775.13601230}],"checksum":1298752319,"timestamp":"2024-06-01T18:06:29.342513Z"}]}
{"channel":"book","type":"update","data":[{"symbol":"EUR/USD","bids":[{"price":1.08411,"qty":0.00000000},{"price":1.08370,"qty":81566.17606039},{"price":1.08413,"qty":1984.80000000}],"asks":[],"checksum":3811699494,"timestamp":"2024-06-01T18:06:29.358565Z"}]}
{"channel":"book","type":"update","data":[{"symbol":"EUR/USD","bids":[{"price":1.08412,"qty":0.00000000},{"price":1.08370,"qty":81566.17606039},{"price":1.08414,"qty":3708.81664796}],"asks":[],"checksum":3603435485,"timestamp":"2024-06-01T18:06:29.361872Z"}]}
{"channel":"book","type":"update","data":[{"symbol":"EUR/USD","bids":[],"asks":[{"price":1.08442,"qty":2010.28417243}],"checksum":1071033637,"timestamp":"2024-06-01T18:06:29.387040Z"}]}
{"channel":"book","type":"update","data":[{"symbol":"EUR/USD","bids":[{"price":1.08387,"qty":381.17258478}],"asks":[],"checksum":1258003670,"timestamp":"2024-06-01T18:06:29.401910Z"}]}
{"channel":"book","type":"update","data":[{"symbol":"EUR/USD","bids":[{"price":1.08413,"qty":0.00000000},{"price":1.08372,"qty":1607.14076882},{"price":1.08415,"qty":1984.80000000}],"asks":[],"checksum":1244937644,"timestamp":"2024-06-01T18:06:29.422955Z"}]}
{"channel":"book","type":"update","data":[{"symbol":"EUR/USD","bids":[{"price":1.08414,"qty":0.00000000},{"price":1.08372,"qty":1607.14076882},{"price":1.08406,"qty":3709.09034622}],"asks":[],"checksum":2227017752,"timestamp":"2024-06-01T18:06:29.426378Z"}]}
{"channel":"book","type":"update","data":[{"symbol":"EUR/USD","bids":[],"asks":[{"price":1.08443,"qty":14976.81354031}],"checksum":1200916039,"timestamp":"2024-06-01T18:06:30.510152Z"}]}
{"channel":"book","type":"update","data":[{"symbol":"EUR/USD","bids":[],"asks":[{"price":1.08444,"qty":0.00000000},{"price":1.08460,"qty":4167.00000000}],"checksum":1736041792,"timestamp":"2024-06-01T18:06:30.510321Z"}]}
{"channel":"book","type":"update","data":[{"symbol":"EUR/USD","bids":[],"asks":[{"price":1.08438,"qty":47.01405440}],"checksum":674547102,"timestamp":"2024-06-01T18:06:30.516223Z"}]}
{"channel":"book","type":"update","data":[{"symbol":"EUR/USD","bids":[],"asks":[{"price":1.08458,"qty":795.21002332}],"checksum":1229010763,"timestamp":"2024-06-01T18:06:30.516369Z"}]}
{"channel":"book","type":"update","data":[{"symbol":"EUR/USD","bids":[],"asks":[{"price":1.08441,"qty":532.81381400}],"checksum":2310088915,"timestamp":"2024-06-01T18:06:30.516390Z"}]}
{"channel":"book","type":"update","data":[{"symbol":"EUR/USD","bids":[{"price":1.08415,"qty":0.00000000},{"price":1.08372,"qty":1630.20945814},{"price":1.08407,"qty":1984.80000000}],"asks":[],"checksum":2203341614,"timestamp":"2024-06-01T18:06:30.544199Z"}]}
{"channel":"book","type":"update","data":[{"symbol":"EUR/USD","bids":[{"price":1.08406,"qty":0.00000000},{"price":1.08372,"qty":1630.20945814},{"price":1.08408,"qty":3709.02191787}],"asks":[],"checksum":2581806464,"timestamp":"2024-06-01T18:06:30.547977Z"}]}
{"channel":"book","type":"update","data":[{"symbol":"EUR/USD","bids":[{"price":1.08407,"qty":0.00000000},{"price":1.08372,"qty":1630.20945814},{"price":1.08409,"qty":1984.80000000}],"asks":[],"checksum":659028545,"timestamp":"2024-06-01T18:06:30.879715Z"}]}
{"channel":"book","type":"update","data":[{"symbol":"EUR/USD","bids":[{"price":1.08408,"qty":0.00000000},{"price":1.08372,"qty":1630.20945814},{"price":1.08410,"qty":3708.95349204}],"asks":[],"checksum":4140007181,"timestamp":"2024-06-01T18:06:30.884633Z"}]}
{"channel":"book","type":"update","data":[{"symbol":"EUR/USD","bids":[{"price":1.08380,"qty":0.00000000},{"price":1.08372,"qty":1630.20945814}],"asks":[],"checksum":2800059748,"timestamp":"2024-06-01T18:06:31.353116Z"}]}
{"channel":"book","type":"update","data":[{"symbol":"EUR/USD","bids":[{"price":1.08379,"qty":7239.99817929}],"asks":[],"checksum":179070526,"timestamp":"2024-06-01T18:06:31.358335Z"}]}
{"channel":"book","type":"update","data":[{"symbol":"EUR/USD","bids":[],"asks":[{"price":1.08443,"qty":0.00000000},{"price":1.08458,"qty":795.21002332}],"checksum":3642438006,"timestamp":"2024-06-01T18:06:31.790396Z"}]}
{"channel":"book","type":"update","data":[{"symbol":"EUR/USD","bids":[],"asks":[{"price":1.08421,"qty":0.00000000},{"price":1.08460,"qty":4167.00000000},{"price":1.08419,"qty":3264.00502870}],"checksum":482449648,"timestamp":"2024-06-01T18:06:31.794397Z"}]}
{"channel":"book","type":"update","data":[{"symbol":"EUR/USD","bids":[],"asks":[{"price":1.08438,"qty":13382.19587654}],"checksum":2099200611,"timestamp":"2024-06-01T18:06:31.795313Z"}]}
{"channel":"book","type":"update","data":[{"symbol":"EUR/USD","bids":[{"price":1.08409,"qty":0.00000000},{"price":1.08374,"qty":16662.23582757},{"price":1.08411,"qty":1984.80000000}],"asks":[],"checksum":3872707381,"timestamp":"2024-06-01T18:06:31.825996Z"}]}
{"channel":"book","type":"update","data":[{"symbol":"EUR/USD","bids":[{"price":1.08410,"qty":0.00000000},{"price":1.08374,"qty":16662.23582757},{"price":1.08412,"qty":3708.88506874}],"asks":[],"checksum":474649741,"timestamp":"2024-06-01T18:06:31.829452Z"}]}
{"channel":"book","type":"update","data":[{"symbol":"EUR/USD","bids":[],"asks":[{"price":1.08442,"qty":0.00000000},{"price":1.08459,"qty":97058.39944863},{"price":1.08458,"qty":2805.49419575}],"checksum":16308488,"timestamp":"2024-06-01T18:06:31.855766Z"}]}
{"channel":"book","type":"update","data":[{"symbol":"EUR/USD","bids":[{"price":1.08411,"qty":0.00000000},{"price":1.08374,"qty":16662.23582757},{"price":1.08413,"qty":1984.80000000}],"asks":[],"checksum":540152467,"timestamp":"2024-06-01T18:06:31.889425Z"}]}
{"channel":"book","type":"update","data":[{"symbol":"EUR/USD","bids":[{"price":1.08412,"qty":0.00000000},{"price":1.08374,"qty":16662.23582757},{"price":1.08414,"qty":3708.81664796}],"asks":[],"checksum":3499711734,"timestamp":"2024-06-01T18:06:31.939001Z"}]}
{"channel":"book","type":"update","data":[{"symbol":"EUR/USD","bids":[{"price":1.08413,"qty":0.00000000},{"price":1.08374,"qty":16662.23582757},{"price":1.08415,"qty":1984.80000000}],"asks":[],"checksum":3495361932,"timestamp":"2024-06-01T18:06:31.951783Z"}]}
{"channel":"book","type":"update","data":[{"symbol":"EUR/USD","bids":[{"price":1.08414,"qty":0.00000000},{"price":1.08374,"qty":16662.23582757},{"price":1.08406,"qty":3709.09034622}],"asks":[],"checksum":517953592,"timestamp":"2024-06-01T18:06:31.955208Z"}]}
{"channel":"book","type":"update","data":[{"symbol":"EUR/USD","bids":[{"price":1.08387,"qty":0.00000000},{"price":1.08374,"qty":16662.23582757}],"asks":[],"checksum":2792298628,"timestamp":"2024-06-01T18:06:32.628113Z"}]}
{"channel":"book","type":"update","data":[{"symbol":"EUR/USD","bids":[{"price":1.08415,"qty":0.00000000},{"price":1.08373,"qty":70831.64236824},{"price":1.08407,"qty":1984.80000000}],"asks":[],"checksum":3232376101,"timestamp":"2024-06-01T18:06:32.649037Z"}]}
{"channel":"book","type":"update","data":[{"symbol":"EUR/USD","bids":[{"price":1.08406,"qty":0.00000000},{"price":1.08373,"qty":70831.64236824},{"price":1.08408,"qty":3709.02191787}],"asks":[],"checksum":1512366762,"timestamp":"2024-06-01T18:06:32.652448Z"}]}
{"channel":"book","type":"update","data":[{"symbol":"EUR/USD","bids":[],"asks":[{"price":1.08438,"qty":13335.18182214}],"checksum":1932856327,"timestamp":"2024-06-01T18:06:32.948632Z"}]}
{"channel":"book","type":"update","data":[{"symbol":"EUR/USD","bids":[],"asks":[{"price":1.08458,"qty":2010.28417243}],"checksum":2159301174,"timestamp":"2024-06-01T18:06:32.948713Z"}]}
{"channel":"book","type":"update","data":[{"symbol":"EUR/USD","bids":[],"asks":[{"price":1.08441,"qty":0.00000000},{"price":1.08460,"qty":4167.00000000}],"checksum":1782799003,"timestamp":"2024-06-01T18:06:32.948890Z"}]}
{"channel":"book","type":"update","data":[{"symbol":"EUR/USD","bids":[{"price":1.08387,"qty":364.68463083}],"asks":[],"checksum":124080445,"timestamp":"2024-06-01T18:06:32.949206Z"}]}
{"channel":"book","type":"update","data":[{"symbol":"EUR/USD","bids":[{"price":1.08380,"qty":1738.76262384}],"asks":[],"checksum":472988861,"timestamp":"2024-06-01T18:06:32.949377Z"}]}
{"channel":"book","type":"update","data":[{"symbol":"EUR/USD","bids":[],"asks":[{"price":1.08457,"qty":905.51646367}],"checksum":342159373,"timestamp":"2024-06-01T18:06:32.953979Z"}]}
{"channel":"book","type":"update","data":[{"symbol":"EUR/USD","bids":[],"asks":[{"price":1.08437,"qty":304.20216242}],"checksum":619673441,"timestamp":"2024-06-01T18:06:32.954175Z"}]}
{"channel":"book","type":"update","data":[{"symbol":"EUR/USD","bids":[{"price":1.08407,"qty":0.00000000},{"price":1.08378,"qty":4613.45216905},{"price":1.08409,"qty":1984.80000000}],"asks":[],"checksum":2588651680,"timestamp":"2024-06-01T18:06:32.983958Z"}]}
{"channel":"book","type":"update","data":[{"symbol":"EUR/USD","bids":[{"price":1.08408,"qty":0.00000000},{"price":1.08378,"qty":4613.45216905},{"price":1.08410,"qty":3708.95349204}],"asks":[],"checksum":1271870956,"timestamp":"2024-06-01T18:06:32.987618Z"}]}
{"channel":"book","type":"update","data":[{"symbol":"EUR/USD","bids":[{"price":1.08410,"qty":0.00000000},{"price":1.08378,"qty":4613.45216905},{"price":1.08411,"qty":3708.91928007}],"asks":[],"checksum":1276271019,"timestamp":"2024-06-01T18:06:32.991143Z"}]}
{"channel":"book","type":"update","data":[{"symbol":"EUR/USD","bids":[{"price":1.08411,"qty":0.00000000},{"price":1.08378,"qty":4613.45216905},{"price":1.08410,"qty":3708.95349204}],"asks":[],"checksum":1271870956,"timestamp":"2024-06-01T18:06:32.995765Z"}]}
{"channel":"book","type":"update","data":[{"symbol":"EUR/USD","bids":[{"price":1.08409,"qty":0.00000000},{"price":1.08378,"qty":4613.45216905},{"price":1.08411,"qty":1984.80000000}],"asks":[],"checksum":3489965242,"timestamp":"2024-06-01T18:06:33.318458Z"}]}
{"channel":"book","type":"update","data":[{"symbol":"EUR/USD","bids":[{"price":1.08410,"qty":0.00000000},{"price":1.08378,"qty":4613.45216905},{"price":1.08412,"qty":3708.88506874}],"asks":[],"checksum":714793730,"timestamp":"2024-06-01T18:06:33.324022Z"}]}
{"channel":"book","type":"update","data":[{"symbol":"EUR/USD","bids":[{"price":1.08411,"qty":0.00000000},{"price":1.08378,"qty":4613.45216905},{"price":1.08413,"qty":1984.80000000}],"asks":[],"checksum":173025433,"timestamp":"2024-06-01T18:06:33.531531Z"}]}
{"channel":"book","type":"update","data":[{"symbol":"EUR/USD","bids":[{"price":1.08412,"qty":0.00000000},{"price":1.08378,"qty":4613.45216905},{"price":1.08414,"qty":3708.81664796}],"asks":[],"checksum":4210779900,"timestamp":"2024-06-01T18:06:33.534798Z"}]}
{"channel":"book","type":"update","data":[{"symbol":"EUR/USD","bids":[{"price":1.08413,"qty":0.00000000},{"price":1.08378,"qty":4613.45216905},{"price":1.08415,"qty":1984.80000000}],"asks":[],"checksum":4197762950,"timestamp":"2024-06-01T18:06:33.866393Z"}]}
{"channel":"book","type":"update","data":[{"symbol":"EUR/USD","bids":[{"price":1.08414,"qty":0.00000000},{"price":1.08378,"qty":4613.45216905},{"price":1.08406,"qty":3709.09034622}],"asks":[],"checksum":884826674,"timestamp":"2024-06-01T18:06:33.870238Z"}]}
{"channel":"book","type":"update","data":[{"symbol":"EUR/USD","bids":[],"asks":[{"price":1.08438,"qty":0.00000000},{"price":1.08459,"qty":97058.39944863}],"checksum":2965992083,"timestamp":"2024-06-01T18:06:34.298652Z"}]}
{"channel":"book","type":"update","data":[{"symbol":"EUR/USD","bids":[],"asks":[{"price":1.08459,"qty":0.00000000},{"price":1.08460,"qty":4167.00000000}],"checksum":4069194002,"timestamp":"2024-06-01T18:06:34.298764Z"}]}
{"channel":"book","type":"update","data":[{"symbol":"EUR/USD","bids":[],"asks":[{"price":1.08419,"qty":0.00000000},{"price":1.08465,"qty":4167.00000000},{"price":1.08421,"qty":3264.13518434}],"checksum":438793826,"timestamp":"2024-06-01T18:06:34.301776Z"}]}
{"channel":"book","type":"update","data":[{"symbol":"EUR/USD","bids":[],"asks":[{"price":1.08458,"qty":0.00000000},{"price":1.08465,"qty":4167.00000000}],"checksum":991095886,"timestamp":"2024-06-01T18:06:34.302277Z"}]}
{"channel":"book","type":"update","data":[{"symbol":"EUR/USD","bids":[],"asks":[{"price":1.08456,"qty":43110.27484914}],"checksum":677808151,"timestamp":"2024-06-01T18:06:34.303510Z"}]}
{"channel":"book","type":"update","data":[{"symbol":"EUR/USD","bids":[],"asks":[{"price":1.08446,"qty":16618.44525847}],"checksum":3974596286,"timestamp":"2024-06-01T18:06:34.303605Z"}]}
{"channel":"book","type":"update","data":[{"symbol":"EUR/USD","bids":[],"asks":[{"price":1.08457,"qty":88068.97638804}],"checksum":956553882,"timestamp":"2024-06-01T18:06:34.303640Z"}]}
{"channel":"book","type":"update","data":[{"symbol":"EUR/USD","bids":[],"asks":[{"price":1.08445,"qty":2010.28417243}],"checksum":1408200712,"timestamp":"2024-06-01T18:06:34.332977Z"}]}
{"channel":"book","type":"update","data":[{"symbol":"EUR/USD","bids":[{"price":1.08387,"qty":0.00000000},{"price":1.08378,"qty":4613.45216905}],"asks":[],"checksum":974648100,"timestamp":"2024-06-01T18:06:35.138457Z"}]}
{"channel":"book","type":"update","data":[{"symbol":"EUR/USD","bids":[{"price":1.08380,"qty":0.00000000},{"price":1.08375,"qty":23.06805074}],"asks":[],"checksum":2043593943,"timestamp":"2024-06-01T18:06:35.138472Z"}]}
{"channel":"book","type":"update","data":[{"symbol":"EUR/USD","bids":[{"price":1.08387,"qty":374.00626903}],"asks":[],"checksum":2080187993,"timestamp":"2024-06-01T18:06:35.146727Z"}]}
{"channel":"book","type":"update","data":[{"symbol":"EUR/USD","bids":[{"price":1.08380,"qty":1727.85391229}],"asks":[],"checksum":4176832113,"timestamp":"2024-06-01T18:06:35.146831Z"}]}
