{"channel":"book","type":"snapshot","data":[{"symbol":"GBP/USD","bids":[{"price":1.27457,"qty":629.46305304},{"price":1.27456,"qty":1569.64310240},{"price":1.27454,"qty":1961.49198926},{"price":1.27435,"qty":13980.57231632},{"price":1.27434,"qty":3923.59230089},{"price":1.27419,"qty":536.98569287},{"price":1.27418,"qty":509.38310000},{"price":1.27410,"qty":314.60440000},{"price":1.27403,"qty":624.07132809},{"price":1.27398,"qty":7432.24713888}],"asks":[{"price":1.27470,"qty":2492.38769881},{"price":1.27471,"qty":1284.69610905},{"price":1.27478,"qty":1961.12270352},{"price":1.27508,"qty":4632.28657759},{"price":1.27509,"qty":3921.30483545},{"price":1.27534,"qty":419.62910000},{"price":1.27537,"qty":24453.29399722},{"price":1.27538,"qty":29222.00000000},{"price":1.27545,"qty":3920.19258238},{"price":1.27550,"qty":5341.00000000}],"checksum":257768244}]}
{"channel":"book","type":"update","data":[{"symbol":"GBP/USD","bids":[{"price":1.27458,"qty":12.25697443}],"asks":[],"checksum":2601295055,"timestamp":"2024-06-01T18:06:44.212270Z"}]}
{"channel":"book","type":"update","data":[{"symbol":"GBP/USD","bids":[],"asks":[{"price":1.27471,"qty":386.45320905},{"price":1.27477,"qty":898.24290000}],"checksum":1374103562,"timestamp":"2024-06-01T18:06:44.233560Z"}]}
{"channel":"book","type":"update","data":[{"symbol":"GBP/USD","bids":[],"asks":[{"price":1.27470,"qty":0.00000000},{"price":1.27550,"qty":5341.00000000},{"price":1.27476,"qty":2492.49187050}],"checksum":766498358,"timestamp":"2024-06-01T18:06:44.236605Z"}]}
{"channel":"book","type":"update","data":[{"symbol":"GBP/USD","bids":[],"asks":[{"price":1.27477,"qty":0.00000000},{"price":1.27550,"qty":5341.00000000},{"price":1.27475,"qty":898.24290000}],"checksum":2413792288,"timestamp":"2024-06-01T18:06:44.265546Z"}]}
{"channel":"book","type":"update","data":[{"symbol":"GBP/USD","bids":[],"asks":[{"price":1.27476,"qty":0.00000000},{"price":1.27550,"qty":5341.00000000},{"price":1.27474,"qty":2492.49187050}],"checksum":1868964295,"timestamp":"2024-06-01T18:06:44.268736Z"}]}
{"channel":"book","type":"update","data":[{"symbol":"GBP/USD","bids":[],"asks":[{"price":1.27474,"qty":0.00000000},{"price":1.27550,"qty":5341.00000000},{"price":1.27470,"qty":2492.49187050}],"checksum":441669171,"timestamp":"2024-06-01T18:06:44.332648Z"}]}
{"channel":"book","type":"update","data":[{"symbol":"GBP/USD","bids":[],"asks":[{"price":1.27470,"qty":0.00000000},{"price":1.27550,"qty":5341.00000000},{"price":1.27474,"qty":2492.49187050}],"checksum":1868964295,"timestamp":"2024-06-01T18:06:44.359295Z"}]}
{"channel":"book","type":"update","data":[{"symbol":"GBP/USD","bids":[],"asks":[{"price":1.27474,"qty":0.00000000},{"price":1.27550,"qty":5341.00000000},{"price":1.27470,"qty":2492.49186777}],"checksum":2296287373,"timestamp":"2024-06-01T18:06:44.410457Z"}]}
{"channel":"book","type":"update","data":[{"symbol":"GBP/USD","bids":[],"asks":[{"price":1.27470,"qty":0.00000000},{"price":1.27550,"qty":5341.00000000},{"price":1.27469,"qty":2492.49186777}],"checksum":2862291280,"timestamp":"2024-06-01T18:06:44.414055Z"}]}
{"channel":"book","type":"update","data":[{"symbol":"GBP/USD","bids":[],"asks":[{"price":1.27469,"qty":0.00000000},{"price":1.27550,"qty":5341.00000000},{"price":1.27470,"qty":2492.49186777}],"checksum":2296287373,"timestamp":"2024-06-01T18:06:44.417652Z"}]}
{"channel":"book","type":"update","data":[{"symbol":"GBP/USD","bids":[],"asks":[{"price":1.27470,"qty":0.00000000},{"price":1.27550,"qty":5341.00000000},{"price":1.27474,"qty":2492.49186777}],"checksum":3014762700,"timestamp":"2024-06-01T18:06:44.518700Z"}]}
{"channel":"book","type":"update","data":[{"symbol":"GBP/USD","bids":[],"asks":[{"price":1.27474,"qty":0.00000000},{"price":1.27550,"qty":5341.00000000},{"price":1.27470,"qty":2492.49186467}],"checksum":143806240,"timestamp":"2024-06-01T18:06:44.917638Z"}]}
{"channel":"book","type":"update","data":[{"symbol":"GBP/USD","bids":[],"asks":[{"price":1.27470,"qty":0.00000000},{"price":1.27550,"qty":5341.00000000},{"price":1.27469,"qty":2492.49186467}],"checksum":718784253,"timestamp":"2024-06-01T18:06:44.921592Z"}]}
{"channel":"book","type":"update","data":[{"symbol":"GBP/USD","bids":[],"asks":[{"price":1.27469,"qty":0.00000000},{"price":1.27550,"qty":5341.00000000},{"price":1.27470,"qty":2492.49186467}],"checksum":143806240,"timestamp":"2024-06-01T18:06:44.925556Z"}]}
{"channel":"book","type":"update","data":[{"symbol":"GBP/USD","bids":[{"price":1.27435,"qty":0.00000000},{"price":1.27398,"qty":7432.24713888}],"asks":[],"checksum":927413653,"timestamp":"2024-06-01T18:06:46.170183Z"}]}
{"channel":"book","type":"update","data":[{"symbol":"GBP/USD","bids":[{"price":1.27456,"qty":0.00000000},{"price":1.27391,"qty":3924.89588349}],"asks":[],"checksum":1323220902,"timestamp":"2024-06-01T18:06:46.170320Z"}]}
{"channel":"book","type":"update","data":[{"symbol":"GBP/USD","bids":[{"price":1.27398,"qty":0.00000000},{"price":1.27386,"qty":818.31086202}],"asks":[],"checksum":404279230,"timestamp":"2024-06-01T18:06:46.170352Z"}]}
{"channel":"book","type":"update","data":[{"symbol":"GBP/USD","bids":[{"price":1.27457,"qty":0.00000000},{"price":1.27368,"qty":14540.74651318},{"price":1.27455,"qty":629.38591578}],"asks":[],"checksum":610526118,"timestamp":"2024-06-01T18:06:46.174078Z"}]}
{"channel":"book","type":"update","data":[{"symbol":"GBP/USD","bids":[{"price":1.27435,"qty":8339.24085545}],"asks":[],"checksum":3092891613,"timestamp":"2024-06-01T18:06:46.176439Z"}]}
{"channel":"book","type":"update","data":[{"symbol":"GBP/USD","bids":[{"price":1.27392,"qty":18025.81693358}],"asks":[],"checksum":3070912343,"timestamp":"2024-06-01T18:06:46.176533Z"}]}
{"channel":"book","type":"update","data":[{"symbol":"GBP/USD","bids":[{"price":1.27455,"qty":0.00000000},{"price":1.27391,"qty":3924.89588349},{"price":1.27456,"qty":629.38097771}],"asks":[],"checksum":1603176066,"timestamp":"2024-06-01T18:06:46.178724Z"}]}
{"channel":"book","type":"update","data":[{"symbol":"GBP/USD","bids":[{"price":1.27393,"qty":14540.74651318}],"asks":[],"checksum":1910009530,"timestamp":"2024-06-01T18:06:46.179569Z"}]}
{"channel":"book","type":"update","data":[{"symbol":"GBP/USD","bids":[{"price":1.27456,"qty":0.00000000},{"price":1.27392,"qty":18025.81693358},{"price":1.27455,"qty":629.38591578}],"asks":[],"checksum":2572980079,"timestamp":"2024-06-01T18:06:46.184421Z"}]}
{"channel":"book","type":"update","data":[{"symbol":"GBP/USD","bids":[],"asks":[{"price":1.27470,"qty":0.00000000},{"price":1.27550,"qty":5341.00000000},{"price":1.27474,"qty":2492.45691298}],"checksum":3103265828,"timestamp":"2024-06-01T18:06:49.514757Z"}]}
{"channel":"book","type":"update","data":[{"symbol":"GBP/USD","bids":[],"asks":[{"price":1.27474,"qty":0.00000000},{"price":1.27550,"qty":5341.00000000},{"price":1.27470,"qty":2492.45691298}],"checksum":1149951153,"timestamp":"2024-06-01T18:06:49.559492Z"}]}
{"channel":"book","type":"update","data":[{"symbol":"GBP/USD","bids":[{"price":1.27456,"qty":1569.64310240}],"asks":[],"checksum":3526676240,"timestamp":"2024-06-01T18:06:49.830326Z"}]}
{"channel":"book","type":"update","data":[{"symbol":"GBP/USD","bids":[{"price":1.27455,"qty":0.00000000},{"price":1.27395,"qty":14540.74651318},{"price":1.27457,"qty":629.37773123}],"asks":[],"checksum":2608202532,"timestamp":"2024-06-01T18:06:49.834970Z"}]}
{"channel":"book","type":"update","data":[{"symbol":"GBP/USD","bids":[],"asks":[{"price":1.27537,"qty":0.00000000},{"price":1.27550,"qty":5341.00000000}],"checksum":2753649806,"timestamp":"2024-06-01T18:06:53.264411Z"}]}
{"channel":"book","type":"update","data":[{"symbol":"GBP/USD","bids":[],"asks":[{"price":1.27537,"qty":22924.96312239}],"checksum":2046066807,"timestamp":"2024-06-01T18:06:53.264832Z"}]}
{"channel":"book","type":"update","data":[{"symbol":"GBP/USD","bids":[{"price":1.27456,"qty":0.00000000},{"price":1.27395,"qty":14540.74651318}],"asks":[],"checksum":147946671,"timestamp":"2024-06-01T18:06:53.420096Z"}]}
{"channel":"book","type":"update","data":[{"symbol":"GBP/USD","bids":[{"price":1.27435,"qty":0.00000000},{"price":1.27394,"qty":14202.94671448}],"asks":[],"checksum":1466344357,"timestamp":"2024-06-01T18:06:53.420148Z"}]}
{"channel":"book","type":"update","data":[{"symbol":"GBP/USD","bids":[{"price":1.27394,"qty":0.00000000},{"price":1.27391,"qty":3924.89588349}],"asks":[],"checksum":2800355428,"timestamp":"2024-06-01T18:06:53.420337Z"}]}
{"channel":"book","type":"update","data":[{"symbol":"GBP/USD","bids":[{"price":1.27457,"qty":0.00000000},{"price":1.27386,"qty":818.31086202},{"price":1.27455,"qty":629.38311335}],"asks":[],"checksum":1759274298,"timestamp":"2024-06-01T18:06:53.423634Z"}]}
{"channel":"book","type":"update","data":[{"symbol":"GBP/USD","bids":[{"price":1.27395,"qty":0.00000000},{"price":1.27386,"qty":818.31086202}],"asks":[],"checksum":3604508468,"timestamp":"2024-06-01T18:06:53.423804Z"}]}
{"channel":"book","type":"update","data":[{"symbol":"GBP/USD","bids":[{"price":1.27435,"qty":10595.77343980}],"asks":[],"checksum":1811057750,"timestamp":"2024-06-01T18:06:53.426927Z"}]}
{"channel":"book","type":"update","data":[{"symbol":"GBP/USD","bids":[{"price":1.27396,"qty":14638.81441195}],"asks":[],"checksum":3925629162,"timestamp":"2024-06-01T18:06:53.427100Z"}]}
{"channel":"book","type":"update","data":[{"symbol":"GBP/USD","bids":[{"price":1.27397,"qty":14540.74651318}],"asks":[],"checksum":4199149975,"timestamp":"2024-06-01T18:06:53.486119Z"}]}
{"channel":"book","type":"update","data":[{"symbol":"GBP/USD","bids":[{"price":1.27458,"qty":0.00000000},{"price":1.27396,"qty":14638.81441195}],"asks":[],"checksum":1239329866,"timestamp":"2024-06-01T18:06:55.034353Z"}]}
{"channel":"book","type":"update","data":[{"symbol":"GBP/USD","bids":[{"price":1.27456,"qty":12.25697443}],"asks":[],"checksum":1090913188,"timestamp":"2024-06-01T18:06:55.271071Z"}]}
{"channel":"book","type":"update","data":[{"symbol":"GBP/USD","bids":[],"asks":[{"price":1.27537,"qty":0.00000000},{"price":1.27550,"qty":5341.00000000}],"checksum":186456698,"timestamp":"2024-06-01T18:06:55.767974Z"}]}
{"channel":"book","type":"update","data":[{"symbol":"GBP/USD","bids":[],"asks":[{"price":1.27537,"qty":24453.29399722}],"checksum":2753641771,"timestamp":"2024-06-01T18:06:55.769254Z"}]}
{"channel":"book","type":"update","data":[{"symbol":"GBP/USD","bids":[{"price":1.27435,"qty":0.00000000},{"price":1.27396,"qty":14638.81441195}],"asks":[],"checksum":2658580010,"timestamp":"2024-06-01T18:06:56.903925Z"}]}
{"channel":"book","type":"update","data":[{"symbol":"GBP/USD","bids":[{"price":1.27396,"qty":0.00000000},{"price":1.27391,"qty":3924.89588349}],"asks":[],"checksum":3861699159,"timestamp":"2024-06-01T18:06:56.904053Z"}]}
{"channel":"book","type":"update","data":[{"symbol":"GBP/USD","bids":[{"price":1.27397,"qty":0.00000000},{"price":1.27386,"qty":818.31086202}],"asks":[],"checksum":4195246278,"timestamp":"2024-06-01T18:06:56.907460Z"}]}
{"channel":"book","type":"update","data":[{"symbol":"GBP/USD","bids":[{"price":1.27456,"qty":1581.90007683}],"asks":[],"checksum":508543079,"timestamp":"2024-06-01T18:06:56.909960Z"}]}
{"channel":"book","type":"update","data":[{"symbol":"GBP/USD","bids":[{"price":1.27435,"qty":14661.40177424}],"asks":[],"checksum":1628001647,"timestamp":"2024-06-01T18:06:56.910006Z"}]}
{"channel":"book","type":"update","data":[{"symbol":"GBP/USD","bids":[{"price":1.27455,"qty":0.00000000},{"price":1.27386,"qty":818.31086202},{"price":1.27457,"qty":629.30936963}],"asks":[],"checksum":1784311208,"timestamp":"2024-06-01T18:06:56.913465Z"}]}
{"channel":"book","type":"update","data":[{"symbol":"GBP/USD","bids":[],"asks":[{"price":1.27470,"qty":0.00000000},{"price":1.27550,"qty":5341.00000000},{"price":1.27474,"qty":2492.39619922}],"checksum":732484506,"timestamp":"2024-06-01T18:06:58.561183Z"}]}
{"channel":"book","type":"update","data":[{"symbol":"GBP/USD","bids":[],"asks":[{"price":1.27475,"qty":0.00000000},{"price":1.27550,"qty":5341.00000000},{"price":1.27473,"qty":898.24290000}],"checksum":1137692552,"timestamp":"2024-06-01T18:06:58.582345Z"}]}
{"channel":"book","type":"update","data":[{"symbol":"GBP/USD","bids":[],"asks":[{"price":1.27474,"qty":0.00000000},{"price":1.27550,"qty":5341.00000000},{"price":1.27470,"qty":2492.39619922}],"checksum":61351045,"timestamp":"2024-06-01T18:06:58.587465Z"}]}
{"channel":"book","type":"update","data":[{"symbol":"GBP/USD","bids":[],"asks":[{"price":1.27473,"qty":1284.69610905}],"checksum":2549328018,"timestamp":"2024-06-01T18:06:58.729068Z"}]}
{"channel":"book","type":"update","data":[{"symbol":"GBP/USD","bids":[],"asks":[{"price":1.27471,"qty":0.00000000},{"price":1.27550,"qty":5341.00000000}],"checksum":1276174992,"timestamp":"2024-06-01T18:06:58.895280Z"}]}
{"channel":"book","type":"update","data":[{"symbol":"GBP/USD","bids":[],"asks":[{"price":1.27470,"qty":0.00000000},{"price":1.27561,"qty":2133.00000000},{"price":1.27472,"qty":2492.39620032}],"checksum":1186095254,"timestamp":"2024-06-01T18:06:58.898691Z"}]}
{"channel":"book","type":"update","data":[{"symbol":"GBP/USD","bids":[{"price":1.27435,"qty":0.00000000},{"price":1.27386,"qty":818.31086202}],"asks":[],"checksum":214480913,"timestamp":"2024-06-01T18:07:00.318003Z"}]}
{"channel":"book","type":"update","data":[{"symbol":"GBP/USD","bids":[{"price":1.27456,"qty":12.25697443}],"asks":[],"checksum":1612947032,"timestamp":"2024-06-01T18:07:00.318070Z"}]}
{"channel":"book","type":"update","data":[{"symbol":"GBP/USD","bids":[{"price":1.27435,"qty":8338.99070279}],"asks":[],"checksum":1225929558,"timestamp":"2024-06-01T18:07:00.324272Z"}]}
{"channel":"book","type":"update","data":[{"symbol":"GBP/USD","bids":[{"price":1.27392,"qty":11265.71927311}],"asks":[],"checksum":3435867838,"timestamp":"2024-06-01T18:07:00.324293Z"}]}
{"channel":"book","type":"update","data":[{"symbol":"GBP/USD","bids":[{"price":1.27393,"qty":14540.74651318}],"asks":[],"checksum":3821510195,"timestamp":"2024-06-01T18:07:00.327461Z"}]}
{"channel":"book","type":"update","data":[{"symbol":"GBP/USD","bids":[{"price":1.27457,"qty":0.00000000},{"price":1.27392,"qty":11265.71927311},{"price":1.27455,"qty":626.97593785}],"asks":[],"checksum":1583824040,"timestamp":"2024-06-01T18:07:00.347652Z"}]}
{"channel":"book","type":"update","data":[{"symbol":"GBP/USD","bids":[],"asks":[{"price":1.27508,"qty":0.00000000},{"price":1.27561,"qty":2133.00000000}],"checksum":1986597199,"timestamp":"2024-06-01T18:07:00.704376Z"}]}
{"channel":"book","type":"update","data":[{"symbol":"GBP/USD","bids":[],"asks":[{"price":1.27537,"qty":0.00000000},{"price":1.27565,"qty":5000.00000000}],"checksum":928849824,"timestamp":"2024-06-01T18:07:00.704484Z"}]}
{"channel":"book","type":"update","data":[{"symbol":"GBP/USD","bids":[],"asks":[{"price":1.27537,"qty":26007.04720558}],"checksum":1703519465,"timestamp":"2024-06-01T18:07:00.705644Z"}]}
{"channel":"book","type":"update","data":[{"symbol":"GBP/USD","bids":[],"asks":[{"price":1.27508,"qty":3100.96483999}],"checksum":2098803809,"timestamp":"2024-06-01T18:07:00.705690Z"}]}
{"channel":"book","type":"update","data":[{"symbol":"GBP/USD","bids":[{"price":1.27456,"qty":1581.90007683}],"asks":[],"checksum":4204621170,"timestamp":"2024-06-01T18:07:04.009086Z"}]}
{"channel":"book","type":"update","data":[{"symbol":"GBP/USD","bids":[{"price":1.27394,"qty":8487.17028037}],"asks":[],"checksum":165878059,"timestamp":"2024-06-01T18:07:04.009122Z"}]}
{"channel":"book","type":"update","data":[{"symbol":"GBP/USD","bids":[{"price":1.27455,"qty":0.00000000},{"price":1.27393,"qty":14540.74651318},{"price":1.27457,"qty":625.02509442}],"asks":[],"checksum":2972598901,"timestamp":"2024-06-01T18:07:04.012280Z"}]}
{"channel":"book","type":"update","data":[{"symbol":"GBP/USD","bids":[{"price":1.27395,"qty":14540.74651318}],"asks":[],"checksum":2385811308,"timestamp":"2024-06-01T18:07:04.012422Z"}]}
{"channel":"book","type":"update","data":[{"symbol":"GBP/USD","bids":[{"price":1.27456,"qty":1569.64310240}],"asks":[],"checksum":1900878073,"timestamp":"2024-06-01T18:07:05.060259Z"}]}
{"channel":"book","type":"update","data":[{"symbol":"GBP/USD","bids":[{"price":1.27458,"qty":12.25697443}],"asks":[],"checksum":1965202896,"timestamp":"2024-06-01T18:07:05.236155Z"}]}
