{"channel":"book","type":"snapshot","data":[{"symbol":"LINK/USD","bids":[{"price":18.54099,"qty":14.50000000},{"price":18.53982,"qty":244.87460027},{"price":18.53966,"qty":50.01000000},{"price":18.53780,"qty":31.30916669},{"price":18.53779,"qty":31.87500000},{"price":18.53734,"qty":269.72576251},{"price":18.53719,"qty":40.00000000},{"price":18.53700,"qty":186.96555600},{"price":18.53578,"qty":269.68105392},{"price":18.53540,"qty":433.54710000}],"asks":[{"price":18.54337,"qty":31.87500000},{"price":18.54377,"qty":30.48430328},{"price":18.54378,"qty":31.87500000},{"price":18.54436,"qty":33.00000000},{"price":18.54529,"qty":40.00000000},{"price":18.54564,"qty":31.87500000},{"price":18.54577,"qty":6.43107813},{"price":18.54671,"qty":200.00000000},{"price":18.54769,"qty":31.87500000},{"price":18.54883,"qty":121.30145927}],"checksum":30992647}]}
{"channel":"book","type":"update","data":[{"symbol":"LINK/USD","bids":[],"asks":[{"price":18.54335,"qty":40.00000000}],"checksum":292627613,"timestamp":"2024-06-01T18:06:54.753250Z"}]}
{"channel":"book","type":"update","data":[{"symbol":"LINK/USD","bids":[],"asks":[{"price":18.54330,"qty":31.87500000}],"checksum":1829045633,"timestamp":"2024-06-01T18:06:54.756868Z"}]}
{"channel":"book","type":"update","data":[{"symbol":"LINK/USD","bids":[],"asks":[{"price":18.54378,"qty":0.00000000},{"price":18.54769,"qty":31.87500000}],"checksum":4144128155,"timestamp":"2024-06-01T18:06:54.757214Z"}]}
{"channel":"book","type":"update","data":[{"symbol":"LINK/USD","bids":[],"asks":[{"price":18.54529,"qty":0.00000000},{"price":18.54883,"qty":121.30145927}],"checksum":1393564540,"timestamp":"2024-06-01T18:06:54.757727Z"}]}
{"channel":"book","type":"update","data":[{"symbol":"LINK/USD","bids":[{"price":18.53982,"qty":1.38787030}],"asks":[],"checksum":3451429203,"timestamp":"2024-06-01T18:06:54.757753Z"}]}
{"channel":"book","type":"update","data":[{"symbol":"LINK/USD","bids":[],"asks":[{"price":18.54436,"qty":0.00000000},{"price":18.54936,"qty":2.23393540}],"checksum":2355549811,"timestamp":"2024-06-01T18:06:54.760373Z"}]}
{"channel":"book","type":"update","data":[{"symbol":"LINK/USD","bids":[{"price":18.53795,"qty":33.00000000}],"asks":[],"checksum":607212896,"timestamp":"2024-06-01T18:06:54.760555Z"}]}
{"channel":"book","type":"update","data":[{"symbol":"LINK/USD","bids":[{"price":18.53982,"qty":0.00000000},{"price":18.53540,"qty":433.54710000},{"price":18.53967,"qty":1.38788154}],"asks":[],"checksum":1647267752,"timestamp":"2024-06-01T18:06:54.760864Z"}]}
{"channel":"book","type":"update","data":[{"symbol":"LINK/USD","bids":[],"asks":[{"price":18.54330,"qty":0.00000000},{"price":18.54989,"qty":40.00000000}],"checksum":1081097125,"timestamp":"2024-06-01T18:06:54.788775Z"}]}
{"channel":"book","type":"update","data":[{"symbol":"LINK/USD","bids":[],"asks":[{"price":18.54337,"qty":0.00000000},{"price":18.55100,"qty":83.67104051}],"checksum":1433769905,"timestamp":"2024-06-01T18:06:54.788950Z"}]}
{"channel":"book","type":"update","data":[{"symbol":"LINK/USD","bids":[],"asks":[{"price":18.54517,"qty":33.00000000}],"checksum":2572411422,"timestamp":"2024-06-01T18:06:54.791874Z"}]}
{"channel":"book","type":"update","data":[{"symbol":"LINK/USD","bids":[{"price":18.54099,"qty":0.00000000},{"price":18.53540,"qty":433.54710000}],"asks":[],"checksum":2914264754,"timestamp":"2024-06-01T18:06:54.833714Z"}]}
{"channel":"book","type":"update","data":[{"symbol":"LINK/USD","bids":[],"asks":[{"price":18.54331,"qty":31.87500000}],"checksum":3671812456,"timestamp":"2024-06-01T18:06:54.837689Z"}]}
{"channel":"book","type":"update","data":[{"symbol":"LINK/USD","bids":[{"price":18.53967,"qty":33.26288154}],"asks":[],"checksum":2312190082,"timestamp":"2024-06-01T18:06:54.841289Z"}]}
{"channel":"book","type":"update","data":[{"symbol":"LINK/USD","bids":[{"price":18.54098,"qty":15.70000000}],"asks":[],"checksum":3238684548,"timestamp":"2024-06-01T18:06:54.913820Z"}]}
{"channel":"book","type":"update","data":[{"symbol":"LINK/USD","bids":[{"price":18.53967,"qty":1.38788154}],"asks":[],"checksum":3994810800,"timestamp":"2024-06-01T18:06:54.917784Z"}]}
{"channel":"book","type":"update","data":[{"symbol":"LINK/USD","bids":[],"asks":[{"price":18.54331,"qty":0.00000000},{"price":18.54989,"qty":40.00000000}],"checksum":2254747057,"timestamp":"2024-06-01T18:06:54.925725Z"}]}
{"channel":"book","type":"update","data":[{"symbol":"LINK/USD","bids":[],"asks":[{"price":18.54330,"qty":31.87500000}],"checksum":2554101671,"timestamp":"2024-06-01T18:06:54.930199Z"}]}
{"channel":"book","type":"update","data":[{"symbol":"LINK/USD","bids":[{"price":18.53719,"qty":0.00000000},{"price":18.53540,"qty":433.54710000}],"asks":[],"checksum":4131401031,"timestamp":"2024-06-01T18:06:55.029656Z"}]}
{"channel":"book","type":"update","data":[{"symbol":"LINK/USD","bids":[{"price":18.54098,"qty":0.00000000},{"price":18.53539,"qty":31.87500000}],"asks":[],"checksum":1462880015,"timestamp":"2024-06-01T18:06:55.087778Z"}]}
{"channel":"book","type":"update","data":[{"symbol":"LINK/USD","bids":[{"price":18.53967,"qty":244.87461151}],"asks":[],"checksum":272547759,"timestamp":"2024-06-01T18:06:55.091813Z"}]}
{"channel":"book","type":"update","data":[{"symbol":"LINK/USD","bids":[{"price":18.53967,"qty":243.48672997},{"price":18.53968,"qty":1.38788080}],"asks":[],"checksum":2126804428,"timestamp":"2024-06-01T18:06:55.175089Z"}]}
{"channel":"book","type":"update","data":[{"symbol":"LINK/USD","bids":[{"price":18.53968,"qty":33.26288080}],"asks":[],"checksum":1862672588,"timestamp":"2024-06-01T18:06:55.225918Z"}]}
{"channel":"book","type":"update","data":[{"symbol":"LINK/USD","bids":[],"asks":[{"price":18.54328,"qty":40.00000000}],"checksum":4050057739,"timestamp":"2024-06-01T18:06:55.231837Z"}]}
{"channel":"book","type":"update","data":[{"symbol":"LINK/USD","bids":[],"asks":[{"price":18.54305,"qty":31.87500000}],"checksum":834061184,"timestamp":"2024-06-01T18:06:55.235504Z"}]}
{"channel":"book","type":"update","data":[{"symbol":"LINK/USD","bids":[{"price":18.53968,"qty":1.38788080}],"asks":[],"checksum":282998708,"timestamp":"2024-06-01T18:06:55.235535Z"}]}
{"channel":"book","type":"update","data":[{"symbol":"LINK/USD","bids":[],"asks":[{"price":18.54516,"qty":8.06136702}],"checksum":2503469177,"timestamp":"2024-06-01T18:06:55.252983Z"}]}
{"channel":"book","type":"update","data":[{"symbol":"LINK/USD","bids":[],"asks":[{"price":18.54328,"qty":0.00000000},{"price":18.54769,"qty":31.87500000}],"checksum":3293237005,"timestamp":"2024-06-01T18:06:55.254614Z"}]}
{"channel":"book","type":"update","data":[{"symbol":"LINK/USD","bids":[{"price":18.53968,"qty":33.26288080}],"asks":[],"checksum":2212453456,"timestamp":"2024-06-01T18:06:55.255601Z"}]}
{"channel":"book","type":"update","data":[{"symbol":"LINK/USD","bids":[],"asks":[{"price":18.54330,"qty":0.00000000},{"price":18.54883,"qty":121.30145927}],"checksum":2446452205,"timestamp":"2024-06-01T18:06:55.258902Z"}]}
{"channel":"book","type":"update","data":[{"symbol":"LINK/USD","bids":[],"asks":[{"price":18.54516,"qty":0.00000000},{"price":18.54936,"qty":2.23393540}],"checksum":2462670199,"timestamp":"2024-06-01T18:06:55.262248Z"}]}
{"channel":"book","type":"update","data":[{"symbol":"LINK/USD","bids":[],"asks":[{"price":18.54303,"qty":40.00000000}],"checksum":817643672,"timestamp":"2024-06-01T18:06:55.263491Z"}]}
{"channel":"book","type":"update","data":[{"symbol":"LINK/USD","bids":[],"asks":[{"price":18.54563,"qty":8.06136702}],"checksum":897166980,"timestamp":"2024-06-01T18:06:55.265718Z"}]}
{"channel":"book","type":"update","data":[{"symbol":"LINK/USD","bids":[{"price":18.53968,"qty":1.38788080}],"asks":[],"checksum":76883506,"timestamp":"2024-06-01T18:06:55.266637Z"}]}
{"channel":"book","type":"update","data":[{"symbol":"LINK/USD","bids":[],"asks":[{"price":18.54563,"qty":0.00000000},{"price":18.54883,"qty":121.30145927}],"checksum":3240897013,"timestamp":"2024-06-01T18:06:55.269558Z"}]}
{"channel":"book","type":"update","data":[{"symbol":"LINK/USD","bids":[],"asks":[{"price":18.54516,"qty":8.06136702}],"checksum":455880134,"timestamp":"2024-06-01T18:06:55.273073Z"}]}
{"channel":"book","type":"update","data":[{"symbol":"LINK/USD","bids":[{"price":18.53968,"qty":33.26288080}],"asks":[],"checksum":2411078026,"timestamp":"2024-06-01T18:06:55.310437Z"}]}
{"channel":"book","type":"update","data":[{"symbol":"LINK/USD","bids":[],"asks":[{"price":18.54335,"qty":0.00000000},{"price":18.54883,"qty":121.30145927}],"checksum":3763144876,"timestamp":"2024-06-01T18:06:55.314659Z"}]}
{"channel":"book","type":"update","data":[{"symbol":"LINK/USD","bids":[{"price":18.53718,"qty":40.00000000}],"asks":[],"checksum":2427443741,"timestamp":"2024-06-01T18:06:55.322691Z"}]}
{"channel":"book","type":"update","data":[{"symbol":"LINK/USD","bids":[],"asks":[{"price":18.54302,"qty":31.87500000}],"checksum":1531311871,"timestamp":"2024-06-01T18:06:55.326437Z"}]}
{"channel":"book","type":"update","data":[{"symbol":"LINK/USD","bids":[{"price":18.53968,"qty":1.38788080}],"asks":[],"checksum":4098501335,"timestamp":"2024-06-01T18:06:55.330108Z"}]}
{"channel":"book","type":"update","data":[{"symbol":"LINK/USD","bids":[{"price":18.53968,"qty":33.26288080}],"asks":[],"checksum":1531311871,"timestamp":"2024-06-01T18:06:55.333565Z"}]}
{"channel":"book","type":"update","data":[{"symbol":"LINK/USD","bids":[],"asks":[{"price":18.54302,"qty":0.00000000},{"price":18.54883,"qty":121.30145927}],"checksum":2427443741,"timestamp":"2024-06-01T18:06:55.343599Z"}]}
{"channel":"book","type":"update","data":[{"symbol":"LINK/USD","bids":[{"price":18.53968,"qty":1.38788080}],"asks":[],"checksum":2144683111,"timestamp":"2024-06-01T18:06:55.351526Z"}]}
{"channel":"book","type":"update","data":[{"symbol":"LINK/USD","bids":[{"price":18.53968,"qty":33.26288080}],"asks":[],"checksum":2427443741,"timestamp":"2024-06-01T18:06:55.354861Z"}]}
{"channel":"book","type":"update","data":[{"symbol":"LINK/USD","bids":[],"asks":[{"price":18.54305,"qty":0.00000000},{"price":18.54936,"qty":2.23393540}],"checksum":1841144410,"timestamp":"2024-06-01T18:06:55.356117Z"}]}
{"channel":"book","type":"update","data":[{"symbol":"LINK/USD","bids":[],"asks":[{"price":18.54516,"qty":0.00000000},{"price":18.54989,"qty":40.00000000}],"checksum":2002614550,"timestamp":"2024-06-01T18:06:55.359979Z"}]}
{"channel":"book","type":"update","data":[{"symbol":"LINK/USD","bids":[],"asks":[{"price":18.54563,"qty":8.06136702}],"checksum":2828924252,"timestamp":"2024-06-01T18:06:55.364070Z"}]}
{"channel":"book","type":"update","data":[{"symbol":"LINK/USD","bids":[],"asks":[{"price":18.54296,"qty":31.87500000}],"checksum":389035946,"timestamp":"2024-06-01T18:06:55.525612Z"}]}
{"channel":"book","type":"update","data":[{"symbol":"LINK/USD","bids":[{"price":18.53968,"qty":1.38788080}],"asks":[],"checksum":3902480886,"timestamp":"2024-06-01T18:06:55.528826Z"}]}
{"channel":"book","type":"update","data":[{"symbol":"LINK/USD","bids":[],"asks":[{"price":18.54563,"qty":0.00000000},{"price":18.54936,"qty":2.23393540}],"checksum":1358442088,"timestamp":"2024-06-01T18:06:55.530085Z"}]}
{"channel":"book","type":"update","data":[{"symbol":"LINK/USD","bids":[],"asks":[{"price":18.54516,"qty":8.06136702}],"checksum":3674531456,"timestamp":"2024-06-01T18:06:55.534099Z"}]}
{"channel":"book","type":"update","data":[{"symbol":"LINK/USD","bids":[{"price":18.53718,"qty":0.00000000},{"price":18.53540,"qty":433.54710000}],"asks":[],"checksum":1857571945,"timestamp":"2024-06-01T18:06:55.606679Z"}]}
{"channel":"book","type":"update","data":[{"symbol":"LINK/USD","bids":[],"asks":[{"price":18.54516,"qty":0.00000000},{"price":18.54936,"qty":2.23393540}],"checksum":3236092651,"timestamp":"2024-06-01T18:06:55.674657Z"}]}
{"channel":"book","type":"update","data":[{"symbol":"LINK/USD","bids":[],"asks":[{"price":18.54563,"qty":8.06136702}],"checksum":3622635431,"timestamp":"2024-06-01T18:06:55.678991Z"}]}
{"channel":"book","type":"update","data":[{"symbol":"LINK/USD","bids":[{"price":18.53970,"qty":31.87500000}],"asks":[],"checksum":603040358,"timestamp":"2024-06-01T18:06:55.707255Z"}]}
{"channel":"book","type":"update","data":[{"symbol":"LINK/USD","bids":[{"price":18.53968,"qty":33.26288080}],"asks":[],"checksum":3820739328,"timestamp":"2024-06-01T18:06:55.707738Z"}]}
{"channel":"book","type":"update","data":[{"symbol":"LINK/USD","bids":[],"asks":[{"price":18.54296,"qty":0.00000000},{"price":18.54936,"qty":2.23393540}],"checksum":1544952310,"timestamp":"2024-06-01T18:06:55.707754Z"}]}
{"channel":"book","type":"update","data":[{"symbol":"LINK/USD","bids":[{"price":18.53970,"qty":0.00000000},{"price":18.53540,"qty":433.54710000}],"asks":[],"checksum":3786296197,"timestamp":"2024-06-01T18:06:55.710361Z"}]}
{"channel":"book","type":"update","data":[{"symbol":"LINK/USD","bids":[{"price":18.53968,"qty":1.38788080}],"asks":[],"checksum":1749075281,"timestamp":"2024-06-01T18:06:55.710930Z"}]}
{"channel":"book","type":"update","data":[{"symbol":"LINK/USD","bids":[],"asks":[{"price":18.54302,"qty":31.87500000}],"checksum":1938153991,"timestamp":"2024-06-01T18:06:55.711133Z"}]}
{"channel":"book","type":"update","data":[{"symbol":"LINK/USD","bids":[{"price":18.53968,"qty":33.26288080}],"asks":[],"checksum":1673362019,"timestamp":"2024-06-01T18:06:55.724868Z"}]}
{"channel":"book","type":"update","data":[{"symbol":"LINK/USD","bids":[{"price":18.53968,"qty":31.87500000},{"price":18.53969,"qty":1.38782119}],"asks":[],"checksum":4224390541,"timestamp":"2024-06-01T18:06:55.779943Z"}]}
{"channel":"book","type":"update","data":[{"symbol":"LINK/USD","bids":[{"price":18.53968,"qty":0.00000000},{"price":18.53540,"qty":433.54710000}],"asks":[],"checksum":3501574803,"timestamp":"2024-06-01T18:06:55.783293Z"}]}
{"channel":"book","type":"update","data":[{"symbol":"LINK/USD","bids":[{"price":18.53969,"qty":0.00000000},{"price":18.53539,"qty":31.87500000},{"price":18.53968,"qty":1.38782194}],"asks":[],"checksum":4278879513,"timestamp":"2024-06-01T18:06:55.786326Z"}]}
{"channel":"book","type":"update","data":[{"symbol":"LINK/USD","bids":[],"asks":[{"price":18.54302,"qty":0.00000000},{"price":18.54936,"qty":2.23393540}],"checksum":3838812751,"timestamp":"2024-06-01T18:06:55.792493Z"}]}
{"channel":"book","type":"update","data":[{"symbol":"LINK/USD","bids":[{"price":18.53968,"qty":33.26282194}],"asks":[],"checksum":1830890651,"timestamp":"2024-06-01T18:06:55.792638Z"}]}
{"channel":"book","type":"update","data":[{"symbol":"LINK/USD","bids":[{"price":18.53971,"qty":31.87500000}],"asks":[],"checksum":1554892535,"timestamp":"2024-06-01T18:06:55.793013Z"}]}
{"channel":"book","type":"update","data":[{"symbol":"LINK/USD","bids":[{"price":18.53968,"qty":1.38782194}],"asks":[],"checksum":3950141655,"timestamp":"2024-06-01T18:06:55.795930Z"}]}
{"channel":"book","type":"update","data":[{"symbol":"LINK/USD","bids":[{"price":18.53971,"qty":63.75000000}],"asks":[],"checksum":370789384,"timestamp":"2024-06-01T18:06:55.799337Z"}]}
{"channel":"book","type":"update","data":[{"symbol":"LINK/USD","bids":[],"asks":[{"price":18.54289,"qty":31.87500000}],"checksum":2423495764,"timestamp":"2024-06-01T18:06:55.828176Z"}]}
{"channel":"book","type":"update","data":[{"symbol":"LINK/USD","bids":[{"price":18.53971,"qty":31.87500000}],"asks":[],"checksum":1830301835,"timestamp":"2024-06-01T18:06:55.828409Z"}]}
{"channel":"book","type":"update","data":[{"symbol":"LINK/USD","bids":[{"price":18.53971,"qty":0.00000000},{"price":18.53540,"qty":433.54710000}],"asks":[],"checksum":2257900992,"timestamp":"2024-06-01T18:06:55.828499Z"}]}
{"channel":"book","type":"update","data":[{"symbol":"LINK/USD","bids":[{"price":18.53713,"qty":40.00000000}],"asks":[],"checksum":166213314,"timestamp":"2024-06-01T18:06:55.880134Z"}]}
{"channel":"book","type":"update","data":[{"symbol":"LINK/USD","bids":[],"asks":[{"price":18.54289,"qty":0.00000000},{"price":18.54936,"qty":2.23393540}],"checksum":2407687838,"timestamp":"2024-06-01T18:06:55.890899Z"}]}
{"channel":"book","type":"update","data":[{"symbol":"LINK/USD","bids":[],"asks":[{"price":18.54303,"qty":71.87500000}],"checksum":3055817662,"timestamp":"2024-06-01T18:06:55.896334Z"}]}
{"channel":"book","type":"update","data":[{"symbol":"LINK/USD","bids":[],"asks":[{"price":18.54297,"qty":31.87500000}],"checksum":708277061,"timestamp":"2024-06-01T18:06:55.899906Z"}]}
{"channel":"book","type":"update","data":[{"symbol":"LINK/USD","bids":[],"asks":[{"price":18.54563,"qty":0.00000000},{"price":18.54936,"qty":2.23393540}],"checksum":2455010523,"timestamp":"2024-06-01T18:06:55.904275Z"}]}
{"channel":"book","type":"update","data":[{"symbol":"LINK/USD","bids":[],"asks":[{"price":18.54303,"qty":40.00000000}],"checksum":3387370354,"timestamp":"2024-06-01T18:06:55.924951Z"}]}
{"channel":"book","type":"update","data":[{"symbol":"LINK/USD","bids":[],"asks":[{"price":18.54297,"qty":0.00000000},{"price":18.54989,"qty":40.00000000}],"checksum":803335986,"timestamp":"2024-06-01T18:06:55.924987Z"}]}
{"channel":"book","type":"update","data":[{"symbol":"LINK/USD","bids":[{"price":18.53969,"qty":31.87500000}],"asks":[],"checksum":3398110970,"timestamp":"2024-06-01T18:06:55.925427Z"}]}
{"channel":"book","type":"update","data":[{"symbol":"LINK/USD","bids":[{"price":18.53968,"qty":33.26282194}],"asks":[],"checksum":3768853088,"timestamp":"2024-06-01T18:06:55.925678Z"}]}
{"channel":"book","type":"update","data":[{"symbol":"LINK/USD","bids":[{"price":18.53969,"qty":0.00000000},{"price":18.53578,"qty":269.68105392}],"asks":[],"checksum":1843912269,"timestamp":"2024-06-01T18:06:56.011243Z"}]}
{"channel":"book","type":"update","data":[{"symbol":"LINK/USD","bids":[{"price":18.53968,"qty":1.38782194}],"asks":[],"checksum":803335986,"timestamp":"2024-06-01T18:06:56.014620Z"}]}
{"channel":"book","type":"update","data":[{"symbol":"LINK/USD","bids":[],"asks":[{"price":18.54297,"qty":31.87500000}],"checksum":3387370354,"timestamp":"2024-06-01T18:06:56.015342Z"}]}
{"channel":"book","type":"update","data":[{"symbol":"LINK/USD","bids":[],"asks":[{"price":18.54297,"qty":0.00000000},{"price":18.54989,"qty":40.00000000}],"checksum":803335986,"timestamp":"2024-06-01T18:06:56.032605Z"}]}
{"channel":"book","type":"update","data":[{"symbol":"LINK/USD","bids":[{"price":18.53968,"qty":33.26282194}],"asks":[],"checksum":1843912269,"timestamp":"2024-06-01T18:06:56.033084Z"}]}
{"channel":"book","type":"update","data":[{"symbol":"LINK/USD","bids":[{"price":18.53969,"qty":31.87500000}],"asks":[],"checksum":3768853088,"timestamp":"2024-06-01T18:06:56.033129Z"}]}
{"channel":"book","type":"update","data":[{"symbol":"LINK/USD","bids":[{"price":18.53969,"qty":0.00000000},{"price":18.53578,"qty":269.68105392}],"asks":[],"checksum":1843912269,"timestamp":"2024-06-01T18:06:56.045844Z"}]}
{"channel":"book","type":"update","data":[{"symbol":"LINK/USD","bids":[{"price":18.53968,"qty":1.38782194}],"asks":[],"checksum":803335986,"timestamp":"2024-06-01T18:06:56.049195Z"}]}
{"channel":"book","type":"update","data":[{"symbol":"LINK/USD","bids":[],"asks":[{"price":18.54302,"qty":31.87500000}],"checksum":4083369045,"timestamp":"2024-06-01T18:06:56.049893Z"}]}
{"channel":"book","type":"update","data":[{"symbol":"LINK/USD","bids":[],"asks":[{"price":18.54302,"qty":0.00000000},{"price":18.54989,"qty":40.00000000}],"checksum":803335986,"timestamp":"2024-06-01T18:06:56.059149Z"}]}
{"channel":"book","type":"update","data":[{"symbol":"LINK/USD","bids":[{"price":18.53968,"qty":33.26282194}],"asks":[],"checksum":1843912269,"timestamp":"2024-06-01T18:06:56.059458Z"}]}
{"channel":"book","type":"update","data":[{"symbol":"LINK/USD","bids":[{"price":18.53968,"qty":1.38782194}],"asks":[],"checksum":803335986,"timestamp":"2024-06-01T18:06:56.062025Z"}]}
{"channel":"book","type":"update","data":[{"symbol":"LINK/USD","bids":[],"asks":[{"price":18.54278,"qty":31.87500000}],"checksum":1046614337,"timestamp":"2024-06-01T18:06:56.063164Z"}]}
{"channel":"book","type":"update","data":[{"symbol":"LINK/USD","bids":[],"asks":[{"price":18.54377,"qty":0.00000000},{"price":18.54989,"qty":40.00000000}],"checksum":1442500970,"timestamp":"2024-06-01T18:06:56.071203Z"}]}
{"channel":"book","type":"update","data":[{"symbol":"LINK/USD","bids":[],"asks":[{"price":18.54278,"qty":63.75000000}],"checksum":2040469315,"timestamp":"2024-06-01T18:06:56.091594Z"}]}
{"channel":"book","type":"update","data":[{"symbol":"LINK/USD","bids":[{"price":18.53713,"qty":0.00000000},{"price":18.53540,"qty":433.54710000}],"asks":[],"checksum":475730263,"timestamp":"2024-06-01T18:06:56.175192Z"}]}
{"channel":"book","type":"update","data":[{"symbol":"LINK/USD","bids":[],"asks":[{"price":18.54563,"qty":30.31076417}],"checksum":389342720,"timestamp":"2024-06-01T18:06:56.178546Z"}]}
{"channel":"book","type":"update","data":[{"symbol":"LINK/USD","bids":[],"asks":[{"price":18.54278,"qty":31.87500000}],"checksum":1437211562,"timestamp":"2024-06-01T18:06:56.249222Z"}]}
{"channel":"book","type":"update","data":[{"symbol":"LINK/USD","bids":[{"price":18.53551,"qty":63.75000000}],"asks":[],"checksum":3956162986,"timestamp":"2024-06-01T18:06:56.444306Z"}]}
{"channel":"book","type":"update","data":[{"symbol":"LINK/USD","bids":[],"asks":[{"price":18.54278,"qty":0.00000000},{"price":18.54989,"qty":40.00000000}],"checksum":287617540,"timestamp":"2024-06-01T18:06:56.450656Z"}]}
{"channel":"book","type":"update","data":[{"symbol":"LINK/USD","bids":[],"asks":[{"price":18.54302,"qty":31.87500000}],"checksum":651105470,"timestamp":"2024-06-01T18:06:56.454487Z"}]}
{"channel":"book","type":"update","data":[{"symbol":"LINK/USD","bids":[],"asks":[{"price":18.54303,"qty":0.00000000},{"price":18.54989,"qty":40.00000000}],"checksum":2855897317,"timestamp":"2024-06-01T18:06:56.456066Z"}]}
{"channel":"book","type":"update","data":[{"symbol":"LINK/USD","bids":[],"asks":[{"price":18.54302,"qty":63.75000000}],"checksum":2254196428,"timestamp":"2024-06-01T18:06:56.674723Z"}]}
{"channel":"book","type":"update","data":[{"symbol":"LINK/USD","bids":[],"asks":[{"price":18.54300,"qty":40.00000000}],"checksum":539891951,"timestamp":"2024-06-01T18:06:56.679846Z"}]}
{"channel":"book","type":"update","data":[{"symbol":"LINK/USD","bids":[],"asks":[{"price":18.54208,"qty":31.87500000}],"checksum":39946696,"timestamp":"2024-06-01T18:06:56.683109Z"}]}
{"channel":"book","type":"update","data":[{"symbol":"LINK/USD","bids":[],"asks":[{"price":18.54208,"qty":0.00000000},{"price":18.54936,"qty":2.23393540}],"checksum":539891951,"timestamp":"2024-06-01T18:06:56.731642Z"}]}
{"channel":"book","type":"update","data":[{"symbol":"LINK/USD","bids":[],"asks":[{"price":18.54302,"qty":31.87500000}],"checksum":1298379481,"timestamp":"2024-06-01T18:06:56.732271Z"}]}
{"channel":"book","type":"update","data":[{"symbol":"LINK/USD","bids":[],"asks":[{"price":18.54274,"qty":31.87500000}],"checksum":3828375395,"timestamp":"2024-06-01T18:06:56.734974Z"}]}
{"channel":"book","type":"update","data":[{"symbol":"LINK/USD","bids":[],"asks":[{"price":18.54274,"qty":0.00000000},{"price":18.54936,"qty":2.23393540}],"checksum":1298379481,"timestamp":"2024-06-01T18:06:56.790078Z"}]}
{"channel":"book","type":"update","data":[{"symbol":"LINK/USD","bids":[],"asks":[{"price":18.54284,"qty":31.87500000}],"checksum":2262896182,"timestamp":"2024-06-01T18:06:56.793709Z"}]}
{"channel":"book","type":"update","data":[{"symbol":"LINK/USD","bids":[],"asks":[{"price":18.54516,"qty":8.06136702}],"checksum":1038597305,"timestamp":"2024-06-01T18:06:56.971250Z"}]}
{"channel":"book","type":"update","data":[{"symbol":"LINK/USD","bids":[],"asks":[{"price":18.54516,"qty":0.00000000},{"price":18.54883,"qty":121.30145927}],"checksum":2262896182,"timestamp":"2024-06-01T18:06:56.974673Z"}]}
{"channel":"book","type":"update","data":[{"symbol":"LINK/USD","bids":[],"asks":[{"price":18.54516,"qty":8.06136702}],"checksum":1038597305,"timestamp":"2024-06-01T18:06:56.977671Z"}]}
{"channel":"book","type":"update","data":[{"symbol":"LINK/USD","bids":[],"asks":[{"price":18.54284,"qty":0.00000000},{"price":18.54883,"qty":121.30145927}],"checksum":1769897545,"timestamp":"2024-06-01T18:06:57.029844Z"}]}
{"channel":"book","type":"update","data":[{"symbol":"LINK/USD","bids":[],"asks":[{"price":18.54302,"qty":0.00000000},{"price":18.54936,"qty":2.23393540}],"checksum":2989753382,"timestamp":"2024-06-01T18:06:57.030250Z"}]}
{"channel":"book","type":"update","data":[{"symbol":"LINK/USD","bids":[{"price":18.53968,"qty":33.26282194}],"asks":[],"checksum":3976804515,"timestamp":"2024-06-01T18:06:57.030438Z"}]}
{"channel":"book","type":"update","data":[{"symbol":"LINK/USD","bids":[],"asks":[{"price":18.54271,"qty":31.87500000}],"checksum":2667498354,"timestamp":"2024-06-01T18:06:57.033013Z"}]}
{"channel":"book","type":"update","data":[{"symbol":"LINK/USD","bids":[{"price":18.53968,"qty":1.38782194}],"asks":[],"checksum":2580633249,"timestamp":"2024-06-01T18:06:57.033455Z"}]}
{"channel":"book","type":"update","data":[{"symbol":"LINK/USD","bids":[{"price":18.53968,"qty":0.00000000},{"price":18.53540,"qty":433.54710000},{"price":18.53969,"qty":1.38779321}],"asks":[],"checksum":3959795056,"timestamp":"2024-06-01T18:06:57.033714Z"}]}
{"channel":"book","type":"update","data":[{"symbol":"LINK/USD","bids":[],"asks":[{"price":18.54271,"qty":0.00000000},{"price":18.54936,"qty":2.23393540}],"checksum":3353411575,"timestamp":"2024-06-01T18:06:57.036029Z"}]}
{"channel":"book","type":"update","data":[{"symbol":"LINK/USD","bids":[{"price":18.53969,"qty":0.00000000},{"price":18.53540,"qty":433.54710000},{"price":18.53968,"qty":1.38779395}],"asks":[],"checksum":2378449892,"timestamp":"2024-06-01T18:06:57.037271Z"}]}
{"channel":"book","type":"update","data":[{"symbol":"LINK/USD","bids":[],"asks":[{"price":18.54293,"qty":31.87500000}],"checksum":1997475160,"timestamp":"2024-06-01T18:06:57.039039Z"}]}
{"channel":"book","type":"update","data":[{"symbol":"LINK/USD","bids":[{"price":18.53968,"qty":33.26279395}],"asks":[],"checksum":282348424,"timestamp":"2024-06-01T18:06:57.133611Z"}]}
{"channel":"book","type":"update","data":[{"symbol":"LINK/USD","bids":[{"price":18.53968,"qty":65.13779395}],"asks":[],"checksum":1005638676,"timestamp":"2024-06-01T18:06:57.133832Z"}]}
{"channel":"book","type":"update","data":[{"symbol":"LINK/USD","bids":[],"asks":[{"price":18.54293,"qty":0.00000000},{"price":18.54936,"qty":2.23393540}],"checksum":4192067837,"timestamp":"2024-06-01T18:06:57.133890Z"}]}
{"channel":"book","type":"update","data":[{"symbol":"LINK/USD","bids":[{"price":18.53968,"qty":33.26279395}],"asks":[],"checksum":3539566433,"timestamp":"2024-06-01T18:06:57.137520Z"}]}
{"channel":"book","type":"update","data":[{"symbol":"LINK/USD","bids":[{"price":18.53969,"qty":243.48672997}],"asks":[],"checksum":3906241837,"timestamp":"2024-06-01T18:06:57.137911Z"}]}
{"channel":"book","type":"update","data":[{"symbol":"LINK/USD","bids":[{"price":18.53968,"qty":65.13779395}],"asks":[],"checksum":1824421181,"timestamp":"2024-06-01T18:06:57.140259Z"}]}
{"channel":"book","type":"update","data":[{"symbol":"LINK/USD","bids":[{"price":18.53970,"qty":31.87500000}],"asks":[],"checksum":1026077407,"timestamp":"2024-06-01T18:06:57.141485Z"}]}
{"channel":"book","type":"update","data":[{"symbol":"LINK/USD","bids":[{"price":18.53970,"qty":0.00000000},{"price":18.53578,"qty":269.68105392}],"asks":[],"checksum":1824421181,"timestamp":"2024-06-01T18:06:57.144503Z"}]}
{"channel":"book","type":"update","data":[{"symbol":"LINK/USD","bids":[{"price":18.53968,"qty":33.26279395}],"asks":[],"checksum":3906241837,"timestamp":"2024-06-01T18:06:57.144650Z"}]}
{"channel":"book","type":"update","data":[{"symbol":"LINK/USD","bids":[{"price":18.53968,"qty":1.38779395}],"asks":[],"checksum":1786873175,"timestamp":"2024-06-01T18:06:57.145446Z"}]}
{"channel":"book","type":"update","data":[{"symbol":"LINK/USD","bids":[{"price":18.53969,"qty":275.36172997}],"asks":[],"checksum":225776097,"timestamp":"2024-06-01T18:06:57.150623Z"}]}
{"channel":"book","type":"update","data":[{"symbol":"LINK/USD","bids":[{"price":18.53972,"qty":31.87500000}],"asks":[],"checksum":2038398621,"timestamp":"2024-06-01T18:06:57.220205Z"}]}
{"channel":"book","type":"update","data":[{"symbol":"LINK/USD","bids":[{"price":18.53969,"qty":243.48672997}],"asks":[],"checksum":3662519132,"timestamp":"2024-06-01T18:06:57.223755Z"}]}
{"channel":"book","type":"update","data":[{"symbol":"LINK/USD","bids":[{"price":18.53967,"qty":0.00000000},{"price":18.53578,"qty":269.68105392}],"asks":[],"checksum":534804288,"timestamp":"2024-06-01T18:06:57.223880Z"}]}
{"channel":"book","type":"update","data":[{"symbol":"LINK/USD","bids":[],"asks":[{"price":18.54300,"qty":0.00000000},{"price":18.54989,"qty":40.00000000}],"checksum":1051039455,"timestamp":"2024-06-01T18:06:57.225041Z"}]}
{"channel":"book","type":"update","data":[{"symbol":"LINK/USD","bids":[],"asks":[{"price":18.54515,"qty":40.00000000}],"checksum":3999250131,"timestamp":"2024-06-01T18:06:57.225179Z"}]}
{"channel":"book","type":"update","data":[{"symbol":"LINK/USD","bids":[],"asks":[{"price":18.54274,"qty":31.87500000}],"checksum":2690137213,"timestamp":"2024-06-01T18:06:57.226851Z"}]}
{"channel":"book","type":"update","data":[{"symbol":"LINK/USD","bids":[{"price":18.53972,"qty":0.00000000},{"price":18.53551,"qty":63.75000000}],"asks":[],"checksum":3370441001,"timestamp":"2024-06-01T18:06:57.226931Z"}]}
{"channel":"book","type":"update","data":[{"symbol":"LINK/USD","bids":[{"price":18.53972,"qty":31.87500000}],"asks":[],"checksum":2690137213,"timestamp":"2024-06-01T18:06:57.227233Z"}]}
{"channel":"book","type":"update","data":[{"symbol":"LINK/USD","bids":[],"asks":[{"price":18.54517,"qty":0.00000000},{"price":18.54936,"qty":2.23393540}],"checksum":325932167,"timestamp":"2024-06-01T18:06:57.228015Z"}]}
{"channel":"book","type":"update","data":[{"symbol":"LINK/USD","bids":[],"asks":[{"price":18.54468,"qty":33.00000000}],"checksum":255121317,"timestamp":"2024-06-01T18:06:57.229059Z"}]}
{"channel":"book","type":"update","data":[{"symbol":"LINK/USD","bids":[],"asks":[{"price":18.54516,"qty":0.00000000},{"price":18.54936,"qty":2.23393540}],"checksum":3175563709,"timestamp":"2024-06-01T18:06:57.229656Z"}]}
{"channel":"book","type":"update","data":[{"symbol":"LINK/USD","bids":[{"price":18.53972,"qty":0.00000000},{"price":18.53551,"qty":63.75000000}],"asks":[],"checksum":3590038761,"timestamp":"2024-06-01T18:06:57.230828Z"}]}
{"channel":"book","type":"update","data":[{"symbol":"LINK/USD","bids":[],"asks":[{"price":18.54514,"qty":8.06136702}],"checksum":645656749,"timestamp":"2024-06-01T18:06:57.233530Z"}]}
{"channel":"book","type":"update","data":[{"symbol":"LINK/USD","bids":[],"asks":[{"price":18.54514,"qty":0.00000000},{"price":18.54936,"qty":2.23393540}],"checksum":3590038761,"timestamp":"2024-06-01T18:06:57.236891Z"}]}
{"channel":"book","type":"update","data":[{"symbol":"LINK/USD","bids":[],"asks":[{"price":18.54274,"qty":0.00000000},{"price":18.54989,"qty":40.00000000}],"checksum":112752353,"timestamp":"2024-06-01T18:06:57.358904Z"}]}
{"channel":"book","type":"update","data":[{"symbol":"LINK/USD","bids":[],"asks":[{"price":18.54257,"qty":31.87500000}],"checksum":2295721251,"timestamp":"2024-06-01T18:06:57.362514Z"}]}
{"channel":"book","type":"update","data":[{"symbol":"LINK/USD","bids":[],"asks":[{"price":18.54257,"qty":0.00000000},{"price":18.54989,"qty":40.00000000}],"checksum":112752353,"timestamp":"2024-06-01T18:06:57.380317Z"}]}
{"channel":"book","type":"update","data":[{"symbol":"LINK/USD","bids":[],"asks":[{"price":18.54376,"qty":31.87500000}],"checksum":3631995151,"timestamp":"2024-06-01T18:06:57.383611Z"}]}
{"channel":"book","type":"update","data":[{"symbol":"LINK/USD","bids":[],"asks":[{"price":18.54468,"qty":0.00000000},{"price":18.54989,"qty":40.00000000}],"checksum":1365725426,"timestamp":"2024-06-01T18:06:57.386308Z"}]}
{"channel":"book","type":"update","data":[{"symbol":"LINK/USD","bids":[],"asks":[{"price":18.54374,"qty":33.00000000}],"checksum":923115661,"timestamp":"2024-06-01T18:06:57.386367Z"}]}
{"channel":"book","type":"update","data":[{"symbol":"LINK/USD","bids":[],"asks":[{"price":18.54285,"qty":31.87500000}],"checksum":727755195,"timestamp":"2024-06-01T18:06:57.390251Z"}]}
{"channel":"book","type":"update","data":[{"symbol":"LINK/USD","bids":[],"asks":[{"price":18.54285,"qty":0.00000000},{"price":18.54936,"qty":2.23393540}],"checksum":923115661,"timestamp":"2024-06-01T18:06:57.528213Z"}]}
{"channel":"book","type":"update","data":[{"symbol":"LINK/USD","bids":[],"asks":[{"price":18.54314,"qty":31.87500000}],"checksum":2335427119,"timestamp":"2024-06-01T18:06:57.532474Z"}]}
{"channel":"book","type":"update","data":[{"symbol":"LINK/USD","bids":[{"price":18.53969,"qty":0.00000000},{"price":18.53540,"qty":433.54710000}],"asks":[],"checksum":2888547299,"timestamp":"2024-06-01T18:06:57.532760Z"}]}
{"channel":"book","type":"update","data":[{"symbol":"LINK/USD","bids":[{"price":18.53967,"qty":243.48672997}],"asks":[],"checksum":1907039199,"timestamp":"2024-06-01T18:06:57.532962Z"}]}
{"channel":"book","type":"update","data":[{"symbol":"LINK/USD","bids":[{"price":18.53968,"qty":0.00000000},{"price":18.53540,"qty":433.54710000},{"price":18.53967,"qty":244.87459344}],"asks":[],"checksum":174185910,"timestamp":"2024-06-01T18:06:57.536680Z"}]}
{"channel":"book","type":"update","data":[{"symbol":"LINK/USD","bids":[{"price":18.53967,"qty":276.74959344}],"asks":[],"checksum":553625001,"timestamp":"2024-06-01T18:06:57.578691Z"}]}
{"channel":"book","type":"update","data":[{"symbol":"LINK/USD","bids":[{"price":18.53967,"qty":244.87459344}],"asks":[],"checksum":174185910,"timestamp":"2024-06-01T18:06:57.627937Z"}]}
{"channel":"book","type":"update","data":[{"symbol":"LINK/USD","bids":[{"price":18.53967,"qty":243.48672997},{"price":18.53968,"qty":1.38786272}],"asks":[],"checksum":2442354747,"timestamp":"2024-06-01T18:06:57.663529Z"}]}
{"channel":"book","type":"update","data":[{"symbol":"LINK/USD","bids":[{"price":18.53968,"qty":33.26286272}],"asks":[],"checksum":2201387769,"timestamp":"2024-06-01T18:06:58.127138Z"}]}
{"channel":"book","type":"update","data":[{"symbol":"LINK/USD","bids":[],"asks":[{"price":18.54314,"qty":0.00000000},{"price":18.54936,"qty":2.23393540}],"checksum":3142743639,"timestamp":"2024-06-01T18:06:58.127391Z"}]}
{"channel":"book","type":"update","data":[{"symbol":"LINK/USD","bids":[{"price":18.53977,"qty":31.87500000}],"asks":[],"checksum":3023347080,"timestamp":"2024-06-01T18:06:58.127999Z"}]}
{"channel":"book","type":"update","data":[{"symbol":"LINK/USD","bids":[],"asks":[{"price":18.54343,"qty":31.87500000}],"checksum":1779699655,"timestamp":"2024-06-01T18:06:58.130884Z"}]}
{"channel":"book","type":"update","data":[{"symbol":"LINK/USD","bids":[{"price":18.53969,"qty":243.48672997}],"asks":[],"checksum":840837609,"timestamp":"2024-06-01T18:06:58.134533Z"}]}
{"channel":"book","type":"update","data":[{"symbol":"LINK/USD","bids":[{"price":18.53977,"qty":0.00000000},{"price":18.53578,"qty":269.68105392}],"asks":[],"checksum":2149739232,"timestamp":"2024-06-01T18:06:58.165129Z"}]}
{"channel":"book","type":"update","data":[{"symbol":"LINK/USD","bids":[{"price":18.53968,"qty":1.38786272}],"asks":[],"checksum":3677214238,"timestamp":"2024-06-01T18:06:58.165209Z"}]}
{"channel":"book","type":"update","data":[{"symbol":"LINK/USD","bids":[{"price":18.53977,"qty":31.87500000}],"asks":[],"checksum":1923373061,"timestamp":"2024-06-01T18:06:58.168393Z"}]}
{"channel":"book","type":"update","data":[{"symbol":"LINK/USD","bids":[{"price":18.53967,"qty":0.00000000},{"price":18.53578,"qty":269.68105392}],"asks":[],"checksum":3070866457,"timestamp":"2024-06-01T18:06:58.168973Z"}]}
{"channel":"book","type":"update","data":[{"symbol":"LINK/USD","bids":[{"price":18.53977,"qty":0.00000000},{"price":18.53551,"qty":63.75000000}],"asks":[],"checksum":3504799535,"timestamp":"2024-06-01T18:06:58.172119Z"}]}
{"channel":"book","type":"update","data":[{"symbol":"LINK/USD","bids":[],"asks":[{"price":18.54343,"qty":63.75000000}],"checksum":2457338501,"timestamp":"2024-06-01T18:06:58.234361Z"}]}
{"channel":"book","type":"update","data":[{"symbol":"LINK/USD","bids":[],"asks":[{"price":18.54514,"qty":8.06136702}],"checksum":2078590585,"timestamp":"2024-06-01T18:06:58.238719Z"}]}
{"channel":"book","type":"update","data":[{"symbol":"LINK/USD","bids":[],"asks":[{"price":18.54341,"qty":40.00000000}],"checksum":437235055,"timestamp":"2024-06-01T18:06:58.239184Z"}]}
{"channel":"book","type":"update","data":[{"symbol":"LINK/USD","bids":[],"asks":[{"price":18.54376,"qty":0.00000000},{"price":18.54769,"qty":31.87500000}],"checksum":3103619445,"timestamp":"2024-06-01T18:06:58.242527Z"}]}
{"channel":"book","type":"update","data":[{"symbol":"LINK/USD","bids":[],"asks":[{"price":18.54249,"qty":31.87500000}],"checksum":3313244856,"timestamp":"2024-06-01T18:06:58.242970Z"}]}
{"channel":"book","type":"update","data":[{"symbol":"LINK/USD","bids":[],"asks":[{"price":18.54374,"qty":0.00000000},{"price":18.54769,"qty":31.87500000}],"checksum":3959785159,"timestamp":"2024-06-01T18:06:58.245290Z"}]}
{"channel":"book","type":"update","data":[{"symbol":"LINK/USD","bids":[],"asks":[{"price":18.54342,"qty":33.00000000}],"checksum":152885480,"timestamp":"2024-06-01T18:06:58.250880Z"}]}
{"channel":"book","type":"update","data":[{"symbol":"LINK/USD","bids":[],"asks":[{"price":18.54341,"qty":0.00000000},{"price":18.54769,"qty":31.87500000}],"checksum":3407149936,"timestamp":"2024-06-01T18:06:58.253982Z"}]}
{"channel":"book","type":"update","data":[{"symbol":"LINK/USD","bids":[],"asks":[{"price":18.54249,"qty":0.00000000},{"price":18.54883,"qty":121.30145927}],"checksum":823168055,"timestamp":"2024-06-01T18:06:58.271979Z"}]}
{"channel":"book","type":"update","data":[{"symbol":"LINK/USD","bids":[],"asks":[{"price":18.54343,"qty":31.87500000}],"checksum":1549608449,"timestamp":"2024-06-01T18:06:58.272445Z"}]}
{"channel":"book","type":"update","data":[{"symbol":"LINK/USD","bids":[],"asks":[{"price":18.54287,"qty":31.87500000}],"checksum":3960061054,"timestamp":"2024-06-01T18:06:58.275303Z"}]}
{"channel":"book","type":"update","data":[{"symbol":"LINK/USD","bids":[],"asks":[{"price":18.54340,"qty":40.00000000}],"checksum":3782160462,"timestamp":"2024-06-01T18:06:58.276786Z"}]}
{"channel":"book","type":"update","data":[{"symbol":"LINK/USD","bids":[{"price":18.53968,"qty":0.00000000},{"price":18.53540,"qty":433.54710000},{"price":18.53970,"qty":1.38786108}],"asks":[],"checksum":1870508764,"timestamp":"2024-06-01T18:06:58.317672Z"}]}
{"channel":"book","type":"update","data":[{"symbol":"LINK/USD","bids":[],"asks":[{"price":18.54340,"qty":0.00000000},{"price":18.54769,"qty":31.87500000}],"checksum":1645952748,"timestamp":"2024-06-01T18:06:58.322031Z"}]}
{"channel":"book","type":"update","data":[{"symbol":"LINK/USD","bids":[],"asks":[{"price":18.54287,"qty":0.00000000},{"price":18.54883,"qty":121.30145927}],"checksum":3528434835,"timestamp":"2024-06-01T18:06:58.374376Z"}]}
{"channel":"book","type":"update","data":[{"symbol":"LINK/USD","bids":[],"asks":[{"price":18.54310,"qty":31.87500000}],"checksum":3211451299,"timestamp":"2024-06-01T18:06:58.378397Z"}]}
{"channel":"book","type":"update","data":[{"symbol":"LINK/USD","bids":[{"price":18.53970,"qty":33.26286108}],"asks":[],"checksum":2941078692,"timestamp":"2024-06-01T18:06:58.382215Z"}]}
{"channel":"book","type":"update","data":[{"symbol":"LINK/USD","bids":[],"asks":[{"price":18.54310,"qty":0.00000000},{"price":18.54883,"qty":121.30145927}],"checksum":2314819959,"timestamp":"2024-06-01T18:06:58.397685Z"}]}
{"channel":"book","type":"update","data":[{"symbol":"LINK/USD","bids":[{"price":18.53979,"qty":31.87500000}],"asks":[],"checksum":839539976,"timestamp":"2024-06-01T18:06:58.397734Z"}]}
{"channel":"book","type":"update","data":[{"symbol":"LINK/USD","bids":[],"asks":[{"price":18.54343,"qty":0.00000000},{"price":18.54936,"qty":2.23393540}],"checksum":146353447,"timestamp":"2024-06-01T18:06:58.400357Z"}]}
{"channel":"book","type":"update","data":[{"symbol":"LINK/USD","bids":[],"asks":[{"price":18.54577,"qty":0.00000000},{"price":18.54989,"qty":40.00000000}],"checksum":633139016,"timestamp":"2024-06-01T18:06:58.400812Z"}]}
{"channel":"book","type":"update","data":[{"symbol":"LINK/USD","bids":[],"asks":[{"price":18.54467,"qty":33.00000000}],"checksum":2734485469,"timestamp":"2024-06-01T18:06:58.403200Z"}]}
{"channel":"book","type":"update","data":[{"symbol":"LINK/USD","bids":[],"asks":[{"price":18.54342,"qty":0.00000000},{"price":18.54989,"qty":40.00000000}],"checksum":1910053982,"timestamp":"2024-06-01T18:06:58.403315Z"}]}
{"channel":"book","type":"update","data":[{"symbol":"LINK/USD","bids":[],"asks":[{"price":18.54411,"qty":31.87500000}],"checksum":3638731303,"timestamp":"2024-06-01T18:06:58.407032Z"}]}
{"channel":"book","type":"update","data":[{"symbol":"LINK/USD","bids":[],"asks":[{"price":18.54467,"qty":0.00000000},{"price":18.54989,"qty":40.00000000}],"checksum":1604494002,"timestamp":"2024-06-01T18:06:58.410157Z"}]}
{"channel":"book","type":"update","data":[{"symbol":"LINK/USD","bids":[],"asks":[{"price":18.54407,"qty":33.00000000}],"checksum":2575576235,"timestamp":"2024-06-01T18:06:58.410489Z"}]}
{"channel":"book","type":"update","data":[{"symbol":"LINK/USD","bids":[{"price":18.53971,"qty":243.48672997}],"asks":[],"checksum":2890983049,"timestamp":"2024-06-01T18:06:58.411195Z"}]}
{"channel":"book","type":"update","data":[{"symbol":"LINK/USD","bids":[],"asks":[{"price":18.54423,"qty":6.43107813}],"checksum":1861996386,"timestamp":"2024-06-01T18:06:58.520144Z"}]}
{"channel":"book","type":"update","data":[{"symbol":"LINK/USD","bids":[{"price":18.53969,"qty":0.00000000},{"price":18.53578,"qty":269.68105392}],"asks":[],"checksum":2730771022,"timestamp":"2024-06-01T18:06:58.524063Z"}]}
{"channel":"book","type":"update","data":[{"symbol":"LINK/USD","bids":[],"asks":[{"price":18.54383,"qty":31.87500000}],"checksum":3765593190,"timestamp":"2024-06-01T18:06:58.527491Z"}]}
{"channel":"book","type":"update","data":[{"symbol":"LINK/USD","bids":[{"price":18.53979,"qty":0.00000000},{"price":18.53551,"qty":63.75000000}],"asks":[],"checksum":634282319,"timestamp":"2024-06-01T18:06:58.858041Z"}]}
{"channel":"book","type":"update","data":[{"symbol":"LINK/USD","bids":[{"price":18.53970,"qty":1.38786108}],"asks":[],"checksum":281211907,"timestamp":"2024-06-01T18:06:58.861740Z"}]}
{"channel":"book","type":"update","data":[{"symbol":"LINK/USD","bids":[{"price":18.53971,"qty":275.36172997}],"asks":[],"checksum":958172824,"timestamp":"2024-06-01T18:06:58.927862Z"}]}
{"channel":"book","type":"update","data":[{"symbol":"LINK/USD","bids":[{"price":18.53970,"qty":0.00000000},{"price":18.53540,"qty":433.54710000},{"price":18.53972,"qty":1.38785953}],"asks":[],"checksum":991660261,"timestamp":"2024-06-01T18:06:58.928204Z"}]}
{"channel":"book","type":"update","data":[{"symbol":"LINK/USD","bids":[{"price":18.53971,"qty":243.48672997}],"asks":[],"checksum":3621472294,"timestamp":"2024-06-01T18:06:58.931794Z"}]}
{"channel":"book","type":"update","data":[{"symbol":"LINK/USD","bids":[{"price":18.53972,"qty":33.26285953}],"asks":[],"checksum":815584351,"timestamp":"2024-06-01T18:06:58.934898Z"}]}
{"channel":"book","type":"update","data":[{"symbol":"LINK/USD","bids":[],"asks":[{"price":18.54381,"qty":40.00000000}],"checksum":3264208465,"timestamp":"2024-06-01T18:06:59.255292Z"}]}
{"channel":"book","type":"update","data":[{"symbol":"LINK/USD","bids":[{"price":18.53972,"qty":1.38785953}],"asks":[],"checksum":2798717045,"timestamp":"2024-06-01T18:06:59.258399Z"}]}
{"channel":"book","type":"update","data":[{"symbol":"LINK/USD","bids":[],"asks":[{"price":18.54411,"qty":0.00000000},{"price":18.54769,"qty":31.87500000}],"checksum":49855523,"timestamp":"2024-06-01T18:06:59.258515Z"}]}
{"channel":"book","type":"update","data":[{"symbol":"LINK/USD","bids":[],"asks":[{"price":18.54310,"qty":31.87500000}],"checksum":2908687564,"timestamp":"2024-06-01T18:06:59.258848Z"}]}
{"channel":"book","type":"update","data":[{"symbol":"LINK/USD","bids":[{"price":18.53973,"qty":243.48672997}],"asks":[],"checksum":1065346619,"timestamp":"2024-06-01T18:06:59.259210Z"}]}
{"channel":"book","type":"update","data":[{"symbol":"LINK/USD","bids":[],"asks":[{"price":18.54515,"qty":0.00000000},{"price":18.54769,"qty":31.87500000}],"checksum":1054317100,"timestamp":"2024-06-01T18:06:59.259526Z"}]}
{"channel":"book","type":"update","data":[{"symbol":"LINK/USD","bids":[{"price":18.53972,"qty":33.26285953}],"asks":[],"checksum":252451105,"timestamp":"2024-06-01T18:06:59.262599Z"}]}
{"channel":"book","type":"update","data":[{"symbol":"LINK/USD","bids":[],"asks":[{"price":18.54514,"qty":0.00000000},{"price":18.54883,"qty":121.30145927}],"checksum":341581733,"timestamp":"2024-06-01T18:06:59.263582Z"}]}
{"channel":"book","type":"update","data":[{"symbol":"LINK/USD","bids":[],"asks":[{"price":18.54310,"qty":0.00000000},{"price":18.54936,"qty":2.23393540}],"checksum":222338849,"timestamp":"2024-06-01T18:06:59.338494Z"}]}
{"channel":"book","type":"update","data":[{"symbol":"LINK/USD","bids":[{"price":18.53981,"qty":31.87500000}],"asks":[],"checksum":137127243,"timestamp":"2024-06-01T18:06:59.341314Z"}]}
{"channel":"book","type":"update","data":[{"symbol":"LINK/USD","bids":[],"asks":[{"price":18.54352,"qty":31.87500000}],"checksum":4105918327,"timestamp":"2024-06-01T18:06:59.342201Z"}]}
{"channel":"book","type":"update","data":[{"symbol":"LINK/USD","bids":[{"price":18.53971,"qty":0.00000000},{"price":18.53578,"qty":269.68105392}],"asks":[],"checksum":2593595191,"timestamp":"2024-06-01T18:06:59.342387Z"}]}
{"channel":"book","type":"update","data":[{"symbol":"LINK/USD","bids":[],"asks":[{"price":18.54352,"qty":0.00000000},{"price":18.54936,"qty":2.23393540}],"checksum":1711287563,"timestamp":"2024-06-01T18:06:59.532845Z"}]}
{"channel":"book","type":"update","data":[{"symbol":"LINK/USD","bids":[],"asks":[{"price":18.54373,"qty":31.87500000}],"checksum":3699899618,"timestamp":"2024-06-01T18:06:59.536918Z"}]}
{"channel":"book","type":"update","data":[{"symbol":"LINK/USD","bids":[],"asks":[{"price":18.54373,"qty":0.00000000},{"price":18.54936,"qty":2.23393540}],"checksum":1711287563,"timestamp":"2024-06-01T18:06:59.561198Z"}]}
{"channel":"book","type":"update","data":[{"symbol":"LINK/USD","bids":[],"asks":[{"price":18.54383,"qty":0.00000000},{"price":18.54989,"qty":40.00000000}],"checksum":4222334625,"timestamp":"2024-06-01T18:06:59.564090Z"}]}
{"channel":"book","type":"update","data":[{"symbol":"LINK/USD","bids":[{"price":18.53972,"qty":31.87500000},{"price":18.53982,"qty":1.38785656}],"asks":[],"checksum":3691214714,"timestamp":"2024-06-01T18:06:59.572227Z"}]}
{"channel":"book","type":"update","data":[{"symbol":"LINK/USD","bids":[],"asks":[{"price":18.54371,"qty":31.87500000}],"checksum":4252086238,"timestamp":"2024-06-01T18:06:59.587107Z"}]}
{"channel":"book","type":"update","data":[{"symbol":"LINK/USD","bids":[{"price":18.53981,"qty":0.00000000},{"price":18.53578,"qty":269.68105392}],"asks":[],"checksum":3396675743,"timestamp":"2024-06-01T18:06:59.706451Z"}]}
{"channel":"book","type":"update","data":[{"symbol":"LINK/USD","bids":[{"price":18.53982,"qty":0.00000000},{"price":18.53551,"qty":63.75000000},{"price":18.53974,"qty":1.38656542}],"asks":[],"checksum":3306216210,"timestamp":"2024-06-01T18:06:59.709783Z"}]}
{"channel":"book","type":"update","data":[{"symbol":"LINK/USD","bids":[{"price":18.53972,"qty":0.00000000},{"price":18.53551,"qty":63.75000000}],"asks":[],"checksum":533254958,"timestamp":"2024-06-01T18:06:59.713061Z"}]}
{"channel":"book","type":"update","data":[{"symbol":"LINK/USD","bids":[{"price":18.53974,"qty":33.26156542}],"asks":[],"checksum":1698201252,"timestamp":"2024-06-01T18:06:59.915679Z"}]}
{"channel":"book","type":"update","data":[{"symbol":"LINK/USD","bids":[{"price":18.53974,"qty":1.38656542}],"asks":[],"checksum":533254958,"timestamp":"2024-06-01T18:06:59.929946Z"}]}
{"channel":"book","type":"update","data":[{"symbol":"LINK/USD","bids":[],"asks":[{"price":18.54371,"qty":63.75000000}],"checksum":866981127,"timestamp":"2024-06-01T18:06:59.934044Z"}]}
{"channel":"book","type":"update","data":[{"symbol":"LINK/USD","bids":[],"asks":[{"price":18.54407,"qty":0.00000000},{"price":18.54989,"qty":40.00000000}],"checksum":3119515526,"timestamp":"2024-06-01T18:06:59.936713Z"}]}
{"channel":"book","type":"update","data":[{"symbol":"LINK/USD","bids":[],"asks":[{"price":18.54375,"qty":33.00000000}],"checksum":1438077715,"timestamp":"2024-06-01T18:06:59.936729Z"}]}
{"channel":"book","type":"update","data":[{"symbol":"LINK/USD","bids":[],"asks":[{"price":18.54371,"qty":31.87500000}],"checksum":2043843898,"timestamp":"2024-06-01T18:07:00.095716Z"}]}
{"channel":"book","type":"update","data":[{"symbol":"LINK/USD","bids":[{"price":18.53974,"qty":33.26156542}],"asks":[],"checksum":2139402399,"timestamp":"2024-06-01T18:07:00.095909Z"}]}
{"channel":"book","type":"update","data":[{"symbol":"LINK/USD","bids":[],"asks":[{"price":18.54563,"qty":0.00000000},{"price":18.54989,"qty":40.00000000}],"checksum":3505908795,"timestamp":"2024-06-01T18:07:00.099035Z"}]}
{"channel":"book","type":"update","data":[{"symbol":"LINK/USD","bids":[{"price":18.54024,"qty":31.87500000}],"asks":[],"checksum":3508244785,"timestamp":"2024-06-01T18:07:00.099907Z"}]}
{"channel":"book","type":"update","data":[{"symbol":"LINK/USD","bids":[],"asks":[{"price":18.54371,"qty":0.00000000},{"price":18.55100,"qty":83.67104051}],"checksum":3946930110,"timestamp":"2024-06-01T18:07:00.100736Z"}]}
{"channel":"book","type":"update","data":[{"symbol":"LINK/USD","bids":[],"asks":[{"price":18.54371,"qty":31.87500000}],"checksum":3508244785,"timestamp":"2024-06-01T18:07:00.132652Z"}]}
{"channel":"book","type":"update","data":[{"symbol":"LINK/USD","bids":[{"price":18.54024,"qty":0.00000000},{"price":18.53551,"qty":63.75000000}],"asks":[],"checksum":3505908795,"timestamp":"2024-06-01T18:07:00.136473Z"}]}
{"channel":"book","type":"update","data":[{"symbol":"LINK/USD","bids":[{"price":18.53975,"qty":243.48672997}],"asks":[],"checksum":1523897132,"timestamp":"2024-06-01T18:07:00.137125Z"}]}
{"channel":"book","type":"update","data":[{"symbol":"LINK/USD","bids":[{"price":18.53974,"qty":1.38656542}],"asks":[],"checksum":1885425680,"timestamp":"2024-06-01T18:07:00.140012Z"}]}
{"channel":"book","type":"update","data":[{"symbol":"LINK/USD","bids":[{"price":18.53975,"qty":275.36172997}],"asks":[],"checksum":395691174,"timestamp":"2024-06-01T18:07:00.148170Z"}]}
{"channel":"book","type":"update","data":[{"symbol":"LINK/USD","bids":[{"price":18.53780,"qty":0.00000000},{"price":18.53551,"qty":63.75000000}],"asks":[],"checksum":4023606569,"timestamp":"2024-06-01T18:07:00.170581Z"}]}
{"channel":"book","type":"update","data":[{"symbol":"LINK/USD","bids":[{"price":18.53974,"qty":0.00000000},{"price":18.53540,"qty":433.54710000},{"price":18.53976,"qty":1.38656429}],"asks":[],"checksum":1521809264,"timestamp":"2024-06-01T18:07:00.172316Z"}]}
{"channel":"book","type":"update","data":[{"symbol":"LINK/USD","bids":[{"price":18.53975,"qty":243.48672997}],"asks":[],"checksum":1479910586,"timestamp":"2024-06-01T18:07:00.176185Z"}]}
{"channel":"book","type":"update","data":[{"symbol":"LINK/USD","bids":[{"price":18.53975,"qty":0.00000000},{"price":18.53540,"qty":433.54710000}],"asks":[],"checksum":2708260071,"timestamp":"2024-06-01T18:07:00.176220Z"}]}
{"channel":"book","type":"update","data":[{"symbol":"LINK/USD","bids":[{"price":18.53976,"qty":0.00000000},{"price":18.53539,"qty":31.87500000},{"price":18.53974,"qty":1.38656579}],"asks":[],"checksum":2712463945,"timestamp":"2024-06-01T18:07:00.179604Z"}]}
{"channel":"book","type":"update","data":[{"symbol":"LINK/USD","bids":[{"price":18.53976,"qty":31.87500000}],"asks":[],"checksum":2665628546,"timestamp":"2024-06-01T18:07:00.179826Z"}]}
{"channel":"book","type":"update","data":[{"symbol":"LINK/USD","bids":[{"price":18.53976,"qty":0.00000000},{"price":18.53540,"qty":433.54710000}],"asks":[],"checksum":2712463945,"timestamp":"2024-06-01T18:07:00.183254Z"}]}
{"channel":"book","type":"update","data":[{"symbol":"LINK/USD","bids":[{"price":18.53976,"qty":31.87500000}],"asks":[],"checksum":2665628546,"timestamp":"2024-06-01T18:07:00.186282Z"}]}
{"channel":"book","type":"update","data":[{"symbol":"LINK/USD","bids":[{"price":18.53976,"qty":0.00000000},{"price":18.53540,"qty":433.54710000}],"asks":[],"checksum":2712463945,"timestamp":"2024-06-01T18:07:00.189814Z"}]}
{"channel":"book","type":"update","data":[{"symbol":"LINK/USD","bids":[{"price":18.53974,"qty":33.26156579}],"asks":[],"checksum":2037490434,"timestamp":"2024-06-01T18:07:00.194991Z"}]}
{"channel":"book","type":"update","data":[{"symbol":"LINK/USD","bids":[{"price":18.53701,"qty":32.68119343}],"asks":[],"checksum":904324388,"timestamp":"2024-06-01T18:07:00.212935Z"}]}
{"channel":"book","type":"update","data":[{"symbol":"LINK/USD","bids":[],"asks":[{"price":18.54563,"qty":30.91774334}],"checksum":1060965023,"timestamp":"2024-06-01T18:07:00.212991Z"}]}
{"channel":"book","type":"update","data":[{"symbol":"LINK/USD","bids":[{"price":18.53975,"qty":243.48672997}],"asks":[],"checksum":1882497664,"timestamp":"2024-06-01T18:07:00.217071Z"}]}
{"channel":"book","type":"update","data":[{"symbol":"LINK/USD","bids":[],"asks":[{"price":18.54369,"qty":40.00000000}],"checksum":4050802148,"timestamp":"2024-06-01T18:07:00.218155Z"}]}
{"channel":"book","type":"update","data":[{"symbol":"LINK/USD","bids":[{"price":18.53974,"qty":1.38656579}],"asks":[],"checksum":4093826616,"timestamp":"2024-06-01T18:07:00.220857Z"}]}
{"channel":"book","type":"update","data":[{"symbol":"LINK/USD","bids":[],"asks":[{"price":18.54320,"qty":31.87500000}],"checksum":3126500948,"timestamp":"2024-06-01T18:07:00.221785Z"}]}
{"channel":"book","type":"update","data":[{"symbol":"LINK/USD","bids":[{"price":18.53975,"qty":275.36172997}],"asks":[],"checksum":3719170786,"timestamp":"2024-06-01T18:07:00.237604Z"}]}
{"channel":"book","type":"update","data":[{"symbol":"LINK/USD","bids":[],"asks":[{"price":18.54369,"qty":0.00000000},{"price":18.54883,"qty":121.30145927}],"checksum":3722427200,"timestamp":"2024-06-01T18:07:00.255057Z"}]}
{"channel":"book","type":"update","data":[{"symbol":"LINK/USD","bids":[],"asks":[{"price":18.54371,"qty":0.00000000},{"price":18.54936,"qty":2.23393540}],"checksum":1275064525,"timestamp":"2024-06-01T18:07:00.258407Z"}]}
{"channel":"book","type":"update","data":[{"symbol":"LINK/USD","bids":[{"price":18.53975,"qty":31.87500000}],"asks":[],"checksum":1414593437,"timestamp":"2024-06-01T18:07:00.258961Z"}]}
{"channel":"book","type":"update","data":[{"symbol":"LINK/USD","bids":[],"asks":[{"price":18.54562,"qty":8.06136702}],"checksum":509361598,"timestamp":"2024-06-01T18:07:00.285939Z"}]}
{"channel":"book","type":"update","data":[{"symbol":"LINK/USD","bids":[],"asks":[{"price":18.54562,"qty":0.00000000},{"price":18.54936,"qty":2.23393540}],"checksum":1414593437,"timestamp":"2024-06-01T18:07:00.289800Z"}]}
{"channel":"book","type":"update","data":[{"symbol":"LINK/USD","bids":[],"asks":[{"price":18.54562,"qty":8.06136702}],"checksum":509361598,"timestamp":"2024-06-01T18:07:00.293926Z"}]}
{"channel":"book","type":"update","data":[{"symbol":"LINK/USD","bids":[{"price":18.53975,"qty":0.00000000},{"price":18.53551,"qty":63.75000000}],"asks":[],"checksum":4082567764,"timestamp":"2024-06-01T18:07:00.474734Z"}]}
{"channel":"book","type":"update","data":[{"symbol":"LINK/USD","bids":[{"price":18.53990,"qty":31.87500000}],"asks":[],"checksum":2171040167,"timestamp":"2024-06-01T18:07:00.580034Z"}]}
{"channel":"book","type":"update","data":[{"symbol":"LINK/USD","bids":[],"asks":[{"price":18.54320,"qty":0.00000000},{"price":18.54936,"qty":2.23393540}],"checksum":2411241942,"timestamp":"2024-06-01T18:07:00.583532Z"}]}
{"channel":"book","type":"update","data":[{"symbol":"LINK/USD","bids":[{"price":18.53990,"qty":0.00000000},{"price":18.53551,"qty":63.75000000}],"asks":[],"checksum":4253604389,"timestamp":"2024-06-01T18:07:00.583976Z"}]}
{"channel":"book","type":"update","data":[{"symbol":"LINK/USD","bids":[],"asks":[{"price":18.54344,"qty":31.87500000}],"checksum":2541777483,"timestamp":"2024-06-01T18:07:00.587019Z"}]}
{"channel":"book","type":"update","data":[{"symbol":"LINK/USD","bids":[{"price":18.53980,"qty":31.87500000}],"asks":[],"checksum":879700639,"timestamp":"2024-06-01T18:07:00.593947Z"}]}
{"channel":"book","type":"update","data":[{"symbol":"LINK/USD","bids":[{"price":18.53980,"qty":0.00000000},{"price":18.53551,"qty":63.75000000}],"asks":[],"checksum":2541777483,"timestamp":"2024-06-01T18:07:00.597674Z"}]}
{"channel":"book","type":"update","data":[{"symbol":"LINK/USD","bids":[{"price":18.53990,"qty":31.87500000}],"asks":[],"checksum":3853519288,"timestamp":"2024-06-01T18:07:00.600412Z"}]}
{"channel":"book","type":"update","data":[{"symbol":"LINK/USD","bids":[{"price":18.53990,"qty":0.00000000},{"price":18.53551,"qty":63.75000000}],"asks":[],"checksum":2541777483,"timestamp":"2024-06-01T18:07:00.604205Z"}]}
{"channel":"book","type":"update","data":[{"symbol":"LINK/USD","bids":[{"price":18.53976,"qty":31.87500000}],"asks":[],"checksum":3594927693,"timestamp":"2024-06-01T18:07:00.621793Z"}]}
{"channel":"book","type":"update","data":[{"symbol":"LINK/USD","bids":[{"price":18.53976,"qty":0.00000000},{"price":18.53551,"qty":63.75000000}],"asks":[],"checksum":2541777483,"timestamp":"2024-06-01T18:07:00.625433Z"}]}
{"channel":"book","type":"update","data":[{"symbol":"LINK/USD","bids":[{"price":18.53993,"qty":31.87500000}],"asks":[],"checksum":1232958036,"timestamp":"2024-06-01T18:07:00.628463Z"}]}
{"channel":"book","type":"update","data":[{"symbol":"LINK/USD","bids":[{"price":18.53993,"qty":0.00000000},{"price":18.53551,"qty":63.75000000}],"asks":[],"checksum":2541777483,"timestamp":"2024-06-01T18:07:00.631529Z"}]}
{"channel":"book","type":"update","data":[{"symbol":"LINK/USD","bids":[{"price":18.53977,"qty":31.87500000}],"asks":[],"checksum":2986535145,"timestamp":"2024-06-01T18:07:00.641806Z"}]}
{"channel":"book","type":"update","data":[{"symbol":"LINK/USD","bids":[{"price":18.53977,"qty":0.00000000},{"price":18.53551,"qty":63.75000000}],"asks":[],"checksum":2541777483,"timestamp":"2024-06-01T18:07:00.645341Z"}]}
{"channel":"book","type":"update","data":[{"symbol":"LINK/USD","bids":[{"price":18.53983,"qty":31.87500000}],"asks":[],"checksum":2560774515,"timestamp":"2024-06-01T18:07:00.648638Z"}]}
{"channel":"book","type":"update","data":[{"symbol":"LINK/USD","bids":[{"price":18.53983,"qty":0.00000000},{"price":18.53551,"qty":63.75000000}],"asks":[],"checksum":2541777483,"timestamp":"2024-06-01T18:07:00.651960Z"}]}
{"channel":"book","type":"update","data":[{"symbol":"LINK/USD","bids":[{"price":18.53986,"qty":31.87500000}],"asks":[],"checksum":3062160134,"timestamp":"2024-06-01T18:07:00.656407Z"}]}
{"channel":"book","type":"update","data":[{"symbol":"LINK/USD","bids":[{"price":18.53986,"qty":0.00000000},{"price":18.53551,"qty":63.75000000}],"asks":[],"checksum":2541777483,"timestamp":"2024-06-01T18:07:00.660232Z"}]}
{"channel":"book","type":"update","data":[{"symbol":"LINK/USD","bids":[{"price":18.53980,"qty":31.87500000}],"asks":[],"checksum":879700639,"timestamp":"2024-06-01T18:07:00.669207Z"}]}
{"channel":"book","type":"update","data":[{"symbol":"LINK/USD","bids":[{"price":18.53980,"qty":0.00000000},{"price":18.53551,"qty":63.75000000}],"asks":[],"checksum":2541777483,"timestamp":"2024-06-01T18:07:00.672653Z"}]}
{"channel":"book","type":"update","data":[{"symbol":"LINK/USD","bids":[],"asks":[{"price":18.54344,"qty":63.75000000}],"checksum":3152393314,"timestamp":"2024-06-01T18:07:00.728018Z"}]}
{"channel":"book","type":"update","data":[{"symbol":"LINK/USD","bids":[],"asks":[{"price":18.54344,"qty":31.87500000}],"checksum":2541777483,"timestamp":"2024-06-01T18:07:00.730794Z"}]}
{"channel":"book","type":"update","data":[{"symbol":"LINK/USD","bids":[],"asks":[{"price":18.54563,"qty":0.00000000},{"price":18.54936,"qty":2.23393540}],"checksum":2769875079,"timestamp":"2024-06-01T18:07:00.731681Z"}]}
{"channel":"book","type":"update","data":[{"symbol":"LINK/USD","bids":[{"price":18.53985,"qty":31.87500000}],"asks":[],"checksum":684794406,"timestamp":"2024-06-01T18:07:00.733051Z"}]}
{"channel":"book","type":"update","data":[{"symbol":"LINK/USD","bids":[{"price":18.53985,"qty":0.00000000},{"price":18.53551,"qty":63.75000000}],"asks":[],"checksum":2769875079,"timestamp":"2024-06-01T18:07:00.737235Z"}]}
{"channel":"book","type":"update","data":[{"symbol":"LINK/USD","bids":[{"price":18.54011,"qty":31.87500000}],"asks":[],"checksum":2959608411,"timestamp":"2024-06-01T18:07:00.741001Z"}]}
{"channel":"book","type":"update","data":[{"symbol":"LINK/USD","bids":[{"price":18.54011,"qty":0.00000000},{"price":18.53551,"qty":63.75000000}],"asks":[],"checksum":2769875079,"timestamp":"2024-06-01T18:07:00.744226Z"}]}
{"channel":"book","type":"update","data":[{"symbol":"LINK/USD","bids":[{"price":18.53979,"qty":31.87500000}],"asks":[],"checksum":2528453150,"timestamp":"2024-06-01T18:07:00.751817Z"}]}
{"channel":"book","type":"update","data":[{"symbol":"LINK/USD","bids":[{"price":18.53979,"qty":0.00000000},{"price":18.53551,"qty":63.75000000}],"asks":[],"checksum":2769875079,"timestamp":"2024-06-01T18:07:00.754986Z"}]}
{"channel":"book","type":"update","data":[{"symbol":"LINK/USD","bids":[],"asks":[{"price":18.54344,"qty":63.75000000}],"checksum":423645753,"timestamp":"2024-06-01T18:07:00.794788Z"}]}
{"channel":"book","type":"update","data":[{"symbol":"LINK/USD","bids":[],"asks":[{"price":18.54344,"qty":31.87500000}],"checksum":2769875079,"timestamp":"2024-06-01T18:07:00.817604Z"}]}
{"channel":"book","type":"update","data":[{"symbol":"LINK/USD","bids":[],"asks":[{"price":18.54344,"qty":63.75000000}],"checksum":423645753,"timestamp":"2024-06-01T18:07:00.834774Z"}]}
{"channel":"book","type":"update","data":[{"symbol":"LINK/USD","bids":[],"asks":[{"price":18.54343,"qty":30.91774334}],"checksum":135562710,"timestamp":"2024-06-01T18:07:00.838671Z"}]}
{"channel":"book","type":"update","data":[{"symbol":"LINK/USD","bids":[],"asks":[{"price":18.54344,"qty":31.87500000}],"checksum":1700343776,"timestamp":"2024-06-01T18:07:00.842283Z"}]}
{"channel":"book","type":"update","data":[{"symbol":"LINK/USD","bids":[],"asks":[{"price":18.54261,"qty":31.87500000}],"checksum":2044847269,"timestamp":"2024-06-01T18:07:00.843609Z"}]}
{"channel":"book","type":"update","data":[{"symbol":"LINK/USD","bids":[],"asks":[{"price":18.54562,"qty":0.00000000},{"price":18.54883,"qty":121.30145927}],"checksum":2513186061,"timestamp":"2024-06-01T18:07:00.848204Z"}]}
{"channel":"book","type":"update","data":[{"symbol":"LINK/USD","bids":[],"asks":[{"price":18.54261,"qty":0.00000000},{"price":18.54936,"qty":2.23393540}],"checksum":3577244176,"timestamp":"2024-06-01T18:07:00.894347Z"}]}
{"channel":"book","type":"update","data":[{"symbol":"LINK/USD","bids":[],"asks":[{"price":18.54279,"qty":31.87500000}],"checksum":1320204040,"timestamp":"2024-06-01T18:07:00.898278Z"}]}
{"channel":"book","type":"update","data":[{"symbol":"LINK/USD","bids":[],"asks":[{"price":18.54279,"qty":0.00000000},{"price":18.54936,"qty":2.23393540}],"checksum":3577244176,"timestamp":"2024-06-01T18:07:00.998499Z"}]}
{"channel":"book","type":"update","data":[{"symbol":"LINK/USD","bids":[],"asks":[{"price":18.54301,"qty":31.87500000}],"checksum":1444334440,"timestamp":"2024-06-01T18:07:01.001909Z"}]}
{"channel":"book","type":"update","data":[{"symbol":"LINK/USD","bids":[{"price":18.53973,"qty":0.00000000},{"price":18.53540,"qty":433.54710000}],"asks":[],"checksum":3340738571,"timestamp":"2024-06-01T18:07:01.003313Z"}]}
{"channel":"book","type":"update","data":[{"symbol":"LINK/USD","bids":[{"price":18.53974,"qty":0.00000000},{"price":18.53539,"qty":31.87500000},{"price":18.53967,"qty":1.38657127}],"asks":[],"checksum":4262351820,"timestamp":"2024-06-01T18:07:01.006392Z"}]}
{"channel":"book","type":"update","data":[{"symbol":"LINK/USD","bids":[{"price":18.53971,"qty":31.87500000}],"asks":[],"checksum":3832262454,"timestamp":"2024-06-01T18:07:01.173038Z"}]}
{"channel":"book","type":"update","data":[{"symbol":"LINK/USD","bids":[],"asks":[{"price":18.54301,"qty":0.00000000},{"price":18.54936,"qty":2.23393540}],"checksum":424611873,"timestamp":"2024-06-01T18:07:01.176375Z"}]}
{"channel":"book","type":"update","data":[{"symbol":"LINK/USD","bids":[{"price":18.53971,"qty":0.00000000},{"price":18.53540,"qty":433.54710000}],"asks":[],"checksum":2099311284,"timestamp":"2024-06-01T18:07:01.177181Z"}]}
{"channel":"book","type":"update","data":[{"symbol":"LINK/USD","bids":[{"price":18.53968,"qty":243.48672997}],"asks":[],"checksum":2592995534,"timestamp":"2024-06-01T18:07:01.177393Z"}]}
{"channel":"book","type":"update","data":[{"symbol":"LINK/USD","bids":[{"price":18.53971,"qty":31.87500000}],"asks":[],"checksum":892814128,"timestamp":"2024-06-01T18:07:01.178460Z"}]}
{"channel":"book","type":"update","data":[{"symbol":"LINK/USD","bids":[],"asks":[{"price":18.54334,"qty":31.87500000}],"checksum":463283026,"timestamp":"2024-06-01T18:07:01.180034Z"}]}
{"channel":"book","type":"update","data":[{"symbol":"LINK/USD","bids":[],"asks":[{"price":18.54344,"qty":0.00000000},{"price":18.54936,"qty":2.23393540}],"checksum":2116318637,"timestamp":"2024-06-01T18:07:01.184094Z"}]}
{"channel":"book","type":"update","data":[{"symbol":"LINK/USD","bids":[{"price":18.53971,"qty":63.75000000}],"asks":[],"checksum":2203048306,"timestamp":"2024-06-01T18:07:01.184165Z"}]}
{"channel":"book","type":"update","data":[{"symbol":"LINK/USD","bids":[],"asks":[{"price":18.54334,"qty":0.00000000},{"price":18.54989,"qty":40.00000000}],"checksum":46570490,"timestamp":"2024-06-01T18:07:01.184282Z"}]}
{"channel":"book","type":"update","data":[{"symbol":"LINK/USD","bids":[],"asks":[{"price":18.54341,"qty":31.87500000}],"checksum":1701173128,"timestamp":"2024-06-01T18:07:01.190554Z"}]}
{"channel":"book","type":"update","data":[{"symbol":"LINK/USD","bids":[],"asks":[{"price":18.54341,"qty":0.00000000},{"price":18.54989,"qty":40.00000000}],"checksum":46570490,"timestamp":"2024-06-01T18:07:01.228932Z"}]}
{"channel":"book","type":"update","data":[{"symbol":"LINK/USD","bids":[],"asks":[{"price":18.54341,"qty":40.00000000}],"checksum":1574784808,"timestamp":"2024-06-01T18:07:01.233776Z"}]}
{"channel":"book","type":"update","data":[{"symbol":"LINK/USD","bids":[],"asks":[{"price":18.54381,"qty":0.00000000},{"price":18.54989,"qty":40.00000000}],"checksum":2928031536,"timestamp":"2024-06-01T18:07:01.252646Z"}]}
{"channel":"book","type":"update","data":[{"symbol":"LINK/USD","bids":[],"asks":[{"price":18.54339,"qty":31.87500000}],"checksum":660653042,"timestamp":"2024-06-01T18:07:01.328821Z"}]}
{"channel":"book","type":"update","data":[{"symbol":"LINK/USD","bids":[{"price":18.53971,"qty":31.87500000}],"asks":[],"checksum":3658182445,"timestamp":"2024-06-01T18:07:01.332221Z"}]}
{"channel":"book","type":"update","data":[{"symbol":"LINK/USD","bids":[],"asks":[{"price":18.54337,"qty":40.00000000}],"checksum":2190836204,"timestamp":"2024-06-01T18:07:01.334781Z"}]}
{"channel":"book","type":"update","data":[{"symbol":"LINK/USD","bids":[{"price":18.53989,"qty":31.87500000}],"asks":[],"checksum":2347392348,"timestamp":"2024-06-01T18:07:01.335021Z"}]}
{"channel":"book","type":"update","data":[{"symbol":"LINK/USD","bids":[],"asks":[{"price":18.54332,"qty":31.87500000}],"checksum":2436576533,"timestamp":"2024-06-01T18:07:01.338101Z"}]}
{"channel":"book","type":"update","data":[{"symbol":"LINK/USD","bids":[{"price":18.53989,"qty":0.00000000},{"price":18.53578,"qty":269.68105392}],"asks":[],"checksum":2375002544,"timestamp":"2024-06-01T18:07:01.338390Z"}]}
{"channel":"book","type":"update","data":[{"symbol":"LINK/USD","bids":[{"price":18.53991,"qty":31.87500000}],"asks":[],"checksum":1442694456,"timestamp":"2024-06-01T18:07:01.341637Z"}]}
{"channel":"book","type":"update","data":[{"symbol":"LINK/USD","bids":[{"price":18.53991,"qty":0.00000000},{"price":18.53578,"qty":269.68105392}],"asks":[],"checksum":2375002544,"timestamp":"2024-06-01T18:07:01.345692Z"}]}
{"channel":"book","type":"update","data":[{"symbol":"LINK/USD","bids":[{"price":18.53993,"qty":31.87500000}],"asks":[],"checksum":184618250,"timestamp":"2024-06-01T18:07:01.348921Z"}]}
{"channel":"book","type":"update","data":[{"symbol":"LINK/USD","bids":[{"price":18.53993,"qty":0.00000000},{"price":18.53578,"qty":269.68105392}],"asks":[],"checksum":2375002544,"timestamp":"2024-06-01T18:07:01.352547Z"}]}
{"channel":"book","type":"update","data":[{"symbol":"LINK/USD","bids":[{"price":18.53996,"qty":31.87500000}],"asks":[],"checksum":2575759735,"timestamp":"2024-06-01T18:07:01.355351Z"}]}
{"channel":"book","type":"update","data":[{"symbol":"LINK/USD","bids":[{"price":18.53996,"qty":0.00000000},{"price":18.53578,"qty":269.68105392}],"asks":[],"checksum":2375002544,"timestamp":"2024-06-01T18:07:01.359163Z"}]}
{"channel":"book","type":"update","data":[{"symbol":"LINK/USD","bids":[{"price":18.54002,"qty":31.87500000}],"asks":[],"checksum":4069406773,"timestamp":"2024-06-01T18:07:01.362151Z"}]}
{"channel":"book","type":"update","data":[{"symbol":"LINK/USD","bids":[{"price":18.54002,"qty":0.00000000},{"price":18.53578,"qty":269.68105392}],"asks":[],"checksum":2375002544,"timestamp":"2024-06-01T18:07:01.365797Z"}]}
{"channel":"book","type":"update","data":[{"symbol":"LINK/USD","bids":[],"asks":[{"price":18.54337,"qty":0.00000000},{"price":18.54883,"qty":121.30145927}],"checksum":1346378920,"timestamp":"2024-06-01T18:07:01.366521Z"}]}
{"channel":"book","type":"update","data":[{"symbol":"LINK/USD","bids":[],"asks":[{"price":18.54332,"qty":0.00000000},{"price":18.54936,"qty":2.23393540}],"checksum":3658182445,"timestamp":"2024-06-01T18:07:01.367584Z"}]}
{"channel":"book","type":"update","data":[{"symbol":"LINK/USD","bids":[{"price":18.53971,"qty":63.75000000}],"asks":[],"checksum":660653042,"timestamp":"2024-06-01T18:07:01.376807Z"}]}
{"channel":"book","type":"update","data":[{"symbol":"LINK/USD","bids":[],"asks":[{"price":18.54339,"qty":0.00000000},{"price":18.54989,"qty":40.00000000}],"checksum":2928031536,"timestamp":"2024-06-01T18:07:01.389462Z"}]}
{"channel":"book","type":"update","data":[{"symbol":"LINK/USD","bids":[],"asks":[{"price":18.54336,"qty":31.87500000}],"checksum":3723601721,"timestamp":"2024-06-01T18:07:01.547844Z"}]}
{"channel":"book","type":"update","data":[{"symbol":"LINK/USD","bids":[{"price":18.53971,"qty":31.87500000}],"asks":[],"checksum":546966502,"timestamp":"2024-06-01T18:07:01.550998Z"}]}
{"channel":"book","type":"update","data":[{"symbol":"LINK/USD","bids":[{"price":18.53983,"qty":31.87500000}],"asks":[],"checksum":493865924,"timestamp":"2024-06-01T18:07:01.553815Z"}]}
{"channel":"book","type":"update","data":[{"symbol":"LINK/USD","bids":[{"price":18.53983,"qty":0.00000000},{"price":18.53578,"qty":269.68105392}],"asks":[],"checksum":546966502,"timestamp":"2024-06-01T18:07:01.557352Z"}]}
{"channel":"book","type":"update","data":[{"symbol":"LINK/USD","bids":[{"price":18.53971,"qty":63.75000000}],"asks":[],"checksum":3723601721,"timestamp":"2024-06-01T18:07:01.565220Z"}]}
{"channel":"book","type":"update","data":[{"symbol":"LINK/USD","bids":[],"asks":[{"price":18.54336,"qty":0.00000000},{"price":18.54989,"qty":40.00000000}],"checksum":2928031536,"timestamp":"2024-06-01T18:07:01.629654Z"}]}
{"channel":"book","type":"update","data":[{"symbol":"LINK/USD","bids":[{"price":18.53967,"qty":0.00000000},{"price":18.53551,"qty":63.75000000},{"price":18.53972,"qty":1.38667866}],"asks":[],"checksum":3800226780,"timestamp":"2024-06-01T18:07:01.664298Z"}]}
{"channel":"book","type":"update","data":[{"symbol":"LINK/USD","bids":[],"asks":[{"price":18.54335,"qty":31.87500000}],"checksum":3463097175,"timestamp":"2024-06-01T18:07:01.691297Z"}]}
{"channel":"book","type":"update","data":[{"symbol":"LINK/USD","bids":[{"price":18.53971,"qty":31.87500000}],"asks":[],"checksum":2121339477,"timestamp":"2024-06-01T18:07:01.694742Z"}]}
{"channel":"book","type":"update","data":[{"symbol":"LINK/USD","bids":[{"price":18.53984,"qty":31.87500000}],"asks":[],"checksum":292544987,"timestamp":"2024-06-01T18:07:01.697649Z"}]}
{"channel":"book","type":"update","data":[{"symbol":"LINK/USD","bids":[{"price":18.53984,"qty":0.00000000},{"price":18.53578,"qty":269.68105392}],"asks":[],"checksum":2121339477,"timestamp":"2024-06-01T18:07:01.701604Z"}]}
{"channel":"book","type":"update","data":[{"symbol":"LINK/USD","bids":[{"price":18.54004,"qty":31.87500000}],"asks":[],"checksum":2748999257,"timestamp":"2024-06-01T18:07:01.704225Z"}]}
{"channel":"book","type":"update","data":[{"symbol":"LINK/USD","bids":[],"asks":[{"price":18.54335,"qty":0.00000000},{"price":18.54989,"qty":40.00000000}],"checksum":2452907751,"timestamp":"2024-06-01T18:07:01.704764Z"}]}
{"channel":"book","type":"update","data":[{"symbol":"LINK/USD","bids":[{"price":18.54004,"qty":0.00000000},{"price":18.53578,"qty":269.68105392}],"asks":[],"checksum":1385784030,"timestamp":"2024-06-01T18:07:01.707648Z"}]}
{"channel":"book","type":"update","data":[{"symbol":"LINK/USD","bids":[],"asks":[{"price":18.54336,"qty":31.87500000}],"checksum":569307863,"timestamp":"2024-06-01T18:07:01.710216Z"}]}
{"channel":"book","type":"update","data":[{"symbol":"LINK/USD","bids":[{"price":18.53987,"qty":31.87500000}],"asks":[],"checksum":4203071433,"timestamp":"2024-06-01T18:07:01.719445Z"}]}
{"channel":"book","type":"update","data":[{"symbol":"LINK/USD","bids":[{"price":18.53987,"qty":0.00000000},{"price":18.53578,"qty":269.68105392}],"asks":[],"checksum":569307863,"timestamp":"2024-06-01T18:07:01.722585Z"}]}
{"channel":"book","type":"update","data":[{"symbol":"LINK/USD","bids":[{"price":18.53984,"qty":31.87500000}],"asks":[],"checksum":2332519394,"timestamp":"2024-06-01T18:07:01.730110Z"}]}
{"channel":"book","type":"update","data":[{"symbol":"LINK/USD","bids":[{"price":18.53984,"qty":0.00000000},{"price":18.53578,"qty":269.68105392}],"asks":[],"checksum":569307863,"timestamp":"2024-06-01T18:07:01.733595Z"}]}
{"channel":"book","type":"update","data":[{"symbol":"LINK/USD","bids":[{"price":18.53981,"qty":31.87500000}],"asks":[],"checksum":427859871,"timestamp":"2024-06-01T18:07:01.743362Z"}]}
{"channel":"book","type":"update","data":[{"symbol":"LINK/USD","bids":[{"price":18.53981,"qty":0.00000000},{"price":18.53578,"qty":269.68105392}],"asks":[],"checksum":569307863,"timestamp":"2024-06-01T18:07:01.746917Z"}]}
{"channel":"book","type":"update","data":[{"symbol":"LINK/USD","bids":[],"asks":[{"price":18.54336,"qty":0.00000000},{"price":18.54989,"qty":40.00000000}],"checksum":1385784030,"timestamp":"2024-06-01T18:07:01.749931Z"}]}
{"channel":"book","type":"update","data":[{"symbol":"LINK/USD","bids":[{"price":18.54028,"qty":31.87500000}],"asks":[],"checksum":1204190530,"timestamp":"2024-06-01T18:07:01.750005Z"}]}
{"channel":"book","type":"update","data":[{"symbol":"LINK/USD","bids":[{"price":18.54041,"qty":31.87500000}],"asks":[],"checksum":136866528,"timestamp":"2024-06-01T18:07:01.750271Z"}]}
{"channel":"book","type":"update","data":[{"symbol":"LINK/USD","bids":[{"price":18.54028,"qty":0.00000000},{"price":18.53700,"qty":186.96555600}],"asks":[],"checksum":1255263819,"timestamp":"2024-06-01T18:07:01.752632Z"}]}
{"channel":"book","type":"update","data":[{"symbol":"LINK/USD","bids":[{"price":18.54041,"qty":0.00000000},{"price":18.53578,"qty":269.68105392}],"asks":[],"checksum":1385784030,"timestamp":"2024-06-01T18:07:01.754107Z"}]}
{"channel":"book","type":"update","data":[{"symbol":"LINK/USD","bids":[{"price":18.53972,"qty":33.26167866}],"asks":[],"checksum":816083537,"timestamp":"2024-06-01T18:07:01.758255Z"}]}
{"channel":"book","type":"update","data":[{"symbol":"LINK/USD","bids":[],"asks":[{"price":18.54337,"qty":31.87500000}],"checksum":1213426113,"timestamp":"2024-06-01T18:07:01.767618Z"}]}
{"channel":"book","type":"update","data":[{"symbol":"LINK/USD","bids":[{"price":18.53972,"qty":1.38667866}],"asks":[],"checksum":2722844822,"timestamp":"2024-06-01T18:07:01.771533Z"}]}
{"channel":"book","type":"update","data":[{"symbol":"LINK/USD","bids":[{"price":18.53989,"qty":31.87500000}],"asks":[],"checksum":3475324673,"timestamp":"2024-06-01T18:07:01.774564Z"}]}
{"channel":"book","type":"update","data":[{"symbol":"LINK/USD","bids":[{"price":18.53989,"qty":0.00000000},{"price":18.53578,"qty":269.68105392}],"asks":[],"checksum":2722844822,"timestamp":"2024-06-01T18:07:01.778368Z"}]}
{"channel":"book","type":"update","data":[{"symbol":"LINK/USD","bids":[{"price":18.53990,"qty":31.87500000}],"asks":[],"checksum":614312757,"timestamp":"2024-06-01T18:07:01.781188Z"}]}
{"channel":"book","type":"update","data":[{"symbol":"LINK/USD","bids":[{"price":18.53990,"qty":0.00000000},{"price":18.53578,"qty":269.68105392}],"asks":[],"checksum":2722844822,"timestamp":"2024-06-01T18:07:01.784796Z"}]}
{"channel":"book","type":"update","data":[{"symbol":"LINK/USD","bids":[{"price":18.53984,"qty":31.87500000}],"asks":[],"checksum":4246793717,"timestamp":"2024-06-01T18:07:01.803024Z"}]}
{"channel":"book","type":"update","data":[{"symbol":"LINK/USD","bids":[{"price":18.53984,"qty":0.00000000},{"price":18.53578,"qty":269.68105392}],"asks":[],"checksum":2722844822,"timestamp":"2024-06-01T18:07:01.805878Z"}]}
{"channel":"book","type":"update","data":[{"symbol":"LINK/USD","bids":[{"price":18.53976,"qty":31.87500000}],"asks":[],"checksum":3518479192,"timestamp":"2024-06-01T18:07:01.817954Z"}]}
{"channel":"book","type":"update","data":[{"symbol":"LINK/USD","bids":[{"price":18.53976,"qty":0.00000000},{"price":18.53578,"qty":269.68105392}],"asks":[],"checksum":2722844822,"timestamp":"2024-06-01T18:07:01.821412Z"}]}
{"channel":"book","type":"update","data":[{"symbol":"LINK/USD","bids":[{"price":18.53972,"qty":33.26167866}],"asks":[],"checksum":1213426113,"timestamp":"2024-06-01T18:07:01.828376Z"}]}
{"channel":"book","type":"update","data":[{"symbol":"LINK/USD","bids":[{"price":18.53971,"qty":0.00000000},{"price":18.53551,"qty":63.75000000}],"asks":[],"checksum":3514566288,"timestamp":"2024-06-01T18:07:01.829895Z"}]}
{"channel":"book","type":"update","data":[{"symbol":"LINK/USD","bids":[],"asks":[{"price":18.54337,"qty":0.00000000},{"price":18.54989,"qty":40.00000000}],"checksum":2844466432,"timestamp":"2024-06-01T18:07:01.833395Z"}]}
{"channel":"book","type":"update","data":[{"symbol":"LINK/USD","bids":[{"price":18.54031,"qty":31.87500000}],"asks":[],"checksum":3877053495,"timestamp":"2024-06-01T18:07:01.834166Z"}]}
{"channel":"book","type":"update","data":[{"symbol":"LINK/USD","bids":[{"price":18.54031,"qty":0.00000000},{"price":18.53551,"qty":63.75000000}],"asks":[],"checksum":2844466432,"timestamp":"2024-06-01T18:07:01.837735Z"}]}
{"channel":"book","type":"update","data":[{"symbol":"LINK/USD","bids":[{"price":18.53972,"qty":1.38667866}],"asks":[],"checksum":3417705871,"timestamp":"2024-06-01T18:07:01.840923Z"}]}
{"channel":"book","type":"update","data":[{"symbol":"LINK/USD","bids":[],"asks":[{"price":18.54337,"qty":31.87500000}],"checksum":996425671,"timestamp":"2024-06-01T18:07:01.841442Z"}]}
{"channel":"book","type":"update","data":[{"symbol":"LINK/USD","bids":[{"price":18.53972,"qty":0.00000000},{"price":18.53540,"qty":433.54710000},{"price":18.53969,"qty":1.38668095}],"asks":[],"checksum":1945990907,"timestamp":"2024-06-01T18:07:01.844341Z"}]}
{"channel":"book","type":"update","data":[{"symbol":"LINK/USD","bids":[{"price":18.53989,"qty":31.87500000}],"asks":[],"checksum":541314028,"timestamp":"2024-06-01T18:07:01.844556Z"}]}
{"channel":"book","type":"update","data":[{"symbol":"LINK/USD","bids":[{"price":18.53989,"qty":0.00000000},{"price":18.53551,"qty":63.75000000}],"asks":[],"checksum":1945990907,"timestamp":"2024-06-01T18:07:01.847944Z"}]}
{"channel":"book","type":"update","data":[{"symbol":"LINK/USD","bids":[{"price":18.53984,"qty":31.87500000}],"asks":[],"checksum":2594306107,"timestamp":"2024-06-01T18:07:01.857785Z"}]}
{"channel":"book","type":"update","data":[{"symbol":"LINK/USD","bids":[{"price":18.53984,"qty":0.00000000},{"price":18.53551,"qty":63.75000000}],"asks":[],"checksum":1945990907,"timestamp":"2024-06-01T18:07:01.861770Z"}]}
{"channel":"book","type":"update","data":[{"symbol":"LINK/USD","bids":[],"asks":[{"price":18.54563,"qty":8.06136702}],"checksum":388299281,"timestamp":"2024-06-01T18:07:01.862209Z"}]}
{"channel":"book","type":"update","data":[{"symbol":"LINK/USD","bids":[{"price":18.53993,"qty":31.87500000}],"asks":[],"checksum":3372773579,"timestamp":"2024-06-01T18:07:01.864557Z"}]}
{"channel":"book","type":"update","data":[{"symbol":"LINK/USD","bids":[{"price":18.53993,"qty":0.00000000},{"price":18.53551,"qty":63.75000000}],"asks":[],"checksum":388299281,"timestamp":"2024-06-01T18:07:01.867503Z"}]}
{"channel":"book","type":"update","data":[{"symbol":"LINK/USD","bids":[{"price":18.53986,"qty":31.87500000}],"asks":[],"checksum":921819545,"timestamp":"2024-06-01T18:07:01.877475Z"}]}
{"channel":"book","type":"update","data":[{"symbol":"LINK/USD","bids":[{"price":18.53986,"qty":0.00000000},{"price":18.53551,"qty":63.75000000}],"asks":[],"checksum":388299281,"timestamp":"2024-06-01T18:07:01.881496Z"}]}
{"channel":"book","type":"update","data":[{"symbol":"LINK/USD","bids":[{"price":18.53973,"qty":31.87500000}],"asks":[],"checksum":2014688935,"timestamp":"2024-06-01T18:07:01.887975Z"}]}
{"channel":"book","type":"update","data":[{"symbol":"LINK/USD","bids":[{"price":18.53973,"qty":0.00000000},{"price":18.53551,"qty":63.75000000}],"asks":[],"checksum":388299281,"timestamp":"2024-06-01T18:07:01.891902Z"}]}
{"channel":"book","type":"update","data":[{"symbol":"LINK/USD","bids":[{"price":18.53980,"qty":31.87500000}],"asks":[],"checksum":3021613056,"timestamp":"2024-06-01T18:07:01.894579Z"}]}
{"channel":"book","type":"update","data":[{"symbol":"LINK/USD","bids":[{"price":18.53980,"qty":0.00000000},{"price":18.53551,"qty":63.75000000}],"asks":[],"checksum":388299281,"timestamp":"2024-06-01T18:07:01.898011Z"}]}
{"channel":"book","type":"update","data":[{"symbol":"LINK/USD","bids":[{"price":18.53987,"qty":31.87500000}],"asks":[],"checksum":1387597629,"timestamp":"2024-06-01T18:07:01.901206Z"}]}
{"channel":"book","type":"update","data":[{"symbol":"LINK/USD","bids":[{"price":18.53987,"qty":0.00000000},{"price":18.53551,"qty":63.75000000}],"asks":[],"checksum":388299281,"timestamp":"2024-06-01T18:07:01.905335Z"}]}
{"channel":"book","type":"update","data":[{"symbol":"LINK/USD","bids":[{"price":18.53978,"qty":31.87500000}],"asks":[],"checksum":1075606761,"timestamp":"2024-06-01T18:07:01.912818Z"}]}
{"channel":"book","type":"update","data":[{"symbol":"LINK/USD","bids":[{"price":18.53978,"qty":0.00000000},{"price":18.53551,"qty":63.75000000}],"asks":[],"checksum":388299281,"timestamp":"2024-06-01T18:07:01.916157Z"}]}
{"channel":"book","type":"update","data":[{"symbol":"LINK/USD","bids":[{"price":18.53983,"qty":31.87500000}],"asks":[],"checksum":416764908,"timestamp":"2024-06-01T18:07:01.919543Z"}]}
{"channel":"book","type":"update","data":[{"symbol":"LINK/USD","bids":[{"price":18.53983,"qty":0.00000000},{"price":18.53551,"qty":63.75000000}],"asks":[],"checksum":388299281,"timestamp":"2024-06-01T18:07:01.922462Z"}]}
{"channel":"book","type":"update","data":[{"symbol":"LINK/USD","bids":[{"price":18.53970,"qty":31.87500000}],"asks":[],"checksum":3570978123,"timestamp":"2024-06-01T18:07:01.929060Z"}]}
{"channel":"book","type":"update","data":[{"symbol":"LINK/USD","bids":[{"price":18.53970,"qty":0.00000000},{"price":18.53551,"qty":63.75000000}],"asks":[],"checksum":388299281,"timestamp":"2024-06-01T18:07:01.932388Z"}]}
{"channel":"book","type":"update","data":[{"symbol":"LINK/USD","bids":[{"price":18.53984,"qty":31.87500000}],"asks":[],"checksum":4269307089,"timestamp":"2024-06-01T18:07:01.938187Z"}]}
{"channel":"book","type":"update","data":[{"symbol":"LINK/USD","bids":[{"price":18.53984,"qty":0.00000000},{"price":18.53551,"qty":63.75000000}],"asks":[],"checksum":388299281,"timestamp":"2024-06-01T18:07:01.941539Z"}]}
{"channel":"book","type":"update","data":[{"symbol":"LINK/USD","bids":[{"price":18.53976,"qty":31.87500000}],"asks":[],"checksum":1446198482,"timestamp":"2024-06-01T18:07:01.948041Z"}]}
{"channel":"book","type":"update","data":[{"symbol":"LINK/USD","bids":[{"price":18.53976,"qty":0.00000000},{"price":18.53551,"qty":63.75000000}],"asks":[],"checksum":388299281,"timestamp":"2024-06-01T18:07:01.951379Z"}]}
{"channel":"book","type":"update","data":[{"symbol":"LINK/USD","bids":[{"price":18.53976,"qty":31.87500000}],"asks":[],"checksum":1446198482,"timestamp":"2024-06-01T18:07:01.954181Z"}]}
{"channel":"book","type":"update","data":[{"symbol":"LINK/USD","bids":[{"price":18.53976,"qty":0.00000000},{"price":18.53551,"qty":63.75000000}],"asks":[],"checksum":388299281,"timestamp":"2024-06-01T18:07:01.957798Z"}]}
{"channel":"book","type":"update","data":[{"symbol":"LINK/USD","bids":[{"price":18.53979,"qty":31.87500000}],"asks":[],"checksum":609788493,"timestamp":"2024-06-01T18:07:01.961289Z"}]}
{"channel":"book","type":"update","data":[{"symbol":"LINK/USD","bids":[{"price":18.53979,"qty":0.00000000},{"price":18.53551,"qty":63.75000000}],"asks":[],"checksum":388299281,"timestamp":"2024-06-01T18:07:01.965252Z"}]}
{"channel":"book","type":"update","data":[{"symbol":"LINK/USD","bids":[{"price":18.53983,"qty":31.87500000}],"asks":[],"checksum":416764908,"timestamp":"2024-06-01T18:07:01.968430Z"}]}
{"channel":"book","type":"update","data":[{"symbol":"LINK/USD","bids":[{"price":18.53983,"qty":0.00000000},{"price":18.53551,"qty":63.75000000}],"asks":[],"checksum":388299281,"timestamp":"2024-06-01T18:07:01.972357Z"}]}
{"channel":"book","type":"update","data":[{"symbol":"LINK/USD","bids":[{"price":18.53976,"qty":31.87500000}],"asks":[],"checksum":1446198482,"timestamp":"2024-06-01T18:07:01.977548Z"}]}
{"channel":"book","type":"update","data":[{"symbol":"LINK/USD","bids":[{"price":18.53976,"qty":0.00000000},{"price":18.53551,"qty":63.75000000}],"asks":[],"checksum":388299281,"timestamp":"2024-06-01T18:07:01.980795Z"}]}
{"channel":"book","type":"update","data":[{"symbol":"LINK/USD","bids":[{"price":18.53976,"qty":31.87500000}],"asks":[],"checksum":1446198482,"timestamp":"2024-06-01T18:07:01.984023Z"}]}
{"channel":"book","type":"update","data":[{"symbol":"LINK/USD","bids":[{"price":18.53976,"qty":0.00000000},{"price":18.53551,"qty":63.75000000}],"asks":[],"checksum":388299281,"timestamp":"2024-06-01T18:07:01.987225Z"}]}
{"channel":"book","type":"update","data":[{"symbol":"LINK/USD","bids":[{"price":18.53979,"qty":31.87500000}],"asks":[],"checksum":609788493,"timestamp":"2024-06-01T18:07:01.990394Z"}]}
{"channel":"book","type":"update","data":[{"symbol":"LINK/USD","bids":[{"price":18.53979,"qty":0.00000000},{"price":18.53551,"qty":63.75000000}],"asks":[],"checksum":388299281,"timestamp":"2024-06-01T18:07:01.993802Z"}]}
{"channel":"book","type":"update","data":[{"symbol":"LINK/USD","bids":[{"price":18.53994,"qty":31.87500000}],"asks":[],"checksum":799496182,"timestamp":"2024-06-01T18:07:02.002240Z"}]}
{"channel":"book","type":"update","data":[{"symbol":"LINK/USD","bids":[{"price":18.53994,"qty":0.00000000},{"price":18.53551,"qty":63.75000000}],"asks":[],"checksum":388299281,"timestamp":"2024-06-01T18:07:02.006285Z"}]}
{"channel":"book","type":"update","data":[{"symbol":"LINK/USD","bids":[{"price":18.53982,"qty":31.87500000}],"asks":[],"checksum":2090042696,"timestamp":"2024-06-01T18:07:02.029296Z"}]}
{"channel":"book","type":"update","data":[{"symbol":"LINK/USD","bids":[{"price":18.53982,"qty":0.00000000},{"price":18.53551,"qty":63.75000000}],"asks":[],"checksum":388299281,"timestamp":"2024-06-01T18:07:02.033335Z"}]}
{"channel":"book","type":"update","data":[{"symbol":"LINK/USD","bids":[{"price":18.53995,"qty":31.87500000}],"asks":[],"checksum":1273200978,"timestamp":"2024-06-01T18:07:02.036855Z"}]}
{"channel":"book","type":"update","data":[{"symbol":"LINK/USD","bids":[{"price":18.53995,"qty":0.00000000},{"price":18.53551,"qty":63.75000000}],"asks":[],"checksum":388299281,"timestamp":"2024-06-01T18:07:02.040608Z"}]}
{"channel":"book","type":"update","data":[{"symbol":"LINK/USD","bids":[{"price":18.53997,"qty":31.87500000}],"asks":[],"checksum":2204773402,"timestamp":"2024-06-01T18:07:02.043301Z"}]}
{"channel":"book","type":"update","data":[{"symbol":"LINK/USD","bids":[{"price":18.53997,"qty":0.00000000},{"price":18.53551,"qty":63.75000000}],"asks":[],"checksum":388299281,"timestamp":"2024-06-01T18:07:02.047341Z"}]}
{"channel":"book","type":"update","data":[{"symbol":"LINK/USD","bids":[{"price":18.53971,"qty":31.87500000}],"asks":[],"checksum":2963020783,"timestamp":"2024-06-01T18:07:02.052542Z"}]}
{"channel":"book","type":"update","data":[{"symbol":"LINK/USD","bids":[{"price":18.53971,"qty":0.00000000},{"price":18.53551,"qty":63.75000000}],"asks":[],"checksum":388299281,"timestamp":"2024-06-01T18:07:02.056073Z"}]}
{"channel":"book","type":"update","data":[{"symbol":"LINK/USD","bids":[{"price":18.53976,"qty":31.87500000}],"asks":[],"checksum":1446198482,"timestamp":"2024-06-01T18:07:02.058835Z"}]}
{"channel":"book","type":"update","data":[{"symbol":"LINK/USD","bids":[{"price":18.53976,"qty":0.00000000},{"price":18.53551,"qty":63.75000000}],"asks":[],"checksum":388299281,"timestamp":"2024-06-01T18:07:02.062127Z"}]}
{"channel":"book","type":"update","data":[{"symbol":"LINK/USD","bids":[{"price":18.53982,"qty":31.87500000}],"asks":[],"checksum":2090042696,"timestamp":"2024-06-01T18:07:02.065288Z"}]}
{"channel":"book","type":"update","data":[{"symbol":"LINK/USD","bids":[{"price":18.53982,"qty":0.00000000},{"price":18.53551,"qty":63.75000000}],"asks":[],"checksum":388299281,"timestamp":"2024-06-01T18:07:02.068798Z"}]}
{"channel":"book","type":"update","data":[{"symbol":"LINK/USD","bids":[{"price":18.53983,"qty":31.87500000}],"asks":[],"checksum":416764908,"timestamp":"2024-06-01T18:07:02.073277Z"}]}
{"channel":"book","type":"update","data":[{"symbol":"LINK/USD","bids":[{"price":18.53983,"qty":0.00000000},{"price":18.53551,"qty":63.75000000}],"asks":[],"checksum":388299281,"timestamp":"2024-06-01T18:07:02.076753Z"}]}
{"channel":"book","type":"update","data":[{"symbol":"LINK/USD","bids":[{"price":18.53988,"qty":31.87500000}],"asks":[],"checksum":551457186,"timestamp":"2024-06-01T18:07:02.080118Z"}]}
{"channel":"book","type":"update","data":[{"symbol":"LINK/USD","bids":[{"price":18.53988,"qty":0.00000000},{"price":18.53551,"qty":63.75000000}],"asks":[],"checksum":388299281,"timestamp":"2024-06-01T18:07:02.084160Z"}]}
{"channel":"book","type":"update","data":[{"symbol":"LINK/USD","bids":[{"price":18.53975,"qty":31.87500000}],"asks":[],"checksum":4210968382,"timestamp":"2024-06-01T18:07:02.090491Z"}]}
{"channel":"book","type":"update","data":[{"symbol":"LINK/USD","bids":[{"price":18.53975,"qty":0.00000000},{"price":18.53551,"qty":63.75000000}],"asks":[],"checksum":388299281,"timestamp":"2024-06-01T18:07:02.094992Z"}]}
{"channel":"book","type":"update","data":[{"symbol":"LINK/USD","bids":[{"price":18.53970,"qty":243.48672997}],"asks":[],"checksum":3249205313,"timestamp":"2024-06-01T18:07:02.095364Z"}]}
{"channel":"book","type":"update","data":[{"symbol":"LINK/USD","bids":[{"price":18.53993,"qty":31.87500000}],"asks":[],"checksum":4003955057,"timestamp":"2024-06-01T18:07:02.098093Z"}]}
{"channel":"book","type":"update","data":[{"symbol":"LINK/USD","bids":[],"asks":[{"price":18.54337,"qty":0.00000000},{"price":18.54936,"qty":2.23393540}],"checksum":20754605,"timestamp":"2024-06-01T18:07:02.099807Z"}]}
{"channel":"book","type":"update","data":[{"symbol":"LINK/USD","bids":[{"price":18.54012,"qty":31.87500000}],"asks":[],"checksum":3564211562,"timestamp":"2024-06-01T18:07:02.099946Z"}]}
{"channel":"book","type":"update","data":[{"symbol":"LINK/USD","bids":[{"price":18.54012,"qty":0.00000000},{"price":18.53700,"qty":186.96555600}],"asks":[],"checksum":20754605,"timestamp":"2024-06-01T18:07:02.120262Z"}]}
{"channel":"book","type":"update","data":[{"symbol":"LINK/USD","bids":[{"price":18.53993,"qty":0.00000000},{"price":18.53578,"qty":269.68105392}],"asks":[],"checksum":1310782863,"timestamp":"2024-06-01T18:07:02.123680Z"}]}
{"channel":"book","type":"update","data":[{"symbol":"LINK/USD","bids":[{"price":18.54000,"qty":31.87500000}],"asks":[],"checksum":2133508077,"timestamp":"2024-06-01T18:07:02.126948Z"}]}
{"channel":"book","type":"update","data":[{"symbol":"LINK/USD","bids":[{"price":18.53970,"qty":0.00000000},{"price":18.53578,"qty":269.68105392}],"asks":[],"checksum":1485131351,"timestamp":"2024-06-01T18:07:02.127329Z"}]}
{"channel":"book","type":"update","data":[{"symbol":"LINK/USD","bids":[{"price":18.53992,"qty":31.87500000}],"asks":[],"checksum":3916032735,"timestamp":"2024-06-01T18:07:02.127546Z"}]}
{"channel":"book","type":"update","data":[{"symbol":"LINK/USD","bids":[{"price":18.54000,"qty":0.00000000},{"price":18.53578,"qty":269.68105392}],"asks":[],"checksum":1121425331,"timestamp":"2024-06-01T18:07:02.130541Z"}]}
{"channel":"book","type":"update","data":[{"symbol":"LINK/USD","bids":[{"price":18.53992,"qty":0.00000000},{"price":18.53551,"qty":63.75000000}],"asks":[],"checksum":4173319117,"timestamp":"2024-06-01T18:07:02.130555Z"}]}
{"channel":"book","type":"update","data":[{"symbol":"LINK/USD","bids":[{"price":18.54000,"qty":31.87500000}],"asks":[],"checksum":1485131351,"timestamp":"2024-06-01T18:07:02.130910Z"}]}
{"channel":"book","type":"update","data":[{"symbol":"LINK/USD","bids":[{"price":18.54000,"qty":63.75000000}],"asks":[],"checksum":2783896200,"timestamp":"2024-06-01T18:07:02.133757Z"}]}
{"channel":"book","type":"update","data":[{"symbol":"LINK/USD","bids":[{"price":18.54000,"qty":31.87500000}],"asks":[],"checksum":1485131351,"timestamp":"2024-06-01T18:07:02.270183Z"}]}
{"channel":"book","type":"update","data":[{"symbol":"LINK/USD","bids":[],"asks":[{"price":18.54340,"qty":31.87500000}],"checksum":2366518194,"timestamp":"2024-06-01T18:07:02.270807Z"}]}
{"channel":"book","type":"update","data":[{"symbol":"LINK/USD","bids":[],"asks":[{"price":18.54340,"qty":0.00000000},{"price":18.54936,"qty":2.23393540}],"checksum":1485131351,"timestamp":"2024-06-01T18:07:02.273708Z"}]}
{"channel":"book","type":"update","data":[{"symbol":"LINK/USD","bids":[{"price":18.54021,"qty":31.87500000}],"asks":[],"checksum":2570805448,"timestamp":"2024-06-01T18:07:02.273907Z"}]}
{"channel":"book","type":"update","data":[{"symbol":"LINK/USD","bids":[{"price":18.54000,"qty":0.00000000},{"price":18.53578,"qty":269.68105392}],"asks":[],"checksum":1141823740,"timestamp":"2024-06-01T18:07:02.274387Z"}]}
{"channel":"book","type":"update","data":[{"symbol":"LINK/USD","bids":[{"price":18.54021,"qty":63.75000000}],"asks":[],"checksum":3110433827,"timestamp":"2024-06-01T18:07:02.278354Z"}]}
{"channel":"book","type":"update","data":[{"symbol":"LINK/USD","bids":[{"price":18.53969,"qty":0.00000000},{"price":18.53551,"qty":63.75000000},{"price":18.54022,"qty":1.38664137}],"asks":[],"checksum":4183034388,"timestamp":"2024-06-01T18:07:02.279631Z"}]}
{"channel":"book","type":"update","data":[{"symbol":"LINK/USD","bids":[{"price":18.54021,"qty":31.87500000}],"asks":[],"checksum":1229959958,"timestamp":"2024-06-01T18:07:02.283621Z"}]}
{"channel":"book","type":"update","data":[{"symbol":"LINK/USD","bids":[{"price":18.54042,"qty":31.87500000}],"asks":[],"checksum":1875972664,"timestamp":"2024-06-01T18:07:02.286204Z"}]}
{"channel":"book","type":"update","data":[{"symbol":"LINK/USD","bids":[{"price":18.54042,"qty":0.00000000},{"price":18.53578,"qty":269.68105392}],"asks":[],"checksum":1229959958,"timestamp":"2024-06-01T18:07:02.289790Z"}]}
{"channel":"book","type":"update","data":[{"symbol":"LINK/USD","bids":[{"price":18.54047,"qty":31.87500000}],"asks":[],"checksum":4250330693,"timestamp":"2024-06-01T18:07:02.292869Z"}]}
{"channel":"book","type":"update","data":[{"symbol":"LINK/USD","bids":[{"price":18.54047,"qty":0.00000000},{"price":18.53578,"qty":269.68105392}],"asks":[],"checksum":1229959958,"timestamp":"2024-06-01T18:07:02.296078Z"}]}
{"channel":"book","type":"update","data":[{"symbol":"LINK/USD","bids":[],"asks":[{"price":18.54423,"qty":0.00000000},{"price":18.54989,"qty":40.00000000}],"checksum":717927373,"timestamp":"2024-06-01T18:07:02.296446Z"}]}
{"channel":"book","type":"update","data":[{"symbol":"LINK/USD","bids":[{"price":18.54047,"qty":31.87500000}],"asks":[],"checksum":2117788760,"timestamp":"2024-06-01T18:07:02.296988Z"}]}
{"channel":"book","type":"update","data":[{"symbol":"LINK/USD","bids":[{"price":18.54047,"qty":63.75000000}],"asks":[],"checksum":2003779906,"timestamp":"2024-06-01T18:07:02.298707Z"}]}
{"channel":"book","type":"update","data":[{"symbol":"LINK/USD","bids":[],"asks":[{"price":18.54375,"qty":0.00000000},{"price":18.55100,"qty":83.67104051}],"checksum":2091925386,"timestamp":"2024-06-01T18:07:02.299114Z"}]}
{"channel":"book","type":"update","data":[{"symbol":"LINK/USD","bids":[],"asks":[{"price":18.54516,"qty":33.00000000}],"checksum":3996898388,"timestamp":"2024-06-01T18:07:02.299163Z"}]}
{"channel":"book","type":"update","data":[{"symbol":"LINK/USD","bids":[],"asks":[{"price":18.54564,"qty":0.00000000},{"price":18.55100,"qty":83.67104051}],"checksum":3659701825,"timestamp":"2024-06-01T18:07:02.299642Z"}]}
{"channel":"book","type":"update","data":[{"symbol":"LINK/USD","bids":[{"price":18.53701,"qty":0.00000000},{"price":18.53578,"qty":269.68105392}],"asks":[],"checksum":129934781,"timestamp":"2024-06-01T18:07:02.302081Z"}]}
{"channel":"book","type":"update","data":[{"symbol":"LINK/USD","bids":[],"asks":[{"price":18.54563,"qty":0.00000000},{"price":18.55119,"qty":31.87500000}],"checksum":2960896778,"timestamp":"2024-06-01T18:07:02.302517Z"}]}
{"channel":"book","type":"update","data":[{"symbol":"LINK/USD","bids":[],"asks":[{"price":18.54516,"qty":0.00000000},{"price":18.55158,"qty":2.07415715}],"checksum":2527779157,"timestamp":"2024-06-01T18:07:02.305162Z"}]}
{"channel":"book","type":"update","data":[{"symbol":"LINK/USD","bids":[],"asks":[{"price":18.54624,"qty":33.00000000}],"checksum":2962078324,"timestamp":"2024-06-01T18:07:02.305420Z"}]}
{"channel":"book","type":"update","data":[{"symbol":"LINK/USD","bids":[],"asks":[{"price":18.54515,"qty":8.06136702}],"checksum":3262610361,"timestamp":"2024-06-01T18:07:02.305764Z"}]}
{"channel":"book","type":"update","data":[{"symbol":"LINK/USD","bids":[],"asks":[{"price":18.54515,"qty":0.00000000},{"price":18.55119,"qty":31.87500000}],"checksum":2962078324,"timestamp":"2024-06-01T18:07:02.309480Z"}]}
{"channel":"book","type":"update","data":[{"symbol":"LINK/USD","bids":[],"asks":[{"price":18.54527,"qty":31.87500000}],"checksum":3989331581,"timestamp":"2024-06-01T18:07:02.329345Z"}]}
{"channel":"book","type":"update","data":[{"symbol":"LINK/USD","bids":[],"asks":[{"price":18.54624,"qty":0.00000000},{"price":18.55119,"qty":31.87500000}],"checksum":1740088067,"timestamp":"2024-06-01T18:07:02.332119Z"}]}
{"channel":"book","type":"update","data":[{"symbol":"LINK/USD","bids":[],"asks":[{"price":18.54480,"qty":33.00000000}],"checksum":2859966919,"timestamp":"2024-06-01T18:07:02.332323Z"}]}
{"channel":"book","type":"update","data":[{"symbol":"LINK/USD","bids":[],"asks":[{"price":18.54527,"qty":0.00000000},{"price":18.55119,"qty":31.87500000}],"checksum":736583518,"timestamp":"2024-06-01T18:07:02.332403Z"}]}
{"channel":"book","type":"update","data":[{"symbol":"LINK/USD","bids":[],"asks":[{"price":18.54480,"qty":0.00000000},{"price":18.55158,"qty":2.07415715}],"checksum":2527779157,"timestamp":"2024-06-01T18:07:02.335081Z"}]}
{"channel":"book","type":"update","data":[{"symbol":"LINK/USD","bids":[],"asks":[{"price":18.54624,"qty":33.00000000}],"checksum":2962078324,"timestamp":"2024-06-01T18:07:02.335313Z"}]}
{"channel":"book","type":"update","data":[{"symbol":"LINK/USD","bids":[],"asks":[{"price":18.54527,"qty":31.87500000}],"checksum":3989331581,"timestamp":"2024-06-01T18:07:02.342827Z"}]}
{"channel":"book","type":"update","data":[{"symbol":"LINK/USD","bids":[],"asks":[{"price":18.54624,"qty":0.00000000},{"price":18.55119,"qty":31.87500000}],"checksum":1740088067,"timestamp":"2024-06-01T18:07:02.345482Z"}]}
{"channel":"book","type":"update","data":[{"symbol":"LINK/USD","bids":[],"asks":[{"price":18.54480,"qty":33.00000000}],"checksum":2859966919,"timestamp":"2024-06-01T18:07:02.345899Z"}]}
{"channel":"book","type":"update","data":[{"symbol":"LINK/USD","bids":[],"asks":[{"price":18.54417,"qty":6.43107813}],"checksum":186866869,"timestamp":"2024-06-01T18:07:02.474193Z"}]}
{"channel":"book","type":"update","data":[{"symbol":"LINK/USD","bids":[{"price":18.53969,"qty":32.39428719}],"asks":[],"checksum":1056068453,"timestamp":"2024-06-01T18:07:02.477378Z"}]}
{"channel":"book","type":"update","data":[{"symbol":"LINK/USD","bids":[],"asks":[{"price":18.54343,"qty":0.00000000},{"price":18.55100,"qty":83.67104051}],"checksum":666131603,"timestamp":"2024-06-01T18:07:02.570614Z"}]}
{"channel":"book","type":"update","data":[{"symbol":"LINK/USD","bids":[{"price":18.53969,"qty":0.00000000},{"price":18.53578,"qty":269.68105392}],"asks":[],"checksum":1608797587,"timestamp":"2024-06-01T18:07:02.570697Z"}]}
{"channel":"book","type":"update","data":[{"symbol":"LINK/USD","bids":[],"asks":[{"price":18.54341,"qty":0.00000000},{"price":18.55119,"qty":31.87500000}],"checksum":3550702767,"timestamp":"2024-06-01T18:07:02.754721Z"}]}
{"channel":"book","type":"update","data":[{"symbol":"LINK/USD","bids":[{"price":18.53796,"qty":32.39428719}],"asks":[],"checksum":3400135439,"timestamp":"2024-06-01T18:07:02.757961Z"}]}
{"channel":"book","type":"update","data":[{"symbol":"LINK/USD","bids":[],"asks":[{"price":18.54416,"qty":31.84104839}],"checksum":1578886798,"timestamp":"2024-06-01T18:07:02.758077Z"}]}
{"channel":"book","type":"update","data":[{"symbol":"LINK/USD","bids":[{"price":18.54047,"qty":31.87500000}],"asks":[],"checksum":1464746900,"timestamp":"2024-06-01T18:07:02.758100Z"}]}
{"channel":"book","type":"update","data":[{"symbol":"LINK/USD","bids":[],"asks":[{"price":18.54402,"qty":31.87500000}],"checksum":3548713218,"timestamp":"2024-06-01T18:07:02.758254Z"}]}
{"channel":"book","type":"update","data":[{"symbol":"LINK/USD","bids":[],"asks":[{"price":18.54478,"qty":40.00000000}],"checksum":894865177,"timestamp":"2024-06-01T18:07:02.759436Z"}]}
{"channel":"book","type":"update","data":[{"symbol":"LINK/USD","bids":[{"price":18.54054,"qty":31.87500000}],"asks":[],"checksum":4213993847,"timestamp":"2024-06-01T18:07:02.761621Z"}]}
{"channel":"book","type":"update","data":[{"symbol":"LINK/USD","bids":[],"asks":[{"price":18.54480,"qty":0.00000000},{"price":18.54989,"qty":40.00000000}],"checksum":3828155933,"timestamp":"2024-06-01T18:07:02.762083Z"}]}
{"channel":"book","type":"update","data":[{"symbol":"LINK/USD","bids":[],"asks":[{"price":18.54434,"qty":33.00000000}],"checksum":2930893899,"timestamp":"2024-06-01T18:07:02.762170Z"}]}
{"channel":"book","type":"update","data":[{"symbol":"LINK/USD","bids":[],"asks":[{"price":18.54417,"qty":0.00000000},{"price":18.54989,"qty":40.00000000}],"checksum":2136958463,"timestamp":"2024-06-01T18:07:02.763332Z"}]}
{"channel":"book","type":"update","data":[{"symbol":"LINK/USD","bids":[{"price":18.54054,"qty":0.00000000},{"price":18.53700,"qty":186.96555600}],"asks":[],"checksum":3601987359,"timestamp":"2024-06-01T18:07:02.765212Z"}]}
{"channel":"book","type":"update","data":[{"symbol":"LINK/USD","bids":[{"price":18.54058,"qty":31.87500000}],"asks":[],"checksum":3019500783,"timestamp":"2024-06-01T18:07:02.768471Z"}]}
{"channel":"book","type":"update","data":[{"symbol":"LINK/USD","bids":[{"price":18.54058,"qty":0.00000000},{"price":18.53700,"qty":186.96555600}],"asks":[],"checksum":3601987359,"timestamp":"2024-06-01T18:07:02.771503Z"}]}
{"channel":"book","type":"update","data":[{"symbol":"LINK/USD","bids":[],"asks":[{"price":18.54527,"qty":0.00000000},{"price":18.55100,"qty":83.67104051}],"checksum":3205060195,"timestamp":"2024-06-01T18:07:02.771644Z"}]}
{"channel":"book","type":"update","data":[{"symbol":"LINK/USD","bids":[{"price":18.54022,"qty":0.00000000},{"price":18.53578,"qty":269.68105392},{"price":18.53969,"qty":1.38668105}],"asks":[],"checksum":292749014,"timestamp":"2024-06-01T18:07:02.771769Z"}]}
{"channel":"book","type":"update","data":[{"symbol":"LINK/USD","bids":[{"price":18.54060,"qty":31.87500000}],"asks":[],"checksum":3094289679,"timestamp":"2024-06-01T18:07:02.774081Z"}]}
{"channel":"book","type":"update","data":[{"symbol":"LINK/USD","bids":[{"price":18.54021,"qty":0.00000000},{"price":18.53700,"qty":186.96555600}],"asks":[],"checksum":2630167452,"timestamp":"2024-06-01T18:07:02.775456Z"}]}
{"channel":"book","type":"update","data":[{"symbol":"LINK/USD","bids":[{"price":18.54060,"qty":0.00000000},{"price":18.53578,"qty":269.68105392}],"asks":[],"checksum":3649468595,"timestamp":"2024-06-01T18:07:02.776679Z"}]}
{"channel":"book","type":"update","data":[{"symbol":"LINK/USD","bids":[{"price":18.54047,"qty":63.75000000}],"asks":[],"checksum":619566188,"timestamp":"2024-06-01T18:07:02.785432Z"}]}
{"channel":"book","type":"update","data":[{"symbol":"LINK/USD","bids":[],"asks":[{"price":18.54402,"qty":0.00000000},{"price":18.55119,"qty":31.87500000}],"checksum":2694115123,"timestamp":"2024-06-01T18:07:02.800597Z"}]}
{"channel":"book","type":"update","data":[{"symbol":"LINK/USD","bids":[],"asks":[{"price":18.54415,"qty":31.87500000}],"checksum":4091397173,"timestamp":"2024-06-01T18:07:02.819031Z"}]}
{"channel":"book","type":"update","data":[{"symbol":"LINK/USD","bids":[{"price":18.54047,"qty":31.87500000}],"asks":[],"checksum":246835434,"timestamp":"2024-06-01T18:07:02.822699Z"}]}
{"channel":"book","type":"update","data":[{"symbol":"LINK/USD","bids":[{"price":18.54059,"qty":31.87500000}],"asks":[],"checksum":2184619265,"timestamp":"2024-06-01T18:07:02.825777Z"}]}
{"channel":"book","type":"update","data":[{"symbol":"LINK/USD","bids":[{"price":18.54059,"qty":0.00000000},{"price":18.53578,"qty":269.68105392}],"asks":[],"checksum":246835434,"timestamp":"2024-06-01T18:07:02.829722Z"}]}
{"channel":"book","type":"update","data":[{"symbol":"LINK/USD","bids":[{"price":18.54047,"qty":0.00000000},{"price":18.53551,"qty":63.75000000}],"asks":[],"checksum":259629875,"timestamp":"2024-06-01T18:07:02.829879Z"}]}
{"channel":"book","type":"update","data":[{"symbol":"LINK/USD","bids":[{"price":18.53983,"qty":31.87500000}],"asks":[],"checksum":3058623406,"timestamp":"2024-06-01T18:07:02.834021Z"}]}
{"channel":"book","type":"update","data":[{"symbol":"LINK/USD","bids":[],"asks":[{"price":18.54432,"qty":6.43107813}],"checksum":3781507753,"timestamp":"2024-06-01T18:07:02.883907Z"}]}
{"channel":"book","type":"update","data":[{"symbol":"LINK/USD","bids":[{"price":18.53983,"qty":63.75000000}],"asks":[],"checksum":470718070,"timestamp":"2024-06-01T18:07:02.898610Z"}]}
{"channel":"book","type":"update","data":[{"symbol":"LINK/USD","bids":[{"price":18.53969,"qty":0.00000000},{"price":18.53551,"qty":63.75000000},{"price":18.53984,"qty":1.38666983}],"asks":[],"checksum":529569190,"timestamp":"2024-06-01T18:07:02.961314Z"}]}
{"channel":"book","type":"update","data":[{"symbol":"LINK/USD","bids":[{"price":18.54038,"qty":31.87500000}],"asks":[],"checksum":1925455587,"timestamp":"2024-06-01T18:07:03.194212Z"}]}
{"channel":"book","type":"update","data":[{"symbol":"LINK/USD","bids":[{"price":18.53985,"qty":243.48672997}],"asks":[],"checksum":1151312832,"timestamp":"2024-06-01T18:07:03.198211Z"}]}
{"channel":"book","type":"update","data":[{"symbol":"LINK/USD","bids":[],"asks":[{"price":18.54413,"qty":40.00000000}],"checksum":1435979168,"timestamp":"2024-06-01T18:07:03.255124Z"}]}
{"channel":"book","type":"update","data":[{"symbol":"LINK/USD","bids":[],"asks":[{"price":18.54411,"qty":31.87500000}],"checksum":293937411,"timestamp":"2024-06-01T18:07:03.258634Z"}]}
{"channel":"book","type":"update","data":[{"symbol":"LINK/USD","bids":[{"price":18.53968,"qty":0.00000000},{"price":18.53700,"qty":186.96555600}],"asks":[],"checksum":1094543997,"timestamp":"2024-06-01T18:07:03.259117Z"}]}
{"channel":"book","type":"update","data":[{"symbol":"LINK/USD","bids":[],"asks":[{"price":18.54478,"qty":0.00000000},{"price":18.54936,"qty":2.23393540}],"checksum":952885542,"timestamp":"2024-06-01T18:07:03.260650Z"}]}
{"channel":"book","type":"update","data":[{"symbol":"LINK/USD","bids":[],"asks":[{"price":18.54411,"qty":0.00000000},{"price":18.54989,"qty":40.00000000}],"checksum":2500210707,"timestamp":"2024-06-01T18:07:03.303103Z"}]}
{"channel":"book","type":"update","data":[{"symbol":"LINK/USD","bids":[],"asks":[{"price":18.54415,"qty":0.00000000},{"price":18.55100,"qty":83.67104051}],"checksum":3074486618,"timestamp":"2024-06-01T18:07:03.303682Z"}]}
{"channel":"book","type":"update","data":[{"symbol":"LINK/USD","bids":[],"asks":[{"price":18.54434,"qty":0.00000000},{"price":18.55119,"qty":31.87500000}],"checksum":2144066957,"timestamp":"2024-06-01T18:07:03.306338Z"}]}
{"channel":"book","type":"update","data":[{"symbol":"LINK/USD","bids":[],"asks":[{"price":18.54670,"qty":8.06136702}],"checksum":3027437385,"timestamp":"2024-06-01T18:07:03.307740Z"}]}
{"channel":"book","type":"update","data":[{"symbol":"LINK/USD","bids":[],"asks":[{"price":18.54416,"qty":0.00000000},{"price":18.55119,"qty":31.87500000}],"checksum":2015973811,"timestamp":"2024-06-01T18:07:03.457701Z"}]}
{"channel":"book","type":"update","data":[{"symbol":"LINK/USD","bids":[],"asks":[{"price":18.54432,"qty":0.00000000},{"price":18.55158,"qty":2.07415715}],"checksum":2844359366,"timestamp":"2024-06-01T18:07:03.482229Z"}]}
{"channel":"book","type":"update","data":[{"symbol":"LINK/USD","bids":[],"asks":[{"price":18.54537,"qty":6.43107813}],"checksum":2449562622,"timestamp":"2024-06-01T18:07:03.603554Z"}]}
{"channel":"book","type":"update","data":[{"symbol":"LINK/USD","bids":[],"asks":[{"price":18.54536,"qty":31.84104839}],"checksum":1750685750,"timestamp":"2024-06-01T18:07:03.606753Z"}]}
{"channel":"book","type":"update","data":[{"symbol":"LINK/USD","bids":[{"price":18.53984,"qty":0.00000000},{"price":18.53578,"qty":269.68105392},{"price":18.54039,"qty":1.38539138}],"asks":[],"checksum":2330987951,"timestamp":"2024-06-01T18:07:03.634430Z"}]}
{"channel":"book","type":"update","data":[{"symbol":"LINK/USD","bids":[{"price":18.54039,"qty":244.87212135}],"asks":[],"checksum":810099737,"timestamp":"2024-06-01T18:07:03.638797Z"}]}
{"channel":"book","type":"update","data":[{"symbol":"LINK/USD","bids":[{"price":18.54131,"qty":31.87500000}],"asks":[],"checksum":1002752473,"timestamp":"2024-06-01T18:07:03.642837Z"}]}
{"channel":"book","type":"update","data":[{"symbol":"LINK/USD","bids":[{"price":18.53983,"qty":31.87500000}],"asks":[],"checksum":1643637531,"timestamp":"2024-06-01T18:07:03.643067Z"}]}
{"channel":"book","type":"update","data":[{"symbol":"LINK/USD","bids":[{"price":18.54131,"qty":0.00000000},{"price":18.53700,"qty":186.96555600}],"asks":[],"checksum":3936490355,"timestamp":"2024-06-01T18:07:03.687196Z"}]}
{"channel":"book","type":"update","data":[{"symbol":"LINK/USD","bids":[{"price":18.53985,"qty":0.00000000},{"price":18.53578,"qty":269.68105392}],"asks":[],"checksum":2540446381,"timestamp":"2024-06-01T18:07:03.690990Z"}]}
{"channel":"book","type":"update","data":[{"symbol":"LINK/USD","bids":[{"price":18.54131,"qty":31.87500000}],"asks":[],"checksum":2467224524,"timestamp":"2024-06-01T18:07:03.691329Z"}]}
{"channel":"book","type":"update","data":[{"symbol":"LINK/USD","bids":[{"price":18.54173,"qty":31.87500000}],"asks":[],"checksum":4052463012,"timestamp":"2024-06-01T18:07:03.692852Z"}]}
{"channel":"book","type":"update","data":[{"symbol":"LINK/USD","bids":[{"price":18.54038,"qty":0.00000000},{"price":18.53700,"qty":186.96555600}],"asks":[],"checksum":1063958056,"timestamp":"2024-06-01T18:07:03.696229Z"}]}
{"channel":"book","type":"update","data":[{"symbol":"LINK/USD","bids":[{"price":18.54173,"qty":63.75000000}],"asks":[],"checksum":3254852343,"timestamp":"2024-06-01T18:07:03.696451Z"}]}
{"channel":"book","type":"update","data":[{"symbol":"LINK/USD","bids":[{"price":18.54131,"qty":0.00000000},{"price":18.53578,"qty":269.68105392}],"asks":[],"checksum":1226620898,"timestamp":"2024-06-01T18:07:03.697259Z"}]}
{"channel":"book","type":"update","data":[{"symbol":"LINK/USD","bids":[{"price":18.54173,"qty":31.87500000}],"asks":[],"checksum":1603083019,"timestamp":"2024-06-01T18:07:03.730629Z"}]}
{"channel":"book","type":"update","data":[{"symbol":"LINK/USD","bids":[{"price":18.54173,"qty":0.00000000},{"price":18.53551,"qty":63.75000000}],"asks":[],"checksum":848419720,"timestamp":"2024-06-01T18:07:03.829991Z"}]}
{"channel":"book","type":"update","data":[{"symbol":"LINK/USD","bids":[{"price":18.54173,"qty":31.87500000}],"asks":[],"checksum":1603083019,"timestamp":"2024-06-01T18:07:03.833204Z"}]}
{"channel":"book","type":"update","data":[{"symbol":"LINK/USD","bids":[{"price":18.54131,"qty":31.87500000}],"asks":[],"checksum":1063958056,"timestamp":"2024-06-01T18:07:03.833504Z"}]}
{"channel":"book","type":"update","data":[{"symbol":"LINK/USD","bids":[{"price":18.54173,"qty":0.00000000},{"price":18.53578,"qty":269.68105392}],"asks":[],"checksum":3720149223,"timestamp":"2024-06-01T18:07:03.835579Z"}]}
{"channel":"book","type":"update","data":[{"symbol":"LINK/USD","bids":[],"asks":[{"price":18.54413,"qty":0.00000000},{"price":18.55119,"qty":31.87500000}],"checksum":54905726,"timestamp":"2024-06-01T18:07:03.836045Z"}]}
{"channel":"book","type":"update","data":[{"symbol":"LINK/USD","bids":[],"asks":[{"price":18.54516,"qty":31.87500000}],"checksum":3558768356,"timestamp":"2024-06-01T18:07:03.839397Z"}]}
{"channel":"book","type":"update","data":[{"symbol":"LINK/USD","bids":[],"asks":[{"price":18.54516,"qty":0.00000000},{"price":18.55119,"qty":31.87500000}],"checksum":54905726,"timestamp":"2024-06-01T18:07:03.874903Z"}]}
{"channel":"book","type":"update","data":[{"symbol":"LINK/USD","bids":[],"asks":[{"price":18.54523,"qty":31.87500000}],"checksum":928457358,"timestamp":"2024-06-01T18:07:03.929345Z"}]}
{"channel":"book","type":"update","data":[{"symbol":"LINK/USD","bids":[{"price":18.53700,"qty":0.00000000},{"price":18.53551,"qty":63.75000000}],"asks":[],"checksum":963630853,"timestamp":"2024-06-01T18:07:03.930496Z"}]}
{"channel":"book","type":"update","data":[{"symbol":"LINK/USD","bids":[{"price":18.54131,"qty":0.00000000},{"price":18.53540,"qty":433.54710000}],"asks":[],"checksum":3350787768,"timestamp":"2024-06-01T18:07:03.930926Z"}]}
{"channel":"book","type":"update","data":[{"symbol":"LINK/USD","bids":[{"price":18.53796,"qty":0.00000000},{"price":18.53539,"qty":31.87500000}],"asks":[],"checksum":3480881386,"timestamp":"2024-06-01T18:07:03.931849Z"}]}
{"channel":"book","type":"update","data":[{"symbol":"LINK/USD","bids":[],"asks":[{"price":18.54670,"qty":0.00000000},{"price":18.55119,"qty":31.87500000}],"checksum":851660823,"timestamp":"2024-06-01T18:07:03.931987Z"}]}
{"channel":"book","type":"update","data":[{"symbol":"LINK/USD","bids":[],"asks":[{"price":18.54532,"qty":31.87500000}],"checksum":3290637735,"timestamp":"2024-06-01T18:07:03.932484Z"}]}
{"channel":"book","type":"update","data":[{"symbol":"LINK/USD","bids":[],"asks":[{"price":18.54522,"qty":8.06136702}],"checksum":4015241640,"timestamp":"2024-06-01T18:07:03.935767Z"}]}
{"channel":"book","type":"update","data":[{"symbol":"LINK/USD","bids":[{"price":18.53552,"qty":32.39428719}],"asks":[],"checksum":1845352624,"timestamp":"2024-06-01T18:07:03.938782Z"}]}
{"channel":"book","type":"update","data":[{"symbol":"LINK/USD","bids":[],"asks":[{"price":18.54430,"qty":31.87500000}],"checksum":2129756161,"timestamp":"2024-06-01T18:07:03.939193Z"}]}
{"channel":"book","type":"update","data":[{"symbol":"LINK/USD","bids":[],"asks":[{"price":18.54522,"qty":0.00000000},{"price":18.54989,"qty":40.00000000}],"checksum":3969945702,"timestamp":"2024-06-01T18:07:03.943133Z"}]}
{"channel":"book","type":"update","data":[{"symbol":"LINK/USD","bids":[],"asks":[{"price":18.54429,"qty":8.06136702}],"checksum":1740460363,"timestamp":"2024-06-01T18:07:03.946951Z"}]}
{"channel":"book","type":"update","data":[{"symbol":"LINK/USD","bids":[],"asks":[{"price":18.54523,"qty":0.00000000},{"price":18.54989,"qty":40.00000000}],"checksum":3675757876,"timestamp":"2024-06-01T18:07:03.947494Z"}]}
{"channel":"book","type":"update","data":[{"symbol":"LINK/USD","bids":[],"asks":[{"price":18.54406,"qty":31.87500000}],"checksum":4140920358,"timestamp":"2024-06-01T18:07:03.950341Z"}]}
{"channel":"book","type":"update","data":[{"symbol":"LINK/USD","bids":[],"asks":[{"price":18.54429,"qty":0.00000000},{"price":18.54989,"qty":40.00000000}],"checksum":3154751805,"timestamp":"2024-06-01T18:07:03.954310Z"}]}
{"channel":"book","type":"update","data":[{"symbol":"LINK/USD","bids":[{"price":18.53734,"qty":0.00000000},{"price":18.53539,"qty":31.87500000}],"asks":[],"checksum":4022740287,"timestamp":"2024-06-01T18:07:03.957867Z"}]}
{"channel":"book","type":"update","data":[{"symbol":"LINK/USD","bids":[],"asks":[{"price":18.54405,"qty":8.06136702}],"checksum":3596942966,"timestamp":"2024-06-01T18:07:03.958300Z"}]}
{"channel":"book","type":"update","data":[{"symbol":"LINK/USD","bids":[],"asks":[{"price":18.54430,"qty":0.00000000},{"price":18.54989,"qty":40.00000000}],"checksum":3219539323,"timestamp":"2024-06-01T18:07:03.959227Z"}]}
{"channel":"book","type":"update","data":[{"symbol":"LINK/USD","bids":[{"price":18.53559,"qty":269.75129911}],"asks":[],"checksum":355578335,"timestamp":"2024-06-01T18:07:03.961521Z"}]}
{"channel":"book","type":"update","data":[{"symbol":"LINK/USD","bids":[],"asks":[{"price":18.54367,"qty":31.87500000}],"checksum":2650115989,"timestamp":"2024-06-01T18:07:03.962079Z"}]}
{"channel":"book","type":"update","data":[{"symbol":"LINK/USD","bids":[],"asks":[{"price":18.54537,"qty":0.00000000},{"price":18.54989,"qty":40.00000000}],"checksum":1496094543,"timestamp":"2024-06-01T18:07:03.965323Z"}]}
{"channel":"book","type":"update","data":[{"symbol":"LINK/USD","bids":[{"price":18.53983,"qty":0.00000000},{"price":18.53539,"qty":31.87500000}],"asks":[],"checksum":504326986,"timestamp":"2024-06-01T18:07:03.965610Z"}]}
{"channel":"book","type":"update","data":[{"symbol":"LINK/USD","bids":[],"asks":[{"price":18.54405,"qty":0.00000000},{"price":18.55100,"qty":83.67104051}],"checksum":2188441434,"timestamp":"2024-06-01T18:07:03.966262Z"}]}
{"channel":"book","type":"update","data":[{"symbol":"LINK/USD","bids":[{"price":18.54044,"qty":31.87500000}],"asks":[],"checksum":318930553,"timestamp":"2024-06-01T18:07:03.969764Z"}]}
{"channel":"book","type":"update","data":[{"symbol":"LINK/USD","bids":[],"asks":[{"price":18.54366,"qty":8.06136702}],"checksum":511299896,"timestamp":"2024-06-01T18:07:03.969787Z"}]}
{"channel":"book","type":"update","data":[{"symbol":"LINK/USD","bids":[],"asks":[{"price":18.54367,"qty":0.00000000},{"price":18.55100,"qty":83.67104051}],"checksum":1309290631,"timestamp":"2024-06-01T18:07:03.970033Z"}]}
{"channel":"book","type":"update","data":[{"symbol":"LINK/USD","bids":[],"asks":[{"price":18.54406,"qty":0.00000000},{"price":18.55119,"qty":31.87500000}],"checksum":2362980405,"timestamp":"2024-06-01T18:07:03.970080Z"}]}
{"channel":"book","type":"update","data":[{"symbol":"LINK/USD","bids":[{"price":18.54044,"qty":0.00000000},{"price":18.53539,"qty":31.87500000}],"asks":[],"checksum":497725718,"timestamp":"2024-06-01T18:07:03.973317Z"}]}
{"channel":"book","type":"update","data":[{"symbol":"LINK/USD","bids":[],"asks":[{"price":18.54366,"qty":0.00000000},{"price":18.55158,"qty":2.07415715}],"checksum":2713027349,"timestamp":"2024-06-01T18:07:03.974295Z"}]}
{"channel":"book","type":"update","data":[{"symbol":"LINK/USD","bids":[{"price":18.54044,"qty":31.87500000}],"asks":[],"checksum":818350646,"timestamp":"2024-06-01T18:07:03.976753Z"}]}
{"channel":"book","type":"update","data":[{"symbol":"LINK/USD","bids":[{"price":18.54050,"qty":31.87500000}],"asks":[],"checksum":554662378,"timestamp":"2024-06-01T18:07:03.976872Z"}]}
{"channel":"book","type":"update","data":[{"symbol":"LINK/USD","bids":[],"asks":[{"price":18.54532,"qty":63.75000000}],"checksum":225099715,"timestamp":"2024-06-01T18:07:03.977465Z"}]}
{"channel":"book","type":"update","data":[{"symbol":"LINK/USD","bids":[],"asks":[{"price":18.54532,"qty":31.87500000}],"checksum":554662378,"timestamp":"2024-06-01T18:07:03.977512Z"}]}
{"channel":"book","type":"update","data":[{"symbol":"LINK/USD","bids":[{"price":18.54050,"qty":0.00000000},{"price":18.53540,"qty":433.54710000}],"asks":[],"checksum":818350646,"timestamp":"2024-06-01T18:07:03.980891Z"}]}
{"channel":"book","type":"update","data":[{"symbol":"LINK/USD","bids":[],"asks":[{"price":18.54440,"qty":31.87500000}],"checksum":1565908578,"timestamp":"2024-06-01T18:07:03.981158Z"}]}
{"channel":"book","type":"update","data":[{"symbol":"LINK/USD","bids":[],"asks":[{"price":18.54532,"qty":0.00000000},{"price":18.55158,"qty":2.07415715}],"checksum":538343998,"timestamp":"2024-06-01T18:07:03.981936Z"}]}
{"channel":"book","type":"update","data":[{"symbol":"LINK/USD","bids":[],"asks":[{"price":18.54532,"qty":31.87500000}],"checksum":1565908578,"timestamp":"2024-06-01T18:07:03.983718Z"}]}
{"channel":"book","type":"update","data":[{"symbol":"LINK/USD","bids":[{"price":18.54083,"qty":31.87500000}],"asks":[],"checksum":3674150999,"timestamp":"2024-06-01T18:07:03.984014Z"}]}
{"channel":"book","type":"update","data":[{"symbol":"LINK/USD","bids":[],"asks":[{"price":18.54440,"qty":0.00000000},{"price":18.55158,"qty":2.07415715}],"checksum":2513413954,"timestamp":"2024-06-01T18:07:03.985292Z"}]}
{"channel":"book","type":"update","data":[{"symbol":"LINK/USD","bids":[{"price":18.53578,"qty":0.00000000},{"price":18.53540,"qty":433.54710000}],"asks":[],"checksum":4077180705,"timestamp":"2024-06-01T18:07:03.986063Z"}]}
{"channel":"book","type":"update","data":[{"symbol":"LINK/USD","bids":[{"price":18.54083,"qty":0.00000000},{"price":18.53539,"qty":31.87500000}],"asks":[],"checksum":1692104855,"timestamp":"2024-06-01T18:07:03.987715Z"}]}
{"channel":"book","type":"update","data":[{"symbol":"LINK/USD","bids":[],"asks":[{"price":18.54532,"qty":0.00000000},{"price":18.55308,"qty":31.87500000}],"checksum":1353339089,"timestamp":"2024-06-01T18:07:03.988284Z"}]}
{"channel":"book","type":"update","data":[{"symbol":"LINK/USD","bids":[],"asks":[{"price":18.54532,"qty":31.87500000}],"checksum":1692104855,"timestamp":"2024-06-01T18:07:03.988620Z"}]}
{"channel":"book","type":"update","data":[{"symbol":"LINK/USD","bids":[],"asks":[{"price":18.54532,"qty":63.75000000}],"checksum":1220460222,"timestamp":"2024-06-01T18:07:03.992555Z"}]}
{"channel":"book","type":"update","data":[{"symbol":"LINK/USD","bids":[{"price":18.54044,"qty":0.00000000},{"price":18.53468,"qty":269.69704036}],"asks":[],"checksum":853236827,"timestamp":"2024-06-01T18:07:03.994708Z"}]}
{"channel":"book","type":"update","data":[{"symbol":"LINK/USD","bids":[{"price":18.54039,"qty":243.48672997},{"price":18.53560,"qty":1.38574946}],"asks":[],"checksum":3324831193,"timestamp":"2024-06-01T18:07:04.025125Z"}]}
{"channel":"book","type":"update","data":[{"symbol":"LINK/USD","bids":[],"asks":[{"price":18.54532,"qty":73.45983660}],"checksum":1573058323,"timestamp":"2024-06-01T18:07:04.026771Z"}]}
{"channel":"book","type":"update","data":[{"symbol":"LINK/USD","bids":[],"asks":[{"price":18.54531,"qty":200.00000000}],"checksum":2394025441,"timestamp":"2024-06-01T18:07:04.030243Z"}]}
{"channel":"book","type":"update","data":[{"symbol":"LINK/USD","bids":[],"asks":[{"price":18.54439,"qty":31.87500000}],"checksum":2054824589,"timestamp":"2024-06-01T18:07:04.034170Z"}]}
{"channel":"book","type":"update","data":[{"symbol":"LINK/USD","bids":[{"price":18.53551,"qty":0.00000000},{"price":18.53468,"qty":269.69704036}],"asks":[],"checksum":1742039329,"timestamp":"2024-06-01T18:07:04.035516Z"}]}
{"channel":"book","type":"update","data":[{"symbol":"LINK/USD","bids":[{"price":18.53552,"qty":0.00000000},{"price":18.53420,"qty":11.70000000}],"asks":[],"checksum":1982377294,"timestamp":"2024-06-01T18:07:04.090789Z"}]}
{"channel":"book","type":"update","data":[{"symbol":"LINK/USD","bids":[],"asks":[{"price":18.54437,"qty":40.00000000}],"checksum":3941448554,"timestamp":"2024-06-01T18:07:04.253060Z"}]}
{"channel":"book","type":"update","data":[{"symbol":"LINK/USD","bids":[],"asks":[{"price":18.54532,"qty":41.58483660}],"checksum":306343960,"timestamp":"2024-06-01T18:07:04.256869Z"}]}
{"channel":"book","type":"update","data":[{"symbol":"LINK/USD","bids":[],"asks":[{"price":18.54345,"qty":31.87500000}],"checksum":502962484,"timestamp":"2024-06-01T18:07:04.257016Z"}]}
{"channel":"book","type":"update","data":[{"symbol":"LINK/USD","bids":[{"price":18.54039,"qty":0.00000000},{"price":18.53390,"qty":186.96555600}],"asks":[],"checksum":3878847087,"timestamp":"2024-06-01T18:07:04.257539Z"}]}
{"channel":"book","type":"update","data":[{"symbol":"LINK/USD","bids":[],"asks":[{"price":18.54531,"qty":0.00000000},{"price":18.54989,"qty":40.00000000}],"checksum":2131980137,"timestamp":"2024-06-01T18:07:04.258095Z"}]}
{"channel":"book","type":"update","data":[{"symbol":"LINK/USD","bids":[{"price":18.53560,"qty":0.00000000},{"price":18.53359,"qty":32.39428719},{"price":18.53796,"qty":1.38557306}],"asks":[],"checksum":877139152,"timestamp":"2024-06-01T18:07:04.264108Z"}]}
{"channel":"book","type":"update","data":[{"symbol":"LINK/USD","bids":[{"price":18.53968,"qty":31.87500000}],"asks":[],"checksum":2362301093,"timestamp":"2024-06-01T18:07:04.277454Z"}]}
{"channel":"book","type":"update","data":[{"symbol":"LINK/USD","bids":[{"price":18.53968,"qty":0.00000000},{"price":18.53390,"qty":186.96555600}],"asks":[],"checksum":877139152,"timestamp":"2024-06-01T18:07:04.280702Z"}]}
{"channel":"book","type":"update","data":[{"symbol":"LINK/USD","bids":[{"price":18.53977,"qty":31.87500000}],"asks":[],"checksum":2221938375,"timestamp":"2024-06-01T18:07:04.283856Z"}]}
{"channel":"book","type":"update","data":[{"symbol":"LINK/USD","bids":[{"price":18.53967,"qty":243.48672997}],"asks":[],"checksum":3937454689,"timestamp":"2024-06-01T18:07:04.287879Z"}]}
{"channel":"book","type":"update","data":[{"symbol":"LINK/USD","bids":[{"price":18.53977,"qty":0.00000000},{"price":18.53420,"qty":11.70000000}],"asks":[],"checksum":272562834,"timestamp":"2024-06-01T18:07:04.288041Z"}]}
{"channel":"book","type":"update","data":[{"symbol":"LINK/USD","bids":[],"asks":[{"price":18.54343,"qty":40.00000000}],"checksum":3718931464,"timestamp":"2024-06-01T18:07:04.288608Z"}]}
{"channel":"book","type":"update","data":[{"symbol":"LINK/USD","bids":[{"price":18.53984,"qty":31.87500000}],"asks":[],"checksum":3945515612,"timestamp":"2024-06-01T18:07:04.291043Z"}]}
{"channel":"book","type":"update","data":[{"symbol":"LINK/USD","bids":[],"asks":[{"price":18.54439,"qty":0.00000000},{"price":18.54989,"qty":40.00000000}],"checksum":4253152274,"timestamp":"2024-06-01T18:07:04.291865Z"}]}
{"channel":"book","type":"update","data":[{"symbol":"LINK/USD","bids":[],"asks":[{"price":18.54322,"qty":31.87500000}],"checksum":2327974493,"timestamp":"2024-06-01T18:07:04.292848Z"}]}
{"channel":"book","type":"update","data":[{"symbol":"LINK/USD","bids":[{"price":18.53984,"qty":0.00000000},{"price":18.53420,"qty":11.70000000}],"asks":[],"checksum":3158555657,"timestamp":"2024-06-01T18:07:04.294454Z"}]}
{"channel":"book","type":"update","data":[{"symbol":"LINK/USD","bids":[],"asks":[{"price":18.54322,"qty":0.00000000},{"price":18.54989,"qty":40.00000000}],"checksum":3405797958,"timestamp":"2024-06-01T18:07:04.297629Z"}]}
{"channel":"book","type":"update","data":[{"symbol":"LINK/USD","bids":[{"price":18.53985,"qty":31.87500000}],"asks":[],"checksum":2579833526,"timestamp":"2024-06-01T18:07:04.297733Z"}]}
{"channel":"book","type":"update","data":[{"symbol":"LINK/USD","bids":[{"price":18.53985,"qty":0.00000000},{"price":18.53420,"qty":11.70000000}],"asks":[],"checksum":3405797958,"timestamp":"2024-06-01T18:07:04.301657Z"}]}
{"channel":"book","type":"update","data":[{"symbol":"LINK/USD","bids":[],"asks":[{"price":18.54330,"qty":31.87500000}],"checksum":1867000420,"timestamp":"2024-06-01T18:07:04.301954Z"}]}
{"channel":"book","type":"update","data":[{"symbol":"LINK/USD","bids":[],"asks":[{"price":18.54317,"qty":33.00000000}],"checksum":948990150,"timestamp":"2024-06-01T18:07:04.304533Z"}]}
{"channel":"book","type":"update","data":[{"symbol":"LINK/USD","bids":[{"price":18.53997,"qty":31.87500000}],"asks":[],"checksum":1929610841,"timestamp":"2024-06-01T18:07:04.304684Z"}]}
{"channel":"book","type":"update","data":[{"symbol":"LINK/USD","bids":[{"price":18.53997,"qty":0.00000000},{"price":18.53420,"qty":11.70000000}],"asks":[],"checksum":948990150,"timestamp":"2024-06-01T18:07:04.307673Z"}]}
{"channel":"book","type":"update","data":[{"symbol":"LINK/USD","bids":[],"asks":[{"price":18.54330,"qty":0.00000000},{"price":18.54936,"qty":2.23393540}],"checksum":1641778975,"timestamp":"2024-06-01T18:07:04.310036Z"}]}
{"channel":"book","type":"update","data":[{"symbol":"LINK/USD","bids":[{"price":18.53978,"qty":31.87500000}],"asks":[],"checksum":3913163123,"timestamp":"2024-06-01T18:07:04.311139Z"}]}
{"channel":"book","type":"update","data":[{"symbol":"LINK/USD","bids":[{"price":18.54003,"qty":31.87500000}],"asks":[],"checksum":17021811,"timestamp":"2024-06-01T18:07:04.311174Z"}]}
{"channel":"book","type":"update","data":[{"symbol":"LINK/USD","bids":[{"price":18.54003,"qty":0.00000000},{"price":18.53468,"qty":269.69704036}],"asks":[],"checksum":3913163123,"timestamp":"2024-06-01T18:07:04.314993Z"}]}
{"channel":"book","type":"update","data":[{"symbol":"LINK/USD","bids":[{"price":18.54010,"qty":31.87500000}],"asks":[],"checksum":348504572,"timestamp":"2024-06-01T18:07:04.318049Z"}]}
{"channel":"book","type":"update","data":[{"symbol":"LINK/USD","bids":[],"asks":[{"price":18.54343,"qty":0.00000000},{"price":18.54989,"qty":40.00000000}],"checksum":3973896644,"timestamp":"2024-06-01T18:07:04.319054Z"}]}
{"channel":"book","type":"update","data":[{"symbol":"LINK/USD","bids":[],"asks":[{"price":18.54345,"qty":0.00000000},{"price":18.55100,"qty":83.67104051}],"checksum":701414170,"timestamp":"2024-06-01T18:07:04.321150Z"}]}
{"channel":"book","type":"update","data":[{"symbol":"LINK/USD","bids":[{"price":18.54010,"qty":0.00000000},{"price":18.53468,"qty":269.69704036}],"asks":[],"checksum":2691329348,"timestamp":"2024-06-01T18:07:04.321877Z"}]}
{"channel":"book","type":"update","data":[{"symbol":"LINK/USD","bids":[{"price":18.54010,"qty":31.87500000}],"asks":[],"checksum":701414170,"timestamp":"2024-06-01T18:07:04.322151Z"}]}
{"channel":"book","type":"update","data":[{"symbol":"LINK/USD","bids":[{"price":18.53978,"qty":0.00000000},{"price":18.53468,"qty":269.69704036}],"asks":[],"checksum":2260157697,"timestamp":"2024-06-01T18:07:04.322752Z"}]}
{"channel":"book","type":"update","data":[{"symbol":"LINK/USD","bids":[{"price":18.54010,"qty":63.75000000}],"asks":[],"checksum":2078075358,"timestamp":"2024-06-01T18:07:04.324757Z"}]}
{"channel":"book","type":"update","data":[{"symbol":"LINK/USD","bids":[],"asks":[{"price":18.54532,"qty":31.87500000}],"checksum":2876474490,"timestamp":"2024-06-01T18:07:04.352229Z"}]}
{"channel":"book","type":"update","data":[{"symbol":"LINK/USD","bids":[],"asks":[{"price":18.54400,"qty":33.00000000}],"checksum":3615504534,"timestamp":"2024-06-01T18:07:04.376116Z"}]}
{"channel":"book","type":"update","data":[{"symbol":"LINK/USD","bids":[],"asks":[{"price":18.54317,"qty":0.00000000},{"price":18.55100,"qty":83.67104051}],"checksum":1410898186,"timestamp":"2024-06-01T18:07:04.376278Z"}]}
{"channel":"book","type":"update","data":[{"symbol":"LINK/USD","bids":[],"asks":[{"price":18.54396,"qty":31.87500000}],"checksum":2644572243,"timestamp":"2024-06-01T18:07:04.379621Z"}]}
{"channel":"book","type":"update","data":[{"symbol":"LINK/USD","bids":[],"asks":[{"price":18.54532,"qty":0.00000000},{"price":18.55100,"qty":83.67104051}],"checksum":2736020722,"timestamp":"2024-06-01T18:07:04.380423Z"}]}
{"channel":"book","type":"update","data":[{"symbol":"LINK/USD","bids":[],"asks":[{"price":18.54396,"qty":0.00000000},{"price":18.55119,"qty":31.87500000}],"checksum":490803254,"timestamp":"2024-06-01T18:07:04.382690Z"}]}
{"channel":"book","type":"update","data":[{"symbol":"LINK/USD","bids":[],"asks":[{"price":18.54582,"qty":31.87500000}],"checksum":2993858513,"timestamp":"2024-06-01T18:07:04.383895Z"}]}
{"channel":"book","type":"update","data":[{"symbol":"LINK/USD","bids":[],"asks":[{"price":18.54397,"qty":31.87500000}],"checksum":1097185665,"timestamp":"2024-06-01T18:07:04.415636Z"}]}
{"channel":"book","type":"update","data":[{"symbol":"LINK/USD","bids":[],"asks":[{"price":18.54397,"qty":0.00000000},{"price":18.55100,"qty":83.67104051}],"checksum":2993858513,"timestamp":"2024-06-01T18:07:04.429878Z"}]}
{"channel":"book","type":"update","data":[{"symbol":"LINK/USD","bids":[{"price":18.54010,"qty":31.87500000}],"asks":[],"checksum":1327041294,"timestamp":"2024-06-01T18:07:04.433063Z"}]}
{"channel":"book","type":"update","data":[{"symbol":"LINK/USD","bids":[],"asks":[{"price":18.54378,"qty":31.87500000}],"checksum":53080434,"timestamp":"2024-06-01T18:07:04.433947Z"}]}
{"channel":"book","type":"update","data":[{"symbol":"LINK/USD","bids":[{"price":18.54030,"qty":31.87500000}],"asks":[],"checksum":3213711709,"timestamp":"2024-06-01T18:07:04.435719Z"}]}
{"channel":"book","type":"update","data":[{"symbol":"LINK/USD","bids":[],"asks":[{"price":18.54378,"qty":0.00000000},{"price":18.55100,"qty":83.67104051}],"checksum":3865541500,"timestamp":"2024-06-01T18:07:04.437294Z"}]}
{"channel":"book","type":"update","data":[{"symbol":"LINK/USD","bids":[{"price":18.54030,"qty":63.75000000}],"asks":[],"checksum":4013088358,"timestamp":"2024-06-01T18:07:04.439150Z"}]}
{"channel":"book","type":"update","data":[{"symbol":"LINK/USD","bids":[{"price":18.54010,"qty":0.00000000},{"price":18.53468,"qty":269.69704036}],"asks":[],"checksum":3401443294,"timestamp":"2024-06-01T18:07:04.440259Z"}]}
{"channel":"book","type":"update","data":[{"symbol":"LINK/USD","bids":[],"asks":[{"price":18.54393,"qty":31.87500000}],"checksum":1019849502,"timestamp":"2024-06-01T18:07:04.499079Z"}]}
{"channel":"book","type":"update","data":[{"symbol":"LINK/USD","bids":[],"asks":[{"price":18.54393,"qty":0.00000000},{"price":18.55100,"qty":83.67104051}],"checksum":3401443294,"timestamp":"2024-06-01T18:07:04.502232Z"}]}
{"channel":"book","type":"update","data":[{"symbol":"LINK/USD","bids":[{"price":18.53797,"qty":32.42011199}],"asks":[],"checksum":1736975966,"timestamp":"2024-06-01T18:07:04.616387Z"}]}
{"channel":"book","type":"update","data":[{"symbol":"LINK/USD","bids":[],"asks":[{"price":18.54398,"qty":31.87500000}],"checksum":863394439,"timestamp":"2024-06-01T18:07:04.639355Z"}]}
{"channel":"book","type":"update","data":[{"symbol":"LINK/USD","bids":[{"price":18.54030,"qty":31.87500000}],"asks":[],"checksum":975437725,"timestamp":"2024-06-01T18:07:04.642939Z"}]}
{"channel":"book","type":"update","data":[{"symbol":"LINK/USD","bids":[{"price":18.54041,"qty":31.87500000}],"asks":[],"checksum":2807704635,"timestamp":"2024-06-01T18:07:04.645533Z"}]}
{"channel":"book","type":"update","data":[{"symbol":"LINK/USD","bids":[],"asks":[{"price":18.54400,"qty":0.00000000},{"price":18.55100,"qty":83.67104051}],"checksum":293737173,"timestamp":"2024-06-01T18:07:04.645560Z"}]}
{"channel":"book","type":"update","data":[{"symbol":"LINK/USD","bids":[],"asks":[{"price":18.54397,"qty":33.00000000}],"checksum":68235503,"timestamp":"2024-06-01T18:07:04.645727Z"}]}
{"channel":"book","type":"update","data":[{"symbol":"LINK/USD","bids":[{"price":18.54041,"qty":0.00000000},{"price":18.53539,"qty":31.87500000}],"asks":[],"checksum":2573787977,"timestamp":"2024-06-01T18:07:04.648979Z"}]}
{"channel":"book","type":"update","data":[{"symbol":"LINK/USD","bids":[],"asks":[{"price":18.54392,"qty":31.87500000}],"checksum":971650851,"timestamp":"2024-06-01T18:07:04.649298Z"}]}
{"channel":"book","type":"update","data":[{"symbol":"LINK/USD","bids":[{"price":18.54057,"qty":31.87500000}],"asks":[],"checksum":600992375,"timestamp":"2024-06-01T18:07:04.652179Z"}]}
{"channel":"book","type":"update","data":[{"symbol":"LINK/USD","bids":[{"price":18.54057,"qty":0.00000000},{"price":18.53539,"qty":31.87500000}],"asks":[],"checksum":971650851,"timestamp":"2024-06-01T18:07:04.656653Z"}]}
{"channel":"book","type":"update","data":[{"symbol":"LINK/USD","bids":[],"asks":[{"price":18.54392,"qty":0.00000000},{"price":18.54989,"qty":40.00000000}],"checksum":2573787977,"timestamp":"2024-06-01T18:07:04.657790Z"}]}
{"channel":"book","type":"update","data":[{"symbol":"LINK/USD","bids":[{"price":18.54063,"qty":31.87500000}],"asks":[],"checksum":2456049045,"timestamp":"2024-06-01T18:07:04.661166Z"}]}
{"channel":"book","type":"update","data":[{"symbol":"LINK/USD","bids":[{"price":18.54063,"qty":0.00000000},{"price":18.53539,"qty":31.87500000}],"asks":[],"checksum":2573787977,"timestamp":"2024-06-01T18:07:04.664883Z"}]}
{"channel":"book","type":"update","data":[{"symbol":"LINK/USD","bids":[{"price":18.54030,"qty":63.75000000}],"asks":[],"checksum":2419934803,"timestamp":"2024-06-01T18:07:04.674064Z"}]}
{"channel":"book","type":"update","data":[{"symbol":"LINK/USD","bids":[],"asks":[{"price":18.54390,"qty":31.87500000}],"checksum":3968192762,"timestamp":"2024-06-01T18:07:04.678534Z"}]}
{"channel":"book","type":"update","data":[{"symbol":"LINK/USD","bids":[{"price":18.54030,"qty":31.87500000}],"asks":[],"checksum":3855644128,"timestamp":"2024-06-01T18:07:04.682386Z"}]}
{"channel":"book","type":"update","data":[{"symbol":"LINK/USD","bids":[{"price":18.54042,"qty":31.87500000}],"asks":[],"checksum":153815661,"timestamp":"2024-06-01T18:07:04.685208Z"}]}
{"channel":"book","type":"update","data":[{"symbol":"LINK/USD","bids":[{"price":18.54042,"qty":0.00000000},{"price":18.53539,"qty":31.87500000}],"asks":[],"checksum":3855644128,"timestamp":"2024-06-01T18:07:04.688805Z"}]}
{"channel":"book","type":"update","data":[{"symbol":"LINK/USD","bids":[{"price":18.54045,"qty":31.87500000}],"asks":[],"checksum":3310368290,"timestamp":"2024-06-01T18:07:04.691891Z"}]}
{"channel":"book","type":"update","data":[{"symbol":"LINK/USD","bids":[{"price":18.54045,"qty":0.00000000},{"price":18.53539,"qty":31.87500000}],"asks":[],"checksum":3855644128,"timestamp":"2024-06-01T18:07:04.695194Z"}]}
{"channel":"book","type":"update","data":[{"symbol":"LINK/USD","bids":[{"price":18.54045,"qty":31.87500000}],"asks":[],"checksum":3310368290,"timestamp":"2024-06-01T18:07:04.698164Z"}]}
{"channel":"book","type":"update","data":[{"symbol":"LINK/USD","bids":[{"price":18.54045,"qty":0.00000000},{"price":18.53539,"qty":31.87500000}],"asks":[],"checksum":3855644128,"timestamp":"2024-06-01T18:07:04.702282Z"}]}
{"channel":"book","type":"update","data":[{"symbol":"LINK/USD","bids":[{"price":18.54045,"qty":31.87500000}],"asks":[],"checksum":3310368290,"timestamp":"2024-06-01T18:07:04.705342Z"}]}
{"channel":"book","type":"update","data":[{"symbol":"LINK/USD","bids":[{"price":18.54045,"qty":0.00000000},{"price":18.53539,"qty":31.87500000}],"asks":[],"checksum":3855644128,"timestamp":"2024-06-01T18:07:04.708467Z"}]}
{"channel":"book","type":"update","data":[{"symbol":"LINK/USD","bids":[{"price":18.54046,"qty":31.87500000}],"asks":[],"checksum":3033700873,"timestamp":"2024-06-01T18:07:04.711504Z"}]}
{"channel":"book","type":"update","data":[{"symbol":"LINK/USD","bids":[{"price":18.54046,"qty":0.00000000},{"price":18.53539,"qty":31.87500000}],"asks":[],"checksum":3855644128,"timestamp":"2024-06-01T18:07:04.714953Z"}]}
{"channel":"book","type":"update","data":[{"symbol":"LINK/USD","bids":[{"price":18.54046,"qty":31.87500000}],"asks":[],"checksum":3033700873,"timestamp":"2024-06-01T18:07:04.718666Z"}]}
{"channel":"book","type":"update","data":[{"symbol":"LINK/USD","bids":[{"price":18.54046,"qty":0.00000000},{"price":18.53539,"qty":31.87500000}],"asks":[],"checksum":3855644128,"timestamp":"2024-06-01T18:07:04.722482Z"}]}
{"channel":"book","type":"update","data":[{"symbol":"LINK/USD","bids":[{"price":18.54048,"qty":31.87500000}],"asks":[],"checksum":4149601494,"timestamp":"2024-06-01T18:07:04.725874Z"}]}
{"channel":"book","type":"update","data":[{"symbol":"LINK/USD","bids":[{"price":18.54048,"qty":0.00000000},{"price":18.53539,"qty":31.87500000}],"asks":[],"checksum":3855644128,"timestamp":"2024-06-01T18:07:04.729030Z"}]}
{"channel":"book","type":"update","data":[{"symbol":"LINK/USD","bids":[{"price":18.54030,"qty":63.75000000}],"asks":[],"checksum":3968192762,"timestamp":"2024-06-01T18:07:04.737267Z"}]}
{"channel":"book","type":"update","data":[{"symbol":"LINK/USD","bids":[{"price":18.54030,"qty":31.87500000}],"asks":[],"checksum":3855644128,"timestamp":"2024-06-01T18:07:04.754413Z"}]}
{"channel":"book","type":"update","data":[{"symbol":"LINK/USD","bids":[],"asks":[{"price":18.54389,"qty":33.00000000}],"checksum":2593178490,"timestamp":"2024-06-01T18:07:04.757114Z"}]}
{"channel":"book","type":"update","data":[{"symbol":"LINK/USD","bids":[],"asks":[{"price":18.54397,"qty":0.00000000},{"price":18.54936,"qty":2.23393540}],"checksum":970477092,"timestamp":"2024-06-01T18:07:04.757189Z"}]}
{"channel":"book","type":"update","data":[{"symbol":"LINK/USD","bids":[{"price":18.54030,"qty":0.00000000},{"price":18.53468,"qty":269.69704036}],"asks":[],"checksum":2251833789,"timestamp":"2024-06-01T18:07:04.760315Z"}]}
{"channel":"book","type":"update","data":[{"symbol":"LINK/USD","bids":[],"asks":[{"price":18.54398,"qty":0.00000000},{"price":18.54989,"qty":40.00000000}],"checksum":619918046,"timestamp":"2024-06-01T18:07:04.760526Z"}]}
{"channel":"book","type":"update","data":[{"symbol":"LINK/USD","bids":[],"asks":[{"price":18.54351,"qty":31.87500000}],"checksum":2587061763,"timestamp":"2024-06-01T18:07:04.761509Z"}]}
{"channel":"book","type":"update","data":[{"symbol":"LINK/USD","bids":[{"price":18.54004,"qty":31.87500000}],"asks":[],"checksum":1336048125,"timestamp":"2024-06-01T18:07:04.764846Z"}]}
{"channel":"book","type":"update","data":[{"symbol":"LINK/USD","bids":[{"price":18.54016,"qty":31.87500000}],"asks":[],"checksum":4227042901,"timestamp":"2024-06-01T18:07:04.768157Z"}]}
{"channel":"book","type":"update","data":[{"symbol":"LINK/USD","bids":[],"asks":[{"price":18.54351,"qty":0.00000000},{"price":18.54989,"qty":40.00000000}],"checksum":817840935,"timestamp":"2024-06-01T18:07:04.768795Z"}]}
{"channel":"book","type":"update","data":[{"symbol":"LINK/USD","bids":[{"price":18.54016,"qty":63.75000000}],"asks":[],"checksum":971695677,"timestamp":"2024-06-01T18:07:04.771312Z"}]}
{"channel":"book","type":"update","data":[{"symbol":"LINK/USD","bids":[{"price":18.54004,"qty":0.00000000},{"price":18.53539,"qty":31.87500000}],"asks":[],"checksum":3070430979,"timestamp":"2024-06-01T18:07:04.771610Z"}]}
{"channel":"book","type":"update","data":[{"symbol":"LINK/USD","bids":[],"asks":[{"price":18.54388,"qty":31.87500000}],"checksum":924599466,"timestamp":"2024-06-01T18:07:04.784075Z"}]}
{"channel":"book","type":"update","data":[{"symbol":"LINK/USD","bids":[],"asks":[{"price":18.54390,"qty":0.00000000},{"price":18.54989,"qty":40.00000000}],"checksum":1828888683,"timestamp":"2024-06-01T18:07:04.830933Z"}]}
{"channel":"book","type":"update","data":[{"symbol":"LINK/USD","bids":[],"asks":[{"price":18.54388,"qty":0.00000000},{"price":18.55100,"qty":83.67104051}],"checksum":1524196503,"timestamp":"2024-06-01T18:07:04.831141Z"}]}
{"channel":"book","type":"update","data":[{"symbol":"LINK/USD","bids":[],"asks":[{"price":18.54389,"qty":0.00000000},{"price":18.55119,"qty":31.87500000}],"checksum":2683249916,"timestamp":"2024-06-01T18:07:04.833772Z"}]}
{"channel":"book","type":"update","data":[{"symbol":"LINK/USD","bids":[],"asks":[{"price":18.54387,"qty":33.00000000}],"checksum":602776093,"timestamp":"2024-06-01T18:07:04.833978Z"}]}
{"channel":"book","type":"update","data":[{"symbol":"LINK/USD","bids":[],"asks":[{"price":18.54404,"qty":31.87500000}],"checksum":1751198477,"timestamp":"2024-06-01T18:07:04.837353Z"}]}
{"channel":"book","type":"update","data":[{"symbol":"LINK/USD","bids":[],"asks":[{"price":18.54379,"qty":31.87500000}],"checksum":548327135,"timestamp":"2024-06-01T18:07:04.848052Z"}]}
{"channel":"book","type":"update","data":[{"symbol":"LINK/USD","bids":[],"asks":[{"price":18.54379,"qty":0.00000000},{"price":18.54989,"qty":40.00000000}],"checksum":1751198477,"timestamp":"2024-06-01T18:07:04.861315Z"}]}
{"channel":"book","type":"update","data":[{"symbol":"LINK/USD","bids":[{"price":18.53796,"qty":0.00000000},{"price":18.53468,"qty":269.69704036},{"price":18.53968,"qty":1.38544452}],"asks":[],"checksum":1702404238,"timestamp":"2024-06-01T18:07:04.959947Z"}]}
{"channel":"book","type":"update","data":[{"symbol":"LINK/USD","bids":[],"asks":[{"price":18.54535,"qty":8.06136702}],"checksum":1603212180,"timestamp":"2024-06-01T18:07:04.998523Z"}]}
{"channel":"book","type":"update","data":[{"symbol":"LINK/USD","bids":[],"asks":[{"price":18.54377,"qty":31.87500000}],"checksum":2871256543,"timestamp":"2024-06-01T18:07:05.119602Z"}]}
{"channel":"book","type":"update","data":[{"symbol":"LINK/USD","bids":[{"price":18.54016,"qty":31.87500000}],"asks":[],"checksum":2725658821,"timestamp":"2024-06-01T18:07:05.123014Z"}]}
{"channel":"book","type":"update","data":[{"symbol":"LINK/USD","bids":[{"price":18.54016,"qty":0.00000000},{"price":18.53468,"qty":269.69704036}],"asks":[],"checksum":1401938311,"timestamp":"2024-06-01T18:07:05.123527Z"}]}
{"channel":"book","type":"update","data":[{"symbol":"LINK/USD","bids":[{"price":18.54017,"qty":243.48672997}],"asks":[],"checksum":440789626,"timestamp":"2024-06-01T18:07:05.123863Z"}]}
{"channel":"book","type":"update","data":[{"symbol":"LINK/USD","bids":[{"price":18.53968,"qty":0.00000000},{"price":18.53468,"qty":269.69704036},{"price":18.53560,"qty":1.38574950}],"asks":[],"checksum":1743252442,"timestamp":"2024-06-01T18:07:05.127263Z"}]}
{"channel":"book","type":"update","data":[{"symbol":"LINK/USD","bids":[{"price":18.54020,"qty":31.87500000}],"asks":[],"checksum":1388849133,"timestamp":"2024-06-01T18:07:05.163896Z"}]}
{"channel":"book","type":"update","data":[{"symbol":"LINK/USD","bids":[{"price":18.54020,"qty":0.00000000},{"price":18.53539,"qty":31.87500000}],"asks":[],"checksum":1743252442,"timestamp":"2024-06-01T18:07:05.167225Z"}]}
{"channel":"book","type":"update","data":[{"symbol":"LINK/USD","bids":[{"price":18.54017,"qty":0.00000000},{"price":18.53468,"qty":269.69704036}],"asks":[],"checksum":288649023,"timestamp":"2024-06-01T18:07:05.167760Z"}]}
{"channel":"book","type":"update","data":[{"symbol":"LINK/USD","bids":[{"price":18.54011,"qty":31.87500000}],"asks":[],"checksum":330267946,"timestamp":"2024-06-01T18:07:05.174746Z"}]}
{"channel":"book","type":"update","data":[{"symbol":"LINK/USD","bids":[{"price":18.54011,"qty":0.00000000},{"price":18.53468,"qty":269.69704036}],"asks":[],"checksum":288649023,"timestamp":"2024-06-01T18:07:05.178619Z"}]}
{"channel":"book","type":"update","data":[{"symbol":"LINK/USD","bids":[{"price":18.54017,"qty":31.87500000}],"asks":[],"checksum":4037682556,"timestamp":"2024-06-01T18:07:05.181528Z"}]}
{"channel":"book","type":"update","data":[{"symbol":"LINK/USD","bids":[{"price":18.54017,"qty":0.00000000},{"price":18.53468,"qty":269.69704036}],"asks":[],"checksum":288649023,"timestamp":"2024-06-01T18:07:05.185099Z"}]}
{"channel":"book","type":"update","data":[{"symbol":"LINK/USD","bids":[{"price":18.54020,"qty":31.87500000}],"asks":[],"checksum":2417779423,"timestamp":"2024-06-01T18:07:05.188187Z"}]}
{"channel":"book","type":"update","data":[{"symbol":"LINK/USD","bids":[{"price":18.54020,"qty":0.00000000},{"price":18.53468,"qty":269.69704036}],"asks":[],"checksum":288649023,"timestamp":"2024-06-01T18:07:05.191595Z"}]}
{"channel":"book","type":"update","data":[{"symbol":"LINK/USD","bids":[{"price":18.54015,"qty":31.87500000}],"asks":[],"checksum":2924932430,"timestamp":"2024-06-01T18:07:05.205171Z"}]}
{"channel":"book","type":"update","data":[{"symbol":"LINK/USD","bids":[{"price":18.54015,"qty":0.00000000},{"price":18.53468,"qty":269.69704036}],"asks":[],"checksum":288649023,"timestamp":"2024-06-01T18:07:05.208880Z"}]}
{"channel":"book","type":"update","data":[{"symbol":"LINK/USD","bids":[{"price":18.54016,"qty":31.87500000}],"asks":[],"checksum":3755229541,"timestamp":"2024-06-01T18:07:05.211730Z"}]}
{"channel":"book","type":"update","data":[{"symbol":"LINK/USD","bids":[{"price":18.54016,"qty":0.00000000},{"price":18.53468,"qty":269.69704036}],"asks":[],"checksum":288649023,"timestamp":"2024-06-01T18:07:05.215527Z"}]}
{"channel":"book","type":"update","data":[{"symbol":"LINK/USD","bids":[{"price":18.54017,"qty":31.87500000}],"asks":[],"checksum":4037682556,"timestamp":"2024-06-01T18:07:05.218342Z"}]}
{"channel":"book","type":"update","data":[{"symbol":"LINK/USD","bids":[{"price":18.54017,"qty":0.00000000},{"price":18.53468,"qty":269.69704036}],"asks":[],"checksum":288649023,"timestamp":"2024-06-01T18:07:05.221344Z"}]}
{"channel":"book","type":"update","data":[{"symbol":"LINK/USD","bids":[{"price":18.54022,"qty":31.87500000}],"asks":[],"checksum":3470830317,"timestamp":"2024-06-01T18:07:05.230759Z"}]}
{"channel":"book","type":"update","data":[{"symbol":"LINK/USD","bids":[],"asks":[{"price":18.54377,"qty":0.00000000},{"price":18.54936,"qty":2.23393540}],"checksum":978082982,"timestamp":"2024-06-01T18:07:05.232917Z"}]}
{"channel":"book","type":"update","data":[{"symbol":"LINK/USD","bids":[{"price":18.54039,"qty":31.87500000}],"asks":[],"checksum":2777635048,"timestamp":"2024-06-01T18:07:05.233350Z"}]}
{"channel":"book","type":"update","data":[{"symbol":"LINK/USD","bids":[],"asks":[{"price":18.54404,"qty":0.00000000},{"price":18.54989,"qty":40.00000000}],"checksum":4149739237,"timestamp":"2024-06-01T18:07:05.236583Z"}]}
{"channel":"book","type":"update","data":[{"symbol":"LINK/USD","bids":[],"asks":[{"price":18.54385,"qty":40.00000000}],"checksum":3789428047,"timestamp":"2024-06-01T18:07:05.241182Z"}]}
