{"channel":"book","type":"snapshot","data":[{"symbol":"LINK/ETH","bids":[{"price":0.00487962,"qty":131.75171000},{"price":0.00487862,"qty":21.57317627},{"price":0.00487850,"qty":26.97523382},{"price":0.00487789,"qty":26.97970310},{"price":0.00487759,"qty":7.38633408},{"price":0.00487746,"qty":71.53689000},{"price":0.00487476,"qty":438.16674000},{"price":0.00487428,"qty":26.99801406},{"price":0.00487226,"qty":0.52121133},{"price":0.00486607,"qty":42.57457429}],"asks":[{"price":0.00488174,"qty":4.85405622},{"price":0.00488196,"qty":21.57260487},{"price":0.00488435,"qty":8.08292440},{"price":0.00488762,"qty":8.07790882},{"price":0.00489320,"qty":70.52987272},{"price":0.00489321,"qty":0.51460698},{"price":0.00489462,"qty":71.53689000},{"price":0.00490373,"qty":131.75171000},{"price":0.00490407,"qty":185.34589070},{"price":0.00490408,"qty":438.16674000}],"checksum":2328072233}]}
{"channel":"book","type":"update","data":[{"symbol":"LINK/ETH","bids":[],"asks":[{"price":0.00488161,"qty":8.08737983}],"checksum":978400070,"timestamp":"2024-06-01T18:06:49.781308Z"}]}
{"channel":"book","type":"update","data":[{"symbol":"LINK/ETH","bids":[],"asks":[{"price":0.00488156,"qty":4.85404880}],"checksum":29465106,"timestamp":"2024-06-01T18:06:49.784072Z"}]}
{"channel":"book","type":"update","data":[{"symbol":"LINK/ETH","bids":[],"asks":[{"price":0.00488174,"qty":0.00000000},{"price":0.00490407,"qty":185.34589070}],"checksum":869094640,"timestamp":"2024-06-01T18:06:49.786754Z"}]}
{"channel":"book","type":"update","data":[{"symbol":"LINK/ETH","bids":[],"asks":[{"price":0.00490373,"qty":0.00000000},{"price":0.00490408,"qty":438.16674000}],"checksum":3174299734,"timestamp":"2024-06-01T18:06:52.283498Z"}]}
{"channel":"book","type":"update","data":[{"symbol":"LINK/ETH","bids":[],"asks":[{"price":0.00490372,"qty":131.75171000}],"checksum":4137730150,"timestamp":"2024-06-01T18:06:52.286416Z"}]}
{"channel":"book","type":"update","data":[{"symbol":"LINK/ETH","bids":[{"price":0.00487850,"qty":0.00000000},{"price":0.00486602,"qty":263.85422000}],"asks":[],"checksum":1575812595,"timestamp":"2024-06-01T18:06:54.206086Z"}]}
{"channel":"book","type":"update","data":[{"symbol":"LINK/ETH","bids":[{"price":0.00487890,"qty":26.97494965}],"asks":[],"checksum":721824580,"timestamp":"2024-06-01T18:06:54.209479Z"}]}
{"channel":"book","type":"update","data":[{"symbol":"LINK/ETH","bids":[],"asks":[{"price":0.00488156,"qty":0.00000000},{"price":0.00490408,"qty":438.16674000}],"checksum":567094859,"timestamp":"2024-06-01T18:06:54.223776Z"}]}
{"channel":"book","type":"update","data":[{"symbol":"LINK/ETH","bids":[],"asks":[{"price":0.00488161,"qty":0.00000000},{"price":0.00492132,"qty":283.29663722}],"checksum":274522480,"timestamp":"2024-06-01T18:06:54.225648Z"}]}
{"channel":"book","type":"update","data":[{"symbol":"LINK/ETH","bids":[],"asks":[{"price":0.00488202,"qty":8.08742550}],"checksum":2402090193,"timestamp":"2024-06-01T18:06:54.230007Z"}]}
{"channel":"book","type":"update","data":[{"symbol":"LINK/ETH","bids":[],"asks":[{"price":0.00488196,"qty":0.00000000},{"price":0.00492132,"qty":283.29663722}],"checksum":2283362818,"timestamp":"2024-06-01T18:06:54.322785Z"}]}
{"channel":"book","type":"update","data":[{"symbol":"LINK/ETH","bids":[],"asks":[{"price":0.00488215,"qty":21.57325242}],"checksum":1413531,"timestamp":"2024-06-01T18:06:54.627794Z"}]}
{"channel":"book","type":"update","data":[{"symbol":"LINK/ETH","bids":[],"asks":[{"price":0.00489321,"qty":0.00000000},{"price":0.00492132,"qty":283.29663722}],"checksum":489621474,"timestamp":"2024-06-01T18:06:54.820935Z"}]}
{"channel":"book","type":"update","data":[{"symbol":"LINK/ETH","bids":[],"asks":[{"price":0.00489461,"qty":70.52987272}],"checksum":3117018544,"timestamp":"2024-06-01T18:06:54.832526Z"}]}
{"channel":"book","type":"update","data":[{"symbol":"LINK/ETH","bids":[],"asks":[{"price":0.00489320,"qty":0.00000000},{"price":0.00492132,"qty":283.29663722}],"checksum":1991659134,"timestamp":"2024-06-01T18:06:54.832601Z"}]}
{"channel":"book","type":"update","data":[{"symbol":"LINK/ETH","bids":[],"asks":[{"price":0.00489281,"qty":0.51511447}],"checksum":136913992,"timestamp":"2024-06-01T18:06:54.913760Z"}]}
{"channel":"book","type":"update","data":[{"symbol":"LINK/ETH","bids":[],"asks":[{"price":0.00488215,"qty":0.00000000},{"price":0.00492132,"qty":283.29663722}],"checksum":1185895909,"timestamp":"2024-06-01T18:06:55.756419Z"}]}
{"channel":"book","type":"update","data":[{"symbol":"LINK/ETH","bids":[],"asks":[{"price":0.00488221,"qty":21.57331567}],"checksum":3216313495,"timestamp":"2024-06-01T18:06:56.054685Z"}]}
{"channel":"book","type":"update","data":[{"symbol":"LINK/ETH","bids":[],"asks":[{"price":0.00490372,"qty":0.00000000},{"price":0.00492132,"qty":283.29663722}],"checksum":3933478057,"timestamp":"2024-06-01T18:06:58.167697Z"}]}
{"channel":"book","type":"update","data":[{"symbol":"LINK/ETH","bids":[{"price":0.00487962,"qty":0.00000000},{"price":0.00486602,"qty":263.85422000}],"asks":[],"checksum":2559381905,"timestamp":"2024-06-01T18:06:58.167805Z"}]}
{"channel":"book","type":"update","data":[{"symbol":"LINK/ETH","bids":[],"asks":[{"price":0.00490371,"qty":131.75171000}],"checksum":2999995341,"timestamp":"2024-06-01T18:06:58.170500Z"}]}
{"channel":"book","type":"update","data":[{"symbol":"LINK/ETH","bids":[{"price":0.00487963,"qty":131.75171000}],"asks":[],"checksum":3410915185,"timestamp":"2024-06-01T18:06:58.170657Z"}]}
{"channel":"book","type":"update","data":[{"symbol":"LINK/ETH","bids":[{"price":0.00487759,"qty":0.00000000},{"price":0.00486602,"qty":263.85422000},{"price":0.00487891,"qty":7.38433569}],"asks":[],"checksum":3285930049,"timestamp":"2024-06-01T18:06:58.175254Z"}]}
{"channel":"book","type":"update","data":[{"symbol":"LINK/ETH","bids":[{"price":0.00487226,"qty":0.00000000},{"price":0.00486602,"qty":263.85422000}],"asks":[],"checksum":165111017,"timestamp":"2024-06-01T18:06:58.849033Z"}]}
{"channel":"book","type":"update","data":[{"symbol":"LINK/ETH","bids":[{"price":0.00486832,"qty":0.52183760}],"asks":[],"checksum":3759206095,"timestamp":"2024-06-01T18:06:58.923849Z"}]}
{"channel":"book","type":"update","data":[{"symbol":"LINK/ETH","bids":[],"asks":[{"price":0.00488221,"qty":0.00000000},{"price":0.00492132,"qty":283.29663722}],"checksum":3899242339,"timestamp":"2024-06-01T18:07:00.835152Z"}]}
{"channel":"book","type":"update","data":[{"symbol":"LINK/ETH","bids":[{"price":0.00487890,"qty":0.00000000},{"price":0.00486602,"qty":263.85422000}],"asks":[],"checksum":2793042321,"timestamp":"2024-06-01T18:07:00.884159Z"}]}
{"channel":"book","type":"update","data":[{"symbol":"LINK/ETH","bids":[{"price":0.00487929,"qty":26.97619806}],"asks":[],"checksum":3150687017,"timestamp":"2024-06-01T18:07:00.887506Z"}]}
{"channel":"book","type":"update","data":[{"symbol":"LINK/ETH","bids":[],"asks":[{"price":0.00488247,"qty":21.57426552}],"checksum":1152971385,"timestamp":"2024-06-01T18:07:01.113758Z"}]}
{"channel":"book","type":"update","data":[{"symbol":"LINK/ETH","bids":[],"asks":[{"price":0.00488247,"qty":0.00000000},{"price":0.00492132,"qty":283.29663722}],"checksum":3150687017,"timestamp":"2024-06-01T18:07:01.418026Z"}]}
{"channel":"book","type":"update","data":[{"symbol":"LINK/ETH","bids":[],"asks":[{"price":0.00488249,"qty":21.57426651}],"checksum":484150169,"timestamp":"2024-06-01T18:07:01.695222Z"}]}
{"channel":"book","type":"update","data":[{"symbol":"LINK/ETH","bids":[],"asks":[{"price":0.00488249,"qty":0.00000000},{"price":0.00492132,"qty":283.29663722}],"checksum":3150687017,"timestamp":"2024-06-01T18:07:02.365630Z"}]}
{"channel":"book","type":"update","data":[{"symbol":"LINK/ETH","bids":[],"asks":[{"price":0.00488248,"qty":21.57412818}],"checksum":2058248113,"timestamp":"2024-06-01T18:07:02.648814Z"}]}
{"channel":"book","type":"update","data":[{"symbol":"LINK/ETH","bids":[],"asks":[{"price":0.00488197,"qty":4.85418693}],"checksum":1966784002,"timestamp":"2024-06-01T18:07:03.362582Z"}]}
{"channel":"book","type":"update","data":[{"symbol":"LINK/ETH","bids":[{"price":0.00487929,"qty":0.00000000},{"price":0.00486602,"qty":263.85422000}],"asks":[],"checksum":168327620,"timestamp":"2024-06-01T18:07:03.396933Z"}]}
{"channel":"book","type":"update","data":[{"symbol":"LINK/ETH","bids":[{"price":0.00487890,"qty":26.97629234}],"asks":[],"checksum":3095880793,"timestamp":"2024-06-01T18:07:03.401339Z"}]}
{"channel":"book","type":"update","data":[{"symbol":"LINK/ETH","bids":[],"asks":[{"price":0.00488202,"qty":0.00000000},{"price":0.00490408,"qty":438.16674000}],"checksum":4233495668,"timestamp":"2024-06-01T18:07:03.936989Z"}]}
{"channel":"book","type":"update","data":[{"symbol":"LINK/ETH","bids":[],"asks":[{"price":0.00488180,"qty":8.08799098}],"checksum":1301003840,"timestamp":"2024-06-01T18:07:03.940331Z"}]}
{"channel":"book","type":"update","data":[{"symbol":"LINK/ETH","bids":[],"asks":[{"price":0.00488175,"qty":4.85459356}],"checksum":138563778,"timestamp":"2024-06-01T18:07:03.955713Z"}]}
{"channel":"book","type":"update","data":[{"symbol":"LINK/ETH","bids":[],"asks":[{"price":0.00488197,"qty":0.00000000},{"price":0.00490407,"qty":185.34589070}],"checksum":4069451864,"timestamp":"2024-06-01T18:07:03.957635Z"}]}
{"channel":"book","type":"update","data":[{"symbol":"LINK/ETH","bids":[],"asks":[{"price":0.00488180,"qty":0.00000000},{"price":0.00490408,"qty":438.16674000}],"checksum":1154172466,"timestamp":"2024-06-01T18:07:04.035831Z"}]}
{"channel":"book","type":"update","data":[{"symbol":"LINK/ETH","bids":[{"price":0.00487963,"qty":0.00000000},{"price":0.00486602,"qty":263.85422000}],"asks":[],"checksum":3594028231,"timestamp":"2024-06-01T18:07:04.051663Z"}]}
{"channel":"book","type":"update","data":[{"symbol":"LINK/ETH","bids":[],"asks":[{"price":0.00490371,"qty":0.00000000},{"price":0.00492132,"qty":283.29663722}],"checksum":4234534555,"timestamp":"2024-06-01T18:07:04.051749Z"}]}
{"channel":"book","type":"update","data":[{"symbol":"LINK/ETH","bids":[],"asks":[{"price":0.00492131,"qty":263.85422000}],"checksum":1196202763,"timestamp":"2024-06-01T18:07:04.054397Z"}]}
{"channel":"book","type":"update","data":[{"symbol":"LINK/ETH","bids":[],"asks":[{"price":0.00490370,"qty":131.75171000}],"checksum":1248050982,"timestamp":"2024-06-01T18:07:04.054437Z"}]}
{"channel":"book","type":"update","data":[{"symbol":"LINK/ETH","bids":[{"price":0.00487892,"qty":131.75171000}],"asks":[],"checksum":202795300,"timestamp":"2024-06-01T18:07:04.054465Z"}]}
{"channel":"book","type":"update","data":[{"symbol":"LINK/ETH","bids":[{"price":0.00487890,"qty":0.00000000},{"price":0.00486602,"qty":263.85422000}],"asks":[],"checksum":604562760,"timestamp":"2024-06-01T18:07:04.329157Z"}]}
{"channel":"book","type":"update","data":[{"symbol":"LINK/ETH","bids":[{"price":0.00487851,"qty":26.97806490}],"asks":[],"checksum":3763697590,"timestamp":"2024-06-01T18:07:05.780844Z"}]}
{"channel":"book","type":"update","data":[{"symbol":"LINK/ETH","bids":[],"asks":[{"price":0.00488164,"qty":8.08825035}],"checksum":2620199229,"timestamp":"2024-06-01T18:07:05.780933Z"}]}
{"channel":"book","type":"update","data":[{"symbol":"LINK/ETH","bids":[{"price":0.00487789,"qty":0.00000000},{"price":0.00486602,"qty":263.85422000}],"asks":[],"checksum":1303904780,"timestamp":"2024-06-01T18:07:06.559498Z"}]}
{"channel":"book","type":"update","data":[{"symbol":"LINK/ETH","bids":[{"price":0.00487656,"qty":26.98752565}],"asks":[],"checksum":1058077047,"timestamp":"2024-06-01T18:07:06.567066Z"}]}
{"channel":"book","type":"update","data":[{"symbol":"LINK/ETH","bids":[],"asks":[{"price":0.00488175,"qty":0.00000000},{"price":0.00490408,"qty":438.16674000}],"checksum":896654432,"timestamp":"2024-06-01T18:07:06.576454Z"}]}
{"channel":"book","type":"update","data":[{"symbol":"LINK/ETH","bids":[],"asks":[{"price":0.00488160,"qty":4.85433022}],"checksum":3326633204,"timestamp":"2024-06-01T18:07:06.576646Z"}]}
{"channel":"book","type":"update","data":[{"symbol":"LINK/ETH","bids":[],"asks":[{"price":0.00488164,"qty":0.00000000},{"price":0.00490408,"qty":438.16674000}],"checksum":1279099970,"timestamp":"2024-06-01T18:07:06.584500Z"}]}
{"channel":"book","type":"update","data":[{"symbol":"LINK/ETH","bids":[],"asks":[{"price":0.00488762,"qty":0.00000000},{"price":0.00492131,"qty":263.85422000}],"checksum":4117605382,"timestamp":"2024-06-01T18:07:06.632085Z"}]}
{"channel":"book","type":"update","data":[{"symbol":"LINK/ETH","bids":[],"asks":[{"price":0.00488303,"qty":8.08527902}],"checksum":1438860254,"timestamp":"2024-06-01T18:07:06.637804Z"}]}
{"channel":"book","type":"update","data":[{"symbol":"LINK/ETH","bids":[{"price":0.00487851,"qty":0.00000000},{"price":0.00486602,"qty":263.85422000}],"asks":[],"checksum":2321820637,"timestamp":"2024-06-01T18:07:06.644005Z"}]}
{"channel":"book","type":"update","data":[{"symbol":"LINK/ETH","bids":[{"price":0.00487862,"qty":0.00000000},{"price":0.00485739,"qty":336.87734579}],"asks":[],"checksum":3432551957,"timestamp":"2024-06-01T18:07:06.746174Z"}]}
{"channel":"book","type":"update","data":[{"symbol":"LINK/ETH","bids":[{"price":0.00487850,"qty":21.57435344}],"asks":[],"checksum":4080858104,"timestamp":"2024-06-01T18:07:07.050162Z"}]}
{"channel":"book","type":"update","data":[{"symbol":"LINK/ETH","bids":[],"asks":[{"price":0.00488160,"qty":0.00000000},{"price":0.00492131,"qty":263.85422000}],"checksum":1925139739,"timestamp":"2024-06-01T18:07:07.136016Z"}]}
{"channel":"book","type":"update","data":[{"symbol":"LINK/ETH","bids":[],"asks":[{"price":0.00488243,"qty":4.85358438}],"checksum":1715886743,"timestamp":"2024-06-01T18:07:07.139339Z"}]}
{"channel":"book","type":"update","data":[{"symbol":"LINK/ETH","bids":[],"asks":[{"price":0.00488144,"qty":8.08817602}],"checksum":3757562858,"timestamp":"2024-06-01T18:07:08.781049Z"}]}
{"channel":"book","type":"update","data":[{"symbol":"LINK/ETH","bids":[{"price":0.00487842,"qty":26.97568341}],"asks":[],"checksum":1622819248,"timestamp":"2024-06-01T18:07:08.781208Z"}]}
{"channel":"book","type":"update","data":[{"symbol":"LINK/ETH","bids":[],"asks":[{"price":0.00490370,"qty":0.00000000},{"price":0.00490408,"qty":438.16674000}],"checksum":2055427821,"timestamp":"2024-06-01T18:07:09.936231Z"}]}
{"channel":"book","type":"update","data":[{"symbol":"LINK/ETH","bids":[{"price":0.00487892,"qty":0.00000000},{"price":0.00486602,"qty":263.85422000}],"asks":[],"checksum":100890170,"timestamp":"2024-06-01T18:07:09.936293Z"}]}
{"channel":"book","type":"update","data":[{"symbol":"LINK/ETH","bids":[{"price":0.00487893,"qty":131.75171000}],"asks":[],"checksum":1910800233,"timestamp":"2024-06-01T18:07:09.939049Z"}]}
{"channel":"book","type":"update","data":[{"symbol":"LINK/ETH","bids":[],"asks":[{"price":0.00490369,"qty":131.75171000}],"checksum":717233330,"timestamp":"2024-06-01T18:07:09.939809Z"}]}
{"channel":"book","type":"update","data":[{"symbol":"LINK/ETH","bids":[],"asks":[{"price":0.00488144,"qty":0.00000000},{"price":0.00490408,"qty":438.16674000}],"checksum":3468518648,"timestamp":"2024-06-01T18:07:11.204605Z"}]}
{"channel":"book","type":"update","data":[{"symbol":"LINK/ETH","bids":[{"price":0.00487842,"qty":0.00000000},{"price":0.00486602,"qty":263.85422000}],"asks":[],"checksum":2807960941,"timestamp":"2024-06-01T18:07:11.204617Z"}]}
{"channel":"book","type":"update","data":[{"symbol":"LINK/ETH","bids":[],"asks":[{"price":0.00488303,"qty":0.00000000},{"price":0.00492130,"qty":283.29663722}],"checksum":2128641700,"timestamp":"2024-06-01T18:07:11.204734Z"}]}
{"channel":"book","type":"update","data":[{"symbol":"LINK/ETH","bids":[],"asks":[{"price":0.00488225,"qty":8.08738864}],"checksum":825115685,"timestamp":"2024-06-01T18:07:11.211363Z"}]}
{"channel":"book","type":"update","data":[{"symbol":"LINK/ETH","bids":[{"price":0.00487914,"qty":26.97511463}],"asks":[],"checksum":4044056588,"timestamp":"2024-06-01T18:07:11.211478Z"}]}
{"channel":"book","type":"update","data":[{"symbol":"LINK/ETH","bids":[],"asks":[{"price":0.00488679,"qty":8.07987306}],"checksum":2675399258,"timestamp":"2024-06-01T18:07:11.211493Z"}]}
{"channel":"book","type":"update","data":[{"symbol":"LINK/ETH","bids":[],"asks":[{"price":0.00488220,"qty":4.85369473}],"checksum":840166603,"timestamp":"2024-06-01T18:07:11.215699Z"}]}
{"channel":"book","type":"update","data":[{"symbol":"LINK/ETH","bids":[],"asks":[{"price":0.00488243,"qty":0.00000000},{"price":0.00490407,"qty":185.34589070}],"checksum":3569214913,"timestamp":"2024-06-01T18:07:11.215801Z"}]}
{"channel":"book","type":"update","data":[{"symbol":"LINK/ETH","bids":[{"price":0.00487919,"qty":4.85375290}],"asks":[],"checksum":3231447297,"timestamp":"2024-06-01T18:07:11.221120Z"}]}
{"channel":"book","type":"update","data":[{"symbol":"LINK/ETH","bids":[],"asks":[{"price":0.00488220,"qty":0.00000000},{"price":0.00490408,"qty":438.16674000}],"checksum":1389176223,"timestamp":"2024-06-01T18:07:11.221400Z"}]}
{"channel":"book","type":"update","data":[{"symbol":"LINK/ETH","bids":[{"price":0.00487914,"qty":0.00000000},{"price":0.00486607,"qty":42.57457429}],"asks":[],"checksum":2043627565,"timestamp":"2024-06-01T18:07:11.228660Z"}]}
{"channel":"book","type":"update","data":[{"symbol":"LINK/ETH","bids":[{"price":0.00487891,"qty":0.00000000},{"price":0.00486602,"qty":263.85422000},{"price":0.00487921,"qty":7.38388166}],"asks":[],"checksum":1488589270,"timestamp":"2024-06-01T18:07:11.232034Z"}]}
{"channel":"book","type":"update","data":[{"symbol":"LINK/ETH","bids":[{"price":0.00487926,"qty":4.85378609}],"asks":[],"checksum":3447350279,"timestamp":"2024-06-01T18:07:11.235361Z"}]}
{"channel":"book","type":"update","data":[{"symbol":"LINK/ETH","bids":[{"price":0.00487919,"qty":0.00000000},{"price":0.00486607,"qty":42.57457429}],"asks":[],"checksum":2547129764,"timestamp":"2024-06-01T18:07:11.235921Z"}]}
{"channel":"book","type":"update","data":[{"symbol":"LINK/ETH","bids":[{"price":0.00487926,"qty":0.00000000},{"price":0.00486602,"qty":263.85422000}],"asks":[],"checksum":3119563404,"timestamp":"2024-06-01T18:07:12.474907Z"}]}
{"channel":"book","type":"update","data":[{"symbol":"LINK/ETH","bids":[],"asks":[{"price":0.00488221,"qty":4.85461586}],"checksum":1769539290,"timestamp":"2024-06-01T18:07:12.477285Z"}]}
{"channel":"book","type":"update","data":[{"symbol":"LINK/ETH","bids":[],"asks":[{"price":0.00488225,"qty":0.00000000},{"price":0.00490408,"qty":438.16674000}],"checksum":3790713629,"timestamp":"2024-06-01T18:07:12.481665Z"}]}
{"channel":"book","type":"update","data":[{"symbol":"LINK/ETH","bids":[{"price":0.00487877,"qty":26.97790545}],"asks":[],"checksum":946631961,"timestamp":"2024-06-01T18:07:13.780932Z"}]}
{"channel":"book","type":"update","data":[{"symbol":"LINK/ETH","bids":[],"asks":[{"price":0.00488189,"qty":8.08820767}],"checksum":1522827468,"timestamp":"2024-06-01T18:07:13.781106Z"}]}
{"channel":"book","type":"update","data":[{"symbol":"LINK/ETH","bids":[],"asks":[{"price":0.00488184,"qty":4.85500345}],"checksum":2850364407,"timestamp":"2024-06-01T18:07:13.784070Z"}]}
{"channel":"book","type":"update","data":[{"symbol":"LINK/ETH","bids":[],"asks":[{"price":0.00488221,"qty":0.00000000},{"price":0.00490407,"qty":185.34589070}],"checksum":303869174,"timestamp":"2024-06-01T18:07:13.786830Z"}]}
{"channel":"book","type":"update","data":[{"symbol":"LINK/ETH","bids":[],"asks":[{"price":0.00488189,"qty":0.00000000},{"price":0.00490408,"qty":438.16674000}],"checksum":373144410,"timestamp":"2024-06-01T18:07:13.789615Z"}]}
{"channel":"book","type":"update","data":[{"symbol":"LINK/ETH","bids":[{"price":0.00487893,"qty":0.00000000},{"price":0.00486602,"qty":263.85422000}],"asks":[],"checksum":2420551413,"timestamp":"2024-06-01T18:07:13.862159Z"}]}
{"channel":"book","type":"update","data":[{"symbol":"LINK/ETH","bids":[{"price":0.00487746,"qty":0.00000000},{"price":0.00485739,"qty":336.87734579}],"asks":[],"checksum":3921142661,"timestamp":"2024-06-01T18:07:13.862209Z"}]}
{"channel":"book","type":"update","data":[{"symbol":"LINK/ETH","bids":[{"price":0.00487476,"qty":0.00000000},{"price":0.00484534,"qty":63.11535592}],"asks":[],"checksum":1086292824,"timestamp":"2024-06-01T18:07:13.863037Z"}]}
{"channel":"book","type":"update","data":[{"symbol":"LINK/ETH","bids":[{"price":0.00487454,"qty":71.53689000}],"asks":[],"checksum":1972994785,"timestamp":"2024-06-01T18:07:13.865036Z"}]}
{"channel":"book","type":"update","data":[{"symbol":"LINK/ETH","bids":[{"price":0.00487429,"qty":131.75171000}],"asks":[],"checksum":995815183,"timestamp":"2024-06-01T18:07:13.865206Z"}]}
{"channel":"book","type":"update","data":[{"symbol":"LINK/ETH","bids":[{"price":0.00486833,"qty":438.16674000}],"asks":[],"checksum":172644963,"timestamp":"2024-06-01T18:07:13.865578Z"}]}
{"channel":"book","type":"update","data":[{"symbol":"LINK/ETH","bids":[{"price":0.00487877,"qty":0.00000000},{"price":0.00485739,"qty":336.87734579}],"asks":[],"checksum":1428053655,"timestamp":"2024-06-01T18:07:13.867553Z"}]}
{"channel":"book","type":"update","data":[{"symbol":"LINK/ETH","bids":[],"asks":[{"price":0.00488679,"qty":0.00000000},{"price":0.00492129,"qty":263.85422000}],"checksum":4282960623,"timestamp":"2024-06-01T18:07:13.867666Z"}]}
{"channel":"book","type":"update","data":[{"symbol":"LINK/ETH","bids":[{"price":0.00485740,"qty":263.85422000}],"asks":[],"checksum":1274306190,"timestamp":"2024-06-01T18:07:13.868948Z"}]}
{"channel":"book","type":"update","data":[{"symbol":"LINK/ETH","bids":[{"price":0.00487656,"qty":0.00000000},{"price":0.00485739,"qty":336.87734579}],"asks":[],"checksum":3231499651,"timestamp":"2024-06-01T18:07:13.870317Z"}]}
{"channel":"book","type":"update","data":[{"symbol":"LINK/ETH","bids":[{"price":0.00487238,"qty":27.01294510}],"asks":[],"checksum":1736340720,"timestamp":"2024-06-01T18:07:13.875999Z"}]}
{"channel":"book","type":"update","data":[{"symbol":"LINK/ETH","bids":[{"price":0.00486834,"qty":42.55472269}],"asks":[],"checksum":3291389750,"timestamp":"2024-06-01T18:07:13.880569Z"}]}
{"channel":"book","type":"update","data":[{"symbol":"LINK/ETH","bids":[{"price":0.00486607,"qty":0.00000000},{"price":0.00485740,"qty":263.85422000}],"asks":[],"checksum":443812532,"timestamp":"2024-06-01T18:07:13.880860Z"}]}
{"channel":"book","type":"update","data":[{"symbol":"LINK/ETH","bids":[{"price":0.00487921,"qty":0.00000000},{"price":0.00485739,"qty":336.87734579}],"asks":[],"checksum":967218079,"timestamp":"2024-06-01T18:07:13.889326Z"}]}
{"channel":"book","type":"update","data":[{"symbol":"LINK/ETH","bids":[{"price":0.00485740,"qty":1073.00727633}],"asks":[],"checksum":2390196593,"timestamp":"2024-06-01T18:07:13.922321Z"}]}
{"channel":"book","type":"update","data":[{"symbol":"LINK/ETH","bids":[{"price":0.00487850,"qty":0.00000000},{"price":0.00485010,"qty":5.86013547}],"asks":[],"checksum":691426390,"timestamp":"2024-06-01T18:07:13.990165Z"}]}
{"channel":"book","type":"update","data":[{"symbol":"LINK/ETH","bids":[{"price":0.00487459,"qty":4.85702548}],"asks":[],"checksum":1527852003,"timestamp":"2024-06-01T18:07:13.993486Z"}]}
{"channel":"book","type":"update","data":[{"symbol":"LINK/ETH","bids":[],"asks":[{"price":0.00492129,"qty":0.00000000},{"price":0.00492130,"qty":283.29663722}],"checksum":1778279244,"timestamp":"2024-06-01T18:07:13.993566Z"}]}
{"channel":"book","type":"update","data":[{"symbol":"LINK/ETH","bids":[{"price":0.00487454,"qty":0.00000000},{"price":0.00485010,"qty":5.86013547}],"asks":[],"checksum":523015456,"timestamp":"2024-06-01T18:07:13.993615Z"}]}
{"channel":"book","type":"update","data":[{"symbol":"LINK/ETH","bids":[{"price":0.00487428,"qty":0.00000000},{"price":0.00484534,"qty":63.11535592}],"asks":[],"checksum":930121377,"timestamp":"2024-06-01T18:07:13.994090Z"}]}
{"channel":"book","type":"update","data":[{"symbol":"LINK/ETH","bids":[],"asks":[{"price":0.00492128,"qty":263.85422000}],"checksum":3754213146,"timestamp":"2024-06-01T18:07:13.997171Z"}]}
{"channel":"book","type":"update","data":[{"symbol":"LINK/ETH","bids":[{"price":0.00487168,"qty":71.53689000}],"asks":[],"checksum":3169346987,"timestamp":"2024-06-01T18:07:13.998329Z"}]}
{"channel":"book","type":"update","data":[{"symbol":"LINK/ETH","bids":[{"price":0.00487497,"qty":26.99857140}],"asks":[],"checksum":328474488,"timestamp":"2024-06-01T18:07:13.998358Z"}]}
{"channel":"book","type":"update","data":[{"symbol":"LINK/ETH","bids":[{"price":0.00487490,"qty":7.39040990}],"asks":[],"checksum":279225679,"timestamp":"2024-06-01T18:07:13.998581Z"}]}
{"channel":"book","type":"update","data":[{"symbol":"LINK/ETH","bids":[{"price":0.00487502,"qty":4.85702548}],"asks":[],"checksum":2160389301,"timestamp":"2024-06-01T18:07:14.002008Z"}]}
{"channel":"book","type":"update","data":[{"symbol":"LINK/ETH","bids":[{"price":0.00487459,"qty":0.00000000},{"price":0.00485740,"qty":1073.00727633}],"asks":[],"checksum":3014355986,"timestamp":"2024-06-01T18:07:14.002361Z"}]}
{"channel":"book","type":"update","data":[{"symbol":"LINK/ETH","bids":[{"price":0.00487503,"qty":21.58444645}],"asks":[],"checksum":92153426,"timestamp":"2024-06-01T18:07:14.292223Z"}]}
{"channel":"book","type":"update","data":[{"symbol":"LINK/ETH","bids":[{"price":0.00487508,"qty":4.85710428}],"asks":[],"checksum":764753330,"timestamp":"2024-06-01T18:07:14.295027Z"}]}
{"channel":"book","type":"update","data":[{"symbol":"LINK/ETH","bids":[{"price":0.00487502,"qty":0.00000000},{"price":0.00486832,"qty":0.52183760}],"asks":[],"checksum":4224113733,"timestamp":"2024-06-01T18:07:14.295518Z"}]}
{"channel":"book","type":"update","data":[{"symbol":"LINK/ETH","bids":[{"price":0.00487497,"qty":0.00000000},{"price":0.00485740,"qty":1073.00727633}],"asks":[],"checksum":255994544,"timestamp":"2024-06-01T18:07:14.296477Z"}]}
{"channel":"book","type":"update","data":[{"symbol":"LINK/ETH","bids":[{"price":0.00487429,"qty":0.00000000},{"price":0.00485739,"qty":336.87734579}],"asks":[],"checksum":2591448825,"timestamp":"2024-06-01T18:07:14.683906Z"}]}
{"channel":"book","type":"update","data":[{"symbol":"LINK/ETH","bids":[],"asks":[{"price":0.00492128,"qty":0.00000000},{"price":0.00492130,"qty":283.29663722}],"checksum":2526795454,"timestamp":"2024-06-01T18:07:14.684079Z"}]}
{"channel":"book","type":"update","data":[{"symbol":"LINK/ETH","bids":[{"price":0.00487239,"qty":131.75171000}],"asks":[],"checksum":1974693339,"timestamp":"2024-06-01T18:07:14.686706Z"}]}
{"channel":"book","type":"update","data":[{"symbol":"LINK/ETH","bids":[],"asks":[{"price":0.00492127,"qty":263.85422000}],"checksum":773651583,"timestamp":"2024-06-01T18:07:14.687032Z"}]}
{"channel":"book","type":"update","data":[{"symbol":"LINK/ETH","bids":[],"asks":[{"price":0.00487960,"qty":8.09235029}],"checksum":601606248,"timestamp":"2024-06-01T18:07:15.638676Z"}]}
{"channel":"book","type":"update","data":[{"symbol":"LINK/ETH","bids":[{"price":0.00487598,"qty":26.99447705}],"asks":[],"checksum":226593463,"timestamp":"2024-06-01T18:07:15.638700Z"}]}
{"channel":"book","type":"update","data":[{"symbol":"LINK/ETH","bids":[{"price":0.00487504,"qty":26.99880347}],"asks":[],"checksum":2224385650,"timestamp":"2024-06-01T18:07:15.638756Z"}]}
{"channel":"book","type":"update","data":[{"symbol":"LINK/ETH","bids":[{"price":0.00487239,"qty":0.00000000},{"price":0.00486832,"qty":0.52183760}],"asks":[],"checksum":1572409001,"timestamp":"2024-06-01T18:07:15.641812Z"}]}
{"channel":"book","type":"update","data":[{"symbol":"LINK/ETH","bids":[{"price":0.00487598,"qty":31.85137232}],"asks":[],"checksum":2028540135,"timestamp":"2024-06-01T18:07:15.641883Z"}]}
{"channel":"book","type":"update","data":[{"symbol":"LINK/ETH","bids":[{"price":0.00487508,"qty":0.00000000},{"price":0.00485740,"qty":1073.00727633}],"asks":[],"checksum":2897550247,"timestamp":"2024-06-01T18:07:15.641899Z"}]}
{"channel":"book","type":"update","data":[{"symbol":"LINK/ETH","bids":[{"price":0.00487240,"qty":131.75171000}],"asks":[],"checksum":3133563102,"timestamp":"2024-06-01T18:07:15.644570Z"}]}
{"channel":"book","type":"update","data":[{"symbol":"LINK/ETH","bids":[],"asks":[{"price":0.00487960,"qty":0.00000000},{"price":0.00492126,"qty":263.85422000}],"checksum":2237637060,"timestamp":"2024-06-01T18:07:16.247966Z"}]}
{"channel":"book","type":"update","data":[{"symbol":"LINK/ETH","bids":[],"asks":[{"price":0.00492126,"qty":0.00000000},{"price":0.00492130,"qty":283.29663722}],"checksum":1638396139,"timestamp":"2024-06-01T18:07:16.251205Z"}]}
{"channel":"book","type":"update","data":[{"symbol":"LINK/ETH","bids":[{"price":0.00487240,"qty":0.00000000},{"price":0.00485740,"qty":1073.00727633}],"asks":[],"checksum":4208836116,"timestamp":"2024-06-01T18:07:16.251339Z"}]}
{"channel":"book","type":"update","data":[{"symbol":"LINK/ETH","bids":[],"asks":[{"price":0.00492125,"qty":263.85422000}],"checksum":2604105897,"timestamp":"2024-06-01T18:07:16.253926Z"}]}
