{"channel":"book","type":"snapshot","data":[{"symbol":"LINK/JPY","bids":[{"price":2916.6,"qty":8.08938490},{"price":2916.5,"qty":42.88900000},{"price":2909.5,"qty":42.76311737},{"price":2909.4,"qty":80.33850000},{"price":2909.2,"qty":219.16400000},{"price":2907.1,"qty":11235.50258512},{"price":2906.5,"qty":167.16150000},{"price":2894.5,"qty":108.24000000},{"price":2891.2,"qty":108.24000000},{"price":2890.4,"qty":3369.68122851}],"asks":[{"price":2923.5,"qty":8.08298531},{"price":2923.6,"qty":42.88900000},{"price":2926.8,"qty":70.52987272},{"price":2926.9,"qty":80.33850000},{"price":2936.9,"qty":219.16400000},{"price":2937.3,"qty":167.16150000},{"price":2946.0,"qty":108.24000000},{"price":2946.6,"qty":3341.62023423},{"price":2952.3,"qty":108.24000000},{"price":2995.1,"qty":53.74600000}],"checksum":1008655219}]}
{"channel":"book","type":"update","data":[{"symbol":"LINK/JPY","bids":[],"asks":[{"price":2995.1,"qty":0.00000000},{"price":2995.5,"qty":0.38927275}],"checksum":3845781035,"timestamp":"2024-06-01T18:07:00.313954Z"}]}
{"channel":"book","type":"update","data":[{"symbol":"LINK/JPY","bids":[{"price":2909.4,"qty":0.00000000},{"price":2852.8,"qty":27.45050000}],"asks":[],"checksum":1734824065,"timestamp":"2024-06-01T18:07:00.314058Z"}]}
{"channel":"book","type":"update","data":[{"symbol":"LINK/JPY","bids":[],"asks":[{"price":2936.9,"qty":0.00000000},{"price":2995.9,"qty":27.45050000}],"checksum":4041019031,"timestamp":"2024-06-01T18:07:00.314197Z"}]}
{"channel":"book","type":"update","data":[{"symbol":"LINK/JPY","bids":[],"asks":[{"price":2937.2,"qty":2.45489792}],"checksum":651417036,"timestamp":"2024-06-01T18:07:00.316003Z"}]}
{"channel":"book","type":"update","data":[{"symbol":"LINK/JPY","bids":[],"asks":[{"price":2995.0,"qty":53.74600000}],"checksum":3281916098,"timestamp":"2024-06-01T18:07:00.316633Z"}]}
{"channel":"book","type":"update","data":[{"symbol":"LINK/JPY","bids":[{"price":2909.6,"qty":80.33850000}],"asks":[],"checksum":770693551,"timestamp":"2024-06-01T18:07:00.316960Z"}]}
{"channel":"book","type":"update","data":[{"symbol":"LINK/JPY","bids":[],"asks":[{"price":2936.8,"qty":219.16400000}],"checksum":3294040873,"timestamp":"2024-06-01T18:07:00.317214Z"}]}
{"channel":"book","type":"update","data":[{"symbol":"LINK/JPY","bids":[{"price":2909.7,"qty":42.76017802}],"asks":[],"checksum":874458157,"timestamp":"2024-06-01T18:07:00.336651Z"}]}
{"channel":"book","type":"update","data":[{"symbol":"LINK/JPY","bids":[{"price":2909.5,"qty":0.00000000},{"price":2890.4,"qty":3369.68122851}],"asks":[],"checksum":493808033,"timestamp":"2024-06-01T18:07:00.336831Z"}]}
{"channel":"book","type":"update","data":[{"symbol":"LINK/JPY","bids":[],"asks":[{"price":2937.2,"qty":0.00000000},{"price":2995.0,"qty":53.74600000}],"checksum":3914265815,"timestamp":"2024-06-01T18:07:03.838443Z"}]}
{"channel":"book","type":"update","data":[{"symbol":"LINK/JPY","bids":[],"asks":[{"price":2936.8,"qty":0.00000000},{"price":2995.5,"qty":0.38927275}],"checksum":3962330443,"timestamp":"2024-06-01T18:07:06.198138Z"}]}
{"channel":"book","type":"update","data":[{"symbol":"LINK/JPY","bids":[],"asks":[{"price":2995.0,"qty":0.00000000},{"price":2995.9,"qty":27.45050000}],"checksum":3348446578,"timestamp":"2024-06-01T18:07:06.198239Z"}]}
{"channel":"book","type":"update","data":[{"symbol":"LINK/JPY","bids":[],"asks":[{"price":2937.2,"qty":2.45489792}],"checksum":295429673,"timestamp":"2024-06-01T18:07:06.200875Z"}]}
{"channel":"book","type":"update","data":[{"symbol":"LINK/JPY","bids":[],"asks":[{"price":2937.2,"qty":221.61889792}],"checksum":2474256722,"timestamp":"2024-06-01T18:07:06.200995Z"}]}
{"channel":"book","type":"update","data":[{"symbol":"LINK/JPY","bids":[],"asks":[{"price":2995.4,"qty":53.74600000}],"checksum":3375922489,"timestamp":"2024-06-01T18:07:06.201035Z"}]}
{"channel":"book","type":"update","data":[{"symbol":"LINK/JPY","bids":[],"asks":[{"price":2946.6,"qty":0.00000000},{"price":2995.5,"qty":0.38927275}],"checksum":2096179523,"timestamp":"2024-06-01T18:07:06.682554Z"}]}
{"channel":"book","type":"update","data":[{"symbol":"LINK/JPY","bids":[],"asks":[{"price":2946.2,"qty":3338.73494482}],"checksum":2847225168,"timestamp":"2024-06-01T18:07:06.723058Z"}]}
{"channel":"book","type":"update","data":[{"symbol":"LINK/JPY","bids":[],"asks":[{"price":2937.2,"qty":219.16400000},{"price":2937.1,"qty":2.45498150}],"checksum":1820445240,"timestamp":"2024-06-01T18:07:08.587878Z"}]}
{"channel":"book","type":"update","data":[{"symbol":"LINK/JPY","bids":[],"asks":[{"price":2937.1,"qty":0.00000000},{"price":2995.4,"qty":53.74600000}],"checksum":4130753925,"timestamp":"2024-06-01T18:07:11.707340Z"}]}
{"channel":"book","type":"update","data":[{"symbol":"LINK/JPY","bids":[],"asks":[{"price":2995.4,"qty":0.00000000},{"price":2995.5,"qty":0.38927275}],"checksum":2925300967,"timestamp":"2024-06-01T18:07:12.082565Z"}]}
{"channel":"book","type":"update","data":[{"symbol":"LINK/JPY","bids":[],"asks":[{"price":2937.2,"qty":0.00000000},{"price":2995.9,"qty":27.45050000}],"checksum":353259554,"timestamp":"2024-06-01T18:07:12.082714Z"}]}
{"channel":"book","type":"update","data":[{"symbol":"LINK/JPY","bids":[{"price":2909.6,"qty":0.00000000},{"price":2852.8,"qty":27.45050000}],"asks":[],"checksum":584167517,"timestamp":"2024-06-01T18:07:12.082776Z"}]}
{"channel":"book","type":"update","data":[{"symbol":"LINK/JPY","bids":[],"asks":[{"price":2937.1,"qty":219.16400000}],"checksum":2031508554,"timestamp":"2024-06-01T18:07:12.085268Z"}]}
{"channel":"book","type":"update","data":[{"symbol":"LINK/JPY","bids":[],"asks":[{"price":2995.3,"qty":53.74600000}],"checksum":2614935844,"timestamp":"2024-06-01T18:07:12.085301Z"}]}
{"channel":"book","type":"update","data":[{"symbol":"LINK/JPY","bids":[{"price":2909.8,"qty":80.33850000}],"asks":[],"checksum":372671422,"timestamp":"2024-06-01T18:07:12.085506Z"}]}
{"channel":"book","type":"update","data":[{"symbol":"LINK/JPY","bids":[],"asks":[{"price":2937.0,"qty":2.45498321}],"checksum":1180905420,"timestamp":"2024-06-01T18:07:12.090158Z"}]}
{"channel":"book","type":"update","data":[{"symbol":"LINK/JPY","bids":[{"price":2909.7,"qty":0.00000000},{"price":2853.0,"qty":53.74600000}],"asks":[],"checksum":3131592356,"timestamp":"2024-06-01T18:07:12.100453Z"}]}
{"channel":"book","type":"update","data":[{"symbol":"LINK/JPY","bids":[{"price":2909.9,"qty":42.75723908}],"asks":[],"checksum":2872695941,"timestamp":"2024-06-01T18:07:12.100519Z"}]}
{"channel":"book","type":"update","data":[{"symbol":"LINK/JPY","bids":[{"price":2906.5,"qty":0.00000000},{"price":2853.0,"qty":53.74600000}],"asks":[],"checksum":3899370307,"timestamp":"2024-06-01T18:07:13.862006Z"}]}
{"channel":"book","type":"update","data":[{"symbol":"LINK/JPY","bids":[{"price":2916.5,"qty":0.00000000},{"price":2852.8,"qty":27.45050000}],"asks":[],"checksum":3840994308,"timestamp":"2024-06-01T18:07:13.862082Z"}]}
{"channel":"book","type":"update","data":[{"symbol":"LINK/JPY","bids":[],"asks":[{"price":2937.1,"qty":0.00000000},{"price":2995.3,"qty":53.74600000}],"checksum":3336769645,"timestamp":"2024-06-01T18:07:13.862181Z"}]}
{"channel":"book","type":"update","data":[{"symbol":"LINK/JPY","bids":[],"asks":[{"price":2923.6,"qty":0.00000000},{"price":2995.5,"qty":0.38927275}],"checksum":2914732468,"timestamp":"2024-06-01T18:07:13.862227Z"}]}
{"channel":"book","type":"update","data":[{"symbol":"LINK/JPY","bids":[],"asks":[{"price":2926.9,"qty":0.00000000},{"price":2995.9,"qty":27.45050000}],"checksum":756152020,"timestamp":"2024-06-01T18:07:13.862238Z"}]}
{"channel":"book","type":"update","data":[{"symbol":"LINK/JPY","bids":[{"price":2853.0,"qty":0.00000000},{"price":2852.4,"qty":4.27881707}],"asks":[],"checksum":1923314959,"timestamp":"2024-06-01T18:07:13.862306Z"}]}
{"channel":"book","type":"update","data":[{"symbol":"LINK/JPY","bids":[],"asks":[{"price":2995.3,"qty":0.00000000},{"price":3015.1,"qty":27.45050000}],"checksum":316281331,"timestamp":"2024-06-01T18:07:13.862325Z"}]}
{"channel":"book","type":"update","data":[{"symbol":"LINK/JPY","bids":[{"price":2894.6,"qty":167.16150000}],"asks":[],"checksum":3283025028,"timestamp":"2024-06-01T18:07:13.864684Z"}]}
{"channel":"book","type":"update","data":[{"symbol":"LINK/JPY","bids":[],"asks":[{"price":2937.2,"qty":219.16400000}],"checksum":2703496897,"timestamp":"2024-06-01T18:07:13.864913Z"}]}
{"channel":"book","type":"update","data":[{"symbol":"LINK/JPY","bids":[{"price":2911.9,"qty":42.88900000}],"asks":[],"checksum":2657963757,"timestamp":"2024-06-01T18:07:13.864953Z"}]}
{"channel":"book","type":"update","data":[{"symbol":"LINK/JPY","bids":[],"asks":[{"price":2937.1,"qty":80.33850000}],"checksum":1581265002,"timestamp":"2024-06-01T18:07:13.864972Z"}]}
{"channel":"book","type":"update","data":[{"symbol":"LINK/JPY","bids":[],"asks":[{"price":2927.1,"qty":42.88900000}],"checksum":415898806,"timestamp":"2024-06-01T18:07:13.865137Z"}]}
{"channel":"book","type":"update","data":[{"symbol":"LINK/JPY","bids":[],"asks":[{"price":2926.8,"qty":0.00000000},{"price":2995.4,"qty":53.74600000}],"checksum":476940962,"timestamp":"2024-06-01T18:07:13.867679Z"}]}
{"channel":"book","type":"update","data":[{"symbol":"LINK/JPY","bids":[],"asks":[{"price":2936.9,"qty":70.52987272}],"checksum":1878683082,"timestamp":"2024-06-01T18:07:13.867711Z"}]}
{"channel":"book","type":"update","data":[{"symbol":"LINK/JPY","bids":[],"asks":[{"price":2936.9,"qty":0.00000000},{"price":2995.4,"qty":53.74600000}],"checksum":476940962,"timestamp":"2024-06-01T18:07:13.880682Z"}]}
{"channel":"book","type":"update","data":[{"symbol":"LINK/JPY","bids":[],"asks":[{"price":2927.0,"qty":70.52987272}],"checksum":3165377427,"timestamp":"2024-06-01T18:07:13.880708Z"}]}
{"channel":"book","type":"update","data":[{"symbol":"LINK/JPY","bids":[{"price":2916.6,"qty":0.00000000},{"price":2852.9,"qty":53.74600000}],"asks":[],"checksum":743942158,"timestamp":"2024-06-01T18:07:13.973306Z"}]}
{"channel":"book","type":"update","data":[{"symbol":"LINK/JPY","bids":[],"asks":[{"price":2927.1,"qty":0.00000000},{"price":2995.4,"qty":53.74600000}],"checksum":3644110293,"timestamp":"2024-06-01T18:07:13.976431Z"}]}
{"channel":"book","type":"update","data":[{"symbol":"LINK/JPY","bids":[{"price":2911.9,"qty":0.00000000},{"price":2852.8,"qty":27.45050000}],"asks":[],"checksum":3896343801,"timestamp":"2024-06-01T18:07:13.976591Z"}]}
{"channel":"book","type":"update","data":[{"symbol":"LINK/JPY","bids":[{"price":2894.6,"qty":0.00000000},{"price":2852.4,"qty":4.27881707}],"asks":[],"checksum":1080197342,"timestamp":"2024-06-01T18:07:13.976677Z"}]}
{"channel":"book","type":"update","data":[{"symbol":"LINK/JPY","bids":[],"asks":[{"price":2937.2,"qty":0.00000000},{"price":2995.5,"qty":0.38927275}],"checksum":394385884,"timestamp":"2024-06-01T18:07:13.976712Z"}]}
{"channel":"book","type":"update","data":[{"symbol":"LINK/JPY","bids":[],"asks":[{"price":2937.1,"qty":0.00000000},{"price":2995.9,"qty":27.45050000}],"checksum":2988873056,"timestamp":"2024-06-01T18:07:13.976725Z"}]}
{"channel":"book","type":"update","data":[{"symbol":"LINK/JPY","bids":[],"asks":[{"price":2995.4,"qty":0.00000000},{"price":3015.1,"qty":27.45050000}],"checksum":3942299952,"timestamp":"2024-06-01T18:07:13.976770Z"}]}
{"channel":"book","type":"update","data":[{"symbol":"LINK/JPY","bids":[{"price":2894.7,"qty":167.16150000}],"asks":[],"checksum":3080514449,"timestamp":"2024-06-01T18:07:13.979125Z"}]}
{"channel":"book","type":"update","data":[{"symbol":"LINK/JPY","bids":[],"asks":[{"price":2922.5,"qty":42.88900000}],"checksum":2375098790,"timestamp":"2024-06-01T18:07:13.979199Z"}]}
{"channel":"book","type":"update","data":[{"symbol":"LINK/JPY","bids":[],"asks":[{"price":2936.9,"qty":219.16400000}],"checksum":3417895316,"timestamp":"2024-06-01T18:07:13.979288Z"}]}
{"channel":"book","type":"update","data":[{"symbol":"LINK/JPY","bids":[{"price":2913.9,"qty":42.88900000}],"asks":[],"checksum":2383511188,"timestamp":"2024-06-01T18:07:13.979471Z"}]}
{"channel":"book","type":"update","data":[{"symbol":"LINK/JPY","bids":[],"asks":[{"price":2995.3,"qty":53.74600000}],"checksum":2108871221,"timestamp":"2024-06-01T18:07:13.979530Z"}]}
{"channel":"book","type":"update","data":[{"symbol":"LINK/JPY","bids":[{"price":2909.8,"qty":0.00000000},{"price":2852.8,"qty":27.45050000}],"asks":[],"checksum":322074681,"timestamp":"2024-06-01T18:07:13.979867Z"}]}
{"channel":"book","type":"update","data":[{"symbol":"LINK/JPY","bids":[],"asks":[{"price":2926.9,"qty":80.33850000}],"checksum":4000038110,"timestamp":"2024-06-01T18:07:13.979879Z"}]}
{"channel":"book","type":"update","data":[{"symbol":"LINK/JPY","bids":[{"price":2910.0,"qty":80.33850000}],"asks":[],"checksum":3288144101,"timestamp":"2024-06-01T18:07:13.982544Z"}]}
{"channel":"book","type":"update","data":[{"symbol":"LINK/JPY","bids":[{"price":2909.9,"qty":0.00000000},{"price":2852.8,"qty":27.45050000}],"asks":[],"checksum":2638257019,"timestamp":"2024-06-01T18:07:13.986823Z"}]}
{"channel":"book","type":"update","data":[{"symbol":"LINK/JPY","bids":[],"asks":[{"price":2927.0,"qty":0.00000000},{"price":2995.3,"qty":53.74600000}],"checksum":1951947433,"timestamp":"2024-06-01T18:07:13.986842Z"}]}
{"channel":"book","type":"update","data":[{"symbol":"LINK/JPY","bids":[],"asks":[{"price":2926.8,"qty":70.52987272}],"checksum":265087238,"timestamp":"2024-06-01T18:07:13.986903Z"}]}
{"channel":"book","type":"update","data":[{"symbol":"LINK/JPY","bids":[{"price":2910.1,"qty":42.75430053}],"asks":[],"checksum":816549819,"timestamp":"2024-06-01T18:07:13.987056Z"}]}
{"channel":"book","type":"update","data":[{"symbol":"LINK/JPY","bids":[{"price":2914.0,"qty":8.09660260}],"asks":[],"checksum":346482534,"timestamp":"2024-06-01T18:07:14.006848Z"}]}
{"channel":"book","type":"update","data":[{"symbol":"LINK/JPY","bids":[],"asks":[{"price":2923.5,"qty":0.00000000},{"price":2995.3,"qty":53.74600000},{"price":2922.4,"qty":8.08298531}],"checksum":360798135,"timestamp":"2024-06-01T18:07:14.032633Z"}]}
{"channel":"book","type":"update","data":[{"symbol":"LINK/JPY","bids":[],"asks":[{"price":2937.0,"qty":0.00000000},{"price":2995.3,"qty":53.74600000},{"price":2936.8,"qty":2.45515040}],"checksum":2459372160,"timestamp":"2024-06-01T18:07:14.487815Z"}]}
{"channel":"book","type":"update","data":[{"symbol":"LINK/JPY","bids":[{"price":2907.1,"qty":0.00000000},{"price":2852.9,"qty":53.74600000}],"asks":[],"checksum":994155477,"timestamp":"2024-06-01T18:07:15.125652Z"}]}
{"channel":"book","type":"update","data":[{"symbol":"LINK/JPY","bids":[{"price":2905.7,"qty":11241.66446195}],"asks":[],"checksum":1453638271,"timestamp":"2024-06-01T18:07:15.165766Z"}]}
