{"channel":"book","type":"snapshot","data":[{"symbol":"LINK/USDT","bids":[{"price":18.55870,"qty":80.89202077},{"price":18.55517,"qty":9.40000000},{"price":18.55505,"qty":243.48672997},{"price":18.55504,"qty":53.93919225},{"price":18.55251,"qty":40.44601038},{"price":18.54965,"qty":50.01000000},{"price":18.54925,"qty":134.88990125},{"price":18.54840,"qty":33.73844400},{"price":18.54800,"qty":20.65302732},{"price":18.54205,"qty":48.75805200}],"asks":[{"price":18.55873,"qty":9.00000000},{"price":18.55876,"qty":16.17851987},{"price":18.56313,"qty":4.85421040},{"price":18.56453,"qty":9.40000000},{"price":18.56519,"qty":40.43225616},{"price":18.56541,"qty":65.00000000},{"price":18.56739,"qty":50.01000000},{"price":18.57000,"qty":33.73844400},{"price":18.57193,"qty":243.48672997},{"price":18.57459,"qty":80.82295392}],"checksum":3586500605}]}
{"channel":"book","type":"update","data":[{"symbol":"LINK/USDT","bids":[{"price":18.55870,"qty":0.00000000},{"price":18.54204,"qty":269.88270992}],"asks":[],"checksum":1500123736,"timestamp":"2024-06-01T18:06:52.149612Z"}]}
{"channel":"book","type":"update","data":[{"symbol":"LINK/USDT","bids":[{"price":18.55251,"qty":0.00000000},{"price":18.53634,"qty":68.73000000}],"asks":[],"checksum":1037730228,"timestamp":"2024-06-01T18:06:52.522391Z"}]}
{"channel":"book","type":"update","data":[{"symbol":"LINK/USDT","bids":[{"price":18.55267,"qty":40.44601038}],"asks":[],"checksum":180607655,"timestamp":"2024-06-01T18:06:52.562646Z"}]}
{"channel":"book","type":"update","data":[{"symbol":"LINK/USDT","bids":[{"price":18.55267,"qty":0.00000000},{"price":18.53634,"qty":68.73000000}],"asks":[],"checksum":1037730228,"timestamp":"2024-06-01T18:06:53.104585Z"}]}
{"channel":"book","type":"update","data":[{"symbol":"LINK/USDT","bids":[{"price":18.55270,"qty":40.44600131}],"asks":[],"checksum":77972515,"timestamp":"2024-06-01T18:06:53.144756Z"}]}
{"channel":"book","type":"update","data":[{"symbol":"LINK/USDT","bids":[{"price":18.55504,"qty":0.00000000},{"price":18.53634,"qty":68.73000000}],"asks":[],"checksum":2690350592,"timestamp":"2024-06-01T18:06:53.376379Z"}]}
{"channel":"book","type":"update","data":[{"symbol":"LINK/USDT","bids":[{"price":18.55519,"qty":53.93875391}],"asks":[],"checksum":2025688727,"timestamp":"2024-06-01T18:06:53.380032Z"}]}
{"channel":"book","type":"update","data":[{"symbol":"LINK/USDT","bids":[{"price":18.55505,"qty":0.00000000},{"price":18.53634,"qty":68.73000000}],"asks":[],"checksum":4226125359,"timestamp":"2024-06-01T18:06:53.380551Z"}]}
{"channel":"book","type":"update","data":[{"symbol":"LINK/USDT","bids":[{"price":18.55271,"qty":243.48672997}],"asks":[],"checksum":622979583,"timestamp":"2024-06-01T18:06:53.380672Z"}]}
{"channel":"book","type":"update","data":[{"symbol":"LINK/USDT","bids":[{"price":18.55517,"qty":0.00000000},{"price":18.53634,"qty":68.73000000}],"asks":[],"checksum":1915195009,"timestamp":"2024-06-01T18:06:53.382677Z"}]}
{"channel":"book","type":"update","data":[{"symbol":"LINK/USDT","bids":[{"price":18.55569,"qty":9.40000000}],"asks":[],"checksum":2866273231,"timestamp":"2024-06-01T18:06:53.382875Z"}]}
{"channel":"book","type":"update","data":[{"symbol":"LINK/USDT","bids":[{"price":18.55520,"qty":243.48672997}],"asks":[],"checksum":3685852607,"timestamp":"2024-06-01T18:06:53.560328Z"}]}
{"channel":"book","type":"update","data":[{"symbol":"LINK/USDT","bids":[{"price":18.55271,"qty":0.00000000},{"price":18.54204,"qty":269.88270992}],"asks":[],"checksum":2841167444,"timestamp":"2024-06-01T18:06:53.565264Z"}]}
{"channel":"book","type":"update","data":[{"symbol":"LINK/USDT","bids":[{"price":18.55270,"qty":0.00000000},{"price":18.53634,"qty":68.73000000}],"asks":[],"checksum":2418508739,"timestamp":"2024-06-01T18:06:53.687233Z"}]}
{"channel":"book","type":"update","data":[{"symbol":"LINK/USDT","bids":[{"price":18.55290,"qty":40.44588999}],"asks":[],"checksum":2012847377,"timestamp":"2024-06-01T18:06:53.727415Z"}]}
{"channel":"book","type":"update","data":[{"symbol":"LINK/USDT","bids":[{"price":18.55290,"qty":0.00000000},{"price":18.53634,"qty":68.73000000}],"asks":[],"checksum":2418508739,"timestamp":"2024-06-01T18:06:54.201280Z"}]}
{"channel":"book","type":"update","data":[{"symbol":"LINK/USDT","bids":[{"price":18.54800,"qty":0.00000000},{"price":18.53633,"qty":47.11000000}],"asks":[],"checksum":3018756313,"timestamp":"2024-06-01T18:06:54.210451Z"}]}
{"channel":"book","type":"update","data":[{"symbol":"LINK/USDT","bids":[{"price":18.54700,"qty":74.06046022}],"asks":[],"checksum":456289734,"timestamp":"2024-06-01T18:06:54.214320Z"}]}
{"channel":"book","type":"update","data":[{"symbol":"LINK/USDT","bids":[{"price":18.55519,"qty":0.00000000},{"price":18.53633,"qty":47.11000000}],"asks":[],"checksum":3091347097,"timestamp":"2024-06-01T18:06:54.217355Z"}]}
{"channel":"book","type":"update","data":[{"symbol":"LINK/USDT","bids":[],"asks":[{"price":18.55876,"qty":0.00000000},{"price":18.57960,"qty":68.73000000}],"checksum":3100694165,"timestamp":"2024-06-01T18:06:54.217366Z"}]}
{"channel":"book","type":"update","data":[{"symbol":"LINK/USDT","bids":[{"price":18.55463,"qty":53.94038277}],"asks":[],"checksum":2932927744,"timestamp":"2024-06-01T18:06:54.222467Z"}]}
{"channel":"book","type":"update","data":[{"symbol":"LINK/USDT","bids":[],"asks":[{"price":18.55870,"qty":16.17856913}],"checksum":331767310,"timestamp":"2024-06-01T18:06:54.222534Z"}]}
{"channel":"book","type":"update","data":[{"symbol":"LINK/USDT","bids":[{"price":18.55293,"qty":40.44574715}],"asks":[],"checksum":3466635839,"timestamp":"2024-06-01T18:06:54.241622Z"}]}
{"channel":"book","type":"update","data":[{"symbol":"LINK/USDT","bids":[{"price":18.55520,"qty":0.00000000},{"price":18.53634,"qty":68.73000000}],"asks":[],"checksum":162472869,"timestamp":"2024-06-01T18:06:54.246068Z"}]}
{"channel":"book","type":"update","data":[{"symbol":"LINK/USDT","bids":[{"price":18.55464,"qty":243.48672997}],"asks":[],"checksum":3876662783,"timestamp":"2024-06-01T18:06:54.246259Z"}]}
{"channel":"book","type":"update","data":[{"symbol":"LINK/USDT","bids":[],"asks":[{"price":18.55867,"qty":9.00000000}],"checksum":1260107457,"timestamp":"2024-06-01T18:06:54.246414Z"}]}
{"channel":"book","type":"update","data":[{"symbol":"LINK/USDT","bids":[],"asks":[{"price":18.55870,"qty":0.00000000},{"price":18.57459,"qty":80.82295392}],"checksum":526645707,"timestamp":"2024-06-01T18:06:54.250813Z"}]}
{"channel":"book","type":"update","data":[{"symbol":"LINK/USDT","bids":[{"price":18.55802,"qty":80.89754996}],"asks":[],"checksum":740852164,"timestamp":"2024-06-01T18:06:54.373373Z"}]}
{"channel":"book","type":"update","data":[{"symbol":"LINK/USDT","bids":[],"asks":[{"price":18.55867,"qty":0.00000000},{"price":18.57960,"qty":68.73000000}],"checksum":2534657769,"timestamp":"2024-06-01T18:06:54.378236Z"}]}
{"channel":"book","type":"update","data":[{"symbol":"LINK/USDT","bids":[{"price":18.55293,"qty":0.00000000},{"price":18.54204,"qty":269.88270992}],"asks":[],"checksum":1762744506,"timestamp":"2024-06-01T18:06:54.782524Z"}]}
{"channel":"book","type":"update","data":[{"symbol":"LINK/USDT","bids":[],"asks":[{"price":18.56310,"qty":9.00000000}],"checksum":367895542,"timestamp":"2024-06-01T18:06:54.787649Z"}]}
{"channel":"book","type":"update","data":[{"symbol":"LINK/USDT","bids":[],"asks":[{"price":18.55873,"qty":0.00000000},{"price":18.57960,"qty":68.73000000}],"checksum":3932649625,"timestamp":"2024-06-01T18:06:54.787688Z"}]}
{"channel":"book","type":"update","data":[{"symbol":"LINK/USDT","bids":[],"asks":[{"price":18.56305,"qty":16.17477656}],"checksum":3143845654,"timestamp":"2024-06-01T18:06:54.792708Z"}]}
{"channel":"book","type":"update","data":[{"symbol":"LINK/USDT","bids":[],"asks":[{"price":18.56305,"qty":0.00000000},{"price":18.57960,"qty":68.73000000}],"checksum":3932649625,"timestamp":"2024-06-01T18:06:54.797238Z"}]}
{"channel":"book","type":"update","data":[{"symbol":"LINK/USDT","bids":[{"price":18.55185,"qty":40.44867383}],"asks":[],"checksum":32757351,"timestamp":"2024-06-01T18:06:54.823068Z"}]}
{"channel":"book","type":"update","data":[{"symbol":"LINK/USDT","bids":[{"price":18.55802,"qty":0.00000000},{"price":18.54204,"qty":269.88270992}],"asks":[],"checksum":1667731752,"timestamp":"2024-06-01T18:06:54.915565Z"}]}
{"channel":"book","type":"update","data":[{"symbol":"LINK/USDT","bids":[{"price":18.55786,"qty":80.89854335}],"asks":[],"checksum":3384381195,"timestamp":"2024-06-01T18:06:54.955847Z"}]}
{"channel":"book","type":"update","data":[{"symbol":"LINK/USDT","bids":[{"price":18.55787,"qty":243.48672997}],"asks":[],"checksum":2087140519,"timestamp":"2024-06-01T18:06:54.959835Z"}]}
{"channel":"book","type":"update","data":[{"symbol":"LINK/USDT","bids":[{"price":18.55464,"qty":0.00000000},{"price":18.54205,"qty":48.75805200}],"asks":[],"checksum":3513841913,"timestamp":"2024-06-01T18:06:55.058120Z"}]}
{"channel":"book","type":"update","data":[{"symbol":"LINK/USDT","bids":[{"price":18.55463,"qty":0.00000000},{"price":18.54204,"qty":269.88270992}],"asks":[],"checksum":1456731071,"timestamp":"2024-06-01T18:06:55.212322Z"}]}
{"channel":"book","type":"update","data":[{"symbol":"LINK/USDT","bids":[{"price":18.55569,"qty":0.00000000},{"price":18.53634,"qty":68.73000000}],"asks":[],"checksum":3996717308,"timestamp":"2024-06-01T18:06:55.215239Z"}]}
{"channel":"book","type":"update","data":[{"symbol":"LINK/USDT","bids":[{"price":18.55389,"qty":53.94251853}],"asks":[],"checksum":4147294585,"timestamp":"2024-06-01T18:06:55.216336Z"}]}
{"channel":"book","type":"update","data":[{"symbol":"LINK/USDT","bids":[{"price":18.55185,"qty":0.00000000},{"price":18.53634,"qty":68.73000000}],"asks":[],"checksum":2420271794,"timestamp":"2024-06-01T18:06:55.364031Z"}]}
{"channel":"book","type":"update","data":[{"symbol":"LINK/USDT","bids":[{"price":18.55183,"qty":40.44903186}],"asks":[],"checksum":3533924790,"timestamp":"2024-06-01T18:06:55.404470Z"}]}
{"channel":"book","type":"update","data":[{"symbol":"LINK/USDT","bids":[{"price":18.55786,"qty":0.00000000},{"price":18.53634,"qty":68.73000000}],"asks":[],"checksum":1880818676,"timestamp":"2024-06-01T18:06:55.503744Z"}]}
{"channel":"book","type":"update","data":[{"symbol":"LINK/USDT","bids":[{"price":18.55787,"qty":0.00000000},{"price":18.53633,"qty":47.11000000}],"asks":[],"checksum":3751158028,"timestamp":"2024-06-01T18:06:55.507919Z"}]}
{"channel":"book","type":"update","data":[{"symbol":"LINK/USDT","bids":[{"price":18.55390,"qty":243.48672997}],"asks":[],"checksum":3180700685,"timestamp":"2024-06-01T18:06:55.508161Z"}]}
{"channel":"book","type":"update","data":[{"symbol":"LINK/USDT","bids":[{"price":18.55415,"qty":9.40000000}],"asks":[],"checksum":1337583150,"timestamp":"2024-06-01T18:06:55.510793Z"}]}
{"channel":"book","type":"update","data":[{"symbol":"LINK/USDT","bids":[{"price":18.55389,"qty":0.00000000},{"price":18.53634,"qty":68.73000000}],"asks":[],"checksum":1325734619,"timestamp":"2024-06-01T18:06:55.543335Z"}]}
{"channel":"book","type":"update","data":[{"symbol":"LINK/USDT","bids":[{"price":18.55814,"qty":80.89806373}],"asks":[],"checksum":2683947630,"timestamp":"2024-06-01T18:06:55.543957Z"}]}
{"channel":"book","type":"update","data":[{"symbol":"LINK/USDT","bids":[],"asks":[{"price":18.56302,"qty":16.17481090}],"checksum":3781982455,"timestamp":"2024-06-01T18:06:55.546865Z"}]}
{"channel":"book","type":"update","data":[{"symbol":"LINK/USDT","bids":[{"price":18.55390,"qty":0.00000000},{"price":18.53634,"qty":68.73000000}],"asks":[],"checksum":3184202061,"timestamp":"2024-06-01T18:06:55.548749Z"}]}
{"channel":"book","type":"update","data":[{"symbol":"LINK/USDT","bids":[{"price":18.55184,"qty":243.48672997}],"asks":[],"checksum":1601901204,"timestamp":"2024-06-01T18:06:55.548960Z"}]}
{"channel":"book","type":"update","data":[{"symbol":"LINK/USDT","bids":[],"asks":[{"price":18.56302,"qty":0.00000000},{"price":18.57960,"qty":68.73000000}],"checksum":569286669,"timestamp":"2024-06-01T18:06:55.550281Z"}]}
{"channel":"book","type":"update","data":[{"symbol":"LINK/USDT","bids":[{"price":18.55814,"qty":0.00000000},{"price":18.53634,"qty":68.73000000}],"asks":[],"checksum":2664779641,"timestamp":"2024-06-01T18:06:55.617760Z"}]}
{"channel":"book","type":"update","data":[{"symbol":"LINK/USDT","bids":[{"price":18.55736,"qty":80.90104899}],"asks":[],"checksum":3261919935,"timestamp":"2024-06-01T18:06:55.658180Z"}]}
{"channel":"book","type":"update","data":[{"symbol":"LINK/USDT","bids":[{"price":18.55737,"qty":243.48672997}],"asks":[],"checksum":1184731515,"timestamp":"2024-06-01T18:06:55.662433Z"}]}
{"channel":"book","type":"update","data":[{"symbol":"LINK/USDT","bids":[{"price":18.55183,"qty":0.00000000},{"price":18.54204,"qty":269.88270992}],"asks":[],"checksum":319178740,"timestamp":"2024-06-01T18:06:55.951996Z"}]}
{"channel":"book","type":"update","data":[{"symbol":"LINK/USDT","bids":[{"price":18.55184,"qty":0.00000000},{"price":18.53634,"qty":68.73000000}],"asks":[],"checksum":1123856,"timestamp":"2024-06-01T18:06:55.955719Z"}]}
{"channel":"book","type":"update","data":[{"symbol":"LINK/USDT","bids":[{"price":18.55415,"qty":0.00000000},{"price":18.53633,"qty":47.11000000}],"asks":[],"checksum":2892746835,"timestamp":"2024-06-01T18:06:55.958433Z"}]}
{"channel":"book","type":"update","data":[{"symbol":"LINK/USDT","bids":[{"price":18.55327,"qty":53.94433644}],"asks":[],"checksum":3221341734,"timestamp":"2024-06-01T18:06:56.029114Z"}]}
{"channel":"book","type":"update","data":[{"symbol":"LINK/USDT","bids":[],"asks":[{"price":18.57960,"qty":0.00000000},{"price":18.57961,"qty":48.75805200},{"price":18.57458,"qty":68.73000000}],"checksum":2017183485,"timestamp":"2024-06-01T18:06:56.072474Z"}]}
{"channel":"book","type":"update","data":[{"symbol":"LINK/USDT","bids":[{"price":18.55737,"qty":0.00000000},{"price":18.53633,"qty":47.11000000}],"asks":[],"checksum":830857776,"timestamp":"2024-06-01T18:06:56.074670Z"}]}
{"channel":"book","type":"update","data":[{"symbol":"LINK/USDT","bids":[{"price":18.55327,"qty":0.00000000},{"price":18.53570,"qty":161.51454496}],"asks":[],"checksum":296278279,"timestamp":"2024-06-01T18:06:56.128900Z"}]}
{"channel":"book","type":"update","data":[{"symbol":"LINK/USDT","bids":[],"asks":[{"price":18.56298,"qty":4.85425095}],"checksum":3065364878,"timestamp":"2024-06-01T18:06:56.131618Z"}]}
{"channel":"book","type":"update","data":[{"symbol":"LINK/USDT","bids":[],"asks":[{"price":18.55772,"qty":16.17943074}],"checksum":3670651148,"timestamp":"2024-06-01T18:06:56.132986Z"}]}
{"channel":"book","type":"update","data":[{"symbol":"LINK/USDT","bids":[],"asks":[{"price":18.56313,"qty":0.00000000},{"price":18.57458,"qty":68.73000000}],"checksum":2834545310,"timestamp":"2024-06-01T18:06:56.134364Z"}]}
{"channel":"book","type":"update","data":[{"symbol":"LINK/USDT","bids":[{"price":18.55736,"qty":0.00000000},{"price":18.53569,"qty":269.97594682}],"asks":[],"checksum":306825242,"timestamp":"2024-06-01T18:06:56.135854Z"}]}
{"channel":"book","type":"update","data":[{"symbol":"LINK/USDT","bids":[{"price":18.55038,"qty":9.40000000}],"asks":[],"checksum":1711646291,"timestamp":"2024-06-01T18:06:56.138955Z"}]}
{"channel":"book","type":"update","data":[{"symbol":"LINK/USDT","bids":[],"asks":[{"price":18.56453,"qty":0.00000000},{"price":18.57459,"qty":80.82295392}],"checksum":1533196223,"timestamp":"2024-06-01T18:06:56.152364Z"}]}
{"channel":"book","type":"update","data":[{"symbol":"LINK/USDT","bids":[],"asks":[{"price":18.56291,"qty":9.40000000}],"checksum":556945961,"timestamp":"2024-06-01T18:06:56.152531Z"}]}
{"channel":"book","type":"update","data":[{"symbol":"LINK/USDT","bids":[{"price":18.55727,"qty":80.90135314}],"asks":[],"checksum":54111362,"timestamp":"2024-06-01T18:06:56.176276Z"}]}
{"channel":"book","type":"update","data":[{"symbol":"LINK/USDT","bids":[],"asks":[{"price":18.55769,"qty":9.00000000}],"checksum":1149679991,"timestamp":"2024-06-01T18:06:56.181426Z"}]}
{"channel":"book","type":"update","data":[{"symbol":"LINK/USDT","bids":[],"asks":[{"price":18.55772,"qty":0.00000000},{"price":18.57458,"qty":68.73000000}],"checksum":1495511732,"timestamp":"2024-06-01T18:06:56.185074Z"}]}
{"channel":"book","type":"update","data":[{"symbol":"LINK/USDT","bids":[{"price":18.55095,"qty":40.45122422}],"asks":[],"checksum":242857400,"timestamp":"2024-06-01T18:06:56.549969Z"}]}
{"channel":"book","type":"update","data":[{"symbol":"LINK/USDT","bids":[{"price":18.55507,"qty":243.48672997}],"asks":[],"checksum":3416819982,"timestamp":"2024-06-01T18:06:56.560138Z"}]}
{"channel":"book","type":"update","data":[{"symbol":"LINK/USDT","bids":[],"asks":[{"price":18.56310,"qty":0.00000000},{"price":18.57459,"qty":80.82295392}],"checksum":4216257860,"timestamp":"2024-06-01T18:06:56.560291Z"}]}
{"channel":"book","type":"update","data":[{"symbol":"LINK/USDT","bids":[],"asks":[{"price":18.55768,"qty":16.17945695}],"checksum":2694936874,"timestamp":"2024-06-01T18:06:56.673907Z"}]}
{"channel":"book","type":"update","data":[{"symbol":"LINK/USDT","bids":[{"price":18.55407,"qty":53.94200341}],"asks":[],"checksum":74437777,"timestamp":"2024-06-01T18:06:56.674135Z"}]}
{"channel":"book","type":"update","data":[{"symbol":"LINK/USDT","bids":[],"asks":[{"price":18.55765,"qty":9.00000000}],"checksum":3237457550,"timestamp":"2024-06-01T18:06:56.678488Z"}]}
{"channel":"book","type":"update","data":[{"symbol":"LINK/USDT","bids":[],"asks":[{"price":18.55768,"qty":0.00000000},{"price":18.57458,"qty":68.73000000}],"checksum":1652253987,"timestamp":"2024-06-01T18:06:56.685712Z"}]}
{"channel":"book","type":"update","data":[{"symbol":"LINK/USDT","bids":[{"price":18.55727,"qty":0.00000000},{"price":18.54204,"qty":269.88270992}],"asks":[],"checksum":3716412851,"timestamp":"2024-06-01T18:06:56.733241Z"}]}
{"channel":"book","type":"update","data":[{"symbol":"LINK/USDT","bids":[],"asks":[{"price":18.55765,"qty":0.00000000},{"price":18.57459,"qty":80.82295392}],"checksum":2741352396,"timestamp":"2024-06-01T18:06:56.737851Z"}]}
{"channel":"book","type":"update","data":[{"symbol":"LINK/USDT","bids":[{"price":18.55507,"qty":0.00000000},{"price":18.53634,"qty":68.73000000}],"asks":[],"checksum":3886807912,"timestamp":"2024-06-01T18:06:56.738408Z"}]}
{"channel":"book","type":"update","data":[{"symbol":"LINK/USDT","bids":[{"price":18.55714,"qty":80.90287451}],"asks":[],"checksum":1650219340,"timestamp":"2024-06-01T18:06:56.773478Z"}]}
{"channel":"book","type":"update","data":[{"symbol":"LINK/USDT","bids":[{"price":18.55407,"qty":0.00000000},{"price":18.53634,"qty":68.73000000}],"asks":[],"checksum":3717511681,"timestamp":"2024-06-01T18:06:57.079410Z"}]}
{"channel":"book","type":"update","data":[{"symbol":"LINK/USDT","bids":[{"price":18.55095,"qty":0.00000000},{"price":18.53633,"qty":47.11000000}],"asks":[],"checksum":2328804621,"timestamp":"2024-06-01T18:06:57.173506Z"}]}
{"channel":"book","type":"update","data":[{"symbol":"LINK/USDT","bids":[{"price":18.55099,"qty":40.45111520}],"asks":[],"checksum":3117457672,"timestamp":"2024-06-01T18:06:57.213518Z"}]}
{"channel":"book","type":"update","data":[{"symbol":"LINK/USDT","bids":[],"asks":[{"price":18.55769,"qty":0.00000000},{"price":18.57961,"qty":48.75805200}],"checksum":4238400680,"timestamp":"2024-06-01T18:06:57.218672Z"}]}
{"channel":"book","type":"update","data":[{"symbol":"LINK/USDT","bids":[],"asks":[{"price":18.56288,"qty":9.00000000}],"checksum":3504161233,"timestamp":"2024-06-01T18:06:57.218803Z"}]}
{"channel":"book","type":"update","data":[{"symbol":"LINK/USDT","bids":[{"price":18.55714,"qty":0.00000000},{"price":18.53633,"qty":47.11000000}],"asks":[],"checksum":332778532,"timestamp":"2024-06-01T18:06:57.332753Z"}]}
{"channel":"book","type":"update","data":[{"symbol":"LINK/USDT","bids":[{"price":18.55038,"qty":0.00000000},{"price":18.53570,"qty":161.51454496}],"asks":[],"checksum":2261600017,"timestamp":"2024-06-01T18:06:57.335648Z"}]}
{"channel":"book","type":"update","data":[{"symbol":"LINK/USDT","bids":[{"price":18.55172,"qty":9.40000000}],"asks":[],"checksum":487061462,"timestamp":"2024-06-01T18:06:57.335836Z"}]}
{"channel":"book","type":"update","data":[{"symbol":"LINK/USDT","bids":[{"price":18.55102,"qty":9.00000000}],"asks":[],"checksum":2023244678,"timestamp":"2024-06-01T18:06:57.337514Z"}]}
{"channel":"book","type":"update","data":[{"symbol":"LINK/USDT","bids":[],"asks":[{"price":18.56277,"qty":16.17503234}],"checksum":369867942,"timestamp":"2024-06-01T18:06:57.342710Z"}]}
{"channel":"book","type":"update","data":[{"symbol":"LINK/USDT","bids":[{"price":18.55355,"qty":53.94349500}],"asks":[],"checksum":254927127,"timestamp":"2024-06-01T18:06:57.342939Z"}]}
{"channel":"book","type":"update","data":[{"symbol":"LINK/USDT","bids":[{"price":18.55172,"qty":0.00000000},{"price":18.53634,"qty":68.73000000}],"asks":[],"checksum":461111534,"timestamp":"2024-06-01T18:06:57.345534Z"}]}
{"channel":"book","type":"update","data":[{"symbol":"LINK/USDT","bids":[{"price":18.55372,"qty":9.40000000}],"asks":[],"checksum":3637083918,"timestamp":"2024-06-01T18:06:57.345754Z"}]}
{"channel":"book","type":"update","data":[{"symbol":"LINK/USDT","bids":[],"asks":[{"price":18.56277,"qty":0.00000000},{"price":18.57459,"qty":80.82295392}],"checksum":3059384366,"timestamp":"2024-06-01T18:06:57.346981Z"}]}
{"channel":"book","type":"update","data":[{"symbol":"LINK/USDT","bids":[{"price":18.55355,"qty":0.00000000},{"price":18.53634,"qty":68.73000000}],"asks":[],"checksum":644123572,"timestamp":"2024-06-01T18:06:57.349265Z"}]}
{"channel":"book","type":"update","data":[{"symbol":"LINK/USDT","bids":[{"price":18.55739,"qty":80.90174621}],"asks":[],"checksum":344496105,"timestamp":"2024-06-01T18:06:57.372789Z"}]}
{"channel":"book","type":"update","data":[{"symbol":"LINK/USDT","bids":[{"price":18.55102,"qty":0.00000000},{"price":18.53634,"qty":68.73000000}],"asks":[],"checksum":1680912624,"timestamp":"2024-06-01T18:06:57.377016Z"}]}
{"channel":"book","type":"update","data":[{"symbol":"LINK/USDT","bids":[{"price":18.55507,"qty":243.48672997}],"asks":[],"checksum":1008731613,"timestamp":"2024-06-01T18:06:57.558243Z"}]}
{"channel":"book","type":"update","data":[{"symbol":"LINK/USDT","bids":[{"price":18.55099,"qty":0.00000000},{"price":18.53634,"qty":68.73000000}],"asks":[],"checksum":640054258,"timestamp":"2024-06-01T18:06:57.773793Z"}]}
{"channel":"book","type":"update","data":[{"symbol":"LINK/USDT","bids":[{"price":18.55372,"qty":0.00000000},{"price":18.53633,"qty":47.11000000}],"asks":[],"checksum":2354115974,"timestamp":"2024-06-01T18:06:57.776550Z"}]}
{"channel":"book","type":"update","data":[{"symbol":"LINK/USDT","bids":[{"price":18.55113,"qty":40.45078472}],"asks":[],"checksum":1981154553,"timestamp":"2024-06-01T18:06:57.813895Z"}]}
{"channel":"book","type":"update","data":[{"symbol":"LINK/USDT","bids":[{"price":18.55739,"qty":0.00000000},{"price":18.53633,"qty":47.11000000}],"asks":[],"checksum":2738550998,"timestamp":"2024-06-01T18:06:57.862557Z"}]}
{"channel":"book","type":"update","data":[{"symbol":"LINK/USDT","bids":[{"price":18.55507,"qty":0.00000000},{"price":18.53570,"qty":161.51454496}],"asks":[],"checksum":1638094717,"timestamp":"2024-06-01T18:06:57.867172Z"}]}
{"channel":"book","type":"update","data":[{"symbol":"LINK/USDT","bids":[{"price":18.55186,"qty":9.40000000}],"asks":[],"checksum":1608833452,"timestamp":"2024-06-01T18:06:57.869871Z"}]}
{"channel":"book","type":"update","data":[{"symbol":"LINK/USDT","bids":[],"asks":[{"price":18.55770,"qty":16.17945667}],"checksum":2466940397,"timestamp":"2024-06-01T18:06:57.871626Z"}]}
{"channel":"book","type":"update","data":[{"symbol":"LINK/USDT","bids":[{"price":18.55124,"qty":53.95025847}],"asks":[],"checksum":3129758744,"timestamp":"2024-06-01T18:06:57.871780Z"}]}
{"channel":"book","type":"update","data":[{"symbol":"LINK/USDT","bids":[{"price":18.55124,"qty":0.00000000},{"price":18.53633,"qty":47.11000000}],"asks":[],"checksum":2466940397,"timestamp":"2024-06-01T18:06:57.875841Z"}]}
{"channel":"book","type":"update","data":[{"symbol":"LINK/USDT","bids":[{"price":18.55743,"qty":80.90156944}],"asks":[],"checksum":2989829320,"timestamp":"2024-06-01T18:06:57.902595Z"}]}
{"channel":"book","type":"update","data":[{"symbol":"LINK/USDT","bids":[],"asks":[{"price":18.55767,"qty":9.00000000}],"checksum":736486384,"timestamp":"2024-06-01T18:06:57.907379Z"}]}
{"channel":"book","type":"update","data":[{"symbol":"LINK/USDT","bids":[],"asks":[{"price":18.55770,"qty":0.00000000},{"price":18.57458,"qty":68.73000000}],"checksum":312141012,"timestamp":"2024-06-01T18:06:57.911374Z"}]}
{"channel":"book","type":"update","data":[{"symbol":"LINK/USDT","bids":[],"asks":[{"price":18.55767,"qty":0.00000000},{"price":18.57459,"qty":80.82295392}],"checksum":2128310409,"timestamp":"2024-06-01T18:06:58.084930Z"}]}
{"channel":"book","type":"update","data":[{"symbol":"LINK/USDT","bids":[],"asks":[{"price":18.56286,"qty":4.85428285}],"checksum":248502162,"timestamp":"2024-06-01T18:06:58.087864Z"}]}
{"channel":"book","type":"update","data":[{"symbol":"LINK/USDT","bids":[],"asks":[{"price":18.56298,"qty":0.00000000},{"price":18.57459,"qty":80.82295392}],"checksum":1200329555,"timestamp":"2024-06-01T18:06:58.091071Z"}]}
{"channel":"book","type":"update","data":[{"symbol":"LINK/USDT","bids":[],"asks":[{"price":18.56281,"qty":16.17500014}],"checksum":3480050712,"timestamp":"2024-06-01T18:06:58.389544Z"}]}
{"channel":"book","type":"update","data":[{"symbol":"LINK/USDT","bids":[{"price":18.55370,"qty":53.94310669}],"asks":[],"checksum":1797326086,"timestamp":"2024-06-01T18:06:58.389581Z"}]}
{"channel":"book","type":"update","data":[{"symbol":"LINK/USDT","bids":[],"asks":[{"price":18.56278,"qty":9.00000000}],"checksum":2441384948,"timestamp":"2024-06-01T18:06:58.394479Z"}]}
{"channel":"book","type":"update","data":[{"symbol":"LINK/USDT","bids":[],"asks":[{"price":18.56281,"qty":0.00000000},{"price":18.57458,"qty":68.73000000}],"checksum":2910469211,"timestamp":"2024-06-01T18:06:58.396178Z"}]}
{"channel":"book","type":"update","data":[{"symbol":"LINK/USDT","bids":[{"price":18.55370,"qty":0.00000000},{"price":18.53634,"qty":68.73000000}],"asks":[],"checksum":154559813,"timestamp":"2024-06-01T18:06:58.408137Z"}]}
{"channel":"book","type":"update","data":[{"symbol":"LINK/USDT","bids":[{"price":18.55743,"qty":0.00000000},{"price":18.53633,"qty":47.11000000}],"asks":[],"checksum":671730784,"timestamp":"2024-06-01T18:06:58.461670Z"}]}
{"channel":"book","type":"update","data":[{"symbol":"LINK/USDT","bids":[{"price":18.55114,"qty":243.48672997}],"asks":[],"checksum":3394074651,"timestamp":"2024-06-01T18:06:58.465973Z"}]}
{"channel":"book","type":"update","data":[{"symbol":"LINK/USDT","bids":[],"asks":[{"price":18.56288,"qty":0.00000000},{"price":18.57459,"qty":80.82295392}],"checksum":3747624715,"timestamp":"2024-06-01T18:06:58.466426Z"}]}
{"channel":"book","type":"update","data":[{"symbol":"LINK/USDT","bids":[{"price":18.55189,"qty":9.00000000}],"asks":[],"checksum":2741917381,"timestamp":"2024-06-01T18:06:58.466595Z"}]}
{"channel":"book","type":"update","data":[{"symbol":"LINK/USDT","bids":[{"price":18.55746,"qty":80.90170010}],"asks":[],"checksum":1243024148,"timestamp":"2024-06-01T18:06:58.501782Z"}]}
{"channel":"book","type":"update","data":[{"symbol":"LINK/USDT","bids":[{"price":18.55507,"qty":243.48672997}],"asks":[],"checksum":380543701,"timestamp":"2024-06-01T18:06:58.506206Z"}]}
{"channel":"book","type":"update","data":[{"symbol":"LINK/USDT","bids":[{"price":18.55189,"qty":0.00000000},{"price":18.54205,"qty":48.75805200}],"asks":[],"checksum":88752697,"timestamp":"2024-06-01T18:06:58.506276Z"}]}
{"channel":"book","type":"update","data":[{"symbol":"LINK/USDT","bids":[],"asks":[{"price":18.56291,"qty":0.00000000},{"price":18.57961,"qty":48.75805200}],"checksum":202322376,"timestamp":"2024-06-01T18:06:58.542283Z"}]}
{"channel":"book","type":"update","data":[{"symbol":"LINK/USDT","bids":[],"asks":[{"price":18.56469,"qty":9.40000000}],"checksum":973750019,"timestamp":"2024-06-01T18:06:58.542435Z"}]}
{"channel":"book","type":"update","data":[{"symbol":"LINK/USDT","bids":[{"price":18.55114,"qty":0.00000000},{"price":18.54204,"qty":269.88270992}],"asks":[],"checksum":3259857490,"timestamp":"2024-06-01T18:06:58.546091Z"}]}
{"channel":"book","type":"update","data":[{"symbol":"LINK/USDT","bids":[{"price":18.55113,"qty":0.00000000},{"price":18.53634,"qty":68.73000000}],"asks":[],"checksum":3338845643,"timestamp":"2024-06-01T18:06:58.862003Z"}]}
{"channel":"book","type":"update","data":[{"symbol":"LINK/USDT","bids":[{"price":18.55164,"qty":40.44970039}],"asks":[],"checksum":3945817037,"timestamp":"2024-06-01T18:06:58.902266Z"}]}
{"channel":"book","type":"update","data":[{"symbol":"LINK/USDT","bids":[],"asks":[{"price":18.56278,"qty":0.00000000},{"price":18.57961,"qty":48.75805200}],"checksum":61506130,"timestamp":"2024-06-01T18:06:58.907441Z"}]}
{"channel":"book","type":"update","data":[{"symbol":"LINK/USDT","bids":[],"asks":[{"price":18.56283,"qty":9.00000000}],"checksum":2081004499,"timestamp":"2024-06-01T18:06:58.907555Z"}]}
{"channel":"book","type":"update","data":[{"symbol":"LINK/USDT","bids":[],"asks":[{"price":18.55754,"qty":16.17959663}],"checksum":1950046226,"timestamp":"2024-06-01T18:06:58.948856Z"}]}
{"channel":"book","type":"update","data":[{"symbol":"LINK/USDT","bids":[{"price":18.55394,"qty":53.94241884}],"asks":[],"checksum":3150125264,"timestamp":"2024-06-01T18:06:58.948956Z"}]}
{"channel":"book","type":"update","data":[{"symbol":"LINK/USDT","bids":[],"asks":[{"price":18.55751,"qty":9.00000000}],"checksum":1028858801,"timestamp":"2024-06-01T18:06:58.953578Z"}]}
{"channel":"book","type":"update","data":[{"symbol":"LINK/USDT","bids":[{"price":18.55746,"qty":0.00000000},{"price":18.54204,"qty":269.88270992}],"asks":[],"checksum":778234478,"timestamp":"2024-06-01T18:06:59.060949Z"}]}
{"channel":"book","type":"update","data":[{"symbol":"LINK/USDT","bids":[{"price":18.55507,"qty":0.00000000},{"price":18.53634,"qty":68.73000000}],"asks":[],"checksum":2728277159,"timestamp":"2024-06-01T18:06:59.064501Z"}]}
{"channel":"book","type":"update","data":[{"symbol":"LINK/USDT","bids":[],"asks":[{"price":18.56283,"qty":0.00000000},{"price":18.57458,"qty":68.73000000}],"checksum":1203090490,"timestamp":"2024-06-01T18:06:59.065964Z"}]}
{"channel":"book","type":"update","data":[{"symbol":"LINK/USDT","bids":[{"price":18.55186,"qty":0.00000000},{"price":18.53633,"qty":47.11000000}],"asks":[],"checksum":2872315521,"timestamp":"2024-06-01T18:06:59.068786Z"}]}
{"channel":"book","type":"update","data":[{"symbol":"LINK/USDT","bids":[{"price":18.55400,"qty":9.40000000}],"asks":[],"checksum":2914741781,"timestamp":"2024-06-01T18:06:59.068827Z"}]}
{"channel":"book","type":"update","data":[{"symbol":"LINK/USDT","bids":[{"price":18.55394,"qty":0.00000000},{"price":18.53633,"qty":47.11000000}],"asks":[],"checksum":173683255,"timestamp":"2024-06-01T18:06:59.235187Z"}]}
{"channel":"book","type":"update","data":[{"symbol":"LINK/USDT","bids":[],"asks":[{"price":18.55754,"qty":0.00000000},{"price":18.57459,"qty":80.82295392}],"checksum":1492776919,"timestamp":"2024-06-01T18:06:59.235231Z"}]}
{"channel":"book","type":"update","data":[{"symbol":"LINK/USDT","bids":[{"price":18.55164,"qty":0.00000000},{"price":18.53570,"qty":161.51454496}],"asks":[],"checksum":4017110341,"timestamp":"2024-06-01T18:06:59.461607Z"}]}
{"channel":"book","type":"update","data":[{"symbol":"LINK/USDT","bids":[{"price":18.55400,"qty":0.00000000},{"price":18.53569,"qty":269.97594682}],"asks":[],"checksum":1571114481,"timestamp":"2024-06-01T18:06:59.464367Z"}]}
{"channel":"book","type":"update","data":[{"symbol":"LINK/USDT","bids":[{"price":18.55038,"qty":9.40000000}],"asks":[],"checksum":312598590,"timestamp":"2024-06-01T18:06:59.464597Z"}]}
{"channel":"book","type":"update","data":[{"symbol":"LINK/USDT","bids":[],"asks":[{"price":18.55751,"qty":0.00000000},{"price":18.57961,"qty":48.75805200}],"checksum":1895857743,"timestamp":"2024-06-01T18:06:59.466693Z"}]}
{"channel":"book","type":"update","data":[{"symbol":"LINK/USDT","bids":[],"asks":[{"price":18.56283,"qty":9.00000000}],"checksum":245589966,"timestamp":"2024-06-01T18:06:59.466926Z"}]}
{"channel":"book","type":"update","data":[{"symbol":"LINK/USDT","bids":[{"price":18.55150,"qty":40.45006712}],"asks":[],"checksum":2216227732,"timestamp":"2024-06-01T18:06:59.502130Z"}]}
{"channel":"book","type":"update","data":[{"symbol":"LINK/USDT","bids":[{"price":18.55038,"qty":0.00000000},{"price":18.53570,"qty":161.51454496}],"asks":[],"checksum":3564000089,"timestamp":"2024-06-01T18:06:59.504929Z"}]}
{"channel":"book","type":"update","data":[{"symbol":"LINK/USDT","bids":[{"price":18.55223,"qty":9.40000000}],"asks":[],"checksum":62442260,"timestamp":"2024-06-01T18:06:59.505031Z"}]}
{"channel":"book","type":"update","data":[{"symbol":"LINK/USDT","bids":[{"price":18.55153,"qty":9.00000000}],"asks":[],"checksum":397528605,"timestamp":"2024-06-01T18:06:59.507237Z"}]}
{"channel":"book","type":"update","data":[{"symbol":"LINK/USDT","bids":[],"asks":[{"price":18.55810,"qty":16.17910374}],"checksum":1966881669,"timestamp":"2024-06-01T18:06:59.513197Z"}]}
{"channel":"book","type":"update","data":[{"symbol":"LINK/USDT","bids":[{"price":18.55233,"qty":53.94709782}],"asks":[],"checksum":1648328983,"timestamp":"2024-06-01T18:06:59.513222Z"}]}
{"channel":"book","type":"update","data":[{"symbol":"LINK/USDT","bids":[{"price":18.55223,"qty":0.00000000},{"price":18.53634,"qty":68.73000000}],"asks":[],"checksum":2733262673,"timestamp":"2024-06-01T18:06:59.516099Z"}]}
{"channel":"book","type":"update","data":[{"symbol":"LINK/USDT","bids":[{"price":18.55306,"qty":9.40000000}],"asks":[],"checksum":3194376307,"timestamp":"2024-06-01T18:06:59.516112Z"}]}
{"channel":"book","type":"update","data":[{"symbol":"LINK/USDT","bids":[{"price":18.55233,"qty":0.00000000},{"price":18.53634,"qty":68.73000000}],"asks":[],"checksum":129204307,"timestamp":"2024-06-01T18:06:59.517481Z"}]}
{"channel":"book","type":"update","data":[{"symbol":"LINK/USDT","bids":[{"price":18.55151,"qty":243.48672997}],"asks":[],"checksum":1995411573,"timestamp":"2024-06-01T18:06:59.523087Z"}]}
{"channel":"book","type":"update","data":[{"symbol":"LINK/USDT","bids":[{"price":18.55153,"qty":0.00000000},{"price":18.53634,"qty":68.73000000}],"asks":[],"checksum":4293367401,"timestamp":"2024-06-01T18:06:59.587140Z"}]}
{"channel":"book","type":"update","data":[{"symbol":"LINK/USDT","bids":[],"asks":[{"price":18.55807,"qty":9.00000000}],"checksum":3771734112,"timestamp":"2024-06-01T18:06:59.587411Z"}]}
{"channel":"book","type":"update","data":[{"symbol":"LINK/USDT","bids":[],"asks":[{"price":18.55810,"qty":0.00000000},{"price":18.57458,"qty":68.73000000}],"checksum":1201199778,"timestamp":"2024-06-01T18:06:59.591336Z"}]}
{"channel":"book","type":"update","data":[{"symbol":"LINK/USDT","bids":[],"asks":[{"price":18.56283,"qty":0.00000000},{"price":18.57459,"qty":80.82295392}],"checksum":3279066251,"timestamp":"2024-06-01T18:06:59.591660Z"}]}
{"channel":"book","type":"update","data":[{"symbol":"LINK/USDT","bids":[{"price":18.55783,"qty":80.89999827}],"asks":[],"checksum":3785134981,"timestamp":"2024-06-01T18:06:59.631073Z"}]}
{"channel":"book","type":"update","data":[{"symbol":"LINK/USDT","bids":[{"price":18.55150,"qty":0.00000000},{"price":18.53634,"qty":68.73000000}],"asks":[],"checksum":1581360125,"timestamp":"2024-06-01T18:06:59.990499Z"}]}
{"channel":"book","type":"update","data":[{"symbol":"LINK/USDT","bids":[{"price":18.55100,"qty":40.45124398}],"asks":[],"checksum":2184596350,"timestamp":"2024-06-01T18:07:00.030762Z"}]}
{"channel":"book","type":"update","data":[{"symbol":"LINK/USDT","bids":[{"price":18.55783,"qty":0.00000000},{"price":18.53634,"qty":68.73000000}],"asks":[],"checksum":512108052,"timestamp":"2024-06-01T18:07:00.189497Z"}]}
{"channel":"book","type":"update","data":[{"symbol":"LINK/USDT","bids":[{"price":18.55151,"qty":0.00000000},{"price":18.53633,"qty":47.11000000}],"asks":[],"checksum":2484429197,"timestamp":"2024-06-01T18:07:00.195011Z"}]}
{"channel":"book","type":"update","data":[{"symbol":"LINK/USDT","bids":[],"asks":[{"price":18.56283,"qty":9.00000000}],"checksum":3222967966,"timestamp":"2024-06-01T18:07:00.196228Z"}]}
{"channel":"book","type":"update","data":[{"symbol":"LINK/USDT","bids":[],"asks":[{"price":18.55807,"qty":0.00000000},{"price":18.57459,"qty":80.82295392}],"checksum":4232430634,"timestamp":"2024-06-01T18:07:00.196244Z"}]}
{"channel":"book","type":"update","data":[{"symbol":"LINK/USDT","bids":[{"price":18.55731,"qty":80.90248344}],"asks":[],"checksum":1123060743,"timestamp":"2024-06-01T18:07:00.229779Z"}]}
{"channel":"book","type":"update","data":[{"symbol":"LINK/USDT","bids":[{"price":18.54965,"qty":0.00000000},{"price":18.53633,"qty":47.11000000}],"asks":[],"checksum":3025468016,"timestamp":"2024-06-01T18:07:00.467030Z"}]}
{"channel":"book","type":"update","data":[{"symbol":"LINK/USDT","bids":[{"price":18.54413,"qty":50.01000000}],"asks":[],"checksum":3080691187,"timestamp":"2024-06-01T18:07:00.469478Z"}]}
{"channel":"book","type":"update","data":[{"symbol":"LINK/USDT","bids":[{"price":18.55507,"qty":243.48672997}],"asks":[],"checksum":2997335448,"timestamp":"2024-06-01T18:07:00.471022Z"}]}
{"channel":"book","type":"update","data":[{"symbol":"LINK/USDT","bids":[],"asks":[{"price":18.55802,"qty":16.17917251}],"checksum":2881350837,"timestamp":"2024-06-01T18:07:00.593361Z"}]}
{"channel":"book","type":"update","data":[{"symbol":"LINK/USDT","bids":[{"price":18.55396,"qty":53.94235276}],"asks":[],"checksum":3493723147,"timestamp":"2024-06-01T18:07:00.593425Z"}]}
{"channel":"book","type":"update","data":[{"symbol":"LINK/USDT","bids":[],"asks":[{"price":18.55799,"qty":9.00000000}],"checksum":2730891071,"timestamp":"2024-06-01T18:07:00.598263Z"}]}
{"channel":"book","type":"update","data":[{"symbol":"LINK/USDT","bids":[],"asks":[{"price":18.55802,"qty":0.00000000},{"price":18.57458,"qty":68.73000000}],"checksum":865713837,"timestamp":"2024-06-01T18:07:00.602063Z"}]}
{"channel":"book","type":"update","data":[{"symbol":"LINK/USDT","bids":[{"price":18.55100,"qty":0.00000000},{"price":18.54204,"qty":269.88270992}],"asks":[],"checksum":1314508219,"timestamp":"2024-06-01T18:07:00.678561Z"}]}
{"channel":"book","type":"update","data":[{"symbol":"LINK/USDT","bids":[],"asks":[{"price":18.55799,"qty":0.00000000},{"price":18.57459,"qty":80.82295392}],"checksum":1746220553,"timestamp":"2024-06-01T18:07:00.683643Z"}]}
{"channel":"book","type":"update","data":[{"symbol":"LINK/USDT","bids":[{"price":18.55122,"qty":40.45070313}],"asks":[],"checksum":1425605535,"timestamp":"2024-06-01T18:07:00.719230Z"}]}
{"channel":"book","type":"update","data":[{"symbol":"LINK/USDT","bids":[{"price":18.55396,"qty":0.00000000},{"price":18.54204,"qty":269.88270992}],"asks":[],"checksum":2172803647,"timestamp":"2024-06-01T18:07:00.769591Z"}]}
{"channel":"book","type":"update","data":[{"symbol":"LINK/USDT","bids":[],"asks":[{"price":18.56264,"qty":4.85434815}],"checksum":3372328979,"timestamp":"2024-06-01T18:07:00.859002Z"}]}
{"channel":"book","type":"update","data":[{"symbol":"LINK/USDT","bids":[],"asks":[{"price":18.56286,"qty":0.00000000},{"price":18.57459,"qty":80.82295392}],"checksum":2719719048,"timestamp":"2024-06-01T18:07:00.861704Z"}]}
{"channel":"book","type":"update","data":[{"symbol":"LINK/USDT","bids":[],"asks":[{"price":18.56261,"qty":9.00000000}],"checksum":3805771007,"timestamp":"2024-06-01T18:07:00.864065Z"}]}
{"channel":"book","type":"update","data":[{"symbol":"LINK/USDT","bids":[],"asks":[{"price":18.56261,"qty":13.85434815}],"checksum":2473136043,"timestamp":"2024-06-01T18:07:00.867026Z"}]}
{"channel":"book","type":"update","data":[{"symbol":"LINK/USDT","bids":[{"price":18.55731,"qty":0.00000000},{"price":18.53634,"qty":68.73000000}],"asks":[],"checksum":2095313809,"timestamp":"2024-06-01T18:07:00.886398Z"}]}
{"channel":"book","type":"update","data":[{"symbol":"LINK/USDT","bids":[],"asks":[{"price":18.56264,"qty":0.00000000},{"price":18.57459,"qty":80.82295392}],"checksum":3205289753,"timestamp":"2024-06-01T18:07:00.889129Z"}]}
{"channel":"book","type":"update","data":[{"symbol":"LINK/USDT","bids":[{"price":18.55507,"qty":0.00000000},{"price":18.53633,"qty":47.11000000}],"asks":[],"checksum":1925400342,"timestamp":"2024-06-01T18:07:00.893445Z"}]}
{"channel":"book","type":"update","data":[{"symbol":"LINK/USDT","bids":[],"asks":[{"price":18.56261,"qty":4.85434815}],"checksum":3651962366,"timestamp":"2024-06-01T18:07:00.898707Z"}]}
{"channel":"book","type":"update","data":[{"symbol":"LINK/USDT","bids":[{"price":18.55742,"qty":80.90178247}],"asks":[],"checksum":1573497873,"timestamp":"2024-06-01T18:07:00.926596Z"}]}
{"channel":"book","type":"update","data":[{"symbol":"LINK/USDT","bids":[],"asks":[{"price":18.56258,"qty":9.00000000}],"checksum":970833496,"timestamp":"2024-06-01T18:07:00.931203Z"}]}
{"channel":"book","type":"update","data":[{"symbol":"LINK/USDT","bids":[],"asks":[{"price":18.56283,"qty":0.00000000},{"price":18.57459,"qty":80.82295392}],"checksum":2394996692,"timestamp":"2024-06-01T18:07:01.084047Z"}]}
{"channel":"book","type":"update","data":[{"symbol":"LINK/USDT","bids":[{"price":18.55122,"qty":0.00000000},{"price":18.53633,"qty":47.11000000}],"asks":[],"checksum":422177232,"timestamp":"2024-06-01T18:07:01.277886Z"}]}
{"channel":"book","type":"update","data":[{"symbol":"LINK/USDT","bids":[{"price":18.55306,"qty":0.00000000},{"price":18.53570,"qty":161.51454496}],"asks":[],"checksum":3023708476,"timestamp":"2024-06-01T18:07:01.280738Z"}]}
{"channel":"book","type":"update","data":[{"symbol":"LINK/USDT","bids":[{"price":18.55742,"qty":0.00000000},{"price":18.53569,"qty":269.97594682}],"asks":[],"checksum":1674010850,"timestamp":"2024-06-01T18:07:01.419261Z"}]}
{"channel":"book","type":"update","data":[{"symbol":"LINK/USDT","bids":[{"price":18.54998,"qty":9.40000000}],"asks":[],"checksum":1215860650,"timestamp":"2024-06-01T18:07:01.422200Z"}]}
{"channel":"book","type":"update","data":[{"symbol":"LINK/USDT","bids":[{"price":18.54926,"qty":243.48672997}],"asks":[],"checksum":1938023071,"timestamp":"2024-06-01T18:07:01.423174Z"}]}
{"channel":"book","type":"update","data":[{"symbol":"LINK/USDT","bids":[],"asks":[{"price":18.55759,"qty":16.17954778}],"checksum":2019802842,"timestamp":"2024-06-01T18:07:01.424102Z"}]}
{"channel":"book","type":"update","data":[{"symbol":"LINK/USDT","bids":[{"price":18.54938,"qty":53.95566830}],"asks":[],"checksum":2400357654,"timestamp":"2024-06-01T18:07:01.424134Z"}]}
{"channel":"book","type":"update","data":[{"symbol":"LINK/USDT","bids":[{"price":18.54928,"qty":9.00000000}],"asks":[],"checksum":1878378233,"timestamp":"2024-06-01T18:07:01.424199Z"}]}
{"channel":"book","type":"update","data":[{"symbol":"LINK/USDT","bids":[{"price":18.54938,"qty":0.00000000},{"price":18.53634,"qty":68.73000000}],"asks":[],"checksum":3786624907,"timestamp":"2024-06-01T18:07:01.428583Z"}]}
{"channel":"book","type":"update","data":[{"symbol":"LINK/USDT","bids":[{"price":18.54927,"qty":8.40563360}],"asks":[],"checksum":92320048,"timestamp":"2024-06-01T18:07:01.429711Z"}]}
{"channel":"book","type":"update","data":[{"symbol":"LINK/USDT","bids":[{"price":18.55735,"qty":80.90203550}],"asks":[],"checksum":3596884762,"timestamp":"2024-06-01T18:07:01.459350Z"}]}
{"channel":"book","type":"update","data":[{"symbol":"LINK/USDT","bids":[{"price":18.55507,"qty":243.48672997}],"asks":[],"checksum":1059577932,"timestamp":"2024-06-01T18:07:01.463563Z"}]}
{"channel":"book","type":"update","data":[{"symbol":"LINK/USDT","bids":[{"price":18.54928,"qty":0.00000000},{"price":18.54205,"qty":48.75805200}],"asks":[],"checksum":1123180778,"timestamp":"2024-06-01T18:07:01.465227Z"}]}
{"channel":"book","type":"update","data":[{"symbol":"LINK/USDT","bids":[{"price":18.54926,"qty":0.00000000},{"price":18.54204,"qty":269.88270992}],"asks":[],"checksum":211158339,"timestamp":"2024-06-01T18:07:01.561608Z"}]}
{"channel":"book","type":"update","data":[{"symbol":"LINK/USDT","bids":[],"asks":[{"price":18.55756,"qty":9.00000000}],"checksum":3805789232,"timestamp":"2024-06-01T18:07:01.569585Z"}]}
{"channel":"book","type":"update","data":[{"symbol":"LINK/USDT","bids":[],"asks":[{"price":18.55759,"qty":0.00000000},{"price":18.57458,"qty":68.73000000}],"checksum":807463394,"timestamp":"2024-06-01T18:07:01.574857Z"}]}
{"channel":"book","type":"update","data":[{"symbol":"LINK/USDT","bids":[],"asks":[{"price":18.55756,"qty":0.00000000},{"price":18.57459,"qty":80.82295392}],"checksum":924148108,"timestamp":"2024-06-01T18:07:01.585634Z"}]}
{"channel":"book","type":"update","data":[{"symbol":"LINK/USDT","bids":[{"price":18.55104,"qty":40.45102455}],"asks":[],"checksum":2168797733,"timestamp":"2024-06-01T18:07:01.832518Z"}]}
{"channel":"book","type":"update","data":[{"symbol":"LINK/USDT","bids":[{"price":18.55735,"qty":0.00000000},{"price":18.54204,"qty":269.88270992}],"asks":[],"checksum":1650379589,"timestamp":"2024-06-01T18:07:02.051076Z"}]}
{"channel":"book","type":"update","data":[{"symbol":"LINK/USDT","bids":[],"asks":[{"price":18.56251,"qty":16.17525831}],"checksum":2631568854,"timestamp":"2024-06-01T18:07:02.055448Z"}]}
{"channel":"book","type":"update","data":[{"symbol":"LINK/USDT","bids":[{"price":18.55348,"qty":53.94373957}],"asks":[],"checksum":4046280930,"timestamp":"2024-06-01T18:07:02.055484Z"}]}
{"channel":"book","type":"update","data":[{"symbol":"LINK/USDT","bids":[],"asks":[{"price":18.56251,"qty":0.00000000},{"price":18.57459,"qty":80.82295392}],"checksum":2708520314,"timestamp":"2024-06-01T18:07:02.059698Z"}]}
{"channel":"book","type":"update","data":[{"symbol":"LINK/USDT","bids":[{"price":18.55507,"qty":0.00000000},{"price":18.54204,"qty":269.88270992}],"asks":[],"checksum":3332538956,"timestamp":"2024-06-01T18:07:02.063221Z"}]}
{"channel":"book","type":"update","data":[{"symbol":"LINK/USDT","bids":[{"price":18.54998,"qty":0.00000000},{"price":18.53634,"qty":68.73000000}],"asks":[],"checksum":3590033609,"timestamp":"2024-06-01T18:07:02.066008Z"}]}
{"channel":"book","type":"update","data":[{"symbol":"LINK/USDT","bids":[{"price":18.55402,"qty":9.40000000}],"asks":[],"checksum":2266378298,"timestamp":"2024-06-01T18:07:02.066239Z"}]}
{"channel":"book","type":"update","data":[{"symbol":"LINK/USDT","bids":[{"price":18.55348,"qty":0.00000000},{"price":18.53634,"qty":68.73000000}],"asks":[],"checksum":441586928,"timestamp":"2024-06-01T18:07:02.073048Z"}]}
{"channel":"book","type":"update","data":[{"symbol":"LINK/USDT","bids":[{"price":18.55177,"qty":9.40000000}],"asks":[],"checksum":2086341124,"timestamp":"2024-06-01T18:07:02.075818Z"}]}
{"channel":"book","type":"update","data":[{"symbol":"LINK/USDT","bids":[{"price":18.55402,"qty":0.00000000},{"price":18.53634,"qty":68.73000000}],"asks":[],"checksum":2153699726,"timestamp":"2024-06-01T18:07:02.075850Z"}]}
{"channel":"book","type":"update","data":[{"symbol":"LINK/USDT","bids":[{"price":18.55734,"qty":80.90193579}],"asks":[],"checksum":2016500949,"timestamp":"2024-06-01T18:07:02.092216Z"}]}
{"channel":"book","type":"update","data":[{"symbol":"LINK/USDT","bids":[{"price":18.55104,"qty":0.00000000},{"price":18.53634,"qty":68.73000000}],"asks":[],"checksum":1231502988,"timestamp":"2024-06-01T18:07:02.422828Z"}]}
{"channel":"book","type":"update","data":[{"symbol":"LINK/USDT","bids":[{"price":18.55507,"qty":243.48672997}],"asks":[],"checksum":2824744948,"timestamp":"2024-06-01T18:07:02.426648Z"}]}
{"channel":"book","type":"update","data":[{"symbol":"LINK/USDT","bids":[{"price":18.55147,"qty":40.44994248}],"asks":[],"checksum":4234107231,"timestamp":"2024-06-01T18:07:02.462842Z"}]}
{"channel":"book","type":"update","data":[{"symbol":"LINK/USDT","bids":[],"asks":[{"price":18.55766,"qty":16.17948951}],"checksum":2157378263,"timestamp":"2024-06-01T18:07:02.599158Z"}]}
{"channel":"book","type":"update","data":[{"symbol":"LINK/USDT","bids":[{"price":18.55394,"qty":53.94241416}],"asks":[],"checksum":2124691570,"timestamp":"2024-06-01T18:07:02.599328Z"}]}
{"channel":"book","type":"update","data":[{"symbol":"LINK/USDT","bids":[],"asks":[{"price":18.55763,"qty":9.00000000}],"checksum":132806058,"timestamp":"2024-06-01T18:07:02.604383Z"}]}
{"channel":"book","type":"update","data":[{"symbol":"LINK/USDT","bids":[],"asks":[{"price":18.55766,"qty":0.00000000},{"price":18.57458,"qty":68.73000000}],"checksum":1150649109,"timestamp":"2024-06-01T18:07:02.622460Z"}]}
{"channel":"book","type":"update","data":[{"symbol":"LINK/USDT","bids":[{"price":18.55734,"qty":0.00000000},{"price":18.54205,"qty":48.75805200}],"asks":[],"checksum":4269902189,"timestamp":"2024-06-01T18:07:02.683471Z"}]}
{"channel":"book","type":"update","data":[{"symbol":"LINK/USDT","bids":[{"price":18.55507,"qty":0.00000000},{"price":18.54204,"qty":269.88270992}],"asks":[],"checksum":2765658675,"timestamp":"2024-06-01T18:07:02.687280Z"}]}
{"channel":"book","type":"update","data":[{"symbol":"LINK/USDT","bids":[],"asks":[{"price":18.55763,"qty":0.00000000},{"price":18.57459,"qty":80.82295392}],"checksum":3793781468,"timestamp":"2024-06-01T18:07:02.687951Z"}]}
{"channel":"book","type":"update","data":[{"symbol":"LINK/USDT","bids":[{"price":18.55177,"qty":0.00000000},{"price":18.53634,"qty":68.73000000}],"asks":[],"checksum":2218797819,"timestamp":"2024-06-01T18:07:02.690104Z"}]}
{"channel":"book","type":"update","data":[{"symbol":"LINK/USDT","bids":[{"price":18.55424,"qty":9.40000000}],"asks":[],"checksum":3526398702,"timestamp":"2024-06-01T18:07:02.690382Z"}]}
{"channel":"book","type":"update","data":[{"symbol":"LINK/USDT","bids":[{"price":18.55147,"qty":0.00000000},{"price":18.53634,"qty":68.73000000}],"asks":[],"checksum":3140921225,"timestamp":"2024-06-01T18:07:03.052833Z"}]}
{"channel":"book","type":"update","data":[{"symbol":"LINK/USDT","bids":[{"price":18.55123,"qty":40.45051957}],"asks":[],"checksum":443419020,"timestamp":"2024-06-01T18:07:03.093551Z"}]}
{"channel":"book","type":"update","data":[{"symbol":"LINK/USDT","bids":[{"price":18.55768,"qty":80.90079439}],"asks":[],"checksum":2917467558,"timestamp":"2024-06-01T18:07:03.282313Z"}]}
{"channel":"book","type":"update","data":[{"symbol":"LINK/USDT","bids":[],"asks":[{"price":18.56254,"qty":16.17523631}],"checksum":2923840849,"timestamp":"2024-06-01T18:07:03.349737Z"}]}
{"channel":"book","type":"update","data":[{"symbol":"LINK/USDT","bids":[],"asks":[{"price":18.56254,"qty":0.00000000},{"price":18.57459,"qty":80.82295392}],"checksum":2917467558,"timestamp":"2024-06-01T18:07:03.353996Z"}]}
{"channel":"book","type":"update","data":[{"symbol":"LINK/USDT","bids":[],"asks":[{"price":18.56251,"qty":9.00000000}],"checksum":3863622509,"timestamp":"2024-06-01T18:07:03.354671Z"}]}
{"channel":"book","type":"update","data":[{"symbol":"LINK/USDT","bids":[{"price":18.55768,"qty":0.00000000},{"price":18.54204,"qty":269.88270992}],"asks":[],"checksum":378781058,"timestamp":"2024-06-01T18:07:03.362188Z"}]}
{"channel":"book","type":"update","data":[{"symbol":"LINK/USDT","bids":[{"price":18.55394,"qty":0.00000000},{"price":18.53634,"qty":68.73000000}],"asks":[],"checksum":1677543865,"timestamp":"2024-06-01T18:07:03.390978Z"}]}
{"channel":"book","type":"update","data":[{"symbol":"LINK/USDT","bids":[{"price":18.55424,"qty":0.00000000},{"price":18.53633,"qty":47.11000000}],"asks":[],"checksum":260112572,"timestamp":"2024-06-01T18:07:03.393826Z"}]}
{"channel":"book","type":"update","data":[{"symbol":"LINK/USDT","bids":[{"price":18.55196,"qty":9.40000000}],"asks":[],"checksum":2042441686,"timestamp":"2024-06-01T18:07:03.394368Z"}]}
{"channel":"book","type":"update","data":[{"symbol":"LINK/USDT","bids":[{"price":18.55427,"qty":53.94143395}],"asks":[],"checksum":3040978557,"timestamp":"2024-06-01T18:07:03.395793Z"}]}
{"channel":"book","type":"update","data":[{"symbol":"LINK/USDT","bids":[],"asks":[{"price":18.56251,"qty":0.00000000},{"price":18.57459,"qty":80.82295392}],"checksum":3116110451,"timestamp":"2024-06-01T18:07:03.395917Z"}]}
{"channel":"book","type":"update","data":[{"symbol":"LINK/USDT","bids":[{"price":18.55196,"qty":0.00000000},{"price":18.53634,"qty":68.73000000}],"asks":[],"checksum":549668463,"timestamp":"2024-06-01T18:07:03.398720Z"}]}
{"channel":"book","type":"update","data":[{"symbol":"LINK/USDT","bids":[{"price":18.55442,"qty":9.40000000}],"asks":[],"checksum":3088600607,"timestamp":"2024-06-01T18:07:03.398770Z"}]}
{"channel":"book","type":"update","data":[{"symbol":"LINK/USDT","bids":[{"price":18.55427,"qty":0.00000000},{"price":18.53634,"qty":68.73000000}],"asks":[],"checksum":1546451941,"timestamp":"2024-06-01T18:07:03.401028Z"}]}
{"channel":"book","type":"update","data":[{"symbol":"LINK/USDT","bids":[{"price":18.55793,"qty":80.89959942}],"asks":[],"checksum":1896889129,"timestamp":"2024-06-01T18:07:03.403493Z"}]}
{"channel":"book","type":"update","data":[{"symbol":"LINK/USDT","bids":[{"price":18.55442,"qty":0.00000000},{"price":18.53634,"qty":68.73000000}],"asks":[],"checksum":513270334,"timestamp":"2024-06-01T18:07:03.405219Z"}]}
{"channel":"book","type":"update","data":[{"symbol":"LINK/USDT","bids":[{"price":18.55196,"qty":9.40000000}],"asks":[],"checksum":2205128852,"timestamp":"2024-06-01T18:07:03.405231Z"}]}
{"channel":"book","type":"update","data":[{"symbol":"LINK/USDT","bids":[],"asks":[{"price":18.57458,"qty":0.00000000},{"price":18.57961,"qty":48.75805200}],"checksum":3553581287,"timestamp":"2024-06-01T18:07:03.437636Z"}]}
{"channel":"book","type":"update","data":[{"symbol":"LINK/USDT","bids":[{"price":18.55507,"qty":243.48672997}],"asks":[],"checksum":1801390264,"timestamp":"2024-06-01T18:07:03.562888Z"}]}
{"channel":"book","type":"update","data":[{"symbol":"LINK/USDT","bids":[{"price":18.55123,"qty":0.00000000},{"price":18.54204,"qty":269.88270992}],"asks":[],"checksum":2606421320,"timestamp":"2024-06-01T18:07:03.611852Z"}]}
{"channel":"book","type":"update","data":[{"symbol":"LINK/USDT","bids":[],"asks":[{"price":18.57572,"qty":68.73000000}],"checksum":979497208,"timestamp":"2024-06-01T18:07:03.615155Z"}]}
{"channel":"book","type":"update","data":[{"symbol":"LINK/USDT","bids":[{"price":18.55214,"qty":40.44830755}],"asks":[],"checksum":427469001,"timestamp":"2024-06-01T18:07:03.652430Z"}]}
{"channel":"book","type":"update","data":[{"symbol":"LINK/USDT","bids":[{"price":18.55214,"qty":0.00000000},{"price":18.54204,"qty":269.88270992}],"asks":[],"checksum":979497208,"timestamp":"2024-06-01T18:07:03.731296Z"}]}
{"channel":"book","type":"update","data":[{"symbol":"LINK/USDT","bids":[{"price":18.54840,"qty":0.00000000},{"price":18.53634,"qty":68.73000000}],"asks":[],"checksum":280052761,"timestamp":"2024-06-01T18:07:03.930581Z"}]}
{"channel":"book","type":"update","data":[{"symbol":"LINK/USDT","bids":[{"price":18.54205,"qty":0.00000000},{"price":18.53633,"qty":47.11000000}],"asks":[],"checksum":2367483713,"timestamp":"2024-06-01T18:07:03.930839Z"}]}
{"channel":"book","type":"update","data":[{"symbol":"LINK/USDT","bids":[{"price":18.55507,"qty":0.00000000},{"price":18.53570,"qty":161.51454496}],"asks":[],"checksum":1481652165,"timestamp":"2024-06-01T18:07:03.932440Z"}]}
{"channel":"book","type":"update","data":[{"symbol":"LINK/USDT","bids":[{"price":18.53571,"qty":48.75805200}],"asks":[],"checksum":3584660646,"timestamp":"2024-06-01T18:07:03.933445Z"}]}
{"channel":"book","type":"update","data":[{"symbol":"LINK/USDT","bids":[{"price":18.54540,"qty":33.73844400}],"asks":[],"checksum":3904048184,"timestamp":"2024-06-01T18:07:03.933712Z"}]}
{"channel":"book","type":"update","data":[{"symbol":"LINK/USDT","bids":[{"price":18.55447,"qty":53.94086587}],"asks":[],"checksum":3888411462,"timestamp":"2024-06-01T18:07:03.935903Z"}]}
{"channel":"book","type":"update","data":[{"symbol":"LINK/USDT","bids":[],"asks":[{"price":18.56254,"qty":16.17523414}],"checksum":454185821,"timestamp":"2024-06-01T18:07:03.936099Z"}]}
{"channel":"book","type":"update","data":[{"symbol":"LINK/USDT","bids":[{"price":18.53635,"qty":161.50888125}],"asks":[],"checksum":2721178640,"timestamp":"2024-06-01T18:07:03.938078Z"}]}
{"channel":"book","type":"update","data":[{"symbol":"LINK/USDT","bids":[],"asks":[{"price":18.56254,"qty":0.00000000},{"price":18.57572,"qty":68.73000000}],"checksum":682163164,"timestamp":"2024-06-01T18:07:03.940889Z"}]}
{"channel":"book","type":"update","data":[{"symbol":"LINK/USDT","bids":[{"price":18.55447,"qty":0.00000000},{"price":18.53634,"qty":68.73000000}],"asks":[],"checksum":1895711496,"timestamp":"2024-06-01T18:07:03.941027Z"}]}
{"channel":"book","type":"update","data":[{"symbol":"LINK/USDT","bids":[{"price":18.53634,"qty":0.00000000},{"price":18.53633,"qty":47.11000000},{"price":18.53636,"qty":68.73000000}],"asks":[],"checksum":3050641380,"timestamp":"2024-06-01T18:07:03.941263Z"}]}
{"channel":"book","type":"update","data":[{"symbol":"LINK/USDT","bids":[],"asks":[{"price":18.56239,"qty":4.85459356}],"checksum":4122723315,"timestamp":"2024-06-01T18:07:03.955863Z"}]}
{"channel":"book","type":"update","data":[{"symbol":"LINK/USDT","bids":[],"asks":[{"price":18.56261,"qty":0.00000000},{"price":18.57572,"qty":68.73000000}],"checksum":3845928167,"timestamp":"2024-06-01T18:07:03.957670Z"}]}
{"channel":"book","type":"update","data":[{"symbol":"LINK/USDT","bids":[{"price":18.55793,"qty":0.00000000},{"price":18.53633,"qty":47.11000000}],"asks":[],"checksum":2796583400,"timestamp":"2024-06-01T18:07:03.973404Z"}]}
{"channel":"book","type":"update","data":[{"symbol":"LINK/USDT","bids":[],"asks":[{"price":18.57000,"qty":0.00000000},{"price":18.57961,"qty":48.75805200}],"checksum":719019911,"timestamp":"2024-06-01T18:07:03.976362Z"}]}
{"channel":"book","type":"update","data":[{"symbol":"LINK/USDT","bids":[],"asks":[{"price":18.56893,"qty":243.48672997}],"checksum":2693856114,"timestamp":"2024-06-01T18:07:03.977582Z"}]}
{"channel":"book","type":"update","data":[{"symbol":"LINK/USDT","bids":[{"price":18.55199,"qty":9.00000000}],"asks":[],"checksum":4251103544,"timestamp":"2024-06-01T18:07:03.978903Z"}]}
{"channel":"book","type":"update","data":[{"symbol":"LINK/USDT","bids":[],"asks":[{"price":18.56500,"qty":33.73844400}],"checksum":1451113385,"timestamp":"2024-06-01T18:07:03.979065Z"}]}
{"channel":"book","type":"update","data":[{"symbol":"LINK/USDT","bids":[{"price":18.55199,"qty":0.00000000},{"price":18.53633,"qty":47.11000000}],"asks":[],"checksum":657671210,"timestamp":"2024-06-01T18:07:04.000382Z"}]}
{"channel":"book","type":"update","data":[{"symbol":"LINK/USDT","bids":[{"price":18.54700,"qty":0.00000000},{"price":18.53571,"qty":48.75805200}],"asks":[],"checksum":2700016455,"timestamp":"2024-06-01T18:07:04.002494Z"}]}
{"channel":"book","type":"update","data":[{"symbol":"LINK/USDT","bids":[{"price":18.54600,"qty":49.72789312}],"asks":[],"checksum":1956911687,"timestamp":"2024-06-01T18:07:04.007250Z"}]}
{"channel":"book","type":"update","data":[{"symbol":"LINK/USDT","bids":[],"asks":[{"price":18.57193,"qty":0.00000000},{"price":18.57572,"qty":68.73000000}],"checksum":2230660789,"timestamp":"2024-06-01T18:07:04.011419Z"}]}
{"channel":"book","type":"update","data":[{"symbol":"LINK/USDT","bids":[{"price":18.55837,"qty":80.89742100}],"asks":[],"checksum":3292030450,"timestamp":"2024-06-01T18:07:04.013613Z"}]}
{"channel":"book","type":"update","data":[{"symbol":"LINK/USDT","bids":[],"asks":[{"price":18.57572,"qty":0.00000000},{"price":18.57961,"qty":48.75805200},{"price":18.57458,"qty":68.73000000}],"checksum":2891956228,"timestamp":"2024-06-01T18:07:04.016719Z"}]}
{"channel":"book","type":"update","data":[{"symbol":"LINK/USDT","bids":[{"price":18.54925,"qty":0.00000000},{"price":18.53633,"qty":47.11000000}],"asks":[],"checksum":1812591242,"timestamp":"2024-06-01T18:07:04.035036Z"}]}
{"channel":"book","type":"update","data":[{"symbol":"LINK/USDT","bids":[{"price":18.54676,"qty":134.90821594}],"asks":[],"checksum":2582975287,"timestamp":"2024-06-01T18:07:04.039013Z"}]}
{"channel":"book","type":"update","data":[{"symbol":"LINK/USDT","bids":[],"asks":[{"price":18.57458,"qty":0.00000000},{"price":18.57961,"qty":48.75805200}],"checksum":1353290609,"timestamp":"2024-06-01T18:07:04.341733Z"}]}
{"channel":"book","type":"update","data":[{"symbol":"LINK/USDT","bids":[],"asks":[{"price":18.56519,"qty":0.00000000},{"price":18.58197,"qty":1.09947012}],"checksum":37794089,"timestamp":"2024-06-01T18:07:04.347649Z"}]}
{"channel":"book","type":"update","data":[{"symbol":"LINK/USDT","bids":[],"asks":[{"price":18.56271,"qty":40.43770677}],"checksum":4282952133,"timestamp":"2024-06-01T18:07:04.352124Z"}]}
{"channel":"book","type":"update","data":[{"symbol":"LINK/USDT","bids":[],"asks":[{"price":18.56236,"qty":9.00000000}],"checksum":876958998,"timestamp":"2024-06-01T18:07:04.358429Z"}]}
{"channel":"book","type":"update","data":[{"symbol":"LINK/USDT","bids":[{"price":18.55407,"qty":243.48672997}],"asks":[],"checksum":3717077767,"timestamp":"2024-06-01T18:07:04.558657Z"}]}
{"channel":"book","type":"update","data":[{"symbol":"LINK/USDT","bids":[],"asks":[{"price":18.56258,"qty":0.00000000},{"price":18.57961,"qty":48.75805200}],"checksum":2728934624,"timestamp":"2024-06-01T18:07:04.569842Z"}]}
{"channel":"book","type":"update","data":[{"symbol":"LINK/USDT","bids":[{"price":18.55837,"qty":0.00000000},{"price":18.53635,"qty":161.50888125}],"asks":[],"checksum":871325236,"timestamp":"2024-06-01T18:07:04.604773Z"}]}
{"channel":"book","type":"update","data":[{"symbol":"LINK/USDT","bids":[{"price":18.55407,"qty":0.00000000},{"price":18.53633,"qty":47.11000000}],"asks":[],"checksum":1731727886,"timestamp":"2024-06-01T18:07:04.608792Z"}]}
{"channel":"book","type":"update","data":[{"symbol":"LINK/USDT","bids":[],"asks":[{"price":18.55673,"qty":16.18029808}],"checksum":1776249982,"timestamp":"2024-06-01T18:07:04.610033Z"}]}
{"channel":"book","type":"update","data":[{"symbol":"LINK/USDT","bids":[{"price":18.55290,"qty":53.94542310}],"asks":[],"checksum":3060990580,"timestamp":"2024-06-01T18:07:04.610065Z"}]}
{"channel":"book","type":"update","data":[{"symbol":"LINK/USDT","bids":[],"asks":[{"price":18.56964,"qty":80.84523184}],"checksum":2166619635,"timestamp":"2024-06-01T18:07:04.610078Z"}]}
{"channel":"book","type":"update","data":[{"symbol":"LINK/USDT","bids":[{"price":18.55290,"qty":0.00000000},{"price":18.53633,"qty":47.11000000}],"asks":[],"checksum":1586467833,"timestamp":"2024-06-01T18:07:04.615100Z"}]}
{"channel":"book","type":"update","data":[{"symbol":"LINK/USDT","bids":[],"asks":[{"price":18.55673,"qty":0.00000000},{"price":18.57459,"qty":80.82295392}],"checksum":91886403,"timestamp":"2024-06-01T18:07:04.742630Z"}]}
{"channel":"book","type":"update","data":[{"symbol":"LINK/USDT","bids":[{"price":18.55069,"qty":40.45159051}],"asks":[],"checksum":221607152,"timestamp":"2024-06-01T18:07:04.956045Z"}]}
{"channel":"book","type":"update","data":[{"symbol":"LINK/USDT","bids":[],"asks":[{"price":18.57458,"qty":68.73000000}],"checksum":920479540,"timestamp":"2024-06-01T18:07:05.048657Z"}]}
{"channel":"book","type":"update","data":[{"symbol":"LINK/USDT","bids":[],"asks":[{"price":18.56226,"qty":16.17547620}],"checksum":4077931997,"timestamp":"2024-06-01T18:07:05.175323Z"}]}
{"channel":"book","type":"update","data":[{"symbol":"LINK/USDT","bids":[{"price":18.55294,"qty":53.94532065}],"asks":[],"checksum":4072585081,"timestamp":"2024-06-01T18:07:05.175439Z"}]}
{"channel":"book","type":"update","data":[{"symbol":"LINK/USDT","bids":[],"asks":[{"price":18.56226,"qty":0.00000000},{"price":18.57458,"qty":68.73000000}],"checksum":2242896065,"timestamp":"2024-06-01T18:07:05.181370Z"}]}
{"channel":"book","type":"update","data":[{"symbol":"LINK/USDT","bids":[{"price":18.55713,"qty":80.90306896}],"asks":[],"checksum":809709583,"timestamp":"2024-06-01T18:07:05.235013Z"}]}
{"channel":"book","type":"update","data":[{"symbol":"LINK/USDT","bids":[{"price":18.55294,"qty":0.00000000},{"price":18.53636,"qty":68.73000000}],"asks":[],"checksum":2004178376,"timestamp":"2024-06-01T18:07:05.335287Z"}]}
{"channel":"book","type":"update","data":[{"symbol":"LINK/USDT","bids":[{"price":18.55069,"qty":0.00000000},{"price":18.53635,"qty":161.50888125}],"asks":[],"checksum":1858078227,"timestamp":"2024-06-01T18:07:05.548105Z"}]}
{"channel":"book","type":"update","data":[{"symbol":"LINK/USDT","bids":[{"price":18.55407,"qty":243.48672997}],"asks":[],"checksum":2265663490,"timestamp":"2024-06-01T18:07:05.560179Z"}]}
{"channel":"book","type":"update","data":[{"symbol":"LINK/USDT","bids":[{"price":18.55067,"qty":40.45151408}],"asks":[],"checksum":3798503670,"timestamp":"2024-06-01T18:07:05.588390Z"}]}
{"channel":"book","type":"update","data":[{"symbol":"LINK/USDT","bids":[],"asks":[{"price":18.57458,"qty":0.00000000},{"price":18.57459,"qty":80.82295392}],"checksum":3649078066,"timestamp":"2024-06-01T18:07:05.652297Z"}]}
{"channel":"book","type":"update","data":[{"symbol":"LINK/USDT","bids":[{"price":18.55713,"qty":0.00000000},{"price":18.53636,"qty":68.73000000}],"asks":[],"checksum":2320502474,"timestamp":"2024-06-01T18:07:05.751560Z"}]}
{"channel":"book","type":"update","data":[{"symbol":"LINK/USDT","bids":[{"price":18.55196,"qty":0.00000000},{"price":18.53635,"qty":161.50888125}],"asks":[],"checksum":2961133525,"timestamp":"2024-06-01T18:07:05.754281Z"}]}
{"channel":"book","type":"update","data":[{"symbol":"LINK/USDT","bids":[{"price":18.55413,"qty":9.40000000}],"asks":[],"checksum":1914650963,"timestamp":"2024-06-01T18:07:05.754558Z"}]}
{"channel":"book","type":"update","data":[{"symbol":"LINK/USDT","bids":[{"price":18.55407,"qty":0.00000000},{"price":18.53635,"qty":161.50888125}],"asks":[],"checksum":2167427036,"timestamp":"2024-06-01T18:07:05.755502Z"}]}
{"channel":"book","type":"update","data":[{"symbol":"LINK/USDT","bids":[{"price":18.55413,"qty":0.00000000},{"price":18.53633,"qty":47.11000000}],"asks":[],"checksum":3563806252,"timestamp":"2024-06-01T18:07:05.758200Z"}]}
{"channel":"book","type":"update","data":[{"symbol":"LINK/USDT","bids":[],"asks":[{"price":18.55732,"qty":16.17978569}],"checksum":1738977845,"timestamp":"2024-06-01T18:07:05.763099Z"}]}
{"channel":"book","type":"update","data":[{"symbol":"LINK/USDT","bids":[{"price":18.55078,"qty":53.95158963}],"asks":[],"checksum":3059992702,"timestamp":"2024-06-01T18:07:05.763138Z"}]}
{"channel":"book","type":"update","data":[{"symbol":"LINK/USDT","bids":[{"price":18.55078,"qty":0.00000000},{"price":18.53633,"qty":47.11000000}],"asks":[],"checksum":1738977845,"timestamp":"2024-06-01T18:07:05.767500Z"}]}
{"channel":"book","type":"update","data":[{"symbol":"LINK/USDT","bids":[{"price":18.55709,"qty":80.90301457}],"asks":[],"checksum":318506927,"timestamp":"2024-06-01T18:07:05.791663Z"}]}
{"channel":"book","type":"update","data":[{"symbol":"LINK/USDT","bids":[],"asks":[{"price":18.55729,"qty":9.00000000}],"checksum":4156786724,"timestamp":"2024-06-01T18:07:05.796189Z"}]}
{"channel":"book","type":"update","data":[{"symbol":"LINK/USDT","bids":[],"asks":[{"price":18.56236,"qty":0.00000000},{"price":18.56964,"qty":80.84523184}],"checksum":2785370575,"timestamp":"2024-06-01T18:07:06.084636Z"}]}
{"channel":"book","type":"update","data":[{"symbol":"LINK/USDT","bids":[],"asks":[{"price":18.55732,"qty":0.00000000},{"price":18.57459,"qty":80.82295392}],"checksum":2508833819,"timestamp":"2024-06-01T18:07:06.099715Z"}]}
{"channel":"book","type":"update","data":[{"symbol":"LINK/USDT","bids":[{"price":18.55709,"qty":0.00000000},{"price":18.53633,"qty":47.11000000}],"asks":[],"checksum":3771953537,"timestamp":"2024-06-01T18:07:06.382473Z"}]}
{"channel":"book","type":"update","data":[{"symbol":"LINK/USDT","bids":[{"price":18.55141,"qty":9.40000000}],"asks":[],"checksum":3377880261,"timestamp":"2024-06-01T18:07:06.385573Z"}]}
{"channel":"book","type":"update","data":[{"symbol":"LINK/USDT","bids":[],"asks":[{"price":18.55729,"qty":0.00000000},{"price":18.57572,"qty":68.73000000}],"checksum":3809425136,"timestamp":"2024-06-01T18:07:06.388035Z"}]}
{"channel":"book","type":"update","data":[{"symbol":"LINK/USDT","bids":[{"price":18.55070,"qty":9.00000000}],"asks":[],"checksum":2153586724,"timestamp":"2024-06-01T18:07:06.388110Z"}]}
{"channel":"book","type":"update","data":[{"symbol":"LINK/USDT","bids":[{"price":18.55707,"qty":80.90293298}],"asks":[],"checksum":1302091777,"timestamp":"2024-06-01T18:07:06.422914Z"}]}
{"channel":"book","type":"update","data":[{"symbol":"LINK/USDT","bids":[{"price":18.55407,"qty":243.48672997}],"asks":[],"checksum":615168097,"timestamp":"2024-06-01T18:07:06.427156Z"}]}
{"channel":"book","type":"update","data":[{"symbol":"LINK/USDT","bids":[{"price":18.55070,"qty":0.00000000},{"price":18.54204,"qty":269.88270992}],"asks":[],"checksum":3404027300,"timestamp":"2024-06-01T18:07:06.427850Z"}]}
{"channel":"book","type":"update","data":[{"symbol":"LINK/USDT","bids":[],"asks":[{"price":18.56234,"qty":16.17540592}],"checksum":3887659933,"timestamp":"2024-06-01T18:07:06.584541Z"}]}
{"channel":"book","type":"update","data":[{"symbol":"LINK/USDT","bids":[{"price":18.55319,"qty":53.94459288}],"asks":[],"checksum":1555486816,"timestamp":"2024-06-01T18:07:06.584657Z"}]}
{"channel":"book","type":"update","data":[{"symbol":"LINK/USDT","bids":[],"asks":[{"price":18.56236,"qty":9.00000000}],"checksum":840105459,"timestamp":"2024-06-01T18:07:06.588776Z"}]}
{"channel":"book","type":"update","data":[{"symbol":"LINK/USDT","bids":[],"asks":[{"price":18.56234,"qty":0.00000000},{"price":18.57459,"qty":80.82295392}],"checksum":356797636,"timestamp":"2024-06-01T18:07:06.594572Z"}]}
{"channel":"book","type":"update","data":[{"symbol":"LINK/USDT","bids":[{"price":18.55319,"qty":0.00000000},{"price":18.54204,"qty":269.88270992}],"asks":[],"checksum":910847736,"timestamp":"2024-06-01T18:07:06.604799Z"}]}
{"channel":"book","type":"update","data":[{"symbol":"LINK/USDT","bids":[{"price":18.55067,"qty":0.00000000},{"price":18.53636,"qty":68.73000000}],"asks":[],"checksum":1395242508,"timestamp":"2024-06-01T18:07:06.669669Z"}]}
{"channel":"book","type":"update","data":[{"symbol":"LINK/USDT","bids":[{"price":18.55136,"qty":40.44983370}],"asks":[],"checksum":260843284,"timestamp":"2024-06-01T18:07:06.709809Z"}]}
{"channel":"book","type":"update","data":[{"symbol":"LINK/USDT","bids":[{"price":18.55707,"qty":0.00000000},{"price":18.53636,"qty":68.73000000}],"asks":[],"checksum":2183359465,"timestamp":"2024-06-01T18:07:06.957118Z"}]}
{"channel":"book","type":"update","data":[{"symbol":"LINK/USDT","bids":[{"price":18.55141,"qty":0.00000000},{"price":18.53635,"qty":161.50888125}],"asks":[],"checksum":4238168617,"timestamp":"2024-06-01T18:07:06.959819Z"}]}
{"channel":"book","type":"update","data":[{"symbol":"LINK/USDT","bids":[{"price":18.55469,"qty":9.40000000}],"asks":[],"checksum":417552599,"timestamp":"2024-06-01T18:07:06.960058Z"}]}
{"channel":"book","type":"update","data":[{"symbol":"LINK/USDT","bids":[{"price":18.55407,"qty":0.00000000},{"price":18.53635,"qty":161.50888125}],"asks":[],"checksum":2874975223,"timestamp":"2024-06-01T18:07:06.961634Z"}]}
{"channel":"book","type":"update","data":[{"symbol":"LINK/USDT","bids":[{"price":18.55469,"qty":0.00000000},{"price":18.53633,"qty":47.11000000}],"asks":[],"checksum":3210030388,"timestamp":"2024-06-01T18:07:06.964498Z"}]}
{"channel":"book","type":"update","data":[{"symbol":"LINK/USDT","bids":[{"price":18.55777,"qty":80.89966741}],"asks":[],"checksum":2864209862,"timestamp":"2024-06-01T18:07:06.997061Z"}]}
{"channel":"book","type":"update","data":[{"symbol":"LINK/USDT","bids":[{"price":18.55407,"qty":243.48672997}],"asks":[],"checksum":419931366,"timestamp":"2024-06-01T18:07:07.001291Z"}]}
{"channel":"book","type":"update","data":[{"symbol":"LINK/USDT","bids":[],"asks":[{"price":18.56893,"qty":0.00000000},{"price":18.57572,"qty":68.73000000}],"checksum":1046587888,"timestamp":"2024-06-01T18:07:07.105308Z"}]}
{"channel":"book","type":"update","data":[{"symbol":"LINK/USDT","bids":[],"asks":[{"price":18.57572,"qty":0.00000000},{"price":18.57961,"qty":48.75805200},{"price":18.57960,"qty":68.73000000}],"checksum":3983691083,"timestamp":"2024-06-01T18:07:07.106532Z"}]}
{"channel":"book","type":"update","data":[{"symbol":"LINK/USDT","bids":[{"price":18.53636,"qty":0.00000000},{"price":18.53635,"qty":161.50888125},{"price":18.54205,"qty":68.73000000}],"asks":[],"checksum":945173965,"timestamp":"2024-06-01T18:07:07.108162Z"}]}
{"channel":"book","type":"update","data":[{"symbol":"LINK/USDT","bids":[],"asks":[{"price":18.56232,"qty":16.17542570}],"checksum":2948410080,"timestamp":"2024-06-01T18:07:07.108553Z"}]}
{"channel":"book","type":"update","data":[{"symbol":"LINK/USDT","bids":[{"price":18.55440,"qty":53.94105484}],"asks":[],"checksum":612063006,"timestamp":"2024-06-01T18:07:07.108703Z"}]}
{"channel":"book","type":"update","data":[{"symbol":"LINK/USDT","bids":[{"price":18.54676,"qty":0.00000000},{"price":18.54204,"qty":269.88270992}],"asks":[],"checksum":3376467833,"timestamp":"2024-06-01T18:07:07.113752Z"}]}
{"channel":"book","type":"update","data":[{"symbol":"LINK/USDT","bids":[],"asks":[{"price":18.56232,"qty":0.00000000},{"price":18.57960,"qty":68.73000000}],"checksum":4035340914,"timestamp":"2024-06-01T18:07:07.113867Z"}]}
{"channel":"book","type":"update","data":[{"symbol":"LINK/USDT","bids":[{"price":18.55440,"qty":0.00000000},{"price":18.53635,"qty":161.50888125}],"asks":[],"checksum":2514812287,"timestamp":"2024-06-01T18:07:07.113894Z"}]}
{"channel":"book","type":"update","data":[{"symbol":"LINK/USDT","bids":[],"asks":[{"price":18.56271,"qty":0.00000000},{"price":18.57961,"qty":48.75805200}],"checksum":2535233065,"timestamp":"2024-06-01T18:07:07.114017Z"}]}
{"channel":"book","type":"update","data":[{"symbol":"LINK/USDT","bids":[{"price":18.54920,"qty":134.89050254}],"asks":[],"checksum":2837887093,"timestamp":"2024-06-01T18:07:07.119432Z"}]}
{"channel":"book","type":"update","data":[{"symbol":"LINK/USDT","bids":[],"asks":[{"price":18.56542,"qty":40.43181194}],"checksum":4105512962,"timestamp":"2024-06-01T18:07:07.119503Z"}]}
{"channel":"book","type":"update","data":[{"symbol":"LINK/USDT","bids":[],"asks":[{"price":18.56964,"qty":0.00000000},{"price":18.57961,"qty":48.75805200}],"checksum":3087408236,"timestamp":"2024-06-01T18:07:07.130002Z"}]}
{"channel":"book","type":"update","data":[{"symbol":"LINK/USDT","bids":[],"asks":[{"price":18.56239,"qty":0.00000000},{"price":18.58099,"qty":226.44000000}],"checksum":2683141190,"timestamp":"2024-06-01T18:07:07.131017Z"}]}
{"channel":"book","type":"update","data":[{"symbol":"LINK/USDT","bids":[{"price":18.55136,"qty":0.00000000},{"price":18.53635,"qty":161.50888125}],"asks":[],"checksum":1983398562,"timestamp":"2024-06-01T18:07:07.244772Z"}]}
{"channel":"book","type":"update","data":[{"symbol":"LINK/USDT","bids":[],"asks":[{"price":18.56236,"qty":0.00000000},{"price":18.58197,"qty":1.09947012}],"checksum":2376019858,"timestamp":"2024-06-01T18:07:07.249812Z"}]}
{"channel":"book","type":"update","data":[{"symbol":"LINK/USDT","bids":[{"price":18.55211,"qty":40.44851844}],"asks":[],"checksum":2451406788,"timestamp":"2024-06-01T18:07:07.285184Z"}]}
{"channel":"book","type":"update","data":[{"symbol":"LINK/USDT","bids":[],"asks":[{"price":18.56466,"qty":9.00000000}],"checksum":734753685,"timestamp":"2024-06-01T18:07:07.289824Z"}]}
{"channel":"book","type":"update","data":[{"symbol":"LINK/USDT","bids":[],"asks":[{"price":18.56542,"qty":0.00000000},{"price":18.58197,"qty":1.09947012}],"checksum":1716463663,"timestamp":"2024-06-01T18:07:07.463013Z"}]}
{"channel":"book","type":"update","data":[{"symbol":"LINK/USDT","bids":[{"price":18.55777,"qty":0.00000000},{"price":18.53635,"qty":161.50888125}],"asks":[],"checksum":1220887712,"timestamp":"2024-06-01T18:07:07.467125Z"}]}
{"channel":"book","type":"update","data":[{"symbol":"LINK/USDT","bids":[{"price":18.55778,"qty":243.48672997}],"asks":[],"checksum":827501791,"timestamp":"2024-06-01T18:07:07.467145Z"}]}
{"channel":"book","type":"update","data":[{"symbol":"LINK/USDT","bids":[{"price":18.55480,"qty":9.40000000}],"asks":[],"checksum":2243153309,"timestamp":"2024-06-01T18:07:07.469967Z"}]}
{"channel":"book","type":"update","data":[{"symbol":"LINK/USDT","bids":[{"price":18.55778,"qty":0.00000000},{"price":18.54204,"qty":269.88270992}],"asks":[],"checksum":2102297231,"timestamp":"2024-06-01T18:07:07.561137Z"}]}
{"channel":"book","type":"update","data":[{"symbol":"LINK/USDT","bids":[{"price":18.55211,"qty":0.00000000},{"price":18.53635,"qty":161.50888125}],"asks":[],"checksum":1820255351,"timestamp":"2024-06-01T18:07:07.753311Z"}]}
{"channel":"book","type":"update","data":[{"symbol":"LINK/USDT","bids":[{"price":18.55217,"qty":40.44799445}],"asks":[],"checksum":647257292,"timestamp":"2024-06-01T18:07:07.793912Z"}]}
{"channel":"book","type":"update","data":[{"symbol":"LINK/USDT","bids":[{"price":18.55407,"qty":0.00000000},{"price":18.53635,"qty":161.50888125}],"asks":[],"checksum":3404599365,"timestamp":"2024-06-01T18:07:07.798074Z"}]}
{"channel":"book","type":"update","data":[{"symbol":"LINK/USDT","bids":[{"price":18.55859,"qty":80.89610673}],"asks":[],"checksum":3280875526,"timestamp":"2024-06-01T18:07:08.042930Z"}]}
{"channel":"book","type":"update","data":[{"symbol":"LINK/USDT","bids":[],"asks":[{"price":18.55874,"qty":16.17854125}],"checksum":3195850131,"timestamp":"2024-06-01T18:07:08.049685Z"}]}
{"channel":"book","type":"update","data":[{"symbol":"LINK/USDT","bids":[],"asks":[{"price":18.56460,"qty":40.43359488}],"checksum":2733259391,"timestamp":"2024-06-01T18:07:08.049709Z"}]}
{"channel":"book","type":"update","data":[{"symbol":"LINK/USDT","bids":[{"price":18.55474,"qty":53.94008729}],"asks":[],"checksum":2602886149,"timestamp":"2024-06-01T18:07:08.049722Z"}]}
{"channel":"book","type":"update","data":[{"symbol":"LINK/USDT","bids":[],"asks":[{"price":18.55874,"qty":0.00000000},{"price":18.58072,"qty":80.79702538}],"checksum":152022658,"timestamp":"2024-06-01T18:07:08.116423Z"}]}
{"channel":"book","type":"update","data":[{"symbol":"LINK/USDT","bids":[{"price":18.55474,"qty":0.00000000},{"price":18.54204,"qty":269.88270992}],"asks":[],"checksum":3517188022,"timestamp":"2024-06-01T18:07:08.116636Z"}]}
{"channel":"book","type":"update","data":[{"symbol":"LINK/USDT","bids":[{"price":18.55217,"qty":0.00000000},{"price":18.53635,"qty":161.50888125}],"asks":[],"checksum":3696839694,"timestamp":"2024-06-01T18:07:08.328885Z"}]}
{"channel":"book","type":"update","data":[{"symbol":"LINK/USDT","bids":[{"price":18.55480,"qty":0.00000000},{"price":18.53633,"qty":47.11000000}],"asks":[],"checksum":1879995386,"timestamp":"2024-06-01T18:07:08.331713Z"}]}
{"channel":"book","type":"update","data":[{"symbol":"LINK/USDT","bids":[],"asks":[{"price":18.56457,"qty":9.00000000}],"checksum":2578982598,"timestamp":"2024-06-01T18:07:08.334991Z"}]}
{"channel":"book","type":"update","data":[{"symbol":"LINK/USDT","bids":[{"price":18.55218,"qty":40.44798805}],"asks":[],"checksum":2075324667,"timestamp":"2024-06-01T18:07:08.369026Z"}]}
{"channel":"book","type":"update","data":[{"symbol":"LINK/USDT","bids":[],"asks":[{"price":18.56466,"qty":0.00000000},{"price":18.58072,"qty":80.79702538}],"checksum":2353037205,"timestamp":"2024-06-01T18:07:08.373567Z"}]}
{"channel":"book","type":"update","data":[{"symbol":"LINK/USDT","bids":[{"price":18.55607,"qty":243.48672997}],"asks":[],"checksum":2316093925,"timestamp":"2024-06-01T18:07:08.562350Z"}]}
{"channel":"book","type":"update","data":[{"symbol":"LINK/USDT","bids":[{"price":18.55859,"qty":0.00000000},{"price":18.53635,"qty":161.50888125}],"asks":[],"checksum":309616152,"timestamp":"2024-06-01T18:07:08.658826Z"}]}
{"channel":"book","type":"update","data":[{"symbol":"LINK/USDT","bids":[{"price":18.55607,"qty":0.00000000},{"price":18.53633,"qty":47.11000000}],"asks":[],"checksum":3233545545,"timestamp":"2024-06-01T18:07:08.663512Z"}]}
{"channel":"book","type":"update","data":[{"symbol":"LINK/USDT","bids":[],"asks":[{"price":18.56500,"qty":0.00000000},{"price":18.58099,"qty":226.44000000}],"checksum":3801650341,"timestamp":"2024-06-01T18:07:08.666162Z"}]}
{"channel":"book","type":"update","data":[{"symbol":"LINK/USDT","bids":[{"price":18.55291,"qty":9.40000000}],"asks":[],"checksum":3378936168,"timestamp":"2024-06-01T18:07:08.666329Z"}]}
{"channel":"book","type":"update","data":[{"symbol":"LINK/USDT","bids":[],"asks":[{"price":18.55927,"qty":16.17808367}],"checksum":322126974,"timestamp":"2024-06-01T18:07:08.667780Z"}]}
{"channel":"book","type":"update","data":[{"symbol":"LINK/USDT","bids":[{"price":18.55230,"qty":53.94720401}],"asks":[],"checksum":334456882,"timestamp":"2024-06-01T18:07:08.667916Z"}]}
{"channel":"book","type":"update","data":[{"symbol":"LINK/USDT","bids":[],"asks":[{"price":18.56800,"qty":33.73844400}],"checksum":1583955586,"timestamp":"2024-06-01T18:07:08.669024Z"}]}
{"channel":"book","type":"update","data":[{"symbol":"LINK/USDT","bids":[{"price":18.55230,"qty":0.00000000},{"price":18.53635,"qty":161.50888125}],"asks":[],"checksum":3625939364,"timestamp":"2024-06-01T18:07:08.672394Z"}]}
{"channel":"book","type":"update","data":[{"symbol":"LINK/USDT","bids":[{"price":18.55863,"qty":80.89586280}],"asks":[],"checksum":1106404217,"timestamp":"2024-06-01T18:07:08.698955Z"}]}
{"channel":"book","type":"update","data":[{"symbol":"LINK/USDT","bids":[],"asks":[{"price":18.55924,"qty":9.00000000}],"checksum":351748366,"timestamp":"2024-06-01T18:07:08.703569Z"}]}
{"channel":"book","type":"update","data":[{"symbol":"LINK/USDT","bids":[],"asks":[{"price":18.55927,"qty":0.00000000},{"price":18.57961,"qty":48.75805200}],"checksum":4128378480,"timestamp":"2024-06-01T18:07:08.707797Z"}]}
{"channel":"book","type":"update","data":[{"symbol":"LINK/USDT","bids":[{"price":18.55218,"qty":0.00000000},{"price":18.53635,"qty":161.50888125}],"asks":[],"checksum":1986412656,"timestamp":"2024-06-01T18:07:08.994210Z"}]}
{"channel":"book","type":"update","data":[{"symbol":"LINK/USDT","bids":[{"price":18.55291,"qty":0.00000000},{"price":18.53633,"qty":47.11000000}],"asks":[],"checksum":4103258448,"timestamp":"2024-06-01T18:07:08.997030Z"}]}
{"channel":"book","type":"update","data":[{"symbol":"LINK/USDT","bids":[],"asks":[{"price":18.55924,"qty":0.00000000},{"price":18.58072,"qty":80.79702538}],"checksum":282342151,"timestamp":"2024-06-01T18:07:08.998785Z"}]}
{"channel":"book","type":"update","data":[{"symbol":"LINK/USDT","bids":[{"price":18.55221,"qty":40.44793366}],"asks":[],"checksum":599985059,"timestamp":"2024-06-01T18:07:09.034424Z"}]}
{"channel":"book","type":"update","data":[{"symbol":"LINK/USDT","bids":[{"price":18.55863,"qty":0.00000000},{"price":18.53633,"qty":47.11000000}],"asks":[],"checksum":2123557111,"timestamp":"2024-06-01T18:07:09.169326Z"}]}
{"channel":"book","type":"update","data":[{"symbol":"LINK/USDT","bids":[{"price":18.55294,"qty":9.40000000}],"asks":[],"checksum":1831763380,"timestamp":"2024-06-01T18:07:09.172151Z"}]}
{"channel":"book","type":"update","data":[{"symbol":"LINK/USDT","bids":[{"price":18.55877,"qty":80.89533711}],"asks":[],"checksum":2090118897,"timestamp":"2024-06-01T18:07:09.209588Z"}]}
{"channel":"book","type":"update","data":[{"symbol":"LINK/USDT","bids":[{"price":18.55221,"qty":0.00000000},{"price":18.53635,"qty":161.50888125}],"asks":[],"checksum":2147991956,"timestamp":"2024-06-01T18:07:09.506444Z"}]}
{"channel":"book","type":"update","data":[{"symbol":"LINK/USDT","bids":[{"price":18.55294,"qty":0.00000000},{"price":18.53633,"qty":47.11000000}],"asks":[],"checksum":17403510,"timestamp":"2024-06-01T18:07:09.509371Z"}]}
{"channel":"book","type":"update","data":[{"symbol":"LINK/USDT","bids":[{"price":18.55607,"qty":243.48672997}],"asks":[],"checksum":2541454728,"timestamp":"2024-06-01T18:07:09.510913Z"}]}
{"channel":"book","type":"update","data":[{"symbol":"LINK/USDT","bids":[],"asks":[{"price":18.57193,"qty":243.48672997}],"checksum":4217856053,"timestamp":"2024-06-01T18:07:09.511065Z"}]}
{"channel":"book","type":"update","data":[{"symbol":"LINK/USDT","bids":[],"asks":[{"price":18.55923,"qty":16.17812145}],"checksum":1483594810,"timestamp":"2024-06-01T18:07:09.595149Z"}]}
{"channel":"book","type":"update","data":[{"symbol":"LINK/USDT","bids":[{"price":18.55514,"qty":53.93894476}],"asks":[],"checksum":3314803995,"timestamp":"2024-06-01T18:07:09.595322Z"}]}
{"channel":"book","type":"update","data":[{"symbol":"LINK/USDT","bids":[],"asks":[{"price":18.55920,"qty":9.00000000}],"checksum":3006602546,"timestamp":"2024-06-01T18:07:09.599911Z"}]}
{"channel":"book","type":"update","data":[{"symbol":"LINK/USDT","bids":[],"asks":[{"price":18.55923,"qty":0.00000000},{"price":18.57960,"qty":68.73000000}],"checksum":2227538975,"timestamp":"2024-06-01T18:07:09.603749Z"}]}
{"channel":"book","type":"update","data":[{"symbol":"LINK/USDT","bids":[{"price":18.55877,"qty":0.00000000},{"price":18.53635,"qty":161.50888125}],"asks":[],"checksum":1930355264,"timestamp":"2024-06-01T18:07:09.764321Z"}]}
{"channel":"book","type":"update","data":[{"symbol":"LINK/USDT","bids":[{"price":18.55607,"qty":0.00000000},{"price":18.53633,"qty":47.11000000}],"asks":[],"checksum":4070151653,"timestamp":"2024-06-01T18:07:09.768654Z"}]}
{"channel":"book","type":"update","data":[{"symbol":"LINK/USDT","bids":[],"asks":[{"price":18.55920,"qty":0.00000000},{"price":18.57961,"qty":48.75805200}],"checksum":91457411,"timestamp":"2024-06-01T18:07:09.769302Z"}]}
{"channel":"book","type":"update","data":[{"symbol":"LINK/USDT","bids":[{"price":18.55230,"qty":40.44777731}],"asks":[],"checksum":1231967521,"timestamp":"2024-06-01T18:07:10.157626Z"}]}
{"channel":"book","type":"update","data":[{"symbol":"LINK/USDT","bids":[{"price":18.55530,"qty":9.40000000}],"asks":[],"checksum":18067737,"timestamp":"2024-06-01T18:07:10.160641Z"}]}
{"channel":"book","type":"update","data":[{"symbol":"LINK/USDT","bids":[],"asks":[{"price":18.55871,"qty":16.17857546}],"checksum":778243637,"timestamp":"2024-06-01T18:07:10.212958Z"}]}
{"channel":"book","type":"update","data":[{"symbol":"LINK/USDT","bids":[{"price":18.55514,"qty":0.00000000},{"price":18.53635,"qty":161.50888125}],"asks":[],"checksum":3605271436,"timestamp":"2024-06-01T18:07:10.263264Z"}]}
{"channel":"book","type":"update","data":[{"symbol":"LINK/USDT","bids":[{"price":18.55303,"qty":9.40000000}],"asks":[],"checksum":535273870,"timestamp":"2024-06-01T18:07:10.265988Z"}]}
{"channel":"book","type":"update","data":[{"symbol":"LINK/USDT","bids":[{"price":18.55530,"qty":0.00000000},{"price":18.53635,"qty":161.50888125}],"asks":[],"checksum":379907194,"timestamp":"2024-06-01T18:07:10.266028Z"}]}
{"channel":"book","type":"update","data":[{"symbol":"LINK/USDT","bids":[{"price":18.55460,"qty":53.94051044}],"asks":[],"checksum":1796351528,"timestamp":"2024-06-01T18:07:10.266632Z"}]}
{"channel":"book","type":"update","data":[{"symbol":"LINK/USDT","bids":[{"price":18.55303,"qty":0.00000000},{"price":18.53635,"qty":161.50888125}],"asks":[],"checksum":1566927509,"timestamp":"2024-06-01T18:07:10.269206Z"}]}
{"channel":"book","type":"update","data":[{"symbol":"LINK/USDT","bids":[{"price":18.55510,"qty":9.40000000}],"asks":[],"checksum":29375481,"timestamp":"2024-06-01T18:07:10.269296Z"}]}
{"channel":"book","type":"update","data":[{"symbol":"LINK/USDT","bids":[{"price":18.55460,"qty":0.00000000},{"price":18.53635,"qty":161.50888125}],"asks":[],"checksum":2283330494,"timestamp":"2024-06-01T18:07:10.315302Z"}]}
{"channel":"book","type":"update","data":[{"symbol":"LINK/USDT","bids":[],"asks":[{"price":18.55868,"qty":9.00000000}],"checksum":1818680790,"timestamp":"2024-06-01T18:07:10.320179Z"}]}
{"channel":"book","type":"update","data":[{"symbol":"LINK/USDT","bids":[],"asks":[{"price":18.56469,"qty":0.00000000},{"price":18.57960,"qty":68.73000000}],"checksum":2086022792,"timestamp":"2024-06-01T18:07:10.322803Z"}]}
{"channel":"book","type":"update","data":[{"symbol":"LINK/USDT","bids":[],"asks":[{"price":18.56458,"qty":9.40000000}],"checksum":1577773542,"timestamp":"2024-06-01T18:07:10.322992Z"}]}
{"channel":"book","type":"update","data":[{"symbol":"LINK/USDT","bids":[{"price":18.55866,"qty":80.89517475}],"asks":[],"checksum":543441826,"timestamp":"2024-06-01T18:07:10.377705Z"}]}
{"channel":"book","type":"update","data":[{"symbol":"LINK/USDT","bids":[],"asks":[{"price":18.56457,"qty":0.00000000},{"price":18.57960,"qty":68.73000000}],"checksum":3620243551,"timestamp":"2024-06-01T18:07:10.381973Z"}]}
{"channel":"book","type":"update","data":[{"symbol":"LINK/USDT","bids":[{"price":18.55607,"qty":243.48672997}],"asks":[],"checksum":2888303511,"timestamp":"2024-06-01T18:07:10.560052Z"}]}
{"channel":"book","type":"update","data":[{"symbol":"LINK/USDT","bids":[{"price":18.55230,"qty":0.00000000},{"price":18.54204,"qty":269.88270992}],"asks":[],"checksum":23384202,"timestamp":"2024-06-01T18:07:10.693944Z"}]}
{"channel":"book","type":"update","data":[{"symbol":"LINK/USDT","bids":[{"price":18.55510,"qty":0.00000000},{"price":18.53635,"qty":161.50888125}],"asks":[],"checksum":1184061715,"timestamp":"2024-06-01T18:07:10.696618Z"}]}
{"channel":"book","type":"update","data":[{"symbol":"LINK/USDT","bids":[{"price":18.55238,"qty":40.44760216}],"asks":[],"checksum":3234943601,"timestamp":"2024-06-01T18:07:10.734215Z"}]}
{"channel":"book","type":"update","data":[{"symbol":"LINK/USDT","bids":[{"price":18.55866,"qty":0.00000000},{"price":18.53635,"qty":161.50888125}],"asks":[],"checksum":2284535937,"timestamp":"2024-06-01T18:07:10.849505Z"}]}
{"channel":"book","type":"update","data":[{"symbol":"LINK/USDT","bids":[{"price":18.55607,"qty":0.00000000},{"price":18.53633,"qty":47.11000000}],"asks":[],"checksum":2843898180,"timestamp":"2024-06-01T18:07:10.853885Z"}]}
{"channel":"book","type":"update","data":[{"symbol":"LINK/USDT","bids":[{"price":18.55311,"qty":9.40000000}],"asks":[],"checksum":4009211058,"timestamp":"2024-06-01T18:07:10.856792Z"}]}
{"channel":"book","type":"update","data":[{"symbol":"LINK/USDT","bids":[],"asks":[{"price":18.55871,"qty":0.00000000},{"price":18.57961,"qty":48.75805200}],"checksum":2367571704,"timestamp":"2024-06-01T18:07:11.131743Z"}]}
{"channel":"book","type":"update","data":[{"symbol":"LINK/USDT","bids":[],"asks":[{"price":18.55918,"qty":16.17825405}],"checksum":3255659518,"timestamp":"2024-06-01T18:07:11.135375Z"}]}
{"channel":"book","type":"update","data":[{"symbol":"LINK/USDT","bids":[{"price":18.55500,"qty":53.93934000}],"asks":[],"checksum":1214681277,"timestamp":"2024-06-01T18:07:11.135510Z"}]}
{"channel":"book","type":"update","data":[{"symbol":"LINK/USDT","bids":[],"asks":[{"price":18.55868,"qty":0.00000000},{"price":18.57961,"qty":48.75805200}],"checksum":947531001,"timestamp":"2024-06-01T18:07:11.137641Z"}]}
{"channel":"book","type":"update","data":[{"symbol":"LINK/USDT","bids":[{"price":18.55238,"qty":0.00000000},{"price":18.53635,"qty":161.50888125}],"asks":[],"checksum":2768828799,"timestamp":"2024-06-01T18:07:11.201417Z"}]}
{"channel":"book","type":"update","data":[{"symbol":"LINK/USDT","bids":[{"price":18.55311,"qty":0.00000000},{"price":18.53633,"qty":47.11000000}],"asks":[],"checksum":1074668842,"timestamp":"2024-06-01T18:07:11.228875Z"}]}
{"channel":"book","type":"update","data":[{"symbol":"LINK/USDT","bids":[{"price":18.55236,"qty":40.44760216}],"asks":[],"checksum":173037159,"timestamp":"2024-06-01T18:07:11.241482Z"}]}
{"channel":"book","type":"update","data":[{"symbol":"LINK/USDT","bids":[],"asks":[{"price":18.55918,"qty":0.00000000},{"price":18.58072,"qty":80.79702538}],"checksum":280034383,"timestamp":"2024-06-01T18:07:11.278136Z"}]}
{"channel":"book","type":"update","data":[{"symbol":"LINK/USDT","bids":[],"asks":[{"price":18.56455,"qty":9.00000000}],"checksum":2566005663,"timestamp":"2024-06-01T18:07:11.285421Z"}]}
{"channel":"book","type":"update","data":[{"symbol":"LINK/USDT","bids":[{"price":18.55236,"qty":0.00000000},{"price":18.53633,"qty":47.11000000}],"asks":[],"checksum":3534508242,"timestamp":"2024-06-01T18:07:11.313974Z"}]}
{"channel":"book","type":"update","data":[{"symbol":"LINK/USDT","bids":[{"price":18.55500,"qty":0.00000000},{"price":18.53571,"qty":48.75805200}],"asks":[],"checksum":3407950489,"timestamp":"2024-06-01T18:07:11.348451Z"}]}
{"channel":"book","type":"update","data":[{"symbol":"LINK/USDT","bids":[{"price":18.54946,"qty":4.85388304}],"asks":[],"checksum":484862392,"timestamp":"2024-06-01T18:07:11.352079Z"}]}
{"channel":"book","type":"update","data":[{"symbol":"LINK/USDT","bids":[],"asks":[{"price":18.56436,"qty":4.85395505}],"checksum":2803860002,"timestamp":"2024-06-01T18:07:11.367633Z"}]}
{"channel":"book","type":"update","data":[{"symbol":"LINK/USDT","bids":[{"price":18.54927,"qty":0.00000000},{"price":18.53571,"qty":48.75805200},{"price":18.54968,"qty":8.40544782}],"asks":[],"checksum":228101059,"timestamp":"2024-06-01T18:07:11.370903Z"}]}
{"channel":"book","type":"update","data":[{"symbol":"LINK/USDT","bids":[],"asks":[{"price":18.56454,"qty":65.00000000}],"checksum":2223783373,"timestamp":"2024-06-01T18:07:11.380648Z"}]}
{"channel":"book","type":"update","data":[{"symbol":"LINK/USDT","bids":[{"price":18.54971,"qty":9.00000000}],"asks":[],"checksum":1455037906,"timestamp":"2024-06-01T18:07:11.386360Z"}]}
{"channel":"book","type":"update","data":[{"symbol":"LINK/USDT","bids":[{"price":18.54205,"qty":0.00000000},{"price":18.53633,"qty":47.11000000}],"asks":[],"checksum":573709806,"timestamp":"2024-06-01T18:07:11.390785Z"}]}
{"channel":"book","type":"update","data":[{"symbol":"LINK/USDT","bids":[{"price":18.55779,"qty":80.89841435}],"asks":[],"checksum":3673197531,"timestamp":"2024-06-01T18:07:11.517223Z"}]}
{"channel":"book","type":"update","data":[{"symbol":"LINK/USDT","bids":[],"asks":[{"price":18.56458,"qty":0.00000000},{"price":18.57960,"qty":68.73000000}],"checksum":1486914056,"timestamp":"2024-06-01T18:07:11.520144Z"}]}
{"channel":"book","type":"update","data":[{"symbol":"LINK/USDT","bids":[],"asks":[{"price":18.56431,"qty":9.40000000}],"checksum":2296711358,"timestamp":"2024-06-01T18:07:11.520291Z"}]}
{"channel":"book","type":"update","data":[{"symbol":"LINK/USDT","bids":[{"price":18.55780,"qty":243.48672997}],"asks":[],"checksum":1775917726,"timestamp":"2024-06-01T18:07:11.521244Z"}]}
{"channel":"book","type":"update","data":[{"symbol":"LINK/USDT","bids":[{"price":18.54971,"qty":0.00000000},{"price":18.53635,"qty":161.50888125}],"asks":[],"checksum":3997620738,"timestamp":"2024-06-01T18:07:11.522258Z"}]}
{"channel":"book","type":"update","data":[{"symbol":"LINK/USDT","bids":[{"price":18.54067,"qty":68.73000000}],"asks":[],"checksum":3243604848,"timestamp":"2024-06-01T18:07:11.523462Z"}]}
{"channel":"book","type":"update","data":[{"symbol":"LINK/USDT","bids":[],"asks":[{"price":18.56541,"qty":0.00000000},{"price":18.57960,"qty":68.73000000}],"checksum":1185956162,"timestamp":"2024-06-01T18:07:11.524138Z"}]}
{"channel":"book","type":"update","data":[{"symbol":"LINK/USDT","bids":[],"asks":[{"price":18.56425,"qty":16.17383791}],"checksum":4061723171,"timestamp":"2024-06-01T18:07:11.648436Z"}]}
{"channel":"book","type":"update","data":[{"symbol":"LINK/USDT","bids":[{"price":18.55443,"qty":53.94129848}],"asks":[],"checksum":3779908219,"timestamp":"2024-06-01T18:07:11.648495Z"}]}
{"channel":"book","type":"update","data":[{"symbol":"LINK/USDT","bids":[],"asks":[{"price":18.56425,"qty":0.00000000},{"price":18.57960,"qty":68.73000000}],"checksum":1441032474,"timestamp":"2024-06-01T18:07:11.652889Z"}]}
{"channel":"book","type":"update","data":[{"symbol":"LINK/USDT","bids":[],"asks":[{"price":18.56424,"qty":65.00000000}],"checksum":1219575544,"timestamp":"2024-06-01T18:07:11.653526Z"}]}
{"channel":"book","type":"update","data":[{"symbol":"LINK/USDT","bids":[],"asks":[{"price":18.56454,"qty":0.00000000},{"price":18.57960,"qty":68.73000000}],"checksum":864868601,"timestamp":"2024-06-01T18:07:11.707998Z"}]}
{"channel":"book","type":"update","data":[{"symbol":"LINK/USDT","bids":[],"asks":[{"price":18.57960,"qty":0.00000000},{"price":18.57961,"qty":48.75805200},{"price":18.57458,"qty":68.73000000}],"checksum":2667265384,"timestamp":"2024-06-01T18:07:11.866385Z"}]}
{"channel":"book","type":"update","data":[{"symbol":"LINK/USDT","bids":[{"price":18.55443,"qty":0.00000000},{"price":18.54067,"qty":68.73000000}],"asks":[],"checksum":2377061680,"timestamp":"2024-06-01T18:07:11.951160Z"}]}
{"channel":"book","type":"update","data":[{"symbol":"LINK/USDT","bids":[{"price":18.55779,"qty":0.00000000},{"price":18.53635,"qty":161.50888125}],"asks":[],"checksum":1902809775,"timestamp":"2024-06-01T18:07:12.109237Z"}]}
{"channel":"book","type":"update","data":[{"symbol":"LINK/USDT","bids":[{"price":18.55780,"qty":0.00000000},{"price":18.53633,"qty":47.11000000}],"asks":[],"checksum":1651158485,"timestamp":"2024-06-01T18:07:12.113979Z"}]}
{"channel":"book","type":"update","data":[{"symbol":"LINK/USDT","bids":[],"asks":[{"price":18.56431,"qty":0.00000000},{"price":18.57961,"qty":48.75805200}],"checksum":643724160,"timestamp":"2024-06-01T18:07:12.116747Z"}]}
{"channel":"book","type":"update","data":[{"symbol":"LINK/USDT","bids":[],"asks":[{"price":18.56410,"qty":9.40000000}],"checksum":1401544802,"timestamp":"2024-06-01T18:07:12.116901Z"}]}
{"channel":"book","type":"update","data":[{"symbol":"LINK/USDT","bids":[{"price":18.55041,"qty":9.40000000}],"asks":[],"checksum":3954414804,"timestamp":"2024-06-01T18:07:12.117739Z"}]}
{"channel":"book","type":"update","data":[{"symbol":"LINK/USDT","bids":[{"price":18.55767,"qty":80.90058908}],"asks":[],"checksum":1873603498,"timestamp":"2024-06-01T18:07:12.149401Z"}]}
{"channel":"book","type":"update","data":[{"symbol":"LINK/USDT","bids":[],"asks":[{"price":18.56424,"qty":0.00000000},{"price":18.57961,"qty":48.75805200}],"checksum":2187210270,"timestamp":"2024-06-01T18:07:12.207539Z"}]}
{"channel":"book","type":"update","data":[{"symbol":"LINK/USDT","bids":[],"asks":[{"price":18.56435,"qty":65.00000000}],"checksum":670872685,"timestamp":"2024-06-01T18:07:12.207752Z"}]}
{"channel":"book","type":"update","data":[{"symbol":"LINK/USDT","bids":[],"asks":[{"price":18.55832,"qty":16.17898816}],"checksum":2305980888,"timestamp":"2024-06-01T18:07:12.346030Z"}]}
{"channel":"book","type":"update","data":[{"symbol":"LINK/USDT","bids":[{"price":18.55434,"qty":53.94147649}],"asks":[],"checksum":3847015588,"timestamp":"2024-06-01T18:07:12.346139Z"}]}
{"channel":"book","type":"update","data":[{"symbol":"LINK/USDT","bids":[],"asks":[{"price":18.55829,"qty":9.00000000}],"checksum":3632549668,"timestamp":"2024-06-01T18:07:12.351359Z"}]}
{"channel":"book","type":"update","data":[{"symbol":"LINK/USDT","bids":[],"asks":[{"price":18.55832,"qty":0.00000000},{"price":18.57458,"qty":68.73000000}],"checksum":1079844680,"timestamp":"2024-06-01T18:07:12.351918Z"}]}
{"channel":"book","type":"update","data":[{"symbol":"LINK/USDT","bids":[{"price":18.55434,"qty":0.00000000},{"price":18.54067,"qty":68.73000000}],"asks":[],"checksum":744729140,"timestamp":"2024-06-01T18:07:12.351996Z"}]}
{"channel":"book","type":"update","data":[{"symbol":"LINK/USDT","bids":[{"price":18.55113,"qty":40.45025828}],"asks":[],"checksum":611539847,"timestamp":"2024-06-01T18:07:12.455951Z"}]}
{"channel":"book","type":"update","data":[{"symbol":"LINK/USDT","bids":[{"price":18.54920,"qty":0.00000000},{"price":18.54067,"qty":68.73000000}],"asks":[],"checksum":2727343172,"timestamp":"2024-06-01T18:07:12.469924Z"}]}
{"channel":"book","type":"update","data":[{"symbol":"LINK/USDT","bids":[{"price":18.54633,"qty":134.91197434}],"asks":[],"checksum":3659358014,"timestamp":"2024-06-01T18:07:12.473905Z"}]}
{"channel":"book","type":"update","data":[{"symbol":"LINK/USDT","bids":[{"price":18.54946,"qty":0.00000000},{"price":18.54067,"qty":68.73000000}],"asks":[],"checksum":2880749441,"timestamp":"2024-06-01T18:07:12.477174Z"}]}
{"channel":"book","type":"update","data":[{"symbol":"LINK/USDT","bids":[{"price":18.54067,"qty":0.00000000},{"price":18.53635,"qty":161.50888125}],"asks":[],"checksum":613873996,"timestamp":"2024-06-01T18:07:12.477823Z"}]}
{"channel":"book","type":"update","data":[{"symbol":"LINK/USDT","bids":[{"price":18.55307,"qty":243.48672997}],"asks":[],"checksum":706969693,"timestamp":"2024-06-01T18:07:12.559189Z"}]}
{"channel":"book","type":"update","data":[{"symbol":"LINK/USDT","bids":[],"asks":[{"price":18.56409,"qty":65.00000000}],"checksum":4172542821,"timestamp":"2024-06-01T18:07:12.563838Z"}]}
{"channel":"book","type":"update","data":[{"symbol":"LINK/USDT","bids":[],"asks":[{"price":18.56455,"qty":0.00000000},{"price":18.57458,"qty":68.73000000}],"checksum":3168409563,"timestamp":"2024-06-01T18:07:12.563948Z"}]}
{"channel":"book","type":"update","data":[{"symbol":"LINK/USDT","bids":[],"asks":[{"price":18.56410,"qty":0.00000000},{"price":18.57459,"qty":80.82295392}],"checksum":603463463,"timestamp":"2024-06-01T18:07:12.701590Z"}]}
{"channel":"book","type":"update","data":[{"symbol":"LINK/USDT","bids":[],"asks":[{"price":18.56336,"qty":9.40000000}],"checksum":1598655072,"timestamp":"2024-06-01T18:07:12.701744Z"}]}
{"channel":"book","type":"update","data":[{"symbol":"LINK/USDT","bids":[],"asks":[{"price":18.56409,"qty":0.00000000},{"price":18.57459,"qty":80.82295392}],"checksum":2727372212,"timestamp":"2024-06-01T18:07:12.706591Z"}]}
{"channel":"book","type":"update","data":[{"symbol":"LINK/USDT","bids":[],"asks":[{"price":18.56335,"qty":65.00000000}],"checksum":1960244425,"timestamp":"2024-06-01T18:07:12.706607Z"}]}
{"channel":"book","type":"update","data":[{"symbol":"LINK/USDT","bids":[{"price":18.55767,"qty":0.00000000},{"price":18.53635,"qty":161.50888125}],"asks":[],"checksum":3272526221,"timestamp":"2024-06-01T18:07:12.740252Z"}]}
{"channel":"book","type":"update","data":[{"symbol":"LINK/USDT","bids":[{"price":18.53768,"qty":68.73000000}],"asks":[],"checksum":15671761,"timestamp":"2024-06-01T18:07:12.743562Z"}]}
{"channel":"book","type":"update","data":[{"symbol":"LINK/USDT","bids":[{"price":18.55307,"qty":0.00000000},{"price":18.53635,"qty":161.50888125}],"asks":[],"checksum":2659487285,"timestamp":"2024-06-01T18:07:12.744384Z"}]}
{"channel":"book","type":"update","data":[{"symbol":"LINK/USDT","bids":[],"asks":[{"price":18.56435,"qty":0.00000000},{"price":18.57459,"qty":80.82295392}],"checksum":2796255426,"timestamp":"2024-06-01T18:07:12.744656Z"}]}
{"channel":"book","type":"update","data":[{"symbol":"LINK/USDT","bids":[{"price":18.55634,"qty":80.90530445}],"asks":[],"checksum":2168408340,"timestamp":"2024-06-01T18:07:12.780773Z"}]}
{"channel":"book","type":"update","data":[{"symbol":"LINK/USDT","bids":[{"price":18.55307,"qty":243.48672997}],"asks":[],"checksum":640964299,"timestamp":"2024-06-01T18:07:12.785528Z"}]}
{"channel":"book","type":"update","data":[{"symbol":"LINK/USDT","bids":[{"price":18.55113,"qty":0.00000000},{"price":18.53768,"qty":68.73000000}],"asks":[],"checksum":1688881430,"timestamp":"2024-06-01T18:07:13.046379Z"}]}
{"channel":"book","type":"update","data":[{"symbol":"LINK/USDT","bids":[],"asks":[{"price":18.55829,"qty":0.00000000},{"price":18.57961,"qty":48.75805200}],"checksum":11732415,"timestamp":"2024-06-01T18:07:13.051332Z"}]}
{"channel":"book","type":"update","data":[{"symbol":"LINK/USDT","bids":[],"asks":[{"price":18.56316,"qty":4.85495375}],"checksum":4081354800,"timestamp":"2024-06-01T18:07:13.054677Z"}]}
{"channel":"book","type":"update","data":[{"symbol":"LINK/USDT","bids":[],"asks":[{"price":18.56460,"qty":0.00000000},{"price":18.57961,"qty":48.75805200}],"checksum":2722032748,"timestamp":"2024-06-01T18:07:13.056339Z"}]}
{"channel":"book","type":"update","data":[{"symbol":"LINK/USDT","bids":[],"asks":[{"price":18.56436,"qty":0.00000000},{"price":18.58099,"qty":226.44000000}],"checksum":2976450913,"timestamp":"2024-06-01T18:07:13.057488Z"}]}
{"channel":"book","type":"update","data":[{"symbol":"LINK/USDT","bids":[],"asks":[{"price":18.55661,"qty":16.18047382}],"checksum":2171822803,"timestamp":"2024-06-01T18:07:13.060899Z"}]}
{"channel":"book","type":"update","data":[{"symbol":"LINK/USDT","bids":[],"asks":[{"price":18.56921,"qty":80.84748443}],"checksum":3075533623,"timestamp":"2024-06-01T18:07:13.060946Z"}]}
{"channel":"book","type":"update","data":[{"symbol":"LINK/USDT","bids":[],"asks":[{"price":18.56310,"qty":40.43705185}],"checksum":3998145544,"timestamp":"2024-06-01T18:07:13.060971Z"}]}
{"channel":"book","type":"update","data":[{"symbol":"LINK/USDT","bids":[{"price":18.55247,"qty":53.94692602}],"asks":[],"checksum":3915851627,"timestamp":"2024-06-01T18:07:13.061003Z"}]}
{"channel":"book","type":"update","data":[{"symbol":"LINK/USDT","bids":[{"price":18.55005,"qty":40.45265222}],"asks":[],"checksum":3217087952,"timestamp":"2024-06-01T18:07:13.086540Z"}]}
{"channel":"book","type":"update","data":[{"symbol":"LINK/USDT","bids":[{"price":18.55634,"qty":0.00000000},{"price":18.54204,"qty":269.88270992}],"asks":[],"checksum":1005088064,"timestamp":"2024-06-01T18:07:13.348480Z"}]}
{"channel":"book","type":"update","data":[{"symbol":"LINK/USDT","bids":[{"price":18.55307,"qty":0.00000000},{"price":18.53768,"qty":68.73000000}],"asks":[],"checksum":1661400504,"timestamp":"2024-06-01T18:07:13.352794Z"}]}
{"channel":"book","type":"update","data":[{"symbol":"LINK/USDT","bids":[],"asks":[{"price":18.55658,"qty":9.00000000}],"checksum":2608653423,"timestamp":"2024-06-01T18:07:13.353443Z"}]}
{"channel":"book","type":"update","data":[{"symbol":"LINK/USDT","bids":[],"asks":[{"price":18.55661,"qty":0.00000000},{"price":18.57458,"qty":68.73000000}],"checksum":3992409017,"timestamp":"2024-06-01T18:07:13.357509Z"}]}
{"channel":"book","type":"update","data":[{"symbol":"LINK/USDT","bids":[{"price":18.55615,"qty":80.90615211}],"asks":[],"checksum":2519899802,"timestamp":"2024-06-01T18:07:13.388491Z"}]}
{"channel":"book","type":"update","data":[{"symbol":"LINK/USDT","bids":[],"asks":[{"price":18.55658,"qty":0.00000000},{"price":18.57459,"qty":80.82295392}],"checksum":463292934,"timestamp":"2024-06-01T18:07:13.393338Z"}]}
{"channel":"book","type":"update","data":[{"symbol":"LINK/USDT","bids":[],"asks":[{"price":18.56291,"qty":4.85495273}],"checksum":1533336516,"timestamp":"2024-06-01T18:07:13.396097Z"}]}
{"channel":"book","type":"update","data":[{"symbol":"LINK/USDT","bids":[],"asks":[{"price":18.56310,"qty":0.00000000},{"price":18.57459,"qty":80.82295392}],"checksum":4134466488,"timestamp":"2024-06-01T18:07:13.398202Z"}]}
{"channel":"book","type":"update","data":[{"symbol":"LINK/USDT","bids":[],"asks":[{"price":18.56316,"qty":0.00000000},{"price":18.57961,"qty":48.75805200}],"checksum":1853095566,"timestamp":"2024-06-01T18:07:13.398630Z"}]}
{"channel":"book","type":"update","data":[{"symbol":"LINK/USDT","bids":[],"asks":[{"price":18.56336,"qty":0.00000000},{"price":18.58098,"qty":70.52987272}],"checksum":966665375,"timestamp":"2024-06-01T18:07:13.400843Z"}]}
{"channel":"book","type":"update","data":[{"symbol":"LINK/USDT","bids":[],"asks":[{"price":18.56242,"qty":9.40000000}],"checksum":1593033294,"timestamp":"2024-06-01T18:07:13.401253Z"}]}
{"channel":"book","type":"update","data":[{"symbol":"LINK/USDT","bids":[],"asks":[{"price":18.56223,"qty":4.85495273}],"checksum":507277362,"timestamp":"2024-06-01T18:07:13.404060Z"}]}
{"channel":"book","type":"update","data":[{"symbol":"LINK/USDT","bids":[],"asks":[{"price":18.56291,"qty":0.00000000},{"price":18.57961,"qty":48.75805200}],"checksum":1204062255,"timestamp":"2024-06-01T18:07:13.406597Z"}]}
{"channel":"book","type":"update","data":[{"symbol":"LINK/USDT","bids":[],"asks":[{"price":18.57458,"qty":0.00000000},{"price":18.58098,"qty":70.52987272},{"price":18.57192,"qty":68.73000000}],"checksum":1985504063,"timestamp":"2024-06-01T18:07:13.453795Z"}]}
{"channel":"book","type":"update","data":[{"symbol":"LINK/USDT","bids":[{"price":18.54600,"qty":0.00000000},{"price":18.53768,"qty":68.73000000}],"asks":[],"checksum":2677590369,"timestamp":"2024-06-01T18:07:13.480679Z"}]}
