{"channel":"book","type":"snapshot","data":[{"symbol":"LINK/BTC","bids":[{"price":0.00027382,"qty":464.40875000},{"price":0.00027381,"qty":26.97231035},{"price":0.00027374,"qty":208.08490002},{"price":0.00027373,"qty":26.97797679},{"price":0.00027371,"qty":8.62106869},{"price":0.00027370,"qty":200.00000000},{"price":0.00027369,"qty":149.84610000},{"price":0.00027366,"qty":26.98439486},{"price":0.00027359,"qty":12.71507272},{"price":0.00027358,"qty":217.68605000}],"asks":[{"price":0.00027396,"qty":5.20000000},{"price":0.00027397,"qty":204.85405622},{"price":0.00027398,"qty":8.08690204},{"price":0.00027404,"qty":200.00000000},{"price":0.00027405,"qty":8.08490002},{"price":0.00027408,"qty":32.16775444},{"price":0.00027412,"qty":40.00000000},{"price":0.00027431,"qty":8.07735306},{"price":0.00027441,"qty":88.51378950},{"price":0.00027447,"qty":70.52987272}],"checksum":3995048743}]}
{"channel":"book","type":"update","data":[{"symbol":"LINK/BTC","bids":[],"asks":[{"price":0.00027396,"qty":10.05418429}],"checksum":2010927604,"timestamp":"2024-06-01T18:06:54.226313Z"}]}
{"channel":"book","type":"update","data":[{"symbol":"LINK/BTC","bids":[],"asks":[{"price":0.00027397,"qty":200.00000000}],"checksum":1738785393,"timestamp":"2024-06-01T18:06:54.229270Z"}]}
{"channel":"book","type":"update","data":[{"symbol":"LINK/BTC","bids":[],"asks":[{"price":0.00027408,"qty":0.00000000},{"price":0.00027448,"qty":145.19162032}],"checksum":1441493968,"timestamp":"2024-06-01T18:06:54.316609Z"}]}
{"channel":"book","type":"update","data":[{"symbol":"LINK/BTC","bids":[],"asks":[{"price":0.00027409,"qty":200.00000000}],"checksum":2309694954,"timestamp":"2024-06-01T18:06:54.622238Z"}]}
{"channel":"book","type":"update","data":[{"symbol":"LINK/BTC","bids":[{"price":0.00027359,"qty":0.00000000},{"price":0.00027357,"qty":915.42645000}],"asks":[],"checksum":432944575,"timestamp":"2024-06-01T18:06:54.751293Z"}]}
{"channel":"book","type":"update","data":[{"symbol":"LINK/BTC","bids":[{"price":0.00027359,"qty":11.63268835}],"asks":[],"checksum":1772216041,"timestamp":"2024-06-01T18:06:54.754138Z"}]}
{"channel":"book","type":"update","data":[{"symbol":"LINK/BTC","bids":[{"price":0.00027382,"qty":5.20000000}],"asks":[],"checksum":644707003,"timestamp":"2024-06-01T18:06:55.201756Z"}]}
{"channel":"book","type":"update","data":[{"symbol":"LINK/BTC","bids":[{"price":0.00027383,"qty":459.20875000}],"asks":[],"checksum":1255296116,"timestamp":"2024-06-01T18:06:55.204890Z"}]}
{"channel":"book","type":"update","data":[{"symbol":"LINK/BTC","bids":[{"price":0.00027374,"qty":0.00000000},{"price":0.00027358,"qty":217.68605000}],"asks":[],"checksum":291381924,"timestamp":"2024-06-01T18:06:56.282045Z"}]}
{"channel":"book","type":"update","data":[{"symbol":"LINK/BTC","bids":[{"price":0.00027373,"qty":226.97797679}],"asks":[],"checksum":3300284602,"timestamp":"2024-06-01T18:06:56.565211Z"}]}
{"channel":"book","type":"update","data":[{"symbol":"LINK/BTC","bids":[{"price":0.00027373,"qty":200.00000000}],"asks":[],"checksum":552828053,"timestamp":"2024-06-01T18:06:57.846907Z"}]}
{"channel":"book","type":"update","data":[{"symbol":"LINK/BTC","bids":[{"price":0.00027359,"qty":0.00000000},{"price":0.00027357,"qty":915.42645000}],"asks":[],"checksum":1077172746,"timestamp":"2024-06-01T18:06:59.518936Z"}]}
{"channel":"book","type":"update","data":[{"symbol":"LINK/BTC","bids":[{"price":0.00027359,"qty":12.71532949}],"asks":[],"checksum":1704363838,"timestamp":"2024-06-01T18:06:59.521600Z"}]}
{"channel":"book","type":"update","data":[{"symbol":"LINK/BTC","bids":[{"price":0.00027383,"qty":0.00000000},{"price":0.00027357,"qty":915.42645000}],"asks":[],"checksum":702472758,"timestamp":"2024-06-01T18:07:01.086023Z"}]}
{"channel":"book","type":"update","data":[{"symbol":"LINK/BTC","bids":[{"price":0.00027384,"qty":459.20875000}],"asks":[],"checksum":382590852,"timestamp":"2024-06-01T18:07:01.088701Z"}]}
{"channel":"book","type":"update","data":[{"symbol":"LINK/BTC","bids":[{"price":0.00027382,"qty":0.00000000},{"price":0.00027357,"qty":915.42645000}],"asks":[],"checksum":2925377558,"timestamp":"2024-06-01T18:07:01.089014Z"}]}
{"channel":"book","type":"update","data":[{"symbol":"LINK/BTC","bids":[{"price":0.00027374,"qty":5.20000000}],"asks":[],"checksum":2932820802,"timestamp":"2024-06-01T18:07:01.089122Z"}]}
{"channel":"book","type":"update","data":[{"symbol":"LINK/BTC","bids":[{"price":0.00027370,"qty":0.00000000},{"price":0.00027357,"qty":915.42645000}],"asks":[],"checksum":2621712470,"timestamp":"2024-06-01T18:07:03.999837Z"}]}
{"channel":"book","type":"update","data":[{"symbol":"LINK/BTC","bids":[{"price":0.00027381,"qty":0.00000000},{"price":0.00027353,"qty":118.39770566}],"asks":[],"checksum":1264379768,"timestamp":"2024-06-01T18:07:04.035337Z"}]}
{"channel":"book","type":"update","data":[{"symbol":"LINK/BTC","bids":[],"asks":[{"price":0.00027398,"qty":0.00000000},{"price":0.00027448,"qty":145.19162032}],"checksum":928225085,"timestamp":"2024-06-01T18:07:04.035503Z"}]}
{"channel":"book","type":"update","data":[{"symbol":"LINK/BTC","bids":[],"asks":[{"price":0.00027396,"qty":18.14193795}],"checksum":3160967595,"timestamp":"2024-06-01T18:07:04.040055Z"}]}
{"channel":"book","type":"update","data":[{"symbol":"LINK/BTC","bids":[{"price":0.00027378,"qty":26.97630080}],"asks":[],"checksum":490486903,"timestamp":"2024-06-01T18:07:04.040212Z"}]}
{"channel":"book","type":"update","data":[{"symbol":"LINK/BTC","bids":[{"price":0.00027373,"qty":0.00000000},{"price":0.00027353,"qty":118.39770566}],"asks":[],"checksum":1376744416,"timestamp":"2024-06-01T18:07:04.127779Z"}]}
{"channel":"book","type":"update","data":[{"symbol":"LINK/BTC","bids":[{"price":0.00027367,"qty":200.00000000}],"asks":[],"checksum":3377616181,"timestamp":"2024-06-01T18:07:04.132095Z"}]}
{"channel":"book","type":"update","data":[{"symbol":"LINK/BTC","bids":[{"price":0.00027372,"qty":200.00000000}],"asks":[],"checksum":684035805,"timestamp":"2024-06-01T18:07:04.399476Z"}]}
{"channel":"book","type":"update","data":[{"symbol":"LINK/BTC","bids":[],"asks":[{"price":0.00027395,"qty":200.00000000}],"checksum":3711968848,"timestamp":"2024-06-01T18:07:04.403778Z"}]}
{"channel":"book","type":"update","data":[{"symbol":"LINK/BTC","bids":[],"asks":[{"price":0.00027395,"qty":204.85429178}],"checksum":3731255616,"timestamp":"2024-06-01T18:07:04.406643Z"}]}
{"channel":"book","type":"update","data":[{"symbol":"LINK/BTC","bids":[],"asks":[{"price":0.00027397,"qty":0.00000000},{"price":0.00027448,"qty":145.19162032}],"checksum":4231632349,"timestamp":"2024-06-01T18:07:04.422384Z"}]}
{"channel":"book","type":"update","data":[{"symbol":"LINK/BTC","bids":[],"asks":[{"price":0.00027396,"qty":13.28775366}],"checksum":1536381178,"timestamp":"2024-06-01T18:07:04.425020Z"}]}
{"channel":"book","type":"update","data":[{"symbol":"LINK/BTC","bids":[],"asks":[{"price":0.00027441,"qty":0.00000000},{"price":0.00027461,"qty":87.99000000}],"checksum":922218426,"timestamp":"2024-06-01T18:07:05.507310Z"}]}
{"channel":"book","type":"update","data":[{"symbol":"LINK/BTC","bids":[],"asks":[{"price":0.00027440,"qty":88.51378950}],"checksum":1900931681,"timestamp":"2024-06-01T18:07:05.638133Z"}]}
{"channel":"book","type":"update","data":[{"symbol":"LINK/BTC","bids":[],"asks":[{"price":0.00027395,"qty":4.85429178}],"checksum":591036996,"timestamp":"2024-06-01T18:07:06.923099Z"}]}
{"channel":"book","type":"update","data":[{"symbol":"LINK/BTC","bids":[],"asks":[{"price":0.00027398,"qty":200.00000000}],"checksum":4291173879,"timestamp":"2024-06-01T18:07:06.923245Z"}]}
{"channel":"book","type":"update","data":[{"symbol":"LINK/BTC","bids":[{"price":0.00027374,"qty":0.00000000},{"price":0.00027357,"qty":915.42645000}],"asks":[],"checksum":3162882376,"timestamp":"2024-06-01T18:07:06.925655Z"}]}
{"channel":"book","type":"update","data":[{"symbol":"LINK/BTC","bids":[{"price":0.00027384,"qty":464.40875000}],"asks":[],"checksum":1551805372,"timestamp":"2024-06-01T18:07:06.925960Z"}]}
{"channel":"book","type":"update","data":[{"symbol":"LINK/BTC","bids":[{"price":0.00027384,"qty":5.20000000}],"asks":[],"checksum":3230603399,"timestamp":"2024-06-01T18:07:06.970123Z"}]}
{"channel":"book","type":"update","data":[{"symbol":"LINK/BTC","bids":[{"price":0.00027384,"qty":0.00000000},{"price":0.00027353,"qty":118.39770566}],"asks":[],"checksum":2690442728,"timestamp":"2024-06-01T18:07:06.972702Z"}]}
{"channel":"book","type":"update","data":[{"symbol":"LINK/BTC","bids":[{"price":0.00027379,"qty":5.20000000}],"asks":[],"checksum":2168448806,"timestamp":"2024-06-01T18:07:06.972905Z"}]}
{"channel":"book","type":"update","data":[{"symbol":"LINK/BTC","bids":[{"price":0.00027379,"qty":464.40875000}],"asks":[],"checksum":3328215081,"timestamp":"2024-06-01T18:07:06.973030Z"}]}
{"channel":"book","type":"update","data":[{"symbol":"LINK/BTC","bids":[{"price":0.00027379,"qty":5.20000000}],"asks":[],"checksum":2168448806,"timestamp":"2024-06-01T18:07:06.976175Z"}]}
{"channel":"book","type":"update","data":[{"symbol":"LINK/BTC","bids":[{"price":0.00027380,"qty":459.20875000}],"asks":[],"checksum":2078978462,"timestamp":"2024-06-01T18:07:06.978866Z"}]}
{"channel":"book","type":"update","data":[{"symbol":"LINK/BTC","bids":[{"price":0.00027379,"qty":0.00000000},{"price":0.00027357,"qty":915.42645000}],"asks":[],"checksum":3057011639,"timestamp":"2024-06-01T18:07:06.981653Z"}]}
{"channel":"book","type":"update","data":[{"symbol":"LINK/BTC","bids":[{"price":0.00027381,"qty":5.20000000}],"asks":[],"checksum":3782613926,"timestamp":"2024-06-01T18:07:06.981673Z"}]}
{"channel":"book","type":"update","data":[{"symbol":"LINK/BTC","bids":[],"asks":[{"price":0.00027395,"qty":0.00000000},{"price":0.00027448,"qty":145.19162032}],"checksum":1207469331,"timestamp":"2024-06-01T18:07:07.135992Z"}]}
{"channel":"book","type":"update","data":[{"symbol":"LINK/BTC","bids":[{"price":0.00027370,"qty":200.00000000}],"asks":[],"checksum":3972035729,"timestamp":"2024-06-01T18:07:07.420533Z"}]}
{"channel":"book","type":"update","data":[{"symbol":"LINK/BTC","bids":[{"price":0.00027367,"qty":0.00000000},{"price":0.00027358,"qty":217.68605000}],"asks":[],"checksum":1278514240,"timestamp":"2024-06-01T18:07:07.922426Z"}]}
{"channel":"book","type":"update","data":[{"symbol":"LINK/BTC","bids":[{"price":0.00027378,"qty":0.00000000},{"price":0.00027357,"qty":915.42645000}],"asks":[],"checksum":1196439049,"timestamp":"2024-06-01T18:07:08.115977Z"}]}
{"channel":"book","type":"update","data":[{"symbol":"LINK/BTC","bids":[{"price":0.00027380,"qty":486.18243732}],"asks":[],"checksum":2733817032,"timestamp":"2024-06-01T18:07:08.120080Z"}]}
{"channel":"book","type":"update","data":[{"symbol":"LINK/BTC","bids":[],"asks":[{"price":0.00027396,"qty":18.14144380}],"checksum":4111522376,"timestamp":"2024-06-01T18:07:08.964131Z"}]}
{"channel":"book","type":"update","data":[{"symbol":"LINK/BTC","bids":[{"price":0.00027359,"qty":0.00000000},{"price":0.00027353,"qty":118.39770566}],"asks":[],"checksum":3183840841,"timestamp":"2024-06-01T18:07:09.066539Z"}]}
{"channel":"book","type":"update","data":[{"symbol":"LINK/BTC","bids":[{"price":0.00027373,"qty":1.07870843}],"asks":[],"checksum":249662340,"timestamp":"2024-06-01T18:07:09.071752Z"}]}
{"channel":"book","type":"update","data":[{"symbol":"LINK/BTC","bids":[{"price":0.00027359,"qty":11.63655458}],"asks":[],"checksum":2621750985,"timestamp":"2024-06-01T18:07:09.071835Z"}]}
{"channel":"book","type":"update","data":[{"symbol":"LINK/BTC","bids":[{"price":0.00027359,"qty":0.00000000},{"price":0.00027357,"qty":915.42645000}],"asks":[],"checksum":249662340,"timestamp":"2024-06-01T18:07:11.474176Z"}]}
{"channel":"book","type":"update","data":[{"symbol":"LINK/BTC","bids":[{"price":0.00027359,"qty":12.36355928}],"asks":[],"checksum":1193923902,"timestamp":"2024-06-01T18:07:11.479594Z"}]}
{"channel":"book","type":"update","data":[{"symbol":"LINK/BTC","bids":[{"price":0.00027370,"qty":0.00000000},{"price":0.00027357,"qty":915.42645000}],"asks":[],"checksum":4200423977,"timestamp":"2024-06-01T18:07:12.453337Z"}]}
{"channel":"book","type":"update","data":[{"symbol":"LINK/BTC","bids":[{"price":0.00027380,"qty":459.20875000}],"asks":[],"checksum":3382786344,"timestamp":"2024-06-01T18:07:12.457577Z"}]}
{"channel":"book","type":"update","data":[{"symbol":"LINK/BTC","bids":[{"price":0.00027377,"qty":26.97691650}],"asks":[],"checksum":1343301599,"timestamp":"2024-06-01T18:07:12.461179Z"}]}
{"channel":"book","type":"update","data":[{"symbol":"LINK/BTC","bids":[],"asks":[{"price":0.00027395,"qty":200.00000000}],"checksum":3851472827,"timestamp":"2024-06-01T18:07:12.462753Z"}]}
{"channel":"book","type":"update","data":[{"symbol":"LINK/BTC","bids":[],"asks":[{"price":0.00027395,"qty":204.85415558}],"checksum":3799987946,"timestamp":"2024-06-01T18:07:12.475228Z"}]}
{"channel":"book","type":"update","data":[{"symbol":"LINK/BTC","bids":[],"asks":[{"price":0.00027396,"qty":13.28775366}],"checksum":375681089,"timestamp":"2024-06-01T18:07:12.476352Z"}]}
{"channel":"book","type":"update","data":[{"symbol":"LINK/BTC","bids":[],"asks":[{"price":0.00027396,"qty":8.08775366}],"checksum":981140142,"timestamp":"2024-06-01T18:07:12.538639Z"}]}
{"channel":"book","type":"update","data":[{"symbol":"LINK/BTC","bids":[],"asks":[{"price":0.00027394,"qty":5.20000000}],"checksum":2185422476,"timestamp":"2024-06-01T18:07:12.538819Z"}]}
{"channel":"book","type":"update","data":[{"symbol":"LINK/BTC","bids":[],"asks":[{"price":0.00027393,"qty":4.85491927}],"checksum":3806330717,"timestamp":"2024-06-01T18:07:12.541758Z"}]}
{"channel":"book","type":"update","data":[{"symbol":"LINK/BTC","bids":[],"asks":[{"price":0.00027398,"qty":0.00000000},{"price":0.00027440,"qty":88.51378950}],"checksum":270731677,"timestamp":"2024-06-01T18:07:12.543033Z"}]}
{"channel":"book","type":"update","data":[{"symbol":"LINK/BTC","bids":[],"asks":[{"price":0.00027395,"qty":200.00000000}],"checksum":3182201134,"timestamp":"2024-06-01T18:07:12.544543Z"}]}
{"channel":"book","type":"update","data":[{"symbol":"LINK/BTC","bids":[{"price":0.00027380,"qty":0.00000000},{"price":0.00027357,"qty":915.42645000}],"asks":[],"checksum":3808987432,"timestamp":"2024-06-01T18:07:12.854324Z"}]}
{"channel":"book","type":"update","data":[{"symbol":"LINK/BTC","bids":[{"price":0.00027381,"qty":0.00000000},{"price":0.00027353,"qty":118.39770566}],"asks":[],"checksum":627086900,"timestamp":"2024-06-01T18:07:12.857148Z"}]}
{"channel":"book","type":"update","data":[{"symbol":"LINK/BTC","bids":[{"price":0.00027378,"qty":459.20875000}],"asks":[],"checksum":2198131398,"timestamp":"2024-06-01T18:07:12.857200Z"}]}
{"channel":"book","type":"update","data":[{"symbol":"LINK/BTC","bids":[{"price":0.00027377,"qty":32.17691650}],"asks":[],"checksum":3088165898,"timestamp":"2024-06-01T18:07:12.857259Z"}]}
{"channel":"book","type":"update","data":[{"symbol":"LINK/BTC","bids":[{"price":0.00027367,"qty":200.00000000}],"asks":[],"checksum":245959246,"timestamp":"2024-06-01T18:07:12.858477Z"}]}
{"channel":"book","type":"update","data":[{"symbol":"LINK/BTC","bids":[{"price":0.00027377,"qty":26.97691650}],"asks":[],"checksum":901543042,"timestamp":"2024-06-01T18:07:12.860132Z"}]}
{"channel":"book","type":"update","data":[{"symbol":"LINK/BTC","bids":[{"price":0.00027379,"qty":5.20000000}],"asks":[],"checksum":733371960,"timestamp":"2024-06-01T18:07:12.860393Z"}]}
{"channel":"book","type":"update","data":[{"symbol":"LINK/BTC","bids":[],"asks":[{"price":0.00027396,"qty":0.00000000},{"price":0.00027447,"qty":70.52987272}],"checksum":2595758081,"timestamp":"2024-06-01T18:07:13.479613Z"}]}
{"channel":"book","type":"update","data":[{"symbol":"LINK/BTC","bids":[],"asks":[{"price":0.00027394,"qty":13.28824790}],"checksum":420809550,"timestamp":"2024-06-01T18:07:13.483217Z"}]}
{"channel":"book","type":"update","data":[{"symbol":"LINK/BTC","bids":[],"asks":[{"price":0.00027393,"qty":204.85491927}],"checksum":3127207945,"timestamp":"2024-06-01T18:07:13.485213Z"}]}
{"channel":"book","type":"update","data":[{"symbol":"LINK/BTC","bids":[],"asks":[{"price":0.00027394,"qty":8.08824790}],"checksum":2430883219,"timestamp":"2024-06-01T18:07:13.487823Z"}]}
{"channel":"book","type":"update","data":[{"symbol":"LINK/BTC","bids":[],"asks":[{"price":0.00027392,"qty":5.20000000}],"checksum":2624558244,"timestamp":"2024-06-01T18:07:13.487983Z"}]}
{"channel":"book","type":"update","data":[{"symbol":"LINK/BTC","bids":[],"asks":[{"price":0.00027391,"qty":4.85495212}],"checksum":967882331,"timestamp":"2024-06-01T18:07:13.490783Z"}]}
{"channel":"book","type":"update","data":[{"symbol":"LINK/BTC","bids":[],"asks":[{"price":0.00027393,"qty":200.00000000}],"checksum":4077288458,"timestamp":"2024-06-01T18:07:13.493612Z"}]}
{"channel":"book","type":"update","data":[{"symbol":"LINK/BTC","bids":[{"price":0.00027372,"qty":0.00000000},{"price":0.00027358,"qty":217.68605000}],"asks":[],"checksum":731271632,"timestamp":"2024-06-01T18:07:13.541067Z"}]}
{"channel":"book","type":"update","data":[{"symbol":"LINK/BTC","bids":[],"asks":[{"price":0.00027393,"qty":0.00000000},{"price":0.00027440,"qty":88.51378950}],"checksum":937636197,"timestamp":"2024-06-01T18:07:13.544952Z"}]}
{"channel":"book","type":"update","data":[{"symbol":"LINK/BTC","bids":[{"price":0.00027379,"qty":26.77631271}],"asks":[],"checksum":71922652,"timestamp":"2024-06-01T18:07:13.814907Z"}]}
{"channel":"book","type":"update","data":[{"symbol":"LINK/BTC","bids":[{"price":0.00027373,"qty":0.00000000},{"price":0.00027357,"qty":915.42645000}],"asks":[],"checksum":170843828,"timestamp":"2024-06-01T18:07:13.819416Z"}]}
{"channel":"book","type":"update","data":[{"symbol":"LINK/BTC","bids":[{"price":0.00027367,"qty":0.00000000},{"price":0.00027353,"qty":118.39770566}],"asks":[],"checksum":1246438666,"timestamp":"2024-06-01T18:07:13.862169Z"}]}
{"channel":"book","type":"update","data":[{"symbol":"LINK/BTC","bids":[{"price":0.00027353,"qty":27.00005276}],"asks":[],"checksum":4015917930,"timestamp":"2024-06-01T18:07:13.866881Z"}]}
{"channel":"book","type":"update","data":[{"symbol":"LINK/BTC","bids":[],"asks":[{"price":0.00027431,"qty":0.00000000},{"price":0.00027447,"qty":70.52987272}],"checksum":224132741,"timestamp":"2024-06-01T18:07:13.867443Z"}]}
{"channel":"book","type":"update","data":[{"symbol":"LINK/BTC","bids":[{"price":0.00027377,"qty":0.00000000},{"price":0.00027339,"qty":42.76000000}],"asks":[],"checksum":2120281526,"timestamp":"2024-06-01T18:07:13.867480Z"}]}
{"channel":"book","type":"update","data":[{"symbol":"LINK/BTC","bids":[],"asks":[{"price":0.00027394,"qty":0.00000000},{"price":0.00027448,"qty":145.19162032}],"checksum":3476110935,"timestamp":"2024-06-01T18:07:13.867618Z"}]}
{"channel":"book","type":"update","data":[{"symbol":"LINK/BTC","bids":[{"price":0.00027340,"qty":53.97064345}],"asks":[],"checksum":2646762115,"timestamp":"2024-06-01T18:07:13.868466Z"}]}
{"channel":"book","type":"update","data":[{"symbol":"LINK/BTC","bids":[],"asks":[{"price":0.00027405,"qty":0.00000000},{"price":0.00027461,"qty":87.99000000}],"checksum":3374864416,"timestamp":"2024-06-01T18:07:13.870410Z"}]}
{"channel":"book","type":"update","data":[{"symbol":"LINK/BTC","bids":[{"price":0.00027366,"qty":0.00000000},{"price":0.00027339,"qty":42.76000000}],"asks":[],"checksum":2336554909,"timestamp":"2024-06-01T18:07:13.870431Z"}]}
{"channel":"book","type":"update","data":[{"symbol":"LINK/BTC","bids":[],"asks":[{"price":0.00027394,"qty":40.00000000}],"checksum":3935247319,"timestamp":"2024-06-01T18:07:13.873827Z"}]}
{"channel":"book","type":"update","data":[{"symbol":"LINK/BTC","bids":[],"asks":[{"price":0.00027391,"qty":204.85495212}],"checksum":3139819247,"timestamp":"2024-06-01T18:07:13.874112Z"}]}
{"channel":"book","type":"update","data":[{"symbol":"LINK/BTC","bids":[{"price":0.00027343,"qty":27.01008760}],"asks":[],"checksum":2496389411,"timestamp":"2024-06-01T18:07:13.876202Z"}]}
{"channel":"book","type":"update","data":[{"symbol":"LINK/BTC","bids":[],"asks":[{"price":0.00027416,"qty":8.08194549}],"checksum":1869756024,"timestamp":"2024-06-01T18:07:13.876215Z"}]}
{"channel":"book","type":"update","data":[{"symbol":"LINK/BTC","bids":[],"asks":[{"price":0.00027394,"qty":0.00000000},{"price":0.00027448,"qty":145.19162032}],"checksum":176544137,"timestamp":"2024-06-01T18:07:13.894735Z"}]}
{"channel":"book","type":"update","data":[{"symbol":"LINK/BTC","bids":[{"price":0.00027371,"qty":0.00000000},{"price":0.00027339,"qty":42.76000000}],"asks":[],"checksum":834188253,"timestamp":"2024-06-01T18:07:13.907766Z"}]}
{"channel":"book","type":"update","data":[{"symbol":"LINK/BTC","bids":[],"asks":[{"price":0.00027395,"qty":0.00000000},{"price":0.00027461,"qty":87.99000000}],"checksum":1687480192,"timestamp":"2024-06-01T18:07:13.911841Z"}]}
{"channel":"book","type":"update","data":[{"symbol":"LINK/BTC","bids":[],"asks":[{"price":0.00027390,"qty":40.00000000}],"checksum":1058588407,"timestamp":"2024-06-01T18:07:13.913425Z"}]}
{"channel":"book","type":"update","data":[{"symbol":"LINK/BTC","bids":[],"asks":[{"price":0.00027392,"qty":0.00000000},{"price":0.00027461,"qty":87.99000000}],"checksum":642898516,"timestamp":"2024-06-01T18:07:13.914543Z"}]}
{"channel":"book","type":"update","data":[{"symbol":"LINK/BTC","bids":[],"asks":[{"price":0.00027391,"qty":210.05495212}],"checksum":4047561282,"timestamp":"2024-06-01T18:07:13.916324Z"}]}
{"channel":"book","type":"update","data":[{"symbol":"LINK/BTC","bids":[],"asks":[{"price":0.00027389,"qty":4.85759410}],"checksum":97727220,"timestamp":"2024-06-01T18:07:13.917772Z"}]}
{"channel":"book","type":"update","data":[{"symbol":"LINK/BTC","bids":[],"asks":[{"price":0.00027391,"qty":205.20000000}],"checksum":752553487,"timestamp":"2024-06-01T18:07:13.920609Z"}]}
{"channel":"book","type":"update","data":[{"symbol":"LINK/BTC","bids":[],"asks":[{"price":0.00027389,"qty":204.85759410}],"checksum":2833983984,"timestamp":"2024-06-01T18:07:13.921993Z"}]}
{"channel":"book","type":"update","data":[{"symbol":"LINK/BTC","bids":[{"price":0.00027379,"qty":21.57631271}],"asks":[],"checksum":1590831546,"timestamp":"2024-06-01T18:07:13.924664Z"}]}
{"channel":"book","type":"update","data":[{"symbol":"LINK/BTC","bids":[],"asks":[{"price":0.00027389,"qty":210.05759410}],"checksum":3345275570,"timestamp":"2024-06-01T18:07:13.942690Z"}]}
{"channel":"book","type":"update","data":[{"symbol":"LINK/BTC","bids":[],"asks":[{"price":0.00027391,"qty":200.00000000}],"checksum":1912766765,"timestamp":"2024-06-01T18:07:13.942720Z"}]}
{"channel":"book","type":"update","data":[{"symbol":"LINK/BTC","bids":[],"asks":[{"price":0.00027391,"qty":0.00000000},{"price":0.00027461,"qty":87.99000000}],"checksum":837076196,"timestamp":"2024-06-01T18:07:13.946574Z"}]}
{"channel":"book","type":"update","data":[{"symbol":"LINK/BTC","bids":[],"asks":[{"price":0.00027390,"qty":0.00000000},{"price":0.00027467,"qty":0.45293700}],"checksum":4141089891,"timestamp":"2024-06-01T18:07:13.948080Z"}]}
{"channel":"book","type":"update","data":[{"symbol":"LINK/BTC","bids":[],"asks":[{"price":0.00027397,"qty":38.79009647}],"checksum":3681424093,"timestamp":"2024-06-01T18:07:13.976448Z"}]}
{"channel":"book","type":"update","data":[{"symbol":"LINK/BTC","bids":[{"price":0.00027366,"qty":26.98779988}],"asks":[],"checksum":396076862,"timestamp":"2024-06-01T18:07:13.984356Z"}]}
{"channel":"book","type":"update","data":[{"symbol":"LINK/BTC","bids":[],"asks":[{"price":0.00027394,"qty":54.50545037}],"checksum":1012894305,"timestamp":"2024-06-01T18:07:13.992597Z"}]}
{"channel":"book","type":"update","data":[{"symbol":"LINK/BTC","bids":[{"price":0.00027378,"qty":0.00000000},{"price":0.00027339,"qty":42.76000000}],"asks":[],"checksum":2158260137,"timestamp":"2024-06-01T18:07:14.014599Z"}]}
{"channel":"book","type":"update","data":[{"symbol":"LINK/BTC","bids":[{"price":0.00027369,"qty":0.00000000},{"price":0.00027334,"qty":0.47056560}],"asks":[],"checksum":1910959326,"timestamp":"2024-06-01T18:07:14.014612Z"}]}
{"channel":"book","type":"update","data":[{"symbol":"LINK/BTC","bids":[{"price":0.00027358,"qty":0.00000000},{"price":0.00027325,"qty":47.28000000}],"asks":[],"checksum":2860503542,"timestamp":"2024-06-01T18:07:14.014649Z"}]}
{"channel":"book","type":"update","data":[{"symbol":"LINK/BTC","bids":[{"price":0.00027343,"qty":244.69613760}],"asks":[],"checksum":2765612698,"timestamp":"2024-06-01T18:07:14.017386Z"}]}
{"channel":"book","type":"update","data":[{"symbol":"LINK/BTC","bids":[{"price":0.00027353,"qty":176.84615276}],"asks":[],"checksum":780776787,"timestamp":"2024-06-01T18:07:14.017430Z"}]}
{"channel":"book","type":"update","data":[{"symbol":"LINK/BTC","bids":[{"price":0.00027360,"qty":459.20875000}],"asks":[],"checksum":2593455924,"timestamp":"2024-06-01T18:07:14.017510Z"}]}
{"channel":"book","type":"update","data":[{"symbol":"LINK/BTC","bids":[],"asks":[{"price":0.00027389,"qty":204.85759410}],"checksum":1323715058,"timestamp":"2024-06-01T18:07:14.017632Z"}]}
{"channel":"book","type":"update","data":[{"symbol":"LINK/BTC","bids":[],"asks":[{"price":0.00027388,"qty":5.20000000}],"checksum":1287658155,"timestamp":"2024-06-01T18:07:14.017759Z"}]}
{"channel":"book","type":"update","data":[{"symbol":"LINK/BTC","bids":[{"price":0.00027370,"qty":5.20000000}],"asks":[],"checksum":1211282285,"timestamp":"2024-06-01T18:07:14.017799Z"}]}
{"channel":"book","type":"update","data":[{"symbol":"LINK/BTC","bids":[],"asks":[{"price":0.00027387,"qty":4.85702548}],"checksum":613436391,"timestamp":"2024-06-01T18:07:14.020712Z"}]}
{"channel":"book","type":"update","data":[{"symbol":"LINK/BTC","bids":[],"asks":[{"price":0.00027389,"qty":200.00000000}],"checksum":3182774808,"timestamp":"2024-06-01T18:07:14.021928Z"}]}
{"channel":"book","type":"update","data":[{"symbol":"LINK/BTC","bids":[],"asks":[{"price":0.00027390,"qty":200.00000000}],"checksum":2332941941,"timestamp":"2024-06-01T18:07:14.048367Z"}]}
{"channel":"book","type":"update","data":[{"symbol":"LINK/BTC","bids":[],"asks":[{"price":0.00027387,"qty":204.85702548}],"checksum":211945285,"timestamp":"2024-06-01T18:07:14.052582Z"}]}
{"channel":"book","type":"update","data":[{"symbol":"LINK/BTC","bids":[],"asks":[{"price":0.00027388,"qty":0.00000000},{"price":0.00027440,"qty":88.51378950}],"checksum":3279304465,"timestamp":"2024-06-01T18:07:14.055248Z"}]}
{"channel":"book","type":"update","data":[{"symbol":"LINK/BTC","bids":[],"asks":[{"price":0.00027386,"qty":5.20000000}],"checksum":1743021207,"timestamp":"2024-06-01T18:07:14.055462Z"}]}
{"channel":"book","type":"update","data":[{"symbol":"LINK/BTC","bids":[],"asks":[{"price":0.00027385,"qty":4.85705384}],"checksum":3527220639,"timestamp":"2024-06-01T18:07:14.058295Z"}]}
{"channel":"book","type":"update","data":[{"symbol":"LINK/BTC","bids":[],"asks":[{"price":0.00027387,"qty":200.00000000}],"checksum":1486173512,"timestamp":"2024-06-01T18:07:14.064676Z"}]}
{"channel":"book","type":"update","data":[{"symbol":"LINK/BTC","bids":[{"price":0.00027379,"qty":0.00000000},{"price":0.00027334,"qty":0.47056560}],"asks":[],"checksum":2509555085,"timestamp":"2024-06-01T18:07:14.123510Z"}]}
{"channel":"book","type":"update","data":[{"symbol":"LINK/BTC","bids":[],"asks":[{"price":0.00027389,"qty":0.00000000},{"price":0.00027416,"qty":8.08194549}],"checksum":902426962,"timestamp":"2024-06-01T18:07:14.127803Z"}]}
{"channel":"book","type":"update","data":[{"symbol":"LINK/BTC","bids":[],"asks":[{"price":0.00027385,"qty":204.85705384}],"checksum":3427963176,"timestamp":"2024-06-01T18:07:14.127833Z"}]}
{"channel":"book","type":"update","data":[{"symbol":"LINK/BTC","bids":[],"asks":[{"price":0.00027386,"qty":0.00000000},{"price":0.00027430,"qty":64.33477648}],"checksum":2645965929,"timestamp":"2024-06-01T18:07:14.130637Z"}]}
{"channel":"book","type":"update","data":[{"symbol":"LINK/BTC","bids":[],"asks":[{"price":0.00027384,"qty":5.20000000}],"checksum":133332791,"timestamp":"2024-06-01T18:07:14.131040Z"}]}
{"channel":"book","type":"update","data":[{"symbol":"LINK/BTC","bids":[{"price":0.00027360,"qty":0.00000000},{"price":0.00027325,"qty":47.28000000}],"asks":[],"checksum":2591955414,"timestamp":"2024-06-01T18:07:14.134372Z"}]}
{"channel":"book","type":"update","data":[{"symbol":"LINK/BTC","bids":[],"asks":[{"price":0.00027383,"qty":4.85702453}],"checksum":2241172612,"timestamp":"2024-06-01T18:07:14.134459Z"}]}
{"channel":"book","type":"update","data":[{"symbol":"LINK/BTC","bids":[{"price":0.00027370,"qty":0.00000000},{"price":0.00027324,"qty":145.19162032}],"asks":[],"checksum":1249207783,"timestamp":"2024-06-01T18:07:14.136992Z"}]}
{"channel":"book","type":"update","data":[{"symbol":"LINK/BTC","bids":[{"price":0.00027367,"qty":459.20875000}],"asks":[],"checksum":3867700456,"timestamp":"2024-06-01T18:07:14.137144Z"}]}
{"channel":"book","type":"update","data":[{"symbol":"LINK/BTC","bids":[{"price":0.00027366,"qty":32.18779988}],"asks":[],"checksum":2648074440,"timestamp":"2024-06-01T18:07:14.137265Z"}]}
{"channel":"book","type":"update","data":[{"symbol":"LINK/BTC","bids":[],"asks":[{"price":0.00027385,"qty":200.00000000}],"checksum":3421429440,"timestamp":"2024-06-01T18:07:14.137512Z"}]}
{"channel":"book","type":"update","data":[{"symbol":"LINK/BTC","bids":[{"price":0.00027366,"qty":26.98779988}],"asks":[],"checksum":2964380384,"timestamp":"2024-06-01T18:07:14.140025Z"}]}
{"channel":"book","type":"update","data":[{"symbol":"LINK/BTC","bids":[{"price":0.00027368,"qty":5.20000000}],"asks":[],"checksum":1207242362,"timestamp":"2024-06-01T18:07:14.140269Z"}]}
{"channel":"book","type":"update","data":[{"symbol":"LINK/BTC","bids":[],"asks":[{"price":0.00027409,"qty":0.00000000},{"price":0.00027416,"qty":8.08194549}],"checksum":2886146329,"timestamp":"2024-06-01T18:07:14.271463Z"}]}
{"channel":"book","type":"update","data":[{"symbol":"LINK/BTC","bids":[],"asks":[{"price":0.00027404,"qty":0.00000000},{"price":0.00027430,"qty":64.33477648}],"checksum":3402328835,"timestamp":"2024-06-01T18:07:14.330661Z"}]}
{"channel":"book","type":"update","data":[{"symbol":"LINK/BTC","bids":[{"price":0.00027357,"qty":1115.42645000}],"asks":[],"checksum":4052134360,"timestamp":"2024-06-01T18:07:14.418364Z"}]}
{"channel":"book","type":"update","data":[{"symbol":"LINK/BTC","bids":[],"asks":[{"price":0.00027387,"qty":0.00000000},{"price":0.00027431,"qty":80.85684384}],"checksum":3070401725,"timestamp":"2024-06-01T18:07:14.422853Z"}]}
{"channel":"book","type":"update","data":[{"symbol":"LINK/BTC","bids":[],"asks":[{"price":0.00027391,"qty":200.00000000}],"checksum":3384714612,"timestamp":"2024-06-01T18:07:14.598933Z"}]}
{"channel":"book","type":"update","data":[{"symbol":"LINK/BTC","bids":[{"price":0.00027366,"qty":0.00000000},{"price":0.00027325,"qty":47.28000000}],"asks":[],"checksum":1424313696,"timestamp":"2024-06-01T18:07:14.675535Z"}]}
{"channel":"book","type":"update","data":[{"symbol":"LINK/BTC","bids":[{"price":0.00027357,"qty":915.42645000}],"asks":[],"checksum":537084695,"timestamp":"2024-06-01T18:07:14.689039Z"}]}
{"channel":"book","type":"update","data":[{"symbol":"LINK/BTC","bids":[],"asks":[{"price":0.00027383,"qty":204.85702453}],"checksum":4049397791,"timestamp":"2024-06-01T18:07:14.922491Z"}]}
{"channel":"book","type":"update","data":[{"symbol":"LINK/BTC","bids":[],"asks":[{"price":0.00027385,"qty":0.00000000},{"price":0.00027431,"qty":80.85684384}],"checksum":3063528488,"timestamp":"2024-06-01T18:07:14.926227Z"}]}
{"channel":"book","type":"update","data":[{"symbol":"LINK/BTC","bids":[],"asks":[{"price":0.00027384,"qty":0.00000000},{"price":0.00027440,"qty":88.51378950}],"checksum":1711790621,"timestamp":"2024-06-01T18:07:14.928981Z"}]}
{"channel":"book","type":"update","data":[{"symbol":"LINK/BTC","bids":[{"price":0.00027356,"qty":200.00000000}],"asks":[],"checksum":3572662340,"timestamp":"2024-06-01T18:07:14.979139Z"}]}
{"channel":"book","type":"update","data":[{"symbol":"LINK/BTC","bids":[],"asks":[{"price":0.00027383,"qty":210.05702453}],"checksum":494183463,"timestamp":"2024-06-01T18:07:15.160351Z"}]}
{"channel":"book","type":"update","data":[{"symbol":"LINK/BTC","bids":[{"price":0.00027353,"qty":376.84615276}],"asks":[],"checksum":2948125937,"timestamp":"2024-06-01T18:07:15.164837Z"}]}
{"channel":"book","type":"update","data":[{"symbol":"LINK/BTC","bids":[],"asks":[{"price":0.00027382,"qty":8.09191941}],"checksum":2550288260,"timestamp":"2024-06-01T18:07:15.636479Z"}]}
{"channel":"book","type":"update","data":[{"symbol":"LINK/BTC","bids":[{"price":0.00027360,"qty":26.99359174}],"asks":[],"checksum":3805221275,"timestamp":"2024-06-01T18:07:15.636674Z"}]}
{"channel":"book","type":"update","data":[{"symbol":"LINK/BTC","bids":[],"asks":[{"price":0.00027382,"qty":12.94881468}],"checksum":2302707626,"timestamp":"2024-06-01T18:07:15.639607Z"}]}
{"channel":"book","type":"update","data":[{"symbol":"LINK/BTC","bids":[],"asks":[{"price":0.00027383,"qty":205.20000000}],"checksum":151711323,"timestamp":"2024-06-01T18:07:15.639713Z"}]}
{"channel":"book","type":"update","data":[{"symbol":"LINK/BTC","bids":[],"asks":[{"price":0.00027381,"qty":200.00000000}],"checksum":1793420723,"timestamp":"2024-06-01T18:07:15.640861Z"}]}
{"channel":"book","type":"update","data":[{"symbol":"LINK/BTC","bids":[],"asks":[{"price":0.00027383,"qty":5.20000000}],"checksum":2880234147,"timestamp":"2024-06-01T18:07:15.920580Z"}]}
{"channel":"book","type":"update","data":[{"symbol":"LINK/BTC","bids":[],"asks":[{"price":0.00027383,"qty":0.00000000},{"price":0.00027431,"qty":80.85684384}],"checksum":2616327852,"timestamp":"2024-06-01T18:07:15.923209Z"}]}
{"channel":"book","type":"update","data":[{"symbol":"LINK/BTC","bids":[],"asks":[{"price":0.00027381,"qty":204.85701152}],"checksum":131735339,"timestamp":"2024-06-01T18:07:16.037818Z"}]}
{"channel":"book","type":"update","data":[{"symbol":"LINK/BTC","bids":[],"asks":[{"price":0.00027429,"qty":70.52987272}],"checksum":357624629,"timestamp":"2024-06-01T18:07:16.072472Z"}]}
{"channel":"book","type":"update","data":[{"symbol":"LINK/BTC","bids":[],"asks":[{"price":0.00027382,"qty":8.09191941}],"checksum":10987219,"timestamp":"2024-06-01T18:07:16.075234Z"}]}
{"channel":"book","type":"update","data":[{"symbol":"LINK/BTC","bids":[{"price":0.00027356,"qty":0.00000000},{"price":0.00027334,"qty":0.47056560}],"asks":[],"checksum":1979189608,"timestamp":"2024-06-01T18:07:16.141950Z"}]}
{"channel":"book","type":"update","data":[{"symbol":"LINK/BTC","bids":[{"price":0.00027359,"qty":0.00000000},{"price":0.00027325,"qty":47.28000000}],"asks":[],"checksum":856434845,"timestamp":"2024-06-01T18:07:16.228876Z"}]}
{"channel":"book","type":"update","data":[{"symbol":"LINK/BTC","bids":[{"price":0.00027358,"qty":9.81151799}],"asks":[],"checksum":451696762,"timestamp":"2024-06-01T18:07:16.234788Z"}]}
{"channel":"book","type":"update","data":[{"symbol":"LINK/BTC","bids":[],"asks":[{"price":0.00027382,"qty":0.00000000},{"price":0.00027431,"qty":80.85684384}],"checksum":3467494455,"timestamp":"2024-06-01T18:07:16.246773Z"}]}
{"channel":"book","type":"update","data":[{"symbol":"LINK/BTC","bids":[],"asks":[{"price":0.00027381,"qty":404.85701152}],"checksum":681601500,"timestamp":"2024-06-01T18:07:16.327192Z"}]}
{"channel":"book","type":"update","data":[{"symbol":"LINK/BTC","bids":[{"price":0.00027355,"qty":204.85701152}],"asks":[],"checksum":698297812,"timestamp":"2024-06-01T18:07:16.450160Z"}]}
{"channel":"book","type":"update","data":[{"symbol":"LINK/BTC","bids":[],"asks":[{"price":0.00027390,"qty":0.00000000},{"price":0.00027440,"qty":88.51378950}],"checksum":27838479,"timestamp":"2024-06-01T18:07:16.507460Z"}]}
{"channel":"book","type":"update","data":[{"symbol":"LINK/BTC","bids":[],"asks":[{"price":0.00027416,"qty":0.00000000},{"price":0.00027451,"qty":4.23826739}],"checksum":4168147139,"timestamp":"2024-06-01T18:07:17.298659Z"}]}
{"channel":"book","type":"update","data":[{"symbol":"LINK/BTC","bids":[],"asks":[{"price":0.00027378,"qty":8.09307846}],"checksum":2722121617,"timestamp":"2024-06-01T18:07:17.303040Z"}]}
{"channel":"book","type":"update","data":[{"symbol":"LINK/BTC","bids":[],"asks":[{"price":0.00027403,"qty":8.08579372}],"checksum":2730675633,"timestamp":"2024-06-01T18:07:17.303155Z"}]}
{"channel":"book","type":"update","data":[{"symbol":"LINK/BTC","bids":[],"asks":[{"price":0.00027381,"qty":410.05701152}],"checksum":3901966433,"timestamp":"2024-06-01T18:07:17.588552Z"}]}
{"channel":"book","type":"update","data":[{"symbol":"LINK/BTC","bids":[],"asks":[{"price":0.00027378,"qty":208.09307846}],"checksum":1887184074,"timestamp":"2024-06-01T18:07:18.506051Z"}]}
{"channel":"book","type":"update","data":[{"symbol":"LINK/BTC","bids":[{"price":0.00027358,"qty":0.00000000},{"price":0.00027334,"qty":0.47056560}],"asks":[],"checksum":2963560082,"timestamp":"2024-06-01T18:07:18.583036Z"}]}
{"channel":"book","type":"update","data":[{"symbol":"LINK/BTC","bids":[{"price":0.00027358,"qty":6.90113710}],"asks":[],"checksum":795764142,"timestamp":"2024-06-01T18:07:18.588472Z"}]}
{"channel":"book","type":"update","data":[{"symbol":"LINK/BTC","bids":[],"asks":[{"price":0.00027381,"qty":210.05701152}],"checksum":1324414730,"timestamp":"2024-06-01T18:07:18.686201Z"}]}
{"channel":"book","type":"update","data":[{"symbol":"LINK/BTC","bids":[{"price":0.00027367,"qty":0.00000000},{"price":0.00027334,"qty":0.47056560}],"asks":[],"checksum":711723087,"timestamp":"2024-06-01T18:07:18.739418Z"}]}
{"channel":"book","type":"update","data":[{"symbol":"LINK/BTC","bids":[],"asks":[{"price":0.00027381,"qty":204.85701152}],"checksum":811873864,"timestamp":"2024-06-01T18:07:18.742133Z"}]}
{"channel":"book","type":"update","data":[{"symbol":"LINK/BTC","bids":[{"price":0.00027368,"qty":0.00000000},{"price":0.00027325,"qty":47.28000000}],"asks":[],"checksum":4091123732,"timestamp":"2024-06-01T18:07:18.742162Z"}]}
{"channel":"book","type":"update","data":[{"symbol":"LINK/BTC","bids":[{"price":0.00027361,"qty":5.20000000}],"asks":[],"checksum":4280879608,"timestamp":"2024-06-01T18:07:18.742293Z"}]}
{"channel":"book","type":"update","data":[{"symbol":"LINK/BTC","bids":[{"price":0.00027368,"qty":459.20875000}],"asks":[],"checksum":2574313222,"timestamp":"2024-06-01T18:07:18.742333Z"}]}
{"channel":"book","type":"update","data":[{"symbol":"LINK/BTC","bids":[],"asks":[{"price":0.00027377,"qty":5.20000000}],"checksum":2886403230,"timestamp":"2024-06-01T18:07:18.742473Z"}]}
{"channel":"book","type":"update","data":[{"symbol":"LINK/BTC","bids":[],"asks":[{"price":0.00027377,"qty":0.00000000},{"price":0.00027431,"qty":80.85684384}],"checksum":2574313222,"timestamp":"2024-06-01T18:07:18.745256Z"}]}
{"channel":"book","type":"update","data":[{"symbol":"LINK/BTC","bids":[],"asks":[{"price":0.00027390,"qty":8.08947716}],"checksum":3364803879,"timestamp":"2024-06-01T18:07:18.923489Z"}]}
{"channel":"book","type":"update","data":[{"symbol":"LINK/BTC","bids":[],"asks":[{"price":0.00027430,"qty":134.86464920}],"checksum":1586888586,"timestamp":"2024-06-01T18:07:19.193635Z"}]}
{"channel":"book","type":"update","data":[{"symbol":"LINK/BTC","bids":[],"asks":[{"price":0.00027429,"qty":0.00000000},{"price":0.00027431,"qty":80.85684384}],"checksum":742756960,"timestamp":"2024-06-01T18:07:19.193654Z"}]}
{"channel":"book","type":"update","data":[{"symbol":"LINK/BTC","bids":[],"asks":[{"price":0.00027381,"qty":200.00000000}],"checksum":3197191500,"timestamp":"2024-06-01T18:07:21.469264Z"}]}
{"channel":"book","type":"update","data":[{"symbol":"LINK/BTC","bids":[{"price":0.00027360,"qty":0.00000000},{"price":0.00027334,"qty":0.47056560}],"asks":[],"checksum":1756738817,"timestamp":"2024-06-01T18:07:21.524912Z"}]}
{"channel":"book","type":"update","data":[{"symbol":"LINK/BTC","bids":[{"price":0.00027362,"qty":26.99448259}],"asks":[],"checksum":3965146414,"timestamp":"2024-06-01T18:07:21.529846Z"}]}
{"channel":"book","type":"update","data":[{"symbol":"LINK/BTC","bids":[],"asks":[{"price":0.00027381,"qty":0.00000000},{"price":0.00027440,"qty":88.51378950}],"checksum":314315228,"timestamp":"2024-06-01T18:07:21.530147Z"}]}
{"channel":"book","type":"update","data":[{"symbol":"LINK/BTC","bids":[{"price":0.00027356,"qty":200.00000000}],"asks":[],"checksum":3229186096,"timestamp":"2024-06-01T18:07:21.530190Z"}]}
{"channel":"book","type":"update","data":[{"symbol":"LINK/BTC","bids":[],"asks":[{"price":0.00027385,"qty":200.00000000}],"checksum":3181923945,"timestamp":"2024-06-01T18:07:21.530246Z"}]}
{"channel":"book","type":"update","data":[{"symbol":"LINK/BTC","bids":[],"asks":[{"price":0.00027391,"qty":0.00000000},{"price":0.00027440,"qty":88.51378950}],"checksum":759453240,"timestamp":"2024-06-01T18:07:21.634284Z"}]}
{"channel":"book","type":"update","data":[{"symbol":"LINK/BTC","bids":[],"asks":[{"price":0.00027378,"qty":200.00000000}],"checksum":3927381269,"timestamp":"2024-06-01T18:07:21.636612Z"}]}
{"channel":"book","type":"update","data":[{"symbol":"LINK/BTC","bids":[{"price":0.00027353,"qty":176.84615276}],"asks":[],"checksum":1930762888,"timestamp":"2024-06-01T18:07:21.639137Z"}]}
{"channel":"book","type":"update","data":[{"symbol":"LINK/BTC","bids":[],"asks":[{"price":0.00027381,"qty":8.09311326}],"checksum":1101635289,"timestamp":"2024-06-01T18:07:21.640579Z"}]}
{"channel":"book","type":"update","data":[{"symbol":"LINK/BTC","bids":[],"asks":[{"price":0.00027392,"qty":200.00000000}],"checksum":2800132628,"timestamp":"2024-06-01T18:07:21.901642Z"}]}
{"channel":"book","type":"update","data":[{"symbol":"LINK/BTC","bids":[],"asks":[{"price":0.00027392,"qty":0.00000000},{"price":0.00027431,"qty":80.85684384}],"checksum":1101635289,"timestamp":"2024-06-01T18:07:22.259657Z"}]}
{"channel":"book","type":"update","data":[{"symbol":"LINK/BTC","bids":[],"asks":[{"price":0.00027394,"qty":254.50545037}],"checksum":746832308,"timestamp":"2024-06-01T18:07:22.564355Z"}]}
{"channel":"book","type":"update","data":[{"symbol":"LINK/BTC","bids":[],"asks":[{"price":0.00027380,"qty":200.00000000}],"checksum":1009231049,"timestamp":"2024-06-01T18:07:22.742349Z"}]}
{"channel":"book","type":"update","data":[{"symbol":"LINK/BTC","bids":[],"asks":[{"price":0.00027378,"qty":0.00000000},{"price":0.00027431,"qty":80.85684384}],"checksum":1925833403,"timestamp":"2024-06-01T18:07:22.921653Z"}]}
{"channel":"book","type":"update","data":[{"symbol":"LINK/BTC","bids":[{"price":0.00027358,"qty":0.00000000},{"price":0.00027339,"qty":42.76000000}],"asks":[],"checksum":2389544789,"timestamp":"2024-06-01T18:07:23.449692Z"}]}
{"channel":"book","type":"update","data":[{"symbol":"LINK/BTC","bids":[{"price":0.00027358,"qty":9.81082599}],"asks":[],"checksum":3311069679,"timestamp":"2024-06-01T18:07:23.457439Z"}]}
{"channel":"book","type":"update","data":[{"symbol":"LINK/BTC","bids":[{"price":0.00027368,"qty":0.00000000},{"price":0.00027339,"qty":42.76000000}],"asks":[],"checksum":1326287439,"timestamp":"2024-06-01T18:07:24.624152Z"}]}
{"channel":"book","type":"update","data":[{"symbol":"LINK/BTC","bids":[{"price":0.00027361,"qty":0.00000000},{"price":0.00027334,"qty":0.47056560}],"asks":[],"checksum":1726675760,"timestamp":"2024-06-01T18:07:24.626924Z"}]}
{"channel":"book","type":"update","data":[{"symbol":"LINK/BTC","bids":[{"price":0.00027369,"qty":459.20875000}],"asks":[],"checksum":1014169215,"timestamp":"2024-06-01T18:07:24.627010Z"}]}
{"channel":"book","type":"update","data":[{"symbol":"LINK/BTC","bids":[],"asks":[{"price":0.00027379,"qty":5.20000000}],"checksum":711452832,"timestamp":"2024-06-01T18:07:24.627060Z"}]}
{"channel":"book","type":"update","data":[{"symbol":"LINK/BTC","bids":[{"price":0.00027363,"qty":4.85667549}],"asks":[],"checksum":116698222,"timestamp":"2024-06-01T18:07:24.627109Z"}]}
{"channel":"book","type":"update","data":[{"symbol":"LINK/BTC","bids":[{"price":0.00027363,"qty":10.05667549}],"asks":[],"checksum":1130614913,"timestamp":"2024-06-01T18:07:24.627255Z"}]}
{"channel":"book","type":"update","data":[{"symbol":"LINK/BTC","bids":[{"price":0.00027363,"qty":18.68026469}],"asks":[],"checksum":2162283063,"timestamp":"2024-06-01T18:07:24.629719Z"}]}
