{"channel":"book","type":"snapshot","data":[{"symbol":"LINK/EUR","bids":[{"price":17.10861,"qty":70.02006900},{"price":17.10856,"qty":28.58000000},{"price":17.10311,"qty":303.70000000},{"price":17.10310,"qty":47.43738600},{"price":17.10205,"qty":70.02006900},{"price":17.10030,"qty":467.47688400},{"price":17.10029,"qty":134.79123346},{"price":17.10007,"qty":243.48672997},{"price":17.09852,"qty":19.20000000},{"price":17.09770,"qty":149.28697600}],"asks":[{"price":17.10862,"qty":145.38590918},{"price":17.11205,"qty":200.00000000},{"price":17.11315,"qty":27.39604051},{"price":17.11559,"qty":200.00000000},{"price":17.11560,"qty":243.48672997},{"price":17.11583,"qty":1078.72421567},{"price":17.12350,"qty":200.00000000},{"price":17.12581,"qty":269.10000000},{"price":17.13808,"qty":70.52987272},{"price":17.13809,"qty":150.00000000}],"checksum":2699376089}]}
{"channel":"book","type":"update","data":[{"symbol":"LINK/EUR","bids":[],"asks":[{"price":17.12350,"qty":0.00000000},{"price":17.13810,"qty":17.20000000}],"checksum":2965646231,"timestamp":"2024-06-01T18:06:54.123281Z"}]}
{"channel":"book","type":"update","data":[{"symbol":"LINK/EUR","bids":[],"asks":[{"price":17.11315,"qty":0.00000000},{"price":17.13890,"qty":47.43738600}],"checksum":4090291535,"timestamp":"2024-06-01T18:06:54.210659Z"}]}
{"channel":"book","type":"update","data":[{"symbol":"LINK/EUR","bids":[],"asks":[{"price":17.10947,"qty":56.74354051}],"checksum":1799035895,"timestamp":"2024-06-01T18:06:54.214482Z"}]}
{"channel":"book","type":"update","data":[{"symbol":"LINK/EUR","bids":[{"price":17.10029,"qty":0.00000000},{"price":17.09559,"qty":161.72000000}],"asks":[],"checksum":3565692607,"timestamp":"2024-06-01T18:06:54.217680Z"}]}
{"channel":"book","type":"update","data":[{"symbol":"LINK/EUR","bids":[{"price":17.09979,"qty":134.79517631}],"asks":[],"checksum":1952050468,"timestamp":"2024-06-01T18:06:54.222548Z"}]}
{"channel":"book","type":"update","data":[{"symbol":"LINK/EUR","bids":[],"asks":[{"price":17.11411,"qty":1078.69515192}],"checksum":1218471351,"timestamp":"2024-06-01T18:06:54.236393Z"}]}
{"channel":"book","type":"update","data":[{"symbol":"LINK/EUR","bids":[{"price":17.10205,"qty":0.00000000},{"price":17.09559,"qty":161.72000000}],"asks":[],"checksum":4144681795,"timestamp":"2024-06-01T18:06:54.409500Z"}]}
{"channel":"book","type":"update","data":[{"symbol":"LINK/EUR","bids":[],"asks":[{"price":17.12302,"qty":200.00000000}],"checksum":1891398735,"timestamp":"2024-06-01T18:06:54.411308Z"}]}
{"channel":"book","type":"update","data":[{"symbol":"LINK/EUR","bids":[{"price":17.09559,"qty":0.00000000},{"price":17.09501,"qty":12.19148185}],"asks":[],"checksum":4186498086,"timestamp":"2024-06-01T18:06:54.606450Z"}]}
{"channel":"book","type":"update","data":[{"symbol":"LINK/EUR","bids":[{"price":17.09781,"qty":200.00000000}],"asks":[],"checksum":2430774472,"timestamp":"2024-06-01T18:06:54.761487Z"}]}
{"channel":"book","type":"update","data":[{"symbol":"LINK/EUR","bids":[{"price":17.09781,"qty":0.00000000},{"price":17.09501,"qty":12.19148185}],"asks":[],"checksum":4186498086,"timestamp":"2024-06-01T18:06:55.065304Z"}]}
{"channel":"book","type":"update","data":[{"symbol":"LINK/EUR","bids":[{"price":17.09979,"qty":0.00000000},{"price":17.09500,"qty":152.64984900}],"asks":[],"checksum":625670455,"timestamp":"2024-06-01T18:06:55.212085Z"}]}
{"channel":"book","type":"update","data":[{"symbol":"LINK/EUR","bids":[{"price":17.09911,"qty":134.80051287}],"asks":[],"checksum":1288067943,"timestamp":"2024-06-01T18:06:55.216586Z"}]}
{"channel":"book","type":"update","data":[{"symbol":"LINK/EUR","bids":[],"asks":[{"price":17.11411,"qty":0.00000000},{"price":17.13809,"qty":150.00000000}],"checksum":392658177,"timestamp":"2024-06-01T18:06:55.352136Z"}]}
{"channel":"book","type":"update","data":[{"symbol":"LINK/EUR","bids":[],"asks":[{"price":17.11583,"qty":0.00000000},{"price":17.13810,"qty":17.20000000}],"checksum":3534567720,"timestamp":"2024-06-01T18:06:55.352299Z"}]}
{"channel":"book","type":"update","data":[{"symbol":"LINK/EUR","bids":[],"asks":[{"price":17.12581,"qty":0.00000000},{"price":17.13890,"qty":47.43738600},{"price":17.13807,"qty":269.10000000}],"checksum":775842805,"timestamp":"2024-06-01T18:06:55.355212Z"}]}
{"channel":"book","type":"update","data":[{"symbol":"LINK/EUR","bids":[{"price":17.09779,"qty":200.00000000}],"asks":[],"checksum":3893451671,"timestamp":"2024-06-01T18:06:55.356291Z"}]}
{"channel":"book","type":"update","data":[{"symbol":"LINK/EUR","bids":[],"asks":[{"price":17.13806,"qty":70.52987272}],"checksum":3239450007,"timestamp":"2024-06-01T18:06:55.362738Z"}]}
{"channel":"book","type":"update","data":[{"symbol":"LINK/EUR","bids":[],"asks":[{"price":17.13808,"qty":0.00000000},{"price":17.13810,"qty":17.20000000}],"checksum":3103660297,"timestamp":"2024-06-01T18:06:55.362761Z"}]}
{"channel":"book","type":"update","data":[{"symbol":"LINK/EUR","bids":[{"price":17.09779,"qty":0.00000000},{"price":17.09501,"qty":12.19148185}],"asks":[],"checksum":3289237893,"timestamp":"2024-06-01T18:06:55.635511Z"}]}
{"channel":"book","type":"update","data":[{"symbol":"LINK/EUR","bids":[],"asks":[{"price":17.13805,"qty":14.76034995}],"checksum":1382899721,"timestamp":"2024-06-01T18:06:55.870216Z"}]}
{"channel":"book","type":"update","data":[{"symbol":"LINK/EUR","bids":[],"asks":[{"price":17.13807,"qty":0.00000000},{"price":17.13810,"qty":17.20000000},{"price":17.13805,"qty":283.86034995}],"checksum":770856546,"timestamp":"2024-06-01T18:06:55.872365Z"}]}
{"channel":"book","type":"update","data":[{"symbol":"LINK/EUR","bids":[],"asks":[{"price":17.13806,"qty":0.00000000},{"price":17.13890,"qty":47.43738600}],"checksum":267311938,"timestamp":"2024-06-01T18:06:55.905554Z"}]}
{"channel":"book","type":"update","data":[{"symbol":"LINK/EUR","bids":[],"asks":[{"price":17.13804,"qty":70.52987272}],"checksum":2784287652,"timestamp":"2024-06-01T18:06:55.905671Z"}]}
{"channel":"book","type":"update","data":[{"symbol":"LINK/EUR","bids":[{"price":17.09776,"qty":200.00000000}],"asks":[],"checksum":2040678268,"timestamp":"2024-06-01T18:06:55.928480Z"}]}
{"channel":"book","type":"update","data":[{"symbol":"LINK/EUR","bids":[{"price":17.09911,"qty":0.00000000},{"price":17.09501,"qty":12.19148185}],"asks":[],"checksum":1163856829,"timestamp":"2024-06-01T18:06:56.029330Z"}]}
{"channel":"book","type":"update","data":[{"symbol":"LINK/EUR","bids":[{"price":17.09854,"qty":134.80505352}],"asks":[],"checksum":1378850294,"timestamp":"2024-06-01T18:06:56.033383Z"}]}
{"channel":"book","type":"update","data":[{"symbol":"LINK/EUR","bids":[],"asks":[{"price":17.11358,"qty":1078.69515192}],"checksum":819074584,"timestamp":"2024-06-01T18:06:56.073408Z"}]}
{"channel":"book","type":"update","data":[{"symbol":"LINK/EUR","bids":[],"asks":[{"price":17.11376,"qty":243.48672997}],"checksum":625566891,"timestamp":"2024-06-01T18:06:56.079986Z"}]}
{"channel":"book","type":"update","data":[{"symbol":"LINK/EUR","bids":[{"price":17.09854,"qty":0.00000000},{"price":17.09501,"qty":12.19148185}],"asks":[],"checksum":614383804,"timestamp":"2024-06-01T18:06:56.129212Z"}]}
{"channel":"book","type":"update","data":[{"symbol":"LINK/EUR","bids":[{"price":17.09776,"qty":0.00000000},{"price":17.09500,"qty":152.64984900}],"asks":[],"checksum":2914628341,"timestamp":"2024-06-01T18:06:56.207219Z"}]}
{"channel":"book","type":"update","data":[{"symbol":"LINK/EUR","bids":[{"price":17.09501,"qty":0.00000000},{"price":17.09422,"qty":269.68105392}],"asks":[],"checksum":1970530065,"timestamp":"2024-06-01T18:06:56.255569Z"}]}
{"channel":"book","type":"update","data":[{"symbol":"LINK/EUR","bids":[{"price":17.09477,"qty":12.19165301}],"asks":[],"checksum":4012277118,"timestamp":"2024-06-01T18:06:56.374431Z"}]}
{"channel":"book","type":"update","data":[{"symbol":"LINK/EUR","bids":[{"price":17.09709,"qty":200.00000000}],"asks":[],"checksum":925222372,"timestamp":"2024-06-01T18:06:56.488427Z"}]}
{"channel":"book","type":"update","data":[{"symbol":"LINK/EUR","bids":[],"asks":[{"price":17.11560,"qty":0.00000000},{"price":17.13809,"qty":150.00000000}],"checksum":376949989,"timestamp":"2024-06-01T18:06:56.558721Z"}]}
{"channel":"book","type":"update","data":[{"symbol":"LINK/EUR","bids":[{"price":17.09928,"qty":134.79922622}],"asks":[],"checksum":4095933906,"timestamp":"2024-06-01T18:06:56.674216Z"}]}
{"channel":"book","type":"update","data":[{"symbol":"LINK/EUR","bids":[{"price":17.09709,"qty":0.00000000},{"price":17.09500,"qty":152.64984900}],"asks":[],"checksum":2083790184,"timestamp":"2024-06-01T18:06:56.890093Z"}]}
{"channel":"book","type":"update","data":[{"symbol":"LINK/EUR","bids":[{"price":17.09928,"qty":0.00000000},{"price":17.09477,"qty":12.19165301}],"asks":[],"checksum":165398858,"timestamp":"2024-06-01T18:06:57.079763Z"}]}
{"channel":"book","type":"update","data":[{"symbol":"LINK/EUR","bids":[{"price":17.09708,"qty":200.00000000}],"asks":[],"checksum":706162669,"timestamp":"2024-06-01T18:06:57.187825Z"}]}
{"channel":"book","type":"update","data":[{"symbol":"LINK/EUR","bids":[{"price":17.09708,"qty":0.00000000},{"price":17.09477,"qty":12.19165301}],"asks":[],"checksum":165398858,"timestamp":"2024-06-01T18:06:57.507674Z"}]}
{"channel":"book","type":"update","data":[{"symbol":"LINK/EUR","bids":[{"price":17.09708,"qty":200.00000000}],"asks":[],"checksum":706162669,"timestamp":"2024-06-01T18:06:57.785291Z"}]}
{"channel":"book","type":"update","data":[{"symbol":"LINK/EUR","bids":[],"asks":[{"price":17.13805,"qty":269.10000000}],"checksum":300115665,"timestamp":"2024-06-01T18:06:58.331037Z"}]}
{"channel":"book","type":"update","data":[{"symbol":"LINK/EUR","bids":[],"asks":[{"price":17.13803,"qty":6.34108489}],"checksum":2420369126,"timestamp":"2024-06-01T18:06:58.331793Z"}]}
{"channel":"book","type":"update","data":[{"symbol":"LINK/EUR","bids":[{"price":17.09708,"qty":0.00000000},{"price":17.09477,"qty":12.19165301}],"asks":[],"checksum":2367997886,"timestamp":"2024-06-01T18:06:58.363229Z"}]}
{"channel":"book","type":"update","data":[{"symbol":"LINK/EUR","bids":[{"price":17.09921,"qty":134.79972717}],"asks":[],"checksum":1559689764,"timestamp":"2024-06-01T18:06:58.389692Z"}]}
{"channel":"book","type":"update","data":[{"symbol":"LINK/EUR","bids":[],"asks":[{"price":17.10862,"qty":144.43411301}],"checksum":1090747892,"timestamp":"2024-06-01T18:06:58.400679Z"}]}
{"channel":"book","type":"update","data":[{"symbol":"LINK/EUR","bids":[],"asks":[{"price":17.10862,"qty":145.38590918}],"checksum":1559689764,"timestamp":"2024-06-01T18:06:58.523082Z"}]}
{"channel":"book","type":"update","data":[{"symbol":"LINK/EUR","bids":[{"price":17.09696,"qty":200.00000000}],"asks":[],"checksum":3169742449,"timestamp":"2024-06-01T18:06:58.663690Z"}]}
{"channel":"book","type":"update","data":[{"symbol":"LINK/EUR","bids":[{"price":17.09696,"qty":0.00000000},{"price":17.09500,"qty":152.64984900}],"asks":[],"checksum":1559689764,"timestamp":"2024-06-01T18:06:58.952191Z"}]}
{"channel":"book","type":"update","data":[{"symbol":"LINK/EUR","bids":[{"price":17.09680,"qty":200.00000000}],"asks":[],"checksum":2386891284,"timestamp":"2024-06-01T18:06:59.248434Z"}]}
{"channel":"book","type":"update","data":[{"symbol":"LINK/EUR","bids":[{"price":17.10007,"qty":0.00000000},{"price":17.09500,"qty":152.64984900}],"asks":[],"checksum":3855698836,"timestamp":"2024-06-01T18:07:00.476453Z"}]}
{"channel":"book","type":"update","data":[{"symbol":"LINK/EUR","bids":[],"asks":[{"price":17.11358,"qty":0.00000000},{"price":17.13809,"qty":150.00000000}],"checksum":4167485666,"timestamp":"2024-06-01T18:07:00.729939Z"}]}
{"channel":"book","type":"update","data":[{"symbol":"LINK/EUR","bids":[],"asks":[{"price":17.13805,"qty":0.00000000},{"price":17.13810,"qty":17.20000000},{"price":17.13803,"qty":275.44108489}],"checksum":3106891786,"timestamp":"2024-06-01T18:07:00.732712Z"}]}
{"channel":"book","type":"update","data":[{"symbol":"LINK/EUR","bids":[],"asks":[{"price":17.13802,"qty":70.52987272}],"checksum":1048197088,"timestamp":"2024-06-01T18:07:00.748395Z"}]}
{"channel":"book","type":"update","data":[{"symbol":"LINK/EUR","bids":[],"asks":[{"price":17.13804,"qty":0.00000000},{"price":17.13810,"qty":17.20000000}],"checksum":1653740727,"timestamp":"2024-06-01T18:07:00.748980Z"}]}
{"channel":"book","type":"update","data":[{"symbol":"LINK/EUR","bids":[{"price":17.09921,"qty":0.00000000},{"price":17.09477,"qty":12.19165301}],"asks":[],"checksum":3380365013,"timestamp":"2024-06-01T18:07:00.769567Z"}]}
{"channel":"book","type":"update","data":[{"symbol":"LINK/EUR","bids":[{"price":17.09878,"qty":134.80313640}],"asks":[],"checksum":3649542084,"timestamp":"2024-06-01T18:07:00.775034Z"}]}
{"channel":"book","type":"update","data":[{"symbol":"LINK/EUR","bids":[],"asks":[{"price":17.13803,"qty":269.10000000}],"checksum":125496016,"timestamp":"2024-06-01T18:07:00.851452Z"}]}
{"channel":"book","type":"update","data":[{"symbol":"LINK/EUR","bids":[],"asks":[{"price":17.13803,"qty":276.49354274}],"checksum":3156563995,"timestamp":"2024-06-01T18:07:00.852595Z"}]}
{"channel":"book","type":"update","data":[{"symbol":"LINK/EUR","bids":[{"price":17.09878,"qty":0.00000000},{"price":17.09477,"qty":12.19165301}],"asks":[],"checksum":3681181581,"timestamp":"2024-06-01T18:07:02.073620Z"}]}
{"channel":"book","type":"update","data":[{"symbol":"LINK/EUR","bids":[],"asks":[{"price":17.13803,"qty":7.39354274},{"price":17.13801,"qty":269.10000000}],"checksum":1099927836,"timestamp":"2024-06-01T18:07:02.076560Z"}]}
{"channel":"book","type":"update","data":[{"symbol":"LINK/EUR","bids":[{"price":17.09914,"qty":134.80030231}],"asks":[],"checksum":3007937354,"timestamp":"2024-06-01T18:07:02.077028Z"}]}
{"channel":"book","type":"update","data":[{"symbol":"LINK/EUR","bids":[],"asks":[{"price":17.13800,"qty":70.52987272}],"checksum":2263695175,"timestamp":"2024-06-01T18:07:02.087272Z"}]}
{"channel":"book","type":"update","data":[{"symbol":"LINK/EUR","bids":[],"asks":[{"price":17.13802,"qty":0.00000000},{"price":17.13809,"qty":150.00000000}],"checksum":3244019980,"timestamp":"2024-06-01T18:07:02.087437Z"}]}
{"channel":"book","type":"update","data":[{"symbol":"LINK/EUR","bids":[],"asks":[{"price":17.10862,"qty":144.43411301}],"checksum":2211210524,"timestamp":"2024-06-01T18:07:02.296945Z"}]}
{"channel":"book","type":"update","data":[{"symbol":"LINK/EUR","bids":[],"asks":[{"price":17.10862,"qty":145.38590918}],"checksum":3244019980,"timestamp":"2024-06-01T18:07:02.472751Z"}]}
{"channel":"book","type":"update","data":[{"symbol":"LINK/EUR","bids":[],"asks":[{"price":17.13803,"qty":0.00000000},{"price":17.13810,"qty":17.20000000}],"checksum":3123342606,"timestamp":"2024-06-01T18:07:03.292985Z"}]}
{"channel":"book","type":"update","data":[{"symbol":"LINK/EUR","bids":[],"asks":[{"price":17.13799,"qty":14.33318670}],"checksum":3410844460,"timestamp":"2024-06-01T18:07:03.293581Z"}]}
{"channel":"book","type":"update","data":[{"symbol":"LINK/EUR","bids":[],"asks":[{"price":17.13801,"qty":0.00000000},{"price":17.13810,"qty":17.20000000},{"price":17.13799,"qty":283.43318670}],"checksum":1882230737,"timestamp":"2024-06-01T18:07:03.295829Z"}]}
{"channel":"book","type":"update","data":[{"symbol":"LINK/EUR","bids":[],"asks":[{"price":17.13798,"qty":70.52987272}],"checksum":3795380357,"timestamp":"2024-06-01T18:07:03.302815Z"}]}
{"channel":"book","type":"update","data":[{"symbol":"LINK/EUR","bids":[],"asks":[{"price":17.13800,"qty":0.00000000},{"price":17.13810,"qty":17.20000000}],"checksum":2721001109,"timestamp":"2024-06-01T18:07:03.303021Z"}]}
{"channel":"book","type":"update","data":[{"symbol":"LINK/EUR","bids":[{"price":17.09914,"qty":0.00000000},{"price":17.09477,"qty":12.19165301}],"asks":[],"checksum":651236039,"timestamp":"2024-06-01T18:07:03.417953Z"}]}
{"channel":"book","type":"update","data":[{"symbol":"LINK/EUR","bids":[{"price":17.09960,"qty":134.79668404}],"asks":[],"checksum":3148447694,"timestamp":"2024-06-01T18:07:03.421531Z"}]}
{"channel":"book","type":"update","data":[{"symbol":"LINK/EUR","bids":[],"asks":[{"price":17.10862,"qty":144.43411301}],"checksum":2791110686,"timestamp":"2024-06-01T18:07:03.482503Z"}]}
{"channel":"book","type":"update","data":[{"symbol":"LINK/EUR","bids":[],"asks":[{"price":17.10862,"qty":145.38590918}],"checksum":3148447694,"timestamp":"2024-06-01T18:07:03.603524Z"}]}
{"channel":"book","type":"update","data":[{"symbol":"LINK/EUR","bids":[{"price":17.09960,"qty":0.00000000},{"price":17.09477,"qty":12.19165301}],"asks":[],"checksum":651236039,"timestamp":"2024-06-01T18:07:03.707809Z"}]}
{"channel":"book","type":"update","data":[{"symbol":"LINK/EUR","bids":[{"price":17.10861,"qty":0.00000000},{"price":17.09422,"qty":269.68105392}],"asks":[],"checksum":2350939838,"timestamp":"2024-06-01T18:07:03.931014Z"}]}
{"channel":"book","type":"update","data":[{"symbol":"LINK/EUR","bids":[{"price":17.10030,"qty":0.00000000},{"price":17.09380,"qty":24.91522417}],"asks":[],"checksum":3906224352,"timestamp":"2024-06-01T18:07:03.931080Z"}]}
{"channel":"book","type":"update","data":[{"symbol":"LINK/EUR","bids":[],"asks":[{"price":17.13799,"qty":14.33318670},{"price":17.13797,"qty":269.10000000}],"checksum":990488514,"timestamp":"2024-06-01T18:07:03.931684Z"}]}
{"channel":"book","type":"update","data":[{"symbol":"LINK/EUR","bids":[{"price":17.10312,"qty":70.02006900}],"asks":[],"checksum":3659733343,"timestamp":"2024-06-01T18:07:03.933672Z"}]}
{"channel":"book","type":"update","data":[{"symbol":"LINK/EUR","bids":[{"price":17.10356,"qty":21.00000000}],"asks":[],"checksum":1044983578,"timestamp":"2024-06-01T18:07:03.934102Z"}]}
{"channel":"book","type":"update","data":[{"symbol":"LINK/EUR","bids":[{"price":17.09681,"qty":467.47688400}],"asks":[],"checksum":155840138,"timestamp":"2024-06-01T18:07:03.934437Z"}]}
{"channel":"book","type":"update","data":[{"symbol":"LINK/EUR","bids":[],"asks":[{"price":17.11192,"qty":243.48672997}],"checksum":131856523,"timestamp":"2024-06-01T18:07:03.935471Z"}]}
{"channel":"book","type":"update","data":[{"symbol":"LINK/EUR","bids":[{"price":17.10311,"qty":0.00000000},{"price":17.09477,"qty":12.19165301},{"price":17.10313,"qty":303.70000000}],"asks":[],"checksum":173469651,"timestamp":"2024-06-01T18:07:03.936200Z"}]}
{"channel":"book","type":"update","data":[{"symbol":"LINK/EUR","bids":[],"asks":[{"price":17.11279,"qty":1078.78816142}],"checksum":1316862691,"timestamp":"2024-06-01T18:07:03.936670Z"}]}
{"channel":"book","type":"update","data":[{"symbol":"LINK/EUR","bids":[],"asks":[{"price":17.13798,"qty":0.00000000},{"price":17.13799,"qty":14.33318670}],"checksum":3166614656,"timestamp":"2024-06-01T18:07:03.937570Z"}]}
{"channel":"book","type":"update","data":[{"symbol":"LINK/EUR","bids":[],"asks":[{"price":17.13796,"qty":70.52987272}],"checksum":2278795125,"timestamp":"2024-06-01T18:07:03.937887Z"}]}
{"channel":"book","type":"update","data":[{"symbol":"LINK/EUR","bids":[{"price":17.09964,"qty":134.79638169}],"asks":[],"checksum":3277640824,"timestamp":"2024-06-01T18:07:03.938024Z"}]}
{"channel":"book","type":"update","data":[{"symbol":"LINK/EUR","bids":[{"price":17.09964,"qty":0.00000000},{"price":17.09500,"qty":152.64984900}],"asks":[],"checksum":2278795125,"timestamp":"2024-06-01T18:07:03.941067Z"}]}
{"channel":"book","type":"update","data":[{"symbol":"LINK/EUR","bids":[],"asks":[{"price":17.10862,"qty":144.43411301}],"checksum":18710566,"timestamp":"2024-06-01T18:07:03.965096Z"}]}
{"channel":"book","type":"update","data":[{"symbol":"LINK/EUR","bids":[],"asks":[{"price":17.11376,"qty":0.00000000},{"price":17.13799,"qty":14.33318670}],"checksum":2636966328,"timestamp":"2024-06-01T18:07:03.968886Z"}]}
{"channel":"book","type":"update","data":[{"symbol":"LINK/EUR","bids":[],"asks":[{"price":17.10859,"qty":40.00000000}],"checksum":781250723,"timestamp":"2024-06-01T18:07:03.970394Z"}]}
{"channel":"book","type":"update","data":[{"symbol":"LINK/EUR","bids":[],"asks":[{"price":17.10857,"qty":9.70954963}],"checksum":2702519496,"timestamp":"2024-06-01T18:07:03.973525Z"}]}
{"channel":"book","type":"update","data":[{"symbol":"LINK/EUR","bids":[],"asks":[{"price":17.10862,"qty":9.70844102}],"checksum":3567017342,"timestamp":"2024-06-01T18:07:03.974882Z"}]}
{"channel":"book","type":"update","data":[{"symbol":"LINK/EUR","bids":[],"asks":[{"price":17.10862,"qty":0.00000000},{"price":17.13797,"qty":269.10000000}],"checksum":3411749045,"timestamp":"2024-06-01T18:07:03.976494Z"}]}
{"channel":"book","type":"update","data":[{"symbol":"LINK/EUR","bids":[{"price":17.09680,"qty":0.00000000},{"price":17.09349,"qty":269.68973428}],"asks":[],"checksum":3258073737,"timestamp":"2024-06-01T18:07:04.048766Z"}]}
{"channel":"book","type":"update","data":[{"symbol":"LINK/EUR","bids":[],"asks":[{"price":17.10859,"qty":0.00000000},{"price":17.13799,"qty":14.33318670}],"checksum":574517985,"timestamp":"2024-06-01T18:07:04.094480Z"}]}
{"channel":"book","type":"update","data":[{"symbol":"LINK/EUR","bids":[],"asks":[{"price":17.10944,"qty":40.00000000}],"checksum":1977148876,"timestamp":"2024-06-01T18:07:04.094553Z"}]}
{"channel":"book","type":"update","data":[{"symbol":"LINK/EUR","bids":[],"asks":[{"price":17.10857,"qty":10.66134580}],"checksum":204394512,"timestamp":"2024-06-01T18:07:04.169277Z"}]}
{"channel":"book","type":"update","data":[{"symbol":"LINK/EUR","bids":[{"price":17.10059,"qty":56.74354051}],"asks":[],"checksum":4049278159,"timestamp":"2024-06-01T18:07:04.332198Z"}]}
{"channel":"book","type":"update","data":[{"symbol":"LINK/EUR","bids":[],"asks":[{"price":17.10946,"qty":200.00000000}],"checksum":3577413119,"timestamp":"2024-06-01T18:07:04.440147Z"}]}
{"channel":"book","type":"update","data":[{"symbol":"LINK/EUR","bids":[],"asks":[{"price":17.10943,"qty":40.00000000}],"checksum":2191202847,"timestamp":"2024-06-01T18:07:04.446026Z"}]}
{"channel":"book","type":"update","data":[{"symbol":"LINK/EUR","bids":[],"asks":[{"price":17.11205,"qty":0.00000000},{"price":17.13796,"qty":70.52987272}],"checksum":1871797546,"timestamp":"2024-06-01T18:07:04.446043Z"}]}
{"channel":"book","type":"update","data":[{"symbol":"LINK/EUR","bids":[],"asks":[{"price":17.10944,"qty":0.00000000},{"price":17.13797,"qty":269.10000000}],"checksum":21083200,"timestamp":"2024-06-01T18:07:04.593615Z"}]}
{"channel":"book","type":"update","data":[{"symbol":"LINK/EUR","bids":[],"asks":[{"price":17.10858,"qty":134.72597483}],"checksum":3327679872,"timestamp":"2024-06-01T18:07:04.742727Z"}]}
{"channel":"book","type":"update","data":[{"symbol":"LINK/EUR","bids":[{"price":17.09855,"qty":134.80496215}],"asks":[],"checksum":1046016216,"timestamp":"2024-06-01T18:07:04.742898Z"}]}
{"channel":"book","type":"update","data":[{"symbol":"LINK/EUR","bids":[],"asks":[{"price":17.10857,"qty":210.66134580}],"checksum":625552582,"timestamp":"2024-06-01T18:07:04.747799Z"}]}
{"channel":"book","type":"update","data":[{"symbol":"LINK/EUR","bids":[],"asks":[{"price":17.10946,"qty":0.00000000},{"price":17.13797,"qty":269.10000000}],"checksum":2559744858,"timestamp":"2024-06-01T18:07:04.939719Z"}]}
{"channel":"book","type":"update","data":[{"symbol":"LINK/EUR","bids":[],"asks":[{"price":17.13795,"qty":6.80171849}],"checksum":1149840905,"timestamp":"2024-06-01T18:07:05.757312Z"}]}
{"channel":"book","type":"update","data":[{"symbol":"LINK/EUR","bids":[],"asks":[{"price":17.10857,"qty":10.66134580}],"checksum":3885375891,"timestamp":"2024-06-01T18:07:06.552460Z"}]}
{"channel":"book","type":"update","data":[{"symbol":"LINK/EUR","bids":[],"asks":[{"price":17.10857,"qty":9.70954963}],"checksum":208784986,"timestamp":"2024-06-01T18:07:06.576772Z"}]}
{"channel":"book","type":"update","data":[{"symbol":"LINK/EUR","bids":[{"price":17.09855,"qty":0.00000000},{"price":17.09500,"qty":152.64984900}],"asks":[],"checksum":4101071618,"timestamp":"2024-06-01T18:07:06.604683Z"}]}
{"channel":"book","type":"update","data":[{"symbol":"LINK/EUR","bids":[{"price":17.09899,"qty":134.80153512}],"asks":[],"checksum":2456763200,"timestamp":"2024-06-01T18:07:06.608842Z"}]}
{"channel":"book","type":"update","data":[{"symbol":"LINK/EUR","bids":[],"asks":[{"price":17.10857,"qty":10.66134580}],"checksum":2039010441,"timestamp":"2024-06-01T18:07:06.695939Z"}]}
{"channel":"book","type":"update","data":[{"symbol":"LINK/EUR","bids":[],"asks":[{"price":17.11113,"qty":200.00000000}],"checksum":3434776536,"timestamp":"2024-06-01T18:07:06.813005Z"}]}
{"channel":"book","type":"update","data":[{"symbol":"LINK/EUR","bids":[],"asks":[{"price":17.11192,"qty":0.00000000},{"price":17.13796,"qty":70.52987272}],"checksum":2067690700,"timestamp":"2024-06-01T18:07:07.105294Z"}]}
{"channel":"book","type":"update","data":[{"symbol":"LINK/EUR","bids":[{"price":17.09899,"qty":0.00000000},{"price":17.09500,"qty":152.64984900}],"asks":[],"checksum":488647822,"timestamp":"2024-06-01T18:07:07.108575Z"}]}
{"channel":"book","type":"update","data":[{"symbol":"LINK/EUR","bids":[{"price":17.09501,"qty":269.60000000}],"asks":[],"checksum":361148924,"timestamp":"2024-06-01T18:07:07.112091Z"}]}
{"channel":"book","type":"update","data":[{"symbol":"LINK/EUR","bids":[{"price":17.10043,"qty":134.79012343}],"asks":[],"checksum":3408659164,"timestamp":"2024-06-01T18:07:07.116938Z"}]}
{"channel":"book","type":"update","data":[{"symbol":"LINK/EUR","bids":[],"asks":[{"price":17.10857,"qty":9.70954963}],"checksum":550235413,"timestamp":"2024-06-01T18:07:07.134574Z"}]}
{"channel":"book","type":"update","data":[{"symbol":"LINK/EUR","bids":[],"asks":[{"price":17.10857,"qty":0.00000000},{"price":17.13797,"qty":269.10000000}],"checksum":2607986054,"timestamp":"2024-06-01T18:07:07.135971Z"}]}
{"channel":"book","type":"update","data":[{"symbol":"LINK/EUR","bids":[{"price":17.10007,"qty":243.48672997}],"asks":[],"checksum":308791618,"timestamp":"2024-06-01T18:07:07.142165Z"}]}
{"channel":"book","type":"update","data":[{"symbol":"LINK/EUR","bids":[{"price":17.10043,"qty":0.00000000},{"price":17.09681,"qty":467.47688400}],"asks":[],"checksum":2863797060,"timestamp":"2024-06-01T18:07:07.157995Z"}]}
{"channel":"book","type":"update","data":[{"symbol":"LINK/EUR","bids":[],"asks":[{"price":17.10899,"qty":0.95179617}],"checksum":567068213,"timestamp":"2024-06-01T18:07:07.255724Z"}]}
{"channel":"book","type":"update","data":[{"symbol":"LINK/EUR","bids":[],"asks":[{"price":17.11469,"qty":243.48672997}],"checksum":2190299787,"timestamp":"2024-06-01T18:07:07.259868Z"}]}
{"channel":"book","type":"update","data":[{"symbol":"LINK/EUR","bids":[],"asks":[{"price":17.12302,"qty":0.00000000},{"price":17.13796,"qty":70.52987272}],"checksum":1842545375,"timestamp":"2024-06-01T18:07:07.369564Z"}]}
{"channel":"book","type":"update","data":[{"symbol":"LINK/EUR","bids":[],"asks":[{"price":17.12091,"qty":134.72597483}],"checksum":4284607931,"timestamp":"2024-06-01T18:07:07.636960Z"}]}
{"channel":"book","type":"update","data":[{"symbol":"LINK/EUR","bids":[{"price":17.09682,"qty":269.60000000}],"asks":[],"checksum":194920326,"timestamp":"2024-06-01T18:07:07.639672Z"}]}
{"channel":"book","type":"update","data":[{"symbol":"LINK/EUR","bids":[{"price":17.10040,"qty":134.79034341}],"asks":[],"checksum":3636488132,"timestamp":"2024-06-01T18:07:08.116520Z"}]}
{"channel":"book","type":"update","data":[{"symbol":"LINK/EUR","bids":[{"price":17.10312,"qty":0.00000000},{"price":17.09682,"qty":269.60000000}],"asks":[],"checksum":1950831293,"timestamp":"2024-06-01T18:07:08.884877Z"}]}
{"channel":"book","type":"update","data":[{"symbol":"LINK/EUR","bids":[{"price":17.10857,"qty":70.02006900}],"asks":[],"checksum":918188934,"timestamp":"2024-06-01T18:07:08.887588Z"}]}
{"channel":"book","type":"update","data":[{"symbol":"LINK/EUR","bids":[{"price":17.10313,"qty":0.00000000},{"price":17.09682,"qty":269.60000000},{"price":17.10311,"qty":303.70000000}],"asks":[],"checksum":2959774111,"timestamp":"2024-06-01T18:07:08.887675Z"}]}
{"channel":"book","type":"update","data":[{"symbol":"LINK/EUR","bids":[],"asks":[{"price":17.12091,"qty":0.00000000},{"price":17.13796,"qty":70.52987272}],"checksum":584613627,"timestamp":"2024-06-01T18:07:08.953529Z"}]}
{"channel":"book","type":"update","data":[{"symbol":"LINK/EUR","bids":[],"asks":[{"price":17.11889,"qty":70.02006900}],"checksum":1555788066,"timestamp":"2024-06-01T18:07:09.268899Z"}]}
{"channel":"book","type":"update","data":[{"symbol":"LINK/EUR","bids":[{"price":17.10040,"qty":0.00000000},{"price":17.09682,"qty":269.60000000}],"asks":[],"checksum":2414160224,"timestamp":"2024-06-01T18:07:10.213090Z"}]}
{"channel":"book","type":"update","data":[{"symbol":"LINK/EUR","bids":[{"price":17.09989,"qty":134.79441763}],"asks":[],"checksum":3810614764,"timestamp":"2024-06-01T18:07:10.216771Z"}]}
{"channel":"book","type":"update","data":[{"symbol":"LINK/EUR","bids":[],"asks":[{"price":17.13795,"qty":14.45755047}],"checksum":1545313218,"timestamp":"2024-06-01T18:07:10.700846Z"}]}
{"channel":"book","type":"update","data":[{"symbol":"LINK/EUR","bids":[],"asks":[{"price":17.13795,"qty":7.65583198}],"checksum":3331190683,"timestamp":"2024-06-01T18:07:10.701011Z"}]}
{"channel":"book","type":"update","data":[{"symbol":"LINK/EUR","bids":[],"asks":[{"price":17.10947,"qty":0.00000000},{"price":17.13796,"qty":70.52987272}],"checksum":2700346591,"timestamp":"2024-06-01T18:07:11.346131Z"}]}
{"channel":"book","type":"update","data":[{"symbol":"LINK/EUR","bids":[],"asks":[{"price":17.10947,"qty":49.36854051}],"checksum":3122178961,"timestamp":"2024-06-01T18:07:11.352102Z"}]}
{"channel":"book","type":"update","data":[{"symbol":"LINK/EUR","bids":[{"price":17.09989,"qty":0.00000000},{"price":17.09681,"qty":467.47688400}],"asks":[],"checksum":572722464,"timestamp":"2024-06-01T18:07:11.422267Z"}]}
{"channel":"book","type":"update","data":[{"symbol":"LINK/EUR","bids":[{"price":17.09942,"qty":134.79807062}],"asks":[],"checksum":682276254,"timestamp":"2024-06-01T18:07:11.428264Z"}]}
{"channel":"book","type":"update","data":[{"symbol":"LINK/EUR","bids":[{"price":17.09942,"qty":0.00000000},{"price":17.09681,"qty":467.47688400}],"asks":[],"checksum":572722464,"timestamp":"2024-06-01T18:07:11.952235Z"}]}
{"channel":"book","type":"update","data":[{"symbol":"LINK/EUR","bids":[{"price":17.09996,"qty":134.79384112}],"asks":[],"checksum":1976861649,"timestamp":"2024-06-01T18:07:11.956035Z"}]}
{"channel":"book","type":"update","data":[{"symbol":"LINK/EUR","bids":[{"price":17.09996,"qty":0.00000000},{"price":17.09681,"qty":467.47688400}],"asks":[],"checksum":572722464,"timestamp":"2024-06-01T18:07:12.346335Z"}]}
{"channel":"book","type":"update","data":[{"symbol":"LINK/EUR","bids":[{"price":17.10007,"qty":0.00000000},{"price":17.09500,"qty":152.64984900}],"asks":[],"checksum":3320808880,"timestamp":"2024-06-01T18:07:12.454610Z"}]}
{"channel":"book","type":"update","data":[{"symbol":"LINK/EUR","bids":[{"price":17.09859,"qty":134.80464861}],"asks":[],"checksum":2506430352,"timestamp":"2024-06-01T18:07:12.456523Z"}]}
{"channel":"book","type":"update","data":[{"symbol":"LINK/EUR","bids":[{"price":17.09859,"qty":0.00000000},{"price":17.09500,"qty":152.64984900}],"asks":[],"checksum":3320808880,"timestamp":"2024-06-01T18:07:12.460484Z"}]}
{"channel":"book","type":"update","data":[{"symbol":"LINK/EUR","bids":[],"asks":[{"price":17.10858,"qty":144.43444826}],"checksum":4017779194,"timestamp":"2024-06-01T18:07:12.476408Z"}]}
{"channel":"book","type":"update","data":[{"symbol":"LINK/EUR","bids":[],"asks":[{"price":17.11192,"qty":243.48672997}],"checksum":1094781948,"timestamp":"2024-06-01T18:07:12.480452Z"}]}
{"channel":"book","type":"update","data":[{"symbol":"LINK/EUR","bids":[],"asks":[{"price":17.11469,"qty":0.00000000},{"price":17.13795,"qty":7.65583198}],"checksum":1808403431,"timestamp":"2024-06-01T18:07:12.559177Z"}]}
{"channel":"book","type":"update","data":[{"symbol":"LINK/EUR","bids":[{"price":17.10059,"qty":0.00000000},{"price":17.09321,"qty":269.69704036}],"asks":[],"checksum":3586685473,"timestamp":"2024-06-01T18:07:12.722923Z"}]}
{"channel":"book","type":"update","data":[{"symbol":"LINK/EUR","bids":[],"asks":[{"price":17.11113,"qty":0.00000000},{"price":17.13796,"qty":70.52987272}],"checksum":459010898,"timestamp":"2024-06-01T18:07:12.937677Z"}]}
{"channel":"book","type":"update","data":[{"symbol":"LINK/EUR","bids":[{"price":17.09990,"qty":70.02006900}],"asks":[],"checksum":2531802082,"timestamp":"2024-06-01T18:07:13.018924Z"}]}
{"channel":"book","type":"update","data":[{"symbol":"LINK/EUR","bids":[],"asks":[{"price":17.11278,"qty":200.00000000}],"checksum":2327726740,"timestamp":"2024-06-01T18:07:13.402736Z"}]}
{"channel":"book","type":"update","data":[{"symbol":"LINK/EUR","bids":[{"price":17.09990,"qty":0.00000000},{"price":17.09311,"qty":12.40000000}],"asks":[],"checksum":2077574297,"timestamp":"2024-06-01T18:07:13.495386Z"}]}
{"channel":"book","type":"update","data":[{"symbol":"LINK/EUR","bids":[],"asks":[{"price":17.11559,"qty":0.00000000},{"price":17.13796,"qty":70.52987272}],"checksum":3468447416,"timestamp":"2024-06-01T18:07:13.585546Z"}]}
{"channel":"book","type":"update","data":[{"symbol":"LINK/EUR","bids":[{"price":17.09771,"qty":134.81160307}],"asks":[],"checksum":2683117534,"timestamp":"2024-06-01T18:07:13.706343Z"}]}
{"channel":"book","type":"update","data":[{"symbol":"LINK/EUR","bids":[{"price":17.09942,"qty":70.02006900}],"asks":[],"checksum":865416244,"timestamp":"2024-06-01T18:07:13.780491Z"}]}
{"channel":"book","type":"update","data":[{"symbol":"LINK/EUR","bids":[{"price":17.10310,"qty":0.00000000},{"price":17.09500,"qty":152.64984900}],"asks":[],"checksum":1581930146,"timestamp":"2024-06-01T18:07:13.861759Z"}]}
{"channel":"book","type":"update","data":[{"symbol":"LINK/EUR","bids":[{"price":17.09500,"qty":0.00000000},{"price":17.09311,"qty":12.40000000}],"asks":[],"checksum":623630965,"timestamp":"2024-06-01T18:07:13.862118Z"}]}
{"channel":"book","type":"update","data":[{"symbol":"LINK/EUR","bids":[{"price":17.10857,"qty":0.00000000},{"price":17.09219,"qty":269.69704036}],"asks":[],"checksum":910184246,"timestamp":"2024-06-01T18:07:13.862147Z"}]}
{"channel":"book","type":"update","data":[{"symbol":"LINK/EUR","bids":[{"price":17.10856,"qty":0.00000000},{"price":17.09205,"qty":269.71248781}],"asks":[],"checksum":252534487,"timestamp":"2024-06-01T18:07:13.862676Z"}]}
{"channel":"book","type":"update","data":[{"symbol":"LINK/EUR","bids":[{"price":17.09219,"qty":0.00000000},{"price":17.09169,"qty":26.96000000}],"asks":[],"checksum":1701613894,"timestamp":"2024-06-01T18:07:13.863859Z"}]}
{"channel":"book","type":"update","data":[{"symbol":"LINK/EUR","bids":[{"price":17.10311,"qty":0.00000000},{"price":17.09098,"qty":12.19435656},{"price":17.09943,"qty":303.70000000}],"asks":[],"checksum":1034874029,"timestamp":"2024-06-01T18:07:13.864565Z"}]}
{"channel":"book","type":"update","data":[{"symbol":"LINK/EUR","bids":[{"price":17.09700,"qty":47.43738600}],"asks":[],"checksum":2501529806,"timestamp":"2024-06-01T18:07:13.864605Z"}]}
{"channel":"book","type":"update","data":[{"symbol":"LINK/EUR","bids":[{"price":17.09379,"qty":70.02006900}],"asks":[],"checksum":3696100135,"timestamp":"2024-06-01T18:07:13.864894Z"}]}
{"channel":"book","type":"update","data":[{"symbol":"LINK/EUR","bids":[{"price":17.09770,"qty":0.00000000},{"price":17.09205,"qty":269.71248781}],"asks":[],"checksum":4156122292,"timestamp":"2024-06-01T18:07:13.864998Z"}]}
{"channel":"book","type":"update","data":[{"symbol":"LINK/EUR","bids":[],"asks":[{"price":17.10858,"qty":387.92117823}],"checksum":2238503504,"timestamp":"2024-06-01T18:07:13.866156Z"}]}
{"channel":"book","type":"update","data":[{"symbol":"LINK/EUR","bids":[{"price":17.09700,"qty":0.00000000},{"price":17.09098,"qty":12.19435656}],"asks":[],"checksum":1298794840,"timestamp":"2024-06-01T18:07:13.867319Z"}]}
{"channel":"book","type":"update","data":[{"symbol":"LINK/EUR","bids":[{"price":17.10356,"qty":0.00000000},{"price":17.08840,"qty":161.75000000}],"asks":[],"checksum":4213263631,"timestamp":"2024-06-01T18:07:13.867654Z"}]}
{"channel":"book","type":"update","data":[{"symbol":"LINK/EUR","bids":[{"price":17.08850,"qty":149.28697600}],"asks":[],"checksum":4072557676,"timestamp":"2024-06-01T18:07:13.867689Z"}]}
{"channel":"book","type":"update","data":[{"symbol":"LINK/EUR","bids":[{"price":17.09988,"qty":21.00000000}],"asks":[],"checksum":522982768,"timestamp":"2024-06-01T18:07:13.867865Z"}]}
{"channel":"book","type":"update","data":[{"symbol":"LINK/EUR","bids":[{"price":17.09205,"qty":0.00000000},{"price":17.08850,"qty":149.28697600}],"asks":[],"checksum":2185448593,"timestamp":"2024-06-01T18:07:13.868711Z"}]}
{"channel":"book","type":"update","data":[{"symbol":"LINK/EUR","bids":[],"asks":[{"price":17.10858,"qty":253.19520340}],"checksum":1555797673,"timestamp":"2024-06-01T18:07:13.868728Z"}]}
{"channel":"book","type":"update","data":[{"symbol":"LINK/EUR","bids":[{"price":17.09771,"qty":0.00000000},{"price":17.08840,"qty":161.75000000}],"asks":[],"checksum":3394027371,"timestamp":"2024-06-01T18:07:13.868741Z"}]}
{"channel":"book","type":"update","data":[{"symbol":"LINK/EUR","bids":[{"price":17.09379,"qty":0.00000000},{"price":17.08788,"qty":26.96000000}],"asks":[],"checksum":2966520394,"timestamp":"2024-06-01T18:07:13.872680Z"}]}
{"channel":"book","type":"update","data":[{"symbol":"LINK/EUR","bids":[{"price":17.09681,"qty":0.00000000},{"price":17.08685,"qty":269.68541367}],"asks":[],"checksum":3569998294,"timestamp":"2024-06-01T18:07:13.872840Z"}]}
{"channel":"book","type":"update","data":[{"symbol":"LINK/EUR","bids":[{"price":17.09380,"qty":70.02006900}],"asks":[],"checksum":2004318122,"timestamp":"2024-06-01T18:07:13.875367Z"}]}
{"channel":"book","type":"update","data":[{"symbol":"LINK/EUR","bids":[{"price":17.09098,"qty":0.00000000},{"price":17.08630,"qty":152.64984900}],"asks":[],"checksum":2148015275,"timestamp":"2024-06-01T18:07:13.885642Z"}]}
{"channel":"book","type":"update","data":[{"symbol":"LINK/EUR","bids":[],"asks":[{"price":17.10899,"qty":0.00000000},{"price":17.13797,"qty":269.10000000}],"checksum":180371315,"timestamp":"2024-06-01T18:07:13.886273Z"}]}
{"channel":"book","type":"update","data":[{"symbol":"LINK/EUR","bids":[{"price":17.09311,"qty":0.00000000},{"price":17.08485,"qty":14.50000000}],"asks":[],"checksum":2532902435,"timestamp":"2024-06-01T18:07:13.925108Z"}]}
{"channel":"book","type":"update","data":[{"symbol":"LINK/EUR","bids":[{"price":17.09988,"qty":0.00000000},{"price":17.08367,"qty":467.47688400}],"asks":[],"checksum":3505542366,"timestamp":"2024-06-01T18:07:13.948982Z"}]}
{"channel":"book","type":"update","data":[{"symbol":"LINK/EUR","bids":[{"price":17.08788,"qty":0.00000000},{"price":17.08366,"qty":24.93000428}],"asks":[],"checksum":1044519343,"timestamp":"2024-06-01T18:07:13.949914Z"}]}
{"channel":"book","type":"update","data":[{"symbol":"LINK/EUR","bids":[],"asks":[{"price":17.11192,"qty":0.00000000},{"price":17.13809,"qty":150.00000000}],"checksum":1330884054,"timestamp":"2024-06-01T18:07:13.952617Z"}]}
{"channel":"book","type":"update","data":[{"symbol":"LINK/EUR","bids":[],"asks":[{"price":17.10855,"qty":40.00000000}],"checksum":3800459830,"timestamp":"2024-06-01T18:07:13.955932Z"}]}
{"channel":"book","type":"update","data":[{"symbol":"LINK/EUR","bids":[],"asks":[{"price":17.10838,"qty":9.21193607}],"checksum":1586837601,"timestamp":"2024-06-01T18:07:13.958898Z"}]}
{"channel":"book","type":"update","data":[{"symbol":"LINK/EUR","bids":[],"asks":[{"price":17.10858,"qty":243.48672997}],"checksum":41865475,"timestamp":"2024-06-01T18:07:13.961982Z"}]}
{"channel":"book","type":"update","data":[{"symbol":"LINK/EUR","bids":[],"asks":[{"price":17.12251,"qty":15.50000000}],"checksum":510188096,"timestamp":"2024-06-01T18:07:14.003631Z"}]}
{"channel":"book","type":"update","data":[{"symbol":"LINK/EUR","bids":[{"price":17.09944,"qty":28.57000000}],"asks":[],"checksum":1428098554,"timestamp":"2024-06-01T18:07:14.014318Z"}]}
{"channel":"book","type":"update","data":[{"symbol":"LINK/EUR","bids":[],"asks":[{"price":17.10854,"qty":243.48672997}],"checksum":733156575,"timestamp":"2024-06-01T18:07:14.018369Z"}]}
{"channel":"book","type":"update","data":[{"symbol":"LINK/EUR","bids":[],"asks":[{"price":17.10943,"qty":0.00000000},{"price":17.13795,"qty":7.65583198}],"checksum":2117500630,"timestamp":"2024-06-01T18:07:14.020413Z"}]}
{"channel":"book","type":"update","data":[{"symbol":"LINK/EUR","bids":[],"asks":[{"price":17.13029,"qty":12.20000000}],"checksum":3488300371,"timestamp":"2024-06-01T18:07:14.053859Z"}]}
{"channel":"book","type":"update","data":[{"symbol":"LINK/EUR","bids":[],"asks":[{"price":17.10858,"qty":0.00000000},{"price":17.13795,"qty":7.65583198}],"checksum":3115288517,"timestamp":"2024-06-01T18:07:14.059491Z"}]}
{"channel":"book","type":"update","data":[{"symbol":"LINK/EUR","bids":[],"asks":[{"price":17.10851,"qty":40.00000000}],"checksum":1780127759,"timestamp":"2024-06-01T18:07:14.066963Z"}]}
{"channel":"book","type":"update","data":[{"symbol":"LINK/EUR","bids":[],"asks":[{"price":17.11889,"qty":0.00000000},{"price":17.13795,"qty":7.65583198}],"checksum":3174682209,"timestamp":"2024-06-01T18:07:14.074375Z"}]}
{"channel":"book","type":"update","data":[{"symbol":"LINK/EUR","bids":[],"asks":[{"price":17.10855,"qty":0.00000000},{"price":17.13796,"qty":70.52987272}],"checksum":1250370794,"timestamp":"2024-06-01T18:07:14.094572Z"}]}
{"channel":"book","type":"update","data":[{"symbol":"LINK/EUR","bids":[],"asks":[{"price":17.10850,"qty":243.48672997}],"checksum":680938565,"timestamp":"2024-06-01T18:07:14.098347Z"}]}
{"channel":"book","type":"update","data":[{"symbol":"LINK/EUR","bids":[{"price":17.09943,"qty":0.00000000},{"price":17.08366,"qty":24.93000428}],"asks":[],"checksum":2883665067,"timestamp":"2024-06-01T18:07:14.141161Z"}]}
{"channel":"book","type":"update","data":[{"symbol":"LINK/EUR","bids":[{"price":17.08851,"qty":10.78223167}],"asks":[],"checksum":764214978,"timestamp":"2024-06-01T18:07:14.145775Z"}]}
{"channel":"book","type":"update","data":[{"symbol":"LINK/EUR","bids":[],"asks":[{"price":17.10854,"qty":0.00000000},{"price":17.13796,"qty":70.52987272}],"checksum":2274171766,"timestamp":"2024-06-01T18:07:14.147063Z"}]}
{"channel":"book","type":"update","data":[{"symbol":"LINK/EUR","bids":[],"asks":[{"price":17.10847,"qty":40.00000000}],"checksum":364496522,"timestamp":"2024-06-01T18:07:14.147303Z"}]}
{"channel":"book","type":"update","data":[{"symbol":"LINK/EUR","bids":[],"asks":[{"price":17.10837,"qty":0.95179617}],"checksum":3084903856,"timestamp":"2024-06-01T18:07:14.173877Z"}]}
{"channel":"book","type":"update","data":[{"symbol":"LINK/EUR","bids":[],"asks":[{"price":17.10820,"qty":9.71404844}],"checksum":3217815285,"timestamp":"2024-06-01T18:07:14.176857Z"}]}
{"channel":"book","type":"update","data":[{"symbol":"LINK/EUR","bids":[],"asks":[{"price":17.10846,"qty":243.48672997}],"checksum":3204833458,"timestamp":"2024-06-01T18:07:14.177823Z"}]}
{"channel":"book","type":"update","data":[{"symbol":"LINK/EUR","bids":[],"asks":[{"price":17.10851,"qty":0.00000000},{"price":17.12251,"qty":15.50000000}],"checksum":2268514213,"timestamp":"2024-06-01T18:07:14.178742Z"}]}
{"channel":"book","type":"update","data":[{"symbol":"LINK/EUR","bids":[],"asks":[{"price":17.10849,"qty":200.00000000}],"checksum":3743995395,"timestamp":"2024-06-01T18:07:14.178751Z"}]}
{"channel":"book","type":"update","data":[{"symbol":"LINK/EUR","bids":[],"asks":[{"price":17.10838,"qty":0.00000000},{"price":17.12251,"qty":15.50000000}],"checksum":1683161645,"timestamp":"2024-06-01T18:07:14.179703Z"}]}
{"channel":"book","type":"update","data":[{"symbol":"LINK/EUR","bids":[{"price":17.08425,"qty":12.19916028}],"asks":[],"checksum":868442041,"timestamp":"2024-06-01T18:07:14.207214Z"}]}
{"channel":"book","type":"update","data":[{"symbol":"LINK/EUR","bids":[{"price":17.08447,"qty":269.83217138}],"asks":[],"checksum":260707328,"timestamp":"2024-06-01T18:07:14.224445Z"}]}
{"channel":"book","type":"update","data":[{"symbol":"LINK/EUR","bids":[{"price":17.08982,"qty":134.87384693}],"asks":[],"checksum":751352211,"timestamp":"2024-06-01T18:07:14.224474Z"}]}
{"channel":"book","type":"update","data":[{"symbol":"LINK/EUR","bids":[],"asks":[{"price":17.10850,"qty":0.00000000},{"price":17.13029,"qty":12.20000000}],"checksum":1850172649,"timestamp":"2024-06-01T18:07:14.227943Z"}]}
{"channel":"book","type":"update","data":[{"symbol":"LINK/EUR","bids":[{"price":17.08851,"qty":0.00000000},{"price":17.08447,"qty":269.83217138}],"asks":[],"checksum":3877604001,"timestamp":"2024-06-01T18:07:14.228808Z"}]}
{"channel":"book","type":"update","data":[{"symbol":"LINK/EUR","bids":[{"price":17.08983,"qty":10.78226605}],"asks":[],"checksum":3374273320,"timestamp":"2024-06-01T18:07:14.228898Z"}]}
{"channel":"book","type":"update","data":[{"symbol":"LINK/EUR","bids":[],"asks":[{"price":17.10843,"qty":40.00000000}],"checksum":3189217056,"timestamp":"2024-06-01T18:07:14.229398Z"}]}
{"channel":"book","type":"update","data":[{"symbol":"LINK/EUR","bids":[{"price":17.08982,"qty":0.00000000},{"price":17.08447,"qty":269.83217138}],"asks":[],"checksum":1579732720,"timestamp":"2024-06-01T18:07:14.310298Z"}]}
{"channel":"book","type":"update","data":[{"symbol":"LINK/EUR","bids":[{"price":17.09942,"qty":0.00000000},{"price":17.08425,"qty":12.19916028}],"asks":[],"checksum":763730634,"timestamp":"2024-06-01T18:07:14.318477Z"}]}
{"channel":"book","type":"update","data":[{"symbol":"LINK/EUR","bids":[{"price":17.09425,"qty":21.00000000}],"asks":[],"checksum":2943318171,"timestamp":"2024-06-01T18:07:14.321320Z"}]}
{"channel":"book","type":"update","data":[{"symbol":"LINK/EUR","bids":[],"asks":[{"price":17.10842,"qty":243.48672997}],"checksum":1524492874,"timestamp":"2024-06-01T18:07:14.323392Z"}]}
{"channel":"book","type":"update","data":[{"symbol":"LINK/EUR","bids":[],"asks":[{"price":17.10847,"qty":0.00000000},{"price":17.12251,"qty":15.50000000}],"checksum":3493163130,"timestamp":"2024-06-01T18:07:14.323555Z"}]}
{"channel":"book","type":"update","data":[{"symbol":"LINK/EUR","bids":[],"asks":[{"price":17.11202,"qty":215.84448906}],"checksum":1945786509,"timestamp":"2024-06-01T18:07:14.379042Z"}]}
{"channel":"book","type":"update","data":[{"symbol":"LINK/EUR","bids":[{"price":17.09642,"qty":303.70000000}],"asks":[],"checksum":2398611142,"timestamp":"2024-06-01T18:07:14.379394Z"}]}
{"channel":"book","type":"update","data":[{"symbol":"LINK/EUR","bids":[{"price":17.09425,"qty":0.00000000},{"price":17.08447,"qty":269.83217138}],"asks":[],"checksum":868984292,"timestamp":"2024-06-01T18:07:14.382128Z"}]}
{"channel":"book","type":"update","data":[{"symbol":"LINK/EUR","bids":[{"price":17.09687,"qty":21.00000000}],"asks":[],"checksum":1511663620,"timestamp":"2024-06-01T18:07:14.382315Z"}]}
{"channel":"book","type":"update","data":[{"symbol":"LINK/EUR","bids":[],"asks":[{"price":17.10846,"qty":0.00000000},{"price":17.12251,"qty":15.50000000}],"checksum":1424181500,"timestamp":"2024-06-01T18:07:14.383266Z"}]}
{"channel":"book","type":"update","data":[{"symbol":"LINK/EUR","bids":[{"price":17.08983,"qty":0.00000000},{"price":17.08447,"qty":269.83217138}],"asks":[],"checksum":2440971843,"timestamp":"2024-06-01T18:07:14.383528Z"}]}
{"channel":"book","type":"update","data":[{"symbol":"LINK/EUR","bids":[],"asks":[{"price":17.10839,"qty":40.00000000}],"checksum":2271090034,"timestamp":"2024-06-01T18:07:14.384455Z"}]}
{"channel":"book","type":"update","data":[{"symbol":"LINK/EUR","bids":[{"price":17.08592,"qty":269.68541367}],"asks":[],"checksum":2925790927,"timestamp":"2024-06-01T18:07:14.421279Z"}]}
{"channel":"book","type":"update","data":[{"symbol":"LINK/EUR","bids":[{"price":17.08506,"qty":269.68541367}],"asks":[],"checksum":370563663,"timestamp":"2024-06-01T18:07:14.422053Z"}]}
