{"channel":"book","type":"snapshot","data":[{"symbol":"LTC/USDT","bids":[{"price":83.22751,"qty":1.80000000},{"price":83.21947,"qty":23.85306512},{"price":83.21946,"qty":1.99000000},{"price":83.21461,"qty":10.00000000},{"price":83.21058,"qty":3.02951062},{"price":83.20469,"qty":10.00000000},{"price":83.20000,"qty":7.77131635},{"price":83.19670,"qty":13.36451721},{"price":83.19584,"qty":7.70595780},{"price":83.19141,"qty":8.00100000}],"asks":[{"price":83.27312,"qty":1.99000000},{"price":83.27332,"qty":10.00000000},{"price":83.27344,"qty":13.36451721},{"price":83.28727,"qty":8.00100000},{"price":83.29196,"qty":2.23000000},{"price":83.29469,"qty":23.85306512},{"price":83.29611,"qty":10.00000000},{"price":83.29682,"qty":8.65544977},{"price":83.30797,"qty":11.24751530},{"price":83.31475,"qty":2.22000000}],"checksum":3346606001}]}
{"channel":"book","type":"update","data":[{"symbol":"LTC/USDT","bids":[{"price":83.22665,"qty":18.03290711}],"asks":[],"checksum":931140735,"timestamp":"2024-06-01T18:07:07.798891Z"}]}
{"channel":"book","type":"update","data":[{"symbol":"LTC/USDT","bids":[{"price":83.22413,"qty":9.01647928}],"asks":[],"checksum":4038339126,"timestamp":"2024-06-01T18:07:08.041001Z"}]}
{"channel":"book","type":"update","data":[{"symbol":"LTC/USDT","bids":[{"price":83.22665,"qty":0.00000000},{"price":83.19584,"qty":7.70595780}],"asks":[],"checksum":2445735830,"timestamp":"2024-06-01T18:07:08.334119Z"}]}
{"channel":"book","type":"update","data":[{"symbol":"LTC/USDT","bids":[],"asks":[{"price":83.27034,"qty":1.80000000}],"checksum":388855668,"timestamp":"2024-06-01T18:07:08.336834Z"}]}
{"channel":"book","type":"update","data":[{"symbol":"LTC/USDT","bids":[{"price":83.22414,"qty":23.85306512}],"asks":[],"checksum":2685961926,"timestamp":"2024-06-01T18:07:08.338402Z"}]}
{"channel":"book","type":"update","data":[{"symbol":"LTC/USDT","bids":[{"price":83.22637,"qty":18.03295857}],"asks":[],"checksum":3021061016,"timestamp":"2024-06-01T18:07:08.374288Z"}]}
{"channel":"book","type":"update","data":[{"symbol":"LTC/USDT","bids":[{"price":83.22414,"qty":0.00000000},{"price":83.19670,"qty":13.36451721}],"asks":[],"checksum":1671324610,"timestamp":"2024-06-01T18:07:08.377883Z"}]}
{"channel":"book","type":"update","data":[{"symbol":"LTC/USDT","bids":[],"asks":[{"price":83.27300,"qty":10.00000000}],"checksum":1674833626,"timestamp":"2024-06-01T18:07:08.378934Z"}]}
{"channel":"book","type":"update","data":[{"symbol":"LTC/USDT","bids":[],"asks":[{"price":83.27014,"qty":1.99000000}],"checksum":3174960930,"timestamp":"2024-06-01T18:07:08.379086Z"}]}
{"channel":"book","type":"update","data":[{"symbol":"LTC/USDT","bids":[{"price":83.22638,"qty":23.85306512}],"asks":[],"checksum":337049219,"timestamp":"2024-06-01T18:07:08.507130Z"}]}
{"channel":"book","type":"update","data":[{"symbol":"LTC/USDT","bids":[],"asks":[{"price":83.27034,"qty":0.00000000},{"price":83.29682,"qty":8.65544977}],"checksum":558063773,"timestamp":"2024-06-01T18:07:08.509647Z"}]}
{"channel":"book","type":"update","data":[{"symbol":"LTC/USDT","bids":[],"asks":[{"price":83.26736,"qty":1.80000000}],"checksum":4231476313,"timestamp":"2024-06-01T18:07:08.509846Z"}]}
{"channel":"book","type":"update","data":[{"symbol":"LTC/USDT","bids":[],"asks":[{"price":83.27332,"qty":0.00000000},{"price":83.29682,"qty":8.65544977}],"checksum":2635136018,"timestamp":"2024-06-01T18:07:08.511677Z"}]}
{"channel":"book","type":"update","data":[{"symbol":"LTC/USDT","bids":[],"asks":[{"price":83.27022,"qty":10.00000000}],"checksum":158860303,"timestamp":"2024-06-01T18:07:08.511699Z"}]}
{"channel":"book","type":"update","data":[{"symbol":"LTC/USDT","bids":[],"asks":[{"price":83.27312,"qty":0.00000000},{"price":83.29682,"qty":8.65544977}],"checksum":3497959582,"timestamp":"2024-06-01T18:07:08.511792Z"}]}
{"channel":"book","type":"update","data":[{"symbol":"LTC/USDT","bids":[],"asks":[{"price":83.26716,"qty":1.99000000}],"checksum":597401850,"timestamp":"2024-06-01T18:07:08.586010Z"}]}
{"channel":"book","type":"update","data":[{"symbol":"LTC/USDT","bids":[],"asks":[{"price":83.26736,"qty":0.00000000},{"price":83.29682,"qty":8.65544977}],"checksum":1002887032,"timestamp":"2024-06-01T18:07:08.588647Z"}]}
{"channel":"book","type":"update","data":[{"symbol":"LTC/USDT","bids":[],"asks":[{"price":83.26638,"qty":1.80000000}],"checksum":2456786453,"timestamp":"2024-06-01T18:07:08.589035Z"}]}
{"channel":"book","type":"update","data":[{"symbol":"LTC/USDT","bids":[{"price":83.21947,"qty":0.00000000},{"price":83.19670,"qty":13.36451721}],"asks":[],"checksum":2663034312,"timestamp":"2024-06-01T18:07:08.589798Z"}]}
{"channel":"book","type":"update","data":[{"symbol":"LTC/USDT","bids":[],"asks":[{"price":83.27022,"qty":0.00000000},{"price":83.29682,"qty":8.65544977}],"checksum":1164265718,"timestamp":"2024-06-01T18:07:08.590558Z"}]}
{"channel":"book","type":"update","data":[{"symbol":"LTC/USDT","bids":[],"asks":[{"price":83.26724,"qty":10.00000000}],"checksum":1298496485,"timestamp":"2024-06-01T18:07:08.590568Z"}]}
{"channel":"book","type":"update","data":[{"symbol":"LTC/USDT","bids":[],"asks":[{"price":83.27014,"qty":0.00000000},{"price":83.29682,"qty":8.65544977}],"checksum":2438623282,"timestamp":"2024-06-01T18:07:08.590602Z"}]}
{"channel":"book","type":"update","data":[{"symbol":"LTC/USDT","bids":[{"price":83.22413,"qty":0.00000000},{"price":83.19584,"qty":7.70595780}],"asks":[],"checksum":1688483336,"timestamp":"2024-06-01T18:07:08.654767Z"}]}
{"channel":"book","type":"update","data":[{"symbol":"LTC/USDT","bids":[],"asks":[{"price":83.26724,"qty":0.00000000},{"price":83.30797,"qty":11.24751530}],"checksum":107385776,"timestamp":"2024-06-01T18:07:08.659216Z"}]}
{"channel":"book","type":"update","data":[{"symbol":"LTC/USDT","bids":[],"asks":[{"price":83.26704,"qty":10.00000000}],"checksum":2152201673,"timestamp":"2024-06-01T18:07:08.659378Z"}]}
{"channel":"book","type":"update","data":[{"symbol":"LTC/USDT","bids":[],"asks":[{"price":83.26618,"qty":1.99000000}],"checksum":1311193831,"timestamp":"2024-06-01T18:07:08.660701Z"}]}
{"channel":"book","type":"update","data":[{"symbol":"LTC/USDT","bids":[{"price":83.22436,"qty":9.01648601}],"asks":[],"checksum":3169223459,"timestamp":"2024-06-01T18:07:08.695150Z"}]}
{"channel":"book","type":"update","data":[{"symbol":"LTC/USDT","bids":[],"asks":[{"price":83.26716,"qty":0.00000000},{"price":83.29682,"qty":8.65544977}],"checksum":3958992363,"timestamp":"2024-06-01T18:07:08.699401Z"}]}
{"channel":"book","type":"update","data":[{"symbol":"LTC/USDT","bids":[],"asks":[{"price":83.26704,"qty":0.00000000},{"price":83.30797,"qty":11.24751530}],"checksum":4004141309,"timestamp":"2024-06-01T18:07:08.700096Z"}]}
{"channel":"book","type":"update","data":[{"symbol":"LTC/USDT","bids":[],"asks":[{"price":83.26626,"qty":10.00000000}],"checksum":1148763624,"timestamp":"2024-06-01T18:07:08.700223Z"}]}
{"channel":"book","type":"update","data":[{"symbol":"LTC/USDT","bids":[],"asks":[{"price":83.27300,"qty":0.00000000},{"price":83.30797,"qty":11.24751530}],"checksum":3670589935,"timestamp":"2024-06-01T18:07:08.711331Z"}]}
{"channel":"book","type":"update","data":[{"symbol":"LTC/USDT","bids":[{"price":83.22637,"qty":0.00000000},{"price":83.19584,"qty":7.70595780}],"asks":[],"checksum":2142090984,"timestamp":"2024-06-01T18:07:08.926050Z"}]}
{"channel":"book","type":"update","data":[{"symbol":"LTC/USDT","bids":[{"price":83.22638,"qty":0.00000000},{"price":83.19141,"qty":8.00100000}],"asks":[],"checksum":3138083687,"timestamp":"2024-06-01T18:07:08.930042Z"}]}
{"channel":"book","type":"update","data":[{"symbol":"LTC/USDT","bids":[{"price":83.22437,"qty":23.85306512}],"asks":[],"checksum":2658678861,"timestamp":"2024-06-01T18:07:08.930181Z"}]}
{"channel":"book","type":"update","data":[{"symbol":"LTC/USDT","bids":[],"asks":[{"price":83.26606,"qty":1.99000000}],"checksum":4027650083,"timestamp":"2024-06-01T18:07:08.931698Z"}]}
{"channel":"book","type":"update","data":[{"symbol":"LTC/USDT","bids":[],"asks":[{"price":83.26638,"qty":0.00000000},{"price":83.30797,"qty":11.24751530}],"checksum":3400874,"timestamp":"2024-06-01T18:07:08.932759Z"}]}
{"channel":"book","type":"update","data":[{"symbol":"LTC/USDT","bids":[],"asks":[{"price":83.26500,"qty":1.80000000}],"checksum":1428471478,"timestamp":"2024-06-01T18:07:08.933013Z"}]}
{"channel":"book","type":"update","data":[{"symbol":"LTC/USDT","bids":[{"price":83.22687,"qty":18.03292254}],"asks":[],"checksum":3214759651,"timestamp":"2024-06-01T18:07:08.966458Z"}]}
{"channel":"book","type":"update","data":[{"symbol":"LTC/USDT","bids":[],"asks":[{"price":83.26594,"qty":10.00000000}],"checksum":1822432169,"timestamp":"2024-06-01T18:07:08.971133Z"}]}
{"channel":"book","type":"update","data":[{"symbol":"LTC/USDT","bids":[],"asks":[{"price":83.26480,"qty":1.99000000}],"checksum":2913385333,"timestamp":"2024-06-01T18:07:08.971295Z"}]}
{"channel":"book","type":"update","data":[{"symbol":"LTC/USDT","bids":[],"asks":[{"price":83.26606,"qty":0.00000000},{"price":83.29611,"qty":10.00000000}],"checksum":156647907,"timestamp":"2024-06-01T18:07:08.971313Z"}]}
{"channel":"book","type":"update","data":[{"symbol":"LTC/USDT","bids":[],"asks":[{"price":83.26618,"qty":0.00000000},{"price":83.29682,"qty":8.65544977}],"checksum":985053727,"timestamp":"2024-06-01T18:07:09.087542Z"}]}
{"channel":"book","type":"update","data":[{"symbol":"LTC/USDT","bids":[],"asks":[{"price":83.26594,"qty":0.00000000},{"price":83.30797,"qty":11.24751530}],"checksum":1209305669,"timestamp":"2024-06-01T18:07:09.092423Z"}]}
{"channel":"book","type":"update","data":[{"symbol":"LTC/USDT","bids":[],"asks":[{"price":83.26488,"qty":10.00000000}],"checksum":4285616494,"timestamp":"2024-06-01T18:07:09.092529Z"}]}
{"channel":"book","type":"update","data":[{"symbol":"LTC/USDT","bids":[{"price":83.22436,"qty":0.00000000},{"price":83.19584,"qty":7.70595780}],"asks":[],"checksum":229697706,"timestamp":"2024-06-01T18:07:09.167540Z"}]}
{"channel":"book","type":"update","data":[{"symbol":"LTC/USDT","bids":[],"asks":[{"price":83.26626,"qty":0.00000000},{"price":83.30797,"qty":11.24751530}],"checksum":3868439947,"timestamp":"2024-06-01T18:07:09.171807Z"}]}
{"channel":"book","type":"update","data":[{"symbol":"LTC/USDT","bids":[],"asks":[{"price":83.26468,"qty":1.99000000}],"checksum":869910188,"timestamp":"2024-06-01T18:07:09.172286Z"}]}
{"channel":"book","type":"update","data":[{"symbol":"LTC/USDT","bids":[],"asks":[{"price":83.26500,"qty":0.00000000},{"price":83.30797,"qty":11.24751530}],"checksum":1273258738,"timestamp":"2024-06-01T18:07:09.174557Z"}]}
{"channel":"book","type":"update","data":[{"symbol":"LTC/USDT","bids":[{"price":83.22454,"qty":9.01646127}],"asks":[],"checksum":2477607673,"timestamp":"2024-06-01T18:07:09.208086Z"}]}
{"channel":"book","type":"update","data":[{"symbol":"LTC/USDT","bids":[],"asks":[{"price":83.26468,"qty":11.99000000}],"checksum":3171804355,"timestamp":"2024-06-01T18:07:09.211421Z"}]}
{"channel":"book","type":"update","data":[{"symbol":"LTC/USDT","bids":[],"asks":[{"price":83.26480,"qty":0.00000000},{"price":83.31475,"qty":2.22000000}],"checksum":2653777695,"timestamp":"2024-06-01T18:07:09.212570Z"}]}
{"channel":"book","type":"update","data":[{"symbol":"LTC/USDT","bids":[{"price":83.22687,"qty":0.00000000},{"price":83.19584,"qty":7.70595780}],"asks":[],"checksum":3224352854,"timestamp":"2024-06-01T18:07:09.511310Z"}]}
{"channel":"book","type":"update","data":[{"symbol":"LTC/USDT","bids":[],"asks":[{"price":83.26468,"qty":1.99000000}],"checksum":3565945643,"timestamp":"2024-06-01T18:07:09.515716Z"}]}
{"channel":"book","type":"update","data":[{"symbol":"LTC/USDT","bids":[{"price":83.22455,"qty":23.85306512}],"asks":[],"checksum":1744821622,"timestamp":"2024-06-01T18:07:09.517843Z"}]}
{"channel":"book","type":"update","data":[{"symbol":"LTC/USDT","bids":[{"price":83.22454,"qty":0.00000000},{"price":83.19584,"qty":7.70595780}],"asks":[],"checksum":3216438653,"timestamp":"2024-06-01T18:07:09.780930Z"}]}
{"channel":"book","type":"update","data":[{"symbol":"LTC/USDT","bids":[{"price":83.22455,"qty":0.00000000},{"price":83.19141,"qty":8.00100000}],"asks":[],"checksum":2207775705,"timestamp":"2024-06-01T18:07:09.784359Z"}]}
{"channel":"book","type":"update","data":[{"symbol":"LTC/USDT","bids":[],"asks":[{"price":83.26488,"qty":0.00000000},{"price":83.32318,"qty":30.00365564}],"checksum":2611043896,"timestamp":"2024-06-01T18:07:09.785901Z"}]}
{"channel":"book","type":"update","data":[{"symbol":"LTC/USDT","bids":[],"asks":[{"price":83.27332,"qty":10.00000000}],"checksum":3015896807,"timestamp":"2024-06-01T18:07:09.786100Z"}]}
{"channel":"book","type":"update","data":[{"symbol":"LTC/USDT","bids":[],"asks":[{"price":83.27066,"qty":1.80000000}],"checksum":1614266314,"timestamp":"2024-06-01T18:07:09.788883Z"}]}
{"channel":"book","type":"update","data":[{"symbol":"LTC/USDT","bids":[{"price":83.21947,"qty":23.85306512}],"asks":[],"checksum":150084747,"timestamp":"2024-06-01T18:07:10.010326Z"}]}
{"channel":"book","type":"update","data":[{"symbol":"LTC/USDT","bids":[{"price":83.22437,"qty":0.00000000},{"price":83.19141,"qty":8.00100000}],"asks":[],"checksum":192944220,"timestamp":"2024-06-01T18:07:10.010357Z"}]}
{"channel":"book","type":"update","data":[{"symbol":"LTC/USDT","bids":[],"asks":[{"price":83.27054,"qty":10.00000000}],"checksum":2012031297,"timestamp":"2024-06-01T18:07:10.015030Z"}]}
{"channel":"book","type":"update","data":[{"symbol":"LTC/USDT","bids":[],"asks":[{"price":83.27046,"qty":1.99000000}],"checksum":3928185531,"timestamp":"2024-06-01T18:07:10.016836Z"}]}
{"channel":"book","type":"update","data":[{"symbol":"LTC/USDT","bids":[],"asks":[{"price":83.26468,"qty":0.00000000},{"price":83.29682,"qty":8.65544977}],"checksum":3974559934,"timestamp":"2024-06-01T18:07:10.016915Z"}]}
{"channel":"book","type":"update","data":[{"symbol":"LTC/USDT","bids":[],"asks":[{"price":83.27066,"qty":0.00000000},{"price":83.30797,"qty":11.24751530}],"checksum":404340066,"timestamp":"2024-06-01T18:07:10.019714Z"}]}
{"channel":"book","type":"update","data":[{"symbol":"LTC/USDT","bids":[],"asks":[{"price":83.26776,"qty":1.80000000}],"checksum":2658234824,"timestamp":"2024-06-01T18:07:10.019729Z"}]}
{"channel":"book","type":"update","data":[{"symbol":"LTC/USDT","bids":[],"asks":[{"price":83.26756,"qty":1.99000000}],"checksum":3478025461,"timestamp":"2024-06-01T18:07:10.087316Z"}]}
{"channel":"book","type":"update","data":[{"symbol":"LTC/USDT","bids":[],"asks":[{"price":83.26776,"qty":0.00000000},{"price":83.29682,"qty":8.65544977}],"checksum":674277389,"timestamp":"2024-06-01T18:07:10.089988Z"}]}
{"channel":"book","type":"update","data":[{"symbol":"LTC/USDT","bids":[],"asks":[{"price":83.26584,"qty":1.80000000}],"checksum":1399179499,"timestamp":"2024-06-01T18:07:10.090195Z"}]}
{"channel":"book","type":"update","data":[{"symbol":"LTC/USDT","bids":[],"asks":[{"price":83.27046,"qty":0.00000000},{"price":83.29682,"qty":8.65544977}],"checksum":25391362,"timestamp":"2024-06-01T18:07:10.092015Z"}]}
{"channel":"book","type":"update","data":[{"symbol":"LTC/USDT","bids":[],"asks":[{"price":83.27054,"qty":0.00000000},{"price":83.30797,"qty":11.24751530}],"checksum":1391841765,"timestamp":"2024-06-01T18:07:10.092346Z"}]}
{"channel":"book","type":"update","data":[{"symbol":"LTC/USDT","bids":[],"asks":[{"price":83.26764,"qty":10.00000000}],"checksum":3905606862,"timestamp":"2024-06-01T18:07:10.092514Z"}]}
{"channel":"book","type":"update","data":[{"symbol":"LTC/USDT","bids":[{"price":83.22689,"qty":18.03278345}],"asks":[],"checksum":1844602515,"timestamp":"2024-06-01T18:07:10.187753Z"}]}
{"channel":"book","type":"update","data":[{"symbol":"LTC/USDT","bids":[],"asks":[{"price":83.26764,"qty":0.00000000},{"price":83.30797,"qty":11.24751530}],"checksum":3254034646,"timestamp":"2024-06-01T18:07:10.193102Z"}]}
{"channel":"book","type":"update","data":[{"symbol":"LTC/USDT","bids":[],"asks":[{"price":83.26744,"qty":10.00000000}],"checksum":3750119736,"timestamp":"2024-06-01T18:07:10.193203Z"}]}
{"channel":"book","type":"update","data":[{"symbol":"LTC/USDT","bids":[],"asks":[{"price":83.26564,"qty":1.99000000}],"checksum":3828072686,"timestamp":"2024-06-01T18:07:10.193369Z"}]}
{"channel":"book","type":"update","data":[{"symbol":"LTC/USDT","bids":[],"asks":[{"price":83.26744,"qty":0.00000000},{"price":83.29682,"qty":8.65544977}],"checksum":437226577,"timestamp":"2024-06-01T18:07:10.211532Z"}]}
{"channel":"book","type":"update","data":[{"symbol":"LTC/USDT","bids":[],"asks":[{"price":83.26572,"qty":10.00000000}],"checksum":3651102795,"timestamp":"2024-06-01T18:07:10.211622Z"}]}
{"channel":"book","type":"update","data":[{"symbol":"LTC/USDT","bids":[],"asks":[{"price":83.26584,"qty":0.00000000},{"price":83.29682,"qty":8.65544977}],"checksum":3676725760,"timestamp":"2024-06-01T18:07:10.357921Z"}]}
{"channel":"book","type":"update","data":[{"symbol":"LTC/USDT","bids":[],"asks":[{"price":83.26545,"qty":1.80000000}],"checksum":2259085525,"timestamp":"2024-06-01T18:07:10.358144Z"}]}
{"channel":"book","type":"update","data":[{"symbol":"LTC/USDT","bids":[],"asks":[{"price":83.27332,"qty":0.00000000},{"price":83.29682,"qty":8.65544977}],"checksum":3309793690,"timestamp":"2024-06-01T18:07:10.362504Z"}]}
{"channel":"book","type":"update","data":[{"symbol":"LTC/USDT","bids":[],"asks":[{"price":83.26552,"qty":1.99000000}],"checksum":1316483637,"timestamp":"2024-06-01T18:07:10.363083Z"}]}
{"channel":"book","type":"update","data":[{"symbol":"LTC/USDT","bids":[],"asks":[{"price":83.26564,"qty":0.00000000},{"price":83.29682,"qty":8.65544977}],"checksum":2135085154,"timestamp":"2024-06-01T18:07:10.363097Z"}]}
{"channel":"book","type":"update","data":[{"symbol":"LTC/USDT","bids":[{"price":83.22445,"qty":9.01639529}],"asks":[],"checksum":1760094845,"timestamp":"2024-06-01T18:07:10.372665Z"}]}
{"channel":"book","type":"update","data":[{"symbol":"LTC/USDT","bids":[],"asks":[{"price":83.26552,"qty":0.00000000},{"price":83.30797,"qty":11.24751530}],"checksum":1647637390,"timestamp":"2024-06-01T18:07:10.586469Z"}]}
{"channel":"book","type":"update","data":[{"symbol":"LTC/USDT","bids":[],"asks":[{"price":83.26525,"qty":1.99000000}],"checksum":868320009,"timestamp":"2024-06-01T18:07:10.586674Z"}]}
{"channel":"book","type":"update","data":[{"symbol":"LTC/USDT","bids":[],"asks":[{"price":83.26756,"qty":0.00000000},{"price":83.30797,"qty":11.24751530}],"checksum":1417935681,"timestamp":"2024-06-01T18:07:10.591710Z"}]}
{"channel":"book","type":"update","data":[{"symbol":"LTC/USDT","bids":[],"asks":[{"price":83.26533,"qty":10.00000000}],"checksum":1262483388,"timestamp":"2024-06-01T18:07:10.711197Z"}]}
{"channel":"book","type":"update","data":[{"symbol":"LTC/USDT","bids":[],"asks":[{"price":83.26545,"qty":0.00000000},{"price":83.30797,"qty":11.24751530}],"checksum":3068349239,"timestamp":"2024-06-01T18:07:10.713734Z"}]}
{"channel":"book","type":"update","data":[{"symbol":"LTC/USDT","bids":[],"asks":[{"price":83.26530,"qty":1.80000000}],"checksum":2325876655,"timestamp":"2024-06-01T18:07:10.713996Z"}]}
{"channel":"book","type":"update","data":[{"symbol":"LTC/USDT","bids":[],"asks":[{"price":83.26572,"qty":0.00000000},{"price":83.30797,"qty":11.24751530}],"checksum":2917622166,"timestamp":"2024-06-01T18:07:10.715467Z"}]}
{"channel":"book","type":"update","data":[{"symbol":"LTC/USDT","bids":[],"asks":[{"price":83.26513,"qty":1.99000000}],"checksum":2339372073,"timestamp":"2024-06-01T18:07:10.716016Z"}]}
{"channel":"book","type":"update","data":[{"symbol":"LTC/USDT","bids":[{"price":83.22689,"qty":0.00000000},{"price":83.19584,"qty":7.70595780}],"asks":[],"checksum":3409556403,"timestamp":"2024-06-01T18:07:10.726578Z"}]}
{"channel":"book","type":"update","data":[{"symbol":"LTC/USDT","bids":[{"price":83.22680,"qty":18.03279501}],"asks":[],"checksum":1642078164,"timestamp":"2024-06-01T18:07:10.766919Z"}]}
{"channel":"book","type":"update","data":[{"symbol":"LTC/USDT","bids":[],"asks":[{"price":83.26513,"qty":11.99000000}],"checksum":131947890,"timestamp":"2024-06-01T18:07:10.771517Z"}]}
{"channel":"book","type":"update","data":[{"symbol":"LTC/USDT","bids":[],"asks":[{"price":83.26513,"qty":10.00000000}],"checksum":863255780,"timestamp":"2024-06-01T18:07:10.771791Z"}]}
{"channel":"book","type":"update","data":[{"symbol":"LTC/USDT","bids":[],"asks":[{"price":83.26510,"qty":1.99000000}],"checksum":446297824,"timestamp":"2024-06-01T18:07:10.771812Z"}]}
{"channel":"book","type":"update","data":[{"symbol":"LTC/USDT","bids":[],"asks":[{"price":83.26530,"qty":0.00000000},{"price":83.29682,"qty":8.65544977}],"checksum":2047778396,"timestamp":"2024-06-01T18:07:10.774264Z"}]}
{"channel":"book","type":"update","data":[{"symbol":"LTC/USDT","bids":[],"asks":[{"price":83.26496,"qty":1.80000000}],"checksum":629329255,"timestamp":"2024-06-01T18:07:10.774687Z"}]}
{"channel":"book","type":"update","data":[{"symbol":"LTC/USDT","bids":[{"price":83.22445,"qty":0.00000000},{"price":83.19584,"qty":7.70595780}],"asks":[],"checksum":841545592,"timestamp":"2024-06-01T18:07:10.841422Z"}]}
{"channel":"book","type":"update","data":[{"symbol":"LTC/USDT","bids":[],"asks":[{"price":83.26510,"qty":0.00000000},{"price":83.29682,"qty":8.65544977}],"checksum":2130952170,"timestamp":"2024-06-01T18:07:10.846917Z"}]}
{"channel":"book","type":"update","data":[{"symbol":"LTC/USDT","bids":[],"asks":[{"price":83.26476,"qty":1.99000000}],"checksum":4018006135,"timestamp":"2024-06-01T18:07:10.847068Z"}]}
{"channel":"book","type":"update","data":[{"symbol":"LTC/USDT","bids":[],"asks":[{"price":83.26513,"qty":0.00000000},{"price":83.29682,"qty":8.65544977}],"checksum":1947646689,"timestamp":"2024-06-01T18:07:10.850625Z"}]}
{"channel":"book","type":"update","data":[{"symbol":"LTC/USDT","bids":[],"asks":[{"price":83.26498,"qty":10.00000000}],"checksum":811728074,"timestamp":"2024-06-01T18:07:10.850701Z"}]}
{"channel":"book","type":"update","data":[{"symbol":"LTC/USDT","bids":[{"price":83.22447,"qty":9.01639750}],"asks":[],"checksum":389155843,"timestamp":"2024-06-01T18:07:10.881624Z"}]}
{"channel":"book","type":"update","data":[{"symbol":"LTC/USDT","bids":[],"asks":[{"price":83.26525,"qty":0.00000000},{"price":83.29682,"qty":8.65544977}],"checksum":3620808547,"timestamp":"2024-06-01T18:07:10.886215Z"}]}
{"channel":"book","type":"update","data":[{"symbol":"LTC/USDT","bids":[],"asks":[{"price":83.26498,"qty":0.00000000},{"price":83.30797,"qty":11.24751530}],"checksum":1848542752,"timestamp":"2024-06-01T18:07:10.886635Z"}]}
{"channel":"book","type":"update","data":[{"symbol":"LTC/USDT","bids":[],"asks":[{"price":83.26484,"qty":10.00000000}],"checksum":3576615535,"timestamp":"2024-06-01T18:07:10.886700Z"}]}
{"channel":"book","type":"update","data":[{"symbol":"LTC/USDT","bids":[],"asks":[{"price":83.26496,"qty":0.00000000},{"price":83.30797,"qty":11.24751530}],"checksum":619082531,"timestamp":"2024-06-01T18:07:10.898004Z"}]}
{"channel":"book","type":"update","data":[{"symbol":"LTC/USDT","bids":[],"asks":[{"price":83.26480,"qty":1.80000000}],"checksum":1283602568,"timestamp":"2024-06-01T18:07:10.898072Z"}]}
{"channel":"book","type":"update","data":[{"symbol":"LTC/USDT","bids":[],"asks":[{"price":83.26480,"qty":0.00000000},{"price":83.30797,"qty":11.24751530}],"checksum":619082531,"timestamp":"2024-06-01T18:07:10.898170Z"}]}
{"channel":"book","type":"update","data":[{"symbol":"LTC/USDT","bids":[],"asks":[{"price":83.26445,"qty":1.80000000}],"checksum":1265954806,"timestamp":"2024-06-01T18:07:10.898268Z"}]}
{"channel":"book","type":"update","data":[{"symbol":"LTC/USDT","bids":[],"asks":[{"price":83.26425,"qty":1.99000000}],"checksum":2531492412,"timestamp":"2024-06-01T18:07:11.086249Z"}]}
{"channel":"book","type":"update","data":[{"symbol":"LTC/USDT","bids":[],"asks":[{"price":83.26476,"qty":0.00000000},{"price":83.29682,"qty":8.65544977}],"checksum":3241092784,"timestamp":"2024-06-01T18:07:11.090547Z"}]}
{"channel":"book","type":"update","data":[{"symbol":"LTC/USDT","bids":[],"asks":[{"price":83.26484,"qty":0.00000000},{"price":83.30797,"qty":11.24751530}],"checksum":984876735,"timestamp":"2024-06-01T18:07:11.091242Z"}]}
{"channel":"book","type":"update","data":[{"symbol":"LTC/USDT","bids":[],"asks":[{"price":83.26445,"qty":0.00000000},{"price":83.31475,"qty":2.22000000}],"checksum":2210854540,"timestamp":"2024-06-01T18:07:11.234101Z"}]}
{"channel":"book","type":"update","data":[{"symbol":"LTC/USDT","bids":[],"asks":[{"price":83.26405,"qty":1.80000000}],"checksum":1510839549,"timestamp":"2024-06-01T18:07:11.234268Z"}]}
{"channel":"book","type":"update","data":[{"symbol":"LTC/USDT","bids":[{"price":83.22680,"qty":0.00000000},{"price":83.19584,"qty":7.70595780}],"asks":[],"checksum":3771898128,"timestamp":"2024-06-01T18:07:11.238126Z"}]}
{"channel":"book","type":"update","data":[{"symbol":"LTC/USDT","bids":[{"price":83.22671,"qty":18.03279501}],"asks":[],"checksum":738019031,"timestamp":"2024-06-01T18:07:11.278251Z"}]}
{"channel":"book","type":"update","data":[{"symbol":"LTC/USDT","bids":[{"price":83.21058,"qty":0.00000000},{"price":83.19584,"qty":7.70595780}],"asks":[],"checksum":1988398715,"timestamp":"2024-06-01T18:07:11.371393Z"}]}
{"channel":"book","type":"update","data":[{"symbol":"LTC/USDT","bids":[{"price":83.21461,"qty":0.00000000},{"price":83.19141,"qty":8.00100000}],"asks":[],"checksum":3297682485,"timestamp":"2024-06-01T18:07:11.376039Z"}]}
{"channel":"book","type":"update","data":[{"symbol":"LTC/USDT","bids":[{"price":83.22447,"qty":0.00000000},{"price":83.18229,"qty":2.30000000}],"asks":[],"checksum":3845297637,"timestamp":"2024-06-01T18:07:11.422556Z"}]}
{"channel":"book","type":"update","data":[{"symbol":"LTC/USDT","bids":[{"price":83.20001,"qty":3.60665010}],"asks":[],"checksum":2352010951,"timestamp":"2024-06-01T18:07:11.428848Z"}]}
{"channel":"book","type":"update","data":[{"symbol":"LTC/USDT","bids":[{"price":83.22435,"qty":9.01641944}],"asks":[],"checksum":3093185069,"timestamp":"2024-06-01T18:07:11.463244Z"}]}
{"channel":"book","type":"update","data":[{"symbol":"LTC/USDT","bids":[{"price":83.20001,"qty":0.00000000},{"price":83.19141,"qty":8.00100000}],"asks":[],"checksum":2622369218,"timestamp":"2024-06-01T18:07:11.467657Z"}]}
{"channel":"book","type":"update","data":[{"symbol":"LTC/USDT","bids":[],"asks":[{"price":83.26385,"qty":1.99000000}],"checksum":2058449139,"timestamp":"2024-06-01T18:07:11.469000Z"}]}
{"channel":"book","type":"update","data":[{"symbol":"LTC/USDT","bids":[{"price":83.20576,"qty":3.02951062}],"asks":[],"checksum":360594034,"timestamp":"2024-06-01T18:07:11.473812Z"}]}
{"channel":"book","type":"update","data":[{"symbol":"LTC/USDT","bids":[],"asks":[{"price":83.26425,"qty":0.00000000},{"price":83.30797,"qty":11.24751530}],"checksum":3589451727,"timestamp":"2024-06-01T18:07:11.585988Z"}]}
{"channel":"book","type":"update","data":[{"symbol":"LTC/USDT","bids":[{"price":83.21464,"qty":10.00000000}],"asks":[],"checksum":125415391,"timestamp":"2024-06-01T18:07:11.685233Z"}]}
{"channel":"book","type":"update","data":[{"symbol":"LTC/USDT","bids":[{"price":83.22671,"qty":0.00000000},{"price":83.19584,"qty":7.70595780}],"asks":[],"checksum":1893816912,"timestamp":"2024-06-01T18:07:11.856631Z"}]}
{"channel":"book","type":"update","data":[{"symbol":"LTC/USDT","bids":[{"price":83.22436,"qty":23.85306512}],"asks":[],"checksum":2312686980,"timestamp":"2024-06-01T18:07:11.860139Z"}]}
{"channel":"book","type":"update","data":[{"symbol":"LTC/USDT","bids":[{"price":83.22669,"qty":18.03283524}],"asks":[],"checksum":1925164031,"timestamp":"2024-06-01T18:07:11.897018Z"}]}
{"channel":"book","type":"update","data":[{"symbol":"LTC/USDT","bids":[{"price":83.22436,"qty":0.00000000},{"price":83.19670,"qty":13.36451721}],"asks":[],"checksum":3754009261,"timestamp":"2024-06-01T18:07:11.900899Z"}]}
{"channel":"book","type":"update","data":[{"symbol":"LTC/USDT","bids":[],"asks":[{"price":83.26405,"qty":0.00000000},{"price":83.31475,"qty":2.22000000}],"checksum":3009712334,"timestamp":"2024-06-01T18:07:11.903597Z"}]}
{"channel":"book","type":"update","data":[{"symbol":"LTC/USDT","bids":[],"asks":[{"price":83.26205,"qty":1.80000000}],"checksum":3285894096,"timestamp":"2024-06-01T18:07:11.903791Z"}]}
{"channel":"book","type":"update","data":[{"symbol":"LTC/USDT","bids":[{"price":83.22435,"qty":0.00000000},{"price":83.19584,"qty":7.70595780}],"asks":[],"checksum":1969727881,"timestamp":"2024-06-01T18:07:12.053579Z"}]}
{"channel":"book","type":"update","data":[{"symbol":"LTC/USDT","bids":[{"price":83.22669,"qty":0.00000000},{"price":83.19141,"qty":8.00100000}],"asks":[],"checksum":4191919946,"timestamp":"2024-06-01T18:07:12.489282Z"}]}
{"channel":"book","type":"update","data":[{"symbol":"LTC/USDT","bids":[],"asks":[{"price":83.26185,"qty":1.99000000}],"checksum":4049338900,"timestamp":"2024-06-01T18:07:12.495458Z"}]}
{"channel":"book","type":"update","data":[{"symbol":"LTC/USDT","bids":[],"asks":[{"price":83.26205,"qty":0.00000000},{"price":83.30797,"qty":11.24751530}],"checksum":1185902663,"timestamp":"2024-06-01T18:07:12.498316Z"}]}
{"channel":"book","type":"update","data":[{"symbol":"LTC/USDT","bids":[],"asks":[{"price":83.26108,"qty":1.80000000}],"checksum":1812480091,"timestamp":"2024-06-01T18:07:12.498478Z"}]}
{"channel":"book","type":"update","data":[{"symbol":"LTC/USDT","bids":[],"asks":[{"price":83.26185,"qty":0.00000000},{"price":83.30797,"qty":11.24751530}],"checksum":413542356,"timestamp":"2024-06-01T18:07:12.589504Z"}]}
{"channel":"book","type":"update","data":[{"symbol":"LTC/USDT","bids":[],"asks":[{"price":83.26088,"qty":1.99000000}],"checksum":2885682400,"timestamp":"2024-06-01T18:07:12.598555Z"}]}
{"channel":"book","type":"update","data":[{"symbol":"LTC/USDT","bids":[{"price":83.22428,"qty":9.01640948}],"asks":[],"checksum":2577998488,"timestamp":"2024-06-01T18:07:12.686315Z"}]}
{"channel":"book","type":"update","data":[{"symbol":"LTC/USDT","bids":[{"price":83.22429,"qty":23.85306512}],"asks":[],"checksum":1982918511,"timestamp":"2024-06-01T18:07:12.690192Z"}]}
{"channel":"book","type":"update","data":[{"symbol":"LTC/USDT","bids":[],"asks":[{"price":83.26385,"qty":0.00000000},{"price":83.30797,"qty":11.24751530}],"checksum":342871056,"timestamp":"2024-06-01T18:07:12.696062Z"}]}
{"channel":"book","type":"update","data":[{"symbol":"LTC/USDT","bids":[{"price":83.21947,"qty":0.00000000},{"price":83.19584,"qty":7.70595780}],"asks":[],"checksum":378203509,"timestamp":"2024-06-01T18:07:13.007372Z"}]}
{"channel":"book","type":"update","data":[{"symbol":"LTC/USDT","bids":[{"price":83.22712,"qty":18.03267556}],"asks":[],"checksum":3671022416,"timestamp":"2024-06-01T18:07:13.048508Z"}]}
{"channel":"book","type":"update","data":[{"symbol":"LTC/USDT","bids":[{"price":83.22428,"qty":0.00000000},{"price":83.19584,"qty":7.70595780}],"asks":[],"checksum":1012810324,"timestamp":"2024-06-01T18:07:13.202188Z"}]}
{"channel":"book","type":"update","data":[{"symbol":"LTC/USDT","bids":[{"price":83.22471,"qty":9.01633778}],"asks":[],"checksum":810735634,"timestamp":"2024-06-01T18:07:13.313726Z"}]}
{"channel":"book","type":"update","data":[{"symbol":"LTC/USDT","bids":[{"price":83.22712,"qty":0.00000000},{"price":83.19584,"qty":7.70595780}],"asks":[],"checksum":643014292,"timestamp":"2024-06-01T18:07:13.706394Z"}]}
{"channel":"book","type":"update","data":[{"symbol":"LTC/USDT","bids":[{"price":83.22472,"qty":23.85306512}],"asks":[],"checksum":2647173614,"timestamp":"2024-06-01T18:07:13.710449Z"}]}
{"channel":"book","type":"update","data":[{"symbol":"LTC/USDT","bids":[{"price":83.22705,"qty":18.03267437}],"asks":[],"checksum":97072297,"timestamp":"2024-06-01T18:07:13.746665Z"}]}
{"channel":"book","type":"update","data":[{"symbol":"LTC/USDT","bids":[{"price":83.22472,"qty":0.00000000},{"price":83.19670,"qty":13.36451721}],"asks":[],"checksum":1597689841,"timestamp":"2024-06-01T18:07:13.750082Z"}]}
{"channel":"book","type":"update","data":[{"symbol":"LTC/USDT","bids":[{"price":83.22471,"qty":0.00000000},{"price":83.19584,"qty":7.70595780}],"asks":[],"checksum":1396069815,"timestamp":"2024-06-01T18:07:13.904053Z"}]}
{"channel":"book","type":"update","data":[{"symbol":"LTC/USDT","bids":[{"price":83.22454,"qty":9.01636252}],"asks":[],"checksum":2239527345,"timestamp":"2024-06-01T18:07:13.943935Z"}]}
{"channel":"book","type":"update","data":[{"symbol":"LTC/USDT","bids":[{"price":83.21464,"qty":0.00000000},{"price":83.19584,"qty":7.70595780}],"asks":[],"checksum":3637510297,"timestamp":"2024-06-01T18:07:14.010957Z"}]}
{"channel":"book","type":"update","data":[{"symbol":"LTC/USDT","bids":[{"price":83.21466,"qty":10.00000000}],"asks":[],"checksum":3721642436,"timestamp":"2024-06-01T18:07:14.320545Z"}]}
{"channel":"book","type":"update","data":[{"symbol":"LTC/USDT","bids":[{"price":83.22705,"qty":0.00000000},{"price":83.19584,"qty":7.70595780}],"asks":[],"checksum":565121475,"timestamp":"2024-06-01T18:07:14.338847Z"}]}
{"channel":"book","type":"update","data":[{"symbol":"LTC/USDT","bids":[{"price":83.22455,"qty":23.85306512}],"asks":[],"checksum":2206813808,"timestamp":"2024-06-01T18:07:14.342821Z"}]}
{"channel":"book","type":"update","data":[{"symbol":"LTC/USDT","bids":[{"price":83.22680,"qty":18.03275424}],"asks":[],"checksum":1644888449,"timestamp":"2024-06-01T18:07:14.379111Z"}]}
{"channel":"book","type":"update","data":[{"symbol":"LTC/USDT","bids":[{"price":83.22455,"qty":0.00000000},{"price":83.19670,"qty":13.36451721}],"asks":[],"checksum":1959423755,"timestamp":"2024-06-01T18:07:14.382833Z"}]}
{"channel":"book","type":"update","data":[{"symbol":"LTC/USDT","bids":[{"price":83.22454,"qty":0.00000000},{"price":83.19584,"qty":7.70595780}],"asks":[],"checksum":1504956234,"timestamp":"2024-06-01T18:07:14.536893Z"}]}
{"channel":"book","type":"update","data":[{"symbol":"LTC/USDT","bids":[{"price":83.22444,"qty":9.01638306}],"asks":[],"checksum":1279879300,"timestamp":"2024-06-01T18:07:14.577094Z"}]}
{"channel":"book","type":"update","data":[{"symbol":"LTC/USDT","bids":[{"price":83.21466,"qty":0.00000000},{"price":83.19584,"qty":7.70595780}],"asks":[],"checksum":638965719,"timestamp":"2024-06-01T18:07:14.669127Z"}]}
{"channel":"book","type":"update","data":[{"symbol":"LTC/USDT","bids":[{"price":83.22680,"qty":0.00000000},{"price":83.19141,"qty":8.00100000}],"asks":[],"checksum":617634139,"timestamp":"2024-06-01T18:07:14.895901Z"}]}
{"channel":"book","type":"update","data":[{"symbol":"LTC/USDT","bids":[{"price":83.22445,"qty":23.85306512}],"asks":[],"checksum":1767858291,"timestamp":"2024-06-01T18:07:14.899888Z"}]}
{"channel":"book","type":"update","data":[{"symbol":"LTC/USDT","bids":[{"price":83.22624,"qty":18.03288757}],"asks":[],"checksum":762527640,"timestamp":"2024-06-01T18:07:14.936352Z"}]}
{"channel":"book","type":"update","data":[{"symbol":"LTC/USDT","bids":[{"price":83.22445,"qty":0.00000000},{"price":83.19584,"qty":7.70595780}],"asks":[],"checksum":2023915462,"timestamp":"2024-06-01T18:07:14.940902Z"}]}
{"channel":"book","type":"update","data":[{"symbol":"LTC/USDT","bids":[{"price":83.21466,"qty":10.00000000}],"asks":[],"checksum":648544222,"timestamp":"2024-06-01T18:07:14.966097Z"}]}
{"channel":"book","type":"update","data":[{"symbol":"LTC/USDT","bids":[{"price":83.22625,"qty":23.85306512}],"asks":[],"checksum":889063368,"timestamp":"2024-06-01T18:07:15.012230Z"}]}
{"channel":"book","type":"update","data":[{"symbol":"LTC/USDT","bids":[{"price":83.22444,"qty":0.00000000},{"price":83.19670,"qty":13.36451721}],"asks":[],"checksum":866490170,"timestamp":"2024-06-01T18:07:15.095356Z"}]}
{"channel":"book","type":"update","data":[{"symbol":"LTC/USDT","bids":[{"price":83.22429,"qty":0.00000000},{"price":83.19584,"qty":7.70595780}],"asks":[],"checksum":1304957221,"timestamp":"2024-06-01T18:07:15.098629Z"}]}
{"channel":"book","type":"update","data":[{"symbol":"LTC/USDT","bids":[{"price":83.21466,"qty":0.00000000},{"price":83.19141,"qty":8.00100000}],"asks":[],"checksum":889373386,"timestamp":"2024-06-01T18:07:15.255397Z"}]}
{"channel":"book","type":"update","data":[{"symbol":"LTC/USDT","bids":[{"price":83.22624,"qty":0.00000000},{"price":83.18229,"qty":2.30000000}],"asks":[],"checksum":499845193,"timestamp":"2024-06-01T18:07:15.529119Z"}]}
{"channel":"book","type":"update","data":[{"symbol":"LTC/USDT","bids":[{"price":83.21947,"qty":23.85306512}],"asks":[],"checksum":3303550010,"timestamp":"2024-06-01T18:07:15.532993Z"}]}
{"channel":"book","type":"update","data":[{"symbol":"LTC/USDT","bids":[{"price":83.22625,"qty":0.00000000},{"price":83.18229,"qty":2.30000000}],"asks":[],"checksum":1869086023,"timestamp":"2024-06-01T18:07:15.533096Z"}]}
{"channel":"book","type":"update","data":[{"symbol":"LTC/USDT","bids":[{"price":83.20001,"qty":3.60664897}],"asks":[],"checksum":3685383633,"timestamp":"2024-06-01T18:07:15.534441Z"}]}
{"channel":"book","type":"update","data":[{"symbol":"LTC/USDT","bids":[],"asks":[{"price":83.26108,"qty":0.00000000},{"price":83.31475,"qty":2.22000000}],"checksum":1556218904,"timestamp":"2024-06-01T18:07:15.535741Z"}]}
{"channel":"book","type":"update","data":[{"symbol":"LTC/USDT","bids":[],"asks":[{"price":83.26057,"qty":1.80000000}],"checksum":3927491718,"timestamp":"2024-06-01T18:07:15.535815Z"}]}
{"channel":"book","type":"update","data":[{"symbol":"LTC/USDT","bids":[{"price":83.21466,"qty":10.00000000}],"asks":[],"checksum":3857958691,"timestamp":"2024-06-01T18:07:15.552821Z"}]}
{"channel":"book","type":"update","data":[{"symbol":"LTC/USDT","bids":[{"price":83.20001,"qty":0.00000000},{"price":83.19141,"qty":8.00100000}],"asks":[],"checksum":2324248303,"timestamp":"2024-06-01T18:07:15.557621Z"}]}
{"channel":"book","type":"update","data":[{"symbol":"LTC/USDT","bids":[],"asks":[{"price":83.26037,"qty":1.99000000}],"checksum":1505370530,"timestamp":"2024-06-01T18:07:15.588196Z"}]}
{"channel":"book","type":"update","data":[{"symbol":"LTC/USDT","bids":[],"asks":[{"price":83.26088,"qty":0.00000000},{"price":83.30797,"qty":11.24751530}],"checksum":2944776000,"timestamp":"2024-06-01T18:07:15.593510Z"}]}
{"channel":"book","type":"update","data":[{"symbol":"LTC/USDT","bids":[{"price":83.22404,"qty":9.01642572}],"asks":[],"checksum":883504860,"timestamp":"2024-06-01T18:07:15.728786Z"}]}
{"channel":"book","type":"update","data":[{"symbol":"LTC/USDT","bids":[{"price":83.22405,"qty":23.85306512}],"asks":[],"checksum":865410821,"timestamp":"2024-06-01T18:07:15.732873Z"}]}
{"channel":"book","type":"update","data":[{"symbol":"LTC/USDT","bids":[{"price":83.21947,"qty":0.00000000},{"price":83.19584,"qty":7.70595780}],"asks":[],"checksum":2322596363,"timestamp":"2024-06-01T18:07:16.006362Z"}]}
{"channel":"book","type":"update","data":[{"symbol":"LTC/USDT","bids":[{"price":83.22627,"qty":18.03279037}],"asks":[],"checksum":679854468,"timestamp":"2024-06-01T18:07:16.161228Z"}]}
{"channel":"book","type":"update","data":[{"symbol":"LTC/USDT","bids":[{"price":83.22628,"qty":23.85306512}],"asks":[],"checksum":1038211738,"timestamp":"2024-06-01T18:07:16.165241Z"}]}
{"channel":"book","type":"update","data":[{"symbol":"LTC/USDT","bids":[{"price":83.22404,"qty":0.00000000},{"price":83.19670,"qty":13.36451721}],"asks":[],"checksum":2613478647,"timestamp":"2024-06-01T18:07:16.319121Z"}]}
{"channel":"book","type":"update","data":[{"symbol":"LTC/USDT","bids":[{"price":83.22405,"qty":0.00000000},{"price":83.19584,"qty":7.70595780}],"asks":[],"checksum":3267400338,"timestamp":"2024-06-01T18:07:16.322764Z"}]}
{"channel":"book","type":"update","data":[{"symbol":"LTC/USDT","bids":[{"price":83.22396,"qty":9.01640297}],"asks":[],"checksum":368687836,"timestamp":"2024-06-01T18:07:16.359501Z"}]}
{"channel":"book","type":"update","data":[{"symbol":"LTC/USDT","bids":[{"price":83.22627,"qty":0.00000000},{"price":83.19584,"qty":7.70595780}],"asks":[],"checksum":2247670317,"timestamp":"2024-06-01T18:07:16.675581Z"}]}
{"channel":"book","type":"update","data":[{"symbol":"LTC/USDT","bids":[{"price":83.22397,"qty":23.85306512}],"asks":[],"checksum":3875601719,"timestamp":"2024-06-01T18:07:16.679622Z"}]}
{"channel":"book","type":"update","data":[{"symbol":"LTC/USDT","bids":[{"price":83.22628,"qty":0.00000000},{"price":83.19584,"qty":7.70595780}],"asks":[],"checksum":3765118569,"timestamp":"2024-06-01T18:07:16.679692Z"}]}
{"channel":"book","type":"update","data":[{"symbol":"LTC/USDT","bids":[{"price":83.22629,"qty":18.03279196}],"asks":[],"checksum":2356459169,"timestamp":"2024-06-01T18:07:16.715824Z"}]}
{"channel":"book","type":"update","data":[{"symbol":"LTC/USDT","bids":[{"price":83.22630,"qty":23.85306512}],"asks":[],"checksum":3270535345,"timestamp":"2024-06-01T18:07:16.720553Z"}]}
{"channel":"book","type":"update","data":[{"symbol":"LTC/USDT","bids":[{"price":83.22397,"qty":0.00000000},{"price":83.19670,"qty":13.36451721}],"asks":[],"checksum":3966789668,"timestamp":"2024-06-01T18:07:17.008570Z"}]}
{"channel":"book","type":"update","data":[{"symbol":"LTC/USDT","bids":[{"price":83.22629,"qty":0.00000000},{"price":83.19584,"qty":7.70595780}],"asks":[],"checksum":988388710,"timestamp":"2024-06-01T18:07:17.306238Z"}]}
{"channel":"book","type":"update","data":[{"symbol":"LTC/USDT","bids":[{"price":83.22630,"qty":0.00000000},{"price":83.19141,"qty":8.00100000}],"asks":[],"checksum":4016833687,"timestamp":"2024-06-01T18:07:17.310218Z"}]}
{"channel":"book","type":"update","data":[{"symbol":"LTC/USDT","bids":[{"price":83.22397,"qty":23.85306512}],"asks":[],"checksum":3765118569,"timestamp":"2024-06-01T18:07:17.310287Z"}]}
{"channel":"book","type":"update","data":[{"symbol":"LTC/USDT","bids":[{"price":83.22622,"qty":18.03277551}],"asks":[],"checksum":2401016912,"timestamp":"2024-06-01T18:07:17.346713Z"}]}
{"channel":"book","type":"update","data":[{"symbol":"LTC/USDT","bids":[{"price":83.22623,"qty":23.85306512}],"asks":[],"checksum":1763486005,"timestamp":"2024-06-01T18:07:17.350301Z"}]}
{"channel":"book","type":"update","data":[{"symbol":"LTC/USDT","bids":[{"price":83.22396,"qty":0.00000000},{"price":83.19670,"qty":13.36451721}],"asks":[],"checksum":438323907,"timestamp":"2024-06-01T18:07:17.454968Z"}]}
{"channel":"book","type":"update","data":[{"symbol":"LTC/USDT","bids":[{"price":83.22397,"qty":0.00000000},{"price":83.19584,"qty":7.70595780}],"asks":[],"checksum":2426765806,"timestamp":"2024-06-01T18:07:17.458606Z"}]}
{"channel":"book","type":"update","data":[{"symbol":"LTC/USDT","bids":[{"price":83.22389,"qty":9.01638755}],"asks":[],"checksum":731253756,"timestamp":"2024-06-01T18:07:17.495175Z"}]}
{"channel":"book","type":"update","data":[{"symbol":"LTC/USDT","bids":[{"price":83.22389,"qty":0.00000000},{"price":83.19584,"qty":7.70595780}],"asks":[],"checksum":2426765806,"timestamp":"2024-06-01T18:07:18.076909Z"}]}
{"channel":"book","type":"update","data":[{"symbol":"LTC/USDT","bids":[{"price":83.22422,"qty":9.01634039}],"asks":[],"checksum":796535882,"timestamp":"2024-06-01T18:07:18.116917Z"}]}
{"channel":"book","type":"update","data":[{"symbol":"LTC/USDT","bids":[{"price":83.22622,"qty":0.00000000},{"price":83.19584,"qty":7.70595780}],"asks":[],"checksum":3825124046,"timestamp":"2024-06-01T18:07:18.571226Z"}]}
{"channel":"book","type":"update","data":[{"symbol":"LTC/USDT","bids":[{"price":83.22623,"qty":0.00000000},{"price":83.19141,"qty":8.00100000}],"asks":[],"checksum":4122794280,"timestamp":"2024-06-01T18:07:18.575370Z"}]}
{"channel":"book","type":"update","data":[{"symbol":"LTC/USDT","bids":[{"price":83.22423,"qty":23.85306512}],"asks":[],"checksum":2928728756,"timestamp":"2024-06-01T18:07:18.575452Z"}]}
{"channel":"book","type":"update","data":[{"symbol":"LTC/USDT","bids":[{"price":83.22649,"qty":18.03266947}],"asks":[],"checksum":2279593796,"timestamp":"2024-06-01T18:07:18.611359Z"}]}
{"channel":"book","type":"update","data":[{"symbol":"LTC/USDT","bids":[{"price":83.22422,"qty":0.00000000},{"price":83.19584,"qty":7.70595780}],"asks":[],"checksum":939555552,"timestamp":"2024-06-01T18:07:18.657166Z"}]}
{"channel":"book","type":"update","data":[{"symbol":"LTC/USDT","bids":[{"price":83.22415,"qty":9.01633473}],"asks":[],"checksum":2574133387,"timestamp":"2024-06-01T18:07:18.697095Z"}]}
{"channel":"book","type":"update","data":[{"symbol":"LTC/USDT","bids":[{"price":83.22423,"qty":0.00000000},{"price":83.19584,"qty":7.70595780}],"asks":[],"checksum":1742133636,"timestamp":"2024-06-01T18:07:18.865743Z"}]}
{"channel":"book","type":"update","data":[{"symbol":"LTC/USDT","bids":[],"asks":[{"price":83.26057,"qty":0.00000000},{"price":83.31475,"qty":2.22000000}],"checksum":2030650165,"timestamp":"2024-06-01T18:07:18.894207Z"}]}
{"channel":"book","type":"update","data":[{"symbol":"LTC/USDT","bids":[],"asks":[{"price":83.26025,"qty":1.80000000}],"checksum":4102555895,"timestamp":"2024-06-01T18:07:18.894311Z"}]}
{"channel":"book","type":"update","data":[{"symbol":"LTC/USDT","bids":[],"asks":[{"price":83.28468,"qty":23.85306512}],"checksum":2159124307,"timestamp":"2024-06-01T18:07:19.022234Z"}]}
{"channel":"book","type":"update","data":[{"symbol":"LTC/USDT","bids":[{"price":83.20808,"qty":23.85306512}],"asks":[],"checksum":2772644655,"timestamp":"2024-06-01T18:07:19.022616Z"}]}
{"channel":"book","type":"update","data":[{"symbol":"LTC/USDT","bids":[{"price":83.21466,"qty":0.00000000},{"price":83.19584,"qty":7.70595780}],"asks":[],"checksum":1425849801,"timestamp":"2024-06-01T18:07:19.044469Z"}]}
{"channel":"book","type":"update","data":[{"symbol":"LTC/USDT","bids":[],"asks":[{"price":83.29469,"qty":0.00000000},{"price":83.30797,"qty":11.24751530}],"checksum":2853832371,"timestamp":"2024-06-01T18:07:19.047776Z"}]}
{"channel":"book","type":"update","data":[{"symbol":"LTC/USDT","bids":[],"asks":[{"price":83.26005,"qty":1.99000000}],"checksum":65081535,"timestamp":"2024-06-01T18:07:19.049812Z"}]}
{"channel":"book","type":"update","data":[{"symbol":"LTC/USDT","bids":[],"asks":[{"price":83.26025,"qty":0.00000000},{"price":83.30797,"qty":11.24751530}],"checksum":475783030,"timestamp":"2024-06-01T18:07:19.052531Z"}]}
{"channel":"book","type":"update","data":[{"symbol":"LTC/USDT","bids":[],"asks":[{"price":83.25727,"qty":1.80000000}],"checksum":3104669792,"timestamp":"2024-06-01T18:07:19.052915Z"}]}
{"channel":"book","type":"update","data":[{"symbol":"LTC/USDT","bids":[{"price":83.20576,"qty":0.00000000},{"price":83.19141,"qty":8.00100000}],"asks":[],"checksum":3603090145,"timestamp":"2024-06-01T18:07:19.065850Z"}]}
{"channel":"book","type":"update","data":[{"symbol":"LTC/USDT","bids":[],"asks":[{"price":83.26005,"qty":0.00000000},{"price":83.30797,"qty":11.24751530}],"checksum":1838959706,"timestamp":"2024-06-01T18:07:19.088225Z"}]}
{"channel":"book","type":"update","data":[{"symbol":"LTC/USDT","bids":[],"asks":[{"price":83.25707,"qty":1.99000000}],"checksum":2684004327,"timestamp":"2024-06-01T18:07:19.088389Z"}]}
{"channel":"book","type":"update","data":[{"symbol":"LTC/USDT","bids":[],"asks":[{"price":83.25727,"qty":0.00000000},{"price":83.30797,"qty":11.24751530}],"checksum":3688732063,"timestamp":"2024-06-01T18:07:19.091017Z"}]}
{"channel":"book","type":"update","data":[{"symbol":"LTC/USDT","bids":[],"asks":[{"price":83.25532,"qty":1.80000000}],"checksum":3985232199,"timestamp":"2024-06-01T18:07:19.091031Z"}]}
{"channel":"book","type":"update","data":[{"symbol":"LTC/USDT","bids":[],"asks":[{"price":83.26037,"qty":0.00000000},{"price":83.30797,"qty":11.24751530}],"checksum":3607083290,"timestamp":"2024-06-01T18:07:19.093047Z"}]}
{"channel":"book","type":"update","data":[{"symbol":"LTC/USDT","bids":[{"price":83.22649,"qty":0.00000000},{"price":83.18229,"qty":2.30000000}],"asks":[],"checksum":2329827624,"timestamp":"2024-06-01T18:07:19.123221Z"}]}
{"channel":"book","type":"update","data":[{"symbol":"LTC/USDT","bids":[{"price":83.22751,"qty":0.00000000},{"price":83.18000,"qty":5.68260000}],"asks":[],"checksum":2554973560,"timestamp":"2024-06-01T18:07:19.125946Z"}]}
{"channel":"book","type":"update","data":[{"symbol":"LTC/USDT","bids":[],"asks":[{"price":83.25512,"qty":1.99000000}],"checksum":3275671267,"timestamp":"2024-06-01T18:07:19.128121Z"}]}
{"channel":"book","type":"update","data":[{"symbol":"LTC/USDT","bids":[],"asks":[{"price":83.25532,"qty":0.00000000},{"price":83.30797,"qty":11.24751530}],"checksum":3216848199,"timestamp":"2024-06-01T18:07:19.130613Z"}]}
{"channel":"book","type":"update","data":[{"symbol":"LTC/USDT","bids":[],"asks":[{"price":83.25413,"qty":1.80000000}],"checksum":4258223837,"timestamp":"2024-06-01T18:07:19.130965Z"}]}
{"channel":"book","type":"update","data":[{"symbol":"LTC/USDT","bids":[{"price":83.22571,"qty":18.03293052}],"asks":[],"checksum":1661183051,"timestamp":"2024-06-01T18:07:19.163423Z"}]}
{"channel":"book","type":"update","data":[{"symbol":"LTC/USDT","bids":[{"price":83.19620,"qty":3.02951062}],"asks":[],"checksum":3626343643,"timestamp":"2024-06-01T18:07:19.168121Z"}]}
{"channel":"book","type":"update","data":[{"symbol":"LTC/USDT","bids":[],"asks":[{"price":83.25512,"qty":0.00000000},{"price":83.30797,"qty":11.24751530}],"checksum":1906956370,"timestamp":"2024-06-01T18:07:19.168351Z"}]}
{"channel":"book","type":"update","data":[{"symbol":"LTC/USDT","bids":[],"asks":[{"price":83.25393,"qty":1.99000000}],"checksum":386839989,"timestamp":"2024-06-01T18:07:19.168472Z"}]}
{"channel":"book","type":"update","data":[{"symbol":"LTC/USDT","bids":[],"asks":[{"price":83.26533,"qty":0.00000000},{"price":83.30797,"qty":11.24751530}],"checksum":544029511,"timestamp":"2024-06-01T18:07:19.204582Z"}]}
{"channel":"book","type":"update","data":[{"symbol":"LTC/USDT","bids":[],"asks":[{"price":83.27344,"qty":0.00000000},{"price":83.31475,"qty":2.22000000}],"checksum":4184896243,"timestamp":"2024-06-01T18:07:19.204828Z"}]}
{"channel":"book","type":"update","data":[{"symbol":"LTC/USDT","bids":[],"asks":[{"price":83.25393,"qty":0.00000000},{"price":83.32318,"qty":30.00365564}],"checksum":377990472,"timestamp":"2024-06-01T18:07:19.204942Z"}]}
{"channel":"book","type":"update","data":[{"symbol":"LTC/USDT","bids":[],"asks":[{"price":83.25707,"qty":0.00000000},{"price":83.33466,"qty":2.34609048}],"checksum":2366026518,"timestamp":"2024-06-01T18:07:19.204988Z"}]}
{"channel":"book","type":"update","data":[{"symbol":"LTC/USDT","bids":[{"price":83.20469,"qty":0.00000000},{"price":83.18229,"qty":2.30000000}],"asks":[],"checksum":29705636,"timestamp":"2024-06-01T18:07:19.206011Z"}]}
{"channel":"book","type":"update","data":[{"symbol":"LTC/USDT","bids":[{"price":83.19670,"qty":0.00000000},{"price":83.18000,"qty":5.68260000}],"asks":[],"checksum":4259422133,"timestamp":"2024-06-01T18:07:19.206148Z"}]}
{"channel":"book","type":"update","data":[{"symbol":"LTC/USDT","bids":[{"price":83.21946,"qty":0.00000000},{"price":83.16269,"qty":1.63851138}],"asks":[],"checksum":1912554556,"timestamp":"2024-06-01T18:07:19.206282Z"}]}
{"channel":"book","type":"update","data":[{"symbol":"LTC/USDT","bids":[{"price":83.20000,"qty":0.00000000},{"price":83.16268,"qty":102.54050000}],"asks":[],"checksum":2748526175,"timestamp":"2024-06-01T18:07:19.207229Z"}]}
{"channel":"book","type":"update","data":[{"symbol":"LTC/USDT","bids":[],"asks":[{"price":83.25413,"qty":0.00000000},{"price":83.33467,"qty":3.02951062}],"checksum":2048756257,"timestamp":"2024-06-01T18:07:19.207720Z"}]}
{"channel":"book","type":"update","data":[{"symbol":"LTC/USDT","bids":[],"asks":[{"price":83.28190,"qty":1.80000000}],"checksum":2538978337,"timestamp":"2024-06-01T18:07:19.207971Z"}]}
{"channel":"book","type":"update","data":[{"symbol":"LTC/USDT","bids":[{"price":83.19000,"qty":4.31253300}],"asks":[],"checksum":1738741881,"timestamp":"2024-06-01T18:07:19.211842Z"}]}
{"channel":"book","type":"update","data":[{"symbol":"LTC/USDT","bids":[{"price":83.22415,"qty":0.00000000},{"price":83.16268,"qty":102.54050000}],"asks":[],"checksum":2291889184,"timestamp":"2024-06-01T18:07:19.288953Z"}]}
{"channel":"book","type":"update","data":[{"symbol":"LTC/USDT","bids":[],"asks":[{"price":83.28468,"qty":0.00000000},{"price":83.33467,"qty":3.02951062}],"checksum":1694687603,"timestamp":"2024-06-01T18:07:19.292536Z"}]}
{"channel":"book","type":"update","data":[{"symbol":"LTC/USDT","bids":[],"asks":[{"price":83.28726,"qty":23.85306512}],"checksum":3534217436,"timestamp":"2024-06-01T18:07:19.292661Z"}]}
{"channel":"book","type":"update","data":[{"symbol":"LTC/USDT","bids":[{"price":83.19142,"qty":3.60710732}],"asks":[],"checksum":2046482386,"timestamp":"2024-06-01T18:07:19.293331Z"}]}
{"channel":"book","type":"update","data":[{"symbol":"LTC/USDT","bids":[{"price":83.21146,"qty":4.80547323}],"asks":[],"checksum":2023439933,"timestamp":"2024-06-01T18:07:19.312860Z"}]}
{"channel":"book","type":"update","data":[{"symbol":"LTC/USDT","bids":[{"price":83.22182,"qty":9.01667414}],"asks":[],"checksum":3808849961,"timestamp":"2024-06-01T18:07:19.329143Z"}]}
{"channel":"book","type":"update","data":[{"symbol":"LTC/USDT","bids":[],"asks":[{"price":83.28714,"qty":10.00000000}],"checksum":2159610016,"timestamp":"2024-06-01T18:07:19.333726Z"}]}
{"channel":"book","type":"update","data":[{"symbol":"LTC/USDT","bids":[{"price":83.19470,"qty":10.00000000}],"asks":[],"checksum":3718767048,"timestamp":"2024-06-01T18:07:19.334036Z"}]}
{"channel":"book","type":"update","data":[{"symbol":"LTC/USDT","bids":[],"asks":[{"price":83.28170,"qty":1.99000000}],"checksum":3085440257,"timestamp":"2024-06-01T18:07:19.334281Z"}]}
{"channel":"book","type":"update","data":[{"symbol":"LTC/USDT","bids":[],"asks":[{"price":83.28189,"qty":13.36451721}],"checksum":3877751177,"timestamp":"2024-06-01T18:07:19.334365Z"}]}
{"channel":"book","type":"update","data":[{"symbol":"LTC/USDT","bids":[{"price":83.19142,"qty":0.00000000},{"price":83.18671,"qty":13.36451721}],"asks":[],"checksum":3047186667,"timestamp":"2024-06-01T18:07:19.334471Z"}]}
{"channel":"book","type":"update","data":[{"symbol":"LTC/USDT","bids":[],"asks":[{"price":83.28169,"qty":13.36451721}],"checksum":523606003,"timestamp":"2024-06-01T18:07:19.452157Z"}]}
{"channel":"book","type":"update","data":[{"symbol":"LTC/USDT","bids":[],"asks":[{"price":83.28168,"qty":23.85306512}],"checksum":461700031,"timestamp":"2024-06-01T18:07:19.456002Z"}]}
{"channel":"book","type":"update","data":[{"symbol":"LTC/USDT","bids":[],"asks":[{"price":83.28189,"qty":0.00000000},{"price":83.29682,"qty":8.65544977}],"checksum":967152427,"timestamp":"2024-06-01T18:07:19.456572Z"}]}
{"channel":"book","type":"update","data":[{"symbol":"LTC/USDT","bids":[],"asks":[{"price":83.28157,"qty":10.00000000}],"checksum":3902093551,"timestamp":"2024-06-01T18:07:19.456680Z"}]}
{"channel":"book","type":"update","data":[{"symbol":"LTC/USDT","bids":[],"asks":[{"price":83.28149,"qty":1.99000000}],"checksum":2418123198,"timestamp":"2024-06-01T18:07:19.457441Z"}]}
{"channel":"book","type":"update","data":[{"symbol":"LTC/USDT","bids":[],"asks":[{"price":83.28168,"qty":0.00000000},{"price":83.29611,"qty":10.00000000}],"checksum":3892704887,"timestamp":"2024-06-01T18:07:19.510949Z"}]}
{"channel":"book","type":"update","data":[{"symbol":"LTC/USDT","bids":[],"asks":[{"price":83.28714,"qty":0.00000000},{"price":83.29682,"qty":8.65544977}],"checksum":1433318629,"timestamp":"2024-06-01T18:07:19.515602Z"}]}
{"channel":"book","type":"update","data":[{"symbol":"LTC/USDT","bids":[],"asks":[{"price":83.28148,"qty":13.36451721}],"checksum":463122028,"timestamp":"2024-06-01T18:07:19.516075Z"}]}
{"channel":"book","type":"update","data":[{"symbol":"LTC/USDT","bids":[],"asks":[{"price":83.28149,"qty":0.00000000},{"price":83.29682,"qty":8.65544977}],"checksum":361716944,"timestamp":"2024-06-01T18:07:19.516625Z"}]}
{"channel":"book","type":"update","data":[{"symbol":"LTC/USDT","bids":[{"price":83.21146,"qty":0.00000000},{"price":83.18229,"qty":2.30000000}],"asks":[],"checksum":1379682838,"timestamp":"2024-06-01T18:07:19.563964Z"}]}
{"channel":"book","type":"update","data":[{"symbol":"LTC/USDT","bids":[],"asks":[{"price":83.28147,"qty":23.85306512}],"checksum":822012128,"timestamp":"2024-06-01T18:07:19.567579Z"}]}
{"channel":"book","type":"update","data":[{"symbol":"LTC/USDT","bids":[],"asks":[{"price":83.28136,"qty":10.00000000}],"checksum":3970447662,"timestamp":"2024-06-01T18:07:19.568549Z"}]}
{"channel":"book","type":"update","data":[{"symbol":"LTC/USDT","bids":[],"asks":[{"price":83.28169,"qty":0.00000000},{"price":83.29611,"qty":10.00000000}],"checksum":348232938,"timestamp":"2024-06-01T18:07:19.568803Z"}]}
{"channel":"book","type":"update","data":[{"symbol":"LTC/USDT","bids":[],"asks":[{"price":83.28128,"qty":1.99000000}],"checksum":1650255958,"timestamp":"2024-06-01T18:07:19.568820Z"}]}
{"channel":"book","type":"update","data":[{"symbol":"LTC/USDT","bids":[],"asks":[{"price":83.28128,"qty":0.00000000},{"price":83.29611,"qty":10.00000000}],"checksum":348232938,"timestamp":"2024-06-01T18:07:19.586195Z"}]}
{"channel":"book","type":"update","data":[{"symbol":"LTC/USDT","bids":[],"asks":[{"price":83.28135,"qty":10.00000000}],"checksum":3817546477,"timestamp":"2024-06-01T18:07:19.711671Z"}]}
{"channel":"book","type":"update","data":[{"symbol":"LTC/USDT","bids":[],"asks":[{"price":83.28157,"qty":0.00000000},{"price":83.29611,"qty":10.00000000}],"checksum":1504433477,"timestamp":"2024-06-01T18:07:19.711689Z"}]}
{"channel":"book","type":"update","data":[{"symbol":"LTC/USDT","bids":[],"asks":[{"price":83.28147,"qty":0.00000000},{"price":83.29682,"qty":8.65544977}],"checksum":818984323,"timestamp":"2024-06-01T18:07:19.715683Z"}]}
{"channel":"book","type":"update","data":[{"symbol":"LTC/USDT","bids":[],"asks":[{"price":83.28136,"qty":0.00000000},{"price":83.30797,"qty":11.24751530}],"checksum":641300696,"timestamp":"2024-06-01T18:07:19.716088Z"}]}
{"channel":"book","type":"update","data":[{"symbol":"LTC/USDT","bids":[],"asks":[{"price":83.28134,"qty":13.36451721}],"checksum":2728438968,"timestamp":"2024-06-01T18:07:19.717281Z"}]}
{"channel":"book","type":"update","data":[{"symbol":"LTC/USDT","bids":[{"price":83.22571,"qty":0.00000000},{"price":83.18000,"qty":5.68260000}],"asks":[],"checksum":1161386697,"timestamp":"2024-06-01T18:07:19.748803Z"}]}
{"channel":"book","type":"update","data":[{"symbol":"LTC/USDT","bids":[],"asks":[{"price":83.28133,"qty":23.85306512}],"checksum":1722730066,"timestamp":"2024-06-01T18:07:19.752846Z"}]}
{"channel":"book","type":"update","data":[{"symbol":"LTC/USDT","bids":[],"asks":[{"price":83.28122,"qty":10.00000000}],"checksum":460268987,"timestamp":"2024-06-01T18:07:19.753506Z"}]}
{"channel":"book","type":"update","data":[{"symbol":"LTC/USDT","bids":[{"price":83.19142,"qty":3.60709775}],"asks":[],"checksum":1715091,"timestamp":"2024-06-01T18:07:19.753534Z"}]}
{"channel":"book","type":"update","data":[{"symbol":"LTC/USDT","bids":[],"asks":[{"price":83.28148,"qty":0.00000000},{"price":83.29611,"qty":10.00000000}],"checksum":512964590,"timestamp":"2024-06-01T18:07:19.753755Z"}]}
{"channel":"book","type":"update","data":[{"symbol":"LTC/USDT","bids":[{"price":83.22069,"qty":18.03386432}],"asks":[],"checksum":3384664239,"timestamp":"2024-06-01T18:07:19.789025Z"}]}
{"channel":"book","type":"update","data":[{"symbol":"LTC/USDT","bids":[],"asks":[{"price":83.28133,"qty":0.00000000},{"price":83.29682,"qty":8.65544977}],"checksum":741734795,"timestamp":"2024-06-01T18:07:19.793010Z"}]}
{"channel":"book","type":"update","data":[{"symbol":"LTC/USDT","bids":[{"price":83.19142,"qty":0.00000000},{"price":83.18229,"qty":2.30000000}],"asks":[],"checksum":2419839978,"timestamp":"2024-06-01T18:07:19.793415Z"}]}
{"channel":"book","type":"update","data":[{"symbol":"LTC/USDT","bids":[],"asks":[{"price":83.28135,"qty":0.00000000},{"price":83.30797,"qty":11.24751530}],"checksum":950539021,"timestamp":"2024-06-01T18:07:19.793462Z"}]}
{"channel":"book","type":"update","data":[{"symbol":"LTC/USDT","bids":[],"asks":[{"price":83.28121,"qty":10.00000000}],"checksum":3649934050,"timestamp":"2024-06-01T18:07:19.793736Z"}]}
{"channel":"book","type":"update","data":[{"symbol":"LTC/USDT","bids":[],"asks":[{"price":83.28121,"qty":23.36451721}],"checksum":901837496,"timestamp":"2024-06-01T18:07:19.794003Z"}]}
{"channel":"book","type":"update","data":[{"symbol":"LTC/USDT","bids":[{"price":83.19619,"qty":23.85306512}],"asks":[],"checksum":3428816132,"timestamp":"2024-06-01T18:07:19.853553Z"}]}
{"channel":"book","type":"update","data":[{"symbol":"LTC/USDT","bids":[],"asks":[{"price":83.28120,"qty":23.85306512}],"checksum":2670821484,"timestamp":"2024-06-01T18:07:19.857376Z"}]}
{"channel":"book","type":"update","data":[{"symbol":"LTC/USDT","bids":[],"asks":[{"price":83.28134,"qty":0.00000000},{"price":83.29682,"qty":8.65544977}],"checksum":2435837522,"timestamp":"2024-06-01T18:07:19.858802Z"}]}
{"channel":"book","type":"update","data":[{"symbol":"LTC/USDT","bids":[{"price":83.19141,"qty":0.00000000},{"price":83.18229,"qty":2.30000000}],"asks":[],"checksum":4148528019,"timestamp":"2024-06-01T18:07:19.859872Z"}]}
{"channel":"book","type":"update","data":[{"symbol":"LTC/USDT","bids":[{"price":83.18501,"qty":7.99100000}],"asks":[],"checksum":1307925720,"timestamp":"2024-06-01T18:07:19.862313Z"}]}
{"channel":"book","type":"update","data":[{"symbol":"LTC/USDT","bids":[],"asks":[{"price":83.28122,"qty":0.00000000},{"price":83.30797,"qty":11.24751530}],"checksum":4037856903,"timestamp":"2024-06-01T18:07:19.863022Z"}]}
{"channel":"book","type":"update","data":[{"symbol":"LTC/USDT","bids":[],"asks":[{"price":83.28108,"qty":10.00000000}],"checksum":467762344,"timestamp":"2024-06-01T18:07:19.863215Z"}]}
{"channel":"book","type":"update","data":[{"symbol":"LTC/USDT","bids":[{"price":83.22182,"qty":0.00000000},{"price":83.18229,"qty":2.30000000}],"asks":[],"checksum":765077459,"timestamp":"2024-06-01T18:07:19.911825Z"}]}
{"channel":"book","type":"update","data":[{"symbol":"LTC/USDT","bids":[],"asks":[{"price":83.28120,"qty":0.00000000},{"price":83.30797,"qty":11.24751530}],"checksum":3466926850,"timestamp":"2024-06-01T18:07:19.915353Z"}]}
{"channel":"book","type":"update","data":[{"symbol":"LTC/USDT","bids":[],"asks":[{"price":83.28121,"qty":13.36451721}],"checksum":3671433496,"timestamp":"2024-06-01T18:07:19.916154Z"}]}
{"channel":"book","type":"update","data":[{"symbol":"LTC/USDT","bids":[],"asks":[{"price":83.28107,"qty":13.36451721}],"checksum":3421464682,"timestamp":"2024-06-01T18:07:19.919505Z"}]}
{"channel":"book","type":"update","data":[{"symbol":"LTC/USDT","bids":[{"price":83.21836,"qty":9.01693217}],"asks":[],"checksum":1332238888,"timestamp":"2024-06-01T18:07:19.952165Z"}]}
{"channel":"book","type":"update","data":[{"symbol":"LTC/USDT","bids":[],"asks":[{"price":83.28121,"qty":0.00000000},{"price":83.30797,"qty":11.24751530}],"checksum":618501837,"timestamp":"2024-06-01T18:07:19.952885Z"}]}
{"channel":"book","type":"update","data":[{"symbol":"LTC/USDT","bids":[],"asks":[{"price":83.28106,"qty":23.85306512}],"checksum":573047207,"timestamp":"2024-06-01T18:07:19.955957Z"}]}
{"channel":"book","type":"update","data":[{"symbol":"LTC/USDT","bids":[],"asks":[{"price":83.28095,"qty":10.00000000}],"checksum":39777781,"timestamp":"2024-06-01T18:07:19.956663Z"}]}
{"channel":"book","type":"update","data":[{"symbol":"LTC/USDT","bids":[],"asks":[{"price":83.28106,"qty":0.00000000},{"price":83.29682,"qty":8.65544977}],"checksum":1587132888,"timestamp":"2024-06-01T18:07:20.007378Z"}]}
{"channel":"book","type":"update","data":[{"symbol":"LTC/USDT","bids":[],"asks":[{"price":83.28108,"qty":0.00000000},{"price":83.30797,"qty":11.24751530}],"checksum":384949950,"timestamp":"2024-06-01T18:07:20.012401Z"}]}
{"channel":"book","type":"update","data":[{"symbol":"LTC/USDT","bids":[],"asks":[{"price":83.28094,"qty":13.36451721}],"checksum":1346261189,"timestamp":"2024-06-01T18:07:20.012791Z"}]}
{"channel":"book","type":"update","data":[{"symbol":"LTC/USDT","bids":[],"asks":[{"price":83.28120,"qty":0.24045545}],"checksum":3527409051,"timestamp":"2024-06-01T18:07:20.039593Z"}]}
{"channel":"book","type":"update","data":[{"symbol":"LTC/USDT","bids":[],"asks":[{"price":83.28082,"qty":10.00000000}],"checksum":51152269,"timestamp":"2024-06-01T18:07:20.044568Z"}]}
{"channel":"book","type":"update","data":[{"symbol":"LTC/USDT","bids":[],"asks":[{"price":83.28107,"qty":0.00000000},{"price":83.29611,"qty":10.00000000}],"checksum":2919578189,"timestamp":"2024-06-01T18:07:20.044594Z"}]}
{"channel":"book","type":"update","data":[{"symbol":"LTC/USDT","bids":[],"asks":[{"price":83.28081,"qty":23.85306512}],"checksum":250382556,"timestamp":"2024-06-01T18:07:20.048663Z"}]}
{"channel":"book","type":"update","data":[{"symbol":"LTC/USDT","bids":[],"asks":[{"price":83.28069,"qty":10.00000000}],"checksum":1621854563,"timestamp":"2024-06-01T18:07:20.211914Z"}]}
{"channel":"book","type":"update","data":[{"symbol":"LTC/USDT","bids":[],"asks":[{"price":83.28095,"qty":0.00000000},{"price":83.29196,"qty":2.23000000}],"checksum":1585381348,"timestamp":"2024-06-01T18:07:20.211945Z"}]}
{"channel":"book","type":"update","data":[{"symbol":"LTC/USDT","bids":[],"asks":[{"price":83.28081,"qty":0.00000000},{"price":83.29611,"qty":10.00000000}],"checksum":3186744593,"timestamp":"2024-06-01T18:07:20.215547Z"}]}
{"channel":"book","type":"update","data":[{"symbol":"LTC/USDT","bids":[],"asks":[{"price":83.28082,"qty":0.00000000},{"price":83.29682,"qty":8.65544977}],"checksum":2187328489,"timestamp":"2024-06-01T18:07:20.216558Z"}]}
{"channel":"book","type":"update","data":[{"symbol":"LTC/USDT","bids":[],"asks":[{"price":83.28068,"qty":13.36451721}],"checksum":2757865112,"timestamp":"2024-06-01T18:07:20.217300Z"}]}
{"channel":"book","type":"update","data":[{"symbol":"LTC/USDT","bids":[{"price":83.22069,"qty":0.00000000},{"price":83.18229,"qty":2.30000000}],"asks":[],"checksum":1948407148,"timestamp":"2024-06-01T18:07:20.373544Z"}]}
{"channel":"book","type":"update","data":[{"symbol":"LTC/USDT","bids":[],"asks":[{"price":83.28067,"qty":23.85306512}],"checksum":2008571528,"timestamp":"2024-06-01T18:07:20.377543Z"}]}
{"channel":"book","type":"update","data":[{"symbol":"LTC/USDT","bids":[],"asks":[{"price":83.28056,"qty":10.00000000}],"checksum":1453884505,"timestamp":"2024-06-01T18:07:20.378035Z"}]}
{"channel":"book","type":"update","data":[{"symbol":"LTC/USDT","bids":[],"asks":[{"price":83.28094,"qty":0.00000000},{"price":83.29196,"qty":2.23000000}],"checksum":2766277739,"timestamp":"2024-06-01T18:07:20.378459Z"}]}
{"channel":"book","type":"update","data":[{"symbol":"LTC/USDT","bids":[{"price":83.22030,"qty":18.03391210}],"asks":[],"checksum":3615503048,"timestamp":"2024-06-01T18:07:20.413911Z"}]}
{"channel":"book","type":"update","data":[{"symbol":"LTC/USDT","bids":[],"asks":[{"price":83.28190,"qty":0.00000000},{"price":83.29611,"qty":10.00000000}],"checksum":3494899173,"timestamp":"2024-06-01T18:07:20.417005Z"}]}
{"channel":"book","type":"update","data":[{"symbol":"LTC/USDT","bids":[],"asks":[{"price":83.27777,"qty":1.80000000}],"checksum":598076006,"timestamp":"2024-06-01T18:07:20.417064Z"}]}
{"channel":"book","type":"update","data":[{"symbol":"LTC/USDT","bids":[],"asks":[{"price":83.28067,"qty":0.00000000},{"price":83.29611,"qty":10.00000000}],"checksum":68537012,"timestamp":"2024-06-01T18:07:20.417600Z"}]}
{"channel":"book","type":"update","data":[{"symbol":"LTC/USDT","bids":[],"asks":[{"price":83.28069,"qty":0.00000000},{"price":83.29682,"qty":8.65544977}],"checksum":3429078326,"timestamp":"2024-06-01T18:07:20.418742Z"}]}
{"channel":"book","type":"update","data":[{"symbol":"LTC/USDT","bids":[],"asks":[{"price":83.28055,"qty":13.36451721}],"checksum":857888747,"timestamp":"2024-06-01T18:07:20.418977Z"}]}
{"channel":"book","type":"update","data":[{"symbol":"LTC/USDT","bids":[],"asks":[{"price":83.28068,"qty":0.00000000},{"price":83.29682,"qty":8.65544977}],"checksum":2461989111,"timestamp":"2024-06-01T18:07:20.452482Z"}]}
{"channel":"book","type":"update","data":[{"symbol":"LTC/USDT","bids":[],"asks":[{"price":83.27776,"qty":13.36451721}],"checksum":1824740196,"timestamp":"2024-06-01T18:07:20.452577Z"}]}
{"channel":"book","type":"update","data":[{"symbol":"LTC/USDT","bids":[],"asks":[{"price":83.27777,"qty":0.00000000},{"price":83.29682,"qty":8.65544977}],"checksum":3899473316,"timestamp":"2024-06-01T18:07:20.455207Z"}]}
{"channel":"book","type":"update","data":[{"symbol":"LTC/USDT","bids":[],"asks":[{"price":83.27497,"qty":1.80000000}],"checksum":3064313616,"timestamp":"2024-06-01T18:07:20.455415Z"}]}
{"channel":"book","type":"update","data":[{"symbol":"LTC/USDT","bids":[],"asks":[{"price":83.28054,"qty":23.85306512}],"checksum":511587701,"timestamp":"2024-06-01T18:07:20.456482Z"}]}
{"channel":"book","type":"update","data":[{"symbol":"LTC/USDT","bids":[],"asks":[{"price":83.28043,"qty":10.00000000}],"checksum":926282741,"timestamp":"2024-06-01T18:07:20.457115Z"}]}
{"channel":"book","type":"update","data":[{"symbol":"LTC/USDT","bids":[],"asks":[{"price":83.28055,"qty":0.00000000},{"price":83.29196,"qty":2.23000000}],"checksum":3147920711,"timestamp":"2024-06-01T18:07:20.457526Z"}]}
{"channel":"book","type":"update","data":[{"symbol":"LTC/USDT","bids":[],"asks":[{"price":83.28054,"qty":0.00000000},{"price":83.29611,"qty":10.00000000}],"checksum":4150890518,"timestamp":"2024-06-01T18:07:20.506023Z"}]}
{"channel":"book","type":"update","data":[{"symbol":"LTC/USDT","bids":[],"asks":[{"price":83.27477,"qty":1.99000000}],"checksum":3543005725,"timestamp":"2024-06-01T18:07:20.510933Z"}]}
{"channel":"book","type":"update","data":[{"symbol":"LTC/USDT","bids":[],"asks":[{"price":83.28056,"qty":0.00000000},{"price":83.29611,"qty":10.00000000}],"checksum":618149031,"timestamp":"2024-06-01T18:07:20.510953Z"}]}
{"channel":"book","type":"update","data":[{"symbol":"LTC/USDT","bids":[],"asks":[{"price":83.27496,"qty":13.36451721}],"checksum":3000778261,"timestamp":"2024-06-01T18:07:20.511087Z"}]}
{"channel":"book","type":"update","data":[{"symbol":"LTC/USDT","bids":[{"price":83.21836,"qty":0.00000000},{"price":83.18229,"qty":2.30000000}],"asks":[],"checksum":911936599,"timestamp":"2024-06-01T18:07:20.538494Z"}]}
{"channel":"book","type":"update","data":[{"symbol":"LTC/USDT","bids":[],"asks":[{"price":83.27477,"qty":0.00000000},{"price":83.29611,"qty":10.00000000}],"checksum":3552454115,"timestamp":"2024-06-01T18:07:20.543478Z"}]}
{"channel":"book","type":"update","data":[{"symbol":"LTC/USDT","bids":[],"asks":[{"price":83.27776,"qty":0.00000000},{"price":83.29682,"qty":8.65544977}],"checksum":1031212317,"timestamp":"2024-06-01T18:07:20.544005Z"}]}
{"channel":"book","type":"update","data":[{"symbol":"LTC/USDT","bids":[],"asks":[{"price":83.27476,"qty":13.36451721}],"checksum":4179162804,"timestamp":"2024-06-01T18:07:20.544137Z"}]}
{"channel":"book","type":"update","data":[{"symbol":"LTC/USDT","bids":[{"price":83.21797,"qty":9.01695585}],"asks":[],"checksum":1890764330,"timestamp":"2024-06-01T18:07:20.578560Z"}]}
{"channel":"book","type":"update","data":[{"symbol":"LTC/USDT","bids":[],"asks":[{"price":83.27476,"qty":0.00000000},{"price":83.29682,"qty":8.65544977}],"checksum":3034398083,"timestamp":"2024-06-01T18:07:20.583372Z"}]}
{"channel":"book","type":"update","data":[{"symbol":"LTC/USDT","bids":[],"asks":[{"price":83.27456,"qty":1.99000000}],"checksum":3616636770,"timestamp":"2024-06-01T18:07:20.583487Z"}]}
{"channel":"book","type":"update","data":[{"symbol":"LTC/USDT","bids":[{"price":83.22030,"qty":0.00000000},{"price":83.18229,"qty":2.30000000}],"asks":[],"checksum":1400204245,"timestamp":"2024-06-01T18:07:20.925666Z"}]}
{"channel":"book","type":"update","data":[{"symbol":"LTC/USDT","bids":[],"asks":[{"price":83.28170,"qty":0.00000000},{"price":83.29682,"qty":8.65544977}],"checksum":3848623099,"timestamp":"2024-06-01T18:07:20.930572Z"}]}
{"channel":"book","type":"update","data":[{"symbol":"LTC/USDT","bids":[],"asks":[{"price":83.27455,"qty":13.36451721}],"checksum":1037877576,"timestamp":"2024-06-01T18:07:20.930774Z"}]}
{"channel":"book","type":"update","data":[{"symbol":"LTC/USDT","bids":[],"asks":[{"price":83.27484,"qty":10.00000000}],"checksum":1643891196,"timestamp":"2024-06-01T18:07:20.931331Z"}]}
{"channel":"book","type":"update","data":[{"symbol":"LTC/USDT","bids":[],"asks":[{"price":83.27496,"qty":0.00000000},{"price":83.29611,"qty":10.00000000}],"checksum":1381486490,"timestamp":"2024-06-01T18:07:20.953235Z"}]}
{"channel":"book","type":"update","data":[{"symbol":"LTC/USDT","bids":[{"price":83.21997,"qty":18.03400565}],"asks":[],"checksum":1787888765,"timestamp":"2024-06-01T18:07:20.966046Z"}]}
{"channel":"book","type":"update","data":[{"symbol":"LTC/USDT","bids":[],"asks":[{"price":83.28043,"qty":0.00000000},{"price":83.29682,"qty":8.65544977}],"checksum":1821380357,"timestamp":"2024-06-01T18:07:20.970935Z"}]}
{"channel":"book","type":"update","data":[{"symbol":"LTC/USDT","bids":[{"price":83.19584,"qty":0.00000000},{"price":83.18229,"qty":2.30000000}],"asks":[],"checksum":94556464,"timestamp":"2024-06-01T18:07:21.005177Z"}]}
{"channel":"book","type":"update","data":[{"symbol":"LTC/USDT","bids":[{"price":83.21797,"qty":0.00000000},{"price":83.18000,"qty":5.68260000}],"asks":[],"checksum":359435976,"timestamp":"2024-06-01T18:07:21.091254Z"}]}
{"channel":"book","type":"update","data":[{"symbol":"LTC/USDT","bids":[],"asks":[{"price":83.27497,"qty":0.00000000},{"price":83.30797,"qty":11.24751530}],"checksum":3163177835,"timestamp":"2024-06-01T18:07:21.093975Z"}]}
{"channel":"book","type":"update","data":[{"symbol":"LTC/USDT","bids":[],"asks":[{"price":83.27176,"qty":1.80000000}],"checksum":442211975,"timestamp":"2024-06-01T18:07:21.094121Z"}]}
{"channel":"book","type":"update","data":[{"symbol":"LTC/USDT","bids":[],"asks":[{"price":83.27443,"qty":10.00000000}],"checksum":3843569678,"timestamp":"2024-06-01T18:07:21.095967Z"}]}
{"channel":"book","type":"update","data":[{"symbol":"LTC/USDT","bids":[],"asks":[{"price":83.27484,"qty":0.00000000},{"price":83.29682,"qty":8.65544977}],"checksum":2092361641,"timestamp":"2024-06-01T18:07:21.211619Z"}]}
{"channel":"book","type":"update","data":[{"symbol":"LTC/USDT","bids":[],"asks":[{"price":83.27175,"qty":13.36451721}],"checksum":3871208378,"timestamp":"2024-06-01T18:07:21.216552Z"}]}
{"channel":"book","type":"update","data":[{"symbol":"LTC/USDT","bids":[],"asks":[{"price":83.27176,"qty":0.00000000},{"price":83.29682,"qty":8.65544977}],"checksum":1159644912,"timestamp":"2024-06-01T18:07:21.219266Z"}]}
{"channel":"book","type":"update","data":[{"symbol":"LTC/USDT","bids":[],"asks":[{"price":83.26896,"qty":1.80000000}],"checksum":873735378,"timestamp":"2024-06-01T18:07:21.219413Z"}]}
{"channel":"book","type":"update","data":[{"symbol":"LTC/USDT","bids":[],"asks":[{"price":83.27455,"qty":0.00000000},{"price":83.29682,"qty":8.65544977}],"checksum":934421551,"timestamp":"2024-06-01T18:07:21.452850Z"}]}
{"channel":"book","type":"update","data":[{"symbol":"LTC/USDT","bids":[],"asks":[{"price":83.26895,"qty":13.36451721}],"checksum":1069104931,"timestamp":"2024-06-01T18:07:21.453042Z"}]}
{"channel":"book","type":"update","data":[{"symbol":"LTC/USDT","bids":[],"asks":[{"price":83.27175,"qty":0.00000000},{"price":83.29682,"qty":8.65544977}],"checksum":278969329,"timestamp":"2024-06-01T18:07:21.460391Z"}]}
{"channel":"book","type":"update","data":[{"symbol":"LTC/USDT","bids":[{"price":83.18000,"qty":0.00000000},{"price":83.16269,"qty":1.88461526}],"asks":[],"checksum":3921676877,"timestamp":"2024-06-01T18:07:21.531243Z"}]}
{"channel":"book","type":"update","data":[{"symbol":"LTC/USDT","bids":[{"price":83.21997,"qty":0.00000000},{"price":83.16268,"qty":102.54050000}],"asks":[],"checksum":3948892230,"timestamp":"2024-06-01T18:07:21.541936Z"}]}
{"channel":"book","type":"update","data":[{"symbol":"LTC/USDT","bids":[{"price":83.20808,"qty":0.00000000},{"price":83.16040,"qty":13.36927600}],"asks":[],"checksum":1378047273,"timestamp":"2024-06-01T18:07:21.546240Z"}]}
{"channel":"book","type":"update","data":[{"symbol":"LTC/USDT","bids":[{"price":83.19620,"qty":26.88257574}],"asks":[],"checksum":333412250,"timestamp":"2024-06-01T18:07:21.546288Z"}]}
{"channel":"book","type":"update","data":[{"symbol":"LTC/USDT","bids":[],"asks":[{"price":83.26875,"qty":1.99000000}],"checksum":1644391140,"timestamp":"2024-06-01T18:07:21.547842Z"}]}
{"channel":"book","type":"update","data":[{"symbol":"LTC/USDT","bids":[{"price":83.19703,"qty":16.23213430}],"asks":[],"checksum":121992845,"timestamp":"2024-06-01T18:07:21.549573Z"}]}
{"channel":"book","type":"update","data":[{"symbol":"LTC/USDT","bids":[{"price":83.19001,"qty":3.60716769}],"asks":[],"checksum":2813235806,"timestamp":"2024-06-01T18:07:21.550663Z"}]}
{"channel":"book","type":"update","data":[{"symbol":"LTC/USDT","bids":[{"price":83.19001,"qty":0.00000000},{"price":83.16268,"qty":102.54050000}],"asks":[],"checksum":121992845,"timestamp":"2024-06-01T18:07:21.555083Z"}]}
{"channel":"book","type":"update","data":[{"symbol":"LTC/USDT","bids":[],"asks":[{"price":83.27456,"qty":0.00000000},{"price":83.29682,"qty":8.65544977}],"checksum":3334000663,"timestamp":"2024-06-01T18:07:21.588101Z"}]}
{"channel":"book","type":"update","data":[{"symbol":"LTC/USDT","bids":[{"price":83.19704,"qty":23.85306512}],"asks":[],"checksum":2621274684,"timestamp":"2024-06-01T18:07:21.592981Z"}]}
{"channel":"book","type":"update","data":[{"symbol":"LTC/USDT","bids":[],"asks":[{"price":83.26874,"qty":13.36451721}],"checksum":797793822,"timestamp":"2024-06-01T18:07:21.593579Z"}]}
{"channel":"book","type":"update","data":[{"symbol":"LTC/USDT","bids":[{"price":83.19787,"qty":16.23223337}],"asks":[],"checksum":528257311,"timestamp":"2024-06-01T18:07:21.596181Z"}]}
{"channel":"book","type":"update","data":[{"symbol":"LTC/USDT","bids":[{"price":83.19703,"qty":0.00000000},{"price":83.16269,"qty":1.88461526}],"asks":[],"checksum":2281504239,"timestamp":"2024-06-01T18:07:21.596453Z"}]}
{"channel":"book","type":"update","data":[{"symbol":"LTC/USDT","bids":[{"price":83.17497,"qty":10.18660867}],"asks":[],"checksum":2900081145,"timestamp":"2024-06-01T18:07:21.644934Z"}]}
{"channel":"book","type":"update","data":[{"symbol":"LTC/USDT","bids":[{"price":83.17994,"qty":7.70595780}],"asks":[],"checksum":38637729,"timestamp":"2024-06-01T18:07:21.646479Z"}]}
{"channel":"book","type":"update","data":[{"symbol":"LTC/USDT","bids":[{"price":83.19619,"qty":0.00000000},{"price":83.17497,"qty":10.18660867}],"asks":[],"checksum":4144275347,"timestamp":"2024-06-01T18:07:21.663274Z"}]}
{"channel":"book","type":"update","data":[{"symbol":"LTC/USDT","bids":[],"asks":[{"price":83.26896,"qty":0.00000000},{"price":83.29682,"qty":8.65544977}],"checksum":128790914,"timestamp":"2024-06-01T18:07:21.665828Z"}]}
{"channel":"book","type":"update","data":[{"symbol":"LTC/USDT","bids":[{"price":83.20066,"qty":1.80000000}],"asks":[],"checksum":1781242346,"timestamp":"2024-06-01T18:07:21.666086Z"}]}
{"channel":"book","type":"update","data":[{"symbol":"LTC/USDT","bids":[{"price":83.19620,"qty":3.02951062}],"asks":[],"checksum":2978543617,"timestamp":"2024-06-01T18:07:21.666796Z"}]}
{"channel":"book","type":"update","data":[{"symbol":"LTC/USDT","bids":[],"asks":[{"price":83.26895,"qty":0.00000000},{"price":83.30797,"qty":11.24751530}],"checksum":3520903074,"timestamp":"2024-06-01T18:07:21.668103Z"}]}
{"channel":"book","type":"update","data":[{"symbol":"LTC/USDT","bids":[{"price":83.20149,"qty":16.23220877}],"asks":[],"checksum":1993844352,"timestamp":"2024-06-01T18:07:21.669046Z"}]}
{"channel":"book","type":"update","data":[{"symbol":"LTC/USDT","bids":[{"price":83.19787,"qty":0.00000000},{"price":83.17994,"qty":7.70595780}],"asks":[],"checksum":2438076158,"timestamp":"2024-06-01T18:07:21.670846Z"}]}
{"channel":"book","type":"update","data":[{"symbol":"LTC/USDT","bids":[{"price":83.19001,"qty":3.60712493}],"asks":[],"checksum":1455650138,"timestamp":"2024-06-01T18:07:21.671493Z"}]}
{"channel":"book","type":"update","data":[{"symbol":"LTC/USDT","bids":[{"price":83.21752,"qty":9.01702102}],"asks":[],"checksum":1899366036,"timestamp":"2024-06-01T18:07:21.699976Z"}]}
{"channel":"book","type":"update","data":[{"symbol":"LTC/USDT","bids":[{"price":83.19001,"qty":0.00000000},{"price":83.18229,"qty":2.30000000}],"asks":[],"checksum":1829175951,"timestamp":"2024-06-01T18:07:21.704211Z"}]}
{"channel":"book","type":"update","data":[{"symbol":"LTC/USDT","bids":[{"price":83.20808,"qty":23.85306512}],"asks":[],"checksum":2191806992,"timestamp":"2024-06-01T18:07:21.704426Z"}]}
{"channel":"book","type":"update","data":[{"symbol":"LTC/USDT","bids":[{"price":83.20150,"qty":13.36451721}],"asks":[],"checksum":2707107185,"timestamp":"2024-06-01T18:07:21.929212Z"}]}
{"channel":"book","type":"update","data":[{"symbol":"LTC/USDT","bids":[{"price":83.19704,"qty":0.00000000},{"price":83.18501,"qty":7.99100000}],"asks":[],"checksum":3814706237,"timestamp":"2024-06-01T18:07:21.933092Z"}]}
{"channel":"book","type":"update","data":[{"symbol":"LTC/USDT","bids":[],"asks":[{"price":83.26862,"qty":10.00000000}],"checksum":4239900014,"timestamp":"2024-06-01T18:07:21.933767Z"}]}
{"channel":"book","type":"update","data":[{"symbol":"LTC/USDT","bids":[],"asks":[{"price":83.26861,"qty":13.36451721}],"checksum":632438230,"timestamp":"2024-06-01T18:07:21.953427Z"}]}
{"channel":"book","type":"update","data":[{"symbol":"LTC/USDT","bids":[{"price":83.22022,"qty":18.03418571}],"asks":[],"checksum":2274015689,"timestamp":"2024-06-01T18:07:22.134580Z"}]}
{"channel":"book","type":"update","data":[{"symbol":"LTC/USDT","bids":[],"asks":[{"price":83.26874,"qty":0.00000000},{"price":83.29682,"qty":8.65544977}],"checksum":1253512,"timestamp":"2024-06-01T18:07:22.139522Z"}]}
{"channel":"book","type":"update","data":[{"symbol":"LTC/USDT","bids":[],"asks":[{"price":83.27443,"qty":0.00000000},{"price":83.30797,"qty":11.24751530}],"checksum":2231155396,"timestamp":"2024-06-01T18:07:22.140278Z"}]}
{"channel":"book","type":"update","data":[{"symbol":"LTC/USDT","bids":[{"price":83.21752,"qty":0.00000000},{"price":83.18501,"qty":7.99100000}],"asks":[],"checksum":1638178815,"timestamp":"2024-06-01T18:07:22.252861Z"}]}
{"channel":"book","type":"update","data":[{"symbol":"LTC/USDT","bids":[{"price":83.21780,"qty":9.01709265}],"asks":[],"checksum":404166964,"timestamp":"2024-06-01T18:07:22.293295Z"}]}
{"channel":"book","type":"update","data":[{"symbol":"LTC/USDT","bids":[],"asks":[{"price":83.28120,"qty":0.00000000},{"price":83.31475,"qty":2.22000000}],"checksum":1985183572,"timestamp":"2024-06-01T18:07:22.439402Z"}]}
{"channel":"book","type":"update","data":[{"symbol":"LTC/USDT","bids":[{"price":83.20809,"qty":0.47504041}],"asks":[],"checksum":2938354166,"timestamp":"2024-06-01T18:07:22.508741Z"}]}
{"channel":"book","type":"update","data":[{"symbol":"LTC/USDT","bids":[],"asks":[{"price":83.26841,"qty":1.99000000}],"checksum":1267009325,"timestamp":"2024-06-01T18:07:22.514663Z"}]}
{"channel":"book","type":"update","data":[{"symbol":"LTC/USDT","bids":[],"asks":[{"price":83.26875,"qty":0.00000000},{"price":83.31475,"qty":2.22000000}],"checksum":3853450983,"timestamp":"2024-06-01T18:07:22.588908Z"}]}
{"channel":"book","type":"update","data":[{"symbol":"LTC/USDT","bids":[],"asks":[{"price":83.26840,"qty":13.36451721}],"checksum":3277374193,"timestamp":"2024-06-01T18:07:22.595258Z"}]}
{"channel":"book","type":"update","data":[{"symbol":"LTC/USDT","bids":[{"price":83.22022,"qty":0.00000000},{"price":83.18671,"qty":13.36451721}],"asks":[],"checksum":1649427811,"timestamp":"2024-06-01T18:07:22.618875Z"}]}
{"channel":"book","type":"update","data":[{"symbol":"LTC/USDT","bids":[{"price":83.22013,"qty":18.03418531}],"asks":[],"checksum":811732346,"timestamp":"2024-06-01T18:07:22.659163Z"}]}
{"channel":"book","type":"update","data":[{"symbol":"LTC/USDT","bids":[],"asks":[{"price":83.26861,"qty":0.00000000},{"price":83.31475,"qty":2.22000000}],"checksum":1255429318,"timestamp":"2024-06-01T18:07:22.665326Z"}]}
{"channel":"book","type":"update","data":[{"symbol":"LTC/USDT","bids":[],"asks":[{"price":83.27132,"qty":2.60000000}],"checksum":3022244521,"timestamp":"2024-06-01T18:07:23.136561Z"}]}
{"channel":"book","type":"update","data":[{"symbol":"LTC/USDT","bids":[],"asks":[{"price":83.26828,"qty":10.00000000}],"checksum":854263214,"timestamp":"2024-06-01T18:07:23.141275Z"}]}
{"channel":"book","type":"update","data":[{"symbol":"LTC/USDT","bids":[],"asks":[{"price":83.26862,"qty":0.00000000},{"price":83.30797,"qty":11.24751530}],"checksum":2318980535,"timestamp":"2024-06-01T18:07:23.212958Z"}]}
{"channel":"book","type":"update","data":[{"symbol":"LTC/USDT","bids":[],"asks":[{"price":83.26827,"qty":13.36451721}],"checksum":3873289677,"timestamp":"2024-06-01T18:07:23.218473Z"}]}
{"channel":"book","type":"update","data":[{"symbol":"LTC/USDT","bids":[{"price":83.22013,"qty":0.00000000},{"price":83.18671,"qty":13.36451721}],"asks":[],"checksum":3035626964,"timestamp":"2024-06-01T18:07:23.264877Z"}]}
{"channel":"book","type":"update","data":[{"symbol":"LTC/USDT","bids":[],"asks":[{"price":83.26840,"qty":0.00000000},{"price":83.30797,"qty":11.24751530}],"checksum":3108163730,"timestamp":"2024-06-01T18:07:23.269753Z"}]}
{"channel":"book","type":"update","data":[{"symbol":"LTC/USDT","bids":[{"price":83.22039,"qty":18.03418525}],"asks":[],"checksum":2767022151,"timestamp":"2024-06-01T18:07:23.305051Z"}]}
{"channel":"book","type":"update","data":[{"symbol":"LTC/USDT","bids":[{"price":83.21780,"qty":0.00000000},{"price":83.18671,"qty":13.36451721}],"asks":[],"checksum":2165802646,"timestamp":"2024-06-01T18:07:23.392644Z"}]}
{"channel":"book","type":"update","data":[{"symbol":"LTC/USDT","bids":[{"price":83.21805,"qty":9.01709302}],"asks":[],"checksum":3371070634,"timestamp":"2024-06-01T18:07:23.432662Z"}]}
{"channel":"book","type":"update","data":[{"symbol":"LTC/USDT","bids":[],"asks":[{"price":83.26807,"qty":1.99000000}],"checksum":3559387541,"timestamp":"2024-06-01T18:07:23.586928Z"}]}
{"channel":"book","type":"update","data":[{"symbol":"LTC/USDT","bids":[],"asks":[{"price":83.26841,"qty":0.00000000},{"price":83.30797,"qty":11.24751530}],"checksum":290867996,"timestamp":"2024-06-01T18:07:23.591261Z"}]}
{"channel":"book","type":"update","data":[{"symbol":"LTC/USDT","bids":[],"asks":[{"price":83.26806,"qty":13.36451721}],"checksum":3184236956,"timestamp":"2024-06-01T18:07:23.592434Z"}]}
{"channel":"book","type":"update","data":[{"symbol":"LTC/USDT","bids":[],"asks":[{"price":83.26527,"qty":1.80000000}],"checksum":570414712,"timestamp":"2024-06-01T18:07:23.916174Z"}]}
{"channel":"book","type":"update","data":[{"symbol":"LTC/USDT","bids":[],"asks":[{"price":83.26794,"qty":10.00000000}],"checksum":1416504023,"timestamp":"2024-06-01T18:07:23.920781Z"}]}
{"channel":"book","type":"update","data":[{"symbol":"LTC/USDT","bids":[],"asks":[{"price":83.26507,"qty":1.99000000}],"checksum":2256067321,"timestamp":"2024-06-01T18:07:23.921254Z"}]}
{"channel":"book","type":"update","data":[{"symbol":"LTC/USDT","bids":[],"asks":[{"price":83.26806,"qty":0.00000000},{"price":83.29196,"qty":2.23000000}],"checksum":1958381076,"timestamp":"2024-06-01T18:07:23.923043Z"}]}
{"channel":"book","type":"update","data":[{"symbol":"LTC/USDT","bids":[],"asks":[{"price":83.26526,"qty":13.36451721}],"checksum":1649144047,"timestamp":"2024-06-01T18:07:23.923072Z"}]}
{"channel":"book","type":"update","data":[{"symbol":"LTC/USDT","bids":[],"asks":[{"price":83.26526,"qty":0.00000000},{"price":83.29196,"qty":2.23000000}],"checksum":1958381076,"timestamp":"2024-06-01T18:07:23.952711Z"}]}
{"channel":"book","type":"update","data":[{"symbol":"LTC/USDT","bids":[],"asks":[{"price":83.26506,"qty":13.36451721}],"checksum":265214137,"timestamp":"2024-06-01T18:07:23.952862Z"}]}
{"channel":"book","type":"update","data":[{"symbol":"LTC/USDT","bids":[],"asks":[{"price":83.26807,"qty":0.00000000},{"price":83.29196,"qty":2.23000000}],"checksum":5973026,"timestamp":"2024-06-01T18:07:23.956915Z"}]}
{"channel":"book","type":"update","data":[{"symbol":"LTC/USDT","bids":[],"asks":[{"price":83.26827,"qty":0.00000000},{"price":83.29611,"qty":10.00000000}],"checksum":3169063001,"timestamp":"2024-06-01T18:07:23.956980Z"}]}
{"channel":"book","type":"update","data":[{"symbol":"LTC/USDT","bids":[],"asks":[{"price":83.26828,"qty":0.00000000},{"price":83.29682,"qty":8.65544977}],"checksum":2266795983,"timestamp":"2024-06-01T18:07:23.957319Z"}]}
{"channel":"book","type":"update","data":[{"symbol":"LTC/USDT","bids":[],"asks":[{"price":83.26494,"qty":10.00000000}],"checksum":2936362668,"timestamp":"2024-06-01T18:07:24.213520Z"}]}
{"channel":"book","type":"update","data":[{"symbol":"LTC/USDT","bids":[],"asks":[{"price":83.26794,"qty":0.00000000},{"price":83.29682,"qty":8.65544977}],"checksum":1640612675,"timestamp":"2024-06-01T18:07:24.217959Z"}]}
{"channel":"book","type":"update","data":[{"symbol":"LTC/USDT","bids":[],"asks":[{"price":83.26493,"qty":13.36451721}],"checksum":2220793341,"timestamp":"2024-06-01T18:07:24.218711Z"}]}
{"channel":"book","type":"update","data":[{"symbol":"LTC/USDT","bids":[{"price":83.22039,"qty":0.00000000},{"price":83.18671,"qty":13.36451721}],"asks":[],"checksum":3631587098,"timestamp":"2024-06-01T18:07:24.345252Z"}]}
{"channel":"book","type":"update","data":[{"symbol":"LTC/USDT","bids":[],"asks":[{"price":83.26506,"qty":0.00000000},{"price":83.29682,"qty":8.65544977}],"checksum":307728616,"timestamp":"2024-06-01T18:07:24.350522Z"}]}
{"channel":"book","type":"update","data":[{"symbol":"LTC/USDT","bids":[{"price":83.21976,"qty":18.03452716}],"asks":[],"checksum":3476353356,"timestamp":"2024-06-01T18:07:24.385450Z"}]}
{"channel":"book","type":"update","data":[{"symbol":"LTC/USDT","bids":[{"price":83.21805,"qty":0.00000000},{"price":83.18671,"qty":13.36451721}],"asks":[],"checksum":3363380062,"timestamp":"2024-06-01T18:07:24.474227Z"}]}
{"channel":"book","type":"update","data":[{"symbol":"LTC/USDT","bids":[],"asks":[{"price":83.26527,"qty":0.00000000},{"price":83.30797,"qty":11.24751530}],"checksum":3109827468,"timestamp":"2024-06-01T18:07:24.476942Z"}]}
{"channel":"book","type":"update","data":[{"symbol":"LTC/USDT","bids":[],"asks":[{"price":83.26214,"qty":1.80000000}],"checksum":4057507669,"timestamp":"2024-06-01T18:07:24.477305Z"}]}
{"channel":"book","type":"update","data":[{"symbol":"LTC/USDT","bids":[],"asks":[{"price":83.26473,"qty":1.99000000}],"checksum":3140759375,"timestamp":"2024-06-01T18:07:24.479262Z"}]}
{"channel":"book","type":"update","data":[{"symbol":"LTC/USDT","bids":[{"price":83.21743,"qty":9.01726358}],"asks":[],"checksum":2108516811,"timestamp":"2024-06-01T18:07:24.514167Z"}]}
{"channel":"book","type":"update","data":[{"symbol":"LTC/USDT","bids":[],"asks":[{"price":83.26473,"qty":0.00000000},{"price":83.29682,"qty":8.65544977}],"checksum":1317024431,"timestamp":"2024-06-01T18:07:24.519426Z"}]}
{"channel":"book","type":"update","data":[{"symbol":"LTC/USDT","bids":[],"asks":[{"price":83.28727,"qty":0.00000000},{"price":83.30797,"qty":11.24751530}],"checksum":1395312992,"timestamp":"2024-06-01T18:07:24.589272Z"}]}
{"channel":"book","type":"update","data":[{"symbol":"LTC/USDT","bids":[],"asks":[{"price":83.27875,"qty":7.99100000}],"checksum":1524168541,"timestamp":"2024-06-01T18:07:24.592012Z"}]}
{"channel":"book","type":"update","data":[{"symbol":"LTC/USDT","bids":[{"price":83.21976,"qty":0.00000000},{"price":83.18671,"qty":13.36451721}],"asks":[],"checksum":3177352258,"timestamp":"2024-06-01T18:07:24.944040Z"}]}
{"channel":"book","type":"update","data":[{"symbol":"LTC/USDT","bids":[],"asks":[{"price":83.26481,"qty":10.00000000}],"checksum":2693818663,"timestamp":"2024-06-01T18:07:24.949482Z"}]}
{"channel":"book","type":"update","data":[{"symbol":"LTC/USDT","bids":[{"price":83.21942,"qty":18.03452716}],"asks":[],"checksum":196930190,"timestamp":"2024-06-01T18:07:24.984062Z"}]}
{"channel":"book","type":"update","data":[{"symbol":"LTC/USDT","bids":[],"asks":[{"price":83.26494,"qty":0.00000000},{"price":83.29682,"qty":8.65544977}],"checksum":3313109413,"timestamp":"2024-06-01T18:07:24.988336Z"}]}
{"channel":"book","type":"update","data":[{"symbol":"LTC/USDT","bids":[{"price":83.21743,"qty":0.00000000},{"price":83.18671,"qty":13.36451721}],"asks":[],"checksum":294040688,"timestamp":"2024-06-01T18:07:25.064186Z"}]}
{"channel":"book","type":"update","data":[{"symbol":"LTC/USDT","bids":[{"price":83.21691,"qty":9.01731075}],"asks":[],"checksum":4092013138,"timestamp":"2024-06-01T18:07:25.104005Z"}]}
{"channel":"book","type":"update","data":[{"symbol":"LTC/USDT","bids":[{"price":83.21942,"qty":0.00000000},{"price":83.18671,"qty":13.36451721}],"asks":[],"checksum":200552105,"timestamp":"2024-06-01T18:07:25.537922Z"}]}
{"channel":"book","type":"update","data":[{"symbol":"LTC/USDT","bids":[],"asks":[{"price":83.26194,"qty":1.99000000}],"checksum":2192317848,"timestamp":"2024-06-01T18:07:25.542795Z"}]}
{"channel":"book","type":"update","data":[{"symbol":"LTC/USDT","bids":[],"asks":[{"price":83.26214,"qty":0.00000000},{"price":83.29682,"qty":8.65544977}],"checksum":2944021914,"timestamp":"2024-06-01T18:07:25.545426Z"}]}
{"channel":"book","type":"update","data":[{"symbol":"LTC/USDT","bids":[],"asks":[{"price":83.25915,"qty":1.80000000}],"checksum":919570277,"timestamp":"2024-06-01T18:07:25.545644Z"}]}
{"channel":"book","type":"update","data":[{"symbol":"LTC/USDT","bids":[{"price":83.21989,"qty":18.03457823}],"asks":[],"checksum":4024147465,"timestamp":"2024-06-01T18:07:25.578118Z"}]}
{"channel":"book","type":"update","data":[{"symbol":"LTC/USDT","bids":[],"asks":[{"price":83.26194,"qty":0.00000000},{"price":83.29682,"qty":8.65544977}],"checksum":2297915708,"timestamp":"2024-06-01T18:07:25.583250Z"}]}
{"channel":"book","type":"update","data":[{"symbol":"LTC/USDT","bids":[{"price":83.21691,"qty":0.00000000},{"price":83.18671,"qty":13.36451721}],"asks":[],"checksum":3153586284,"timestamp":"2024-06-01T18:07:25.655182Z"}]}
{"channel":"book","type":"update","data":[{"symbol":"LTC/USDT","bids":[{"price":83.21732,"qty":9.01732298}],"asks":[],"checksum":116386277,"timestamp":"2024-06-01T18:07:25.695440Z"}]}
{"channel":"book","type":"update","data":[{"symbol":"LTC/USDT","bids":[{"price":83.21989,"qty":0.00000000},{"price":83.18671,"qty":13.36451721}],"asks":[],"checksum":1597032370,"timestamp":"2024-06-01T18:07:26.130417Z"}]}
{"channel":"book","type":"update","data":[{"symbol":"LTC/USDT","bids":[{"price":83.21732,"qty":0.00000000},{"price":83.18501,"qty":7.99100000}],"asks":[],"checksum":1090401282,"timestamp":"2024-06-01T18:07:26.178477Z"}]}
{"channel":"book","type":"update","data":[{"symbol":"LTC/USDT","bids":[{"price":83.20066,"qty":0.00000000},{"price":83.18093,"qty":2.69000000}],"asks":[],"checksum":1941981735,"timestamp":"2024-06-01T18:07:26.180939Z"}]}
{"channel":"book","type":"update","data":[{"symbol":"LTC/USDT","bids":[{"price":83.21088,"qty":1.80000000}],"asks":[],"checksum":2424808987,"timestamp":"2024-06-01T18:07:26.181362Z"}]}
{"channel":"book","type":"update","data":[{"symbol":"LTC/USDT","bids":[{"price":83.20808,"qty":0.00000000},{"price":83.18093,"qty":2.69000000}],"asks":[],"checksum":610868654,"timestamp":"2024-06-01T18:07:26.182496Z"}]}
{"channel":"book","type":"update","data":[{"symbol":"LTC/USDT","bids":[{"price":83.20151,"qty":23.85306512}],"asks":[],"checksum":1514504665,"timestamp":"2024-06-01T18:07:26.182654Z"}]}
{"channel":"book","type":"update","data":[{"symbol":"LTC/USDT","bids":[{"price":83.21723,"qty":9.01738342}],"asks":[],"checksum":2358037950,"timestamp":"2024-06-01T18:07:26.218697Z"}]}
{"channel":"book","type":"update","data":[{"symbol":"LTC/USDT","bids":[],"asks":[{"price":83.28612,"qty":3.02951062}],"checksum":3690220971,"timestamp":"2024-06-01T18:07:26.461145Z"}]}
{"channel":"book","type":"update","data":[{"symbol":"LTC/USDT","bids":[],"asks":[{"price":83.25895,"qty":1.99000000}],"checksum":1034725586,"timestamp":"2024-06-01T18:07:26.587306Z"}]}
{"channel":"book","type":"update","data":[{"symbol":"LTC/USDT","bids":[],"asks":[{"price":83.25915,"qty":0.00000000},{"price":83.29611,"qty":10.00000000}],"checksum":564322751,"timestamp":"2024-06-01T18:07:26.590021Z"}]}
{"channel":"book","type":"update","data":[{"symbol":"LTC/USDT","bids":[],"asks":[{"price":83.25616,"qty":1.80000000}],"checksum":585848400,"timestamp":"2024-06-01T18:07:26.590337Z"}]}
{"channel":"book","type":"update","data":[{"symbol":"LTC/USDT","bids":[],"asks":[{"price":83.26507,"qty":0.00000000},{"price":83.29611,"qty":10.00000000}],"checksum":2390441787,"timestamp":"2024-06-01T18:07:26.592087Z"}]}
{"channel":"book","type":"update","data":[{"symbol":"LTC/USDT","bids":[],"asks":[{"price":83.25903,"qty":10.00000000}],"checksum":3829796796,"timestamp":"2024-06-01T18:07:26.592311Z"}]}
{"channel":"book","type":"update","data":[{"symbol":"LTC/USDT","bids":[{"price":83.21989,"qty":18.03468766}],"asks":[],"checksum":315281064,"timestamp":"2024-06-01T18:07:26.648030Z"}]}
{"channel":"book","type":"update","data":[{"symbol":"LTC/USDT","bids":[],"asks":[{"price":83.25903,"qty":0.00000000},{"price":83.29611,"qty":10.00000000}],"checksum":2029518383,"timestamp":"2024-06-01T18:07:26.652989Z"}]}
{"channel":"book","type":"update","data":[{"symbol":"LTC/USDT","bids":[],"asks":[{"price":83.25596,"qty":1.99000000}],"checksum":2835703993,"timestamp":"2024-06-01T18:07:26.653172Z"}]}
{"channel":"book","type":"update","data":[{"symbol":"LTC/USDT","bids":[],"asks":[{"price":83.25616,"qty":0.00000000},{"price":83.29611,"qty":10.00000000}],"checksum":3698976028,"timestamp":"2024-06-01T18:07:26.655889Z"}]}
{"channel":"book","type":"update","data":[{"symbol":"LTC/USDT","bids":[],"asks":[{"price":83.25352,"qty":1.80000000}],"checksum":3501298119,"timestamp":"2024-06-01T18:07:26.655906Z"}]}
{"channel":"book","type":"update","data":[{"symbol":"LTC/USDT","bids":[{"price":83.21723,"qty":0.00000000},{"price":83.18671,"qty":13.36451721}],"asks":[],"checksum":1513973655,"timestamp":"2024-06-01T18:07:26.772222Z"}]}
{"channel":"book","type":"update","data":[{"symbol":"LTC/USDT","bids":[],"asks":[{"price":83.25584,"qty":10.00000000}],"checksum":3521165826,"timestamp":"2024-06-01T18:07:26.776938Z"}]}
{"channel":"book","type":"update","data":[{"symbol":"LTC/USDT","bids":[],"asks":[{"price":83.25596,"qty":0.00000000},{"price":83.29196,"qty":2.23000000}],"checksum":3060612980,"timestamp":"2024-06-01T18:07:26.777427Z"}]}
{"channel":"book","type":"update","data":[{"symbol":"LTC/USDT","bids":[{"price":83.21756,"qty":9.01734233}],"asks":[],"checksum":1450079222,"timestamp":"2024-06-01T18:07:26.812640Z"}]}
{"channel":"book","type":"update","data":[{"symbol":"LTC/USDT","bids":[],"asks":[{"price":83.26481,"qty":0.00000000},{"price":83.29611,"qty":10.00000000}],"checksum":1721037121,"timestamp":"2024-06-01T18:07:26.816961Z"}]}
{"channel":"book","type":"update","data":[{"symbol":"LTC/USDT","bids":[{"price":83.21989,"qty":0.00000000},{"price":83.18671,"qty":13.36451721}],"asks":[],"checksum":2286825514,"timestamp":"2024-06-01T18:07:27.192770Z"}]}
{"channel":"book","type":"update","data":[{"symbol":"LTC/USDT","bids":[{"price":83.22028,"qty":18.03470443}],"asks":[],"checksum":1923704351,"timestamp":"2024-06-01T18:07:27.232800Z"}]}
{"channel":"book","type":"update","data":[{"symbol":"LTC/USDT","bids":[{"price":83.21756,"qty":0.00000000},{"price":83.18671,"qty":13.36451721}],"asks":[],"checksum":1872732861,"timestamp":"2024-06-01T18:07:27.356743Z"}]}
{"channel":"book","type":"update","data":[{"symbol":"LTC/USDT","bids":[],"asks":[{"price":83.25584,"qty":0.00000000},{"price":83.29682,"qty":8.65544977}],"checksum":3772265399,"timestamp":"2024-06-01T18:07:27.361359Z"}]}
{"channel":"book","type":"update","data":[{"symbol":"LTC/USDT","bids":[{"price":83.21794,"qty":9.01735201}],"asks":[],"checksum":162255784,"timestamp":"2024-06-01T18:07:27.396840Z"}]}
{"channel":"book","type":"update","data":[{"symbol":"LTC/USDT","bids":[],"asks":[{"price":83.25883,"qty":10.00000000}],"checksum":2048363910,"timestamp":"2024-06-01T18:07:27.401180Z"}]}
{"channel":"book","type":"update","data":[{"symbol":"LTC/USDT","bids":[],"asks":[{"price":83.25332,"qty":1.99000000}],"checksum":3251073963,"timestamp":"2024-06-01T18:07:27.587358Z"}]}
{"channel":"book","type":"update","data":[{"symbol":"LTC/USDT","bids":[],"asks":[{"price":83.25895,"qty":0.00000000},{"price":83.29611,"qty":10.00000000}],"checksum":2438603080,"timestamp":"2024-06-01T18:07:27.591858Z"}]}
{"channel":"book","type":"update","data":[{"symbol":"LTC/USDT","bids":[],"asks":[{"price":83.25352,"qty":0.00000000},{"price":83.29682,"qty":8.65544977}],"checksum":2416372917,"timestamp":"2024-06-01T18:07:27.672787Z"}]}
{"channel":"book","type":"update","data":[{"symbol":"LTC/USDT","bids":[],"asks":[{"price":83.25328,"qty":1.80000000}],"checksum":2464636499,"timestamp":"2024-06-01T18:07:27.673117Z"}]}
{"channel":"book","type":"update","data":[{"symbol":"LTC/USDT","bids":[],"asks":[{"price":83.25883,"qty":0.00000000},{"price":83.29682,"qty":8.65544977}],"checksum":3432193571,"timestamp":"2024-06-01T18:07:27.677490Z"}]}
{"channel":"book","type":"update","data":[{"symbol":"LTC/USDT","bids":[{"price":83.20809,"qty":0.00000000},{"price":83.18671,"qty":13.36451721}],"asks":[],"checksum":40188601,"timestamp":"2024-06-01T18:07:28.127140Z"}]}
{"channel":"book","type":"update","data":[{"symbol":"LTC/USDT","bids":[],"asks":[{"price":83.26296,"qty":10.00000000}],"checksum":1875662415,"timestamp":"2024-06-01T18:07:28.132442Z"}]}
{"channel":"book","type":"update","data":[{"symbol":"LTC/USDT","bids":[{"price":83.20152,"qty":0.36759560}],"asks":[],"checksum":3228167937,"timestamp":"2024-06-01T18:07:28.133324Z"}]}
{"channel":"book","type":"update","data":[{"symbol":"LTC/USDT","bids":[{"price":83.22028,"qty":0.00000000},{"price":83.18671,"qty":13.36451721}],"asks":[],"checksum":4157355681,"timestamp":"2024-06-01T18:07:28.301714Z"}]}
{"channel":"book","type":"update","data":[{"symbol":"LTC/USDT","bids":[{"price":83.22075,"qty":18.03470522}],"asks":[],"checksum":759938861,"timestamp":"2024-06-01T18:07:28.342011Z"}]}
{"channel":"book","type":"update","data":[{"symbol":"LTC/USDT","bids":[{"price":83.21794,"qty":0.00000000},{"price":83.18671,"qty":13.36451721}],"asks":[],"checksum":3773972500,"timestamp":"2024-06-01T18:07:28.504805Z"}]}
{"channel":"book","type":"update","data":[{"symbol":"LTC/USDT","bids":[],"asks":[{"price":83.25308,"qty":1.99000000}],"checksum":3215411926,"timestamp":"2024-06-01T18:07:28.509841Z"}]}
{"channel":"book","type":"update","data":[{"symbol":"LTC/USDT","bids":[],"asks":[{"price":83.25328,"qty":0.00000000},{"price":83.29611,"qty":10.00000000}],"checksum":1454610897,"timestamp":"2024-06-01T18:07:28.512623Z"}]}
{"channel":"book","type":"update","data":[{"symbol":"LTC/USDT","bids":[],"asks":[{"price":83.25239,"qty":1.80000000}],"checksum":2073140009,"timestamp":"2024-06-01T18:07:28.513019Z"}]}
{"channel":"book","type":"update","data":[{"symbol":"LTC/USDT","bids":[{"price":83.21842,"qty":9.01735241}],"asks":[],"checksum":653462604,"timestamp":"2024-06-01T18:07:28.544906Z"}]}
{"channel":"book","type":"update","data":[{"symbol":"LTC/USDT","bids":[],"asks":[{"price":83.25308,"qty":0.00000000},{"price":83.29611,"qty":10.00000000}],"checksum":1911553281,"timestamp":"2024-06-01T18:07:28.549545Z"}]}
{"channel":"book","type":"update","data":[{"symbol":"LTC/USDT","bids":[{"price":83.22075,"qty":0.00000000},{"price":83.18671,"qty":13.36451721}],"asks":[],"checksum":815157205,"timestamp":"2024-06-01T18:07:28.885958Z"}]}
{"channel":"book","type":"update","data":[{"symbol":"LTC/USDT","bids":[{"price":83.22076,"qty":18.03471920}],"asks":[],"checksum":3786798229,"timestamp":"2024-06-01T18:07:28.926295Z"}]}
{"channel":"book","type":"update","data":[{"symbol":"LTC/USDT","bids":[{"price":83.21842,"qty":0.00000000},{"price":83.18671,"qty":13.36451721}],"asks":[],"checksum":2220472225,"timestamp":"2024-06-01T18:07:29.090038Z"}]}
{"channel":"book","type":"update","data":[{"symbol":"LTC/USDT","bids":[{"price":83.21860,"qty":9.01733386}],"asks":[],"checksum":4101573034,"timestamp":"2024-06-01T18:07:29.129956Z"}]}
{"channel":"book","type":"update","data":[{"symbol":"LTC/USDT","bids":[{"price":83.22076,"qty":0.00000000},{"price":83.18671,"qty":13.36451721}],"asks":[],"checksum":1722792720,"timestamp":"2024-06-01T18:07:29.469099Z"}]}
{"channel":"book","type":"update","data":[{"symbol":"LTC/USDT","bids":[],"asks":[{"price":83.25219,"qty":1.99000000}],"checksum":293969558,"timestamp":"2024-06-01T18:07:29.474126Z"}]}
{"channel":"book","type":"update","data":[{"symbol":"LTC/USDT","bids":[],"asks":[{"price":83.25239,"qty":0.00000000},{"price":83.29611,"qty":10.00000000}],"checksum":1096500015,"timestamp":"2024-06-01T18:07:29.477099Z"}]}
{"channel":"book","type":"update","data":[{"symbol":"LTC/USDT","bids":[],"asks":[{"price":83.25213,"qty":1.80000000}],"checksum":226532465,"timestamp":"2024-06-01T18:07:29.477355Z"}]}
{"channel":"book","type":"update","data":[{"symbol":"LTC/USDT","bids":[{"price":83.22115,"qty":18.03476209}],"asks":[],"checksum":20523877,"timestamp":"2024-06-01T18:07:29.509435Z"}]}
{"channel":"book","type":"update","data":[{"symbol":"LTC/USDT","bids":[],"asks":[{"price":83.25219,"qty":0.00000000},{"price":83.29611,"qty":10.00000000}],"checksum":3226981295,"timestamp":"2024-06-01T18:07:29.514449Z"}]}
{"channel":"book","type":"update","data":[{"symbol":"LTC/USDT","bids":[],"asks":[{"price":83.25193,"qty":1.99000000}],"checksum":2925674273,"timestamp":"2024-06-01T18:07:29.588578Z"}]}
{"channel":"book","type":"update","data":[{"symbol":"LTC/USDT","bids":[],"asks":[{"price":83.25332,"qty":0.00000000},{"price":83.29611,"qty":10.00000000}],"checksum":2914621488,"timestamp":"2024-06-01T18:07:29.592942Z"}]}
{"channel":"book","type":"update","data":[{"symbol":"LTC/USDT","bids":[],"asks":[{"price":83.25213,"qty":0.00000000},{"price":83.29682,"qty":8.65544977}],"checksum":3786106968,"timestamp":"2024-06-01T18:07:29.595668Z"}]}
{"channel":"book","type":"update","data":[{"symbol":"LTC/USDT","bids":[],"asks":[{"price":83.26017,"qty":1.80000000}],"checksum":797505146,"timestamp":"2024-06-01T18:07:29.595738Z"}]}
{"channel":"book","type":"update","data":[{"symbol":"LTC/USDT","bids":[{"price":83.21860,"qty":0.00000000},{"price":83.18671,"qty":13.36451721}],"asks":[],"checksum":38900874,"timestamp":"2024-06-01T18:07:29.672324Z"}]}
{"channel":"book","type":"update","data":[{"symbol":"LTC/USDT","bids":[],"asks":[{"price":83.26005,"qty":10.00000000}],"checksum":1633308895,"timestamp":"2024-06-01T18:07:29.677058Z"}]}
{"channel":"book","type":"update","data":[{"symbol":"LTC/USDT","bids":[],"asks":[{"price":83.26017,"qty":0.00000000},{"price":83.29611,"qty":10.00000000}],"checksum":737931963,"timestamp":"2024-06-01T18:07:29.679818Z"}]}
{"channel":"book","type":"update","data":[{"symbol":"LTC/USDT","bids":[],"asks":[{"price":83.25726,"qty":1.80000000}],"checksum":3036079461,"timestamp":"2024-06-01T18:07:29.680227Z"}]}
{"channel":"book","type":"update","data":[{"symbol":"LTC/USDT","bids":[],"asks":[{"price":83.26005,"qty":0.00000000},{"price":83.29611,"qty":10.00000000}],"checksum":856364950,"timestamp":"2024-06-01T18:07:29.711435Z"}]}
{"channel":"book","type":"update","data":[{"symbol":"LTC/USDT","bids":[{"price":83.21882,"qty":9.01738104}],"asks":[],"checksum":4116928535,"timestamp":"2024-06-01T18:07:29.712691Z"}]}
{"channel":"book","type":"update","data":[{"symbol":"LTC/USDT","bids":[],"asks":[{"price":83.25714,"qty":10.00000000}],"checksum":2610885467,"timestamp":"2024-06-01T18:07:29.715956Z"}]}
{"channel":"book","type":"update","data":[{"symbol":"LTC/USDT","bids":[],"asks":[{"price":83.25726,"qty":0.00000000},{"price":83.29611,"qty":10.00000000}],"checksum":3629800397,"timestamp":"2024-06-01T18:07:29.718802Z"}]}
{"channel":"book","type":"update","data":[{"symbol":"LTC/USDT","bids":[],"asks":[{"price":83.25435,"qty":1.80000000}],"checksum":2573588911,"timestamp":"2024-06-01T18:07:29.718930Z"}]}
{"channel":"book","type":"update","data":[{"symbol":"LTC/USDT","bids":[{"price":83.22115,"qty":0.00000000},{"price":83.18671,"qty":13.36451721}],"asks":[],"checksum":3826194492,"timestamp":"2024-06-01T18:07:29.985238Z"}]}
{"channel":"book","type":"update","data":[{"symbol":"LTC/USDT","bids":[],"asks":[{"price":83.25435,"qty":0.00000000},{"price":83.29611,"qty":10.00000000}],"checksum":2771425886,"timestamp":"2024-06-01T18:07:29.987843Z"}]}
{"channel":"book","type":"update","data":[{"symbol":"LTC/USDT","bids":[],"asks":[{"price":83.25185,"qty":1.80000000}],"checksum":2238364614,"timestamp":"2024-06-01T18:07:29.988321Z"}]}
{"channel":"book","type":"update","data":[{"symbol":"LTC/USDT","bids":[],"asks":[{"price":83.25714,"qty":0.00000000},{"price":83.29611,"qty":10.00000000}],"checksum":2223485218,"timestamp":"2024-06-01T18:07:29.989666Z"}]}
{"channel":"book","type":"update","data":[{"symbol":"LTC/USDT","bids":[{"price":83.22097,"qty":18.03481435}],"asks":[],"checksum":4264734211,"timestamp":"2024-06-01T18:07:30.025426Z"}]}
{"channel":"book","type":"update","data":[{"symbol":"LTC/USDT","bids":[{"price":83.21882,"qty":0.00000000},{"price":83.18671,"qty":13.36451721}],"asks":[],"checksum":702190109,"timestamp":"2024-06-01T18:07:30.188833Z"}]}
{"channel":"book","type":"update","data":[{"symbol":"LTC/USDT","bids":[{"price":83.21953,"qty":9.01736758}],"asks":[],"checksum":2634997831,"timestamp":"2024-06-01T18:07:30.228970Z"}]}
{"channel":"book","type":"update","data":[{"symbol":"LTC/USDT","bids":[{"price":83.22097,"qty":0.00000000},{"price":83.18671,"qty":13.36451721}],"asks":[],"checksum":3722137999,"timestamp":"2024-06-01T18:07:30.569566Z"}]}
{"channel":"book","type":"update","data":[{"symbol":"LTC/USDT","bids":[],"asks":[{"price":83.25165,"qty":1.99000000}],"checksum":1926862185,"timestamp":"2024-06-01T18:07:30.574928Z"}]}
{"channel":"book","type":"update","data":[{"symbol":"LTC/USDT","bids":[],"asks":[{"price":83.25193,"qty":0.00000000},{"price":83.29611,"qty":10.00000000}],"checksum":2312893977,"timestamp":"2024-06-01T18:07:30.585798Z"}]}
{"channel":"book","type":"update","data":[{"symbol":"LTC/USDT","bids":[],"asks":[{"price":83.25185,"qty":0.00000000},{"price":83.29682,"qty":8.65544977}],"checksum":3915608575,"timestamp":"2024-06-01T18:07:30.588565Z"}]}
{"channel":"book","type":"update","data":[{"symbol":"LTC/USDT","bids":[],"asks":[{"price":83.26017,"qty":1.80000000}],"checksum":658567133,"timestamp":"2024-06-01T18:07:30.588821Z"}]}
{"channel":"book","type":"update","data":[{"symbol":"LTC/USDT","bids":[],"asks":[{"price":83.26005,"qty":10.00000000}],"checksum":719872960,"timestamp":"2024-06-01T18:07:30.712526Z"}]}
{"channel":"book","type":"update","data":[{"symbol":"LTC/USDT","bids":[],"asks":[{"price":83.26017,"qty":0.00000000},{"price":83.29611,"qty":10.00000000}],"checksum":495682417,"timestamp":"2024-06-01T18:07:30.715200Z"}]}
{"channel":"book","type":"update","data":[{"symbol":"LTC/USDT","bids":[],"asks":[{"price":83.25726,"qty":1.80000000}],"checksum":3860610530,"timestamp":"2024-06-01T18:07:30.715235Z"}]}
