{"channel":"book","type":"snapshot","data":[{"symbol":"LTC/GBP","bids":[{"price":65.25583,"qty":15.21015478},{"price":65.25582,"qty":6.01117861},{"price":65.25580,"qty":8.68000000},{"price":65.21780,"qty":7.95653448},{"price":65.20050,"qty":4.82112449},{"price":65.09499,"qty":6.01289199},{"price":65.09498,"qty":6.44641331},{"price":65.09496,"qty":9.13893827},{"price":65.09035,"qty":17.82430478},{"price":65.08662,"qty":55.11221680}],"asks":[{"price":65.31984,"qty":6.00000000},{"price":65.31985,"qty":111.08992608},{"price":65.33890,"qty":4.82112449},{"price":65.37027,"qty":1.84738230},{"price":65.39336,"qty":8.83137436},{"price":65.39337,"qty":15.37633582},{"price":65.43111,"qty":9.13893827},{"price":65.44615,"qty":0.14256327},{"price":65.67474,"qty":17.82430478},{"price":65.67494,"qty":17.82430478}],"checksum":3326500591}]}
{"channel":"book","type":"update","data":[{"symbol":"LTC/GBP","bids":[{"price":65.09499,"qty":0.00000000},{"price":65.04259,"qty":0.13071089}],"asks":[],"checksum":1293538669,"timestamp":"2024-06-01T18:07:05.876956Z"}]}
{"channel":"book","type":"update","data":[{"symbol":"LTC/GBP","bids":[{"price":65.09499,"qty":6.01288844}],"asks":[],"checksum":2247335321,"timestamp":"2024-06-01T18:07:06.257400Z"}]}
{"channel":"book","type":"update","data":[{"symbol":"LTC/GBP","bids":[{"price":65.09499,"qty":0.00000000},{"price":65.04259,"qty":0.13071089}],"asks":[],"checksum":1293538669,"timestamp":"2024-06-01T18:07:06.674874Z"}]}
{"channel":"book","type":"update","data":[{"symbol":"LTC/GBP","bids":[{"price":65.09499,"qty":6.01284346}],"asks":[],"checksum":3869901694,"timestamp":"2024-06-01T18:07:06.738886Z"}]}
{"channel":"book","type":"update","data":[{"symbol":"LTC/GBP","bids":[{"price":65.25580,"qty":0.00000000},{"price":65.04259,"qty":0.13071089},{"price":65.25584,"qty":8.68000000}],"asks":[],"checksum":3686235632,"timestamp":"2024-06-01T18:07:08.421945Z"}]}
{"channel":"book","type":"update","data":[{"symbol":"LTC/GBP","bids":[],"asks":[{"price":65.31985,"qty":0.00000000},{"price":65.73807,"qty":12.06939088}],"checksum":1230066646,"timestamp":"2024-06-01T18:07:08.425009Z"}]}
{"channel":"book","type":"update","data":[{"symbol":"LTC/GBP","bids":[{"price":65.25583,"qty":0.00000000},{"price":65.04259,"qty":0.13071089},{"price":65.25585,"qty":15.21041796}],"asks":[],"checksum":1789090925,"timestamp":"2024-06-01T18:07:08.425844Z"}]}
{"channel":"book","type":"update","data":[{"symbol":"LTC/GBP","bids":[],"asks":[{"price":65.69870,"qty":0.29364866}],"checksum":1151101208,"timestamp":"2024-06-01T18:07:08.427239Z"}]}
{"channel":"book","type":"update","data":[{"symbol":"LTC/GBP","bids":[],"asks":[{"price":65.31200,"qty":104.32253435}],"checksum":109410669,"timestamp":"2024-06-01T18:07:08.427899Z"}]}
{"channel":"book","type":"update","data":[{"symbol":"LTC/GBP","bids":[{"price":65.09499,"qty":0.00000000},{"price":65.04259,"qty":0.13071089}],"asks":[],"checksum":3079329895,"timestamp":"2024-06-01T18:07:08.516100Z"}]}
{"channel":"book","type":"update","data":[{"symbol":"LTC/GBP","bids":[],"asks":[{"price":65.31199,"qty":6.00000000}],"checksum":4013154308,"timestamp":"2024-06-01T18:07:08.729148Z"}]}
{"channel":"book","type":"update","data":[{"symbol":"LTC/GBP","bids":[],"asks":[{"price":65.31984,"qty":0.00000000},{"price":65.67494,"qty":17.82430478}],"checksum":1206650344,"timestamp":"2024-06-01T18:07:08.735279Z"}]}
{"channel":"book","type":"update","data":[{"symbol":"LTC/GBP","bids":[{"price":65.09499,"qty":6.01283389}],"asks":[],"checksum":1538655046,"timestamp":"2024-06-01T18:07:12.530215Z"}]}
{"channel":"book","type":"update","data":[{"symbol":"LTC/GBP","bids":[{"price":65.09499,"qty":0.00000000},{"price":65.04259,"qty":0.13071089}],"asks":[],"checksum":1206650344,"timestamp":"2024-06-01T18:07:14.178723Z"}]}
{"channel":"book","type":"update","data":[{"symbol":"LTC/GBP","bids":[{"price":65.09499,"qty":6.01292642}],"asks":[],"checksum":3255358079,"timestamp":"2024-06-01T18:07:14.220427Z"}]}
{"channel":"book","type":"update","data":[{"symbol":"LTC/GBP","bids":[{"price":65.21780,"qty":0.00000000},{"price":65.04259,"qty":0.13071089}],"asks":[],"checksum":2781527371,"timestamp":"2024-06-01T18:07:19.207364Z"}]}
{"channel":"book","type":"update","data":[{"symbol":"LTC/GBP","bids":[{"price":65.25585,"qty":0.00000000},{"price":65.00001,"qty":17.82430478},{"price":65.09500,"qty":15.24723000}],"asks":[],"checksum":1252199027,"timestamp":"2024-06-01T18:07:19.210832Z"}]}
{"channel":"book","type":"update","data":[{"symbol":"LTC/GBP","bids":[{"price":65.20995,"qty":7.04152865}],"asks":[],"checksum":1650497032,"timestamp":"2024-06-01T18:07:19.212006Z"}]}
{"channel":"book","type":"update","data":[{"symbol":"LTC/GBP","bids":[{"price":65.09500,"qty":0.00000000},{"price":65.04259,"qty":0.13071089},{"price":65.25585,"qty":15.20964690}],"asks":[],"checksum":1710782638,"timestamp":"2024-06-01T18:07:19.213975Z"}]}
{"channel":"book","type":"update","data":[{"symbol":"LTC/GBP","bids":[{"price":65.09499,"qty":0.00000000},{"price":65.04259,"qty":0.13071089}],"asks":[],"checksum":3495998732,"timestamp":"2024-06-01T18:07:19.215446Z"}]}
{"channel":"book","type":"update","data":[{"symbol":"LTC/GBP","bids":[{"price":65.09501,"qty":6.01369973}],"asks":[],"checksum":3692998066,"timestamp":"2024-06-01T18:07:19.215502Z"}]}
{"channel":"book","type":"update","data":[{"symbol":"LTC/GBP","bids":[{"price":65.09498,"qty":0.00000000},{"price":65.04259,"qty":0.13071089}],"asks":[],"checksum":1638422368,"timestamp":"2024-06-01T18:07:19.216608Z"}]}
{"channel":"book","type":"update","data":[{"symbol":"LTC/GBP","bids":[{"price":65.09501,"qty":12.46010937}],"asks":[],"checksum":3132064093,"timestamp":"2024-06-01T18:07:19.216893Z"}]}
{"channel":"book","type":"update","data":[{"symbol":"LTC/GBP","bids":[{"price":65.09501,"qty":18.47128798}],"asks":[],"checksum":400960157,"timestamp":"2024-06-01T18:07:19.376518Z"}]}
{"channel":"book","type":"update","data":[{"symbol":"LTC/GBP","bids":[{"price":65.25584,"qty":0.00000000},{"price":65.00001,"qty":17.82430478}],"asks":[],"checksum":19058338,"timestamp":"2024-06-01T18:07:19.428888Z"}]}
{"channel":"book","type":"update","data":[{"symbol":"LTC/GBP","bids":[{"price":65.25585,"qty":0.00000000},{"price":65.00000,"qty":7.69231000},{"price":65.20996,"qty":15.22083311}],"asks":[],"checksum":1201536213,"timestamp":"2024-06-01T18:07:19.431899Z"}]}
{"channel":"book","type":"update","data":[{"symbol":"LTC/GBP","bids":[{"price":65.21587,"qty":1.30000000}],"asks":[],"checksum":284677303,"timestamp":"2024-06-01T18:07:19.434875Z"}]}
{"channel":"book","type":"update","data":[{"symbol":"LTC/GBP","bids":[{"price":65.09501,"qty":12.45758825}],"asks":[],"checksum":607429341,"timestamp":"2024-06-01T18:07:19.436494Z"}]}
{"channel":"book","type":"update","data":[{"symbol":"LTC/GBP","bids":[{"price":65.20997,"qty":6.01372179}],"asks":[],"checksum":2971129003,"timestamp":"2024-06-01T18:07:19.436677Z"}]}
{"channel":"book","type":"update","data":[{"symbol":"LTC/GBP","bids":[{"price":65.20996,"qty":0.00000000},{"price":65.04259,"qty":0.13071089},{"price":65.21588,"qty":15.21945144}],"asks":[],"checksum":3503295353,"timestamp":"2024-06-01T18:07:19.438097Z"}]}
{"channel":"book","type":"update","data":[{"symbol":"LTC/GBP","bids":[{"price":65.21587,"qty":0.00000000},{"price":65.04259,"qty":0.13071089}],"asks":[],"checksum":4282114677,"timestamp":"2024-06-01T18:07:19.440700Z"}]}
{"channel":"book","type":"update","data":[{"symbol":"LTC/GBP","bids":[{"price":65.22179,"qty":1.30000000}],"asks":[],"checksum":3589336827,"timestamp":"2024-06-01T18:07:19.440804Z"}]}
{"channel":"book","type":"update","data":[{"symbol":"LTC/GBP","bids":[{"price":65.20997,"qty":0.00000000},{"price":65.04259,"qty":0.13071089}],"asks":[],"checksum":3204754285,"timestamp":"2024-06-01T18:07:19.442862Z"}]}
{"channel":"book","type":"update","data":[{"symbol":"LTC/GBP","bids":[{"price":65.09502,"qty":6.01371486}],"asks":[],"checksum":2667846381,"timestamp":"2024-06-01T18:07:19.443074Z"}]}
{"channel":"book","type":"update","data":[{"symbol":"LTC/GBP","bids":[{"price":65.21588,"qty":0.00000000},{"price":65.04259,"qty":0.13071089},{"price":65.20998,"qty":15.22082845}],"asks":[],"checksum":444051435,"timestamp":"2024-06-01T18:07:19.444051Z"}]}
{"channel":"book","type":"update","data":[{"symbol":"LTC/GBP","bids":[{"price":65.20998,"qty":0.00000000},{"price":65.04259,"qty":0.13071089},{"price":65.20996,"qty":15.22083311}],"asks":[],"checksum":3407712544,"timestamp":"2024-06-01T18:07:19.447143Z"}]}
{"channel":"book","type":"update","data":[{"symbol":"LTC/GBP","bids":[{"price":65.09502,"qty":0.00000000},{"price":65.04259,"qty":0.13071089}],"asks":[],"checksum":2027442075,"timestamp":"2024-06-01T18:07:19.447967Z"}]}
{"channel":"book","type":"update","data":[{"symbol":"LTC/GBP","bids":[{"price":65.20999,"qty":6.01371486}],"asks":[],"checksum":3644818185,"timestamp":"2024-06-01T18:07:19.448115Z"}]}
{"channel":"book","type":"update","data":[{"symbol":"LTC/GBP","bids":[{"price":65.20996,"qty":0.00000000},{"price":65.04259,"qty":0.13071089},{"price":65.21000,"qty":15.22082378}],"asks":[],"checksum":2019069445,"timestamp":"2024-06-01T18:07:19.451299Z"}]}
{"channel":"book","type":"update","data":[{"symbol":"LTC/GBP","bids":[{"price":65.20999,"qty":0.00000000},{"price":65.04259,"qty":0.13071089}],"asks":[],"checksum":1021927718,"timestamp":"2024-06-01T18:07:19.455065Z"}]}
{"channel":"book","type":"update","data":[{"symbol":"LTC/GBP","bids":[{"price":65.21000,"qty":0.00000000},{"price":65.00001,"qty":17.82430478},{"price":65.20996,"qty":15.22083311}],"asks":[],"checksum":2027442075,"timestamp":"2024-06-01T18:07:19.458040Z"}]}
{"channel":"book","type":"update","data":[{"symbol":"LTC/GBP","bids":[{"price":65.22180,"qty":8.68000000}],"asks":[],"checksum":1772781671,"timestamp":"2024-06-01T18:07:19.488836Z"}]}
{"channel":"book","type":"update","data":[{"symbol":"LTC/GBP","bids":[{"price":65.22179,"qty":0.00000000},{"price":65.04259,"qty":0.13071089}],"asks":[],"checksum":1957042810,"timestamp":"2024-06-01T18:07:19.491681Z"}]}
{"channel":"book","type":"update","data":[{"symbol":"LTC/GBP","bids":[{"price":65.22771,"qty":1.30000000}],"asks":[],"checksum":2185602213,"timestamp":"2024-06-01T18:07:19.491751Z"}]}
{"channel":"book","type":"update","data":[{"symbol":"LTC/GBP","bids":[{"price":65.20996,"qty":0.00000000},{"price":65.04259,"qty":0.13071089},{"price":65.25583,"qty":15.21013400}],"asks":[],"checksum":1014169571,"timestamp":"2024-06-01T18:07:19.492097Z"}]}
{"channel":"book","type":"update","data":[{"symbol":"LTC/GBP","bids":[{"price":65.25583,"qty":0.00000000},{"price":65.04259,"qty":0.13071089},{"price":65.25584,"qty":15.21013167}],"asks":[],"checksum":1568095039,"timestamp":"2024-06-01T18:07:19.495576Z"}]}
{"channel":"book","type":"update","data":[{"symbol":"LTC/GBP","bids":[{"price":65.25584,"qty":0.00000000},{"price":65.04259,"qty":0.13071089},{"price":65.25583,"qty":15.21013400}],"asks":[],"checksum":1014169571,"timestamp":"2024-06-01T18:07:19.499362Z"}]}
{"channel":"book","type":"update","data":[{"symbol":"LTC/GBP","bids":[{"price":65.25583,"qty":0.00000000},{"price":65.04259,"qty":0.13071089},{"price":65.25584,"qty":15.21013167}],"asks":[],"checksum":1568095039,"timestamp":"2024-06-01T18:07:19.533160Z"}]}
{"channel":"book","type":"update","data":[{"symbol":"LTC/GBP","bids":[{"price":65.25584,"qty":0.00000000},{"price":65.04259,"qty":0.13071089},{"price":65.25583,"qty":15.21013400}],"asks":[],"checksum":1014169571,"timestamp":"2024-06-01T18:07:19.536568Z"}]}
{"channel":"book","type":"update","data":[{"symbol":"LTC/GBP","bids":[{"price":65.25582,"qty":0.00000000},{"price":65.04259,"qty":0.13071089}],"asks":[],"checksum":2713517866,"timestamp":"2024-06-01T18:07:19.551736Z"}]}
{"channel":"book","type":"update","data":[{"symbol":"LTC/GBP","bids":[{"price":65.25583,"qty":0.00000000},{"price":65.00001,"qty":17.82430478},{"price":65.22772,"qty":15.21668883}],"asks":[],"checksum":1824213459,"timestamp":"2024-06-01T18:07:19.554653Z"}]}
{"channel":"book","type":"update","data":[{"symbol":"LTC/GBP","bids":[{"price":65.22771,"qty":0.00000000},{"price":65.00001,"qty":17.82430478}],"asks":[],"checksum":2037170186,"timestamp":"2024-06-01T18:07:19.557251Z"}]}
{"channel":"book","type":"update","data":[{"symbol":"LTC/GBP","bids":[{"price":65.22926,"qty":1.30000000}],"asks":[],"checksum":2283378847,"timestamp":"2024-06-01T18:07:19.557498Z"}]}
{"channel":"book","type":"update","data":[{"symbol":"LTC/GBP","bids":[],"asks":[{"price":65.67474,"qty":0.00000000},{"price":65.73807,"qty":12.06939088}],"checksum":3954641724,"timestamp":"2024-06-01T18:07:19.557777Z"}]}
{"channel":"book","type":"update","data":[{"symbol":"LTC/GBP","bids":[],"asks":[{"price":65.43111,"qty":0.00000000},{"price":65.85262,"qty":126.80617069}],"checksum":1930634603,"timestamp":"2024-06-01T18:07:19.557803Z"}]}
{"channel":"book","type":"update","data":[{"symbol":"LTC/GBP","bids":[],"asks":[{"price":65.69080,"qty":0.29368398}],"checksum":2541849108,"timestamp":"2024-06-01T18:07:19.559985Z"}]}
{"channel":"book","type":"update","data":[{"symbol":"LTC/GBP","bids":[{"price":65.22772,"qty":0.00000000},{"price":65.00001,"qty":17.82430478},{"price":65.22181,"qty":15.21806768}],"asks":[],"checksum":1427873164,"timestamp":"2024-06-01T18:07:19.560255Z"}]}
{"channel":"book","type":"update","data":[{"symbol":"LTC/GBP","bids":[],"asks":[{"price":65.39335,"qty":9.13893827}],"checksum":941764734,"timestamp":"2024-06-01T18:07:19.560514Z"}]}
{"channel":"book","type":"update","data":[{"symbol":"LTC/GBP","bids":[],"asks":[{"price":65.67473,"qty":17.82430478}],"checksum":3128214160,"timestamp":"2024-06-01T18:07:19.560586Z"}]}
{"channel":"book","type":"update","data":[{"symbol":"LTC/GBP","bids":[{"price":65.22181,"qty":0.00000000},{"price":65.00001,"qty":17.82430478},{"price":65.22927,"qty":15.21632725}],"asks":[],"checksum":2678357019,"timestamp":"2024-06-01T18:07:19.563474Z"}]}
{"channel":"book","type":"update","data":[{"symbol":"LTC/GBP","bids":[{"price":65.22926,"qty":0.00000000},{"price":65.00001,"qty":17.82430478}],"asks":[],"checksum":3621513819,"timestamp":"2024-06-01T18:07:19.566197Z"}]}
{"channel":"book","type":"update","data":[{"symbol":"LTC/GBP","bids":[{"price":65.22937,"qty":1.30000000}],"asks":[],"checksum":1924668517,"timestamp":"2024-06-01T18:07:19.566452Z"}]}
{"channel":"book","type":"update","data":[{"symbol":"LTC/GBP","bids":[{"price":65.22927,"qty":0.00000000},{"price":65.00001,"qty":17.82430478},{"price":65.22181,"qty":15.21806768}],"asks":[],"checksum":588341820,"timestamp":"2024-06-01T18:07:19.569999Z"}]}
{"channel":"book","type":"update","data":[{"symbol":"LTC/GBP","bids":[{"price":65.22180,"qty":0.00000000},{"price":65.00001,"qty":17.82430478},{"price":65.22938,"qty":8.68000000}],"asks":[],"checksum":2415814434,"timestamp":"2024-06-01T18:07:19.583800Z"}]}
{"channel":"book","type":"update","data":[{"symbol":"LTC/GBP","bids":[{"price":65.22181,"qty":0.00000000},{"price":65.00001,"qty":17.82430478},{"price":65.22939,"qty":15.21629926}],"asks":[],"checksum":4288036570,"timestamp":"2024-06-01T18:07:19.688834Z"}]}
{"channel":"book","type":"update","data":[{"symbol":"LTC/GBP","bids":[{"price":65.22937,"qty":0.00000000},{"price":65.00001,"qty":17.82430478}],"asks":[],"checksum":2559711095,"timestamp":"2024-06-01T18:07:19.691387Z"}]}
{"channel":"book","type":"update","data":[{"symbol":"LTC/GBP","bids":[{"price":65.22974,"qty":1.30000000}],"asks":[],"checksum":2998005035,"timestamp":"2024-06-01T18:07:19.691700Z"}]}
{"channel":"book","type":"update","data":[{"symbol":"LTC/GBP","bids":[{"price":65.22938,"qty":0.00000000},{"price":65.00001,"qty":17.82430478},{"price":65.22975,"qty":8.68000000}],"asks":[],"checksum":1376592177,"timestamp":"2024-06-01T18:07:19.708034Z"}]}
{"channel":"book","type":"update","data":[{"symbol":"LTC/GBP","bids":[{"price":65.22976,"qty":1.30000000}],"asks":[],"checksum":2616657449,"timestamp":"2024-06-01T18:07:19.710807Z"}]}
{"channel":"book","type":"update","data":[{"symbol":"LTC/GBP","bids":[{"price":65.22974,"qty":0.00000000},{"price":65.04259,"qty":0.13071089}],"asks":[],"checksum":2904710388,"timestamp":"2024-06-01T18:07:19.710835Z"}]}
{"channel":"book","type":"update","data":[{"symbol":"LTC/GBP","bids":[{"price":65.22939,"qty":0.00000000},{"price":65.00001,"qty":17.82430478},{"price":65.22977,"qty":15.21621064}],"asks":[],"checksum":350033766,"timestamp":"2024-06-01T18:07:19.880967Z"}]}
{"channel":"book","type":"update","data":[{"symbol":"LTC/GBP","bids":[{"price":65.22975,"qty":0.00000000},{"price":65.00001,"qty":17.82430478},{"price":65.22978,"qty":8.68000000}],"asks":[],"checksum":645611282,"timestamp":"2024-06-01T18:07:19.892117Z"}]}
{"channel":"book","type":"update","data":[{"symbol":"LTC/GBP","bids":[{"price":65.22976,"qty":0.00000000},{"price":65.00001,"qty":17.82430478}],"asks":[],"checksum":334271208,"timestamp":"2024-06-01T18:07:19.894881Z"}]}
{"channel":"book","type":"update","data":[{"symbol":"LTC/GBP","bids":[{"price":65.22977,"qty":0.00000000},{"price":65.00000,"qty":7.69231000},{"price":65.22979,"qty":15.21620598}],"asks":[],"checksum":580719509,"timestamp":"2024-06-01T18:07:20.107526Z"}]}
{"channel":"book","type":"update","data":[{"symbol":"LTC/GBP","bids":[{"price":65.22978,"qty":0.00000000},{"price":65.00000,"qty":7.69231000},{"price":65.22980,"qty":8.68000000}],"asks":[],"checksum":3099005830,"timestamp":"2024-06-01T18:07:20.137144Z"}]}
{"channel":"book","type":"update","data":[{"symbol":"LTC/GBP","bids":[{"price":65.22979,"qty":0.00000000},{"price":65.00000,"qty":7.69231000},{"price":65.22981,"qty":15.21620132}],"asks":[],"checksum":117028463,"timestamp":"2024-06-01T18:07:20.367138Z"}]}
{"channel":"book","type":"update","data":[{"symbol":"LTC/GBP","bids":[{"price":65.22980,"qty":0.00000000},{"price":65.00000,"qty":7.69231000},{"price":65.22982,"qty":8.68000000}],"asks":[],"checksum":1507105933,"timestamp":"2024-06-01T18:07:20.382693Z"}]}
{"channel":"book","type":"update","data":[{"symbol":"LTC/GBP","bids":[{"price":65.22981,"qty":0.00000000},{"price":65.00000,"qty":7.69231000},{"price":65.22983,"qty":15.21619666}],"asks":[],"checksum":2817454871,"timestamp":"2024-06-01T18:07:20.660334Z"}]}
{"channel":"book","type":"update","data":[{"symbol":"LTC/GBP","bids":[{"price":65.22982,"qty":0.00000000},{"price":65.00000,"qty":7.69231000},{"price":65.22984,"qty":8.68000000}],"asks":[],"checksum":1600868544,"timestamp":"2024-06-01T18:07:20.689622Z"}]}
{"channel":"book","type":"update","data":[{"symbol":"LTC/GBP","bids":[{"price":65.22983,"qty":0.00000000},{"price":65.00000,"qty":7.69231000},{"price":65.22985,"qty":15.21619200}],"asks":[],"checksum":4082972994,"timestamp":"2024-06-01T18:07:20.910334Z"}]}
{"channel":"book","type":"update","data":[{"symbol":"LTC/GBP","bids":[{"price":65.22984,"qty":0.00000000},{"price":65.00000,"qty":7.69231000},{"price":65.22986,"qty":8.68000000}],"asks":[],"checksum":3115558107,"timestamp":"2024-06-01T18:07:20.930888Z"}]}
{"channel":"book","type":"update","data":[{"symbol":"LTC/GBP","bids":[{"price":65.22985,"qty":0.00000000},{"price":65.00000,"qty":7.69231000},{"price":65.22987,"qty":15.21618734}],"asks":[],"checksum":374771093,"timestamp":"2024-06-01T18:07:21.194069Z"}]}
{"channel":"book","type":"update","data":[{"symbol":"LTC/GBP","bids":[{"price":65.22986,"qty":0.00000000},{"price":65.00000,"qty":7.69231000},{"price":65.22988,"qty":8.68000000}],"asks":[],"checksum":2048408665,"timestamp":"2024-06-01T18:07:21.207216Z"}]}
{"channel":"book","type":"update","data":[{"symbol":"LTC/GBP","bids":[{"price":65.22987,"qty":0.00000000},{"price":65.00000,"qty":7.69231000},{"price":65.22989,"qty":15.21618267}],"asks":[],"checksum":1842982602,"timestamp":"2024-06-01T18:07:21.513994Z"}]}
{"channel":"book","type":"update","data":[{"symbol":"LTC/GBP","bids":[{"price":65.22988,"qty":0.00000000},{"price":65.00000,"qty":7.69231000},{"price":65.22990,"qty":8.68000000}],"asks":[],"checksum":3564919135,"timestamp":"2024-06-01T18:07:21.572653Z"}]}
{"channel":"book","type":"update","data":[{"symbol":"LTC/GBP","bids":[{"price":65.22989,"qty":0.00000000},{"price":65.00000,"qty":7.69231000},{"price":65.22991,"qty":15.21596343}],"asks":[],"checksum":4084672315,"timestamp":"2024-06-01T18:07:21.863572Z"}]}
{"channel":"book","type":"update","data":[{"symbol":"LTC/GBP","bids":[{"price":65.22990,"qty":0.00000000},{"price":65.00000,"qty":7.69231000},{"price":65.22992,"qty":8.68000000}],"asks":[],"checksum":1007725893,"timestamp":"2024-06-01T18:07:21.879879Z"}]}
{"channel":"book","type":"update","data":[{"symbol":"LTC/GBP","bids":[{"price":65.22991,"qty":0.00000000},{"price":65.00000,"qty":7.69231000},{"price":65.22993,"qty":15.21595858}],"asks":[],"checksum":796759950,"timestamp":"2024-06-01T18:07:22.171727Z"}]}
{"channel":"book","type":"update","data":[{"symbol":"LTC/GBP","bids":[{"price":65.22992,"qty":0.00000000},{"price":65.00000,"qty":7.69231000},{"price":65.22994,"qty":8.68000000}],"asks":[],"checksum":3835719066,"timestamp":"2024-06-01T18:07:22.186414Z"}]}
{"channel":"book","type":"update","data":[{"symbol":"LTC/GBP","bids":[{"price":65.22993,"qty":0.00000000},{"price":65.00000,"qty":7.69231000},{"price":65.22995,"qty":15.21595386}],"asks":[],"checksum":2046589612,"timestamp":"2024-06-01T18:07:22.512942Z"}]}
{"channel":"book","type":"update","data":[{"symbol":"LTC/GBP","bids":[{"price":65.22994,"qty":0.00000000},{"price":65.00000,"qty":7.69231000},{"price":65.22996,"qty":8.68000000}],"asks":[],"checksum":2701139012,"timestamp":"2024-06-01T18:07:22.522159Z"}]}
{"channel":"book","type":"update","data":[{"symbol":"LTC/GBP","bids":[{"price":65.22995,"qty":0.00000000},{"price":65.00000,"qty":7.69231000},{"price":65.22997,"qty":15.21594914}],"asks":[],"checksum":1535128701,"timestamp":"2024-06-01T18:07:22.888009Z"}]}
{"channel":"book","type":"update","data":[{"symbol":"LTC/GBP","bids":[{"price":65.22996,"qty":0.00000000},{"price":65.00000,"qty":7.69231000},{"price":65.22998,"qty":8.68000000}],"asks":[],"checksum":1442755134,"timestamp":"2024-06-01T18:07:22.922206Z"}]}
{"channel":"book","type":"update","data":[{"symbol":"LTC/GBP","bids":[{"price":65.22997,"qty":0.00000000},{"price":65.00000,"qty":7.69231000},{"price":65.22999,"qty":15.21594445}],"asks":[],"checksum":2022926667,"timestamp":"2024-06-01T18:07:23.220394Z"}]}
{"channel":"book","type":"update","data":[{"symbol":"LTC/GBP","bids":[{"price":65.22998,"qty":0.00000000},{"price":65.00000,"qty":7.69231000},{"price":65.23000,"qty":8.68000000}],"asks":[],"checksum":3928840970,"timestamp":"2024-06-01T18:07:23.253046Z"}]}
{"channel":"book","type":"update","data":[{"symbol":"LTC/GBP","bids":[{"price":65.22999,"qty":0.00000000},{"price":65.00000,"qty":7.69231000},{"price":65.23001,"qty":15.21593978}],"asks":[],"checksum":1785821602,"timestamp":"2024-06-01T18:07:23.585369Z"}]}
{"channel":"book","type":"update","data":[{"symbol":"LTC/GBP","bids":[],"asks":[{"price":65.31200,"qty":0.00000000},{"price":65.73807,"qty":12.06939088}],"checksum":695168531,"timestamp":"2024-06-01T18:07:23.588541Z"}]}
{"channel":"book","type":"update","data":[{"symbol":"LTC/GBP","bids":[],"asks":[{"price":65.69080,"qty":0.29368398}],"checksum":548032692,"timestamp":"2024-06-01T18:07:23.590706Z"}]}
{"channel":"book","type":"update","data":[{"symbol":"LTC/GBP","bids":[{"price":65.23593,"qty":1.30000000}],"asks":[],"checksum":159214776,"timestamp":"2024-06-01T18:07:23.591226Z"}]}
{"channel":"book","type":"update","data":[{"symbol":"LTC/GBP","bids":[],"asks":[{"price":65.30415,"qty":105.77317608}],"checksum":3940675493,"timestamp":"2024-06-01T18:07:23.591310Z"}]}
{"channel":"book","type":"update","data":[{"symbol":"LTC/GBP","bids":[{"price":65.23593,"qty":0.00000000},{"price":65.00001,"qty":17.82430478}],"asks":[],"checksum":1129292014,"timestamp":"2024-06-01T18:07:23.593904Z"}]}
{"channel":"book","type":"update","data":[{"symbol":"LTC/GBP","bids":[],"asks":[{"price":65.31199,"qty":0.00000000},{"price":65.69080,"qty":0.29368398}],"checksum":1956334399,"timestamp":"2024-06-01T18:07:23.602741Z"}]}
{"channel":"book","type":"update","data":[{"symbol":"LTC/GBP","bids":[],"asks":[{"price":65.33889,"qty":6.00000000}],"checksum":506808035,"timestamp":"2024-06-01T18:07:23.602980Z"}]}
{"channel":"book","type":"update","data":[{"symbol":"LTC/GBP","bids":[{"price":65.23000,"qty":0.00000000},{"price":65.00000,"qty":7.69231000},{"price":65.23002,"qty":8.68000000}],"asks":[],"checksum":3960048868,"timestamp":"2024-06-01T18:07:23.620887Z"}]}
{"channel":"book","type":"update","data":[{"symbol":"LTC/GBP","bids":[],"asks":[{"price":65.30414,"qty":6.00000000}],"checksum":3415164837,"timestamp":"2024-06-01T18:07:23.728963Z"}]}
{"channel":"book","type":"update","data":[{"symbol":"LTC/GBP","bids":[],"asks":[{"price":65.33889,"qty":0.00000000},{"price":65.67494,"qty":17.82430478}],"checksum":180416584,"timestamp":"2024-06-01T18:07:23.734019Z"}]}
{"channel":"book","type":"update","data":[{"symbol":"LTC/GBP","bids":[{"price":65.23001,"qty":0.00000000},{"price":65.00000,"qty":7.69231000},{"price":65.23003,"qty":15.21554523}],"asks":[],"checksum":808994110,"timestamp":"2024-06-01T18:07:23.984161Z"}]}
{"channel":"book","type":"update","data":[{"symbol":"LTC/GBP","bids":[{"price":65.23002,"qty":0.00000000},{"price":65.00000,"qty":7.69231000},{"price":65.23004,"qty":8.68000000}],"asks":[],"checksum":2492620077,"timestamp":"2024-06-01T18:07:24.019903Z"}]}
{"channel":"book","type":"update","data":[{"symbol":"LTC/GBP","bids":[{"price":65.23003,"qty":0.00000000},{"price":65.00000,"qty":7.69231000},{"price":65.23005,"qty":15.21554070}],"asks":[],"checksum":4142477977,"timestamp":"2024-06-01T18:07:24.339809Z"}]}
{"channel":"book","type":"update","data":[{"symbol":"LTC/GBP","bids":[{"price":65.23004,"qty":0.00000000},{"price":65.00000,"qty":7.69231000},{"price":65.23006,"qty":8.68000000}],"asks":[],"checksum":4253504787,"timestamp":"2024-06-01T18:07:24.350165Z"}]}
{"channel":"book","type":"update","data":[{"symbol":"LTC/GBP","bids":[{"price":65.23005,"qty":0.00000000},{"price":65.00000,"qty":7.69231000},{"price":65.23007,"qty":15.21553610}],"asks":[],"checksum":727781189,"timestamp":"2024-06-01T18:07:24.729303Z"}]}
{"channel":"book","type":"update","data":[{"symbol":"LTC/GBP","bids":[{"price":65.23006,"qty":0.00000000},{"price":65.00000,"qty":7.69231000},{"price":65.23008,"qty":8.68000000}],"asks":[],"checksum":4195960474,"timestamp":"2024-06-01T18:07:24.746488Z"}]}
{"channel":"book","type":"update","data":[{"symbol":"LTC/GBP","bids":[{"price":65.23007,"qty":0.00000000},{"price":65.00000,"qty":7.69231000},{"price":65.23009,"qty":15.21553146}],"asks":[],"checksum":1805037806,"timestamp":"2024-06-01T18:07:25.152259Z"}]}
{"channel":"book","type":"update","data":[{"symbol":"LTC/GBP","bids":[{"price":65.23008,"qty":0.00000000},{"price":65.00000,"qty":7.69231000},{"price":65.23010,"qty":8.68000000}],"asks":[],"checksum":682123232,"timestamp":"2024-06-01T18:07:25.173318Z"}]}
{"channel":"book","type":"update","data":[{"symbol":"LTC/GBP","bids":[{"price":65.23009,"qty":0.00000000},{"price":65.00000,"qty":7.69231000},{"price":65.23011,"qty":15.21552681}],"asks":[],"checksum":1154037827,"timestamp":"2024-06-01T18:07:25.532516Z"}]}
{"channel":"book","type":"update","data":[{"symbol":"LTC/GBP","bids":[{"price":65.23010,"qty":0.00000000},{"price":65.00000,"qty":7.69231000},{"price":65.23012,"qty":8.68000000}],"asks":[],"checksum":3534420866,"timestamp":"2024-06-01T18:07:25.570331Z"}]}
{"channel":"book","type":"update","data":[{"symbol":"LTC/GBP","bids":[{"price":65.23011,"qty":0.00000000},{"price":65.00000,"qty":7.69231000},{"price":65.23013,"qty":15.21611906}],"asks":[],"checksum":3173102042,"timestamp":"2024-06-01T18:07:25.945876Z"}]}
{"channel":"book","type":"update","data":[{"symbol":"LTC/GBP","bids":[{"price":65.23012,"qty":0.00000000},{"price":65.00000,"qty":7.69231000},{"price":65.23014,"qty":8.68000000}],"asks":[],"checksum":591579357,"timestamp":"2024-06-01T18:07:25.967110Z"}]}
{"channel":"book","type":"update","data":[{"symbol":"LTC/GBP","bids":[{"price":65.23013,"qty":0.00000000},{"price":65.00000,"qty":7.69231000},{"price":65.23015,"qty":15.21611425}],"asks":[],"checksum":3046320538,"timestamp":"2024-06-01T18:07:26.316272Z"}]}
{"channel":"book","type":"update","data":[{"symbol":"LTC/GBP","bids":[{"price":65.23014,"qty":0.00000000},{"price":65.00000,"qty":7.69231000},{"price":65.23016,"qty":8.68000000}],"asks":[],"checksum":2792565261,"timestamp":"2024-06-01T18:07:26.337004Z"}]}
{"channel":"book","type":"update","data":[{"symbol":"LTC/GBP","bids":[{"price":65.23015,"qty":0.00000000},{"price":65.00000,"qty":7.69231000},{"price":65.23017,"qty":15.21610952}],"asks":[],"checksum":947136326,"timestamp":"2024-06-01T18:07:26.719953Z"}]}
{"channel":"book","type":"update","data":[{"symbol":"LTC/GBP","bids":[{"price":65.23016,"qty":0.00000000},{"price":65.00000,"qty":7.69231000},{"price":65.23018,"qty":8.68000000}],"asks":[],"checksum":671959411,"timestamp":"2024-06-01T18:07:26.731636Z"}]}
{"channel":"book","type":"update","data":[{"symbol":"LTC/GBP","bids":[{"price":65.23017,"qty":0.00000000},{"price":65.00000,"qty":7.69231000},{"price":65.23019,"qty":15.21610482}],"asks":[],"checksum":3975175962,"timestamp":"2024-06-01T18:07:27.157580Z"}]}
{"channel":"book","type":"update","data":[{"symbol":"LTC/GBP","bids":[{"price":65.23018,"qty":0.00000000},{"price":65.00000,"qty":7.69231000},{"price":65.23020,"qty":8.68000000}],"asks":[],"checksum":1017597457,"timestamp":"2024-06-01T18:07:27.189370Z"}]}
{"channel":"book","type":"update","data":[{"symbol":"LTC/GBP","bids":[{"price":65.09502,"qty":6.01378699}],"asks":[],"checksum":3013753681,"timestamp":"2024-06-01T18:07:27.449438Z"}]}
{"channel":"book","type":"update","data":[{"symbol":"LTC/GBP","bids":[{"price":65.09501,"qty":6.01117861}],"asks":[],"checksum":2502864260,"timestamp":"2024-06-01T18:07:27.458689Z"}]}
{"channel":"book","type":"update","data":[{"symbol":"LTC/GBP","bids":[{"price":65.09503,"qty":6.44640765}],"asks":[],"checksum":2583754287,"timestamp":"2024-06-01T18:07:27.458855Z"}]}
{"channel":"book","type":"update","data":[{"symbol":"LTC/GBP","bids":[{"price":65.09504,"qty":6.01378293}],"asks":[],"checksum":1016277518,"timestamp":"2024-06-01T18:07:27.462787Z"}]}
{"channel":"book","type":"update","data":[{"symbol":"LTC/GBP","bids":[{"price":65.09502,"qty":0.00000000},{"price":65.08662,"qty":55.11221680}],"asks":[],"checksum":3489461547,"timestamp":"2024-06-01T18:07:27.462872Z"}]}
{"channel":"book","type":"update","data":[{"symbol":"LTC/GBP","bids":[{"price":65.23019,"qty":0.00000000},{"price":65.04259,"qty":0.13071089},{"price":65.23021,"qty":15.21610014}],"asks":[],"checksum":2688095480,"timestamp":"2024-06-01T18:07:27.551890Z"}]}
{"channel":"book","type":"update","data":[{"symbol":"LTC/GBP","bids":[{"price":65.23020,"qty":0.00000000},{"price":65.04259,"qty":0.13071089},{"price":65.23022,"qty":8.68000000}],"asks":[],"checksum":2153973425,"timestamp":"2024-06-01T18:07:27.586752Z"}]}
{"channel":"book","type":"update","data":[{"symbol":"LTC/GBP","bids":[{"price":65.23021,"qty":0.00000000},{"price":65.04259,"qty":0.13071089},{"price":65.23023,"qty":15.21581917}],"asks":[],"checksum":2408421985,"timestamp":"2024-06-01T18:07:27.980199Z"}]}
{"channel":"book","type":"update","data":[{"symbol":"LTC/GBP","bids":[{"price":65.23022,"qty":0.00000000},{"price":65.04259,"qty":0.13071089},{"price":65.23024,"qty":8.68000000}],"asks":[],"checksum":2360770750,"timestamp":"2024-06-01T18:07:28.015364Z"}]}
{"channel":"book","type":"update","data":[{"symbol":"LTC/GBP","bids":[{"price":65.23023,"qty":0.00000000},{"price":65.04259,"qty":0.13071089},{"price":65.23025,"qty":15.21581478}],"asks":[],"checksum":3159618026,"timestamp":"2024-06-01T18:07:28.364896Z"}]}
{"channel":"book","type":"update","data":[{"symbol":"LTC/GBP","bids":[{"price":65.23024,"qty":0.00000000},{"price":65.04259,"qty":0.13071089},{"price":65.23026,"qty":8.68000000}],"asks":[],"checksum":128247402,"timestamp":"2024-06-01T18:07:28.382625Z"}]}
{"channel":"book","type":"update","data":[{"symbol":"LTC/GBP","bids":[{"price":65.23025,"qty":0.00000000},{"price":65.04259,"qty":0.13071089},{"price":65.23027,"qty":15.21581020}],"asks":[],"checksum":3126852072,"timestamp":"2024-06-01T18:07:28.782626Z"}]}
{"channel":"book","type":"update","data":[{"symbol":"LTC/GBP","bids":[{"price":65.23026,"qty":0.00000000},{"price":65.04259,"qty":0.13071089},{"price":65.23028,"qty":8.68000000}],"asks":[],"checksum":1650515257,"timestamp":"2024-06-01T18:07:28.808421Z"}]}
{"channel":"book","type":"update","data":[{"symbol":"LTC/GBP","bids":[{"price":65.23027,"qty":0.00000000},{"price":65.04259,"qty":0.13071089},{"price":65.23029,"qty":15.21580558}],"asks":[],"checksum":442217323,"timestamp":"2024-06-01T18:07:29.234704Z"}]}
{"channel":"book","type":"update","data":[{"symbol":"LTC/GBP","bids":[{"price":65.23028,"qty":0.00000000},{"price":65.04259,"qty":0.13071089},{"price":65.23030,"qty":8.68000000}],"asks":[],"checksum":3512561804,"timestamp":"2024-06-01T18:07:29.266729Z"}]}
{"channel":"book","type":"update","data":[{"symbol":"LTC/GBP","bids":[],"asks":[{"price":65.30414,"qty":3.75934766}],"checksum":176382220,"timestamp":"2024-06-01T18:07:29.504492Z"}]}
{"channel":"book","type":"update","data":[{"symbol":"LTC/GBP","bids":[{"price":65.23029,"qty":0.00000000},{"price":65.04259,"qty":0.13071089},{"price":65.23031,"qty":15.21563789}],"asks":[],"checksum":3969326021,"timestamp":"2024-06-01T18:07:29.643822Z"}]}
{"channel":"book","type":"update","data":[{"symbol":"LTC/GBP","bids":[{"price":65.23030,"qty":0.00000000},{"price":65.04259,"qty":0.13071089},{"price":65.23032,"qty":8.68000000}],"asks":[],"checksum":858222409,"timestamp":"2024-06-01T18:07:29.663659Z"}]}
{"channel":"book","type":"update","data":[{"symbol":"LTC/GBP","bids":[{"price":65.23031,"qty":0.00000000},{"price":65.04259,"qty":0.13071089},{"price":65.23033,"qty":15.21563327}],"asks":[],"checksum":3728558149,"timestamp":"2024-06-01T18:07:30.085621Z"}]}
{"channel":"book","type":"update","data":[{"symbol":"LTC/GBP","bids":[{"price":65.23032,"qty":0.00000000},{"price":65.04259,"qty":0.13071089},{"price":65.23034,"qty":8.68000000}],"asks":[],"checksum":214951408,"timestamp":"2024-06-01T18:07:30.123427Z"}]}
{"channel":"book","type":"update","data":[{"symbol":"LTC/GBP","bids":[{"price":65.23033,"qty":0.00000000},{"price":65.04259,"qty":0.13071089},{"price":65.23035,"qty":15.21562863}],"asks":[],"checksum":270297091,"timestamp":"2024-06-01T18:07:30.484301Z"}]}
{"channel":"book","type":"update","data":[{"symbol":"LTC/GBP","bids":[{"price":65.23034,"qty":0.00000000},{"price":65.04259,"qty":0.13071089},{"price":65.23036,"qty":8.68000000}],"asks":[],"checksum":3444726845,"timestamp":"2024-06-01T18:07:30.518817Z"}]}
{"channel":"book","type":"update","data":[{"symbol":"LTC/GBP","bids":[{"price":65.23035,"qty":0.00000000},{"price":65.04259,"qty":0.13071089},{"price":65.23037,"qty":15.21562397}],"asks":[],"checksum":3650620098,"timestamp":"2024-06-01T18:07:30.917405Z"}]}
{"channel":"book","type":"update","data":[{"symbol":"LTC/GBP","bids":[{"price":65.23036,"qty":0.00000000},{"price":65.04259,"qty":0.13071089},{"price":65.23038,"qty":8.68000000}],"asks":[],"checksum":1100295265,"timestamp":"2024-06-01T18:07:30.997056Z"}]}
{"channel":"book","type":"update","data":[{"symbol":"LTC/GBP","bids":[{"price":65.23037,"qty":0.00000000},{"price":65.04259,"qty":0.13071089},{"price":65.23039,"qty":15.21561931}],"asks":[],"checksum":431965839,"timestamp":"2024-06-01T18:07:31.383679Z"}]}
{"channel":"book","type":"update","data":[{"symbol":"LTC/GBP","bids":[{"price":65.23038,"qty":0.00000000},{"price":65.04259,"qty":0.13071089},{"price":65.23040,"qty":8.68000000}],"asks":[],"checksum":1197021472,"timestamp":"2024-06-01T18:07:31.427063Z"}]}
{"channel":"book","type":"update","data":[{"symbol":"LTC/GBP","bids":[{"price":65.23039,"qty":0.00000000},{"price":65.04259,"qty":0.13071089},{"price":65.23041,"qty":15.21615268}],"asks":[],"checksum":571878563,"timestamp":"2024-06-01T18:07:31.806134Z"}]}
{"channel":"book","type":"update","data":[{"symbol":"LTC/GBP","bids":[{"price":65.23040,"qty":0.00000000},{"price":65.04259,"qty":0.13071089},{"price":65.23042,"qty":8.68000000}],"asks":[],"checksum":2849560061,"timestamp":"2024-06-01T18:07:31.826314Z"}]}
{"channel":"book","type":"update","data":[{"symbol":"LTC/GBP","bids":[{"price":65.23041,"qty":0.00000000},{"price":65.04259,"qty":0.13071089},{"price":65.23043,"qty":15.21614814}],"asks":[],"checksum":77044344,"timestamp":"2024-06-01T18:07:32.263570Z"}]}
{"channel":"book","type":"update","data":[{"symbol":"LTC/GBP","bids":[{"price":65.23042,"qty":0.00000000},{"price":65.04259,"qty":0.13071089},{"price":65.23044,"qty":8.68000000}],"asks":[],"checksum":88946155,"timestamp":"2024-06-01T18:07:32.283411Z"}]}
{"channel":"book","type":"update","data":[{"symbol":"LTC/GBP","bids":[{"price":65.23043,"qty":0.00000000},{"price":65.04259,"qty":0.13071089},{"price":65.23045,"qty":15.21614349}],"asks":[],"checksum":2998637844,"timestamp":"2024-06-01T18:07:32.676798Z"}]}
{"channel":"book","type":"update","data":[{"symbol":"LTC/GBP","bids":[{"price":65.23044,"qty":0.00000000},{"price":65.04259,"qty":0.13071089},{"price":65.23046,"qty":8.68000000}],"asks":[],"checksum":2156175445,"timestamp":"2024-06-01T18:07:32.711137Z"}]}
{"channel":"book","type":"update","data":[{"symbol":"LTC/GBP","bids":[{"price":65.23045,"qty":0.00000000},{"price":65.04259,"qty":0.13071089},{"price":65.23047,"qty":15.21613883}],"asks":[],"checksum":1253765267,"timestamp":"2024-06-01T18:07:33.123765Z"}]}
{"channel":"book","type":"update","data":[{"symbol":"LTC/GBP","bids":[{"price":65.23046,"qty":0.00000000},{"price":65.04259,"qty":0.13071089},{"price":65.23048,"qty":8.68000000}],"asks":[],"checksum":888033793,"timestamp":"2024-06-01T18:07:33.139081Z"}]}
{"channel":"book","type":"update","data":[{"symbol":"LTC/GBP","bids":[{"price":65.23047,"qty":0.00000000},{"price":65.04259,"qty":0.13071089},{"price":65.23049,"qty":15.21613417}],"asks":[],"checksum":2542535037,"timestamp":"2024-06-01T18:07:33.604219Z"}]}
{"channel":"book","type":"update","data":[{"symbol":"LTC/GBP","bids":[{"price":65.23048,"qty":0.00000000},{"price":65.04259,"qty":0.13071089},{"price":65.23050,"qty":8.68000000}],"asks":[],"checksum":4137391080,"timestamp":"2024-06-01T18:07:33.627228Z"}]}
{"channel":"book","type":"update","data":[{"symbol":"LTC/GBP","bids":[{"price":65.23049,"qty":0.00000000},{"price":65.04259,"qty":0.13071089},{"price":65.23051,"qty":15.21587122}],"asks":[],"checksum":3313595339,"timestamp":"2024-06-01T18:07:34.042316Z"}]}
{"channel":"book","type":"update","data":[{"symbol":"LTC/GBP","bids":[{"price":65.23050,"qty":0.00000000},{"price":65.04259,"qty":0.13071089},{"price":65.23052,"qty":8.68000000}],"asks":[],"checksum":742021943,"timestamp":"2024-06-01T18:07:34.053154Z"}]}
{"channel":"book","type":"update","data":[{"symbol":"LTC/GBP","bids":[{"price":65.23051,"qty":0.00000000},{"price":65.04259,"qty":0.13071089},{"price":65.23053,"qty":15.21586654}],"asks":[],"checksum":1536513182,"timestamp":"2024-06-01T18:07:34.512214Z"}]}
{"channel":"book","type":"update","data":[{"symbol":"LTC/GBP","bids":[{"price":65.23052,"qty":0.00000000},{"price":65.04259,"qty":0.13071089},{"price":65.23054,"qty":8.68000000}],"asks":[],"checksum":1611788627,"timestamp":"2024-06-01T18:07:34.544884Z"}]}
{"channel":"book","type":"update","data":[{"symbol":"LTC/GBP","bids":[{"price":65.23053,"qty":0.00000000},{"price":65.04259,"qty":0.13071089},{"price":65.23055,"qty":15.21586186}],"asks":[],"checksum":1377314380,"timestamp":"2024-06-01T18:07:34.939819Z"}]}
{"channel":"book","type":"update","data":[{"symbol":"LTC/GBP","bids":[{"price":65.23054,"qty":0.00000000},{"price":65.04259,"qty":0.13071089},{"price":65.23056,"qty":8.68000000}],"asks":[],"checksum":2002953841,"timestamp":"2024-06-01T18:07:34.967140Z"}]}
{"channel":"book","type":"update","data":[{"symbol":"LTC/GBP","bids":[{"price":65.23055,"qty":0.00000000},{"price":65.04259,"qty":0.13071089},{"price":65.23057,"qty":15.21585719}],"asks":[],"checksum":2608156316,"timestamp":"2024-06-01T18:07:35.401493Z"}]}
{"channel":"book","type":"update","data":[{"symbol":"LTC/GBP","bids":[{"price":65.23056,"qty":0.00000000},{"price":65.04259,"qty":0.13071089},{"price":65.23058,"qty":8.68000000}],"asks":[],"checksum":2023176330,"timestamp":"2024-06-01T18:07:35.425294Z"}]}
{"channel":"book","type":"update","data":[{"symbol":"LTC/GBP","bids":[{"price":65.23057,"qty":0.00000000},{"price":65.04259,"qty":0.13071089},{"price":65.23059,"qty":15.21573808}],"asks":[],"checksum":3832368806,"timestamp":"2024-06-01T18:07:35.819856Z"}]}
{"channel":"book","type":"update","data":[{"symbol":"LTC/GBP","bids":[{"price":65.23058,"qty":0.00000000},{"price":65.04259,"qty":0.13071089},{"price":65.23060,"qty":8.68000000}],"asks":[],"checksum":3850832916,"timestamp":"2024-06-01T18:07:35.852781Z"}]}
{"channel":"book","type":"update","data":[{"symbol":"LTC/GBP","bids":[{"price":65.23059,"qty":0.00000000},{"price":65.04259,"qty":0.13071089},{"price":65.23061,"qty":15.21573385}],"asks":[],"checksum":2193287486,"timestamp":"2024-06-01T18:07:36.271494Z"}]}
{"channel":"book","type":"update","data":[{"symbol":"LTC/GBP","bids":[{"price":65.23060,"qty":0.00000000},{"price":65.04259,"qty":0.13071089},{"price":65.23062,"qty":8.68000000}],"asks":[],"checksum":1857258591,"timestamp":"2024-06-01T18:07:36.308616Z"}]}
{"channel":"book","type":"update","data":[{"symbol":"LTC/GBP","bids":[{"price":65.23061,"qty":0.00000000},{"price":65.04259,"qty":0.13071089},{"price":65.23063,"qty":15.21572939}],"asks":[],"checksum":2490557342,"timestamp":"2024-06-01T18:07:36.756790Z"}]}
{"channel":"book","type":"update","data":[{"symbol":"LTC/GBP","bids":[{"price":65.23062,"qty":0.00000000},{"price":65.04259,"qty":0.13071089},{"price":65.23064,"qty":8.68000000}],"asks":[],"checksum":2970310218,"timestamp":"2024-06-01T18:07:36.765744Z"}]}
{"channel":"book","type":"update","data":[{"symbol":"LTC/GBP","bids":[{"price":65.09504,"qty":0.00000000},{"price":65.04259,"qty":0.13071089}],"asks":[],"checksum":3236758240,"timestamp":"2024-06-01T18:07:37.162939Z"}]}
{"channel":"book","type":"update","data":[{"symbol":"LTC/GBP","bids":[{"price":65.23063,"qty":0.00000000},{"price":65.00001,"qty":17.82430478},{"price":65.23065,"qty":15.21572484}],"asks":[],"checksum":3825258834,"timestamp":"2024-06-01T18:07:37.199356Z"}]}
{"channel":"book","type":"update","data":[{"symbol":"LTC/GBP","bids":[{"price":65.23064,"qty":0.00000000},{"price":65.00001,"qty":17.82430478},{"price":65.23066,"qty":8.68000000}],"asks":[],"checksum":2357968138,"timestamp":"2024-06-01T18:07:37.224315Z"}]}
{"channel":"book","type":"update","data":[{"symbol":"LTC/GBP","bids":[{"price":65.09504,"qty":6.01356560}],"asks":[],"checksum":1312710656,"timestamp":"2024-06-01T18:07:37.228912Z"}]}
{"channel":"book","type":"update","data":[{"symbol":"LTC/GBP","bids":[{"price":65.23065,"qty":0.00000000},{"price":65.04259,"qty":0.13071089},{"price":65.23067,"qty":15.21533781}],"asks":[],"checksum":3738771572,"timestamp":"2024-06-01T18:07:37.675748Z"}]}
{"channel":"book","type":"update","data":[{"symbol":"LTC/GBP","bids":[{"price":65.23066,"qty":0.00000000},{"price":65.04259,"qty":0.13071089},{"price":65.23068,"qty":8.68000000}],"asks":[],"checksum":646365212,"timestamp":"2024-06-01T18:07:37.711347Z"}]}
{"channel":"book","type":"update","data":[{"symbol":"LTC/GBP","bids":[{"price":65.09504,"qty":0.00000000},{"price":65.04259,"qty":0.13071089}],"asks":[],"checksum":3919075800,"timestamp":"2024-06-01T18:07:38.032292Z"}]}
{"channel":"book","type":"update","data":[{"symbol":"LTC/GBP","bids":[{"price":65.23067,"qty":0.00000000},{"price":65.00001,"qty":17.82430478},{"price":65.23069,"qty":16.05836993}],"asks":[],"checksum":3268165946,"timestamp":"2024-06-01T18:07:38.109085Z"}]}
{"channel":"book","type":"update","data":[{"symbol":"LTC/GBP","bids":[{"price":65.23068,"qty":0.00000000},{"price":65.00001,"qty":17.82430478},{"price":65.23070,"qty":8.68000000}],"asks":[],"checksum":225618477,"timestamp":"2024-06-01T18:07:38.139132Z"}]}
{"channel":"book","type":"update","data":[{"symbol":"LTC/GBP","bids":[{"price":65.09504,"qty":6.01356641}],"asks":[],"checksum":1162861727,"timestamp":"2024-06-01T18:07:38.210463Z"}]}
{"channel":"book","type":"update","data":[{"symbol":"LTC/GBP","bids":[{"price":65.23069,"qty":0.00000000},{"price":65.04259,"qty":0.13071089},{"price":65.23071,"qty":16.05836500}],"asks":[],"checksum":57557527,"timestamp":"2024-06-01T18:07:38.575123Z"}]}
{"channel":"book","type":"update","data":[{"symbol":"LTC/GBP","bids":[{"price":65.23070,"qty":0.00000000},{"price":65.04259,"qty":0.13071089},{"price":65.23072,"qty":8.68000000}],"asks":[],"checksum":2041252137,"timestamp":"2024-06-01T18:07:38.596704Z"}]}
{"channel":"book","type":"update","data":[{"symbol":"LTC/GBP","bids":[],"asks":[{"price":65.30415,"qty":0.00000000},{"price":65.73807,"qty":12.06939088}],"checksum":1525292216,"timestamp":"2024-06-01T18:07:38.599645Z"}]}
