{"channel":"book","type":"snapshot","data":[{"symbol":"LTC/EUR","bids":[{"price":76.71,"qty":60.08992023},{"price":76.70,"qty":65.90307421},{"price":76.69,"qty":2.42781769},{"price":76.68,"qty":271.50335643},{"price":76.67,"qty":114.87020000},{"price":76.66,"qty":60.01000000},{"price":76.65,"qty":66.13665032},{"price":76.64,"qty":7.43180730},{"price":76.63,"qty":387.20841007},{"price":76.62,"qty":37.82190367}],"asks":[{"price":76.74,"qty":60.07228383},{"price":76.75,"qty":79.92424153},{"price":76.76,"qty":116.59066325},{"price":76.78,"qty":132.74185107},{"price":76.79,"qty":7.99500000},{"price":76.80,"qty":11.54968817},{"price":76.83,"qty":108.10947680},{"price":76.84,"qty":113.24216904},{"price":76.85,"qty":0.15250789},{"price":76.86,"qty":32.86737436}],"checksum":2925654428}]}
{"channel":"book","type":"update","data":[{"symbol":"LTC/EUR","bids":[{"price":76.64,"qty":0.00000000},{"price":76.61,"qty":59.02700000}],"asks":[],"checksum":2673547490,"timestamp":"2024-06-01T18:07:15.024718Z"}]}
{"channel":"book","type":"update","data":[{"symbol":"LTC/EUR","bids":[{"price":76.64,"qty":8.17498803}],"asks":[],"checksum":3670032702,"timestamp":"2024-06-01T18:07:15.030228Z"}]}
{"channel":"book","type":"update","data":[{"symbol":"LTC/EUR","bids":[{"price":76.71,"qty":59.95002023}],"asks":[],"checksum":1023033244,"timestamp":"2024-06-01T18:07:15.246892Z"}]}
{"channel":"book","type":"update","data":[{"symbol":"LTC/EUR","bids":[{"price":76.64,"qty":0.00000000},{"price":76.61,"qty":59.02700000}],"asks":[],"checksum":2808471640,"timestamp":"2024-06-01T18:07:17.444696Z"}]}
{"channel":"book","type":"update","data":[{"symbol":"LTC/EUR","bids":[{"price":76.64,"qty":6.47649390}],"asks":[],"checksum":3536654579,"timestamp":"2024-06-01T18:07:17.449348Z"}]}
{"channel":"book","type":"update","data":[{"symbol":"LTC/EUR","bids":[{"price":76.68,"qty":203.86335643}],"asks":[],"checksum":3168713683,"timestamp":"2024-06-01T18:07:18.866303Z"}]}
{"channel":"book","type":"update","data":[{"symbol":"LTC/EUR","bids":[{"price":76.68,"qty":197.81216105}],"asks":[],"checksum":3768471162,"timestamp":"2024-06-01T18:07:18.886554Z"}]}
{"channel":"book","type":"update","data":[{"symbol":"LTC/EUR","bids":[{"price":76.67,"qty":182.51020000}],"asks":[],"checksum":2852258272,"timestamp":"2024-06-01T18:07:19.002065Z"}]}
{"channel":"book","type":"update","data":[{"symbol":"LTC/EUR","bids":[{"price":76.70,"qty":5.80000000}],"asks":[],"checksum":1517670636,"timestamp":"2024-06-01T18:07:19.003366Z"}]}
{"channel":"book","type":"update","data":[{"symbol":"LTC/EUR","bids":[{"price":76.66,"qty":0.00000000},{"price":76.61,"qty":59.02700000}],"asks":[],"checksum":23595133,"timestamp":"2024-06-01T18:07:19.004706Z"}]}
{"channel":"book","type":"update","data":[{"symbol":"LTC/EUR","bids":[],"asks":[{"price":76.74,"qty":74.34043124}],"checksum":2128397034,"timestamp":"2024-06-01T18:07:19.004997Z"}]}
{"channel":"book","type":"update","data":[{"symbol":"LTC/EUR","bids":[{"price":76.65,"qty":6.00100000}],"asks":[],"checksum":1947162783,"timestamp":"2024-06-01T18:07:19.005718Z"}]}
{"channel":"book","type":"update","data":[{"symbol":"LTC/EUR","bids":[],"asks":[{"price":76.83,"qty":48.04947680},{"price":76.78,"qty":192.80185107}],"checksum":3995324247,"timestamp":"2024-06-01T18:07:19.006254Z"}]}
{"channel":"book","type":"update","data":[{"symbol":"LTC/EUR","bids":[{"price":76.68,"qty":203.86335643}],"asks":[],"checksum":498885356,"timestamp":"2024-06-01T18:07:19.008203Z"}]}
{"channel":"book","type":"update","data":[{"symbol":"LTC/EUR","bids":[{"price":76.65,"qty":66.07100000}],"asks":[],"checksum":2066536623,"timestamp":"2024-06-01T18:07:19.008820Z"}]}
{"channel":"book","type":"update","data":[{"symbol":"LTC/EUR","bids":[{"price":76.62,"qty":97.98262076}],"asks":[],"checksum":200271279,"timestamp":"2024-06-01T18:07:19.010072Z"}]}
{"channel":"book","type":"update","data":[{"symbol":"LTC/EUR","bids":[{"price":76.67,"qty":242.63511346}],"asks":[],"checksum":3970842198,"timestamp":"2024-06-01T18:07:19.010144Z"}]}
{"channel":"book","type":"update","data":[{"symbol":"LTC/EUR","bids":[{"price":76.71,"qty":0.00000000},{"price":76.60,"qty":332.38400000}],"asks":[],"checksum":1360464866,"timestamp":"2024-06-01T18:07:19.014480Z"}]}
{"channel":"book","type":"update","data":[{"symbol":"LTC/EUR","bids":[{"price":76.70,"qty":65.89870874}],"asks":[],"checksum":1327888486,"timestamp":"2024-06-01T18:07:19.019509Z"}]}
{"channel":"book","type":"update","data":[{"symbol":"LTC/EUR","bids":[],"asks":[{"price":76.75,"qty":103.77730665}],"checksum":2865947784,"timestamp":"2024-06-01T18:07:19.022109Z"}]}
{"channel":"book","type":"update","data":[{"symbol":"LTC/EUR","bids":[{"price":76.68,"qty":197.81216105}],"asks":[],"checksum":1939966254,"timestamp":"2024-06-01T18:07:19.031097Z"}]}
{"channel":"book","type":"update","data":[{"symbol":"LTC/EUR","bids":[{"price":76.67,"qty":256.32717891}],"asks":[],"checksum":465686038,"timestamp":"2024-06-01T18:07:19.038849Z"}]}
{"channel":"book","type":"update","data":[{"symbol":"LTC/EUR","bids":[],"asks":[{"price":76.76,"qty":92.73759813}],"checksum":1106448394,"timestamp":"2024-06-01T18:07:19.042949Z"}]}
{"channel":"book","type":"update","data":[{"symbol":"LTC/EUR","bids":[],"asks":[{"price":76.74,"qty":79.34043124}],"checksum":1786056640,"timestamp":"2024-06-01T18:07:19.117965Z"}]}
{"channel":"book","type":"update","data":[{"symbol":"LTC/EUR","bids":[{"price":76.66,"qty":6.05277409}],"asks":[],"checksum":1101172491,"timestamp":"2024-06-01T18:07:19.158079Z"}]}
{"channel":"book","type":"update","data":[{"symbol":"LTC/EUR","bids":[{"price":76.61,"qty":35.00000000}],"asks":[],"checksum":538062281,"timestamp":"2024-06-01T18:07:19.179839Z"}]}
{"channel":"book","type":"update","data":[{"symbol":"LTC/EUR","bids":[{"price":76.68,"qty":193.27279401}],"asks":[],"checksum":331189479,"timestamp":"2024-06-01T18:07:19.204921Z"}]}
{"channel":"book","type":"update","data":[{"symbol":"LTC/EUR","bids":[{"price":76.67,"qty":260.70213311}],"asks":[],"checksum":4172592868,"timestamp":"2024-06-01T18:07:19.209453Z"}]}
{"channel":"book","type":"update","data":[{"symbol":"LTC/EUR","bids":[{"price":76.67,"qty":247.01006766}],"asks":[],"checksum":1693360277,"timestamp":"2024-06-01T18:07:19.210093Z"}]}
{"channel":"book","type":"update","data":[{"symbol":"LTC/EUR","bids":[],"asks":[{"price":76.74,"qty":93.03249669}],"checksum":3120079718,"timestamp":"2024-06-01T18:07:19.210233Z"}]}
{"channel":"book","type":"update","data":[{"symbol":"LTC/EUR","bids":[{"price":76.67,"qty":216.71006766}],"asks":[],"checksum":1215884398,"timestamp":"2024-06-01T18:07:19.210778Z"}]}
{"channel":"book","type":"update","data":[{"symbol":"LTC/EUR","bids":[{"price":76.66,"qty":36.35277409}],"asks":[],"checksum":3010936073,"timestamp":"2024-06-01T18:07:19.210929Z"}]}
{"channel":"book","type":"update","data":[{"symbol":"LTC/EUR","bids":[],"asks":[{"price":76.75,"qty":134.07730665}],"checksum":891811853,"timestamp":"2024-06-01T18:07:19.210970Z"}]}
{"channel":"book","type":"update","data":[{"symbol":"LTC/EUR","bids":[],"asks":[{"price":76.75,"qty":120.38524120}],"checksum":3355998398,"timestamp":"2024-06-01T18:07:19.231464Z"}]}
{"channel":"book","type":"update","data":[{"symbol":"LTC/EUR","bids":[{"price":76.66,"qty":30.30000000}],"asks":[],"checksum":2311896273,"timestamp":"2024-06-01T18:07:19.231587Z"}]}
{"channel":"book","type":"update","data":[{"symbol":"LTC/EUR","bids":[],"asks":[{"price":76.86,"qty":49.88257436}],"checksum":2771971577,"timestamp":"2024-06-01T18:07:19.274346Z"}]}
{"channel":"book","type":"update","data":[{"symbol":"LTC/EUR","bids":[{"price":76.68,"qty":145.21949132}],"asks":[],"checksum":1725388721,"timestamp":"2024-06-01T18:07:19.321750Z"}]}
{"channel":"book","type":"update","data":[{"symbol":"LTC/EUR","bids":[],"asks":[{"price":76.76,"qty":62.43759813}],"checksum":3023291459,"timestamp":"2024-06-01T18:07:19.325934Z"}]}
{"channel":"book","type":"update","data":[{"symbol":"LTC/EUR","bids":[{"price":76.67,"qty":222.76205229}],"asks":[],"checksum":1397448218,"timestamp":"2024-06-01T18:07:19.476917Z"}]}
{"channel":"book","type":"update","data":[{"symbol":"LTC/EUR","bids":[{"price":76.67,"qty":216.71006766}],"asks":[],"checksum":3023291459,"timestamp":"2024-06-01T18:07:19.521016Z"}]}
{"channel":"book","type":"update","data":[{"symbol":"LTC/EUR","bids":[{"price":76.67,"qty":264.76832262}],"asks":[],"checksum":3626260753,"timestamp":"2024-06-01T18:07:19.616279Z"}]}
{"channel":"book","type":"update","data":[{"symbol":"LTC/EUR","bids":[{"price":76.67,"qty":270.82030725}],"asks":[],"checksum":4285276766,"timestamp":"2024-06-01T18:07:19.639864Z"}]}
{"channel":"book","type":"update","data":[{"symbol":"LTC/EUR","bids":[{"price":76.69,"qty":1.06931562}],"asks":[],"checksum":683066808,"timestamp":"2024-06-01T18:07:19.866516Z"}]}
{"channel":"book","type":"update","data":[{"symbol":"LTC/EUR","bids":[{"price":76.64,"qty":0.00000000},{"price":76.60,"qty":356.42100000}],"asks":[],"checksum":171013811,"timestamp":"2024-06-01T18:07:19.866537Z"}]}
{"channel":"book","type":"update","data":[{"symbol":"LTC/EUR","bids":[],"asks":[{"price":76.75,"qty":96.53217608}],"checksum":1366014287,"timestamp":"2024-06-01T18:07:19.870890Z"}]}
{"channel":"book","type":"update","data":[{"symbol":"LTC/EUR","bids":[],"asks":[{"price":76.76,"qty":86.29066325}],"checksum":3295658203,"timestamp":"2024-06-01T18:07:19.870921Z"}]}
{"channel":"book","type":"update","data":[{"symbol":"LTC/EUR","bids":[{"price":76.69,"qty":2.80049990}],"asks":[],"checksum":331460730,"timestamp":"2024-06-01T18:07:19.872576Z"}]}
{"channel":"book","type":"update","data":[{"symbol":"LTC/EUR","bids":[{"price":76.64,"qty":7.61014156}],"asks":[],"checksum":289416658,"timestamp":"2024-06-01T18:07:19.872651Z"}]}
{"channel":"book","type":"update","data":[{"symbol":"LTC/EUR","bids":[{"price":76.67,"qty":266.31610725},{"price":76.62,"qty":102.14132076}],"asks":[],"checksum":1747292425,"timestamp":"2024-06-01T18:07:21.496983Z"}]}
{"channel":"book","type":"update","data":[{"symbol":"LTC/EUR","bids":[],"asks":[{"price":76.84,"qty":116.17626904}],"checksum":1029350144,"timestamp":"2024-06-01T18:07:21.524567Z"}]}
{"channel":"book","type":"update","data":[{"symbol":"LTC/EUR","bids":[],"asks":[{"price":76.74,"qty":78.76434928}],"checksum":450148647,"timestamp":"2024-06-01T18:07:21.694733Z"}]}
{"channel":"book","type":"update","data":[{"symbol":"LTC/EUR","bids":[],"asks":[{"price":76.78,"qty":132.75963925}],"checksum":759241762,"timestamp":"2024-06-01T18:07:21.727211Z"}]}
{"channel":"book","type":"update","data":[{"symbol":"LTC/EUR","bids":[],"asks":[{"price":76.73,"qty":60.08013485}],"checksum":123300932,"timestamp":"2024-06-01T18:07:21.731162Z"}]}
{"channel":"book","type":"update","data":[{"symbol":"LTC/EUR","bids":[],"asks":[{"price":76.74,"qty":73.76434928}],"checksum":291270719,"timestamp":"2024-06-01T18:07:21.763276Z"}]}
{"channel":"book","type":"update","data":[{"symbol":"LTC/EUR","bids":[{"price":76.64,"qty":0.00000000},{"price":76.60,"qty":356.42100000}],"asks":[],"checksum":518748530,"timestamp":"2024-06-01T18:07:22.187082Z"}]}
{"channel":"book","type":"update","data":[{"symbol":"LTC/EUR","bids":[],"asks":[{"price":76.75,"qty":36.10000000}],"checksum":3406592716,"timestamp":"2024-06-01T18:07:22.190456Z"}]}
{"channel":"book","type":"update","data":[{"symbol":"LTC/EUR","bids":[{"price":76.64,"qty":6.54879497}],"asks":[],"checksum":2174271141,"timestamp":"2024-06-01T18:07:22.191370Z"}]}
{"channel":"book","type":"update","data":[{"symbol":"LTC/EUR","bids":[],"asks":[{"price":76.74,"qty":134.68052536}],"checksum":3595093247,"timestamp":"2024-06-01T18:07:22.193568Z"}]}
{"channel":"book","type":"update","data":[{"symbol":"LTC/EUR","bids":[],"asks":[{"price":76.74,"qty":74.60824153}],"checksum":1382651433,"timestamp":"2024-06-01T18:07:22.703716Z"}]}
{"channel":"book","type":"update","data":[{"symbol":"LTC/EUR","bids":[],"asks":[{"price":76.77,"qty":60.04970939}],"checksum":3527465014,"timestamp":"2024-06-01T18:07:22.708494Z"}]}
{"channel":"book","type":"update","data":[{"symbol":"LTC/EUR","bids":[],"asks":[{"price":76.78,"qty":65.11963925},{"price":76.77,"qty":127.68970939}],"checksum":3774831358,"timestamp":"2024-06-01T18:07:22.711605Z"}]}
{"channel":"book","type":"update","data":[{"symbol":"LTC/EUR","bids":[],"asks":[{"price":76.78,"qty":62.67000000},{"price":76.77,"qty":130.13934864}],"checksum":3185802566,"timestamp":"2024-06-01T18:07:22.711895Z"}]}
{"channel":"book","type":"update","data":[{"symbol":"LTC/EUR","bids":[],"asks":[{"price":76.75,"qty":59.95306512}],"checksum":2900949307,"timestamp":"2024-06-01T18:07:23.014148Z"}]}
{"channel":"book","type":"update","data":[{"symbol":"LTC/EUR","bids":[{"price":76.67,"qty":264.01610725}],"asks":[],"checksum":2530089636,"timestamp":"2024-06-01T18:07:23.140049Z"}]}
{"channel":"book","type":"update","data":[{"symbol":"LTC/EUR","bids":[],"asks":[{"price":76.76,"qty":62.43759813}],"checksum":2338441668,"timestamp":"2024-06-01T18:07:23.143556Z"}]}
{"channel":"book","type":"update","data":[{"symbol":"LTC/EUR","bids":[{"price":76.66,"qty":32.60000000}],"asks":[],"checksum":205739450,"timestamp":"2024-06-01T18:07:23.275327Z"}]}
{"channel":"book","type":"update","data":[{"symbol":"LTC/EUR","bids":[{"price":76.67,"qty":186.25010725}],"asks":[],"checksum":2050146603,"timestamp":"2024-06-01T18:07:24.319319Z"}]}
{"channel":"book","type":"update","data":[{"symbol":"LTC/EUR","bids":[{"price":76.63,"qty":464.97441007}],"asks":[],"checksum":819141111,"timestamp":"2024-06-01T18:07:24.322116Z"}]}
{"channel":"book","type":"update","data":[{"symbol":"LTC/EUR","bids":[{"price":76.69,"qty":1.06931562}],"asks":[],"checksum":2473678358,"timestamp":"2024-06-01T18:07:27.027609Z"}]}
{"channel":"book","type":"update","data":[{"symbol":"LTC/EUR","bids":[{"price":76.64,"qty":0.00000000},{"price":76.60,"qty":24.03700000}],"asks":[],"checksum":3012808349,"timestamp":"2024-06-01T18:07:27.027747Z"}]}
{"channel":"book","type":"update","data":[{"symbol":"LTC/EUR","bids":[{"price":76.69,"qty":1.68252694}],"asks":[],"checksum":2937303095,"timestamp":"2024-06-01T18:07:27.033544Z"}]}
{"channel":"book","type":"update","data":[{"symbol":"LTC/EUR","bids":[{"price":76.64,"qty":9.12289327}],"asks":[],"checksum":2931743498,"timestamp":"2024-06-01T18:07:27.033803Z"}]}
{"channel":"book","type":"update","data":[{"symbol":"LTC/EUR","bids":[{"price":76.67,"qty":180.19812262}],"asks":[],"checksum":429371086,"timestamp":"2024-06-01T18:07:28.167235Z"}]}
{"channel":"book","type":"update","data":[{"symbol":"LTC/EUR","bids":[{"price":76.68,"qty":137.21549132}],"asks":[],"checksum":3497311744,"timestamp":"2024-06-01T18:07:28.377719Z"}]}
{"channel":"book","type":"update","data":[{"symbol":"LTC/EUR","bids":[{"price":76.67,"qty":188.18312262}],"asks":[],"checksum":2025545241,"timestamp":"2024-06-01T18:07:28.380236Z"}]}
{"channel":"book","type":"update","data":[{"symbol":"LTC/EUR","bids":[{"price":76.67,"qty":194.23510725}],"asks":[],"checksum":3737715722,"timestamp":"2024-06-01T18:07:28.384059Z"}]}
{"channel":"book","type":"update","data":[{"symbol":"LTC/EUR","bids":[],"asks":[{"price":76.80,"qty":11.70222938}],"checksum":3756811406,"timestamp":"2024-06-01T18:07:28.392875Z"}]}
{"channel":"book","type":"update","data":[{"symbol":"LTC/EUR","bids":[{"price":76.64,"qty":0.00000000},{"price":76.60,"qty":24.03700000}],"asks":[],"checksum":1169663409,"timestamp":"2024-06-01T18:07:29.367075Z"}]}
{"channel":"book","type":"update","data":[{"symbol":"LTC/EUR","bids":[{"price":76.64,"qty":8.56434879}],"asks":[],"checksum":2240972961,"timestamp":"2024-06-01T18:07:29.371702Z"}]}
{"channel":"book","type":"update","data":[{"symbol":"LTC/EUR","bids":[],"asks":[{"price":76.83,"qty":56.88085116}],"checksum":3597481774,"timestamp":"2024-06-01T18:07:30.000371Z"}]}
{"channel":"book","type":"update","data":[{"symbol":"LTC/EUR","bids":[],"asks":[{"price":76.83,"qty":48.04947680}],"checksum":2240972961,"timestamp":"2024-06-01T18:07:31.107908Z"}]}
{"channel":"book","type":"update","data":[{"symbol":"LTC/EUR","bids":[],"asks":[{"price":76.73,"qty":0.00000000},{"price":76.85,"qty":8.83137436}],"checksum":1424230224,"timestamp":"2024-06-01T18:07:31.373263Z"}]}
{"channel":"book","type":"update","data":[{"symbol":"LTC/EUR","bids":[],"asks":[{"price":76.74,"qty":134.68715755}],"checksum":2378516948,"timestamp":"2024-06-01T18:07:31.379373Z"}]}
{"channel":"book","type":"update","data":[{"symbol":"LTC/EUR","bids":[],"asks":[{"price":76.74,"qty":140.68715755}],"checksum":2396914242,"timestamp":"2024-06-01T18:07:31.406086Z"}]}
{"channel":"book","type":"update","data":[{"symbol":"LTC/EUR","bids":[{"price":76.64,"qty":0.00000000},{"price":76.60,"qty":24.03700000}],"asks":[],"checksum":2092915449,"timestamp":"2024-06-01T18:07:31.714255Z"}]}
{"channel":"book","type":"update","data":[{"symbol":"LTC/EUR","bids":[{"price":76.64,"qty":8.93671178}],"asks":[],"checksum":560824707,"timestamp":"2024-06-01T18:07:31.718321Z"}]}
{"channel":"book","type":"update","data":[{"symbol":"LTC/EUR","bids":[{"price":76.63,"qty":246.74761007}],"asks":[],"checksum":3879026289,"timestamp":"2024-06-01T18:07:32.386261Z"}]}
{"channel":"book","type":"update","data":[{"symbol":"LTC/EUR","bids":[{"price":76.62,"qty":97.98262076}],"asks":[],"checksum":4211227174,"timestamp":"2024-06-01T18:07:32.422216Z"}]}
{"channel":"book","type":"update","data":[{"symbol":"LTC/EUR","bids":[],"asks":[{"price":76.84,"qty":113.24216904}],"checksum":3819639441,"timestamp":"2024-06-01T18:07:32.426137Z"}]}
{"channel":"book","type":"update","data":[{"symbol":"LTC/EUR","bids":[],"asks":[{"price":76.85,"qty":11.88277436}],"checksum":178328548,"timestamp":"2024-06-01T18:07:33.474278Z"}]}
{"channel":"book","type":"update","data":[{"symbol":"LTC/EUR","bids":[{"price":76.62,"qty":102.29372076}],"asks":[],"checksum":547448505,"timestamp":"2024-06-01T18:07:33.477832Z"}]}
{"channel":"book","type":"update","data":[{"symbol":"LTC/EUR","bids":[{"price":76.64,"qty":0.00000000},{"price":76.60,"qty":24.03700000}],"asks":[],"checksum":3352606221,"timestamp":"2024-06-01T18:07:33.993758Z"}]}
{"channel":"book","type":"update","data":[{"symbol":"LTC/EUR","bids":[{"price":76.60,"qty":26.54246522}],"asks":[],"checksum":1051723659,"timestamp":"2024-06-01T18:07:34.036634Z"}]}
{"channel":"book","type":"update","data":[{"symbol":"LTC/EUR","bids":[{"price":76.64,"qty":6.20411605}],"asks":[],"checksum":21974636,"timestamp":"2024-06-01T18:07:34.036686Z"}]}
{"channel":"book","type":"update","data":[{"symbol":"LTC/EUR","bids":[],"asks":[{"price":76.76,"qty":2.38000000}],"checksum":611378558,"timestamp":"2024-06-01T18:07:34.548330Z"}]}
{"channel":"book","type":"update","data":[{"symbol":"LTC/EUR","bids":[],"asks":[{"price":76.74,"qty":200.76706227}],"checksum":2692006241,"timestamp":"2024-06-01T18:07:34.553045Z"}]}
{"channel":"book","type":"update","data":[{"symbol":"LTC/EUR","bids":[{"price":76.64,"qty":0.00000000},{"price":76.60,"qty":24.03700000}],"asks":[],"checksum":3116691775,"timestamp":"2024-06-01T18:07:36.192072Z"}]}
{"channel":"book","type":"update","data":[{"symbol":"LTC/EUR","bids":[{"price":76.60,"qty":26.25261225}],"asks":[],"checksum":2418977515,"timestamp":"2024-06-01T18:07:36.198311Z"}]}
{"channel":"book","type":"update","data":[{"symbol":"LTC/EUR","bids":[{"price":76.64,"qty":6.35321531}],"asks":[],"checksum":627646713,"timestamp":"2024-06-01T18:07:36.198364Z"}]}
{"channel":"book","type":"update","data":[{"symbol":"LTC/EUR","bids":[{"price":76.70,"qty":60.09870874}],"asks":[],"checksum":450024073,"timestamp":"2024-06-01T18:07:37.753588Z"}]}
{"channel":"book","type":"update","data":[{"symbol":"LTC/EUR","bids":[{"price":76.69,"qty":7.48252694}],"asks":[],"checksum":1284821745,"timestamp":"2024-06-01T18:07:37.753711Z"}]}
{"channel":"book","type":"update","data":[{"symbol":"LTC/EUR","bids":[],"asks":[{"price":76.79,"qty":0.00000000},{"price":76.86,"qty":43.63225004}],"checksum":1533328908,"timestamp":"2024-06-01T18:07:37.836546Z"}]}
{"channel":"book","type":"update","data":[{"symbol":"LTC/EUR","bids":[],"asks":[{"price":76.78,"qty":70.65500000}],"checksum":3323010287,"timestamp":"2024-06-01T18:07:37.838874Z"}]}
{"channel":"book","type":"update","data":[{"symbol":"LTC/EUR","bids":[{"price":76.69,"qty":6.86931562}],"asks":[],"checksum":1379817651,"timestamp":"2024-06-01T18:07:38.579023Z"}]}
{"channel":"book","type":"update","data":[{"symbol":"LTC/EUR","bids":[{"price":76.64,"qty":0.00000000},{"price":76.60,"qty":24.03700000}],"asks":[],"checksum":800722633,"timestamp":"2024-06-01T18:07:38.579609Z"}]}
{"channel":"book","type":"update","data":[{"symbol":"LTC/EUR","bids":[{"price":76.64,"qty":5.70484427}],"asks":[],"checksum":355535108,"timestamp":"2024-06-01T18:07:38.581887Z"}]}
{"channel":"book","type":"update","data":[{"symbol":"LTC/EUR","bids":[{"price":76.69,"qty":7.27538662}],"asks":[],"checksum":700518686,"timestamp":"2024-06-01T18:07:38.582044Z"}]}
