{"channel":"book","type":"snapshot","data":[{"symbol":"LTC/BTC","bids":[{"price":0.001229,"qty":0.10050000},{"price":0.001228,"qty":62.70672932},{"price":0.001227,"qty":244.24994606},{"price":0.001226,"qty":253.26373636},{"price":0.001225,"qty":627.24574135},{"price":0.001224,"qty":132.18400000},{"price":0.001222,"qty":23.38912387},{"price":0.001221,"qty":156.11618079},{"price":0.001220,"qty":139.61920000},{"price":0.001219,"qty":1.95970960}],"asks":[{"price":0.001230,"qty":96.74296775},{"price":0.001231,"qty":77.96894646},{"price":0.001232,"qty":413.62485651},{"price":0.001233,"qty":219.02052387},{"price":0.001234,"qty":44.62341195},{"price":0.001235,"qty":9.29300000},{"price":0.001236,"qty":14.68529058},{"price":0.001237,"qty":139.06544678},{"price":0.001239,"qty":4.54581508},{"price":0.001240,"qty":84.05469176}],"checksum":2775383767}]}
{"channel":"book","type":"update","data":[{"symbol":"LTC/BTC","bids":[{"price":0.001228,"qty":58.90000000}],"asks":[],"checksum":272207544,"timestamp":"2024-06-01T18:07:06.658095Z"}]}
{"channel":"book","type":"update","data":[{"symbol":"LTC/BTC","bids":[{"price":0.001227,"qty":243.76885794}],"asks":[],"checksum":1204697943,"timestamp":"2024-06-01T18:07:06.658122Z"}]}
{"channel":"book","type":"update","data":[{"symbol":"LTC/BTC","bids":[{"price":0.001228,"qty":60.43738872}],"asks":[],"checksum":4029322934,"timestamp":"2024-06-01T18:07:06.663023Z"}]}
{"channel":"book","type":"update","data":[{"symbol":"LTC/BTC","bids":[{"price":0.001227,"qty":246.51408068}],"asks":[],"checksum":2891405076,"timestamp":"2024-06-01T18:07:06.663787Z"}]}
{"channel":"book","type":"update","data":[{"symbol":"LTC/BTC","bids":[{"price":0.001224,"qty":123.18400000}],"asks":[],"checksum":1761549907,"timestamp":"2024-06-01T18:07:08.020494Z"}]}
{"channel":"book","type":"update","data":[{"symbol":"LTC/BTC","bids":[{"price":0.001224,"qty":132.18400000}],"asks":[],"checksum":2891405076,"timestamp":"2024-06-01T18:07:08.052294Z"}]}
{"channel":"book","type":"update","data":[{"symbol":"LTC/BTC","bids":[{"price":0.001227,"qty":236.60598393}],"asks":[],"checksum":2263265913,"timestamp":"2024-06-01T18:07:08.273602Z"}]}
{"channel":"book","type":"update","data":[{"symbol":"LTC/BTC","bids":[{"price":0.001226,"qty":263.17183311}],"asks":[],"checksum":3892657750,"timestamp":"2024-06-01T18:07:08.378989Z"}]}
{"channel":"book","type":"update","data":[{"symbol":"LTC/BTC","bids":[{"price":0.001227,"qty":233.86076119}],"asks":[],"checksum":3789169229,"timestamp":"2024-06-01T18:07:09.066162Z"}]}
{"channel":"book","type":"update","data":[{"symbol":"LTC/BTC","bids":[{"price":0.001228,"qty":58.90000000}],"asks":[],"checksum":1446940588,"timestamp":"2024-06-01T18:07:09.066202Z"}]}
{"channel":"book","type":"update","data":[{"symbol":"LTC/BTC","bids":[{"price":0.001228,"qty":59.95104192}],"asks":[],"checksum":3080455689,"timestamp":"2024-06-01T18:07:09.071399Z"}]}
{"channel":"book","type":"update","data":[{"symbol":"LTC/BTC","bids":[{"price":0.001227,"qty":237.09520078}],"asks":[],"checksum":2021623203,"timestamp":"2024-06-01T18:07:09.071548Z"}]}
{"channel":"book","type":"update","data":[{"symbol":"LTC/BTC","bids":[{"price":0.001227,"qty":233.86076119}],"asks":[],"checksum":3080455689,"timestamp":"2024-06-01T18:07:11.473832Z"}]}
{"channel":"book","type":"update","data":[{"symbol":"LTC/BTC","bids":[{"price":0.001227,"qty":237.25695074}],"asks":[],"checksum":4190121547,"timestamp":"2024-06-01T18:07:11.479339Z"}]}
{"channel":"book","type":"update","data":[{"symbol":"LTC/BTC","bids":[],"asks":[{"price":0.001231,"qty":68.97285914}],"checksum":3665201741,"timestamp":"2024-06-01T18:07:12.056683Z"}]}
{"channel":"book","type":"update","data":[{"symbol":"LTC/BTC","bids":[],"asks":[{"price":0.001231,"qty":77.96894646}],"checksum":4190121547,"timestamp":"2024-06-01T18:07:12.153427Z"}]}
{"channel":"book","type":"update","data":[{"symbol":"LTC/BTC","bids":[],"asks":[{"price":0.001236,"qty":12.52684882}],"checksum":3989355600,"timestamp":"2024-06-01T18:07:12.951070Z"}]}
{"channel":"book","type":"update","data":[{"symbol":"LTC/BTC","bids":[],"asks":[{"price":0.001238,"qty":21.58937090}],"checksum":3933039392,"timestamp":"2024-06-01T18:07:12.951205Z"}]}
{"channel":"book","type":"update","data":[{"symbol":"LTC/BTC","bids":[],"asks":[{"price":0.001237,"qty":117.48102922}],"checksum":3694667775,"timestamp":"2024-06-01T18:07:12.951318Z"}]}
{"channel":"book","type":"update","data":[{"symbol":"LTC/BTC","bids":[],"asks":[{"price":0.001235,"qty":11.45193709}],"checksum":4249915114,"timestamp":"2024-06-01T18:07:12.951878Z"}]}
{"channel":"book","type":"update","data":[{"symbol":"LTC/BTC","bids":[{"price":0.001228,"qty":58.90000000}],"asks":[],"checksum":485623631,"timestamp":"2024-06-01T18:07:13.819031Z"}]}
{"channel":"book","type":"update","data":[{"symbol":"LTC/BTC","bids":[{"price":0.001227,"qty":233.86076119}],"asks":[],"checksum":1387147021,"timestamp":"2024-06-01T18:07:13.819324Z"}]}
{"channel":"book","type":"update","data":[{"symbol":"LTC/BTC","bids":[{"price":0.001227,"qty":237.09359918}],"asks":[],"checksum":2576874048,"timestamp":"2024-06-01T18:07:13.823988Z"}]}
{"channel":"book","type":"update","data":[{"symbol":"LTC/BTC","bids":[{"price":0.001228,"qty":60.11315656}],"asks":[],"checksum":396338867,"timestamp":"2024-06-01T18:07:13.824033Z"}]}
{"channel":"book","type":"update","data":[{"symbol":"LTC/BTC","bids":[{"price":0.001227,"qty":233.86076119}],"asks":[],"checksum":3701896190,"timestamp":"2024-06-01T18:07:16.228629Z"}]}
{"channel":"book","type":"update","data":[{"symbol":"LTC/BTC","bids":[{"price":0.001228,"qty":58.90000000}],"asks":[],"checksum":1387147021,"timestamp":"2024-06-01T18:07:16.228707Z"}]}
{"channel":"book","type":"update","data":[{"symbol":"LTC/BTC","bids":[{"price":0.001228,"qty":60.76160179}],"asks":[],"checksum":3198885698,"timestamp":"2024-06-01T18:07:16.234237Z"}]}
{"channel":"book","type":"update","data":[{"symbol":"LTC/BTC","bids":[{"price":0.001227,"qty":236.44193013}],"asks":[],"checksum":1911371449,"timestamp":"2024-06-01T18:07:16.234441Z"}]}
{"channel":"book","type":"update","data":[{"symbol":"LTC/BTC","bids":[{"price":0.001222,"qty":35.30040902}],"asks":[],"checksum":1143486083,"timestamp":"2024-06-01T18:07:16.331148Z"}]}
{"channel":"book","type":"update","data":[{"symbol":"LTC/BTC","bids":[{"price":0.001221,"qty":153.95099296}],"asks":[],"checksum":3837968100,"timestamp":"2024-06-01T18:07:16.331719Z"}]}
{"channel":"book","type":"update","data":[{"symbol":"LTC/BTC","bids":[{"price":0.001221,"qty":142.04245991}],"asks":[],"checksum":264408792,"timestamp":"2024-06-01T18:07:16.332034Z"}]}
{"channel":"book","type":"update","data":[{"symbol":"LTC/BTC","bids":[{"price":0.001222,"qty":37.46609723}],"asks":[],"checksum":3146587777,"timestamp":"2024-06-01T18:07:16.332066Z"}]}
{"channel":"book","type":"update","data":[{"symbol":"LTC/BTC","bids":[{"price":0.001228,"qty":241.12510825}],"asks":[],"checksum":2088374244,"timestamp":"2024-06-01T18:07:17.291455Z"}]}
{"channel":"book","type":"update","data":[{"symbol":"LTC/BTC","bids":[{"price":0.001225,"qty":716.24574135}],"asks":[],"checksum":2534882791,"timestamp":"2024-06-01T18:07:17.553099Z"}]}
{"channel":"book","type":"update","data":[{"symbol":"LTC/BTC","bids":[{"price":0.001225,"qty":646.24574135}],"asks":[],"checksum":3412885962,"timestamp":"2024-06-01T18:07:17.568911Z"}]}
{"channel":"book","type":"update","data":[{"symbol":"LTC/BTC","bids":[{"price":0.001228,"qty":239.26350646}],"asks":[],"checksum":2861799929,"timestamp":"2024-06-01T18:07:18.582808Z"}]}
{"channel":"book","type":"update","data":[{"symbol":"LTC/BTC","bids":[{"price":0.001227,"qty":233.86076119}],"asks":[],"checksum":1708503042,"timestamp":"2024-06-01T18:07:18.582952Z"}]}
{"channel":"book","type":"update","data":[{"symbol":"LTC/BTC","bids":[{"price":0.001227,"qty":234.66697742}],"asks":[],"checksum":3713540560,"timestamp":"2024-06-01T18:07:18.588111Z"}]}
{"channel":"book","type":"update","data":[{"symbol":"LTC/BTC","bids":[{"price":0.001228,"qty":241.28721564}],"asks":[],"checksum":2358396253,"timestamp":"2024-06-01T18:07:18.588308Z"}]}
{"channel":"book","type":"update","data":[{"symbol":"LTC/BTC","bids":[],"asks":[{"price":0.001232,"qty":396.48620946}],"checksum":1069043671,"timestamp":"2024-06-01T18:07:18.643399Z"}]}
{"channel":"book","type":"update","data":[{"symbol":"LTC/BTC","bids":[],"asks":[{"price":0.001232,"qty":413.62485651}],"checksum":2358396253,"timestamp":"2024-06-01T18:07:18.756151Z"}]}
{"channel":"book","type":"update","data":[{"symbol":"LTC/BTC","bids":[],"asks":[{"price":0.001231,"qty":72.82862657}],"checksum":3308792032,"timestamp":"2024-06-01T18:07:19.396380Z"}]}
{"channel":"book","type":"update","data":[{"symbol":"LTC/BTC","bids":[],"asks":[{"price":0.001231,"qty":78.09269132}],"checksum":3559526556,"timestamp":"2024-06-01T18:07:19.533181Z"}]}
{"channel":"book","type":"update","data":[{"symbol":"LTC/BTC","bids":[],"asks":[{"price":0.001231,"qty":75.74099480}],"checksum":1708217876,"timestamp":"2024-06-01T18:07:20.038858Z"}]}
{"channel":"book","type":"update","data":[{"symbol":"LTC/BTC","bids":[],"asks":[{"price":0.001231,"qty":78.56188476}],"checksum":2058265076,"timestamp":"2024-06-01T18:07:20.039751Z"}]}
{"channel":"book","type":"update","data":[{"symbol":"LTC/BTC","bids":[{"price":0.001227,"qty":233.86076119}],"asks":[],"checksum":3257085990,"timestamp":"2024-06-01T18:07:21.032527Z"}]}
{"channel":"book","type":"update","data":[{"symbol":"LTC/BTC","bids":[{"price":0.001228,"qty":239.26350646}],"asks":[],"checksum":2481542315,"timestamp":"2024-06-01T18:07:21.032574Z"}]}
{"channel":"book","type":"update","data":[{"symbol":"LTC/BTC","bids":[{"price":0.001228,"qty":240.47667517}],"asks":[],"checksum":3026310538,"timestamp":"2024-06-01T18:07:21.037240Z"}]}
{"channel":"book","type":"update","data":[{"symbol":"LTC/BTC","bids":[{"price":0.001227,"qty":235.80048821}],"asks":[],"checksum":1218070331,"timestamp":"2024-06-01T18:07:21.037392Z"}]}
{"channel":"book","type":"update","data":[{"symbol":"LTC/BTC","bids":[],"asks":[{"price":0.001231,"qty":75.74099480}],"checksum":1474670811,"timestamp":"2024-06-01T18:07:22.439496Z"}]}
{"channel":"book","type":"update","data":[{"symbol":"LTC/BTC","bids":[],"asks":[{"price":0.001231,"qty":78.32729981}],"checksum":850484654,"timestamp":"2024-06-01T18:07:22.440043Z"}]}
{"channel":"book","type":"update","data":[{"symbol":"LTC/BTC","bids":[{"price":0.001222,"qty":37.21710511}],"asks":[],"checksum":2070124837,"timestamp":"2024-06-01T18:07:22.447768Z"}]}
{"channel":"book","type":"update","data":[{"symbol":"LTC/BTC","bids":[],"asks":[{"price":0.001235,"qty":9.29300000}],"checksum":1577722885,"timestamp":"2024-06-01T18:07:23.415466Z"}]}
{"channel":"book","type":"update","data":[{"symbol":"LTC/BTC","bids":[],"asks":[{"price":0.001237,"qty":139.07040012}],"checksum":1970460550,"timestamp":"2024-06-01T18:07:23.415596Z"}]}
{"channel":"book","type":"update","data":[{"symbol":"LTC/BTC","bids":[],"asks":[{"price":0.001238,"qty":0.00000000},{"price":0.001240,"qty":84.05469176}],"checksum":628097901,"timestamp":"2024-06-01T18:07:23.415989Z"}]}
{"channel":"book","type":"update","data":[{"symbol":"LTC/BTC","bids":[],"asks":[{"price":0.001236,"qty":14.68578591}],"checksum":4111080914,"timestamp":"2024-06-01T18:07:23.415999Z"}]}
{"channel":"book","type":"update","data":[{"symbol":"LTC/BTC","bids":[{"price":0.001228,"qty":239.26350646}],"asks":[],"checksum":3531775219,"timestamp":"2024-06-01T18:07:23.449438Z"}]}
{"channel":"book","type":"update","data":[{"symbol":"LTC/BTC","bids":[{"price":0.001227,"qty":233.86076119}],"asks":[],"checksum":779685442,"timestamp":"2024-06-01T18:07:23.449525Z"}]}
{"channel":"book","type":"update","data":[{"symbol":"LTC/BTC","bids":[{"price":0.001228,"qty":242.09743337}],"asks":[],"checksum":1967039171,"timestamp":"2024-06-01T18:07:23.457024Z"}]}
{"channel":"book","type":"update","data":[{"symbol":"LTC/BTC","bids":[{"price":0.001226,"qty":263.41181194}],"asks":[],"checksum":3495248951,"timestamp":"2024-06-01T18:07:24.590366Z"}]}
{"channel":"book","type":"update","data":[{"symbol":"LTC/BTC","bids":[{"price":0.001227,"qty":225.71368346}],"asks":[],"checksum":646703845,"timestamp":"2024-06-01T18:07:25.051420Z"}]}
{"channel":"book","type":"update","data":[{"symbol":"LTC/BTC","bids":[{"price":0.001227,"qty":233.86076119}],"asks":[],"checksum":3495248951,"timestamp":"2024-06-01T18:07:25.160176Z"}]}
{"channel":"book","type":"update","data":[{"symbol":"LTC/BTC","bids":[{"price":0.001228,"qty":239.26350646}],"asks":[],"checksum":2333272246,"timestamp":"2024-06-01T18:07:25.920678Z"}]}
{"channel":"book","type":"update","data":[{"symbol":"LTC/BTC","bids":[{"price":0.001228,"qty":240.63877088}],"asks":[],"checksum":3013926540,"timestamp":"2024-06-01T18:07:25.925517Z"}]}
{"channel":"book","type":"update","data":[{"symbol":"LTC/BTC","bids":[{"price":0.001227,"qty":234.50699058}],"asks":[],"checksum":528725412,"timestamp":"2024-06-01T18:07:25.925670Z"}]}
{"channel":"book","type":"update","data":[{"symbol":"LTC/BTC","bids":[{"price":0.001222,"qty":39.38279012}],"asks":[],"checksum":533099502,"timestamp":"2024-06-01T18:07:26.821279Z"}]}
{"channel":"book","type":"update","data":[{"symbol":"LTC/BTC","bids":[{"price":0.001222,"qty":37.21710191}],"asks":[],"checksum":657624078,"timestamp":"2024-06-01T18:07:26.821835Z"}]}
{"channel":"book","type":"update","data":[{"symbol":"LTC/BTC","bids":[{"price":0.001221,"qty":153.95372746}],"asks":[],"checksum":2442701516,"timestamp":"2024-06-01T18:07:26.822533Z"}]}
{"channel":"book","type":"update","data":[{"symbol":"LTC/BTC","bids":[{"price":0.001222,"qty":25.30581676}],"asks":[],"checksum":3296990865,"timestamp":"2024-06-01T18:07:26.822596Z"}]}
{"channel":"book","type":"update","data":[{"symbol":"LTC/BTC","bids":[{"price":0.001228,"qty":239.26350646}],"asks":[],"checksum":4231143595,"timestamp":"2024-06-01T18:07:28.269546Z"}]}
{"channel":"book","type":"update","data":[{"symbol":"LTC/BTC","bids":[{"price":0.001227,"qty":233.86076119}],"asks":[],"checksum":1343572867,"timestamp":"2024-06-01T18:07:28.269669Z"}]}
{"channel":"book","type":"update","data":[{"symbol":"LTC/BTC","bids":[{"price":0.001228,"qty":240.80088232}],"asks":[],"checksum":1683733130,"timestamp":"2024-06-01T18:07:28.273464Z"}]}
{"channel":"book","type":"update","data":[{"symbol":"LTC/BTC","bids":[{"price":0.001227,"qty":234.34519577}],"asks":[],"checksum":3577832220,"timestamp":"2024-06-01T18:07:28.273527Z"}]}
{"channel":"book","type":"update","data":[{"symbol":"LTC/BTC","bids":[{"price":0.001228,"qty":239.26350646}],"asks":[],"checksum":3775894037,"timestamp":"2024-06-01T18:07:30.709822Z"}]}
{"channel":"book","type":"update","data":[{"symbol":"LTC/BTC","bids":[{"price":0.001227,"qty":233.86076119}],"asks":[],"checksum":1343572867,"timestamp":"2024-06-01T18:07:30.710057Z"}]}
{"channel":"book","type":"update","data":[{"symbol":"LTC/BTC","bids":[{"price":0.001228,"qty":240.96299376}],"asks":[],"checksum":3791773321,"timestamp":"2024-06-01T18:07:30.713725Z"}]}
{"channel":"book","type":"update","data":[{"symbol":"LTC/BTC","bids":[{"price":0.001227,"qty":234.18355926}],"asks":[],"checksum":1890264977,"timestamp":"2024-06-01T18:07:30.713795Z"}]}
{"channel":"book","type":"update","data":[{"symbol":"LTC/BTC","bids":[{"price":0.001220,"qty":47.62150000}],"asks":[],"checksum":2024079713,"timestamp":"2024-06-01T18:07:32.385989Z"}]}
{"channel":"book","type":"update","data":[{"symbol":"LTC/BTC","bids":[],"asks":[{"price":0.001240,"qty":7.49009176}],"checksum":1060385358,"timestamp":"2024-06-01T18:07:32.386230Z"}]}
{"channel":"book","type":"update","data":[{"symbol":"LTC/BTC","bids":[],"asks":[{"price":0.001240,"qty":5.49070000}],"checksum":1855829479,"timestamp":"2024-06-01T18:07:32.394440Z"}]}
{"channel":"book","type":"update","data":[{"symbol":"LTC/BTC","bids":[{"price":0.001225,"qty":645.86100367}],"asks":[],"checksum":672617780,"timestamp":"2024-06-01T18:07:32.394494Z"}]}
{"channel":"book","type":"update","data":[{"symbol":"LTC/BTC","bids":[{"price":0.001220,"qty":39.92400000}],"asks":[],"checksum":58315369,"timestamp":"2024-06-01T18:07:32.408522Z"}]}
{"channel":"book","type":"update","data":[{"symbol":"LTC/BTC","bids":[],"asks":[{"price":0.001240,"qty":0.00000000},{"price":0.001241,"qty":80.83942032}],"checksum":117771716,"timestamp":"2024-06-01T18:07:32.425071Z"}]}
{"channel":"book","type":"update","data":[{"symbol":"LTC/BTC","bids":[{"price":0.001227,"qty":233.86076119}],"asks":[],"checksum":2138213896,"timestamp":"2024-06-01T18:07:33.049393Z"}]}
{"channel":"book","type":"update","data":[{"symbol":"LTC/BTC","bids":[{"price":0.001228,"qty":239.26350646}],"asks":[],"checksum":3605834929,"timestamp":"2024-06-01T18:07:33.049665Z"}]}
{"channel":"book","type":"update","data":[{"symbol":"LTC/BTC","bids":[{"price":0.001228,"qty":240.15246007}],"asks":[],"checksum":346711818,"timestamp":"2024-06-01T18:07:33.055002Z"}]}
{"channel":"book","type":"update","data":[{"symbol":"LTC/BTC","bids":[{"price":0.001227,"qty":234.50796392}],"asks":[],"checksum":2407113625,"timestamp":"2024-06-01T18:07:33.055128Z"}]}
{"channel":"book","type":"update","data":[{"symbol":"LTC/BTC","bids":[],"asks":[{"price":0.001232,"qty":210.61181447}],"checksum":598418538,"timestamp":"2024-06-01T18:07:33.090501Z"}]}
{"channel":"book","type":"update","data":[{"symbol":"LTC/BTC","bids":[],"asks":[{"price":0.001232,"qty":182.25553835}],"checksum":562185766,"timestamp":"2024-06-01T18:07:33.102551Z"}]}
{"channel":"book","type":"update","data":[{"symbol":"LTC/BTC","bids":[],"asks":[{"price":0.001233,"qty":422.13112669}],"checksum":3018947872,"timestamp":"2024-06-01T18:07:33.131029Z"}]}
{"channel":"book","type":"update","data":[{"symbol":"LTC/BTC","bids":[],"asks":[{"price":0.001232,"qty":210.61181447}],"checksum":2983731052,"timestamp":"2024-06-01T18:07:33.200762Z"}]}
{"channel":"book","type":"update","data":[{"symbol":"LTC/BTC","bids":[],"asks":[{"price":0.001240,"qty":83.62510000}],"checksum":2519080716,"timestamp":"2024-06-01T18:07:33.457307Z"}]}
{"channel":"book","type":"update","data":[{"symbol":"LTC/BTC","bids":[{"price":0.001220,"qty":134.39180000}],"asks":[],"checksum":2946605817,"timestamp":"2024-06-01T18:07:33.460707Z"}]}
{"channel":"book","type":"update","data":[{"symbol":"LTC/BTC","bids":[{"price":0.001225,"qty":646.25995307}],"asks":[],"checksum":9415842,"timestamp":"2024-06-01T18:07:33.473441Z"}]}
