{"channel":"book","type":"snapshot","data":[{"symbol":"LTC/USD","bids":[{"price":83.19,"qty":33.98300000},{"price":83.18,"qty":7.68729227},{"price":83.17,"qty":37.74518990},{"price":83.16,"qty":31.54056512},{"price":83.15,"qty":69.41304145},{"price":83.14,"qty":141.19451561},{"price":83.13,"qty":185.05078324},{"price":83.12,"qty":141.26750000},{"price":83.11,"qty":19.48675117},{"price":83.10,"qty":164.48480600}],"asks":[{"price":83.20,"qty":52.83557692},{"price":83.21,"qty":48.59278599},{"price":83.22,"qty":115.80529883},{"price":83.23,"qty":139.29190099},{"price":83.24,"qty":132.26033625},{"price":83.25,"qty":12.99701062},{"price":83.26,"qty":13.57511735},{"price":83.27,"qty":57.07546424},{"price":83.28,"qty":101.84926237},{"price":83.29,"qty":120.24760382}],"checksum":4041025895}]}
{"channel":"book","type":"update","data":[{"symbol":"LTC/USD","bids":[{"price":83.11,"qty":11.75740000}],"asks":[],"checksum":1024146205,"timestamp":"2024-06-01T18:07:13.750547Z"}]}
{"channel":"book","type":"update","data":[{"symbol":"LTC/USD","bids":[{"price":83.14,"qty":138.19845742}],"asks":[],"checksum":3987708764,"timestamp":"2024-06-01T18:07:13.750603Z"}]}
{"channel":"book","type":"update","data":[{"symbol":"LTC/USD","bids":[{"price":83.14,"qty":141.01926096}],"asks":[],"checksum":1004911314,"timestamp":"2024-06-01T18:07:13.760298Z"}]}
{"channel":"book","type":"update","data":[{"symbol":"LTC/USD","bids":[{"price":83.11,"qty":19.02028553}],"asks":[],"checksum":661724947,"timestamp":"2024-06-01T18:07:13.760369Z"}]}
{"channel":"book","type":"update","data":[{"symbol":"LTC/USD","bids":[{"price":83.13,"qty":205.05078324}],"asks":[],"checksum":1280870291,"timestamp":"2024-06-01T18:07:14.116852Z"}]}
{"channel":"book","type":"update","data":[{"symbol":"LTC/USD","bids":[{"price":83.14,"qty":133.46926096}],"asks":[],"checksum":3201504991,"timestamp":"2024-06-01T18:07:14.154226Z"}]}
{"channel":"book","type":"update","data":[{"symbol":"LTC/USD","bids":[{"price":83.12,"qty":133.71750000}],"asks":[],"checksum":4268670349,"timestamp":"2024-06-01T18:07:14.243278Z"}]}
{"channel":"book","type":"update","data":[{"symbol":"LTC/USD","bids":[{"price":83.14,"qty":122.27926096}],"asks":[],"checksum":2665062814,"timestamp":"2024-06-01T18:07:14.302498Z"}]}
{"channel":"book","type":"update","data":[{"symbol":"LTC/USD","bids":[{"price":83.13,"qty":216.24078324}],"asks":[],"checksum":95605602,"timestamp":"2024-06-01T18:07:14.304899Z"}]}
{"channel":"book","type":"update","data":[{"symbol":"LTC/USD","bids":[{"price":83.14,"qty":129.82926096},{"price":83.12,"qty":141.26750000}],"asks":[],"checksum":2963471185,"timestamp":"2024-06-01T18:07:14.551921Z"}]}
{"channel":"book","type":"update","data":[{"symbol":"LTC/USD","bids":[{"price":83.14,"qty":122.27926096}],"asks":[],"checksum":1158641712,"timestamp":"2024-06-01T18:07:14.668320Z"}]}
{"channel":"book","type":"update","data":[{"symbol":"LTC/USD","bids":[{"price":83.14,"qty":129.82926096}],"asks":[],"checksum":2963471185,"timestamp":"2024-06-01T18:07:14.832644Z"}]}
{"channel":"book","type":"update","data":[{"symbol":"LTC/USD","bids":[{"price":83.11,"qty":11.75740000}],"asks":[],"checksum":2889244304,"timestamp":"2024-06-01T18:07:16.529051Z"}]}
{"channel":"book","type":"update","data":[{"symbol":"LTC/USD","bids":[{"price":83.14,"qty":127.00845742}],"asks":[],"checksum":1364272413,"timestamp":"2024-06-01T18:07:16.529282Z"}]}
{"channel":"book","type":"update","data":[{"symbol":"LTC/USD","bids":[{"price":83.14,"qty":130.68937699}],"asks":[],"checksum":1056894965,"timestamp":"2024-06-01T18:07:16.536202Z"}]}
{"channel":"book","type":"update","data":[{"symbol":"LTC/USD","bids":[{"price":83.11,"qty":18.79853687}],"asks":[],"checksum":394607299,"timestamp":"2024-06-01T18:07:16.536395Z"}]}
{"channel":"book","type":"update","data":[{"symbol":"LTC/USD","bids":[],"asks":[{"price":83.22,"qty":114.65582668}],"checksum":2878118736,"timestamp":"2024-06-01T18:07:17.607389Z"}]}
{"channel":"book","type":"update","data":[{"symbol":"LTC/USD","bids":[],"asks":[{"price":83.21,"qty":48.83324144}],"checksum":1073756345,"timestamp":"2024-06-01T18:07:17.608216Z"}]}
{"channel":"book","type":"update","data":[{"symbol":"LTC/USD","bids":[],"asks":[{"price":83.22,"qty":115.59416650}],"checksum":3600368727,"timestamp":"2024-06-01T18:07:17.608276Z"}]}
{"channel":"book","type":"update","data":[{"symbol":"LTC/USD","bids":[{"price":83.17,"qty":30.05768990}],"asks":[],"checksum":2825867331,"timestamp":"2024-06-01T18:07:18.863331Z"}]}
{"channel":"book","type":"update","data":[{"symbol":"LTC/USD","bids":[{"price":83.15,"qty":69.12812087}],"asks":[],"checksum":3042220274,"timestamp":"2024-06-01T18:07:18.866273Z"}]}
{"channel":"book","type":"update","data":[{"symbol":"LTC/USD","bids":[{"price":83.12,"qty":81.29750000}],"asks":[],"checksum":763672480,"timestamp":"2024-06-01T18:07:18.866327Z"}]}
{"channel":"book","type":"update","data":[{"symbol":"LTC/USD","bids":[{"price":83.15,"qty":68.84320029}],"asks":[],"checksum":3070725443,"timestamp":"2024-06-01T18:07:18.866508Z"}]}
{"channel":"book","type":"update","data":[{"symbol":"LTC/USD","bids":[{"price":83.10,"qty":224.45480600}],"asks":[],"checksum":1188637432,"timestamp":"2024-06-01T18:07:18.869735Z"}]}
{"channel":"book","type":"update","data":[{"symbol":"LTC/USD","bids":[{"price":83.14,"qty":123.44365157}],"asks":[],"checksum":3503990203,"timestamp":"2024-06-01T18:07:18.887793Z"}]}
{"channel":"book","type":"update","data":[{"symbol":"LTC/USD","bids":[{"price":83.12,"qty":75.29750000}],"asks":[],"checksum":2692692837,"timestamp":"2024-06-01T18:07:18.892838Z"}]}
{"channel":"book","type":"update","data":[{"symbol":"LTC/USD","bids":[{"price":83.18,"qty":0.00000000},{"price":83.09,"qty":68.02961122}],"asks":[],"checksum":1443732617,"timestamp":"2024-06-01T18:07:18.969043Z"}]}
{"channel":"book","type":"update","data":[{"symbol":"LTC/USD","bids":[{"price":83.16,"qty":39.29455512}],"asks":[],"checksum":1285573919,"timestamp":"2024-06-01T18:07:18.972377Z"}]}
{"channel":"book","type":"update","data":[{"symbol":"LTC/USD","bids":[{"price":83.10,"qty":230.46080600}],"asks":[],"checksum":4163559441,"timestamp":"2024-06-01T18:07:18.975301Z"}]}
{"channel":"book","type":"update","data":[{"symbol":"LTC/USD","bids":[],"asks":[{"price":83.24,"qty":131.40388486},{"price":83.23,"qty":140.14835238}],"checksum":823063705,"timestamp":"2024-06-01T18:07:19.002316Z"}]}
{"channel":"book","type":"update","data":[{"symbol":"LTC/USD","bids":[{"price":83.13,"qty":142.72056164},{"price":83.12,"qty":148.81772160}],"asks":[],"checksum":436112767,"timestamp":"2024-06-01T18:07:19.002578Z"}]}
{"channel":"book","type":"update","data":[{"symbol":"LTC/USD","bids":[],"asks":[{"price":83.22,"qty":115.87908708}],"checksum":1826001867,"timestamp":"2024-06-01T18:07:19.002873Z"}]}
{"channel":"book","type":"update","data":[{"symbol":"LTC/USD","bids":[{"price":83.17,"qty":0.00000000},{"price":83.08,"qty":67.86635432}],"asks":[],"checksum":3100850512,"timestamp":"2024-06-01T18:07:19.004348Z"}]}
{"channel":"book","type":"update","data":[{"symbol":"LTC/USD","bids":[{"price":83.12,"qty":88.75772160}],"asks":[],"checksum":3494328029,"timestamp":"2024-06-01T18:07:19.004869Z"}]}
{"channel":"book","type":"update","data":[{"symbol":"LTC/USD","bids":[],"asks":[{"price":83.23,"qty":80.14835238},{"price":83.22,"qty":175.87908708}],"checksum":1824699053,"timestamp":"2024-06-01T18:07:19.006181Z"}]}
{"channel":"book","type":"update","data":[{"symbol":"LTC/USD","bids":[],"asks":[{"price":83.22,"qty":176.16400766}],"checksum":237528640,"timestamp":"2024-06-01T18:07:19.006463Z"}]}
{"channel":"book","type":"update","data":[{"symbol":"LTC/USD","bids":[],"asks":[{"price":83.23,"qty":74.74835238}],"checksum":1467972239,"timestamp":"2024-06-01T18:07:19.007387Z"}]}
{"channel":"book","type":"update","data":[{"symbol":"LTC/USD","bids":[],"asks":[{"price":83.20,"qty":58.23557692}],"checksum":1125546386,"timestamp":"2024-06-01T18:07:19.007443Z"}]}
{"channel":"book","type":"update","data":[{"symbol":"LTC/USD","bids":[],"asks":[{"price":83.22,"qty":176.44892824}],"checksum":4004278989,"timestamp":"2024-06-01T18:07:19.007616Z"}]}
{"channel":"book","type":"update","data":[{"symbol":"LTC/USD","bids":[{"price":83.15,"qty":68.55827971}],"asks":[],"checksum":3319092620,"timestamp":"2024-06-01T18:07:19.007639Z"}]}
{"channel":"book","type":"update","data":[{"symbol":"LTC/USD","bids":[],"asks":[{"price":83.22,"qty":176.73384882}],"checksum":821379764,"timestamp":"2024-06-01T18:07:19.007947Z"}]}
{"channel":"book","type":"update","data":[{"symbol":"LTC/USD","bids":[{"price":83.15,"qty":68.27335913}],"asks":[],"checksum":1431629796,"timestamp":"2024-06-01T18:07:19.007989Z"}]}
{"channel":"book","type":"update","data":[{"symbol":"LTC/USD","bids":[{"price":83.16,"qty":69.35623273}],"asks":[],"checksum":1864812568,"timestamp":"2024-06-01T18:07:19.008637Z"}]}
{"channel":"book","type":"update","data":[{"symbol":"LTC/USD","bids":[{"price":83.14,"qty":130.68937699}],"asks":[],"checksum":3797409691,"timestamp":"2024-06-01T18:07:19.008925Z"}]}
{"channel":"book","type":"update","data":[{"symbol":"LTC/USD","bids":[{"price":83.11,"qty":78.85853687}],"asks":[],"checksum":1147509938,"timestamp":"2024-06-01T18:07:19.009979Z"}]}
{"channel":"book","type":"update","data":[{"symbol":"LTC/USD","bids":[{"price":83.15,"qty":8.14297990}],"asks":[],"checksum":1859478349,"timestamp":"2024-06-01T18:07:19.014404Z"}]}
{"channel":"book","type":"update","data":[{"symbol":"LTC/USD","bids":[{"price":83.10,"qty":290.62312925}],"asks":[],"checksum":2091570856,"timestamp":"2024-06-01T18:07:19.019585Z"}]}
{"channel":"book","type":"update","data":[{"symbol":"LTC/USD","bids":[{"price":83.16,"qty":45.50316761}],"asks":[],"checksum":3211298250,"timestamp":"2024-06-01T18:07:19.022076Z"}]}
{"channel":"book","type":"update","data":[{"symbol":"LTC/USD","bids":[],"asks":[{"price":83.23,"qty":98.60141750}],"checksum":3253902112,"timestamp":"2024-06-01T18:07:19.022263Z"}]}
{"channel":"book","type":"update","data":[{"symbol":"LTC/USD","bids":[{"price":83.15,"qty":31.99604502}],"asks":[],"checksum":1321776797,"timestamp":"2024-06-01T18:07:19.022380Z"}]}
{"channel":"book","type":"update","data":[{"symbol":"LTC/USD","bids":[{"price":83.14,"qty":123.44365157}],"asks":[],"checksum":3283722526,"timestamp":"2024-06-01T18:07:19.031424Z"}]}
{"channel":"book","type":"update","data":[{"symbol":"LTC/USD","bids":[],"asks":[{"price":83.22,"qty":165.53084882}],"checksum":177420960,"timestamp":"2024-06-01T18:07:19.031919Z"}]}
{"channel":"book","type":"update","data":[{"symbol":"LTC/USD","bids":[],"asks":[{"price":83.22,"qty":105.44751647}],"checksum":3801594147,"timestamp":"2024-06-01T18:07:19.033520Z"}]}
{"channel":"book","type":"update","data":[{"symbol":"LTC/USD","bids":[],"asks":[{"price":83.21,"qty":60.02424144}],"checksum":1856965039,"timestamp":"2024-06-01T18:07:19.034473Z"}]}
{"channel":"book","type":"update","data":[{"symbol":"LTC/USD","bids":[],"asks":[{"price":83.23,"qty":98.31649692}],"checksum":2811173382,"timestamp":"2024-06-01T18:07:19.037153Z"}]}
{"channel":"book","type":"update","data":[{"symbol":"LTC/USD","bids":[],"asks":[{"price":83.23,"qty":98.03157634}],"checksum":663432164,"timestamp":"2024-06-01T18:07:19.037173Z"}]}
{"channel":"book","type":"update","data":[{"symbol":"LTC/USD","bids":[],"asks":[{"price":83.21,"qty":120.11508916}],"checksum":1540456273,"timestamp":"2024-06-01T18:07:19.037348Z"}]}
{"channel":"book","type":"update","data":[{"symbol":"LTC/USD","bids":[],"asks":[{"price":83.23,"qty":97.74665576}],"checksum":3250896570,"timestamp":"2024-06-01T18:07:19.038131Z"}]}
{"channel":"book","type":"update","data":[{"symbol":"LTC/USD","bids":[],"asks":[{"price":83.24,"qty":107.55081974}],"checksum":2829191169,"timestamp":"2024-06-01T18:07:19.041089Z"}]}
{"channel":"book","type":"update","data":[{"symbol":"LTC/USD","bids":[],"asks":[{"price":83.23,"qty":95.29701651},{"price":83.22,"qty":107.89715572}],"checksum":1135580039,"timestamp":"2024-06-01T18:07:19.062250Z"}]}
{"channel":"book","type":"update","data":[{"symbol":"LTC/USD","bids":[],"asks":[{"price":83.24,"qty":107.26589916}],"checksum":2205950050,"timestamp":"2024-06-01T18:07:19.105308Z"}]}
{"channel":"book","type":"update","data":[{"symbol":"LTC/USD","bids":[],"asks":[{"price":83.22,"qty":99.76516139}],"checksum":3553661600,"timestamp":"2024-06-01T18:07:19.108360Z"}]}
{"channel":"book","type":"update","data":[{"symbol":"LTC/USD","bids":[],"asks":[{"price":83.26,"qty":4.91907602}],"checksum":2752839354,"timestamp":"2024-06-01T18:07:19.109639Z"}]}
{"channel":"book","type":"update","data":[{"symbol":"LTC/USD","bids":[],"asks":[{"price":83.29,"qty":129.07897818}],"checksum":1416068097,"timestamp":"2024-06-01T18:07:19.146698Z"}]}
{"channel":"book","type":"update","data":[{"symbol":"LTC/USD","bids":[{"price":83.12,"qty":96.00519045}],"asks":[],"checksum":2702814081,"timestamp":"2024-06-01T18:07:19.149314Z"}]}
{"channel":"book","type":"update","data":[{"symbol":"LTC/USD","bids":[{"price":83.13,"qty":103.21192187}],"asks":[],"checksum":1872592556,"timestamp":"2024-06-01T18:07:19.180326Z"}]}
{"channel":"book","type":"update","data":[{"symbol":"LTC/USD","bids":[],"asks":[{"price":83.23,"qty":103.95305784}],"checksum":4163662864,"timestamp":"2024-06-01T18:07:19.203059Z"}]}
{"channel":"book","type":"update","data":[{"symbol":"LTC/USD","bids":[{"price":83.13,"qty":99.01893201}],"asks":[],"checksum":3686150215,"timestamp":"2024-06-01T18:07:19.207158Z"}]}
{"channel":"book","type":"update","data":[{"symbol":"LTC/USD","bids":[],"asks":[{"price":83.29,"qty":9.01654572}],"checksum":1975349538,"timestamp":"2024-06-01T18:07:19.209904Z"}]}
{"channel":"book","type":"update","data":[{"symbol":"LTC/USD","bids":[],"asks":[{"price":83.20,"qty":65.85330068}],"checksum":2677547752,"timestamp":"2024-06-01T18:07:19.210281Z"}]}
{"channel":"book","type":"update","data":[{"symbol":"LTC/USD","bids":[],"asks":[{"price":83.24,"qty":227.40044985}],"checksum":76252093,"timestamp":"2024-06-01T18:07:19.211569Z"}]}
{"channel":"book","type":"update","data":[{"symbol":"LTC/USD","bids":[{"price":83.12,"qty":100.19868476}],"asks":[],"checksum":1949353956,"timestamp":"2024-06-01T18:07:19.211957Z"}]}
{"channel":"book","type":"update","data":[{"symbol":"LTC/USD","bids":[],"asks":[{"price":83.20,"qty":85.85330068}],"checksum":2358620008,"timestamp":"2024-06-01T18:07:19.214895Z"}]}
{"channel":"book","type":"update","data":[{"symbol":"LTC/USD","bids":[],"asks":[{"price":83.29,"qty":0.18517136}],"checksum":2831619638,"timestamp":"2024-06-01T18:07:19.216559Z"}]}
{"channel":"book","type":"update","data":[{"symbol":"LTC/USD","bids":[],"asks":[{"price":83.20,"qty":99.52664450}],"checksum":1764336200,"timestamp":"2024-06-01T18:07:19.217356Z"}]}
{"channel":"book","type":"update","data":[{"symbol":"LTC/USD","bids":[{"price":83.13,"qty":79.01893201}],"asks":[],"checksum":1313143416,"timestamp":"2024-06-01T18:07:19.217906Z"}]}
{"channel":"book","type":"update","data":[{"symbol":"LTC/USD","bids":[],"asks":[{"price":83.21,"qty":140.11508916}],"checksum":1406360539,"timestamp":"2024-06-01T18:07:19.218033Z"}]}
{"channel":"book","type":"update","data":[{"symbol":"LTC/USD","bids":[{"price":83.12,"qty":92.95121591}],"asks":[],"checksum":395951227,"timestamp":"2024-06-01T18:07:19.230175Z"}]}
{"channel":"book","type":"update","data":[{"symbol":"LTC/USD","bids":[{"price":83.12,"qty":138.45438352}],"asks":[],"checksum":1772736429,"timestamp":"2024-06-01T18:07:19.442929Z"}]}
{"channel":"book","type":"update","data":[{"symbol":"LTC/USD","bids":[{"price":83.13,"qty":86.26552904}],"asks":[],"checksum":3771849446,"timestamp":"2024-06-01T18:07:19.476242Z"}]}
{"channel":"book","type":"update","data":[{"symbol":"LTC/USD","bids":[],"asks":[{"price":83.22,"qty":79.76516139}],"checksum":2361248632,"timestamp":"2024-06-01T18:07:19.481661Z"}]}
{"channel":"book","type":"update","data":[{"symbol":"LTC/USD","bids":[],"asks":[{"price":83.21,"qty":126.44174534}],"checksum":1004540958,"timestamp":"2024-06-01T18:07:19.482433Z"}]}
{"channel":"book","type":"update","data":[{"symbol":"LTC/USD","bids":[],"asks":[{"price":83.20,"qty":79.52664450}],"checksum":4230410691,"timestamp":"2024-06-01T18:07:19.494341Z"}]}
{"channel":"book","type":"update","data":[{"symbol":"LTC/USD","bids":[{"price":83.13,"qty":79.01893201}],"asks":[],"checksum":1969153160,"timestamp":"2024-06-01T18:07:19.521213Z"}]}
{"channel":"book","type":"update","data":[{"symbol":"LTC/USD","bids":[],"asks":[{"price":83.20,"qty":99.52664450}],"checksum":2996306261,"timestamp":"2024-06-01T18:07:19.598032Z"}]}
{"channel":"book","type":"update","data":[{"symbol":"LTC/USD","bids":[{"price":83.17,"qty":7.68750000}],"asks":[],"checksum":3927033383,"timestamp":"2024-06-01T18:07:19.625575Z"}]}
{"channel":"book","type":"update","data":[{"symbol":"LTC/USD","bids":[{"price":83.13,"qty":86.26552904}],"asks":[],"checksum":3858167385,"timestamp":"2024-06-01T18:07:19.641378Z"}]}
{"channel":"book","type":"update","data":[{"symbol":"LTC/USD","bids":[{"price":83.17,"qty":0.00000000},{"price":83.08,"qty":67.86635432}],"asks":[],"checksum":1004540958,"timestamp":"2024-06-01T18:07:19.905811Z"}]}
{"channel":"book","type":"update","data":[{"symbol":"LTC/USD","bids":[{"price":83.17,"qty":7.68750000}],"asks":[],"checksum":3858167385,"timestamp":"2024-06-01T18:07:19.914388Z"}]}
{"channel":"book","type":"update","data":[{"symbol":"LTC/USD","bids":[{"price":83.17,"qty":0.00000000},{"price":83.08,"qty":67.86635432}],"asks":[],"checksum":1004540958,"timestamp":"2024-06-01T18:07:20.012235Z"}]}
{"channel":"book","type":"update","data":[{"symbol":"LTC/USD","bids":[],"asks":[{"price":83.21,"qty":126.20128989}],"checksum":1534537684,"timestamp":"2024-06-01T18:07:20.038819Z"}]}
{"channel":"book","type":"update","data":[{"symbol":"LTC/USD","bids":[{"price":83.12,"qty":158.45438352}],"asks":[],"checksum":3255925382,"timestamp":"2024-06-01T18:07:20.117369Z"}]}
{"channel":"book","type":"update","data":[{"symbol":"LTC/USD","bids":[{"price":83.14,"qty":115.89365157}],"asks":[],"checksum":77324388,"timestamp":"2024-06-01T18:07:21.442723Z"}]}
{"channel":"book","type":"update","data":[{"symbol":"LTC/USD","bids":[{"price":83.12,"qty":150.90438352}],"asks":[],"checksum":3398664790,"timestamp":"2024-06-01T18:07:21.448771Z"}]}
{"channel":"book","type":"update","data":[{"symbol":"LTC/USD","bids":[{"price":83.10,"qty":283.07312925}],"asks":[],"checksum":2478764866,"timestamp":"2024-06-01T18:07:21.477496Z"}]}
{"channel":"book","type":"update","data":[{"symbol":"LTC/USD","bids":[{"price":83.11,"qty":74.78863687}],"asks":[],"checksum":2919899558,"timestamp":"2024-06-01T18:07:21.488647Z"}]}
{"channel":"book","type":"update","data":[{"symbol":"LTC/USD","bids":[{"price":83.12,"qty":158.45438352},{"price":83.10,"qty":290.62312925}],"asks":[],"checksum":959394432,"timestamp":"2024-06-01T18:07:21.576511Z"}]}
{"channel":"book","type":"update","data":[{"symbol":"LTC/USD","bids":[{"price":83.14,"qty":123.44365157}],"asks":[],"checksum":4289046626,"timestamp":"2024-06-01T18:07:21.705022Z"}]}
{"channel":"book","type":"update","data":[{"symbol":"LTC/USD","bids":[{"price":83.15,"qty":31.54056512}],"asks":[],"checksum":1685570557,"timestamp":"2024-06-01T18:07:22.058055Z"}]}
{"channel":"book","type":"update","data":[{"symbol":"LTC/USD","bids":[{"price":83.14,"qty":119.76273200}],"asks":[],"checksum":3890175516,"timestamp":"2024-06-01T18:07:22.058206Z"}]}
{"channel":"book","type":"update","data":[{"symbol":"LTC/USD","bids":[{"price":83.11,"qty":67.74750000}],"asks":[],"checksum":4085612239,"timestamp":"2024-06-01T18:07:22.058286Z"}]}
{"channel":"book","type":"update","data":[{"symbol":"LTC/USD","bids":[{"price":83.15,"qty":32.27782309}],"asks":[],"checksum":1550171941,"timestamp":"2024-06-01T18:07:22.067250Z"}]}
{"channel":"book","type":"update","data":[{"symbol":"LTC/USD","bids":[{"price":83.11,"qty":73.58737701}],"asks":[],"checksum":1351946007,"timestamp":"2024-06-01T18:07:22.067347Z"}]}
{"channel":"book","type":"update","data":[{"symbol":"LTC/USD","bids":[{"price":83.13,"qty":91.30840890}],"asks":[],"checksum":586323296,"timestamp":"2024-06-01T18:07:22.067501Z"}]}
{"channel":"book","type":"update","data":[{"symbol":"LTC/USD","bids":[{"price":83.14,"qty":112.21273200}],"asks":[],"checksum":1277111691,"timestamp":"2024-06-01T18:07:22.157890Z"}]}
{"channel":"book","type":"update","data":[{"symbol":"LTC/USD","bids":[],"asks":[{"price":83.23,"qty":115.21111277}],"checksum":4068527444,"timestamp":"2024-06-01T18:07:22.161872Z"}]}
{"channel":"book","type":"update","data":[{"symbol":"LTC/USD","bids":[{"price":83.14,"qty":119.76273200}],"asks":[],"checksum":2624419263,"timestamp":"2024-06-01T18:07:22.447231Z"}]}
{"channel":"book","type":"update","data":[{"symbol":"LTC/USD","bids":[],"asks":[{"price":83.27,"qty":54.49546424}],"checksum":4111482348,"timestamp":"2024-06-01T18:07:23.135303Z"}]}
{"channel":"book","type":"update","data":[{"symbol":"LTC/USD","bids":[],"asks":[{"price":83.21,"qty":129.26128989}],"checksum":1561780393,"timestamp":"2024-06-01T18:07:23.135732Z"}]}
{"channel":"book","type":"update","data":[{"symbol":"LTC/USD","bids":[{"price":83.12,"qty":84.93416192},{"price":83.12,"qty":158.45438352}],"asks":[],"checksum":1561780393,"timestamp":"2024-06-01T18:07:23.318051Z"}]}
{"channel":"book","type":"update","data":[{"symbol":"LTC/USD","bids":[],"asks":[{"price":83.27,"qty":0.41346424}],"checksum":688733390,"timestamp":"2024-06-01T18:07:23.761191Z"}]}
{"channel":"book","type":"update","data":[{"symbol":"LTC/USD","bids":[],"asks":[{"price":83.25,"qty":67.08101062}],"checksum":468589588,"timestamp":"2024-06-01T18:07:23.763772Z"}]}
{"channel":"book","type":"update","data":[{"symbol":"LTC/USD","bids":[],"asks":[{"price":83.22,"qty":78.82682157}],"checksum":4028679337,"timestamp":"2024-06-01T18:07:24.882896Z"}]}
{"channel":"book","type":"update","data":[{"symbol":"LTC/USD","bids":[],"asks":[{"price":83.20,"qty":99.76712884}],"checksum":3944264590,"timestamp":"2024-06-01T18:07:24.883806Z"}]}
{"channel":"book","type":"update","data":[{"symbol":"LTC/USD","bids":[],"asks":[{"price":83.22,"qty":80.11719384}],"checksum":2858626558,"timestamp":"2024-06-01T18:07:24.884035Z"}]}
{"channel":"book","type":"update","data":[{"symbol":"LTC/USD","bids":[],"asks":[{"price":83.21,"qty":102.18686381}],"checksum":3272689300,"timestamp":"2024-06-01T18:07:26.607074Z"}]}
{"channel":"book","type":"update","data":[{"symbol":"LTC/USD","bids":[],"asks":[{"price":83.20,"qty":160.38655492}],"checksum":1540097451,"timestamp":"2024-06-01T18:07:26.611572Z"}]}
{"channel":"book","type":"update","data":[{"symbol":"LTC/USD","bids":[],"asks":[{"price":83.20,"qty":160.14607058}],"checksum":3540871433,"timestamp":"2024-06-01T18:07:27.261722Z"}]}
{"channel":"book","type":"update","data":[{"symbol":"LTC/USD","bids":[{"price":83.15,"qty":31.54056512}],"asks":[],"checksum":2095950051,"timestamp":"2024-06-01T18:07:27.756682Z"}]}
{"channel":"book","type":"update","data":[{"symbol":"LTC/USD","bids":[{"price":83.11,"qty":67.74750000}],"asks":[],"checksum":1880955089,"timestamp":"2024-06-01T18:07:27.756700Z"}]}
{"channel":"book","type":"update","data":[{"symbol":"LTC/USD","bids":[{"price":83.13,"qty":86.26552904}],"asks":[],"checksum":41583270,"timestamp":"2024-06-01T18:07:27.756756Z"}]}
{"channel":"book","type":"update","data":[{"symbol":"LTC/USD","bids":[{"price":83.13,"qty":87.79634243}],"asks":[],"checksum":1866951059,"timestamp":"2024-06-01T18:07:27.761249Z"}]}
{"channel":"book","type":"update","data":[{"symbol":"LTC/USD","bids":[{"price":83.11,"qty":77.84027153}],"asks":[],"checksum":3279661866,"timestamp":"2024-06-01T18:07:27.761415Z"}]}
{"channel":"book","type":"update","data":[{"symbol":"LTC/USD","bids":[{"price":83.13,"qty":80.54974540}],"asks":[],"checksum":1533200314,"timestamp":"2024-06-01T18:07:28.167689Z"}]}
{"channel":"book","type":"update","data":[{"symbol":"LTC/USD","bids":[{"price":83.13,"qty":87.79634243}],"asks":[],"checksum":3279661866,"timestamp":"2024-06-01T18:07:28.400699Z"}]}
{"channel":"book","type":"update","data":[{"symbol":"LTC/USD","bids":[{"price":83.14,"qty":112.21273200}],"asks":[],"checksum":2912293825,"timestamp":"2024-06-01T18:07:30.354021Z"}]}
{"channel":"book","type":"update","data":[{"symbol":"LTC/USD","bids":[{"price":83.13,"qty":86.26552904}],"asks":[],"checksum":3232495860,"timestamp":"2024-06-01T18:07:30.479575Z"}]}
{"channel":"book","type":"update","data":[{"symbol":"LTC/USD","bids":[{"price":83.11,"qty":67.74750000}],"asks":[],"checksum":1821850189,"timestamp":"2024-06-01T18:07:30.479766Z"}]}
{"channel":"book","type":"update","data":[{"symbol":"LTC/USD","bids":[{"price":83.13,"qty":88.01139727}],"asks":[],"checksum":1743364057,"timestamp":"2024-06-01T18:07:30.487527Z"}]}
{"channel":"book","type":"update","data":[{"symbol":"LTC/USD","bids":[{"price":83.11,"qty":76.97905459}],"asks":[],"checksum":1037415896,"timestamp":"2024-06-01T18:07:30.487563Z"}]}
{"channel":"book","type":"update","data":[{"symbol":"LTC/USD","bids":[{"price":83.14,"qty":119.76273200}],"asks":[],"checksum":1396182323,"timestamp":"2024-06-01T18:07:30.518768Z"}]}
{"channel":"book","type":"update","data":[{"symbol":"LTC/USD","bids":[{"price":83.17,"qty":7.68750000}],"asks":[],"checksum":1231458671,"timestamp":"2024-06-01T18:07:30.647226Z"}]}
{"channel":"book","type":"update","data":[{"symbol":"LTC/USD","bids":[{"price":83.17,"qty":0.00000000},{"price":83.08,"qty":67.86635432}],"asks":[],"checksum":1396182323,"timestamp":"2024-06-01T18:07:30.739492Z"}]}
{"channel":"book","type":"update","data":[{"symbol":"LTC/USD","bids":[{"price":83.14,"qty":112.21273200}],"asks":[],"checksum":1037415896,"timestamp":"2024-06-01T18:07:30.812413Z"}]}
{"channel":"book","type":"update","data":[{"symbol":"LTC/USD","bids":[{"price":83.14,"qty":119.76273200}],"asks":[],"checksum":1396182323,"timestamp":"2024-06-01T18:07:30.947041Z"}]}
{"channel":"book","type":"update","data":[{"symbol":"LTC/USD","bids":[{"price":83.17,"qty":7.68750000}],"asks":[],"checksum":1231458671,"timestamp":"2024-06-01T18:07:31.434635Z"}]}
{"channel":"book","type":"update","data":[{"symbol":"LTC/USD","bids":[{"price":83.17,"qty":0.00000000},{"price":83.08,"qty":67.86635432}],"asks":[],"checksum":1396182323,"timestamp":"2024-06-01T18:07:31.452379Z"}]}
{"channel":"book","type":"update","data":[{"symbol":"LTC/USD","bids":[{"price":83.17,"qty":7.68750000}],"asks":[],"checksum":1231458671,"timestamp":"2024-06-01T18:07:31.459100Z"}]}
{"channel":"book","type":"update","data":[{"symbol":"LTC/USD","bids":[],"asks":[{"price":83.24,"qty":107.26589916}],"checksum":4153954422,"timestamp":"2024-06-01T18:07:31.490393Z"}]}
{"channel":"book","type":"update","data":[{"symbol":"LTC/USD","bids":[],"asks":[{"price":83.29,"qty":120.24760382}],"checksum":1098220070,"timestamp":"2024-06-01T18:07:31.491978Z"}]}
{"channel":"book","type":"update","data":[{"symbol":"LTC/USD","bids":[{"price":83.17,"qty":0.00000000},{"price":83.08,"qty":67.86635432}],"asks":[],"checksum":1546708756,"timestamp":"2024-06-01T18:07:31.834985Z"}]}
{"channel":"book","type":"update","data":[{"symbol":"LTC/USD","bids":[{"price":83.17,"qty":7.68750000}],"asks":[],"checksum":1098220070,"timestamp":"2024-06-01T18:07:31.889007Z"}]}
{"channel":"book","type":"update","data":[{"symbol":"LTC/USD","bids":[],"asks":[{"price":83.22,"qty":78.82682157}],"checksum":2046625000,"timestamp":"2024-06-01T18:07:31.983788Z"}]}
{"channel":"book","type":"update","data":[{"symbol":"LTC/USD","bids":[],"asks":[{"price":83.22,"qty":79.99109514}],"checksum":1497642575,"timestamp":"2024-06-01T18:07:31.984272Z"}]}
{"channel":"book","type":"update","data":[{"symbol":"LTC/USD","bids":[{"price":83.17,"qty":0.00000000},{"price":83.08,"qty":67.86635432}],"asks":[],"checksum":1749421916,"timestamp":"2024-06-01T18:07:31.990446Z"}]}
{"channel":"book","type":"update","data":[{"symbol":"LTC/USD","bids":[{"price":83.17,"qty":7.68750000}],"asks":[],"checksum":1497642575,"timestamp":"2024-06-01T18:07:32.000654Z"}]}
{"channel":"book","type":"update","data":[{"symbol":"LTC/USD","bids":[{"price":83.17,"qty":0.00000000},{"price":83.08,"qty":67.86635432}],"asks":[],"checksum":1749421916,"timestamp":"2024-06-01T18:07:32.048000Z"}]}
{"channel":"book","type":"update","data":[{"symbol":"LTC/USD","bids":[{"price":83.17,"qty":7.68750000}],"asks":[],"checksum":1497642575,"timestamp":"2024-06-01T18:07:32.165896Z"}]}
{"channel":"book","type":"update","data":[{"symbol":"LTC/USD","bids":[{"price":83.17,"qty":0.00000000},{"price":83.08,"qty":67.86635432}],"asks":[],"checksum":1749421916,"timestamp":"2024-06-01T18:07:32.258157Z"}]}
{"channel":"book","type":"update","data":[{"symbol":"LTC/USD","bids":[{"price":83.17,"qty":7.68750000}],"asks":[],"checksum":1497642575,"timestamp":"2024-06-01T18:07:32.336264Z"}]}
{"channel":"book","type":"update","data":[{"symbol":"LTC/USD","bids":[{"price":83.17,"qty":0.00000000},{"price":83.08,"qty":67.86635432}],"asks":[],"checksum":1749421916,"timestamp":"2024-06-01T18:07:32.449042Z"}]}
{"channel":"book","type":"update","data":[{"symbol":"LTC/USD","bids":[{"price":83.17,"qty":7.68750000}],"asks":[],"checksum":1497642575,"timestamp":"2024-06-01T18:07:32.457714Z"}]}
{"channel":"book","type":"update","data":[{"symbol":"LTC/USD","bids":[{"price":83.17,"qty":0.00000000},{"price":83.08,"qty":67.86635432}],"asks":[],"checksum":1749421916,"timestamp":"2024-06-01T18:07:32.522056Z"}]}
{"channel":"book","type":"update","data":[{"symbol":"LTC/USD","bids":[{"price":83.11,"qty":67.74750000}],"asks":[],"checksum":846865757,"timestamp":"2024-06-01T18:07:33.151991Z"}]}
{"channel":"book","type":"update","data":[{"symbol":"LTC/USD","bids":[{"price":83.10,"qty":230.65312925},{"price":83.11,"qty":127.71750000}],"asks":[],"checksum":575196628,"timestamp":"2024-06-01T18:07:33.155391Z"}]}
{"channel":"book","type":"update","data":[{"symbol":"LTC/USD","bids":[{"price":83.11,"qty":137.59311654}],"asks":[],"checksum":356939130,"timestamp":"2024-06-01T18:07:33.161543Z"}]}
{"channel":"book","type":"update","data":[{"symbol":"LTC/USD","bids":[{"price":83.09,"qty":13.95661122}],"asks":[],"checksum":3910241455,"timestamp":"2024-06-01T18:07:33.220042Z"}]}
{"channel":"book","type":"update","data":[{"symbol":"LTC/USD","bids":[{"price":83.08,"qty":121.95335432}],"asks":[],"checksum":4236559444,"timestamp":"2024-06-01T18:07:33.222631Z"}]}
{"channel":"book","type":"update","data":[{"symbol":"LTC/USD","bids":[{"price":83.17,"qty":7.68750000}],"asks":[],"checksum":246418303,"timestamp":"2024-06-01T18:07:33.870846Z"}]}
{"channel":"book","type":"update","data":[{"symbol":"LTC/USD","bids":[{"price":83.17,"qty":0.00000000},{"price":83.08,"qty":121.95335432}],"asks":[],"checksum":4236559444,"timestamp":"2024-06-01T18:07:34.070660Z"}]}
{"channel":"book","type":"update","data":[{"symbol":"LTC/USD","bids":[{"price":83.17,"qty":7.68750000}],"asks":[],"checksum":246418303,"timestamp":"2024-06-01T18:07:34.148866Z"}]}
{"channel":"book","type":"update","data":[{"symbol":"LTC/USD","bids":[],"asks":[{"price":83.22,"qty":78.82682157}],"checksum":1176667142,"timestamp":"2024-06-01T18:07:34.346083Z"}]}
{"channel":"book","type":"update","data":[{"symbol":"LTC/USD","bids":[],"asks":[{"price":83.22,"qty":80.25503493}],"checksum":2834302283,"timestamp":"2024-06-01T18:07:34.347208Z"}]}
{"channel":"book","type":"update","data":[{"symbol":"LTC/USD","bids":[],"asks":[{"price":83.29,"qty":0.18517136}],"checksum":2145851851,"timestamp":"2024-06-01T18:07:34.644692Z"}]}
{"channel":"book","type":"update","data":[{"symbol":"LTC/USD","bids":[],"asks":[{"price":83.24,"qty":227.40044985}],"checksum":456282058,"timestamp":"2024-06-01T18:07:34.646225Z"}]}
{"channel":"book","type":"update","data":[{"symbol":"LTC/USD","bids":[],"asks":[{"price":83.24,"qty":187.89181008}],"checksum":59785348,"timestamp":"2024-06-01T18:07:34.801395Z"}]}
{"channel":"book","type":"update","data":[{"symbol":"LTC/USD","bids":[],"asks":[{"price":83.23,"qty":160.71428038}],"checksum":2217065595,"timestamp":"2024-06-01T18:07:35.122991Z"}]}
{"channel":"book","type":"update","data":[{"symbol":"LTC/USD","bids":[],"asks":[{"price":83.28,"qty":101.51523200}],"checksum":2940380992,"timestamp":"2024-06-01T18:07:35.156897Z"}]}
{"channel":"book","type":"update","data":[{"symbol":"LTC/USD","bids":[{"price":83.17,"qty":0.00000000},{"price":83.08,"qty":121.95335432}],"asks":[],"checksum":2067439705,"timestamp":"2024-06-01T18:07:35.646299Z"}]}
{"channel":"book","type":"update","data":[{"symbol":"LTC/USD","bids":[{"price":83.13,"qty":86.26552904}],"asks":[],"checksum":3366695774,"timestamp":"2024-06-01T18:07:35.913749Z"}]}
{"channel":"book","type":"update","data":[{"symbol":"LTC/USD","bids":[{"price":83.11,"qty":127.71750000}],"asks":[],"checksum":4193399561,"timestamp":"2024-06-01T18:07:35.913890Z"}]}
{"channel":"book","type":"update","data":[{"symbol":"LTC/USD","bids":[{"price":83.13,"qty":89.25126692}],"asks":[],"checksum":2779402231,"timestamp":"2024-06-01T18:07:35.922443Z"}]}
{"channel":"book","type":"update","data":[{"symbol":"LTC/USD","bids":[{"price":83.12,"qty":162.91833485}],"asks":[],"checksum":3272670858,"timestamp":"2024-06-01T18:07:35.922511Z"}]}
{"channel":"book","type":"update","data":[{"symbol":"LTC/USD","bids":[{"price":83.11,"qty":131.87659792}],"asks":[],"checksum":298480508,"timestamp":"2024-06-01T18:07:35.922700Z"}]}
{"channel":"book","type":"update","data":[{"symbol":"LTC/USD","bids":[{"price":83.17,"qty":7.68750000}],"asks":[],"checksum":1799444754,"timestamp":"2024-06-01T18:07:36.191481Z"}]}
{"channel":"book","type":"update","data":[{"symbol":"LTC/USD","bids":[{"price":83.17,"qty":0.00000000},{"price":83.08,"qty":121.95335432}],"asks":[],"checksum":298480508,"timestamp":"2024-06-01T18:07:36.446378Z"}]}
{"channel":"book","type":"update","data":[{"symbol":"LTC/USD","bids":[],"asks":[{"price":83.22,"qty":78.82682157}],"checksum":3442086526,"timestamp":"2024-06-01T18:07:36.657904Z"}]}
{"channel":"book","type":"update","data":[{"symbol":"LTC/USD","bids":[],"asks":[{"price":83.22,"qty":80.09373839}],"checksum":2537543139,"timestamp":"2024-06-01T18:07:36.658291Z"}]}
{"channel":"book","type":"update","data":[{"symbol":"LTC/USD","bids":[],"asks":[{"price":83.23,"qty":149.45622545}],"checksum":2642586722,"timestamp":"2024-06-01T18:07:36.923339Z"}]}
{"channel":"book","type":"update","data":[{"symbol":"LTC/USD","bids":[],"asks":[{"price":83.23,"qty":149.85845050}],"checksum":2883625447,"timestamp":"2024-06-01T18:07:37.368956Z"}]}
{"channel":"book","type":"update","data":[{"symbol":"LTC/USD","bids":[],"asks":[{"price":83.25,"qty":12.99701062}],"checksum":3948519001,"timestamp":"2024-06-01T18:07:37.949379Z"}]}
{"channel":"book","type":"update","data":[{"symbol":"LTC/USD","bids":[],"asks":[{"price":83.26,"qty":59.00807602}],"checksum":2119999779,"timestamp":"2024-06-01T18:07:37.951635Z"}]}
{"channel":"book","type":"update","data":[{"symbol":"LTC/USD","bids":[{"price":83.17,"qty":7.68750000}],"asks":[],"checksum":399450914,"timestamp":"2024-06-01T18:07:38.242525Z"}]}
{"channel":"book","type":"update","data":[{"symbol":"LTC/USD","bids":[{"price":83.17,"qty":0.00000000},{"price":83.08,"qty":121.95335432}],"asks":[],"checksum":2119999779,"timestamp":"2024-06-01T18:07:38.444542Z"}]}
{"channel":"book","type":"update","data":[{"symbol":"LTC/USD","bids":[{"price":83.17,"qty":7.68750000}],"asks":[],"checksum":399450914,"timestamp":"2024-06-01T18:07:38.550961Z"}]}
{"channel":"book","type":"update","data":[{"symbol":"LTC/USD","bids":[{"price":83.17,"qty":0.00000000},{"price":83.08,"qty":121.95335432}],"asks":[],"checksum":2119999779,"timestamp":"2024-06-01T18:07:38.601134Z"}]}
{"channel":"book","type":"update","data":[{"symbol":"LTC/USD","bids":[{"price":83.17,"qty":7.68750000}],"asks":[],"checksum":399450914,"timestamp":"2024-06-01T18:07:38.606292Z"}]}
{"channel":"book","type":"update","data":[{"symbol":"LTC/USD","bids":[{"price":83.17,"qty":0.00000000},{"price":83.08,"qty":121.95335432}],"asks":[],"checksum":2119999779,"timestamp":"2024-06-01T18:07:38.633414Z"}]}
{"channel":"book","type":"update","data":[{"symbol":"LTC/USD","bids":[{"price":83.17,"qty":7.68750000}],"asks":[],"checksum":399450914,"timestamp":"2024-06-01T18:07:38.654259Z"}]}
{"channel":"book","type":"update","data":[{"symbol":"LTC/USD","bids":[{"price":83.17,"qty":0.00000000},{"price":83.08,"qty":121.95335432}],"asks":[],"checksum":2119999779,"timestamp":"2024-06-01T18:07:38.657722Z"}]}
{"channel":"book","type":"update","data":[{"symbol":"LTC/USD","bids":[{"price":83.11,"qty":127.71750000}],"asks":[],"checksum":2894474453,"timestamp":"2024-06-01T18:07:38.741070Z"}]}
{"channel":"book","type":"update","data":[{"symbol":"LTC/USD","bids":[{"price":83.11,"qty":131.87154934}],"asks":[],"checksum":810004440,"timestamp":"2024-06-01T18:07:38.750392Z"}]}
{"channel":"book","type":"update","data":[{"symbol":"LTC/USD","bids":[{"price":83.14,"qty":112.21273200}],"asks":[],"checksum":1215811756,"timestamp":"2024-06-01T18:07:39.348460Z"}]}
{"channel":"book","type":"update","data":[{"symbol":"LTC/USD","bids":[{"price":83.14,"qty":119.76273200}],"asks":[],"checksum":810004440,"timestamp":"2024-06-01T18:07:39.526690Z"}]}
{"channel":"book","type":"update","data":[{"symbol":"LTC/USD","bids":[{"price":83.17,"qty":7.68750000}],"asks":[],"checksum":3702710798,"timestamp":"2024-06-01T18:07:39.564492Z"}]}
{"channel":"book","type":"update","data":[{"symbol":"LTC/USD","bids":[{"price":83.17,"qty":0.00000000},{"price":83.08,"qty":121.95335432}],"asks":[],"checksum":810004440,"timestamp":"2024-06-01T18:07:39.891643Z"}]}
{"channel":"book","type":"update","data":[{"symbol":"LTC/USD","bids":[{"price":83.17,"qty":7.68750000}],"asks":[],"checksum":3702710798,"timestamp":"2024-06-01T18:07:39.930360Z"}]}
{"channel":"book","type":"update","data":[{"symbol":"LTC/USD","bids":[{"price":83.17,"qty":0.00000000},{"price":83.08,"qty":121.95335432}],"asks":[],"checksum":810004440,"timestamp":"2024-06-01T18:07:40.101150Z"}]}
{"channel":"book","type":"update","data":[{"symbol":"LTC/USD","bids":[{"price":83.17,"qty":7.68750000}],"asks":[],"checksum":3702710798,"timestamp":"2024-06-01T18:07:40.184995Z"}]}
{"channel":"book","type":"update","data":[{"symbol":"LTC/USD","bids":[{"price":83.17,"qty":0.00000000},{"price":83.08,"qty":121.95335432}],"asks":[],"checksum":810004440,"timestamp":"2024-06-01T18:07:40.202127Z"}]}
{"channel":"book","type":"update","data":[{"symbol":"LTC/USD","bids":[{"price":83.14,"qty":116.75273200}],"asks":[],"checksum":316142608,"timestamp":"2024-06-01T18:07:40.270367Z"}]}
{"channel":"book","type":"update","data":[{"symbol":"LTC/USD","bids":[{"price":83.17,"qty":7.68750000}],"asks":[],"checksum":383185732,"timestamp":"2024-06-01T18:07:40.470254Z"}]}
