{"channel":"book","type":"snapshot","data":[{"symbol":"USD/CAD","bids":[{"price":1.36512,"qty":584.67808736},{"price":1.36511,"qty":72.88881272},{"price":1.36509,"qty":153.54928979},{"price":1.36508,"qty":2767.72756486},{"price":1.36477,"qty":852.48122914},{"price":1.36438,"qty":98.04687500},{"price":1.36437,"qty":4735.09526101},{"price":1.36436,"qty":3951.17187500},{"price":1.36393,"qty":776.15000000},{"price":1.36391,"qty":2202.57339978}],"asks":[{"price":1.36541,"qty":3817.57414007},{"price":1.36542,"qty":4921.49210000},{"price":1.36557,"qty":421.60074306},{"price":1.36579,"qty":1193.08873662},{"price":1.36601,"qty":684.22180000},{"price":1.36606,"qty":1797.25049943},{"price":1.36663,"qty":3417.27454042},{"price":1.36670,"qty":75.00000000},{"price":1.36724,"qty":776.15000000},{"price":1.36734,"qty":358.75373990}],"checksum":2277666098}]}
{"channel":"book","type":"update","data":[{"symbol":"USD/CAD","bids":[],"asks":[{"price":1.36663,"qty":0.00000000},{"price":1.36735,"qty":26439.34794814}],"checksum":149780189,"timestamp":"2024-06-01T18:06:48.827849Z"}]}
{"channel":"book","type":"update","data":[{"symbol":"USD/CAD","bids":[],"asks":[{"price":1.36663,"qty":3417.27454042}],"checksum":2277666098,"timestamp":"2024-06-01T18:06:48.858457Z"}]}
{"channel":"book","type":"update","data":[{"symbol":"USD/CAD","bids":[],"asks":[{"price":1.36734,"qty":0.00000000},{"price":1.36735,"qty":26439.34794814}],"checksum":482160490,"timestamp":"2024-06-01T18:06:49.010398Z"}]}
{"channel":"book","type":"update","data":[{"symbol":"USD/CAD","bids":[],"asks":[{"price":1.36734,"qty":341.93257695}],"checksum":3453789950,"timestamp":"2024-06-01T18:06:49.019185Z"}]}
{"channel":"book","type":"update","data":[{"symbol":"USD/CAD","bids":[],"asks":[{"price":1.36579,"qty":0.00000000},{"price":1.36735,"qty":26439.34794814}],"checksum":703913057,"timestamp":"2024-06-01T18:06:49.464857Z"}]}
{"channel":"book","type":"update","data":[{"symbol":"USD/CAD","bids":[],"asks":[{"price":1.36580,"qty":1110.75446488}],"checksum":3939701755,"timestamp":"2024-06-01T18:06:49.471010Z"}]}
{"channel":"book","type":"update","data":[{"symbol":"USD/CAD","bids":[],"asks":[{"price":1.36733,"qty":25001.73924531}],"checksum":1470907569,"timestamp":"2024-06-01T18:06:49.829955Z"}]}
{"channel":"book","type":"update","data":[{"symbol":"USD/CAD","bids":[{"price":1.36436,"qty":0.00000000},{"price":1.36321,"qty":310.96801758}],"asks":[],"checksum":1007856580,"timestamp":"2024-06-01T18:06:50.382755Z"}]}
{"channel":"book","type":"update","data":[{"symbol":"USD/CAD","bids":[{"price":1.36439,"qty":2000.00000000}],"asks":[],"checksum":2353236468,"timestamp":"2024-06-01T18:06:50.384322Z"}]}
{"channel":"book","type":"update","data":[{"symbol":"USD/CAD","bids":[{"price":1.36438,"qty":4049.21875000}],"asks":[],"checksum":3512465925,"timestamp":"2024-06-01T18:06:50.384409Z"}]}
{"channel":"book","type":"update","data":[{"symbol":"USD/CAD","bids":[{"price":1.36437,"qty":0.00000000},{"price":1.36321,"qty":310.96801758}],"asks":[],"checksum":1679436497,"timestamp":"2024-06-01T18:06:50.418908Z"}]}
{"channel":"book","type":"update","data":[{"symbol":"USD/CAD","bids":[{"price":1.36440,"qty":4734.99116235}],"asks":[],"checksum":2154378502,"timestamp":"2024-06-01T18:06:50.419102Z"}]}
{"channel":"book","type":"update","data":[{"symbol":"USD/CAD","bids":[{"price":1.36438,"qty":3951.17187500}],"asks":[],"checksum":3976118781,"timestamp":"2024-06-01T18:06:51.279780Z"}]}
{"channel":"book","type":"update","data":[{"symbol":"USD/CAD","bids":[{"price":1.36441,"qty":137.07031250}],"asks":[],"checksum":4031210482,"timestamp":"2024-06-01T18:06:51.284051Z"}]}
{"channel":"book","type":"update","data":[{"symbol":"USD/CAD","bids":[],"asks":[{"price":1.36542,"qty":0.00000000},{"price":1.36734,"qty":341.93257695},{"price":1.36556,"qty":4921.49210000}],"checksum":1005644230,"timestamp":"2024-06-01T18:06:51.302878Z"}]}
{"channel":"book","type":"update","data":[{"symbol":"USD/CAD","bids":[],"asks":[{"price":1.36541,"qty":0.00000000},{"price":1.36734,"qty":341.93257695},{"price":1.36555,"qty":3817.57414007}],"checksum":3247026947,"timestamp":"2024-06-01T18:06:51.306321Z"}]}
{"channel":"book","type":"update","data":[{"symbol":"USD/CAD","bids":[],"asks":[{"price":1.36556,"qty":0.00000000},{"price":1.36734,"qty":341.93257695},{"price":1.36554,"qty":4921.49210000}],"checksum":3582900012,"timestamp":"2024-06-01T18:06:51.334993Z"}]}
{"channel":"book","type":"update","data":[{"symbol":"USD/CAD","bids":[],"asks":[{"price":1.36555,"qty":0.00000000},{"price":1.36734,"qty":341.93257695},{"price":1.36553,"qty":3817.57414007}],"checksum":114483464,"timestamp":"2024-06-01T18:06:51.338225Z"}]}
{"channel":"book","type":"update","data":[{"symbol":"USD/CAD","bids":[],"asks":[{"price":1.36554,"qty":0.00000000},{"price":1.36734,"qty":341.93257695},{"price":1.36552,"qty":4921.49210000}],"checksum":3592779330,"timestamp":"2024-06-01T18:06:51.367180Z"}]}
{"channel":"book","type":"update","data":[{"symbol":"USD/CAD","bids":[],"asks":[{"price":1.36553,"qty":0.00000000},{"price":1.36734,"qty":341.93257695},{"price":1.36551,"qty":3817.57414007}],"checksum":1972646024,"timestamp":"2024-06-01T18:06:51.371283Z"}]}
{"channel":"book","type":"update","data":[{"symbol":"USD/CAD","bids":[],"asks":[{"price":1.36552,"qty":0.00000000},{"price":1.36734,"qty":341.93257695},{"price":1.36550,"qty":4921.49210000}],"checksum":1637037223,"timestamp":"2024-06-01T18:06:51.398216Z"}]}
{"channel":"book","type":"update","data":[{"symbol":"USD/CAD","bids":[],"asks":[{"price":1.36551,"qty":0.00000000},{"price":1.36734,"qty":341.93257695},{"price":1.36549,"qty":3817.57414007}],"checksum":2434437613,"timestamp":"2024-06-01T18:06:51.402295Z"}]}
{"channel":"book","type":"update","data":[{"symbol":"USD/CAD","bids":[],"asks":[{"price":1.36554,"qty":421.60074306}],"checksum":3525410999,"timestamp":"2024-06-01T18:06:51.477723Z"}]}
{"channel":"book","type":"update","data":[{"symbol":"USD/CAD","bids":[],"asks":[{"price":1.36550,"qty":0.00000000},{"price":1.36733,"qty":25001.73924531},{"price":1.36548,"qty":4921.49210000}],"checksum":2425739494,"timestamp":"2024-06-01T18:06:51.491936Z"}]}
{"channel":"book","type":"update","data":[{"symbol":"USD/CAD","bids":[],"asks":[{"price":1.36549,"qty":0.00000000},{"price":1.36733,"qty":25001.73924531},{"price":1.36547,"qty":3817.57414007}],"checksum":1433926302,"timestamp":"2024-06-01T18:06:51.508823Z"}]}
{"channel":"book","type":"update","data":[{"symbol":"USD/CAD","bids":[],"asks":[{"price":1.36547,"qty":0.00000000},{"price":1.36733,"qty":25001.73924531},{"price":1.36546,"qty":3817.57414007}],"checksum":412815082,"timestamp":"2024-06-01T18:06:51.513409Z"}]}
{"channel":"book","type":"update","data":[{"symbol":"USD/CAD","bids":[],"asks":[{"price":1.36546,"qty":0.00000000},{"price":1.36733,"qty":25001.73924531},{"price":1.36547,"qty":3817.57414007}],"checksum":1433926302,"timestamp":"2024-06-01T18:06:51.516807Z"}]}
{"channel":"book","type":"update","data":[{"symbol":"USD/CAD","bids":[],"asks":[{"price":1.36548,"qty":0.00000000},{"price":1.36733,"qty":25001.73924531},{"price":1.36546,"qty":4921.49210000}],"checksum":2785037640,"timestamp":"2024-06-01T18:06:51.524599Z"}]}
{"channel":"book","type":"update","data":[{"symbol":"USD/CAD","bids":[],"asks":[{"price":1.36547,"qty":0.00000000},{"price":1.36733,"qty":25001.73924531},{"price":1.36545,"qty":3817.57414007}],"checksum":2379485634,"timestamp":"2024-06-01T18:06:51.528703Z"}]}
{"channel":"book","type":"update","data":[{"symbol":"USD/CAD","bids":[],"asks":[{"price":1.36546,"qty":0.00000000},{"price":1.36732,"qty":341.93257695},{"price":1.36544,"qty":4921.49210000}],"checksum":1661014663,"timestamp":"2024-06-01T18:06:51.586278Z"}]}
{"channel":"book","type":"update","data":[{"symbol":"USD/CAD","bids":[],"asks":[{"price":1.36545,"qty":0.00000000},{"price":1.36732,"qty":341.93257695},{"price":1.36543,"qty":3817.57414007}],"checksum":2753010076,"timestamp":"2024-06-01T18:06:51.589667Z"}]}
{"channel":"book","type":"update","data":[{"symbol":"USD/CAD","bids":[],"asks":[{"price":1.36557,"qty":0.00000000},{"price":1.36732,"qty":341.93257695}],"checksum":4060109304,"timestamp":"2024-06-01T18:06:51.641869Z"}]}
{"channel":"book","type":"update","data":[{"symbol":"USD/CAD","bids":[],"asks":[{"price":1.36544,"qty":0.00000000},{"price":1.36733,"qty":25001.73924531},{"price":1.36553,"qty":4921.49210000}],"checksum":2165796556,"timestamp":"2024-06-01T18:06:51.649886Z"}]}
{"channel":"book","type":"update","data":[{"symbol":"USD/CAD","bids":[],"asks":[{"price":1.36543,"qty":0.00000000},{"price":1.36733,"qty":25001.73924531},{"price":1.36552,"qty":3817.57414007}],"checksum":2615067497,"timestamp":"2024-06-01T18:06:51.653617Z"}]}
{"channel":"book","type":"update","data":[{"symbol":"USD/CAD","bids":[],"asks":[{"price":1.36553,"qty":0.00000000},{"price":1.36733,"qty":25001.73924531},{"price":1.36551,"qty":4921.49210000}],"checksum":2953486307,"timestamp":"2024-06-01T18:06:51.680582Z"}]}
{"channel":"book","type":"update","data":[{"symbol":"USD/CAD","bids":[],"asks":[{"price":1.36552,"qty":0.00000000},{"price":1.36733,"qty":25001.73924531},{"price":1.36550,"qty":3817.57414007}],"checksum":1591712934,"timestamp":"2024-06-01T18:06:51.684351Z"}]}
{"channel":"book","type":"update","data":[{"symbol":"USD/CAD","bids":[],"asks":[{"price":1.36551,"qty":0.00000000},{"price":1.36733,"qty":25001.73924531},{"price":1.36549,"qty":4921.49210000}],"checksum":3137591414,"timestamp":"2024-06-01T18:06:51.718989Z"}]}
{"channel":"book","type":"update","data":[{"symbol":"USD/CAD","bids":[],"asks":[{"price":1.36550,"qty":0.00000000},{"price":1.36733,"qty":25001.73924531},{"price":1.36548,"qty":3817.57414007}],"checksum":4189552679,"timestamp":"2024-06-01T18:06:51.722272Z"}]}
{"channel":"book","type":"update","data":[{"symbol":"USD/CAD","bids":[],"asks":[{"price":1.36549,"qty":0.00000000},{"price":1.36733,"qty":25001.73924531},{"price":1.36547,"qty":4921.49210000}],"checksum":1012245087,"timestamp":"2024-06-01T18:06:52.380167Z"}]}
{"channel":"book","type":"update","data":[{"symbol":"USD/CAD","bids":[{"price":1.36393,"qty":2978.69110232}],"asks":[],"checksum":2903185713,"timestamp":"2024-06-01T18:06:52.383271Z"}]}
{"channel":"book","type":"update","data":[{"symbol":"USD/CAD","bids":[],"asks":[{"price":1.36548,"qty":0.00000000},{"price":1.36733,"qty":25001.73924531},{"price":1.36546,"qty":3817.57414007}],"checksum":3259504999,"timestamp":"2024-06-01T18:06:52.383951Z"}]}
{"channel":"book","type":"update","data":[{"symbol":"USD/CAD","bids":[{"price":1.36439,"qty":0.00000000},{"price":1.36317,"qty":290.96088409}],"asks":[],"checksum":2216295205,"timestamp":"2024-06-01T18:06:53.416166Z"}]}
{"channel":"book","type":"update","data":[{"symbol":"USD/CAD","bids":[{"price":1.36438,"qty":0.00000000},{"price":1.36316,"qty":79869.19021606}],"asks":[],"checksum":1034249442,"timestamp":"2024-06-01T18:06:53.416362Z"}]}
{"channel":"book","type":"update","data":[{"symbol":"USD/CAD","bids":[{"price":1.36316,"qty":0.00000000},{"price":1.36315,"qty":1455.02000000}],"asks":[],"checksum":3551667053,"timestamp":"2024-06-01T18:06:53.416774Z"}]}
{"channel":"book","type":"update","data":[{"symbol":"USD/CAD","bids":[{"price":1.36442,"qty":2000.00000000}],"asks":[],"checksum":3865367251,"timestamp":"2024-06-01T18:06:53.418076Z"}]}
{"channel":"book","type":"update","data":[{"symbol":"USD/CAD","bids":[{"price":1.36318,"qty":37121.09375000}],"asks":[],"checksum":4138560105,"timestamp":"2024-06-01T18:06:53.418248Z"}]}
{"channel":"book","type":"update","data":[{"symbol":"USD/CAD","bids":[{"price":1.36440,"qty":0.00000000},{"price":1.36317,"qty":290.96088409}],"asks":[],"checksum":3485692658,"timestamp":"2024-06-01T18:06:53.435995Z"}]}
{"channel":"book","type":"update","data":[{"symbol":"USD/CAD","bids":[{"price":1.36443,"qty":4734.88704095}],"asks":[],"checksum":463036452,"timestamp":"2024-06-01T18:06:53.436116Z"}]}
{"channel":"book","type":"update","data":[{"symbol":"USD/CAD","bids":[],"asks":[{"price":1.36547,"qty":0.00000000},{"price":1.36735,"qty":25001.73924531},{"price":1.36545,"qty":4921.49210000}],"checksum":3089639150,"timestamp":"2024-06-01T18:06:53.440402Z"}]}
{"channel":"book","type":"update","data":[{"symbol":"USD/CAD","bids":[],"asks":[{"price":1.36546,"qty":0.00000000},{"price":1.36735,"qty":25001.73924531},{"price":1.36544,"qty":3817.57414007}],"checksum":2888770241,"timestamp":"2024-06-01T18:06:53.445411Z"}]}
{"channel":"book","type":"update","data":[{"symbol":"USD/CAD","bids":[],"asks":[{"price":1.36545,"qty":0.00000000},{"price":1.36735,"qty":25001.73924531},{"price":1.36543,"qty":4921.49210000}],"checksum":2138272997,"timestamp":"2024-06-01T18:06:53.471875Z"}]}
{"channel":"book","type":"update","data":[{"symbol":"USD/CAD","bids":[],"asks":[{"price":1.36544,"qty":0.00000000},{"price":1.36735,"qty":25001.73924531},{"price":1.36542,"qty":3817.57414007}],"checksum":2944721839,"timestamp":"2024-06-01T18:06:53.475462Z"}]}
{"channel":"book","type":"update","data":[{"symbol":"USD/CAD","bids":[],"asks":[{"price":1.36543,"qty":0.00000000},{"price":1.36735,"qty":25001.73924531},{"price":1.36541,"qty":4921.49210000}],"checksum":204842341,"timestamp":"2024-06-01T18:06:53.503459Z"}]}
{"channel":"book","type":"update","data":[{"symbol":"USD/CAD","bids":[],"asks":[{"price":1.36542,"qty":0.00000000},{"price":1.36735,"qty":25001.73924531},{"price":1.36540,"qty":3817.57414007}],"checksum":405971274,"timestamp":"2024-06-01T18:06:53.507052Z"}]}
{"channel":"book","type":"update","data":[{"symbol":"USD/CAD","bids":[],"asks":[{"price":1.36541,"qty":0.00000000},{"price":1.36735,"qty":25001.73924531},{"price":1.36539,"qty":4921.49210000}],"checksum":1629533304,"timestamp":"2024-06-01T18:06:53.535080Z"}]}
{"channel":"book","type":"update","data":[{"symbol":"USD/CAD","bids":[],"asks":[{"price":1.36540,"qty":0.00000000},{"price":1.36735,"qty":25001.73924531},{"price":1.36662,"qty":3817.57414007}],"checksum":1283906830,"timestamp":"2024-06-01T18:06:53.538994Z"}]}
{"channel":"book","type":"update","data":[{"symbol":"USD/CAD","bids":[],"asks":[{"price":1.36539,"qty":0.00000000},{"price":1.36735,"qty":25001.73924531},{"price":1.36553,"qty":4921.49210000}],"checksum":481412317,"timestamp":"2024-06-01T18:06:53.567584Z"}]}
{"channel":"book","type":"update","data":[{"symbol":"USD/CAD","bids":[],"asks":[{"price":1.36662,"qty":0.00000000},{"price":1.36735,"qty":25001.73924531},{"price":1.36552,"qty":3817.57414007}],"checksum":710389973,"timestamp":"2024-06-01T18:06:53.570996Z"}]}
{"channel":"book","type":"update","data":[{"symbol":"USD/CAD","bids":[],"asks":[{"price":1.36553,"qty":0.00000000},{"price":1.36735,"qty":25001.73924531},{"price":1.36551,"qty":4921.49210000}],"checksum":2313614879,"timestamp":"2024-06-01T18:06:53.598589Z"}]}
{"channel":"book","type":"update","data":[{"symbol":"USD/CAD","bids":[],"asks":[{"price":1.36552,"qty":0.00000000},{"price":1.36735,"qty":25001.73924531},{"price":1.36550,"qty":3817.57414007}],"checksum":2648830512,"timestamp":"2024-06-01T18:06:53.687185Z"}]}
{"channel":"book","type":"update","data":[{"symbol":"USD/CAD","bids":[],"asks":[{"price":1.36551,"qty":0.00000000},{"price":1.36735,"qty":25001.73924531},{"price":1.36549,"qty":4921.49210000}],"checksum":1835554682,"timestamp":"2024-06-01T18:06:53.721913Z"}]}
{"channel":"book","type":"update","data":[{"symbol":"USD/CAD","bids":[{"price":1.36513,"qty":72.88881272}],"asks":[],"checksum":2761528424,"timestamp":"2024-06-01T18:06:53.736020Z"}]}
{"channel":"book","type":"update","data":[{"symbol":"USD/CAD","bids":[{"price":1.36512,"qty":0.00000000},{"price":1.36318,"qty":37121.09375000},{"price":1.36514,"qty":584.68139518}],"asks":[],"checksum":3427455651,"timestamp":"2024-06-01T18:06:53.836895Z"}]}
{"channel":"book","type":"update","data":[{"symbol":"USD/CAD","bids":[],"asks":[{"price":1.36550,"qty":0.00000000},{"price":1.36735,"qty":25001.73924531},{"price":1.36548,"qty":3817.57414007}],"checksum":3398102922,"timestamp":"2024-06-01T18:06:53.837092Z"}]}
{"channel":"book","type":"update","data":[{"symbol":"USD/CAD","bids":[{"price":1.36511,"qty":0.00000000},{"price":1.36318,"qty":37121.09375000}],"asks":[],"checksum":2201513588,"timestamp":"2024-06-01T18:06:53.898543Z"}]}
{"channel":"book","type":"update","data":[{"symbol":"USD/CAD","bids":[],"asks":[{"price":1.36549,"qty":0.00000000},{"price":1.36735,"qty":25001.73924531},{"price":1.36547,"qty":4921.49210000}],"checksum":2982025612,"timestamp":"2024-06-01T18:06:53.937781Z"}]}
{"channel":"book","type":"update","data":[{"symbol":"USD/CAD","bids":[],"asks":[{"price":1.36548,"qty":0.00000000},{"price":1.36735,"qty":25001.73924531},{"price":1.36546,"qty":3817.57414007}],"checksum":869903949,"timestamp":"2024-06-01T18:06:54.053345Z"}]}
{"channel":"book","type":"update","data":[{"symbol":"USD/CAD","bids":[],"asks":[{"price":1.36580,"qty":0.00000000},{"price":1.36735,"qty":25001.73924531}],"checksum":4004443291,"timestamp":"2024-06-01T18:06:54.056093Z"}]}
{"channel":"book","type":"update","data":[{"symbol":"USD/CAD","bids":[],"asks":[{"price":1.36581,"qty":1110.75446488}],"checksum":2279100413,"timestamp":"2024-06-01T18:06:54.060208Z"}]}
{"channel":"book","type":"update","data":[{"symbol":"USD/CAD","bids":[{"price":1.36441,"qty":0.00000000},{"price":1.36317,"qty":290.96088409}],"asks":[],"checksum":3455854759,"timestamp":"2024-06-01T18:06:54.511794Z"}]}
{"channel":"book","type":"update","data":[{"symbol":"USD/CAD","bids":[{"price":1.36317,"qty":0.00000000},{"price":1.36316,"qty":47838.72222900}],"asks":[],"checksum":4146746425,"timestamp":"2024-06-01T18:06:54.512151Z"}]}
{"channel":"book","type":"update","data":[{"symbol":"USD/CAD","bids":[{"price":1.36444,"qty":39.51171875}],"asks":[],"checksum":3311005861,"timestamp":"2024-06-01T18:06:54.513578Z"}]}
{"channel":"book","type":"update","data":[{"symbol":"USD/CAD","bids":[{"price":1.36319,"qty":389.85328674}],"asks":[],"checksum":1809219044,"timestamp":"2024-06-01T18:06:54.513652Z"}]}
{"channel":"book","type":"update","data":[{"symbol":"USD/CAD","bids":[],"asks":[{"price":1.36732,"qty":0.00000000},{"price":1.36735,"qty":25001.73924531}],"checksum":2782644706,"timestamp":"2024-06-01T18:06:54.674800Z"}]}
{"channel":"book","type":"update","data":[{"symbol":"USD/CAD","bids":[],"asks":[{"price":1.36734,"qty":341.93257695}],"checksum":975068217,"timestamp":"2024-06-01T18:06:54.679300Z"}]}
{"channel":"book","type":"update","data":[{"symbol":"USD/CAD","bids":[],"asks":[{"price":1.36547,"qty":0.00000000},{"price":1.36735,"qty":25001.73924531},{"price":1.36545,"qty":4921.49210000}],"checksum":1511539843,"timestamp":"2024-06-01T18:06:56.212418Z"}]}
{"channel":"book","type":"update","data":[{"symbol":"USD/CAD","bids":[],"asks":[{"price":1.36546,"qty":0.00000000},{"price":1.36735,"qty":25001.73924531},{"price":1.36544,"qty":3817.57414007}],"checksum":2172267905,"timestamp":"2024-06-01T18:06:56.216362Z"}]}
{"channel":"book","type":"update","data":[{"symbol":"USD/CAD","bids":[],"asks":[{"price":1.36545,"qty":0.00000000},{"price":1.36735,"qty":25001.73924531},{"price":1.36543,"qty":4921.49210000}],"checksum":1079608058,"timestamp":"2024-06-01T18:06:56.244015Z"}]}
{"channel":"book","type":"update","data":[{"symbol":"USD/CAD","bids":[],"asks":[{"price":1.36544,"qty":0.00000000},{"price":1.36735,"qty":25001.73924531},{"price":1.36542,"qty":3817.57414007}],"checksum":2544351496,"timestamp":"2024-06-01T18:06:56.346244Z"}]}
{"channel":"book","type":"update","data":[{"symbol":"USD/CAD","bids":[],"asks":[{"price":1.36543,"qty":0.00000000},{"price":1.36735,"qty":25001.73924531},{"price":1.36541,"qty":4921.49210000}],"checksum":4154565042,"timestamp":"2024-06-01T18:06:56.367274Z"}]}
{"channel":"book","type":"update","data":[{"symbol":"USD/CAD","bids":[],"asks":[{"price":1.36542,"qty":0.00000000},{"price":1.36735,"qty":25001.73924531},{"price":1.36662,"qty":3817.57414007}],"checksum":811869774,"timestamp":"2024-06-01T18:06:56.370739Z"}]}
{"channel":"book","type":"update","data":[{"symbol":"USD/CAD","bids":[],"asks":[{"price":1.36541,"qty":0.00000000},{"price":1.36735,"qty":25001.73924531},{"price":1.36553,"qty":4921.49210000}],"checksum":3231877882,"timestamp":"2024-06-01T18:06:56.399282Z"}]}
{"channel":"book","type":"update","data":[{"symbol":"USD/CAD","bids":[{"price":1.36442,"qty":0.00000000},{"price":1.36318,"qty":37121.09375000}],"asks":[],"checksum":483034667,"timestamp":"2024-06-01T18:06:56.473959Z"}]}
{"channel":"book","type":"update","data":[{"symbol":"USD/CAD","bids":[{"price":1.36318,"qty":0.00000000},{"price":1.36315,"qty":1455.02000000}],"asks":[],"checksum":1450487017,"timestamp":"2024-06-01T18:06:56.474172Z"}]}
{"channel":"book","type":"update","data":[{"symbol":"USD/CAD","bids":[{"price":1.36320,"qty":19560.54687500}],"asks":[],"checksum":1106976974,"timestamp":"2024-06-01T18:06:56.476195Z"}]}
{"channel":"book","type":"update","data":[{"symbol":"USD/CAD","bids":[{"price":1.36445,"qty":2000.00000000}],"asks":[],"checksum":1247119728,"timestamp":"2024-06-01T18:06:56.476225Z"}]}
{"channel":"book","type":"update","data":[{"symbol":"USD/CAD","bids":[{"price":1.36443,"qty":0.00000000},{"price":1.36319,"qty":389.85328674}],"asks":[],"checksum":2082924955,"timestamp":"2024-06-01T18:06:56.484947Z"}]}
{"channel":"book","type":"update","data":[{"symbol":"USD/CAD","bids":[{"price":1.36446,"qty":4734.78298868}],"asks":[],"checksum":990432728,"timestamp":"2024-06-01T18:06:56.485041Z"}]}
{"channel":"book","type":"update","data":[{"symbol":"USD/CAD","bids":[],"asks":[{"price":1.36662,"qty":0.00000000},{"price":1.36735,"qty":25001.73924531},{"price":1.36552,"qty":3817.57414007}],"checksum":338811558,"timestamp":"2024-06-01T18:06:56.510229Z"}]}
{"channel":"book","type":"update","data":[{"symbol":"USD/CAD","bids":[],"asks":[{"price":1.36733,"qty":14938.47832549}],"checksum":3323131336,"timestamp":"2024-06-01T18:06:56.909644Z"}]}
{"channel":"book","type":"update","data":[{"symbol":"USD/CAD","bids":[{"price":1.36444,"qty":0.00000000},{"price":1.36319,"qty":389.85328674}],"asks":[],"checksum":3338876469,"timestamp":"2024-06-01T18:06:57.754328Z"}]}
{"channel":"book","type":"update","data":[{"symbol":"USD/CAD","bids":[{"price":1.36319,"qty":0.00000000},{"price":1.36316,"qty":63756.77871704}],"asks":[],"checksum":3132331621,"timestamp":"2024-06-01T18:06:57.754363Z"}]}
{"channel":"book","type":"update","data":[{"symbol":"USD/CAD","bids":[{"price":1.36447,"qty":39.51171875}],"asks":[],"checksum":946417140,"timestamp":"2024-06-01T18:06:57.755372Z"}]}
{"channel":"book","type":"update","data":[{"symbol":"USD/CAD","bids":[{"price":1.36321,"qty":389.85328674}],"asks":[],"checksum":3370711143,"timestamp":"2024-06-01T18:06:57.755526Z"}]}
{"channel":"book","type":"update","data":[{"symbol":"USD/CAD","bids":[],"asks":[{"price":1.36553,"qty":0.00000000},{"price":1.36734,"qty":341.93257695},{"price":1.36551,"qty":4921.49210000}],"checksum":3316532741,"timestamp":"2024-06-01T18:06:58.670918Z"}]}
{"channel":"book","type":"update","data":[{"symbol":"USD/CAD","bids":[],"asks":[{"price":1.36552,"qty":0.00000000},{"price":1.36734,"qty":341.93257695},{"price":1.36550,"qty":3817.57414007}],"checksum":3287688729,"timestamp":"2024-06-01T18:06:58.674678Z"}]}
{"channel":"book","type":"update","data":[{"symbol":"USD/CAD","bids":[],"asks":[{"price":1.36551,"qty":0.00000000},{"price":1.36734,"qty":341.93257695},{"price":1.36549,"qty":4921.49210000}],"checksum":1170221193,"timestamp":"2024-06-01T18:06:58.703280Z"}]}
{"channel":"book","type":"update","data":[{"symbol":"USD/CAD","bids":[],"asks":[{"price":1.36550,"qty":0.00000000},{"price":1.36734,"qty":341.93257695},{"price":1.36548,"qty":3817.57414007}],"checksum":1508834739,"timestamp":"2024-06-01T18:06:58.708801Z"}]}
{"channel":"book","type":"update","data":[{"symbol":"USD/CAD","bids":[],"asks":[{"price":1.36549,"qty":0.00000000},{"price":1.36734,"qty":341.93257695},{"price":1.36547,"qty":4921.49210000}],"checksum":133555871,"timestamp":"2024-06-01T18:06:58.735422Z"}]}
{"channel":"book","type":"update","data":[{"symbol":"USD/CAD","bids":[],"asks":[{"price":1.36548,"qty":0.00000000},{"price":1.36734,"qty":341.93257695},{"price":1.36546,"qty":3817.57414007}],"checksum":1756817097,"timestamp":"2024-06-01T18:06:58.777022Z"}]}
{"channel":"book","type":"update","data":[{"symbol":"USD/CAD","bids":[],"asks":[{"price":1.36547,"qty":0.00000000},{"price":1.36734,"qty":341.93257695},{"price":1.36545,"qty":4921.49210000}],"checksum":1710250155,"timestamp":"2024-06-01T18:06:58.798456Z"}]}
{"channel":"book","type":"update","data":[{"symbol":"USD/CAD","bids":[],"asks":[{"price":1.36546,"qty":0.00000000},{"price":1.36734,"qty":341.93257695},{"price":1.36544,"qty":3817.57414007}],"checksum":1671968951,"timestamp":"2024-06-01T18:06:58.878210Z"}]}
{"channel":"book","type":"update","data":[{"symbol":"USD/CAD","bids":[{"price":1.36445,"qty":0.00000000},{"price":1.36316,"qty":63756.77871704}],"asks":[],"checksum":2431348381,"timestamp":"2024-06-01T18:06:59.435192Z"}]}
{"channel":"book","type":"update","data":[{"symbol":"USD/CAD","bids":[{"price":1.36322,"qty":19560.54687500}],"asks":[],"checksum":3543460750,"timestamp":"2024-06-01T18:06:59.435634Z"}]}
{"channel":"book","type":"update","data":[{"symbol":"USD/CAD","bids":[{"price":1.36447,"qty":2039.51171875}],"asks":[],"checksum":1563692872,"timestamp":"2024-06-01T18:06:59.435711Z"}]}
{"channel":"book","type":"update","data":[{"symbol":"USD/CAD","bids":[{"price":1.36446,"qty":0.00000000},{"price":1.36316,"qty":63756.77871704}],"asks":[],"checksum":3834838878,"timestamp":"2024-06-01T18:06:59.478056Z"}]}
{"channel":"book","type":"update","data":[{"symbol":"USD/CAD","bids":[{"price":1.36448,"qty":4734.71356204}],"asks":[],"checksum":2645017343,"timestamp":"2024-06-01T18:06:59.478156Z"}]}
{"channel":"book","type":"update","data":[{"symbol":"USD/CAD","bids":[],"asks":[{"price":1.36732,"qty":341.93257695}],"checksum":500786573,"timestamp":"2024-06-01T18:06:59.850660Z"}]}
{"channel":"book","type":"update","data":[{"symbol":"USD/CAD","bids":[{"price":1.36447,"qty":2000.00000000}],"asks":[],"checksum":3948350495,"timestamp":"2024-06-01T18:07:00.928288Z"}]}
{"channel":"book","type":"update","data":[{"symbol":"USD/CAD","bids":[{"price":1.36321,"qty":0.00000000},{"price":1.36316,"qty":63756.77871704}],"asks":[],"checksum":837868516,"timestamp":"2024-06-01T18:07:00.928366Z"}]}
{"channel":"book","type":"update","data":[{"symbol":"USD/CAD","bids":[{"price":1.36449,"qty":20.00000000}],"asks":[],"checksum":1599704701,"timestamp":"2024-06-01T18:07:00.929023Z"}]}
{"channel":"book","type":"update","data":[{"symbol":"USD/CAD","bids":[{"price":1.36323,"qty":429.25781250}],"asks":[],"checksum":2827796767,"timestamp":"2024-06-01T18:07:00.929208Z"}]}
{"channel":"book","type":"update","data":[{"symbol":"USD/CAD","bids":[],"asks":[{"price":1.36545,"qty":0.00000000},{"price":1.36733,"qty":17813.11137767},{"price":1.36543,"qty":4921.49210000}],"checksum":1773104740,"timestamp":"2024-06-01T18:07:00.950872Z"}]}
{"channel":"book","type":"update","data":[{"symbol":"USD/CAD","bids":[],"asks":[{"price":1.36544,"qty":0.00000000},{"price":1.36733,"qty":17813.11137767},{"price":1.36542,"qty":3817.57414007}],"checksum":3193001366,"timestamp":"2024-06-01T18:07:00.954261Z"}]}
{"channel":"book","type":"update","data":[{"symbol":"USD/CAD","bids":[],"asks":[{"price":1.36542,"qty":0.00000000},{"price":1.36733,"qty":17813.11137767},{"price":1.36541,"qty":3817.57414007}],"checksum":1575887158,"timestamp":"2024-06-01T18:07:00.969320Z"}]}
{"channel":"book","type":"update","data":[{"symbol":"USD/CAD","bids":[],"asks":[{"price":1.36541,"qty":0.00000000},{"price":1.36733,"qty":17813.11137767},{"price":1.36542,"qty":3817.57414007}],"checksum":3193001366,"timestamp":"2024-06-01T18:07:00.972862Z"}]}
{"channel":"book","type":"update","data":[{"symbol":"USD/CAD","bids":[],"asks":[{"price":1.36543,"qty":0.00000000},{"price":1.36733,"qty":17813.11137767},{"price":1.36541,"qty":4921.49210000}],"checksum":3730263340,"timestamp":"2024-06-01T18:07:00.981573Z"}]}
{"channel":"book","type":"update","data":[{"symbol":"USD/CAD","bids":[],"asks":[{"price":1.36542,"qty":0.00000000},{"price":1.36733,"qty":17813.11137767},{"price":1.36662,"qty":3817.57414007}],"checksum":429050576,"timestamp":"2024-06-01T18:07:00.985270Z"}]}
{"channel":"book","type":"update","data":[{"symbol":"USD/CAD","bids":[],"asks":[{"price":1.36541,"qty":0.00000000},{"price":1.36733,"qty":17813.11137767},{"price":1.36553,"qty":4921.49210000}],"checksum":3914622564,"timestamp":"2024-06-01T18:07:01.013744Z"}]}
{"channel":"book","type":"update","data":[{"symbol":"USD/CAD","bids":[],"asks":[{"price":1.36662,"qty":0.00000000},{"price":1.36733,"qty":17813.11137767},{"price":1.36552,"qty":3817.57414007}],"checksum":828995921,"timestamp":"2024-06-01T18:07:01.017425Z"}]}
{"channel":"book","type":"update","data":[{"symbol":"USD/CAD","bids":[],"asks":[{"price":1.36553,"qty":0.00000000},{"price":1.36733,"qty":17813.11137767},{"price":1.36551,"qty":4921.49210000}],"checksum":1366254059,"timestamp":"2024-06-01T18:07:01.045825Z"}]}
{"channel":"book","type":"update","data":[{"symbol":"USD/CAD","bids":[],"asks":[{"price":1.36552,"qty":0.00000000},{"price":1.36733,"qty":17813.11137767},{"price":1.36550,"qty":3817.57414007}],"checksum":2316110057,"timestamp":"2024-06-01T18:07:01.166644Z"}]}
{"channel":"book","type":"update","data":[{"symbol":"USD/CAD","bids":[],"asks":[{"price":1.36581,"qty":0.00000000},{"price":1.36733,"qty":17813.11137767}],"checksum":1229725435,"timestamp":"2024-06-01T18:07:01.171498Z"}]}
{"channel":"book","type":"update","data":[{"symbol":"USD/CAD","bids":[],"asks":[{"price":1.36582,"qty":1109.93389281}],"checksum":2469884422,"timestamp":"2024-06-01T18:07:01.174516Z"}]}
{"channel":"book","type":"update","data":[{"symbol":"USD/CAD","bids":[],"asks":[{"price":1.36549,"qty":421.60074306}],"checksum":4125622036,"timestamp":"2024-06-01T18:07:02.063096Z"}]}
{"channel":"book","type":"update","data":[{"symbol":"USD/CAD","bids":[],"asks":[{"price":1.36550,"qty":0.00000000},{"price":1.36732,"qty":341.93257695},{"price":1.36548,"qty":3817.57414007}],"checksum":2711895147,"timestamp":"2024-06-01T18:07:02.066642Z"}]}
{"channel":"book","type":"update","data":[{"symbol":"USD/CAD","bids":[],"asks":[{"price":1.36554,"qty":0.00000000},{"price":1.36732,"qty":341.93257695}],"checksum":2835112516,"timestamp":"2024-06-01T18:07:02.237018Z"}]}
{"channel":"book","type":"update","data":[{"symbol":"USD/CAD","bids":[{"price":1.36447,"qty":0.00000000},{"price":1.36316,"qty":63756.77871704}],"asks":[],"checksum":3761449221,"timestamp":"2024-06-01T18:07:02.453745Z"}]}
{"channel":"book","type":"update","data":[{"symbol":"USD/CAD","bids":[{"price":1.36316,"qty":0.00000000},{"price":1.36315,"qty":1455.02000000}],"asks":[],"checksum":1732293367,"timestamp":"2024-06-01T18:07:02.453977Z"}]}
{"channel":"book","type":"update","data":[{"symbol":"USD/CAD","bids":[{"price":1.36449,"qty":2020.00000000}],"asks":[],"checksum":872648527,"timestamp":"2024-06-01T18:07:02.455464Z"}]}
{"channel":"book","type":"update","data":[{"symbol":"USD/CAD","bids":[{"price":1.36316,"qty":83900.39062500}],"asks":[],"checksum":191079709,"timestamp":"2024-06-01T18:07:02.455548Z"}]}
{"channel":"book","type":"update","data":[{"symbol":"USD/CAD","bids":[{"price":1.36450,"qty":4734.64416452}],"asks":[],"checksum":3828452248,"timestamp":"2024-06-01T18:07:02.470483Z"}]}
{"channel":"book","type":"update","data":[{"symbol":"USD/CAD","bids":[{"price":1.36448,"qty":0.00000000},{"price":1.36316,"qty":83900.39062500}],"asks":[],"checksum":543576933,"timestamp":"2024-06-01T18:07:02.470537Z"}]}
{"channel":"book","type":"update","data":[{"symbol":"USD/CAD","bids":[],"asks":[{"price":1.36551,"qty":0.00000000},{"price":1.36733,"qty":17813.11137767},{"price":1.36547,"qty":4921.49210000}],"checksum":3888866007,"timestamp":"2024-06-01T18:07:03.422663Z"}]}
{"channel":"book","type":"update","data":[{"symbol":"USD/CAD","bids":[],"asks":[{"price":1.36548,"qty":0.00000000},{"price":1.36733,"qty":17813.11137767},{"price":1.36546,"qty":3817.57414007}],"checksum":1705825558,"timestamp":"2024-06-01T18:07:03.426864Z"}]}
{"channel":"book","type":"update","data":[{"symbol":"USD/CAD","bids":[],"asks":[{"price":1.36547,"qty":0.00000000},{"price":1.36733,"qty":17813.11137767},{"price":1.36545,"qty":4921.49210000}],"checksum":3323827164,"timestamp":"2024-06-01T18:07:03.441736Z"}]}
{"channel":"book","type":"update","data":[{"symbol":"USD/CAD","bids":[],"asks":[{"price":1.36546,"qty":0.00000000},{"price":1.36733,"qty":17813.11137767},{"price":1.36544,"qty":3817.57414007}],"checksum":3524958195,"timestamp":"2024-06-01T18:07:03.523478Z"}]}
{"channel":"book","type":"update","data":[{"symbol":"USD/CAD","bids":[],"asks":[{"price":1.36545,"qty":0.00000000},{"price":1.36733,"qty":17813.11137767},{"price":1.36543,"qty":4921.49210000}],"checksum":21414359,"timestamp":"2024-06-01T18:07:03.535990Z"}]}
{"channel":"book","type":"update","data":[{"symbol":"USD/CAD","bids":[],"asks":[{"price":1.36544,"qty":0.00000000},{"price":1.36733,"qty":17813.11137767},{"price":1.36542,"qty":3817.57414007}],"checksum":3518060189,"timestamp":"2024-06-01T18:07:03.653876Z"}]}
{"channel":"book","type":"update","data":[{"symbol":"USD/CAD","bids":[],"asks":[{"price":1.36543,"qty":0.00000000},{"price":1.36733,"qty":17813.11137767},{"price":1.36541,"qty":4921.49210000}],"checksum":1912606807,"timestamp":"2024-06-01T18:07:03.689804Z"}]}
{"channel":"book","type":"update","data":[{"symbol":"USD/CAD","bids":[],"asks":[{"price":1.36542,"qty":0.00000000},{"price":1.36733,"qty":17813.11137767},{"price":1.36662,"qty":3817.57414007}],"checksum":3544475021,"timestamp":"2024-06-01T18:07:03.693483Z"}]}
{"channel":"book","type":"update","data":[{"symbol":"USD/CAD","bids":[],"asks":[{"price":1.36663,"qty":0.00000000},{"price":1.36733,"qty":17813.11137767}],"checksum":4198272690,"timestamp":"2024-06-01T18:07:03.859168Z"}]}
{"channel":"book","type":"update","data":[{"symbol":"USD/CAD","bids":[],"asks":[{"price":1.36662,"qty":0.00000000},{"price":1.36736,"qty":13500.40000000},{"price":1.36723,"qty":3817.57414007}],"checksum":548000589,"timestamp":"2024-06-01T18:07:03.862636Z"}]}
{"channel":"book","type":"update","data":[{"symbol":"USD/CAD","bids":[],"asks":[{"price":1.36664,"qty":3417.27454042}],"checksum":1340712895,"timestamp":"2024-06-01T18:07:03.887165Z"}]}
{"channel":"book","type":"update","data":[{"symbol":"USD/CAD","bids":[],"asks":[{"price":1.36723,"qty":0.00000000},{"price":1.36735,"qty":17736.11125840},{"price":1.36663,"qty":3817.57414007}],"checksum":3042245762,"timestamp":"2024-06-01T18:07:04.093490Z"}]}
{"channel":"book","type":"update","data":[{"symbol":"USD/CAD","bids":[{"price":1.36449,"qty":2000.00000000}],"asks":[],"checksum":1884266985,"timestamp":"2024-06-01T18:07:04.159003Z"}]}
{"channel":"book","type":"update","data":[{"symbol":"USD/CAD","bids":[{"price":1.36323,"qty":0.00000000},{"price":1.36315,"qty":1455.02000000}],"asks":[],"checksum":3143876389,"timestamp":"2024-06-01T18:07:04.159151Z"}]}
{"channel":"book","type":"update","data":[{"symbol":"USD/CAD","bids":[{"price":1.36451,"qty":20.00000000}],"asks":[],"checksum":3251460308,"timestamp":"2024-06-01T18:07:04.160006Z"}]}
{"channel":"book","type":"update","data":[{"symbol":"USD/CAD","bids":[{"price":1.36317,"qty":409.74609375}],"asks":[],"checksum":1125051955,"timestamp":"2024-06-01T18:07:04.160206Z"}]}
{"channel":"book","type":"update","data":[{"symbol":"USD/CAD","bids":[],"asks":[{"price":1.36541,"qty":0.00000000},{"price":1.36735,"qty":17736.11125840},{"price":1.36548,"qty":4921.49210000}],"checksum":2225187728,"timestamp":"2024-06-01T18:07:04.179410Z"}]}
{"channel":"book","type":"update","data":[{"symbol":"USD/CAD","bids":[],"asks":[{"price":1.36663,"qty":0.00000000},{"price":1.36735,"qty":17736.11125840},{"price":1.36547,"qty":3817.57414007}],"checksum":1229972330,"timestamp":"2024-06-01T18:07:04.282086Z"}]}
{"channel":"book","type":"update","data":[{"symbol":"USD/CAD","bids":[],"asks":[{"price":1.36548,"qty":0.00000000},{"price":1.36735,"qty":17736.11125840},{"price":1.36546,"qty":4921.49210000}],"checksum":2273934712,"timestamp":"2024-06-01T18:07:04.333650Z"}]}
{"channel":"book","type":"update","data":[{"symbol":"USD/CAD","bids":[{"price":1.36515,"qty":72.88881272}],"asks":[],"checksum":2686521433,"timestamp":"2024-06-01T18:07:04.349489Z"}]}
{"channel":"book","type":"update","data":[{"symbol":"USD/CAD","bids":[],"asks":[{"price":1.36547,"qty":0.00000000},{"price":1.36735,"qty":17736.11125840},{"price":1.36545,"qty":3817.57414007}],"checksum":381124550,"timestamp":"2024-06-01T18:07:04.502898Z"}]}
{"channel":"book","type":"update","data":[{"symbol":"USD/CAD","bids":[{"price":1.36514,"qty":0.00000000},{"price":1.36317,"qty":409.74609375},{"price":1.36516,"qty":587.59406892}],"asks":[],"checksum":2127535062,"timestamp":"2024-06-01T18:07:04.502959Z"}]}
{"channel":"book","type":"update","data":[{"symbol":"USD/CAD","bids":[{"price":1.36513,"qty":0.00000000},{"price":1.36317,"qty":409.74609375}],"asks":[],"checksum":3130381462,"timestamp":"2024-06-01T18:07:04.512127Z"}]}
{"channel":"book","type":"update","data":[{"symbol":"USD/CAD","bids":[{"price":1.36516,"qty":0.00000000},{"price":1.36316,"qty":83900.39062500},{"price":1.36510,"qty":587.61989534}],"asks":[],"checksum":1320245492,"timestamp":"2024-06-01T18:07:04.515564Z"}]}
{"channel":"book","type":"update","data":[{"symbol":"USD/CAD","bids":[{"price":1.36449,"qty":0.00000000},{"price":1.36316,"qty":83900.39062500}],"asks":[],"checksum":2622227393,"timestamp":"2024-06-01T18:07:05.457132Z"}]}
{"channel":"book","type":"update","data":[{"symbol":"USD/CAD","bids":[{"price":1.36316,"qty":0.00000000},{"price":1.36315,"qty":1455.02000000}],"asks":[],"checksum":3380403012,"timestamp":"2024-06-01T18:07:05.457301Z"}]}
{"channel":"book","type":"update","data":[{"symbol":"USD/CAD","bids":[{"price":1.36511,"qty":2000.00000000}],"asks":[],"checksum":2095095160,"timestamp":"2024-06-01T18:07:05.458223Z"}]}
{"channel":"book","type":"update","data":[{"symbol":"USD/CAD","bids":[{"price":1.36318,"qty":83900.39062500}],"asks":[],"checksum":3503785202,"timestamp":"2024-06-01T18:07:05.458340Z"}]}
{"channel":"book","type":"update","data":[{"symbol":"USD/CAD","bids":[{"price":1.36510,"qty":0.00000000},{"price":1.36317,"qty":409.74609375},{"price":1.36516,"qty":587.59166375}],"asks":[],"checksum":1427787028,"timestamp":"2024-06-01T18:07:05.461868Z"}]}
{"channel":"book","type":"update","data":[{"symbol":"USD/CAD","bids":[],"asks":[{"price":1.36732,"qty":0.00000000},{"price":1.36735,"qty":17736.11125840}],"checksum":3356790498,"timestamp":"2024-06-01T18:07:05.718550Z"}]}
{"channel":"book","type":"update","data":[{"symbol":"USD/CAD","bids":[],"asks":[{"price":1.36734,"qty":341.93257695}],"checksum":770029520,"timestamp":"2024-06-01T18:07:05.723226Z"}]}
{"channel":"book","type":"update","data":[{"symbol":"USD/CAD","bids":[],"asks":[{"price":1.36546,"qty":0.00000000},{"price":1.36735,"qty":17736.11125840},{"price":1.36544,"qty":4921.49210000}],"checksum":733861836,"timestamp":"2024-06-01T18:07:06.666817Z"}]}
{"channel":"book","type":"update","data":[{"symbol":"USD/CAD","bids":[],"asks":[{"price":1.36545,"qty":0.00000000},{"price":1.36735,"qty":17736.11125840},{"price":1.36543,"qty":3817.57414007}],"checksum":2703165611,"timestamp":"2024-06-01T18:07:06.671302Z"}]}
{"channel":"book","type":"update","data":[{"symbol":"USD/CAD","bids":[{"price":1.36451,"qty":0.00000000},{"price":1.36315,"qty":1455.02000000}],"asks":[],"checksum":3883164403,"timestamp":"2024-06-01T18:07:07.366257Z"}]}
{"channel":"book","type":"update","data":[{"symbol":"USD/CAD","bids":[{"price":1.36319,"qty":390.72265625}],"asks":[],"checksum":2862040263,"timestamp":"2024-06-01T18:07:07.367873Z"}]}
{"channel":"book","type":"update","data":[{"symbol":"USD/CAD","bids":[{"price":1.36394,"qty":4736.58807690}],"asks":[],"checksum":3337716363,"timestamp":"2024-06-01T18:07:07.373302Z"}]}
{"channel":"book","type":"update","data":[{"symbol":"USD/CAD","bids":[{"price":1.36450,"qty":0.00000000},{"price":1.36318,"qty":83900.39062500}],"asks":[],"checksum":22342603,"timestamp":"2024-06-01T18:07:07.373437Z"}]}
