{"channel":"book","type":"snapshot","data":[{"symbol":"USDC/AUD","bids":[{"price":1.5046,"qty":51.08104991},{"price":1.5045,"qty":2035.80657523},{"price":1.5042,"qty":271.45104775},{"price":1.5041,"qty":6208.12824808},{"price":1.5040,"qty":6733.87492716},{"price":1.5039,"qty":15689.20571199},{"price":1.5037,"qty":4963.47000000},{"price":1.5036,"qty":10603.08000000},{"price":1.5035,"qty":9566.58000000},{"price":1.5033,"qty":5089.59000000}],"asks":[{"price":1.5050,"qty":45.26898936},{"price":1.5051,"qty":10102.34677523},{"price":1.5052,"qty":5058.15804217},{"price":1.5053,"qty":12002.89541485},{"price":1.5054,"qty":15127.96000000},{"price":1.5055,"qty":41493.86943014},{"price":1.5056,"qty":2035.80657523},{"price":1.5065,"qty":1102.00000000},{"price":1.5068,"qty":1003.00000000},{"price":1.5069,"qty":1000.00000000}],"checksum":2758213711}]}
{"channel":"book","type":"update","data":[{"symbol":"USDC/AUD","bids":[],"asks":[{"price":1.5052,"qty":4960.66000000}],"checksum":2240690907,"timestamp":"2024-06-01T18:06:25.212675Z"}]}
{"channel":"book","type":"update","data":[{"symbol":"USDC/AUD","bids":[],"asks":[{"price":1.5051,"qty":10141.85712091}],"checksum":1120950124,"timestamp":"2024-06-01T18:06:25.213955Z"}]}
{"channel":"book","type":"update","data":[{"symbol":"USDC/AUD","bids":[],"asks":[{"price":1.5052,"qty":4999.07949457}],"checksum":3246879137,"timestamp":"2024-06-01T18:06:25.214090Z"}]}
{"channel":"book","type":"update","data":[{"symbol":"USDC/AUD","bids":[],"asks":[{"price":1.5053,"qty":342.00000000}],"checksum":2420770809,"timestamp":"2024-06-01T18:06:26.356579Z"}]}
{"channel":"book","type":"update","data":[{"symbol":"USDC/AUD","bids":[],"asks":[{"price":1.5053,"qty":8115.93022962}],"checksum":2594133799,"timestamp":"2024-06-01T18:06:26.357096Z"}]}
{"channel":"book","type":"update","data":[{"symbol":"USDC/AUD","bids":[],"asks":[{"price":1.5052,"qty":4960.66000000}],"checksum":507272496,"timestamp":"2024-06-01T18:06:27.991687Z"}]}
{"channel":"book","type":"update","data":[{"symbol":"USDC/AUD","bids":[],"asks":[{"price":1.5052,"qty":5038.06346823}],"checksum":1892717694,"timestamp":"2024-06-01T18:06:27.992398Z"}]}
{"channel":"book","type":"update","data":[{"symbol":"USDC/AUD","bids":[],"asks":[{"price":1.5053,"qty":342.00000000}],"checksum":181299069,"timestamp":"2024-06-01T18:06:29.925667Z"}]}
{"channel":"book","type":"update","data":[{"symbol":"USDC/AUD","bids":[],"asks":[{"price":1.5053,"qty":4228.96510805}],"checksum":2117138820,"timestamp":"2024-06-01T18:06:29.927724Z"}]}
{"channel":"book","type":"update","data":[{"symbol":"USDC/AUD","bids":[],"asks":[{"price":1.5051,"qty":10102.34677523}],"checksum":4160092927,"timestamp":"2024-06-01T18:06:30.828704Z"}]}
{"channel":"book","type":"update","data":[{"symbol":"USDC/AUD","bids":[],"asks":[{"price":1.5052,"qty":4960.66000000}],"checksum":2568565681,"timestamp":"2024-06-01T18:06:30.828826Z"}]}
{"channel":"book","type":"update","data":[{"symbol":"USDC/AUD","bids":[],"asks":[{"price":1.5052,"qty":5058.15804185}],"checksum":3256605,"timestamp":"2024-06-01T18:06:30.829330Z"}]}
{"channel":"book","type":"update","data":[{"symbol":"USDC/AUD","bids":[],"asks":[{"price":1.5052,"qty":4960.66000000}],"checksum":2568565681,"timestamp":"2024-06-01T18:06:33.647946Z"}]}
{"channel":"book","type":"update","data":[{"symbol":"USDC/AUD","bids":[],"asks":[{"price":1.5051,"qty":10160.78462826}],"checksum":1577544027,"timestamp":"2024-06-01T18:06:33.648937Z"}]}
{"channel":"book","type":"update","data":[{"symbol":"USDC/AUD","bids":[],"asks":[{"price":1.5053,"qty":342.00000000}],"checksum":1390086920,"timestamp":"2024-06-01T18:06:33.699007Z"}]}
{"channel":"book","type":"update","data":[{"symbol":"USDC/AUD","bids":[],"asks":[{"price":1.5051,"qty":356.43785303}],"checksum":1714292008,"timestamp":"2024-06-01T18:06:33.699046Z"}]}
{"channel":"book","type":"update","data":[{"symbol":"USDC/AUD","bids":[],"asks":[{"price":1.5051,"qty":12104.26716086}],"checksum":1880996652,"timestamp":"2024-06-01T18:06:33.700259Z"}]}
{"channel":"book","type":"update","data":[{"symbol":"USDC/AUD","bids":[{"price":1.5042,"qty":322.53209766}],"asks":[],"checksum":1507327725,"timestamp":"2024-06-01T18:06:35.075564Z"}]}
{"channel":"book","type":"update","data":[{"symbol":"USDC/AUD","bids":[{"price":1.5046,"qty":0.00000000},{"price":1.5028,"qty":97701.00000000}],"asks":[],"checksum":1378219885,"timestamp":"2024-06-01T18:06:35.244001Z"}]}
{"channel":"book","type":"update","data":[{"symbol":"USDC/AUD","bids":[{"price":1.5039,"qty":387.00000000}],"asks":[],"checksum":3902656692,"timestamp":"2024-06-01T18:06:35.247264Z"}]}
{"channel":"book","type":"update","data":[{"symbol":"USDC/AUD","bids":[],"asks":[{"price":1.5055,"qty":13459.31679986}],"checksum":2602123045,"timestamp":"2024-06-01T18:06:35.249622Z"}]}
{"channel":"book","type":"update","data":[{"symbol":"USDC/AUD","bids":[{"price":1.5039,"qty":15689.20571199}],"asks":[],"checksum":181059675,"timestamp":"2024-06-01T18:06:35.251890Z"}]}
{"channel":"book","type":"update","data":[{"symbol":"USDC/AUD","bids":[],"asks":[{"price":1.5055,"qty":41493.86943014}],"checksum":1378219885,"timestamp":"2024-06-01T18:06:35.254307Z"}]}
{"channel":"book","type":"update","data":[{"symbol":"USDC/AUD","bids":[],"asks":[{"price":1.5051,"qty":12045.82930783}],"checksum":3781299995,"timestamp":"2024-06-01T18:06:36.379109Z"}]}
{"channel":"book","type":"update","data":[{"symbol":"USDC/AUD","bids":[],"asks":[{"price":1.5053,"qty":400.47596042}],"checksum":2908641351,"timestamp":"2024-06-01T18:06:36.380058Z"}]}
{"channel":"book","type":"update","data":[{"symbol":"USDC/AUD","bids":[],"asks":[{"price":1.5051,"qty":298.00000000}],"checksum":1984088472,"timestamp":"2024-06-01T18:06:37.320860Z"}]}
{"channel":"book","type":"update","data":[{"symbol":"USDC/AUD","bids":[],"asks":[{"price":1.5051,"qty":10102.34673056}],"checksum":3416285722,"timestamp":"2024-06-01T18:06:37.322105Z"}]}
{"channel":"book","type":"update","data":[{"symbol":"USDC/AUD","bids":[],"asks":[{"price":1.5053,"qty":4287.44108100}],"checksum":3551396670,"timestamp":"2024-06-01T18:06:37.322160Z"}]}
{"channel":"book","type":"update","data":[{"symbol":"USDC/AUD","bids":[],"asks":[{"price":1.5053,"qty":4228.96512058}],"checksum":1139407810,"timestamp":"2024-06-01T18:06:39.046447Z"}]}
{"channel":"book","type":"update","data":[{"symbol":"USDC/AUD","bids":[],"asks":[{"price":1.5051,"qty":10141.29259737}],"checksum":3947891347,"timestamp":"2024-06-01T18:06:39.087515Z"}]}
{"channel":"book","type":"update","data":[{"symbol":"USDC/AUD","bids":[],"asks":[{"price":1.5053,"qty":342.00000000}],"checksum":1504850411,"timestamp":"2024-06-01T18:06:44.528260Z"}]}
{"channel":"book","type":"update","data":[{"symbol":"USDC/AUD","bids":[],"asks":[{"price":1.5051,"qty":10102.34673056}],"checksum":2275161414,"timestamp":"2024-06-01T18:06:47.469274Z"}]}
{"channel":"book","type":"update","data":[{"symbol":"USDC/AUD","bids":[],"asks":[{"price":1.5053,"qty":439.49804321}],"checksum":157498281,"timestamp":"2024-06-01T18:06:47.470337Z"}]}
{"channel":"book","type":"update","data":[{"symbol":"USDC/AUD","bids":[{"price":1.5039,"qty":387.00000000}],"asks":[],"checksum":1483002870,"timestamp":"2024-06-01T18:06:50.371638Z"}]}
{"channel":"book","type":"update","data":[{"symbol":"USDC/AUD","bids":[],"asks":[{"price":1.5055,"qty":13459.31679986}],"checksum":736115815,"timestamp":"2024-06-01T18:06:50.373972Z"}]}
{"channel":"book","type":"update","data":[{"symbol":"USDC/AUD","bids":[{"price":1.5039,"qty":15689.20571199}],"asks":[],"checksum":1368132767,"timestamp":"2024-06-01T18:06:50.376356Z"}]}
{"channel":"book","type":"update","data":[{"symbol":"USDC/AUD","bids":[],"asks":[{"price":1.5055,"qty":41493.86943014}],"checksum":157498281,"timestamp":"2024-06-01T18:06:50.378870Z"}]}
{"channel":"book","type":"update","data":[{"symbol":"USDC/AUD","bids":[],"asks":[{"price":1.5053,"qty":342.00000000}],"checksum":2275161414,"timestamp":"2024-06-01T18:06:53.053678Z"}]}
{"channel":"book","type":"update","data":[{"symbol":"USDC/AUD","bids":[],"asks":[{"price":1.5053,"qty":419.98700088}],"checksum":1146807714,"timestamp":"2024-06-01T18:06:53.054343Z"}]}
{"channel":"book","type":"update","data":[{"symbol":"USDC/AUD","bids":[],"asks":[{"price":1.5050,"qty":25.21252308}],"checksum":4008339740,"timestamp":"2024-06-01T18:06:55.740083Z"}]}
{"channel":"book","type":"update","data":[{"symbol":"USDC/AUD","bids":[],"asks":[{"price":1.5053,"qty":342.00000000}],"checksum":757905912,"timestamp":"2024-06-01T18:06:55.740276Z"}]}
{"channel":"book","type":"update","data":[{"symbol":"USDC/AUD","bids":[],"asks":[{"price":1.5050,"qty":64.72286856}],"checksum":948787218,"timestamp":"2024-06-01T18:06:55.780446Z"}]}
{"channel":"book","type":"update","data":[{"symbol":"USDC/AUD","bids":[],"asks":[{"price":1.5053,"qty":400.47596055}],"checksum":954911463,"timestamp":"2024-06-01T18:06:55.780622Z"}]}
{"channel":"book","type":"update","data":[{"symbol":"USDC/AUD","bids":[],"asks":[{"price":1.5050,"qty":25.21252308}],"checksum":759900941,"timestamp":"2024-06-01T18:07:01.356107Z"}]}
{"channel":"book","type":"update","data":[{"symbol":"USDC/AUD","bids":[],"asks":[{"price":1.5053,"qty":342.00000000}],"checksum":757905912,"timestamp":"2024-06-01T18:07:01.356176Z"}]}
{"channel":"book","type":"update","data":[{"symbol":"USDC/AUD","bids":[],"asks":[{"price":1.5053,"qty":517.59936483}],"checksum":3075027838,"timestamp":"2024-06-01T18:07:01.361750Z"}]}
{"channel":"book","type":"update","data":[{"symbol":"USDC/AUD","bids":[],"asks":[{"price":1.5050,"qty":45.21182789}],"checksum":3085840034,"timestamp":"2024-06-01T18:07:01.361774Z"}]}
{"channel":"book","type":"update","data":[{"symbol":"USDC/AUD","bids":[],"asks":[{"price":1.5051,"qty":298.00000000}],"checksum":3392544338,"timestamp":"2024-06-01T18:07:02.260768Z"}]}
{"channel":"book","type":"update","data":[{"symbol":"USDC/AUD","bids":[],"asks":[{"price":1.5051,"qty":12053.45092476}],"checksum":1681201547,"timestamp":"2024-06-01T18:07:02.262439Z"}]}
{"channel":"book","type":"update","data":[{"symbol":"USDC/AUD","bids":[],"asks":[{"price":1.5053,"qty":342.00000000}],"checksum":4266693389,"timestamp":"2024-06-01T18:07:04.156667Z"}]}
{"channel":"book","type":"update","data":[{"symbol":"USDC/AUD","bids":[],"asks":[{"price":1.5053,"qty":439.55520508}],"checksum":2713393939,"timestamp":"2024-06-01T18:07:04.158400Z"}]}
{"channel":"book","type":"update","data":[{"symbol":"USDC/AUD","bids":[],"asks":[{"price":1.5055,"qty":13459.31679986}],"checksum":4183043109,"timestamp":"2024-06-01T18:07:05.438646Z"}]}
{"channel":"book","type":"update","data":[{"symbol":"USDC/AUD","bids":[{"price":1.5039,"qty":387.00000000}],"asks":[],"checksum":74352468,"timestamp":"2024-06-01T18:07:05.438703Z"}]}
{"channel":"book","type":"update","data":[{"symbol":"USDC/AUD","bids":[{"price":1.5039,"qty":15689.20571199}],"asks":[],"checksum":4183043109,"timestamp":"2024-06-01T18:07:05.443307Z"}]}
{"channel":"book","type":"update","data":[{"symbol":"USDC/AUD","bids":[],"asks":[{"price":1.5055,"qty":41493.86943014}],"checksum":2713393939,"timestamp":"2024-06-01T18:07:05.443362Z"}]}
