{"channel":"book","type":"snapshot","data":[{"symbol":"USDC/USDT","bids":[{"price":1.0008,"qty":100.15711970},{"price":1.0007,"qty":185003.22703592},{"price":1.0006,"qty":400538.42810427},{"price":1.0005,"qty":169162.25415064},{"price":1.0004,"qty":72199.15455000},{"price":1.0003,"qty":146762.69400000},{"price":1.0002,"qty":8014.35175000},{"price":1.0001,"qty":24678.00000000},{"price":1.0000,"qty":644578.60015079},{"price":0.9999,"qty":6690.70586326}],"asks":[{"price":1.0009,"qty":158021.35536640},{"price":1.0010,"qty":151654.04033353},{"price":1.0011,"qty":142474.33872739},{"price":1.0013,"qty":8007.00000000},{"price":1.0016,"qty":3327.61175000},{"price":1.0017,"qty":3012.87679986},{"price":1.0021,"qty":300.00000000},{"price":1.0022,"qty":10570.65051720},{"price":1.0023,"qty":21289.23663382},{"price":1.0028,"qty":10280.15375162}],"checksum":1482163842}]}
{"channel":"book","type":"update","data":[{"symbol":"USDC/USDT","bids":[{"price":1.0008,"qty":69.58680456}],"asks":[],"checksum":814308041,"timestamp":"2024-06-01T18:06:24.520770Z"}]}
{"channel":"book","type":"update","data":[{"symbol":"USDC/USDT","bids":[{"price":1.0007,"qty":183947.11705190}],"asks":[],"checksum":3382750151,"timestamp":"2024-06-01T18:06:24.520881Z"}]}
{"channel":"book","type":"update","data":[{"symbol":"USDC/USDT","bids":[{"price":1.0008,"qty":110.72812988}],"asks":[],"checksum":1350463410,"timestamp":"2024-06-01T18:06:24.526666Z"}]}
{"channel":"book","type":"update","data":[{"symbol":"USDC/USDT","bids":[{"price":1.0007,"qty":184801.88232707}],"asks":[],"checksum":3236184696,"timestamp":"2024-06-01T18:06:24.526753Z"}]}
{"channel":"book","type":"update","data":[{"symbol":"USDC/USDT","bids":[{"price":1.0007,"qty":157695.54106336}],"asks":[],"checksum":335168894,"timestamp":"2024-06-01T18:06:25.284412Z"}]}
{"channel":"book","type":"update","data":[{"symbol":"USDC/USDT","bids":[{"price":1.0006,"qty":181104.55685768}],"asks":[],"checksum":1671191188,"timestamp":"2024-06-01T18:06:25.284428Z"}]}
{"channel":"book","type":"update","data":[{"symbol":"USDC/USDT","bids":[{"price":1.0007,"qty":185847.98278670}],"asks":[],"checksum":2340637030,"timestamp":"2024-06-01T18:06:25.289388Z"}]}
{"channel":"book","type":"update","data":[{"symbol":"USDC/USDT","bids":[{"price":1.0006,"qty":399444.82415650}],"asks":[],"checksum":3371169881,"timestamp":"2024-06-01T18:06:25.289488Z"}]}
{"channel":"book","type":"update","data":[{"symbol":"USDC/USDT","bids":[],"asks":[{"price":1.0009,"qty":150168.11266058}],"checksum":2615679487,"timestamp":"2024-06-01T18:06:26.356503Z"}]}
{"channel":"book","type":"update","data":[{"symbol":"USDC/USDT","bids":[{"price":1.0006,"qty":181104.55685768}],"asks":[],"checksum":3632572608,"timestamp":"2024-06-01T18:06:28.866532Z"}]}
{"channel":"book","type":"update","data":[{"symbol":"USDC/USDT","bids":[{"price":1.0006,"qty":390087.38357984}],"asks":[],"checksum":486343470,"timestamp":"2024-06-01T18:06:28.869031Z"}]}
{"channel":"book","type":"update","data":[{"symbol":"USDC/USDT","bids":[{"price":1.0003,"qty":147805.95320257}],"asks":[],"checksum":3091060680,"timestamp":"2024-06-01T18:06:29.328031Z"}]}
{"channel":"book","type":"update","data":[{"symbol":"USDC/USDT","bids":[],"asks":[{"price":1.0015,"qty":1043.25920257}],"checksum":2140694232,"timestamp":"2024-06-01T18:06:29.328461Z"}]}
{"channel":"book","type":"update","data":[{"symbol":"USDC/USDT","bids":[{"price":1.0007,"qty":184993.21751153}],"asks":[],"checksum":3454374616,"timestamp":"2024-06-01T18:06:30.175049Z"}]}
{"channel":"book","type":"update","data":[{"symbol":"USDC/USDT","bids":[{"price":1.0007,"qty":185620.04537827}],"asks":[],"checksum":4204726257,"timestamp":"2024-06-01T18:06:30.177855Z"}]}
{"channel":"book","type":"update","data":[{"symbol":"USDC/USDT","bids":[{"price":1.0006,"qty":181104.55685768}],"asks":[],"checksum":1055304735,"timestamp":"2024-06-01T18:06:32.675175Z"}]}
{"channel":"book","type":"update","data":[{"symbol":"USDC/USDT","bids":[{"price":1.0006,"qty":400484.53885546}],"asks":[],"checksum":612410811,"timestamp":"2024-06-01T18:06:32.679773Z"}]}
{"channel":"book","type":"update","data":[{"symbol":"USDC/USDT","bids":[{"price":1.0007,"qty":184993.21751153}],"asks":[],"checksum":335163538,"timestamp":"2024-06-01T18:06:32.951669Z"}]}
{"channel":"book","type":"update","data":[{"symbol":"USDC/USDT","bids":[{"price":1.0007,"qty":185847.98278359}],"asks":[],"checksum":2102866524,"timestamp":"2024-06-01T18:06:32.957763Z"}]}
{"channel":"book","type":"update","data":[{"symbol":"USDC/USDT","bids":[{"price":1.0008,"qty":69.58680456}],"asks":[],"checksum":3057685526,"timestamp":"2024-06-01T18:06:35.550348Z"}]}
{"channel":"book","type":"update","data":[{"symbol":"USDC/USDT","bids":[{"price":1.0007,"qty":184993.21751153}],"asks":[],"checksum":3639449304,"timestamp":"2024-06-01T18:06:35.550619Z"}]}
{"channel":"book","type":"update","data":[{"symbol":"USDC/USDT","bids":[{"price":1.0007,"qty":185425.69241100}],"asks":[],"checksum":3417141566,"timestamp":"2024-06-01T18:06:35.552690Z"}]}
{"channel":"book","type":"update","data":[{"symbol":"USDC/USDT","bids":[{"price":1.0007,"qty":157273.25068766}],"asks":[],"checksum":1188041628,"timestamp":"2024-06-01T18:06:36.176950Z"}]}
{"channel":"book","type":"update","data":[{"symbol":"USDC/USDT","bids":[{"price":1.0006,"qty":181104.55685768}],"asks":[],"checksum":1555438136,"timestamp":"2024-06-01T18:06:36.176962Z"}]}
{"channel":"book","type":"update","data":[{"symbol":"USDC/USDT","bids":[{"price":1.0007,"qty":171136.07839803}],"asks":[],"checksum":2609032254,"timestamp":"2024-06-01T18:06:36.179721Z"}]}
{"channel":"book","type":"update","data":[{"symbol":"USDC/USDT","bids":[{"price":1.0005,"qty":393896.96431441}],"asks":[],"checksum":2790689130,"timestamp":"2024-06-01T18:06:36.179928Z"}]}
{"channel":"book","type":"update","data":[{"symbol":"USDC/USDT","bids":[{"price":1.0007,"qty":170703.60349856}],"asks":[],"checksum":1831492406,"timestamp":"2024-06-01T18:06:38.379765Z"}]}
{"channel":"book","type":"update","data":[{"symbol":"USDC/USDT","bids":[{"price":1.0008,"qty":110.72814155}],"asks":[],"checksum":1410547991,"timestamp":"2024-06-01T18:06:38.385649Z"}]}
{"channel":"book","type":"update","data":[{"symbol":"USDC/USDT","bids":[{"price":1.0007,"qty":171547.29754543}],"asks":[],"checksum":3309290060,"timestamp":"2024-06-01T18:06:38.385694Z"}]}
{"channel":"book","type":"update","data":[{"symbol":"USDC/USDT","bids":[{"price":1.0007,"qty":157684.46983506}],"asks":[],"checksum":2445973488,"timestamp":"2024-06-01T18:06:39.808957Z"}]}
{"channel":"book","type":"update","data":[{"symbol":"USDC/USDT","bids":[{"price":1.0005,"qty":169162.25415064}],"asks":[],"checksum":2887692964,"timestamp":"2024-06-01T18:06:39.809140Z"}]}
{"channel":"book","type":"update","data":[{"symbol":"USDC/USDT","bids":[{"price":1.0006,"qty":409785.79447094}],"asks":[],"checksum":2058103694,"timestamp":"2024-06-01T18:06:39.813740Z"}]}
{"channel":"book","type":"update","data":[{"symbol":"USDC/USDT","bids":[{"price":1.0007,"qty":186883.01223271}],"asks":[],"checksum":571876371,"timestamp":"2024-06-01T18:06:39.813758Z"}]}
{"channel":"book","type":"update","data":[{"symbol":"USDC/USDT","bids":[],"asks":[{"price":1.0009,"qty":1953.52622640}],"checksum":933014798,"timestamp":"2024-06-01T18:06:40.738819Z"}]}
{"channel":"book","type":"update","data":[{"symbol":"USDC/USDT","bids":[],"asks":[{"price":1.0012,"qty":149980.50133493}],"checksum":1140649971,"timestamp":"2024-06-01T18:06:40.744671Z"}]}
{"channel":"book","type":"update","data":[{"symbol":"USDC/USDT","bids":[],"asks":[{"price":1.0010,"qty":151722.24033353}],"checksum":2441250984,"timestamp":"2024-06-01T18:06:40.776102Z"}]}
{"channel":"book","type":"update","data":[{"symbol":"USDC/USDT","bids":[],"asks":[{"price":1.0009,"qty":7953.52622640}],"checksum":3801172410,"timestamp":"2024-06-01T18:06:40.851959Z"}]}
{"channel":"book","type":"update","data":[{"symbol":"USDC/USDT","bids":[{"price":1.0007,"qty":186039.31818584}],"asks":[],"checksum":3207831944,"timestamp":"2024-06-01T18:06:40.945155Z"}]}
{"channel":"book","type":"update","data":[{"symbol":"USDC/USDT","bids":[{"price":1.0007,"qty":186791.51162234}],"asks":[],"checksum":2170409727,"timestamp":"2024-06-01T18:06:40.949986Z"}]}
{"channel":"book","type":"update","data":[{"symbol":"USDC/USDT","bids":[{"price":1.0005,"qty":19146.79862878}],"asks":[],"checksum":2467298804,"timestamp":"2024-06-01T18:06:41.788419Z"}]}
{"channel":"book","type":"update","data":[{"symbol":"USDC/USDT","bids":[{"price":1.0008,"qty":150117.04920699}],"asks":[],"checksum":986453635,"timestamp":"2024-06-01T18:06:41.793105Z"}]}
{"channel":"book","type":"update","data":[{"symbol":"USDC/USDT","bids":[],"asks":[{"price":1.0009,"qty":6052.52622640}],"checksum":565603277,"timestamp":"2024-06-01T18:06:42.047227Z"}]}
{"channel":"book","type":"update","data":[{"symbol":"USDC/USDT","bids":[{"price":1.0008,"qty":151735.04920699}],"asks":[],"checksum":3708231272,"timestamp":"2024-06-01T18:06:42.306246Z"}]}
{"channel":"book","type":"update","data":[{"symbol":"USDC/USDT","bids":[{"price":1.0006,"qty":408779.40361855},{"price":1.0005,"qty":20153.29006996}],"asks":[],"checksum":3589194907,"timestamp":"2024-06-01T18:06:42.718619Z"}]}
{"channel":"book","type":"update","data":[{"symbol":"USDC/USDT","bids":[{"price":1.0006,"qty":180098.16600529}],"asks":[],"checksum":219585132,"timestamp":"2024-06-01T18:06:43.409645Z"}]}
{"channel":"book","type":"update","data":[{"symbol":"USDC/USDT","bids":[{"price":1.0007,"qty":157592.96922469}],"asks":[],"checksum":1328591173,"timestamp":"2024-06-01T18:06:43.409700Z"}]}
{"channel":"book","type":"update","data":[{"symbol":"USDC/USDT","bids":[{"price":1.0004,"qty":165709.96206480}],"asks":[],"checksum":538144324,"timestamp":"2024-06-01T18:06:43.414314Z"}]}
{"channel":"book","type":"update","data":[{"symbol":"USDC/USDT","bids":[{"price":1.0005,"qty":188483.19331431}],"asks":[],"checksum":934916380,"timestamp":"2024-06-01T18:06:43.414339Z"}]}
{"channel":"book","type":"update","data":[{"symbol":"USDC/USDT","bids":[{"price":1.0008,"qty":151693.90787000}],"asks":[],"checksum":4227020147,"timestamp":"2024-06-01T18:06:43.904208Z"}]}
{"channel":"book","type":"update","data":[{"symbol":"USDC/USDT","bids":[{"price":1.0007,"qty":156840.77578819}],"asks":[],"checksum":1411690166,"timestamp":"2024-06-01T18:06:43.904365Z"}]}
{"channel":"book","type":"update","data":[{"symbol":"USDC/USDT","bids":[{"price":1.0007,"qty":157019.34024711}],"asks":[],"checksum":3315870861,"timestamp":"2024-06-01T18:06:43.909545Z"}]}
{"channel":"book","type":"update","data":[{"symbol":"USDC/USDT","bids":[],"asks":[{"price":1.0009,"qty":89998.82832359}],"checksum":1699184044,"timestamp":"2024-06-01T18:06:44.530236Z"}]}
{"channel":"book","type":"update","data":[{"symbol":"USDC/USDT","bids":[{"price":1.0008,"qty":150075.90787000}],"asks":[],"checksum":2101099523,"timestamp":"2024-06-01T18:06:44.785582Z"}]}
{"channel":"book","type":"update","data":[{"symbol":"USDC/USDT","bids":[{"price":1.0007,"qty":156840.77578819}],"asks":[],"checksum":3971792440,"timestamp":"2024-06-01T18:06:46.708748Z"}]}
{"channel":"book","type":"update","data":[{"symbol":"USDC/USDT","bids":[{"price":1.0007,"qty":157149.49581098}],"asks":[],"checksum":1001124802,"timestamp":"2024-06-01T18:06:46.714438Z"}]}
{"channel":"book","type":"update","data":[{"symbol":"USDC/USDT","bids":[{"price":1.0004,"qty":72199.15455000}],"asks":[],"checksum":4127738896,"timestamp":"2024-06-01T18:06:47.045847Z"}]}
{"channel":"book","type":"update","data":[{"symbol":"USDC/USDT","bids":[{"price":1.0004,"qty":167720.94730368}],"asks":[],"checksum":3372332501,"timestamp":"2024-06-01T18:06:47.048180Z"}]}
{"channel":"book","type":"update","data":[{"symbol":"USDC/USDT","bids":[],"asks":[{"price":1.0009,"qty":6052.52622640}],"checksum":1776477428,"timestamp":"2024-06-01T18:06:48.118659Z"}]}
{"channel":"book","type":"update","data":[{"symbol":"USDC/USDT","bids":[],"asks":[{"price":1.0009,"qty":99754.34882105}],"checksum":2313706032,"timestamp":"2024-06-01T18:06:48.119708Z"}]}
{"channel":"book","type":"update","data":[{"symbol":"USDC/USDT","bids":[{"price":1.0008,"qty":152097.90787000}],"asks":[],"checksum":3382229778,"timestamp":"2024-06-01T18:06:48.372440Z"}]}
{"channel":"book","type":"update","data":[{"symbol":"USDC/USDT","bids":[{"price":1.0008,"qty":150075.90787000}],"asks":[],"checksum":2313706032,"timestamp":"2024-06-01T18:06:48.375726Z"}]}
{"channel":"book","type":"update","data":[{"symbol":"USDC/USDT","bids":[{"price":1.0001,"qty":1008.00000000}],"asks":[],"checksum":2421498747,"timestamp":"2024-06-01T18:06:48.828395Z"}]}
{"channel":"book","type":"update","data":[{"symbol":"USDC/USDT","bids":[{"price":1.0004,"qty":156064.40450368}],"asks":[],"checksum":4254305254,"timestamp":"2024-06-01T18:06:48.828524Z"}]}
{"channel":"book","type":"update","data":[{"symbol":"USDC/USDT","bids":[{"price":1.0004,"qty":159368.66470368}],"asks":[],"checksum":4006247496,"timestamp":"2024-06-01T18:06:49.029124Z"}]}
{"channel":"book","type":"update","data":[{"symbol":"USDC/USDT","bids":[{"price":1.0005,"qty":196459.29351431}],"asks":[],"checksum":1497564599,"timestamp":"2024-06-01T18:06:49.029166Z"}]}
{"channel":"book","type":"update","data":[{"symbol":"USDC/USDT","bids":[{"price":1.0001,"qty":20551.55710000}],"asks":[],"checksum":1269379879,"timestamp":"2024-06-01T18:06:49.029295Z"}]}
{"channel":"book","type":"update","data":[{"symbol":"USDC/USDT","bids":[{"price":1.0007,"qty":156840.77578819}],"asks":[],"checksum":2629730013,"timestamp":"2024-06-01T18:06:49.501929Z"}]}
{"channel":"book","type":"update","data":[{"symbol":"USDC/USDT","bids":[{"price":1.0007,"qty":157174.60196034}],"asks":[],"checksum":1265963406,"timestamp":"2024-06-01T18:06:49.507466Z"}]}
{"channel":"book","type":"update","data":[{"symbol":"USDC/USDT","bids":[{"price":1.0005,"qty":28129.39026996}],"asks":[],"checksum":4186183269,"timestamp":"2024-06-01T18:06:50.651790Z"}]}
{"channel":"book","type":"update","data":[{"symbol":"USDC/USDT","bids":[{"price":1.0004,"qty":63846.87195000}],"asks":[],"checksum":1813850345,"timestamp":"2024-06-01T18:06:50.651815Z"}]}
{"channel":"book","type":"update","data":[{"symbol":"USDC/USDT","bids":[{"price":1.0005,"qty":58374.03291699}],"asks":[],"checksum":281671278,"timestamp":"2024-06-01T18:06:50.656298Z"}]}
{"channel":"book","type":"update","data":[{"symbol":"USDC/USDT","bids":[{"price":1.0004,"qty":297667.94479800}],"asks":[],"checksum":2384140646,"timestamp":"2024-06-01T18:06:50.656368Z"}]}
{"channel":"book","type":"update","data":[{"symbol":"USDC/USDT","bids":[],"asks":[{"price":1.0009,"qty":6052.52622640}],"checksum":1363985260,"timestamp":"2024-06-01T18:06:51.716594Z"}]}
{"channel":"book","type":"update","data":[{"symbol":"USDC/USDT","bids":[],"asks":[{"price":1.0009,"qty":95852.13960144}],"checksum":1974801737,"timestamp":"2024-06-01T18:06:51.717808Z"}]}
{"channel":"book","type":"update","data":[{"symbol":"USDC/USDT","bids":[{"price":1.0008,"qty":151623.90787000}],"asks":[],"checksum":3374894650,"timestamp":"2024-06-01T18:06:51.969402Z"}]}
{"channel":"book","type":"update","data":[{"symbol":"USDC/USDT","bids":[{"price":1.0008,"qty":150075.90787000}],"asks":[],"checksum":1974801737,"timestamp":"2024-06-01T18:06:51.970605Z"}]}
{"channel":"book","type":"update","data":[{"symbol":"USDC/USDT","bids":[{"price":1.0007,"qty":156840.77578819}],"asks":[],"checksum":3003689128,"timestamp":"2024-06-01T18:06:52.380143Z"}]}
{"channel":"book","type":"update","data":[{"symbol":"USDC/USDT","bids":[{"price":1.0007,"qty":157199.04741621}],"asks":[],"checksum":2053384455,"timestamp":"2024-06-01T18:06:52.385651Z"}]}
{"channel":"book","type":"update","data":[{"symbol":"USDC/USDT","bids":[{"price":1.0005,"qty":58394.84459312}],"asks":[],"checksum":525855370,"timestamp":"2024-06-01T18:06:52.385680Z"}]}
{"channel":"book","type":"update","data":[{"symbol":"USDC/USDT","bids":[{"price":1.0004,"qty":63846.87195000}],"asks":[],"checksum":945196320,"timestamp":"2024-06-01T18:06:54.105071Z"}]}
{"channel":"book","type":"update","data":[{"symbol":"USDC/USDT","bids":[{"price":1.0004,"qty":341314.54283497}],"asks":[],"checksum":2285849087,"timestamp":"2024-06-01T18:06:54.110695Z"}]}
{"channel":"book","type":"update","data":[{"symbol":"USDC/USDT","bids":[{"price":1.0007,"qty":156840.77578819}],"asks":[],"checksum":1096009808,"timestamp":"2024-06-01T18:06:55.000353Z"}]}
{"channel":"book","type":"update","data":[{"symbol":"USDC/USDT","bids":[{"price":1.0005,"qty":58374.03291699}],"asks":[],"checksum":610274269,"timestamp":"2024-06-01T18:06:55.000426Z"}]}
{"channel":"book","type":"update","data":[{"symbol":"USDC/USDT","bids":[{"price":1.0005,"qty":59526.95055394}],"asks":[],"checksum":1460686282,"timestamp":"2024-06-01T18:06:55.002794Z"}]}
{"channel":"book","type":"update","data":[{"symbol":"USDC/USDT","bids":[{"price":1.0007,"qty":157184.79075874}],"asks":[],"checksum":418466685,"timestamp":"2024-06-01T18:06:55.002935Z"}]}
