{"channel":"book","type":"snapshot","data":[{"symbol":"USDT/AUD","bids":[{"price":1.5033,"qty":2392.93519270},{"price":1.5032,"qty":2789.00000000},{"price":1.5031,"qty":2650.00000000},{"price":1.5030,"qty":2640.00000000},{"price":1.5029,"qty":3710.82373900},{"price":1.5028,"qty":390.92831489},{"price":1.5027,"qty":10457.39218927},{"price":1.5026,"qty":16639.19752546},{"price":1.5025,"qty":10249.82682195},{"price":1.5023,"qty":25477.50000000}],"asks":[{"price":1.5037,"qty":20.01651362},{"price":1.5038,"qty":3862.06170586},{"price":1.5039,"qty":4564.79162626},{"price":1.5040,"qty":27583.79066775},{"price":1.5041,"qty":48674.04029117},{"price":1.5042,"qty":20063.47000000},{"price":1.5043,"qty":20000.00000000},{"price":1.5044,"qty":5264.59000000},{"price":1.5056,"qty":1002.00000000},{"price":1.5057,"qty":7301.00000000}],"checksum":3231202432}]}
{"channel":"book","type":"update","data":[{"symbol":"USDT/AUD","bids":[],"asks":[{"price":1.5038,"qty":4018.15045820}],"checksum":2383467325,"timestamp":"2024-06-01T18:06:16.413855Z"}]}
{"channel":"book","type":"update","data":[{"symbol":"USDT/AUD","bids":[],"asks":[{"price":1.5038,"qty":195.63309517},{"price":1.5037,"qty":3857.47128006}],"checksum":2943159402,"timestamp":"2024-06-01T18:06:16.417314Z"}]}
{"channel":"book","type":"update","data":[{"symbol":"USDT/AUD","bids":[],"asks":[{"price":1.5039,"qty":4408.70287392}],"checksum":3684053205,"timestamp":"2024-06-01T18:06:16.581065Z"}]}
{"channel":"book","type":"update","data":[{"symbol":"USDT/AUD","bids":[{"price":1.5028,"qty":351.38397206}],"asks":[],"checksum":3249164062,"timestamp":"2024-06-01T18:06:16.764621Z"}]}
{"channel":"book","type":"update","data":[{"symbol":"USDT/AUD","bids":[{"price":1.5028,"qty":405.57418680}],"asks":[],"checksum":1803578199,"timestamp":"2024-06-01T18:06:16.765366Z"}]}
{"channel":"book","type":"update","data":[{"symbol":"USDT/AUD","bids":[{"price":1.5029,"qty":5932.82373900}],"asks":[],"checksum":661685135,"timestamp":"2024-06-01T18:06:16.915357Z"}]}
{"channel":"book","type":"update","data":[{"symbol":"USDT/AUD","bids":[],"asks":[{"price":1.5039,"qty":533.52728170}],"checksum":1595734362,"timestamp":"2024-06-01T18:06:18.147871Z"}]}
{"channel":"book","type":"update","data":[{"symbol":"USDT/AUD","bids":[],"asks":[{"price":1.5040,"qty":2993.78515109}],"checksum":909763230,"timestamp":"2024-06-01T18:06:18.147985Z"}]}
{"channel":"book","type":"update","data":[{"symbol":"USDT/AUD","bids":[],"asks":[{"price":1.5039,"qty":6723.18095856}],"checksum":2147438692,"timestamp":"2024-06-01T18:06:18.152851Z"}]}
{"channel":"book","type":"update","data":[{"symbol":"USDT/AUD","bids":[],"asks":[{"price":1.5040,"qty":25896.92280843}],"checksum":2855352359,"timestamp":"2024-06-01T18:06:18.153078Z"}]}
{"channel":"book","type":"update","data":[{"symbol":"USDT/AUD","bids":[],"asks":[{"price":1.5038,"qty":156.08875234}],"checksum":4151217139,"timestamp":"2024-06-01T18:06:18.923916Z"}]}
{"channel":"book","type":"update","data":[{"symbol":"USDT/AUD","bids":[],"asks":[{"price":1.5037,"qty":3837.45476644}],"checksum":1604907716,"timestamp":"2024-06-01T18:06:18.924143Z"}]}
{"channel":"book","type":"update","data":[{"symbol":"USDT/AUD","bids":[],"asks":[{"price":1.5038,"qty":217.09147100}],"checksum":1265717271,"timestamp":"2024-06-01T18:06:18.929195Z"}]}
{"channel":"book","type":"update","data":[{"symbol":"USDT/AUD","bids":[{"price":1.5028,"qty":351.38397206}],"asks":[],"checksum":3780867166,"timestamp":"2024-06-01T18:06:19.984558Z"}]}
{"channel":"book","type":"update","data":[{"symbol":"USDT/AUD","bids":[{"price":1.5028,"qty":390.92831489}],"asks":[],"checksum":4217834389,"timestamp":"2024-06-01T18:06:19.986549Z"}]}
{"channel":"book","type":"update","data":[{"symbol":"USDT/AUD","bids":[],"asks":[{"price":1.5040,"qty":2993.78515109}],"checksum":2165908397,"timestamp":"2024-06-01T18:06:21.771913Z"}]}
{"channel":"book","type":"update","data":[{"symbol":"USDT/AUD","bids":[],"asks":[{"price":1.5039,"qty":533.52728170}],"checksum":1921296126,"timestamp":"2024-06-01T18:06:21.771938Z"}]}
{"channel":"book","type":"update","data":[{"symbol":"USDT/AUD","bids":[],"asks":[{"price":1.5040,"qty":27532.86121253}],"checksum":1274659790,"timestamp":"2024-06-01T18:06:21.776634Z"}]}
{"channel":"book","type":"update","data":[{"symbol":"USDT/AUD","bids":[],"asks":[{"price":1.5039,"qty":3582.17922270}],"checksum":2259235919,"timestamp":"2024-06-01T18:06:21.776880Z"}]}
{"channel":"book","type":"update","data":[{"symbol":"USDT/AUD","bids":[{"price":1.5033,"qty":0.00000000},{"price":1.5018,"qty":346.49580497},{"price":1.5033,"qty":2329.20457397}],"asks":[],"checksum":104396330,"timestamp":"2024-06-01T18:06:22.687534Z"}]}
{"channel":"book","type":"update","data":[{"symbol":"USDT/AUD","bids":[{"price":1.5026,"qty":4922.50000000}],"asks":[],"checksum":3285199388,"timestamp":"2024-06-01T18:06:23.959911Z"}]}
{"channel":"book","type":"update","data":[{"symbol":"USDT/AUD","bids":[{"price":1.5026,"qty":18103.78471614}],"asks":[],"checksum":93662864,"timestamp":"2024-06-01T18:06:23.960865Z"}]}
{"channel":"book","type":"update","data":[{"symbol":"USDT/AUD","bids":[],"asks":[{"price":1.5038,"qty":156.08875234}],"checksum":290229315,"timestamp":"2024-06-01T18:06:24.520804Z"}]}
{"channel":"book","type":"update","data":[{"symbol":"USDT/AUD","bids":[],"asks":[{"price":1.5039,"qty":3504.65194100}],"checksum":1075042793,"timestamp":"2024-06-01T18:06:24.520979Z"}]}
{"channel":"book","type":"update","data":[{"symbol":"USDT/AUD","bids":[],"asks":[{"price":1.5038,"qty":176.10526596}],"checksum":1885293002,"timestamp":"2024-06-01T18:06:24.526770Z"}]}
{"channel":"book","type":"update","data":[{"symbol":"USDT/AUD","bids":[],"asks":[{"price":1.5039,"qty":3606.48546239}],"checksum":828567445,"timestamp":"2024-06-01T18:06:24.527078Z"}]}
{"channel":"book","type":"update","data":[{"symbol":"USDT/AUD","bids":[],"asks":[{"price":1.5040,"qty":2993.78515109}],"checksum":4015085501,"timestamp":"2024-06-01T18:06:28.866802Z"}]}
{"channel":"book","type":"update","data":[{"symbol":"USDT/AUD","bids":[],"asks":[{"price":1.5040,"qty":25896.92280843}],"checksum":1936570885,"timestamp":"2024-06-01T18:06:28.869145Z"}]}
{"channel":"book","type":"update","data":[{"symbol":"USDT/AUD","bids":[],"asks":[{"price":1.5040,"qty":26053.01156077}],"checksum":731466882,"timestamp":"2024-06-01T18:06:29.035543Z"}]}
{"channel":"book","type":"update","data":[{"symbol":"USDT/AUD","bids":[],"asks":[{"price":1.5038,"qty":20.01651362}],"checksum":3208163971,"timestamp":"2024-06-01T18:06:29.203258Z"}]}
{"channel":"book","type":"update","data":[{"symbol":"USDT/AUD","bids":[],"asks":[{"price":1.5037,"qty":0.00000000},{"price":1.5058,"qty":1418.28198000},{"price":1.5038,"qty":3857.49173416}],"checksum":3314324929,"timestamp":"2024-06-01T18:06:29.206436Z"}]}
{"channel":"book","type":"update","data":[{"symbol":"USDT/AUD","bids":[],"asks":[{"price":1.5038,"qty":20.01651362},{"price":1.5037,"qty":3837.47522054}],"checksum":1874449708,"timestamp":"2024-06-01T18:06:29.210238Z"}]}
{"channel":"book","type":"update","data":[{"symbol":"USDT/AUD","bids":[],"asks":[{"price":1.5037,"qty":0.00000000},{"price":1.5058,"qty":1418.28198000},{"price":1.5038,"qty":3857.49173416}],"checksum":3314324929,"timestamp":"2024-06-01T18:06:29.214831Z"}]}
{"channel":"book","type":"update","data":[{"symbol":"USDT/AUD","bids":[],"asks":[{"price":1.5039,"qty":557.83352139}],"checksum":287912951,"timestamp":"2024-06-01T18:06:32.675222Z"}]}
{"channel":"book","type":"update","data":[{"symbol":"USDT/AUD","bids":[],"asks":[{"price":1.5039,"qty":5307.86140265}],"checksum":3908182744,"timestamp":"2024-06-01T18:06:32.680424Z"}]}
{"channel":"book","type":"update","data":[{"symbol":"USDT/AUD","bids":[{"price":1.5027,"qty":10486.68393309}],"asks":[],"checksum":2691262952,"timestamp":"2024-06-01T18:06:32.885131Z"}]}
{"channel":"book","type":"update","data":[{"symbol":"USDT/AUD","bids":[],"asks":[{"price":1.5038,"qty":3837.47522054}],"checksum":3128347860,"timestamp":"2024-06-01T18:06:35.550803Z"}]}
{"channel":"book","type":"update","data":[{"symbol":"USDT/AUD","bids":[{"price":1.5027,"qty":10457.39218927}],"asks":[],"checksum":4075653092,"timestamp":"2024-06-01T18:06:36.059754Z"}]}
{"channel":"book","type":"update","data":[{"symbol":"USDT/AUD","bids":[],"asks":[{"price":1.5039,"qty":5206.02788126}],"checksum":765731645,"timestamp":"2024-06-01T18:06:38.379873Z"}]}
{"channel":"book","type":"update","data":[{"symbol":"USDT/AUD","bids":[],"asks":[{"price":1.5038,"qty":3878.65193567}],"checksum":547768046,"timestamp":"2024-06-01T18:06:38.385970Z"}]}
{"channel":"book","type":"update","data":[{"symbol":"USDT/AUD","bids":[],"asks":[{"price":1.5039,"qty":5289.34621698}],"checksum":2373755588,"timestamp":"2024-06-01T18:06:38.386006Z"}]}
{"channel":"book","type":"update","data":[{"symbol":"USDT/AUD","bids":[{"price":1.5027,"qty":10486.68393309}],"asks":[],"checksum":3320310260,"timestamp":"2024-06-01T18:06:39.249544Z"}]}
{"channel":"book","type":"update","data":[{"symbol":"USDT/AUD","bids":[],"asks":[{"price":1.5037,"qty":156.08875234}],"checksum":879953529,"timestamp":"2024-06-01T18:06:41.419081Z"}]}
{"channel":"book","type":"update","data":[{"symbol":"USDT/AUD","bids":[],"asks":[{"price":1.5040,"qty":25896.92280843}],"checksum":1820848382,"timestamp":"2024-06-01T18:06:41.586725Z"}]}
{"channel":"book","type":"update","data":[{"symbol":"USDT/AUD","bids":[],"asks":[{"price":1.5039,"qty":539.31833572}],"checksum":3756489212,"timestamp":"2024-06-01T18:06:43.410114Z"}]}
{"channel":"book","type":"update","data":[{"symbol":"USDT/AUD","bids":[],"asks":[{"price":1.5040,"qty":2993.78515109}],"checksum":3096305153,"timestamp":"2024-06-01T18:06:43.410252Z"}]}
{"channel":"book","type":"update","data":[{"symbol":"USDT/AUD","bids":[],"asks":[{"price":1.5040,"qty":28514.42425498}],"checksum":339507255,"timestamp":"2024-06-01T18:06:43.414727Z"}]}
{"channel":"book","type":"update","data":[{"symbol":"USDT/AUD","bids":[],"asks":[{"price":1.5039,"qty":3587.97027672}],"checksum":1108794991,"timestamp":"2024-06-01T18:06:43.414758Z"}]}
{"channel":"book","type":"update","data":[{"symbol":"USDT/AUD","bids":[],"asks":[{"price":1.5037,"qty":115.17054293}],"checksum":3765971351,"timestamp":"2024-06-01T18:06:46.465941Z"}]}
{"channel":"book","type":"update","data":[{"symbol":"USDT/AUD","bids":[],"asks":[{"price":1.5038,"qty":3837.47522054}],"checksum":4284904318,"timestamp":"2024-06-01T18:06:46.708673Z"}]}
{"channel":"book","type":"update","data":[{"symbol":"USDT/AUD","bids":[],"asks":[{"price":1.5039,"qty":3504.65194100}],"checksum":4044680388,"timestamp":"2024-06-01T18:06:46.708854Z"}]}
{"channel":"book","type":"update","data":[{"symbol":"USDT/AUD","bids":[],"asks":[{"price":1.5038,"qty":3857.49173416}],"checksum":881346715,"timestamp":"2024-06-01T18:06:46.714404Z"}]}
{"channel":"book","type":"update","data":[{"symbol":"USDT/AUD","bids":[],"asks":[{"price":1.5039,"qty":3606.48546239}],"checksum":1974857412,"timestamp":"2024-06-01T18:06:46.714560Z"}]}
{"channel":"book","type":"update","data":[{"symbol":"USDT/AUD","bids":[{"price":1.5027,"qty":10457.39218927}],"asks":[],"checksum":1026467316,"timestamp":"2024-06-01T18:06:48.878340Z"}]}
{"channel":"book","type":"update","data":[{"symbol":"USDT/AUD","bids":[{"price":1.5027,"qty":10486.68393309}],"asks":[],"checksum":1974857412,"timestamp":"2024-06-01T18:06:52.119208Z"}]}
{"channel":"book","type":"update","data":[{"symbol":"USDT/AUD","bids":[],"asks":[{"price":1.5040,"qty":2993.78515109}],"checksum":1524956895,"timestamp":"2024-06-01T18:06:54.105246Z"}]}
{"channel":"book","type":"update","data":[{"symbol":"USDT/AUD","bids":[],"asks":[{"price":1.5040,"qty":30215.80019524}],"checksum":1260863129,"timestamp":"2024-06-01T18:06:54.111008Z"}]}
{"channel":"book","type":"update","data":[{"symbol":"USDT/AUD","bids":[],"asks":[{"price":1.5040,"qty":30351.42984288}],"checksum":31849334,"timestamp":"2024-06-01T18:06:54.283040Z"}]}
{"channel":"book","type":"update","data":[{"symbol":"USDT/AUD","bids":[],"asks":[{"price":1.5037,"qty":0.00000000},{"price":1.5058,"qty":1418.28198000}],"checksum":3365975510,"timestamp":"2024-06-01T18:06:54.449034Z"}]}
{"channel":"book","type":"update","data":[{"symbol":"USDT/AUD","bids":[],"asks":[{"price":1.5040,"qty":3129.41479873}],"checksum":3521585711,"timestamp":"2024-06-01T18:06:57.579846Z"}]}
{"channel":"book","type":"update","data":[{"symbol":"USDT/AUD","bids":[],"asks":[{"price":1.5039,"qty":557.83352139}],"checksum":3480352332,"timestamp":"2024-06-01T18:06:57.579931Z"}]}
{"channel":"book","type":"update","data":[{"symbol":"USDT/AUD","bids":[],"asks":[{"price":1.5039,"qty":6747.48719825}],"checksum":2494783516,"timestamp":"2024-06-01T18:06:57.584686Z"}]}
{"channel":"book","type":"update","data":[{"symbol":"USDT/AUD","bids":[],"asks":[{"price":1.5040,"qty":26686.92781771}],"checksum":3345013249,"timestamp":"2024-06-01T18:06:57.584713Z"}]}
{"channel":"book","type":"update","data":[{"symbol":"USDT/AUD","bids":[],"asks":[{"price":1.5038,"qty":3837.47522054}],"checksum":3716120381,"timestamp":"2024-06-01T18:06:57.776192Z"}]}
{"channel":"book","type":"update","data":[{"symbol":"USDT/AUD","bids":[],"asks":[{"price":1.5037,"qty":20.01651362}],"checksum":982395085,"timestamp":"2024-06-01T18:06:57.783686Z"}]}
{"channel":"book","type":"update","data":[{"symbol":"USDT/AUD","bids":[],"asks":[{"price":1.5038,"qty":3862.54614583}],"checksum":2725997072,"timestamp":"2024-06-01T18:06:57.783710Z"}]}
{"channel":"book","type":"update","data":[{"symbol":"USDT/AUD","bids":[{"price":1.5028,"qty":351.38397206}],"asks":[],"checksum":3091666395,"timestamp":"2024-06-01T18:06:58.585313Z"}]}
{"channel":"book","type":"update","data":[{"symbol":"USDT/AUD","bids":[{"price":1.5027,"qty":10457.39218927}],"asks":[],"checksum":4040974059,"timestamp":"2024-06-01T18:06:58.585333Z"}]}
{"channel":"book","type":"update","data":[{"symbol":"USDT/AUD","bids":[{"price":1.5028,"qty":405.57418680}],"asks":[],"checksum":1526102690,"timestamp":"2024-06-01T18:06:58.586761Z"}]}
{"channel":"book","type":"update","data":[{"symbol":"USDT/AUD","bids":[{"price":1.5026,"qty":4922.50000000}],"asks":[],"checksum":2769031205,"timestamp":"2024-06-01T18:07:00.168352Z"}]}
{"channel":"book","type":"update","data":[{"symbol":"USDT/AUD","bids":[{"price":1.5026,"qty":20300.66550217}],"asks":[],"checksum":1132631589,"timestamp":"2024-06-01T18:07:00.169187Z"}]}
{"channel":"book","type":"update","data":[{"symbol":"USDT/AUD","bids":[],"asks":[{"price":1.5038,"qty":3837.47522054}],"checksum":3682063608,"timestamp":"2024-06-01T18:07:00.672281Z"}]}
{"channel":"book","type":"update","data":[{"symbol":"USDT/AUD","bids":[],"asks":[{"price":1.5039,"qty":6645.65367686}],"checksum":2212051493,"timestamp":"2024-06-01T18:07:00.672368Z"}]}
{"channel":"book","type":"update","data":[{"symbol":"USDT/AUD","bids":[],"asks":[{"price":1.5038,"qty":3899.81215864}],"checksum":753790101,"timestamp":"2024-06-01T18:07:00.677651Z"}]}
{"channel":"book","type":"update","data":[{"symbol":"USDT/AUD","bids":[],"asks":[{"price":1.5039,"qty":6699.55325618}],"checksum":513215744,"timestamp":"2024-06-01T18:07:00.678035Z"}]}
{"channel":"book","type":"update","data":[{"symbol":"USDT/AUD","bids":[],"asks":[{"price":1.5039,"qty":509.89957932}],"checksum":3454421031,"timestamp":"2024-06-01T18:07:01.109596Z"}]}
{"channel":"book","type":"update","data":[{"symbol":"USDT/AUD","bids":[],"asks":[{"price":1.5039,"qty":5119.85071611}],"checksum":1870515616,"timestamp":"2024-06-01T18:07:01.114444Z"}]}
{"channel":"book","type":"update","data":[{"symbol":"USDT/AUD","bids":[],"asks":[{"price":1.5039,"qty":5255.48036375}],"checksum":3232451024,"timestamp":"2024-06-01T18:07:01.282393Z"}]}
{"channel":"book","type":"update","data":[{"symbol":"USDT/AUD","bids":[],"asks":[{"price":1.5040,"qty":26551.29817007}],"checksum":1443246690,"timestamp":"2024-06-01T18:07:01.458049Z"}]}
{"channel":"book","type":"update","data":[{"symbol":"USDT/AUD","bids":[{"price":1.5026,"qty":4922.50000000}],"asks":[],"checksum":4219805304,"timestamp":"2024-06-01T18:07:03.161372Z"}]}
{"channel":"book","type":"update","data":[{"symbol":"USDT/AUD","bids":[{"price":1.5027,"qty":2597.39206417}],"asks":[],"checksum":3850437091,"timestamp":"2024-06-01T18:07:03.161464Z"}]}
