{"channel":"book","type":"snapshot","data":[{"symbol":"USDT/GBP","bids":[{"price":0.7838,"qty":9055.72158293},{"price":0.7837,"qty":22841.22792050},{"price":0.7836,"qty":90494.72651110},{"price":0.7835,"qty":25566.95341476},{"price":0.7834,"qty":103208.27550947},{"price":0.7833,"qty":238653.19317384},{"price":0.7832,"qty":10032.07000000},{"price":0.7831,"qty":4124.77932149},{"price":0.7830,"qty":34661.38000000},{"price":0.7829,"qty":262138.27825512}],"asks":[{"price":0.7839,"qty":6984.55766536},{"price":0.7840,"qty":18771.94883738},{"price":0.7841,"qty":203857.38399227},{"price":0.7842,"qty":55982.37140039},{"price":0.7843,"qty":83032.70966721},{"price":0.7844,"qty":35104.85122931},{"price":0.7845,"qty":263539.55250547},{"price":0.7846,"qty":18322.45000000},{"price":0.7847,"qty":22741.62000000},{"price":0.7848,"qty":2255.00000000}],"checksum":3582076512}]}
{"channel":"book","type":"update","data":[{"symbol":"USDT/GBP","bids":[{"price":0.7834,"qty":30173.43146162}],"asks":[],"checksum":2460059873,"timestamp":"2024-06-01T18:06:13.395947Z"}]}
{"channel":"book","type":"update","data":[{"symbol":"USDT/GBP","bids":[{"price":0.7836,"qty":6476.19247052}],"asks":[],"checksum":2374779726,"timestamp":"2024-06-01T18:06:13.396029Z"}]}
{"channel":"book","type":"update","data":[{"symbol":"USDT/GBP","bids":[{"price":0.7836,"qty":69014.11438110}],"asks":[],"checksum":1274790388,"timestamp":"2024-06-01T18:06:13.396519Z"}]}
{"channel":"book","type":"update","data":[{"symbol":"USDT/GBP","bids":[{"price":0.7834,"qty":117282.04304494}],"asks":[],"checksum":3099218692,"timestamp":"2024-06-01T18:06:13.396893Z"}]}
{"channel":"book","type":"update","data":[{"symbol":"USDT/GBP","bids":[{"price":0.7837,"qty":10097.51337938},{"price":0.7835,"qty":38310.66795588}],"asks":[],"checksum":2055960523,"timestamp":"2024-06-01T18:06:13.399202Z"}]}
{"channel":"book","type":"update","data":[{"symbol":"USDT/GBP","bids":[{"price":0.7837,"qty":10336.13062870}],"asks":[],"checksum":3046995551,"timestamp":"2024-06-01T18:06:14.050622Z"}]}
{"channel":"book","type":"update","data":[{"symbol":"USDT/GBP","bids":[{"price":0.7835,"qty":25566.95341476},{"price":0.7837,"qty":23079.84516982}],"asks":[],"checksum":2717060316,"timestamp":"2024-06-01T18:06:14.053622Z"}]}
{"channel":"book","type":"update","data":[{"symbol":"USDT/GBP","bids":[{"price":0.7836,"qty":68775.49713178}],"asks":[],"checksum":1495717403,"timestamp":"2024-06-01T18:06:14.219161Z"}]}
{"channel":"book","type":"update","data":[{"symbol":"USDT/GBP","bids":[{"price":0.7831,"qty":1442.60692807}],"asks":[],"checksum":3400784929,"timestamp":"2024-06-01T18:06:17.799819Z"}]}
{"channel":"book","type":"update","data":[{"symbol":"USDT/GBP","bids":[{"price":0.7830,"qty":37343.55239342}],"asks":[],"checksum":1763295806,"timestamp":"2024-06-01T18:06:17.802599Z"}]}
{"channel":"book","type":"update","data":[{"symbol":"USDT/GBP","bids":[],"asks":[{"price":0.7841,"qty":6066.62442772}],"checksum":3786258572,"timestamp":"2024-06-01T18:06:18.147939Z"}]}
{"channel":"book","type":"update","data":[{"symbol":"USDT/GBP","bids":[],"asks":[{"price":0.7840,"qty":11248.46337850},{"price":0.7841,"qty":13590.10988660}],"checksum":985471673,"timestamp":"2024-06-01T18:06:18.151074Z"}]}
{"channel":"book","type":"update","data":[{"symbol":"USDT/GBP","bids":[],"asks":[{"price":0.7840,"qty":11157.54852082},{"price":0.7841,"qty":13681.16440786}],"checksum":176823671,"timestamp":"2024-06-01T18:06:18.151677Z"}]}
{"channel":"book","type":"update","data":[{"symbol":"USDT/GBP","bids":[],"asks":[{"price":0.7841,"qty":210432.08062430}],"checksum":546335315,"timestamp":"2024-06-01T18:06:18.152794Z"}]}
{"channel":"book","type":"update","data":[{"symbol":"USDT/GBP","bids":[],"asks":[{"price":0.7841,"qty":210341.02610304},{"price":0.7840,"qty":11248.60304208}],"checksum":90156358,"timestamp":"2024-06-01T18:06:18.154879Z"}]}
{"channel":"book","type":"update","data":[{"symbol":"USDT/GBP","bids":[],"asks":[{"price":0.7839,"qty":6346.72120663}],"checksum":3022167240,"timestamp":"2024-06-01T18:06:19.471730Z"}]}
{"channel":"book","type":"update","data":[{"symbol":"USDT/GBP","bids":[],"asks":[{"price":0.7841,"qty":202817.54064416},{"price":0.7840,"qty":18772.08850096}],"checksum":709634120,"timestamp":"2024-06-01T18:06:19.475371Z"}]}
{"channel":"book","type":"update","data":[{"symbol":"USDT/GBP","bids":[],"asks":[{"price":0.7840,"qty":18814.94197461}],"checksum":3416833004,"timestamp":"2024-06-01T18:06:19.639321Z"}]}
{"channel":"book","type":"update","data":[{"symbol":"USDT/GBP","bids":[],"asks":[{"price":0.7841,"qty":202774.68717051}],"checksum":4755230,"timestamp":"2024-06-01T18:06:19.800758Z"}]}
{"channel":"book","type":"update","data":[{"symbol":"USDT/GBP","bids":[{"price":0.7838,"qty":10242.72158293}],"asks":[],"checksum":2518763211,"timestamp":"2024-06-01T18:06:20.353686Z"}]}
{"channel":"book","type":"update","data":[{"symbol":"USDT/GBP","bids":[{"price":0.7838,"qty":9055.72158293}],"asks":[],"checksum":4755230,"timestamp":"2024-06-01T18:06:20.486399Z"}]}
{"channel":"book","type":"update","data":[{"symbol":"USDT/GBP","bids":[{"price":0.7834,"qty":30173.43146162}],"asks":[],"checksum":3193310217,"timestamp":"2024-06-01T18:06:20.895023Z"}]}
{"channel":"book","type":"update","data":[{"symbol":"USDT/GBP","bids":[{"price":0.7834,"qty":124856.70492174}],"asks":[],"checksum":502177002,"timestamp":"2024-06-01T18:06:20.895522Z"}]}
{"channel":"book","type":"update","data":[{"symbol":"USDT/GBP","bids":[],"asks":[{"price":0.7842,"qty":28004.75730584}],"checksum":3544644735,"timestamp":"2024-06-01T18:06:21.771684Z"}]}
{"channel":"book","type":"update","data":[{"symbol":"USDT/GBP","bids":[],"asks":[{"price":0.7842,"qty":57981.28363790}],"checksum":1967293800,"timestamp":"2024-06-01T18:06:21.776347Z"}]}
{"channel":"book","type":"update","data":[{"symbol":"USDT/GBP","bids":[{"price":0.7834,"qty":30173.43146162}],"asks":[],"checksum":3489429211,"timestamp":"2024-06-01T18:06:23.354229Z"}]}
{"channel":"book","type":"update","data":[{"symbol":"USDT/GBP","bids":[{"price":0.7834,"qty":117282.04304493}],"asks":[],"checksum":2683645778,"timestamp":"2024-06-01T18:06:23.354545Z"}]}
{"channel":"book","type":"update","data":[{"symbol":"USDT/GBP","bids":[{"price":0.7834,"qty":30173.43146162}],"asks":[],"checksum":3489429211,"timestamp":"2024-06-01T18:06:25.860446Z"}]}
{"channel":"book","type":"update","data":[{"symbol":"USDT/GBP","bids":[{"price":0.7834,"qty":124856.70492174}],"asks":[],"checksum":1967293800,"timestamp":"2024-06-01T18:06:25.861547Z"}]}
{"channel":"book","type":"update","data":[{"symbol":"USDT/GBP","bids":[{"price":0.7838,"qty":9994.72158293}],"asks":[],"checksum":797781555,"timestamp":"2024-06-01T18:06:27.585849Z"}]}
{"channel":"book","type":"update","data":[{"symbol":"USDT/GBP","bids":[{"price":0.7838,"qty":9055.72158293}],"asks":[],"checksum":1967293800,"timestamp":"2024-06-01T18:06:27.671420Z"}]}
{"channel":"book","type":"update","data":[{"symbol":"USDT/GBP","bids":[],"asks":[{"price":0.7842,"qty":28004.75730584}],"checksum":3544644735,"timestamp":"2024-06-01T18:06:28.866549Z"}]}
{"channel":"book","type":"update","data":[{"symbol":"USDT/GBP","bids":[],"asks":[{"price":0.7842,"qty":53983.45916289}],"checksum":172428511,"timestamp":"2024-06-01T18:06:28.869096Z"}]}
{"channel":"book","type":"update","data":[{"symbol":"USDT/GBP","bids":[{"price":0.7836,"qty":6237.57522120}],"asks":[],"checksum":1844075308,"timestamp":"2024-06-01T18:06:30.792596Z"}]}
{"channel":"book","type":"update","data":[{"symbol":"USDT/GBP","bids":[{"price":0.7834,"qty":30173.43146162}],"asks":[],"checksum":3496297740,"timestamp":"2024-06-01T18:06:30.792615Z"}]}
{"channel":"book","type":"update","data":[{"symbol":"USDT/GBP","bids":[{"price":0.7834,"qty":130739.84487390}],"asks":[],"checksum":3182511827,"timestamp":"2024-06-01T18:06:30.793562Z"}]}
{"channel":"book","type":"update","data":[{"symbol":"USDT/GBP","bids":[{"price":0.7836,"qty":64869.93128996}],"asks":[],"checksum":3542769624,"timestamp":"2024-06-01T18:06:30.793609Z"}]}
{"channel":"book","type":"update","data":[{"symbol":"USDT/GBP","bids":[{"price":0.7837,"qty":10336.13062870},{"price":0.7835,"qty":38310.66795588}],"asks":[],"checksum":3343131995,"timestamp":"2024-06-01T18:06:30.796720Z"}]}
{"channel":"book","type":"update","data":[{"symbol":"USDT/GBP","bids":[{"price":0.7835,"qty":25566.95341476},{"price":0.7837,"qty":23079.84516982}],"asks":[],"checksum":3542769624,"timestamp":"2024-06-01T18:06:32.589343Z"}]}
{"channel":"book","type":"update","data":[{"symbol":"USDT/GBP","bids":[],"asks":[{"price":0.7841,"qty":6023.77095407}],"checksum":1219069164,"timestamp":"2024-06-01T18:06:32.675004Z"}]}
{"channel":"book","type":"update","data":[{"symbol":"USDT/GBP","bids":[],"asks":[{"price":0.7842,"qty":28004.75730584}],"checksum":2443736140,"timestamp":"2024-06-01T18:06:32.675087Z"}]}
{"channel":"book","type":"update","data":[{"symbol":"USDT/GBP","bids":[],"asks":[{"price":0.7840,"qty":11291.45651573},{"price":0.7842,"qty":35528.24276472}],"checksum":1923870663,"timestamp":"2024-06-01T18:06:32.678545Z"}]}
{"channel":"book","type":"update","data":[{"symbol":"USDT/GBP","bids":[],"asks":[{"price":0.7840,"qty":11200.40199447},{"price":0.7841,"qty":6119.10960915}],"checksum":2328831739,"timestamp":"2024-06-01T18:06:32.679091Z"}]}
{"channel":"book","type":"update","data":[{"symbol":"USDT/GBP","bids":[],"asks":[{"price":0.7841,"qty":201815.86801646}],"checksum":3650658078,"timestamp":"2024-06-01T18:06:32.679989Z"}]}
{"channel":"book","type":"update","data":[{"symbol":"USDT/GBP","bids":[],"asks":[{"price":0.7842,"qty":65519.59478856}],"checksum":624010590,"timestamp":"2024-06-01T18:06:32.680028Z"}]}
{"channel":"book","type":"update","data":[{"symbol":"USDT/GBP","bids":[],"asks":[{"price":0.7841,"qty":201720.52936138},{"price":0.7840,"qty":11295.74064955}],"checksum":133772731,"timestamp":"2024-06-01T18:06:32.683066Z"}]}
{"channel":"book","type":"update","data":[{"symbol":"USDT/GBP","bids":[],"asks":[{"price":0.7842,"qty":57996.10932968},{"price":0.7840,"qty":18819.22610843}],"checksum":3991706305,"timestamp":"2024-06-01T18:06:35.891492Z"}]}
{"channel":"book","type":"update","data":[{"symbol":"USDT/GBP","bids":[],"asks":[{"price":0.7842,"qty":28004.75730584}],"checksum":2240243121,"timestamp":"2024-06-01T18:06:36.177060Z"}]}
{"channel":"book","type":"update","data":[{"symbol":"USDT/GBP","bids":[],"asks":[{"price":0.7841,"qty":6023.77095407}],"checksum":2988277754,"timestamp":"2024-06-01T18:06:36.177172Z"}]}
{"channel":"book","type":"update","data":[{"symbol":"USDT/GBP","bids":[],"asks":[{"price":0.7841,"qty":243508.54114755}],"checksum":2634272260,"timestamp":"2024-06-01T18:06:36.179985Z"}]}
{"channel":"book","type":"update","data":[{"symbol":"USDT/GBP","bids":[],"asks":[{"price":0.7840,"qty":11295.74064955},{"price":0.7842,"qty":35528.24276472}],"checksum":3822363726,"timestamp":"2024-06-01T18:06:36.180213Z"}]}
{"channel":"book","type":"update","data":[{"symbol":"USDT/GBP","bids":[],"asks":[{"price":0.7840,"qty":11200.40199447},{"price":0.7841,"qty":243603.87745611}],"checksum":2679188437,"timestamp":"2024-06-01T18:06:36.180595Z"}]}
{"channel":"book","type":"update","data":[{"symbol":"USDT/GBP","bids":[],"asks":[{"price":0.7841,"qty":243508.54114755},{"price":0.7840,"qty":11295.73830303}],"checksum":1042246557,"timestamp":"2024-06-01T18:06:36.184021Z"}]}
{"channel":"book","type":"update","data":[{"symbol":"USDT/GBP","bids":[{"price":0.7838,"qty":9294.33883225}],"asks":[],"checksum":3698825770,"timestamp":"2024-06-01T18:06:36.345946Z"}]}
{"channel":"book","type":"update","data":[{"symbol":"USDT/GBP","bids":[],"asks":[{"price":0.7842,"qty":28004.75730584},{"price":0.7840,"qty":18819.22376191}],"checksum":132857646,"timestamp":"2024-06-01T18:06:36.348904Z"}]}
{"channel":"book","type":"update","data":[{"symbol":"USDT/GBP","bids":[{"price":0.7837,"qty":22841.22792050}],"asks":[],"checksum":513958134,"timestamp":"2024-06-01T18:06:36.522423Z"}]}
{"channel":"book","type":"update","data":[{"symbol":"USDT/GBP","bids":[{"price":0.7838,"qty":10593.33883225}],"asks":[],"checksum":2099083058,"timestamp":"2024-06-01T18:06:38.631913Z"}]}
{"channel":"book","type":"update","data":[{"symbol":"USDT/GBP","bids":[],"asks":[{"price":0.7841,"qty":6023.77095407}],"checksum":775480873,"timestamp":"2024-06-01T18:06:39.808976Z"}]}
{"channel":"book","type":"update","data":[{"symbol":"USDT/GBP","bids":[],"asks":[{"price":0.7840,"qty":11295.73830303},{"price":0.7842,"qty":35528.24276472}],"checksum":1408267072,"timestamp":"2024-06-01T18:06:39.812168Z"}]}
{"channel":"book","type":"update","data":[{"symbol":"USDT/GBP","bids":[],"asks":[{"price":0.7840,"qty":11200.40199447},{"price":0.7841,"qty":6119.10315659}],"checksum":1486440710,"timestamp":"2024-06-01T18:06:39.812420Z"}]}
{"channel":"book","type":"update","data":[{"symbol":"USDT/GBP","bids":[],"asks":[{"price":0.7841,"qty":202862.86214252}],"checksum":1027011316,"timestamp":"2024-06-01T18:06:39.813836Z"}]}
{"channel":"book","type":"update","data":[{"symbol":"USDT/GBP","bids":[],"asks":[{"price":0.7842,"qty":69509.75080230}],"checksum":2825695949,"timestamp":"2024-06-01T18:06:39.813849Z"}]}
{"channel":"book","type":"update","data":[{"symbol":"USDT/GBP","bids":[],"asks":[{"price":0.7841,"qty":202767.52994000},{"price":0.7840,"qty":11295.73419699}],"checksum":884087052,"timestamp":"2024-06-01T18:06:39.817704Z"}]}
{"channel":"book","type":"update","data":[{"symbol":"USDT/GBP","bids":[{"price":0.7838,"qty":9294.33883225}],"asks":[],"checksum":3632993040,"timestamp":"2024-06-01T18:06:40.646257Z"}]}
{"channel":"book","type":"update","data":[{"symbol":"USDT/GBP","bids":[],"asks":[{"price":0.7842,"qty":61986.26534342},{"price":0.7840,"qty":18819.21965587}],"checksum":920076588,"timestamp":"2024-06-01T18:06:40.649279Z"}]}
{"channel":"book","type":"update","data":[{"symbol":"USDT/GBP","bids":[{"price":0.7834,"qty":30173.43146162}],"asks":[],"checksum":148525142,"timestamp":"2024-06-01T18:06:40.784657Z"}]}
{"channel":"book","type":"update","data":[{"symbol":"USDT/GBP","bids":[{"price":0.7836,"qty":6237.57522120}],"asks":[],"checksum":1914967604,"timestamp":"2024-06-01T18:06:40.784695Z"}]}
{"channel":"book","type":"update","data":[{"symbol":"USDT/GBP","bids":[{"price":0.7836,"qty":66822.71421087}],"asks":[],"checksum":3838561142,"timestamp":"2024-06-01T18:06:40.786272Z"}]}
{"channel":"book","type":"update","data":[{"symbol":"USDT/GBP","bids":[{"price":0.7834,"qty":132534.34558540}],"asks":[],"checksum":1216498592,"timestamp":"2024-06-01T18:06:40.786329Z"}]}
{"channel":"book","type":"update","data":[{"symbol":"USDT/GBP","bids":[{"price":0.7837,"qty":10097.51337938},{"price":0.7835,"qty":38310.66795588}],"asks":[],"checksum":2327015279,"timestamp":"2024-06-01T18:06:40.787802Z"}]}
