{"channel":"book","type":"snapshot","data":[{"symbol":"USDT/EUR","bids":[{"price":0.9216,"qty":113233.07453877},{"price":0.9215,"qty":303005.08255094},{"price":0.9214,"qty":79068.48491318},{"price":0.9213,"qty":741211.15058650},{"price":0.9212,"qty":287734.94355159},{"price":0.9211,"qty":319064.77775943},{"price":0.9210,"qty":191006.48096477},{"price":0.9209,"qty":46150.06359310},{"price":0.9208,"qty":88628.86303891},{"price":0.9207,"qty":171003.81203064}],"asks":[{"price":0.9217,"qty":182300.01946503},{"price":0.9218,"qty":465437.43693835},{"price":0.9219,"qty":95976.77037225},{"price":0.9220,"qty":166019.49260095},{"price":0.9221,"qty":167460.64417069},{"price":0.9222,"qty":39732.89000000},{"price":0.9223,"qty":148458.61369925},{"price":0.9224,"qty":114230.49737077},{"price":0.9225,"qty":71974.51883956},{"price":0.9226,"qty":50109.29278321}],"checksum":2078749980}]}
{"channel":"book","type":"update","data":[{"symbol":"USDT/EUR","bids":[{"price":0.9214,"qty":76147.57705772}],"asks":[],"checksum":368291608,"timestamp":"2024-06-01T18:06:18.666946Z"}]}
{"channel":"book","type":"update","data":[{"symbol":"USDT/EUR","bids":[],"asks":[{"price":0.9217,"qty":181598.93136505}],"checksum":303138544,"timestamp":"2024-06-01T18:06:18.923674Z"}]}
{"channel":"book","type":"update","data":[{"symbol":"USDT/EUR","bids":[],"asks":[{"price":0.9217,"qty":182172.01081676}],"checksum":3190469619,"timestamp":"2024-06-01T18:06:18.929054Z"}]}
{"channel":"book","type":"update","data":[{"symbol":"USDT/EUR","bids":[{"price":0.9213,"qty":92887.32739768}],"asks":[],"checksum":1555678985,"timestamp":"2024-06-01T18:06:19.444143Z"}]}
{"channel":"book","type":"update","data":[{"symbol":"USDT/EUR","bids":[{"price":0.9216,"qty":79151.57268039}],"asks":[],"checksum":34424524,"timestamp":"2024-06-01T18:06:19.444302Z"}]}
{"channel":"book","type":"update","data":[{"symbol":"USDT/EUR","bids":[{"price":0.9216,"qty":111179.79296403}],"asks":[],"checksum":2734419034,"timestamp":"2024-06-01T18:06:19.448446Z"}]}
{"channel":"book","type":"update","data":[{"symbol":"USDT/EUR","bids":[{"price":0.9213,"qty":707701.50706102}],"asks":[],"checksum":2426012403,"timestamp":"2024-06-01T18:06:19.448490Z"}]}
{"channel":"book","type":"update","data":[{"symbol":"USDT/EUR","bids":[{"price":0.9216,"qty":115477.79296403}],"asks":[],"checksum":1515205557,"timestamp":"2024-06-01T18:06:20.343149Z"}]}
{"channel":"book","type":"update","data":[{"symbol":"USDT/EUR","bids":[{"price":0.9216,"qty":111179.79296403}],"asks":[],"checksum":2426012403,"timestamp":"2024-06-01T18:06:20.584593Z"}]}
{"channel":"book","type":"update","data":[{"symbol":"USDT/EUR","bids":[],"asks":[{"price":0.9217,"qty":181833.56180708}],"checksum":2690117562,"timestamp":"2024-06-01T18:06:20.902780Z"}]}
{"channel":"book","type":"update","data":[{"symbol":"USDT/EUR","bids":[{"price":0.9214,"qty":78464.91685866}],"asks":[],"checksum":2485534935,"timestamp":"2024-06-01T18:06:21.098228Z"}]}
{"channel":"book","type":"update","data":[{"symbol":"USDT/EUR","bids":[],"asks":[{"price":0.9217,"qty":180821.15676208}],"checksum":1117886723,"timestamp":"2024-06-01T18:06:21.553677Z"}]}
{"channel":"book","type":"update","data":[{"symbol":"USDT/EUR","bids":[{"price":0.9216,"qty":111165.67354503}],"asks":[],"checksum":1948544042,"timestamp":"2024-06-01T18:06:21.617237Z"}]}
{"channel":"book","type":"update","data":[{"symbol":"USDT/EUR","bids":[],"asks":[{"price":0.9217,"qty":180248.07731037}],"checksum":4086360387,"timestamp":"2024-06-01T18:06:21.768410Z"}]}
{"channel":"book","type":"update","data":[{"symbol":"USDT/EUR","bids":[],"asks":[{"price":0.9217,"qty":143695.40685349}],"checksum":3020282865,"timestamp":"2024-06-01T18:06:21.771388Z"}]}
{"channel":"book","type":"update","data":[{"symbol":"USDT/EUR","bids":[],"asks":[{"price":0.9217,"qty":144318.48941586}],"checksum":879775367,"timestamp":"2024-06-01T18:06:21.773676Z"}]}
{"channel":"book","type":"update","data":[{"symbol":"USDT/EUR","bids":[],"asks":[{"price":0.9217,"qty":181918.16045136}],"checksum":1728927220,"timestamp":"2024-06-01T18:06:21.775887Z"}]}
{"channel":"book","type":"update","data":[{"symbol":"USDT/EUR","bids":[{"price":0.9216,"qty":79137.45326139}],"asks":[],"checksum":1293126248,"timestamp":"2024-06-01T18:06:21.928215Z"}]}
{"channel":"book","type":"update","data":[{"symbol":"USDT/EUR","bids":[{"price":0.9213,"qty":92887.32739768}],"asks":[],"checksum":638565941,"timestamp":"2024-06-01T18:06:21.928400Z"}]}
{"channel":"book","type":"update","data":[{"symbol":"USDT/EUR","bids":[{"price":0.9216,"qty":113218.95511977}],"asks":[],"checksum":760429477,"timestamp":"2024-06-01T18:06:21.935016Z"}]}
{"channel":"book","type":"update","data":[{"symbol":"USDT/EUR","bids":[{"price":0.9213,"qty":704113.60212065}],"asks":[],"checksum":1518863726,"timestamp":"2024-06-01T18:06:21.935105Z"}]}
{"channel":"book","type":"update","data":[{"symbol":"USDT/EUR","bids":[{"price":0.9216,"qty":117085.95511977}],"asks":[],"checksum":35260150,"timestamp":"2024-06-01T18:06:22.629575Z"}]}
{"channel":"book","type":"update","data":[{"symbol":"USDT/EUR","bids":[{"price":0.9214,"qty":76147.57705772}],"asks":[],"checksum":913025435,"timestamp":"2024-06-01T18:06:23.795321Z"}]}
{"channel":"book","type":"update","data":[{"symbol":"USDT/EUR","bids":[{"price":0.9214,"qty":76187.61008497}],"asks":[],"checksum":1006032980,"timestamp":"2024-06-01T18:06:23.883348Z"}]}
{"channel":"book","type":"update","data":[{"symbol":"USDT/EUR","bids":[{"price":0.9216,"qty":113875.87928977}],"asks":[],"checksum":291528993,"timestamp":"2024-06-01T18:06:24.021244Z"}]}
{"channel":"book","type":"update","data":[{"symbol":"USDT/EUR","bids":[{"price":0.9216,"qty":79794.37743139}],"asks":[],"checksum":1327912427,"timestamp":"2024-06-01T18:06:24.476585Z"}]}
{"channel":"book","type":"update","data":[{"symbol":"USDT/EUR","bids":[{"price":0.9213,"qty":92887.32739768}],"asks":[],"checksum":1496250360,"timestamp":"2024-06-01T18:06:24.476659Z"}]}
{"channel":"book","type":"update","data":[{"symbol":"USDT/EUR","bids":[{"price":0.9216,"qty":112093.66537333}],"asks":[],"checksum":678709554,"timestamp":"2024-06-01T18:06:24.481205Z"}]}
{"channel":"book","type":"update","data":[{"symbol":"USDT/EUR","bids":[{"price":0.9213,"qty":686740.49732187}],"asks":[],"checksum":2081454715,"timestamp":"2024-06-01T18:06:24.481329Z"}]}
{"channel":"book","type":"update","data":[{"symbol":"USDT/EUR","bids":[],"asks":[{"price":0.9217,"qty":181295.07788899}],"checksum":3615629227,"timestamp":"2024-06-01T18:06:24.520557Z"}]}
{"channel":"book","type":"update","data":[{"symbol":"USDT/EUR","bids":[],"asks":[{"price":0.9217,"qty":181748.87875346}],"checksum":1005286334,"timestamp":"2024-06-01T18:06:24.526592Z"}]}
{"channel":"book","type":"update","data":[{"symbol":"USDT/EUR","bids":[{"price":0.9216,"qty":108226.66537333}],"asks":[],"checksum":2214846146,"timestamp":"2024-06-01T18:06:24.637239Z"}]}
{"channel":"book","type":"update","data":[{"symbol":"USDT/EUR","bids":[],"asks":[{"price":0.9217,"qty":144149.20771796}],"checksum":3695836153,"timestamp":"2024-06-01T18:06:25.284324Z"}]}
{"channel":"book","type":"update","data":[{"symbol":"USDT/EUR","bids":[],"asks":[{"price":0.9217,"qty":182795.87933208}],"checksum":4110614803,"timestamp":"2024-06-01T18:06:25.289409Z"}]}
{"channel":"book","type":"update","data":[{"symbol":"USDT/EUR","bids":[{"price":0.9208,"qty":85652.86303891},{"price":0.9209,"qty":39774.06359310}],"asks":[],"checksum":2082303199,"timestamp":"2024-06-01T18:06:25.630098Z"}]}
{"channel":"book","type":"update","data":[{"symbol":"USDT/EUR","bids":[{"price":0.9214,"qty":76147.57705772}],"asks":[],"checksum":1904221456,"timestamp":"2024-06-01T18:06:25.842332Z"}]}
{"channel":"book","type":"update","data":[{"symbol":"USDT/EUR","bids":[{"price":0.9214,"qty":79226.38918424}],"asks":[],"checksum":3871362010,"timestamp":"2024-06-01T18:06:25.847205Z"}]}
{"channel":"book","type":"update","data":[{"symbol":"USDT/EUR","bids":[{"price":0.9216,"qty":75927.37743139}],"asks":[],"checksum":2866098824,"timestamp":"2024-06-01T18:06:26.825396Z"}]}
{"channel":"book","type":"update","data":[{"symbol":"USDT/EUR","bids":[{"price":0.9213,"qty":92887.32739768}],"asks":[],"checksum":2143753159,"timestamp":"2024-06-01T18:06:26.825469Z"}]}
{"channel":"book","type":"update","data":[{"symbol":"USDT/EUR","bids":[{"price":0.9216,"qty":115355.52103911}],"asks":[],"checksum":2471680952,"timestamp":"2024-06-01T18:06:26.830019Z"}]}
{"channel":"book","type":"update","data":[{"symbol":"USDT/EUR","bids":[{"price":0.9213,"qty":740253.03656208}],"asks":[],"checksum":1532241056,"timestamp":"2024-06-01T18:06:26.830192Z"}]}
{"channel":"book","type":"update","data":[{"symbol":"USDT/EUR","bids":[{"price":0.9216,"qty":119966.52103911}],"asks":[],"checksum":175880646,"timestamp":"2024-06-01T18:06:27.551663Z"}]}
{"channel":"book","type":"update","data":[{"symbol":"USDT/EUR","bids":[{"price":0.9216,"qty":115355.52103911}],"asks":[],"checksum":1532241056,"timestamp":"2024-06-01T18:06:27.782755Z"}]}
{"channel":"book","type":"update","data":[{"symbol":"USDT/EUR","bids":[{"price":0.9214,"qty":76147.57705772}],"asks":[],"checksum":3423892074,"timestamp":"2024-06-01T18:06:28.101447Z"}]}
{"channel":"book","type":"update","data":[{"symbol":"USDT/EUR","bids":[{"price":0.9214,"qty":79343.77661737}],"asks":[],"checksum":1547888011,"timestamp":"2024-06-01T18:06:28.106945Z"}]}
{"channel":"book","type":"update","data":[{"symbol":"USDT/EUR","bids":[{"price":0.9212,"qty":273513.32165086}],"asks":[],"checksum":378840664,"timestamp":"2024-06-01T18:06:28.463440Z"}]}
{"channel":"book","type":"update","data":[{"symbol":"USDT/EUR","bids":[{"price":0.9212,"qty":287734.94355159}],"asks":[],"checksum":1547888011,"timestamp":"2024-06-01T18:06:28.496070Z"}]}
{"channel":"book","type":"update","data":[{"symbol":"USDT/EUR","bids":[],"asks":[{"price":0.9221,"qty":156115.10312952}],"checksum":57956946,"timestamp":"2024-06-01T18:06:28.573515Z"}]}
{"channel":"book","type":"update","data":[{"symbol":"USDT/EUR","bids":[],"asks":[{"price":0.9221,"qty":167460.64417069}],"checksum":1547888011,"timestamp":"2024-06-01T18:06:28.606072Z"}]}
{"channel":"book","type":"update","data":[{"symbol":"USDT/EUR","bids":[],"asks":[{"price":0.9220,"qty":199233.26050095}],"checksum":3121152927,"timestamp":"2024-06-01T18:06:28.770058Z"}]}
{"channel":"book","type":"update","data":[{"symbol":"USDT/EUR","bids":[],"asks":[{"price":0.9218,"qty":162768.38295059}],"checksum":1774583665,"timestamp":"2024-06-01T18:06:28.866452Z"}]}
{"channel":"book","type":"update","data":[{"symbol":"USDT/EUR","bids":[],"asks":[{"price":0.9218,"qty":454431.66132480}],"checksum":4248261341,"timestamp":"2024-06-01T18:06:28.868991Z"}]}
{"channel":"book","type":"update","data":[{"symbol":"USDT/EUR","bids":[{"price":0.9213,"qty":92887.32739768}],"asks":[],"checksum":1282654493,"timestamp":"2024-06-01T18:06:29.337310Z"}]}
{"channel":"book","type":"update","data":[{"symbol":"USDT/EUR","bids":[{"price":0.9213,"qty":881368.17752435}],"asks":[],"checksum":2719817877,"timestamp":"2024-06-01T18:06:29.341989Z"}]}
{"channel":"book","type":"update","data":[{"symbol":"USDT/EUR","bids":[],"asks":[{"price":0.9217,"qty":182342.07846761}],"checksum":3450288714,"timestamp":"2024-06-01T18:06:30.174954Z"}]}
{"channel":"book","type":"update","data":[{"symbol":"USDT/EUR","bids":[],"asks":[{"price":0.9217,"qty":182594.85731584}],"checksum":1926899503,"timestamp":"2024-06-01T18:06:30.177745Z"}]}
{"channel":"book","type":"update","data":[{"symbol":"USDT/EUR","bids":[{"price":0.9216,"qty":115267.74143452}],"asks":[],"checksum":3907118119,"timestamp":"2024-06-01T18:06:30.455577Z"}]}
{"channel":"book","type":"update","data":[{"symbol":"USDT/EUR","bids":[{"price":0.9214,"qty":76147.57705772}],"asks":[],"checksum":2025288646,"timestamp":"2024-06-01T18:06:30.510383Z"}]}
{"channel":"book","type":"update","data":[{"symbol":"USDT/EUR","bids":[{"price":0.9214,"qty":79471.60908569}],"asks":[],"checksum":1449262845,"timestamp":"2024-06-01T18:06:30.516125Z"}]}
{"channel":"book","type":"update","data":[{"symbol":"USDT/EUR","bids":[{"price":0.9216,"qty":119799.74143452}],"asks":[],"checksum":148685888,"timestamp":"2024-06-01T18:06:30.735858Z"}]}
{"channel":"book","type":"update","data":[{"symbol":"USDT/EUR","bids":[{"price":0.9216,"qty":115267.74143452}],"asks":[],"checksum":1449262845,"timestamp":"2024-06-01T18:06:31.022163Z"}]}
{"channel":"book","type":"update","data":[{"symbol":"USDT/EUR","bids":[{"price":0.9216,"qty":75839.59782680}],"asks":[],"checksum":3364972824,"timestamp":"2024-06-01T18:06:31.790264Z"}]}
{"channel":"book","type":"update","data":[{"symbol":"USDT/EUR","bids":[{"price":0.9213,"qty":92887.32739768}],"asks":[],"checksum":1880800780,"timestamp":"2024-06-01T18:06:31.790384Z"}]}
{"channel":"book","type":"update","data":[{"symbol":"USDT/EUR","bids":[{"price":0.9216,"qty":117049.95535096}],"asks":[],"checksum":739055794,"timestamp":"2024-06-01T18:06:31.795377Z"}]}
{"channel":"book","type":"update","data":[{"symbol":"USDT/EUR","bids":[{"price":0.9213,"qty":701146.14633204}],"asks":[],"checksum":3606211448,"timestamp":"2024-06-01T18:06:31.795500Z"}]}
{"channel":"book","type":"update","data":[{"symbol":"USDT/EUR","bids":[],"asks":[{"price":0.9218,"qty":162768.38295059}],"checksum":1107347156,"timestamp":"2024-06-01T18:06:32.675100Z"}]}
{"channel":"book","type":"update","data":[{"symbol":"USDT/EUR","bids":[],"asks":[{"price":0.9218,"qty":465629.65970083}],"checksum":1624724238,"timestamp":"2024-06-01T18:06:32.679661Z"}]}
{"channel":"book","type":"update","data":[{"symbol":"USDT/EUR","bids":[{"price":0.9214,"qty":76147.57705772}],"asks":[],"checksum":1308745269,"timestamp":"2024-06-01T18:06:32.948571Z"}]}
{"channel":"book","type":"update","data":[{"symbol":"USDT/EUR","bids":[],"asks":[{"price":0.9217,"qty":182342.07846761}],"checksum":4051485520,"timestamp":"2024-06-01T18:06:32.951496Z"}]}
{"channel":"book","type":"update","data":[{"symbol":"USDT/EUR","bids":[{"price":0.9214,"qty":79110.23238881}],"asks":[],"checksum":3698343798,"timestamp":"2024-06-01T18:06:32.953849Z"}]}
{"channel":"book","type":"update","data":[{"symbol":"USDT/EUR","bids":[],"asks":[{"price":0.9217,"qty":182795.87933208}],"checksum":3016369577,"timestamp":"2024-06-01T18:06:32.957683Z"}]}
{"channel":"book","type":"update","data":[{"symbol":"USDT/EUR","bids":[{"price":0.9213,"qty":92887.32739768}],"asks":[],"checksum":2761560042,"timestamp":"2024-06-01T18:06:34.298748Z"}]}
{"channel":"book","type":"update","data":[{"symbol":"USDT/EUR","bids":[{"price":0.9213,"qty":739933.66522061}],"asks":[],"checksum":3950266707,"timestamp":"2024-06-01T18:06:34.303390Z"}]}
{"channel":"book","type":"update","data":[{"symbol":"USDT/EUR","bids":[],"asks":[{"price":0.9217,"qty":181684.32100341}],"checksum":3020468811,"timestamp":"2024-06-01T18:06:34.376879Z"}]}
{"channel":"book","type":"update","data":[{"symbol":"USDT/EUR","bids":[{"price":0.9214,"qty":76147.57705772}],"asks":[],"checksum":2567196269,"timestamp":"2024-06-01T18:06:35.149666Z"}]}
{"channel":"book","type":"update","data":[{"symbol":"USDT/EUR","bids":[{"price":0.9214,"qty":79051.99409725}],"asks":[],"checksum":965525350,"timestamp":"2024-06-01T18:06:35.154001Z"}]}
{"channel":"book","type":"update","data":[{"symbol":"USDT/EUR","bids":[],"asks":[{"price":0.9217,"qty":181230.52013894}],"checksum":2424257758,"timestamp":"2024-06-01T18:06:35.550414Z"}]}
{"channel":"book","type":"update","data":[{"symbol":"USDT/EUR","bids":[{"price":0.9216,"qty":75839.59782680}],"asks":[],"checksum":4274851728,"timestamp":"2024-06-01T18:06:35.618823Z"}]}
{"channel":"book","type":"update","data":[{"symbol":"USDT/EUR","bids":[],"asks":[{"price":0.9217,"qty":142583.84852482}],"checksum":2167566502,"timestamp":"2024-06-01T18:06:36.176924Z"}]}
{"channel":"book","type":"update","data":[{"symbol":"USDT/EUR","bids":[],"asks":[{"price":0.9218,"qty":162768.38295059}],"checksum":1420890896,"timestamp":"2024-06-01T18:06:36.177011Z"}]}
{"channel":"book","type":"update","data":[{"symbol":"USDT/EUR","bids":[],"asks":[{"price":0.9217,"qty":174268.24501992}],"checksum":297042117,"timestamp":"2024-06-01T18:06:36.179523Z"}]}
{"channel":"book","type":"update","data":[{"symbol":"USDT/EUR","bids":[],"asks":[{"price":0.9218,"qty":494983.24400862}],"checksum":1099852817,"timestamp":"2024-06-01T18:06:36.179836Z"}]}
{"channel":"book","type":"update","data":[{"symbol":"USDT/EUR","bids":[],"asks":[{"price":0.9220,"qty":188568.90530095}],"checksum":1535463783,"timestamp":"2024-06-01T18:06:36.455506Z"}]}
{"channel":"book","type":"update","data":[{"symbol":"USDT/EUR","bids":[{"price":0.9213,"qty":92887.32739768}],"asks":[],"checksum":2233080208,"timestamp":"2024-06-01T18:06:36.765339Z"}]}
{"channel":"book","type":"update","data":[{"symbol":"USDT/EUR","bids":[{"price":0.9213,"qty":809556.37480272}],"asks":[],"checksum":1837114768,"timestamp":"2024-06-01T18:06:36.769851Z"}]}
{"channel":"book","type":"update","data":[{"symbol":"USDT/EUR","bids":[{"price":0.9214,"qty":76147.57705772}],"asks":[],"checksum":3439907995,"timestamp":"2024-06-01T18:06:37.555167Z"}]}
{"channel":"book","type":"update","data":[{"symbol":"USDT/EUR","bids":[{"price":0.9214,"qty":78742.55262709}],"asks":[],"checksum":179634392,"timestamp":"2024-06-01T18:06:37.559643Z"}]}
{"channel":"book","type":"update","data":[{"symbol":"USDT/EUR","bids":[],"asks":[{"price":0.9217,"qty":174679.72544938}],"checksum":3595967850,"timestamp":"2024-06-01T18:06:38.385663Z"}]}
{"channel":"book","type":"update","data":[{"symbol":"USDT/EUR","bids":[{"price":0.9216,"qty":75829.59782680}],"asks":[],"checksum":1938650914,"timestamp":"2024-06-01T18:06:38.817428Z"}]}
{"channel":"book","type":"update","data":[{"symbol":"USDT/EUR","bids":[{"price":0.9213,"qty":92887.32739768}],"asks":[],"checksum":2310718210,"timestamp":"2024-06-01T18:06:39.339111Z"}]}
{"channel":"book","type":"update","data":[{"symbol":"USDT/EUR","bids":[{"price":0.9213,"qty":751183.02034653}],"asks":[],"checksum":813054089,"timestamp":"2024-06-01T18:06:39.343682Z"}]}
{"channel":"book","type":"update","data":[{"symbol":"USDT/EUR","bids":[{"price":0.9216,"qty":93871.17443718}],"asks":[],"checksum":1815233182,"timestamp":"2024-06-01T18:06:39.343698Z"}]}
{"channel":"book","type":"update","data":[{"symbol":"USDT/EUR","bids":[],"asks":[{"price":0.9218,"qty":162768.38295059}],"checksum":1007201866,"timestamp":"2024-06-01T18:06:39.808730Z"}]}
{"channel":"book","type":"update","data":[{"symbol":"USDT/EUR","bids":[],"asks":[{"price":0.9217,"qty":142995.32895428}],"checksum":3292015368,"timestamp":"2024-06-01T18:06:39.808754Z"}]}
{"channel":"book","type":"update","data":[{"symbol":"USDT/EUR","bids":[],"asks":[{"price":0.9217,"qty":182689.00114702}],"checksum":3061498501,"timestamp":"2024-06-01T18:06:39.813582Z"}]}
{"channel":"book","type":"update","data":[{"symbol":"USDT/EUR","bids":[],"asks":[{"price":0.9218,"qty":478373.61986874}],"checksum":3999370590,"timestamp":"2024-06-01T18:06:39.813667Z"}]}
{"channel":"book","type":"update","data":[{"symbol":"USDT/EUR","bids":[{"price":0.9214,"qty":76147.57705772}],"asks":[],"checksum":702306589,"timestamp":"2024-06-01T18:06:39.902400Z"}]}
{"channel":"book","type":"update","data":[{"symbol":"USDT/EUR","bids":[{"price":0.9214,"qty":78852.10617675}],"asks":[],"checksum":3518655806,"timestamp":"2024-06-01T18:06:39.907785Z"}]}
