{"channel":"book","type":"snapshot","data":[{"symbol":"XRP/EUR","bids":[{"price":0.47834,"qty":63.15896743},{"price":0.47833,"qty":4000.00000000},{"price":0.47830,"qty":9638.09635206},{"price":0.47829,"qty":1200.00000000},{"price":0.47828,"qty":9638.41755529},{"price":0.47825,"qty":4711.98344985},{"price":0.47824,"qty":5849.57952000},{"price":0.47821,"qty":276.87166127},{"price":0.47820,"qty":19280.13253779},{"price":0.47818,"qty":12759.81095016}],"asks":[{"price":0.47838,"qty":9636.66120378},{"price":0.47843,"qty":9635.63508403},{"price":0.47849,"qty":3011.74580865},{"price":0.47850,"qty":19268.29775231},{"price":0.47851,"qty":386.76301446},{"price":0.47855,"qty":666.62346400},{"price":0.47856,"qty":5050.00000000},{"price":0.47862,"qty":31106.67288077},{"price":0.47863,"qty":20857.30413315},{"price":0.47865,"qty":1283.00000000}],"checksum":62703015}]}
{"channel":"book","type":"update","data":[{"symbol":"XRP/EUR","bids":[{"price":0.47821,"qty":0.00000000},{"price":0.47816,"qty":10076.56421876}],"asks":[],"checksum":2560086298,"timestamp":"2024-06-01T18:07:03.296027Z"}]}
{"channel":"book","type":"update","data":[{"symbol":"XRP/EUR","bids":[{"price":0.47821,"qty":158.10375357}],"asks":[],"checksum":1512422906,"timestamp":"2024-06-01T18:07:03.303851Z"}]}
{"channel":"book","type":"update","data":[{"symbol":"XRP/EUR","bids":[{"price":0.47830,"qty":0.00000000},{"price":0.47816,"qty":10076.56421876}],"asks":[],"checksum":2711826801,"timestamp":"2024-06-01T18:07:03.638623Z"}]}
{"channel":"book","type":"update","data":[{"symbol":"XRP/EUR","bids":[],"asks":[{"price":0.47838,"qty":0.00000000},{"price":0.47869,"qty":3853.00000000}],"checksum":445593747,"timestamp":"2024-06-01T18:07:03.638705Z"}]}
{"channel":"book","type":"update","data":[{"symbol":"XRP/EUR","bids":[{"price":0.47816,"qty":31036.75425146}],"asks":[],"checksum":818840374,"timestamp":"2024-06-01T18:07:03.642205Z"}]}
{"channel":"book","type":"update","data":[{"symbol":"XRP/EUR","bids":[],"asks":[{"price":0.47869,"qty":0.00000000},{"price":0.47877,"qty":48144.16733884},{"price":0.47861,"qty":3853.00000000}],"checksum":4127776006,"timestamp":"2024-06-01T18:07:03.642395Z"}]}
{"channel":"book","type":"update","data":[{"symbol":"XRP/EUR","bids":[],"asks":[{"price":0.47840,"qty":9636.34886108}],"checksum":2639937971,"timestamp":"2024-06-01T18:07:03.643702Z"}]}
{"channel":"book","type":"update","data":[{"symbol":"XRP/EUR","bids":[{"price":0.47831,"qty":9637.78671270}],"asks":[],"checksum":3215360162,"timestamp":"2024-06-01T18:07:03.643779Z"}]}
{"channel":"book","type":"update","data":[{"symbol":"XRP/EUR","bids":[],"asks":[{"price":0.47840,"qty":0.00000000},{"price":0.47865,"qty":1283.00000000}],"checksum":2255208946,"timestamp":"2024-06-01T18:07:03.647965Z"}]}
{"channel":"book","type":"update","data":[{"symbol":"XRP/EUR","bids":[{"price":0.47831,"qty":0.00000000},{"price":0.47816,"qty":31036.75425146}],"asks":[],"checksum":4127776006,"timestamp":"2024-06-01T18:07:03.710063Z"}]}
{"channel":"book","type":"update","data":[{"symbol":"XRP/EUR","bids":[],"asks":[{"price":0.47842,"qty":9635.75987049}],"checksum":2029019746,"timestamp":"2024-06-01T18:07:03.819845Z"}]}
{"channel":"book","type":"update","data":[{"symbol":"XRP/EUR","bids":[{"price":0.47833,"qty":13637.55252724}],"asks":[],"checksum":2461412413,"timestamp":"2024-06-01T18:07:03.819949Z"}]}
{"channel":"book","type":"update","data":[{"symbol":"XRP/EUR","bids":[{"price":0.47816,"qty":10076.56421876}],"asks":[],"checksum":3103233944,"timestamp":"2024-06-01T18:07:03.822998Z"}]}
{"channel":"book","type":"update","data":[{"symbol":"XRP/EUR","bids":[],"asks":[{"price":0.47842,"qty":0.00000000},{"price":0.47865,"qty":1283.00000000}],"checksum":4071017062,"timestamp":"2024-06-01T18:07:03.824545Z"}]}
{"channel":"book","type":"update","data":[{"symbol":"XRP/EUR","bids":[{"price":0.47817,"qty":20960.19003270}],"asks":[],"checksum":3898141922,"timestamp":"2024-06-01T18:07:03.827746Z"}]}
{"channel":"book","type":"update","data":[{"symbol":"XRP/EUR","bids":[],"asks":[{"price":0.47861,"qty":3891.56374841}],"checksum":4266185200,"timestamp":"2024-06-01T18:07:04.114775Z"}]}
{"channel":"book","type":"update","data":[{"symbol":"XRP/EUR","bids":[],"asks":[{"price":0.47841,"qty":9636.10518396}],"checksum":2309147455,"timestamp":"2024-06-01T18:07:04.843931Z"}]}
{"channel":"book","type":"update","data":[{"symbol":"XRP/EUR","bids":[{"price":0.47817,"qty":0.00000000},{"price":0.47816,"qty":10076.56421876}],"asks":[],"checksum":2472340923,"timestamp":"2024-06-01T18:07:04.847013Z"}]}
{"channel":"book","type":"update","data":[{"symbol":"XRP/EUR","bids":[{"price":0.47816,"qty":8663.77728000}],"asks":[],"checksum":1484596558,"timestamp":"2024-06-01T18:07:05.157224Z"}]}
{"channel":"book","type":"update","data":[{"symbol":"XRP/EUR","bids":[{"price":0.47821,"qty":1570.74297617}],"asks":[],"checksum":807059476,"timestamp":"2024-06-01T18:07:05.277270Z"}]}
{"channel":"book","type":"update","data":[{"symbol":"XRP/EUR","bids":[],"asks":[{"price":0.47841,"qty":0.00000000},{"price":0.47865,"qty":1283.00000000}],"checksum":1206967003,"timestamp":"2024-06-01T18:07:06.179166Z"}]}
{"channel":"book","type":"update","data":[{"symbol":"XRP/EUR","bids":[{"price":0.47817,"qty":20960.19003270}],"asks":[],"checksum":165159179,"timestamp":"2024-06-01T18:07:06.182221Z"}]}
{"channel":"book","type":"update","data":[{"symbol":"XRP/EUR","bids":[],"asks":[{"price":0.47840,"qty":9636.22153741}],"checksum":2535918517,"timestamp":"2024-06-01T18:07:06.184105Z"}]}
{"channel":"book","type":"update","data":[{"symbol":"XRP/EUR","bids":[{"price":0.47817,"qty":0.00000000},{"price":0.47816,"qty":8663.77728000}],"asks":[],"checksum":3696216028,"timestamp":"2024-06-01T18:07:06.255383Z"}]}
{"channel":"book","type":"update","data":[{"symbol":"XRP/EUR","bids":[{"price":0.47833,"qty":4000.00000000}],"asks":[],"checksum":3626150675,"timestamp":"2024-06-01T18:07:06.563047Z"}]}
{"channel":"book","type":"update","data":[{"symbol":"XRP/EUR","bids":[],"asks":[{"price":0.47840,"qty":0.00000000},{"price":0.47865,"qty":1283.00000000}],"checksum":66919635,"timestamp":"2024-06-01T18:07:06.563122Z"}]}
{"channel":"book","type":"update","data":[{"symbol":"XRP/EUR","bids":[],"asks":[{"price":0.47849,"qty":0.00000000},{"price":0.47877,"qty":48144.16733884}],"checksum":4006942472,"timestamp":"2024-06-01T18:07:06.563915Z"}]}
{"channel":"book","type":"update","data":[{"symbol":"XRP/EUR","bids":[],"asks":[{"price":0.47862,"qty":21474.67288077}],"checksum":2408537562,"timestamp":"2024-06-01T18:07:06.570181Z"}]}
{"channel":"book","type":"update","data":[{"symbol":"XRP/EUR","bids":[{"price":0.47816,"qty":29623.96731270}],"asks":[],"checksum":137245755,"timestamp":"2024-06-01T18:07:06.571553Z"}]}
{"channel":"book","type":"update","data":[{"symbol":"XRP/EUR","bids":[],"asks":[{"price":0.47843,"qty":0.00000000},{"price":0.47883,"qty":48137.94016789}],"checksum":485796508,"timestamp":"2024-06-01T18:07:06.571772Z"}]}
{"channel":"book","type":"update","data":[{"symbol":"XRP/EUR","bids":[{"price":0.47828,"qty":0.00000000},{"price":0.47815,"qty":4493.03245185}],"asks":[],"checksum":3152063322,"timestamp":"2024-06-01T18:07:06.571784Z"}]}
{"channel":"book","type":"update","data":[{"symbol":"XRP/EUR","bids":[],"asks":[{"price":0.47861,"qty":38.56374841}],"checksum":300188228,"timestamp":"2024-06-01T18:07:06.576890Z"}]}
{"channel":"book","type":"update","data":[{"symbol":"XRP/EUR","bids":[{"price":0.47829,"qty":0.00000000},{"price":0.47814,"qty":1594.00653543}],"asks":[],"checksum":2904251982,"timestamp":"2024-06-01T18:07:06.577721Z"}]}
{"channel":"book","type":"update","data":[{"symbol":"XRP/EUR","bids":[],"asks":[{"price":0.47872,"qty":9632.00000000}],"checksum":374788342,"timestamp":"2024-06-01T18:07:06.578575Z"}]}
{"channel":"book","type":"update","data":[{"symbol":"XRP/EUR","bids":[{"price":0.47836,"qty":9636.81552018}],"asks":[],"checksum":171887435,"timestamp":"2024-06-01T18:07:06.587403Z"}]}
{"channel":"book","type":"update","data":[{"symbol":"XRP/EUR","bids":[],"asks":[{"price":0.47844,"qty":9635.38422305}],"checksum":3400447460,"timestamp":"2024-06-01T18:07:06.587423Z"}]}
{"channel":"book","type":"update","data":[{"symbol":"XRP/EUR","bids":[],"asks":[{"price":0.47849,"qty":9634.35022098}],"checksum":2527927983,"timestamp":"2024-06-01T18:07:06.587596Z"}]}
{"channel":"book","type":"update","data":[{"symbol":"XRP/EUR","bids":[{"price":0.47833,"qty":5200.00000000}],"asks":[],"checksum":1462436741,"timestamp":"2024-06-01T18:07:06.592228Z"}]}
{"channel":"book","type":"update","data":[{"symbol":"XRP/EUR","bids":[{"price":0.47834,"qty":0.00000000},{"price":0.47814,"qty":1594.00653543},{"price":0.47837,"qty":63.22170603}],"asks":[],"checksum":3997434221,"timestamp":"2024-06-01T18:07:06.592769Z"}]}
{"channel":"book","type":"update","data":[{"symbol":"XRP/EUR","bids":[{"price":0.47836,"qty":0.00000000},{"price":0.47814,"qty":1594.00653543}],"asks":[],"checksum":3251664752,"timestamp":"2024-06-01T18:07:06.600589Z"}]}
{"channel":"book","type":"update","data":[{"symbol":"XRP/EUR","bids":[],"asks":[{"price":0.47861,"qty":0.00000000},{"price":0.47869,"qty":3853.00000000}],"checksum":3310365714,"timestamp":"2024-06-01T18:07:06.602436Z"}]}
{"channel":"book","type":"update","data":[{"symbol":"XRP/EUR","bids":[{"price":0.47816,"qty":8663.77728000},{"price":0.47817,"qty":20960.19003270}],"asks":[],"checksum":2249823409,"timestamp":"2024-06-01T18:07:06.604271Z"}]}
{"channel":"book","type":"update","data":[{"symbol":"XRP/EUR","bids":[{"price":0.47837,"qty":0.00000000},{"price":0.47814,"qty":1594.00653543},{"price":0.47834,"qty":63.22567110}],"asks":[],"checksum":3147421461,"timestamp":"2024-06-01T18:07:06.607852Z"}]}
{"channel":"book","type":"update","data":[{"symbol":"XRP/EUR","bids":[],"asks":[{"price":0.47844,"qty":0.00000000},{"price":0.47872,"qty":9632.00000000}],"checksum":3917252288,"timestamp":"2024-06-01T18:07:06.653663Z"}]}
{"channel":"book","type":"update","data":[{"symbol":"XRP/EUR","bids":[{"price":0.47833,"qty":4000.00000000}],"asks":[],"checksum":690408072,"timestamp":"2024-06-01T18:07:06.656310Z"}]}
{"channel":"book","type":"update","data":[{"symbol":"XRP/EUR","bids":[{"price":0.47834,"qty":1263.22567110}],"asks":[],"checksum":2827760140,"timestamp":"2024-06-01T18:07:06.656858Z"}]}
{"channel":"book","type":"update","data":[{"symbol":"XRP/EUR","bids":[{"price":0.47834,"qty":1200.00000000},{"price":0.47835,"qty":63.22434936}],"asks":[],"checksum":3998938603,"timestamp":"2024-06-01T18:07:06.660385Z"}]}
{"channel":"book","type":"update","data":[{"symbol":"XRP/EUR","bids":[],"asks":[{"price":0.47844,"qty":9635.51520576}],"checksum":3500844565,"timestamp":"2024-06-01T18:07:06.706422Z"}]}
{"channel":"book","type":"update","data":[{"symbol":"XRP/EUR","bids":[{"price":0.47836,"qty":9636.87909431}],"asks":[],"checksum":2203188949,"timestamp":"2024-06-01T18:07:06.706485Z"}]}
{"channel":"book","type":"update","data":[{"symbol":"XRP/EUR","bids":[],"asks":[{"price":0.47861,"qty":3011.74580865}],"checksum":1256834207,"timestamp":"2024-06-01T18:07:06.710092Z"}]}
{"channel":"book","type":"update","data":[{"symbol":"XRP/EUR","bids":[{"price":0.47835,"qty":0.00000000},{"price":0.47816,"qty":8663.77728000},{"price":0.47837,"qty":63.22170603}],"asks":[],"checksum":3516155566,"timestamp":"2024-06-01T18:07:06.711872Z"}]}
{"channel":"book","type":"update","data":[{"symbol":"XRP/EUR","bids":[],"asks":[{"price":0.47844,"qty":0.00000000},{"price":0.47869,"qty":3853.00000000}],"checksum":2666373407,"timestamp":"2024-06-01T18:07:06.773756Z"}]}
{"channel":"book","type":"update","data":[{"symbol":"XRP/EUR","bids":[],"asks":[{"price":0.47849,"qty":0.00000000},{"price":0.47872,"qty":9632.00000000}],"checksum":3597869714,"timestamp":"2024-06-01T18:07:06.778043Z"}]}
{"channel":"book","type":"update","data":[{"symbol":"XRP/EUR","bids":[],"asks":[{"price":0.47848,"qty":9634.55157423}],"checksum":25283060,"timestamp":"2024-06-01T18:07:06.804446Z"}]}
{"channel":"book","type":"update","data":[{"symbol":"XRP/EUR","bids":[{"price":0.47834,"qty":10837.21545680}],"asks":[],"checksum":3250550531,"timestamp":"2024-06-01T18:07:06.809364Z"}]}
{"channel":"book","type":"update","data":[{"symbol":"XRP/EUR","bids":[],"asks":[{"price":0.47848,"qty":0.00000000},{"price":0.47872,"qty":9632.00000000}],"checksum":1706639749,"timestamp":"2024-06-01T18:07:06.809404Z"}]}
{"channel":"book","type":"update","data":[{"symbol":"XRP/EUR","bids":[],"asks":[{"price":0.47849,"qty":9634.35022098}],"checksum":4143456411,"timestamp":"2024-06-01T18:07:06.809480Z"}]}
{"channel":"book","type":"update","data":[{"symbol":"XRP/EUR","bids":[{"price":0.47834,"qty":9637.21545680}],"asks":[],"checksum":1043051237,"timestamp":"2024-06-01T18:07:06.812284Z"}]}
{"channel":"book","type":"update","data":[{"symbol":"XRP/EUR","bids":[{"price":0.47837,"qty":1263.22170603}],"asks":[],"checksum":3910591810,"timestamp":"2024-06-01T18:07:06.812396Z"}]}
{"channel":"book","type":"update","data":[{"symbol":"XRP/EUR","bids":[{"price":0.47837,"qty":1200.00000000},{"price":0.47838,"qty":63.22038479}],"asks":[],"checksum":2077697591,"timestamp":"2024-06-01T18:07:06.816736Z"}]}
{"channel":"book","type":"update","data":[{"symbol":"XRP/EUR","bids":[],"asks":[{"price":0.47844,"qty":9635.44586153}],"checksum":1219566749,"timestamp":"2024-06-01T18:07:06.939054Z"}]}
{"channel":"book","type":"update","data":[{"symbol":"XRP/EUR","bids":[{"price":0.47819,"qty":20960.19003270}],"asks":[],"checksum":701208536,"timestamp":"2024-06-01T18:07:07.056819Z"}]}
{"channel":"book","type":"update","data":[{"symbol":"XRP/EUR","bids":[{"price":0.47836,"qty":0.00000000},{"price":0.47818,"qty":12759.81095016}],"asks":[],"checksum":359830848,"timestamp":"2024-06-01T18:07:07.185382Z"}]}
{"channel":"book","type":"update","data":[{"symbol":"XRP/EUR","bids":[],"asks":[{"price":0.47844,"qty":0.00000000},{"price":0.47869,"qty":3853.00000000}],"checksum":591575436,"timestamp":"2024-06-01T18:07:07.185404Z"}]}
{"channel":"book","type":"update","data":[{"symbol":"XRP/EUR","bids":[{"price":0.47837,"qty":0.00000000},{"price":0.47816,"qty":8663.77728000}],"asks":[],"checksum":3725004469,"timestamp":"2024-06-01T18:07:07.188424Z"}]}
{"channel":"book","type":"update","data":[{"symbol":"XRP/EUR","bids":[{"price":0.47835,"qty":1200.00000000}],"asks":[],"checksum":3632141487,"timestamp":"2024-06-01T18:07:07.188438Z"}]}
{"channel":"book","type":"update","data":[{"symbol":"XRP/EUR","bids":[{"price":0.47838,"qty":0.00000000},{"price":0.47816,"qty":8663.77728000},{"price":0.47835,"qty":1263.22434992}],"asks":[],"checksum":3098218647,"timestamp":"2024-06-01T18:07:07.191568Z"}]}
{"channel":"book","type":"update","data":[{"symbol":"XRP/EUR","bids":[],"asks":[{"price":0.47849,"qty":0.00000000},{"price":0.47872,"qty":9632.00000000}],"checksum":1110928533,"timestamp":"2024-06-01T18:07:07.191611Z"}]}
{"channel":"book","type":"update","data":[{"symbol":"XRP/EUR","bids":[{"price":0.47835,"qty":1200.00000000},{"price":0.47836,"qty":63.22302823}],"asks":[],"checksum":2805008685,"timestamp":"2024-06-01T18:07:07.195309Z"}]}
{"channel":"book","type":"update","data":[{"symbol":"XRP/EUR","bids":[],"asks":[{"price":0.47842,"qty":9635.85729957}],"checksum":850134389,"timestamp":"2024-06-01T18:07:07.196525Z"}]}
{"channel":"book","type":"update","data":[{"symbol":"XRP/EUR","bids":[],"asks":[{"price":0.47848,"qty":9634.55157423}],"checksum":1039499848,"timestamp":"2024-06-01T18:07:07.196589Z"}]}
{"channel":"book","type":"update","data":[{"symbol":"XRP/EUR","bids":[{"price":0.47829,"qty":9638.31238186}],"asks":[],"checksum":1401552098,"timestamp":"2024-06-01T18:07:07.196609Z"}]}
{"channel":"book","type":"update","data":[{"symbol":"XRP/EUR","bids":[{"price":0.47834,"qty":13637.21545680}],"asks":[],"checksum":2359448010,"timestamp":"2024-06-01T18:07:07.495092Z"}]}
{"channel":"book","type":"update","data":[{"symbol":"XRP/EUR","bids":[{"price":0.47834,"qty":4000.00000000}],"asks":[],"checksum":256977732,"timestamp":"2024-06-01T18:07:07.567816Z"}]}
{"channel":"book","type":"update","data":[{"symbol":"XRP/EUR","bids":[],"asks":[{"price":0.47842,"qty":0.00000000},{"price":0.47869,"qty":3853.00000000}],"checksum":2337304612,"timestamp":"2024-06-01T18:07:07.567862Z"}]}
{"channel":"book","type":"update","data":[{"symbol":"XRP/EUR","bids":[],"asks":[{"price":0.47843,"qty":9635.61649403}],"checksum":125339474,"timestamp":"2024-06-01T18:07:07.573261Z"}]}
{"channel":"book","type":"update","data":[{"symbol":"XRP/EUR","bids":[{"price":0.47835,"qty":10837.04782500}],"asks":[],"checksum":3245761860,"timestamp":"2024-06-01T18:07:07.573378Z"}]}
{"channel":"book","type":"update","data":[{"symbol":"XRP/EUR","bids":[],"asks":[{"price":0.47843,"qty":0.00000000},{"price":0.47869,"qty":3853.00000000}],"checksum":2023528890,"timestamp":"2024-06-01T18:07:07.577432Z"}]}
{"channel":"book","type":"update","data":[{"symbol":"XRP/EUR","bids":[{"price":0.47833,"qty":0.00000000},{"price":0.47818,"qty":12759.81095016}],"asks":[],"checksum":2896957329,"timestamp":"2024-06-01T18:07:07.680817Z"}]}
{"channel":"book","type":"update","data":[{"symbol":"XRP/EUR","bids":[],"asks":[{"price":0.47848,"qty":0.00000000},{"price":0.47872,"qty":9632.00000000}],"checksum":145373463,"timestamp":"2024-06-01T18:07:07.940990Z"}]}
{"channel":"book","type":"update","data":[{"symbol":"XRP/EUR","bids":[{"price":0.47835,"qty":1200.00000000}],"asks":[],"checksum":1813681757,"timestamp":"2024-06-01T18:07:07.941031Z"}]}
{"channel":"book","type":"update","data":[{"symbol":"XRP/EUR","bids":[],"asks":[{"price":0.47842,"qty":9635.77260954}],"checksum":1013589463,"timestamp":"2024-06-01T18:07:07.945517Z"}]}
{"channel":"book","type":"update","data":[{"symbol":"XRP/EUR","bids":[{"price":0.47834,"qty":13637.29977904}],"asks":[],"checksum":2385711552,"timestamp":"2024-06-01T18:07:07.945556Z"}]}
{"channel":"book","type":"update","data":[{"symbol":"XRP/EUR","bids":[],"asks":[{"price":0.47847,"qty":9634.75293590}],"checksum":2331025844,"timestamp":"2024-06-01T18:07:07.945716Z"}]}
{"channel":"book","type":"update","data":[{"symbol":"XRP/EUR","bids":[{"price":0.47821,"qty":1412.63922260}],"asks":[],"checksum":1722944821,"timestamp":"2024-06-01T18:07:07.990908Z"}]}
{"channel":"book","type":"update","data":[{"symbol":"XRP/EUR","bids":[{"price":0.47821,"qty":1899.47799035}],"asks":[],"checksum":2496801429,"timestamp":"2024-06-01T18:07:07.997690Z"}]}
{"channel":"book","type":"update","data":[{"symbol":"XRP/EUR","bids":[{"price":0.47819,"qty":0.00000000},{"price":0.47816,"qty":8663.77728000},{"price":0.47817,"qty":20960.19003270}],"asks":[],"checksum":3209866523,"timestamp":"2024-06-01T18:07:08.187314Z"}]}
{"channel":"book","type":"update","data":[{"symbol":"XRP/EUR","bids":[],"asks":[{"price":0.47842,"qty":0.00000000},{"price":0.47869,"qty":3853.00000000}],"checksum":2141488940,"timestamp":"2024-06-01T18:07:08.246619Z"}]}
{"channel":"book","type":"update","data":[{"symbol":"XRP/EUR","bids":[],"asks":[{"price":0.47847,"qty":0.00000000},{"price":0.47872,"qty":9632.00000000}],"checksum":3064727522,"timestamp":"2024-06-01T18:07:08.251567Z"}]}
{"channel":"book","type":"update","data":[{"symbol":"XRP/EUR","bids":[],"asks":[{"price":0.47841,"qty":9636.03908712}],"checksum":903287205,"timestamp":"2024-06-01T18:07:08.255805Z"}]}
{"channel":"book","type":"update","data":[{"symbol":"XRP/EUR","bids":[],"asks":[{"price":0.47846,"qty":9634.95430598}],"checksum":2196199299,"timestamp":"2024-06-01T18:07:08.255988Z"}]}
{"channel":"book","type":"update","data":[{"symbol":"XRP/EUR","bids":[],"asks":[{"price":0.47861,"qty":3078.52624505}],"checksum":1994243678,"timestamp":"2024-06-01T18:07:09.128345Z"}]}
{"channel":"book","type":"update","data":[{"symbol":"XRP/EUR","bids":[{"price":0.47834,"qty":4000.00000000}],"asks":[],"checksum":2456652685,"timestamp":"2024-06-01T18:07:09.251798Z"}]}
{"channel":"book","type":"update","data":[{"symbol":"XRP/EUR","bids":[{"price":0.47833,"qty":9637.49721500}],"asks":[],"checksum":594369532,"timestamp":"2024-06-01T18:07:09.256078Z"}]}
{"channel":"book","type":"update","data":[{"symbol":"XRP/EUR","bids":[{"price":0.47821,"qty":1412.63922260}],"asks":[],"checksum":446962449,"timestamp":"2024-06-01T18:07:10.345719Z"}]}
{"channel":"book","type":"update","data":[{"symbol":"XRP/EUR","bids":[{"price":0.47821,"qty":1839.70798777}],"asks":[],"checksum":4169744811,"timestamp":"2024-06-01T18:07:10.350941Z"}]}
{"channel":"book","type":"update","data":[{"symbol":"XRP/EUR","bids":[{"price":0.47819,"qty":486.83876775}],"asks":[],"checksum":3005254104,"timestamp":"2024-06-01T18:07:10.351083Z"}]}
{"channel":"book","type":"update","data":[{"symbol":"XRP/EUR","bids":[],"asks":[{"price":0.47841,"qty":0.00000000},{"price":0.47869,"qty":3853.00000000}],"checksum":819634971,"timestamp":"2024-06-01T18:07:10.905723Z"}]}
{"channel":"book","type":"update","data":[{"symbol":"XRP/EUR","bids":[{"price":0.47833,"qty":0.00000000},{"price":0.47818,"qty":12759.81095016}],"asks":[],"checksum":2614982169,"timestamp":"2024-06-01T18:07:10.905847Z"}]}
{"channel":"book","type":"update","data":[{"symbol":"XRP/EUR","bids":[{"price":0.47819,"qty":21447.02880045}],"asks":[],"checksum":4037459021,"timestamp":"2024-06-01T18:07:10.908839Z"}]}
{"channel":"book","type":"update","data":[{"symbol":"XRP/EUR","bids":[{"price":0.47834,"qty":13637.23020947}],"asks":[],"checksum":2408686501,"timestamp":"2024-06-01T18:07:10.910621Z"}]}
{"channel":"book","type":"update","data":[{"symbol":"XRP/EUR","bids":[],"asks":[{"price":0.47842,"qty":9635.79255622}],"checksum":3790179124,"timestamp":"2024-06-01T18:07:10.910650Z"}]}
{"channel":"book","type":"update","data":[{"symbol":"XRP/EUR","bids":[{"price":0.47834,"qty":4000.00000000}],"asks":[],"checksum":3817392858,"timestamp":"2024-06-01T18:07:10.984758Z"}]}
{"channel":"book","type":"update","data":[{"symbol":"XRP/EUR","bids":[],"asks":[{"price":0.47842,"qty":0.00000000},{"price":0.47869,"qty":3853.00000000}],"checksum":4037459021,"timestamp":"2024-06-01T18:07:10.984772Z"}]}
{"channel":"book","type":"update","data":[{"symbol":"XRP/EUR","bids":[{"price":0.47819,"qty":486.83876775}],"asks":[],"checksum":2614982169,"timestamp":"2024-06-01T18:07:10.987829Z"}]}
{"channel":"book","type":"update","data":[{"symbol":"XRP/EUR","bids":[{"price":0.47833,"qty":9637.49704071}],"asks":[],"checksum":3902195686,"timestamp":"2024-06-01T18:07:11.035063Z"}]}
{"channel":"book","type":"update","data":[{"symbol":"XRP/EUR","bids":[],"asks":[{"price":0.47841,"qty":9636.11039608}],"checksum":118979647,"timestamp":"2024-06-01T18:07:11.035187Z"}]}
{"channel":"book","type":"update","data":[{"symbol":"XRP/EUR","bids":[{"price":0.47821,"qty":427.06876517}],"asks":[],"checksum":3534290,"timestamp":"2024-06-01T18:07:11.222105Z"}]}
{"channel":"book","type":"update","data":[{"symbol":"XRP/EUR","bids":[],"asks":[{"price":0.47841,"qty":0.00000000},{"price":0.47869,"qty":3853.00000000}],"checksum":1419648657,"timestamp":"2024-06-01T18:07:11.226496Z"}]}
{"channel":"book","type":"update","data":[{"symbol":"XRP/EUR","bids":[{"price":0.47833,"qty":0.00000000},{"price":0.47818,"qty":12759.81095016}],"asks":[],"checksum":3129001,"timestamp":"2024-06-01T18:07:11.226528Z"}]}
{"channel":"book","type":"update","data":[{"symbol":"XRP/EUR","bids":[],"asks":[{"price":0.47846,"qty":0.00000000},{"price":0.47872,"qty":9632.00000000}],"checksum":3259114148,"timestamp":"2024-06-01T18:07:11.233274Z"}]}
{"channel":"book","type":"update","data":[{"symbol":"XRP/EUR","bids":[{"price":0.47821,"qty":21387.25879787}],"asks":[],"checksum":3644888941,"timestamp":"2024-06-01T18:07:11.237803Z"}]}
{"channel":"book","type":"update","data":[{"symbol":"XRP/EUR","bids":[],"asks":[{"price":0.47840,"qty":9636.35405126}],"checksum":597886553,"timestamp":"2024-06-01T18:07:11.237874Z"}]}
{"channel":"book","type":"update","data":[{"symbol":"XRP/EUR","bids":[{"price":0.47832,"qty":9637.70412361}],"asks":[],"checksum":681490524,"timestamp":"2024-06-01T18:07:11.237905Z"}]}
{"channel":"book","type":"update","data":[{"symbol":"XRP/EUR","bids":[],"asks":[{"price":0.47845,"qty":9635.15568448}],"checksum":4113283046,"timestamp":"2024-06-01T18:07:11.237970Z"}]}
{"channel":"book","type":"update","data":[{"symbol":"XRP/EUR","bids":[{"price":0.47821,"qty":427.06876517}],"asks":[],"checksum":2591812474,"timestamp":"2024-06-01T18:07:11.282739Z"}]}
{"channel":"book","type":"update","data":[{"symbol":"XRP/EUR","bids":[{"price":0.47835,"qty":0.00000000},{"price":0.47818,"qty":12759.81095016}],"asks":[],"checksum":564320306,"timestamp":"2024-06-01T18:07:11.296184Z"}]}
{"channel":"book","type":"update","data":[{"symbol":"XRP/EUR","bids":[{"price":0.47836,"qty":0.00000000},{"price":0.47817,"qty":20960.19003270},{"price":0.47835,"qty":63.28435933}],"asks":[],"checksum":2125299166,"timestamp":"2024-06-01T18:07:11.299335Z"}]}
{"channel":"book","type":"update","data":[{"symbol":"XRP/EUR","bids":[],"asks":[{"price":0.47840,"qty":0.00000000},{"price":0.47869,"qty":3853.00000000}],"checksum":1420557476,"timestamp":"2024-06-01T18:07:11.363200Z"}]}
{"channel":"book","type":"update","data":[{"symbol":"XRP/EUR","bids":[],"asks":[{"price":0.47839,"qty":9636.38102131}],"checksum":3823555485,"timestamp":"2024-06-01T18:07:11.368291Z"}]}
{"channel":"book","type":"update","data":[{"symbol":"XRP/EUR","bids":[{"price":0.47820,"qty":20692.80130115}],"asks":[],"checksum":1206585572,"timestamp":"2024-06-01T18:07:11.373980Z"}]}
{"channel":"book","type":"update","data":[{"symbol":"XRP/EUR","bids":[],"asks":[{"price":0.47839,"qty":0.00000000},{"price":0.47869,"qty":3853.00000000}],"checksum":4037421021,"timestamp":"2024-06-01T18:07:11.443249Z"}]}
{"channel":"book","type":"update","data":[{"symbol":"XRP/EUR","bids":[{"price":0.47832,"qty":0.00000000},{"price":0.47817,"qty":20960.19003270}],"asks":[],"checksum":3169297473,"timestamp":"2024-06-01T18:07:11.443262Z"}]}
{"channel":"book","type":"update","data":[{"symbol":"XRP/EUR","bids":[],"asks":[{"price":0.47845,"qty":0.00000000},{"price":0.47872,"qty":9632.00000000}],"checksum":1023697478,"timestamp":"2024-06-01T18:07:11.448110Z"}]}
{"channel":"book","type":"update","data":[{"symbol":"XRP/EUR","bids":[],"asks":[{"price":0.47844,"qty":9635.35707140}],"checksum":1023452721,"timestamp":"2024-06-01T18:07:11.453748Z"}]}
{"channel":"book","type":"update","data":[{"symbol":"XRP/EUR","bids":[{"price":0.47830,"qty":9638.05483090}],"asks":[],"checksum":423329566,"timestamp":"2024-06-01T18:07:11.453769Z"}]}
{"channel":"book","type":"update","data":[{"symbol":"XRP/EUR","bids":[{"price":0.47820,"qty":19280.13253779}],"asks":[],"checksum":3174474855,"timestamp":"2024-06-01T18:07:11.463793Z"}]}
{"channel":"book","type":"update","data":[{"symbol":"XRP/EUR","bids":[],"asks":[{"price":0.47844,"qty":0.00000000},{"price":0.47872,"qty":9632.00000000}],"checksum":3119698791,"timestamp":"2024-06-01T18:07:11.464430Z"}]}
{"channel":"book","type":"update","data":[{"symbol":"XRP/EUR","bids":[],"asks":[{"price":0.47838,"qty":9636.61705463}],"checksum":3320252667,"timestamp":"2024-06-01T18:07:11.468594Z"}]}
{"channel":"book","type":"update","data":[{"symbol":"XRP/EUR","bids":[{"price":0.47818,"qty":14172.53879875}],"asks":[],"checksum":2426407280,"timestamp":"2024-06-01T18:07:11.581488Z"}]}
{"channel":"book","type":"update","data":[{"symbol":"XRP/EUR","bids":[],"asks":[{"price":0.47861,"qty":3011.74580865}],"checksum":2016574826,"timestamp":"2024-06-01T18:07:11.585936Z"}]}
{"channel":"book","type":"update","data":[{"symbol":"XRP/EUR","bids":[],"asks":[{"price":0.47861,"qty":3050.30994302}],"checksum":904887892,"timestamp":"2024-06-01T18:07:11.586855Z"}]}
{"channel":"book","type":"update","data":[{"symbol":"XRP/EUR","bids":[],"asks":[{"price":0.47843,"qty":9635.58805447}],"checksum":2842267783,"timestamp":"2024-06-01T18:07:11.981787Z"}]}
{"channel":"book","type":"update","data":[{"symbol":"XRP/EUR","bids":[],"asks":[{"price":0.47838,"qty":0.00000000},{"price":0.47869,"qty":3853.00000000}],"checksum":2431974788,"timestamp":"2024-06-01T18:07:12.112387Z"}]}
{"channel":"book","type":"update","data":[{"symbol":"XRP/EUR","bids":[{"price":0.47830,"qty":0.00000000},{"price":0.47816,"qty":8663.77728000}],"asks":[],"checksum":3135239552,"timestamp":"2024-06-01T18:07:12.112559Z"}]}
{"channel":"book","type":"update","data":[{"symbol":"XRP/EUR","bids":[{"price":0.47832,"qty":9637.64985701}],"asks":[],"checksum":2592052503,"timestamp":"2024-06-01T18:07:12.117361Z"}]}
{"channel":"book","type":"update","data":[{"symbol":"XRP/EUR","bids":[],"asks":[{"price":0.47840,"qty":9636.21033471}],"checksum":969922838,"timestamp":"2024-06-01T18:07:12.117492Z"}]}
{"channel":"book","type":"update","data":[{"symbol":"XRP/EUR","bids":[{"price":0.47821,"qty":0.00000000},{"price":0.47816,"qty":8663.77728000}],"asks":[],"checksum":152431106,"timestamp":"2024-06-01T18:07:12.629283Z"}]}
{"channel":"book","type":"update","data":[{"symbol":"XRP/EUR","bids":[{"price":0.47819,"qty":0.00000000},{"price":0.47815,"qty":4493.03245185}],"asks":[],"checksum":1658125888,"timestamp":"2024-06-01T18:07:12.629503Z"}]}
{"channel":"book","type":"update","data":[{"symbol":"XRP/EUR","bids":[{"price":0.47821,"qty":277.64653748}],"asks":[],"checksum":3800237438,"timestamp":"2024-06-01T18:07:12.635295Z"}]}
{"channel":"book","type":"update","data":[{"symbol":"XRP/EUR","bids":[{"price":0.47817,"qty":337.41713826}],"asks":[],"checksum":4169099170,"timestamp":"2024-06-01T18:07:12.635424Z"}]}
{"channel":"book","type":"update","data":[{"symbol":"XRP/EUR","bids":[],"asks":[{"price":0.47840,"qty":0.00000000},{"price":0.47869,"qty":3853.00000000}],"checksum":1540303779,"timestamp":"2024-06-01T18:07:12.865163Z"}]}
{"channel":"book","type":"update","data":[{"symbol":"XRP/EUR","bids":[],"asks":[{"price":0.47839,"qty":9636.44105887}],"checksum":2779299818,"timestamp":"2024-06-01T18:07:12.869234Z"}]}
{"channel":"book","type":"update","data":[{"symbol":"XRP/EUR","bids":[{"price":0.47817,"qty":21297.60717096}],"asks":[],"checksum":1991877792,"timestamp":"2024-06-01T18:07:13.086667Z"}]}
{"channel":"book","type":"update","data":[{"symbol":"XRP/EUR","bids":[{"price":0.47832,"qty":0.00000000},{"price":0.47816,"qty":8663.77728000}],"asks":[],"checksum":2730509308,"timestamp":"2024-06-01T18:07:13.087029Z"}]}
{"channel":"book","type":"update","data":[{"symbol":"XRP/EUR","bids":[{"price":0.47831,"qty":9637.90855305}],"asks":[],"checksum":4251475149,"timestamp":"2024-06-01T18:07:13.091615Z"}]}
{"channel":"book","type":"update","data":[{"symbol":"XRP/EUR","bids":[],"asks":[{"price":0.47839,"qty":0.00000000},{"price":0.47869,"qty":3853.00000000}],"checksum":733020603,"timestamp":"2024-06-01T18:07:13.217863Z"}]}
{"channel":"book","type":"update","data":[{"symbol":"XRP/EUR","bids":[{"price":0.47831,"qty":0.00000000},{"price":0.47816,"qty":8663.77728000}],"asks":[],"checksum":1947803274,"timestamp":"2024-06-01T18:07:13.217957Z"}]}
{"channel":"book","type":"update","data":[{"symbol":"XRP/EUR","bids":[],"asks":[{"price":0.47840,"qty":9636.22305879}],"checksum":2229275146,"timestamp":"2024-06-01T18:07:13.222634Z"}]}
{"channel":"book","type":"update","data":[{"symbol":"XRP/EUR","bids":[{"price":0.47832,"qty":9637.66077627}],"asks":[],"checksum":419115421,"timestamp":"2024-06-01T18:07:13.222650Z"}]}
{"channel":"book","type":"update","data":[{"symbol":"XRP/EUR","bids":[],"asks":[{"price":0.47840,"qty":0.00000000},{"price":0.47869,"qty":3853.00000000}],"checksum":3892454685,"timestamp":"2024-06-01T18:07:14.145967Z"}]}
{"channel":"book","type":"update","data":[{"symbol":"XRP/EUR","bids":[{"price":0.47832,"qty":0.00000000},{"price":0.47816,"qty":8663.77728000}],"asks":[],"checksum":1947803274,"timestamp":"2024-06-01T18:07:14.145989Z"}]}
{"channel":"book","type":"update","data":[{"symbol":"XRP/EUR","bids":[{"price":0.47834,"qty":5200.00000000}],"asks":[],"checksum":2486828021,"timestamp":"2024-06-01T18:07:14.148755Z"}]}
{"channel":"book","type":"update","data":[{"symbol":"XRP/EUR","bids":[],"asks":[{"price":0.47839,"qty":9636.47551182}],"checksum":1077761224,"timestamp":"2024-06-01T18:07:14.151463Z"}]}
{"channel":"book","type":"update","data":[{"symbol":"XRP/EUR","bids":[{"price":0.47831,"qty":9637.91326697}],"asks":[],"checksum":3465330147,"timestamp":"2024-06-01T18:07:14.151554Z"}]}
{"channel":"book","type":"update","data":[{"symbol":"XRP/EUR","bids":[],"asks":[{"price":0.47862,"qty":0.00000000},{"price":0.47869,"qty":3853.00000000}],"checksum":997830490,"timestamp":"2024-06-01T18:07:14.154269Z"}]}
{"channel":"book","type":"update","data":[{"symbol":"XRP/EUR","bids":[{"price":0.47817,"qty":337.41713826}],"asks":[],"checksum":3362609708,"timestamp":"2024-06-01T18:07:14.154616Z"}]}
{"channel":"book","type":"update","data":[{"symbol":"XRP/EUR","bids":[],"asks":[{"price":0.47862,"qty":21474.67288077}],"checksum":297692722,"timestamp":"2024-06-01T18:07:14.156892Z"}]}
{"channel":"book","type":"update","data":[{"symbol":"XRP/EUR","bids":[],"asks":[{"price":0.47839,"qty":0.00000000},{"price":0.47869,"qty":3853.00000000}],"checksum":1577065217,"timestamp":"2024-06-01T18:07:14.989126Z"}]}
{"channel":"book","type":"update","data":[{"symbol":"XRP/EUR","bids":[{"price":0.47831,"qty":0.00000000},{"price":0.47816,"qty":29623.96731270}],"asks":[],"checksum":4072081436,"timestamp":"2024-06-01T18:07:14.989173Z"}]}
{"channel":"book","type":"update","data":[{"symbol":"XRP/EUR","bids":[{"price":0.47816,"qty":8663.77728000},{"price":0.47817,"qty":21297.60717096}],"asks":[],"checksum":2486828021,"timestamp":"2024-06-01T18:07:14.992395Z"}]}
{"channel":"book","type":"update","data":[{"symbol":"XRP/EUR","bids":[],"asks":[{"price":0.47840,"qty":9636.23111038}],"checksum":1286116645,"timestamp":"2024-06-01T18:07:14.994681Z"}]}
{"channel":"book","type":"update","data":[{"symbol":"XRP/EUR","bids":[{"price":0.47832,"qty":9637.67003355}],"asks":[],"checksum":3740395376,"timestamp":"2024-06-01T18:07:14.994860Z"}]}
{"channel":"book","type":"update","data":[{"symbol":"XRP/EUR","bids":[{"price":0.47817,"qty":20960.19003270}],"asks":[],"checksum":3072427103,"timestamp":"2024-06-01T18:07:15.024919Z"}]}
{"channel":"book","type":"update","data":[{"symbol":"XRP/EUR","bids":[{"price":0.47817,"qty":21387.26307213}],"asks":[],"checksum":182561025,"timestamp":"2024-06-01T18:07:15.030311Z"}]}
{"channel":"book","type":"update","data":[{"symbol":"XRP/EUR","bids":[{"price":0.47832,"qty":0.00000000},{"price":0.47816,"qty":8663.77728000}],"asks":[],"checksum":1492165743,"timestamp":"2024-06-01T18:07:15.063534Z"}]}
{"channel":"book","type":"update","data":[{"symbol":"XRP/EUR","bids":[{"price":0.47835,"qty":1263.28435933}],"asks":[],"checksum":310661488,"timestamp":"2024-06-01T18:07:15.096537Z"}]}
{"channel":"book","type":"update","data":[{"symbol":"XRP/EUR","bids":[{"price":0.47834,"qty":4000.00000000}],"asks":[],"checksum":4070880271,"timestamp":"2024-06-01T18:07:15.096716Z"}]}
{"channel":"book","type":"update","data":[{"symbol":"XRP/EUR","bids":[{"price":0.47835,"qty":1200.00000000},{"price":0.47836,"qty":63.24791713}],"asks":[],"checksum":4242812423,"timestamp":"2024-06-01T18:07:15.100135Z"}]}
{"channel":"book","type":"update","data":[{"symbol":"XRP/EUR","bids":[],"asks":[{"price":0.47840,"qty":0.00000000},{"price":0.47869,"qty":3853.00000000}],"checksum":611664087,"timestamp":"2024-06-01T18:07:15.108222Z"}]}
{"channel":"book","type":"update","data":[{"symbol":"XRP/EUR","bids":[{"price":0.47834,"qty":13637.36217723}],"asks":[],"checksum":2750230741,"timestamp":"2024-06-01T18:07:15.113138Z"}]}
{"channel":"book","type":"update","data":[{"symbol":"XRP/EUR","bids":[],"asks":[{"price":0.47842,"qty":9635.92330004}],"checksum":625001043,"timestamp":"2024-06-01T18:07:15.113225Z"}]}
{"channel":"book","type":"update","data":[{"symbol":"XRP/EUR","bids":[],"asks":[{"price":0.47842,"qty":0.00000000},{"price":0.47869,"qty":3853.00000000}],"checksum":2750230741,"timestamp":"2024-06-01T18:07:15.583172Z"}]}
{"channel":"book","type":"update","data":[{"symbol":"XRP/EUR","bids":[{"price":0.47834,"qty":4000.00000000}],"asks":[],"checksum":611664087,"timestamp":"2024-06-01T18:07:15.583272Z"}]}
{"channel":"book","type":"update","data":[{"symbol":"XRP/EUR","bids":[],"asks":[{"price":0.47838,"qty":9636.61259534}],"checksum":1332134553,"timestamp":"2024-06-01T18:07:15.588127Z"}]}
{"channel":"book","type":"update","data":[{"symbol":"XRP/EUR","bids":[{"price":0.47830,"qty":9638.05540839}],"asks":[],"checksum":3211851262,"timestamp":"2024-06-01T18:07:15.588152Z"}]}
{"channel":"book","type":"update","data":[{"symbol":"XRP/EUR","bids":[{"price":0.47830,"qty":0.00000000},{"price":0.47817,"qty":427.07303943}],"asks":[],"checksum":2844835342,"timestamp":"2024-06-01T18:07:15.983707Z"}]}
{"channel":"book","type":"update","data":[{"symbol":"XRP/EUR","bids":[{"price":0.47831,"qty":9637.88874210}],"asks":[],"checksum":3640720425,"timestamp":"2024-06-01T18:07:15.987730Z"}]}
{"channel":"book","type":"update","data":[{"symbol":"XRP/EUR","bids":[],"asks":[{"price":0.47838,"qty":0.00000000},{"price":0.47869,"qty":3853.00000000}],"checksum":2714977913,"timestamp":"2024-06-01T18:07:16.087361Z"}]}
{"channel":"book","type":"update","data":[{"symbol":"XRP/EUR","bids":[],"asks":[{"price":0.47839,"qty":9636.42970236}],"checksum":395859353,"timestamp":"2024-06-01T18:07:16.092561Z"}]}
{"channel":"book","type":"update","data":[{"symbol":"XRP/EUR","bids":[{"price":0.47831,"qty":0.00000000},{"price":0.47817,"qty":427.07303943}],"asks":[],"checksum":1356697977,"timestamp":"2024-06-01T18:07:16.113673Z"}]}
{"channel":"book","type":"update","data":[{"symbol":"XRP/EUR","bids":[{"price":0.47832,"qty":9637.70197444}],"asks":[],"checksum":2715355359,"timestamp":"2024-06-01T18:07:16.117533Z"}]}
{"channel":"book","type":"update","data":[{"symbol":"XRP/EUR","bids":[],"asks":[{"price":0.47839,"qty":0.00000000},{"price":0.47869,"qty":3853.00000000}],"checksum":395451199,"timestamp":"2024-06-01T18:07:16.154263Z"}]}
{"channel":"book","type":"update","data":[{"symbol":"XRP/EUR","bids":[{"price":0.47832,"qty":0.00000000},{"price":0.47817,"qty":427.07303943}],"asks":[],"checksum":2112048198,"timestamp":"2024-06-01T18:07:16.154470Z"}]}
{"channel":"book","type":"update","data":[{"symbol":"XRP/EUR","bids":[],"asks":[{"price":0.47840,"qty":9636.24476643}],"checksum":1086572715,"timestamp":"2024-06-01T18:07:16.224765Z"}]}
{"channel":"book","type":"update","data":[{"symbol":"XRP/EUR","bids":[{"price":0.47833,"qty":9637.55169627}],"asks":[],"checksum":3489263934,"timestamp":"2024-06-01T18:07:16.224858Z"}]}
{"channel":"book","type":"update","data":[{"symbol":"XRP/EUR","bids":[{"price":0.47834,"qty":0.00000000},{"price":0.47817,"qty":427.07303943}],"asks":[],"checksum":4270401866,"timestamp":"2024-06-01T18:07:16.410359Z"}]}
{"channel":"book","type":"update","data":[{"symbol":"XRP/EUR","bids":[],"asks":[{"price":0.47861,"qty":3011.74580865}],"checksum":817969448,"timestamp":"2024-06-01T18:07:16.484925Z"}]}
{"channel":"book","type":"update","data":[{"symbol":"XRP/EUR","bids":[{"price":0.47817,"qty":21387.26307213}],"asks":[],"checksum":4284796527,"timestamp":"2024-06-01T18:07:16.876393Z"}]}
{"channel":"book","type":"update","data":[{"symbol":"XRP/EUR","bids":[],"asks":[{"price":0.47840,"qty":0.00000000},{"price":0.47869,"qty":3853.00000000}],"checksum":1825696196,"timestamp":"2024-06-01T18:07:16.920117Z"}]}
{"channel":"book","type":"update","data":[{"symbol":"XRP/EUR","bids":[],"asks":[{"price":0.47841,"qty":9635.98724574}],"checksum":2685582993,"timestamp":"2024-06-01T18:07:16.927773Z"}]}
{"channel":"book","type":"update","data":[{"symbol":"XRP/EUR","bids":[{"price":0.47834,"qty":4000.00000000}],"asks":[],"checksum":527650659,"timestamp":"2024-06-01T18:07:17.194672Z"}]}
{"channel":"book","type":"update","data":[{"symbol":"XRP/EUR","bids":[{"price":0.47821,"qty":0.00000000},{"price":0.47817,"qty":21387.26307213}],"asks":[],"checksum":2035756615,"timestamp":"2024-06-01T18:07:17.444574Z"}]}
{"channel":"book","type":"update","data":[{"symbol":"XRP/EUR","bids":[{"price":0.47817,"qty":20960.19003270}],"asks":[],"checksum":3298231065,"timestamp":"2024-06-01T18:07:17.445067Z"}]}
{"channel":"book","type":"update","data":[{"symbol":"XRP/EUR","bids":[{"price":0.47821,"qty":306.60229504}],"asks":[],"checksum":569583464,"timestamp":"2024-06-01T18:07:17.449363Z"}]}
{"channel":"book","type":"update","data":[{"symbol":"XRP/EUR","bids":[{"price":0.47819,"qty":425.73036645}],"asks":[],"checksum":1648973859,"timestamp":"2024-06-01T18:07:17.449722Z"}]}
{"channel":"book","type":"update","data":[{"symbol":"XRP/EUR","bids":[{"price":0.47833,"qty":0.00000000},{"price":0.47818,"qty":14172.53879875}],"asks":[],"checksum":784937409,"timestamp":"2024-06-01T18:07:18.750425Z"}]}
{"channel":"book","type":"update","data":[{"symbol":"XRP/EUR","bids":[],"asks":[{"price":0.47841,"qty":0.00000000},{"price":0.47869,"qty":3853.00000000}],"checksum":3030129911,"timestamp":"2024-06-01T18:07:18.750491Z"}]}
{"channel":"book","type":"update","data":[{"symbol":"XRP/EUR","bids":[{"price":0.47832,"qty":9637.76263402}],"asks":[],"checksum":3520940128,"timestamp":"2024-06-01T18:07:18.755669Z"}]}
{"channel":"book","type":"update","data":[{"symbol":"XRP/EUR","bids":[],"asks":[{"price":0.47840,"qty":9636.31159670}],"checksum":2315516651,"timestamp":"2024-06-01T18:07:18.755681Z"}]}
{"channel":"book","type":"update","data":[{"symbol":"XRP/EUR","bids":[{"price":0.47832,"qty":0.00000000},{"price":0.47818,"qty":12759.81095016}],"asks":[],"checksum":2615843174,"timestamp":"2024-06-01T18:07:18.924346Z"}]}
{"channel":"book","type":"update","data":[{"symbol":"XRP/EUR","bids":[],"asks":[{"price":0.47840,"qty":0.00000000},{"price":0.47869,"qty":3853.00000000}],"checksum":3789233532,"timestamp":"2024-06-01T18:07:18.924544Z"}]}
{"channel":"book","type":"update","data":[{"symbol":"XRP/EUR","bids":[{"price":0.47831,"qty":9637.90756202}],"asks":[],"checksum":3924478822,"timestamp":"2024-06-01T18:07:18.931049Z"}]}
{"channel":"book","type":"update","data":[{"symbol":"XRP/EUR","bids":[],"asks":[{"price":0.47839,"qty":9636.45650289}],"checksum":346769916,"timestamp":"2024-06-01T18:07:18.931108Z"}]}
{"channel":"book","type":"update","data":[{"symbol":"XRP/EUR","bids":[],"asks":[{"price":0.47861,"qty":3087.93257021}],"checksum":2448038171,"timestamp":"2024-06-01T18:07:19.007479Z"}]}
{"channel":"book","type":"update","data":[{"symbol":"XRP/EUR","bids":[{"price":0.47831,"qty":0.00000000},{"price":0.47818,"qty":12759.81095016}],"asks":[],"checksum":3474395183,"timestamp":"2024-06-01T18:07:19.073856Z"}]}
{"channel":"book","type":"update","data":[{"symbol":"XRP/EUR","bids":[],"asks":[{"price":0.47839,"qty":0.00000000},{"price":0.47869,"qty":3853.00000000}],"checksum":4266978331,"timestamp":"2024-06-01T18:07:19.073911Z"}]}
{"channel":"book","type":"update","data":[{"symbol":"XRP/EUR","bids":[{"price":0.47835,"qty":0.00000000},{"price":0.47816,"qty":8663.77728000}],"asks":[],"checksum":4035549756,"timestamp":"2024-06-01T18:07:19.076705Z"}]}
{"channel":"book","type":"update","data":[{"symbol":"XRP/EUR","bids":[{"price":0.47834,"qty":5200.00000000}],"asks":[],"checksum":4079798123,"timestamp":"2024-06-01T18:07:19.076965Z"}]}
{"channel":"book","type":"update","data":[{"symbol":"XRP/EUR","bids":[{"price":0.47816,"qty":29623.96731270}],"asks":[],"checksum":3023312059,"timestamp":"2024-06-01T18:07:19.076987Z"}]}
{"channel":"book","type":"update","data":[{"symbol":"XRP/EUR","bids":[{"price":0.47819,"qty":1838.42867181}],"asks":[],"checksum":517687811,"timestamp":"2024-06-01T18:07:19.077758Z"}]}
{"channel":"book","type":"update","data":[{"symbol":"XRP/EUR","bids":[{"price":0.47830,"qty":9638.12213479}],"asks":[],"checksum":4063846504,"timestamp":"2024-06-01T18:07:19.078241Z"}]}
{"channel":"book","type":"update","data":[{"symbol":"XRP/EUR","bids":[],"asks":[{"price":0.47838,"qty":9636.67104333}],"checksum":3683714682,"timestamp":"2024-06-01T18:07:19.078430Z"}]}
{"channel":"book","type":"update","data":[{"symbol":"XRP/EUR","bids":[{"price":0.47836,"qty":0.00000000},{"price":0.47816,"qty":29623.96731270},{"price":0.47835,"qty":63.22266324}],"asks":[],"checksum":2548905245,"timestamp":"2024-06-01T18:07:19.080065Z"}]}
{"channel":"book","type":"update","data":[{"symbol":"XRP/EUR","bids":[],"asks":[{"price":0.47838,"qty":0.00000000},{"price":0.47869,"qty":3853.00000000}],"checksum":3192214287,"timestamp":"2024-06-01T18:07:19.082575Z"}]}
{"channel":"book","type":"update","data":[{"symbol":"XRP/EUR","bids":[],"asks":[{"price":0.47849,"qty":1363.73000000}],"checksum":2308828790,"timestamp":"2024-06-01T18:07:19.336808Z"}]}
{"channel":"book","type":"update","data":[{"symbol":"XRP/EUR","bids":[{"price":0.47836,"qty":4000.00000000}],"asks":[],"checksum":675735917,"timestamp":"2024-06-01T18:07:19.379672Z"}]}
{"channel":"book","type":"update","data":[{"symbol":"XRP/EUR","bids":[{"price":0.47835,"qty":0.00000000},{"price":0.47818,"qty":12759.81095016},{"price":0.47837,"qty":63.20411774}],"asks":[],"checksum":2907320745,"timestamp":"2024-06-01T18:07:19.383422Z"}]}
{"channel":"book","type":"update","data":[{"symbol":"XRP/EUR","bids":[{"price":0.47834,"qty":1200.00000000}],"asks":[],"checksum":4255756756,"timestamp":"2024-06-01T18:07:19.559214Z"}]}
{"channel":"book","type":"update","data":[{"symbol":"XRP/EUR","bids":[{"price":0.47834,"qty":0.00000000},{"price":0.47818,"qty":12759.81095016}],"asks":[],"checksum":3161197284,"timestamp":"2024-06-01T18:07:19.561831Z"}]}
{"channel":"book","type":"update","data":[{"symbol":"XRP/EUR","bids":[{"price":0.47821,"qty":0.00000000},{"price":0.47816,"qty":29623.96731270}],"asks":[],"checksum":3807841875,"timestamp":"2024-06-01T18:07:19.866451Z"}]}
{"channel":"book","type":"update","data":[{"symbol":"XRP/EUR","bids":[{"price":0.47819,"qty":1412.69830536}],"asks":[],"checksum":4251976349,"timestamp":"2024-06-01T18:07:19.866731Z"}]}
{"channel":"book","type":"update","data":[{"symbol":"XRP/EUR","bids":[{"price":0.47821,"qty":217.87593671}],"asks":[],"checksum":609230264,"timestamp":"2024-06-01T18:07:19.872827Z"}]}
{"channel":"book","type":"update","data":[{"symbol":"XRP/EUR","bids":[{"price":0.47829,"qty":0.00000000},{"price":0.47816,"qty":29623.96731270}],"asks":[],"checksum":4025594840,"timestamp":"2024-06-01T18:07:20.392777Z"}]}
{"channel":"book","type":"update","data":[{"symbol":"XRP/EUR","bids":[],"asks":[{"price":0.47843,"qty":0.00000000},{"price":0.47869,"qty":3853.00000000}],"checksum":3936601459,"timestamp":"2024-06-01T18:07:20.392794Z"}]}
{"channel":"book","type":"update","data":[{"symbol":"XRP/EUR","bids":[{"price":0.47816,"qty":8663.77728000},{"price":0.47817,"qty":20960.19003270}],"asks":[],"checksum":2627379026,"timestamp":"2024-06-01T18:07:20.396054Z"}]}
{"channel":"book","type":"update","data":[{"symbol":"XRP/EUR","bids":[],"asks":[{"price":0.47842,"qty":9635.75987049}],"checksum":2463410814,"timestamp":"2024-06-01T18:07:20.397973Z"}]}
{"channel":"book","type":"update","data":[{"symbol":"XRP/EUR","bids":[],"asks":[{"price":0.47838,"qty":9636.68067584}],"checksum":1683990826,"timestamp":"2024-06-01T18:07:20.398022Z"}]}
{"channel":"book","type":"update","data":[{"symbol":"XRP/EUR","bids":[{"price":0.47824,"qty":15488.87131686}],"asks":[],"checksum":124889618,"timestamp":"2024-06-01T18:07:20.398110Z"}]}
{"channel":"book","type":"update","data":[{"symbol":"XRP/EUR","bids":[{"price":0.47837,"qty":0.00000000},{"price":0.47816,"qty":8663.77728000},{"price":0.47831,"qty":63.21205959}],"asks":[],"checksum":2498135405,"timestamp":"2024-06-01T18:07:20.401893Z"}]}
{"channel":"book","type":"update","data":[{"symbol":"XRP/EUR","bids":[],"asks":[{"price":0.47838,"qty":0.00000000},{"price":0.47865,"qty":1283.00000000}],"checksum":4162231171,"timestamp":"2024-06-01T18:07:20.406531Z"}]}
{"channel":"book","type":"update","data":[{"symbol":"XRP/EUR","bids":[],"asks":[{"price":0.47849,"qty":0.00000000},{"price":0.47869,"qty":3853.00000000}],"checksum":3007029717,"timestamp":"2024-06-01T18:07:20.502992Z"}]}
{"channel":"book","type":"update","data":[{"symbol":"XRP/EUR","bids":[{"price":0.47830,"qty":0.00000000},{"price":0.47816,"qty":8663.77728000}],"asks":[],"checksum":3209710254,"timestamp":"2024-06-01T18:07:21.090024Z"}]}
{"channel":"book","type":"update","data":[{"symbol":"XRP/EUR","bids":[{"price":0.47831,"qty":0.00000000},{"price":0.47815,"qty":52700.98236295},{"price":0.47826,"qty":63.21866846}],"asks":[],"checksum":3716121411,"timestamp":"2024-06-01T18:07:21.093432Z"}]}
{"channel":"book","type":"update","data":[{"symbol":"XRP/EUR","bids":[{"price":0.47829,"qty":9638.37246177}],"asks":[],"checksum":1301350352,"timestamp":"2024-06-01T18:07:21.094748Z"}]}
{"channel":"book","type":"update","data":[{"symbol":"XRP/EUR","bids":[],"asks":[{"price":0.47837,"qty":9636.76701557}],"checksum":3704010415,"timestamp":"2024-06-01T18:07:21.095000Z"}]}
{"channel":"book","type":"update","data":[{"symbol":"XRP/EUR","bids":[{"price":0.47826,"qty":0.00000000},{"price":0.47816,"qty":8663.77728000},{"price":0.47830,"qty":63.21338151}],"asks":[],"checksum":1817712833,"timestamp":"2024-06-01T18:07:21.097791Z"}]}
{"channel":"book","type":"update","data":[{"symbol":"XRP/EUR","bids":[{"price":0.47817,"qty":0.00000000},{"price":0.47816,"qty":8663.77728000}],"asks":[],"checksum":1997592195,"timestamp":"2024-06-01T18:07:21.098106Z"}]}
{"channel":"book","type":"update","data":[{"symbol":"XRP/EUR","bids":[{"price":0.47825,"qty":0.00000000},{"price":0.47815,"qty":52700.98236295}],"asks":[],"checksum":2513808529,"timestamp":"2024-06-01T18:07:21.445205Z"}]}
{"channel":"book","type":"update","data":[{"symbol":"XRP/EUR","bids":[],"asks":[{"price":0.47851,"qty":0.00000000},{"price":0.47869,"qty":3853.00000000}],"checksum":4124533023,"timestamp":"2024-06-01T18:07:21.445411Z"}]}
{"channel":"book","type":"update","data":[{"symbol":"XRP/EUR","bids":[{"price":0.47815,"qty":4493.03245185}],"asks":[],"checksum":3662534254,"timestamp":"2024-06-01T18:07:21.447926Z"}]}
{"channel":"book","type":"update","data":[{"symbol":"XRP/EUR","bids":[{"price":0.47819,"qty":6188.49729874}],"asks":[],"checksum":2216882085,"timestamp":"2024-06-01T18:07:21.448637Z"}]}
{"channel":"book","type":"update","data":[{"symbol":"XRP/EUR","bids":[{"price":0.47829,"qty":0.00000000},{"price":0.47814,"qty":1594.00653543}],"asks":[],"checksum":1272062587,"timestamp":"2024-06-01T18:07:21.448846Z"}]}
{"channel":"book","type":"update","data":[{"symbol":"XRP/EUR","bids":[],"asks":[{"price":0.47864,"qty":383.32244994}],"checksum":1939307219,"timestamp":"2024-06-01T18:07:21.449038Z"}]}
{"channel":"book","type":"update","data":[{"symbol":"XRP/EUR","bids":[],"asks":[{"price":0.47852,"qty":3011.74580865}],"checksum":404663400,"timestamp":"2024-06-01T18:07:21.450420Z"}]}
{"channel":"book","type":"update","data":[{"symbol":"XRP/EUR","bids":[{"price":0.47828,"qty":9638.54316896}],"asks":[],"checksum":913153968,"timestamp":"2024-06-01T18:07:21.456995Z"}]}
{"channel":"book","type":"update","data":[{"symbol":"XRP/EUR","bids":[{"price":0.47830,"qty":0.00000000},{"price":0.47814,"qty":1594.00653543},{"price":0.47829,"qty":63.22841382}],"asks":[],"checksum":2855346857,"timestamp":"2024-06-01T18:07:21.461074Z"}]}
{"channel":"book","type":"update","data":[{"symbol":"XRP/EUR","bids":[{"price":0.47828,"qty":0.00000000},{"price":0.47814,"qty":1594.00653543}],"asks":[],"checksum":2218922353,"timestamp":"2024-06-01T18:07:21.461435Z"}]}
{"channel":"book","type":"update","data":[{"symbol":"XRP/EUR","bids":[{"price":0.47819,"qty":4775.79899338}],"asks":[],"checksum":2223657830,"timestamp":"2024-06-01T18:07:21.465230Z"}]}
{"channel":"book","type":"update","data":[{"symbol":"XRP/EUR","bids":[{"price":0.47829,"qty":0.00000000},{"price":0.47813,"qty":9641.50727222},{"price":0.47825,"qty":63.23370214}],"asks":[],"checksum":758738627,"timestamp":"2024-06-01T18:07:21.468380Z"}]}
{"channel":"book","type":"update","data":[{"symbol":"XRP/EUR","bids":[{"price":0.47815,"qty":25453.22248455}],"asks":[],"checksum":2321413552,"timestamp":"2024-06-01T18:07:21.469617Z"}]}
{"channel":"book","type":"update","data":[{"symbol":"XRP/EUR","bids":[],"asks":[{"price":0.47861,"qty":76.18676156}],"checksum":255199779,"timestamp":"2024-06-01T18:07:21.482404Z"}]}
{"channel":"book","type":"update","data":[{"symbol":"XRP/EUR","bids":[],"asks":[{"price":0.47861,"qty":0.00000000},{"price":0.47865,"qty":1283.00000000}],"checksum":1044186596,"timestamp":"2024-06-01T18:07:21.529310Z"}]}
{"channel":"book","type":"update","data":[{"symbol":"XRP/EUR","bids":[],"asks":[{"price":0.47837,"qty":0.00000000},{"price":0.47869,"qty":3853.00000000}],"checksum":3886301196,"timestamp":"2024-06-01T18:07:21.548837Z"}]}
{"channel":"book","type":"update","data":[{"symbol":"XRP/EUR","bids":[],"asks":[{"price":0.47869,"qty":0.00000000},{"price":0.47872,"qty":9632.00000000},{"price":0.47861,"qty":3853.00000000}],"checksum":3250936593,"timestamp":"2024-06-01T18:07:21.552168Z"}]}
{"channel":"book","type":"update","data":[{"symbol":"XRP/EUR","bids":[{"price":0.47815,"qty":4493.03245185},{"price":0.47817,"qty":20960.19003270}],"asks":[],"checksum":1939246283,"timestamp":"2024-06-01T18:07:21.552478Z"}]}
{"channel":"book","type":"update","data":[{"symbol":"XRP/EUR","bids":[],"asks":[{"price":0.47838,"qty":9636.63545696}],"checksum":1591298049,"timestamp":"2024-06-01T18:07:21.553711Z"}]}
{"channel":"book","type":"update","data":[{"symbol":"XRP/EUR","bids":[{"price":0.47830,"qty":9638.02486984}],"asks":[],"checksum":1665843465,"timestamp":"2024-06-01T18:07:21.559147Z"}]}
{"channel":"book","type":"update","data":[{"symbol":"XRP/EUR","bids":[{"price":0.47825,"qty":0.00000000},{"price":0.47815,"qty":4493.03245185},{"price":0.47831,"qty":63.22575402}],"asks":[],"checksum":3037509403,"timestamp":"2024-06-01T18:07:21.562851Z"}]}
{"channel":"book","type":"update","data":[{"symbol":"XRP/EUR","bids":[{"price":0.47817,"qty":0.00000000},{"price":0.47815,"qty":4493.03245185}],"asks":[],"checksum":2270043265,"timestamp":"2024-06-01T18:07:21.586408Z"}]}
{"channel":"book","type":"update","data":[{"symbol":"XRP/EUR","bids":[{"price":0.47830,"qty":0.00000000},{"price":0.47814,"qty":1594.00653543}],"asks":[],"checksum":1035635111,"timestamp":"2024-06-01T18:07:21.703560Z"}]}
{"channel":"book","type":"update","data":[{"symbol":"XRP/EUR","bids":[{"price":0.47820,"qty":0.00000000},{"price":0.47813,"qty":9641.50727222}],"asks":[],"checksum":1949355229,"timestamp":"2024-06-01T18:07:21.703654Z"}]}
{"channel":"book","type":"update","data":[{"symbol":"XRP/EUR","bids":[],"asks":[{"price":0.47842,"qty":0.00000000},{"price":0.47865,"qty":1283.00000000}],"checksum":3663345917,"timestamp":"2024-06-01T18:07:21.703777Z"}]}
{"channel":"book","type":"update","data":[{"symbol":"XRP/EUR","bids":[{"price":0.47831,"qty":0.00000000},{"price":0.47812,"qty":1412.90513394},{"price":0.47825,"qty":63.23367700}],"asks":[],"checksum":2625100716,"timestamp":"2024-06-01T18:07:21.707088Z"}]}
{"channel":"book","type":"update","data":[{"symbol":"XRP/EUR","bids":[],"asks":[{"price":0.47837,"qty":9636.76701557}],"checksum":3997998551,"timestamp":"2024-06-01T18:07:21.709231Z"}]}
{"channel":"book","type":"update","data":[{"symbol":"XRP/EUR","bids":[{"price":0.47827,"qty":9638.70928355}],"asks":[],"checksum":2501258486,"timestamp":"2024-06-01T18:07:21.709712Z"}]}
{"channel":"book","type":"update","data":[{"symbol":"XRP/EUR","bids":[{"price":0.47825,"qty":0.00000000},{"price":0.47813,"qty":9641.50727222},{"price":0.47828,"qty":63.22971068}],"asks":[],"checksum":222874640,"timestamp":"2024-06-01T18:07:21.712925Z"}]}
{"channel":"book","type":"update","data":[{"symbol":"XRP/EUR","bids":[{"price":0.47814,"qty":22554.19656813}],"asks":[],"checksum":463550710,"timestamp":"2024-06-01T18:07:21.839689Z"}]}
{"channel":"book","type":"update","data":[{"symbol":"XRP/EUR","bids":[{"price":0.47827,"qty":0.00000000},{"price":0.47813,"qty":9641.50727222}],"asks":[],"checksum":640457300,"timestamp":"2024-06-01T18:07:22.101400Z"}]}
{"channel":"book","type":"update","data":[{"symbol":"XRP/EUR","bids":[{"price":0.47828,"qty":0.00000000},{"price":0.47812,"qty":1412.90513394},{"price":0.47825,"qty":63.23366741}],"asks":[],"checksum":2043631800,"timestamp":"2024-06-01T18:07:22.104727Z"}]}
{"channel":"book","type":"update","data":[{"symbol":"XRP/EUR","bids":[{"price":0.47828,"qty":9638.53972674}],"asks":[],"checksum":4055368417,"timestamp":"2024-06-01T18:07:22.105313Z"}]}
{"channel":"book","type":"update","data":[{"symbol":"XRP/EUR","bids":[{"price":0.47825,"qty":0.00000000},{"price":0.47813,"qty":9641.50727222},{"price":0.47829,"qty":63.22837909}],"asks":[],"checksum":3916646448,"timestamp":"2024-06-01T18:07:22.108651Z"}]}
{"channel":"book","type":"update","data":[{"symbol":"XRP/EUR","bids":[{"price":0.47821,"qty":0.00000000},{"price":0.47813,"qty":9641.50727222}],"asks":[],"checksum":3146474116,"timestamp":"2024-06-01T18:07:22.186751Z"}]}
{"channel":"book","type":"update","data":[{"symbol":"XRP/EUR","bids":[{"price":0.47820,"qty":129.44050901}],"asks":[],"checksum":2011010427,"timestamp":"2024-06-01T18:07:22.191210Z"}]}
{"channel":"book","type":"update","data":[{"symbol":"XRP/EUR","bids":[{"price":0.47828,"qty":0.00000000},{"price":0.47813,"qty":9641.50727222}],"asks":[],"checksum":4060797902,"timestamp":"2024-06-01T18:07:22.262529Z"}]}
{"channel":"book","type":"update","data":[{"symbol":"XRP/EUR","bids":[{"price":0.47829,"qty":0.00000000},{"price":0.47812,"qty":1412.90513394},{"price":0.47825,"qty":63.23366741}],"asks":[],"checksum":159784641,"timestamp":"2024-06-01T18:07:22.266192Z"}]}
{"channel":"book","type":"update","data":[{"symbol":"XRP/EUR","bids":[{"price":0.47829,"qty":9638.36692243}],"asks":[],"checksum":3107385795,"timestamp":"2024-06-01T18:07:22.266543Z"}]}
{"channel":"book","type":"update","data":[{"symbol":"XRP/EUR","bids":[{"price":0.47825,"qty":0.00000000},{"price":0.47813,"qty":9641.50727222},{"price":0.47830,"qty":63.22705459}],"asks":[],"checksum":2905234312,"timestamp":"2024-06-01T18:07:22.269493Z"}]}
{"channel":"book","type":"update","data":[{"symbol":"XRP/EUR","bids":[{"price":0.47829,"qty":0.00000000},{"price":0.47813,"qty":9641.50727222}],"asks":[],"checksum":2267165721,"timestamp":"2024-06-01T18:07:22.432593Z"}]}
{"channel":"book","type":"update","data":[{"symbol":"XRP/EUR","bids":[{"price":0.47830,"qty":0.00000000},{"price":0.47812,"qty":1412.90513394},{"price":0.47825,"qty":63.23366484}],"asks":[],"checksum":1963133746,"timestamp":"2024-06-01T18:07:22.435929Z"}]}
{"channel":"book","type":"update","data":[{"symbol":"XRP/EUR","bids":[{"price":0.47828,"qty":9638.57576453}],"asks":[],"checksum":3106934227,"timestamp":"2024-06-01T18:07:22.436567Z"}]}
{"channel":"book","type":"update","data":[{"symbol":"XRP/EUR","bids":[{"price":0.47825,"qty":0.00000000},{"price":0.47813,"qty":9641.50727222},{"price":0.47829,"qty":63.22837653}],"asks":[],"checksum":958694186,"timestamp":"2024-06-01T18:07:22.439522Z"}]}
{"channel":"book","type":"update","data":[{"symbol":"XRP/EUR","bids":[{"price":0.47828,"qty":0.00000000},{"price":0.47813,"qty":9641.50727222}],"asks":[],"checksum":3496845723,"timestamp":"2024-06-01T18:07:23.267326Z"}]}
{"channel":"book","type":"update","data":[{"symbol":"XRP/EUR","bids":[{"price":0.47829,"qty":9701.46317890}],"asks":[],"checksum":144883198,"timestamp":"2024-06-01T18:07:23.270818Z"}]}
{"channel":"book","type":"update","data":[{"symbol":"XRP/EUR","bids":[{"price":0.47829,"qty":9638.23480237},{"price":0.47825,"qty":63.22932876}],"asks":[],"checksum":2650697683,"timestamp":"2024-06-01T18:07:23.271885Z"}]}
{"channel":"book","type":"update","data":[{"symbol":"XRP/EUR","bids":[{"price":0.47825,"qty":0.00000000},{"price":0.47813,"qty":9641.50727222},{"price":0.47830,"qty":63.22271896}],"asks":[],"checksum":2049685784,"timestamp":"2024-06-01T18:07:23.275253Z"}]}
{"channel":"book","type":"update","data":[{"symbol":"XRP/EUR","bids":[{"price":0.47820,"qty":0.00000000},{"price":0.47813,"qty":9641.50727222}],"asks":[],"checksum":1866310730,"timestamp":"2024-06-01T18:07:24.646276Z"}]}
{"channel":"book","type":"update","data":[{"symbol":"XRP/EUR","bids":[{"price":0.47820,"qty":181.50887142}],"asks":[],"checksum":807109669,"timestamp":"2024-06-01T18:07:24.652095Z"}]}
{"channel":"book","type":"update","data":[{"symbol":"XRP/EUR","bids":[{"price":0.47819,"qty":5071.66365443}],"asks":[],"checksum":3021445384,"timestamp":"2024-06-01T18:07:24.652248Z"}]}
{"channel":"book","type":"update","data":[{"symbol":"XRP/EUR","bids":[{"price":0.47817,"qty":615.46387538}],"asks":[],"checksum":406700197,"timestamp":"2024-06-01T18:07:24.652259Z"}]}
{"channel":"book","type":"update","data":[{"symbol":"XRP/EUR","bids":[{"price":0.47829,"qty":0.00000000},{"price":0.47814,"qty":22554.19656813}],"asks":[],"checksum":3786420798,"timestamp":"2024-06-01T18:07:25.279158Z"}]}
{"channel":"book","type":"update","data":[{"symbol":"XRP/EUR","bids":[],"asks":[{"price":0.47838,"qty":0.00000000},{"price":0.47865,"qty":1283.00000000}],"checksum":1549028848,"timestamp":"2024-06-01T18:07:25.279290Z"}]}
{"channel":"book","type":"update","data":[{"symbol":"XRP/EUR","bids":[{"price":0.47830,"qty":0.00000000},{"price":0.47813,"qty":9641.50727222},{"price":0.47825,"qty":63.23713680}],"asks":[],"checksum":1275414514,"timestamp":"2024-06-01T18:07:25.282997Z"}]}
{"channel":"book","type":"update","data":[{"symbol":"XRP/EUR","bids":[],"asks":[{"price":0.47843,"qty":9635.68714199}],"checksum":36161131,"timestamp":"2024-06-01T18:07:25.284364Z"}]}
{"channel":"book","type":"update","data":[{"symbol":"XRP/EUR","bids":[{"price":0.47830,"qty":9638.15449468}],"asks":[],"checksum":2308807348,"timestamp":"2024-06-01T18:07:25.284416Z"}]}
{"channel":"book","type":"update","data":[{"symbol":"XRP/EUR","bids":[{"price":0.47825,"qty":0.00000000},{"price":0.47814,"qty":22554.19656813},{"price":0.47831,"qty":63.22920423}],"asks":[],"checksum":265704384,"timestamp":"2024-06-01T18:07:25.288397Z"}]}
{"channel":"book","type":"update","data":[{"symbol":"XRP/EUR","bids":[{"price":0.47820,"qty":0.00000000},{"price":0.47814,"qty":22554.19656813}],"asks":[],"checksum":3325041582,"timestamp":"2024-06-01T18:07:27.027776Z"}]}
{"channel":"book","type":"update","data":[{"symbol":"XRP/EUR","bids":[{"price":0.47820,"qty":199.83770721}],"asks":[],"checksum":733786403,"timestamp":"2024-06-01T18:07:27.034015Z"}]}
{"channel":"book","type":"update","data":[{"symbol":"XRP/EUR","bids":[{"price":0.47817,"qty":0.00000000},{"price":0.47814,"qty":22554.19656813}],"asks":[],"checksum":4274836718,"timestamp":"2024-06-01T18:07:29.366994Z"}]}
{"channel":"book","type":"update","data":[{"symbol":"XRP/EUR","bids":[{"price":0.47817,"qty":585.43265067}],"asks":[],"checksum":3404982976,"timestamp":"2024-06-01T18:07:29.371527Z"}]}
{"channel":"book","type":"update","data":[{"symbol":"XRP/EUR","bids":[{"price":0.47830,"qty":0.00000000},{"price":0.47814,"qty":22554.19656813}],"asks":[],"checksum":1114127466,"timestamp":"2024-06-01T18:07:29.465802Z"}]}
{"channel":"book","type":"update","data":[{"symbol":"XRP/EUR","bids":[{"price":0.47831,"qty":0.00000000},{"price":0.47813,"qty":9641.50727222},{"price":0.47825,"qty":63.22578064}],"asks":[],"checksum":355206455,"timestamp":"2024-06-01T18:07:29.469356Z"}]}
{"channel":"book","type":"update","data":[{"symbol":"XRP/EUR","bids":[{"price":0.47829,"qty":9638.31019874}],"asks":[],"checksum":3966136711,"timestamp":"2024-06-01T18:07:29.469488Z"}]}
{"channel":"book","type":"update","data":[{"symbol":"XRP/EUR","bids":[{"price":0.47825,"qty":0.00000000},{"price":0.47814,"qty":22554.19656813},{"price":0.47830,"qty":63.21917121}],"asks":[],"checksum":1238135072,"timestamp":"2024-06-01T18:07:29.473242Z"}]}
{"channel":"book","type":"update","data":[{"symbol":"XRP/EUR","bids":[{"price":0.47829,"qty":0.00000000},{"price":0.47814,"qty":22554.19656813}],"asks":[],"checksum":672611250,"timestamp":"2024-06-01T18:07:30.803073Z"}]}
{"channel":"book","type":"update","data":[{"symbol":"XRP/EUR","bids":[{"price":0.47830,"qty":0.00000000},{"price":0.47813,"qty":9641.50727222},{"price":0.47825,"qty":63.22578495}],"asks":[],"checksum":2952337430,"timestamp":"2024-06-01T18:07:30.806523Z"}]}
{"channel":"book","type":"update","data":[{"symbol":"XRP/EUR","bids":[{"price":0.47830,"qty":9638.08382948}],"asks":[],"checksum":3735041930,"timestamp":"2024-06-01T18:07:30.806709Z"}]}
{"channel":"book","type":"update","data":[{"symbol":"XRP/EUR","bids":[{"price":0.47825,"qty":0.00000000},{"price":0.47814,"qty":22554.19656813},{"price":0.47831,"qty":63.21785380}],"asks":[],"checksum":3452448317,"timestamp":"2024-06-01T18:07:30.809756Z"}]}
{"channel":"book","type":"update","data":[{"symbol":"XRP/EUR","bids":[],"asks":[{"price":0.47837,"qty":0.00000000},{"price":0.47865,"qty":1283.00000000}],"checksum":2201135970,"timestamp":"2024-06-01T18:07:30.812531Z"}]}
{"channel":"book","type":"update","data":[{"symbol":"XRP/EUR","bids":[{"price":0.47815,"qty":136.38430000}],"asks":[],"checksum":798299726,"timestamp":"2024-06-01T18:07:30.815589Z"}]}
{"channel":"book","type":"update","data":[{"symbol":"XRP/EUR","bids":[{"price":0.47817,"qty":21545.62268337}],"asks":[],"checksum":954116210,"timestamp":"2024-06-01T18:07:30.816008Z"}]}
{"channel":"book","type":"update","data":[{"symbol":"XRP/EUR","bids":[],"asks":[{"price":0.47838,"qty":9636.61395703}],"checksum":3492229992,"timestamp":"2024-06-01T18:07:30.816878Z"}]}
{"channel":"book","type":"update","data":[{"symbol":"XRP/EUR","bids":[],"asks":[{"price":0.47862,"qty":0.00000000},{"price":0.47865,"qty":1283.00000000}],"checksum":1129730671,"timestamp":"2024-06-01T18:07:30.817818Z"}]}
{"channel":"book","type":"update","data":[{"symbol":"XRP/EUR","bids":[{"price":0.47831,"qty":0.00000000},{"price":0.47814,"qty":1594.00653543},{"price":0.47837,"qty":63.20992465}],"asks":[],"checksum":3521182798,"timestamp":"2024-06-01T18:07:30.818681Z"}]}
{"channel":"book","type":"update","data":[{"symbol":"XRP/EUR","bids":[{"price":0.47815,"qty":2025.50702303}],"asks":[],"checksum":880700151,"timestamp":"2024-06-01T18:07:30.820228Z"}]}
{"channel":"book","type":"update","data":[{"symbol":"XRP/EUR","bids":[{"price":0.47837,"qty":0.00000000},{"price":0.47814,"qty":1594.00653543},{"price":0.47831,"qty":63.21785380}],"asks":[],"checksum":2022034439,"timestamp":"2024-06-01T18:07:30.821967Z"}]}
{"channel":"book","type":"update","data":[{"symbol":"XRP/EUR","bids":[],"asks":[{"price":0.47862,"qty":21474.67288077}],"checksum":3866241221,"timestamp":"2024-06-01T18:07:30.822843Z"}]}
{"channel":"book","type":"update","data":[{"symbol":"XRP/EUR","bids":[],"asks":[{"price":0.47849,"qty":922.18000000}],"checksum":889345760,"timestamp":"2024-06-01T18:07:30.937905Z"}]}
{"channel":"book","type":"update","data":[{"symbol":"XRP/EUR","bids":[{"price":0.47837,"qty":4000.00000000}],"asks":[],"checksum":1692357971,"timestamp":"2024-06-01T18:07:31.037152Z"}]}
{"channel":"book","type":"update","data":[{"symbol":"XRP/EUR","bids":[{"price":0.47817,"qty":585.43265067}],"asks":[],"checksum":1754775788,"timestamp":"2024-06-01T18:07:31.040616Z"}]}
{"channel":"book","type":"update","data":[{"symbol":"XRP/EUR","bids":[],"asks":[{"price":0.47849,"qty":0.00000000},{"price":0.47864,"qty":383.32244994}],"checksum":1579073609,"timestamp":"2024-06-01T18:07:31.180560Z"}]}
{"channel":"book","type":"update","data":[{"symbol":"XRP/EUR","bids":[{"price":0.47836,"qty":0.00000000},{"price":0.47815,"qty":2025.50702303}],"asks":[],"checksum":1817859713,"timestamp":"2024-06-01T18:07:31.219397Z"}]}
{"channel":"book","type":"update","data":[{"symbol":"XRP/EUR","bids":[{"price":0.47830,"qty":0.00000000},{"price":0.47814,"qty":22554.19656813}],"asks":[],"checksum":1616729403,"timestamp":"2024-06-01T18:07:31.314398Z"}]}
{"channel":"book","type":"update","data":[{"symbol":"XRP/EUR","bids":[{"price":0.47831,"qty":0.00000000},{"price":0.47813,"qty":9641.50727222},{"price":0.47825,"qty":63.22858160}],"asks":[],"checksum":3563780271,"timestamp":"2024-06-01T18:07:31.317762Z"}]}
{"channel":"book","type":"update","data":[{"symbol":"XRP/EUR","bids":[{"price":0.47831,"qty":9637.95251455}],"asks":[],"checksum":1640531807,"timestamp":"2024-06-01T18:07:31.317984Z"}]}
{"channel":"book","type":"update","data":[{"symbol":"XRP/EUR","bids":[{"price":0.47825,"qty":0.00000000},{"price":0.47814,"qty":22554.19656813},{"price":0.47832,"qty":63.21932838}],"asks":[],"checksum":1520238801,"timestamp":"2024-06-01T18:07:31.321280Z"}]}
{"channel":"book","type":"update","data":[{"symbol":"XRP/EUR","bids":[],"asks":[{"price":0.47838,"qty":0.00000000},{"price":0.47865,"qty":1283.00000000}],"checksum":466758038,"timestamp":"2024-06-01T18:07:31.561108Z"}]}
{"channel":"book","type":"update","data":[{"symbol":"XRP/EUR","bids":[],"asks":[{"price":0.47839,"qty":9636.38111560}],"checksum":1325288595,"timestamp":"2024-06-01T18:07:31.566703Z"}]}
{"channel":"book","type":"update","data":[{"symbol":"XRP/EUR","bids":[{"price":0.47831,"qty":0.00000000},{"price":0.47814,"qty":22554.19656813}],"asks":[],"checksum":2394770241,"timestamp":"2024-06-01T18:07:31.647570Z"}]}
{"channel":"book","type":"update","data":[{"symbol":"XRP/EUR","bids":[{"price":0.47832,"qty":0.00000000},{"price":0.47813,"qty":9641.50727222},{"price":0.47825,"qty":63.22858950}],"asks":[],"checksum":2595145514,"timestamp":"2024-06-01T18:07:31.651340Z"}]}
{"channel":"book","type":"update","data":[{"symbol":"XRP/EUR","bids":[{"price":0.47820,"qty":19479.86616852}],"asks":[],"checksum":2888187154,"timestamp":"2024-06-01T18:07:31.651718Z"}]}
{"channel":"book","type":"update","data":[{"symbol":"XRP/EUR","bids":[{"price":0.47832,"qty":9637.71831099}],"asks":[],"checksum":2033515584,"timestamp":"2024-06-01T18:07:31.651756Z"}]}
{"channel":"book","type":"update","data":[{"symbol":"XRP/EUR","bids":[{"price":0.47825,"qty":0.00000000},{"price":0.47814,"qty":22554.19656813},{"price":0.47833,"qty":63.21801461}],"asks":[],"checksum":543275428,"timestamp":"2024-06-01T18:07:31.656368Z"}]}
{"channel":"book","type":"update","data":[{"symbol":"XRP/EUR","bids":[{"price":0.47817,"qty":0.00000000},{"price":0.47814,"qty":22554.19656813}],"asks":[],"checksum":2509345035,"timestamp":"2024-06-01T18:07:31.714477Z"}]}
{"channel":"book","type":"update","data":[{"symbol":"XRP/EUR","bids":[{"price":0.47815,"qty":2789.81370308}],"asks":[],"checksum":1824779789,"timestamp":"2024-06-01T18:07:31.718447Z"}]}
{"channel":"book","type":"update","data":[{"symbol":"XRP/EUR","bids":[],"asks":[{"price":0.47861,"qty":0.00000000},{"price":0.47865,"qty":1283.00000000}],"checksum":17435233,"timestamp":"2024-06-01T18:07:31.799830Z"}]}
{"channel":"book","type":"update","data":[{"symbol":"XRP/EUR","bids":[{"price":0.47814,"qty":1594.00653543}],"asks":[],"checksum":2091787780,"timestamp":"2024-06-01T18:07:31.803103Z"}]}
{"channel":"book","type":"update","data":[{"symbol":"XRP/EUR","bids":[{"price":0.47817,"qty":20960.19003270}],"asks":[],"checksum":2123328242,"timestamp":"2024-06-01T18:07:31.910698Z"}]}
{"channel":"book","type":"update","data":[{"symbol":"XRP/EUR","bids":[{"price":0.47824,"qty":5849.57952000}],"asks":[],"checksum":3386457663,"timestamp":"2024-06-01T18:07:31.990459Z"}]}
{"channel":"book","type":"update","data":[{"symbol":"XRP/EUR","bids":[],"asks":[{"price":0.47839,"qty":0.00000000},{"price":0.47872,"qty":9632.00000000}],"checksum":618930769,"timestamp":"2024-06-01T18:07:31.990555Z"}]}
{"channel":"book","type":"update","data":[{"symbol":"XRP/EUR","bids":[{"price":0.47833,"qty":0.00000000},{"price":0.47814,"qty":1594.00653543},{"price":0.47838,"qty":63.21141071}],"asks":[],"checksum":2940528579,"timestamp":"2024-06-01T18:07:31.994418Z"}]}
{"channel":"book","type":"update","data":[{"symbol":"XRP/EUR","bids":[],"asks":[{"price":0.47841,"qty":9636.00801510}],"checksum":725274205,"timestamp":"2024-06-01T18:07:31.995720Z"}]}
{"channel":"book","type":"update","data":[{"symbol":"XRP/EUR","bids":[{"price":0.47833,"qty":9637.43666881}],"asks":[],"checksum":3442279975,"timestamp":"2024-06-01T18:07:31.995772Z"}]}
{"channel":"book","type":"update","data":[{"symbol":"XRP/EUR","bids":[{"price":0.47838,"qty":0.00000000},{"price":0.47815,"qty":2789.81370308},{"price":0.47833,"qty":9700.65468703}],"asks":[],"checksum":3540750797,"timestamp":"2024-06-01T18:07:31.999436Z"}]}
{"channel":"book","type":"update","data":[{"symbol":"XRP/EUR","bids":[{"price":0.47833,"qty":9637.43666881},{"price":0.47834,"qty":63.21669661}],"asks":[],"checksum":2011303673,"timestamp":"2024-06-01T18:07:32.002728Z"}]}
{"channel":"book","type":"update","data":[{"symbol":"XRP/EUR","bids":[{"price":0.47833,"qty":0.00000000},{"price":0.47815,"qty":2789.81370308}],"asks":[],"checksum":2448803459,"timestamp":"2024-06-01T18:07:32.018938Z"}]}
{"channel":"book","type":"update","data":[{"symbol":"XRP/EUR","bids":[],"asks":[{"price":0.47841,"qty":0.00000000},{"price":0.47872,"qty":9632.00000000}],"checksum":361492253,"timestamp":"2024-06-01T18:07:32.018951Z"}]}
{"channel":"book","type":"update","data":[{"symbol":"XRP/EUR","bids":[{"price":0.47826,"qty":9638.83693703}],"asks":[],"checksum":3760994790,"timestamp":"2024-06-01T18:07:32.023886Z"}]}
{"channel":"book","type":"update","data":[{"symbol":"XRP/EUR","bids":[{"price":0.47834,"qty":0.00000000},{"price":0.47815,"qty":2789.81370308},{"price":0.47833,"qty":63.21801822}],"asks":[],"checksum":2017514229,"timestamp":"2024-06-01T18:07:32.073498Z"}]}
{"channel":"book","type":"update","data":[{"symbol":"XRP/EUR","bids":[{"price":0.47818,"qty":14172.53879875}],"asks":[],"checksum":3060403738,"timestamp":"2024-06-01T18:07:32.125820Z"}]}
{"channel":"book","type":"update","data":[{"symbol":"XRP/EUR","bids":[{"price":0.47817,"qty":0.00000000},{"price":0.47815,"qty":2789.81370308},{"price":0.47819,"qty":26031.85368713}],"asks":[],"checksum":846639845,"timestamp":"2024-06-01T18:07:32.128909Z"}]}
{"channel":"book","type":"update","data":[{"symbol":"XRP/EUR","bids":[],"asks":[{"price":0.47840,"qty":9636.29696146}],"checksum":740807687,"timestamp":"2024-06-01T18:07:32.131421Z"}]}
{"channel":"book","type":"update","data":[{"symbol":"XRP/EUR","bids":[],"asks":[{"price":0.47840,"qty":0.00000000},{"price":0.47872,"qty":9632.00000000}],"checksum":846639845,"timestamp":"2024-06-01T18:07:32.149919Z"}]}
{"channel":"book","type":"update","data":[{"symbol":"XRP/EUR","bids":[{"price":0.47832,"qty":0.00000000},{"price":0.47814,"qty":1594.00653543}],"asks":[],"checksum":666202534,"timestamp":"2024-06-01T18:07:32.149929Z"}]}
