{"channel":"book","type":"snapshot","data":[{"symbol":"XRP/USD","bids":[{"price":0.51857,"qty":2512.50000000},{"price":0.51856,"qty":1400.00000000},{"price":0.51855,"qty":3256.25000000},{"price":0.51853,"qty":4821.23146771},{"price":0.51850,"qty":4561.18878872},{"price":0.51849,"qty":2051.59300000},{"price":0.51846,"qty":2000.00000000},{"price":0.51843,"qty":279.96510488},{"price":0.51842,"qty":5050.00000000},{"price":0.51841,"qty":12646.74580865}],"asks":[{"price":0.51869,"qty":4819.83458327},{"price":0.51871,"qty":680.00000000},{"price":0.51877,"qty":1256.25000000},{"price":0.51879,"qty":1400.00000000},{"price":0.51880,"qty":276.60170459},{"price":0.51881,"qty":36.23516623},{"price":0.51882,"qty":36.23516623},{"price":0.51883,"qty":1292.48516623},{"price":0.51884,"qty":14723.23743391},{"price":0.51888,"qty":9635.00000000}],"checksum":3309635357}]}
{"channel":"book","type":"update","data":[{"symbol":"XRP/USD","bids":[{"price":0.51846,"qty":3673.77765634}],"asks":[],"checksum":87727357,"timestamp":"2024-06-01T18:07:05.169733Z"}]}
{"channel":"book","type":"update","data":[{"symbol":"XRP/USD","bids":[],"asks":[{"price":0.51877,"qty":0.00000000},{"price":0.51889,"qty":23884.88327097}],"checksum":3545103687,"timestamp":"2024-06-01T18:07:05.632626Z"}]}
{"channel":"book","type":"update","data":[{"symbol":"XRP/USD","bids":[],"asks":[{"price":0.51871,"qty":0.00000000},{"price":0.51890,"qty":8901.27241272}],"checksum":2496025047,"timestamp":"2024-06-01T18:07:05.638879Z"}]}
{"channel":"book","type":"update","data":[{"symbol":"XRP/USD","bids":[],"asks":[{"price":0.51875,"qty":1256.25000000}],"checksum":452298221,"timestamp":"2024-06-01T18:07:05.640673Z"}]}
{"channel":"book","type":"update","data":[{"symbol":"XRP/USD","bids":[{"price":0.51856,"qty":0.00000000},{"price":0.51840,"qty":9134.11855241}],"asks":[],"checksum":4288793215,"timestamp":"2024-06-01T18:07:05.662387Z"}]}
{"channel":"book","type":"update","data":[{"symbol":"XRP/USD","bids":[{"price":0.51858,"qty":1400.00000000}],"asks":[],"checksum":3553989968,"timestamp":"2024-06-01T18:07:05.662533Z"}]}
{"channel":"book","type":"update","data":[{"symbol":"XRP/USD","bids":[{"price":0.51860,"qty":1256.25000000}],"asks":[],"checksum":1235896304,"timestamp":"2024-06-01T18:07:05.666430Z"}]}
{"channel":"book","type":"update","data":[{"symbol":"XRP/USD","bids":[{"price":0.51855,"qty":2000.00000000}],"asks":[],"checksum":2329871,"timestamp":"2024-06-01T18:07:05.666912Z"}]}
{"channel":"book","type":"update","data":[{"symbol":"XRP/USD","bids":[],"asks":[{"price":0.51873,"qty":680.00000000}],"checksum":601486749,"timestamp":"2024-06-01T18:07:05.783210Z"}]}
{"channel":"book","type":"update","data":[{"symbol":"XRP/USD","bids":[{"price":0.51860,"qty":0.00000000},{"price":0.51841,"qty":12646.74580865}],"asks":[],"checksum":3026367900,"timestamp":"2024-06-01T18:07:06.008667Z"}]}
{"channel":"book","type":"update","data":[{"symbol":"XRP/USD","bids":[{"price":0.51860,"qty":1256.25000000}],"asks":[],"checksum":601486749,"timestamp":"2024-06-01T18:07:06.011547Z"}]}
{"channel":"book","type":"update","data":[{"symbol":"XRP/USD","bids":[],"asks":[{"price":0.51873,"qty":0.00000000},{"price":0.51889,"qty":23884.88327097}],"checksum":2329871,"timestamp":"2024-06-01T18:07:06.556401Z"}]}
{"channel":"book","type":"update","data":[{"symbol":"XRP/USD","bids":[],"asks":[{"price":0.51875,"qty":0.00000000},{"price":0.51890,"qty":8901.27241272}],"checksum":2367180434,"timestamp":"2024-06-01T18:07:06.557784Z"}]}
{"channel":"book","type":"update","data":[{"symbol":"XRP/USD","bids":[],"asks":[{"price":0.51882,"qty":0.00000000},{"price":0.51892,"qty":4656.25000000}],"checksum":662354583,"timestamp":"2024-06-01T18:07:06.561085Z"}]}
{"channel":"book","type":"update","data":[{"symbol":"XRP/USD","bids":[],"asks":[{"price":0.51881,"qty":0.00000000},{"price":0.51893,"qty":13963.46584921}],"checksum":1745340964,"timestamp":"2024-06-01T18:07:06.561293Z"}]}
{"channel":"book","type":"update","data":[{"symbol":"XRP/USD","bids":[],"asks":[{"price":0.51884,"qty":14687.00226768}],"checksum":3032714166,"timestamp":"2024-06-01T18:07:06.561616Z"}]}
{"channel":"book","type":"update","data":[{"symbol":"XRP/USD","bids":[],"asks":[{"price":0.51883,"qty":1256.25000000}],"checksum":1804868334,"timestamp":"2024-06-01T18:07:06.561924Z"}]}
{"channel":"book","type":"update","data":[{"symbol":"XRP/USD","bids":[],"asks":[{"price":0.51893,"qty":10951.72004056}],"checksum":3043383709,"timestamp":"2024-06-01T18:07:06.564148Z"}]}
{"channel":"book","type":"update","data":[{"symbol":"XRP/USD","bids":[],"asks":[{"price":0.51889,"qty":1592.73711874}],"checksum":3095046103,"timestamp":"2024-06-01T18:07:06.567179Z"}]}
{"channel":"book","type":"update","data":[{"symbol":"XRP/USD","bids":[{"price":0.51842,"qty":5086.23516623}],"asks":[],"checksum":2854740056,"timestamp":"2024-06-01T18:07:06.569377Z"}]}
{"channel":"book","type":"update","data":[{"symbol":"XRP/USD","bids":[],"asks":[{"price":0.51888,"qty":0.00000000},{"price":0.51894,"qty":488.81421089}],"checksum":2881459993,"timestamp":"2024-06-01T18:07:06.570446Z"}]}
{"channel":"book","type":"update","data":[{"symbol":"XRP/USD","bids":[{"price":0.51843,"qty":15894.47725448}],"asks":[],"checksum":3437790129,"timestamp":"2024-06-01T18:07:06.570476Z"}]}
{"channel":"book","type":"update","data":[{"symbol":"XRP/USD","bids":[],"asks":[{"price":0.51869,"qty":0.00000000},{"price":0.51895,"qty":52.83973936}],"checksum":674651345,"timestamp":"2024-06-01T18:07:06.570627Z"}]}
{"channel":"book","type":"update","data":[{"symbol":"XRP/USD","bids":[],"asks":[{"price":0.51893,"qty":1316.72004056}],"checksum":2523155952,"timestamp":"2024-06-01T18:07:06.576526Z"}]}
{"channel":"book","type":"update","data":[{"symbol":"XRP/USD","bids":[{"price":0.51842,"qty":14721.23516623}],"asks":[],"checksum":671159141,"timestamp":"2024-06-01T18:07:06.578339Z"}]}
{"channel":"book","type":"update","data":[{"symbol":"XRP/USD","bids":[],"asks":[{"price":0.51875,"qty":4819.33405497}],"checksum":1816078627,"timestamp":"2024-06-01T18:07:06.583624Z"}]}
{"channel":"book","type":"update","data":[{"symbol":"XRP/USD","bids":[{"price":0.51850,"qty":14196.18878872}],"asks":[],"checksum":687862335,"timestamp":"2024-06-01T18:07:06.589900Z"}]}
{"channel":"book","type":"update","data":[{"symbol":"XRP/USD","bids":[{"price":0.51849,"qty":1371.59300000},{"price":0.51853,"qty":5501.23146771}],"asks":[],"checksum":1762875261,"timestamp":"2024-06-01T18:07:06.622608Z"}]}
{"channel":"book","type":"update","data":[{"symbol":"XRP/USD","bids":[{"price":0.51853,"qty":6181.23146771}],"asks":[],"checksum":1946923370,"timestamp":"2024-06-01T18:07:06.627071Z"}]}
{"channel":"book","type":"update","data":[{"symbol":"XRP/USD","bids":[{"price":0.51849,"qty":4383.33880865}],"asks":[],"checksum":2410844757,"timestamp":"2024-06-01T18:07:06.630299Z"}]}
{"channel":"book","type":"update","data":[{"symbol":"XRP/USD","bids":[{"price":0.51858,"qty":0.00000000},{"price":0.51841,"qty":3011.74580865}],"asks":[],"checksum":4258474328,"timestamp":"2024-06-01T18:07:06.679017Z"}]}
{"channel":"book","type":"update","data":[{"symbol":"XRP/USD","bids":[{"price":0.51861,"qty":1400.00000000}],"asks":[],"checksum":2296926369,"timestamp":"2024-06-01T18:07:06.679530Z"}]}
{"channel":"book","type":"update","data":[{"symbol":"XRP/USD","bids":[{"price":0.51857,"qty":1256.25000000}],"asks":[],"checksum":4078253252,"timestamp":"2024-06-01T18:07:06.683865Z"}]}
{"channel":"book","type":"update","data":[{"symbol":"XRP/USD","bids":[],"asks":[{"price":0.51893,"qty":1352.95520679}],"checksum":3719805549,"timestamp":"2024-06-01T18:07:06.684093Z"}]}
{"channel":"book","type":"update","data":[{"symbol":"XRP/USD","bids":[{"price":0.51864,"qty":1256.25000000}],"asks":[],"checksum":3963033779,"timestamp":"2024-06-01T18:07:06.684131Z"}]}
{"channel":"book","type":"update","data":[{"symbol":"XRP/USD","bids":[],"asks":[{"price":0.51892,"qty":4692.48516623}],"checksum":3762949946,"timestamp":"2024-06-01T18:07:06.684768Z"}]}
{"channel":"book","type":"update","data":[{"symbol":"XRP/USD","bids":[{"price":0.51863,"qty":1256.25000000}],"asks":[],"checksum":146815051,"timestamp":"2024-06-01T18:07:06.684790Z"}]}
{"channel":"book","type":"update","data":[{"symbol":"XRP/USD","bids":[{"price":0.51864,"qty":2512.50000000}],"asks":[],"checksum":2497898745,"timestamp":"2024-06-01T18:07:06.687961Z"}]}
{"channel":"book","type":"update","data":[{"symbol":"XRP/USD","bids":[{"price":0.51860,"qty":0.00000000},{"price":0.51843,"qty":15894.47725448}],"asks":[],"checksum":1248104812,"timestamp":"2024-06-01T18:07:06.688551Z"}]}
{"channel":"book","type":"update","data":[{"symbol":"XRP/USD","bids":[{"price":0.51863,"qty":0.00000000},{"price":0.51842,"qty":14721.23516623}],"asks":[],"checksum":805804682,"timestamp":"2024-06-01T18:07:06.689087Z"}]}
{"channel":"book","type":"update","data":[{"symbol":"XRP/USD","bids":[{"price":0.51861,"qty":0.00000000},{"price":0.51840,"qty":8617.61855241}],"asks":[],"checksum":1952157463,"timestamp":"2024-06-01T18:07:06.691650Z"}]}
{"channel":"book","type":"update","data":[{"symbol":"XRP/USD","bids":[{"price":0.51858,"qty":1400.00000000}],"asks":[],"checksum":3831176997,"timestamp":"2024-06-01T18:07:06.692467Z"}]}
{"channel":"book","type":"update","data":[{"symbol":"XRP/USD","bids":[],"asks":[{"price":0.51891,"qty":36.23516623}],"checksum":855122520,"timestamp":"2024-06-01T18:07:06.704454Z"}]}
{"channel":"book","type":"update","data":[{"symbol":"XRP/USD","bids":[],"asks":[{"price":0.51876,"qty":680.00000000}],"checksum":1730062326,"timestamp":"2024-06-01T18:07:06.719269Z"}]}
{"channel":"book","type":"update","data":[{"symbol":"XRP/USD","bids":[{"price":0.51855,"qty":2481.92759749}],"asks":[],"checksum":3144099228,"timestamp":"2024-06-01T18:07:06.723616Z"}]}
{"channel":"book","type":"update","data":[{"symbol":"XRP/USD","bids":[],"asks":[{"price":0.51876,"qty":0.00000000},{"price":0.51893,"qty":1352.95520679}],"checksum":4001472562,"timestamp":"2024-06-01T18:07:06.795004Z"}]}
{"channel":"book","type":"update","data":[{"symbol":"XRP/USD","bids":[],"asks":[{"price":0.51876,"qty":680.00000000}],"checksum":3144099228,"timestamp":"2024-06-01T18:07:06.934765Z"}]}
{"channel":"book","type":"update","data":[{"symbol":"XRP/USD","bids":[],"asks":[{"price":0.51874,"qty":16387.50375356}],"checksum":571579945,"timestamp":"2024-06-01T18:07:06.949829Z"}]}
{"channel":"book","type":"update","data":[{"symbol":"XRP/USD","bids":[{"price":0.51864,"qty":4512.50000000}],"asks":[],"checksum":2873122360,"timestamp":"2024-06-01T18:07:07.100825Z"}]}
{"channel":"book","type":"update","data":[{"symbol":"XRP/USD","bids":[{"price":0.51855,"qty":481.92759749}],"asks":[],"checksum":1047794045,"timestamp":"2024-06-01T18:07:07.104785Z"}]}
{"channel":"book","type":"update","data":[{"symbol":"XRP/USD","bids":[{"price":0.51866,"qty":1256.25000000}],"asks":[],"checksum":4022228341,"timestamp":"2024-06-01T18:07:07.104819Z"}]}
{"channel":"book","type":"update","data":[{"symbol":"XRP/USD","bids":[{"price":0.51853,"qty":5501.23146771}],"asks":[],"checksum":3794254814,"timestamp":"2024-06-01T18:07:07.143455Z"}]}
{"channel":"book","type":"update","data":[{"symbol":"XRP/USD","bids":[],"asks":[{"price":0.51875,"qty":0.00000000},{"price":0.51892,"qty":4692.48516623}],"checksum":3378808574,"timestamp":"2024-06-01T18:07:07.185842Z"}]}
{"channel":"book","type":"update","data":[{"symbol":"XRP/USD","bids":[],"asks":[{"price":0.51873,"qty":4819.46291905}],"checksum":1074172645,"timestamp":"2024-06-01T18:07:07.190949Z"}]}
{"channel":"book","type":"update","data":[{"symbol":"XRP/USD","bids":[{"price":0.51864,"qty":2512.50000000}],"asks":[],"checksum":603284065,"timestamp":"2024-06-01T18:07:07.275424Z"}]}
{"channel":"book","type":"update","data":[{"symbol":"XRP/USD","bids":[{"price":0.51864,"qty":4512.50000000}],"asks":[],"checksum":1074172645,"timestamp":"2024-06-01T18:07:07.443455Z"}]}
{"channel":"book","type":"update","data":[{"symbol":"XRP/USD","bids":[{"price":0.51846,"qty":51881.72756744}],"asks":[],"checksum":3918974731,"timestamp":"2024-06-01T18:07:07.455610Z"}]}
{"channel":"book","type":"update","data":[{"symbol":"XRP/USD","bids":[{"price":0.51844,"qty":7388.06225600}],"asks":[],"checksum":3773347149,"timestamp":"2024-06-01T18:07:07.459088Z"}]}
{"channel":"book","type":"update","data":[{"symbol":"XRP/USD","bids":[],"asks":[{"price":0.51874,"qty":0.00000000},{"price":0.51892,"qty":4692.48516623}],"checksum":1739606454,"timestamp":"2024-06-01T18:07:07.489318Z"}]}
{"channel":"book","type":"update","data":[{"symbol":"XRP/USD","bids":[],"asks":[{"price":0.51872,"qty":16387.39805158}],"checksum":3067965715,"timestamp":"2024-06-01T18:07:07.529753Z"}]}
{"channel":"book","type":"update","data":[{"symbol":"XRP/USD","bids":[{"price":0.51855,"qty":0.00000000},{"price":0.51843,"qty":15894.47725448}],"asks":[],"checksum":1189124188,"timestamp":"2024-06-01T18:07:07.865090Z"}]}
{"channel":"book","type":"update","data":[{"symbol":"XRP/USD","bids":[{"price":0.51866,"qty":0.00000000},{"price":0.51842,"qty":14721.23516623}],"asks":[],"checksum":3714021759,"timestamp":"2024-06-01T18:07:07.934311Z"}]}
{"channel":"book","type":"update","data":[{"symbol":"XRP/USD","bids":[{"price":0.51844,"qty":0.00000000},{"price":0.51840,"qty":8653.85371864}],"asks":[],"checksum":1788961773,"timestamp":"2024-06-01T18:07:07.937518Z"}]}
{"channel":"book","type":"update","data":[{"symbol":"XRP/USD","bids":[{"price":0.51866,"qty":1256.25000000}],"asks":[],"checksum":46347453,"timestamp":"2024-06-01T18:07:07.939007Z"}]}
{"channel":"book","type":"update","data":[{"symbol":"XRP/USD","bids":[{"price":0.51866,"qty":0.00000000},{"price":0.51840,"qty":8653.85371864}],"asks":[],"checksum":1788961773,"timestamp":"2024-06-01T18:07:08.061817Z"}]}
{"channel":"book","type":"update","data":[{"symbol":"XRP/USD","bids":[{"price":0.51866,"qty":1256.25000000}],"asks":[],"checksum":46347453,"timestamp":"2024-06-01T18:07:08.065831Z"}]}
{"channel":"book","type":"update","data":[{"symbol":"XRP/USD","bids":[{"price":0.51866,"qty":0.00000000},{"price":0.51840,"qty":8653.85371864}],"asks":[],"checksum":1788961773,"timestamp":"2024-06-01T18:07:08.077055Z"}]}
{"channel":"book","type":"update","data":[{"symbol":"XRP/USD","bids":[{"price":0.51866,"qty":1256.25000000}],"asks":[],"checksum":46347453,"timestamp":"2024-06-01T18:07:08.081292Z"}]}
{"channel":"book","type":"update","data":[{"symbol":"XRP/USD","bids":[{"price":0.51866,"qty":0.00000000},{"price":0.51840,"qty":8653.85371864}],"asks":[],"checksum":1788961773,"timestamp":"2024-06-01T18:07:08.089514Z"}]}
{"channel":"book","type":"update","data":[{"symbol":"XRP/USD","bids":[{"price":0.51866,"qty":1256.25000000}],"asks":[],"checksum":46347453,"timestamp":"2024-06-01T18:07:08.094201Z"}]}
{"channel":"book","type":"update","data":[{"symbol":"XRP/USD","bids":[{"price":0.51864,"qty":2512.50000000}],"asks":[],"checksum":3573007769,"timestamp":"2024-06-01T18:07:08.103884Z"}]}
{"channel":"book","type":"update","data":[{"symbol":"XRP/USD","bids":[{"price":0.51865,"qty":2000.00000000}],"asks":[],"checksum":202064308,"timestamp":"2024-06-01T18:07:08.182617Z"}]}
{"channel":"book","type":"update","data":[{"symbol":"XRP/USD","bids":[{"price":0.51843,"qty":15614.51214960}],"asks":[],"checksum":2033510919,"timestamp":"2024-06-01T18:07:08.369195Z"}]}
{"channel":"book","type":"update","data":[{"symbol":"XRP/USD","bids":[{"price":0.51851,"qty":38.56374841}],"asks":[],"checksum":1989945034,"timestamp":"2024-06-01T18:07:08.381011Z"}]}
{"channel":"book","type":"update","data":[{"symbol":"XRP/USD","bids":[{"price":0.51847,"qty":140.55052167}],"asks":[],"checksum":1535615876,"timestamp":"2024-06-01T18:07:08.381158Z"}]}
{"channel":"book","type":"update","data":[{"symbol":"XRP/USD","bids":[],"asks":[{"price":0.51872,"qty":0.00000000},{"price":0.51892,"qty":4692.48516623}],"checksum":2145444637,"timestamp":"2024-06-01T18:07:08.603833Z"}]}
{"channel":"book","type":"update","data":[{"symbol":"XRP/USD","bids":[{"price":0.51854,"qty":481.92895136}],"asks":[],"checksum":1223101364,"timestamp":"2024-06-01T18:07:08.607978Z"}]}
{"channel":"book","type":"update","data":[{"symbol":"XRP/USD","bids":[],"asks":[{"price":0.51871,"qty":16387.37227874}],"checksum":1652681939,"timestamp":"2024-06-01T18:07:08.643715Z"}]}
{"channel":"book","type":"update","data":[{"symbol":"XRP/USD","bids":[{"price":0.51854,"qty":0.00000000},{"price":0.51847,"qty":140.55052167}],"asks":[],"checksum":1434846330,"timestamp":"2024-06-01T18:07:08.647626Z"}]}
{"channel":"book","type":"update","data":[{"symbol":"XRP/USD","bids":[{"price":0.51866,"qty":0.00000000},{"price":0.51846,"qty":51881.72756744}],"asks":[],"checksum":3886940685,"timestamp":"2024-06-01T18:07:09.489814Z"}]}
{"channel":"book","type":"update","data":[{"symbol":"XRP/USD","bids":[{"price":0.51865,"qty":3256.25000000}],"asks":[],"checksum":2971325172,"timestamp":"2024-06-01T18:07:09.493772Z"}]}
{"channel":"book","type":"update","data":[{"symbol":"XRP/USD","bids":[{"price":0.51866,"qty":1256.25000000}],"asks":[],"checksum":2666615874,"timestamp":"2024-06-01T18:07:09.494197Z"}]}
{"channel":"book","type":"update","data":[{"symbol":"XRP/USD","bids":[{"price":0.51864,"qty":1256.25000000}],"asks":[],"checksum":2364215601,"timestamp":"2024-06-01T18:07:09.494691Z"}]}
{"channel":"book","type":"update","data":[{"symbol":"XRP/USD","bids":[{"price":0.51866,"qty":0.00000000},{"price":0.51846,"qty":51881.72756744}],"asks":[],"checksum":3312236746,"timestamp":"2024-06-01T18:07:09.620856Z"}]}
{"channel":"book","type":"update","data":[{"symbol":"XRP/USD","bids":[{"price":0.51864,"qty":0.00000000},{"price":0.51843,"qty":15614.51214960}],"asks":[],"checksum":937739181,"timestamp":"2024-06-01T18:07:09.624782Z"}]}
{"channel":"book","type":"update","data":[{"symbol":"XRP/USD","bids":[{"price":0.51865,"qty":4512.50000000}],"asks":[],"checksum":1481679001,"timestamp":"2024-06-01T18:07:09.628328Z"}]}
{"channel":"book","type":"update","data":[{"symbol":"XRP/USD","bids":[{"price":0.51866,"qty":1256.25000000}],"asks":[],"checksum":1347592139,"timestamp":"2024-06-01T18:07:09.716453Z"}]}
{"channel":"book","type":"update","data":[{"symbol":"XRP/USD","bids":[{"price":0.51865,"qty":3256.25000000}],"asks":[],"checksum":3335161455,"timestamp":"2024-06-01T18:07:09.720651Z"}]}
{"channel":"book","type":"update","data":[{"symbol":"XRP/USD","bids":[],"asks":[{"price":0.51876,"qty":0.00000000},{"price":0.51892,"qty":4692.48516623}],"checksum":1074192904,"timestamp":"2024-06-01T18:07:09.773838Z"}]}
{"channel":"book","type":"update","data":[{"symbol":"XRP/USD","bids":[{"price":0.51866,"qty":2512.50000000}],"asks":[],"checksum":575124658,"timestamp":"2024-06-01T18:07:09.830325Z"}]}
{"channel":"book","type":"update","data":[{"symbol":"XRP/USD","bids":[],"asks":[{"price":0.51876,"qty":680.00000000}],"checksum":2760626389,"timestamp":"2024-06-01T18:07:09.936861Z"}]}
{"channel":"book","type":"update","data":[{"symbol":"XRP/USD","bids":[{"price":0.51866,"qty":1256.25000000}],"asks":[],"checksum":3335161455,"timestamp":"2024-06-01T18:07:10.286688Z"}]}
{"channel":"book","type":"update","data":[{"symbol":"XRP/USD","bids":[{"price":0.51866,"qty":0.00000000},{"price":0.51843,"qty":15614.51214960}],"asks":[],"checksum":937739181,"timestamp":"2024-06-01T18:07:10.288621Z"}]}
{"channel":"book","type":"update","data":[{"symbol":"XRP/USD","bids":[{"price":0.51866,"qty":1256.25000000}],"asks":[],"checksum":3335161455,"timestamp":"2024-06-01T18:07:10.292757Z"}]}
{"channel":"book","type":"update","data":[{"symbol":"XRP/USD","bids":[{"price":0.51865,"qty":4512.50000000}],"asks":[],"checksum":1347592139,"timestamp":"2024-06-01T18:07:10.294459Z"}]}
{"channel":"book","type":"update","data":[{"symbol":"XRP/USD","bids":[{"price":0.51866,"qty":0.00000000},{"price":0.51843,"qty":15614.51214960}],"asks":[],"checksum":1481679001,"timestamp":"2024-06-01T18:07:10.331434Z"}]}
{"channel":"book","type":"update","data":[{"symbol":"XRP/USD","bids":[{"price":0.51865,"qty":3256.25000000}],"asks":[],"checksum":937739181,"timestamp":"2024-06-01T18:07:10.334752Z"}]}
{"channel":"book","type":"update","data":[{"symbol":"XRP/USD","bids":[{"price":0.51866,"qty":1256.25000000}],"asks":[],"checksum":3335161455,"timestamp":"2024-06-01T18:07:10.335295Z"}]}
{"channel":"book","type":"update","data":[{"symbol":"XRP/USD","bids":[{"price":0.51865,"qty":4512.50000000}],"asks":[],"checksum":1347592139,"timestamp":"2024-06-01T18:07:10.337390Z"}]}
{"channel":"book","type":"update","data":[{"symbol":"XRP/USD","bids":[{"price":0.51866,"qty":0.00000000},{"price":0.51843,"qty":15614.51214960}],"asks":[],"checksum":1481679001,"timestamp":"2024-06-01T18:07:10.351751Z"}]}
{"channel":"book","type":"update","data":[{"symbol":"XRP/USD","bids":[{"price":0.51865,"qty":3256.25000000}],"asks":[],"checksum":937739181,"timestamp":"2024-06-01T18:07:10.355614Z"}]}
{"channel":"book","type":"update","data":[{"symbol":"XRP/USD","bids":[{"price":0.51865,"qty":4512.50000000}],"asks":[],"checksum":1481679001,"timestamp":"2024-06-01T18:07:10.358498Z"}]}
{"channel":"book","type":"update","data":[{"symbol":"XRP/USD","bids":[{"price":0.51866,"qty":1256.25000000}],"asks":[],"checksum":1347592139,"timestamp":"2024-06-01T18:07:10.359626Z"}]}
{"channel":"book","type":"update","data":[{"symbol":"XRP/USD","bids":[{"price":0.51865,"qty":3256.25000000}],"asks":[],"checksum":3335161455,"timestamp":"2024-06-01T18:07:10.363413Z"}]}
{"channel":"book","type":"update","data":[{"symbol":"XRP/USD","bids":[{"price":0.51866,"qty":0.00000000},{"price":0.51843,"qty":15614.51214960}],"asks":[],"checksum":937739181,"timestamp":"2024-06-01T18:07:10.404713Z"}]}
{"channel":"book","type":"update","data":[{"symbol":"XRP/USD","bids":[{"price":0.51866,"qty":1256.25000000}],"asks":[],"checksum":3335161455,"timestamp":"2024-06-01T18:07:10.413015Z"}]}
{"channel":"book","type":"update","data":[{"symbol":"XRP/USD","bids":[{"price":0.51865,"qty":4512.50000000}],"asks":[],"checksum":1347592139,"timestamp":"2024-06-01T18:07:10.413543Z"}]}
{"channel":"book","type":"update","data":[{"symbol":"XRP/USD","bids":[{"price":0.51866,"qty":0.00000000},{"price":0.51843,"qty":15614.51214960}],"asks":[],"checksum":1481679001,"timestamp":"2024-06-01T18:07:10.417018Z"}]}
{"channel":"book","type":"update","data":[{"symbol":"XRP/USD","bids":[{"price":0.51865,"qty":3256.25000000}],"asks":[],"checksum":937739181,"timestamp":"2024-06-01T18:07:10.417299Z"}]}
{"channel":"book","type":"update","data":[{"symbol":"XRP/USD","bids":[{"price":0.51866,"qty":1256.25000000}],"asks":[],"checksum":3335161455,"timestamp":"2024-06-01T18:07:10.421497Z"}]}
{"channel":"book","type":"update","data":[{"symbol":"XRP/USD","bids":[{"price":0.51866,"qty":2512.50000000}],"asks":[],"checksum":2760626389,"timestamp":"2024-06-01T18:07:10.597801Z"}]}
{"channel":"book","type":"update","data":[{"symbol":"XRP/USD","bids":[{"price":0.51866,"qty":1256.25000000}],"asks":[],"checksum":3335161455,"timestamp":"2024-06-01T18:07:10.739653Z"}]}
{"channel":"book","type":"update","data":[{"symbol":"XRP/USD","bids":[{"price":0.51866,"qty":0.00000000},{"price":0.51843,"qty":15614.51214960}],"asks":[],"checksum":937739181,"timestamp":"2024-06-01T18:07:10.840392Z"}]}
{"channel":"book","type":"update","data":[{"symbol":"XRP/USD","bids":[{"price":0.51866,"qty":1256.25000000}],"asks":[],"checksum":3335161455,"timestamp":"2024-06-01T18:07:10.844066Z"}]}
{"channel":"book","type":"update","data":[{"symbol":"XRP/USD","bids":[{"price":0.51866,"qty":2512.50000000}],"asks":[],"checksum":2760626389,"timestamp":"2024-06-01T18:07:10.898727Z"}]}
{"channel":"book","type":"update","data":[{"symbol":"XRP/USD","bids":[{"price":0.51851,"qty":0.00000000},{"price":0.51843,"qty":15614.51214960}],"asks":[],"checksum":3766817074,"timestamp":"2024-06-01T18:07:11.116958Z"}]}
{"channel":"book","type":"update","data":[{"symbol":"XRP/USD","bids":[{"price":0.51843,"qty":0.00000000},{"price":0.51842,"qty":14721.23516623},{"price":0.51842,"qty":30335.74731583}],"asks":[],"checksum":3841115464,"timestamp":"2024-06-01T18:07:11.121596Z"}]}
{"channel":"book","type":"update","data":[{"symbol":"XRP/USD","bids":[{"price":0.51851,"qty":57.01962490}],"asks":[],"checksum":1045245141,"timestamp":"2024-06-01T18:07:11.121802Z"}]}
{"channel":"book","type":"update","data":[{"symbol":"XRP/USD","bids":[{"price":0.51866,"qty":1256.25000000}],"asks":[],"checksum":1544321647,"timestamp":"2024-06-01T18:07:11.194872Z"}]}
{"channel":"book","type":"update","data":[{"symbol":"XRP/USD","bids":[{"price":0.51866,"qty":0.00000000},{"price":0.51842,"qty":30335.74731583}],"asks":[],"checksum":877337109,"timestamp":"2024-06-01T18:07:11.195178Z"}]}
{"channel":"book","type":"update","data":[{"symbol":"XRP/USD","bids":[{"price":0.51853,"qty":4821.23146771}],"asks":[],"checksum":2580439382,"timestamp":"2024-06-01T18:07:11.195998Z"}]}
{"channel":"book","type":"update","data":[{"symbol":"XRP/USD","bids":[],"asks":[{"price":0.51877,"qty":1256.25000000}],"checksum":706758670,"timestamp":"2024-06-01T18:07:11.196282Z"}]}
{"channel":"book","type":"update","data":[{"symbol":"XRP/USD","bids":[{"price":0.51865,"qty":2000.00000000}],"asks":[],"checksum":3994531430,"timestamp":"2024-06-01T18:07:11.197497Z"}]}
{"channel":"book","type":"update","data":[{"symbol":"XRP/USD","bids":[{"price":0.51852,"qty":481.96536437}],"asks":[],"checksum":4277659702,"timestamp":"2024-06-01T18:07:11.201184Z"}]}
{"channel":"book","type":"update","data":[{"symbol":"XRP/USD","bids":[{"price":0.51846,"qty":50207.94991110}],"asks":[],"checksum":2379225741,"timestamp":"2024-06-01T18:07:11.222243Z"}]}
{"channel":"book","type":"update","data":[{"symbol":"XRP/USD","bids":[{"price":0.51850,"qty":4561.18878872}],"asks":[],"checksum":1038482647,"timestamp":"2024-06-01T18:07:11.235903Z"}]}
{"channel":"book","type":"update","data":[{"symbol":"XRP/USD","bids":[],"asks":[{"price":0.51876,"qty":0.00000000},{"price":0.51891,"qty":36.23516623},{"price":0.51872,"qty":680.00000000}],"checksum":524434595,"timestamp":"2024-06-01T18:07:11.236603Z"}]}
{"channel":"book","type":"update","data":[{"symbol":"XRP/USD","bids":[],"asks":[{"price":0.51872,"qty":1360.00000000}],"checksum":643064550,"timestamp":"2024-06-01T18:07:11.237364Z"}]}
{"channel":"book","type":"update","data":[{"symbol":"XRP/USD","bids":[],"asks":[{"price":0.51873,"qty":0.00000000},{"price":0.51891,"qty":36.23516623}],"checksum":570042743,"timestamp":"2024-06-01T18:07:11.238024Z"}]}
{"channel":"book","type":"update","data":[{"symbol":"XRP/USD","bids":[],"asks":[{"price":0.51870,"qty":4819.74166184}],"checksum":3928676589,"timestamp":"2024-06-01T18:07:11.243573Z"}]}
{"channel":"book","type":"update","data":[{"symbol":"XRP/USD","bids":[],"asks":[{"price":0.51872,"qty":680.00000000}],"checksum":681320963,"timestamp":"2024-06-01T18:07:11.270328Z"}]}
{"channel":"book","type":"update","data":[{"symbol":"XRP/USD","bids":[],"asks":[{"price":0.51870,"qty":6075.99166184}],"checksum":3517700763,"timestamp":"2024-06-01T18:07:11.337856Z"}]}
{"channel":"book","type":"update","data":[{"symbol":"XRP/USD","bids":[],"asks":[{"price":0.51870,"qty":4819.74166184}],"checksum":681320963,"timestamp":"2024-06-01T18:07:11.341928Z"}]}
{"channel":"book","type":"update","data":[{"symbol":"XRP/USD","bids":[{"price":0.51849,"qty":5063.33880865}],"asks":[],"checksum":509514520,"timestamp":"2024-06-01T18:07:11.342858Z"}]}
{"channel":"book","type":"update","data":[{"symbol":"XRP/USD","bids":[{"price":0.51858,"qty":0.00000000},{"price":0.51842,"qty":30335.74731583}],"asks":[],"checksum":3335009371,"timestamp":"2024-06-01T18:07:11.347606Z"}]}
{"channel":"book","type":"update","data":[{"symbol":"XRP/USD","bids":[],"asks":[{"price":0.51870,"qty":6075.99166184}],"checksum":954538197,"timestamp":"2024-06-01T18:07:11.351682Z"}]}
{"channel":"book","type":"update","data":[{"symbol":"XRP/USD","bids":[],"asks":[{"price":0.51870,"qty":4819.74166184}],"checksum":3335009371,"timestamp":"2024-06-01T18:07:11.355710Z"}]}
{"channel":"book","type":"update","data":[{"symbol":"XRP/USD","bids":[{"price":0.51847,"qty":1814.29589499}],"asks":[],"checksum":1077061565,"timestamp":"2024-06-01T18:07:11.379430Z"}]}
{"channel":"book","type":"update","data":[{"symbol":"XRP/USD","bids":[{"price":0.51847,"qty":140.55052167}],"asks":[],"checksum":3335009371,"timestamp":"2024-06-01T18:07:11.469134Z"}]}
{"channel":"book","type":"update","data":[{"symbol":"XRP/USD","bids":[{"price":0.51845,"qty":1673.80994060}],"asks":[],"checksum":1602118734,"timestamp":"2024-06-01T18:07:11.587630Z"}]}
{"channel":"book","type":"update","data":[{"symbol":"XRP/USD","bids":[{"price":0.51850,"qty":14196.18878872}],"asks":[],"checksum":1419200915,"timestamp":"2024-06-01T18:07:12.103465Z"}]}
{"channel":"book","type":"update","data":[{"symbol":"XRP/USD","bids":[{"price":0.51865,"qty":3256.25000000}],"asks":[],"checksum":1401131942,"timestamp":"2024-06-01T18:07:12.111986Z"}]}
{"channel":"book","type":"update","data":[{"symbol":"XRP/USD","bids":[{"price":0.51865,"qty":2000.00000000}],"asks":[],"checksum":1419200915,"timestamp":"2024-06-01T18:07:12.142111Z"}]}
{"channel":"book","type":"update","data":[{"symbol":"XRP/USD","bids":[{"price":0.51865,"qty":3256.25000000}],"asks":[],"checksum":1401131942,"timestamp":"2024-06-01T18:07:12.167433Z"}]}
{"channel":"book","type":"update","data":[{"symbol":"XRP/USD","bids":[{"price":0.51849,"qty":4383.33880865},{"price":0.51853,"qty":5501.23146771}],"asks":[],"checksum":2834737228,"timestamp":"2024-06-01T18:07:12.270752Z"}]}
{"channel":"book","type":"update","data":[{"symbol":"XRP/USD","bids":[{"price":0.51853,"qty":6181.23146771}],"asks":[],"checksum":4141773704,"timestamp":"2024-06-01T18:07:12.275169Z"}]}
{"channel":"book","type":"update","data":[{"symbol":"XRP/USD","bids":[{"price":0.51865,"qty":2000.00000000}],"asks":[],"checksum":4056590781,"timestamp":"2024-06-01T18:07:12.346385Z"}]}
{"channel":"book","type":"update","data":[{"symbol":"XRP/USD","bids":[{"price":0.51865,"qty":3256.25000000}],"asks":[],"checksum":4141773704,"timestamp":"2024-06-01T18:07:12.442223Z"}]}
{"channel":"book","type":"update","data":[{"symbol":"XRP/USD","bids":[{"price":0.51865,"qty":4512.50000000}],"asks":[],"checksum":959295502,"timestamp":"2024-06-01T18:07:12.466765Z"}]}
{"channel":"book","type":"update","data":[{"symbol":"XRP/USD","bids":[],"asks":[{"price":0.51877,"qty":0.00000000},{"price":0.51891,"qty":36.23516623}],"checksum":1079598232,"timestamp":"2024-06-01T18:07:12.468072Z"}]}
{"channel":"book","type":"update","data":[{"symbol":"XRP/USD","bids":[{"price":0.51865,"qty":3256.25000000}],"asks":[],"checksum":2410323742,"timestamp":"2024-06-01T18:07:12.505509Z"}]}
{"channel":"book","type":"update","data":[{"symbol":"XRP/USD","bids":[{"price":0.51865,"qty":2000.00000000}],"asks":[],"checksum":2294170923,"timestamp":"2024-06-01T18:07:12.668000Z"}]}
{"channel":"book","type":"update","data":[{"symbol":"XRP/USD","bids":[],"asks":[{"price":0.51876,"qty":1256.25000000}],"checksum":1854422311,"timestamp":"2024-06-01T18:07:12.671656Z"}]}
{"channel":"book","type":"update","data":[{"symbol":"XRP/USD","bids":[],"asks":[{"price":0.51876,"qty":0.00000000},{"price":0.51891,"qty":36.23516623}],"checksum":2294170923,"timestamp":"2024-06-01T18:07:12.882589Z"}]}
{"channel":"book","type":"update","data":[{"symbol":"XRP/USD","bids":[{"price":0.51865,"qty":3256.25000000}],"asks":[],"checksum":2410323742,"timestamp":"2024-06-01T18:07:12.882763Z"}]}
{"channel":"book","type":"update","data":[{"symbol":"XRP/USD","bids":[{"price":0.51865,"qty":2000.00000000}],"asks":[],"checksum":2294170923,"timestamp":"2024-06-01T18:07:12.993131Z"}]}
{"channel":"book","type":"update","data":[{"symbol":"XRP/USD","bids":[{"price":0.51865,"qty":3256.25000000}],"asks":[],"checksum":2410323742,"timestamp":"2024-06-01T18:07:13.138080Z"}]}
{"channel":"book","type":"update","data":[{"symbol":"XRP/USD","bids":[{"price":0.51865,"qty":4512.50000000}],"asks":[],"checksum":1079598232,"timestamp":"2024-06-01T18:07:13.296466Z"}]}
{"channel":"book","type":"update","data":[{"symbol":"XRP/USD","bids":[{"price":0.51866,"qty":1256.25000000}],"asks":[],"checksum":531173631,"timestamp":"2024-06-01T18:07:13.297974Z"}]}
{"channel":"book","type":"update","data":[{"symbol":"XRP/USD","bids":[{"price":0.51866,"qty":0.00000000},{"price":0.51845,"qty":1673.80994060}],"asks":[],"checksum":1079598232,"timestamp":"2024-06-01T18:07:13.301053Z"}]}
{"channel":"book","type":"update","data":[{"symbol":"XRP/USD","bids":[{"price":0.51865,"qty":3256.25000000}],"asks":[],"checksum":2410323742,"timestamp":"2024-06-01T18:07:13.301726Z"}]}
{"channel":"book","type":"update","data":[{"symbol":"XRP/USD","bids":[{"price":0.51865,"qty":4512.50000000}],"asks":[],"checksum":1079598232,"timestamp":"2024-06-01T18:07:13.314002Z"}]}
{"channel":"book","type":"update","data":[{"symbol":"XRP/USD","bids":[{"price":0.51865,"qty":3256.25000000}],"asks":[],"checksum":2410323742,"timestamp":"2024-06-01T18:07:13.464747Z"}]}
{"channel":"book","type":"update","data":[{"symbol":"XRP/USD","bids":[],"asks":[{"price":0.51871,"qty":0.00000000},{"price":0.51892,"qty":4692.48516623}],"checksum":2641483237,"timestamp":"2024-06-01T18:07:13.693311Z"}]}
{"channel":"book","type":"update","data":[{"symbol":"XRP/USD","bids":[{"price":0.51865,"qty":2000.00000000}],"asks":[],"checksum":2590314448,"timestamp":"2024-06-01T18:07:13.796096Z"}]}
{"channel":"book","type":"update","data":[{"symbol":"XRP/USD","bids":[{"price":0.51858,"qty":1400.00000000}],"asks":[],"checksum":4066223255,"timestamp":"2024-06-01T18:07:13.798962Z"}]}
{"channel":"book","type":"update","data":[{"symbol":"XRP/USD","bids":[{"price":0.51853,"qty":6663.16686321}],"asks":[],"checksum":2050080048,"timestamp":"2024-06-01T18:07:13.799788Z"}]}
{"channel":"book","type":"update","data":[{"symbol":"XRP/USD","bids":[{"price":0.51865,"qty":3256.25000000}],"asks":[],"checksum":2099603205,"timestamp":"2024-06-01T18:07:13.847730Z"}]}
{"channel":"book","type":"update","data":[{"symbol":"XRP/USD","bids":[{"price":0.51865,"qty":2000.00000000}],"asks":[],"checksum":2050080048,"timestamp":"2024-06-01T18:07:13.862278Z"}]}
{"channel":"book","type":"update","data":[{"symbol":"XRP/USD","bids":[{"price":0.51865,"qty":3256.25000000}],"asks":[],"checksum":2099603205,"timestamp":"2024-06-01T18:07:13.870229Z"}]}
{"channel":"book","type":"update","data":[{"symbol":"XRP/USD","bids":[{"price":0.51865,"qty":4512.50000000}],"asks":[],"checksum":3000411267,"timestamp":"2024-06-01T18:07:13.870808Z"}]}
{"channel":"book","type":"update","data":[{"symbol":"XRP/USD","bids":[{"price":0.51866,"qty":1256.25000000}],"asks":[],"checksum":1858036476,"timestamp":"2024-06-01T18:07:13.881963Z"}]}
{"channel":"book","type":"update","data":[{"symbol":"XRP/USD","bids":[{"price":0.51865,"qty":3256.25000000}],"asks":[],"checksum":3153706930,"timestamp":"2024-06-01T18:07:13.887652Z"}]}
{"channel":"book","type":"update","data":[{"symbol":"XRP/USD","bids":[{"price":0.51866,"qty":0.00000000},{"price":0.51846,"qty":50207.94991110}],"asks":[],"checksum":2099603205,"timestamp":"2024-06-01T18:07:13.895676Z"}]}
{"channel":"book","type":"update","data":[{"symbol":"XRP/USD","bids":[{"price":0.51866,"qty":1256.25000000}],"asks":[],"checksum":3153706930,"timestamp":"2024-06-01T18:07:13.900321Z"}]}
{"channel":"book","type":"update","data":[{"symbol":"XRP/USD","bids":[{"price":0.51866,"qty":0.00000000},{"price":0.51846,"qty":50207.94991110}],"asks":[],"checksum":2099603205,"timestamp":"2024-06-01T18:07:13.905640Z"}]}
{"channel":"book","type":"update","data":[{"symbol":"XRP/USD","bids":[{"price":0.51865,"qty":4512.50000000}],"asks":[],"checksum":3000411267,"timestamp":"2024-06-01T18:07:13.914469Z"}]}
{"channel":"book","type":"update","data":[{"symbol":"XRP/USD","bids":[{"price":0.51865,"qty":3256.25000000}],"asks":[],"checksum":2099603205,"timestamp":"2024-06-01T18:07:13.934844Z"}]}
{"channel":"book","type":"update","data":[{"symbol":"XRP/USD","bids":[{"price":0.51865,"qty":4512.50000000}],"asks":[],"checksum":3000411267,"timestamp":"2024-06-01T18:07:13.937804Z"}]}
{"channel":"book","type":"update","data":[{"symbol":"XRP/USD","bids":[{"price":0.51866,"qty":1256.25000000}],"asks":[],"checksum":1858036476,"timestamp":"2024-06-01T18:07:13.937846Z"}]}
{"channel":"book","type":"update","data":[{"symbol":"XRP/USD","bids":[{"price":0.51865,"qty":3256.25000000}],"asks":[],"checksum":3153706930,"timestamp":"2024-06-01T18:07:13.942040Z"}]}
{"channel":"book","type":"update","data":[{"symbol":"XRP/USD","bids":[{"price":0.51866,"qty":0.00000000},{"price":0.51846,"qty":50207.94991110}],"asks":[],"checksum":2099603205,"timestamp":"2024-06-01T18:07:13.942238Z"}]}
{"channel":"book","type":"update","data":[{"symbol":"XRP/USD","bids":[{"price":0.51866,"qty":1256.25000000}],"asks":[],"checksum":3153706930,"timestamp":"2024-06-01T18:07:13.946625Z"}]}
{"channel":"book","type":"update","data":[{"symbol":"XRP/USD","bids":[{"price":0.51865,"qty":4512.50000000}],"asks":[],"checksum":1858036476,"timestamp":"2024-06-01T18:07:13.948159Z"}]}
{"channel":"book","type":"update","data":[{"symbol":"XRP/USD","bids":[{"price":0.51866,"qty":0.00000000},{"price":0.51846,"qty":50207.94991110}],"asks":[],"checksum":3000411267,"timestamp":"2024-06-01T18:07:13.960818Z"}]}
{"channel":"book","type":"update","data":[{"symbol":"XRP/USD","bids":[{"price":0.51865,"qty":3256.25000000}],"asks":[],"checksum":2099603205,"timestamp":"2024-06-01T18:07:13.964386Z"}]}
{"channel":"book","type":"update","data":[{"symbol":"XRP/USD","bids":[{"price":0.51866,"qty":1256.25000000}],"asks":[],"checksum":3153706930,"timestamp":"2024-06-01T18:07:13.964485Z"}]}
{"channel":"book","type":"update","data":[{"symbol":"XRP/USD","bids":[{"price":0.51865,"qty":4512.50000000}],"asks":[],"checksum":1858036476,"timestamp":"2024-06-01T18:07:13.967791Z"}]}
{"channel":"book","type":"update","data":[{"symbol":"XRP/USD","bids":[{"price":0.51866,"qty":0.00000000},{"price":0.51846,"qty":50207.94991110}],"asks":[],"checksum":3000411267,"timestamp":"2024-06-01T18:07:13.976644Z"}]}
{"channel":"book","type":"update","data":[{"symbol":"XRP/USD","bids":[{"price":0.51865,"qty":3256.25000000}],"asks":[],"checksum":2099603205,"timestamp":"2024-06-01T18:07:13.978704Z"}]}
{"channel":"book","type":"update","data":[{"symbol":"XRP/USD","bids":[{"price":0.51866,"qty":1256.25000000}],"asks":[],"checksum":3153706930,"timestamp":"2024-06-01T18:07:13.991249Z"}]}
{"channel":"book","type":"update","data":[{"symbol":"XRP/USD","bids":[{"price":0.51865,"qty":4512.50000000}],"asks":[],"checksum":1858036476,"timestamp":"2024-06-01T18:07:13.991340Z"}]}
{"channel":"book","type":"update","data":[{"symbol":"XRP/USD","bids":[{"price":0.51865,"qty":3256.25000000}],"asks":[],"checksum":3153706930,"timestamp":"2024-06-01T18:07:13.995450Z"}]}
{"channel":"book","type":"update","data":[{"symbol":"XRP/USD","bids":[{"price":0.51866,"qty":0.00000000},{"price":0.51846,"qty":50207.94991110}],"asks":[],"checksum":2099603205,"timestamp":"2024-06-01T18:07:13.995735Z"}]}
{"channel":"book","type":"update","data":[{"symbol":"XRP/USD","bids":[{"price":0.51866,"qty":1256.25000000}],"asks":[],"checksum":3153706930,"timestamp":"2024-06-01T18:07:14.002928Z"}]}
{"channel":"book","type":"update","data":[{"symbol":"XRP/USD","bids":[{"price":0.51866,"qty":0.00000000},{"price":0.51846,"qty":50207.94991110}],"asks":[],"checksum":2099603205,"timestamp":"2024-06-01T18:07:14.043700Z"}]}
{"channel":"book","type":"update","data":[{"symbol":"XRP/USD","bids":[{"price":0.51865,"qty":4512.50000000}],"asks":[],"checksum":3000411267,"timestamp":"2024-06-01T18:07:14.051698Z"}]}
{"channel":"book","type":"update","data":[{"symbol":"XRP/USD","bids":[{"price":0.51865,"qty":3256.25000000}],"asks":[],"checksum":2099603205,"timestamp":"2024-06-01T18:07:14.136755Z"}]}
{"channel":"book","type":"update","data":[{"symbol":"XRP/USD","bids":[{"price":0.51865,"qty":2000.00000000}],"asks":[],"checksum":2050080048,"timestamp":"2024-06-01T18:07:14.137127Z"}]}
{"channel":"book","type":"update","data":[{"symbol":"XRP/USD","bids":[],"asks":[{"price":0.51876,"qty":1256.25000000}],"checksum":2336373256,"timestamp":"2024-06-01T18:07:14.138531Z"}]}
{"channel":"book","type":"update","data":[{"symbol":"XRP/USD","bids":[{"price":0.51853,"qty":5983.16686321}],"asks":[],"checksum":1579424222,"timestamp":"2024-06-01T18:07:14.153662Z"}]}
{"channel":"book","type":"update","data":[{"symbol":"XRP/USD","bids":[{"price":0.51853,"qty":5303.16686321}],"asks":[],"checksum":2104377250,"timestamp":"2024-06-01T18:07:14.157392Z"}]}
{"channel":"book","type":"update","data":[{"symbol":"XRP/USD","bids":[{"price":0.51865,"qty":3256.25000000}],"asks":[],"checksum":2054874519,"timestamp":"2024-06-01T18:07:14.170390Z"}]}
{"channel":"book","type":"update","data":[{"symbol":"XRP/USD","bids":[],"asks":[{"price":0.51876,"qty":0.00000000},{"price":0.51892,"qty":4692.48516623}],"checksum":2332648111,"timestamp":"2024-06-01T18:07:14.170912Z"}]}
{"channel":"book","type":"update","data":[{"symbol":"XRP/USD","bids":[{"price":0.51865,"qty":2000.00000000}],"asks":[],"checksum":2350758042,"timestamp":"2024-06-01T18:07:14.174675Z"}]}
{"channel":"book","type":"update","data":[{"symbol":"XRP/USD","bids":[],"asks":[{"price":0.51876,"qty":1256.25000000}],"checksum":2104377250,"timestamp":"2024-06-01T18:07:14.185050Z"}]}
{"channel":"book","type":"update","data":[{"symbol":"XRP/USD","bids":[],"asks":[{"price":0.51876,"qty":0.00000000},{"price":0.51892,"qty":4692.48516623}],"checksum":2350758042,"timestamp":"2024-06-01T18:07:14.211912Z"}]}
{"channel":"book","type":"update","data":[{"symbol":"XRP/USD","bids":[{"price":0.51865,"qty":3256.25000000}],"asks":[],"checksum":2332648111,"timestamp":"2024-06-01T18:07:14.214790Z"}]}
{"channel":"book","type":"update","data":[{"symbol":"XRP/USD","bids":[{"price":0.51865,"qty":2000.00000000}],"asks":[],"checksum":2350758042,"timestamp":"2024-06-01T18:07:14.234186Z"}]}
{"channel":"book","type":"update","data":[{"symbol":"XRP/USD","bids":[],"asks":[{"price":0.51876,"qty":1256.25000000}],"checksum":2104377250,"timestamp":"2024-06-01T18:07:14.236943Z"}]}
{"channel":"book","type":"update","data":[{"symbol":"XRP/USD","bids":[{"price":0.51865,"qty":3256.25000000}],"asks":[],"checksum":2054874519,"timestamp":"2024-06-01T18:07:14.238275Z"}]}
{"channel":"book","type":"update","data":[{"symbol":"XRP/USD","bids":[],"asks":[{"price":0.51876,"qty":0.00000000},{"price":0.51892,"qty":4692.48516623}],"checksum":2332648111,"timestamp":"2024-06-01T18:07:14.240920Z"}]}
{"channel":"book","type":"update","data":[{"symbol":"XRP/USD","bids":[{"price":0.51865,"qty":2000.00000000}],"asks":[],"checksum":2350758042,"timestamp":"2024-06-01T18:07:14.245178Z"}]}
{"channel":"book","type":"update","data":[{"symbol":"XRP/USD","bids":[],"asks":[{"price":0.51876,"qty":1256.25000000}],"checksum":2104377250,"timestamp":"2024-06-01T18:07:14.246371Z"}]}
{"channel":"book","type":"update","data":[{"symbol":"XRP/USD","bids":[{"price":0.51865,"qty":3256.25000000}],"asks":[],"checksum":2054874519,"timestamp":"2024-06-01T18:07:14.248591Z"}]}
{"channel":"book","type":"update","data":[{"symbol":"XRP/USD","bids":[],"asks":[{"price":0.51876,"qty":0.00000000},{"price":0.51892,"qty":4692.48516623}],"checksum":2332648111,"timestamp":"2024-06-01T18:07:14.249071Z"}]}
{"channel":"book","type":"update","data":[{"symbol":"XRP/USD","bids":[{"price":0.51865,"qty":2000.00000000}],"asks":[],"checksum":2350758042,"timestamp":"2024-06-01T18:07:14.258863Z"}]}
{"channel":"book","type":"update","data":[{"symbol":"XRP/USD","bids":[],"asks":[{"price":0.51876,"qty":1256.25000000}],"checksum":2104377250,"timestamp":"2024-06-01T18:07:14.340072Z"}]}
{"channel":"book","type":"update","data":[{"symbol":"XRP/USD","bids":[{"price":0.51865,"qty":3256.25000000}],"asks":[],"checksum":2054874519,"timestamp":"2024-06-01T18:07:14.438079Z"}]}
{"channel":"book","type":"update","data":[{"symbol":"XRP/USD","bids":[],"asks":[{"price":0.51876,"qty":0.00000000},{"price":0.51892,"qty":4692.48516623}],"checksum":2332648111,"timestamp":"2024-06-01T18:07:14.438126Z"}]}
{"channel":"book","type":"update","data":[{"symbol":"XRP/USD","bids":[{"price":0.51865,"qty":2000.00000000}],"asks":[],"checksum":2350758042,"timestamp":"2024-06-01T18:07:14.443722Z"}]}
{"channel":"book","type":"update","data":[{"symbol":"XRP/USD","bids":[],"asks":[{"price":0.51876,"qty":1256.25000000}],"checksum":2104377250,"timestamp":"2024-06-01T18:07:14.447722Z"}]}
{"channel":"book","type":"update","data":[{"symbol":"XRP/USD","bids":[],"asks":[{"price":0.51876,"qty":0.00000000},{"price":0.51892,"qty":4692.48516623}],"checksum":2350758042,"timestamp":"2024-06-01T18:07:14.478357Z"}]}
{"channel":"book","type":"update","data":[{"symbol":"XRP/USD","bids":[{"price":0.51865,"qty":3256.25000000}],"asks":[],"checksum":2332648111,"timestamp":"2024-06-01T18:07:14.478399Z"}]}
{"channel":"book","type":"update","data":[{"symbol":"XRP/USD","bids":[{"price":0.51865,"qty":4512.50000000}],"asks":[],"checksum":1157275945,"timestamp":"2024-06-01T18:07:14.481251Z"}]}
{"channel":"book","type":"update","data":[{"symbol":"XRP/USD","bids":[{"price":0.51865,"qty":3256.25000000}],"asks":[],"checksum":2332648111,"timestamp":"2024-06-01T18:07:14.490272Z"}]}
{"channel":"book","type":"update","data":[{"symbol":"XRP/USD","bids":[{"price":0.51852,"qty":1161.96536437}],"asks":[],"checksum":464885477,"timestamp":"2024-06-01T18:07:14.518183Z"}]}
{"channel":"book","type":"update","data":[{"symbol":"XRP/USD","bids":[{"price":0.51852,"qty":481.96536437}],"asks":[],"checksum":2332648111,"timestamp":"2024-06-01T18:07:14.668356Z"}]}
{"channel":"book","type":"update","data":[{"symbol":"XRP/USD","bids":[{"price":0.51865,"qty":4512.50000000}],"asks":[],"checksum":1157275945,"timestamp":"2024-06-01T18:07:14.674852Z"}]}
{"channel":"book","type":"update","data":[{"symbol":"XRP/USD","bids":[{"price":0.51865,"qty":3256.25000000}],"asks":[],"checksum":2332648111,"timestamp":"2024-06-01T18:07:14.680041Z"}]}
{"channel":"book","type":"update","data":[{"symbol":"XRP/USD","bids":[{"price":0.51865,"qty":4512.50000000}],"asks":[],"checksum":1157275945,"timestamp":"2024-06-01T18:07:14.683978Z"}]}
{"channel":"book","type":"update","data":[{"symbol":"XRP/USD","bids":[{"price":0.51865,"qty":3256.25000000}],"asks":[],"checksum":2332648111,"timestamp":"2024-06-01T18:07:14.711152Z"}]}
{"channel":"book","type":"update","data":[{"symbol":"XRP/USD","bids":[{"price":0.51852,"qty":1161.96536437}],"asks":[],"checksum":464885477,"timestamp":"2024-06-01T18:07:14.831778Z"}]}
{"channel":"book","type":"update","data":[{"symbol":"XRP/USD","bids":[{"price":0.51865,"qty":4512.50000000}],"asks":[],"checksum":530662195,"timestamp":"2024-06-01T18:07:14.847858Z"}]}
{"channel":"book","type":"update","data":[{"symbol":"XRP/USD","bids":[{"price":0.51865,"qty":3256.25000000}],"asks":[],"checksum":464885477,"timestamp":"2024-06-01T18:07:14.937731Z"}]}
{"channel":"book","type":"update","data":[{"symbol":"XRP/USD","bids":[{"price":0.51865,"qty":4512.50000000}],"asks":[],"checksum":530662195,"timestamp":"2024-06-01T18:07:14.945601Z"}]}
{"channel":"book","type":"update","data":[{"symbol":"XRP/USD","bids":[],"asks":[{"price":0.51869,"qty":16387.58594704}],"checksum":1883201021,"timestamp":"2024-06-01T18:07:15.001909Z"}]}
{"channel":"book","type":"update","data":[{"symbol":"XRP/USD","bids":[{"price":0.51865,"qty":3256.25000000}],"asks":[],"checksum":1949009963,"timestamp":"2024-06-01T18:07:15.006021Z"}]}
{"channel":"book","type":"update","data":[{"symbol":"XRP/USD","bids":[{"price":0.51866,"qty":1256.25000000}],"asks":[],"checksum":2593598656,"timestamp":"2024-06-01T18:07:15.009724Z"}]}
{"channel":"book","type":"update","data":[{"symbol":"XRP/USD","bids":[{"price":0.51865,"qty":4512.50000000}],"asks":[],"checksum":187041418,"timestamp":"2024-06-01T18:07:15.009895Z"}]}
{"channel":"book","type":"update","data":[{"symbol":"XRP/USD","bids":[{"price":0.51853,"qty":4821.23146771}],"asks":[],"checksum":86818717,"timestamp":"2024-06-01T18:07:15.012245Z"}]}
{"channel":"book","type":"update","data":[{"symbol":"XRP/USD","bids":[{"price":0.51866,"qty":0.00000000},{"price":0.51846,"qty":50207.94991110}],"asks":[],"checksum":1153060202,"timestamp":"2024-06-01T18:07:15.013622Z"}]}
{"channel":"book","type":"update","data":[{"symbol":"XRP/USD","bids":[{"price":0.51865,"qty":3256.25000000}],"asks":[],"checksum":1085184188,"timestamp":"2024-06-01T18:07:15.013920Z"}]}
{"channel":"book","type":"update","data":[{"symbol":"XRP/USD","bids":[{"price":0.51866,"qty":1256.25000000}],"asks":[],"checksum":2493355479,"timestamp":"2024-06-01T18:07:15.018113Z"}]}
{"channel":"book","type":"update","data":[{"symbol":"XRP/USD","bids":[{"price":0.51866,"qty":0.00000000},{"price":0.51846,"qty":50207.94991110}],"asks":[],"checksum":1085184188,"timestamp":"2024-06-01T18:07:15.022085Z"}]}
{"channel":"book","type":"update","data":[{"symbol":"XRP/USD","bids":[{"price":0.51866,"qty":1256.25000000}],"asks":[],"checksum":2493355479,"timestamp":"2024-06-01T18:07:15.026465Z"}]}
{"channel":"book","type":"update","data":[{"symbol":"XRP/USD","bids":[{"price":0.51865,"qty":4512.50000000}],"asks":[],"checksum":86818717,"timestamp":"2024-06-01T18:07:15.027797Z"}]}
{"channel":"book","type":"update","data":[{"symbol":"XRP/USD","bids":[{"price":0.51865,"qty":3256.25000000}],"asks":[],"checksum":2493355479,"timestamp":"2024-06-01T18:07:15.030776Z"}]}
{"channel":"book","type":"update","data":[{"symbol":"XRP/USD","bids":[{"price":0.51866,"qty":2512.50000000}],"asks":[],"checksum":148304011,"timestamp":"2024-06-01T18:07:15.034263Z"}]}
{"channel":"book","type":"update","data":[{"symbol":"XRP/USD","bids":[],"asks":[{"price":0.51872,"qty":0.00000000},{"price":0.51892,"qty":4692.48516623},{"price":0.51876,"qty":680.00000000}],"checksum":99664902,"timestamp":"2024-06-01T18:07:15.283102Z"}]}
{"channel":"book","type":"update","data":[{"symbol":"XRP/USD","bids":[],"asks":[{"price":0.51876,"qty":1360.00000000}],"checksum":2206657443,"timestamp":"2024-06-01T18:07:15.287501Z"}]}
{"channel":"book","type":"update","data":[{"symbol":"XRP/USD","bids":[],"asks":[{"price":0.51869,"qty":0.00000000},{"price":0.51892,"qty":4692.48516623}],"checksum":3048460829,"timestamp":"2024-06-01T18:07:15.519753Z"}]}
{"channel":"book","type":"update","data":[{"symbol":"XRP/USD","bids":[{"price":0.51866,"qty":1256.25000000}],"asks":[],"checksum":704165697,"timestamp":"2024-06-01T18:07:15.523783Z"}]}
{"channel":"book","type":"update","data":[{"symbol":"XRP/USD","bids":[{"price":0.51866,"qty":2512.50000000}],"asks":[],"checksum":3048460829,"timestamp":"2024-06-01T18:07:15.526960Z"}]}
{"channel":"book","type":"update","data":[{"symbol":"XRP/USD","bids":[{"price":0.51866,"qty":1256.25000000}],"asks":[],"checksum":704165697,"timestamp":"2024-06-01T18:07:16.092172Z"}]}
{"channel":"book","type":"update","data":[{"symbol":"XRP/USD","bids":[{"price":0.51866,"qty":2512.50000000}],"asks":[],"checksum":3048460829,"timestamp":"2024-06-01T18:07:16.220929Z"}]}
{"channel":"book","type":"update","data":[{"symbol":"XRP/USD","bids":[{"price":0.51866,"qty":1256.25000000}],"asks":[],"checksum":704165697,"timestamp":"2024-06-01T18:07:16.358533Z"}]}
{"channel":"book","type":"update","data":[{"symbol":"XRP/USD","bids":[{"price":0.51866,"qty":0.00000000},{"price":0.51846,"qty":50207.94991110}],"asks":[],"checksum":1501547503,"timestamp":"2024-06-01T18:07:16.358938Z"}]}
{"channel":"book","type":"update","data":[{"symbol":"XRP/USD","bids":[{"price":0.51866,"qty":1256.25000000}],"asks":[],"checksum":704165697,"timestamp":"2024-06-01T18:07:16.363285Z"}]}
{"channel":"book","type":"update","data":[{"symbol":"XRP/USD","bids":[{"price":0.51866,"qty":2512.50000000}],"asks":[],"checksum":3048460829,"timestamp":"2024-06-01T18:07:16.428236Z"}]}
{"channel":"book","type":"update","data":[{"symbol":"XRP/USD","bids":[{"price":0.51866,"qty":1256.25000000}],"asks":[],"checksum":704165697,"timestamp":"2024-06-01T18:07:16.621947Z"}]}
{"channel":"book","type":"update","data":[{"symbol":"XRP/USD","bids":[{"price":0.51866,"qty":0.00000000},{"price":0.51846,"qty":50207.94991110}],"asks":[],"checksum":1501547503,"timestamp":"2024-06-01T18:07:16.678380Z"}]}
{"channel":"book","type":"update","data":[{"symbol":"XRP/USD","bids":[{"price":0.51866,"qty":1256.25000000}],"asks":[],"checksum":704165697,"timestamp":"2024-06-01T18:07:16.682584Z"}]}
{"channel":"book","type":"update","data":[{"symbol":"XRP/USD","bids":[{"price":0.51866,"qty":0.00000000},{"price":0.51846,"qty":50207.94991110}],"asks":[],"checksum":1501547503,"timestamp":"2024-06-01T18:07:16.761643Z"}]}
{"channel":"book","type":"update","data":[{"symbol":"XRP/USD","bids":[{"price":0.51865,"qty":4512.50000000}],"asks":[],"checksum":1567301177,"timestamp":"2024-06-01T18:07:16.769155Z"}]}
{"channel":"book","type":"update","data":[{"symbol":"XRP/USD","bids":[{"price":0.51866,"qty":1256.25000000}],"asks":[],"checksum":3091832075,"timestamp":"2024-06-01T18:07:16.815290Z"}]}
{"channel":"book","type":"update","data":[{"symbol":"XRP/USD","bids":[{"price":0.51865,"qty":3256.25000000}],"asks":[],"checksum":704165697,"timestamp":"2024-06-01T18:07:16.819116Z"}]}
{"channel":"book","type":"update","data":[{"symbol":"XRP/USD","bids":[{"price":0.51866,"qty":2512.50000000}],"asks":[],"checksum":3048460829,"timestamp":"2024-06-01T18:07:16.835607Z"}]}
{"channel":"book","type":"update","data":[{"symbol":"XRP/USD","bids":[{"price":0.51866,"qty":1256.25000000}],"asks":[],"checksum":704165697,"timestamp":"2024-06-01T18:07:16.840142Z"}]}
{"channel":"book","type":"update","data":[{"symbol":"XRP/USD","bids":[{"price":0.51866,"qty":2512.50000000}],"asks":[],"checksum":3048460829,"timestamp":"2024-06-01T18:07:16.854552Z"}]}
{"channel":"book","type":"update","data":[{"symbol":"XRP/USD","bids":[{"price":0.51866,"qty":1256.25000000}],"asks":[],"checksum":704165697,"timestamp":"2024-06-01T18:07:16.862401Z"}]}
{"channel":"book","type":"update","data":[{"symbol":"XRP/USD","bids":[{"price":0.51866,"qty":2512.50000000}],"asks":[],"checksum":3048460829,"timestamp":"2024-06-01T18:07:16.877216Z"}]}
{"channel":"book","type":"update","data":[{"symbol":"XRP/USD","bids":[{"price":0.51866,"qty":1256.25000000}],"asks":[],"checksum":704165697,"timestamp":"2024-06-01T18:07:16.938518Z"}]}
{"channel":"book","type":"update","data":[{"symbol":"XRP/USD","bids":[{"price":0.51866,"qty":2512.50000000}],"asks":[],"checksum":3048460829,"timestamp":"2024-06-01T18:07:16.953946Z"}]}
{"channel":"book","type":"update","data":[{"symbol":"XRP/USD","bids":[],"asks":[{"price":0.51869,"qty":16387.48929290}],"checksum":2441888156,"timestamp":"2024-06-01T18:07:17.336581Z"}]}
{"channel":"book","type":"update","data":[{"symbol":"XRP/USD","bids":[{"price":0.51866,"qty":1256.25000000}],"asks":[],"checksum":231154880,"timestamp":"2024-06-01T18:07:17.340324Z"}]}
{"channel":"book","type":"update","data":[{"symbol":"XRP/USD","bids":[{"price":0.51866,"qty":2512.50000000}],"asks":[],"checksum":2441888156,"timestamp":"2024-06-01T18:07:17.344005Z"}]}
{"channel":"book","type":"update","data":[{"symbol":"XRP/USD","bids":[{"price":0.51866,"qty":1256.25000000}],"asks":[],"checksum":231154880,"timestamp":"2024-06-01T18:07:18.069089Z"}]}
{"channel":"book","type":"update","data":[{"symbol":"XRP/USD","bids":[{"price":0.51866,"qty":0.00000000},{"price":0.51846,"qty":50207.94991110}],"asks":[],"checksum":3286517706,"timestamp":"2024-06-01T18:07:18.099392Z"}]}
{"channel":"book","type":"update","data":[{"symbol":"XRP/USD","bids":[{"price":0.51866,"qty":1256.25000000}],"asks":[],"checksum":231154880,"timestamp":"2024-06-01T18:07:18.103133Z"}]}
{"channel":"book","type":"update","data":[{"symbol":"XRP/USD","bids":[{"price":0.51866,"qty":2512.50000000}],"asks":[],"checksum":2441888156,"timestamp":"2024-06-01T18:07:18.135965Z"}]}
{"channel":"book","type":"update","data":[{"symbol":"XRP/USD","bids":[{"price":0.51852,"qty":680.00000000}],"asks":[],"checksum":1979633191,"timestamp":"2024-06-01T18:07:18.460445Z"}]}
{"channel":"book","type":"update","data":[{"symbol":"XRP/USD","bids":[{"price":0.51866,"qty":1256.25000000}],"asks":[],"checksum":933051363,"timestamp":"2024-06-01T18:07:18.667930Z"}]}
{"channel":"book","type":"update","data":[{"symbol":"XRP/USD","bids":[{"price":0.51849,"qty":1371.59300000}],"asks":[],"checksum":651906920,"timestamp":"2024-06-01T18:07:18.674251Z"}]}
{"channel":"book","type":"update","data":[{"symbol":"XRP/USD","bids":[{"price":0.51866,"qty":2512.50000000}],"asks":[],"checksum":1689828012,"timestamp":"2024-06-01T18:07:18.677560Z"}]}
{"channel":"book","type":"update","data":[{"symbol":"XRP/USD","bids":[{"price":0.51866,"qty":1256.25000000}],"asks":[],"checksum":651906920,"timestamp":"2024-06-01T18:07:18.732680Z"}]}
{"channel":"book","type":"update","data":[{"symbol":"XRP/USD","bids":[{"price":0.51866,"qty":0.00000000},{"price":0.51846,"qty":2000.00000000}],"asks":[],"checksum":3452471180,"timestamp":"2024-06-01T18:07:18.733864Z"}]}
{"channel":"book","type":"update","data":[{"symbol":"XRP/USD","bids":[{"price":0.51865,"qty":2000.00000000}],"asks":[],"checksum":3033967496,"timestamp":"2024-06-01T18:07:18.734654Z"}]}
{"channel":"book","type":"update","data":[{"symbol":"XRP/USD","bids":[{"price":0.51865,"qty":3256.25000000}],"asks":[],"checksum":3452471180,"timestamp":"2024-06-01T18:07:18.737854Z"}]}
{"channel":"book","type":"update","data":[{"symbol":"XRP/USD","bids":[{"price":0.51865,"qty":2000.00000000}],"asks":[],"checksum":3033967496,"timestamp":"2024-06-01T18:07:18.740958Z"}]}
{"channel":"book","type":"update","data":[{"symbol":"XRP/USD","bids":[],"asks":[{"price":0.51875,"qty":1256.25000000}],"checksum":1509557852,"timestamp":"2024-06-01T18:07:18.743696Z"}]}
{"channel":"book","type":"update","data":[{"symbol":"XRP/USD","bids":[],"asks":[{"price":0.51875,"qty":0.00000000},{"price":0.51891,"qty":36.23516623}],"checksum":3033967496,"timestamp":"2024-06-01T18:07:18.747642Z"}]}
{"channel":"book","type":"update","data":[{"symbol":"XRP/USD","bids":[{"price":0.51865,"qty":3256.25000000}],"asks":[],"checksum":3452471180,"timestamp":"2024-06-01T18:07:18.762649Z"}]}
{"channel":"book","type":"update","data":[{"symbol":"XRP/USD","bids":[{"price":0.51865,"qty":2000.00000000}],"asks":[],"checksum":3033967496,"timestamp":"2024-06-01T18:07:18.817960Z"}]}
{"channel":"book","type":"update","data":[{"symbol":"XRP/USD","bids":[{"price":0.51849,"qty":4383.33880865}],"asks":[],"checksum":2738616689,"timestamp":"2024-06-01T18:07:18.821907Z"}]}
{"channel":"book","type":"update","data":[{"symbol":"XRP/USD","bids":[{"price":0.51865,"qty":3256.25000000}],"asks":[],"checksum":3659912565,"timestamp":"2024-06-01T18:07:18.857129Z"}]}
{"channel":"book","type":"update","data":[{"symbol":"XRP/USD","bids":[{"price":0.51865,"qty":2000.00000000}],"asks":[],"checksum":2738616689,"timestamp":"2024-06-01T18:07:18.865425Z"}]}
{"channel":"book","type":"update","data":[{"symbol":"XRP/USD","bids":[{"price":0.51865,"qty":3256.25000000}],"asks":[],"checksum":3659912565,"timestamp":"2024-06-01T18:07:18.869352Z"}]}
{"channel":"book","type":"update","data":[{"symbol":"XRP/USD","bids":[{"price":0.51865,"qty":2000.00000000}],"asks":[],"checksum":2738616689,"timestamp":"2024-06-01T18:07:18.872410Z"}]}
{"channel":"book","type":"update","data":[{"symbol":"XRP/USD","bids":[{"price":0.51850,"qty":4561.18878872}],"asks":[],"checksum":2724684501,"timestamp":"2024-06-01T18:07:18.920289Z"}]}
{"channel":"book","type":"update","data":[{"symbol":"XRP/USD","bids":[],"asks":[{"price":0.51875,"qty":1256.25000000}],"checksum":910792277,"timestamp":"2024-06-01T18:07:18.934662Z"}]}
{"channel":"book","type":"update","data":[{"symbol":"XRP/USD","bids":[],"asks":[{"price":0.51870,"qty":0.00000000},{"price":0.51891,"qty":36.23516623}],"checksum":1937842573,"timestamp":"2024-06-01T18:07:19.075157Z"}]}
{"channel":"book","type":"update","data":[{"symbol":"XRP/USD","bids":[],"asks":[{"price":0.51868,"qty":4819.92750829}],"checksum":1726891071,"timestamp":"2024-06-01T18:07:19.078630Z"}]}
{"channel":"book","type":"update","data":[{"symbol":"XRP/USD","bids":[{"price":0.51846,"qty":3673.77765634}],"asks":[],"checksum":2358971514,"timestamp":"2024-06-01T18:07:19.084936Z"}]}
{"channel":"book","type":"update","data":[{"symbol":"XRP/USD","bids":[],"asks":[{"price":0.51876,"qty":680.00000000}],"checksum":3614035794,"timestamp":"2024-06-01T18:07:19.211256Z"}]}
{"channel":"book","type":"update","data":[{"symbol":"XRP/USD","bids":[{"price":0.51851,"qty":0.00000000},{"price":0.51842,"qty":20700.74731583}],"asks":[],"checksum":4247790674,"timestamp":"2024-06-01T18:07:19.297719Z"}]}
{"channel":"book","type":"update","data":[{"symbol":"XRP/USD","bids":[{"price":0.51847,"qty":0.00000000},{"price":0.51840,"qty":18325.08888487}],"asks":[],"checksum":3603504680,"timestamp":"2024-06-01T18:07:19.297788Z"}]}
{"channel":"book","type":"update","data":[{"symbol":"XRP/USD","bids":[{"price":0.51842,"qty":5086.23516623},{"price":0.51841,"qty":15614.51214960}],"asks":[],"checksum":479871697,"timestamp":"2024-06-01T18:07:19.301835Z"}]}
{"channel":"book","type":"update","data":[{"symbol":"XRP/USD","bids":[{"price":0.51843,"qty":142.02289401}],"asks":[],"checksum":3994795339,"timestamp":"2024-06-01T18:07:19.308516Z"}]}
{"channel":"book","type":"update","data":[{"symbol":"XRP/USD","bids":[{"price":0.51846,"qty":51881.72756744}],"asks":[],"checksum":2307650539,"timestamp":"2024-06-01T18:07:19.587171Z"}]}
{"channel":"book","type":"update","data":[{"symbol":"XRP/USD","bids":[],"asks":[{"price":0.51875,"qty":0.00000000},{"price":0.51891,"qty":36.23516623}],"checksum":2912772301,"timestamp":"2024-06-01T18:07:19.789545Z"}]}
{"channel":"book","type":"update","data":[{"symbol":"XRP/USD","bids":[{"price":0.51853,"qty":0.00000000},{"price":0.51841,"qty":15614.51214960}],"asks":[],"checksum":1357955751,"timestamp":"2024-06-01T18:07:20.086830Z"}]}
{"channel":"book","type":"update","data":[{"symbol":"XRP/USD","bids":[{"price":0.51848,"qty":4821.76463575}],"asks":[],"checksum":573575949,"timestamp":"2024-06-01T18:07:20.090977Z"}]}
{"channel":"book","type":"update","data":[{"symbol":"XRP/USD","bids":[],"asks":[{"price":0.51874,"qty":1256.25000000}],"checksum":638861214,"timestamp":"2024-06-01T18:07:20.175084Z"}]}
{"channel":"book","type":"update","data":[{"symbol":"XRP/USD","bids":[{"price":0.51865,"qty":0.00000000},{"price":0.51841,"qty":15614.51214960}],"asks":[],"checksum":1839555194,"timestamp":"2024-06-01T18:07:20.196591Z"}]}
{"channel":"book","type":"update","data":[{"symbol":"XRP/USD","bids":[],"asks":[{"price":0.51874,"qty":0.00000000},{"price":0.51891,"qty":36.23516623}],"checksum":78087336,"timestamp":"2024-06-01T18:07:20.200806Z"}]}
{"channel":"book","type":"update","data":[{"symbol":"XRP/USD","bids":[{"price":0.51860,"qty":1256.25000000}],"asks":[],"checksum":315942030,"timestamp":"2024-06-01T18:07:20.200884Z"}]}
{"channel":"book","type":"update","data":[{"symbol":"XRP/USD","bids":[],"asks":[{"price":0.51874,"qty":1256.25000000}],"checksum":384878621,"timestamp":"2024-06-01T18:07:20.203939Z"}]}
{"channel":"book","type":"update","data":[{"symbol":"XRP/USD","bids":[],"asks":[{"price":0.51876,"qty":0.00000000},{"price":0.51891,"qty":36.23516623},{"price":0.51872,"qty":680.00000000}],"checksum":992357074,"timestamp":"2024-06-01T18:07:20.576696Z"}]}
{"channel":"book","type":"update","data":[{"symbol":"XRP/USD","bids":[],"asks":[{"price":0.51872,"qty":1360.00000000}],"checksum":4076841308,"timestamp":"2024-06-01T18:07:20.580358Z"}]}
{"channel":"book","type":"update","data":[{"symbol":"XRP/USD","bids":[{"price":0.51860,"qty":0.00000000},{"price":0.51841,"qty":15614.51214960}],"asks":[],"checksum":1822039069,"timestamp":"2024-06-01T18:07:20.840159Z"}]}
{"channel":"book","type":"update","data":[{"symbol":"XRP/USD","bids":[{"price":0.51841,"qty":0.00000000},{"price":0.51840,"qty":9707.47033246},{"price":0.51842,"qty":20700.74731583}],"asks":[],"checksum":4213387445,"timestamp":"2024-06-01T18:07:20.843488Z"}]}
{"channel":"book","type":"update","data":[{"symbol":"XRP/USD","bids":[{"price":0.51859,"qty":1256.25000000}],"asks":[],"checksum":2789695770,"timestamp":"2024-06-01T18:07:20.843864Z"}]}
{"channel":"book","type":"update","data":[{"symbol":"XRP/USD","bids":[{"price":0.51857,"qty":0.00000000},{"price":0.51840,"qty":18129.83888487}],"asks":[],"checksum":2951284230,"timestamp":"2024-06-01T18:07:20.847634Z"}]}
{"channel":"book","type":"update","data":[{"symbol":"XRP/USD","bids":[{"price":0.51859,"qty":0.00000000},{"price":0.51839,"qty":1256.25000000}],"asks":[],"checksum":896852320,"timestamp":"2024-06-01T18:07:20.848229Z"}]}
{"channel":"book","type":"update","data":[{"symbol":"XRP/USD","bids":[{"price":0.51853,"qty":1400.00000000}],"asks":[],"checksum":3334962374,"timestamp":"2024-06-01T18:07:20.850623Z"}]}
{"channel":"book","type":"update","data":[{"symbol":"XRP/USD","bids":[{"price":0.51858,"qty":0.00000000},{"price":0.51839,"qty":1256.25000000}],"asks":[],"checksum":226304814,"timestamp":"2024-06-01T18:07:20.850722Z"}]}
{"channel":"book","type":"update","data":[{"symbol":"XRP/USD","bids":[{"price":0.51858,"qty":1256.25000000}],"asks":[],"checksum":4000759483,"timestamp":"2024-06-01T18:07:20.852782Z"}]}
{"channel":"book","type":"update","data":[{"symbol":"XRP/USD","bids":[{"price":0.51858,"qty":2512.50000000}],"asks":[],"checksum":1918135817,"timestamp":"2024-06-01T18:07:20.853947Z"}]}
{"channel":"book","type":"update","data":[{"symbol":"XRP/USD","bids":[{"price":0.51858,"qty":1256.25000000}],"asks":[],"checksum":4000759483,"timestamp":"2024-06-01T18:07:20.856737Z"}]}
{"channel":"book","type":"update","data":[{"symbol":"XRP/USD","bids":[{"price":0.51858,"qty":2512.50000000}],"asks":[],"checksum":1918135817,"timestamp":"2024-06-01T18:07:20.860995Z"}]}
{"channel":"book","type":"update","data":[{"symbol":"XRP/USD","bids":[{"price":0.51858,"qty":4512.50000000}],"asks":[],"checksum":2438018655,"timestamp":"2024-06-01T18:07:21.317654Z"}]}
{"channel":"book","type":"update","data":[{"symbol":"XRP/USD","bids":[{"price":0.51858,"qty":3256.25000000}],"asks":[],"checksum":2961864329,"timestamp":"2024-06-01T18:07:21.432367Z"}]}
{"channel":"book","type":"update","data":[{"symbol":"XRP/USD","bids":[],"asks":[{"price":0.51868,"qty":6076.17750829}],"checksum":3263891623,"timestamp":"2024-06-01T18:07:21.432411Z"}]}
{"channel":"book","type":"update","data":[{"symbol":"XRP/USD","bids":[{"price":0.51858,"qty":2000.00000000}],"asks":[],"checksum":2166806067,"timestamp":"2024-06-01T18:07:21.432787Z"}]}
{"channel":"book","type":"update","data":[{"symbol":"XRP/USD","bids":[],"asks":[{"price":0.51868,"qty":4819.92750829}],"checksum":4079462429,"timestamp":"2024-06-01T18:07:21.435306Z"}]}
{"channel":"book","type":"update","data":[{"symbol":"XRP/USD","bids":[],"asks":[{"price":0.51868,"qty":6076.17750829}],"checksum":2166806067,"timestamp":"2024-06-01T18:07:21.439015Z"}]}
{"channel":"book","type":"update","data":[{"symbol":"XRP/USD","bids":[],"asks":[{"price":0.51868,"qty":4819.92750829}],"checksum":4079462429,"timestamp":"2024-06-01T18:07:21.442357Z"}]}
{"channel":"book","type":"update","data":[{"symbol":"XRP/USD","bids":[{"price":0.51852,"qty":0.00000000},{"price":0.51839,"qty":1256.25000000}],"asks":[],"checksum":64045896,"timestamp":"2024-06-01T18:07:21.443264Z"}]}
{"channel":"book","type":"update","data":[{"symbol":"XRP/USD","bids":[{"price":0.51858,"qty":3256.25000000}],"asks":[],"checksum":4109416907,"timestamp":"2024-06-01T18:07:21.443470Z"}]}
{"channel":"book","type":"update","data":[{"symbol":"XRP/USD","bids":[{"price":0.51850,"qty":0.00000000},{"price":0.51838,"qty":36.23516623}],"asks":[],"checksum":1122402464,"timestamp":"2024-06-01T18:07:21.443804Z"}]}
{"channel":"book","type":"update","data":[{"symbol":"XRP/USD","bids":[{"price":0.51858,"qty":4512.50000000}],"asks":[],"checksum":760406932,"timestamp":"2024-06-01T18:07:21.443838Z"}]}
{"channel":"book","type":"update","data":[{"symbol":"XRP/USD","bids":[{"price":0.51838,"qty":0.00000000},{"price":0.51837,"qty":6097.65223000}],"asks":[],"checksum":3358136745,"timestamp":"2024-06-01T18:07:21.444354Z"}]}
{"channel":"book","type":"update","data":[{"symbol":"XRP/USD","bids":[{"price":0.51840,"qty":18093.60371864}],"asks":[],"checksum":520925072,"timestamp":"2024-06-01T18:07:21.444414Z"}]}
{"channel":"book","type":"update","data":[{"symbol":"XRP/USD","bids":[{"price":0.51840,"qty":18057.36855241}],"asks":[],"checksum":2311198490,"timestamp":"2024-06-01T18:07:21.444449Z"}]}
{"channel":"book","type":"update","data":[{"symbol":"XRP/USD","bids":[{"price":0.51842,"qty":20664.51214960}],"asks":[],"checksum":2257713257,"timestamp":"2024-06-01T18:07:21.444577Z"}]}
{"channel":"book","type":"update","data":[{"symbol":"XRP/USD","bids":[{"price":0.51849,"qty":1371.59300000}],"asks":[],"checksum":3493422256,"timestamp":"2024-06-01T18:07:21.444841Z"}]}
{"channel":"book","type":"update","data":[{"symbol":"XRP/USD","bids":[{"price":0.51842,"qty":5050.00000000}],"asks":[],"checksum":3228041937,"timestamp":"2024-06-01T18:07:21.445337Z"}]}
{"channel":"book","type":"update","data":[{"symbol":"XRP/USD","bids":[],"asks":[{"price":0.51882,"qty":36.23516623}],"checksum":4004212499,"timestamp":"2024-06-01T18:07:21.445554Z"}]}
{"channel":"book","type":"update","data":[{"symbol":"XRP/USD","bids":[],"asks":[{"price":0.51888,"qty":9635.00000000}],"checksum":2915196160,"timestamp":"2024-06-01T18:07:21.445622Z"}]}
{"channel":"book","type":"update","data":[{"symbol":"XRP/USD","bids":[{"price":0.51853,"qty":0.00000000},{"price":0.51836,"qty":9645.69618474}],"asks":[],"checksum":3031476507,"timestamp":"2024-06-01T18:07:21.446765Z"}]}
{"channel":"book","type":"update","data":[{"symbol":"XRP/USD","bids":[{"price":0.51858,"qty":3256.25000000}],"asks":[],"checksum":2506877389,"timestamp":"2024-06-01T18:07:21.447258Z"}]}
{"channel":"book","type":"update","data":[{"symbol":"XRP/USD","bids":[{"price":0.51858,"qty":2000.00000000}],"asks":[],"checksum":3603314521,"timestamp":"2024-06-01T18:07:21.447296Z"}]}
{"channel":"book","type":"update","data":[{"symbol":"XRP/USD","bids":[{"price":0.51846,"qty":3673.77765634}],"asks":[],"checksum":1570923081,"timestamp":"2024-06-01T18:07:21.448371Z"}]}
{"channel":"book","type":"update","data":[{"symbol":"XRP/USD","bids":[],"asks":[{"price":0.51868,"qty":6076.17750829}],"checksum":1231055840,"timestamp":"2024-06-01T18:07:21.449217Z"}]}
{"channel":"book","type":"update","data":[{"symbol":"XRP/USD","bids":[{"price":0.51850,"qty":1400.00000000}],"asks":[],"checksum":2023258393,"timestamp":"2024-06-01T18:07:21.450830Z"}]}
{"channel":"book","type":"update","data":[{"symbol":"XRP/USD","bids":[{"price":0.51846,"qty":2000.00000000}],"asks":[],"checksum":3709776185,"timestamp":"2024-06-01T18:07:21.458966Z"}]}
{"channel":"book","type":"update","data":[{"symbol":"XRP/USD","bids":[],"asks":[{"price":0.51881,"qty":36.23516623}],"checksum":2438780315,"timestamp":"2024-06-01T18:07:21.462498Z"}]}
{"channel":"book","type":"update","data":[{"symbol":"XRP/USD","bids":[],"asks":[{"price":0.51872,"qty":680.00000000}],"checksum":1454178791,"timestamp":"2024-06-01T18:07:21.469602Z"}]}
{"channel":"book","type":"update","data":[{"symbol":"XRP/USD","bids":[],"asks":[{"price":0.51884,"qty":14723.23743391}],"checksum":1678979636,"timestamp":"2024-06-01T18:07:21.471365Z"}]}
{"channel":"book","type":"update","data":[{"symbol":"XRP/USD","bids":[],"asks":[{"price":0.51868,"qty":4819.92750829}],"checksum":3214137416,"timestamp":"2024-06-01T18:07:21.471878Z"}]}
{"channel":"book","type":"update","data":[{"symbol":"XRP/USD","bids":[],"asks":[{"price":0.51883,"qty":1292.48516623}],"checksum":1040340812,"timestamp":"2024-06-01T18:07:21.474307Z"}]}
{"channel":"book","type":"update","data":[{"symbol":"XRP/USD","bids":[],"asks":[{"price":0.51872,"qty":0.00000000},{"price":0.51888,"qty":9635.00000000},{"price":0.51868,"qty":5499.92750829}],"checksum":1269931999,"timestamp":"2024-06-01T18:07:21.478488Z"}]}
{"channel":"book","type":"update","data":[{"symbol":"XRP/USD","bids":[],"asks":[{"price":0.51868,"qty":6179.92750829}],"checksum":3852511462,"timestamp":"2024-06-01T18:07:21.481682Z"}]}
{"channel":"book","type":"update","data":[{"symbol":"XRP/USD","bids":[],"asks":[{"price":0.51868,"qty":7436.17750829}],"checksum":2355798061,"timestamp":"2024-06-01T18:07:21.490191Z"}]}
{"channel":"book","type":"update","data":[{"symbol":"XRP/USD","bids":[],"asks":[{"price":0.51867,"qty":1256.25000000}],"checksum":1491515618,"timestamp":"2024-06-01T18:07:21.498629Z"}]}
{"channel":"book","type":"update","data":[{"symbol":"XRP/USD","bids":[],"asks":[{"price":0.51867,"qty":0.00000000},{"price":0.51888,"qty":9635.00000000}],"checksum":2355798061,"timestamp":"2024-06-01T18:07:21.502488Z"}]}
{"channel":"book","type":"update","data":[{"symbol":"XRP/USD","bids":[],"asks":[{"price":0.51868,"qty":8692.42750829}],"checksum":582820087,"timestamp":"2024-06-01T18:07:21.503175Z"}]}
{"channel":"book","type":"update","data":[{"symbol":"XRP/USD","bids":[{"price":0.51858,"qty":0.00000000},{"price":0.51836,"qty":9645.69618474}],"asks":[],"checksum":3402077738,"timestamp":"2024-06-01T18:07:21.505785Z"}]}
{"channel":"book","type":"update","data":[{"symbol":"XRP/USD","bids":[],"asks":[{"price":0.51868,"qty":7436.17750829}],"checksum":1678776048,"timestamp":"2024-06-01T18:07:21.507962Z"}]}
{"channel":"book","type":"update","data":[{"symbol":"XRP/USD","bids":[],"asks":[{"price":0.51867,"qty":1256.25000000}],"checksum":2963017279,"timestamp":"2024-06-01T18:07:21.508234Z"}]}
{"channel":"book","type":"update","data":[{"symbol":"XRP/USD","bids":[{"price":0.51852,"qty":1256.25000000}],"asks":[],"checksum":1084134473,"timestamp":"2024-06-01T18:07:21.511242Z"}]}
{"channel":"book","type":"update","data":[{"symbol":"XRP/USD","bids":[{"price":0.51844,"qty":4949.79293158}],"asks":[],"checksum":395457677,"timestamp":"2024-06-01T18:07:21.511611Z"}]}
{"channel":"book","type":"update","data":[{"symbol":"XRP/USD","bids":[{"price":0.51855,"qty":1256.25000000}],"asks":[],"checksum":4064039228,"timestamp":"2024-06-01T18:07:21.512658Z"}]}
{"channel":"book","type":"update","data":[{"symbol":"XRP/USD","bids":[{"price":0.51850,"qty":0.00000000},{"price":0.51839,"qty":1256.25000000}],"asks":[],"checksum":376465862,"timestamp":"2024-06-01T18:07:21.514717Z"}]}
{"channel":"book","type":"update","data":[{"symbol":"XRP/USD","bids":[{"price":0.51853,"qty":1400.00000000}],"asks":[],"checksum":152499321,"timestamp":"2024-06-01T18:07:21.515071Z"}]}
{"channel":"book","type":"update","data":[{"symbol":"XRP/USD","bids":[{"price":0.51855,"qty":2512.50000000}],"asks":[],"checksum":583069629,"timestamp":"2024-06-01T18:07:21.517999Z"}]}
{"channel":"book","type":"update","data":[{"symbol":"XRP/USD","bids":[{"price":0.51852,"qty":0.00000000},{"price":0.51839,"qty":1256.25000000}],"asks":[],"checksum":3251039044,"timestamp":"2024-06-01T18:07:21.518530Z"}]}
{"channel":"book","type":"update","data":[{"symbol":"XRP/USD","bids":[],"asks":[{"price":0.51867,"qty":0.00000000},{"price":0.51888,"qty":27838.73774400}],"checksum":2303724127,"timestamp":"2024-06-01T18:07:21.519147Z"}]}
{"channel":"book","type":"update","data":[{"symbol":"XRP/USD","bids":[{"price":0.51853,"qty":0.00000000},{"price":0.51837,"qty":6097.65223000}],"asks":[],"checksum":890778742,"timestamp":"2024-06-01T18:07:21.521899Z"}]}
{"channel":"book","type":"update","data":[{"symbol":"XRP/USD","bids":[{"price":0.51855,"qty":1256.25000000}],"asks":[],"checksum":516829106,"timestamp":"2024-06-01T18:07:21.523178Z"}]}
{"channel":"book","type":"update","data":[{"symbol":"XRP/USD","bids":[{"price":0.51850,"qty":1400.00000000}],"asks":[],"checksum":2474633689,"timestamp":"2024-06-01T18:07:21.523472Z"}]}
{"channel":"book","type":"update","data":[{"symbol":"XRP/USD","bids":[],"asks":[{"price":0.51867,"qty":1256.25000000}],"checksum":3689482434,"timestamp":"2024-06-01T18:07:21.523671Z"}]}
{"channel":"book","type":"update","data":[{"symbol":"XRP/USD","bids":[{"price":0.51855,"qty":2512.50000000}],"asks":[],"checksum":4030665478,"timestamp":"2024-06-01T18:07:21.526622Z"}]}
{"channel":"book","type":"update","data":[{"symbol":"XRP/USD","bids":[{"price":0.51839,"qty":2930.25367234}],"asks":[],"checksum":1631826812,"timestamp":"2024-06-01T18:07:21.579938Z"}]}
{"channel":"book","type":"update","data":[{"symbol":"XRP/USD","bids":[{"price":0.51846,"qty":0.00000000},{"price":0.51837,"qty":6097.65223000}],"asks":[],"checksum":592029383,"timestamp":"2024-06-01T18:07:21.584172Z"}]}
{"channel":"book","type":"update","data":[{"symbol":"XRP/USD","bids":[{"price":0.51839,"qty":5941.99948099}],"asks":[],"checksum":2366684188,"timestamp":"2024-06-01T18:07:21.588548Z"}]}
{"channel":"book","type":"update","data":[{"symbol":"XRP/USD","bids":[],"asks":[{"price":0.51867,"qty":0.00000000},{"price":0.51888,"qty":27838.73774400}],"checksum":3313917191,"timestamp":"2024-06-01T18:07:21.643834Z"}]}
{"channel":"book","type":"update","data":[{"symbol":"XRP/USD","bids":[{"price":0.51847,"qty":680.00000000}],"asks":[],"checksum":1604273056,"timestamp":"2024-06-01T18:07:21.648662Z"}]}
{"channel":"book","type":"update","data":[{"symbol":"XRP/USD","bids":[],"asks":[{"price":0.51867,"qty":1256.25000000}],"checksum":2068321031,"timestamp":"2024-06-01T18:07:21.653532Z"}]}
{"channel":"book","type":"update","data":[{"symbol":"XRP/USD","bids":[],"asks":[{"price":0.51867,"qty":0.00000000},{"price":0.51888,"qty":27838.73774400}],"checksum":1604273056,"timestamp":"2024-06-01T18:07:21.662193Z"}]}
{"channel":"book","type":"update","data":[{"symbol":"XRP/USD","bids":[{"price":0.51855,"qty":1256.25000000}],"asks":[],"checksum":1037964570,"timestamp":"2024-06-01T18:07:21.665878Z"}]}
{"channel":"book","type":"update","data":[{"symbol":"XRP/USD","bids":[{"price":0.51855,"qty":2512.50000000}],"asks":[],"checksum":1604273056,"timestamp":"2024-06-01T18:07:21.668415Z"}]}
{"channel":"book","type":"update","data":[{"symbol":"XRP/USD","bids":[],"asks":[{"price":0.51868,"qty":8692.42750829}],"checksum":4048077690,"timestamp":"2024-06-01T18:07:21.699601Z"}]}
{"channel":"book","type":"update","data":[{"symbol":"XRP/USD","bids":[],"asks":[{"price":0.51867,"qty":1256.25000000}],"checksum":246049734,"timestamp":"2024-06-01T18:07:21.699677Z"}]}
{"channel":"book","type":"update","data":[{"symbol":"XRP/USD","bids":[],"asks":[{"price":0.51868,"qty":7436.17750829}],"checksum":2068321031,"timestamp":"2024-06-01T18:07:21.704121Z"}]}
{"channel":"book","type":"update","data":[{"symbol":"XRP/USD","bids":[],"asks":[{"price":0.51868,"qty":2616.25000000}],"checksum":549115727,"timestamp":"2024-06-01T18:07:21.704572Z"}]}
{"channel":"book","type":"update","data":[{"symbol":"XRP/USD","bids":[],"asks":[{"price":0.51866,"qty":4820.11336906}],"checksum":2843974312,"timestamp":"2024-06-01T18:07:21.709361Z"}]}
{"channel":"book","type":"update","data":[{"symbol":"XRP/USD","bids":[{"price":0.51855,"qty":1256.25000000}],"asks":[],"checksum":3418541074,"timestamp":"2024-06-01T18:07:21.713007Z"}]}
{"channel":"book","type":"update","data":[{"symbol":"XRP/USD","bids":[{"price":0.51855,"qty":2512.50000000}],"asks":[],"checksum":2843974312,"timestamp":"2024-06-01T18:07:21.717034Z"}]}
{"channel":"book","type":"update","data":[{"symbol":"XRP/USD","bids":[],"asks":[{"price":0.51866,"qty":6076.36336906}],"checksum":3145600531,"timestamp":"2024-06-01T18:07:21.734343Z"}]}
{"channel":"book","type":"update","data":[{"symbol":"XRP/USD","bids":[],"asks":[{"price":0.51868,"qty":1360.00000000}],"checksum":273060908,"timestamp":"2024-06-01T18:07:21.734996Z"}]}
{"channel":"book","type":"update","data":[{"symbol":"XRP/USD","bids":[],"asks":[{"price":0.51866,"qty":4820.11336906}],"checksum":45809815,"timestamp":"2024-06-01T18:07:21.748273Z"}]}
{"channel":"book","type":"update","data":[{"symbol":"XRP/USD","bids":[{"price":0.51843,"qty":2654.52289401}],"asks":[],"checksum":3856573525,"timestamp":"2024-06-01T18:07:21.843868Z"}]}
{"channel":"book","type":"update","data":[{"symbol":"XRP/USD","bids":[],"asks":[{"price":0.51866,"qty":6076.36336906}],"checksum":3112121285,"timestamp":"2024-06-01T18:07:21.938771Z"}]}
{"channel":"book","type":"update","data":[{"symbol":"XRP/USD","bids":[],"asks":[{"price":0.51866,"qty":4820.11336906}],"checksum":3856573525,"timestamp":"2024-06-01T18:07:21.944669Z"}]}
{"channel":"book","type":"update","data":[{"symbol":"XRP/USD","bids":[],"asks":[{"price":0.51866,"qty":6076.36336906}],"checksum":3112121285,"timestamp":"2024-06-01T18:07:22.001096Z"}]}
{"channel":"book","type":"update","data":[{"symbol":"XRP/USD","bids":[],"asks":[{"price":0.51866,"qty":4820.11336906}],"checksum":3856573525,"timestamp":"2024-06-01T18:07:22.015377Z"}]}
{"channel":"book","type":"update","data":[{"symbol":"XRP/USD","bids":[{"price":0.51855,"qty":1256.25000000}],"asks":[],"checksum":3456679825,"timestamp":"2024-06-01T18:07:22.039502Z"}]}
{"channel":"book","type":"update","data":[{"symbol":"XRP/USD","bids":[],"asks":[{"price":0.51866,"qty":6076.36336906}],"checksum":2460559361,"timestamp":"2024-06-01T18:07:22.040511Z"}]}
{"channel":"book","type":"update","data":[{"symbol":"XRP/USD","bids":[{"price":0.51855,"qty":2512.50000000}],"asks":[],"checksum":3112121285,"timestamp":"2024-06-01T18:07:22.046422Z"}]}
{"channel":"book","type":"update","data":[{"symbol":"XRP/USD","bids":[],"asks":[{"price":0.51866,"qty":4820.11336906}],"checksum":3856573525,"timestamp":"2024-06-01T18:07:22.056722Z"}]}
{"channel":"book","type":"update","data":[{"symbol":"XRP/USD","bids":[{"price":0.51843,"qty":2512.50000000}],"asks":[],"checksum":4085403259,"timestamp":"2024-06-01T18:07:22.058341Z"}]}
{"channel":"book","type":"update","data":[{"symbol":"XRP/USD","bids":[{"price":0.51847,"qty":877.91805465}],"asks":[],"checksum":876876418,"timestamp":"2024-06-01T18:07:22.067395Z"}]}
{"channel":"book","type":"update","data":[{"symbol":"XRP/USD","bids":[{"price":0.51851,"qty":38.56413437}],"asks":[],"checksum":2178746857,"timestamp":"2024-06-01T18:07:22.067477Z"}]}
{"channel":"book","type":"update","data":[{"symbol":"XRP/USD","bids":[],"asks":[{"price":0.51866,"qty":6076.36336906}],"checksum":3416318640,"timestamp":"2024-06-01T18:07:22.138775Z"}]}
{"channel":"book","type":"update","data":[{"symbol":"XRP/USD","bids":[{"price":0.51855,"qty":1256.25000000}],"asks":[],"checksum":1475053548,"timestamp":"2024-06-01T18:07:22.141318Z"}]}
{"channel":"book","type":"update","data":[{"symbol":"XRP/USD","bids":[{"price":0.51855,"qty":0.00000000},{"price":0.51839,"qty":5941.99948099}],"asks":[],"checksum":3550638684,"timestamp":"2024-06-01T18:07:22.141864Z"}]}
{"channel":"book","type":"update","data":[{"symbol":"XRP/USD","bids":[{"price":0.51853,"qty":1256.25000000}],"asks":[],"checksum":43304246,"timestamp":"2024-06-01T18:07:22.146336Z"}]}
{"channel":"book","type":"update","data":[{"symbol":"XRP/USD","bids":[{"price":0.51847,"qty":197.91805465}],"asks":[],"checksum":2930841703,"timestamp":"2024-06-01T18:07:22.157601Z"}]}
{"channel":"book","type":"update","data":[{"symbol":"XRP/USD","bids":[{"price":0.51847,"qty":877.91805465}],"asks":[],"checksum":43304246,"timestamp":"2024-06-01T18:07:22.284797Z"}]}
{"channel":"book","type":"update","data":[{"symbol":"XRP/USD","bids":[],"asks":[{"price":0.51866,"qty":4820.11336906}],"checksum":1223241327,"timestamp":"2024-06-01T18:07:22.441336Z"}]}
{"channel":"book","type":"update","data":[{"symbol":"XRP/USD","bids":[],"asks":[{"price":0.51869,"qty":0.00000000},{"price":0.51884,"qty":14723.23743391}],"checksum":251892963,"timestamp":"2024-06-01T18:07:22.888961Z"}]}
{"channel":"book","type":"update","data":[{"symbol":"XRP/USD","bids":[{"price":0.51853,"qty":3256.25000000}],"asks":[],"checksum":652199822,"timestamp":"2024-06-01T18:07:23.137744Z"}]}
{"channel":"book","type":"update","data":[{"symbol":"XRP/USD","bids":[{"price":0.51850,"qty":0.00000000},{"price":0.51839,"qty":5941.99948099}],"asks":[],"checksum":3265139587,"timestamp":"2024-06-01T18:07:23.140404Z"}]}
{"channel":"book","type":"update","data":[{"symbol":"XRP/USD","bids":[{"price":0.51854,"qty":1400.00000000}],"asks":[],"checksum":2600476454,"timestamp":"2024-06-01T18:07:23.140658Z"}]}
{"channel":"book","type":"update","data":[{"symbol":"XRP/USD","bids":[{"price":0.51855,"qty":1256.25000000}],"asks":[],"checksum":1002233062,"timestamp":"2024-06-01T18:07:23.142508Z"}]}
{"channel":"book","type":"update","data":[{"symbol":"XRP/USD","bids":[{"price":0.51855,"qty":0.00000000},{"price":0.51840,"qty":18057.36855241}],"asks":[],"checksum":2600476454,"timestamp":"2024-06-01T18:07:23.145230Z"}]}
{"channel":"book","type":"update","data":[{"symbol":"XRP/USD","bids":[{"price":0.51855,"qty":1256.25000000}],"asks":[],"checksum":1002233062,"timestamp":"2024-06-01T18:07:23.145414Z"}]}
{"channel":"book","type":"update","data":[{"symbol":"XRP/USD","bids":[{"price":0.51855,"qty":2512.50000000}],"asks":[],"checksum":2044668194,"timestamp":"2024-06-01T18:07:23.161988Z"}]}
{"channel":"book","type":"update","data":[{"symbol":"XRP/USD","bids":[],"asks":[{"price":0.51866,"qty":6076.36336906}],"checksum":3683725638,"timestamp":"2024-06-01T18:07:23.194205Z"}]}
{"channel":"book","type":"update","data":[{"symbol":"XRP/USD","bids":[{"price":0.51855,"qty":1256.25000000}],"asks":[],"checksum":2582824066,"timestamp":"2024-06-01T18:07:23.263032Z"}]}
{"channel":"book","type":"update","data":[{"symbol":"XRP/USD","bids":[{"price":0.51855,"qty":2512.50000000}],"asks":[],"checksum":3683725638,"timestamp":"2024-06-01T18:07:23.266543Z"}]}
{"channel":"book","type":"update","data":[{"symbol":"XRP/USD","bids":[],"asks":[{"price":0.51866,"qty":4820.11336906}],"checksum":2044668194,"timestamp":"2024-06-01T18:07:23.273529Z"}]}
{"channel":"book","type":"update","data":[{"symbol":"XRP/USD","bids":[],"asks":[{"price":0.51866,"qty":6076.36336906}],"checksum":3683725638,"timestamp":"2024-06-01T18:07:23.592876Z"}]}
{"channel":"book","type":"update","data":[{"symbol":"XRP/USD","bids":[],"asks":[{"price":0.51866,"qty":4820.11336906}],"checksum":2044668194,"timestamp":"2024-06-01T18:07:23.651052Z"}]}
{"channel":"book","type":"update","data":[{"symbol":"XRP/USD","bids":[],"asks":[{"price":0.51866,"qty":6076.36336906}],"checksum":3683725638,"timestamp":"2024-06-01T18:07:23.802515Z"}]}
{"channel":"book","type":"update","data":[{"symbol":"XRP/USD","bids":[],"asks":[{"price":0.51866,"qty":4820.11336906}],"checksum":2044668194,"timestamp":"2024-06-01T18:07:23.814076Z"}]}
{"channel":"book","type":"update","data":[{"symbol":"XRP/USD","bids":[],"asks":[{"price":0.51867,"qty":0.00000000},{"price":0.51888,"qty":27838.73774400}],"checksum":1389456506,"timestamp":"2024-06-01T18:07:23.850541Z"}]}
{"channel":"book","type":"update","data":[{"symbol":"XRP/USD","bids":[],"asks":[{"price":0.51888,"qty":9635.00000000}],"checksum":275251273,"timestamp":"2024-06-01T18:07:23.853863Z"}]}
{"channel":"book","type":"update","data":[{"symbol":"XRP/USD","bids":[],"asks":[{"price":0.51866,"qty":6076.36336906}],"checksum":2988841005,"timestamp":"2024-06-01T18:07:23.944291Z"}]}
{"channel":"book","type":"update","data":[{"symbol":"XRP/USD","bids":[],"asks":[{"price":0.51866,"qty":4820.11336906}],"checksum":275251273,"timestamp":"2024-06-01T18:07:23.982556Z"}]}
{"channel":"book","type":"update","data":[{"symbol":"XRP/USD","bids":[],"asks":[{"price":0.51887,"qty":38.56413437}],"checksum":1824166959,"timestamp":"2024-06-01T18:07:24.016462Z"}]}
{"channel":"book","type":"update","data":[{"symbol":"XRP/USD","bids":[{"price":0.51853,"qty":1256.25000000}],"asks":[],"checksum":189103689,"timestamp":"2024-06-01T18:07:24.110639Z"}]}
{"channel":"book","type":"update","data":[{"symbol":"XRP/USD","bids":[{"price":0.51854,"qty":3400.00000000}],"asks":[],"checksum":3151530099,"timestamp":"2024-06-01T18:07:24.118471Z"}]}
{"channel":"book","type":"update","data":[{"symbol":"XRP/USD","bids":[],"asks":[{"price":0.51868,"qty":680.00000000}],"checksum":3176979751,"timestamp":"2024-06-01T18:07:24.273522Z"}]}
{"channel":"book","type":"update","data":[{"symbol":"XRP/USD","bids":[{"price":0.51854,"qty":2000.00000000}],"asks":[],"checksum":2144212686,"timestamp":"2024-06-01T18:07:24.300767Z"}]}
{"channel":"book","type":"update","data":[{"symbol":"XRP/USD","bids":[{"price":0.51856,"qty":1400.00000000}],"asks":[],"checksum":891509084,"timestamp":"2024-06-01T18:07:24.301022Z"}]}
{"channel":"book","type":"update","data":[{"symbol":"XRP/USD","bids":[{"price":0.51856,"qty":2656.25000000}],"asks":[],"checksum":1235714081,"timestamp":"2024-06-01T18:07:24.304700Z"}]}
{"channel":"book","type":"update","data":[{"symbol":"XRP/USD","bids":[{"price":0.51853,"qty":0.00000000},{"price":0.51842,"qty":5050.00000000}],"asks":[],"checksum":738010585,"timestamp":"2024-06-01T18:07:24.307757Z"}]}
{"channel":"book","type":"update","data":[{"symbol":"XRP/USD","bids":[{"price":0.51857,"qty":1256.25000000}],"asks":[],"checksum":3294529721,"timestamp":"2024-06-01T18:07:24.444786Z"}]}
{"channel":"book","type":"update","data":[{"symbol":"XRP/USD","bids":[{"price":0.51855,"qty":1256.25000000}],"asks":[],"checksum":1777511392,"timestamp":"2024-06-01T18:07:24.445030Z"}]}
{"channel":"book","type":"update","data":[{"symbol":"XRP/USD","bids":[{"price":0.51857,"qty":0.00000000},{"price":0.51842,"qty":5050.00000000}],"asks":[],"checksum":1156649634,"timestamp":"2024-06-01T18:07:24.782018Z"}]}
{"channel":"book","type":"update","data":[{"symbol":"XRP/USD","bids":[{"price":0.51857,"qty":1256.25000000}],"asks":[],"checksum":1777511392,"timestamp":"2024-06-01T18:07:24.785913Z"}]}
{"channel":"book","type":"update","data":[{"symbol":"XRP/USD","bids":[{"price":0.51857,"qty":0.00000000},{"price":0.51842,"qty":5050.00000000}],"asks":[],"checksum":1156649634,"timestamp":"2024-06-01T18:07:24.817354Z"}]}
{"channel":"book","type":"update","data":[{"symbol":"XRP/USD","bids":[{"price":0.51857,"qty":1256.25000000}],"asks":[],"checksum":1777511392,"timestamp":"2024-06-01T18:07:24.821105Z"}]}
{"channel":"book","type":"update","data":[{"symbol":"XRP/USD","bids":[{"price":0.51857,"qty":0.00000000},{"price":0.51842,"qty":5050.00000000}],"asks":[],"checksum":1156649634,"timestamp":"2024-06-01T18:07:24.933005Z"}]}
{"channel":"book","type":"update","data":[{"symbol":"XRP/USD","bids":[{"price":0.51857,"qty":1256.25000000}],"asks":[],"checksum":1777511392,"timestamp":"2024-06-01T18:07:24.936932Z"}]}
{"channel":"book","type":"update","data":[{"symbol":"XRP/USD","bids":[{"price":0.51851,"qty":0.00000000},{"price":0.51842,"qty":5050.00000000}],"asks":[],"checksum":321451407,"timestamp":"2024-06-01T18:07:25.003422Z"}]}
{"channel":"book","type":"update","data":[{"symbol":"XRP/USD","bids":[{"price":0.51847,"qty":680.00000000}],"asks":[],"checksum":885016061,"timestamp":"2024-06-01T18:07:25.003512Z"}]}
{"channel":"book","type":"update","data":[{"symbol":"XRP/USD","bids":[{"price":0.51845,"qty":105.71789412}],"asks":[],"checksum":3630893919,"timestamp":"2024-06-01T18:07:25.015748Z"}]}
{"channel":"book","type":"update","data":[{"symbol":"XRP/USD","bids":[{"price":0.51857,"qty":0.00000000},{"price":0.51842,"qty":5050.00000000}],"asks":[],"checksum":294739371,"timestamp":"2024-06-01T18:07:25.158172Z"}]}
{"channel":"book","type":"update","data":[{"symbol":"XRP/USD","bids":[{"price":0.51857,"qty":1256.25000000}],"asks":[],"checksum":3630893919,"timestamp":"2024-06-01T18:07:25.162730Z"}]}
{"channel":"book","type":"update","data":[{"symbol":"XRP/USD","bids":[{"price":0.51857,"qty":0.00000000},{"price":0.51842,"qty":5050.00000000}],"asks":[],"checksum":294739371,"timestamp":"2024-06-01T18:07:25.166064Z"}]}
{"channel":"book","type":"update","data":[{"symbol":"XRP/USD","bids":[{"price":0.51855,"qty":0.00000000},{"price":0.51841,"qty":307.17917335}],"asks":[],"checksum":2438528957,"timestamp":"2024-06-01T18:07:25.166739Z"}]}
{"channel":"book","type":"update","data":[{"symbol":"XRP/USD","bids":[{"price":0.51857,"qty":1256.25000000}],"asks":[],"checksum":1751614497,"timestamp":"2024-06-01T18:07:25.170740Z"}]}
{"channel":"book","type":"update","data":[{"symbol":"XRP/USD","bids":[{"price":0.51856,"qty":3912.50000000}],"asks":[],"checksum":3330782925,"timestamp":"2024-06-01T18:07:25.171392Z"}]}
{"channel":"book","type":"update","data":[{"symbol":"XRP/USD","bids":[{"price":0.51856,"qty":2656.25000000}],"asks":[],"checksum":1751614497,"timestamp":"2024-06-01T18:07:25.174350Z"}]}
{"channel":"book","type":"update","data":[{"symbol":"XRP/USD","bids":[{"price":0.51857,"qty":0.00000000},{"price":0.51841,"qty":307.17917335}],"asks":[],"checksum":2438528957,"timestamp":"2024-06-01T18:07:25.195808Z"}]}
{"channel":"book","type":"update","data":[{"symbol":"XRP/USD","bids":[{"price":0.51857,"qty":1256.25000000}],"asks":[],"checksum":1751614497,"timestamp":"2024-06-01T18:07:25.200935Z"}]}
{"channel":"book","type":"update","data":[{"symbol":"XRP/USD","bids":[{"price":0.51856,"qty":3912.50000000}],"asks":[],"checksum":3330782925,"timestamp":"2024-06-01T18:07:25.201088Z"}]}
{"channel":"book","type":"update","data":[{"symbol":"XRP/USD","bids":[{"price":0.51856,"qty":2656.25000000}],"asks":[],"checksum":1751614497,"timestamp":"2024-06-01T18:07:25.204485Z"}]}
{"channel":"book","type":"update","data":[{"symbol":"XRP/USD","bids":[{"price":0.51857,"qty":2512.50000000}],"asks":[],"checksum":4096582013,"timestamp":"2024-06-01T18:07:25.589438Z"}]}
{"channel":"book","type":"update","data":[{"symbol":"XRP/USD","bids":[{"price":0.51857,"qty":1256.25000000}],"asks":[],"checksum":1751614497,"timestamp":"2024-06-01T18:07:26.992212Z"}]}
{"channel":"book","type":"update","data":[{"symbol":"XRP/USD","bids":[{"price":0.51857,"qty":0.00000000},{"price":0.51841,"qty":307.17917335}],"asks":[],"checksum":2438528957,"timestamp":"2024-06-01T18:07:26.992351Z"}]}
{"channel":"book","type":"update","data":[{"symbol":"XRP/USD","bids":[{"price":0.51857,"qty":1256.25000000}],"asks":[],"checksum":1751614497,"timestamp":"2024-06-01T18:07:26.996098Z"}]}
{"channel":"book","type":"update","data":[{"symbol":"XRP/USD","bids":[{"price":0.51857,"qty":0.00000000},{"price":0.51841,"qty":307.17917335}],"asks":[],"checksum":2438528957,"timestamp":"2024-06-01T18:07:27.185587Z"}]}
{"channel":"book","type":"update","data":[{"symbol":"XRP/USD","bids":[{"price":0.51856,"qty":3912.50000000}],"asks":[],"checksum":3518717663,"timestamp":"2024-06-01T18:07:27.201665Z"}]}
{"channel":"book","type":"update","data":[{"symbol":"XRP/USD","bids":[{"price":0.51857,"qty":1256.25000000}],"asks":[],"checksum":3330782925,"timestamp":"2024-06-01T18:07:27.207733Z"}]}
{"channel":"book","type":"update","data":[{"symbol":"XRP/USD","bids":[{"price":0.51857,"qty":0.00000000},{"price":0.51841,"qty":307.17917335}],"asks":[],"checksum":3518717663,"timestamp":"2024-06-01T18:07:27.211279Z"}]}
{"channel":"book","type":"update","data":[{"symbol":"XRP/USD","bids":[{"price":0.51856,"qty":2656.25000000}],"asks":[],"checksum":2438528957,"timestamp":"2024-06-01T18:07:27.211714Z"}]}
{"channel":"book","type":"update","data":[{"symbol":"XRP/USD","bids":[{"price":0.51856,"qty":3912.50000000}],"asks":[],"checksum":3518717663,"timestamp":"2024-06-01T18:07:27.224824Z"}]}
{"channel":"book","type":"update","data":[{"symbol":"XRP/USD","bids":[{"price":0.51856,"qty":2656.25000000}],"asks":[],"checksum":2438528957,"timestamp":"2024-06-01T18:07:27.453625Z"}]}
{"channel":"book","type":"update","data":[{"symbol":"XRP/USD","bids":[{"price":0.51856,"qty":1400.00000000}],"asks":[],"checksum":3990628032,"timestamp":"2024-06-01T18:07:27.455285Z"}]}
{"channel":"book","type":"update","data":[{"symbol":"XRP/USD","bids":[{"price":0.51856,"qty":2656.25000000}],"asks":[],"checksum":2438528957,"timestamp":"2024-06-01T18:07:27.496004Z"}]}
{"channel":"book","type":"update","data":[{"symbol":"XRP/USD","bids":[{"price":0.51856,"qty":3912.50000000}],"asks":[],"checksum":3518717663,"timestamp":"2024-06-01T18:07:27.496754Z"}]}
{"channel":"book","type":"update","data":[{"symbol":"XRP/USD","bids":[{"price":0.51857,"qty":1256.25000000}],"asks":[],"checksum":3330782925,"timestamp":"2024-06-01T18:07:28.163276Z"}]}
{"channel":"book","type":"update","data":[{"symbol":"XRP/USD","bids":[{"price":0.51857,"qty":0.00000000},{"price":0.51841,"qty":307.17917335}],"asks":[],"checksum":3518717663,"timestamp":"2024-06-01T18:07:28.166846Z"}]}
{"channel":"book","type":"update","data":[{"symbol":"XRP/USD","bids":[{"price":0.51856,"qty":2656.25000000}],"asks":[],"checksum":2438528957,"timestamp":"2024-06-01T18:07:28.167016Z"}]}
{"channel":"book","type":"update","data":[{"symbol":"XRP/USD","bids":[{"price":0.51856,"qty":1400.00000000}],"asks":[],"checksum":3990628032,"timestamp":"2024-06-01T18:07:28.167291Z"}]}
{"channel":"book","type":"update","data":[{"symbol":"XRP/USD","bids":[],"asks":[{"price":0.51866,"qty":6076.36336906}],"checksum":3808394682,"timestamp":"2024-06-01T18:07:28.168870Z"}]}
{"channel":"book","type":"update","data":[{"symbol":"XRP/USD","bids":[],"asks":[{"price":0.51866,"qty":4820.11336906}],"checksum":3990628032,"timestamp":"2024-06-01T18:07:28.172081Z"}]}
{"channel":"book","type":"update","data":[{"symbol":"XRP/USD","bids":[{"price":0.51856,"qty":2656.25000000}],"asks":[],"checksum":2438528957,"timestamp":"2024-06-01T18:07:28.172594Z"}]}
{"channel":"book","type":"update","data":[{"symbol":"XRP/USD","bids":[{"price":0.51856,"qty":1400.00000000}],"asks":[],"checksum":3990628032,"timestamp":"2024-06-01T18:07:28.176796Z"}]}
{"channel":"book","type":"update","data":[{"symbol":"XRP/USD","bids":[{"price":0.51856,"qty":2656.25000000}],"asks":[],"checksum":2438528957,"timestamp":"2024-06-01T18:07:28.242315Z"}]}
{"channel":"book","type":"update","data":[{"symbol":"XRP/USD","bids":[{"price":0.51856,"qty":3912.50000000}],"asks":[],"checksum":3518717663,"timestamp":"2024-06-01T18:07:28.242358Z"}]}
{"channel":"book","type":"update","data":[{"symbol":"XRP/USD","bids":[{"price":0.51856,"qty":2656.25000000}],"asks":[],"checksum":2438528957,"timestamp":"2024-06-01T18:07:28.302476Z"}]}
{"channel":"book","type":"update","data":[{"symbol":"XRP/USD","bids":[{"price":0.51856,"qty":3912.50000000}],"asks":[],"checksum":3518717663,"timestamp":"2024-06-01T18:07:28.358645Z"}]}
{"channel":"book","type":"update","data":[{"symbol":"XRP/USD","bids":[{"price":0.51856,"qty":2656.25000000}],"asks":[],"checksum":2438528957,"timestamp":"2024-06-01T18:07:28.432442Z"}]}
{"channel":"book","type":"update","data":[{"symbol":"XRP/USD","bids":[{"price":0.51856,"qty":3912.50000000}],"asks":[],"checksum":3518717663,"timestamp":"2024-06-01T18:07:28.441592Z"}]}
{"channel":"book","type":"update","data":[{"symbol":"XRP/USD","bids":[{"price":0.51857,"qty":1256.25000000}],"asks":[],"checksum":3330782925,"timestamp":"2024-06-01T18:07:28.525076Z"}]}
{"channel":"book","type":"update","data":[{"symbol":"XRP/USD","bids":[{"price":0.51856,"qty":2656.25000000}],"asks":[],"checksum":1751614497,"timestamp":"2024-06-01T18:07:28.528517Z"}]}
{"channel":"book","type":"update","data":[{"symbol":"XRP/USD","bids":[{"price":0.51857,"qty":0.00000000},{"price":0.51841,"qty":307.17917335}],"asks":[],"checksum":2438528957,"timestamp":"2024-06-01T18:07:28.531332Z"}]}
{"channel":"book","type":"update","data":[{"symbol":"XRP/USD","bids":[{"price":0.51856,"qty":3912.50000000}],"asks":[],"checksum":3518717663,"timestamp":"2024-06-01T18:07:28.540638Z"}]}
{"channel":"book","type":"update","data":[{"symbol":"XRP/USD","bids":[{"price":0.51857,"qty":1256.25000000}],"asks":[],"checksum":3330782925,"timestamp":"2024-06-01T18:07:28.643141Z"}]}
{"channel":"book","type":"update","data":[{"symbol":"XRP/USD","bids":[{"price":0.51857,"qty":0.00000000},{"price":0.51841,"qty":307.17917335}],"asks":[],"checksum":3518717663,"timestamp":"2024-06-01T18:07:28.646565Z"}]}
{"channel":"book","type":"update","data":[{"symbol":"XRP/USD","bids":[{"price":0.51856,"qty":2656.25000000}],"asks":[],"checksum":2438528957,"timestamp":"2024-06-01T18:07:28.646837Z"}]}
{"channel":"book","type":"update","data":[{"symbol":"XRP/USD","bids":[{"price":0.51856,"qty":3912.50000000}],"asks":[],"checksum":3518717663,"timestamp":"2024-06-01T18:07:28.669126Z"}]}
{"channel":"book","type":"update","data":[{"symbol":"XRP/USD","bids":[{"price":0.51856,"qty":2656.25000000}],"asks":[],"checksum":2438528957,"timestamp":"2024-06-01T18:07:28.838242Z"}]}
{"channel":"book","type":"update","data":[{"symbol":"XRP/USD","bids":[{"price":0.51856,"qty":1400.00000000}],"asks":[],"checksum":3990628032,"timestamp":"2024-06-01T18:07:28.876981Z"}]}
{"channel":"book","type":"update","data":[{"symbol":"XRP/USD","bids":[{"price":0.51856,"qty":2656.25000000}],"asks":[],"checksum":2438528957,"timestamp":"2024-06-01T18:07:28.896064Z"}]}
{"channel":"book","type":"update","data":[{"symbol":"XRP/USD","bids":[{"price":0.51856,"qty":3912.50000000}],"asks":[],"checksum":3518717663,"timestamp":"2024-06-01T18:07:28.896243Z"}]}
{"channel":"book","type":"update","data":[{"symbol":"XRP/USD","bids":[{"price":0.51856,"qty":2656.25000000}],"asks":[],"checksum":2438528957,"timestamp":"2024-06-01T18:07:28.928491Z"}]}
{"channel":"book","type":"update","data":[{"symbol":"XRP/USD","bids":[{"price":0.51856,"qty":1400.00000000}],"asks":[],"checksum":3990628032,"timestamp":"2024-06-01T18:07:29.241591Z"}]}
{"channel":"book","type":"update","data":[{"symbol":"XRP/USD","bids":[{"price":0.51856,"qty":2656.25000000}],"asks":[],"checksum":2438528957,"timestamp":"2024-06-01T18:07:29.292319Z"}]}
{"channel":"book","type":"update","data":[{"symbol":"XRP/USD","bids":[{"price":0.51856,"qty":3912.50000000}],"asks":[],"checksum":3518717663,"timestamp":"2024-06-01T18:07:29.528198Z"}]}
{"channel":"book","type":"update","data":[{"symbol":"XRP/USD","bids":[{"price":0.51857,"qty":1256.25000000}],"asks":[],"checksum":3330782925,"timestamp":"2024-06-01T18:07:29.559738Z"}]}
{"channel":"book","type":"update","data":[{"symbol":"XRP/USD","bids":[{"price":0.51856,"qty":2656.25000000}],"asks":[],"checksum":1751614497,"timestamp":"2024-06-01T18:07:29.563181Z"}]}
{"channel":"book","type":"update","data":[{"symbol":"XRP/USD","bids":[{"price":0.51857,"qty":0.00000000},{"price":0.51841,"qty":307.17917335}],"asks":[],"checksum":2438528957,"timestamp":"2024-06-01T18:07:29.563801Z"}]}
{"channel":"book","type":"update","data":[{"symbol":"XRP/USD","bids":[{"price":0.51857,"qty":1256.25000000}],"asks":[],"checksum":1751614497,"timestamp":"2024-06-01T18:07:29.567917Z"}]}
{"channel":"book","type":"update","data":[{"symbol":"XRP/USD","bids":[{"price":0.51857,"qty":0.00000000},{"price":0.51841,"qty":307.17917335}],"asks":[],"checksum":2438528957,"timestamp":"2024-06-01T18:07:29.571443Z"}]}
{"channel":"book","type":"update","data":[{"symbol":"XRP/USD","bids":[{"price":0.51856,"qty":3912.50000000}],"asks":[],"checksum":3518717663,"timestamp":"2024-06-01T18:07:29.583344Z"}]}
{"channel":"book","type":"update","data":[{"symbol":"XRP/USD","bids":[{"price":0.51857,"qty":1256.25000000}],"asks":[],"checksum":3330782925,"timestamp":"2024-06-01T18:07:29.723581Z"}]}
{"channel":"book","type":"update","data":[{"symbol":"XRP/USD","bids":[{"price":0.51856,"qty":2656.25000000}],"asks":[],"checksum":1751614497,"timestamp":"2024-06-01T18:07:29.727018Z"}]}
{"channel":"book","type":"update","data":[{"symbol":"XRP/USD","bids":[{"price":0.51857,"qty":0.00000000},{"price":0.51841,"qty":307.17917335}],"asks":[],"checksum":2438528957,"timestamp":"2024-06-01T18:07:29.743178Z"}]}
{"channel":"book","type":"update","data":[{"symbol":"XRP/USD","bids":[{"price":0.51857,"qty":1256.25000000}],"asks":[],"checksum":1751614497,"timestamp":"2024-06-01T18:07:29.746822Z"}]}
{"channel":"book","type":"update","data":[{"symbol":"XRP/USD","bids":[{"price":0.51856,"qty":3912.50000000}],"asks":[],"checksum":3330782925,"timestamp":"2024-06-01T18:07:29.748405Z"}]}
{"channel":"book","type":"update","data":[{"symbol":"XRP/USD","bids":[{"price":0.51857,"qty":0.00000000},{"price":0.51841,"qty":307.17917335}],"asks":[],"checksum":3518717663,"timestamp":"2024-06-01T18:07:29.823850Z"}]}
{"channel":"book","type":"update","data":[{"symbol":"XRP/USD","bids":[{"price":0.51856,"qty":2656.25000000}],"asks":[],"checksum":2438528957,"timestamp":"2024-06-01T18:07:29.827376Z"}]}
{"channel":"book","type":"update","data":[{"symbol":"XRP/USD","bids":[{"price":0.51857,"qty":1256.25000000}],"asks":[],"checksum":1751614497,"timestamp":"2024-06-01T18:07:29.828673Z"}]}
{"channel":"book","type":"update","data":[{"symbol":"XRP/USD","bids":[{"price":0.51856,"qty":3912.50000000}],"asks":[],"checksum":3330782925,"timestamp":"2024-06-01T18:07:29.830079Z"}]}
{"channel":"book","type":"update","data":[{"symbol":"XRP/USD","bids":[{"price":0.51856,"qty":2656.25000000}],"asks":[],"checksum":1751614497,"timestamp":"2024-06-01T18:07:29.832596Z"}]}
{"channel":"book","type":"update","data":[{"symbol":"XRP/USD","bids":[{"price":0.51857,"qty":0.00000000},{"price":0.51841,"qty":307.17917335}],"asks":[],"checksum":2438528957,"timestamp":"2024-06-01T18:07:29.943129Z"}]}
{"channel":"book","type":"update","data":[{"symbol":"XRP/USD","bids":[{"price":0.51856,"qty":3912.50000000}],"asks":[],"checksum":3518717663,"timestamp":"2024-06-01T18:07:29.949044Z"}]}
{"channel":"book","type":"update","data":[{"symbol":"XRP/USD","bids":[{"price":0.51857,"qty":1256.25000000}],"asks":[],"checksum":3330782925,"timestamp":"2024-06-01T18:07:29.949598Z"}]}
{"channel":"book","type":"update","data":[{"symbol":"XRP/USD","bids":[{"price":0.51856,"qty":2656.25000000}],"asks":[],"checksum":1751614497,"timestamp":"2024-06-01T18:07:29.953129Z"}]}
{"channel":"book","type":"update","data":[{"symbol":"XRP/USD","bids":[{"price":0.51857,"qty":0.00000000},{"price":0.51841,"qty":307.17917335}],"asks":[],"checksum":2438528957,"timestamp":"2024-06-01T18:07:29.953483Z"}]}
{"channel":"book","type":"update","data":[{"symbol":"XRP/USD","bids":[{"price":0.51857,"qty":1256.25000000}],"asks":[],"checksum":1751614497,"timestamp":"2024-06-01T18:07:29.957355Z"}]}
{"channel":"book","type":"update","data":[{"symbol":"XRP/USD","bids":[{"price":0.51856,"qty":3912.50000000}],"asks":[],"checksum":3330782925,"timestamp":"2024-06-01T18:07:29.958473Z"}]}
{"channel":"book","type":"update","data":[{"symbol":"XRP/USD","bids":[{"price":0.51856,"qty":2656.25000000}],"asks":[],"checksum":1751614497,"timestamp":"2024-06-01T18:07:29.961016Z"}]}
{"channel":"book","type":"update","data":[{"symbol":"XRP/USD","bids":[{"price":0.51857,"qty":0.00000000},{"price":0.51841,"qty":307.17917335}],"asks":[],"checksum":2438528957,"timestamp":"2024-06-01T18:07:29.962176Z"}]}
{"channel":"book","type":"update","data":[{"symbol":"XRP/USD","bids":[{"price":0.51857,"qty":1256.25000000}],"asks":[],"checksum":1751614497,"timestamp":"2024-06-01T18:07:29.966103Z"}]}
{"channel":"book","type":"update","data":[{"symbol":"XRP/USD","bids":[{"price":0.51857,"qty":0.00000000},{"price":0.51841,"qty":307.17917335}],"asks":[],"checksum":2438528957,"timestamp":"2024-06-01T18:07:30.043751Z"}]}
{"channel":"book","type":"update","data":[{"symbol":"XRP/USD","bids":[{"price":0.51856,"qty":3912.50000000}],"asks":[],"checksum":3518717663,"timestamp":"2024-06-01T18:07:30.050056Z"}]}
{"channel":"book","type":"update","data":[{"symbol":"XRP/USD","bids":[{"price":0.51857,"qty":1256.25000000}],"asks":[],"checksum":3330782925,"timestamp":"2024-06-01T18:07:30.186672Z"}]}
{"channel":"book","type":"update","data":[{"symbol":"XRP/USD","bids":[{"price":0.51856,"qty":2656.25000000}],"asks":[],"checksum":1751614497,"timestamp":"2024-06-01T18:07:30.190649Z"}]}
{"channel":"book","type":"update","data":[{"symbol":"XRP/USD","bids":[{"price":0.51857,"qty":0.00000000},{"price":0.51841,"qty":307.17917335}],"asks":[],"checksum":2438528957,"timestamp":"2024-06-01T18:07:30.344056Z"}]}
{"channel":"book","type":"update","data":[{"symbol":"XRP/USD","bids":[{"price":0.51856,"qty":3912.50000000}],"asks":[],"checksum":3518717663,"timestamp":"2024-06-01T18:07:30.352443Z"}]}
{"channel":"book","type":"update","data":[{"symbol":"XRP/USD","bids":[{"price":0.51847,"qty":0.00000000},{"price":0.51840,"qty":18057.36855241}],"asks":[],"checksum":3075566220,"timestamp":"2024-06-01T18:07:30.354041Z"}]}
{"channel":"book","type":"update","data":[{"symbol":"XRP/USD","bids":[{"price":0.51857,"qty":1256.25000000}],"asks":[],"checksum":2997917355,"timestamp":"2024-06-01T18:07:30.354207Z"}]}
{"channel":"book","type":"update","data":[{"symbol":"XRP/USD","bids":[{"price":0.51856,"qty":2656.25000000}],"asks":[],"checksum":475046983,"timestamp":"2024-06-01T18:07:30.357868Z"}]}
{"channel":"book","type":"update","data":[{"symbol":"XRP/USD","bids":[{"price":0.51857,"qty":0.00000000},{"price":0.51840,"qty":18057.36855241}],"asks":[],"checksum":1095479348,"timestamp":"2024-06-01T18:07:30.357953Z"}]}
{"channel":"book","type":"update","data":[{"symbol":"XRP/USD","bids":[{"price":0.51857,"qty":1256.25000000}],"asks":[],"checksum":475046983,"timestamp":"2024-06-01T18:07:30.361645Z"}]}
{"channel":"book","type":"update","data":[{"symbol":"XRP/USD","bids":[{"price":0.51856,"qty":3912.50000000}],"asks":[],"checksum":2997917355,"timestamp":"2024-06-01T18:07:30.364398Z"}]}
{"channel":"book","type":"update","data":[{"symbol":"XRP/USD","bids":[{"price":0.51857,"qty":0.00000000},{"price":0.51840,"qty":18057.36855241}],"asks":[],"checksum":3075566220,"timestamp":"2024-06-01T18:07:30.368268Z"}]}
{"channel":"book","type":"update","data":[{"symbol":"XRP/USD","bids":[{"price":0.51856,"qty":2656.25000000}],"asks":[],"checksum":1095479348,"timestamp":"2024-06-01T18:07:30.371760Z"}]}
{"channel":"book","type":"update","data":[{"symbol":"XRP/USD","bids":[{"price":0.51856,"qty":3912.50000000}],"asks":[],"checksum":3075566220,"timestamp":"2024-06-01T18:07:30.375211Z"}]}
{"channel":"book","type":"update","data":[{"symbol":"XRP/USD","bids":[{"price":0.51857,"qty":1256.25000000}],"asks":[],"checksum":2997917355,"timestamp":"2024-06-01T18:07:30.407072Z"}]}
{"channel":"book","type":"update","data":[{"symbol":"XRP/USD","bids":[{"price":0.51856,"qty":2656.25000000}],"asks":[],"checksum":475046983,"timestamp":"2024-06-01T18:07:30.410822Z"}]}
{"channel":"book","type":"update","data":[{"symbol":"XRP/USD","bids":[{"price":0.51857,"qty":0.00000000},{"price":0.51840,"qty":18057.36855241}],"asks":[],"checksum":1095479348,"timestamp":"2024-06-01T18:07:30.411403Z"}]}
{"channel":"book","type":"update","data":[{"symbol":"XRP/USD","bids":[{"price":0.51846,"qty":680.00000000}],"asks":[],"checksum":4147838481,"timestamp":"2024-06-01T18:07:30.413866Z"}]}
{"channel":"book","type":"update","data":[{"symbol":"XRP/USD","bids":[{"price":0.51856,"qty":3912.50000000}],"asks":[],"checksum":3084476275,"timestamp":"2024-06-01T18:07:30.417365Z"}]}
{"channel":"book","type":"update","data":[{"symbol":"XRP/USD","bids":[{"price":0.51857,"qty":1256.25000000}],"asks":[],"checksum":2373894556,"timestamp":"2024-06-01T18:07:30.538298Z"}]}
{"channel":"book","type":"update","data":[{"symbol":"XRP/USD","bids":[],"asks":[{"price":0.51868,"qty":0.00000000},{"price":0.51888,"qty":9635.00000000}],"checksum":477398115,"timestamp":"2024-06-01T18:07:30.543859Z"}]}
{"channel":"book","type":"update","data":[{"symbol":"XRP/USD","bids":[],"asks":[{"price":0.51866,"qty":5500.11336906}],"checksum":1743201865,"timestamp":"2024-06-01T18:07:30.659625Z"}]}
{"channel":"book","type":"update","data":[{"symbol":"XRP/USD","bids":[{"price":0.51846,"qty":0.00000000},{"price":0.51841,"qty":307.17917335}],"asks":[],"checksum":1479111038,"timestamp":"2024-06-01T18:07:30.811261Z"}]}
{"channel":"book","type":"update","data":[{"symbol":"XRP/USD","bids":[{"price":0.51846,"qty":680.00000000}],"asks":[],"checksum":1743201865,"timestamp":"2024-06-01T18:07:30.947350Z"}]}
{"channel":"book","type":"update","data":[{"symbol":"XRP/USD","bids":[],"asks":[{"price":0.51874,"qty":0.00000000},{"price":0.51889,"qty":23884.88327097}],"checksum":3007886315,"timestamp":"2024-06-01T18:07:31.746159Z"}]}
{"channel":"book","type":"update","data":[{"symbol":"XRP/USD","bids":[{"price":0.51846,"qty":0.00000000},{"price":0.51841,"qty":307.17917335},{"price":0.51849,"qty":2051.59300000}],"asks":[],"checksum":196969979,"timestamp":"2024-06-01T18:07:31.808744Z"}]}
{"channel":"book","type":"update","data":[{"symbol":"XRP/USD","bids":[],"asks":[{"price":0.51866,"qty":4820.11336906},{"price":0.51870,"qty":680.00000000}],"checksum":1098012476,"timestamp":"2024-06-01T18:07:31.812129Z"}]}
{"channel":"book","type":"update","data":[{"symbol":"XRP/USD","bids":[{"price":0.51849,"qty":2731.59300000}],"asks":[],"checksum":324707786,"timestamp":"2024-06-01T18:07:31.812168Z"}]}
{"channel":"book","type":"update","data":[{"symbol":"XRP/USD","bids":[],"asks":[{"price":0.51870,"qty":1360.00000000}],"checksum":2326598657,"timestamp":"2024-06-01T18:07:31.812236Z"}]}
{"channel":"book","type":"update","data":[{"symbol":"XRP/USD","bids":[],"asks":[{"price":0.51870,"qty":680.00000000}],"checksum":324707786,"timestamp":"2024-06-01T18:07:31.830781Z"}]}
{"channel":"book","type":"update","data":[{"symbol":"XRP/USD","bids":[],"asks":[{"price":0.51870,"qty":0.00000000},{"price":0.51889,"qty":23884.88327097}],"checksum":2186620281,"timestamp":"2024-06-01T18:07:31.834454Z"}]}
{"channel":"book","type":"update","data":[{"symbol":"XRP/USD","bids":[{"price":0.51844,"qty":53161.21058165}],"asks":[],"checksum":3936538666,"timestamp":"2024-06-01T18:07:31.908902Z"}]}
{"channel":"book","type":"update","data":[{"symbol":"XRP/USD","bids":[{"price":0.51856,"qty":2512.50000000}],"asks":[],"checksum":3317390519,"timestamp":"2024-06-01T18:07:31.917249Z"}]}
{"channel":"book","type":"update","data":[{"symbol":"XRP/USD","bids":[{"price":0.51858,"qty":1400.00000000}],"asks":[],"checksum":1155771747,"timestamp":"2024-06-01T18:07:31.917474Z"}]}
{"channel":"book","type":"update","data":[{"symbol":"XRP/USD","bids":[{"price":0.51860,"qty":1256.25000000}],"asks":[],"checksum":1452932233,"timestamp":"2024-06-01T18:07:31.921044Z"}]}
{"channel":"book","type":"update","data":[{"symbol":"XRP/USD","bids":[{"price":0.51856,"qty":1256.25000000}],"asks":[],"checksum":1169718119,"timestamp":"2024-06-01T18:07:31.921597Z"}]}
{"channel":"book","type":"update","data":[{"symbol":"XRP/USD","bids":[{"price":0.51862,"qty":1256.25000000}],"asks":[],"checksum":279122964,"timestamp":"2024-06-01T18:07:31.922965Z"}]}
{"channel":"book","type":"update","data":[{"symbol":"XRP/USD","bids":[{"price":0.51857,"qty":0.00000000},{"price":0.51843,"qty":2512.50000000}],"asks":[],"checksum":3811077769,"timestamp":"2024-06-01T18:07:31.926961Z"}]}
{"channel":"book","type":"update","data":[{"symbol":"XRP/USD","bids":[{"price":0.51860,"qty":0.00000000},{"price":0.51842,"qty":5050.00000000}],"asks":[],"checksum":3176693262,"timestamp":"2024-06-01T18:07:31.927082Z"}]}
{"channel":"book","type":"update","data":[{"symbol":"XRP/USD","bids":[{"price":0.51862,"qty":2512.50000000}],"asks":[],"checksum":2525914570,"timestamp":"2024-06-01T18:07:31.927090Z"}]}
{"channel":"book","type":"update","data":[{"symbol":"XRP/USD","bids":[],"asks":[{"price":0.51866,"qty":0.00000000},{"price":0.51890,"qty":8901.27241272}],"checksum":328766603,"timestamp":"2024-06-01T18:07:31.990422Z"}]}
