{"channel":"book","type":"snapshot","data":[{"symbol":"XRP/USDT","bids":[{"price":0.51899,"qty":815.62500000},{"price":0.51898,"qty":9642.40488941},{"price":0.51897,"qty":470.00000000},{"price":0.51894,"qty":9643.15646714},{"price":0.51893,"qty":407.81250000},{"price":0.51889,"qty":3000.00000000},{"price":0.51885,"qty":407.81250000},{"price":0.51884,"qty":800.00000000},{"price":0.51883,"qty":374.29601420},{"price":0.51882,"qty":38.56374841}],"asks":[{"price":0.51911,"qty":407.81250000},{"price":0.51912,"qty":877.81250000},{"price":0.51916,"qty":10046.96645139},{"price":0.51922,"qty":407.81250000},{"price":0.51925,"qty":9637.38728367},{"price":0.51926,"qty":6011.74580865},{"price":0.51928,"qty":407.81250000},{"price":0.51931,"qty":1582.65411094},{"price":0.51932,"qty":1283.40000000},{"price":0.51936,"qty":782.10851420}],"checksum":785137783}]}
{"channel":"book","type":"update","data":[{"symbol":"XRP/USDT","bids":[{"price":0.51899,"qty":407.81250000}],"asks":[],"checksum":2960310008,"timestamp":"2024-06-01T18:06:59.283032Z"}]}
{"channel":"book","type":"update","data":[{"symbol":"XRP/USDT","bids":[{"price":0.51899,"qty":0.00000000},{"price":0.51881,"qty":9645.41687087}],"asks":[],"checksum":1123282419,"timestamp":"2024-06-01T18:06:59.589280Z"}]}
{"channel":"book","type":"update","data":[{"symbol":"XRP/USDT","bids":[],"asks":[{"price":0.51912,"qty":10517.68212008}],"checksum":3719916835,"timestamp":"2024-06-01T18:06:59.973454Z"}]}
{"channel":"book","type":"update","data":[{"symbol":"XRP/USDT","bids":[{"price":0.51901,"qty":9641.81415823}],"asks":[],"checksum":715884189,"timestamp":"2024-06-01T18:06:59.973515Z"}]}
{"channel":"book","type":"update","data":[{"symbol":"XRP/USDT","bids":[],"asks":[{"price":0.51911,"qty":0.00000000},{"price":0.51937,"qty":9635.19216179}],"checksum":3272002849,"timestamp":"2024-06-01T18:07:00.234859Z"}]}
{"channel":"book","type":"update","data":[{"symbol":"XRP/USDT","bids":[],"asks":[{"price":0.51911,"qty":407.81250000}],"checksum":715884189,"timestamp":"2024-06-01T18:07:00.247311Z"}]}
{"channel":"book","type":"update","data":[{"symbol":"XRP/USDT","bids":[{"price":0.51901,"qty":0.00000000},{"price":0.51881,"qty":9645.41687087}],"asks":[],"checksum":3719916835,"timestamp":"2024-06-01T18:07:00.248743Z"}]}
{"channel":"book","type":"update","data":[{"symbol":"XRP/USDT","bids":[],"asks":[{"price":0.51912,"qty":877.81250000}],"checksum":1123282419,"timestamp":"2024-06-01T18:07:00.248807Z"}]}
{"channel":"book","type":"update","data":[{"symbol":"XRP/USDT","bids":[{"price":0.51899,"qty":407.81250000}],"asks":[],"checksum":2960310008,"timestamp":"2024-06-01T18:07:00.252529Z"}]}
{"channel":"book","type":"update","data":[{"symbol":"XRP/USDT","bids":[{"price":0.51899,"qty":815.62500000}],"asks":[],"checksum":785137783,"timestamp":"2024-06-01T18:07:00.254325Z"}]}
{"channel":"book","type":"update","data":[{"symbol":"XRP/USDT","bids":[{"price":0.51899,"qty":407.81250000}],"asks":[],"checksum":2960310008,"timestamp":"2024-06-01T18:07:00.440470Z"}]}
{"channel":"book","type":"update","data":[{"symbol":"XRP/USDT","bids":[{"price":0.51899,"qty":0.00000000},{"price":0.51881,"qty":9645.41687087}],"asks":[],"checksum":1123282419,"timestamp":"2024-06-01T18:07:00.463548Z"}]}
{"channel":"book","type":"update","data":[{"symbol":"XRP/USDT","bids":[{"price":0.51882,"qty":0.00000000},{"price":0.51880,"qty":3432.83600310}],"asks":[],"checksum":3094241775,"timestamp":"2024-06-01T18:07:00.672990Z"}]}
{"channel":"book","type":"update","data":[{"symbol":"XRP/USDT","bids":[{"price":0.51898,"qty":0.00000000},{"price":0.51879,"qty":1609.38099461}],"asks":[],"checksum":1552160996,"timestamp":"2024-06-01T18:07:00.770536Z"}]}
{"channel":"book","type":"update","data":[{"symbol":"XRP/USDT","bids":[],"asks":[{"price":0.51912,"qty":10517.67945933}],"checksum":1435553251,"timestamp":"2024-06-01T18:07:00.776117Z"}]}
{"channel":"book","type":"update","data":[{"symbol":"XRP/USDT","bids":[{"price":0.51898,"qty":9642.42080581}],"asks":[],"checksum":3656588357,"timestamp":"2024-06-01T18:07:00.776191Z"}]}
{"channel":"book","type":"update","data":[{"symbol":"XRP/USDT","bids":[{"price":0.51889,"qty":12644.07692770}],"asks":[],"checksum":1207298298,"timestamp":"2024-06-01T18:07:00.776300Z"}]}
{"channel":"book","type":"update","data":[{"symbol":"XRP/USDT","bids":[{"price":0.51898,"qty":0.00000000},{"price":0.51879,"qty":1609.38099461}],"asks":[],"checksum":2409883122,"timestamp":"2024-06-01T18:07:00.781239Z"}]}
{"channel":"book","type":"update","data":[{"symbol":"XRP/USDT","bids":[],"asks":[{"price":0.51916,"qty":407.81250000}],"checksum":3747205486,"timestamp":"2024-06-01T18:07:01.159737Z"}]}
{"channel":"book","type":"update","data":[{"symbol":"XRP/USDT","bids":[{"price":0.51897,"qty":0.00000000},{"price":0.51874,"qty":407.81250000}],"asks":[],"checksum":961638300,"timestamp":"2024-06-01T18:07:01.876316Z"}]}
{"channel":"book","type":"update","data":[{"symbol":"XRP/USDT","bids":[],"asks":[{"price":0.51925,"qty":0.00000000},{"price":0.51937,"qty":9635.19216179}],"checksum":3026960072,"timestamp":"2024-06-01T18:07:01.878232Z"}]}
{"channel":"book","type":"update","data":[{"symbol":"XRP/USDT","bids":[{"price":0.51893,"qty":0.00000000},{"price":0.51873,"qty":4295.14580865}],"asks":[],"checksum":2210162691,"timestamp":"2024-06-01T18:07:01.881001Z"}]}
{"channel":"book","type":"update","data":[{"symbol":"XRP/USDT","bids":[],"asks":[{"price":0.51910,"qty":9640.33677508}],"checksum":1541985407,"timestamp":"2024-06-01T18:07:01.882368Z"}]}
{"channel":"book","type":"update","data":[{"symbol":"XRP/USDT","bids":[{"price":0.51895,"qty":9642.97497458}],"asks":[],"checksum":3390430557,"timestamp":"2024-06-01T18:07:01.882390Z"}]}
{"channel":"book","type":"update","data":[{"symbol":"XRP/USDT","bids":[],"asks":[{"price":0.51920,"qty":9638.34377607}],"checksum":1602226880,"timestamp":"2024-06-01T18:07:01.882412Z"}]}
{"channel":"book","type":"update","data":[{"symbol":"XRP/USDT","bids":[{"price":0.51894,"qty":10113.15646714}],"asks":[],"checksum":2741671530,"timestamp":"2024-06-01T18:07:01.884324Z"}]}
{"channel":"book","type":"update","data":[{"symbol":"XRP/USDT","bids":[],"asks":[{"price":0.51912,"qty":10047.67945933}],"checksum":241622007,"timestamp":"2024-06-01T18:07:01.885613Z"}]}
{"channel":"book","type":"update","data":[{"symbol":"XRP/USDT","bids":[],"asks":[{"price":0.51909,"qty":470.00000000}],"checksum":2368446877,"timestamp":"2024-06-01T18:07:01.885818Z"}]}
{"channel":"book","type":"update","data":[{"symbol":"XRP/USDT","bids":[],"asks":[{"price":0.51906,"qty":407.81250000}],"checksum":2489174922,"timestamp":"2024-06-01T18:07:01.886752Z"}]}
{"channel":"book","type":"update","data":[{"symbol":"XRP/USDT","bids":[],"asks":[{"price":0.51912,"qty":9639.86695933}],"checksum":1654073346,"timestamp":"2024-06-01T18:07:01.886811Z"}]}
{"channel":"book","type":"update","data":[{"symbol":"XRP/USDT","bids":[],"asks":[{"price":0.51908,"qty":407.81250000}],"checksum":3115326573,"timestamp":"2024-06-01T18:07:01.886909Z"}]}
{"channel":"book","type":"update","data":[{"symbol":"XRP/USDT","bids":[{"price":0.51895,"qty":0.00000000},{"price":0.51873,"qty":4295.14580865}],"asks":[],"checksum":1698637039,"timestamp":"2024-06-01T18:07:01.887097Z"}]}
{"channel":"book","type":"update","data":[{"symbol":"XRP/USDT","bids":[],"asks":[{"price":0.51908,"qty":0.00000000},{"price":0.51928,"qty":407.81250000}],"checksum":3189248128,"timestamp":"2024-06-01T18:07:01.890344Z"}]}
{"channel":"book","type":"update","data":[{"symbol":"XRP/USDT","bids":[],"asks":[{"price":0.51906,"qty":815.62500000}],"checksum":2861030416,"timestamp":"2024-06-01T18:07:01.890680Z"}]}
{"channel":"book","type":"update","data":[{"symbol":"XRP/USDT","bids":[],"asks":[{"price":0.51911,"qty":0.00000000},{"price":0.51931,"qty":1582.65411094}],"checksum":1343203816,"timestamp":"2024-06-01T18:07:01.891039Z"}]}
{"channel":"book","type":"update","data":[{"symbol":"XRP/USDT","bids":[{"price":0.51894,"qty":470.00000000}],"asks":[],"checksum":380738580,"timestamp":"2024-06-01T18:07:02.389309Z"}]}
{"channel":"book","type":"update","data":[{"symbol":"XRP/USDT","bids":[{"price":0.51890,"qty":470.00000000}],"asks":[],"checksum":1703677020,"timestamp":"2024-06-01T18:07:02.392014Z"}]}
{"channel":"book","type":"update","data":[{"symbol":"XRP/USDT","bids":[{"price":0.51894,"qty":0.00000000},{"price":0.51873,"qty":4295.14580865}],"asks":[],"checksum":495220454,"timestamp":"2024-06-01T18:07:02.392111Z"}]}
{"channel":"book","type":"update","data":[{"symbol":"XRP/USDT","bids":[{"price":0.51898,"qty":9642.39533759}],"asks":[],"checksum":10463767,"timestamp":"2024-06-01T18:07:02.392948Z"}]}
{"channel":"book","type":"update","data":[{"symbol":"XRP/USDT","bids":[{"price":0.51895,"qty":9642.97530435}],"asks":[],"checksum":1236708495,"timestamp":"2024-06-01T18:07:02.392994Z"}]}
{"channel":"book","type":"update","data":[{"symbol":"XRP/USDT","bids":[{"price":0.51880,"qty":1336.07806000}],"asks":[],"checksum":2267844522,"timestamp":"2024-06-01T18:07:02.397278Z"}]}
{"channel":"book","type":"update","data":[{"symbol":"XRP/USDT","bids":[{"price":0.51892,"qty":407.81250000}],"asks":[],"checksum":1408701171,"timestamp":"2024-06-01T18:07:02.398732Z"}]}
{"channel":"book","type":"update","data":[{"symbol":"XRP/USDT","bids":[{"price":0.51880,"qty":3308.83600310}],"asks":[],"checksum":3215942383,"timestamp":"2024-06-01T18:07:02.402789Z"}]}
{"channel":"book","type":"update","data":[{"symbol":"XRP/USDT","bids":[],"asks":[{"price":0.51910,"qty":0.00000000},{"price":0.51932,"qty":1283.40000000}],"checksum":3280422639,"timestamp":"2024-06-01T18:07:03.032059Z"}]}
{"channel":"book","type":"update","data":[{"symbol":"XRP/USDT","bids":[],"asks":[{"price":0.51909,"qty":10110.39498062}],"checksum":1606405123,"timestamp":"2024-06-01T18:07:03.035602Z"}]}
{"channel":"book","type":"update","data":[{"symbol":"XRP/USDT","bids":[],"asks":[{"price":0.51906,"qty":407.81250000}],"checksum":2946809995,"timestamp":"2024-06-01T18:07:03.387861Z"}]}
{"channel":"book","type":"update","data":[{"symbol":"XRP/USDT","bids":[],"asks":[{"price":0.51906,"qty":0.00000000},{"price":0.51936,"qty":782.10851420}],"checksum":1562897676,"timestamp":"2024-06-01T18:07:03.387892Z"}]}
{"channel":"book","type":"update","data":[{"symbol":"XRP/USDT","bids":[],"asks":[{"price":0.51907,"qty":407.81250000}],"checksum":1752107801,"timestamp":"2024-06-01T18:07:03.392244Z"}]}
{"channel":"book","type":"update","data":[{"symbol":"XRP/USDT","bids":[],"asks":[{"price":0.51908,"qty":407.81250000}],"checksum":3799967909,"timestamp":"2024-06-01T18:07:03.392332Z"}]}
{"channel":"book","type":"update","data":[{"symbol":"XRP/USDT","bids":[],"asks":[{"price":0.51909,"qty":470.00000000}],"checksum":1907528607,"timestamp":"2024-06-01T18:07:03.638643Z"}]}
{"channel":"book","type":"update","data":[{"symbol":"XRP/USDT","bids":[{"price":0.51898,"qty":0.00000000},{"price":0.51879,"qty":1609.38099461}],"asks":[],"checksum":3420777012,"timestamp":"2024-06-01T18:07:03.638758Z"}]}
{"channel":"book","type":"update","data":[{"symbol":"XRP/USDT","bids":[],"asks":[{"price":0.51911,"qty":9640.02671041}],"checksum":850426606,"timestamp":"2024-06-01T18:07:03.643177Z"}]}
{"channel":"book","type":"update","data":[{"symbol":"XRP/USDT","bids":[{"price":0.51899,"qty":9642.08520671}],"asks":[],"checksum":952744307,"timestamp":"2024-06-01T18:07:03.643220Z"}]}
{"channel":"book","type":"update","data":[{"symbol":"XRP/USDT","bids":[],"asks":[{"price":0.51912,"qty":0.00000000},{"price":0.51931,"qty":1582.65411094}],"checksum":3599733374,"timestamp":"2024-06-01T18:07:03.709625Z"}]}
{"channel":"book","type":"update","data":[{"symbol":"XRP/USDT","bids":[],"asks":[{"price":0.51915,"qty":9639.27940480}],"checksum":3101277069,"timestamp":"2024-06-01T18:07:03.713609Z"}]}
{"channel":"book","type":"update","data":[{"symbol":"XRP/USDT","bids":[],"asks":[{"price":0.51907,"qty":0.00000000},{"price":0.51931,"qty":1582.65411094}],"checksum":1226504486,"timestamp":"2024-06-01T18:07:03.791794Z"}]}
{"channel":"book","type":"update","data":[{"symbol":"XRP/USDT","bids":[],"asks":[{"price":0.51908,"qty":815.62500000}],"checksum":3616155194,"timestamp":"2024-06-01T18:07:03.795164Z"}]}
{"channel":"book","type":"update","data":[{"symbol":"XRP/USDT","bids":[],"asks":[{"price":0.51908,"qty":407.81250000}],"checksum":1226504486,"timestamp":"2024-06-01T18:07:03.796041Z"}]}
{"channel":"book","type":"update","data":[{"symbol":"XRP/USDT","bids":[],"asks":[{"price":0.51908,"qty":815.62500000}],"checksum":3616155194,"timestamp":"2024-06-01T18:07:03.805636Z"}]}
{"channel":"book","type":"update","data":[{"symbol":"XRP/USDT","bids":[],"asks":[{"price":0.51911,"qty":0.00000000},{"price":0.51932,"qty":1283.40000000}],"checksum":1847832905,"timestamp":"2024-06-01T18:07:03.819463Z"}]}
{"channel":"book","type":"update","data":[{"symbol":"XRP/USDT","bids":[{"price":0.51895,"qty":0.00000000},{"price":0.51879,"qty":1609.38099461}],"asks":[],"checksum":3265238037,"timestamp":"2024-06-01T18:07:03.819582Z"}]}
{"channel":"book","type":"update","data":[{"symbol":"XRP/USDT","bids":[],"asks":[{"price":0.51909,"qty":0.00000000},{"price":0.51936,"qty":782.10851420}],"checksum":887682272,"timestamp":"2024-06-01T18:07:03.822351Z"}]}
{"channel":"book","type":"update","data":[{"symbol":"XRP/USDT","bids":[],"asks":[{"price":0.51914,"qty":470.00000000}],"checksum":801379093,"timestamp":"2024-06-01T18:07:03.822414Z"}]}
{"channel":"book","type":"update","data":[{"symbol":"XRP/USDT","bids":[],"asks":[{"price":0.51913,"qty":9639.79244779}],"checksum":3089041529,"timestamp":"2024-06-01T18:07:04.972327Z"}]}
{"channel":"book","type":"update","data":[{"symbol":"XRP/USDT","bids":[{"price":0.51901,"qty":9641.85089407}],"asks":[],"checksum":2836523438,"timestamp":"2024-06-01T18:07:04.972424Z"}]}
{"channel":"book","type":"update","data":[{"symbol":"XRP/USDT","bids":[],"asks":[{"price":0.51914,"qty":0.00000000},{"price":0.51932,"qty":1283.40000000}],"checksum":3810594729,"timestamp":"2024-06-01T18:07:04.974955Z"}]}
{"channel":"book","type":"update","data":[{"symbol":"XRP/USDT","bids":[],"asks":[{"price":0.51912,"qty":470.00000000}],"checksum":1369998568,"timestamp":"2024-06-01T18:07:04.975202Z"}]}
{"channel":"book","type":"update","data":[{"symbol":"XRP/USDT","bids":[],"asks":[{"price":0.51908,"qty":407.81250000}],"checksum":3476577268,"timestamp":"2024-06-01T18:07:04.976587Z"}]}
{"channel":"book","type":"update","data":[{"symbol":"XRP/USDT","bids":[],"asks":[{"price":0.51908,"qty":815.62500000}],"checksum":1369998568,"timestamp":"2024-06-01T18:07:04.980140Z"}]}
{"channel":"book","type":"update","data":[{"symbol":"XRP/USDT","bids":[],"asks":[{"price":0.51908,"qty":407.81250000}],"checksum":3476577268,"timestamp":"2024-06-01T18:07:05.670076Z"}]}
{"channel":"book","type":"update","data":[{"symbol":"XRP/USDT","bids":[],"asks":[{"price":0.51908,"qty":0.00000000},{"price":0.51932,"qty":1283.40000000}],"checksum":1858743905,"timestamp":"2024-06-01T18:07:05.670496Z"}]}
{"channel":"book","type":"update","data":[{"symbol":"XRP/USDT","bids":[],"asks":[{"price":0.51910,"qty":407.81250000}],"checksum":2841884423,"timestamp":"2024-06-01T18:07:05.674160Z"}]}
{"channel":"book","type":"update","data":[{"symbol":"XRP/USDT","bids":[],"asks":[{"price":0.51910,"qty":815.62500000}],"checksum":938698779,"timestamp":"2024-06-01T18:07:05.678660Z"}]}
{"channel":"book","type":"update","data":[{"symbol":"XRP/USDT","bids":[],"asks":[{"price":0.51912,"qty":0.00000000},{"price":0.51932,"qty":1283.40000000}],"checksum":3354654691,"timestamp":"2024-06-01T18:07:05.720517Z"}]}
{"channel":"book","type":"update","data":[{"symbol":"XRP/USDT","bids":[],"asks":[{"price":0.51909,"qty":470.00000000}],"checksum":643506246,"timestamp":"2024-06-01T18:07:05.720772Z"}]}
{"channel":"book","type":"update","data":[{"symbol":"XRP/USDT","bids":[],"asks":[{"price":0.51908,"qty":407.81250000}],"checksum":167719599,"timestamp":"2024-06-01T18:07:05.724379Z"}]}
{"channel":"book","type":"update","data":[{"symbol":"XRP/USDT","bids":[],"asks":[{"price":0.51913,"qty":0.00000000},{"price":0.51931,"qty":1582.65411094}],"checksum":1923906762,"timestamp":"2024-06-01T18:07:06.179435Z"}]}
{"channel":"book","type":"update","data":[{"symbol":"XRP/USDT","bids":[],"asks":[{"price":0.51912,"qty":9639.90230706}],"checksum":3061202741,"timestamp":"2024-06-01T18:07:06.183486Z"}]}
{"channel":"book","type":"update","data":[{"symbol":"XRP/USDT","bids":[],"asks":[{"price":0.51908,"qty":0.00000000},{"price":0.51931,"qty":1582.65411094}],"checksum":4129560487,"timestamp":"2024-06-01T18:07:06.557018Z"}]}
{"channel":"book","type":"update","data":[{"symbol":"XRP/USDT","bids":[],"asks":[{"price":0.51910,"qty":407.81250000}],"checksum":1485828959,"timestamp":"2024-06-01T18:07:06.557500Z"}]}
{"channel":"book","type":"update","data":[{"symbol":"XRP/USDT","bids":[],"asks":[{"price":0.51910,"qty":0.00000000},{"price":0.51934,"qty":1281.70000000}],"checksum":1806074879,"timestamp":"2024-06-01T18:07:06.558177Z"}]}
{"channel":"book","type":"update","data":[{"symbol":"XRP/USDT","bids":[],"asks":[{"price":0.51912,"qty":0.00000000},{"price":0.51936,"qty":782.10851420}],"checksum":2155125886,"timestamp":"2024-06-01T18:07:06.563037Z"}]}
{"channel":"book","type":"update","data":[{"symbol":"XRP/USDT","bids":[],"asks":[{"price":0.51926,"qty":3000.00000000}],"checksum":1361905933,"timestamp":"2024-06-01T18:07:06.563962Z"}]}
{"channel":"book","type":"update","data":[{"symbol":"XRP/USDT","bids":[{"price":0.51901,"qty":0.00000000},{"price":0.51879,"qty":1609.38099461}],"asks":[],"checksum":1076095194,"timestamp":"2024-06-01T18:07:06.565313Z"}]}
{"channel":"book","type":"update","data":[{"symbol":"XRP/USDT","bids":[],"asks":[{"price":0.51909,"qty":0.00000000},{"price":0.51937,"qty":9635.19216179}],"checksum":1542401811,"timestamp":"2024-06-01T18:07:06.567659Z"}]}
{"channel":"book","type":"update","data":[{"symbol":"XRP/USDT","bids":[],"asks":[{"price":0.51914,"qty":470.00000000}],"checksum":337868860,"timestamp":"2024-06-01T18:07:06.567749Z"}]}
{"channel":"book","type":"update","data":[{"symbol":"XRP/USDT","bids":[{"price":0.51889,"qty":3000.00000000}],"asks":[],"checksum":3671987700,"timestamp":"2024-06-01T18:07:06.570210Z"}]}
{"channel":"book","type":"update","data":[{"symbol":"XRP/USDT","bids":[{"price":0.51899,"qty":10049.89770671}],"asks":[],"checksum":3331035793,"timestamp":"2024-06-01T18:07:06.571917Z"}]}
{"channel":"book","type":"update","data":[{"symbol":"XRP/USDT","bids":[{"price":0.51900,"qty":407.81250000}],"asks":[],"checksum":2573955915,"timestamp":"2024-06-01T18:07:06.575319Z"}]}
{"channel":"book","type":"update","data":[{"symbol":"XRP/USDT","bids":[],"asks":[{"price":0.51913,"qty":407.81250000}],"checksum":2213596777,"timestamp":"2024-06-01T18:07:06.578071Z"}]}
{"channel":"book","type":"update","data":[{"symbol":"XRP/USDT","bids":[],"asks":[{"price":0.51927,"qty":9637.10491549}],"checksum":1355615469,"timestamp":"2024-06-01T18:07:06.581815Z"}]}
{"channel":"book","type":"update","data":[{"symbol":"XRP/USDT","bids":[{"price":0.51902,"qty":9641.51508158}],"asks":[],"checksum":3543387681,"timestamp":"2024-06-01T18:07:06.581890Z"}]}
{"channel":"book","type":"update","data":[{"symbol":"XRP/USDT","bids":[{"price":0.51892,"qty":10051.31722041}],"asks":[],"checksum":3943674791,"timestamp":"2024-06-01T18:07:06.581957Z"}]}
{"channel":"book","type":"update","data":[{"symbol":"XRP/USDT","bids":[{"price":0.51900,"qty":0.00000000},{"price":0.51880,"qty":3308.83600310}],"asks":[],"checksum":1319181900,"timestamp":"2024-06-01T18:07:06.582111Z"}]}
{"channel":"book","type":"update","data":[{"symbol":"XRP/USDT","bids":[{"price":0.51899,"qty":407.81250000}],"asks":[],"checksum":3351491782,"timestamp":"2024-06-01T18:07:06.584613Z"}]}
{"channel":"book","type":"update","data":[{"symbol":"XRP/USDT","bids":[{"price":0.51900,"qty":407.81250000}],"asks":[],"checksum":2203769092,"timestamp":"2024-06-01T18:07:06.589611Z"}]}
{"channel":"book","type":"update","data":[{"symbol":"XRP/USDT","bids":[{"price":0.51899,"qty":0.00000000},{"price":0.51880,"qty":3308.83600310}],"asks":[],"checksum":707247494,"timestamp":"2024-06-01T18:07:06.590564Z"}]}
{"channel":"book","type":"update","data":[{"symbol":"XRP/USDT","bids":[{"price":0.51902,"qty":10049.32758158}],"asks":[],"checksum":85818117,"timestamp":"2024-06-01T18:07:06.593075Z"}]}
{"channel":"book","type":"update","data":[{"symbol":"XRP/USDT","bids":[],"asks":[{"price":0.51915,"qty":0.00000000},{"price":0.51934,"qty":1281.70000000}],"checksum":411144380,"timestamp":"2024-06-01T18:07:06.596571Z"}]}
{"channel":"book","type":"update","data":[{"symbol":"XRP/USDT","bids":[{"price":0.51902,"qty":407.81250000}],"asks":[],"checksum":3130551388,"timestamp":"2024-06-01T18:07:06.596648Z"}]}
{"channel":"book","type":"update","data":[{"symbol":"XRP/USDT","bids":[{"price":0.51890,"qty":0.00000000},{"price":0.51879,"qty":1609.38099461}],"asks":[],"checksum":262593451,"timestamp":"2024-06-01T18:07:06.601337Z"}]}
{"channel":"book","type":"update","data":[{"symbol":"XRP/USDT","bids":[{"price":0.51900,"qty":0.00000000},{"price":0.51874,"qty":407.81250000}],"asks":[],"checksum":1691546710,"timestamp":"2024-06-01T18:07:06.603646Z"}]}
{"channel":"book","type":"update","data":[{"symbol":"XRP/USDT","bids":[{"price":0.51893,"qty":470.00000000}],"asks":[],"checksum":3563324794,"timestamp":"2024-06-01T18:07:06.603957Z"}]}
{"channel":"book","type":"update","data":[{"symbol":"XRP/USDT","bids":[{"price":0.51883,"qty":3386.04182285}],"asks":[],"checksum":3604334800,"timestamp":"2024-06-01T18:07:06.608915Z"}]}
{"channel":"book","type":"update","data":[{"symbol":"XRP/USDT","bids":[{"price":0.51902,"qty":815.62500000}],"asks":[],"checksum":2748906121,"timestamp":"2024-06-01T18:07:06.620453Z"}]}
{"channel":"book","type":"update","data":[{"symbol":"XRP/USDT","bids":[{"price":0.51901,"qty":9641.85969428}],"asks":[],"checksum":2508762216,"timestamp":"2024-06-01T18:07:06.621928Z"}]}
{"channel":"book","type":"update","data":[{"symbol":"XRP/USDT","bids":[],"asks":[{"price":0.51913,"qty":0.00000000},{"price":0.51936,"qty":782.10851420}],"checksum":2436611787,"timestamp":"2024-06-01T18:07:06.623915Z"}]}
{"channel":"book","type":"update","data":[{"symbol":"XRP/USDT","bids":[],"asks":[{"price":0.51914,"qty":877.81250000}],"checksum":1605334109,"timestamp":"2024-06-01T18:07:06.638697Z"}]}
{"channel":"book","type":"update","data":[{"symbol":"XRP/USDT","bids":[],"asks":[{"price":0.51913,"qty":407.81250000}],"checksum":4262642025,"timestamp":"2024-06-01T18:07:06.651988Z"}]}
{"channel":"book","type":"update","data":[{"symbol":"XRP/USDT","bids":[{"price":0.51902,"qty":407.81250000}],"asks":[],"checksum":2334126896,"timestamp":"2024-06-01T18:07:06.667248Z"}]}
{"channel":"book","type":"update","data":[{"symbol":"XRP/USDT","bids":[{"price":0.51902,"qty":815.62500000}],"asks":[],"checksum":4262642025,"timestamp":"2024-06-01T18:07:06.672152Z"}]}
{"channel":"book","type":"update","data":[{"symbol":"XRP/USDT","bids":[{"price":0.51902,"qty":407.81250000}],"asks":[],"checksum":2334126896,"timestamp":"2024-06-01T18:07:06.724807Z"}]}
{"channel":"book","type":"update","data":[{"symbol":"XRP/USDT","bids":[{"price":0.51902,"qty":0.00000000},{"price":0.51879,"qty":1609.38099461}],"asks":[],"checksum":183212158,"timestamp":"2024-06-01T18:07:06.725204Z"}]}
{"channel":"book","type":"update","data":[{"symbol":"XRP/USDT","bids":[{"price":0.51902,"qty":407.81250000}],"asks":[],"checksum":2334126896,"timestamp":"2024-06-01T18:07:06.729026Z"}]}
{"channel":"book","type":"update","data":[{"symbol":"XRP/USDT","bids":[{"price":0.51902,"qty":815.62500000}],"asks":[],"checksum":4262642025,"timestamp":"2024-06-01T18:07:06.729396Z"}]}
{"channel":"book","type":"update","data":[{"symbol":"XRP/USDT","bids":[{"price":0.51902,"qty":407.81250000}],"asks":[],"checksum":2334126896,"timestamp":"2024-06-01T18:07:06.732981Z"}]}
{"channel":"book","type":"update","data":[{"symbol":"XRP/USDT","bids":[{"price":0.51902,"qty":815.62500000}],"asks":[],"checksum":4262642025,"timestamp":"2024-06-01T18:07:06.738209Z"}]}
{"channel":"book","type":"update","data":[{"symbol":"XRP/USDT","bids":[{"price":0.51902,"qty":407.81250000}],"asks":[],"checksum":2334126896,"timestamp":"2024-06-01T18:07:06.779447Z"}]}
{"channel":"book","type":"update","data":[{"symbol":"XRP/USDT","bids":[{"price":0.51902,"qty":815.62500000}],"asks":[],"checksum":4262642025,"timestamp":"2024-06-01T18:07:06.783019Z"}]}
{"channel":"book","type":"update","data":[{"symbol":"XRP/USDT","bids":[{"price":0.51902,"qty":407.81250000}],"asks":[],"checksum":2334126896,"timestamp":"2024-06-01T18:07:06.837994Z"}]}
{"channel":"book","type":"update","data":[{"symbol":"XRP/USDT","bids":[{"price":0.51902,"qty":815.62500000}],"asks":[],"checksum":4262642025,"timestamp":"2024-06-01T18:07:06.881091Z"}]}
{"channel":"book","type":"update","data":[{"symbol":"XRP/USDT","bids":[{"price":0.51902,"qty":407.81250000}],"asks":[],"checksum":2334126896,"timestamp":"2024-06-01T18:07:06.989357Z"}]}
{"channel":"book","type":"update","data":[{"symbol":"XRP/USDT","bids":[{"price":0.51902,"qty":815.62500000}],"asks":[],"checksum":4262642025,"timestamp":"2024-06-01T18:07:06.991934Z"}]}
{"channel":"book","type":"update","data":[{"symbol":"XRP/USDT","bids":[{"price":0.51902,"qty":407.81250000}],"asks":[],"checksum":2334126896,"timestamp":"2024-06-01T18:07:06.996567Z"}]}
{"channel":"book","type":"update","data":[{"symbol":"XRP/USDT","bids":[{"price":0.51902,"qty":0.00000000},{"price":0.51879,"qty":1609.38099461}],"asks":[],"checksum":183212158,"timestamp":"2024-06-01T18:07:06.996920Z"}]}
{"channel":"book","type":"update","data":[{"symbol":"XRP/USDT","bids":[{"price":0.51901,"qty":10049.67219428}],"asks":[],"checksum":1718825316,"timestamp":"2024-06-01T18:07:07.002505Z"}]}
{"channel":"book","type":"update","data":[{"symbol":"XRP/USDT","bids":[],"asks":[{"price":0.51920,"qty":0.00000000},{"price":0.51936,"qty":3793.85432285}],"checksum":1743762618,"timestamp":"2024-06-01T18:07:07.184952Z"}]}
{"channel":"book","type":"update","data":[{"symbol":"XRP/USDT","bids":[],"asks":[{"price":0.51914,"qty":10517.35058697}],"checksum":711024985,"timestamp":"2024-06-01T18:07:07.190387Z"}]}
{"channel":"book","type":"update","data":[{"symbol":"XRP/USDT","bids":[{"price":0.51902,"qty":9641.67510224}],"asks":[],"checksum":416989837,"timestamp":"2024-06-01T18:07:07.190410Z"}]}
{"channel":"book","type":"update","data":[{"symbol":"XRP/USDT","bids":[{"price":0.51902,"qty":10049.48760224}],"asks":[],"checksum":3051194965,"timestamp":"2024-06-01T18:07:07.473090Z"}]}
{"channel":"book","type":"update","data":[{"symbol":"XRP/USDT","bids":[{"price":0.51902,"qty":407.81250000}],"asks":[],"checksum":1226838119,"timestamp":"2024-06-01T18:07:07.567546Z"}]}
{"channel":"book","type":"update","data":[{"symbol":"XRP/USDT","bids":[{"price":0.51902,"qty":815.62500000}],"asks":[],"checksum":1541600261,"timestamp":"2024-06-01T18:07:07.571190Z"}]}
{"channel":"book","type":"update","data":[{"symbol":"XRP/USDT","bids":[],"asks":[{"price":0.51913,"qty":0.00000000},{"price":0.51937,"qty":9635.19216179}],"checksum":1720303894,"timestamp":"2024-06-01T18:07:07.708032Z"}]}
{"channel":"book","type":"update","data":[{"symbol":"XRP/USDT","bids":[],"asks":[{"price":0.51913,"qty":407.81250000}],"checksum":1541600261,"timestamp":"2024-06-01T18:07:07.825602Z"}]}
{"channel":"book","type":"update","data":[{"symbol":"XRP/USDT","bids":[{"price":0.51902,"qty":407.81250000}],"asks":[],"checksum":1226838119,"timestamp":"2024-06-01T18:07:07.829182Z"}]}
{"channel":"book","type":"update","data":[{"symbol":"XRP/USDT","bids":[{"price":0.51902,"qty":815.62500000}],"asks":[],"checksum":1541600261,"timestamp":"2024-06-01T18:07:07.868729Z"}]}
{"channel":"book","type":"update","data":[{"symbol":"XRP/USDT","bids":[{"price":0.51902,"qty":407.81250000}],"asks":[],"checksum":1226838119,"timestamp":"2024-06-01T18:07:07.926280Z"}]}
{"channel":"book","type":"update","data":[{"symbol":"XRP/USDT","bids":[{"price":0.51902,"qty":0.00000000},{"price":0.51879,"qty":1609.38099461}],"asks":[],"checksum":711024985,"timestamp":"2024-06-01T18:07:07.926442Z"}]}
{"channel":"book","type":"update","data":[{"symbol":"XRP/USDT","bids":[{"price":0.51901,"qty":9641.85969428}],"asks":[],"checksum":1907096415,"timestamp":"2024-06-01T18:07:08.107279Z"}]}
{"channel":"book","type":"update","data":[{"symbol":"XRP/USDT","bids":[],"asks":[{"price":0.51914,"qty":877.81250000}],"checksum":1293893695,"timestamp":"2024-06-01T18:07:08.246930Z"}]}
{"channel":"book","type":"update","data":[{"symbol":"XRP/USDT","bids":[],"asks":[{"price":0.51913,"qty":10047.53153229}],"checksum":530234339,"timestamp":"2024-06-01T18:07:08.251398Z"}]}
{"channel":"book","type":"update","data":[{"symbol":"XRP/USDT","bids":[{"price":0.51897,"qty":9642.49409198}],"asks":[],"checksum":2020887637,"timestamp":"2024-06-01T18:07:08.251497Z"}]}
{"channel":"book","type":"update","data":[{"symbol":"XRP/USDT","bids":[{"price":0.51901,"qty":0.00000000},{"price":0.51879,"qty":1609.38099461}],"asks":[],"checksum":1172463565,"timestamp":"2024-06-01T18:07:08.353154Z"}]}
{"channel":"book","type":"update","data":[{"symbol":"XRP/USDT","bids":[{"price":0.51893,"qty":0.00000000},{"price":0.51874,"qty":407.81250000}],"asks":[],"checksum":2645797838,"timestamp":"2024-06-01T18:07:08.355836Z"}]}
{"channel":"book","type":"update","data":[{"symbol":"XRP/USDT","bids":[{"price":0.51898,"qty":470.00000000}],"asks":[],"checksum":2102069780,"timestamp":"2024-06-01T18:07:08.355955Z"}]}
{"channel":"book","type":"update","data":[{"symbol":"XRP/USDT","bids":[{"price":0.51898,"qty":877.81250000}],"asks":[],"checksum":2065994288,"timestamp":"2024-06-01T18:07:08.356943Z"}]}
{"channel":"book","type":"update","data":[{"symbol":"XRP/USDT","bids":[{"price":0.51897,"qty":0.00000000},{"price":0.51874,"qty":407.81250000}],"asks":[],"checksum":1304122164,"timestamp":"2024-06-01T18:07:08.357110Z"}]}
{"channel":"book","type":"update","data":[{"symbol":"XRP/USDT","bids":[],"asks":[{"price":0.51914,"qty":407.81250000}],"checksum":1871695828,"timestamp":"2024-06-01T18:07:08.359839Z"}]}
{"channel":"book","type":"update","data":[{"symbol":"XRP/USDT","bids":[],"asks":[{"price":0.51912,"qty":470.00000000}],"checksum":3138074615,"timestamp":"2024-06-01T18:07:08.360087Z"}]}
{"channel":"book","type":"update","data":[{"symbol":"XRP/USDT","bids":[{"price":0.51902,"qty":9641.63861135}],"asks":[],"checksum":3394115358,"timestamp":"2024-06-01T18:07:08.361444Z"}]}
{"channel":"book","type":"update","data":[{"symbol":"XRP/USDT","bids":[],"asks":[{"price":0.51911,"qty":407.81250000}],"checksum":1070665537,"timestamp":"2024-06-01T18:07:08.363438Z"}]}
{"channel":"book","type":"update","data":[{"symbol":"XRP/USDT","bids":[],"asks":[{"price":0.51914,"qty":0.00000000},{"price":0.51934,"qty":1281.70000000}],"checksum":1090584469,"timestamp":"2024-06-01T18:07:08.364429Z"}]}
{"channel":"book","type":"update","data":[{"symbol":"XRP/USDT","bids":[],"asks":[{"price":0.51911,"qty":0.00000000},{"price":0.51936,"qty":3793.85432285}],"checksum":1089801854,"timestamp":"2024-06-01T18:07:08.849086Z"}]}
{"channel":"book","type":"update","data":[{"symbol":"XRP/USDT","bids":[],"asks":[{"price":0.51912,"qty":877.81250000}],"checksum":2132583019,"timestamp":"2024-06-01T18:07:08.852832Z"}]}
{"channel":"book","type":"update","data":[{"symbol":"XRP/USDT","bids":[{"price":0.51902,"qty":10049.45111135}],"asks":[],"checksum":3833079039,"timestamp":"2024-06-01T18:07:08.978043Z"}]}
{"channel":"book","type":"update","data":[{"symbol":"XRP/USDT","bids":[],"asks":[{"price":0.51912,"qty":470.00000000}],"checksum":2308581816,"timestamp":"2024-06-01T18:07:08.978468Z"}]}
{"channel":"book","type":"update","data":[{"symbol":"XRP/USDT","bids":[],"asks":[{"price":0.51913,"qty":9639.71903229}],"checksum":3716394235,"timestamp":"2024-06-01T18:07:09.284262Z"}]}
{"channel":"book","type":"update","data":[{"symbol":"XRP/USDT","bids":[{"price":0.51902,"qty":9641.63861135}],"asks":[],"checksum":2267505800,"timestamp":"2024-06-01T18:07:09.476018Z"}]}
{"channel":"book","type":"update","data":[{"symbol":"XRP/USDT","bids":[],"asks":[{"price":0.51912,"qty":877.81250000}],"checksum":3683494958,"timestamp":"2024-06-01T18:07:09.477308Z"}]}
{"channel":"book","type":"update","data":[{"symbol":"XRP/USDT","bids":[],"asks":[{"price":0.51911,"qty":407.81250000}],"checksum":1986779049,"timestamp":"2024-06-01T18:07:09.484510Z"}]}
{"channel":"book","type":"update","data":[{"symbol":"XRP/USDT","bids":[],"asks":[{"price":0.51916,"qty":10046.90704944}],"checksum":337328889,"timestamp":"2024-06-01T18:07:09.973220Z"}]}
{"channel":"book","type":"update","data":[{"symbol":"XRP/USDT","bids":[{"price":0.51898,"qty":10520.23536291}],"asks":[],"checksum":294152526,"timestamp":"2024-06-01T18:07:09.973358Z"}]}
{"channel":"book","type":"update","data":[{"symbol":"XRP/USDT","bids":[],"asks":[{"price":0.51911,"qty":0.00000000},{"price":0.51936,"qty":3793.85432285}],"checksum":2222647865,"timestamp":"2024-06-01T18:07:10.182380Z"}]}
{"channel":"book","type":"update","data":[{"symbol":"XRP/USDT","bids":[{"price":0.51880,"qty":1972.75794310}],"asks":[],"checksum":2877356822,"timestamp":"2024-06-01T18:07:10.256935Z"}]}
{"channel":"book","type":"update","data":[{"symbol":"XRP/USDT","bids":[{"price":0.51891,"qty":1336.07806000}],"asks":[],"checksum":1469012212,"timestamp":"2024-06-01T18:07:10.259613Z"}]}
{"channel":"book","type":"update","data":[{"symbol":"XRP/USDT","bids":[],"asks":[{"price":0.51911,"qty":407.81250000}],"checksum":3263028099,"timestamp":"2024-06-01T18:07:10.262128Z"}]}
{"channel":"book","type":"update","data":[{"symbol":"XRP/USDT","bids":[],"asks":[{"price":0.51911,"qty":0.00000000},{"price":0.51936,"qty":3793.85432285}],"checksum":1469012212,"timestamp":"2024-06-01T18:07:10.644705Z"}]}
{"channel":"book","type":"update","data":[{"symbol":"XRP/USDT","bids":[],"asks":[{"price":0.51912,"qty":470.00000000}],"checksum":2517012585,"timestamp":"2024-06-01T18:07:10.899022Z"}]}
{"channel":"book","type":"update","data":[{"symbol":"XRP/USDT","bids":[],"asks":[{"price":0.51912,"qty":877.81250000}],"checksum":1469012212,"timestamp":"2024-06-01T18:07:10.902777Z"}]}
{"channel":"book","type":"update","data":[{"symbol":"XRP/USDT","bids":[],"asks":[{"price":0.51911,"qty":407.81250000}],"checksum":3263028099,"timestamp":"2024-06-01T18:07:11.197871Z"}]}
{"channel":"book","type":"update","data":[{"symbol":"XRP/USDT","bids":[{"price":0.51898,"qty":10112.42286291}],"asks":[],"checksum":642827727,"timestamp":"2024-06-01T18:07:11.202219Z"}]}
{"channel":"book","type":"update","data":[{"symbol":"XRP/USDT","bids":[],"asks":[{"price":0.51913,"qty":0.00000000},{"price":0.51936,"qty":3793.85432285}],"checksum":2146067043,"timestamp":"2024-06-01T18:07:11.225323Z"}]}
{"channel":"book","type":"update","data":[{"symbol":"XRP/USDT","bids":[{"price":0.51902,"qty":0.00000000},{"price":0.51879,"qty":1609.38099461}],"asks":[],"checksum":3473873035,"timestamp":"2024-06-01T18:07:11.225382Z"}]}
{"channel":"book","type":"update","data":[{"symbol":"XRP/USDT","bids":[],"asks":[{"price":0.51912,"qty":10517.76038422}],"checksum":1077464813,"timestamp":"2024-06-01T18:07:11.232395Z"}]}
{"channel":"book","type":"update","data":[{"symbol":"XRP/USDT","bids":[{"price":0.51900,"qty":9642.00635029}],"asks":[],"checksum":2137705078,"timestamp":"2024-06-01T18:07:11.232588Z"}]}
{"channel":"book","type":"update","data":[{"symbol":"XRP/USDT","bids":[],"asks":[{"price":0.51927,"qty":0.00000000},{"price":0.51937,"qty":9635.19216179}],"checksum":2978389410,"timestamp":"2024-06-01T18:07:11.237887Z"}]}
{"channel":"book","type":"update","data":[{"symbol":"XRP/USDT","bids":[],"asks":[{"price":0.51922,"qty":10045.85517557}],"checksum":2441377272,"timestamp":"2024-06-01T18:07:11.243098Z"}]}
{"channel":"book","type":"update","data":[{"symbol":"XRP/USDT","bids":[{"price":0.51900,"qty":0.00000000},{"price":0.51879,"qty":1609.38099461}],"asks":[],"checksum":2933289315,"timestamp":"2024-06-01T18:07:11.247828Z"}]}
{"channel":"book","type":"update","data":[{"symbol":"XRP/USDT","bids":[],"asks":[{"price":0.51912,"qty":877.81250000}],"checksum":4072752532,"timestamp":"2024-06-01T18:07:11.441398Z"}]}
{"channel":"book","type":"update","data":[{"symbol":"XRP/USDT","bids":[{"price":0.51887,"qty":9644.35109185}],"asks":[],"checksum":484270126,"timestamp":"2024-06-01T18:07:11.445578Z"}]}
{"channel":"book","type":"update","data":[{"symbol":"XRP/USDT","bids":[{"price":0.51892,"qty":407.81250000}],"asks":[],"checksum":2233887189,"timestamp":"2024-06-01T18:07:11.449863Z"}]}
{"channel":"book","type":"update","data":[{"symbol":"XRP/USDT","bids":[{"price":0.51894,"qty":9643.04020522}],"asks":[],"checksum":1449725700,"timestamp":"2024-06-01T18:07:11.453248Z"}]}
{"channel":"book","type":"update","data":[{"symbol":"XRP/USDT","bids":[{"price":0.51894,"qty":0.00000000},{"price":0.51880,"qty":1972.75794310}],"asks":[],"checksum":2233887189,"timestamp":"2024-06-01T18:07:12.112188Z"}]}
{"channel":"book","type":"update","data":[{"symbol":"XRP/USDT","bids":[{"price":0.51900,"qty":9641.94267563}],"asks":[],"checksum":1935123137,"timestamp":"2024-06-01T18:07:12.116071Z"}]}
{"channel":"book","type":"update","data":[{"symbol":"XRP/USDT","bids":[],"asks":[{"price":0.51912,"qty":10517.69672315}],"checksum":3440807718,"timestamp":"2024-06-01T18:07:12.116101Z"}]}
{"channel":"book","type":"update","data":[{"symbol":"XRP/USDT","bids":[],"asks":[{"price":0.51912,"qty":877.81250000}],"checksum":1935123137,"timestamp":"2024-06-01T18:07:12.865016Z"}]}
{"channel":"book","type":"update","data":[{"symbol":"XRP/USDT","bids":[],"asks":[{"price":0.51911,"qty":10047.92763766}],"checksum":1872670073,"timestamp":"2024-06-01T18:07:12.869220Z"}]}
{"channel":"book","type":"update","data":[{"symbol":"XRP/USDT","bids":[],"asks":[{"price":0.51909,"qty":407.81250000}],"checksum":2977967610,"timestamp":"2024-06-01T18:07:12.873508Z"}]}
{"channel":"book","type":"update","data":[{"symbol":"XRP/USDT","bids":[],"asks":[{"price":0.51909,"qty":815.62500000}],"checksum":2114962493,"timestamp":"2024-06-01T18:07:12.876811Z"}]}
{"channel":"book","type":"update","data":[{"symbol":"XRP/USDT","bids":[],"asks":[{"price":0.51912,"qty":470.00000000}],"checksum":4250378274,"timestamp":"2024-06-01T18:07:12.877173Z"}]}
{"channel":"book","type":"update","data":[{"symbol":"XRP/USDT","bids":[],"asks":[{"price":0.51912,"qty":0.00000000},{"price":0.51937,"qty":9635.19216179}],"checksum":3254234245,"timestamp":"2024-06-01T18:07:12.879857Z"}]}
{"channel":"book","type":"update","data":[{"symbol":"XRP/USDT","bids":[],"asks":[{"price":0.51911,"qty":10517.92763766}],"checksum":1939311135,"timestamp":"2024-06-01T18:07:13.015127Z"}]}
{"channel":"book","type":"update","data":[{"symbol":"XRP/USDT","bids":[],"asks":[{"price":0.51909,"qty":407.81250000}],"checksum":1985499877,"timestamp":"2024-06-01T18:07:13.377785Z"}]}
{"channel":"book","type":"update","data":[{"symbol":"XRP/USDT","bids":[],"asks":[{"price":0.51909,"qty":815.62500000}],"checksum":1939311135,"timestamp":"2024-06-01T18:07:13.477814Z"}]}
{"channel":"book","type":"update","data":[{"symbol":"XRP/USDT","bids":[],"asks":[{"price":0.51909,"qty":407.81250000}],"checksum":1985499877,"timestamp":"2024-06-01T18:07:13.548327Z"}]}
{"channel":"book","type":"update","data":[{"symbol":"XRP/USDT","bids":[],"asks":[{"price":0.51909,"qty":0.00000000},{"price":0.51942,"qty":407.81250000}],"checksum":2515469980,"timestamp":"2024-06-01T18:07:13.548339Z"}]}
{"channel":"book","type":"update","data":[{"symbol":"XRP/USDT","bids":[],"asks":[{"price":0.51910,"qty":407.81250000}],"checksum":1212182710,"timestamp":"2024-06-01T18:07:13.559778Z"}]}
{"channel":"book","type":"update","data":[{"symbol":"XRP/USDT","bids":[],"asks":[{"price":0.51910,"qty":815.62500000}],"checksum":1301260364,"timestamp":"2024-06-01T18:07:13.563685Z"}]}
{"channel":"book","type":"update","data":[{"symbol":"XRP/USDT","bids":[],"asks":[{"price":0.51910,"qty":407.81250000}],"checksum":1212182710,"timestamp":"2024-06-01T18:07:13.564123Z"}]}
{"channel":"book","type":"update","data":[{"symbol":"XRP/USDT","bids":[],"asks":[{"price":0.51910,"qty":815.62500000}],"checksum":1301260364,"timestamp":"2024-06-01T18:07:13.567223Z"}]}
{"channel":"book","type":"update","data":[{"symbol":"XRP/USDT","bids":[],"asks":[{"price":0.51910,"qty":407.81250000}],"checksum":1212182710,"timestamp":"2024-06-01T18:07:13.882354Z"}]}
{"channel":"book","type":"update","data":[{"symbol":"XRP/USDT","bids":[],"asks":[{"price":0.51910,"qty":815.62500000}],"checksum":1301260364,"timestamp":"2024-06-01T18:07:13.896675Z"}]}
{"channel":"book","type":"update","data":[{"symbol":"XRP/USDT","bids":[],"asks":[{"price":0.51910,"qty":407.81250000}],"checksum":1212182710,"timestamp":"2024-06-01T18:07:13.922302Z"}]}
{"channel":"book","type":"update","data":[{"symbol":"XRP/USDT","bids":[],"asks":[{"price":0.51910,"qty":815.62500000}],"checksum":1301260364,"timestamp":"2024-06-01T18:07:13.934194Z"}]}
{"channel":"book","type":"update","data":[{"symbol":"XRP/USDT","bids":[],"asks":[{"price":0.51910,"qty":407.81250000}],"checksum":1212182710,"timestamp":"2024-06-01T18:07:13.938018Z"}]}
{"channel":"book","type":"update","data":[{"symbol":"XRP/USDT","bids":[{"price":0.51900,"qty":10049.75517563}],"asks":[],"checksum":1501192804,"timestamp":"2024-06-01T18:07:13.938041Z"}]}
{"channel":"book","type":"update","data":[{"symbol":"XRP/USDT","bids":[],"asks":[{"price":0.51910,"qty":0.00000000},{"price":0.51942,"qty":407.81250000}],"checksum":2182874308,"timestamp":"2024-06-01T18:07:13.938439Z"}]}
{"channel":"book","type":"update","data":[{"symbol":"XRP/USDT","bids":[],"asks":[{"price":0.51910,"qty":407.81250000}],"checksum":1501192804,"timestamp":"2024-06-01T18:07:14.013240Z"}]}
{"channel":"book","type":"update","data":[{"symbol":"XRP/USDT","bids":[{"price":0.51900,"qty":9641.94267563}],"asks":[],"checksum":1212182710,"timestamp":"2024-06-01T18:07:14.013562Z"}]}
{"channel":"book","type":"update","data":[{"symbol":"XRP/USDT","bids":[],"asks":[{"price":0.51910,"qty":815.62500000}],"checksum":1301260364,"timestamp":"2024-06-01T18:07:14.016608Z"}]}
{"channel":"book","type":"update","data":[{"symbol":"XRP/USDT","bids":[],"asks":[{"price":0.51910,"qty":407.81250000}],"checksum":1212182710,"timestamp":"2024-06-01T18:07:14.016892Z"}]}
{"channel":"book","type":"update","data":[{"symbol":"XRP/USDT","bids":[],"asks":[{"price":0.51910,"qty":815.62500000}],"checksum":1301260364,"timestamp":"2024-06-01T18:07:14.020064Z"}]}
{"channel":"book","type":"update","data":[{"symbol":"XRP/USDT","bids":[],"asks":[{"price":0.51910,"qty":407.81250000}],"checksum":1212182710,"timestamp":"2024-06-01T18:07:15.029910Z"}]}
{"channel":"book","type":"update","data":[{"symbol":"XRP/USDT","bids":[],"asks":[{"price":0.51910,"qty":0.00000000},{"price":0.51942,"qty":407.81250000}],"checksum":2515469980,"timestamp":"2024-06-01T18:07:15.030751Z"}]}
{"channel":"book","type":"update","data":[{"symbol":"XRP/USDT","bids":[{"price":0.51900,"qty":10049.75517563}],"asks":[],"checksum":2182874308,"timestamp":"2024-06-01T18:07:15.031153Z"}]}
{"channel":"book","type":"update","data":[{"symbol":"XRP/USDT","bids":[{"price":0.51901,"qty":407.81250000}],"asks":[],"checksum":633318494,"timestamp":"2024-06-01T18:07:15.031188Z"}]}
{"channel":"book","type":"update","data":[{"symbol":"XRP/USDT","bids":[{"price":0.51901,"qty":815.62500000}],"asks":[],"checksum":930957372,"timestamp":"2024-06-01T18:07:15.031234Z"}]}
{"channel":"book","type":"update","data":[{"symbol":"XRP/USDT","bids":[],"asks":[{"price":0.51911,"qty":10110.11513766}],"checksum":257959939,"timestamp":"2024-06-01T18:07:15.031753Z"}]}
{"channel":"book","type":"update","data":[{"symbol":"XRP/USDT","bids":[],"asks":[{"price":0.51911,"qty":470.00000000}],"checksum":3775049965,"timestamp":"2024-06-01T18:07:15.063296Z"}]}
{"channel":"book","type":"update","data":[{"symbol":"XRP/USDT","bids":[{"price":0.51900,"qty":407.81250000}],"asks":[],"checksum":121723579,"timestamp":"2024-06-01T18:07:15.063432Z"}]}
{"channel":"book","type":"update","data":[{"symbol":"XRP/USDT","bids":[],"asks":[{"price":0.51911,"qty":0.00000000},{"price":0.51949,"qty":10040.85119023}],"checksum":4183254345,"timestamp":"2024-06-01T18:07:15.066044Z"}]}
{"channel":"book","type":"update","data":[{"symbol":"XRP/USDT","bids":[],"asks":[{"price":0.51915,"qty":470.00000000}],"checksum":3811872086,"timestamp":"2024-06-01T18:07:15.066061Z"}]}
{"channel":"book","type":"update","data":[{"symbol":"XRP/USDT","bids":[],"asks":[{"price":0.51913,"qty":9639.74761080}],"checksum":3964803096,"timestamp":"2024-06-01T18:07:15.067598Z"}]}
{"channel":"book","type":"update","data":[{"symbol":"XRP/USDT","bids":[{"price":0.51901,"qty":10457.43103411}],"asks":[],"checksum":1275965912,"timestamp":"2024-06-01T18:07:15.067731Z"}]}
{"channel":"book","type":"update","data":[{"symbol":"XRP/USDT","bids":[{"price":0.51901,"qty":815.62500000}],"asks":[],"checksum":3964803096,"timestamp":"2024-06-01T18:07:15.108129Z"}]}
{"channel":"book","type":"update","data":[{"symbol":"XRP/USDT","bids":[],"asks":[{"price":0.51912,"qty":407.81250000}],"checksum":2175328979,"timestamp":"2024-06-01T18:07:15.573034Z"}]}
{"channel":"book","type":"update","data":[{"symbol":"XRP/USDT","bids":[{"price":0.51901,"qty":407.81250000}],"asks":[],"checksum":3862505233,"timestamp":"2024-06-01T18:07:15.576289Z"}]}
{"channel":"book","type":"update","data":[{"symbol":"XRP/USDT","bids":[],"asks":[{"price":0.51916,"qty":407.81250000}],"checksum":3199220967,"timestamp":"2024-06-01T18:07:15.582403Z"}]}
{"channel":"book","type":"update","data":[{"symbol":"XRP/USDT","bids":[{"price":0.51900,"qty":0.00000000},{"price":0.51881,"qty":9645.41687087}],"asks":[],"checksum":2559036413,"timestamp":"2024-06-01T18:07:15.583600Z"}]}
{"channel":"book","type":"update","data":[{"symbol":"XRP/USDT","bids":[{"price":0.51894,"qty":9643.06627685}],"asks":[],"checksum":2793121799,"timestamp":"2024-06-01T18:07:15.586142Z"}]}
{"channel":"book","type":"update","data":[{"symbol":"XRP/USDT","bids":[],"asks":[{"price":0.51911,"qty":9640.05614059}],"checksum":2943785606,"timestamp":"2024-06-01T18:07:15.586189Z"}]}
{"channel":"book","type":"update","data":[{"symbol":"XRP/USDT","bids":[],"asks":[{"price":0.51911,"qty":0.00000000},{"price":0.51936,"qty":3793.85432285}],"checksum":2793121799,"timestamp":"2024-06-01T18:07:15.590230Z"}]}
{"channel":"book","type":"update","data":[{"symbol":"XRP/USDT","bids":[{"price":0.51901,"qty":815.62500000}],"asks":[],"checksum":3547765342,"timestamp":"2024-06-01T18:07:15.608715Z"}]}
{"channel":"book","type":"update","data":[{"symbol":"XRP/USDT","bids":[{"price":0.51901,"qty":407.81250000}],"asks":[],"checksum":2793121799,"timestamp":"2024-06-01T18:07:15.873175Z"}]}
{"channel":"book","type":"update","data":[{"symbol":"XRP/USDT","bids":[{"price":0.51901,"qty":815.62500000}],"asks":[],"checksum":3547765342,"timestamp":"2024-06-01T18:07:15.877438Z"}]}
{"channel":"book","type":"update","data":[{"symbol":"XRP/USDT","bids":[{"price":0.51898,"qty":470.00000000}],"asks":[],"checksum":2258520944,"timestamp":"2024-06-01T18:07:15.983081Z"}]}
{"channel":"book","type":"update","data":[{"symbol":"XRP/USDT","bids":[{"price":0.51899,"qty":9642.18140796}],"asks":[],"checksum":1565951845,"timestamp":"2024-06-01T18:07:15.986664Z"}]}
{"channel":"book","type":"update","data":[{"symbol":"XRP/USDT","bids":[{"price":0.51894,"qty":0.00000000},{"price":0.51883,"qty":3386.04182285}],"asks":[],"checksum":735001216,"timestamp":"2024-06-01T18:07:16.113662Z"}]}
{"channel":"book","type":"update","data":[{"symbol":"XRP/USDT","bids":[{"price":0.51898,"qty":0.00000000},{"price":0.51881,"qty":9645.41687087}],"asks":[],"checksum":3104642981,"timestamp":"2024-06-01T18:07:16.116749Z"}]}
{"channel":"book","type":"update","data":[{"symbol":"XRP/USDT","bids":[],"asks":[{"price":0.51912,"qty":10047.74211055}],"checksum":2610831880,"timestamp":"2024-06-01T18:07:16.117459Z"}]}
{"channel":"book","type":"update","data":[{"symbol":"XRP/USDT","bids":[{"price":0.51899,"qty":10112.18140796}],"asks":[],"checksum":767954124,"timestamp":"2024-06-01T18:07:16.120155Z"}]}
{"channel":"book","type":"update","data":[{"symbol":"XRP/USDT","bids":[{"price":0.51901,"qty":407.81250000}],"asks":[],"checksum":1489714837,"timestamp":"2024-06-01T18:07:16.124092Z"}]}
{"channel":"book","type":"update","data":[{"symbol":"XRP/USDT","bids":[{"price":0.51901,"qty":815.62500000}],"asks":[],"checksum":767954124,"timestamp":"2024-06-01T18:07:16.127898Z"}]}
{"channel":"book","type":"update","data":[{"symbol":"XRP/USDT","bids":[],"asks":[{"price":0.51913,"qty":0.00000000},{"price":0.51937,"qty":9635.19216179}],"checksum":1009542102,"timestamp":"2024-06-01T18:07:16.153779Z"}]}
{"channel":"book","type":"update","data":[{"symbol":"XRP/USDT","bids":[],"asks":[{"price":0.51917,"qty":9639.06142084}],"checksum":2225191789,"timestamp":"2024-06-01T18:07:16.157427Z"}]}
{"channel":"book","type":"update","data":[{"symbol":"XRP/USDT","bids":[{"price":0.51901,"qty":407.81250000}],"asks":[],"checksum":4054616372,"timestamp":"2024-06-01T18:07:16.192908Z"}]}
{"channel":"book","type":"update","data":[{"symbol":"XRP/USDT","bids":[{"price":0.51901,"qty":0.00000000},{"price":0.51880,"qty":1972.75794310}],"asks":[],"checksum":2800091397,"timestamp":"2024-06-01T18:07:16.193341Z"}]}
{"channel":"book","type":"update","data":[{"symbol":"XRP/USDT","bids":[{"price":0.51900,"qty":407.81250000}],"asks":[],"checksum":150610850,"timestamp":"2024-06-01T18:07:16.197888Z"}]}
{"channel":"book","type":"update","data":[{"symbol":"XRP/USDT","bids":[{"price":0.51900,"qty":815.62500000}],"asks":[],"checksum":2113343995,"timestamp":"2024-06-01T18:07:16.200430Z"}]}
{"channel":"book","type":"update","data":[{"symbol":"XRP/USDT","bids":[{"price":0.51900,"qty":407.81250000}],"asks":[],"checksum":150610850,"timestamp":"2024-06-01T18:07:16.732351Z"}]}
{"channel":"book","type":"update","data":[{"symbol":"XRP/USDT","bids":[{"price":0.51900,"qty":0.00000000},{"price":0.51880,"qty":1972.75794310}],"asks":[],"checksum":2800091397,"timestamp":"2024-06-01T18:07:16.732585Z"}]}
{"channel":"book","type":"update","data":[{"symbol":"XRP/USDT","bids":[{"price":0.51900,"qty":407.81250000}],"asks":[],"checksum":150610850,"timestamp":"2024-06-01T18:07:16.805756Z"}]}
{"channel":"book","type":"update","data":[{"symbol":"XRP/USDT","bids":[{"price":0.51900,"qty":0.00000000},{"price":0.51880,"qty":1972.75794310}],"asks":[],"checksum":2800091397,"timestamp":"2024-06-01T18:07:16.809202Z"}]}
{"channel":"book","type":"update","data":[{"symbol":"XRP/USDT","bids":[],"asks":[{"price":0.51910,"qty":407.81250000}],"checksum":3085951726,"timestamp":"2024-06-01T18:07:16.861818Z"}]}
{"channel":"book","type":"update","data":[{"symbol":"XRP/USDT","bids":[],"asks":[{"price":0.51910,"qty":0.00000000},{"price":0.51936,"qty":3793.85432285}],"checksum":2800091397,"timestamp":"2024-06-01T18:07:16.865121Z"}]}
{"channel":"book","type":"update","data":[{"symbol":"XRP/USDT","bids":[{"price":0.51899,"qty":10519.99390796}],"asks":[],"checksum":3751639190,"timestamp":"2024-06-01T18:07:16.865131Z"}]}
{"channel":"book","type":"update","data":[{"symbol":"XRP/USDT","bids":[{"price":0.51900,"qty":407.81250000}],"asks":[],"checksum":4068805030,"timestamp":"2024-06-01T18:07:16.877286Z"}]}
{"channel":"book","type":"update","data":[{"symbol":"XRP/USDT","bids":[{"price":0.51900,"qty":815.62500000}],"asks":[],"checksum":2273852415,"timestamp":"2024-06-01T18:07:16.877866Z"}]}
{"channel":"book","type":"update","data":[{"symbol":"XRP/USDT","bids":[{"price":0.51900,"qty":407.81250000}],"asks":[],"checksum":4068805030,"timestamp":"2024-06-01T18:07:16.880801Z"}]}
{"channel":"book","type":"update","data":[{"symbol":"XRP/USDT","bids":[{"price":0.51900,"qty":815.62500000}],"asks":[],"checksum":2273852415,"timestamp":"2024-06-01T18:07:16.883244Z"}]}
{"channel":"book","type":"update","data":[{"symbol":"XRP/USDT","bids":[],"asks":[{"price":0.51912,"qty":407.81250000}],"checksum":801994655,"timestamp":"2024-06-01T18:07:16.919904Z"}]}
{"channel":"book","type":"update","data":[{"symbol":"XRP/USDT","bids":[{"price":0.51901,"qty":9641.84407943}],"asks":[],"checksum":128456820,"timestamp":"2024-06-01T18:07:16.926300Z"}]}
{"channel":"book","type":"update","data":[{"symbol":"XRP/USDT","bids":[],"asks":[{"price":0.51914,"qty":9639.65790350}],"checksum":50370304,"timestamp":"2024-06-01T18:07:16.926529Z"}]}
{"channel":"book","type":"update","data":[{"symbol":"XRP/USDT","bids":[],"asks":[{"price":0.51915,"qty":0.00000000},{"price":0.51936,"qty":3793.85432285}],"checksum":2912415768,"timestamp":"2024-06-01T18:07:16.929206Z"}]}
{"channel":"book","type":"update","data":[{"symbol":"XRP/USDT","bids":[],"asks":[{"price":0.51913,"qty":470.00000000}],"checksum":848330655,"timestamp":"2024-06-01T18:07:16.929562Z"}]}
{"channel":"book","type":"update","data":[{"symbol":"XRP/USDT","bids":[{"price":0.51900,"qty":407.81250000}],"asks":[],"checksum":873667142,"timestamp":"2024-06-01T18:07:16.929881Z"}]}
{"channel":"book","type":"update","data":[{"symbol":"XRP/USDT","bids":[{"price":0.51888,"qty":38.56413437}],"asks":[],"checksum":1813948692,"timestamp":"2024-06-01T18:07:16.947094Z"}]}
{"channel":"book","type":"update","data":[{"symbol":"XRP/USDT","bids":[{"price":0.51901,"qty":0.00000000},{"price":0.51883,"qty":3386.04182285}],"asks":[],"checksum":3372011596,"timestamp":"2024-06-01T18:07:17.088763Z"}]}
{"channel":"book","type":"update","data":[{"symbol":"XRP/USDT","bids":[{"price":0.51900,"qty":815.62500000}],"asks":[],"checksum":2222186199,"timestamp":"2024-06-01T18:07:17.106329Z"}]}
{"channel":"book","type":"update","data":[{"symbol":"XRP/USDT","bids":[{"price":0.51902,"qty":9641.68105484}],"asks":[],"checksum":2519343766,"timestamp":"2024-06-01T18:07:17.972225Z"}]}
{"channel":"book","type":"update","data":[{"symbol":"XRP/USDT","bids":[],"asks":[{"price":0.51914,"qty":0.00000000},{"price":0.51936,"qty":3793.85432285}],"checksum":2584923448,"timestamp":"2024-06-01T18:07:17.974311Z"}]}
{"channel":"book","type":"update","data":[{"symbol":"XRP/USDT","bids":[],"asks":[{"price":0.51913,"qty":10109.75819111}],"checksum":1947545716,"timestamp":"2024-06-01T18:07:17.978117Z"}]}
{"channel":"book","type":"update","data":[{"symbol":"XRP/USDT","bids":[],"asks":[{"price":0.51912,"qty":0.00000000},{"price":0.51937,"qty":9635.19216179}],"checksum":1172973238,"timestamp":"2024-06-01T18:07:18.018620Z"}]}
{"channel":"book","type":"update","data":[{"symbol":"XRP/USDT","bids":[],"asks":[{"price":0.51913,"qty":10517.57069111}],"checksum":2199306080,"timestamp":"2024-06-01T18:07:18.022934Z"}]}
{"channel":"book","type":"update","data":[{"symbol":"XRP/USDT","bids":[{"price":0.51902,"qty":10049.49355484}],"asks":[],"checksum":864737456,"timestamp":"2024-06-01T18:07:18.146862Z"}]}
{"channel":"book","type":"update","data":[{"symbol":"XRP/USDT","bids":[{"price":0.51899,"qty":10112.18140796}],"asks":[],"checksum":2020436244,"timestamp":"2024-06-01T18:07:18.147184Z"}]}
{"channel":"book","type":"update","data":[{"symbol":"XRP/USDT","bids":[{"price":0.51902,"qty":9641.68105484}],"asks":[],"checksum":3371241156,"timestamp":"2024-06-01T18:07:18.641498Z"}]}
{"channel":"book","type":"update","data":[{"symbol":"XRP/USDT","bids":[],"asks":[{"price":0.51912,"qty":407.81250000}],"checksum":2535379990,"timestamp":"2024-06-01T18:07:18.669668Z"}]}
{"channel":"book","type":"update","data":[{"symbol":"XRP/USDT","bids":[{"price":0.51900,"qty":407.81250000}],"asks":[],"checksum":4067453758,"timestamp":"2024-06-01T18:07:18.737195Z"}]}
{"channel":"book","type":"update","data":[{"symbol":"XRP/USDT","bids":[{"price":0.51900,"qty":0.00000000},{"price":0.51883,"qty":374.29601420}],"asks":[],"checksum":3941779237,"timestamp":"2024-06-01T18:07:18.737784Z"}]}
{"channel":"book","type":"update","data":[{"symbol":"XRP/USDT","bids":[{"price":0.51902,"qty":0.00000000},{"price":0.51881,"qty":9645.41687087}],"asks":[],"checksum":3418608781,"timestamp":"2024-06-01T18:07:18.750264Z"}]}
{"channel":"book","type":"update","data":[{"symbol":"XRP/USDT","bids":[],"asks":[{"price":0.51913,"qty":877.81250000}],"checksum":3870429446,"timestamp":"2024-06-01T18:07:18.750281Z"}]}
{"channel":"book","type":"update","data":[{"symbol":"XRP/USDT","bids":[],"asks":[{"price":0.51912,"qty":10047.79627627}],"checksum":1086766436,"timestamp":"2024-06-01T18:07:18.754873Z"}]}
{"channel":"book","type":"update","data":[{"symbol":"XRP/USDT","bids":[{"price":0.51900,"qty":9642.05612765}],"asks":[],"checksum":381889584,"timestamp":"2024-06-01T18:07:18.754934Z"}]}
{"channel":"book","type":"update","data":[{"symbol":"XRP/USDT","bids":[],"asks":[{"price":0.51909,"qty":407.81250000}],"checksum":153586594,"timestamp":"2024-06-01T18:07:18.758348Z"}]}
{"channel":"book","type":"update","data":[{"symbol":"XRP/USDT","bids":[],"asks":[{"price":0.51909,"qty":0.00000000},{"price":0.51936,"qty":3793.85432285}],"checksum":381889584,"timestamp":"2024-06-01T18:07:18.761159Z"}]}
{"channel":"book","type":"update","data":[{"symbol":"XRP/USDT","bids":[],"asks":[{"price":0.51913,"qty":470.00000000}],"checksum":2103001393,"timestamp":"2024-06-01T18:07:18.762081Z"}]}
{"channel":"book","type":"update","data":[{"symbol":"XRP/USDT","bids":[],"asks":[{"price":0.51909,"qty":407.81250000}],"checksum":954428698,"timestamp":"2024-06-01T18:07:18.762460Z"}]}
{"channel":"book","type":"update","data":[{"symbol":"XRP/USDT","bids":[],"asks":[{"price":0.51909,"qty":815.62500000}],"checksum":3371721106,"timestamp":"2024-06-01T18:07:18.772102Z"}]}
{"channel":"book","type":"update","data":[{"symbol":"XRP/USDT","bids":[{"price":0.51883,"qty":3386.04182285}],"asks":[],"checksum":3462368677,"timestamp":"2024-06-01T18:07:18.775788Z"}]}
{"channel":"book","type":"update","data":[{"symbol":"XRP/USDT","bids":[{"price":0.51900,"qty":0.00000000},{"price":0.51881,"qty":9645.41687087}],"asks":[],"checksum":2764021511,"timestamp":"2024-06-01T18:07:18.923879Z"}]}
{"channel":"book","type":"update","data":[{"symbol":"XRP/USDT","bids":[],"asks":[{"price":0.51917,"qty":0.00000000},{"price":0.51936,"qty":3793.85432285}],"checksum":781527817,"timestamp":"2024-06-01T18:07:18.924199Z"}]}
{"channel":"book","type":"update","data":[{"symbol":"XRP/USDT","bids":[{"price":0.51895,"qty":9642.92076372}],"asks":[],"checksum":3737670251,"timestamp":"2024-06-01T18:07:18.928438Z"}]}
{"channel":"book","type":"update","data":[{"symbol":"XRP/USDT","bids":[],"asks":[{"price":0.51913,"qty":0.00000000},{"price":0.51937,"qty":9635.19216179}],"checksum":3768974509,"timestamp":"2024-06-01T18:07:18.960793Z"}]}
{"channel":"book","type":"update","data":[{"symbol":"XRP/USDT","bids":[],"asks":[{"price":0.51911,"qty":470.00000000}],"checksum":3442054300,"timestamp":"2024-06-01T18:07:18.960964Z"}]}
{"channel":"book","type":"update","data":[{"symbol":"XRP/USDT","bids":[{"price":0.51888,"qty":0.00000000},{"price":0.51881,"qty":9645.41687087}],"asks":[],"checksum":2675009390,"timestamp":"2024-06-01T18:07:19.721010Z"}]}
{"channel":"book","type":"update","data":[{"symbol":"XRP/USDT","bids":[],"asks":[{"price":0.51910,"qty":9640.34338843}],"checksum":2563448706,"timestamp":"2024-06-01T18:07:19.972272Z"}]}
{"channel":"book","type":"update","data":[{"symbol":"XRP/USDT","bids":[{"price":0.51899,"qty":470.00000000}],"asks":[],"checksum":1150384419,"timestamp":"2024-06-01T18:07:20.086411Z"}]}
{"channel":"book","type":"update","data":[{"symbol":"XRP/USDT","bids":[{"price":0.51897,"qty":9642.52030103}],"asks":[],"checksum":137729880,"timestamp":"2024-06-01T18:07:20.090473Z"}]}
{"channel":"book","type":"update","data":[{"symbol":"XRP/USDT","bids":[],"asks":[{"price":0.51910,"qty":0.00000000},{"price":0.51936,"qty":3793.85432285}],"checksum":3104996793,"timestamp":"2024-06-01T18:07:20.394485Z"}]}
{"channel":"book","type":"update","data":[{"symbol":"XRP/USDT","bids":[],"asks":[{"price":0.51909,"qty":10456.10948282}],"checksum":802123910,"timestamp":"2024-06-01T18:07:21.094431Z"}]}
{"channel":"book","type":"update","data":[{"symbol":"XRP/USDT","bids":[{"price":0.51883,"qty":374.29601420}],"asks":[],"checksum":1453152985,"timestamp":"2024-06-01T18:07:21.444562Z"}]}
{"channel":"book","type":"update","data":[{"symbol":"XRP/USDT","bids":[{"price":0.51895,"qty":0.00000000},{"price":0.51880,"qty":12154.31109875}],"asks":[],"checksum":4131386215,"timestamp":"2024-06-01T18:07:21.448755Z"}]}
{"channel":"book","type":"update","data":[{"symbol":"XRP/USDT","bids":[],"asks":[{"price":0.51909,"qty":815.62500000}],"checksum":1625488984,"timestamp":"2024-06-01T18:07:21.448827Z"}]}
{"channel":"book","type":"update","data":[{"symbol":"XRP/USDT","bids":[{"price":0.51892,"qty":10051.37286179}],"asks":[],"checksum":3717534988,"timestamp":"2024-06-01T18:07:21.457047Z"}]}
{"channel":"book","type":"update","data":[{"symbol":"XRP/USDT","bids":[{"price":0.51899,"qty":0.00000000},{"price":0.51879,"qty":1609.38099461}],"asks":[],"checksum":3555634572,"timestamp":"2024-06-01T18:07:21.470263Z"}]}
{"channel":"book","type":"update","data":[{"symbol":"XRP/USDT","bids":[{"price":0.51892,"qty":9643.56036179}],"asks":[],"checksum":2755586605,"timestamp":"2024-06-01T18:07:21.474518Z"}]}
{"channel":"book","type":"update","data":[{"symbol":"XRP/USDT","bids":[{"price":0.51891,"qty":1743.89056000}],"asks":[],"checksum":85566678,"timestamp":"2024-06-01T18:07:21.478461Z"}]}
{"channel":"book","type":"update","data":[{"symbol":"XRP/USDT","bids":[],"asks":[{"price":0.51926,"qty":6011.74580865}],"checksum":1294984449,"timestamp":"2024-06-01T18:07:21.486183Z"}]}
{"channel":"book","type":"update","data":[{"symbol":"XRP/USDT","bids":[],"asks":[{"price":0.51911,"qty":0.00000000},{"price":0.51937,"qty":9635.19216179}],"checksum":1284495143,"timestamp":"2024-06-01T18:07:21.495996Z"}]}
{"channel":"book","type":"update","data":[{"symbol":"XRP/USDT","bids":[],"asks":[{"price":0.51908,"qty":470.00000000}],"checksum":3956761835,"timestamp":"2024-06-01T18:07:21.496101Z"}]}
{"channel":"book","type":"update","data":[{"symbol":"XRP/USDT","bids":[{"price":0.51891,"qty":1336.07806000}],"asks":[],"checksum":1257253392,"timestamp":"2024-06-01T18:07:21.500854Z"}]}
{"channel":"book","type":"update","data":[{"symbol":"XRP/USDT","bids":[],"asks":[{"price":0.51912,"qty":9639.98377627}],"checksum":4175501184,"timestamp":"2024-06-01T18:07:21.501734Z"}]}
{"channel":"book","type":"update","data":[{"symbol":"XRP/USDT","bids":[],"asks":[{"price":0.51903,"qty":407.81250000}],"checksum":2845597634,"timestamp":"2024-06-01T18:07:21.502061Z"}]}
{"channel":"book","type":"update","data":[{"symbol":"XRP/USDT","bids":[],"asks":[{"price":0.51906,"qty":407.81250000}],"checksum":344977140,"timestamp":"2024-06-01T18:07:21.502173Z"}]}
{"channel":"book","type":"update","data":[{"symbol":"XRP/USDT","bids":[],"asks":[{"price":0.51909,"qty":407.81250000}],"checksum":3663260562,"timestamp":"2024-06-01T18:07:21.507009Z"}]}
{"channel":"book","type":"update","data":[{"symbol":"XRP/USDT","bids":[],"asks":[{"price":0.51906,"qty":0.00000000},{"price":0.51934,"qty":1281.70000000}],"checksum":1431975122,"timestamp":"2024-06-01T18:07:21.507650Z"}]}
{"channel":"book","type":"update","data":[{"symbol":"XRP/USDT","bids":[],"asks":[{"price":0.51903,"qty":815.62500000}],"checksum":3066635468,"timestamp":"2024-06-01T18:07:21.507751Z"}]}
{"channel":"book","type":"update","data":[{"symbol":"XRP/USDT","bids":[{"price":0.51892,"qty":0.00000000},{"price":0.51874,"qty":407.81250000}],"asks":[],"checksum":3408565591,"timestamp":"2024-06-01T18:07:21.548659Z"}]}
{"channel":"book","type":"update","data":[{"symbol":"XRP/USDT","bids":[{"price":0.51898,"qty":9642.38367779}],"asks":[],"checksum":3244521002,"timestamp":"2024-06-01T18:07:21.552894Z"}]}
{"channel":"book","type":"update","data":[{"symbol":"XRP/USDT","bids":[],"asks":[{"price":0.51912,"qty":0.00000000},{"price":0.51936,"qty":782.10851420}],"checksum":3669315415,"timestamp":"2024-06-01T18:07:21.703321Z"}]}
{"channel":"book","type":"update","data":[{"symbol":"XRP/USDT","bids":[{"price":0.51898,"qty":0.00000000},{"price":0.51874,"qty":407.81250000}],"asks":[],"checksum":481727234,"timestamp":"2024-06-01T18:07:21.703333Z"}]}
{"channel":"book","type":"update","data":[{"symbol":"XRP/USDT","bids":[{"price":0.51897,"qty":0.00000000},{"price":0.51873,"qty":13942.22393425}],"asks":[],"checksum":326758536,"timestamp":"2024-06-01T18:07:21.703548Z"}]}
{"channel":"book","type":"update","data":[{"symbol":"XRP/USDT","bids":[{"price":0.51892,"qty":470.00000000}],"asks":[],"checksum":881659395,"timestamp":"2024-06-01T18:07:21.706591Z"}]}
{"channel":"book","type":"update","data":[{"symbol":"XRP/USDT","bids":[],"asks":[{"price":0.51907,"qty":9640.92893913}],"checksum":3564547614,"timestamp":"2024-06-01T18:07:21.708612Z"}]}
{"channel":"book","type":"update","data":[{"symbol":"XRP/USDT","bids":[],"asks":[{"price":0.51908,"qty":0.00000000},{"price":0.51936,"qty":782.10851420}],"checksum":385280167,"timestamp":"2024-06-01T18:07:21.711509Z"}]}
{"channel":"book","type":"update","data":[{"symbol":"XRP/USDT","bids":[],"asks":[{"price":0.51906,"qty":470.00000000}],"checksum":3524824656,"timestamp":"2024-06-01T18:07:21.711794Z"}]}
{"channel":"book","type":"update","data":[{"symbol":"XRP/USDT","bids":[],"asks":[{"price":0.51922,"qty":407.81250000}],"checksum":676302110,"timestamp":"2024-06-01T18:07:21.728233Z"}]}
{"channel":"book","type":"update","data":[{"symbol":"XRP/USDT","bids":[],"asks":[{"price":0.51918,"qty":9638.93639320}],"checksum":2033238793,"timestamp":"2024-06-01T18:07:21.731809Z"}]}
{"channel":"book","type":"update","data":[{"symbol":"XRP/USDT","bids":[{"price":0.51892,"qty":4301.80641855}],"asks":[],"checksum":71753439,"timestamp":"2024-06-01T18:07:21.850622Z"}]}
{"channel":"book","type":"update","data":[{"symbol":"XRP/USDT","bids":[{"price":0.51891,"qty":10979.80444394}],"asks":[],"checksum":983511755,"timestamp":"2024-06-01T18:07:21.969903Z"}]}
{"channel":"book","type":"update","data":[{"symbol":"XRP/USDT","bids":[{"price":0.51891,"qty":9643.72638394}],"asks":[],"checksum":4160770340,"timestamp":"2024-06-01T18:07:22.074024Z"}]}
{"channel":"book","type":"update","data":[{"symbol":"XRP/USDT","bids":[{"price":0.51882,"qty":1336.07806000}],"asks":[],"checksum":163659151,"timestamp":"2024-06-01T18:07:22.076694Z"}]}
{"channel":"book","type":"update","data":[{"symbol":"XRP/USDT","bids":[{"price":0.51896,"qty":9642.80424024}],"asks":[],"checksum":3169168802,"timestamp":"2024-06-01T18:07:22.191230Z"}]}
{"channel":"book","type":"update","data":[{"symbol":"XRP/USDT","bids":[],"asks":[{"price":0.51907,"qty":0.00000000},{"price":0.51934,"qty":1281.70000000}],"checksum":1858262629,"timestamp":"2024-06-01T18:07:22.262517Z"}]}
{"channel":"book","type":"update","data":[{"symbol":"XRP/USDT","bids":[],"asks":[{"price":0.51909,"qty":10048.39885762}],"checksum":1323324410,"timestamp":"2024-06-01T18:07:22.266422Z"}]}
{"channel":"book","type":"update","data":[{"symbol":"XRP/USDT","bids":[{"price":0.51892,"qty":470.00000000}],"asks":[],"checksum":2237265037,"timestamp":"2024-06-01T18:07:22.403727Z"}]}
{"channel":"book","type":"update","data":[{"symbol":"XRP/USDT","bids":[],"asks":[{"price":0.51909,"qty":407.81250000}],"checksum":3361331448,"timestamp":"2024-06-01T18:07:22.432226Z"}]}
{"channel":"book","type":"update","data":[{"symbol":"XRP/USDT","bids":[{"price":0.51896,"qty":13474.55590848}],"asks":[],"checksum":1873043300,"timestamp":"2024-06-01T18:07:22.444094Z"}]}
{"channel":"book","type":"update","data":[{"symbol":"XRP/USDT","bids":[],"asks":[{"price":0.51909,"qty":0.00000000},{"price":0.51936,"qty":782.10851420}],"checksum":3051357287,"timestamp":"2024-06-01T18:07:22.456969Z"}]}
{"channel":"book","type":"update","data":[{"symbol":"XRP/USDT","bids":[],"asks":[{"price":0.51906,"qty":0.00000000},{"price":0.51937,"qty":9635.19216179}],"checksum":794584569,"timestamp":"2024-06-01T18:07:22.459759Z"}]}
{"channel":"book","type":"update","data":[{"symbol":"XRP/USDT","bids":[],"asks":[{"price":0.51915,"qty":470.00000000}],"checksum":3201815212,"timestamp":"2024-06-01T18:07:22.460005Z"}]}
{"channel":"book","type":"update","data":[{"symbol":"XRP/USDT","bids":[],"asks":[{"price":0.51903,"qty":407.81250000}],"checksum":2856853052,"timestamp":"2024-06-01T18:07:22.463669Z"}]}
{"channel":"book","type":"update","data":[{"symbol":"XRP/USDT","bids":[{"price":0.51893,"qty":76.18676156}],"asks":[],"checksum":1195146264,"timestamp":"2024-06-01T18:07:22.508978Z"}]}
{"channel":"book","type":"update","data":[{"symbol":"XRP/USDT","bids":[],"asks":[{"price":0.51903,"qty":815.62500000}],"checksum":3644205582,"timestamp":"2024-06-01T18:07:22.625765Z"}]}
{"channel":"book","type":"update","data":[{"symbol":"XRP/USDT","bids":[{"price":0.51891,"qty":0.00000000},{"price":0.51880,"qty":12154.31109875}],"asks":[],"checksum":4092715989,"timestamp":"2024-06-01T18:07:23.267465Z"}]}
{"channel":"book","type":"update","data":[{"symbol":"XRP/USDT","bids":[{"price":0.51897,"qty":9642.53102936}],"asks":[],"checksum":319632088,"timestamp":"2024-06-01T18:07:23.271269Z"}]}
{"channel":"book","type":"update","data":[{"symbol":"XRP/USDT","bids":[],"asks":[{"price":0.51908,"qty":9640.79533416}],"checksum":399140340,"timestamp":"2024-06-01T18:07:23.271296Z"}]}
{"channel":"book","type":"update","data":[{"symbol":"XRP/USDT","bids":[],"asks":[{"price":0.51913,"qty":9639.73393130}],"checksum":1261344826,"timestamp":"2024-06-01T18:07:23.271320Z"}]}
{"channel":"book","type":"update","data":[{"symbol":"XRP/USDT","bids":[],"asks":[{"price":0.51915,"qty":0.00000000},{"price":0.51934,"qty":1281.70000000}],"checksum":2173081246,"timestamp":"2024-06-01T18:07:23.274080Z"}]}
{"channel":"book","type":"update","data":[{"symbol":"XRP/USDT","bids":[],"asks":[{"price":0.51907,"qty":470.00000000}],"checksum":2647515066,"timestamp":"2024-06-01T18:07:23.274277Z"}]}
{"channel":"book","type":"update","data":[{"symbol":"XRP/USDT","bids":[],"asks":[{"price":0.51903,"qty":407.81250000}],"checksum":1770479805,"timestamp":"2024-06-01T18:07:23.275133Z"}]}
{"channel":"book","type":"update","data":[{"symbol":"XRP/USDT","bids":[{"price":0.51891,"qty":407.81250000}],"asks":[],"checksum":722520499,"timestamp":"2024-06-01T18:07:23.276593Z"}]}
{"channel":"book","type":"update","data":[{"symbol":"XRP/USDT","bids":[],"asks":[{"price":0.51903,"qty":815.62500000}],"checksum":3038420901,"timestamp":"2024-06-01T18:07:23.278775Z"}]}
{"channel":"book","type":"update","data":[{"symbol":"XRP/USDT","bids":[{"price":0.51896,"qty":9642.80424024}],"asks":[],"checksum":2784771816,"timestamp":"2024-06-01T18:07:23.536147Z"}]}
{"channel":"book","type":"update","data":[{"symbol":"XRP/USDT","bids":[],"asks":[{"price":0.51903,"qty":407.81250000}],"checksum":3409939439,"timestamp":"2024-06-01T18:07:23.813462Z"}]}
{"channel":"book","type":"update","data":[{"symbol":"XRP/USDT","bids":[],"asks":[{"price":0.51903,"qty":0.00000000},{"price":0.51934,"qty":1281.70000000}],"checksum":3987437541,"timestamp":"2024-06-01T18:07:23.813968Z"}]}
{"channel":"book","type":"update","data":[{"symbol":"XRP/USDT","bids":[],"asks":[{"price":0.51905,"qty":407.81250000}],"checksum":676745862,"timestamp":"2024-06-01T18:07:23.817675Z"}]}
{"channel":"book","type":"update","data":[{"symbol":"XRP/USDT","bids":[],"asks":[{"price":0.51906,"qty":407.81250000}],"checksum":1293104977,"timestamp":"2024-06-01T18:07:23.818710Z"}]}
{"channel":"book","type":"update","data":[{"symbol":"XRP/USDT","bids":[{"price":0.51897,"qty":13474.27863758}],"asks":[],"checksum":1261084437,"timestamp":"2024-06-01T18:07:24.171779Z"}]}
{"channel":"book","type":"update","data":[{"symbol":"XRP/USDT","bids":[{"price":0.51897,"qty":9642.53102936}],"asks":[],"checksum":1293104977,"timestamp":"2024-06-01T18:07:24.737602Z"}]}
{"channel":"book","type":"update","data":[{"symbol":"XRP/USDT","bids":[{"price":0.51897,"qty":0.00000000},{"price":0.51882,"qty":1336.07806000}],"asks":[],"checksum":1927951368,"timestamp":"2024-06-01T18:07:25.279029Z"}]}
{"channel":"book","type":"update","data":[{"symbol":"XRP/USDT","bids":[],"asks":[{"price":0.51908,"qty":0.00000000},{"price":0.51931,"qty":1582.65411094}],"checksum":2152694919,"timestamp":"2024-06-01T18:07:25.279142Z"}]}
{"channel":"book","type":"update","data":[{"symbol":"XRP/USDT","bids":[],"asks":[{"price":0.51907,"qty":0.00000000},{"price":0.51934,"qty":1281.70000000}],"checksum":4087471652,"timestamp":"2024-06-01T18:07:25.282634Z"}]}
{"channel":"book","type":"update","data":[{"symbol":"XRP/USDT","bids":[],"asks":[{"price":0.51912,"qty":470.00000000}],"checksum":1108302681,"timestamp":"2024-06-01T18:07:25.282968Z"}]}
{"channel":"book","type":"update","data":[{"symbol":"XRP/USDT","bids":[{"price":0.51898,"qty":9642.44943937}],"asks":[],"checksum":1426576358,"timestamp":"2024-06-01T18:07:25.284467Z"}]}
{"channel":"book","type":"update","data":[{"symbol":"XRP/USDT","bids":[],"asks":[{"price":0.51910,"qty":9640.38776990}],"checksum":3465277467,"timestamp":"2024-06-01T18:07:25.284488Z"}]}
{"channel":"book","type":"update","data":[{"symbol":"XRP/USDT","bids":[],"asks":[{"price":0.51912,"qty":0.00000000},{"price":0.51931,"qty":1582.65411094}],"checksum":1485066876,"timestamp":"2024-06-01T18:07:25.287412Z"}]}
{"channel":"book","type":"update","data":[{"symbol":"XRP/USDT","bids":[],"asks":[{"price":0.51909,"qty":470.00000000}],"checksum":1193836151,"timestamp":"2024-06-01T18:07:25.287680Z"}]}
{"channel":"book","type":"update","data":[{"symbol":"XRP/USDT","bids":[{"price":0.51893,"qty":0.00000000},{"price":0.51882,"qty":1336.07806000}],"asks":[],"checksum":3390910487,"timestamp":"2024-06-01T18:07:25.422665Z"}]}
{"channel":"book","type":"update","data":[{"symbol":"XRP/USDT","bids":[{"price":0.51898,"qty":9681.01357374}],"asks":[],"checksum":1203857891,"timestamp":"2024-06-01T18:07:25.427899Z"}]}
{"channel":"book","type":"update","data":[{"symbol":"XRP/USDT","bids":[],"asks":[{"price":0.51925,"qty":374.29601420}],"checksum":1249057002,"timestamp":"2024-06-01T18:07:25.680552Z"}]}
{"channel":"book","type":"update","data":[{"symbol":"XRP/USDT","bids":[{"price":0.51898,"qty":9642.44943937}],"asks":[],"checksum":3350151454,"timestamp":"2024-06-01T18:07:28.127184Z"}]}
{"channel":"book","type":"update","data":[{"symbol":"XRP/USDT","bids":[{"price":0.51888,"qty":38.56413437}],"asks":[],"checksum":3691051575,"timestamp":"2024-06-01T18:07:28.133635Z"}]}
{"channel":"book","type":"update","data":[{"symbol":"XRP/USDT","bids":[],"asks":[{"price":0.51910,"qty":0.00000000},{"price":0.51928,"qty":407.81250000}],"checksum":2424695275,"timestamp":"2024-06-01T18:07:29.395329Z"}]}
{"channel":"book","type":"update","data":[{"symbol":"XRP/USDT","bids":[],"asks":[{"price":0.51909,"qty":0.00000000},{"price":0.51931,"qty":1582.65411094}],"checksum":1885894595,"timestamp":"2024-06-01T18:07:29.398245Z"}]}
{"channel":"book","type":"update","data":[{"symbol":"XRP/USDT","bids":[],"asks":[{"price":0.51912,"qty":470.00000000}],"checksum":1754841023,"timestamp":"2024-06-01T18:07:29.398680Z"}]}
{"channel":"book","type":"update","data":[{"symbol":"XRP/USDT","bids":[],"asks":[{"price":0.51909,"qty":9640.50824699}],"checksum":1296718262,"timestamp":"2024-06-01T18:07:29.399166Z"}]}
{"channel":"book","type":"update","data":[{"symbol":"XRP/USDT","bids":[],"asks":[{"price":0.51912,"qty":0.00000000},{"price":0.51928,"qty":407.81250000}],"checksum":2660906712,"timestamp":"2024-06-01T18:07:29.401819Z"}]}
{"channel":"book","type":"update","data":[{"symbol":"XRP/USDT","bids":[],"asks":[{"price":0.51908,"qty":470.00000000}],"checksum":959276952,"timestamp":"2024-06-01T18:07:29.401890Z"}]}
