{"channel":"book","type":"snapshot","data":[{"symbol":"XRP/BTC","bids":[{"price":0.00000766,"qty":5928.32073020},{"price":0.00000765,"qty":88281.21545047},{"price":0.00000764,"qty":98557.75888986},{"price":0.00000763,"qty":71133.47317066},{"price":0.00000762,"qty":27861.99064832},{"price":0.00000761,"qty":17828.73344448},{"price":0.00000760,"qty":37482.46836948},{"price":0.00000759,"qty":1085.69006902},{"price":0.00000758,"qty":430.64979825},{"price":0.00000757,"qty":394635.98036016}],"asks":[{"price":0.00000767,"qty":33268.82653852},{"price":0.00000768,"qty":123895.79695467},{"price":0.00000769,"qty":60605.87481275},{"price":0.00000770,"qty":27561.16578416},{"price":0.00000771,"qty":27750.33357504},{"price":0.00000772,"qty":17671.74086962},{"price":0.00000773,"qty":9154.47402989},{"price":0.00000774,"qty":8693.68328603},{"price":0.00000775,"qty":214327.84896478},{"price":0.00000776,"qty":868.46128644}],"checksum":1247507336}]}
{"channel":"book","type":"update","data":[{"symbol":"XRP/BTC","bids":[],"asks":[{"price":0.00000768,"qty":129175.20485834}],"checksum":2645952838,"timestamp":"2024-06-01T18:06:58.459782Z"}]}
{"channel":"book","type":"update","data":[{"symbol":"XRP/BTC","bids":[],"asks":[{"price":0.00000768,"qty":123895.79695467}],"checksum":1247507336,"timestamp":"2024-06-01T18:06:59.095694Z"}]}
{"channel":"book","type":"update","data":[{"symbol":"XRP/BTC","bids":[{"price":0.00000765,"qty":86646.10298931}],"asks":[],"checksum":1545553439,"timestamp":"2024-06-01T18:06:59.126923Z"}]}
{"channel":"book","type":"update","data":[{"symbol":"XRP/BTC","bids":[],"asks":[{"price":0.00000768,"qty":129175.20485834}],"checksum":2347908305,"timestamp":"2024-06-01T18:06:59.472502Z"}]}
{"channel":"book","type":"update","data":[{"symbol":"XRP/BTC","bids":[{"price":0.00000765,"qty":86179.95341858}],"asks":[],"checksum":1946438673,"timestamp":"2024-06-01T18:06:59.518665Z"}]}
{"channel":"book","type":"update","data":[{"symbol":"XRP/BTC","bids":[{"price":0.00000765,"qty":86738.51230884}],"asks":[],"checksum":958729259,"timestamp":"2024-06-01T18:06:59.521541Z"}]}
{"channel":"book","type":"update","data":[{"symbol":"XRP/BTC","bids":[],"asks":[{"price":0.00000768,"qty":123895.79695467}],"checksum":4006115045,"timestamp":"2024-06-01T18:06:59.652837Z"}]}
{"channel":"book","type":"update","data":[{"symbol":"XRP/BTC","bids":[],"asks":[{"price":0.00000768,"qty":129175.20485834}],"checksum":958729259,"timestamp":"2024-06-01T18:06:59.718724Z"}]}
{"channel":"book","type":"update","data":[{"symbol":"XRP/BTC","bids":[],"asks":[{"price":0.00000768,"qty":123895.79695467}],"checksum":4006115045,"timestamp":"2024-06-01T18:07:00.761320Z"}]}
{"channel":"book","type":"update","data":[{"symbol":"XRP/BTC","bids":[],"asks":[{"price":0.00000768,"qty":129175.20485834}],"checksum":958729259,"timestamp":"2024-06-01T18:07:00.866839Z"}]}
{"channel":"book","type":"update","data":[{"symbol":"XRP/BTC","bids":[],"asks":[{"price":0.00000768,"qty":123895.79695467}],"checksum":4006115045,"timestamp":"2024-06-01T18:07:00.998874Z"}]}
{"channel":"book","type":"update","data":[{"symbol":"XRP/BTC","bids":[{"price":0.00000765,"qty":38526.74583870}],"asks":[],"checksum":2868964048,"timestamp":"2024-06-01T18:07:01.751231Z"}]}
{"channel":"book","type":"update","data":[{"symbol":"XRP/BTC","bids":[{"price":0.00000765,"qty":37968.18694844}],"asks":[],"checksum":4097352890,"timestamp":"2024-06-01T18:07:01.932161Z"}]}
{"channel":"book","type":"update","data":[{"symbol":"XRP/BTC","bids":[{"price":0.00000765,"qty":38500.74126439}],"asks":[],"checksum":3247628455,"timestamp":"2024-06-01T18:07:01.934507Z"}]}
{"channel":"book","type":"update","data":[{"symbol":"XRP/BTC","bids":[{"price":0.00000765,"qty":40135.85372555}],"asks":[],"checksum":372089491,"timestamp":"2024-06-01T18:07:01.997779Z"}]}
{"channel":"book","type":"update","data":[{"symbol":"XRP/BTC","bids":[{"price":0.00000760,"qty":56762.19272711}],"asks":[],"checksum":1071028815,"timestamp":"2024-06-01T18:07:02.317119Z"}]}
{"channel":"book","type":"update","data":[{"symbol":"XRP/BTC","bids":[{"price":0.00000766,"qty":4964.16036510}],"asks":[],"checksum":1127835244,"timestamp":"2024-06-01T18:07:03.679298Z"}]}
{"channel":"book","type":"update","data":[{"symbol":"XRP/BTC","bids":[{"price":0.00000765,"qty":41100.20993043}],"asks":[],"checksum":1539283955,"timestamp":"2024-06-01T18:07:03.683091Z"}]}
{"channel":"book","type":"update","data":[{"symbol":"XRP/BTC","bids":[],"asks":[{"price":0.00000767,"qty":29268.82653852}],"checksum":1542826292,"timestamp":"2024-06-01T18:07:04.053001Z"}]}
{"channel":"book","type":"update","data":[{"symbol":"XRP/BTC","bids":[],"asks":[{"price":0.00000767,"qty":33268.82653852}],"checksum":1539283955,"timestamp":"2024-06-01T18:07:04.060296Z"}]}
{"channel":"book","type":"update","data":[{"symbol":"XRP/BTC","bids":[{"price":0.00000765,"qty":34100.20993043}],"asks":[],"checksum":2500596929,"timestamp":"2024-06-01T18:07:04.208315Z"}]}
{"channel":"book","type":"update","data":[{"symbol":"XRP/BTC","bids":[{"price":0.00000765,"qty":30100.20993043}],"asks":[],"checksum":2725905247,"timestamp":"2024-06-01T18:07:04.213326Z"}]}
{"channel":"book","type":"update","data":[{"symbol":"XRP/BTC","bids":[{"price":0.00000765,"qty":37100.20993043}],"asks":[],"checksum":1859262921,"timestamp":"2024-06-01T18:07:04.214934Z"}]}
{"channel":"book","type":"update","data":[{"symbol":"XRP/BTC","bids":[{"price":0.00000765,"qty":36567.65561448}],"asks":[],"checksum":2793855628,"timestamp":"2024-06-01T18:07:04.268888Z"}]}
{"channel":"book","type":"update","data":[{"symbol":"XRP/BTC","bids":[{"price":0.00000765,"qty":37490.20516265}],"asks":[],"checksum":3341274714,"timestamp":"2024-06-01T18:07:04.271670Z"}]}
{"channel":"book","type":"update","data":[{"symbol":"XRP/BTC","bids":[{"price":0.00000765,"qty":41490.20516265}],"asks":[],"checksum":4064955488,"timestamp":"2024-06-01T18:07:04.275410Z"}]}
{"channel":"book","type":"update","data":[{"symbol":"XRP/BTC","bids":[],"asks":[{"price":0.00000768,"qty":119750.08884929}],"checksum":1598952452,"timestamp":"2024-06-01T18:07:04.569404Z"}]}
{"channel":"book","type":"update","data":[{"symbol":"XRP/BTC","bids":[{"price":0.00000765,"qty":40525.84895777}],"asks":[],"checksum":3251459778,"timestamp":"2024-06-01T18:07:06.569775Z"}]}
{"channel":"book","type":"update","data":[{"symbol":"XRP/BTC","bids":[{"price":0.00000766,"qty":5928.33662550}],"asks":[],"checksum":4249507773,"timestamp":"2024-06-01T18:07:06.582050Z"}]}
{"channel":"book","type":"update","data":[{"symbol":"XRP/BTC","bids":[],"asks":[{"price":0.00000768,"qty":125029.49675296}],"checksum":2522943145,"timestamp":"2024-06-01T18:07:06.658041Z"}]}
{"channel":"book","type":"update","data":[{"symbol":"XRP/BTC","bids":[{"price":0.00000765,"qty":39603.29940960}],"asks":[],"checksum":1723213594,"timestamp":"2024-06-01T18:07:06.658227Z"}]}
{"channel":"book","type":"update","data":[{"symbol":"XRP/BTC","bids":[{"price":0.00000765,"qty":40551.87167759}],"asks":[],"checksum":3856728556,"timestamp":"2024-06-01T18:07:06.663038Z"}]}
{"channel":"book","type":"update","data":[{"symbol":"XRP/BTC","bids":[],"asks":[{"price":0.00000768,"qty":119750.08884929}],"checksum":2395625720,"timestamp":"2024-06-01T18:07:06.862372Z"}]}
{"channel":"book","type":"update","data":[{"symbol":"XRP/BTC","bids":[],"asks":[{"price":0.00000768,"qty":125029.49675296}],"checksum":3856728556,"timestamp":"2024-06-01T18:07:07.005495Z"}]}
{"channel":"book","type":"update","data":[{"symbol":"XRP/BTC","bids":[],"asks":[{"price":0.00000768,"qty":119750.08884929}],"checksum":2395625720,"timestamp":"2024-06-01T18:07:07.938398Z"}]}
{"channel":"book","type":"update","data":[{"symbol":"XRP/BTC","bids":[{"price":0.00000765,"qty":39603.29940960}],"asks":[],"checksum":228425230,"timestamp":"2024-06-01T18:07:09.066353Z"}]}
{"channel":"book","type":"update","data":[{"symbol":"XRP/BTC","bids":[{"price":0.00000765,"qty":40499.87550309}],"asks":[],"checksum":1695132683,"timestamp":"2024-06-01T18:07:09.071528Z"}]}
{"channel":"book","type":"update","data":[{"symbol":"XRP/BTC","bids":[],"asks":[{"price":0.00000767,"qty":33004.52928621}],"checksum":1095352110,"timestamp":"2024-06-01T18:07:09.127003Z"}]}
{"channel":"book","type":"update","data":[{"symbol":"XRP/BTC","bids":[],"asks":[{"price":0.00000767,"qty":33306.44878917}],"checksum":2485781225,"timestamp":"2024-06-01T18:07:09.128359Z"}]}
{"channel":"book","type":"update","data":[{"symbol":"XRP/BTC","bids":[{"price":0.00000766,"qty":4964.16036510}],"asks":[],"checksum":2829910934,"timestamp":"2024-06-01T18:07:11.443017Z"}]}
{"channel":"book","type":"update","data":[{"symbol":"XRP/BTC","bids":[{"price":0.00000765,"qty":41464.23704137}],"asks":[],"checksum":1568141374,"timestamp":"2024-06-01T18:07:11.447702Z"}]}
{"channel":"book","type":"update","data":[{"symbol":"XRP/BTC","bids":[{"price":0.00000765,"qty":40567.66094788}],"asks":[],"checksum":2742224968,"timestamp":"2024-06-01T18:07:11.473850Z"}]}
{"channel":"book","type":"update","data":[{"symbol":"XRP/BTC","bids":[{"price":0.00000765,"qty":41490.24329593}],"asks":[],"checksum":557444317,"timestamp":"2024-06-01T18:07:11.479288Z"}]}
{"channel":"book","type":"update","data":[{"symbol":"XRP/BTC","bids":[{"price":0.00000765,"qty":40567.66094788}],"asks":[],"checksum":2742224968,"timestamp":"2024-06-01T18:07:13.819251Z"}]}
{"channel":"book","type":"update","data":[{"symbol":"XRP/BTC","bids":[{"price":0.00000765,"qty":41542.23321582}],"asks":[],"checksum":3375651964,"timestamp":"2024-06-01T18:07:13.824021Z"}]}
{"channel":"book","type":"update","data":[{"symbol":"XRP/BTC","bids":[],"asks":[{"price":0.00000767,"qty":33004.52928621}],"checksum":475521467,"timestamp":"2024-06-01T18:07:14.010890Z"}]}
{"channel":"book","type":"update","data":[{"symbol":"XRP/BTC","bids":[],"asks":[{"price":0.00000767,"qty":33268.82918370}],"checksum":78773604,"timestamp":"2024-06-01T18:07:14.011655Z"}]}
{"channel":"book","type":"update","data":[{"symbol":"XRP/BTC","bids":[{"price":0.00000765,"qty":89750.18312692}],"asks":[],"checksum":1008153869,"timestamp":"2024-06-01T18:07:14.105956Z"}]}
{"channel":"book","type":"update","data":[{"symbol":"XRP/BTC","bids":[{"price":0.00000765,"qty":88775.61085898}],"asks":[],"checksum":3247142140,"timestamp":"2024-06-01T18:07:16.228686Z"}]}
{"channel":"book","type":"update","data":[{"symbol":"XRP/BTC","bids":[{"price":0.00000765,"qty":89360.17227205}],"asks":[],"checksum":398215946,"timestamp":"2024-06-01T18:07:16.234568Z"}]}
{"channel":"book","type":"update","data":[{"symbol":"XRP/BTC","bids":[{"price":0.00000760,"qty":37482.46836948}],"asks":[],"checksum":1044870102,"timestamp":"2024-06-01T18:07:17.788590Z"}]}
{"channel":"book","type":"update","data":[{"symbol":"XRP/BTC","bids":[{"price":0.00000765,"qty":41152.22236095}],"asks":[],"checksum":2538712931,"timestamp":"2024-06-01T18:07:18.452243Z"}]}
{"channel":"book","type":"update","data":[{"symbol":"XRP/BTC","bids":[{"price":0.00000764,"qty":92008.45427345},{"price":0.00000765,"qty":50509.26572018}],"asks":[],"checksum":1234552832,"timestamp":"2024-06-01T18:07:18.571194Z"}]}
{"channel":"book","type":"update","data":[{"symbol":"XRP/BTC","bids":[{"price":0.00000765,"qty":49924.70430711}],"asks":[],"checksum":2187775129,"timestamp":"2024-06-01T18:07:18.583180Z"}]}
{"channel":"book","type":"update","data":[{"symbol":"XRP/BTC","bids":[{"price":0.00000765,"qty":50535.26326533}],"asks":[],"checksum":3165433683,"timestamp":"2024-06-01T18:07:18.588392Z"}]}
{"channel":"book","type":"update","data":[{"symbol":"XRP/BTC","bids":[{"price":0.00000757,"qty":413915.47293921}],"asks":[],"checksum":2273626821,"timestamp":"2024-06-01T18:07:19.013659Z"}]}
{"channel":"book","type":"update","data":[{"symbol":"XRP/BTC","bids":[{"price":0.00000765,"qty":49924.70430711}],"asks":[],"checksum":3108940047,"timestamp":"2024-06-01T18:07:21.032640Z"}]}
{"channel":"book","type":"update","data":[{"symbol":"XRP/BTC","bids":[{"price":0.00000765,"qty":51003.29046966}],"asks":[],"checksum":3905634743,"timestamp":"2024-06-01T18:07:21.037318Z"}]}
{"channel":"book","type":"update","data":[{"symbol":"XRP/BTC","bids":[{"price":0.00000763,"qty":61390.89317066},{"price":0.00000763,"qty":71573.88317066}],"asks":[],"checksum":2764158092,"timestamp":"2024-06-01T18:07:21.502213Z"}]}
{"channel":"book","type":"update","data":[{"symbol":"XRP/BTC","bids":[],"asks":[{"price":0.00000768,"qty":109535.06884929},{"price":0.00000769,"qty":71933.42481275}],"checksum":527738556,"timestamp":"2024-06-01T18:07:21.502262Z"}]}
{"channel":"book","type":"update","data":[{"symbol":"XRP/BTC","bids":[],"asks":[{"price":0.00000767,"qty":33004.52928621}],"checksum":127056483,"timestamp":"2024-06-01T18:07:21.529427Z"}]}
{"channel":"book","type":"update","data":[{"symbol":"XRP/BTC","bids":[],"asks":[{"price":0.00000767,"qty":33344.07443808}],"checksum":809864174,"timestamp":"2024-06-01T18:07:21.531187Z"}]}
{"channel":"book","type":"update","data":[{"symbol":"XRP/BTC","bids":[{"price":0.00000765,"qty":50038.92893138}],"asks":[],"checksum":3307522786,"timestamp":"2024-06-01T18:07:21.583975Z"}]}
{"channel":"book","type":"update","data":[{"symbol":"XRP/BTC","bids":[{"price":0.00000766,"qty":5928.43786083}],"asks":[],"checksum":2036888126,"timestamp":"2024-06-01T18:07:21.587481Z"}]}
{"channel":"book","type":"update","data":[{"symbol":"XRP/BTC","bids":[{"price":0.00000766,"qty":4964.16036510}],"asks":[],"checksum":3307522786,"timestamp":"2024-06-01T18:07:21.702619Z"}]}
{"channel":"book","type":"update","data":[{"symbol":"XRP/BTC","bids":[{"price":0.00000765,"qty":51003.39362550}],"asks":[],"checksum":813139406,"timestamp":"2024-06-01T18:07:21.707454Z"}]}
{"channel":"book","type":"update","data":[{"symbol":"XRP/BTC","bids":[{"price":0.00000765,"qty":50038.92893138}],"asks":[],"checksum":3307522786,"timestamp":"2024-06-01T18:07:22.508463Z"}]}
{"channel":"book","type":"update","data":[{"symbol":"XRP/BTC","bids":[{"price":0.00000766,"qty":5928.47076374}],"asks":[],"checksum":3261784137,"timestamp":"2024-06-01T18:07:22.511959Z"}]}
{"channel":"book","type":"update","data":[{"symbol":"XRP/BTC","bids":[],"asks":[{"price":0.00000768,"qty":114814.47675296}],"checksum":1281977659,"timestamp":"2024-06-01T18:07:23.134193Z"}]}
{"channel":"book","type":"update","data":[{"symbol":"XRP/BTC","bids":[{"price":0.00000765,"qty":48960.34276883}],"asks":[],"checksum":2292338185,"timestamp":"2024-06-01T18:07:23.449561Z"}]}
{"channel":"book","type":"update","data":[{"symbol":"XRP/BTC","bids":[{"price":0.00000765,"qty":49778.79394965}],"asks":[],"checksum":3707336169,"timestamp":"2024-06-01T18:07:23.457039Z"}]}
{"channel":"book","type":"update","data":[{"symbol":"XRP/BTC","bids":[{"price":0.00000757,"qty":394635.98036016}],"asks":[],"checksum":3889238143,"timestamp":"2024-06-01T18:07:24.000698Z"}]}
{"channel":"book","type":"update","data":[{"symbol":"XRP/BTC","bids":[],"asks":[{"price":0.00000767,"qty":33004.52928621}],"checksum":3490062834,"timestamp":"2024-06-01T18:07:24.015744Z"}]}
{"channel":"book","type":"update","data":[{"symbol":"XRP/BTC","bids":[],"asks":[{"price":0.00000767,"qty":33231.20655652}],"checksum":1123705597,"timestamp":"2024-06-01T18:07:24.016668Z"}]}
{"channel":"book","type":"update","data":[{"symbol":"XRP/BTC","bids":[{"price":0.00000760,"qty":56762.30335816}],"asks":[],"checksum":4119253647,"timestamp":"2024-06-01T18:07:24.040907Z"}]}
{"channel":"book","type":"update","data":[{"symbol":"XRP/BTC","bids":[{"price":0.00000765,"qty":48960.34276883}],"asks":[],"checksum":2715674991,"timestamp":"2024-06-01T18:07:25.920749Z"}]}
{"channel":"book","type":"update","data":[{"symbol":"XRP/BTC","bids":[{"price":0.00000765,"qty":49674.80901013}],"asks":[],"checksum":763287587,"timestamp":"2024-06-01T18:07:25.925612Z"}]}
{"channel":"book","type":"update","data":[{"symbol":"XRP/BTC","bids":[{"price":0.00000765,"qty":48960.34276883}],"asks":[],"checksum":2715674991,"timestamp":"2024-06-01T18:07:28.269648Z"}]}
{"channel":"book","type":"update","data":[{"symbol":"XRP/BTC","bids":[{"price":0.00000765,"qty":49648.81277524}],"asks":[],"checksum":2169007026,"timestamp":"2024-06-01T18:07:28.273612Z"}]}
