{"channel":"book","type":"snapshot","data":[{"symbol":"XRP/GBP","bids":[{"price":0.40682,"qty":482.10512671},{"price":0.40679,"qty":675.01184533},{"price":0.40675,"qty":964.37398807},{"price":0.40664,"qty":1500.29190957},{"price":0.40662,"qty":964.70579257},{"price":0.40646,"qty":4822.91089905},{"price":0.40645,"qty":2895.26500298},{"price":0.40642,"qty":2011.04404777},{"price":0.40639,"qty":4826.22758212},{"price":0.40637,"qty":1018.21471200}],"asks":[{"price":0.40691,"qty":482.01522512},{"price":0.40693,"qty":220.00000000},{"price":0.40694,"qty":674.76303278},{"price":0.40700,"qty":963.82728318},{"price":0.40711,"qty":812.30105047},{"price":0.40712,"qty":22228.59733663},{"price":0.40717,"qty":1737.00000000},{"price":0.40726,"qty":2889.63759376},{"price":0.40729,"qty":6826.58715077},{"price":0.40740,"qty":5000.00000000}],"checksum":819370646}]}
{"channel":"book","type":"update","data":[{"symbol":"XRP/GBP","bids":[],"asks":[{"price":0.40691,"qty":0.00000000},{"price":0.40746,"qty":583.41282844}],"checksum":4123836302,"timestamp":"2024-06-01T18:06:58.477115Z"}]}
{"channel":"book","type":"update","data":[{"symbol":"XRP/GBP","bids":[],"asks":[{"price":0.40690,"qty":482.02116271}],"checksum":705546877,"timestamp":"2024-06-01T18:06:58.482354Z"}]}
{"channel":"book","type":"update","data":[{"symbol":"XRP/GBP","bids":[],"asks":[{"price":0.40690,"qty":0.00000000},{"price":0.40746,"qty":583.41282844}],"checksum":4123836302,"timestamp":"2024-06-01T18:07:00.249026Z"}]}
{"channel":"book","type":"update","data":[{"symbol":"XRP/GBP","bids":[],"asks":[{"price":0.40692,"qty":482.00295414}],"checksum":2096454549,"timestamp":"2024-06-01T18:07:00.254060Z"}]}
{"channel":"book","type":"update","data":[{"symbol":"XRP/GBP","bids":[],"asks":[{"price":0.40692,"qty":0.00000000},{"price":0.40746,"qty":583.41282844}],"checksum":4123836302,"timestamp":"2024-06-01T18:07:00.379017Z"}]}
{"channel":"book","type":"update","data":[{"symbol":"XRP/GBP","bids":[{"price":0.40682,"qty":0.00000000},{"price":0.40629,"qty":1032.83152113}],"asks":[],"checksum":2008515979,"timestamp":"2024-06-01T18:07:00.770047Z"}]}
{"channel":"book","type":"update","data":[{"symbol":"XRP/GBP","bids":[{"price":0.40680,"qty":482.13184629}],"asks":[],"checksum":1428442090,"timestamp":"2024-06-01T18:07:00.775290Z"}]}
{"channel":"book","type":"update","data":[{"symbol":"XRP/GBP","bids":[],"asks":[{"price":0.40694,"qty":0.00000000},{"price":0.40747,"qty":12145.20305669}],"checksum":967821682,"timestamp":"2024-06-01T18:07:01.160042Z"}]}
{"channel":"book","type":"update","data":[{"symbol":"XRP/GBP","bids":[],"asks":[{"price":0.40693,"qty":0.00000000},{"price":0.40753,"qty":1018.21471200}],"checksum":2329769215,"timestamp":"2024-06-01T18:07:01.162712Z"}]}
{"channel":"book","type":"update","data":[{"symbol":"XRP/GBP","bids":[],"asks":[{"price":0.40698,"qty":220.00000000}],"checksum":3973336719,"timestamp":"2024-06-01T18:07:01.162781Z"}]}
{"channel":"book","type":"update","data":[{"symbol":"XRP/GBP","bids":[],"asks":[{"price":0.40692,"qty":674.79619719}],"checksum":766548074,"timestamp":"2024-06-01T18:07:01.164099Z"}]}
{"channel":"book","type":"update","data":[{"symbol":"XRP/GBP","bids":[{"price":0.40675,"qty":0.00000000},{"price":0.40629,"qty":1032.83152113}],"asks":[],"checksum":287405235,"timestamp":"2024-06-01T18:07:01.877915Z"}]}
{"channel":"book","type":"update","data":[{"symbol":"XRP/GBP","bids":[{"price":0.40679,"qty":0.00000000},{"price":0.40628,"qty":30786.27990000}],"asks":[],"checksum":1723998685,"timestamp":"2024-06-01T18:07:01.878095Z"}]}
{"channel":"book","type":"update","data":[{"symbol":"XRP/GBP","bids":[],"asks":[{"price":0.40689,"qty":482.04452195}],"checksum":2472795779,"timestamp":"2024-06-01T18:07:01.882645Z"}]}
{"channel":"book","type":"update","data":[{"symbol":"XRP/GBP","bids":[{"price":0.40676,"qty":675.05660965}],"asks":[],"checksum":188289275,"timestamp":"2024-06-01T18:07:01.882748Z"}]}
{"channel":"book","type":"update","data":[{"symbol":"XRP/GBP","bids":[{"price":0.40670,"qty":964.49430711}],"asks":[],"checksum":235718439,"timestamp":"2024-06-01T18:07:01.882823Z"}]}
{"channel":"book","type":"update","data":[{"symbol":"XRP/GBP","bids":[],"asks":[{"price":0.40729,"qty":4815.64317245}],"checksum":2100088837,"timestamp":"2024-06-01T18:07:02.453936Z"}]}
{"channel":"book","type":"update","data":[{"symbol":"XRP/GBP","bids":[],"asks":[{"price":0.40689,"qty":0.00000000},{"price":0.40746,"qty":583.41282844}],"checksum":1039183994,"timestamp":"2024-06-01T18:07:02.993533Z"}]}
{"channel":"book","type":"update","data":[{"symbol":"XRP/GBP","bids":[],"asks":[{"price":0.40692,"qty":0.00000000},{"price":0.40747,"qty":12145.20305669}],"checksum":3980193045,"timestamp":"2024-06-01T18:07:02.998217Z"}]}
{"channel":"book","type":"update","data":[{"symbol":"XRP/GBP","bids":[],"asks":[{"price":0.40688,"qty":482.04666112}],"checksum":1929749264,"timestamp":"2024-06-01T18:07:02.998299Z"}]}
{"channel":"book","type":"update","data":[{"symbol":"XRP/GBP","bids":[{"price":0.40680,"qty":0.00000000},{"price":0.40629,"qty":1032.83152113}],"asks":[],"checksum":2113326636,"timestamp":"2024-06-01T18:07:03.032374Z"}]}
{"channel":"book","type":"update","data":[{"symbol":"XRP/GBP","bids":[{"price":0.40679,"qty":482.15036707}],"asks":[],"checksum":881424677,"timestamp":"2024-06-01T18:07:03.038419Z"}]}
{"channel":"book","type":"update","data":[{"symbol":"XRP/GBP","bids":[{"price":0.40646,"qty":0.00000000},{"price":0.40629,"qty":1032.83152113}],"asks":[],"checksum":2688363755,"timestamp":"2024-06-01T18:07:03.485658Z"}]}
{"channel":"book","type":"update","data":[{"symbol":"XRP/GBP","bids":[{"price":0.40679,"qty":0.00000000},{"price":0.40628,"qty":30786.27990000}],"asks":[],"checksum":588302813,"timestamp":"2024-06-01T18:07:03.638013Z"}]}
{"channel":"book","type":"update","data":[{"symbol":"XRP/GBP","bids":[],"asks":[{"price":0.40688,"qty":0.00000000},{"price":0.40747,"qty":12145.20305669}],"checksum":3473133366,"timestamp":"2024-06-01T18:07:03.638028Z"}]}
{"channel":"book","type":"update","data":[{"symbol":"XRP/GBP","bids":[{"price":0.40676,"qty":0.00000000},{"price":0.40625,"qty":1885.71669300}],"asks":[],"checksum":620785713,"timestamp":"2024-06-01T18:07:03.642303Z"}]}
{"channel":"book","type":"update","data":[{"symbol":"XRP/GBP","bids":[{"price":0.40670,"qty":0.00000000},{"price":0.40594,"qty":3781.90474200}],"asks":[],"checksum":488108961,"timestamp":"2024-06-01T18:07:03.646814Z"}]}
{"channel":"book","type":"update","data":[{"symbol":"XRP/GBP","bids":[],"asks":[{"price":0.40697,"qty":674.71329229}],"checksum":2547877738,"timestamp":"2024-06-01T18:07:03.650767Z"}]}
{"channel":"book","type":"update","data":[{"symbol":"XRP/GBP","bids":[],"asks":[{"price":0.40698,"qty":0.00000000},{"price":0.40747,"qty":12145.20305669}],"checksum":3121371597,"timestamp":"2024-06-01T18:07:03.653386Z"}]}
{"channel":"book","type":"update","data":[{"symbol":"XRP/GBP","bids":[],"asks":[{"price":0.40695,"qty":220.00000000}],"checksum":3392792086,"timestamp":"2024-06-01T18:07:03.653568Z"}]}
{"channel":"book","type":"update","data":[{"symbol":"XRP/GBP","bids":[],"asks":[{"price":0.40697,"qty":0.00000000},{"price":0.40747,"qty":12145.20305669}],"checksum":3752421754,"timestamp":"2024-06-01T18:07:03.655298Z"}]}
{"channel":"book","type":"update","data":[{"symbol":"XRP/GBP","bids":[{"price":0.40646,"qty":4823.11289859}],"asks":[],"checksum":2641942818,"timestamp":"2024-06-01T18:07:03.685330Z"}]}
{"channel":"book","type":"update","data":[{"symbol":"XRP/GBP","bids":[{"price":0.40665,"qty":113.08000000}],"asks":[],"checksum":1317425882,"timestamp":"2024-06-01T18:07:03.720860Z"}]}
{"channel":"book","type":"update","data":[{"symbol":"XRP/GBP","bids":[{"price":0.40666,"qty":675.22763134}],"asks":[],"checksum":2080994469,"timestamp":"2024-06-01T18:07:03.884846Z"}]}
{"channel":"book","type":"update","data":[{"symbol":"XRP/GBP","bids":[{"price":0.40666,"qty":0.00000000},{"price":0.40628,"qty":30786.27990000}],"asks":[],"checksum":1317425882,"timestamp":"2024-06-01T18:07:03.888763Z"}]}
{"channel":"book","type":"update","data":[{"symbol":"XRP/GBP","bids":[],"asks":[{"price":0.40691,"qty":482.01682082}],"checksum":2414175379,"timestamp":"2024-06-01T18:07:04.033698Z"}]}
{"channel":"book","type":"update","data":[{"symbol":"XRP/GBP","bids":[{"price":0.40681,"qty":482.12023105}],"asks":[],"checksum":503494006,"timestamp":"2024-06-01T18:07:04.038070Z"}]}
{"channel":"book","type":"update","data":[{"symbol":"XRP/GBP","bids":[{"price":0.40681,"qty":0.00000000},{"price":0.40628,"qty":30786.27990000}],"asks":[],"checksum":2414175379,"timestamp":"2024-06-01T18:07:04.843351Z"}]}
{"channel":"book","type":"update","data":[{"symbol":"XRP/GBP","bids":[{"price":0.40664,"qty":220.00000000}],"asks":[],"checksum":3239294753,"timestamp":"2024-06-01T18:07:04.846166Z"}]}
{"channel":"book","type":"update","data":[{"symbol":"XRP/GBP","bids":[{"price":0.40664,"qty":2404.32244046}],"asks":[],"checksum":3895978959,"timestamp":"2024-06-01T18:07:04.849154Z"}]}
{"channel":"book","type":"update","data":[{"symbol":"XRP/GBP","bids":[{"price":0.40673,"qty":964.43266105}],"asks":[],"checksum":354579313,"timestamp":"2024-06-01T18:07:04.896039Z"}]}
{"channel":"book","type":"update","data":[{"symbol":"XRP/GBP","bids":[{"price":0.40681,"qty":482.11654291}],"asks":[],"checksum":1138343219,"timestamp":"2024-06-01T18:07:05.046378Z"}]}
{"channel":"book","type":"update","data":[{"symbol":"XRP/GBP","bids":[{"price":0.40646,"qty":0.00000000},{"price":0.40629,"qty":1032.83152113}],"asks":[],"checksum":1803612127,"timestamp":"2024-06-01T18:07:05.182273Z"}]}
{"channel":"book","type":"update","data":[{"symbol":"XRP/GBP","bids":[{"price":0.40646,"qty":4823.13056914}],"asks":[],"checksum":4179711192,"timestamp":"2024-06-01T18:07:05.713570Z"}]}
{"channel":"book","type":"update","data":[{"symbol":"XRP/GBP","bids":[],"asks":[{"price":0.40694,"qty":674.76303278}],"checksum":2967377713,"timestamp":"2024-06-01T18:07:05.767448Z"}]}
{"channel":"book","type":"update","data":[{"symbol":"XRP/GBP","bids":[],"asks":[{"price":0.40695,"qty":0.00000000},{"price":0.40746,"qty":583.41282844}],"checksum":3565646621,"timestamp":"2024-06-01T18:07:05.770066Z"}]}
{"channel":"book","type":"update","data":[{"symbol":"XRP/GBP","bids":[],"asks":[{"price":0.40693,"qty":220.00000000}],"checksum":3888557813,"timestamp":"2024-06-01T18:07:05.770467Z"}]}
{"channel":"book","type":"update","data":[{"symbol":"XRP/GBP","bids":[{"price":0.40646,"qty":0.00000000},{"price":0.40629,"qty":1032.83152113}],"asks":[],"checksum":1969690098,"timestamp":"2024-06-01T18:07:05.873753Z"}]}
{"channel":"book","type":"update","data":[{"symbol":"XRP/GBP","bids":[{"price":0.40681,"qty":0.00000000},{"price":0.40628,"qty":30786.27990000}],"asks":[],"checksum":2562923135,"timestamp":"2024-06-01T18:07:05.989055Z"}]}
{"channel":"book","type":"update","data":[{"symbol":"XRP/GBP","bids":[{"price":0.40678,"qty":675.01332813}],"asks":[],"checksum":1513737522,"timestamp":"2024-06-01T18:07:05.993070Z"}]}
{"channel":"book","type":"update","data":[{"symbol":"XRP/GBP","bids":[{"price":0.40678,"qty":0.00000000},{"price":0.40628,"qty":30786.27990000}],"asks":[],"checksum":2562923135,"timestamp":"2024-06-01T18:07:05.997149Z"}]}
{"channel":"book","type":"update","data":[{"symbol":"XRP/GBP","bids":[{"price":0.40665,"qty":0.00000000},{"price":0.40625,"qty":1885.71669300}],"asks":[],"checksum":1783646118,"timestamp":"2024-06-01T18:07:06.025187Z"}]}
{"channel":"book","type":"update","data":[{"symbol":"XRP/GBP","bids":[{"price":0.40674,"qty":482.21058830}],"asks":[],"checksum":4129538631,"timestamp":"2024-06-01T18:07:06.089191Z"}]}
{"channel":"book","type":"update","data":[{"symbol":"XRP/GBP","bids":[{"price":0.40674,"qty":0.00000000},{"price":0.40625,"qty":1885.71669300}],"asks":[],"checksum":1783646118,"timestamp":"2024-06-01T18:07:06.093524Z"}]}
{"channel":"book","type":"update","data":[{"symbol":"XRP/GBP","bids":[{"price":0.40646,"qty":4823.09986745}],"asks":[],"checksum":2117908837,"timestamp":"2024-06-01T18:07:06.174300Z"}]}
{"channel":"book","type":"update","data":[{"symbol":"XRP/GBP","bids":[],"asks":[{"price":0.40691,"qty":0.00000000},{"price":0.40746,"qty":583.41282844}],"checksum":1419551719,"timestamp":"2024-06-01T18:07:06.179310Z"}]}
{"channel":"book","type":"update","data":[{"symbol":"XRP/GBP","bids":[],"asks":[{"price":0.40690,"qty":482.02279685}],"checksum":250428133,"timestamp":"2024-06-01T18:07:06.183896Z"}]}
{"channel":"book","type":"update","data":[{"symbol":"XRP/GBP","bids":[{"price":0.40673,"qty":0.00000000},{"price":0.40625,"qty":1885.71669300}],"asks":[],"checksum":1318483116,"timestamp":"2024-06-01T18:07:06.562620Z"}]}
{"channel":"book","type":"update","data":[{"symbol":"XRP/GBP","bids":[],"asks":[{"price":0.40690,"qty":0.00000000},{"price":0.40746,"qty":583.41282844}],"checksum":2697094169,"timestamp":"2024-06-01T18:07:06.562631Z"}]}
{"channel":"book","type":"update","data":[{"symbol":"XRP/GBP","bids":[],"asks":[{"price":0.40694,"qty":0.00000000},{"price":0.40747,"qty":12145.20305669}],"checksum":3307125346,"timestamp":"2024-06-01T18:07:06.576414Z"}]}
{"channel":"book","type":"update","data":[{"symbol":"XRP/GBP","bids":[],"asks":[{"price":0.40693,"qty":0.00000000},{"price":0.40753,"qty":1018.21471200}],"checksum":2947399672,"timestamp":"2024-06-01T18:07:06.580442Z"}]}
{"channel":"book","type":"update","data":[{"symbol":"XRP/GBP","bids":[],"asks":[{"price":0.40698,"qty":220.00000000}],"checksum":1864040315,"timestamp":"2024-06-01T18:07:06.581114Z"}]}
{"channel":"book","type":"update","data":[{"symbol":"XRP/GBP","bids":[],"asks":[{"price":0.40746,"qty":0.00000000},{"price":0.40753,"qty":1018.21471200}],"checksum":2736780417,"timestamp":"2024-06-01T18:07:06.583478Z"}]}
{"channel":"book","type":"update","data":[{"symbol":"XRP/GBP","bids":[],"asks":[{"price":0.40746,"qty":583.41282844}],"checksum":1864040315,"timestamp":"2024-06-01T18:07:06.592217Z"}]}
{"channel":"book","type":"update","data":[{"symbol":"XRP/GBP","bids":[{"price":0.40646,"qty":0.00000000},{"price":0.40594,"qty":3781.90474200}],"asks":[],"checksum":2441571654,"timestamp":"2024-06-01T18:07:06.595689Z"}]}
{"channel":"book","type":"update","data":[{"symbol":"XRP/GBP","bids":[{"price":0.40663,"qty":4381.11265516}],"asks":[],"checksum":285751882,"timestamp":"2024-06-01T18:07:06.595823Z"}]}
{"channel":"book","type":"update","data":[{"symbol":"XRP/GBP","bids":[{"price":0.40665,"qty":113.08000000}],"asks":[],"checksum":3295516867,"timestamp":"2024-06-01T18:07:06.602936Z"}]}
{"channel":"book","type":"update","data":[{"symbol":"XRP/GBP","bids":[{"price":0.40663,"qty":0.00000000},{"price":0.40625,"qty":1885.71669300}],"asks":[],"checksum":372575597,"timestamp":"2024-06-01T18:07:06.644133Z"}]}
{"channel":"book","type":"update","data":[{"symbol":"XRP/GBP","bids":[{"price":0.40666,"qty":482.30545096}],"asks":[],"checksum":2161523587,"timestamp":"2024-06-01T18:07:07.185114Z"}]}
{"channel":"book","type":"update","data":[{"symbol":"XRP/GBP","bids":[],"asks":[{"price":0.40692,"qty":482.00458613}],"checksum":2923185727,"timestamp":"2024-06-01T18:07:07.185151Z"}]}
{"channel":"book","type":"update","data":[{"symbol":"XRP/GBP","bids":[{"price":0.40666,"qty":0.00000000},{"price":0.40625,"qty":1885.71669300}],"asks":[],"checksum":3570145463,"timestamp":"2024-06-01T18:07:07.190870Z"}]}
{"channel":"book","type":"update","data":[{"symbol":"XRP/GBP","bids":[],"asks":[{"price":0.40746,"qty":0.00000000},{"price":0.40747,"qty":12145.20305669}],"checksum":2319136174,"timestamp":"2024-06-01T18:07:07.732942Z"}]}
{"channel":"book","type":"update","data":[{"symbol":"XRP/GBP","bids":[],"asks":[{"price":0.40746,"qty":583.41282844}],"checksum":3570145463,"timestamp":"2024-06-01T18:07:07.829697Z"}]}
{"channel":"book","type":"update","data":[{"symbol":"XRP/GBP","bids":[],"asks":[{"price":0.40695,"qty":674.75638834}],"checksum":2607173736,"timestamp":"2024-06-01T18:07:07.940795Z"}]}
{"channel":"book","type":"update","data":[{"symbol":"XRP/GBP","bids":[{"price":0.40667,"qty":964.58718217}],"asks":[],"checksum":3926522669,"timestamp":"2024-06-01T18:07:07.940950Z"}]}
{"channel":"book","type":"update","data":[{"symbol":"XRP/GBP","bids":[{"price":0.40667,"qty":0.00000000},{"price":0.40625,"qty":1885.71669300}],"asks":[],"checksum":2607173736,"timestamp":"2024-06-01T18:07:07.945145Z"}]}
{"channel":"book","type":"update","data":[{"symbol":"XRP/GBP","bids":[{"price":0.40665,"qty":0.00000000},{"price":0.40594,"qty":3781.90474200}],"asks":[],"checksum":3781216916,"timestamp":"2024-06-01T18:07:07.967300Z"}]}
{"channel":"book","type":"update","data":[{"symbol":"XRP/GBP","bids":[],"asks":[{"price":0.40692,"qty":0.00000000},{"price":0.40746,"qty":583.41282844}],"checksum":761878632,"timestamp":"2024-06-01T18:07:08.246903Z"}]}
{"channel":"book","type":"update","data":[{"symbol":"XRP/GBP","bids":[],"asks":[{"price":0.40695,"qty":0.00000000},{"price":0.40747,"qty":12145.20305669}],"checksum":2441571654,"timestamp":"2024-06-01T18:07:08.251839Z"}]}
{"channel":"book","type":"update","data":[{"symbol":"XRP/GBP","bids":[],"asks":[{"price":0.40691,"qty":482.01363355}],"checksum":2012026305,"timestamp":"2024-06-01T18:07:08.256185Z"}]}
{"channel":"book","type":"update","data":[{"symbol":"XRP/GBP","bids":[{"price":0.40681,"qty":482.11656032}],"asks":[],"checksum":2706661884,"timestamp":"2024-06-01T18:07:08.256302Z"}]}
{"channel":"book","type":"update","data":[{"symbol":"XRP/GBP","bids":[{"price":0.40678,"qty":675.01335231}],"asks":[],"checksum":3119587969,"timestamp":"2024-06-01T18:07:08.256329Z"}]}
{"channel":"book","type":"update","data":[{"symbol":"XRP/GBP","bids":[{"price":0.40681,"qty":0.00000000},{"price":0.40625,"qty":1885.71669300}],"asks":[],"checksum":1125857613,"timestamp":"2024-06-01T18:07:08.352982Z"}]}
{"channel":"book","type":"update","data":[{"symbol":"XRP/GBP","bids":[{"price":0.40678,"qty":0.00000000},{"price":0.40594,"qty":3781.90474200}],"asks":[],"checksum":2012026305,"timestamp":"2024-06-01T18:07:08.357018Z"}]}
{"channel":"book","type":"update","data":[{"symbol":"XRP/GBP","bids":[{"price":0.40646,"qty":4822.30213998}],"asks":[],"checksum":2786105672,"timestamp":"2024-06-01T18:07:08.697714Z"}]}
{"channel":"book","type":"update","data":[{"symbol":"XRP/GBP","bids":[{"price":0.40642,"qty":0.00000000},{"price":0.40594,"qty":3781.90474200}],"asks":[],"checksum":2121999480,"timestamp":"2024-06-01T18:07:09.111233Z"}]}
{"channel":"book","type":"update","data":[{"symbol":"XRP/GBP","bids":[{"price":0.40681,"qty":482.11757923}],"asks":[],"checksum":811800346,"timestamp":"2024-06-01T18:07:09.267584Z"}]}
{"channel":"book","type":"update","data":[{"symbol":"XRP/GBP","bids":[{"price":0.40644,"qty":2011.10215718}],"asks":[],"checksum":3458412739,"timestamp":"2024-06-01T18:07:09.358760Z"}]}
{"channel":"book","type":"update","data":[{"symbol":"XRP/GBP","bids":[],"asks":[{"price":0.40694,"qty":674.76893356}],"checksum":369131283,"timestamp":"2024-06-01T18:07:09.939404Z"}]}
{"channel":"book","type":"update","data":[{"symbol":"XRP/GBP","bids":[{"price":0.40646,"qty":0.00000000},{"price":0.40625,"qty":1885.71669300}],"asks":[],"checksum":1931271774,"timestamp":"2024-06-01T18:07:10.587323Z"}]}
{"channel":"book","type":"update","data":[{"symbol":"XRP/GBP","bids":[{"price":0.40646,"qty":4822.34219786}],"asks":[],"checksum":743801029,"timestamp":"2024-06-01T18:07:10.699554Z"}]}
{"channel":"book","type":"update","data":[{"symbol":"XRP/GBP","bids":[{"price":0.40637,"qty":0.00000000},{"price":0.40625,"qty":1885.71669300}],"asks":[],"checksum":358307857,"timestamp":"2024-06-01T18:07:10.900981Z"}]}
{"channel":"book","type":"update","data":[{"symbol":"XRP/GBP","bids":[{"price":0.40655,"qty":1018.21471200}],"asks":[],"checksum":3615158626,"timestamp":"2024-06-01T18:07:10.903907Z"}]}
{"channel":"book","type":"update","data":[{"symbol":"XRP/GBP","bids":[{"price":0.40681,"qty":0.00000000},{"price":0.40625,"qty":1885.71669300}],"asks":[],"checksum":3676129070,"timestamp":"2024-06-01T18:07:10.906654Z"}]}
{"channel":"book","type":"update","data":[{"symbol":"XRP/GBP","bids":[{"price":0.40646,"qty":0.00000000},{"price":0.40594,"qty":3781.90474200}],"asks":[],"checksum":2693552130,"timestamp":"2024-06-01T18:07:10.908320Z"}]}
{"channel":"book","type":"update","data":[{"symbol":"XRP/GBP","bids":[{"price":0.40656,"qty":4822.33423249}],"asks":[],"checksum":1531010498,"timestamp":"2024-06-01T18:07:10.908520Z"}]}
{"channel":"book","type":"update","data":[{"symbol":"XRP/GBP","bids":[{"price":0.40682,"qty":482.10429090}],"asks":[],"checksum":1773281997,"timestamp":"2024-06-01T18:07:10.910925Z"}]}
{"channel":"book","type":"update","data":[{"symbol":"XRP/GBP","bids":[{"price":0.40665,"qty":675.24423598}],"asks":[],"checksum":3629867640,"timestamp":"2024-06-01T18:07:10.911119Z"}]}
{"channel":"book","type":"update","data":[{"symbol":"XRP/GBP","bids":[{"price":0.40656,"qty":0.00000000},{"price":0.40628,"qty":30786.27990000}],"asks":[],"checksum":2619825775,"timestamp":"2024-06-01T18:07:10.912361Z"}]}
{"channel":"book","type":"update","data":[{"symbol":"XRP/GBP","bids":[{"price":0.40664,"qty":2184.32244046}],"asks":[],"checksum":3156323228,"timestamp":"2024-06-01T18:07:10.913836Z"}]}
{"channel":"book","type":"update","data":[{"symbol":"XRP/GBP","bids":[{"price":0.40667,"qty":220.00000000}],"asks":[],"checksum":3744332233,"timestamp":"2024-06-01T18:07:10.914116Z"}]}
{"channel":"book","type":"update","data":[{"symbol":"XRP/GBP","bids":[{"price":0.40665,"qty":0.00000000},{"price":0.40628,"qty":30786.27990000}],"asks":[],"checksum":1340590584,"timestamp":"2024-06-01T18:07:10.915624Z"}]}
{"channel":"book","type":"update","data":[{"symbol":"XRP/GBP","bids":[{"price":0.40674,"qty":964.40795842}],"asks":[],"checksum":2182887793,"timestamp":"2024-06-01T18:07:11.167234Z"}]}
{"channel":"book","type":"update","data":[{"symbol":"XRP/GBP","bids":[],"asks":[{"price":0.40691,"qty":0.00000000},{"price":0.40746,"qty":583.41282844}],"checksum":869341227,"timestamp":"2024-06-01T18:07:11.226477Z"}]}
{"channel":"book","type":"update","data":[{"symbol":"XRP/GBP","bids":[{"price":0.40682,"qty":0.00000000},{"price":0.40628,"qty":30786.27990000}],"asks":[],"checksum":1621732246,"timestamp":"2024-06-01T18:07:11.226552Z"}]}
{"channel":"book","type":"update","data":[{"symbol":"XRP/GBP","bids":[],"asks":[{"price":0.40694,"qty":0.00000000},{"price":0.40747,"qty":12145.20305669}],"checksum":3493515647,"timestamp":"2024-06-01T18:07:11.232362Z"}]}
{"channel":"book","type":"update","data":[{"symbol":"XRP/GBP","bids":[],"asks":[{"price":0.40690,"qty":482.02507617}],"checksum":1724996701,"timestamp":"2024-06-01T18:07:11.237046Z"}]}
{"channel":"book","type":"update","data":[{"symbol":"XRP/GBP","bids":[{"price":0.40675,"qty":113.08000000}],"asks":[],"checksum":171613445,"timestamp":"2024-06-01T18:07:11.243205Z"}]}
{"channel":"book","type":"update","data":[{"symbol":"XRP/GBP","bids":[],"asks":[{"price":0.40690,"qty":0.00000000},{"price":0.40747,"qty":12145.20305669}],"checksum":2720552730,"timestamp":"2024-06-01T18:07:11.443278Z"}]}
{"channel":"book","type":"update","data":[{"symbol":"XRP/GBP","bids":[],"asks":[{"price":0.40700,"qty":0.00000000},{"price":0.40753,"qty":1018.21471200}],"checksum":1280025783,"timestamp":"2024-06-01T18:07:11.448022Z"}]}
{"channel":"book","type":"update","data":[{"symbol":"XRP/GBP","bids":[],"asks":[{"price":0.40698,"qty":0.00000000},{"price":0.40771,"qty":9621.27252115}],"checksum":1246309145,"timestamp":"2024-06-01T18:07:11.450791Z"}]}
{"channel":"book","type":"update","data":[{"symbol":"XRP/GBP","bids":[],"asks":[{"price":0.40709,"qty":220.00000000}],"checksum":433467461,"timestamp":"2024-06-01T18:07:11.450934Z"}]}
{"channel":"book","type":"update","data":[{"symbol":"XRP/GBP","bids":[],"asks":[{"price":0.40697,"qty":963.87613184}],"checksum":2163995651,"timestamp":"2024-06-01T18:07:11.451948Z"}]}
{"channel":"book","type":"update","data":[{"symbol":"XRP/GBP","bids":[],"asks":[{"price":0.40709,"qty":0.00000000},{"price":0.40753,"qty":1018.21471200}],"checksum":1349759718,"timestamp":"2024-06-01T18:07:11.454550Z"}]}
{"channel":"book","type":"update","data":[{"symbol":"XRP/GBP","bids":[],"asks":[{"price":0.40695,"qty":220.00000000}],"checksum":730510653,"timestamp":"2024-06-01T18:07:11.454803Z"}]}
{"channel":"book","type":"update","data":[{"symbol":"XRP/GBP","bids":[],"asks":[{"price":0.40694,"qty":674.76303278}],"checksum":590438027,"timestamp":"2024-06-01T18:07:11.951302Z"}]}
{"channel":"book","type":"update","data":[{"symbol":"XRP/GBP","bids":[{"price":0.40679,"qty":482.14555275}],"asks":[],"checksum":1024723639,"timestamp":"2024-06-01T18:07:11.951512Z"}]}
{"channel":"book","type":"update","data":[{"symbol":"XRP/GBP","bids":[],"asks":[{"price":0.40694,"qty":0.00000000},{"price":0.40747,"qty":12145.20305669}],"checksum":3955397114,"timestamp":"2024-06-01T18:07:11.956077Z"}]}
{"channel":"book","type":"update","data":[{"symbol":"XRP/GBP","bids":[{"price":0.40679,"qty":0.00000000},{"price":0.40629,"qty":1032.83152113}],"asks":[],"checksum":730510653,"timestamp":"2024-06-01T18:07:12.112295Z"}]}
{"channel":"book","type":"update","data":[{"symbol":"XRP/GBP","bids":[],"asks":[{"price":0.40690,"qty":482.02649791}],"checksum":1844332566,"timestamp":"2024-06-01T18:07:12.845988Z"}]}
{"channel":"book","type":"update","data":[{"symbol":"XRP/GBP","bids":[],"asks":[{"price":0.40690,"qty":0.00000000},{"price":0.40747,"qty":12145.20305669}],"checksum":730510653,"timestamp":"2024-06-01T18:07:12.865179Z"}]}
{"channel":"book","type":"update","data":[{"symbol":"XRP/GBP","bids":[{"price":0.40677,"qty":675.03551956}],"asks":[],"checksum":1768138404,"timestamp":"2024-06-01T18:07:13.208031Z"}]}
{"channel":"book","type":"update","data":[{"symbol":"XRP/GBP","bids":[{"price":0.40676,"qty":482.18687847}],"asks":[],"checksum":499740318,"timestamp":"2024-06-01T18:07:13.208077Z"}]}
{"channel":"book","type":"update","data":[{"symbol":"XRP/GBP","bids":[{"price":0.40676,"qty":0.00000000},{"price":0.40639,"qty":4826.22758212}],"asks":[],"checksum":1768138404,"timestamp":"2024-06-01T18:07:13.213781Z"}]}
{"channel":"book","type":"update","data":[{"symbol":"XRP/GBP","bids":[{"price":0.40677,"qty":0.00000000},{"price":0.40629,"qty":1032.83152113}],"asks":[],"checksum":730510653,"timestamp":"2024-06-01T18:07:13.218041Z"}]}
{"channel":"book","type":"update","data":[{"symbol":"XRP/GBP","bids":[],"asks":[{"price":0.40690,"qty":482.02105073}],"checksum":141186317,"timestamp":"2024-06-01T18:07:13.953834Z"}]}
{"channel":"book","type":"update","data":[{"symbol":"XRP/GBP","bids":[],"asks":[{"price":0.40693,"qty":674.77961458}],"checksum":557833620,"timestamp":"2024-06-01T18:07:13.954003Z"}]}
{"channel":"book","type":"update","data":[{"symbol":"XRP/GBP","bids":[{"price":0.40675,"qty":0.00000000},{"price":0.40628,"qty":30786.27990000}],"asks":[],"checksum":2019003795,"timestamp":"2024-06-01T18:07:13.969934Z"}]}
{"channel":"book","type":"update","data":[{"symbol":"XRP/GBP","bids":[],"asks":[{"price":0.40690,"qty":0.00000000},{"price":0.40746,"qty":583.41282844}],"checksum":47997079,"timestamp":"2024-06-01T18:07:14.146158Z"}]}
{"channel":"book","type":"update","data":[{"symbol":"XRP/GBP","bids":[],"asks":[{"price":0.40693,"qty":0.00000000},{"price":0.40747,"qty":12145.20305669}],"checksum":1157327340,"timestamp":"2024-06-01T18:07:14.150888Z"}]}
{"channel":"book","type":"update","data":[{"symbol":"XRP/GBP","bids":[{"price":0.40675,"qty":113.08000000}],"asks":[],"checksum":730510653,"timestamp":"2024-06-01T18:07:14.182225Z"}]}
{"channel":"book","type":"update","data":[{"symbol":"XRP/GBP","bids":[{"price":0.40680,"qty":482.13800926}],"asks":[],"checksum":464940947,"timestamp":"2024-06-01T18:07:14.816844Z"}]}
{"channel":"book","type":"update","data":[{"symbol":"XRP/GBP","bids":[],"asks":[{"price":0.40690,"qty":482.03176397}],"checksum":3002908812,"timestamp":"2024-06-01T18:07:14.974571Z"}]}
{"channel":"book","type":"update","data":[{"symbol":"XRP/GBP","bids":[{"price":0.40656,"qty":4822.39256064}],"asks":[],"checksum":702666076,"timestamp":"2024-06-01T18:07:14.979419Z"}]}
{"channel":"book","type":"update","data":[{"symbol":"XRP/GBP","bids":[{"price":0.40680,"qty":0.00000000},{"price":0.40639,"qty":4826.22758212}],"asks":[],"checksum":772338805,"timestamp":"2024-06-01T18:07:14.987746Z"}]}
{"channel":"book","type":"update","data":[{"symbol":"XRP/GBP","bids":[{"price":0.40656,"qty":0.00000000},{"price":0.40629,"qty":1032.83152113}],"asks":[],"checksum":2787897959,"timestamp":"2024-06-01T18:07:15.033535Z"}]}
{"channel":"book","type":"update","data":[{"symbol":"XRP/GBP","bids":[{"price":0.40662,"qty":5345.50276809}],"asks":[],"checksum":3107148079,"timestamp":"2024-06-01T18:07:15.033716Z"}]}
{"channel":"book","type":"update","data":[{"symbol":"XRP/GBP","bids":[],"asks":[{"price":0.40690,"qty":0.00000000},{"price":0.40747,"qty":12145.20305669}],"checksum":838879362,"timestamp":"2024-06-01T18:07:15.108299Z"}]}
{"channel":"book","type":"update","data":[{"symbol":"XRP/GBP","bids":[{"price":0.40676,"qty":675.06162986}],"asks":[],"checksum":325567929,"timestamp":"2024-06-01T18:07:15.224281Z"}]}
{"channel":"book","type":"update","data":[{"symbol":"XRP/GBP","bids":[{"price":0.40676,"qty":0.00000000},{"price":0.40629,"qty":1032.83152113}],"asks":[],"checksum":838879362,"timestamp":"2024-06-01T18:07:15.228469Z"}]}
{"channel":"book","type":"update","data":[{"symbol":"XRP/GBP","bids":[{"price":0.40680,"qty":482.13675916}],"asks":[],"checksum":1376398753,"timestamp":"2024-06-01T18:07:15.983639Z"}]}
{"channel":"book","type":"update","data":[{"symbol":"XRP/GBP","bids":[],"asks":[{"price":0.40689,"qty":482.04184707}],"checksum":1620466597,"timestamp":"2024-06-01T18:07:15.983746Z"}]}
{"channel":"book","type":"update","data":[{"symbol":"XRP/GBP","bids":[],"asks":[{"price":0.40692,"qty":674.79619719}],"checksum":2697814027,"timestamp":"2024-06-01T18:07:15.983896Z"}]}
{"channel":"book","type":"update","data":[{"symbol":"XRP/GBP","bids":[{"price":0.40675,"qty":0.00000000},{"price":0.40629,"qty":1032.83152113}],"asks":[],"checksum":301879428,"timestamp":"2024-06-01T18:07:16.002789Z"}]}
{"channel":"book","type":"update","data":[{"symbol":"XRP/GBP","bids":[{"price":0.40680,"qty":0.00000000},{"price":0.40628,"qty":30786.27990000}],"asks":[],"checksum":2120831726,"timestamp":"2024-06-01T18:07:16.113644Z"}]}
{"channel":"book","type":"update","data":[{"symbol":"XRP/GBP","bids":[{"price":0.40662,"qty":964.70579257}],"asks":[],"checksum":410972773,"timestamp":"2024-06-01T18:07:16.118909Z"}]}
{"channel":"book","type":"update","data":[{"symbol":"XRP/GBP","bids":[{"price":0.40656,"qty":3954.24193214}],"asks":[],"checksum":558064501,"timestamp":"2024-06-01T18:07:16.118931Z"}]}
{"channel":"book","type":"update","data":[{"symbol":"XRP/GBP","bids":[{"price":0.40656,"qty":0.00000000},{"price":0.40628,"qty":30786.27990000}],"asks":[],"checksum":410972773,"timestamp":"2024-06-01T18:07:16.123950Z"}]}
{"channel":"book","type":"update","data":[{"symbol":"XRP/GBP","bids":[{"price":0.40662,"qty":5345.50276809}],"asks":[],"checksum":2120831726,"timestamp":"2024-06-01T18:07:16.124147Z"}]}
{"channel":"book","type":"update","data":[{"symbol":"XRP/GBP","bids":[],"asks":[{"price":0.40689,"qty":0.00000000},{"price":0.40746,"qty":583.41282844}],"checksum":2631134441,"timestamp":"2024-06-01T18:07:16.154099Z"}]}
{"channel":"book","type":"update","data":[{"symbol":"XRP/GBP","bids":[{"price":0.40662,"qty":964.70579257}],"asks":[],"checksum":448455084,"timestamp":"2024-06-01T18:07:17.182358Z"}]}
{"channel":"book","type":"update","data":[{"symbol":"XRP/GBP","bids":[],"asks":[{"price":0.40691,"qty":482.00912901}],"checksum":2548030529,"timestamp":"2024-06-01T18:07:17.573720Z"}]}
{"channel":"book","type":"update","data":[{"symbol":"XRP/GBP","bids":[{"price":0.40675,"qty":482.19873309}],"asks":[],"checksum":3765397980,"timestamp":"2024-06-01T18:07:17.573782Z"}]}
{"channel":"book","type":"update","data":[{"symbol":"XRP/GBP","bids":[{"price":0.40677,"qty":675.04503420}],"asks":[],"checksum":2044660374,"timestamp":"2024-06-01T18:07:17.573811Z"}]}
{"channel":"book","type":"update","data":[{"symbol":"XRP/GBP","bids":[{"price":0.40677,"qty":0.00000000},{"price":0.40629,"qty":1032.83152113}],"asks":[],"checksum":3765397980,"timestamp":"2024-06-01T18:07:17.578867Z"}]}
{"channel":"book","type":"update","data":[{"symbol":"XRP/GBP","bids":[{"price":0.40675,"qty":0.00000000},{"price":0.40628,"qty":30786.27990000}],"asks":[],"checksum":2548030529,"timestamp":"2024-06-01T18:07:17.578905Z"}]}
{"channel":"book","type":"update","data":[{"symbol":"XRP/GBP","bids":[{"price":0.40681,"qty":482.11588441}],"asks":[],"checksum":1245258744,"timestamp":"2024-06-01T18:07:18.711022Z"}]}
{"channel":"book","type":"update","data":[{"symbol":"XRP/GBP","bids":[],"asks":[{"price":0.40691,"qty":0.00000000},{"price":0.40746,"qty":583.41282844}],"checksum":2814760941,"timestamp":"2024-06-01T18:07:18.750146Z"}]}
{"channel":"book","type":"update","data":[{"symbol":"XRP/GBP","bids":[],"asks":[{"price":0.40690,"qty":482.02672484}],"checksum":456442871,"timestamp":"2024-06-01T18:07:18.754461Z"}]}
{"channel":"book","type":"update","data":[{"symbol":"XRP/GBP","bids":[],"asks":[{"price":0.40690,"qty":0.00000000},{"price":0.40746,"qty":583.41282844}],"checksum":2814760941,"timestamp":"2024-06-01T18:07:18.924145Z"}]}
{"channel":"book","type":"update","data":[{"symbol":"XRP/GBP","bids":[{"price":0.40681,"qty":0.00000000},{"price":0.40628,"qty":30786.27990000}],"asks":[],"checksum":448455084,"timestamp":"2024-06-01T18:07:18.930466Z"}]}
{"channel":"book","type":"update","data":[{"symbol":"XRP/GBP","bids":[],"asks":[{"price":0.40692,"qty":0.00000000},{"price":0.40747,"qty":12145.20305669}],"checksum":1157327340,"timestamp":"2024-06-01T18:07:19.143347Z"}]}
{"channel":"book","type":"update","data":[{"symbol":"XRP/GBP","bids":[],"asks":[{"price":0.40694,"qty":674.76303278}],"checksum":3250344857,"timestamp":"2024-06-01T18:07:19.147939Z"}]}
{"channel":"book","type":"update","data":[{"symbol":"XRP/GBP","bids":[],"asks":[{"price":0.40694,"qty":0.00000000},{"price":0.40747,"qty":12145.20305669}],"checksum":1157327340,"timestamp":"2024-06-01T18:07:19.153462Z"}]}
{"channel":"book","type":"update","data":[{"symbol":"XRP/GBP","bids":[{"price":0.40675,"qty":675.07822633}],"asks":[],"checksum":193294144,"timestamp":"2024-06-01T18:07:19.596570Z"}]}
{"channel":"book","type":"update","data":[{"symbol":"XRP/GBP","bids":[{"price":0.40675,"qty":0.00000000},{"price":0.40628,"qty":30786.27990000}],"asks":[],"checksum":1157327340,"timestamp":"2024-06-01T18:07:19.600896Z"}]}
{"channel":"book","type":"update","data":[{"symbol":"XRP/GBP","bids":[],"asks":[{"price":0.40688,"qty":482.04992988}],"checksum":1652061819,"timestamp":"2024-06-01T18:07:20.087001Z"}]}
{"channel":"book","type":"update","data":[{"symbol":"XRP/GBP","bids":[{"price":0.40675,"qty":482.19873309}],"asks":[],"checksum":3923602289,"timestamp":"2024-06-01T18:07:20.087020Z"}]}
{"channel":"book","type":"update","data":[{"symbol":"XRP/GBP","bids":[{"price":0.40664,"qty":0.00000000},{"price":0.40628,"qty":30786.27990000}],"asks":[],"checksum":2752430800,"timestamp":"2024-06-01T18:07:20.089950Z"}]}
{"channel":"book","type":"update","data":[{"symbol":"XRP/GBP","bids":[{"price":0.40675,"qty":0.00000000},{"price":0.40625,"qty":1885.71669300}],"asks":[],"checksum":3260978005,"timestamp":"2024-06-01T18:07:20.091613Z"}]}
{"channel":"book","type":"update","data":[{"symbol":"XRP/GBP","bids":[{"price":0.40664,"qty":3883.20329453}],"asks":[],"checksum":1525372963,"timestamp":"2024-06-01T18:07:20.092922Z"}]}
{"channel":"book","type":"update","data":[{"symbol":"XRP/GBP","bids":[],"asks":[{"price":0.40688,"qty":0.00000000},{"price":0.40747,"qty":12145.20305669}],"checksum":2087208884,"timestamp":"2024-06-01T18:07:21.089949Z"}]}
{"channel":"book","type":"update","data":[{"symbol":"XRP/GBP","bids":[{"price":0.40674,"qty":0.00000000},{"price":0.40625,"qty":1885.71669300}],"asks":[],"checksum":173329084,"timestamp":"2024-06-01T18:07:21.090049Z"}]}
{"channel":"book","type":"update","data":[{"symbol":"XRP/GBP","bids":[{"price":0.40669,"qty":964.52229068}],"asks":[],"checksum":4031619709,"timestamp":"2024-06-01T18:07:21.095083Z"}]}
{"channel":"book","type":"update","data":[{"symbol":"XRP/GBP","bids":[],"asks":[{"price":0.40687,"qty":482.05714813}],"checksum":3851646422,"timestamp":"2024-06-01T18:07:21.095145Z"}]}
{"channel":"book","type":"update","data":[{"symbol":"XRP/GBP","bids":[{"price":0.40678,"qty":482.15148504}],"asks":[],"checksum":3202882291,"timestamp":"2024-06-01T18:07:21.095224Z"}]}
