{"channel":"book","type":"snapshot","data":[{"symbol":"ADA/USDT","bids":[{"price":0.452355,"qty":3304.28005306},{"price":0.452350,"qty":15400.06038698},{"price":0.452340,"qty":5531.47100551},{"price":0.452268,"qty":600.00000000},{"price":0.452256,"qty":11064.97840298},{"price":0.452200,"qty":7145.58013039},{"price":0.452174,"qty":5876.59157689},{"price":0.452129,"qty":370.00000000},{"price":0.452107,"qty":11068.64350842},{"price":0.452034,"qty":5531.47100551}],"asks":[{"price":0.452445,"qty":5530.19533402},{"price":0.452536,"qty":1450.90000000},{"price":0.452555,"qty":11057.68974460},{"price":0.452557,"qty":600.00000000},{"price":0.452637,"qty":5876.59157689},{"price":0.452700,"qty":4554.52143223},{"price":0.452704,"qty":11054.06983537},{"price":0.452774,"qty":34.12226265},{"price":0.452818,"qty":2112.00000000},{"price":0.452819,"qty":8841.58753618}],"checksum":3928347936}]}
{"channel":"book","type":"update","data":[{"symbol":"ADA/USDT","bids":[{"price":0.452355,"qty":0.00000000},{"price":0.452017,"qty":1450.90000000}],"asks":[],"checksum":3877911692,"timestamp":"2024-06-01T22:43:05.704368Z"}]}
{"channel":"book","type":"update","data":[{"symbol":"ADA/USDT","bids":[{"price":0.452350,"qty":800.00000000}],"asks":[],"checksum":276617523,"timestamp":"2024-06-01T22:43:05.704384Z"}]}
{"channel":"book","type":"update","data":[{"symbol":"ADA/USDT","bids":[{"price":0.452356,"qty":3304.38823976}],"asks":[],"checksum":4027613224,"timestamp":"2024-06-01T22:43:05.744975Z"}]}
{"channel":"book","type":"update","data":[{"symbol":"ADA/USDT","bids":[{"price":0.452355,"qty":14600.29593514}],"asks":[],"checksum":887563912,"timestamp":"2024-06-01T22:43:05.745177Z"}]}
{"channel":"book","type":"update","data":[{"symbol":"ADA/USDT","bids":[{"price":0.452356,"qty":0.00000000},{"price":0.452034,"qty":5531.47100551}],"asks":[],"checksum":1766451151,"timestamp":"2024-06-01T22:43:06.700852Z"}]}
{"channel":"book","type":"update","data":[{"symbol":"ADA/USDT","bids":[{"price":0.452357,"qty":3304.33521707}],"asks":[],"checksum":750963169,"timestamp":"2024-06-01T22:43:06.741029Z"}]}
{"channel":"book","type":"update","data":[{"symbol":"ADA/USDT","bids":[{"price":0.452357,"qty":0.00000000},{"price":0.452034,"qty":5531.47100551}],"asks":[],"checksum":1766451151,"timestamp":"2024-06-01T22:43:07.250877Z"}]}
{"channel":"book","type":"update","data":[{"symbol":"ADA/USDT","bids":[{"price":0.452358,"qty":3304.28081014}],"asks":[],"checksum":635318650,"timestamp":"2024-06-01T22:43:07.291263Z"}]}
{"channel":"book","type":"update","data":[{"symbol":"ADA/USDT","bids":[{"price":0.452358,"qty":0.00000000},{"price":0.452034,"qty":5531.47100551}],"asks":[],"checksum":1766451151,"timestamp":"2024-06-01T22:43:08.804022Z"}]}
{"channel":"book","type":"update","data":[{"symbol":"ADA/USDT","bids":[{"price":0.452359,"qty":3304.40513171}],"asks":[],"checksum":3174337109,"timestamp":"2024-06-01T22:43:08.844462Z"}]}
{"channel":"book","type":"update","data":[{"symbol":"ADA/USDT","bids":[{"price":0.452359,"qty":0.00000000},{"price":0.452034,"qty":5531.47100551}],"asks":[],"checksum":1766451151,"timestamp":"2024-06-01T22:43:10.311718Z"}]}
{"channel":"book","type":"update","data":[{"symbol":"ADA/USDT","bids":[{"price":0.452361,"qty":3304.40066033}],"asks":[],"checksum":2862240518,"timestamp":"2024-06-01T22:43:10.351880Z"}]}
{"channel":"book","type":"update","data":[{"symbol":"ADA/USDT","bids":[{"price":0.452355,"qty":0.00000000},{"price":0.452034,"qty":5531.47100551}],"asks":[],"checksum":3924864303,"timestamp":"2024-06-01T22:43:10.799092Z"}]}
{"channel":"book","type":"update","data":[{"symbol":"ADA/USDT","bids":[{"price":0.452361,"qty":17904.75046075}],"asks":[],"checksum":517865139,"timestamp":"2024-06-01T22:43:10.839224Z"}]}
{"channel":"book","type":"update","data":[{"symbol":"ADA/USDT","bids":[{"price":0.452361,"qty":14600.34980042}],"asks":[],"checksum":1518219394,"timestamp":"2024-06-01T22:43:11.355153Z"}]}
{"channel":"book","type":"update","data":[{"symbol":"ADA/USDT","bids":[{"price":0.452278,"qty":350.00000000}],"asks":[],"checksum":1067818968,"timestamp":"2024-06-01T22:43:11.360035Z"}]}
{"channel":"book","type":"update","data":[{"symbol":"ADA/USDT","bids":[{"price":0.452362,"qty":3304.40024278}],"asks":[],"checksum":3767381194,"timestamp":"2024-06-01T22:43:11.395325Z"}]}
{"channel":"book","type":"update","data":[{"symbol":"ADA/USDT","bids":[{"price":0.452362,"qty":0.00000000},{"price":0.452107,"qty":11068.64350842}],"asks":[],"checksum":1067818968,"timestamp":"2024-06-01T22:43:12.418115Z"}]}
{"channel":"book","type":"update","data":[{"symbol":"ADA/USDT","bids":[{"price":0.452364,"qty":3304.40003401}],"asks":[],"checksum":518619454,"timestamp":"2024-06-01T22:43:12.458246Z"}]}
{"channel":"book","type":"update","data":[{"symbol":"ADA/USDT","bids":[{"price":0.452364,"qty":0.00000000},{"price":0.452107,"qty":11068.64350842}],"asks":[],"checksum":1067818968,"timestamp":"2024-06-01T22:43:13.482816Z"}]}
{"channel":"book","type":"update","data":[{"symbol":"ADA/USDT","bids":[{"price":0.452366,"qty":3304.45381265}],"asks":[],"checksum":67912618,"timestamp":"2024-06-01T22:43:13.522697Z"}]}
{"channel":"book","type":"update","data":[{"symbol":"ADA/USDT","bids":[{"price":0.452366,"qty":0.00000000},{"price":0.452107,"qty":11068.64350842}],"asks":[],"checksum":1067818968,"timestamp":"2024-06-01T22:43:14.485570Z"}]}
{"channel":"book","type":"update","data":[{"symbol":"ADA/USDT","bids":[{"price":0.452369,"qty":3304.39919892}],"asks":[],"checksum":3172667882,"timestamp":"2024-06-01T22:43:14.526079Z"}]}
{"channel":"book","type":"update","data":[{"symbol":"ADA/USDT","bids":[{"price":0.452361,"qty":0.00000000},{"price":0.452107,"qty":11068.64350842}],"asks":[],"checksum":1508197498,"timestamp":"2024-06-01T22:43:15.997852Z"}]}
{"channel":"book","type":"update","data":[{"symbol":"ADA/USDT","bids":[{"price":0.452369,"qty":17904.46469371}],"asks":[],"checksum":2146164627,"timestamp":"2024-06-01T22:43:16.038183Z"}]}
{"channel":"book","type":"update","data":[{"symbol":"ADA/USDT","bids":[],"asks":[{"price":0.452637,"qty":0.00000000},{"price":0.452879,"qty":73.83575134}],"checksum":1129409485,"timestamp":"2024-06-01T22:43:18.154005Z"}]}
{"channel":"book","type":"update","data":[{"symbol":"ADA/USDT","bids":[{"price":0.452369,"qty":18504.46469371}],"asks":[],"checksum":1535544235,"timestamp":"2024-06-01T22:43:18.238360Z"}]}
{"channel":"book","type":"update","data":[{"symbol":"ADA/USDT","bids":[{"price":0.452268,"qty":0.00000000},{"price":0.452034,"qty":5531.47100551}],"asks":[],"checksum":2769935711,"timestamp":"2024-06-01T22:43:18.238414Z"}]}
{"channel":"book","type":"update","data":[{"symbol":"ADA/USDT","bids":[{"price":0.452274,"qty":5876.59157689}],"asks":[],"checksum":2614790797,"timestamp":"2024-06-01T22:43:18.242480Z"}]}
{"channel":"book","type":"update","data":[{"symbol":"ADA/USDT","bids":[{"price":0.452369,"qty":17904.46469371}],"asks":[],"checksum":1058248960,"timestamp":"2024-06-01T22:43:18.247769Z"}]}
{"channel":"book","type":"update","data":[{"symbol":"ADA/USDT","bids":[{"price":0.452370,"qty":600.00000000}],"asks":[],"checksum":1414002594,"timestamp":"2024-06-01T22:43:18.247855Z"}]}
{"channel":"book","type":"update","data":[{"symbol":"ADA/USDT","bids":[{"price":0.452174,"qty":0.00000000},{"price":0.452107,"qty":11068.64350842}],"asks":[],"checksum":240084102,"timestamp":"2024-06-01T22:43:18.515364Z"}]}
{"channel":"book","type":"update","data":[{"symbol":"ADA/USDT","bids":[{"price":0.452369,"qty":14600.06549479}],"asks":[],"checksum":1321577151,"timestamp":"2024-06-01T22:43:18.611576Z"}]}
{"channel":"book","type":"update","data":[{"symbol":"ADA/USDT","bids":[{"price":0.452373,"qty":3304.26233050}],"asks":[],"checksum":445492777,"timestamp":"2024-06-01T22:43:18.651807Z"}]}
{"channel":"book","type":"update","data":[{"symbol":"ADA/USDT","bids":[],"asks":[{"price":0.452445,"qty":0.00000000},{"price":0.452883,"qty":2175.21196000}],"checksum":997270118,"timestamp":"2024-06-01T22:43:19.162036Z"}]}
{"channel":"book","type":"update","data":[{"symbol":"ADA/USDT","bids":[{"price":0.452340,"qty":0.00000000},{"price":0.452107,"qty":11068.64350842}],"asks":[],"checksum":3157534972,"timestamp":"2024-06-01T22:43:19.162258Z"}]}
{"channel":"book","type":"update","data":[{"symbol":"ADA/USDT","bids":[],"asks":[{"price":0.452533,"qty":600.00000000}],"checksum":2587174851,"timestamp":"2024-06-01T22:43:19.165028Z"}]}
{"channel":"book","type":"update","data":[{"symbol":"ADA/USDT","bids":[],"asks":[{"price":0.452557,"qty":0.00000000},{"price":0.452883,"qty":2175.21196000}],"checksum":3122540604,"timestamp":"2024-06-01T22:43:19.165067Z"}]}
{"channel":"book","type":"update","data":[{"symbol":"ADA/USDT","bids":[],"asks":[{"price":0.452737,"qty":5876.59157689}],"checksum":548422630,"timestamp":"2024-06-01T22:43:19.167649Z"}]}
{"channel":"book","type":"update","data":[{"symbol":"ADA/USDT","bids":[{"price":0.452374,"qty":5531.05593685}],"asks":[],"checksum":3988811116,"timestamp":"2024-06-01T22:43:19.169161Z"}]}
{"channel":"book","type":"update","data":[{"symbol":"ADA/USDT","bids":[],"asks":[{"price":0.452502,"qty":5529.49664409}],"checksum":3312433180,"timestamp":"2024-06-01T22:43:19.169185Z"}]}
{"channel":"book","type":"update","data":[{"symbol":"ADA/USDT","bids":[{"price":0.452373,"qty":0.00000000},{"price":0.452107,"qty":11068.64350842}],"asks":[],"checksum":4179342401,"timestamp":"2024-06-01T22:43:19.608557Z"}]}
{"channel":"book","type":"update","data":[{"symbol":"ADA/USDT","bids":[{"price":0.452374,"qty":8835.30043803}],"asks":[],"checksum":3381921394,"timestamp":"2024-06-01T22:43:19.648815Z"}]}
{"channel":"book","type":"update","data":[{"symbol":"ADA/USDT","bids":[{"price":0.452369,"qty":0.00000000},{"price":0.452034,"qty":5531.47100551}],"asks":[],"checksum":3524635090,"timestamp":"2024-06-01T22:43:20.687456Z"}]}
{"channel":"book","type":"update","data":[{"symbol":"ADA/USDT","bids":[{"price":0.452374,"qty":5531.05593685}],"asks":[],"checksum":3898110781,"timestamp":"2024-06-01T22:43:20.687541Z"}]}
{"channel":"book","type":"update","data":[{"symbol":"ADA/USDT","bids":[{"price":0.452374,"qty":20130.62487827}],"asks":[],"checksum":207200755,"timestamp":"2024-06-01T22:43:20.727715Z"}]}
{"channel":"book","type":"update","data":[{"symbol":"ADA/USDT","bids":[{"price":0.452375,"qty":3304.22412365}],"asks":[],"checksum":4015253081,"timestamp":"2024-06-01T22:43:20.727927Z"}]}
{"channel":"book","type":"update","data":[{"symbol":"ADA/USDT","bids":[{"price":0.452370,"qty":0.00000000},{"price":0.452034,"qty":5531.47100551}],"asks":[],"checksum":1920487100,"timestamp":"2024-06-01T22:43:20.868344Z"}]}
{"channel":"book","type":"update","data":[{"symbol":"ADA/USDT","bids":[{"price":0.452376,"qty":600.00000000}],"asks":[],"checksum":1860984371,"timestamp":"2024-06-01T22:43:20.869347Z"}]}
{"channel":"book","type":"update","data":[{"symbol":"ADA/USDT","bids":[{"price":0.452375,"qty":0.00000000},{"price":0.452034,"qty":5531.47100551}],"asks":[],"checksum":3695627032,"timestamp":"2024-06-01T22:43:21.180948Z"}]}
{"channel":"book","type":"update","data":[{"symbol":"ADA/USDT","bids":[{"price":0.452390,"qty":3303.81661644}],"asks":[],"checksum":2671281978,"timestamp":"2024-06-01T22:43:21.221354Z"}]}
{"channel":"book","type":"update","data":[{"symbol":"ADA/USDT","bids":[{"price":0.452390,"qty":0.00000000},{"price":0.452034,"qty":5531.47100551}],"asks":[],"checksum":3695627032,"timestamp":"2024-06-01T22:43:21.739837Z"}]}
{"channel":"book","type":"update","data":[{"symbol":"ADA/USDT","bids":[{"price":0.452388,"qty":3303.87051801}],"asks":[],"checksum":369432003,"timestamp":"2024-06-01T22:43:21.779947Z"}]}
{"channel":"book","type":"update","data":[{"symbol":"ADA/USDT","bids":[{"price":0.452388,"qty":0.00000000},{"price":0.452034,"qty":5531.47100551}],"asks":[],"checksum":3695627032,"timestamp":"2024-06-01T22:43:23.330545Z"}]}
{"channel":"book","type":"update","data":[{"symbol":"ADA/USDT","bids":[{"price":0.452387,"qty":3303.87867982}],"asks":[],"checksum":3491969765,"timestamp":"2024-06-01T22:43:23.370908Z"}]}
{"channel":"book","type":"update","data":[{"symbol":"ADA/USDT","bids":[{"price":0.452108,"qty":130.56327650}],"asks":[],"checksum":2848775595,"timestamp":"2024-06-01T22:43:23.489485Z"}]}
{"channel":"book","type":"update","data":[{"symbol":"ADA/USDT","bids":[],"asks":[{"price":0.452536,"qty":0.00000000},{"price":0.452879,"qty":73.83575134}],"checksum":2946544449,"timestamp":"2024-06-01T22:43:24.406039Z"}]}
{"channel":"book","type":"update","data":[{"symbol":"ADA/USDT","bids":[],"asks":[{"price":0.452570,"qty":1449.50000000}],"checksum":806355856,"timestamp":"2024-06-01T22:43:24.408578Z"}]}
{"channel":"book","type":"update","data":[{"symbol":"ADA/USDT","bids":[{"price":0.452387,"qty":0.00000000},{"price":0.452107,"qty":11068.64350842}],"asks":[],"checksum":4213132787,"timestamp":"2024-06-01T22:43:24.665372Z"}]}
{"channel":"book","type":"update","data":[{"symbol":"ADA/USDT","bids":[{"price":0.452388,"qty":3303.86870047}],"asks":[],"checksum":442287898,"timestamp":"2024-06-01T22:43:24.705401Z"}]}
{"channel":"book","type":"update","data":[{"symbol":"ADA/USDT","bids":[{"price":0.452374,"qty":5531.05593685}],"asks":[],"checksum":633300785,"timestamp":"2024-06-01T22:43:25.731111Z"}]}
{"channel":"book","type":"update","data":[{"symbol":"ADA/USDT","bids":[{"price":0.452388,"qty":17902.24413086}],"asks":[],"checksum":81133459,"timestamp":"2024-06-01T22:43:25.771295Z"}]}
{"channel":"book","type":"update","data":[{"symbol":"ADA/USDT","bids":[{"price":0.452376,"qty":0.00000000},{"price":0.452107,"qty":11068.64350842}],"asks":[],"checksum":3539737512,"timestamp":"2024-06-01T22:43:26.585734Z"}]}
{"channel":"book","type":"update","data":[{"symbol":"ADA/USDT","bids":[{"price":0.452389,"qty":600.00000000}],"asks":[],"checksum":3141170039,"timestamp":"2024-06-01T22:43:26.585749Z"}]}
{"channel":"book","type":"update","data":[{"symbol":"ADA/USDT","bids":[{"price":0.452200,"qty":0.00000000},{"price":0.452107,"qty":11068.64350842}],"asks":[],"checksum":1850785691,"timestamp":"2024-06-01T22:43:26.589266Z"}]}
{"channel":"book","type":"update","data":[{"symbol":"ADA/USDT","bids":[{"price":0.452200,"qty":11915.48013039}],"asks":[],"checksum":3813542718,"timestamp":"2024-06-01T22:43:26.592643Z"}]}
{"channel":"book","type":"update","data":[{"symbol":"ADA/USDT","bids":[{"price":0.452388,"qty":14598.37543039}],"asks":[],"checksum":2526784854,"timestamp":"2024-06-01T22:43:26.791440Z"}]}
{"channel":"book","type":"update","data":[{"symbol":"ADA/USDT","bids":[{"price":0.452396,"qty":3303.61465983}],"asks":[],"checksum":1857691338,"timestamp":"2024-06-01T22:43:26.831951Z"}]}
{"channel":"book","type":"update","data":[{"symbol":"ADA/USDT","bids":[{"price":0.452389,"qty":0.00000000},{"price":0.452108,"qty":130.56327650}],"asks":[],"checksum":3429726120,"timestamp":"2024-06-01T22:43:27.232343Z"}]}
{"channel":"book","type":"update","data":[{"symbol":"ADA/USDT","bids":[{"price":0.452398,"qty":600.00000000}],"asks":[],"checksum":1813207387,"timestamp":"2024-06-01T22:43:27.232611Z"}]}
{"channel":"book","type":"update","data":[{"symbol":"ADA/USDT","bids":[{"price":0.452396,"qty":0.00000000},{"price":0.452108,"qty":130.56327650}],"asks":[],"checksum":666848851,"timestamp":"2024-06-01T22:43:27.862390Z"}]}
{"channel":"book","type":"update","data":[{"symbol":"ADA/USDT","bids":[{"price":0.452394,"qty":3303.62058422}],"asks":[],"checksum":629430346,"timestamp":"2024-06-01T22:43:27.901955Z"}]}
{"channel":"book","type":"update","data":[{"symbol":"ADA/USDT","bids":[{"price":0.452394,"qty":0.00000000},{"price":0.452108,"qty":130.56327650}],"asks":[],"checksum":666848851,"timestamp":"2024-06-01T22:43:28.351525Z"}]}
{"channel":"book","type":"update","data":[{"symbol":"ADA/USDT","bids":[{"price":0.452390,"qty":3303.78215906}],"asks":[],"checksum":1509658113,"timestamp":"2024-06-01T22:43:28.391766Z"}]}
{"channel":"book","type":"update","data":[{"symbol":"ADA/USDT","bids":[{"price":0.452390,"qty":0.00000000},{"price":0.452108,"qty":130.56327650}],"asks":[],"checksum":666848851,"timestamp":"2024-06-01T22:43:28.903118Z"}]}
{"channel":"book","type":"update","data":[{"symbol":"ADA/USDT","bids":[{"price":0.452394,"qty":3303.72197423}],"asks":[],"checksum":1279603512,"timestamp":"2024-06-01T22:43:28.943519Z"}]}
{"channel":"book","type":"update","data":[{"symbol":"ADA/USDT","bids":[{"price":0.452394,"qty":0.00000000},{"price":0.452108,"qty":130.56327650}],"asks":[],"checksum":666848851,"timestamp":"2024-06-01T22:43:29.457099Z"}]}
{"channel":"book","type":"update","data":[{"symbol":"ADA/USDT","bids":[{"price":0.452396,"qty":3303.57609532}],"asks":[],"checksum":1116725207,"timestamp":"2024-06-01T22:43:29.497430Z"}]}
{"channel":"book","type":"update","data":[{"symbol":"ADA/USDT","bids":[{"price":0.452396,"qty":0.00000000},{"price":0.452108,"qty":87.40221984}],"asks":[],"checksum":2461017766,"timestamp":"2024-06-01T22:43:29.945534Z"}]}
{"channel":"book","type":"update","data":[{"symbol":"ADA/USDT","bids":[{"price":0.452393,"qty":3303.67837633}],"asks":[],"checksum":173755344,"timestamp":"2024-06-01T22:43:29.985452Z"}]}
{"channel":"book","type":"update","data":[{"symbol":"ADA/USDT","bids":[{"price":0.452388,"qty":0.00000000},{"price":0.452108,"qty":87.40221984}],"asks":[],"checksum":2853208674,"timestamp":"2024-06-01T22:43:31.089810Z"}]}
{"channel":"book","type":"update","data":[{"symbol":"ADA/USDT","bids":[{"price":0.452393,"qty":0.00000000},{"price":0.452107,"qty":11068.64350842}],"asks":[],"checksum":3536389301,"timestamp":"2024-06-01T22:43:32.165573Z"}]}
{"channel":"book","type":"update","data":[{"symbol":"ADA/USDT","bids":[{"price":0.452392,"qty":3303.72238462}],"asks":[],"checksum":1456734902,"timestamp":"2024-06-01T22:43:32.205726Z"}]}
{"channel":"book","type":"update","data":[{"symbol":"ADA/USDT","bids":[{"price":0.452108,"qty":0.00000000},{"price":0.452107,"qty":11068.64350842}],"asks":[],"checksum":3260152462,"timestamp":"2024-06-01T22:43:32.797736Z"}]}
{"channel":"book","type":"update","data":[{"symbol":"ADA/USDT","bids":[{"price":0.452275,"qty":44.24116318}],"asks":[],"checksum":1633390996,"timestamp":"2024-06-01T22:43:32.803143Z"}]}
{"channel":"book","type":"update","data":[{"symbol":"ADA/USDT","bids":[{"price":0.452392,"qty":0.00000000},{"price":0.452108,"qty":260.04644647}],"asks":[],"checksum":1532955098,"timestamp":"2024-06-01T22:43:37.177273Z"}]}
{"channel":"book","type":"update","data":[{"symbol":"ADA/USDT","bids":[{"price":0.452393,"qty":3303.58342838}],"asks":[],"checksum":2961262539,"timestamp":"2024-06-01T22:43:37.217355Z"}]}
{"channel":"book","type":"update","data":[{"symbol":"ADA/USDT","bids":[{"price":0.452393,"qty":0.00000000},{"price":0.452108,"qty":260.04644647}],"asks":[],"checksum":1532955098,"timestamp":"2024-06-01T22:43:37.727240Z"}]}
{"channel":"book","type":"update","data":[{"symbol":"ADA/USDT","bids":[{"price":0.452394,"qty":3303.56305289}],"asks":[],"checksum":3501857237,"timestamp":"2024-06-01T22:43:37.767684Z"}]}
{"channel":"book","type":"update","data":[{"symbol":"ADA/USDT","bids":[{"price":0.452394,"qty":0.00000000},{"price":0.452108,"qty":260.04644647}],"asks":[],"checksum":1532955098,"timestamp":"2024-06-01T22:43:38.213977Z"}]}
{"channel":"book","type":"update","data":[{"symbol":"ADA/USDT","bids":[{"price":0.452395,"qty":3303.59687467}],"asks":[],"checksum":65219157,"timestamp":"2024-06-01T22:43:38.254316Z"}]}
{"channel":"book","type":"update","data":[{"symbol":"ADA/USDT","bids":[{"price":0.452395,"qty":0.00000000},{"price":0.452108,"qty":260.04644647}],"asks":[],"checksum":1532955098,"timestamp":"2024-06-01T22:43:39.282772Z"}]}
{"channel":"book","type":"update","data":[{"symbol":"ADA/USDT","bids":[{"price":0.452394,"qty":3303.59736143}],"asks":[],"checksum":1761925706,"timestamp":"2024-06-01T22:43:39.323006Z"}]}
{"channel":"book","type":"update","data":[{"symbol":"ADA/USDT","bids":[{"price":0.452394,"qty":0.00000000},{"price":0.452108,"qty":260.04644647}],"asks":[],"checksum":1532955098,"timestamp":"2024-06-01T22:43:42.375040Z"}]}
{"channel":"book","type":"update","data":[{"symbol":"ADA/USDT","bids":[{"price":0.452393,"qty":3303.59736143}],"asks":[],"checksum":1496385238,"timestamp":"2024-06-01T22:43:42.415252Z"}]}
{"channel":"book","type":"update","data":[{"symbol":"ADA/USDT","bids":[],"asks":[{"price":0.452818,"qty":0.00000000},{"price":0.452879,"qty":73.83575134}],"checksum":1374041908,"timestamp":"2024-06-01T22:43:42.619155Z"}]}
{"channel":"book","type":"update","data":[{"symbol":"ADA/USDT","bids":[],"asks":[{"price":0.452737,"qty":0.00000000},{"price":0.452883,"qty":2175.21196000}],"checksum":486198359,"timestamp":"2024-06-01T22:43:42.623049Z"}]}
{"channel":"book","type":"update","data":[{"symbol":"ADA/USDT","bids":[{"price":0.452278,"qty":792.36248106}],"asks":[],"checksum":60551588,"timestamp":"2024-06-01T22:43:42.623150Z"}]}
{"channel":"book","type":"update","data":[{"symbol":"ADA/USDT","bids":[],"asks":[{"price":0.452700,"qty":0.00000000},{"price":0.452892,"qty":36.34233859}],"checksum":744683377,"timestamp":"2024-06-01T22:43:42.629858Z"}]}
{"channel":"book","type":"update","data":[{"symbol":"ADA/USDT","bids":[],"asks":[{"price":0.452555,"qty":0.00000000},{"price":0.452901,"qty":2112.00000000}],"checksum":3548143627,"timestamp":"2024-06-01T22:43:42.630475Z"}]}
{"channel":"book","type":"update","data":[{"symbol":"ADA/USDT","bids":[{"price":0.452374,"qty":0.00000000},{"price":0.452108,"qty":2372.04644647}],"asks":[],"checksum":3877046771,"timestamp":"2024-06-01T22:43:42.630561Z"}]}
{"channel":"book","type":"update","data":[{"symbol":"ADA/USDT","bids":[],"asks":[{"price":0.452800,"qty":4554.52143223}],"checksum":2816309248,"timestamp":"2024-06-01T22:43:42.635370Z"}]}
{"channel":"book","type":"update","data":[{"symbol":"ADA/USDT","bids":[],"asks":[{"price":0.452625,"qty":11055.98522552}],"checksum":3835315062,"timestamp":"2024-06-01T22:43:42.637914Z"}]}
{"channel":"book","type":"update","data":[{"symbol":"ADA/USDT","bids":[{"price":0.452399,"qty":5530.75046741}],"asks":[],"checksum":1663204341,"timestamp":"2024-06-01T22:43:42.637928Z"}]}
{"channel":"book","type":"update","data":[{"symbol":"ADA/USDT","bids":[{"price":0.452398,"qty":0.00000000},{"price":0.452108,"qty":2372.04644647}],"asks":[],"checksum":2980878656,"timestamp":"2024-06-01T22:43:42.659243Z"}]}
{"channel":"book","type":"update","data":[{"symbol":"ADA/USDT","bids":[{"price":0.452400,"qty":600.00000000}],"asks":[],"checksum":1319318684,"timestamp":"2024-06-01T22:43:42.659652Z"}]}
{"channel":"book","type":"update","data":[{"symbol":"ADA/USDT","bids":[],"asks":[{"price":0.452533,"qty":0.00000000},{"price":0.452892,"qty":36.34233859}],"checksum":1114681119,"timestamp":"2024-06-01T22:43:42.660676Z"}]}
{"channel":"book","type":"update","data":[{"symbol":"ADA/USDT","bids":[{"price":0.452409,"qty":800.00000000}],"asks":[],"checksum":4244609226,"timestamp":"2024-06-01T22:43:42.663688Z"}]}
{"channel":"book","type":"update","data":[{"symbol":"ADA/USDT","bids":[{"price":0.452400,"qty":0.00000000},{"price":0.452129,"qty":370.00000000}],"asks":[],"checksum":434234554,"timestamp":"2024-06-01T22:43:42.718152Z"}]}
{"channel":"book","type":"update","data":[{"symbol":"ADA/USDT","bids":[{"price":0.452410,"qty":600.00000000}],"asks":[],"checksum":3701280760,"timestamp":"2024-06-01T22:43:42.718430Z"}]}
{"channel":"book","type":"update","data":[{"symbol":"ADA/USDT","bids":[{"price":0.452350,"qty":0.00000000},{"price":0.452129,"qty":370.00000000}],"asks":[],"checksum":3557911778,"timestamp":"2024-06-01T22:43:42.722843Z"}]}
{"channel":"book","type":"update","data":[{"symbol":"ADA/USDT","bids":[],"asks":[{"price":0.452819,"qty":0.00000000},{"price":0.452901,"qty":2112.00000000}],"checksum":1046418149,"timestamp":"2024-06-01T22:43:42.734767Z"}]}
{"channel":"book","type":"update","data":[{"symbol":"ADA/USDT","bids":[{"price":0.452393,"qty":0.00000000},{"price":0.452108,"qty":2372.04644647}],"asks":[],"checksum":3911171706,"timestamp":"2024-06-01T22:43:42.926872Z"}]}
