{"channel":"book","type":"snapshot","data":[{"symbol":"ADA/USD","bids":[{"price":0.451937,"qty":5531.74446880},{"price":0.451936,"qty":11060.90334582},{"price":0.451928,"qty":1600.34540247},{"price":0.451878,"qty":1900.00000000},{"price":0.451876,"qty":721.50121232},{"price":0.451855,"qty":370.00000000},{"price":0.451851,"qty":33.79805661},{"price":0.451847,"qty":10000.00000000},{"price":0.451846,"qty":1665.51870603},{"price":0.451843,"qty":11055.91829313}],"asks":[{"price":0.451995,"qty":1000.00000000},{"price":0.452051,"qty":5530.36125868},{"price":0.452068,"qty":91.70666280},{"price":0.452124,"qty":149.49701430},{"price":0.452139,"qty":1900.00000000},{"price":0.452153,"qty":253.71100506},{"price":0.452205,"qty":11056.94601674},{"price":0.452246,"qty":1450.70000000},{"price":0.452278,"qty":5529.71578600},{"price":0.452292,"qty":78.34833535}],"checksum":353488609}]}
{"channel":"book","type":"update","data":[{"symbol":"ADA/USD","bids":[{"price":0.451848,"qty":13127.43983263}],"asks":[],"checksum":4103196961,"timestamp":"2024-06-01T22:43:07.513084Z"}]}
{"channel":"book","type":"update","data":[{"symbol":"ADA/USD","bids":[{"price":0.451927,"qty":55304.51672911}],"asks":[],"checksum":529476021,"timestamp":"2024-06-01T22:43:09.355757Z"}]}
{"channel":"book","type":"update","data":[{"symbol":"ADA/USD","bids":[{"price":0.451927,"qty":0.00000000},{"price":0.451846,"qty":1665.51870603}],"asks":[],"checksum":4103196961,"timestamp":"2024-06-01T22:43:11.846307Z"}]}
{"channel":"book","type":"update","data":[{"symbol":"ADA/USD","bids":[{"price":0.451927,"qty":55304.51672911}],"asks":[],"checksum":529476021,"timestamp":"2024-06-01T22:43:14.573275Z"}]}
{"channel":"book","type":"update","data":[{"symbol":"ADA/USD","bids":[{"price":0.451945,"qty":55304.51672911}],"asks":[],"checksum":3715793996,"timestamp":"2024-06-01T22:43:18.156699Z"}]}
{"channel":"book","type":"update","data":[{"symbol":"ADA/USD","bids":[{"price":0.451848,"qty":0.00000000},{"price":0.451847,"qty":10000.00000000},{"price":0.451938,"qty":13127.43983263}],"asks":[],"checksum":2018149012,"timestamp":"2024-06-01T22:43:18.157679Z"}]}
{"channel":"book","type":"update","data":[{"symbol":"ADA/USD","bids":[{"price":0.451851,"qty":0.00000000},{"price":0.451847,"qty":10000.00000000}],"asks":[],"checksum":3431156997,"timestamp":"2024-06-01T22:43:18.157899Z"}]}
{"channel":"book","type":"update","data":[{"symbol":"ADA/USD","bids":[{"price":0.451951,"qty":11060.90334582}],"asks":[],"checksum":822121567,"timestamp":"2024-06-01T22:43:18.159680Z"}]}
{"channel":"book","type":"update","data":[{"symbol":"ADA/USD","bids":[{"price":0.451860,"qty":5876.59157689}],"asks":[],"checksum":1978160904,"timestamp":"2024-06-01T22:43:18.160688Z"}]}
{"channel":"book","type":"update","data":[{"symbol":"ADA/USD","bids":[{"price":0.451936,"qty":0.00000000},{"price":0.451855,"qty":370.00000000}],"asks":[],"checksum":2126543974,"timestamp":"2024-06-01T22:43:18.164083Z"}]}
{"channel":"book","type":"update","data":[{"symbol":"ADA/USD","bids":[],"asks":[{"price":0.452124,"qty":0.00000000},{"price":0.452306,"qty":44.25094348}],"checksum":540223002,"timestamp":"2024-06-01T22:43:18.292889Z"}]}
{"channel":"book","type":"update","data":[{"symbol":"ADA/USD","bids":[{"price":0.451930,"qty":327.45318857}],"asks":[],"checksum":2925845340,"timestamp":"2024-06-01T22:43:18.296100Z"}]}
{"channel":"book","type":"update","data":[{"symbol":"ADA/USD","bids":[],"asks":[{"price":0.452247,"qty":149.49469894}],"checksum":532318579,"timestamp":"2024-06-01T22:43:18.296385Z"}]}
{"channel":"book","type":"update","data":[{"symbol":"ADA/USD","bids":[{"price":0.451876,"qty":1048.95440089}],"asks":[],"checksum":705750323,"timestamp":"2024-06-01T22:43:18.323404Z"}]}
{"channel":"book","type":"update","data":[{"symbol":"ADA/USD","bids":[{"price":0.451930,"qty":0.00000000},{"price":0.451855,"qty":370.00000000}],"asks":[],"checksum":3300126431,"timestamp":"2024-06-01T22:43:18.326303Z"}]}
{"channel":"book","type":"update","data":[{"symbol":"ADA/USD","bids":[],"asks":[{"price":0.452051,"qty":0.00000000},{"price":0.452306,"qty":44.25094348}],"checksum":1538234154,"timestamp":"2024-06-01T22:43:19.162020Z"}]}
{"channel":"book","type":"update","data":[{"symbol":"ADA/USD","bids":[{"price":0.451937,"qty":0.00000000},{"price":0.451847,"qty":10000.00000000}],"asks":[],"checksum":438798395,"timestamp":"2024-06-01T22:43:19.162121Z"}]}
{"channel":"book","type":"update","data":[{"symbol":"ADA/USD","bids":[{"price":0.451952,"qty":33.79805661}],"asks":[],"checksum":2026272838,"timestamp":"2024-06-01T22:43:19.167184Z"}]}
{"channel":"book","type":"update","data":[{"symbol":"ADA/USD","bids":[{"price":0.451952,"qty":5565.35893033}],"asks":[],"checksum":282962905,"timestamp":"2024-06-01T22:43:19.169093Z"}]}
{"channel":"book","type":"update","data":[{"symbol":"ADA/USD","bids":[],"asks":[{"price":0.452108,"qty":5529.66254888}],"checksum":4165912178,"timestamp":"2024-06-01T22:43:19.169120Z"}]}
{"channel":"book","type":"update","data":[{"symbol":"ADA/USD","bids":[],"asks":[{"price":0.452174,"qty":149.49453356}],"checksum":1208705105,"timestamp":"2024-06-01T22:43:19.172302Z"}]}
{"channel":"book","type":"update","data":[{"symbol":"ADA/USD","bids":[{"price":0.451938,"qty":0.00000000},{"price":0.451847,"qty":10000.00000000}],"asks":[],"checksum":2065449792,"timestamp":"2024-06-01T22:43:19.510072Z"}]}
{"channel":"book","type":"update","data":[{"symbol":"ADA/USD","bids":[{"price":0.451953,"qty":55304.51672911}],"asks":[],"checksum":141027932,"timestamp":"2024-06-01T22:43:20.188349Z"}]}
{"channel":"book","type":"update","data":[{"symbol":"ADA/USD","bids":[{"price":0.451927,"qty":0.00000000},{"price":0.451847,"qty":10000.00000000}],"asks":[],"checksum":1600957351,"timestamp":"2024-06-01T22:43:20.192164Z"}]}
{"channel":"book","type":"update","data":[{"symbol":"ADA/USD","bids":[{"price":0.451952,"qty":33.79805661}],"asks":[],"checksum":334479893,"timestamp":"2024-06-01T22:43:20.193308Z"}]}
{"channel":"book","type":"update","data":[{"symbol":"ADA/USD","bids":[{"price":0.451954,"qty":5531.53639529}],"asks":[],"checksum":2230329430,"timestamp":"2024-06-01T22:43:20.197781Z"}]}
{"channel":"book","type":"update","data":[{"symbol":"ADA/USD","bids":[{"price":0.451955,"qty":11060.09663548}],"asks":[],"checksum":3996044484,"timestamp":"2024-06-01T22:43:20.447076Z"}]}
{"channel":"book","type":"update","data":[{"symbol":"ADA/USD","bids":[{"price":0.451954,"qty":0.00000000},{"price":0.451855,"qty":370.00000000}],"asks":[],"checksum":150361436,"timestamp":"2024-06-01T22:43:20.451967Z"}]}
{"channel":"book","type":"update","data":[{"symbol":"ADA/USD","bids":[{"price":0.451956,"qty":5531.51191708}],"asks":[],"checksum":3618941139,"timestamp":"2024-06-01T22:43:20.456452Z"}]}
{"channel":"book","type":"update","data":[{"symbol":"ADA/USD","bids":[{"price":0.451951,"qty":0.00000000},{"price":0.451855,"qty":370.00000000}],"asks":[],"checksum":3765916410,"timestamp":"2024-06-01T22:43:20.467279Z"}]}
{"channel":"book","type":"update","data":[{"symbol":"ADA/USD","bids":[],"asks":[{"price":0.452139,"qty":0.00000000},{"price":0.452292,"qty":78.34833535}],"checksum":3036476409,"timestamp":"2024-06-01T22:43:20.881293Z"}]}
{"channel":"book","type":"update","data":[{"symbol":"ADA/USD","bids":[{"price":0.451952,"qty":0.00000000},{"price":0.451847,"qty":10000.00000000}],"asks":[],"checksum":936892418,"timestamp":"2024-06-01T22:43:20.886913Z"}]}
{"channel":"book","type":"update","data":[{"symbol":"ADA/USD","bids":[{"price":0.451955,"qty":11470.09663548}],"asks":[],"checksum":927494427,"timestamp":"2024-06-01T22:43:20.895945Z"}]}
{"channel":"book","type":"update","data":[{"symbol":"ADA/USD","bids":[{"price":0.451957,"qty":11060.09663548}],"asks":[],"checksum":1682415301,"timestamp":"2024-06-01T22:43:20.906775Z"}]}
{"channel":"book","type":"update","data":[{"symbol":"ADA/USD","bids":[{"price":0.451955,"qty":410.00000000}],"asks":[],"checksum":3072733629,"timestamp":"2024-06-01T22:43:20.910662Z"}]}
{"channel":"book","type":"update","data":[{"symbol":"ADA/USD","bids":[{"price":0.451956,"qty":0.00000000},{"price":0.451847,"qty":10000.00000000}],"asks":[],"checksum":2341248204,"timestamp":"2024-06-01T22:43:20.911909Z"}]}
{"channel":"book","type":"update","data":[{"symbol":"ADA/USD","bids":[{"price":0.451958,"qty":5531.48743909}],"asks":[],"checksum":535040806,"timestamp":"2024-06-01T22:43:20.916228Z"}]}
{"channel":"book","type":"update","data":[{"symbol":"ADA/USD","bids":[{"price":0.451876,"qty":721.50121232}],"asks":[],"checksum":2111396639,"timestamp":"2024-06-01T22:43:21.132364Z"}]}
{"channel":"book","type":"update","data":[{"symbol":"ADA/USD","bids":[{"price":0.451959,"qty":55300.48317738}],"asks":[],"checksum":2774240679,"timestamp":"2024-06-01T22:43:22.188549Z"}]}
{"channel":"book","type":"update","data":[{"symbol":"ADA/USD","bids":[{"price":0.451945,"qty":0.00000000},{"price":0.451855,"qty":370.00000000}],"asks":[],"checksum":3263525055,"timestamp":"2024-06-01T22:43:22.192449Z"}]}
{"channel":"book","type":"update","data":[{"symbol":"ADA/USD","bids":[{"price":0.451960,"qty":33.79805661}],"asks":[],"checksum":3547200868,"timestamp":"2024-06-01T22:43:22.193360Z"}]}
{"channel":"book","type":"update","data":[{"symbol":"ADA/USD","bids":[{"price":0.451958,"qty":0.00000000},{"price":0.451855,"qty":370.00000000}],"asks":[],"checksum":4000868763,"timestamp":"2024-06-01T22:43:22.193555Z"}]}
{"channel":"book","type":"update","data":[{"symbol":"ADA/USD","bids":[{"price":0.451960,"qty":5565.26101793}],"asks":[],"checksum":2896998132,"timestamp":"2024-06-01T22:43:22.198109Z"}]}
{"channel":"book","type":"update","data":[{"symbol":"ADA/USD","bids":[{"price":0.451961,"qty":33.79805661}],"asks":[],"checksum":3649071207,"timestamp":"2024-06-01T22:43:24.238358Z"}]}
{"channel":"book","type":"update","data":[{"symbol":"ADA/USD","bids":[{"price":0.451960,"qty":33.79805661}],"asks":[],"checksum":3448215886,"timestamp":"2024-06-01T22:43:24.243723Z"}]}
{"channel":"book","type":"update","data":[{"symbol":"ADA/USD","bids":[{"price":0.451962,"qty":5531.43848376}],"asks":[],"checksum":898480941,"timestamp":"2024-06-01T22:43:24.249466Z"}]}
{"channel":"book","type":"update","data":[{"symbol":"ADA/USD","bids":[{"price":0.451960,"qty":0.00000000},{"price":0.451860,"qty":5876.59157689}],"asks":[],"checksum":3424209517,"timestamp":"2024-06-01T22:43:24.253983Z"}]}
{"channel":"book","type":"update","data":[{"symbol":"ADA/USD","bids":[{"price":0.451963,"qty":33.79805661}],"asks":[],"checksum":757498745,"timestamp":"2024-06-01T22:43:24.960838Z"}]}
{"channel":"book","type":"update","data":[{"symbol":"ADA/USD","bids":[{"price":0.451962,"qty":0.00000000},{"price":0.451860,"qty":5876.59157689}],"asks":[],"checksum":3936352275,"timestamp":"2024-06-01T22:43:24.966067Z"}]}
{"channel":"book","type":"update","data":[{"symbol":"ADA/USD","bids":[{"price":0.451964,"qty":5531.41400642}],"asks":[],"checksum":992984283,"timestamp":"2024-06-01T22:43:24.970131Z"}]}
{"channel":"book","type":"update","data":[{"symbol":"ADA/USD","bids":[{"price":0.451965,"qty":11060.09663548}],"asks":[],"checksum":3024380098,"timestamp":"2024-06-01T22:43:25.316445Z"}]}
{"channel":"book","type":"update","data":[{"symbol":"ADA/USD","bids":[{"price":0.451957,"qty":0.00000000},{"price":0.451876,"qty":721.50121232}],"asks":[],"checksum":3770446984,"timestamp":"2024-06-01T22:43:25.320466Z"}]}
{"channel":"book","type":"update","data":[{"symbol":"ADA/USD","bids":[{"price":0.451961,"qty":0.00000000},{"price":0.451860,"qty":5876.59157689}],"asks":[],"checksum":982693595,"timestamp":"2024-06-01T22:43:25.737748Z"}]}
{"channel":"book","type":"update","data":[{"symbol":"ADA/USD","bids":[{"price":0.451898,"qty":327.44811717}],"asks":[],"checksum":3017074445,"timestamp":"2024-06-01T22:43:26.619032Z"}]}
{"channel":"book","type":"update","data":[{"symbol":"ADA/USD","bids":[{"price":0.451928,"qty":0.00000000},{"price":0.451860,"qty":5876.59157689}],"asks":[],"checksum":2905775208,"timestamp":"2024-06-01T22:43:26.645189Z"}]}
{"channel":"book","type":"update","data":[{"symbol":"ADA/USD","bids":[{"price":0.451966,"qty":1600.21085003}],"asks":[],"checksum":1659531720,"timestamp":"2024-06-01T22:43:26.763624Z"}]}
{"channel":"book","type":"update","data":[{"symbol":"ADA/USD","bids":[{"price":0.451898,"qty":0.00000000},{"price":0.451860,"qty":5876.59157689}],"asks":[],"checksum":3511533170,"timestamp":"2024-06-01T22:43:26.817353Z"}]}
{"channel":"book","type":"update","data":[{"symbol":"ADA/USD","bids":[{"price":0.451967,"qty":7599.60876256}],"asks":[],"checksum":686564975,"timestamp":"2024-06-01T22:43:26.858903Z"}]}
{"channel":"book","type":"update","data":[{"symbol":"ADA/USD","bids":[{"price":0.451968,"qty":33.79805661}],"asks":[],"checksum":636990448,"timestamp":"2024-06-01T22:43:27.848135Z"}]}
{"channel":"book","type":"update","data":[{"symbol":"ADA/USD","bids":[{"price":0.451968,"qty":67.59611322}],"asks":[],"checksum":3777702026,"timestamp":"2024-06-01T22:43:27.853830Z"}]}
{"channel":"book","type":"update","data":[{"symbol":"ADA/USD","bids":[{"price":0.451967,"qty":0.00000000},{"price":0.451876,"qty":721.50121232}],"asks":[],"checksum":2611655012,"timestamp":"2024-06-01T22:43:27.896724Z"}]}
{"channel":"book","type":"update","data":[{"symbol":"ADA/USD","bids":[{"price":0.451968,"qty":33.79805661}],"asks":[],"checksum":645624733,"timestamp":"2024-06-01T22:43:27.901435Z"}]}
{"channel":"book","type":"update","data":[{"symbol":"ADA/USD","bids":[{"price":0.451968,"qty":0.00000000},{"price":0.451860,"qty":5876.59157689}],"asks":[],"checksum":3511533170,"timestamp":"2024-06-01T22:43:27.903045Z"}]}
{"channel":"book","type":"update","data":[{"symbol":"ADA/USD","bids":[{"price":0.451967,"qty":33.79805661}],"asks":[],"checksum":1899588222,"timestamp":"2024-06-01T22:43:27.903058Z"}]}
{"channel":"book","type":"update","data":[{"symbol":"ADA/USD","bids":[{"price":0.451968,"qty":11060.09663548}],"asks":[],"checksum":2694615386,"timestamp":"2024-06-01T22:43:30.864449Z"}]}
{"channel":"book","type":"update","data":[{"symbol":"ADA/USD","bids":[{"price":0.451969,"qty":33.79805661}],"asks":[],"checksum":132800445,"timestamp":"2024-06-01T22:43:30.870448Z"}]}
{"channel":"book","type":"update","data":[{"symbol":"ADA/USD","bids":[{"price":0.451965,"qty":0.00000000},{"price":0.451878,"qty":1900.00000000}],"asks":[],"checksum":1954127638,"timestamp":"2024-06-01T22:43:30.875671Z"}]}
{"channel":"book","type":"update","data":[{"symbol":"ADA/USD","bids":[{"price":0.451967,"qty":0.00000000},{"price":0.451876,"qty":721.50121232}],"asks":[],"checksum":3408733964,"timestamp":"2024-06-01T22:43:31.346795Z"}]}
