{"channel":"book","type":"snapshot","data":[{"symbol":"ADA/EUR","bids":[{"price":0.416735,"qty":870.00000000},{"price":0.416734,"qty":7741.47989757},{"price":0.416732,"qty":923.52456466},{"price":0.416713,"qty":121.22090000},{"price":0.416692,"qty":2100.00000000},{"price":0.416659,"qty":1150.67827488},{"price":0.416650,"qty":5876.59157689},{"price":0.416646,"qty":11055.91829313},{"price":0.416641,"qty":11060.90334582},{"price":0.416635,"qty":24385.37509912}],"asks":[{"price":0.416844,"qty":7077.78882128},{"price":0.416924,"qty":870.00000000},{"price":0.416935,"qty":7737.76239909},{"price":0.416975,"qty":184.30279142},{"price":0.416982,"qty":33.79805661},{"price":0.416985,"qty":33.79805661},{"price":0.417002,"qty":33.79805661},{"price":0.417008,"qty":2100.00000000},{"price":0.417014,"qty":1170.48636843},{"price":0.417038,"qty":7735.84483160}],"checksum":3629430222}]}
{"channel":"book","type":"update","data":[{"symbol":"ADA/EUR","bids":[{"price":0.416635,"qty":0.00000000},{"price":0.416633,"qty":22121.80669165},{"price":0.416634,"qty":24385.37509912}],"asks":[],"checksum":1163613368,"timestamp":"2024-06-01T22:43:09.358333Z"}]}
{"channel":"book","type":"update","data":[{"symbol":"ADA/EUR","bids":[{"price":0.416651,"qty":44.25094348}],"asks":[],"checksum":963436898,"timestamp":"2024-06-01T22:43:09.936389Z"}]}
{"channel":"book","type":"update","data":[{"symbol":"ADA/EUR","bids":[{"price":0.416734,"qty":0.00000000},{"price":0.416628,"qty":24385.37509912}],"asks":[],"checksum":4211444873,"timestamp":"2024-06-01T22:43:13.526305Z"}]}
{"channel":"book","type":"update","data":[{"symbol":"ADA/EUR","bids":[{"price":0.416728,"qty":7741.58925203}],"asks":[],"checksum":3060746774,"timestamp":"2024-06-01T22:43:13.530756Z"}]}
{"channel":"book","type":"update","data":[{"symbol":"ADA/EUR","bids":[{"price":0.416651,"qty":0.00000000},{"price":0.416634,"qty":24385.37509912}],"asks":[],"checksum":3260653603,"timestamp":"2024-06-01T22:43:15.150853Z"}]}
{"channel":"book","type":"update","data":[{"symbol":"ADA/EUR","bids":[{"price":0.416651,"qty":101.96942904}],"asks":[],"checksum":2749665516,"timestamp":"2024-06-01T22:43:15.157883Z"}]}
{"channel":"book","type":"update","data":[{"symbol":"ADA/EUR","bids":[{"price":0.416732,"qty":0.00000000},{"price":0.416634,"qty":24385.37509912}],"asks":[],"checksum":2170711516,"timestamp":"2024-06-01T22:43:17.224104Z"}]}
{"channel":"book","type":"update","data":[{"symbol":"ADA/EUR","bids":[{"price":0.416736,"qty":923.51570030}],"asks":[],"checksum":3406841170,"timestamp":"2024-06-01T22:43:17.462215Z"}]}
{"channel":"book","type":"update","data":[{"symbol":"ADA/EUR","bids":[{"price":0.416735,"qty":0.00000000},{"price":0.416634,"qty":24385.37509912}],"asks":[],"checksum":4091592370,"timestamp":"2024-06-01T22:43:17.465002Z"}]}
{"channel":"book","type":"update","data":[{"symbol":"ADA/EUR","bids":[{"price":0.416746,"qty":870.00000000}],"asks":[],"checksum":114805751,"timestamp":"2024-06-01T22:43:17.465492Z"}]}
{"channel":"book","type":"update","data":[{"symbol":"ADA/EUR","bids":[],"asks":[{"price":0.416985,"qty":0.00000000},{"price":0.417046,"qty":33.79805661}],"checksum":2709343931,"timestamp":"2024-06-01T22:43:18.153550Z"}]}
{"channel":"book","type":"update","data":[{"symbol":"ADA/EUR","bids":[],"asks":[{"price":0.416982,"qty":0.00000000},{"price":0.417076,"qty":5876.59157689}],"checksum":2086932543,"timestamp":"2024-06-01T22:43:18.153785Z"}]}
{"channel":"book","type":"update","data":[{"symbol":"ADA/EUR","bids":[],"asks":[{"price":0.417076,"qty":0.00000000},{"price":0.417077,"qty":1628.00162800}],"checksum":2258831880,"timestamp":"2024-06-01T22:43:18.153801Z"}]}
{"channel":"book","type":"update","data":[{"symbol":"ADA/EUR","bids":[],"asks":[{"price":0.417002,"qty":0.00000000},{"price":0.417134,"qty":44.25094348}],"checksum":559408502,"timestamp":"2024-06-01T22:43:18.153845Z"}]}
{"channel":"book","type":"update","data":[{"symbol":"ADA/EUR","bids":[],"asks":[{"price":0.417046,"qty":0.00000000},{"price":0.417136,"qty":10000.00000000}],"checksum":2850040830,"timestamp":"2024-06-01T22:43:18.154293Z"}]}
{"channel":"book","type":"update","data":[{"symbol":"ADA/EUR","bids":[{"price":0.416651,"qty":135.76748565}],"asks":[],"checksum":3363106577,"timestamp":"2024-06-01T22:43:18.158066Z"}]}
{"channel":"book","type":"update","data":[{"symbol":"ADA/EUR","bids":[{"price":0.416646,"qty":0.00000000},{"price":0.416634,"qty":24385.37509912}],"asks":[],"checksum":3144561401,"timestamp":"2024-06-01T22:43:18.160191Z"}]}
{"channel":"book","type":"update","data":[{"symbol":"ADA/EUR","bids":[{"price":0.416668,"qty":33.79805661}],"asks":[],"checksum":1965536770,"timestamp":"2024-06-01T22:43:18.239755Z"}]}
{"channel":"book","type":"update","data":[{"symbol":"ADA/EUR","bids":[{"price":0.416747,"qty":33.79805661}],"asks":[],"checksum":2672308064,"timestamp":"2024-06-01T22:43:18.339546Z"}]}
{"channel":"book","type":"update","data":[{"symbol":"ADA/EUR","bids":[{"price":0.416747,"qty":5910.38963350}],"asks":[],"checksum":1016954877,"timestamp":"2024-06-01T22:43:18.343734Z"}]}
{"channel":"book","type":"update","data":[{"symbol":"ADA/EUR","bids":[{"price":0.416746,"qty":0.00000000},{"price":0.416641,"qty":11060.90334582}],"asks":[],"checksum":3530705198,"timestamp":"2024-06-01T22:43:18.346332Z"}]}
{"channel":"book","type":"update","data":[{"symbol":"ADA/EUR","bids":[{"price":0.416753,"qty":870.00000000}],"asks":[],"checksum":844993184,"timestamp":"2024-06-01T22:43:18.346359Z"}]}
{"channel":"book","type":"update","data":[{"symbol":"ADA/EUR","bids":[{"price":0.416650,"qty":0.00000000},{"price":0.416641,"qty":11060.90334582}],"asks":[],"checksum":3894238930,"timestamp":"2024-06-01T22:43:18.515479Z"}]}
{"channel":"book","type":"update","data":[{"symbol":"ADA/EUR","bids":[{"price":0.416754,"qty":5876.59157689}],"asks":[],"checksum":3038366593,"timestamp":"2024-06-01T22:43:19.018834Z"}]}
{"channel":"book","type":"update","data":[{"symbol":"ADA/EUR","bids":[{"price":0.416753,"qty":0.00000000},{"price":0.416641,"qty":11060.90334582}],"asks":[],"checksum":4052151810,"timestamp":"2024-06-01T22:43:19.021491Z"}]}
{"channel":"book","type":"update","data":[{"symbol":"ADA/EUR","bids":[{"price":0.416755,"qty":870.00000000}],"asks":[],"checksum":551770274,"timestamp":"2024-06-01T22:43:19.021911Z"}]}
{"channel":"book","type":"update","data":[{"symbol":"ADA/EUR","bids":[{"price":0.416747,"qty":33.79805661}],"asks":[],"checksum":4244051769,"timestamp":"2024-06-01T22:43:19.022597Z"}]}
{"channel":"book","type":"update","data":[{"symbol":"ADA/EUR","bids":[],"asks":[{"price":0.416844,"qty":0.00000000},{"price":0.417141,"qty":5876.59157689}],"checksum":2891667765,"timestamp":"2024-06-01T22:43:19.161681Z"}]}
{"channel":"book","type":"update","data":[{"symbol":"ADA/EUR","bids":[{"price":0.416728,"qty":0.00000000},{"price":0.416642,"qty":24385.37509912}],"asks":[],"checksum":2619884890,"timestamp":"2024-06-01T22:43:19.161759Z"}]}
{"channel":"book","type":"update","data":[{"symbol":"ADA/EUR","bids":[],"asks":[{"price":0.417094,"qty":33.79805661}],"checksum":1068031760,"timestamp":"2024-06-01T22:43:19.165910Z"}]}
{"channel":"book","type":"update","data":[{"symbol":"ADA/EUR","bids":[{"price":0.416756,"qty":5876.59157689}],"asks":[],"checksum":795249758,"timestamp":"2024-06-01T22:43:19.165977Z"}]}
{"channel":"book","type":"update","data":[{"symbol":"ADA/EUR","bids":[],"asks":[{"price":0.417074,"qty":33.79805661}],"checksum":2142283096,"timestamp":"2024-06-01T22:43:19.166915Z"}]}
{"channel":"book","type":"update","data":[{"symbol":"ADA/EUR","bids":[],"asks":[{"price":0.417077,"qty":1661.79968461}],"checksum":1003358668,"timestamp":"2024-06-01T22:43:19.167135Z"}]}
{"channel":"book","type":"update","data":[{"symbol":"ADA/EUR","bids":[{"price":0.416755,"qty":0.00000000},{"price":0.416642,"qty":24385.37509912}],"asks":[],"checksum":493923543,"timestamp":"2024-06-01T22:43:19.168665Z"}]}
{"channel":"book","type":"update","data":[{"symbol":"ADA/EUR","bids":[{"price":0.416763,"qty":870.00000000}],"asks":[],"checksum":3827308507,"timestamp":"2024-06-01T22:43:19.168749Z"}]}
{"channel":"book","type":"update","data":[{"symbol":"ADA/EUR","bids":[],"asks":[{"price":0.416879,"qty":7738.79444737}],"checksum":1082987874,"timestamp":"2024-06-01T22:43:19.169067Z"}]}
{"channel":"book","type":"update","data":[{"symbol":"ADA/EUR","bids":[{"price":0.416756,"qty":13617.66348117}],"asks":[],"checksum":266333464,"timestamp":"2024-06-01T22:43:19.169173Z"}]}
{"channel":"book","type":"update","data":[{"symbol":"ADA/EUR","bids":[{"price":0.416756,"qty":5876.59157689}],"asks":[],"checksum":1082987874,"timestamp":"2024-06-01T22:43:19.175156Z"}]}
{"channel":"book","type":"update","data":[{"symbol":"ADA/EUR","bids":[{"price":0.416756,"qty":0.00000000},{"price":0.416642,"qty":24385.37509912}],"asks":[],"checksum":803822431,"timestamp":"2024-06-01T22:43:19.516382Z"}]}
{"channel":"book","type":"update","data":[{"symbol":"ADA/EUR","bids":[{"price":0.416764,"qty":5876.59157689}],"asks":[],"checksum":99282133,"timestamp":"2024-06-01T22:43:20.015869Z"}]}
{"channel":"book","type":"update","data":[{"symbol":"ADA/EUR","bids":[{"price":0.416651,"qty":33.79805661}],"asks":[],"checksum":2088709030,"timestamp":"2024-06-01T22:43:20.039335Z"}]}
{"channel":"book","type":"update","data":[{"symbol":"ADA/EUR","bids":[{"price":0.416762,"qty":7740.95586279}],"asks":[],"checksum":489158693,"timestamp":"2024-06-01T22:43:20.283210Z"}]}
{"channel":"book","type":"update","data":[{"symbol":"ADA/EUR","bids":[{"price":0.416754,"qty":0.00000000},{"price":0.416651,"qty":33.79805661}],"asks":[],"checksum":2717278063,"timestamp":"2024-06-01T22:43:20.286889Z"}]}
{"channel":"book","type":"update","data":[{"symbol":"ADA/EUR","bids":[{"price":0.416651,"qty":11093.89469209}],"asks":[],"checksum":3383465142,"timestamp":"2024-06-01T22:43:20.446079Z"}]}
{"channel":"book","type":"update","data":[{"symbol":"ADA/EUR","bids":[{"price":0.416763,"qty":0.00000000},{"price":0.416643,"qty":159.68791460}],"asks":[],"checksum":165572574,"timestamp":"2024-06-01T22:43:20.920174Z"}]}
{"channel":"book","type":"update","data":[{"symbol":"ADA/EUR","bids":[{"price":0.416768,"qty":870.00000000}],"asks":[],"checksum":1485315899,"timestamp":"2024-06-01T22:43:20.920452Z"}]}
{"channel":"book","type":"update","data":[{"symbol":"ADA/EUR","bids":[{"price":0.416652,"qty":24385.37509912}],"asks":[],"checksum":3480163245,"timestamp":"2024-06-01T22:43:20.923728Z"}]}
{"channel":"book","type":"update","data":[{"symbol":"ADA/EUR","bids":[{"price":0.416763,"qty":5876.59157689}],"asks":[],"checksum":347878244,"timestamp":"2024-06-01T22:43:20.924478Z"}]}
{"channel":"book","type":"update","data":[{"symbol":"ADA/EUR","bids":[{"price":0.416764,"qty":0.00000000},{"price":0.416652,"qty":24385.37509912}],"asks":[],"checksum":2306684728,"timestamp":"2024-06-01T22:43:20.924524Z"}]}
{"channel":"book","type":"update","data":[{"symbol":"ADA/EUR","bids":[{"price":0.416769,"qty":5876.59157689}],"asks":[],"checksum":1854792311,"timestamp":"2024-06-01T22:43:21.016463Z"}]}
{"channel":"book","type":"update","data":[{"symbol":"ADA/EUR","bids":[{"price":0.416768,"qty":0.00000000},{"price":0.416652,"qty":24385.37509912}],"asks":[],"checksum":2276916005,"timestamp":"2024-06-01T22:43:21.166110Z"}]}
{"channel":"book","type":"update","data":[{"symbol":"ADA/EUR","bids":[{"price":0.416771,"qty":870.00000000}],"asks":[],"checksum":3739796344,"timestamp":"2024-06-01T22:43:21.166272Z"}]}
{"channel":"book","type":"update","data":[{"symbol":"ADA/EUR","bids":[{"price":0.416769,"qty":0.00000000},{"price":0.416652,"qty":24385.37509912}],"asks":[],"checksum":2055736895,"timestamp":"2024-06-01T22:43:21.170175Z"}]}
{"channel":"book","type":"update","data":[{"symbol":"ADA/EUR","bids":[{"price":0.416736,"qty":0.00000000},{"price":0.416651,"qty":11093.89469209}],"asks":[],"checksum":2725238974,"timestamp":"2024-06-01T22:43:21.362853Z"}]}
{"channel":"book","type":"update","data":[{"symbol":"ADA/EUR","bids":[{"price":0.416772,"qty":5876.59157689}],"asks":[],"checksum":1519099523,"timestamp":"2024-06-01T22:43:21.366854Z"}]}
{"channel":"book","type":"update","data":[{"symbol":"ADA/EUR","bids":[{"price":0.416696,"qty":923.60435157}],"asks":[],"checksum":3472111808,"timestamp":"2024-06-01T22:43:21.488388Z"}]}
{"channel":"book","type":"update","data":[{"symbol":"ADA/EUR","bids":[{"price":0.416763,"qty":0.00000000},{"price":0.416652,"qty":24385.37509912}],"asks":[],"checksum":690826749,"timestamp":"2024-06-01T22:43:21.514731Z"}]}
{"channel":"book","type":"update","data":[{"symbol":"ADA/EUR","bids":[{"price":0.416762,"qty":0.00000000},{"price":0.416651,"qty":11093.89469209}],"asks":[],"checksum":2447284383,"timestamp":"2024-06-01T22:43:22.167788Z"}]}
{"channel":"book","type":"update","data":[{"symbol":"ADA/EUR","bids":[],"asks":[{"price":0.416879,"qty":0.00000000},{"price":0.417135,"qty":87.42154165}],"checksum":3191866022,"timestamp":"2024-06-01T22:43:22.168017Z"}]}
{"channel":"book","type":"update","data":[{"symbol":"ADA/EUR","bids":[],"asks":[{"price":0.416871,"qty":7738.94882014}],"checksum":1138043275,"timestamp":"2024-06-01T22:43:22.172551Z"}]}
{"channel":"book","type":"update","data":[{"symbol":"ADA/EUR","bids":[{"price":0.416753,"qty":7741.11377158}],"asks":[],"checksum":3389029864,"timestamp":"2024-06-01T22:43:22.172569Z"}]}
{"channel":"book","type":"update","data":[{"symbol":"ADA/EUR","bids":[{"price":0.416653,"qty":390.47553529}],"asks":[],"checksum":806514839,"timestamp":"2024-06-01T22:43:22.610711Z"}]}
{"channel":"book","type":"update","data":[{"symbol":"ADA/EUR","bids":[{"price":0.416696,"qty":0.00000000},{"price":0.416652,"qty":24385.37509912}],"asks":[],"checksum":1095069211,"timestamp":"2024-06-01T22:43:23.021022Z"}]}
{"channel":"book","type":"update","data":[{"symbol":"ADA/EUR","bids":[{"price":0.416736,"qty":923.51570030}],"asks":[],"checksum":7769228,"timestamp":"2024-06-01T22:43:23.441726Z"}]}
{"channel":"book","type":"update","data":[{"symbol":"ADA/EUR","bids":[],"asks":[{"price":0.416871,"qty":0.00000000},{"price":0.417136,"qty":10000.00000000}],"checksum":1361184355,"timestamp":"2024-06-01T22:43:24.171149Z"}]}
{"channel":"book","type":"update","data":[{"symbol":"ADA/EUR","bids":[{"price":0.416771,"qty":0.00000000},{"price":0.416652,"qty":24385.37509912}],"asks":[],"checksum":2127881550,"timestamp":"2024-06-01T22:43:24.173991Z"}]}
{"channel":"book","type":"update","data":[{"symbol":"ADA/EUR","bids":[{"price":0.416775,"qty":870.00000000}],"asks":[],"checksum":2946532474,"timestamp":"2024-06-01T22:43:24.174192Z"}]}
{"channel":"book","type":"update","data":[{"symbol":"ADA/EUR","bids":[],"asks":[{"price":0.416865,"qty":7739.06492541}],"checksum":440090336,"timestamp":"2024-06-01T22:43:24.175731Z"}]}
{"channel":"book","type":"update","data":[{"symbol":"ADA/EUR","bids":[{"price":0.416776,"qty":5876.59157689}],"asks":[],"checksum":38320136,"timestamp":"2024-06-01T22:43:24.516339Z"}]}
{"channel":"book","type":"update","data":[{"symbol":"ADA/EUR","bids":[{"price":0.416772,"qty":0.00000000},{"price":0.416653,"qty":390.47553529}],"asks":[],"checksum":3967369424,"timestamp":"2024-06-01T22:43:25.017908Z"}]}
{"channel":"book","type":"update","data":[{"symbol":"ADA/EUR","bids":[{"price":0.416653,"qty":0.00000000},{"price":0.416652,"qty":24385.37509912}],"asks":[],"checksum":1407273197,"timestamp":"2024-06-01T22:43:25.152631Z"}]}
{"channel":"book","type":"update","data":[{"symbol":"ADA/EUR","bids":[{"price":0.416653,"qty":361.62267095}],"asks":[],"checksum":593145328,"timestamp":"2024-06-01T22:43:25.157830Z"}]}
{"channel":"book","type":"update","data":[{"symbol":"ADA/EUR","bids":[{"price":0.416753,"qty":0.00000000},{"price":0.416652,"qty":24385.37509912}],"asks":[],"checksum":3258395209,"timestamp":"2024-06-01T22:43:25.171677Z"}]}
{"channel":"book","type":"update","data":[{"symbol":"ADA/EUR","bids":[{"price":0.416745,"qty":7741.25891687}],"asks":[],"checksum":2197127548,"timestamp":"2024-06-01T22:43:25.175330Z"}]}
{"channel":"book","type":"update","data":[{"symbol":"ADA/EUR","bids":[{"price":0.416736,"qty":0.00000000},{"price":0.416652,"qty":24385.37509912}],"asks":[],"checksum":2108196536,"timestamp":"2024-06-01T22:43:25.632905Z"}]}
{"channel":"book","type":"update","data":[{"symbol":"ADA/EUR","bids":[{"price":0.416736,"qty":923.51570030}],"asks":[],"checksum":2197127548,"timestamp":"2024-06-01T22:43:25.934991Z"}]}
{"channel":"book","type":"update","data":[{"symbol":"ADA/EUR","bids":[{"price":0.416736,"qty":0.00000000},{"price":0.416652,"qty":24385.37509912}],"asks":[],"checksum":2108196536,"timestamp":"2024-06-01T22:43:26.645206Z"}]}
{"channel":"book","type":"update","data":[{"symbol":"ADA/EUR","bids":[{"price":0.416738,"qty":923.51126818}],"asks":[],"checksum":2161484311,"timestamp":"2024-06-01T22:43:26.763508Z"}]}
{"channel":"book","type":"update","data":[{"symbol":"ADA/EUR","bids":[{"price":0.416775,"qty":0.00000000},{"price":0.416652,"qty":24385.37509912}],"asks":[],"checksum":1782054489,"timestamp":"2024-06-01T22:43:27.228394Z"}]}
{"channel":"book","type":"update","data":[{"symbol":"ADA/EUR","bids":[{"price":0.416777,"qty":870.00000000}],"asks":[],"checksum":221948385,"timestamp":"2024-06-01T22:43:27.228493Z"}]}
{"channel":"book","type":"update","data":[{"symbol":"ADA/EUR","bids":[{"price":0.416776,"qty":0.00000000},{"price":0.416652,"qty":24385.37509912}],"asks":[],"checksum":4141143383,"timestamp":"2024-06-01T22:43:27.232856Z"}]}
{"channel":"book","type":"update","data":[{"symbol":"ADA/EUR","bids":[{"price":0.416746,"qty":5876.59157689}],"asks":[],"checksum":3341505406,"timestamp":"2024-06-01T22:43:27.232907Z"}]}
{"channel":"book","type":"update","data":[{"symbol":"ADA/EUR","bids":[{"price":0.416778,"qty":5876.59157689}],"asks":[],"checksum":60238486,"timestamp":"2024-06-01T22:43:27.515176Z"}]}
{"channel":"book","type":"update","data":[{"symbol":"ADA/EUR","bids":[{"price":0.416746,"qty":0.00000000},{"price":0.416653,"qty":361.62267095}],"asks":[],"checksum":3081484880,"timestamp":"2024-06-01T22:43:27.518599Z"}]}
{"channel":"book","type":"update","data":[{"symbol":"ADA/EUR","bids":[{"price":0.416653,"qty":0.00000000},{"price":0.416652,"qty":24385.37509912}],"asks":[],"checksum":2117461298,"timestamp":"2024-06-01T22:43:27.721474Z"}]}
{"channel":"book","type":"update","data":[{"symbol":"ADA/EUR","bids":[{"price":0.416653,"qty":390.47553529}],"asks":[],"checksum":2022201200,"timestamp":"2024-06-01T22:43:27.725606Z"}]}
{"channel":"book","type":"update","data":[{"symbol":"ADA/EUR","bids":[{"price":0.416695,"qty":390.00000000}],"asks":[],"checksum":3320602831,"timestamp":"2024-06-01T22:43:27.767578Z"}]}
{"channel":"book","type":"update","data":[{"symbol":"ADA/EUR","bids":[],"asks":[{"price":0.416865,"qty":0.00000000},{"price":0.417136,"qty":10000.00000000}],"checksum":1886902869,"timestamp":"2024-06-01T22:43:29.179846Z"}]}
{"channel":"book","type":"update","data":[{"symbol":"ADA/EUR","bids":[{"price":0.416777,"qty":0.00000000},{"price":0.416653,"qty":390.47553529}],"asks":[],"checksum":2068400160,"timestamp":"2024-06-01T22:43:29.182550Z"}]}
{"channel":"book","type":"update","data":[{"symbol":"ADA/EUR","bids":[{"price":0.416781,"qty":870.00000000}],"asks":[],"checksum":2135023266,"timestamp":"2024-06-01T22:43:29.182974Z"}]}
{"channel":"book","type":"update","data":[{"symbol":"ADA/EUR","bids":[],"asks":[{"price":0.416859,"qty":7739.15956387}],"checksum":1545768029,"timestamp":"2024-06-01T22:43:29.184122Z"}]}
{"channel":"book","type":"update","data":[{"symbol":"ADA/EUR","bids":[{"price":0.416782,"qty":5876.59157689}],"asks":[],"checksum":1155233317,"timestamp":"2024-06-01T22:43:29.513907Z"}]}
{"channel":"book","type":"update","data":[{"symbol":"ADA/EUR","bids":[{"price":0.416778,"qty":0.00000000},{"price":0.416659,"qty":1150.67827488}],"asks":[],"checksum":2593603352,"timestamp":"2024-06-01T22:43:29.517382Z"}]}
{"channel":"book","type":"update","data":[{"symbol":"ADA/EUR","bids":[{"price":0.416715,"qty":5876.59157689}],"asks":[],"checksum":705401265,"timestamp":"2024-06-01T22:43:35.016996Z"}]}
{"channel":"book","type":"update","data":[{"symbol":"ADA/EUR","bids":[{"price":0.416782,"qty":0.00000000},{"price":0.416659,"qty":1150.67827488}],"asks":[],"checksum":89160041,"timestamp":"2024-06-01T22:43:35.017012Z"}]}
{"channel":"book","type":"update","data":[{"symbol":"ADA/EUR","bids":[{"price":0.416738,"qty":0.00000000},{"price":0.416653,"qty":361.62267095}],"asks":[],"checksum":1362509317,"timestamp":"2024-06-01T22:43:36.213338Z"}]}
{"channel":"book","type":"update","data":[{"symbol":"ADA/EUR","bids":[{"price":0.416709,"qty":923.57553804}],"asks":[],"checksum":1492139520,"timestamp":"2024-06-01T22:43:37.251821Z"}]}
{"channel":"book","type":"update","data":[{"symbol":"ADA/EUR","bids":[{"price":0.416688,"qty":22120.19327095}],"asks":[],"checksum":3619630069,"timestamp":"2024-06-01T22:43:37.797847Z"}]}
{"channel":"book","type":"update","data":[{"symbol":"ADA/EUR","bids":[{"price":0.416716,"qty":44.24116318}],"asks":[],"checksum":1166234186,"timestamp":"2024-06-01T22:43:40.477547Z"}]}
{"channel":"book","type":"update","data":[{"symbol":"ADA/EUR","bids":[{"price":0.416693,"qty":101.94689187}],"asks":[],"checksum":3855113227,"timestamp":"2024-06-01T22:43:40.477688Z"}]}
{"channel":"book","type":"update","data":[{"symbol":"ADA/EUR","bids":[],"asks":[{"price":0.416859,"qty":0.00000000},{"price":0.417136,"qty":10000.00000000}],"checksum":1610423548,"timestamp":"2024-06-01T22:43:41.182865Z"}]}
{"channel":"book","type":"update","data":[{"symbol":"ADA/EUR","bids":[],"asks":[{"price":0.416854,"qty":7739.26753767}],"checksum":1977253908,"timestamp":"2024-06-01T22:43:41.187044Z"}]}
{"channel":"book","type":"update","data":[{"symbol":"ADA/EUR","bids":[{"price":0.416693,"qty":11149.94689187}],"asks":[],"checksum":4082755830,"timestamp":"2024-06-01T22:43:42.622185Z"}]}
{"channel":"book","type":"update","data":[{"symbol":"ADA/EUR","bids":[],"asks":[{"price":0.417074,"qty":0.00000000},{"price":0.417136,"qty":10000.00000000}],"checksum":1940587945,"timestamp":"2024-06-01T22:43:42.622797Z"}]}
{"channel":"book","type":"update","data":[{"symbol":"ADA/EUR","bids":[],"asks":[{"price":0.417136,"qty":0.00000000},{"price":0.417141,"qty":5876.59157689}],"checksum":1482358541,"timestamp":"2024-06-01T22:43:42.623034Z"}]}
{"channel":"book","type":"update","data":[{"symbol":"ADA/EUR","bids":[],"asks":[{"price":0.417077,"qty":1628.00162800}],"checksum":391069883,"timestamp":"2024-06-01T22:43:42.623107Z"}]}
{"channel":"book","type":"update","data":[{"symbol":"ADA/EUR","bids":[],"asks":[{"price":0.417094,"qty":0.00000000},{"price":0.417158,"qty":1449.50000000}],"checksum":3771148801,"timestamp":"2024-06-01T22:43:42.623119Z"}]}
{"channel":"book","type":"update","data":[{"symbol":"ADA/EUR","bids":[],"asks":[{"price":0.417008,"qty":0.00000000},{"price":0.417165,"qty":6970.95223077}],"checksum":4034346681,"timestamp":"2024-06-01T22:43:42.623431Z"}]}
{"channel":"book","type":"update","data":[{"symbol":"ADA/EUR","bids":[{"price":0.416782,"qty":33.79805661}],"asks":[],"checksum":4193513798,"timestamp":"2024-06-01T22:43:42.623539Z"}]}
{"channel":"book","type":"update","data":[{"symbol":"ADA/EUR","bids":[],"asks":[{"price":0.417077,"qty":0.00000000},{"price":0.417231,"qty":11046.09579839}],"checksum":1949415806,"timestamp":"2024-06-01T22:43:42.625959Z"}]}
{"channel":"book","type":"update","data":[{"symbol":"ADA/EUR","bids":[{"price":0.416782,"qty":67.59611322}],"asks":[],"checksum":3857892592,"timestamp":"2024-06-01T22:43:42.627547Z"}]}
{"channel":"book","type":"update","data":[{"symbol":"ADA/EUR","bids":[{"price":0.416782,"qty":5944.18769011}],"asks":[],"checksum":2825913324,"timestamp":"2024-06-01T22:43:42.627705Z"}]}
{"channel":"book","type":"update","data":[{"symbol":"ADA/EUR","bids":[{"price":0.416740,"qty":33.79805661}],"asks":[],"checksum":514438022,"timestamp":"2024-06-01T22:43:42.628640Z"}]}
{"channel":"book","type":"update","data":[{"symbol":"ADA/EUR","bids":[{"price":0.416782,"qty":5977.98574672}],"asks":[],"checksum":1988942060,"timestamp":"2024-06-01T22:43:42.629339Z"}]}
{"channel":"book","type":"update","data":[{"symbol":"ADA/EUR","bids":[],"asks":[{"price":0.417165,"qty":0.00000000},{"price":0.417280,"qty":390.00000000}],"checksum":2190770088,"timestamp":"2024-06-01T22:43:42.629924Z"}]}
{"channel":"book","type":"update","data":[{"symbol":"ADA/EUR","bids":[{"price":0.416740,"qty":11093.87024815}],"asks":[],"checksum":1180090990,"timestamp":"2024-06-01T22:43:42.630034Z"}]}
{"channel":"book","type":"update","data":[{"symbol":"ADA/EUR","bids":[],"asks":[{"price":0.416854,"qty":0.00000000},{"price":0.417336,"qty":529.80305059}],"checksum":4289830101,"timestamp":"2024-06-01T22:43:42.630332Z"}]}
{"channel":"book","type":"update","data":[{"symbol":"ADA/EUR","bids":[],"asks":[{"price":0.416935,"qty":0.00000000},{"price":0.417337,"qty":2031.53723400}],"checksum":425348070,"timestamp":"2024-06-01T22:43:42.630402Z"}]}
{"channel":"book","type":"update","data":[{"symbol":"ADA/EUR","bids":[{"price":0.416745,"qty":0.00000000},{"price":0.416693,"qty":11149.94689187}],"asks":[],"checksum":1318877596,"timestamp":"2024-06-01T22:43:42.630453Z"}]}
{"channel":"book","type":"update","data":[{"symbol":"ADA/EUR","bids":[{"price":0.416739,"qty":11060.07219154}],"asks":[],"checksum":4139830280,"timestamp":"2024-06-01T22:43:42.630606Z"}]}
{"channel":"book","type":"update","data":[{"symbol":"ADA/EUR","bids":[],"asks":[{"price":0.417038,"qty":0.00000000},{"price":0.417339,"qty":688.06094185}],"checksum":3091665517,"timestamp":"2024-06-01T22:43:42.633004Z"}]}
{"channel":"book","type":"update","data":[{"symbol":"ADA/EUR","bids":[{"price":0.416781,"qty":0.00000000},{"price":0.416693,"qty":11149.94689187}],"asks":[],"checksum":3723638089,"timestamp":"2024-06-01T22:43:42.633075Z"}]}
{"channel":"book","type":"update","data":[{"symbol":"ADA/EUR","bids":[],"asks":[{"price":0.416924,"qty":0.00000000},{"price":0.417340,"qty":2307.39308784}],"checksum":3765911711,"timestamp":"2024-06-01T22:43:42.633171Z"}]}
{"channel":"book","type":"update","data":[{"symbol":"ADA/EUR","bids":[],"asks":[{"price":0.416964,"qty":870.00000000}],"checksum":1285643439,"timestamp":"2024-06-01T22:43:42.633515Z"}]}
{"channel":"book","type":"update","data":[{"symbol":"ADA/EUR","bids":[{"price":0.416739,"qty":0.00000000},{"price":0.416692,"qty":2100.00000000}],"asks":[],"checksum":1119982615,"timestamp":"2024-06-01T22:43:42.633658Z"}]}
{"channel":"book","type":"update","data":[{"symbol":"ADA/EUR","bids":[{"price":0.416792,"qty":870.00000000}],"asks":[],"checksum":3043187759,"timestamp":"2024-06-01T22:43:42.633778Z"}]}
{"channel":"book","type":"update","data":[{"symbol":"ADA/EUR","bids":[],"asks":[{"price":0.417257,"qty":4833.65223077}],"checksum":353886054,"timestamp":"2024-06-01T22:43:42.635384Z"}]}
{"channel":"book","type":"update","data":[{"symbol":"ADA/EUR","bids":[],"asks":[{"price":0.416899,"qty":7738.42515193}],"checksum":1677412008,"timestamp":"2024-06-01T22:43:42.638843Z"}]}
{"channel":"book","type":"update","data":[{"symbol":"ADA/EUR","bids":[{"price":0.416783,"qty":7740.57042284}],"asks":[],"checksum":1996850673,"timestamp":"2024-06-01T22:43:42.639014Z"}]}
{"channel":"book","type":"update","data":[{"symbol":"ADA/EUR","bids":[],"asks":[{"price":0.416988,"qty":7736.76804459}],"checksum":712248698,"timestamp":"2024-06-01T22:43:42.639093Z"}]}
{"channel":"book","type":"update","data":[{"symbol":"ADA/EUR","bids":[],"asks":[{"price":0.417083,"qty":7735.01761592}],"checksum":1913193664,"timestamp":"2024-06-01T22:43:42.639111Z"}]}
{"channel":"book","type":"update","data":[{"symbol":"ADA/EUR","bids":[],"asks":[{"price":0.416975,"qty":0.00000000},{"price":0.417280,"qty":390.00000000}],"checksum":1187184050,"timestamp":"2024-06-01T22:43:42.650397Z"}]}
{"channel":"book","type":"update","data":[{"symbol":"ADA/EUR","bids":[{"price":0.416709,"qty":0.00000000},{"price":0.416693,"qty":11149.94689187}],"asks":[],"checksum":2982287131,"timestamp":"2024-06-01T22:43:42.652597Z"}]}
{"channel":"book","type":"update","data":[{"symbol":"ADA/EUR","bids":[{"price":0.416694,"qty":24385.37509912}],"asks":[],"checksum":3967102234,"timestamp":"2024-06-01T22:43:42.653562Z"}]}
{"channel":"book","type":"update","data":[{"symbol":"ADA/EUR","bids":[{"price":0.416782,"qty":5944.18769011}],"asks":[],"checksum":1051487907,"timestamp":"2024-06-01T22:43:42.657088Z"}]}
{"channel":"book","type":"update","data":[{"symbol":"ADA/EUR","bids":[{"price":0.416782,"qty":5910.38963350}],"asks":[],"checksum":15183661,"timestamp":"2024-06-01T22:43:42.657499Z"}]}
{"channel":"book","type":"update","data":[{"symbol":"ADA/EUR","bids":[{"price":0.416740,"qty":11060.07219154}],"asks":[],"checksum":1844760971,"timestamp":"2024-06-01T22:43:42.657515Z"}]}
{"channel":"book","type":"update","data":[{"symbol":"ADA/EUR","bids":[{"price":0.416782,"qty":33.79805661}],"asks":[],"checksum":3670821005,"timestamp":"2024-06-01T22:43:42.657663Z"}]}
{"channel":"book","type":"update","data":[{"symbol":"ADA/EUR","bids":[{"price":0.416782,"qty":0.00000000},{"price":0.416693,"qty":11149.94689187}],"asks":[],"checksum":186633967,"timestamp":"2024-06-01T22:43:42.657902Z"}]}
{"channel":"book","type":"update","data":[{"symbol":"ADA/EUR","bids":[{"price":0.416789,"qty":2100.00000000}],"asks":[],"checksum":3291602043,"timestamp":"2024-06-01T22:43:42.661858Z"}]}
{"channel":"book","type":"update","data":[{"symbol":"ADA/EUR","bids":[],"asks":[{"price":0.416899,"qty":0.00000000},{"price":0.417336,"qty":529.80305059}],"checksum":106439489,"timestamp":"2024-06-01T22:43:42.719125Z"}]}
{"channel":"book","type":"update","data":[{"symbol":"ADA/EUR","bids":[],"asks":[{"price":0.417166,"qty":33.79805661}],"checksum":3510216725,"timestamp":"2024-06-01T22:43:42.723968Z"}]}
{"channel":"book","type":"update","data":[{"symbol":"ADA/EUR","bids":[],"asks":[{"price":0.417228,"qty":10000.00000000}],"checksum":3799328020,"timestamp":"2024-06-01T22:43:42.724965Z"}]}
{"channel":"book","type":"update","data":[{"symbol":"ADA/EUR","bids":[],"asks":[{"price":0.417141,"qty":0.00000000},{"price":0.417280,"qty":390.00000000}],"checksum":1933086657,"timestamp":"2024-06-01T22:43:42.734380Z"}]}
