{"channel":"book","type":"snapshot","data":[{"symbol":"ALGO/BTC","bids":[{"price":0.00000278,"qty":23603.98273277},{"price":0.00000277,"qty":208337.81855310},{"price":0.00000276,"qty":17858.42987804},{"price":0.00000275,"qty":52286.79573918},{"price":0.00000274,"qty":85287.95767566},{"price":0.00000273,"qty":317023.98598642},{"price":0.00000272,"qty":7925.04956949},{"price":0.00000271,"qty":60.96153054},{"price":0.00000270,"qty":2101.03140172},{"price":0.00000269,"qty":3308.99596742}],"asks":[{"price":0.00000279,"qty":60178.22841847},{"price":0.00000280,"qty":68047.14387199},{"price":0.00000281,"qty":2379.47689988},{"price":0.00000282,"qty":4726.44102000},{"price":0.00000283,"qty":3982.69993663},{"price":0.00000284,"qty":157484.61287942},{"price":0.00000285,"qty":38331.65333500},{"price":0.00000286,"qty":8261.97909483},{"price":0.00000287,"qty":1595.24726673},{"price":0.00000288,"qty":3663.77596355}],"checksum":1233499784}]}
{"channel":"book","type":"update","data":[{"symbol":"ALGO/BTC","bids":[],"asks":[{"price":0.00000288,"qty":2782.58671438}],"checksum":686389563,"timestamp":"2024-06-01T22:43:57.920599Z"}]}
{"channel":"book","type":"update","data":[{"symbol":"ALGO/BTC","bids":[{"price":0.00000276,"qty":17404.23211268},{"price":0.00000276,"qty":17858.43043623}],"asks":[],"checksum":669139504,"timestamp":"2024-06-01T22:43:58.052948Z"}]}
{"channel":"book","type":"update","data":[{"symbol":"ALGO/BTC","bids":[],"asks":[{"price":0.00000280,"qty":61071.67965387}],"checksum":3888182553,"timestamp":"2024-06-01T22:43:59.154111Z"}]}
{"channel":"book","type":"update","data":[{"symbol":"ALGO/BTC","bids":[{"price":0.00000277,"qty":200952.52201952}],"asks":[],"checksum":1576440156,"timestamp":"2024-06-01T22:43:59.408751Z"}]}
{"channel":"book","type":"update","data":[{"symbol":"ALGO/BTC","bids":[],"asks":[{"price":0.00000280,"qty":68047.14387199}],"checksum":2647926389,"timestamp":"2024-06-01T22:43:59.425278Z"}]}
{"channel":"book","type":"update","data":[{"symbol":"ALGO/BTC","bids":[],"asks":[{"price":0.00000280,"qty":61071.67965387}],"checksum":1576440156,"timestamp":"2024-06-01T22:43:59.551311Z"}]}
{"channel":"book","type":"update","data":[{"symbol":"ALGO/BTC","bids":[{"price":0.00000277,"qty":208337.81855310}],"asks":[],"checksum":3888182553,"timestamp":"2024-06-01T22:43:59.697636Z"}]}
{"channel":"book","type":"update","data":[{"symbol":"ALGO/BTC","bids":[],"asks":[{"price":0.00000280,"qty":68047.14387199}],"checksum":669139504,"timestamp":"2024-06-01T22:43:59.798512Z"}]}
{"channel":"book","type":"update","data":[{"symbol":"ALGO/BTC","bids":[],"asks":[{"price":0.00000280,"qty":61071.67965387}],"checksum":3888182553,"timestamp":"2024-06-01T22:43:59.990610Z"}]}
{"channel":"book","type":"update","data":[{"symbol":"ALGO/BTC","bids":[],"asks":[{"price":0.00000280,"qty":68047.14387199}],"checksum":669139504,"timestamp":"2024-06-01T22:44:00.017014Z"}]}
{"channel":"book","type":"update","data":[{"symbol":"ALGO/BTC","bids":[{"price":0.00000277,"qty":200952.52201952}],"asks":[],"checksum":2647926389,"timestamp":"2024-06-01T22:44:00.232610Z"}]}
{"channel":"book","type":"update","data":[{"symbol":"ALGO/BTC","bids":[{"price":0.00000277,"qty":208337.81855310}],"asks":[],"checksum":669139504,"timestamp":"2024-06-01T22:44:00.336992Z"}]}
{"channel":"book","type":"update","data":[{"symbol":"ALGO/BTC","bids":[{"price":0.00000277,"qty":200952.52201952}],"asks":[],"checksum":2647926389,"timestamp":"2024-06-01T22:44:00.439947Z"}]}
{"channel":"book","type":"update","data":[{"symbol":"ALGO/BTC","bids":[{"price":0.00000277,"qty":208337.81855310}],"asks":[],"checksum":669139504,"timestamp":"2024-06-01T22:44:00.545585Z"}]}
{"channel":"book","type":"update","data":[{"symbol":"ALGO/BTC","bids":[{"price":0.00000277,"qty":200952.52201952}],"asks":[],"checksum":2647926389,"timestamp":"2024-06-01T22:44:00.649869Z"}]}
{"channel":"book","type":"update","data":[{"symbol":"ALGO/BTC","bids":[{"price":0.00000277,"qty":208337.81855310}],"asks":[],"checksum":669139504,"timestamp":"2024-06-01T22:44:00.758240Z"}]}
{"channel":"book","type":"update","data":[{"symbol":"ALGO/BTC","bids":[{"price":0.00000277,"qty":200952.52201952}],"asks":[],"checksum":2647926389,"timestamp":"2024-06-01T22:44:00.892539Z"}]}
{"channel":"book","type":"update","data":[{"symbol":"ALGO/BTC","bids":[{"price":0.00000276,"qty":18743.09237610}],"asks":[],"checksum":3139082566,"timestamp":"2024-06-01T22:44:01.018954Z"}]}
{"channel":"book","type":"update","data":[{"symbol":"ALGO/BTC","bids":[{"price":0.00000276,"qty":9896.44687366}],"asks":[],"checksum":4114596578,"timestamp":"2024-06-01T22:44:01.019271Z"}]}
{"channel":"book","type":"update","data":[{"symbol":"ALGO/BTC","bids":[{"price":0.00000276,"qty":9011.78232342}],"asks":[],"checksum":2190386161,"timestamp":"2024-06-01T22:44:01.019510Z"}]}
{"channel":"book","type":"update","data":[{"symbol":"ALGO/BTC","bids":[{"price":0.00000276,"qty":17858.40172225}],"asks":[],"checksum":627182743,"timestamp":"2024-06-01T22:44:01.019548Z"}]}
{"channel":"book","type":"update","data":[{"symbol":"ALGO/BTC","bids":[{"price":0.00000277,"qty":208337.81855310}],"asks":[],"checksum":2673109202,"timestamp":"2024-06-01T22:44:01.028107Z"}]}
{"channel":"book","type":"update","data":[{"symbol":"ALGO/BTC","bids":[{"price":0.00000277,"qty":200952.52201952}],"asks":[],"checksum":627182743,"timestamp":"2024-06-01T22:44:01.132724Z"}]}
{"channel":"book","type":"update","data":[{"symbol":"ALGO/BTC","bids":[{"price":0.00000277,"qty":208337.81855310}],"asks":[],"checksum":2673109202,"timestamp":"2024-06-01T22:44:01.248851Z"}]}
{"channel":"book","type":"update","data":[{"symbol":"ALGO/BTC","bids":[{"price":0.00000277,"qty":200952.52201952}],"asks":[],"checksum":627182743,"timestamp":"2024-06-01T22:44:01.360460Z"}]}
{"channel":"book","type":"update","data":[{"symbol":"ALGO/BTC","bids":[{"price":0.00000277,"qty":208337.81855310}],"asks":[],"checksum":2673109202,"timestamp":"2024-06-01T22:44:01.504620Z"}]}
{"channel":"book","type":"update","data":[{"symbol":"ALGO/BTC","bids":[{"price":0.00000277,"qty":200952.52201952}],"asks":[],"checksum":627182743,"timestamp":"2024-06-01T22:44:01.635263Z"}]}
{"channel":"book","type":"update","data":[{"symbol":"ALGO/BTC","bids":[],"asks":[{"price":0.00000279,"qty":59926.08520148}],"checksum":2037534932,"timestamp":"2024-06-01T22:44:03.275353Z"}]}
{"channel":"book","type":"update","data":[{"symbol":"ALGO/BTC","bids":[{"price":0.00000277,"qty":208337.81855310}],"asks":[],"checksum":3276027025,"timestamp":"2024-06-01T22:44:04.119290Z"}]}
{"channel":"book","type":"update","data":[{"symbol":"ALGO/BTC","bids":[{"price":0.00000277,"qty":200952.52201952}],"asks":[],"checksum":2037534932,"timestamp":"2024-06-01T22:44:04.216131Z"}]}
{"channel":"book","type":"update","data":[{"symbol":"ALGO/BTC","bids":[{"price":0.00000277,"qty":208337.81855310}],"asks":[],"checksum":3276027025,"timestamp":"2024-06-01T22:44:04.223176Z"}]}
{"channel":"book","type":"update","data":[{"symbol":"ALGO/BTC","bids":[{"price":0.00000277,"qty":200952.52201952}],"asks":[],"checksum":2037534932,"timestamp":"2024-06-01T22:44:04.690959Z"}]}
{"channel":"book","type":"update","data":[{"symbol":"ALGO/BTC","bids":[{"price":0.00000277,"qty":208337.81855310}],"asks":[],"checksum":3276027025,"timestamp":"2024-06-01T22:44:06.571221Z"}]}
{"channel":"book","type":"update","data":[{"symbol":"ALGO/BTC","bids":[{"price":0.00000277,"qty":200952.52201952}],"asks":[],"checksum":2037534932,"timestamp":"2024-06-01T22:44:06.745881Z"}]}
{"channel":"book","type":"update","data":[{"symbol":"ALGO/BTC","bids":[],"asks":[{"price":0.00000280,"qty":49547.14387199}],"checksum":2726841331,"timestamp":"2024-06-01T22:44:07.528857Z"}]}
{"channel":"book","type":"update","data":[{"symbol":"ALGO/BTC","bids":[{"price":0.00000277,"qty":208337.81855310}],"asks":[],"checksum":415117238,"timestamp":"2024-06-01T22:44:07.957127Z"}]}
{"channel":"book","type":"update","data":[{"symbol":"ALGO/BTC","bids":[{"price":0.00000276,"qty":17404.20339870},{"price":0.00000276,"qty":17858.40238325}],"asks":[],"checksum":4050878909,"timestamp":"2024-06-01T22:44:08.382201Z"}]}
{"channel":"book","type":"update","data":[{"symbol":"ALGO/BTC","bids":[],"asks":[{"price":0.00000288,"qty":3664.19483137}],"checksum":1784198265,"timestamp":"2024-06-01T22:44:08.453958Z"}]}
{"channel":"book","type":"update","data":[{"symbol":"ALGO/BTC","bids":[],"asks":[{"price":0.00000280,"qty":68047.14387199}],"checksum":2980228958,"timestamp":"2024-06-01T22:44:09.029704Z"}]}
{"channel":"book","type":"update","data":[{"symbol":"ALGO/BTC","bids":[{"price":0.00000277,"qty":200952.52201952}],"asks":[],"checksum":194300699,"timestamp":"2024-06-01T22:44:09.056336Z"}]}
{"channel":"book","type":"update","data":[{"symbol":"ALGO/BTC","bids":[{"price":0.00000276,"qty":18743.44958504}],"asks":[],"checksum":4136127497,"timestamp":"2024-06-01T22:44:11.562863Z"}]}
{"channel":"book","type":"update","data":[{"symbol":"ALGO/BTC","bids":[{"price":0.00000276,"qty":17858.78764517}],"asks":[],"checksum":3819950690,"timestamp":"2024-06-01T22:44:11.563388Z"}]}
{"channel":"book","type":"update","data":[{"symbol":"ALGO/BTC","bids":[{"price":0.00000276,"qty":9012.16824634}],"asks":[],"checksum":2570404960,"timestamp":"2024-06-01T22:44:11.563931Z"}]}
{"channel":"book","type":"update","data":[{"symbol":"ALGO/BTC","bids":[{"price":0.00000276,"qty":17862.64026425}],"asks":[],"checksum":306010205,"timestamp":"2024-06-01T22:44:11.563942Z"}]}
{"channel":"book","type":"update","data":[{"symbol":"ALGO/BTC","bids":[{"price":0.00000277,"qty":208337.81855310}],"asks":[],"checksum":2819308568,"timestamp":"2024-06-01T22:44:11.671392Z"}]}
{"channel":"book","type":"update","data":[{"symbol":"ALGO/BTC","bids":[{"price":0.00000277,"qty":200952.52201952}],"asks":[],"checksum":306010205,"timestamp":"2024-06-01T22:44:11.860903Z"}]}
{"channel":"book","type":"update","data":[{"symbol":"ALGO/BTC","bids":[{"price":0.00000276,"qty":17212.64026425}],"asks":[],"checksum":3234075888,"timestamp":"2024-06-01T22:44:12.377762Z"}]}
{"channel":"book","type":"update","data":[{"symbol":"ALGO/BTC","bids":[{"price":0.00000277,"qty":199079.45179952}],"asks":[],"checksum":2389290480,"timestamp":"2024-06-01T22:44:12.430599Z"}]}
{"channel":"book","type":"update","data":[{"symbol":"ALGO/BTC","bids":[{"price":0.00000278,"qty":25477.05295277}],"asks":[],"checksum":3501956338,"timestamp":"2024-06-01T22:44:12.433515Z"}]}
{"channel":"book","type":"update","data":[{"symbol":"ALGO/BTC","bids":[{"price":0.00000276,"qty":17862.64026425}],"asks":[],"checksum":37933151,"timestamp":"2024-06-01T22:44:14.637704Z"}]}
{"channel":"book","type":"update","data":[{"symbol":"ALGO/BTC","bids":[{"price":0.00000277,"qty":206054.91601764}],"asks":[],"checksum":3237651018,"timestamp":"2024-06-01T22:44:18.580471Z"}]}
{"channel":"book","type":"update","data":[{"symbol":"ALGO/BTC","bids":[{"price":0.00000276,"qty":17408.44127970},{"price":0.00000276,"qty":17857.70012371}],"asks":[],"checksum":2436188607,"timestamp":"2024-06-01T22:44:18.607538Z"}]}
{"channel":"book","type":"update","data":[{"symbol":"ALGO/BTC","bids":[],"asks":[{"price":0.00000288,"qty":2782.58671438}],"checksum":169770107,"timestamp":"2024-06-01T22:44:18.987247Z"}]}
