{"channel":"book","type":"snapshot","data":[{"symbol":"ATOM/BTC","bids":[{"price":0.0001233,"qty":85.00000000},{"price":0.0001232,"qty":865.53277324},{"price":0.0001231,"qty":718.82848123},{"price":0.0001230,"qty":1382.25090775},{"price":0.0001229,"qty":5260.45494000},{"price":0.0001228,"qty":1295.43200000},{"price":0.0001227,"qty":719.72800000},{"price":0.0001223,"qty":49.32485730},{"price":0.0001222,"qty":481.10400000},{"price":0.0001219,"qty":6253.80860944}],"asks":[{"price":0.0001234,"qty":311.19284308},{"price":0.0001235,"qty":1428.29948614},{"price":0.0001236,"qty":1604.47290365},{"price":0.0001237,"qty":3279.72175286},{"price":0.0001238,"qty":202.10000000},{"price":0.0001239,"qty":718.72800000},{"price":0.0001241,"qty":3.64564975},{"price":0.0001242,"qty":481.10400000},{"price":0.0001245,"qty":396.18746954},{"price":0.0001246,"qty":242.20800000}],"checksum":371872194}]}
{"channel":"book","type":"update","data":[{"symbol":"ATOM/BTC","bids":[{"price":0.0001232,"qty":386.86676880}],"asks":[],"checksum":1712580417,"timestamp":"2024-06-01T22:43:08.569087Z"}]}
{"channel":"book","type":"update","data":[{"symbol":"ATOM/BTC","bids":[{"price":0.0001232,"qty":865.53304366}],"asks":[],"checksum":1772421987,"timestamp":"2024-06-01T22:43:08.880266Z"}]}
{"channel":"book","type":"update","data":[{"symbol":"ATOM/BTC","bids":[{"price":0.0001232,"qty":386.86676880}],"asks":[],"checksum":1712580417,"timestamp":"2024-06-01T22:43:09.171583Z"}]}
{"channel":"book","type":"update","data":[{"symbol":"ATOM/BTC","bids":[{"price":0.0001232,"qty":865.53304366}],"asks":[],"checksum":1772421987,"timestamp":"2024-06-01T22:43:09.480539Z"}]}
{"channel":"book","type":"update","data":[{"symbol":"ATOM/BTC","bids":[{"price":0.0001230,"qty":1203.78190417}],"asks":[],"checksum":2430120896,"timestamp":"2024-06-01T22:43:09.707965Z"}]}
{"channel":"book","type":"update","data":[{"symbol":"ATOM/BTC","bids":[{"price":0.0001232,"qty":386.86676880}],"asks":[],"checksum":2674808802,"timestamp":"2024-06-01T22:43:09.796842Z"}]}
{"channel":"book","type":"update","data":[{"symbol":"ATOM/BTC","bids":[{"price":0.0001230,"qty":1382.25090775}],"asks":[],"checksum":1712580417,"timestamp":"2024-06-01T22:43:09.809972Z"}]}
{"channel":"book","type":"update","data":[{"symbol":"ATOM/BTC","bids":[{"price":0.0001232,"qty":865.52925812}],"asks":[],"checksum":3113010330,"timestamp":"2024-06-01T22:43:10.089241Z"}]}
{"channel":"book","type":"update","data":[{"symbol":"ATOM/BTC","bids":[{"price":0.0001232,"qty":386.86676880}],"asks":[],"checksum":1712580417,"timestamp":"2024-06-01T22:43:10.387810Z"}]}
{"channel":"book","type":"update","data":[{"symbol":"ATOM/BTC","bids":[{"price":0.0001232,"qty":865.52925812}],"asks":[],"checksum":3113010330,"timestamp":"2024-06-01T22:43:10.685603Z"}]}
{"channel":"book","type":"update","data":[{"symbol":"ATOM/BTC","bids":[{"price":0.0001232,"qty":386.86676880}],"asks":[],"checksum":1712580417,"timestamp":"2024-06-01T22:43:11.064776Z"}]}
{"channel":"book","type":"update","data":[{"symbol":"ATOM/BTC","bids":[{"price":0.0001232,"qty":865.52925812}],"asks":[],"checksum":3113010330,"timestamp":"2024-06-01T22:43:11.359246Z"}]}
{"channel":"book","type":"update","data":[{"symbol":"ATOM/BTC","bids":[],"asks":[{"price":0.0001234,"qty":226.19284308}],"checksum":2164865977,"timestamp":"2024-06-01T22:43:11.367966Z"}]}
{"channel":"book","type":"update","data":[{"symbol":"ATOM/BTC","bids":[{"price":0.0001230,"qty":1202.31316185}],"asks":[],"checksum":3715412170,"timestamp":"2024-06-01T22:43:11.386578Z"}]}
{"channel":"book","type":"update","data":[{"symbol":"ATOM/BTC","bids":[{"price":0.0001232,"qty":1045.24698138}],"asks":[],"checksum":1667778668,"timestamp":"2024-06-01T22:43:11.391205Z"}]}
{"channel":"book","type":"update","data":[{"symbol":"ATOM/BTC","bids":[{"price":0.0001233,"qty":111.93401546}],"asks":[],"checksum":456902518,"timestamp":"2024-06-01T22:43:11.396241Z"}]}
{"channel":"book","type":"update","data":[{"symbol":"ATOM/BTC","bids":[],"asks":[{"price":0.0001234,"qty":199.26104616}],"checksum":4083955878,"timestamp":"2024-06-01T22:43:11.451898Z"}]}
{"channel":"book","type":"update","data":[{"symbol":"ATOM/BTC","bids":[{"price":0.0001231,"qty":659.92522011}],"asks":[],"checksum":357669572,"timestamp":"2024-06-01T22:43:11.848776Z"}]}
{"channel":"book","type":"update","data":[{"symbol":"ATOM/BTC","bids":[{"price":0.0001232,"qty":1104.15024250}],"asks":[],"checksum":3251295626,"timestamp":"2024-06-01T22:43:11.883879Z"}]}
{"channel":"book","type":"update","data":[{"symbol":"ATOM/BTC","bids":[],"asks":[{"price":0.0001235,"qty":1248.90371470}],"checksum":3854423057,"timestamp":"2024-06-01T22:43:12.577857Z"}]}
{"channel":"book","type":"update","data":[{"symbol":"ATOM/BTC","bids":[],"asks":[{"price":0.0001237,"qty":3458.84467841}],"checksum":1398168266,"timestamp":"2024-06-01T22:43:12.581785Z"}]}
{"channel":"book","type":"update","data":[{"symbol":"ATOM/BTC","bids":[],"asks":[{"price":0.0001234,"qty":1.90904616}],"checksum":3655047802,"timestamp":"2024-06-01T22:43:13.295532Z"}]}
{"channel":"book","type":"update","data":[{"symbol":"ATOM/BTC","bids":[],"asks":[{"price":0.0001235,"qty":1446.25571470}],"checksum":548042443,"timestamp":"2024-06-01T22:43:13.298193Z"}]}
{"channel":"book","type":"update","data":[{"symbol":"ATOM/BTC","bids":[],"asks":[{"price":0.0001235,"qty":1443.86134696}],"checksum":3302693438,"timestamp":"2024-06-01T22:43:13.357140Z"}]}
{"channel":"book","type":"update","data":[{"symbol":"ATOM/BTC","bids":[],"asks":[{"price":0.0001236,"qty":1590.45743469}],"checksum":2181580116,"timestamp":"2024-06-01T22:43:13.357255Z"}]}
{"channel":"book","type":"update","data":[{"symbol":"ATOM/BTC","bids":[],"asks":[{"price":0.0001236,"qty":1602.19371820}],"checksum":3026217737,"timestamp":"2024-06-01T22:43:13.357862Z"}]}
{"channel":"book","type":"update","data":[{"symbol":"ATOM/BTC","bids":[{"price":0.0001231,"qty":605.05883763}],"asks":[],"checksum":1797684519,"timestamp":"2024-06-01T22:43:14.731814Z"}]}
{"channel":"book","type":"update","data":[{"symbol":"ATOM/BTC","bids":[{"price":0.0001232,"qty":1159.01662498}],"asks":[],"checksum":2302033596,"timestamp":"2024-06-01T22:43:14.871166Z"}]}
{"channel":"book","type":"update","data":[{"symbol":"ATOM/BTC","bids":[{"price":0.0001231,"qty":575.99797942}],"asks":[],"checksum":1340717678,"timestamp":"2024-06-01T22:43:14.952635Z"}]}
{"channel":"book","type":"update","data":[{"symbol":"ATOM/BTC","bids":[{"price":0.0001231,"qty":603.38814402}],"asks":[],"checksum":199338445,"timestamp":"2024-06-01T22:43:14.958664Z"}]}
{"channel":"book","type":"update","data":[{"symbol":"ATOM/BTC","bids":[{"price":0.0001232,"qty":680.35413566}],"asks":[],"checksum":3991453837,"timestamp":"2024-06-01T22:43:15.290948Z"}]}
{"channel":"book","type":"update","data":[{"symbol":"ATOM/BTC","bids":[],"asks":[{"price":0.0001236,"qty":1549.53704646}],"checksum":1859952795,"timestamp":"2024-06-01T22:43:15.557064Z"}]}
{"channel":"book","type":"update","data":[{"symbol":"ATOM/BTC","bids":[{"price":0.0001232,"qty":1158.91878551}],"asks":[],"checksum":2520451495,"timestamp":"2024-06-01T22:43:15.584072Z"}]}
{"channel":"book","type":"update","data":[{"symbol":"ATOM/BTC","bids":[],"asks":[{"price":0.0001235,"qty":1503.01002332}],"checksum":2131036878,"timestamp":"2024-06-01T22:43:15.673968Z"}]}
{"channel":"book","type":"update","data":[{"symbol":"ATOM/BTC","bids":[],"asks":[{"price":0.0001237,"qty":1310.29168063}],"checksum":3884161607,"timestamp":"2024-06-01T22:43:16.073273Z"}]}
{"channel":"book","type":"update","data":[{"symbol":"ATOM/BTC","bids":[],"asks":[{"price":0.0001238,"qty":2350.60667771}],"checksum":3513714108,"timestamp":"2024-06-01T22:43:16.113541Z"}]}
{"channel":"book","type":"update","data":[{"symbol":"ATOM/BTC","bids":[{"price":0.0001232,"qty":680.35413566}],"asks":[],"checksum":2283783285,"timestamp":"2024-06-01T22:43:16.185694Z"}]}
{"channel":"book","type":"update","data":[{"symbol":"ATOM/BTC","bids":[{"price":0.0001230,"qty":1025.23525561}],"asks":[],"checksum":1050360003,"timestamp":"2024-06-01T22:43:16.315943Z"}]}
{"channel":"book","type":"update","data":[{"symbol":"ATOM/BTC","bids":[{"price":0.0001230,"qty":1202.31316185}],"asks":[],"checksum":2283783285,"timestamp":"2024-06-01T22:43:16.453575Z"}]}
{"channel":"book","type":"update","data":[{"symbol":"ATOM/BTC","bids":[{"price":0.0001232,"qty":1158.91822210}],"asks":[],"checksum":4051050726,"timestamp":"2024-06-01T22:43:16.534746Z"}]}
{"channel":"book","type":"update","data":[{"symbol":"ATOM/BTC","bids":[{"price":0.0001232,"qty":680.35413566}],"asks":[],"checksum":2283783285,"timestamp":"2024-06-01T22:43:16.841519Z"}]}
{"channel":"book","type":"update","data":[{"symbol":"ATOM/BTC","bids":[{"price":0.0001232,"qty":1158.92172784}],"asks":[],"checksum":2560313501,"timestamp":"2024-06-01T22:43:17.131570Z"}]}
{"channel":"book","type":"update","data":[{"symbol":"ATOM/BTC","bids":[{"price":0.0001232,"qty":680.35413566}],"asks":[],"checksum":2283783285,"timestamp":"2024-06-01T22:43:17.423498Z"}]}
{"channel":"book","type":"update","data":[{"symbol":"ATOM/BTC","bids":[{"price":0.0001232,"qty":1158.91415848}],"asks":[],"checksum":3991148114,"timestamp":"2024-06-01T22:43:17.757489Z"}]}
{"channel":"book","type":"update","data":[{"symbol":"ATOM/BTC","bids":[{"price":0.0001232,"qty":680.35413566}],"asks":[],"checksum":2283783285,"timestamp":"2024-06-01T22:43:18.079225Z"}]}
{"channel":"book","type":"update","data":[{"symbol":"ATOM/BTC","bids":[{"price":0.0001232,"qty":1158.91415847}],"asks":[],"checksum":1817193938,"timestamp":"2024-06-01T22:43:18.385055Z"}]}
{"channel":"book","type":"update","data":[{"symbol":"ATOM/BTC","bids":[{"price":0.0001232,"qty":680.35413566}],"asks":[],"checksum":2283783285,"timestamp":"2024-06-01T22:43:18.688590Z"}]}
{"channel":"book","type":"update","data":[{"symbol":"ATOM/BTC","bids":[{"price":0.0001232,"qty":1158.91334763}],"asks":[],"checksum":616439071,"timestamp":"2024-06-01T22:43:19.004189Z"}]}
{"channel":"book","type":"update","data":[{"symbol":"ATOM/BTC","bids":[],"asks":[{"price":0.0001235,"qty":1142.79402332}],"checksum":2505455513,"timestamp":"2024-06-01T22:43:19.180393Z"}]}
{"channel":"book","type":"update","data":[{"symbol":"ATOM/BTC","bids":[],"asks":[{"price":0.0001236,"qty":1909.75304646}],"checksum":2767870937,"timestamp":"2024-06-01T22:43:19.183036Z"}]}
{"channel":"book","type":"update","data":[{"symbol":"ATOM/BTC","bids":[{"price":0.0001232,"qty":680.35413566}],"asks":[],"checksum":2839464416,"timestamp":"2024-06-01T22:43:19.299616Z"}]}
{"channel":"book","type":"update","data":[{"symbol":"ATOM/BTC","bids":[],"asks":[{"price":0.0001236,"qty":1898.01676295}],"checksum":2629468416,"timestamp":"2024-06-01T22:43:19.429226Z"}]}
{"channel":"book","type":"update","data":[{"symbol":"ATOM/BTC","bids":[],"asks":[{"price":0.0001235,"qty":1147.52360530}],"checksum":2308545542,"timestamp":"2024-06-01T22:43:19.429362Z"}]}
{"channel":"book","type":"update","data":[{"symbol":"ATOM/BTC","bids":[],"asks":[{"price":0.0001236,"qty":1906.19124806}],"checksum":2897486567,"timestamp":"2024-06-01T22:43:19.429392Z"}]}
{"channel":"book","type":"update","data":[{"symbol":"ATOM/BTC","bids":[{"price":0.0001232,"qty":1158.91334762}],"asks":[],"checksum":1318960644,"timestamp":"2024-06-01T22:43:19.597060Z"}]}
{"channel":"book","type":"update","data":[{"symbol":"ATOM/BTC","bids":[{"price":0.0001232,"qty":680.35413566}],"asks":[],"checksum":2897486567,"timestamp":"2024-06-01T22:43:19.888116Z"}]}
{"channel":"book","type":"update","data":[{"symbol":"ATOM/BTC","bids":[{"price":0.0001232,"qty":1158.91334763}],"asks":[],"checksum":983254161,"timestamp":"2024-06-01T22:43:20.187415Z"}]}
{"channel":"book","type":"update","data":[{"symbol":"ATOM/BTC","bids":[{"price":0.0001231,"qty":575.99797942}],"asks":[],"checksum":2123585330,"timestamp":"2024-06-01T22:43:20.319729Z"}]}
{"channel":"book","type":"update","data":[{"symbol":"ATOM/BTC","bids":[{"price":0.0001231,"qty":605.05455401}],"asks":[],"checksum":4250001700,"timestamp":"2024-06-01T22:43:20.324507Z"}]}
{"channel":"book","type":"update","data":[{"symbol":"ATOM/BTC","bids":[{"price":0.0001232,"qty":680.35413566}],"asks":[],"checksum":1803454290,"timestamp":"2024-06-01T22:43:20.492542Z"}]}
{"channel":"book","type":"update","data":[{"symbol":"ATOM/BTC","bids":[{"price":0.0001232,"qty":1158.91334763}],"asks":[],"checksum":4250001700,"timestamp":"2024-06-01T22:43:20.788417Z"}]}
{"channel":"book","type":"update","data":[{"symbol":"ATOM/BTC","bids":[{"price":0.0001232,"qty":680.35413566}],"asks":[],"checksum":1803454290,"timestamp":"2024-06-01T22:43:21.113168Z"}]}
{"channel":"book","type":"update","data":[{"symbol":"ATOM/BTC","bids":[{"price":0.0001232,"qty":1158.89074176}],"asks":[],"checksum":2655298440,"timestamp":"2024-06-01T22:43:21.438355Z"}]}
{"channel":"book","type":"update","data":[{"symbol":"ATOM/BTC","bids":[{"price":0.0001232,"qty":680.35413566}],"asks":[],"checksum":1803454290,"timestamp":"2024-06-01T22:43:21.714985Z"}]}
{"channel":"book","type":"update","data":[{"symbol":"ATOM/BTC","bids":[{"price":0.0001232,"qty":1158.93775633}],"asks":[],"checksum":2478492703,"timestamp":"2024-06-01T22:43:22.018075Z"}]}
{"channel":"book","type":"update","data":[{"symbol":"ATOM/BTC","bids":[{"price":0.0001232,"qty":680.35413566}],"asks":[],"checksum":1803454290,"timestamp":"2024-06-01T22:43:22.317491Z"}]}
{"channel":"book","type":"update","data":[{"symbol":"ATOM/BTC","bids":[],"asks":[{"price":0.0001235,"qty":1142.79402332}],"checksum":2120063572,"timestamp":"2024-06-01T22:43:22.459454Z"}]}
{"channel":"book","type":"update","data":[{"symbol":"ATOM/BTC","bids":[],"asks":[{"price":0.0001235,"qty":1144.01984611}],"checksum":3485952066,"timestamp":"2024-06-01T22:43:22.464831Z"}]}
{"channel":"book","type":"update","data":[{"symbol":"ATOM/BTC","bids":[{"price":0.0001232,"qty":1158.93807317}],"asks":[],"checksum":1587236386,"timestamp":"2024-06-01T22:43:22.667642Z"}]}
{"channel":"book","type":"update","data":[{"symbol":"ATOM/BTC","bids":[{"price":0.0001232,"qty":680.35413566}],"asks":[],"checksum":3485952066,"timestamp":"2024-06-01T22:43:22.946873Z"}]}
{"channel":"book","type":"update","data":[{"symbol":"ATOM/BTC","bids":[{"price":0.0001231,"qty":575.99797942}],"asks":[],"checksum":1275453012,"timestamp":"2024-06-01T22:43:23.026303Z"}]}
{"channel":"book","type":"update","data":[{"symbol":"ATOM/BTC","bids":[{"price":0.0001231,"qty":606.28834145}],"asks":[],"checksum":3758651548,"timestamp":"2024-06-01T22:43:23.028572Z"}]}
{"channel":"book","type":"update","data":[{"symbol":"ATOM/BTC","bids":[{"price":0.0001232,"qty":1158.93805540}],"asks":[],"checksum":367499616,"timestamp":"2024-06-01T22:43:23.248798Z"}]}
{"channel":"book","type":"update","data":[{"symbol":"ATOM/BTC","bids":[{"price":0.0001232,"qty":680.35413566}],"asks":[],"checksum":3758651548,"timestamp":"2024-06-01T22:43:23.548131Z"}]}
{"channel":"book","type":"update","data":[{"symbol":"ATOM/BTC","bids":[{"price":0.0001232,"qty":1158.92998039}],"asks":[],"checksum":1290960862,"timestamp":"2024-06-01T22:43:23.852396Z"}]}
{"channel":"book","type":"update","data":[{"symbol":"ATOM/BTC","bids":[{"price":0.0001232,"qty":680.35413566}],"asks":[],"checksum":3758651548,"timestamp":"2024-06-01T22:43:24.147608Z"}]}
{"channel":"book","type":"update","data":[{"symbol":"ATOM/BTC","bids":[{"price":0.0001232,"qty":1158.92998039}],"asks":[],"checksum":1290960862,"timestamp":"2024-06-01T22:43:24.494152Z"}]}
{"channel":"book","type":"update","data":[{"symbol":"ATOM/BTC","bids":[{"price":0.0001232,"qty":1139.78723849},{"price":0.0001233,"qty":131.06884726}],"asks":[],"checksum":2566666738,"timestamp":"2024-06-01T22:43:25.136634Z"}]}
{"channel":"book","type":"update","data":[{"symbol":"ATOM/BTC","bids":[{"price":0.0001232,"qty":1084.92085601}],"asks":[],"checksum":2560659249,"timestamp":"2024-06-01T22:43:25.144462Z"}]}
{"channel":"book","type":"update","data":[{"symbol":"ATOM/BTC","bids":[{"price":0.0001232,"qty":1032.82461810}],"asks":[],"checksum":4067740771,"timestamp":"2024-06-01T22:43:25.168955Z"}]}
{"channel":"book","type":"update","data":[{"symbol":"ATOM/BTC","bids":[{"price":0.0001231,"qty":661.15472393}],"asks":[],"checksum":2404328974,"timestamp":"2024-06-01T22:43:25.241715Z"}]}
{"channel":"book","type":"update","data":[{"symbol":"ATOM/BTC","bids":[{"price":0.0001229,"qty":5235.87753258}],"asks":[],"checksum":3330270150,"timestamp":"2024-06-01T22:43:25.341912Z"}]}
{"channel":"book","type":"update","data":[{"symbol":"ATOM/BTC","bids":[{"price":0.0001230,"qty":1226.89056927}],"asks":[],"checksum":2951964721,"timestamp":"2024-06-01T22:43:25.381218Z"}]}
{"channel":"book","type":"update","data":[{"symbol":"ATOM/BTC","bids":[],"asks":[{"price":0.0001235,"qty":1142.79402332}],"checksum":1536575378,"timestamp":"2024-06-01T22:43:25.480813Z"}]}
{"channel":"book","type":"update","data":[{"symbol":"ATOM/BTC","bids":[],"asks":[{"price":0.0001236,"qty":1898.01676295}],"checksum":2361309378,"timestamp":"2024-06-01T22:43:25.480931Z"}]}
{"channel":"book","type":"update","data":[{"symbol":"ATOM/BTC","bids":[],"asks":[{"price":0.0001236,"qty":1909.16746425}],"checksum":4160429047,"timestamp":"2024-06-01T22:43:25.482330Z"}]}
{"channel":"book","type":"update","data":[{"symbol":"ATOM/BTC","bids":[{"price":0.0001232,"qty":554.24877337}],"asks":[],"checksum":3888860351,"timestamp":"2024-06-01T22:43:25.627264Z"}]}
{"channel":"book","type":"update","data":[{"symbol":"ATOM/BTC","bids":[{"price":0.0001231,"qty":630.86436190}],"asks":[],"checksum":1795243384,"timestamp":"2024-06-01T22:43:25.784840Z"}]}
{"channel":"book","type":"update","data":[{"symbol":"ATOM/BTC","bids":[{"price":0.0001231,"qty":659.91479532}],"asks":[],"checksum":282762380,"timestamp":"2024-06-01T22:43:25.788111Z"}]}
{"channel":"book","type":"update","data":[{"symbol":"ATOM/BTC","bids":[{"price":0.0001232,"qty":1032.80973046}],"asks":[],"checksum":1505446325,"timestamp":"2024-06-01T22:43:25.983065Z"}]}
{"channel":"book","type":"update","data":[{"symbol":"ATOM/BTC","bids":[{"price":0.0001232,"qty":554.24877337}],"asks":[],"checksum":282762380,"timestamp":"2024-06-01T22:43:26.295076Z"}]}
{"channel":"book","type":"update","data":[{"symbol":"ATOM/BTC","bids":[{"price":0.0001232,"qty":1032.80301275}],"asks":[],"checksum":3740041204,"timestamp":"2024-06-01T22:43:26.863111Z"}]}
{"channel":"book","type":"update","data":[{"symbol":"ATOM/BTC","bids":[{"price":0.0001231,"qty":630.86436190}],"asks":[],"checksum":2771901952,"timestamp":"2024-06-01T22:43:28.382539Z"}]}
{"channel":"book","type":"update","data":[{"symbol":"ATOM/BTC","bids":[{"price":0.0001231,"qty":654.27353266}],"asks":[],"checksum":1567552101,"timestamp":"2024-06-01T22:43:28.384766Z"}]}
{"channel":"book","type":"update","data":[{"symbol":"ATOM/BTC","bids":[{"price":0.0001230,"qty":1233.83422059}],"asks":[],"checksum":892477261,"timestamp":"2024-06-01T22:43:28.385081Z"}]}
{"channel":"book","type":"update","data":[{"symbol":"ATOM/BTC","bids":[],"asks":[{"price":0.0001236,"qty":1898.01676295}],"checksum":1316469880,"timestamp":"2024-06-01T22:43:28.514858Z"}]}
{"channel":"book","type":"update","data":[{"symbol":"ATOM/BTC","bids":[],"asks":[{"price":0.0001236,"qty":1905.08041887}],"checksum":2783997484,"timestamp":"2024-06-01T22:43:28.515669Z"}]}
{"channel":"book","type":"update","data":[{"symbol":"ATOM/BTC","bids":[],"asks":[{"price":0.0001237,"qty":1319.61373206}],"checksum":1538964787,"timestamp":"2024-06-01T22:43:28.515941Z"}]}
{"channel":"book","type":"update","data":[{"symbol":"ATOM/BTC","bids":[{"price":0.0001231,"qty":630.86436190}],"asks":[],"checksum":2749600086,"timestamp":"2024-06-01T22:43:31.515095Z"}]}
{"channel":"book","type":"update","data":[{"symbol":"ATOM/BTC","bids":[{"price":0.0001230,"qty":1226.89056927}],"asks":[],"checksum":3418324094,"timestamp":"2024-06-01T22:43:31.515200Z"}]}
{"channel":"book","type":"update","data":[{"symbol":"ATOM/BTC","bids":[{"price":0.0001231,"qty":659.91578523}],"asks":[],"checksum":2376046569,"timestamp":"2024-06-01T22:43:31.520089Z"}]}
{"channel":"book","type":"update","data":[{"symbol":"ATOM/BTC","bids":[],"asks":[{"price":0.0001237,"qty":1310.29168063}],"checksum":1943356662,"timestamp":"2024-06-01T22:43:31.571212Z"}]}
{"channel":"book","type":"update","data":[{"symbol":"ATOM/BTC","bids":[],"asks":[{"price":0.0001236,"qty":1898.01676295}],"checksum":2555549346,"timestamp":"2024-06-01T22:43:31.571263Z"}]}
{"channel":"book","type":"update","data":[{"symbol":"ATOM/BTC","bids":[],"asks":[{"price":0.0001236,"qty":1907.41549242}],"checksum":3156212532,"timestamp":"2024-06-01T22:43:31.571629Z"}]}
{"channel":"book","type":"update","data":[{"symbol":"ATOM/BTC","bids":[],"asks":[{"price":0.0001237,"qty":1314.94814565}],"checksum":3149807727,"timestamp":"2024-06-01T22:43:31.571723Z"}]}
{"channel":"book","type":"update","data":[{"symbol":"ATOM/BTC","bids":[],"asks":[{"price":0.0001235,"qty":1097.04049340}],"checksum":1639076908,"timestamp":"2024-06-01T22:43:33.329992Z"}]}
{"channel":"book","type":"update","data":[{"symbol":"ATOM/BTC","bids":[],"asks":[{"price":0.0001235,"qty":1142.79402332}],"checksum":3149807727,"timestamp":"2024-06-01T22:43:33.425998Z"}]}
{"channel":"book","type":"update","data":[{"symbol":"ATOM/BTC","bids":[{"price":0.0001232,"qty":554.24877337}],"asks":[],"checksum":3961012178,"timestamp":"2024-06-01T22:43:33.755113Z"}]}
{"channel":"book","type":"update","data":[{"symbol":"ATOM/BTC","bids":[{"price":0.0001232,"qty":1032.80523072}],"asks":[],"checksum":4254567238,"timestamp":"2024-06-01T22:43:34.029493Z"}]}
{"channel":"book","type":"update","data":[{"symbol":"ATOM/BTC","bids":[{"price":0.0001232,"qty":554.24877337}],"asks":[],"checksum":3961012178,"timestamp":"2024-06-01T22:43:34.369878Z"}]}
{"channel":"book","type":"update","data":[{"symbol":"ATOM/BTC","bids":[{"price":0.0001232,"qty":1032.80576890}],"asks":[],"checksum":3665300217,"timestamp":"2024-06-01T22:43:34.664087Z"}]}
{"channel":"book","type":"update","data":[{"symbol":"ATOM/BTC","bids":[{"price":0.0001232,"qty":554.24877337}],"asks":[],"checksum":3961012178,"timestamp":"2024-06-01T22:43:34.972911Z"}]}
{"channel":"book","type":"update","data":[{"symbol":"ATOM/BTC","bids":[{"price":0.0001232,"qty":1032.79348913}],"asks":[],"checksum":980336292,"timestamp":"2024-06-01T22:43:35.266131Z"}]}
{"channel":"book","type":"update","data":[{"symbol":"ATOM/BTC","bids":[{"price":0.0001232,"qty":554.24877337}],"asks":[],"checksum":3961012178,"timestamp":"2024-06-01T22:43:35.565980Z"}]}
{"channel":"book","type":"update","data":[{"symbol":"ATOM/BTC","bids":[],"asks":[{"price":0.0001245,"qty":1.00000000}],"checksum":2689229455,"timestamp":"2024-06-01T22:43:35.762954Z"}]}
{"channel":"book","type":"update","data":[{"symbol":"ATOM/BTC","bids":[{"price":0.0001232,"qty":1032.79402732}],"asks":[],"checksum":3052281494,"timestamp":"2024-06-01T22:43:35.883568Z"}]}
{"channel":"book","type":"update","data":[{"symbol":"ATOM/BTC","bids":[{"price":0.0001232,"qty":554.24877337}],"asks":[],"checksum":2689229455,"timestamp":"2024-06-01T22:43:36.161165Z"}]}
{"channel":"book","type":"update","data":[{"symbol":"ATOM/BTC","bids":[{"price":0.0001232,"qty":1032.79438945}],"asks":[],"checksum":871311371,"timestamp":"2024-06-01T22:43:36.470784Z"}]}
{"channel":"book","type":"update","data":[{"symbol":"ATOM/BTC","bids":[{"price":0.0001232,"qty":554.24877337}],"asks":[],"checksum":2689229455,"timestamp":"2024-06-01T22:43:36.762935Z"}]}
{"channel":"book","type":"update","data":[{"symbol":"ATOM/BTC","bids":[{"price":0.0001232,"qty":1032.79387138}],"asks":[],"checksum":65841828,"timestamp":"2024-06-01T22:43:37.077352Z"}]}
{"channel":"book","type":"update","data":[{"symbol":"ATOM/BTC","bids":[{"price":0.0001232,"qty":554.24877337}],"asks":[],"checksum":2689229455,"timestamp":"2024-06-01T22:43:37.376789Z"}]}
{"channel":"book","type":"update","data":[{"symbol":"ATOM/BTC","bids":[{"price":0.0001232,"qty":1032.79387138}],"asks":[],"checksum":65841828,"timestamp":"2024-06-01T22:43:37.669949Z"}]}
{"channel":"book","type":"update","data":[{"symbol":"ATOM/BTC","bids":[{"price":0.0001232,"qty":554.24877337}],"asks":[],"checksum":2689229455,"timestamp":"2024-06-01T22:43:37.985117Z"}]}
{"channel":"book","type":"update","data":[{"symbol":"ATOM/BTC","bids":[{"price":0.0001232,"qty":1032.79366940}],"asks":[],"checksum":3567820446,"timestamp":"2024-06-01T22:43:38.294702Z"}]}
{"channel":"book","type":"update","data":[{"symbol":"ATOM/BTC","bids":[{"price":0.0001232,"qty":554.24877337}],"asks":[],"checksum":2689229455,"timestamp":"2024-06-01T22:43:38.608559Z"}]}
{"channel":"book","type":"update","data":[{"symbol":"ATOM/BTC","bids":[{"price":0.0001229,"qty":5098.91753258},{"price":0.0001230,"qty":1364.51056927}],"asks":[],"checksum":716815862,"timestamp":"2024-06-01T22:43:38.640733Z"}]}
{"channel":"book","type":"update","data":[{"symbol":"ATOM/BTC","bids":[],"asks":[{"price":0.0001238,"qty":2222.64667771},{"price":0.0001238,"qty":2349.82667771}],"checksum":3066311139,"timestamp":"2024-06-01T22:43:38.640957Z"}]}
{"channel":"book","type":"update","data":[{"symbol":"ATOM/BTC","bids":[{"price":0.0001232,"qty":1032.76205926}],"asks":[],"checksum":368402961,"timestamp":"2024-06-01T22:43:38.906579Z"}]}
{"channel":"book","type":"update","data":[{"symbol":"ATOM/BTC","bids":[{"price":0.0001232,"qty":554.24877337}],"asks":[],"checksum":3066311139,"timestamp":"2024-06-01T22:43:39.206062Z"}]}
{"channel":"book","type":"update","data":[{"symbol":"ATOM/BTC","bids":[{"price":0.0001232,"qty":1032.76192203}],"asks":[],"checksum":1382470922,"timestamp":"2024-06-01T22:43:39.518075Z"}]}
{"channel":"book","type":"update","data":[{"symbol":"ATOM/BTC","bids":[{"price":0.0001232,"qty":554.24877337}],"asks":[],"checksum":3066311139,"timestamp":"2024-06-01T22:43:39.819510Z"}]}
{"channel":"book","type":"update","data":[{"symbol":"ATOM/BTC","bids":[{"price":0.0001232,"qty":1032.76162786}],"asks":[],"checksum":3867273650,"timestamp":"2024-06-01T22:43:40.100816Z"}]}
{"channel":"book","type":"update","data":[{"symbol":"ATOM/BTC","bids":[{"price":0.0001232,"qty":554.24877337}],"asks":[],"checksum":3066311139,"timestamp":"2024-06-01T22:43:40.388119Z"}]}
{"channel":"book","type":"update","data":[{"symbol":"ATOM/BTC","bids":[],"asks":[{"price":0.0001236,"qty":1898.01676295}],"checksum":1583889378,"timestamp":"2024-06-01T22:43:40.616301Z"}]}
{"channel":"book","type":"update","data":[{"symbol":"ATOM/BTC","bids":[],"asks":[{"price":0.0001237,"qty":1310.29168063}],"checksum":3085896805,"timestamp":"2024-06-01T22:43:40.616325Z"}]}
{"channel":"book","type":"update","data":[{"symbol":"ATOM/BTC","bids":[],"asks":[{"price":0.0001236,"qty":1909.74372493}],"checksum":1919704949,"timestamp":"2024-06-01T22:43:40.618091Z"}]}
{"channel":"book","type":"update","data":[{"symbol":"ATOM/BTC","bids":[{"price":0.0001232,"qty":1032.76162787}],"asks":[],"checksum":2335149368,"timestamp":"2024-06-01T22:43:40.679782Z"}]}
{"channel":"book","type":"update","data":[{"symbol":"ATOM/BTC","bids":[{"price":0.0001232,"qty":554.24877337}],"asks":[],"checksum":1919704949,"timestamp":"2024-06-01T22:43:40.967906Z"}]}
{"channel":"book","type":"update","data":[{"symbol":"ATOM/BTC","bids":[{"price":0.0001232,"qty":598.63990080}],"asks":[],"checksum":1222995740,"timestamp":"2024-06-01T22:43:40.973855Z"}]}
