{"channel":"book","type":"snapshot","data":[{"symbol":"ATOM/USDT","bids":[{"price":8.3567,"qty":23.94076783},{"price":8.3566,"qty":1109.83633266},{"price":8.3564,"qty":179.65280210},{"price":8.3561,"qty":221.22262370},{"price":8.3560,"qty":127.98073240},{"price":8.3459,"qty":477.02833669},{"price":8.3458,"qty":116.69747472},{"price":8.3454,"qty":179.89008495},{"price":8.3412,"qty":179.98047136},{"price":8.3403,"qty":174.46441853}],"asks":[{"price":8.3658,"qty":221.22262370},{"price":8.3659,"qty":508.58659932},{"price":8.3660,"qty":120.94360497},{"price":8.3661,"qty":179.44804670},{"price":8.3677,"qty":174.46441853},{"price":8.3679,"qty":221.22262370},{"price":8.3680,"qty":116.69747472},{"price":8.3726,"qty":179.30678802},{"price":8.3770,"qty":103.02220825},{"price":8.3771,"qty":261.07651868}],"checksum":2582168132}]}
{"channel":"book","type":"update","data":[{"symbol":"ATOM/USDT","bids":[],"asks":[{"price":8.3657,"qty":1017.19678564}],"checksum":2064468170,"timestamp":"2024-06-01T22:43:12.544052Z"}]}
{"channel":"book","type":"update","data":[{"symbol":"ATOM/USDT","bids":[{"price":8.3564,"qty":0.00000000},{"price":8.3394,"qty":361.77248190}],"asks":[],"checksum":1799575420,"timestamp":"2024-06-01T22:43:12.548165Z"}]}
{"channel":"book","type":"update","data":[{"symbol":"ATOM/USDT","bids":[{"price":8.3568,"qty":179.64574311}],"asks":[],"checksum":1320177658,"timestamp":"2024-06-01T22:43:12.551746Z"}]}
{"channel":"book","type":"update","data":[{"symbol":"ATOM/USDT","bids":[{"price":8.3567,"qty":0.00000000},{"price":8.3394,"qty":361.77248190}],"asks":[],"checksum":373414638,"timestamp":"2024-06-01T22:43:12.556107Z"}]}
{"channel":"book","type":"update","data":[{"symbol":"ATOM/USDT","bids":[{"price":8.3569,"qty":23.93557775}],"asks":[],"checksum":2490367246,"timestamp":"2024-06-01T22:43:12.556435Z"}]}
{"channel":"book","type":"update","data":[{"symbol":"ATOM/USDT","bids":[{"price":8.3569,"qty":245.15820145}],"asks":[],"checksum":4274809887,"timestamp":"2024-06-01T22:43:12.714396Z"}]}
{"channel":"book","type":"update","data":[{"symbol":"ATOM/USDT","bids":[],"asks":[{"price":8.3677,"qty":0.00000000},{"price":8.3771,"qty":261.07651868}],"checksum":2969108344,"timestamp":"2024-06-01T22:43:12.885291Z"}]}
{"channel":"book","type":"update","data":[{"symbol":"ATOM/USDT","bids":[],"asks":[{"price":8.3725,"qty":174.46441853}],"checksum":1032300406,"timestamp":"2024-06-01T22:43:12.888022Z"}]}
{"channel":"book","type":"update","data":[{"symbol":"ATOM/USDT","bids":[],"asks":[{"price":8.3679,"qty":0.00000000},{"price":8.3771,"qty":261.07651868}],"checksum":828270681,"timestamp":"2024-06-01T22:43:12.997627Z"}]}
{"channel":"book","type":"update","data":[{"symbol":"ATOM/USDT","bids":[{"price":8.3566,"qty":888.61370896}],"asks":[],"checksum":423441722,"timestamp":"2024-06-01T22:43:13.212328Z"}]}
{"channel":"book","type":"update","data":[{"symbol":"ATOM/USDT","bids":[],"asks":[{"price":8.3697,"qty":478.56580837}],"checksum":604175099,"timestamp":"2024-06-01T22:43:13.470061Z"}]}
{"channel":"book","type":"update","data":[{"symbol":"ATOM/USDT","bids":[{"price":8.3566,"qty":637.03523881}],"asks":[],"checksum":1949858486,"timestamp":"2024-06-01T22:43:14.745606Z"}]}
{"channel":"book","type":"update","data":[{"symbol":"ATOM/USDT","bids":[{"price":8.3569,"qty":496.60220969}],"asks":[],"checksum":4173026273,"timestamp":"2024-06-01T22:43:14.786028Z"}]}
{"channel":"book","type":"update","data":[{"symbol":"ATOM/USDT","bids":[],"asks":[{"price":8.3657,"qty":0.00000000},{"price":8.3771,"qty":261.07651868}],"checksum":424945468,"timestamp":"2024-06-01T22:43:15.146637Z"}]}
{"channel":"book","type":"update","data":[{"symbol":"ATOM/USDT","bids":[{"price":8.3566,"qty":0.00000000},{"price":8.3394,"qty":361.77248190}],"asks":[],"checksum":63410265,"timestamp":"2024-06-01T22:43:15.146716Z"}]}
{"channel":"book","type":"update","data":[{"symbol":"ATOM/USDT","bids":[{"price":8.3569,"qty":1133.24718433}],"asks":[],"checksum":674444328,"timestamp":"2024-06-01T22:43:15.187045Z"}]}
{"channel":"book","type":"update","data":[{"symbol":"ATOM/USDT","bids":[{"price":8.3476,"qty":124.86453051}],"asks":[],"checksum":429962936,"timestamp":"2024-06-01T22:43:15.431489Z"}]}
{"channel":"book","type":"update","data":[{"symbol":"ATOM/USDT","bids":[],"asks":[{"price":8.3659,"qty":0.00000000},{"price":8.3774,"qty":179.20539688}],"checksum":2417210493,"timestamp":"2024-06-01T22:43:16.703937Z"}]}
{"channel":"book","type":"update","data":[{"symbol":"ATOM/USDT","bids":[],"asks":[{"price":8.3659,"qty":221.22262370}],"checksum":1316206257,"timestamp":"2024-06-01T22:43:16.709079Z"}]}
{"channel":"book","type":"update","data":[{"symbol":"ATOM/USDT","bids":[],"asks":[{"price":8.3658,"qty":0.00000000},{"price":8.3774,"qty":179.20539688}],"checksum":1837735723,"timestamp":"2024-06-01T22:43:16.709117Z"}]}
{"channel":"book","type":"update","data":[{"symbol":"ATOM/USDT","bids":[],"asks":[{"price":8.3697,"qty":0.00000000},{"price":8.3850,"qty":50.64940495}],"checksum":3987562196,"timestamp":"2024-06-01T22:43:17.293153Z"}]}
{"channel":"book","type":"update","data":[{"symbol":"ATOM/USDT","bids":[],"asks":[{"price":8.3660,"qty":629.54154221}],"checksum":2967181818,"timestamp":"2024-06-01T22:43:17.294712Z"}]}
{"channel":"book","type":"update","data":[{"symbol":"ATOM/USDT","bids":[],"asks":[{"price":8.3698,"qty":478.56002281}],"checksum":2096726409,"timestamp":"2024-06-01T22:43:17.764705Z"}]}
{"channel":"book","type":"update","data":[{"symbol":"ATOM/USDT","bids":[],"asks":[{"price":8.3660,"qty":120.94360497}],"checksum":2691889793,"timestamp":"2024-06-01T22:43:17.886049Z"}]}
{"channel":"book","type":"update","data":[{"symbol":"ATOM/USDT","bids":[{"price":8.3476,"qty":0.00000000},{"price":8.3394,"qty":361.77248190}],"asks":[],"checksum":2447472657,"timestamp":"2024-06-01T22:43:18.478886Z"}]}
{"channel":"book","type":"update","data":[{"symbol":"ATOM/USDT","bids":[{"price":8.3560,"qty":0.00000000},{"price":8.3332,"qty":361.77248190}],"asks":[],"checksum":1328711429,"timestamp":"2024-06-01T22:43:21.115990Z"}]}
{"channel":"book","type":"update","data":[{"symbol":"ATOM/USDT","bids":[],"asks":[{"price":8.3660,"qty":0.00000000},{"price":8.3850,"qty":50.64940495}],"checksum":545867810,"timestamp":"2024-06-01T22:43:21.116068Z"}]}
{"channel":"book","type":"update","data":[{"symbol":"ATOM/USDT","bids":[{"price":8.3570,"qty":35.08106197}],"asks":[],"checksum":3893175218,"timestamp":"2024-06-01T22:43:21.121713Z"}]}
{"channel":"book","type":"update","data":[{"symbol":"ATOM/USDT","bids":[],"asks":[{"price":8.3670,"qty":57.39360497}],"checksum":3315028174,"timestamp":"2024-06-01T22:43:21.121730Z"}]}
{"channel":"book","type":"update","data":[{"symbol":"ATOM/USDT","bids":[{"price":8.3568,"qty":0.00000000},{"price":8.3332,"qty":361.77248190}],"asks":[],"checksum":2325764205,"timestamp":"2024-06-01T22:43:21.125703Z"}]}
{"channel":"book","type":"update","data":[{"symbol":"ATOM/USDT","bids":[{"price":8.3569,"qty":1109.31160658}],"asks":[],"checksum":684944355,"timestamp":"2024-06-01T22:43:21.125823Z"}]}
{"channel":"book","type":"update","data":[{"symbol":"ATOM/USDT","bids":[{"price":8.3571,"qty":23.93514207}],"asks":[],"checksum":3471122573,"timestamp":"2024-06-01T22:43:21.125945Z"}]}
{"channel":"book","type":"update","data":[{"symbol":"ATOM/USDT","bids":[{"price":8.3571,"qty":203.57443648}],"asks":[],"checksum":2136200331,"timestamp":"2024-06-01T22:43:21.129762Z"}]}
{"channel":"book","type":"update","data":[{"symbol":"ATOM/USDT","bids":[],"asks":[{"price":8.3659,"qty":0.00000000},{"price":8.3850,"qty":50.64940495}],"checksum":3932023982,"timestamp":"2024-06-01T22:43:21.213077Z"}]}
{"channel":"book","type":"update","data":[{"symbol":"ATOM/USDT","bids":[{"price":8.3572,"qty":221.22262370}],"asks":[],"checksum":516982129,"timestamp":"2024-06-01T22:43:21.213226Z"}]}
{"channel":"book","type":"update","data":[{"symbol":"ATOM/USDT","bids":[],"asks":[{"price":8.3660,"qty":221.22262370}],"checksum":1830760905,"timestamp":"2024-06-01T22:43:21.213321Z"}]}
{"channel":"book","type":"update","data":[{"symbol":"ATOM/USDT","bids":[{"price":8.3571,"qty":179.63929441}],"asks":[],"checksum":3267121418,"timestamp":"2024-06-01T22:43:21.217622Z"}]}
{"channel":"book","type":"update","data":[{"symbol":"ATOM/USDT","bids":[{"price":8.3573,"qty":23.93526326}],"asks":[],"checksum":11811189,"timestamp":"2024-06-01T22:43:21.217762Z"}]}
{"channel":"book","type":"update","data":[{"symbol":"ATOM/USDT","bids":[],"asks":[{"price":8.3698,"qty":0.00000000},{"price":8.3850,"qty":50.64940495}],"checksum":2813280355,"timestamp":"2024-06-01T22:43:21.245887Z"}]}
{"channel":"book","type":"update","data":[{"symbol":"ATOM/USDT","bids":[{"price":8.3569,"qty":888.08898288}],"asks":[],"checksum":1358724032,"timestamp":"2024-06-01T22:43:21.249441Z"}]}
{"channel":"book","type":"update","data":[{"symbol":"ATOM/USDT","bids":[],"asks":[{"price":8.3675,"qty":221.22262370}],"checksum":2560564372,"timestamp":"2024-06-01T22:43:21.531657Z"}]}
{"channel":"book","type":"update","data":[{"symbol":"ATOM/USDT","bids":[{"price":8.3571,"qty":0.00000000},{"price":8.3404,"qty":113.26134686}],"asks":[],"checksum":4158363453,"timestamp":"2024-06-01T22:43:22.729658Z"}]}
{"channel":"book","type":"update","data":[{"symbol":"ATOM/USDT","bids":[{"price":8.3572,"qty":0.00000000},{"price":8.3403,"qty":174.46441853}],"asks":[],"checksum":1945493313,"timestamp":"2024-06-01T22:43:22.733677Z"}]}
{"channel":"book","type":"update","data":[{"symbol":"ATOM/USDT","bids":[{"price":8.3571,"qty":221.22262370}],"asks":[],"checksum":4194025730,"timestamp":"2024-06-01T22:43:22.733804Z"}]}
{"channel":"book","type":"update","data":[{"symbol":"ATOM/USDT","bids":[{"price":8.3574,"qty":179.63284707}],"asks":[],"checksum":2015851515,"timestamp":"2024-06-01T22:43:22.734344Z"}]}
{"channel":"book","type":"update","data":[{"symbol":"ATOM/USDT","bids":[{"price":8.3573,"qty":0.00000000},{"price":8.3404,"qty":113.26134686}],"asks":[],"checksum":4053686294,"timestamp":"2024-06-01T22:43:22.738611Z"}]}
{"channel":"book","type":"update","data":[{"symbol":"ATOM/USDT","bids":[{"price":8.3575,"qty":23.93462456}],"asks":[],"checksum":2828293489,"timestamp":"2024-06-01T22:43:22.738703Z"}]}
{"channel":"book","type":"update","data":[{"symbol":"ATOM/USDT","bids":[{"price":8.3575,"qty":245.15724826}],"asks":[],"checksum":2307625268,"timestamp":"2024-06-01T22:43:23.215301Z"}]}
{"channel":"book","type":"update","data":[{"symbol":"ATOM/USDT","bids":[{"price":8.3571,"qty":0.00000000},{"price":8.3404,"qty":113.26134686}],"asks":[],"checksum":41847768,"timestamp":"2024-06-01T22:43:23.218562Z"}]}
{"channel":"book","type":"update","data":[{"symbol":"ATOM/USDT","bids":[],"asks":[{"price":8.3675,"qty":0.00000000},{"price":8.3850,"qty":50.64940495}],"checksum":1857060178,"timestamp":"2024-06-01T22:43:23.461388Z"}]}
{"channel":"book","type":"update","data":[{"symbol":"ATOM/USDT","bids":[],"asks":[{"price":8.3677,"qty":221.22262370}],"checksum":505959577,"timestamp":"2024-06-01T22:43:23.765710Z"}]}
{"channel":"book","type":"update","data":[{"symbol":"ATOM/USDT","bids":[],"asks":[{"price":8.3660,"qty":0.00000000},{"price":8.3850,"qty":50.64940495}],"checksum":4103472993,"timestamp":"2024-06-01T22:43:25.112124Z"}]}
{"channel":"book","type":"update","data":[{"symbol":"ATOM/USDT","bids":[{"price":8.3574,"qty":0.00000000},{"price":8.3403,"qty":174.46441853}],"asks":[],"checksum":3697025685,"timestamp":"2024-06-01T22:43:25.115406Z"}]}
{"channel":"book","type":"update","data":[{"symbol":"ATOM/USDT","bids":[{"price":8.3576,"qty":179.62854972}],"asks":[],"checksum":1182685483,"timestamp":"2024-06-01T22:43:25.119668Z"}]}
{"channel":"book","type":"update","data":[{"symbol":"ATOM/USDT","bids":[{"price":8.3575,"qty":221.22262370}],"asks":[],"checksum":3952159280,"timestamp":"2024-06-01T22:43:25.124192Z"}]}
{"channel":"book","type":"update","data":[{"symbol":"ATOM/USDT","bids":[{"price":8.3577,"qty":23.93295124}],"asks":[],"checksum":708460158,"timestamp":"2024-06-01T22:43:25.124404Z"}]}
{"channel":"book","type":"update","data":[{"symbol":"ATOM/USDT","bids":[{"price":8.3576,"qty":0.00000000},{"price":8.3404,"qty":113.26134686}],"asks":[],"checksum":2042096352,"timestamp":"2024-06-01T22:43:25.128475Z"}]}
{"channel":"book","type":"update","data":[{"symbol":"ATOM/USDT","bids":[{"price":8.3575,"qty":0.00000000},{"price":8.3403,"qty":174.46441853}],"asks":[],"checksum":3828956407,"timestamp":"2024-06-01T22:43:25.211733Z"}]}
{"channel":"book","type":"update","data":[{"symbol":"ATOM/USDT","bids":[{"price":8.3571,"qty":221.22262370}],"asks":[],"checksum":1849107124,"timestamp":"2024-06-01T22:43:25.211867Z"}]}
{"channel":"book","type":"update","data":[{"symbol":"ATOM/USDT","bids":[],"asks":[{"price":8.3676,"qty":221.22262370}],"checksum":1651877445,"timestamp":"2024-06-01T22:43:25.219475Z"}]}
{"channel":"book","type":"update","data":[{"symbol":"ATOM/USDT","bids":[],"asks":[{"price":8.3677,"qty":0.00000000},{"price":8.3850,"qty":50.64940495}],"checksum":2096176814,"timestamp":"2024-06-01T22:43:25.236615Z"}]}
{"channel":"book","type":"update","data":[{"symbol":"ATOM/USDT","bids":[],"asks":[{"price":8.3679,"qty":221.22262370}],"checksum":3343863538,"timestamp":"2024-06-01T22:43:25.673916Z"}]}
{"channel":"book","type":"update","data":[{"symbol":"ATOM/USDT","bids":[{"price":8.3569,"qty":636.64497464}],"asks":[],"checksum":1495330548,"timestamp":"2024-06-01T22:43:25.888379Z"}]}
{"channel":"book","type":"update","data":[{"symbol":"ATOM/USDT","bids":[{"price":8.3577,"qty":275.26823168}],"asks":[],"checksum":1388234501,"timestamp":"2024-06-01T22:43:25.928510Z"}]}
{"channel":"book","type":"update","data":[{"symbol":"ATOM/USDT","bids":[{"price":8.3578,"qty":221.22262370}],"asks":[],"checksum":2924769008,"timestamp":"2024-06-01T22:43:25.932801Z"}]}
{"channel":"book","type":"update","data":[{"symbol":"ATOM/USDT","bids":[{"price":8.3577,"qty":251.33528044}],"asks":[],"checksum":759824404,"timestamp":"2024-06-01T22:43:25.937814Z"}]}
{"channel":"book","type":"update","data":[{"symbol":"ATOM/USDT","bids":[{"price":8.3579,"qty":23.93216801}],"asks":[],"checksum":3879893379,"timestamp":"2024-06-01T22:43:25.937927Z"}]}
{"channel":"book","type":"update","data":[{"symbol":"ATOM/USDT","bids":[{"price":8.3569,"qty":0.00000000},{"price":8.3412,"qty":179.98047136}],"asks":[],"checksum":1493098357,"timestamp":"2024-06-01T22:43:26.068723Z"}]}
{"channel":"book","type":"update","data":[{"symbol":"ATOM/USDT","bids":[{"price":8.3579,"qty":660.26300639}],"asks":[],"checksum":2997309151,"timestamp":"2024-06-01T22:43:26.109082Z"}]}
{"channel":"book","type":"update","data":[{"symbol":"ATOM/USDT","bids":[{"price":8.3571,"qty":0.00000000},{"price":8.3404,"qty":113.26134686}],"asks":[],"checksum":4180040607,"timestamp":"2024-06-01T22:43:26.113030Z"}]}
{"channel":"book","type":"update","data":[{"symbol":"ATOM/USDT","bids":[{"price":8.3580,"qty":179.61995365}],"asks":[],"checksum":1771382549,"timestamp":"2024-06-01T22:43:26.128749Z"}]}
{"channel":"book","type":"update","data":[{"symbol":"ATOM/USDT","bids":[{"price":8.3579,"qty":636.33083838}],"asks":[],"checksum":3357200489,"timestamp":"2024-06-01T22:43:26.133035Z"}]}
{"channel":"book","type":"update","data":[{"symbol":"ATOM/USDT","bids":[{"price":8.3581,"qty":23.93184379}],"asks":[],"checksum":1392699554,"timestamp":"2024-06-01T22:43:26.133217Z"}]}
{"channel":"book","type":"update","data":[{"symbol":"ATOM/USDT","bids":[{"price":8.3581,"qty":245.15446749}],"asks":[],"checksum":515976950,"timestamp":"2024-06-01T22:43:26.212343Z"}]}
{"channel":"book","type":"update","data":[{"symbol":"ATOM/USDT","bids":[{"price":8.3488,"qty":124.85635444}],"asks":[],"checksum":2545173363,"timestamp":"2024-06-01T22:43:26.333630Z"}]}
{"channel":"book","type":"update","data":[{"symbol":"ATOM/USDT","bids":[{"price":8.3577,"qty":0.00000000},{"price":8.3454,"qty":179.89008495}],"asks":[],"checksum":3661848899,"timestamp":"2024-06-01T22:43:26.439103Z"}]}
{"channel":"book","type":"update","data":[{"symbol":"ATOM/USDT","bids":[{"price":8.3578,"qty":0.00000000},{"price":8.3412,"qty":179.98047136}],"asks":[],"checksum":3785109053,"timestamp":"2024-06-01T22:43:26.443147Z"}]}
{"channel":"book","type":"update","data":[{"symbol":"ATOM/USDT","bids":[{"price":8.3581,"qty":496.51099691}],"asks":[],"checksum":1432862268,"timestamp":"2024-06-01T22:43:26.479351Z"}]}
{"channel":"book","type":"update","data":[{"symbol":"ATOM/USDT","bids":[],"asks":[{"price":8.3679,"qty":0.00000000},{"price":8.3850,"qty":50.64940495}],"checksum":922820019,"timestamp":"2024-06-01T22:43:26.497374Z"}]}
{"channel":"book","type":"update","data":[{"symbol":"ATOM/USDT","bids":[{"price":8.3579,"qty":0.00000000},{"price":8.3404,"qty":113.26134686}],"asks":[],"checksum":4239672560,"timestamp":"2024-06-01T22:43:26.701125Z"}]}
{"channel":"book","type":"update","data":[{"symbol":"ATOM/USDT","bids":[{"price":8.3581,"qty":1132.90219188}],"asks":[],"checksum":837003029,"timestamp":"2024-06-01T22:43:26.741506Z"}]}
{"channel":"book","type":"update","data":[{"symbol":"ATOM/USDT","bids":[],"asks":[{"price":8.3680,"qty":337.92009842}],"checksum":1358535372,"timestamp":"2024-06-01T22:43:26.856555Z"}]}
{"channel":"book","type":"update","data":[{"symbol":"ATOM/USDT","bids":[],"asks":[{"price":8.3680,"qty":116.69747472}],"checksum":837003029,"timestamp":"2024-06-01T22:43:29.059998Z"}]}
{"channel":"book","type":"update","data":[{"symbol":"ATOM/USDT","bids":[],"asks":[{"price":8.3681,"qty":221.22262370}],"checksum":2561677373,"timestamp":"2024-06-01T22:43:29.356185Z"}]}
{"channel":"book","type":"update","data":[{"symbol":"ATOM/USDT","bids":[{"price":8.3488,"qty":0.00000000},{"price":8.3403,"qty":174.46441853}],"asks":[],"checksum":613822005,"timestamp":"2024-06-01T22:43:29.359472Z"}]}
{"channel":"book","type":"update","data":[{"symbol":"ATOM/USDT","bids":[{"price":8.3403,"qty":0.00000000},{"price":8.3394,"qty":361.77248190}],"asks":[],"checksum":4138431963,"timestamp":"2024-06-01T22:43:30.610210Z"}]}
{"channel":"book","type":"update","data":[{"symbol":"ATOM/USDT","bids":[{"price":8.3413,"qty":174.46441853}],"asks":[],"checksum":970935813,"timestamp":"2024-06-01T22:43:30.612900Z"}]}
{"channel":"book","type":"update","data":[{"symbol":"ATOM/USDT","bids":[{"price":8.3404,"qty":0.00000000},{"price":8.3394,"qty":361.77248190}],"asks":[],"checksum":704901684,"timestamp":"2024-06-01T22:43:33.817573Z"}]}
{"channel":"book","type":"update","data":[{"symbol":"ATOM/USDT","bids":[],"asks":[{"price":8.3681,"qty":0.00000000},{"price":8.3850,"qty":50.64940495}],"checksum":2203077916,"timestamp":"2024-06-01T22:43:35.227722Z"}]}
{"channel":"book","type":"update","data":[{"symbol":"ATOM/USDT","bids":[],"asks":[{"price":8.3682,"qty":221.22262370}],"checksum":772405905,"timestamp":"2024-06-01T22:43:35.632195Z"}]}
{"channel":"book","type":"update","data":[{"symbol":"ATOM/USDT","bids":[{"price":8.3580,"qty":0.00000000},{"price":8.3333,"qty":113.35784592}],"asks":[],"checksum":1153376952,"timestamp":"2024-06-01T22:43:37.753592Z"}]}
{"channel":"book","type":"update","data":[{"symbol":"ATOM/USDT","bids":[{"price":8.3582,"qty":179.61567089}],"asks":[],"checksum":611449206,"timestamp":"2024-06-01T22:43:37.757322Z"}]}
{"channel":"book","type":"update","data":[{"symbol":"ATOM/USDT","bids":[{"price":8.3570,"qty":0.00000000},{"price":8.3333,"qty":113.35784592}],"asks":[],"checksum":3416915144,"timestamp":"2024-06-01T22:43:37.760405Z"}]}
{"channel":"book","type":"update","data":[{"symbol":"ATOM/USDT","bids":[{"price":8.3581,"qty":1108.97034809}],"asks":[],"checksum":3698398150,"timestamp":"2024-06-01T22:43:37.761094Z"}]}
{"channel":"book","type":"update","data":[{"symbol":"ATOM/USDT","bids":[{"price":8.3583,"qty":23.93206507}],"asks":[],"checksum":1913297129,"timestamp":"2024-06-01T22:43:37.761419Z"}]}
{"channel":"book","type":"update","data":[{"symbol":"ATOM/USDT","bids":[],"asks":[{"price":8.3670,"qty":0.00000000},{"price":8.3850,"qty":50.64940495}],"checksum":3023119655,"timestamp":"2024-06-01T22:43:37.763214Z"}]}
