{"channel":"book","type":"snapshot","data":[{"symbol":"ATOM/USD","bids":[{"price":8.3588,"qty":11.96343972},{"price":8.3536,"qty":32.00000000},{"price":8.3533,"qty":299.28212353},{"price":8.3509,"qty":95.73993235},{"price":8.3508,"qty":621.33882732},{"price":8.3500,"qty":200.00000000},{"price":8.3495,"qty":598.83548007},{"price":8.3490,"qty":100.08318602},{"price":8.3488,"qty":299.36886051},{"price":8.3480,"qty":20.50000000}],"asks":[{"price":8.3589,"qty":1204.32752567},{"price":8.3590,"qty":120.60110497},{"price":8.3597,"qty":57.11859677},{"price":8.3599,"qty":16.40983670},{"price":8.3601,"qty":567.60578167},{"price":8.3605,"qty":598.05303036},{"price":8.3611,"qty":200.00000000},{"price":8.3620,"qty":1196.30000000},{"price":8.3624,"qty":299.28212353},{"price":8.3626,"qty":1734.68407200}],"checksum":4174381129}]}
{"channel":"book","type":"update","data":[{"symbol":"ATOM/USD","bids":[],"asks":[{"price":8.3601,"qty":15.19637467}],"checksum":1795020375,"timestamp":"2024-06-01T22:43:13.319581Z"}]}
{"channel":"book","type":"update","data":[{"symbol":"ATOM/USD","bids":[],"asks":[{"price":8.3599,"qty":0.00000000},{"price":8.3633,"qty":597.85360870}],"checksum":794577874,"timestamp":"2024-06-01T22:43:13.357085Z"}]}
{"channel":"book","type":"update","data":[{"symbol":"ATOM/USD","bids":[],"asks":[{"price":8.3600,"qty":14.07185068}],"checksum":2215225905,"timestamp":"2024-06-01T22:43:13.357736Z"}]}
{"channel":"book","type":"update","data":[{"symbol":"ATOM/USD","bids":[],"asks":[{"price":8.3600,"qty":0.00000000},{"price":8.3633,"qty":597.85360870}],"checksum":794577874,"timestamp":"2024-06-01T22:43:16.385964Z"}]}
{"channel":"book","type":"update","data":[{"symbol":"ATOM/USD","bids":[],"asks":[{"price":8.3604,"qty":11.73628351}],"checksum":2647228976,"timestamp":"2024-06-01T22:43:16.386759Z"}]}
{"channel":"book","type":"update","data":[{"symbol":"ATOM/USD","bids":[],"asks":[{"price":8.3619,"qty":4.37918845}],"checksum":1724378791,"timestamp":"2024-06-01T22:43:16.386779Z"}]}
{"channel":"book","type":"update","data":[{"symbol":"ATOM/USD","bids":[{"price":8.3490,"qty":0.00000000},{"price":8.3467,"qty":598.00000000}],"asks":[],"checksum":2135357403,"timestamp":"2024-06-01T22:43:16.991930Z"}]}
{"channel":"book","type":"update","data":[{"symbol":"ATOM/USD","bids":[{"price":8.3510,"qty":79.62334913}],"asks":[],"checksum":2651185749,"timestamp":"2024-06-01T22:43:16.997583Z"}]}
{"channel":"book","type":"update","data":[{"symbol":"ATOM/USD","bids":[{"price":8.3509,"qty":0.00000000},{"price":8.3467,"qty":598.00000000}],"asks":[],"checksum":1556541548,"timestamp":"2024-06-01T22:43:17.001237Z"}]}
{"channel":"book","type":"update","data":[{"symbol":"ATOM/USD","bids":[{"price":8.3511,"qty":95.74059905}],"asks":[],"checksum":3086389416,"timestamp":"2024-06-01T22:43:17.001421Z"}]}
{"channel":"book","type":"update","data":[{"symbol":"ATOM/USD","bids":[],"asks":[{"price":8.3620,"qty":598.30000000}],"checksum":3540366455,"timestamp":"2024-06-01T22:43:20.912762Z"}]}
{"channel":"book","type":"update","data":[{"symbol":"ATOM/USD","bids":[],"asks":[{"price":8.3620,"qty":0.00000000},{"price":8.3633,"qty":597.85360870},{"price":8.3623,"qty":598.30000000}],"checksum":900580559,"timestamp":"2024-06-01T22:43:20.915998Z"}]}
{"channel":"book","type":"update","data":[{"symbol":"ATOM/USD","bids":[],"asks":[{"price":8.3611,"qty":0.00000000},{"price":8.3633,"qty":597.85360870}],"checksum":2159096900,"timestamp":"2024-06-01T22:43:21.114394Z"}]}
{"channel":"book","type":"update","data":[{"symbol":"ATOM/USD","bids":[],"asks":[{"price":8.3590,"qty":0.00000000},{"price":8.3640,"qty":552.40940700}],"checksum":2840797863,"timestamp":"2024-06-01T22:43:21.116011Z"}]}
{"channel":"book","type":"update","data":[{"symbol":"ATOM/USD","bids":[],"asks":[{"price":8.3600,"qty":57.39360497}],"checksum":3497608902,"timestamp":"2024-06-01T22:43:21.121608Z"}]}
{"channel":"book","type":"update","data":[{"symbol":"ATOM/USD","bids":[],"asks":[{"price":8.3631,"qty":598.00000000}],"checksum":1662520898,"timestamp":"2024-06-01T22:43:21.121890Z"}]}
{"channel":"book","type":"update","data":[{"symbol":"ATOM/USD","bids":[],"asks":[{"price":8.3624,"qty":0.00000000},{"price":8.3633,"qty":597.85360870}],"checksum":2735168057,"timestamp":"2024-06-01T22:43:21.256981Z"}]}
{"channel":"book","type":"update","data":[{"symbol":"ATOM/USD","bids":[{"price":8.3508,"qty":22.60000000}],"asks":[],"checksum":1488560109,"timestamp":"2024-06-01T22:43:21.346549Z"}]}
{"channel":"book","type":"update","data":[{"symbol":"ATOM/USD","bids":[{"price":8.3519,"qty":598.66207404}],"asks":[],"checksum":1541805419,"timestamp":"2024-06-01T22:43:21.352029Z"}]}
{"channel":"book","type":"update","data":[{"symbol":"ATOM/USD","bids":[{"price":8.3511,"qty":0.00000000},{"price":8.3480,"qty":20.50000000}],"asks":[],"checksum":2998471675,"timestamp":"2024-06-01T22:43:21.355090Z"}]}
{"channel":"book","type":"update","data":[{"symbol":"ATOM/USD","bids":[],"asks":[{"price":8.3621,"qty":200.00000000}],"checksum":2954277571,"timestamp":"2024-06-01T22:43:21.357692Z"}]}
{"channel":"book","type":"update","data":[{"symbol":"ATOM/USD","bids":[{"price":8.3510,"qty":279.62334913}],"asks":[],"checksum":829853504,"timestamp":"2024-06-01T22:43:21.391010Z"}]}
{"channel":"book","type":"update","data":[{"symbol":"ATOM/USD","bids":[{"price":8.3500,"qty":0.00000000},{"price":8.3462,"qty":598.30000000}],"asks":[],"checksum":2875479074,"timestamp":"2024-06-01T22:43:21.395510Z"}]}
{"channel":"book","type":"update","data":[{"symbol":"ATOM/USD","bids":[],"asks":[{"price":8.3620,"qty":299.28212353}],"checksum":2357083849,"timestamp":"2024-06-01T22:43:21.576672Z"}]}
{"channel":"book","type":"update","data":[{"symbol":"ATOM/USD","bids":[{"price":8.3533,"qty":0.00000000},{"price":8.3461,"qty":598.00000000}],"asks":[],"checksum":1316178190,"timestamp":"2024-06-01T22:43:22.142614Z"}]}
{"channel":"book","type":"update","data":[{"symbol":"ATOM/USD","bids":[{"price":8.3536,"qty":0.00000000},{"price":8.3460,"qty":599.08248192}],"asks":[],"checksum":1365441272,"timestamp":"2024-06-01T22:43:22.145246Z"}]}
{"channel":"book","type":"update","data":[{"symbol":"ATOM/USD","bids":[{"price":8.3522,"qty":32.00000000}],"asks":[],"checksum":3809570,"timestamp":"2024-06-01T22:43:22.145389Z"}]}
{"channel":"book","type":"update","data":[{"symbol":"ATOM/USD","bids":[{"price":8.3461,"qty":0.00000000},{"price":8.3460,"qty":599.08248192},{"price":8.3462,"qty":1196.30000000}],"asks":[],"checksum":516494143,"timestamp":"2024-06-01T22:43:22.145832Z"}]}
{"channel":"book","type":"update","data":[{"symbol":"ATOM/USD","bids":[{"price":8.3539,"qty":299.25840191}],"asks":[],"checksum":3013139104,"timestamp":"2024-06-01T22:43:22.146801Z"}]}
{"channel":"book","type":"update","data":[{"symbol":"ATOM/USD","bids":[{"price":8.3522,"qty":0.00000000},{"price":8.3460,"qty":599.08248192}],"asks":[],"checksum":487649352,"timestamp":"2024-06-01T22:43:22.149494Z"}]}
{"channel":"book","type":"update","data":[{"symbol":"ATOM/USD","bids":[{"price":8.3541,"qty":32.00000000}],"asks":[],"checksum":111928024,"timestamp":"2024-06-01T22:43:22.149727Z"}]}
{"channel":"book","type":"update","data":[{"symbol":"ATOM/USD","bids":[],"asks":[{"price":8.3619,"qty":0.00000000},{"price":8.3631,"qty":598.00000000}],"checksum":1928081656,"timestamp":"2024-06-01T22:43:22.459322Z"}]}
{"channel":"book","type":"update","data":[{"symbol":"ATOM/USD","bids":[],"asks":[{"price":8.3604,"qty":0.00000000},{"price":8.3633,"qty":597.85360870}],"checksum":1762978883,"timestamp":"2024-06-01T22:43:22.459352Z"}]}
{"channel":"book","type":"update","data":[{"symbol":"ATOM/USD","bids":[],"asks":[{"price":8.3619,"qty":8.75799639}],"checksum":2354600925,"timestamp":"2024-06-01T22:43:22.464741Z"}]}
{"channel":"book","type":"update","data":[{"symbol":"ATOM/USD","bids":[],"asks":[{"price":8.3604,"qty":4.72937650}],"checksum":1609236076,"timestamp":"2024-06-01T22:43:22.464755Z"}]}
{"channel":"book","type":"update","data":[{"symbol":"ATOM/USD","bids":[],"asks":[{"price":8.3620,"qty":0.00000000},{"price":8.3631,"qty":598.00000000}],"checksum":1746264054,"timestamp":"2024-06-01T22:43:23.468022Z"}]}
{"channel":"book","type":"update","data":[{"symbol":"ATOM/USD","bids":[],"asks":[{"price":8.3623,"qty":0.00000000},{"price":8.3633,"qty":597.85360870},{"price":8.3630,"qty":598.30000000}],"checksum":3069590067,"timestamp":"2024-06-01T22:43:23.471066Z"}]}
{"channel":"book","type":"update","data":[{"symbol":"ATOM/USD","bids":[],"asks":[{"price":8.3621,"qty":499.25840191}],"checksum":1332765057,"timestamp":"2024-06-01T22:43:23.852900Z"}]}
{"channel":"book","type":"update","data":[{"symbol":"ATOM/USD","bids":[],"asks":[{"price":8.3631,"qty":0.00000000},{"price":8.3633,"qty":597.85360870}],"checksum":1754809869,"timestamp":"2024-06-01T22:43:25.091275Z"}]}
{"channel":"book","type":"update","data":[{"symbol":"ATOM/USD","bids":[{"price":8.3520,"qty":95.73313989}],"asks":[],"checksum":3127113143,"timestamp":"2024-06-01T22:43:25.110083Z"}]}
{"channel":"book","type":"update","data":[{"symbol":"ATOM/USD","bids":[],"asks":[{"price":8.3631,"qty":598.00000000}],"checksum":151174451,"timestamp":"2024-06-01T22:43:25.113349Z"}]}
{"channel":"book","type":"update","data":[{"symbol":"ATOM/USD","bids":[],"asks":[{"price":8.3589,"qty":983.10490197}],"checksum":645999646,"timestamp":"2024-06-01T22:43:25.113823Z"}]}
{"channel":"book","type":"update","data":[{"symbol":"ATOM/USD","bids":[],"asks":[{"price":8.3630,"qty":0.00000000},{"price":8.3633,"qty":597.85360870}],"checksum":1642453498,"timestamp":"2024-06-01T22:43:25.155110Z"}]}
{"channel":"book","type":"update","data":[{"symbol":"ATOM/USD","bids":[],"asks":[{"price":8.3631,"qty":0.00000000},{"price":8.3640,"qty":552.40940700}],"checksum":1674052772,"timestamp":"2024-06-01T22:43:25.163489Z"}]}
{"channel":"book","type":"update","data":[{"symbol":"ATOM/USD","bids":[],"asks":[{"price":8.3640,"qty":1150.70940700}],"checksum":3082020693,"timestamp":"2024-06-01T22:43:25.166253Z"}]}
{"channel":"book","type":"update","data":[{"symbol":"ATOM/USD","bids":[],"asks":[{"price":8.3621,"qty":200.00000000}],"checksum":2285320905,"timestamp":"2024-06-01T22:43:25.233373Z"}]}
{"channel":"book","type":"update","data":[{"symbol":"ATOM/USD","bids":[],"asks":[{"price":8.3597,"qty":0.00000000},{"price":8.3649,"qty":1734.68407200}],"checksum":2675147054,"timestamp":"2024-06-01T22:43:25.286184Z"}]}
{"channel":"book","type":"update","data":[{"symbol":"ATOM/USD","bids":[],"asks":[{"price":8.3599,"qty":221.22262370}],"checksum":390666285,"timestamp":"2024-06-01T22:43:25.290221Z"}]}
{"channel":"book","type":"update","data":[{"symbol":"ATOM/USD","bids":[],"asks":[{"price":8.3619,"qty":0.00000000},{"price":8.3649,"qty":1734.68407200}],"checksum":3516856705,"timestamp":"2024-06-01T22:43:25.480642Z"}]}
{"channel":"book","type":"update","data":[{"symbol":"ATOM/USD","bids":[],"asks":[{"price":8.3604,"qty":0.00000000},{"price":8.3650,"qty":125.84000000}],"checksum":13556550,"timestamp":"2024-06-01T22:43:25.480733Z"}]}
{"channel":"book","type":"update","data":[{"symbol":"ATOM/USD","bids":[],"asks":[{"price":8.3639,"qty":2.91901646}],"checksum":2248875221,"timestamp":"2024-06-01T22:43:25.482200Z"}]}
{"channel":"book","type":"update","data":[{"symbol":"ATOM/USD","bids":[],"asks":[{"price":8.3632,"qty":14.06971776}],"checksum":1944493140,"timestamp":"2024-06-01T22:43:25.482270Z"}]}
{"channel":"book","type":"update","data":[{"symbol":"ATOM/USD","bids":[],"asks":[{"price":8.3601,"qty":0.00000000},{"price":8.3649,"qty":1734.68407200}],"checksum":3571340512,"timestamp":"2024-06-01T22:43:25.498247Z"}]}
{"channel":"book","type":"update","data":[{"symbol":"ATOM/USD","bids":[],"asks":[{"price":8.3611,"qty":15.19637467}],"checksum":3626129084,"timestamp":"2024-06-01T22:43:25.590285Z"}]}
{"channel":"book","type":"update","data":[{"symbol":"ATOM/USD","bids":[],"asks":[{"price":8.3640,"qty":552.40940700},{"price":8.3632,"qty":612.36971776}],"checksum":759615856,"timestamp":"2024-06-01T22:43:25.671302Z"}]}
{"channel":"book","type":"update","data":[{"symbol":"ATOM/USD","bids":[],"asks":[{"price":8.3624,"qty":299.25840191}],"checksum":1599079042,"timestamp":"2024-06-01T22:43:25.674365Z"}]}
{"channel":"book","type":"update","data":[{"symbol":"ATOM/USD","bids":[{"price":8.3539,"qty":0.00000000},{"price":8.3468,"qty":59.80000000}],"asks":[],"checksum":426135919,"timestamp":"2024-06-01T22:43:26.131661Z"}]}
{"channel":"book","type":"update","data":[{"symbol":"ATOM/USD","bids":[{"price":8.3541,"qty":0.00000000},{"price":8.3467,"qty":598.30000000}],"asks":[],"checksum":2994489870,"timestamp":"2024-06-01T22:43:26.134267Z"}]}
{"channel":"book","type":"update","data":[{"symbol":"ATOM/USD","bids":[{"price":8.3523,"qty":32.00000000}],"asks":[],"checksum":2848778622,"timestamp":"2024-06-01T22:43:26.134398Z"}]}
{"channel":"book","type":"update","data":[{"symbol":"ATOM/USD","bids":[{"price":8.3545,"qty":299.23942933}],"asks":[],"checksum":4251587005,"timestamp":"2024-06-01T22:43:26.135162Z"}]}
{"channel":"book","type":"update","data":[{"symbol":"ATOM/USD","bids":[{"price":8.3523,"qty":0.00000000},{"price":8.3468,"qty":59.80000000}],"asks":[],"checksum":4032696481,"timestamp":"2024-06-01T22:43:26.137889Z"}]}
{"channel":"book","type":"update","data":[{"symbol":"ATOM/USD","bids":[{"price":8.3524,"qty":95.72487259}],"asks":[],"checksum":59615911,"timestamp":"2024-06-01T22:43:26.138048Z"}]}
{"channel":"book","type":"update","data":[{"symbol":"ATOM/USD","bids":[{"price":8.3520,"qty":0.00000000},{"price":8.3468,"qty":59.80000000}],"asks":[],"checksum":2413213582,"timestamp":"2024-06-01T22:43:26.138091Z"}]}
{"channel":"book","type":"update","data":[{"symbol":"ATOM/USD","bids":[{"price":8.3548,"qty":32.00000000}],"asks":[],"checksum":3596962382,"timestamp":"2024-06-01T22:43:26.138111Z"}]}
{"channel":"book","type":"update","data":[{"symbol":"ATOM/USD","bids":[],"asks":[{"price":8.3632,"qty":14.06971776}],"checksum":3863893952,"timestamp":"2024-06-01T22:43:26.378502Z"}]}
{"channel":"book","type":"update","data":[{"symbol":"ATOM/USD","bids":[],"asks":[{"price":8.3624,"qty":0.00000000},{"price":8.3640,"qty":1150.70940700}],"checksum":1360469616,"timestamp":"2024-06-01T22:43:26.766233Z"}]}
{"channel":"book","type":"update","data":[{"symbol":"ATOM/USD","bids":[],"asks":[{"price":8.3625,"qty":299.23942933}],"checksum":3808405665,"timestamp":"2024-06-01T22:43:27.067306Z"}]}
{"channel":"book","type":"update","data":[{"symbol":"ATOM/USD","bids":[{"price":8.3520,"qty":95.72439428}],"asks":[],"checksum":555954659,"timestamp":"2024-06-01T22:43:27.181862Z"}]}
{"channel":"book","type":"update","data":[{"symbol":"ATOM/USD","bids":[{"price":8.3524,"qty":0.00000000},{"price":8.3480,"qty":20.50000000}],"asks":[],"checksum":2583534251,"timestamp":"2024-06-01T22:43:27.181933Z"}]}
{"channel":"book","type":"update","data":[{"symbol":"ATOM/USD","bids":[],"asks":[{"price":8.3632,"qty":612.06971776}],"checksum":3817668473,"timestamp":"2024-06-01T22:43:27.765697Z"}]}
{"channel":"book","type":"update","data":[{"symbol":"ATOM/USD","bids":[],"asks":[{"price":8.3632,"qty":14.06971776}],"checksum":2583534251,"timestamp":"2024-06-01T22:43:27.772434Z"}]}
{"channel":"book","type":"update","data":[{"symbol":"ATOM/USD","bids":[],"asks":[{"price":8.3632,"qty":0.00000000},{"price":8.3640,"qty":1150.70940700}],"checksum":649686268,"timestamp":"2024-06-01T22:43:28.514809Z"}]}
{"channel":"book","type":"update","data":[{"symbol":"ATOM/USD","bids":[],"asks":[{"price":8.3639,"qty":0.00000000},{"price":8.3649,"qty":1734.68407200}],"checksum":191042127,"timestamp":"2024-06-01T22:43:28.514884Z"}]}
{"channel":"book","type":"update","data":[{"symbol":"ATOM/USD","bids":[],"asks":[{"price":8.3620,"qty":4.72858237}],"checksum":596526113,"timestamp":"2024-06-01T22:43:28.515437Z"}]}
{"channel":"book","type":"update","data":[{"symbol":"ATOM/USD","bids":[],"asks":[{"price":8.3632,"qty":11.65484463}],"checksum":3777864553,"timestamp":"2024-06-01T22:43:28.515684Z"}]}
{"channel":"book","type":"update","data":[{"symbol":"ATOM/USD","bids":[{"price":8.3480,"qty":618.50000000}],"asks":[],"checksum":652270321,"timestamp":"2024-06-01T22:43:31.583616Z"}]}
{"channel":"book","type":"update","data":[{"symbol":"ATOM/USD","bids":[{"price":8.3481,"qty":598.30000000}],"asks":[],"checksum":4045388268,"timestamp":"2024-06-01T22:43:31.586463Z"}]}
{"channel":"book","type":"update","data":[{"symbol":"ATOM/USD","bids":[{"price":8.3510,"qty":200.00000000}],"asks":[],"checksum":1954225071,"timestamp":"2024-06-01T22:43:32.071119Z"}]}
{"channel":"book","type":"update","data":[{"symbol":"ATOM/USD","bids":[{"price":8.3520,"qty":175.33820997}],"asks":[],"checksum":2728561229,"timestamp":"2024-06-01T22:43:32.074466Z"}]}
{"channel":"book","type":"update","data":[{"symbol":"ATOM/USD","bids":[],"asks":[{"price":8.3632,"qty":609.95484463}],"checksum":3833527116,"timestamp":"2024-06-01T22:43:32.488274Z"}]}
{"channel":"book","type":"update","data":[{"symbol":"ATOM/USD","bids":[{"price":8.3482,"qty":598.00000000}],"asks":[],"checksum":493825631,"timestamp":"2024-06-01T22:43:32.491354Z"}]}
{"channel":"book","type":"update","data":[{"symbol":"ATOM/USD","bids":[],"asks":[{"price":8.3631,"qty":598.00000000}],"checksum":4222403647,"timestamp":"2024-06-01T22:43:32.540956Z"}]}
{"channel":"book","type":"update","data":[{"symbol":"ATOM/USD","bids":[{"price":8.3482,"qty":0.00000000},{"price":8.3481,"qty":598.30000000}],"asks":[],"checksum":45945132,"timestamp":"2024-06-01T22:43:32.541081Z"}]}
{"channel":"book","type":"update","data":[{"symbol":"ATOM/USD","bids":[],"asks":[{"price":8.3632,"qty":11.65484463},{"price":8.3630,"qty":598.30000000}],"checksum":3080912581,"timestamp":"2024-06-01T22:43:33.536676Z"}]}
{"channel":"book","type":"update","data":[{"symbol":"ATOM/USD","bids":[{"price":8.3481,"qty":0.00000000},{"price":8.3480,"qty":20.50000000}],"asks":[],"checksum":903148486,"timestamp":"2024-06-01T22:43:33.536855Z"}]}
{"channel":"book","type":"update","data":[{"symbol":"ATOM/USD","bids":[],"asks":[{"price":8.3630,"qty":0.00000000},{"price":8.3632,"qty":11.65484463}],"checksum":1092422633,"timestamp":"2024-06-01T22:43:33.578698Z"}]}
{"channel":"book","type":"update","data":[{"symbol":"ATOM/USD","bids":[],"asks":[{"price":8.3631,"qty":0.00000000},{"price":8.3633,"qty":597.85360870}],"checksum":4019008155,"timestamp":"2024-06-01T22:43:33.578772Z"}]}
{"channel":"book","type":"update","data":[{"symbol":"ATOM/USD","bids":[],"asks":[{"price":8.3625,"qty":0.00000000},{"price":8.3640,"qty":552.40940700}],"checksum":4224036297,"timestamp":"2024-06-01T22:43:35.231850Z"}]}
