{"channel":"book","type":"snapshot","data":[{"symbol":"ATOM/GBP","bids":[{"price":6.5519,"qty":29.93574930},{"price":6.5506,"qty":41.91842203},{"price":6.5502,"qty":78.20542535},{"price":6.5491,"qty":11.96343972},{"price":6.5490,"qty":59.89789770},{"price":6.5475,"qty":89.86763146},{"price":6.5455,"qty":179.79025668},{"price":6.5394,"qty":299.93058362},{"price":6.5357,"qty":132.09000000},{"price":6.5352,"qty":65.01000000}],"asks":[{"price":6.5537,"qty":29.92773903},{"price":6.5551,"qty":41.88985275},{"price":6.5565,"qty":59.82957269},{"price":6.5578,"qty":89.72656837},{"price":6.5590,"qty":120.60110497},{"price":6.5593,"qty":229.41255162},{"price":6.5668,"qty":77.05000000},{"price":6.5683,"qty":103.02220825},{"price":6.5684,"qty":298.60759526},{"price":6.5710,"qty":76.15000000}],"checksum":1158618101}]}
{"channel":"book","type":"update","data":[{"symbol":"ATOM/GBP","bids":[],"asks":[{"price":6.5537,"qty":0.00000000},{"price":6.5715,"qty":1.71986848}],"checksum":2172740597,"timestamp":"2024-06-01T22:43:11.301247Z"}]}
{"channel":"book","type":"update","data":[{"symbol":"ATOM/GBP","bids":[{"price":6.5519,"qty":0.00000000},{"price":6.5333,"qty":141.35000000}],"asks":[],"checksum":1109159361,"timestamp":"2024-06-01T22:43:11.301259Z"}]}
{"channel":"book","type":"update","data":[{"symbol":"ATOM/GBP","bids":[{"price":6.5520,"qty":29.93502925}],"asks":[],"checksum":149990149,"timestamp":"2024-06-01T22:43:11.307744Z"}]}
{"channel":"book","type":"update","data":[{"symbol":"ATOM/GBP","bids":[],"asks":[{"price":6.5539,"qty":29.92696513}],"checksum":2427098877,"timestamp":"2024-06-01T22:43:11.307830Z"}]}
{"channel":"book","type":"update","data":[{"symbol":"ATOM/GBP","bids":[{"price":6.5520,"qty":0.00000000},{"price":6.5333,"qty":141.35000000}],"asks":[],"checksum":4058140114,"timestamp":"2024-06-01T22:43:11.340630Z"}]}
{"channel":"book","type":"update","data":[{"symbol":"ATOM/GBP","bids":[],"asks":[{"price":6.5539,"qty":0.00000000},{"price":6.5715,"qty":1.71986848}],"checksum":1109159361,"timestamp":"2024-06-01T22:43:11.365426Z"}]}
{"channel":"book","type":"update","data":[{"symbol":"ATOM/GBP","bids":[],"asks":[{"price":6.5551,"qty":0.00000000},{"price":6.5727,"qty":145.18000000}],"checksum":2262549279,"timestamp":"2024-06-01T22:43:11.365437Z"}]}
{"channel":"book","type":"update","data":[{"symbol":"ATOM/GBP","bids":[{"price":6.5506,"qty":0.00000000},{"price":6.5313,"qty":1.60193551}],"asks":[],"checksum":1270710016,"timestamp":"2024-06-01T22:43:11.365586Z"}]}
{"channel":"book","type":"update","data":[{"symbol":"ATOM/GBP","bids":[],"asks":[{"price":6.5564,"qty":41.88133966}],"checksum":1347376566,"timestamp":"2024-06-01T22:43:11.372922Z"}]}
{"channel":"book","type":"update","data":[{"symbol":"ATOM/GBP","bids":[{"price":6.5503,"qty":41.92034187}],"asks":[],"checksum":2417384742,"timestamp":"2024-06-01T22:43:11.373015Z"}]}
{"channel":"book","type":"update","data":[{"symbol":"ATOM/GBP","bids":[],"asks":[{"price":6.5590,"qty":0.00000000},{"price":6.5727,"qty":145.18000000}],"checksum":2448918277,"timestamp":"2024-06-01T22:43:11.373956Z"}]}
{"channel":"book","type":"update","data":[{"symbol":"ATOM/GBP","bids":[{"price":6.5503,"qty":0.00000000},{"price":6.5313,"qty":1.60193551}],"asks":[],"checksum":1793356023,"timestamp":"2024-06-01T22:43:11.378888Z"}]}
{"channel":"book","type":"update","data":[{"symbol":"ATOM/GBP","bids":[],"asks":[{"price":6.5564,"qty":0.00000000},{"price":6.5752,"qty":129.72000000}],"checksum":2901451023,"timestamp":"2024-06-01T22:43:11.378970Z"}]}
{"channel":"book","type":"update","data":[{"symbol":"ATOM/GBP","bids":[],"asks":[{"price":6.5598,"qty":204.91110497}],"checksum":377533967,"timestamp":"2024-06-01T22:43:11.379647Z"}]}
{"channel":"book","type":"update","data":[{"symbol":"ATOM/GBP","bids":[],"asks":[{"price":6.5565,"qty":0.00000000},{"price":6.5752,"qty":129.72000000}],"checksum":2774428539,"timestamp":"2024-06-01T22:43:11.386098Z"}]}
{"channel":"book","type":"update","data":[{"symbol":"ATOM/GBP","bids":[{"price":6.5490,"qty":0.00000000},{"price":6.5277,"qty":63.92000000}],"asks":[],"checksum":416931361,"timestamp":"2024-06-01T22:43:11.386737Z"}]}
{"channel":"book","type":"update","data":[{"symbol":"ATOM/GBP","bids":[{"price":6.5502,"qty":0.00000000},{"price":6.4795,"qty":0.50000000}],"asks":[],"checksum":1633888943,"timestamp":"2024-06-01T22:43:11.390247Z"}]}
{"channel":"book","type":"update","data":[{"symbol":"ATOM/GBP","bids":[],"asks":[{"price":6.5577,"qty":59.81921195}],"checksum":2632833337,"timestamp":"2024-06-01T22:43:11.392152Z"}]}
{"channel":"book","type":"update","data":[{"symbol":"ATOM/GBP","bids":[{"price":6.5500,"qty":59.88825195}],"asks":[],"checksum":402611561,"timestamp":"2024-06-01T22:43:11.392211Z"}]}
{"channel":"book","type":"update","data":[{"symbol":"ATOM/GBP","bids":[{"price":6.5476,"qty":11.96343972}],"asks":[],"checksum":3087843657,"timestamp":"2024-06-01T22:43:11.395262Z"}]}
{"channel":"book","type":"update","data":[{"symbol":"ATOM/GBP","bids":[{"price":6.5491,"qty":0.00000000},{"price":6.5277,"qty":63.92000000}],"asks":[],"checksum":97873387,"timestamp":"2024-06-01T22:43:11.395276Z"}]}
{"channel":"book","type":"update","data":[{"symbol":"ATOM/GBP","bids":[{"price":6.5502,"qty":121.59034712}],"asks":[],"checksum":3033238597,"timestamp":"2024-06-01T22:43:11.395757Z"}]}
{"channel":"book","type":"update","data":[{"symbol":"ATOM/GBP","bids":[{"price":6.5530,"qty":29.93052179}],"asks":[],"checksum":3145932247,"timestamp":"2024-06-01T22:43:11.411503Z"}]}
{"channel":"book","type":"update","data":[{"symbol":"ATOM/GBP","bids":[],"asks":[{"price":6.5576,"qty":29.90976831}],"checksum":3886657176,"timestamp":"2024-06-01T22:43:11.411564Z"}]}
{"channel":"book","type":"update","data":[{"symbol":"ATOM/GBP","bids":[],"asks":[{"price":6.5593,"qty":179.41255162}],"checksum":3408176337,"timestamp":"2024-06-01T22:43:11.416541Z"}]}
{"channel":"book","type":"update","data":[{"symbol":"ATOM/GBP","bids":[],"asks":[{"price":6.5576,"qty":0.00000000},{"price":6.5727,"qty":145.18000000}],"checksum":851768658,"timestamp":"2024-06-01T22:43:11.416778Z"}]}
{"channel":"book","type":"update","data":[{"symbol":"ATOM/GBP","bids":[],"asks":[{"price":6.5578,"qty":0.00000000},{"price":6.5752,"qty":129.72000000}],"checksum":1460768150,"timestamp":"2024-06-01T22:43:11.419674Z"}]}
{"channel":"book","type":"update","data":[{"symbol":"ATOM/GBP","bids":[],"asks":[{"price":6.5593,"qty":0.00000000},{"price":6.6415,"qty":8.33792284}],"checksum":65421855,"timestamp":"2024-06-01T22:43:11.419721Z"}]}
{"channel":"book","type":"update","data":[{"symbol":"ATOM/GBP","bids":[{"price":6.5530,"qty":0.00000000},{"price":6.5313,"qty":1.60193551}],"asks":[],"checksum":1815169906,"timestamp":"2024-06-01T22:43:11.419791Z"}]}
{"channel":"book","type":"update","data":[{"symbol":"ATOM/GBP","bids":[{"price":6.5475,"qty":0.00000000},{"price":6.5277,"qty":63.92000000}],"asks":[],"checksum":708291518,"timestamp":"2024-06-01T22:43:11.419810Z"}]}
{"channel":"book","type":"update","data":[{"symbol":"ATOM/GBP","bids":[{"price":6.5456,"qty":11.96343972}],"asks":[],"checksum":1903274401,"timestamp":"2024-06-01T22:43:11.423083Z"}]}
{"channel":"book","type":"update","data":[{"symbol":"ATOM/GBP","bids":[{"price":6.5476,"qty":0.00000000},{"price":6.5277,"qty":63.92000000}],"asks":[],"checksum":3545985149,"timestamp":"2024-06-01T22:43:11.423365Z"}]}
{"channel":"book","type":"update","data":[{"symbol":"ATOM/GBP","bids":[{"price":6.5500,"qty":0.00000000},{"price":6.5132,"qty":1.54759388}],"asks":[],"checksum":539721334,"timestamp":"2024-06-01T22:43:11.424246Z"}]}
{"channel":"book","type":"update","data":[{"symbol":"ATOM/GBP","bids":[],"asks":[{"price":6.5951,"qty":3.63257048}],"checksum":3636857204,"timestamp":"2024-06-01T22:43:11.424549Z"}]}
{"channel":"book","type":"update","data":[{"symbol":"ATOM/GBP","bids":[{"price":6.5491,"qty":89.84505885}],"asks":[],"checksum":936738299,"timestamp":"2024-06-01T22:43:11.427593Z"}]}
{"channel":"book","type":"update","data":[{"symbol":"ATOM/GBP","bids":[],"asks":[{"price":6.5616,"qty":179.34953976}],"checksum":2708690555,"timestamp":"2024-06-01T22:43:11.427607Z"}]}
{"channel":"book","type":"update","data":[{"symbol":"ATOM/GBP","bids":[],"asks":[{"price":6.5596,"qty":89.70305308}],"checksum":1206000111,"timestamp":"2024-06-01T22:43:11.427715Z"}]}
{"channel":"book","type":"update","data":[{"symbol":"ATOM/GBP","bids":[{"price":6.5492,"qty":11.96343972}],"asks":[],"checksum":2612315732,"timestamp":"2024-06-01T22:43:11.436098Z"}]}
{"channel":"book","type":"update","data":[{"symbol":"ATOM/GBP","bids":[{"price":6.5456,"qty":0.00000000},{"price":6.5277,"qty":63.92000000}],"asks":[],"checksum":3237135435,"timestamp":"2024-06-01T22:43:11.436118Z"}]}
{"channel":"book","type":"update","data":[{"symbol":"ATOM/GBP","bids":[],"asks":[{"price":6.5598,"qty":0.00000000},{"price":6.5752,"qty":129.72000000}],"checksum":467325424,"timestamp":"2024-06-01T22:43:11.496065Z"}]}
{"channel":"book","type":"update","data":[{"symbol":"ATOM/GBP","bids":[],"asks":[{"price":6.5605,"qty":320.29360497}],"checksum":2335343711,"timestamp":"2024-06-01T22:43:11.501897Z"}]}
{"channel":"book","type":"update","data":[{"symbol":"ATOM/GBP","bids":[],"asks":[{"price":6.5550,"qty":29.92182384}],"checksum":3027821269,"timestamp":"2024-06-01T22:43:11.519812Z"}]}
{"channel":"book","type":"update","data":[{"symbol":"ATOM/GBP","bids":[{"price":6.5531,"qty":29.92992885}],"asks":[],"checksum":3601359374,"timestamp":"2024-06-01T22:43:11.519854Z"}]}
{"channel":"book","type":"update","data":[{"symbol":"ATOM/GBP","bids":[],"asks":[{"price":6.5550,"qty":0.00000000},{"price":6.5727,"qty":145.18000000}],"checksum":3923903620,"timestamp":"2024-06-01T22:43:11.524658Z"}]}
{"channel":"book","type":"update","data":[{"symbol":"ATOM/GBP","bids":[{"price":6.5531,"qty":0.00000000},{"price":6.5277,"qty":63.92000000}],"asks":[],"checksum":2335343711,"timestamp":"2024-06-01T22:43:11.524781Z"}]}
{"channel":"book","type":"update","data":[{"symbol":"ATOM/GBP","bids":[],"asks":[{"price":6.5577,"qty":0.00000000},{"price":6.5752,"qty":129.72000000}],"checksum":2736516304,"timestamp":"2024-06-01T22:43:11.546251Z"}]}
{"channel":"book","type":"update","data":[{"symbol":"ATOM/GBP","bids":[],"asks":[{"price":6.5596,"qty":0.00000000},{"price":6.5951,"qty":3.63257048}],"checksum":2945745293,"timestamp":"2024-06-01T22:43:11.550209Z"}]}
{"channel":"book","type":"update","data":[{"symbol":"ATOM/GBP","bids":[],"asks":[{"price":6.5706,"qty":50.00000000}],"checksum":2749131288,"timestamp":"2024-06-01T22:43:11.551427Z"}]}
{"channel":"book","type":"update","data":[{"symbol":"ATOM/GBP","bids":[],"asks":[{"price":6.5547,"qty":29.92307775}],"checksum":3579375687,"timestamp":"2024-06-01T22:43:11.664761Z"}]}
{"channel":"book","type":"update","data":[{"symbol":"ATOM/GBP","bids":[{"price":6.5503,"qty":29.94308762}],"asks":[],"checksum":1295121199,"timestamp":"2024-06-01T22:43:11.664848Z"}]}
{"channel":"book","type":"update","data":[{"symbol":"ATOM/GBP","bids":[],"asks":[{"price":6.5604,"qty":41.85582296}],"checksum":935177544,"timestamp":"2024-06-01T22:43:11.664922Z"}]}
{"channel":"book","type":"update","data":[{"symbol":"ATOM/GBP","bids":[{"price":6.5503,"qty":71.86342949}],"asks":[],"checksum":1728595208,"timestamp":"2024-06-01T22:43:11.665039Z"}]}
{"channel":"book","type":"update","data":[{"symbol":"ATOM/GBP","bids":[{"price":6.5503,"qty":29.94308762}],"asks":[],"checksum":935177544,"timestamp":"2024-06-01T22:43:11.670149Z"}]}
{"channel":"book","type":"update","data":[{"symbol":"ATOM/GBP","bids":[],"asks":[{"price":6.5604,"qty":0.00000000},{"price":6.5727,"qty":145.18000000}],"checksum":1295121199,"timestamp":"2024-06-01T22:43:11.670210Z"}]}
{"channel":"book","type":"update","data":[{"symbol":"ATOM/GBP","bids":[],"asks":[{"price":6.5562,"qty":41.88319863}],"checksum":3540193554,"timestamp":"2024-06-01T22:43:11.885269Z"}]}
{"channel":"book","type":"update","data":[{"symbol":"ATOM/GBP","bids":[{"price":6.5504,"qty":41.91970190}],"asks":[],"checksum":445438701,"timestamp":"2024-06-01T22:43:11.885323Z"}]}
{"channel":"book","type":"update","data":[{"symbol":"ATOM/GBP","bids":[{"price":6.5529,"qty":29.93109330}],"asks":[],"checksum":895131258,"timestamp":"2024-06-01T22:43:11.885346Z"}]}
{"channel":"book","type":"update","data":[{"symbol":"ATOM/GBP","bids":[{"price":6.5504,"qty":0.00000000},{"price":6.5333,"qty":141.35000000}],"asks":[],"checksum":3987189269,"timestamp":"2024-06-01T22:43:11.890450Z"}]}
{"channel":"book","type":"update","data":[{"symbol":"ATOM/GBP","bids":[],"asks":[{"price":6.5576,"qty":59.82018672}],"checksum":388243746,"timestamp":"2024-06-01T22:43:11.894359Z"}]}
{"channel":"book","type":"update","data":[{"symbol":"ATOM/GBP","bids":[],"asks":[{"price":6.5547,"qty":0.00000000},{"price":6.5715,"qty":1.71986848}],"checksum":2099504659,"timestamp":"2024-06-01T22:43:12.383583Z"}]}
{"channel":"book","type":"update","data":[{"symbol":"ATOM/GBP","bids":[{"price":6.5529,"qty":0.00000000},{"price":6.5313,"qty":1.60193551}],"asks":[],"checksum":3897984541,"timestamp":"2024-06-01T22:43:12.383738Z"}]}
{"channel":"book","type":"update","data":[{"symbol":"ATOM/GBP","bids":[],"asks":[{"price":6.5548,"qty":29.92258396}],"checksum":955101642,"timestamp":"2024-06-01T22:43:12.388194Z"}]}
{"channel":"book","type":"update","data":[{"symbol":"ATOM/GBP","bids":[{"price":6.5530,"qty":29.93068918}],"asks":[],"checksum":343034603,"timestamp":"2024-06-01T22:43:12.388235Z"}]}
{"channel":"book","type":"update","data":[{"symbol":"ATOM/GBP","bids":[{"price":6.5504,"qty":41.91970190}],"asks":[],"checksum":1499533286,"timestamp":"2024-06-01T22:43:12.388371Z"}]}
{"channel":"book","type":"update","data":[{"symbol":"ATOM/GBP","bids":[{"price":6.5504,"qty":0.00000000},{"price":6.5333,"qty":141.35000000}],"asks":[],"checksum":343034603,"timestamp":"2024-06-01T22:43:12.392410Z"}]}
{"channel":"book","type":"update","data":[{"symbol":"ATOM/GBP","bids":[{"price":6.5530,"qty":0.00000000},{"price":6.5313,"qty":1.60193551}],"asks":[],"checksum":955101642,"timestamp":"2024-06-01T22:43:12.425136Z"}]}
{"channel":"book","type":"update","data":[{"symbol":"ATOM/GBP","bids":[],"asks":[{"price":6.5548,"qty":0.00000000},{"price":6.5715,"qty":1.71986848}],"checksum":3897984541,"timestamp":"2024-06-01T22:43:12.425175Z"}]}
{"channel":"book","type":"update","data":[{"symbol":"ATOM/GBP","bids":[],"asks":[{"price":6.5562,"qty":0.00000000},{"price":6.5727,"qty":145.18000000}],"checksum":330155213,"timestamp":"2024-06-01T22:43:12.425196Z"}]}
{"channel":"book","type":"update","data":[{"symbol":"ATOM/GBP","bids":[{"price":6.5503,"qty":0.00000000},{"price":6.5277,"qty":63.92000000}],"asks":[],"checksum":2344931237,"timestamp":"2024-06-01T22:43:12.429839Z"}]}
{"channel":"book","type":"update","data":[{"symbol":"ATOM/GBP","bids":[{"price":6.5504,"qty":59.88528844}],"asks":[],"checksum":490732980,"timestamp":"2024-06-01T22:43:12.433910Z"}]}
{"channel":"book","type":"update","data":[{"symbol":"ATOM/GBP","bids":[],"asks":[{"price":6.5575,"qty":41.87431420}],"checksum":462976257,"timestamp":"2024-06-01T22:43:12.433988Z"}]}
{"channel":"book","type":"update","data":[{"symbol":"ATOM/GBP","bids":[],"asks":[{"price":6.5595,"qty":89.70331429}],"checksum":3991621460,"timestamp":"2024-06-01T22:43:12.434052Z"}]}
{"channel":"book","type":"update","data":[{"symbol":"ATOM/GBP","bids":[{"price":6.5504,"qty":0.00000000},{"price":6.5277,"qty":63.92000000}],"asks":[],"checksum":2064678213,"timestamp":"2024-06-01T22:43:12.438334Z"}]}
{"channel":"book","type":"update","data":[{"symbol":"ATOM/GBP","bids":[],"asks":[{"price":6.5575,"qty":0.00000000},{"price":6.5715,"qty":1.71986848}],"checksum":2573481179,"timestamp":"2024-06-01T22:43:12.438434Z"}]}
{"channel":"book","type":"update","data":[{"symbol":"ATOM/GBP","bids":[],"asks":[{"price":6.5575,"qty":29.91022443}],"checksum":865432310,"timestamp":"2024-06-01T22:43:12.515535Z"}]}
{"channel":"book","type":"update","data":[{"symbol":"ATOM/GBP","bids":[{"price":6.5534,"qty":29.92891374}],"asks":[],"checksum":2319024861,"timestamp":"2024-06-01T22:43:12.515675Z"}]}
{"channel":"book","type":"update","data":[{"symbol":"ATOM/GBP","bids":[],"asks":[{"price":6.5575,"qty":0.00000000},{"price":6.5715,"qty":1.71986848}],"checksum":550028528,"timestamp":"2024-06-01T22:43:12.520217Z"}]}
{"channel":"book","type":"update","data":[{"symbol":"ATOM/GBP","bids":[],"asks":[{"price":6.5553,"qty":29.92064441}],"checksum":1601477215,"timestamp":"2024-06-01T22:43:13.742083Z"}]}
{"channel":"book","type":"update","data":[{"symbol":"ATOM/GBP","bids":[{"price":6.5519,"qty":41.90966868}],"asks":[],"checksum":1526479456,"timestamp":"2024-06-01T22:43:13.742107Z"}]}
{"channel":"book","type":"update","data":[{"symbol":"ATOM/GBP","bids":[],"asks":[{"price":6.5575,"qty":41.87431420}],"checksum":497598086,"timestamp":"2024-06-01T22:43:13.742241Z"}]}
{"channel":"book","type":"update","data":[{"symbol":"ATOM/GBP","bids":[{"price":6.5505,"qty":59.88437423}],"asks":[],"checksum":1490998643,"timestamp":"2024-06-01T22:43:13.742388Z"}]}
{"channel":"book","type":"update","data":[{"symbol":"ATOM/GBP","bids":[],"asks":[{"price":6.5575,"qty":0.00000000},{"price":6.5710,"qty":76.15000000}],"checksum":3197455517,"timestamp":"2024-06-01T22:43:13.747095Z"}]}
{"channel":"book","type":"update","data":[{"symbol":"ATOM/GBP","bids":[],"asks":[{"price":6.5568,"qty":41.87906545}],"checksum":3378984747,"timestamp":"2024-06-01T22:43:14.741431Z"}]}
{"channel":"book","type":"update","data":[{"symbol":"ATOM/GBP","bids":[{"price":6.5534,"qty":0.00000000},{"price":6.5333,"qty":141.35000000}],"asks":[],"checksum":3344186511,"timestamp":"2024-06-01T22:43:15.299897Z"}]}
{"channel":"book","type":"update","data":[{"symbol":"ATOM/GBP","bids":[{"price":6.5519,"qty":0.00000000},{"price":6.5313,"qty":1.60193551}],"asks":[],"checksum":1312769264,"timestamp":"2024-06-01T22:43:15.304553Z"}]}
{"channel":"book","type":"update","data":[{"symbol":"ATOM/GBP","bids":[{"price":6.5505,"qty":0.00000000},{"price":6.5277,"qty":63.92000000}],"asks":[],"checksum":2435453378,"timestamp":"2024-06-01T22:43:15.309719Z"}]}
{"channel":"book","type":"update","data":[{"symbol":"ATOM/GBP","bids":[{"price":6.5506,"qty":59.88346005}],"asks":[],"checksum":206039302,"timestamp":"2024-06-01T22:43:15.313829Z"}]}
{"channel":"book","type":"update","data":[{"symbol":"ATOM/GBP","bids":[{"price":6.5535,"qty":29.92827370}],"asks":[],"checksum":45041611,"timestamp":"2024-06-01T22:43:15.313843Z"}]}
{"channel":"book","type":"update","data":[{"symbol":"ATOM/GBP","bids":[{"price":6.5506,"qty":101.80188208}],"asks":[],"checksum":2824647927,"timestamp":"2024-06-01T22:43:15.313856Z"}]}
{"channel":"book","type":"update","data":[{"symbol":"ATOM/GBP","bids":[{"price":6.5506,"qty":41.91842203}],"asks":[],"checksum":3104410124,"timestamp":"2024-06-01T22:43:15.318482Z"}]}
{"channel":"book","type":"update","data":[{"symbol":"ATOM/GBP","bids":[{"price":6.5520,"qty":41.90907897}],"asks":[],"checksum":4279942294,"timestamp":"2024-06-01T22:43:16.741627Z"}]}
{"channel":"book","type":"update","data":[{"symbol":"ATOM/GBP","bids":[],"asks":[{"price":6.5553,"qty":0.00000000},{"price":6.5710,"qty":76.15000000}],"checksum":1829523553,"timestamp":"2024-06-01T22:43:20.929612Z"}]}
{"channel":"book","type":"update","data":[{"symbol":"ATOM/GBP","bids":[],"asks":[{"price":6.5555,"qty":29.91974669}],"checksum":2592628654,"timestamp":"2024-06-01T22:43:20.935244Z"}]}
{"channel":"book","type":"update","data":[{"symbol":"ATOM/GBP","bids":[],"asks":[{"price":6.5576,"qty":0.00000000},{"price":6.5710,"qty":76.15000000}],"checksum":816908176,"timestamp":"2024-06-01T22:43:21.023301Z"}]}
{"channel":"book","type":"update","data":[{"symbol":"ATOM/GBP","bids":[{"price":6.5535,"qty":0.00000000},{"price":6.5333,"qty":141.35000000}],"asks":[],"checksum":2171503034,"timestamp":"2024-06-01T22:43:21.023315Z"}]}
{"channel":"book","type":"update","data":[{"symbol":"ATOM/GBP","bids":[{"price":6.5520,"qty":0.00000000},{"price":6.5313,"qty":1.60193551}],"asks":[],"checksum":3577863214,"timestamp":"2024-06-01T22:43:21.027755Z"}]}
{"channel":"book","type":"update","data":[{"symbol":"ATOM/GBP","bids":[{"price":6.5536,"qty":29.92793978}],"asks":[],"checksum":775017937,"timestamp":"2024-06-01T22:43:21.032556Z"}]}
{"channel":"book","type":"update","data":[{"symbol":"ATOM/GBP","bids":[],"asks":[{"price":6.5584,"qty":59.81243852}],"checksum":2372873954,"timestamp":"2024-06-01T22:43:21.032571Z"}]}
{"channel":"book","type":"update","data":[{"symbol":"ATOM/GBP","bids":[{"price":6.5521,"qty":41.90882547}],"asks":[],"checksum":581003135,"timestamp":"2024-06-01T22:43:21.032725Z"}]}
{"channel":"book","type":"update","data":[{"symbol":"ATOM/GBP","bids":[],"asks":[{"price":6.5605,"qty":0.00000000},{"price":6.5710,"qty":76.15000000}],"checksum":2153744795,"timestamp":"2024-06-01T22:43:21.115938Z"}]}
{"channel":"book","type":"update","data":[{"symbol":"ATOM/GBP","bids":[],"asks":[{"price":6.5613,"qty":234.40610497}],"checksum":2149021840,"timestamp":"2024-06-01T22:43:21.121579Z"}]}
{"channel":"book","type":"update","data":[{"symbol":"ATOM/GBP","bids":[],"asks":[{"price":6.5555,"qty":0.00000000},{"price":6.5710,"qty":76.15000000}],"checksum":3595940196,"timestamp":"2024-06-01T22:43:21.346299Z"}]}
{"channel":"book","type":"update","data":[{"symbol":"ATOM/GBP","bids":[{"price":6.5536,"qty":0.00000000},{"price":6.5333,"qty":141.35000000}],"asks":[],"checksum":2291516478,"timestamp":"2024-06-01T22:43:21.346446Z"}]}
{"channel":"book","type":"update","data":[{"symbol":"ATOM/GBP","bids":[{"price":6.5521,"qty":0.00000000},{"price":6.5313,"qty":1.60193551}],"asks":[],"checksum":3276688727,"timestamp":"2024-06-01T22:43:21.353306Z"}]}
{"channel":"book","type":"update","data":[{"symbol":"ATOM/GBP","bids":[{"price":6.5506,"qty":0.00000000},{"price":6.5277,"qty":63.92000000}],"asks":[],"checksum":1217280957,"timestamp":"2024-06-01T22:43:21.357807Z"}]}
{"channel":"book","type":"update","data":[{"symbol":"ATOM/GBP","bids":[{"price":6.5538,"qty":29.92698535}],"asks":[],"checksum":4286990571,"timestamp":"2024-06-01T22:43:21.364391Z"}]}
{"channel":"book","type":"update","data":[{"symbol":"ATOM/GBP","bids":[],"asks":[{"price":6.5557,"qty":29.91861898}],"checksum":4163301142,"timestamp":"2024-06-01T22:43:21.364411Z"}]}
{"channel":"book","type":"update","data":[{"symbol":"ATOM/GBP","bids":[{"price":6.5507,"qty":41.91778212}],"asks":[],"checksum":54097334,"timestamp":"2024-06-01T22:43:21.364485Z"}]}
{"channel":"book","type":"update","data":[{"symbol":"ATOM/GBP","bids":[{"price":6.5507,"qty":101.80032801}],"asks":[],"checksum":2315475218,"timestamp":"2024-06-01T22:43:21.364531Z"}]}
{"channel":"book","type":"update","data":[{"symbol":"ATOM/GBP","bids":[{"price":6.5507,"qty":41.91778212}],"asks":[],"checksum":54097334,"timestamp":"2024-06-01T22:43:21.369737Z"}]}
{"channel":"book","type":"update","data":[{"symbol":"ATOM/GBP","bids":[],"asks":[{"price":6.5557,"qty":0.00000000},{"price":6.5710,"qty":76.15000000}],"checksum":3224525744,"timestamp":"2024-06-01T22:43:21.443404Z"}]}
{"channel":"book","type":"update","data":[{"symbol":"ATOM/GBP","bids":[{"price":6.5538,"qty":0.00000000},{"price":6.5313,"qty":1.60193551}],"asks":[],"checksum":492751077,"timestamp":"2024-06-01T22:43:21.649943Z"}]}
{"channel":"book","type":"update","data":[{"symbol":"ATOM/GBP","bids":[{"price":6.5536,"qty":29.92766141}],"asks":[],"checksum":3307371941,"timestamp":"2024-06-01T22:43:21.654201Z"}]}
{"channel":"book","type":"update","data":[{"symbol":"ATOM/GBP","bids":[],"asks":[{"price":6.5556,"qty":29.91913961}],"checksum":1134009509,"timestamp":"2024-06-01T22:43:21.654235Z"}]}
{"channel":"book","type":"update","data":[{"symbol":"ATOM/GBP","bids":[{"price":6.5508,"qty":41.91714223}],"asks":[],"checksum":4031117592,"timestamp":"2024-06-01T22:43:21.654334Z"}]}
{"channel":"book","type":"update","data":[{"symbol":"ATOM/GBP","bids":[{"price":6.5508,"qty":0.00000000},{"price":6.5333,"qty":141.35000000}],"asks":[],"checksum":1134009509,"timestamp":"2024-06-01T22:43:21.658563Z"}]}
{"channel":"book","type":"update","data":[{"symbol":"ATOM/GBP","bids":[],"asks":[{"price":6.5556,"qty":0.00000000},{"price":6.5710,"qty":76.15000000}],"checksum":3307371941,"timestamp":"2024-06-01T22:43:21.890253Z"}]}
{"channel":"book","type":"update","data":[{"symbol":"ATOM/GBP","bids":[{"price":6.5521,"qty":41.90827391}],"asks":[],"checksum":1950773661,"timestamp":"2024-06-01T22:43:21.894636Z"}]}
{"channel":"book","type":"update","data":[{"symbol":"ATOM/GBP","bids":[],"asks":[{"price":6.5555,"qty":29.91946277}],"checksum":2200757295,"timestamp":"2024-06-01T22:43:21.894688Z"}]}
{"channel":"book","type":"update","data":[{"symbol":"ATOM/GBP","bids":[],"asks":[{"price":6.5555,"qty":0.00000000},{"price":6.5710,"qty":76.15000000}],"checksum":1950773661,"timestamp":"2024-06-01T22:43:21.985959Z"}]}
{"channel":"book","type":"update","data":[{"symbol":"ATOM/GBP","bids":[],"asks":[{"price":6.5568,"qty":0.00000000},{"price":6.5715,"qty":1.71986848}],"checksum":3308830110,"timestamp":"2024-06-01T22:43:22.141874Z"}]}
{"channel":"book","type":"update","data":[{"symbol":"ATOM/GBP","bids":[{"price":6.5536,"qty":0.00000000},{"price":6.5333,"qty":141.35000000}],"asks":[],"checksum":3041570717,"timestamp":"2024-06-01T22:43:22.141924Z"}]}
{"channel":"book","type":"update","data":[{"symbol":"ATOM/GBP","bids":[{"price":6.5521,"qty":0.00000000},{"price":6.5313,"qty":1.60193551}],"asks":[],"checksum":2887779558,"timestamp":"2024-06-01T22:43:22.146704Z"}]}
{"channel":"book","type":"update","data":[{"symbol":"ATOM/GBP","bids":[{"price":6.5507,"qty":0.00000000},{"price":6.5277,"qty":63.92000000}],"asks":[],"checksum":4193318846,"timestamp":"2024-06-01T22:43:22.150549Z"}]}
{"channel":"book","type":"update","data":[{"symbol":"ATOM/GBP","bids":[],"asks":[{"price":6.5583,"qty":41.86920625}],"checksum":836164027,"timestamp":"2024-06-01T22:43:22.154609Z"}]}
{"channel":"book","type":"update","data":[{"symbol":"ATOM/GBP","bids":[],"asks":[{"price":6.5558,"qty":29.91817525}],"checksum":1404119332,"timestamp":"2024-06-01T22:43:22.154694Z"}]}
{"channel":"book","type":"update","data":[{"symbol":"ATOM/GBP","bids":[{"price":6.5508,"qty":41.91714223}],"asks":[],"checksum":1420253154,"timestamp":"2024-06-01T22:43:22.154719Z"}]}
{"channel":"book","type":"update","data":[{"symbol":"ATOM/GBP","bids":[{"price":6.5508,"qty":101.79877400}],"asks":[],"checksum":2538299410,"timestamp":"2024-06-01T22:43:22.154743Z"}]}
{"channel":"book","type":"update","data":[{"symbol":"ATOM/GBP","bids":[{"price":6.5539,"qty":29.92654115}],"asks":[],"checksum":92641726,"timestamp":"2024-06-01T22:43:22.154779Z"}]}
{"channel":"book","type":"update","data":[{"symbol":"ATOM/GBP","bids":[{"price":6.5508,"qty":41.91714223}],"asks":[],"checksum":2538825891,"timestamp":"2024-06-01T22:43:22.160320Z"}]}
{"channel":"book","type":"update","data":[{"symbol":"ATOM/GBP","bids":[],"asks":[{"price":6.5583,"qty":0.00000000},{"price":6.5710,"qty":76.15000000}],"checksum":4240955532,"timestamp":"2024-06-01T22:43:22.160482Z"}]}
{"channel":"book","type":"update","data":[{"symbol":"ATOM/GBP","bids":[],"asks":[{"price":6.5558,"qty":0.00000000},{"price":6.5715,"qty":1.71986848}],"checksum":2267239207,"timestamp":"2024-06-01T22:43:22.874388Z"}]}
{"channel":"book","type":"update","data":[{"symbol":"ATOM/GBP","bids":[],"asks":[{"price":6.5573,"qty":41.87590262}],"checksum":2364149192,"timestamp":"2024-06-01T22:43:22.878701Z"}]}
{"channel":"book","type":"update","data":[{"symbol":"ATOM/GBP","bids":[],"asks":[{"price":6.5557,"qty":29.91848305}],"checksum":2021661091,"timestamp":"2024-06-01T22:43:22.878727Z"}]}
{"channel":"book","type":"update","data":[{"symbol":"ATOM/GBP","bids":[{"price":6.5524,"qty":41.90670519}],"asks":[],"checksum":675802986,"timestamp":"2024-06-01T22:43:22.878742Z"}]}
{"channel":"book","type":"update","data":[{"symbol":"ATOM/GBP","bids":[],"asks":[{"price":6.5573,"qty":0.00000000},{"price":6.5710,"qty":76.15000000}],"checksum":3834900864,"timestamp":"2024-06-01T22:43:22.882689Z"}]}
{"channel":"book","type":"update","data":[{"symbol":"ATOM/GBP","bids":[],"asks":[{"price":6.5572,"qty":41.87634458}],"checksum":1705863826,"timestamp":"2024-06-01T22:43:23.741921Z"}]}
{"channel":"book","type":"update","data":[{"symbol":"ATOM/GBP","bids":[],"asks":[{"price":6.5557,"qty":0.00000000},{"price":6.5710,"qty":76.15000000}],"checksum":745446674,"timestamp":"2024-06-01T22:43:25.066688Z"}]}
{"channel":"book","type":"update","data":[{"symbol":"ATOM/GBP","bids":[{"price":6.5539,"qty":0.00000000},{"price":6.5333,"qty":141.35000000}],"asks":[],"checksum":3131024429,"timestamp":"2024-06-01T22:43:25.066837Z"}]}
{"channel":"book","type":"update","data":[{"symbol":"ATOM/GBP","bids":[{"price":6.5455,"qty":0.00000000},{"price":6.5313,"qty":1.60193551}],"asks":[],"checksum":3955895155,"timestamp":"2024-06-01T22:43:25.066918Z"}]}
{"channel":"book","type":"update","data":[{"symbol":"ATOM/GBP","bids":[{"price":6.5524,"qty":0.00000000},{"price":6.5277,"qty":63.92000000}],"asks":[],"checksum":2339100498,"timestamp":"2024-06-01T22:43:25.071897Z"}]}
{"channel":"book","type":"update","data":[{"symbol":"ATOM/GBP","bids":[{"price":6.5508,"qty":0.00000000},{"price":6.4795,"qty":0.50000000}],"asks":[],"checksum":3972439938,"timestamp":"2024-06-01T22:43:25.076291Z"}]}
{"channel":"book","type":"update","data":[{"symbol":"ATOM/GBP","bids":[{"price":6.5143,"qty":1.54725595}],"asks":[],"checksum":362536747,"timestamp":"2024-06-01T22:43:25.078605Z"}]}
{"channel":"book","type":"update","data":[{"symbol":"ATOM/GBP","bids":[],"asks":[{"price":6.5560,"qty":29.91742012}],"checksum":561584641,"timestamp":"2024-06-01T22:43:25.080506Z"}]}
{"channel":"book","type":"update","data":[{"symbol":"ATOM/GBP","bids":[{"price":6.5509,"qty":59.88071767}],"asks":[],"checksum":3944397579,"timestamp":"2024-06-01T22:43:25.080609Z"}]}
{"channel":"book","type":"update","data":[{"symbol":"ATOM/GBP","bids":[{"price":6.5476,"qty":179.73009327}],"asks":[],"checksum":2225684459,"timestamp":"2024-06-01T22:43:25.080623Z"}]}
{"channel":"book","type":"update","data":[{"symbol":"ATOM/GBP","bids":[{"price":6.5509,"qty":101.79722004}],"asks":[],"checksum":400473419,"timestamp":"2024-06-01T22:43:25.080671Z"}]}
{"channel":"book","type":"update","data":[{"symbol":"ATOM/GBP","bids":[{"price":6.5541,"qty":29.92573609}],"asks":[],"checksum":1615328783,"timestamp":"2024-06-01T22:43:25.080741Z"}]}
{"channel":"book","type":"update","data":[{"symbol":"ATOM/GBP","bids":[{"price":6.5509,"qty":41.91650237}],"asks":[],"checksum":23760437,"timestamp":"2024-06-01T22:43:25.085785Z"}]}
{"channel":"book","type":"update","data":[{"symbol":"ATOM/GBP","bids":[{"price":6.5541,"qty":0.00000000},{"price":6.5313,"qty":1.60193551}],"asks":[],"checksum":3775459864,"timestamp":"2024-06-01T22:43:25.114932Z"}]}
{"channel":"book","type":"update","data":[{"symbol":"ATOM/GBP","bids":[{"price":6.5509,"qty":0.00000000},{"price":6.5277,"qty":63.92000000}],"asks":[],"checksum":3707677899,"timestamp":"2024-06-01T22:43:25.119449Z"}]}
{"channel":"book","type":"update","data":[{"symbol":"ATOM/GBP","bids":[{"price":6.5541,"qty":29.92547888}],"asks":[],"checksum":2669670633,"timestamp":"2024-06-01T22:43:25.198420Z"}]}
{"channel":"book","type":"update","data":[{"symbol":"ATOM/GBP","bids":[{"price":6.5541,"qty":0.00000000},{"price":6.5277,"qty":63.92000000}],"asks":[],"checksum":3707677899,"timestamp":"2024-06-01T22:43:25.213202Z"}]}
{"channel":"book","type":"update","data":[{"symbol":"ATOM/GBP","bids":[{"price":6.5503,"qty":41.92034187}],"asks":[],"checksum":2853772196,"timestamp":"2024-06-01T22:43:25.288489Z"}]}
{"channel":"book","type":"update","data":[{"symbol":"ATOM/GBP","bids":[{"price":6.5503,"qty":0.00000000},{"price":6.5277,"qty":63.92000000}],"asks":[],"checksum":3707677899,"timestamp":"2024-06-01T22:43:25.293224Z"}]}
{"channel":"book","type":"update","data":[{"symbol":"ATOM/GBP","bids":[],"asks":[{"price":6.5560,"qty":0.00000000},{"price":6.5710,"qty":76.15000000}],"checksum":1486578238,"timestamp":"2024-06-01T22:43:25.641420Z"}]}
{"channel":"book","type":"update","data":[{"symbol":"ATOM/GBP","bids":[],"asks":[{"price":6.5559,"qty":29.91761778}],"checksum":360816882,"timestamp":"2024-06-01T22:43:25.646192Z"}]}
{"channel":"book","type":"update","data":[{"symbol":"ATOM/GBP","bids":[{"price":6.5525,"qty":41.90583035}],"asks":[],"checksum":3514807812,"timestamp":"2024-06-01T22:43:25.646296Z"}]}
{"channel":"book","type":"update","data":[{"symbol":"ATOM/GBP","bids":[{"price":6.5540,"qty":29.92593381}],"asks":[],"checksum":2202814688,"timestamp":"2024-06-01T22:43:25.646317Z"}]}
{"channel":"book","type":"update","data":[{"symbol":"ATOM/GBP","bids":[{"price":6.5510,"qty":59.87980360}],"asks":[],"checksum":1413867802,"timestamp":"2024-06-01T22:43:25.646466Z"}]}
{"channel":"book","type":"update","data":[{"symbol":"ATOM/GBP","bids":[{"price":6.5540,"qty":0.00000000},{"price":6.5333,"qty":141.35000000}],"asks":[],"checksum":2902884470,"timestamp":"2024-06-01T22:43:26.127357Z"}]}
{"channel":"book","type":"update","data":[{"symbol":"ATOM/GBP","bids":[],"asks":[{"price":6.5572,"qty":0.00000000},{"price":6.5710,"qty":76.15000000}],"checksum":1581174693,"timestamp":"2024-06-01T22:43:26.127399Z"}]}
{"channel":"book","type":"update","data":[{"symbol":"ATOM/GBP","bids":[],"asks":[{"price":6.5559,"qty":0.00000000},{"price":6.5715,"qty":1.71986848}],"checksum":2665516759,"timestamp":"2024-06-01T22:43:26.127475Z"}]}
{"channel":"book","type":"update","data":[{"symbol":"ATOM/GBP","bids":[{"price":6.5525,"qty":0.00000000},{"price":6.5313,"qty":1.60193551}],"asks":[],"checksum":3417381788,"timestamp":"2024-06-01T22:43:26.132827Z"}]}
{"channel":"book","type":"update","data":[{"symbol":"ATOM/GBP","bids":[],"asks":[{"price":6.5562,"qty":29.91650172}],"checksum":2181841182,"timestamp":"2024-06-01T22:43:26.137278Z"}]}
{"channel":"book","type":"update","data":[{"symbol":"ATOM/GBP","bids":[],"asks":[{"price":6.5583,"qty":41.86920625}],"checksum":2112723534,"timestamp":"2024-06-01T22:43:26.137331Z"}]}
{"channel":"book","type":"update","data":[{"symbol":"ATOM/GBP","bids":[{"price":6.5510,"qty":0.00000000},{"price":6.5277,"qty":63.92000000}],"asks":[],"checksum":1187931469,"timestamp":"2024-06-01T22:43:26.137403Z"}]}
{"channel":"book","type":"update","data":[{"symbol":"ATOM/GBP","bids":[{"price":6.5543,"qty":29.92481743}],"asks":[],"checksum":3495192449,"timestamp":"2024-06-01T22:43:26.137540Z"}]}
{"channel":"book","type":"update","data":[{"symbol":"ATOM/GBP","bids":[{"price":6.5526,"qty":41.90562759}],"asks":[],"checksum":904705125,"timestamp":"2024-06-01T22:43:26.137591Z"}]}
{"channel":"book","type":"update","data":[{"symbol":"ATOM/GBP","bids":[{"price":6.5526,"qty":0.00000000},{"price":6.5313,"qty":1.60193551}],"asks":[],"checksum":3495192449,"timestamp":"2024-06-01T22:43:26.143822Z"}]}
{"channel":"book","type":"update","data":[{"symbol":"ATOM/GBP","bids":[],"asks":[{"price":6.5583,"qty":0.00000000},{"price":6.5710,"qty":76.15000000}],"checksum":800439505,"timestamp":"2024-06-01T22:43:26.143915Z"}]}
{"channel":"book","type":"update","data":[{"symbol":"ATOM/GBP","bids":[{"price":6.5513,"qty":59.87630122}],"asks":[],"checksum":2430508828,"timestamp":"2024-06-01T22:43:26.147644Z"}]}
{"channel":"book","type":"update","data":[{"symbol":"ATOM/GBP","bids":[],"asks":[{"price":6.5577,"qty":41.87358456}],"checksum":2210123957,"timestamp":"2024-06-01T22:43:27.742847Z"}]}
{"channel":"book","type":"update","data":[{"symbol":"ATOM/GBP","bids":[{"price":6.5528,"qty":41.90426707}],"asks":[],"checksum":299237160,"timestamp":"2024-06-01T22:43:27.742894Z"}]}
