{"channel":"book","type":"snapshot","data":[{"symbol":"ATOM/EUR","bids":[{"price":7.7010,"qty":21.00000000},{"price":7.7008,"qty":299.23937567},{"price":7.6994,"qty":221.22262370},{"price":7.6993,"qty":136.16119736},{"price":7.6990,"qty":53.87347990},{"price":7.6989,"qty":897.93523478},{"price":7.6986,"qty":221.22262370},{"price":7.6981,"qty":200.00000000},{"price":7.6970,"qty":11.96343972},{"price":7.6969,"qty":2.39436774}],"asks":[{"price":7.7028,"qty":299.16481469},{"price":7.7039,"qty":21.00000000},{"price":7.7044,"qty":897.29936211},{"price":7.7054,"qty":53.87347220},{"price":7.7060,"qty":1196.15623746},{"price":7.7063,"qty":545.14448000},{"price":7.7068,"qty":200.00000000},{"price":7.7070,"qty":221.22262370},{"price":7.7073,"qty":1195.96317371},{"price":7.7076,"qty":120.60110497}],"checksum":100371669}]}
{"channel":"book","type":"update","data":[{"symbol":"ATOM/EUR","bids":[{"price":7.7009,"qty":221.22262370}],"asks":[],"checksum":3062604855,"timestamp":"2024-06-01T22:43:07.716878Z"}]}
{"channel":"book","type":"update","data":[{"symbol":"ATOM/EUR","bids":[{"price":7.6994,"qty":0.00000000},{"price":7.6969,"qty":2.39436774}],"asks":[],"checksum":3325120622,"timestamp":"2024-06-01T22:43:07.720254Z"}]}
{"channel":"book","type":"update","data":[{"symbol":"ATOM/EUR","bids":[{"price":7.7008,"qty":0.00000000},{"price":7.6968,"qty":1197.56566591}],"asks":[],"checksum":1281990890,"timestamp":"2024-06-01T22:43:09.612550Z"}]}
{"channel":"book","type":"update","data":[{"symbol":"ATOM/EUR","bids":[{"price":7.7006,"qty":299.24487247}],"asks":[],"checksum":490256589,"timestamp":"2024-06-01T22:43:09.616755Z"}]}
{"channel":"book","type":"update","data":[{"symbol":"ATOM/EUR","bids":[{"price":7.7009,"qty":0.00000000},{"price":7.6968,"qty":1197.56566591}],"asks":[],"checksum":3060906336,"timestamp":"2024-06-01T22:43:09.616872Z"}]}
{"channel":"book","type":"update","data":[{"symbol":"ATOM/EUR","bids":[{"price":7.6994,"qty":221.22262370}],"asks":[],"checksum":1153336820,"timestamp":"2024-06-01T22:43:09.617092Z"}]}
{"channel":"book","type":"update","data":[{"symbol":"ATOM/EUR","bids":[{"price":7.7007,"qty":221.22262370}],"asks":[],"checksum":3746679091,"timestamp":"2024-06-01T22:43:09.716940Z"}]}
{"channel":"book","type":"update","data":[{"symbol":"ATOM/EUR","bids":[{"price":7.6994,"qty":0.00000000},{"price":7.6969,"qty":2.39436774}],"asks":[],"checksum":3217427520,"timestamp":"2024-06-01T22:43:09.721652Z"}]}
{"channel":"book","type":"update","data":[{"symbol":"ATOM/EUR","bids":[{"price":7.7006,"qty":0.00000000},{"price":7.6968,"qty":1197.56566591}],"asks":[],"checksum":3754074563,"timestamp":"2024-06-01T22:43:11.291717Z"}]}
{"channel":"book","type":"update","data":[{"symbol":"ATOM/EUR","bids":[{"price":7.7007,"qty":520.46535496}],"asks":[],"checksum":279709662,"timestamp":"2024-06-01T22:43:11.296816Z"}]}
{"channel":"book","type":"update","data":[{"symbol":"ATOM/EUR","bids":[{"price":7.7007,"qty":299.24273126}],"asks":[],"checksum":3652196048,"timestamp":"2024-06-01T22:43:11.296993Z"}]}
{"channel":"book","type":"update","data":[{"symbol":"ATOM/EUR","bids":[{"price":7.6994,"qty":221.22262370}],"asks":[],"checksum":895931426,"timestamp":"2024-06-01T22:43:11.297291Z"}]}
{"channel":"book","type":"update","data":[{"symbol":"ATOM/EUR","bids":[{"price":7.7007,"qty":0.00000000},{"price":7.6968,"qty":1197.56566591}],"asks":[],"checksum":473121539,"timestamp":"2024-06-01T22:43:11.301401Z"}]}
{"channel":"book","type":"update","data":[{"symbol":"ATOM/EUR","bids":[],"asks":[{"price":7.7028,"qty":0.00000000},{"price":7.7080,"qty":598.30000000}],"checksum":255926236,"timestamp":"2024-06-01T22:43:11.301446Z"}]}
{"channel":"book","type":"update","data":[{"symbol":"ATOM/EUR","bids":[{"price":7.7010,"qty":0.00000000},{"price":7.6952,"qty":1197.81417167}],"asks":[],"checksum":4206137193,"timestamp":"2024-06-01T22:43:11.304574Z"}]}
{"channel":"book","type":"update","data":[{"symbol":"ATOM/EUR","bids":[{"price":7.6996,"qty":21.00000000}],"asks":[],"checksum":2216138483,"timestamp":"2024-06-01T22:43:11.304654Z"}]}
{"channel":"book","type":"update","data":[{"symbol":"ATOM/EUR","bids":[],"asks":[{"price":7.7030,"qty":299.15703463}],"checksum":2371149375,"timestamp":"2024-06-01T22:43:11.306812Z"}]}
{"channel":"book","type":"update","data":[{"symbol":"ATOM/EUR","bids":[],"asks":[{"price":7.7070,"qty":0.00000000},{"price":7.7080,"qty":598.30000000}],"checksum":1297805092,"timestamp":"2024-06-01T22:43:11.361103Z"}]}
{"channel":"book","type":"update","data":[{"symbol":"ATOM/EUR","bids":[],"asks":[{"price":7.7030,"qty":0.00000000},{"price":7.7094,"qty":299.24487247}],"checksum":1335192167,"timestamp":"2024-06-01T22:43:11.365989Z"}]}
{"channel":"book","type":"update","data":[{"symbol":"ATOM/EUR","bids":[],"asks":[{"price":7.7044,"qty":0.00000000},{"price":7.7099,"qty":1195.56118799}],"checksum":1035966868,"timestamp":"2024-06-01T22:43:11.366010Z"}]}
{"channel":"book","type":"update","data":[{"symbol":"ATOM/EUR","bids":[],"asks":[{"price":7.7068,"qty":0.00000000},{"price":7.7109,"qty":1669.51760000}],"checksum":1484883051,"timestamp":"2024-06-01T22:43:11.366975Z"}]}
{"channel":"book","type":"update","data":[{"symbol":"ATOM/EUR","bids":[],"asks":[{"price":7.7039,"qty":0.00000000},{"price":7.7110,"qty":944.58200000}],"checksum":4048556882,"timestamp":"2024-06-01T22:43:11.369052Z"}]}
{"channel":"book","type":"update","data":[{"symbol":"ATOM/EUR","bids":[],"asks":[{"price":7.7052,"qty":21.00000000}],"checksum":1084117178,"timestamp":"2024-06-01T22:43:11.369339Z"}]}
{"channel":"book","type":"update","data":[{"symbol":"ATOM/EUR","bids":[{"price":7.6990,"qty":77.80710860}],"asks":[],"checksum":2073845539,"timestamp":"2024-06-01T22:43:11.369991Z"}]}
{"channel":"book","type":"update","data":[{"symbol":"ATOM/EUR","bids":[{"price":7.6995,"qty":200.00000000}],"asks":[],"checksum":4106144835,"timestamp":"2024-06-01T22:43:11.371739Z"}]}
{"channel":"book","type":"update","data":[{"symbol":"ATOM/EUR","bids":[],"asks":[{"price":7.7060,"qty":0.00000000},{"price":7.7110,"qty":944.58200000}],"checksum":1999926016,"timestamp":"2024-06-01T22:43:11.373729Z"}]}
{"channel":"book","type":"update","data":[{"symbol":"ATOM/EUR","bids":[{"price":7.6989,"qty":0.00000000},{"price":7.6968,"qty":1197.56566591}],"asks":[],"checksum":3017642823,"timestamp":"2024-06-01T22:43:11.373798Z"}]}
{"channel":"book","type":"update","data":[{"symbol":"ATOM/EUR","bids":[],"asks":[{"price":7.7076,"qty":0.00000000},{"price":7.7119,"qty":598.10000000}],"checksum":2323104546,"timestamp":"2024-06-01T22:43:11.376952Z"}]}
{"channel":"book","type":"update","data":[{"symbol":"ATOM/EUR","bids":[{"price":7.6993,"qty":0.00000000},{"price":7.6933,"qty":1198.12028524}],"asks":[],"checksum":724515846,"timestamp":"2024-06-01T22:43:11.376983Z"}]}
{"channel":"book","type":"update","data":[{"symbol":"ATOM/EUR","bids":[],"asks":[{"price":7.7080,"qty":0.00000000},{"price":7.7138,"qty":1.82601092},{"price":7.7093,"qty":598.30000000}],"checksum":4193809635,"timestamp":"2024-06-01T22:43:11.377329Z"}]}
{"channel":"book","type":"update","data":[{"symbol":"ATOM/EUR","bids":[],"asks":[{"price":7.7111,"qty":1195.37245673}],"checksum":1624423767,"timestamp":"2024-06-01T22:43:11.380403Z"}]}
{"channel":"book","type":"update","data":[{"symbol":"ATOM/EUR","bids":[{"price":7.6997,"qty":897.84708565}],"asks":[],"checksum":829402145,"timestamp":"2024-06-01T22:43:11.380444Z"}]}
{"channel":"book","type":"update","data":[{"symbol":"ATOM/EUR","bids":[],"asks":[{"price":7.7049,"qty":897.24250278}],"checksum":2899614379,"timestamp":"2024-06-01T22:43:11.380486Z"}]}
{"channel":"book","type":"update","data":[{"symbol":"ATOM/EUR","bids":[{"price":7.6980,"qty":1197.38595507}],"asks":[],"checksum":3349185889,"timestamp":"2024-06-01T22:43:11.380510Z"}]}
{"channel":"book","type":"update","data":[{"symbol":"ATOM/EUR","bids":[],"asks":[{"price":7.7086,"qty":204.91110497}],"checksum":3158656254,"timestamp":"2024-06-01T22:43:11.381521Z"}]}
{"channel":"book","type":"update","data":[{"symbol":"ATOM/EUR","bids":[{"price":7.7002,"qty":109.94769324}],"asks":[],"checksum":4052816737,"timestamp":"2024-06-01T22:43:11.381654Z"}]}
{"channel":"book","type":"update","data":[{"symbol":"ATOM/EUR","bids":[{"price":7.6996,"qty":0.00000000},{"price":7.6969,"qty":2.39436774}],"asks":[],"checksum":2173664284,"timestamp":"2024-06-01T22:43:11.383516Z"}]}
{"channel":"book","type":"update","data":[{"symbol":"ATOM/EUR","bids":[{"price":7.6999,"qty":21.00000000}],"asks":[],"checksum":1501315916,"timestamp":"2024-06-01T22:43:11.383623Z"}]}
{"channel":"book","type":"update","data":[{"symbol":"ATOM/EUR","bids":[],"asks":[{"price":7.7052,"qty":0.00000000},{"price":7.7110,"qty":944.58200000}],"checksum":4261491438,"timestamp":"2024-06-01T22:43:11.383675Z"}]}
{"channel":"book","type":"update","data":[{"symbol":"ATOM/EUR","bids":[],"asks":[{"price":7.7047,"qty":21.00000000}],"checksum":2486544311,"timestamp":"2024-06-01T22:43:11.383908Z"}]}
{"channel":"book","type":"update","data":[{"symbol":"ATOM/EUR","bids":[{"price":7.6990,"qty":53.87347990}],"asks":[],"checksum":1671325330,"timestamp":"2024-06-01T22:43:11.384037Z"}]}
{"channel":"book","type":"update","data":[{"symbol":"ATOM/EUR","bids":[{"price":7.6994,"qty":245.15579807}],"asks":[],"checksum":2563318181,"timestamp":"2024-06-01T22:43:11.384124Z"}]}
{"channel":"book","type":"update","data":[{"symbol":"ATOM/EUR","bids":[{"price":7.7004,"qty":21.00000000}],"asks":[],"checksum":792672752,"timestamp":"2024-06-01T22:43:11.384844Z"}]}
{"channel":"book","type":"update","data":[{"symbol":"ATOM/EUR","bids":[{"price":7.6999,"qty":0.00000000},{"price":7.6970,"qty":11.96343972}],"asks":[],"checksum":1561180616,"timestamp":"2024-06-01T22:43:11.384865Z"}]}
{"channel":"book","type":"update","data":[{"symbol":"ATOM/EUR","bids":[{"price":7.6997,"qty":0.00000000},{"price":7.6969,"qty":2.39436774}],"asks":[],"checksum":2827523283,"timestamp":"2024-06-01T22:43:11.387082Z"}]}
{"channel":"book","type":"update","data":[{"symbol":"ATOM/EUR","bids":[],"asks":[{"price":7.7049,"qty":0.00000000},{"price":7.7110,"qty":944.58200000}],"checksum":2299279767,"timestamp":"2024-06-01T22:43:11.387137Z"}]}
{"channel":"book","type":"update","data":[{"symbol":"ATOM/EUR","bids":[{"price":7.6994,"qty":221.22262370}],"asks":[],"checksum":1709708219,"timestamp":"2024-06-01T22:43:11.387317Z"}]}
{"channel":"book","type":"update","data":[{"symbol":"ATOM/EUR","bids":[],"asks":[{"price":7.7054,"qty":0.00000000},{"price":7.7111,"qty":1195.37245673}],"checksum":2567675768,"timestamp":"2024-06-01T22:43:11.409077Z"}]}
{"channel":"book","type":"update","data":[{"symbol":"ATOM/EUR","bids":[],"asks":[{"price":7.7046,"qty":299.09202318}],"checksum":1214463157,"timestamp":"2024-06-01T22:43:11.411869Z"}]}
{"channel":"book","type":"update","data":[{"symbol":"ATOM/EUR","bids":[],"asks":[{"price":7.7047,"qty":0.00000000},{"price":7.7111,"qty":1195.37245673}],"checksum":3054794404,"timestamp":"2024-06-01T22:43:11.411962Z"}]}
{"channel":"book","type":"update","data":[{"symbol":"ATOM/EUR","bids":[],"asks":[{"price":7.7061,"qty":21.00000000}],"checksum":3307800066,"timestamp":"2024-06-01T22:43:11.412023Z"}]}
{"channel":"book","type":"update","data":[{"symbol":"ATOM/EUR","bids":[{"price":7.7020,"qty":299.19259137}],"asks":[],"checksum":51175163,"timestamp":"2024-06-01T22:43:11.412586Z"}]}
{"channel":"book","type":"update","data":[{"symbol":"ATOM/EUR","bids":[{"price":7.7003,"qty":221.22262370}],"asks":[],"checksum":2831982637,"timestamp":"2024-06-01T22:43:11.415659Z"}]}
{"channel":"book","type":"update","data":[{"symbol":"ATOM/EUR","bids":[],"asks":[{"price":7.7046,"qty":0.00000000},{"price":7.7111,"qty":1195.37245673}],"checksum":3157240750,"timestamp":"2024-06-01T22:43:11.417217Z"}]}
{"channel":"book","type":"update","data":[{"symbol":"ATOM/EUR","bids":[{"price":7.6981,"qty":0.00000000},{"price":7.6970,"qty":11.96343972}],"asks":[],"checksum":1561510674,"timestamp":"2024-06-01T22:43:11.417799Z"}]}
{"channel":"book","type":"update","data":[{"symbol":"ATOM/EUR","bids":[{"price":7.7020,"qty":0.00000000},{"price":7.6969,"qty":2.39436774}],"asks":[],"checksum":3349380429,"timestamp":"2024-06-01T22:43:11.420164Z"}]}
{"channel":"book","type":"update","data":[{"symbol":"ATOM/EUR","bids":[],"asks":[{"price":7.7063,"qty":0.00000000},{"price":7.7119,"qty":598.10000000}],"checksum":2763323911,"timestamp":"2024-06-01T22:43:11.420523Z"}]}
{"channel":"book","type":"update","data":[{"symbol":"ATOM/EUR","bids":[],"asks":[{"price":7.7061,"qty":0.00000000},{"price":7.7138,"qty":1.82601092}],"checksum":2343748858,"timestamp":"2024-06-01T22:43:11.423131Z"}]}
{"channel":"book","type":"update","data":[{"symbol":"ATOM/EUR","bids":[],"asks":[{"price":7.7099,"qty":1740.70566799}],"checksum":3485301454,"timestamp":"2024-06-01T22:43:11.423164Z"}]}
{"channel":"book","type":"update","data":[{"symbol":"ATOM/EUR","bids":[],"asks":[{"price":7.7071,"qty":21.00000000}],"checksum":4178699863,"timestamp":"2024-06-01T22:43:11.423349Z"}]}
{"channel":"book","type":"update","data":[{"symbol":"ATOM/EUR","bids":[],"asks":[{"price":7.7072,"qty":53.86552536}],"checksum":3187332011,"timestamp":"2024-06-01T22:43:11.425923Z"}]}
{"channel":"book","type":"update","data":[{"symbol":"ATOM/EUR","bids":[],"asks":[{"price":7.7070,"qty":53.86552536}],"checksum":555340638,"timestamp":"2024-06-01T22:43:11.426483Z"}]}
{"channel":"book","type":"update","data":[{"symbol":"ATOM/EUR","bids":[],"asks":[{"price":7.7072,"qty":0.00000000},{"price":7.7111,"qty":1195.37245673}],"checksum":2865985346,"timestamp":"2024-06-01T22:43:11.428740Z"}]}
{"channel":"book","type":"update","data":[{"symbol":"ATOM/EUR","bids":[],"asks":[{"price":7.7071,"qty":0.00000000},{"price":7.7119,"qty":598.10000000}],"checksum":2056893098,"timestamp":"2024-06-01T22:43:11.429001Z"}]}
{"channel":"book","type":"update","data":[{"symbol":"ATOM/EUR","bids":[],"asks":[{"price":7.7068,"qty":21.00000000}],"checksum":522953461,"timestamp":"2024-06-01T22:43:11.429211Z"}]}
{"channel":"book","type":"update","data":[{"symbol":"ATOM/EUR","bids":[],"asks":[{"price":7.7067,"qty":53.86552536}],"checksum":3149689813,"timestamp":"2024-06-01T22:43:11.432499Z"}]}
{"channel":"book","type":"update","data":[{"symbol":"ATOM/EUR","bids":[],"asks":[{"price":7.7068,"qty":0.00000000},{"price":7.7111,"qty":1195.37245673}],"checksum":2336189612,"timestamp":"2024-06-01T22:43:11.434921Z"}]}
{"channel":"book","type":"update","data":[{"symbol":"ATOM/EUR","bids":[],"asks":[{"price":7.7070,"qty":0.00000000},{"price":7.7119,"qty":598.10000000}],"checksum":656853281,"timestamp":"2024-06-01T22:43:11.435163Z"}]}
{"channel":"book","type":"update","data":[{"symbol":"ATOM/EUR","bids":[],"asks":[{"price":7.7065,"qty":21.00000000}],"checksum":1329069450,"timestamp":"2024-06-01T22:43:11.435391Z"}]}
{"channel":"book","type":"update","data":[{"symbol":"ATOM/EUR","bids":[{"price":7.7004,"qty":221.00000000}],"asks":[],"checksum":1433032290,"timestamp":"2024-06-01T22:43:11.437105Z"}]}
{"channel":"book","type":"update","data":[{"symbol":"ATOM/EUR","bids":[],"asks":[{"price":7.7064,"qty":53.86626120}],"checksum":1284016114,"timestamp":"2024-06-01T22:43:11.440398Z"}]}
{"channel":"book","type":"update","data":[{"symbol":"ATOM/EUR","bids":[],"asks":[{"price":7.7067,"qty":0.00000000},{"price":7.7111,"qty":1195.37245673}],"checksum":872432728,"timestamp":"2024-06-01T22:43:11.441453Z"}]}
{"channel":"book","type":"update","data":[{"symbol":"ATOM/EUR","bids":[],"asks":[{"price":7.7065,"qty":0.00000000},{"price":7.7119,"qty":598.10000000}],"checksum":3846222136,"timestamp":"2024-06-01T22:43:11.443092Z"}]}
{"channel":"book","type":"update","data":[{"symbol":"ATOM/EUR","bids":[],"asks":[{"price":7.7062,"qty":21.00000000}],"checksum":1240346251,"timestamp":"2024-06-01T22:43:11.443177Z"}]}
{"channel":"book","type":"update","data":[{"symbol":"ATOM/EUR","bids":[{"price":7.7005,"qty":53.86299377}],"asks":[],"checksum":4181902719,"timestamp":"2024-06-01T22:43:11.444019Z"}]}
{"channel":"book","type":"update","data":[{"symbol":"ATOM/EUR","bids":[{"price":7.6990,"qty":0.00000000},{"price":7.6969,"qty":2.39436774}],"asks":[],"checksum":1085165267,"timestamp":"2024-06-01T22:43:11.444261Z"}]}
{"channel":"book","type":"update","data":[{"symbol":"ATOM/EUR","bids":[{"price":7.6994,"qty":0.00000000},{"price":7.6934,"qty":598.10000000}],"asks":[],"checksum":591465559,"timestamp":"2024-06-01T22:43:11.446130Z"}]}
{"channel":"book","type":"update","data":[{"symbol":"ATOM/EUR","bids":[{"price":7.7004,"qty":200.00000000}],"asks":[],"checksum":2850945797,"timestamp":"2024-06-01T22:43:11.446533Z"}]}
{"channel":"book","type":"update","data":[{"symbol":"ATOM/EUR","bids":[{"price":7.7007,"qty":21.00000000}],"asks":[],"checksum":1539086799,"timestamp":"2024-06-01T22:43:11.446942Z"}]}
{"channel":"book","type":"update","data":[{"symbol":"ATOM/EUR","bids":[{"price":7.6995,"qty":0.00000000},{"price":7.6934,"qty":598.10000000}],"asks":[],"checksum":3223177684,"timestamp":"2024-06-01T22:43:11.449277Z"}]}
{"channel":"book","type":"update","data":[{"symbol":"ATOM/EUR","bids":[],"asks":[{"price":7.7094,"qty":0.00000000},{"price":7.7119,"qty":598.10000000}],"checksum":1163704981,"timestamp":"2024-06-01T22:43:11.491989Z"}]}
{"channel":"book","type":"update","data":[{"symbol":"ATOM/EUR","bids":[],"asks":[{"price":7.7086,"qty":0.00000000},{"price":7.7138,"qty":1.82601092}],"checksum":4264188837,"timestamp":"2024-06-01T22:43:11.493307Z"}]}
{"channel":"book","type":"update","data":[{"symbol":"ATOM/EUR","bids":[],"asks":[{"price":7.7092,"qty":221.22262370}],"checksum":1510732258,"timestamp":"2024-06-01T22:43:11.497392Z"}]}
{"channel":"book","type":"update","data":[{"symbol":"ATOM/EUR","bids":[{"price":7.7006,"qty":221.22262370}],"asks":[],"checksum":399612194,"timestamp":"2024-06-01T22:43:11.497509Z"}]}
{"channel":"book","type":"update","data":[{"symbol":"ATOM/EUR","bids":[],"asks":[{"price":7.7087,"qty":200.00000000}],"checksum":2690880834,"timestamp":"2024-06-01T22:43:11.498131Z"}]}
{"channel":"book","type":"update","data":[{"symbol":"ATOM/EUR","bids":[{"price":7.7006,"qty":421.22262370}],"asks":[],"checksum":602235998,"timestamp":"2024-06-01T22:43:11.498238Z"}]}
{"channel":"book","type":"update","data":[{"symbol":"ATOM/EUR","bids":[],"asks":[{"price":7.7095,"qty":320.29360497}],"checksum":427200985,"timestamp":"2024-06-01T22:43:11.498958Z"}]}
{"channel":"book","type":"update","data":[{"symbol":"ATOM/EUR","bids":[{"price":7.7019,"qty":299.19665026}],"asks":[],"checksum":130096349,"timestamp":"2024-06-01T22:43:11.520116Z"}]}
{"channel":"book","type":"update","data":[{"symbol":"ATOM/EUR","bids":[],"asks":[{"price":7.7040,"qty":299.11562791}],"checksum":3156713080,"timestamp":"2024-06-01T22:43:11.520187Z"}]}
{"channel":"book","type":"update","data":[{"symbol":"ATOM/EUR","bids":[],"asks":[{"price":7.7040,"qty":0.00000000},{"price":7.7110,"qty":944.58200000}],"checksum":130096349,"timestamp":"2024-06-01T22:43:11.664867Z"}]}
{"channel":"book","type":"update","data":[{"symbol":"ATOM/EUR","bids":[{"price":7.7019,"qty":0.00000000},{"price":7.6969,"qty":2.39436774}],"asks":[],"checksum":427200985,"timestamp":"2024-06-01T22:43:11.665029Z"}]}
{"channel":"book","type":"update","data":[{"symbol":"ATOM/EUR","bids":[{"price":7.7003,"qty":0.00000000},{"price":7.6967,"qty":1197.58151510}],"asks":[],"checksum":436954658,"timestamp":"2024-06-01T22:43:11.669269Z"}]}
{"channel":"book","type":"update","data":[{"symbol":"ATOM/EUR","bids":[{"price":7.7017,"qty":299.20137655}],"asks":[],"checksum":4088743666,"timestamp":"2024-06-01T22:43:11.669992Z"}]}
{"channel":"book","type":"update","data":[{"symbol":"ATOM/EUR","bids":[],"asks":[{"price":7.7039,"qty":299.12035291}],"checksum":3869321966,"timestamp":"2024-06-01T22:43:11.670009Z"}]}
{"channel":"book","type":"update","data":[{"symbol":"ATOM/EUR","bids":[{"price":7.7001,"qty":897.79174515}],"asks":[],"checksum":767286672,"timestamp":"2024-06-01T22:43:11.670189Z"}]}
{"channel":"book","type":"update","data":[{"symbol":"ATOM/EUR","bids":[{"price":7.7006,"qty":221.22262370}],"asks":[],"checksum":3836755990,"timestamp":"2024-06-01T22:43:11.670200Z"}]}
{"channel":"book","type":"update","data":[{"symbol":"ATOM/EUR","bids":[],"asks":[{"price":7.7057,"qty":897.15936119}],"checksum":288429330,"timestamp":"2024-06-01T22:43:11.670662Z"}]}
{"channel":"book","type":"update","data":[{"symbol":"ATOM/EUR","bids":[{"price":7.7018,"qty":221.22262370}],"asks":[],"checksum":841236430,"timestamp":"2024-06-01T22:43:11.717683Z"}]}
{"channel":"book","type":"update","data":[{"symbol":"ATOM/EUR","bids":[{"price":7.7006,"qty":0.00000000},{"price":7.6970,"qty":11.96343972}],"asks":[],"checksum":4181651484,"timestamp":"2024-06-01T22:43:11.721701Z"}]}
{"channel":"book","type":"update","data":[{"symbol":"ATOM/EUR","bids":[{"price":7.7017,"qty":0.00000000},{"price":7.6969,"qty":2.39436774}],"asks":[],"checksum":1526597230,"timestamp":"2024-06-01T22:43:11.885291Z"}]}
{"channel":"book","type":"update","data":[{"symbol":"ATOM/EUR","bids":[{"price":7.7018,"qty":520.42091917}],"asks":[],"checksum":881344262,"timestamp":"2024-06-01T22:43:11.889799Z"}]}
{"channel":"book","type":"update","data":[{"symbol":"ATOM/EUR","bids":[{"price":7.7018,"qty":221.22262370}],"asks":[],"checksum":1526597230,"timestamp":"2024-06-01T22:43:11.900542Z"}]}
{"channel":"book","type":"update","data":[{"symbol":"ATOM/EUR","bids":[{"price":7.7018,"qty":0.00000000},{"price":7.6967,"qty":1197.58151510}],"asks":[],"checksum":2701720696,"timestamp":"2024-06-01T22:43:12.217959Z"}]}
{"channel":"book","type":"update","data":[{"symbol":"ATOM/EUR","bids":[{"price":7.7006,"qty":221.22262370}],"asks":[],"checksum":205259884,"timestamp":"2024-06-01T22:43:12.218148Z"}]}
{"channel":"book","type":"update","data":[{"symbol":"ATOM/EUR","bids":[{"price":7.7006,"qty":421.22262370}],"asks":[],"checksum":2411394416,"timestamp":"2024-06-01T22:43:12.222764Z"}]}
{"channel":"book","type":"update","data":[{"symbol":"ATOM/EUR","bids":[],"asks":[{"price":7.7039,"qty":0.00000000},{"price":7.7105,"qty":221.22262370}],"checksum":296453044,"timestamp":"2024-06-01T22:43:12.377901Z"}]}
{"channel":"book","type":"update","data":[{"symbol":"ATOM/EUR","bids":[{"price":7.7019,"qty":299.19620157}],"asks":[],"checksum":2364101352,"timestamp":"2024-06-01T22:43:12.382600Z"}]}
{"channel":"book","type":"update","data":[{"symbol":"ATOM/EUR","bids":[],"asks":[{"price":7.7041,"qty":299.11511953}],"checksum":4036106018,"timestamp":"2024-06-01T22:43:12.382623Z"}]}
{"channel":"book","type":"update","data":[{"symbol":"ATOM/EUR","bids":[{"price":7.7004,"qty":0.00000000},{"price":7.6969,"qty":2.39436774}],"asks":[],"checksum":2113359605,"timestamp":"2024-06-01T22:43:12.382798Z"}]}
{"channel":"book","type":"update","data":[{"symbol":"ATOM/EUR","bids":[{"price":7.7019,"qty":0.00000000},{"price":7.6967,"qty":1197.58151510}],"asks":[],"checksum":1042404591,"timestamp":"2024-06-01T22:43:12.425439Z"}]}
{"channel":"book","type":"update","data":[{"symbol":"ATOM/EUR","bids":[],"asks":[{"price":7.7041,"qty":0.00000000},{"price":7.7105,"qty":221.22262370}],"checksum":2576066849,"timestamp":"2024-06-01T22:43:12.425519Z"}]}
{"channel":"book","type":"update","data":[{"symbol":"ATOM/EUR","bids":[{"price":7.7001,"qty":0.00000000},{"price":7.6934,"qty":598.10000000}],"asks":[],"checksum":157460248,"timestamp":"2024-06-01T22:43:12.425572Z"}]}
{"channel":"book","type":"update","data":[{"symbol":"ATOM/EUR","bids":[{"price":7.6967,"qty":0.00000000},{"price":7.6933,"qty":1198.12028524}],"asks":[],"checksum":3564170925,"timestamp":"2024-06-01T22:43:12.425613Z"}]}
{"channel":"book","type":"update","data":[{"symbol":"ATOM/EUR","bids":[],"asks":[{"price":7.7057,"qty":0.00000000},{"price":7.7109,"qty":1669.51760000}],"checksum":122280034,"timestamp":"2024-06-01T22:43:12.425696Z"}]}
{"channel":"book","type":"update","data":[{"symbol":"ATOM/EUR","bids":[],"asks":[{"price":7.7093,"qty":0.00000000},{"price":7.7110,"qty":944.58200000},{"price":7.7091,"qty":598.30000000}],"checksum":1650128013,"timestamp":"2024-06-01T22:43:12.429052Z"}]}
{"channel":"book","type":"update","data":[{"symbol":"ATOM/EUR","bids":[{"price":7.7006,"qty":1318.95393816}],"asks":[],"checksum":4198729908,"timestamp":"2024-06-01T22:43:12.431187Z"}]}
{"channel":"book","type":"update","data":[{"symbol":"ATOM/EUR","bids":[],"asks":[{"price":7.7063,"qty":897.08479716}],"checksum":1468541994,"timestamp":"2024-06-01T22:43:12.431245Z"}]}
{"channel":"book","type":"update","data":[{"symbol":"ATOM/EUR","bids":[{"price":7.6990,"qty":1197.23429320}],"asks":[],"checksum":2434263423,"timestamp":"2024-06-01T22:43:12.431446Z"}]}
{"channel":"book","type":"update","data":[{"symbol":"ATOM/EUR","bids":[{"price":7.6969,"qty":0.00000000},{"price":7.6933,"qty":1198.12028524}],"asks":[],"checksum":1065869007,"timestamp":"2024-06-01T22:43:12.526355Z"}]}
{"channel":"book","type":"update","data":[{"symbol":"ATOM/EUR","bids":[{"price":7.6981,"qty":2.39401480}],"asks":[],"checksum":3906128858,"timestamp":"2024-06-01T22:43:12.532289Z"}]}
{"channel":"book","type":"update","data":[{"symbol":"ATOM/EUR","bids":[{"price":7.6970,"qty":0.00000000},{"price":7.6933,"qty":1198.12028524}],"asks":[],"checksum":2196429143,"timestamp":"2024-06-01T22:43:12.535936Z"}]}
{"channel":"book","type":"update","data":[{"symbol":"ATOM/EUR","bids":[{"price":7.6935,"qty":22.77785448}],"asks":[],"checksum":3745055015,"timestamp":"2024-06-01T22:43:12.536008Z"}]}
{"channel":"book","type":"update","data":[{"symbol":"ATOM/EUR","bids":[],"asks":[{"price":7.7105,"qty":0.00000000},{"price":7.7109,"qty":1669.51760000}],"checksum":2235837712,"timestamp":"2024-06-01T22:43:12.990536Z"}]}
{"channel":"book","type":"update","data":[{"symbol":"ATOM/EUR","bids":[],"asks":[{"price":7.7062,"qty":23.39401480}],"checksum":2126793896,"timestamp":"2024-06-01T22:43:13.357682Z"}]}
{"channel":"book","type":"update","data":[{"symbol":"ATOM/EUR","bids":[],"asks":[{"price":7.7061,"qty":299.03380462}],"checksum":2316201018,"timestamp":"2024-06-01T22:43:13.441564Z"}]}
{"channel":"book","type":"update","data":[{"symbol":"ATOM/EUR","bids":[{"price":7.7024,"qty":299.17651122}],"asks":[],"checksum":2995042620,"timestamp":"2024-06-01T22:43:13.441628Z"}]}
{"channel":"book","type":"update","data":[{"symbol":"ATOM/EUR","bids":[],"asks":[{"price":7.7061,"qty":0.00000000},{"price":7.7109,"qty":1669.51760000}],"checksum":1179556270,"timestamp":"2024-06-01T22:43:13.445901Z"}]}
{"channel":"book","type":"update","data":[{"symbol":"ATOM/EUR","bids":[{"price":7.7025,"qty":221.22262370}],"asks":[],"checksum":2300803358,"timestamp":"2024-06-01T22:43:13.718200Z"}]}
{"channel":"book","type":"update","data":[{"symbol":"ATOM/EUR","bids":[{"price":7.7006,"qty":1097.73131446}],"asks":[],"checksum":2205120574,"timestamp":"2024-06-01T22:43:13.721463Z"}]}
{"channel":"book","type":"update","data":[{"symbol":"ATOM/EUR","bids":[],"asks":[{"price":7.7047,"qty":299.09137949}],"checksum":1782369854,"timestamp":"2024-06-01T22:43:14.532458Z"}]}
{"channel":"book","type":"update","data":[{"symbol":"ATOM/EUR","bids":[{"price":7.7007,"qty":0.00000000},{"price":7.6935,"qty":22.77785448}],"asks":[],"checksum":874937572,"timestamp":"2024-06-01T22:43:14.842010Z"}]}
{"channel":"book","type":"update","data":[{"symbol":"ATOM/EUR","bids":[{"price":7.7025,"qty":242.22262370}],"asks":[],"checksum":1676268630,"timestamp":"2024-06-01T22:43:14.842339Z"}]}
{"channel":"book","type":"update","data":[{"symbol":"ATOM/EUR","bids":[{"price":7.6981,"qty":0.00000000},{"price":7.6934,"qty":598.10000000}],"asks":[],"checksum":771074912,"timestamp":"2024-06-01T22:43:15.151322Z"}]}
{"channel":"book","type":"update","data":[{"symbol":"ATOM/EUR","bids":[{"price":7.7024,"qty":0.00000000},{"price":7.6933,"qty":1198.12028524}],"asks":[],"checksum":414554128,"timestamp":"2024-06-01T22:43:15.300796Z"}]}
{"channel":"book","type":"update","data":[{"symbol":"ATOM/EUR","bids":[{"price":7.7025,"qty":541.39271092}],"asks":[],"checksum":355876949,"timestamp":"2024-06-01T22:43:15.305312Z"}]}
{"channel":"book","type":"update","data":[{"symbol":"ATOM/EUR","bids":[{"price":7.7025,"qty":320.17008722}],"asks":[],"checksum":3153408525,"timestamp":"2024-06-01T22:43:15.306137Z"}]}
{"channel":"book","type":"update","data":[{"symbol":"ATOM/EUR","bids":[{"price":7.7007,"qty":221.22262370}],"asks":[],"checksum":228251582,"timestamp":"2024-06-01T22:43:15.306240Z"}]}
{"channel":"book","type":"update","data":[{"symbol":"ATOM/EUR","bids":[{"price":7.7026,"qty":221.22262370}],"asks":[],"checksum":152368738,"timestamp":"2024-06-01T22:43:15.716808Z"}]}
{"channel":"book","type":"update","data":[{"symbol":"ATOM/EUR","bids":[{"price":7.7007,"qty":0.00000000},{"price":7.6934,"qty":598.10000000}],"asks":[],"checksum":1519653203,"timestamp":"2024-06-01T22:43:15.720340Z"}]}
{"channel":"book","type":"update","data":[{"symbol":"ATOM/EUR","bids":[],"asks":[{"price":7.7062,"qty":21.00000000}],"checksum":3762762362,"timestamp":"2024-06-01T22:43:16.386011Z"}]}
{"channel":"book","type":"update","data":[{"symbol":"ATOM/EUR","bids":[],"asks":[{"price":7.7073,"qty":0.00000000},{"price":7.7109,"qty":1669.51760000}],"checksum":3346319648,"timestamp":"2024-06-01T22:43:20.929310Z"}]}
{"channel":"book","type":"update","data":[{"symbol":"ATOM/EUR","bids":[{"price":7.7025,"qty":21.00000000}],"asks":[],"checksum":1794325657,"timestamp":"2024-06-01T22:43:20.929387Z"}]}
{"channel":"book","type":"update","data":[{"symbol":"ATOM/EUR","bids":[],"asks":[{"price":7.7064,"qty":0.00000000},{"price":7.7110,"qty":944.58200000}],"checksum":2699930471,"timestamp":"2024-06-01T22:43:20.931628Z"}]}
{"channel":"book","type":"update","data":[{"symbol":"ATOM/EUR","bids":[{"price":7.7025,"qty":0.00000000},{"price":7.6933,"qty":1198.12028524}],"asks":[],"checksum":2089096209,"timestamp":"2024-06-01T22:43:20.932201Z"}]}
{"channel":"book","type":"update","data":[{"symbol":"ATOM/EUR","bids":[],"asks":[{"price":7.7083,"qty":1195.80539079}],"checksum":3771733519,"timestamp":"2024-06-01T22:43:20.934741Z"}]}
{"channel":"book","type":"update","data":[{"symbol":"ATOM/EUR","bids":[{"price":7.7026,"qty":520.39109260}],"asks":[],"checksum":3107967791,"timestamp":"2024-06-01T22:43:20.934930Z"}]}
{"channel":"book","type":"update","data":[{"symbol":"ATOM/EUR","bids":[],"asks":[{"price":7.7047,"qty":0.00000000},{"price":7.7110,"qty":944.58200000}],"checksum":2656408029,"timestamp":"2024-06-01T22:43:21.023340Z"}]}
{"channel":"book","type":"update","data":[{"symbol":"ATOM/EUR","bids":[],"asks":[{"price":7.7049,"qty":299.08310282}],"checksum":3537502959,"timestamp":"2024-06-01T22:43:21.027414Z"}]}
{"channel":"book","type":"update","data":[{"symbol":"ATOM/EUR","bids":[{"price":7.7026,"qty":221.22262370}],"asks":[],"checksum":2335557583,"timestamp":"2024-06-01T22:43:21.111156Z"}]}
{"channel":"book","type":"update","data":[{"symbol":"ATOM/EUR","bids":[],"asks":[{"price":7.7095,"qty":0.00000000},{"price":7.7110,"qty":944.58200000}],"checksum":3986032828,"timestamp":"2024-06-01T22:43:21.113084Z"}]}
{"channel":"book","type":"update","data":[{"symbol":"ATOM/EUR","bids":[],"asks":[{"price":7.7087,"qty":0.00000000},{"price":7.7111,"qty":1195.37245673}],"checksum":3441168346,"timestamp":"2024-06-01T22:43:21.113935Z"}]}
{"channel":"book","type":"update","data":[{"symbol":"ATOM/EUR","bids":[{"price":7.7026,"qty":0.00000000},{"price":7.6929,"qty":59.81000000}],"asks":[],"checksum":493519633,"timestamp":"2024-06-01T22:43:21.115529Z"}]}
{"channel":"book","type":"update","data":[{"symbol":"ATOM/EUR","bids":[{"price":7.7027,"qty":299.16458081}],"asks":[],"checksum":1350177557,"timestamp":"2024-06-01T22:43:21.115555Z"}]}
{"channel":"book","type":"update","data":[{"symbol":"ATOM/EUR","bids":[{"price":7.7007,"qty":221.22262370}],"asks":[],"checksum":2358112379,"timestamp":"2024-06-01T22:43:21.115638Z"}]}
{"channel":"book","type":"update","data":[{"symbol":"ATOM/EUR","bids":[{"price":7.7008,"qty":21.00000000}],"asks":[],"checksum":1334642553,"timestamp":"2024-06-01T22:43:21.118213Z"}]}
{"channel":"book","type":"update","data":[{"symbol":"ATOM/EUR","bids":[{"price":7.7007,"qty":275.08232876}],"asks":[],"checksum":4081499534,"timestamp":"2024-06-01T22:43:21.118647Z"}]}
{"channel":"book","type":"update","data":[{"symbol":"ATOM/EUR","bids":[],"asks":[{"price":7.7104,"qty":242.65110497}],"checksum":2828086802,"timestamp":"2024-06-01T22:43:21.118714Z"}]}
{"channel":"book","type":"update","data":[{"symbol":"ATOM/EUR","bids":[{"price":7.7005,"qty":0.00000000},{"price":7.6934,"qty":598.10000000}],"asks":[],"checksum":3974436304,"timestamp":"2024-06-01T22:43:21.118777Z"}]}
{"channel":"book","type":"update","data":[{"symbol":"ATOM/EUR","bids":[{"price":7.7028,"qty":221.22262370}],"asks":[],"checksum":4159720967,"timestamp":"2024-06-01T22:43:21.218112Z"}]}
{"channel":"book","type":"update","data":[{"symbol":"ATOM/EUR","bids":[{"price":7.7007,"qty":53.85970506}],"asks":[],"checksum":920362222,"timestamp":"2024-06-01T22:43:21.221603Z"}]}
{"channel":"book","type":"update","data":[{"symbol":"ATOM/EUR","bids":[],"asks":[{"price":7.7096,"qty":200.00000000}],"checksum":3432034514,"timestamp":"2024-06-01T22:43:21.222830Z"}]}
{"channel":"book","type":"update","data":[{"symbol":"ATOM/EUR","bids":[],"asks":[{"price":7.7096,"qty":0.00000000},{"price":7.7110,"qty":944.58200000}],"checksum":920362222,"timestamp":"2024-06-01T22:43:21.323850Z"}]}
{"channel":"book","type":"update","data":[{"symbol":"ATOM/EUR","bids":[],"asks":[{"price":7.7091,"qty":0.00000000},{"price":7.7111,"qty":1195.37245673}],"checksum":2897425115,"timestamp":"2024-06-01T22:43:21.326255Z"}]}
{"channel":"book","type":"update","data":[{"symbol":"ATOM/EUR","bids":[],"asks":[{"price":7.7049,"qty":0.00000000},{"price":7.7119,"qty":598.10000000}],"checksum":1011581902,"timestamp":"2024-06-01T22:43:21.346067Z"}]}
{"channel":"book","type":"update","data":[{"symbol":"ATOM/EUR","bids":[],"asks":[{"price":7.7063,"qty":0.00000000},{"price":7.7138,"qty":1.82601092}],"checksum":3232155964,"timestamp":"2024-06-01T22:43:21.346098Z"}]}
{"channel":"book","type":"update","data":[{"symbol":"ATOM/EUR","bids":[{"price":7.7006,"qty":200.00000000}],"asks":[],"checksum":21624557,"timestamp":"2024-06-01T22:43:21.346109Z"}]}
{"channel":"book","type":"update","data":[{"symbol":"ATOM/EUR","bids":[{"price":7.7027,"qty":0.00000000},{"price":7.6934,"qty":598.10000000}],"asks":[],"checksum":3963287638,"timestamp":"2024-06-01T22:43:21.346155Z"}]}
{"channel":"book","type":"update","data":[{"symbol":"ATOM/EUR","bids":[],"asks":[{"price":7.7062,"qty":0.00000000},{"price":7.7173,"qty":619.96000000}],"checksum":4068534885,"timestamp":"2024-06-01T22:43:21.348791Z"}]}
{"channel":"book","type":"update","data":[{"symbol":"ATOM/EUR","bids":[],"asks":[{"price":7.7081,"qty":21.00000000}],"checksum":3756472506,"timestamp":"2024-06-01T22:43:21.349185Z"}]}
{"channel":"book","type":"update","data":[{"symbol":"ATOM/EUR","bids":[],"asks":[{"price":7.7099,"qty":2339.00566799}],"checksum":1903650641,"timestamp":"2024-06-01T22:43:21.351198Z"}]}
{"channel":"book","type":"update","data":[{"symbol":"ATOM/EUR","bids":[],"asks":[{"price":7.7082,"qty":53.85483190}],"checksum":3709496386,"timestamp":"2024-06-01T22:43:21.351680Z"}]}
{"channel":"book","type":"update","data":[{"symbol":"ATOM/EUR","bids":[],"asks":[{"price":7.7069,"qty":897.01629155}],"checksum":1185009671,"timestamp":"2024-06-01T22:43:21.353220Z"}]}
{"channel":"book","type":"update","data":[{"symbol":"ATOM/EUR","bids":[],"asks":[{"price":7.7051,"qty":299.07356827}],"checksum":1829097130,"timestamp":"2024-06-01T22:43:21.353332Z"}]}
{"channel":"book","type":"update","data":[{"symbol":"ATOM/EUR","bids":[{"price":7.7011,"qty":897.67622023}],"asks":[],"checksum":1819051530,"timestamp":"2024-06-01T22:43:21.353353Z"}]}
{"channel":"book","type":"update","data":[{"symbol":"ATOM/EUR","bids":[{"price":7.7029,"qty":299.15803162}],"asks":[],"checksum":543184499,"timestamp":"2024-06-01T22:43:21.353368Z"}]}
{"channel":"book","type":"update","data":[{"symbol":"ATOM/EUR","bids":[],"asks":[{"price":7.7081,"qty":0.00000000},{"price":7.7111,"qty":1195.37245673}],"checksum":2446749031,"timestamp":"2024-06-01T22:43:21.355738Z"}]}
{"channel":"book","type":"update","data":[{"symbol":"ATOM/EUR","bids":[],"asks":[{"price":7.7067,"qty":21.00000000}],"checksum":2260227413,"timestamp":"2024-06-01T22:43:21.355990Z"}]}
{"channel":"book","type":"update","data":[{"symbol":"ATOM/EUR","bids":[{"price":7.7008,"qty":0.00000000},{"price":7.6935,"qty":22.77785448}],"asks":[],"checksum":1892426965,"timestamp":"2024-06-01T22:43:21.422673Z"}]}
{"channel":"book","type":"update","data":[{"symbol":"ATOM/EUR","bids":[{"price":7.7029,"qty":320.15803162}],"asks":[],"checksum":2274798105,"timestamp":"2024-06-01T22:43:21.422764Z"}]}
{"channel":"book","type":"update","data":[{"symbol":"ATOM/EUR","bids":[{"price":7.7029,"qty":21.00000000}],"asks":[],"checksum":2326844312,"timestamp":"2024-06-01T22:43:21.443416Z"}]}
{"channel":"book","type":"update","data":[{"symbol":"ATOM/EUR","bids":[],"asks":[{"price":7.7051,"qty":0.00000000},{"price":7.7111,"qty":1195.37245673}],"checksum":3024322310,"timestamp":"2024-06-01T22:43:21.443612Z"}]}
{"channel":"book","type":"update","data":[{"symbol":"ATOM/EUR","bids":[],"asks":[{"price":7.7107,"qty":299.16458081}],"checksum":702143347,"timestamp":"2024-06-01T22:43:21.536421Z"}]}
{"channel":"book","type":"update","data":[{"symbol":"ATOM/EUR","bids":[{"price":7.7028,"qty":0.00000000},{"price":7.6934,"qty":598.10000000}],"asks":[],"checksum":1221845375,"timestamp":"2024-06-01T22:43:21.716714Z"}]}
{"channel":"book","type":"update","data":[{"symbol":"ATOM/EUR","bids":[{"price":7.7012,"qty":221.22262370}],"asks":[],"checksum":4036831318,"timestamp":"2024-06-01T22:43:21.716800Z"}]}
{"channel":"book","type":"update","data":[{"symbol":"ATOM/EUR","bids":[{"price":7.7029,"qty":0.00000000},{"price":7.6934,"qty":598.10000000}],"asks":[],"checksum":2676832763,"timestamp":"2024-06-01T22:43:21.719344Z"}]}
{"channel":"book","type":"update","data":[{"symbol":"ATOM/EUR","bids":[{"price":7.7013,"qty":21.00000000}],"asks":[],"checksum":3800245631,"timestamp":"2024-06-01T22:43:21.719377Z"}]}
{"channel":"book","type":"update","data":[{"symbol":"ATOM/EUR","bids":[{"price":7.7012,"qty":421.22262370}],"asks":[],"checksum":4274227457,"timestamp":"2024-06-01T22:43:21.721367Z"}]}
{"channel":"book","type":"update","data":[{"symbol":"ATOM/EUR","bids":[{"price":7.7013,"qty":74.85581718}],"asks":[],"checksum":1007599908,"timestamp":"2024-06-01T22:43:21.722002Z"}]}
{"channel":"book","type":"update","data":[{"symbol":"ATOM/EUR","bids":[{"price":7.7007,"qty":0.00000000},{"price":7.6934,"qty":598.10000000}],"asks":[],"checksum":772575754,"timestamp":"2024-06-01T22:43:21.722030Z"}]}
{"channel":"book","type":"update","data":[{"symbol":"ATOM/EUR","bids":[],"asks":[{"price":7.7049,"qty":299.08199739}],"checksum":2004276452,"timestamp":"2024-06-01T22:43:21.890418Z"}]}
{"channel":"book","type":"update","data":[{"symbol":"ATOM/EUR","bids":[{"price":7.7027,"qty":299.16243823}],"asks":[],"checksum":2099550618,"timestamp":"2024-06-01T22:43:21.890476Z"}]}
{"channel":"book","type":"update","data":[{"symbol":"ATOM/EUR","bids":[{"price":7.7014,"qty":221.22262370}],"asks":[],"checksum":596514349,"timestamp":"2024-06-01T22:43:21.894607Z"}]}
{"channel":"book","type":"update","data":[{"symbol":"ATOM/EUR","bids":[{"price":7.7012,"qty":221.22262370}],"asks":[],"checksum":3507764202,"timestamp":"2024-06-01T22:43:21.895237Z"}]}
{"channel":"book","type":"update","data":[{"symbol":"ATOM/EUR","bids":[{"price":7.7014,"qty":421.22262370}],"asks":[],"checksum":1723148157,"timestamp":"2024-06-01T22:43:21.895372Z"}]}
{"channel":"book","type":"update","data":[{"symbol":"ATOM/EUR","bids":[{"price":7.7013,"qty":53.85581718}],"asks":[],"checksum":1031991388,"timestamp":"2024-06-01T22:43:21.897214Z"}]}
{"channel":"book","type":"update","data":[{"symbol":"ATOM/EUR","bids":[{"price":7.7027,"qty":320.16243823}],"asks":[],"checksum":2946966601,"timestamp":"2024-06-01T22:43:21.897442Z"}]}
{"channel":"book","type":"update","data":[{"symbol":"ATOM/EUR","bids":[{"price":7.7014,"qty":221.22262370}],"asks":[],"checksum":403060958,"timestamp":"2024-06-01T22:43:21.935969Z"}]}
{"channel":"book","type":"update","data":[{"symbol":"ATOM/EUR","bids":[{"price":7.7012,"qty":0.00000000},{"price":7.6935,"qty":22.77785448}],"asks":[],"checksum":1023713409,"timestamp":"2024-06-01T22:43:21.939337Z"}]}
{"channel":"book","type":"update","data":[{"symbol":"ATOM/EUR","bids":[{"price":7.7027,"qty":21.00000000}],"asks":[],"checksum":2881072843,"timestamp":"2024-06-01T22:43:21.986161Z"}]}
{"channel":"book","type":"update","data":[{"symbol":"ATOM/EUR","bids":[],"asks":[{"price":7.7049,"qty":0.00000000},{"price":7.7110,"qty":944.58200000}],"checksum":1656903607,"timestamp":"2024-06-01T22:43:21.986326Z"}]}
{"channel":"book","type":"update","data":[{"symbol":"ATOM/EUR","bids":[{"price":7.7027,"qty":0.00000000},{"price":7.6934,"qty":598.10000000}],"asks":[],"checksum":3158881825,"timestamp":"2024-06-01T22:43:21.988785Z"}]}
{"channel":"book","type":"update","data":[{"symbol":"ATOM/EUR","bids":[{"price":7.7016,"qty":21.00000000}],"asks":[],"checksum":2952406379,"timestamp":"2024-06-01T22:43:21.989044Z"}]}
{"channel":"book","type":"update","data":[{"symbol":"ATOM/EUR","bids":[],"asks":[{"price":7.7069,"qty":0.00000000},{"price":7.7111,"qty":1195.37245673}],"checksum":1341593835,"timestamp":"2024-06-01T22:43:21.990469Z"}]}
{"channel":"book","type":"update","data":[{"symbol":"ATOM/EUR","bids":[{"price":7.7015,"qty":200.00000000}],"asks":[],"checksum":3566874440,"timestamp":"2024-06-01T22:43:21.991157Z"}]}
{"channel":"book","type":"update","data":[{"symbol":"ATOM/EUR","bids":[{"price":7.7015,"qty":253.85581718}],"asks":[],"checksum":2543529485,"timestamp":"2024-06-01T22:43:21.991618Z"}]}
{"channel":"book","type":"update","data":[{"symbol":"ATOM/EUR","bids":[{"price":7.7013,"qty":0.00000000},{"price":7.6935,"qty":22.77785448}],"asks":[],"checksum":3900825306,"timestamp":"2024-06-01T22:43:21.991745Z"}]}
{"channel":"book","type":"update","data":[{"symbol":"ATOM/EUR","bids":[{"price":7.7017,"qty":53.85581718}],"asks":[],"checksum":188869758,"timestamp":"2024-06-01T22:43:21.994937Z"}]}
{"channel":"book","type":"update","data":[{"symbol":"ATOM/EUR","bids":[{"price":7.7015,"qty":200.00000000}],"asks":[],"checksum":201369766,"timestamp":"2024-06-01T22:43:21.996040Z"}]}
{"channel":"book","type":"update","data":[{"symbol":"ATOM/EUR","bids":[],"asks":[{"price":7.7067,"qty":0.00000000},{"price":7.7119,"qty":598.10000000}],"checksum":3803455763,"timestamp":"2024-06-01T22:43:21.996131Z"}]}
{"channel":"book","type":"update","data":[{"symbol":"ATOM/EUR","bids":[{"price":7.7025,"qty":299.17086895}],"asks":[],"checksum":2280989687,"timestamp":"2024-06-01T22:43:21.996294Z"}]}
{"channel":"book","type":"update","data":[{"symbol":"ATOM/EUR","bids":[],"asks":[{"price":7.7080,"qty":21.00000000}],"checksum":3558369468,"timestamp":"2024-06-01T22:43:21.996369Z"}]}
{"channel":"book","type":"update","data":[{"symbol":"ATOM/EUR","bids":[],"asks":[{"price":7.7048,"qty":299.08720006}],"checksum":383517780,"timestamp":"2024-06-01T22:43:21.996394Z"}]}
{"channel":"book","type":"update","data":[{"symbol":"ATOM/EUR","bids":[],"asks":[{"price":7.7066,"qty":897.04321042}],"checksum":2698524249,"timestamp":"2024-06-01T22:43:21.996459Z"}]}
{"channel":"book","type":"update","data":[{"symbol":"ATOM/EUR","bids":[{"price":7.7016,"qty":0.00000000},{"price":7.6980,"qty":1197.38595507}],"asks":[],"checksum":1405886197,"timestamp":"2024-06-01T22:43:21.997468Z"}]}
{"channel":"book","type":"update","data":[{"symbol":"ATOM/EUR","bids":[{"price":7.7019,"qty":21.00000000}],"asks":[],"checksum":684813706,"timestamp":"2024-06-01T22:43:21.997691Z"}]}
{"channel":"book","type":"update","data":[{"symbol":"ATOM/EUR","bids":[{"price":7.7019,"qty":0.00000000},{"price":7.6980,"qty":1197.38595507}],"asks":[],"checksum":1405886197,"timestamp":"2024-06-01T22:43:21.998763Z"}]}
{"channel":"book","type":"update","data":[{"symbol":"ATOM/EUR","bids":[],"asks":[{"price":7.7079,"qty":53.85581718}],"checksum":900361847,"timestamp":"2024-06-01T22:43:21.999005Z"}]}
{"channel":"book","type":"update","data":[{"symbol":"ATOM/EUR","bids":[{"price":7.7027,"qty":21.00000000}],"asks":[],"checksum":3880234695,"timestamp":"2024-06-01T22:43:21.999083Z"}]}
{"channel":"book","type":"update","data":[{"symbol":"ATOM/EUR","bids":[],"asks":[{"price":7.7082,"qty":0.00000000},{"price":7.7109,"qty":1669.51760000}],"checksum":359465441,"timestamp":"2024-06-01T22:43:21.999188Z"}]}
{"channel":"book","type":"update","data":[{"symbol":"ATOM/EUR","bids":[],"asks":[{"price":7.7066,"qty":0.00000000},{"price":7.7110,"qty":944.58200000}],"checksum":3197567159,"timestamp":"2024-06-01T22:43:22.000938Z"}]}
{"channel":"book","type":"update","data":[{"symbol":"ATOM/EUR","bids":[{"price":7.7025,"qty":0.00000000},{"price":7.6980,"qty":1197.38595507}],"asks":[],"checksum":602324311,"timestamp":"2024-06-01T22:43:22.141753Z"}]}
{"channel":"book","type":"update","data":[{"symbol":"ATOM/EUR","bids":[],"asks":[{"price":7.7048,"qty":0.00000000},{"price":7.7111,"qty":1195.37245673}],"checksum":3729731364,"timestamp":"2024-06-01T22:43:22.141782Z"}]}
{"channel":"book","type":"update","data":[{"symbol":"ATOM/EUR","bids":[{"price":7.7027,"qty":0.00000000},{"price":7.6935,"qty":22.77785448}],"asks":[],"checksum":3516973917,"timestamp":"2024-06-01T22:43:22.144369Z"}]}
{"channel":"book","type":"update","data":[{"symbol":"ATOM/EUR","bids":[{"price":7.7019,"qty":21.00000000}],"asks":[],"checksum":3919089749,"timestamp":"2024-06-01T22:43:22.144459Z"}]}
{"channel":"book","type":"update","data":[{"symbol":"ATOM/EUR","bids":[],"asks":[{"price":7.7080,"qty":0.00000000},{"price":7.7119,"qty":598.10000000}],"checksum":297964835,"timestamp":"2024-06-01T22:43:22.144505Z"}]}
{"channel":"book","type":"update","data":[{"symbol":"ATOM/EUR","bids":[],"asks":[{"price":7.7077,"qty":21.00000000}],"checksum":1242878471,"timestamp":"2024-06-01T22:43:22.144695Z"}]}
{"channel":"book","type":"update","data":[{"symbol":"ATOM/EUR","bids":[{"price":7.7018,"qty":221.22262370}],"asks":[],"checksum":2214136232,"timestamp":"2024-06-01T22:43:22.146265Z"}]}
