{"channel":"book","type":"snapshot","data":[{"symbol":"AUD/USD","bids":[{"price":0.66443,"qty":253.23426000},{"price":0.66440,"qty":5574.34921653},{"price":0.66439,"qty":4843.14500000},{"price":0.66381,"qty":559.48885976},{"price":0.66375,"qty":582.12015683},{"price":0.66374,"qty":25341.91959668},{"price":0.66373,"qty":53001.00000000},{"price":0.66366,"qty":47002.00000000},{"price":0.66359,"qty":3003.00000000},{"price":0.66353,"qty":2804.00000000}],"asks":[{"price":0.66453,"qty":171.84142498},{"price":0.66467,"qty":5436.00000000},{"price":0.66468,"qty":5721.13011755},{"price":0.66471,"qty":2297.49030000},{"price":0.66477,"qty":8871.83596627},{"price":0.66483,"qty":11804.65003983},{"price":0.66510,"qty":466.07172610},{"price":0.66536,"qty":11597.71694755},{"price":0.66537,"qty":71701.00000000},{"price":0.66544,"qty":3013.00000000}],"checksum":741192661}]}
{"channel":"book","type":"update","data":[{"symbol":"AUD/USD","bids":[],"asks":[{"price":0.66468,"qty":147.28761190},{"price":0.66466,"qty":5573.84526323}],"checksum":4228743804,"timestamp":"2024-06-01T22:43:23.027489Z"}]}
{"channel":"book","type":"update","data":[{"symbol":"AUD/USD","bids":[],"asks":[{"price":0.66471,"qty":0.00000000},{"price":0.66544,"qty":3013.00000000}],"checksum":3868078340,"timestamp":"2024-06-01T22:43:23.080124Z"}]}
{"channel":"book","type":"update","data":[{"symbol":"AUD/USD","bids":[],"asks":[{"price":0.66465,"qty":2297.49030000}],"checksum":693134658,"timestamp":"2024-06-01T22:43:23.080380Z"}]}
{"channel":"book","type":"update","data":[{"symbol":"AUD/USD","bids":[],"asks":[{"price":0.66466,"qty":0.00000000},{"price":0.66544,"qty":3013.00000000},{"price":0.66464,"qty":5573.84648177}],"checksum":545928185,"timestamp":"2024-06-01T22:43:23.383131Z"}]}
{"channel":"book","type":"update","data":[{"symbol":"AUD/USD","bids":[],"asks":[{"price":0.66467,"qty":0.00000000},{"price":0.66544,"qty":3013.00000000},{"price":0.66463,"qty":5436.00000000}],"checksum":3487407297,"timestamp":"2024-06-01T22:43:23.419077Z"}]}
{"channel":"book","type":"update","data":[{"symbol":"AUD/USD","bids":[],"asks":[{"price":0.66465,"qty":0.00000000},{"price":0.66544,"qty":3013.00000000}],"checksum":2644399243,"timestamp":"2024-06-01T22:43:23.433678Z"}]}
{"channel":"book","type":"update","data":[{"symbol":"AUD/USD","bids":[],"asks":[{"price":0.66467,"qty":2297.49030000}],"checksum":892025079,"timestamp":"2024-06-01T22:43:23.433792Z"}]}
{"channel":"book","type":"update","data":[{"symbol":"AUD/USD","bids":[{"price":0.66374,"qty":0.00000000},{"price":0.66347,"qty":2506.00000000}],"asks":[],"checksum":2507203954,"timestamp":"2024-06-01T22:43:23.450832Z"}]}
{"channel":"book","type":"update","data":[{"symbol":"AUD/USD","bids":[{"price":0.66376,"qty":24652.27296056}],"asks":[],"checksum":2574321599,"timestamp":"2024-06-01T22:43:23.457789Z"}]}
{"channel":"book","type":"update","data":[{"symbol":"AUD/USD","bids":[],"asks":[{"price":0.66464,"qty":0.00000000},{"price":0.66544,"qty":3013.00000000},{"price":0.66462,"qty":5573.84703622}],"checksum":56121186,"timestamp":"2024-06-01T22:43:23.772805Z"}]}
{"channel":"book","type":"update","data":[{"symbol":"AUD/USD","bids":[],"asks":[{"price":0.66463,"qty":0.00000000},{"price":0.66544,"qty":3013.00000000},{"price":0.66461,"qty":5436.00000000}],"checksum":1256228664,"timestamp":"2024-06-01T22:43:24.087349Z"}]}
{"channel":"book","type":"update","data":[{"symbol":"AUD/USD","bids":[],"asks":[{"price":0.66483,"qty":0.00000000},{"price":0.66544,"qty":3013.00000000}],"checksum":221657682,"timestamp":"2024-06-01T22:43:24.151139Z"}]}
{"channel":"book","type":"update","data":[{"symbol":"AUD/USD","bids":[],"asks":[{"price":0.66536,"qty":0.00000000},{"price":0.66558,"qty":9466.00000000}],"checksum":2326182323,"timestamp":"2024-06-01T22:43:24.151278Z"}]}
{"channel":"book","type":"update","data":[{"symbol":"AUD/USD","bids":[],"asks":[{"price":0.66477,"qty":0.00000000},{"price":0.66581,"qty":2955.00000000}],"checksum":3168124916,"timestamp":"2024-06-01T22:43:24.151363Z"}]}
{"channel":"book","type":"update","data":[{"symbol":"AUD/USD","bids":[],"asks":[{"price":0.66536,"qty":35267.16262833}],"checksum":4148696732,"timestamp":"2024-06-01T22:43:24.152572Z"}]}
{"channel":"book","type":"update","data":[{"symbol":"AUD/USD","bids":[],"asks":[{"price":0.66462,"qty":0.00000000},{"price":0.66581,"qty":2955.00000000},{"price":0.66460,"qty":5573.84735764}],"checksum":638015501,"timestamp":"2024-06-01T22:43:24.195716Z"}]}
{"channel":"book","type":"update","data":[{"symbol":"AUD/USD","bids":[],"asks":[{"price":0.66461,"qty":0.00000000},{"price":0.66581,"qty":2955.00000000},{"price":0.66459,"qty":5436.00000000}],"checksum":4080513498,"timestamp":"2024-06-01T22:43:24.514760Z"}]}
{"channel":"book","type":"update","data":[{"symbol":"AUD/USD","bids":[],"asks":[{"price":0.66460,"qty":0.00000000},{"price":0.66581,"qty":2955.00000000},{"price":0.66458,"qty":5573.83760431}],"checksum":2006171556,"timestamp":"2024-06-01T22:43:24.575325Z"}]}
{"channel":"book","type":"update","data":[{"symbol":"AUD/USD","bids":[],"asks":[{"price":0.66459,"qty":0.00000000},{"price":0.66581,"qty":2955.00000000},{"price":0.66457,"qty":5436.00000000}],"checksum":2363861543,"timestamp":"2024-06-01T22:43:25.213016Z"}]}
{"channel":"book","type":"update","data":[{"symbol":"AUD/USD","bids":[],"asks":[{"price":0.66458,"qty":0.00000000},{"price":0.66581,"qty":2955.00000000},{"price":0.66456,"qty":5573.83286085}],"checksum":3751088021,"timestamp":"2024-06-01T22:43:25.216209Z"}]}
{"channel":"book","type":"update","data":[{"symbol":"AUD/USD","bids":[],"asks":[{"price":0.66457,"qty":0.00000000},{"price":0.66581,"qty":2955.00000000},{"price":0.66455,"qty":5436.00000000}],"checksum":1530555822,"timestamp":"2024-06-01T22:43:25.850014Z"}]}
{"channel":"book","type":"update","data":[{"symbol":"AUD/USD","bids":[],"asks":[{"price":0.66456,"qty":0.00000000},{"price":0.66581,"qty":2955.00000000},{"price":0.66454,"qty":5573.83197043}],"checksum":4110590756,"timestamp":"2024-06-01T22:43:25.853143Z"}]}
{"channel":"book","type":"update","data":[{"symbol":"AUD/USD","bids":[{"price":0.66375,"qty":0.00000000},{"price":0.66347,"qty":2506.00000000}],"asks":[],"checksum":3338858626,"timestamp":"2024-06-01T22:43:25.912313Z"}]}
{"channel":"book","type":"update","data":[{"symbol":"AUD/USD","bids":[{"price":0.66377,"qty":582.12015683}],"asks":[],"checksum":3202478421,"timestamp":"2024-06-01T22:43:25.914717Z"}]}
{"channel":"book","type":"update","data":[{"symbol":"AUD/USD","bids":[],"asks":[{"price":0.66468,"qty":0.00000000},{"price":0.66581,"qty":2955.00000000}],"checksum":4056007865,"timestamp":"2024-06-01T22:43:26.197894Z"}]}
{"channel":"book","type":"update","data":[{"symbol":"AUD/USD","bids":[],"asks":[{"price":0.66535,"qty":264.68521483}],"checksum":361430118,"timestamp":"2024-06-01T22:43:26.198721Z"}]}
{"channel":"book","type":"update","data":[{"symbol":"AUD/USD","bids":[],"asks":[{"price":0.66467,"qty":0.00000000},{"price":0.66581,"qty":2955.00000000}],"checksum":3029797468,"timestamp":"2024-06-01T22:43:26.209410Z"}]}
{"channel":"book","type":"update","data":[{"symbol":"AUD/USD","bids":[],"asks":[{"price":0.66509,"qty":2297.49030000}],"checksum":3399812442,"timestamp":"2024-06-01T22:43:26.209507Z"}]}
{"channel":"book","type":"update","data":[{"symbol":"AUD/USD","bids":[{"price":0.66376,"qty":0.00000000},{"price":0.66347,"qty":2506.00000000}],"asks":[],"checksum":618398560,"timestamp":"2024-06-01T22:43:26.958797Z"}]}
{"channel":"book","type":"update","data":[{"symbol":"AUD/USD","bids":[{"price":0.66378,"qty":11940.49253016}],"asks":[],"checksum":1894768308,"timestamp":"2024-06-01T22:43:26.964093Z"}]}
{"channel":"book","type":"update","data":[{"symbol":"AUD/USD","bids":[{"price":0.66374,"qty":13388.33973540}],"asks":[],"checksum":528569900,"timestamp":"2024-06-01T22:43:26.964318Z"}]}
{"channel":"book","type":"update","data":[{"symbol":"AUD/USD","bids":[],"asks":[{"price":0.66536,"qty":0.00000000},{"price":0.66581,"qty":2955.00000000}],"checksum":2145274678,"timestamp":"2024-06-01T22:43:27.038196Z"}]}
{"channel":"book","type":"update","data":[{"symbol":"AUD/USD","bids":[],"asks":[{"price":0.66534,"qty":8871.83596627}],"checksum":3184991433,"timestamp":"2024-06-01T22:43:27.039492Z"}]}
{"channel":"book","type":"update","data":[{"symbol":"AUD/USD","bids":[],"asks":[{"price":0.66536,"qty":23416.68736860}],"checksum":1307635956,"timestamp":"2024-06-01T22:43:27.039713Z"}]}
{"channel":"book","type":"update","data":[{"symbol":"AUD/USD","bids":[{"price":0.66377,"qty":0.00000000},{"price":0.66353,"qty":2804.00000000}],"asks":[],"checksum":1776044242,"timestamp":"2024-06-01T22:43:29.116580Z"}]}
{"channel":"book","type":"update","data":[{"symbol":"AUD/USD","bids":[{"price":0.66379,"qty":420.20509343}],"asks":[],"checksum":1961641830,"timestamp":"2024-06-01T22:43:29.125394Z"}]}
{"channel":"book","type":"update","data":[{"symbol":"AUD/USD","bids":[{"price":0.66382,"qty":135.21581504}],"asks":[],"checksum":1801760260,"timestamp":"2024-06-01T22:43:29.125509Z"}]}
{"channel":"book","type":"update","data":[{"symbol":"AUD/USD","bids":[],"asks":[{"price":0.66535,"qty":0.00000000},{"price":0.66558,"qty":9466.00000000}],"checksum":4043738828,"timestamp":"2024-06-01T22:43:29.728803Z"}]}
{"channel":"book","type":"update","data":[{"symbol":"AUD/USD","bids":[],"asks":[{"price":0.66533,"qty":264.68521483}],"checksum":2125876328,"timestamp":"2024-06-01T22:43:29.729715Z"}]}
{"channel":"book","type":"update","data":[{"symbol":"AUD/USD","bids":[{"price":0.66374,"qty":0.00000000},{"price":0.66359,"qty":3003.00000000}],"asks":[],"checksum":1562371996,"timestamp":"2024-06-01T22:43:30.279808Z"}]}
{"channel":"book","type":"update","data":[{"symbol":"AUD/USD","bids":[{"price":0.66378,"qty":0.00000000},{"price":0.66353,"qty":2804.00000000}],"asks":[],"checksum":3252577804,"timestamp":"2024-06-01T22:43:30.279818Z"}]}
{"channel":"book","type":"update","data":[{"symbol":"AUD/USD","bids":[{"price":0.66374,"qty":23600.76665185}],"asks":[],"checksum":4015140869,"timestamp":"2024-06-01T22:43:30.285060Z"}]}
{"channel":"book","type":"update","data":[{"symbol":"AUD/USD","bids":[{"price":0.66379,"qty":0.00000000},{"price":0.66353,"qty":2804.00000000}],"asks":[],"checksum":2016505180,"timestamp":"2024-06-01T22:43:32.114048Z"}]}
{"channel":"book","type":"update","data":[{"symbol":"AUD/USD","bids":[{"price":0.66382,"qty":0.00000000},{"price":0.66347,"qty":2506.00000000}],"asks":[],"checksum":697836256,"timestamp":"2024-06-01T22:43:32.114068Z"}]}
{"channel":"book","type":"update","data":[{"symbol":"AUD/USD","bids":[{"price":0.66375,"qty":582.12015683}],"asks":[],"checksum":4120531343,"timestamp":"2024-06-01T22:43:32.118015Z"}]}
{"channel":"book","type":"update","data":[{"symbol":"AUD/USD","bids":[],"asks":[{"price":0.66536,"qty":0.00000000},{"price":0.66558,"qty":9466.00000000}],"checksum":3237539630,"timestamp":"2024-06-01T22:43:32.751453Z"}]}
{"channel":"book","type":"update","data":[{"symbol":"AUD/USD","bids":[],"asks":[{"price":0.66534,"qty":0.00000000},{"price":0.66581,"qty":2955.00000000}],"checksum":1874064770,"timestamp":"2024-06-01T22:43:32.751519Z"}]}
{"channel":"book","type":"update","data":[{"symbol":"AUD/USD","bids":[],"asks":[{"price":0.66536,"qty":32334.34855477}],"checksum":1683078376,"timestamp":"2024-06-01T22:43:32.752602Z"}]}
{"channel":"book","type":"update","data":[{"symbol":"AUD/USD","bids":[],"asks":[{"price":0.66533,"qty":0.00000000},{"price":0.66581,"qty":2955.00000000}],"checksum":3115111821,"timestamp":"2024-06-01T22:43:33.125697Z"}]}
{"channel":"book","type":"update","data":[{"symbol":"AUD/USD","bids":[],"asks":[{"price":0.66535,"qty":294.01313515}],"checksum":3050432934,"timestamp":"2024-06-01T22:43:33.126964Z"}]}
{"channel":"book","type":"update","data":[{"symbol":"AUD/USD","bids":[{"price":0.66374,"qty":0.00000000},{"price":0.66347,"qty":2506.00000000}],"asks":[],"checksum":2713955972,"timestamp":"2024-06-01T22:43:33.913719Z"}]}
{"channel":"book","type":"update","data":[{"symbol":"AUD/USD","bids":[{"price":0.66376,"qty":26187.09216825}],"asks":[],"checksum":2465046569,"timestamp":"2024-06-01T22:43:33.919311Z"}]}
{"channel":"book","type":"update","data":[{"symbol":"AUD/USD","bids":[{"price":0.66375,"qty":0.00000000},{"price":0.66347,"qty":2506.00000000}],"asks":[],"checksum":3117703996,"timestamp":"2024-06-01T22:43:35.045055Z"}]}
{"channel":"book","type":"update","data":[{"symbol":"AUD/USD","bids":[{"price":0.66377,"qty":582.12015683}],"asks":[],"checksum":1113826636,"timestamp":"2024-06-01T22:43:35.051078Z"}]}
{"channel":"book","type":"update","data":[{"symbol":"AUD/USD","bids":[],"asks":[{"price":0.66536,"qty":0.00000000},{"price":0.66581,"qty":2955.00000000}],"checksum":2738030284,"timestamp":"2024-06-01T22:43:35.625374Z"}]}
{"channel":"book","type":"update","data":[{"symbol":"AUD/USD","bids":[],"asks":[{"price":0.66534,"qty":8871.83596627}],"checksum":4254681235,"timestamp":"2024-06-01T22:43:35.626930Z"}]}
{"channel":"book","type":"update","data":[{"symbol":"AUD/USD","bids":[],"asks":[{"price":0.66536,"qty":23416.68736860}],"checksum":4159507161,"timestamp":"2024-06-01T22:43:35.627111Z"}]}
{"channel":"book","type":"update","data":[{"symbol":"AUD/USD","bids":[],"asks":[{"price":0.66535,"qty":0.00000000},{"price":0.66558,"qty":9466.00000000}],"checksum":2375606209,"timestamp":"2024-06-01T22:43:36.468293Z"}]}
{"channel":"book","type":"update","data":[{"symbol":"AUD/USD","bids":[],"asks":[{"price":0.66533,"qty":264.68521483}],"checksum":36183397,"timestamp":"2024-06-01T22:43:36.468934Z"}]}
{"channel":"book","type":"update","data":[{"symbol":"AUD/USD","bids":[{"price":0.66376,"qty":0.00000000},{"price":0.66347,"qty":2506.00000000}],"asks":[],"checksum":80471211,"timestamp":"2024-06-01T22:43:37.434675Z"}]}
{"channel":"book","type":"update","data":[{"symbol":"AUD/USD","bids":[{"price":0.66378,"qty":11940.49253016}],"asks":[],"checksum":2088358507,"timestamp":"2024-06-01T22:43:37.439919Z"}]}
{"channel":"book","type":"update","data":[{"symbol":"AUD/USD","bids":[{"price":0.66374,"qty":13388.33973540}],"asks":[],"checksum":165744485,"timestamp":"2024-06-01T22:43:37.439932Z"}]}
{"channel":"book","type":"update","data":[{"symbol":"AUD/USD","bids":[{"price":0.66377,"qty":0.00000000},{"price":0.66353,"qty":2804.00000000}],"asks":[],"checksum":4002478847,"timestamp":"2024-06-01T22:43:38.241115Z"}]}
{"channel":"book","type":"update","data":[{"symbol":"AUD/USD","bids":[{"price":0.66382,"qty":135.48951581}],"asks":[],"checksum":2738382851,"timestamp":"2024-06-01T22:43:38.247362Z"}]}
{"channel":"book","type":"update","data":[{"symbol":"AUD/USD","bids":[{"price":0.66379,"qty":447.63000410}],"asks":[],"checksum":1386996857,"timestamp":"2024-06-01T22:43:38.247470Z"}]}
{"channel":"book","type":"update","data":[{"symbol":"AUD/USD","bids":[],"asks":[{"price":0.66534,"qty":0.00000000},{"price":0.66558,"qty":9466.00000000}],"checksum":714956554,"timestamp":"2024-06-01T22:43:38.523460Z"}]}
{"channel":"book","type":"update","data":[{"symbol":"AUD/USD","bids":[],"asks":[{"price":0.66536,"qty":0.00000000},{"price":0.66581,"qty":2955.00000000}],"checksum":3363979380,"timestamp":"2024-06-01T22:43:38.523578Z"}]}
{"channel":"book","type":"update","data":[{"symbol":"AUD/USD","bids":[],"asks":[{"price":0.66536,"qty":32334.34855477}],"checksum":3277850910,"timestamp":"2024-06-01T22:43:38.525370Z"}]}
{"channel":"book","type":"update","data":[{"symbol":"AUD/USD","bids":[],"asks":[{"price":0.66533,"qty":0.00000000},{"price":0.66581,"qty":2955.00000000}],"checksum":513630331,"timestamp":"2024-06-01T22:43:39.898606Z"}]}
{"channel":"book","type":"update","data":[{"symbol":"AUD/USD","bids":[],"asks":[{"price":0.66535,"qty":264.68521483}],"checksum":3413383252,"timestamp":"2024-06-01T22:43:39.899291Z"}]}
{"channel":"book","type":"update","data":[{"symbol":"AUD/USD","bids":[{"price":0.66378,"qty":0.00000000},{"price":0.66359,"qty":3003.00000000}],"asks":[],"checksum":3356578199,"timestamp":"2024-06-01T22:43:40.842110Z"}]}
{"channel":"book","type":"update","data":[{"symbol":"AUD/USD","bids":[{"price":0.66374,"qty":0.00000000},{"price":0.66353,"qty":2804.00000000}],"asks":[],"checksum":3980036949,"timestamp":"2024-06-01T22:43:40.842389Z"}]}
{"channel":"book","type":"update","data":[{"symbol":"AUD/USD","bids":[{"price":0.66374,"qty":25341.91959668}],"asks":[],"checksum":844076601,"timestamp":"2024-06-01T22:43:40.847713Z"}]}
{"channel":"book","type":"update","data":[{"symbol":"AUD/USD","bids":[],"asks":[{"price":0.66536,"qty":0.00000000},{"price":0.66581,"qty":2955.00000000}],"checksum":2183812018,"timestamp":"2024-06-01T22:43:41.347933Z"}]}
{"channel":"book","type":"update","data":[{"symbol":"AUD/USD","bids":[],"asks":[{"price":0.66534,"qty":8871.83596627}],"checksum":2448173663,"timestamp":"2024-06-01T22:43:41.349190Z"}]}
{"channel":"book","type":"update","data":[{"symbol":"AUD/USD","bids":[],"asks":[{"price":0.66536,"qty":23416.68736860}],"checksum":3962381415,"timestamp":"2024-06-01T22:43:41.349341Z"}]}
{"channel":"book","type":"update","data":[{"symbol":"AUD/USD","bids":[{"price":0.66382,"qty":0.00000000},{"price":0.66353,"qty":2804.00000000}],"asks":[],"checksum":1219857629,"timestamp":"2024-06-01T22:43:41.537608Z"}]}
{"channel":"book","type":"update","data":[{"symbol":"AUD/USD","bids":[{"price":0.66379,"qty":0.00000000},{"price":0.66347,"qty":2506.00000000}],"asks":[],"checksum":1964409260,"timestamp":"2024-06-01T22:43:41.537650Z"}]}
{"channel":"book","type":"update","data":[{"symbol":"AUD/USD","bids":[{"price":0.66375,"qty":583.55708590}],"asks":[],"checksum":3509107557,"timestamp":"2024-06-01T22:43:41.541802Z"}]}
{"channel":"book","type":"update","data":[{"symbol":"AUD/USD","bids":[],"asks":[{"price":0.66535,"qty":0.00000000},{"price":0.66558,"qty":9466.00000000}],"checksum":1263180717,"timestamp":"2024-06-01T22:43:43.347132Z"}]}
{"channel":"book","type":"update","data":[{"symbol":"AUD/USD","bids":[],"asks":[{"price":0.66533,"qty":264.68521483}],"checksum":3304741129,"timestamp":"2024-06-01T22:43:43.348125Z"}]}
{"channel":"book","type":"update","data":[{"symbol":"AUD/USD","bids":[{"price":0.66374,"qty":0.00000000},{"price":0.66347,"qty":2506.00000000}],"asks":[],"checksum":2431867299,"timestamp":"2024-06-01T22:43:44.124248Z"}]}
{"channel":"book","type":"update","data":[{"symbol":"AUD/USD","bids":[{"price":0.66376,"qty":24783.52680224}],"asks":[],"checksum":4253333687,"timestamp":"2024-06-01T22:43:44.129395Z"}]}
{"channel":"book","type":"update","data":[{"symbol":"AUD/USD","bids":[],"asks":[{"price":0.66534,"qty":0.00000000},{"price":0.66558,"qty":9466.00000000}],"checksum":2243036100,"timestamp":"2024-06-01T22:43:44.201614Z"}]}
{"channel":"book","type":"update","data":[{"symbol":"AUD/USD","bids":[],"asks":[{"price":0.66536,"qty":0.00000000},{"price":0.66581,"qty":2955.00000000}],"checksum":1739398330,"timestamp":"2024-06-01T22:43:44.201783Z"}]}
{"channel":"book","type":"update","data":[{"symbol":"AUD/USD","bids":[],"asks":[{"price":0.66536,"qty":32334.34855477}],"checksum":1817138640,"timestamp":"2024-06-01T22:43:44.202931Z"}]}
{"channel":"book","type":"update","data":[{"symbol":"AUD/USD","bids":[{"price":0.66377,"qty":253.23426000}],"asks":[],"checksum":3558419601,"timestamp":"2024-06-01T22:43:44.365872Z"}]}
{"channel":"book","type":"update","data":[{"symbol":"AUD/USD","bids":[{"price":0.66443,"qty":0.00000000},{"price":0.66353,"qty":2804.00000000}],"asks":[],"checksum":4291511893,"timestamp":"2024-06-01T22:43:44.827637Z"}]}
{"channel":"book","type":"update","data":[{"symbol":"AUD/USD","bids":[],"asks":[{"price":0.66455,"qty":0.00000000},{"price":0.66581,"qty":2955.00000000},{"price":0.66453,"qty":5607.84142498}],"checksum":1362365426,"timestamp":"2024-06-01T22:43:44.847670Z"}]}
{"channel":"book","type":"update","data":[{"symbol":"AUD/USD","bids":[],"asks":[{"price":0.66454,"qty":0.00000000},{"price":0.66595,"qty":3415.09400402},{"price":0.66452,"qty":5573.93828613}],"checksum":3398252613,"timestamp":"2024-06-01T22:43:44.851025Z"}]}
{"channel":"book","type":"update","data":[{"symbol":"AUD/USD","bids":[],"asks":[{"price":0.66453,"qty":171.84142498},{"price":0.66451,"qty":5436.00000000}],"checksum":2046497065,"timestamp":"2024-06-01T22:43:44.879922Z"}]}
{"channel":"book","type":"update","data":[{"symbol":"AUD/USD","bids":[],"asks":[{"price":0.66452,"qty":0.00000000},{"price":0.66581,"qty":2955.00000000},{"price":0.66450,"qty":5573.93828613}],"checksum":1837986573,"timestamp":"2024-06-01T22:43:44.883120Z"}]}
{"channel":"book","type":"update","data":[{"symbol":"AUD/USD","bids":[],"asks":[{"price":0.66451,"qty":0.00000000},{"price":0.66581,"qty":2955.00000000},{"price":0.66449,"qty":5436.00000000}],"checksum":1656713135,"timestamp":"2024-06-01T22:43:44.911411Z"}]}
{"channel":"book","type":"update","data":[{"symbol":"AUD/USD","bids":[],"asks":[{"price":0.66450,"qty":0.00000000},{"price":0.66581,"qty":2955.00000000},{"price":0.66448,"qty":5573.93828613}],"checksum":612518592,"timestamp":"2024-06-01T22:43:44.914604Z"}]}
{"channel":"book","type":"update","data":[{"symbol":"AUD/USD","bids":[],"asks":[{"price":0.66451,"qty":171.84142498}],"checksum":1764110161,"timestamp":"2024-06-01T22:43:45.018508Z"}]}
{"channel":"book","type":"update","data":[{"symbol":"AUD/USD","bids":[],"asks":[{"price":0.66449,"qty":0.00000000},{"price":0.66558,"qty":9466.00000000},{"price":0.66447,"qty":5436.00000000}],"checksum":3367952794,"timestamp":"2024-06-01T22:43:45.035659Z"}]}
{"channel":"book","type":"update","data":[{"symbol":"AUD/USD","bids":[],"asks":[{"price":0.66448,"qty":0.00000000},{"price":0.66558,"qty":9466.00000000},{"price":0.66508,"qty":5573.93683082}],"checksum":3320139128,"timestamp":"2024-06-01T22:43:45.038707Z"}]}
{"channel":"book","type":"update","data":[{"symbol":"AUD/USD","bids":[],"asks":[{"price":0.66507,"qty":2297.49030000}],"checksum":3387060773,"timestamp":"2024-06-01T22:43:45.044104Z"}]}
{"channel":"book","type":"update","data":[{"symbol":"AUD/USD","bids":[],"asks":[{"price":0.66509,"qty":0.00000000},{"price":0.66544,"qty":3013.00000000}],"checksum":483312523,"timestamp":"2024-06-01T22:43:45.044122Z"}]}
{"channel":"book","type":"update","data":[{"symbol":"AUD/USD","bids":[],"asks":[{"price":0.66508,"qty":0.00000000},{"price":0.66558,"qty":9466.00000000},{"price":0.66506,"qty":5573.93683082}],"checksum":1106058222,"timestamp":"2024-06-01T22:43:45.049510Z"}]}
{"channel":"book","type":"update","data":[{"symbol":"AUD/USD","bids":[],"asks":[{"price":0.66447,"qty":0.00000000},{"price":0.66558,"qty":9466.00000000},{"price":0.66452,"qty":5436.00000000}],"checksum":3735747969,"timestamp":"2024-06-01T22:43:45.066295Z"}]}
{"channel":"book","type":"update","data":[{"symbol":"AUD/USD","bids":[],"asks":[{"price":0.66505,"qty":2297.49030000}],"checksum":3322226629,"timestamp":"2024-06-01T22:43:45.069056Z"}]}
{"channel":"book","type":"update","data":[{"symbol":"AUD/USD","bids":[],"asks":[{"price":0.66507,"qty":0.00000000},{"price":0.66544,"qty":3013.00000000}],"checksum":2135263221,"timestamp":"2024-06-01T22:43:45.069079Z"}]}
{"channel":"book","type":"update","data":[{"symbol":"AUD/USD","bids":[],"asks":[{"price":0.66506,"qty":0.00000000},{"price":0.66558,"qty":9466.00000000},{"price":0.66450,"qty":5573.93683082}],"checksum":1765118131,"timestamp":"2024-06-01T22:43:45.090916Z"}]}
{"channel":"book","type":"update","data":[{"symbol":"AUD/USD","bids":[],"asks":[{"price":0.66452,"qty":0.00000000},{"price":0.66558,"qty":9466.00000000},{"price":0.66449,"qty":5436.00000000}],"checksum":3866846959,"timestamp":"2024-06-01T22:43:45.098617Z"}]}
{"channel":"book","type":"update","data":[{"symbol":"AUD/USD","bids":[],"asks":[{"price":0.66450,"qty":0.00000000},{"price":0.66558,"qty":9466.00000000},{"price":0.66448,"qty":5573.93683082}],"checksum":2398271174,"timestamp":"2024-06-01T22:43:45.101504Z"}]}
{"channel":"book","type":"update","data":[{"symbol":"AUD/USD","bids":[],"asks":[{"price":0.66449,"qty":0.00000000},{"price":0.66558,"qty":9466.00000000},{"price":0.66447,"qty":5436.00000000}],"checksum":326680203,"timestamp":"2024-06-01T22:43:45.130243Z"}]}
{"channel":"book","type":"update","data":[{"symbol":"AUD/USD","bids":[],"asks":[{"price":0.66448,"qty":0.00000000},{"price":0.66558,"qty":9466.00000000},{"price":0.66504,"qty":5573.93583884}],"checksum":2017992804,"timestamp":"2024-06-01T22:43:45.133308Z"}]}
{"channel":"book","type":"update","data":[{"symbol":"AUD/USD","bids":[],"asks":[{"price":0.66505,"qty":0.00000000},{"price":0.66558,"qty":9466.00000000}],"checksum":1190334438,"timestamp":"2024-06-01T22:43:45.136817Z"}]}
{"channel":"book","type":"update","data":[{"symbol":"AUD/USD","bids":[],"asks":[{"price":0.66503,"qty":2297.49030000}],"checksum":3279182071,"timestamp":"2024-06-01T22:43:45.137030Z"}]}
{"channel":"book","type":"update","data":[{"symbol":"AUD/USD","bids":[],"asks":[{"price":0.66504,"qty":0.00000000},{"price":0.66558,"qty":9466.00000000},{"price":0.66532,"qty":5573.93583884}],"checksum":1404650687,"timestamp":"2024-06-01T22:43:45.139781Z"}]}
{"channel":"book","type":"update","data":[{"symbol":"AUD/USD","bids":[],"asks":[{"price":0.66532,"qty":0.00000000},{"price":0.66558,"qty":9466.00000000},{"price":0.66446,"qty":5573.93583884}],"checksum":4170041268,"timestamp":"2024-06-01T22:43:45.142684Z"}]}
{"channel":"book","type":"update","data":[{"symbol":"AUD/USD","bids":[],"asks":[{"price":0.66447,"qty":0.00000000},{"price":0.66558,"qty":9466.00000000},{"price":0.66445,"qty":5436.00000000}],"checksum":2347358127,"timestamp":"2024-06-01T22:43:45.161987Z"}]}
{"channel":"book","type":"update","data":[{"symbol":"AUD/USD","bids":[],"asks":[{"price":0.66446,"qty":0.00000000},{"price":0.66558,"qty":9466.00000000},{"price":0.66502,"qty":5573.93583884}],"checksum":2353920978,"timestamp":"2024-06-01T22:43:45.165345Z"}]}
{"channel":"book","type":"update","data":[{"symbol":"AUD/USD","bids":[],"asks":[{"price":0.66503,"qty":0.00000000},{"price":0.66558,"qty":9466.00000000}],"checksum":2965355579,"timestamp":"2024-06-01T22:43:45.177909Z"}]}
{"channel":"book","type":"update","data":[{"symbol":"AUD/USD","bids":[],"asks":[{"price":0.66501,"qty":2297.49030000}],"checksum":523382588,"timestamp":"2024-06-01T22:43:45.178163Z"}]}
{"channel":"book","type":"update","data":[{"symbol":"AUD/USD","bids":[],"asks":[{"price":0.66502,"qty":0.00000000},{"price":0.66558,"qty":9466.00000000},{"price":0.66532,"qty":5573.93583884}],"checksum":2377538335,"timestamp":"2024-06-01T22:43:45.181117Z"}]}
{"channel":"book","type":"update","data":[{"symbol":"AUD/USD","bids":[],"asks":[{"price":0.66453,"qty":0.00000000},{"price":0.66558,"qty":9466.00000000}],"checksum":2238253433,"timestamp":"2024-06-01T22:43:45.182224Z"}]}
{"channel":"book","type":"update","data":[{"symbol":"AUD/USD","bids":[],"asks":[{"price":0.66532,"qty":0.00000000},{"price":0.66581,"qty":2955.00000000},{"price":0.66500,"qty":5573.93583884}],"checksum":2530084250,"timestamp":"2024-06-01T22:43:45.184250Z"}]}
{"channel":"book","type":"update","data":[{"symbol":"AUD/USD","bids":[],"asks":[{"price":0.66445,"qty":0.00000000},{"price":0.66581,"qty":2955.00000000},{"price":0.66499,"qty":5436.00000000}],"checksum":2257139647,"timestamp":"2024-06-01T22:43:45.194825Z"}]}
{"channel":"book","type":"update","data":[{"symbol":"AUD/USD","bids":[],"asks":[{"price":0.66501,"qty":0.00000000},{"price":0.66581,"qty":2955.00000000}],"checksum":3145165315,"timestamp":"2024-06-01T22:43:45.206493Z"}]}
{"channel":"book","type":"update","data":[{"symbol":"AUD/USD","bids":[],"asks":[{"price":0.66498,"qty":2297.49030000}],"checksum":2448192573,"timestamp":"2024-06-01T22:43:45.206659Z"}]}
{"channel":"book","type":"update","data":[{"symbol":"AUD/USD","bids":[],"asks":[{"price":0.66500,"qty":0.00000000},{"price":0.66581,"qty":2955.00000000},{"price":0.66497,"qty":5573.93583884}],"checksum":1818683607,"timestamp":"2024-06-01T22:43:45.217947Z"}]}
{"channel":"book","type":"update","data":[{"symbol":"AUD/USD","bids":[],"asks":[{"price":0.66499,"qty":0.00000000},{"price":0.66581,"qty":2955.00000000},{"price":0.66496,"qty":5436.00000000}],"checksum":4213424832,"timestamp":"2024-06-01T22:43:45.225537Z"}]}
{"channel":"book","type":"update","data":[{"symbol":"AUD/USD","bids":[],"asks":[{"price":0.66498,"qty":0.00000000},{"price":0.66581,"qty":2955.00000000}],"checksum":1087181302,"timestamp":"2024-06-01T22:43:45.251854Z"}]}
{"channel":"book","type":"update","data":[{"symbol":"AUD/USD","bids":[],"asks":[{"price":0.66495,"qty":2297.49030000}],"checksum":3837803756,"timestamp":"2024-06-01T22:43:45.251914Z"}]}
{"channel":"book","type":"update","data":[{"symbol":"AUD/USD","bids":[],"asks":[{"price":0.66497,"qty":0.00000000},{"price":0.66581,"qty":2955.00000000},{"price":0.66494,"qty":5573.93583884}],"checksum":2315244308,"timestamp":"2024-06-01T22:43:45.285868Z"}]}
{"channel":"book","type":"update","data":[{"symbol":"AUD/USD","bids":[],"asks":[{"price":0.66496,"qty":0.00000000},{"price":0.66581,"qty":2955.00000000},{"price":0.66494,"qty":11009.93583884}],"checksum":3879084134,"timestamp":"2024-06-01T22:43:45.288781Z"}]}
{"channel":"book","type":"update","data":[{"symbol":"AUD/USD","bids":[],"asks":[{"price":0.66494,"qty":5573.93583884},{"price":0.66493,"qty":5436.00000000}],"checksum":4172605334,"timestamp":"2024-06-01T22:43:45.319937Z"}]}
{"channel":"book","type":"update","data":[{"symbol":"AUD/USD","bids":[],"asks":[{"price":0.66493,"qty":7733.49030000}],"checksum":371697678,"timestamp":"2024-06-01T22:43:45.321075Z"}]}
{"channel":"book","type":"update","data":[{"symbol":"AUD/USD","bids":[],"asks":[{"price":0.66495,"qty":0.00000000},{"price":0.66581,"qty":2955.00000000}],"checksum":2848007472,"timestamp":"2024-06-01T22:43:45.321089Z"}]}
{"channel":"book","type":"update","data":[{"symbol":"AUD/USD","bids":[],"asks":[{"price":0.66493,"qty":2297.49030000},{"price":0.66492,"qty":5436.00000000}],"checksum":68461655,"timestamp":"2024-06-01T22:43:45.351897Z"}]}
{"channel":"book","type":"update","data":[{"symbol":"AUD/USD","bids":[],"asks":[{"price":0.66491,"qty":2297.49030000}],"checksum":593116399,"timestamp":"2024-06-01T22:43:45.362358Z"}]}
{"channel":"book","type":"update","data":[{"symbol":"AUD/USD","bids":[],"asks":[{"price":0.66493,"qty":0.00000000},{"price":0.66558,"qty":9466.00000000}],"checksum":79848150,"timestamp":"2024-06-01T22:43:45.362425Z"}]}
{"channel":"book","type":"update","data":[{"symbol":"AUD/USD","bids":[],"asks":[{"price":0.66492,"qty":0.00000000},{"price":0.66581,"qty":2955.00000000},{"price":0.66490,"qty":5436.00000000}],"checksum":3674732450,"timestamp":"2024-06-01T22:43:45.384535Z"}]}
{"channel":"book","type":"update","data":[{"symbol":"AUD/USD","bids":[],"asks":[{"price":0.66494,"qty":0.00000000},{"price":0.66581,"qty":2955.00000000},{"price":0.66490,"qty":11009.93516608}],"checksum":705605649,"timestamp":"2024-06-01T22:43:45.386893Z"}]}
{"channel":"book","type":"update","data":[{"symbol":"AUD/USD","bids":[],"asks":[{"price":0.66489,"qty":2297.49030000}],"checksum":4022096882,"timestamp":"2024-06-01T22:43:45.398153Z"}]}
{"channel":"book","type":"update","data":[{"symbol":"AUD/USD","bids":[],"asks":[{"price":0.66491,"qty":0.00000000},{"price":0.66581,"qty":2955.00000000}],"checksum":2014933681,"timestamp":"2024-06-01T22:43:45.398255Z"}]}
{"channel":"book","type":"update","data":[{"symbol":"AUD/USD","bids":[],"asks":[{"price":0.66490,"qty":5573.93516608},{"price":0.66488,"qty":5436.00000000}],"checksum":1500530738,"timestamp":"2024-06-01T22:43:45.416625Z"}]}
{"channel":"book","type":"update","data":[{"symbol":"AUD/USD","bids":[],"asks":[{"price":0.66487,"qty":2297.49030000}],"checksum":707188219,"timestamp":"2024-06-01T22:43:45.431794Z"}]}
{"channel":"book","type":"update","data":[{"symbol":"AUD/USD","bids":[],"asks":[{"price":0.66489,"qty":0.00000000},{"price":0.66558,"qty":9466.00000000}],"checksum":3973876305,"timestamp":"2024-06-01T22:43:45.431812Z"}]}
{"channel":"book","type":"update","data":[{"symbol":"AUD/USD","bids":[],"asks":[{"price":0.66488,"qty":0.00000000},{"price":0.66581,"qty":2955.00000000},{"price":0.66486,"qty":5436.00000000}],"checksum":698087738,"timestamp":"2024-06-01T22:43:45.447178Z"}]}
{"channel":"book","type":"update","data":[{"symbol":"AUD/USD","bids":[],"asks":[{"price":0.66487,"qty":0.00000000},{"price":0.66581,"qty":2955.00000000}],"checksum":1201433976,"timestamp":"2024-06-01T22:43:45.471403Z"}]}
{"channel":"book","type":"update","data":[{"symbol":"AUD/USD","bids":[],"asks":[{"price":0.66485,"qty":2297.49030000}],"checksum":692928443,"timestamp":"2024-06-01T22:43:45.471690Z"}]}
{"channel":"book","type":"update","data":[{"symbol":"AUD/USD","bids":[],"asks":[{"price":0.66486,"qty":0.00000000},{"price":0.66581,"qty":2955.00000000},{"price":0.66484,"qty":5436.00000000}],"checksum":4136151759,"timestamp":"2024-06-01T22:43:45.479599Z"}]}
{"channel":"book","type":"update","data":[{"symbol":"AUD/USD","bids":[],"asks":[{"price":0.66485,"qty":0.00000000},{"price":0.66581,"qty":2955.00000000}],"checksum":3341259112,"timestamp":"2024-06-01T22:43:45.495638Z"}]}
{"channel":"book","type":"update","data":[{"symbol":"AUD/USD","bids":[],"asks":[{"price":0.66483,"qty":2297.49030000}],"checksum":744002095,"timestamp":"2024-06-01T22:43:45.496047Z"}]}
{"channel":"book","type":"update","data":[{"symbol":"AUD/USD","bids":[],"asks":[{"price":0.66484,"qty":0.00000000},{"price":0.66581,"qty":2955.00000000},{"price":0.66482,"qty":5436.00000000}],"checksum":1288460433,"timestamp":"2024-06-01T22:43:45.511849Z"}]}
{"channel":"book","type":"update","data":[{"symbol":"AUD/USD","bids":[],"asks":[{"price":0.66490,"qty":0.00000000},{"price":0.66581,"qty":2955.00000000},{"price":0.66481,"qty":5573.93471108}],"checksum":4234425720,"timestamp":"2024-06-01T22:43:45.521833Z"}]}
{"channel":"book","type":"update","data":[{"symbol":"AUD/USD","bids":[],"asks":[{"price":0.66483,"qty":0.00000000},{"price":0.66581,"qty":2955.00000000}],"checksum":4012053310,"timestamp":"2024-06-01T22:43:45.530315Z"}]}
{"channel":"book","type":"update","data":[{"symbol":"AUD/USD","bids":[],"asks":[{"price":0.66480,"qty":2297.49030000}],"checksum":235831039,"timestamp":"2024-06-01T22:43:45.530423Z"}]}
{"channel":"book","type":"update","data":[{"symbol":"AUD/USD","bids":[],"asks":[{"price":0.66482,"qty":0.00000000},{"price":0.66581,"qty":2955.00000000},{"price":0.66479,"qty":5436.00000000}],"checksum":2918670821,"timestamp":"2024-06-01T22:43:45.543071Z"}]}
{"channel":"book","type":"update","data":[{"symbol":"AUD/USD","bids":[],"asks":[{"price":0.66478,"qty":2297.49030000}],"checksum":134975893,"timestamp":"2024-06-01T22:43:45.556317Z"}]}
{"channel":"book","type":"update","data":[{"symbol":"AUD/USD","bids":[],"asks":[{"price":0.66480,"qty":0.00000000},{"price":0.66558,"qty":9466.00000000}],"checksum":3178958022,"timestamp":"2024-06-01T22:43:45.556356Z"}]}
{"channel":"book","type":"update","data":[{"symbol":"AUD/USD","bids":[],"asks":[{"price":0.66479,"qty":0.00000000},{"price":0.66581,"qty":2955.00000000},{"price":0.66477,"qty":5436.00000000}],"checksum":148360869,"timestamp":"2024-06-01T22:43:45.575345Z"}]}
{"channel":"book","type":"update","data":[{"symbol":"AUD/USD","bids":[],"asks":[{"price":0.66478,"qty":0.00000000},{"price":0.66581,"qty":2955.00000000}],"checksum":1177608375,"timestamp":"2024-06-01T22:43:45.605652Z"}]}
{"channel":"book","type":"update","data":[{"symbol":"AUD/USD","bids":[],"asks":[{"price":0.66476,"qty":2297.49030000}],"checksum":3448815054,"timestamp":"2024-06-01T22:43:45.605854Z"}]}
{"channel":"book","type":"update","data":[{"symbol":"AUD/USD","bids":[],"asks":[{"price":0.66477,"qty":0.00000000},{"price":0.66581,"qty":2955.00000000},{"price":0.66475,"qty":5436.00000000}],"checksum":3443948367,"timestamp":"2024-06-01T22:43:45.637584Z"}]}
{"channel":"book","type":"update","data":[{"symbol":"AUD/USD","bids":[],"asks":[{"price":0.66476,"qty":0.00000000},{"price":0.66581,"qty":2955.00000000}],"checksum":3331005607,"timestamp":"2024-06-01T22:43:45.650672Z"}]}
{"channel":"book","type":"update","data":[{"symbol":"AUD/USD","bids":[],"asks":[{"price":0.66474,"qty":2297.49030000}],"checksum":310636091,"timestamp":"2024-06-01T22:43:45.655679Z"}]}
{"channel":"book","type":"update","data":[{"symbol":"AUD/USD","bids":[],"asks":[{"price":0.66475,"qty":0.00000000},{"price":0.66581,"qty":2955.00000000},{"price":0.66473,"qty":5436.00000000}],"checksum":3360937691,"timestamp":"2024-06-01T22:43:45.669157Z"}]}
{"channel":"book","type":"update","data":[{"symbol":"AUD/USD","bids":[],"asks":[{"price":0.66472,"qty":2297.49030000}],"checksum":3252488465,"timestamp":"2024-06-01T22:43:45.675857Z"}]}
{"channel":"book","type":"update","data":[{"symbol":"AUD/USD","bids":[],"asks":[{"price":0.66474,"qty":0.00000000},{"price":0.66558,"qty":9466.00000000}],"checksum":2831621221,"timestamp":"2024-06-01T22:43:45.675879Z"}]}
{"channel":"book","type":"update","data":[{"symbol":"AUD/USD","bids":[],"asks":[{"price":0.66481,"qty":0.00000000},{"price":0.66581,"qty":2955.00000000},{"price":0.66471,"qty":5573.93471108}],"checksum":41288182,"timestamp":"2024-06-01T22:43:45.689846Z"}]}
{"channel":"book","type":"update","data":[{"symbol":"AUD/USD","bids":[],"asks":[{"price":0.66472,"qty":0.00000000},{"price":0.66581,"qty":2955.00000000}],"checksum":1163964047,"timestamp":"2024-06-01T22:43:45.697877Z"}]}
{"channel":"book","type":"update","data":[{"symbol":"AUD/USD","bids":[],"asks":[{"price":0.66470,"qty":2297.49030000}],"checksum":4005861705,"timestamp":"2024-06-01T22:43:45.698087Z"}]}
{"channel":"book","type":"update","data":[{"symbol":"AUD/USD","bids":[],"asks":[{"price":0.66471,"qty":0.00000000},{"price":0.66581,"qty":2955.00000000},{"price":0.66472,"qty":5573.93440383}],"checksum":610530033,"timestamp":"2024-06-01T22:43:45.701109Z"}]}
{"channel":"book","type":"update","data":[{"symbol":"AUD/USD","bids":[],"asks":[{"price":0.66473,"qty":0.00000000},{"price":0.66581,"qty":2955.00000000},{"price":0.66470,"qty":7733.49030000}],"checksum":1305925257,"timestamp":"2024-06-01T22:43:45.701205Z"}]}
{"channel":"book","type":"update","data":[{"symbol":"AUD/USD","bids":[],"asks":[{"price":0.66470,"qty":2297.49030000},{"price":0.66469,"qty":5436.00000000}],"checksum":861127721,"timestamp":"2024-06-01T22:43:45.733076Z"}]}
{"channel":"book","type":"update","data":[{"symbol":"AUD/USD","bids":[],"asks":[{"price":0.66470,"qty":0.00000000},{"price":0.66581,"qty":2955.00000000}],"checksum":2197768278,"timestamp":"2024-06-01T22:43:45.753840Z"}]}
{"channel":"book","type":"update","data":[{"symbol":"AUD/USD","bids":[],"asks":[{"price":0.66468,"qty":2297.49030000}],"checksum":2129827905,"timestamp":"2024-06-01T22:43:45.753856Z"}]}
{"channel":"book","type":"update","data":[{"symbol":"AUD/USD","bids":[],"asks":[{"price":0.66469,"qty":0.00000000},{"price":0.66581,"qty":2955.00000000},{"price":0.66467,"qty":5436.00000000}],"checksum":3411958306,"timestamp":"2024-06-01T22:43:45.764825Z"}]}
{"channel":"book","type":"update","data":[{"symbol":"AUD/USD","bids":[],"asks":[{"price":0.66468,"qty":0.00000000},{"price":0.66581,"qty":2955.00000000}],"checksum":3074338980,"timestamp":"2024-06-01T22:43:45.784692Z"}]}
{"channel":"book","type":"update","data":[{"symbol":"AUD/USD","bids":[],"asks":[{"price":0.66466,"qty":2297.49030000}],"checksum":236529993,"timestamp":"2024-06-01T22:43:45.784868Z"}]}
{"channel":"book","type":"update","data":[{"symbol":"AUD/USD","bids":[],"asks":[{"price":0.66467,"qty":0.00000000},{"price":0.66581,"qty":2955.00000000},{"price":0.66465,"qty":5436.00000000}],"checksum":248508360,"timestamp":"2024-06-01T22:43:45.797677Z"}]}
{"channel":"book","type":"update","data":[{"symbol":"AUD/USD","bids":[],"asks":[{"price":0.66466,"qty":0.00000000},{"price":0.66581,"qty":2955.00000000}],"checksum":931482804,"timestamp":"2024-06-01T22:43:45.827252Z"}]}
{"channel":"book","type":"update","data":[{"symbol":"AUD/USD","bids":[],"asks":[{"price":0.66471,"qty":2297.49030000}],"checksum":1145377817,"timestamp":"2024-06-01T22:43:45.827285Z"}]}
{"channel":"book","type":"update","data":[{"symbol":"AUD/USD","bids":[],"asks":[{"price":0.66472,"qty":0.00000000},{"price":0.66581,"qty":2955.00000000},{"price":0.66464,"qty":5573.93440383}],"checksum":3424488271,"timestamp":"2024-06-01T22:43:45.892778Z"}]}
{"channel":"book","type":"update","data":[{"symbol":"AUD/USD","bids":[],"asks":[{"price":0.66471,"qty":0.00000000},{"price":0.66581,"qty":2955.00000000}],"checksum":3538607181,"timestamp":"2024-06-01T22:43:45.903240Z"}]}
{"channel":"book","type":"update","data":[{"symbol":"AUD/USD","bids":[],"asks":[{"price":0.66509,"qty":2297.49030000}],"checksum":3214137611,"timestamp":"2024-06-01T22:43:45.903276Z"}]}
{"channel":"book","type":"update","data":[{"symbol":"AUD/USD","bids":[],"asks":[{"price":0.66465,"qty":0.00000000},{"price":0.66581,"qty":2955.00000000},{"price":0.66463,"qty":5436.00000000}],"checksum":2292671616,"timestamp":"2024-06-01T22:43:45.920445Z"}]}
{"channel":"book","type":"update","data":[{"symbol":"AUD/USD","bids":[],"asks":[{"price":0.66464,"qty":0.00000000},{"price":0.66581,"qty":2955.00000000},{"price":0.66462,"qty":5573.93419653}],"checksum":1639129143,"timestamp":"2024-06-01T22:43:46.162704Z"}]}
{"channel":"book","type":"update","data":[{"symbol":"AUD/USD","bids":[],"asks":[{"price":0.66463,"qty":0.00000000},{"price":0.66581,"qty":2955.00000000},{"price":0.66461,"qty":5436.00000000}],"checksum":4070101727,"timestamp":"2024-06-01T22:43:46.195567Z"}]}
{"channel":"book","type":"update","data":[{"symbol":"AUD/USD","bids":[],"asks":[{"price":0.66462,"qty":0.00000000},{"price":0.66581,"qty":2955.00000000},{"price":0.66460,"qty":5573.93405673}],"checksum":4046629886,"timestamp":"2024-06-01T22:43:46.388515Z"}]}
{"channel":"book","type":"update","data":[{"symbol":"AUD/USD","bids":[],"asks":[{"price":0.66461,"qty":0.00000000},{"price":0.66581,"qty":2955.00000000},{"price":0.66459,"qty":5436.00000000}],"checksum":498750966,"timestamp":"2024-06-01T22:43:46.407982Z"}]}
{"channel":"book","type":"update","data":[{"symbol":"AUD/USD","bids":[],"asks":[{"price":0.66460,"qty":0.00000000},{"price":0.66581,"qty":2955.00000000},{"price":0.66458,"qty":5573.95352717}],"checksum":16373047,"timestamp":"2024-06-01T22:43:46.648174Z"}]}
{"channel":"book","type":"update","data":[{"symbol":"AUD/USD","bids":[],"asks":[{"price":0.66459,"qty":0.00000000},{"price":0.66581,"qty":2955.00000000},{"price":0.66457,"qty":5436.00000000}],"checksum":1103702751,"timestamp":"2024-06-01T22:43:46.682156Z"}]}
{"channel":"book","type":"update","data":[{"symbol":"AUD/USD","bids":[],"asks":[{"price":0.66533,"qty":0.00000000},{"price":0.66581,"qty":2955.00000000}],"checksum":803555170,"timestamp":"2024-06-01T22:43:46.745474Z"}]}
{"channel":"book","type":"update","data":[{"symbol":"AUD/USD","bids":[],"asks":[{"price":0.66535,"qty":264.68521483}],"checksum":1239235477,"timestamp":"2024-06-01T22:43:46.746507Z"}]}
{"channel":"book","type":"update","data":[{"symbol":"AUD/USD","bids":[],"asks":[{"price":0.66458,"qty":0.00000000},{"price":0.66581,"qty":2955.00000000},{"price":0.66456,"qty":5573.95331860}],"checksum":3927763163,"timestamp":"2024-06-01T22:43:46.941481Z"}]}
{"channel":"book","type":"update","data":[{"symbol":"AUD/USD","bids":[],"asks":[{"price":0.66457,"qty":0.00000000},{"price":0.66581,"qty":2955.00000000},{"price":0.66455,"qty":5436.00000000}],"checksum":4040446348,"timestamp":"2024-06-01T22:43:46.958006Z"}]}
{"channel":"book","type":"update","data":[{"symbol":"AUD/USD","bids":[],"asks":[{"price":0.66536,"qty":0.00000000},{"price":0.66581,"qty":2955.00000000}],"checksum":3955745398,"timestamp":"2024-06-01T22:43:47.077392Z"}]}
{"channel":"book","type":"update","data":[{"symbol":"AUD/USD","bids":[],"asks":[{"price":0.66534,"qty":8871.83596627}],"checksum":896514762,"timestamp":"2024-06-01T22:43:47.078534Z"}]}
{"channel":"book","type":"update","data":[{"symbol":"AUD/USD","bids":[],"asks":[{"price":0.66536,"qty":23416.68736860}],"checksum":2094616525,"timestamp":"2024-06-01T22:43:47.078661Z"}]}
{"channel":"book","type":"update","data":[{"symbol":"AUD/USD","bids":[],"asks":[{"price":0.66456,"qty":0.00000000},{"price":0.66558,"qty":9466.00000000},{"price":0.66454,"qty":5573.95305243}],"checksum":1291750809,"timestamp":"2024-06-01T22:43:47.267894Z"}]}
{"channel":"book","type":"update","data":[{"symbol":"AUD/USD","bids":[],"asks":[{"price":0.66455,"qty":0.00000000},{"price":0.66558,"qty":9466.00000000},{"price":0.66453,"qty":5436.00000000}],"checksum":2072671094,"timestamp":"2024-06-01T22:43:47.294907Z"}]}
{"channel":"book","type":"update","data":[{"symbol":"AUD/USD","bids":[],"asks":[{"price":0.66454,"qty":0.00000000},{"price":0.66558,"qty":9466.00000000},{"price":0.66452,"qty":5573.95297612}],"checksum":2715880934,"timestamp":"2024-06-01T22:43:47.551301Z"}]}
{"channel":"book","type":"update","data":[{"symbol":"AUD/USD","bids":[],"asks":[{"price":0.66453,"qty":0.00000000},{"price":0.66558,"qty":9466.00000000},{"price":0.66451,"qty":5607.84142498}],"checksum":3869339770,"timestamp":"2024-06-01T22:43:47.568727Z"}]}
{"channel":"book","type":"update","data":[{"symbol":"AUD/USD","bids":[{"price":0.66375,"qty":0.00000000},{"price":0.66347,"qty":2506.00000000}],"asks":[],"checksum":2149734889,"timestamp":"2024-06-01T22:43:47.720984Z"}]}
{"channel":"book","type":"update","data":[{"symbol":"AUD/USD","bids":[{"price":0.66378,"qty":135.48951581}],"asks":[],"checksum":2223689970,"timestamp":"2024-06-01T22:43:47.732805Z"}]}
{"channel":"book","type":"update","data":[{"symbol":"AUD/USD","bids":[{"price":0.66377,"qty":700.86426410}],"asks":[],"checksum":3439528859,"timestamp":"2024-06-01T22:43:47.732934Z"}]}
{"channel":"book","type":"update","data":[{"symbol":"AUD/USD","bids":[],"asks":[{"price":0.66452,"qty":0.00000000},{"price":0.66581,"qty":2955.00000000},{"price":0.66450,"qty":5573.95288867}],"checksum":1128649159,"timestamp":"2024-06-01T22:43:47.869609Z"}]}
{"channel":"book","type":"update","data":[{"symbol":"AUD/USD","bids":[],"asks":[{"price":0.66535,"qty":0.00000000},{"price":0.66581,"qty":2955.00000000}],"checksum":2793477549,"timestamp":"2024-06-01T22:43:50.191971Z"}]}
{"channel":"book","type":"update","data":[{"symbol":"AUD/USD","bids":[],"asks":[{"price":0.66533,"qty":294.01313515}],"checksum":3470594187,"timestamp":"2024-06-01T22:43:50.193146Z"}]}
{"channel":"book","type":"update","data":[{"symbol":"AUD/USD","bids":[{"price":0.66376,"qty":0.00000000},{"price":0.66347,"qty":2506.00000000}],"asks":[],"checksum":3135459303,"timestamp":"2024-06-01T22:43:51.100810Z"}]}
{"channel":"book","type":"update","data":[{"symbol":"AUD/USD","bids":[{"price":0.66382,"qty":14174.06370791}],"asks":[],"checksum":3030472510,"timestamp":"2024-06-01T22:43:51.107077Z"}]}
{"channel":"book","type":"update","data":[{"symbol":"AUD/USD","bids":[{"price":0.66374,"qty":11154.22325218}],"asks":[],"checksum":2927555756,"timestamp":"2024-06-01T22:43:51.107106Z"}]}
{"channel":"book","type":"update","data":[{"symbol":"AUD/USD","bids":[{"price":0.66381,"qty":0.00000000},{"price":0.66353,"qty":2804.00000000}],"asks":[],"checksum":3521531883,"timestamp":"2024-06-01T22:43:51.115396Z"}]}
{"channel":"book","type":"update","data":[{"symbol":"AUD/USD","bids":[{"price":0.66383,"qty":559.47200337}],"asks":[],"checksum":260763070,"timestamp":"2024-06-01T22:43:51.115428Z"}]}
{"channel":"book","type":"update","data":[{"symbol":"AUD/USD","bids":[],"asks":[{"price":0.66536,"qty":0.00000000},{"price":0.66581,"qty":2955.00000000}],"checksum":3889390986,"timestamp":"2024-06-01T22:43:52.795695Z"}]}
{"channel":"book","type":"update","data":[{"symbol":"AUD/USD","bids":[],"asks":[{"price":0.66534,"qty":0.00000000},{"price":0.66595,"qty":3415.09400402}],"checksum":116816707,"timestamp":"2024-06-01T22:43:52.795718Z"}]}
{"channel":"book","type":"update","data":[{"symbol":"AUD/USD","bids":[],"asks":[{"price":0.66536,"qty":32334.34855477}],"checksum":821849381,"timestamp":"2024-06-01T22:43:52.796752Z"}]}
{"channel":"book","type":"update","data":[{"symbol":"AUD/USD","bids":[{"price":0.66377,"qty":253.23426000}],"asks":[],"checksum":2337385485,"timestamp":"2024-06-01T22:43:53.577409Z"}]}
{"channel":"book","type":"update","data":[{"symbol":"AUD/USD","bids":[{"price":0.66378,"qty":0.00000000},{"price":0.66353,"qty":2804.00000000}],"asks":[],"checksum":902482935,"timestamp":"2024-06-01T22:43:53.577526Z"}]}
{"channel":"book","type":"update","data":[{"symbol":"AUD/USD","bids":[{"price":0.66384,"qty":478.12942235}],"asks":[],"checksum":4273965261,"timestamp":"2024-06-01T22:43:53.586899Z"}]}
{"channel":"book","type":"update","data":[{"symbol":"AUD/USD","bids":[{"price":0.66383,"qty":664.46210093}],"asks":[],"checksum":4252620315,"timestamp":"2024-06-01T22:43:53.587093Z"}]}
{"channel":"book","type":"update","data":[{"symbol":"AUD/USD","bids":[],"asks":[{"price":0.66533,"qty":0.00000000},{"price":0.66595,"qty":3415.09400402}],"checksum":1086813622,"timestamp":"2024-06-01T22:43:53.637072Z"}]}
{"channel":"book","type":"update","data":[{"symbol":"AUD/USD","bids":[],"asks":[{"price":0.66535,"qty":264.68521483}],"checksum":3313010274,"timestamp":"2024-06-01T22:43:53.637968Z"}]}
{"channel":"book","type":"update","data":[{"symbol":"AUD/USD","bids":[{"price":0.66382,"qty":0.00000000},{"price":0.66353,"qty":2804.00000000}],"asks":[],"checksum":4146840226,"timestamp":"2024-06-01T22:43:54.467546Z"}]}
{"channel":"book","type":"update","data":[{"symbol":"AUD/USD","bids":[{"price":0.66374,"qty":0.00000000},{"price":0.66347,"qty":2506.00000000}],"asks":[],"checksum":2028288687,"timestamp":"2024-06-01T22:43:54.467615Z"}]}
{"channel":"book","type":"update","data":[{"symbol":"AUD/USD","bids":[{"price":0.66374,"qty":24729.80898055}],"asks":[],"checksum":2562807337,"timestamp":"2024-06-01T22:43:54.473476Z"}]}
{"channel":"book","type":"update","data":[{"symbol":"AUD/USD","bids":[],"asks":[{"price":0.66536,"qty":0.00000000},{"price":0.66595,"qty":3415.09400402}],"checksum":216532424,"timestamp":"2024-06-01T22:43:55.678414Z"}]}
{"channel":"book","type":"update","data":[{"symbol":"AUD/USD","bids":[],"asks":[{"price":0.66534,"qty":8871.83596627}],"checksum":4081390453,"timestamp":"2024-06-01T22:43:55.680846Z"}]}
{"channel":"book","type":"update","data":[{"symbol":"AUD/USD","bids":[],"asks":[{"price":0.66536,"qty":23416.68736860}],"checksum":256732257,"timestamp":"2024-06-01T22:43:55.680940Z"}]}
{"channel":"book","type":"update","data":[{"symbol":"AUD/USD","bids":[{"price":0.66384,"qty":0.00000000},{"price":0.66347,"qty":2506.00000000}],"asks":[],"checksum":4239925960,"timestamp":"2024-06-01T22:43:56.412900Z"}]}
{"channel":"book","type":"update","data":[{"symbol":"AUD/USD","bids":[{"price":0.66383,"qty":559.47200337}],"asks":[],"checksum":3752177040,"timestamp":"2024-06-01T22:43:56.413030Z"}]}
{"channel":"book","type":"update","data":[{"symbol":"AUD/USD","bids":[{"price":0.66375,"qty":583.55708590}],"asks":[],"checksum":3602554932,"timestamp":"2024-06-01T22:43:56.417625Z"}]}
{"channel":"book","type":"update","data":[{"symbol":"AUD/USD","bids":[],"asks":[{"price":0.66535,"qty":0.00000000},{"price":0.66581,"qty":2955.00000000}],"checksum":863921246,"timestamp":"2024-06-01T22:43:57.025663Z"}]}
{"channel":"book","type":"update","data":[{"symbol":"AUD/USD","bids":[],"asks":[{"price":0.66533,"qty":294.01313515}],"checksum":1528979832,"timestamp":"2024-06-01T22:43:57.026620Z"}]}
{"channel":"book","type":"update","data":[{"symbol":"AUD/USD","bids":[{"price":0.66374,"qty":0.00000000},{"price":0.66347,"qty":2506.00000000}],"asks":[],"checksum":2539440722,"timestamp":"2024-06-01T22:43:57.941138Z"}]}
{"channel":"book","type":"update","data":[{"symbol":"AUD/USD","bids":[{"price":0.66376,"qty":24783.52680224}],"asks":[],"checksum":926537134,"timestamp":"2024-06-01T22:43:57.946848Z"}]}
{"channel":"book","type":"update","data":[{"symbol":"AUD/USD","bids":[],"asks":[{"price":0.66449,"qty":171.84142498}],"checksum":1377270915,"timestamp":"2024-06-01T22:43:58.113566Z"}]}
{"channel":"book","type":"update","data":[{"symbol":"AUD/USD","bids":[],"asks":[{"price":0.66451,"qty":171.84142498},{"price":0.66448,"qty":5436.00000000}],"checksum":1737356612,"timestamp":"2024-06-01T22:43:58.129500Z"}]}
{"channel":"book","type":"update","data":[{"symbol":"AUD/USD","bids":[],"asks":[{"price":0.66450,"qty":0.00000000},{"price":0.66544,"qty":3013.00000000},{"price":0.66447,"qty":5574.01386444}],"checksum":1661317715,"timestamp":"2024-06-01T22:43:58.132560Z"}]}
{"channel":"book","type":"update","data":[{"symbol":"AUD/USD","bids":[],"asks":[{"price":0.66448,"qty":0.00000000},{"price":0.66544,"qty":3013.00000000},{"price":0.66446,"qty":5436.00000000}],"checksum":2447976396,"timestamp":"2024-06-01T22:43:58.161378Z"}]}
{"channel":"book","type":"update","data":[{"symbol":"AUD/USD","bids":[],"asks":[{"price":0.66447,"qty":0.00000000},{"price":0.66544,"qty":3013.00000000},{"price":0.66508,"qty":5574.01386444}],"checksum":611764870,"timestamp":"2024-06-01T22:43:58.164443Z"}]}
{"channel":"book","type":"update","data":[{"symbol":"AUD/USD","bids":[],"asks":[{"price":0.66509,"qty":0.00000000},{"price":0.66544,"qty":3013.00000000}],"checksum":2424847302,"timestamp":"2024-06-01T22:43:58.168144Z"}]}
{"channel":"book","type":"update","data":[{"symbol":"AUD/USD","bids":[],"asks":[{"price":0.66507,"qty":2297.49030000}],"checksum":1708811017,"timestamp":"2024-06-01T22:43:58.168175Z"}]}
{"channel":"book","type":"update","data":[{"symbol":"AUD/USD","bids":[],"asks":[{"price":0.66508,"qty":0.00000000},{"price":0.66544,"qty":3013.00000000},{"price":0.66532,"qty":5574.01386444}],"checksum":4052332908,"timestamp":"2024-06-01T22:43:58.171498Z"}]}
{"channel":"book","type":"update","data":[{"symbol":"AUD/USD","bids":[],"asks":[{"price":0.66532,"qty":0.00000000},{"price":0.66544,"qty":3013.00000000},{"price":0.66506,"qty":5574.01386444}],"checksum":2692652048,"timestamp":"2024-06-01T22:43:58.174804Z"}]}
{"channel":"book","type":"update","data":[{"symbol":"AUD/USD","bids":[],"asks":[{"price":0.66506,"qty":0.00000000},{"price":0.66544,"qty":3013.00000000},{"price":0.66505,"qty":5574.01386444}],"checksum":623600513,"timestamp":"2024-06-01T22:43:58.177764Z"}]}
{"channel":"book","type":"update","data":[{"symbol":"AUD/USD","bids":[],"asks":[{"price":0.66505,"qty":0.00000000},{"price":0.66544,"qty":3013.00000000},{"price":0.66506,"qty":5574.01386444}],"checksum":2692652048,"timestamp":"2024-06-01T22:43:58.181054Z"}]}
{"channel":"book","type":"update","data":[{"symbol":"AUD/USD","bids":[],"asks":[{"price":0.66506,"qty":0.00000000},{"price":0.66544,"qty":3013.00000000},{"price":0.66505,"qty":5574.01386444}],"checksum":623600513,"timestamp":"2024-06-01T22:43:58.184877Z"}]}
{"channel":"book","type":"update","data":[{"symbol":"AUD/USD","bids":[],"asks":[{"price":0.66505,"qty":0.00000000},{"price":0.66544,"qty":3013.00000000},{"price":0.66506,"qty":5574.01386444}],"checksum":2692652048,"timestamp":"2024-06-01T22:43:58.189127Z"}]}
{"channel":"book","type":"update","data":[{"symbol":"AUD/USD","bids":[],"asks":[{"price":0.66506,"qty":0.00000000},{"price":0.66544,"qty":3013.00000000},{"price":0.66505,"qty":5574.05664489}],"checksum":211015425,"timestamp":"2024-06-01T22:43:58.192295Z"}]}
{"channel":"book","type":"update","data":[{"symbol":"AUD/USD","bids":[],"asks":[{"price":0.66505,"qty":0.00000000},{"price":0.66544,"qty":3013.00000000},{"price":0.66504,"qty":5574.05664489}],"checksum":1885306254,"timestamp":"2024-06-01T22:43:58.195567Z"}]}
{"channel":"book","type":"update","data":[{"symbol":"AUD/USD","bids":[],"asks":[{"price":0.66504,"qty":0.00000000},{"price":0.66544,"qty":3013.00000000},{"price":0.66503,"qty":5574.05664489}],"checksum":3712560738,"timestamp":"2024-06-01T22:43:58.198661Z"}]}
{"channel":"book","type":"update","data":[{"symbol":"AUD/USD","bids":[],"asks":[{"price":0.66507,"qty":0.00000000},{"price":0.66544,"qty":3013.00000000}],"checksum":1826760749,"timestamp":"2024-06-01T22:43:58.203387Z"}]}
{"channel":"book","type":"update","data":[{"symbol":"AUD/USD","bids":[],"asks":[{"price":0.66502,"qty":2297.49030000}],"checksum":3469575887,"timestamp":"2024-06-01T22:43:58.203680Z"}]}
{"channel":"book","type":"update","data":[{"symbol":"AUD/USD","bids":[],"asks":[{"price":0.66503,"qty":0.00000000},{"price":0.66544,"qty":3013.00000000},{"price":0.66501,"qty":5574.05664489}],"checksum":3389334530,"timestamp":"2024-06-01T22:43:58.232919Z"}]}
{"channel":"book","type":"update","data":[{"symbol":"AUD/USD","bids":[],"asks":[{"price":0.66502,"qty":0.00000000},{"price":0.66544,"qty":3013.00000000}],"checksum":2507898163,"timestamp":"2024-06-01T22:43:58.258205Z"}]}
{"channel":"book","type":"update","data":[{"symbol":"AUD/USD","bids":[],"asks":[{"price":0.66500,"qty":2297.49030000}],"checksum":915665928,"timestamp":"2024-06-01T22:43:58.258279Z"}]}
{"channel":"book","type":"update","data":[{"symbol":"AUD/USD","bids":[],"asks":[{"price":0.66501,"qty":0.00000000},{"price":0.66544,"qty":3013.00000000},{"price":0.66532,"qty":5574.05664489}],"checksum":3982412691,"timestamp":"2024-06-01T22:43:58.261203Z"}]}
{"channel":"book","type":"update","data":[{"symbol":"AUD/USD","bids":[],"asks":[{"price":0.66451,"qty":0.00000000},{"price":0.66544,"qty":3013.00000000}],"checksum":3776919151,"timestamp":"2024-06-01T22:43:58.281306Z"}]}
{"channel":"book","type":"update","data":[{"symbol":"AUD/USD","bids":[],"asks":[{"price":0.66446,"qty":0.00000000},{"price":0.66558,"qty":9466.00000000},{"price":0.66499,"qty":5436.00000000}],"checksum":1869525510,"timestamp":"2024-06-01T22:43:58.286804Z"}]}
{"channel":"book","type":"update","data":[{"symbol":"AUD/USD","bids":[],"asks":[{"price":0.66498,"qty":2297.49030000}],"checksum":1792105502,"timestamp":"2024-06-01T22:43:58.292607Z"}]}
{"channel":"book","type":"update","data":[{"symbol":"AUD/USD","bids":[],"asks":[{"price":0.66500,"qty":0.00000000},{"price":0.66544,"qty":3013.00000000}],"checksum":3865274544,"timestamp":"2024-06-01T22:43:58.292630Z"}]}
{"channel":"book","type":"update","data":[{"symbol":"AUD/USD","bids":[],"asks":[{"price":0.66532,"qty":0.00000000},{"price":0.66558,"qty":9466.00000000},{"price":0.66497,"qty":5574.05664489}],"checksum":2788842184,"timestamp":"2024-06-01T22:43:58.300273Z"}]}
{"channel":"book","type":"update","data":[{"symbol":"AUD/USD","bids":[],"asks":[{"price":0.66498,"qty":0.00000000},{"price":0.66558,"qty":9466.00000000}],"checksum":1229532619,"timestamp":"2024-06-01T22:43:58.312300Z"}]}
{"channel":"book","type":"update","data":[{"symbol":"AUD/USD","bids":[],"asks":[{"price":0.66496,"qty":2297.49030000}],"checksum":1888526594,"timestamp":"2024-06-01T22:43:58.312381Z"}]}
{"channel":"book","type":"update","data":[{"symbol":"AUD/USD","bids":[],"asks":[{"price":0.66497,"qty":0.00000000},{"price":0.66558,"qty":9466.00000000},{"price":0.66498,"qty":5574.05664489}],"checksum":4158012458,"timestamp":"2024-06-01T22:43:58.315334Z"}]}
{"channel":"book","type":"update","data":[{"symbol":"AUD/USD","bids":[],"asks":[{"price":0.66499,"qty":0.00000000},{"price":0.66558,"qty":9466.00000000},{"price":0.66496,"qty":7733.49030000}],"checksum":906412072,"timestamp":"2024-06-01T22:43:58.318670Z"}]}
{"channel":"book","type":"update","data":[{"symbol":"AUD/USD","bids":[],"asks":[{"price":0.66496,"qty":2297.49030000},{"price":0.66495,"qty":5436.00000000}],"checksum":3839431613,"timestamp":"2024-06-01T22:43:58.350641Z"}]}
{"channel":"book","type":"update","data":[{"symbol":"AUD/USD","bids":[],"asks":[{"price":0.66494,"qty":2297.49030000}],"checksum":759005796,"timestamp":"2024-06-01T22:43:58.373444Z"}]}
{"channel":"book","type":"update","data":[{"symbol":"AUD/USD","bids":[],"asks":[{"price":0.66496,"qty":0.00000000},{"price":0.66544,"qty":3013.00000000}],"checksum":991725257,"timestamp":"2024-06-01T22:43:58.373495Z"}]}
{"channel":"book","type":"update","data":[{"symbol":"AUD/USD","bids":[],"asks":[{"price":0.66495,"qty":0.00000000},{"price":0.66558,"qty":9466.00000000},{"price":0.66493,"qty":5436.00000000}],"checksum":3788291625,"timestamp":"2024-06-01T22:43:58.382409Z"}]}
{"channel":"book","type":"update","data":[{"symbol":"AUD/USD","bids":[],"asks":[{"price":0.66492,"qty":2297.49030000}],"checksum":1860183332,"timestamp":"2024-06-01T22:43:58.402585Z"}]}
{"channel":"book","type":"update","data":[{"symbol":"AUD/USD","bids":[],"asks":[{"price":0.66494,"qty":0.00000000},{"price":0.66544,"qty":3013.00000000}],"checksum":2170057879,"timestamp":"2024-06-01T22:43:58.402667Z"}]}
{"channel":"book","type":"update","data":[{"symbol":"AUD/USD","bids":[],"asks":[{"price":0.66493,"qty":0.00000000},{"price":0.66558,"qty":9466.00000000},{"price":0.66491,"qty":5436.00000000}],"checksum":2173612566,"timestamp":"2024-06-01T22:43:58.413977Z"}]}
{"channel":"book","type":"update","data":[{"symbol":"AUD/USD","bids":[],"asks":[{"price":0.66498,"qty":0.00000000},{"price":0.66558,"qty":9466.00000000},{"price":0.66490,"qty":5574.05762706}],"checksum":2846718379,"timestamp":"2024-06-01T22:43:58.434905Z"}]}
{"channel":"book","type":"update","data":[{"symbol":"AUD/USD","bids":[],"asks":[{"price":0.66489,"qty":2297.49030000}],"checksum":237386660,"timestamp":"2024-06-01T22:43:58.444619Z"}]}
{"channel":"book","type":"update","data":[{"symbol":"AUD/USD","bids":[],"asks":[{"price":0.66492,"qty":0.00000000},{"price":0.66544,"qty":3013.00000000}],"checksum":4081544125,"timestamp":"2024-06-01T22:43:58.444678Z"}]}
{"channel":"book","type":"update","data":[{"symbol":"AUD/USD","bids":[],"asks":[{"price":0.66491,"qty":0.00000000},{"price":0.66558,"qty":9466.00000000},{"price":0.66489,"qty":7733.49030000}],"checksum":1645268805,"timestamp":"2024-06-01T22:43:58.446248Z"}]}
{"channel":"book","type":"update","data":[{"symbol":"AUD/USD","bids":[],"asks":[{"price":0.66489,"qty":2297.49030000},{"price":0.66488,"qty":5436.00000000}],"checksum":1641879665,"timestamp":"2024-06-01T22:43:58.477432Z"}]}
{"channel":"book","type":"update","data":[{"symbol":"AUD/USD","bids":[],"asks":[{"price":0.66489,"qty":0.00000000},{"price":0.66558,"qty":9466.00000000}],"checksum":3437133525,"timestamp":"2024-06-01T22:43:58.481851Z"}]}
{"channel":"book","type":"update","data":[{"symbol":"AUD/USD","bids":[],"asks":[{"price":0.66487,"qty":2297.49030000}],"checksum":3564231186,"timestamp":"2024-06-01T22:43:58.482100Z"}]}
{"channel":"book","type":"update","data":[{"symbol":"AUD/USD","bids":[],"asks":[{"price":0.66488,"qty":0.00000000},{"price":0.66558,"qty":9466.00000000},{"price":0.66486,"qty":5436.00000000}],"checksum":288795001,"timestamp":"2024-06-01T22:43:58.508948Z"}]}
{"channel":"book","type":"update","data":[{"symbol":"AUD/USD","bids":[],"asks":[{"price":0.66485,"qty":2297.49030000}],"checksum":1682782230,"timestamp":"2024-06-01T22:43:58.521994Z"}]}
{"channel":"book","type":"update","data":[{"symbol":"AUD/USD","bids":[],"asks":[{"price":0.66487,"qty":0.00000000},{"price":0.66544,"qty":3013.00000000}],"checksum":299921400,"timestamp":"2024-06-01T22:43:58.522058Z"}]}
{"channel":"book","type":"update","data":[{"symbol":"AUD/USD","bids":[],"asks":[{"price":0.66486,"qty":0.00000000},{"price":0.66558,"qty":9466.00000000},{"price":0.66484,"qty":5436.00000000}],"checksum":3458595468,"timestamp":"2024-06-01T22:43:58.540915Z"}]}
{"channel":"book","type":"update","data":[{"symbol":"AUD/USD","bids":[],"asks":[{"price":0.66485,"qty":0.00000000},{"price":0.66558,"qty":9466.00000000}],"checksum":2040822327,"timestamp":"2024-06-01T22:43:58.544512Z"}]}
{"channel":"book","type":"update","data":[{"symbol":"AUD/USD","bids":[],"asks":[{"price":0.66483,"qty":2297.49030000}],"checksum":351650412,"timestamp":"2024-06-01T22:43:58.544796Z"}]}
{"channel":"book","type":"update","data":[{"symbol":"AUD/USD","bids":[],"asks":[{"price":0.66484,"qty":0.00000000},{"price":0.66558,"qty":9466.00000000},{"price":0.66482,"qty":5436.00000000}],"checksum":1952516306,"timestamp":"2024-06-01T22:43:58.572477Z"}]}
{"channel":"book","type":"update","data":[{"symbol":"AUD/USD","bids":[],"asks":[{"price":0.66536,"qty":0.00000000},{"price":0.66558,"qty":9466.00000000}],"checksum":2036862821,"timestamp":"2024-06-01T22:43:58.580466Z"}]}
{"channel":"book","type":"update","data":[{"symbol":"AUD/USD","bids":[],"asks":[{"price":0.66534,"qty":0.00000000},{"price":0.66581,"qty":2955.00000000}],"checksum":3592623561,"timestamp":"2024-06-01T22:43:58.580551Z"}]}
{"channel":"book","type":"update","data":[{"symbol":"AUD/USD","bids":[],"asks":[{"price":0.66493,"qty":35267.16262833}],"checksum":1091536610,"timestamp":"2024-06-01T22:43:58.581359Z"}]}
{"channel":"book","type":"update","data":[{"symbol":"AUD/USD","bids":[],"asks":[{"price":0.66483,"qty":0.00000000},{"price":0.66581,"qty":2955.00000000}],"checksum":955117528,"timestamp":"2024-06-01T22:43:58.584368Z"}]}
{"channel":"book","type":"update","data":[{"symbol":"AUD/USD","bids":[],"asks":[{"price":0.66481,"qty":2297.49030000}],"checksum":1104756835,"timestamp":"2024-06-01T22:43:58.584509Z"}]}
{"channel":"book","type":"update","data":[{"symbol":"AUD/USD","bids":[],"asks":[{"price":0.66482,"qty":0.00000000},{"price":0.66581,"qty":2955.00000000},{"price":0.66480,"qty":5436.00000000}],"checksum":2652689687,"timestamp":"2024-06-01T22:43:58.604630Z"}]}
{"channel":"book","type":"update","data":[{"symbol":"AUD/USD","bids":[],"asks":[{"price":0.66479,"qty":2297.49030000}],"checksum":1362246596,"timestamp":"2024-06-01T22:43:58.615779Z"}]}
{"channel":"book","type":"update","data":[{"symbol":"AUD/USD","bids":[],"asks":[{"price":0.66481,"qty":0.00000000},{"price":0.66558,"qty":9466.00000000}],"checksum":739283457,"timestamp":"2024-06-01T22:43:58.615873Z"}]}
{"channel":"book","type":"update","data":[{"symbol":"AUD/USD","bids":[],"asks":[{"price":0.66480,"qty":0.00000000},{"price":0.66581,"qty":2955.00000000},{"price":0.66478,"qty":5436.00000000}],"checksum":1016921890,"timestamp":"2024-06-01T22:43:58.635703Z"}]}
{"channel":"book","type":"update","data":[{"symbol":"AUD/USD","bids":[],"asks":[{"price":0.66490,"qty":0.00000000},{"price":0.66581,"qty":2955.00000000},{"price":0.66478,"qty":11010.05836436}],"checksum":3263033276,"timestamp":"2024-06-01T22:43:58.636621Z"}]}
{"channel":"book","type":"update","data":[{"symbol":"AUD/USD","bids":[],"asks":[{"price":0.66479,"qty":0.00000000},{"price":0.66595,"qty":3415.09400402}],"checksum":1403285567,"timestamp":"2024-06-01T22:43:58.656530Z"}]}
{"channel":"book","type":"update","data":[{"symbol":"AUD/USD","bids":[],"asks":[{"price":0.66477,"qty":2297.49030000}],"checksum":3730316512,"timestamp":"2024-06-01T22:43:58.656659Z"}]}
{"channel":"book","type":"update","data":[{"symbol":"AUD/USD","bids":[],"asks":[{"price":0.66478,"qty":5574.05836436},{"price":0.66476,"qty":5436.00000000}],"checksum":3931277271,"timestamp":"2024-06-01T22:43:58.667257Z"}]}
{"channel":"book","type":"update","data":[{"symbol":"AUD/USD","bids":[],"asks":[{"price":0.66477,"qty":0.00000000},{"price":0.66581,"qty":2955.00000000}],"checksum":3508500861,"timestamp":"2024-06-01T22:43:58.684145Z"}]}
{"channel":"book","type":"update","data":[{"symbol":"AUD/USD","bids":[],"asks":[{"price":0.66475,"qty":2297.49030000}],"checksum":3934536022,"timestamp":"2024-06-01T22:43:58.684161Z"}]}
{"channel":"book","type":"update","data":[{"symbol":"AUD/USD","bids":[],"asks":[{"price":0.66476,"qty":0.00000000},{"price":0.66581,"qty":2955.00000000},{"price":0.66474,"qty":5436.00000000}],"checksum":893506594,"timestamp":"2024-06-01T22:43:58.698782Z"}]}
{"channel":"book","type":"update","data":[{"symbol":"AUD/USD","bids":[],"asks":[{"price":0.66475,"qty":0.00000000},{"price":0.66581,"qty":2955.00000000}],"checksum":1369736557,"timestamp":"2024-06-01T22:43:58.713875Z"}]}
{"channel":"book","type":"update","data":[{"symbol":"AUD/USD","bids":[],"asks":[{"price":0.66473,"qty":2297.49030000}],"checksum":4019317954,"timestamp":"2024-06-01T22:43:58.713891Z"}]}
{"channel":"book","type":"update","data":[{"symbol":"AUD/USD","bids":[],"asks":[{"price":0.66474,"qty":0.00000000},{"price":0.66581,"qty":2955.00000000},{"price":0.66472,"qty":5436.00000000}],"checksum":2399479420,"timestamp":"2024-06-01T22:43:58.731012Z"}]}
{"channel":"book","type":"update","data":[{"symbol":"AUD/USD","bids":[],"asks":[{"price":0.66471,"qty":2297.49030000}],"checksum":1583692873,"timestamp":"2024-06-01T22:43:58.742336Z"}]}
{"channel":"book","type":"update","data":[{"symbol":"AUD/USD","bids":[],"asks":[{"price":0.66473,"qty":0.00000000},{"price":0.66558,"qty":9466.00000000}],"checksum":2413027581,"timestamp":"2024-06-01T22:43:58.742366Z"}]}
{"channel":"book","type":"update","data":[{"symbol":"AUD/USD","bids":[],"asks":[{"price":0.66472,"qty":0.00000000},{"price":0.66581,"qty":2955.00000000},{"price":0.66470,"qty":5436.00000000}],"checksum":1343649161,"timestamp":"2024-06-01T22:43:58.762514Z"}]}
{"channel":"book","type":"update","data":[{"symbol":"AUD/USD","bids":[],"asks":[{"price":0.66471,"qty":0.00000000},{"price":0.66581,"qty":2955.00000000}],"checksum":2342681356,"timestamp":"2024-06-01T22:43:58.779822Z"}]}
{"channel":"book","type":"update","data":[{"symbol":"AUD/USD","bids":[],"asks":[{"price":0.66469,"qty":2297.49030000}],"checksum":2979815511,"timestamp":"2024-06-01T22:43:58.780113Z"}]}
{"channel":"book","type":"update","data":[{"symbol":"AUD/USD","bids":[],"asks":[{"price":0.66470,"qty":0.00000000},{"price":0.66581,"qty":2955.00000000},{"price":0.66468,"qty":5436.00000000}],"checksum":4231871551,"timestamp":"2024-06-01T22:43:58.794094Z"}]}
{"channel":"book","type":"update","data":[{"symbol":"AUD/USD","bids":[],"asks":[{"price":0.66478,"qty":0.00000000},{"price":0.66581,"qty":2955.00000000},{"price":0.66468,"qty":11010.05889288}],"checksum":3967409900,"timestamp":"2024-06-01T22:43:58.795977Z"}]}
{"channel":"book","type":"update","data":[{"symbol":"AUD/USD","bids":[],"asks":[{"price":0.66469,"qty":0.00000000},{"price":0.66595,"qty":3415.09400402}],"checksum":364879427,"timestamp":"2024-06-01T22:43:58.802853Z"}]}
{"channel":"book","type":"update","data":[{"symbol":"AUD/USD","bids":[],"asks":[{"price":0.66467,"qty":2297.49030000}],"checksum":3171982145,"timestamp":"2024-06-01T22:43:58.803270Z"}]}
{"channel":"book","type":"update","data":[{"symbol":"AUD/USD","bids":[],"asks":[{"price":0.66468,"qty":5574.05889288},{"price":0.66466,"qty":5436.00000000}],"checksum":1595049232,"timestamp":"2024-06-01T22:43:58.825570Z"}]}
{"channel":"book","type":"update","data":[{"symbol":"AUD/USD","bids":[],"asks":[{"price":0.66467,"qty":0.00000000},{"price":0.66581,"qty":2955.00000000}],"checksum":1958711886,"timestamp":"2024-06-01T22:43:58.846442Z"}]}
{"channel":"book","type":"update","data":[{"symbol":"AUD/USD","bids":[],"asks":[{"price":0.66465,"qty":2297.49030000}],"checksum":1606697873,"timestamp":"2024-06-01T22:43:58.846566Z"}]}
{"channel":"book","type":"update","data":[{"symbol":"AUD/USD","bids":[],"asks":[{"price":0.66466,"qty":0.00000000},{"price":0.66581,"qty":2955.00000000},{"price":0.66464,"qty":5436.00000000}],"checksum":2147604197,"timestamp":"2024-06-01T22:43:58.888356Z"}]}
{"channel":"book","type":"update","data":[{"symbol":"AUD/USD","bids":[],"asks":[{"price":0.66467,"qty":2297.49030000}],"checksum":128303021,"timestamp":"2024-06-01T22:43:58.910033Z"}]}
{"channel":"book","type":"update","data":[{"symbol":"AUD/USD","bids":[],"asks":[{"price":0.66465,"qty":0.00000000},{"price":0.66558,"qty":9466.00000000}],"checksum":3752425728,"timestamp":"2024-06-01T22:43:58.910141Z"}]}
{"channel":"book","type":"update","data":[{"symbol":"AUD/USD","bids":[],"asks":[{"price":0.66468,"qty":0.00000000},{"price":0.66581,"qty":2955.00000000},{"price":0.66463,"qty":5574.05889288}],"checksum":817739746,"timestamp":"2024-06-01T22:43:58.988226Z"}]}
