{"channel":"book","type":"snapshot","data":[{"symbol":"BCH/AUD","bids":[{"price":695.95,"qty":0.23037383},{"price":695.93,"qty":6.00000000},{"price":695.80,"qty":3.30194067},{"price":695.79,"qty":1.00000000},{"price":695.57,"qty":2.00000000},{"price":695.56,"qty":0.26329050},{"price":695.29,"qty":1.00000000},{"price":695.10,"qty":0.03244644},{"price":694.62,"qty":2.74650750},{"price":694.61,"qty":10.93257000}],"asks":[{"price":697.74,"qty":6.00000000},{"price":697.75,"qty":1.00000000},{"price":697.76,"qty":0.26329050},{"price":698.25,"qty":0.02500000},{"price":698.60,"qty":2.58366799},{"price":698.61,"qty":2.74650750},{"price":698.83,"qty":10.93257000},{"price":699.08,"qty":0.26329050},{"price":700.39,"qty":7.88802300},{"price":700.40,"qty":1.00000000}],"checksum":657755453}]}
{"channel":"book","type":"update","data":[{"symbol":"BCH/AUD","bids":[{"price":695.93,"qty":0.00000000},{"price":694.58,"qty":0.26329050}],"asks":[],"checksum":2050044447,"timestamp":"2024-06-01T22:43:43.143955Z"}]}
{"channel":"book","type":"update","data":[{"symbol":"BCH/AUD","bids":[{"price":695.81,"qty":6.00000000}],"asks":[],"checksum":850045494,"timestamp":"2024-06-01T22:43:43.144059Z"}]}
{"channel":"book","type":"update","data":[{"symbol":"BCH/AUD","bids":[{"price":695.80,"qty":0.00000000},{"price":694.58,"qty":0.26329050}],"asks":[],"checksum":2146891327,"timestamp":"2024-06-01T22:43:43.163535Z"}]}
{"channel":"book","type":"update","data":[{"symbol":"BCH/AUD","bids":[{"price":695.82,"qty":3.30184586}],"asks":[],"checksum":235188320,"timestamp":"2024-06-01T22:43:43.163559Z"}]}
{"channel":"book","type":"update","data":[{"symbol":"BCH/AUD","bids":[{"price":695.83,"qty":6.00000000}],"asks":[],"checksum":2612487234,"timestamp":"2024-06-01T22:43:43.647576Z"}]}
{"channel":"book","type":"update","data":[{"symbol":"BCH/AUD","bids":[{"price":695.81,"qty":0.00000000},{"price":694.61,"qty":10.93257000}],"asks":[],"checksum":48363076,"timestamp":"2024-06-01T22:43:43.653044Z"}]}
{"channel":"book","type":"update","data":[{"symbol":"BCH/AUD","bids":[{"price":695.82,"qty":0.00000000},{"price":694.58,"qty":0.26329050}],"asks":[],"checksum":2868009635,"timestamp":"2024-06-01T22:43:43.676109Z"}]}
{"channel":"book","type":"update","data":[{"symbol":"BCH/AUD","bids":[{"price":695.84,"qty":3.30175091}],"asks":[],"checksum":1110181650,"timestamp":"2024-06-01T22:43:43.676289Z"}]}
{"channel":"book","type":"update","data":[{"symbol":"BCH/AUD","bids":[{"price":695.85,"qty":6.00000000}],"asks":[],"checksum":2909481699,"timestamp":"2024-06-01T22:43:44.144204Z"}]}
{"channel":"book","type":"update","data":[{"symbol":"BCH/AUD","bids":[{"price":695.83,"qty":0.00000000},{"price":694.61,"qty":10.93257000}],"asks":[],"checksum":2201157398,"timestamp":"2024-06-01T22:43:44.149429Z"}]}
{"channel":"book","type":"update","data":[{"symbol":"BCH/AUD","bids":[{"price":695.84,"qty":0.00000000},{"price":694.58,"qty":0.26329050}],"asks":[],"checksum":244230470,"timestamp":"2024-06-01T22:43:44.166012Z"}]}
{"channel":"book","type":"update","data":[{"symbol":"BCH/AUD","bids":[{"price":695.86,"qty":3.30165596}],"asks":[],"checksum":1440614657,"timestamp":"2024-06-01T22:43:44.166289Z"}]}
{"channel":"book","type":"update","data":[{"symbol":"BCH/AUD","bids":[{"price":695.87,"qty":6.00000000}],"asks":[],"checksum":3985316081,"timestamp":"2024-06-01T22:43:44.642784Z"}]}
{"channel":"book","type":"update","data":[{"symbol":"BCH/AUD","bids":[{"price":695.85,"qty":0.00000000},{"price":694.61,"qty":10.93257000}],"asks":[],"checksum":278373578,"timestamp":"2024-06-01T22:43:44.649298Z"}]}
{"channel":"book","type":"update","data":[{"symbol":"BCH/AUD","bids":[{"price":695.88,"qty":3.30156117}],"asks":[],"checksum":1326259126,"timestamp":"2024-06-01T22:43:44.664657Z"}]}
{"channel":"book","type":"update","data":[{"symbol":"BCH/AUD","bids":[{"price":695.86,"qty":0.00000000},{"price":694.61,"qty":10.93257000}],"asks":[],"checksum":114344270,"timestamp":"2024-06-01T22:43:44.664681Z"}]}
{"channel":"book","type":"update","data":[{"symbol":"BCH/AUD","bids":[{"price":695.88,"qty":0.00000000},{"price":694.58,"qty":0.26329050}],"asks":[],"checksum":3683255770,"timestamp":"2024-06-01T22:43:44.909523Z"}]}
{"channel":"book","type":"update","data":[{"symbol":"BCH/AUD","bids":[{"price":695.96,"qty":3.30118161}],"asks":[],"checksum":2376804929,"timestamp":"2024-06-01T22:43:44.909566Z"}]}
{"channel":"book","type":"update","data":[{"symbol":"BCH/AUD","bids":[{"price":695.97,"qty":6.00000000}],"asks":[],"checksum":3702341681,"timestamp":"2024-06-01T22:43:44.915215Z"}]}
{"channel":"book","type":"update","data":[{"symbol":"BCH/AUD","bids":[{"price":695.96,"qty":0.00000000},{"price":694.61,"qty":10.93257000}],"asks":[],"checksum":4052633993,"timestamp":"2024-06-01T22:43:44.940551Z"}]}
{"channel":"book","type":"update","data":[{"symbol":"BCH/AUD","bids":[{"price":695.98,"qty":3.30108669}],"asks":[],"checksum":1570986303,"timestamp":"2024-06-01T22:43:44.940704Z"}]}
{"channel":"book","type":"update","data":[{"symbol":"BCH/AUD","bids":[{"price":695.97,"qty":0.00000000},{"price":694.61,"qty":10.93257000}],"asks":[],"checksum":1736761644,"timestamp":"2024-06-01T22:43:44.945754Z"}]}
{"channel":"book","type":"update","data":[{"symbol":"BCH/AUD","bids":[{"price":695.98,"qty":0.00000000},{"price":694.58,"qty":0.26329050}],"asks":[],"checksum":3683255770,"timestamp":"2024-06-01T22:43:44.970957Z"}]}
{"channel":"book","type":"update","data":[{"symbol":"BCH/AUD","bids":[{"price":695.96,"qty":3.30118161}],"asks":[],"checksum":2376804929,"timestamp":"2024-06-01T22:43:44.971119Z"}]}
{"channel":"book","type":"update","data":[{"symbol":"BCH/AUD","bids":[{"price":695.96,"qty":0.00000000},{"price":694.58,"qty":0.26329050}],"asks":[],"checksum":3683255770,"timestamp":"2024-06-01T22:43:45.074355Z"}]}
{"channel":"book","type":"update","data":[{"symbol":"BCH/AUD","bids":[{"price":695.88,"qty":3.30156117}],"asks":[],"checksum":114344270,"timestamp":"2024-06-01T22:43:45.074544Z"}]}
{"channel":"book","type":"update","data":[{"symbol":"BCH/AUD","bids":[{"price":695.96,"qty":3.30118161}],"asks":[],"checksum":2204605091,"timestamp":"2024-06-01T22:43:45.100415Z"}]}
{"channel":"book","type":"update","data":[{"symbol":"BCH/AUD","bids":[{"price":695.88,"qty":0.00000000},{"price":694.61,"qty":10.93257000}],"asks":[],"checksum":2376804929,"timestamp":"2024-06-01T22:43:45.100556Z"}]}
{"channel":"book","type":"update","data":[{"symbol":"BCH/AUD","bids":[{"price":695.97,"qty":6.00000000}],"asks":[],"checksum":3702341681,"timestamp":"2024-06-01T22:43:45.142622Z"}]}
{"channel":"book","type":"update","data":[{"symbol":"BCH/AUD","bids":[{"price":695.87,"qty":0.00000000},{"price":694.61,"qty":10.93257000}],"asks":[],"checksum":2885027392,"timestamp":"2024-06-01T22:43:45.147627Z"}]}
{"channel":"book","type":"update","data":[{"symbol":"BCH/AUD","bids":[{"price":695.98,"qty":3.30108669}],"asks":[],"checksum":1728586947,"timestamp":"2024-06-01T22:43:45.182241Z"}]}
{"channel":"book","type":"update","data":[{"symbol":"BCH/AUD","bids":[{"price":695.96,"qty":0.00000000},{"price":694.61,"qty":10.93257000}],"asks":[],"checksum":1288643934,"timestamp":"2024-06-01T22:43:45.182313Z"}]}
{"channel":"book","type":"update","data":[{"symbol":"BCH/AUD","bids":[{"price":695.99,"qty":6.00000000}],"asks":[],"checksum":233596474,"timestamp":"2024-06-01T22:43:45.187671Z"}]}
{"channel":"book","type":"update","data":[{"symbol":"BCH/AUD","bids":[{"price":695.98,"qty":0.00000000},{"price":694.61,"qty":10.93257000}],"asks":[],"checksum":2016090959,"timestamp":"2024-06-01T22:43:45.210879Z"}]}
{"channel":"book","type":"update","data":[{"symbol":"BCH/AUD","bids":[{"price":695.80,"qty":3.30194070}],"asks":[],"checksum":2320640252,"timestamp":"2024-06-01T22:43:45.211095Z"}]}
{"channel":"book","type":"update","data":[{"symbol":"BCH/AUD","bids":[{"price":695.99,"qty":0.00000000},{"price":694.61,"qty":10.93257000}],"asks":[],"checksum":700553980,"timestamp":"2024-06-01T22:43:45.643996Z"}]}
{"channel":"book","type":"update","data":[{"symbol":"BCH/AUD","bids":[{"price":695.97,"qty":0.00000000},{"price":694.58,"qty":0.26329050}],"asks":[],"checksum":1577390021,"timestamp":"2024-06-01T22:43:46.644062Z"}]}
{"channel":"book","type":"update","data":[{"symbol":"BCH/AUD","bids":[{"price":695.81,"qty":6.00000000}],"asks":[],"checksum":3407233623,"timestamp":"2024-06-01T22:43:46.644233Z"}]}
{"channel":"book","type":"update","data":[{"symbol":"BCH/AUD","bids":[{"price":695.82,"qty":3.30184578}],"asks":[],"checksum":4275495979,"timestamp":"2024-06-01T22:43:46.650886Z"}]}
{"channel":"book","type":"update","data":[{"symbol":"BCH/AUD","bids":[{"price":695.80,"qty":0.00000000},{"price":694.61,"qty":10.93257000}],"asks":[],"checksum":1625872628,"timestamp":"2024-06-01T22:43:46.651038Z"}]}
{"channel":"book","type":"update","data":[{"symbol":"BCH/AUD","bids":[{"price":695.83,"qty":6.00000000}],"asks":[],"checksum":4068764260,"timestamp":"2024-06-01T22:43:47.142550Z"}]}
{"channel":"book","type":"update","data":[{"symbol":"BCH/AUD","bids":[{"price":695.81,"qty":0.00000000},{"price":694.61,"qty":10.93257000}],"asks":[],"checksum":3498393783,"timestamp":"2024-06-01T22:43:47.147884Z"}]}
{"channel":"book","type":"update","data":[{"symbol":"BCH/AUD","bids":[{"price":695.82,"qty":0.00000000},{"price":694.58,"qty":0.26329050}],"asks":[],"checksum":2868009635,"timestamp":"2024-06-01T22:43:47.165633Z"}]}
{"channel":"book","type":"update","data":[{"symbol":"BCH/AUD","bids":[{"price":695.84,"qty":3.30175091}],"asks":[],"checksum":1110181650,"timestamp":"2024-06-01T22:43:47.166020Z"}]}
{"channel":"book","type":"update","data":[{"symbol":"BCH/AUD","bids":[{"price":695.95,"qty":0.00000000},{"price":694.58,"qty":0.26329050},{"price":695.96,"qty":0.23037052}],"asks":[],"checksum":304043930,"timestamp":"2024-06-01T22:43:47.264897Z"}]}
{"channel":"book","type":"update","data":[{"symbol":"BCH/AUD","bids":[{"price":695.85,"qty":6.00000000}],"asks":[],"checksum":2605358739,"timestamp":"2024-06-01T22:43:47.269976Z"}]}
{"channel":"book","type":"update","data":[{"symbol":"BCH/AUD","bids":[{"price":695.84,"qty":0.00000000},{"price":694.61,"qty":10.93257000}],"asks":[],"checksum":1935833232,"timestamp":"2024-06-01T22:43:47.278929Z"}]}
{"channel":"book","type":"update","data":[{"symbol":"BCH/AUD","bids":[{"price":695.86,"qty":3.30165594}],"asks":[],"checksum":345909222,"timestamp":"2024-06-01T22:43:47.278943Z"}]}
{"channel":"book","type":"update","data":[{"symbol":"BCH/AUD","bids":[{"price":695.87,"qty":6.00000000}],"asks":[],"checksum":2521036630,"timestamp":"2024-06-01T22:43:47.643977Z"}]}
{"channel":"book","type":"update","data":[{"symbol":"BCH/AUD","bids":[{"price":695.85,"qty":0.00000000},{"price":694.62,"qty":2.74650750}],"asks":[],"checksum":1385349851,"timestamp":"2024-06-01T22:43:47.644007Z"}]}
{"channel":"book","type":"update","data":[{"symbol":"BCH/AUD","bids":[{"price":695.83,"qty":0.00000000},{"price":694.61,"qty":10.93257000}],"asks":[],"checksum":2882518624,"timestamp":"2024-06-01T22:43:47.648776Z"}]}
{"channel":"book","type":"update","data":[{"symbol":"BCH/AUD","bids":[{"price":695.86,"qty":0.00000000},{"price":694.58,"qty":0.26329050}],"asks":[],"checksum":3987452330,"timestamp":"2024-06-01T22:43:47.674361Z"}]}
{"channel":"book","type":"update","data":[{"symbol":"BCH/AUD","bids":[{"price":695.88,"qty":3.30156117}],"asks":[],"checksum":1457754566,"timestamp":"2024-06-01T22:43:47.674550Z"}]}
{"channel":"book","type":"update","data":[{"symbol":"BCH/AUD","bids":[{"price":695.89,"qty":6.00000000}],"asks":[],"checksum":3247984678,"timestamp":"2024-06-01T22:43:48.142553Z"}]}
{"channel":"book","type":"update","data":[{"symbol":"BCH/AUD","bids":[{"price":695.87,"qty":0.00000000},{"price":694.61,"qty":10.93257000}],"asks":[],"checksum":674805399,"timestamp":"2024-06-01T22:43:48.148625Z"}]}
{"channel":"book","type":"update","data":[{"symbol":"BCH/AUD","bids":[{"price":695.90,"qty":3.30146623}],"asks":[],"checksum":2703534966,"timestamp":"2024-06-01T22:43:48.162290Z"}]}
{"channel":"book","type":"update","data":[{"symbol":"BCH/AUD","bids":[{"price":695.88,"qty":0.00000000},{"price":694.61,"qty":10.93257000}],"asks":[],"checksum":2985967875,"timestamp":"2024-06-01T22:43:48.162544Z"}]}
{"channel":"book","type":"update","data":[{"symbol":"BCH/AUD","bids":[{"price":695.91,"qty":6.00000000}],"asks":[],"checksum":930386461,"timestamp":"2024-06-01T22:43:48.644490Z"}]}
{"channel":"book","type":"update","data":[{"symbol":"BCH/AUD","bids":[{"price":695.89,"qty":0.00000000},{"price":694.61,"qty":10.93257000}],"asks":[],"checksum":2034786399,"timestamp":"2024-06-01T22:43:48.650947Z"}]}
{"channel":"book","type":"update","data":[{"symbol":"BCH/AUD","bids":[{"price":695.90,"qty":0.00000000},{"price":694.58,"qty":0.26329050}],"asks":[],"checksum":3638144142,"timestamp":"2024-06-01T22:43:48.666388Z"}]}
{"channel":"book","type":"update","data":[{"symbol":"BCH/AUD","bids":[{"price":695.92,"qty":3.30137130}],"asks":[],"checksum":3050391491,"timestamp":"2024-06-01T22:43:48.666636Z"}]}
{"channel":"book","type":"update","data":[{"symbol":"BCH/AUD","bids":[{"price":695.93,"qty":6.00000000}],"asks":[],"checksum":1176934348,"timestamp":"2024-06-01T22:43:49.143358Z"}]}
{"channel":"book","type":"update","data":[{"symbol":"BCH/AUD","bids":[{"price":695.91,"qty":0.00000000},{"price":694.61,"qty":10.93257000}],"asks":[],"checksum":1509086089,"timestamp":"2024-06-01T22:43:49.148139Z"}]}
{"channel":"book","type":"update","data":[{"symbol":"BCH/AUD","bids":[{"price":695.92,"qty":0.00000000},{"price":694.58,"qty":0.26329050}],"asks":[],"checksum":232587282,"timestamp":"2024-06-01T22:43:49.167806Z"}]}
{"channel":"book","type":"update","data":[{"symbol":"BCH/AUD","bids":[{"price":695.94,"qty":3.30127652}],"asks":[],"checksum":540239078,"timestamp":"2024-06-01T22:43:49.167888Z"}]}
{"channel":"book","type":"update","data":[{"symbol":"BCH/AUD","bids":[{"price":695.95,"qty":6.00000000}],"asks":[],"checksum":717131802,"timestamp":"2024-06-01T22:43:49.643118Z"}]}
{"channel":"book","type":"update","data":[{"symbol":"BCH/AUD","bids":[{"price":695.93,"qty":0.00000000},{"price":694.61,"qty":10.93257000}],"asks":[],"checksum":370833933,"timestamp":"2024-06-01T22:43:49.648390Z"}]}
{"channel":"book","type":"update","data":[{"symbol":"BCH/AUD","bids":[{"price":695.94,"qty":0.00000000},{"price":694.58,"qty":0.26329050}],"asks":[],"checksum":2845963255,"timestamp":"2024-06-01T22:43:49.654209Z"}]}
{"channel":"book","type":"update","data":[{"symbol":"BCH/AUD","bids":[{"price":695.96,"qty":3.53155213}],"asks":[],"checksum":4084682509,"timestamp":"2024-06-01T22:43:49.654686Z"}]}
{"channel":"book","type":"update","data":[{"symbol":"BCH/AUD","bids":[{"price":695.97,"qty":6.00000000}],"asks":[],"checksum":1455116469,"timestamp":"2024-06-01T22:43:50.143359Z"}]}
{"channel":"book","type":"update","data":[{"symbol":"BCH/AUD","bids":[{"price":695.95,"qty":0.00000000},{"price":694.58,"qty":0.26329050}],"asks":[],"checksum":1421873654,"timestamp":"2024-06-01T22:43:50.149855Z"}]}
{"channel":"book","type":"update","data":[{"symbol":"BCH/AUD","bids":[{"price":695.96,"qty":0.23037052}],"asks":[],"checksum":1824126445,"timestamp":"2024-06-01T22:43:50.156370Z"}]}
{"channel":"book","type":"update","data":[{"symbol":"BCH/AUD","bids":[{"price":695.80,"qty":3.30194067}],"asks":[],"checksum":1516525261,"timestamp":"2024-06-01T22:43:50.156380Z"}]}
{"channel":"book","type":"update","data":[{"symbol":"BCH/AUD","bids":[{"price":695.97,"qty":0.00000000},{"price":694.58,"qty":0.26329050}],"asks":[],"checksum":1276151407,"timestamp":"2024-06-01T22:43:51.642888Z"}]}
{"channel":"book","type":"update","data":[{"symbol":"BCH/AUD","bids":[{"price":695.81,"qty":6.00000000}],"asks":[],"checksum":1654258366,"timestamp":"2024-06-01T22:43:51.643173Z"}]}
{"channel":"book","type":"update","data":[{"symbol":"BCH/AUD","bids":[{"price":695.82,"qty":3.30184586}],"asks":[],"checksum":1515215658,"timestamp":"2024-06-01T22:43:51.653997Z"}]}
{"channel":"book","type":"update","data":[{"symbol":"BCH/AUD","bids":[{"price":695.80,"qty":0.00000000},{"price":694.61,"qty":10.93257000}],"asks":[],"checksum":1580720360,"timestamp":"2024-06-01T22:43:51.654108Z"}]}
{"channel":"book","type":"update","data":[{"symbol":"BCH/AUD","bids":[{"price":695.83,"qty":6.00000000}],"asks":[],"checksum":2912342066,"timestamp":"2024-06-01T22:43:52.143856Z"}]}
{"channel":"book","type":"update","data":[{"symbol":"BCH/AUD","bids":[{"price":695.81,"qty":0.00000000},{"price":694.61,"qty":10.93257000}],"asks":[],"checksum":1389536972,"timestamp":"2024-06-01T22:43:52.148680Z"}]}
{"channel":"book","type":"update","data":[{"symbol":"BCH/AUD","bids":[{"price":695.82,"qty":0.00000000},{"price":694.58,"qty":0.26329050}],"asks":[],"checksum":2631134931,"timestamp":"2024-06-01T22:43:52.152212Z"}]}
{"channel":"book","type":"update","data":[{"symbol":"BCH/AUD","bids":[{"price":695.84,"qty":3.30175091}],"asks":[],"checksum":304043930,"timestamp":"2024-06-01T22:43:52.152286Z"}]}
{"channel":"book","type":"update","data":[{"symbol":"BCH/AUD","bids":[{"price":695.85,"qty":6.00000000}],"asks":[],"checksum":2605358739,"timestamp":"2024-06-01T22:43:52.644450Z"}]}
{"channel":"book","type":"update","data":[{"symbol":"BCH/AUD","bids":[{"price":695.83,"qty":0.00000000},{"price":694.61,"qty":10.93257000}],"asks":[],"checksum":3540103070,"timestamp":"2024-06-01T22:43:52.649157Z"}]}
{"channel":"book","type":"update","data":[{"symbol":"BCH/AUD","bids":[{"price":695.84,"qty":0.00000000},{"price":694.58,"qty":0.26329050}],"asks":[],"checksum":951000374,"timestamp":"2024-06-01T22:43:52.662395Z"}]}
{"channel":"book","type":"update","data":[{"symbol":"BCH/AUD","bids":[{"price":695.86,"qty":3.30165596}],"asks":[],"checksum":99441033,"timestamp":"2024-06-01T22:43:52.662486Z"}]}
{"channel":"book","type":"update","data":[{"symbol":"BCH/AUD","bids":[{"price":695.96,"qty":0.00000000},{"price":694.58,"qty":0.26329050},{"price":695.97,"qty":0.23036721}],"asks":[],"checksum":2256020918,"timestamp":"2024-06-01T22:43:52.779591Z"}]}
{"channel":"book","type":"update","data":[{"symbol":"BCH/AUD","bids":[{"price":695.87,"qty":6.00000000}],"asks":[],"checksum":2639484054,"timestamp":"2024-06-01T22:43:52.785909Z"}]}
{"channel":"book","type":"update","data":[{"symbol":"BCH/AUD","bids":[{"price":695.86,"qty":0.00000000},{"price":694.61,"qty":10.93257000}],"asks":[],"checksum":4048769231,"timestamp":"2024-06-01T22:43:52.798760Z"}]}
{"channel":"book","type":"update","data":[{"symbol":"BCH/AUD","bids":[{"price":695.88,"qty":3.30156117}],"asks":[],"checksum":3069809993,"timestamp":"2024-06-01T22:43:52.798879Z"}]}
{"channel":"book","type":"update","data":[{"symbol":"BCH/AUD","bids":[{"price":695.87,"qty":0.00000000},{"price":694.61,"qty":10.93257000}],"asks":[],"checksum":874408615,"timestamp":"2024-06-01T22:43:53.142770Z"}]}
{"channel":"book","type":"update","data":[{"symbol":"BCH/AUD","bids":[{"price":695.89,"qty":6.00000000}],"asks":[],"checksum":3701635396,"timestamp":"2024-06-01T22:43:53.142787Z"}]}
{"channel":"book","type":"update","data":[{"symbol":"BCH/AUD","bids":[{"price":695.85,"qty":0.00000000},{"price":694.61,"qty":10.93257000}],"asks":[],"checksum":2880293544,"timestamp":"2024-06-01T22:43:53.148032Z"}]}
{"channel":"book","type":"update","data":[{"symbol":"BCH/AUD","bids":[{"price":695.90,"qty":3.30146623}],"asks":[],"checksum":3890041697,"timestamp":"2024-06-01T22:43:53.152395Z"}]}
{"channel":"book","type":"update","data":[{"symbol":"BCH/AUD","bids":[{"price":695.88,"qty":0.00000000},{"price":694.61,"qty":10.93257000}],"asks":[],"checksum":846150972,"timestamp":"2024-06-01T22:43:53.152425Z"}]}
{"channel":"book","type":"update","data":[{"symbol":"BCH/AUD","bids":[{"price":695.91,"qty":6.00000000}],"asks":[],"checksum":1905093130,"timestamp":"2024-06-01T22:43:53.643218Z"}]}
{"channel":"book","type":"update","data":[{"symbol":"BCH/AUD","bids":[{"price":695.89,"qty":0.00000000},{"price":694.61,"qty":10.93257000}],"asks":[],"checksum":4208794720,"timestamp":"2024-06-01T22:43:53.648331Z"}]}
{"channel":"book","type":"update","data":[{"symbol":"BCH/AUD","bids":[{"price":695.92,"qty":3.30137130}],"asks":[],"checksum":3987948689,"timestamp":"2024-06-01T22:43:53.653344Z"}]}
{"channel":"book","type":"update","data":[{"symbol":"BCH/AUD","bids":[{"price":695.90,"qty":0.00000000},{"price":694.61,"qty":10.93257000}],"asks":[],"checksum":910441468,"timestamp":"2024-06-01T22:43:53.653383Z"}]}
{"channel":"book","type":"update","data":[{"symbol":"BCH/AUD","bids":[{"price":695.93,"qty":6.00000000}],"asks":[],"checksum":14643163,"timestamp":"2024-06-01T22:43:54.144234Z"}]}
{"channel":"book","type":"update","data":[{"symbol":"BCH/AUD","bids":[{"price":695.91,"qty":0.00000000},{"price":694.61,"qty":10.93257000}],"asks":[],"checksum":3664228278,"timestamp":"2024-06-01T22:43:54.149054Z"}]}
{"channel":"book","type":"update","data":[{"symbol":"BCH/AUD","bids":[{"price":695.92,"qty":0.00000000},{"price":694.58,"qty":0.26329050}],"asks":[],"checksum":1260713989,"timestamp":"2024-06-01T22:43:54.162772Z"}]}
{"channel":"book","type":"update","data":[{"symbol":"BCH/AUD","bids":[{"price":695.94,"qty":3.30127652}],"asks":[],"checksum":2745571545,"timestamp":"2024-06-01T22:43:54.162850Z"}]}
{"channel":"book","type":"update","data":[{"symbol":"BCH/AUD","bids":[{"price":695.95,"qty":6.00000000}],"asks":[],"checksum":1816619021,"timestamp":"2024-06-01T22:43:54.643231Z"}]}
{"channel":"book","type":"update","data":[{"symbol":"BCH/AUD","bids":[{"price":695.93,"qty":0.00000000},{"price":694.61,"qty":10.93257000}],"asks":[],"checksum":2509178418,"timestamp":"2024-06-01T22:43:54.648141Z"}]}
{"channel":"book","type":"update","data":[{"symbol":"BCH/AUD","bids":[{"price":695.96,"qty":3.30118161}],"asks":[],"checksum":851178773,"timestamp":"2024-06-01T22:43:54.662936Z"}]}
{"channel":"book","type":"update","data":[{"symbol":"BCH/AUD","bids":[{"price":695.94,"qty":0.00000000},{"price":694.61,"qty":10.93257000}],"asks":[],"checksum":125501362,"timestamp":"2024-06-01T22:43:54.662977Z"}]}
{"channel":"book","type":"update","data":[{"symbol":"BCH/AUD","bids":[{"price":695.97,"qty":6.23036721}],"asks":[],"checksum":711461158,"timestamp":"2024-06-01T22:43:55.142331Z"}]}
{"channel":"book","type":"update","data":[{"symbol":"BCH/AUD","bids":[{"price":695.95,"qty":0.00000000},{"price":694.58,"qty":0.26329050}],"asks":[],"checksum":1534473528,"timestamp":"2024-06-01T22:43:55.147832Z"}]}
{"channel":"book","type":"update","data":[{"symbol":"BCH/AUD","bids":[{"price":695.80,"qty":3.30194067}],"asks":[],"checksum":2901065558,"timestamp":"2024-06-01T22:43:55.166469Z"}]}
{"channel":"book","type":"update","data":[{"symbol":"BCH/AUD","bids":[{"price":695.96,"qty":0.00000000},{"price":694.58,"qty":0.26329050}],"asks":[],"checksum":451962759,"timestamp":"2024-06-01T22:43:55.166591Z"}]}
{"channel":"book","type":"update","data":[{"symbol":"BCH/AUD","bids":[{"price":695.81,"qty":6.00000000}],"asks":[],"checksum":3424546837,"timestamp":"2024-06-01T22:43:56.644136Z"}]}
{"channel":"book","type":"update","data":[{"symbol":"BCH/AUD","bids":[{"price":695.97,"qty":0.23036721}],"asks":[],"checksum":3775694465,"timestamp":"2024-06-01T22:43:56.644174Z"}]}
{"channel":"book","type":"update","data":[{"symbol":"BCH/AUD","bids":[{"price":695.98,"qty":6.00000000}],"asks":[],"checksum":2403736704,"timestamp":"2024-06-01T22:43:56.649546Z"}]}
{"channel":"book","type":"update","data":[{"symbol":"BCH/AUD","bids":[{"price":695.80,"qty":0.00000000},{"price":694.61,"qty":10.93257000}],"asks":[],"checksum":1759624281,"timestamp":"2024-06-01T22:43:56.675002Z"}]}
{"channel":"book","type":"update","data":[{"symbol":"BCH/AUD","bids":[{"price":695.82,"qty":3.30184582}],"asks":[],"checksum":661449795,"timestamp":"2024-06-01T22:43:56.675098Z"}]}
{"channel":"book","type":"update","data":[{"symbol":"BCH/AUD","bids":[{"price":695.81,"qty":0.00000000},{"price":694.61,"qty":10.93257000}],"asks":[],"checksum":1968840026,"timestamp":"2024-06-01T22:43:56.681562Z"}]}
{"channel":"book","type":"update","data":[{"symbol":"BCH/AUD","bids":[{"price":695.98,"qty":0.00000000},{"price":694.58,"qty":0.26329050}],"asks":[],"checksum":4283293054,"timestamp":"2024-06-01T22:43:58.144237Z"}]}
{"channel":"book","type":"update","data":[{"symbol":"BCH/AUD","bids":[{"price":695.83,"qty":6.00000000}],"asks":[],"checksum":3705686262,"timestamp":"2024-06-01T22:43:58.144294Z"}]}
{"channel":"book","type":"update","data":[{"symbol":"BCH/AUD","bids":[{"price":695.82,"qty":0.00000000},{"price":694.58,"qty":0.26329050}],"asks":[],"checksum":3660191428,"timestamp":"2024-06-01T22:43:58.152234Z"}]}
{"channel":"book","type":"update","data":[{"symbol":"BCH/AUD","bids":[{"price":695.98,"qty":3.30108680}],"asks":[],"checksum":2942043293,"timestamp":"2024-06-01T22:43:58.152389Z"}]}
{"channel":"book","type":"update","data":[{"symbol":"BCH/AUD","bids":[{"price":695.97,"qty":0.00000000},{"price":694.58,"qty":0.26329050},{"price":695.99,"qty":0.23036059}],"asks":[],"checksum":634625646,"timestamp":"2024-06-01T22:43:58.292403Z"}]}
{"channel":"book","type":"update","data":[{"symbol":"BCH/AUD","bids":[{"price":695.98,"qty":0.00000000},{"price":694.58,"qty":0.26329050}],"asks":[],"checksum":510087960,"timestamp":"2024-06-01T22:43:58.294568Z"}]}
{"channel":"book","type":"update","data":[{"symbol":"BCH/AUD","bids":[{"price":695.84,"qty":3.30175084}],"asks":[],"checksum":2382713077,"timestamp":"2024-06-01T22:43:58.294831Z"}]}
{"channel":"book","type":"update","data":[{"symbol":"BCH/AUD","bids":[{"price":695.99,"qty":6.23036059}],"asks":[],"checksum":3445074390,"timestamp":"2024-06-01T22:43:58.297753Z"}]}
{"channel":"book","type":"update","data":[{"symbol":"BCH/AUD","bids":[{"price":695.83,"qty":0.00000000},{"price":694.58,"qty":0.26329050}],"asks":[],"checksum":107891524,"timestamp":"2024-06-01T22:43:58.643793Z"}]}
{"channel":"book","type":"update","data":[{"symbol":"BCH/AUD","bids":[{"price":695.80,"qty":3.30194074}],"asks":[],"checksum":18866267,"timestamp":"2024-06-01T22:43:58.666306Z"}]}
{"channel":"book","type":"update","data":[{"symbol":"BCH/AUD","bids":[{"price":695.84,"qty":0.00000000},{"price":694.58,"qty":0.26329050}],"asks":[],"checksum":1643365629,"timestamp":"2024-06-01T22:43:58.666408Z"}]}
{"channel":"book","type":"update","data":[{"symbol":"BCH/AUD","bids":[{"price":695.81,"qty":6.00000000}],"asks":[],"checksum":3655652988,"timestamp":"2024-06-01T22:43:59.643922Z"}]}
{"channel":"book","type":"update","data":[{"symbol":"BCH/AUD","bids":[{"price":695.99,"qty":0.23036059}],"asks":[],"checksum":2595630943,"timestamp":"2024-06-01T22:43:59.643951Z"}]}
{"channel":"book","type":"update","data":[{"symbol":"BCH/AUD","bids":[{"price":695.82,"qty":3.30184574}],"asks":[],"checksum":3536060026,"timestamp":"2024-06-01T22:43:59.649546Z"}]}
{"channel":"book","type":"update","data":[{"symbol":"BCH/AUD","bids":[{"price":695.80,"qty":0.00000000},{"price":694.61,"qty":10.93257000}],"asks":[],"checksum":1700265844,"timestamp":"2024-06-01T22:43:59.649770Z"}]}
{"channel":"book","type":"update","data":[{"symbol":"BCH/AUD","bids":[{"price":695.83,"qty":6.00000000}],"asks":[],"checksum":3261606144,"timestamp":"2024-06-01T22:44:00.142799Z"}]}
{"channel":"book","type":"update","data":[{"symbol":"BCH/AUD","bids":[{"price":695.81,"qty":0.00000000},{"price":694.61,"qty":10.93257000}],"asks":[],"checksum":2590640565,"timestamp":"2024-06-01T22:44:00.147786Z"}]}
{"channel":"book","type":"update","data":[{"symbol":"BCH/AUD","bids":[{"price":695.84,"qty":3.30175091}],"asks":[],"checksum":937753885,"timestamp":"2024-06-01T22:44:00.148827Z"}]}
{"channel":"book","type":"update","data":[{"symbol":"BCH/AUD","bids":[{"price":695.82,"qty":0.00000000},{"price":694.61,"qty":10.93257000}],"asks":[],"checksum":506198047,"timestamp":"2024-06-01T22:44:00.148854Z"}]}
{"channel":"book","type":"update","data":[{"symbol":"BCH/AUD","bids":[{"price":695.85,"qty":6.00000000}],"asks":[],"checksum":436085592,"timestamp":"2024-06-01T22:44:00.644591Z"}]}
{"channel":"book","type":"update","data":[{"symbol":"BCH/AUD","bids":[{"price":695.83,"qty":0.00000000},{"price":694.61,"qty":10.93257000}],"asks":[],"checksum":3744792603,"timestamp":"2024-06-01T22:44:00.649292Z"}]}
{"channel":"book","type":"update","data":[{"symbol":"BCH/AUD","bids":[{"price":695.86,"qty":3.30165594}],"asks":[],"checksum":3372171679,"timestamp":"2024-06-01T22:44:00.670887Z"}]}
{"channel":"book","type":"update","data":[{"symbol":"BCH/AUD","bids":[{"price":695.84,"qty":0.00000000},{"price":694.61,"qty":10.93257000}],"asks":[],"checksum":4292170001,"timestamp":"2024-06-01T22:44:00.670987Z"}]}
{"channel":"book","type":"update","data":[{"symbol":"BCH/AUD","bids":[{"price":695.87,"qty":6.00000000}],"asks":[],"checksum":1013058703,"timestamp":"2024-06-01T22:44:01.142666Z"}]}
{"channel":"book","type":"update","data":[{"symbol":"BCH/AUD","bids":[{"price":695.85,"qty":0.00000000},{"price":694.61,"qty":10.93257000}],"asks":[],"checksum":2818249189,"timestamp":"2024-06-01T22:44:01.148757Z"}]}
{"channel":"book","type":"update","data":[{"symbol":"BCH/AUD","bids":[{"price":695.86,"qty":0.00000000},{"price":694.58,"qty":0.26329050}],"asks":[],"checksum":1864305761,"timestamp":"2024-06-01T22:44:01.156057Z"}]}
{"channel":"book","type":"update","data":[{"symbol":"BCH/AUD","bids":[{"price":695.88,"qty":3.30156110}],"asks":[],"checksum":218956171,"timestamp":"2024-06-01T22:44:01.156193Z"}]}
{"channel":"book","type":"update","data":[{"symbol":"BCH/AUD","bids":[{"price":695.89,"qty":6.00000000}],"asks":[],"checksum":867059296,"timestamp":"2024-06-01T22:44:01.643260Z"}]}
{"channel":"book","type":"update","data":[{"symbol":"BCH/AUD","bids":[{"price":695.87,"qty":0.00000000},{"price":694.61,"qty":10.93257000}],"asks":[],"checksum":3077923876,"timestamp":"2024-06-01T22:44:01.649511Z"}]}
{"channel":"book","type":"update","data":[{"symbol":"BCH/AUD","bids":[{"price":695.90,"qty":3.30146618}],"asks":[],"checksum":3925588510,"timestamp":"2024-06-01T22:44:01.650756Z"}]}
{"channel":"book","type":"update","data":[{"symbol":"BCH/AUD","bids":[{"price":695.88,"qty":0.00000000},{"price":694.61,"qty":10.93257000}],"asks":[],"checksum":3785644418,"timestamp":"2024-06-01T22:44:01.650786Z"}]}
{"channel":"book","type":"update","data":[{"symbol":"BCH/AUD","bids":[{"price":695.90,"qty":0.00000000},{"price":694.58,"qty":0.26329050}],"asks":[],"checksum":697516406,"timestamp":"2024-06-01T22:44:01.874768Z"}]}
{"channel":"book","type":"update","data":[{"symbol":"BCH/AUD","bids":[{"price":696.00,"qty":3.30099183}],"asks":[],"checksum":3725559078,"timestamp":"2024-06-01T22:44:01.874968Z"}]}
{"channel":"book","type":"update","data":[{"symbol":"BCH/AUD","bids":[{"price":696.01,"qty":6.00000000}],"asks":[],"checksum":2084348114,"timestamp":"2024-06-01T22:44:02.143588Z"}]}
{"channel":"book","type":"update","data":[{"symbol":"BCH/AUD","bids":[{"price":695.89,"qty":0.00000000},{"price":694.61,"qty":10.93257000}],"asks":[],"checksum":1926821708,"timestamp":"2024-06-01T22:44:02.148395Z"}]}
{"channel":"book","type":"update","data":[{"symbol":"BCH/AUD","bids":[{"price":696.00,"qty":0.00000000},{"price":694.58,"qty":0.26329050}],"asks":[],"checksum":1190485474,"timestamp":"2024-06-01T22:44:02.986746Z"}]}
{"channel":"book","type":"update","data":[{"symbol":"BCH/AUD","bids":[{"price":696.02,"qty":3.30089701}],"asks":[],"checksum":1404999955,"timestamp":"2024-06-01T22:44:02.986861Z"}]}
{"channel":"book","type":"update","data":[{"symbol":"BCH/AUD","bids":[{"price":696.03,"qty":6.00000000}],"asks":[],"checksum":2786337008,"timestamp":"2024-06-01T22:44:02.992887Z"}]}
{"channel":"book","type":"update","data":[{"symbol":"BCH/AUD","bids":[{"price":696.01,"qty":0.00000000},{"price":694.61,"qty":10.93257000}],"asks":[],"checksum":2635000869,"timestamp":"2024-06-01T22:44:03.141978Z"}]}
{"channel":"book","type":"update","data":[{"symbol":"BCH/AUD","bids":[{"price":696.00,"qty":3.30099192}],"asks":[],"checksum":270676233,"timestamp":"2024-06-01T22:44:03.146571Z"}]}
{"channel":"book","type":"update","data":[{"symbol":"BCH/AUD","bids":[{"price":696.02,"qty":0.00000000},{"price":694.61,"qty":10.93257000}],"asks":[],"checksum":1753935252,"timestamp":"2024-06-01T22:44:03.146711Z"}]}
{"channel":"book","type":"update","data":[{"symbol":"BCH/AUD","bids":[{"price":696.00,"qty":0.00000000},{"price":694.58,"qty":0.26329050}],"asks":[],"checksum":3158288834,"timestamp":"2024-06-01T22:44:03.252754Z"}]}
{"channel":"book","type":"update","data":[{"symbol":"BCH/AUD","bids":[{"price":695.80,"qty":3.30194065}],"asks":[],"checksum":437168106,"timestamp":"2024-06-01T22:44:03.252921Z"}]}
{"channel":"book","type":"update","data":[{"symbol":"BCH/AUD","bids":[{"price":696.03,"qty":0.00000000},{"price":694.58,"qty":0.26329050}],"asks":[],"checksum":2066054513,"timestamp":"2024-06-01T22:44:04.142972Z"}]}
{"channel":"book","type":"update","data":[{"symbol":"BCH/AUD","bids":[{"price":695.81,"qty":6.00000000}],"asks":[],"checksum":2244353817,"timestamp":"2024-06-01T22:44:04.143105Z"}]}
{"channel":"book","type":"update","data":[{"symbol":"BCH/AUD","bids":[{"price":695.80,"qty":0.00000000},{"price":694.58,"qty":0.26329050}],"asks":[],"checksum":3412328324,"timestamp":"2024-06-01T22:44:04.173863Z"}]}
{"channel":"book","type":"update","data":[{"symbol":"BCH/AUD","bids":[{"price":695.82,"qty":3.30184586}],"asks":[],"checksum":1375948653,"timestamp":"2024-06-01T22:44:04.173884Z"}]}
{"channel":"book","type":"update","data":[{"symbol":"BCH/AUD","bids":[{"price":695.83,"qty":6.00000000}],"asks":[],"checksum":790785529,"timestamp":"2024-06-01T22:44:04.178886Z"}]}
{"channel":"book","type":"update","data":[{"symbol":"BCH/AUD","bids":[{"price":695.84,"qty":3.30175087}],"asks":[],"checksum":3181466411,"timestamp":"2024-06-01T22:44:04.203718Z"}]}
{"channel":"book","type":"update","data":[{"symbol":"BCH/AUD","bids":[{"price":695.82,"qty":0.00000000},{"price":694.62,"qty":2.74650750}],"asks":[],"checksum":2928951427,"timestamp":"2024-06-01T22:44:04.203799Z"}]}
{"channel":"book","type":"update","data":[{"symbol":"BCH/AUD","bids":[{"price":695.85,"qty":6.00000000}],"asks":[],"checksum":3019202145,"timestamp":"2024-06-01T22:44:04.643437Z"}]}
{"channel":"book","type":"update","data":[{"symbol":"BCH/AUD","bids":[{"price":695.83,"qty":0.00000000},{"price":694.62,"qty":2.74650750}],"asks":[],"checksum":2550952307,"timestamp":"2024-06-01T22:44:04.643492Z"}]}
{"channel":"book","type":"update","data":[{"symbol":"BCH/AUD","bids":[{"price":695.81,"qty":0.00000000},{"price":694.61,"qty":10.93257000}],"asks":[],"checksum":1396460907,"timestamp":"2024-06-01T22:44:04.648334Z"}]}
{"channel":"book","type":"update","data":[{"symbol":"BCH/AUD","bids":[{"price":695.84,"qty":0.00000000},{"price":694.58,"qty":0.26329050}],"asks":[],"checksum":3122372861,"timestamp":"2024-06-01T22:44:04.673323Z"}]}
{"channel":"book","type":"update","data":[{"symbol":"BCH/AUD","bids":[{"price":695.86,"qty":3.30165594}],"asks":[],"checksum":4292170001,"timestamp":"2024-06-01T22:44:04.673646Z"}]}
{"channel":"book","type":"update","data":[{"symbol":"BCH/AUD","bids":[{"price":695.87,"qty":6.00000000}],"asks":[],"checksum":1013058703,"timestamp":"2024-06-01T22:44:05.142274Z"}]}
{"channel":"book","type":"update","data":[{"symbol":"BCH/AUD","bids":[{"price":695.85,"qty":0.00000000},{"price":694.61,"qty":10.93257000}],"asks":[],"checksum":2818249189,"timestamp":"2024-06-01T22:44:05.147145Z"}]}
{"channel":"book","type":"update","data":[{"symbol":"BCH/AUD","bids":[{"price":695.88,"qty":3.30156114}],"asks":[],"checksum":2966663257,"timestamp":"2024-06-01T22:44:05.171586Z"}]}
{"channel":"book","type":"update","data":[{"symbol":"BCH/AUD","bids":[{"price":695.86,"qty":0.00000000},{"price":694.61,"qty":10.93257000}],"asks":[],"checksum":979716592,"timestamp":"2024-06-01T22:44:05.171607Z"}]}
{"channel":"book","type":"update","data":[{"symbol":"BCH/AUD","bids":[{"price":695.89,"qty":6.00000000}],"asks":[],"checksum":4183195114,"timestamp":"2024-06-01T22:44:05.643878Z"}]}
{"channel":"book","type":"update","data":[{"symbol":"BCH/AUD","bids":[{"price":695.90,"qty":3.30146628}],"asks":[],"checksum":2212917955,"timestamp":"2024-06-01T22:44:05.647450Z"}]}
{"channel":"book","type":"update","data":[{"symbol":"BCH/AUD","bids":[{"price":695.88,"qty":0.00000000},{"price":694.62,"qty":2.74650750}],"asks":[],"checksum":837137638,"timestamp":"2024-06-01T22:44:05.647506Z"}]}
{"channel":"book","type":"update","data":[{"symbol":"BCH/AUD","bids":[{"price":695.87,"qty":0.00000000},{"price":694.61,"qty":10.93257000}],"asks":[],"checksum":3014396355,"timestamp":"2024-06-01T22:44:05.648299Z"}]}
{"channel":"book","type":"update","data":[{"symbol":"BCH/AUD","bids":[{"price":695.91,"qty":6.00000000}],"asks":[],"checksum":1094438532,"timestamp":"2024-06-01T22:44:06.143983Z"}]}
{"channel":"book","type":"update","data":[{"symbol":"BCH/AUD","bids":[{"price":695.89,"qty":0.00000000},{"price":694.61,"qty":10.93257000}],"asks":[],"checksum":4042065123,"timestamp":"2024-06-01T22:44:06.149068Z"}]}
{"channel":"book","type":"update","data":[{"symbol":"BCH/AUD","bids":[{"price":695.90,"qty":0.00000000},{"price":694.58,"qty":0.26329050}],"asks":[],"checksum":1517097285,"timestamp":"2024-06-01T22:44:06.178519Z"}]}
{"channel":"book","type":"update","data":[{"symbol":"BCH/AUD","bids":[{"price":695.92,"qty":3.30137130}],"asks":[],"checksum":3118852166,"timestamp":"2024-06-01T22:44:06.178754Z"}]}
{"channel":"book","type":"update","data":[{"symbol":"BCH/AUD","bids":[{"price":695.93,"qty":6.00000000}],"asks":[],"checksum":3297913351,"timestamp":"2024-06-01T22:44:06.643569Z"}]}
{"channel":"book","type":"update","data":[{"symbol":"BCH/AUD","bids":[{"price":695.91,"qty":0.00000000},{"price":694.61,"qty":10.93257000}],"asks":[],"checksum":1439071244,"timestamp":"2024-06-01T22:44:06.648470Z"}]}
{"channel":"book","type":"update","data":[{"symbol":"BCH/AUD","bids":[{"price":695.92,"qty":0.00000000},{"price":694.58,"qty":0.26329050}],"asks":[],"checksum":2406071769,"timestamp":"2024-06-01T22:44:06.670883Z"}]}
{"channel":"book","type":"update","data":[{"symbol":"BCH/AUD","bids":[{"price":695.94,"qty":3.30127648}],"asks":[],"checksum":2233715895,"timestamp":"2024-06-01T22:44:06.670958Z"}]}
{"channel":"book","type":"update","data":[{"symbol":"BCH/AUD","bids":[{"price":695.95,"qty":6.00000000}],"asks":[],"checksum":4131578960,"timestamp":"2024-06-01T22:44:07.143655Z"}]}
{"channel":"book","type":"update","data":[{"symbol":"BCH/AUD","bids":[{"price":695.93,"qty":0.00000000},{"price":694.61,"qty":10.93257000}],"asks":[],"checksum":2161061623,"timestamp":"2024-06-01T22:44:07.148320Z"}]}
{"channel":"book","type":"update","data":[{"symbol":"BCH/AUD","bids":[{"price":695.94,"qty":0.00000000},{"price":694.58,"qty":0.26329050}],"asks":[],"checksum":722816572,"timestamp":"2024-06-01T22:44:07.157350Z"}]}
{"channel":"book","type":"update","data":[{"symbol":"BCH/AUD","bids":[{"price":695.80,"qty":3.30194074}],"asks":[],"checksum":1609327184,"timestamp":"2024-06-01T22:44:07.157433Z"}]}
{"channel":"book","type":"update","data":[{"symbol":"BCH/AUD","bids":[{"price":695.99,"qty":0.00000000},{"price":694.58,"qty":0.26329050},{"price":696.00,"qty":0.23035728}],"asks":[],"checksum":247800019,"timestamp":"2024-06-01T22:44:07.269231Z"}]}
{"channel":"book","type":"update","data":[{"symbol":"BCH/AUD","bids":[{"price":695.80,"qty":0.00000000},{"price":694.58,"qty":0.26329050}],"asks":[],"checksum":3696752397,"timestamp":"2024-06-01T22:44:08.627249Z"}]}
{"channel":"book","type":"update","data":[{"symbol":"BCH/AUD","bids":[{"price":695.96,"qty":3.30118160}],"asks":[],"checksum":1330429477,"timestamp":"2024-06-01T22:44:08.627408Z"}]}
{"channel":"book","type":"update","data":[{"symbol":"BCH/AUD","bids":[{"price":695.97,"qty":6.00000000}],"asks":[],"checksum":3413655684,"timestamp":"2024-06-01T22:44:08.632897Z"}]}
{"channel":"book","type":"update","data":[{"symbol":"BCH/AUD","bids":[{"price":695.95,"qty":0.00000000},{"price":694.61,"qty":10.93257000}],"asks":[],"checksum":1628489784,"timestamp":"2024-06-01T22:44:08.642615Z"}]}
{"channel":"book","type":"update","data":[{"symbol":"BCH/AUD","bids":[{"price":695.96,"qty":0.00000000},{"price":694.58,"qty":0.26329050}],"asks":[],"checksum":156457873,"timestamp":"2024-06-01T22:44:08.647461Z"}]}
{"channel":"book","type":"update","data":[{"symbol":"BCH/AUD","bids":[{"price":695.80,"qty":3.30194072}],"asks":[],"checksum":291840823,"timestamp":"2024-06-01T22:44:08.647634Z"}]}
{"channel":"book","type":"update","data":[{"symbol":"BCH/AUD","bids":[{"price":695.98,"qty":3.30108672}],"asks":[],"checksum":2487046190,"timestamp":"2024-06-01T22:44:08.692343Z"}]}
{"channel":"book","type":"update","data":[{"symbol":"BCH/AUD","bids":[{"price":695.80,"qty":0.00000000},{"price":694.61,"qty":10.93257000}],"asks":[],"checksum":471297587,"timestamp":"2024-06-01T22:44:08.692493Z"}]}
{"channel":"book","type":"update","data":[{"symbol":"BCH/AUD","bids":[{"price":695.99,"qty":6.00000000}],"asks":[],"checksum":2506464251,"timestamp":"2024-06-01T22:44:08.701908Z"}]}
{"channel":"book","type":"update","data":[{"symbol":"BCH/AUD","bids":[{"price":695.97,"qty":0.00000000},{"price":694.61,"qty":10.93257000}],"asks":[],"checksum":2176909100,"timestamp":"2024-06-01T22:44:09.142153Z"}]}
{"channel":"book","type":"update","data":[{"symbol":"BCH/AUD","bids":[{"price":695.98,"qty":0.00000000},{"price":694.58,"qty":0.26329050}],"asks":[],"checksum":1340020358,"timestamp":"2024-06-01T22:44:09.177764Z"}]}
{"channel":"book","type":"update","data":[{"symbol":"BCH/AUD","bids":[{"price":695.80,"qty":3.30194066}],"asks":[],"checksum":4119997935,"timestamp":"2024-06-01T22:44:09.178048Z"}]}
{"channel":"book","type":"update","data":[{"symbol":"BCH/AUD","bids":[{"price":695.80,"qty":0.00000000},{"price":694.58,"qty":0.26329050}],"asks":[],"checksum":1340020358,"timestamp":"2024-06-01T22:44:09.603460Z"}]}
{"channel":"book","type":"update","data":[{"symbol":"BCH/AUD","bids":[{"price":696.01,"qty":3.30094439}],"asks":[],"checksum":2546362815,"timestamp":"2024-06-01T22:44:09.603853Z"}]}
{"channel":"book","type":"update","data":[{"symbol":"BCH/AUD","bids":[{"price":696.02,"qty":6.00000000}],"asks":[],"checksum":2375449958,"timestamp":"2024-06-01T22:44:09.644100Z"}]}
{"channel":"book","type":"update","data":[{"symbol":"BCH/AUD","bids":[{"price":695.99,"qty":0.00000000},{"price":694.61,"qty":10.93257000}],"asks":[],"checksum":4025167901,"timestamp":"2024-06-01T22:44:09.648598Z"}]}
{"channel":"book","type":"update","data":[{"symbol":"BCH/AUD","bids":[{"price":696.01,"qty":0.00000000},{"price":694.58,"qty":0.26329050}],"asks":[],"checksum":792437469,"timestamp":"2024-06-01T22:44:10.612606Z"}]}
{"channel":"book","type":"update","data":[{"symbol":"BCH/AUD","bids":[{"price":695.80,"qty":3.30194069}],"asks":[],"checksum":2172459035,"timestamp":"2024-06-01T22:44:10.612724Z"}]}
{"channel":"book","type":"update","data":[{"symbol":"BCH/AUD","bids":[{"price":696.02,"qty":0.00000000},{"price":694.58,"qty":0.26329050}],"asks":[],"checksum":2273467964,"timestamp":"2024-06-01T22:44:11.143653Z"}]}
{"channel":"book","type":"update","data":[{"symbol":"BCH/AUD","bids":[{"price":695.81,"qty":6.00000000}],"asks":[],"checksum":3255298965,"timestamp":"2024-06-01T22:44:11.143702Z"}]}
{"channel":"book","type":"update","data":[{"symbol":"BCH/AUD","bids":[{"price":695.80,"qty":0.00000000},{"price":694.58,"qty":0.26329050}],"asks":[],"checksum":1008813749,"timestamp":"2024-06-01T22:44:11.146762Z"}]}
{"channel":"book","type":"update","data":[{"symbol":"BCH/AUD","bids":[{"price":695.82,"qty":3.30184579}],"asks":[],"checksum":4218992084,"timestamp":"2024-06-01T22:44:11.146818Z"}]}
{"channel":"book","type":"update","data":[{"symbol":"BCH/AUD","bids":[{"price":695.83,"qty":6.00000000}],"asks":[],"checksum":1851086636,"timestamp":"2024-06-01T22:44:11.642746Z"}]}
{"channel":"book","type":"update","data":[{"symbol":"BCH/AUD","bids":[{"price":695.81,"qty":0.00000000},{"price":694.61,"qty":10.93257000}],"asks":[],"checksum":2820560936,"timestamp":"2024-06-01T22:44:11.647303Z"}]}
{"channel":"book","type":"update","data":[{"symbol":"BCH/AUD","bids":[{"price":695.84,"qty":3.30175086}],"asks":[],"checksum":1126958152,"timestamp":"2024-06-01T22:44:11.677374Z"}]}
{"channel":"book","type":"update","data":[{"symbol":"BCH/AUD","bids":[{"price":695.82,"qty":0.00000000},{"price":694.61,"qty":10.93257000}],"asks":[],"checksum":690009451,"timestamp":"2024-06-01T22:44:11.677465Z"}]}
{"channel":"book","type":"update","data":[{"symbol":"BCH/AUD","bids":[{"price":695.85,"qty":6.00000000}],"asks":[],"checksum":3951793397,"timestamp":"2024-06-01T22:44:11.682331Z"}]}
{"channel":"book","type":"update","data":[{"symbol":"BCH/AUD","bids":[{"price":695.84,"qty":0.00000000},{"price":694.61,"qty":10.93257000}],"asks":[],"checksum":780113302,"timestamp":"2024-06-01T22:44:11.701542Z"}]}
{"channel":"book","type":"update","data":[{"symbol":"BCH/AUD","bids":[{"price":695.86,"qty":3.30165604}],"asks":[],"checksum":3406705413,"timestamp":"2024-06-01T22:44:11.701557Z"}]}
