{"channel":"book","type":"snapshot","data":[{"symbol":"BCH/USDT","bids":[{"price":463.38,"qty":0.90000000},{"price":463.35,"qty":6.80879832},{"price":463.30,"qty":3.70723691},{"price":463.23,"qty":7.83392088},{"price":463.18,"qty":0.90130527},{"price":462.65,"qty":8.60527568},{"price":462.64,"qty":0.76032560},{"price":462.42,"qty":1.21000000},{"price":462.32,"qty":2.44000000},{"price":462.28,"qty":1.36603240}],"asks":[{"price":463.72,"qty":0.90000000},{"price":463.75,"qty":3.00000000},{"price":463.76,"qty":3.80879832},{"price":463.80,"qty":2.89779953},{"price":463.89,"qty":0.76032560},{"price":464.08,"qty":0.08935707},{"price":464.09,"qty":0.05918635},{"price":464.11,"qty":0.05275078},{"price":464.12,"qty":0.04185087},{"price":464.13,"qty":0.05272449}],"checksum":2207327724}]}
{"channel":"book","type":"update","data":[{"symbol":"BCH/USDT","bids":[{"price":463.38,"qty":0.00000000},{"price":462.06,"qty":2.55000000}],"asks":[],"checksum":85013035,"timestamp":"2024-06-01T22:43:48.088186Z"}]}
{"channel":"book","type":"update","data":[{"symbol":"BCH/USDT","bids":[],"asks":[{"price":463.72,"qty":0.00000000},{"price":464.14,"qty":0.08721902}],"checksum":477619206,"timestamp":"2024-06-01T22:43:48.092990Z"}]}
{"channel":"book","type":"update","data":[{"symbol":"BCH/USDT","bids":[{"price":462.60,"qty":1.26382000}],"asks":[],"checksum":2524139801,"timestamp":"2024-06-01T22:43:48.255059Z"}]}
{"channel":"book","type":"update","data":[{"symbol":"BCH/USDT","bids":[{"price":463.36,"qty":0.90000000}],"asks":[],"checksum":3659151713,"timestamp":"2024-06-01T22:43:48.588572Z"}]}
{"channel":"book","type":"update","data":[{"symbol":"BCH/USDT","bids":[],"asks":[{"price":463.74,"qty":0.90000000}],"checksum":1419110251,"timestamp":"2024-06-01T22:43:48.588621Z"}]}
{"channel":"book","type":"update","data":[{"symbol":"BCH/USDT","bids":[],"asks":[{"price":463.73,"qty":1.52229000}],"checksum":2500513381,"timestamp":"2024-06-01T22:43:49.598593Z"}]}
{"channel":"book","type":"update","data":[{"symbol":"BCH/USDT","bids":[{"price":463.37,"qty":1.52229000}],"asks":[],"checksum":642121881,"timestamp":"2024-06-01T22:43:49.598613Z"}]}
{"channel":"book","type":"update","data":[{"symbol":"BCH/USDT","bids":[],"asks":[{"price":463.72,"qty":0.90000000}],"checksum":1046562133,"timestamp":"2024-06-01T22:43:49.603353Z"}]}
{"channel":"book","type":"update","data":[{"symbol":"BCH/USDT","bids":[],"asks":[{"price":463.73,"qty":0.00000000},{"price":464.12,"qty":0.04185087}],"checksum":151837586,"timestamp":"2024-06-01T22:43:49.607549Z"}]}
{"channel":"book","type":"update","data":[{"symbol":"BCH/USDT","bids":[],"asks":[{"price":463.72,"qty":0.00000000},{"price":464.13,"qty":0.05272449}],"checksum":3889768855,"timestamp":"2024-06-01T22:43:50.088131Z"}]}
{"channel":"book","type":"update","data":[{"symbol":"BCH/USDT","bids":[{"price":463.38,"qty":0.90000000}],"asks":[],"checksum":2384279357,"timestamp":"2024-06-01T22:43:50.092589Z"}]}
{"channel":"book","type":"update","data":[{"symbol":"BCH/USDT","bids":[{"price":463.37,"qty":0.00000000},{"price":462.42,"qty":1.21000000}],"asks":[],"checksum":2911313747,"timestamp":"2024-06-01T22:43:50.097372Z"}]}
{"channel":"book","type":"update","data":[{"symbol":"BCH/USDT","bids":[{"price":463.38,"qty":0.00000000},{"price":462.32,"qty":2.44000000}],"asks":[],"checksum":1419110251,"timestamp":"2024-06-01T22:43:50.588310Z"}]}
{"channel":"book","type":"update","data":[{"symbol":"BCH/USDT","bids":[{"price":463.37,"qty":1.48269749}],"asks":[],"checksum":1304929461,"timestamp":"2024-06-01T22:43:50.679191Z"}]}
{"channel":"book","type":"update","data":[{"symbol":"BCH/USDT","bids":[],"asks":[{"price":463.73,"qty":1.48269749}],"checksum":3433278341,"timestamp":"2024-06-01T22:43:50.679231Z"}]}
{"channel":"book","type":"update","data":[{"symbol":"BCH/USDT","bids":[{"price":463.38,"qty":0.90000000}],"asks":[],"checksum":2015658159,"timestamp":"2024-06-01T22:43:50.684275Z"}]}
{"channel":"book","type":"update","data":[{"symbol":"BCH/USDT","bids":[{"price":463.37,"qty":0.00000000},{"price":462.42,"qty":1.21000000}],"asks":[],"checksum":2006901383,"timestamp":"2024-06-01T22:43:50.688684Z"}]}
{"channel":"book","type":"update","data":[{"symbol":"BCH/USDT","bids":[{"price":463.38,"qty":0.00000000},{"price":462.32,"qty":2.44000000}],"asks":[],"checksum":3589400667,"timestamp":"2024-06-01T22:43:51.088342Z"}]}
{"channel":"book","type":"update","data":[{"symbol":"BCH/USDT","bids":[],"asks":[{"price":463.72,"qty":0.90000000}],"checksum":3429512258,"timestamp":"2024-06-01T22:43:51.588425Z"}]}
{"channel":"book","type":"update","data":[{"symbol":"BCH/USDT","bids":[],"asks":[{"price":463.73,"qty":0.00000000},{"price":464.12,"qty":0.04185087}],"checksum":3124761966,"timestamp":"2024-06-01T22:43:51.592339Z"}]}
{"channel":"book","type":"update","data":[{"symbol":"BCH/USDT","bids":[],"asks":[{"price":463.74,"qty":0.00000000},{"price":464.13,"qty":0.05272449}],"checksum":3506071031,"timestamp":"2024-06-01T22:43:51.593153Z"}]}
{"channel":"book","type":"update","data":[{"symbol":"BCH/USDT","bids":[],"asks":[{"price":463.72,"qty":0.00000000},{"price":464.14,"qty":0.08721902}],"checksum":3659151713,"timestamp":"2024-06-01T22:43:52.589927Z"}]}
{"channel":"book","type":"update","data":[{"symbol":"BCH/USDT","bids":[],"asks":[{"price":463.74,"qty":0.90000000}],"checksum":1419110251,"timestamp":"2024-06-01T22:43:52.589959Z"}]}
{"channel":"book","type":"update","data":[{"symbol":"BCH/USDT","bids":[{"price":463.37,"qty":1.26374250}],"asks":[],"checksum":3377811872,"timestamp":"2024-06-01T22:43:52.642726Z"}]}
{"channel":"book","type":"update","data":[{"symbol":"BCH/USDT","bids":[],"asks":[{"price":463.73,"qty":1.26374250}],"checksum":1730821231,"timestamp":"2024-06-01T22:43:52.642832Z"}]}
{"channel":"book","type":"update","data":[{"symbol":"BCH/USDT","bids":[{"price":463.38,"qty":0.90000000}],"asks":[],"checksum":3028442373,"timestamp":"2024-06-01T22:43:52.647896Z"}]}
{"channel":"book","type":"update","data":[{"symbol":"BCH/USDT","bids":[{"price":463.37,"qty":0.00000000},{"price":462.42,"qty":1.21000000}],"asks":[],"checksum":58759867,"timestamp":"2024-06-01T22:43:52.652556Z"}]}
{"channel":"book","type":"update","data":[{"symbol":"BCH/USDT","bids":[{"price":463.38,"qty":0.00000000},{"price":462.32,"qty":2.44000000}],"asks":[],"checksum":4209674916,"timestamp":"2024-06-01T22:43:53.088195Z"}]}
{"channel":"book","type":"update","data":[{"symbol":"BCH/USDT","bids":[],"asks":[{"price":463.72,"qty":0.90000000}],"checksum":232741670,"timestamp":"2024-06-01T22:43:53.588518Z"}]}
{"channel":"book","type":"update","data":[{"symbol":"BCH/USDT","bids":[],"asks":[{"price":463.73,"qty":0.00000000},{"price":464.12,"qty":0.04185087}],"checksum":3124761966,"timestamp":"2024-06-01T22:43:53.593455Z"}]}
{"channel":"book","type":"update","data":[{"symbol":"BCH/USDT","bids":[],"asks":[{"price":463.74,"qty":0.00000000},{"price":464.13,"qty":0.05272449}],"checksum":3506071031,"timestamp":"2024-06-01T22:43:53.593769Z"}]}
{"channel":"book","type":"update","data":[{"symbol":"BCH/USDT","bids":[{"price":463.37,"qty":1.24869000}],"asks":[],"checksum":2515739579,"timestamp":"2024-06-01T22:43:53.658934Z"}]}
{"channel":"book","type":"update","data":[{"symbol":"BCH/USDT","bids":[],"asks":[{"price":463.71,"qty":1.24869000}],"checksum":594871676,"timestamp":"2024-06-01T22:43:53.659055Z"}]}
{"channel":"book","type":"update","data":[{"symbol":"BCH/USDT","bids":[{"price":463.38,"qty":0.90000000}],"asks":[],"checksum":2486830223,"timestamp":"2024-06-01T22:43:53.663845Z"}]}
{"channel":"book","type":"update","data":[{"symbol":"BCH/USDT","bids":[{"price":463.37,"qty":0.00000000},{"price":462.42,"qty":1.21000000}],"asks":[],"checksum":2622465919,"timestamp":"2024-06-01T22:43:53.668385Z"}]}
{"channel":"book","type":"update","data":[{"symbol":"BCH/USDT","bids":[{"price":463.38,"qty":0.00000000},{"price":462.32,"qty":2.44000000}],"asks":[],"checksum":1719419696,"timestamp":"2024-06-01T22:43:54.087999Z"}]}
{"channel":"book","type":"update","data":[{"symbol":"BCH/USDT","bids":[],"asks":[{"price":463.70,"qty":0.90000000}],"checksum":483077747,"timestamp":"2024-06-01T22:43:54.588942Z"}]}
{"channel":"book","type":"update","data":[{"symbol":"BCH/USDT","bids":[],"asks":[{"price":463.71,"qty":0.00000000},{"price":464.12,"qty":0.04185087}],"checksum":1026476197,"timestamp":"2024-06-01T22:43:54.593802Z"}]}
{"channel":"book","type":"update","data":[{"symbol":"BCH/USDT","bids":[],"asks":[{"price":463.72,"qty":0.00000000},{"price":464.13,"qty":0.05272449}],"checksum":2900302723,"timestamp":"2024-06-01T22:43:54.593967Z"}]}
{"channel":"book","type":"update","data":[{"symbol":"BCH/USDT","bids":[],"asks":[{"price":463.70,"qty":0.00000000},{"price":464.14,"qty":0.08721902}],"checksum":3659151713,"timestamp":"2024-06-01T22:43:55.589756Z"}]}
{"channel":"book","type":"update","data":[{"symbol":"BCH/USDT","bids":[],"asks":[{"price":463.74,"qty":0.90000000}],"checksum":1419110251,"timestamp":"2024-06-01T22:43:55.594460Z"}]}
{"channel":"book","type":"update","data":[{"symbol":"BCH/USDT","bids":[{"price":463.35,"qty":3.00000000}],"asks":[],"checksum":927957514,"timestamp":"2024-06-01T22:43:55.925989Z"}]}
{"channel":"book","type":"update","data":[{"symbol":"BCH/USDT","bids":[{"price":463.35,"qty":0.00000000},{"price":462.28,"qty":1.36603240}],"asks":[],"checksum":385992671,"timestamp":"2024-06-01T22:43:55.926284Z"}]}
{"channel":"book","type":"update","data":[{"symbol":"BCH/USDT","bids":[{"price":463.36,"qty":0.00000000},{"price":462.06,"qty":2.55000000}],"asks":[],"checksum":4287063512,"timestamp":"2024-06-01T22:43:55.926538Z"}]}
{"channel":"book","type":"update","data":[{"symbol":"BCH/USDT","bids":[{"price":463.30,"qty":0.06791242}],"asks":[],"checksum":2935651447,"timestamp":"2024-06-01T22:43:55.929824Z"}]}
{"channel":"book","type":"update","data":[{"symbol":"BCH/USDT","bids":[{"price":463.37,"qty":1.28771250}],"asks":[],"checksum":3807717716,"timestamp":"2024-06-01T22:43:55.930883Z"}]}
{"channel":"book","type":"update","data":[{"symbol":"BCH/USDT","bids":[{"price":463.31,"qty":1.30165500}],"asks":[],"checksum":1330744250,"timestamp":"2024-06-01T22:43:55.930993Z"}]}
{"channel":"book","type":"update","data":[{"symbol":"BCH/USDT","bids":[],"asks":[{"price":463.73,"qty":1.28771250}],"checksum":1160762515,"timestamp":"2024-06-01T22:43:55.931012Z"}]}
{"channel":"book","type":"update","data":[{"symbol":"BCH/USDT","bids":[{"price":463.30,"qty":2.23298691}],"asks":[],"checksum":487281036,"timestamp":"2024-06-01T22:43:55.933139Z"}]}
{"channel":"book","type":"update","data":[{"symbol":"BCH/USDT","bids":[{"price":463.37,"qty":0.00000000},{"price":462.28,"qty":1.36603240}],"asks":[],"checksum":3593756541,"timestamp":"2024-06-01T22:43:55.935378Z"}]}
{"channel":"book","type":"update","data":[{"symbol":"BCH/USDT","bids":[{"price":463.31,"qty":0.00000000},{"price":462.06,"qty":2.55000000}],"asks":[],"checksum":2192465837,"timestamp":"2024-06-01T22:43:55.939513Z"}]}
{"channel":"book","type":"update","data":[{"symbol":"BCH/USDT","bids":[{"price":463.31,"qty":3.00000000}],"asks":[],"checksum":548504385,"timestamp":"2024-06-01T22:43:56.210177Z"}]}
{"channel":"book","type":"update","data":[{"symbol":"BCH/USDT","bids":[{"price":463.32,"qty":3.80879832}],"asks":[],"checksum":3120295412,"timestamp":"2024-06-01T22:43:56.214897Z"}]}
{"channel":"book","type":"update","data":[{"symbol":"BCH/USDT","bids":[{"price":463.33,"qty":0.90000000}],"asks":[],"checksum":2228121369,"timestamp":"2024-06-01T22:43:56.589472Z"}]}
{"channel":"book","type":"update","data":[{"symbol":"BCH/USDT","bids":[],"asks":[{"price":463.72,"qty":0.90000000}],"checksum":3472152537,"timestamp":"2024-06-01T22:43:56.589595Z"}]}
{"channel":"book","type":"update","data":[{"symbol":"BCH/USDT","bids":[],"asks":[{"price":463.74,"qty":0.00000000},{"price":464.12,"qty":0.04185087}],"checksum":194900024,"timestamp":"2024-06-01T22:43:56.593584Z"}]}
{"channel":"book","type":"update","data":[{"symbol":"BCH/USDT","bids":[],"asks":[{"price":463.73,"qty":0.00000000},{"price":464.13,"qty":0.05272449}],"checksum":1108937654,"timestamp":"2024-06-01T22:43:56.593668Z"}]}
{"channel":"book","type":"update","data":[{"symbol":"BCH/USDT","bids":[{"price":463.34,"qty":3.80879832}],"asks":[],"checksum":201548812,"timestamp":"2024-06-01T22:43:56.593883Z"}]}
{"channel":"book","type":"update","data":[{"symbol":"BCH/USDT","bids":[{"price":463.33,"qty":3.90000000}],"asks":[],"checksum":3907917724,"timestamp":"2024-06-01T22:43:56.593901Z"}]}
{"channel":"book","type":"update","data":[{"symbol":"BCH/USDT","bids":[{"price":463.33,"qty":0.90000000}],"asks":[],"checksum":201548812,"timestamp":"2024-06-01T22:43:56.709523Z"}]}
{"channel":"book","type":"update","data":[{"symbol":"BCH/USDT","bids":[{"price":463.35,"qty":3.00000000}],"asks":[],"checksum":112716912,"timestamp":"2024-06-01T22:43:56.709694Z"}]}
{"channel":"book","type":"update","data":[{"symbol":"BCH/USDT","bids":[{"price":463.32,"qty":0.00000000},{"price":462.60,"qty":1.26382000}],"asks":[],"checksum":2469732066,"timestamp":"2024-06-01T22:43:56.713968Z"}]}
{"channel":"book","type":"update","data":[{"symbol":"BCH/USDT","bids":[],"asks":[{"price":463.71,"qty":1.11417750}],"checksum":1612264683,"timestamp":"2024-06-01T22:43:57.134384Z"}]}
{"channel":"book","type":"update","data":[{"symbol":"BCH/USDT","bids":[{"price":463.36,"qty":1.11417750}],"asks":[],"checksum":162509715,"timestamp":"2024-06-01T22:43:57.134401Z"}]}
{"channel":"book","type":"update","data":[{"symbol":"BCH/USDT","bids":[{"price":463.31,"qty":0.00000000},{"price":462.60,"qty":1.26382000}],"asks":[],"checksum":3616566642,"timestamp":"2024-06-01T22:43:57.139213Z"}]}
{"channel":"book","type":"update","data":[{"symbol":"BCH/USDT","bids":[{"price":463.37,"qty":0.90000000}],"asks":[],"checksum":459998808,"timestamp":"2024-06-01T22:43:57.588876Z"}]}
{"channel":"book","type":"update","data":[{"symbol":"BCH/USDT","bids":[{"price":463.36,"qty":0.00000000},{"price":462.60,"qty":1.26382000}],"asks":[],"checksum":1386141244,"timestamp":"2024-06-01T22:43:57.593683Z"}]}
{"channel":"book","type":"update","data":[{"symbol":"BCH/USDT","bids":[{"price":463.33,"qty":0.00000000},{"price":462.42,"qty":1.21000000}],"asks":[],"checksum":2816225478,"timestamp":"2024-06-01T22:43:57.593830Z"}]}
{"channel":"book","type":"update","data":[{"symbol":"BCH/USDT","bids":[{"price":463.37,"qty":0.00000000},{"price":462.32,"qty":2.44000000}],"asks":[],"checksum":3661784918,"timestamp":"2024-06-01T22:43:58.589735Z"}]}
{"channel":"book","type":"update","data":[{"symbol":"BCH/USDT","bids":[{"price":463.36,"qty":0.90000000}],"asks":[],"checksum":3122021848,"timestamp":"2024-06-01T22:43:58.594646Z"}]}
{"channel":"book","type":"update","data":[{"symbol":"BCH/USDT","bids":[{"price":463.37,"qty":1.11633750}],"asks":[],"checksum":708879609,"timestamp":"2024-06-01T22:43:58.599243Z"}]}
{"channel":"book","type":"update","data":[{"symbol":"BCH/USDT","bids":[],"asks":[{"price":463.70,"qty":0.90000000}],"checksum":3375568320,"timestamp":"2024-06-01T22:43:59.589860Z"}]}
{"channel":"book","type":"update","data":[{"symbol":"BCH/USDT","bids":[{"price":463.38,"qty":0.90000000}],"asks":[],"checksum":3487306380,"timestamp":"2024-06-01T22:43:59.589896Z"}]}
{"channel":"book","type":"update","data":[{"symbol":"BCH/USDT","bids":[{"price":463.36,"qty":0.00000000},{"price":462.60,"qty":1.26382000}],"asks":[],"checksum":1609762257,"timestamp":"2024-06-01T22:43:59.594725Z"}]}
{"channel":"book","type":"update","data":[{"symbol":"BCH/USDT","bids":[],"asks":[{"price":463.72,"qty":0.00000000},{"price":464.12,"qty":0.04185087}],"checksum":1241633278,"timestamp":"2024-06-01T22:43:59.594784Z"}]}
{"channel":"book","type":"update","data":[{"symbol":"BCH/USDT","bids":[],"asks":[{"price":463.71,"qty":0.00000000},{"price":464.13,"qty":0.05272449}],"checksum":864673941,"timestamp":"2024-06-01T22:43:59.594964Z"}]}
{"channel":"book","type":"update","data":[{"symbol":"BCH/USDT","bids":[{"price":463.37,"qty":0.00000000},{"price":462.42,"qty":1.21000000}],"asks":[],"checksum":2549188369,"timestamp":"2024-06-01T22:43:59.595033Z"}]}
{"channel":"book","type":"update","data":[{"symbol":"BCH/USDT","bids":[{"price":463.39,"qty":1.22605499}],"asks":[],"checksum":3093912305,"timestamp":"2024-06-01T22:43:59.595135Z"}]}
{"channel":"book","type":"update","data":[{"symbol":"BCH/USDT","bids":[],"asks":[{"price":463.69,"qty":1.27386750}],"checksum":3766539,"timestamp":"2024-06-01T22:43:59.599736Z"}]}
{"channel":"book","type":"update","data":[{"symbol":"BCH/USDT","bids":[{"price":463.40,"qty":0.90000000}],"asks":[],"checksum":1373162520,"timestamp":"2024-06-01T22:44:00.587618Z"}]}
{"channel":"book","type":"update","data":[{"symbol":"BCH/USDT","bids":[{"price":463.38,"qty":0.00000000},{"price":462.60,"qty":1.26382000}],"asks":[],"checksum":1669842955,"timestamp":"2024-06-01T22:44:00.592127Z"}]}
{"channel":"book","type":"update","data":[{"symbol":"BCH/USDT","bids":[{"price":463.39,"qty":0.00000000},{"price":462.42,"qty":1.21000000}],"asks":[],"checksum":1243464634,"timestamp":"2024-06-01T22:44:00.592782Z"}]}
{"channel":"book","type":"update","data":[{"symbol":"BCH/USDT","bids":[{"price":463.41,"qty":1.03528500}],"asks":[],"checksum":494542785,"timestamp":"2024-06-01T22:44:00.592945Z"}]}
{"channel":"book","type":"update","data":[{"symbol":"BCH/USDT","bids":[{"price":463.42,"qty":0.90000000}],"asks":[],"checksum":137117795,"timestamp":"2024-06-01T22:44:01.586323Z"}]}
{"channel":"book","type":"update","data":[{"symbol":"BCH/USDT","bids":[],"asks":[{"price":463.80,"qty":0.00000000},{"price":464.13,"qty":0.05272449}],"checksum":98825387,"timestamp":"2024-06-01T22:44:01.589562Z"}]}
{"channel":"book","type":"update","data":[{"symbol":"BCH/USDT","bids":[{"price":463.40,"qty":0.00000000},{"price":462.60,"qty":1.26382000}],"asks":[],"checksum":197472280,"timestamp":"2024-06-01T22:44:01.591233Z"}]}
{"channel":"book","type":"update","data":[{"symbol":"BCH/USDT","bids":[{"price":463.41,"qty":0.00000000},{"price":462.42,"qty":1.21000000}],"asks":[],"checksum":3829116080,"timestamp":"2024-06-01T22:44:01.591249Z"}]}
{"channel":"book","type":"update","data":[{"symbol":"BCH/USDT","bids":[{"price":463.43,"qty":1.03082250}],"asks":[],"checksum":1088022853,"timestamp":"2024-06-01T22:44:01.591387Z"}]}
{"channel":"book","type":"update","data":[{"symbol":"BCH/USDT","bids":[],"asks":[{"price":463.80,"qty":2.35929953}],"checksum":1248217197,"timestamp":"2024-06-01T22:44:01.592994Z"}]}
{"channel":"book","type":"update","data":[{"symbol":"BCH/USDT","bids":[],"asks":[{"price":463.68,"qty":0.90000000}],"checksum":1240400368,"timestamp":"2024-06-01T22:44:02.589888Z"}]}
{"channel":"book","type":"update","data":[{"symbol":"BCH/USDT","bids":[{"price":463.44,"qty":0.90000000}],"asks":[],"checksum":4254586331,"timestamp":"2024-06-01T22:44:02.590038Z"}]}
{"channel":"book","type":"update","data":[{"symbol":"BCH/USDT","bids":[],"asks":[{"price":463.69,"qty":0.00000000},{"price":464.12,"qty":0.04185087}],"checksum":1578767903,"timestamp":"2024-06-01T22:44:02.594091Z"}]}
{"channel":"book","type":"update","data":[{"symbol":"BCH/USDT","bids":[{"price":463.42,"qty":0.00000000},{"price":462.60,"qty":1.26382000}],"asks":[],"checksum":653932849,"timestamp":"2024-06-01T22:44:02.595476Z"}]}
{"channel":"book","type":"update","data":[{"symbol":"BCH/USDT","bids":[],"asks":[{"price":463.70,"qty":0.00000000},{"price":464.13,"qty":0.05272449}],"checksum":1089211478,"timestamp":"2024-06-01T22:44:02.595653Z"}]}
{"channel":"book","type":"update","data":[{"symbol":"BCH/USDT","bids":[],"asks":[{"price":463.67,"qty":1.01998499}],"checksum":4292545055,"timestamp":"2024-06-01T22:44:02.598374Z"}]}
{"channel":"book","type":"update","data":[{"symbol":"BCH/USDT","bids":[{"price":463.43,"qty":0.00000000},{"price":462.42,"qty":1.21000000}],"asks":[],"checksum":3829121541,"timestamp":"2024-06-01T22:44:02.599362Z"}]}
{"channel":"book","type":"update","data":[{"symbol":"BCH/USDT","bids":[{"price":463.36,"qty":1.04971500}],"asks":[],"checksum":4191647195,"timestamp":"2024-06-01T22:44:02.599564Z"}]}
{"channel":"book","type":"update","data":[{"symbol":"BCH/USDT","bids":[{"price":463.44,"qty":1.93639366}],"asks":[],"checksum":1888214901,"timestamp":"2024-06-01T22:44:02.603222Z"}]}
{"channel":"book","type":"update","data":[{"symbol":"BCH/USDT","bids":[{"price":463.36,"qty":0.00000000},{"price":462.42,"qty":1.21000000}],"asks":[],"checksum":1835493547,"timestamp":"2024-06-01T22:44:02.603435Z"}]}
{"channel":"book","type":"update","data":[{"symbol":"BCH/USDT","bids":[{"price":463.44,"qty":0.90000000}],"asks":[],"checksum":3829121541,"timestamp":"2024-06-01T22:44:03.228345Z"}]}
{"channel":"book","type":"update","data":[{"symbol":"BCH/USDT","bids":[{"price":463.44,"qty":0.00000000},{"price":462.32,"qty":2.44000000}],"asks":[],"checksum":2893049956,"timestamp":"2024-06-01T22:44:03.589695Z"}]}
{"channel":"book","type":"update","data":[{"symbol":"BCH/USDT","bids":[{"price":463.36,"qty":0.90000000}],"asks":[],"checksum":1413539736,"timestamp":"2024-06-01T22:44:03.595192Z"}]}
{"channel":"book","type":"update","data":[{"symbol":"BCH/USDT","bids":[{"price":463.37,"qty":1.14756750}],"asks":[],"checksum":3037803655,"timestamp":"2024-06-01T22:44:04.360221Z"}]}
{"channel":"book","type":"update","data":[{"symbol":"BCH/USDT","bids":[{"price":463.38,"qty":0.90000000}],"asks":[],"checksum":515059908,"timestamp":"2024-06-01T22:44:04.589296Z"}]}
{"channel":"book","type":"update","data":[{"symbol":"BCH/USDT","bids":[{"price":463.36,"qty":0.00000000},{"price":462.60,"qty":1.26382000}],"asks":[],"checksum":656778065,"timestamp":"2024-06-01T22:44:04.593978Z"}]}
{"channel":"book","type":"update","data":[{"symbol":"BCH/USDT","bids":[{"price":463.39,"qty":1.08139500}],"asks":[],"checksum":3784826683,"timestamp":"2024-06-01T22:44:04.594186Z"}]}
{"channel":"book","type":"update","data":[{"symbol":"BCH/USDT","bids":[{"price":463.40,"qty":0.90000000}],"asks":[],"checksum":3538587459,"timestamp":"2024-06-01T22:44:05.587714Z"}]}
{"channel":"book","type":"update","data":[{"symbol":"BCH/USDT","bids":[],"asks":[{"price":463.66,"qty":0.90000000}],"checksum":3287673680,"timestamp":"2024-06-01T22:44:05.587788Z"}]}
{"channel":"book","type":"update","data":[{"symbol":"BCH/USDT","bids":[{"price":463.37,"qty":0.00000000},{"price":462.64,"qty":0.76032560}],"asks":[],"checksum":1280955519,"timestamp":"2024-06-01T22:44:05.592213Z"}]}
{"channel":"book","type":"update","data":[{"symbol":"BCH/USDT","bids":[],"asks":[{"price":463.67,"qty":0.00000000},{"price":464.12,"qty":0.04185087}],"checksum":169575284,"timestamp":"2024-06-01T22:44:05.592261Z"}]}
{"channel":"book","type":"update","data":[{"symbol":"BCH/USDT","bids":[],"asks":[{"price":463.65,"qty":0.92967616}],"checksum":843373899,"timestamp":"2024-06-01T22:44:05.592280Z"}]}
{"channel":"book","type":"update","data":[{"symbol":"BCH/USDT","bids":[{"price":463.41,"qty":1.16092500}],"asks":[],"checksum":728961161,"timestamp":"2024-06-01T22:44:05.592366Z"}]}
{"channel":"book","type":"update","data":[{"symbol":"BCH/USDT","bids":[],"asks":[{"price":463.68,"qty":0.00000000},{"price":464.12,"qty":0.04185087}],"checksum":2306711565,"timestamp":"2024-06-01T22:44:05.592847Z"}]}
{"channel":"book","type":"update","data":[{"symbol":"BCH/USDT","bids":[{"price":463.38,"qty":0.00000000},{"price":462.64,"qty":0.76032560}],"asks":[],"checksum":210307277,"timestamp":"2024-06-01T22:44:05.592949Z"}]}
{"channel":"book","type":"update","data":[{"symbol":"BCH/USDT","bids":[{"price":463.39,"qty":0.00000000},{"price":462.60,"qty":1.26382000}],"asks":[],"checksum":2119506009,"timestamp":"2024-06-01T22:44:06.119449Z"}]}
{"channel":"book","type":"update","data":[{"symbol":"BCH/USDT","bids":[],"asks":[{"price":463.65,"qty":0.00000000},{"price":464.13,"qty":0.05272449}],"checksum":4231159350,"timestamp":"2024-06-01T22:44:06.119665Z"}]}
{"channel":"book","type":"update","data":[{"symbol":"BCH/USDT","bids":[],"asks":[{"price":463.66,"qty":0.00000000},{"price":464.14,"qty":0.08721902}],"checksum":595500244,"timestamp":"2024-06-01T22:44:06.590001Z"}]}
{"channel":"book","type":"update","data":[{"symbol":"BCH/USDT","bids":[],"asks":[{"price":463.74,"qty":0.90000000}],"checksum":1176890191,"timestamp":"2024-06-01T22:44:06.594451Z"}]}
{"channel":"book","type":"update","data":[{"symbol":"BCH/USDT","bids":[],"asks":[{"price":463.73,"qty":1.32012749}],"checksum":181003520,"timestamp":"2024-06-01T22:44:07.140705Z"}]}
{"channel":"book","type":"update","data":[{"symbol":"BCH/USDT","bids":[],"asks":[{"price":463.72,"qty":0.90000000}],"checksum":2788128075,"timestamp":"2024-06-01T22:44:07.587781Z"}]}
{"channel":"book","type":"update","data":[{"symbol":"BCH/USDT","bids":[],"asks":[{"price":463.73,"qty":0.00000000},{"price":464.12,"qty":0.04185087}],"checksum":71563708,"timestamp":"2024-06-01T22:44:07.592210Z"}]}
{"channel":"book","type":"update","data":[{"symbol":"BCH/USDT","bids":[],"asks":[{"price":463.74,"qty":0.00000000},{"price":464.13,"qty":0.05272449}],"checksum":3259656659,"timestamp":"2024-06-01T22:44:07.592468Z"}]}
{"channel":"book","type":"update","data":[{"symbol":"BCH/USDT","bids":[],"asks":[{"price":463.72,"qty":0.00000000},{"price":464.14,"qty":0.08721902}],"checksum":595500244,"timestamp":"2024-06-01T22:44:08.587811Z"}]}
{"channel":"book","type":"update","data":[{"symbol":"BCH/USDT","bids":[{"price":463.42,"qty":0.90000000}],"asks":[],"checksum":1736050514,"timestamp":"2024-06-01T22:44:08.588058Z"}]}
{"channel":"book","type":"update","data":[{"symbol":"BCH/USDT","bids":[{"price":463.40,"qty":0.00000000},{"price":462.60,"qty":1.26382000}],"asks":[],"checksum":3485918035,"timestamp":"2024-06-01T22:44:08.592222Z"}]}
{"channel":"book","type":"update","data":[{"symbol":"BCH/USDT","bids":[{"price":463.41,"qty":0.00000000},{"price":462.42,"qty":1.21000000}],"asks":[],"checksum":1735804391,"timestamp":"2024-06-01T22:44:08.592336Z"}]}
{"channel":"book","type":"update","data":[{"symbol":"BCH/USDT","bids":[{"price":463.43,"qty":1.28658000}],"asks":[],"checksum":863387344,"timestamp":"2024-06-01T22:44:08.682150Z"}]}
{"channel":"book","type":"update","data":[{"symbol":"BCH/USDT","bids":[],"asks":[{"price":463.74,"qty":1.28658000}],"checksum":988157015,"timestamp":"2024-06-01T22:44:08.682286Z"}]}
{"channel":"book","type":"update","data":[{"symbol":"BCH/USDT","bids":[],"asks":[{"price":463.74,"qty":2.18658000}],"checksum":4253611824,"timestamp":"2024-06-01T22:44:08.688859Z"}]}
{"channel":"book","type":"update","data":[{"symbol":"BCH/USDT","bids":[{"price":463.44,"qty":0.90000000}],"asks":[],"checksum":2036891909,"timestamp":"2024-06-01T22:44:09.587651Z"}]}
{"channel":"book","type":"update","data":[{"symbol":"BCH/USDT","bids":[{"price":463.42,"qty":0.00000000},{"price":462.60,"qty":1.26382000}],"asks":[],"checksum":3686773468,"timestamp":"2024-06-01T22:44:09.591899Z"}]}
{"channel":"book","type":"update","data":[{"symbol":"BCH/USDT","bids":[{"price":463.43,"qty":0.00000000},{"price":462.42,"qty":1.21000000}],"asks":[],"checksum":3845501507,"timestamp":"2024-06-01T22:44:09.592029Z"}]}
{"channel":"book","type":"update","data":[{"symbol":"BCH/USDT","bids":[{"price":463.45,"qty":1.17347684}],"asks":[],"checksum":3946505606,"timestamp":"2024-06-01T22:44:09.592251Z"}]}
{"channel":"book","type":"update","data":[{"symbol":"BCH/USDT","bids":[{"price":463.45,"qty":0.00000000},{"price":462.42,"qty":1.21000000}],"asks":[],"checksum":3845501507,"timestamp":"2024-06-01T22:44:10.597561Z"}]}
{"channel":"book","type":"update","data":[{"symbol":"BCH/USDT","bids":[{"price":463.36,"qty":1.22122935}],"asks":[],"checksum":591162341,"timestamp":"2024-06-01T22:44:10.598008Z"}]}
{"channel":"book","type":"update","data":[{"symbol":"BCH/USDT","bids":[{"price":463.44,"qty":0.00000000},{"price":462.42,"qty":1.21000000}],"asks":[],"checksum":4214918519,"timestamp":"2024-06-01T22:44:10.603205Z"}]}
{"channel":"book","type":"update","data":[{"symbol":"BCH/USDT","bids":[{"price":463.37,"qty":0.90000000}],"asks":[],"checksum":2391620454,"timestamp":"2024-06-01T22:44:11.087704Z"}]}
{"channel":"book","type":"update","data":[{"symbol":"BCH/USDT","bids":[{"price":463.30,"qty":0.06791242}],"asks":[],"checksum":2466375587,"timestamp":"2024-06-01T22:44:11.091744Z"}]}
{"channel":"book","type":"update","data":[{"symbol":"BCH/USDT","bids":[{"price":463.36,"qty":0.00000000},{"price":462.42,"qty":1.21000000}],"asks":[],"checksum":3409991875,"timestamp":"2024-06-01T22:44:11.093107Z"}]}
{"channel":"book","type":"update","data":[{"symbol":"BCH/USDT","bids":[{"price":463.38,"qty":1.22132685}],"asks":[],"checksum":2762197588,"timestamp":"2024-06-01T22:44:11.093258Z"}]}
{"channel":"book","type":"update","data":[{"symbol":"BCH/USDT","bids":[{"price":463.30,"qty":1.42798691}],"asks":[],"checksum":2857289098,"timestamp":"2024-06-01T22:44:11.095237Z"}]}
{"channel":"book","type":"update","data":[{"symbol":"BCH/USDT","bids":[{"price":463.39,"qty":0.90000000}],"asks":[],"checksum":1941513208,"timestamp":"2024-06-01T22:44:11.589315Z"}]}
{"channel":"book","type":"update","data":[{"symbol":"BCH/USDT","bids":[{"price":463.37,"qty":0.00000000},{"price":462.60,"qty":1.26382000}],"asks":[],"checksum":3608470446,"timestamp":"2024-06-01T22:44:11.593700Z"}]}
{"channel":"book","type":"update","data":[{"symbol":"BCH/USDT","bids":[{"price":463.38,"qty":0.00000000},{"price":462.42,"qty":1.21000000}],"asks":[],"checksum":3790370030,"timestamp":"2024-06-01T22:44:11.593956Z"}]}
{"channel":"book","type":"update","data":[{"symbol":"BCH/USDT","bids":[{"price":463.40,"qty":1.20597435}],"asks":[],"checksum":3499123573,"timestamp":"2024-06-01T22:44:11.594234Z"}]}
{"channel":"book","type":"update","data":[{"symbol":"BCH/USDT","bids":[{"price":463.41,"qty":0.90000000}],"asks":[],"checksum":886187105,"timestamp":"2024-06-01T22:44:12.089153Z"}]}
{"channel":"book","type":"update","data":[{"symbol":"BCH/USDT","bids":[{"price":463.40,"qty":0.00000000},{"price":462.60,"qty":1.26382000}],"asks":[],"checksum":720923230,"timestamp":"2024-06-01T22:44:12.094456Z"}]}
{"channel":"book","type":"update","data":[{"symbol":"BCH/USDT","bids":[{"price":463.42,"qty":1.13186684}],"asks":[],"checksum":3663583553,"timestamp":"2024-06-01T22:44:12.094579Z"}]}
{"channel":"book","type":"update","data":[{"symbol":"BCH/USDT","bids":[{"price":463.41,"qty":0.00000000},{"price":462.60,"qty":1.26382000}],"asks":[],"checksum":229812242,"timestamp":"2024-06-01T22:44:12.100952Z"}]}
{"channel":"book","type":"update","data":[{"symbol":"BCH/USDT","bids":[{"price":463.43,"qty":0.90000000}],"asks":[],"checksum":4095746433,"timestamp":"2024-06-01T22:44:12.587324Z"}]}
