{"channel":"book","type":"snapshot","data":[{"symbol":"BCH/ETH","bids":[{"price":0.1210,"qty":1.40200683},{"price":0.1209,"qty":4.04408022},{"price":0.1208,"qty":6.92620200},{"price":0.1207,"qty":0.02500000},{"price":0.1205,"qty":4.24536900},{"price":0.1201,"qty":4.28118300},{"price":0.1200,"qty":0.02500000},{"price":0.1198,"qty":30.06199799},{"price":0.1195,"qty":108.16001562},{"price":0.1194,"qty":0.69386100}],"asks":[{"price":0.1214,"qty":1.10586300},{"price":0.1215,"qty":9.09369700},{"price":0.1216,"qty":2.58366799},{"price":0.1217,"qty":4.24536900},{"price":0.1221,"qty":0.02516319},{"price":0.1222,"qty":2.83198500},{"price":0.1223,"qty":1.44919800},{"price":0.1225,"qty":15.21167641},{"price":0.1232,"qty":88.11505212},{"price":0.1233,"qty":0.69386100}],"checksum":2687232514}]}
{"channel":"book","type":"update","data":[{"symbol":"BCH/ETH","bids":[],"asks":[{"price":0.1214,"qty":0.00000000},{"price":0.1241,"qty":0.18428760}],"checksum":3304066436,"timestamp":"2024-06-01T22:43:51.460315Z"}]}
{"channel":"book","type":"update","data":[{"symbol":"BCH/ETH","bids":[],"asks":[{"price":0.1215,"qty":6.95120200}],"checksum":4265034696,"timestamp":"2024-06-01T22:43:51.460664Z"}]}
{"channel":"book","type":"update","data":[{"symbol":"BCH/ETH","bids":[],"asks":[{"price":0.1221,"qty":0.00000000},{"price":0.1242,"qty":0.69386100},{"price":0.1222,"qty":2.85712760}],"checksum":2183633006,"timestamp":"2024-06-01T22:43:51.462757Z"}]}
{"channel":"book","type":"update","data":[{"symbol":"BCH/ETH","bids":[],"asks":[{"price":0.1215,"qty":8.05706500}],"checksum":3482001,"timestamp":"2024-06-01T22:43:51.463018Z"}]}
{"channel":"book","type":"update","data":[{"symbol":"BCH/ETH","bids":[],"asks":[{"price":0.1214,"qty":2.14249500}],"checksum":269232358,"timestamp":"2024-06-01T22:43:51.463343Z"}]}
{"channel":"book","type":"update","data":[{"symbol":"BCH/ETH","bids":[],"asks":[{"price":0.1215,"qty":6.95120200}],"checksum":609107795,"timestamp":"2024-06-01T22:43:51.466139Z"}]}
{"channel":"book","type":"update","data":[{"symbol":"BCH/ETH","bids":[],"asks":[{"price":0.1214,"qty":3.24835800}],"checksum":1729753896,"timestamp":"2024-06-01T22:43:51.469013Z"}]}
{"channel":"book","type":"update","data":[{"symbol":"BCH/ETH","bids":[{"price":0.1210,"qty":1.10586300}],"asks":[],"checksum":4071932286,"timestamp":"2024-06-01T22:43:53.560882Z"}]}
{"channel":"book","type":"update","data":[{"symbol":"BCH/ETH","bids":[],"asks":[{"price":0.1232,"qty":0.00000000},{"price":0.1242,"qty":0.69386100}],"checksum":3144479080,"timestamp":"2024-06-01T22:43:53.588055Z"}]}
{"channel":"book","type":"update","data":[{"symbol":"BCH/ETH","bids":[],"asks":[{"price":0.1224,"qty":116.44269934}],"checksum":223608841,"timestamp":"2024-06-01T22:43:53.800458Z"}]}
{"channel":"book","type":"update","data":[{"symbol":"BCH/ETH","bids":[],"asks":[{"price":0.1222,"qty":2.83198500},{"price":0.1221,"qty":0.02516319}],"checksum":2724852024,"timestamp":"2024-06-01T22:43:53.860489Z"}]}
{"channel":"book","type":"update","data":[{"symbol":"BCH/ETH","bids":[{"price":0.1210,"qty":0.00000000},{"price":0.1183,"qty":0.69386100}],"asks":[],"checksum":2687985162,"timestamp":"2024-06-01T22:43:57.344706Z"}]}
{"channel":"book","type":"update","data":[{"symbol":"BCH/ETH","bids":[],"asks":[{"price":0.1214,"qty":2.14249500}],"checksum":2652010338,"timestamp":"2024-06-01T22:43:57.345023Z"}]}
{"channel":"book","type":"update","data":[{"symbol":"BCH/ETH","bids":[{"price":0.1209,"qty":1.90158522}],"asks":[],"checksum":2727656426,"timestamp":"2024-06-01T22:43:57.347305Z"}]}
{"channel":"book","type":"update","data":[{"symbol":"BCH/ETH","bids":[],"asks":[{"price":0.1214,"qty":0.00000000},{"price":0.1241,"qty":0.18428760}],"checksum":846555083,"timestamp":"2024-06-01T22:43:57.347331Z"}]}
{"channel":"book","type":"update","data":[{"symbol":"BCH/ETH","bids":[],"asks":[{"price":0.1213,"qty":1.10586300}],"checksum":1710445521,"timestamp":"2024-06-01T22:43:57.347484Z"}]}
{"channel":"book","type":"update","data":[{"symbol":"BCH/ETH","bids":[{"price":0.1209,"qty":3.00744822}],"asks":[],"checksum":28490913,"timestamp":"2024-06-01T22:43:57.347544Z"}]}
{"channel":"book","type":"update","data":[{"symbol":"BCH/ETH","bids":[],"asks":[{"price":0.1221,"qty":0.00000000},{"price":0.1241,"qty":0.18428760},{"price":0.1222,"qty":2.85712760}],"checksum":1031895788,"timestamp":"2024-06-01T22:43:57.349680Z"}]}
{"channel":"book","type":"update","data":[{"symbol":"BCH/ETH","bids":[{"price":0.1208,"qty":9.06869700}],"asks":[],"checksum":1801255076,"timestamp":"2024-06-01T22:43:57.349933Z"}]}
{"channel":"book","type":"update","data":[{"symbol":"BCH/ETH","bids":[{"price":0.1209,"qty":3.30400669}],"asks":[],"checksum":1337777981,"timestamp":"2024-06-01T22:43:57.350048Z"}]}
{"channel":"book","type":"update","data":[{"symbol":"BCH/ETH","bids":[],"asks":[{"price":0.1213,"qty":0.00000000},{"price":0.1242,"qty":0.69386100}],"checksum":119204493,"timestamp":"2024-06-01T22:43:57.350115Z"}]}
{"channel":"book","type":"update","data":[{"symbol":"BCH/ETH","bids":[],"asks":[{"price":0.1215,"qty":9.09369700}],"checksum":2018123896,"timestamp":"2024-06-01T22:43:57.350162Z"}]}
{"channel":"book","type":"update","data":[{"symbol":"BCH/ETH","bids":[],"asks":[{"price":0.1215,"qty":10.19956000}],"checksum":3828573521,"timestamp":"2024-06-01T22:43:57.352770Z"}]}
{"channel":"book","type":"update","data":[{"symbol":"BCH/ETH","bids":[],"asks":[{"price":0.1215,"qty":8.05706500}],"checksum":2231915378,"timestamp":"2024-06-01T22:43:57.353069Z"}]}
{"channel":"book","type":"update","data":[{"symbol":"BCH/ETH","bids":[],"asks":[{"price":0.1214,"qty":2.14249500}],"checksum":3392292420,"timestamp":"2024-06-01T22:43:57.355629Z"}]}
{"channel":"book","type":"update","data":[{"symbol":"BCH/ETH","bids":[],"asks":[{"price":0.1214,"qty":0.00000000},{"price":0.1242,"qty":0.69386100}],"checksum":2231915378,"timestamp":"2024-06-01T22:43:57.358316Z"}]}
{"channel":"book","type":"update","data":[{"symbol":"BCH/ETH","bids":[],"asks":[{"price":0.1215,"qty":6.95120200}],"checksum":119204493,"timestamp":"2024-06-01T22:43:57.358597Z"}]}
{"channel":"book","type":"update","data":[{"symbol":"BCH/ETH","bids":[],"asks":[{"price":0.1215,"qty":9.09369700}],"checksum":2018123896,"timestamp":"2024-06-01T22:43:57.361217Z"}]}
{"channel":"book","type":"update","data":[{"symbol":"BCH/ETH","bids":[],"asks":[{"price":0.1214,"qty":1.10586300}],"checksum":211059439,"timestamp":"2024-06-01T22:43:57.361281Z"}]}
{"channel":"book","type":"update","data":[{"symbol":"BCH/ETH","bids":[],"asks":[{"price":0.1215,"qty":6.95120200}],"checksum":690451513,"timestamp":"2024-06-01T22:43:57.363975Z"}]}
{"channel":"book","type":"update","data":[{"symbol":"BCH/ETH","bids":[],"asks":[{"price":0.1214,"qty":0.00000000},{"price":0.1242,"qty":0.69386100}],"checksum":119204493,"timestamp":"2024-06-01T22:43:57.364229Z"}]}
{"channel":"book","type":"update","data":[{"symbol":"BCH/ETH","bids":[],"asks":[{"price":0.1214,"qty":2.14249500}],"checksum":4268773873,"timestamp":"2024-06-01T22:43:57.366570Z"}]}
{"channel":"book","type":"update","data":[{"symbol":"BCH/ETH","bids":[],"asks":[{"price":0.1215,"qty":8.05706500}],"checksum":3392292420,"timestamp":"2024-06-01T22:43:57.366684Z"}]}
{"channel":"book","type":"update","data":[{"symbol":"BCH/ETH","bids":[],"asks":[{"price":0.1215,"qty":6.95120200}],"checksum":4268773873,"timestamp":"2024-06-01T22:43:57.369553Z"}]}
{"channel":"book","type":"update","data":[{"symbol":"BCH/ETH","bids":[],"asks":[{"price":0.1214,"qty":3.24835800}],"checksum":3173490058,"timestamp":"2024-06-01T22:43:57.372162Z"}]}
{"channel":"book","type":"update","data":[{"symbol":"BCH/ETH","bids":[{"price":0.1209,"qty":18.17562724}],"asks":[],"checksum":55342066,"timestamp":"2024-06-01T22:43:57.493366Z"}]}
{"channel":"book","type":"update","data":[{"symbol":"BCH/ETH","bids":[],"asks":[{"price":0.1222,"qty":2.83198500},{"price":0.1221,"qty":0.02516319}],"checksum":2893120195,"timestamp":"2024-06-01T22:43:59.750408Z"}]}
{"channel":"book","type":"update","data":[{"symbol":"BCH/ETH","bids":[{"price":0.1195,"qty":21.58920742}],"asks":[],"checksum":1485327581,"timestamp":"2024-06-01T22:43:59.754422Z"}]}
{"channel":"book","type":"update","data":[{"symbol":"BCH/ETH","bids":[{"price":0.1195,"qty":166.64568620}],"asks":[],"checksum":1360163767,"timestamp":"2024-06-01T22:43:59.963284Z"}]}
{"channel":"book","type":"update","data":[{"symbol":"BCH/ETH","bids":[{"price":0.1198,"qty":0.00000000},{"price":0.1181,"qty":0.07201578}],"asks":[],"checksum":1911842552,"timestamp":"2024-06-01T22:44:02.461403Z"}]}
{"channel":"book","type":"update","data":[{"symbol":"BCH/ETH","bids":[{"price":0.1197,"qty":30.11892379}],"asks":[],"checksum":3055162558,"timestamp":"2024-06-01T22:44:02.501618Z"}]}
{"channel":"book","type":"update","data":[{"symbol":"BCH/ETH","bids":[],"asks":[{"price":0.1214,"qty":2.14249500}],"checksum":4115519685,"timestamp":"2024-06-01T22:44:03.229348Z"}]}
{"channel":"book","type":"update","data":[{"symbol":"BCH/ETH","bids":[],"asks":[{"price":0.1213,"qty":1.10586300}],"checksum":3856860143,"timestamp":"2024-06-01T22:44:03.232219Z"}]}
{"channel":"book","type":"update","data":[{"symbol":"BCH/ETH","bids":[],"asks":[{"price":0.1213,"qty":0.00000000},{"price":0.1233,"qty":0.69386100}],"checksum":4115519685,"timestamp":"2024-06-01T22:44:03.234661Z"}]}
{"channel":"book","type":"update","data":[{"symbol":"BCH/ETH","bids":[{"price":0.1195,"qty":21.58920742}],"asks":[],"checksum":3605484475,"timestamp":"2024-06-01T22:44:03.235062Z"}]}
{"channel":"book","type":"update","data":[{"symbol":"BCH/ETH","bids":[],"asks":[{"price":0.1214,"qty":0.00000000},{"price":0.1241,"qty":0.18428760}],"checksum":1174835098,"timestamp":"2024-06-01T22:44:03.237219Z"}]}
{"channel":"book","type":"update","data":[{"symbol":"BCH/ETH","bids":[],"asks":[{"price":0.1214,"qty":1.10586300}],"checksum":2349888858,"timestamp":"2024-06-01T22:44:03.237339Z"}]}
{"channel":"book","type":"update","data":[{"symbol":"BCH/ETH","bids":[],"asks":[{"price":0.1221,"qty":0.00000000},{"price":0.1241,"qty":0.18428760},{"price":0.1222,"qty":2.85712760}],"checksum":1260967625,"timestamp":"2024-06-01T22:44:03.239793Z"}]}
{"channel":"book","type":"update","data":[{"symbol":"BCH/ETH","bids":[],"asks":[{"price":0.1215,"qty":9.09369700}],"checksum":1855660063,"timestamp":"2024-06-01T22:44:03.239970Z"}]}
{"channel":"book","type":"update","data":[{"symbol":"BCH/ETH","bids":[],"asks":[{"price":0.1214,"qty":0.00000000},{"price":0.1242,"qty":0.69386100}],"checksum":440763016,"timestamp":"2024-06-01T22:44:03.239985Z"}]}
{"channel":"book","type":"update","data":[{"symbol":"BCH/ETH","bids":[],"asks":[{"price":0.1215,"qty":6.95120200}],"checksum":1695893629,"timestamp":"2024-06-01T22:44:03.242354Z"}]}
{"channel":"book","type":"update","data":[{"symbol":"BCH/ETH","bids":[],"asks":[{"price":0.1215,"qty":8.05706500}],"checksum":3876057474,"timestamp":"2024-06-01T22:44:03.242859Z"}]}
{"channel":"book","type":"update","data":[{"symbol":"BCH/ETH","bids":[],"asks":[{"price":0.1214,"qty":2.14249500}],"checksum":2822628532,"timestamp":"2024-06-01T22:44:03.244908Z"}]}
{"channel":"book","type":"update","data":[{"symbol":"BCH/ETH","bids":[],"asks":[{"price":0.1215,"qty":6.95120200}],"checksum":2625630977,"timestamp":"2024-06-01T22:44:03.247260Z"}]}
{"channel":"book","type":"update","data":[{"symbol":"BCH/ETH","bids":[],"asks":[{"price":0.1214,"qty":3.24835800}],"checksum":3743956858,"timestamp":"2024-06-01T22:44:03.250263Z"}]}
{"channel":"book","type":"update","data":[{"symbol":"BCH/ETH","bids":[{"price":0.1198,"qty":145.94635640}],"asks":[],"checksum":2185939633,"timestamp":"2024-06-01T22:44:03.438594Z"}]}
{"channel":"book","type":"update","data":[{"symbol":"BCH/ETH","bids":[],"asks":[{"price":0.1222,"qty":2.83198500},{"price":0.1221,"qty":0.02516319}],"checksum":2393743540,"timestamp":"2024-06-01T22:44:05.630472Z"}]}
{"channel":"book","type":"update","data":[{"symbol":"BCH/ETH","bids":[],"asks":[{"price":0.1214,"qty":2.14249500}],"checksum":3501509957,"timestamp":"2024-06-01T22:44:09.113800Z"}]}
{"channel":"book","type":"update","data":[{"symbol":"BCH/ETH","bids":[],"asks":[{"price":0.1213,"qty":1.10586300}],"checksum":2933791391,"timestamp":"2024-06-01T22:44:09.116497Z"}]}
