{"channel":"book","type":"snapshot","data":[{"symbol":"BCH/USD","bids":[{"price":463.05,"qty":0.43181172},{"price":463.04,"qty":0.47968687},{"price":463.03,"qty":1.03181116},{"price":463.02,"qty":5.39933480},{"price":463.00,"qty":0.44000000},{"price":462.93,"qty":1.80255901},{"price":462.90,"qty":0.92053054},{"price":462.86,"qty":0.43000000},{"price":462.85,"qty":10.80244803},{"price":462.84,"qty":10.80000000}],"asks":[{"price":463.19,"qty":0.03762589},{"price":463.20,"qty":0.15636927},{"price":463.23,"qty":0.05930895},{"price":463.24,"qty":0.64853433},{"price":463.25,"qty":5.55143936},{"price":463.26,"qty":0.06145513},{"price":463.36,"qty":7.07000000},{"price":463.37,"qty":0.86359037},{"price":463.40,"qty":2.89779953},{"price":463.41,"qty":4.26149332}],"checksum":2051295999}]}
{"channel":"book","type":"update","data":[{"symbol":"BCH/USD","bids":[],"asks":[{"price":463.25,"qty":5.44729153}],"checksum":2715576481,"timestamp":"2024-06-01T22:43:53.523747Z"}]}
{"channel":"book","type":"update","data":[{"symbol":"BCH/USD","bids":[],"asks":[{"price":463.24,"qty":0.75268216}],"checksum":3173024082,"timestamp":"2024-06-01T22:43:53.672118Z"}]}
{"channel":"book","type":"update","data":[{"symbol":"BCH/USD","bids":[{"price":463.04,"qty":0.00000000},{"price":462.83,"qty":8.20209125}],"asks":[],"checksum":2689266194,"timestamp":"2024-06-01T22:43:55.949210Z"}]}
{"channel":"book","type":"update","data":[{"symbol":"BCH/USD","bids":[],"asks":[{"price":463.39,"qty":10.79013885}],"checksum":1031343894,"timestamp":"2024-06-01T22:43:55.951522Z"}]}
{"channel":"book","type":"update","data":[{"symbol":"BCH/USD","bids":[{"price":463.05,"qty":0.00000000},{"price":462.82,"qty":10.80000000}],"asks":[],"checksum":320325038,"timestamp":"2024-06-01T22:43:55.953287Z"}]}
{"channel":"book","type":"update","data":[{"symbol":"BCH/USD","bids":[{"price":463.04,"qty":0.47968687}],"asks":[],"checksum":3470332909,"timestamp":"2024-06-01T22:43:56.068910Z"}]}
{"channel":"book","type":"update","data":[{"symbol":"BCH/USD","bids":[{"price":463.05,"qty":0.43181470}],"asks":[],"checksum":1045458351,"timestamp":"2024-06-01T22:43:56.072886Z"}]}
{"channel":"book","type":"update","data":[{"symbol":"BCH/USD","bids":[{"price":462.84,"qty":0.00000000},{"price":462.83,"qty":8.20209125}],"asks":[],"checksum":2107372146,"timestamp":"2024-06-01T22:44:03.227350Z"}]}
{"channel":"book","type":"update","data":[{"symbol":"BCH/USD","bids":[],"asks":[{"price":463.38,"qty":10.80000000}],"checksum":1723025640,"timestamp":"2024-06-01T22:44:03.233803Z"}]}
{"channel":"book","type":"update","data":[{"symbol":"BCH/USD","bids":[{"price":463.05,"qty":0.00000000},{"price":462.80,"qty":1.44500000}],"asks":[],"checksum":1152288928,"timestamp":"2024-06-01T22:44:03.239812Z"}]}
{"channel":"book","type":"update","data":[{"symbol":"BCH/USD","bids":[{"price":462.90,"qty":0.00000000},{"price":462.79,"qty":10.80000000}],"asks":[],"checksum":1171505143,"timestamp":"2024-06-01T22:44:03.244767Z"}]}
{"channel":"book","type":"update","data":[{"symbol":"BCH/USD","bids":[{"price":462.90,"qty":0.58605718}],"asks":[],"checksum":3963889256,"timestamp":"2024-06-01T22:44:03.248234Z"}]}
{"channel":"book","type":"update","data":[{"symbol":"BCH/USD","bids":[{"price":463.04,"qty":0.00000000},{"price":462.79,"qty":10.80000000}],"asks":[],"checksum":2256535148,"timestamp":"2024-06-01T22:44:03.248581Z"}]}
{"channel":"book","type":"update","data":[{"symbol":"BCH/USD","bids":[{"price":463.00,"qty":0.91972831}],"asks":[],"checksum":3992056419,"timestamp":"2024-06-01T22:44:03.374174Z"}]}
{"channel":"book","type":"update","data":[{"symbol":"BCH/USD","bids":[{"price":463.02,"qty":0.00000000},{"price":462.75,"qty":6.48047877}],"asks":[],"checksum":4114376982,"timestamp":"2024-06-01T22:44:04.245320Z"}]}
{"channel":"book","type":"update","data":[{"symbol":"BCH/USD","bids":[{"price":463.03,"qty":0.43181116}],"asks":[],"checksum":2301331186,"timestamp":"2024-06-01T22:44:04.248314Z"}]}
{"channel":"book","type":"update","data":[{"symbol":"BCH/USD","bids":[{"price":462.95,"qty":0.60000000}],"asks":[],"checksum":43294693,"timestamp":"2024-06-01T22:44:04.248440Z"}]}
{"channel":"book","type":"update","data":[{"symbol":"BCH/USD","bids":[{"price":462.80,"qty":12.24500000}],"asks":[],"checksum":1333575504,"timestamp":"2024-06-01T22:44:04.248618Z"}]}
{"channel":"book","type":"update","data":[{"symbol":"BCH/USD","bids":[{"price":462.99,"qty":5.39968403}],"asks":[],"checksum":1310806971,"timestamp":"2024-06-01T22:44:04.249301Z"}]}
{"channel":"book","type":"update","data":[{"symbol":"BCH/USD","bids":[{"price":463.03,"qty":0.00000000},{"price":462.79,"qty":10.80000000}],"asks":[],"checksum":702430371,"timestamp":"2024-06-01T22:44:04.251520Z"}]}
{"channel":"book","type":"update","data":[{"symbol":"BCH/USD","bids":[{"price":463.01,"qty":0.43184596}],"asks":[],"checksum":731336021,"timestamp":"2024-06-01T22:44:04.251649Z"}]}
{"channel":"book","type":"update","data":[{"symbol":"BCH/USD","bids":[{"price":462.95,"qty":0.00000000},{"price":462.79,"qty":10.80000000}],"asks":[],"checksum":2059677475,"timestamp":"2024-06-01T22:44:04.252029Z"}]}
{"channel":"book","type":"update","data":[{"symbol":"BCH/USD","bids":[{"price":463.00,"qty":1.51972831}],"asks":[],"checksum":3711930506,"timestamp":"2024-06-01T22:44:04.252209Z"}]}
{"channel":"book","type":"update","data":[{"symbol":"BCH/USD","bids":[{"price":463.04,"qty":0.43184569}],"asks":[],"checksum":3629648682,"timestamp":"2024-06-01T22:44:04.255000Z"}]}
{"channel":"book","type":"update","data":[{"symbol":"BCH/USD","bids":[{"price":463.04,"qty":0.00000000},{"price":462.79,"qty":10.80000000}],"asks":[],"checksum":3711930506,"timestamp":"2024-06-01T22:44:04.258125Z"}]}
{"channel":"book","type":"update","data":[{"symbol":"BCH/USD","bids":[{"price":463.00,"qty":1.07972831}],"asks":[],"checksum":3827366372,"timestamp":"2024-06-01T22:44:04.499005Z"}]}
{"channel":"book","type":"update","data":[{"symbol":"BCH/USD","bids":[{"price":462.99,"qty":5.74968403}],"asks":[],"checksum":2103545317,"timestamp":"2024-06-01T22:44:04.632645Z"}]}
{"channel":"book","type":"update","data":[{"symbol":"BCH/USD","bids":[],"asks":[{"price":463.38,"qty":0.00000000},{"price":463.40,"qty":4.48404953}],"checksum":2467109256,"timestamp":"2024-06-01T22:44:04.748256Z"}]}
{"channel":"book","type":"update","data":[{"symbol":"BCH/USD","bids":[{"price":462.79,"qty":11.88000000}],"asks":[],"checksum":3080274860,"timestamp":"2024-06-01T22:44:06.229400Z"}]}
{"channel":"book","type":"update","data":[{"symbol":"BCH/USD","bids":[{"price":462.80,"qty":1.44500000},{"price":462.83,"qty":19.00209125}],"asks":[],"checksum":1600621967,"timestamp":"2024-06-01T22:44:06.229572Z"}]}
{"channel":"book","type":"update","data":[{"symbol":"BCH/USD","bids":[{"price":462.99,"qty":0.35000000}],"asks":[],"checksum":3779398677,"timestamp":"2024-06-01T22:44:06.289705Z"}]}
{"channel":"book","type":"update","data":[{"symbol":"BCH/USD","bids":[{"price":463.02,"qty":5.39933480}],"asks":[],"checksum":66283546,"timestamp":"2024-06-01T22:44:06.294024Z"}]}
{"channel":"book","type":"update","data":[{"symbol":"BCH/USD","bids":[{"price":463.03,"qty":0.43182837}],"asks":[],"checksum":2033624334,"timestamp":"2024-06-01T22:44:06.297434Z"}]}
{"channel":"book","type":"update","data":[{"symbol":"BCH/USD","bids":[{"price":462.99,"qty":1.21361556}],"asks":[],"checksum":350241523,"timestamp":"2024-06-01T22:44:14.629080Z"}]}
{"channel":"book","type":"update","data":[{"symbol":"BCH/USD","bids":[],"asks":[{"price":463.36,"qty":7.10335154}],"checksum":2032409699,"timestamp":"2024-06-01T22:44:16.103559Z"}]}
{"channel":"book","type":"update","data":[{"symbol":"BCH/USD","bids":[{"price":462.90,"qty":0.00000000},{"price":462.81,"qty":2.52300000}],"asks":[],"checksum":969655537,"timestamp":"2024-06-01T22:44:21.538474Z"}]}
{"channel":"book","type":"update","data":[{"symbol":"BCH/USD","bids":[{"price":462.90,"qty":0.89219870}],"asks":[],"checksum":3112746471,"timestamp":"2024-06-01T22:44:21.541551Z"}]}
{"channel":"book","type":"update","data":[{"symbol":"BCH/USD","bids":[{"price":463.00,"qty":0.60000000}],"asks":[],"checksum":4053115656,"timestamp":"2024-06-01T22:44:24.875065Z"}]}
{"channel":"book","type":"update","data":[{"symbol":"BCH/USD","bids":[{"price":462.99,"qty":1.69335423}],"asks":[],"checksum":2534150052,"timestamp":"2024-06-01T22:44:25.967795Z"}]}
{"channel":"book","type":"update","data":[{"symbol":"BCH/USD","bids":[],"asks":[{"price":463.32,"qty":0.36817037}],"checksum":2729279911,"timestamp":"2024-06-01T22:44:26.059567Z"}]}
{"channel":"book","type":"update","data":[{"symbol":"BCH/USD","bids":[{"price":462.90,"qty":0.00000000},{"price":462.80,"qty":1.44300000}],"asks":[],"checksum":909754882,"timestamp":"2024-06-01T22:44:26.409578Z"}]}
{"channel":"book","type":"update","data":[{"symbol":"BCH/USD","bids":[{"price":462.80,"qty":2.33539148}],"asks":[],"checksum":1196570646,"timestamp":"2024-06-01T22:44:26.415187Z"}]}
{"channel":"book","type":"update","data":[{"symbol":"BCH/USD","bids":[],"asks":[{"price":463.24,"qty":0.64853433}],"checksum":1677354841,"timestamp":"2024-06-01T22:44:26.431300Z"}]}
{"channel":"book","type":"update","data":[{"symbol":"BCH/USD","bids":[{"price":462.99,"qty":1.21361556}],"asks":[],"checksum":3170636086,"timestamp":"2024-06-01T22:44:26.431840Z"}]}
{"channel":"book","type":"update","data":[{"symbol":"BCH/USD","bids":[],"asks":[{"price":463.25,"qty":0.05062885}],"checksum":3239797669,"timestamp":"2024-06-01T22:44:26.432924Z"}]}
{"channel":"book","type":"update","data":[{"symbol":"BCH/USD","bids":[{"price":463.02,"qty":0.00000000},{"price":462.79,"qty":10.80000000}],"asks":[],"checksum":3035675180,"timestamp":"2024-06-01T22:44:26.432951Z"}]}
{"channel":"book","type":"update","data":[{"symbol":"BCH/USD","bids":[],"asks":[{"price":463.24,"qty":7.71853433}],"checksum":1525546322,"timestamp":"2024-06-01T22:44:26.436439Z"}]}
{"channel":"book","type":"update","data":[{"symbol":"BCH/USD","bids":[{"price":463.03,"qty":0.00000000},{"price":462.74,"qty":1.08000000}],"asks":[],"checksum":3465440543,"timestamp":"2024-06-01T22:44:26.436593Z"}]}
{"channel":"book","type":"update","data":[{"symbol":"BCH/USD","bids":[],"asks":[{"price":463.31,"qty":3.89332295}],"checksum":2788863213,"timestamp":"2024-06-01T22:44:26.436802Z"}]}
{"channel":"book","type":"update","data":[{"symbol":"BCH/USD","bids":[],"asks":[{"price":463.20,"qty":5.55362436}],"checksum":859444975,"timestamp":"2024-06-01T22:44:26.437343Z"}]}
{"channel":"book","type":"update","data":[{"symbol":"BCH/USD","bids":[{"price":462.96,"qty":5.39992970}],"asks":[],"checksum":1901392440,"timestamp":"2024-06-01T22:44:26.437398Z"}]}
{"channel":"book","type":"update","data":[{"symbol":"BCH/USD","bids":[{"price":462.83,"qty":8.20209125}],"asks":[],"checksum":1794750935,"timestamp":"2024-06-01T22:44:26.453171Z"}]}
{"channel":"book","type":"update","data":[{"symbol":"BCH/USD","bids":[{"price":462.79,"qty":21.60000000}],"asks":[],"checksum":2201945253,"timestamp":"2024-06-01T22:44:26.461719Z"}]}
{"channel":"book","type":"update","data":[{"symbol":"BCH/USD","bids":[{"price":462.83,"qty":7.83392088}],"asks":[],"checksum":233039754,"timestamp":"2024-06-01T22:44:26.470437Z"}]}
{"channel":"book","type":"update","data":[{"symbol":"BCH/USD","bids":[{"price":462.96,"qty":0.00000000},{"price":462.71,"qty":1.08000000}],"asks":[],"checksum":1314327493,"timestamp":"2024-06-01T22:44:26.480336Z"}]}
{"channel":"book","type":"update","data":[{"symbol":"BCH/USD","bids":[],"asks":[{"price":463.24,"qty":7.11853433}],"checksum":1116115572,"timestamp":"2024-06-01T22:44:26.482906Z"}]}
{"channel":"book","type":"update","data":[{"symbol":"BCH/USD","bids":[],"asks":[{"price":463.19,"qty":0.63762589}],"checksum":2157395517,"timestamp":"2024-06-01T22:44:26.483168Z"}]}
{"channel":"book","type":"update","data":[{"symbol":"BCH/USD","bids":[],"asks":[{"price":463.36,"qty":0.03335154}],"checksum":3944965774,"timestamp":"2024-06-01T22:44:26.485022Z"}]}
{"channel":"book","type":"update","data":[{"symbol":"BCH/USD","bids":[{"price":462.99,"qty":0.35000000}],"asks":[],"checksum":210890107,"timestamp":"2024-06-01T22:44:26.505975Z"}]}
{"channel":"book","type":"update","data":[{"symbol":"BCH/USD","bids":[],"asks":[{"price":463.20,"qty":0.15636927}],"checksum":2233895411,"timestamp":"2024-06-01T22:44:26.544515Z"}]}
{"channel":"book","type":"update","data":[{"symbol":"BCH/USD","bids":[],"asks":[{"price":463.23,"qty":7.12930895}],"checksum":2714373252,"timestamp":"2024-06-01T22:44:26.549040Z"}]}
{"channel":"book","type":"update","data":[{"symbol":"BCH/USD","bids":[{"price":462.96,"qty":0.47976976}],"asks":[],"checksum":817620082,"timestamp":"2024-06-01T22:44:26.565618Z"}]}
{"channel":"book","type":"update","data":[{"symbol":"BCH/USD","bids":[],"asks":[{"price":463.18,"qty":0.10414783}],"checksum":151996020,"timestamp":"2024-06-01T22:44:26.566203Z"}]}
{"channel":"book","type":"update","data":[{"symbol":"BCH/USD","bids":[{"price":462.82,"qty":0.36817037}],"asks":[],"checksum":517561861,"timestamp":"2024-06-01T22:44:26.570728Z"}]}
{"channel":"book","type":"update","data":[{"symbol":"BCH/USD","bids":[{"price":462.96,"qty":0.00000000},{"price":462.79,"qty":21.60000000}],"asks":[],"checksum":641871702,"timestamp":"2024-06-01T22:44:26.573058Z"}]}
{"channel":"book","type":"update","data":[{"symbol":"BCH/USD","bids":[],"asks":[{"price":463.18,"qty":0.00000000},{"price":463.37,"qty":0.86359037}],"checksum":536251728,"timestamp":"2024-06-01T22:44:26.573775Z"}]}
{"channel":"book","type":"update","data":[{"symbol":"BCH/USD","bids":[],"asks":[{"price":463.24,"qty":0.04853433}],"checksum":4237998822,"timestamp":"2024-06-01T22:44:26.609310Z"}]}
{"channel":"book","type":"update","data":[{"symbol":"BCH/USD","bids":[{"price":462.96,"qty":0.47976976}],"asks":[],"checksum":2384214578,"timestamp":"2024-06-01T22:44:26.765726Z"}]}
