{"channel":"book","type":"snapshot","data":[{"symbol":"BCH/GBP","bids":[{"price":363.22,"qty":0.27796855},{"price":363.15,"qty":3.00000000},{"price":363.14,"qty":2.18447706},{"price":362.00,"qty":1.06943377},{"price":361.99,"qty":0.02789928},{"price":360.65,"qty":0.27796855},{"price":359.27,"qty":36.44504229},{"price":358.64,"qty":2.34501793},{"price":357.91,"qty":7.03667381},{"price":357.71,"qty":0.59209758}],"asks":[{"price":363.60,"qty":4.30941607},{"price":363.61,"qty":0.51840801},{"price":363.64,"qty":0.27796855},{"price":363.70,"qty":12.22979953},{"price":363.83,"qty":1.08651483},{"price":364.15,"qty":2.58366799},{"price":364.17,"qty":0.02500000},{"price":364.24,"qty":3.00000000},{"price":365.87,"qty":1.08651483},{"price":365.99,"qty":0.72258459}],"checksum":2838874886}]}
{"channel":"book","type":"update","data":[{"symbol":"BCH/GBP","bids":[],"asks":[{"price":363.61,"qty":0.00000000},{"price":366.00,"qty":0.02500000}],"checksum":709823326,"timestamp":"2024-06-01T22:43:46.384567Z"}]}
{"channel":"book","type":"update","data":[{"symbol":"BCH/GBP","bids":[],"asks":[{"price":363.62,"qty":0.51840801}],"checksum":1956515730,"timestamp":"2024-06-01T22:43:46.388430Z"}]}
{"channel":"book","type":"update","data":[{"symbol":"BCH/GBP","bids":[],"asks":[{"price":363.60,"qty":0.00000000},{"price":366.00,"qty":0.02500000}],"checksum":3044530605,"timestamp":"2024-06-01T22:43:46.389562Z"}]}
{"channel":"book","type":"update","data":[{"symbol":"BCH/GBP","bids":[],"asks":[{"price":363.63,"qty":4.30941607}],"checksum":2452823071,"timestamp":"2024-06-01T22:43:46.389839Z"}]}
{"channel":"book","type":"update","data":[{"symbol":"BCH/GBP","bids":[],"asks":[{"price":363.70,"qty":0.00000000},{"price":366.00,"qty":0.02500000}],"checksum":3842059824,"timestamp":"2024-06-01T22:43:46.393388Z"}]}
{"channel":"book","type":"update","data":[{"symbol":"BCH/GBP","bids":[],"asks":[{"price":363.70,"qty":8.57854953}],"checksum":2024053856,"timestamp":"2024-06-01T22:43:46.396694Z"}]}
{"channel":"book","type":"update","data":[{"symbol":"BCH/GBP","bids":[],"asks":[{"price":363.61,"qty":4.30941607}],"checksum":4214193662,"timestamp":"2024-06-01T22:43:46.562711Z"}]}
{"channel":"book","type":"update","data":[{"symbol":"BCH/GBP","bids":[],"asks":[{"price":363.63,"qty":0.00000000},{"price":365.99,"qty":0.72258459}],"checksum":1433992367,"timestamp":"2024-06-01T22:43:46.566994Z"}]}
{"channel":"book","type":"update","data":[{"symbol":"BCH/GBP","bids":[],"asks":[{"price":363.62,"qty":0.00000000},{"price":366.00,"qty":0.02500000}],"checksum":1270160340,"timestamp":"2024-06-01T22:43:52.268912Z"}]}
{"channel":"book","type":"update","data":[{"symbol":"BCH/GBP","bids":[{"price":359.27,"qty":0.00000000},{"price":357.21,"qty":9.38405499}],"asks":[],"checksum":785980629,"timestamp":"2024-06-01T22:43:52.270312Z"}]}
{"channel":"book","type":"update","data":[{"symbol":"BCH/GBP","bids":[],"asks":[{"price":363.61,"qty":4.82782408}],"checksum":2338251657,"timestamp":"2024-06-01T22:43:52.272520Z"}]}
{"channel":"book","type":"update","data":[{"symbol":"BCH/GBP","bids":[],"asks":[{"price":363.61,"qty":0.51840801}],"checksum":3900024668,"timestamp":"2024-06-01T22:43:52.274165Z"}]}
{"channel":"book","type":"update","data":[{"symbol":"BCH/GBP","bids":[],"asks":[{"price":363.63,"qty":4.30941607}],"checksum":4128963681,"timestamp":"2024-06-01T22:43:52.274219Z"}]}
{"channel":"book","type":"update","data":[{"symbol":"BCH/GBP","bids":[{"price":359.26,"qty":36.44500869}],"asks":[],"checksum":339251303,"timestamp":"2024-06-01T22:43:52.310564Z"}]}
{"channel":"book","type":"update","data":[{"symbol":"BCH/GBP","bids":[],"asks":[{"price":363.60,"qty":4.30941607}],"checksum":1485215328,"timestamp":"2024-06-01T22:43:52.563134Z"}]}
{"channel":"book","type":"update","data":[{"symbol":"BCH/GBP","bids":[],"asks":[{"price":363.63,"qty":0.00000000},{"price":365.99,"qty":0.72258459}],"checksum":2198499974,"timestamp":"2024-06-01T22:43:52.567328Z"}]}
{"channel":"book","type":"update","data":[{"symbol":"BCH/GBP","bids":[],"asks":[{"price":363.61,"qty":0.00000000},{"price":366.00,"qty":0.02500000}],"checksum":671856282,"timestamp":"2024-06-01T22:43:58.153561Z"}]}
{"channel":"book","type":"update","data":[{"symbol":"BCH/GBP","bids":[],"asks":[{"price":363.62,"qty":0.51840801}],"checksum":632434665,"timestamp":"2024-06-01T22:43:58.157287Z"}]}
{"channel":"book","type":"update","data":[{"symbol":"BCH/GBP","bids":[],"asks":[{"price":363.60,"qty":0.00000000},{"price":366.00,"qty":0.02500000}],"checksum":2940068060,"timestamp":"2024-06-01T22:43:58.158357Z"}]}
{"channel":"book","type":"update","data":[{"symbol":"BCH/GBP","bids":[],"asks":[{"price":363.63,"qty":4.30941607}],"checksum":3959268262,"timestamp":"2024-06-01T22:43:58.158426Z"}]}
{"channel":"book","type":"update","data":[{"symbol":"BCH/GBP","bids":[{"price":363.14,"qty":0.00000000},{"price":357.21,"qty":9.38405499}],"asks":[],"checksum":3436001560,"timestamp":"2024-06-01T22:43:58.161807Z"}]}
{"channel":"book","type":"update","data":[{"symbol":"BCH/GBP","bids":[{"price":363.14,"qty":2.20460432}],"asks":[],"checksum":3799913891,"timestamp":"2024-06-01T22:43:58.165320Z"}]}
{"channel":"book","type":"update","data":[{"symbol":"BCH/GBP","bids":[],"asks":[{"price":363.61,"qty":4.30941607}],"checksum":1643508797,"timestamp":"2024-06-01T22:43:58.560539Z"}]}
{"channel":"book","type":"update","data":[{"symbol":"BCH/GBP","bids":[],"asks":[{"price":363.63,"qty":0.00000000},{"price":365.99,"qty":0.72258459}],"checksum":3483530604,"timestamp":"2024-06-01T22:43:59.062504Z"}]}
{"channel":"book","type":"update","data":[{"symbol":"BCH/GBP","bids":[],"asks":[{"price":365.87,"qty":0.00000000},{"price":366.00,"qty":0.02500000}],"checksum":1081497220,"timestamp":"2024-06-01T22:44:04.037711Z"}]}
{"channel":"book","type":"update","data":[{"symbol":"BCH/GBP","bids":[],"asks":[{"price":363.62,"qty":0.00000000},{"price":366.63,"qty":0.02511159}],"checksum":3252824234,"timestamp":"2024-06-01T22:44:04.037982Z"}]}
{"channel":"book","type":"update","data":[{"symbol":"BCH/GBP","bids":[],"asks":[{"price":365.86,"qty":1.08651483}],"checksum":1151892103,"timestamp":"2024-06-01T22:44:04.041250Z"}]}
{"channel":"book","type":"update","data":[{"symbol":"BCH/GBP","bids":[],"asks":[{"price":363.60,"qty":0.51840801}],"checksum":3909467469,"timestamp":"2024-06-01T22:44:04.041987Z"}]}
{"channel":"book","type":"update","data":[{"symbol":"BCH/GBP","bids":[],"asks":[{"price":363.63,"qty":4.30941607}],"checksum":2914015849,"timestamp":"2024-06-01T22:44:04.042960Z"}]}
{"channel":"book","type":"update","data":[{"symbol":"BCH/GBP","bids":[],"asks":[{"price":363.61,"qty":0.00000000},{"price":365.99,"qty":0.72258459}],"checksum":3373807722,"timestamp":"2024-06-01T22:44:04.043007Z"}]}
{"channel":"book","type":"update","data":[{"symbol":"BCH/GBP","bids":[],"asks":[{"price":363.70,"qty":0.00000000},{"price":366.00,"qty":0.02500000}],"checksum":3782135810,"timestamp":"2024-06-01T22:44:04.045324Z"}]}
{"channel":"book","type":"update","data":[{"symbol":"BCH/GBP","bids":[],"asks":[{"price":363.70,"qty":10.70404953}],"checksum":2256819389,"timestamp":"2024-06-01T22:44:04.048821Z"}]}
{"channel":"book","type":"update","data":[{"symbol":"BCH/GBP","bids":[],"asks":[{"price":365.86,"qty":0.00000000},{"price":366.00,"qty":0.02500000}],"checksum":2293512800,"timestamp":"2024-06-01T22:44:09.922053Z"}]}
{"channel":"book","type":"update","data":[{"symbol":"BCH/GBP","bids":[],"asks":[{"price":363.60,"qty":0.00000000},{"price":366.62,"qty":0.02511091}],"checksum":1615189939,"timestamp":"2024-06-01T22:44:09.922591Z"}]}
{"channel":"book","type":"update","data":[{"symbol":"BCH/GBP","bids":[],"asks":[{"price":366.62,"qty":0.00000000},{"price":366.93,"qty":0.35735297},{"price":366.65,"qty":0.02511159}],"checksum":1242767904,"timestamp":"2024-06-01T22:44:09.924909Z"}]}
{"channel":"book","type":"update","data":[{"symbol":"BCH/GBP","bids":[],"asks":[{"price":365.85,"qty":1.08651483}],"checksum":2426248661,"timestamp":"2024-06-01T22:44:09.925503Z"}]}
{"channel":"book","type":"update","data":[{"symbol":"BCH/GBP","bids":[],"asks":[{"price":363.61,"qty":0.51840801}],"checksum":848188393,"timestamp":"2024-06-01T22:44:09.926029Z"}]}
{"channel":"book","type":"update","data":[{"symbol":"BCH/GBP","bids":[],"asks":[{"price":363.60,"qty":4.30941607}],"checksum":3920391580,"timestamp":"2024-06-01T22:44:10.062001Z"}]}
{"channel":"book","type":"update","data":[{"symbol":"BCH/GBP","bids":[],"asks":[{"price":363.63,"qty":0.00000000},{"price":365.99,"qty":0.72258459}],"checksum":3843339237,"timestamp":"2024-06-01T22:44:10.066790Z"}]}
{"channel":"book","type":"update","data":[{"symbol":"BCH/GBP","bids":[],"asks":[{"price":364.17,"qty":0.00000000},{"price":366.00,"qty":0.02500000}],"checksum":1419110603,"timestamp":"2024-06-01T22:44:10.304785Z"}]}
{"channel":"book","type":"update","data":[{"symbol":"BCH/GBP","bids":[],"asks":[{"price":364.23,"qty":2.58366799}],"checksum":3126440689,"timestamp":"2024-06-01T22:44:10.328458Z"}]}
{"channel":"book","type":"update","data":[{"symbol":"BCH/GBP","bids":[],"asks":[{"price":364.15,"qty":0.00000000},{"price":366.00,"qty":0.02500000}],"checksum":2625360741,"timestamp":"2024-06-01T22:44:10.328694Z"}]}
{"channel":"book","type":"update","data":[{"symbol":"BCH/GBP","bids":[],"asks":[{"price":364.21,"qty":0.02500000}],"checksum":3454411714,"timestamp":"2024-06-01T22:44:10.375838Z"}]}
{"channel":"book","type":"update","data":[{"symbol":"BCH/GBP","bids":[{"price":361.99,"qty":0.00000000},{"price":357.21,"qty":9.38405499}],"asks":[],"checksum":2019673693,"timestamp":"2024-06-01T22:44:14.363110Z"}]}
{"channel":"book","type":"update","data":[{"symbol":"BCH/GBP","bids":[{"price":360.66,"qty":1.07340714}],"asks":[],"checksum":3846699730,"timestamp":"2024-06-01T22:44:14.406220Z"}]}
{"channel":"book","type":"update","data":[{"symbol":"BCH/GBP","bids":[{"price":362.00,"qty":0.00000000},{"price":357.21,"qty":9.38405499}],"asks":[],"checksum":1238886595,"timestamp":"2024-06-01T22:44:14.406439Z"}]}
{"channel":"book","type":"update","data":[{"symbol":"BCH/GBP","bids":[{"price":362.02,"qty":0.02788645}],"asks":[],"checksum":4253158467,"timestamp":"2024-06-01T22:44:14.506961Z"}]}
{"channel":"book","type":"update","data":[{"symbol":"BCH/GBP","bids":[],"asks":[{"price":363.61,"qty":0.00000000},{"price":366.00,"qty":0.02500000}],"checksum":3339861673,"timestamp":"2024-06-01T22:44:15.807419Z"}]}
{"channel":"book","type":"update","data":[{"symbol":"BCH/GBP","bids":[],"asks":[{"price":363.60,"qty":4.82782408}],"checksum":4229850875,"timestamp":"2024-06-01T22:44:15.810338Z"}]}
{"channel":"book","type":"update","data":[{"symbol":"BCH/GBP","bids":[],"asks":[{"price":363.60,"qty":0.51840801}],"checksum":1653919499,"timestamp":"2024-06-01T22:44:15.812852Z"}]}
{"channel":"book","type":"update","data":[{"symbol":"BCH/GBP","bids":[],"asks":[{"price":363.63,"qty":4.30941607}],"checksum":3343121539,"timestamp":"2024-06-01T22:44:15.812894Z"}]}
