{"channel":"book","type":"snapshot","data":[{"symbol":"BCH/EUR","bids":[{"price":426.95,"qty":0.45000000},{"price":426.94,"qty":5.39733644},{"price":426.92,"qty":0.07380960},{"price":426.90,"qty":0.35000000},{"price":426.88,"qty":0.77540034},{"price":426.82,"qty":3.88726919},{"price":426.81,"qty":7.83392088},{"price":426.77,"qty":5.39947189},{"price":426.73,"qty":0.44000000},{"price":426.69,"qty":5.40054343}],"asks":[{"price":427.16,"qty":8.28392088},{"price":427.17,"qty":5.39461702},{"price":427.25,"qty":8.00000000},{"price":427.26,"qty":2.00000000},{"price":427.27,"qty":3.88726919},{"price":427.29,"qty":15.96804300},{"price":427.32,"qty":5.39271273},{"price":427.39,"qty":24.84732600},{"price":427.41,"qty":5.39152166},{"price":427.44,"qty":5.96029953}],"checksum":3347041052}]}
{"channel":"book","type":"update","data":[{"symbol":"BCH/EUR","bids":[{"price":426.84,"qty":8.00000000}],"asks":[],"checksum":2199649898,"timestamp":"2024-06-01T22:43:40.635420Z"}]}
{"channel":"book","type":"update","data":[{"symbol":"BCH/EUR","bids":[{"price":426.84,"qty":0.00000000},{"price":426.69,"qty":5.40054343}],"asks":[],"checksum":3347041052,"timestamp":"2024-06-01T22:43:41.634077Z"}]}
{"channel":"book","type":"update","data":[{"symbol":"BCH/EUR","bids":[{"price":426.84,"qty":8.00000000}],"asks":[],"checksum":2199649898,"timestamp":"2024-06-01T22:43:42.634720Z"}]}
{"channel":"book","type":"update","data":[{"symbol":"BCH/EUR","bids":[{"price":426.84,"qty":0.00000000},{"price":426.69,"qty":5.40054343}],"asks":[],"checksum":3347041052,"timestamp":"2024-06-01T22:43:43.632442Z"}]}
{"channel":"book","type":"update","data":[{"symbol":"BCH/EUR","bids":[{"price":426.84,"qty":8.00000000}],"asks":[],"checksum":2199649898,"timestamp":"2024-06-01T22:43:45.136536Z"}]}
{"channel":"book","type":"update","data":[{"symbol":"BCH/EUR","bids":[{"price":426.84,"qty":0.00000000},{"price":426.69,"qty":5.40054343}],"asks":[],"checksum":3347041052,"timestamp":"2024-06-01T22:43:46.135633Z"}]}
{"channel":"book","type":"update","data":[{"symbol":"BCH/EUR","bids":[{"price":426.84,"qty":8.00000000}],"asks":[],"checksum":2199649898,"timestamp":"2024-06-01T22:43:47.135898Z"}]}
{"channel":"book","type":"update","data":[{"symbol":"BCH/EUR","bids":[{"price":426.84,"qty":0.00000000},{"price":426.69,"qty":5.40054343}],"asks":[],"checksum":3347041052,"timestamp":"2024-06-01T22:43:48.134385Z"}]}
{"channel":"book","type":"update","data":[{"symbol":"BCH/EUR","bids":[{"price":426.84,"qty":8.00000000}],"asks":[],"checksum":2199649898,"timestamp":"2024-06-01T22:43:49.636146Z"}]}
{"channel":"book","type":"update","data":[{"symbol":"BCH/EUR","bids":[{"price":426.84,"qty":0.00000000},{"price":426.69,"qty":5.40054343}],"asks":[],"checksum":3347041052,"timestamp":"2024-06-01T22:43:50.632795Z"}]}
{"channel":"book","type":"update","data":[{"symbol":"BCH/EUR","bids":[{"price":426.84,"qty":8.00000000}],"asks":[],"checksum":2199649898,"timestamp":"2024-06-01T22:43:51.134440Z"}]}
{"channel":"book","type":"update","data":[{"symbol":"BCH/EUR","bids":[{"price":426.84,"qty":0.00000000},{"price":426.69,"qty":5.40054343}],"asks":[],"checksum":3347041052,"timestamp":"2024-06-01T22:43:52.136016Z"}]}
{"channel":"book","type":"update","data":[{"symbol":"BCH/EUR","bids":[{"price":426.84,"qty":8.00000000}],"asks":[],"checksum":2199649898,"timestamp":"2024-06-01T22:43:52.635309Z"}]}
{"channel":"book","type":"update","data":[{"symbol":"BCH/EUR","bids":[{"price":426.88,"qty":0.00000000},{"price":426.69,"qty":5.40054343}],"asks":[],"checksum":4154034552,"timestamp":"2024-06-01T22:43:52.904745Z"}]}
{"channel":"book","type":"update","data":[{"symbol":"BCH/EUR","bids":[],"asks":[{"price":427.44,"qty":0.00000000},{"price":427.48,"qty":5.39461702}],"checksum":1042836722,"timestamp":"2024-06-01T22:43:52.907390Z"}]}
{"channel":"book","type":"update","data":[{"symbol":"BCH/EUR","bids":[{"price":426.88,"qty":0.77540034}],"asks":[],"checksum":1054798361,"timestamp":"2024-06-01T22:43:52.910092Z"}]}
{"channel":"book","type":"update","data":[{"symbol":"BCH/EUR","bids":[],"asks":[{"price":427.44,"qty":2.99779953}],"checksum":2645258911,"timestamp":"2024-06-01T22:43:52.912828Z"}]}
{"channel":"book","type":"update","data":[{"symbol":"BCH/EUR","bids":[{"price":426.84,"qty":0.00000000},{"price":426.69,"qty":5.40054343}],"asks":[],"checksum":3654240233,"timestamp":"2024-06-01T22:43:53.135599Z"}]}
{"channel":"book","type":"update","data":[{"symbol":"BCH/EUR","bids":[{"price":426.84,"qty":8.00000000}],"asks":[],"checksum":2645258911,"timestamp":"2024-06-01T22:43:54.134119Z"}]}
{"channel":"book","type":"update","data":[{"symbol":"BCH/EUR","bids":[{"price":426.84,"qty":0.00000000},{"price":426.69,"qty":5.40054343}],"asks":[],"checksum":3654240233,"timestamp":"2024-06-01T22:43:55.136404Z"}]}
{"channel":"book","type":"update","data":[{"symbol":"BCH/EUR","bids":[{"price":426.84,"qty":8.00000000}],"asks":[],"checksum":2645258911,"timestamp":"2024-06-01T22:43:55.634550Z"}]}
{"channel":"book","type":"update","data":[{"symbol":"BCH/EUR","bids":[{"price":426.82,"qty":0.00000000},{"price":426.69,"qty":5.40054343}],"asks":[],"checksum":227943052,"timestamp":"2024-06-01T22:43:55.926099Z"}]}
{"channel":"book","type":"update","data":[{"symbol":"BCH/EUR","bids":[{"price":426.84,"qty":0.00000000},{"price":426.61,"qty":16.20578183}],"asks":[],"checksum":1076273875,"timestamp":"2024-06-01T22:43:55.926377Z"}]}
{"channel":"book","type":"update","data":[{"symbol":"BCH/EUR","bids":[],"asks":[{"price":427.17,"qty":0.00000000},{"price":427.48,"qty":5.39461702}],"checksum":820522965,"timestamp":"2024-06-01T22:43:55.945856Z"}]}
{"channel":"book","type":"update","data":[{"symbol":"BCH/EUR","bids":[{"price":426.92,"qty":0.00000000},{"price":426.43,"qty":1.49094998}],"asks":[],"checksum":1050817404,"timestamp":"2024-06-01T22:43:55.949239Z"}]}
{"channel":"book","type":"update","data":[{"symbol":"BCH/EUR","bids":[],"asks":[{"price":427.16,"qty":0.45000000}],"checksum":1216298245,"timestamp":"2024-06-01T22:43:55.949889Z"}]}
{"channel":"book","type":"update","data":[{"symbol":"BCH/EUR","bids":[],"asks":[{"price":427.15,"qty":5.39478965}],"checksum":1575699730,"timestamp":"2024-06-01T22:43:55.950111Z"}]}
{"channel":"book","type":"update","data":[{"symbol":"BCH/EUR","bids":[],"asks":[{"price":427.25,"qty":0.00000000},{"price":427.48,"qty":5.39461702}],"checksum":181450493,"timestamp":"2024-06-01T22:43:55.950507Z"}]}
{"channel":"book","type":"update","data":[{"symbol":"BCH/EUR","bids":[],"asks":[{"price":427.28,"qty":8.00000000}],"checksum":1076942038,"timestamp":"2024-06-01T22:43:55.950600Z"}]}
{"channel":"book","type":"update","data":[{"symbol":"BCH/EUR","bids":[],"asks":[{"price":427.16,"qty":0.00000000},{"price":427.48,"qty":5.39461702}],"checksum":2137803338,"timestamp":"2024-06-01T22:43:55.952649Z"}]}
{"channel":"book","type":"update","data":[{"symbol":"BCH/EUR","bids":[],"asks":[{"price":427.23,"qty":0.45000000}],"checksum":1453159842,"timestamp":"2024-06-01T22:43:55.953268Z"}]}
{"channel":"book","type":"update","data":[{"symbol":"BCH/EUR","bids":[{"price":426.43,"qty":1.08000000}],"asks":[],"checksum":639274302,"timestamp":"2024-06-01T22:43:55.964688Z"}]}
{"channel":"book","type":"update","data":[{"symbol":"BCH/EUR","bids":[{"price":426.95,"qty":0.52380441}],"asks":[],"checksum":1114109651,"timestamp":"2024-06-01T22:43:56.068203Z"}]}
{"channel":"book","type":"update","data":[{"symbol":"BCH/EUR","bids":[],"asks":[{"price":427.28,"qty":0.00000000},{"price":427.48,"qty":5.39461702}],"checksum":143103224,"timestamp":"2024-06-01T22:43:56.074238Z"}]}
{"channel":"book","type":"update","data":[{"symbol":"BCH/EUR","bids":[{"price":426.84,"qty":8.00000000}],"asks":[],"checksum":3762782721,"timestamp":"2024-06-01T22:43:56.074308Z"}]}
{"channel":"book","type":"update","data":[{"symbol":"BCH/EUR","bids":[],"asks":[{"price":427.28,"qty":8.00000000}],"checksum":2863128618,"timestamp":"2024-06-01T22:43:56.136266Z"}]}
{"channel":"book","type":"update","data":[{"symbol":"BCH/EUR","bids":[],"asks":[{"price":427.28,"qty":0.00000000},{"price":427.48,"qty":5.39461702}],"checksum":3762782721,"timestamp":"2024-06-01T22:43:56.140789Z"}]}
{"channel":"book","type":"update","data":[{"symbol":"BCH/EUR","bids":[{"price":426.84,"qty":0.00000000},{"price":426.43,"qty":1.49094998}],"asks":[],"checksum":2013293668,"timestamp":"2024-06-01T22:43:56.140805Z"}]}
{"channel":"book","type":"update","data":[{"symbol":"BCH/EUR","bids":[],"asks":[{"price":427.28,"qty":8.00000000}],"checksum":853544527,"timestamp":"2024-06-01T22:43:56.633824Z"}]}
{"channel":"book","type":"update","data":[{"symbol":"BCH/EUR","bids":[],"asks":[{"price":427.28,"qty":0.00000000},{"price":427.48,"qty":5.39461702}],"checksum":2013293668,"timestamp":"2024-06-01T22:43:56.638399Z"}]}
{"channel":"book","type":"update","data":[{"symbol":"BCH/EUR","bids":[{"price":426.84,"qty":8.00000000}],"asks":[],"checksum":3762782721,"timestamp":"2024-06-01T22:43:56.638479Z"}]}
{"channel":"book","type":"update","data":[{"symbol":"BCH/EUR","bids":[{"price":426.82,"qty":3.88726919}],"asks":[],"checksum":2987257097,"timestamp":"2024-06-01T22:43:56.733119Z"}]}
{"channel":"book","type":"update","data":[{"symbol":"BCH/EUR","bids":[],"asks":[{"price":427.28,"qty":8.00000000}],"checksum":2378860397,"timestamp":"2024-06-01T22:43:57.133061Z"}]}
{"channel":"book","type":"update","data":[{"symbol":"BCH/EUR","bids":[],"asks":[{"price":427.28,"qty":0.00000000},{"price":427.48,"qty":5.39461702}],"checksum":2987257097,"timestamp":"2024-06-01T22:43:57.137635Z"}]}
{"channel":"book","type":"update","data":[{"symbol":"BCH/EUR","bids":[{"price":426.84,"qty":0.00000000},{"price":426.61,"qty":16.20578183}],"asks":[],"checksum":1210428199,"timestamp":"2024-06-01T22:43:57.137693Z"}]}
{"channel":"book","type":"update","data":[{"symbol":"BCH/EUR","bids":[],"asks":[{"price":427.14,"qty":7.83392088}],"checksum":2588640516,"timestamp":"2024-06-01T22:43:57.511015Z"}]}
{"channel":"book","type":"update","data":[{"symbol":"BCH/EUR","bids":[],"asks":[{"price":427.25,"qty":8.00000000}],"checksum":2953476483,"timestamp":"2024-06-01T22:43:57.518049Z"}]}
{"channel":"book","type":"update","data":[{"symbol":"BCH/EUR","bids":[{"price":426.84,"qty":8.00000000}],"asks":[],"checksum":4285604052,"timestamp":"2024-06-01T22:43:57.634969Z"}]}
{"channel":"book","type":"update","data":[{"symbol":"BCH/EUR","bids":[{"price":426.84,"qty":0.00000000},{"price":426.61,"qty":16.20578183}],"asks":[],"checksum":2953476483,"timestamp":"2024-06-01T22:43:58.135736Z"}]}
{"channel":"book","type":"update","data":[{"symbol":"BCH/EUR","bids":[{"price":426.84,"qty":8.00000000}],"asks":[],"checksum":4285604052,"timestamp":"2024-06-01T22:43:58.634960Z"}]}
{"channel":"book","type":"update","data":[{"symbol":"BCH/EUR","bids":[{"price":426.84,"qty":0.00000000},{"price":426.61,"qty":16.20578183}],"asks":[],"checksum":2953476483,"timestamp":"2024-06-01T22:43:59.134031Z"}]}
{"channel":"book","type":"update","data":[{"symbol":"BCH/EUR","bids":[{"price":426.84,"qty":8.00000000}],"asks":[],"checksum":4285604052,"timestamp":"2024-06-01T22:44:00.135075Z"}]}
{"channel":"book","type":"update","data":[{"symbol":"BCH/EUR","bids":[{"price":426.84,"qty":0.00000000},{"price":426.61,"qty":16.20578183}],"asks":[],"checksum":2953476483,"timestamp":"2024-06-01T22:44:00.634976Z"}]}
{"channel":"book","type":"update","data":[{"symbol":"BCH/EUR","bids":[{"price":426.84,"qty":8.00000000}],"asks":[],"checksum":4285604052,"timestamp":"2024-06-01T22:44:01.134354Z"}]}
{"channel":"book","type":"update","data":[{"symbol":"BCH/EUR","bids":[{"price":426.84,"qty":0.00000000},{"price":426.61,"qty":16.20578183}],"asks":[],"checksum":2953476483,"timestamp":"2024-06-01T22:44:01.634874Z"}]}
{"channel":"book","type":"update","data":[{"symbol":"BCH/EUR","bids":[{"price":426.84,"qty":8.00000000}],"asks":[],"checksum":4285604052,"timestamp":"2024-06-01T22:44:02.134709Z"}]}
{"channel":"book","type":"update","data":[{"symbol":"BCH/EUR","bids":[],"asks":[{"price":427.23,"qty":0.00000000},{"price":427.44,"qty":2.99779953}],"checksum":1337684034,"timestamp":"2024-06-01T22:44:02.393764Z"}]}
{"channel":"book","type":"update","data":[{"symbol":"BCH/EUR","bids":[],"asks":[{"price":427.14,"qty":8.28392088}],"checksum":1194391653,"timestamp":"2024-06-01T22:44:02.394071Z"}]}
{"channel":"book","type":"update","data":[{"symbol":"BCH/EUR","bids":[{"price":426.84,"qty":0.00000000},{"price":426.61,"qty":16.20578183}],"asks":[],"checksum":215268161,"timestamp":"2024-06-01T22:44:02.398763Z"}]}
{"channel":"book","type":"update","data":[{"symbol":"BCH/EUR","bids":[{"price":426.61,"qty":5.39578183}],"asks":[],"checksum":1097763207,"timestamp":"2024-06-01T22:44:03.233253Z"}]}
{"channel":"book","type":"update","data":[{"symbol":"BCH/EUR","bids":[{"price":426.95,"qty":0.45000000}],"asks":[],"checksum":1472046238,"timestamp":"2024-06-01T22:44:03.248779Z"}]}
{"channel":"book","type":"update","data":[{"symbol":"BCH/EUR","bids":[],"asks":[{"price":427.14,"qty":7.83392088}],"checksum":1597385913,"timestamp":"2024-06-01T22:44:03.251570Z"}]}
{"channel":"book","type":"update","data":[{"symbol":"BCH/EUR","bids":[],"asks":[{"price":427.13,"qty":0.45000000}],"checksum":3217712360,"timestamp":"2024-06-01T22:44:03.251998Z"}]}
{"channel":"book","type":"update","data":[{"symbol":"BCH/EUR","bids":[{"price":426.95,"qty":0.00000000},{"price":426.57,"qty":10.81000000}],"asks":[],"checksum":3447155997,"timestamp":"2024-06-01T22:44:03.353010Z"}]}
{"channel":"book","type":"update","data":[{"symbol":"BCH/EUR","bids":[{"price":426.82,"qty":11.88726919}],"asks":[],"checksum":1090102164,"timestamp":"2024-06-01T22:44:03.358009Z"}]}
{"channel":"book","type":"update","data":[{"symbol":"BCH/EUR","bids":[{"price":426.91,"qty":0.07381133}],"asks":[],"checksum":1162256555,"timestamp":"2024-06-01T22:44:03.371995Z"}]}
{"channel":"book","type":"update","data":[{"symbol":"BCH/EUR","bids":[{"price":426.82,"qty":3.88726919}],"asks":[],"checksum":56778578,"timestamp":"2024-06-01T22:44:04.634102Z"}]}
{"channel":"book","type":"update","data":[{"symbol":"BCH/EUR","bids":[{"price":426.62,"qty":10.81000000}],"asks":[],"checksum":1345015282,"timestamp":"2024-06-01T22:44:05.616907Z"}]}
{"channel":"book","type":"update","data":[{"symbol":"BCH/EUR","bids":[{"price":426.62,"qty":0.00000000},{"price":426.61,"qty":5.39578183}],"asks":[],"checksum":56778578,"timestamp":"2024-06-01T22:44:05.635772Z"}]}
{"channel":"book","type":"update","data":[{"symbol":"BCH/EUR","bids":[{"price":426.63,"qty":10.81000000}],"asks":[],"checksum":2443547186,"timestamp":"2024-06-01T22:44:06.229505Z"}]}
{"channel":"book","type":"update","data":[{"symbol":"BCH/EUR","bids":[{"price":426.84,"qty":8.00000000}],"asks":[],"checksum":87830192,"timestamp":"2024-06-01T22:44:06.633538Z"}]}
{"channel":"book","type":"update","data":[{"symbol":"BCH/EUR","bids":[{"price":426.84,"qty":0.00000000},{"price":426.63,"qty":10.81000000}],"asks":[],"checksum":2443547186,"timestamp":"2024-06-01T22:44:07.133510Z"}]}
{"channel":"book","type":"update","data":[{"symbol":"BCH/EUR","bids":[{"price":426.84,"qty":8.00000000}],"asks":[],"checksum":87830192,"timestamp":"2024-06-01T22:44:07.635866Z"}]}
{"channel":"book","type":"update","data":[{"symbol":"BCH/EUR","bids":[{"price":426.84,"qty":0.00000000},{"price":426.62,"qty":10.81000000}],"asks":[],"checksum":1345015282,"timestamp":"2024-06-01T22:44:08.135856Z"}]}
{"channel":"book","type":"update","data":[{"symbol":"BCH/EUR","bids":[{"price":426.84,"qty":8.00000000}],"asks":[],"checksum":87830192,"timestamp":"2024-06-01T22:44:08.634973Z"}]}
{"channel":"book","type":"update","data":[{"symbol":"BCH/EUR","bids":[{"price":426.84,"qty":0.00000000},{"price":426.62,"qty":10.81000000}],"asks":[],"checksum":1345015282,"timestamp":"2024-06-01T22:44:09.135137Z"}]}
{"channel":"book","type":"update","data":[{"symbol":"BCH/EUR","bids":[{"price":426.84,"qty":8.00000000}],"asks":[],"checksum":87830192,"timestamp":"2024-06-01T22:44:09.634710Z"}]}
{"channel":"book","type":"update","data":[{"symbol":"BCH/EUR","bids":[{"price":426.84,"qty":0.00000000},{"price":426.62,"qty":10.81000000}],"asks":[],"checksum":1345015282,"timestamp":"2024-06-01T22:44:10.134979Z"}]}
{"channel":"book","type":"update","data":[{"symbol":"BCH/EUR","bids":[{"price":426.84,"qty":8.00000000}],"asks":[],"checksum":87830192,"timestamp":"2024-06-01T22:44:10.635933Z"}]}
{"channel":"book","type":"update","data":[{"symbol":"BCH/EUR","bids":[{"price":426.84,"qty":0.00000000},{"price":426.62,"qty":10.81000000}],"asks":[],"checksum":1345015282,"timestamp":"2024-06-01T22:44:11.135064Z"}]}
{"channel":"book","type":"update","data":[{"symbol":"BCH/EUR","bids":[{"price":426.84,"qty":8.00000000}],"asks":[],"checksum":87830192,"timestamp":"2024-06-01T22:44:11.635416Z"}]}
