{"channel":"book","type":"snapshot","data":[{"symbol":"BTC/USDT","bids":[{"price":67779.9,"qty":0.00640000},{"price":67768.8,"qty":0.05000000},{"price":67762.4,"qty":0.04290000},{"price":67761.5,"qty":0.14770060},{"price":67760.4,"qty":0.04443599},{"price":67760.2,"qty":0.00519353},{"price":67759.4,"qty":0.04405954},{"price":67756.8,"qty":0.01066797},{"price":67755.8,"qty":0.02213572},{"price":67754.3,"qty":0.32757555}],"asks":[{"price":67780.0,"qty":0.24204985},{"price":67781.3,"qty":0.14765770},{"price":67784.7,"qty":0.00619058},{"price":67784.8,"qty":0.18117270},{"price":67786.3,"qty":0.48445028},{"price":67789.4,"qty":2.44812500},{"price":67789.5,"qty":0.11630000},{"price":67789.8,"qty":0.19976708},{"price":67792.0,"qty":0.22140000},{"price":67792.1,"qty":0.19986334}],"checksum":459935933}]}
{"channel":"book","type":"update","data":[{"symbol":"BTC/USDT","bids":[{"price":67755.8,"qty":0.00000000},{"price":67754.2,"qty":0.11631100}],"asks":[],"checksum":2878897176,"timestamp":"2024-06-01T22:42:06.440996Z"}]}
{"channel":"book","type":"update","data":[{"symbol":"BTC/USDT","bids":[{"price":67755.7,"qty":0.02213655}],"asks":[],"checksum":2295036160,"timestamp":"2024-06-01T22:42:06.481126Z"}]}
{"channel":"book","type":"update","data":[{"symbol":"BTC/USDT","bids":[{"price":67762.5,"qty":0.05439736}],"asks":[],"checksum":4036038620,"timestamp":"2024-06-01T22:42:06.768938Z"}]}
{"channel":"book","type":"update","data":[{"symbol":"BTC/USDT","bids":[{"price":67762.4,"qty":0.00000000},{"price":67754.3,"qty":0.32757555}],"asks":[],"checksum":3082462767,"timestamp":"2024-06-01T22:42:06.771681Z"}]}
{"channel":"book","type":"update","data":[{"symbol":"BTC/USDT","bids":[{"price":67762.8,"qty":0.04290000}],"asks":[],"checksum":2441077320,"timestamp":"2024-06-01T22:42:06.771778Z"}]}
{"channel":"book","type":"update","data":[{"symbol":"BTC/USDT","bids":[{"price":67762.5,"qty":0.00000000},{"price":67754.3,"qty":0.32757555},{"price":67759.5,"qty":0.05439977}],"asks":[],"checksum":1075034627,"timestamp":"2024-06-01T22:42:06.859780Z"}]}
{"channel":"book","type":"update","data":[{"symbol":"BTC/USDT","bids":[{"price":67755.7,"qty":0.00000000},{"price":67754.3,"qty":0.32757555}],"asks":[],"checksum":2195268314,"timestamp":"2024-06-01T22:42:07.276180Z"}]}
{"channel":"book","type":"update","data":[{"symbol":"BTC/USDT","bids":[{"price":67755.9,"qty":0.02213675}],"asks":[],"checksum":1739573939,"timestamp":"2024-06-01T22:42:07.316183Z"}]}
{"channel":"book","type":"update","data":[{"symbol":"BTC/USDT","bids":[],"asks":[{"price":67786.3,"qty":0.00000000},{"price":67793.0,"qty":0.05695000}],"checksum":3425934646,"timestamp":"2024-06-01T22:42:07.494056Z"}]}
{"channel":"book","type":"update","data":[{"symbol":"BTC/USDT","bids":[],"asks":[{"price":67789.4,"qty":0.00000000},{"price":67793.4,"qty":0.05000000}],"checksum":376402587,"timestamp":"2024-06-01T22:42:07.494085Z"}]}
{"channel":"book","type":"update","data":[{"symbol":"BTC/USDT","bids":[],"asks":[{"price":67784.8,"qty":0.00000000},{"price":67793.8,"qty":0.29890395}],"checksum":3027620718,"timestamp":"2024-06-01T22:42:07.494093Z"}]}
{"channel":"book","type":"update","data":[{"symbol":"BTC/USDT","bids":[],"asks":[{"price":67789.4,"qty":1.32929495}],"checksum":190212474,"timestamp":"2024-06-01T22:42:07.498885Z"}]}
{"channel":"book","type":"update","data":[{"symbol":"BTC/USDT","bids":[],"asks":[{"price":67791.9,"qty":1.81435556}],"checksum":1742523948,"timestamp":"2024-06-01T22:42:07.498900Z"}]}
{"channel":"book","type":"update","data":[{"symbol":"BTC/USDT","bids":[],"asks":[{"price":67792.0,"qty":0.00000000},{"price":67793.4,"qty":0.05000000},{"price":67791.8,"qty":0.22140000}],"checksum":1828289622,"timestamp":"2024-06-01T22:42:07.501981Z"}]}
{"channel":"book","type":"update","data":[{"symbol":"BTC/USDT","bids":[{"price":67759.5,"qty":0.00000000},{"price":67754.3,"qty":0.32757555},{"price":67762.9,"qty":0.05439704}],"asks":[],"checksum":2722363619,"timestamp":"2024-06-01T22:42:07.640703Z"}]}
{"channel":"book","type":"update","data":[{"symbol":"BTC/USDT","bids":[{"price":67762.8,"qty":0.00000000},{"price":67754.3,"qty":0.32757555}],"asks":[],"checksum":855835790,"timestamp":"2024-06-01T22:42:07.643474Z"}]}
{"channel":"book","type":"update","data":[{"symbol":"BTC/USDT","bids":[{"price":67763.7,"qty":0.04290000}],"asks":[],"checksum":319879481,"timestamp":"2024-06-01T22:42:07.643716Z"}]}
{"channel":"book","type":"update","data":[{"symbol":"BTC/USDT","bids":[{"price":67756.8,"qty":0.00000000},{"price":67755.4,"qty":0.15000000}],"asks":[],"checksum":2977841860,"timestamp":"2024-06-01T22:42:07.965758Z"}]}
{"channel":"book","type":"update","data":[{"symbol":"BTC/USDT","bids":[{"price":67760.2,"qty":0.00000000},{"price":67754.3,"qty":0.32757555}],"asks":[],"checksum":1538018168,"timestamp":"2024-06-01T22:42:07.965786Z"}]}
{"channel":"book","type":"update","data":[{"symbol":"BTC/USDT","bids":[{"price":67754.4,"qty":0.02190499}],"asks":[],"checksum":2013435522,"timestamp":"2024-06-01T22:42:07.970758Z"}]}
{"channel":"book","type":"update","data":[{"symbol":"BTC/USDT","bids":[{"price":67762.9,"qty":0.00000000},{"price":67754.3,"qty":0.32757555},{"price":67761.6,"qty":0.05439808}],"asks":[],"checksum":4023320962,"timestamp":"2024-06-01T22:42:08.008287Z"}]}
{"channel":"book","type":"update","data":[{"symbol":"BTC/USDT","bids":[{"price":67755.9,"qty":0.00000000},{"price":67754.3,"qty":0.32757555}],"asks":[],"checksum":269226000,"timestamp":"2024-06-01T22:42:08.010328Z"}]}
{"channel":"book","type":"update","data":[{"symbol":"BTC/USDT","bids":[{"price":67761.7,"qty":0.15000000}],"asks":[],"checksum":1005986349,"timestamp":"2024-06-01T22:42:08.013326Z"}]}
{"channel":"book","type":"update","data":[{"symbol":"BTC/USDT","bids":[{"price":67761.8,"qty":0.00101400}],"asks":[],"checksum":3400936367,"timestamp":"2024-06-01T22:42:08.042800Z"}]}
{"channel":"book","type":"update","data":[{"symbol":"BTC/USDT","bids":[{"price":67761.7,"qty":0.00000000},{"price":67754.4,"qty":0.02190499}],"asks":[],"checksum":2224334942,"timestamp":"2024-06-01T22:42:08.047264Z"}]}
{"channel":"book","type":"update","data":[{"symbol":"BTC/USDT","bids":[{"price":67761.9,"qty":0.15000000}],"asks":[],"checksum":2191821052,"timestamp":"2024-06-01T22:42:08.047461Z"}]}
{"channel":"book","type":"update","data":[{"symbol":"BTC/USDT","bids":[{"price":67773.7,"qty":0.17960327}],"asks":[],"checksum":75870523,"timestamp":"2024-06-01T22:42:08.060893Z"}]}
{"channel":"book","type":"update","data":[{"symbol":"BTC/USDT","bids":[{"price":67761.9,"qty":0.00000000},{"price":67755.4,"qty":0.15000000}],"asks":[],"checksum":1560548940,"timestamp":"2024-06-01T22:42:08.212887Z"}]}
{"channel":"book","type":"update","data":[{"symbol":"BTC/USDT","bids":[],"asks":[{"price":67782.6,"qty":0.06804000}],"checksum":3577967624,"timestamp":"2024-06-01T22:42:08.463984Z"}]}
{"channel":"book","type":"update","data":[{"symbol":"BTC/USDT","bids":[{"price":67761.6,"qty":0.00000000},{"price":67754.4,"qty":0.02190499},{"price":67763.8,"qty":0.05439638}],"asks":[],"checksum":67010297,"timestamp":"2024-06-01T22:42:08.494556Z"}]}
{"channel":"book","type":"update","data":[{"symbol":"BTC/USDT","bids":[{"price":67763.8,"qty":0.00000000},{"price":67754.4,"qty":0.02190499},{"price":67761.6,"qty":0.05439815}],"asks":[],"checksum":2847376974,"timestamp":"2024-06-01T22:42:08.540325Z"}]}
{"channel":"book","type":"update","data":[{"symbol":"BTC/USDT","bids":[],"asks":[{"price":67784.7,"qty":0.00000000},{"price":67793.0,"qty":0.05695000}],"checksum":2692028989,"timestamp":"2024-06-01T22:42:08.851691Z"}]}
{"channel":"book","type":"update","data":[{"symbol":"BTC/USDT","bids":[],"asks":[{"price":67789.3,"qty":0.00803473}],"checksum":3766661701,"timestamp":"2024-06-01T22:42:08.856509Z"}]}
{"channel":"book","type":"update","data":[{"symbol":"BTC/USDT","bids":[{"price":67761.6,"qty":0.00000000},{"price":67754.4,"qty":0.02190499}],"asks":[],"checksum":1454734714,"timestamp":"2024-06-01T22:42:08.948019Z"}]}
{"channel":"book","type":"update","data":[{"symbol":"BTC/USDT","bids":[{"price":67760.4,"qty":0.00000000},{"price":67754.3,"qty":0.32757555}],"asks":[],"checksum":2979440462,"timestamp":"2024-06-01T22:42:08.996921Z"}]}
{"channel":"book","type":"update","data":[{"symbol":"BTC/USDT","bids":[{"price":67754.3,"qty":0.00000000},{"price":67753.7,"qty":0.02213741}],"asks":[],"checksum":1613049227,"timestamp":"2024-06-01T22:42:08.997036Z"}]}
{"channel":"book","type":"update","data":[{"symbol":"BTC/USDT","bids":[{"price":67755.5,"qty":0.30188576}],"asks":[],"checksum":820223604,"timestamp":"2024-06-01T22:42:09.001730Z"}]}
{"channel":"book","type":"update","data":[{"symbol":"BTC/USDT","bids":[{"price":67763.8,"qty":0.05439639}],"asks":[],"checksum":2544175110,"timestamp":"2024-06-01T22:42:09.341560Z"}]}
{"channel":"book","type":"update","data":[{"symbol":"BTC/USDT","bids":[{"price":67761.6,"qty":0.00518720}],"asks":[],"checksum":1129829710,"timestamp":"2024-06-01T22:42:09.384041Z"}]}
{"channel":"book","type":"update","data":[{"symbol":"BTC/USDT","bids":[],"asks":[{"price":67791.7,"qty":0.00518720}],"checksum":831713700,"timestamp":"2024-06-01T22:42:09.425650Z"}]}
{"channel":"book","type":"update","data":[{"symbol":"BTC/USDT","bids":[{"price":67763.8,"qty":0.00000000},{"price":67755.4,"qty":0.15000000},{"price":67761.6,"qty":0.05958536}],"asks":[],"checksum":310757964,"timestamp":"2024-06-01T22:42:09.429577Z"}]}
{"channel":"book","type":"update","data":[{"symbol":"BTC/USDT","bids":[],"asks":[{"price":67789.4,"qty":0.00000000},{"price":67792.1,"qty":0.19986334}],"checksum":1861187529,"timestamp":"2024-06-01T22:42:10.073875Z"}]}
{"channel":"book","type":"update","data":[{"symbol":"BTC/USDT","bids":[],"asks":[{"price":67791.9,"qty":0.00000000},{"price":67793.0,"qty":0.05695000}],"checksum":2917486932,"timestamp":"2024-06-01T22:42:10.073962Z"}]}
{"channel":"book","type":"update","data":[{"symbol":"BTC/USDT","bids":[],"asks":[{"price":67791.8,"qty":0.00000000},{"price":67793.4,"qty":0.05000000},{"price":67792.0,"qty":0.22140000}],"checksum":2696277936,"timestamp":"2024-06-01T22:42:10.077461Z"}]}
{"channel":"book","type":"update","data":[{"symbol":"BTC/USDT","bids":[],"asks":[{"price":67789.2,"qty":0.31114880}],"checksum":2329949588,"timestamp":"2024-06-01T22:42:10.078741Z"}]}
{"channel":"book","type":"update","data":[{"symbol":"BTC/USDT","bids":[],"asks":[{"price":67789.4,"qty":1.28596958}],"checksum":1156604371,"timestamp":"2024-06-01T22:42:10.078924Z"}]}
{"channel":"book","type":"update","data":[{"symbol":"BTC/USDT","bids":[],"asks":[{"price":67791.7,"qty":1.50929304}],"checksum":996189687,"timestamp":"2024-06-01T22:42:10.079029Z"}]}
{"channel":"book","type":"update","data":[{"symbol":"BTC/USDT","bids":[{"price":67761.6,"qty":0.00518720},{"price":67763.8,"qty":0.05439639}],"asks":[],"checksum":2488621440,"timestamp":"2024-06-01T22:42:10.215834Z"}]}
{"channel":"book","type":"update","data":[{"symbol":"BTC/USDT","bids":[],"asks":[{"price":67792.0,"qty":0.00000000},{"price":67792.1,"qty":0.19986334},{"price":67791.6,"qty":0.22140000}],"checksum":2321618779,"timestamp":"2024-06-01T22:42:10.588879Z"}]}
{"channel":"book","type":"update","data":[{"symbol":"BTC/USDT","bids":[{"price":67779.9,"qty":0.00000000},{"price":67755.4,"qty":0.15000000}],"asks":[],"checksum":250824137,"timestamp":"2024-06-01T22:42:10.818573Z"}]}
{"channel":"book","type":"update","data":[{"symbol":"BTC/USDT","bids":[],"asks":[{"price":67780.0,"qty":0.19914985}],"checksum":336092666,"timestamp":"2024-06-01T22:42:10.821366Z"}]}
{"channel":"book","type":"update","data":[{"symbol":"BTC/USDT","bids":[],"asks":[{"price":67780.0,"qty":0.14384549}],"checksum":3627963612,"timestamp":"2024-06-01T22:42:10.821384Z"}]}
{"channel":"book","type":"update","data":[{"symbol":"BTC/USDT","bids":[],"asks":[{"price":67779.1,"qty":0.04290000}],"checksum":3545589196,"timestamp":"2024-06-01T22:42:10.821618Z"}]}
{"channel":"book","type":"update","data":[{"symbol":"BTC/USDT","bids":[],"asks":[{"price":67779.9,"qty":0.01848835}],"checksum":4096861080,"timestamp":"2024-06-01T22:42:10.823383Z"}]}
{"channel":"book","type":"update","data":[{"symbol":"BTC/USDT","bids":[],"asks":[{"price":67779.9,"qty":0.00000000},{"price":67791.6,"qty":0.22140000}],"checksum":3545589196,"timestamp":"2024-06-01T22:42:10.827322Z"}]}
{"channel":"book","type":"update","data":[{"symbol":"BTC/USDT","bids":[],"asks":[{"price":67780.0,"qty":0.09384549},{"price":67779.1,"qty":0.09290000}],"checksum":538042367,"timestamp":"2024-06-01T22:42:10.830728Z"}]}
{"channel":"book","type":"update","data":[{"symbol":"BTC/USDT","bids":[],"asks":[{"price":67779.0,"qty":0.01848835}],"checksum":2321649810,"timestamp":"2024-06-01T22:42:10.831593Z"}]}
{"channel":"book","type":"update","data":[{"symbol":"BTC/USDT","bids":[],"asks":[{"price":67779.1,"qty":0.04290000},{"price":67779.0,"qty":0.06848835}],"checksum":3992350863,"timestamp":"2024-06-01T22:42:10.840585Z"}]}
{"channel":"book","type":"update","data":[{"symbol":"BTC/USDT","bids":[],"asks":[{"price":67779.1,"qty":0.00000000},{"price":67791.6,"qty":0.22140000}],"checksum":959841039,"timestamp":"2024-06-01T22:42:10.843309Z"}]}
{"channel":"book","type":"update","data":[{"symbol":"BTC/USDT","bids":[],"asks":[{"price":67778.1,"qty":0.04290000}],"checksum":2599075280,"timestamp":"2024-06-01T22:42:10.843413Z"}]}
{"channel":"book","type":"update","data":[{"symbol":"BTC/USDT","bids":[],"asks":[{"price":67789.5,"qty":0.00000000},{"price":67791.6,"qty":0.22140000}],"checksum":1493141645,"timestamp":"2024-06-01T22:42:10.846395Z"}]}
{"channel":"book","type":"update","data":[{"symbol":"BTC/USDT","bids":[],"asks":[{"price":67779.0,"qty":0.05000000}],"checksum":1448064802,"timestamp":"2024-06-01T22:42:10.847784Z"}]}
{"channel":"book","type":"update","data":[{"symbol":"BTC/USDT","bids":[],"asks":[{"price":67778.0,"qty":0.11620300}],"checksum":290420435,"timestamp":"2024-06-01T22:42:10.848723Z"}]}
{"channel":"book","type":"update","data":[{"symbol":"BTC/USDT","bids":[],"asks":[{"price":67779.0,"qty":0.00000000},{"price":67791.6,"qty":0.22140000},{"price":67778.1,"qty":0.09290000}],"checksum":2669096610,"timestamp":"2024-06-01T22:42:10.850468Z"}]}
{"channel":"book","type":"update","data":[{"symbol":"BTC/USDT","bids":[],"asks":[{"price":67778.1,"qty":0.05000000}],"checksum":3298521074,"timestamp":"2024-06-01T22:42:10.851507Z"}]}
{"channel":"book","type":"update","data":[{"symbol":"BTC/USDT","bids":[],"asks":[{"price":67777.1,"qty":0.04290000}],"checksum":288025767,"timestamp":"2024-06-01T22:42:10.851828Z"}]}
{"channel":"book","type":"update","data":[{"symbol":"BTC/USDT","bids":[],"asks":[{"price":67778.0,"qty":0.13469135}],"checksum":764059015,"timestamp":"2024-06-01T22:42:10.851935Z"}]}
{"channel":"book","type":"update","data":[{"symbol":"BTC/USDT","bids":[],"asks":[{"price":67778.1,"qty":0.00000000},{"price":67791.6,"qty":0.22140000},{"price":67778.0,"qty":0.18469135}],"checksum":1919146476,"timestamp":"2024-06-01T22:42:10.855124Z"}]}
{"channel":"book","type":"update","data":[{"symbol":"BTC/USDT","bids":[],"asks":[{"price":67778.0,"qty":0.16620300}],"checksum":2106037919,"timestamp":"2024-06-01T22:42:10.855653Z"}]}
{"channel":"book","type":"update","data":[{"symbol":"BTC/USDT","bids":[],"asks":[{"price":67777.0,"qty":0.01848835}],"checksum":2309633233,"timestamp":"2024-06-01T22:42:10.859450Z"}]}
{"channel":"book","type":"update","data":[{"symbol":"BTC/USDT","bids":[],"asks":[{"price":67778.0,"qty":0.11620300}],"checksum":2588037090,"timestamp":"2024-06-01T22:42:10.860738Z"}]}
{"channel":"book","type":"update","data":[{"symbol":"BTC/USDT","bids":[],"asks":[{"price":67778.0,"qty":0.16620300}],"checksum":2309633233,"timestamp":"2024-06-01T22:42:10.860808Z"}]}
{"channel":"book","type":"update","data":[{"symbol":"BTC/USDT","bids":[],"asks":[{"price":67778.0,"qty":0.11620300},{"price":67777.1,"qty":0.09290000}],"checksum":1202229849,"timestamp":"2024-06-01T22:42:10.864798Z"}]}
{"channel":"book","type":"update","data":[{"symbol":"BTC/USDT","bids":[],"asks":[{"price":67777.1,"qty":0.04290000},{"price":67777.0,"qty":0.06848835}],"checksum":541028932,"timestamp":"2024-06-01T22:42:10.868873Z"}]}
{"channel":"book","type":"update","data":[{"symbol":"BTC/USDT","bids":[],"asks":[{"price":67777.1,"qty":0.00000000},{"price":67791.6,"qty":0.22140000}],"checksum":2023723885,"timestamp":"2024-06-01T22:42:10.871661Z"}]}
{"channel":"book","type":"update","data":[{"symbol":"BTC/USDT","bids":[],"asks":[{"price":67776.1,"qty":0.04290000}],"checksum":1461960475,"timestamp":"2024-06-01T22:42:10.871921Z"}]}
{"channel":"book","type":"update","data":[{"symbol":"BTC/USDT","bids":[],"asks":[{"price":67777.0,"qty":0.05000000}],"checksum":1502838964,"timestamp":"2024-06-01T22:42:10.876078Z"}]}
{"channel":"book","type":"update","data":[{"symbol":"BTC/USDT","bids":[],"asks":[{"price":67777.0,"qty":0.00000000},{"price":67791.6,"qty":0.22140000},{"price":67776.1,"qty":0.09290000}],"checksum":3634425050,"timestamp":"2024-06-01T22:42:10.878443Z"}]}
{"channel":"book","type":"update","data":[{"symbol":"BTC/USDT","bids":[],"asks":[{"price":67776.0,"qty":0.01848835}],"checksum":4232187020,"timestamp":"2024-06-01T22:42:10.880681Z"}]}
{"channel":"book","type":"update","data":[{"symbol":"BTC/USDT","bids":[],"asks":[{"price":67776.1,"qty":0.04290000},{"price":67776.0,"qty":0.06848835}],"checksum":2614488209,"timestamp":"2024-06-01T22:42:10.889686Z"}]}
{"channel":"book","type":"update","data":[{"symbol":"BTC/USDT","bids":[],"asks":[{"price":67776.1,"qty":0.00000000},{"price":67791.6,"qty":0.22140000}],"checksum":3246862378,"timestamp":"2024-06-01T22:42:10.892312Z"}]}
{"channel":"book","type":"update","data":[{"symbol":"BTC/USDT","bids":[],"asks":[{"price":67775.7,"qty":0.04290000}],"checksum":3910798799,"timestamp":"2024-06-01T22:42:10.892538Z"}]}
{"channel":"book","type":"update","data":[{"symbol":"BTC/USDT","bids":[],"asks":[{"price":67776.0,"qty":0.05000000}],"checksum":3886690912,"timestamp":"2024-06-01T22:42:10.896858Z"}]}
{"channel":"book","type":"update","data":[{"symbol":"BTC/USDT","bids":[],"asks":[{"price":67776.0,"qty":0.00000000},{"price":67791.6,"qty":0.22140000},{"price":67775.7,"qty":0.09290000}],"checksum":381332519,"timestamp":"2024-06-01T22:42:10.899144Z"}]}
{"channel":"book","type":"update","data":[{"symbol":"BTC/USDT","bids":[],"asks":[{"price":67775.6,"qty":0.01848835}],"checksum":3259716815,"timestamp":"2024-06-01T22:42:10.901708Z"}]}
{"channel":"book","type":"update","data":[{"symbol":"BTC/USDT","bids":[],"asks":[{"price":67775.7,"qty":0.04290000},{"price":67775.6,"qty":0.06848835}],"checksum":2782704850,"timestamp":"2024-06-01T22:42:10.908867Z"}]}
{"channel":"book","type":"update","data":[{"symbol":"BTC/USDT","bids":[],"asks":[{"price":67775.5,"qty":0.06230246}],"checksum":515199854,"timestamp":"2024-06-01T22:42:11.028366Z"}]}
{"channel":"book","type":"update","data":[{"symbol":"BTC/USDT","bids":[],"asks":[{"price":67775.7,"qty":0.00000000},{"price":67789.8,"qty":0.19976708}],"checksum":2906233463,"timestamp":"2024-06-01T22:42:11.031235Z"}]}
{"channel":"book","type":"update","data":[{"symbol":"BTC/USDT","bids":[],"asks":[{"price":67775.5,"qty":0.10520246}],"checksum":2501460239,"timestamp":"2024-06-01T22:42:11.031450Z"}]}
{"channel":"book","type":"update","data":[{"symbol":"BTC/USDT","bids":[],"asks":[{"price":67775.6,"qty":0.05000000}],"checksum":2611576480,"timestamp":"2024-06-01T22:42:11.033382Z"}]}
{"channel":"book","type":"update","data":[{"symbol":"BTC/USDT","bids":[],"asks":[{"price":67775.6,"qty":0.00000000},{"price":67791.6,"qty":0.22140000},{"price":67775.5,"qty":0.15520246}],"checksum":728789881,"timestamp":"2024-06-01T22:42:11.036165Z"}]}
{"channel":"book","type":"update","data":[{"symbol":"BTC/USDT","bids":[],"asks":[{"price":67775.4,"qty":0.01848835}],"checksum":1349681161,"timestamp":"2024-06-01T22:42:11.038092Z"}]}
{"channel":"book","type":"update","data":[{"symbol":"BTC/USDT","bids":[],"asks":[{"price":67775.5,"qty":0.10520246},{"price":67775.4,"qty":0.06848835}],"checksum":2511580382,"timestamp":"2024-06-01T22:42:11.046552Z"}]}
{"channel":"book","type":"update","data":[{"symbol":"BTC/USDT","bids":[{"price":67755.6,"qty":0.01527803}],"asks":[],"checksum":3074586752,"timestamp":"2024-06-01T22:42:11.060028Z"}]}
{"channel":"book","type":"update","data":[{"symbol":"BTC/USDT","bids":[],"asks":[{"price":67780.0,"qty":0.03947498},{"price":67777.9,"qty":0.05437073}],"checksum":2845500530,"timestamp":"2024-06-01T22:42:11.075572Z"}]}
{"channel":"book","type":"update","data":[{"symbol":"BTC/USDT","bids":[],"asks":[{"price":67775.5,"qty":0.06230246}],"checksum":910990169,"timestamp":"2024-06-01T22:42:11.078301Z"}]}
{"channel":"book","type":"update","data":[{"symbol":"BTC/USDT","bids":[],"asks":[{"price":67775.4,"qty":0.11138835}],"checksum":1758830985,"timestamp":"2024-06-01T22:42:11.078757Z"}]}
{"channel":"book","type":"update","data":[{"symbol":"BTC/USDT","bids":[],"asks":[{"price":67775.5,"qty":0.00000000},{"price":67789.8,"qty":0.19976708}],"checksum":294441770,"timestamp":"2024-06-01T22:42:11.281061Z"}]}
{"channel":"book","type":"update","data":[{"symbol":"BTC/USDT","bids":[],"asks":[{"price":67775.3,"qty":0.06230246}],"checksum":1263988125,"timestamp":"2024-06-01T22:42:11.482611Z"}]}
{"channel":"book","type":"update","data":[{"symbol":"BTC/USDT","bids":[],"asks":[{"price":67775.4,"qty":0.09290000}],"checksum":3235630909,"timestamp":"2024-06-01T22:42:11.487433Z"}]}
{"channel":"book","type":"update","data":[{"symbol":"BTC/USDT","bids":[],"asks":[{"price":67775.2,"qty":0.01848835}],"checksum":2541338826,"timestamp":"2024-06-01T22:42:11.491783Z"}]}
{"channel":"book","type":"update","data":[{"symbol":"BTC/USDT","bids":[],"asks":[{"price":67775.4,"qty":0.04290000}],"checksum":2923573514,"timestamp":"2024-06-01T22:42:11.600148Z"}]}
{"channel":"book","type":"update","data":[{"symbol":"BTC/USDT","bids":[],"asks":[{"price":67789.3,"qty":0.00000000},{"price":67789.4,"qty":1.28596958}],"checksum":3927413921,"timestamp":"2024-06-01T22:42:11.665732Z"}]}
{"channel":"book","type":"update","data":[{"symbol":"BTC/USDT","bids":[],"asks":[{"price":67789.1,"qty":0.00713684}],"checksum":1331035416,"timestamp":"2024-06-01T22:42:11.670477Z"}]}
{"channel":"book","type":"update","data":[{"symbol":"BTC/USDT","bids":[],"asks":[{"price":67789.2,"qty":0.31864880}],"checksum":3293849315,"timestamp":"2024-06-01T22:42:11.737495Z"}]}
{"channel":"book","type":"update","data":[{"symbol":"BTC/USDT","bids":[{"price":67761.8,"qty":0.00000000},{"price":67755.4,"qty":0.15000000},{"price":67763.9,"qty":0.00101400}],"asks":[],"checksum":434942808,"timestamp":"2024-06-01T22:42:11.741642Z"}]}
{"channel":"book","type":"update","data":[{"symbol":"BTC/USDT","bids":[],"asks":[{"price":67775.3,"qty":0.00000000},{"price":67789.4,"qty":1.28596958}],"checksum":1491892458,"timestamp":"2024-06-01T22:42:11.748865Z"}]}
{"channel":"book","type":"update","data":[{"symbol":"BTC/USDT","bids":[],"asks":[{"price":67775.1,"qty":0.06230246}],"checksum":1471759854,"timestamp":"2024-06-01T22:42:11.952904Z"}]}
{"channel":"book","type":"update","data":[{"symbol":"BTC/USDT","bids":[],"asks":[{"price":67775.2,"qty":0.00000000},{"price":67789.4,"qty":1.28596958}],"checksum":1386100915,"timestamp":"2024-06-01T22:42:11.957778Z"}]}
{"channel":"book","type":"update","data":[{"symbol":"BTC/USDT","bids":[],"asks":[{"price":67775.0,"qty":0.01848835}],"checksum":1499785446,"timestamp":"2024-06-01T22:42:11.962705Z"}]}
{"channel":"book","type":"update","data":[{"symbol":"BTC/USDT","bids":[],"asks":[{"price":67775.1,"qty":0.00000000},{"price":67789.4,"qty":1.28596958}],"checksum":2709371684,"timestamp":"2024-06-01T22:42:12.205148Z"}]}
{"channel":"book","type":"update","data":[{"symbol":"BTC/USDT","bids":[],"asks":[{"price":67774.9,"qty":0.06612977}],"checksum":2424426492,"timestamp":"2024-06-01T22:42:12.406474Z"}]}
{"channel":"book","type":"update","data":[{"symbol":"BTC/USDT","bids":[],"asks":[{"price":67775.0,"qty":0.00000000},{"price":67789.4,"qty":1.28596958}],"checksum":1483304298,"timestamp":"2024-06-01T22:42:12.411094Z"}]}
{"channel":"book","type":"update","data":[{"symbol":"BTC/USDT","bids":[],"asks":[{"price":67774.8,"qty":0.01848835}],"checksum":3921887705,"timestamp":"2024-06-01T22:42:12.415717Z"}]}
{"channel":"book","type":"update","data":[{"symbol":"BTC/USDT","bids":[{"price":67755.5,"qty":0.00000000},{"price":67755.4,"qty":0.15000000}],"asks":[],"checksum":1892957394,"timestamp":"2024-06-01T22:42:12.449479Z"}]}
{"channel":"book","type":"update","data":[{"symbol":"BTC/USDT","bids":[{"price":67755.7,"qty":0.27162444}],"asks":[],"checksum":1251043129,"timestamp":"2024-06-01T22:42:12.452120Z"}]}
{"channel":"book","type":"update","data":[{"symbol":"BTC/USDT","bids":[],"asks":[{"price":67774.9,"qty":0.00000000},{"price":67789.4,"qty":1.28596958}],"checksum":1821909316,"timestamp":"2024-06-01T22:42:12.663687Z"}]}
{"channel":"book","type":"update","data":[{"symbol":"BTC/USDT","bids":[],"asks":[{"price":67789.2,"qty":0.00750000}],"checksum":4276496342,"timestamp":"2024-06-01T22:42:12.781691Z"}]}
{"channel":"book","type":"update","data":[{"symbol":"BTC/USDT","bids":[],"asks":[{"price":67789.4,"qty":0.00000000},{"price":67789.8,"qty":0.19976708}],"checksum":168255426,"timestamp":"2024-06-01T22:42:12.781872Z"}]}
{"channel":"book","type":"update","data":[{"symbol":"BTC/USDT","bids":[],"asks":[{"price":67789.7,"qty":1.22098153}],"checksum":2975099068,"timestamp":"2024-06-01T22:42:12.786530Z"}]}
{"channel":"book","type":"update","data":[{"symbol":"BTC/USDT","bids":[],"asks":[{"price":67774.7,"qty":0.06612977}],"checksum":914050634,"timestamp":"2024-06-01T22:42:12.874777Z"}]}
{"channel":"book","type":"update","data":[{"symbol":"BTC/USDT","bids":[],"asks":[{"price":67774.8,"qty":0.00000000},{"price":67789.7,"qty":1.22098153}],"checksum":3923305552,"timestamp":"2024-06-01T22:42:12.879224Z"}]}
{"channel":"book","type":"update","data":[{"symbol":"BTC/USDT","bids":[],"asks":[{"price":67774.6,"qty":0.01848835}],"checksum":3258048404,"timestamp":"2024-06-01T22:42:12.883534Z"}]}
{"channel":"book","type":"update","data":[{"symbol":"BTC/USDT","bids":[],"asks":[{"price":67774.7,"qty":0.00000000},{"price":67789.7,"qty":1.22098153}],"checksum":3944441364,"timestamp":"2024-06-01T22:42:13.128314Z"}]}
{"channel":"book","type":"update","data":[{"symbol":"BTC/USDT","bids":[{"price":67763.9,"qty":0.00000000},{"price":67755.4,"qty":0.15000000}],"asks":[],"checksum":3874847637,"timestamp":"2024-06-01T22:42:13.259057Z"}]}
{"channel":"book","type":"update","data":[{"symbol":"BTC/USDT","bids":[],"asks":[{"price":67774.5,"qty":0.06612977}],"checksum":2884040254,"timestamp":"2024-06-01T22:42:13.336195Z"}]}
{"channel":"book","type":"update","data":[{"symbol":"BTC/USDT","bids":[],"asks":[{"price":67774.6,"qty":0.00000000},{"price":67789.7,"qty":1.22098153}],"checksum":2294796949,"timestamp":"2024-06-01T22:42:13.340418Z"}]}
{"channel":"book","type":"update","data":[{"symbol":"BTC/USDT","bids":[],"asks":[{"price":67774.4,"qty":0.01848835}],"checksum":792959586,"timestamp":"2024-06-01T22:42:13.345087Z"}]}
{"channel":"book","type":"update","data":[{"symbol":"BTC/USDT","bids":[],"asks":[{"price":67774.5,"qty":0.00000000},{"price":67789.7,"qty":1.22098153}],"checksum":526694491,"timestamp":"2024-06-01T22:42:13.589474Z"}]}
{"channel":"book","type":"update","data":[{"symbol":"BTC/USDT","bids":[],"asks":[{"price":67774.3,"qty":0.06612977}],"checksum":3613174256,"timestamp":"2024-06-01T22:42:13.799362Z"}]}
{"channel":"book","type":"update","data":[{"symbol":"BTC/USDT","bids":[],"asks":[{"price":67774.4,"qty":0.00000000},{"price":67789.7,"qty":1.22098153}],"checksum":1493471366,"timestamp":"2024-06-01T22:42:13.803999Z"}]}
{"channel":"book","type":"update","data":[{"symbol":"BTC/USDT","bids":[],"asks":[{"price":67774.2,"qty":0.01848835}],"checksum":4007360160,"timestamp":"2024-06-01T22:42:13.808577Z"}]}
{"channel":"book","type":"update","data":[{"symbol":"BTC/USDT","bids":[],"asks":[{"price":67774.3,"qty":0.00000000},{"price":67789.7,"qty":1.22098153}],"checksum":3467115080,"timestamp":"2024-06-01T22:42:14.052913Z"}]}
{"channel":"book","type":"update","data":[{"symbol":"BTC/USDT","bids":[],"asks":[{"price":67774.2,"qty":0.00000000},{"price":67789.8,"qty":0.19976708}],"checksum":3310932890,"timestamp":"2024-06-01T22:42:14.058080Z"}]}
{"channel":"book","type":"update","data":[{"symbol":"BTC/USDT","bids":[],"asks":[{"price":67775.3,"qty":0.01848835}],"checksum":2357044373,"timestamp":"2024-06-01T22:42:14.063355Z"}]}
{"channel":"book","type":"update","data":[{"symbol":"BTC/USDT","bids":[],"asks":[{"price":67775.3,"qty":0.06848835}],"checksum":3763738367,"timestamp":"2024-06-01T22:42:14.069923Z"}]}
{"channel":"book","type":"update","data":[{"symbol":"BTC/USDT","bids":[{"price":67755.6,"qty":0.00000000},{"price":67754.1,"qty":0.02214438}],"asks":[],"checksum":3378220976,"timestamp":"2024-06-01T22:42:14.187915Z"}]}
{"channel":"book","type":"update","data":[{"symbol":"BTC/USDT","bids":[{"price":67755.8,"qty":0.01412552}],"asks":[],"checksum":4260615406,"timestamp":"2024-06-01T22:42:14.191595Z"}]}
{"channel":"book","type":"update","data":[{"symbol":"BTC/USDT","bids":[],"asks":[{"price":67775.2,"qty":0.06612977}],"checksum":3899915112,"timestamp":"2024-06-01T22:42:14.253688Z"}]}
{"channel":"book","type":"update","data":[{"symbol":"BTC/USDT","bids":[],"asks":[{"price":67775.3,"qty":0.05000000}],"checksum":3275270268,"timestamp":"2024-06-01T22:42:14.258399Z"}]}
{"channel":"book","type":"update","data":[{"symbol":"BTC/USDT","bids":[],"asks":[{"price":67775.3,"qty":0.00000000},{"price":67789.7,"qty":1.22098153},{"price":67775.2,"qty":0.11612977}],"checksum":1598989846,"timestamp":"2024-06-01T22:42:14.260809Z"}]}
{"channel":"book","type":"update","data":[{"symbol":"BTC/USDT","bids":[],"asks":[{"price":67775.1,"qty":0.01848835}],"checksum":2249852201,"timestamp":"2024-06-01T22:42:14.262637Z"}]}
{"channel":"book","type":"update","data":[{"symbol":"BTC/USDT","bids":[],"asks":[{"price":67775.2,"qty":0.06612977},{"price":67775.1,"qty":0.06848835}],"checksum":4261923265,"timestamp":"2024-06-01T22:42:14.270885Z"}]}
{"channel":"book","type":"update","data":[{"symbol":"BTC/USDT","bids":[],"asks":[{"price":67789.1,"qty":0.00000000},{"price":67789.7,"qty":1.22098153}],"checksum":3234217750,"timestamp":"2024-06-01T22:42:14.315075Z"}]}
{"channel":"book","type":"update","data":[{"symbol":"BTC/USDT","bids":[],"asks":[{"price":67789.6,"qty":0.00773420}],"checksum":423311470,"timestamp":"2024-06-01T22:42:14.317743Z"}]}
{"channel":"book","type":"update","data":[{"symbol":"BTC/USDT","bids":[],"asks":[{"price":67775.2,"qty":0.00000000},{"price":67789.7,"qty":1.22098153}],"checksum":3279231482,"timestamp":"2024-06-01T22:42:14.524078Z"}]}
{"channel":"book","type":"update","data":[{"symbol":"BTC/USDT","bids":[],"asks":[{"price":67775.1,"qty":0.01848835}],"checksum":2942217104,"timestamp":"2024-06-01T22:42:14.695848Z"}]}
{"channel":"book","type":"update","data":[{"symbol":"BTC/USDT","bids":[{"price":67773.7,"qty":0.22960327}],"asks":[],"checksum":3191964944,"timestamp":"2024-06-01T22:42:14.700051Z"}]}
{"channel":"book","type":"update","data":[{"symbol":"BTC/USDT","bids":[],"asks":[{"price":67775.0,"qty":0.06431365}],"checksum":1791086183,"timestamp":"2024-06-01T22:42:14.731043Z"}]}
{"channel":"book","type":"update","data":[{"symbol":"BTC/USDT","bids":[],"asks":[{"price":67775.1,"qty":0.00000000},{"price":67789.7,"qty":1.22098153}],"checksum":1972043067,"timestamp":"2024-06-01T22:42:14.735461Z"}]}
{"channel":"book","type":"update","data":[{"symbol":"BTC/USDT","bids":[],"asks":[{"price":67774.9,"qty":0.01848835}],"checksum":2996020912,"timestamp":"2024-06-01T22:42:14.739648Z"}]}
{"channel":"book","type":"update","data":[{"symbol":"BTC/USDT","bids":[{"price":67773.7,"qty":0.17960327},{"price":67774.8,"qty":0.05000000}],"asks":[],"checksum":4052265556,"timestamp":"2024-06-01T22:42:14.846537Z"}]}
{"channel":"book","type":"update","data":[{"symbol":"BTC/USDT","bids":[],"asks":[{"price":67774.9,"qty":0.00000000},{"price":67789.7,"qty":1.22098153}],"checksum":1065063727,"timestamp":"2024-06-01T22:42:14.850793Z"}]}
{"channel":"book","type":"update","data":[{"symbol":"BTC/USDT","bids":[],"asks":[{"price":67782.6,"qty":0.00000000},{"price":67789.8,"qty":0.19976708}],"checksum":550847654,"timestamp":"2024-06-01T22:42:14.886857Z"}]}
{"channel":"book","type":"update","data":[{"symbol":"BTC/USDT","bids":[],"asks":[{"price":67775.4,"qty":0.00000000},{"price":67791.4,"qty":0.22140000}],"checksum":962908497,"timestamp":"2024-06-01T22:42:14.895227Z"}]}
{"channel":"book","type":"update","data":[{"symbol":"BTC/USDT","bids":[],"asks":[{"price":67777.5,"qty":0.04290000}],"checksum":380314115,"timestamp":"2024-06-01T22:42:14.895359Z"}]}
{"channel":"book","type":"update","data":[{"symbol":"BTC/USDT","bids":[{"price":67774.8,"qty":0.00000000},{"price":67755.4,"qty":0.15000000},{"price":67774.9,"qty":0.05000000}],"asks":[],"checksum":3930322030,"timestamp":"2024-06-01T22:42:14.906255Z"}]}
{"channel":"book","type":"update","data":[{"symbol":"BTC/USDT","bids":[],"asks":[{"price":67777.9,"qty":0.00000000},{"price":67791.4,"qty":0.22140000},{"price":67789.5,"qty":0.05437121}],"checksum":1628762545,"timestamp":"2024-06-01T22:42:14.937319Z"}]}
{"channel":"book","type":"update","data":[{"symbol":"BTC/USDT","bids":[],"asks":[{"price":67775.0,"qty":0.00000000},{"price":67791.4,"qty":0.22140000}],"checksum":1278661918,"timestamp":"2024-06-01T22:42:14.981383Z"}]}
{"channel":"book","type":"update","data":[{"symbol":"BTC/USDT","bids":[{"price":67775.0,"qty":0.00101400}],"asks":[],"checksum":3023734096,"timestamp":"2024-06-01T22:42:15.009612Z"}]}
{"channel":"book","type":"update","data":[{"symbol":"BTC/USDT","bids":[{"price":67774.9,"qty":0.00000000},{"price":67755.7,"qty":0.27162444},{"price":67775.0,"qty":0.05101400}],"asks":[],"checksum":105372069,"timestamp":"2024-06-01T22:42:15.017192Z"}]}
{"channel":"book","type":"update","data":[{"symbol":"BTC/USDT","bids":[{"price":67775.0,"qty":0.05000000}],"asks":[],"checksum":161700908,"timestamp":"2024-06-01T22:42:15.103787Z"}]}
{"channel":"book","type":"update","data":[{"symbol":"BTC/USDT","bids":[],"asks":[{"price":67777.4,"qty":0.06431365}],"checksum":1895204650,"timestamp":"2024-06-01T22:42:15.181778Z"}]}
{"channel":"book","type":"update","data":[{"symbol":"BTC/USDT","bids":[],"asks":[{"price":67789.7,"qty":0.00000000},{"price":67791.4,"qty":0.22140000}],"checksum":1141330695,"timestamp":"2024-06-01T22:42:15.294314Z"}]}
{"channel":"book","type":"update","data":[{"symbol":"BTC/USDT","bids":[],"asks":[{"price":67791.4,"qty":0.00000000},{"price":67791.7,"qty":0.00518720}],"checksum":1977187317,"timestamp":"2024-06-01T22:42:15.297699Z"}]}
{"channel":"book","type":"update","data":[{"symbol":"BTC/USDT","bids":[],"asks":[{"price":67789.5,"qty":0.27886928}],"checksum":574292188,"timestamp":"2024-06-01T22:42:15.299739Z"}]}
{"channel":"book","type":"update","data":[{"symbol":"BTC/USDT","bids":[],"asks":[{"price":67789.7,"qty":1.17765616}],"checksum":1237269532,"timestamp":"2024-06-01T22:42:15.299882Z"}]}
{"channel":"book","type":"update","data":[{"symbol":"BTC/USDT","bids":[],"asks":[{"price":67789.5,"qty":0.22449807},{"price":67789.1,"qty":0.05437121}],"checksum":1287995034,"timestamp":"2024-06-01T22:42:15.553830Z"}]}
{"channel":"book","type":"update","data":[{"symbol":"BTC/USDT","bids":[{"price":67755.7,"qty":0.00000000},{"price":67755.4,"qty":0.15000000}],"asks":[],"checksum":3863303130,"timestamp":"2024-06-01T22:42:15.861330Z"}]}
{"channel":"book","type":"update","data":[{"symbol":"BTC/USDT","bids":[{"price":67755.5,"qty":0.22470038}],"asks":[],"checksum":3058776835,"timestamp":"2024-06-01T22:42:15.863517Z"}]}
{"channel":"book","type":"update","data":[{"symbol":"BTC/USDT","bids":[],"asks":[{"price":67789.1,"qty":0.00000000},{"price":67789.8,"qty":0.19976708},{"price":67777.3,"qty":0.05437121}],"checksum":3856264490,"timestamp":"2024-06-01T22:42:16.131159Z"}]}
{"channel":"book","type":"update","data":[{"symbol":"BTC/USDT","bids":[],"asks":[{"price":67777.4,"qty":0.00000000},{"price":67789.8,"qty":0.19976708}],"checksum":3723154721,"timestamp":"2024-06-01T22:42:16.136206Z"}]}
{"channel":"book","type":"update","data":[{"symbol":"BTC/USDT","bids":[],"asks":[{"price":67777.3,"qty":0.00000000},{"price":67791.2,"qty":0.22140000},{"price":67777.4,"qty":0.05437121}],"checksum":1738008711,"timestamp":"2024-06-01T22:42:16.187505Z"}]}
{"channel":"book","type":"update","data":[{"symbol":"BTC/USDT","bids":[],"asks":[{"price":67777.3,"qty":0.06384784}],"checksum":425286297,"timestamp":"2024-06-01T22:42:16.339766Z"}]}
{"channel":"book","type":"update","data":[{"symbol":"BTC/USDT","bids":[],"asks":[{"price":67777.4,"qty":0.00000000},{"price":67789.8,"qty":0.19976708},{"price":67777.2,"qty":0.05437113}],"checksum":1521698101,"timestamp":"2024-06-01T22:42:16.738605Z"}]}
{"channel":"book","type":"update","data":[{"symbol":"BTC/USDT","bids":[],"asks":[{"price":67777.3,"qty":0.00000000},{"price":67789.8,"qty":0.19976708}],"checksum":878318501,"timestamp":"2024-06-01T22:42:16.742498Z"}]}
{"channel":"book","type":"update","data":[{"symbol":"BTC/USDT","bids":[],"asks":[{"price":67777.2,"qty":0.00000000},{"price":67791.2,"qty":0.22140000},{"price":67777.4,"qty":0.05437114}],"checksum":765812707,"timestamp":"2024-06-01T22:42:16.807125Z"}]}
{"channel":"book","type":"update","data":[{"symbol":"BTC/USDT","bids":[],"asks":[{"price":67777.4,"qty":0.10437114}],"checksum":1612221086,"timestamp":"2024-06-01T22:42:16.899335Z"}]}
{"channel":"book","type":"update","data":[{"symbol":"BTC/USDT","bids":[],"asks":[{"price":67777.3,"qty":0.06384784}],"checksum":2554278476,"timestamp":"2024-06-01T22:42:16.959411Z"}]}
{"channel":"book","type":"update","data":[{"symbol":"BTC/USDT","bids":[],"asks":[{"price":67777.4,"qty":0.05437114},{"price":67777.3,"qty":0.11384784}],"checksum":2885447129,"timestamp":"2024-06-01T22:42:16.966888Z"}]}
{"channel":"book","type":"update","data":[{"symbol":"BTC/USDT","bids":[],"asks":[{"price":67789.6,"qty":0.00000000},{"price":67789.8,"qty":0.19976708}],"checksum":3876213598,"timestamp":"2024-06-01T22:42:17.035524Z"}]}
{"channel":"book","type":"update","data":[{"symbol":"BTC/USDT","bids":[],"asks":[{"price":67789.4,"qty":0.00826752}],"checksum":3280566671,"timestamp":"2024-06-01T22:42:17.040273Z"}]}
{"channel":"book","type":"update","data":[{"symbol":"BTC/USDT","bids":[],"asks":[{"price":67777.3,"qty":0.05000000}],"checksum":827461571,"timestamp":"2024-06-01T22:42:17.262422Z"}]}
{"channel":"book","type":"update","data":[{"symbol":"BTC/USDT","bids":[{"price":67755.8,"qty":0.00000000},{"price":67755.4,"qty":0.15000000}],"asks":[],"checksum":425191732,"timestamp":"2024-06-01T22:42:17.337052Z"}]}
{"channel":"book","type":"update","data":[{"symbol":"BTC/USDT","bids":[],"asks":[{"price":67777.4,"qty":0.00000000},{"price":67789.8,"qty":0.19976708},{"price":67777.2,"qty":0.05437115}],"checksum":3849134707,"timestamp":"2024-06-01T22:42:17.341485Z"}]}
{"channel":"book","type":"update","data":[{"symbol":"BTC/USDT","bids":[{"price":67755.6,"qty":0.01354926}],"asks":[],"checksum":2641275563,"timestamp":"2024-06-01T22:42:17.341728Z"}]}
{"channel":"book","type":"update","data":[{"symbol":"BTC/USDT","bids":[],"asks":[{"price":67777.1,"qty":0.06384784}],"checksum":2782289241,"timestamp":"2024-06-01T22:42:17.462597Z"}]}
{"channel":"book","type":"update","data":[{"symbol":"BTC/USDT","bids":[],"asks":[{"price":67777.3,"qty":0.00000000},{"price":67789.7,"qty":1.17765616},{"price":67777.1,"qty":0.11384784}],"checksum":286781905,"timestamp":"2024-06-01T22:42:17.702630Z"}]}
{"channel":"book","type":"update","data":[{"symbol":"BTC/USDT","bids":[],"asks":[{"price":67777.1,"qty":0.05000000}],"checksum":1719155239,"timestamp":"2024-06-01T22:42:17.714716Z"}]}
{"channel":"book","type":"update","data":[{"symbol":"BTC/USDT","bids":[{"price":67775.0,"qty":0.00000000},{"price":67755.4,"qty":0.15000000}],"asks":[],"checksum":2401720993,"timestamp":"2024-06-01T22:42:17.798033Z"}]}
{"channel":"book","type":"update","data":[{"symbol":"BTC/USDT","bids":[{"price":67773.7,"qty":0.22960327}],"asks":[],"checksum":2654499873,"timestamp":"2024-06-01T22:42:17.806819Z"}]}
{"channel":"book","type":"update","data":[{"symbol":"BTC/USDT","bids":[],"asks":[{"price":67789.7,"qty":0.00000000},{"price":67789.8,"qty":0.19976708}],"checksum":3760615335,"timestamp":"2024-06-01T22:42:17.845629Z"}]}
{"channel":"book","type":"update","data":[{"symbol":"BTC/USDT","bids":[],"asks":[{"price":67789.5,"qty":0.00000000},{"price":67791.2,"qty":0.22140000}],"checksum":3690840410,"timestamp":"2024-06-01T22:42:17.845697Z"}]}
{"channel":"book","type":"update","data":[{"symbol":"BTC/USDT","bids":[],"asks":[{"price":67791.2,"qty":0.00000000},{"price":67791.7,"qty":0.00518720}],"checksum":3003014370,"timestamp":"2024-06-01T22:42:17.849101Z"}]}
{"channel":"book","type":"update","data":[{"symbol":"BTC/USDT","bids":[],"asks":[{"price":67789.7,"qty":1.67589790}],"checksum":2531854462,"timestamp":"2024-06-01T22:42:17.850577Z"}]}
{"channel":"book","type":"update","data":[{"symbol":"BTC/USDT","bids":[],"asks":[{"price":67777.1,"qty":0.07953391}],"checksum":596428826,"timestamp":"2024-06-01T22:42:17.850601Z"}]}
{"channel":"book","type":"update","data":[{"symbol":"BTC/USDT","bids":[],"asks":[{"price":67777.0,"qty":0.06384784}],"checksum":3670939423,"timestamp":"2024-06-01T22:42:17.927827Z"}]}
{"channel":"book","type":"update","data":[{"symbol":"BTC/USDT","bids":[],"asks":[{"price":67777.2,"qty":0.00000000},{"price":67789.8,"qty":0.19976708},{"price":67776.9,"qty":0.05437115}],"checksum":2364718973,"timestamp":"2024-06-01T22:42:18.014162Z"}]}
{"channel":"book","type":"update","data":[{"symbol":"BTC/USDT","bids":[],"asks":[{"price":67777.0,"qty":0.00000000},{"price":67789.8,"qty":0.19976708}],"checksum":3663003916,"timestamp":"2024-06-01T22:42:18.179973Z"}]}
{"channel":"book","type":"update","data":[{"symbol":"BTC/USDT","bids":[],"asks":[{"price":67776.9,"qty":0.00000000},{"price":67791.1,"qty":1.54376083},{"price":67777.0,"qty":0.05437125}],"checksum":4264457779,"timestamp":"2024-06-01T22:42:18.237812Z"}]}
{"channel":"book","type":"update","data":[{"symbol":"BTC/USDT","bids":[],"asks":[{"price":67776.9,"qty":0.06323292}],"checksum":1312182817,"timestamp":"2024-06-01T22:42:18.380643Z"}]}
{"channel":"book","type":"update","data":[{"symbol":"BTC/USDT","bids":[],"asks":[{"price":67777.0,"qty":0.00000000},{"price":67789.8,"qty":0.19976708},{"price":67776.8,"qty":0.05437125}],"checksum":1941257112,"timestamp":"2024-06-01T22:42:18.643056Z"}]}
{"channel":"book","type":"update","data":[{"symbol":"BTC/USDT","bids":[],"asks":[{"price":67776.9,"qty":0.00000000},{"price":67789.8,"qty":0.19976708}],"checksum":335037103,"timestamp":"2024-06-01T22:42:18.646843Z"}]}
{"channel":"book","type":"update","data":[{"symbol":"BTC/USDT","bids":[],"asks":[{"price":67776.8,"qty":0.00000000},{"price":67791.0,"qty":0.22140000},{"price":67777.0,"qty":0.05437125}],"checksum":4264457779,"timestamp":"2024-06-01T22:42:18.699277Z"}]}
{"channel":"book","type":"update","data":[{"symbol":"BTC/USDT","bids":[],"asks":[{"price":67776.9,"qty":0.06323292}],"checksum":1312182817,"timestamp":"2024-06-01T22:42:18.849910Z"}]}
{"channel":"book","type":"update","data":[{"symbol":"BTC/USDT","bids":[],"asks":[{"price":67777.1,"qty":0.02953391},{"price":67776.9,"qty":0.11323292}],"checksum":3612629754,"timestamp":"2024-06-01T22:42:18.896283Z"}]}
{"channel":"book","type":"update","data":[{"symbol":"BTC/USDT","bids":[],"asks":[{"price":67776.9,"qty":0.05000000}],"checksum":4150700734,"timestamp":"2024-06-01T22:42:19.101572Z"}]}
{"channel":"book","type":"update","data":[{"symbol":"BTC/USDT","bids":[],"asks":[{"price":67776.8,"qty":0.06323292}],"checksum":4071182187,"timestamp":"2024-06-01T22:42:19.302910Z"}]}
{"channel":"book","type":"update","data":[{"symbol":"BTC/USDT","bids":[],"asks":[{"price":67776.9,"qty":0.00000000},{"price":67789.7,"qty":1.67589790},{"price":67776.8,"qty":0.11323292}],"checksum":3913737664,"timestamp":"2024-06-01T22:42:19.309933Z"}]}
{"channel":"book","type":"update","data":[{"symbol":"BTC/USDT","bids":[{"price":67755.5,"qty":0.00000000},{"price":67754.3,"qty":0.02214495}],"asks":[],"checksum":2831866091,"timestamp":"2024-06-01T22:42:19.317190Z"}]}
{"channel":"book","type":"update","data":[{"symbol":"BTC/USDT","bids":[{"price":67755.7,"qty":0.22623247}],"asks":[],"checksum":164984461,"timestamp":"2024-06-01T22:42:19.318227Z"}]}
{"channel":"book","type":"update","data":[{"symbol":"BTC/USDT","bids":[],"asks":[{"price":67777.0,"qty":0.00000000},{"price":67789.8,"qty":0.19976708},{"price":67776.8,"qty":0.16760417}],"checksum":1365548305,"timestamp":"2024-06-01T22:42:19.344606Z"}]}
{"channel":"book","type":"update","data":[{"symbol":"BTC/USDT","bids":[],"asks":[{"price":67776.8,"qty":0.10437125}],"checksum":1029550360,"timestamp":"2024-06-01T22:42:19.559642Z"}]}
{"channel":"book","type":"update","data":[{"symbol":"BTC/USDT","bids":[],"asks":[{"price":67776.7,"qty":0.06323292}],"checksum":2743675063,"timestamp":"2024-06-01T22:42:19.763553Z"}]}
{"channel":"book","type":"update","data":[{"symbol":"BTC/USDT","bids":[],"asks":[{"price":67776.8,"qty":0.05437125},{"price":67776.7,"qty":0.11323292}],"checksum":1474003130,"timestamp":"2024-06-01T22:42:19.770626Z"}]}
{"channel":"book","type":"update","data":[{"symbol":"BTC/USDT","bids":[],"asks":[{"price":67789.4,"qty":0.00000000},{"price":67789.8,"qty":0.19976708}],"checksum":1097840183,"timestamp":"2024-06-01T22:42:19.796461Z"}]}
{"channel":"book","type":"update","data":[{"symbol":"BTC/USDT","bids":[],"asks":[{"price":67789.6,"qty":0.00784125}],"checksum":915807988,"timestamp":"2024-06-01T22:42:19.798352Z"}]}
{"channel":"book","type":"update","data":[{"symbol":"BTC/USDT","bids":[],"asks":[{"price":67776.8,"qty":0.00000000},{"price":67789.8,"qty":0.19976708},{"price":67776.6,"qty":0.05437124}],"checksum":3602418646,"timestamp":"2024-06-01T22:42:20.003029Z"}]}
{"channel":"book","type":"update","data":[{"symbol":"BTC/USDT","bids":[],"asks":[{"price":67776.7,"qty":0.06323292},{"price":67776.6,"qty":0.10437124}],"checksum":3716467571,"timestamp":"2024-06-01T22:42:20.010501Z"}]}
{"channel":"book","type":"update","data":[{"symbol":"BTC/USDT","bids":[],"asks":[{"price":67776.7,"qty":0.00000000},{"price":67789.8,"qty":0.19976708}],"checksum":3855275393,"timestamp":"2024-06-01T22:42:20.015907Z"}]}
{"channel":"book","type":"update","data":[{"symbol":"BTC/USDT","bids":[],"asks":[{"price":67776.5,"qty":0.06323292}],"checksum":2213139945,"timestamp":"2024-06-01T22:42:20.218359Z"}]}
{"channel":"book","type":"update","data":[{"symbol":"BTC/USDT","bids":[],"asks":[{"price":67776.6,"qty":0.05437124},{"price":67776.5,"qty":0.11323292}],"checksum":3988532968,"timestamp":"2024-06-01T22:42:20.227467Z"}]}
{"channel":"book","type":"update","data":[{"symbol":"BTC/USDT","bids":[],"asks":[{"price":67776.5,"qty":0.05000000}],"checksum":1725390770,"timestamp":"2024-06-01T22:42:20.469627Z"}]}
{"channel":"book","type":"update","data":[{"symbol":"BTC/USDT","bids":[],"asks":[{"price":67789.7,"qty":0.00000000},{"price":67789.8,"qty":0.19976708}],"checksum":1084201914,"timestamp":"2024-06-01T22:42:20.491855Z"}]}
{"channel":"book","type":"update","data":[{"symbol":"BTC/USDT","bids":[],"asks":[{"price":67777.1,"qty":0.00000000},{"price":67791.0,"qty":0.22140000}],"checksum":4149795794,"timestamp":"2024-06-01T22:42:20.491875Z"}]}
{"channel":"book","type":"update","data":[{"symbol":"BTC/USDT","bids":[],"asks":[{"price":67789.7,"qty":2.87707522}],"checksum":1232472128,"timestamp":"2024-06-01T22:42:20.495070Z"}]}
{"channel":"book","type":"update","data":[{"symbol":"BTC/USDT","bids":[],"asks":[{"price":67789.5,"qty":0.31114880}],"checksum":1685881694,"timestamp":"2024-06-01T22:42:20.495529Z"}]}
{"channel":"book","type":"update","data":[{"symbol":"BTC/USDT","bids":[{"price":67755.6,"qty":0.00000000},{"price":67754.2,"qty":0.02214550}],"asks":[],"checksum":2376581926,"timestamp":"2024-06-01T22:42:20.507427Z"}]}
{"channel":"book","type":"update","data":[{"symbol":"BTC/USDT","bids":[{"price":67755.8,"qty":0.01268487}],"asks":[],"checksum":1063963174,"timestamp":"2024-06-01T22:42:20.509902Z"}]}
{"channel":"book","type":"update","data":[{"symbol":"BTC/USDT","bids":[],"asks":[{"price":67776.6,"qty":0.00000000},{"price":67789.8,"qty":0.19976708},{"price":67776.4,"qty":0.05437137}],"checksum":1304558980,"timestamp":"2024-06-01T22:42:20.639691Z"}]}
{"channel":"book","type":"update","data":[{"symbol":"BTC/USDT","bids":[],"asks":[{"price":67776.5,"qty":0.00000000},{"price":67789.8,"qty":0.19976708},{"price":67776.4,"qty":0.10437137}],"checksum":965516108,"timestamp":"2024-06-01T22:42:20.647637Z"}]}
{"channel":"book","type":"update","data":[{"symbol":"BTC/USDT","bids":[],"asks":[{"price":67776.3,"qty":0.06231172}],"checksum":2455507474,"timestamp":"2024-06-01T22:42:20.671771Z"}]}
{"channel":"book","type":"update","data":[{"symbol":"BTC/USDT","bids":[],"asks":[{"price":67776.4,"qty":0.05437137},{"price":67776.3,"qty":0.11231172}],"checksum":2290768214,"timestamp":"2024-06-01T22:42:20.679669Z"}]}
{"channel":"book","type":"update","data":[{"symbol":"BTC/USDT","bids":[],"asks":[{"price":67776.3,"qty":0.06231172}],"checksum":26315992,"timestamp":"2024-06-01T22:42:20.907149Z"}]}
{"channel":"book","type":"update","data":[{"symbol":"BTC/USDT","bids":[{"price":67763.9,"qty":0.00101400}],"asks":[],"checksum":246044570,"timestamp":"2024-06-01T22:42:21.246975Z"}]}
{"channel":"book","type":"update","data":[{"symbol":"BTC/USDT","bids":[],"asks":[{"price":67776.4,"qty":0.00000000},{"price":67789.8,"qty":0.19976708},{"price":67776.2,"qty":0.05437140}],"checksum":1541906178,"timestamp":"2024-06-01T22:42:21.329586Z"}]}
{"channel":"book","type":"update","data":[{"symbol":"BTC/USDT","bids":[],"asks":[{"price":67776.3,"qty":0.00000000},{"price":67789.8,"qty":0.19976708}],"checksum":2562712377,"timestamp":"2024-06-01T22:42:21.332390Z"}]}
{"channel":"book","type":"update","data":[{"symbol":"BTC/USDT","bids":[],"asks":[{"price":67776.2,"qty":0.00000000},{"price":67791.7,"qty":0.00518720},{"price":67777.4,"qty":0.05437141}],"checksum":2748765962,"timestamp":"2024-06-01T22:42:21.395574Z"}]}
{"channel":"book","type":"update","data":[{"symbol":"BTC/USDT","bids":[],"asks":[{"price":67777.3,"qty":0.06231172}],"checksum":2814577177,"timestamp":"2024-06-01T22:42:21.559000Z"}]}
{"channel":"book","type":"update","data":[{"symbol":"BTC/USDT","bids":[],"asks":[{"price":67777.4,"qty":0.00000000},{"price":67789.8,"qty":0.19976708},{"price":67777.2,"qty":0.05437141}],"checksum":459391616,"timestamp":"2024-06-01T22:42:21.952666Z"}]}
{"channel":"book","type":"update","data":[{"symbol":"BTC/USDT","bids":[],"asks":[{"price":67777.3,"qty":0.00000000},{"price":67789.8,"qty":0.19976708}],"checksum":1914017049,"timestamp":"2024-06-01T22:42:21.956745Z"}]}
{"channel":"book","type":"update","data":[{"symbol":"BTC/USDT","bids":[],"asks":[{"price":67777.2,"qty":0.00000000},{"price":67791.7,"qty":0.00518720},{"price":67777.4,"qty":0.05437141}],"checksum":2748765962,"timestamp":"2024-06-01T22:42:22.033829Z"}]}
{"channel":"book","type":"update","data":[{"symbol":"BTC/USDT","bids":[],"asks":[{"price":67777.3,"qty":0.06231172}],"checksum":2814577177,"timestamp":"2024-06-01T22:42:22.175850Z"}]}
{"channel":"book","type":"update","data":[{"symbol":"BTC/USDT","bids":[],"asks":[{"price":67789.6,"qty":0.00000000},{"price":67789.8,"qty":0.19976708}],"checksum":2464240596,"timestamp":"2024-06-01T22:42:22.572935Z"}]}
{"channel":"book","type":"update","data":[{"symbol":"BTC/USDT","bids":[],"asks":[{"price":67789.4,"qty":0.00840677}],"checksum":4127110570,"timestamp":"2024-06-01T22:42:22.574904Z"}]}
{"channel":"book","type":"update","data":[{"symbol":"BTC/USDT","bids":[],"asks":[{"price":67777.4,"qty":0.00000000},{"price":67789.8,"qty":0.19976708},{"price":67777.2,"qty":0.05437141}],"checksum":1230798131,"timestamp":"2024-06-01T22:42:22.580353Z"}]}
{"channel":"book","type":"update","data":[{"symbol":"BTC/USDT","bids":[],"asks":[{"price":67777.3,"qty":0.00000000},{"price":67789.8,"qty":0.19976708}],"checksum":216421782,"timestamp":"2024-06-01T22:42:22.583200Z"}]}
{"channel":"book","type":"update","data":[{"symbol":"BTC/USDT","bids":[],"asks":[{"price":67777.2,"qty":0.00000000},{"price":67791.7,"qty":0.00518720},{"price":67777.4,"qty":0.05437147}],"checksum":1260694298,"timestamp":"2024-06-01T22:42:22.652266Z"}]}
{"channel":"book","type":"update","data":[{"symbol":"BTC/USDT","bids":[{"price":67755.7,"qty":0.00000000},{"price":67755.4,"qty":0.15000000}],"asks":[],"checksum":2116105704,"timestamp":"2024-06-01T22:42:22.772167Z"}]}
{"channel":"book","type":"update","data":[{"symbol":"BTC/USDT","bids":[{"price":67755.5,"qty":0.89198142}],"asks":[],"checksum":971835344,"timestamp":"2024-06-01T22:42:22.776833Z"}]}
{"channel":"book","type":"update","data":[{"symbol":"BTC/USDT","bids":[],"asks":[{"price":67777.3,"qty":0.06673366}],"checksum":2378260212,"timestamp":"2024-06-01T22:42:22.794193Z"}]}
{"channel":"book","type":"update","data":[{"symbol":"BTC/USDT","bids":[],"asks":[{"price":67789.5,"qty":0.00000000},{"price":67789.8,"qty":0.19976708}],"checksum":620865648,"timestamp":"2024-06-01T22:42:23.066086Z"}]}
{"channel":"book","type":"update","data":[{"symbol":"BTC/USDT","bids":[],"asks":[{"price":67789.7,"qty":0.00000000},{"price":67791.7,"qty":0.00518720}],"checksum":112467260,"timestamp":"2024-06-01T22:42:23.066149Z"}]}
{"channel":"book","type":"update","data":[{"symbol":"BTC/USDT","bids":[],"asks":[{"price":67777.3,"qty":0.09626757}],"checksum":4036310281,"timestamp":"2024-06-01T22:42:23.071635Z"}]}
{"channel":"book","type":"update","data":[{"symbol":"BTC/USDT","bids":[],"asks":[{"price":67789.7,"qty":1.26430690}],"checksum":2951096174,"timestamp":"2024-06-01T22:42:23.071773Z"}]}
{"channel":"book","type":"update","data":[{"symbol":"BTC/USDT","bids":[],"asks":[{"price":67777.3,"qty":0.02953391}],"checksum":4225306430,"timestamp":"2024-06-01T22:42:23.077777Z"}]}
{"channel":"book","type":"update","data":[{"symbol":"BTC/USDT","bids":[],"asks":[{"price":67777.4,"qty":0.00000000},{"price":67791.7,"qty":0.00518720},{"price":67777.2,"qty":0.05437147}],"checksum":3838295756,"timestamp":"2024-06-01T22:42:23.262463Z"}]}
{"channel":"book","type":"update","data":[{"symbol":"BTC/USDT","bids":[{"price":67763.9,"qty":0.00000000},{"price":67755.4,"qty":0.15000000},{"price":67773.8,"qty":0.00101400}],"asks":[],"checksum":2343588466,"timestamp":"2024-06-01T22:42:23.275337Z"}]}
{"channel":"book","type":"update","data":[{"symbol":"BTC/USDT","bids":[],"asks":[{"price":67777.1,"qty":0.06673366}],"checksum":2029173222,"timestamp":"2024-06-01T22:42:23.278277Z"}]}
{"channel":"book","type":"update","data":[{"symbol":"BTC/USDT","bids":[{"price":67773.7,"qty":0.17960327},{"price":67773.8,"qty":0.05101400}],"asks":[],"checksum":2222657365,"timestamp":"2024-06-01T22:42:23.282474Z"}]}
{"channel":"book","type":"update","data":[{"symbol":"BTC/USDT","bids":[],"asks":[{"price":67777.2,"qty":0.00000000},{"price":67789.8,"qty":0.19976708},{"price":67789.1,"qty":0.05437147}],"checksum":921336960,"timestamp":"2024-06-01T22:42:23.372367Z"}]}
{"channel":"book","type":"update","data":[{"symbol":"BTC/USDT","bids":[{"price":67773.8,"qty":0.05000000},{"price":67773.9,"qty":0.00101400}],"asks":[],"checksum":3234853674,"timestamp":"2024-06-01T22:42:23.398857Z"}]}
{"channel":"book","type":"update","data":[{"symbol":"BTC/USDT","bids":[{"price":67773.8,"qty":0.00000000},{"price":67755.5,"qty":0.89198142},{"price":67773.9,"qty":0.05101400}],"asks":[],"checksum":3389172461,"timestamp":"2024-06-01T22:42:23.406344Z"}]}
{"channel":"book","type":"update","data":[{"symbol":"BTC/USDT","bids":[],"asks":[{"price":67777.1,"qty":0.00000000},{"price":67789.8,"qty":0.19976708}],"checksum":1484431335,"timestamp":"2024-06-01T22:42:23.528427Z"}]}
