{"channel":"book","type":"snapshot","data":[{"symbol":"BTC/AUD","bids":[{"price":101906.1,"qty":0.00474700},{"price":101906.0,"qty":0.00075200},{"price":101885.7,"qty":0.00135100},{"price":101878.2,"qty":0.05324169},{"price":101878.1,"qty":0.14477810},{"price":101877.9,"qty":0.00058344},{"price":101877.5,"qty":0.04717373},{"price":101868.7,"qty":0.14462714},{"price":101831.1,"qty":0.02256177},{"price":101831.0,"qty":0.02930000}],"asks":[{"price":101940.5,"qty":0.01925523},{"price":101940.6,"qty":0.04717373},{"price":101943.1,"qty":0.00474600},{"price":101944.3,"qty":0.00075200},{"price":101970.6,"qty":0.00359666},{"price":101970.7,"qty":0.18117122},{"price":101971.1,"qty":0.46946074},{"price":101971.2,"qty":0.63075382},{"price":101971.9,"qty":0.00564000},{"price":101974.2,"qty":0.00135100}],"checksum":2636371867}]}
{"channel":"book","type":"update","data":[{"symbol":"BTC/AUD","bids":[],"asks":[{"price":101940.4,"qty":0.04717373}],"checksum":118019491,"timestamp":"2024-06-01T22:42:01.680684Z"}]}
{"channel":"book","type":"update","data":[{"symbol":"BTC/AUD","bids":[],"asks":[{"price":101940.5,"qty":0.00000000},{"price":101974.2,"qty":0.00135100},{"price":101940.3,"qty":0.01925524}],"checksum":2701987536,"timestamp":"2024-06-01T22:42:01.964706Z"}]}
{"channel":"book","type":"update","data":[{"symbol":"BTC/AUD","bids":[{"price":101831.0,"qty":0.00000000},{"price":101830.9,"qty":0.05739775},{"price":101831.2,"qty":0.02930000}],"asks":[],"checksum":72908832,"timestamp":"2024-06-01T22:42:01.967391Z"}]}
{"channel":"book","type":"update","data":[{"symbol":"BTC/AUD","bids":[],"asks":[{"price":101940.4,"qty":0.00000000},{"price":101974.2,"qty":0.00135100}],"checksum":2978388828,"timestamp":"2024-06-01T22:42:01.969960Z"}]}
{"channel":"book","type":"update","data":[{"symbol":"BTC/AUD","bids":[],"asks":[{"price":101940.2,"qty":0.04717373}],"checksum":2117492803,"timestamp":"2024-06-01T22:42:01.970064Z"}]}
{"channel":"book","type":"update","data":[{"symbol":"BTC/AUD","bids":[],"asks":[{"price":101940.6,"qty":0.00000000},{"price":101974.2,"qty":0.00135100}],"checksum":3342648482,"timestamp":"2024-06-01T22:42:02.179413Z"}]}
{"channel":"book","type":"update","data":[{"symbol":"BTC/AUD","bids":[],"asks":[{"price":101970.7,"qty":0.00000000},{"price":102003.7,"qty":0.02930000}],"checksum":1390876479,"timestamp":"2024-06-01T22:42:02.288542Z"}]}
{"channel":"book","type":"update","data":[{"symbol":"BTC/AUD","bids":[],"asks":[{"price":101971.1,"qty":0.05000000}],"checksum":2986074947,"timestamp":"2024-06-01T22:42:02.288607Z"}]}
{"channel":"book","type":"update","data":[{"symbol":"BTC/AUD","bids":[],"asks":[{"price":101970.5,"qty":0.18117122}],"checksum":1307400183,"timestamp":"2024-06-01T22:42:02.293315Z"}]}
{"channel":"book","type":"update","data":[{"symbol":"BTC/AUD","bids":[],"asks":[{"price":101971.0,"qty":0.44112343}],"checksum":1561444049,"timestamp":"2024-06-01T22:42:02.293328Z"}]}
{"channel":"book","type":"update","data":[{"symbol":"BTC/AUD","bids":[],"asks":[{"price":101940.3,"qty":0.00000000},{"price":101974.2,"qty":0.00135100},{"price":101940.1,"qty":0.01925524}],"checksum":1184822786,"timestamp":"2024-06-01T22:42:02.534208Z"}]}
{"channel":"book","type":"update","data":[{"symbol":"BTC/AUD","bids":[],"asks":[{"price":101940.0,"qty":0.04717373}],"checksum":3315030238,"timestamp":"2024-06-01T22:42:02.539487Z"}]}
{"channel":"book","type":"update","data":[{"symbol":"BTC/AUD","bids":[],"asks":[{"price":101940.2,"qty":0.00000000},{"price":101971.9,"qty":0.00564000}],"checksum":2093685807,"timestamp":"2024-06-01T22:42:02.680101Z"}]}
{"channel":"book","type":"update","data":[{"symbol":"BTC/AUD","bids":[{"price":101906.1,"qty":0.00000000},{"price":101830.9,"qty":0.05739775},{"price":101901.3,"qty":0.00474800}],"asks":[],"checksum":328893508,"timestamp":"2024-06-01T22:42:02.727047Z"}]}
{"channel":"book","type":"update","data":[{"symbol":"BTC/AUD","bids":[],"asks":[{"price":101940.1,"qty":0.00000000},{"price":101974.2,"qty":0.00135100},{"price":101939.9,"qty":0.01925528}],"checksum":3122603828,"timestamp":"2024-06-01T22:42:03.049815Z"}]}
{"channel":"book","type":"update","data":[{"symbol":"BTC/AUD","bids":[],"asks":[{"price":101939.8,"qty":0.04717373}],"checksum":792181698,"timestamp":"2024-06-01T22:42:03.055020Z"}]}
{"channel":"book","type":"update","data":[{"symbol":"BTC/AUD","bids":[],"asks":[{"price":101940.0,"qty":0.00000000},{"price":101971.9,"qty":0.00564000}],"checksum":2269039372,"timestamp":"2024-06-01T22:42:03.179176Z"}]}
{"channel":"book","type":"update","data":[{"symbol":"BTC/AUD","bids":[],"asks":[{"price":101970.6,"qty":0.00000000},{"price":101974.2,"qty":0.00135100}],"checksum":1836912771,"timestamp":"2024-06-01T22:42:03.343077Z"}]}
{"channel":"book","type":"update","data":[{"symbol":"BTC/AUD","bids":[],"asks":[{"price":101970.4,"qty":0.00308876}],"checksum":4268761977,"timestamp":"2024-06-01T22:42:03.348353Z"}]}
{"channel":"book","type":"update","data":[{"symbol":"BTC/AUD","bids":[],"asks":[{"price":101939.9,"qty":0.00000000},{"price":101974.2,"qty":0.00135100},{"price":101939.7,"qty":0.01925589}],"checksum":82896416,"timestamp":"2024-06-01T22:42:03.601130Z"}]}
{"channel":"book","type":"update","data":[{"symbol":"BTC/AUD","bids":[],"asks":[{"price":101939.6,"qty":0.04717373}],"checksum":3623733289,"timestamp":"2024-06-01T22:42:03.606385Z"}]}
{"channel":"book","type":"update","data":[{"symbol":"BTC/AUD","bids":[],"asks":[{"price":101939.8,"qty":0.00000000},{"price":101971.9,"qty":0.00564000}],"checksum":170894250,"timestamp":"2024-06-01T22:42:03.680086Z"}]}
{"channel":"book","type":"update","data":[{"symbol":"BTC/AUD","bids":[{"price":101877.9,"qty":0.00000000},{"price":101830.9,"qty":0.05739775}],"asks":[],"checksum":657228843,"timestamp":"2024-06-01T22:42:03.749385Z"}]}
{"channel":"book","type":"update","data":[{"symbol":"BTC/AUD","bids":[{"price":101878.3,"qty":0.00058344}],"asks":[],"checksum":4257891592,"timestamp":"2024-06-01T22:42:03.750299Z"}]}
{"channel":"book","type":"update","data":[{"symbol":"BTC/AUD","bids":[{"price":101868.7,"qty":0.00000000},{"price":101830.9,"qty":0.05739775}],"asks":[],"checksum":488337889,"timestamp":"2024-06-01T22:42:03.876280Z"}]}
{"channel":"book","type":"update","data":[{"symbol":"BTC/AUD","bids":[{"price":101863.6,"qty":0.14463438}],"asks":[],"checksum":3828544860,"timestamp":"2024-06-01T22:42:03.883343Z"}]}
{"channel":"book","type":"update","data":[{"symbol":"BTC/AUD","bids":[{"price":101878.1,"qty":0.00000000},{"price":101830.9,"qty":0.05739775}],"asks":[],"checksum":1484679534,"timestamp":"2024-06-01T22:42:04.052101Z"}]}
{"channel":"book","type":"update","data":[{"symbol":"BTC/AUD","bids":[{"price":101830.9,"qty":0.00000000},{"price":101821.1,"qty":0.05056249}],"asks":[],"checksum":2639529451,"timestamp":"2024-06-01T22:42:04.052284Z"}]}
{"channel":"book","type":"update","data":[{"symbol":"BTC/AUD","bids":[{"price":101831.3,"qty":0.17270839}],"asks":[],"checksum":2566647189,"timestamp":"2024-06-01T22:42:04.053212Z"}]}
{"channel":"book","type":"update","data":[{"symbol":"BTC/AUD","bids":[{"price":101878.4,"qty":0.05834678}],"asks":[],"checksum":1288433005,"timestamp":"2024-06-01T22:42:04.053346Z"}]}
{"channel":"book","type":"update","data":[{"symbol":"BTC/AUD","bids":[{"price":101831.2,"qty":0.00000000},{"price":101831.1,"qty":0.02256177},{"price":101831.4,"qty":0.02930000}],"asks":[],"checksum":885910224,"timestamp":"2024-06-01T22:42:04.055993Z"}]}
{"channel":"book","type":"update","data":[{"symbol":"BTC/AUD","bids":[{"price":101831.5,"qty":0.02256168}],"asks":[],"checksum":4049453623,"timestamp":"2024-06-01T22:42:04.066061Z"}]}
{"channel":"book","type":"update","data":[{"symbol":"BTC/AUD","bids":[{"price":101878.2,"qty":0.00000000},{"price":101831.3,"qty":0.17270839},{"price":101878.5,"qty":0.05324153}],"asks":[],"checksum":2606304106,"timestamp":"2024-06-01T22:42:04.104285Z"}]}
{"channel":"book","type":"update","data":[{"symbol":"BTC/AUD","bids":[{"price":101831.4,"qty":0.00000000},{"price":101831.3,"qty":0.17270839},{"price":101831.6,"qty":0.02930000}],"asks":[],"checksum":1296628550,"timestamp":"2024-06-01T22:42:04.561718Z"}]}
{"channel":"book","type":"update","data":[{"symbol":"BTC/AUD","bids":[],"asks":[{"price":101939.7,"qty":0.00000000},{"price":101974.2,"qty":0.00135100},{"price":101939.5,"qty":0.02314163}],"checksum":4210627592,"timestamp":"2024-06-01T22:42:04.646857Z"}]}
{"channel":"book","type":"update","data":[{"symbol":"BTC/AUD","bids":[],"asks":[{"price":101939.4,"qty":0.04717373}],"checksum":3763046641,"timestamp":"2024-06-01T22:42:04.652315Z"}]}
{"channel":"book","type":"update","data":[{"symbol":"BTC/AUD","bids":[],"asks":[{"price":101939.6,"qty":0.00000000},{"price":101971.9,"qty":0.00564000}],"checksum":3156601411,"timestamp":"2024-06-01T22:42:04.679842Z"}]}
{"channel":"book","type":"update","data":[{"symbol":"BTC/AUD","bids":[],"asks":[{"price":101970.5,"qty":0.00000000},{"price":101974.2,"qty":0.00135100}],"checksum":1745214271,"timestamp":"2024-06-01T22:42:04.915340Z"}]}
{"channel":"book","type":"update","data":[{"symbol":"BTC/AUD","bids":[],"asks":[{"price":101971.0,"qty":0.00000000},{"price":102003.7,"qty":0.02930000}],"checksum":279390792,"timestamp":"2024-06-01T22:42:04.915365Z"}]}
{"channel":"book","type":"update","data":[{"symbol":"BTC/AUD","bids":[],"asks":[{"price":101970.3,"qty":0.18117270}],"checksum":3417301915,"timestamp":"2024-06-01T22:42:04.920995Z"}]}
{"channel":"book","type":"update","data":[{"symbol":"BTC/AUD","bids":[],"asks":[{"price":101971.0,"qty":0.51901591}],"checksum":2850402022,"timestamp":"2024-06-01T22:42:04.921114Z"}]}
{"channel":"book","type":"update","data":[{"symbol":"BTC/AUD","bids":[],"asks":[{"price":101939.5,"qty":0.00000000},{"price":101974.2,"qty":0.00135100},{"price":101939.3,"qty":0.02314152}],"checksum":2268956082,"timestamp":"2024-06-01T22:42:05.221599Z"}]}
{"channel":"book","type":"update","data":[{"symbol":"BTC/AUD","bids":[],"asks":[{"price":101939.2,"qty":0.04717373}],"checksum":4014934305,"timestamp":"2024-06-01T22:42:05.227344Z"}]}
{"channel":"book","type":"update","data":[{"symbol":"BTC/AUD","bids":[],"asks":[{"price":101939.4,"qty":0.00000000},{"price":101971.9,"qty":0.00564000}],"checksum":1501848598,"timestamp":"2024-06-01T22:42:05.679688Z"}]}
{"channel":"book","type":"update","data":[{"symbol":"BTC/AUD","bids":[],"asks":[{"price":101939.3,"qty":0.00000000},{"price":101974.2,"qty":0.00135100},{"price":101939.1,"qty":0.02314152}],"checksum":225109612,"timestamp":"2024-06-01T22:42:05.746651Z"}]}
{"channel":"book","type":"update","data":[{"symbol":"BTC/AUD","bids":[],"asks":[{"price":101939.0,"qty":0.04717373}],"checksum":3483732977,"timestamp":"2024-06-01T22:42:05.751529Z"}]}
{"channel":"book","type":"update","data":[{"symbol":"BTC/AUD","bids":[{"price":101885.7,"qty":0.00000000},{"price":101831.3,"qty":0.17270839},{"price":101875.9,"qty":0.00135100}],"asks":[],"checksum":1550003296,"timestamp":"2024-06-01T22:42:05.938601Z"}]}
{"channel":"book","type":"update","data":[{"symbol":"BTC/AUD","bids":[],"asks":[{"price":101939.2,"qty":0.00000000},{"price":101971.9,"qty":0.00564000}],"checksum":2752809139,"timestamp":"2024-06-01T22:42:05.943229Z"}]}
{"channel":"book","type":"update","data":[{"symbol":"BTC/AUD","bids":[],"asks":[{"price":101970.4,"qty":0.00000000},{"price":101974.2,"qty":0.00135100}],"checksum":143024308,"timestamp":"2024-06-01T22:42:06.101718Z"}]}
{"channel":"book","type":"update","data":[{"symbol":"BTC/AUD","bids":[],"asks":[{"price":101970.2,"qty":0.00307668}],"checksum":616457236,"timestamp":"2024-06-01T22:42:06.104038Z"}]}
{"channel":"book","type":"update","data":[{"symbol":"BTC/AUD","bids":[],"asks":[{"price":101939.1,"qty":0.00000000},{"price":101974.2,"qty":0.00135100},{"price":101938.9,"qty":0.02314152}],"checksum":4026946791,"timestamp":"2024-06-01T22:42:06.310335Z"}]}
{"channel":"book","type":"update","data":[{"symbol":"BTC/AUD","bids":[],"asks":[{"price":101938.8,"qty":0.04717373}],"checksum":1919055244,"timestamp":"2024-06-01T22:42:06.317028Z"}]}
{"channel":"book","type":"update","data":[{"symbol":"BTC/AUD","bids":[],"asks":[{"price":101939.0,"qty":0.00000000},{"price":101971.9,"qty":0.00564000}],"checksum":1450909690,"timestamp":"2024-06-01T22:42:06.681272Z"}]}
{"channel":"book","type":"update","data":[{"symbol":"BTC/AUD","bids":[],"asks":[{"price":101938.9,"qty":0.00000000},{"price":101974.2,"qty":0.00135100},{"price":101938.7,"qty":0.02314133}],"checksum":3015982461,"timestamp":"2024-06-01T22:42:06.825209Z"}]}
{"channel":"book","type":"update","data":[{"symbol":"BTC/AUD","bids":[],"asks":[{"price":101938.6,"qty":0.04717373}],"checksum":3481645488,"timestamp":"2024-06-01T22:42:06.830492Z"}]}
{"channel":"book","type":"update","data":[{"symbol":"BTC/AUD","bids":[{"price":101878.4,"qty":0.00000000},{"price":101821.1,"qty":0.05056249}],"asks":[],"checksum":2508043256,"timestamp":"2024-06-01T22:42:06.903288Z"}]}
{"channel":"book","type":"update","data":[{"symbol":"BTC/AUD","bids":[{"price":101878.6,"qty":0.02953391}],"asks":[],"checksum":4232091183,"timestamp":"2024-06-01T22:42:06.903940Z"}]}
{"channel":"book","type":"update","data":[{"symbol":"BTC/AUD","bids":[{"price":101863.7,"qty":0.11597252}],"asks":[],"checksum":13506513,"timestamp":"2024-06-01T22:42:06.903959Z"}]}
{"channel":"book","type":"update","data":[{"symbol":"BTC/AUD","bids":[{"price":101831.7,"qty":0.08537991}],"asks":[],"checksum":722796691,"timestamp":"2024-06-01T22:42:06.904033Z"}]}
{"channel":"book","type":"update","data":[{"symbol":"BTC/AUD","bids":[{"price":101831.8,"qty":0.02930000}],"asks":[],"checksum":356779491,"timestamp":"2024-06-01T22:42:06.908249Z"}]}
{"channel":"book","type":"update","data":[{"symbol":"BTC/AUD","bids":[],"asks":[{"price":101938.8,"qty":0.00000000},{"price":101971.9,"qty":0.00564000}],"checksum":1128078554,"timestamp":"2024-06-01T22:42:06.908604Z"}]}
{"channel":"book","type":"update","data":[{"symbol":"BTC/AUD","bids":[{"price":101831.9,"qty":0.02256159}],"asks":[],"checksum":1242718253,"timestamp":"2024-06-01T22:42:06.917949Z"}]}
{"channel":"book","type":"update","data":[{"symbol":"BTC/AUD","bids":[{"price":101878.3,"qty":0.00000000},{"price":101831.8,"qty":0.02930000}],"asks":[],"checksum":4085816690,"timestamp":"2024-06-01T22:42:07.152857Z"}]}
{"channel":"book","type":"update","data":[{"symbol":"BTC/AUD","bids":[{"price":101863.8,"qty":0.00072753}],"asks":[],"checksum":3490029071,"timestamp":"2024-06-01T22:42:07.153963Z"}]}
{"channel":"book","type":"update","data":[{"symbol":"BTC/AUD","bids":[],"asks":[{"price":101971.1,"qty":0.00000000},{"price":101974.2,"qty":0.00135100}],"checksum":1991691658,"timestamp":"2024-06-01T22:42:07.183739Z"}]}
{"channel":"book","type":"update","data":[{"symbol":"BTC/AUD","bids":[],"asks":[{"price":101970.1,"qty":0.05000000}],"checksum":708950362,"timestamp":"2024-06-01T22:42:07.214217Z"}]}
{"channel":"book","type":"update","data":[{"symbol":"BTC/AUD","bids":[{"price":101878.5,"qty":0.00000000},{"price":101831.8,"qty":0.02930000},{"price":101878.7,"qty":0.05324124}],"asks":[],"checksum":2091522155,"timestamp":"2024-06-01T22:42:07.380463Z"}]}
{"channel":"book","type":"update","data":[{"symbol":"BTC/AUD","bids":[],"asks":[{"price":101938.7,"qty":0.00000000},{"price":101974.2,"qty":0.00135100},{"price":101938.5,"qty":0.02314133}],"checksum":787301119,"timestamp":"2024-06-01T22:42:07.380512Z"}]}
{"channel":"book","type":"update","data":[{"symbol":"BTC/AUD","bids":[{"price":101832.0,"qty":0.02930000}],"asks":[],"checksum":3450476920,"timestamp":"2024-06-01T22:42:07.412434Z"}]}
{"channel":"book","type":"update","data":[{"symbol":"BTC/AUD","bids":[],"asks":[{"price":101971.0,"qty":0.00000000},{"price":101974.2,"qty":0.00135100}],"checksum":492228641,"timestamp":"2024-06-01T22:42:07.494485Z"}]}
{"channel":"book","type":"update","data":[{"symbol":"BTC/AUD","bids":[],"asks":[{"price":101970.3,"qty":0.00000000},{"price":102003.7,"qty":0.02930000}],"checksum":2660782074,"timestamp":"2024-06-01T22:42:07.494646Z"}]}
{"channel":"book","type":"update","data":[{"symbol":"BTC/AUD","bids":[],"asks":[{"price":101971.0,"qty":0.54943833}],"checksum":1049096696,"timestamp":"2024-06-01T22:42:07.499597Z"}]}
{"channel":"book","type":"update","data":[{"symbol":"BTC/AUD","bids":[],"asks":[{"price":101970.1,"qty":0.07953391}],"checksum":603224409,"timestamp":"2024-06-01T22:42:07.499616Z"}]}
{"channel":"book","type":"update","data":[{"symbol":"BTC/AUD","bids":[],"asks":[{"price":101938.4,"qty":0.04717373}],"checksum":699561396,"timestamp":"2024-06-01T22:42:07.504999Z"}]}
{"channel":"book","type":"update","data":[{"symbol":"BTC/AUD","bids":[],"asks":[{"price":101938.6,"qty":0.00000000},{"price":101974.2,"qty":0.00135100}],"checksum":3379011314,"timestamp":"2024-06-01T22:42:07.679828Z"}]}
{"channel":"book","type":"update","data":[{"symbol":"BTC/AUD","bids":[],"asks":[{"price":101938.5,"qty":0.00000000},{"price":102003.7,"qty":0.02930000},{"price":101938.3,"qty":0.02314133}],"checksum":1808133228,"timestamp":"2024-06-01T22:42:07.921393Z"}]}
{"channel":"book","type":"update","data":[{"symbol":"BTC/AUD","bids":[],"asks":[{"price":101971.2,"qty":0.00000000},{"price":102003.7,"qty":0.02930000}],"checksum":2782322621,"timestamp":"2024-06-01T22:42:07.924866Z"}]}
{"channel":"book","type":"update","data":[{"symbol":"BTC/AUD","bids":[],"asks":[{"price":101938.2,"qty":0.04717373}],"checksum":4247853947,"timestamp":"2024-06-01T22:42:07.926640Z"}]}
{"channel":"book","type":"update","data":[{"symbol":"BTC/AUD","bids":[],"asks":[{"price":101965.6,"qty":0.63077179}],"checksum":1182349471,"timestamp":"2024-06-01T22:42:07.928358Z"}]}
{"channel":"book","type":"update","data":[{"symbol":"BTC/AUD","bids":[],"asks":[{"price":101938.4,"qty":0.00000000},{"price":101974.2,"qty":0.00135100}],"checksum":1628533352,"timestamp":"2024-06-01T22:42:08.179183Z"}]}
{"channel":"book","type":"update","data":[{"symbol":"BTC/AUD","bids":[],"asks":[{"price":101938.3,"qty":0.00000000},{"price":102003.7,"qty":0.02930000},{"price":101938.1,"qty":0.02314133}],"checksum":3067037268,"timestamp":"2024-06-01T22:42:08.428145Z"}]}
{"channel":"book","type":"update","data":[{"symbol":"BTC/AUD","bids":[],"asks":[{"price":101938.0,"qty":0.04717373}],"checksum":3279838186,"timestamp":"2024-06-01T22:42:08.432958Z"}]}
{"channel":"book","type":"update","data":[{"symbol":"BTC/AUD","bids":[],"asks":[{"price":101943.1,"qty":0.00000000},{"price":101974.2,"qty":0.00135100},{"price":101938.1,"qty":0.02788833}],"checksum":1197912900,"timestamp":"2024-06-01T22:42:08.488637Z"}]}
{"channel":"book","type":"update","data":[{"symbol":"BTC/AUD","bids":[],"asks":[{"price":101938.2,"qty":0.00000000},{"price":102003.7,"qty":0.02930000}],"checksum":1315384552,"timestamp":"2024-06-01T22:42:08.493585Z"}]}
{"channel":"book","type":"update","data":[{"symbol":"BTC/AUD","bids":[],"asks":[{"price":101944.3,"qty":0.00000000},{"price":102003.8,"qty":0.00551000},{"price":101938.1,"qty":0.02864033}],"checksum":1563897409,"timestamp":"2024-06-01T22:42:08.496233Z"}]}
{"channel":"book","type":"update","data":[{"symbol":"BTC/AUD","bids":[],"asks":[{"price":101970.2,"qty":0.00000000},{"price":102017.0,"qty":0.09768924}],"checksum":3185216250,"timestamp":"2024-06-01T22:42:08.851867Z"}]}
{"channel":"book","type":"update","data":[{"symbol":"BTC/AUD","bids":[],"asks":[{"price":101937.9,"qty":0.00029534}],"checksum":4050123794,"timestamp":"2024-06-01T22:42:08.856855Z"}]}
{"channel":"book","type":"update","data":[{"symbol":"BTC/AUD","bids":[],"asks":[{"price":101965.5,"qty":0.00228554}],"checksum":3854207567,"timestamp":"2024-06-01T22:42:08.856868Z"}]}
{"channel":"book","type":"update","data":[{"symbol":"BTC/AUD","bids":[],"asks":[{"price":101938.1,"qty":0.00549900},{"price":101937.8,"qty":0.02314192}],"checksum":2076881913,"timestamp":"2024-06-01T22:42:08.972211Z"}]}
{"channel":"book","type":"update","data":[{"symbol":"BTC/AUD","bids":[],"asks":[{"price":101937.7,"qty":0.04717373}],"checksum":531700966,"timestamp":"2024-06-01T22:42:08.977577Z"}]}
{"channel":"book","type":"update","data":[{"symbol":"BTC/AUD","bids":[],"asks":[{"price":101938.0,"qty":0.00000000},{"price":101974.2,"qty":0.00135100}],"checksum":1945576037,"timestamp":"2024-06-01T22:42:09.178153Z"}]}
{"channel":"book","type":"update","data":[{"symbol":"BTC/AUD","bids":[],"asks":[{"price":101937.8,"qty":0.00000000},{"price":102003.7,"qty":0.02930000},{"price":101937.6,"qty":0.02314192}],"checksum":229486943,"timestamp":"2024-06-01T22:42:09.518665Z"}]}
{"channel":"book","type":"update","data":[{"symbol":"BTC/AUD","bids":[],"asks":[{"price":101937.5,"qty":0.04717373}],"checksum":2622868394,"timestamp":"2024-06-01T22:42:09.523966Z"}]}
{"channel":"book","type":"update","data":[{"symbol":"BTC/AUD","bids":[],"asks":[{"price":101937.7,"qty":0.00000000},{"price":101974.2,"qty":0.00135100}],"checksum":1586680678,"timestamp":"2024-06-01T22:42:09.678552Z"}]}
{"channel":"book","type":"update","data":[{"symbol":"BTC/AUD","bids":[{"price":101878.6,"qty":0.00000000},{"price":101831.9,"qty":0.02256159}],"asks":[],"checksum":1433643880,"timestamp":"2024-06-01T22:42:09.808025Z"}]}
{"channel":"book","type":"update","data":[{"symbol":"BTC/AUD","bids":[{"price":101832.1,"qty":0.05665146}],"asks":[],"checksum":528080189,"timestamp":"2024-06-01T22:42:09.808958Z"}]}
{"channel":"book","type":"update","data":[{"symbol":"BTC/AUD","bids":[{"price":101878.8,"qty":0.02953391}],"asks":[],"checksum":1589771448,"timestamp":"2024-06-01T22:42:09.809061Z"}]}
{"channel":"book","type":"update","data":[{"symbol":"BTC/AUD","bids":[{"price":101832.2,"qty":0.02930000}],"asks":[],"checksum":2538340932,"timestamp":"2024-06-01T22:42:09.811855Z"}]}
{"channel":"book","type":"update","data":[{"symbol":"BTC/AUD","bids":[{"price":101832.3,"qty":0.02256150}],"asks":[],"checksum":3888104983,"timestamp":"2024-06-01T22:42:09.832336Z"}]}
{"channel":"book","type":"update","data":[{"symbol":"BTC/AUD","bids":[{"price":101878.7,"qty":0.00000000},{"price":101832.2,"qty":0.02930000},{"price":101877.6,"qty":0.05324164}],"asks":[],"checksum":4185272214,"timestamp":"2024-06-01T22:42:09.845593Z"}]}
{"channel":"book","type":"update","data":[{"symbol":"BTC/AUD","bids":[],"asks":[{"price":101937.6,"qty":0.00000000},{"price":102003.7,"qty":0.02930000},{"price":101937.4,"qty":0.02314192}],"checksum":2533662264,"timestamp":"2024-06-01T22:42:10.050655Z"}]}
{"channel":"book","type":"update","data":[{"symbol":"BTC/AUD","bids":[],"asks":[{"price":101937.3,"qty":0.04717373}],"checksum":2192234732,"timestamp":"2024-06-01T22:42:10.056706Z"}]}
{"channel":"book","type":"update","data":[{"symbol":"BTC/AUD","bids":[],"asks":[{"price":101971.0,"qty":0.00000000},{"price":101974.2,"qty":0.00135100}],"checksum":3417156415,"timestamp":"2024-06-01T22:42:10.074478Z"}]}
{"channel":"book","type":"update","data":[{"symbol":"BTC/AUD","bids":[],"asks":[{"price":101970.1,"qty":0.05000000}],"checksum":4061926459,"timestamp":"2024-06-01T22:42:10.074690Z"}]}
{"channel":"book","type":"update","data":[{"symbol":"BTC/AUD","bids":[],"asks":[{"price":101965.4,"qty":0.44112491}],"checksum":14536976,"timestamp":"2024-06-01T22:42:10.079413Z"}]}
{"channel":"book","type":"update","data":[{"symbol":"BTC/AUD","bids":[],"asks":[{"price":101937.4,"qty":0.05267583}],"checksum":926061119,"timestamp":"2024-06-01T22:42:10.079656Z"}]}
{"channel":"book","type":"update","data":[{"symbol":"BTC/AUD","bids":[],"asks":[{"price":101937.5,"qty":0.00000000},{"price":101974.2,"qty":0.00135100}],"checksum":2925208061,"timestamp":"2024-06-01T22:42:10.179379Z"}]}
{"channel":"book","type":"update","data":[{"symbol":"BTC/AUD","bids":[{"price":101832.4,"qty":0.02930000}],"asks":[],"checksum":415755305,"timestamp":"2024-06-01T22:42:10.588809Z"}]}
{"channel":"book","type":"update","data":[{"symbol":"BTC/AUD","bids":[],"asks":[{"price":101937.4,"qty":0.02953391},{"price":101937.2,"qty":0.02314192}],"checksum":806845541,"timestamp":"2024-06-01T22:42:10.637790Z"}]}
{"channel":"book","type":"update","data":[{"symbol":"BTC/AUD","bids":[],"asks":[{"price":101937.1,"qty":0.04717373}],"checksum":3491168163,"timestamp":"2024-06-01T22:42:10.642824Z"}]}
{"channel":"book","type":"update","data":[{"symbol":"BTC/AUD","bids":[],"asks":[{"price":101937.3,"qty":0.00000000},{"price":101971.9,"qty":0.00564000}],"checksum":1866582799,"timestamp":"2024-06-01T22:42:10.678564Z"}]}
{"channel":"book","type":"update","data":[{"symbol":"BTC/AUD","bids":[],"asks":[{"price":101970.1,"qty":0.00000000},{"price":101974.2,"qty":0.00135100}],"checksum":1155633616,"timestamp":"2024-06-01T22:42:11.045094Z"}]}
{"channel":"book","type":"update","data":[{"symbol":"BTC/AUD","bids":[],"asks":[{"price":101965.3,"qty":0.05000000}],"checksum":816034522,"timestamp":"2024-06-01T22:42:11.139552Z"}]}
{"channel":"book","type":"update","data":[{"symbol":"BTC/AUD","bids":[{"price":101877.6,"qty":0.00000000},{"price":101832.3,"qty":0.02256150},{"price":101878.9,"qty":0.05324096}],"asks":[],"checksum":3063977886,"timestamp":"2024-06-01T22:42:11.189788Z"}]}
{"channel":"book","type":"update","data":[{"symbol":"BTC/AUD","bids":[],"asks":[{"price":101937.2,"qty":0.00000000},{"price":101974.2,"qty":0.00135100},{"price":101937.0,"qty":0.02314180}],"checksum":1076041524,"timestamp":"2024-06-01T22:42:11.189823Z"}]}
{"channel":"book","type":"update","data":[{"symbol":"BTC/AUD","bids":[{"price":101832.4,"qty":0.00000000},{"price":101832.3,"qty":0.02256150}],"asks":[],"checksum":4139768544,"timestamp":"2024-06-01T22:42:11.518781Z"}]}
{"channel":"book","type":"update","data":[{"symbol":"BTC/AUD","bids":[{"price":101832.3,"qty":0.00000000},{"price":101832.1,"qty":0.05665146}],"asks":[],"checksum":1338105935,"timestamp":"2024-06-01T22:42:11.532760Z"}]}
{"channel":"book","type":"update","data":[{"symbol":"BTC/AUD","bids":[],"asks":[{"price":101965.3,"qty":0.00000000},{"price":101974.2,"qty":0.00135100}],"checksum":4154896954,"timestamp":"2024-06-01T22:42:11.539460Z"}]}
{"channel":"book","type":"update","data":[{"symbol":"BTC/AUD","bids":[],"asks":[{"price":101937.9,"qty":0.00000000},{"price":102003.7,"qty":0.02930000}],"checksum":3851345954,"timestamp":"2024-06-01T22:42:11.665782Z"}]}
{"channel":"book","type":"update","data":[{"symbol":"BTC/AUD","bids":[],"asks":[{"price":101965.5,"qty":0.00000000},{"price":102003.8,"qty":0.00551000}],"checksum":2080412448,"timestamp":"2024-06-01T22:42:11.665966Z"}]}
{"channel":"book","type":"update","data":[{"symbol":"BTC/AUD","bids":[],"asks":[{"price":101936.9,"qty":0.00029534}],"checksum":3963473387,"timestamp":"2024-06-01T22:42:11.670601Z"}]}
{"channel":"book","type":"update","data":[{"symbol":"BTC/AUD","bids":[],"asks":[{"price":101965.2,"qty":0.00253949}],"checksum":2695399474,"timestamp":"2024-06-01T22:42:11.670748Z"}]}
{"channel":"book","type":"update","data":[{"symbol":"BTC/AUD","bids":[],"asks":[{"price":101936.9,"qty":0.04746907}],"checksum":3456823699,"timestamp":"2024-06-01T22:42:11.671377Z"}]}
{"channel":"book","type":"update","data":[{"symbol":"BTC/AUD","bids":[],"asks":[{"price":101937.1,"qty":0.00000000},{"price":102003.7,"qty":0.02930000}],"checksum":2971837531,"timestamp":"2024-06-01T22:42:11.679551Z"}]}
{"channel":"book","type":"update","data":[{"symbol":"BTC/AUD","bids":[],"asks":[{"price":101937.0,"qty":0.00000000},{"price":102003.8,"qty":0.00551000},{"price":101936.8,"qty":0.02314181}],"checksum":800852592,"timestamp":"2024-06-01T22:42:11.725949Z"}]}
{"channel":"book","type":"update","data":[{"symbol":"BTC/AUD","bids":[],"asks":[{"price":101936.7,"qty":0.04717373}],"checksum":128511794,"timestamp":"2024-06-01T22:42:12.179039Z"}]}
{"channel":"book","type":"update","data":[{"symbol":"BTC/AUD","bids":[],"asks":[{"price":101936.9,"qty":0.00029534}],"checksum":859880083,"timestamp":"2024-06-01T22:42:12.183412Z"}]}
{"channel":"book","type":"update","data":[{"symbol":"BTC/AUD","bids":[],"asks":[{"price":101936.8,"qty":0.00000000},{"price":102003.7,"qty":0.02930000},{"price":101936.6,"qty":0.02314181}],"checksum":2119899135,"timestamp":"2024-06-01T22:42:12.300737Z"}]}
{"channel":"book","type":"update","data":[{"symbol":"BTC/AUD","bids":[{"price":101832.2,"qty":0.02931000}],"asks":[],"checksum":258641510,"timestamp":"2024-06-01T22:42:12.368295Z"}]}
{"channel":"book","type":"update","data":[{"symbol":"BTC/AUD","bids":[{"price":101878.8,"qty":0.00000000},{"price":101821.1,"qty":0.05056249}],"asks":[],"checksum":3359619341,"timestamp":"2024-06-01T22:42:12.696862Z"}]}
{"channel":"book","type":"update","data":[{"symbol":"BTC/AUD","bids":[{"price":101821.2,"qty":0.05665146}],"asks":[],"checksum":1459956485,"timestamp":"2024-06-01T22:42:12.698092Z"}]}
{"channel":"book","type":"update","data":[{"symbol":"BTC/AUD","bids":[{"price":101879.0,"qty":0.02953391}],"asks":[],"checksum":2451430420,"timestamp":"2024-06-01T22:42:12.698114Z"}]}
{"channel":"book","type":"update","data":[{"symbol":"BTC/AUD","bids":[],"asks":[{"price":101965.4,"qty":0.00000000},{"price":102003.7,"qty":0.02930000}],"checksum":3939184235,"timestamp":"2024-06-01T22:42:12.782447Z"}]}
{"channel":"book","type":"update","data":[{"symbol":"BTC/AUD","bids":[],"asks":[{"price":101937.4,"qty":0.00000000},{"price":102003.8,"qty":0.00551000}],"checksum":4273918098,"timestamp":"2024-06-01T22:42:12.782558Z"}]}
{"channel":"book","type":"update","data":[{"symbol":"BTC/AUD","bids":[],"asks":[{"price":101965.1,"qty":0.18117270}],"checksum":3444337384,"timestamp":"2024-06-01T22:42:12.787113Z"}]}
{"channel":"book","type":"update","data":[{"symbol":"BTC/AUD","bids":[],"asks":[{"price":101965.5,"qty":0.41946222}],"checksum":1327096934,"timestamp":"2024-06-01T22:42:12.787290Z"}]}
{"channel":"book","type":"update","data":[{"symbol":"BTC/AUD","bids":[{"price":101879.1,"qty":0.00272197}],"asks":[],"checksum":2264456361,"timestamp":"2024-06-01T22:42:12.793273Z"}]}
{"channel":"book","type":"update","data":[{"symbol":"BTC/AUD","bids":[{"price":101878.9,"qty":0.00000000},{"price":101832.2,"qty":0.02931000},{"price":101879.1,"qty":0.05596189}],"asks":[],"checksum":2848460879,"timestamp":"2024-06-01T22:42:12.831262Z"}]}
{"channel":"book","type":"update","data":[{"symbol":"BTC/AUD","bids":[],"asks":[{"price":101971.8,"qty":0.02930000}],"checksum":1943486264,"timestamp":"2024-06-01T22:42:13.003261Z"}]}
{"channel":"book","type":"update","data":[{"symbol":"BTC/AUD","bids":[{"price":101832.2,"qty":0.00000000},{"price":101821.2,"qty":0.05665146}],"asks":[],"checksum":1512502969,"timestamp":"2024-06-01T22:42:13.015674Z"}]}
{"channel":"book","type":"update","data":[{"symbol":"BTC/AUD","bids":[],"asks":[{"price":101936.5,"qty":0.04717373}],"checksum":3010873357,"timestamp":"2024-06-01T22:42:13.179026Z"}]}
{"channel":"book","type":"update","data":[{"symbol":"BTC/AUD","bids":[],"asks":[{"price":101936.7,"qty":0.00000000},{"price":101971.9,"qty":0.00564000}],"checksum":3667852400,"timestamp":"2024-06-01T22:42:13.183324Z"}]}
{"channel":"book","type":"update","data":[{"symbol":"BTC/AUD","bids":[],"asks":[{"price":101971.7,"qty":0.05000000}],"checksum":427991977,"timestamp":"2024-06-01T22:42:13.212951Z"}]}
{"channel":"book","type":"update","data":[{"symbol":"BTC/AUD","bids":[],"asks":[{"price":101936.6,"qty":0.00000000},{"price":101971.9,"qty":0.00564000},{"price":101936.4,"qty":0.02314021}],"checksum":2704286871,"timestamp":"2024-06-01T22:42:13.386431Z"}]}
{"channel":"book","type":"update","data":[{"symbol":"BTC/AUD","bids":[],"asks":[{"price":101936.3,"qty":0.04717373}],"checksum":3445097577,"timestamp":"2024-06-01T22:42:13.391609Z"}]}
{"channel":"book","type":"update","data":[{"symbol":"BTC/AUD","bids":[],"asks":[{"price":101971.6,"qty":0.02930000}],"checksum":1715816628,"timestamp":"2024-06-01T22:42:13.542587Z"}]}
{"channel":"book","type":"update","data":[{"symbol":"BTC/AUD","bids":[],"asks":[{"price":101936.5,"qty":0.00000000},{"price":101971.7,"qty":0.05000000}],"checksum":4002436157,"timestamp":"2024-06-01T22:42:13.682548Z"}]}
{"channel":"book","type":"update","data":[{"symbol":"BTC/AUD","bids":[],"asks":[{"price":101936.4,"qty":0.00000000},{"price":101971.9,"qty":0.00564000},{"price":101936.2,"qty":0.02314021}],"checksum":2841937100,"timestamp":"2024-06-01T22:42:13.897785Z"}]}
{"channel":"book","type":"update","data":[{"symbol":"BTC/AUD","bids":[],"asks":[{"price":101965.6,"qty":0.00000000},{"price":101971.9,"qty":0.00564000}],"checksum":3429375718,"timestamp":"2024-06-01T22:42:13.900977Z"}]}
{"channel":"book","type":"update","data":[{"symbol":"BTC/AUD","bids":[],"asks":[{"price":101965.7,"qty":0.63077830}],"checksum":2723242469,"timestamp":"2024-06-01T22:42:13.904230Z"}]}
{"channel":"book","type":"update","data":[{"symbol":"BTC/AUD","bids":[],"asks":[{"price":101936.1,"qty":0.04717373}],"checksum":3155240049,"timestamp":"2024-06-01T22:42:14.177837Z"}]}
{"channel":"book","type":"update","data":[{"symbol":"BTC/AUD","bids":[],"asks":[{"price":101936.3,"qty":0.00000000},{"price":101971.7,"qty":0.05000000}],"checksum":782623536,"timestamp":"2024-06-01T22:42:14.182400Z"}]}
{"channel":"book","type":"update","data":[{"symbol":"BTC/AUD","bids":[],"asks":[{"price":101936.9,"qty":0.00000000},{"price":101971.9,"qty":0.00564000}],"checksum":4048484270,"timestamp":"2024-06-01T22:42:14.315476Z"}]}
{"channel":"book","type":"update","data":[{"symbol":"BTC/AUD","bids":[],"asks":[{"price":101965.2,"qty":0.00000000},{"price":101974.2,"qty":0.00135100}],"checksum":1488698120,"timestamp":"2024-06-01T22:42:14.315582Z"}]}
{"channel":"book","type":"update","data":[{"symbol":"BTC/AUD","bids":[],"asks":[{"price":101965.0,"qty":0.00279880}],"checksum":1505857217,"timestamp":"2024-06-01T22:42:14.317924Z"}]}
{"channel":"book","type":"update","data":[{"symbol":"BTC/AUD","bids":[{"price":101879.1,"qty":0.00272197},{"price":101879.2,"qty":0.05323987}],"asks":[],"checksum":1441836889,"timestamp":"2024-06-01T22:42:14.453879Z"}]}
{"channel":"book","type":"update","data":[{"symbol":"BTC/AUD","bids":[],"asks":[{"price":101936.2,"qty":0.00000000},{"price":101974.2,"qty":0.00135100},{"price":101936.0,"qty":0.02314021}],"checksum":2199922741,"timestamp":"2024-06-01T22:42:14.454055Z"}]}
{"channel":"book","type":"update","data":[{"symbol":"BTC/AUD","bids":[],"asks":[{"price":101936.0,"qty":0.00000000},{"price":101974.2,"qty":0.00135100},{"price":101936.0,"qty":0.02097629}],"checksum":3539748220,"timestamp":"2024-06-01T22:42:15.010066Z"}]}
{"channel":"book","type":"update","data":[{"symbol":"BTC/AUD","bids":[],"asks":[{"price":101935.9,"qty":0.04717373}],"checksum":3107750681,"timestamp":"2024-06-01T22:42:15.015805Z"}]}
{"channel":"book","type":"update","data":[{"symbol":"BTC/AUD","bids":[],"asks":[{"price":101936.1,"qty":0.00000000},{"price":101971.9,"qty":0.00564000}],"checksum":2326289562,"timestamp":"2024-06-01T22:42:15.178793Z"}]}
{"channel":"book","type":"update","data":[{"symbol":"BTC/AUD","bids":[],"asks":[{"price":101965.1,"qty":0.00000000},{"price":101974.2,"qty":0.00135100}],"checksum":3169148374,"timestamp":"2024-06-01T22:42:15.295041Z"}]}
{"channel":"book","type":"update","data":[{"symbol":"BTC/AUD","bids":[],"asks":[{"price":101965.5,"qty":0.00000000},{"price":102003.8,"qty":0.00551000}],"checksum":1883709239,"timestamp":"2024-06-01T22:42:15.295183Z"}]}
{"channel":"book","type":"update","data":[{"symbol":"BTC/AUD","bids":[],"asks":[{"price":101965.6,"qty":0.46278759}],"checksum":3435537256,"timestamp":"2024-06-01T22:42:15.300647Z"}]}
{"channel":"book","type":"update","data":[{"symbol":"BTC/AUD","bids":[],"asks":[{"price":101964.9,"qty":0.02953391}],"checksum":3630562462,"timestamp":"2024-06-01T22:42:15.300671Z"}]}
{"channel":"book","type":"update","data":[{"symbol":"BTC/AUD","bids":[{"price":101863.7,"qty":0.00000000},{"price":101821.3,"qty":0.02931000}],"asks":[],"checksum":4249403814,"timestamp":"2024-06-01T22:42:15.503273Z"}]}
{"channel":"book","type":"update","data":[{"symbol":"BTC/AUD","bids":[{"price":101879.0,"qty":0.00000000},{"price":101821.1,"qty":0.05056249}],"asks":[],"checksum":3139306335,"timestamp":"2024-06-01T22:42:15.503284Z"}]}
{"channel":"book","type":"update","data":[{"symbol":"BTC/AUD","bids":[{"price":101863.7,"qty":0.08715965}],"asks":[],"checksum":1001538855,"timestamp":"2024-06-01T22:42:15.504548Z"}]}
{"channel":"book","type":"update","data":[{"symbol":"BTC/AUD","bids":[{"price":101821.4,"qty":0.11424906}],"asks":[],"checksum":3147743175,"timestamp":"2024-06-01T22:42:15.504644Z"}]}
{"channel":"book","type":"update","data":[{"symbol":"BTC/AUD","bids":[{"price":101879.3,"qty":0.02953391}],"asks":[],"checksum":824529332,"timestamp":"2024-06-01T22:42:15.504666Z"}]}
{"channel":"book","type":"update","data":[{"symbol":"BTC/AUD","bids":[{"price":101879.2,"qty":0.00000000},{"price":101821.4,"qty":0.11424906},{"price":101879.4,"qty":0.05323959}],"asks":[],"checksum":2041312227,"timestamp":"2024-06-01T22:42:15.577028Z"}]}
{"channel":"book","type":"update","data":[{"symbol":"BTC/AUD","bids":[{"price":101875.9,"qty":0.00000000},{"price":101821.5,"qty":0.02931000},{"price":101883.0,"qty":0.00135100}],"asks":[],"checksum":2546807990,"timestamp":"2024-06-01T22:42:15.781384Z"}]}
{"channel":"book","type":"update","data":[{"symbol":"BTC/AUD","bids":[{"price":101879.4,"qty":0.00000000},{"price":101821.5,"qty":0.02931000},{"price":101883.1,"qty":0.05323766}],"asks":[],"checksum":3523964713,"timestamp":"2024-06-01T22:42:16.108853Z"}]}
{"channel":"book","type":"update","data":[{"symbol":"BTC/AUD","bids":[],"asks":[{"price":101936.0,"qty":0.00000000},{"price":101974.2,"qty":0.00135100},{"price":101935.8,"qty":0.02097629}],"checksum":3607583261,"timestamp":"2024-06-01T22:42:16.108958Z"}]}
{"channel":"book","type":"update","data":[{"symbol":"BTC/AUD","bids":[],"asks":[{"price":101935.7,"qty":0.04717373}],"checksum":1118818951,"timestamp":"2024-06-01T22:42:16.114371Z"}]}
{"channel":"book","type":"update","data":[{"symbol":"BTC/AUD","bids":[],"asks":[{"price":101935.9,"qty":0.00000000},{"price":101971.9,"qty":0.00564000}],"checksum":1232330991,"timestamp":"2024-06-01T22:42:16.178105Z"}]}
{"channel":"book","type":"update","data":[{"symbol":"BTC/AUD","bids":[],"asks":[{"price":101971.7,"qty":0.00000000},{"price":101974.2,"qty":0.00135100}],"checksum":1176920030,"timestamp":"2024-06-01T22:42:16.484563Z"}]}
{"channel":"book","type":"update","data":[{"symbol":"BTC/AUD","bids":[],"asks":[{"price":101971.6,"qty":0.00000000},{"price":102003.8,"qty":0.00551000},{"price":101971.8,"qty":0.02930000}],"checksum":4147878322,"timestamp":"2024-06-01T22:42:16.487213Z"}]}
{"channel":"book","type":"update","data":[{"symbol":"BTC/AUD","bids":[],"asks":[{"price":101971.5,"qty":0.05000000}],"checksum":1734653732,"timestamp":"2024-06-01T22:42:16.515405Z"}]}
{"channel":"book","type":"update","data":[{"symbol":"BTC/AUD","bids":[],"asks":[{"price":101935.8,"qty":0.00000000},{"price":101974.2,"qty":0.00135100},{"price":101935.6,"qty":0.02097629}],"checksum":700643867,"timestamp":"2024-06-01T22:42:16.706748Z"}]}
{"channel":"book","type":"update","data":[{"symbol":"BTC/AUD","bids":[],"asks":[{"price":101935.5,"qty":0.04717373}],"checksum":3073573082,"timestamp":"2024-06-01T22:42:16.712966Z"}]}
{"channel":"book","type":"update","data":[{"symbol":"BTC/AUD","bids":[],"asks":[{"price":101971.8,"qty":0.00000000},{"price":101971.9,"qty":0.00564000},{"price":101971.4,"qty":0.02930000}],"checksum":874773835,"timestamp":"2024-06-01T22:42:17.031882Z"}]}
{"channel":"book","type":"update","data":[{"symbol":"BTC/AUD","bids":[],"asks":[{"price":101965.0,"qty":0.00000000},{"price":101971.9,"qty":0.00564000}],"checksum":1615240165,"timestamp":"2024-06-01T22:42:17.035769Z"}]}
