{"channel":"book","type":"snapshot","data":[{"symbol":"BTC/EUR","bids":[{"price":62452.1,"qty":0.02274603},{"price":62451.1,"qty":0.00010000},{"price":62449.3,"qty":0.00755492},{"price":62439.0,"qty":0.00060274},{"price":62438.9,"qty":0.12491725},{"price":62436.8,"qty":0.35892992},{"price":62436.7,"qty":1.47630118},{"price":62434.9,"qty":0.63765088},{"price":62434.8,"qty":1.47634382},{"price":62432.1,"qty":3.59760119}],"asks":[{"price":62452.2,"qty":8.23031927},{"price":62453.1,"qty":0.00853300},{"price":62453.2,"qty":0.00010000},{"price":62455.1,"qty":1.10726439},{"price":62456.3,"qty":0.12448546},{"price":62456.9,"qty":0.08006129},{"price":62457.4,"qty":0.12677357},{"price":62457.5,"qty":0.06426000},{"price":62460.5,"qty":0.03947498},{"price":62465.2,"qty":0.83105175}],"checksum":550569048}]}
{"channel":"book","type":"update","data":[{"symbol":"BTC/EUR","bids":[{"price":62434.9,"qty":0.00000000},{"price":62432.0,"qty":0.11001120}],"asks":[],"checksum":3125387220,"timestamp":"2024-06-01T22:42:01.689530Z"}]}
{"channel":"book","type":"update","data":[{"symbol":"BTC/EUR","bids":[{"price":62436.8,"qty":0.00000000},{"price":62431.8,"qty":1.47641606}],"asks":[],"checksum":3197260178,"timestamp":"2024-06-01T22:42:01.689565Z"}]}
{"channel":"book","type":"update","data":[{"symbol":"BTC/EUR","bids":[{"price":62432.1,"qty":0.00000000},{"price":62429.6,"qty":1.47646878}],"asks":[],"checksum":2767652713,"timestamp":"2024-06-01T22:42:01.689582Z"}]}
{"channel":"book","type":"update","data":[{"symbol":"BTC/EUR","bids":[{"price":62432.0,"qty":0.10263774}],"asks":[],"checksum":1571076588,"timestamp":"2024-06-01T22:42:01.693914Z"}]}
{"channel":"book","type":"update","data":[{"symbol":"BTC/EUR","bids":[{"price":62434.9,"qty":0.68832742}],"asks":[],"checksum":2750170041,"timestamp":"2024-06-01T22:42:01.695001Z"}]}
{"channel":"book","type":"update","data":[{"symbol":"BTC/EUR","bids":[{"price":62432.1,"qty":3.49298185}],"asks":[],"checksum":3934799831,"timestamp":"2024-06-01T22:42:01.695095Z"}]}
{"channel":"book","type":"update","data":[{"symbol":"BTC/EUR","bids":[{"price":62436.8,"qty":0.40960646}],"asks":[],"checksum":3762186487,"timestamp":"2024-06-01T22:42:01.695163Z"}]}
{"channel":"book","type":"update","data":[{"symbol":"BTC/EUR","bids":[{"price":62432.2,"qty":0.00653082}],"asks":[],"checksum":805147992,"timestamp":"2024-06-01T22:42:01.698986Z"}]}
{"channel":"book","type":"update","data":[{"symbol":"BTC/EUR","bids":[{"price":62439.0,"qty":0.00000000},{"price":62432.1,"qty":3.49298185},{"price":62436.9,"qty":0.00060275}],"asks":[],"checksum":2556986098,"timestamp":"2024-06-01T22:42:01.757443Z"}]}
{"channel":"book","type":"update","data":[{"symbol":"BTC/EUR","bids":[{"price":62436.9,"qty":0.00000000},{"price":62432.1,"qty":3.49298185},{"price":62439.0,"qty":0.00060273}],"asks":[],"checksum":494437087,"timestamp":"2024-06-01T22:42:01.872110Z"}]}
{"channel":"book","type":"update","data":[{"symbol":"BTC/EUR","bids":[{"price":62439.0,"qty":0.00000000},{"price":62432.1,"qty":3.49298185},{"price":62436.9,"qty":0.00060275}],"asks":[],"checksum":2556986098,"timestamp":"2024-06-01T22:42:01.964815Z"}]}
{"channel":"book","type":"update","data":[{"symbol":"BTC/EUR","bids":[{"price":62436.9,"qty":0.00000000},{"price":62432.1,"qty":3.49298185},{"price":62439.0,"qty":0.00060273}],"asks":[],"checksum":494437087,"timestamp":"2024-06-01T22:42:02.035706Z"}]}
{"channel":"book","type":"update","data":[{"symbol":"BTC/EUR","bids":[],"asks":[{"price":62465.2,"qty":0.00000000},{"price":62465.3,"qty":2.21344117}],"checksum":4170479944,"timestamp":"2024-06-01T22:42:02.287998Z"}]}
{"channel":"book","type":"update","data":[{"symbol":"BTC/EUR","bids":[],"asks":[{"price":62465.2,"qty":1.04767859}],"checksum":3278776169,"timestamp":"2024-06-01T22:42:02.292415Z"}]}
{"channel":"book","type":"update","data":[{"symbol":"BTC/EUR","bids":[{"price":62452.1,"qty":0.02185343}],"asks":[],"checksum":6844369,"timestamp":"2024-06-01T22:42:02.877666Z"}]}
{"channel":"book","type":"update","data":[{"symbol":"BTC/EUR","bids":[{"price":62452.1,"qty":0.01848793}],"asks":[],"checksum":53933429,"timestamp":"2024-06-01T22:42:02.978752Z"}]}
{"channel":"book","type":"update","data":[{"symbol":"BTC/EUR","bids":[{"price":62434.9,"qty":0.00000000},{"price":62431.8,"qty":1.47641606}],"asks":[],"checksum":2981454524,"timestamp":"2024-06-01T22:42:03.802335Z"}]}
{"channel":"book","type":"update","data":[{"symbol":"BTC/EUR","bids":[{"price":62436.8,"qty":0.00000000},{"price":62430.3,"qty":0.10264053}],"asks":[],"checksum":2463386050,"timestamp":"2024-06-01T22:42:03.802363Z"}]}
{"channel":"book","type":"update","data":[{"symbol":"BTC/EUR","bids":[{"price":62434.9,"qty":0.38426953}],"asks":[],"checksum":3972942208,"timestamp":"2024-06-01T22:42:03.807535Z"}]}
{"channel":"book","type":"update","data":[{"symbol":"BTC/EUR","bids":[{"price":62436.8,"qty":0.18156267}],"asks":[],"checksum":3395575533,"timestamp":"2024-06-01T22:42:03.807563Z"}]}
{"channel":"book","type":"update","data":[{"symbol":"BTC/EUR","bids":[{"price":62436.7,"qty":0.00000000},{"price":62431.9,"qty":3.97068639}],"asks":[],"checksum":2302056753,"timestamp":"2024-06-01T22:42:03.879474Z"}]}
{"channel":"book","type":"update","data":[{"symbol":"BTC/EUR","bids":[{"price":62434.4,"qty":1.47635332}],"asks":[],"checksum":1983453840,"timestamp":"2024-06-01T22:42:03.886876Z"}]}
{"channel":"book","type":"update","data":[{"symbol":"BTC/EUR","bids":[{"price":62432.2,"qty":0.00000000},{"price":62431.9,"qty":3.97068639}],"asks":[],"checksum":1040896189,"timestamp":"2024-06-01T22:42:03.951244Z"}]}
{"channel":"book","type":"update","data":[{"symbol":"BTC/EUR","bids":[{"price":62436.8,"qty":0.00000000},{"price":62431.8,"qty":1.47641606}],"asks":[],"checksum":38313551,"timestamp":"2024-06-01T22:42:04.016509Z"}]}
{"channel":"book","type":"update","data":[{"symbol":"BTC/EUR","bids":[{"price":62439.0,"qty":0.00000000},{"price":62431.3,"qty":0.10263889},{"price":62435.0,"qty":0.00060261}],"asks":[],"checksum":92418738,"timestamp":"2024-06-01T22:42:04.140087Z"}]}
{"channel":"book","type":"update","data":[{"symbol":"BTC/EUR","bids":[{"price":62435.0,"qty":0.00000000},{"price":62431.3,"qty":0.10263889},{"price":62439.0,"qty":0.00060258}],"asks":[],"checksum":611459242,"timestamp":"2024-06-01T22:42:04.200066Z"}]}
{"channel":"book","type":"update","data":[{"symbol":"BTC/EUR","bids":[{"price":62432.2,"qty":0.00462889}],"asks":[],"checksum":1784536242,"timestamp":"2024-06-01T22:42:04.270988Z"}]}
{"channel":"book","type":"update","data":[{"symbol":"BTC/EUR","bids":[{"price":62439.0,"qty":0.00000000},{"price":62431.8,"qty":1.47641606},{"price":62435.0,"qty":0.00060261}],"asks":[],"checksum":1382065275,"timestamp":"2024-06-01T22:42:04.294267Z"}]}
{"channel":"book","type":"update","data":[{"symbol":"BTC/EUR","bids":[{"price":62435.0,"qty":0.00000000},{"price":62431.8,"qty":1.47641606},{"price":62435.1,"qty":0.00060261}],"asks":[],"checksum":2475686753,"timestamp":"2024-06-01T22:42:04.364885Z"}]}
{"channel":"book","type":"update","data":[{"symbol":"BTC/EUR","bids":[{"price":62435.1,"qty":0.00000000},{"price":62431.8,"qty":1.47641606},{"price":62435.0,"qty":0.00060261}],"asks":[],"checksum":1382065275,"timestamp":"2024-06-01T22:42:04.432289Z"}]}
{"channel":"book","type":"update","data":[{"symbol":"BTC/EUR","bids":[{"price":62432.2,"qty":0.00000000},{"price":62431.8,"qty":1.47641606}],"asks":[],"checksum":92418738,"timestamp":"2024-06-01T22:42:04.474926Z"}]}
{"channel":"book","type":"update","data":[{"symbol":"BTC/EUR","bids":[{"price":62435.0,"qty":0.00000000},{"price":62431.3,"qty":0.10263889},{"price":62435.1,"qty":0.00060261}],"asks":[],"checksum":430287527,"timestamp":"2024-06-01T22:42:04.499086Z"}]}
{"channel":"book","type":"update","data":[{"symbol":"BTC/EUR","bids":[{"price":62435.1,"qty":0.00000000},{"price":62431.3,"qty":0.10263889},{"price":62435.0,"qty":0.00060261}],"asks":[],"checksum":92418738,"timestamp":"2024-06-01T22:42:04.567315Z"}]}
{"channel":"book","type":"update","data":[{"symbol":"BTC/EUR","bids":[],"asks":[{"price":62465.2,"qty":0.00000000},{"price":62465.3,"qty":2.21344117}],"checksum":611719488,"timestamp":"2024-06-01T22:42:04.914688Z"}]}
{"channel":"book","type":"update","data":[{"symbol":"BTC/EUR","bids":[],"asks":[{"price":62465.2,"qty":1.26430690}],"checksum":3245738828,"timestamp":"2024-06-01T22:42:04.920362Z"}]}
{"channel":"book","type":"update","data":[{"symbol":"BTC/EUR","bids":[{"price":62435.0,"qty":0.00000000},{"price":62431.3,"qty":0.10263889},{"price":62439.0,"qty":0.00060257}],"asks":[],"checksum":2420342639,"timestamp":"2024-06-01T22:42:05.166359Z"}]}
{"channel":"book","type":"update","data":[{"symbol":"BTC/EUR","bids":[{"price":62439.0,"qty":0.00000000},{"price":62431.3,"qty":0.10263889},{"price":62439.1,"qty":0.00060257}],"asks":[],"checksum":4101577141,"timestamp":"2024-06-01T22:42:05.222747Z"}]}
{"channel":"book","type":"update","data":[{"symbol":"BTC/EUR","bids":[{"price":62439.1,"qty":0.00000000},{"price":62431.3,"qty":0.10263889},{"price":62439.0,"qty":0.00060257}],"asks":[],"checksum":2420342639,"timestamp":"2024-06-01T22:42:05.269956Z"}]}
{"channel":"book","type":"update","data":[{"symbol":"BTC/EUR","bids":[],"asks":[{"price":62457.4,"qty":0.00000000},{"price":62465.3,"qty":2.21344117}],"checksum":3438869368,"timestamp":"2024-06-01T22:42:05.763832Z"}]}
{"channel":"book","type":"update","data":[{"symbol":"BTC/EUR","bids":[{"price":62434.8,"qty":0.00000000},{"price":62431.3,"qty":0.10263889}],"asks":[],"checksum":2174379408,"timestamp":"2024-06-01T22:42:05.768577Z"}]}
{"channel":"book","type":"update","data":[{"symbol":"BTC/EUR","bids":[{"price":62431.3,"qty":0.00000000},{"price":62429.6,"qty":1.47646878}],"asks":[],"checksum":3620708268,"timestamp":"2024-06-01T22:42:05.794360Z"}]}
{"channel":"book","type":"update","data":[{"symbol":"BTC/EUR","bids":[],"asks":[{"price":62465.1,"qty":0.13107751}],"checksum":1215348147,"timestamp":"2024-06-01T22:42:05.798525Z"}]}
{"channel":"book","type":"update","data":[{"symbol":"BTC/EUR","bids":[{"price":62434.9,"qty":0.00000000},{"price":62426.2,"qty":1.47654819}],"asks":[],"checksum":2603901590,"timestamp":"2024-06-01T22:42:05.806432Z"}]}
{"channel":"book","type":"update","data":[{"symbol":"BTC/EUR","bids":[{"price":62431.9,"qty":0.00000000},{"price":62425.9,"qty":0.00478567}],"asks":[],"checksum":3884672878,"timestamp":"2024-06-01T22:42:05.806604Z"}]}
{"channel":"book","type":"update","data":[{"symbol":"BTC/EUR","bids":[{"price":62434.4,"qty":0.00000000},{"price":62425.2,"qty":0.03947498}],"asks":[],"checksum":4052848158,"timestamp":"2024-06-01T22:42:05.852034Z"}]}
{"channel":"book","type":"update","data":[{"symbol":"BTC/EUR","bids":[{"price":62431.8,"qty":2.95283246}],"asks":[],"checksum":1013036750,"timestamp":"2024-06-01T22:42:05.856762Z"}]}
{"channel":"book","type":"update","data":[{"symbol":"BTC/EUR","bids":[{"price":62439.0,"qty":0.00000000},{"price":62424.1,"qty":0.04003064},{"price":62431.9,"qty":0.00060264}],"asks":[],"checksum":625130635,"timestamp":"2024-06-01T22:42:05.868568Z"}]}
{"channel":"book","type":"update","data":[{"symbol":"BTC/EUR","bids":[],"asks":[{"price":62452.2,"qty":8.26979425}],"checksum":886808212,"timestamp":"2024-06-01T22:42:05.873000Z"}]}
{"channel":"book","type":"update","data":[{"symbol":"BTC/EUR","bids":[],"asks":[{"price":62465.1,"qty":0.00000000},{"price":62465.3,"qty":2.21344117}],"checksum":1371811683,"timestamp":"2024-06-01T22:42:05.911271Z"}]}
{"channel":"book","type":"update","data":[{"symbol":"BTC/EUR","bids":[{"price":62429.4,"qty":0.10264201}],"asks":[],"checksum":952345943,"timestamp":"2024-06-01T22:42:05.917558Z"}]}
{"channel":"book","type":"update","data":[{"symbol":"BTC/EUR","bids":[{"price":62431.9,"qty":0.00000000},{"price":62425.2,"qty":0.03947498},{"price":62426.3,"qty":0.00060269}],"asks":[],"checksum":3209069542,"timestamp":"2024-06-01T22:42:05.933333Z"}]}
{"channel":"book","type":"update","data":[{"symbol":"BTC/EUR","bids":[],"asks":[{"price":62460.5,"qty":0.00000000},{"price":62466.7,"qty":0.04480000}],"checksum":1009781021,"timestamp":"2024-06-01T22:42:05.937337Z"}]}
{"channel":"book","type":"update","data":[{"symbol":"BTC/EUR","bids":[],"asks":[{"price":62455.0,"qty":0.13107751}],"checksum":2946835461,"timestamp":"2024-06-01T22:42:06.047417Z"}]}
{"channel":"book","type":"update","data":[{"symbol":"BTC/EUR","bids":[{"price":62426.3,"qty":0.00000000},{"price":62425.2,"qty":0.03947498},{"price":62431.9,"qty":0.00060264}],"asks":[],"checksum":673186484,"timestamp":"2024-06-01T22:42:06.208480Z"}]}
{"channel":"book","type":"update","data":[{"symbol":"BTC/EUR","bids":[{"price":62431.9,"qty":0.00000000},{"price":62425.2,"qty":0.03947498},{"price":62432.0,"qty":0.00060264}],"asks":[],"checksum":2375321109,"timestamp":"2024-06-01T22:42:06.324634Z"}]}
{"channel":"book","type":"update","data":[{"symbol":"BTC/EUR","bids":[{"price":62432.0,"qty":0.00000000},{"price":62425.2,"qty":0.03947498},{"price":62431.9,"qty":0.00060275}],"asks":[],"checksum":1910967598,"timestamp":"2024-06-01T22:42:06.379425Z"}]}
{"channel":"book","type":"update","data":[{"symbol":"BTC/EUR","bids":[{"price":62429.4,"qty":0.00000000},{"price":62425.2,"qty":0.03947498}],"asks":[],"checksum":472587141,"timestamp":"2024-06-01T22:42:07.351632Z"}]}
{"channel":"book","type":"update","data":[{"symbol":"BTC/EUR","bids":[{"price":62431.9,"qty":0.00000000},{"price":62424.1,"qty":0.04003064},{"price":62439.0,"qty":0.00060268}],"asks":[],"checksum":1797013452,"timestamp":"2024-06-01T22:42:07.415445Z"}]}
{"channel":"book","type":"update","data":[{"symbol":"BTC/EUR","bids":[{"price":62428.2,"qty":0.10264399}],"asks":[],"checksum":3417584827,"timestamp":"2024-06-01T22:42:07.470442Z"}]}
{"channel":"book","type":"update","data":[{"symbol":"BTC/EUR","bids":[{"price":62439.0,"qty":0.00000000},{"price":62425.2,"qty":0.03947498},{"price":62431.9,"qty":0.00060275}],"asks":[],"checksum":3301178027,"timestamp":"2024-06-01T22:42:07.472428Z"}]}
{"channel":"book","type":"update","data":[{"symbol":"BTC/EUR","bids":[],"asks":[{"price":62465.2,"qty":0.00000000},{"price":62466.7,"qty":0.04480000}],"checksum":3465992144,"timestamp":"2024-06-01T22:42:07.493886Z"}]}
{"channel":"book","type":"update","data":[{"symbol":"BTC/EUR","bids":[],"asks":[{"price":62465.2,"qty":1.24264422}],"checksum":1372546571,"timestamp":"2024-06-01T22:42:07.498810Z"}]}
{"channel":"book","type":"update","data":[{"symbol":"BTC/EUR","bids":[{"price":62431.9,"qty":0.00000000},{"price":62425.2,"qty":0.03947498},{"price":62432.0,"qty":0.00060275}],"asks":[],"checksum":4101759658,"timestamp":"2024-06-01T22:42:07.540726Z"}]}
{"channel":"book","type":"update","data":[{"symbol":"BTC/EUR","bids":[{"price":62432.0,"qty":0.00000000},{"price":62425.2,"qty":0.03947498},{"price":62439.0,"qty":0.00060268}],"asks":[],"checksum":1589159963,"timestamp":"2024-06-01T22:42:07.754301Z"}]}
{"channel":"book","type":"update","data":[{"symbol":"BTC/EUR","bids":[{"price":62431.9,"qty":1.82864152}],"asks":[],"checksum":1785401296,"timestamp":"2024-06-01T22:42:07.954287Z"}]}
{"channel":"book","type":"update","data":[{"symbol":"BTC/EUR","bids":[{"price":62439.0,"qty":0.00000000},{"price":62425.9,"qty":0.00478567},{"price":62432.0,"qty":0.00060275}],"asks":[],"checksum":2785849304,"timestamp":"2024-06-01T22:42:08.008207Z"}]}
{"channel":"book","type":"update","data":[{"symbol":"BTC/EUR","bids":[{"price":62432.0,"qty":0.00000000},{"price":62425.9,"qty":0.00478567},{"price":62439.0,"qty":0.00060272}],"asks":[],"checksum":3591734141,"timestamp":"2024-06-01T22:42:08.494588Z"}]}
{"channel":"book","type":"update","data":[{"symbol":"BTC/EUR","bids":[{"price":62439.0,"qty":0.00000000},{"price":62425.9,"qty":0.00478567},{"price":62432.0,"qty":0.00060278}],"asks":[],"checksum":2465816415,"timestamp":"2024-06-01T22:42:08.550950Z"}]}
{"channel":"book","type":"update","data":[{"symbol":"BTC/EUR","bids":[{"price":62432.0,"qty":0.00000000},{"price":62425.9,"qty":0.00478567},{"price":62439.0,"qty":0.00060272}],"asks":[],"checksum":3591734141,"timestamp":"2024-06-01T22:42:08.784972Z"}]}
{"channel":"book","type":"update","data":[{"symbol":"BTC/EUR","bids":[{"price":62431.8,"qty":1.47641606}],"asks":[],"checksum":1520007357,"timestamp":"2024-06-01T22:42:08.811793Z"}]}
{"channel":"book","type":"update","data":[{"symbol":"BTC/EUR","bids":[{"price":62433.5,"qty":1.47637528}],"asks":[],"checksum":3793222743,"timestamp":"2024-06-01T22:42:08.816529Z"}]}
{"channel":"book","type":"update","data":[{"symbol":"BTC/EUR","bids":[],"asks":[{"price":62456.3,"qty":0.00000000},{"price":62466.7,"qty":0.04480000}],"checksum":3411499752,"timestamp":"2024-06-01T22:42:08.843692Z"}]}
{"channel":"book","type":"update","data":[{"symbol":"BTC/EUR","bids":[{"price":62439.0,"qty":0.00000000},{"price":62426.2,"qty":1.47654819},{"price":62433.6,"qty":0.00060277}],"asks":[],"checksum":3180489787,"timestamp":"2024-06-01T22:42:08.877242Z"}]}
{"channel":"book","type":"update","data":[{"symbol":"BTC/EUR","bids":[{"price":62433.6,"qty":0.00000000},{"price":62426.2,"qty":1.47654819},{"price":62426.3,"qty":0.00060284}],"asks":[],"checksum":487653,"timestamp":"2024-06-01T22:42:08.948265Z"}]}
{"channel":"book","type":"update","data":[{"symbol":"BTC/EUR","bids":[],"asks":[{"price":62453.2,"qty":0.12458546}],"checksum":2914624397,"timestamp":"2024-06-01T22:42:08.967315Z"}]}
{"channel":"book","type":"update","data":[{"symbol":"BTC/EUR","bids":[{"price":62428.2,"qty":0.00000000},{"price":62426.2,"qty":1.47654819}],"asks":[],"checksum":1893885504,"timestamp":"2024-06-01T22:42:08.984417Z"}]}
{"channel":"book","type":"update","data":[{"symbol":"BTC/EUR","bids":[{"price":62426.3,"qty":0.00000000},{"price":62425.9,"qty":0.00478567},{"price":62433.6,"qty":0.00060277}],"asks":[],"checksum":2464002073,"timestamp":"2024-06-01T22:42:09.087901Z"}]}
{"channel":"book","type":"update","data":[{"symbol":"BTC/EUR","bids":[{"price":62429.6,"qty":1.57911046}],"asks":[],"checksum":1078365588,"timestamp":"2024-06-01T22:42:09.106382Z"}]}
{"channel":"book","type":"update","data":[{"symbol":"BTC/EUR","bids":[{"price":62429.6,"qty":1.47646878}],"asks":[],"checksum":2464002073,"timestamp":"2024-06-01T22:42:09.485307Z"}]}
{"channel":"book","type":"update","data":[{"symbol":"BTC/EUR","bids":[{"price":62429.8,"qty":0.10264136}],"asks":[],"checksum":3321772024,"timestamp":"2024-06-01T22:42:09.604315Z"}]}
{"channel":"book","type":"update","data":[{"symbol":"BTC/EUR","bids":[{"price":62431.9,"qty":0.00000000},{"price":62426.2,"qty":1.47654819}],"asks":[],"checksum":3924284730,"timestamp":"2024-06-01T22:42:10.002738Z"}]}
{"channel":"book","type":"update","data":[{"symbol":"BTC/EUR","bids":[{"price":62433.6,"qty":0.46090893}],"asks":[],"checksum":901886439,"timestamp":"2024-06-01T22:42:10.005804Z"}]}
{"channel":"book","type":"update","data":[{"symbol":"BTC/EUR","bids":[{"price":62433.6,"qty":0.46030616},{"price":62433.7,"qty":0.00060277}],"asks":[],"checksum":2312793973,"timestamp":"2024-06-01T22:42:10.062165Z"}]}
{"channel":"book","type":"update","data":[{"symbol":"BTC/EUR","bids":[],"asks":[{"price":62465.2,"qty":0.00000000},{"price":62467.3,"qty":0.00015134}],"checksum":70754140,"timestamp":"2024-06-01T22:42:10.073903Z"}]}
{"channel":"book","type":"update","data":[{"symbol":"BTC/EUR","bids":[],"asks":[{"price":62465.2,"qty":1.30763227}],"checksum":721488364,"timestamp":"2024-06-01T22:42:10.078911Z"}]}
{"channel":"book","type":"update","data":[{"symbol":"BTC/EUR","bids":[{"price":62433.7,"qty":0.00000000},{"price":62426.2,"qty":1.47654819},{"price":62433.8,"qty":0.00060277}],"asks":[],"checksum":835124049,"timestamp":"2024-06-01T22:42:10.406035Z"}]}
{"channel":"book","type":"update","data":[{"symbol":"BTC/EUR","bids":[{"price":62433.8,"qty":0.00000000},{"price":62426.2,"qty":1.47654819},{"price":62433.7,"qty":0.00060277}],"asks":[],"checksum":721488364,"timestamp":"2024-06-01T22:42:10.459695Z"}]}
{"channel":"book","type":"update","data":[{"symbol":"BTC/EUR","bids":[],"asks":[{"price":62455.0,"qty":0.00000000},{"price":62467.3,"qty":0.00015134}],"checksum":3478751339,"timestamp":"2024-06-01T22:42:10.729725Z"}]}
{"channel":"book","type":"update","data":[{"symbol":"BTC/EUR","bids":[],"asks":[{"price":62465.1,"qty":0.12452906}],"checksum":611294666,"timestamp":"2024-06-01T22:42:10.733131Z"}]}
{"channel":"book","type":"update","data":[{"symbol":"BTC/EUR","bids":[{"price":62433.7,"qty":0.00000000},{"price":62426.2,"qty":1.47654819},{"price":62433.8,"qty":0.00060277}],"asks":[],"checksum":1051225975,"timestamp":"2024-06-01T22:42:10.736066Z"}]}
{"channel":"book","type":"update","data":[{"symbol":"BTC/EUR","bids":[{"price":62433.8,"qty":0.00000000},{"price":62426.2,"qty":1.47654819},{"price":62433.7,"qty":0.00060277}],"asks":[],"checksum":611294666,"timestamp":"2024-06-01T22:42:10.801618Z"}]}
{"channel":"book","type":"update","data":[{"symbol":"BTC/EUR","bids":[],"asks":[{"price":62465.1,"qty":0.00000000},{"price":62467.3,"qty":0.00015134}],"checksum":3478751339,"timestamp":"2024-06-01T22:42:11.653926Z"}]}
{"channel":"book","type":"update","data":[{"symbol":"BTC/EUR","bids":[],"asks":[{"price":62465.1,"qty":0.12745597}],"checksum":2221855280,"timestamp":"2024-06-01T22:42:11.827633Z"}]}
{"channel":"book","type":"update","data":[{"symbol":"BTC/EUR","bids":[{"price":62433.6,"qty":0.00000000},{"price":62426.2,"qty":1.47654819}],"asks":[],"checksum":4084944013,"timestamp":"2024-06-01T22:42:12.092205Z"}]}
{"channel":"book","type":"update","data":[{"symbol":"BTC/EUR","bids":[{"price":62433.6,"qty":0.51098524}],"asks":[],"checksum":1770185181,"timestamp":"2024-06-01T22:42:12.097415Z"}]}
{"channel":"book","type":"update","data":[{"symbol":"BTC/EUR","bids":[{"price":62431.9,"qty":0.59719912}],"asks":[],"checksum":1023820924,"timestamp":"2024-06-01T22:42:12.097436Z"}]}
{"channel":"book","type":"update","data":[{"symbol":"BTC/EUR","bids":[],"asks":[{"price":62452.2,"qty":8.22976361}],"checksum":3832472872,"timestamp":"2024-06-01T22:42:12.325747Z"}]}
{"channel":"book","type":"update","data":[{"symbol":"BTC/EUR","bids":[],"asks":[{"price":62456.9,"qty":0.00000000},{"price":62467.3,"qty":0.00015134}],"checksum":3305378924,"timestamp":"2024-06-01T22:42:12.328400Z"}]}
{"channel":"book","type":"update","data":[{"symbol":"BTC/EUR","bids":[],"asks":[{"price":62465.2,"qty":0.00000000},{"price":62467.4,"qty":0.04443074}],"checksum":2907540884,"timestamp":"2024-06-01T22:42:12.781860Z"}]}
{"channel":"book","type":"update","data":[{"symbol":"BTC/EUR","bids":[],"asks":[{"price":62465.0,"qty":1.41594569}],"checksum":3404160068,"timestamp":"2024-06-01T22:42:12.786676Z"}]}
{"channel":"book","type":"update","data":[{"symbol":"BTC/EUR","bids":[{"price":62431.9,"qty":0.00000000},{"price":62429.6,"qty":1.47646878}],"asks":[],"checksum":1098365019,"timestamp":"2024-06-01T22:42:14.243060Z"}]}
{"channel":"book","type":"update","data":[{"symbol":"BTC/EUR","bids":[{"price":62433.6,"qty":0.00000000},{"price":62426.2,"qty":1.47654819}],"asks":[],"checksum":4152926145,"timestamp":"2024-06-01T22:42:14.243185Z"}]}
{"channel":"book","type":"update","data":[{"symbol":"BTC/EUR","bids":[{"price":62433.6,"qty":0.56166433}],"asks":[],"checksum":1547382893,"timestamp":"2024-06-01T22:42:14.248554Z"}]}
{"channel":"book","type":"update","data":[{"symbol":"BTC/EUR","bids":[],"asks":[{"price":62452.2,"qty":8.26979425}],"checksum":3804280964,"timestamp":"2024-06-01T22:42:14.343346Z"}]}
{"channel":"book","type":"update","data":[{"symbol":"BTC/EUR","bids":[],"asks":[{"price":62456.9,"qty":0.08006129}],"checksum":1858256124,"timestamp":"2024-06-01T22:42:14.349033Z"}]}
