{"channel":"book","type":"snapshot","data":[{"symbol":"BTC/CHF","bids":[{"price":61177.8,"qty":0.00163457},{"price":61150.8,"qty":0.05547556},{"price":61150.7,"qty":0.00058347},{"price":61150.5,"qty":0.00135100},{"price":61150.3,"qty":0.00075200},{"price":61146.6,"qty":0.00126056},{"price":61146.5,"qty":0.25643525},{"price":61146.4,"qty":0.43513260},{"price":61145.7,"qty":0.11589697},{"price":61119.9,"qty":0.04647936}],"asks":[{"price":61188.1,"qty":0.00340536},{"price":61188.2,"qty":0.09452196},{"price":61188.4,"qty":0.00232692},{"price":61188.8,"qty":0.00016603},{"price":61189.0,"qty":0.01495500},{"price":61192.3,"qty":0.67105135},{"price":61192.4,"qty":0.78416837},{"price":61194.0,"qty":0.00719000},{"price":61199.9,"qty":0.00135100},{"price":61200.0,"qty":0.08198599}],"checksum":4034410435}]}
{"channel":"book","type":"update","data":[{"symbol":"BTC/CHF","bids":[{"price":61150.5,"qty":0.00000000},{"price":61119.8,"qty":0.00811000},{"price":61143.4,"qty":0.00135100}],"asks":[],"checksum":710044123,"timestamp":"2024-06-01T22:42:05.213226Z"}]}
{"channel":"book","type":"update","data":[{"symbol":"BTC/CHF","bids":[{"price":61150.8,"qty":0.00000000},{"price":61119.8,"qty":0.00811000},{"price":61146.7,"qty":0.05547929}],"asks":[],"checksum":540475416,"timestamp":"2024-06-01T22:42:05.881188Z"}]}
{"channel":"book","type":"update","data":[{"symbol":"BTC/CHF","bids":[{"price":61146.7,"qty":0.00000000},{"price":61119.8,"qty":0.00811000},{"price":61146.8,"qty":0.05547920}],"asks":[],"checksum":1166217484,"timestamp":"2024-06-01T22:42:05.957410Z"}]}
{"channel":"book","type":"update","data":[{"symbol":"BTC/CHF","bids":[{"price":61146.8,"qty":0.00000000},{"price":61119.8,"qty":0.00811000},{"price":61146.7,"qty":0.05547929}],"asks":[],"checksum":540475416,"timestamp":"2024-06-01T22:42:06.026129Z"}]}
{"channel":"book","type":"update","data":[{"symbol":"BTC/CHF","bids":[{"price":61146.7,"qty":0.00000000},{"price":61119.8,"qty":0.00811000},{"price":61146.8,"qty":0.05547920}],"asks":[],"checksum":1166217484,"timestamp":"2024-06-01T22:42:06.094077Z"}]}
{"channel":"book","type":"update","data":[{"symbol":"BTC/CHF","bids":[],"asks":[{"price":61188.4,"qty":0.00000000},{"price":61203.7,"qty":0.10000000}],"checksum":2085368742,"timestamp":"2024-06-01T22:42:06.101506Z"}]}
{"channel":"book","type":"update","data":[{"symbol":"BTC/CHF","bids":[],"asks":[{"price":61188.0,"qty":0.00283483}],"checksum":3062848831,"timestamp":"2024-06-01T22:42:06.103981Z"}]}
{"channel":"book","type":"update","data":[{"symbol":"BTC/CHF","bids":[{"price":61146.8,"qty":0.00000000},{"price":61119.8,"qty":0.00811000},{"price":61146.7,"qty":0.05547929}],"asks":[],"checksum":3543878699,"timestamp":"2024-06-01T22:42:06.151903Z"}]}
{"channel":"book","type":"update","data":[{"symbol":"BTC/CHF","bids":[{"price":61146.5,"qty":0.00000000},{"price":61119.8,"qty":0.00811000}],"asks":[],"checksum":20003968,"timestamp":"2024-06-01T22:42:06.241591Z"}]}
{"channel":"book","type":"update","data":[{"symbol":"BTC/CHF","bids":[{"price":61146.9,"qty":0.26363847}],"asks":[],"checksum":3629479044,"timestamp":"2024-06-01T22:42:06.243139Z"}]}
{"channel":"book","type":"update","data":[{"symbol":"BTC/CHF","bids":[{"price":61146.7,"qty":0.00000000},{"price":61119.8,"qty":0.00811000},{"price":61146.8,"qty":0.05547920}],"asks":[],"checksum":3392330813,"timestamp":"2024-06-01T22:42:06.286673Z"}]}
{"channel":"book","type":"update","data":[{"symbol":"BTC/CHF","bids":[],"asks":[{"price":61188.1,"qty":0.00000000},{"price":61203.7,"qty":0.10000000},{"price":61187.9,"qty":0.00340536}],"checksum":2764063345,"timestamp":"2024-06-01T22:42:06.286743Z"}]}
{"channel":"book","type":"update","data":[{"symbol":"BTC/CHF","bids":[{"price":61146.8,"qty":0.00000000},{"price":61119.8,"qty":0.00811000},{"price":61150.8,"qty":0.05547548}],"asks":[],"checksum":2120017783,"timestamp":"2024-06-01T22:42:06.578387Z"}]}
{"channel":"book","type":"update","data":[{"symbol":"BTC/CHF","bids":[{"price":61145.7,"qty":0.00000000},{"price":61119.8,"qty":0.00811000},{"price":61134.5,"qty":0.11589697}],"asks":[],"checksum":1072913522,"timestamp":"2024-06-01T22:42:06.584706Z"}]}
{"channel":"book","type":"update","data":[{"symbol":"BTC/CHF","bids":[{"price":61150.7,"qty":0.00000000},{"price":61119.8,"qty":0.00811000}],"asks":[],"checksum":147818834,"timestamp":"2024-06-01T22:42:07.088972Z"}]}
{"channel":"book","type":"update","data":[{"symbol":"BTC/CHF","bids":[{"price":61146.6,"qty":0.00000000},{"price":61118.0,"qty":0.10000000}],"asks":[],"checksum":1504132062,"timestamp":"2024-06-01T22:42:07.088987Z"}]}
{"channel":"book","type":"update","data":[{"symbol":"BTC/CHF","bids":[{"price":61150.9,"qty":0.00058347}],"asks":[],"checksum":3699239944,"timestamp":"2024-06-01T22:42:07.090037Z"}]}
{"channel":"book","type":"update","data":[{"symbol":"BTC/CHF","bids":[{"price":61147.0,"qty":0.00117052}],"asks":[],"checksum":3896188173,"timestamp":"2024-06-01T22:42:07.090149Z"}]}
{"channel":"book","type":"update","data":[{"symbol":"BTC/CHF","bids":[{"price":61150.8,"qty":0.00000000},{"price":61119.8,"qty":0.00811000},{"price":61151.0,"qty":0.05547529}],"asks":[],"checksum":858106458,"timestamp":"2024-06-01T22:42:07.136289Z"}]}
{"channel":"book","type":"update","data":[{"symbol":"BTC/CHF","bids":[{"price":61151.0,"qty":0.00000000},{"price":61119.8,"qty":0.00811000},{"price":61147.1,"qty":0.05547883}],"asks":[],"checksum":3096994601,"timestamp":"2024-06-01T22:42:07.415242Z"}]}
{"channel":"book","type":"update","data":[{"symbol":"BTC/CHF","bids":[],"asks":[{"price":61188.2,"qty":0.00000000},{"price":61203.7,"qty":0.10000000}],"checksum":981223188,"timestamp":"2024-06-01T22:42:07.494260Z"}]}
{"channel":"book","type":"update","data":[{"symbol":"BTC/CHF","bids":[],"asks":[{"price":61192.3,"qty":0.00000000},{"price":61207.9,"qty":0.00601000}],"checksum":1276665168,"timestamp":"2024-06-01T22:42:07.494565Z"}]}
{"channel":"book","type":"update","data":[{"symbol":"BTC/CHF","bids":[],"asks":[{"price":61187.8,"qty":0.09452196}],"checksum":2166641644,"timestamp":"2024-06-01T22:42:07.499389Z"}]}
{"channel":"book","type":"update","data":[{"symbol":"BTC/CHF","bids":[],"asks":[{"price":61192.3,"qty":0.64940453}],"checksum":33358600,"timestamp":"2024-06-01T22:42:07.499429Z"}]}
{"channel":"book","type":"update","data":[{"symbol":"BTC/CHF","bids":[],"asks":[{"price":61187.9,"qty":0.00000000},{"price":61203.7,"qty":0.10000000},{"price":61187.7,"qty":0.00340536}],"checksum":902727107,"timestamp":"2024-06-01T22:42:07.731861Z"}]}
{"channel":"book","type":"update","data":[{"symbol":"BTC/CHF","bids":[{"price":61146.9,"qty":0.00000000},{"price":61119.8,"qty":0.00811000}],"asks":[],"checksum":525937477,"timestamp":"2024-06-01T22:42:08.343300Z"}]}
{"channel":"book","type":"update","data":[{"symbol":"BTC/CHF","bids":[{"price":61147.2,"qty":0.24563043}],"asks":[],"checksum":1304443891,"timestamp":"2024-06-01T22:42:08.344358Z"}]}
{"channel":"book","type":"update","data":[{"symbol":"BTC/CHF","bids":[{"price":61147.1,"qty":0.00000000},{"price":61119.8,"qty":0.00811000},{"price":61147.3,"qty":0.05547896}],"asks":[],"checksum":2496604205,"timestamp":"2024-06-01T22:42:08.405429Z"}]}
{"channel":"book","type":"update","data":[{"symbol":"BTC/CHF","bids":[{"price":61147.3,"qty":0.00000000},{"price":61119.8,"qty":0.00811000},{"price":61151.0,"qty":0.05547560}],"asks":[],"checksum":3155571723,"timestamp":"2024-06-01T22:42:08.717802Z"}]}
{"channel":"book","type":"update","data":[{"symbol":"BTC/CHF","bids":[{"price":61151.0,"qty":0.00000000},{"price":61119.8,"qty":0.00811000},{"price":61147.3,"qty":0.05547896}],"asks":[],"checksum":2496604205,"timestamp":"2024-06-01T22:42:08.785420Z"}]}
{"channel":"book","type":"update","data":[{"symbol":"BTC/CHF","bids":[],"asks":[{"price":61188.0,"qty":0.00000000},{"price":61203.7,"qty":0.10000000}],"checksum":673129491,"timestamp":"2024-06-01T22:42:08.851879Z"}]}
{"channel":"book","type":"update","data":[{"symbol":"BTC/CHF","bids":[],"asks":[{"price":61187.6,"qty":0.00281064}],"checksum":607768043,"timestamp":"2024-06-01T22:42:08.856771Z"}]}
{"channel":"book","type":"update","data":[{"symbol":"BTC/CHF","bids":[{"price":61147.3,"qty":0.00000000},{"price":61119.8,"qty":0.00811000},{"price":61151.0,"qty":0.05547561}],"asks":[],"checksum":3121100672,"timestamp":"2024-06-01T22:42:09.065171Z"}]}
{"channel":"book","type":"update","data":[{"symbol":"BTC/CHF","bids":[],"asks":[{"price":61187.7,"qty":0.00000000},{"price":61203.7,"qty":0.10000000},{"price":61187.5,"qty":0.00340555}],"checksum":3794644313,"timestamp":"2024-06-01T22:42:09.065209Z"}]}
{"channel":"book","type":"update","data":[{"symbol":"BTC/CHF","bids":[],"asks":[{"price":61187.5,"qty":0.00000000},{"price":61203.7,"qty":0.10000000},{"price":61187.4,"qty":0.00340555}],"checksum":3717917023,"timestamp":"2024-06-01T22:42:09.429756Z"}]}
{"channel":"book","type":"update","data":[{"symbol":"BTC/CHF","bids":[],"asks":[{"price":61187.4,"qty":0.00000000},{"price":61203.7,"qty":0.10000000},{"price":61187.5,"qty":0.00340555}],"checksum":3794644313,"timestamp":"2024-06-01T22:42:09.485719Z"}]}
{"channel":"book","type":"update","data":[{"symbol":"BTC/CHF","bids":[{"price":61150.9,"qty":0.00000000},{"price":61119.8,"qty":0.00811000}],"asks":[],"checksum":264424281,"timestamp":"2024-06-01T22:42:09.606529Z"}]}
{"channel":"book","type":"update","data":[{"symbol":"BTC/CHF","bids":[{"price":61147.0,"qty":0.00000000},{"price":61118.0,"qty":0.10000000}],"asks":[],"checksum":1547568636,"timestamp":"2024-06-01T22:42:09.606640Z"}]}
{"channel":"book","type":"update","data":[{"symbol":"BTC/CHF","bids":[{"price":61151.1,"qty":0.00029534}],"asks":[],"checksum":1064340626,"timestamp":"2024-06-01T22:42:09.607311Z"}]}
{"channel":"book","type":"update","data":[{"symbol":"BTC/CHF","bids":[{"price":61147.3,"qty":0.00126056}],"asks":[],"checksum":2700055661,"timestamp":"2024-06-01T22:42:09.607501Z"}]}
{"channel":"book","type":"update","data":[{"symbol":"BTC/CHF","bids":[{"price":61151.0,"qty":0.00000000},{"price":61119.8,"qty":0.00811000},{"price":61147.4,"qty":0.05547888}],"asks":[],"checksum":54168620,"timestamp":"2024-06-01T22:42:09.669293Z"}]}
{"channel":"book","type":"update","data":[{"symbol":"BTC/CHF","bids":[],"asks":[{"price":61187.8,"qty":0.00000000},{"price":61203.7,"qty":0.10000000}],"checksum":2840902837,"timestamp":"2024-06-01T22:42:10.074225Z"}]}
{"channel":"book","type":"update","data":[{"symbol":"BTC/CHF","bids":[],"asks":[{"price":61192.3,"qty":0.00000000},{"price":61207.9,"qty":0.00601000}],"checksum":377023564,"timestamp":"2024-06-01T22:42:10.074324Z"}]}
{"channel":"book","type":"update","data":[{"symbol":"BTC/CHF","bids":[],"asks":[{"price":61192.3,"qty":0.67105135}],"checksum":328228432,"timestamp":"2024-06-01T22:42:10.079332Z"}]}
{"channel":"book","type":"update","data":[{"symbol":"BTC/CHF","bids":[],"asks":[{"price":61187.4,"qty":0.09452196}],"checksum":652443911,"timestamp":"2024-06-01T22:42:10.079432Z"}]}
{"channel":"book","type":"update","data":[{"symbol":"BTC/CHF","bids":[],"asks":[{"price":61187.5,"qty":0.00000000},{"price":61203.7,"qty":0.10000000},{"price":61187.3,"qty":0.00340555}],"checksum":884659170,"timestamp":"2024-06-01T22:42:10.128329Z"}]}
{"channel":"book","type":"update","data":[{"symbol":"BTC/CHF","bids":[{"price":61147.2,"qty":0.00000000},{"price":61119.8,"qty":0.00811000}],"asks":[],"checksum":2627460229,"timestamp":"2024-06-01T22:42:10.383313Z"}]}
{"channel":"book","type":"update","data":[{"symbol":"BTC/CHF","bids":[{"price":61147.5,"qty":0.23122399}],"asks":[],"checksum":1120745003,"timestamp":"2024-06-01T22:42:10.384977Z"}]}
{"channel":"book","type":"update","data":[{"symbol":"BTC/CHF","bids":[{"price":61147.4,"qty":0.00000000},{"price":61119.8,"qty":0.00811000},{"price":61147.6,"qty":0.05547827}],"asks":[],"checksum":717359611,"timestamp":"2024-06-01T22:42:10.559211Z"}]}
{"channel":"book","type":"update","data":[{"symbol":"BTC/CHF","bids":[{"price":61119.9,"qty":0.00000000},{"price":61119.8,"qty":0.00811000}],"asks":[],"checksum":3146187888,"timestamp":"2024-06-01T22:42:11.071399Z"}]}
{"channel":"book","type":"update","data":[{"symbol":"BTC/CHF","bids":[],"asks":[{"price":61187.6,"qty":0.00000000},{"price":61203.7,"qty":0.10000000}],"checksum":2509962939,"timestamp":"2024-06-01T22:42:11.665951Z"}]}
{"channel":"book","type":"update","data":[{"symbol":"BTC/CHF","bids":[],"asks":[{"price":61187.2,"qty":0.00280951}],"checksum":551498109,"timestamp":"2024-06-01T22:42:11.670531Z"}]}
{"channel":"book","type":"update","data":[{"symbol":"BTC/CHF","bids":[],"asks":[{"price":61187.3,"qty":0.00000000},{"price":61203.7,"qty":0.10000000},{"price":61187.1,"qty":0.00340545}],"checksum":120824544,"timestamp":"2024-06-01T22:42:11.725854Z"}]}
{"channel":"book","type":"update","data":[{"symbol":"BTC/CHF","bids":[{"price":61147.3,"qty":0.00000000},{"price":61118.0,"qty":0.10000000}],"asks":[],"checksum":940328795,"timestamp":"2024-06-01T22:42:12.174987Z"}]}
{"channel":"book","type":"update","data":[{"symbol":"BTC/CHF","bids":[{"price":61151.1,"qty":0.00000000},{"price":61053.7,"qty":0.16916205}],"asks":[],"checksum":3319689194,"timestamp":"2024-06-01T22:42:12.175126Z"}]}
{"channel":"book","type":"update","data":[{"symbol":"BTC/CHF","bids":[{"price":61147.7,"qty":0.00193407}],"asks":[],"checksum":3986272914,"timestamp":"2024-06-01T22:42:12.176182Z"}]}
{"channel":"book","type":"update","data":[{"symbol":"BTC/CHF","bids":[{"price":61147.6,"qty":0.00000000},{"price":61053.7,"qty":0.16916205},{"price":61147.8,"qty":0.05547812}],"asks":[],"checksum":1477591626,"timestamp":"2024-06-01T22:42:12.206891Z"}]}
{"channel":"book","type":"update","data":[{"symbol":"BTC/CHF","bids":[{"price":61119.9,"qty":0.04647939}],"asks":[],"checksum":246625410,"timestamp":"2024-06-01T22:42:12.207841Z"}]}
{"channel":"book","type":"update","data":[{"symbol":"BTC/CHF","bids":[{"price":61147.5,"qty":0.00000000},{"price":61118.0,"qty":0.10000000}],"asks":[],"checksum":3293733606,"timestamp":"2024-06-01T22:42:12.534955Z"}]}
{"channel":"book","type":"update","data":[{"symbol":"BTC/CHF","bids":[{"price":61147.9,"qty":0.17359826}],"asks":[],"checksum":3578818519,"timestamp":"2024-06-01T22:42:12.536606Z"}]}
{"channel":"book","type":"update","data":[{"symbol":"BTC/CHF","bids":[{"price":61146.5,"qty":0.08103619}],"asks":[],"checksum":2955979517,"timestamp":"2024-06-01T22:42:12.536771Z"}]}
{"channel":"book","type":"update","data":[{"symbol":"BTC/CHF","bids":[{"price":61147.8,"qty":0.00000000},{"price":61119.8,"qty":0.00811000},{"price":61148.0,"qty":0.05547789}],"asks":[],"checksum":2378200388,"timestamp":"2024-06-01T22:42:12.663260Z"}]}
{"channel":"book","type":"update","data":[{"symbol":"BTC/CHF","bids":[{"price":61147.9,"qty":0.00000000},{"price":61119.8,"qty":0.00811000}],"asks":[],"checksum":3254093820,"timestamp":"2024-06-01T22:42:12.752575Z"}]}
{"channel":"book","type":"update","data":[{"symbol":"BTC/CHF","bids":[],"asks":[{"price":61192.3,"qty":0.00000000},{"price":61203.7,"qty":0.10000000}],"checksum":2091416455,"timestamp":"2024-06-01T22:42:12.782383Z"}]}
{"channel":"book","type":"update","data":[{"symbol":"BTC/CHF","bids":[],"asks":[{"price":61187.4,"qty":0.00000000},{"price":61207.9,"qty":0.00601000}],"checksum":4244860829,"timestamp":"2024-06-01T22:42:12.782457Z"}]}
{"channel":"book","type":"update","data":[{"symbol":"BTC/CHF","bids":[],"asks":[{"price":61187.0,"qty":0.07285928}],"checksum":1434551059,"timestamp":"2024-06-01T22:42:12.786902Z"}]}
{"channel":"book","type":"update","data":[{"symbol":"BTC/CHF","bids":[],"asks":[{"price":61192.3,"qty":0.69286741}],"checksum":3015518402,"timestamp":"2024-06-01T22:42:12.787071Z"}]}
{"channel":"book","type":"update","data":[{"symbol":"BTC/CHF","bids":[{"price":61148.0,"qty":0.00000000},{"price":61118.0,"qty":0.10000000},{"price":61147.8,"qty":0.05547808}],"asks":[],"checksum":4282875510,"timestamp":"2024-06-01T22:42:12.808498Z"}]}
{"channel":"book","type":"update","data":[{"symbol":"BTC/CHF","bids":[{"price":61147.8,"qty":0.00000000},{"price":61118.0,"qty":0.10000000},{"price":61147.9,"qty":0.05547799}],"asks":[],"checksum":1223172103,"timestamp":"2024-06-01T22:42:13.065808Z"}]}
{"channel":"book","type":"update","data":[{"symbol":"BTC/CHF","bids":[],"asks":[{"price":61187.1,"qty":0.00000000},{"price":61203.7,"qty":0.10000000},{"price":61186.9,"qty":0.00340541}],"checksum":3115263722,"timestamp":"2024-06-01T22:42:13.065850Z"}]}
{"channel":"book","type":"update","data":[{"symbol":"BTC/CHF","bids":[{"price":61147.9,"qty":0.00000000},{"price":61118.0,"qty":0.10000000},{"price":61147.8,"qty":0.05547809}],"asks":[],"checksum":3461944065,"timestamp":"2024-06-01T22:42:13.121691Z"}]}
{"channel":"book","type":"update","data":[{"symbol":"BTC/CHF","bids":[],"asks":[{"price":61199.9,"qty":0.00000000},{"price":61203.7,"qty":0.10000000},{"price":61197.2,"qty":0.00135100}],"checksum":1251787735,"timestamp":"2024-06-01T22:42:13.185061Z"}]}
{"channel":"book","type":"update","data":[{"symbol":"BTC/CHF","bids":[],"asks":[{"price":61189.0,"qty":0.00000000},{"price":61203.7,"qty":0.10000000},{"price":61186.8,"qty":0.01495500}],"checksum":646470257,"timestamp":"2024-06-01T22:42:13.575886Z"}]}
{"channel":"book","type":"update","data":[{"symbol":"BTC/CHF","bids":[],"asks":[{"price":61186.9,"qty":0.00000000},{"price":61203.7,"qty":0.10000000},{"price":61186.7,"qty":0.00340541}],"checksum":2158216653,"timestamp":"2024-06-01T22:42:13.599202Z"}]}
{"channel":"book","type":"update","data":[{"symbol":"BTC/CHF","bids":[],"asks":[{"price":61187.2,"qty":0.00000000},{"price":61203.7,"qty":0.10000000}],"checksum":2384282825,"timestamp":"2024-06-01T22:42:14.315014Z"}]}
{"channel":"book","type":"update","data":[{"symbol":"BTC/CHF","bids":[],"asks":[{"price":61192.2,"qty":0.00075924}],"checksum":1611747520,"timestamp":"2024-06-01T22:42:14.317841Z"}]}
{"channel":"book","type":"update","data":[{"symbol":"BTC/CHF","bids":[],"asks":[{"price":61186.6,"qty":0.00220274}],"checksum":1511437580,"timestamp":"2024-06-01T22:42:14.317906Z"}]}
{"channel":"book","type":"update","data":[{"symbol":"BTC/CHF","bids":[],"asks":[{"price":61186.7,"qty":0.00000000},{"price":61200.0,"qty":0.08198599},{"price":61186.5,"qty":0.00340506}],"checksum":2997320301,"timestamp":"2024-06-01T22:42:14.375328Z"}]}
{"channel":"book","type":"update","data":[{"symbol":"BTC/CHF","bids":[{"price":61147.7,"qty":0.00000000},{"price":61118.0,"qty":0.10000000}],"asks":[],"checksum":1618297384,"timestamp":"2024-06-01T22:42:14.658706Z"}]}
{"channel":"book","type":"update","data":[{"symbol":"BTC/CHF","bids":[{"price":61146.6,"qty":0.00094363}],"asks":[],"checksum":3015920012,"timestamp":"2024-06-01T22:42:14.660248Z"}]}
{"channel":"book","type":"update","data":[{"symbol":"BTC/CHF","bids":[{"price":61146.5,"qty":0.00000000},{"price":61118.0,"qty":0.10000000}],"asks":[],"checksum":2840522020,"timestamp":"2024-06-01T22:42:14.660745Z"}]}
{"channel":"book","type":"update","data":[{"symbol":"BTC/CHF","bids":[{"price":61120.0,"qty":0.14478539}],"asks":[],"checksum":1358470677,"timestamp":"2024-06-01T22:42:14.661434Z"}]}
{"channel":"book","type":"update","data":[{"symbol":"BTC/CHF","bids":[{"price":61147.8,"qty":0.00000000},{"price":61118.0,"qty":0.10000000},{"price":61146.7,"qty":0.05547725}],"asks":[],"checksum":609216529,"timestamp":"2024-06-01T22:42:14.716227Z"}]}
{"channel":"book","type":"update","data":[{"symbol":"BTC/CHF","bids":[],"asks":[{"price":61186.5,"qty":0.00000000},{"price":61200.0,"qty":0.08198599},{"price":61186.5,"qty":0.00308665}],"checksum":2161440414,"timestamp":"2024-06-01T22:42:14.909239Z"}]}
{"channel":"book","type":"update","data":[{"symbol":"BTC/CHF","bids":[],"asks":[{"price":61192.3,"qty":0.00000000},{"price":61200.0,"qty":0.08198599}],"checksum":3609822359,"timestamp":"2024-06-01T22:42:15.294984Z"}]}
{"channel":"book","type":"update","data":[{"symbol":"BTC/CHF","bids":[],"asks":[{"price":61187.0,"qty":0.00000000},{"price":61203.7,"qty":0.10000000}],"checksum":989644071,"timestamp":"2024-06-01T22:42:15.295122Z"}]}
{"channel":"book","type":"update","data":[{"symbol":"BTC/CHF","bids":[],"asks":[{"price":61186.4,"qty":0.07285928}],"checksum":2326990601,"timestamp":"2024-06-01T22:42:15.300281Z"}]}
{"channel":"book","type":"update","data":[{"symbol":"BTC/CHF","bids":[],"asks":[{"price":61192.3,"qty":0.67121530}],"checksum":1386001585,"timestamp":"2024-06-01T22:42:15.300493Z"}]}
{"channel":"book","type":"update","data":[{"symbol":"BTC/CHF","bids":[{"price":61119.9,"qty":0.00000000},{"price":61118.0,"qty":0.10000000}],"asks":[],"checksum":3885894876,"timestamp":"2024-06-01T22:42:15.329379Z"}]}
{"channel":"book","type":"update","data":[{"symbol":"BTC/CHF","bids":[],"asks":[{"price":61186.5,"qty":0.00000000},{"price":61200.0,"qty":0.08198599},{"price":61186.3,"qty":0.00308665}],"checksum":770626575,"timestamp":"2024-06-01T22:42:15.424928Z"}]}
{"channel":"book","type":"update","data":[{"symbol":"BTC/CHF","bids":[{"price":61120.1,"qty":0.04647941}],"asks":[],"checksum":1317414315,"timestamp":"2024-06-01T22:42:16.484721Z"}]}
{"channel":"book","type":"update","data":[{"symbol":"BTC/CHF","bids":[{"price":61120.0,"qty":0.00000000},{"price":61118.0,"qty":0.10000000}],"asks":[],"checksum":971241834,"timestamp":"2024-06-01T22:42:16.794427Z"}]}
{"channel":"book","type":"update","data":[{"symbol":"BTC/CHF","bids":[{"price":61120.2,"qty":0.17359826}],"asks":[],"checksum":3808618109,"timestamp":"2024-06-01T22:42:16.795919Z"}]}
{"channel":"book","type":"update","data":[{"symbol":"BTC/CHF","bids":[],"asks":[{"price":61192.2,"qty":0.00000000},{"price":61200.0,"qty":0.08198599}],"checksum":633882850,"timestamp":"2024-06-01T22:42:17.035753Z"}]}
{"channel":"book","type":"update","data":[{"symbol":"BTC/CHF","bids":[],"asks":[{"price":61186.6,"qty":0.00000000},{"price":61203.7,"qty":0.10000000}],"checksum":2635544351,"timestamp":"2024-06-01T22:42:17.035790Z"}]}
{"channel":"book","type":"update","data":[{"symbol":"BTC/CHF","bids":[],"asks":[{"price":61186.2,"qty":0.00203670}],"checksum":3695751875,"timestamp":"2024-06-01T22:42:17.040484Z"}]}
{"channel":"book","type":"update","data":[{"symbol":"BTC/CHF","bids":[],"asks":[{"price":61192.2,"qty":0.00096317}],"checksum":4258293226,"timestamp":"2024-06-01T22:42:17.040604Z"}]}
{"channel":"book","type":"update","data":[{"symbol":"BTC/CHF","bids":[],"asks":[{"price":61192.4,"qty":0.00000000},{"price":61200.0,"qty":0.08198599}],"checksum":81154288,"timestamp":"2024-06-01T22:42:17.044328Z"}]}
{"channel":"book","type":"update","data":[{"symbol":"BTC/CHF","bids":[],"asks":[{"price":61189.5,"qty":0.78418441}],"checksum":3689514396,"timestamp":"2024-06-01T22:42:17.047470Z"}]}
{"channel":"book","type":"update","data":[{"symbol":"BTC/CHF","bids":[],"asks":[{"price":61186.3,"qty":0.00000000},{"price":61200.0,"qty":0.08198599},{"price":61186.1,"qty":0.00308666}],"checksum":3979670033,"timestamp":"2024-06-01T22:42:17.098937Z"}]}
{"channel":"book","type":"update","data":[{"symbol":"BTC/CHF","bids":[{"price":61146.6,"qty":0.00000000},{"price":61118.0,"qty":0.10000000}],"asks":[],"checksum":3003037619,"timestamp":"2024-06-01T22:42:17.171708Z"}]}
{"channel":"book","type":"update","data":[{"symbol":"BTC/CHF","bids":[{"price":61146.8,"qty":0.00115973}],"asks":[],"checksum":1211721252,"timestamp":"2024-06-01T22:42:17.173546Z"}]}
{"channel":"book","type":"update","data":[{"symbol":"BTC/CHF","bids":[{"price":61146.7,"qty":0.00000000},{"price":61118.0,"qty":0.10000000},{"price":61146.5,"qty":0.05547767}],"asks":[],"checksum":2626364202,"timestamp":"2024-06-01T22:42:17.219478Z"}]}
{"channel":"book","type":"update","data":[{"symbol":"BTC/CHF","bids":[{"price":61146.5,"qty":0.00000000},{"price":61118.0,"qty":0.10000000},{"price":61146.9,"qty":0.05547731}],"asks":[],"checksum":1396367463,"timestamp":"2024-06-01T22:42:17.523015Z"}]}
{"channel":"book","type":"update","data":[{"symbol":"BTC/CHF","bids":[],"asks":[{"price":61186.4,"qty":0.00000000},{"price":61200.0,"qty":0.08198599}],"checksum":2689753608,"timestamp":"2024-06-01T22:42:17.846134Z"}]}
{"channel":"book","type":"update","data":[{"symbol":"BTC/CHF","bids":[],"asks":[{"price":61192.3,"qty":0.00000000},{"price":61203.7,"qty":0.10000000}],"checksum":1119580577,"timestamp":"2024-06-01T22:42:17.846162Z"}]}
{"channel":"book","type":"update","data":[{"symbol":"BTC/CHF","bids":[],"asks":[{"price":61186.0,"qty":0.09452196}],"checksum":1199503194,"timestamp":"2024-06-01T22:42:17.851203Z"}]}
{"channel":"book","type":"update","data":[{"symbol":"BTC/CHF","bids":[],"asks":[{"price":61189.4,"qty":0.64940453}],"checksum":2619969061,"timestamp":"2024-06-01T22:42:17.851386Z"}]}
{"channel":"book","type":"update","data":[{"symbol":"BTC/CHF","bids":[],"asks":[{"price":61186.1,"qty":0.00000000},{"price":61200.0,"qty":0.08198599},{"price":61185.9,"qty":0.00308666}],"checksum":2666225612,"timestamp":"2024-06-01T22:42:18.025365Z"}]}
{"channel":"book","type":"update","data":[{"symbol":"BTC/CHF","bids":[],"asks":[{"price":61188.8,"qty":0.00000000},{"price":61200.0,"qty":0.08198599},{"price":61185.8,"qty":0.00075200}],"checksum":700182707,"timestamp":"2024-06-01T22:42:18.521676Z"}]}
{"channel":"book","type":"update","data":[{"symbol":"BTC/CHF","bids":[],"asks":[{"price":61185.9,"qty":0.00000000},{"price":61200.0,"qty":0.08198599},{"price":61185.7,"qty":0.00308667}],"checksum":4052876777,"timestamp":"2024-06-01T22:42:18.577147Z"}]}
{"channel":"book","type":"update","data":[{"symbol":"BTC/CHF","bids":[{"price":61146.8,"qty":0.00000000},{"price":61118.0,"qty":0.10000000}],"asks":[],"checksum":1680271615,"timestamp":"2024-06-01T22:42:19.730650Z"}]}
{"channel":"book","type":"update","data":[{"symbol":"BTC/CHF","bids":[{"price":61147.0,"qty":0.00094363}],"asks":[],"checksum":650933857,"timestamp":"2024-06-01T22:42:19.731539Z"}]}
{"channel":"book","type":"update","data":[{"symbol":"BTC/CHF","bids":[{"price":61146.9,"qty":0.00000000},{"price":61118.0,"qty":0.10000000},{"price":61147.1,"qty":0.05547703}],"asks":[],"checksum":504478418,"timestamp":"2024-06-01T22:42:19.762012Z"}]}
{"channel":"book","type":"update","data":[{"symbol":"BTC/CHF","bids":[],"asks":[{"price":61186.2,"qty":0.00000000},{"price":61200.0,"qty":0.08198599}],"checksum":1174416005,"timestamp":"2024-06-01T22:42:19.796664Z"}]}
{"channel":"book","type":"update","data":[{"symbol":"BTC/CHF","bids":[],"asks":[{"price":61192.2,"qty":0.00000000},{"price":61203.7,"qty":0.10000000}],"checksum":1092988664,"timestamp":"2024-06-01T22:42:19.796769Z"}]}
{"channel":"book","type":"update","data":[{"symbol":"BTC/CHF","bids":[],"asks":[{"price":61185.6,"qty":0.00087579}],"checksum":3011247390,"timestamp":"2024-06-01T22:42:19.798657Z"}]}
{"channel":"book","type":"update","data":[{"symbol":"BTC/CHF","bids":[],"asks":[{"price":61185.9,"qty":0.00159625}],"checksum":2518107986,"timestamp":"2024-06-01T22:42:19.798681Z"}]}
{"channel":"book","type":"update","data":[{"symbol":"BTC/CHF","bids":[{"price":61146.4,"qty":0.00000000},{"price":61118.0,"qty":0.10000000}],"asks":[],"checksum":1012658632,"timestamp":"2024-06-01T22:42:19.802144Z"}]}
{"channel":"book","type":"update","data":[{"symbol":"BTC/CHF","bids":[{"price":61146.5,"qty":0.43993513}],"asks":[],"checksum":1079539761,"timestamp":"2024-06-01T22:42:19.805489Z"}]}
{"channel":"book","type":"update","data":[{"symbol":"BTC/CHF","bids":[{"price":61147.1,"qty":0.00000000},{"price":61118.0,"qty":0.10000000},{"price":61134.6,"qty":0.05548838}],"asks":[],"checksum":1397218993,"timestamp":"2024-06-01T22:42:19.850788Z"}]}
{"channel":"book","type":"update","data":[{"symbol":"BTC/CHF","bids":[],"asks":[{"price":61185.7,"qty":0.00000000},{"price":61200.0,"qty":0.08198599},{"price":61185.5,"qty":0.00308671}],"checksum":1334894451,"timestamp":"2024-06-01T22:42:20.132918Z"}]}
{"channel":"book","type":"update","data":[{"symbol":"BTC/CHF","bids":[{"price":61134.6,"qty":0.00000000},{"price":61118.0,"qty":0.10000000},{"price":61147.1,"qty":0.05547703}],"asks":[],"checksum":1552906739,"timestamp":"2024-06-01T22:42:20.133020Z"}]}
{"channel":"book","type":"update","data":[{"symbol":"BTC/CHF","bids":[{"price":61120.1,"qty":0.00000000},{"price":61118.0,"qty":0.10000000}],"asks":[],"checksum":711351306,"timestamp":"2024-06-01T22:42:20.290256Z"}]}
{"channel":"book","type":"update","data":[{"symbol":"BTC/CHF","bids":[],"asks":[{"price":61186.0,"qty":0.00000000},{"price":61200.0,"qty":0.08198599}],"checksum":3499272673,"timestamp":"2024-06-01T22:42:20.492426Z"}]}
{"channel":"book","type":"update","data":[{"symbol":"BTC/CHF","bids":[],"asks":[{"price":61185.5,"qty":0.09760868}],"checksum":2616502505,"timestamp":"2024-06-01T22:42:20.494663Z"}]}
{"channel":"book","type":"update","data":[{"symbol":"BTC/CHF","bids":[],"asks":[{"price":61185.5,"qty":0.09452197},{"price":61185.4,"qty":0.00308670}],"checksum":2971655565,"timestamp":"2024-06-01T22:42:20.617578Z"}]}
{"channel":"book","type":"update","data":[{"symbol":"BTC/CHF","bids":[{"price":61120.2,"qty":0.00000000},{"price":61053.7,"qty":0.16916205}],"asks":[],"checksum":798548748,"timestamp":"2024-06-01T22:42:20.933086Z"}]}
{"channel":"book","type":"update","data":[{"symbol":"BTC/CHF","bids":[{"price":61118.1,"qty":0.14478539}],"asks":[],"checksum":2252543936,"timestamp":"2024-06-01T22:42:20.934665Z"}]}
{"channel":"book","type":"update","data":[{"symbol":"BTC/CHF","bids":[],"asks":[{"price":61185.4,"qty":0.00000000},{"price":61200.0,"qty":0.08198599},{"price":61185.3,"qty":0.00308670}],"checksum":2307855794,"timestamp":"2024-06-01T22:42:21.116598Z"}]}
{"channel":"book","type":"update","data":[{"symbol":"BTC/CHF","bids":[],"asks":[{"price":61185.3,"qty":0.00000000},{"price":61200.0,"qty":0.08198599},{"price":61185.2,"qty":0.00308670}],"checksum":2345520660,"timestamp":"2024-06-01T22:42:21.578673Z"}]}
{"channel":"book","type":"update","data":[{"symbol":"BTC/CHF","bids":[],"asks":[{"price":61185.2,"qty":0.00000000},{"price":61200.0,"qty":0.08198599},{"price":61185.4,"qty":0.00308670}],"checksum":2252543936,"timestamp":"2024-06-01T22:42:21.633246Z"}]}
{"channel":"book","type":"update","data":[{"symbol":"BTC/CHF","bids":[{"price":61147.0,"qty":0.00000000},{"price":61053.7,"qty":0.16916205}],"asks":[],"checksum":2483832759,"timestamp":"2024-06-01T22:42:22.277272Z"}]}
{"channel":"book","type":"update","data":[{"symbol":"BTC/CHF","bids":[{"price":61147.2,"qty":0.00094363}],"asks":[],"checksum":159230228,"timestamp":"2024-06-01T22:42:22.278574Z"}]}
{"channel":"book","type":"update","data":[{"symbol":"BTC/CHF","bids":[{"price":61147.1,"qty":0.00000000},{"price":61053.7,"qty":0.16916205},{"price":61146.6,"qty":0.05547731}],"asks":[],"checksum":1245354490,"timestamp":"2024-06-01T22:42:22.321124Z"}]}
{"channel":"book","type":"update","data":[{"symbol":"BTC/CHF","bids":[],"asks":[{"price":61185.9,"qty":0.00000000},{"price":61200.0,"qty":0.08198599}],"checksum":4099715870,"timestamp":"2024-06-01T22:42:22.572891Z"}]}
{"channel":"book","type":"update","data":[{"symbol":"BTC/CHF","bids":[],"asks":[{"price":61185.6,"qty":0.00000000},{"price":61203.7,"qty":0.10000000}],"checksum":538108778,"timestamp":"2024-06-01T22:42:22.572963Z"}]}
{"channel":"book","type":"update","data":[{"symbol":"BTC/CHF","bids":[],"asks":[{"price":61185.3,"qty":0.00229420}],"checksum":2006468229,"timestamp":"2024-06-01T22:42:22.574991Z"}]}
{"channel":"book","type":"update","data":[{"symbol":"BTC/CHF","bids":[{"price":61146.6,"qty":0.00000000},{"price":61053.7,"qty":0.16916205},{"price":61147.3,"qty":0.05547720}],"asks":[],"checksum":4159831694,"timestamp":"2024-06-01T22:42:22.815864Z"}]}
{"channel":"book","type":"update","data":[{"symbol":"BTC/CHF","bids":[],"asks":[{"price":61185.4,"qty":0.00000000},{"price":61203.7,"qty":0.10000000},{"price":61185.2,"qty":0.00308678}],"checksum":1601952772,"timestamp":"2024-06-01T22:42:22.815968Z"}]}
{"channel":"book","type":"update","data":[{"symbol":"BTC/CHF","bids":[],"asks":[{"price":61185.5,"qty":0.00000000},{"price":61203.7,"qty":0.10000000}],"checksum":440451139,"timestamp":"2024-06-01T22:42:23.066368Z"}]}
{"channel":"book","type":"update","data":[{"symbol":"BTC/CHF","bids":[],"asks":[{"price":61185.2,"qty":0.09760875}],"checksum":2993560676,"timestamp":"2024-06-01T22:42:23.073170Z"}]}
{"channel":"book","type":"update","data":[{"symbol":"BTC/CHF","bids":[],"asks":[{"price":61185.2,"qty":0.09452197},{"price":61185.1,"qty":0.00308678}],"checksum":871482672,"timestamp":"2024-06-01T22:42:23.372275Z"}]}
{"channel":"book","type":"update","data":[{"symbol":"BTC/CHF","bids":[],"asks":[{"price":61185.3,"qty":0.00000000},{"price":61203.7,"qty":0.10000000}],"checksum":2292386473,"timestamp":"2024-06-01T22:42:25.407924Z"}]}
{"channel":"book","type":"update","data":[{"symbol":"BTC/CHF","bids":[],"asks":[{"price":61185.0,"qty":0.00232693}],"checksum":722766270,"timestamp":"2024-06-01T22:42:25.410432Z"}]}
{"channel":"book","type":"update","data":[{"symbol":"BTC/CHF","bids":[],"asks":[{"price":61185.1,"qty":0.00000000},{"price":61203.7,"qty":0.10000000},{"price":61184.9,"qty":0.00308687}],"checksum":1686243415,"timestamp":"2024-06-01T22:42:25.477190Z"}]}
{"channel":"book","type":"update","data":[{"symbol":"BTC/CHF","bids":[],"asks":[{"price":61185.2,"qty":0.00000000},{"price":61203.7,"qty":0.10000000}],"checksum":190290175,"timestamp":"2024-06-01T22:42:25.706246Z"}]}
{"channel":"book","type":"update","data":[{"symbol":"BTC/CHF","bids":[],"asks":[{"price":61185.0,"qty":0.09684890}],"checksum":3958287823,"timestamp":"2024-06-01T22:42:25.708115Z"}]}
{"channel":"book","type":"update","data":[{"symbol":"BTC/CHF","bids":[{"price":61119.9,"qty":0.04647936}],"asks":[],"checksum":4177325331,"timestamp":"2024-06-01T22:42:25.738811Z"}]}
{"channel":"book","type":"update","data":[{"symbol":"BTC/CHF","bids":[{"price":61147.2,"qty":0.00000000},{"price":61118.0,"qty":0.10000000}],"asks":[],"checksum":1272796572,"timestamp":"2024-06-01T22:42:27.361723Z"}]}
{"channel":"book","type":"update","data":[{"symbol":"BTC/CHF","bids":[{"price":61147.4,"qty":0.00115973}],"asks":[],"checksum":3861868109,"timestamp":"2024-06-01T22:42:27.363755Z"}]}
{"channel":"book","type":"update","data":[{"symbol":"BTC/CHF","bids":[{"price":61118.1,"qty":0.00000000},{"price":61118.0,"qty":0.10000000}],"asks":[],"checksum":3173302648,"timestamp":"2024-06-01T22:42:27.378866Z"}]}
{"channel":"book","type":"update","data":[{"symbol":"BTC/CHF","bids":[{"price":61120.0,"qty":0.14478539}],"asks":[],"checksum":1941305200,"timestamp":"2024-06-01T22:42:27.379944Z"}]}
{"channel":"book","type":"update","data":[{"symbol":"BTC/CHF","bids":[{"price":61147.3,"qty":0.00000000},{"price":61118.0,"qty":0.10000000},{"price":61147.5,"qty":0.05547709}],"asks":[],"checksum":1595372562,"timestamp":"2024-06-01T22:42:27.415526Z"}]}
{"channel":"book","type":"update","data":[{"symbol":"BTC/CHF","bids":[],"asks":[{"price":61185.0,"qty":0.09452197}],"checksum":2736574957,"timestamp":"2024-06-01T22:42:28.165213Z"}]}
{"channel":"book","type":"update","data":[{"symbol":"BTC/CHF","bids":[],"asks":[{"price":61184.8,"qty":0.00242367}],"checksum":2748700979,"timestamp":"2024-06-01T22:42:28.166998Z"}]}
{"channel":"book","type":"update","data":[{"symbol":"BTC/CHF","bids":[],"asks":[{"price":61184.9,"qty":0.00000000},{"price":61203.7,"qty":0.10000000},{"price":61184.7,"qty":0.00313600}],"checksum":2050571909,"timestamp":"2024-06-01T22:42:28.234916Z"}]}
{"channel":"book","type":"update","data":[{"symbol":"BTC/CHF","bids":[],"asks":[{"price":61185.0,"qty":0.00000000},{"price":61203.7,"qty":0.10000000}],"checksum":737438003,"timestamp":"2024-06-01T22:42:28.402222Z"}]}
{"channel":"book","type":"update","data":[{"symbol":"BTC/CHF","bids":[],"asks":[{"price":61184.8,"qty":0.09694564}],"checksum":2995726750,"timestamp":"2024-06-01T22:42:28.407118Z"}]}
{"channel":"book","type":"update","data":[{"symbol":"BTC/CHF","bids":[],"asks":[{"price":61186.8,"qty":0.00000000},{"price":61207.9,"qty":0.00601000},{"price":61184.6,"qty":0.01495500}],"checksum":2035194286,"timestamp":"2024-06-01T22:42:28.818649Z"}]}
{"channel":"book","type":"update","data":[{"symbol":"BTC/CHF","bids":[],"asks":[{"price":61184.7,"qty":0.00000000},{"price":61207.9,"qty":0.00601000},{"price":61184.5,"qty":0.00313597}],"checksum":689875065,"timestamp":"2024-06-01T22:42:28.864559Z"}]}
{"channel":"book","type":"update","data":[{"symbol":"BTC/CHF","bids":[{"price":61119.9,"qty":0.00000000},{"price":61118.0,"qty":0.10000000}],"asks":[],"checksum":617509044,"timestamp":"2024-06-01T22:42:29.481111Z"}]}
{"channel":"book","type":"update","data":[{"symbol":"BTC/CHF","bids":[{"price":61134.6,"qty":0.04647930}],"asks":[],"checksum":2772604500,"timestamp":"2024-06-01T22:42:29.511437Z"}]}
{"channel":"book","type":"update","data":[{"symbol":"BTC/CHF","bids":[{"price":61134.6,"qty":0.00000000},{"price":61118.0,"qty":0.10000000}],"asks":[],"checksum":617509044,"timestamp":"2024-06-01T22:42:29.684778Z"}]}
{"channel":"book","type":"update","data":[{"symbol":"BTC/CHF","bids":[{"price":61147.4,"qty":0.00000000},{"price":61053.7,"qty":0.16916205}],"asks":[],"checksum":1589023957,"timestamp":"2024-06-01T22:42:29.907708Z"}]}
{"channel":"book","type":"update","data":[{"symbol":"BTC/CHF","bids":[{"price":61147.6,"qty":0.00115973}],"asks":[],"checksum":3138451916,"timestamp":"2024-06-01T22:42:29.908823Z"}]}
{"channel":"book","type":"update","data":[{"symbol":"BTC/CHF","bids":[{"price":61147.5,"qty":0.00000000},{"price":61053.7,"qty":0.16916205},{"price":61147.7,"qty":0.05547706}],"asks":[],"checksum":3263306018,"timestamp":"2024-06-01T22:42:29.964853Z"}]}
