{"channel":"book","type":"snapshot","data":[{"symbol":"BTC/CAD","bids":[{"price":92578.2,"qty":0.03218786},{"price":92578.1,"qty":0.04719084},{"price":92578.0,"qty":0.00075200},{"price":92577.8,"qty":0.00135100},{"price":92561.3,"qty":0.00450400},{"price":92555.7,"qty":0.01630000},{"price":92542.9,"qty":0.31201115},{"price":92526.2,"qty":0.04134020},{"price":92511.4,"qty":0.00728000},{"price":92406.4,"qty":0.00605761}],"asks":[{"price":92638.0,"qty":0.00602924},{"price":92638.1,"qty":0.04719084},{"price":92638.2,"qty":0.02953243},{"price":92638.7,"qty":0.00029532},{"price":92647.6,"qty":0.00571000},{"price":92668.2,"qty":0.74440101},{"price":92668.3,"qty":0.00251530},{"price":92668.8,"qty":0.07381000},{"price":92668.9,"qty":0.04134020},{"price":92670.2,"qty":0.00759000}],"checksum":2683407719}]}
{"channel":"book","type":"update","data":[{"symbol":"BTC/CAD","bids":[{"price":92578.2,"qty":0.00000000},{"price":92406.3,"qty":0.07379000},{"price":92555.8,"qty":0.03219565}],"asks":[],"checksum":4123234573,"timestamp":"2024-06-01T22:41:59.951619Z"}]}
{"channel":"book","type":"update","data":[{"symbol":"BTC/CAD","bids":[],"asks":[{"price":92637.9,"qty":0.04719084}],"checksum":3652915224,"timestamp":"2024-06-01T22:42:00.179189Z"}]}
{"channel":"book","type":"update","data":[{"symbol":"BTC/CAD","bids":[],"asks":[{"price":92668.8,"qty":0.00000000},{"price":92670.2,"qty":0.00759000},{"price":92668.1,"qty":0.07381000}],"checksum":3152342472,"timestamp":"2024-06-01T22:42:00.181959Z"}]}
{"channel":"book","type":"update","data":[{"symbol":"BTC/CAD","bids":[],"asks":[{"price":92638.1,"qty":0.00000000},{"price":92670.2,"qty":0.00759000}],"checksum":2309694682,"timestamp":"2024-06-01T22:42:00.184677Z"}]}
{"channel":"book","type":"update","data":[{"symbol":"BTC/CAD","bids":[],"asks":[{"price":92638.0,"qty":0.00000000},{"price":92683.5,"qty":0.05642020},{"price":92637.8,"qty":0.00602924}],"checksum":3808129153,"timestamp":"2024-06-01T22:42:00.242852Z"}]}
{"channel":"book","type":"update","data":[{"symbol":"BTC/CAD","bids":[{"price":92406.5,"qty":1.75821758}],"asks":[],"checksum":876701923,"timestamp":"2024-06-01T22:42:00.528258Z"}]}
{"channel":"book","type":"update","data":[{"symbol":"BTC/CAD","bids":[{"price":92406.6,"qty":0.07379000}],"asks":[],"checksum":2345238560,"timestamp":"2024-06-01T22:42:00.531644Z"}]}
{"channel":"book","type":"update","data":[{"symbol":"BTC/CAD","bids":[{"price":92406.6,"qty":0.27011769}],"asks":[],"checksum":3432057253,"timestamp":"2024-06-01T22:42:00.532009Z"}]}
{"channel":"book","type":"update","data":[{"symbol":"BTC/CAD","bids":[{"price":92406.7,"qty":0.07085431}],"asks":[],"checksum":1381110256,"timestamp":"2024-06-01T22:42:00.553826Z"}]}
{"channel":"book","type":"update","data":[{"symbol":"BTC/CAD","bids":[],"asks":[{"price":92638.7,"qty":0.00000000},{"price":92683.5,"qty":0.05642020}],"checksum":3830682844,"timestamp":"2024-06-01T22:42:00.622663Z"}]}
{"channel":"book","type":"update","data":[{"symbol":"BTC/CAD","bids":[],"asks":[{"price":92668.3,"qty":0.00000000},{"price":92692.5,"qty":0.08473671}],"checksum":2188965497,"timestamp":"2024-06-01T22:42:00.622801Z"}]}
{"channel":"book","type":"update","data":[{"symbol":"BTC/CAD","bids":[],"asks":[{"price":92637.8,"qty":0.00632456}],"checksum":2041885682,"timestamp":"2024-06-01T22:42:00.628189Z"}]}
{"channel":"book","type":"update","data":[{"symbol":"BTC/CAD","bids":[],"asks":[{"price":92668.0,"qty":0.00251530}],"checksum":1066864641,"timestamp":"2024-06-01T22:42:00.628451Z"}]}
{"channel":"book","type":"update","data":[{"symbol":"BTC/CAD","bids":[],"asks":[{"price":92637.8,"qty":0.00029532},{"price":92637.7,"qty":0.00602924}],"checksum":2527854348,"timestamp":"2024-06-01T22:42:00.719480Z"}]}
{"channel":"book","type":"update","data":[{"symbol":"BTC/CAD","bids":[],"asks":[{"price":92637.6,"qty":0.04719084}],"checksum":4171485082,"timestamp":"2024-06-01T22:42:01.178230Z"}]}
{"channel":"book","type":"update","data":[{"symbol":"BTC/CAD","bids":[{"price":92406.8,"qty":0.07379000}],"asks":[],"checksum":884100216,"timestamp":"2024-06-01T22:42:01.181184Z"}]}
{"channel":"book","type":"update","data":[{"symbol":"BTC/CAD","bids":[],"asks":[{"price":92637.9,"qty":0.00000000},{"price":92670.2,"qty":0.00759000}],"checksum":2594729795,"timestamp":"2024-06-01T22:42:01.183287Z"}]}
{"channel":"book","type":"update","data":[{"symbol":"BTC/CAD","bids":[],"asks":[{"price":92637.7,"qty":0.00000000},{"price":92683.5,"qty":0.05642020},{"price":92637.5,"qty":0.00602923}],"checksum":3881547036,"timestamp":"2024-06-01T22:42:01.215190Z"}]}
{"channel":"book","type":"update","data":[{"symbol":"BTC/CAD","bids":[],"asks":[{"price":92637.4,"qty":0.04719084}],"checksum":3698406341,"timestamp":"2024-06-01T22:42:01.220600Z"}]}
{"channel":"book","type":"update","data":[{"symbol":"BTC/CAD","bids":[],"asks":[{"price":92637.6,"qty":0.00000000},{"price":92670.2,"qty":0.00759000}],"checksum":3618138576,"timestamp":"2024-06-01T22:42:01.679326Z"}]}
{"channel":"book","type":"update","data":[{"symbol":"BTC/CAD","bids":[],"asks":[{"price":92637.5,"qty":0.00000000},{"price":92683.5,"qty":0.05642020},{"price":92637.3,"qty":0.00602923}],"checksum":3863543218,"timestamp":"2024-06-01T22:42:01.711548Z"}]}
{"channel":"book","type":"update","data":[{"symbol":"BTC/CAD","bids":[],"asks":[{"price":92637.2,"qty":0.04719084}],"checksum":3167644535,"timestamp":"2024-06-01T22:42:02.177292Z"}]}
{"channel":"book","type":"update","data":[{"symbol":"BTC/CAD","bids":[],"asks":[{"price":92637.4,"qty":0.00000000},{"price":92670.2,"qty":0.00759000}],"checksum":2797107033,"timestamp":"2024-06-01T22:42:02.182318Z"}]}
{"channel":"book","type":"update","data":[{"symbol":"BTC/CAD","bids":[],"asks":[{"price":92637.3,"qty":0.00000000},{"price":92683.5,"qty":0.05642020},{"price":92637.1,"qty":0.00602924}],"checksum":4130089299,"timestamp":"2024-06-01T22:42:02.226380Z"}]}
{"channel":"book","type":"update","data":[{"symbol":"BTC/CAD","bids":[],"asks":[{"price":92668.2,"qty":0.00000000},{"price":92683.5,"qty":0.05642020}],"checksum":3637355767,"timestamp":"2024-06-01T22:42:02.288236Z"}]}
{"channel":"book","type":"update","data":[{"symbol":"BTC/CAD","bids":[],"asks":[{"price":92638.2,"qty":0.00000000},{"price":92692.5,"qty":0.08473671}],"checksum":3748909654,"timestamp":"2024-06-01T22:42:02.288365Z"}]}
{"channel":"book","type":"update","data":[{"symbol":"BTC/CAD","bids":[],"asks":[{"price":92683.5,"qty":0.00000000},{"price":92692.6,"qty":0.07380000}],"checksum":3971875108,"timestamp":"2024-06-01T22:42:02.288509Z"}]}
{"channel":"book","type":"update","data":[{"symbol":"BTC/CAD","bids":[],"asks":[{"price":92668.1,"qty":0.00000000},{"price":92692.8,"qty":0.00686000},{"price":92668.8,"qty":0.07381000}],"checksum":1132666521,"timestamp":"2024-06-01T22:42:02.291688Z"}]}
{"channel":"book","type":"update","data":[{"symbol":"BTC/CAD","bids":[],"asks":[{"price":92692.6,"qty":0.00000000},{"price":92692.8,"qty":0.00686000},{"price":92683.4,"qty":0.07380000}],"checksum":204312789,"timestamp":"2024-06-01T22:42:02.291818Z"}]}
{"channel":"book","type":"update","data":[{"symbol":"BTC/CAD","bids":[],"asks":[{"price":92692.5,"qty":0.01096671},{"price":92683.4,"qty":0.14757000}],"checksum":3788113983,"timestamp":"2024-06-01T22:42:02.292002Z"}]}
{"channel":"book","type":"update","data":[{"symbol":"BTC/CAD","bids":[],"asks":[{"price":92637.2,"qty":0.07672327}],"checksum":2479809046,"timestamp":"2024-06-01T22:42:02.292882Z"}]}
{"channel":"book","type":"update","data":[{"symbol":"BTC/CAD","bids":[],"asks":[{"price":92692.4,"qty":0.29334523}],"checksum":497328665,"timestamp":"2024-06-01T22:42:02.293055Z"}]}
{"channel":"book","type":"update","data":[{"symbol":"BTC/CAD","bids":[],"asks":[{"price":92667.9,"qty":0.59276222}],"checksum":3621943327,"timestamp":"2024-06-01T22:42:02.293121Z"}]}
{"channel":"book","type":"update","data":[{"symbol":"BTC/CAD","bids":[{"price":92561.3,"qty":0.00000000},{"price":92406.7,"qty":0.07085431},{"price":92553.3,"qty":0.00450400}],"asks":[],"checksum":3721137921,"timestamp":"2024-06-01T22:42:02.735322Z"}]}
{"channel":"book","type":"update","data":[{"symbol":"BTC/CAD","bids":[{"price":92578.0,"qty":0.00000000},{"price":92406.7,"qty":0.07085431},{"price":92574.6,"qty":0.00075200}],"asks":[],"checksum":2888164944,"timestamp":"2024-06-01T22:42:02.739659Z"}]}
{"channel":"book","type":"update","data":[{"symbol":"BTC/CAD","bids":[{"price":92555.7,"qty":0.00000000},{"price":92406.7,"qty":0.07085431},{"price":92555.9,"qty":0.01630000}],"asks":[],"checksum":3333225977,"timestamp":"2024-06-01T22:42:02.771276Z"}]}
{"channel":"book","type":"update","data":[{"symbol":"BTC/CAD","bids":[{"price":92578.1,"qty":0.00000000},{"price":92406.7,"qty":0.07085431}],"asks":[],"checksum":1423128985,"timestamp":"2024-06-01T22:42:02.777468Z"}]}
{"channel":"book","type":"update","data":[{"symbol":"BTC/CAD","bids":[{"price":92555.8,"qty":0.00000000},{"price":92406.6,"qty":0.19632769},{"price":92556.0,"qty":0.03219339}],"asks":[],"checksum":1526010476,"timestamp":"2024-06-01T22:42:02.813251Z"}]}
{"channel":"book","type":"update","data":[{"symbol":"BTC/CAD","bids":[],"asks":[{"price":92668.8,"qty":0.00000000},{"price":92692.3,"qty":0.01096671},{"price":92667.8,"qty":0.07381000}],"checksum":1827012409,"timestamp":"2024-06-01T22:42:02.816122Z"}]}
{"channel":"book","type":"update","data":[{"symbol":"BTC/CAD","bids":[{"price":92555.9,"qty":0.00000000},{"price":92406.6,"qty":0.19632769},{"price":92556.1,"qty":0.01630000}],"asks":[],"checksum":1501479446,"timestamp":"2024-06-01T22:42:02.834372Z"}]}
{"channel":"book","type":"update","data":[{"symbol":"BTC/CAD","bids":[{"price":92406.9,"qty":0.00634574}],"asks":[],"checksum":493863529,"timestamp":"2024-06-01T22:42:02.889141Z"}]}
{"channel":"book","type":"update","data":[{"symbol":"BTC/CAD","bids":[{"price":92526.2,"qty":0.00000000},{"price":92406.7,"qty":0.07085431},{"price":92500.1,"qty":0.04134020}],"asks":[],"checksum":3451908143,"timestamp":"2024-06-01T22:42:02.926701Z"}]}
{"channel":"book","type":"update","data":[{"symbol":"BTC/CAD","bids":[],"asks":[{"price":92637.0,"qty":0.04719084}],"checksum":4109259751,"timestamp":"2024-06-01T22:42:03.179228Z"}]}
{"channel":"book","type":"update","data":[{"symbol":"BTC/CAD","bids":[],"asks":[{"price":92637.2,"qty":0.02953243}],"checksum":1028360003,"timestamp":"2024-06-01T22:42:03.185973Z"}]}
{"channel":"book","type":"update","data":[{"symbol":"BTC/CAD","bids":[],"asks":[{"price":92637.1,"qty":0.00000000},{"price":92683.4,"qty":0.14757000},{"price":92636.9,"qty":0.00602943}],"checksum":191792648,"timestamp":"2024-06-01T22:42:03.236511Z"}]}
{"channel":"book","type":"update","data":[{"symbol":"BTC/CAD","bids":[],"asks":[{"price":92668.0,"qty":0.00000000},{"price":92683.4,"qty":0.14757000}],"checksum":2370172781,"timestamp":"2024-06-01T22:42:03.343004Z"}]}
{"channel":"book","type":"update","data":[{"symbol":"BTC/CAD","bids":[],"asks":[{"price":92637.8,"qty":0.00000000},{"price":92692.3,"qty":0.01096671}],"checksum":280569809,"timestamp":"2024-06-01T22:42:03.343106Z"}]}
{"channel":"book","type":"update","data":[{"symbol":"BTC/CAD","bids":[],"asks":[{"price":92667.7,"qty":0.00251530}],"checksum":1734865769,"timestamp":"2024-06-01T22:42:03.347976Z"}]}
{"channel":"book","type":"update","data":[{"symbol":"BTC/CAD","bids":[],"asks":[{"price":92637.0,"qty":0.04748617}],"checksum":3304569398,"timestamp":"2024-06-01T22:42:03.348198Z"}]}
{"channel":"book","type":"update","data":[{"symbol":"BTC/CAD","bids":[{"price":92407.0,"qty":1.87346979}],"asks":[],"checksum":4068317782,"timestamp":"2024-06-01T22:42:03.380193Z"}]}
{"channel":"book","type":"update","data":[{"symbol":"BTC/CAD","bids":[{"price":92407.1,"qty":0.07379000}],"asks":[],"checksum":426093575,"timestamp":"2024-06-01T22:42:03.383149Z"}]}
{"channel":"book","type":"update","data":[{"symbol":"BTC/CAD","bids":[{"price":92407.1,"qty":0.27011769}],"asks":[],"checksum":3484008721,"timestamp":"2024-06-01T22:42:03.383599Z"}]}
{"channel":"book","type":"update","data":[{"symbol":"BTC/CAD","bids":[{"price":92407.2,"qty":0.07085393}],"asks":[],"checksum":245276088,"timestamp":"2024-06-01T22:42:03.391416Z"}]}
{"channel":"book","type":"update","data":[{"symbol":"BTC/CAD","bids":[{"price":92556.0,"qty":0.00000000},{"price":92407.0,"qty":1.87346979},{"price":92556.2,"qty":0.03219332}],"asks":[],"checksum":131040969,"timestamp":"2024-06-01T22:42:03.709108Z"}]}
{"channel":"book","type":"update","data":[{"symbol":"BTC/CAD","bids":[],"asks":[{"price":92636.9,"qty":0.00000000},{"price":92692.3,"qty":0.01096671},{"price":92636.9,"qty":0.00724614}],"checksum":3504291327,"timestamp":"2024-06-01T22:42:03.709365Z"}]}
{"channel":"book","type":"update","data":[{"symbol":"BTC/CAD","bids":[{"price":92556.1,"qty":0.00000000},{"price":92407.0,"qty":1.87346979},{"price":92556.3,"qty":0.01630000}],"asks":[],"checksum":3900663910,"timestamp":"2024-06-01T22:42:03.719760Z"}]}
{"channel":"book","type":"update","data":[{"symbol":"BTC/CAD","bids":[{"price":92542.9,"qty":0.00000000},{"price":92407.0,"qty":1.87346979}],"asks":[],"checksum":112471480,"timestamp":"2024-06-01T22:42:03.876135Z"}]}
{"channel":"book","type":"update","data":[{"symbol":"BTC/CAD","bids":[{"price":92407.3,"qty":0.07377000}],"asks":[],"checksum":2597969252,"timestamp":"2024-06-01T22:42:03.878954Z"}]}
{"channel":"book","type":"update","data":[{"symbol":"BTC/CAD","bids":[{"price":92538.5,"qty":0.31202598}],"asks":[],"checksum":3246870310,"timestamp":"2024-06-01T22:42:03.880653Z"}]}
{"channel":"book","type":"update","data":[{"symbol":"BTC/CAD","bids":[{"price":92407.4,"qty":0.07379000}],"asks":[],"checksum":3249424424,"timestamp":"2024-06-01T22:42:03.883925Z"}]}
{"channel":"book","type":"update","data":[{"symbol":"BTC/CAD","bids":[{"price":92407.5,"qty":0.07085370}],"asks":[],"checksum":3331736804,"timestamp":"2024-06-01T22:42:03.889385Z"}]}
{"channel":"book","type":"update","data":[{"symbol":"BTC/CAD","bids":[{"price":92556.2,"qty":0.00000000},{"price":92407.3,"qty":0.07377000},{"price":92556.4,"qty":0.03219325}],"asks":[],"checksum":820634307,"timestamp":"2024-06-01T22:42:04.164153Z"}]}
{"channel":"book","type":"update","data":[{"symbol":"BTC/CAD","bids":[{"price":92568.2,"qty":0.04719084}],"asks":[],"checksum":3487165405,"timestamp":"2024-06-01T22:42:04.169852Z"}]}
{"channel":"book","type":"update","data":[{"symbol":"BTC/CAD","bids":[],"asks":[{"price":92636.8,"qty":0.04719084}],"checksum":2491886808,"timestamp":"2024-06-01T22:42:04.169884Z"}]}
{"channel":"book","type":"update","data":[{"symbol":"BTC/CAD","bids":[],"asks":[{"price":92637.0,"qty":0.00029533}],"checksum":3036719819,"timestamp":"2024-06-01T22:42:04.175066Z"}]}
{"channel":"book","type":"update","data":[{"symbol":"BTC/CAD","bids":[],"asks":[{"price":92636.9,"qty":0.00000000},{"price":92683.4,"qty":0.14757000},{"price":92636.7,"qty":0.00724614}],"checksum":3093609424,"timestamp":"2024-06-01T22:42:04.659500Z"}]}
{"channel":"book","type":"update","data":[{"symbol":"BTC/CAD","bids":[{"price":92407.6,"qty":0.07379000}],"asks":[],"checksum":905891434,"timestamp":"2024-06-01T22:42:04.662361Z"}]}
{"channel":"book","type":"update","data":[{"symbol":"BTC/CAD","bids":[],"asks":[{"price":92637.2,"qty":0.00000000},{"price":92683.4,"qty":0.14757000}],"checksum":65859308,"timestamp":"2024-06-01T22:42:04.914927Z"}]}
{"channel":"book","type":"update","data":[{"symbol":"BTC/CAD","bids":[],"asks":[{"price":92667.9,"qty":0.00000000},{"price":92692.3,"qty":0.01096671}],"checksum":62882157,"timestamp":"2024-06-01T22:42:04.915047Z"}]}
{"channel":"book","type":"update","data":[{"symbol":"BTC/CAD","bids":[],"asks":[{"price":92667.8,"qty":0.00000000},{"price":92692.8,"qty":0.00686000},{"price":92668.8,"qty":0.07381000}],"checksum":1135413763,"timestamp":"2024-06-01T22:42:04.918303Z"}]}
{"channel":"book","type":"update","data":[{"symbol":"BTC/CAD","bids":[],"asks":[{"price":92636.7,"qty":0.03678005}],"checksum":2028554464,"timestamp":"2024-06-01T22:42:04.920691Z"}]}
{"channel":"book","type":"update","data":[{"symbol":"BTC/CAD","bids":[],"asks":[{"price":92683.3,"qty":0.12110530}],"checksum":740203156,"timestamp":"2024-06-01T22:42:04.920735Z"}]}
{"channel":"book","type":"update","data":[{"symbol":"BTC/CAD","bids":[],"asks":[{"price":92667.6,"qty":0.61442638}],"checksum":643600979,"timestamp":"2024-06-01T22:42:04.920836Z"}]}
{"channel":"book","type":"update","data":[{"symbol":"BTC/CAD","bids":[{"price":92556.4,"qty":0.00000000},{"price":92407.5,"qty":0.07085370},{"price":92568.3,"qty":0.03218901}],"asks":[],"checksum":640882528,"timestamp":"2024-06-01T22:42:05.166230Z"}]}
{"channel":"book","type":"update","data":[{"symbol":"BTC/CAD","bids":[],"asks":[{"price":92636.6,"qty":0.04719084}],"checksum":1985291291,"timestamp":"2024-06-01T22:42:05.171657Z"}]}
{"channel":"book","type":"update","data":[{"symbol":"BTC/CAD","bids":[{"price":92568.3,"qty":0.00000000},{"price":92407.5,"qty":0.07085370},{"price":92568.4,"qty":0.03218897}],"asks":[],"checksum":2487065536,"timestamp":"2024-06-01T22:42:05.615070Z"}]}
{"channel":"book","type":"update","data":[{"symbol":"BTC/CAD","bids":[],"asks":[{"price":92668.8,"qty":0.00000000},{"price":92683.3,"qty":0.12110530},{"price":92667.5,"qty":0.07381000}],"checksum":1143845510,"timestamp":"2024-06-01T22:42:05.618096Z"}]}
{"channel":"book","type":"update","data":[{"symbol":"BTC/CAD","bids":[],"asks":[{"price":92636.8,"qty":0.00000000},{"price":92683.3,"qty":0.12110530}],"checksum":3593746200,"timestamp":"2024-06-01T22:42:05.620141Z"}]}
{"channel":"book","type":"update","data":[{"symbol":"BTC/CAD","bids":[{"price":92568.4,"qty":0.00000000},{"price":92407.5,"qty":0.07085370},{"price":92568.3,"qty":0.03218901}],"asks":[],"checksum":878479555,"timestamp":"2024-06-01T22:42:05.626558Z"}]}
{"channel":"book","type":"update","data":[{"symbol":"BTC/CAD","bids":[{"price":92577.8,"qty":0.00000000},{"price":92407.5,"qty":0.07085370},{"price":92573.5,"qty":0.00135100}],"asks":[],"checksum":3047285689,"timestamp":"2024-06-01T22:42:05.824787Z"}]}
{"channel":"book","type":"update","data":[{"symbol":"BTC/CAD","bids":[{"price":92568.3,"qty":0.00000000},{"price":92407.5,"qty":0.07085370},{"price":92556.4,"qty":0.03219315}],"asks":[],"checksum":1774583673,"timestamp":"2024-06-01T22:42:05.868678Z"}]}
{"channel":"book","type":"update","data":[{"symbol":"BTC/CAD","bids":[{"price":92556.4,"qty":0.00000000},{"price":92407.5,"qty":0.07085370},{"price":92538.6,"qty":0.03219934}],"asks":[],"checksum":2003847628,"timestamp":"2024-06-01T22:42:05.933276Z"}]}
{"channel":"book","type":"update","data":[{"symbol":"BTC/CAD","bids":[],"asks":[{"price":92667.7,"qty":0.00000000},{"price":92683.4,"qty":0.14757000}],"checksum":346086025,"timestamp":"2024-06-01T22:42:06.101410Z"}]}
{"channel":"book","type":"update","data":[{"symbol":"BTC/CAD","bids":[],"asks":[{"price":92637.0,"qty":0.00000000},{"price":92692.3,"qty":0.01096671}],"checksum":523201386,"timestamp":"2024-06-01T22:42:06.101600Z"}]}
{"channel":"book","type":"update","data":[{"symbol":"BTC/CAD","bids":[],"asks":[{"price":92667.4,"qty":0.00281064}],"checksum":431232485,"timestamp":"2024-06-01T22:42:06.103966Z"}]}
{"channel":"book","type":"update","data":[{"symbol":"BTC/CAD","bids":[{"price":92574.7,"qty":0.04719084}],"asks":[],"checksum":2592193224,"timestamp":"2024-06-01T22:42:06.107627Z"}]}
{"channel":"book","type":"update","data":[{"symbol":"BTC/CAD","bids":[{"price":92556.3,"qty":0.00000000},{"price":92407.6,"qty":0.07379000},{"price":92574.8,"qty":0.01630000}],"asks":[],"checksum":3445066439,"timestamp":"2024-06-01T22:42:06.125171Z"}]}
{"channel":"book","type":"update","data":[{"symbol":"BTC/CAD","bids":[],"asks":[{"price":92636.7,"qty":0.02953391},{"price":92636.5,"qty":0.00724620}],"checksum":1018843133,"timestamp":"2024-06-01T22:42:06.140062Z"}]}
{"channel":"book","type":"update","data":[{"symbol":"BTC/CAD","bids":[{"price":92538.6,"qty":0.00000000},{"price":92407.6,"qty":0.07379000},{"price":92538.7,"qty":0.03219930}],"asks":[],"checksum":2235696967,"timestamp":"2024-06-01T22:42:06.140295Z"}]}
{"channel":"book","type":"update","data":[{"symbol":"BTC/CAD","bids":[{"price":92574.7,"qty":0.00000000},{"price":92407.6,"qty":0.07379000}],"asks":[],"checksum":2657471670,"timestamp":"2024-06-01T22:42:06.146287Z"}]}
{"channel":"book","type":"update","data":[{"symbol":"BTC/CAD","bids":[{"price":92538.7,"qty":0.00000000},{"price":92407.5,"qty":0.07085370},{"price":92538.6,"qty":0.03219934}],"asks":[],"checksum":1957004668,"timestamp":"2024-06-01T22:42:06.197123Z"}]}
{"channel":"book","type":"update","data":[{"symbol":"BTC/CAD","bids":[{"price":92574.8,"qty":0.00000000},{"price":92407.5,"qty":0.07085370},{"price":92538.7,"qty":0.01630000}],"asks":[],"checksum":121669106,"timestamp":"2024-06-01T22:42:06.218783Z"}]}
{"channel":"book","type":"update","data":[{"symbol":"BTC/CAD","bids":[{"price":92407.7,"qty":1.78711891}],"asks":[],"checksum":4207181333,"timestamp":"2024-06-01T22:42:06.233583Z"}]}
{"channel":"book","type":"update","data":[{"symbol":"BTC/CAD","bids":[{"price":92407.8,"qty":0.07379000}],"asks":[],"checksum":315267008,"timestamp":"2024-06-01T22:42:06.236745Z"}]}
{"channel":"book","type":"update","data":[{"symbol":"BTC/CAD","bids":[{"price":92407.8,"qty":0.27011769}],"asks":[],"checksum":1812129994,"timestamp":"2024-06-01T22:42:06.237047Z"}]}
{"channel":"book","type":"update","data":[{"symbol":"BTC/CAD","bids":[{"price":92407.9,"qty":0.07085339}],"asks":[],"checksum":3234175143,"timestamp":"2024-06-01T22:42:06.242807Z"}]}
{"channel":"book","type":"update","data":[{"symbol":"BTC/CAD","bids":[{"price":92573.5,"qty":0.00000000},{"price":92407.8,"qty":0.27011769},{"price":92568.7,"qty":0.00135100}],"asks":[],"checksum":1256065288,"timestamp":"2024-06-01T22:42:06.398886Z"}]}
{"channel":"book","type":"update","data":[{"symbol":"BTC/CAD","bids":[{"price":92538.6,"qty":0.00000000},{"price":92407.8,"qty":0.27011769},{"price":92538.8,"qty":0.03219927}],"asks":[],"checksum":3981120005,"timestamp":"2024-06-01T22:42:06.745947Z"}]}
{"channel":"book","type":"update","data":[{"symbol":"BTC/CAD","bids":[{"price":92408.0,"qty":0.07379000}],"asks":[],"checksum":857262342,"timestamp":"2024-06-01T22:42:06.748907Z"}]}
{"channel":"book","type":"update","data":[{"symbol":"BTC/CAD","bids":[{"price":92538.7,"qty":0.00000000},{"price":92407.9,"qty":0.07085339},{"price":92538.9,"qty":0.01630000}],"asks":[],"checksum":2878264881,"timestamp":"2024-06-01T22:42:06.767410Z"}]}
{"channel":"book","type":"update","data":[{"symbol":"BTC/CAD","bids":[],"asks":[{"price":92636.4,"qty":0.04719084}],"checksum":4225987134,"timestamp":"2024-06-01T22:42:07.177468Z"}]}
{"channel":"book","type":"update","data":[{"symbol":"BTC/CAD","bids":[{"price":92574.7,"qty":0.04719084}],"asks":[],"checksum":2532130748,"timestamp":"2024-06-01T22:42:07.177627Z"}]}
{"channel":"book","type":"update","data":[{"symbol":"BTC/CAD","bids":[],"asks":[{"price":92636.6,"qty":0.00000000},{"price":92683.3,"qty":0.12110530}],"checksum":1331492137,"timestamp":"2024-06-01T22:42:07.183472Z"}]}
{"channel":"book","type":"update","data":[{"symbol":"BTC/CAD","bids":[{"price":92568.2,"qty":0.00000000},{"price":92408.0,"qty":0.07379000}],"asks":[],"checksum":204424055,"timestamp":"2024-06-01T22:42:07.183613Z"}]}
{"channel":"book","type":"update","data":[{"symbol":"BTC/CAD","bids":[],"asks":[{"price":92636.5,"qty":0.00000000},{"price":92683.4,"qty":0.14757000},{"price":92636.3,"qty":0.00724618}],"checksum":2766322140,"timestamp":"2024-06-01T22:42:07.426740Z"}]}
{"channel":"book","type":"update","data":[{"symbol":"BTC/CAD","bids":[{"price":92538.8,"qty":0.00000000},{"price":92407.9,"qty":0.07085339},{"price":92539.0,"qty":0.03219901}],"asks":[],"checksum":2503532266,"timestamp":"2024-06-01T22:42:07.426765Z"}]}
{"channel":"book","type":"update","data":[{"symbol":"BTC/CAD","bids":[{"price":92538.9,"qty":0.00000000},{"price":92407.9,"qty":0.07085339},{"price":92539.1,"qty":0.01630000}],"asks":[],"checksum":3540415322,"timestamp":"2024-06-01T22:42:07.436287Z"}]}
{"channel":"book","type":"update","data":[{"symbol":"BTC/CAD","bids":[],"asks":[{"price":92667.6,"qty":0.00000000},{"price":92683.4,"qty":0.14757000}],"checksum":1111891931,"timestamp":"2024-06-01T22:42:07.494142Z"}]}
{"channel":"book","type":"update","data":[{"symbol":"BTC/CAD","bids":[],"asks":[{"price":92636.7,"qty":0.00000000},{"price":92692.3,"qty":0.01096671}],"checksum":592742620,"timestamp":"2024-06-01T22:42:07.494379Z"}]}
{"channel":"book","type":"update","data":[{"symbol":"BTC/CAD","bids":[],"asks":[{"price":92683.4,"qty":0.07380000},{"price":92683.2,"qty":0.07377000}],"checksum":3484891244,"timestamp":"2024-06-01T22:42:07.497480Z"}]}
{"channel":"book","type":"update","data":[{"symbol":"BTC/CAD","bids":[],"asks":[{"price":92667.5,"qty":0.00000000},{"price":92692.3,"qty":0.01096671},{"price":92668.8,"qty":0.07381000}],"checksum":3886905489,"timestamp":"2024-06-01T22:42:07.497823Z"}]}
{"channel":"book","type":"update","data":[{"symbol":"BTC/CAD","bids":[],"asks":[{"price":92636.4,"qty":0.07672475}],"checksum":2881442512,"timestamp":"2024-06-01T22:42:07.499176Z"}]}
{"channel":"book","type":"update","data":[{"symbol":"BTC/CAD","bids":[],"asks":[{"price":92667.3,"qty":0.61442638}],"checksum":2305923664,"timestamp":"2024-06-01T22:42:07.499331Z"}]}
{"channel":"book","type":"update","data":[{"symbol":"BTC/CAD","bids":[{"price":92539.0,"qty":0.00000000},{"price":92407.9,"qty":0.07085339},{"price":92539.2,"qty":0.03219894}],"asks":[],"checksum":2318007201,"timestamp":"2024-06-01T22:42:08.086712Z"}]}
{"channel":"book","type":"update","data":[{"symbol":"BTC/CAD","bids":[],"asks":[{"price":92668.8,"qty":0.00000000},{"price":92683.4,"qty":0.07380000},{"price":92667.2,"qty":0.07381000}],"checksum":2853247845,"timestamp":"2024-06-01T22:42:08.089720Z"}]}
{"channel":"book","type":"update","data":[{"symbol":"BTC/CAD","bids":[],"asks":[{"price":92636.2,"qty":0.04719084}],"checksum":2482293531,"timestamp":"2024-06-01T22:42:08.092014Z"}]}
{"channel":"book","type":"update","data":[{"symbol":"BTC/CAD","bids":[{"price":92539.1,"qty":0.00000000},{"price":92407.9,"qty":0.07085339},{"price":92539.3,"qty":0.01630000}],"asks":[],"checksum":2597531642,"timestamp":"2024-06-01T22:42:08.103956Z"}]}
{"channel":"book","type":"update","data":[{"symbol":"BTC/CAD","bids":[],"asks":[{"price":92636.4,"qty":0.02953391}],"checksum":1862729312,"timestamp":"2024-06-01T22:42:08.176818Z"}]}
{"channel":"book","type":"update","data":[{"symbol":"BTC/CAD","bids":[{"price":92539.2,"qty":0.00000000},{"price":92407.9,"qty":0.07085339},{"price":92539.4,"qty":0.03219887}],"asks":[],"checksum":582406208,"timestamp":"2024-06-01T22:42:08.704872Z"}]}
{"channel":"book","type":"update","data":[{"symbol":"BTC/CAD","bids":[],"asks":[{"price":92636.3,"qty":0.00000000},{"price":92683.3,"qty":0.12110530},{"price":92636.1,"qty":0.00724618}],"checksum":1071731335,"timestamp":"2024-06-01T22:42:08.704949Z"}]}
{"channel":"book","type":"update","data":[{"symbol":"BTC/CAD","bids":[{"price":92539.3,"qty":0.00000000},{"price":92407.9,"qty":0.07085339},{"price":92539.5,"qty":0.01630000}],"asks":[],"checksum":2128472788,"timestamp":"2024-06-01T22:42:08.712534Z"}]}
{"channel":"book","type":"update","data":[{"symbol":"BTC/CAD","bids":[],"asks":[{"price":92667.4,"qty":0.00000000},{"price":92683.3,"qty":0.12110530}],"checksum":2433779248,"timestamp":"2024-06-01T22:42:08.851804Z"}]}
{"channel":"book","type":"update","data":[{"symbol":"BTC/CAD","bids":[],"asks":[{"price":92667.1,"qty":0.00281064}],"checksum":3680409129,"timestamp":"2024-06-01T22:42:08.856601Z"}]}
{"channel":"book","type":"update","data":[{"symbol":"BTC/CAD","bids":[{"price":92408.1,"qty":1.72949318}],"asks":[],"checksum":852016109,"timestamp":"2024-06-01T22:42:09.133747Z"}]}
{"channel":"book","type":"update","data":[{"symbol":"BTC/CAD","bids":[{"price":92408.2,"qty":0.07379000}],"asks":[],"checksum":2575012180,"timestamp":"2024-06-01T22:42:09.136702Z"}]}
{"channel":"book","type":"update","data":[{"symbol":"BTC/CAD","bids":[{"price":92408.2,"qty":0.27011769}],"asks":[],"checksum":2615873169,"timestamp":"2024-06-01T22:42:09.136853Z"}]}
{"channel":"book","type":"update","data":[{"symbol":"BTC/CAD","bids":[{"price":92408.3,"qty":0.07085308}],"asks":[],"checksum":392101222,"timestamp":"2024-06-01T22:42:09.145460Z"}]}
{"channel":"book","type":"update","data":[{"symbol":"BTC/CAD","bids":[],"asks":[{"price":92636.0,"qty":0.04719084}],"checksum":2526474919,"timestamp":"2024-06-01T22:42:09.178392Z"}]}
{"channel":"book","type":"update","data":[{"symbol":"BTC/CAD","bids":[],"asks":[{"price":92636.2,"qty":0.00000000},{"price":92683.2,"qty":0.07377000}],"checksum":3004979377,"timestamp":"2024-06-01T22:42:09.183321Z"}]}
{"channel":"book","type":"update","data":[{"symbol":"BTC/CAD","bids":[],"asks":[{"price":92636.1,"qty":0.00000000},{"price":92683.3,"qty":0.12110530},{"price":92635.9,"qty":0.00724649}],"checksum":779952128,"timestamp":"2024-06-01T22:42:09.395446Z"}]}
{"channel":"book","type":"update","data":[{"symbol":"BTC/CAD","bids":[{"price":92539.4,"qty":0.00000000},{"price":92408.2,"qty":0.27011769},{"price":92539.6,"qty":0.03219881}],"asks":[],"checksum":3889619948,"timestamp":"2024-06-01T22:42:09.395565Z"}]}
{"channel":"book","type":"update","data":[{"symbol":"BTC/CAD","bids":[{"price":92539.5,"qty":0.00000000},{"price":92408.2,"qty":0.27011769},{"price":92539.7,"qty":0.01630000}],"asks":[],"checksum":2313167557,"timestamp":"2024-06-01T22:42:09.411863Z"}]}
{"channel":"book","type":"update","data":[{"symbol":"BTC/CAD","bids":[{"price":92408.4,"qty":0.00605791}],"asks":[],"checksum":1319005187,"timestamp":"2024-06-01T22:42:09.792697Z"}]}
{"channel":"book","type":"update","data":[{"symbol":"BTC/CAD","bids":[{"price":92408.4,"qty":0.07984791}],"asks":[],"checksum":3011622464,"timestamp":"2024-06-01T22:42:09.795191Z"}]}
{"channel":"book","type":"update","data":[{"symbol":"BTC/CAD","bids":[{"price":92539.6,"qty":0.00000000},{"price":92408.3,"qty":0.07085308},{"price":92539.8,"qty":0.03219874}],"asks":[],"checksum":231591627,"timestamp":"2024-06-01T22:42:10.073042Z"}]}
{"channel":"book","type":"update","data":[{"symbol":"BTC/CAD","bids":[],"asks":[{"price":92636.4,"qty":0.00000000},{"price":92683.4,"qty":0.07380000}],"checksum":3861467735,"timestamp":"2024-06-01T22:42:10.074212Z"}]}
{"channel":"book","type":"update","data":[{"symbol":"BTC/CAD","bids":[],"asks":[{"price":92667.3,"qty":0.00000000},{"price":92692.3,"qty":0.01096671}],"checksum":2479002924,"timestamp":"2024-06-01T22:42:10.074379Z"}]}
{"channel":"book","type":"update","data":[{"symbol":"BTC/CAD","bids":[],"asks":[{"price":92667.2,"qty":0.00000000},{"price":92692.8,"qty":0.00686000},{"price":92668.8,"qty":0.07381000}],"checksum":2546954896,"timestamp":"2024-06-01T22:42:10.077593Z"}]}
{"channel":"book","type":"update","data":[{"symbol":"BTC/CAD","bids":[],"asks":[{"price":92683.2,"qty":0.00000000},{"price":92692.8,"qty":0.00686000},{"price":92683.3,"qty":0.07377000}],"checksum":1956333936,"timestamp":"2024-06-01T22:42:10.077676Z"}]}
{"channel":"book","type":"update","data":[{"symbol":"BTC/CAD","bids":[],"asks":[{"price":92683.4,"qty":0.00000000},{"price":92692.8,"qty":0.00686000},{"price":92692.2,"qty":0.07380000}],"checksum":2239287171,"timestamp":"2024-06-01T22:42:10.077916Z"}]}
{"channel":"book","type":"update","data":[{"symbol":"BTC/CAD","bids":[],"asks":[{"price":92667.0,"qty":0.61442638}],"checksum":3431977726,"timestamp":"2024-06-01T22:42:10.079141Z"}]}
{"channel":"book","type":"update","data":[{"symbol":"BTC/CAD","bids":[],"asks":[{"price":92635.8,"qty":0.02953391}],"checksum":1494616687,"timestamp":"2024-06-01T22:42:10.079163Z"}]}
{"channel":"book","type":"update","data":[{"symbol":"BTC/CAD","bids":[],"asks":[{"price":92683.1,"qty":0.12110530}],"checksum":1628024986,"timestamp":"2024-06-01T22:42:10.079283Z"}]}
{"channel":"book","type":"update","data":[{"symbol":"BTC/CAD","bids":[],"asks":[{"price":92635.8,"qty":0.07672475}],"checksum":1487747397,"timestamp":"2024-06-01T22:42:10.079727Z"}]}
{"channel":"book","type":"update","data":[{"symbol":"BTC/CAD","bids":[{"price":92539.7,"qty":0.00000000},{"price":92408.3,"qty":0.07085308},{"price":92539.9,"qty":0.01630000}],"asks":[],"checksum":212884023,"timestamp":"2024-06-01T22:42:10.080068Z"}]}
{"channel":"book","type":"update","data":[{"symbol":"BTC/CAD","bids":[],"asks":[{"price":92636.0,"qty":0.00000000},{"price":92683.3,"qty":0.07377000}],"checksum":2291454368,"timestamp":"2024-06-01T22:42:10.176763Z"}]}
{"channel":"book","type":"update","data":[{"symbol":"BTC/CAD","bids":[],"asks":[{"price":92668.8,"qty":0.00000000},{"price":92692.2,"qty":0.07380000},{"price":92666.9,"qty":0.07381000}],"checksum":3827942845,"timestamp":"2024-06-01T22:42:10.588677Z"}]}
{"channel":"book","type":"update","data":[{"symbol":"BTC/CAD","bids":[{"price":92539.8,"qty":0.00000000},{"price":92408.3,"qty":0.07085308},{"price":92540.0,"qty":0.03219867}],"asks":[],"checksum":793093257,"timestamp":"2024-06-01T22:42:10.714551Z"}]}
{"channel":"book","type":"update","data":[{"symbol":"BTC/CAD","bids":[],"asks":[{"price":92635.9,"qty":0.00000000},{"price":92692.2,"qty":0.07380000},{"price":92635.7,"qty":0.00724649}],"checksum":1436220621,"timestamp":"2024-06-01T22:42:10.714703Z"}]}
{"channel":"book","type":"update","data":[{"symbol":"BTC/CAD","bids":[{"price":92539.9,"qty":0.00000000},{"price":92408.3,"qty":0.07085308},{"price":92540.1,"qty":0.01630000}],"asks":[],"checksum":2528009669,"timestamp":"2024-06-01T22:42:10.748616Z"}]}
{"channel":"book","type":"update","data":[{"symbol":"BTC/CAD","bids":[],"asks":[{"price":92635.6,"qty":0.04719084}],"checksum":4017156258,"timestamp":"2024-06-01T22:42:10.753942Z"}]}
{"channel":"book","type":"update","data":[{"symbol":"BTC/CAD","bids":[],"asks":[{"price":92683.0,"qty":0.01096671}],"checksum":1988905457,"timestamp":"2024-06-01T22:42:10.825139Z"}]}
{"channel":"book","type":"update","data":[{"symbol":"BTC/CAD","bids":[],"asks":[{"price":92635.8,"qty":0.02953391}],"checksum":2203687019,"timestamp":"2024-06-01T22:42:11.176022Z"}]}
{"channel":"book","type":"update","data":[{"symbol":"BTC/CAD","bids":[],"asks":[{"price":92635.7,"qty":0.00000000},{"price":92683.1,"qty":0.12110530},{"price":92635.5,"qty":0.00724644}],"checksum":834234796,"timestamp":"2024-06-01T22:42:11.400096Z"}]}
{"channel":"book","type":"update","data":[{"symbol":"BTC/CAD","bids":[{"price":92540.0,"qty":0.00000000},{"price":92408.3,"qty":0.07085308},{"price":92540.2,"qty":0.03219857}],"asks":[],"checksum":4212830970,"timestamp":"2024-06-01T22:42:11.400125Z"}]}
{"channel":"book","type":"update","data":[{"symbol":"BTC/CAD","bids":[],"asks":[{"price":92635.4,"qty":0.04719084}],"checksum":1458874707,"timestamp":"2024-06-01T22:42:11.405771Z"}]}
{"channel":"book","type":"update","data":[{"symbol":"BTC/CAD","bids":[{"price":92540.1,"qty":0.00000000},{"price":92408.3,"qty":0.07085308},{"price":92540.3,"qty":0.01630000}],"asks":[],"checksum":3833998813,"timestamp":"2024-06-01T22:42:11.418171Z"}]}
{"channel":"book","type":"update","data":[{"symbol":"BTC/CAD","bids":[],"asks":[{"price":92667.1,"qty":0.00000000},{"price":92683.0,"qty":0.01096671}],"checksum":3322946102,"timestamp":"2024-06-01T22:42:11.665860Z"}]}
{"channel":"book","type":"update","data":[{"symbol":"BTC/CAD","bids":[],"asks":[{"price":92666.8,"qty":0.00281064}],"checksum":95148547,"timestamp":"2024-06-01T22:42:11.670358Z"}]}
{"channel":"book","type":"update","data":[{"symbol":"BTC/CAD","bids":[],"asks":[{"price":92635.6,"qty":0.00000000},{"price":92683.0,"qty":0.01096671}],"checksum":778468051,"timestamp":"2024-06-01T22:42:11.677875Z"}]}
{"channel":"book","type":"update","data":[{"symbol":"BTC/CAD","bids":[{"price":92408.5,"qty":1.75830604}],"asks":[],"checksum":3077484243,"timestamp":"2024-06-01T22:42:12.002341Z"}]}
{"channel":"book","type":"update","data":[{"symbol":"BTC/CAD","bids":[{"price":92408.6,"qty":0.07379000}],"asks":[],"checksum":510168222,"timestamp":"2024-06-01T22:42:12.005283Z"}]}
{"channel":"book","type":"update","data":[{"symbol":"BTC/CAD","bids":[{"price":92408.6,"qty":0.27011769}],"asks":[],"checksum":3772593698,"timestamp":"2024-06-01T22:42:12.005632Z"}]}
{"channel":"book","type":"update","data":[{"symbol":"BTC/CAD","bids":[{"price":92408.7,"qty":0.07085278}],"asks":[],"checksum":3738049628,"timestamp":"2024-06-01T22:42:12.015465Z"}]}
{"channel":"book","type":"update","data":[{"symbol":"BTC/CAD","bids":[],"asks":[{"price":92635.5,"qty":0.00000000},{"price":92683.1,"qty":0.12110530},{"price":92635.3,"qty":0.00724644}],"checksum":125351167,"timestamp":"2024-06-01T22:42:12.089972Z"}]}
{"channel":"book","type":"update","data":[{"symbol":"BTC/CAD","bids":[],"asks":[{"price":92635.2,"qty":0.04719084}],"checksum":3490500980,"timestamp":"2024-06-01T22:42:12.097844Z"}]}
{"channel":"book","type":"update","data":[{"symbol":"BTC/CAD","bids":[],"asks":[{"price":92635.4,"qty":0.00000000},{"price":92683.0,"qty":0.01096671}],"checksum":3464524589,"timestamp":"2024-06-01T22:42:12.176049Z"}]}
{"channel":"book","type":"update","data":[{"symbol":"BTC/CAD","bids":[],"asks":[{"price":92635.8,"qty":0.00000000},{"price":92683.1,"qty":0.12110530}],"checksum":930772732,"timestamp":"2024-06-01T22:42:12.781946Z"}]}
{"channel":"book","type":"update","data":[{"symbol":"BTC/CAD","bids":[],"asks":[{"price":92667.0,"qty":0.00000000},{"price":92683.3,"qty":0.07377000}],"checksum":2986286682,"timestamp":"2024-06-01T22:42:12.782014Z"}]}
{"channel":"book","type":"update","data":[{"symbol":"BTC/CAD","bids":[],"asks":[{"price":92683.1,"qty":0.00000000},{"price":92692.2,"qty":0.07380000}],"checksum":2154618883,"timestamp":"2024-06-01T22:42:12.782125Z"}]}
{"channel":"book","type":"update","data":[{"symbol":"BTC/CAD","bids":[{"price":92408.8,"qty":0.07379000}],"asks":[],"checksum":1430282995,"timestamp":"2024-06-01T22:42:12.785359Z"}]}
{"channel":"book","type":"update","data":[{"symbol":"BTC/CAD","bids":[],"asks":[{"price":92683.3,"qty":0.00000000},{"price":92692.8,"qty":0.00686000},{"price":92682.9,"qty":0.07377000}],"checksum":737424406,"timestamp":"2024-06-01T22:42:12.785467Z"}]}
{"channel":"book","type":"update","data":[{"symbol":"BTC/CAD","bids":[],"asks":[{"price":92666.9,"qty":0.00000000},{"price":92692.8,"qty":0.00686000},{"price":92668.8,"qty":0.07381000}],"checksum":2870065655,"timestamp":"2024-06-01T22:42:12.785503Z"}]}
{"channel":"book","type":"update","data":[{"symbol":"BTC/CAD","bids":[],"asks":[{"price":92692.2,"qty":0.00000000},{"price":92692.8,"qty":0.00686000}],"checksum":546403955,"timestamp":"2024-06-01T22:42:12.785582Z"}]}
{"channel":"book","type":"update","data":[{"symbol":"BTC/CAD","bids":[],"asks":[{"price":92666.7,"qty":0.61442638}],"checksum":3644527639,"timestamp":"2024-06-01T22:42:12.786879Z"}]}
{"channel":"book","type":"update","data":[{"symbol":"BTC/CAD","bids":[],"asks":[{"price":92635.1,"qty":0.02953391}],"checksum":2305676520,"timestamp":"2024-06-01T22:42:12.786890Z"}]}
{"channel":"book","type":"update","data":[{"symbol":"BTC/CAD","bids":[],"asks":[{"price":92682.9,"qty":0.19487530}],"checksum":225736133,"timestamp":"2024-06-01T22:42:12.786915Z"}]}
{"channel":"book","type":"update","data":[{"symbol":"BTC/CAD","bids":[],"asks":[{"price":92682.8,"qty":0.01096671}],"checksum":3833616243,"timestamp":"2024-06-01T22:42:12.810096Z"}]}
{"channel":"book","type":"update","data":[{"symbol":"BTC/CAD","bids":[{"price":92540.2,"qty":0.00000000},{"price":92408.7,"qty":0.07085278},{"price":92540.4,"qty":0.03219851}],"asks":[],"checksum":706404934,"timestamp":"2024-06-01T22:42:12.819833Z"}]}
{"channel":"book","type":"update","data":[{"symbol":"BTC/CAD","bids":[],"asks":[{"price":92635.3,"qty":0.00000000},{"price":92682.9,"qty":0.19487530},{"price":92635.1,"qty":0.03678035}],"checksum":269232822,"timestamp":"2024-06-01T22:42:12.820010Z"}]}
{"channel":"book","type":"update","data":[{"symbol":"BTC/CAD","bids":[{"price":92540.3,"qty":0.00000000},{"price":92408.7,"qty":0.07085278},{"price":92540.5,"qty":0.01630000}],"asks":[],"checksum":2373244738,"timestamp":"2024-06-01T22:42:12.849007Z"}]}
{"channel":"book","type":"update","data":[{"symbol":"BTC/CAD","bids":[],"asks":[{"price":92635.0,"qty":0.04719084}],"checksum":2974835239,"timestamp":"2024-06-01T22:42:13.176501Z"}]}
{"channel":"book","type":"update","data":[{"symbol":"BTC/CAD","bids":[],"asks":[{"price":92635.2,"qty":0.00000000},{"price":92682.9,"qty":0.19487530}],"checksum":3690510389,"timestamp":"2024-06-01T22:42:13.182198Z"}]}
{"channel":"book","type":"update","data":[{"symbol":"BTC/CAD","bids":[{"price":92408.9,"qty":0.00576978}],"asks":[],"checksum":2869094099,"timestamp":"2024-06-01T22:42:13.191955Z"}]}
{"channel":"book","type":"update","data":[{"symbol":"BTC/CAD","bids":[],"asks":[{"price":92635.1,"qty":0.02953391},{"price":92634.9,"qty":0.00724639}],"checksum":3335847032,"timestamp":"2024-06-01T22:42:13.541899Z"}]}
{"channel":"book","type":"update","data":[{"symbol":"BTC/CAD","bids":[{"price":92540.4,"qty":0.00000000},{"price":92408.8,"qty":0.07379000},{"price":92540.6,"qty":0.03219849}],"asks":[],"checksum":3531420506,"timestamp":"2024-06-01T22:42:13.541961Z"}]}
{"channel":"book","type":"update","data":[{"symbol":"BTC/CAD","bids":[],"asks":[{"price":92668.8,"qty":0.00000000},{"price":92682.9,"qty":0.19487530},{"price":92666.6,"qty":0.07381000}],"checksum":2759143966,"timestamp":"2024-06-01T22:42:13.544914Z"}]}
{"channel":"book","type":"update","data":[{"symbol":"BTC/CAD","bids":[],"asks":[{"price":92634.8,"qty":0.04719084}],"checksum":43240490,"timestamp":"2024-06-01T22:42:13.547323Z"}]}
{"channel":"book","type":"update","data":[{"symbol":"BTC/CAD","bids":[{"price":92540.5,"qty":0.00000000},{"price":92408.8,"qty":0.07379000},{"price":92540.7,"qty":0.01630000}],"asks":[],"checksum":3315135784,"timestamp":"2024-06-01T22:42:13.549189Z"}]}
{"channel":"book","type":"update","data":[{"symbol":"BTC/CAD","bids":[],"asks":[{"price":92635.0,"qty":0.00000000},{"price":92682.8,"qty":0.01096671}],"checksum":4160214910,"timestamp":"2024-06-01T22:42:13.677759Z"}]}
{"channel":"book","type":"update","data":[{"symbol":"BTC/CAD","bids":[],"asks":[{"price":92634.9,"qty":0.00000000},{"price":92682.9,"qty":0.19487530},{"price":92634.7,"qty":0.00724639}],"checksum":2922460495,"timestamp":"2024-06-01T22:42:14.251501Z"}]}
{"channel":"book","type":"update","data":[{"symbol":"BTC/CAD","bids":[{"price":92540.6,"qty":0.00000000},{"price":92408.8,"qty":0.07379000},{"price":92540.8,"qty":0.03219843}],"asks":[],"checksum":2678541321,"timestamp":"2024-06-01T22:42:14.251530Z"}]}
{"channel":"book","type":"update","data":[{"symbol":"BTC/CAD","bids":[],"asks":[{"price":92634.6,"qty":0.04719084}],"checksum":3891594795,"timestamp":"2024-06-01T22:42:14.257260Z"}]}
{"channel":"book","type":"update","data":[{"symbol":"BTC/CAD","bids":[{"price":92540.7,"qty":0.00000000},{"price":92408.8,"qty":0.07379000},{"price":92540.9,"qty":0.01630000}],"asks":[],"checksum":2414884973,"timestamp":"2024-06-01T22:42:14.276868Z"}]}
{"channel":"book","type":"update","data":[{"symbol":"BTC/CAD","bids":[],"asks":[{"price":92634.8,"qty":0.00000000},{"price":92682.8,"qty":0.01096671}],"checksum":785176701,"timestamp":"2024-06-01T22:42:14.679765Z"}]}
{"channel":"book","type":"update","data":[{"symbol":"BTC/CAD","bids":[{"price":92409.0,"qty":1.75830604}],"asks":[],"checksum":213408454,"timestamp":"2024-06-01T22:42:14.890369Z"}]}
{"channel":"book","type":"update","data":[{"symbol":"BTC/CAD","bids":[{"price":92409.1,"qty":0.07379000}],"asks":[],"checksum":3794270092,"timestamp":"2024-06-01T22:42:14.893785Z"}]}
{"channel":"book","type":"update","data":[{"symbol":"BTC/CAD","bids":[{"price":92409.1,"qty":0.27011769}],"asks":[],"checksum":328730641,"timestamp":"2024-06-01T22:42:14.895529Z"}]}
{"channel":"book","type":"update","data":[{"symbol":"BTC/CAD","bids":[{"price":92409.1,"qty":0.34097016}],"asks":[],"checksum":561028060,"timestamp":"2024-06-01T22:42:14.896802Z"}]}
{"channel":"book","type":"update","data":[{"symbol":"BTC/CAD","bids":[],"asks":[{"price":92634.7,"qty":0.00000000},{"price":92682.9,"qty":0.19487530},{"price":92634.5,"qty":0.00656850}],"checksum":144512471,"timestamp":"2024-06-01T22:42:15.035784Z"}]}
{"channel":"book","type":"update","data":[{"symbol":"BTC/CAD","bids":[{"price":92540.8,"qty":0.00000000},{"price":92409.0,"qty":1.75830604},{"price":92574.8,"qty":0.03218672}],"asks":[],"checksum":2450196919,"timestamp":"2024-06-01T22:42:15.035810Z"}]}
{"channel":"book","type":"update","data":[{"symbol":"BTC/CAD","bids":[{"price":92574.8,"qty":0.00000000},{"price":92409.0,"qty":1.75830604},{"price":92541.0,"qty":0.03219848}],"asks":[],"checksum":3069611245,"timestamp":"2024-06-01T22:42:15.113235Z"}]}
{"channel":"book","type":"update","data":[{"symbol":"BTC/CAD","bids":[],"asks":[{"price":92634.4,"qty":0.04719084}],"checksum":2574599052,"timestamp":"2024-06-01T22:42:15.118816Z"}]}
{"channel":"book","type":"update","data":[{"symbol":"BTC/CAD","bids":[{"price":92540.9,"qty":0.00000000},{"price":92409.0,"qty":1.75830604},{"price":92541.1,"qty":0.01630000}],"asks":[],"checksum":1839938711,"timestamp":"2024-06-01T22:42:15.135938Z"}]}
{"channel":"book","type":"update","data":[{"symbol":"BTC/CAD","bids":[],"asks":[{"price":92634.6,"qty":0.00000000},{"price":92682.8,"qty":0.01096671}],"checksum":3694593170,"timestamp":"2024-06-01T22:42:15.176423Z"}]}
{"channel":"book","type":"update","data":[{"symbol":"BTC/CAD","bids":[],"asks":[{"price":92666.7,"qty":0.00000000},{"price":92682.9,"qty":0.19487530}],"checksum":3010378712,"timestamp":"2024-06-01T22:42:15.294671Z"}]}
{"channel":"book","type":"update","data":[{"symbol":"BTC/CAD","bids":[],"asks":[{"price":92682.9,"qty":0.07377000}],"checksum":2387499308,"timestamp":"2024-06-01T22:42:15.294684Z"}]}
{"channel":"book","type":"update","data":[{"symbol":"BTC/CAD","bids":[],"asks":[{"price":92635.1,"qty":0.00000000},{"price":92692.8,"qty":0.00686000}],"checksum":2918623001,"timestamp":"2024-06-01T22:42:15.294762Z"}]}
{"channel":"book","type":"update","data":[{"symbol":"BTC/CAD","bids":[],"asks":[{"price":92666.6,"qty":0.00000000},{"price":92701.3,"qty":0.07380000},{"price":92668.8,"qty":0.07381000}],"checksum":1086509385,"timestamp":"2024-06-01T22:42:15.297960Z"}]}
{"channel":"book","type":"update","data":[{"symbol":"BTC/CAD","bids":[],"asks":[{"price":92682.9,"qty":0.00000000},{"price":92701.3,"qty":0.07380000},{"price":92682.7,"qty":0.07377000}],"checksum":3380845217,"timestamp":"2024-06-01T22:42:15.298253Z"}]}
{"channel":"book","type":"update","data":[{"symbol":"BTC/CAD","bids":[],"asks":[{"price":92634.5,"qty":0.03610241}],"checksum":3690702005,"timestamp":"2024-06-01T22:42:15.300156Z"}]}
{"channel":"book","type":"update","data":[{"symbol":"BTC/CAD","bids":[],"asks":[{"price":92666.5,"qty":0.65775175}],"checksum":408922421,"timestamp":"2024-06-01T22:42:15.300317Z"}]}
{"channel":"book","type":"update","data":[{"symbol":"BTC/CAD","bids":[{"price":92568.7,"qty":0.00000000},{"price":92409.0,"qty":1.75830604},{"price":92574.8,"qty":0.00135100}],"asks":[],"checksum":1975146363,"timestamp":"2024-06-01T22:42:15.781452Z"}]}
{"channel":"book","type":"update","data":[{"symbol":"BTC/CAD","bids":[{"price":92541.0,"qty":0.00000000},{"price":92409.0,"qty":1.75830604},{"price":92541.2,"qty":0.03219841}],"asks":[],"checksum":1181858435,"timestamp":"2024-06-01T22:42:15.799765Z"}]}
{"channel":"book","type":"update","data":[{"symbol":"BTC/CAD","bids":[],"asks":[{"price":92634.5,"qty":0.02953391},{"price":92634.3,"qty":0.00656850}],"checksum":3540822455,"timestamp":"2024-06-01T22:42:15.800085Z"}]}
{"channel":"book","type":"update","data":[{"symbol":"BTC/CAD","bids":[],"asks":[{"price":92668.8,"qty":0.00000000},{"price":92682.8,"qty":0.01096671},{"price":92666.4,"qty":0.07381000}],"checksum":816175104,"timestamp":"2024-06-01T22:42:15.802642Z"}]}
{"channel":"book","type":"update","data":[{"symbol":"BTC/CAD","bids":[{"price":92541.1,"qty":0.00000000},{"price":92409.0,"qty":1.75830604},{"price":92541.3,"qty":0.01630000}],"asks":[],"checksum":3784478583,"timestamp":"2024-06-01T22:42:15.816118Z"}]}
{"channel":"book","type":"update","data":[{"symbol":"BTC/CAD","bids":[],"asks":[{"price":92634.2,"qty":0.04719084}],"checksum":3109747565,"timestamp":"2024-06-01T22:42:16.178220Z"}]}
{"channel":"book","type":"update","data":[{"symbol":"BTC/CAD","bids":[{"price":92574.9,"qty":0.04719084}],"asks":[],"checksum":2195137971,"timestamp":"2024-06-01T22:42:16.178238Z"}]}
{"channel":"book","type":"update","data":[{"symbol":"BTC/CAD","bids":[],"asks":[{"price":92634.4,"qty":0.00000000},{"price":92682.7,"qty":0.07377000}],"checksum":21028654,"timestamp":"2024-06-01T22:42:16.183898Z"}]}
{"channel":"book","type":"update","data":[{"symbol":"BTC/CAD","bids":[{"price":92574.7,"qty":0.00000000},{"price":92409.1,"qty":0.34097016}],"asks":[],"checksum":1050016677,"timestamp":"2024-06-01T22:42:16.183911Z"}]}
{"channel":"book","type":"update","data":[{"symbol":"BTC/CAD","bids":[{"price":92541.2,"qty":0.00000000},{"price":92409.0,"qty":1.75830604},{"price":92541.4,"qty":0.03219834}],"asks":[],"checksum":522177249,"timestamp":"2024-06-01T22:42:16.585091Z"}]}
{"channel":"book","type":"update","data":[{"symbol":"BTC/CAD","bids":[],"asks":[{"price":92634.3,"qty":0.00000000},{"price":92682.8,"qty":0.01096671},{"price":92634.1,"qty":0.00656850}],"checksum":2647273649,"timestamp":"2024-06-01T22:42:16.585208Z"}]}
{"channel":"book","type":"update","data":[{"symbol":"BTC/CAD","bids":[{"price":92541.3,"qty":0.00000000},{"price":92409.0,"qty":1.75830604},{"price":92541.5,"qty":0.01630000}],"asks":[],"checksum":3163877937,"timestamp":"2024-06-01T22:42:16.597220Z"}]}
{"channel":"book","type":"update","data":[{"symbol":"BTC/CAD","bids":[{"price":92409.2,"qty":0.00576978}],"asks":[],"checksum":4251582387,"timestamp":"2024-06-01T22:42:16.602101Z"}]}
{"channel":"book","type":"update","data":[{"symbol":"BTC/CAD","bids":[{"price":92409.3,"qty":0.07085232}],"asks":[],"checksum":514395698,"timestamp":"2024-06-01T22:42:16.637068Z"}]}
{"channel":"book","type":"update","data":[{"symbol":"BTC/CAD","bids":[{"price":92409.4,"qty":0.07379000}],"asks":[],"checksum":2631514989,"timestamp":"2024-06-01T22:42:16.639901Z"}]}
{"channel":"book","type":"update","data":[{"symbol":"BTC/CAD","bids":[],"asks":[{"price":92666.8,"qty":0.00000000},{"price":92682.8,"qty":0.01096671}],"checksum":2318616894,"timestamp":"2024-06-01T22:42:17.035554Z"}]}
{"channel":"book","type":"update","data":[{"symbol":"BTC/CAD","bids":[],"asks":[{"price":92666.3,"qty":0.00251530}],"checksum":3153590510,"timestamp":"2024-06-01T22:42:17.040368Z"}]}
{"channel":"book","type":"update","data":[{"symbol":"BTC/CAD","bids":[],"asks":[{"price":92634.0,"qty":0.00029534}],"checksum":2533274539,"timestamp":"2024-06-01T22:42:17.040433Z"}]}
{"channel":"book","type":"update","data":[{"symbol":"BTC/CAD","bids":[],"asks":[{"price":92633.9,"qty":0.04719084}],"checksum":1344345898,"timestamp":"2024-06-01T22:42:17.047845Z"}]}
{"channel":"book","type":"update","data":[{"symbol":"BTC/CAD","bids":[],"asks":[{"price":92634.2,"qty":0.00000000},{"price":92670.2,"qty":0.00759000}],"checksum":841385752,"timestamp":"2024-06-01T22:42:17.179298Z"}]}
{"channel":"book","type":"update","data":[{"symbol":"BTC/CAD","bids":[{"price":92541.4,"qty":0.00000000},{"price":92409.3,"qty":0.07085232},{"price":92541.6,"qty":0.03219804}],"asks":[],"checksum":1932528441,"timestamp":"2024-06-01T22:42:17.352788Z"}]}
{"channel":"book","type":"update","data":[{"symbol":"BTC/CAD","bids":[{"price":92541.5,"qty":0.00000000},{"price":92409.3,"qty":0.07085232},{"price":92541.7,"qty":0.01630000}],"asks":[],"checksum":1257756864,"timestamp":"2024-06-01T22:42:17.362725Z"}]}
{"channel":"book","type":"update","data":[{"symbol":"BTC/CAD","bids":[{"price":92409.5,"qty":1.75830604}],"asks":[],"checksum":4221947718,"timestamp":"2024-06-01T22:42:17.700005Z"}]}
{"channel":"book","type":"update","data":[{"symbol":"BTC/CAD","bids":[{"price":92409.6,"qty":0.07379000}],"asks":[],"checksum":148037565,"timestamp":"2024-06-01T22:42:17.703042Z"}]}
{"channel":"book","type":"update","data":[{"symbol":"BTC/CAD","bids":[{"price":92409.6,"qty":0.27011769}],"asks":[],"checksum":1118633219,"timestamp":"2024-06-01T22:42:17.703460Z"}]}
{"channel":"book","type":"update","data":[{"symbol":"BTC/CAD","bids":[{"price":92409.6,"qty":0.34096978}],"asks":[],"checksum":1993062565,"timestamp":"2024-06-01T22:42:17.704728Z"}]}
{"channel":"book","type":"update","data":[{"symbol":"BTC/CAD","bids":[],"asks":[{"price":92666.5,"qty":0.00000000},{"price":92682.7,"qty":0.07377000}],"checksum":44334185,"timestamp":"2024-06-01T22:42:17.845945Z"}]}
{"channel":"book","type":"update","data":[{"symbol":"BTC/CAD","bids":[],"asks":[{"price":92634.5,"qty":0.00000000},{"price":92682.8,"qty":0.01096671}],"checksum":1652636521,"timestamp":"2024-06-01T22:42:17.846067Z"}]}
{"channel":"book","type":"update","data":[{"symbol":"BTC/CAD","bids":[],"asks":[{"price":92666.4,"qty":0.00000000},{"price":92692.8,"qty":0.00686000},{"price":92668.8,"qty":0.07381000}],"checksum":79916343,"timestamp":"2024-06-01T22:42:17.849477Z"}]}
{"channel":"book","type":"update","data":[{"symbol":"BTC/CAD","bids":[],"asks":[{"price":92682.6,"qty":0.07380000}],"checksum":2216443979,"timestamp":"2024-06-01T22:42:17.849650Z"}]}
{"channel":"book","type":"update","data":[{"symbol":"BTC/CAD","bids":[],"asks":[{"price":92682.6,"qty":0.08476671}],"checksum":939651974,"timestamp":"2024-06-01T22:42:17.849978Z"}]}
{"channel":"book","type":"update","data":[{"symbol":"BTC/CAD","bids":[],"asks":[{"price":92633.8,"qty":0.02953391}],"checksum":1881576699,"timestamp":"2024-06-01T22:42:17.850883Z"}]}
{"channel":"book","type":"update","data":[{"symbol":"BTC/CAD","bids":[],"asks":[{"price":92666.2,"qty":0.65775175}],"checksum":2329398431,"timestamp":"2024-06-01T22:42:17.851132Z"}]}
{"channel":"book","type":"update","data":[{"symbol":"BTC/CAD","bids":[{"price":92541.6,"qty":0.00000000},{"price":92409.5,"qty":1.75830604},{"price":92541.8,"qty":0.03219797}],"asks":[],"checksum":839547204,"timestamp":"2024-06-01T22:42:18.170427Z"}]}
{"channel":"book","type":"update","data":[{"symbol":"BTC/CAD","bids":[],"asks":[{"price":92634.1,"qty":0.00000000},{"price":92682.5,"qty":0.07377000},{"price":92633.7,"qty":0.00656841}],"checksum":1957203031,"timestamp":"2024-06-01T22:42:18.170481Z"}]}
{"channel":"book","type":"update","data":[{"symbol":"BTC/CAD","bids":[],"asks":[{"price":92633.6,"qty":0.04719084}],"checksum":2382356486,"timestamp":"2024-06-01T22:42:18.177998Z"}]}
{"channel":"book","type":"update","data":[{"symbol":"BTC/CAD","bids":[{"price":92541.7,"qty":0.00000000},{"price":92409.5,"qty":1.75830604},{"price":92541.9,"qty":0.01630000}],"asks":[],"checksum":2218718263,"timestamp":"2024-06-01T22:42:18.182251Z"}]}
{"channel":"book","type":"update","data":[{"symbol":"BTC/CAD","bids":[{"price":92553.3,"qty":0.00000000},{"price":92409.5,"qty":1.75830604},{"price":92558.6,"qty":0.00450400}],"asks":[],"checksum":1526839180,"timestamp":"2024-06-01T22:42:18.521313Z"}]}
{"channel":"book","type":"update","data":[{"symbol":"BTC/CAD","bids":[],"asks":[{"price":92668.8,"qty":0.00000000},{"price":92670.2,"qty":0.00759000},{"price":92666.1,"qty":0.07381000}],"checksum":47904272,"timestamp":"2024-06-01T22:42:18.524393Z"}]}
{"channel":"book","type":"update","data":[{"symbol":"BTC/CAD","bids":[],"asks":[{"price":92633.9,"qty":0.00000000},{"price":92670.2,"qty":0.00759000}],"checksum":4012835303,"timestamp":"2024-06-01T22:42:18.525848Z"}]}
{"channel":"book","type":"update","data":[{"symbol":"BTC/CAD","bids":[{"price":92541.8,"qty":0.00000000},{"price":92409.5,"qty":1.75830604},{"price":92542.0,"qty":0.03219787}],"asks":[],"checksum":2225872247,"timestamp":"2024-06-01T22:42:18.936954Z"}]}
{"channel":"book","type":"update","data":[{"symbol":"BTC/CAD","bids":[{"price":92541.9,"qty":0.00000000},{"price":92409.5,"qty":1.75830604},{"price":92542.1,"qty":0.01630000}],"asks":[],"checksum":483437670,"timestamp":"2024-06-01T22:42:18.971544Z"}]}
{"channel":"book","type":"update","data":[{"symbol":"BTC/CAD","bids":[],"asks":[{"price":92633.7,"qty":0.00000000},{"price":92682.5,"qty":0.07377000},{"price":92633.5,"qty":0.00656854}],"checksum":1391851539,"timestamp":"2024-06-01T22:42:19.676419Z"}]}
{"channel":"book","type":"update","data":[{"symbol":"BTC/CAD","bids":[{"price":92542.0,"qty":0.00000000},{"price":92409.5,"qty":1.75830604},{"price":92542.2,"qty":0.03219780}],"asks":[],"checksum":2459270996,"timestamp":"2024-06-01T22:42:19.676467Z"}]}
{"channel":"book","type":"update","data":[{"symbol":"BTC/CAD","bids":[{"price":92538.5,"qty":0.00000000},{"price":92409.5,"qty":1.75830604}],"asks":[],"checksum":4069489649,"timestamp":"2024-06-01T22:42:19.679957Z"}]}
{"channel":"book","type":"update","data":[{"symbol":"BTC/CAD","bids":[],"asks":[{"price":92633.4,"qty":0.04719084}],"checksum":1604573750,"timestamp":"2024-06-01T22:42:19.681635Z"}]}
{"channel":"book","type":"update","data":[{"symbol":"BTC/CAD","bids":[{"price":92409.7,"qty":0.07377000}],"asks":[],"checksum":3537846028,"timestamp":"2024-06-01T22:42:19.682706Z"}]}
{"channel":"book","type":"update","data":[{"symbol":"BTC/CAD","bids":[{"price":92542.2,"qty":0.00000000},{"price":92409.5,"qty":1.75830604},{"price":92511.5,"qty":0.03220849}],"asks":[],"checksum":2975952679,"timestamp":"2024-06-01T22:42:19.683050Z"}]}
{"channel":"book","type":"update","data":[{"symbol":"BTC/CAD","bids":[{"price":92539.0,"qty":0.31202430}],"asks":[],"checksum":2662680835,"timestamp":"2024-06-01T22:42:19.685464Z"}]}
{"channel":"book","type":"update","data":[{"symbol":"BTC/CAD","bids":[{"price":92409.8,"qty":0.07379000}],"asks":[],"checksum":2806656156,"timestamp":"2024-06-01T22:42:19.685680Z"}]}
{"channel":"book","type":"update","data":[{"symbol":"BTC/CAD","bids":[{"price":92409.9,"qty":0.07085186}],"asks":[],"checksum":92943311,"timestamp":"2024-06-01T22:42:19.688893Z"}]}
{"channel":"book","type":"update","data":[{"symbol":"BTC/CAD","bids":[],"asks":[{"price":92634.0,"qty":0.00000000},{"price":92670.2,"qty":0.00759000}],"checksum":4050084695,"timestamp":"2024-06-01T22:42:19.796603Z"}]}
{"channel":"book","type":"update","data":[{"symbol":"BTC/CAD","bids":[],"asks":[{"price":92666.3,"qty":0.00000000},{"price":92682.5,"qty":0.07377000}],"checksum":2793110807,"timestamp":"2024-06-01T22:42:19.796632Z"}]}
{"channel":"book","type":"update","data":[{"symbol":"BTC/CAD","bids":[],"asks":[{"price":92666.0,"qty":0.00251530}],"checksum":3580101438,"timestamp":"2024-06-01T22:42:19.798448Z"}]}
{"channel":"book","type":"update","data":[{"symbol":"BTC/CAD","bids":[],"asks":[{"price":92633.5,"qty":0.00686388}],"checksum":426532192,"timestamp":"2024-06-01T22:42:19.798613Z"}]}
{"channel":"book","type":"update","data":[{"symbol":"BTC/CAD","bids":[],"asks":[{"price":92633.6,"qty":0.00000000},{"price":92682.5,"qty":0.07377000}],"checksum":1353031145,"timestamp":"2024-06-01T22:42:19.801878Z"}]}
{"channel":"book","type":"update","data":[{"symbol":"BTC/CAD","bids":[{"price":92410.0,"qty":0.00605791}],"asks":[],"checksum":3114074721,"timestamp":"2024-06-01T22:42:20.029582Z"}]}
{"channel":"book","type":"update","data":[{"symbol":"BTC/CAD","bids":[],"asks":[{"price":92633.8,"qty":0.00000000},{"price":92682.6,"qty":0.08476671}],"checksum":432776732,"timestamp":"2024-06-01T22:42:20.492268Z"}]}
{"channel":"book","type":"update","data":[{"symbol":"BTC/CAD","bids":[],"asks":[{"price":92666.2,"qty":0.00000000},{"price":92692.8,"qty":0.00686000}],"checksum":2828198257,"timestamp":"2024-06-01T22:42:20.492308Z"}]}
{"channel":"book","type":"update","data":[{"symbol":"BTC/CAD","bids":[],"asks":[{"price":92633.3,"qty":0.02953391}],"checksum":1980428864,"timestamp":"2024-06-01T22:42:20.494598Z"}]}
{"channel":"book","type":"update","data":[{"symbol":"BTC/CAD","bids":[],"asks":[{"price":92665.9,"qty":0.80114910}],"checksum":609127184,"timestamp":"2024-06-01T22:42:20.494641Z"}]}
{"channel":"book","type":"update","data":[{"symbol":"BTC/CAD","bids":[{"price":92410.0,"qty":0.07984791}],"asks":[],"checksum":928327545,"timestamp":"2024-06-01T22:42:20.495720Z"}]}
{"channel":"book","type":"update","data":[{"symbol":"BTC/CAD","bids":[],"asks":[{"price":92666.1,"qty":0.00000000},{"price":92682.6,"qty":0.08476671},{"price":92668.8,"qty":0.07381000}],"checksum":3357363197,"timestamp":"2024-06-01T22:42:20.495800Z"}]}
{"channel":"book","type":"update","data":[{"symbol":"BTC/CAD","bids":[{"price":92511.5,"qty":0.00000000},{"price":92409.9,"qty":0.07085186},{"price":92542.2,"qty":0.03219780}],"asks":[],"checksum":726193457,"timestamp":"2024-06-01T22:42:20.516939Z"}]}
{"channel":"book","type":"update","data":[{"symbol":"BTC/CAD","bids":[],"asks":[{"price":92633.5,"qty":0.00029534},{"price":92633.3,"qty":0.03610255}],"checksum":4165093841,"timestamp":"2024-06-01T22:42:20.516990Z"}]}
{"channel":"book","type":"update","data":[{"symbol":"BTC/CAD","bids":[{"price":92410.1,"qty":1.78711891}],"asks":[],"checksum":3276013247,"timestamp":"2024-06-01T22:42:20.528476Z"}]}
{"channel":"book","type":"update","data":[{"symbol":"BTC/CAD","bids":[{"price":92410.2,"qty":0.19632769}],"asks":[],"checksum":1855524880,"timestamp":"2024-06-01T22:42:20.532043Z"}]}
{"channel":"book","type":"update","data":[{"symbol":"BTC/CAD","bids":[{"price":92410.3,"qty":0.07085155}],"asks":[],"checksum":1177259832,"timestamp":"2024-06-01T22:42:20.536132Z"}]}
{"channel":"book","type":"update","data":[{"symbol":"BTC/CAD","bids":[{"price":92542.1,"qty":0.00000000},{"price":92410.2,"qty":0.19632769},{"price":92542.3,"qty":0.01630000}],"asks":[],"checksum":1166399427,"timestamp":"2024-06-01T22:42:20.549130Z"}]}
{"channel":"book","type":"update","data":[{"symbol":"BTC/CAD","bids":[],"asks":[{"price":92633.2,"qty":0.04719084}],"checksum":566855812,"timestamp":"2024-06-01T22:42:20.554285Z"}]}
{"channel":"book","type":"update","data":[{"symbol":"BTC/CAD","bids":[],"asks":[{"price":92633.4,"qty":0.00000000},{"price":92682.5,"qty":0.07377000}],"checksum":109121665,"timestamp":"2024-06-01T22:42:20.676714Z"}]}
{"channel":"book","type":"update","data":[{"symbol":"BTC/CAD","bids":[],"asks":[{"price":92633.3,"qty":0.02953391},{"price":92633.1,"qty":0.00656880}],"checksum":1947312139,"timestamp":"2024-06-01T22:42:21.362915Z"}]}
{"channel":"book","type":"update","data":[{"symbol":"BTC/CAD","bids":[{"price":92410.4,"qty":0.07379000}],"asks":[],"checksum":1008310568,"timestamp":"2024-06-01T22:42:21.365954Z"}]}
{"channel":"book","type":"update","data":[{"symbol":"BTC/CAD","bids":[],"asks":[{"price":92668.8,"qty":0.00000000},{"price":92682.5,"qty":0.07377000},{"price":92665.8,"qty":0.07381000}],"checksum":4150105273,"timestamp":"2024-06-01T22:42:21.366035Z"}]}
{"channel":"book","type":"update","data":[{"symbol":"BTC/CAD","bids":[],"asks":[{"price":92633.0,"qty":0.04719084}],"checksum":3326383600,"timestamp":"2024-06-01T22:42:21.368095Z"}]}
{"channel":"book","type":"update","data":[{"symbol":"BTC/CAD","bids":[],"asks":[{"price":92633.2,"qty":0.00000000},{"price":92670.2,"qty":0.00759000}],"checksum":1291752113,"timestamp":"2024-06-01T22:42:21.676442Z"}]}
{"channel":"book","type":"update","data":[{"symbol":"BTC/CAD","bids":[],"asks":[{"price":92633.1,"qty":0.00000000},{"price":92682.5,"qty":0.07377000},{"price":92632.9,"qty":0.00656881}],"checksum":3591793912,"timestamp":"2024-06-01T22:42:22.171296Z"}]}
{"channel":"book","type":"update","data":[{"symbol":"BTC/CAD","bids":[{"price":92542.2,"qty":0.00000000},{"price":92410.3,"qty":0.07085155},{"price":92542.4,"qty":0.03219787}],"asks":[],"checksum":3770263719,"timestamp":"2024-06-01T22:42:22.171378Z"}]}
{"channel":"book","type":"update","data":[{"symbol":"BTC/CAD","bids":[],"asks":[{"price":92632.8,"qty":0.04719084}],"checksum":3271904802,"timestamp":"2024-06-01T22:42:22.178867Z"}]}
{"channel":"book","type":"update","data":[{"symbol":"BTC/CAD","bids":[{"price":92542.3,"qty":0.00000000},{"price":92410.3,"qty":0.07085155},{"price":92542.5,"qty":0.01630000}],"asks":[],"checksum":3633345277,"timestamp":"2024-06-01T22:42:22.185982Z"}]}
{"channel":"book","type":"update","data":[{"symbol":"BTC/CAD","bids":[],"asks":[{"price":92666.0,"qty":0.00000000},{"price":92670.2,"qty":0.00759000}],"checksum":413638308,"timestamp":"2024-06-01T22:42:22.572810Z"}]}
{"channel":"book","type":"update","data":[{"symbol":"BTC/CAD","bids":[],"asks":[{"price":92633.5,"qty":0.00000000},{"price":92682.5,"qty":0.07377000}],"checksum":2434155374,"timestamp":"2024-06-01T22:42:22.572825Z"}]}
{"channel":"book","type":"update","data":[{"symbol":"BTC/CAD","bids":[],"asks":[{"price":92665.7,"qty":0.00246077}],"checksum":23792534,"timestamp":"2024-06-01T22:42:22.575152Z"}]}
{"channel":"book","type":"update","data":[{"symbol":"BTC/CAD","bids":[],"asks":[{"price":92633.0,"qty":0.00000000},{"price":92682.5,"qty":0.07377000}],"checksum":61789033,"timestamp":"2024-06-01T22:42:22.577809Z"}]}
{"channel":"book","type":"update","data":[{"symbol":"BTC/CAD","bids":[],"asks":[{"price":92632.9,"qty":0.00000000},{"price":92682.6,"qty":0.08476671},{"price":92632.7,"qty":0.00656881}],"checksum":751058605,"timestamp":"2024-06-01T22:42:22.963843Z"}]}
{"channel":"book","type":"update","data":[{"symbol":"BTC/CAD","bids":[{"price":92542.4,"qty":0.00000000},{"price":92410.3,"qty":0.07085155},{"price":92542.6,"qty":0.03219781}],"asks":[],"checksum":3217455565,"timestamp":"2024-06-01T22:42:22.963943Z"}]}
{"channel":"book","type":"update","data":[{"symbol":"BTC/CAD","bids":[],"asks":[{"price":92632.6,"qty":0.04719084}],"checksum":2496397923,"timestamp":"2024-06-01T22:42:22.969495Z"}]}
{"channel":"book","type":"update","data":[{"symbol":"BTC/CAD","bids":[{"price":92542.5,"qty":0.00000000},{"price":92410.3,"qty":0.07085155},{"price":92542.7,"qty":0.01630000}],"asks":[],"checksum":2689812422,"timestamp":"2024-06-01T22:42:22.977113Z"}]}
{"channel":"book","type":"update","data":[{"symbol":"BTC/CAD","bids":[],"asks":[{"price":92633.3,"qty":0.00000000},{"price":92682.5,"qty":0.07377000}],"checksum":2221252434,"timestamp":"2024-06-01T22:42:23.066316Z"}]}
{"channel":"book","type":"update","data":[{"symbol":"BTC/CAD","bids":[],"asks":[{"price":92665.9,"qty":0.00000000},{"price":92682.6,"qty":0.08476671}],"checksum":2873990035,"timestamp":"2024-06-01T22:42:23.066463Z"}]}
{"channel":"book","type":"update","data":[{"symbol":"BTC/CAD","bids":[],"asks":[{"price":92665.8,"qty":0.00000000},{"price":92692.8,"qty":0.00686000},{"price":92668.8,"qty":0.07381000}],"checksum":4165482746,"timestamp":"2024-06-01T22:42:23.070142Z"}]}
{"channel":"book","type":"update","data":[{"symbol":"BTC/CAD","bids":[],"asks":[{"price":92632.7,"qty":0.03610272}],"checksum":3324529389,"timestamp":"2024-06-01T22:42:23.071948Z"}]}
{"channel":"book","type":"update","data":[{"symbol":"BTC/CAD","bids":[],"asks":[{"price":92682.4,"qty":0.12110530}],"checksum":3793188736,"timestamp":"2024-06-01T22:42:23.072074Z"}]}
{"channel":"book","type":"update","data":[{"symbol":"BTC/CAD","bids":[],"asks":[{"price":92665.6,"qty":0.61442638}],"checksum":2276208181,"timestamp":"2024-06-01T22:42:23.072154Z"}]}
{"channel":"book","type":"update","data":[{"symbol":"BTC/CAD","bids":[],"asks":[{"price":92632.8,"qty":0.00000000},{"price":92682.5,"qty":0.07377000}],"checksum":733108799,"timestamp":"2024-06-01T22:42:23.072214Z"}]}
{"channel":"book","type":"update","data":[{"symbol":"BTC/CAD","bids":[],"asks":[{"price":92682.3,"qty":0.01096671}],"checksum":3039382353,"timestamp":"2024-06-01T22:42:23.075357Z"}]}
{"channel":"book","type":"update","data":[{"symbol":"BTC/CAD","bids":[{"price":92410.5,"qty":1.78711891}],"asks":[],"checksum":53660897,"timestamp":"2024-06-01T22:42:23.339781Z"}]}
{"channel":"book","type":"update","data":[{"symbol":"BTC/CAD","bids":[{"price":92410.6,"qty":0.07379000}],"asks":[],"checksum":4144778284,"timestamp":"2024-06-01T22:42:23.342819Z"}]}
{"channel":"book","type":"update","data":[{"symbol":"BTC/CAD","bids":[{"price":92410.6,"qty":0.27011769}],"asks":[],"checksum":3311108162,"timestamp":"2024-06-01T22:42:23.342941Z"}]}
{"channel":"book","type":"update","data":[{"symbol":"BTC/CAD","bids":[{"price":92410.7,"qty":0.07085124}],"asks":[],"checksum":1093524185,"timestamp":"2024-06-01T22:42:23.381981Z"}]}
{"channel":"book","type":"update","data":[{"symbol":"BTC/CAD","bids":[{"price":92542.6,"qty":0.00000000},{"price":92410.6,"qty":0.27011769},{"price":92542.8,"qty":0.03219774}],"asks":[],"checksum":2781357790,"timestamp":"2024-06-01T22:42:23.741684Z"}]}
{"channel":"book","type":"update","data":[{"symbol":"BTC/CAD","bids":[],"asks":[{"price":92632.7,"qty":0.02953391},{"price":92632.5,"qty":0.00656883}],"checksum":3621094369,"timestamp":"2024-06-01T22:42:23.741762Z"}]}
{"channel":"book","type":"update","data":[{"symbol":"BTC/CAD","bids":[],"asks":[{"price":92668.8,"qty":0.00000000},{"price":92682.4,"qty":0.12110530},{"price":92665.5,"qty":0.07381000}],"checksum":3129111308,"timestamp":"2024-06-01T22:42:23.744933Z"}]}
{"channel":"book","type":"update","data":[{"symbol":"BTC/CAD","bids":[],"asks":[{"price":92632.4,"qty":0.04719084}],"checksum":1054318352,"timestamp":"2024-06-01T22:42:23.747394Z"}]}
{"channel":"book","type":"update","data":[{"symbol":"BTC/CAD","bids":[{"price":92542.7,"qty":0.00000000},{"price":92410.6,"qty":0.27011769},{"price":92542.9,"qty":0.01630000}],"asks":[],"checksum":811825390,"timestamp":"2024-06-01T22:42:23.768334Z"}]}
{"channel":"book","type":"update","data":[{"symbol":"BTC/CAD","bids":[],"asks":[{"price":92632.6,"qty":0.00000000},{"price":92682.3,"qty":0.01096671}],"checksum":2267033520,"timestamp":"2024-06-01T22:42:24.177868Z"}]}
{"channel":"book","type":"update","data":[{"symbol":"BTC/CAD","bids":[{"price":92410.8,"qty":0.07379000}],"asks":[],"checksum":613133175,"timestamp":"2024-06-01T22:42:24.181074Z"}]}
{"channel":"book","type":"update","data":[{"symbol":"BTC/CAD","bids":[],"asks":[{"price":92632.5,"qty":0.00000000},{"price":92682.4,"qty":0.12110530},{"price":92632.3,"qty":0.00656883}],"checksum":1595820515,"timestamp":"2024-06-01T22:42:24.601195Z"}]}
{"channel":"book","type":"update","data":[{"symbol":"BTC/CAD","bids":[{"price":92542.8,"qty":0.00000000},{"price":92410.7,"qty":0.07085124},{"price":92543.0,"qty":0.03219767}],"asks":[],"checksum":23847831,"timestamp":"2024-06-01T22:42:24.601227Z"}]}
{"channel":"book","type":"update","data":[{"symbol":"BTC/CAD","bids":[],"asks":[{"price":92632.2,"qty":0.04719084}],"checksum":3903994789,"timestamp":"2024-06-01T22:42:24.606709Z"}]}
{"channel":"book","type":"update","data":[{"symbol":"BTC/CAD","bids":[{"price":92542.9,"qty":0.00000000},{"price":92410.7,"qty":0.07085124},{"price":92543.1,"qty":0.01630000}],"asks":[],"checksum":2634471049,"timestamp":"2024-06-01T22:42:24.617613Z"}]}
{"channel":"book","type":"update","data":[{"symbol":"BTC/CAD","bids":[],"asks":[{"price":92632.4,"qty":0.00000000},{"price":92682.3,"qty":0.01096671}],"checksum":520389470,"timestamp":"2024-06-01T22:42:24.676211Z"}]}
{"channel":"book","type":"update","data":[{"symbol":"BTC/CAD","bids":[],"asks":[{"price":92665.7,"qty":0.00000000},{"price":92682.4,"qty":0.12110530}],"checksum":2908199478,"timestamp":"2024-06-01T22:42:25.407859Z"}]}
{"channel":"book","type":"update","data":[{"symbol":"BTC/CAD","bids":[],"asks":[{"price":92665.4,"qty":0.00281064}],"checksum":3438375975,"timestamp":"2024-06-01T22:42:25.410265Z"}]}
{"channel":"book","type":"update","data":[{"symbol":"BTC/CAD","bids":[{"price":92543.0,"qty":0.00000000},{"price":92410.7,"qty":0.07085124},{"price":92543.2,"qty":0.03219763}],"asks":[],"checksum":3969889129,"timestamp":"2024-06-01T22:42:25.444258Z"}]}
{"channel":"book","type":"update","data":[{"symbol":"BTC/CAD","bids":[],"asks":[{"price":92632.3,"qty":0.00000000},{"price":92682.4,"qty":0.12110530},{"price":92632.1,"qty":0.00656885}],"checksum":1233942190,"timestamp":"2024-06-01T22:42:25.444379Z"}]}
{"channel":"book","type":"update","data":[{"symbol":"BTC/CAD","bids":[],"asks":[{"price":92632.0,"qty":0.04719084}],"checksum":464348037,"timestamp":"2024-06-01T22:42:25.449815Z"}]}
{"channel":"book","type":"update","data":[{"symbol":"BTC/CAD","bids":[{"price":92543.1,"qty":0.00000000},{"price":92410.7,"qty":0.07085124},{"price":92543.3,"qty":0.01630000}],"asks":[],"checksum":1643103884,"timestamp":"2024-06-01T22:42:25.468267Z"}]}
{"channel":"book","type":"update","data":[{"symbol":"BTC/CAD","bids":[],"asks":[{"price":92632.2,"qty":0.00000000},{"price":92682.3,"qty":0.01096671}],"checksum":3914408837,"timestamp":"2024-06-01T22:42:25.676667Z"}]}
{"channel":"book","type":"update","data":[{"symbol":"BTC/CAD","bids":[],"asks":[{"price":92632.7,"qty":0.00000000},{"price":92682.4,"qty":0.12110530}],"checksum":3267299541,"timestamp":"2024-06-01T22:42:25.706088Z"}]}
{"channel":"book","type":"update","data":[{"symbol":"BTC/CAD","bids":[],"asks":[{"price":92665.6,"qty":0.00000000},{"price":92682.5,"qty":0.07377000}],"checksum":3935894022,"timestamp":"2024-06-01T22:42:25.706141Z"}]}
{"channel":"book","type":"update","data":[{"symbol":"BTC/CAD","bids":[],"asks":[{"price":92682.4,"qty":0.00000000},{"price":92682.6,"qty":0.07380000}],"checksum":1938072004,"timestamp":"2024-06-01T22:42:25.706218Z"}]}
{"channel":"book","type":"update","data":[{"symbol":"BTC/CAD","bids":[],"asks":[{"price":92665.4,"qty":0.61723702}],"checksum":3139421913,"timestamp":"2024-06-01T22:42:25.707922Z"}]}
{"channel":"book","type":"update","data":[{"symbol":"BTC/CAD","bids":[],"asks":[{"price":92632.1,"qty":0.03610276}],"checksum":3433842634,"timestamp":"2024-06-01T22:42:25.708132Z"}]}
{"channel":"book","type":"update","data":[{"symbol":"BTC/CAD","bids":[],"asks":[{"price":92682.2,"qty":0.14262519}],"checksum":4260737663,"timestamp":"2024-06-01T22:42:25.708158Z"}]}
{"channel":"book","type":"update","data":[{"symbol":"BTC/CAD","bids":[],"asks":[{"price":92665.5,"qty":0.00000000},{"price":92682.6,"qty":0.07380000},{"price":92668.8,"qty":0.07381000}],"checksum":2904894296,"timestamp":"2024-06-01T22:42:25.709247Z"}]}
{"channel":"book","type":"update","data":[{"symbol":"BTC/CAD","bids":[],"asks":[{"price":92682.5,"qty":0.00000000},{"price":92682.6,"qty":0.07380000},{"price":92682.2,"qty":0.21639519}],"checksum":595649968,"timestamp":"2024-06-01T22:42:25.709278Z"}]}
{"channel":"book","type":"update","data":[{"symbol":"BTC/CAD","bids":[],"asks":[{"price":92682.6,"qty":0.00000000},{"price":92692.8,"qty":0.00686000}],"checksum":2599298342,"timestamp":"2024-06-01T22:42:25.710587Z"}]}
{"channel":"book","type":"update","data":[{"symbol":"BTC/CAD","bids":[],"asks":[{"price":92682.3,"qty":0.00000000},{"price":92701.3,"qty":0.07380000}],"checksum":3170908054,"timestamp":"2024-06-01T22:42:25.724882Z"}]}
{"channel":"book","type":"update","data":[{"symbol":"BTC/CAD","bids":[],"asks":[{"price":92682.1,"qty":0.01096671}],"checksum":1749486256,"timestamp":"2024-06-01T22:42:25.725054Z"}]}
{"channel":"book","type":"update","data":[{"symbol":"BTC/CAD","bids":[{"price":92410.9,"qty":1.75830604}],"asks":[],"checksum":3158779896,"timestamp":"2024-06-01T22:42:26.218490Z"}]}
{"channel":"book","type":"update","data":[{"symbol":"BTC/CAD","bids":[],"asks":[{"price":92668.8,"qty":0.00000000},{"price":92701.3,"qty":0.07380000},{"price":92665.3,"qty":0.07381000}],"checksum":2867516928,"timestamp":"2024-06-01T22:42:26.220258Z"}]}
{"channel":"book","type":"update","data":[{"symbol":"BTC/CAD","bids":[{"price":92411.0,"qty":0.07379000}],"asks":[],"checksum":4084822392,"timestamp":"2024-06-01T22:42:26.221333Z"}]}
{"channel":"book","type":"update","data":[{"symbol":"BTC/CAD","bids":[{"price":92411.0,"qty":0.27011769}],"asks":[],"checksum":2841206930,"timestamp":"2024-06-01T22:42:26.221614Z"}]}
{"channel":"book","type":"update","data":[{"symbol":"BTC/CAD","bids":[{"price":92411.1,"qty":0.07085094}],"asks":[],"checksum":2809025649,"timestamp":"2024-06-01T22:42:26.234695Z"}]}
{"channel":"book","type":"update","data":[{"symbol":"BTC/CAD","bids":[{"price":92543.2,"qty":0.00000000},{"price":92411.0,"qty":0.27011769},{"price":92543.4,"qty":0.03219756}],"asks":[],"checksum":927800651,"timestamp":"2024-06-01T22:42:26.277624Z"}]}
{"channel":"book","type":"update","data":[{"symbol":"BTC/CAD","bids":[],"asks":[{"price":92632.1,"qty":0.02953391},{"price":92631.9,"qty":0.00656885}],"checksum":3842520303,"timestamp":"2024-06-01T22:42:26.277658Z"}]}
{"channel":"book","type":"update","data":[{"symbol":"BTC/CAD","bids":[{"price":92543.3,"qty":0.00000000},{"price":92411.0,"qty":0.27011769},{"price":92543.5,"qty":0.01630000}],"asks":[],"checksum":2806914829,"timestamp":"2024-06-01T22:42:26.292566Z"}]}
{"channel":"book","type":"update","data":[{"symbol":"BTC/CAD","bids":[],"asks":[{"price":92631.8,"qty":0.04719084}],"checksum":1092676282,"timestamp":"2024-06-01T22:42:26.677088Z"}]}
{"channel":"book","type":"update","data":[{"symbol":"BTC/CAD","bids":[],"asks":[{"price":92632.0,"qty":0.00000000},{"price":92682.2,"qty":0.21639519}],"checksum":3655666124,"timestamp":"2024-06-01T22:42:26.683016Z"}]}
{"channel":"book","type":"update","data":[{"symbol":"BTC/CAD","bids":[{"price":92411.2,"qty":0.00548166}],"asks":[],"checksum":1953853286,"timestamp":"2024-06-01T22:42:26.934065Z"}]}
{"channel":"book","type":"update","data":[{"symbol":"BTC/CAD","bids":[{"price":92411.2,"qty":0.07927166}],"asks":[],"checksum":4169701401,"timestamp":"2024-06-01T22:42:26.936073Z"}]}
{"channel":"book","type":"update","data":[{"symbol":"BTC/CAD","bids":[{"price":92543.4,"qty":0.00000000},{"price":92411.1,"qty":0.07085094},{"price":92543.6,"qty":0.03219712}],"asks":[],"checksum":4179495385,"timestamp":"2024-06-01T22:42:27.095417Z"}]}
{"channel":"book","type":"update","data":[{"symbol":"BTC/CAD","bids":[],"asks":[{"price":92631.9,"qty":0.00000000},{"price":92692.8,"qty":0.00686000},{"price":92631.7,"qty":0.00656867}],"checksum":2888749291,"timestamp":"2024-06-01T22:42:27.095443Z"}]}
{"channel":"book","type":"update","data":[{"symbol":"BTC/CAD","bids":[{"price":92543.5,"qty":0.00000000},{"price":92411.1,"qty":0.07085094},{"price":92543.7,"qty":0.01630000}],"asks":[],"checksum":4043474356,"timestamp":"2024-06-01T22:42:27.113288Z"}]}
{"channel":"book","type":"update","data":[{"symbol":"BTC/CAD","bids":[],"asks":[{"price":92631.6,"qty":0.04719084}],"checksum":3544276654,"timestamp":"2024-06-01T22:42:27.176518Z"}]}
{"channel":"book","type":"update","data":[{"symbol":"BTC/CAD","bids":[],"asks":[{"price":92631.8,"qty":0.00000000},{"price":92682.2,"qty":0.21639519}],"checksum":2327765321,"timestamp":"2024-06-01T22:42:27.181689Z"}]}
{"channel":"book","type":"update","data":[{"symbol":"BTC/CAD","bids":[{"price":92543.6,"qty":0.00000000},{"price":92411.1,"qty":0.07085094},{"price":92543.8,"qty":0.03219698}],"asks":[],"checksum":1925252027,"timestamp":"2024-06-01T22:42:27.978013Z"}]}
{"channel":"book","type":"update","data":[{"symbol":"BTC/CAD","bids":[],"asks":[{"price":92631.7,"qty":0.00000000},{"price":92692.8,"qty":0.00686000},{"price":92631.5,"qty":0.00656866}],"checksum":4124136372,"timestamp":"2024-06-01T22:42:27.978183Z"}]}
{"channel":"book","type":"update","data":[{"symbol":"BTC/CAD","bids":[],"asks":[{"price":92631.4,"qty":0.04719084}],"checksum":343206831,"timestamp":"2024-06-01T22:42:27.984053Z"}]}
{"channel":"book","type":"update","data":[{"symbol":"BTC/CAD","bids":[{"price":92543.7,"qty":0.00000000},{"price":92411.1,"qty":0.07085094},{"price":92543.9,"qty":0.01630000}],"asks":[],"checksum":3279709370,"timestamp":"2024-06-01T22:42:27.992678Z"}]}
{"channel":"book","type":"update","data":[{"symbol":"BTC/CAD","bids":[],"asks":[{"price":92665.4,"qty":0.61442638}],"checksum":1313847008,"timestamp":"2024-06-01T22:42:28.164988Z"}]}
{"channel":"book","type":"update","data":[{"symbol":"BTC/CAD","bids":[],"asks":[{"price":92665.2,"qty":0.00265344}],"checksum":3139245558,"timestamp":"2024-06-01T22:42:28.166669Z"}]}
{"channel":"book","type":"update","data":[{"symbol":"BTC/CAD","bids":[],"asks":[{"price":92631.6,"qty":0.00000000},{"price":92682.1,"qty":0.01096671}],"checksum":589356454,"timestamp":"2024-06-01T22:42:28.176886Z"}]}
{"channel":"book","type":"update","data":[{"symbol":"BTC/CAD","bids":[],"asks":[{"price":92632.1,"qty":0.00000000},{"price":92682.2,"qty":0.21639519}],"checksum":55463564,"timestamp":"2024-06-01T22:42:28.402151Z"}]}
{"channel":"book","type":"update","data":[{"symbol":"BTC/CAD","bids":[],"asks":[{"price":92682.2,"qty":0.07377000}],"checksum":4052905748,"timestamp":"2024-06-01T22:42:28.402208Z"}]}
{"channel":"book","type":"update","data":[{"symbol":"BTC/CAD","bids":[],"asks":[{"price":92665.4,"qty":0.00000000},{"price":92692.8,"qty":0.00686000}],"checksum":2704545688,"timestamp":"2024-06-01T22:42:28.402320Z"}]}
{"channel":"book","type":"update","data":[{"symbol":"BTC/CAD","bids":[],"asks":[{"price":92665.3,"qty":0.00000000},{"price":92701.3,"qty":0.07380000},{"price":92668.8,"qty":0.07381000}],"checksum":160056950,"timestamp":"2024-06-01T22:42:28.405345Z"}]}
{"channel":"book","type":"update","data":[{"symbol":"BTC/CAD","bids":[],"asks":[{"price":92682.2,"qty":0.00000000},{"price":92701.3,"qty":0.07380000},{"price":92682.0,"qty":0.07377000}],"checksum":2365765530,"timestamp":"2024-06-01T22:42:28.406804Z"}]}
{"channel":"book","type":"update","data":[{"symbol":"BTC/CAD","bids":[],"asks":[{"price":92631.3,"qty":0.02953391}],"checksum":3561081613,"timestamp":"2024-06-01T22:42:28.406861Z"}]}
{"channel":"book","type":"update","data":[{"symbol":"BTC/CAD","bids":[],"asks":[{"price":92665.2,"qty":0.53042908}],"checksum":2262371932,"timestamp":"2024-06-01T22:42:28.406899Z"}]}
{"channel":"book","type":"update","data":[{"symbol":"BTC/CAD","bids":[],"asks":[{"price":92631.2,"qty":0.04719084}],"checksum":3618557405,"timestamp":"2024-06-01T22:42:28.677248Z"}]}
{"channel":"book","type":"update","data":[{"symbol":"BTC/CAD","bids":[],"asks":[{"price":92631.5,"qty":0.00000000},{"price":92682.1,"qty":0.01096671},{"price":92631.1,"qty":0.00667316}],"checksum":3424581608,"timestamp":"2024-06-01T22:42:28.876849Z"}]}
{"channel":"book","type":"update","data":[{"symbol":"BTC/CAD","bids":[],"asks":[{"price":92631.2,"qty":0.00000000},{"price":92682.1,"qty":0.01096671}],"checksum":3607613333,"timestamp":"2024-06-01T22:42:28.882304Z"}]}
{"channel":"book","type":"update","data":[{"symbol":"BTC/CAD","bids":[],"asks":[{"price":92631.0,"qty":0.04719084}],"checksum":3010902814,"timestamp":"2024-06-01T22:42:28.882473Z"}]}
{"channel":"book","type":"update","data":[{"symbol":"BTC/CAD","bids":[{"price":92411.3,"qty":1.75830604}],"asks":[],"checksum":3587290741,"timestamp":"2024-06-01T22:42:29.084778Z"}]}
{"channel":"book","type":"update","data":[{"symbol":"BTC/CAD","bids":[],"asks":[{"price":92668.8,"qty":0.00000000},{"price":92682.1,"qty":0.01096671},{"price":92665.1,"qty":0.07381000}],"checksum":2225947568,"timestamp":"2024-06-01T22:42:29.087139Z"}]}
{"channel":"book","type":"update","data":[{"symbol":"BTC/CAD","bids":[{"price":92411.4,"qty":0.07379000}],"asks":[],"checksum":3502785051,"timestamp":"2024-06-01T22:42:29.087919Z"}]}
{"channel":"book","type":"update","data":[{"symbol":"BTC/CAD","bids":[{"price":92411.4,"qty":0.27011769}],"asks":[],"checksum":2109858115,"timestamp":"2024-06-01T22:42:29.088287Z"}]}
{"channel":"book","type":"update","data":[{"symbol":"BTC/CAD","bids":[{"price":92411.5,"qty":0.07085063}],"asks":[],"checksum":2636377726,"timestamp":"2024-06-01T22:42:29.109644Z"}]}
{"channel":"book","type":"update","data":[{"symbol":"BTC/CAD","bids":[],"asks":[{"price":92631.4,"qty":0.00000000},{"price":92682.1,"qty":0.01096671}],"checksum":3053215063,"timestamp":"2024-06-01T22:42:29.177917Z"}]}
{"channel":"book","type":"update","data":[{"symbol":"BTC/CAD","bids":[{"price":92543.8,"qty":0.00000000},{"price":92411.4,"qty":0.27011769},{"price":92544.0,"qty":0.03219690}],"asks":[],"checksum":2040767379,"timestamp":"2024-06-01T22:42:29.721793Z"}]}
{"channel":"book","type":"update","data":[{"symbol":"BTC/CAD","bids":[],"asks":[{"price":92631.1,"qty":0.00000000},{"price":92692.8,"qty":0.00686000},{"price":92630.9,"qty":0.00667316}],"checksum":2566745455,"timestamp":"2024-06-01T22:42:29.721838Z"}]}
{"channel":"book","type":"update","data":[{"symbol":"BTC/CAD","bids":[{"price":92411.6,"qty":0.07379000}],"asks":[],"checksum":2536752759,"timestamp":"2024-06-01T22:42:29.724918Z"}]}
{"channel":"book","type":"update","data":[{"symbol":"BTC/CAD","bids":[{"price":92543.9,"qty":0.00000000},{"price":92411.5,"qty":0.07085063},{"price":92544.1,"qty":0.01630000}],"asks":[],"checksum":1537961422,"timestamp":"2024-06-01T22:42:29.730526Z"}]}
{"channel":"book","type":"update","data":[{"symbol":"BTC/CAD","bids":[],"asks":[{"price":92630.8,"qty":0.04719084}],"checksum":4280477885,"timestamp":"2024-06-01T22:42:30.177927Z"}]}
{"channel":"book","type":"update","data":[{"symbol":"BTC/CAD","bids":[],"asks":[{"price":92631.0,"qty":0.00000000},{"price":92682.1,"qty":0.01096671}],"checksum":1418803721,"timestamp":"2024-06-01T22:42:30.183573Z"}]}
{"channel":"book","type":"update","data":[{"symbol":"BTC/CAD","bids":[{"price":92411.7,"qty":0.00605791}],"asks":[],"checksum":1826528383,"timestamp":"2024-06-01T22:42:30.374838Z"}]}
{"channel":"book","type":"update","data":[{"symbol":"BTC/CAD","bids":[{"price":92544.0,"qty":0.00000000},{"price":92411.6,"qty":0.07379000},{"price":92544.2,"qty":0.03219688}],"asks":[],"checksum":265535087,"timestamp":"2024-06-01T22:42:30.544461Z"}]}
{"channel":"book","type":"update","data":[{"symbol":"BTC/CAD","bids":[{"price":92544.1,"qty":0.00000000},{"price":92411.6,"qty":0.07379000},{"price":92544.3,"qty":0.01630000}],"asks":[],"checksum":3212601951,"timestamp":"2024-06-01T22:42:30.554871Z"}]}
{"channel":"book","type":"update","data":[{"symbol":"BTC/CAD","bids":[],"asks":[{"price":92665.2,"qty":0.52777564}],"checksum":1945713748,"timestamp":"2024-06-01T22:42:30.927389Z"}]}
{"channel":"book","type":"update","data":[{"symbol":"BTC/CAD","bids":[],"asks":[{"price":92631.3,"qty":0.00000000},{"price":92692.8,"qty":0.00686000}],"checksum":2936164530,"timestamp":"2024-06-01T22:42:31.050494Z"}]}
{"channel":"book","type":"update","data":[{"symbol":"BTC/CAD","bids":[],"asks":[{"price":92665.2,"qty":0.00000000},{"price":92701.1,"qty":0.07380000}],"checksum":697658810,"timestamp":"2024-06-01T22:42:31.050621Z"}]}
{"channel":"book","type":"update","data":[{"symbol":"BTC/CAD","bids":[],"asks":[{"price":92665.1,"qty":0.00000000},{"price":92701.4,"qty":0.32905872},{"price":92668.8,"qty":0.07381000}],"checksum":3911568687,"timestamp":"2024-06-01T22:42:31.053956Z"}]}
{"channel":"book","type":"update","data":[{"symbol":"BTC/CAD","bids":[],"asks":[{"price":92701.1,"qty":0.00000000},{"price":92701.4,"qty":0.32905872},{"price":92701.3,"qty":0.07380000}],"checksum":3534825235,"timestamp":"2024-06-01T22:42:31.054013Z"}]}
{"channel":"book","type":"update","data":[{"symbol":"BTC/CAD","bids":[],"asks":[{"price":92630.7,"qty":0.02953391}],"checksum":1059807836,"timestamp":"2024-06-01T22:42:31.055097Z"}]}
{"channel":"book","type":"update","data":[{"symbol":"BTC/CAD","bids":[],"asks":[{"price":92665.0,"qty":0.61442638}],"checksum":243517329,"timestamp":"2024-06-01T22:42:31.055206Z"}]}
{"channel":"book","type":"update","data":[{"symbol":"BTC/CAD","bids":[],"asks":[{"price":92630.6,"qty":0.04719084}],"checksum":3646451393,"timestamp":"2024-06-01T22:42:31.177535Z"}]}
{"channel":"book","type":"update","data":[{"symbol":"BTC/CAD","bids":[],"asks":[{"price":92630.8,"qty":0.00000000},{"price":92682.1,"qty":0.01096671}],"checksum":3549909140,"timestamp":"2024-06-01T22:42:31.182650Z"}]}
{"channel":"book","type":"update","data":[{"symbol":"BTC/CAD","bids":[],"asks":[{"price":92630.9,"qty":0.00000000},{"price":92692.8,"qty":0.00686000},{"price":92630.5,"qty":0.00667314}],"checksum":3998403255,"timestamp":"2024-06-01T22:42:31.343770Z"}]}
{"channel":"book","type":"update","data":[{"symbol":"BTC/CAD","bids":[{"price":92544.2,"qty":0.00000000},{"price":92411.6,"qty":0.07379000},{"price":92544.4,"qty":0.03219690}],"asks":[],"checksum":1260511030,"timestamp":"2024-06-01T22:42:31.343800Z"}]}
{"channel":"book","type":"update","data":[{"symbol":"BTC/CAD","bids":[],"asks":[{"price":92630.4,"qty":0.04719084}],"checksum":4289374843,"timestamp":"2024-06-01T22:42:31.349713Z"}]}
{"channel":"book","type":"update","data":[{"symbol":"BTC/CAD","bids":[{"price":92544.3,"qty":0.00000000},{"price":92411.6,"qty":0.07379000},{"price":92544.5,"qty":0.01630000}],"asks":[],"checksum":579083468,"timestamp":"2024-06-01T22:42:31.376272Z"}]}
{"channel":"book","type":"update","data":[{"symbol":"BTC/CAD","bids":[],"asks":[{"price":92630.6,"qty":0.00000000},{"price":92682.1,"qty":0.01096671}],"checksum":1114800958,"timestamp":"2024-06-01T22:42:31.382568Z"}]}
{"channel":"book","type":"update","data":[{"symbol":"BTC/CAD","bids":[{"price":92411.8,"qty":1.70068031}],"asks":[],"checksum":3506811601,"timestamp":"2024-06-01T22:42:31.956934Z"}]}
{"channel":"book","type":"update","data":[{"symbol":"BTC/CAD","bids":[],"asks":[{"price":92668.8,"qty":0.00000000},{"price":92692.8,"qty":0.00686000},{"price":92664.9,"qty":0.07381000}],"checksum":3247775032,"timestamp":"2024-06-01T22:42:31.959387Z"}]}
{"channel":"book","type":"update","data":[{"symbol":"BTC/CAD","bids":[{"price":92411.9,"qty":0.07379000}],"asks":[],"checksum":2253532888,"timestamp":"2024-06-01T22:42:31.960286Z"}]}
{"channel":"book","type":"update","data":[{"symbol":"BTC/CAD","bids":[{"price":92411.9,"qty":0.27011769}],"asks":[],"checksum":2147149861,"timestamp":"2024-06-01T22:42:31.960797Z"}]}
{"channel":"book","type":"update","data":[{"symbol":"BTC/CAD","bids":[{"price":92412.0,"qty":0.07085025}],"asks":[],"checksum":2900280828,"timestamp":"2024-06-01T22:42:31.967063Z"}]}
{"channel":"book","type":"update","data":[{"symbol":"BTC/CAD","bids":[{"price":92544.4,"qty":0.00000000},{"price":92411.9,"qty":0.27011769},{"price":92575.0,"qty":0.03218625}],"asks":[],"checksum":2089761503,"timestamp":"2024-06-01T22:42:32.182874Z"}]}
{"channel":"book","type":"update","data":[{"symbol":"BTC/CAD","bids":[{"price":92575.1,"qty":0.04719084}],"asks":[],"checksum":3406821484,"timestamp":"2024-06-01T22:42:32.187837Z"}]}
{"channel":"book","type":"update","data":[{"symbol":"BTC/CAD","bids":[{"price":92575.0,"qty":0.00000000},{"price":92412.0,"qty":0.07085025},{"price":92544.6,"qty":0.03219682}],"asks":[],"checksum":105636054,"timestamp":"2024-06-01T22:42:32.227970Z"}]}
{"channel":"book","type":"update","data":[{"symbol":"BTC/CAD","bids":[{"price":92575.1,"qty":0.00000000},{"price":92412.0,"qty":0.07085025}],"asks":[],"checksum":516287,"timestamp":"2024-06-01T22:42:32.233455Z"}]}
{"channel":"book","type":"update","data":[{"symbol":"BTC/CAD","bids":[{"price":92544.5,"qty":0.00000000},{"price":92411.9,"qty":0.27011769},{"price":92544.7,"qty":0.01630000}],"asks":[],"checksum":720742858,"timestamp":"2024-06-01T22:42:32.257491Z"}]}
{"channel":"book","type":"update","data":[{"symbol":"BTC/CAD","bids":[{"price":92544.6,"qty":0.00000000},{"price":92411.9,"qty":0.27011769},{"price":92544.8,"qty":0.03219685}],"asks":[],"checksum":3869279599,"timestamp":"2024-06-01T22:42:32.993114Z"}]}
{"channel":"book","type":"update","data":[{"symbol":"BTC/CAD","bids":[],"asks":[{"price":92630.5,"qty":0.00000000},{"price":92692.8,"qty":0.00686000},{"price":92630.3,"qty":0.00667314}],"checksum":3528630816,"timestamp":"2024-06-01T22:42:32.993174Z"}]}
{"channel":"book","type":"update","data":[{"symbol":"BTC/CAD","bids":[{"price":92412.1,"qty":0.07379000}],"asks":[],"checksum":313945716,"timestamp":"2024-06-01T22:42:32.996116Z"}]}
{"channel":"book","type":"update","data":[{"symbol":"BTC/CAD","bids":[{"price":92544.7,"qty":0.00000000},{"price":92412.0,"qty":0.07085025},{"price":92544.9,"qty":0.01630000}],"asks":[],"checksum":3226871832,"timestamp":"2024-06-01T22:42:33.015318Z"}]}
{"channel":"book","type":"update","data":[{"symbol":"BTC/CAD","bids":[],"asks":[{"price":92630.2,"qty":0.04719084}],"checksum":3388267459,"timestamp":"2024-06-01T22:42:33.177990Z"}]}
{"channel":"book","type":"update","data":[{"symbol":"BTC/CAD","bids":[],"asks":[{"price":92630.4,"qty":0.00000000},{"price":92682.1,"qty":0.01096671}],"checksum":3551920274,"timestamp":"2024-06-01T22:42:33.182370Z"}]}
{"channel":"book","type":"update","data":[{"symbol":"BTC/CAD","bids":[],"asks":[{"price":92664.8,"qty":0.00249623}],"checksum":3521598119,"timestamp":"2024-06-01T22:42:33.678514Z"}]}
{"channel":"book","type":"update","data":[{"symbol":"BTC/CAD","bids":[],"asks":[{"price":92665.0,"qty":0.00000000},{"price":92682.1,"qty":0.01096671}],"checksum":326098317,"timestamp":"2024-06-01T22:42:33.681332Z"}]}
{"channel":"book","type":"update","data":[{"symbol":"BTC/CAD","bids":[],"asks":[{"price":92630.7,"qty":0.00000000},{"price":92692.8,"qty":0.00686000}],"checksum":155561040,"timestamp":"2024-06-01T22:42:33.681345Z"}]}
{"channel":"book","type":"update","data":[{"symbol":"BTC/CAD","bids":[],"asks":[{"price":92664.8,"qty":0.55193456}],"checksum":666854020,"timestamp":"2024-06-01T22:42:33.684050Z"}]}
{"channel":"book","type":"update","data":[{"symbol":"BTC/CAD","bids":[],"asks":[{"price":92664.9,"qty":0.00000000},{"price":92701.2,"qty":0.23689330},{"price":92668.8,"qty":0.07381000}],"checksum":1613468644,"timestamp":"2024-06-01T22:42:33.684587Z"}]}
{"channel":"book","type":"update","data":[{"symbol":"BTC/CAD","bids":[],"asks":[{"price":92681.9,"qty":0.07380000}],"checksum":1384123514,"timestamp":"2024-06-01T22:42:33.684765Z"}]}
{"channel":"book","type":"update","data":[{"symbol":"BTC/CAD","bids":[],"asks":[{"price":92681.8,"qty":0.01096671}],"checksum":3214359476,"timestamp":"2024-06-01T22:42:33.689372Z"}]}
{"channel":"book","type":"update","data":[{"symbol":"BTC/CAD","bids":[{"price":92412.2,"qty":0.00605791}],"asks":[],"checksum":4084600723,"timestamp":"2024-06-01T22:42:33.817939Z"}]}
{"channel":"book","type":"update","data":[{"symbol":"BTC/CAD","bids":[{"price":92544.8,"qty":0.00000000},{"price":92412.1,"qty":0.07379000},{"price":92545.0,"qty":0.03219681}],"asks":[],"checksum":2803185130,"timestamp":"2024-06-01T22:42:33.832787Z"}]}
{"channel":"book","type":"update","data":[{"symbol":"BTC/CAD","bids":[],"asks":[{"price":92630.3,"qty":0.00000000},{"price":92692.8,"qty":0.00686000},{"price":92630.1,"qty":0.00667317}],"checksum":3442482542,"timestamp":"2024-06-01T22:42:33.832987Z"}]}
{"channel":"book","type":"update","data":[{"symbol":"BTC/CAD","bids":[{"price":92544.9,"qty":0.00000000},{"price":92412.1,"qty":0.07379000},{"price":92545.1,"qty":0.01630000}],"asks":[],"checksum":1417785230,"timestamp":"2024-06-01T22:42:33.866150Z"}]}
{"channel":"book","type":"update","data":[{"symbol":"BTC/CAD","bids":[],"asks":[{"price":92630.0,"qty":0.04719084}],"checksum":541017148,"timestamp":"2024-06-01T22:42:33.871396Z"}]}
{"channel":"book","type":"update","data":[{"symbol":"BTC/CAD","bids":[],"asks":[{"price":92630.2,"qty":0.00000000},{"price":92682.0,"qty":0.07377000}],"checksum":155560512,"timestamp":"2024-06-01T22:42:34.176160Z"}]}
{"channel":"book","type":"update","data":[{"symbol":"BTC/CAD","bids":[{"price":92545.0,"qty":0.00000000},{"price":92412.1,"qty":0.07379000},{"price":92545.2,"qty":0.03219674}],"asks":[],"checksum":3407945942,"timestamp":"2024-06-01T22:42:34.656697Z"}]}
{"channel":"book","type":"update","data":[{"symbol":"BTC/CAD","bids":[],"asks":[{"price":92630.1,"qty":0.00000000},{"price":92692.8,"qty":0.00686000},{"price":92629.9,"qty":0.00667317}],"checksum":3846616893,"timestamp":"2024-06-01T22:42:34.656832Z"}]}
{"channel":"book","type":"update","data":[{"symbol":"BTC/CAD","bids":[],"asks":[{"price":92668.8,"qty":0.00000000},{"price":92692.8,"qty":0.00686000},{"price":92664.7,"qty":0.07381000}],"checksum":1813935417,"timestamp":"2024-06-01T22:42:34.659728Z"}]}
{"channel":"book","type":"update","data":[{"symbol":"BTC/CAD","bids":[],"asks":[{"price":92629.8,"qty":0.04719084}],"checksum":2348652668,"timestamp":"2024-06-01T22:42:34.675677Z"}]}
{"channel":"book","type":"update","data":[{"symbol":"BTC/CAD","bids":[{"price":92545.1,"qty":0.00000000},{"price":92412.1,"qty":0.07379000},{"price":92545.3,"qty":0.01630000}],"asks":[],"checksum":3937741589,"timestamp":"2024-06-01T22:42:34.684410Z"}]}
{"channel":"book","type":"update","data":[{"symbol":"BTC/CAD","bids":[{"price":92412.3,"qty":1.84474465}],"asks":[],"checksum":609300504,"timestamp":"2024-06-01T22:42:34.824883Z"}]}
{"channel":"book","type":"update","data":[{"symbol":"BTC/CAD","bids":[{"price":92412.4,"qty":0.07379000}],"asks":[],"checksum":4088778977,"timestamp":"2024-06-01T22:42:34.827851Z"}]}
{"channel":"book","type":"update","data":[{"symbol":"BTC/CAD","bids":[{"price":92412.4,"qty":0.27011769}],"asks":[],"checksum":545949651,"timestamp":"2024-06-01T22:42:34.828167Z"}]}
{"channel":"book","type":"update","data":[{"symbol":"BTC/CAD","bids":[{"price":92412.5,"qty":0.07084986}],"asks":[],"checksum":3889887599,"timestamp":"2024-06-01T22:42:34.854455Z"}]}
{"channel":"book","type":"update","data":[{"symbol":"BTC/CAD","bids":[],"asks":[{"price":92630.0,"qty":0.00000000},{"price":92682.0,"qty":0.07377000}],"checksum":2315052924,"timestamp":"2024-06-01T22:42:35.175115Z"}]}
{"channel":"book","type":"update","data":[{"symbol":"BTC/CAD","bids":[{"price":92412.6,"qty":0.07379000}],"asks":[],"checksum":3753298319,"timestamp":"2024-06-01T22:42:35.408268Z"}]}
