{"channel":"book","type":"snapshot","data":[{"symbol":"BTC/USDC","bids":[{"price":67713.98,"qty":0.01900000},{"price":67706.03,"qty":0.00240688},{"price":67704.81,"qty":0.00182633},{"price":67703.03,"qty":0.02953391},{"price":67703.02,"qty":0.03692597},{"price":67700.28,"qty":0.07267774},{"price":67700.00,"qty":0.00073855},{"price":67696.30,"qty":0.05340781},{"price":67694.58,"qty":0.01900000},{"price":67690.51,"qty":0.07386559}],"asks":[{"price":67724.17,"qty":0.09956810},{"price":67724.27,"qty":0.14768014},{"price":67740.79,"qty":0.00356040},{"price":67740.80,"qty":0.09452196},{"price":67740.81,"qty":0.02161000},{"price":67741.52,"qty":0.00028461},{"price":67741.53,"qty":0.59060117},{"price":67741.54,"qty":0.07380995},{"price":67747.86,"qty":1.01740044},{"price":67747.87,"qty":0.17000000}],"checksum":2504006977}]}
{"channel":"book","type":"update","data":[{"symbol":"BTC/USDC","bids":[],"asks":[{"price":67740.80,"qty":0.00000000},{"price":67747.98,"qty":0.04647919}],"checksum":632969045,"timestamp":"2024-06-01T22:42:07.494070Z"}]}
{"channel":"book","type":"update","data":[{"symbol":"BTC/USDC","bids":[],"asks":[{"price":67747.86,"qty":0.00000000},{"price":67748.85,"qty":1.09794493}],"checksum":2601762679,"timestamp":"2024-06-01T22:42:07.494285Z"}]}
{"channel":"book","type":"update","data":[{"symbol":"BTC/USDC","bids":[],"asks":[{"price":67724.16,"qty":0.14768037}],"checksum":4204301261,"timestamp":"2024-06-01T22:42:07.497427Z"}]}
{"channel":"book","type":"update","data":[{"symbol":"BTC/USDC","bids":[],"asks":[{"price":67724.27,"qty":0.00000000},{"price":67748.85,"qty":1.09794493}],"checksum":1491297628,"timestamp":"2024-06-01T22:42:07.497539Z"}]}
{"channel":"book","type":"update","data":[{"symbol":"BTC/USDC","bids":[],"asks":[{"price":67740.78,"qty":0.74440248}],"checksum":1185107068,"timestamp":"2024-06-01T22:42:07.499063Z"}]}
{"channel":"book","type":"update","data":[{"symbol":"BTC/USDC","bids":[],"asks":[{"price":67741.52,"qty":0.19367801}],"checksum":1304507480,"timestamp":"2024-06-01T22:42:07.499142Z"}]}
{"channel":"book","type":"update","data":[{"symbol":"BTC/USDC","bids":[],"asks":[{"price":67724.17,"qty":0.03691444}],"checksum":3181136430,"timestamp":"2024-06-01T22:42:07.501660Z"}]}
{"channel":"book","type":"update","data":[{"symbol":"BTC/USDC","bids":[],"asks":[{"price":67724.17,"qty":0.00000000},{"price":67748.85,"qty":1.09794493}],"checksum":21517284,"timestamp":"2024-06-01T22:42:07.501787Z"}]}
{"channel":"book","type":"update","data":[{"symbol":"BTC/USDC","bids":[],"asks":[{"price":67724.06,"qty":0.03691450}],"checksum":395075834,"timestamp":"2024-06-01T22:42:07.505665Z"}]}
{"channel":"book","type":"update","data":[{"symbol":"BTC/USDC","bids":[{"price":67694.58,"qty":0.00000000},{"price":67681.39,"qty":0.06993823}],"asks":[],"checksum":2856080755,"timestamp":"2024-06-01T22:42:07.630060Z"}]}
{"channel":"book","type":"update","data":[{"symbol":"BTC/USDC","bids":[],"asks":[{"price":67724.01,"qty":0.14768071}],"checksum":2087641437,"timestamp":"2024-06-01T22:42:07.632936Z"}]}
{"channel":"book","type":"update","data":[{"symbol":"BTC/USDC","bids":[],"asks":[{"price":67724.16,"qty":0.00000000},{"price":67747.98,"qty":0.04647919}],"checksum":846344163,"timestamp":"2024-06-01T22:42:07.635731Z"}]}
{"channel":"book","type":"update","data":[{"symbol":"BTC/USDC","bids":[],"asks":[{"price":67724.06,"qty":0.00000000},{"price":67748.85,"qty":1.09794493}],"checksum":2835916232,"timestamp":"2024-06-01T22:42:07.637892Z"}]}
{"channel":"book","type":"update","data":[{"symbol":"BTC/USDC","bids":[],"asks":[{"price":67724.01,"qty":0.21033437}],"checksum":8820284,"timestamp":"2024-06-01T22:42:07.711814Z"}]}
{"channel":"book","type":"update","data":[{"symbol":"BTC/USDC","bids":[{"price":67694.49,"qty":0.01900000}],"asks":[],"checksum":829238689,"timestamp":"2024-06-01T22:42:07.897802Z"}]}
{"channel":"book","type":"update","data":[{"symbol":"BTC/USDC","bids":[],"asks":[{"price":67747.87,"qty":0.00000000},{"price":67751.15,"qty":0.00400000},{"price":67747.97,"qty":0.17000000}],"checksum":1802935804,"timestamp":"2024-06-01T22:42:08.263764Z"}]}
{"channel":"book","type":"update","data":[{"symbol":"BTC/USDC","bids":[{"price":67694.49,"qty":0.00000000},{"price":67681.40,"qty":0.00350000}],"asks":[],"checksum":3295289444,"timestamp":"2024-06-01T22:42:08.447419Z"}]}
{"channel":"book","type":"update","data":[{"symbol":"BTC/USDC","bids":[{"price":67694.50,"qty":0.01900000}],"asks":[],"checksum":1584281064,"timestamp":"2024-06-01T22:42:08.697752Z"}]}
{"channel":"book","type":"update","data":[{"symbol":"BTC/USDC","bids":[],"asks":[{"price":67740.79,"qty":0.00000000},{"price":67751.15,"qty":0.00400000}],"checksum":593937313,"timestamp":"2024-06-01T22:42:08.851665Z"}]}
{"channel":"book","type":"update","data":[{"symbol":"BTC/USDC","bids":[],"asks":[{"price":67740.77,"qty":0.00397155}],"checksum":2966621994,"timestamp":"2024-06-01T22:42:08.856538Z"}]}
{"channel":"book","type":"update","data":[{"symbol":"BTC/USDC","bids":[],"asks":[{"price":67723.91,"qty":0.03691458}],"checksum":1546510546,"timestamp":"2024-06-01T22:42:08.948221Z"}]}
{"channel":"book","type":"update","data":[{"symbol":"BTC/USDC","bids":[],"asks":[{"price":67724.01,"qty":0.14768071}],"checksum":2497548666,"timestamp":"2024-06-01T22:42:08.951276Z"}]}
{"channel":"book","type":"update","data":[{"symbol":"BTC/USDC","bids":[],"asks":[{"price":67723.91,"qty":0.10267945}],"checksum":2164585674,"timestamp":"2024-06-01T22:42:09.152692Z"}]}
{"channel":"book","type":"update","data":[{"symbol":"BTC/USDC","bids":[{"price":67694.50,"qty":0.00000000},{"price":67681.41,"qty":0.03198949}],"asks":[],"checksum":3964968795,"timestamp":"2024-06-01T22:42:09.454647Z"}]}
{"channel":"book","type":"update","data":[{"symbol":"BTC/USDC","bids":[{"price":67694.47,"qty":0.01900000}],"asks":[],"checksum":2142117982,"timestamp":"2024-06-01T22:42:09.955981Z"}]}
{"channel":"book","type":"update","data":[{"symbol":"BTC/USDC","bids":[],"asks":[{"price":67740.78,"qty":0.00000000},{"price":67748.85,"qty":1.09794493}],"checksum":1695472189,"timestamp":"2024-06-01T22:42:10.073853Z"}]}
{"channel":"book","type":"update","data":[{"symbol":"BTC/USDC","bids":[],"asks":[{"price":67741.52,"qty":0.00028461}],"checksum":1279603318,"timestamp":"2024-06-01T22:42:10.073997Z"}]}
{"channel":"book","type":"update","data":[{"symbol":"BTC/USDC","bids":[],"asks":[{"price":67740.76,"qty":0.67941443}],"checksum":4034917819,"timestamp":"2024-06-01T22:42:10.079181Z"}]}
{"channel":"book","type":"update","data":[{"symbol":"BTC/USDC","bids":[],"asks":[{"price":67741.52,"qty":0.21532483}],"checksum":3125762732,"timestamp":"2024-06-01T22:42:10.079300Z"}]}
{"channel":"book","type":"update","data":[{"symbol":"BTC/USDC","bids":[],"asks":[{"price":67740.77,"qty":0.00000000},{"price":67748.85,"qty":1.09794493}],"checksum":3281147546,"timestamp":"2024-06-01T22:42:11.665873Z"}]}
{"channel":"book","type":"update","data":[{"symbol":"BTC/USDC","bids":[],"asks":[{"price":67740.75,"qty":0.00377807}],"checksum":3788208251,"timestamp":"2024-06-01T22:42:11.670304Z"}]}
{"channel":"book","type":"update","data":[{"symbol":"BTC/USDC","bids":[{"price":67694.47,"qty":0.00000000},{"price":67681.44,"qty":0.03198949}],"asks":[],"checksum":986827034,"timestamp":"2024-06-01T22:42:12.123238Z"}]}
{"channel":"book","type":"update","data":[{"symbol":"BTC/USDC","bids":[{"price":67681.45,"qty":0.00350000}],"asks":[],"checksum":2645649512,"timestamp":"2024-06-01T22:42:12.263991Z"}]}
{"channel":"book","type":"update","data":[{"symbol":"BTC/USDC","bids":[{"price":67694.46,"qty":0.01900000}],"asks":[],"checksum":4142079163,"timestamp":"2024-06-01T22:42:12.387585Z"}]}
{"channel":"book","type":"update","data":[{"symbol":"BTC/USDC","bids":[],"asks":[{"price":67740.76,"qty":0.00000000},{"price":67748.85,"qty":1.09794493}],"checksum":1722912168,"timestamp":"2024-06-01T22:42:12.781880Z"}]}
{"channel":"book","type":"update","data":[{"symbol":"BTC/USDC","bids":[],"asks":[{"price":67741.52,"qty":0.00028461}],"checksum":3885172029,"timestamp":"2024-06-01T22:42:12.781923Z"}]}
{"channel":"book","type":"update","data":[{"symbol":"BTC/USDC","bids":[],"asks":[{"price":67740.74,"qty":0.67941443}],"checksum":3526554193,"timestamp":"2024-06-01T22:42:12.786726Z"}]}
{"channel":"book","type":"update","data":[{"symbol":"BTC/USDC","bids":[],"asks":[{"price":67741.52,"qty":0.23682885}],"checksum":1599187444,"timestamp":"2024-06-01T22:42:12.786855Z"}]}
{"channel":"book","type":"update","data":[{"symbol":"BTC/USDC","bids":[{"price":67700.29,"qty":0.05834678}],"asks":[],"checksum":4115022776,"timestamp":"2024-06-01T22:42:13.449758Z"}]}
{"channel":"book","type":"update","data":[{"symbol":"BTC/USDC","bids":[],"asks":[{"price":67741.52,"qty":0.23654424}],"checksum":4016617580,"timestamp":"2024-06-01T22:42:13.917020Z"}]}
{"channel":"book","type":"update","data":[{"symbol":"BTC/USDC","bids":[],"asks":[{"price":67740.75,"qty":0.00000000},{"price":67748.85,"qty":1.09794493}],"checksum":39085787,"timestamp":"2024-06-01T22:42:14.314973Z"}]}
{"channel":"book","type":"update","data":[{"symbol":"BTC/USDC","bids":[],"asks":[{"price":67740.73,"qty":0.00372866}],"checksum":1896404651,"timestamp":"2024-06-01T22:42:14.317760Z"}]}
{"channel":"book","type":"update","data":[{"symbol":"BTC/USDC","bids":[{"price":67713.98,"qty":0.00000000},{"price":67690.51,"qty":0.07386559}],"asks":[],"checksum":1852258585,"timestamp":"2024-06-01T22:42:14.480526Z"}]}
{"channel":"book","type":"update","data":[{"symbol":"BTC/USDC","bids":[{"price":67706.03,"qty":0.01440688}],"asks":[],"checksum":2157248857,"timestamp":"2024-06-01T22:42:14.514637Z"}]}
{"channel":"book","type":"update","data":[{"symbol":"BTC/USDC","bids":[],"asks":[{"price":67745.44,"qty":1.09796055}],"checksum":3799119452,"timestamp":"2024-06-01T22:42:14.521786Z"}]}
{"channel":"book","type":"update","data":[{"symbol":"BTC/USDC","bids":[{"price":67700.05,"qty":0.02309426}],"asks":[],"checksum":3951576765,"timestamp":"2024-06-01T22:42:14.751576Z"}]}
{"channel":"book","type":"update","data":[{"symbol":"BTC/USDC","bids":[],"asks":[{"price":67740.74,"qty":0.00000000},{"price":67747.98,"qty":0.04647919}],"checksum":577509485,"timestamp":"2024-06-01T22:42:15.294492Z"}]}
{"channel":"book","type":"update","data":[{"symbol":"BTC/USDC","bids":[],"asks":[{"price":67741.52,"qty":0.00000000},{"price":67750.03,"qty":0.00400000}],"checksum":276537094,"timestamp":"2024-06-01T22:42:15.294597Z"}]}
{"channel":"book","type":"update","data":[{"symbol":"BTC/USDC","bids":[],"asks":[{"price":67740.72,"qty":0.67941443}],"checksum":607200732,"timestamp":"2024-06-01T22:42:15.299869Z"}]}
{"channel":"book","type":"update","data":[{"symbol":"BTC/USDC","bids":[],"asks":[{"price":67741.52,"qty":0.15052815}],"checksum":1119298278,"timestamp":"2024-06-01T22:42:15.300073Z"}]}
{"channel":"book","type":"update","data":[{"symbol":"BTC/USDC","bids":[{"price":67700.29,"qty":0.00000000},{"price":67690.51,"qty":0.07386559}],"asks":[],"checksum":1213016206,"timestamp":"2024-06-01T22:42:16.826102Z"}]}
{"channel":"book","type":"update","data":[{"symbol":"BTC/USDC","bids":[{"price":67700.29,"qty":0.17359826}],"asks":[],"checksum":350868026,"timestamp":"2024-06-01T22:42:16.826679Z"}]}
{"channel":"book","type":"update","data":[{"symbol":"BTC/USDC","bids":[],"asks":[{"price":67740.73,"qty":0.00000000},{"price":67747.98,"qty":0.04647919}],"checksum":1962155148,"timestamp":"2024-06-01T22:42:17.035568Z"}]}
{"channel":"book","type":"update","data":[{"symbol":"BTC/USDC","bids":[],"asks":[{"price":67740.71,"qty":0.00358458}],"checksum":2072469605,"timestamp":"2024-06-01T22:42:17.040327Z"}]}
{"channel":"book","type":"update","data":[{"symbol":"BTC/USDC","bids":[],"asks":[{"price":67740.72,"qty":0.00000000},{"price":67747.98,"qty":0.04647919}],"checksum":4249364501,"timestamp":"2024-06-01T22:42:17.845870Z"}]}
{"channel":"book","type":"update","data":[{"symbol":"BTC/USDC","bids":[],"asks":[{"price":67741.52,"qty":0.00000000},{"price":67755.85,"qty":0.01540151}],"checksum":902962882,"timestamp":"2024-06-01T22:42:17.845932Z"}]}
{"channel":"book","type":"update","data":[{"symbol":"BTC/USDC","bids":[],"asks":[{"price":67740.70,"qty":0.67941443}],"checksum":3524545756,"timestamp":"2024-06-01T22:42:17.850742Z"}]}
{"channel":"book","type":"update","data":[{"symbol":"BTC/USDC","bids":[],"asks":[{"price":67741.52,"qty":0.25804826}],"checksum":3631160637,"timestamp":"2024-06-01T22:42:17.850837Z"}]}
{"channel":"book","type":"update","data":[{"symbol":"BTC/USDC","bids":[{"price":67703.04,"qty":0.00029534}],"asks":[],"checksum":1001201116,"timestamp":"2024-06-01T22:42:18.233077Z"}]}
{"channel":"book","type":"update","data":[{"symbol":"BTC/USDC","bids":[{"price":67700.30,"qty":0.00288850}],"asks":[],"checksum":3551854384,"timestamp":"2024-06-01T22:42:18.233190Z"}]}
{"channel":"book","type":"update","data":[{"symbol":"BTC/USDC","bids":[],"asks":[{"price":67740.71,"qty":0.00000000},{"price":67747.98,"qty":0.04647919}],"checksum":2199578348,"timestamp":"2024-06-01T22:42:19.796361Z"}]}
{"channel":"book","type":"update","data":[{"symbol":"BTC/USDC","bids":[],"asks":[{"price":67740.69,"qty":0.00377807}],"checksum":1357254705,"timestamp":"2024-06-01T22:42:19.798575Z"}]}
{"channel":"book","type":"update","data":[{"symbol":"BTC/USDC","bids":[],"asks":[{"price":67747.97,"qty":0.00000000},{"price":67747.98,"qty":0.04647919},{"price":67745.43,"qty":0.17000000}],"checksum":2434102434,"timestamp":"2024-06-01T22:42:20.263338Z"}]}
{"channel":"book","type":"update","data":[{"symbol":"BTC/USDC","bids":[{"price":67700.29,"qty":0.00000000},{"price":67696.30,"qty":0.05340781}],"asks":[],"checksum":1717969783,"timestamp":"2024-06-01T22:42:20.306200Z"}]}
{"channel":"book","type":"update","data":[{"symbol":"BTC/USDC","bids":[{"price":67703.03,"qty":0.00000000},{"price":67694.46,"qty":0.01900000}],"asks":[],"checksum":3849862078,"timestamp":"2024-06-01T22:42:20.306211Z"}]}
{"channel":"book","type":"update","data":[{"symbol":"BTC/USDC","bids":[{"price":67703.05,"qty":0.02953391}],"asks":[],"checksum":223424843,"timestamp":"2024-06-01T22:42:20.307349Z"}]}
{"channel":"book","type":"update","data":[{"symbol":"BTC/USDC","bids":[{"price":67700.31,"qty":0.17359826}],"asks":[],"checksum":1454837222,"timestamp":"2024-06-01T22:42:20.307456Z"}]}
{"channel":"book","type":"update","data":[{"symbol":"BTC/USDC","bids":[],"asks":[{"price":67740.70,"qty":0.00000000},{"price":67747.98,"qty":0.04647919}],"checksum":1765104703,"timestamp":"2024-06-01T22:42:20.492154Z"}]}
{"channel":"book","type":"update","data":[{"symbol":"BTC/USDC","bids":[],"asks":[{"price":67741.52,"qty":0.00000000},{"price":67751.27,"qty":0.00400000}],"checksum":4284130533,"timestamp":"2024-06-01T22:42:20.492349Z"}]}
{"channel":"book","type":"update","data":[{"symbol":"BTC/USDC","bids":[],"asks":[{"price":67740.68,"qty":0.67941443}],"checksum":2961341297,"timestamp":"2024-06-01T22:42:20.494506Z"}]}
{"channel":"book","type":"update","data":[{"symbol":"BTC/USDC","bids":[],"asks":[{"price":67741.52,"qty":0.23654424}],"checksum":1273017730,"timestamp":"2024-06-01T22:42:20.494525Z"}]}
{"channel":"book","type":"update","data":[{"symbol":"BTC/USDC","bids":[{"price":67700.05,"qty":0.00000000},{"price":67696.30,"qty":0.05340781}],"asks":[],"checksum":3725389988,"timestamp":"2024-06-01T22:42:21.412307Z"}]}
{"channel":"book","type":"update","data":[{"symbol":"BTC/USDC","bids":[{"price":67703.04,"qty":0.00000000},{"price":67694.46,"qty":0.01900000}],"asks":[],"checksum":671961053,"timestamp":"2024-06-01T22:42:21.428039Z"}]}
{"channel":"book","type":"update","data":[{"symbol":"BTC/USDC","bids":[{"price":67700.30,"qty":0.00000000},{"price":67690.51,"qty":0.07386559}],"asks":[],"checksum":774351765,"timestamp":"2024-06-01T22:42:21.428118Z"}]}
{"channel":"book","type":"update","data":[{"symbol":"BTC/USDC","bids":[{"price":67703.06,"qty":0.00029534}],"asks":[],"checksum":956804621,"timestamp":"2024-06-01T22:42:21.428981Z"}]}
{"channel":"book","type":"update","data":[{"symbol":"BTC/USDC","bids":[{"price":67700.32,"qty":0.00288850}],"asks":[],"checksum":438257844,"timestamp":"2024-06-01T22:42:21.429106Z"}]}
{"channel":"book","type":"update","data":[{"symbol":"BTC/USDC","bids":[],"asks":[{"price":67740.69,"qty":0.00000000},{"price":67747.98,"qty":0.04647919}],"checksum":2376222211,"timestamp":"2024-06-01T22:42:22.572699Z"}]}
{"channel":"book","type":"update","data":[{"symbol":"BTC/USDC","bids":[],"asks":[{"price":67740.67,"qty":0.00372195}],"checksum":2875660153,"timestamp":"2024-06-01T22:42:22.575022Z"}]}
{"channel":"book","type":"update","data":[{"symbol":"BTC/USDC","bids":[],"asks":[{"price":67740.68,"qty":0.00000000},{"price":67747.98,"qty":0.04647919}],"checksum":3494853106,"timestamp":"2024-06-01T22:42:23.066207Z"}]}
{"channel":"book","type":"update","data":[{"symbol":"BTC/USDC","bids":[],"asks":[{"price":67741.52,"qty":0.00000000},{"price":67751.27,"qty":0.00400000}],"checksum":3927922021,"timestamp":"2024-06-01T22:42:23.066361Z"}]}
{"channel":"book","type":"update","data":[{"symbol":"BTC/USDC","bids":[],"asks":[{"price":67740.66,"qty":0.67941443}],"checksum":2553471539,"timestamp":"2024-06-01T22:42:23.071831Z"}]}
{"channel":"book","type":"update","data":[{"symbol":"BTC/USDC","bids":[],"asks":[{"price":67741.52,"qty":0.25804826}],"checksum":261358005,"timestamp":"2024-06-01T22:42:23.072036Z"}]}
{"channel":"book","type":"update","data":[{"symbol":"BTC/USDC","bids":[{"price":67700.31,"qty":0.00000000},{"price":67694.46,"qty":0.01900000}],"asks":[],"checksum":2781529982,"timestamp":"2024-06-01T22:42:23.735987Z"}]}
{"channel":"book","type":"update","data":[{"symbol":"BTC/USDC","bids":[{"price":67703.05,"qty":0.00000000},{"price":67690.51,"qty":0.07386559}],"asks":[],"checksum":3093736534,"timestamp":"2024-06-01T22:42:23.736010Z"}]}
{"channel":"book","type":"update","data":[{"symbol":"BTC/USDC","bids":[{"price":67700.33,"qty":0.20241112}],"asks":[],"checksum":1868975840,"timestamp":"2024-06-01T22:42:23.736628Z"}]}
{"channel":"book","type":"update","data":[{"symbol":"BTC/USDC","bids":[{"price":67703.03,"qty":0.02953391}],"asks":[],"checksum":3743153002,"timestamp":"2024-06-01T22:42:23.736683Z"}]}
{"channel":"book","type":"update","data":[{"symbol":"BTC/USDC","bids":[],"asks":[{"price":67745.43,"qty":0.00000000},{"price":67747.98,"qty":0.04647919}],"checksum":3974392815,"timestamp":"2024-06-01T22:42:24.263361Z"}]}
{"channel":"book","type":"update","data":[{"symbol":"BTC/USDC","bids":[{"price":67703.06,"qty":0.00000000},{"price":67694.46,"qty":0.01900000}],"asks":[],"checksum":3010081404,"timestamp":"2024-06-01T22:42:24.623360Z"}]}
{"channel":"book","type":"update","data":[{"symbol":"BTC/USDC","bids":[{"price":67700.32,"qty":0.00000000},{"price":67690.52,"qty":0.00350000}],"asks":[],"checksum":355236353,"timestamp":"2024-06-01T22:42:24.623551Z"}]}
{"channel":"book","type":"update","data":[{"symbol":"BTC/USDC","bids":[{"price":67700.34,"qty":0.00288850}],"asks":[],"checksum":636616655,"timestamp":"2024-06-01T22:42:24.625337Z"}]}
{"channel":"book","type":"update","data":[{"symbol":"BTC/USDC","bids":[{"price":67703.04,"qty":0.00029534}],"asks":[],"checksum":2198473962,"timestamp":"2024-06-01T22:42:24.625356Z"}]}
{"channel":"book","type":"update","data":[{"symbol":"BTC/USDC","bids":[],"asks":[{"price":67740.67,"qty":0.00000000},{"price":67755.85,"qty":0.01540151}],"checksum":1281539343,"timestamp":"2024-06-01T22:42:25.407841Z"}]}
{"channel":"book","type":"update","data":[{"symbol":"BTC/USDC","bids":[],"asks":[{"price":67740.65,"qty":0.00358458}],"checksum":1705852029,"timestamp":"2024-06-01T22:42:25.410212Z"}]}
{"channel":"book","type":"update","data":[{"symbol":"BTC/USDC","bids":[{"price":67700.33,"qty":0.00000000},{"price":67694.46,"qty":0.01900000}],"asks":[],"checksum":266998993,"timestamp":"2024-06-01T22:42:27.231539Z"}]}
{"channel":"book","type":"update","data":[{"symbol":"BTC/USDC","bids":[{"price":67703.03,"qty":0.00000000},{"price":67690.52,"qty":0.00350000}],"asks":[],"checksum":3511088661,"timestamp":"2024-06-01T22:42:27.231676Z"}]}
{"channel":"book","type":"update","data":[{"symbol":"BTC/USDC","bids":[{"price":67703.05,"qty":0.02953391}],"asks":[],"checksum":1692206829,"timestamp":"2024-06-01T22:42:27.232459Z"}]}
{"channel":"book","type":"update","data":[{"symbol":"BTC/USDC","bids":[{"price":67700.35,"qty":0.20241112}],"asks":[],"checksum":1027254923,"timestamp":"2024-06-01T22:42:27.232640Z"}]}
{"channel":"book","type":"update","data":[{"symbol":"BTC/USDC","bids":[{"price":67700.34,"qty":0.00000000},{"price":67694.46,"qty":0.01900000}],"asks":[],"checksum":424390135,"timestamp":"2024-06-01T22:42:27.859565Z"}]}
{"channel":"book","type":"update","data":[{"symbol":"BTC/USDC","bids":[{"price":67703.04,"qty":0.00000000},{"price":67690.53,"qty":2.23334552}],"asks":[],"checksum":3075480166,"timestamp":"2024-06-01T22:42:27.859578Z"}]}
{"channel":"book","type":"update","data":[{"symbol":"BTC/USDC","bids":[{"price":67703.06,"qty":0.00029534}],"asks":[],"checksum":1693587070,"timestamp":"2024-06-01T22:42:27.860750Z"}]}
{"channel":"book","type":"update","data":[{"symbol":"BTC/USDC","bids":[{"price":67700.36,"qty":0.00461727}],"asks":[],"checksum":2827728176,"timestamp":"2024-06-01T22:42:27.860809Z"}]}
{"channel":"book","type":"update","data":[{"symbol":"BTC/USDC","bids":[],"asks":[{"price":67747.97,"qty":0.17000000}],"checksum":3534606438,"timestamp":"2024-06-01T22:42:28.263784Z"}]}
{"channel":"book","type":"update","data":[{"symbol":"BTC/USDC","bids":[],"asks":[{"price":67740.66,"qty":0.00000000},{"price":67747.98,"qty":0.04647919}],"checksum":2741832710,"timestamp":"2024-06-01T22:42:28.402169Z"}]}
{"channel":"book","type":"update","data":[{"symbol":"BTC/USDC","bids":[],"asks":[{"price":67740.64,"qty":0.67941443}],"checksum":4064455256,"timestamp":"2024-06-01T22:42:28.406874Z"}]}
{"channel":"book","type":"update","data":[{"symbol":"BTC/USDC","bids":[{"price":67700.28,"qty":0.00000000},{"price":67694.46,"qty":0.01900000}],"asks":[],"checksum":3354789415,"timestamp":"2024-06-01T22:42:29.655482Z"}]}
{"channel":"book","type":"update","data":[{"symbol":"BTC/USDC","bids":[{"price":67700.28,"qty":0.07267773}],"asks":[],"checksum":546827486,"timestamp":"2024-06-01T22:42:29.658780Z"}]}
{"channel":"book","type":"update","data":[{"symbol":"BTC/USDC","bids":[{"price":67703.05,"qty":0.00000000},{"price":67694.46,"qty":0.01900000}],"asks":[],"checksum":3886169353,"timestamp":"2024-06-01T22:42:30.634345Z"}]}
{"channel":"book","type":"update","data":[{"symbol":"BTC/USDC","bids":[{"price":67700.35,"qty":0.00000000},{"price":67690.54,"qty":0.02326903}],"asks":[],"checksum":1344438161,"timestamp":"2024-06-01T22:42:30.634413Z"}]}
{"channel":"book","type":"update","data":[{"symbol":"BTC/USDC","bids":[{"price":67703.03,"qty":0.02953391}],"asks":[],"checksum":3373023687,"timestamp":"2024-06-01T22:42:30.635044Z"}]}
{"channel":"book","type":"update","data":[{"symbol":"BTC/USDC","bids":[{"price":67700.37,"qty":0.23122399}],"asks":[],"checksum":2725214339,"timestamp":"2024-06-01T22:42:30.635337Z"}]}
{"channel":"book","type":"update","data":[{"symbol":"BTC/USDC","bids":[],"asks":[{"price":67740.65,"qty":0.00000000},{"price":67747.98,"qty":0.04647919}],"checksum":548185787,"timestamp":"2024-06-01T22:42:30.927481Z"}]}
{"channel":"book","type":"update","data":[{"symbol":"BTC/USDC","bids":[],"asks":[{"price":67740.63,"qty":0.00377807}],"checksum":2736289112,"timestamp":"2024-06-01T22:42:30.930772Z"}]}
{"channel":"book","type":"update","data":[{"symbol":"BTC/USDC","bids":[{"price":67703.06,"qty":0.00000000},{"price":67694.46,"qty":0.01900000}],"asks":[],"checksum":2451056627,"timestamp":"2024-06-01T22:42:31.002370Z"}]}
{"channel":"book","type":"update","data":[{"symbol":"BTC/USDC","bids":[{"price":67700.36,"qty":0.00000000},{"price":67690.55,"qty":2.20250675}],"asks":[],"checksum":2517887371,"timestamp":"2024-06-01T22:42:31.002430Z"}]}
{"channel":"book","type":"update","data":[{"symbol":"BTC/USDC","bids":[{"price":67700.38,"qty":0.00461727}],"asks":[],"checksum":181942718,"timestamp":"2024-06-01T22:42:31.003025Z"}]}
{"channel":"book","type":"update","data":[{"symbol":"BTC/USDC","bids":[{"price":67703.04,"qty":0.00029534}],"asks":[],"checksum":3028312548,"timestamp":"2024-06-01T22:42:31.003041Z"}]}
{"channel":"book","type":"update","data":[{"symbol":"BTC/USDC","bids":[],"asks":[{"price":67741.52,"qty":0.00000000},{"price":67747.98,"qty":0.04647919}],"checksum":1664801193,"timestamp":"2024-06-01T22:42:31.050358Z"}]}
{"channel":"book","type":"update","data":[{"symbol":"BTC/USDC","bids":[],"asks":[{"price":67741.52,"qty":0.23654424}],"checksum":4128952996,"timestamp":"2024-06-01T22:42:31.054977Z"}]}
{"channel":"book","type":"update","data":[{"symbol":"BTC/USDC","bids":[],"asks":[{"price":67747.97,"qty":0.00000000},{"price":67747.98,"qty":0.04647919}],"checksum":3952480074,"timestamp":"2024-06-01T22:42:32.263959Z"}]}
{"channel":"book","type":"update","data":[{"symbol":"BTC/USDC","bids":[],"asks":[{"price":67743.33,"qty":0.01440688}],"checksum":2418210727,"timestamp":"2024-06-01T22:42:32.979382Z"}]}
{"channel":"book","type":"update","data":[{"symbol":"BTC/USDC","bids":[],"asks":[{"price":67740.63,"qty":0.00000000},{"price":67747.98,"qty":0.04647919}],"checksum":1088833333,"timestamp":"2024-06-01T22:42:33.676157Z"}]}
{"channel":"book","type":"update","data":[{"symbol":"BTC/USDC","bids":[],"asks":[{"price":67740.63,"qty":0.00358458}],"checksum":1628050595,"timestamp":"2024-06-01T22:42:33.678447Z"}]}
{"channel":"book","type":"update","data":[{"symbol":"BTC/USDC","bids":[],"asks":[{"price":67740.64,"qty":0.00000000},{"price":67747.98,"qty":0.04647919}],"checksum":2861253338,"timestamp":"2024-06-01T22:42:33.681047Z"}]}
{"channel":"book","type":"update","data":[{"symbol":"BTC/USDC","bids":[],"asks":[{"price":67740.62,"qty":0.67941443}],"checksum":318529517,"timestamp":"2024-06-01T22:42:33.683977Z"}]}
{"channel":"book","type":"update","data":[{"symbol":"BTC/USDC","bids":[{"price":67703.03,"qty":0.00000000},{"price":67694.46,"qty":0.01900000}],"asks":[],"checksum":1818631690,"timestamp":"2024-06-01T22:42:34.124967Z"}]}
{"channel":"book","type":"update","data":[{"symbol":"BTC/USDC","bids":[{"price":67700.37,"qty":0.00000000},{"price":67690.57,"qty":0.00350000}],"asks":[],"checksum":3007788070,"timestamp":"2024-06-01T22:42:34.124994Z"}]}
{"channel":"book","type":"update","data":[{"symbol":"BTC/USDC","bids":[{"price":67703.05,"qty":0.02953391}],"asks":[],"checksum":2275396505,"timestamp":"2024-06-01T22:42:34.125570Z"}]}
{"channel":"book","type":"update","data":[{"symbol":"BTC/USDC","bids":[{"price":67700.39,"qty":0.23122399}],"asks":[],"checksum":2143288655,"timestamp":"2024-06-01T22:42:34.125706Z"}]}
{"channel":"book","type":"update","data":[{"symbol":"BTC/USDC","bids":[],"asks":[{"price":67740.70,"qty":0.04519066}],"checksum":1107749124,"timestamp":"2024-06-01T22:42:34.359336Z"}]}
{"channel":"book","type":"update","data":[{"symbol":"BTC/USDC","bids":[],"asks":[{"price":67740.70,"qty":0.00000000},{"price":67745.44,"qty":1.09796055}],"checksum":2143288655,"timestamp":"2024-06-01T22:42:34.365157Z"}]}
{"channel":"book","type":"update","data":[{"symbol":"BTC/USDC","bids":[],"asks":[{"price":67740.70,"qty":0.05309445}],"checksum":3020237212,"timestamp":"2024-06-01T22:42:34.508072Z"}]}
{"channel":"book","type":"update","data":[{"symbol":"BTC/USDC","bids":[],"asks":[{"price":67740.70,"qty":0.00000000},{"price":67745.44,"qty":1.09796055}],"checksum":2143288655,"timestamp":"2024-06-01T22:42:34.514449Z"}]}
{"channel":"book","type":"update","data":[{"symbol":"BTC/USDC","bids":[],"asks":[{"price":67740.70,"qty":0.04874251}],"checksum":802159853,"timestamp":"2024-06-01T22:42:34.658661Z"}]}
{"channel":"book","type":"update","data":[{"symbol":"BTC/USDC","bids":[],"asks":[{"price":67740.70,"qty":0.00000000},{"price":67745.44,"qty":1.09796055}],"checksum":2143288655,"timestamp":"2024-06-01T22:42:34.664798Z"}]}
{"channel":"book","type":"update","data":[{"symbol":"BTC/USDC","bids":[],"asks":[{"price":67740.70,"qty":0.05401354}],"checksum":6981077,"timestamp":"2024-06-01T22:42:34.807517Z"}]}
{"channel":"book","type":"update","data":[{"symbol":"BTC/USDC","bids":[],"asks":[{"price":67740.70,"qty":0.00000000},{"price":67745.44,"qty":1.09796055}],"checksum":2143288655,"timestamp":"2024-06-01T22:42:34.813125Z"}]}
{"channel":"book","type":"update","data":[{"symbol":"BTC/USDC","bids":[],"asks":[{"price":67740.70,"qty":0.04553966}],"checksum":322527572,"timestamp":"2024-06-01T22:42:34.958832Z"}]}
{"channel":"book","type":"update","data":[{"symbol":"BTC/USDC","bids":[],"asks":[{"price":67740.70,"qty":0.00000000},{"price":67745.44,"qty":1.09796055}],"checksum":2143288655,"timestamp":"2024-06-01T22:42:34.965425Z"}]}
{"channel":"book","type":"update","data":[{"symbol":"BTC/USDC","bids":[],"asks":[{"price":67740.70,"qty":0.05088989}],"checksum":2675032106,"timestamp":"2024-06-01T22:42:35.109808Z"}]}
{"channel":"book","type":"update","data":[{"symbol":"BTC/USDC","bids":[],"asks":[{"price":67740.70,"qty":0.00000000},{"price":67745.44,"qty":1.09796055}],"checksum":2143288655,"timestamp":"2024-06-01T22:42:35.116341Z"}]}
{"channel":"book","type":"update","data":[{"symbol":"BTC/USDC","bids":[],"asks":[{"price":67740.70,"qty":0.04547713}],"checksum":2781978192,"timestamp":"2024-06-01T22:42:35.261171Z"}]}
{"channel":"book","type":"update","data":[{"symbol":"BTC/USDC","bids":[],"asks":[{"price":67740.70,"qty":0.00000000},{"price":67745.44,"qty":1.09796055}],"checksum":2143288655,"timestamp":"2024-06-01T22:42:35.267194Z"}]}
{"channel":"book","type":"update","data":[{"symbol":"BTC/USDC","bids":[],"asks":[{"price":67740.70,"qty":0.04577555}],"checksum":1906419469,"timestamp":"2024-06-01T22:42:35.410499Z"}]}
{"channel":"book","type":"update","data":[{"symbol":"BTC/USDC","bids":[],"asks":[{"price":67740.70,"qty":0.00000000},{"price":67745.44,"qty":1.09796055}],"checksum":2143288655,"timestamp":"2024-06-01T22:42:35.416273Z"}]}
{"channel":"book","type":"update","data":[{"symbol":"BTC/USDC","bids":[],"asks":[{"price":67740.70,"qty":0.05240934}],"checksum":1774851085,"timestamp":"2024-06-01T22:42:35.560606Z"}]}
{"channel":"book","type":"update","data":[{"symbol":"BTC/USDC","bids":[],"asks":[{"price":67740.70,"qty":0.00000000},{"price":67745.44,"qty":1.09796055}],"checksum":2143288655,"timestamp":"2024-06-01T22:42:35.566883Z"}]}
{"channel":"book","type":"update","data":[{"symbol":"BTC/USDC","bids":[],"asks":[{"price":67740.70,"qty":0.05206609}],"checksum":4056631456,"timestamp":"2024-06-01T22:42:35.711474Z"}]}
{"channel":"book","type":"update","data":[{"symbol":"BTC/USDC","bids":[],"asks":[{"price":67740.70,"qty":0.00000000},{"price":67745.44,"qty":1.09796055}],"checksum":2143288655,"timestamp":"2024-06-01T22:42:35.717172Z"}]}
{"channel":"book","type":"update","data":[{"symbol":"BTC/USDC","bids":[],"asks":[{"price":67729.42,"qty":0.01921000}],"checksum":1050276377,"timestamp":"2024-06-01T22:42:35.835859Z"}]}
{"channel":"book","type":"update","data":[{"symbol":"BTC/USDC","bids":[],"asks":[{"price":67740.70,"qty":0.04715647}],"checksum":128044724,"timestamp":"2024-06-01T22:42:35.862164Z"}]}
{"channel":"book","type":"update","data":[{"symbol":"BTC/USDC","bids":[],"asks":[{"price":67740.70,"qty":0.00000000},{"price":67743.33,"qty":0.01440688}],"checksum":1050276377,"timestamp":"2024-06-01T22:42:35.869579Z"}]}
{"channel":"book","type":"update","data":[{"symbol":"BTC/USDC","bids":[],"asks":[{"price":67740.70,"qty":0.05050349}],"checksum":135562509,"timestamp":"2024-06-01T22:42:36.013574Z"}]}
{"channel":"book","type":"update","data":[{"symbol":"BTC/USDC","bids":[],"asks":[{"price":67740.70,"qty":0.00000000},{"price":67743.33,"qty":0.01440688}],"checksum":1050276377,"timestamp":"2024-06-01T22:42:36.021192Z"}]}
{"channel":"book","type":"update","data":[{"symbol":"BTC/USDC","bids":[],"asks":[{"price":67740.70,"qty":0.04829929}],"checksum":1661908208,"timestamp":"2024-06-01T22:42:36.162415Z"}]}
{"channel":"book","type":"update","data":[{"symbol":"BTC/USDC","bids":[],"asks":[{"price":67740.70,"qty":0.00000000},{"price":67743.33,"qty":0.01440688}],"checksum":1050276377,"timestamp":"2024-06-01T22:42:36.168362Z"}]}
{"channel":"book","type":"update","data":[{"symbol":"BTC/USDC","bids":[],"asks":[{"price":67740.62,"qty":0.00000000},{"price":67745.44,"qty":1.09796055}],"checksum":1237431109,"timestamp":"2024-06-01T22:42:36.264003Z"}]}
{"channel":"book","type":"update","data":[{"symbol":"BTC/USDC","bids":[],"asks":[{"price":67741.52,"qty":0.00000000},{"price":67755.85,"qty":0.01540151}],"checksum":2255567491,"timestamp":"2024-06-01T22:42:36.264085Z"}]}
{"channel":"book","type":"update","data":[{"symbol":"BTC/USDC","bids":[],"asks":[{"price":67740.62,"qty":0.11422708}],"checksum":4136185296,"timestamp":"2024-06-01T22:42:36.266377Z"}]}
{"channel":"book","type":"update","data":[{"symbol":"BTC/USDC","bids":[],"asks":[{"price":67740.80,"qty":0.66473271}],"checksum":937904774,"timestamp":"2024-06-01T22:42:36.266510Z"}]}
{"channel":"book","type":"update","data":[{"symbol":"BTC/USDC","bids":[],"asks":[{"price":67741.52,"qty":0.11697328}],"checksum":3988957311,"timestamp":"2024-06-01T22:42:36.267068Z"}]}
{"channel":"book","type":"update","data":[{"symbol":"BTC/USDC","bids":[],"asks":[{"price":67740.70,"qty":0.04734994}],"checksum":4118496994,"timestamp":"2024-06-01T22:42:36.311821Z"}]}
{"channel":"book","type":"update","data":[{"symbol":"BTC/USDC","bids":[],"asks":[{"price":67740.63,"qty":0.00000000},{"price":67741.54,"qty":0.07380995}],"checksum":3034005834,"timestamp":"2024-06-01T22:42:36.398325Z"}]}
{"channel":"book","type":"update","data":[{"symbol":"BTC/USDC","bids":[],"asks":[{"price":67740.61,"qty":0.00353153}],"checksum":290819310,"timestamp":"2024-06-01T22:42:36.401182Z"}]}
{"channel":"book","type":"update","data":[{"symbol":"BTC/USDC","bids":[{"price":67700.38,"qty":0.00000000},{"price":67694.46,"qty":0.01900000}],"asks":[],"checksum":380337458,"timestamp":"2024-06-01T22:42:37.344722Z"}]}
{"channel":"book","type":"update","data":[{"symbol":"BTC/USDC","bids":[{"price":67703.04,"qty":0.00000000},{"price":67690.58,"qty":2.22492405}],"asks":[],"checksum":1720929573,"timestamp":"2024-06-01T22:42:37.344794Z"}]}
{"channel":"book","type":"update","data":[{"symbol":"BTC/USDC","bids":[{"price":67690.58,"qty":2.20250675}],"asks":[],"checksum":74045490,"timestamp":"2024-06-01T22:42:37.344914Z"}]}
{"channel":"book","type":"update","data":[{"symbol":"BTC/USDC","bids":[{"price":67703.06,"qty":0.00029534}],"asks":[],"checksum":1796392635,"timestamp":"2024-06-01T22:42:37.345880Z"}]}
{"channel":"book","type":"update","data":[{"symbol":"BTC/USDC","bids":[{"price":67700.40,"qty":0.00490540}],"asks":[],"checksum":122984523,"timestamp":"2024-06-01T22:42:37.346025Z"}]}
{"channel":"book","type":"update","data":[{"symbol":"BTC/USDC","bids":[{"price":67700.39,"qty":0.00000000},{"price":67694.46,"qty":0.01900000}],"asks":[],"checksum":622345361,"timestamp":"2024-06-01T22:42:37.511869Z"}]}
{"channel":"book","type":"update","data":[{"symbol":"BTC/USDC","bids":[{"price":67700.39,"qty":0.05834678}],"asks":[],"checksum":2723738141,"timestamp":"2024-06-01T22:42:37.512686Z"}]}
{"channel":"book","type":"update","data":[{"symbol":"BTC/USDC","bids":[],"asks":[{"price":67740.62,"qty":0.00000000},{"price":67741.54,"qty":0.07380995}],"checksum":3207827342,"timestamp":"2024-06-01T22:42:38.971880Z"}]}
{"channel":"book","type":"update","data":[{"symbol":"BTC/USDC","bids":[],"asks":[{"price":67740.80,"qty":0.00000000},{"price":67743.33,"qty":0.01440688}],"checksum":1075971126,"timestamp":"2024-06-01T22:42:38.971891Z"}]}
{"channel":"book","type":"update","data":[{"symbol":"BTC/USDC","bids":[],"asks":[{"price":67741.52,"qty":0.00000000},{"price":67745.44,"qty":1.09796055}],"checksum":4111686619,"timestamp":"2024-06-01T22:42:38.971965Z"}]}
{"channel":"book","type":"update","data":[{"symbol":"BTC/USDC","bids":[],"asks":[{"price":67740.60,"qty":0.67941443}],"checksum":3619759445,"timestamp":"2024-06-01T22:42:38.978192Z"}]}
{"channel":"book","type":"update","data":[{"symbol":"BTC/USDC","bids":[],"asks":[{"price":67740.69,"qty":0.21504022}],"checksum":740676952,"timestamp":"2024-06-01T22:42:38.978206Z"}]}
{"channel":"book","type":"update","data":[{"symbol":"BTC/USDC","bids":[],"asks":[{"price":67729.42,"qty":0.00000000},{"price":67743.33,"qty":0.01440688}],"checksum":665180496,"timestamp":"2024-06-01T22:42:39.137475Z"}]}
{"channel":"book","type":"update","data":[{"symbol":"BTC/USDC","bids":[],"asks":[{"price":67740.61,"qty":0.00000000},{"price":67745.44,"qty":1.09796055}],"checksum":1016597763,"timestamp":"2024-06-01T22:42:39.190559Z"}]}
{"channel":"book","type":"update","data":[{"symbol":"BTC/USDC","bids":[],"asks":[{"price":67740.61,"qty":0.00377807}],"checksum":1205436059,"timestamp":"2024-06-01T22:42:39.192394Z"}]}
{"channel":"book","type":"update","data":[{"symbol":"BTC/USDC","bids":[],"asks":[{"price":67729.71,"qty":0.02466000}],"checksum":1010068623,"timestamp":"2024-06-01T22:42:39.232111Z"}]}
{"channel":"book","type":"update","data":[{"symbol":"BTC/USDC","bids":[],"asks":[{"price":67729.71,"qty":0.00000000},{"price":67743.33,"qty":0.01440688}],"checksum":1205436059,"timestamp":"2024-06-01T22:42:39.294621Z"}]}
{"channel":"book","type":"update","data":[{"symbol":"BTC/USDC","bids":[{"price":67700.40,"qty":0.00000000},{"price":67694.46,"qty":0.01900000}],"asks":[],"checksum":2603383626,"timestamp":"2024-06-01T22:42:40.397901Z"}]}
{"channel":"book","type":"update","data":[{"symbol":"BTC/USDC","bids":[{"price":67703.06,"qty":0.00000000},{"price":67690.60,"qty":0.00350000}],"asks":[],"checksum":54939914,"timestamp":"2024-06-01T22:42:40.397956Z"}]}
{"channel":"book","type":"update","data":[{"symbol":"BTC/USDC","bids":[{"price":67700.39,"qty":0.00000000},{"price":67690.51,"qty":0.07386559}],"asks":[],"checksum":2090063794,"timestamp":"2024-06-01T22:42:40.804842Z"}]}
{"channel":"book","type":"update","data":[{"symbol":"BTC/USDC","bids":[{"price":67703.05,"qty":0.00000000},{"price":67689.95,"qty":0.02309418}],"asks":[],"checksum":3509467542,"timestamp":"2024-06-01T22:42:40.804882Z"}]}
{"channel":"book","type":"update","data":[{"symbol":"BTC/USDC","bids":[{"price":67703.03,"qty":0.02953391}],"asks":[],"checksum":1313549064,"timestamp":"2024-06-01T22:42:40.805861Z"}]}
{"channel":"book","type":"update","data":[{"symbol":"BTC/USDC","bids":[{"price":67700.29,"qty":0.08715965}],"asks":[],"checksum":2477479477,"timestamp":"2024-06-01T22:42:40.805935Z"}]}
{"channel":"book","type":"update","data":[{"symbol":"BTC/USDC","bids":[],"asks":[{"price":67740.61,"qty":0.00000000},{"price":67745.44,"qty":1.09796055}],"checksum":3812560352,"timestamp":"2024-06-01T22:42:41.903193Z"}]}
{"channel":"book","type":"update","data":[{"symbol":"BTC/USDC","bids":[],"asks":[{"price":67740.59,"qty":0.00358458}],"checksum":1650223330,"timestamp":"2024-06-01T22:42:41.907710Z"}]}
{"channel":"book","type":"update","data":[{"symbol":"BTC/USDC","bids":[{"price":67703.04,"qty":0.00029534}],"asks":[],"checksum":3813310429,"timestamp":"2024-06-01T22:42:43.430633Z"}]}
{"channel":"book","type":"update","data":[{"symbol":"BTC/USDC","bids":[],"asks":[{"price":67740.60,"qty":0.00000000},{"price":67745.44,"qty":1.09796055}],"checksum":114655714,"timestamp":"2024-06-01T22:42:44.210993Z"}]}
{"channel":"book","type":"update","data":[{"symbol":"BTC/USDC","bids":[],"asks":[{"price":67740.69,"qty":0.00000000},{"price":67748.19,"qty":0.01540250}],"checksum":2435758285,"timestamp":"2024-06-01T22:42:44.211301Z"}]}
{"channel":"book","type":"update","data":[{"symbol":"BTC/USDC","bids":[],"asks":[{"price":67740.58,"qty":0.67941443}],"checksum":3371958521,"timestamp":"2024-06-01T22:42:44.216121Z"}]}
{"channel":"book","type":"update","data":[{"symbol":"BTC/USDC","bids":[],"asks":[{"price":67740.69,"qty":0.23654424}],"checksum":3366996686,"timestamp":"2024-06-01T22:42:44.216201Z"}]}
{"channel":"book","type":"update","data":[{"symbol":"BTC/USDC","bids":[{"price":67703.03,"qty":0.00000000},{"price":67690.52,"qty":0.00350000}],"asks":[],"checksum":1289663403,"timestamp":"2024-06-01T22:42:44.269909Z"}]}
{"channel":"book","type":"update","data":[{"symbol":"BTC/USDC","bids":[{"price":67703.05,"qty":0.02953391}],"asks":[],"checksum":3887333723,"timestamp":"2024-06-01T22:42:44.270872Z"}]}
{"channel":"book","type":"update","data":[{"symbol":"BTC/USDC","bids":[],"asks":[{"price":67740.59,"qty":0.00000000},{"price":67745.44,"qty":1.09796055}],"checksum":1379322497,"timestamp":"2024-06-01T22:42:44.640418Z"}]}
{"channel":"book","type":"update","data":[{"symbol":"BTC/USDC","bids":[],"asks":[{"price":67740.59,"qty":0.00377807}],"checksum":1119891472,"timestamp":"2024-06-01T22:42:44.642366Z"}]}
{"channel":"book","type":"update","data":[{"symbol":"BTC/USDC","bids":[{"price":67700.28,"qty":0.00000000},{"price":67690.52,"qty":0.00350000}],"asks":[],"checksum":3946762934,"timestamp":"2024-06-01T22:42:44.730511Z"}]}
