{"channel":"book","type":"snapshot","data":[{"symbol":"BTC/USD","bids":[{"price":67749.9,"qty":0.52276117},{"price":67734.9,"qty":0.00438706},{"price":67730.8,"qty":0.00010000},{"price":67728.8,"qty":0.07811865},{"price":67728.2,"qty":0.01379223},{"price":67723.6,"qty":0.03690039},{"price":67722.0,"qty":0.04490000},{"price":67720.2,"qty":0.02952033},{"price":67714.1,"qty":0.13840000},{"price":67713.9,"qty":0.00120000}],"asks":[{"price":67750.0,"qty":17.73525082},{"price":67750.1,"qty":0.11661400},{"price":67750.2,"qty":0.83023375},{"price":67750.3,"qty":0.00200000},{"price":67751.3,"qty":0.28000000},{"price":67753.5,"qty":1.20000000},{"price":67753.6,"qty":0.17709800},{"price":67755.4,"qty":0.02289967},{"price":67756.5,"qty":0.22836862},{"price":67757.0,"qty":0.05902587}],"checksum":3610247804}]}
{"channel":"book","type":"update","data":[{"symbol":"BTC/USD","bids":[{"price":67714.1,"qty":0.06920000}],"asks":[],"checksum":907695170,"timestamp":"2024-06-01T22:42:06.892580Z"}]}
{"channel":"book","type":"update","data":[{"symbol":"BTC/USD","bids":[{"price":67722.0,"qty":0.00000000},{"price":67713.1,"qty":0.11347823}],"asks":[],"checksum":2700440236,"timestamp":"2024-06-01T22:42:07.196346Z"}]}
{"channel":"book","type":"update","data":[{"symbol":"BTC/USD","bids":[{"price":67714.1,"qty":0.00000000},{"price":67711.8,"qty":0.05904791},{"price":67712.7,"qty":0.06920000}],"asks":[],"checksum":1490426375,"timestamp":"2024-06-01T22:42:07.304011Z"}]}
{"channel":"book","type":"update","data":[{"symbol":"BTC/USD","bids":[{"price":67712.7,"qty":0.13840000}],"asks":[],"checksum":2420723561,"timestamp":"2024-06-01T22:42:07.308526Z"}]}
{"channel":"book","type":"update","data":[{"symbol":"BTC/USD","bids":[{"price":67712.7,"qty":0.06920000}],"asks":[],"checksum":1490426375,"timestamp":"2024-06-01T22:42:07.443628Z"}]}
{"channel":"book","type":"update","data":[{"symbol":"BTC/USD","bids":[{"price":67712.7,"qty":0.00000000},{"price":67711.8,"qty":0.05904791}],"asks":[],"checksum":3753605022,"timestamp":"2024-06-01T22:42:07.448957Z"}]}
{"channel":"book","type":"update","data":[{"symbol":"BTC/USD","bids":[{"price":67713.8,"qty":0.06920000}],"asks":[],"checksum":3168544579,"timestamp":"2024-06-01T22:42:07.451756Z"}]}
{"channel":"book","type":"update","data":[{"symbol":"BTC/USD","bids":[],"asks":[{"price":67750.0,"qty":17.33633931}],"checksum":3461465448,"timestamp":"2024-06-01T22:42:08.843271Z"}]}
{"channel":"book","type":"update","data":[{"symbol":"BTC/USD","bids":[{"price":67713.8,"qty":0.00000000},{"price":67711.7,"qty":0.05904803},{"price":67715.8,"qty":0.06920000}],"asks":[],"checksum":3322370440,"timestamp":"2024-06-01T22:42:08.901767Z"}]}
{"channel":"book","type":"update","data":[{"symbol":"BTC/USD","bids":[{"price":67715.8,"qty":0.13840000}],"asks":[],"checksum":1914822228,"timestamp":"2024-06-01T22:42:08.904931Z"}]}
{"channel":"book","type":"update","data":[{"symbol":"BTC/USD","bids":[],"asks":[{"price":67750.0,"qty":17.73525082}],"checksum":3740248822,"timestamp":"2024-06-01T22:42:08.973542Z"}]}
{"channel":"book","type":"update","data":[{"symbol":"BTC/USD","bids":[{"price":67715.8,"qty":0.06920000}],"asks":[],"checksum":3028990883,"timestamp":"2024-06-01T22:42:09.152635Z"}]}
{"channel":"book","type":"update","data":[{"symbol":"BTC/USD","bids":[{"price":67715.8,"qty":0.00000000},{"price":67711.7,"qty":0.05904803},{"price":67715.0,"qty":0.06920000}],"asks":[],"checksum":1273574482,"timestamp":"2024-06-01T22:42:09.152646Z"}]}
{"channel":"book","type":"update","data":[{"symbol":"BTC/USD","bids":[{"price":67715.0,"qty":0.00000000},{"price":67711.7,"qty":0.05904803},{"price":67714.2,"qty":0.06920000}],"asks":[],"checksum":3446899190,"timestamp":"2024-06-01T22:42:09.157876Z"}]}
{"channel":"book","type":"update","data":[{"symbol":"BTC/USD","bids":[{"price":67714.2,"qty":0.13840000}],"asks":[],"checksum":3315070647,"timestamp":"2024-06-01T22:42:09.158456Z"}]}
{"channel":"book","type":"update","data":[{"symbol":"BTC/USD","bids":[{"price":67714.2,"qty":0.06920000}],"asks":[],"checksum":3446899190,"timestamp":"2024-06-01T22:42:09.160578Z"}]}
{"channel":"book","type":"update","data":[{"symbol":"BTC/USD","bids":[],"asks":[{"price":67753.5,"qty":2.11278265}],"checksum":2299489401,"timestamp":"2024-06-01T22:42:09.185525Z"}]}
{"channel":"book","type":"update","data":[{"symbol":"BTC/USD","bids":[],"asks":[{"price":67753.8,"qty":0.00518720}],"checksum":851005016,"timestamp":"2024-06-01T22:42:09.669875Z"}]}
{"channel":"book","type":"update","data":[{"symbol":"BTC/USD","bids":[],"asks":[{"price":67753.5,"qty":0.91278265},{"price":67751.2,"qty":1.20000000}],"checksum":3656434589,"timestamp":"2024-06-01T22:42:10.319080Z"}]}
{"channel":"book","type":"update","data":[{"symbol":"BTC/USD","bids":[],"asks":[{"price":67750.0,"qty":17.69835043}],"checksum":660103746,"timestamp":"2024-06-01T22:42:12.325965Z"}]}
{"channel":"book","type":"update","data":[{"symbol":"BTC/USD","bids":[{"price":67723.6,"qty":0.00000000},{"price":67711.7,"qty":0.05904803}],"asks":[],"checksum":2522504670,"timestamp":"2024-06-01T22:42:12.329178Z"}]}
{"channel":"book","type":"update","data":[{"symbol":"BTC/USD","bids":[],"asks":[{"price":67750.0,"qty":17.62265945}],"checksum":477948335,"timestamp":"2024-06-01T22:42:13.589643Z"}]}
{"channel":"book","type":"update","data":[{"symbol":"BTC/USD","bids":[{"price":67711.8,"qty":0.91856796}],"asks":[],"checksum":779619996,"timestamp":"2024-06-01T22:42:13.615388Z"}]}
{"channel":"book","type":"update","data":[{"symbol":"BTC/USD","bids":[{"price":67711.8,"qty":0.00000000},{"price":67711.7,"qty":0.05904803}],"asks":[],"checksum":477948335,"timestamp":"2024-06-01T22:42:13.969128Z"}]}
{"channel":"book","type":"update","data":[{"symbol":"BTC/USD","bids":[{"price":67714.2,"qty":0.00000000},{"price":67709.6,"qty":0.91857227},{"price":67715.1,"qty":0.06920000}],"asks":[],"checksum":2588285148,"timestamp":"2024-06-01T22:42:14.114397Z"}]}
{"channel":"book","type":"update","data":[{"symbol":"BTC/USD","bids":[{"price":67715.1,"qty":0.13840000}],"asks":[],"checksum":3683407587,"timestamp":"2024-06-01T22:42:14.117458Z"}]}
{"channel":"book","type":"update","data":[{"symbol":"BTC/USD","bids":[],"asks":[{"price":67750.0,"qty":17.65955984}],"checksum":4232968228,"timestamp":"2024-06-01T22:42:14.343463Z"}]}
{"channel":"book","type":"update","data":[{"symbol":"BTC/USD","bids":[{"price":67726.2,"qty":0.03690039}],"asks":[],"checksum":943247450,"timestamp":"2024-06-01T22:42:14.346602Z"}]}
{"channel":"book","type":"update","data":[{"symbol":"BTC/USD","bids":[],"asks":[{"price":67750.0,"qty":14.81855984}],"checksum":1434237598,"timestamp":"2024-06-01T22:42:14.477284Z"}]}
{"channel":"book","type":"update","data":[{"symbol":"BTC/USD","bids":[],"asks":[{"price":67750.0,"qty":16.31255984}],"checksum":1270619304,"timestamp":"2024-06-01T22:42:14.494180Z"}]}
{"channel":"book","type":"update","data":[{"symbol":"BTC/USD","bids":[],"asks":[{"price":67750.0,"qty":16.31225634}],"checksum":3835335590,"timestamp":"2024-06-01T22:42:14.517928Z"}]}
{"channel":"book","type":"update","data":[{"symbol":"BTC/USD","bids":[],"asks":[{"price":67750.0,"qty":16.31067115}],"checksum":990249656,"timestamp":"2024-06-01T22:42:14.621284Z"}]}
{"channel":"book","type":"update","data":[{"symbol":"BTC/USD","bids":[],"asks":[{"price":67753.5,"qty":0.00000000},{"price":67756.4,"qty":0.08331761}],"checksum":3450145210,"timestamp":"2024-06-01T22:42:14.643938Z"}]}
{"channel":"book","type":"update","data":[{"symbol":"BTC/USD","bids":[],"asks":[{"price":67750.0,"qty":16.24147115}],"checksum":2485704942,"timestamp":"2024-06-01T22:42:14.802611Z"}]}
{"channel":"book","type":"update","data":[{"symbol":"BTC/USD","bids":[],"asks":[{"price":67750.0,"qty":16.17227115}],"checksum":748636286,"timestamp":"2024-06-01T22:42:14.805609Z"}]}
{"channel":"book","type":"update","data":[{"symbol":"BTC/USD","bids":[],"asks":[{"price":67750.0,"qty":16.03387115}],"checksum":2152929304,"timestamp":"2024-06-01T22:42:14.805620Z"}]}
{"channel":"book","type":"update","data":[{"symbol":"BTC/USD","bids":[{"price":67715.1,"qty":0.06920000},{"price":67716.2,"qty":0.06920000}],"asks":[],"checksum":3737680707,"timestamp":"2024-06-01T22:42:14.882035Z"}]}
{"channel":"book","type":"update","data":[{"symbol":"BTC/USD","bids":[{"price":67715.1,"qty":0.00000000},{"price":67713.1,"qty":0.11347823}],"asks":[],"checksum":815044248,"timestamp":"2024-06-01T22:42:14.883877Z"}]}
{"channel":"book","type":"update","data":[{"symbol":"BTC/USD","bids":[{"price":67716.2,"qty":0.00000000},{"price":67711.7,"qty":0.05904803},{"price":67717.4,"qty":0.06920000}],"asks":[],"checksum":604465124,"timestamp":"2024-06-01T22:42:14.888988Z"}]}
{"channel":"book","type":"update","data":[{"symbol":"BTC/USD","bids":[{"price":67717.4,"qty":0.00000000},{"price":67711.7,"qty":0.05904803}],"asks":[],"checksum":2342635221,"timestamp":"2024-06-01T22:42:14.892172Z"}]}
{"channel":"book","type":"update","data":[{"symbol":"BTC/USD","bids":[{"price":67717.4,"qty":0.06920000}],"asks":[],"checksum":604465124,"timestamp":"2024-06-01T22:42:14.892197Z"}]}
{"channel":"book","type":"update","data":[{"symbol":"BTC/USD","bids":[],"asks":[{"price":67750.0,"qty":16.10307115},{"price":67750.0,"qty":16.17227115},{"price":67750.0,"qty":16.31067115}],"checksum":1618451844,"timestamp":"2024-06-01T22:42:14.930502Z"}]}
{"channel":"book","type":"update","data":[{"symbol":"BTC/USD","bids":[],"asks":[{"price":67750.0,"qty":15.75015746}],"checksum":352100256,"timestamp":"2024-06-01T22:42:14.938377Z"}]}
{"channel":"book","type":"update","data":[{"symbol":"BTC/USD","bids":[],"asks":[{"price":67753.5,"qty":0.89946366}],"checksum":3472218842,"timestamp":"2024-06-01T22:42:14.939171Z"}]}
{"channel":"book","type":"update","data":[{"symbol":"BTC/USD","bids":[],"asks":[{"price":67750.0,"qty":16.31064881}],"checksum":332164128,"timestamp":"2024-06-01T22:42:14.956269Z"}]}
{"channel":"book","type":"update","data":[{"symbol":"BTC/USD","bids":[{"price":67713.2,"qty":0.91854500}],"asks":[],"checksum":525442470,"timestamp":"2024-06-01T22:42:15.004709Z"}]}
{"channel":"book","type":"update","data":[{"symbol":"BTC/USD","bids":[],"asks":[{"price":67751.1,"qty":0.38760201}],"checksum":2707488045,"timestamp":"2024-06-01T22:42:15.121549Z"}]}
{"channel":"book","type":"update","data":[{"symbol":"BTC/USD","bids":[{"price":67717.4,"qty":0.00000000},{"price":67713.1,"qty":0.11347823}],"asks":[],"checksum":812413232,"timestamp":"2024-06-01T22:42:15.385568Z"}]}
{"channel":"book","type":"update","data":[{"symbol":"BTC/USD","bids":[{"price":67716.3,"qty":0.06920000}],"asks":[],"checksum":2440125799,"timestamp":"2024-06-01T22:42:15.521328Z"}]}
{"channel":"book","type":"update","data":[{"symbol":"BTC/USD","bids":[{"price":67713.2,"qty":0.00000000},{"price":67713.1,"qty":0.11347823}],"asks":[],"checksum":2649533665,"timestamp":"2024-06-01T22:42:15.708525Z"}]}
{"channel":"book","type":"update","data":[{"symbol":"BTC/USD","bids":[],"asks":[{"price":67750.0,"qty":15.43397029}],"checksum":3076481043,"timestamp":"2024-06-01T22:42:15.795571Z"}]}
{"channel":"book","type":"update","data":[{"symbol":"BTC/USD","bids":[],"asks":[{"price":67750.0,"qty":16.27552418}],"checksum":818651971,"timestamp":"2024-06-01T22:42:15.801409Z"}]}
{"channel":"book","type":"update","data":[{"symbol":"BTC/USD","bids":[{"price":67722.0,"qty":0.04490000}],"asks":[],"checksum":3174948406,"timestamp":"2024-06-01T22:42:15.813108Z"}]}
{"channel":"book","type":"update","data":[{"symbol":"BTC/USD","bids":[],"asks":[{"price":67750.0,"qty":16.12032418}],"checksum":3852636521,"timestamp":"2024-06-01T22:42:15.816230Z"}]}
{"channel":"book","type":"update","data":[{"symbol":"BTC/USD","bids":[{"price":67722.0,"qty":0.00000000},{"price":67713.1,"qty":0.11347823}],"asks":[],"checksum":3410456681,"timestamp":"2024-06-01T22:42:15.819104Z"}]}
{"channel":"book","type":"update","data":[{"symbol":"BTC/USD","bids":[{"price":67724.0,"qty":0.04490000}],"asks":[],"checksum":1237691510,"timestamp":"2024-06-01T22:42:15.820524Z"}]}
{"channel":"book","type":"update","data":[{"symbol":"BTC/USD","bids":[],"asks":[{"price":67750.0,"qty":16.27552418}],"checksum":291169065,"timestamp":"2024-06-01T22:42:15.880148Z"}]}
{"channel":"book","type":"update","data":[{"symbol":"BTC/USD","bids":[],"asks":[{"price":67751.1,"qty":0.00000000},{"price":67755.4,"qty":0.02289967}],"checksum":860000475,"timestamp":"2024-06-01T22:42:15.892089Z"}]}
{"channel":"book","type":"update","data":[{"symbol":"BTC/USD","bids":[],"asks":[{"price":67751.0,"qty":0.38760175}],"checksum":3019611287,"timestamp":"2024-06-01T22:42:15.932684Z"}]}
{"channel":"book","type":"update","data":[{"symbol":"BTC/USD","bids":[],"asks":[{"price":67751.2,"qty":0.00000000},{"price":67755.4,"qty":0.02289967},{"price":67755.2,"qty":1.20000000}],"checksum":3212295711,"timestamp":"2024-06-01T22:42:16.318806Z"}]}
{"channel":"book","type":"update","data":[{"symbol":"BTC/USD","bids":[{"price":67724.0,"qty":0.00000000},{"price":67713.1,"qty":0.11347823}],"asks":[],"checksum":4292811655,"timestamp":"2024-06-01T22:42:17.066470Z"}]}
{"channel":"book","type":"update","data":[{"symbol":"BTC/USD","bids":[],"asks":[{"price":67751.0,"qty":0.00000000},{"price":67755.4,"qty":0.02289967}],"checksum":1871026124,"timestamp":"2024-06-01T22:42:17.285759Z"}]}
{"channel":"book","type":"update","data":[{"symbol":"BTC/USD","bids":[],"asks":[{"price":67750.9,"qty":0.38760174}],"checksum":1511955127,"timestamp":"2024-06-01T22:42:17.326082Z"}]}
{"channel":"book","type":"update","data":[{"symbol":"BTC/USD","bids":[{"price":67716.3,"qty":0.00000000},{"price":67712.9,"qty":0.53000000}],"asks":[],"checksum":4199553554,"timestamp":"2024-06-01T22:42:17.596073Z"}]}
{"channel":"book","type":"update","data":[{"symbol":"BTC/USD","bids":[{"price":67716.4,"qty":0.06920000}],"asks":[],"checksum":2777754933,"timestamp":"2024-06-01T22:42:17.896518Z"}]}
{"channel":"book","type":"update","data":[{"symbol":"BTC/USD","bids":[],"asks":[{"price":67753.6,"qty":0.00000000},{"price":67755.4,"qty":0.02289967}],"checksum":3898653525,"timestamp":"2024-06-01T22:42:19.113948Z"}]}
{"channel":"book","type":"update","data":[{"symbol":"BTC/USD","bids":[],"asks":[{"price":67750.1,"qty":0.29373300}],"checksum":1814800756,"timestamp":"2024-06-01T22:42:19.116086Z"}]}
{"channel":"book","type":"update","data":[{"symbol":"BTC/USD","bids":[],"asks":[{"price":67750.0,"qty":16.85472097}],"checksum":2701639669,"timestamp":"2024-06-01T22:42:19.612308Z"}]}
{"channel":"book","type":"update","data":[{"symbol":"BTC/USD","bids":[],"asks":[{"price":67750.9,"qty":0.00000000},{"price":67756.4,"qty":0.08331761}],"checksum":901397805,"timestamp":"2024-06-01T22:42:20.871384Z"}]}
{"channel":"book","type":"update","data":[{"symbol":"BTC/USD","bids":[{"price":67716.4,"qty":0.00000000},{"price":67712.9,"qty":0.53000000},{"price":67717.4,"qty":0.06920000}],"asks":[],"checksum":4196674277,"timestamp":"2024-06-01T22:42:24.371829Z"}]}
{"channel":"book","type":"update","data":[{"symbol":"BTC/USD","bids":[{"price":67717.4,"qty":0.13840000}],"asks":[],"checksum":1092542658,"timestamp":"2024-06-01T22:42:24.374934Z"}]}
{"channel":"book","type":"update","data":[{"symbol":"BTC/USD","bids":[{"price":67718.0,"qty":0.04490000}],"asks":[],"checksum":4172279730,"timestamp":"2024-06-01T22:42:24.532797Z"}]}
{"channel":"book","type":"update","data":[{"symbol":"BTC/USD","bids":[],"asks":[{"price":67750.0,"qty":16.78552097}],"checksum":1270648365,"timestamp":"2024-06-01T22:42:24.866609Z"}]}
