{"channel":"book","type":"snapshot","data":[{"symbol":"DOT/ETH","bids":[{"price":0.001854,"qty":31.74335177},{"price":0.001853,"qty":703.10145093},{"price":0.001852,"qty":247.84811240},{"price":0.001850,"qty":500.55654777},{"price":0.001849,"qty":124.33837404},{"price":0.001848,"qty":21.14834782},{"price":0.001841,"qty":15.42228682},{"price":0.001840,"qty":84.63508152},{"price":0.001838,"qty":212.39237792},{"price":0.001837,"qty":1274.00558904}],"asks":[{"price":0.001856,"qty":505.87044565},{"price":0.001857,"qty":262.54049393},{"price":0.001858,"qty":211.28189471},{"price":0.001859,"qty":1.69265503},{"price":0.001864,"qty":66.00173030},{"price":0.001865,"qty":140.31027877},{"price":0.001866,"qty":3.67684173},{"price":0.001874,"qty":53.96266524},{"price":0.001900,"qty":7387.66448699},{"price":0.001901,"qty":4000.85533728}],"checksum":402421540}]}
{"channel":"book","type":"update","data":[{"symbol":"DOT/ETH","bids":[{"price":0.001837,"qty":1061.68522683}],"asks":[],"checksum":2671362966,"timestamp":"2024-06-01T22:42:29.826693Z"}]}
{"channel":"book","type":"update","data":[{"symbol":"DOT/ETH","bids":[{"price":0.001837,"qty":1344.93659801}],"asks":[],"checksum":1549965602,"timestamp":"2024-06-01T22:42:29.826754Z"}]}
{"channel":"book","type":"update","data":[{"symbol":"DOT/ETH","bids":[{"price":0.001840,"qty":155.44114283}],"asks":[],"checksum":1622944533,"timestamp":"2024-06-01T22:42:29.826839Z"}]}
{"channel":"book","type":"update","data":[{"symbol":"DOT/ETH","bids":[{"price":0.001837,"qty":920.24892478}],"asks":[],"checksum":1480678333,"timestamp":"2024-06-01T22:42:29.826960Z"}]}
{"channel":"book","type":"update","data":[{"symbol":"DOT/ETH","bids":[{"price":0.001837,"qty":566.35650466}],"asks":[],"checksum":3911664412,"timestamp":"2024-06-01T22:42:29.827278Z"}]}
{"channel":"book","type":"update","data":[{"symbol":"DOT/ETH","bids":[{"price":0.001838,"qty":70.79679300}],"asks":[],"checksum":1949481406,"timestamp":"2024-06-01T22:42:29.827383Z"}]}
{"channel":"book","type":"update","data":[{"symbol":"DOT/ETH","bids":[{"price":0.001838,"qty":0.00000000},{"price":0.001836,"qty":1557.80133232}],"asks":[],"checksum":2848484598,"timestamp":"2024-06-01T22:42:29.827393Z"}]}
{"channel":"book","type":"update","data":[{"symbol":"DOT/ETH","bids":[{"price":0.001837,"qty":778.78158021}],"asks":[],"checksum":484301713,"timestamp":"2024-06-01T22:42:29.827676Z"}]}
{"channel":"book","type":"update","data":[{"symbol":"DOT/ETH","bids":[{"price":0.001837,"qty":495.67644673}],"asks":[],"checksum":3297348532,"timestamp":"2024-06-01T22:42:29.827708Z"}]}
{"channel":"book","type":"update","data":[{"symbol":"DOT/ETH","bids":[{"price":0.001836,"qty":991.35501902}],"asks":[],"checksum":1881662554,"timestamp":"2024-06-01T22:42:29.827923Z"}]}
{"channel":"book","type":"update","data":[{"symbol":"DOT/ETH","bids":[{"price":0.001836,"qty":495.71449488}],"asks":[],"checksum":1306951543,"timestamp":"2024-06-01T22:42:29.828104Z"}]}
{"channel":"book","type":"update","data":[{"symbol":"DOT/ETH","bids":[{"price":0.001836,"qty":1133.06170259}],"asks":[],"checksum":2989129938,"timestamp":"2024-06-01T22:42:29.828139Z"}]}
{"channel":"book","type":"update","data":[{"symbol":"DOT/ETH","bids":[{"price":0.001836,"qty":1557.95984106}],"asks":[],"checksum":1917388491,"timestamp":"2024-06-01T22:42:29.828286Z"}]}
{"channel":"book","type":"update","data":[{"symbol":"DOT/ETH","bids":[{"price":0.001836,"qty":2124.49069235}],"asks":[],"checksum":3905778932,"timestamp":"2024-06-01T22:42:29.828349Z"}]}
{"channel":"book","type":"update","data":[{"symbol":"DOT/ETH","bids":[{"price":0.001840,"qty":297.05526465}],"asks":[],"checksum":73518253,"timestamp":"2024-06-01T22:42:29.828437Z"}]}
{"channel":"book","type":"update","data":[{"symbol":"DOT/ETH","bids":[{"price":0.001837,"qty":849.74323168}],"asks":[],"checksum":1398969572,"timestamp":"2024-06-01T22:42:29.828483Z"}]}
{"channel":"book","type":"update","data":[{"symbol":"DOT/ETH","bids":[{"price":0.001840,"qty":212.42018313},{"price":0.001842,"qty":84.54318675}],"asks":[],"checksum":2468897072,"timestamp":"2024-06-01T22:42:31.222121Z"}]}
{"channel":"book","type":"update","data":[{"symbol":"DOT/ETH","bids":[{"price":0.001853,"qty":491.25913348}],"asks":[],"checksum":2881687444,"timestamp":"2024-06-01T22:42:33.299857Z"}]}
{"channel":"book","type":"update","data":[{"symbol":"DOT/ETH","bids":[{"price":0.001841,"qty":0.00000000},{"price":0.001836,"qty":6891.48203848},{"price":0.001843,"qty":15.40555075}],"asks":[],"checksum":2402631890,"timestamp":"2024-06-01T22:42:33.302028Z"}]}
{"channel":"book","type":"update","data":[{"symbol":"DOT/ETH","bids":[{"price":0.001852,"qty":459.80658580}],"asks":[],"checksum":1858876805,"timestamp":"2024-06-01T22:42:33.303852Z"}]}
{"channel":"book","type":"update","data":[{"symbol":"DOT/ETH","bids":[{"price":0.001852,"qty":247.82898103}],"asks":[],"checksum":4030693364,"timestamp":"2024-06-01T22:42:36.215275Z"}]}
{"channel":"book","type":"update","data":[{"symbol":"DOT/ETH","bids":[{"price":0.001853,"qty":703.10304131}],"asks":[],"checksum":1808636777,"timestamp":"2024-06-01T22:42:36.219267Z"}]}
{"channel":"book","type":"update","data":[{"symbol":"DOT/ETH","bids":[{"price":0.001842,"qty":0.00000000},{"price":0.001836,"qty":6891.48203848},{"price":0.001844,"qty":84.45149132}],"asks":[],"checksum":776453966,"timestamp":"2024-06-01T22:42:39.658987Z"}]}
{"channel":"book","type":"update","data":[{"symbol":"DOT/ETH","bids":[{"price":0.001837,"qty":920.56697110}],"asks":[],"checksum":1915460038,"timestamp":"2024-06-01T22:42:40.353816Z"}]}
{"channel":"book","type":"update","data":[{"symbol":"DOT/ETH","bids":[{"price":0.001840,"qty":70.80606131}],"asks":[],"checksum":3820982933,"timestamp":"2024-06-01T22:42:40.354798Z"}]}
{"channel":"book","type":"update","data":[{"symbol":"DOT/ETH","bids":[{"price":0.001840,"qty":0.00000000},{"price":0.001836,"qty":5829.34671903}],"asks":[],"checksum":2414649626,"timestamp":"2024-06-01T22:42:40.354905Z"}]}
{"channel":"book","type":"update","data":[{"symbol":"DOT/ETH","bids":[{"price":0.001836,"qty":5333.63222415}],"asks":[],"checksum":3791819451,"timestamp":"2024-06-01T22:42:40.354917Z"}]}
{"channel":"book","type":"update","data":[{"symbol":"DOT/ETH","bids":[{"price":0.001837,"qty":1345.54762960}],"asks":[],"checksum":1769116630,"timestamp":"2024-06-01T22:42:40.354926Z"}]}
{"channel":"book","type":"update","data":[{"symbol":"DOT/ETH","bids":[{"price":0.001836,"qty":6041.93332167}],"asks":[],"checksum":3283929441,"timestamp":"2024-06-01T22:42:40.354961Z"}]}
{"channel":"book","type":"update","data":[{"symbol":"DOT/ETH","bids":[{"price":0.001836,"qty":6537.74408994}],"asks":[],"checksum":3600457133,"timestamp":"2024-06-01T22:42:40.354998Z"}]}
{"channel":"book","type":"update","data":[{"symbol":"DOT/ETH","bids":[{"price":0.001837,"qty":1487.19784980}],"asks":[],"checksum":1472549830,"timestamp":"2024-06-01T22:42:40.355039Z"}]}
{"channel":"book","type":"update","data":[{"symbol":"DOT/ETH","bids":[{"price":0.001836,"qty":7175.21507771}],"asks":[],"checksum":909439724,"timestamp":"2024-06-01T22:42:40.355083Z"}]}
{"channel":"book","type":"update","data":[{"symbol":"DOT/ETH","bids":[{"price":0.001836,"qty":2408.22373158}],"asks":[],"checksum":1506263491,"timestamp":"2024-06-01T22:42:40.359299Z"}]}
{"channel":"book","type":"update","data":[{"symbol":"DOT/ETH","bids":[],"asks":[{"price":0.001856,"qty":474.11722156}],"checksum":855949815,"timestamp":"2024-06-01T22:42:50.186691Z"}]}
{"channel":"book","type":"update","data":[{"symbol":"DOT/ETH","bids":[{"price":0.001843,"qty":0.00000000},{"price":0.001825,"qty":4761.86062132},{"price":0.001838,"qty":15.44745922}],"asks":[],"checksum":3953941834,"timestamp":"2024-06-01T22:42:50.189152Z"}]}
{"channel":"book","type":"update","data":[{"symbol":"DOT/ETH","bids":[],"asks":[{"price":0.001856,"qty":505.87090315}],"checksum":1550787906,"timestamp":"2024-06-01T22:42:50.406181Z"}]}
{"channel":"book","type":"update","data":[{"symbol":"DOT/ETH","bids":[{"price":0.001837,"qty":1203.94647862}],"asks":[],"checksum":2453671372,"timestamp":"2024-06-01T22:42:50.897498Z"}]}
{"channel":"book","type":"update","data":[{"symbol":"DOT/ETH","bids":[{"price":0.001837,"qty":1062.29625842}],"asks":[],"checksum":4256166863,"timestamp":"2024-06-01T22:42:50.897528Z"}]}
{"channel":"book","type":"update","data":[{"symbol":"DOT/ETH","bids":[{"price":0.001836,"qty":1770.75274381}],"asks":[],"checksum":1592604462,"timestamp":"2024-06-01T22:42:50.897715Z"}]}
{"channel":"book","type":"update","data":[{"symbol":"DOT/ETH","bids":[{"price":0.001836,"qty":2266.53055188}],"asks":[],"checksum":283480235,"timestamp":"2024-06-01T22:42:50.897933Z"}]}
{"channel":"book","type":"update","data":[{"symbol":"DOT/ETH","bids":[{"price":0.001837,"qty":1133.11443531}],"asks":[],"checksum":2535281135,"timestamp":"2024-06-01T22:42:50.898070Z"}]}
{"channel":"book","type":"update","data":[{"symbol":"DOT/ETH","bids":[{"price":0.001836,"qty":2974.78456341}],"asks":[],"checksum":1793263786,"timestamp":"2024-06-01T22:42:50.898577Z"}]}
{"channel":"book","type":"update","data":[{"symbol":"DOT/ETH","bids":[{"price":0.001837,"qty":1416.41603992}],"asks":[],"checksum":1527664923,"timestamp":"2024-06-01T22:42:50.898788Z"}]}
{"channel":"book","type":"update","data":[{"symbol":"DOT/ETH","bids":[{"price":0.001836,"qty":2266.48346589}],"asks":[],"checksum":2970759296,"timestamp":"2024-06-01T22:42:50.899084Z"}]}
{"channel":"book","type":"update","data":[{"symbol":"DOT/ETH","bids":[{"price":0.001837,"qty":1345.59230050}],"asks":[],"checksum":2226126372,"timestamp":"2024-06-01T22:42:50.899103Z"}]}
{"channel":"book","type":"update","data":[{"symbol":"DOT/ETH","bids":[{"price":0.001837,"qty":1133.16722495}],"asks":[],"checksum":3926589511,"timestamp":"2024-06-01T22:42:50.899132Z"}]}
{"channel":"book","type":"update","data":[{"symbol":"DOT/ETH","bids":[{"price":0.001837,"qty":1274.80965750}],"asks":[],"checksum":1891082646,"timestamp":"2024-06-01T22:42:50.899259Z"}]}
{"channel":"book","type":"update","data":[{"symbol":"DOT/ETH","bids":[{"price":0.001836,"qty":1770.67269762}],"asks":[],"checksum":3185642239,"timestamp":"2024-06-01T22:42:50.899414Z"}]}
{"channel":"book","type":"update","data":[{"symbol":"DOT/ETH","bids":[{"price":0.001836,"qty":1204.03181960}],"asks":[],"checksum":1495689562,"timestamp":"2024-06-01T22:42:50.899424Z"}]}
{"channel":"book","type":"update","data":[{"symbol":"DOT/ETH","bids":[{"price":0.001837,"qty":1487.27386259}],"asks":[],"checksum":2495486934,"timestamp":"2024-06-01T22:42:50.899446Z"}]}
{"channel":"book","type":"update","data":[{"symbol":"DOT/ETH","bids":[{"price":0.001837,"qty":1062.29320409}],"asks":[],"checksum":276730909,"timestamp":"2024-06-01T22:42:50.899471Z"}]}
{"channel":"book","type":"update","data":[{"symbol":"DOT/ETH","bids":[{"price":0.001837,"qty":708.22641914}],"asks":[],"checksum":149414857,"timestamp":"2024-06-01T22:42:50.899493Z"}]}
{"channel":"book","type":"update","data":[{"symbol":"DOT/ETH","bids":[{"price":0.001836,"qty":1841.46042998}],"asks":[],"checksum":3927734930,"timestamp":"2024-06-01T22:42:50.899506Z"}]}
{"channel":"book","type":"update","data":[{"symbol":"DOT/ETH","bids":[{"price":0.001836,"qty":2408.06363920}],"asks":[],"checksum":526202156,"timestamp":"2024-06-01T22:42:50.899529Z"}]}
{"channel":"book","type":"update","data":[{"symbol":"DOT/ETH","bids":[{"price":0.001837,"qty":1133.17882606}],"asks":[],"checksum":2379391337,"timestamp":"2024-06-01T22:42:50.899586Z"}]}
{"channel":"book","type":"update","data":[{"symbol":"DOT/ETH","bids":[{"price":0.001837,"qty":1487.30583183}],"asks":[],"checksum":1328688190,"timestamp":"2024-06-01T22:42:50.899613Z"}]}
{"channel":"book","type":"update","data":[{"symbol":"DOT/ETH","bids":[{"price":0.001844,"qty":0.00000000},{"price":0.001825,"qty":4761.86062132},{"price":0.001839,"qty":84.68110386}],"asks":[],"checksum":589722213,"timestamp":"2024-06-01T22:42:52.015509Z"}]}
{"channel":"book","type":"update","data":[{"symbol":"DOT/ETH","bids":[{"price":0.001853,"qty":491.25913348}],"asks":[],"checksum":1085160353,"timestamp":"2024-06-01T22:42:56.514141Z"}]}
{"channel":"book","type":"update","data":[{"symbol":"DOT/ETH","bids":[{"price":0.001838,"qty":0.00000000},{"price":0.001825,"qty":4761.86062132},{"price":0.001840,"qty":15.43066850}],"asks":[],"checksum":2254024103,"timestamp":"2024-06-01T22:42:56.516316Z"}]}
{"channel":"book","type":"update","data":[{"symbol":"DOT/ETH","bids":[{"price":0.001852,"qty":459.78771198}],"asks":[],"checksum":3708368958,"timestamp":"2024-06-01T22:42:56.517823Z"}]}
{"channel":"book","type":"update","data":[{"symbol":"DOT/ETH","bids":[{"price":0.001852,"qty":247.82898103}],"asks":[],"checksum":2254024103,"timestamp":"2024-06-01T22:42:57.291507Z"}]}
{"channel":"book","type":"update","data":[{"symbol":"DOT/ETH","bids":[{"price":0.001853,"qty":703.10156735}],"asks":[],"checksum":342623174,"timestamp":"2024-06-01T22:42:57.295970Z"}]}
