{"channel":"book","type":"snapshot","data":[{"symbol":"DOT/USDT","bids":[{"price":7.0900,"qty":352.90512162},{"price":7.0884,"qty":57.69502000},{"price":7.0881,"qty":1027.64303039},{"price":7.0870,"qty":347.13255255},{"price":7.0858,"qty":84.75558000},{"price":7.0857,"qty":27.60836201},{"price":7.0856,"qty":1270.88260078},{"price":7.0855,"qty":92.57000000},{"price":7.0852,"qty":28.60000000},{"price":7.0842,"qty":139.72000000}],"asks":[{"price":7.0917,"qty":385.82175568},{"price":7.0931,"qty":9.00000000},{"price":7.0933,"qty":705.48434575},{"price":7.0937,"qty":1.19523883},{"price":7.0940,"qty":18.11964415},{"price":7.0943,"qty":92.57000000},{"price":7.0950,"qty":352.86977376},{"price":7.0953,"qty":416.60595178},{"price":7.0966,"qty":57.69502000},{"price":7.0968,"qty":705.14276568}],"checksum":4182121500}]}
{"channel":"book","type":"update","data":[{"symbol":"DOT/USDT","bids":[{"price":7.0857,"qty":0.00000000},{"price":7.0840,"qty":706.40702915}],"asks":[],"checksum":2430792223,"timestamp":"2024-06-01T22:42:30.097008Z"}]}
{"channel":"book","type":"update","data":[{"symbol":"DOT/USDT","bids":[{"price":7.0857,"qty":24.85441756}],"asks":[],"checksum":2849090389,"timestamp":"2024-06-01T22:42:30.099288Z"}]}
{"channel":"book","type":"update","data":[{"symbol":"DOT/USDT","bids":[{"price":7.0855,"qty":0.00000000},{"price":7.0840,"qty":706.40702915}],"asks":[],"checksum":3902168054,"timestamp":"2024-06-01T22:42:33.035091Z"}]}
{"channel":"book","type":"update","data":[{"symbol":"DOT/USDT","bids":[{"price":7.0860,"qty":92.57000000}],"asks":[],"checksum":3984882712,"timestamp":"2024-06-01T22:42:33.037705Z"}]}
{"channel":"book","type":"update","data":[{"symbol":"DOT/USDT","bids":[{"price":7.0857,"qty":0.00000000},{"price":7.0840,"qty":706.40702915}],"asks":[],"checksum":1657823750,"timestamp":"2024-06-01T22:42:33.232743Z"}]}
{"channel":"book","type":"update","data":[{"symbol":"DOT/USDT","bids":[{"price":7.0857,"qty":27.60836201}],"asks":[],"checksum":375196018,"timestamp":"2024-06-01T22:42:33.235180Z"}]}
{"channel":"book","type":"update","data":[{"symbol":"DOT/USDT","bids":[{"price":7.0852,"qty":0.00000000},{"price":7.0840,"qty":706.40702915}],"asks":[],"checksum":1289561282,"timestamp":"2024-06-01T22:42:35.802387Z"}]}
{"channel":"book","type":"update","data":[{"symbol":"DOT/USDT","bids":[],"asks":[{"price":7.0942,"qty":23.20000000}],"checksum":1583652247,"timestamp":"2024-06-01T22:42:35.813581Z"}]}
{"channel":"book","type":"update","data":[{"symbol":"DOT/USDT","bids":[{"price":7.0857,"qty":0.00000000},{"price":7.0829,"qty":313.47000000}],"asks":[],"checksum":155593891,"timestamp":"2024-06-01T22:42:36.497797Z"}]}
{"channel":"book","type":"update","data":[{"symbol":"DOT/USDT","bids":[{"price":7.0857,"qty":24.85441756}],"asks":[],"checksum":4093168804,"timestamp":"2024-06-01T22:42:36.502969Z"}]}
{"channel":"book","type":"update","data":[{"symbol":"DOT/USDT","bids":[{"price":7.0857,"qty":0.00000000},{"price":7.0829,"qty":313.47000000}],"asks":[],"checksum":155593891,"timestamp":"2024-06-01T22:42:39.542564Z"}]}
{"channel":"book","type":"update","data":[{"symbol":"DOT/USDT","bids":[{"price":7.0857,"qty":33.11625091}],"asks":[],"checksum":3938994432,"timestamp":"2024-06-01T22:42:39.546262Z"}]}
{"channel":"book","type":"update","data":[{"symbol":"DOT/USDT","bids":[],"asks":[{"price":7.0940,"qty":0.00000000},{"price":7.0968,"qty":705.14276568}],"checksum":1996375954,"timestamp":"2024-06-01T22:42:39.904633Z"}]}
{"channel":"book","type":"update","data":[{"symbol":"DOT/USDT","bids":[],"asks":[{"price":7.0940,"qty":11.12964415}],"checksum":819969783,"timestamp":"2024-06-01T22:42:39.910255Z"}]}
{"channel":"book","type":"update","data":[{"symbol":"DOT/USDT","bids":[{"price":7.0857,"qty":0.00000000},{"price":7.0829,"qty":313.47000000}],"asks":[],"checksum":709188843,"timestamp":"2024-06-01T22:42:42.581471Z"}]}
{"channel":"book","type":"update","data":[{"symbol":"DOT/USDT","bids":[{"price":7.0857,"qty":27.60836201}],"asks":[],"checksum":2222156384,"timestamp":"2024-06-01T22:42:42.586757Z"}]}
{"channel":"book","type":"update","data":[{"symbol":"DOT/USDT","bids":[],"asks":[{"price":7.0942,"qty":0.00000000},{"price":7.0968,"qty":705.14276568}],"checksum":1876841610,"timestamp":"2024-06-01T22:42:47.569963Z"}]}
{"channel":"book","type":"update","data":[{"symbol":"DOT/USDT","bids":[],"asks":[{"price":7.0943,"qty":120.37000000}],"checksum":1667628528,"timestamp":"2024-06-01T22:42:47.793564Z"}]}
{"channel":"book","type":"update","data":[{"symbol":"DOT/USDT","bids":[],"asks":[{"price":7.0943,"qty":92.57000000}],"checksum":1876841610,"timestamp":"2024-06-01T22:42:49.372870Z"}]}
{"channel":"book","type":"update","data":[{"symbol":"DOT/USDT","bids":[],"asks":[{"price":7.0944,"qty":22.60000000}],"checksum":1421919934,"timestamp":"2024-06-01T22:42:49.526342Z"}]}
{"channel":"book","type":"update","data":[{"symbol":"DOT/USDT","bids":[],"asks":[{"price":7.0944,"qty":0.00000000},{"price":7.0968,"qty":705.14276568}],"checksum":1876841610,"timestamp":"2024-06-01T22:42:49.645459Z"}]}
{"channel":"book","type":"update","data":[{"symbol":"DOT/USDT","bids":[],"asks":[{"price":7.0945,"qty":28.10000000}],"checksum":2822634245,"timestamp":"2024-06-01T22:42:49.765753Z"}]}
{"channel":"book","type":"update","data":[{"symbol":"DOT/USDT","bids":[],"asks":[{"price":7.0945,"qty":0.00000000},{"price":7.0968,"qty":705.14276568}],"checksum":1876841610,"timestamp":"2024-06-01T22:42:51.140716Z"}]}
{"channel":"book","type":"update","data":[{"symbol":"DOT/USDT","bids":[],"asks":[{"price":7.0946,"qty":29.30000000}],"checksum":979503824,"timestamp":"2024-06-01T22:42:51.264535Z"}]}
{"channel":"book","type":"update","data":[{"symbol":"DOT/USDT","bids":[{"price":7.0860,"qty":0.00000000},{"price":7.0829,"qty":313.47000000}],"asks":[],"checksum":672385238,"timestamp":"2024-06-01T22:42:51.951921Z"}]}
{"channel":"book","type":"update","data":[{"symbol":"DOT/USDT","bids":[{"price":7.0859,"qty":92.48000000}],"asks":[],"checksum":3885370506,"timestamp":"2024-06-01T22:42:51.954280Z"}]}
{"channel":"book","type":"update","data":[{"symbol":"DOT/USDT","bids":[{"price":7.0870,"qty":0.00000000},{"price":7.0829,"qty":313.47000000}],"asks":[],"checksum":2061307562,"timestamp":"2024-06-01T22:42:54.991823Z"}]}
{"channel":"book","type":"update","data":[{"symbol":"DOT/USDT","bids":[{"price":7.0870,"qty":329.72505255}],"asks":[],"checksum":871409871,"timestamp":"2024-06-01T22:42:54.997415Z"}]}
{"channel":"book","type":"update","data":[{"symbol":"DOT/USDT","bids":[{"price":7.0857,"qty":0.00000000},{"price":7.0829,"qty":313.47000000}],"asks":[],"checksum":1822122320,"timestamp":"2024-06-01T22:42:55.324004Z"}]}
{"channel":"book","type":"update","data":[{"symbol":"DOT/USDT","bids":[{"price":7.0857,"qty":16.47525751}],"asks":[],"checksum":22664547,"timestamp":"2024-06-01T22:42:55.330338Z"}]}
{"channel":"book","type":"update","data":[{"symbol":"DOT/USDT","bids":[{"price":7.0860,"qty":11.08469532}],"asks":[],"checksum":468982105,"timestamp":"2024-06-01T22:42:55.330399Z"}]}
{"channel":"book","type":"update","data":[{"symbol":"DOT/USDT","bids":[],"asks":[{"price":7.0946,"qty":0.00000000},{"price":7.0968,"qty":705.14276568}],"checksum":2727111918,"timestamp":"2024-06-01T22:42:56.379375Z"}]}
{"channel":"book","type":"update","data":[{"symbol":"DOT/USDT","bids":[{"price":7.0853,"qty":25.90000000}],"asks":[],"checksum":2921210518,"timestamp":"2024-06-01T22:42:56.404288Z"}]}
{"channel":"book","type":"update","data":[{"symbol":"DOT/USDT","bids":[{"price":7.0857,"qty":0.00000000},{"price":7.0842,"qty":139.72000000}],"asks":[],"checksum":2425285132,"timestamp":"2024-06-01T22:42:58.247983Z"}]}
{"channel":"book","type":"update","data":[{"symbol":"DOT/USDT","bids":[{"price":7.0860,"qty":0.00000000},{"price":7.0840,"qty":706.40702915}],"asks":[],"checksum":1557100201,"timestamp":"2024-06-01T22:42:58.247999Z"}]}
{"channel":"book","type":"update","data":[{"symbol":"DOT/USDT","bids":[{"price":7.0857,"qty":13.71593426}],"asks":[],"checksum":790502398,"timestamp":"2024-06-01T22:42:58.250121Z"}]}
{"channel":"book","type":"update","data":[{"symbol":"DOT/USDT","bids":[{"price":7.0860,"qty":13.83863977}],"asks":[],"checksum":2915064551,"timestamp":"2024-06-01T22:42:58.250132Z"}]}
{"channel":"book","type":"update","data":[{"symbol":"DOT/USDT","bids":[{"price":7.0860,"qty":0.00000000},{"price":7.0842,"qty":139.72000000}],"asks":[],"checksum":790502398,"timestamp":"2024-06-01T22:43:10.899412Z"}]}
{"channel":"book","type":"update","data":[{"symbol":"DOT/USDT","bids":[{"price":7.0857,"qty":0.00000000},{"price":7.0840,"qty":706.40702915}],"asks":[],"checksum":1557100201,"timestamp":"2024-06-01T22:43:10.899448Z"}]}
{"channel":"book","type":"update","data":[{"symbol":"DOT/USDT","bids":[{"price":7.0857,"qty":31.91140021}],"asks":[],"checksum":206507566,"timestamp":"2024-06-01T22:43:10.904167Z"}]}
{"channel":"book","type":"update","data":[{"symbol":"DOT/USDT","bids":[{"price":7.0882,"qty":28.22757879}],"asks":[],"checksum":2667815965,"timestamp":"2024-06-01T22:43:11.288887Z"}]}
{"channel":"book","type":"update","data":[{"symbol":"DOT/USDT","bids":[],"asks":[{"price":7.0917,"qty":33.00000000}],"checksum":1680518974,"timestamp":"2024-06-01T22:43:11.289303Z"}]}
{"channel":"book","type":"update","data":[{"symbol":"DOT/USDT","bids":[],"asks":[{"price":7.0940,"qty":0.00000000},{"price":7.0971,"qty":22.00000000}],"checksum":1624076311,"timestamp":"2024-06-01T22:43:11.291400Z"}]}
{"channel":"book","type":"update","data":[{"symbol":"DOT/USDT","bids":[],"asks":[{"price":7.0953,"qty":94.95912000}],"checksum":2013053466,"timestamp":"2024-06-01T22:43:11.291467Z"}]}
{"channel":"book","type":"update","data":[{"symbol":"DOT/USDT","bids":[],"asks":[{"price":7.0917,"qty":0.00000000},{"price":7.0988,"qty":4.01307589}],"checksum":1589819902,"timestamp":"2024-06-01T22:43:11.292325Z"}]}
{"channel":"book","type":"update","data":[{"symbol":"DOT/USDT","bids":[{"price":7.0900,"qty":0.00000000},{"price":7.0842,"qty":139.72000000}],"asks":[],"checksum":197628296,"timestamp":"2024-06-01T22:43:11.292644Z"}]}
{"channel":"book","type":"update","data":[{"symbol":"DOT/USDT","bids":[{"price":7.0856,"qty":564.63728921}],"asks":[],"checksum":2295923858,"timestamp":"2024-06-01T22:43:11.292779Z"}]}
{"channel":"book","type":"update","data":[{"symbol":"DOT/USDT","bids":[],"asks":[{"price":7.0933,"qty":0.00000000},{"price":7.0993,"qty":84.75558000}],"checksum":2818314764,"timestamp":"2024-06-01T22:43:11.292795Z"}]}
{"channel":"book","type":"update","data":[{"symbol":"DOT/USDT","bids":[],"asks":[{"price":7.0929,"qty":33.00000000}],"checksum":742622024,"timestamp":"2024-06-01T22:43:11.292946Z"}]}
{"channel":"book","type":"update","data":[{"symbol":"DOT/USDT","bids":[{"price":7.0882,"qty":0.00000000},{"price":7.0840,"qty":706.40702915}],"asks":[],"checksum":3886774436,"timestamp":"2024-06-01T22:43:11.293390Z"}]}
{"channel":"book","type":"update","data":[{"symbol":"DOT/USDT","bids":[{"price":7.0885,"qty":31.75372056}],"asks":[],"checksum":737794980,"timestamp":"2024-06-01T22:43:11.296864Z"}]}
{"channel":"book","type":"update","data":[{"symbol":"DOT/USDT","bids":[{"price":7.0884,"qty":85.91834570}],"asks":[],"checksum":807505650,"timestamp":"2024-06-01T22:43:11.297148Z"}]}
{"channel":"book","type":"update","data":[{"symbol":"DOT/USDT","bids":[],"asks":[{"price":7.0950,"qty":381.84191791}],"checksum":2506477913,"timestamp":"2024-06-01T22:43:11.297610Z"}]}
{"channel":"book","type":"update","data":[{"symbol":"DOT/USDT","bids":[],"asks":[{"price":7.0928,"qty":352.76701755}],"checksum":2349737635,"timestamp":"2024-06-01T22:43:11.302541Z"}]}
{"channel":"book","type":"update","data":[{"symbol":"DOT/USDT","bids":[{"price":7.0908,"qty":352.86414430}],"asks":[],"checksum":700152999,"timestamp":"2024-06-01T22:43:11.302609Z"}]}
{"channel":"book","type":"update","data":[{"symbol":"DOT/USDT","bids":[],"asks":[{"price":7.0944,"qty":705.37994088}],"checksum":1226393178,"timestamp":"2024-06-01T22:43:11.302631Z"}]}
{"channel":"book","type":"update","data":[{"symbol":"DOT/USDT","bids":[{"price":7.0892,"qty":705.88660004}],"asks":[],"checksum":1734354301,"timestamp":"2024-06-01T22:43:11.302643Z"}]}
{"channel":"book","type":"update","data":[{"symbol":"DOT/USDT","bids":[],"asks":[{"price":7.0929,"qty":0.00000000},{"price":7.0971,"qty":22.00000000}],"checksum":2730724382,"timestamp":"2024-06-01T22:43:11.305677Z"}]}
{"channel":"book","type":"update","data":[{"symbol":"DOT/USDT","bids":[],"asks":[{"price":7.0926,"qty":33.00000000}],"checksum":2592433723,"timestamp":"2024-06-01T22:43:11.305872Z"}]}
{"channel":"book","type":"update","data":[{"symbol":"DOT/USDT","bids":[{"price":7.0884,"qty":57.69502000}],"asks":[],"checksum":2008744131,"timestamp":"2024-06-01T22:43:11.306874Z"}]}
{"channel":"book","type":"update","data":[{"symbol":"DOT/USDT","bids":[{"price":7.0901,"qty":321.64683178}],"asks":[],"checksum":139169524,"timestamp":"2024-06-01T22:43:11.311572Z"}]}
{"channel":"book","type":"update","data":[{"symbol":"DOT/USDT","bids":[{"price":7.0909,"qty":31.74297723}],"asks":[],"checksum":2374936827,"timestamp":"2024-06-01T22:43:11.321100Z"}]}
{"channel":"book","type":"update","data":[{"symbol":"DOT/USDT","bids":[{"price":7.0885,"qty":0.00000000},{"price":7.0857,"qty":31.91140021}],"asks":[],"checksum":2147500026,"timestamp":"2024-06-01T22:43:11.324869Z"}]}
{"channel":"book","type":"update","data":[{"symbol":"DOT/USDT","bids":[],"asks":[{"price":7.0926,"qty":0.00000000},{"price":7.0971,"qty":22.00000000}],"checksum":3091650015,"timestamp":"2024-06-01T22:43:11.340099Z"}]}
{"channel":"book","type":"update","data":[{"symbol":"DOT/USDT","bids":[{"price":7.0881,"qty":705.99619861}],"asks":[],"checksum":4124690673,"timestamp":"2024-06-01T22:43:11.344733Z"}]}
{"channel":"book","type":"update","data":[{"symbol":"DOT/USDT","bids":[],"asks":[{"price":7.0971,"qty":0.00000000},{"price":7.0988,"qty":4.01307589}],"checksum":744430443,"timestamp":"2024-06-01T22:43:11.349100Z"}]}
{"channel":"book","type":"update","data":[{"symbol":"DOT/USDT","bids":[{"price":7.0876,"qty":31.00000000}],"asks":[],"checksum":864467863,"timestamp":"2024-06-01T22:43:11.355696Z"}]}
{"channel":"book","type":"update","data":[{"symbol":"DOT/USDT","bids":[{"price":7.0909,"qty":0.00000000},{"price":7.0857,"qty":31.91140021}],"asks":[],"checksum":3329251728,"timestamp":"2024-06-01T22:43:11.399346Z"}]}
