{"channel":"book","type":"snapshot","data":[{"symbol":"DOT/JPY","bids":[{"price":1113.3,"qty":21.19240097},{"price":1112.6,"qty":205.20559183},{"price":1112.4,"qty":80.91000000},{"price":1111.2,"qty":6.39962651},{"price":1111.1,"qty":148.48000000},{"price":1110.1,"qty":409.33000000},{"price":1104.0,"qty":298.05000000},{"price":1103.9,"qty":198.51000000},{"price":1103.8,"qty":198.51000000},{"price":1086.0,"qty":102.34000000}],"asks":[{"price":1117.3,"qty":21.12824846},{"price":1118.1,"qty":59.01111075},{"price":1119.2,"qty":136.26072105},{"price":1119.3,"qty":80.91000000},{"price":1120.6,"qty":148.48000000},{"price":1122.2,"qty":409.33000000},{"price":1123.7,"qty":4.04807581},{"price":1123.8,"qty":298.05000000},{"price":1127.6,"qty":198.51000000},{"price":1134.8,"qty":198.51000000}],"checksum":2114945956}]}
{"channel":"book","type":"update","data":[{"symbol":"DOT/JPY","bids":[],"asks":[{"price":1118.1,"qty":0.00000000},{"price":1138.2,"qty":102.34000000},{"price":1119.1,"qty":59.01111075}],"checksum":1304906739,"timestamp":"2024-06-01T22:42:27.349752Z"}]}
{"channel":"book","type":"update","data":[{"symbol":"DOT/JPY","bids":[],"asks":[{"price":1119.2,"qty":0.00000000},{"price":1138.2,"qty":102.34000000}],"checksum":1581989738,"timestamp":"2024-06-01T22:42:27.372699Z"}]}
{"channel":"book","type":"update","data":[{"symbol":"DOT/JPY","bids":[],"asks":[{"price":1119.0,"qty":136.26072105}],"checksum":1467320406,"timestamp":"2024-06-01T22:42:27.372930Z"}]}
{"channel":"book","type":"update","data":[{"symbol":"DOT/JPY","bids":[],"asks":[{"price":1119.1,"qty":0.00000000},{"price":1138.2,"qty":102.34000000},{"price":1118.9,"qty":59.01111075}],"checksum":535224580,"timestamp":"2024-06-01T22:42:27.432175Z"}]}
{"channel":"book","type":"update","data":[{"symbol":"DOT/JPY","bids":[],"asks":[{"price":1118.8,"qty":136.26072105}],"checksum":3017246155,"timestamp":"2024-06-01T22:42:27.462683Z"}]}
{"channel":"book","type":"update","data":[{"symbol":"DOT/JPY","bids":[],"asks":[{"price":1119.0,"qty":0.00000000},{"price":1134.8,"qty":198.51000000}],"checksum":2934967854,"timestamp":"2024-06-01T22:42:27.462769Z"}]}
{"channel":"book","type":"update","data":[{"symbol":"DOT/JPY","bids":[],"asks":[{"price":1118.9,"qty":0.00000000},{"price":1138.2,"qty":102.34000000},{"price":1118.7,"qty":59.01111075}],"checksum":3434937962,"timestamp":"2024-06-01T22:42:27.506456Z"}]}
{"channel":"book","type":"update","data":[{"symbol":"DOT/JPY","bids":[],"asks":[{"price":1118.8,"qty":0.00000000},{"price":1138.2,"qty":102.34000000}],"checksum":3102560400,"timestamp":"2024-06-01T22:42:27.510299Z"}]}
{"channel":"book","type":"update","data":[{"symbol":"DOT/JPY","bids":[],"asks":[{"price":1118.6,"qty":136.26072105}],"checksum":2145133921,"timestamp":"2024-06-01T22:42:27.510486Z"}]}
{"channel":"book","type":"update","data":[{"symbol":"DOT/JPY","bids":[],"asks":[{"price":1118.7,"qty":0.00000000},{"price":1138.2,"qty":102.34000000},{"price":1118.5,"qty":59.01111075}],"checksum":2337348048,"timestamp":"2024-06-01T22:42:27.567972Z"}]}
{"channel":"book","type":"update","data":[{"symbol":"DOT/JPY","bids":[],"asks":[{"price":1118.6,"qty":0.00000000},{"price":1138.2,"qty":102.34000000}],"checksum":4097257995,"timestamp":"2024-06-01T22:42:27.589922Z"}]}
{"channel":"book","type":"update","data":[{"symbol":"DOT/JPY","bids":[],"asks":[{"price":1118.4,"qty":136.26072105}],"checksum":298003043,"timestamp":"2024-06-01T22:42:27.590136Z"}]}
{"channel":"book","type":"update","data":[{"symbol":"DOT/JPY","bids":[],"asks":[{"price":1118.5,"qty":0.00000000},{"price":1138.2,"qty":102.34000000},{"price":1118.3,"qty":59.01111075}],"checksum":3620622576,"timestamp":"2024-06-01T22:42:27.648390Z"}]}
{"channel":"book","type":"update","data":[{"symbol":"DOT/JPY","bids":[],"asks":[{"price":1118.4,"qty":0.00000000},{"price":1138.2,"qty":102.34000000}],"checksum":559519142,"timestamp":"2024-06-01T22:42:27.653090Z"}]}
{"channel":"book","type":"update","data":[{"symbol":"DOT/JPY","bids":[],"asks":[{"price":1118.2,"qty":136.26072105}],"checksum":2749512549,"timestamp":"2024-06-01T22:42:27.653104Z"}]}
{"channel":"book","type":"update","data":[{"symbol":"DOT/JPY","bids":[],"asks":[{"price":1118.3,"qty":0.00000000},{"price":1138.2,"qty":102.34000000},{"price":1118.1,"qty":59.01111075}],"checksum":3665233853,"timestamp":"2024-06-01T22:42:27.709398Z"}]}
{"channel":"book","type":"update","data":[{"symbol":"DOT/JPY","bids":[],"asks":[{"price":1118.2,"qty":0.00000000},{"price":1138.2,"qty":102.34000000}],"checksum":1837365053,"timestamp":"2024-06-01T22:42:27.713017Z"}]}
{"channel":"book","type":"update","data":[{"symbol":"DOT/JPY","bids":[],"asks":[{"price":1119.2,"qty":136.26072105}],"checksum":2114945956,"timestamp":"2024-06-01T22:42:27.713107Z"}]}
{"channel":"book","type":"update","data":[{"symbol":"DOT/JPY","bids":[{"price":1104.0,"qty":0.00000000},{"price":1085.9,"qty":1.57012616}],"asks":[],"checksum":2429278726,"timestamp":"2024-06-01T22:42:31.509745Z"}]}
{"channel":"book","type":"update","data":[{"symbol":"DOT/JPY","bids":[{"price":1086.0,"qty":0.00000000},{"price":1085.8,"qty":49.69000000}],"asks":[],"checksum":767378710,"timestamp":"2024-06-01T22:42:31.509816Z"}]}
{"channel":"book","type":"update","data":[{"symbol":"DOT/JPY","bids":[{"price":1104.1,"qty":298.05000000}],"asks":[],"checksum":3029004581,"timestamp":"2024-06-01T22:42:31.512341Z"}]}
{"channel":"book","type":"update","data":[{"symbol":"DOT/JPY","bids":[{"price":1086.1,"qty":102.34000000}],"asks":[],"checksum":796475716,"timestamp":"2024-06-01T22:42:31.512716Z"}]}
{"channel":"book","type":"update","data":[{"symbol":"DOT/JPY","bids":[{"price":1086.1,"qty":0.00000000},{"price":1085.9,"qty":1.57012616}],"asks":[],"checksum":3029004581,"timestamp":"2024-06-01T22:42:37.394387Z"}]}
{"channel":"book","type":"update","data":[{"symbol":"DOT/JPY","bids":[{"price":1104.1,"qty":0.00000000},{"price":1085.8,"qty":49.69000000}],"asks":[],"checksum":767378710,"timestamp":"2024-06-01T22:42:37.394552Z"}]}
{"channel":"book","type":"update","data":[{"symbol":"DOT/JPY","bids":[{"price":1104.0,"qty":298.05000000}],"asks":[],"checksum":4266524342,"timestamp":"2024-06-01T22:42:37.397172Z"}]}
{"channel":"book","type":"update","data":[{"symbol":"DOT/JPY","bids":[{"price":1086.0,"qty":102.34000000}],"asks":[],"checksum":2114945956,"timestamp":"2024-06-01T22:42:37.397275Z"}]}
{"channel":"book","type":"update","data":[{"symbol":"DOT/JPY","bids":[],"asks":[{"price":1118.1,"qty":0.00000000},{"price":1138.2,"qty":102.34000000},{"price":1119.1,"qty":59.01111075}],"checksum":1304906739,"timestamp":"2024-06-01T22:42:37.773024Z"}]}
{"channel":"book","type":"update","data":[{"symbol":"DOT/JPY","bids":[],"asks":[{"price":1119.2,"qty":0.00000000},{"price":1138.2,"qty":102.34000000}],"checksum":1581989738,"timestamp":"2024-06-01T22:42:37.790241Z"}]}
{"channel":"book","type":"update","data":[{"symbol":"DOT/JPY","bids":[],"asks":[{"price":1119.0,"qty":136.26072105}],"checksum":1467320406,"timestamp":"2024-06-01T22:42:37.790270Z"}]}
{"channel":"book","type":"update","data":[{"symbol":"DOT/JPY","bids":[],"asks":[{"price":1119.1,"qty":0.00000000},{"price":1138.2,"qty":102.34000000},{"price":1118.9,"qty":59.01111075}],"checksum":535224580,"timestamp":"2024-06-01T22:42:37.850203Z"}]}
{"channel":"book","type":"update","data":[{"symbol":"DOT/JPY","bids":[],"asks":[{"price":1119.0,"qty":0.00000000},{"price":1138.2,"qty":102.34000000}],"checksum":2241559312,"timestamp":"2024-06-01T22:42:37.869891Z"}]}
{"channel":"book","type":"update","data":[{"symbol":"DOT/JPY","bids":[],"asks":[{"price":1118.8,"qty":136.26072105}],"checksum":2934967854,"timestamp":"2024-06-01T22:42:37.870001Z"}]}
{"channel":"book","type":"update","data":[{"symbol":"DOT/JPY","bids":[],"asks":[{"price":1118.9,"qty":0.00000000},{"price":1138.2,"qty":102.34000000},{"price":1118.7,"qty":59.01111075}],"checksum":3434937962,"timestamp":"2024-06-01T22:42:37.942264Z"}]}
{"channel":"book","type":"update","data":[{"symbol":"DOT/JPY","bids":[],"asks":[{"price":1118.8,"qty":0.00000000},{"price":1138.2,"qty":102.34000000}],"checksum":3102560400,"timestamp":"2024-06-01T22:42:37.970394Z"}]}
{"channel":"book","type":"update","data":[{"symbol":"DOT/JPY","bids":[],"asks":[{"price":1118.6,"qty":136.26072105}],"checksum":2145133921,"timestamp":"2024-06-01T22:42:37.970416Z"}]}
{"channel":"book","type":"update","data":[{"symbol":"DOT/JPY","bids":[],"asks":[{"price":1118.7,"qty":0.00000000},{"price":1138.2,"qty":102.34000000},{"price":1118.5,"qty":59.01111075}],"checksum":2337348048,"timestamp":"2024-06-01T22:42:38.019096Z"}]}
{"channel":"book","type":"update","data":[{"symbol":"DOT/JPY","bids":[],"asks":[{"price":1118.6,"qty":0.00000000},{"price":1138.2,"qty":102.34000000}],"checksum":4097257995,"timestamp":"2024-06-01T22:42:38.032245Z"}]}
{"channel":"book","type":"update","data":[{"symbol":"DOT/JPY","bids":[],"asks":[{"price":1118.4,"qty":136.26072105}],"checksum":298003043,"timestamp":"2024-06-01T22:42:38.032302Z"}]}
{"channel":"book","type":"update","data":[{"symbol":"DOT/JPY","bids":[],"asks":[{"price":1118.5,"qty":0.00000000},{"price":1138.2,"qty":102.34000000},{"price":1118.3,"qty":59.01111075}],"checksum":3620622576,"timestamp":"2024-06-01T22:42:38.098723Z"}]}
{"channel":"book","type":"update","data":[{"symbol":"DOT/JPY","bids":[],"asks":[{"price":1118.4,"qty":0.00000000},{"price":1138.2,"qty":102.34000000}],"checksum":559519142,"timestamp":"2024-06-01T22:42:38.121752Z"}]}
{"channel":"book","type":"update","data":[{"symbol":"DOT/JPY","bids":[],"asks":[{"price":1118.2,"qty":136.26072105}],"checksum":2749512549,"timestamp":"2024-06-01T22:42:38.122132Z"}]}
{"channel":"book","type":"update","data":[{"symbol":"DOT/JPY","bids":[],"asks":[{"price":1118.3,"qty":0.00000000},{"price":1138.2,"qty":102.34000000},{"price":1118.1,"qty":59.01111075}],"checksum":3665233853,"timestamp":"2024-06-01T22:42:38.170780Z"}]}
{"channel":"book","type":"update","data":[{"symbol":"DOT/JPY","bids":[],"asks":[{"price":1118.2,"qty":0.00000000},{"price":1138.2,"qty":102.34000000}],"checksum":1837365053,"timestamp":"2024-06-01T22:42:38.182822Z"}]}
{"channel":"book","type":"update","data":[{"symbol":"DOT/JPY","bids":[],"asks":[{"price":1119.2,"qty":136.26072105}],"checksum":2114945956,"timestamp":"2024-06-01T22:42:38.182975Z"}]}
{"channel":"book","type":"update","data":[{"symbol":"DOT/JPY","bids":[],"asks":[{"price":1118.1,"qty":0.00000000},{"price":1138.2,"qty":102.34000000},{"price":1119.1,"qty":59.01111075}],"checksum":1304906739,"timestamp":"2024-06-01T22:42:48.220450Z"}]}
{"channel":"book","type":"update","data":[{"symbol":"DOT/JPY","bids":[],"asks":[{"price":1119.0,"qty":136.26072105}],"checksum":913800647,"timestamp":"2024-06-01T22:42:48.254196Z"}]}
{"channel":"book","type":"update","data":[{"symbol":"DOT/JPY","bids":[],"asks":[{"price":1119.2,"qty":0.00000000},{"price":1134.8,"qty":198.51000000}],"checksum":1467320406,"timestamp":"2024-06-01T22:42:48.254214Z"}]}
{"channel":"book","type":"update","data":[{"symbol":"DOT/JPY","bids":[],"asks":[{"price":1119.1,"qty":0.00000000},{"price":1138.2,"qty":102.34000000},{"price":1118.9,"qty":59.01111075}],"checksum":535224580,"timestamp":"2024-06-01T22:42:48.299905Z"}]}
{"channel":"book","type":"update","data":[{"symbol":"DOT/JPY","bids":[],"asks":[{"price":1118.8,"qty":136.26072105}],"checksum":3017246155,"timestamp":"2024-06-01T22:42:48.346662Z"}]}
{"channel":"book","type":"update","data":[{"symbol":"DOT/JPY","bids":[],"asks":[{"price":1119.0,"qty":0.00000000},{"price":1134.8,"qty":198.51000000}],"checksum":2934967854,"timestamp":"2024-06-01T22:42:48.346691Z"}]}
{"channel":"book","type":"update","data":[{"symbol":"DOT/JPY","bids":[],"asks":[{"price":1118.9,"qty":0.00000000},{"price":1138.2,"qty":102.34000000},{"price":1118.7,"qty":59.01111075}],"checksum":3434937962,"timestamp":"2024-06-01T22:42:48.395350Z"}]}
{"channel":"book","type":"update","data":[{"symbol":"DOT/JPY","bids":[],"asks":[{"price":1118.8,"qty":0.00000000},{"price":1138.2,"qty":102.34000000}],"checksum":3102560400,"timestamp":"2024-06-01T22:42:48.414761Z"}]}
{"channel":"book","type":"update","data":[{"symbol":"DOT/JPY","bids":[],"asks":[{"price":1118.6,"qty":136.26072105}],"checksum":2145133921,"timestamp":"2024-06-01T22:42:48.414937Z"}]}
{"channel":"book","type":"update","data":[{"symbol":"DOT/JPY","bids":[],"asks":[{"price":1118.7,"qty":0.00000000},{"price":1138.2,"qty":102.34000000},{"price":1118.5,"qty":59.01111075}],"checksum":2337348048,"timestamp":"2024-06-01T22:42:48.474534Z"}]}
{"channel":"book","type":"update","data":[{"symbol":"DOT/JPY","bids":[],"asks":[{"price":1118.6,"qty":0.00000000},{"price":1138.2,"qty":102.34000000}],"checksum":4097257995,"timestamp":"2024-06-01T22:42:48.481822Z"}]}
{"channel":"book","type":"update","data":[{"symbol":"DOT/JPY","bids":[],"asks":[{"price":1118.4,"qty":136.26072105}],"checksum":298003043,"timestamp":"2024-06-01T22:42:48.482009Z"}]}
{"channel":"book","type":"update","data":[{"symbol":"DOT/JPY","bids":[],"asks":[{"price":1118.5,"qty":0.00000000},{"price":1138.2,"qty":102.34000000},{"price":1118.3,"qty":59.01111075}],"checksum":3620622576,"timestamp":"2024-06-01T22:42:48.531753Z"}]}
{"channel":"book","type":"update","data":[{"symbol":"DOT/JPY","bids":[],"asks":[{"price":1118.4,"qty":0.00000000},{"price":1138.2,"qty":102.34000000}],"checksum":559519142,"timestamp":"2024-06-01T22:42:48.562177Z"}]}
{"channel":"book","type":"update","data":[{"symbol":"DOT/JPY","bids":[],"asks":[{"price":1118.2,"qty":136.26072105}],"checksum":2749512549,"timestamp":"2024-06-01T22:42:48.562299Z"}]}
{"channel":"book","type":"update","data":[{"symbol":"DOT/JPY","bids":[],"asks":[{"price":1118.3,"qty":0.00000000},{"price":1138.2,"qty":102.34000000},{"price":1118.1,"qty":59.01111075}],"checksum":3665233853,"timestamp":"2024-06-01T22:42:48.612959Z"}]}
{"channel":"book","type":"update","data":[{"symbol":"DOT/JPY","bids":[],"asks":[{"price":1119.2,"qty":136.26072105}],"checksum":3145069100,"timestamp":"2024-06-01T22:42:48.637228Z"}]}
{"channel":"book","type":"update","data":[{"symbol":"DOT/JPY","bids":[],"asks":[{"price":1118.2,"qty":0.00000000},{"price":1134.8,"qty":198.51000000}],"checksum":2114945956,"timestamp":"2024-06-01T22:42:48.637320Z"}]}
{"channel":"book","type":"update","data":[{"symbol":"DOT/JPY","bids":[{"price":1086.0,"qty":0.00000000},{"price":1085.9,"qty":1.57012616}],"asks":[],"checksum":4266524342,"timestamp":"2024-06-01T22:42:55.050575Z"}]}
{"channel":"book","type":"update","data":[{"symbol":"DOT/JPY","bids":[{"price":1112.4,"qty":0.00000000},{"price":1085.8,"qty":49.69000000}],"asks":[],"checksum":327086876,"timestamp":"2024-06-01T22:42:55.050761Z"}]}
{"channel":"book","type":"update","data":[{"symbol":"DOT/JPY","bids":[{"price":1104.0,"qty":0.00000000},{"price":1084.8,"qty":2.78913438}],"asks":[],"checksum":421173254,"timestamp":"2024-06-01T22:42:55.050909Z"}]}
{"channel":"book","type":"update","data":[{"symbol":"DOT/JPY","bids":[{"price":1086.1,"qty":102.34000000}],"asks":[],"checksum":1819115720,"timestamp":"2024-06-01T22:42:55.053251Z"}]}
{"channel":"book","type":"update","data":[{"symbol":"DOT/JPY","bids":[{"price":1111.9,"qty":80.91000000}],"asks":[],"checksum":3871276630,"timestamp":"2024-06-01T22:42:55.053274Z"}]}
{"channel":"book","type":"update","data":[{"symbol":"DOT/JPY","bids":[{"price":1104.1,"qty":298.05000000}],"asks":[],"checksum":2826204073,"timestamp":"2024-06-01T22:42:55.053722Z"}]}
{"channel":"book","type":"update","data":[{"symbol":"DOT/JPY","bids":[{"price":1111.2,"qty":0.00000000},{"price":1085.9,"qty":1.57012616}],"asks":[],"checksum":110856402,"timestamp":"2024-06-01T22:42:55.069772Z"}]}
{"channel":"book","type":"update","data":[{"symbol":"DOT/JPY","bids":[{"price":1112.0,"qty":6.40050825}],"asks":[],"checksum":3267772945,"timestamp":"2024-06-01T22:42:55.070015Z"}]}
