{"channel":"book","type":"snapshot","data":[{"symbol":"DOT/EUR","bids":[{"price":6.5320,"qty":46.80000000},{"price":6.5318,"qty":92.57000000},{"price":6.5317,"qty":85.80186000},{"price":6.5316,"qty":352.80531188},{"price":6.5312,"qty":352.82243797},{"price":6.5311,"qty":130.32990000},{"price":6.5309,"qty":321.64683178},{"price":6.5301,"qty":4.66385457},{"price":6.5300,"qty":352.89180084},{"price":6.5299,"qty":1411.49109114}],"asks":[{"price":6.5334,"qty":352.70860031},{"price":6.5338,"qty":352.68716803},{"price":6.5359,"qty":352.57583569},{"price":6.5362,"qty":200.00000000},{"price":6.5367,"qty":193.47964415},{"price":6.5370,"qty":63.50663386},{"price":6.5373,"qty":705.76843803},{"price":6.5376,"qty":94.58897344},{"price":6.5384,"qty":8.50347200},{"price":6.5385,"qty":1411.57470061}],"checksum":1315358364}]}
{"channel":"book","type":"update","data":[{"symbol":"DOT/EUR","bids":[{"price":6.5300,"qty":358.87885911}],"asks":[],"checksum":3101290936,"timestamp":"2024-06-01T22:42:26.930694Z"}]}
{"channel":"book","type":"update","data":[{"symbol":"DOT/EUR","bids":[],"asks":[{"price":6.5384,"qty":0.00000000},{"price":6.5386,"qty":1411.57470061}],"checksum":120335098,"timestamp":"2024-06-01T22:42:28.289129Z"}]}
{"channel":"book","type":"update","data":[{"symbol":"DOT/EUR","bids":[],"asks":[{"price":6.5384,"qty":5.23256337}],"checksum":3135772950,"timestamp":"2024-06-01T22:42:28.289786Z"}]}
{"channel":"book","type":"update","data":[{"symbol":"DOT/EUR","bids":[],"asks":[{"price":6.5384,"qty":0.00000000},{"price":6.5386,"qty":1411.57470061}],"checksum":120335098,"timestamp":"2024-06-01T22:42:33.818972Z"}]}
{"channel":"book","type":"update","data":[{"symbol":"DOT/EUR","bids":[],"asks":[{"price":6.5384,"qty":2.82286198}],"checksum":2250765032,"timestamp":"2024-06-01T22:42:33.821195Z"}]}
{"channel":"book","type":"update","data":[{"symbol":"DOT/EUR","bids":[],"asks":[{"price":6.5376,"qty":0.00000000},{"price":6.5386,"qty":1411.57470061}],"checksum":546341002,"timestamp":"2024-06-01T22:42:34.023700Z"}]}
{"channel":"book","type":"update","data":[{"symbol":"DOT/EUR","bids":[],"asks":[{"price":6.5362,"qty":292.57000000}],"checksum":2783418189,"timestamp":"2024-06-01T22:42:34.311221Z"}]}
{"channel":"book","type":"update","data":[{"symbol":"DOT/EUR","bids":[],"asks":[{"price":6.5365,"qty":31.70000000}],"checksum":4209035848,"timestamp":"2024-06-01T22:42:35.818628Z"}]}
{"channel":"book","type":"update","data":[{"symbol":"DOT/EUR","bids":[],"asks":[{"price":6.5384,"qty":0.00000000},{"price":6.5386,"qty":1411.57470061}],"checksum":3435895822,"timestamp":"2024-06-01T22:42:36.598327Z"}]}
{"channel":"book","type":"update","data":[{"symbol":"DOT/EUR","bids":[{"price":6.5301,"qty":0.00000000},{"price":6.5298,"qty":1411.53687606}],"asks":[],"checksum":2417920879,"timestamp":"2024-06-01T22:42:37.000973Z"}]}
{"channel":"book","type":"update","data":[{"symbol":"DOT/EUR","bids":[{"price":6.5300,"qty":352.89180084}],"asks":[],"checksum":2250417706,"timestamp":"2024-06-01T22:42:37.001191Z"}]}
{"channel":"book","type":"update","data":[{"symbol":"DOT/EUR","bids":[{"price":6.5301,"qty":6.50484716}],"asks":[],"checksum":1870669934,"timestamp":"2024-06-01T22:42:37.006425Z"}]}
{"channel":"book","type":"update","data":[{"symbol":"DOT/EUR","bids":[],"asks":[{"price":6.5367,"qty":0.00000000},{"price":6.5387,"qty":737.29777480}],"checksum":3233507212,"timestamp":"2024-06-01T22:42:37.494191Z"}]}
{"channel":"book","type":"update","data":[{"symbol":"DOT/EUR","bids":[],"asks":[{"price":6.5367,"qty":161.95464415}],"checksum":1945824718,"timestamp":"2024-06-01T22:42:37.498446Z"}]}
{"channel":"book","type":"update","data":[{"symbol":"DOT/EUR","bids":[],"asks":[{"price":6.5384,"qty":5.57680643}],"checksum":388699373,"timestamp":"2024-06-01T22:42:39.433119Z"}]}
{"channel":"book","type":"update","data":[{"symbol":"DOT/EUR","bids":[{"price":6.5318,"qty":0.00000000},{"price":6.5298,"qty":1411.53687606}],"asks":[],"checksum":1236868234,"timestamp":"2024-06-01T22:42:40.373787Z"}]}
{"channel":"book","type":"update","data":[{"symbol":"DOT/EUR","bids":[{"price":6.5321,"qty":92.48000000}],"asks":[],"checksum":3836619298,"timestamp":"2024-06-01T22:42:40.376074Z"}]}
{"channel":"book","type":"update","data":[{"symbol":"DOT/EUR","bids":[{"price":6.5320,"qty":0.00000000},{"price":6.5298,"qty":1411.53687606}],"asks":[],"checksum":140985562,"timestamp":"2024-06-01T22:42:40.378728Z"}]}
{"channel":"book","type":"update","data":[{"symbol":"DOT/EUR","bids":[{"price":6.5322,"qty":46.80000000}],"asks":[],"checksum":1698276071,"timestamp":"2024-06-01T22:42:40.379074Z"}]}
{"channel":"book","type":"update","data":[{"symbol":"DOT/EUR","bids":[],"asks":[{"price":6.5373,"qty":0.00000000},{"price":6.5386,"qty":1411.57470061}],"checksum":1511950959,"timestamp":"2024-06-01T22:42:44.708754Z"}]}
{"channel":"book","type":"update","data":[{"symbol":"DOT/EUR","bids":[],"asks":[{"price":6.5384,"qty":0.00000000},{"price":6.5387,"qty":737.29777480}],"checksum":1803791733,"timestamp":"2024-06-01T22:42:44.999873Z"}]}
{"channel":"book","type":"update","data":[{"symbol":"DOT/EUR","bids":[],"asks":[{"price":6.5384,"qty":11.42893838}],"checksum":2096669909,"timestamp":"2024-06-01T22:42:45.000471Z"}]}
{"channel":"book","type":"update","data":[{"symbol":"DOT/EUR","bids":[],"asks":[{"price":6.5365,"qty":0.00000000},{"price":6.5387,"qty":737.29777480}],"checksum":2705382450,"timestamp":"2024-06-01T22:42:48.991582Z"}]}
{"channel":"book","type":"update","data":[{"symbol":"DOT/EUR","bids":[],"asks":[{"price":6.5379,"qty":705.74455028}],"checksum":2755110780,"timestamp":"2024-06-01T22:42:49.668800Z"}]}
{"channel":"book","type":"update","data":[{"symbol":"DOT/EUR","bids":[{"price":6.5300,"qty":361.23764059}],"asks":[],"checksum":2729342857,"timestamp":"2024-06-01T22:42:49.717124Z"}]}
{"channel":"book","type":"update","data":[{"symbol":"DOT/EUR","bids":[],"asks":[{"price":6.5384,"qty":0.00000000},{"price":6.5387,"qty":737.29777480}],"checksum":3267930575,"timestamp":"2024-06-01T22:42:50.443594Z"}]}
{"channel":"book","type":"update","data":[{"symbol":"DOT/EUR","bids":[],"asks":[{"price":6.5378,"qty":8.33075087}],"checksum":1805438425,"timestamp":"2024-06-01T22:42:50.444358Z"}]}
{"channel":"book","type":"update","data":[{"symbol":"DOT/EUR","bids":[],"asks":[{"price":6.5375,"qty":705.74455028}],"checksum":1302867681,"timestamp":"2024-06-01T22:42:54.760442Z"}]}
{"channel":"book","type":"update","data":[{"symbol":"DOT/EUR","bids":[],"asks":[{"price":6.5367,"qty":0.00000000},{"price":6.5386,"qty":1411.57470061}],"checksum":3712755096,"timestamp":"2024-06-01T22:42:55.597027Z"}]}
{"channel":"book","type":"update","data":[{"symbol":"DOT/EUR","bids":[],"asks":[{"price":6.5367,"qty":161.95464415}],"checksum":1302867681,"timestamp":"2024-06-01T22:42:55.602845Z"}]}
{"channel":"book","type":"update","data":[{"symbol":"DOT/EUR","bids":[],"asks":[{"price":6.5378,"qty":0.00000000},{"price":6.5386,"qty":1411.57470061}],"checksum":413887624,"timestamp":"2024-06-01T22:42:55.998438Z"}]}
{"channel":"book","type":"update","data":[{"symbol":"DOT/EUR","bids":[],"asks":[{"price":6.5374,"qty":2.82286198}],"checksum":950692024,"timestamp":"2024-06-01T22:42:56.000093Z"}]}
{"channel":"book","type":"update","data":[{"symbol":"DOT/EUR","bids":[{"price":6.5300,"qty":352.89180084}],"asks":[],"checksum":1043576909,"timestamp":"2024-06-01T22:42:57.301656Z"}]}
{"channel":"book","type":"update","data":[{"symbol":"DOT/EUR","bids":[{"price":6.5321,"qty":0.00000000},{"price":6.5298,"qty":1411.53687606}],"asks":[],"checksum":4143823249,"timestamp":"2024-06-01T22:42:59.290579Z"}]}
{"channel":"book","type":"update","data":[{"symbol":"DOT/EUR","bids":[{"price":6.5323,"qty":92.47000000}],"asks":[],"checksum":1493776427,"timestamp":"2024-06-01T22:42:59.293036Z"}]}
{"channel":"book","type":"update","data":[{"symbol":"DOT/EUR","bids":[{"price":6.5322,"qty":0.00000000},{"price":6.5298,"qty":1411.53687606}],"asks":[],"checksum":568088406,"timestamp":"2024-06-01T22:42:59.293383Z"}]}
{"channel":"book","type":"update","data":[{"symbol":"DOT/EUR","bids":[{"price":6.5318,"qty":46.80000000}],"asks":[],"checksum":2672843489,"timestamp":"2024-06-01T22:42:59.293510Z"}]}
{"channel":"book","type":"update","data":[{"symbol":"DOT/EUR","bids":[],"asks":[{"price":6.5374,"qty":0.00000000},{"price":6.5386,"qty":1411.57470061}],"checksum":3209780945,"timestamp":"2024-06-01T22:43:01.513969Z"}]}
{"channel":"book","type":"update","data":[{"symbol":"DOT/EUR","bids":[],"asks":[{"price":6.5374,"qty":5.57680643}],"checksum":2607745742,"timestamp":"2024-06-01T22:43:01.514190Z"}]}
{"channel":"book","type":"update","data":[{"symbol":"DOT/EUR","bids":[],"asks":[{"price":6.5374,"qty":0.00000000},{"price":6.5386,"qty":1411.57470061}],"checksum":3209780945,"timestamp":"2024-06-01T22:43:07.206900Z"}]}
{"channel":"book","type":"update","data":[{"symbol":"DOT/EUR","bids":[],"asks":[{"price":6.5374,"qty":2.82286198}],"checksum":2672843489,"timestamp":"2024-06-01T22:43:07.207813Z"}]}
{"channel":"book","type":"update","data":[{"symbol":"DOT/EUR","bids":[],"asks":[{"price":6.5375,"qty":0.00000000},{"price":6.5386,"qty":1411.57470061}],"checksum":3823375912,"timestamp":"2024-06-01T22:43:07.295863Z"}]}
{"channel":"book","type":"update","data":[{"symbol":"DOT/EUR","bids":[{"price":6.5318,"qty":0.00000000},{"price":6.5298,"qty":1411.53687606}],"asks":[],"checksum":1150175838,"timestamp":"2024-06-01T22:43:07.671968Z"}]}
{"channel":"book","type":"update","data":[{"symbol":"DOT/EUR","bids":[{"price":6.5324,"qty":46.80000000}],"asks":[],"checksum":2436452959,"timestamp":"2024-06-01T22:43:07.672314Z"}]}
{"channel":"book","type":"update","data":[{"symbol":"DOT/EUR","bids":[{"price":6.5301,"qty":0.00000000},{"price":6.5298,"qty":1411.53687606}],"asks":[],"checksum":3303453479,"timestamp":"2024-06-01T22:43:09.930986Z"}]}
{"channel":"book","type":"update","data":[{"symbol":"DOT/EUR","bids":[],"asks":[{"price":6.5374,"qty":0.00000000},{"price":6.5387,"qty":31.60000000}],"checksum":139689110,"timestamp":"2024-06-01T22:43:10.008990Z"}]}
{"channel":"book","type":"update","data":[{"symbol":"DOT/EUR","bids":[],"asks":[{"price":6.5378,"qty":8.33075087}],"checksum":2676430201,"timestamp":"2024-06-01T22:43:10.009764Z"}]}
{"channel":"book","type":"update","data":[{"symbol":"DOT/EUR","bids":[],"asks":[{"price":6.5381,"qty":705.72464506}],"checksum":548731175,"timestamp":"2024-06-01T22:43:10.178855Z"}]}
{"channel":"book","type":"update","data":[{"symbol":"DOT/EUR","bids":[],"asks":[{"price":6.5362,"qty":92.57000000}],"checksum":2677811080,"timestamp":"2024-06-01T22:43:11.278942Z"}]}
{"channel":"book","type":"update","data":[{"symbol":"DOT/EUR","bids":[{"price":6.5325,"qty":321.64683178}],"asks":[],"checksum":448377473,"timestamp":"2024-06-01T22:43:11.283861Z"}]}
{"channel":"book","type":"update","data":[{"symbol":"DOT/EUR","bids":[],"asks":[{"price":6.5334,"qty":0.00000000},{"price":6.5386,"qty":1411.57470061}],"checksum":117371843,"timestamp":"2024-06-01T22:43:11.284891Z"}]}
{"channel":"book","type":"update","data":[{"symbol":"DOT/EUR","bids":[{"price":6.5316,"qty":0.00000000},{"price":6.5298,"qty":1411.53687606}],"asks":[],"checksum":688789658,"timestamp":"2024-06-01T22:43:11.284905Z"}]}
{"channel":"book","type":"update","data":[{"symbol":"DOT/EUR","bids":[],"asks":[{"price":6.5379,"qty":0.00000000},{"price":6.5387,"qty":31.60000000}],"checksum":2572246776,"timestamp":"2024-06-01T22:43:11.288690Z"}]}
{"channel":"book","type":"update","data":[{"symbol":"DOT/EUR","bids":[],"asks":[{"price":6.5385,"qty":0.00000000},{"price":6.5388,"qty":352.41981939}],"checksum":3979422808,"timestamp":"2024-06-01T22:43:11.289721Z"}]}
{"channel":"book","type":"update","data":[{"symbol":"DOT/EUR","bids":[],"asks":[{"price":6.5386,"qty":0.00000000},{"price":6.5397,"qty":704.74585881}],"checksum":124296113,"timestamp":"2024-06-01T22:43:11.290018Z"}]}
{"channel":"book","type":"update","data":[{"symbol":"DOT/EUR","bids":[],"asks":[{"price":6.5346,"qty":352.64827157}],"checksum":3962440603,"timestamp":"2024-06-01T22:43:11.290859Z"}]}
{"channel":"book","type":"update","data":[{"symbol":"DOT/EUR","bids":[{"price":6.5320,"qty":352.78347060}],"asks":[],"checksum":2680297052,"timestamp":"2024-06-01T22:43:11.290896Z"}]}
{"channel":"book","type":"update","data":[{"symbol":"DOT/EUR","bids":[],"asks":[{"price":6.5367,"qty":0.00000000},{"price":6.5397,"qty":704.74585881}],"checksum":784711880,"timestamp":"2024-06-01T22:43:11.291365Z"}]}
{"channel":"book","type":"update","data":[{"symbol":"DOT/EUR","bids":[{"price":6.5312,"qty":0.00000000},{"price":6.5298,"qty":1411.53687606}],"asks":[],"checksum":464616334,"timestamp":"2024-06-01T22:43:11.291658Z"}]}
{"channel":"book","type":"update","data":[{"symbol":"DOT/EUR","bids":[],"asks":[{"price":6.5338,"qty":0.00000000},{"price":6.5400,"qty":3.00000000}],"checksum":4246126815,"timestamp":"2024-06-01T22:43:11.291757Z"}]}
{"channel":"book","type":"update","data":[{"symbol":"DOT/EUR","bids":[],"asks":[{"price":6.5345,"qty":46.80000000}],"checksum":1315448878,"timestamp":"2024-06-01T22:43:11.296626Z"}]}
{"channel":"book","type":"update","data":[{"symbol":"DOT/EUR","bids":[{"price":6.5310,"qty":181.52934865}],"asks":[],"checksum":3712625080,"timestamp":"2024-06-01T22:43:11.297521Z"}]}
{"channel":"book","type":"update","data":[{"symbol":"DOT/EUR","bids":[],"asks":[{"price":6.5381,"qty":0.00000000},{"price":6.5400,"qty":3.00000000}],"checksum":2637578361,"timestamp":"2024-06-01T22:43:11.299209Z"}]}
{"channel":"book","type":"update","data":[{"symbol":"DOT/EUR","bids":[],"asks":[{"price":6.5376,"qty":341.85964415}],"checksum":1858690280,"timestamp":"2024-06-01T22:43:11.299751Z"}]}
{"channel":"book","type":"update","data":[{"symbol":"DOT/EUR","bids":[{"price":6.5324,"qty":0.00000000},{"price":6.5298,"qty":1411.53687606}],"asks":[],"checksum":1985659038,"timestamp":"2024-06-01T22:43:11.300047Z"}]}
{"channel":"book","type":"update","data":[{"symbol":"DOT/EUR","bids":[{"price":6.5326,"qty":46.80000000}],"asks":[],"checksum":1714066993,"timestamp":"2024-06-01T22:43:11.300661Z"}]}
{"channel":"book","type":"update","data":[{"symbol":"DOT/EUR","bids":[],"asks":[{"price":6.5346,"qty":0.00000000},{"price":6.5400,"qty":3.00000000}],"checksum":665629500,"timestamp":"2024-06-01T22:43:11.301348Z"}]}
{"channel":"book","type":"update","data":[{"symbol":"DOT/EUR","bids":[],"asks":[{"price":6.5358,"qty":46.80000000}],"checksum":4171806733,"timestamp":"2024-06-01T22:43:11.304874Z"}]}
{"channel":"book","type":"update","data":[{"symbol":"DOT/EUR","bids":[],"asks":[{"price":6.5345,"qty":0.00000000},{"price":6.5400,"qty":3.00000000}],"checksum":781432290,"timestamp":"2024-06-01T22:43:11.304995Z"}]}
{"channel":"book","type":"update","data":[{"symbol":"DOT/EUR","bids":[],"asks":[{"price":6.5400,"qty":1414.44929012}],"checksum":2737546963,"timestamp":"2024-06-01T22:43:11.306503Z"}]}
{"channel":"book","type":"update","data":[{"symbol":"DOT/EUR","bids":[],"asks":[{"price":6.5344,"qty":352.65432202}],"checksum":3423602751,"timestamp":"2024-06-01T22:43:11.307245Z"}]}
{"channel":"book","type":"update","data":[{"symbol":"DOT/EUR","bids":[{"price":6.5327,"qty":63.48993182}],"asks":[],"checksum":404928953,"timestamp":"2024-06-01T22:43:11.311050Z"}]}
{"channel":"book","type":"update","data":[{"symbol":"DOT/EUR","bids":[],"asks":[{"price":6.5370,"qty":0.00000000},{"price":6.5400,"qty":1414.44929012}],"checksum":3317143920,"timestamp":"2024-06-01T22:43:11.311077Z"}]}
{"channel":"book","type":"update","data":[{"symbol":"DOT/EUR","bids":[],"asks":[{"price":6.5344,"qty":0.00000000},{"price":6.5409,"qty":23.60000000}],"checksum":1770238967,"timestamp":"2024-06-01T22:43:11.311877Z"}]}
{"channel":"book","type":"update","data":[{"symbol":"DOT/EUR","bids":[{"price":6.5326,"qty":0.00000000},{"price":6.5299,"qty":1411.49109114}],"asks":[],"checksum":384326852,"timestamp":"2024-06-01T22:43:11.315739Z"}]}
{"channel":"book","type":"update","data":[{"symbol":"DOT/EUR","bids":[{"price":6.5309,"qty":0.00000000},{"price":6.5298,"qty":1411.53687606}],"asks":[],"checksum":1776793726,"timestamp":"2024-06-01T22:43:11.315930Z"}]}
{"channel":"book","type":"update","data":[{"symbol":"DOT/EUR","bids":[{"price":6.5328,"qty":46.80000000}],"asks":[],"checksum":2243933910,"timestamp":"2024-06-01T22:43:11.316406Z"}]}
{"channel":"book","type":"update","data":[{"symbol":"DOT/EUR","bids":[{"price":6.5329,"qty":63.48595446}],"asks":[],"checksum":3183792026,"timestamp":"2024-06-01T22:43:11.321029Z"}]}
{"channel":"book","type":"update","data":[{"symbol":"DOT/EUR","bids":[],"asks":[{"price":6.5359,"qty":0.00000000},{"price":6.5413,"qty":65.17445234}],"checksum":2626507810,"timestamp":"2024-06-01T22:43:11.321724Z"}]}
{"channel":"book","type":"update","data":[{"symbol":"DOT/EUR","bids":[{"price":6.5327,"qty":0.00000000},{"price":6.5299,"qty":1411.49109114}],"asks":[],"checksum":2330768744,"timestamp":"2024-06-01T22:43:11.324442Z"}]}
{"channel":"book","type":"update","data":[{"symbol":"DOT/EUR","bids":[{"price":6.5330,"qty":46.80000000}],"asks":[],"checksum":3772882815,"timestamp":"2024-06-01T22:43:11.325860Z"}]}
{"channel":"book","type":"update","data":[{"symbol":"DOT/EUR","bids":[{"price":6.5328,"qty":0.00000000},{"price":6.5299,"qty":1411.49109114}],"asks":[],"checksum":292434222,"timestamp":"2024-06-01T22:43:11.325943Z"}]}
{"channel":"book","type":"update","data":[{"symbol":"DOT/EUR","bids":[],"asks":[{"price":6.5367,"qty":352.53183714}],"checksum":559974919,"timestamp":"2024-06-01T22:43:11.326064Z"}]}
{"channel":"book","type":"update","data":[{"symbol":"DOT/EUR","bids":[{"price":6.5331,"qty":63.48794685}],"asks":[],"checksum":200776387,"timestamp":"2024-06-01T22:43:11.329793Z"}]}
{"channel":"book","type":"update","data":[{"symbol":"DOT/EUR","bids":[{"price":6.5329,"qty":0.00000000},{"price":6.5299,"qty":1411.49109114}],"asks":[],"checksum":3445423730,"timestamp":"2024-06-01T22:43:11.330485Z"}]}
{"channel":"book","type":"update","data":[{"symbol":"DOT/EUR","bids":[{"price":6.5330,"qty":0.00000000},{"price":6.5298,"qty":1411.53687606}],"asks":[],"checksum":4287177886,"timestamp":"2024-06-01T22:43:11.336626Z"}]}
{"channel":"book","type":"update","data":[{"symbol":"DOT/EUR","bids":[{"price":6.5326,"qty":46.80000000}],"asks":[],"checksum":3832664118,"timestamp":"2024-06-01T22:43:11.336857Z"}]}
{"channel":"book","type":"update","data":[{"symbol":"DOT/EUR","bids":[{"price":6.5326,"qty":0.00000000},{"price":6.5298,"qty":1411.53687606}],"asks":[],"checksum":4287177886,"timestamp":"2024-06-01T22:43:11.338209Z"}]}
{"channel":"book","type":"update","data":[{"symbol":"DOT/EUR","bids":[{"price":6.5332,"qty":46.80000000}],"asks":[],"checksum":4222532415,"timestamp":"2024-06-01T22:43:11.338230Z"}]}
{"channel":"book","type":"update","data":[{"symbol":"DOT/EUR","bids":[],"asks":[{"price":6.5387,"qty":0.00000000},{"price":6.5413,"qty":65.17445234}],"checksum":2615961180,"timestamp":"2024-06-01T22:43:11.345165Z"}]}
{"channel":"book","type":"update","data":[{"symbol":"DOT/EUR","bids":[],"asks":[{"price":6.5390,"qty":705.72464506}],"checksum":716517320,"timestamp":"2024-06-01T22:43:11.395509Z"}]}
{"channel":"book","type":"update","data":[{"symbol":"DOT/EUR","bids":[],"asks":[{"price":6.5394,"qty":705.72464506}],"checksum":3625035769,"timestamp":"2024-06-01T22:43:11.396374Z"}]}
{"channel":"book","type":"update","data":[{"symbol":"DOT/EUR","bids":[],"asks":[{"price":6.5362,"qty":0.00000000},{"price":6.5409,"qty":23.60000000}],"checksum":1281112310,"timestamp":"2024-06-01T22:43:11.396630Z"}]}
{"channel":"book","type":"update","data":[{"symbol":"DOT/EUR","bids":[],"asks":[{"price":6.5366,"qty":46.80000000}],"checksum":515987449,"timestamp":"2024-06-01T22:43:11.399405Z"}]}
{"channel":"book","type":"update","data":[{"symbol":"DOT/EUR","bids":[],"asks":[{"price":6.5358,"qty":0.00000000},{"price":6.5409,"qty":23.60000000}],"checksum":3883954031,"timestamp":"2024-06-01T22:43:11.399502Z"}]}
{"channel":"book","type":"update","data":[{"symbol":"DOT/EUR","bids":[{"price":6.5333,"qty":321.64683178}],"asks":[],"checksum":809810613,"timestamp":"2024-06-01T22:43:11.402326Z"}]}
{"channel":"book","type":"update","data":[{"symbol":"DOT/EUR","bids":[{"price":6.5332,"qty":0.00000000},{"price":6.5299,"qty":1411.49109114}],"asks":[],"checksum":3864430470,"timestamp":"2024-06-01T22:43:11.404979Z"}]}
{"channel":"book","type":"update","data":[{"symbol":"DOT/EUR","bids":[{"price":6.5334,"qty":46.80000000}],"asks":[],"checksum":2480514624,"timestamp":"2024-06-01T22:43:11.405180Z"}]}
{"channel":"book","type":"update","data":[{"symbol":"DOT/EUR","bids":[{"price":6.5331,"qty":0.00000000},{"price":6.5299,"qty":1411.49109114}],"asks":[],"checksum":3102278436,"timestamp":"2024-06-01T22:43:11.414803Z"}]}
{"channel":"book","type":"update","data":[{"symbol":"DOT/EUR","bids":[],"asks":[{"price":6.5367,"qty":0.00000000},{"price":6.5413,"qty":65.17445234}],"checksum":1726415442,"timestamp":"2024-06-01T22:43:11.440386Z"}]}
{"channel":"book","type":"update","data":[{"symbol":"DOT/EUR","bids":[],"asks":[{"price":6.5366,"qty":0.00000000},{"price":6.5414,"qty":306.38000000}],"checksum":1142217047,"timestamp":"2024-06-01T22:43:11.443071Z"}]}
{"channel":"book","type":"update","data":[{"symbol":"DOT/EUR","bids":[],"asks":[{"price":6.5375,"qty":46.80000000}],"checksum":218098579,"timestamp":"2024-06-01T22:43:11.443231Z"}]}
{"channel":"book","type":"update","data":[{"symbol":"DOT/EUR","bids":[],"asks":[{"price":6.5393,"qty":321.64683178}],"checksum":1247021287,"timestamp":"2024-06-01T22:43:11.445120Z"}]}
{"channel":"book","type":"update","data":[{"symbol":"DOT/EUR","bids":[{"price":6.5325,"qty":0.00000000},{"price":6.5298,"qty":1411.53687606}],"asks":[],"checksum":1543962390,"timestamp":"2024-06-01T22:43:11.445147Z"}]}
{"channel":"book","type":"update","data":[{"symbol":"DOT/EUR","bids":[],"asks":[{"price":6.5376,"qty":405.35519193}],"checksum":1617379588,"timestamp":"2024-06-01T22:43:11.446107Z"}]}
{"channel":"book","type":"update","data":[{"symbol":"DOT/EUR","bids":[{"price":6.5317,"qty":0.00000000},{"price":6.5289,"qty":200.00000000}],"asks":[],"checksum":1878523770,"timestamp":"2024-06-01T22:43:11.446142Z"}]}
{"channel":"book","type":"update","data":[{"symbol":"DOT/EUR","bids":[{"price":6.5336,"qty":85.80186000}],"asks":[],"checksum":2117566637,"timestamp":"2024-06-01T22:43:11.448814Z"}]}
{"channel":"book","type":"update","data":[{"symbol":"DOT/EUR","bids":[{"price":6.5334,"qty":0.00000000},{"price":6.5289,"qty":200.00000000}],"asks":[],"checksum":692710382,"timestamp":"2024-06-01T22:43:11.451797Z"}]}
{"channel":"book","type":"update","data":[{"symbol":"DOT/EUR","bids":[{"price":6.5337,"qty":46.80000000}],"asks":[],"checksum":1352757091,"timestamp":"2024-06-01T22:43:11.451997Z"}]}
{"channel":"book","type":"update","data":[{"symbol":"DOT/EUR","bids":[],"asks":[{"price":6.5375,"qty":110.29626439}],"checksum":2441562957,"timestamp":"2024-06-01T22:43:11.541183Z"}]}
{"channel":"book","type":"update","data":[{"symbol":"DOT/EUR","bids":[],"asks":[{"price":6.5376,"qty":341.85964415}],"checksum":2917594463,"timestamp":"2024-06-01T22:43:11.613996Z"}]}
{"channel":"book","type":"update","data":[{"symbol":"DOT/EUR","bids":[],"asks":[{"price":6.5387,"qty":150.00000000}],"checksum":2238891952,"timestamp":"2024-06-01T22:43:11.679021Z"}]}
{"channel":"book","type":"update","data":[{"symbol":"DOT/EUR","bids":[],"asks":[{"price":6.5384,"qty":321.64683178}],"checksum":1767095005,"timestamp":"2024-06-01T22:43:11.736242Z"}]}
{"channel":"book","type":"update","data":[{"symbol":"DOT/EUR","bids":[],"asks":[{"price":6.5387,"qty":0.00000000},{"price":6.5400,"qty":1414.44929012}],"checksum":770249729,"timestamp":"2024-06-01T22:43:11.905147Z"}]}
{"channel":"book","type":"update","data":[{"symbol":"DOT/EUR","bids":[],"asks":[{"price":6.5374,"qty":352.49248964}],"checksum":1325832844,"timestamp":"2024-06-01T22:43:12.129053Z"}]}
{"channel":"book","type":"update","data":[{"symbol":"DOT/EUR","bids":[{"price":6.5328,"qty":352.73595678}],"asks":[],"checksum":350550537,"timestamp":"2024-06-01T22:43:12.129138Z"}]}
{"channel":"book","type":"update","data":[{"symbol":"DOT/EUR","bids":[],"asks":[{"price":6.5374,"qty":704.98497928}],"checksum":4137383615,"timestamp":"2024-06-01T22:43:12.129228Z"}]}
{"channel":"book","type":"update","data":[{"symbol":"DOT/EUR","bids":[],"asks":[{"price":6.5375,"qty":63.49626439}],"checksum":3429038093,"timestamp":"2024-06-01T22:43:12.131809Z"}]}
{"channel":"book","type":"update","data":[{"symbol":"DOT/EUR","bids":[],"asks":[{"price":6.5373,"qty":46.80000000}],"checksum":3677878901,"timestamp":"2024-06-01T22:43:12.131891Z"}]}
{"channel":"book","type":"update","data":[{"symbol":"DOT/EUR","bids":[],"asks":[{"price":6.5375,"qty":0.00000000},{"price":6.5397,"qty":704.74585881}],"checksum":3430314257,"timestamp":"2024-06-01T22:43:12.132042Z"}]}
{"channel":"book","type":"update","data":[{"symbol":"DOT/EUR","bids":[],"asks":[{"price":6.5373,"qty":110.29858140}],"checksum":2227592139,"timestamp":"2024-06-01T22:43:12.132192Z"}]}
{"channel":"book","type":"update","data":[{"symbol":"DOT/EUR","bids":[],"asks":[{"price":6.5374,"qty":352.49248964}],"checksum":2494129531,"timestamp":"2024-06-01T22:43:12.134710Z"}]}
{"channel":"book","type":"update","data":[{"symbol":"DOT/EUR","bids":[],"asks":[{"price":6.5374,"qty":0.00000000},{"price":6.5400,"qty":1414.44929012}],"checksum":1245394218,"timestamp":"2024-06-01T22:43:12.135838Z"}]}
{"channel":"book","type":"update","data":[{"symbol":"DOT/EUR","bids":[],"asks":[{"price":6.5347,"qty":352.64043601}],"checksum":1036480859,"timestamp":"2024-06-01T22:43:12.139024Z"}]}
{"channel":"book","type":"update","data":[{"symbol":"DOT/EUR","bids":[{"price":6.5336,"qty":0.00000000},{"price":6.5298,"qty":1411.53687606}],"asks":[],"checksum":778576360,"timestamp":"2024-06-01T22:43:12.141733Z"}]}
{"channel":"book","type":"update","data":[{"symbol":"DOT/EUR","bids":[{"price":6.5325,"qty":85.80186000}],"asks":[],"checksum":3351751733,"timestamp":"2024-06-01T22:43:12.144334Z"}]}
{"channel":"book","type":"update","data":[{"symbol":"DOT/EUR","bids":[{"price":6.5320,"qty":0.00000000},{"price":6.5298,"qty":1411.53687606}],"asks":[],"checksum":794805374,"timestamp":"2024-06-01T22:43:12.296058Z"}]}
{"channel":"book","type":"update","data":[{"symbol":"DOT/EUR","bids":[],"asks":[{"price":6.5347,"qty":0.00000000},{"price":6.5400,"qty":1414.44929012}],"checksum":137001360,"timestamp":"2024-06-01T22:43:12.296175Z"}]}
{"channel":"book","type":"update","data":[{"symbol":"DOT/EUR","bids":[{"price":6.5311,"qty":483.16136923}],"asks":[],"checksum":45234242,"timestamp":"2024-06-01T22:43:12.302210Z"}]}
{"channel":"book","type":"update","data":[{"symbol":"DOT/EUR","bids":[{"price":6.5333,"qty":0.00000000},{"price":6.5289,"qty":200.00000000}],"asks":[],"checksum":4139453376,"timestamp":"2024-06-01T22:43:12.560749Z"}]}
{"channel":"book","type":"update","data":[{"symbol":"DOT/EUR","bids":[{"price":6.5337,"qty":0.00000000},{"price":6.5281,"qty":384.57583569}],"asks":[],"checksum":2414326180,"timestamp":"2024-06-01T22:43:12.563577Z"}]}
{"channel":"book","type":"update","data":[{"symbol":"DOT/EUR","bids":[{"price":6.5329,"qty":46.80000000}],"asks":[],"checksum":3280213667,"timestamp":"2024-06-01T22:43:12.563796Z"}]}
{"channel":"book","type":"update","data":[{"symbol":"DOT/EUR","bids":[{"price":6.5307,"qty":1411.44929012}],"asks":[],"checksum":2961636071,"timestamp":"2024-06-01T22:43:12.564402Z"}]}
{"channel":"book","type":"update","data":[{"symbol":"DOT/EUR","bids":[],"asks":[{"price":6.5372,"qty":200.00000000}],"checksum":1601172744,"timestamp":"2024-06-01T22:43:12.565817Z"}]}
{"channel":"book","type":"update","data":[{"symbol":"DOT/EUR","bids":[],"asks":[{"price":6.5384,"qty":643.29366356}],"checksum":3186160984,"timestamp":"2024-06-01T22:43:12.566900Z"}]}
{"channel":"book","type":"update","data":[{"symbol":"DOT/EUR","bids":[{"price":6.5298,"qty":0.00000000},{"price":6.5289,"qty":200.00000000}],"asks":[],"checksum":2597012201,"timestamp":"2024-06-01T22:43:12.568094Z"}]}
{"channel":"book","type":"update","data":[{"symbol":"DOT/EUR","bids":[],"asks":[{"price":6.5371,"qty":46.80000000}],"checksum":557387299,"timestamp":"2024-06-01T22:43:12.568500Z"}]}
{"channel":"book","type":"update","data":[{"symbol":"DOT/EUR","bids":[],"asks":[{"price":6.5373,"qty":63.49858140}],"checksum":491300431,"timestamp":"2024-06-01T22:43:12.568513Z"}]}
{"channel":"book","type":"update","data":[{"symbol":"DOT/EUR","bids":[],"asks":[{"price":6.5370,"qty":40.00000000}],"checksum":2736907585,"timestamp":"2024-06-01T22:43:12.568879Z"}]}
{"channel":"book","type":"update","data":[{"symbol":"DOT/EUR","bids":[{"price":6.5301,"qty":49.61697648}],"asks":[],"checksum":1730695966,"timestamp":"2024-06-01T22:43:12.569476Z"}]}
{"channel":"book","type":"update","data":[{"symbol":"DOT/EUR","bids":[{"price":6.5312,"qty":43.49950590}],"asks":[],"checksum":4283985919,"timestamp":"2024-06-01T22:43:12.569505Z"}]}
{"channel":"book","type":"update","data":[{"symbol":"DOT/EUR","bids":[{"price":6.5300,"qty":385.77998719}],"asks":[],"checksum":1499705908,"timestamp":"2024-06-01T22:43:12.569640Z"}]}
{"channel":"book","type":"update","data":[{"symbol":"DOT/EUR","bids":[],"asks":[{"price":6.5371,"qty":0.00000000},{"price":6.5394,"qty":705.72464506}],"checksum":2902944852,"timestamp":"2024-06-01T22:43:12.571271Z"}]}
{"channel":"book","type":"update","data":[{"symbol":"DOT/EUR","bids":[],"asks":[{"price":6.5369,"qty":46.80000000}],"checksum":3374197456,"timestamp":"2024-06-01T22:43:12.571684Z"}]}
{"channel":"book","type":"update","data":[{"symbol":"DOT/EUR","bids":[],"asks":[{"price":6.5368,"qty":63.50380887}],"checksum":3550623223,"timestamp":"2024-06-01T22:43:12.587038Z"}]}
{"channel":"book","type":"update","data":[{"symbol":"DOT/EUR","bids":[],"asks":[{"price":6.5373,"qty":0.00000000},{"price":6.5393,"qty":321.64683178}],"checksum":1103038536,"timestamp":"2024-06-01T22:43:12.587765Z"}]}
{"channel":"book","type":"update","data":[{"symbol":"DOT/EUR","bids":[],"asks":[{"price":6.5369,"qty":0.00000000},{"price":6.5394,"qty":705.72464506}],"checksum":141439500,"timestamp":"2024-06-01T22:43:12.589447Z"}]}
{"channel":"book","type":"update","data":[{"symbol":"DOT/EUR","bids":[],"asks":[{"price":6.5367,"qty":46.80000000}],"checksum":3365964362,"timestamp":"2024-06-01T22:43:12.589795Z"}]}
{"channel":"book","type":"update","data":[{"symbol":"DOT/EUR","bids":[],"asks":[{"price":6.5367,"qty":110.30398448}],"checksum":3736033964,"timestamp":"2024-06-01T22:43:12.592671Z"}]}
{"channel":"book","type":"update","data":[{"symbol":"DOT/EUR","bids":[],"asks":[{"price":6.5365,"qty":40.00000000}],"checksum":3050841252,"timestamp":"2024-06-01T22:43:12.594111Z"}]}
{"channel":"book","type":"update","data":[{"symbol":"DOT/EUR","bids":[],"asks":[{"price":6.5364,"qty":46.80000000}],"checksum":2721902127,"timestamp":"2024-06-01T22:43:12.596794Z"}]}
{"channel":"book","type":"update","data":[{"symbol":"DOT/EUR","bids":[],"asks":[{"price":6.5367,"qty":63.50398448}],"checksum":53556308,"timestamp":"2024-06-01T22:43:12.596841Z"}]}
{"channel":"book","type":"update","data":[{"symbol":"DOT/EUR","bids":[],"asks":[{"price":6.5368,"qty":0.00000000},{"price":6.5390,"qty":705.72464506}],"checksum":2182016851,"timestamp":"2024-06-01T22:43:12.597322Z"}]}
{"channel":"book","type":"update","data":[{"symbol":"DOT/EUR","bids":[],"asks":[{"price":6.5366,"qty":200.00000000}],"checksum":496891469,"timestamp":"2024-06-01T22:43:12.597437Z"}]}
