{"channel":"book","type":"snapshot","data":[{"symbol":"DOT/USD","bids":[{"price":7.0836,"qty":73.80000000},{"price":7.0835,"qty":357.30539499},{"price":7.0832,"qty":10.60000000},{"price":7.0830,"qty":149.73724630},{"price":7.0827,"qty":3528.72772786},{"price":7.0826,"qty":3528.98154554},{"price":7.0822,"qty":27.71050439},{"price":7.0819,"qty":706.01774948},{"price":7.0816,"qty":5.08744038},{"price":7.0815,"qty":2.54372019}],"asks":[{"price":7.0857,"qty":352.82329198},{"price":7.0861,"qty":73.80000000},{"price":7.0862,"qty":705.78735031},{"price":7.0863,"qty":705.76843803},{"price":7.0875,"qty":834.39590186},{"price":7.0880,"qty":234.98573415},{"price":7.0882,"qty":2.54372019},{"price":7.0886,"qty":5.08744038},{"price":7.0887,"qty":324.19055197},{"price":7.0892,"qty":27.71050439}],"checksum":4099634621}]}
{"channel":"book","type":"update","data":[{"symbol":"DOT/USD","bids":[],"asks":[{"price":7.0859,"qty":705.76843803}],"checksum":3221038006,"timestamp":"2024-06-01T22:42:32.478156Z"}]}
{"channel":"book","type":"update","data":[{"symbol":"DOT/USD","bids":[],"asks":[{"price":7.0863,"qty":0.00000000},{"price":7.0892,"qty":27.71050439}],"checksum":2239652801,"timestamp":"2024-06-01T22:42:32.481810Z"}]}
{"channel":"book","type":"update","data":[{"symbol":"DOT/USD","bids":[{"price":7.0830,"qty":3678.57943644}],"asks":[],"checksum":1785577599,"timestamp":"2024-06-01T22:42:35.765714Z"}]}
{"channel":"book","type":"update","data":[{"symbol":"DOT/USD","bids":[{"price":7.0826,"qty":0.00000000},{"price":7.0814,"qty":321.64683178}],"asks":[],"checksum":3108232610,"timestamp":"2024-06-01T22:42:35.795890Z"}]}
{"channel":"book","type":"update","data":[{"symbol":"DOT/USD","bids":[],"asks":[{"price":7.0884,"qty":30.30000000}],"checksum":2647012450,"timestamp":"2024-06-01T22:42:35.800513Z"}]}
{"channel":"book","type":"update","data":[{"symbol":"DOT/USD","bids":[],"asks":[{"price":7.0880,"qty":216.86609000}],"checksum":2922743152,"timestamp":"2024-06-01T22:42:42.917668Z"}]}
{"channel":"book","type":"update","data":[{"symbol":"DOT/USD","bids":[],"asks":[{"price":7.0880,"qty":227.99573415}],"checksum":718583111,"timestamp":"2024-06-01T22:42:42.921921Z"}]}
{"channel":"book","type":"update","data":[{"symbol":"DOT/USD","bids":[],"asks":[{"price":7.0884,"qty":0.00000000},{"price":7.0892,"qty":27.71050439}],"checksum":240213127,"timestamp":"2024-06-01T22:42:43.137287Z"}]}
{"channel":"book","type":"update","data":[{"symbol":"DOT/USD","bids":[],"asks":[{"price":7.0885,"qty":24.20000000}],"checksum":1456239038,"timestamp":"2024-06-01T22:42:43.326051Z"}]}
{"channel":"book","type":"update","data":[{"symbol":"DOT/USD","bids":[],"asks":[{"price":7.0885,"qty":0.00000000},{"price":7.0892,"qty":27.71050439}],"checksum":240213127,"timestamp":"2024-06-01T22:42:43.583884Z"}]}
{"channel":"book","type":"update","data":[{"symbol":"DOT/USD","bids":[],"asks":[{"price":7.0886,"qty":32.48744038}],"checksum":1148365288,"timestamp":"2024-06-01T22:42:43.670454Z"}]}
{"channel":"book","type":"update","data":[{"symbol":"DOT/USD","bids":[],"asks":[{"price":7.0859,"qty":0.00000000},{"price":7.0893,"qty":1.19296277}],"checksum":2768366249,"timestamp":"2024-06-01T22:42:44.708535Z"}]}
{"channel":"book","type":"update","data":[{"symbol":"DOT/USD","bids":[{"price":7.0831,"qty":3528.72275141}],"asks":[],"checksum":3324590144,"timestamp":"2024-06-01T22:42:47.350029Z"}]}
{"channel":"book","type":"update","data":[{"symbol":"DOT/USD","bids":[{"price":7.0827,"qty":0.00000000},{"price":7.0814,"qty":321.64683178}],"asks":[],"checksum":2040851476,"timestamp":"2024-06-01T22:42:47.353349Z"}]}
{"channel":"book","type":"update","data":[{"symbol":"DOT/USD","bids":[],"asks":[{"price":7.0886,"qty":5.08744038}],"checksum":428738031,"timestamp":"2024-06-01T22:42:47.569991Z"}]}
{"channel":"book","type":"update","data":[{"symbol":"DOT/USD","bids":[],"asks":[{"price":7.0866,"qty":705.74455028}],"checksum":3337673241,"timestamp":"2024-06-01T22:42:49.668193Z"}]}
{"channel":"book","type":"update","data":[{"symbol":"DOT/USD","bids":[{"price":7.0822,"qty":0.00000000},{"price":7.0813,"qty":449.78539499}],"asks":[],"checksum":4220523915,"timestamp":"2024-06-01T22:42:51.604144Z"}]}
{"channel":"book","type":"update","data":[{"symbol":"DOT/USD","bids":[{"price":7.0813,"qty":477.49589938}],"asks":[],"checksum":41747219,"timestamp":"2024-06-01T22:42:51.698064Z"}]}
{"channel":"book","type":"update","data":[{"symbol":"DOT/USD","bids":[{"price":7.0832,"qty":3539.32275141}],"asks":[],"checksum":826945963,"timestamp":"2024-06-01T22:42:58.091170Z"}]}
{"channel":"book","type":"update","data":[{"symbol":"DOT/USD","bids":[{"price":7.0830,"qty":149.73724630}],"asks":[],"checksum":2107428947,"timestamp":"2024-06-01T22:42:58.094860Z"}]}
{"channel":"book","type":"update","data":[{"symbol":"DOT/USD","bids":[],"asks":[{"price":7.0856,"qty":1199.62971620}],"checksum":3353787765,"timestamp":"2024-06-01T22:43:00.951194Z"}]}
{"channel":"book","type":"update","data":[{"symbol":"DOT/USD","bids":[],"asks":[{"price":7.0857,"qty":0.00000000},{"price":7.0892,"qty":27.71050439}],"checksum":3702902200,"timestamp":"2024-06-01T22:43:00.956054Z"}]}
{"channel":"book","type":"update","data":[{"symbol":"DOT/USD","bids":[],"asks":[{"price":7.0855,"qty":352.83325100}],"checksum":4213983979,"timestamp":"2024-06-01T22:43:00.960173Z"}]}
{"channel":"book","type":"update","data":[{"symbol":"DOT/USD","bids":[],"asks":[{"price":7.0856,"qty":0.00000000},{"price":7.0892,"qty":27.71050439}],"checksum":1916464253,"timestamp":"2024-06-01T22:43:05.530673Z"}]}
{"channel":"book","type":"update","data":[{"symbol":"DOT/USD","bids":[],"asks":[{"price":7.0862,"qty":0.00000000},{"price":7.0893,"qty":1.19296277}],"checksum":4158557093,"timestamp":"2024-06-01T22:43:07.295654Z"}]}
{"channel":"book","type":"update","data":[{"symbol":"DOT/USD","bids":[],"asks":[{"price":7.0861,"qty":0.00000000},{"price":7.0895,"qty":351.84433103}],"checksum":967736567,"timestamp":"2024-06-01T22:43:07.298555Z"}]}
{"channel":"book","type":"update","data":[{"symbol":"DOT/USD","bids":[],"asks":[{"price":7.0866,"qty":779.54455028}],"checksum":3371174435,"timestamp":"2024-06-01T22:43:07.298801Z"}]}
{"channel":"book","type":"update","data":[{"symbol":"DOT/USD","bids":[],"asks":[{"price":7.0894,"qty":11.08469532}],"checksum":54118943,"timestamp":"2024-06-01T22:43:10.009739Z"}]}
{"channel":"book","type":"update","data":[{"symbol":"DOT/USD","bids":[],"asks":[{"price":7.0864,"qty":705.72464506}],"checksum":660927853,"timestamp":"2024-06-01T22:43:10.178168Z"}]}
{"channel":"book","type":"update","data":[{"symbol":"DOT/USD","bids":[],"asks":[{"price":7.0887,"qty":2.54372019}],"checksum":4077165054,"timestamp":"2024-06-01T22:43:11.280467Z"}]}
{"channel":"book","type":"update","data":[{"symbol":"DOT/USD","bids":[],"asks":[{"price":7.0886,"qty":2.54372019}],"checksum":1948393390,"timestamp":"2024-06-01T22:43:11.281051Z"}]}
{"channel":"book","type":"update","data":[{"symbol":"DOT/USD","bids":[{"price":7.0815,"qty":0.00000000},{"price":7.0811,"qty":2.54372019}],"asks":[],"checksum":4104496132,"timestamp":"2024-06-01T22:43:11.281696Z"}]}
{"channel":"book","type":"update","data":[{"symbol":"DOT/USD","bids":[],"asks":[{"price":7.0882,"qty":0.00000000},{"price":7.0894,"qty":11.08469532}],"checksum":858900142,"timestamp":"2024-06-01T22:43:11.282634Z"}]}
{"channel":"book","type":"update","data":[{"symbol":"DOT/USD","bids":[],"asks":[{"price":7.0887,"qty":0.00000000},{"price":7.0895,"qty":351.84433103}],"checksum":4263385854,"timestamp":"2024-06-01T22:43:11.282792Z"}]}
{"channel":"book","type":"update","data":[{"symbol":"DOT/USD","bids":[],"asks":[{"price":7.0886,"qty":0.00000000},{"price":7.0896,"qty":2267.91934069}],"checksum":4106240600,"timestamp":"2024-06-01T22:43:11.283721Z"}]}
{"channel":"book","type":"update","data":[{"symbol":"DOT/USD","bids":[],"asks":[{"price":7.0896,"qty":0.00000000},{"price":7.0898,"qty":92.39000000}],"checksum":2386194968,"timestamp":"2024-06-01T22:43:11.285582Z"}]}
{"channel":"book","type":"update","data":[{"symbol":"DOT/USD","bids":[{"price":7.0835,"qty":4.37636761}],"asks":[],"checksum":3161184425,"timestamp":"2024-06-01T22:43:11.285781Z"}]}
{"channel":"book","type":"update","data":[{"symbol":"DOT/USD","bids":[{"price":7.0833,"qty":28.22572183}],"asks":[],"checksum":3014413718,"timestamp":"2024-06-01T22:43:11.286541Z"}]}
{"channel":"book","type":"update","data":[{"symbol":"DOT/USD","bids":[{"price":7.0819,"qty":1385.69469696}],"asks":[],"checksum":754087733,"timestamp":"2024-06-01T22:43:11.286601Z"}]}
{"channel":"book","type":"update","data":[{"symbol":"DOT/USD","bids":[],"asks":[{"price":7.0864,"qty":0.00000000},{"price":7.0899,"qty":1.75833579}],"checksum":4243737189,"timestamp":"2024-06-01T22:43:11.287796Z"}]}
{"channel":"book","type":"update","data":[{"symbol":"DOT/USD","bids":[],"asks":[{"price":7.0866,"qty":73.80000000}],"checksum":1408378494,"timestamp":"2024-06-01T22:43:11.288242Z"}]}
{"channel":"book","type":"update","data":[{"symbol":"DOT/USD","bids":[{"price":7.0836,"qty":3602.42322531}],"asks":[],"checksum":917073126,"timestamp":"2024-06-01T22:43:11.289067Z"}]}
{"channel":"book","type":"update","data":[{"symbol":"DOT/USD","bids":[],"asks":[{"price":7.0855,"qty":0.00000000},{"price":7.0900,"qty":4.85599962}],"checksum":3238433748,"timestamp":"2024-06-01T22:43:11.289342Z"}]}
{"channel":"book","type":"update","data":[{"symbol":"DOT/USD","bids":[{"price":7.0829,"qty":2.54372019}],"asks":[],"checksum":3553559446,"timestamp":"2024-06-01T22:43:11.290589Z"}]}
{"channel":"book","type":"update","data":[{"symbol":"DOT/USD","bids":[],"asks":[{"price":7.0880,"qty":216.86609000}],"checksum":3914054541,"timestamp":"2024-06-01T22:43:11.291334Z"}]}
{"channel":"book","type":"update","data":[{"symbol":"DOT/USD","bids":[{"price":7.0826,"qty":321.64683178}],"asks":[],"checksum":2202054275,"timestamp":"2024-06-01T22:43:11.291667Z"}]}
{"channel":"book","type":"update","data":[{"symbol":"DOT/USD","bids":[],"asks":[{"price":7.0866,"qty":0.00000000},{"price":7.0901,"qty":13.18457666}],"checksum":1327144954,"timestamp":"2024-06-01T22:43:11.291772Z"}]}
{"channel":"book","type":"update","data":[{"symbol":"DOT/USD","bids":[],"asks":[{"price":7.0873,"qty":73.80000000}],"checksum":2732685410,"timestamp":"2024-06-01T22:43:11.292226Z"}]}
{"channel":"book","type":"update","data":[{"symbol":"DOT/USD","bids":[{"price":7.0829,"qty":5.08744038}],"asks":[],"checksum":3768566591,"timestamp":"2024-06-01T22:43:11.295966Z"}]}
{"channel":"book","type":"update","data":[{"symbol":"DOT/USD","bids":[],"asks":[{"price":7.0890,"qty":28.97214415}],"checksum":3745892763,"timestamp":"2024-06-01T22:43:11.297650Z"}]}
{"channel":"book","type":"update","data":[{"symbol":"DOT/USD","bids":[],"asks":[{"price":7.0872,"qty":352.74861722}],"checksum":2915488552,"timestamp":"2024-06-01T22:43:11.299608Z"}]}
{"channel":"book","type":"update","data":[{"symbol":"DOT/USD","bids":[{"price":7.0830,"qty":855.64502307}],"asks":[],"checksum":4191074363,"timestamp":"2024-06-01T22:43:11.299689Z"}]}
{"channel":"book","type":"update","data":[{"symbol":"DOT/USD","bids":[{"price":7.0846,"qty":352.87473029}],"asks":[],"checksum":230402734,"timestamp":"2024-06-01T22:43:11.299730Z"}]}
{"channel":"book","type":"update","data":[{"symbol":"DOT/USD","bids":[{"price":7.0837,"qty":28.22278423}],"asks":[],"checksum":3520333091,"timestamp":"2024-06-01T22:43:11.301831Z"}]}
{"channel":"book","type":"update","data":[{"symbol":"DOT/USD","bids":[],"asks":[{"price":7.0875,"qty":705.47578398}],"checksum":3720238443,"timestamp":"2024-06-01T22:43:11.301883Z"}]}
{"channel":"book","type":"update","data":[{"symbol":"DOT/USD","bids":[{"price":7.0831,"qty":0.00000000},{"price":7.0819,"qty":1385.69469696}],"asks":[],"checksum":3810188384,"timestamp":"2024-06-01T22:43:11.302600Z"}]}
{"channel":"book","type":"update","data":[{"symbol":"DOT/USD","bids":[],"asks":[{"price":7.0873,"qty":0.00000000},{"price":7.0899,"qty":1.75833579}],"checksum":4183300095,"timestamp":"2024-06-01T22:43:11.303061Z"}]}
{"channel":"book","type":"update","data":[{"symbol":"DOT/USD","bids":[],"asks":[{"price":7.0870,"qty":73.80000000}],"checksum":394528958,"timestamp":"2024-06-01T22:43:11.303367Z"}]}
{"channel":"book","type":"update","data":[{"symbol":"DOT/USD","bids":[{"price":7.0833,"qty":0.00000000},{"price":7.0816,"qty":5.08744038}],"asks":[],"checksum":2840105764,"timestamp":"2024-06-01T22:43:11.306973Z"}]}
{"channel":"book","type":"update","data":[{"symbol":"DOT/USD","bids":[{"price":7.0830,"qty":705.90777677}],"asks":[],"checksum":2314206523,"timestamp":"2024-06-01T22:43:11.307958Z"}]}
{"channel":"book","type":"update","data":[{"symbol":"DOT/USD","bids":[],"asks":[{"price":7.0872,"qty":0.00000000},{"price":7.0899,"qty":1.75833579}],"checksum":1344955308,"timestamp":"2024-06-01T22:43:11.310401Z"}]}
{"channel":"book","type":"update","data":[{"symbol":"DOT/USD","bids":[{"price":7.0847,"qty":63.48993182}],"asks":[],"checksum":4055864638,"timestamp":"2024-06-01T22:43:11.311151Z"}]}
{"channel":"book","type":"update","data":[{"symbol":"DOT/USD","bids":[],"asks":[{"price":7.0892,"qty":0.00000000},{"price":7.0900,"qty":4.85599962}],"checksum":4091251925,"timestamp":"2024-06-01T22:43:11.328341Z"}]}
{"channel":"book","type":"update","data":[{"symbol":"DOT/USD","bids":[{"price":7.0836,"qty":3528.62322531}],"asks":[],"checksum":3016205396,"timestamp":"2024-06-01T22:43:11.337679Z"}]}
{"channel":"book","type":"update","data":[{"symbol":"DOT/USD","bids":[{"price":7.0847,"qty":137.28993182}],"asks":[],"checksum":1173811187,"timestamp":"2024-06-01T22:43:11.337829Z"}]}
{"channel":"book","type":"update","data":[{"symbol":"DOT/USD","bids":[],"asks":[{"price":7.0893,"qty":706.91760783}],"checksum":288046715,"timestamp":"2024-06-01T22:43:11.348421Z"}]}
{"channel":"book","type":"update","data":[{"symbol":"DOT/USD","bids":[],"asks":[{"price":7.0897,"qty":705.72464506}],"checksum":3960576228,"timestamp":"2024-06-01T22:43:11.349222Z"}]}
{"channel":"book","type":"update","data":[{"symbol":"DOT/USD","bids":[{"price":7.0829,"qty":32.98744038}],"asks":[],"checksum":554216625,"timestamp":"2024-06-01T22:43:11.349775Z"}]}
{"channel":"book","type":"update","data":[{"symbol":"DOT/USD","bids":[],"asks":[{"price":7.0870,"qty":0.00000000},{"price":7.0900,"qty":4.85599962}],"checksum":1750358904,"timestamp":"2024-06-01T22:43:11.375319Z"}]}
{"channel":"book","type":"update","data":[{"symbol":"DOT/USD","bids":[],"asks":[{"price":7.0874,"qty":73.80000000}],"checksum":4108283617,"timestamp":"2024-06-01T22:43:11.375635Z"}]}
{"channel":"book","type":"update","data":[{"symbol":"DOT/USD","bids":[{"price":7.0839,"qty":2.54372019}],"asks":[],"checksum":2879512390,"timestamp":"2024-06-01T22:43:11.379740Z"}]}
{"channel":"book","type":"update","data":[{"symbol":"DOT/USD","bids":[{"price":7.0836,"qty":3850.27005709}],"asks":[],"checksum":515013581,"timestamp":"2024-06-01T22:43:11.379830Z"}]}
{"channel":"book","type":"update","data":[{"symbol":"DOT/USD","bids":[],"asks":[{"price":7.0873,"qty":40.00000000}],"checksum":2435737821,"timestamp":"2024-06-01T22:43:11.380530Z"}]}
{"channel":"book","type":"update","data":[{"symbol":"DOT/USD","bids":[{"price":7.0839,"qty":30.76480047}],"asks":[],"checksum":926088393,"timestamp":"2024-06-01T22:43:11.384697Z"}]}
{"channel":"book","type":"update","data":[{"symbol":"DOT/USD","bids":[{"price":7.0839,"qty":33.30852066}],"asks":[],"checksum":4086936858,"timestamp":"2024-06-01T22:43:11.384934Z"}]}
{"channel":"book","type":"update","data":[{"symbol":"DOT/USD","bids":[],"asks":[{"price":7.0893,"qty":1.19296277}],"checksum":534292080,"timestamp":"2024-06-01T22:43:11.394835Z"}]}
{"channel":"book","type":"update","data":[{"symbol":"DOT/USD","bids":[],"asks":[{"price":7.0875,"qty":0.00000000},{"price":7.0899,"qty":1.75833579}],"checksum":2497897196,"timestamp":"2024-06-01T22:43:11.459051Z"}]}
{"channel":"book","type":"update","data":[{"symbol":"DOT/USD","bids":[],"asks":[{"price":7.0874,"qty":0.00000000},{"price":7.0900,"qty":4.85599962}],"checksum":2037714949,"timestamp":"2024-06-01T22:43:11.462241Z"}]}
{"channel":"book","type":"update","data":[{"symbol":"DOT/USD","bids":[],"asks":[{"price":7.0878,"qty":73.80000000}],"checksum":2817088550,"timestamp":"2024-06-01T22:43:11.462294Z"}]}
{"channel":"book","type":"update","data":[{"symbol":"DOT/USD","bids":[],"asks":[{"price":7.0873,"qty":0.00000000},{"price":7.0900,"qty":4.85599962}],"checksum":1717935304,"timestamp":"2024-06-01T22:43:11.463299Z"}]}
{"channel":"book","type":"update","data":[{"symbol":"DOT/USD","bids":[{"price":7.0826,"qty":0.00000000},{"price":7.0819,"qty":1385.69469696}],"asks":[],"checksum":3984570546,"timestamp":"2024-06-01T22:43:11.463411Z"}]}
{"channel":"book","type":"update","data":[{"symbol":"DOT/USD","bids":[],"asks":[{"price":7.0884,"qty":705.37810318}],"checksum":1860293837,"timestamp":"2024-06-01T22:43:11.463746Z"}]}
{"channel":"book","type":"update","data":[{"symbol":"DOT/USD","bids":[{"price":7.0829,"qty":30.44372019}],"asks":[],"checksum":3865234692,"timestamp":"2024-06-01T22:43:11.465165Z"}]}
