{"channel":"book","type":"snapshot","data":[{"symbol":"ETH/CAD","bids":[{"price":5220.50,"qty":0.06634500},{"price":5220.49,"qty":0.90311190},{"price":5220.48,"qty":0.80016485},{"price":5220.47,"qty":0.85630509},{"price":5219.64,"qty":3.83766124},{"price":5216.49,"qty":0.11300000},{"price":5216.31,"qty":1.30800000},{"price":5216.30,"qty":3.58837415},{"price":5216.24,"qty":0.92000000},{"price":5214.52,"qty":1.84146195}],"asks":[{"price":5223.54,"qty":0.31441188},{"price":5223.55,"qty":0.09983515},{"price":5223.81,"qty":0.01561100},{"price":5224.47,"qty":0.90311190},{"price":5224.99,"qty":0.52358152},{"price":5225.00,"qty":1.50000000},{"price":5226.22,"qty":1.84146195},{"price":5226.56,"qty":0.11100000},{"price":5228.40,"qty":1.53790165},{"price":5228.41,"qty":17.46370412}],"checksum":409075126}]}
{"channel":"book","type":"update","data":[{"symbol":"ETH/CAD","bids":[{"price":5220.47,"qty":0.00000000},{"price":5214.12,"qty":1.92000000},{"price":5220.51,"qty":0.85629845}],"asks":[],"checksum":749306863,"timestamp":"2024-06-01T22:42:31.853579Z"}]}
{"channel":"book","type":"update","data":[{"symbol":"ETH/CAD","bids":[{"price":5216.30,"qty":0.00000000},{"price":5214.12,"qty":1.92000000}],"asks":[],"checksum":435398920,"timestamp":"2024-06-01T22:42:31.956421Z"}]}
{"channel":"book","type":"update","data":[{"symbol":"ETH/CAD","bids":[{"price":5216.32,"qty":3.07757538}],"asks":[],"checksum":1407398265,"timestamp":"2024-06-01T22:42:31.956966Z"}]}
{"channel":"book","type":"update","data":[{"symbol":"ETH/CAD","bids":[{"price":5216.31,"qty":0.00000000},{"price":5214.12,"qty":1.92000000},{"price":5216.25,"qty":1.30800000}],"asks":[],"checksum":502434779,"timestamp":"2024-06-01T22:42:31.959895Z"}]}
{"channel":"book","type":"update","data":[{"symbol":"ETH/CAD","bids":[{"price":5220.48,"qty":0.00000000},{"price":5214.12,"qty":1.92000000},{"price":5220.52,"qty":0.80016485}],"asks":[],"checksum":563803848,"timestamp":"2024-06-01T22:42:31.991881Z"}]}
{"channel":"book","type":"update","data":[{"symbol":"ETH/CAD","bids":[],"asks":[{"price":5228.39,"qty":0.05131782}],"checksum":3249749926,"timestamp":"2024-06-01T22:42:32.098301Z"}]}
{"channel":"book","type":"update","data":[{"symbol":"ETH/CAD","bids":[],"asks":[{"price":5228.40,"qty":1.30800000}],"checksum":3395124516,"timestamp":"2024-06-01T22:42:32.123356Z"}]}
{"channel":"book","type":"update","data":[{"symbol":"ETH/CAD","bids":[],"asks":[{"price":5228.38,"qty":0.22990165}],"checksum":529663781,"timestamp":"2024-06-01T22:42:32.123593Z"}]}
{"channel":"book","type":"update","data":[{"symbol":"ETH/CAD","bids":[{"price":5220.51,"qty":0.00000000},{"price":5214.12,"qty":1.92000000},{"price":5220.53,"qty":0.85629517}],"asks":[],"checksum":2630938848,"timestamp":"2024-06-01T22:42:32.506470Z"}]}
{"channel":"book","type":"update","data":[{"symbol":"ETH/CAD","bids":[{"price":5216.25,"qty":0.00000000},{"price":5214.12,"qty":1.92000000},{"price":5216.33,"qty":1.30800000}],"asks":[],"checksum":4209041446,"timestamp":"2024-06-01T22:42:32.509514Z"}]}
{"channel":"book","type":"update","data":[{"symbol":"ETH/CAD","bids":[{"price":5220.54,"qty":0.90311190}],"asks":[],"checksum":1688611311,"timestamp":"2024-06-01T22:42:32.512079Z"}]}
{"channel":"book","type":"update","data":[{"symbol":"ETH/CAD","bids":[{"price":5220.52,"qty":0.00000000},{"price":5214.52,"qty":1.84146195},{"price":5220.55,"qty":0.80016485}],"asks":[],"checksum":1946785437,"timestamp":"2024-06-01T22:42:32.540903Z"}]}
{"channel":"book","type":"update","data":[{"symbol":"ETH/CAD","bids":[{"price":5220.49,"qty":0.00000000},{"price":5214.52,"qty":1.84146195}],"asks":[],"checksum":3849106092,"timestamp":"2024-06-01T22:42:32.547416Z"}]}
{"channel":"book","type":"update","data":[{"symbol":"ETH/CAD","bids":[],"asks":[{"price":5224.99,"qty":0.00000000},{"price":5228.40,"qty":1.30800000}],"checksum":1696860965,"timestamp":"2024-06-01T22:42:32.601606Z"}]}
{"channel":"book","type":"update","data":[{"symbol":"ETH/CAD","bids":[],"asks":[{"price":5228.40,"qty":0.00000000},{"price":5228.78,"qty":1.04000000},{"price":5228.77,"qty":1.30800000}],"checksum":4172153926,"timestamp":"2024-06-01T22:42:32.605473Z"}]}
{"channel":"book","type":"update","data":[{"symbol":"ETH/CAD","bids":[],"asks":[{"price":5224.46,"qty":0.52358152}],"checksum":727861627,"timestamp":"2024-06-01T22:42:32.606569Z"}]}
{"channel":"book","type":"update","data":[{"symbol":"ETH/CAD","bids":[],"asks":[{"price":5228.37,"qty":20.45748197}],"checksum":3922094214,"timestamp":"2024-06-01T22:42:32.606640Z"}]}
{"channel":"book","type":"update","data":[{"symbol":"ETH/CAD","bids":[],"asks":[{"price":5228.36,"qty":0.22990165}],"checksum":2256752109,"timestamp":"2024-06-01T22:42:32.612315Z"}]}
{"channel":"book","type":"update","data":[{"symbol":"ETH/CAD","bids":[{"price":5220.53,"qty":0.00000000},{"price":5214.12,"qty":1.92000000},{"price":5220.56,"qty":0.85629270}],"asks":[],"checksum":3886229613,"timestamp":"2024-06-01T22:42:33.123057Z"}]}
{"channel":"book","type":"update","data":[{"symbol":"ETH/CAD","bids":[],"asks":[{"price":5228.36,"qty":1.53790165}],"checksum":1875793570,"timestamp":"2024-06-01T22:42:33.125925Z"}]}
{"channel":"book","type":"update","data":[{"symbol":"ETH/CAD","bids":[{"price":5220.55,"qty":0.00000000},{"price":5214.12,"qty":1.92000000},{"price":5220.57,"qty":0.80016485}],"asks":[],"checksum":2131279927,"timestamp":"2024-06-01T22:42:33.452999Z"}]}
{"channel":"book","type":"update","data":[{"symbol":"ETH/CAD","bids":[{"price":5220.58,"qty":0.90311190}],"asks":[],"checksum":2582660349,"timestamp":"2024-06-01T22:42:33.458126Z"}]}
{"channel":"book","type":"update","data":[{"symbol":"ETH/CAD","bids":[],"asks":[{"price":5223.55,"qty":0.00000000},{"price":5228.39,"qty":0.05131782},{"price":5223.53,"qty":0.09983515}],"checksum":547971824,"timestamp":"2024-06-01T22:42:33.484633Z"}]}
{"channel":"book","type":"update","data":[{"symbol":"ETH/CAD","bids":[{"price":5220.54,"qty":0.00000000},{"price":5214.52,"qty":1.84146195}],"asks":[],"checksum":4228267987,"timestamp":"2024-06-01T22:42:33.489541Z"}]}
{"channel":"book","type":"update","data":[{"symbol":"ETH/CAD","bids":[{"price":5220.56,"qty":0.00000000},{"price":5214.12,"qty":1.92000000},{"price":5220.59,"qty":0.85628847}],"asks":[],"checksum":3785485407,"timestamp":"2024-06-01T22:42:33.772659Z"}]}
{"channel":"book","type":"update","data":[{"symbol":"ETH/CAD","bids":[],"asks":[{"price":5223.54,"qty":0.00000000},{"price":5228.39,"qty":0.05131782},{"price":5223.52,"qty":0.31441065}],"checksum":184432556,"timestamp":"2024-06-01T22:42:33.772704Z"}]}
{"channel":"book","type":"update","data":[{"symbol":"ETH/CAD","bids":[{"price":5220.60,"qty":0.90311190}],"asks":[],"checksum":4239023103,"timestamp":"2024-06-01T22:42:33.778348Z"}]}
{"channel":"book","type":"update","data":[{"symbol":"ETH/CAD","bids":[{"price":5220.57,"qty":0.00000000},{"price":5214.52,"qty":1.84146195},{"price":5220.61,"qty":0.80016485}],"asks":[],"checksum":1342408459,"timestamp":"2024-06-01T22:42:34.092508Z"}]}
{"channel":"book","type":"update","data":[{"symbol":"ETH/CAD","bids":[{"price":5220.58,"qty":0.00000000},{"price":5214.52,"qty":1.84146195}],"asks":[],"checksum":1382085757,"timestamp":"2024-06-01T22:42:34.097984Z"}]}
{"channel":"book","type":"update","data":[{"symbol":"ETH/CAD","bids":[{"price":5220.59,"qty":0.00000000},{"price":5214.12,"qty":1.92000000},{"price":5220.62,"qty":0.85628363}],"asks":[],"checksum":195625553,"timestamp":"2024-06-01T22:42:34.403800Z"}]}
{"channel":"book","type":"update","data":[{"symbol":"ETH/CAD","bids":[{"price":5220.63,"qty":0.90311190}],"asks":[],"checksum":4180735637,"timestamp":"2024-06-01T22:42:34.409313Z"}]}
{"channel":"book","type":"update","data":[{"symbol":"ETH/CAD","bids":[{"price":5220.60,"qty":0.00000000},{"price":5214.52,"qty":1.84146195}],"asks":[],"checksum":2502027049,"timestamp":"2024-06-01T22:42:34.678868Z"}]}
{"channel":"book","type":"update","data":[{"symbol":"ETH/CAD","bids":[{"price":5220.61,"qty":0.00000000},{"price":5214.12,"qty":1.92000000},{"price":5220.64,"qty":0.80016485}],"asks":[],"checksum":387421214,"timestamp":"2024-06-01T22:42:34.701689Z"}]}
{"channel":"book","type":"update","data":[{"symbol":"ETH/CAD","bids":[{"price":5216.32,"qty":0.00000000},{"price":5214.12,"qty":1.92000000}],"asks":[],"checksum":1986917735,"timestamp":"2024-06-01T22:42:34.824321Z"}]}
{"channel":"book","type":"update","data":[{"symbol":"ETH/CAD","bids":[{"price":5216.33,"qty":0.00000000},{"price":5213.48,"qty":1.25586241},{"price":5216.25,"qty":1.30800000}],"asks":[],"checksum":1370731459,"timestamp":"2024-06-01T22:42:34.827492Z"}]}
{"channel":"book","type":"update","data":[{"symbol":"ETH/CAD","bids":[],"asks":[{"price":5228.35,"qty":0.05131782}],"checksum":1883601072,"timestamp":"2024-06-01T22:42:34.830316Z"}]}
{"channel":"book","type":"update","data":[{"symbol":"ETH/CAD","bids":[],"asks":[{"price":5228.34,"qty":0.22990165}],"checksum":3661564987,"timestamp":"2024-06-01T22:42:34.855118Z"}]}
{"channel":"book","type":"update","data":[{"symbol":"ETH/CAD","bids":[],"asks":[{"price":5224.46,"qty":0.00000000},{"price":5228.36,"qty":1.30800000}],"checksum":3108838261,"timestamp":"2024-06-01T22:42:34.875636Z"}]}
{"channel":"book","type":"update","data":[{"symbol":"ETH/CAD","bids":[],"asks":[{"price":5228.36,"qty":0.00000000},{"price":5228.78,"qty":1.04000000},{"price":5228.77,"qty":1.30800000}],"checksum":673650858,"timestamp":"2024-06-01T22:42:34.879549Z"}]}
{"channel":"book","type":"update","data":[{"symbol":"ETH/CAD","bids":[],"asks":[{"price":5228.35,"qty":19.53549239}],"checksum":3938006620,"timestamp":"2024-06-01T22:42:34.880790Z"}]}
{"channel":"book","type":"update","data":[{"symbol":"ETH/CAD","bids":[{"price":5220.62,"qty":0.00000000},{"price":5213.48,"qty":1.25586241},{"price":5220.65,"qty":0.85627866}],"asks":[],"checksum":4248136238,"timestamp":"2024-06-01T22:42:35.049845Z"}]}
{"channel":"book","type":"update","data":[{"symbol":"ETH/CAD","bids":[{"price":5220.64,"qty":0.00000000},{"price":5213.48,"qty":1.25586241},{"price":5220.66,"qty":0.80016485}],"asks":[],"checksum":769755951,"timestamp":"2024-06-01T22:42:35.068908Z"}]}
{"channel":"book","type":"update","data":[{"symbol":"ETH/CAD","bids":[{"price":5220.65,"qty":0.00000000},{"price":5213.48,"qty":1.25586241},{"price":5220.67,"qty":0.85627540}],"asks":[],"checksum":1351319054,"timestamp":"2024-06-01T22:42:35.667606Z"}]}
{"channel":"book","type":"update","data":[{"symbol":"ETH/CAD","bids":[],"asks":[{"price":5228.77,"qty":0.00000000},{"price":5228.78,"qty":1.04000000},{"price":5228.34,"qty":1.53790165}],"checksum":3493376392,"timestamp":"2024-06-01T22:42:35.670623Z"}]}
{"channel":"book","type":"update","data":[{"symbol":"ETH/CAD","bids":[{"price":5220.68,"qty":0.90311190}],"asks":[],"checksum":2369251969,"timestamp":"2024-06-01T22:42:35.673360Z"}]}
{"channel":"book","type":"update","data":[{"symbol":"ETH/CAD","bids":[{"price":5220.66,"qty":0.00000000},{"price":5214.12,"qty":1.92000000},{"price":5220.68,"qty":1.70327675}],"asks":[],"checksum":159588370,"timestamp":"2024-06-01T22:42:35.678008Z"}]}
{"channel":"book","type":"update","data":[{"symbol":"ETH/CAD","bids":[{"price":5220.68,"qty":0.90311190},{"price":5220.69,"qty":0.80016485}],"asks":[],"checksum":2225703118,"timestamp":"2024-06-01T22:42:36.011777Z"}]}
{"channel":"book","type":"update","data":[{"symbol":"ETH/CAD","bids":[{"price":5220.63,"qty":0.00000000},{"price":5214.12,"qty":1.92000000}],"asks":[],"checksum":1405307728,"timestamp":"2024-06-01T22:42:36.016984Z"}]}
{"channel":"book","type":"update","data":[{"symbol":"ETH/CAD","bids":[{"price":5220.67,"qty":0.00000000},{"price":5213.48,"qty":1.25586241},{"price":5220.70,"qty":0.85627049}],"asks":[],"checksum":1560647023,"timestamp":"2024-06-01T22:42:36.252219Z"}]}
{"channel":"book","type":"update","data":[{"symbol":"ETH/CAD","bids":[{"price":5220.71,"qty":0.90311190}],"asks":[],"checksum":1450662794,"timestamp":"2024-06-01T22:42:36.257759Z"}]}
{"channel":"book","type":"update","data":[{"symbol":"ETH/CAD","bids":[{"price":5220.68,"qty":0.00000000},{"price":5214.12,"qty":1.92000000}],"asks":[],"checksum":3596349784,"timestamp":"2024-06-01T22:42:36.676738Z"}]}
{"channel":"book","type":"update","data":[{"symbol":"ETH/CAD","bids":[{"price":5220.70,"qty":0.00000000},{"price":5213.48,"qty":1.25586241},{"price":5220.72,"qty":0.85627076}],"asks":[],"checksum":4064009365,"timestamp":"2024-06-01T22:42:36.874582Z"}]}
{"channel":"book","type":"update","data":[{"symbol":"ETH/CAD","bids":[{"price":5220.73,"qty":0.90311190}],"asks":[],"checksum":3671087742,"timestamp":"2024-06-01T22:42:36.879803Z"}]}
{"channel":"book","type":"update","data":[{"symbol":"ETH/CAD","bids":[{"price":5220.69,"qty":0.00000000},{"price":5214.12,"qty":1.92000000},{"price":5220.74,"qty":0.80016485}],"asks":[],"checksum":1263465812,"timestamp":"2024-06-01T22:42:36.896018Z"}]}
{"channel":"book","type":"update","data":[{"symbol":"ETH/CAD","bids":[],"asks":[{"price":5228.35,"qty":0.05131782}],"checksum":2635547282,"timestamp":"2024-06-01T22:42:37.113428Z"}]}
{"channel":"book","type":"update","data":[{"symbol":"ETH/CAD","bids":[],"asks":[{"price":5228.34,"qty":0.22990165},{"price":5228.77,"qty":1.30800000}],"checksum":3560434045,"timestamp":"2024-06-01T22:42:37.116630Z"}]}
{"channel":"book","type":"update","data":[{"symbol":"ETH/CAD","bids":[],"asks":[{"price":5224.99,"qty":0.52358152}],"checksum":3241967193,"timestamp":"2024-06-01T22:42:37.118794Z"}]}
{"channel":"book","type":"update","data":[{"symbol":"ETH/CAD","bids":[],"asks":[{"price":5228.33,"qty":16.96474115}],"checksum":2045611237,"timestamp":"2024-06-01T22:42:37.118930Z"}]}
{"channel":"book","type":"update","data":[{"symbol":"ETH/CAD","bids":[{"price":5220.71,"qty":0.00000000},{"price":5214.12,"qty":1.92000000}],"asks":[],"checksum":4014689984,"timestamp":"2024-06-01T22:42:37.124416Z"}]}
{"channel":"book","type":"update","data":[{"symbol":"ETH/CAD","bids":[],"asks":[{"price":5228.32,"qty":0.22990165}],"checksum":3086691581,"timestamp":"2024-06-01T22:42:37.133478Z"}]}
{"channel":"book","type":"update","data":[{"symbol":"ETH/CAD","bids":[],"asks":[{"price":5223.53,"qty":0.00000000},{"price":5228.35,"qty":0.05131782},{"price":5223.51,"qty":0.09983515}],"checksum":2054585948,"timestamp":"2024-06-01T22:42:37.140540Z"}]}
{"channel":"book","type":"update","data":[{"symbol":"ETH/CAD","bids":[{"price":5220.72,"qty":0.00000000},{"price":5213.48,"qty":1.25586241},{"price":5220.75,"qty":0.85626534}],"asks":[],"checksum":358451866,"timestamp":"2024-06-01T22:42:37.423751Z"}]}
{"channel":"book","type":"update","data":[{"symbol":"ETH/CAD","bids":[],"asks":[{"price":5223.52,"qty":0.00000000},{"price":5228.35,"qty":0.05131782},{"price":5223.50,"qty":0.31438236}],"checksum":1391634427,"timestamp":"2024-06-01T22:42:37.423959Z"}]}
{"channel":"book","type":"update","data":[{"symbol":"ETH/CAD","bids":[{"price":5220.76,"qty":0.90311190}],"asks":[],"checksum":1250102739,"timestamp":"2024-06-01T22:42:37.429588Z"}]}
{"channel":"book","type":"update","data":[{"symbol":"ETH/CAD","bids":[],"asks":[{"price":5228.31,"qty":0.05131782}],"checksum":3524480983,"timestamp":"2024-06-01T22:42:37.610952Z"}]}
{"channel":"book","type":"update","data":[{"symbol":"ETH/CAD","bids":[{"price":5220.74,"qty":0.00000000},{"price":5214.12,"qty":1.92000000},{"price":5220.77,"qty":0.80016485}],"asks":[],"checksum":3728797943,"timestamp":"2024-06-01T22:42:37.627267Z"}]}
{"channel":"book","type":"update","data":[{"symbol":"ETH/CAD","bids":[],"asks":[{"price":5228.32,"qty":1.53790165}],"checksum":3784898774,"timestamp":"2024-06-01T22:42:37.630414Z"}]}
{"channel":"book","type":"update","data":[{"symbol":"ETH/CAD","bids":[{"price":5220.73,"qty":0.00000000},{"price":5214.12,"qty":1.92000000}],"asks":[],"checksum":897533799,"timestamp":"2024-06-01T22:42:37.632851Z"}]}
{"channel":"book","type":"update","data":[{"symbol":"ETH/CAD","bids":[],"asks":[{"price":5228.32,"qty":1.30800000}],"checksum":1049691621,"timestamp":"2024-06-01T22:42:37.648224Z"}]}
{"channel":"book","type":"update","data":[{"symbol":"ETH/CAD","bids":[],"asks":[{"price":5228.30,"qty":0.22990165}],"checksum":414376267,"timestamp":"2024-06-01T22:42:37.648542Z"}]}
{"channel":"book","type":"update","data":[{"symbol":"ETH/CAD","bids":[{"price":5220.75,"qty":0.00000000},{"price":5213.48,"qty":1.25586241},{"price":5220.78,"qty":0.85626027}],"asks":[],"checksum":1841480411,"timestamp":"2024-06-01T22:42:38.027250Z"}]}
{"channel":"book","type":"update","data":[{"symbol":"ETH/CAD","bids":[{"price":5219.64,"qty":0.00000000},{"price":5213.48,"qty":1.25586241}],"asks":[],"checksum":1560714640,"timestamp":"2024-06-01T22:42:38.030326Z"}]}
{"channel":"book","type":"update","data":[{"symbol":"ETH/CAD","bids":[{"price":5219.90,"qty":3.83754935}],"asks":[],"checksum":2748434271,"timestamp":"2024-06-01T22:42:38.033673Z"}]}
{"channel":"book","type":"update","data":[{"symbol":"ETH/CAD","bids":[{"price":5220.77,"qty":0.00000000},{"price":5213.48,"qty":1.25586241},{"price":5220.79,"qty":0.80016485}],"asks":[],"checksum":1096712613,"timestamp":"2024-06-01T22:42:38.360721Z"}]}
{"channel":"book","type":"update","data":[{"symbol":"ETH/CAD","bids":[{"price":5220.80,"qty":0.90311190}],"asks":[],"checksum":1758197813,"timestamp":"2024-06-01T22:42:38.366118Z"}]}
{"channel":"book","type":"update","data":[{"symbol":"ETH/CAD","bids":[{"price":5220.78,"qty":0.00000000},{"price":5214.12,"qty":1.92000000},{"price":5220.81,"qty":0.85625602}],"asks":[],"checksum":1094182019,"timestamp":"2024-06-01T22:42:38.628228Z"}]}
{"channel":"book","type":"update","data":[{"symbol":"ETH/CAD","bids":[{"price":5220.76,"qty":0.00000000},{"price":5214.12,"qty":1.92000000}],"asks":[],"checksum":150672324,"timestamp":"2024-06-01T22:42:38.633620Z"}]}
{"channel":"book","type":"update","data":[{"symbol":"ETH/CAD","bids":[{"price":5220.79,"qty":0.00000000},{"price":5213.48,"qty":1.25586241},{"price":5220.82,"qty":0.80016485}],"asks":[],"checksum":3259479827,"timestamp":"2024-06-01T22:42:38.993670Z"}]}
{"channel":"book","type":"update","data":[{"symbol":"ETH/CAD","bids":[{"price":5220.81,"qty":0.00000000},{"price":5213.48,"qty":1.25586241},{"price":5220.83,"qty":0.85625372}],"asks":[],"checksum":3797191167,"timestamp":"2024-06-01T22:42:39.259501Z"}]}
{"channel":"book","type":"update","data":[{"symbol":"ETH/CAD","bids":[{"price":5220.84,"qty":0.90311190}],"asks":[],"checksum":721557202,"timestamp":"2024-06-01T22:42:39.265243Z"}]}
{"channel":"book","type":"update","data":[{"symbol":"ETH/CAD","bids":[],"asks":[{"price":5228.29,"qty":16.96474115}],"checksum":470576135,"timestamp":"2024-06-01T22:42:39.382654Z"}]}
{"channel":"book","type":"update","data":[{"symbol":"ETH/CAD","bids":[],"asks":[{"price":5228.30,"qty":0.00000000},{"price":5228.31,"qty":0.05131782}],"checksum":2517446431,"timestamp":"2024-06-01T22:42:39.387635Z"}]}
{"channel":"book","type":"update","data":[{"symbol":"ETH/CAD","bids":[],"asks":[{"price":5228.28,"qty":0.22990165}],"checksum":2156434209,"timestamp":"2024-06-01T22:42:39.387897Z"}]}
{"channel":"book","type":"update","data":[{"symbol":"ETH/CAD","bids":[{"price":5220.80,"qty":0.00000000},{"price":5214.12,"qty":1.92000000}],"asks":[],"checksum":391123204,"timestamp":"2024-06-01T22:42:39.678576Z"}]}
{"channel":"book","type":"update","data":[{"symbol":"ETH/CAD","bids":[{"price":5220.83,"qty":0.00000000},{"price":5213.48,"qty":1.25586241},{"price":5220.85,"qty":0.85625052}],"asks":[],"checksum":1991516809,"timestamp":"2024-06-01T22:42:39.855516Z"}]}
{"channel":"book","type":"update","data":[{"symbol":"ETH/CAD","bids":[{"price":5220.86,"qty":0.90311190}],"asks":[],"checksum":2175581766,"timestamp":"2024-06-01T22:42:39.860926Z"}]}
{"channel":"book","type":"update","data":[{"symbol":"ETH/CAD","bids":[{"price":5220.82,"qty":0.00000000},{"price":5214.12,"qty":1.92000000},{"price":5220.87,"qty":0.80016485}],"asks":[],"checksum":2101424680,"timestamp":"2024-06-01T22:42:39.877898Z"}]}
{"channel":"book","type":"update","data":[{"symbol":"ETH/CAD","bids":[{"price":5220.84,"qty":0.00000000},{"price":5214.12,"qty":1.92000000}],"asks":[],"checksum":2760465291,"timestamp":"2024-06-01T22:42:40.178599Z"}]}
{"channel":"book","type":"update","data":[{"symbol":"ETH/CAD","bids":[],"asks":[{"price":5228.28,"qty":1.53790165}],"checksum":274844048,"timestamp":"2024-06-01T22:42:40.181410Z"}]}
{"channel":"book","type":"update","data":[{"symbol":"ETH/CAD","bids":[{"price":5220.88,"qty":0.90311190}],"asks":[],"checksum":2526201907,"timestamp":"2024-06-01T22:42:40.183290Z"}]}
{"channel":"book","type":"update","data":[{"symbol":"ETH/CAD","bids":[{"price":5220.87,"qty":0.00000000},{"price":5214.12,"qty":1.92000000},{"price":5220.89,"qty":0.80016485}],"asks":[],"checksum":3330812775,"timestamp":"2024-06-01T22:42:40.213731Z"}]}
{"channel":"book","type":"update","data":[{"symbol":"ETH/CAD","bids":[{"price":5220.86,"qty":0.00000000},{"price":5214.12,"qty":1.92000000}],"asks":[],"checksum":2817670120,"timestamp":"2024-06-01T22:42:40.219290Z"}]}
{"channel":"book","type":"update","data":[{"symbol":"ETH/CAD","bids":[{"price":5220.85,"qty":0.00000000},{"price":5213.48,"qty":1.25586241},{"price":5220.90,"qty":0.85623948}],"asks":[],"checksum":2494372662,"timestamp":"2024-06-01T22:42:40.386667Z"}]}
{"channel":"book","type":"update","data":[{"symbol":"ETH/CAD","bids":[],"asks":[{"price":5228.27,"qty":0.05131782}],"checksum":3771715892,"timestamp":"2024-06-01T22:42:40.394024Z"}]}
{"channel":"book","type":"update","data":[{"symbol":"ETH/CAD","bids":[],"asks":[{"price":5228.26,"qty":0.22990165}],"checksum":1057200526,"timestamp":"2024-06-01T22:42:40.404751Z"}]}
{"channel":"book","type":"update","data":[{"symbol":"ETH/CAD","bids":[{"price":5216.26,"qty":3.58837415}],"asks":[],"checksum":1566406954,"timestamp":"2024-06-01T22:42:40.540323Z"}]}
{"channel":"book","type":"update","data":[{"symbol":"ETH/CAD","bids":[{"price":5216.25,"qty":0.00000000},{"price":5214.12,"qty":1.92000000},{"price":5216.27,"qty":1.30800000}],"asks":[],"checksum":3658567157,"timestamp":"2024-06-01T22:42:40.543173Z"}]}
{"channel":"book","type":"update","data":[{"symbol":"ETH/CAD","bids":[{"price":5220.89,"qty":0.00000000},{"price":5214.12,"qty":1.92000000},{"price":5220.91,"qty":0.80016485}],"asks":[],"checksum":124384894,"timestamp":"2024-06-01T22:42:40.853591Z"}]}
{"channel":"book","type":"update","data":[{"symbol":"ETH/CAD","bids":[{"price":5220.90,"qty":0.00000000},{"price":5214.12,"qty":1.92000000},{"price":5220.92,"qty":0.85623548}],"asks":[],"checksum":608423202,"timestamp":"2024-06-01T22:42:40.985863Z"}]}
{"channel":"book","type":"update","data":[{"symbol":"ETH/CAD","bids":[{"price":5220.50,"qty":0.00000000},{"price":5214.12,"qty":1.92000000},{"price":5220.92,"qty":0.92257448}],"asks":[],"checksum":553728267,"timestamp":"2024-06-01T22:42:41.028318Z"}]}
{"channel":"book","type":"update","data":[{"symbol":"ETH/CAD","bids":[{"price":5220.91,"qty":0.00000000},{"price":5213.48,"qty":1.25586241},{"price":5220.93,"qty":0.80016485}],"asks":[],"checksum":2888065245,"timestamp":"2024-06-01T22:42:41.342154Z"}]}
{"channel":"book","type":"update","data":[{"symbol":"ETH/CAD","bids":[{"price":5220.94,"qty":0.90311190}],"asks":[],"checksum":4100096298,"timestamp":"2024-06-01T22:42:41.348128Z"}]}
{"channel":"book","type":"update","data":[{"symbol":"ETH/CAD","bids":[{"price":5220.92,"qty":0.06633900},{"price":5220.95,"qty":0.85623032}],"asks":[],"checksum":3687933120,"timestamp":"2024-06-01T22:42:41.495745Z"}]}
{"channel":"book","type":"update","data":[{"symbol":"ETH/CAD","bids":[{"price":5220.88,"qty":0.00000000},{"price":5214.52,"qty":1.84146195}],"asks":[],"checksum":4050328468,"timestamp":"2024-06-01T22:42:41.501311Z"}]}
{"channel":"book","type":"update","data":[{"symbol":"ETH/CAD","bids":[],"asks":[{"price":5228.25,"qty":16.96474115}],"checksum":2678905021,"timestamp":"2024-06-01T22:42:41.645077Z"}]}
{"channel":"book","type":"update","data":[{"symbol":"ETH/CAD","bids":[],"asks":[{"price":5228.26,"qty":0.00000000},{"price":5228.27,"qty":0.05131782}],"checksum":2206756674,"timestamp":"2024-06-01T22:42:41.673392Z"}]}
{"channel":"book","type":"update","data":[{"symbol":"ETH/CAD","bids":[],"asks":[{"price":5228.24,"qty":0.22990165}],"checksum":1364879204,"timestamp":"2024-06-01T22:42:41.673455Z"}]}
{"channel":"book","type":"update","data":[{"symbol":"ETH/CAD","bids":[{"price":5220.93,"qty":0.00000000},{"price":5214.12,"qty":1.92000000},{"price":5220.96,"qty":0.80016485}],"asks":[],"checksum":41753958,"timestamp":"2024-06-01T22:42:41.983677Z"}]}
{"channel":"book","type":"update","data":[{"symbol":"ETH/CAD","bids":[{"price":5220.95,"qty":0.00000000},{"price":5214.12,"qty":1.92000000},{"price":5220.97,"qty":0.85622696}],"asks":[],"checksum":3553564062,"timestamp":"2024-06-01T22:42:42.079505Z"}]}
{"channel":"book","type":"update","data":[{"symbol":"ETH/CAD","bids":[],"asks":[{"price":5228.24,"qty":1.53790165}],"checksum":2055725954,"timestamp":"2024-06-01T22:42:42.226783Z"}]}
{"channel":"book","type":"update","data":[{"symbol":"ETH/CAD","bids":[],"asks":[{"price":5223.81,"qty":0.00000000},{"price":5228.27,"qty":0.05131782},{"price":5223.50,"qty":0.33000436}],"checksum":915145340,"timestamp":"2024-06-01T22:42:42.425969Z"}]}
{"channel":"book","type":"update","data":[{"symbol":"ETH/CAD","bids":[{"price":5220.98,"qty":0.90311190}],"asks":[],"checksum":23141772,"timestamp":"2024-06-01T22:42:42.431197Z"}]}
{"channel":"book","type":"update","data":[{"symbol":"ETH/CAD","bids":[{"price":5220.97,"qty":0.00000000},{"price":5214.52,"qty":1.84146195},{"price":5220.99,"qty":0.85622404}],"asks":[],"checksum":503926136,"timestamp":"2024-06-01T22:42:42.574621Z"}]}
{"channel":"book","type":"update","data":[{"symbol":"ETH/CAD","bids":[{"price":5220.94,"qty":0.00000000},{"price":5214.52,"qty":1.84146195}],"asks":[],"checksum":4139601916,"timestamp":"2024-06-01T22:42:42.580042Z"}]}
{"channel":"book","type":"update","data":[{"symbol":"ETH/CAD","bids":[{"price":5221.00,"qty":0.90311190}],"asks":[],"checksum":3028159867,"timestamp":"2024-06-01T22:42:42.678488Z"}]}
{"channel":"book","type":"update","data":[{"symbol":"ETH/CAD","bids":[{"price":5220.98,"qty":0.00000000},{"price":5214.52,"qty":1.84146195}],"asks":[],"checksum":801676445,"timestamp":"2024-06-01T22:42:42.682877Z"}]}
{"channel":"book","type":"update","data":[{"symbol":"ETH/CAD","bids":[{"price":5220.96,"qty":0.00000000},{"price":5214.12,"qty":1.92000000},{"price":5221.01,"qty":0.80016485}],"asks":[],"checksum":3960910684,"timestamp":"2024-06-01T22:42:43.019515Z"}]}
{"channel":"book","type":"update","data":[{"symbol":"ETH/CAD","bids":[],"asks":[{"price":5223.51,"qty":0.00000000},{"price":5228.78,"qty":1.04000000},{"price":5223.49,"qty":0.09983515}],"checksum":2250363324,"timestamp":"2024-06-01T22:42:43.051451Z"}]}
{"channel":"book","type":"update","data":[{"symbol":"ETH/CAD","bids":[],"asks":[{"price":5223.50,"qty":0.01562200},{"price":5223.48,"qty":0.31438519}],"checksum":1231360109,"timestamp":"2024-06-01T22:42:43.112263Z"}]}
{"channel":"book","type":"update","data":[{"symbol":"ETH/CAD","bids":[],"asks":[{"price":5228.23,"qty":0.05131782}],"checksum":2396779679,"timestamp":"2024-06-01T22:42:43.192764Z"}]}
{"channel":"book","type":"update","data":[{"symbol":"ETH/CAD","bids":[],"asks":[{"price":5228.24,"qty":1.30800000}],"checksum":2234889757,"timestamp":"2024-06-01T22:42:43.219134Z"}]}
{"channel":"book","type":"update","data":[{"symbol":"ETH/CAD","bids":[],"asks":[{"price":5228.22,"qty":0.22990165}],"checksum":3305485413,"timestamp":"2024-06-01T22:42:43.219335Z"}]}
{"channel":"book","type":"update","data":[{"symbol":"ETH/CAD","bids":[{"price":5216.26,"qty":0.00000000},{"price":5214.12,"qty":1.92000000}],"asks":[],"checksum":593245042,"timestamp":"2024-06-01T22:42:43.401344Z"}]}
{"channel":"book","type":"update","data":[{"symbol":"ETH/CAD","bids":[{"price":5216.28,"qty":3.58837415}],"asks":[],"checksum":3618320364,"timestamp":"2024-06-01T22:42:43.402225Z"}]}
{"channel":"book","type":"update","data":[{"symbol":"ETH/CAD","bids":[{"price":5216.27,"qty":0.00000000},{"price":5214.12,"qty":1.92000000},{"price":5216.25,"qty":1.30800000}],"asks":[],"checksum":1253652670,"timestamp":"2024-06-01T22:42:43.404490Z"}]}
{"channel":"book","type":"update","data":[{"symbol":"ETH/CAD","bids":[{"price":5220.99,"qty":0.00000000},{"price":5214.12,"qty":1.92000000},{"price":5221.02,"qty":0.85621914}],"asks":[],"checksum":3826043314,"timestamp":"2024-06-01T22:42:43.640483Z"}]}
{"channel":"book","type":"update","data":[{"symbol":"ETH/CAD","bids":[{"price":5221.03,"qty":0.90311190}],"asks":[],"checksum":1219203645,"timestamp":"2024-06-01T22:42:43.646274Z"}]}
{"channel":"book","type":"update","data":[{"symbol":"ETH/CAD","bids":[{"price":5221.01,"qty":0.00000000},{"price":5214.52,"qty":1.84146195},{"price":5221.04,"qty":0.80016485}],"asks":[],"checksum":2089468422,"timestamp":"2024-06-01T22:42:43.661853Z"}]}
{"channel":"book","type":"update","data":[{"symbol":"ETH/CAD","bids":[{"price":5221.00,"qty":0.00000000},{"price":5214.52,"qty":1.84146195}],"asks":[],"checksum":2593674883,"timestamp":"2024-06-01T22:42:43.675527Z"}]}
{"channel":"book","type":"update","data":[{"symbol":"ETH/CAD","bids":[],"asks":[{"price":5224.99,"qty":0.00000000},{"price":5228.24,"qty":1.30800000}],"checksum":668292638,"timestamp":"2024-06-01T22:42:43.875110Z"}]}
{"channel":"book","type":"update","data":[{"symbol":"ETH/CAD","bids":[],"asks":[{"price":5228.24,"qty":0.00000000},{"price":5228.78,"qty":1.04000000},{"price":5228.77,"qty":1.30800000}],"checksum":524562842,"timestamp":"2024-06-01T22:42:43.878571Z"}]}
{"channel":"book","type":"update","data":[{"symbol":"ETH/CAD","bids":[],"asks":[{"price":5228.21,"qty":16.96474115}],"checksum":333093096,"timestamp":"2024-06-01T22:42:43.880405Z"}]}
{"channel":"book","type":"update","data":[{"symbol":"ETH/CAD","bids":[],"asks":[{"price":5224.46,"qty":0.52358152}],"checksum":3346655636,"timestamp":"2024-06-01T22:42:43.880468Z"}]}
{"channel":"book","type":"update","data":[{"symbol":"ETH/CAD","bids":[],"asks":[{"price":5228.22,"qty":0.00000000},{"price":5228.23,"qty":0.05131782}],"checksum":3330429767,"timestamp":"2024-06-01T22:42:43.909014Z"}]}
{"channel":"book","type":"update","data":[{"symbol":"ETH/CAD","bids":[],"asks":[{"price":5228.20,"qty":0.22990165}],"checksum":152808538,"timestamp":"2024-06-01T22:42:43.909332Z"}]}
{"channel":"book","type":"update","data":[{"symbol":"ETH/CAD","bids":[{"price":5216.25,"qty":0.00000000},{"price":5214.12,"qty":1.92000000},{"price":5216.29,"qty":1.30800000}],"asks":[],"checksum":3956011193,"timestamp":"2024-06-01T22:42:43.911867Z"}]}
{"channel":"book","type":"update","data":[{"symbol":"ETH/CAD","bids":[{"price":5221.02,"qty":0.00000000},{"price":5214.12,"qty":1.92000000},{"price":5221.05,"qty":0.85621422}],"asks":[],"checksum":411979339,"timestamp":"2024-06-01T22:42:44.176499Z"}]}
{"channel":"book","type":"update","data":[{"symbol":"ETH/CAD","bids":[{"price":5221.06,"qty":0.90311190}],"asks":[],"checksum":3349014014,"timestamp":"2024-06-01T22:42:44.181525Z"}]}
{"channel":"book","type":"update","data":[{"symbol":"ETH/CAD","bids":[{"price":5221.04,"qty":0.00000000},{"price":5214.52,"qty":1.84146195},{"price":5221.07,"qty":0.80016485}],"asks":[],"checksum":2744435887,"timestamp":"2024-06-01T22:42:44.514597Z"}]}
{"channel":"book","type":"update","data":[{"symbol":"ETH/CAD","bids":[],"asks":[{"price":5228.20,"qty":1.53790165}],"checksum":1839747223,"timestamp":"2024-06-01T22:42:44.517893Z"}]}
{"channel":"book","type":"update","data":[{"symbol":"ETH/CAD","bids":[{"price":5221.03,"qty":0.00000000},{"price":5214.52,"qty":1.84146195}],"asks":[],"checksum":3077595407,"timestamp":"2024-06-01T22:42:44.519884Z"}]}
{"channel":"book","type":"update","data":[{"symbol":"ETH/CAD","bids":[{"price":5221.05,"qty":0.00000000},{"price":5214.12,"qty":1.92000000},{"price":5221.08,"qty":0.85620869}],"asks":[],"checksum":1894703903,"timestamp":"2024-06-01T22:42:44.687519Z"}]}
{"channel":"book","type":"update","data":[{"symbol":"ETH/CAD","bids":[{"price":5221.07,"qty":0.00000000},{"price":5214.12,"qty":1.92000000},{"price":5221.09,"qty":0.80016485}],"asks":[],"checksum":1662391512,"timestamp":"2024-06-01T22:42:44.699275Z"}]}
{"channel":"book","type":"update","data":[{"symbol":"ETH/CAD","bids":[{"price":5221.08,"qty":0.00000000},{"price":5214.12,"qty":1.92000000},{"price":5221.10,"qty":0.85620544}],"asks":[],"checksum":3960447395,"timestamp":"2024-06-01T22:42:45.225255Z"}]}
{"channel":"book","type":"update","data":[{"symbol":"ETH/CAD","bids":[{"price":5221.11,"qty":0.90311190}],"asks":[],"checksum":685826826,"timestamp":"2024-06-01T22:42:45.230649Z"}]}
{"channel":"book","type":"update","data":[{"symbol":"ETH/CAD","bids":[{"price":5221.06,"qty":0.00000000},{"price":5214.52,"qty":1.84146195}],"asks":[],"checksum":745893901,"timestamp":"2024-06-01T22:42:45.676772Z"}]}
{"channel":"book","type":"update","data":[{"symbol":"ETH/CAD","bids":[{"price":5221.10,"qty":0.00000000},{"price":5214.12,"qty":1.92000000},{"price":5221.12,"qty":0.85620220}],"asks":[],"checksum":978190710,"timestamp":"2024-06-01T22:42:45.720719Z"}]}
{"channel":"book","type":"update","data":[{"symbol":"ETH/CAD","bids":[{"price":5221.13,"qty":0.90311190}],"asks":[],"checksum":3870655923,"timestamp":"2024-06-01T22:42:45.725938Z"}]}
{"channel":"book","type":"update","data":[{"symbol":"ETH/CAD","bids":[],"asks":[{"price":5228.19,"qty":0.05131782}],"checksum":1080634944,"timestamp":"2024-06-01T22:42:45.958001Z"}]}
{"channel":"book","type":"update","data":[{"symbol":"ETH/CAD","bids":[],"asks":[{"price":5228.20,"qty":1.30800000}],"checksum":1978961295,"timestamp":"2024-06-01T22:42:45.975940Z"}]}
{"channel":"book","type":"update","data":[{"symbol":"ETH/CAD","bids":[],"asks":[{"price":5228.18,"qty":0.22990165}],"checksum":2495137041,"timestamp":"2024-06-01T22:42:45.976132Z"}]}
{"channel":"book","type":"update","data":[{"symbol":"ETH/CAD","bids":[{"price":5221.09,"qty":0.00000000},{"price":5214.52,"qty":1.84146195},{"price":5221.14,"qty":0.80016485}],"asks":[],"checksum":3963720309,"timestamp":"2024-06-01T22:42:45.978210Z"}]}
{"channel":"book","type":"update","data":[{"symbol":"ETH/CAD","bids":[{"price":5221.11,"qty":0.00000000},{"price":5214.52,"qty":1.84146195}],"asks":[],"checksum":3913069389,"timestamp":"2024-06-01T22:42:45.983447Z"}]}
{"channel":"book","type":"update","data":[{"symbol":"ETH/CAD","bids":[],"asks":[{"price":5223.49,"qty":0.00000000},{"price":5228.20,"qty":1.30800000},{"price":5223.47,"qty":0.09983515}],"checksum":3842620879,"timestamp":"2024-06-01T22:42:46.009997Z"}]}
{"channel":"book","type":"update","data":[{"symbol":"ETH/CAD","bids":[],"asks":[{"price":5228.19,"qty":20.00983682}],"checksum":206060141,"timestamp":"2024-06-01T22:42:46.188122Z"}]}
{"channel":"book","type":"update","data":[{"symbol":"ETH/CAD","bids":[],"asks":[{"price":5223.48,"qty":0.00000000},{"price":5228.77,"qty":1.30800000},{"price":5223.46,"qty":0.31438680}],"checksum":3929660612,"timestamp":"2024-06-01T22:42:46.233629Z"}]}
{"channel":"book","type":"update","data":[{"symbol":"ETH/CAD","bids":[{"price":5221.12,"qty":0.00000000},{"price":5214.12,"qty":1.92000000},{"price":5221.15,"qty":0.85619730}],"asks":[],"checksum":3045380426,"timestamp":"2024-06-01T22:42:46.233754Z"}]}
{"channel":"book","type":"update","data":[{"symbol":"ETH/CAD","bids":[{"price":5221.15,"qty":1.75930920}],"asks":[],"checksum":52152061,"timestamp":"2024-06-01T22:42:46.240012Z"}]}
{"channel":"book","type":"update","data":[{"symbol":"ETH/CAD","bids":[{"price":5216.28,"qty":0.00000000},{"price":5214.12,"qty":1.92000000}],"asks":[],"checksum":2162043350,"timestamp":"2024-06-01T22:42:46.285305Z"}]}
{"channel":"book","type":"update","data":[{"symbol":"ETH/CAD","bids":[{"price":5216.30,"qty":3.58837415}],"asks":[],"checksum":912989136,"timestamp":"2024-06-01T22:42:46.286309Z"}]}
{"channel":"book","type":"update","data":[{"symbol":"ETH/CAD","bids":[{"price":5216.29,"qty":0.00000000},{"price":5214.12,"qty":1.92000000},{"price":5216.25,"qty":1.30800000}],"asks":[],"checksum":3471140030,"timestamp":"2024-06-01T22:42:46.288905Z"}]}
{"channel":"book","type":"update","data":[{"symbol":"ETH/CAD","bids":[{"price":5221.14,"qty":0.00000000},{"price":5214.12,"qty":1.92000000},{"price":5221.16,"qty":0.80016485}],"asks":[],"checksum":2140699911,"timestamp":"2024-06-01T22:42:46.619484Z"}]}
{"channel":"book","type":"update","data":[{"symbol":"ETH/CAD","bids":[{"price":5221.13,"qty":0.00000000},{"price":5214.12,"qty":1.92000000}],"asks":[],"checksum":2546737628,"timestamp":"2024-06-01T22:42:46.624930Z"}]}
{"channel":"book","type":"update","data":[{"symbol":"ETH/CAD","bids":[{"price":5220.92,"qty":0.00000000},{"price":5213.48,"qty":1.25586241},{"price":5221.16,"qty":0.86650285}],"asks":[],"checksum":1467198766,"timestamp":"2024-06-01T22:42:46.678212Z"}]}
{"channel":"book","type":"update","data":[{"symbol":"ETH/CAD","bids":[{"price":5221.15,"qty":0.90311190},{"price":5221.17,"qty":0.85620134}],"asks":[],"checksum":2315961031,"timestamp":"2024-06-01T22:42:46.763953Z"}]}
{"channel":"book","type":"update","data":[{"symbol":"ETH/CAD","bids":[],"asks":[{"price":5228.18,"qty":1.53790165}],"checksum":2069207454,"timestamp":"2024-06-01T22:42:46.766873Z"}]}
{"channel":"book","type":"update","data":[{"symbol":"ETH/CAD","bids":[{"price":5221.16,"qty":0.06633800},{"price":5221.18,"qty":0.80016485}],"asks":[],"checksum":3623272973,"timestamp":"2024-06-01T22:42:47.077049Z"}]}
{"channel":"book","type":"update","data":[{"symbol":"ETH/CAD","bids":[{"price":5216.25,"qty":0.00000000},{"price":5214.12,"qty":1.92000000},{"price":5216.31,"qty":1.30800000}],"asks":[],"checksum":2209962786,"timestamp":"2024-06-01T22:42:47.080171Z"}]}
{"channel":"book","type":"update","data":[{"symbol":"ETH/CAD","bids":[{"price":5221.17,"qty":0.00000000},{"price":5214.12,"qty":1.92000000},{"price":5221.19,"qty":0.85619828}],"asks":[],"checksum":3595116254,"timestamp":"2024-06-01T22:42:47.318111Z"}]}
{"channel":"book","type":"update","data":[{"symbol":"ETH/CAD","bids":[{"price":5221.20,"qty":0.90311190}],"asks":[],"checksum":3111331299,"timestamp":"2024-06-01T22:42:47.323422Z"}]}
{"channel":"book","type":"update","data":[{"symbol":"ETH/CAD","bids":[{"price":5221.15,"qty":0.00000000},{"price":5214.52,"qty":1.84146195}],"asks":[],"checksum":1449740400,"timestamp":"2024-06-01T22:42:47.679483Z"}]}
{"channel":"book","type":"update","data":[{"symbol":"ETH/CAD","bids":[{"price":5221.18,"qty":0.00000000},{"price":5214.12,"qty":1.92000000},{"price":5221.21,"qty":0.80016485}],"asks":[],"checksum":1877605368,"timestamp":"2024-06-01T22:42:47.686661Z"}]}
{"channel":"book","type":"update","data":[{"symbol":"ETH/CAD","bids":[{"price":5221.19,"qty":0.00000000},{"price":5214.12,"qty":1.92000000},{"price":5221.22,"qty":0.85619348}],"asks":[],"checksum":468309610,"timestamp":"2024-06-01T22:42:47.834268Z"}]}
{"channel":"book","type":"update","data":[{"symbol":"ETH/CAD","bids":[{"price":5221.21,"qty":0.00000000},{"price":5214.12,"qty":1.92000000},{"price":5221.23,"qty":0.80016485}],"asks":[],"checksum":1818619330,"timestamp":"2024-06-01T22:42:48.326514Z"}]}
{"channel":"book","type":"update","data":[{"symbol":"ETH/CAD","bids":[{"price":5221.24,"qty":0.90311190}],"asks":[],"checksum":1860271604,"timestamp":"2024-06-01T22:42:48.331760Z"}]}
{"channel":"book","type":"update","data":[{"symbol":"ETH/CAD","bids":[{"price":5221.22,"qty":0.00000000},{"price":5214.52,"qty":1.84146195},{"price":5221.25,"qty":0.85618832}],"asks":[],"checksum":2112237644,"timestamp":"2024-06-01T22:42:48.375073Z"}]}
{"channel":"book","type":"update","data":[{"symbol":"ETH/CAD","bids":[{"price":5221.20,"qty":0.00000000},{"price":5214.52,"qty":1.84146195}],"asks":[],"checksum":2012205562,"timestamp":"2024-06-01T22:42:48.380768Z"}]}
{"channel":"book","type":"update","data":[{"symbol":"ETH/CAD","bids":[{"price":5221.23,"qty":0.00000000},{"price":5214.12,"qty":1.92000000},{"price":5221.26,"qty":0.80016485}],"asks":[],"checksum":429574328,"timestamp":"2024-06-01T22:42:48.389775Z"}]}
{"channel":"book","type":"update","data":[{"symbol":"ETH/CAD","bids":[],"asks":[{"price":5228.19,"qty":0.05131782}],"checksum":4268892516,"timestamp":"2024-06-01T22:42:48.432809Z"}]}
{"channel":"book","type":"update","data":[{"symbol":"ETH/CAD","bids":[],"asks":[{"price":5228.18,"qty":0.22990165}],"checksum":1031599459,"timestamp":"2024-06-01T22:42:48.435858Z"}]}
{"channel":"book","type":"update","data":[{"symbol":"ETH/CAD","bids":[],"asks":[{"price":5228.17,"qty":15.96681520}],"checksum":1914510622,"timestamp":"2024-06-01T22:42:48.438087Z"}]}
{"channel":"book","type":"update","data":[{"symbol":"ETH/CAD","bids":[],"asks":[{"price":5228.16,"qty":0.22990165}],"checksum":2056132258,"timestamp":"2024-06-01T22:42:48.460717Z"}]}
{"channel":"book","type":"update","data":[{"symbol":"ETH/CAD","bids":[{"price":5221.27,"qty":0.90311190}],"asks":[],"checksum":2348312954,"timestamp":"2024-06-01T22:42:48.678083Z"}]}
{"channel":"book","type":"update","data":[{"symbol":"ETH/CAD","bids":[{"price":5221.24,"qty":0.00000000},{"price":5214.52,"qty":1.84146195}],"asks":[],"checksum":1918591408,"timestamp":"2024-06-01T22:42:48.683103Z"}]}
{"channel":"book","type":"update","data":[{"symbol":"ETH/CAD","bids":[],"asks":[{"price":5228.16,"qty":0.28121947}],"checksum":2327035242,"timestamp":"2024-06-01T22:42:48.786459Z"}]}
{"channel":"book","type":"update","data":[{"symbol":"ETH/CAD","bids":[{"price":5221.25,"qty":0.00000000},{"price":5214.12,"qty":1.92000000},{"price":5221.28,"qty":0.85618334}],"asks":[],"checksum":2164521659,"timestamp":"2024-06-01T22:42:48.968112Z"}]}
{"channel":"book","type":"update","data":[{"symbol":"ETH/CAD","bids":[],"asks":[{"price":5228.16,"qty":1.58921947}],"checksum":975509417,"timestamp":"2024-06-01T22:42:48.971208Z"}]}
{"channel":"book","type":"update","data":[{"symbol":"ETH/CAD","bids":[{"price":5221.26,"qty":0.00000000},{"price":5214.12,"qty":1.92000000},{"price":5221.29,"qty":0.80016485}],"asks":[],"checksum":3947548287,"timestamp":"2024-06-01T22:42:49.000658Z"}]}
{"channel":"book","type":"update","data":[{"symbol":"ETH/CAD","bids":[{"price":5216.30,"qty":0.00000000},{"price":5214.12,"qty":1.92000000}],"asks":[],"checksum":3725649048,"timestamp":"2024-06-01T22:42:49.131816Z"}]}
{"channel":"book","type":"update","data":[{"symbol":"ETH/CAD","bids":[{"price":5216.31,"qty":0.00000000},{"price":5213.48,"qty":1.25586241},{"price":5216.25,"qty":1.30800000}],"asks":[],"checksum":4203082064,"timestamp":"2024-06-01T22:42:49.135207Z"}]}
{"channel":"book","type":"update","data":[{"symbol":"ETH/CAD","bids":[{"price":5221.28,"qty":0.00000000},{"price":5213.48,"qty":1.25586241},{"price":5221.30,"qty":0.85618003}],"asks":[],"checksum":103351557,"timestamp":"2024-06-01T22:42:49.504980Z"}]}
{"channel":"book","type":"update","data":[{"symbol":"ETH/CAD","bids":[{"price":5221.31,"qty":0.90311190}],"asks":[],"checksum":1043128235,"timestamp":"2024-06-01T22:42:49.515631Z"}]}
{"channel":"book","type":"update","data":[{"symbol":"ETH/CAD","bids":[{"price":5221.27,"qty":0.00000000},{"price":5214.12,"qty":1.92000000}],"asks":[],"checksum":1179571164,"timestamp":"2024-06-01T22:42:49.677754Z"}]}
{"channel":"book","type":"update","data":[{"symbol":"ETH/CAD","bids":[{"price":5221.29,"qty":0.00000000},{"price":5213.48,"qty":1.25586241},{"price":5221.32,"qty":0.80016485}],"asks":[],"checksum":3013187774,"timestamp":"2024-06-01T22:42:49.703179Z"}]}
{"channel":"book","type":"update","data":[{"symbol":"ETH/CAD","bids":[],"asks":[{"price":5223.47,"qty":0.00000000},{"price":5228.78,"qty":1.04000000},{"price":5223.45,"qty":0.09983515}],"checksum":2484176015,"timestamp":"2024-06-01T22:42:49.735089Z"}]}
{"channel":"book","type":"update","data":[{"symbol":"ETH/CAD","bids":[{"price":5221.30,"qty":0.00000000},{"price":5213.48,"qty":1.25586241},{"price":5221.33,"qty":0.85617510}],"asks":[],"checksum":2272893400,"timestamp":"2024-06-01T22:42:50.001694Z"}]}
{"channel":"book","type":"update","data":[{"symbol":"ETH/CAD","bids":[],"asks":[{"price":5223.46,"qty":0.00000000},{"price":5228.78,"qty":1.04000000},{"price":5223.44,"qty":0.31436622}],"checksum":850466860,"timestamp":"2024-06-01T22:42:50.001845Z"}]}
{"channel":"book","type":"update","data":[{"symbol":"ETH/CAD","bids":[{"price":5221.32,"qty":0.00000000},{"price":5213.48,"qty":1.25586241},{"price":5221.34,"qty":0.80016485}],"asks":[],"checksum":1288773975,"timestamp":"2024-06-01T22:42:50.312089Z"}]}
{"channel":"book","type":"update","data":[{"symbol":"ETH/CAD","bids":[{"price":5221.35,"qty":0.90311190}],"asks":[],"checksum":1852725163,"timestamp":"2024-06-01T22:42:50.317336Z"}]}
{"channel":"book","type":"update","data":[{"symbol":"ETH/CAD","bids":[{"price":5221.33,"qty":0.00000000},{"price":5214.12,"qty":1.92000000},{"price":5221.36,"qty":0.85616936}],"asks":[],"checksum":2572951698,"timestamp":"2024-06-01T22:42:50.564115Z"}]}
{"channel":"book","type":"update","data":[{"symbol":"ETH/CAD","bids":[{"price":5221.31,"qty":0.00000000},{"price":5214.12,"qty":1.92000000}],"asks":[],"checksum":3286083701,"timestamp":"2024-06-01T22:42:50.569336Z"}]}
{"channel":"book","type":"update","data":[{"symbol":"ETH/CAD","bids":[],"asks":[{"price":5228.17,"qty":0.00000000},{"price":5228.78,"qty":1.04000000}],"checksum":3227129676,"timestamp":"2024-06-01T22:42:50.720172Z"}]}
{"channel":"book","type":"update","data":[{"symbol":"ETH/CAD","bids":[],"asks":[{"price":5228.16,"qty":0.28121947},{"price":5228.77,"qty":1.30800000}],"checksum":2663037063,"timestamp":"2024-06-01T22:42:50.723759Z"}]}
{"channel":"book","type":"update","data":[{"symbol":"ETH/CAD","bids":[],"asks":[{"price":5228.15,"qty":14.46992628}],"checksum":4169956266,"timestamp":"2024-06-01T22:42:50.725317Z"}]}
{"channel":"book","type":"update","data":[{"symbol":"ETH/CAD","bids":[],"asks":[{"price":5228.14,"qty":0.22990165}],"checksum":2481486104,"timestamp":"2024-06-01T22:42:50.745149Z"}]}
{"channel":"book","type":"update","data":[{"symbol":"ETH/CAD","bids":[{"price":5221.34,"qty":0.00000000},{"price":5213.48,"qty":1.25586241},{"price":5221.37,"qty":0.80016485}],"asks":[],"checksum":1077449971,"timestamp":"2024-06-01T22:42:51.073667Z"}]}
{"channel":"book","type":"update","data":[{"symbol":"ETH/CAD","bids":[],"asks":[{"price":5223.45,"qty":0.00000000},{"price":5228.16,"qty":0.05131782},{"price":5223.43,"qty":0.09983515}],"checksum":1150854064,"timestamp":"2024-06-01T22:42:51.105280Z"}]}
{"channel":"book","type":"update","data":[{"symbol":"ETH/CAD","bids":[{"price":5221.36,"qty":0.00000000},{"price":5213.48,"qty":1.25586241},{"price":5221.38,"qty":0.85616570}],"asks":[],"checksum":3035232032,"timestamp":"2024-06-01T22:42:51.123904Z"}]}
{"channel":"book","type":"update","data":[{"symbol":"ETH/CAD","bids":[],"asks":[{"price":5228.14,"qty":1.53790165}],"checksum":1170795562,"timestamp":"2024-06-01T22:42:51.291154Z"}]}
{"channel":"book","type":"update","data":[{"symbol":"ETH/CAD","bids":[],"asks":[{"price":5228.13,"qty":0.05131782}],"checksum":682232100,"timestamp":"2024-06-01T22:42:51.455045Z"}]}
{"channel":"book","type":"update","data":[{"symbol":"ETH/CAD","bids":[],"asks":[{"price":5228.14,"qty":1.30800000}],"checksum":591678374,"timestamp":"2024-06-01T22:42:51.506860Z"}]}
{"channel":"book","type":"update","data":[{"symbol":"ETH/CAD","bids":[],"asks":[{"price":5228.12,"qty":0.22990165}],"checksum":389507104,"timestamp":"2024-06-01T22:42:51.507046Z"}]}
{"channel":"book","type":"update","data":[{"symbol":"ETH/CAD","bids":[],"asks":[{"price":5223.44,"qty":0.00000000},{"price":5228.14,"qty":1.30800000},{"price":5223.42,"qty":0.31436698}],"checksum":2753810439,"timestamp":"2024-06-01T22:42:51.676891Z"}]}
{"channel":"book","type":"update","data":[{"symbol":"ETH/CAD","bids":[{"price":5221.39,"qty":0.90311190}],"asks":[],"checksum":1587086410,"timestamp":"2024-06-01T22:42:51.677923Z"}]}
{"channel":"book","type":"update","data":[{"symbol":"ETH/CAD","bids":[{"price":5221.37,"qty":0.00000000},{"price":5214.12,"qty":1.92000000},{"price":5221.40,"qty":0.80016485}],"asks":[],"checksum":4115217391,"timestamp":"2024-06-01T22:42:51.684662Z"}]}
{"channel":"book","type":"update","data":[{"symbol":"ETH/CAD","bids":[{"price":5221.35,"qty":0.00000000},{"price":5214.12,"qty":1.92000000}],"asks":[],"checksum":670927717,"timestamp":"2024-06-01T22:42:52.177646Z"}]}
{"channel":"book","type":"update","data":[{"symbol":"ETH/CAD","bids":[{"price":5221.38,"qty":0.00000000},{"price":5213.48,"qty":1.25586241},{"price":5221.41,"qty":0.85616071}],"asks":[],"checksum":4079481113,"timestamp":"2024-06-01T22:42:52.180004Z"}]}
{"channel":"book","type":"update","data":[{"symbol":"ETH/CAD","bids":[{"price":5221.41,"qty":1.75927261}],"asks":[],"checksum":2444088441,"timestamp":"2024-06-01T22:42:52.182440Z"}]}
{"channel":"book","type":"update","data":[{"symbol":"ETH/CAD","bids":[{"price":5221.39,"qty":0.00000000},{"price":5213.48,"qty":1.25586241}],"asks":[],"checksum":398309924,"timestamp":"2024-06-01T22:42:52.679825Z"}]}
{"channel":"book","type":"update","data":[{"symbol":"ETH/CAD","bids":[{"price":5221.40,"qty":0.00000000},{"price":5213.47,"qty":0.95000000}],"asks":[],"checksum":4003855758,"timestamp":"2024-06-01T22:42:52.686795Z"}]}
{"channel":"book","type":"update","data":[{"symbol":"ETH/CAD","bids":[{"price":5221.41,"qty":0.90311190},{"price":5221.42,"qty":0.85615963}],"asks":[],"checksum":1256892454,"timestamp":"2024-06-01T22:42:52.715581Z"}]}
{"channel":"book","type":"update","data":[{"symbol":"ETH/CAD","bids":[{"price":5221.43,"qty":0.90311190}],"asks":[],"checksum":2820542925,"timestamp":"2024-06-01T22:42:52.720518Z"}]}
{"channel":"book","type":"update","data":[{"symbol":"ETH/CAD","bids":[],"asks":[{"price":5224.46,"qty":0.00000000},{"price":5228.14,"qty":1.30800000}],"checksum":583967590,"timestamp":"2024-06-01T22:42:52.923980Z"}]}
{"channel":"book","type":"update","data":[{"symbol":"ETH/CAD","bids":[],"asks":[{"price":5228.14,"qty":0.00000000},{"price":5228.78,"qty":1.04000000},{"price":5228.77,"qty":1.30800000}],"checksum":133611118,"timestamp":"2024-06-01T22:42:52.928756Z"}]}
{"channel":"book","type":"update","data":[{"symbol":"ETH/CAD","bids":[{"price":5221.41,"qty":0.00000000},{"price":5213.48,"qty":1.25586241}],"asks":[],"checksum":1874879682,"timestamp":"2024-06-01T22:42:52.929312Z"}]}
{"channel":"book","type":"update","data":[{"symbol":"ETH/CAD","bids":[],"asks":[{"price":5228.11,"qty":17.59624091}],"checksum":2067603779,"timestamp":"2024-06-01T22:42:52.929328Z"}]}
{"channel":"book","type":"update","data":[{"symbol":"ETH/CAD","bids":[],"asks":[{"price":5224.46,"qty":1.02255915}],"checksum":1491087298,"timestamp":"2024-06-01T22:42:52.929435Z"}]}
{"channel":"book","type":"update","data":[{"symbol":"ETH/CAD","bids":[],"asks":[{"price":5223.43,"qty":0.00000000},{"price":5228.13,"qty":0.05131782}],"checksum":739815464,"timestamp":"2024-06-01T22:42:52.933916Z"}]}
{"channel":"book","type":"update","data":[{"symbol":"ETH/CAD","bids":[],"asks":[{"price":5228.12,"qty":0.00000000},{"price":5228.77,"qty":1.30800000}],"checksum":330837299,"timestamp":"2024-06-01T22:42:52.954977Z"}]}
{"channel":"book","type":"update","data":[{"symbol":"ETH/CAD","bids":[],"asks":[{"price":5228.10,"qty":0.22990165}],"checksum":2242614739,"timestamp":"2024-06-01T22:42:52.955174Z"}]}
{"channel":"book","type":"update","data":[{"symbol":"ETH/CAD","bids":[],"asks":[{"price":5223.42,"qty":0.00000000},{"price":5228.77,"qty":1.30800000},{"price":5224.45,"qty":0.31436949}],"checksum":183612535,"timestamp":"2024-06-01T22:42:52.972136Z"}]}
{"channel":"book","type":"update","data":[{"symbol":"ETH/CAD","bids":[{"price":5221.42,"qty":0.00000000},{"price":5213.47,"qty":0.95000000},{"price":5221.44,"qty":0.85615661}],"asks":[],"checksum":3713378951,"timestamp":"2024-06-01T22:42:53.185872Z"}]}
{"channel":"book","type":"update","data":[{"symbol":"ETH/CAD","bids":[{"price":5219.90,"qty":0.00000000},{"price":5213.47,"qty":0.95000000}],"asks":[],"checksum":2786219308,"timestamp":"2024-06-01T22:42:53.190746Z"}]}
{"channel":"book","type":"update","data":[{"symbol":"ETH/CAD","bids":[{"price":5221.45,"qty":0.90311190}],"asks":[],"checksum":3602303788,"timestamp":"2024-06-01T22:42:53.191111Z"}]}
{"channel":"book","type":"update","data":[{"symbol":"ETH/CAD","bids":[{"price":5219.90,"qty":3.83754935}],"asks":[],"checksum":677482979,"timestamp":"2024-06-01T22:42:53.194106Z"}]}
{"channel":"book","type":"update","data":[{"symbol":"ETH/CAD","bids":[{"price":5221.43,"qty":0.00000000},{"price":5213.48,"qty":1.25586241}],"asks":[],"checksum":183151469,"timestamp":"2024-06-01T22:42:53.678830Z"}]}
{"channel":"book","type":"update","data":[{"symbol":"ETH/CAD","bids":[],"asks":[{"price":5228.10,"qty":1.53790165}],"checksum":66838353,"timestamp":"2024-06-01T22:42:53.681941Z"}]}
{"channel":"book","type":"update","data":[{"symbol":"ETH/CAD","bids":[{"price":5221.46,"qty":0.80016485}],"asks":[],"checksum":3869635234,"timestamp":"2024-06-01T22:42:53.692532Z"}]}
{"channel":"book","type":"update","data":[{"symbol":"ETH/CAD","bids":[{"price":5221.44,"qty":0.00000000},{"price":5213.48,"qty":1.25586241},{"price":5221.47,"qty":0.85615189}],"asks":[],"checksum":4073363889,"timestamp":"2024-06-01T22:42:53.747926Z"}]}
{"channel":"book","type":"update","data":[{"symbol":"ETH/CAD","bids":[],"asks":[{"price":5224.44,"qty":0.09983515}],"checksum":2339636242,"timestamp":"2024-06-01T22:42:54.058320Z"}]}
{"channel":"book","type":"update","data":[{"symbol":"ETH/CAD","bids":[],"asks":[{"price":5224.45,"qty":0.00000000},{"price":5228.13,"qty":0.05131782},{"price":5224.43,"qty":0.31436948}],"checksum":3564074167,"timestamp":"2024-06-01T22:42:54.270604Z"}]}
{"channel":"book","type":"update","data":[{"symbol":"ETH/CAD","bids":[{"price":5221.48,"qty":0.90311190}],"asks":[],"checksum":1889629332,"timestamp":"2024-06-01T22:42:54.277024Z"}]}
{"channel":"book","type":"update","data":[{"symbol":"ETH/CAD","bids":[],"asks":[{"price":5228.09,"qty":0.05131792}],"checksum":2288505755,"timestamp":"2024-06-01T22:42:54.287529Z"}]}
{"channel":"book","type":"update","data":[{"symbol":"ETH/CAD","bids":[],"asks":[{"price":5228.10,"qty":1.30800000}],"checksum":3187306580,"timestamp":"2024-06-01T22:42:54.302525Z"}]}
{"channel":"book","type":"update","data":[{"symbol":"ETH/CAD","bids":[],"asks":[{"price":5228.08,"qty":0.22990165}],"checksum":671866778,"timestamp":"2024-06-01T22:42:54.302584Z"}]}
{"channel":"book","type":"update","data":[{"symbol":"ETH/CAD","bids":[{"price":5221.46,"qty":0.00000000},{"price":5214.12,"qty":1.92000000},{"price":5221.49,"qty":0.80016485}],"asks":[],"checksum":2962956701,"timestamp":"2024-06-01T22:42:54.302877Z"}]}
{"channel":"book","type":"update","data":[{"symbol":"ETH/CAD","bids":[{"price":5221.45,"qty":0.00000000},{"price":5214.12,"qty":1.92000000}],"asks":[],"checksum":181023833,"timestamp":"2024-06-01T22:42:54.311577Z"}]}
{"channel":"book","type":"update","data":[{"symbol":"ETH/CAD","bids":[{"price":5221.50,"qty":0.90311190}],"asks":[],"checksum":2281492540,"timestamp":"2024-06-01T22:42:54.679813Z"}]}
{"channel":"book","type":"update","data":[{"symbol":"ETH/CAD","bids":[{"price":5221.48,"qty":0.00000000},{"price":5214.12,"qty":1.92000000}],"asks":[],"checksum":4163004267,"timestamp":"2024-06-01T22:42:54.684538Z"}]}
{"channel":"book","type":"update","data":[{"symbol":"ETH/CAD","bids":[{"price":5221.49,"qty":0.00000000},{"price":5213.48,"qty":1.25586241}],"asks":[],"checksum":1277084388,"timestamp":"2024-06-01T22:42:54.699693Z"}]}
{"channel":"book","type":"update","data":[{"symbol":"ETH/CAD","bids":[{"price":5221.47,"qty":0.00000000},{"price":5213.47,"qty":0.95000000},{"price":5221.51,"qty":0.85614218}],"asks":[],"checksum":1886484956,"timestamp":"2024-06-01T22:42:54.830613Z"}]}
{"channel":"book","type":"update","data":[{"symbol":"ETH/CAD","bids":[],"asks":[{"price":5224.46,"qty":0.00000000},{"price":5228.10,"qty":1.30800000}],"checksum":3873937771,"timestamp":"2024-06-01T22:42:55.226662Z"}]}
{"channel":"book","type":"update","data":[{"symbol":"ETH/CAD","bids":[],"asks":[{"price":5228.07,"qty":13.97096316}],"checksum":1096224817,"timestamp":"2024-06-01T22:42:55.228823Z"}]}
{"channel":"book","type":"update","data":[{"symbol":"ETH/CAD","bids":[],"asks":[{"price":5224.42,"qty":1.52151747}],"checksum":316940934,"timestamp":"2024-06-01T22:42:55.228998Z"}]}
{"channel":"book","type":"update","data":[{"symbol":"ETH/CAD","bids":[],"asks":[{"price":5228.06,"qty":0.22990165}],"checksum":3294163244,"timestamp":"2024-06-01T22:42:55.232045Z"}]}
{"channel":"book","type":"update","data":[{"symbol":"ETH/CAD","bids":[{"price":5221.52,"qty":0.90311190}],"asks":[],"checksum":2659968862,"timestamp":"2024-06-01T22:42:55.233005Z"}]}
{"channel":"book","type":"update","data":[{"symbol":"ETH/CAD","bids":[],"asks":[{"price":5224.43,"qty":0.00000000},{"price":5228.09,"qty":0.05131792},{"price":5224.41,"qty":0.31436970}],"checksum":165621779,"timestamp":"2024-06-01T22:42:55.341850Z"}]}
{"channel":"book","type":"update","data":[{"symbol":"ETH/CAD","bids":[{"price":5221.50,"qty":0.00000000},{"price":5213.48,"qty":1.25586241}],"asks":[],"checksum":3862732892,"timestamp":"2024-06-01T22:42:55.346757Z"}]}
{"channel":"book","type":"update","data":[{"symbol":"ETH/CAD","bids":[{"price":5221.51,"qty":0.00000000},{"price":5213.47,"qty":0.95000000},{"price":5219.91,"qty":0.85640437}],"asks":[],"checksum":3739231219,"timestamp":"2024-06-01T22:42:55.406575Z"}]}
{"channel":"book","type":"update","data":[{"symbol":"ETH/CAD","bids":[],"asks":[{"price":5224.44,"qty":0.00000000},{"price":5228.09,"qty":0.05131792},{"price":5224.40,"qty":0.09983515}],"checksum":939986636,"timestamp":"2024-06-01T22:42:55.733018Z"}]}
{"channel":"book","type":"update","data":[{"symbol":"ETH/CAD","bids":[],"asks":[{"price":5228.06,"qty":1.53790165}],"checksum":421116255,"timestamp":"2024-06-01T22:42:55.736016Z"}]}
{"channel":"book","type":"update","data":[{"symbol":"ETH/CAD","bids":[],"asks":[{"price":5224.41,"qty":0.00000000},{"price":5228.09,"qty":0.05131792},{"price":5224.39,"qty":0.31436971}],"checksum":4186044284,"timestamp":"2024-06-01T22:42:55.883095Z"}]}
{"channel":"book","type":"update","data":[{"symbol":"ETH/CAD","bids":[],"asks":[{"price":5224.40,"qty":0.00000000},{"price":5228.09,"qty":0.05131792},{"price":5224.38,"qty":0.09983515}],"checksum":3646787373,"timestamp":"2024-06-01T22:42:55.916646Z"}]}
{"channel":"book","type":"update","data":[{"symbol":"ETH/CAD","bids":[],"asks":[{"price":5224.39,"qty":0.00000000},{"price":5228.09,"qty":0.05131792},{"price":5224.37,"qty":0.31436972}],"checksum":782277357,"timestamp":"2024-06-01T22:42:56.496179Z"}]}
{"channel":"book","type":"update","data":[{"symbol":"ETH/CAD","bids":[],"asks":[{"price":5223.50,"qty":0.00000000},{"price":5228.09,"qty":0.05131792},{"price":5224.37,"qty":0.33000472}],"checksum":3885656349,"timestamp":"2024-06-01T22:42:56.496714Z"}]}
{"channel":"book","type":"update","data":[{"symbol":"ETH/CAD","bids":[{"price":5221.52,"qty":0.00000000},{"price":5213.47,"qty":0.95000000}],"asks":[],"checksum":2473003266,"timestamp":"2024-06-01T22:42:56.501643Z"}]}
{"channel":"book","type":"update","data":[{"symbol":"ETH/CAD","bids":[{"price":5221.17,"qty":0.90311190}],"asks":[],"checksum":2582349433,"timestamp":"2024-06-01T22:42:56.501700Z"}]}
{"channel":"book","type":"update","data":[{"symbol":"ETH/CAD","bids":[{"price":5221.18,"qty":0.80016485}],"asks":[],"checksum":2740437189,"timestamp":"2024-06-01T22:42:56.523136Z"}]}
{"channel":"book","type":"update","data":[{"symbol":"ETH/CAD","bids":[],"asks":[{"price":5224.38,"qty":0.00000000},{"price":5228.78,"qty":1.04000000},{"price":5224.36,"qty":0.09983515}],"checksum":1365052759,"timestamp":"2024-06-01T22:42:56.858035Z"}]}
{"channel":"book","type":"update","data":[{"symbol":"ETH/CAD","bids":[],"asks":[{"price":5228.09,"qty":0.00000000},{"price":5228.78,"qty":1.04000000}],"checksum":2382441862,"timestamp":"2024-06-01T22:42:57.027960Z"}]}
{"channel":"book","type":"update","data":[{"symbol":"ETH/CAD","bids":[],"asks":[{"price":5228.05,"qty":0.05131785}],"checksum":2678967081,"timestamp":"2024-06-01T22:42:57.029551Z"}]}
{"channel":"book","type":"update","data":[{"symbol":"ETH/CAD","bids":[],"asks":[{"price":5228.04,"qty":0.22990165}],"checksum":843398396,"timestamp":"2024-06-01T22:42:57.035047Z"}]}
{"channel":"book","type":"update","data":[{"symbol":"ETH/CAD","bids":[],"asks":[{"price":5228.06,"qty":1.30800000}],"checksum":967540350,"timestamp":"2024-06-01T22:42:57.035252Z"}]}
{"channel":"book","type":"update","data":[{"symbol":"ETH/CAD","bids":[{"price":5219.91,"qty":0.00000000},{"price":5213.48,"qty":1.25586241},{"price":5221.19,"qty":0.85619473}],"asks":[],"checksum":3230852715,"timestamp":"2024-06-01T22:42:57.060038Z"}]}
{"channel":"book","type":"update","data":[{"symbol":"ETH/CAD","bids":[],"asks":[{"price":5224.37,"qty":0.01563500},{"price":5224.35,"qty":0.31436630}],"checksum":430366649,"timestamp":"2024-06-01T22:42:57.060114Z"}]}
{"channel":"book","type":"update","data":[{"symbol":"ETH/CAD","bids":[],"asks":[{"price":5224.36,"qty":0.00000000},{"price":5228.06,"qty":1.30800000},{"price":5224.34,"qty":0.09983515}],"checksum":3494888031,"timestamp":"2024-06-01T22:42:57.073050Z"}]}
{"channel":"book","type":"update","data":[{"symbol":"ETH/CAD","bids":[],"asks":[{"price":5224.42,"qty":0.00000000},{"price":5228.06,"qty":1.30800000}],"checksum":374771796,"timestamp":"2024-06-01T22:42:57.516330Z"}]}
{"channel":"book","type":"update","data":[{"symbol":"ETH/CAD","bids":[],"asks":[{"price":5228.06,"qty":0.00000000},{"price":5228.78,"qty":1.04000000},{"price":5228.77,"qty":1.30800000}],"checksum":2593515783,"timestamp":"2024-06-01T22:42:57.519627Z"}]}
{"channel":"book","type":"update","data":[{"symbol":"ETH/CAD","bids":[{"price":5221.20,"qty":0.90311190}],"asks":[],"checksum":620417984,"timestamp":"2024-06-01T22:42:57.522002Z"}]}
{"channel":"book","type":"update","data":[{"symbol":"ETH/CAD","bids":[],"asks":[{"price":5224.33,"qty":1.02254724}],"checksum":3217720402,"timestamp":"2024-06-01T22:42:57.522031Z"}]}
{"channel":"book","type":"update","data":[{"symbol":"ETH/CAD","bids":[],"asks":[{"price":5224.33,"qty":1.92565914}],"checksum":144967035,"timestamp":"2024-06-01T22:42:57.522089Z"}]}
{"channel":"book","type":"update","data":[{"symbol":"ETH/CAD","bids":[],"asks":[{"price":5228.03,"qty":12.99765860}],"checksum":3950331151,"timestamp":"2024-06-01T22:42:57.522158Z"}]}
{"channel":"book","type":"update","data":[{"symbol":"ETH/CAD","bids":[{"price":5221.18,"qty":0.00000000},{"price":5214.12,"qty":1.92000000},{"price":5221.20,"qty":1.70327675}],"asks":[],"checksum":2778168536,"timestamp":"2024-06-01T22:42:57.529072Z"}]}
{"channel":"book","type":"update","data":[{"symbol":"ETH/CAD","bids":[{"price":5221.19,"qty":0.00000000},{"price":5213.48,"qty":1.25586241},{"price":5221.21,"qty":0.85619128}],"asks":[],"checksum":1270025849,"timestamp":"2024-06-01T22:42:57.624001Z"}]}
{"channel":"book","type":"update","data":[{"symbol":"ETH/CAD","bids":[],"asks":[{"price":5224.35,"qty":0.00000000},{"price":5228.05,"qty":0.05131785},{"price":5224.32,"qty":0.31436631}],"checksum":3369793931,"timestamp":"2024-06-01T22:42:57.624029Z"}]}
{"channel":"book","type":"update","data":[{"symbol":"ETH/CAD","bids":[],"asks":[{"price":5224.33,"qty":1.02254724}],"checksum":622183587,"timestamp":"2024-06-01T22:42:57.629942Z"}]}
{"channel":"book","type":"update","data":[{"symbol":"ETH/CAD","bids":[{"price":5221.17,"qty":0.00000000},{"price":5213.48,"qty":1.25586241}],"asks":[],"checksum":3175818768,"timestamp":"2024-06-01T22:42:57.629956Z"}]}
{"channel":"book","type":"update","data":[{"symbol":"ETH/CAD","bids":[{"price":5221.20,"qty":0.90311190}],"asks":[],"checksum":3649857983,"timestamp":"2024-06-01T22:42:57.653599Z"}]}
{"channel":"book","type":"update","data":[{"symbol":"ETH/CAD","bids":[],"asks":[{"price":5228.04,"qty":0.00000000},{"price":5228.05,"qty":0.05131785}],"checksum":441227287,"timestamp":"2024-06-01T22:42:57.797858Z"}]}
{"channel":"book","type":"update","data":[{"symbol":"ETH/CAD","bids":[],"asks":[{"price":5224.32,"qty":0.00000000},{"price":5228.76,"qty":0.22990165},{"price":5224.32,"qty":0.40043936}],"checksum":2908562950,"timestamp":"2024-06-01T22:42:58.252875Z"}]}
{"channel":"book","type":"update","data":[{"symbol":"ETH/CAD","bids":[{"price":5221.21,"qty":0.00000000},{"price":5213.47,"qty":0.95000000},{"price":5221.21,"qty":0.81729965}],"asks":[],"checksum":2823154117,"timestamp":"2024-06-01T22:42:58.253027Z"}]}
{"channel":"book","type":"update","data":[{"symbol":"ETH/CAD","bids":[],"asks":[{"price":5228.02,"qty":1.30800000}],"checksum":2532164147,"timestamp":"2024-06-01T22:42:58.256160Z"}]}
{"channel":"book","type":"update","data":[{"symbol":"ETH/CAD","bids":[{"price":5221.22,"qty":0.90311190}],"asks":[],"checksum":114879317,"timestamp":"2024-06-01T22:42:58.258452Z"}]}
{"channel":"book","type":"update","data":[{"symbol":"ETH/CAD","bids":[{"price":5221.20,"qty":0.00000000},{"price":5213.48,"qty":1.25586241}],"asks":[],"checksum":3966030751,"timestamp":"2024-06-01T22:42:58.678013Z"}]}
{"channel":"book","type":"update","data":[{"symbol":"ETH/CAD","bids":[{"price":5221.21,"qty":0.00000000},{"price":5213.47,"qty":0.95000000},{"price":5221.23,"qty":0.81729652}],"asks":[],"checksum":2302373196,"timestamp":"2024-06-01T22:42:58.864498Z"}]}
{"channel":"book","type":"update","data":[{"symbol":"ETH/CAD","bids":[],"asks":[{"price":5224.34,"qty":0.00000000},{"price":5228.05,"qty":0.05131785},{"price":5224.31,"qty":0.09983515}],"checksum":1849917686,"timestamp":"2024-06-01T22:42:59.355972Z"}]}
{"channel":"book","type":"update","data":[{"symbol":"ETH/CAD","bids":[],"asks":[{"price":5224.30,"qty":0.90311190}],"checksum":3336133941,"timestamp":"2024-06-01T22:42:59.361703Z"}]}
{"channel":"book","type":"update","data":[{"symbol":"ETH/CAD","bids":[],"asks":[{"price":5224.31,"qty":0.00000000},{"price":5228.03,"qty":12.99765860},{"price":5224.29,"qty":0.09983515}],"checksum":3800945053,"timestamp":"2024-06-01T22:42:59.387561Z"}]}
{"channel":"book","type":"update","data":[{"symbol":"ETH/CAD","bids":[],"asks":[{"price":5224.30,"qty":0.00000000},{"price":5228.03,"qty":12.99765860}],"checksum":1597245806,"timestamp":"2024-06-01T22:42:59.393135Z"}]}
{"channel":"book","type":"update","data":[{"symbol":"ETH/CAD","bids":[],"asks":[{"price":5224.32,"qty":0.00000000},{"price":5228.05,"qty":0.05131785},{"price":5224.28,"qty":0.40044276}],"checksum":2903138042,"timestamp":"2024-06-01T22:42:59.517012Z"}]}
{"channel":"book","type":"update","data":[{"symbol":"ETH/CAD","bids":[],"asks":[{"price":5224.33,"qty":0.00000000},{"price":5228.05,"qty":0.05131785}],"checksum":3330561458,"timestamp":"2024-06-01T22:42:59.725433Z"}]}
{"channel":"book","type":"update","data":[{"symbol":"ETH/CAD","bids":[],"asks":[{"price":5228.03,"qty":0.00000000},{"price":5228.76,"qty":0.22990165}],"checksum":969078959,"timestamp":"2024-06-01T22:42:59.725739Z"}]}
{"channel":"book","type":"update","data":[{"symbol":"ETH/CAD","bids":[],"asks":[{"price":5228.02,"qty":0.00000000},{"price":5228.78,"qty":1.04000000},{"price":5228.77,"qty":1.30800000}],"checksum":1392528219,"timestamp":"2024-06-01T22:42:59.729126Z"}]}
{"channel":"book","type":"update","data":[{"symbol":"ETH/CAD","bids":[],"asks":[{"price":5224.29,"qty":1.62134536}],"checksum":3685927570,"timestamp":"2024-06-01T22:42:59.730955Z"}]}
{"channel":"book","type":"update","data":[{"symbol":"ETH/CAD","bids":[],"asks":[{"price":5228.01,"qty":6.01217697}],"checksum":1122515884,"timestamp":"2024-06-01T22:42:59.731039Z"}]}
{"channel":"book","type":"update","data":[{"symbol":"ETH/CAD","bids":[],"asks":[{"price":5228.75,"qty":7.41158373}],"checksum":3826666483,"timestamp":"2024-06-01T22:42:59.731208Z"}]}
{"channel":"book","type":"update","data":[{"symbol":"ETH/CAD","bids":[],"asks":[{"price":5228.74,"qty":0.22990165}],"checksum":3765728883,"timestamp":"2024-06-01T22:42:59.750059Z"}]}
{"channel":"book","type":"update","data":[{"symbol":"ETH/CAD","bids":[],"asks":[{"price":5228.05,"qty":0.00000000},{"price":5228.75,"qty":7.41158373}],"checksum":959739061,"timestamp":"2024-06-01T22:42:59.810355Z"}]}
{"channel":"book","type":"update","data":[{"symbol":"ETH/CAD","bids":[],"asks":[{"price":5228.01,"qty":6.06349482}],"checksum":1350444019,"timestamp":"2024-06-01T22:42:59.812512Z"}]}
{"channel":"book","type":"update","data":[{"symbol":"ETH/CAD","bids":[{"price":5216.26,"qty":4.09919436}],"asks":[],"checksum":1840466532,"timestamp":"2024-06-01T22:43:00.609230Z"}]}
{"channel":"book","type":"update","data":[{"symbol":"ETH/CAD","bids":[{"price":5216.25,"qty":0.00000000},{"price":5213.48,"qty":1.25586241},{"price":5216.27,"qty":1.30800000}],"asks":[],"checksum":2823695363,"timestamp":"2024-06-01T22:43:00.611936Z"}]}
{"channel":"book","type":"update","data":[{"symbol":"ETH/CAD","bids":[],"asks":[{"price":5228.00,"qty":1.30800000}],"checksum":1671235377,"timestamp":"2024-06-01T22:43:00.612027Z"}]}
{"channel":"book","type":"update","data":[{"symbol":"ETH/CAD","bids":[{"price":5221.24,"qty":0.80016485}],"asks":[],"checksum":3897306487,"timestamp":"2024-06-01T22:43:00.634595Z"}]}
{"channel":"book","type":"update","data":[{"symbol":"ETH/CAD","bids":[{"price":5221.25,"qty":0.90311190}],"asks":[],"checksum":1987025176,"timestamp":"2024-06-01T22:43:00.639748Z"}]}
{"channel":"book","type":"update","data":[{"symbol":"ETH/CAD","bids":[],"asks":[{"price":5224.27,"qty":0.90311190}],"checksum":610097642,"timestamp":"2024-06-01T22:43:00.639996Z"}]}
{"channel":"book","type":"update","data":[{"symbol":"ETH/CAD","bids":[{"price":5221.23,"qty":0.00000000},{"price":5214.52,"qty":1.84146195},{"price":5221.25,"qty":1.72039428}],"asks":[],"checksum":263595589,"timestamp":"2024-06-01T22:43:00.645054Z"}]}
{"channel":"book","type":"update","data":[{"symbol":"ETH/CAD","bids":[],"asks":[{"price":5224.29,"qty":1.52151021},{"price":5224.26,"qty":0.09983515}],"checksum":2707066186,"timestamp":"2024-06-01T22:43:00.666160Z"}]}
{"channel":"book","type":"update","data":[{"symbol":"ETH/CAD","bids":[],"asks":[{"price":5224.27,"qty":0.00000000},{"price":5228.01,"qty":6.06349482}],"checksum":3887965029,"timestamp":"2024-06-01T22:43:00.671326Z"}]}
{"channel":"book","type":"update","data":[{"symbol":"ETH/CAD","bids":[{"price":5221.22,"qty":0.00000000},{"price":5214.12,"qty":1.92000000}],"asks":[],"checksum":3119126329,"timestamp":"2024-06-01T22:43:00.671471Z"}]}
{"channel":"book","type":"update","data":[{"symbol":"ETH/CAD","bids":[{"price":5221.24,"qty":0.00000000},{"price":5213.48,"qty":1.25586241}],"asks":[],"checksum":3314549057,"timestamp":"2024-06-01T22:43:00.697301Z"}]}
{"channel":"book","type":"update","data":[{"symbol":"ETH/CAD","bids":[{"price":5221.25,"qty":0.90311190},{"price":5221.26,"qty":0.81728081}],"asks":[],"checksum":222700328,"timestamp":"2024-06-01T22:43:01.223470Z"}]}
{"channel":"book","type":"update","data":[{"symbol":"ETH/CAD","bids":[],"asks":[{"price":5224.28,"qty":0.00000000},{"price":5228.74,"qty":0.22990165},{"price":5224.25,"qty":0.40044604}],"checksum":3215118401,"timestamp":"2024-06-01T22:43:01.223522Z"}]}
{"channel":"book","type":"update","data":[{"symbol":"ETH/CAD","bids":[{"price":5221.27,"qty":0.90311190}],"asks":[],"checksum":1682159396,"timestamp":"2024-06-01T22:43:01.229320Z"}]}
{"channel":"book","type":"update","data":[{"symbol":"ETH/CAD","bids":[],"asks":[{"price":5227.99,"qty":0.22990165}],"checksum":1159955925,"timestamp":"2024-06-01T22:43:01.521033Z"}]}
{"channel":"book","type":"update","data":[{"symbol":"ETH/CAD","bids":[{"price":5221.28,"qty":0.80016485}],"asks":[],"checksum":2986840865,"timestamp":"2024-06-01T22:43:01.545747Z"}]}
{"channel":"book","type":"update","data":[{"symbol":"ETH/CAD","bids":[{"price":5221.25,"qty":0.00000000},{"price":5214.52,"qty":1.84146195}],"asks":[],"checksum":2107596437,"timestamp":"2024-06-01T22:43:01.551168Z"}]}
{"channel":"book","type":"update","data":[{"symbol":"ETH/CAD","bids":[{"price":5221.26,"qty":0.00000000},{"price":5214.12,"qty":1.92000000},{"price":5221.29,"qty":0.81727619}],"asks":[],"checksum":2413203503,"timestamp":"2024-06-01T22:43:01.845109Z"}]}
{"channel":"book","type":"update","data":[{"symbol":"ETH/CAD","bids":[],"asks":[{"price":5224.29,"qty":0.00000000},{"price":5228.01,"qty":6.06349482}],"checksum":411082252,"timestamp":"2024-06-01T22:43:01.976146Z"}]}
{"channel":"book","type":"update","data":[{"symbol":"ETH/CAD","bids":[],"asks":[{"price":5228.01,"qty":0.05131785}],"checksum":156637808,"timestamp":"2024-06-01T22:43:01.976217Z"}]}
{"channel":"book","type":"update","data":[{"symbol":"ETH/CAD","bids":[],"asks":[{"price":5224.24,"qty":1.02254724}],"checksum":3431633029,"timestamp":"2024-06-01T22:43:01.981153Z"}]}
{"channel":"book","type":"update","data":[{"symbol":"ETH/CAD","bids":[],"asks":[{"price":5227.98,"qty":9.50491779}],"checksum":1074459903,"timestamp":"2024-06-01T22:43:01.981426Z"}]}
{"channel":"book","type":"update","data":[{"symbol":"ETH/CAD","bids":[{"price":5221.28,"qty":0.00000000},{"price":5214.12,"qty":1.92000000},{"price":5221.30,"qty":0.80016485}],"asks":[],"checksum":3939121262,"timestamp":"2024-06-01T22:43:02.002000Z"}]}
{"channel":"book","type":"update","data":[{"symbol":"ETH/CAD","bids":[],"asks":[{"price":5227.97,"qty":0.22990165}],"checksum":2490113410,"timestamp":"2024-06-01T22:43:02.007455Z"}]}
{"channel":"book","type":"update","data":[{"symbol":"ETH/CAD","bids":[],"asks":[{"price":5224.26,"qty":0.00000000},{"price":5228.01,"qty":0.05131785},{"price":5224.23,"qty":0.09983515}],"checksum":1742056660,"timestamp":"2024-06-01T22:43:02.033757Z"}]}
{"channel":"book","type":"update","data":[{"symbol":"ETH/CAD","bids":[{"price":5221.29,"qty":0.00000000},{"price":5214.12,"qty":1.92000000},{"price":5221.31,"qty":0.81727307}],"asks":[],"checksum":2191692928,"timestamp":"2024-06-01T22:43:02.411238Z"}]}
{"channel":"book","type":"update","data":[{"symbol":"ETH/CAD","bids":[],"asks":[{"price":5224.25,"qty":0.00000000},{"price":5228.01,"qty":0.05131785},{"price":5224.22,"qty":0.40044603}],"checksum":1851445808,"timestamp":"2024-06-01T22:43:02.411423Z"}]}
{"channel":"book","type":"update","data":[{"symbol":"ETH/CAD","bids":[{"price":5221.32,"qty":0.90311190}],"asks":[],"checksum":2404088745,"timestamp":"2024-06-01T22:43:02.417037Z"}]}
{"channel":"book","type":"update","data":[{"symbol":"ETH/CAD","bids":[],"asks":[{"price":5224.22,"qty":1.30355793}],"checksum":670017746,"timestamp":"2024-06-01T22:43:02.417116Z"}]}
{"channel":"book","type":"update","data":[{"symbol":"ETH/CAD","bids":[],"asks":[{"price":5227.96,"qty":0.05131785}],"checksum":3632845788,"timestamp":"2024-06-01T22:43:02.524167Z"}]}
{"channel":"book","type":"update","data":[{"symbol":"ETH/CAD","bids":[],"asks":[{"price":5227.97,"qty":1.53790165}],"checksum":179211451,"timestamp":"2024-06-01T22:43:02.526287Z"}]}
{"channel":"book","type":"update","data":[{"symbol":"ETH/CAD","bids":[{"price":5221.27,"qty":0.00000000},{"price":5214.52,"qty":1.84146195}],"asks":[],"checksum":142708757,"timestamp":"2024-06-01T22:43:02.678752Z"}]}
{"channel":"book","type":"update","data":[{"symbol":"ETH/CAD","bids":[],"asks":[{"price":5224.22,"qty":0.40044603}],"checksum":2686796654,"timestamp":"2024-06-01T22:43:02.678775Z"}]}
{"channel":"book","type":"update","data":[{"symbol":"ETH/CAD","bids":[],"asks":[{"price":5227.95,"qty":0.22990165}],"checksum":1944101447,"timestamp":"2024-06-01T22:43:02.712376Z"}]}
{"channel":"book","type":"update","data":[{"symbol":"ETH/CAD","bids":[{"price":5221.30,"qty":0.00000000},{"price":5214.12,"qty":1.92000000}],"asks":[],"checksum":818141608,"timestamp":"2024-06-01T22:43:02.735641Z"}]}
{"channel":"book","type":"update","data":[{"symbol":"ETH/CAD","bids":[{"price":5221.31,"qty":0.00000000},{"price":5213.48,"qty":1.25586241},{"price":5221.33,"qty":0.81727274}],"asks":[],"checksum":511536344,"timestamp":"2024-06-01T22:43:03.004563Z"}]}
{"channel":"book","type":"update","data":[{"symbol":"ETH/CAD","bids":[{"price":5216.26,"qty":0.00000000},{"price":5213.48,"qty":1.25586241}],"asks":[],"checksum":2536938897,"timestamp":"2024-06-01T22:43:03.481561Z"}]}
{"channel":"book","type":"update","data":[{"symbol":"ETH/CAD","bids":[{"price":5216.28,"qty":4.60999580}],"asks":[],"checksum":3199810127,"timestamp":"2024-06-01T22:43:03.482872Z"}]}
{"channel":"book","type":"update","data":[{"symbol":"ETH/CAD","bids":[{"price":5216.27,"qty":0.00000000},{"price":5213.48,"qty":1.25586241},{"price":5216.25,"qty":1.30800000}],"asks":[],"checksum":3186780451,"timestamp":"2024-06-01T22:43:03.484928Z"}]}
{"channel":"book","type":"update","data":[{"symbol":"ETH/CAD","bids":[],"asks":[{"price":5227.95,"qty":0.00000000},{"price":5227.97,"qty":1.30800000}],"checksum":4230887648,"timestamp":"2024-06-01T22:43:03.545622Z"}]}
{"channel":"book","type":"update","data":[{"symbol":"ETH/CAD","bids":[{"price":5221.34,"qty":0.90311190}],"asks":[],"checksum":90816060,"timestamp":"2024-06-01T22:43:03.679044Z"}]}
{"channel":"book","type":"update","data":[{"symbol":"ETH/CAD","bids":[{"price":5221.32,"qty":0.00000000},{"price":5214.12,"qty":1.92000000}],"asks":[],"checksum":3359676353,"timestamp":"2024-06-01T22:43:03.684114Z"}]}
{"channel":"book","type":"update","data":[{"symbol":"ETH/CAD","bids":[{"price":5221.33,"qty":0.00000000},{"price":5213.48,"qty":1.25586241},{"price":5221.35,"qty":0.81727066}],"asks":[],"checksum":3587378568,"timestamp":"2024-06-01T22:43:03.728385Z"}]}
{"channel":"book","type":"update","data":[{"symbol":"ETH/CAD","bids":[],"asks":[{"price":5224.23,"qty":0.00000000},{"price":5227.98,"qty":9.50491779},{"price":5224.21,"qty":0.09983515}],"checksum":2773487135,"timestamp":"2024-06-01T22:43:04.043068Z"}]}
{"channel":"book","type":"update","data":[{"symbol":"ETH/CAD","bids":[{"price":5216.25,"qty":0.00000000},{"price":5213.48,"qty":1.25586241},{"price":5216.29,"qty":1.30800000}],"asks":[],"checksum":2120668497,"timestamp":"2024-06-01T22:43:04.046253Z"}]}
{"channel":"book","type":"update","data":[{"symbol":"ETH/CAD","bids":[],"asks":[{"price":5224.24,"qty":0.00000000},{"price":5227.98,"qty":9.50491779}],"checksum":1938521818,"timestamp":"2024-06-01T22:43:04.111816Z"}]}
{"channel":"book","type":"update","data":[{"symbol":"ETH/CAD","bids":[],"asks":[{"price":5227.98,"qty":0.00000000},{"price":5228.76,"qty":0.22990165}],"checksum":842321449,"timestamp":"2024-06-01T22:43:04.111977Z"}]}
{"channel":"book","type":"update","data":[{"symbol":"ETH/CAD","bids":[],"asks":[{"price":5228.75,"qty":19.42257719}],"checksum":641773836,"timestamp":"2024-06-01T22:43:04.112095Z"}]}
{"channel":"book","type":"update","data":[{"symbol":"ETH/CAD","bids":[],"asks":[{"price":5227.97,"qty":0.00000000},{"price":5228.76,"qty":0.22990165}],"checksum":1193178412,"timestamp":"2024-06-01T22:43:04.114948Z"}]}
{"channel":"book","type":"update","data":[{"symbol":"ETH/CAD","bids":[],"asks":[{"price":5228.76,"qty":0.00000000},{"price":5228.77,"qty":1.30800000}],"checksum":1655390365,"timestamp":"2024-06-01T22:43:04.119439Z"}]}
{"channel":"book","type":"update","data":[{"symbol":"ETH/CAD","bids":[],"asks":[{"price":5228.74,"qty":0.22990165}],"checksum":4261843334,"timestamp":"2024-06-01T22:43:04.119565Z"}]}
{"channel":"book","type":"update","data":[{"symbol":"ETH/CAD","bids":[{"price":5221.36,"qty":0.80016485}],"asks":[],"checksum":2530491895,"timestamp":"2024-06-01T22:43:04.136059Z"}]}
{"channel":"book","type":"update","data":[{"symbol":"ETH/CAD","bids":[{"price":5221.35,"qty":0.00000000},{"price":5214.12,"qty":1.92000000},{"price":5221.37,"qty":0.81726757}],"asks":[],"checksum":1471065735,"timestamp":"2024-06-01T22:43:04.292528Z"}]}
{"channel":"book","type":"update","data":[{"symbol":"ETH/CAD","bids":[],"asks":[{"price":5224.22,"qty":0.00000000},{"price":5228.77,"qty":1.30800000},{"price":5224.20,"qty":0.40043145}],"checksum":1434176697,"timestamp":"2024-06-01T22:43:04.292554Z"}]}
{"channel":"book","type":"update","data":[{"symbol":"ETH/CAD","bids":[{"price":5221.38,"qty":0.90311190}],"asks":[],"checksum":2543525753,"timestamp":"2024-06-01T22:43:04.298226Z"}]}
{"channel":"book","type":"update","data":[{"symbol":"ETH/CAD","bids":[],"asks":[{"price":5224.47,"qty":0.00000000},{"price":5228.77,"qty":1.30800000}],"checksum":4022524663,"timestamp":"2024-06-01T22:43:04.601324Z"}]}
{"channel":"book","type":"update","data":[{"symbol":"ETH/CAD","bids":[{"price":5221.34,"qty":0.00000000},{"price":5214.52,"qty":1.84146195}],"asks":[],"checksum":3636101844,"timestamp":"2024-06-01T22:43:04.606656Z"}]}
{"channel":"book","type":"update","data":[{"symbol":"ETH/CAD","bids":[{"price":5221.36,"qty":0.00000000},{"price":5214.12,"qty":1.92000000},{"price":5221.39,"qty":0.80016485}],"asks":[],"checksum":3727717553,"timestamp":"2024-06-01T22:43:04.622751Z"}]}
{"channel":"book","type":"update","data":[{"symbol":"ETH/CAD","bids":[],"asks":[{"price":5228.77,"qty":0.00000000},{"price":5228.78,"qty":1.04000000},{"price":5228.74,"qty":1.53790165}],"checksum":2080625265,"timestamp":"2024-06-01T22:43:04.625690Z"}]}
{"channel":"book","type":"update","data":[{"symbol":"ETH/CAD","bids":[],"asks":[{"price":5224.21,"qty":0.00000000},{"price":5228.84,"qty":0.12100000},{"price":5224.19,"qty":0.09983515}],"checksum":1675518775,"timestamp":"2024-06-01T22:43:04.654643Z"}]}
{"channel":"book","type":"update","data":[{"symbol":"ETH/CAD","bids":[],"asks":[{"price":5224.20,"qty":0.00000000},{"price":5228.84,"qty":0.12100000},{"price":5224.18,"qty":0.40043231}],"checksum":4080106321,"timestamp":"2024-06-01T22:43:04.947308Z"}]}
{"channel":"book","type":"update","data":[{"symbol":"ETH/CAD","bids":[{"price":5221.37,"qty":0.00000000},{"price":5214.12,"qty":1.92000000},{"price":5221.40,"qty":0.81726310}],"asks":[],"checksum":4285124178,"timestamp":"2024-06-01T22:43:04.947355Z"}]}
{"channel":"book","type":"update","data":[{"symbol":"ETH/CAD","bids":[],"asks":[{"price":5227.96,"qty":0.00000000},{"price":5228.84,"qty":0.12100000}],"checksum":109904601,"timestamp":"2024-06-01T22:43:05.188631Z"}]}
{"channel":"book","type":"update","data":[{"symbol":"ETH/CAD","bids":[],"asks":[{"price":5228.73,"qty":0.05120343}],"checksum":73248022,"timestamp":"2024-06-01T22:43:05.188900Z"}]}
{"channel":"book","type":"update","data":[{"symbol":"ETH/CAD","bids":[{"price":5221.39,"qty":0.00000000},{"price":5214.12,"qty":1.92000000},{"price":5221.41,"qty":0.80016485}],"asks":[],"checksum":415363536,"timestamp":"2024-06-01T22:43:05.202234Z"}]}
{"channel":"book","type":"update","data":[{"symbol":"ETH/CAD","bids":[],"asks":[{"price":5225.16,"qty":0.90311190}],"checksum":2711546750,"timestamp":"2024-06-01T22:43:05.207398Z"}]}
{"channel":"book","type":"update","data":[{"symbol":"ETH/CAD","bids":[{"price":5221.42,"qty":0.90311190}],"asks":[],"checksum":4067179388,"timestamp":"2024-06-01T22:43:05.207455Z"}]}
{"channel":"book","type":"update","data":[{"symbol":"ETH/CAD","bids":[],"asks":[{"price":5228.74,"qty":1.30800000}],"checksum":2438405885,"timestamp":"2024-06-01T22:43:05.213431Z"}]}
{"channel":"book","type":"update","data":[{"symbol":"ETH/CAD","bids":[],"asks":[{"price":5228.72,"qty":0.22990165}],"checksum":1851445313,"timestamp":"2024-06-01T22:43:05.213715Z"}]}
{"channel":"book","type":"update","data":[{"symbol":"ETH/CAD","bids":[{"price":5221.40,"qty":0.00000000},{"price":5214.52,"qty":1.84146195},{"price":5221.43,"qty":0.81725808}],"asks":[],"checksum":2372508624,"timestamp":"2024-06-01T22:43:05.547753Z"}]}
{"channel":"book","type":"update","data":[{"symbol":"ETH/CAD","bids":[{"price":5221.38,"qty":0.00000000},{"price":5214.52,"qty":1.84146195}],"asks":[],"checksum":4188788257,"timestamp":"2024-06-01T22:43:05.553055Z"}]}
{"channel":"book","type":"update","data":[{"symbol":"ETH/CAD","bids":[{"price":5221.41,"qty":0.00000000},{"price":5214.12,"qty":1.92000000},{"price":5221.44,"qty":0.80016485}],"asks":[],"checksum":3900045996,"timestamp":"2024-06-01T22:43:05.870908Z"}]}
{"channel":"book","type":"update","data":[{"symbol":"ETH/CAD","bids":[{"price":5221.43,"qty":0.00000000},{"price":5214.12,"qty":1.92000000},{"price":5221.45,"qty":0.81725486}],"asks":[],"checksum":3988450944,"timestamp":"2024-06-01T22:43:06.131605Z"}]}
