{"channel":"book","type":"snapshot","data":[{"symbol":"ETH/AUD","bids":[{"price":5746.71,"qty":0.08640000},{"price":5746.70,"qty":0.06633200},{"price":5746.68,"qty":1.03516910},{"price":5746.65,"qty":0.90387105},{"price":5746.53,"qty":0.02406309},{"price":5745.58,"qty":4.21098449},{"price":5743.96,"qty":1.60677000},{"price":5741.77,"qty":0.51970000},{"price":5741.76,"qty":6.14236800},{"price":5741.75,"qty":0.05631569}],"asks":[{"price":5749.31,"qty":0.90387105},{"price":5749.32,"qty":0.52888943},{"price":5749.33,"qty":0.90387105},{"price":5749.50,"qty":0.06631300},{"price":5751.45,"qty":5.51321127},{"price":5751.46,"qty":0.05899816},{"price":5751.62,"qty":0.51970000},{"price":5751.63,"qty":4.46873969},{"price":5751.64,"qty":11.18673011},{"price":5754.83,"qty":0.83372964}],"checksum":3935723551}]}
{"channel":"book","type":"update","data":[{"symbol":"ETH/AUD","bids":[],"asks":[{"price":5749.33,"qty":0.00000000},{"price":5754.84,"qty":0.07800000}],"checksum":1890802317,"timestamp":"2024-06-01T22:42:34.181376Z"}]}
{"channel":"book","type":"update","data":[{"symbol":"ETH/AUD","bids":[],"asks":[{"price":5749.32,"qty":0.00000000},{"price":5756.74,"qty":0.00413707},{"price":5749.30,"qty":0.52888960}],"checksum":2847849139,"timestamp":"2024-06-01T22:42:34.241900Z"}]}
{"channel":"book","type":"update","data":[{"symbol":"ETH/AUD","bids":[{"price":5746.68,"qty":0.00000000},{"price":5741.73,"qty":2.35323000},{"price":5746.72,"qty":1.03516208}],"asks":[],"checksum":1994251473,"timestamp":"2024-06-01T22:42:34.241978Z"}]}
{"channel":"book","type":"update","data":[{"symbol":"ETH/AUD","bids":[{"price":5746.71,"qty":0.00000000},{"price":5741.73,"qty":2.35323000},{"price":5746.73,"qty":0.08640000}],"asks":[],"checksum":1400953048,"timestamp":"2024-06-01T22:42:34.264516Z"}]}
{"channel":"book","type":"update","data":[{"symbol":"ETH/AUD","bids":[{"price":5741.75,"qty":0.00000000},{"price":5741.73,"qty":2.35323000}],"asks":[],"checksum":4228367015,"timestamp":"2024-06-01T22:42:34.656201Z"}]}
{"channel":"book","type":"update","data":[{"symbol":"ETH/AUD","bids":[{"price":5741.78,"qty":0.05631569}],"asks":[],"checksum":3761560681,"timestamp":"2024-06-01T22:42:34.658247Z"}]}
{"channel":"book","type":"update","data":[{"symbol":"ETH/AUD","bids":[],"asks":[{"price":5751.46,"qty":0.00000000},{"price":5756.74,"qty":0.00413707}],"checksum":2728748194,"timestamp":"2024-06-01T22:42:34.828692Z"}]}
{"channel":"book","type":"update","data":[{"symbol":"ETH/AUD","bids":[],"asks":[{"price":5751.44,"qty":0.05899816}],"checksum":991076003,"timestamp":"2024-06-01T22:42:34.830354Z"}]}
{"channel":"book","type":"update","data":[{"symbol":"ETH/AUD","bids":[],"asks":[{"price":5751.45,"qty":0.00000000},{"price":5756.74,"qty":0.00413707}],"checksum":389686722,"timestamp":"2024-06-01T22:42:34.875943Z"}]}
{"channel":"book","type":"update","data":[{"symbol":"ETH/AUD","bids":[],"asks":[{"price":5751.63,"qty":0.00000000},{"price":5756.88,"qty":0.22990165}],"checksum":677450459,"timestamp":"2024-06-01T22:42:34.876401Z"}]}
{"channel":"book","type":"update","data":[{"symbol":"ETH/AUD","bids":[],"asks":[{"price":5751.62,"qty":0.00000000},{"price":5756.89,"qty":1.60677000},{"price":5751.63,"qty":0.51970000}],"checksum":3202192410,"timestamp":"2024-06-01T22:42:34.879369Z"}]}
{"channel":"book","type":"update","data":[{"symbol":"ETH/AUD","bids":[],"asks":[{"price":5751.61,"qty":10.62758177}],"checksum":2066818867,"timestamp":"2024-06-01T22:42:34.881235Z"}]}
{"channel":"book","type":"update","data":[{"symbol":"ETH/AUD","bids":[{"price":5746.72,"qty":0.00000000},{"price":5741.73,"qty":2.35323000},{"price":5746.74,"qty":1.03516623}],"asks":[],"checksum":195751503,"timestamp":"2024-06-01T22:42:35.151063Z"}]}
{"channel":"book","type":"update","data":[{"symbol":"ETH/AUD","bids":[],"asks":[{"price":5749.29,"qty":0.90387105}],"checksum":764223244,"timestamp":"2024-06-01T22:42:35.156405Z"}]}
{"channel":"book","type":"update","data":[{"symbol":"ETH/AUD","bids":[],"asks":[{"price":5749.31,"qty":0.00000000},{"price":5756.74,"qty":0.00413707}],"checksum":957619471,"timestamp":"2024-06-01T22:42:35.177639Z"}]}
{"channel":"book","type":"update","data":[{"symbol":"ETH/AUD","bids":[{"price":5746.73,"qty":0.00000000},{"price":5741.73,"qty":2.35323000},{"price":5746.75,"qty":0.08640000}],"asks":[],"checksum":1303427470,"timestamp":"2024-06-01T22:42:35.206467Z"}]}
{"channel":"book","type":"update","data":[{"symbol":"ETH/AUD","bids":[{"price":5741.76,"qty":0.00000000},{"price":5741.73,"qty":2.35323000}],"asks":[],"checksum":3721819280,"timestamp":"2024-06-01T22:42:35.511964Z"}]}
{"channel":"book","type":"update","data":[{"symbol":"ETH/AUD","bids":[{"price":5741.79,"qty":6.65316677}],"asks":[],"checksum":4160915332,"timestamp":"2024-06-01T22:42:35.513363Z"}]}
{"channel":"book","type":"update","data":[{"symbol":"ETH/AUD","bids":[{"price":5741.77,"qty":0.00000000},{"price":5741.73,"qty":2.35323000},{"price":5741.74,"qty":0.51970000}],"asks":[],"checksum":3247422273,"timestamp":"2024-06-01T22:42:35.515372Z"}]}
{"channel":"book","type":"update","data":[{"symbol":"ETH/AUD","bids":[],"asks":[{"price":5751.63,"qty":0.00000000},{"price":5756.88,"qty":0.22990165},{"price":5751.60,"qty":0.51970000}],"checksum":3077070082,"timestamp":"2024-06-01T22:42:35.515526Z"}]}
{"channel":"book","type":"update","data":[{"symbol":"ETH/AUD","bids":[{"price":5746.74,"qty":0.00000000},{"price":5741.73,"qty":2.35323000},{"price":5746.76,"qty":1.03516275}],"asks":[],"checksum":1791487110,"timestamp":"2024-06-01T22:42:36.010149Z"}]}
{"channel":"book","type":"update","data":[{"symbol":"ETH/AUD","bids":[],"asks":[{"price":5749.30,"qty":0.00000000},{"price":5756.88,"qty":0.22990165},{"price":5749.28,"qty":0.52889698}],"checksum":2889514873,"timestamp":"2024-06-01T22:42:36.010349Z"}]}
{"channel":"book","type":"update","data":[{"symbol":"ETH/AUD","bids":[{"price":5746.75,"qty":0.00000000},{"price":5741.73,"qty":2.35323000},{"price":5746.77,"qty":0.08640000}],"asks":[],"checksum":976829485,"timestamp":"2024-06-01T22:42:36.025594Z"}]}
{"channel":"book","type":"update","data":[{"symbol":"ETH/AUD","bids":[{"price":5741.74,"qty":0.00000000},{"price":5741.73,"qty":2.35323000},{"price":5741.80,"qty":0.51970000}],"asks":[],"checksum":2101649371,"timestamp":"2024-06-01T22:42:36.029884Z"}]}
{"channel":"book","type":"update","data":[{"symbol":"ETH/AUD","bids":[],"asks":[{"price":5749.27,"qty":0.90387105}],"checksum":889311667,"timestamp":"2024-06-01T22:42:36.178375Z"}]}
{"channel":"book","type":"update","data":[{"symbol":"ETH/AUD","bids":[],"asks":[{"price":5749.29,"qty":0.00000000},{"price":5756.74,"qty":0.00413707}],"checksum":623041662,"timestamp":"2024-06-01T22:42:36.182838Z"}]}
{"channel":"book","type":"update","data":[{"symbol":"ETH/AUD","bids":[{"price":5746.76,"qty":0.00000000},{"price":5741.73,"qty":2.35323000},{"price":5746.78,"qty":1.03515917}],"asks":[],"checksum":487486265,"timestamp":"2024-06-01T22:42:36.863071Z"}]}
{"channel":"book","type":"update","data":[{"symbol":"ETH/AUD","bids":[],"asks":[{"price":5749.28,"qty":0.00000000},{"price":5756.88,"qty":0.22990165},{"price":5749.26,"qty":0.52889699}],"checksum":3316899934,"timestamp":"2024-06-01T22:42:36.863239Z"}]}
{"channel":"book","type":"update","data":[{"symbol":"ETH/AUD","bids":[{"price":5746.77,"qty":0.00000000},{"price":5741.73,"qty":2.35323000},{"price":5746.79,"qty":0.08640000}],"asks":[],"checksum":116083600,"timestamp":"2024-06-01T22:42:36.876786Z"}]}
{"channel":"book","type":"update","data":[{"symbol":"ETH/AUD","bids":[],"asks":[{"price":5751.61,"qty":0.00000000},{"price":5756.88,"qty":0.22990165}],"checksum":451033340,"timestamp":"2024-06-01T22:42:37.113555Z"}]}
{"channel":"book","type":"update","data":[{"symbol":"ETH/AUD","bids":[],"asks":[{"price":5751.60,"qty":0.00000000},{"price":5756.89,"qty":1.60677000},{"price":5751.63,"qty":0.51970000}],"checksum":2052503038,"timestamp":"2024-06-01T22:42:37.116810Z"}]}
{"channel":"book","type":"update","data":[{"symbol":"ETH/AUD","bids":[],"asks":[{"price":5751.59,"qty":9.13069284}],"checksum":2075814846,"timestamp":"2024-06-01T22:42:37.119094Z"}]}
{"channel":"book","type":"update","data":[{"symbol":"ETH/AUD","bids":[],"asks":[{"price":5749.25,"qty":0.90387105}],"checksum":3294335358,"timestamp":"2024-06-01T22:42:37.122256Z"}]}
{"channel":"book","type":"update","data":[{"symbol":"ETH/AUD","bids":[],"asks":[{"price":5749.27,"qty":0.00000000},{"price":5756.74,"qty":0.00413707}],"checksum":1756685931,"timestamp":"2024-06-01T22:42:37.177636Z"}]}
{"channel":"book","type":"update","data":[{"symbol":"ETH/AUD","bids":[{"price":5741.80,"qty":0.00000000},{"price":5741.73,"qty":2.35323000},{"price":5743.97,"qty":0.51970000}],"asks":[],"checksum":1640978892,"timestamp":"2024-06-01T22:42:37.385948Z"}]}
{"channel":"book","type":"update","data":[{"symbol":"ETH/AUD","bids":[],"asks":[{"price":5751.44,"qty":0.00000000},{"price":5756.88,"qty":0.22990165}],"checksum":1994134781,"timestamp":"2024-06-01T22:42:37.608850Z"}]}
{"channel":"book","type":"update","data":[{"symbol":"ETH/AUD","bids":[],"asks":[{"price":5751.58,"qty":0.06015021}],"checksum":26922812,"timestamp":"2024-06-01T22:42:37.610929Z"}]}
{"channel":"book","type":"update","data":[{"symbol":"ETH/AUD","bids":[],"asks":[{"price":5749.26,"qty":0.00000000},{"price":5756.88,"qty":0.22990165},{"price":5749.24,"qty":0.52889079}],"checksum":2410828074,"timestamp":"2024-06-01T22:42:37.702063Z"}]}
{"channel":"book","type":"update","data":[{"symbol":"ETH/AUD","bids":[],"asks":[{"price":5751.63,"qty":0.00000000},{"price":5756.88,"qty":0.22990165},{"price":5751.58,"qty":0.57985021}],"checksum":1142982313,"timestamp":"2024-06-01T22:42:37.705058Z"}]}
{"channel":"book","type":"update","data":[{"symbol":"ETH/AUD","bids":[{"price":5745.58,"qty":0.00000000},{"price":5741.73,"qty":2.35323000}],"asks":[],"checksum":1111150931,"timestamp":"2024-06-01T22:42:37.705588Z"}]}
{"channel":"book","type":"update","data":[{"symbol":"ETH/AUD","bids":[],"asks":[{"price":5749.23,"qty":0.90387105}],"checksum":2308152865,"timestamp":"2024-06-01T22:42:37.707466Z"}]}
{"channel":"book","type":"update","data":[{"symbol":"ETH/AUD","bids":[{"price":5745.85,"qty":4.21078627}],"asks":[],"checksum":1354022834,"timestamp":"2024-06-01T22:42:37.708866Z"}]}
{"channel":"book","type":"update","data":[{"symbol":"ETH/AUD","bids":[{"price":5741.78,"qty":0.00000000},{"price":5741.73,"qty":2.35323000}],"asks":[],"checksum":1161641461,"timestamp":"2024-06-01T22:42:38.098570Z"}]}
{"channel":"book","type":"update","data":[{"symbol":"ETH/AUD","bids":[{"price":5741.80,"qty":0.05120770}],"asks":[],"checksum":3111894412,"timestamp":"2024-06-01T22:42:38.099555Z"}]}
{"channel":"book","type":"update","data":[{"symbol":"ETH/AUD","bids":[],"asks":[{"price":5749.25,"qty":0.00000000},{"price":5756.88,"qty":0.22990165}],"checksum":3030698064,"timestamp":"2024-06-01T22:42:38.175112Z"}]}
{"channel":"book","type":"update","data":[{"symbol":"ETH/AUD","bids":[{"price":5741.79,"qty":0.00000000},{"price":5741.73,"qty":2.35323000}],"asks":[],"checksum":324858565,"timestamp":"2024-06-01T22:42:38.334217Z"}]}
{"channel":"book","type":"update","data":[{"symbol":"ETH/AUD","bids":[{"price":5741.74,"qty":6.65316677}],"asks":[],"checksum":1096434656,"timestamp":"2024-06-01T22:42:38.334958Z"}]}
{"channel":"book","type":"update","data":[{"symbol":"ETH/AUD","bids":[{"price":5746.78,"qty":0.00000000},{"price":5741.73,"qty":2.35323000},{"price":5746.80,"qty":1.03515392}],"asks":[],"checksum":910025922,"timestamp":"2024-06-01T22:42:38.510978Z"}]}
{"channel":"book","type":"update","data":[{"symbol":"ETH/AUD","bids":[],"asks":[{"price":5749.24,"qty":0.00000000},{"price":5756.89,"qty":1.60677000},{"price":5749.22,"qty":0.52889072}],"checksum":801153070,"timestamp":"2024-06-01T22:42:38.511115Z"}]}
{"channel":"book","type":"update","data":[{"symbol":"ETH/AUD","bids":[{"price":5746.79,"qty":0.00000000},{"price":5741.73,"qty":2.35323000},{"price":5746.81,"qty":0.08640000}],"asks":[],"checksum":3313261596,"timestamp":"2024-06-01T22:42:38.520980Z"}]}
{"channel":"book","type":"update","data":[{"symbol":"ETH/AUD","bids":[{"price":5743.97,"qty":0.00000000},{"price":5741.73,"qty":2.35323000}],"asks":[],"checksum":1540476536,"timestamp":"2024-06-01T22:42:38.664740Z"}]}
{"channel":"book","type":"update","data":[{"symbol":"ETH/AUD","bids":[],"asks":[{"price":5749.21,"qty":0.90387105}],"checksum":175172641,"timestamp":"2024-06-01T22:42:38.676355Z"}]}
{"channel":"book","type":"update","data":[{"symbol":"ETH/AUD","bids":[],"asks":[{"price":5749.23,"qty":0.00000000},{"price":5756.88,"qty":0.22990165}],"checksum":78329279,"timestamp":"2024-06-01T22:42:38.682063Z"}]}
{"channel":"book","type":"update","data":[{"symbol":"ETH/AUD","bids":[],"asks":[{"price":5754.83,"qty":0.00000000},{"price":5756.89,"qty":1.60677000}],"checksum":3890226035,"timestamp":"2024-06-01T22:42:38.707041Z"}]}
{"channel":"book","type":"update","data":[{"symbol":"ETH/AUD","bids":[],"asks":[{"price":5749.22,"qty":0.00000000},{"price":5757.84,"qty":2.35323000},{"price":5749.20,"qty":0.52889180}],"checksum":4006882320,"timestamp":"2024-06-01T22:42:39.373092Z"}]}
{"channel":"book","type":"update","data":[{"symbol":"ETH/AUD","bids":[{"price":5746.80,"qty":0.00000000},{"price":5740.82,"qty":5.07672000},{"price":5746.82,"qty":1.03516114}],"asks":[],"checksum":2999322181,"timestamp":"2024-06-01T22:42:39.373150Z"}]}
{"channel":"book","type":"update","data":[{"symbol":"ETH/AUD","bids":[],"asks":[{"price":5751.59,"qty":0.00000000},{"price":5757.84,"qty":2.35323000}],"checksum":3995845060,"timestamp":"2024-06-01T22:42:39.378013Z"}]}
{"channel":"book","type":"update","data":[{"symbol":"ETH/AUD","bids":[],"asks":[{"price":5749.19,"qty":0.90387105}],"checksum":272892673,"timestamp":"2024-06-01T22:42:39.378667Z"}]}
{"channel":"book","type":"update","data":[{"symbol":"ETH/AUD","bids":[],"asks":[{"price":5751.58,"qty":0.06015021},{"price":5751.63,"qty":0.51970000}],"checksum":3450503982,"timestamp":"2024-06-01T22:42:39.381249Z"}]}
{"channel":"book","type":"update","data":[{"symbol":"ETH/AUD","bids":[],"asks":[{"price":5751.57,"qty":9.13069284}],"checksum":3391787998,"timestamp":"2024-06-01T22:42:39.382667Z"}]}
{"channel":"book","type":"update","data":[{"symbol":"ETH/AUD","bids":[],"asks":[{"price":5749.21,"qty":0.00000000},{"price":5756.88,"qty":0.22990165}],"checksum":3698809567,"timestamp":"2024-06-01T22:42:39.675844Z"}]}
{"channel":"book","type":"update","data":[{"symbol":"ETH/AUD","bids":[{"price":5746.81,"qty":0.00000000},{"price":5740.82,"qty":5.07672000},{"price":5746.83,"qty":0.08640000}],"asks":[],"checksum":3401146662,"timestamp":"2024-06-01T22:42:39.707439Z"}]}
{"channel":"book","type":"update","data":[{"symbol":"ETH/AUD","bids":[],"asks":[{"price":5754.83,"qty":0.83372964}],"checksum":3686008932,"timestamp":"2024-06-01T22:42:39.738032Z"}]}
{"channel":"book","type":"update","data":[{"symbol":"ETH/AUD","bids":[],"asks":[{"price":5751.63,"qty":0.00000000},{"price":5756.88,"qty":0.22990165},{"price":5751.56,"qty":0.51970000}],"checksum":2392847510,"timestamp":"2024-06-01T22:42:39.881881Z"}]}
{"channel":"book","type":"update","data":[{"symbol":"ETH/AUD","bids":[],"asks":[{"price":5749.20,"qty":0.00000000},{"price":5756.88,"qty":0.22990165},{"price":5749.18,"qty":0.52889215}],"checksum":2120276260,"timestamp":"2024-06-01T22:42:40.226093Z"}]}
{"channel":"book","type":"update","data":[{"symbol":"ETH/AUD","bids":[],"asks":[{"price":5749.17,"qty":0.90387105}],"checksum":2058985875,"timestamp":"2024-06-01T22:42:40.231694Z"}]}
{"channel":"book","type":"update","data":[{"symbol":"ETH/AUD","bids":[],"asks":[{"price":5751.58,"qty":0.00000000},{"price":5756.74,"qty":0.00413707}],"checksum":1772652992,"timestamp":"2024-06-01T22:42:40.392928Z"}]}
{"channel":"book","type":"update","data":[{"symbol":"ETH/AUD","bids":[],"asks":[{"price":5751.55,"qty":0.06168627}],"checksum":3642795116,"timestamp":"2024-06-01T22:42:40.394102Z"}]}
{"channel":"book","type":"update","data":[{"symbol":"ETH/AUD","bids":[],"asks":[{"price":5749.19,"qty":0.00000000},{"price":5756.74,"qty":0.00413707}],"checksum":3706762840,"timestamp":"2024-06-01T22:42:40.399180Z"}]}
{"channel":"book","type":"update","data":[{"symbol":"ETH/AUD","bids":[{"price":5746.82,"qty":0.00000000},{"price":5741.08,"qty":0.51970000},{"price":5746.84,"qty":1.03515909}],"asks":[],"checksum":4269230931,"timestamp":"2024-06-01T22:42:41.007144Z"}]}
{"channel":"book","type":"update","data":[{"symbol":"ETH/AUD","bids":[],"asks":[{"price":5749.18,"qty":0.00000000},{"price":5756.88,"qty":0.22990165},{"price":5749.16,"qty":0.52888902}],"checksum":2920005705,"timestamp":"2024-06-01T22:42:41.007259Z"}]}
{"channel":"book","type":"update","data":[{"symbol":"ETH/AUD","bids":[{"price":5746.83,"qty":0.00000000},{"price":5741.08,"qty":0.51970000},{"price":5746.85,"qty":0.08640000}],"asks":[],"checksum":2004746153,"timestamp":"2024-06-01T22:42:41.015761Z"}]}
{"channel":"book","type":"update","data":[{"symbol":"ETH/AUD","bids":[],"asks":[{"price":5749.15,"qty":0.90387105}],"checksum":3456280146,"timestamp":"2024-06-01T22:42:41.179203Z"}]}
{"channel":"book","type":"update","data":[{"symbol":"ETH/AUD","bids":[],"asks":[{"price":5749.17,"qty":0.00000000},{"price":5756.74,"qty":0.00413707}],"checksum":3673330477,"timestamp":"2024-06-01T22:42:41.183983Z"}]}
{"channel":"book","type":"update","data":[{"symbol":"ETH/AUD","bids":[{"price":5741.74,"qty":0.00000000},{"price":5741.08,"qty":0.51970000}],"asks":[],"checksum":3056780941,"timestamp":"2024-06-01T22:42:41.209333Z"}]}
{"channel":"book","type":"update","data":[{"symbol":"ETH/AUD","bids":[{"price":5741.74,"qty":7.16396554}],"asks":[],"checksum":2663377921,"timestamp":"2024-06-01T22:42:41.210584Z"}]}
{"channel":"book","type":"update","data":[{"symbol":"ETH/AUD","bids":[{"price":5741.80,"qty":0.00000000},{"price":5741.08,"qty":0.51970000}],"asks":[],"checksum":3504715456,"timestamp":"2024-06-01T22:42:41.513625Z"}]}
{"channel":"book","type":"update","data":[{"symbol":"ETH/AUD","bids":[{"price":5741.75,"qty":0.05631569}],"asks":[],"checksum":836329663,"timestamp":"2024-06-01T22:42:41.514706Z"}]}
{"channel":"book","type":"update","data":[{"symbol":"ETH/AUD","bids":[],"asks":[{"price":5751.57,"qty":0.00000000},{"price":5756.88,"qty":0.22990165}],"checksum":383842804,"timestamp":"2024-06-01T22:42:41.640370Z"}]}
{"channel":"book","type":"update","data":[{"symbol":"ETH/AUD","bids":[],"asks":[{"price":5751.56,"qty":0.00000000},{"price":5756.89,"qty":1.60677000},{"price":5751.63,"qty":0.51970000}],"checksum":1578990845,"timestamp":"2024-06-01T22:42:41.643384Z"}]}
{"channel":"book","type":"update","data":[{"symbol":"ETH/AUD","bids":[],"asks":[{"price":5751.54,"qty":9.25543358}],"checksum":1136764256,"timestamp":"2024-06-01T22:42:41.645374Z"}]}
{"channel":"book","type":"update","data":[{"symbol":"ETH/AUD","bids":[],"asks":[{"price":5749.16,"qty":0.00000000},{"price":5756.88,"qty":0.22990165},{"price":5749.14,"qty":0.52888833}],"checksum":1496234452,"timestamp":"2024-06-01T22:42:41.830202Z"}]}
{"channel":"book","type":"update","data":[{"symbol":"ETH/AUD","bids":[],"asks":[{"price":5749.13,"qty":0.90387105}],"checksum":2353932952,"timestamp":"2024-06-01T22:42:41.835387Z"}]}
{"channel":"book","type":"update","data":[{"symbol":"ETH/AUD","bids":[],"asks":[{"price":5749.15,"qty":0.00000000},{"price":5756.74,"qty":0.00413707}],"checksum":3427697373,"timestamp":"2024-06-01T22:42:42.177291Z"}]}
{"channel":"book","type":"update","data":[{"symbol":"ETH/AUD","bids":[],"asks":[{"price":5751.63,"qty":0.00000000},{"price":5756.88,"qty":0.22990165},{"price":5751.53,"qty":0.51970000}],"checksum":1279500123,"timestamp":"2024-06-01T22:42:42.180427Z"}]}
{"channel":"book","type":"update","data":[{"symbol":"ETH/AUD","bids":[{"price":5746.84,"qty":0.00000000},{"price":5741.08,"qty":0.51970000},{"price":5746.86,"qty":1.03514791}],"asks":[],"checksum":3785752305,"timestamp":"2024-06-01T22:42:42.661592Z"}]}
{"channel":"book","type":"update","data":[{"symbol":"ETH/AUD","bids":[],"asks":[{"price":5749.14,"qty":0.00000000},{"price":5756.88,"qty":0.22990165},{"price":5749.12,"qty":0.52888824}],"checksum":3612974300,"timestamp":"2024-06-01T22:42:42.661677Z"}]}
{"channel":"book","type":"update","data":[{"symbol":"ETH/AUD","bids":[],"asks":[{"price":5749.11,"qty":0.90387105}],"checksum":3457979842,"timestamp":"2024-06-01T22:42:42.676144Z"}]}
{"channel":"book","type":"update","data":[{"symbol":"ETH/AUD","bids":[],"asks":[{"price":5749.13,"qty":0.00000000},{"price":5756.74,"qty":0.00413707}],"checksum":1136369322,"timestamp":"2024-06-01T22:42:43.176337Z"}]}
{"channel":"book","type":"update","data":[{"symbol":"ETH/AUD","bids":[],"asks":[{"price":5751.55,"qty":0.00000000},{"price":5756.88,"qty":0.22990165}],"checksum":2461462275,"timestamp":"2024-06-01T22:42:43.190930Z"}]}
{"channel":"book","type":"update","data":[{"symbol":"ETH/AUD","bids":[],"asks":[{"price":5751.52,"qty":0.05765410}],"checksum":2122822112,"timestamp":"2024-06-01T22:42:43.192927Z"}]}
{"channel":"book","type":"update","data":[{"symbol":"ETH/AUD","bids":[{"price":5746.85,"qty":0.00000000},{"price":5741.08,"qty":0.51970000},{"price":5746.87,"qty":0.08640000}],"asks":[],"checksum":3479227309,"timestamp":"2024-06-01T22:42:43.211666Z"}]}
{"channel":"book","type":"update","data":[{"symbol":"ETH/AUD","bids":[{"price":5741.75,"qty":0.57601569}],"asks":[],"checksum":1423247036,"timestamp":"2024-06-01T22:42:43.267463Z"}]}
{"channel":"book","type":"update","data":[{"symbol":"ETH/AUD","bids":[{"price":5746.86,"qty":0.00000000},{"price":5740.82,"qty":5.07672000},{"price":5746.88,"qty":1.03514286}],"asks":[],"checksum":3307597609,"timestamp":"2024-06-01T22:42:43.481796Z"}]}
{"channel":"book","type":"update","data":[{"symbol":"ETH/AUD","bids":[{"price":5746.87,"qty":0.00000000},{"price":5740.82,"qty":5.07672000},{"price":5746.89,"qty":0.08640000}],"asks":[],"checksum":1497505201,"timestamp":"2024-06-01T22:42:43.517058Z"}]}
{"channel":"book","type":"update","data":[{"symbol":"ETH/AUD","bids":[],"asks":[{"price":5751.54,"qty":0.00000000},{"price":5756.88,"qty":0.22990165}],"checksum":3905288364,"timestamp":"2024-06-01T22:42:43.875578Z"}]}
{"channel":"book","type":"update","data":[{"symbol":"ETH/AUD","bids":[],"asks":[{"price":5751.53,"qty":0.00000000},{"price":5756.89,"qty":1.60677000},{"price":5751.63,"qty":0.51970000}],"checksum":2841689393,"timestamp":"2024-06-01T22:42:43.878933Z"}]}
{"channel":"book","type":"update","data":[{"symbol":"ETH/AUD","bids":[],"asks":[{"price":5751.51,"qty":9.00595210}],"checksum":1830562588,"timestamp":"2024-06-01T22:42:43.880631Z"}]}
{"channel":"book","type":"update","data":[{"symbol":"ETH/AUD","bids":[{"price":5741.74,"qty":0.00000000},{"price":5740.82,"qty":5.07672000}],"asks":[],"checksum":3982709881,"timestamp":"2024-06-01T22:42:44.078315Z"}]}
{"channel":"book","type":"update","data":[{"symbol":"ETH/AUD","bids":[{"price":5741.76,"qty":7.16396554}],"asks":[],"checksum":911009206,"timestamp":"2024-06-01T22:42:44.079225Z"}]}
{"channel":"book","type":"update","data":[{"symbol":"ETH/AUD","bids":[{"price":5741.75,"qty":0.05631569},{"price":5741.77,"qty":0.51970000}],"asks":[],"checksum":1199275602,"timestamp":"2024-06-01T22:42:44.082447Z"}]}
{"channel":"book","type":"update","data":[{"symbol":"ETH/AUD","bids":[{"price":5746.88,"qty":0.00000000},{"price":5741.73,"qty":2.35323000},{"price":5746.90,"qty":1.03513926}],"asks":[],"checksum":2580364369,"timestamp":"2024-06-01T22:42:44.274886Z"}]}
{"channel":"book","type":"update","data":[{"symbol":"ETH/AUD","bids":[],"asks":[{"price":5749.12,"qty":0.00000000},{"price":5756.88,"qty":0.22990165},{"price":5749.10,"qty":0.52888628}],"checksum":1838943214,"timestamp":"2024-06-01T22:42:44.275001Z"}]}
{"channel":"book","type":"update","data":[{"symbol":"ETH/AUD","bids":[],"asks":[{"price":5751.64,"qty":0.00000000},{"price":5756.88,"qty":0.22990165}],"checksum":2399644407,"timestamp":"2024-06-01T22:42:44.278326Z"}]}
{"channel":"book","type":"update","data":[{"symbol":"ETH/AUD","bids":[],"asks":[{"price":5751.64,"qty":11.18671063}],"checksum":296493233,"timestamp":"2024-06-01T22:42:44.281586Z"}]}
{"channel":"book","type":"update","data":[{"symbol":"ETH/AUD","bids":[{"price":5746.89,"qty":0.00000000},{"price":5741.73,"qty":2.35323000},{"price":5746.91,"qty":0.08640000}],"asks":[],"checksum":4101098635,"timestamp":"2024-06-01T22:42:44.309088Z"}]}
{"channel":"book","type":"update","data":[{"symbol":"ETH/AUD","bids":[],"asks":[{"price":5749.09,"qty":0.90387105}],"checksum":1703791323,"timestamp":"2024-06-01T22:42:44.314702Z"}]}
{"channel":"book","type":"update","data":[{"symbol":"ETH/AUD","bids":[{"price":5746.91,"qty":0.00000000},{"price":5741.73,"qty":2.35323000},{"price":5745.86,"qty":0.08640000}],"asks":[],"checksum":2695123838,"timestamp":"2024-06-01T22:42:44.402695Z"}]}
{"channel":"book","type":"update","data":[{"symbol":"ETH/AUD","bids":[],"asks":[{"price":5751.63,"qty":0.00000000},{"price":5756.74,"qty":0.00413707},{"price":5751.50,"qty":0.51970000}],"checksum":3201727576,"timestamp":"2024-06-01T22:42:44.405796Z"}]}
{"channel":"book","type":"update","data":[{"symbol":"ETH/AUD","bids":[],"asks":[{"price":5749.11,"qty":0.00000000},{"price":5756.74,"qty":0.00413707}],"checksum":2264482147,"timestamp":"2024-06-01T22:42:44.407798Z"}]}
{"channel":"book","type":"update","data":[{"symbol":"ETH/AUD","bids":[{"price":5746.90,"qty":0.00000000},{"price":5741.73,"qty":2.35323000},{"price":5746.71,"qty":1.03517547}],"asks":[],"checksum":4294620900,"timestamp":"2024-06-01T22:42:44.433075Z"}]}
{"channel":"book","type":"update","data":[{"symbol":"ETH/AUD","bids":[{"price":5745.86,"qty":0.00000000},{"price":5741.73,"qty":2.35323000},{"price":5746.72,"qty":0.08640000}],"asks":[],"checksum":3274509531,"timestamp":"2024-06-01T22:42:44.466204Z"}]}
{"channel":"book","type":"update","data":[{"symbol":"ETH/AUD","bids":[{"price":5741.75,"qty":0.00000000},{"price":5741.73,"qty":2.35323000}],"asks":[],"checksum":1452545796,"timestamp":"2024-06-01T22:42:44.947324Z"}]}
{"channel":"book","type":"update","data":[{"symbol":"ETH/AUD","bids":[{"price":5741.78,"qty":0.05631569}],"asks":[],"checksum":951271769,"timestamp":"2024-06-01T22:42:44.948595Z"}]}
{"channel":"book","type":"update","data":[{"symbol":"ETH/AUD","bids":[{"price":5746.71,"qty":0.00000000},{"price":5741.73,"qty":2.35323000},{"price":5746.73,"qty":1.03517199}],"asks":[],"checksum":3935407868,"timestamp":"2024-06-01T22:42:45.050301Z"}]}
{"channel":"book","type":"update","data":[{"symbol":"ETH/AUD","bids":[{"price":5746.72,"qty":0.00000000},{"price":5741.73,"qty":2.35323000},{"price":5746.74,"qty":0.08640000}],"asks":[],"checksum":3782594046,"timestamp":"2024-06-01T22:42:45.075267Z"}]}
{"channel":"book","type":"update","data":[{"symbol":"ETH/AUD","bids":[{"price":5746.73,"qty":0.00000000},{"price":5741.73,"qty":2.35323000},{"price":5746.75,"qty":1.03516853}],"asks":[],"checksum":766486033,"timestamp":"2024-06-01T22:42:45.896212Z"}]}
{"channel":"book","type":"update","data":[{"symbol":"ETH/AUD","bids":[],"asks":[{"price":5749.10,"qty":0.00000000},{"price":5756.88,"qty":0.22990165},{"price":5749.08,"qty":0.52888864}],"checksum":1099000598,"timestamp":"2024-06-01T22:42:45.896340Z"}]}
{"channel":"book","type":"update","data":[{"symbol":"ETH/AUD","bids":[{"price":5746.74,"qty":0.00000000},{"price":5741.73,"qty":2.35323000},{"price":5746.76,"qty":0.08640000}],"asks":[],"checksum":543084487,"timestamp":"2024-06-01T22:42:45.929565Z"}]}
{"channel":"book","type":"update","data":[{"symbol":"ETH/AUD","bids":[],"asks":[{"price":5749.07,"qty":0.90387105}],"checksum":361952671,"timestamp":"2024-06-01T22:42:45.934779Z"}]}
{"channel":"book","type":"update","data":[{"symbol":"ETH/AUD","bids":[],"asks":[{"price":5751.52,"qty":0.00000000},{"price":5756.74,"qty":0.00413707}],"checksum":1921407087,"timestamp":"2024-06-01T22:42:45.956359Z"}]}
{"channel":"book","type":"update","data":[{"symbol":"ETH/AUD","bids":[],"asks":[{"price":5751.49,"qty":0.06168627}],"checksum":3447579903,"timestamp":"2024-06-01T22:42:45.958227Z"}]}
{"channel":"book","type":"update","data":[{"symbol":"ETH/AUD","bids":[],"asks":[{"price":5749.09,"qty":0.00000000},{"price":5756.74,"qty":0.00413707}],"checksum":1224393284,"timestamp":"2024-06-01T22:42:46.177010Z"}]}
{"channel":"book","type":"update","data":[{"symbol":"ETH/AUD","bids":[],"asks":[{"price":5751.51,"qty":0.00000000},{"price":5756.88,"qty":0.22990165}],"checksum":1084777056,"timestamp":"2024-06-01T22:42:46.183287Z"}]}
{"channel":"book","type":"update","data":[{"symbol":"ETH/AUD","bids":[],"asks":[{"price":5751.50,"qty":0.00000000},{"price":5756.89,"qty":1.60677000},{"price":5751.63,"qty":0.51970000}],"checksum":3463592643,"timestamp":"2024-06-01T22:42:46.186534Z"}]}
{"channel":"book","type":"update","data":[{"symbol":"ETH/AUD","bids":[],"asks":[{"price":5751.49,"qty":8.06971242}],"checksum":170388705,"timestamp":"2024-06-01T22:42:46.188098Z"}]}
{"channel":"book","type":"update","data":[{"symbol":"ETH/AUD","bids":[],"asks":[{"price":5751.63,"qty":2.50093384}],"checksum":525302016,"timestamp":"2024-06-01T22:42:46.188273Z"}]}
{"channel":"book","type":"update","data":[{"symbol":"ETH/AUD","bids":[{"price":5746.75,"qty":0.00000000},{"price":5741.73,"qty":2.35323000},{"price":5746.77,"qty":1.03516498}],"asks":[],"checksum":3840112806,"timestamp":"2024-06-01T22:42:46.731294Z"}]}
{"channel":"book","type":"update","data":[{"symbol":"ETH/AUD","bids":[],"asks":[{"price":5749.08,"qty":0.00000000},{"price":5756.89,"qty":1.60677000},{"price":5749.06,"qty":0.52888879}],"checksum":829057312,"timestamp":"2024-06-01T22:42:46.731468Z"}]}
{"channel":"book","type":"update","data":[{"symbol":"ETH/AUD","bids":[],"asks":[{"price":5751.63,"qty":1.98123384},{"price":5751.48,"qty":0.51970000}],"checksum":1134831950,"timestamp":"2024-06-01T22:42:46.734492Z"}]}
{"channel":"book","type":"update","data":[{"symbol":"ETH/AUD","bids":[{"price":5746.76,"qty":0.00000000},{"price":5741.73,"qty":2.35323000},{"price":5746.78,"qty":0.08640000}],"asks":[],"checksum":2765051938,"timestamp":"2024-06-01T22:42:46.748843Z"}]}
{"channel":"book","type":"update","data":[{"symbol":"ETH/AUD","bids":[{"price":5741.76,"qty":0.00000000},{"price":5741.73,"qty":2.35323000}],"asks":[],"checksum":1197733981,"timestamp":"2024-06-01T22:42:46.925968Z"}]}
{"channel":"book","type":"update","data":[{"symbol":"ETH/AUD","bids":[{"price":5741.79,"qty":7.16396554}],"asks":[],"checksum":4201440542,"timestamp":"2024-06-01T22:42:46.927354Z"}]}
{"channel":"book","type":"update","data":[{"symbol":"ETH/AUD","bids":[{"price":5741.77,"qty":0.00000000},{"price":5741.73,"qty":2.35323000},{"price":5741.74,"qty":0.51970000}],"asks":[],"checksum":3286358491,"timestamp":"2024-06-01T22:42:46.928975Z"}]}
{"channel":"book","type":"update","data":[{"symbol":"ETH/AUD","bids":[],"asks":[{"price":5749.05,"qty":0.90387105}],"checksum":1279599637,"timestamp":"2024-06-01T22:42:47.176700Z"}]}
{"channel":"book","type":"update","data":[{"symbol":"ETH/AUD","bids":[],"asks":[{"price":5749.07,"qty":0.00000000},{"price":5756.74,"qty":0.00413707}],"checksum":2699321904,"timestamp":"2024-06-01T22:42:47.181785Z"}]}
{"channel":"book","type":"update","data":[{"symbol":"ETH/AUD","bids":[{"price":5746.77,"qty":0.00000000},{"price":5741.73,"qty":2.35323000},{"price":5746.79,"qty":1.03516865}],"asks":[],"checksum":4010921761,"timestamp":"2024-06-01T22:42:47.554359Z"}]}
{"channel":"book","type":"update","data":[{"symbol":"ETH/AUD","bids":[],"asks":[{"price":5749.06,"qty":0.00000000},{"price":5756.88,"qty":0.22990165},{"price":5749.04,"qty":0.52887040}],"checksum":3716099615,"timestamp":"2024-06-01T22:42:47.554521Z"}]}
{"channel":"book","type":"update","data":[{"symbol":"ETH/AUD","bids":[{"price":5741.74,"qty":0.00000000},{"price":5741.73,"qty":2.35323000},{"price":5741.80,"qty":0.51970000}],"asks":[],"checksum":968966744,"timestamp":"2024-06-01T22:42:47.557696Z"}]}
{"channel":"book","type":"update","data":[{"symbol":"ETH/AUD","bids":[{"price":5746.78,"qty":0.00000000},{"price":5741.73,"qty":2.35323000},{"price":5746.80,"qty":0.08640000}],"asks":[],"checksum":1782934074,"timestamp":"2024-06-01T22:42:47.569560Z"}]}
{"channel":"book","type":"update","data":[{"symbol":"ETH/AUD","bids":[{"price":5741.78,"qty":0.00000000},{"price":5741.73,"qty":2.35323000}],"asks":[],"checksum":1088303900,"timestamp":"2024-06-01T22:42:48.343589Z"}]}
{"channel":"book","type":"update","data":[{"symbol":"ETH/AUD","bids":[{"price":5741.81,"qty":0.04609972}],"asks":[],"checksum":1112498714,"timestamp":"2024-06-01T22:42:48.344400Z"}]}
{"channel":"book","type":"update","data":[{"symbol":"ETH/AUD","bids":[{"price":5746.79,"qty":0.00000000},{"price":5741.73,"qty":2.35323000},{"price":5746.81,"qty":1.03516565}],"asks":[],"checksum":1241914604,"timestamp":"2024-06-01T22:42:48.364370Z"}]}
{"channel":"book","type":"update","data":[{"symbol":"ETH/AUD","bids":[{"price":5746.80,"qty":0.00000000},{"price":5741.73,"qty":2.35323000},{"price":5746.82,"qty":0.08640000}],"asks":[],"checksum":3957365114,"timestamp":"2024-06-01T22:42:48.388865Z"}]}
{"channel":"book","type":"update","data":[{"symbol":"ETH/AUD","bids":[],"asks":[{"price":5751.49,"qty":0.06168627}],"checksum":3770683274,"timestamp":"2024-06-01T22:42:48.433165Z"}]}
{"channel":"book","type":"update","data":[{"symbol":"ETH/AUD","bids":[],"asks":[{"price":5751.48,"qty":0.00000000},{"price":5756.88,"qty":0.22990165},{"price":5751.62,"qty":0.51970000}],"checksum":2154057611,"timestamp":"2024-06-01T22:42:48.436100Z"}]}
{"channel":"book","type":"update","data":[{"symbol":"ETH/AUD","bids":[],"asks":[{"price":5751.47,"qty":7.01204927}],"checksum":3214766637,"timestamp":"2024-06-01T22:42:48.438186Z"}]}
{"channel":"book","type":"update","data":[{"symbol":"ETH/AUD","bids":[],"asks":[{"price":5751.49,"qty":0.00000000},{"price":5756.74,"qty":0.00413707}],"checksum":3625641870,"timestamp":"2024-06-01T22:42:48.783720Z"}]}
{"channel":"book","type":"update","data":[{"symbol":"ETH/AUD","bids":[],"asks":[{"price":5751.46,"qty":0.05765410}],"checksum":2176048096,"timestamp":"2024-06-01T22:42:48.786424Z"}]}
{"channel":"book","type":"update","data":[{"symbol":"ETH/AUD","bids":[{"price":5746.81,"qty":0.00000000},{"price":5741.73,"qty":2.35323000},{"price":5746.83,"qty":1.03516645}],"asks":[],"checksum":2629138806,"timestamp":"2024-06-01T22:42:49.231968Z"}]}
{"channel":"book","type":"update","data":[{"symbol":"ETH/AUD","bids":[],"asks":[{"price":5751.62,"qty":0.00000000},{"price":5756.74,"qty":0.00413707},{"price":5751.46,"qty":0.57735410}],"checksum":3376353037,"timestamp":"2024-06-01T22:42:49.235122Z"}]}
{"channel":"book","type":"update","data":[{"symbol":"ETH/AUD","bids":[{"price":5746.82,"qty":0.00000000},{"price":5741.73,"qty":2.35323000},{"price":5746.84,"qty":0.08640000}],"asks":[],"checksum":1236100130,"timestamp":"2024-06-01T22:42:49.241971Z"}]}
{"channel":"book","type":"update","data":[{"symbol":"ETH/AUD","bids":[{"price":5741.79,"qty":0.00000000},{"price":5741.73,"qty":2.35323000}],"asks":[],"checksum":1527422928,"timestamp":"2024-06-01T22:42:49.801420Z"}]}
{"channel":"book","type":"update","data":[{"symbol":"ETH/AUD","bids":[{"price":5741.82,"qty":7.16396554}],"asks":[],"checksum":405991981,"timestamp":"2024-06-01T22:42:49.801854Z"}]}
{"channel":"book","type":"update","data":[{"symbol":"ETH/AUD","bids":[{"price":5741.80,"qty":0.00000000},{"price":5741.73,"qty":2.35323000},{"price":5741.74,"qty":0.51970000}],"asks":[],"checksum":3033921708,"timestamp":"2024-06-01T22:42:49.804366Z"}]}
{"channel":"book","type":"update","data":[{"symbol":"ETH/AUD","bids":[],"asks":[{"price":5754.83,"qty":0.00000000},{"price":5756.88,"qty":0.22990165}],"checksum":3099059831,"timestamp":"2024-06-01T22:42:50.000450Z"}]}
{"channel":"book","type":"update","data":[{"symbol":"ETH/AUD","bids":[{"price":5746.83,"qty":0.00000000},{"price":5741.73,"qty":2.35323000},{"price":5746.85,"qty":1.03516276}],"asks":[],"checksum":1606461340,"timestamp":"2024-06-01T22:42:50.047442Z"}]}
{"channel":"book","type":"update","data":[{"symbol":"ETH/AUD","bids":[{"price":5746.84,"qty":0.00000000},{"price":5741.73,"qty":2.35323000},{"price":5746.86,"qty":0.08640000}],"asks":[],"checksum":373197143,"timestamp":"2024-06-01T22:42:50.062898Z"}]}
{"channel":"book","type":"update","data":[{"symbol":"ETH/AUD","bids":[{"price":5741.74,"qty":0.00000000},{"price":5741.73,"qty":2.35323000},{"price":5741.83,"qty":0.51970000}],"asks":[],"checksum":1864552343,"timestamp":"2024-06-01T22:42:50.371516Z"}]}
{"channel":"book","type":"update","data":[{"symbol":"ETH/AUD","bids":[],"asks":[{"price":5749.50,"qty":0.00000000},{"price":5756.89,"qty":1.60677000},{"price":5749.03,"qty":0.06631800}],"checksum":916058621,"timestamp":"2024-06-01T22:42:50.398843Z"}]}
{"channel":"book","type":"update","data":[{"symbol":"ETH/AUD","bids":[],"asks":[{"price":5751.64,"qty":12.02044027}],"checksum":2818151292,"timestamp":"2024-06-01T22:42:50.407494Z"}]}
{"channel":"book","type":"update","data":[{"symbol":"ETH/AUD","bids":[],"asks":[{"price":5751.47,"qty":0.00000000},{"price":5756.89,"qty":1.60677000}],"checksum":4016005460,"timestamp":"2024-06-01T22:42:50.720310Z"}]}
{"channel":"book","type":"update","data":[{"symbol":"ETH/AUD","bids":[],"asks":[{"price":5751.63,"qty":0.00000000},{"price":5757.84,"qty":2.35323000}],"checksum":2370298357,"timestamp":"2024-06-01T22:42:50.720412Z"}]}
{"channel":"book","type":"update","data":[{"symbol":"ETH/AUD","bids":[],"asks":[{"price":5751.46,"qty":0.05765410},{"price":5751.63,"qty":0.51970000}],"checksum":2208733487,"timestamp":"2024-06-01T22:42:50.723718Z"}]}
{"channel":"book","type":"update","data":[{"symbol":"ETH/AUD","bids":[],"asks":[{"price":5751.45,"qty":6.01217425}],"checksum":4256415502,"timestamp":"2024-06-01T22:42:50.725642Z"}]}
{"channel":"book","type":"update","data":[{"symbol":"ETH/AUD","bids":[],"asks":[{"price":5751.63,"qty":3.00111499}],"checksum":2160306088,"timestamp":"2024-06-01T22:42:50.725732Z"}]}
{"channel":"book","type":"update","data":[{"symbol":"ETH/AUD","bids":[],"asks":[{"price":5749.04,"qty":0.00000000},{"price":5756.89,"qty":1.60677000},{"price":5749.02,"qty":0.52887722}],"checksum":3840485938,"timestamp":"2024-06-01T22:42:50.796377Z"}]}
{"channel":"book","type":"update","data":[{"symbol":"ETH/AUD","bids":[{"price":5746.87,"qty":0.01738799}],"asks":[],"checksum":3829126094,"timestamp":"2024-06-01T22:42:50.886316Z"}]}
{"channel":"book","type":"update","data":[{"symbol":"ETH/AUD","bids":[{"price":5746.86,"qty":0.00000000},{"price":5741.81,"qty":0.04609972},{"price":5746.88,"qty":0.08640000}],"asks":[],"checksum":3779942987,"timestamp":"2024-06-01T22:42:50.915690Z"}]}
{"channel":"book","type":"update","data":[{"symbol":"ETH/AUD","bids":[{"price":5746.53,"qty":0.00000000},{"price":5741.81,"qty":0.04609972}],"asks":[],"checksum":3634231655,"timestamp":"2024-06-01T22:42:51.084008Z"}]}
{"channel":"book","type":"update","data":[{"symbol":"ETH/AUD","bids":[],"asks":[{"price":5751.63,"qty":2.48141499},{"price":5751.44,"qty":0.51970000}],"checksum":2272068071,"timestamp":"2024-06-01T22:42:51.291079Z"}]}
{"channel":"book","type":"update","data":[{"symbol":"ETH/AUD","bids":[{"price":5746.88,"qty":0.00000000},{"price":5741.73,"qty":2.35323000},{"price":5745.86,"qty":0.08640000}],"asks":[],"checksum":4022001816,"timestamp":"2024-06-01T22:42:51.312211Z"}]}
{"channel":"book","type":"update","data":[{"symbol":"ETH/AUD","bids":[],"asks":[{"price":5751.46,"qty":0.00000000},{"price":5756.88,"qty":0.22990165}],"checksum":2849404389,"timestamp":"2024-06-01T22:42:51.452559Z"}]}
{"channel":"book","type":"update","data":[{"symbol":"ETH/AUD","bids":[],"asks":[{"price":5751.44,"qty":0.57735410}],"checksum":1128759166,"timestamp":"2024-06-01T22:42:51.455349Z"}]}
{"channel":"book","type":"update","data":[{"symbol":"ETH/AUD","bids":[{"price":5745.86,"qty":0.00000000},{"price":5741.73,"qty":2.35323000},{"price":5746.88,"qty":0.08640000}],"asks":[],"checksum":730897921,"timestamp":"2024-06-01T22:42:51.465940Z"}]}
{"channel":"book","type":"update","data":[{"symbol":"ETH/AUD","bids":[{"price":5746.85,"qty":0.00000000},{"price":5741.73,"qty":2.35323000},{"price":5746.89,"qty":1.03515144}],"asks":[],"checksum":2494221465,"timestamp":"2024-06-01T22:42:51.504127Z"}]}
{"channel":"book","type":"update","data":[{"symbol":"ETH/AUD","bids":[{"price":5746.88,"qty":0.00000000},{"price":5741.73,"qty":2.35323000},{"price":5746.90,"qty":0.08640000}],"asks":[],"checksum":4025607292,"timestamp":"2024-06-01T22:42:51.529739Z"}]}
{"channel":"book","type":"update","data":[{"symbol":"ETH/AUD","bids":[{"price":5745.85,"qty":0.00000000},{"price":5741.73,"qty":2.35323000}],"asks":[],"checksum":3709346659,"timestamp":"2024-06-01T22:42:51.672423Z"}]}
{"channel":"book","type":"update","data":[{"symbol":"ETH/AUD","bids":[{"price":5746.65,"qty":0.00000000},{"price":5740.82,"qty":5.07672000}],"asks":[],"checksum":2041198094,"timestamp":"2024-06-01T22:42:51.677710Z"}]}
{"channel":"book","type":"update","data":[{"symbol":"ETH/AUD","bids":[],"asks":[{"price":5749.01,"qty":0.90387105}],"checksum":1843488723,"timestamp":"2024-06-01T22:42:51.677858Z"}]}
{"channel":"book","type":"update","data":[{"symbol":"ETH/AUD","bids":[{"price":5746.07,"qty":0.90387105}],"asks":[],"checksum":2520873668,"timestamp":"2024-06-01T22:42:51.677983Z"}]}
{"channel":"book","type":"update","data":[{"symbol":"ETH/AUD","bids":[{"price":5745.82,"qty":4.21080829}],"asks":[],"checksum":2167784338,"timestamp":"2024-06-01T22:42:51.678104Z"}]}
{"channel":"book","type":"update","data":[{"symbol":"ETH/AUD","bids":[],"asks":[{"price":5749.05,"qty":0.00000000},{"price":5756.88,"qty":0.22990165}],"checksum":2833286776,"timestamp":"2024-06-01T22:42:51.682708Z"}]}
{"channel":"book","type":"update","data":[{"symbol":"ETH/AUD","bids":[{"price":5741.81,"qty":0.00000000},{"price":5741.73,"qty":2.35323000}],"asks":[],"checksum":4279845975,"timestamp":"2024-06-01T22:42:51.766357Z"}]}
{"channel":"book","type":"update","data":[{"symbol":"ETH/AUD","bids":[{"price":5741.84,"qty":0.04609972}],"asks":[],"checksum":4045519759,"timestamp":"2024-06-01T22:42:51.767972Z"}]}
{"channel":"book","type":"update","data":[{"symbol":"ETH/AUD","bids":[{"price":5746.89,"qty":0.00000000},{"price":5741.73,"qty":2.35323000},{"price":5746.91,"qty":1.03514781}],"asks":[],"checksum":3512601863,"timestamp":"2024-06-01T22:42:52.257603Z"}]}
{"channel":"book","type":"update","data":[{"symbol":"ETH/AUD","bids":[],"asks":[{"price":5749.02,"qty":0.00000000},{"price":5756.89,"qty":1.60677000},{"price":5749.00,"qty":0.52887687}],"checksum":2909392323,"timestamp":"2024-06-01T22:42:52.257800Z"}]}
{"channel":"book","type":"update","data":[{"symbol":"ETH/AUD","bids":[{"price":5746.90,"qty":0.00000000},{"price":5741.73,"qty":2.35323000},{"price":5746.92,"qty":0.08640000}],"asks":[],"checksum":1327339845,"timestamp":"2024-06-01T22:42:52.291324Z"}]}
{"channel":"book","type":"update","data":[{"symbol":"ETH/AUD","bids":[],"asks":[{"price":5751.64,"qty":11.18671063}],"checksum":3732798404,"timestamp":"2024-06-01T22:42:52.335292Z"}]}
{"channel":"book","type":"update","data":[{"symbol":"ETH/AUD","bids":[],"asks":[{"price":5754.83,"qty":0.83372964}],"checksum":3525305631,"timestamp":"2024-06-01T22:42:52.366054Z"}]}
{"channel":"book","type":"update","data":[{"symbol":"ETH/AUD","bids":[{"price":5741.82,"qty":0.00000000},{"price":5741.73,"qty":2.35323000}],"asks":[],"checksum":2879394268,"timestamp":"2024-06-01T22:42:52.686553Z"}]}
{"channel":"book","type":"update","data":[{"symbol":"ETH/AUD","bids":[{"price":5741.85,"qty":6.65320157}],"asks":[],"checksum":480950541,"timestamp":"2024-06-01T22:42:52.687169Z"}]}
{"channel":"book","type":"update","data":[{"symbol":"ETH/AUD","bids":[{"price":5741.83,"qty":0.00000000},{"price":5741.73,"qty":2.35323000},{"price":5741.74,"qty":0.51970000}],"asks":[],"checksum":2311098185,"timestamp":"2024-06-01T22:42:52.689763Z"}]}
{"channel":"book","type":"update","data":[{"symbol":"ETH/AUD","bids":[],"asks":[{"price":5751.63,"qty":0.00000000},{"price":5756.88,"qty":0.22990165}],"checksum":1196327573,"timestamp":"2024-06-01T22:42:52.924413Z"}]}
{"channel":"book","type":"update","data":[{"symbol":"ETH/AUD","bids":[],"asks":[{"price":5751.45,"qty":0.00000000},{"price":5756.89,"qty":1.60677000}],"checksum":56562004,"timestamp":"2024-06-01T22:42:52.924794Z"}]}
{"channel":"book","type":"update","data":[{"symbol":"ETH/AUD","bids":[],"asks":[{"price":5751.43,"qty":5.51322586}],"checksum":1871689285,"timestamp":"2024-06-01T22:42:52.929775Z"}]}
{"channel":"book","type":"update","data":[{"symbol":"ETH/AUD","bids":[],"asks":[{"price":5751.63,"qty":3.97221300}],"checksum":1881779030,"timestamp":"2024-06-01T22:42:52.930002Z"}]}
{"channel":"book","type":"update","data":[{"symbol":"ETH/AUD","bids":[],"asks":[{"price":5751.44,"qty":0.05765410},{"price":5751.42,"qty":0.51970000}],"checksum":1963885825,"timestamp":"2024-06-01T22:42:52.932960Z"}]}
{"channel":"book","type":"update","data":[{"symbol":"ETH/AUD","bids":[{"price":5746.91,"qty":0.00000000},{"price":5741.73,"qty":2.35323000},{"price":5746.93,"qty":1.03514431}],"asks":[],"checksum":1576045190,"timestamp":"2024-06-01T22:42:52.983227Z"}]}
{"channel":"book","type":"update","data":[{"symbol":"ETH/AUD","bids":[{"price":5746.93,"qty":0.00000000},{"price":5741.73,"qty":2.35323000},{"price":5746.94,"qty":1.03514307}],"asks":[],"checksum":2242388163,"timestamp":"2024-06-01T22:42:53.682319Z"}]}
{"channel":"book","type":"update","data":[{"symbol":"ETH/AUD","bids":[{"price":5741.74,"qty":0.00000000},{"price":5741.73,"qty":2.35323000},{"price":5741.86,"qty":0.51970000}],"asks":[],"checksum":1956225632,"timestamp":"2024-06-01T22:42:53.685331Z"}]}
{"channel":"book","type":"update","data":[{"symbol":"ETH/AUD","bids":[{"price":5746.92,"qty":0.00000000},{"price":5741.73,"qty":2.35323000},{"price":5746.08,"qty":0.08640000}],"asks":[],"checksum":163920796,"timestamp":"2024-06-01T22:42:53.721380Z"}]}
{"channel":"book","type":"update","data":[{"symbol":"ETH/AUD","bids":[{"price":5746.94,"qty":0.00000000},{"price":5741.73,"qty":2.35323000},{"price":5746.93,"qty":1.03514502}],"asks":[],"checksum":3486002161,"timestamp":"2024-06-01T22:42:53.747874Z"}]}
{"channel":"book","type":"update","data":[{"symbol":"ETH/AUD","bids":[{"price":5746.93,"qty":0.00000000},{"price":5741.73,"qty":2.35323000},{"price":5746.88,"qty":1.03515403}],"asks":[],"checksum":645444511,"timestamp":"2024-06-01T22:42:53.770580Z"}]}
{"channel":"book","type":"update","data":[{"symbol":"ETH/AUD","bids":[],"asks":[{"price":5751.44,"qty":0.00000000},{"price":5756.74,"qty":0.00413707}],"checksum":116752899,"timestamp":"2024-06-01T22:42:54.286383Z"}]}
{"channel":"book","type":"update","data":[{"symbol":"ETH/AUD","bids":[],"asks":[{"price":5751.41,"qty":0.05765420}],"checksum":1384858713,"timestamp":"2024-06-01T22:42:54.287788Z"}]}
{"channel":"book","type":"update","data":[{"symbol":"ETH/AUD","bids":[{"price":5741.84,"qty":0.00000000},{"price":5741.73,"qty":2.35323000}],"asks":[],"checksum":3771056903,"timestamp":"2024-06-01T22:42:55.171974Z"}]}
{"channel":"book","type":"update","data":[{"symbol":"ETH/AUD","bids":[{"price":5741.87,"qty":0.05120868}],"asks":[],"checksum":1924586659,"timestamp":"2024-06-01T22:42:55.173017Z"}]}
{"channel":"book","type":"update","data":[{"symbol":"ETH/AUD","bids":[],"asks":[{"price":5751.43,"qty":0.00000000},{"price":5756.74,"qty":0.00413707}],"checksum":3732415050,"timestamp":"2024-06-01T22:42:55.226723Z"}]}
{"channel":"book","type":"update","data":[{"symbol":"ETH/AUD","bids":[],"asks":[{"price":5751.63,"qty":0.00000000},{"price":5756.88,"qty":0.22990165}],"checksum":195012942,"timestamp":"2024-06-01T22:42:55.226986Z"}]}
{"channel":"book","type":"update","data":[{"symbol":"ETH/AUD","bids":[],"asks":[{"price":5751.40,"qty":4.01633232}],"checksum":2055184474,"timestamp":"2024-06-01T22:42:55.229119Z"}]}
{"channel":"book","type":"update","data":[{"symbol":"ETH/AUD","bids":[],"asks":[{"price":5751.63,"qty":4.97257530}],"checksum":917260729,"timestamp":"2024-06-01T22:42:55.229140Z"}]}
{"channel":"book","type":"update","data":[{"symbol":"ETH/AUD","bids":[],"asks":[{"price":5751.42,"qty":0.00000000},{"price":5756.74,"qty":0.00413707},{"price":5751.62,"qty":0.51970000}],"checksum":3875271463,"timestamp":"2024-06-01T22:42:55.230260Z"}]}
{"channel":"book","type":"update","data":[{"symbol":"ETH/AUD","bids":[{"price":5741.85,"qty":0.00000000},{"price":5741.73,"qty":2.35323000}],"asks":[],"checksum":2641726705,"timestamp":"2024-06-01T22:42:55.534300Z"}]}
{"channel":"book","type":"update","data":[{"symbol":"ETH/AUD","bids":[{"price":5741.88,"qty":6.65329399}],"asks":[],"checksum":2938629794,"timestamp":"2024-06-01T22:42:55.535973Z"}]}
{"channel":"book","type":"update","data":[{"symbol":"ETH/AUD","bids":[{"price":5741.86,"qty":0.00000000},{"price":5741.73,"qty":2.35323000},{"price":5741.74,"qty":0.51970000}],"asks":[],"checksum":1893375401,"timestamp":"2024-06-01T22:42:55.537313Z"}]}
{"channel":"book","type":"update","data":[{"symbol":"ETH/AUD","bids":[],"asks":[{"price":5751.62,"qty":0.00000000},{"price":5756.74,"qty":0.00413707},{"price":5751.39,"qty":0.51970000}],"checksum":3428956499,"timestamp":"2024-06-01T22:42:56.213886Z"}]}
{"channel":"book","type":"update","data":[{"symbol":"ETH/AUD","bids":[{"price":5741.74,"qty":0.00000000},{"price":5741.73,"qty":2.35323000},{"price":5741.89,"qty":0.51970000}],"asks":[],"checksum":2872986704,"timestamp":"2024-06-01T22:42:56.214012Z"}]}
{"channel":"book","type":"update","data":[{"symbol":"ETH/AUD","bids":[{"price":5741.89,"qty":0.00000000},{"price":5741.73,"qty":2.35323000}],"asks":[],"checksum":4138277879,"timestamp":"2024-06-01T22:42:56.403766Z"}]}
{"channel":"book","type":"update","data":[{"symbol":"ETH/AUD","bids":[],"asks":[{"price":5749.03,"qty":0.00000000},{"price":5756.74,"qty":0.00413707},{"price":5749.46,"qty":0.06631400}],"checksum":2496203248,"timestamp":"2024-06-01T22:42:56.580602Z"}]}
{"channel":"book","type":"update","data":[{"symbol":"ETH/AUD","bids":[],"asks":[{"price":5751.41,"qty":0.00000000},{"price":5756.74,"qty":0.00413707}],"checksum":4046725390,"timestamp":"2024-06-01T22:42:57.027947Z"}]}
{"channel":"book","type":"update","data":[{"symbol":"ETH/AUD","bids":[],"asks":[{"price":5751.38,"qty":0.06283835}],"checksum":1153778433,"timestamp":"2024-06-01T22:42:57.029881Z"}]}
{"channel":"book","type":"update","data":[{"symbol":"ETH/AUD","bids":[],"asks":[{"price":5754.83,"qty":0.00000000},{"price":5756.74,"qty":0.00413707}],"checksum":3550624955,"timestamp":"2024-06-01T22:42:57.169989Z"}]}
{"channel":"book","type":"update","data":[{"symbol":"ETH/AUD","bids":[],"asks":[{"price":5751.62,"qty":0.83372964}],"checksum":2978116618,"timestamp":"2024-06-01T22:42:57.201865Z"}]}
{"channel":"book","type":"update","data":[{"symbol":"ETH/AUD","bids":[{"price":5741.89,"qty":0.51970000}],"asks":[],"checksum":849268414,"timestamp":"2024-06-01T22:42:57.265696Z"}]}
{"channel":"book","type":"update","data":[{"symbol":"ETH/AUD","bids":[],"asks":[{"price":5751.40,"qty":0.00000000},{"price":5756.74,"qty":0.00413707}],"checksum":36894270,"timestamp":"2024-06-01T22:42:57.516454Z"}]}
{"channel":"book","type":"update","data":[{"symbol":"ETH/AUD","bids":[],"asks":[{"price":5751.63,"qty":0.00000000},{"price":5756.88,"qty":0.22990165}],"checksum":2602986069,"timestamp":"2024-06-01T22:42:57.516813Z"}]}
{"channel":"book","type":"update","data":[{"symbol":"ETH/AUD","bids":[],"asks":[{"price":5751.39,"qty":0.00000000},{"price":5756.89,"qty":1.60677000},{"price":5751.61,"qty":0.51970000}],"checksum":472265081,"timestamp":"2024-06-01T22:42:57.519809Z"}]}
{"channel":"book","type":"update","data":[{"symbol":"ETH/AUD","bids":[],"asks":[{"price":5751.37,"qty":3.51736210}],"checksum":3367670456,"timestamp":"2024-06-01T22:42:57.522476Z"}]}
{"channel":"book","type":"update","data":[{"symbol":"ETH/AUD","bids":[],"asks":[{"price":5751.63,"qty":6.96501635}],"checksum":2975726157,"timestamp":"2024-06-01T22:42:57.522706Z"}]}
{"channel":"book","type":"update","data":[{"symbol":"ETH/AUD","bids":[],"asks":[{"price":5749.00,"qty":0.00000000},{"price":5756.74,"qty":0.00413707},{"price":5749.00,"qty":0.47792655}],"checksum":1554614363,"timestamp":"2024-06-01T22:42:57.888752Z"}]}
{"channel":"book","type":"update","data":[{"symbol":"ETH/AUD","bids":[],"asks":[{"price":5751.61,"qty":0.00000000},{"price":5756.74,"qty":0.00413707},{"price":5751.36,"qty":0.51970000}],"checksum":4018297901,"timestamp":"2024-06-01T22:42:58.077233Z"}]}
{"channel":"book","type":"update","data":[{"symbol":"ETH/AUD","bids":[{"price":5741.88,"qty":0.00000000},{"price":5741.73,"qty":2.35323000}],"asks":[],"checksum":1015714768,"timestamp":"2024-06-01T22:42:58.434790Z"}]}
{"channel":"book","type":"update","data":[{"symbol":"ETH/AUD","bids":[{"price":5741.90,"qty":6.65320157}],"asks":[],"checksum":511680931,"timestamp":"2024-06-01T22:42:58.435957Z"}]}
{"channel":"book","type":"update","data":[{"symbol":"ETH/AUD","bids":[{"price":5741.89,"qty":0.00000000},{"price":5741.73,"qty":2.35323000},{"price":5741.74,"qty":0.51970000}],"asks":[],"checksum":692834350,"timestamp":"2024-06-01T22:42:58.437798Z"}]}
{"channel":"book","type":"update","data":[{"symbol":"ETH/AUD","bids":[{"price":5746.87,"qty":0.00000000},{"price":5741.73,"qty":2.35323000}],"asks":[],"checksum":2371493834,"timestamp":"2024-06-01T22:42:58.600564Z"}]}
{"channel":"book","type":"update","data":[{"symbol":"ETH/AUD","bids":[{"price":5746.88,"qty":0.00000000},{"price":5740.82,"qty":5.07672000},{"price":5746.71,"qty":1.03517051}],"asks":[],"checksum":1910583129,"timestamp":"2024-06-01T22:42:58.670792Z"}]}
{"channel":"book","type":"update","data":[{"symbol":"ETH/AUD","bids":[{"price":5741.87,"qty":0.00000000},{"price":5740.82,"qty":5.07672000}],"asks":[],"checksum":3465526085,"timestamp":"2024-06-01T22:42:58.702033Z"}]}
{"channel":"book","type":"update","data":[{"symbol":"ETH/AUD","bids":[{"price":5741.91,"qty":0.05120797}],"asks":[],"checksum":664088446,"timestamp":"2024-06-01T22:42:58.703184Z"}]}
{"channel":"book","type":"update","data":[{"symbol":"ETH/AUD","bids":[{"price":5741.74,"qty":0.00000000},{"price":5740.82,"qty":5.07672000},{"price":5741.91,"qty":0.57090797}],"asks":[],"checksum":1472241421,"timestamp":"2024-06-01T22:42:59.124150Z"}]}
{"channel":"book","type":"update","data":[{"symbol":"ETH/AUD","bids":[],"asks":[{"price":5751.62,"qty":0.00000000},{"price":5756.74,"qty":0.00413707}],"checksum":4206245254,"timestamp":"2024-06-01T22:42:59.308822Z"}]}
{"channel":"book","type":"update","data":[{"symbol":"ETH/AUD","bids":[],"asks":[{"price":5751.37,"qty":0.00000000},{"price":5756.88,"qty":0.22990165}],"checksum":3109706675,"timestamp":"2024-06-01T22:42:59.725843Z"}]}
{"channel":"book","type":"update","data":[{"symbol":"ETH/AUD","bids":[],"asks":[{"price":5751.63,"qty":0.00000000},{"price":5756.89,"qty":1.60677000}],"checksum":631516594,"timestamp":"2024-06-01T22:42:59.726126Z"}]}
{"channel":"book","type":"update","data":[{"symbol":"ETH/AUD","bids":[],"asks":[{"price":5751.36,"qty":0.00000000},{"price":5757.84,"qty":2.35323000},{"price":5751.62,"qty":0.51970000}],"checksum":3982289682,"timestamp":"2024-06-01T22:42:59.728882Z"}]}
{"channel":"book","type":"update","data":[{"symbol":"ETH/AUD","bids":[],"asks":[{"price":5751.35,"qty":3.51736210}],"checksum":1086268933,"timestamp":"2024-06-01T22:42:59.731271Z"}]}
{"channel":"book","type":"update","data":[{"symbol":"ETH/AUD","bids":[],"asks":[{"price":5751.63,"qty":5.47251285}],"checksum":3543558245,"timestamp":"2024-06-01T22:42:59.731346Z"}]}
{"channel":"book","type":"update","data":[{"symbol":"ETH/AUD","bids":[],"asks":[{"price":5754.83,"qty":0.83372964}],"checksum":1368102770,"timestamp":"2024-06-01T22:42:59.756970Z"}]}
{"channel":"book","type":"update","data":[{"symbol":"ETH/AUD","bids":[{"price":5746.08,"qty":0.00000000},{"price":5740.35,"qty":1.31000000},{"price":5746.72,"qty":0.08640000}],"asks":[],"checksum":3311733745,"timestamp":"2024-06-01T22:42:59.775366Z"}]}
{"channel":"book","type":"update","data":[{"symbol":"ETH/AUD","bids":[],"asks":[{"price":5751.38,"qty":0.00000000},{"price":5756.74,"qty":0.00413707}],"checksum":2644026272,"timestamp":"2024-06-01T22:42:59.810545Z"}]}
{"channel":"book","type":"update","data":[{"symbol":"ETH/AUD","bids":[],"asks":[{"price":5751.35,"qty":3.58096849}],"checksum":1024394461,"timestamp":"2024-06-01T22:42:59.812661Z"}]}
{"channel":"book","type":"update","data":[{"symbol":"ETH/AUD","bids":[],"asks":[{"price":5751.64,"qty":0.00000000},{"price":5756.88,"qty":0.22990165}],"checksum":3698390751,"timestamp":"2024-06-01T22:42:59.816210Z"}]}
{"channel":"book","type":"update","data":[{"symbol":"ETH/AUD","bids":[],"asks":[{"price":5751.61,"qty":11.18699314}],"checksum":874246528,"timestamp":"2024-06-01T22:42:59.819549Z"}]}
{"channel":"book","type":"update","data":[{"symbol":"ETH/AUD","bids":[{"price":5746.71,"qty":0.00000000},{"price":5740.35,"qty":1.31000000},{"price":5746.73,"qty":1.03516624}],"asks":[],"checksum":420203415,"timestamp":"2024-06-01T22:42:59.832810Z"}]}
{"channel":"book","type":"update","data":[{"symbol":"ETH/AUD","bids":[{"price":5746.72,"qty":0.00000000},{"price":5740.35,"qty":1.31000000},{"price":5746.74,"qty":0.08640000}],"asks":[],"checksum":1490314820,"timestamp":"2024-06-01T22:42:59.869593Z"}]}
{"channel":"book","type":"update","data":[{"symbol":"ETH/AUD","bids":[{"price":5746.73,"qty":0.00000000},{"price":5740.35,"qty":1.31000000},{"price":5746.75,"qty":1.03516264}],"asks":[],"checksum":2552959146,"timestamp":"2024-06-01T22:43:00.261956Z"}]}
{"channel":"book","type":"update","data":[{"symbol":"ETH/AUD","bids":[],"asks":[{"price":5751.62,"qty":0.00000000},{"price":5756.88,"qty":0.22990165},{"price":5751.34,"qty":0.51970000}],"checksum":1058391708,"timestamp":"2024-06-01T22:43:00.265230Z"}]}
{"channel":"book","type":"update","data":[{"symbol":"ETH/AUD","bids":[{"price":5746.74,"qty":0.00000000},{"price":5740.35,"qty":1.31000000},{"price":5746.76,"qty":0.08640000}],"asks":[],"checksum":1883052798,"timestamp":"2024-06-01T22:43:00.295301Z"}]}
{"channel":"book","type":"update","data":[{"symbol":"ETH/AUD","bids":[{"price":5746.75,"qty":0.00000000},{"price":5740.35,"qty":1.31000000},{"price":5746.77,"qty":1.03515065}],"asks":[],"checksum":972057794,"timestamp":"2024-06-01T22:43:00.644771Z"}]}
{"channel":"book","type":"update","data":[{"symbol":"ETH/AUD","bids":[{"price":5746.76,"qty":0.00000000},{"price":5740.35,"qty":1.31000000},{"price":5746.78,"qty":0.08640000}],"asks":[],"checksum":4067847980,"timestamp":"2024-06-01T22:43:00.660595Z"}]}
{"channel":"book","type":"update","data":[{"symbol":"ETH/AUD","bids":[{"price":5746.77,"qty":0.00000000},{"price":5740.35,"qty":1.31000000},{"price":5746.79,"qty":1.03514714}],"asks":[],"checksum":2247145118,"timestamp":"2024-06-01T22:43:01.103104Z"}]}
{"channel":"book","type":"update","data":[{"symbol":"ETH/AUD","bids":[{"price":5746.78,"qty":0.00000000},{"price":5740.35,"qty":1.31000000},{"price":5746.80,"qty":0.08640000}],"asks":[],"checksum":1788584241,"timestamp":"2024-06-01T22:43:01.116240Z"}]}
{"channel":"book","type":"update","data":[{"symbol":"ETH/AUD","bids":[{"price":5741.90,"qty":0.00000000},{"price":5740.35,"qty":1.31000000}],"asks":[],"checksum":1433858033,"timestamp":"2024-06-01T22:43:01.275838Z"}]}
{"channel":"book","type":"update","data":[{"symbol":"ETH/AUD","bids":[{"price":5741.92,"qty":6.65320157}],"asks":[],"checksum":2641202347,"timestamp":"2024-06-01T22:43:01.277135Z"}]}
{"channel":"book","type":"update","data":[{"symbol":"ETH/AUD","bids":[{"price":5741.91,"qty":0.05120797},{"price":5741.74,"qty":0.51970000}],"asks":[],"checksum":1778498353,"timestamp":"2024-06-01T22:43:01.278837Z"}]}
{"channel":"book","type":"update","data":[{"symbol":"ETH/AUD","bids":[{"price":5746.79,"qty":0.00000000},{"price":5740.82,"qty":5.07672000},{"price":5746.81,"qty":1.03514370}],"asks":[],"checksum":667566760,"timestamp":"2024-06-01T22:43:01.561239Z"}]}
{"channel":"book","type":"update","data":[{"symbol":"ETH/AUD","bids":[{"price":5746.80,"qty":0.00000000},{"price":5740.82,"qty":5.07672000},{"price":5746.82,"qty":0.08640000}],"asks":[],"checksum":804047635,"timestamp":"2024-06-01T22:43:01.573829Z"}]}
{"channel":"book","type":"update","data":[{"symbol":"ETH/AUD","bids":[],"asks":[{"price":5749.01,"qty":0.00000000},{"price":5756.88,"qty":0.22990165}],"checksum":2246791830,"timestamp":"2024-06-01T22:43:01.880668Z"}]}
{"channel":"book","type":"update","data":[{"symbol":"ETH/AUD","bids":[{"price":5741.74,"qty":0.00000000},{"price":5740.82,"qty":5.07672000},{"price":5741.93,"qty":0.51970000}],"asks":[],"checksum":1015585644,"timestamp":"2024-06-01T22:43:01.883937Z"}]}
{"channel":"book","type":"update","data":[{"symbol":"ETH/AUD","bids":[],"asks":[{"price":5749.00,"qty":0.00000000},{"price":5756.89,"qty":1.60677000},{"price":5751.33,"qty":0.47794693}],"checksum":1856339922,"timestamp":"2024-06-01T22:43:01.902917Z"}]}
{"channel":"book","type":"update","data":[{"symbol":"ETH/AUD","bids":[],"asks":[{"price":5751.34,"qty":0.00000000},{"price":5756.89,"qty":1.60677000},{"price":5751.32,"qty":0.51970000}],"checksum":3689732579,"timestamp":"2024-06-01T22:43:01.905872Z"}]}
{"channel":"book","type":"update","data":[{"symbol":"ETH/AUD","bids":[],"asks":[{"price":5751.63,"qty":0.00000000},{"price":5756.89,"qty":1.60677000}],"checksum":2757211855,"timestamp":"2024-06-01T22:43:01.976435Z"}]}
{"channel":"book","type":"update","data":[{"symbol":"ETH/AUD","bids":[],"asks":[{"price":5751.35,"qty":0.06360639}],"checksum":3838904542,"timestamp":"2024-06-01T22:43:01.976579Z"}]}
{"channel":"book","type":"update","data":[{"symbol":"ETH/AUD","bids":[],"asks":[{"price":5751.33,"qty":3.99530903}],"checksum":1556601742,"timestamp":"2024-06-01T22:43:01.981725Z"}]}
{"channel":"book","type":"update","data":[{"symbol":"ETH/AUD","bids":[],"asks":[{"price":5751.60,"qty":5.47251285}],"checksum":3027006598,"timestamp":"2024-06-01T22:43:01.981970Z"}]}
{"channel":"book","type":"update","data":[{"symbol":"ETH/AUD","bids":[],"asks":[{"price":5749.45,"qty":0.90387105}],"checksum":972314029,"timestamp":"2024-06-01T22:43:01.982592Z"}]}
{"channel":"book","type":"update","data":[{"symbol":"ETH/AUD","bids":[],"asks":[{"price":5751.33,"qty":3.51736210},{"price":5751.31,"qty":0.47794693}],"checksum":1525855498,"timestamp":"2024-06-01T22:43:01.989653Z"}]}
{"channel":"book","type":"update","data":[{"symbol":"ETH/AUD","bids":[{"price":5746.81,"qty":0.00000000},{"price":5740.82,"qty":5.07672000},{"price":5746.83,"qty":1.03514014}],"asks":[],"checksum":2856095929,"timestamp":"2024-06-01T22:43:01.989783Z"}]}
{"channel":"book","type":"update","data":[{"symbol":"ETH/AUD","bids":[{"price":5746.82,"qty":0.00000000},{"price":5740.82,"qty":5.07672000},{"price":5746.84,"qty":0.08640000}],"asks":[],"checksum":1543660446,"timestamp":"2024-06-01T22:43:02.000629Z"}]}
{"channel":"book","type":"update","data":[{"symbol":"ETH/AUD","bids":[{"price":5741.91,"qty":0.00000000},{"price":5740.82,"qty":5.07672000}],"asks":[],"checksum":391263481,"timestamp":"2024-06-01T22:43:02.118679Z"}]}
{"channel":"book","type":"update","data":[{"symbol":"ETH/AUD","bids":[{"price":5741.94,"qty":0.05120797}],"asks":[],"checksum":1704746307,"timestamp":"2024-06-01T22:43:02.119305Z"}]}
{"channel":"book","type":"update","data":[{"symbol":"ETH/AUD","bids":[{"price":5746.83,"qty":1.05688387}],"asks":[],"checksum":3813467485,"timestamp":"2024-06-01T22:43:02.144612Z"}]}
{"channel":"book","type":"update","data":[{"symbol":"ETH/AUD","bids":[],"asks":[{"price":5751.31,"qty":0.00000000},{"price":5756.74,"qty":0.00413707},{"price":5749.44,"qty":0.47794694}],"checksum":173735390,"timestamp":"2024-06-01T22:43:02.517253Z"}]}
{"channel":"book","type":"update","data":[{"symbol":"ETH/AUD","bids":[{"price":5746.83,"qty":0.02174373},{"price":5746.85,"qty":1.03513656}],"asks":[],"checksum":274404775,"timestamp":"2024-06-01T22:43:02.517278Z"}]}
{"channel":"book","type":"update","data":[{"symbol":"ETH/AUD","bids":[{"price":5741.93,"qty":0.00000000},{"price":5741.73,"qty":2.35323000},{"price":5743.97,"qty":0.51970000}],"asks":[],"checksum":1178956777,"timestamp":"2024-06-01T22:43:02.520093Z"}]}
{"channel":"book","type":"update","data":[{"symbol":"ETH/AUD","bids":[],"asks":[{"price":5749.43,"qty":0.90387105}],"checksum":3870049529,"timestamp":"2024-06-01T22:43:02.522590Z"}]}
{"channel":"book","type":"update","data":[{"symbol":"ETH/AUD","bids":[],"asks":[{"price":5751.35,"qty":0.00000000},{"price":5754.84,"qty":0.07800000}],"checksum":3129230752,"timestamp":"2024-06-01T22:43:02.522796Z"}]}
{"channel":"book","type":"update","data":[{"symbol":"ETH/AUD","bids":[],"asks":[{"price":5751.30,"qty":0.05631007}],"checksum":2158392192,"timestamp":"2024-06-01T22:43:02.524223Z"}]}
{"channel":"book","type":"update","data":[{"symbol":"ETH/AUD","bids":[{"price":5746.84,"qty":0.00000000},{"price":5741.73,"qty":2.35323000},{"price":5746.08,"qty":0.08640000}],"asks":[],"checksum":3096680334,"timestamp":"2024-06-01T22:43:02.548334Z"}]}
{"channel":"book","type":"update","data":[{"symbol":"ETH/AUD","bids":[],"asks":[{"price":5749.45,"qty":0.00000000},{"price":5754.84,"qty":0.07800000}],"checksum":631441156,"timestamp":"2024-06-01T22:43:02.553396Z"}]}
{"channel":"book","type":"update","data":[{"symbol":"ETH/AUD","bids":[{"price":5746.85,"qty":0.00000000},{"price":5741.73,"qty":2.35323000},{"price":5746.84,"qty":1.03515079}],"asks":[],"checksum":3876490880,"timestamp":"2024-06-01T22:43:02.596710Z"}]}
{"channel":"book","type":"update","data":[{"symbol":"ETH/AUD","bids":[{"price":5746.08,"qty":0.00000000},{"price":5741.73,"qty":2.35323000},{"price":5746.85,"qty":0.08640000}],"asks":[],"checksum":1169416539,"timestamp":"2024-06-01T22:43:02.611058Z"}]}
{"channel":"book","type":"update","data":[{"symbol":"ETH/AUD","bids":[{"price":5743.97,"qty":0.00000000},{"price":5741.73,"qty":2.35323000}],"asks":[],"checksum":1095157902,"timestamp":"2024-06-01T22:43:02.902313Z"}]}
{"channel":"book","type":"update","data":[{"symbol":"ETH/AUD","bids":[],"asks":[{"price":5749.44,"qty":0.00000000},{"price":5756.74,"qty":0.00413707},{"price":5749.42,"qty":0.47793784}],"checksum":494086880,"timestamp":"2024-06-01T22:43:03.027359Z"}]}
{"channel":"book","type":"update","data":[{"symbol":"ETH/AUD","bids":[{"price":5746.84,"qty":0.00000000},{"price":5740.82,"qty":5.07672000},{"price":5746.86,"qty":1.03514780}],"asks":[],"checksum":1624224826,"timestamp":"2024-06-01T22:43:03.027499Z"}]}
{"channel":"book","type":"update","data":[{"symbol":"ETH/AUD","bids":[],"asks":[{"price":5749.41,"qty":0.90387105}],"checksum":498808751,"timestamp":"2024-06-01T22:43:03.032906Z"}]}
{"channel":"book","type":"update","data":[{"symbol":"ETH/AUD","bids":[{"price":5746.85,"qty":0.00000000},{"price":5740.82,"qty":5.07672000},{"price":5746.08,"qty":0.08640000}],"asks":[],"checksum":382325636,"timestamp":"2024-06-01T22:43:03.068772Z"}]}
{"channel":"book","type":"update","data":[{"symbol":"ETH/AUD","bids":[],"asks":[{"price":5749.43,"qty":0.00000000},{"price":5754.84,"qty":0.07800000}],"checksum":2404852049,"timestamp":"2024-06-01T22:43:03.073670Z"}]}
{"channel":"book","type":"update","data":[{"symbol":"ETH/AUD","bids":[{"price":5746.86,"qty":0.00000000},{"price":5740.82,"qty":5.07672000},{"price":5746.84,"qty":1.03515210}],"asks":[],"checksum":2464584895,"timestamp":"2024-06-01T22:43:03.120829Z"}]}
{"channel":"book","type":"update","data":[{"symbol":"ETH/AUD","bids":[],"asks":[{"price":5751.32,"qty":0.00000000},{"price":5756.74,"qty":0.00413707}],"checksum":1015889380,"timestamp":"2024-06-01T22:43:03.634566Z"}]}
{"channel":"book","type":"update","data":[{"symbol":"ETH/AUD","bids":[{"price":5746.08,"qty":0.00000000},{"price":5740.82,"qty":5.07672000},{"price":5746.85,"qty":0.08640000}],"asks":[],"checksum":1025450054,"timestamp":"2024-06-01T22:43:03.645281Z"}]}
{"channel":"book","type":"update","data":[{"symbol":"ETH/AUD","bids":[{"price":5746.84,"qty":0.00000000},{"price":5740.82,"qty":5.07672000},{"price":5746.85,"qty":1.12155030}],"asks":[],"checksum":3732999433,"timestamp":"2024-06-01T22:43:03.648821Z"}]}
{"channel":"book","type":"update","data":[{"symbol":"ETH/AUD","bids":[],"asks":[{"price":5749.42,"qty":0.00000000},{"price":5756.88,"qty":0.22990165},{"price":5749.40,"qty":0.47793827}],"checksum":3556441017,"timestamp":"2024-06-01T22:43:03.648948Z"}]}
{"channel":"book","type":"update","data":[{"symbol":"ETH/AUD","bids":[],"asks":[{"price":5751.65,"qty":0.51970000}],"checksum":3169936328,"timestamp":"2024-06-01T22:43:03.651983Z"}]}
{"channel":"book","type":"update","data":[{"symbol":"ETH/AUD","bids":[],"asks":[{"price":5749.39,"qty":0.90387105}],"checksum":806961640,"timestamp":"2024-06-01T22:43:03.676269Z"}]}
{"channel":"book","type":"update","data":[{"symbol":"ETH/AUD","bids":[],"asks":[{"price":5749.41,"qty":0.00000000},{"price":5754.84,"qty":0.07800000}],"checksum":2817732918,"timestamp":"2024-06-01T22:43:03.682991Z"}]}
{"channel":"book","type":"update","data":[{"symbol":"ETH/AUD","bids":[{"price":5746.85,"qty":1.03515030},{"price":5746.08,"qty":0.08640000}],"asks":[],"checksum":2507442071,"timestamp":"2024-06-01T22:43:03.708704Z"}]}
{"channel":"book","type":"update","data":[{"symbol":"ETH/AUD","bids":[{"price":5746.85,"qty":0.00000000},{"price":5740.82,"qty":5.07672000},{"price":5746.84,"qty":1.03515250}],"asks":[],"checksum":2793646784,"timestamp":"2024-06-01T22:43:03.751924Z"}]}
{"channel":"book","type":"update","data":[{"symbol":"ETH/AUD","bids":[{"price":5741.92,"qty":0.00000000},{"price":5740.82,"qty":5.07672000}],"asks":[],"checksum":1694165592,"timestamp":"2024-06-01T22:43:04.138517Z"}]}
{"channel":"book","type":"update","data":[{"symbol":"ETH/AUD","bids":[{"price":5741.74,"qty":6.65297534}],"asks":[],"checksum":3312283962,"timestamp":"2024-06-01T22:43:04.139243Z"}]}
{"channel":"book","type":"update","data":[{"symbol":"ETH/AUD","bids":[],"asks":[{"price":5749.40,"qty":0.00000000},{"price":5756.74,"qty":0.00413707},{"price":5749.38,"qty":0.47793842}],"checksum":2870330316,"timestamp":"2024-06-01T22:43:04.280456Z"}]}
{"channel":"book","type":"update","data":[{"symbol":"ETH/AUD","bids":[],"asks":[{"price":5749.37,"qty":0.90387105}],"checksum":16655566,"timestamp":"2024-06-01T22:43:04.286339Z"}]}
{"channel":"book","type":"update","data":[{"symbol":"ETH/AUD","bids":[],"asks":[{"price":5754.83,"qty":0.00000000},{"price":5754.84,"qty":0.07800000}],"checksum":2673142922,"timestamp":"2024-06-01T22:43:04.316260Z"}]}
{"channel":"book","type":"update","data":[{"symbol":"ETH/AUD","bids":[],"asks":[{"price":5751.65,"qty":0.00000000},{"price":5756.74,"qty":0.00413707},{"price":5751.59,"qty":0.51970000}],"checksum":1258235507,"timestamp":"2024-06-01T22:43:04.493660Z"}]}
{"channel":"book","type":"update","data":[{"symbol":"ETH/AUD","bids":[],"asks":[{"price":5751.61,"qty":0.00000000},{"price":5756.74,"qty":0.00413707}],"checksum":3369645185,"timestamp":"2024-06-01T22:43:04.565178Z"}]}
{"channel":"book","type":"update","data":[{"symbol":"ETH/AUD","bids":[],"asks":[{"price":5751.81,"qty":11.18651580}],"checksum":2289056164,"timestamp":"2024-06-01T22:43:04.570847Z"}]}
{"channel":"book","type":"update","data":[{"symbol":"ETH/AUD","bids":[],"asks":[{"price":5751.81,"qty":0.00000000},{"price":5756.74,"qty":0.00413707}],"checksum":3369645185,"timestamp":"2024-06-01T22:43:04.572633Z"}]}
{"channel":"book","type":"update","data":[{"symbol":"ETH/AUD","bids":[],"asks":[{"price":5751.84,"qty":11.18651580}],"checksum":3708477288,"timestamp":"2024-06-01T22:43:04.576972Z"}]}
{"channel":"book","type":"update","data":[{"symbol":"ETH/AUD","bids":[],"asks":[{"price":5751.84,"qty":0.00000000},{"price":5756.74,"qty":0.00413707}],"checksum":3369645185,"timestamp":"2024-06-01T22:43:04.592107Z"}]}
{"channel":"book","type":"update","data":[{"symbol":"ETH/AUD","bids":[],"asks":[{"price":5752.12,"qty":11.18651580}],"checksum":2556994204,"timestamp":"2024-06-01T22:43:04.596381Z"}]}
{"channel":"book","type":"update","data":[{"symbol":"ETH/AUD","bids":[],"asks":[{"price":5749.39,"qty":0.00000000},{"price":5756.74,"qty":0.00413707}],"checksum":932623114,"timestamp":"2024-06-01T22:43:04.601416Z"}]}
{"channel":"book","type":"update","data":[{"symbol":"ETH/AUD","bids":[],"asks":[{"price":5749.37,"qty":0.00000000},{"price":5756.88,"qty":0.22990165}],"checksum":2786889173,"timestamp":"2024-06-01T22:43:04.601526Z"}]}
{"channel":"book","type":"update","data":[{"symbol":"ETH/AUD","bids":[{"price":5746.85,"qty":0.90387105}],"asks":[],"checksum":1434278950,"timestamp":"2024-06-01T22:43:04.607192Z"}]}
{"channel":"book","type":"update","data":[{"symbol":"ETH/AUD","bids":[{"price":5746.08,"qty":0.00000000},{"price":5741.73,"qty":2.35323000},{"price":5746.86,"qty":0.08640000}],"asks":[],"checksum":2114765248,"timestamp":"2024-06-01T22:43:04.625798Z"}]}
{"channel":"book","type":"update","data":[{"symbol":"ETH/AUD","bids":[],"asks":[{"price":5749.38,"qty":0.00000000},{"price":5756.89,"qty":1.60677000},{"price":5751.29,"qty":0.47795457}],"checksum":312418145,"timestamp":"2024-06-01T22:43:04.648769Z"}]}
{"channel":"book","type":"update","data":[{"symbol":"ETH/AUD","bids":[{"price":5746.07,"qty":0.00000000},{"price":5741.73,"qty":2.35323000}],"asks":[],"checksum":2698799728,"timestamp":"2024-06-01T22:43:04.654130Z"}]}
{"channel":"book","type":"update","data":[{"symbol":"ETH/AUD","bids":[{"price":5746.87,"qty":0.90387105}],"asks":[],"checksum":2354443700,"timestamp":"2024-06-01T22:43:04.654158Z"}]}
{"channel":"book","type":"update","data":[{"symbol":"ETH/AUD","bids":[{"price":5746.85,"qty":0.00000000},{"price":5741.73,"qty":2.35323000}],"asks":[],"checksum":823891256,"timestamp":"2024-06-01T22:43:04.676101Z"}]}
{"channel":"book","type":"update","data":[{"symbol":"ETH/AUD","bids":[{"price":5746.86,"qty":0.00000000},{"price":5740.82,"qty":5.07672000},{"price":5746.88,"qty":0.08640000}],"asks":[],"checksum":3070478266,"timestamp":"2024-06-01T22:43:04.688716Z"}]}
{"channel":"book","type":"update","data":[{"symbol":"ETH/AUD","bids":[{"price":5746.89,"qty":0.90387105}],"asks":[],"checksum":1335521937,"timestamp":"2024-06-01T22:43:04.693887Z"}]}
{"channel":"book","type":"update","data":[{"symbol":"ETH/AUD","bids":[],"asks":[{"price":5751.30,"qty":0.00000000},{"price":5756.89,"qty":1.60677000}],"checksum":983164712,"timestamp":"2024-06-01T22:43:04.739756Z"}]}
{"channel":"book","type":"update","data":[{"symbol":"ETH/AUD","bids":[{"price":5746.87,"qty":0.00000000},{"price":5741.73,"qty":2.35323000}],"asks":[],"checksum":2577228536,"timestamp":"2024-06-01T22:43:04.745573Z"}]}
{"channel":"book","type":"update","data":[{"symbol":"ETH/AUD","bids":[],"asks":[{"price":5750.10,"qty":0.90387105}],"checksum":1475999915,"timestamp":"2024-06-01T22:43:04.745641Z"}]}
{"channel":"book","type":"update","data":[{"symbol":"ETH/AUD","bids":[{"price":5746.88,"qty":0.00000000},{"price":5740.82,"qty":5.07672000},{"price":5746.90,"qty":0.08640000}],"asks":[],"checksum":3879570328,"timestamp":"2024-06-01T22:43:04.752282Z"}]}
{"channel":"book","type":"update","data":[{"symbol":"ETH/AUD","bids":[],"asks":[{"price":5749.46,"qty":0.00000000},{"price":5756.89,"qty":1.60677000},{"price":5749.93,"qty":0.06630900}],"checksum":3931183373,"timestamp":"2024-06-01T22:43:04.760822Z"}]}
{"channel":"book","type":"update","data":[{"symbol":"ETH/AUD","bids":[],"asks":[{"price":5751.29,"qty":0.00000000},{"price":5756.89,"qty":1.60677000},{"price":5749.92,"qty":0.47795446}],"checksum":1233089466,"timestamp":"2024-06-01T22:43:04.995278Z"}]}
{"channel":"book","type":"update","data":[{"symbol":"ETH/AUD","bids":[{"price":5746.84,"qty":0.00000000},{"price":5741.15,"qty":0.51970000},{"price":5746.91,"qty":1.03513389}],"asks":[],"checksum":1052531202,"timestamp":"2024-06-01T22:43:04.995355Z"}]}
{"channel":"book","type":"update","data":[{"symbol":"ETH/AUD","bids":[],"asks":[{"price":5749.91,"qty":0.90387105}],"checksum":3377487921,"timestamp":"2024-06-01T22:43:05.000681Z"}]}
{"channel":"book","type":"update","data":[{"symbol":"ETH/AUD","bids":[{"price":5746.91,"qty":1.93900494}],"asks":[],"checksum":1551916500,"timestamp":"2024-06-01T22:43:05.000857Z"}]}
{"channel":"book","type":"update","data":[{"symbol":"ETH/AUD","bids":[{"price":5746.91,"qty":1.03513389}],"asks":[],"checksum":3377487921,"timestamp":"2024-06-01T22:43:05.178732Z"}]}
{"channel":"book","type":"update","data":[{"symbol":"ETH/AUD","bids":[],"asks":[{"price":5750.10,"qty":0.00000000},{"price":5756.88,"qty":0.22990165}],"checksum":3088311525,"timestamp":"2024-06-01T22:43:05.178777Z"}]}
{"channel":"book","type":"update","data":[{"symbol":"ETH/AUD","bids":[{"price":5746.92,"qty":0.90387105}],"asks":[],"checksum":3268913820,"timestamp":"2024-06-01T22:43:05.179066Z"}]}
{"channel":"book","type":"update","data":[{"symbol":"ETH/AUD","bids":[{"price":5746.89,"qty":0.00000000},{"price":5741.73,"qty":2.35323000}],"asks":[],"checksum":610552044,"timestamp":"2024-06-01T22:43:05.183461Z"}]}
{"channel":"book","type":"update","data":[{"symbol":"ETH/AUD","bids":[{"price":5746.90,"qty":0.00000000},{"price":5741.15,"qty":0.51970000},{"price":5746.93,"qty":0.08640000}],"asks":[],"checksum":245851245,"timestamp":"2024-06-01T22:43:05.210834Z"}]}
{"channel":"book","type":"update","data":[{"symbol":"ETH/AUD","bids":[{"price":5746.94,"qty":0.90387105}],"asks":[],"checksum":1730841968,"timestamp":"2024-06-01T22:43:05.215417Z"}]}
{"channel":"book","type":"update","data":[{"symbol":"ETH/AUD","bids":[{"price":5746.93,"qty":0.00000000},{"price":5741.73,"qty":2.35323000},{"price":5746.95,"qty":0.08640000}],"asks":[],"checksum":2588565207,"timestamp":"2024-06-01T22:43:05.514966Z"}]}
{"channel":"book","type":"update","data":[{"symbol":"ETH/AUD","bids":[{"price":5746.94,"qty":0.00000000},{"price":5741.73,"qty":2.35323000}],"asks":[],"checksum":2367788401,"timestamp":"2024-06-01T22:43:05.520373Z"}]}
{"channel":"book","type":"update","data":[{"symbol":"ETH/AUD","bids":[{"price":5746.96,"qty":0.90387105}],"asks":[],"checksum":1404814350,"timestamp":"2024-06-01T22:43:05.520910Z"}]}
{"channel":"book","type":"update","data":[{"symbol":"ETH/AUD","bids":[{"price":5741.94,"qty":0.00000000},{"price":5741.73,"qty":2.35323000}],"asks":[],"checksum":2064124415,"timestamp":"2024-06-01T22:43:05.524083Z"}]}
{"channel":"book","type":"update","data":[{"symbol":"ETH/AUD","bids":[{"price":5741.75,"qty":0.05631099}],"asks":[],"checksum":2956362173,"timestamp":"2024-06-01T22:43:05.524385Z"}]}
{"channel":"book","type":"update","data":[{"symbol":"ETH/AUD","bids":[{"price":5746.92,"qty":0.00000000},{"price":5741.73,"qty":2.35323000}],"asks":[],"checksum":4177466861,"timestamp":"2024-06-01T22:43:05.675661Z"}]}
{"channel":"book","type":"update","data":[{"symbol":"ETH/AUD","bids":[{"price":5746.91,"qty":0.00000000},{"price":5741.15,"qty":0.51970000},{"price":5746.97,"qty":1.03512255}],"asks":[],"checksum":502454379,"timestamp":"2024-06-01T22:43:05.721457Z"}]}
{"channel":"book","type":"update","data":[{"symbol":"ETH/AUD","bids":[],"asks":[{"price":5749.92,"qty":0.00000000},{"price":5756.89,"qty":1.60677000},{"price":5749.90,"qty":0.47795437}],"checksum":3329365382,"timestamp":"2024-06-01T22:43:05.721561Z"}]}
{"channel":"book","type":"update","data":[{"symbol":"ETH/AUD","bids":[{"price":5746.98,"qty":0.90387105}],"asks":[],"checksum":458001396,"timestamp":"2024-06-01T22:43:05.727471Z"}]}
{"channel":"book","type":"update","data":[{"symbol":"ETH/AUD","bids":[{"price":5746.95,"qty":0.00000000},{"price":5741.73,"qty":2.35323000},{"price":5746.99,"qty":0.08640000}],"asks":[],"checksum":661787054,"timestamp":"2024-06-01T22:43:05.760918Z"}]}
{"channel":"book","type":"update","data":[{"symbol":"ETH/AUD","bids":[],"asks":[{"price":5749.89,"qty":0.90387105}],"checksum":1039911003,"timestamp":"2024-06-01T22:43:05.766558Z"}]}
{"channel":"book","type":"update","data":[{"symbol":"ETH/AUD","bids":[{"price":5746.98,"qty":0.00000000},{"price":5741.73,"qty":2.35323000}],"asks":[],"checksum":504874433,"timestamp":"2024-06-01T22:43:05.766608Z"}]}
{"channel":"book","type":"update","data":[{"symbol":"ETH/AUD","bids":[{"price":5747.00,"qty":0.90387105}],"asks":[],"checksum":3814569713,"timestamp":"2024-06-01T22:43:05.766712Z"}]}
{"channel":"book","type":"update","data":[{"symbol":"ETH/AUD","bids":[{"price":5741.75,"qty":0.57601099}],"asks":[],"checksum":2327344750,"timestamp":"2024-06-01T22:43:05.872428Z"}]}
{"channel":"book","type":"update","data":[{"symbol":"ETH/AUD","bids":[{"price":5746.96,"qty":0.00000000},{"price":5741.73,"qty":2.35323000}],"asks":[],"checksum":3815694759,"timestamp":"2024-06-01T22:43:06.176165Z"}]}
{"channel":"book","type":"update","data":[{"symbol":"ETH/AUD","bids":[],"asks":[{"price":5749.91,"qty":0.00000000},{"price":5756.88,"qty":0.22990165}],"checksum":3969268073,"timestamp":"2024-06-01T22:43:06.176206Z"}]}
{"channel":"book","type":"update","data":[{"symbol":"ETH/AUD","bids":[{"price":5746.97,"qty":0.00000000},{"price":5740.83,"qty":0.40020176},{"price":5747.01,"qty":1.03511521}],"asks":[],"checksum":2024266663,"timestamp":"2024-06-01T22:43:06.417416Z"}]}
{"channel":"book","type":"update","data":[{"symbol":"ETH/AUD","bids":[],"asks":[{"price":5749.90,"qty":0.00000000},{"price":5756.89,"qty":1.60677000},{"price":5749.88,"qty":0.47795423}],"checksum":2892216161,"timestamp":"2024-06-01T22:43:06.417525Z"}]}
{"channel":"book","type":"update","data":[{"symbol":"ETH/AUD","bids":[{"price":5747.02,"qty":0.90387105}],"asks":[],"checksum":968843116,"timestamp":"2024-06-01T22:43:06.422502Z"}]}
{"channel":"book","type":"update","data":[{"symbol":"ETH/AUD","bids":[],"asks":[{"price":5749.87,"qty":0.90387105}],"checksum":3115139551,"timestamp":"2024-06-01T22:43:06.676960Z"}]}
{"channel":"book","type":"update","data":[{"symbol":"ETH/AUD","bids":[{"price":5747.00,"qty":0.00000000},{"price":5741.73,"qty":2.35323000}],"asks":[],"checksum":2162317010,"timestamp":"2024-06-01T22:43:06.677000Z"}]}
{"channel":"book","type":"update","data":[{"symbol":"ETH/AUD","bids":[{"price":5745.82,"qty":0.00000000},{"price":5740.83,"qty":0.40020176}],"asks":[],"checksum":174801827,"timestamp":"2024-06-01T22:43:06.680134Z"}]}
{"channel":"book","type":"update","data":[{"symbol":"ETH/AUD","bids":[{"price":5746.34,"qty":4.21042292}],"asks":[],"checksum":80624503,"timestamp":"2024-06-01T22:43:06.683634Z"}]}
{"channel":"book","type":"update","data":[{"symbol":"ETH/AUD","bids":[],"asks":[{"price":5749.89,"qty":0.00000000},{"price":5756.88,"qty":0.22990165}],"checksum":713218203,"timestamp":"2024-06-01T22:43:06.684460Z"}]}
{"channel":"book","type":"update","data":[{"symbol":"ETH/AUD","bids":[],"asks":[{"price":5751.33,"qty":0.00000000},{"price":5756.89,"qty":1.60677000}],"checksum":123919917,"timestamp":"2024-06-01T22:43:06.743926Z"}]}
{"channel":"book","type":"update","data":[{"symbol":"ETH/AUD","bids":[],"asks":[{"price":5751.60,"qty":0.00000000},{"price":5757.84,"qty":2.35323000}],"checksum":123120719,"timestamp":"2024-06-01T22:43:06.744319Z"}]}
{"channel":"book","type":"update","data":[{"symbol":"ETH/AUD","bids":[],"asks":[{"price":5752.11,"qty":9.50487176}],"checksum":24997252,"timestamp":"2024-06-01T22:43:06.749838Z"}]}
{"channel":"book","type":"update","data":[{"symbol":"ETH/AUD","bids":[],"asks":[{"price":5751.59,"qty":0.00000000},{"price":5757.84,"qty":2.35323000},{"price":5752.10,"qty":0.51970000}],"checksum":872138595,"timestamp":"2024-06-01T22:43:06.753023Z"}]}
{"channel":"book","type":"update","data":[{"symbol":"ETH/AUD","bids":[{"price":5746.99,"qty":0.00000000},{"price":5740.83,"qty":0.40020176},{"price":5747.03,"qty":0.08640000}],"asks":[],"checksum":2067822529,"timestamp":"2024-06-01T22:43:06.765011Z"}]}
{"channel":"book","type":"update","data":[{"symbol":"ETH/AUD","bids":[{"price":5741.74,"qty":0.00000000},{"price":5740.83,"qty":0.40020176}],"asks":[],"checksum":3000579274,"timestamp":"2024-06-01T22:43:07.030483Z"}]}
{"channel":"book","type":"update","data":[{"symbol":"ETH/AUD","bids":[{"price":5741.76,"qty":7.67412386}],"asks":[],"checksum":1616001630,"timestamp":"2024-06-01T22:43:07.031084Z"}]}
{"channel":"book","type":"update","data":[{"symbol":"ETH/AUD","bids":[{"price":5741.75,"qty":0.05631099},{"price":5741.74,"qty":0.51970000}],"asks":[],"checksum":3913498911,"timestamp":"2024-06-01T22:43:07.033565Z"}]}
{"channel":"book","type":"update","data":[{"symbol":"ETH/AUD","bids":[{"price":5747.04,"qty":0.90387105}],"asks":[],"checksum":1013457031,"timestamp":"2024-06-01T22:43:07.175834Z"}]}
{"channel":"book","type":"update","data":[{"symbol":"ETH/AUD","bids":[{"price":5747.02,"qty":0.00000000},{"price":5741.74,"qty":0.51970000}],"asks":[],"checksum":2711957355,"timestamp":"2024-06-01T22:43:07.180528Z"}]}
{"channel":"book","type":"update","data":[{"symbol":"ETH/AUD","bids":[{"price":5747.03,"qty":0.00000000},{"price":5741.73,"qty":2.35323000},{"price":5747.05,"qty":0.08640000}],"asks":[],"checksum":1966868366,"timestamp":"2024-06-01T22:43:07.192259Z"}]}
{"channel":"book","type":"update","data":[{"symbol":"ETH/AUD","bids":[{"price":5747.01,"qty":0.00000000},{"price":5741.73,"qty":2.35323000},{"price":5747.04,"qty":1.93899448}],"asks":[],"checksum":4074940476,"timestamp":"2024-06-01T22:43:07.198494Z"}]}
{"channel":"book","type":"update","data":[{"symbol":"ETH/AUD","bids":[{"price":5746.70,"qty":0.00000000},{"price":5740.83,"qty":0.40020176},{"price":5747.04,"qty":2.00532348}],"asks":[],"checksum":3241132695,"timestamp":"2024-06-01T22:43:07.266777Z"}]}
{"channel":"book","type":"update","data":[{"symbol":"ETH/AUD","bids":[{"price":5747.06,"qty":0.90387105}],"asks":[],"checksum":3352611140,"timestamp":"2024-06-01T22:43:07.271956Z"}]}
{"channel":"book","type":"update","data":[{"symbol":"ETH/AUD","bids":[{"price":5747.05,"qty":0.00000000},{"price":5740.83,"qty":0.40020176},{"price":5747.07,"qty":0.08640000}],"asks":[],"checksum":1031236140,"timestamp":"2024-06-01T22:43:07.286890Z"}]}
{"channel":"book","type":"update","data":[{"symbol":"ETH/AUD","bids":[{"price":5741.74,"qty":0.00000000},{"price":5740.83,"qty":0.40020176},{"price":5741.77,"qty":0.51970000}],"asks":[],"checksum":1666812283,"timestamp":"2024-06-01T22:43:07.560176Z"}]}
{"channel":"book","type":"update","data":[{"symbol":"ETH/AUD","bids":[{"price":5747.06,"qty":0.00000000},{"price":5740.83,"qty":0.40020176}],"asks":[],"checksum":4057758428,"timestamp":"2024-06-01T22:43:07.676453Z"}]}
{"channel":"book","type":"update","data":[{"symbol":"ETH/AUD","bids":[{"price":5747.08,"qty":0.90387105}],"asks":[],"checksum":3211801213,"timestamp":"2024-06-01T22:43:07.676468Z"}]}
{"channel":"book","type":"update","data":[{"symbol":"ETH/AUD","bids":[{"price":5747.04,"qty":1.10145243}],"asks":[],"checksum":1246433301,"timestamp":"2024-06-01T22:43:07.681237Z"}]}
{"channel":"book","type":"update","data":[{"symbol":"ETH/AUD","bids":[{"price":5747.07,"qty":0.00000000},{"price":5740.83,"qty":0.40020176},{"price":5747.09,"qty":0.08640000}],"asks":[],"checksum":4034620207,"timestamp":"2024-06-01T22:43:07.712791Z"}]}
{"channel":"book","type":"update","data":[{"symbol":"ETH/AUD","bids":[{"price":5747.10,"qty":0.90387105}],"asks":[],"checksum":1744920950,"timestamp":"2024-06-01T22:43:07.717757Z"}]}
{"channel":"book","type":"update","data":[{"symbol":"ETH/AUD","bids":[{"price":5747.09,"qty":0.00000000},{"price":5741.73,"qty":2.35323000},{"price":5747.11,"qty":0.08640000}],"asks":[],"checksum":4260200504,"timestamp":"2024-06-01T22:43:07.866511Z"}]}
{"channel":"book","type":"update","data":[{"symbol":"ETH/AUD","bids":[{"price":5747.10,"qty":0.00000000},{"price":5741.73,"qty":2.35323000}],"asks":[],"checksum":2537010815,"timestamp":"2024-06-01T22:43:07.872191Z"}]}
{"channel":"book","type":"update","data":[{"symbol":"ETH/AUD","bids":[{"price":5747.12,"qty":0.90387105}],"asks":[],"checksum":3490769015,"timestamp":"2024-06-01T22:43:07.872405Z"}]}
{"channel":"book","type":"update","data":[{"symbol":"ETH/AUD","bids":[{"price":5747.04,"qty":0.06632900},{"price":5747.13,"qty":1.03510802}],"asks":[],"checksum":427166425,"timestamp":"2024-06-01T22:43:07.932452Z"}]}
{"channel":"book","type":"update","data":[{"symbol":"ETH/AUD","bids":[{"price":5747.12,"qty":0.00000000},{"price":5741.75,"qty":0.05631099}],"asks":[],"checksum":3783129058,"timestamp":"2024-06-01T22:43:07.937712Z"}]}
{"channel":"book","type":"update","data":[{"symbol":"ETH/AUD","bids":[{"price":5747.14,"qty":0.90387105}],"asks":[],"checksum":2727485107,"timestamp":"2024-06-01T22:43:07.937787Z"}]}
{"channel":"book","type":"update","data":[{"symbol":"ETH/AUD","bids":[{"price":5747.11,"qty":0.00000000},{"price":5741.75,"qty":0.05631099},{"price":5747.15,"qty":0.08640000}],"asks":[],"checksum":2643845583,"timestamp":"2024-06-01T22:43:07.959467Z"}]}
{"channel":"book","type":"update","data":[{"symbol":"ETH/AUD","bids":[{"price":5747.14,"qty":0.00000000},{"price":5741.75,"qty":0.05631099}],"asks":[],"checksum":2981302307,"timestamp":"2024-06-01T22:43:07.972204Z"}]}
{"channel":"book","type":"update","data":[{"symbol":"ETH/AUD","bids":[{"price":5747.16,"qty":0.90387105}],"asks":[],"checksum":965105268,"timestamp":"2024-06-01T22:43:07.972215Z"}]}
{"channel":"book","type":"update","data":[{"symbol":"ETH/AUD","bids":[{"price":5747.08,"qty":0.00000000},{"price":5741.75,"qty":0.05631099}],"asks":[],"checksum":2404187258,"timestamp":"2024-06-01T22:43:08.176866Z"}]}
{"channel":"book","type":"update","data":[{"symbol":"ETH/AUD","bids":[{"price":5747.15,"qty":0.00000000},{"price":5741.73,"qty":2.35323000},{"price":5747.17,"qty":0.08640000}],"asks":[],"checksum":2412058028,"timestamp":"2024-06-01T22:43:08.203434Z"}]}
{"channel":"book","type":"update","data":[{"symbol":"ETH/AUD","bids":[],"asks":[{"price":5752.09,"qty":0.06437395}],"checksum":3438957446,"timestamp":"2024-06-01T22:43:08.223641Z"}]}
