{"channel":"book","type":"snapshot","data":[{"symbol":"ETH/USDC","bids":[{"price":3819.05,"qty":0.65461252},{"price":3818.79,"qty":1.40513722},{"price":3818.35,"qty":0.40944083},{"price":3818.13,"qty":1.30954055},{"price":3817.63,"qty":0.24969950},{"price":3817.62,"qty":0.41898282},{"price":3817.53,"qty":11.25035570},{"price":3817.52,"qty":3.91000000},{"price":3817.02,"qty":1.30992005},{"price":3816.64,"qty":1.04660818}],"asks":[{"price":3820.04,"qty":1.30920227},{"price":3820.08,"qty":0.65443662},{"price":3820.97,"qty":0.06053422},{"price":3820.98,"qty":1.02254450},{"price":3821.01,"qty":1.30855525},{"price":3821.32,"qty":0.12485044},{"price":3821.33,"qty":6.01217425},{"price":3821.35,"qty":10.88824746},{"price":3821.36,"qty":18.81713051},{"price":3821.51,"qty":0.41600000}],"checksum":3208779236}]}
{"channel":"book","type":"update","data":[{"symbol":"ETH/USDC","bids":[{"price":3817.62,"qty":0.00000000},{"price":3816.43,"qty":0.59020553}],"asks":[],"checksum":3626887994,"timestamp":"2024-06-01T22:42:43.429927Z"}]}
{"channel":"book","type":"update","data":[{"symbol":"ETH/USDC","bids":[{"price":3817.54,"qty":0.44963075}],"asks":[],"checksum":3530823456,"timestamp":"2024-06-01T22:42:43.430722Z"}]}
{"channel":"book","type":"update","data":[{"symbol":"ETH/USDC","bids":[],"asks":[{"price":3820.98,"qty":0.00000000},{"price":3821.74,"qty":0.27306760}],"checksum":2514371721,"timestamp":"2024-06-01T22:42:43.875122Z"}]}
{"channel":"book","type":"update","data":[{"symbol":"ETH/USDC","bids":[],"asks":[{"price":3821.33,"qty":0.00000000},{"price":3822.46,"qty":0.84711189}],"checksum":4145704616,"timestamp":"2024-06-01T22:42:43.875214Z"}]}
{"channel":"book","type":"update","data":[{"symbol":"ETH/USDC","bids":[],"asks":[{"price":3821.35,"qty":0.00000000},{"price":3822.47,"qty":0.39600000}],"checksum":2816465424,"timestamp":"2024-06-01T22:42:43.875335Z"}]}
{"channel":"book","type":"update","data":[{"symbol":"ETH/USDC","bids":[{"price":3817.55,"qty":3.55776000}],"asks":[],"checksum":1109121198,"timestamp":"2024-06-01T22:42:43.878757Z"}]}
{"channel":"book","type":"update","data":[{"symbol":"ETH/USDC","bids":[],"asks":[{"price":3821.00,"qty":1.02254450}],"checksum":1390852792,"timestamp":"2024-06-01T22:42:43.880249Z"}]}
{"channel":"book","type":"update","data":[{"symbol":"ETH/USDC","bids":[],"asks":[{"price":3821.35,"qty":17.45517692}],"checksum":46124298,"timestamp":"2024-06-01T22:42:43.880375Z"}]}
{"channel":"book","type":"update","data":[{"symbol":"ETH/USDC","bids":[{"price":3817.53,"qty":0.00000000},{"price":3816.64,"qty":1.04660818}],"asks":[],"checksum":764625275,"timestamp":"2024-06-01T22:42:44.270168Z"}]}
{"channel":"book","type":"update","data":[{"symbol":"ETH/USDC","bids":[{"price":3817.56,"qty":16.35834341}],"asks":[],"checksum":3405623267,"timestamp":"2024-06-01T22:42:44.270814Z"}]}
{"channel":"book","type":"update","data":[{"symbol":"ETH/USDC","bids":[{"price":3817.55,"qty":0.00000000},{"price":3816.64,"qty":1.04660818}],"asks":[],"checksum":2235006046,"timestamp":"2024-06-01T22:42:44.273356Z"}]}
{"channel":"book","type":"update","data":[{"symbol":"ETH/USDC","bids":[],"asks":[{"price":3820.08,"qty":0.00000000},{"price":3822.46,"qty":0.84711189}],"checksum":4187515219,"timestamp":"2024-06-01T22:42:44.327402Z"}]}
{"channel":"book","type":"update","data":[{"symbol":"ETH/USDC","bids":[],"asks":[{"price":3820.03,"qty":0.65444512}],"checksum":1686576114,"timestamp":"2024-06-01T22:42:44.331454Z"}]}
{"channel":"book","type":"update","data":[{"symbol":"ETH/USDC","bids":[],"asks":[{"price":3819.99,"qty":1.30919797}],"checksum":1341263737,"timestamp":"2024-06-01T22:42:44.334233Z"}]}
{"channel":"book","type":"update","data":[{"symbol":"ETH/USDC","bids":[],"asks":[{"price":3820.04,"qty":0.00000000},{"price":3821.74,"qty":0.27306760}],"checksum":2024348379,"timestamp":"2024-06-01T22:42:44.336986Z"}]}
{"channel":"book","type":"update","data":[{"symbol":"ETH/USDC","bids":[],"asks":[{"price":3820.03,"qty":0.00000000},{"price":3822.46,"qty":0.84711189}],"checksum":3139861241,"timestamp":"2024-06-01T22:42:44.339113Z"}]}
{"channel":"book","type":"update","data":[{"symbol":"ETH/USDC","bids":[{"price":3816.64,"qty":0.00000000},{"price":3816.43,"qty":0.59020553}],"asks":[],"checksum":1157634806,"timestamp":"2024-06-01T22:42:44.406972Z"}]}
{"channel":"book","type":"update","data":[{"symbol":"ETH/USDC","bids":[{"price":3816.57,"qty":1.04662662}],"asks":[],"checksum":3337633187,"timestamp":"2024-06-01T22:42:44.679821Z"}]}
{"channel":"book","type":"update","data":[{"symbol":"ETH/USDC","bids":[{"price":3818.35,"qty":0.00000000},{"price":3816.43,"qty":0.59020553}],"asks":[],"checksum":299280156,"timestamp":"2024-06-01T22:42:45.429771Z"}]}
{"channel":"book","type":"update","data":[{"symbol":"ETH/USDC","bids":[{"price":3818.72,"qty":0.40941913}],"asks":[],"checksum":1642953797,"timestamp":"2024-06-01T22:42:45.678218Z"}]}
{"channel":"book","type":"update","data":[{"symbol":"ETH/USDC","bids":[],"asks":[{"price":3821.32,"qty":0.00000000},{"price":3822.47,"qty":0.39600000}],"checksum":2015821267,"timestamp":"2024-06-01T22:42:45.956026Z"}]}
{"channel":"book","type":"update","data":[{"symbol":"ETH/USDC","bids":[],"asks":[{"price":3820.97,"qty":0.00000000},{"price":3822.49,"qty":1.30805093}],"checksum":1460273372,"timestamp":"2024-06-01T22:42:45.956099Z"}]}
{"channel":"book","type":"update","data":[{"symbol":"ETH/USDC","bids":[],"asks":[{"price":3820.99,"qty":0.06975063}],"checksum":2438551677,"timestamp":"2024-06-01T22:42:45.957957Z"}]}
{"channel":"book","type":"update","data":[{"symbol":"ETH/USDC","bids":[],"asks":[{"price":3821.34,"qty":0.11554403}],"checksum":508686550,"timestamp":"2024-06-01T22:42:45.957981Z"}]}
{"channel":"book","type":"update","data":[{"symbol":"ETH/USDC","bids":[],"asks":[{"price":3819.98,"qty":0.65445368}],"checksum":676952855,"timestamp":"2024-06-01T22:42:45.961606Z"}]}
{"channel":"book","type":"update","data":[{"symbol":"ETH/USDC","bids":[],"asks":[{"price":3819.94,"qty":1.30916639}],"checksum":3771213484,"timestamp":"2024-06-01T22:42:45.964456Z"}]}
{"channel":"book","type":"update","data":[{"symbol":"ETH/USDC","bids":[],"asks":[{"price":3819.99,"qty":0.00000000},{"price":3821.74,"qty":0.27306760}],"checksum":3843170622,"timestamp":"2024-06-01T22:42:45.967113Z"}]}
{"channel":"book","type":"update","data":[{"symbol":"ETH/USDC","bids":[],"asks":[{"price":3821.00,"qty":0.00000000},{"price":3822.46,"qty":0.84711189}],"checksum":1301351688,"timestamp":"2024-06-01T22:42:46.182723Z"}]}
{"channel":"book","type":"update","data":[{"symbol":"ETH/USDC","bids":[],"asks":[{"price":3821.35,"qty":0.00000000},{"price":3822.47,"qty":0.39600000}],"checksum":2464849511,"timestamp":"2024-06-01T22:42:46.182879Z"}]}
{"channel":"book","type":"update","data":[{"symbol":"ETH/USDC","bids":[{"price":3817.57,"qty":3.55776000}],"asks":[],"checksum":3916781560,"timestamp":"2024-06-01T22:42:46.186339Z"}]}
{"channel":"book","type":"update","data":[{"symbol":"ETH/USDC","bids":[],"asks":[{"price":3821.00,"qty":1.52150747}],"checksum":2920408047,"timestamp":"2024-06-01T22:42:46.187800Z"}]}
{"channel":"book","type":"update","data":[{"symbol":"ETH/USDC","bids":[],"asks":[{"price":3821.35,"qty":20.43750396}],"checksum":379365194,"timestamp":"2024-06-01T22:42:46.188023Z"}]}
{"channel":"book","type":"update","data":[{"symbol":"ETH/USDC","bids":[{"price":3817.54,"qty":0.00000000},{"price":3816.57,"qty":1.04662662}],"asks":[],"checksum":1366706726,"timestamp":"2024-06-01T22:42:46.556232Z"}]}
{"channel":"book","type":"update","data":[{"symbol":"ETH/USDC","bids":[{"price":3817.58,"qty":0.44452276}],"asks":[],"checksum":279657014,"timestamp":"2024-06-01T22:42:46.556523Z"}]}
{"channel":"book","type":"update","data":[{"symbol":"ETH/USDC","bids":[{"price":3817.57,"qty":0.00000000},{"price":3816.57,"qty":1.04662662}],"asks":[],"checksum":3723728251,"timestamp":"2024-06-01T22:42:46.559520Z"}]}
{"channel":"book","type":"update","data":[{"symbol":"ETH/USDC","bids":[{"price":3817.56,"qty":0.00000000},{"price":3816.43,"qty":0.59020553}],"asks":[],"checksum":2190204597,"timestamp":"2024-06-01T22:42:47.619210Z"}]}
{"channel":"book","type":"update","data":[{"symbol":"ETH/USDC","bids":[{"price":3817.59,"qty":12.27195324}],"asks":[],"checksum":3211948334,"timestamp":"2024-06-01T22:42:47.620467Z"}]}
{"channel":"book","type":"update","data":[{"symbol":"ETH/USDC","bids":[{"price":3817.64,"qty":11.25035570}],"asks":[],"checksum":2883683122,"timestamp":"2024-06-01T22:42:47.620479Z"}]}
{"channel":"book","type":"update","data":[{"symbol":"ETH/USDC","bids":[{"price":3817.63,"qty":0.00000000},{"price":3816.57,"qty":1.04662662}],"asks":[],"checksum":2915896626,"timestamp":"2024-06-01T22:42:47.673105Z"}]}
{"channel":"book","type":"update","data":[{"symbol":"ETH/USDC","bids":[],"asks":[{"price":3821.35,"qty":0.00000000},{"price":3822.46,"qty":0.84711189}],"checksum":252475546,"timestamp":"2024-06-01T22:42:48.432620Z"}]}
{"channel":"book","type":"update","data":[{"symbol":"ETH/USDC","bids":[],"asks":[{"price":3821.00,"qty":0.00000000},{"price":3822.47,"qty":0.39600000}],"checksum":3330526461,"timestamp":"2024-06-01T22:42:48.432689Z"}]}
{"channel":"book","type":"update","data":[{"symbol":"ETH/USDC","bids":[{"price":3817.65,"qty":3.55776000}],"asks":[],"checksum":2664310032,"timestamp":"2024-06-01T22:42:48.436255Z"}]}
{"channel":"book","type":"update","data":[{"symbol":"ETH/USDC","bids":[],"asks":[{"price":3820.98,"qty":1.02254450}],"checksum":38258107,"timestamp":"2024-06-01T22:42:48.437810Z"}]}
{"channel":"book","type":"update","data":[{"symbol":"ETH/USDC","bids":[],"asks":[{"price":3821.33,"qty":6.01217425}],"checksum":2833490932,"timestamp":"2024-06-01T22:42:48.437863Z"}]}
{"channel":"book","type":"update","data":[{"symbol":"ETH/USDC","bids":[],"asks":[{"price":3821.35,"qty":9.89568146}],"checksum":1819065935,"timestamp":"2024-06-01T22:42:48.437953Z"}]}
{"channel":"book","type":"update","data":[{"symbol":"ETH/USDC","bids":[],"asks":[{"price":3820.99,"qty":0.00000000},{"price":3821.74,"qty":0.27306760}],"checksum":2339446131,"timestamp":"2024-06-01T22:42:48.783429Z"}]}
{"channel":"book","type":"update","data":[{"symbol":"ETH/USDC","bids":[],"asks":[{"price":3821.34,"qty":0.00000000},{"price":3822.46,"qty":0.84711189}],"checksum":1485199133,"timestamp":"2024-06-01T22:42:48.783590Z"}]}
{"channel":"book","type":"update","data":[{"symbol":"ETH/USDC","bids":[],"asks":[{"price":3820.97,"qty":0.06360636}],"checksum":3086214886,"timestamp":"2024-06-01T22:42:48.786234Z"}]}
{"channel":"book","type":"update","data":[{"symbol":"ETH/USDC","bids":[],"asks":[{"price":3821.32,"qty":0.10652714}],"checksum":329555073,"timestamp":"2024-06-01T22:42:48.786341Z"}]}
{"channel":"book","type":"update","data":[{"symbol":"ETH/USDC","bids":[{"price":3817.65,"qty":0.00000000},{"price":3816.57,"qty":1.04662662}],"asks":[],"checksum":1273591148,"timestamp":"2024-06-01T22:42:48.786797Z"}]}
{"channel":"book","type":"update","data":[{"symbol":"ETH/USDC","bids":[{"price":3817.58,"qty":0.00000000},{"price":3816.43,"qty":0.59020553}],"asks":[],"checksum":1052004888,"timestamp":"2024-06-01T22:42:49.835497Z"}]}
{"channel":"book","type":"update","data":[{"symbol":"ETH/USDC","bids":[{"price":3817.65,"qty":0.43941477}],"asks":[],"checksum":3439273004,"timestamp":"2024-06-01T22:42:49.835834Z"}]}
{"channel":"book","type":"update","data":[{"symbol":"ETH/USDC","bids":[{"price":3817.65,"qty":0.68911296}],"asks":[],"checksum":910089120,"timestamp":"2024-06-01T22:42:49.866734Z"}]}
{"channel":"book","type":"update","data":[{"symbol":"ETH/USDC","bids":[{"price":3817.65,"qty":0.43941477}],"asks":[],"checksum":3439273004,"timestamp":"2024-06-01T22:42:50.000598Z"}]}
{"channel":"book","type":"update","data":[{"symbol":"ETH/USDC","bids":[{"price":3819.05,"qty":0.00000000},{"price":3816.43,"qty":0.59020553}],"asks":[],"checksum":975908873,"timestamp":"2024-06-01T22:42:50.201063Z"}]}
{"channel":"book","type":"update","data":[{"symbol":"ETH/USDC","bids":[{"price":3818.74,"qty":0.65466537}],"asks":[],"checksum":269322058,"timestamp":"2024-06-01T22:42:50.206322Z"}]}
{"channel":"book","type":"update","data":[{"symbol":"ETH/USDC","bids":[{"price":3816.57,"qty":0.00000000},{"price":3816.43,"qty":0.47019039}],"asks":[],"checksum":2019613116,"timestamp":"2024-06-01T22:42:50.270379Z"}]}
{"channel":"book","type":"update","data":[{"symbol":"ETH/USDC","bids":[],"asks":[{"price":3821.33,"qty":0.00000000},{"price":3821.74,"qty":0.27306760}],"checksum":2700168583,"timestamp":"2024-06-01T22:42:50.719828Z"}]}
{"channel":"book","type":"update","data":[{"symbol":"ETH/USDC","bids":[],"asks":[{"price":3820.98,"qty":0.00000000},{"price":3822.46,"qty":0.84711189}],"checksum":2586153764,"timestamp":"2024-06-01T22:42:50.719944Z"}]}
{"channel":"book","type":"update","data":[{"symbol":"ETH/USDC","bids":[],"asks":[{"price":3821.35,"qty":0.00000000},{"price":3822.47,"qty":0.39600000}],"checksum":79037420,"timestamp":"2024-06-01T22:42:50.720479Z"}]}
{"channel":"book","type":"update","data":[{"symbol":"ETH/USDC","bids":[{"price":3817.66,"qty":3.55776000}],"asks":[],"checksum":3248082207,"timestamp":"2024-06-01T22:42:50.724613Z"}]}
{"channel":"book","type":"update","data":[{"symbol":"ETH/USDC","bids":[],"asks":[{"price":3821.00,"qty":1.02254450}],"checksum":1784105140,"timestamp":"2024-06-01T22:42:50.724995Z"}]}
{"channel":"book","type":"update","data":[{"symbol":"ETH/USDC","bids":[],"asks":[{"price":3821.35,"qty":14.46286088}],"checksum":1408976124,"timestamp":"2024-06-01T22:42:50.725239Z"}]}
{"channel":"book","type":"update","data":[{"symbol":"ETH/USDC","bids":[{"price":3817.64,"qty":0.00000000},{"price":3816.44,"qty":1.04666396}],"asks":[],"checksum":2095729998,"timestamp":"2024-06-01T22:42:51.014916Z"}]}
{"channel":"book","type":"update","data":[{"symbol":"ETH/USDC","bids":[{"price":3817.59,"qty":0.00000000},{"price":3816.43,"qty":0.47019039}],"asks":[],"checksum":409005818,"timestamp":"2024-06-01T22:42:51.014968Z"}]}
{"channel":"book","type":"update","data":[{"symbol":"ETH/USDC","bids":[{"price":3817.67,"qty":14.82597070}],"asks":[],"checksum":2352994178,"timestamp":"2024-06-01T22:42:51.015837Z"}]}
{"channel":"book","type":"update","data":[{"symbol":"ETH/USDC","bids":[{"price":3816.45,"qty":22.34748178}],"asks":[],"checksum":297449856,"timestamp":"2024-06-01T22:42:51.015993Z"}]}
{"channel":"book","type":"update","data":[{"symbol":"ETH/USDC","bids":[{"price":3817.66,"qty":0.00000000},{"price":3816.44,"qty":1.04666396}],"asks":[],"checksum":3624193979,"timestamp":"2024-06-01T22:42:51.018382Z"}]}
{"channel":"book","type":"update","data":[{"symbol":"ETH/USDC","bids":[{"price":3816.44,"qty":0.00000000},{"price":3816.43,"qty":0.47019039}],"asks":[],"checksum":2599927417,"timestamp":"2024-06-01T22:42:51.029950Z"}]}
{"channel":"book","type":"update","data":[{"symbol":"ETH/USDC","bids":[{"price":3816.43,"qty":1.51685644}],"asks":[],"checksum":3505273092,"timestamp":"2024-06-01T22:42:51.326333Z"}]}
{"channel":"book","type":"update","data":[{"symbol":"ETH/USDC","bids":[{"price":3817.03,"qty":0.24973875}],"asks":[],"checksum":2733952720,"timestamp":"2024-06-01T22:42:51.361225Z"}]}
{"channel":"book","type":"update","data":[{"symbol":"ETH/USDC","bids":[],"asks":[{"price":3820.97,"qty":0.00000000},{"price":3822.46,"qty":0.84711189}],"checksum":3559341768,"timestamp":"2024-06-01T22:42:51.452187Z"}]}
{"channel":"book","type":"update","data":[{"symbol":"ETH/USDC","bids":[],"asks":[{"price":3821.32,"qty":0.00000000},{"price":3822.47,"qty":0.39600000}],"checksum":787674489,"timestamp":"2024-06-01T22:42:51.452296Z"}]}
{"channel":"book","type":"update","data":[{"symbol":"ETH/USDC","bids":[],"asks":[{"price":3820.99,"qty":0.06360636}],"checksum":4191962701,"timestamp":"2024-06-01T22:42:51.454979Z"}]}
{"channel":"book","type":"update","data":[{"symbol":"ETH/USDC","bids":[],"asks":[{"price":3821.34,"qty":0.10957077}],"checksum":2486235095,"timestamp":"2024-06-01T22:42:51.455192Z"}]}
{"channel":"book","type":"update","data":[{"symbol":"ETH/USDC","bids":[{"price":3818.79,"qty":0.00000000},{"price":3816.43,"qty":1.51685644}],"asks":[],"checksum":2917150755,"timestamp":"2024-06-01T22:42:51.672478Z"}]}
{"channel":"book","type":"update","data":[{"symbol":"ETH/USDC","bids":[{"price":3818.77,"qty":1.40514458}],"asks":[],"checksum":977224806,"timestamp":"2024-06-01T22:42:51.677966Z"}]}
{"channel":"book","type":"update","data":[{"symbol":"ETH/USDC","bids":[{"price":3818.74,"qty":0.00000000},{"price":3816.43,"qty":1.51685644}],"asks":[],"checksum":926818292,"timestamp":"2024-06-01T22:42:51.683371Z"}]}
{"channel":"book","type":"update","data":[{"symbol":"ETH/USDC","bids":[{"price":3818.78,"qty":0.65465905}],"asks":[],"checksum":1430298040,"timestamp":"2024-06-01T22:42:51.687705Z"}]}
{"channel":"book","type":"update","data":[{"symbol":"ETH/USDC","bids":[],"asks":[{"price":3819.98,"qty":0.00000000},{"price":3822.46,"qty":0.84711189}],"checksum":2149075095,"timestamp":"2024-06-01T22:42:51.693940Z"}]}
{"channel":"book","type":"update","data":[{"symbol":"ETH/USDC","bids":[],"asks":[{"price":3819.93,"qty":0.65446252}],"checksum":412379383,"timestamp":"2024-06-01T22:42:51.697901Z"}]}
{"channel":"book","type":"update","data":[{"symbol":"ETH/USDC","bids":[],"asks":[{"price":3819.89,"qty":1.30919296}],"checksum":1216676028,"timestamp":"2024-06-01T22:42:51.700741Z"}]}
{"channel":"book","type":"update","data":[{"symbol":"ETH/USDC","bids":[],"asks":[{"price":3819.94,"qty":0.00000000},{"price":3821.74,"qty":0.27306760}],"checksum":1501732197,"timestamp":"2024-06-01T22:42:51.703488Z"}]}
{"channel":"book","type":"update","data":[{"symbol":"ETH/USDC","bids":[],"asks":[{"price":3821.00,"qty":0.00000000},{"price":3822.46,"qty":0.84711189}],"checksum":904433456,"timestamp":"2024-06-01T22:42:52.923878Z"}]}
{"channel":"book","type":"update","data":[{"symbol":"ETH/USDC","bids":[],"asks":[{"price":3821.35,"qty":0.00000000},{"price":3822.47,"qty":0.39600000}],"checksum":3841207653,"timestamp":"2024-06-01T22:42:52.924143Z"}]}
{"channel":"book","type":"update","data":[{"symbol":"ETH/USDC","bids":[{"price":3817.68,"qty":3.55776000}],"asks":[],"checksum":3083262358,"timestamp":"2024-06-01T22:42:52.927828Z"}]}
{"channel":"book","type":"update","data":[{"symbol":"ETH/USDC","bids":[],"asks":[{"price":3821.33,"qty":6.01218883}],"checksum":4021619229,"timestamp":"2024-06-01T22:42:52.929113Z"}]}
{"channel":"book","type":"update","data":[{"symbol":"ETH/USDC","bids":[],"asks":[{"price":3821.35,"qty":12.37708160}],"checksum":2209100845,"timestamp":"2024-06-01T22:42:52.929164Z"}]}
{"channel":"book","type":"update","data":[{"symbol":"ETH/USDC","bids":[],"asks":[{"price":3820.98,"qty":1.02255915}],"checksum":316956526,"timestamp":"2024-06-01T22:42:52.929402Z"}]}
{"channel":"book","type":"update","data":[{"symbol":"ETH/USDC","bids":[{"price":3817.68,"qty":0.00000000},{"price":3816.45,"qty":22.34748178}],"asks":[],"checksum":1463252429,"timestamp":"2024-06-01T22:42:53.105110Z"}]}
{"channel":"book","type":"update","data":[{"symbol":"ETH/USDC","bids":[],"asks":[{"price":3820.99,"qty":0.00000000},{"price":3821.74,"qty":0.27306760}],"checksum":3075601481,"timestamp":"2024-06-01T22:42:54.286076Z"}]}
{"channel":"book","type":"update","data":[{"symbol":"ETH/USDC","bids":[],"asks":[{"price":3821.34,"qty":0.00000000},{"price":3822.46,"qty":0.84711189}],"checksum":1933237318,"timestamp":"2024-06-01T22:42:54.286285Z"}]}
{"channel":"book","type":"update","data":[{"symbol":"ETH/USDC","bids":[],"asks":[{"price":3820.97,"qty":0.06667859}],"checksum":215775921,"timestamp":"2024-06-01T22:42:54.287499Z"}]}
{"channel":"book","type":"update","data":[{"symbol":"ETH/USDC","bids":[],"asks":[{"price":3821.32,"qty":0.09126397}],"checksum":1876513838,"timestamp":"2024-06-01T22:42:54.287625Z"}]}
{"channel":"book","type":"update","data":[{"symbol":"ETH/USDC","bids":[{"price":3816.45,"qty":0.00000000},{"price":3816.43,"qty":0.47019039}],"asks":[],"checksum":3811466921,"timestamp":"2024-06-01T22:42:54.482694Z"}]}
{"channel":"book","type":"update","data":[{"symbol":"ETH/USDC","bids":[{"price":3817.67,"qty":0.00000000},{"price":3816.42,"qty":0.33800000}],"asks":[],"checksum":2883236718,"timestamp":"2024-06-01T22:42:54.482718Z"}]}
{"channel":"book","type":"update","data":[{"symbol":"ETH/USDC","bids":[{"price":3817.53,"qty":11.76137937}],"asks":[],"checksum":4273157746,"timestamp":"2024-06-01T22:42:54.483528Z"}]}
{"channel":"book","type":"update","data":[{"symbol":"ETH/USDC","bids":[{"price":3816.44,"qty":27.94880934}],"asks":[],"checksum":3330184678,"timestamp":"2024-06-01T22:42:54.483566Z"}]}
{"channel":"book","type":"update","data":[{"symbol":"ETH/USDC","bids":[{"price":3816.45,"qty":3.55776000}],"asks":[],"checksum":2898939619,"timestamp":"2024-06-01T22:42:54.486805Z"}]}
{"channel":"book","type":"update","data":[{"symbol":"ETH/USDC","bids":[],"asks":[{"price":3821.33,"qty":0.00000000},{"price":3821.74,"qty":0.27306760}],"checksum":1508093196,"timestamp":"2024-06-01T22:42:55.226347Z"}]}
{"channel":"book","type":"update","data":[{"symbol":"ETH/USDC","bids":[],"asks":[{"price":3821.35,"qty":0.00000000},{"price":3822.46,"qty":0.84711189}],"checksum":4278695606,"timestamp":"2024-06-01T22:42:55.226486Z"}]}
{"channel":"book","type":"update","data":[{"symbol":"ETH/USDC","bids":[],"asks":[{"price":3820.98,"qty":0.00000000},{"price":3822.47,"qty":0.39600000}],"checksum":3692744,"timestamp":"2024-06-01T22:42:55.226613Z"}]}
{"channel":"book","type":"update","data":[{"symbol":"ETH/USDC","bids":[],"asks":[{"price":3821.00,"qty":2.51944341}],"checksum":2654906083,"timestamp":"2024-06-01T22:42:55.228693Z"}]}
{"channel":"book","type":"update","data":[{"symbol":"ETH/USDC","bids":[],"asks":[{"price":3821.35,"qty":13.94367612}],"checksum":2162400432,"timestamp":"2024-06-01T22:42:55.228768Z"}]}
{"channel":"book","type":"update","data":[{"symbol":"ETH/USDC","bids":[{"price":3816.45,"qty":0.00000000},{"price":3816.44,"qty":27.94880934},{"price":3817.54,"qty":3.55776000}],"asks":[],"checksum":3286528454,"timestamp":"2024-06-01T22:42:55.230541Z"}]}
{"channel":"book","type":"update","data":[{"symbol":"ETH/USDC","bids":[{"price":3817.65,"qty":0.00000000},{"price":3816.44,"qty":27.94880934}],"asks":[],"checksum":2019103175,"timestamp":"2024-06-01T22:42:56.101192Z"}]}
{"channel":"book","type":"update","data":[{"symbol":"ETH/USDC","bids":[{"price":3817.55,"qty":0.43942317}],"asks":[],"checksum":2003250449,"timestamp":"2024-06-01T22:42:56.101941Z"}]}
{"channel":"book","type":"update","data":[{"symbol":"ETH/USDC","bids":[{"price":3817.54,"qty":0.00000000},{"price":3816.44,"qty":27.94880934},{"price":3816.45,"qty":3.55776000}],"asks":[],"checksum":878755943,"timestamp":"2024-06-01T22:42:56.104514Z"}]}
{"channel":"book","type":"update","data":[{"symbol":"ETH/USDC","bids":[],"asks":[{"price":3819.93,"qty":0.00000000},{"price":3822.46,"qty":0.84711189}],"checksum":2171280948,"timestamp":"2024-06-01T22:42:56.367365Z"}]}
{"channel":"book","type":"update","data":[{"symbol":"ETH/USDC","bids":[],"asks":[{"price":3820.22,"qty":0.65441306}],"checksum":65583704,"timestamp":"2024-06-01T22:42:56.370989Z"}]}
{"channel":"book","type":"update","data":[{"symbol":"ETH/USDC","bids":[{"price":3818.78,"qty":0.00000000},{"price":3816.44,"qty":27.94880934}],"asks":[],"checksum":175990660,"timestamp":"2024-06-01T22:42:56.384169Z"}]}
{"channel":"book","type":"update","data":[{"symbol":"ETH/USDC","bids":[{"price":3819.08,"qty":0.65460746}],"asks":[],"checksum":4223322553,"timestamp":"2024-06-01T22:42:56.389179Z"}]}
{"channel":"book","type":"update","data":[{"symbol":"ETH/USDC","bids":[],"asks":[{"price":3821.74,"qty":0.00000000},{"price":3822.46,"qty":0.84711189}],"checksum":3000597113,"timestamp":"2024-06-01T22:42:56.405280Z"}]}
{"channel":"book","type":"update","data":[{"symbol":"ETH/USDC","bids":[],"asks":[{"price":3821.51,"qty":0.00000000},{"price":3822.47,"qty":0.39600000}],"checksum":2818827745,"timestamp":"2024-06-01T22:42:56.417275Z"}]}
{"channel":"book","type":"update","data":[{"symbol":"ETH/USDC","bids":[],"asks":[{"price":3819.89,"qty":0.00000000},{"price":3822.49,"qty":1.30805093}],"checksum":2614303176,"timestamp":"2024-06-01T22:42:56.430268Z"}]}
{"channel":"book","type":"update","data":[{"symbol":"ETH/USDC","bids":[{"price":3817.47,"qty":0.35500000}],"asks":[],"checksum":2543809879,"timestamp":"2024-06-01T22:42:56.435403Z"}]}
{"channel":"book","type":"update","data":[{"symbol":"ETH/USDC","bids":[],"asks":[{"price":3820.19,"qty":1.30903789}],"checksum":3538633337,"timestamp":"2024-06-01T22:42:56.559701Z"}]}
{"channel":"book","type":"update","data":[{"symbol":"ETH/USDC","bids":[{"price":3817.03,"qty":0.00000000},{"price":3816.45,"qty":3.55776000}],"asks":[],"checksum":3168489078,"timestamp":"2024-06-01T22:42:56.602035Z"}]}
{"channel":"book","type":"update","data":[{"symbol":"ETH/USDC","bids":[],"asks":[{"price":3822.13,"qty":0.27304802}],"checksum":3876263759,"timestamp":"2024-06-01T22:42:56.657650Z"}]}
{"channel":"book","type":"update","data":[{"symbol":"ETH/USDC","bids":[],"asks":[{"price":3820.97,"qty":0.00000000},{"price":3822.47,"qty":0.39600000}],"checksum":37972341,"timestamp":"2024-06-01T22:42:57.027761Z"}]}
{"channel":"book","type":"update","data":[{"symbol":"ETH/USDC","bids":[],"asks":[{"price":3821.32,"qty":0.00000000},{"price":3822.49,"qty":1.30805093}],"checksum":1145129639,"timestamp":"2024-06-01T22:42:57.027777Z"}]}
{"channel":"book","type":"update","data":[{"symbol":"ETH/USDC","bids":[],"asks":[{"price":3820.99,"qty":0.19878027}],"checksum":2011779953,"timestamp":"2024-06-01T22:42:57.029383Z"}]}
{"channel":"book","type":"update","data":[{"symbol":"ETH/USDC","bids":[],"asks":[{"price":3820.22,"qty":0.00000000},{"price":3822.49,"qty":1.30805093}],"checksum":483365472,"timestamp":"2024-06-01T22:42:57.280666Z"}]}
{"channel":"book","type":"update","data":[{"symbol":"ETH/USDC","bids":[],"asks":[{"price":3820.18,"qty":0.65441961}],"checksum":3260700114,"timestamp":"2024-06-01T22:42:57.286641Z"}]}
{"channel":"book","type":"update","data":[{"symbol":"ETH/USDC","bids":[],"asks":[{"price":3820.14,"qty":1.30915405}],"checksum":2199502274,"timestamp":"2024-06-01T22:42:57.289470Z"}]}
{"channel":"book","type":"update","data":[{"symbol":"ETH/USDC","bids":[],"asks":[{"price":3820.19,"qty":0.00000000},{"price":3822.47,"qty":0.39600000}],"checksum":3668390061,"timestamp":"2024-06-01T22:42:57.292404Z"}]}
{"channel":"book","type":"update","data":[{"symbol":"ETH/USDC","bids":[],"asks":[{"price":3820.18,"qty":0.00000000},{"price":3822.49,"qty":1.30805093}],"checksum":1369064900,"timestamp":"2024-06-01T22:42:57.293590Z"}]}
{"channel":"book","type":"update","data":[{"symbol":"ETH/USDC","bids":[],"asks":[{"price":3821.35,"qty":0.00000000},{"price":3823.40,"qty":1.30773849}],"checksum":2280562055,"timestamp":"2024-06-01T22:42:57.516185Z"}]}
{"channel":"book","type":"update","data":[{"symbol":"ETH/USDC","bids":[],"asks":[{"price":3821.00,"qty":0.00000000},{"price":3823.43,"qty":0.39200000}],"checksum":109635839,"timestamp":"2024-06-01T22:42:57.516393Z"}]}
{"channel":"book","type":"update","data":[{"symbol":"ETH/USDC","bids":[{"price":3816.45,"qty":0.00000000},{"price":3816.44,"qty":27.94880934},{"price":3817.56,"qty":3.55776000}],"asks":[],"checksum":265209785,"timestamp":"2024-06-01T22:42:57.519745Z"}]}
{"channel":"book","type":"update","data":[{"symbol":"ETH/USDC","bids":[],"asks":[{"price":3820.98,"qty":1.02254724}],"checksum":1982174733,"timestamp":"2024-06-01T22:42:57.521935Z"}]}
{"channel":"book","type":"update","data":[{"symbol":"ETH/USDC","bids":[],"asks":[{"price":3821.35,"qty":21.94365093}],"checksum":2467015226,"timestamp":"2024-06-01T22:42:57.522047Z"}]}
{"channel":"book","type":"update","data":[{"symbol":"ETH/USDC","bids":[{"price":3817.53,"qty":0.00000000},{"price":3816.42,"qty":0.33800000}],"asks":[],"checksum":44367838,"timestamp":"2024-06-01T22:42:57.938723Z"}]}
{"channel":"book","type":"update","data":[{"symbol":"ETH/USDC","bids":[{"price":3817.57,"qty":14.82602466}],"asks":[],"checksum":2563814639,"timestamp":"2024-06-01T22:42:57.939376Z"}]}
{"channel":"book","type":"update","data":[{"symbol":"ETH/USDC","bids":[{"price":3817.56,"qty":0.00000000},{"price":3816.42,"qty":0.33800000}],"asks":[],"checksum":1132694675,"timestamp":"2024-06-01T22:42:57.941934Z"}]}
{"channel":"book","type":"update","data":[{"symbol":"ETH/USDC","bids":[{"price":3817.54,"qty":0.46922861}],"asks":[],"checksum":1060981264,"timestamp":"2024-06-01T22:42:57.947248Z"}]}
{"channel":"book","type":"update","data":[{"symbol":"ETH/USDC","bids":[{"price":3817.56,"qty":0.41524027}],"asks":[],"checksum":2489908141,"timestamp":"2024-06-01T22:42:57.951584Z"}]}
{"channel":"book","type":"update","data":[{"symbol":"ETH/USDC","bids":[],"asks":[{"price":3820.13,"qty":0.65442809}],"checksum":314664216,"timestamp":"2024-06-01T22:42:58.961474Z"}]}
{"channel":"book","type":"update","data":[{"symbol":"ETH/USDC","bids":[],"asks":[{"price":3820.09,"qty":1.30912613}],"checksum":2956786728,"timestamp":"2024-06-01T22:42:58.964359Z"}]}
{"channel":"book","type":"update","data":[{"symbol":"ETH/USDC","bids":[],"asks":[{"price":3820.14,"qty":0.00000000},{"price":3822.47,"qty":0.39600000}],"checksum":2355538481,"timestamp":"2024-06-01T22:42:58.967328Z"}]}
{"channel":"book","type":"update","data":[{"symbol":"ETH/USDC","bids":[{"price":3817.55,"qty":0.00000000},{"price":3817.02,"qty":1.30992005}],"asks":[],"checksum":2607849481,"timestamp":"2024-06-01T22:42:59.146787Z"}]}
{"channel":"book","type":"update","data":[{"symbol":"ETH/USDC","bids":[{"price":3817.58,"qty":0.44452508}],"asks":[],"checksum":3277474457,"timestamp":"2024-06-01T22:42:59.147191Z"}]}
{"channel":"book","type":"update","data":[{"symbol":"ETH/USDC","bids":[],"asks":[{"price":3821.35,"qty":0.00000000},{"price":3822.49,"qty":1.30805093}],"checksum":2774683796,"timestamp":"2024-06-01T22:42:59.725641Z"}]}
{"channel":"book","type":"update","data":[{"symbol":"ETH/USDC","bids":[{"price":3817.59,"qty":3.55776000}],"asks":[],"checksum":1843908933,"timestamp":"2024-06-01T22:42:59.729540Z"}]}
{"channel":"book","type":"update","data":[{"symbol":"ETH/USDC","bids":[],"asks":[{"price":3821.35,"qty":15.46029952}],"checksum":3501564529,"timestamp":"2024-06-01T22:42:59.731664Z"}]}
{"channel":"book","type":"update","data":[{"symbol":"ETH/USDC","bids":[],"asks":[{"price":3820.99,"qty":0.00000000},{"price":3822.49,"qty":1.30805093}],"checksum":2011470858,"timestamp":"2024-06-01T22:42:59.810503Z"}]}
{"channel":"book","type":"update","data":[{"symbol":"ETH/USDC","bids":[],"asks":[{"price":3820.97,"qty":0.06360639}],"checksum":2792212275,"timestamp":"2024-06-01T22:42:59.812353Z"}]}
{"channel":"book","type":"update","data":[{"symbol":"ETH/USDC","bids":[],"asks":[{"price":3821.34,"qty":0.16131253}],"checksum":862106093,"timestamp":"2024-06-01T22:42:59.812484Z"}]}
{"channel":"book","type":"update","data":[{"symbol":"ETH/USDC","bids":[{"price":3817.59,"qty":0.00000000},{"price":3817.47,"qty":0.35500000}],"asks":[],"checksum":4277925612,"timestamp":"2024-06-01T22:42:59.814097Z"}]}
{"channel":"book","type":"update","data":[{"symbol":"ETH/USDC","bids":[{"price":3817.57,"qty":0.00000000},{"price":3817.02,"qty":1.30992005}],"asks":[],"checksum":2826458849,"timestamp":"2024-06-01T22:43:01.396346Z"}]}
{"channel":"book","type":"update","data":[{"symbol":"ETH/USDC","bids":[{"price":3817.59,"qty":12.78281889}],"asks":[],"checksum":3934298711,"timestamp":"2024-06-01T22:43:01.397541Z"}]}
{"channel":"book","type":"update","data":[{"symbol":"ETH/USDC","bids":[{"price":3817.60,"qty":0.24970146}],"asks":[],"checksum":1446682152,"timestamp":"2024-06-01T22:43:01.742948Z"}]}
{"channel":"book","type":"update","data":[{"symbol":"ETH/USDC","bids":[],"asks":[{"price":3821.35,"qty":0.00000000},{"price":3822.47,"qty":0.39600000}],"checksum":1810834802,"timestamp":"2024-06-01T22:43:01.975981Z"}]}
{"channel":"book","type":"update","data":[{"symbol":"ETH/USDC","bids":[],"asks":[{"price":3820.98,"qty":0.00000000},{"price":3822.49,"qty":1.30805093}],"checksum":731559767,"timestamp":"2024-06-01T22:43:01.976038Z"}]}
{"channel":"book","type":"update","data":[{"symbol":"ETH/USDC","bids":[{"price":3817.61,"qty":3.55776000}],"asks":[],"checksum":3115847606,"timestamp":"2024-06-01T22:43:01.979868Z"}]}
{"channel":"book","type":"update","data":[{"symbol":"ETH/USDC","bids":[],"asks":[{"price":3821.00,"qty":1.02254724}],"checksum":1780318755,"timestamp":"2024-06-01T22:43:01.981136Z"}]}
{"channel":"book","type":"update","data":[{"symbol":"ETH/USDC","bids":[],"asks":[{"price":3821.33,"qty":16.95645754}],"checksum":429557258,"timestamp":"2024-06-01T22:43:01.981239Z"}]}
{"channel":"book","type":"update","data":[{"symbol":"ETH/USDC","bids":[{"price":3817.58,"qty":0.00000000},{"price":3817.52,"qty":3.91000000}],"asks":[],"checksum":1309975324,"timestamp":"2024-06-01T22:43:02.153926Z"}]}
{"channel":"book","type":"update","data":[{"symbol":"ETH/USDC","bids":[{"price":3817.61,"qty":4.00228508}],"asks":[],"checksum":4015231503,"timestamp":"2024-06-01T22:43:02.154701Z"}]}
{"channel":"book","type":"update","data":[{"symbol":"ETH/USDC","bids":[{"price":3817.61,"qty":0.44452508}],"asks":[],"checksum":3970131293,"timestamp":"2024-06-01T22:43:02.157395Z"}]}
{"channel":"book","type":"update","data":[{"symbol":"ETH/USDC","bids":[],"asks":[{"price":3820.97,"qty":0.00000000},{"price":3822.47,"qty":0.39600000}],"checksum":500733911,"timestamp":"2024-06-01T22:43:02.522350Z"}]}
{"channel":"book","type":"update","data":[{"symbol":"ETH/USDC","bids":[],"asks":[{"price":3821.34,"qty":0.00000000},{"price":3822.49,"qty":1.30805093}],"checksum":300112727,"timestamp":"2024-06-01T22:43:02.522571Z"}]}
{"channel":"book","type":"update","data":[{"symbol":"ETH/USDC","bids":[],"asks":[{"price":3820.99,"qty":0.06667852}],"checksum":2274069844,"timestamp":"2024-06-01T22:43:02.524092Z"}]}
{"channel":"book","type":"update","data":[{"symbol":"ETH/USDC","bids":[],"asks":[{"price":3821.32,"qty":0.10951677}],"checksum":575497139,"timestamp":"2024-06-01T22:43:02.524140Z"}]}
{"channel":"book","type":"update","data":[{"symbol":"ETH/USDC","bids":[],"asks":[{"price":3820.13,"qty":0.00000000},{"price":3822.47,"qty":0.39600000}],"checksum":701955982,"timestamp":"2024-06-01T22:43:03.604583Z"}]}
{"channel":"book","type":"update","data":[{"symbol":"ETH/USDC","bids":[],"asks":[{"price":3820.42,"qty":0.65437855}],"checksum":1318120202,"timestamp":"2024-06-01T22:43:03.608612Z"}]}
{"channel":"book","type":"update","data":[{"symbol":"ETH/USDC","bids":[{"price":3817.60,"qty":0.00000000},{"price":3817.47,"qty":0.35500000}],"asks":[],"checksum":3544212663,"timestamp":"2024-06-01T22:43:04.316157Z"}]}
{"channel":"book","type":"update","data":[{"symbol":"ETH/USDC","bids":[],"asks":[{"price":3821.36,"qty":0.00000000},{"price":3822.47,"qty":0.39600000}],"checksum":2841038585,"timestamp":"2024-06-01T22:43:04.565044Z"}]}
{"channel":"book","type":"update","data":[{"symbol":"ETH/USDC","bids":[{"price":3819.08,"qty":0.00000000},{"price":3817.02,"qty":1.30992005}],"asks":[],"checksum":2120882398,"timestamp":"2024-06-01T22:43:04.567465Z"}]}
{"channel":"book","type":"update","data":[{"symbol":"ETH/USDC","bids":[{"price":3817.62,"qty":3.55776000}],"asks":[],"checksum":1222215422,"timestamp":"2024-06-01T22:43:04.568387Z"}]}
{"channel":"book","type":"update","data":[{"symbol":"ETH/USDC","bids":[],"asks":[{"price":3821.47,"qty":18.09335551}],"checksum":524416526,"timestamp":"2024-06-01T22:43:04.569736Z"}]}
{"channel":"book","type":"update","data":[{"symbol":"ETH/USDC","bids":[],"asks":[{"price":3821.47,"qty":0.00000000},{"price":3822.47,"qty":0.39600000}],"checksum":1222215422,"timestamp":"2024-06-01T22:43:04.572682Z"}]}
{"channel":"book","type":"update","data":[{"symbol":"ETH/USDC","bids":[{"price":3819.37,"qty":0.65455798}],"asks":[],"checksum":2895866787,"timestamp":"2024-06-01T22:43:04.573271Z"}]}
{"channel":"book","type":"update","data":[{"symbol":"ETH/USDC","bids":[],"asks":[{"price":3821.49,"qty":17.89415551}],"checksum":3229432560,"timestamp":"2024-06-01T22:43:04.576946Z"}]}
{"channel":"book","type":"update","data":[{"symbol":"ETH/USDC","bids":[],"asks":[{"price":3820.09,"qty":0.00000000},{"price":3822.47,"qty":0.39600000}],"checksum":3119036584,"timestamp":"2024-06-01T22:43:04.590984Z"}]}
{"channel":"book","type":"update","data":[{"symbol":"ETH/USDC","bids":[],"asks":[{"price":3821.49,"qty":0.00000000},{"price":3822.49,"qty":1.30805093}],"checksum":1653971246,"timestamp":"2024-06-01T22:43:04.592093Z"}]}
{"channel":"book","type":"update","data":[{"symbol":"ETH/USDC","bids":[],"asks":[{"price":3821.01,"qty":0.00000000},{"price":3823.43,"qty":0.39200000}],"checksum":1780511211,"timestamp":"2024-06-01T22:43:04.596245Z"}]}
{"channel":"book","type":"update","data":[{"symbol":"ETH/USDC","bids":[],"asks":[{"price":3821.68,"qty":15.61698051}],"checksum":3239834929,"timestamp":"2024-06-01T22:43:04.596294Z"}]}
{"channel":"book","type":"update","data":[{"symbol":"ETH/USDC","bids":[{"price":3817.62,"qty":0.00000000},{"price":3817.47,"qty":0.35500000}],"asks":[],"checksum":4064532402,"timestamp":"2024-06-01T22:43:04.599558Z"}]}
{"channel":"book","type":"update","data":[{"symbol":"ETH/USDC","bids":[],"asks":[{"price":3821.51,"qty":1.30838575}],"checksum":3707575681,"timestamp":"2024-06-01T22:43:04.600961Z"}]}
{"channel":"book","type":"update","data":[{"symbol":"ETH/USDC","bids":[{"price":3818.13,"qty":0.00000000},{"price":3817.02,"qty":1.30992005}],"asks":[],"checksum":2930348940,"timestamp":"2024-06-01T22:43:04.607318Z"}]}
{"channel":"book","type":"update","data":[{"symbol":"ETH/USDC","bids":[{"price":3818.61,"qty":1.30937422}],"asks":[],"checksum":2724782727,"timestamp":"2024-06-01T22:43:04.611913Z"}]}
{"channel":"book","type":"update","data":[{"symbol":"ETH/USDC","bids":[{"price":3817.59,"qty":0.00000000},{"price":3817.02,"qty":1.30992005}],"asks":[],"checksum":3752210702,"timestamp":"2024-06-01T22:43:04.837051Z"}]}
{"channel":"book","type":"update","data":[{"symbol":"ETH/USDC","bids":[{"price":3817.62,"qty":13.80363779}],"asks":[],"checksum":497178633,"timestamp":"2024-06-01T22:43:04.837830Z"}]}
{"channel":"book","type":"update","data":[{"symbol":"ETH/USDC","bids":[{"price":3817.61,"qty":0.00000000},{"price":3817.02,"qty":1.30992005}],"asks":[],"checksum":1294421760,"timestamp":"2024-06-01T22:43:05.341646Z"}]}
{"channel":"book","type":"update","data":[{"symbol":"ETH/USDC","bids":[{"price":3817.63,"qty":0.47513103}],"asks":[],"checksum":3130282603,"timestamp":"2024-06-01T22:43:05.342290Z"}]}
{"channel":"book","type":"update","data":[{"symbol":"ETH/USDC","bids":[],"asks":[{"price":3821.67,"qty":0.00542329}],"checksum":2712648847,"timestamp":"2024-06-01T22:43:05.592533Z"}]}
{"channel":"book","type":"update","data":[{"symbol":"ETH/USDC","bids":[{"price":3817.63,"qty":0.48058332}],"asks":[],"checksum":885032820,"timestamp":"2024-06-01T22:43:05.593773Z"}]}
{"channel":"book","type":"update","data":[{"symbol":"ETH/USDC","bids":[],"asks":[{"price":3821.33,"qty":0.00000000},{"price":3822.47,"qty":0.39600000}],"checksum":2115526899,"timestamp":"2024-06-01T22:43:06.743468Z"}]}
{"channel":"book","type":"update","data":[{"symbol":"ETH/USDC","bids":[],"asks":[{"price":3821.00,"qty":0.00000000},{"price":3822.49,"qty":1.30805093}],"checksum":709011286,"timestamp":"2024-06-01T22:43:06.743735Z"}]}
{"channel":"book","type":"update","data":[{"symbol":"ETH/USDC","bids":[{"price":3817.64,"qty":3.55776000}],"asks":[],"checksum":632768518,"timestamp":"2024-06-01T22:43:06.747523Z"}]}
{"channel":"book","type":"update","data":[{"symbol":"ETH/USDC","bids":[],"asks":[{"price":3821.50,"qty":20.98102068}],"checksum":691816763,"timestamp":"2024-06-01T22:43:06.749204Z"}]}
{"channel":"book","type":"update","data":[{"symbol":"ETH/USDC","bids":[{"price":3817.64,"qty":0.00000000},{"price":3817.47,"qty":0.35500000}],"asks":[],"checksum":391684765,"timestamp":"2024-06-01T22:43:06.987716Z"}]}
{"channel":"book","type":"update","data":[{"symbol":"ETH/USDC","bids":[],"asks":[{"price":3820.42,"qty":0.00000000},{"price":3822.49,"qty":1.30805093}],"checksum":3141052019,"timestamp":"2024-06-01T22:43:07.049536Z"}]}
{"channel":"book","type":"update","data":[{"symbol":"ETH/USDC","bids":[],"asks":[{"price":3820.95,"qty":1.30890288}],"checksum":2126573214,"timestamp":"2024-06-01T22:43:07.052940Z"}]}
{"channel":"book","type":"update","data":[{"symbol":"ETH/USDC","bids":[],"asks":[{"price":3820.73,"qty":0.65432676}],"checksum":4069884248,"timestamp":"2024-06-01T22:43:07.054971Z"}]}
{"channel":"book","type":"update","data":[{"symbol":"ETH/USDC","bids":[],"asks":[{"price":3820.69,"qty":1.30890288}],"checksum":257983516,"timestamp":"2024-06-01T22:43:07.057997Z"}]}
{"channel":"book","type":"update","data":[{"symbol":"ETH/USDC","bids":[{"price":3818.77,"qty":0.00000000},{"price":3817.02,"qty":1.30992005}],"asks":[],"checksum":27099187,"timestamp":"2024-06-01T22:43:07.058481Z"}]}
{"channel":"book","type":"update","data":[{"symbol":"ETH/USDC","bids":[],"asks":[{"price":3820.95,"qty":0.00000000},{"price":3822.46,"qty":0.84711189}],"checksum":2767986062,"timestamp":"2024-06-01T22:43:07.060569Z"}]}
{"channel":"book","type":"update","data":[{"symbol":"ETH/USDC","bids":[{"price":3819.11,"qty":1.40501948}],"asks":[],"checksum":1568856766,"timestamp":"2024-06-01T22:43:07.063985Z"}]}
{"channel":"book","type":"update","data":[{"symbol":"ETH/USDC","bids":[{"price":3819.37,"qty":0.00000000},{"price":3817.02,"qty":1.30992005}],"asks":[],"checksum":3809941314,"timestamp":"2024-06-01T22:43:07.170545Z"}]}
{"channel":"book","type":"update","data":[{"symbol":"ETH/USDC","bids":[{"price":3819.68,"qty":0.65450347}],"asks":[],"checksum":1463734111,"timestamp":"2024-06-01T22:43:07.175158Z"}]}
{"channel":"book","type":"update","data":[{"symbol":"ETH/USDC","bids":[],"asks":[{"price":3822.13,"qty":0.00000000},{"price":3822.47,"qty":0.39600000}],"checksum":2073182807,"timestamp":"2024-06-01T22:43:07.750590Z"}]}
{"channel":"book","type":"update","data":[{"symbol":"ETH/USDC","bids":[{"price":3817.62,"qty":0.00000000},{"price":3817.02,"qty":1.30992005}],"asks":[],"checksum":713516805,"timestamp":"2024-06-01T22:43:08.188801Z"}]}
{"channel":"book","type":"update","data":[{"symbol":"ETH/USDC","bids":[{"price":3817.64,"qty":14.31391957}],"asks":[],"checksum":2688666216,"timestamp":"2024-06-01T22:43:08.189704Z"}]}
{"channel":"book","type":"update","data":[{"symbol":"ETH/USDC","bids":[{"price":3817.63,"qty":0.47513103}],"asks":[],"checksum":72260389,"timestamp":"2024-06-01T22:43:08.192579Z"}]}
{"channel":"book","type":"update","data":[{"symbol":"ETH/USDC","bids":[],"asks":[{"price":3820.99,"qty":0.00000000},{"price":3822.49,"qty":1.30805093}],"checksum":1789275293,"timestamp":"2024-06-01T22:43:08.221788Z"}]}
{"channel":"book","type":"update","data":[{"symbol":"ETH/USDC","bids":[],"asks":[{"price":3821.32,"qty":0.00000000},{"price":3822.63,"qty":0.27301350}],"checksum":1201164744,"timestamp":"2024-06-01T22:43:08.221826Z"}]}
{"channel":"book","type":"update","data":[{"symbol":"ETH/USDC","bids":[],"asks":[{"price":3821.49,"qty":0.19570768}],"checksum":4123686772,"timestamp":"2024-06-01T22:43:08.223475Z"}]}
{"channel":"book","type":"update","data":[{"symbol":"ETH/USDC","bids":[{"price":3817.65,"qty":0.00522181}],"asks":[],"checksum":3501480788,"timestamp":"2024-06-01T22:43:08.314794Z"}]}
{"channel":"book","type":"update","data":[{"symbol":"ETH/USDC","bids":[{"price":3817.63,"qty":0.00000000},{"price":3817.47,"qty":0.35500000}],"asks":[],"checksum":2376894856,"timestamp":"2024-06-01T22:43:08.538937Z"}]}
{"channel":"book","type":"update","data":[{"symbol":"ETH/USDC","bids":[{"price":3817.65,"qty":0.48545926}],"asks":[],"checksum":2283491595,"timestamp":"2024-06-01T22:43:08.539856Z"}]}
{"channel":"book","type":"update","data":[{"symbol":"ETH/USDC","bids":[],"asks":[{"price":3821.50,"qty":0.00000000},{"price":3822.63,"qty":0.27301350}],"checksum":135012900,"timestamp":"2024-06-01T22:43:08.859364Z"}]}
{"channel":"book","type":"update","data":[{"symbol":"ETH/USDC","bids":[{"price":3817.66,"qty":3.55776000}],"asks":[],"checksum":3271975589,"timestamp":"2024-06-01T22:43:08.863187Z"}]}
{"channel":"book","type":"update","data":[{"symbol":"ETH/USDC","bids":[],"asks":[{"price":3820.68,"qty":0.52353658}],"checksum":2103700778,"timestamp":"2024-06-01T22:43:08.864977Z"}]}
{"channel":"book","type":"update","data":[{"symbol":"ETH/USDC","bids":[],"asks":[{"price":3821.48,"qty":28.93985382}],"checksum":3267806744,"timestamp":"2024-06-01T22:43:08.865044Z"}]}
{"channel":"book","type":"update","data":[{"symbol":"ETH/USDC","bids":[],"asks":[{"price":3820.68,"qty":1.83240602}],"checksum":833535834,"timestamp":"2024-06-01T22:43:08.868207Z"}]}
{"channel":"book","type":"update","data":[{"symbol":"ETH/USDC","bids":[{"price":3817.66,"qty":3.80745754}],"asks":[],"checksum":1303184387,"timestamp":"2024-06-01T22:43:08.890038Z"}]}
{"channel":"book","type":"update","data":[{"symbol":"ETH/USDC","bids":[{"price":3817.66,"qty":0.24969754}],"asks":[],"checksum":4216828704,"timestamp":"2024-06-01T22:43:08.893079Z"}]}
