{"channel":"book","type":"snapshot","data":[{"symbol":"ETH/USDT","bids":[{"price":3822.50,"qty":0.25000000},{"price":3822.49,"qty":2.61829948},{"price":3822.27,"qty":0.34000000},{"price":3822.22,"qty":0.84627249},{"price":3822.03,"qty":0.07349757},{"price":3821.86,"qty":2.09700000},{"price":3821.71,"qty":31.90748938},{"price":3821.70,"qty":21.84457666},{"price":3821.66,"qty":0.40940967},{"price":3821.62,"qty":5.00000000}],"asks":[{"price":3823.25,"qty":0.60000000},{"price":3823.26,"qty":2.02047045},{"price":3823.27,"qty":0.34000000},{"price":3823.29,"qty":0.60000000},{"price":3823.30,"qty":2.61841198},{"price":3823.45,"qty":2.61764390},{"price":3823.57,"qty":2.10000000},{"price":3823.78,"qty":0.25000000},{"price":3823.99,"qty":0.07349757},{"price":3824.03,"qty":49.92091604}],"checksum":3655950796}]}
{"channel":"book","type":"update","data":[{"symbol":"ETH/USDT","bids":[{"price":3821.70,"qty":26.85930615}],"asks":[],"checksum":3762685528,"timestamp":"2024-06-01T22:42:39.997121Z"}]}
{"channel":"book","type":"update","data":[{"symbol":"ETH/USDT","bids":[{"price":3822.50,"qty":0.24316679}],"asks":[],"checksum":1300491,"timestamp":"2024-06-01T22:42:40.168085Z"}]}
{"channel":"book","type":"update","data":[{"symbol":"ETH/USDT","bids":[],"asks":[{"price":3824.02,"qty":0.43533455}],"checksum":1093711074,"timestamp":"2024-06-01T22:42:40.393916Z"}]}
{"channel":"book","type":"update","data":[{"symbol":"ETH/USDT","bids":[{"price":3821.70,"qty":27.61833853}],"asks":[],"checksum":277065451,"timestamp":"2024-06-01T22:42:40.462473Z"}]}
{"channel":"book","type":"update","data":[{"symbol":"ETH/USDT","bids":[{"price":3821.86,"qty":0.00000000},{"price":3821.59,"qty":2.61891228}],"asks":[],"checksum":2887615856,"timestamp":"2024-06-01T22:42:41.395443Z"}]}
{"channel":"book","type":"update","data":[{"symbol":"ETH/USDT","bids":[],"asks":[{"price":3823.24,"qty":0.09817562}],"checksum":2458052660,"timestamp":"2024-06-01T22:42:41.409503Z"}]}
{"channel":"book","type":"update","data":[{"symbol":"ETH/USDT","bids":[],"asks":[{"price":3823.24,"qty":2.71662002}],"checksum":2654049953,"timestamp":"2024-06-01T22:42:41.419757Z"}]}
{"channel":"book","type":"update","data":[{"symbol":"ETH/USDT","bids":[],"asks":[{"price":3823.30,"qty":0.00000000},{"price":3824.02,"qty":0.43533455}],"checksum":2703317034,"timestamp":"2024-06-01T22:42:41.424495Z"}]}
{"channel":"book","type":"update","data":[{"symbol":"ETH/USDT","bids":[{"price":3821.76,"qty":2.09700000}],"asks":[],"checksum":2439006904,"timestamp":"2024-06-01T22:42:41.493933Z"}]}
{"channel":"book","type":"update","data":[{"symbol":"ETH/USDT","bids":[],"asks":[{"price":3823.23,"qty":0.60000000}],"checksum":1466002083,"timestamp":"2024-06-01T22:42:41.521999Z"}]}
{"channel":"book","type":"update","data":[{"symbol":"ETH/USDT","bids":[],"asks":[{"price":3823.29,"qty":0.00000000},{"price":3824.02,"qty":0.43533455}],"checksum":1181293400,"timestamp":"2024-06-01T22:42:41.522029Z"}]}
{"channel":"book","type":"update","data":[{"symbol":"ETH/USDT","bids":[],"asks":[{"price":3823.24,"qty":2.61844440}],"checksum":3580615177,"timestamp":"2024-06-01T22:42:41.526651Z"}]}
{"channel":"book","type":"update","data":[{"symbol":"ETH/USDT","bids":[],"asks":[{"price":3823.22,"qty":0.09817565}],"checksum":1203276044,"timestamp":"2024-06-01T22:42:41.531271Z"}]}
{"channel":"book","type":"update","data":[{"symbol":"ETH/USDT","bids":[],"asks":[{"price":3823.26,"qty":0.00000000},{"price":3824.02,"qty":0.43533455}],"checksum":4241943243,"timestamp":"2024-06-01T22:42:41.639670Z"}]}
{"channel":"book","type":"update","data":[{"symbol":"ETH/USDT","bids":[],"asks":[{"price":3823.24,"qty":4.63891485}],"checksum":256407963,"timestamp":"2024-06-01T22:42:41.644642Z"}]}
{"channel":"book","type":"update","data":[{"symbol":"ETH/USDT","bids":[],"asks":[{"price":3823.25,"qty":0.00000000},{"price":3824.05,"qty":48.92299009}],"checksum":336112255,"timestamp":"2024-06-01T22:42:41.813162Z"}]}
{"channel":"book","type":"update","data":[{"symbol":"ETH/USDT","bids":[],"asks":[{"price":3824.01,"qty":0.21589289}],"checksum":91678754,"timestamp":"2024-06-01T22:42:42.420799Z"}]}
{"channel":"book","type":"update","data":[{"symbol":"ETH/USDT","bids":[{"price":3821.71,"qty":32.09615153}],"asks":[],"checksum":3075960354,"timestamp":"2024-06-01T22:42:42.420835Z"}]}
{"channel":"book","type":"update","data":[{"symbol":"ETH/USDT","bids":[],"asks":[{"price":3824.01,"qty":0.00000000},{"price":3824.05,"qty":48.92299009}],"checksum":2787716223,"timestamp":"2024-06-01T22:42:42.428737Z"}]}
{"channel":"book","type":"update","data":[{"symbol":"ETH/USDT","bids":[],"asks":[{"price":3824.01,"qty":0.21274541}],"checksum":2931711422,"timestamp":"2024-06-01T22:42:42.571580Z"}]}
{"channel":"book","type":"update","data":[{"symbol":"ETH/USDT","bids":[],"asks":[{"price":3824.01,"qty":0.00000000},{"price":3824.05,"qty":48.92299009}],"checksum":2787716223,"timestamp":"2024-06-01T22:42:42.577204Z"}]}
{"channel":"book","type":"update","data":[{"symbol":"ETH/USDT","bids":[{"price":3821.77,"qty":0.21466331}],"asks":[],"checksum":2782165529,"timestamp":"2024-06-01T22:42:42.586628Z"}]}
{"channel":"book","type":"update","data":[{"symbol":"ETH/USDT","bids":[{"price":3821.72,"qty":0.09316590}],"asks":[],"checksum":371240887,"timestamp":"2024-06-01T22:42:42.586715Z"}]}
{"channel":"book","type":"update","data":[{"symbol":"ETH/USDT","bids":[],"asks":[{"price":3824.01,"qty":0.21726422}],"checksum":1519822963,"timestamp":"2024-06-01T22:42:42.720073Z"}]}
{"channel":"book","type":"update","data":[{"symbol":"ETH/USDT","bids":[],"asks":[{"price":3824.01,"qty":0.00000000},{"price":3824.05,"qty":48.92299009}],"checksum":371240887,"timestamp":"2024-06-01T22:42:42.726700Z"}]}
{"channel":"book","type":"update","data":[{"symbol":"ETH/USDT","bids":[],"asks":[{"price":3824.01,"qty":0.19096592}],"checksum":2982173136,"timestamp":"2024-06-01T22:42:42.870315Z"}]}
{"channel":"book","type":"update","data":[{"symbol":"ETH/USDT","bids":[],"asks":[{"price":3824.01,"qty":0.00000000},{"price":3824.05,"qty":48.92299009}],"checksum":371240887,"timestamp":"2024-06-01T22:42:42.876388Z"}]}
{"channel":"book","type":"update","data":[{"symbol":"ETH/USDT","bids":[],"asks":[{"price":3824.01,"qty":0.19059999}],"checksum":1613788868,"timestamp":"2024-06-01T22:42:43.019646Z"}]}
{"channel":"book","type":"update","data":[{"symbol":"ETH/USDT","bids":[],"asks":[{"price":3824.01,"qty":0.00000000},{"price":3824.05,"qty":48.92299009}],"checksum":371240887,"timestamp":"2024-06-01T22:42:43.025520Z"}]}
{"channel":"book","type":"update","data":[{"symbol":"ETH/USDT","bids":[],"asks":[{"price":3824.01,"qty":0.20481555}],"checksum":3993152884,"timestamp":"2024-06-01T22:42:43.171200Z"}]}
{"channel":"book","type":"update","data":[{"symbol":"ETH/USDT","bids":[],"asks":[{"price":3824.01,"qty":0.00000000},{"price":3824.05,"qty":48.92299009}],"checksum":371240887,"timestamp":"2024-06-01T22:42:43.177271Z"}]}
{"channel":"book","type":"update","data":[{"symbol":"ETH/USDT","bids":[],"asks":[{"price":3823.22,"qty":0.00000000},{"price":3824.06,"qty":0.72912968}],"checksum":3344710311,"timestamp":"2024-06-01T22:42:43.184622Z"}]}
{"channel":"book","type":"update","data":[{"symbol":"ETH/USDT","bids":[],"asks":[{"price":3824.02,"qty":0.00000000},{"price":3824.10,"qty":0.71500000}],"checksum":1691379431,"timestamp":"2024-06-01T22:42:43.190960Z"}]}
{"channel":"book","type":"update","data":[{"symbol":"ETH/USDT","bids":[],"asks":[{"price":3824.04,"qty":0.45683949}],"checksum":2247937097,"timestamp":"2024-06-01T22:42:43.192564Z"}]}
{"channel":"book","type":"update","data":[{"symbol":"ETH/USDT","bids":[{"price":3821.71,"qty":0.18866215}],"asks":[],"checksum":2072055600,"timestamp":"2024-06-01T22:42:43.223431Z"}]}
{"channel":"book","type":"update","data":[{"symbol":"ETH/USDT","bids":[{"price":3821.77,"qty":5.03006129}],"asks":[],"checksum":96028494,"timestamp":"2024-06-01T22:42:43.225412Z"}]}
{"channel":"book","type":"update","data":[{"symbol":"ETH/USDT","bids":[],"asks":[{"price":3824.01,"qty":0.19338828}],"checksum":2932667204,"timestamp":"2024-06-01T22:42:43.320092Z"}]}
{"channel":"book","type":"update","data":[{"symbol":"ETH/USDT","bids":[],"asks":[{"price":3824.01,"qty":0.00000000},{"price":3824.06,"qty":0.72912968}],"checksum":96028494,"timestamp":"2024-06-01T22:42:43.325987Z"}]}
{"channel":"book","type":"update","data":[{"symbol":"ETH/USDT","bids":[],"asks":[{"price":3823.22,"qty":0.09817560}],"checksum":1220832272,"timestamp":"2024-06-01T22:42:43.445079Z"}]}
{"channel":"book","type":"update","data":[{"symbol":"ETH/USDT","bids":[],"asks":[{"price":3823.26,"qty":0.60000000}],"checksum":2326432468,"timestamp":"2024-06-01T22:42:43.465772Z"}]}
{"channel":"book","type":"update","data":[{"symbol":"ETH/USDT","bids":[],"asks":[{"price":3824.01,"qty":0.19721880}],"checksum":2959591292,"timestamp":"2024-06-01T22:42:43.470118Z"}]}
{"channel":"book","type":"update","data":[{"symbol":"ETH/USDT","bids":[],"asks":[{"price":3824.01,"qty":0.00000000},{"price":3824.04,"qty":0.45683949}],"checksum":2326432468,"timestamp":"2024-06-01T22:42:43.475834Z"}]}
{"channel":"book","type":"update","data":[{"symbol":"ETH/USDT","bids":[{"price":3821.70,"qty":26.85930615}],"asks":[],"checksum":577542598,"timestamp":"2024-06-01T22:42:43.570709Z"}]}
{"channel":"book","type":"update","data":[{"symbol":"ETH/USDT","bids":[],"asks":[{"price":3824.01,"qty":0.19327792}],"checksum":2202151067,"timestamp":"2024-06-01T22:42:43.620094Z"}]}
{"channel":"book","type":"update","data":[{"symbol":"ETH/USDT","bids":[],"asks":[{"price":3824.01,"qty":0.00000000},{"price":3824.04,"qty":0.45683949}],"checksum":577542598,"timestamp":"2024-06-01T22:42:43.626874Z"}]}
{"channel":"book","type":"update","data":[{"symbol":"ETH/USDT","bids":[{"price":3821.70,"qty":21.84457666}],"asks":[],"checksum":2554062337,"timestamp":"2024-06-01T22:42:43.637950Z"}]}
{"channel":"book","type":"update","data":[{"symbol":"ETH/USDT","bids":[],"asks":[{"price":3823.30,"qty":0.60000000}],"checksum":1153965935,"timestamp":"2024-06-01T22:42:43.722071Z"}]}
{"channel":"book","type":"update","data":[{"symbol":"ETH/USDT","bids":[],"asks":[{"price":3823.24,"qty":2.61844440}],"checksum":3365498981,"timestamp":"2024-06-01T22:42:43.874935Z"}]}
{"channel":"book","type":"update","data":[{"symbol":"ETH/USDT","bids":[],"asks":[{"price":3823.22,"qty":1.61968307}],"checksum":346112136,"timestamp":"2024-06-01T22:42:43.879822Z"}]}
{"channel":"book","type":"update","data":[{"symbol":"ETH/USDT","bids":[],"asks":[{"price":3823.21,"qty":1.02254450}],"checksum":1074728604,"timestamp":"2024-06-01T22:42:43.880018Z"}]}
{"channel":"book","type":"update","data":[{"symbol":"ETH/USDT","bids":[],"asks":[{"price":3823.22,"qty":1.52150747}],"checksum":1947536841,"timestamp":"2024-06-01T22:42:43.884518Z"}]}
{"channel":"book","type":"update","data":[{"symbol":"ETH/USDT","bids":[],"asks":[{"price":3823.20,"qty":0.60000000}],"checksum":62558240,"timestamp":"2024-06-01T22:42:44.030527Z"}]}
{"channel":"book","type":"update","data":[{"symbol":"ETH/USDT","bids":[],"asks":[{"price":3823.19,"qty":0.09817559}],"checksum":2524343547,"timestamp":"2024-06-01T22:42:44.045598Z"}]}
{"channel":"book","type":"update","data":[{"symbol":"ETH/USDT","bids":[{"price":3822.49,"qty":0.00000000},{"price":3821.66,"qty":0.40940967}],"asks":[],"checksum":785508242,"timestamp":"2024-06-01T22:42:44.324022Z"}]}
{"channel":"book","type":"update","data":[{"symbol":"ETH/USDT","bids":[{"price":3822.19,"qty":2.61850160}],"asks":[],"checksum":3689466616,"timestamp":"2024-06-01T22:42:44.328247Z"}]}
{"channel":"book","type":"update","data":[{"symbol":"ETH/USDT","bids":[],"asks":[{"price":3823.21,"qty":1.62254450}],"checksum":3556563890,"timestamp":"2024-06-01T22:42:44.356663Z"}]}
{"channel":"book","type":"update","data":[{"symbol":"ETH/USDT","bids":[],"asks":[{"price":3823.16,"qty":2.61850364}],"checksum":3605626832,"timestamp":"2024-06-01T22:42:44.358078Z"}]}
{"channel":"book","type":"update","data":[{"symbol":"ETH/USDT","bids":[],"asks":[{"price":3823.24,"qty":0.00000000},{"price":3823.45,"qty":2.61764390}],"checksum":3410758218,"timestamp":"2024-06-01T22:42:44.360255Z"}]}
{"channel":"book","type":"update","data":[{"symbol":"ETH/USDT","bids":[{"price":3822.50,"qty":0.00000000},{"price":3821.66,"qty":0.40940967}],"asks":[],"checksum":2220460295,"timestamp":"2024-06-01T22:42:44.361569Z"}]}
{"channel":"book","type":"update","data":[{"symbol":"ETH/USDT","bids":[{"price":3822.28,"qty":0.25000000}],"asks":[],"checksum":4263712942,"timestamp":"2024-06-01T22:42:44.361611Z"}]}
{"channel":"book","type":"update","data":[{"symbol":"ETH/USDT","bids":[{"price":3822.20,"qty":5.00000000}],"asks":[],"checksum":93814078,"timestamp":"2024-06-01T22:42:44.361885Z"}]}
{"channel":"book","type":"update","data":[{"symbol":"ETH/USDT","bids":[],"asks":[{"price":3823.19,"qty":0.00000000},{"price":3823.57,"qty":2.10000000}],"checksum":2506086279,"timestamp":"2024-06-01T22:42:44.362458Z"}]}
{"channel":"book","type":"update","data":[{"symbol":"ETH/USDT","bids":[],"asks":[{"price":3823.15,"qty":0.09818299}],"checksum":3613700039,"timestamp":"2024-06-01T22:42:44.366458Z"}]}
{"channel":"book","type":"update","data":[{"symbol":"ETH/USDT","bids":[{"price":3822.29,"qty":0.84627249}],"asks":[],"checksum":691558531,"timestamp":"2024-06-01T22:42:44.451872Z"}]}
{"channel":"book","type":"update","data":[{"symbol":"ETH/USDT","bids":[{"price":3822.22,"qty":0.00000000},{"price":3821.71,"qty":0.18866215}],"asks":[],"checksum":1906161095,"timestamp":"2024-06-01T22:42:44.455871Z"}]}
{"channel":"book","type":"update","data":[{"symbol":"ETH/USDT","bids":[{"price":3822.20,"qty":0.00000000},{"price":3821.70,"qty":21.84457666}],"asks":[],"checksum":976640222,"timestamp":"2024-06-01T22:42:44.456229Z"}]}
{"channel":"book","type":"update","data":[{"symbol":"ETH/USDT","bids":[{"price":3822.23,"qty":5.00000000}],"asks":[],"checksum":3678123827,"timestamp":"2024-06-01T22:42:44.456377Z"}]}
{"channel":"book","type":"update","data":[{"symbol":"ETH/USDT","bids":[{"price":3822.30,"qty":0.25000000}],"asks":[],"checksum":3493992863,"timestamp":"2024-06-01T22:42:44.456824Z"}]}
{"channel":"book","type":"update","data":[{"symbol":"ETH/USDT","bids":[{"price":3822.28,"qty":0.00000000},{"price":3821.71,"qty":0.18866215}],"asks":[],"checksum":3494020382,"timestamp":"2024-06-01T22:42:44.587846Z"}]}
{"channel":"book","type":"update","data":[{"symbol":"ETH/USDT","bids":[],"asks":[{"price":3823.23,"qty":0.00000000},{"price":3823.57,"qty":2.10000000}],"checksum":3462232294,"timestamp":"2024-06-01T22:42:44.821396Z"}]}
{"channel":"book","type":"update","data":[{"symbol":"ETH/USDT","bids":[{"price":3822.20,"qty":5.00000000}],"asks":[],"checksum":3174839428,"timestamp":"2024-06-01T22:42:45.208322Z"}]}
{"channel":"book","type":"update","data":[{"symbol":"ETH/USDT","bids":[{"price":3822.23,"qty":0.00000000},{"price":3821.71,"qty":0.18866215}],"asks":[],"checksum":1694202386,"timestamp":"2024-06-01T22:42:45.208613Z"}]}
{"channel":"book","type":"update","data":[{"symbol":"ETH/USDT","bids":[{"price":3821.77,"qty":4.81539798}],"asks":[],"checksum":3241794415,"timestamp":"2024-06-01T22:42:45.685199Z"}]}
{"channel":"book","type":"update","data":[{"symbol":"ETH/USDT","bids":[{"price":3821.72,"qty":0.00000000},{"price":3821.70,"qty":21.84457666}],"asks":[],"checksum":3926607799,"timestamp":"2024-06-01T22:42:45.685429Z"}]}
{"channel":"book","type":"update","data":[{"symbol":"ETH/USDT","bids":[{"price":3821.78,"qty":0.26358826}],"asks":[],"checksum":2014337781,"timestamp":"2024-06-01T22:42:45.687382Z"}]}
{"channel":"book","type":"update","data":[{"symbol":"ETH/USDT","bids":[],"asks":[{"price":3823.21,"qty":0.60000000}],"checksum":417512321,"timestamp":"2024-06-01T22:42:46.182525Z"}]}
{"channel":"book","type":"update","data":[{"symbol":"ETH/USDT","bids":[],"asks":[{"price":3823.22,"qty":0.00000000},{"price":3823.78,"qty":0.25000000}],"checksum":1479616236,"timestamp":"2024-06-01T22:42:46.182589Z"}]}
{"channel":"book","type":"update","data":[{"symbol":"ETH/USDT","bids":[],"asks":[{"price":3823.14,"qty":1.02254450}],"checksum":78021029,"timestamp":"2024-06-01T22:42:46.187370Z"}]}
{"channel":"book","type":"update","data":[{"symbol":"ETH/USDT","bids":[],"asks":[{"price":3823.15,"qty":0.00000000},{"price":3823.78,"qty":0.25000000}],"checksum":1652758372,"timestamp":"2024-06-01T22:42:46.191659Z"}]}
{"channel":"book","type":"update","data":[{"symbol":"ETH/USDT","bids":[],"asks":[{"price":3823.20,"qty":0.00000000},{"price":3823.99,"qty":0.07349757}],"checksum":1706955591,"timestamp":"2024-06-01T22:42:46.221132Z"}]}
{"channel":"book","type":"update","data":[{"symbol":"ETH/USDT","bids":[],"asks":[{"price":3823.21,"qty":0.00000000},{"price":3824.02,"qty":0.41997389}],"checksum":539723319,"timestamp":"2024-06-01T22:42:46.265981Z"}]}
{"channel":"book","type":"update","data":[{"symbol":"ETH/USDT","bids":[],"asks":[{"price":3823.13,"qty":0.09818292}],"checksum":884891849,"timestamp":"2024-06-01T22:42:46.277795Z"}]}
{"channel":"book","type":"update","data":[{"symbol":"ETH/USDT","bids":[],"asks":[{"price":3823.13,"qty":0.00000000},{"price":3824.02,"qty":0.41997389}],"checksum":539723319,"timestamp":"2024-06-01T22:42:46.642399Z"}]}
{"channel":"book","type":"update","data":[{"symbol":"ETH/USDT","bids":[{"price":3821.77,"qty":0.00000000},{"price":3821.70,"qty":21.84457666}],"asks":[],"checksum":3448070092,"timestamp":"2024-06-01T22:42:46.658743Z"}]}
{"channel":"book","type":"update","data":[{"symbol":"ETH/USDT","bids":[{"price":3821.71,"qty":29.41376624}],"asks":[],"checksum":4070570951,"timestamp":"2024-06-01T22:42:46.664104Z"}]}
{"channel":"book","type":"update","data":[{"symbol":"ETH/USDT","bids":[{"price":3821.70,"qty":22.60373447}],"asks":[],"checksum":2227536854,"timestamp":"2024-06-01T22:42:46.755963Z"}]}
{"channel":"book","type":"update","data":[{"symbol":"ETH/USDT","bids":[],"asks":[{"price":3824.01,"qty":0.20369785}],"checksum":3251398799,"timestamp":"2024-06-01T22:42:46.773184Z"}]}
{"channel":"book","type":"update","data":[{"symbol":"ETH/USDT","bids":[{"price":3821.70,"qty":27.61929219}],"asks":[],"checksum":3047739382,"timestamp":"2024-06-01T22:42:46.819223Z"}]}
{"channel":"book","type":"update","data":[{"symbol":"ETH/USDT","bids":[],"asks":[{"price":3823.14,"qty":0.00000000},{"price":3824.02,"qty":0.41997389}],"checksum":3234278304,"timestamp":"2024-06-01T22:42:48.432305Z"}]}
{"channel":"book","type":"update","data":[{"symbol":"ETH/USDT","bids":[],"asks":[{"price":3823.15,"qty":1.02254450}],"checksum":2783835960,"timestamp":"2024-06-01T22:42:48.437521Z"}]}
{"channel":"book","type":"update","data":[{"symbol":"ETH/USDT","bids":[{"price":3821.78,"qty":0.00000000},{"price":3821.66,"qty":0.40940967}],"asks":[],"checksum":266970829,"timestamp":"2024-06-01T22:42:48.866464Z"}]}
{"channel":"book","type":"update","data":[{"symbol":"ETH/USDT","bids":[{"price":3821.77,"qty":0.24531124}],"asks":[],"checksum":1075610216,"timestamp":"2024-06-01T22:42:48.869151Z"}]}
{"channel":"book","type":"update","data":[{"symbol":"ETH/USDT","bids":[{"price":3821.72,"qty":0.03411477}],"asks":[],"checksum":2125276139,"timestamp":"2024-06-01T22:42:48.869177Z"}]}
{"channel":"book","type":"update","data":[{"symbol":"ETH/USDT","bids":[{"price":3822.19,"qty":0.00000000},{"price":3821.70,"qty":27.61929219}],"asks":[],"checksum":2439568863,"timestamp":"2024-06-01T22:42:49.325782Z"}]}
{"channel":"book","type":"update","data":[{"symbol":"ETH/USDT","bids":[{"price":3822.31,"qty":2.61842281}],"asks":[],"checksum":2730445427,"timestamp":"2024-06-01T22:42:49.330388Z"}]}
{"channel":"book","type":"update","data":[{"symbol":"ETH/USDT","bids":[{"price":3822.20,"qty":0.00000000},{"price":3821.70,"qty":27.61929219}],"asks":[],"checksum":3123067269,"timestamp":"2024-06-01T22:42:49.330553Z"}]}
{"channel":"book","type":"update","data":[{"symbol":"ETH/USDT","bids":[{"price":3822.32,"qty":0.25000000}],"asks":[],"checksum":309034411,"timestamp":"2024-06-01T22:42:49.586052Z"}]}
{"channel":"book","type":"update","data":[{"symbol":"ETH/USDT","bids":[{"price":3821.90,"qty":5.00000000}],"asks":[],"checksum":2010826026,"timestamp":"2024-06-01T22:42:49.590598Z"}]}
{"channel":"book","type":"update","data":[{"symbol":"ETH/USDT","bids":[{"price":3822.31,"qty":0.00000000},{"price":3821.71,"qty":29.41376624}],"asks":[],"checksum":513506272,"timestamp":"2024-06-01T22:42:49.590832Z"}]}
{"channel":"book","type":"update","data":[{"symbol":"ETH/USDT","bids":[{"price":3822.33,"qty":2.61840911}],"asks":[],"checksum":1025291682,"timestamp":"2024-06-01T22:42:49.595244Z"}]}
{"channel":"book","type":"update","data":[{"symbol":"ETH/USDT","bids":[{"price":3822.32,"qty":0.00000000},{"price":3821.71,"qty":31.02319741}],"asks":[],"checksum":388005837,"timestamp":"2024-06-01T22:42:50.087840Z"}]}
{"channel":"book","type":"update","data":[{"symbol":"ETH/USDT","bids":[{"price":3822.34,"qty":0.25000000}],"asks":[],"checksum":2389883385,"timestamp":"2024-06-01T22:42:50.088117Z"}]}
{"channel":"book","type":"update","data":[{"symbol":"ETH/USDT","bids":[{"price":3822.30,"qty":0.00000000},{"price":3821.71,"qty":31.02319741}],"asks":[],"checksum":4076346704,"timestamp":"2024-06-01T22:42:50.092557Z"}]}
{"channel":"book","type":"update","data":[{"symbol":"ETH/USDT","bids":[{"price":3821.76,"qty":0.00000000},{"price":3821.70,"qty":27.61929219}],"asks":[],"checksum":4055558149,"timestamp":"2024-06-01T22:42:50.156180Z"}]}
{"channel":"book","type":"update","data":[{"symbol":"ETH/USDT","bids":[],"asks":[{"price":3823.14,"qty":0.09818284}],"checksum":3943263235,"timestamp":"2024-06-01T22:42:50.158777Z"}]}
{"channel":"book","type":"update","data":[{"symbol":"ETH/USDT","bids":[],"asks":[{"price":3823.14,"qty":0.00000000},{"price":3824.01,"qty":0.20369785}],"checksum":4055558149,"timestamp":"2024-06-01T22:42:50.178246Z"}]}
{"channel":"book","type":"update","data":[{"symbol":"ETH/USDT","bids":[],"asks":[{"price":3823.11,"qty":2.61863413}],"checksum":4110353746,"timestamp":"2024-06-01T22:42:50.184223Z"}]}
{"channel":"book","type":"update","data":[{"symbol":"ETH/USDT","bids":[],"asks":[{"price":3823.16,"qty":0.00000000},{"price":3824.01,"qty":0.20369785}],"checksum":1239424192,"timestamp":"2024-06-01T22:42:50.184464Z"}]}
{"channel":"book","type":"update","data":[{"symbol":"ETH/USDT","bids":[],"asks":[{"price":3823.14,"qty":0.09818996}],"checksum":383276361,"timestamp":"2024-06-01T22:42:50.187684Z"}]}
{"channel":"book","type":"update","data":[{"symbol":"ETH/USDT","bids":[],"asks":[{"price":3823.14,"qty":0.00000000},{"price":3824.01,"qty":0.20369785}],"checksum":1239424192,"timestamp":"2024-06-01T22:42:50.191301Z"}]}
{"channel":"book","type":"update","data":[{"symbol":"ETH/USDT","bids":[],"asks":[{"price":3823.10,"qty":0.09818923}],"checksum":1857742590,"timestamp":"2024-06-01T22:42:50.195355Z"}]}
{"channel":"book","type":"update","data":[{"symbol":"ETH/USDT","bids":[],"asks":[{"price":3823.10,"qty":2.71673465}],"checksum":1898385157,"timestamp":"2024-06-01T22:42:50.214713Z"}]}
{"channel":"book","type":"update","data":[{"symbol":"ETH/USDT","bids":[],"asks":[{"price":3823.11,"qty":0.00000000},{"price":3824.01,"qty":0.20369785}],"checksum":3900700110,"timestamp":"2024-06-01T22:42:50.217000Z"}]}
{"channel":"book","type":"update","data":[{"symbol":"ETH/USDT","bids":[{"price":3822.27,"qty":0.00000000},{"price":3821.66,"qty":0.40940967}],"asks":[],"checksum":3762291246,"timestamp":"2024-06-01T22:42:50.217517Z"}]}
{"channel":"book","type":"update","data":[{"symbol":"ETH/USDT","bids":[{"price":3822.03,"qty":0.00000000},{"price":3821.59,"qty":2.61891228}],"asks":[],"checksum":3144534755,"timestamp":"2024-06-01T22:42:50.219506Z"}]}
{"channel":"book","type":"update","data":[{"symbol":"ETH/USDT","bids":[],"asks":[{"price":3823.48,"qty":0.72912968}],"checksum":1761561001,"timestamp":"2024-06-01T22:42:50.221087Z"}]}
{"channel":"book","type":"update","data":[{"symbol":"ETH/USDT","bids":[],"asks":[{"price":3823.10,"qty":2.61854542}],"checksum":714820936,"timestamp":"2024-06-01T22:42:50.311091Z"}]}
{"channel":"book","type":"update","data":[{"symbol":"ETH/USDT","bids":[{"price":3821.62,"qty":0.07349757}],"asks":[],"checksum":3747387992,"timestamp":"2024-06-01T22:42:50.320768Z"}]}
{"channel":"book","type":"update","data":[{"symbol":"ETH/USDT","bids":[],"asks":[{"price":3823.10,"qty":0.00000000},{"price":3824.01,"qty":0.20369785}],"checksum":3681268132,"timestamp":"2024-06-01T22:42:50.406000Z"}]}
{"channel":"book","type":"update","data":[{"symbol":"ETH/USDT","bids":[],"asks":[{"price":3823.98,"qty":15.70725859}],"checksum":749071123,"timestamp":"2024-06-01T22:42:50.409941Z"}]}
{"channel":"book","type":"update","data":[{"symbol":"ETH/USDT","bids":[],"asks":[{"price":3823.14,"qty":0.72912968}],"checksum":3632379617,"timestamp":"2024-06-01T22:42:50.410174Z"}]}
{"channel":"book","type":"update","data":[{"symbol":"ETH/USDT","bids":[],"asks":[{"price":3823.48,"qty":0.00000000},{"price":3823.99,"qty":0.07349757}],"checksum":3271440313,"timestamp":"2024-06-01T22:42:50.587699Z"}]}
{"channel":"book","type":"update","data":[{"symbol":"ETH/USDT","bids":[],"asks":[{"price":3823.15,"qty":0.00000000},{"price":3824.01,"qty":0.20369785}],"checksum":288434184,"timestamp":"2024-06-01T22:42:50.719464Z"}]}
{"channel":"book","type":"update","data":[{"symbol":"ETH/USDT","bids":[],"asks":[{"price":3823.14,"qty":0.00000000},{"price":3824.04,"qty":0.43533455}],"checksum":3730465897,"timestamp":"2024-06-01T22:42:50.723903Z"}]}
{"channel":"book","type":"update","data":[{"symbol":"ETH/USDT","bids":[],"asks":[{"price":3823.25,"qty":0.72912968}],"checksum":2532813985,"timestamp":"2024-06-01T22:42:50.723919Z"}]}
{"channel":"book","type":"update","data":[{"symbol":"ETH/USDT","bids":[],"asks":[{"price":3823.09,"qty":0.52358152}],"checksum":24980314,"timestamp":"2024-06-01T22:42:50.724673Z"}]}
{"channel":"book","type":"update","data":[{"symbol":"ETH/USDT","bids":[],"asks":[{"price":3823.27,"qty":0.00000000},{"price":3824.01,"qty":0.20369785}],"checksum":1265155798,"timestamp":"2024-06-01T22:42:50.727838Z"}]}
{"channel":"book","type":"update","data":[{"symbol":"ETH/USDT","bids":[],"asks":[{"price":3823.25,"qty":1.06912968}],"checksum":1384375410,"timestamp":"2024-06-01T22:42:50.728023Z"}]}
{"channel":"book","type":"update","data":[{"symbol":"ETH/USDT","bids":[],"asks":[{"price":3823.26,"qty":0.00000000},{"price":3824.04,"qty":0.43533455}],"checksum":1426609524,"timestamp":"2024-06-01T22:42:50.757342Z"}]}
{"channel":"book","type":"update","data":[{"symbol":"ETH/USDT","bids":[],"asks":[{"price":3824.04,"qty":0.00000000},{"price":3824.09,"qty":39.94165654}],"checksum":1352389786,"timestamp":"2024-06-01T22:42:51.452337Z"}]}
{"channel":"book","type":"update","data":[{"symbol":"ETH/USDT","bids":[],"asks":[{"price":3823.97,"qty":0.45071923}],"checksum":3435730283,"timestamp":"2024-06-01T22:42:51.454899Z"}]}
{"channel":"book","type":"update","data":[{"symbol":"ETH/USDT","bids":[{"price":3822.29,"qty":0.00000000},{"price":3821.59,"qty":2.61891228}],"asks":[],"checksum":3823239667,"timestamp":"2024-06-01T22:42:51.660656Z"}]}
{"channel":"book","type":"update","data":[{"symbol":"ETH/USDT","bids":[],"asks":[{"price":3823.56,"qty":2.77900000}],"checksum":3442991956,"timestamp":"2024-06-01T22:42:51.664528Z"}]}
{"channel":"book","type":"update","data":[{"symbol":"ETH/USDT","bids":[],"asks":[{"price":3823.25,"qty":0.72912968}],"checksum":2363636664,"timestamp":"2024-06-01T22:42:51.716570Z"}]}
{"channel":"book","type":"update","data":[{"symbol":"ETH/USDT","bids":[],"asks":[{"price":3823.24,"qty":0.34000000}],"checksum":235217135,"timestamp":"2024-06-01T22:42:51.716840Z"}]}
{"channel":"book","type":"update","data":[{"symbol":"ETH/USDT","bids":[],"asks":[{"price":3823.08,"qty":0.09818917}],"checksum":421316804,"timestamp":"2024-06-01T22:42:51.734335Z"}]}
{"channel":"book","type":"update","data":[{"symbol":"ETH/USDT","bids":[{"price":3821.90,"qty":5.84627249}],"asks":[],"checksum":3400537180,"timestamp":"2024-06-01T22:42:51.953071Z"}]}
{"channel":"book","type":"update","data":[{"symbol":"ETH/USDT","bids":[{"price":3822.34,"qty":0.24316679}],"asks":[],"checksum":1250384214,"timestamp":"2024-06-01T22:42:51.996391Z"}]}
{"channel":"book","type":"update","data":[{"symbol":"ETH/USDT","bids":[{"price":3821.77,"qty":0.00000000},{"price":3821.54,"qty":2.09700000}],"asks":[],"checksum":2069955127,"timestamp":"2024-06-01T22:42:52.054977Z"}]}
{"channel":"book","type":"update","data":[{"symbol":"ETH/USDT","bids":[{"price":3821.72,"qty":0.00000000},{"price":3821.44,"qty":0.72912968}],"asks":[],"checksum":2705929184,"timestamp":"2024-06-01T22:42:52.054996Z"}]}
{"channel":"book","type":"update","data":[{"symbol":"ETH/USDT","bids":[{"price":3821.91,"qty":0.04609996}],"asks":[],"checksum":2210292380,"timestamp":"2024-06-01T22:42:52.057355Z"}]}
{"channel":"book","type":"update","data":[{"symbol":"ETH/USDT","bids":[{"price":3821.72,"qty":0.24326919}],"asks":[],"checksum":3809119323,"timestamp":"2024-06-01T22:42:52.057470Z"}]}
{"channel":"book","type":"update","data":[{"symbol":"ETH/USDT","bids":[{"price":3822.33,"qty":0.00000000},{"price":3821.54,"qty":2.09700000}],"asks":[],"checksum":2800133331,"timestamp":"2024-06-01T22:42:52.157101Z"}]}
{"channel":"book","type":"update","data":[{"symbol":"ETH/USDT","bids":[{"price":3821.99,"qty":0.34000000}],"asks":[],"checksum":3933188716,"timestamp":"2024-06-01T22:42:52.160214Z"}]}
{"channel":"book","type":"update","data":[{"symbol":"ETH/USDT","bids":[{"price":3822.34,"qty":0.00000000},{"price":3821.54,"qty":2.09700000}],"asks":[],"checksum":1365407241,"timestamp":"2024-06-01T22:42:52.161574Z"}]}
{"channel":"book","type":"update","data":[{"symbol":"ETH/USDT","bids":[{"price":3821.72,"qty":5.24326919}],"asks":[],"checksum":3508794767,"timestamp":"2024-06-01T22:42:52.161892Z"}]}
{"channel":"book","type":"update","data":[{"symbol":"ETH/USDT","bids":[{"price":3821.90,"qty":0.84627249}],"asks":[],"checksum":747428901,"timestamp":"2024-06-01T22:42:52.161908Z"}]}
{"channel":"book","type":"update","data":[{"symbol":"ETH/USDT","bids":[{"price":3822.02,"qty":2.61861615}],"asks":[],"checksum":121738118,"timestamp":"2024-06-01T22:42:52.162168Z"}]}
{"channel":"book","type":"update","data":[{"symbol":"ETH/USDT","bids":[],"asks":[{"price":3823.45,"qty":0.00000000},{"price":3823.98,"qty":15.70725859}],"checksum":664506664,"timestamp":"2024-06-01T22:42:52.206476Z"}]}
{"channel":"book","type":"update","data":[{"symbol":"ETH/USDT","bids":[{"price":3822.03,"qty":5.00000000}],"asks":[],"checksum":1220299071,"timestamp":"2024-06-01T22:42:52.209587Z"}]}
{"channel":"book","type":"update","data":[{"symbol":"ETH/USDT","bids":[],"asks":[{"price":3823.17,"qty":2.61783787}],"checksum":3173527283,"timestamp":"2024-06-01T22:42:52.211249Z"}]}
{"channel":"book","type":"update","data":[{"symbol":"ETH/USDT","bids":[{"price":3821.99,"qty":0.00000000},{"price":3821.59,"qty":2.61891228}],"asks":[],"checksum":2016076151,"timestamp":"2024-06-01T22:42:52.212370Z"}]}
{"channel":"book","type":"update","data":[{"symbol":"ETH/USDT","bids":[{"price":3822.06,"qty":0.34000000}],"asks":[],"checksum":3289431028,"timestamp":"2024-06-01T22:42:52.212606Z"}]}
{"channel":"book","type":"update","data":[{"symbol":"ETH/USDT","bids":[],"asks":[{"price":3823.24,"qty":0.00000000},{"price":3823.98,"qty":15.70725859}],"checksum":4276182954,"timestamp":"2024-06-01T22:42:52.213823Z"}]}
{"channel":"book","type":"update","data":[{"symbol":"ETH/USDT","bids":[{"price":3821.72,"qty":0.24326919}],"asks":[],"checksum":3141093395,"timestamp":"2024-06-01T22:42:52.213881Z"}]}
{"channel":"book","type":"update","data":[{"symbol":"ETH/USDT","bids":[],"asks":[{"price":3823.14,"qty":0.34000000}],"checksum":2485098124,"timestamp":"2024-06-01T22:42:52.214294Z"}]}
{"channel":"book","type":"update","data":[{"symbol":"ETH/USDT","bids":[{"price":3822.04,"qty":0.84627249}],"asks":[],"checksum":2181282263,"timestamp":"2024-06-01T22:42:52.214988Z"}]}
{"channel":"book","type":"update","data":[{"symbol":"ETH/USDT","bids":[{"price":3822.04,"qty":0.00000000},{"price":3821.62,"qty":0.07349757}],"asks":[],"checksum":2485098124,"timestamp":"2024-06-01T22:42:52.453166Z"}]}
{"channel":"book","type":"update","data":[{"symbol":"ETH/USDT","bids":[{"price":3822.07,"qty":0.84627249}],"asks":[],"checksum":3004167459,"timestamp":"2024-06-01T22:42:52.453316Z"}]}
{"channel":"book","type":"update","data":[{"symbol":"ETH/USDT","bids":[{"price":3821.90,"qty":0.00000000},{"price":3821.62,"qty":0.07349757}],"asks":[],"checksum":56065845,"timestamp":"2024-06-01T22:42:52.457465Z"}]}
{"channel":"book","type":"update","data":[{"symbol":"ETH/USDT","bids":[{"price":3822.02,"qty":0.00000000},{"price":3821.59,"qty":2.61891228}],"asks":[],"checksum":3244617377,"timestamp":"2024-06-01T22:42:52.458499Z"}]}
{"channel":"book","type":"update","data":[{"symbol":"ETH/USDT","bids":[{"price":3822.08,"qty":2.61858028}],"asks":[],"checksum":2880656446,"timestamp":"2024-06-01T22:42:52.462536Z"}]}
{"channel":"book","type":"update","data":[{"symbol":"ETH/USDT","bids":[],"asks":[{"price":3823.57,"qty":0.00000000},{"price":3823.98,"qty":15.70725859}],"checksum":926609833,"timestamp":"2024-06-01T22:42:52.707197Z"}]}
{"channel":"book","type":"update","data":[{"symbol":"ETH/USDT","bids":[{"price":3822.09,"qty":5.00000000}],"asks":[],"checksum":2061415175,"timestamp":"2024-06-01T22:42:52.707429Z"}]}
{"channel":"book","type":"update","data":[{"symbol":"ETH/USDT","bids":[],"asks":[{"price":3823.26,"qty":2.09700000}],"checksum":1040837990,"timestamp":"2024-06-01T22:42:52.709519Z"}]}
{"channel":"book","type":"update","data":[{"symbol":"ETH/USDT","bids":[],"asks":[{"price":3823.56,"qty":0.00000000},{"price":3823.98,"qty":15.70725859},{"price":3823.96,"qty":2.77900000}],"checksum":3816253431,"timestamp":"2024-06-01T22:42:52.710356Z"}]}
{"channel":"book","type":"update","data":[{"symbol":"ETH/USDT","bids":[{"price":3822.10,"qty":0.84627249}],"asks":[],"checksum":762563102,"timestamp":"2024-06-01T22:42:52.712245Z"}]}
{"channel":"book","type":"update","data":[{"symbol":"ETH/USDT","bids":[{"price":3822.06,"qty":0.00000000},{"price":3821.66,"qty":0.40940967}],"asks":[],"checksum":2880604228,"timestamp":"2024-06-01T22:42:52.817705Z"}]}
{"channel":"book","type":"update","data":[{"symbol":"ETH/USDT","bids":[{"price":3822.09,"qty":5.34000000}],"asks":[],"checksum":4221223235,"timestamp":"2024-06-01T22:42:52.817887Z"}]}
{"channel":"book","type":"update","data":[{"symbol":"ETH/USDT","bids":[{"price":3822.03,"qty":0.00000000},{"price":3821.62,"qty":0.07349757}],"asks":[],"checksum":4080840756,"timestamp":"2024-06-01T22:42:52.821931Z"}]}
{"channel":"book","type":"update","data":[{"symbol":"ETH/USDT","bids":[{"price":3822.07,"qty":0.00000000},{"price":3821.59,"qty":2.61891228}],"asks":[],"checksum":3627485922,"timestamp":"2024-06-01T22:42:52.822392Z"}]}
{"channel":"book","type":"update","data":[{"symbol":"ETH/USDT","bids":[],"asks":[{"price":3823.09,"qty":0.00000000},{"price":3823.98,"qty":15.70725859}],"checksum":3570642347,"timestamp":"2024-06-01T22:42:52.923921Z"}]}
{"channel":"book","type":"update","data":[{"symbol":"ETH/USDT","bids":[],"asks":[{"price":3823.13,"qty":1.02255915}],"checksum":3150069255,"timestamp":"2024-06-01T22:42:52.928715Z"}]}
{"channel":"book","type":"update","data":[{"symbol":"ETH/USDT","bids":[],"asks":[{"price":3823.55,"qty":2.02048509}],"checksum":4269273842,"timestamp":"2024-06-01T22:42:52.928966Z"}]}
{"channel":"book","type":"update","data":[{"symbol":"ETH/USDT","bids":[],"asks":[{"price":3823.96,"qty":57.55843213}],"checksum":2206611749,"timestamp":"2024-06-01T22:42:52.929007Z"}]}
{"channel":"book","type":"update","data":[{"symbol":"ETH/USDT","bids":[],"asks":[{"price":3823.08,"qty":0.00000000},{"price":3823.97,"qty":0.45071923}],"checksum":48824091,"timestamp":"2024-06-01T22:42:52.929020Z"}]}
{"channel":"book","type":"update","data":[{"symbol":"ETH/USDT","bids":[],"asks":[{"price":3823.12,"qty":0.09818915}],"checksum":3294849193,"timestamp":"2024-06-01T22:42:52.934048Z"}]}
{"channel":"book","type":"update","data":[{"symbol":"ETH/USDT","bids":[{"price":3822.11,"qty":0.25000000}],"asks":[],"checksum":3022201458,"timestamp":"2024-06-01T22:42:53.086220Z"}]}
{"channel":"book","type":"update","data":[{"symbol":"ETH/USDT","bids":[{"price":3822.12,"qty":0.84627249}],"asks":[],"checksum":1312037764,"timestamp":"2024-06-01T22:42:53.091308Z"}]}
{"channel":"book","type":"update","data":[{"symbol":"ETH/USDT","bids":[],"asks":[{"price":3823.11,"qty":0.72912968}],"checksum":2977485706,"timestamp":"2024-06-01T22:42:53.098228Z"}]}
{"channel":"book","type":"update","data":[{"symbol":"ETH/USDT","bids":[],"asks":[{"price":3823.12,"qty":0.00000000},{"price":3823.96,"qty":57.55843213}],"checksum":3607963503,"timestamp":"2024-06-01T22:42:53.103236Z"}]}
{"channel":"book","type":"update","data":[{"symbol":"ETH/USDT","bids":[],"asks":[{"price":3823.10,"qty":0.09818915}],"checksum":963896092,"timestamp":"2024-06-01T22:42:53.107250Z"}]}
{"channel":"book","type":"update","data":[{"symbol":"ETH/USDT","bids":[{"price":3821.71,"qty":0.18866215}],"asks":[],"checksum":3467227471,"timestamp":"2024-06-01T22:42:53.441413Z"}]}
{"channel":"book","type":"update","data":[{"symbol":"ETH/USDT","bids":[{"price":3821.71,"qty":2.85824139}],"asks":[],"checksum":1710943788,"timestamp":"2024-06-01T22:42:53.443182Z"}]}
{"channel":"book","type":"update","data":[{"symbol":"ETH/USDT","bids":[{"price":3822.10,"qty":0.00000000},{"price":3821.62,"qty":0.07349757}],"asks":[],"checksum":4027448357,"timestamp":"2024-06-01T22:42:53.451661Z"}]}
{"channel":"book","type":"update","data":[{"symbol":"ETH/USDT","bids":[],"asks":[{"price":3823.11,"qty":0.00000000},{"price":3823.96,"qty":57.55843213}],"checksum":50115770,"timestamp":"2024-06-01T22:42:53.455891Z"}]}
{"channel":"book","type":"update","data":[{"symbol":"ETH/USDT","bids":[{"price":3822.13,"qty":0.25000000}],"asks":[],"checksum":3482867744,"timestamp":"2024-06-01T22:42:53.456773Z"}]}
{"channel":"book","type":"update","data":[{"symbol":"ETH/USDT","bids":[{"price":3821.70,"qty":22.60373447}],"asks":[],"checksum":2154367641,"timestamp":"2024-06-01T22:42:53.471591Z"}]}
{"channel":"book","type":"update","data":[{"symbol":"ETH/USDT","bids":[{"price":3822.11,"qty":0.00000000},{"price":3821.62,"qty":0.07349757}],"asks":[],"checksum":320052028,"timestamp":"2024-06-01T22:42:53.585670Z"}]}
{"channel":"book","type":"update","data":[{"symbol":"ETH/USDT","bids":[{"price":3822.14,"qty":0.84627249}],"asks":[],"checksum":2069236808,"timestamp":"2024-06-01T22:42:53.590627Z"}]}
{"channel":"book","type":"update","data":[{"symbol":"ETH/USDT","bids":[{"price":3821.70,"qty":21.84457666}],"asks":[],"checksum":2697417830,"timestamp":"2024-06-01T22:42:53.930674Z"}]}
{"channel":"book","type":"update","data":[{"symbol":"ETH/USDT","bids":[],"asks":[{"price":3823.25,"qty":0.00000000},{"price":3823.97,"qty":0.45071923}],"checksum":1517664753,"timestamp":"2024-06-01T22:42:53.951760Z"}]}
{"channel":"book","type":"update","data":[{"symbol":"ETH/USDT","bids":[{"price":3822.12,"qty":0.00000000},{"price":3821.62,"qty":0.07349757}],"asks":[],"checksum":1615952512,"timestamp":"2024-06-01T22:42:53.951860Z"}]}
{"channel":"book","type":"update","data":[{"symbol":"ETH/USDT","bids":[],"asks":[{"price":3823.10,"qty":0.00000000},{"price":3823.98,"qty":15.70725859}],"checksum":3363842075,"timestamp":"2024-06-01T22:42:53.953402Z"}]}
{"channel":"book","type":"update","data":[{"symbol":"ETH/USDT","bids":[{"price":3822.09,"qty":5.00000000}],"asks":[],"checksum":2587574587,"timestamp":"2024-06-01T22:42:53.972406Z"}]}
{"channel":"book","type":"update","data":[{"symbol":"ETH/USDT","bids":[{"price":3822.10,"qty":0.34000000}],"asks":[],"checksum":1977549536,"timestamp":"2024-06-01T22:42:53.972573Z"}]}
{"channel":"book","type":"update","data":[{"symbol":"ETH/USDT","bids":[{"price":3822.15,"qty":0.25000000}],"asks":[],"checksum":2217906679,"timestamp":"2024-06-01T22:42:54.086899Z"}]}
{"channel":"book","type":"update","data":[{"symbol":"ETH/USDT","bids":[],"asks":[{"price":3823.71,"qty":0.72912968}],"checksum":1828068723,"timestamp":"2024-06-01T22:42:54.087684Z"}]}
{"channel":"book","type":"update","data":[{"symbol":"ETH/USDT","bids":[{"price":3822.13,"qty":0.00000000},{"price":3821.66,"qty":0.40940967}],"asks":[],"checksum":2176471079,"timestamp":"2024-06-01T22:42:54.091938Z"}]}
{"channel":"book","type":"update","data":[{"symbol":"ETH/USDT","bids":[{"price":3822.16,"qty":0.84627249}],"asks":[],"checksum":3072433037,"timestamp":"2024-06-01T22:42:54.092017Z"}]}
{"channel":"book","type":"update","data":[{"symbol":"ETH/USDT","bids":[{"price":3822.09,"qty":0.00000000},{"price":3821.66,"qty":0.40940967}],"asks":[],"checksum":2896311691,"timestamp":"2024-06-01T22:42:54.092244Z"}]}
{"channel":"book","type":"update","data":[{"symbol":"ETH/USDT","bids":[{"price":3822.08,"qty":0.00000000},{"price":3821.62,"qty":0.07349757}],"asks":[],"checksum":2885375388,"timestamp":"2024-06-01T22:42:54.092564Z"}]}
{"channel":"book","type":"update","data":[{"symbol":"ETH/USDT","bids":[{"price":3822.16,"qty":3.46479805}],"asks":[],"checksum":2248758112,"timestamp":"2024-06-01T22:42:54.097315Z"}]}
{"channel":"book","type":"update","data":[{"symbol":"ETH/USDT","bids":[{"price":3822.17,"qty":5.00000000}],"asks":[],"checksum":3082372223,"timestamp":"2024-06-01T22:42:54.207942Z"}]}
{"channel":"book","type":"update","data":[{"symbol":"ETH/USDT","bids":[{"price":3822.16,"qty":2.61852556}],"asks":[],"checksum":1740365990,"timestamp":"2024-06-01T22:42:54.212992Z"}]}
{"channel":"book","type":"update","data":[{"symbol":"ETH/USDT","bids":[{"price":3822.18,"qty":0.84627249}],"asks":[],"checksum":488594362,"timestamp":"2024-06-01T22:42:54.213052Z"}]}
{"channel":"book","type":"update","data":[{"symbol":"ETH/USDT","bids":[{"price":3822.16,"qty":0.00000000},{"price":3821.66,"qty":0.40940967}],"asks":[],"checksum":212208878,"timestamp":"2024-06-01T22:42:54.213234Z"}]}
{"channel":"book","type":"update","data":[{"symbol":"ETH/USDT","bids":[{"price":3822.18,"qty":1.09627249}],"asks":[],"checksum":914311435,"timestamp":"2024-06-01T22:42:54.214142Z"}]}
{"channel":"book","type":"update","data":[{"symbol":"ETH/USDT","bids":[],"asks":[{"price":3823.97,"qty":0.00000000},{"price":3823.98,"qty":15.70725859}],"checksum":2352942220,"timestamp":"2024-06-01T22:42:54.285987Z"}]}
{"channel":"book","type":"update","data":[{"symbol":"ETH/USDT","bids":[],"asks":[{"price":3823.95,"qty":0.41075758}],"checksum":3711999266,"timestamp":"2024-06-01T22:42:54.287513Z"}]}
{"channel":"book","type":"update","data":[{"symbol":"ETH/USDT","bids":[{"price":3822.14,"qty":0.00000000},{"price":3821.62,"qty":0.07349757}],"asks":[],"checksum":672770392,"timestamp":"2024-06-01T22:42:54.452230Z"}]}
{"channel":"book","type":"update","data":[{"symbol":"ETH/USDT","bids":[{"price":3822.15,"qty":0.00000000},{"price":3821.59,"qty":2.61891228}],"asks":[],"checksum":470044890,"timestamp":"2024-06-01T22:42:54.456936Z"}]}
{"channel":"book","type":"update","data":[{"symbol":"ETH/USDT","bids":[],"asks":[{"price":3823.12,"qty":0.09818322}],"checksum":3066285210,"timestamp":"2024-06-01T22:42:54.549658Z"}]}
{"channel":"book","type":"update","data":[{"symbol":"ETH/USDT","bids":[{"price":3821.70,"qty":0.00000000},{"price":3821.54,"qty":2.09700000}],"asks":[],"checksum":1618493515,"timestamp":"2024-06-01T22:42:54.552817Z"}]}
{"channel":"book","type":"update","data":[{"symbol":"ETH/USDT","bids":[{"price":3821.71,"qty":16.58861930}],"asks":[],"checksum":2554254503,"timestamp":"2024-06-01T22:42:54.556124Z"}]}
{"channel":"book","type":"update","data":[{"symbol":"ETH/USDT","bids":[],"asks":[{"price":3823.12,"qty":0.00000000},{"price":3823.96,"qty":57.55843213}],"checksum":855197927,"timestamp":"2024-06-01T22:42:54.602202Z"}]}
{"channel":"book","type":"update","data":[{"symbol":"ETH/USDT","bids":[{"price":3822.17,"qty":0.00000000},{"price":3821.44,"qty":0.72912968}],"asks":[],"checksum":415919792,"timestamp":"2024-06-01T22:42:55.208558Z"}]}
{"channel":"book","type":"update","data":[{"symbol":"ETH/USDT","bids":[{"price":3821.72,"qty":5.24326919}],"asks":[],"checksum":1286303856,"timestamp":"2024-06-01T22:42:55.214293Z"}]}
{"channel":"book","type":"update","data":[{"symbol":"ETH/USDT","bids":[],"asks":[{"price":3823.55,"qty":0.00000000},{"price":3823.98,"qty":15.70725859}],"checksum":2181598018,"timestamp":"2024-06-01T22:42:55.226183Z"}]}
{"channel":"book","type":"update","data":[{"symbol":"ETH/USDT","bids":[],"asks":[{"price":3823.96,"qty":2.77900000}],"checksum":1968071758,"timestamp":"2024-06-01T22:42:55.226322Z"}]}
{"channel":"book","type":"update","data":[{"symbol":"ETH/USDT","bids":[],"asks":[{"price":3823.94,"qty":48.64888494}],"checksum":2956608521,"timestamp":"2024-06-01T22:42:55.228405Z"}]}
{"channel":"book","type":"update","data":[{"symbol":"ETH/USDT","bids":[{"price":3821.72,"qty":5.00000000}],"asks":[],"checksum":2147367863,"timestamp":"2024-06-01T22:42:55.323907Z"}]}
{"channel":"book","type":"update","data":[{"symbol":"ETH/USDT","bids":[{"price":3821.91,"qty":0.00000000},{"price":3821.20,"qty":0.52358152}],"asks":[],"checksum":3919822477,"timestamp":"2024-06-01T22:42:55.323964Z"}]}
{"channel":"book","type":"update","data":[{"symbol":"ETH/USDT","bids":[{"price":3822.10,"qty":0.00000000},{"price":3820.97,"qty":0.30543870}],"asks":[],"checksum":1242602730,"timestamp":"2024-06-01T22:42:55.327009Z"}]}
{"channel":"book","type":"update","data":[{"symbol":"ETH/USDT","bids":[{"price":3821.80,"qty":0.34000000}],"asks":[],"checksum":2178306875,"timestamp":"2024-06-01T22:42:55.327523Z"}]}
{"channel":"book","type":"update","data":[{"symbol":"ETH/USDT","bids":[{"price":3821.72,"qty":5.25042401}],"asks":[],"checksum":1114690067,"timestamp":"2024-06-01T22:42:55.330216Z"}]}
{"channel":"book","type":"update","data":[{"symbol":"ETH/USDT","bids":[{"price":3822.18,"qty":3.71478436}],"asks":[],"checksum":1803960326,"timestamp":"2024-06-01T22:42:55.881500Z"}]}
{"channel":"book","type":"update","data":[{"symbol":"ETH/USDT","bids":[{"price":3822.19,"qty":5.00000000}],"asks":[],"checksum":1769229672,"timestamp":"2024-06-01T22:42:55.886137Z"}]}
{"channel":"book","type":"update","data":[{"symbol":"ETH/USDT","bids":[{"price":3822.20,"qty":0.84627249}],"asks":[],"checksum":887904259,"timestamp":"2024-06-01T22:42:55.953065Z"}]}
{"channel":"book","type":"update","data":[{"symbol":"ETH/USDT","bids":[{"price":3821.72,"qty":0.25042401}],"asks":[],"checksum":4195543971,"timestamp":"2024-06-01T22:42:55.957120Z"}]}
{"channel":"book","type":"update","data":[{"symbol":"ETH/USDT","bids":[{"price":3822.18,"qty":2.86851187}],"asks":[],"checksum":3963581075,"timestamp":"2024-06-01T22:42:55.957814Z"}]}
{"channel":"book","type":"update","data":[{"symbol":"ETH/USDT","bids":[{"price":3822.21,"qty":0.25000000}],"asks":[],"checksum":2908078432,"timestamp":"2024-06-01T22:42:55.957925Z"}]}
{"channel":"book","type":"update","data":[{"symbol":"ETH/USDT","bids":[{"price":3822.18,"qty":2.61851187}],"asks":[],"checksum":3616795553,"timestamp":"2024-06-01T22:42:56.086331Z"}]}
{"channel":"book","type":"update","data":[{"symbol":"ETH/USDT","bids":[{"price":3822.22,"qty":0.84627249}],"asks":[],"checksum":2131125407,"timestamp":"2024-06-01T22:42:56.091407Z"}]}
{"channel":"book","type":"update","data":[{"symbol":"ETH/USDT","bids":[],"asks":[{"price":3823.26,"qty":0.00000000},{"price":3823.98,"qty":15.70725859}],"checksum":3647266970,"timestamp":"2024-06-01T22:42:56.323367Z"}]}
{"channel":"book","type":"update","data":[{"symbol":"ETH/USDT","bids":[{"price":3822.23,"qty":0.25000000}],"asks":[],"checksum":2654029987,"timestamp":"2024-06-01T22:42:56.329000Z"}]}
{"channel":"book","type":"update","data":[{"symbol":"ETH/USDT","bids":[{"price":3822.20,"qty":0.00000000},{"price":3821.62,"qty":0.07349757}],"asks":[],"checksum":1131412331,"timestamp":"2024-06-01T22:42:56.329777Z"}]}
{"channel":"book","type":"update","data":[{"symbol":"ETH/USDT","bids":[],"asks":[{"price":3823.30,"qty":0.00000000},{"price":3823.99,"qty":0.07349757}],"checksum":1809226064,"timestamp":"2024-06-01T22:42:56.342377Z"}]}
{"channel":"book","type":"update","data":[{"symbol":"ETH/USDT","bids":[],"asks":[{"price":3823.98,"qty":0.00000000},{"price":3824.01,"qty":0.20369785}],"checksum":3188899019,"timestamp":"2024-06-01T22:42:56.354568Z"}]}
{"channel":"book","type":"update","data":[{"symbol":"ETH/USDT","bids":[],"asks":[{"price":3823.17,"qty":0.00000000},{"price":3824.10,"qty":0.71500000}],"checksum":2988591687,"timestamp":"2024-06-01T22:42:56.355685Z"}]}
{"channel":"book","type":"update","data":[{"symbol":"ETH/USDT","bids":[{"price":3822.18,"qty":0.00000000},{"price":3821.59,"qty":2.61891228}],"asks":[],"checksum":2120915756,"timestamp":"2024-06-01T22:42:56.355755Z"}]}
{"channel":"book","type":"update","data":[{"symbol":"ETH/USDT","bids":[],"asks":[{"price":3823.14,"qty":0.00000000},{"price":3824.15,"qty":5.00000000}],"checksum":1927659698,"timestamp":"2024-06-01T22:42:56.359135Z"}]}
{"channel":"book","type":"update","data":[{"symbol":"ETH/USDT","bids":[{"price":3821.80,"qty":0.00000000},{"price":3821.54,"qty":2.09700000}],"asks":[],"checksum":1130167070,"timestamp":"2024-06-01T22:42:56.359169Z"}]}
{"channel":"book","type":"update","data":[{"symbol":"ETH/USDT","bids":[],"asks":[{"price":3823.63,"qty":0.34000000}],"checksum":2090680290,"timestamp":"2024-06-01T22:42:56.359355Z"}]}
{"channel":"book","type":"update","data":[{"symbol":"ETH/USDT","bids":[{"price":3822.21,"qty":0.59000000}],"asks":[],"checksum":4031942489,"timestamp":"2024-06-01T22:42:56.359464Z"}]}
{"channel":"book","type":"update","data":[{"symbol":"ETH/USDT","bids":[{"price":3822.24,"qty":2.61847073}],"asks":[],"checksum":2094392140,"timestamp":"2024-06-01T22:42:56.360713Z"}]}
{"channel":"book","type":"update","data":[{"symbol":"ETH/USDT","bids":[],"asks":[{"price":3823.51,"qty":2.61760256}],"checksum":3288825915,"timestamp":"2024-06-01T22:42:56.360817Z"}]}
{"channel":"book","type":"update","data":[{"symbol":"ETH/USDT","bids":[],"asks":[{"price":3823.63,"qty":0.00000000},{"price":3824.10,"qty":0.71500000}],"checksum":2065360370,"timestamp":"2024-06-01T22:42:56.363840Z"}]}
{"channel":"book","type":"update","data":[{"symbol":"ETH/USDT","bids":[],"asks":[{"price":3823.43,"qty":0.34000000}],"checksum":978699890,"timestamp":"2024-06-01T22:42:56.364021Z"}]}
{"channel":"book","type":"update","data":[{"symbol":"ETH/USDT","bids":[],"asks":[{"price":3823.96,"qty":0.00000000},{"price":3824.10,"qty":0.71500000}],"checksum":768625591,"timestamp":"2024-06-01T22:42:56.373245Z"}]}
{"channel":"book","type":"update","data":[{"symbol":"ETH/USDT","bids":[{"price":3822.21,"qty":0.25000000}],"asks":[],"checksum":421981897,"timestamp":"2024-06-01T22:42:56.380504Z"}]}
{"channel":"book","type":"update","data":[{"symbol":"ETH/USDT","bids":[{"price":3822.25,"qty":0.34000000}],"asks":[],"checksum":2544101155,"timestamp":"2024-06-01T22:42:56.380885Z"}]}
{"channel":"book","type":"update","data":[{"symbol":"ETH/USDT","bids":[],"asks":[{"price":3823.71,"qty":0.00000000},{"price":3824.15,"qty":5.00000000}],"checksum":1456283829,"timestamp":"2024-06-01T22:42:56.381249Z"}]}
{"channel":"book","type":"update","data":[{"symbol":"ETH/USDT","bids":[],"asks":[{"price":3824.09,"qty":2.77900000}],"checksum":2339323206,"timestamp":"2024-06-01T22:42:56.381882Z"}]}
{"channel":"book","type":"update","data":[{"symbol":"ETH/USDT","bids":[{"price":3822.24,"qty":0.00000000},{"price":3821.59,"qty":2.61891228}],"asks":[],"checksum":4203532927,"timestamp":"2024-06-01T22:42:56.387213Z"}]}
{"channel":"book","type":"update","data":[{"symbol":"ETH/USDT","bids":[{"price":3822.19,"qty":0.00000000},{"price":3821.54,"qty":2.09700000}],"asks":[],"checksum":2801145200,"timestamp":"2024-06-01T22:42:56.392004Z"}]}
{"channel":"book","type":"update","data":[{"symbol":"ETH/USDT","bids":[{"price":3822.21,"qty":0.00000000},{"price":3821.44,"qty":0.72912968}],"asks":[],"checksum":1773510491,"timestamp":"2024-06-01T22:42:56.392100Z"}]}
{"channel":"book","type":"update","data":[{"symbol":"ETH/USDT","bids":[{"price":3822.26,"qty":0.25000000}],"asks":[],"checksum":961395620,"timestamp":"2024-06-01T22:42:56.392264Z"}]}
{"channel":"book","type":"update","data":[{"symbol":"ETH/USDT","bids":[{"price":3822.26,"qty":1.09627249}],"asks":[],"checksum":2256740694,"timestamp":"2024-06-01T22:42:56.392582Z"}]}
{"channel":"book","type":"update","data":[{"symbol":"ETH/USDT","bids":[{"price":3822.26,"qty":1.17481104}],"asks":[],"checksum":1737943425,"timestamp":"2024-06-01T22:42:56.394908Z"}]}
{"channel":"book","type":"update","data":[{"symbol":"ETH/USDT","bids":[{"price":3822.25,"qty":0.00000000},{"price":3821.44,"qty":0.72912968}],"asks":[],"checksum":1126052102,"timestamp":"2024-06-01T22:42:56.396119Z"}]}
{"channel":"book","type":"update","data":[{"symbol":"ETH/USDT","bids":[{"price":3822.28,"qty":0.34000000}],"asks":[],"checksum":2187551082,"timestamp":"2024-06-01T22:42:56.396223Z"}]}
{"channel":"book","type":"update","data":[{"symbol":"ETH/USDT","bids":[],"asks":[{"price":3823.99,"qty":0.00000000},{"price":3824.15,"qty":5.00000000}],"checksum":1689133784,"timestamp":"2024-06-01T22:42:56.403675Z"}]}
{"channel":"book","type":"update","data":[{"symbol":"ETH/USDT","bids":[],"asks":[{"price":3823.82,"qty":2.09700000}],"checksum":2031154864,"timestamp":"2024-06-01T22:42:56.422254Z"}]}
{"channel":"book","type":"update","data":[{"symbol":"ETH/USDT","bids":[{"price":3822.26,"qty":1.09627249}],"asks":[],"checksum":4046244594,"timestamp":"2024-06-01T22:42:56.426298Z"}]}
{"channel":"book","type":"update","data":[{"symbol":"ETH/USDT","bids":[{"price":3822.26,"qty":0.25000000}],"asks":[],"checksum":3983113892,"timestamp":"2024-06-01T22:42:56.426554Z"}]}
{"channel":"book","type":"update","data":[{"symbol":"ETH/USDT","bids":[{"price":3822.23,"qty":5.25000000}],"asks":[],"checksum":2612590681,"timestamp":"2024-06-01T22:42:56.426867Z"}]}
{"channel":"book","type":"update","data":[{"symbol":"ETH/USDT","bids":[{"price":3822.23,"qty":5.00000000}],"asks":[],"checksum":2746405438,"timestamp":"2024-06-01T22:42:56.427669Z"}]}
{"channel":"book","type":"update","data":[{"symbol":"ETH/USDT","bids":[{"price":3822.29,"qty":0.25000000}],"asks":[],"checksum":1997862056,"timestamp":"2024-06-01T22:42:56.427812Z"}]}
{"channel":"book","type":"update","data":[{"symbol":"ETH/USDT","bids":[],"asks":[{"price":3824.10,"qty":0.00000000},{"price":3824.15,"qty":5.00000000}],"checksum":3579838304,"timestamp":"2024-06-01T22:42:56.437556Z"}]}
{"channel":"book","type":"update","data":[{"symbol":"ETH/USDT","bids":[{"price":3822.26,"qty":0.00000000},{"price":3821.54,"qty":2.09700000}],"asks":[],"checksum":3452149075,"timestamp":"2024-06-01T22:42:56.586835Z"}]}
{"channel":"book","type":"update","data":[{"symbol":"ETH/USDT","bids":[],"asks":[{"price":3824.10,"qty":0.72912968}],"checksum":639111750,"timestamp":"2024-06-01T22:42:56.588662Z"}]}
{"channel":"book","type":"update","data":[{"symbol":"ETH/USDT","bids":[{"price":3821.71,"qty":13.91904006}],"asks":[],"checksum":4221505092,"timestamp":"2024-06-01T22:42:56.939491Z"}]}
{"channel":"book","type":"update","data":[{"symbol":"ETH/USDT","bids":[{"price":3821.72,"qty":0.77400827}],"asks":[],"checksum":3462879193,"timestamp":"2024-06-01T22:42:56.944216Z"}]}
{"channel":"book","type":"update","data":[{"symbol":"ETH/USDT","bids":[{"price":3821.73,"qty":5.00000000}],"asks":[],"checksum":213108223,"timestamp":"2024-06-01T22:42:56.951267Z"}]}
{"channel":"book","type":"update","data":[{"symbol":"ETH/USDT","bids":[{"price":3822.23,"qty":0.00000000},{"price":3821.54,"qty":2.09700000}],"asks":[],"checksum":1102155362,"timestamp":"2024-06-01T22:42:56.951286Z"}]}
{"channel":"book","type":"update","data":[{"symbol":"ETH/USDT","bids":[],"asks":[{"price":3823.95,"qty":0.00000000},{"price":3824.15,"qty":5.00000000}],"checksum":1729188705,"timestamp":"2024-06-01T22:42:57.027979Z"}]}
{"channel":"book","type":"update","data":[{"symbol":"ETH/USDT","bids":[],"asks":[{"price":3823.81,"qty":0.03595718}],"checksum":1834675243,"timestamp":"2024-06-01T22:42:57.029262Z"}]}
{"channel":"book","type":"update","data":[{"symbol":"ETH/USDT","bids":[],"asks":[{"price":3823.93,"qty":0.48302704}],"checksum":1620662415,"timestamp":"2024-06-01T22:42:57.029563Z"}]}
{"channel":"book","type":"update","data":[{"symbol":"ETH/USDT","bids":[],"asks":[{"price":3823.94,"qty":0.00000000},{"price":3824.10,"qty":0.72912968}],"checksum":1816917694,"timestamp":"2024-06-01T22:42:57.516100Z"}]}
{"channel":"book","type":"update","data":[{"symbol":"ETH/USDT","bids":[],"asks":[{"price":3823.13,"qty":0.00000000},{"price":3824.15,"qty":5.00000000}],"checksum":3163221148,"timestamp":"2024-06-01T22:42:57.516149Z"}]}
{"channel":"book","type":"update","data":[{"symbol":"ETH/USDT","bids":[],"asks":[{"price":3823.42,"qty":0.72912968}],"checksum":3957749858,"timestamp":"2024-06-01T22:42:57.520428Z"}]}
{"channel":"book","type":"update","data":[{"symbol":"ETH/USDT","bids":[],"asks":[{"price":3823.42,"qty":0.82731057}],"checksum":3768215494,"timestamp":"2024-06-01T22:42:57.520728Z"}]}
{"channel":"book","type":"update","data":[{"symbol":"ETH/USDT","bids":[],"asks":[{"price":3823.51,"qty":0.00000000},{"price":3824.15,"qty":5.00000000}],"checksum":319670277,"timestamp":"2024-06-01T22:42:57.521298Z"}]}
{"channel":"book","type":"update","data":[{"symbol":"ETH/USDT","bids":[],"asks":[{"price":3823.42,"qty":1.84985781}],"checksum":1598598035,"timestamp":"2024-06-01T22:42:57.521617Z"}]}
{"channel":"book","type":"update","data":[{"symbol":"ETH/USDT","bids":[],"asks":[{"price":3824.08,"qty":77.50564889}],"checksum":2024979157,"timestamp":"2024-06-01T22:42:57.521681Z"}]}
{"channel":"book","type":"update","data":[{"symbol":"ETH/USDT","bids":[],"asks":[{"price":3823.50,"qty":4.51528805}],"checksum":1480302013,"timestamp":"2024-06-01T22:42:57.521753Z"}]}
{"channel":"book","type":"update","data":[{"symbol":"ETH/USDT","bids":[],"asks":[{"price":3823.43,"qty":0.00000000},{"price":3824.10,"qty":0.72912968}],"checksum":1140903780,"timestamp":"2024-06-01T22:42:57.523142Z"}]}
{"channel":"book","type":"update","data":[{"symbol":"ETH/USDT","bids":[],"asks":[{"price":3823.34,"qty":0.34000000}],"checksum":1431976032,"timestamp":"2024-06-01T22:42:57.523294Z"}]}
{"channel":"book","type":"update","data":[{"symbol":"ETH/USDT","bids":[],"asks":[{"price":3824.09,"qty":0.00000000},{"price":3824.10,"qty":0.72912968},{"price":3823.92,"qty":2.77900000}],"checksum":176738171,"timestamp":"2024-06-01T22:42:57.524307Z"}]}
{"channel":"book","type":"update","data":[{"symbol":"ETH/USDT","bids":[],"asks":[{"price":3823.42,"qty":4.46752138}],"checksum":2534651163,"timestamp":"2024-06-01T22:42:57.526469Z"}]}
{"channel":"book","type":"update","data":[{"symbol":"ETH/USDT","bids":[{"price":3822.29,"qty":2.86843648}],"asks":[],"checksum":3936462785,"timestamp":"2024-06-01T22:42:57.526622Z"}]}
{"channel":"book","type":"update","data":[{"symbol":"ETH/USDT","bids":[],"asks":[{"price":3823.42,"qty":4.36934049}],"checksum":2048319020,"timestamp":"2024-06-01T22:42:57.527378Z"}]}
{"channel":"book","type":"update","data":[{"symbol":"ETH/USDT","bids":[],"asks":[{"price":3823.33,"qty":0.09818089}],"checksum":3675697270,"timestamp":"2024-06-01T22:42:57.531617Z"}]}
{"channel":"book","type":"update","data":[{"symbol":"ETH/USDT","bids":[],"asks":[{"price":3823.42,"qty":3.64021081}],"checksum":2622236265,"timestamp":"2024-06-01T22:42:57.588911Z"}]}
{"channel":"book","type":"update","data":[{"symbol":"ETH/USDT","bids":[{"price":3821.72,"qty":0.52358426}],"asks":[],"checksum":487459976,"timestamp":"2024-06-01T22:42:58.247684Z"}]}
{"channel":"book","type":"update","data":[{"symbol":"ETH/USDT","bids":[{"price":3821.74,"qty":0.31985819}],"asks":[],"checksum":4288366740,"timestamp":"2024-06-01T22:42:58.249901Z"}]}
{"channel":"book","type":"update","data":[{"symbol":"ETH/USDT","bids":[{"price":3821.83,"qty":2.09700000}],"asks":[],"checksum":2011770989,"timestamp":"2024-06-01T22:42:59.014779Z"}]}
{"channel":"book","type":"update","data":[{"symbol":"ETH/USDT","bids":[],"asks":[{"price":3823.42,"qty":2.61766357}],"checksum":3901709036,"timestamp":"2024-06-01T22:42:59.725353Z"}]}
{"channel":"book","type":"update","data":[{"symbol":"ETH/USDT","bids":[],"asks":[{"price":3823.50,"qty":0.00000000},{"price":3824.08,"qty":15.70672405}],"checksum":2429927926,"timestamp":"2024-06-01T22:42:59.725548Z"}]}
{"channel":"book","type":"update","data":[{"symbol":"ETH/USDT","bids":[],"asks":[{"price":3823.32,"qty":1.02254724}],"checksum":880068438,"timestamp":"2024-06-01T22:42:59.730227Z"}]}
{"channel":"book","type":"update","data":[{"symbol":"ETH/USDT","bids":[],"asks":[{"price":3823.41,"qty":2.02047318}],"checksum":544685521,"timestamp":"2024-06-01T22:42:59.730403Z"}]}
{"channel":"book","type":"update","data":[{"symbol":"ETH/USDT","bids":[],"asks":[{"price":3823.77,"qty":46.80773156}],"checksum":4071590221,"timestamp":"2024-06-01T22:42:59.730518Z"}]}
{"channel":"book","type":"update","data":[{"symbol":"ETH/USDT","bids":[],"asks":[{"price":3823.33,"qty":0.00000000},{"price":3823.93,"qty":0.48302704}],"checksum":3972057905,"timestamp":"2024-06-01T22:42:59.735156Z"}]}
{"channel":"book","type":"update","data":[{"symbol":"ETH/USDT","bids":[],"asks":[{"price":3823.31,"qty":0.09818086}],"checksum":1818159709,"timestamp":"2024-06-01T22:42:59.740533Z"}]}
{"channel":"book","type":"update","data":[{"symbol":"ETH/USDT","bids":[],"asks":[{"price":3823.81,"qty":0.00000000},{"price":3824.01,"qty":0.20369785}],"checksum":649371889,"timestamp":"2024-06-01T22:42:59.810477Z"}]}
{"channel":"book","type":"update","data":[{"symbol":"ETH/USDT","bids":[],"asks":[{"price":3823.41,"qty":2.03799756}],"checksum":1134934603,"timestamp":"2024-06-01T22:42:59.812299Z"}]}
{"channel":"book","type":"update","data":[{"symbol":"ETH/USDT","bids":[],"asks":[{"price":3823.34,"qty":0.00000000},{"price":3824.07,"qty":0.56416858}],"checksum":3614723014,"timestamp":"2024-06-01T22:42:59.857158Z"}]}
{"channel":"book","type":"update","data":[{"symbol":"ETH/USDT","bids":[],"asks":[{"price":3823.31,"qty":0.43818086}],"checksum":3653574330,"timestamp":"2024-06-01T22:42:59.857276Z"}]}
{"channel":"book","type":"update","data":[{"symbol":"ETH/USDT","bids":[{"price":3821.72,"qty":0.00000000},{"price":3821.59,"qty":2.61891228}],"asks":[],"checksum":1902840559,"timestamp":"2024-06-01T22:43:00.433749Z"}]}
{"channel":"book","type":"update","data":[{"symbol":"ETH/USDT","bids":[{"price":3821.75,"qty":0.79182419}],"asks":[],"checksum":1193779530,"timestamp":"2024-06-01T22:43:00.438324Z"}]}
{"channel":"book","type":"update","data":[{"symbol":"ETH/USDT","bids":[{"price":3821.74,"qty":2.98936191}],"asks":[],"checksum":1096952805,"timestamp":"2024-06-01T22:43:00.438469Z"}]}
{"channel":"book","type":"update","data":[{"symbol":"ETH/USDT","bids":[{"price":3821.74,"qty":2.66950372}],"asks":[],"checksum":1690798904,"timestamp":"2024-06-01T22:43:01.278935Z"}]}
{"channel":"book","type":"update","data":[{"symbol":"ETH/USDT","bids":[{"price":3821.84,"qty":0.05631599}],"asks":[],"checksum":350881141,"timestamp":"2024-06-01T22:43:01.281356Z"}]}
{"channel":"book","type":"update","data":[{"symbol":"ETH/USDT","bids":[{"price":3821.76,"qty":0.24741945}],"asks":[],"checksum":1680677763,"timestamp":"2024-06-01T22:43:01.281395Z"}]}
{"channel":"book","type":"update","data":[{"symbol":"ETH/USDT","bids":[],"asks":[{"price":3823.32,"qty":0.00000000},{"price":3824.10,"qty":0.72912968}],"checksum":285724890,"timestamp":"2024-06-01T22:43:01.975744Z"}]}
{"channel":"book","type":"update","data":[{"symbol":"ETH/USDT","bids":[],"asks":[{"price":3823.77,"qty":0.00000000},{"price":3824.15,"qty":5.00000000}],"checksum":2988759801,"timestamp":"2024-06-01T22:43:01.975892Z"}]}
{"channel":"book","type":"update","data":[{"symbol":"ETH/USDT","bids":[],"asks":[{"price":3823.30,"qty":1.02254724}],"checksum":833398068,"timestamp":"2024-06-01T22:43:01.980961Z"}]}
{"channel":"book","type":"update","data":[{"symbol":"ETH/USDT","bids":[],"asks":[{"price":3823.81,"qty":50.29535606}],"checksum":3784856757,"timestamp":"2024-06-01T22:43:01.980982Z"}]}
{"channel":"book","type":"update","data":[{"symbol":"ETH/USDT","bids":[],"asks":[{"price":3823.31,"qty":0.34000000}],"checksum":1305202617,"timestamp":"2024-06-01T22:43:01.985811Z"}]}
{"channel":"book","type":"update","data":[{"symbol":"ETH/USDT","bids":[],"asks":[{"price":3823.29,"qty":0.09818083}],"checksum":1413657122,"timestamp":"2024-06-01T22:43:01.990958Z"}]}
{"channel":"book","type":"update","data":[{"symbol":"ETH/USDT","bids":[],"asks":[{"price":3823.41,"qty":2.02047318}],"checksum":2140404138,"timestamp":"2024-06-01T22:43:02.522372Z"}]}
{"channel":"book","type":"update","data":[{"symbol":"ETH/USDT","bids":[],"asks":[{"price":3823.80,"qty":0.41997391}],"checksum":1051681237,"timestamp":"2024-06-01T22:43:02.524026Z"}]}
{"channel":"book","type":"update","data":[{"symbol":"ETH/USDT","bids":[],"asks":[{"price":3823.92,"qty":0.00000000},{"price":3824.01,"qty":0.20369785}],"checksum":97483985,"timestamp":"2024-06-01T22:43:03.532753Z"}]}
{"channel":"book","type":"update","data":[{"symbol":"ETH/USDT","bids":[],"asks":[{"price":3823.29,"qty":0.00000000},{"price":3824.10,"qty":0.72912968}],"checksum":3678434990,"timestamp":"2024-06-01T22:43:03.533415Z"}]}
{"channel":"book","type":"update","data":[{"symbol":"ETH/USDT","bids":[],"asks":[{"price":3824.09,"qty":2.77900000}],"checksum":3489381601,"timestamp":"2024-06-01T22:43:03.536174Z"}]}
{"channel":"book","type":"update","data":[{"symbol":"ETH/USDT","bids":[{"price":3822.29,"qty":0.25000000}],"asks":[],"checksum":4011707920,"timestamp":"2024-06-01T22:43:03.606226Z"}]}
{"channel":"book","type":"update","data":[{"symbol":"ETH/USDT","bids":[],"asks":[{"price":3823.42,"qty":0.00000000},{"price":3824.10,"qty":0.72912968}],"checksum":573376816,"timestamp":"2024-06-01T22:43:03.606277Z"}]}
{"channel":"book","type":"update","data":[{"symbol":"ETH/USDT","bids":[{"price":3822.59,"qty":2.61822590}],"asks":[],"checksum":64531300,"timestamp":"2024-06-01T22:43:03.611040Z"}]}
{"channel":"book","type":"update","data":[{"symbol":"ETH/USDT","bids":[],"asks":[{"price":3823.76,"qty":2.61743569}],"checksum":4232563269,"timestamp":"2024-06-01T22:43:03.611084Z"}]}
{"channel":"book","type":"update","data":[{"symbol":"ETH/USDT","bids":[],"asks":[{"price":3824.09,"qty":0.00000000},{"price":3824.10,"qty":0.72912968}],"checksum":1270522546,"timestamp":"2024-06-01T22:43:03.634473Z"}]}
{"channel":"book","type":"update","data":[{"symbol":"ETH/USDT","bids":[{"price":3821.75,"qty":0.00000000},{"price":3821.71,"qty":13.91904006}],"asks":[],"checksum":2149410864,"timestamp":"2024-06-01T22:43:03.923355Z"}]}
{"channel":"book","type":"update","data":[{"symbol":"ETH/USDT","bids":[{"price":3821.74,"qty":0.00000000},{"price":3821.66,"qty":0.40940967}],"asks":[],"checksum":2503163265,"timestamp":"2024-06-01T22:43:03.923482Z"}]}
{"channel":"book","type":"update","data":[{"symbol":"ETH/USDT","bids":[{"price":3821.74,"qty":3.20598358}],"asks":[],"checksum":3551033734,"timestamp":"2024-06-01T22:43:03.928180Z"}]}
{"channel":"book","type":"update","data":[{"symbol":"ETH/USDT","bids":[{"price":3822.60,"qty":0.25000000}],"asks":[],"checksum":510577621,"timestamp":"2024-06-01T22:43:04.086169Z"}]}
{"channel":"book","type":"update","data":[{"symbol":"ETH/USDT","bids":[{"price":3822.29,"qty":0.00000000},{"price":3821.71,"qty":13.91904006}],"asks":[],"checksum":2118689720,"timestamp":"2024-06-01T22:43:04.090508Z"}]}
{"channel":"book","type":"update","data":[{"symbol":"ETH/USDT","bids":[{"price":3822.59,"qty":0.00000000},{"price":3821.66,"qty":0.40940967}],"asks":[],"checksum":3832903457,"timestamp":"2024-06-01T22:43:04.091187Z"}]}
{"channel":"book","type":"update","data":[{"symbol":"ETH/USDT","bids":[{"price":3822.61,"qty":2.61821728}],"asks":[],"checksum":2174360204,"timestamp":"2024-06-01T22:43:04.095310Z"}]}
{"channel":"book","type":"update","data":[{"symbol":"ETH/USDT","bids":[{"price":3821.84,"qty":0.00000000},{"price":3821.66,"qty":0.40940967}],"asks":[],"checksum":2914612249,"timestamp":"2024-06-01T22:43:04.430286Z"}]}
{"channel":"book","type":"update","data":[{"symbol":"ETH/USDT","bids":[{"price":3821.76,"qty":0.00000000},{"price":3821.62,"qty":0.07349757}],"asks":[],"checksum":705036009,"timestamp":"2024-06-01T22:43:04.430368Z"}]}
{"channel":"book","type":"update","data":[{"symbol":"ETH/USDT","bids":[{"price":3821.84,"qty":0.06652975}],"asks":[],"checksum":2360159626,"timestamp":"2024-06-01T22:43:04.432084Z"}]}
{"channel":"book","type":"update","data":[{"symbol":"ETH/USDT","bids":[{"price":3821.75,"qty":0.28767519}],"asks":[],"checksum":2786175628,"timestamp":"2024-06-01T22:43:04.432231Z"}]}
{"channel":"book","type":"update","data":[{"symbol":"ETH/USDT","bids":[{"price":3822.62,"qty":0.25000000}],"asks":[],"checksum":3337790298,"timestamp":"2024-06-01T22:43:04.435238Z"}]}
{"channel":"book","type":"update","data":[{"symbol":"ETH/USDT","bids":[{"price":3822.61,"qty":0.00000000},{"price":3821.71,"qty":13.91904006}],"asks":[],"checksum":986765523,"timestamp":"2024-06-01T22:43:04.562941Z"}]}
{"channel":"book","type":"update","data":[{"symbol":"ETH/USDT","bids":[{"price":3822.63,"qty":2.61820359}],"asks":[],"checksum":1965080777,"timestamp":"2024-06-01T22:43:04.572310Z"}]}
{"channel":"book","type":"update","data":[{"symbol":"ETH/USDT","bids":[{"price":3822.64,"qty":0.25000000}],"asks":[],"checksum":997089143,"timestamp":"2024-06-01T22:43:04.586027Z"}]}
{"channel":"book","type":"update","data":[{"symbol":"ETH/USDT","bids":[{"price":3822.62,"qty":0.00000000},{"price":3821.73,"qty":5.00000000}],"asks":[],"checksum":2706041498,"timestamp":"2024-06-01T22:43:04.586049Z"}]}
{"channel":"book","type":"update","data":[{"symbol":"ETH/USDT","bids":[{"price":3821.89,"qty":0.72912968}],"asks":[],"checksum":2892000499,"timestamp":"2024-06-01T22:43:04.588160Z"}]}
{"channel":"book","type":"update","data":[{"symbol":"ETH/USDT","bids":[{"price":3822.63,"qty":0.00000000},{"price":3821.73,"qty":5.00000000}],"asks":[],"checksum":369300228,"timestamp":"2024-06-01T22:43:04.592249Z"}]}
{"channel":"book","type":"update","data":[{"symbol":"ETH/USDT","bids":[],"asks":[{"price":3823.78,"qty":0.00000000},{"price":3824.15,"qty":5.00000000}],"checksum":2716471318,"timestamp":"2024-06-01T22:43:04.593966Z"}]}
{"channel":"book","type":"update","data":[{"symbol":"ETH/USDT","bids":[],"asks":[{"price":3824.01,"qty":0.00000000},{"price":3824.22,"qty":2.77900000}],"checksum":433739620,"timestamp":"2024-06-01T22:43:04.616427Z"}]}
{"channel":"book","type":"update","data":[{"symbol":"ETH/USDT","bids":[{"price":3821.91,"qty":0.21042607}],"asks":[],"checksum":2460323231,"timestamp":"2024-06-01T22:43:04.617697Z"}]}
{"channel":"book","type":"update","data":[{"symbol":"ETH/USDT","bids":[],"asks":[{"price":3824.21,"qty":0.18726136}],"checksum":3099238700,"timestamp":"2024-06-01T22:43:04.617918Z"}]}
{"channel":"book","type":"update","data":[{"symbol":"ETH/USDT","bids":[],"asks":[{"price":3824.15,"qty":0.00000000},{"price":3824.22,"qty":2.77900000}],"checksum":3334053740,"timestamp":"2024-06-01T22:43:04.622869Z"}]}
{"channel":"book","type":"update","data":[{"symbol":"ETH/USDT","bids":[{"price":3822.64,"qty":0.00000000},{"price":3821.71,"qty":13.73037791}],"asks":[],"checksum":2536104365,"timestamp":"2024-06-01T22:43:04.622990Z"}]}
{"channel":"book","type":"update","data":[{"symbol":"ETH/USDT","bids":[{"price":3821.91,"qty":0.00000000},{"price":3821.66,"qty":0.40940967}],"asks":[],"checksum":1695443252,"timestamp":"2024-06-01T22:43:04.624421Z"}]}
{"channel":"book","type":"update","data":[{"symbol":"ETH/USDT","bids":[],"asks":[{"price":3824.21,"qty":0.00000000},{"price":3824.54,"qty":5.00000000}],"checksum":3277270774,"timestamp":"2024-06-01T22:43:04.624432Z"}]}
{"channel":"book","type":"update","data":[{"symbol":"ETH/USDT","bids":[{"price":3821.90,"qty":5.00000000}],"asks":[],"checksum":2879562561,"timestamp":"2024-06-01T22:43:04.706105Z"}]}
{"channel":"book","type":"update","data":[{"symbol":"ETH/USDT","bids":[{"price":3822.61,"qty":0.84627249}],"asks":[],"checksum":2305933869,"timestamp":"2024-06-01T22:43:04.711258Z"}]}
{"channel":"book","type":"update","data":[{"symbol":"ETH/USDT","bids":[],"asks":[{"price":3824.17,"qty":0.25000000}],"checksum":4109706376,"timestamp":"2024-06-01T22:43:04.711467Z"}]}
{"channel":"book","type":"update","data":[{"symbol":"ETH/USDT","bids":[{"price":3822.03,"qty":0.21959978}],"asks":[],"checksum":2526874731,"timestamp":"2024-06-01T22:43:04.766393Z"}]}
{"channel":"book","type":"update","data":[{"symbol":"ETH/USDT","bids":[{"price":3822.22,"qty":0.00000000},{"price":3821.74,"qty":3.20598358}],"asks":[],"checksum":2234022425,"timestamp":"2024-06-01T22:43:04.770816Z"}]}
{"channel":"book","type":"update","data":[{"symbol":"ETH/USDT","bids":[{"price":3822.23,"qty":5.00000000}],"asks":[],"checksum":300889397,"timestamp":"2024-06-01T22:43:04.770949Z"}]}
{"channel":"book","type":"update","data":[{"symbol":"ETH/USDT","bids":[{"price":3822.62,"qty":0.25000000}],"asks":[],"checksum":2906377306,"timestamp":"2024-06-01T22:43:04.771251Z"}]}
{"channel":"book","type":"update","data":[{"symbol":"ETH/USDT","bids":[],"asks":[{"price":3823.31,"qty":0.00000000},{"price":3824.33,"qty":0.18314166}],"checksum":769918269,"timestamp":"2024-06-01T22:43:04.773651Z"}]}
{"channel":"book","type":"update","data":[{"symbol":"ETH/USDT","bids":[{"price":3822.03,"qty":0.00000000},{"price":3821.75,"qty":0.28767519}],"asks":[],"checksum":3370055879,"timestamp":"2024-06-01T22:43:04.774251Z"}]}
{"channel":"book","type":"update","data":[{"symbol":"ETH/USDT","bids":[],"asks":[{"price":3824.33,"qty":0.00000000},{"price":3824.54,"qty":5.00000000}],"checksum":813436491,"timestamp":"2024-06-01T22:43:04.774453Z"}]}
{"channel":"book","type":"update","data":[{"symbol":"ETH/USDT","bids":[{"price":3822.03,"qty":0.19518066}],"asks":[],"checksum":2315124201,"timestamp":"2024-06-01T22:43:04.916439Z"}]}
{"channel":"book","type":"update","data":[{"symbol":"ETH/USDT","bids":[],"asks":[{"price":3824.33,"qty":0.19540192}],"checksum":2311069000,"timestamp":"2024-06-01T22:43:04.916997Z"}]}
{"channel":"book","type":"update","data":[{"symbol":"ETH/USDT","bids":[{"price":3822.60,"qty":0.00000000},{"price":3821.75,"qty":0.28767519}],"asks":[],"checksum":643357253,"timestamp":"2024-06-01T22:43:05.086117Z"}]}
{"channel":"book","type":"update","data":[{"symbol":"ETH/USDT","bids":[{"price":3821.90,"qty":0.00000000},{"price":3821.74,"qty":3.20598358}],"asks":[],"checksum":602242592,"timestamp":"2024-06-01T22:43:05.090458Z"}]}
{"channel":"book","type":"update","data":[{"symbol":"ETH/USDT","bids":[{"price":3822.23,"qty":0.00000000},{"price":3821.72,"qty":0.00525192}],"asks":[],"checksum":2375665109,"timestamp":"2024-06-01T22:43:05.708008Z"}]}
{"channel":"book","type":"update","data":[{"symbol":"ETH/USDT","bids":[{"price":3821.90,"qty":5.00000000}],"asks":[],"checksum":1640873801,"timestamp":"2024-06-01T22:43:05.713375Z"}]}
{"channel":"book","type":"update","data":[{"symbol":"ETH/USDT","bids":[{"price":3822.65,"qty":2.61818990}],"asks":[],"checksum":1985661612,"timestamp":"2024-06-01T22:43:05.882678Z"}]}
{"channel":"book","type":"update","data":[{"symbol":"ETH/USDT","bids":[{"price":3822.66,"qty":0.25000000}],"asks":[],"checksum":4093207117,"timestamp":"2024-06-01T22:43:05.888822Z"}]}
{"channel":"book","type":"update","data":[{"symbol":"ETH/USDT","bids":[{"price":3822.65,"qty":0.00000000},{"price":3821.75,"qty":0.28767519}],"asks":[],"checksum":503943853,"timestamp":"2024-06-01T22:43:05.893254Z"}]}
{"channel":"book","type":"update","data":[{"symbol":"ETH/USDT","bids":[{"price":3822.66,"qty":0.00000000},{"price":3821.74,"qty":3.20598358}],"asks":[],"checksum":1640873801,"timestamp":"2024-06-01T22:43:06.087632Z"}]}
{"channel":"book","type":"update","data":[{"symbol":"ETH/USDT","bids":[{"price":3821.90,"qty":0.00000000},{"price":3821.72,"qty":0.00525192}],"asks":[],"checksum":2375665109,"timestamp":"2024-06-01T22:43:06.092469Z"}]}
