{"channel":"book","type":"update","data":[{"symbol":"ETH/GBP","bids":[],"asks":[{"price":2997.53,"qty":0.00000000},{"price":2999.45,"qty":1.00000000}],"checksum":3480474351,"timestamp":"2024-06-01T22:43:07.205954Z"}]}
{"channel":"book","type":"update","data":[{"symbol":"ETH/GBP","bids":[],"asks":[{"price":2997.30,"qty":0.00000000},{"price":2999.71,"qty":1.33100000}],"checksum":1938667401,"timestamp":"2024-06-01T22:43:07.258219Z"}]}
{"channel":"book","type":"update","data":[{"symbol":"ETH/GBP","bids":[{"price":2996.29,"qty":6.54597174}],"asks":[],"checksum":2992768101,"timestamp":"2024-06-01T22:43:07.261331Z"}]}
{"channel":"book","type":"update","data":[{"symbol":"ETH/GBP","bids":[{"price":2996.28,"qty":0.00000000},{"price":2993.00,"qty":0.94850883}],"asks":[],"checksum":2435228315,"timestamp":"2024-06-01T22:43:07.263899Z"}]}
{"channel":"book","type":"update","data":[{"symbol":"ETH/GBP","bids":[{"price":2996.37,"qty":0.31000000}],"asks":[],"checksum":2220445553,"timestamp":"2024-06-01T22:43:07.264020Z"}]}
{"channel":"book","type":"update","data":[{"symbol":"ETH/GBP","bids":[{"price":2996.29,"qty":0.00000000},{"price":2993.00,"qty":0.94850883}],"asks":[],"checksum":2394175481,"timestamp":"2024-06-01T22:43:07.267094Z"}]}
{"channel":"book","type":"update","data":[{"symbol":"ETH/GBP","bids":[],"asks":[{"price":2997.20,"qty":6.54400487}],"checksum":1263544337,"timestamp":"2024-06-01T22:43:07.334908Z"}]}
{"channel":"book","type":"update","data":[{"symbol":"ETH/GBP","bids":[{"price":2996.38,"qty":13.09155025}],"asks":[],"checksum":2349072907,"timestamp":"2024-06-01T22:43:07.335054Z"}]}
{"channel":"book","type":"update","data":[{"symbol":"ETH/GBP","bids":[{"price":2996.37,"qty":0.00000000},{"price":2993.00,"qty":0.94850883}],"asks":[],"checksum":3642786371,"timestamp":"2024-06-01T22:43:07.337929Z"}]}
{"channel":"book","type":"update","data":[{"symbol":"ETH/GBP","bids":[{"price":2996.46,"qty":0.31000000}],"asks":[],"checksum":1648760267,"timestamp":"2024-06-01T22:43:07.338188Z"}]}
{"channel":"book","type":"update","data":[{"symbol":"ETH/GBP","bids":[{"price":2996.38,"qty":0.00000000},{"price":2993.00,"qty":0.94850883}],"asks":[],"checksum":3073784135,"timestamp":"2024-06-01T22:43:07.339743Z"}]}
{"channel":"book","type":"update","data":[{"symbol":"ETH/GBP","bids":[{"price":2997.00,"qty":6.54440106}],"asks":[],"checksum":1372865553,"timestamp":"2024-06-01T22:43:07.384603Z"}]}
{"channel":"book","type":"update","data":[{"symbol":"ETH/GBP","bids":[],"asks":[{"price":2997.20,"qty":0.00000000},{"price":2999.71,"qty":1.33100000}],"checksum":4290824772,"timestamp":"2024-06-01T22:43:07.384659Z"}]}
{"channel":"book","type":"update","data":[{"symbol":"ETH/GBP","bids":[{"price":2997.00,"qty":0.00000000},{"price":2993.00,"qty":0.94850883}],"asks":[],"checksum":1926375087,"timestamp":"2024-06-01T22:43:07.389314Z"}]}
{"channel":"book","type":"update","data":[{"symbol":"ETH/GBP","bids":[],"asks":[{"price":2997.59,"qty":13.08629270}],"checksum":3771614987,"timestamp":"2024-06-01T22:43:07.393856Z"}]}
{"channel":"book","type":"update","data":[{"symbol":"ETH/GBP","bids":[],"asks":[{"price":2997.59,"qty":0.00000000},{"price":2999.71,"qty":1.33100000}],"checksum":1926375087,"timestamp":"2024-06-01T22:43:07.460334Z"}]}
{"channel":"book","type":"update","data":[{"symbol":"ETH/GBP","bids":[],"asks":[{"price":2997.18,"qty":6.54402851}],"checksum":4136015383,"timestamp":"2024-06-01T22:43:07.464477Z"}]}
{"channel":"book","type":"update","data":[{"symbol":"ETH/GBP","bids":[{"price":2996.98,"qty":6.54444425}],"asks":[],"checksum":980487912,"timestamp":"2024-06-01T22:43:07.494265Z"}]}
{"channel":"book","type":"update","data":[{"symbol":"ETH/GBP","bids":[{"price":2996.98,"qty":0.00000000},{"price":2993.00,"qty":0.94850883}],"asks":[],"checksum":4136015383,"timestamp":"2024-06-01T22:43:07.514840Z"}]}
{"channel":"book","type":"update","data":[{"symbol":"ETH/GBP","bids":[],"asks":[{"price":2997.18,"qty":0.00000000},{"price":2999.71,"qty":1.33100000}],"checksum":1926375087,"timestamp":"2024-06-01T22:43:07.515045Z"}]}
{"channel":"book","type":"update","data":[{"symbol":"ETH/GBP","bids":[{"price":2996.47,"qty":13.09115704}],"asks":[],"checksum":278598158,"timestamp":"2024-06-01T22:43:07.562474Z"}]}
{"channel":"book","type":"update","data":[{"symbol":"ETH/GBP","bids":[{"price":2995.80,"qty":0.00000000},{"price":2993.00,"qty":0.94850883}],"asks":[],"checksum":3051242102,"timestamp":"2024-06-01T22:43:07.564639Z"}]}
{"channel":"book","type":"update","data":[{"symbol":"ETH/GBP","bids":[{"price":2993.55,"qty":0.27305540},{"price":2993.92,"qty":1.33100000}],"asks":[],"checksum":463454408,"timestamp":"2024-06-01T22:43:07.565273Z"}]}
{"channel":"book","type":"update","data":[{"symbol":"ETH/GBP","bids":[{"price":2996.46,"qty":0.00000000},{"price":2993.00,"qty":0.94850883}],"asks":[],"checksum":521720770,"timestamp":"2024-06-01T22:43:07.565428Z"}]}
{"channel":"book","type":"update","data":[{"symbol":"ETH/GBP","bids":[{"price":2996.54,"qty":0.31000000}],"asks":[],"checksum":2522227543,"timestamp":"2024-06-01T22:43:07.565584Z"}]}
{"channel":"book","type":"update","data":[{"symbol":"ETH/GBP","bids":[{"price":2996.47,"qty":0.00000000},{"price":2993.00,"qty":0.94850883}],"asks":[],"checksum":561363755,"timestamp":"2024-06-01T22:43:07.567148Z"}]}
{"channel":"book","type":"update","data":[{"symbol":"ETH/GBP","bids":[],"asks":[{"price":2998.17,"qty":0.00000000},{"price":2999.72,"qty":0.34280000}],"checksum":1492194004,"timestamp":"2024-06-01T22:43:07.571964Z"}]}
{"channel":"book","type":"update","data":[{"symbol":"ETH/GBP","bids":[],"asks":[{"price":2997.27,"qty":6.54383480}],"checksum":404628595,"timestamp":"2024-06-01T22:43:07.576020Z"}]}
{"channel":"book","type":"update","data":[{"symbol":"ETH/GBP","bids":[{"price":2996.00,"qty":1.30931746}],"asks":[],"checksum":266536801,"timestamp":"2024-06-01T22:43:07.576122Z"}]}
{"channel":"book","type":"update","data":[{"symbol":"ETH/GBP","bids":[],"asks":[{"price":2997.27,"qty":0.00000000},{"price":2999.72,"qty":0.34280000}],"checksum":1192353308,"timestamp":"2024-06-01T22:43:07.613740Z"}]}
{"channel":"book","type":"update","data":[{"symbol":"ETH/GBP","bids":[{"price":2997.04,"qty":6.54433363}],"asks":[],"checksum":1180566109,"timestamp":"2024-06-01T22:43:07.617337Z"}]}
{"channel":"book","type":"update","data":[{"symbol":"ETH/GBP","bids":[],"asks":[{"price":2997.65,"qty":13.08600783}],"checksum":4065607896,"timestamp":"2024-06-01T22:43:07.617439Z"}]}
{"channel":"book","type":"update","data":[{"symbol":"ETH/GBP","bids":[],"asks":[{"price":2997.26,"qty":6.54387210}],"checksum":1371446975,"timestamp":"2024-06-01T22:43:07.687775Z"}]}
{"channel":"book","type":"update","data":[{"symbol":"ETH/GBP","bids":[],"asks":[{"price":2997.26,"qty":0.00000000},{"price":2999.71,"qty":1.33100000}],"checksum":4065607896,"timestamp":"2024-06-01T22:43:07.697184Z"}]}
{"channel":"book","type":"update","data":[{"symbol":"ETH/GBP","bids":[],"asks":[{"price":2999.09,"qty":0.00000000},{"price":2999.72,"qty":0.34280000}],"checksum":2897480264,"timestamp":"2024-06-01T22:43:07.750644Z"}]}
{"channel":"book","type":"update","data":[{"symbol":"ETH/GBP","bids":[{"price":2996.68,"qty":13.09021284}],"asks":[],"checksum":2395086294,"timestamp":"2024-06-01T22:43:07.815666Z"}]}
{"channel":"book","type":"update","data":[{"symbol":"ETH/GBP","bids":[],"asks":[{"price":2997.26,"qty":6.54385705}],"checksum":3227140846,"timestamp":"2024-06-01T22:43:07.815786Z"}]}
{"channel":"book","type":"update","data":[{"symbol":"ETH/GBP","bids":[],"asks":[{"price":2997.26,"qty":0.00000000},{"price":2999.72,"qty":0.34280000}],"checksum":2395086294,"timestamp":"2024-06-01T22:43:07.837687Z"}]}
{"channel":"book","type":"update","data":[{"symbol":"ETH/GBP","bids":[{"price":2997.04,"qty":0.00000000},{"price":2993.78,"qty":0.27600000}],"asks":[],"checksum":1881869256,"timestamp":"2024-06-01T22:43:07.885369Z"}]}
{"channel":"book","type":"update","data":[{"symbol":"ETH/GBP","bids":[],"asks":[{"price":2997.60,"qty":13.08625826}],"checksum":3795421750,"timestamp":"2024-06-01T22:43:07.889927Z"}]}
{"channel":"book","type":"update","data":[{"symbol":"ETH/GBP","bids":[{"price":2997.01,"qty":6.54438359}],"asks":[],"checksum":1347892977,"timestamp":"2024-06-01T22:43:07.889952Z"}]}
{"channel":"book","type":"update","data":[{"symbol":"ETH/GBP","bids":[{"price":2997.01,"qty":0.00000000},{"price":2993.78,"qty":0.27600000}],"asks":[],"checksum":3795421750,"timestamp":"2024-06-01T22:43:07.894401Z"}]}
{"channel":"book","type":"update","data":[{"symbol":"ETH/GBP","bids":[],"asks":[{"price":2997.24,"qty":6.54389697}],"checksum":3176694581,"timestamp":"2024-06-01T22:43:07.933537Z"}]}
{"channel":"book","type":"update","data":[{"symbol":"ETH/GBP","bids":[],"asks":[{"price":2997.24,"qty":0.00000000},{"price":2999.72,"qty":0.34280000}],"checksum":3795421750,"timestamp":"2024-06-01T22:43:07.938114Z"}]}
{"channel":"book","type":"update","data":[{"symbol":"ETH/GBP","bids":[],"asks":[{"price":2999.48,"qty":0.27301350}],"checksum":497150138,"timestamp":"2024-06-01T22:43:08.001802Z"}]}
{"channel":"book","type":"update","data":[{"symbol":"ETH/GBP","bids":[{"price":2997.01,"qty":6.54438988}],"asks":[],"checksum":1334415971,"timestamp":"2024-06-01T22:43:08.028939Z"}]}
{"channel":"book","type":"update","data":[{"symbol":"ETH/GBP","bids":[],"asks":[{"price":2997.20,"qty":6.54400131}],"checksum":1246423174,"timestamp":"2024-06-01T22:43:08.034830Z"}]}
{"channel":"book","type":"update","data":[{"symbol":"ETH/GBP","bids":[],"asks":[{"price":2997.20,"qty":0.00000000},{"price":2999.71,"qty":1.33100000}],"checksum":1334415971,"timestamp":"2024-06-01T22:43:08.063899Z"}]}
{"channel":"book","type":"update","data":[{"symbol":"ETH/GBP","bids":[{"price":2997.01,"qty":0.00000000},{"price":2993.78,"qty":0.27600000}],"asks":[],"checksum":497150138,"timestamp":"2024-06-01T22:43:08.063974Z"}]}
{"channel":"book","type":"update","data":[{"symbol":"ETH/GBP","bids":[{"price":2997.01,"qty":6.54437805}],"asks":[],"checksum":2262155382,"timestamp":"2024-06-01T22:43:08.144505Z"}]}
{"channel":"book","type":"update","data":[{"symbol":"ETH/GBP","bids":[],"asks":[{"price":2998.38,"qty":1.30828411}],"checksum":3930940678,"timestamp":"2024-06-01T22:43:08.144614Z"}]}
{"channel":"book","type":"update","data":[{"symbol":"ETH/GBP","bids":[],"asks":[{"price":2997.20,"qty":6.54399004}],"checksum":395590844,"timestamp":"2024-06-01T22:43:08.144638Z"}]}
{"channel":"book","type":"update","data":[{"symbol":"ETH/GBP","bids":[{"price":2997.01,"qty":0.00000000},{"price":2993.78,"qty":0.27600000}],"asks":[],"checksum":942781940,"timestamp":"2024-06-01T22:43:08.168780Z"}]}
{"channel":"book","type":"update","data":[{"symbol":"ETH/GBP","bids":[],"asks":[{"price":2997.20,"qty":0.00000000},{"price":2999.48,"qty":0.27301350}],"checksum":2207348206,"timestamp":"2024-06-01T22:43:08.168926Z"}]}
{"channel":"book","type":"update","data":[{"symbol":"ETH/GBP","bids":[],"asks":[{"price":2997.21,"qty":6.54397172}],"checksum":2285052190,"timestamp":"2024-06-01T22:43:08.249689Z"}]}
{"channel":"book","type":"update","data":[{"symbol":"ETH/GBP","bids":[{"price":2997.01,"qty":6.54437805}],"asks":[],"checksum":1476080974,"timestamp":"2024-06-01T22:43:08.249913Z"}]}
{"channel":"book","type":"update","data":[{"symbol":"ETH/GBP","bids":[],"asks":[{"price":2997.21,"qty":0.00000000},{"price":2999.48,"qty":0.27301350}],"checksum":3930940678,"timestamp":"2024-06-01T22:43:08.487675Z"}]}
{"channel":"book","type":"update","data":[{"symbol":"ETH/GBP","bids":[],"asks":[{"price":2997.20,"qty":6.54400378}],"checksum":230816457,"timestamp":"2024-06-01T22:43:08.491839Z"}]}
{"channel":"book","type":"update","data":[{"symbol":"ETH/GBP","bids":[],"asks":[{"price":2997.38,"qty":0.00000000},{"price":2999.48,"qty":0.27301350}],"checksum":680547782,"timestamp":"2024-06-01T22:43:08.859043Z"}]}
{"channel":"book","type":"update","data":[{"symbol":"ETH/GBP","bids":[],"asks":[{"price":2999.16,"qty":0.00000000},{"price":2999.71,"qty":1.33100000}],"checksum":2391466377,"timestamp":"2024-06-01T22:43:08.859071Z"}]}
{"channel":"book","type":"update","data":[{"symbol":"ETH/GBP","bids":[],"asks":[{"price":2997.20,"qty":12.05717033}],"checksum":1797348792,"timestamp":"2024-06-01T22:43:08.864789Z"}]}
{"channel":"book","type":"update","data":[{"symbol":"ETH/GBP","bids":[],"asks":[{"price":2999.16,"qty":24.82633271}],"checksum":2147493436,"timestamp":"2024-06-01T22:43:08.865118Z"}]}
{"channel":"book","type":"update","data":[{"symbol":"ETH/GBP","bids":[{"price":2997.01,"qty":0.00000000},{"price":2993.78,"qty":0.27600000}],"asks":[],"checksum":2129837567,"timestamp":"2024-06-01T22:43:08.935685Z"}]}
{"channel":"book","type":"update","data":[{"symbol":"ETH/GBP","bids":[{"price":2997.02,"qty":6.54437057}],"asks":[],"checksum":2921270572,"timestamp":"2024-06-01T22:43:08.940333Z"}]}
{"channel":"book","type":"update","data":[{"symbol":"ETH/GBP","bids":[{"price":2997.02,"qty":0.00000000},{"price":2993.78,"qty":0.27600000}],"asks":[],"checksum":2129837567,"timestamp":"2024-06-01T22:43:08.985196Z"}]}
{"channel":"book","type":"update","data":[{"symbol":"ETH/GBP","bids":[],"asks":[{"price":2997.20,"qty":5.51316655}],"checksum":3411264912,"timestamp":"2024-06-01T22:43:08.985213Z"}]}
{"channel":"book","type":"update","data":[{"symbol":"ETH/GBP","bids":[],"asks":[{"price":2997.24,"qty":6.54391140}],"checksum":1951641727,"timestamp":"2024-06-01T22:43:08.989471Z"}]}
{"channel":"book","type":"update","data":[{"symbol":"ETH/GBP","bids":[{"price":2996.23,"qty":0.00000000},{"price":2993.55,"qty":0.27305540},{"price":2996.53,"qty":0.08527500}],"asks":[],"checksum":4271824931,"timestamp":"2024-06-01T22:43:09.017354Z"}]}
{"channel":"book","type":"update","data":[{"symbol":"ETH/GBP","bids":[],"asks":[{"price":2997.24,"qty":0.00000000},{"price":2999.48,"qty":0.27301350}],"checksum":1100912076,"timestamp":"2024-06-01T22:43:09.175033Z"}]}
{"channel":"book","type":"update","data":[{"symbol":"ETH/GBP","bids":[{"price":2996.69,"qty":6.54509798}],"asks":[],"checksum":3738664337,"timestamp":"2024-06-01T22:43:09.178902Z"}]}
{"channel":"book","type":"update","data":[{"symbol":"ETH/GBP","bids":[],"asks":[{"price":2997.22,"qty":6.54396203}],"checksum":2387840421,"timestamp":"2024-06-01T22:43:09.178939Z"}]}
{"channel":"book","type":"update","data":[{"symbol":"ETH/GBP","bids":[{"price":2996.69,"qty":0.00000000},{"price":2993.78,"qty":0.27600000}],"asks":[],"checksum":3223297468,"timestamp":"2024-06-01T22:43:09.185237Z"}]}
{"channel":"book","type":"update","data":[{"symbol":"ETH/GBP","bids":[{"price":2997.03,"qty":6.54435304}],"asks":[],"checksum":3951697953,"timestamp":"2024-06-01T22:43:09.300755Z"}]}
{"channel":"book","type":"update","data":[{"symbol":"ETH/GBP","bids":[],"asks":[{"price":2997.05,"qty":0.08252921}],"checksum":2896070163,"timestamp":"2024-06-01T22:43:09.553538Z"}]}
{"channel":"book","type":"update","data":[{"symbol":"ETH/GBP","bids":[],"asks":[{"price":2997.22,"qty":0.00000000},{"price":2999.48,"qty":0.27301350}],"checksum":493329915,"timestamp":"2024-06-01T22:43:09.580785Z"}]}
{"channel":"book","type":"update","data":[{"symbol":"ETH/GBP","bids":[],"asks":[{"price":2997.21,"qty":6.54397197}],"checksum":1065036567,"timestamp":"2024-06-01T22:43:09.584597Z"}]}
{"channel":"book","type":"update","data":[{"symbol":"ETH/GBP","bids":[],"asks":[{"price":2997.21,"qty":0.00000000},{"price":2999.48,"qty":0.27301350}],"checksum":493329915,"timestamp":"2024-06-01T22:43:10.301213Z"}]}
{"channel":"book","type":"update","data":[{"symbol":"ETH/GBP","bids":[{"price":2997.03,"qty":0.00000000},{"price":2993.78,"qty":0.27600000}],"asks":[],"checksum":2491685993,"timestamp":"2024-06-01T22:43:10.301329Z"}]}
{"channel":"book","type":"update","data":[{"symbol":"ETH/GBP","bids":[],"asks":[{"price":2997.20,"qty":12.05716078}],"checksum":2993987895,"timestamp":"2024-06-01T22:43:10.305947Z"}]}
{"channel":"book","type":"update","data":[{"symbol":"ETH/GBP","bids":[{"price":2997.01,"qty":6.54438227}],"asks":[],"checksum":220864943,"timestamp":"2024-06-01T22:43:10.305966Z"}]}
{"channel":"book","type":"update","data":[{"symbol":"ETH/GBP","bids":[{"price":2996.69,"qty":0.14401886}],"asks":[],"checksum":697955764,"timestamp":"2024-06-01T22:43:10.306272Z"}]}
{"channel":"book","type":"update","data":[{"symbol":"ETH/GBP","bids":[{"price":2996.69,"qty":0.00000000},{"price":2993.91,"qty":1.31023505}],"asks":[],"checksum":220864943,"timestamp":"2024-06-01T22:43:10.310633Z"}]}
{"channel":"book","type":"update","data":[{"symbol":"ETH/GBP","bids":[{"price":2997.01,"qty":0.00000000},{"price":2993.78,"qty":0.27600000}],"asks":[],"checksum":2993987895,"timestamp":"2024-06-01T22:43:10.425607Z"}]}
{"channel":"book","type":"update","data":[{"symbol":"ETH/GBP","bids":[{"price":2997.02,"qty":6.54437245}],"asks":[],"checksum":3859511718,"timestamp":"2024-06-01T22:43:10.429923Z"}]}
{"channel":"book","type":"update","data":[{"symbol":"ETH/GBP","bids":[{"price":2996.69,"qty":0.14401886}],"asks":[],"checksum":116900721,"timestamp":"2024-06-01T22:43:10.430388Z"}]}
{"channel":"book","type":"update","data":[{"symbol":"ETH/GBP","bids":[{"price":2996.69,"qty":0.00000000},{"price":2993.91,"qty":1.31023505}],"asks":[],"checksum":3859511718,"timestamp":"2024-06-01T22:43:10.434462Z"}]}
{"channel":"book","type":"update","data":[{"symbol":"ETH/GBP","bids":[],"asks":[{"price":2999.16,"qty":0.00000000},{"price":2999.71,"qty":1.33100000}],"checksum":3158659751,"timestamp":"2024-06-01T22:43:11.077911Z"}]}
{"channel":"book","type":"update","data":[{"symbol":"ETH/GBP","bids":[],"asks":[{"price":2997.20,"qty":6.54399423}],"checksum":2644870718,"timestamp":"2024-06-01T22:43:11.078101Z"}]}
{"channel":"book","type":"update","data":[{"symbol":"ETH/GBP","bids":[],"asks":[{"price":2999.16,"qty":27.37596603}],"checksum":1626566511,"timestamp":"2024-06-01T22:43:11.083103Z"}]}
{"channel":"book","type":"update","data":[{"symbol":"ETH/GBP","bids":[],"asks":[{"price":2997.19,"qty":3.01832810}],"checksum":185075935,"timestamp":"2024-06-01T22:43:11.083160Z"}]}
{"channel":"book","type":"update","data":[{"symbol":"ETH/GBP","bids":[],"asks":[{"price":2999.17,"qty":0.00000000},{"price":2999.48,"qty":0.27301350}],"checksum":1240185020,"timestamp":"2024-06-01T22:43:11.141894Z"}]}
{"channel":"book","type":"update","data":[{"symbol":"ETH/GBP","bids":[],"asks":[{"price":2997.20,"qty":0.00000000},{"price":2999.71,"qty":1.33100000}],"checksum":808578050,"timestamp":"2024-06-01T22:43:11.144334Z"}]}
{"channel":"book","type":"update","data":[{"symbol":"ETH/GBP","bids":[{"price":2997.02,"qty":0.00000000},{"price":2993.78,"qty":0.27600000}],"asks":[],"checksum":1581444503,"timestamp":"2024-06-01T22:43:11.144396Z"}]}
{"channel":"book","type":"update","data":[{"symbol":"ETH/GBP","bids":[],"asks":[{"price":2999.18,"qty":9.62013200}],"checksum":2347379331,"timestamp":"2024-06-01T22:43:11.146402Z"}]}
{"channel":"book","type":"update","data":[{"symbol":"ETH/GBP","bids":[],"asks":[{"price":2997.22,"qty":6.54396078}],"checksum":3175446038,"timestamp":"2024-06-01T22:43:11.149565Z"}]}
{"channel":"book","type":"update","data":[{"symbol":"ETH/GBP","bids":[{"price":2997.03,"qty":6.54434297}],"asks":[],"checksum":3213057445,"timestamp":"2024-06-01T22:43:11.149685Z"}]}
{"channel":"book","type":"update","data":[{"symbol":"ETH/GBP","bids":[],"asks":[{"price":2997.22,"qty":0.00000000},{"price":2999.48,"qty":0.27301350}],"checksum":1070634290,"timestamp":"2024-06-01T22:43:11.161892Z"}]}
{"channel":"book","type":"update","data":[{"symbol":"ETH/GBP","bids":[{"price":2997.03,"qty":0.00000000},{"price":2993.78,"qty":0.27600000}],"asks":[],"checksum":2347379331,"timestamp":"2024-06-01T22:43:11.248901Z"}]}
{"channel":"book","type":"update","data":[{"symbol":"ETH/GBP","bids":[{"price":2996.69,"qty":6.54509798}],"asks":[],"checksum":947803439,"timestamp":"2024-06-01T22:43:11.255676Z"}]}
{"channel":"book","type":"update","data":[{"symbol":"ETH/GBP","bids":[],"asks":[{"price":2997.21,"qty":6.54396732}],"checksum":1596026356,"timestamp":"2024-06-01T22:43:11.255723Z"}]}
{"channel":"book","type":"update","data":[{"symbol":"ETH/GBP","bids":[],"asks":[{"price":2997.21,"qty":0.00000000},{"price":2999.48,"qty":0.27301350}],"checksum":947803439,"timestamp":"2024-06-01T22:43:11.262830Z"}]}
{"channel":"book","type":"update","data":[{"symbol":"ETH/GBP","bids":[{"price":2996.69,"qty":0.00000000},{"price":2993.78,"qty":0.27600000}],"asks":[],"checksum":2347379331,"timestamp":"2024-06-01T22:43:11.262884Z"}]}
{"channel":"book","type":"update","data":[{"symbol":"ETH/GBP","bids":[{"price":2996.68,"qty":0.00000000},{"price":2993.55,"qty":0.27305540}],"asks":[],"checksum":1701448597,"timestamp":"2024-06-01T22:43:11.267896Z"}]}
{"channel":"book","type":"update","data":[{"symbol":"ETH/GBP","bids":[{"price":2996.55,"qty":13.09080754}],"asks":[],"checksum":2984524987,"timestamp":"2024-06-01T22:43:11.277104Z"}]}
{"channel":"book","type":"update","data":[{"symbol":"ETH/GBP","bids":[{"price":2995.00,"qty":0.00000000},{"price":2993.55,"qty":0.27305540}],"asks":[],"checksum":1514151724,"timestamp":"2024-06-01T22:43:11.277117Z"}]}
{"channel":"book","type":"update","data":[{"symbol":"ETH/GBP","bids":[],"asks":[{"price":2997.60,"qty":0.00000000},{"price":2999.71,"qty":1.33100000}],"checksum":1260373478,"timestamp":"2024-06-01T22:43:11.277207Z"}]}
{"channel":"book","type":"update","data":[{"symbol":"ETH/GBP","bids":[{"price":2996.54,"qty":0.00000000},{"price":2993.02,"qty":0.12934594}],"asks":[],"checksum":571092707,"timestamp":"2024-06-01T22:43:11.280302Z"}]}
{"channel":"book","type":"update","data":[{"symbol":"ETH/GBP","bids":[{"price":2996.57,"qty":0.31000000}],"asks":[],"checksum":896367070,"timestamp":"2024-06-01T22:43:11.280417Z"}]}
{"channel":"book","type":"update","data":[{"symbol":"ETH/GBP","bids":[],"asks":[{"price":2999.71,"qty":0.00000000},{"price":2999.72,"qty":0.34280000}],"checksum":3970531218,"timestamp":"2024-06-01T22:43:11.283399Z"}]}
{"channel":"book","type":"update","data":[{"symbol":"ETH/GBP","bids":[],"asks":[{"price":2998.71,"qty":0.00000000},{"price":2999.73,"qty":1.30769587}],"checksum":2278580357,"timestamp":"2024-06-01T22:43:11.283906Z"}]}
{"channel":"book","type":"update","data":[{"symbol":"ETH/GBP","bids":[],"asks":[{"price":2999.72,"qty":0.00000000},{"price":2999.74,"qty":0.28700000}],"checksum":1522845061,"timestamp":"2024-06-01T22:43:11.284307Z"}]}
{"channel":"book","type":"update","data":[{"symbol":"ETH/GBP","bids":[],"asks":[{"price":2999.18,"qty":0.00000000},{"price":2999.79,"qty":0.94850883}],"checksum":4045012617,"timestamp":"2024-06-01T22:43:11.287719Z"}]}
{"channel":"book","type":"update","data":[{"symbol":"ETH/GBP","bids":[{"price":2996.55,"qty":0.00000000},{"price":2993.02,"qty":0.12934594}],"asks":[],"checksum":961592642,"timestamp":"2024-06-01T22:43:11.288947Z"}]}
