{"channel":"book","type":"snapshot","data":[{"symbol":"ETH/CHF","bids":[{"price":3448.82,"qty":0.85088790},{"price":3448.81,"qty":0.02566777},{"price":3448.71,"qty":3.20066186},{"price":3448.69,"qty":0.06634600},{"price":3447.50,"qty":2.00000000},{"price":3446.19,"qty":0.09600000},{"price":3444.88,"qty":0.01017607},{"price":3444.87,"qty":2.99807228},{"price":3444.86,"qty":6.65316677},{"price":3444.67,"qty":0.89000000}],"asks":[{"price":3450.84,"qty":0.01016236},{"price":3450.85,"qty":2.00000000},{"price":3450.86,"qty":1.52150747},{"price":3451.38,"qty":0.06630200},{"price":3451.54,"qty":0.08050309},{"price":3451.55,"qty":20.48210052},{"price":3451.56,"qty":13.90935277},{"price":3451.99,"qty":3.19800000},{"price":3452.95,"qty":6.03120000},{"price":3452.96,"qty":1.07000000}],"checksum":3695912358}]}
{"channel":"book","type":"update","data":[{"symbol":"ETH/CHF","bids":[{"price":3448.82,"qty":0.00000000},{"price":3444.14,"qty":0.96000000},{"price":3448.83,"qty":0.85088544}],"asks":[],"checksum":1897685655,"timestamp":"2024-06-01T22:42:37.943765Z"}]}
{"channel":"book","type":"update","data":[{"symbol":"ETH/CHF","bids":[{"price":3448.83,"qty":0.00000000},{"price":3444.14,"qty":0.96000000},{"price":3448.82,"qty":0.85088792}],"asks":[],"checksum":4276850493,"timestamp":"2024-06-01T22:42:37.947402Z"}]}
{"channel":"book","type":"update","data":[{"symbol":"ETH/CHF","bids":[{"price":3444.86,"qty":0.00000000},{"price":3444.14,"qty":0.96000000}],"asks":[],"checksum":2290757533,"timestamp":"2024-06-01T22:42:37.977004Z"}]}
{"channel":"book","type":"update","data":[{"symbol":"ETH/CHF","bids":[{"price":3444.88,"qty":6.15254407}],"asks":[],"checksum":3573328079,"timestamp":"2024-06-01T22:42:37.978643Z"}]}
{"channel":"book","type":"update","data":[{"symbol":"ETH/CHF","bids":[{"price":3444.87,"qty":0.00000000},{"price":3442.91,"qty":1.66000000}],"asks":[],"checksum":1206094343,"timestamp":"2024-06-01T22:42:37.991933Z"}]}
{"channel":"book","type":"update","data":[{"symbol":"ETH/CHF","bids":[{"price":3444.89,"qty":2.99805486}],"asks":[],"checksum":725896738,"timestamp":"2024-06-01T22:42:37.992253Z"}]}
{"channel":"book","type":"update","data":[{"symbol":"ETH/CHF","bids":[],"asks":[{"price":3450.86,"qty":0.00000000},{"price":3453.24,"qty":2.58000000}],"checksum":1196972793,"timestamp":"2024-06-01T22:42:39.378075Z"}]}
{"channel":"book","type":"update","data":[{"symbol":"ETH/CHF","bids":[],"asks":[{"price":3450.84,"qty":1.53166983}],"checksum":1205273813,"timestamp":"2024-06-01T22:42:39.382727Z"}]}
{"channel":"book","type":"update","data":[{"symbol":"ETH/CHF","bids":[],"asks":[{"price":3450.85,"qty":0.00000000},{"price":3453.27,"qty":2.53000000}],"checksum":828582591,"timestamp":"2024-06-01T22:42:39.384482Z"}]}
{"channel":"book","type":"update","data":[{"symbol":"ETH/CHF","bids":[],"asks":[{"price":3451.54,"qty":2.08050309}],"checksum":4233942401,"timestamp":"2024-06-01T22:42:39.384611Z"}]}
{"channel":"book","type":"update","data":[{"symbol":"ETH/CHF","bids":[],"asks":[{"price":3450.84,"qty":1.52150747},{"price":3450.83,"qty":0.01016260}],"checksum":3940761468,"timestamp":"2024-06-01T22:42:39.395872Z"}]}
{"channel":"book","type":"update","data":[{"symbol":"ETH/CHF","bids":[],"asks":[{"price":3450.83,"qty":2.01016260}],"checksum":2137805536,"timestamp":"2024-06-01T22:42:39.644010Z"}]}
{"channel":"book","type":"update","data":[{"symbol":"ETH/CHF","bids":[{"price":3448.71,"qty":0.00000000},{"price":3442.91,"qty":1.66000000}],"asks":[],"checksum":3402583850,"timestamp":"2024-06-01T22:42:39.647567Z"}]}
{"channel":"book","type":"update","data":[{"symbol":"ETH/CHF","bids":[],"asks":[{"price":3451.54,"qty":0.08050309}],"checksum":4193257137,"timestamp":"2024-06-01T22:42:39.649244Z"}]}
{"channel":"book","type":"update","data":[{"symbol":"ETH/CHF","bids":[{"price":3448.83,"qty":3.20055050}],"asks":[],"checksum":1676907145,"timestamp":"2024-06-01T22:42:39.651015Z"}]}
{"channel":"book","type":"update","data":[{"symbol":"ETH/CHF","bids":[],"asks":[{"price":3450.83,"qty":2.00000000},{"price":3450.82,"qty":0.01016260}],"checksum":3078927197,"timestamp":"2024-06-01T22:42:39.695088Z"}]}
{"channel":"book","type":"update","data":[{"symbol":"ETH/CHF","bids":[{"price":3448.82,"qty":0.00000000},{"price":3442.91,"qty":1.66000000},{"price":3447.51,"qty":0.85119883}],"asks":[],"checksum":536459220,"timestamp":"2024-06-01T22:42:39.695160Z"}]}
{"channel":"book","type":"update","data":[{"symbol":"ETH/CHF","bids":[{"price":3444.88,"qty":6.14236800}],"asks":[],"checksum":3763020626,"timestamp":"2024-06-01T22:42:40.015338Z"}]}
{"channel":"book","type":"update","data":[{"symbol":"ETH/CHF","bids":[{"price":3448.81,"qty":0.00000000},{"price":3442.91,"qty":1.66000000}],"asks":[],"checksum":3959845879,"timestamp":"2024-06-01T22:42:40.015489Z"}]}
{"channel":"book","type":"update","data":[{"symbol":"ETH/CHF","bids":[{"price":3448.84,"qty":0.02055978}],"asks":[],"checksum":388278020,"timestamp":"2024-06-01T22:42:40.016614Z"}]}
{"channel":"book","type":"update","data":[{"symbol":"ETH/CHF","bids":[{"price":3447.52,"qty":0.01529902}],"asks":[],"checksum":926070711,"timestamp":"2024-06-01T22:42:40.016627Z"}]}
{"channel":"book","type":"update","data":[{"symbol":"ETH/CHF","bids":[{"price":3447.51,"qty":0.00000000},{"price":3444.14,"qty":0.96000000},{"price":3448.84,"qty":0.87143035}],"asks":[],"checksum":3810611003,"timestamp":"2024-06-01T22:42:40.048804Z"}]}
{"channel":"book","type":"update","data":[{"symbol":"ETH/CHF","bids":[{"price":3444.88,"qty":0.00000000},{"price":3442.91,"qty":1.66000000}],"asks":[],"checksum":3807536397,"timestamp":"2024-06-01T22:42:40.062144Z"}]}
{"channel":"book","type":"update","data":[{"symbol":"ETH/CHF","bids":[{"price":3447.52,"qty":2.07127685}],"asks":[],"checksum":67387399,"timestamp":"2024-06-01T22:42:40.063099Z"}]}
{"channel":"book","type":"update","data":[{"symbol":"ETH/CHF","bids":[{"price":3444.90,"qty":4.07441832}],"asks":[],"checksum":2903536673,"timestamp":"2024-06-01T22:42:40.063210Z"}]}
{"channel":"book","type":"update","data":[{"symbol":"ETH/CHF","bids":[{"price":3444.89,"qty":0.00000000},{"price":3442.91,"qty":1.66000000}],"asks":[],"checksum":1931550312,"timestamp":"2024-06-01T22:42:40.073196Z"}]}
{"channel":"book","type":"update","data":[{"symbol":"ETH/CHF","bids":[{"price":3444.91,"qty":2.99803746}],"asks":[],"checksum":3413410967,"timestamp":"2024-06-01T22:42:40.073349Z"}]}
{"channel":"book","type":"update","data":[{"symbol":"ETH/CHF","bids":[{"price":3448.84,"qty":0.02055978},{"price":3448.85,"qty":0.85086805}],"asks":[],"checksum":108691376,"timestamp":"2024-06-01T22:42:40.325409Z"}]}
{"channel":"book","type":"update","data":[{"symbol":"ETH/CHF","bids":[],"asks":[{"price":3451.54,"qty":0.00000000},{"price":3453.24,"qty":2.58000000}],"checksum":3314977178,"timestamp":"2024-06-01T22:42:40.392300Z"}]}
{"channel":"book","type":"update","data":[{"symbol":"ETH/CHF","bids":[],"asks":[{"price":3451.54,"qty":0.08319121}],"checksum":2976803598,"timestamp":"2024-06-01T22:42:40.394187Z"}]}
{"channel":"book","type":"update","data":[{"symbol":"ETH/CHF","bids":[],"asks":[{"price":3451.55,"qty":0.00000000},{"price":3453.24,"qty":2.58000000}],"checksum":4098930843,"timestamp":"2024-06-01T22:42:41.640392Z"}]}
{"channel":"book","type":"update","data":[{"symbol":"ETH/CHF","bids":[],"asks":[{"price":3450.84,"qty":0.00000000},{"price":3453.27,"qty":2.53000000}],"checksum":2805550643,"timestamp":"2024-06-01T22:42:41.640638Z"}]}
{"channel":"book","type":"update","data":[{"symbol":"ETH/CHF","bids":[],"asks":[{"price":3450.82,"qty":1.03270710}],"checksum":1880809546,"timestamp":"2024-06-01T22:42:41.645134Z"}]}
{"channel":"book","type":"update","data":[{"symbol":"ETH/CHF","bids":[],"asks":[{"price":3451.55,"qty":28.34439892}],"checksum":19949107,"timestamp":"2024-06-01T22:42:41.645264Z"}]}
{"channel":"book","type":"update","data":[{"symbol":"ETH/CHF","bids":[],"asks":[{"price":3451.53,"qty":3.01839640}],"checksum":3773781463,"timestamp":"2024-06-01T22:42:41.645280Z"}]}
{"channel":"book","type":"update","data":[{"symbol":"ETH/CHF","bids":[],"asks":[{"price":3450.83,"qty":0.00000000},{"price":3453.24,"qty":2.58000000}],"checksum":625419006,"timestamp":"2024-06-01T22:42:41.646393Z"}]}
{"channel":"book","type":"update","data":[{"symbol":"ETH/CHF","bids":[],"asks":[{"price":3451.55,"qty":30.34439892}],"checksum":438755498,"timestamp":"2024-06-01T22:42:41.646418Z"}]}
{"channel":"book","type":"update","data":[{"symbol":"ETH/CHF","bids":[],"asks":[{"price":3450.82,"qty":1.02254450},{"price":3450.81,"qty":0.01016275}],"checksum":393798656,"timestamp":"2024-06-01T22:42:41.695939Z"}]}
{"channel":"book","type":"update","data":[{"symbol":"ETH/CHF","bids":[],"asks":[{"price":3450.81,"qty":2.01016275}],"checksum":993165475,"timestamp":"2024-06-01T22:42:41.701306Z"}]}
{"channel":"book","type":"update","data":[{"symbol":"ETH/CHF","bids":[],"asks":[{"price":3450.81,"qty":2.00000000},{"price":3450.80,"qty":0.01016275}],"checksum":3837006249,"timestamp":"2024-06-01T22:42:41.991962Z"}]}
{"channel":"book","type":"update","data":[{"symbol":"ETH/CHF","bids":[],"asks":[{"price":3451.55,"qty":28.34439892}],"checksum":2733502556,"timestamp":"2024-06-01T22:42:41.997054Z"}]}
{"channel":"book","type":"update","data":[{"symbol":"ETH/CHF","bids":[{"price":3447.52,"qty":0.01529902}],"asks":[],"checksum":3914999553,"timestamp":"2024-06-01T22:42:42.163274Z"}]}
{"channel":"book","type":"update","data":[{"symbol":"ETH/CHF","bids":[{"price":3444.90,"qty":0.00000000},{"price":3444.14,"qty":0.96000000}],"asks":[],"checksum":1356568278,"timestamp":"2024-06-01T22:42:42.163576Z"}]}
{"channel":"book","type":"update","data":[{"symbol":"ETH/CHF","bids":[{"price":3444.92,"qty":6.65316677}],"asks":[],"checksum":141395209,"timestamp":"2024-06-01T22:42:42.164579Z"}]}
{"channel":"book","type":"update","data":[{"symbol":"ETH/CHF","bids":[{"price":3444.91,"qty":0.00000000},{"price":3444.14,"qty":0.96000000}],"asks":[],"checksum":279529435,"timestamp":"2024-06-01T22:42:42.176098Z"}]}
{"channel":"book","type":"update","data":[{"symbol":"ETH/CHF","bids":[{"price":3444.93,"qty":2.99802006}],"asks":[],"checksum":4217011901,"timestamp":"2024-06-01T22:42:42.176143Z"}]}
{"channel":"book","type":"update","data":[{"symbol":"ETH/CHF","bids":[{"price":3448.69,"qty":0.00000000},{"price":3444.14,"qty":0.96000000},{"price":3448.86,"qty":0.06633800}],"asks":[],"checksum":2885997044,"timestamp":"2024-06-01T22:42:42.427300Z"}]}
{"channel":"book","type":"update","data":[{"symbol":"ETH/CHF","bids":[{"price":3448.85,"qty":0.00000000},{"price":3444.14,"qty":0.96000000},{"price":3448.87,"qty":0.85086579}],"asks":[],"checksum":4160894899,"timestamp":"2024-06-01T22:42:42.461662Z"}]}
{"channel":"book","type":"update","data":[{"symbol":"ETH/CHF","bids":[{"price":3447.52,"qty":0.00000000},{"price":3444.14,"qty":0.96000000}],"asks":[],"checksum":1476348682,"timestamp":"2024-06-01T22:42:42.561109Z"}]}
{"channel":"book","type":"update","data":[{"symbol":"ETH/CHF","bids":[{"price":3448.84,"qty":0.00000000},{"price":3442.91,"qty":1.66000000}],"asks":[],"checksum":2480310921,"timestamp":"2024-06-01T22:42:42.561190Z"}]}
{"channel":"book","type":"update","data":[{"symbol":"ETH/CHF","bids":[{"price":3448.86,"qty":0.09200577}],"asks":[],"checksum":3216591753,"timestamp":"2024-06-01T22:42:42.562886Z"}]}
{"channel":"book","type":"update","data":[{"symbol":"ETH/CHF","bids":[{"price":3444.94,"qty":0.01017607}],"asks":[],"checksum":2678452830,"timestamp":"2024-06-01T22:42:42.563059Z"}]}
{"channel":"book","type":"update","data":[{"symbol":"ETH/CHF","bids":[],"asks":[{"price":3451.54,"qty":0.00000000},{"price":3452.96,"qty":1.07000000}],"checksum":1974591916,"timestamp":"2024-06-01T22:42:43.190884Z"}]}
{"channel":"book","type":"update","data":[{"symbol":"ETH/CHF","bids":[],"asks":[{"price":3451.52,"qty":0.08511130}],"checksum":1899166323,"timestamp":"2024-06-01T22:42:43.192752Z"}]}
{"channel":"book","type":"update","data":[{"symbol":"ETH/CHF","bids":[],"asks":[{"price":3451.55,"qty":0.00000000},{"price":3452.96,"qty":1.07000000}],"checksum":2436735277,"timestamp":"2024-06-01T22:42:43.875413Z"}]}
{"channel":"book","type":"update","data":[{"symbol":"ETH/CHF","bids":[],"asks":[{"price":3450.82,"qty":0.00000000},{"price":3453.24,"qty":2.58000000}],"checksum":2069032827,"timestamp":"2024-06-01T22:42:43.875618Z"}]}
{"channel":"book","type":"update","data":[{"symbol":"ETH/CHF","bids":[],"asks":[{"price":3451.53,"qty":0.00000000},{"price":3453.27,"qty":2.53000000}],"checksum":86706971,"timestamp":"2024-06-01T22:42:43.875792Z"}]}
{"channel":"book","type":"update","data":[{"symbol":"ETH/CHF","bids":[],"asks":[{"price":3451.55,"qty":20.98106350}],"checksum":3799295882,"timestamp":"2024-06-01T22:42:43.880553Z"}]}
{"channel":"book","type":"update","data":[{"symbol":"ETH/CHF","bids":[],"asks":[{"price":3450.80,"qty":1.03270725}],"checksum":378105147,"timestamp":"2024-06-01T22:42:43.880661Z"}]}
{"channel":"book","type":"update","data":[{"symbol":"ETH/CHF","bids":[],"asks":[{"price":3451.55,"qty":22.98106350}],"checksum":3414187653,"timestamp":"2024-06-01T22:42:43.881922Z"}]}
{"channel":"book","type":"update","data":[{"symbol":"ETH/CHF","bids":[],"asks":[{"price":3450.81,"qty":0.00000000},{"price":3453.27,"qty":2.53000000}],"checksum":3333571757,"timestamp":"2024-06-01T22:42:43.881965Z"}]}
{"channel":"book","type":"update","data":[{"symbol":"ETH/CHF","bids":[],"asks":[{"price":3450.80,"qty":1.02254450},{"price":3450.79,"qty":0.01016264}],"checksum":2775161128,"timestamp":"2024-06-01T22:42:43.937437Z"}]}
{"channel":"book","type":"update","data":[{"symbol":"ETH/CHF","bids":[],"asks":[{"price":3450.79,"qty":2.01016264}],"checksum":2222181846,"timestamp":"2024-06-01T22:42:43.942807Z"}]}
{"channel":"book","type":"update","data":[{"symbol":"ETH/CHF","bids":[],"asks":[{"price":3451.55,"qty":20.98106350}],"checksum":1501232744,"timestamp":"2024-06-01T22:42:44.141732Z"}]}
{"channel":"book","type":"update","data":[{"symbol":"ETH/CHF","bids":[],"asks":[{"price":3450.79,"qty":2.00000000},{"price":3450.78,"qty":0.01016264}],"checksum":518141196,"timestamp":"2024-06-01T22:42:44.176531Z"}]}
{"channel":"book","type":"update","data":[{"symbol":"ETH/CHF","bids":[{"price":3444.92,"qty":0.00000000},{"price":3442.91,"qty":1.66000000}],"asks":[],"checksum":3940270874,"timestamp":"2024-06-01T22:42:44.293410Z"}]}
{"channel":"book","type":"update","data":[{"symbol":"ETH/CHF","bids":[{"price":3444.94,"qty":6.15254407}],"asks":[],"checksum":258212353,"timestamp":"2024-06-01T22:42:44.295056Z"}]}
{"channel":"book","type":"update","data":[{"symbol":"ETH/CHF","bids":[{"price":3444.93,"qty":0.00000000},{"price":3442.88,"qty":1.69000000}],"asks":[],"checksum":136979828,"timestamp":"2024-06-01T22:42:44.316051Z"}]}
{"channel":"book","type":"update","data":[{"symbol":"ETH/CHF","bids":[{"price":3444.95,"qty":2.99800265}],"asks":[],"checksum":3721237695,"timestamp":"2024-06-01T22:42:44.316082Z"}]}
{"channel":"book","type":"update","data":[{"symbol":"ETH/CHF","bids":[{"price":3448.86,"qty":0.06633800}],"asks":[],"checksum":4053947839,"timestamp":"2024-06-01T22:42:45.128753Z"}]}
{"channel":"book","type":"update","data":[{"symbol":"ETH/CHF","bids":[{"price":3444.94,"qty":6.14236800}],"asks":[],"checksum":2430869877,"timestamp":"2024-06-01T22:42:45.128802Z"}]}
{"channel":"book","type":"update","data":[{"symbol":"ETH/CHF","bids":[{"price":3448.88,"qty":0.02566777}],"asks":[],"checksum":3156522922,"timestamp":"2024-06-01T22:42:45.129818Z"}]}
{"channel":"book","type":"update","data":[{"symbol":"ETH/CHF","bids":[{"price":3448.87,"qty":0.00000000},{"price":3442.91,"qty":1.66000000},{"price":3448.89,"qty":0.85085894}],"asks":[],"checksum":68548745,"timestamp":"2024-06-01T22:42:45.181629Z"}]}
{"channel":"book","type":"update","data":[{"symbol":"ETH/CHF","bids":[],"asks":[{"price":3451.52,"qty":0.00000000},{"price":3453.24,"qty":2.58000000}],"checksum":2387128780,"timestamp":"2024-06-01T22:42:45.956142Z"}]}
{"channel":"book","type":"update","data":[{"symbol":"ETH/CHF","bids":[],"asks":[{"price":3451.54,"qty":0.08597533}],"checksum":3088454810,"timestamp":"2024-06-01T22:42:45.958076Z"}]}
{"channel":"book","type":"update","data":[{"symbol":"ETH/CHF","bids":[],"asks":[{"price":3450.80,"qty":0.00000000},{"price":3453.24,"qty":2.58000000}],"checksum":2193072227,"timestamp":"2024-06-01T22:42:46.183038Z"}]}
{"channel":"book","type":"update","data":[{"symbol":"ETH/CHF","bids":[],"asks":[{"price":3450.78,"qty":1.03270714}],"checksum":3866065675,"timestamp":"2024-06-01T22:42:46.188162Z"}]}
{"channel":"book","type":"update","data":[{"symbol":"ETH/CHF","bids":[],"asks":[{"price":3451.54,"qty":2.08597533}],"checksum":1325020861,"timestamp":"2024-06-01T22:42:46.189298Z"}]}
{"channel":"book","type":"update","data":[{"symbol":"ETH/CHF","bids":[],"asks":[{"price":3450.79,"qty":0.00000000},{"price":3453.27,"qty":2.53000000}],"checksum":32333799,"timestamp":"2024-06-01T22:42:46.189417Z"}]}
{"channel":"book","type":"update","data":[{"symbol":"ETH/CHF","bids":[],"asks":[{"price":3450.78,"qty":1.02254450},{"price":3450.77,"qty":0.01016271}],"checksum":1048854923,"timestamp":"2024-06-01T22:42:46.255236Z"}]}
{"channel":"book","type":"update","data":[{"symbol":"ETH/CHF","bids":[],"asks":[{"price":3451.13,"qty":2.00000000}],"checksum":1677109177,"timestamp":"2024-06-01T22:42:46.261135Z"}]}
{"channel":"book","type":"update","data":[{"symbol":"ETH/CHF","bids":[{"price":3444.94,"qty":0.00000000},{"price":3442.91,"qty":1.66000000}],"asks":[],"checksum":3229450747,"timestamp":"2024-06-01T22:42:46.300446Z"}]}
{"channel":"book","type":"update","data":[{"symbol":"ETH/CHF","bids":[{"price":3444.96,"qty":6.14236800}],"asks":[],"checksum":3510190224,"timestamp":"2024-06-01T22:42:46.302075Z"}]}
{"channel":"book","type":"update","data":[{"symbol":"ETH/CHF","bids":[{"price":3444.95,"qty":0.00000000},{"price":3442.91,"qty":1.66000000}],"asks":[],"checksum":527201430,"timestamp":"2024-06-01T22:42:46.330022Z"}]}
{"channel":"book","type":"update","data":[{"symbol":"ETH/CHF","bids":[{"price":3444.97,"qty":2.99798525}],"asks":[],"checksum":1409884871,"timestamp":"2024-06-01T22:42:46.330185Z"}]}
{"channel":"book","type":"update","data":[{"symbol":"ETH/CHF","bids":[],"asks":[{"price":3451.54,"qty":0.08597533}],"checksum":3882346135,"timestamp":"2024-06-01T22:42:46.644107Z"}]}
{"channel":"book","type":"update","data":[{"symbol":"ETH/CHF","bids":[{"price":3448.88,"qty":0.00000000},{"price":3442.91,"qty":1.66000000}],"asks":[],"checksum":3026220704,"timestamp":"2024-06-01T22:42:47.642479Z"}]}
{"channel":"book","type":"update","data":[{"symbol":"ETH/CHF","bids":[{"price":3448.90,"qty":0.02758326}],"asks":[],"checksum":1940453266,"timestamp":"2024-06-01T22:42:47.643482Z"}]}
{"channel":"book","type":"update","data":[{"symbol":"ETH/CHF","bids":[{"price":3448.89,"qty":0.00000000},{"price":3442.91,"qty":1.66000000},{"price":3448.87,"qty":0.85086443}],"asks":[],"checksum":555382444,"timestamp":"2024-06-01T22:42:47.705406Z"}]}
{"channel":"book","type":"update","data":[{"symbol":"ETH/CHF","bids":[{"price":3448.87,"qty":0.00000000},{"price":3442.91,"qty":1.66000000},{"price":3448.91,"qty":0.85085456}],"asks":[],"checksum":2073003802,"timestamp":"2024-06-01T22:42:47.769598Z"}]}
{"channel":"book","type":"update","data":[{"symbol":"ETH/CHF","bids":[{"price":3444.96,"qty":0.00000000},{"price":3442.91,"qty":1.66000000}],"asks":[],"checksum":409230557,"timestamp":"2024-06-01T22:42:48.414054Z"}]}
{"channel":"book","type":"update","data":[{"symbol":"ETH/CHF","bids":[{"price":3444.98,"qty":6.14236800}],"asks":[],"checksum":3280026271,"timestamp":"2024-06-01T22:42:48.416456Z"}]}
{"channel":"book","type":"update","data":[{"symbol":"ETH/CHF","bids":[{"price":3444.97,"qty":0.00000000},{"price":3442.91,"qty":1.66000000}],"asks":[],"checksum":2909796358,"timestamp":"2024-06-01T22:42:48.428146Z"}]}
{"channel":"book","type":"update","data":[{"symbol":"ETH/CHF","bids":[{"price":3444.99,"qty":2.99796785}],"asks":[],"checksum":3839758050,"timestamp":"2024-06-01T22:42:48.428561Z"}]}
{"channel":"book","type":"update","data":[{"symbol":"ETH/CHF","bids":[],"asks":[{"price":3450.78,"qty":0.00000000},{"price":3453.24,"qty":2.58000000}],"checksum":1005568757,"timestamp":"2024-06-01T22:42:48.432979Z"}]}
{"channel":"book","type":"update","data":[{"symbol":"ETH/CHF","bids":[],"asks":[{"price":3451.55,"qty":0.00000000},{"price":3453.27,"qty":2.53000000}],"checksum":1661470465,"timestamp":"2024-06-01T22:42:48.433201Z"}]}
{"channel":"book","type":"update","data":[{"symbol":"ETH/CHF","bids":[],"asks":[{"price":3451.53,"qty":5.51321127}],"checksum":1301867411,"timestamp":"2024-06-01T22:42:48.438060Z"}]}
{"channel":"book","type":"update","data":[{"symbol":"ETH/CHF","bids":[],"asks":[{"price":3451.12,"qty":4.01632235}],"checksum":4269199707,"timestamp":"2024-06-01T22:42:48.438171Z"}]}
{"channel":"book","type":"update","data":[{"symbol":"ETH/CHF","bids":[],"asks":[{"price":3451.55,"qty":22.29958916}],"checksum":3949033378,"timestamp":"2024-06-01T22:42:48.438317Z"}]}
{"channel":"book","type":"update","data":[{"symbol":"ETH/CHF","bids":[],"asks":[{"price":3451.13,"qty":0.00000000},{"price":3452.96,"qty":1.07000000}],"checksum":3415820418,"timestamp":"2024-06-01T22:42:48.439727Z"}]}
{"channel":"book","type":"update","data":[{"symbol":"ETH/CHF","bids":[],"asks":[{"price":3451.54,"qty":2.08597533}],"checksum":1277264521,"timestamp":"2024-06-01T22:42:48.439878Z"}]}
{"channel":"book","type":"update","data":[{"symbol":"ETH/CHF","bids":[],"asks":[{"price":3450.77,"qty":0.00000000},{"price":3453.24,"qty":2.58000000},{"price":3451.11,"qty":0.01016228}],"checksum":973332858,"timestamp":"2024-06-01T22:42:48.496839Z"}]}
{"channel":"book","type":"update","data":[{"symbol":"ETH/CHF","bids":[],"asks":[{"price":3451.11,"qty":2.01016228}],"checksum":157830611,"timestamp":"2024-06-01T22:42:48.502515Z"}]}
{"channel":"book","type":"update","data":[{"symbol":"ETH/CHF","bids":[],"asks":[{"price":3451.11,"qty":2.00000000},{"price":3451.10,"qty":0.01016228}],"checksum":2885410434,"timestamp":"2024-06-01T22:42:48.550827Z"}]}
{"channel":"book","type":"update","data":[{"symbol":"ETH/CHF","bids":[],"asks":[{"price":3451.54,"qty":0.08597533}],"checksum":2435553102,"timestamp":"2024-06-01T22:42:48.555782Z"}]}
{"channel":"book","type":"update","data":[{"symbol":"ETH/CHF","bids":[],"asks":[{"price":3451.54,"qty":0.00000000},{"price":3452.96,"qty":1.07000000}],"checksum":2913236414,"timestamp":"2024-06-01T22:42:48.783667Z"}]}
{"channel":"book","type":"update","data":[{"symbol":"ETH/CHF","bids":[],"asks":[{"price":3451.11,"qty":2.01445222}],"checksum":4050658168,"timestamp":"2024-06-01T22:42:48.786316Z"}]}
{"channel":"book","type":"update","data":[{"symbol":"ETH/CHF","bids":[],"asks":[{"price":3451.52,"qty":0.06739494}],"checksum":2044092341,"timestamp":"2024-06-01T22:42:48.786610Z"}]}
{"channel":"book","type":"update","data":[{"symbol":"ETH/CHF","bids":[{"price":3448.90,"qty":0.00000000},{"price":3442.91,"qty":1.66000000}],"asks":[],"checksum":2813021159,"timestamp":"2024-06-01T22:42:50.164711Z"}]}
{"channel":"book","type":"update","data":[{"symbol":"ETH/CHF","bids":[{"price":3448.92,"qty":0.02566777}],"asks":[],"checksum":1582261483,"timestamp":"2024-06-01T22:42:50.166256Z"}]}
{"channel":"book","type":"update","data":[{"symbol":"ETH/CHF","bids":[{"price":3445.00,"qty":0.01017607}],"asks":[],"checksum":4136839430,"timestamp":"2024-06-01T22:42:50.166313Z"}]}
{"channel":"book","type":"update","data":[{"symbol":"ETH/CHF","bids":[{"price":3448.91,"qty":0.00000000},{"price":3444.14,"qty":0.96000000},{"price":3448.93,"qty":0.85084548}],"asks":[],"checksum":1300377160,"timestamp":"2024-06-01T22:42:50.209115Z"}]}
{"channel":"book","type":"update","data":[{"symbol":"ETH/CHF","bids":[{"price":3444.68,"qty":2.99823765}],"asks":[],"checksum":3665115906,"timestamp":"2024-06-01T22:42:50.217274Z"}]}
{"channel":"book","type":"update","data":[{"symbol":"ETH/CHF","bids":[{"price":3444.99,"qty":0.00000000},{"price":3444.67,"qty":0.89000000}],"asks":[],"checksum":2024795530,"timestamp":"2024-06-01T22:42:50.217302Z"}]}
{"channel":"book","type":"update","data":[{"symbol":"ETH/CHF","bids":[{"price":3444.98,"qty":0.00000000},{"price":3444.14,"qty":0.96000000}],"asks":[],"checksum":1259927763,"timestamp":"2024-06-01T22:42:50.540520Z"}]}
{"channel":"book","type":"update","data":[{"symbol":"ETH/CHF","bids":[{"price":3444.69,"qty":6.14236800}],"asks":[],"checksum":3060307083,"timestamp":"2024-06-01T22:42:50.541225Z"}]}
{"channel":"book","type":"update","data":[{"symbol":"ETH/CHF","bids":[{"price":3444.68,"qty":0.00000000},{"price":3444.14,"qty":0.96000000}],"asks":[],"checksum":3074721883,"timestamp":"2024-06-01T22:42:50.554324Z"}]}
{"channel":"book","type":"update","data":[{"symbol":"ETH/CHF","bids":[{"price":3444.70,"qty":2.99822024}],"asks":[],"checksum":948047315,"timestamp":"2024-06-01T22:42:50.554385Z"}]}
{"channel":"book","type":"update","data":[{"symbol":"ETH/CHF","bids":[],"asks":[{"price":3451.53,"qty":0.00000000},{"price":3452.96,"qty":1.07000000}],"checksum":433621392,"timestamp":"2024-06-01T22:42:50.720110Z"}]}
{"channel":"book","type":"update","data":[{"symbol":"ETH/CHF","bids":[],"asks":[{"price":3451.55,"qty":0.00000000},{"price":3453.24,"qty":2.58000000}],"checksum":1479920974,"timestamp":"2024-06-01T22:42:50.720184Z"}]}
{"channel":"book","type":"update","data":[{"symbol":"ETH/CHF","bids":[],"asks":[{"price":3451.12,"qty":0.00000000},{"price":3453.27,"qty":2.53000000}],"checksum":2064737789,"timestamp":"2024-06-01T22:42:50.720690Z"}]}
{"channel":"book","type":"update","data":[{"symbol":"ETH/CHF","bids":[],"asks":[{"price":3451.55,"qty":25.35914827}],"checksum":1342518303,"timestamp":"2024-06-01T22:42:50.725429Z"}]}
{"channel":"book","type":"update","data":[{"symbol":"ETH/CHF","bids":[],"asks":[{"price":3451.09,"qty":0.52358152}],"checksum":1359766896,"timestamp":"2024-06-01T22:42:50.725447Z"}]}
{"channel":"book","type":"update","data":[{"symbol":"ETH/CHF","bids":[],"asks":[{"price":3451.10,"qty":3.02855868}],"checksum":216424730,"timestamp":"2024-06-01T22:42:50.725553Z"}]}
{"channel":"book","type":"update","data":[{"symbol":"ETH/CHF","bids":[],"asks":[{"price":3451.55,"qty":27.35914827}],"checksum":3364899915,"timestamp":"2024-06-01T22:42:50.727401Z"}]}
{"channel":"book","type":"update","data":[{"symbol":"ETH/CHF","bids":[],"asks":[{"price":3451.11,"qty":0.01445222}],"checksum":356797106,"timestamp":"2024-06-01T22:42:50.727458Z"}]}
{"channel":"book","type":"update","data":[{"symbol":"ETH/CHF","bids":[],"asks":[{"price":3451.10,"qty":3.01839640},{"price":3451.08,"qty":0.01016247}],"checksum":796911040,"timestamp":"2024-06-01T22:42:50.763269Z"}]}
{"channel":"book","type":"update","data":[{"symbol":"ETH/CHF","bids":[],"asks":[{"price":3451.08,"qty":2.01016247}],"checksum":2873559115,"timestamp":"2024-06-01T22:42:50.768706Z"}]}
{"channel":"book","type":"update","data":[{"symbol":"ETH/CHF","bids":[],"asks":[{"price":3451.08,"qty":2.00000000},{"price":3451.07,"qty":0.01016247}],"checksum":1848119819,"timestamp":"2024-06-01T22:42:50.796709Z"}]}
{"channel":"book","type":"update","data":[{"symbol":"ETH/CHF","bids":[],"asks":[{"price":3451.55,"qty":25.35914827}],"checksum":138125428,"timestamp":"2024-06-01T22:42:50.802093Z"}]}
{"channel":"book","type":"update","data":[{"symbol":"ETH/CHF","bids":[],"asks":[{"price":3451.11,"qty":0.00000000},{"price":3452.95,"qty":6.03120000}],"checksum":2510118421,"timestamp":"2024-06-01T22:42:51.452410Z"}]}
{"channel":"book","type":"update","data":[{"symbol":"ETH/CHF","bids":[],"asks":[{"price":3451.52,"qty":0.00000000},{"price":3452.96,"qty":1.07000000}],"checksum":1009263040,"timestamp":"2024-06-01T22:42:51.452593Z"}]}
{"channel":"book","type":"update","data":[{"symbol":"ETH/CHF","bids":[],"asks":[{"price":3451.54,"qty":0.06681891}],"checksum":2187840337,"timestamp":"2024-06-01T22:42:51.455176Z"}]}
{"channel":"book","type":"update","data":[{"symbol":"ETH/CHF","bids":[],"asks":[{"price":3451.07,"qty":0.02768682}],"checksum":1990280313,"timestamp":"2024-06-01T22:42:51.455320Z"}]}
{"channel":"book","type":"update","data":[{"symbol":"ETH/CHF","bids":[],"asks":[{"price":3451.07,"qty":0.01752435},{"price":3451.06,"qty":0.01016247}],"checksum":960795689,"timestamp":"2024-06-01T22:42:51.504208Z"}]}
{"channel":"book","type":"update","data":[{"symbol":"ETH/CHF","bids":[{"price":3444.69,"qty":0.00000000},{"price":3444.14,"qty":0.96000000}],"asks":[],"checksum":3841015604,"timestamp":"2024-06-01T22:42:52.518454Z"}]}
{"channel":"book","type":"update","data":[{"symbol":"ETH/CHF","bids":[{"price":3444.71,"qty":6.14240013}],"asks":[],"checksum":877598205,"timestamp":"2024-06-01T22:42:52.519553Z"}]}
{"channel":"book","type":"update","data":[{"symbol":"ETH/CHF","bids":[{"price":3444.70,"qty":0.00000000},{"price":3444.14,"qty":0.96000000}],"asks":[],"checksum":1954655791,"timestamp":"2024-06-01T22:42:52.525102Z"}]}
{"channel":"book","type":"update","data":[{"symbol":"ETH/CHF","bids":[{"price":3444.72,"qty":2.99820283}],"asks":[],"checksum":1147518610,"timestamp":"2024-06-01T22:42:52.525204Z"}]}
{"channel":"book","type":"update","data":[{"symbol":"ETH/CHF","bids":[{"price":3448.92,"qty":0.00000000},{"price":3444.14,"qty":0.96000000}],"asks":[],"checksum":1261820066,"timestamp":"2024-06-01T22:42:52.668087Z"}]}
{"channel":"book","type":"update","data":[{"symbol":"ETH/CHF","bids":[{"price":3445.00,"qty":0.00000000},{"price":3442.91,"qty":1.66000000}],"asks":[],"checksum":169886456,"timestamp":"2024-06-01T22:42:52.668135Z"}]}
{"channel":"book","type":"update","data":[{"symbol":"ETH/CHF","bids":[{"price":3448.94,"qty":0.02566790}],"asks":[],"checksum":4117157714,"timestamp":"2024-06-01T22:42:52.669442Z"}]}
{"channel":"book","type":"update","data":[{"symbol":"ETH/CHF","bids":[{"price":3448.93,"qty":0.00000000},{"price":3442.91,"qty":1.66000000},{"price":3448.87,"qty":0.85085604}],"asks":[],"checksum":2387011842,"timestamp":"2024-06-01T22:42:52.715653Z"}]}
{"channel":"book","type":"update","data":[{"symbol":"ETH/CHF","bids":[{"price":3448.87,"qty":0.00000000},{"price":3442.91,"qty":1.66000000},{"price":3448.95,"qty":0.85083631}],"asks":[],"checksum":4083506407,"timestamp":"2024-06-01T22:42:52.781461Z"}]}
{"channel":"book","type":"update","data":[{"symbol":"ETH/CHF","bids":[{"price":3448.95,"qty":0.00000000},{"price":3442.91,"qty":1.66000000},{"price":3448.96,"qty":0.85083376}],"asks":[],"checksum":1678348179,"timestamp":"2024-06-01T22:42:52.846235Z"}]}
{"channel":"book","type":"update","data":[{"symbol":"ETH/CHF","bids":[{"price":3448.96,"qty":0.00000000},{"price":3442.91,"qty":1.66000000},{"price":3448.95,"qty":0.85083623}],"asks":[],"checksum":729360482,"timestamp":"2024-06-01T22:42:52.904282Z"}]}
{"channel":"book","type":"update","data":[{"symbol":"ETH/CHF","bids":[],"asks":[{"price":3451.38,"qty":0.00000000},{"price":3452.95,"qty":6.03120000},{"price":3451.10,"qty":3.08470140}],"checksum":2723855315,"timestamp":"2024-06-01T22:42:52.915506Z"}]}
{"channel":"book","type":"update","data":[{"symbol":"ETH/CHF","bids":[],"asks":[{"price":3451.09,"qty":0.00000000},{"price":3452.96,"qty":1.07000000}],"checksum":682497576,"timestamp":"2024-06-01T22:42:52.924207Z"}]}
{"channel":"book","type":"update","data":[{"symbol":"ETH/CHF","bids":[],"asks":[{"price":3451.10,"qty":0.06630500}],"checksum":2726289476,"timestamp":"2024-06-01T22:42:52.924534Z"}]}
{"channel":"book","type":"update","data":[{"symbol":"ETH/CHF","bids":[],"asks":[{"price":3451.55,"qty":0.00000000},{"price":3453.24,"qty":2.58000000}],"checksum":2969745208,"timestamp":"2024-06-01T22:42:52.926618Z"}]}
{"channel":"book","type":"update","data":[{"symbol":"ETH/CHF","bids":[],"asks":[{"price":3451.07,"qty":24.41771313}],"checksum":1680453889,"timestamp":"2024-06-01T22:42:52.929467Z"}]}
{"channel":"book","type":"update","data":[{"symbol":"ETH/CHF","bids":[],"asks":[{"price":3451.06,"qty":1.53168459}],"checksum":3100293214,"timestamp":"2024-06-01T22:42:52.929543Z"}]}
{"channel":"book","type":"update","data":[{"symbol":"ETH/CHF","bids":[],"asks":[{"price":3451.05,"qty":0.52359618}],"checksum":421895880,"timestamp":"2024-06-01T22:42:52.929562Z"}]}
{"channel":"book","type":"update","data":[{"symbol":"ETH/CHF","bids":[],"asks":[{"price":3451.06,"qty":1.52152212},{"price":3451.04,"qty":0.01016247}],"checksum":1039657122,"timestamp":"2024-06-01T22:42:52.972204Z"}]}
{"channel":"book","type":"update","data":[{"symbol":"ETH/CHF","bids":[],"asks":[{"price":3451.04,"qty":2.01016247}],"checksum":4291285053,"timestamp":"2024-06-01T22:42:52.978110Z"}]}
{"channel":"book","type":"update","data":[{"symbol":"ETH/CHF","bids":[],"asks":[{"price":3451.04,"qty":2.00000000},{"price":3451.03,"qty":0.01016247}],"checksum":1653898967,"timestamp":"2024-06-01T22:42:53.061256Z"}]}
{"channel":"book","type":"update","data":[{"symbol":"ETH/CHF","bids":[],"asks":[{"price":3451.08,"qty":0.00000000},{"price":3452.95,"qty":6.03120000}],"checksum":2695093436,"timestamp":"2024-06-01T22:42:53.066560Z"}]}
{"channel":"book","type":"update","data":[{"symbol":"ETH/CHF","bids":[],"asks":[{"price":3451.54,"qty":0.00000000},{"price":3452.96,"qty":1.07000000}],"checksum":947614348,"timestamp":"2024-06-01T22:42:54.286193Z"}]}
{"channel":"book","type":"update","data":[{"symbol":"ETH/CHF","bids":[],"asks":[{"price":3451.07,"qty":24.40018878}],"checksum":3335875778,"timestamp":"2024-06-01T22:42:54.286362Z"}]}
{"channel":"book","type":"update","data":[{"symbol":"ETH/CHF","bids":[],"asks":[{"price":3451.03,"qty":0.04611972}],"checksum":2122829967,"timestamp":"2024-06-01T22:42:54.287656Z"}]}
{"channel":"book","type":"update","data":[{"symbol":"ETH/CHF","bids":[],"asks":[{"price":3451.03,"qty":0.03595725},{"price":3451.02,"qty":0.01016238}],"checksum":3614671718,"timestamp":"2024-06-01T22:42:54.339270Z"}]}
{"channel":"book","type":"update","data":[{"symbol":"ETH/CHF","bids":[],"asks":[{"price":3451.02,"qty":0.00000000},{"price":3452.96,"qty":1.07000000},{"price":3451.01,"qty":0.01016238}],"checksum":3761882952,"timestamp":"2024-06-01T22:42:54.395487Z"}]}
{"channel":"book","type":"update","data":[{"symbol":"ETH/CHF","bids":[],"asks":[{"price":3451.01,"qty":0.00000000},{"price":3452.96,"qty":1.07000000},{"price":3451.02,"qty":0.01016238}],"checksum":3614671718,"timestamp":"2024-06-01T22:42:54.450382Z"}]}
{"channel":"book","type":"update","data":[{"symbol":"ETH/CHF","bids":[{"price":3444.71,"qty":0.00000000},{"price":3442.91,"qty":1.66000000}],"asks":[],"checksum":3768182459,"timestamp":"2024-06-01T22:42:54.632599Z"}]}
{"channel":"book","type":"update","data":[{"symbol":"ETH/CHF","bids":[{"price":3444.73,"qty":6.14248545}],"asks":[],"checksum":1171271241,"timestamp":"2024-06-01T22:42:54.634188Z"}]}
{"channel":"book","type":"update","data":[{"symbol":"ETH/CHF","bids":[{"price":3444.72,"qty":0.00000000},{"price":3442.91,"qty":1.66000000}],"asks":[],"checksum":3052481041,"timestamp":"2024-06-01T22:42:54.642761Z"}]}
{"channel":"book","type":"update","data":[{"symbol":"ETH/CHF","bids":[{"price":3444.74,"qty":2.99818541}],"asks":[],"checksum":4107744690,"timestamp":"2024-06-01T22:42:54.642932Z"}]}
{"channel":"book","type":"update","data":[{"symbol":"ETH/CHF","bids":[],"asks":[{"price":3451.07,"qty":0.00000000},{"price":3452.96,"qty":1.07000000}],"checksum":1852293475,"timestamp":"2024-06-01T22:42:55.226641Z"}]}
{"channel":"book","type":"update","data":[{"symbol":"ETH/CHF","bids":[],"asks":[{"price":3451.06,"qty":0.00000000},{"price":3453.24,"qty":2.58000000}],"checksum":3413447516,"timestamp":"2024-06-01T22:42:55.226969Z"}]}
{"channel":"book","type":"update","data":[{"symbol":"ETH/CHF","bids":[],"asks":[{"price":3451.05,"qty":0.00000000},{"price":3453.27,"qty":2.53000000}],"checksum":2615229547,"timestamp":"2024-06-01T22:42:55.227031Z"}]}
{"channel":"book","type":"update","data":[{"symbol":"ETH/CHF","bids":[],"asks":[{"price":3451.01,"qty":0.52359153}],"checksum":1562052663,"timestamp":"2024-06-01T22:42:55.229031Z"}]}
{"channel":"book","type":"update","data":[{"symbol":"ETH/CHF","bids":[],"asks":[{"price":3451.55,"qty":28.35973758}],"checksum":2804206482,"timestamp":"2024-06-01T22:42:55.229066Z"}]}
{"channel":"book","type":"update","data":[{"symbol":"ETH/CHF","bids":[],"asks":[{"price":3451.02,"qty":2.52960579}],"checksum":69964194,"timestamp":"2024-06-01T22:42:55.229085Z"}]}
{"channel":"book","type":"update","data":[{"symbol":"ETH/CHF","bids":[{"price":3448.83,"qty":0.00000000},{"price":3442.91,"qty":1.66000000}],"asks":[],"checksum":3402275989,"timestamp":"2024-06-01T22:42:55.232379Z"}]}
{"channel":"book","type":"update","data":[{"symbol":"ETH/CHF","bids":[{"price":3448.96,"qty":3.20042986}],"asks":[],"checksum":1504162417,"timestamp":"2024-06-01T22:42:55.235881Z"}]}
{"channel":"book","type":"update","data":[{"symbol":"ETH/CHF","bids":[{"price":3448.94,"qty":0.00000000},{"price":3442.91,"qty":1.66000000}],"asks":[],"checksum":4132463419,"timestamp":"2024-06-01T22:42:55.253627Z"}]}
{"channel":"book","type":"update","data":[{"symbol":"ETH/CHF","bids":[{"price":3448.96,"qty":3.22099003}],"asks":[],"checksum":1675934698,"timestamp":"2024-06-01T22:42:55.254827Z"}]}
{"channel":"book","type":"update","data":[{"symbol":"ETH/CHF","bids":[{"price":3444.75,"qty":0.01527936}],"asks":[],"checksum":1737992172,"timestamp":"2024-06-01T22:42:55.254887Z"}]}
{"channel":"book","type":"update","data":[{"symbol":"ETH/CHF","bids":[],"asks":[{"price":3451.02,"qty":2.51944341},{"price":3451.00,"qty":0.01016238}],"checksum":3803762597,"timestamp":"2024-06-01T22:42:55.295366Z"}]}
{"channel":"book","type":"update","data":[{"symbol":"ETH/CHF","bids":[{"price":3448.95,"qty":0.00000000},{"price":3442.91,"qty":1.66000000},{"price":3448.97,"qty":0.85083762}],"asks":[],"checksum":141937200,"timestamp":"2024-06-01T22:42:55.295445Z"}]}
{"channel":"book","type":"update","data":[{"symbol":"ETH/CHF","bids":[],"asks":[{"price":3451.00,"qty":2.01016238}],"checksum":2445564524,"timestamp":"2024-06-01T22:42:55.301701Z"}]}
{"channel":"book","type":"update","data":[{"symbol":"ETH/CHF","bids":[],"asks":[{"price":3451.00,"qty":2.00000000},{"price":3450.99,"qty":0.01016238}],"checksum":3872469057,"timestamp":"2024-06-01T22:42:55.428248Z"}]}
{"channel":"book","type":"update","data":[{"symbol":"ETH/CHF","bids":[],"asks":[{"price":3451.04,"qty":0.00000000},{"price":3452.95,"qty":6.03120000}],"checksum":2490096992,"timestamp":"2024-06-01T22:42:55.433514Z"}]}
{"channel":"book","type":"update","data":[{"symbol":"ETH/CHF","bids":[],"asks":[{"price":3451.10,"qty":0.00000000},{"price":3452.96,"qty":1.07000000},{"price":3451.45,"qty":0.06630300}],"checksum":3062911266,"timestamp":"2024-06-01T22:42:56.497500Z"}]}
{"channel":"book","type":"update","data":[{"symbol":"ETH/CHF","bids":[],"asks":[{"price":3451.03,"qty":0.00000000},{"price":3452.96,"qty":1.07000000}],"checksum":349321351,"timestamp":"2024-06-01T22:42:56.604169Z"}]}
{"channel":"book","type":"update","data":[{"symbol":"ETH/CHF","bids":[{"price":3444.73,"qty":0.00000000},{"price":3442.91,"qty":1.66000000}],"asks":[],"checksum":1773559983,"timestamp":"2024-06-01T22:42:56.726084Z"}]}
{"channel":"book","type":"update","data":[{"symbol":"ETH/CHF","bids":[{"price":3444.75,"qty":6.15767949}],"asks":[],"checksum":1238269824,"timestamp":"2024-06-01T22:42:56.727482Z"}]}
{"channel":"book","type":"update","data":[{"symbol":"ETH/CHF","bids":[{"price":3444.74,"qty":0.00000000},{"price":3442.88,"qty":1.69000000}],"asks":[],"checksum":2582555528,"timestamp":"2024-06-01T22:42:56.751227Z"}]}
{"channel":"book","type":"update","data":[{"symbol":"ETH/CHF","bids":[{"price":3444.76,"qty":2.99816802}],"asks":[],"checksum":1500231918,"timestamp":"2024-06-01T22:42:56.751504Z"}]}
{"channel":"book","type":"update","data":[{"symbol":"ETH/CHF","bids":[],"asks":[{"price":3451.54,"qty":0.08294761}],"checksum":3752439665,"timestamp":"2024-06-01T22:42:57.029762Z"}]}
{"channel":"book","type":"update","data":[{"symbol":"ETH/CHF","bids":[],"asks":[{"price":3450.99,"qty":0.02154249}],"checksum":3503042321,"timestamp":"2024-06-01T22:42:57.029822Z"}]}
{"channel":"book","type":"update","data":[{"symbol":"ETH/CHF","bids":[],"asks":[{"price":3450.99,"qty":0.01138011},{"price":3450.98,"qty":0.01016220}],"checksum":65791422,"timestamp":"2024-06-01T22:42:57.093422Z"}]}
{"channel":"book","type":"update","data":[{"symbol":"ETH/CHF","bids":[],"asks":[{"price":3451.01,"qty":0.00000000},{"price":3452.95,"qty":6.03120000}],"checksum":3976847468,"timestamp":"2024-06-01T22:42:57.516251Z"}]}
{"channel":"book","type":"update","data":[{"symbol":"ETH/CHF","bids":[],"asks":[{"price":3451.55,"qty":0.00000000},{"price":3452.96,"qty":1.07000000}],"checksum":465197946,"timestamp":"2024-06-01T22:42:57.516561Z"}]}
{"channel":"book","type":"update","data":[{"symbol":"ETH/CHF","bids":[],"asks":[{"price":3451.02,"qty":0.00000000},{"price":3453.24,"qty":2.58000000}],"checksum":397369301,"timestamp":"2024-06-01T22:42:57.517037Z"}]}
{"channel":"book","type":"update","data":[{"symbol":"ETH/CHF","bids":[],"asks":[{"price":3450.97,"qty":0.52358426}],"checksum":4046144994,"timestamp":"2024-06-01T22:42:57.522301Z"}]}
{"channel":"book","type":"update","data":[{"symbol":"ETH/CHF","bids":[],"asks":[{"price":3450.99,"qty":2.53081627}],"checksum":2668602015,"timestamp":"2024-06-01T22:42:57.522355Z"}]}
{"channel":"book","type":"update","data":[{"symbol":"ETH/CHF","bids":[],"asks":[{"price":3451.53,"qty":35.82957161}],"checksum":2677491876,"timestamp":"2024-06-01T22:42:57.522444Z"}]}
{"channel":"book","type":"update","data":[{"symbol":"ETH/CHF","bids":[],"asks":[{"price":3451.00,"qty":0.00000000},{"price":3452.96,"qty":1.07000000}],"checksum":1240375476,"timestamp":"2024-06-01T22:42:57.523990Z"}]}
{"channel":"book","type":"update","data":[{"symbol":"ETH/CHF","bids":[],"asks":[{"price":3451.01,"qty":2.00000000}],"checksum":3777381353,"timestamp":"2024-06-01T22:42:57.524139Z"}]}
{"channel":"book","type":"update","data":[{"symbol":"ETH/CHF","bids":[],"asks":[{"price":3450.98,"qty":0.00000000},{"price":3452.96,"qty":1.07000000},{"price":3450.96,"qty":0.01016220}],"checksum":3546558259,"timestamp":"2024-06-01T22:42:57.568328Z"}]}
{"channel":"book","type":"update","data":[{"symbol":"ETH/CHF","bids":[],"asks":[{"price":3450.96,"qty":2.01016220}],"checksum":1428787693,"timestamp":"2024-06-01T22:42:57.573671Z"}]}
{"channel":"book","type":"update","data":[{"symbol":"ETH/CHF","bids":[],"asks":[{"price":3451.01,"qty":0.00000000},{"price":3452.96,"qty":1.07000000}],"checksum":4259410608,"timestamp":"2024-06-01T22:42:57.642205Z"}]}
{"channel":"book","type":"update","data":[{"symbol":"ETH/CHF","bids":[],"asks":[{"price":3450.96,"qty":2.00000000},{"price":3450.95,"qty":0.01016220}],"checksum":1225567882,"timestamp":"2024-06-01T22:42:57.646023Z"}]}
{"channel":"book","type":"update","data":[{"symbol":"ETH/CHF","bids":[{"price":3444.75,"qty":6.14240013}],"asks":[],"checksum":95534214,"timestamp":"2024-06-01T22:42:57.773743Z"}]}
{"channel":"book","type":"update","data":[{"symbol":"ETH/CHF","bids":[{"price":3448.96,"qty":3.20042986}],"asks":[],"checksum":2693447847,"timestamp":"2024-06-01T22:42:57.773770Z"}]}
{"channel":"book","type":"update","data":[{"symbol":"ETH/CHF","bids":[{"price":3448.98,"qty":0.02565294}],"asks":[],"checksum":518859707,"timestamp":"2024-06-01T22:42:57.774974Z"}]}
{"channel":"book","type":"update","data":[{"symbol":"ETH/CHF","bids":[{"price":3448.97,"qty":0.00000000},{"price":3442.91,"qty":1.66000000},{"price":3448.99,"qty":0.85083787}],"asks":[],"checksum":2730208402,"timestamp":"2024-06-01T22:42:57.821238Z"}]}
{"channel":"book","type":"update","data":[{"symbol":"ETH/CHF","bids":[{"price":3448.99,"qty":0.00000000},{"price":3442.91,"qty":1.66000000},{"price":3449.00,"qty":0.85083541}],"asks":[],"checksum":3708800673,"timestamp":"2024-06-01T22:42:57.976699Z"}]}
{"channel":"book","type":"update","data":[{"symbol":"ETH/CHF","bids":[],"asks":[{"price":3450.95,"qty":0.00000000},{"price":3452.96,"qty":1.07000000},{"price":3450.95,"qty":0.00918327}],"checksum":3182103440,"timestamp":"2024-06-01T22:42:57.976745Z"}]}
{"channel":"book","type":"update","data":[{"symbol":"ETH/CHF","bids":[{"price":3449.00,"qty":0.00000000},{"price":3442.91,"qty":1.66000000},{"price":3449.01,"qty":0.85083295}],"asks":[],"checksum":865422785,"timestamp":"2024-06-01T22:42:58.197996Z"}]}
{"channel":"book","type":"update","data":[{"symbol":"ETH/CHF","bids":[{"price":3449.01,"qty":0.00000000},{"price":3442.91,"qty":1.66000000},{"price":3448.99,"qty":0.85083789}],"asks":[],"checksum":781318352,"timestamp":"2024-06-01T22:42:58.252983Z"}]}
{"channel":"book","type":"update","data":[{"symbol":"ETH/CHF","bids":[{"price":3444.75,"qty":0.00000000},{"price":3442.91,"qty":1.66000000}],"asks":[],"checksum":1120624710,"timestamp":"2024-06-01T22:42:58.851504Z"}]}
{"channel":"book","type":"update","data":[{"symbol":"ETH/CHF","bids":[{"price":3444.77,"qty":6.14240013}],"asks":[],"checksum":4004811679,"timestamp":"2024-06-01T22:42:58.853018Z"}]}
{"channel":"book","type":"update","data":[{"symbol":"ETH/CHF","bids":[{"price":3444.76,"qty":0.00000000},{"price":3442.91,"qty":1.66000000}],"asks":[],"checksum":1727831209,"timestamp":"2024-06-01T22:42:58.858225Z"}]}
{"channel":"book","type":"update","data":[{"symbol":"ETH/CHF","bids":[{"price":3444.78,"qty":2.99815061}],"asks":[],"checksum":2176799777,"timestamp":"2024-06-01T22:42:58.858351Z"}]}
{"channel":"book","type":"update","data":[{"symbol":"ETH/CHF","bids":[],"asks":[{"price":3450.97,"qty":0.00000000},{"price":3452.96,"qty":1.07000000}],"checksum":1595926070,"timestamp":"2024-06-01T22:42:59.725683Z"}]}
{"channel":"book","type":"update","data":[{"symbol":"ETH/CHF","bids":[],"asks":[{"price":3450.99,"qty":0.01138011}],"checksum":1150541745,"timestamp":"2024-06-01T22:42:59.725759Z"}]}
{"channel":"book","type":"update","data":[{"symbol":"ETH/CHF","bids":[],"asks":[{"price":3451.53,"qty":0.00000000},{"price":3453.24,"qty":2.58000000}],"checksum":2154142438,"timestamp":"2024-06-01T22:42:59.726001Z"}]}
{"channel":"book","type":"update","data":[{"symbol":"ETH/CHF","bids":[],"asks":[{"price":3451.53,"qty":28.37387585}],"checksum":3394543201,"timestamp":"2024-06-01T22:42:59.731121Z"}]}
{"channel":"book","type":"update","data":[{"symbol":"ETH/CHF","bids":[],"asks":[{"price":3450.94,"qty":0.52358426}],"checksum":4157507016,"timestamp":"2024-06-01T22:42:59.731251Z"}]}
{"channel":"book","type":"update","data":[{"symbol":"ETH/CHF","bids":[],"asks":[{"price":3450.95,"qty":2.02965645}],"checksum":542949165,"timestamp":"2024-06-01T22:42:59.731384Z"}]}
{"channel":"book","type":"update","data":[{"symbol":"ETH/CHF","bids":[],"asks":[{"price":3450.96,"qty":0.00000000},{"price":3452.96,"qty":1.07000000}],"checksum":3077111532,"timestamp":"2024-06-01T22:42:59.732484Z"}]}
{"channel":"book","type":"update","data":[{"symbol":"ETH/CHF","bids":[],"asks":[{"price":3451.52,"qty":2.00000000}],"checksum":857458638,"timestamp":"2024-06-01T22:42:59.732635Z"}]}
{"channel":"book","type":"update","data":[{"symbol":"ETH/CHF","bids":[],"asks":[{"price":3450.95,"qty":2.02047318},{"price":3450.93,"qty":0.00918383}],"checksum":3472968209,"timestamp":"2024-06-01T22:42:59.788899Z"}]}
{"channel":"book","type":"update","data":[{"symbol":"ETH/CHF","bids":[],"asks":[{"price":3450.93,"qty":2.00918383}],"checksum":898731278,"timestamp":"2024-06-01T22:42:59.794974Z"}]}
{"channel":"book","type":"update","data":[{"symbol":"ETH/CHF","bids":[],"asks":[{"price":3451.54,"qty":0.00000000},{"price":3452.95,"qty":6.03120000}],"checksum":1133954444,"timestamp":"2024-06-01T22:42:59.810494Z"}]}
{"channel":"book","type":"update","data":[{"symbol":"ETH/CHF","bids":[],"asks":[{"price":3450.99,"qty":0.00000000},{"price":3452.96,"qty":1.07000000}],"checksum":1289763011,"timestamp":"2024-06-01T22:42:59.810660Z"}]}
{"channel":"book","type":"update","data":[{"symbol":"ETH/CHF","bids":[],"asks":[{"price":3451.52,"qty":2.08597775}],"checksum":1614769470,"timestamp":"2024-06-01T22:42:59.812601Z"}]}
{"channel":"book","type":"update","data":[{"symbol":"ETH/CHF","bids":[],"asks":[{"price":3450.95,"qty":2.02878116}],"checksum":3915987010,"timestamp":"2024-06-01T22:42:59.812673Z"}]}
{"channel":"book","type":"update","data":[{"symbol":"ETH/CHF","bids":[],"asks":[{"price":3450.93,"qty":2.00000000},{"price":3450.92,"qty":0.00918383}],"checksum":3332752233,"timestamp":"2024-06-01T22:42:59.950921Z"}]}
{"channel":"book","type":"update","data":[{"symbol":"ETH/CHF","bids":[],"asks":[{"price":3451.52,"qty":0.08597775}],"checksum":4275695479,"timestamp":"2024-06-01T22:42:59.955900Z"}]}
{"channel":"book","type":"update","data":[{"symbol":"ETH/CHF","bids":[{"price":3448.98,"qty":0.00000000},{"price":3442.91,"qty":1.66000000}],"asks":[],"checksum":3240649035,"timestamp":"2024-06-01T22:43:00.337099Z"}]}
{"channel":"book","type":"update","data":[{"symbol":"ETH/CHF","bids":[{"price":3449.00,"qty":0.02565294}],"asks":[],"checksum":1549390217,"timestamp":"2024-06-01T22:43:00.339441Z"}]}
{"channel":"book","type":"update","data":[{"symbol":"ETH/CHF","bids":[{"price":3448.99,"qty":0.00000000},{"price":3442.91,"qty":1.66000000},{"price":3448.97,"qty":0.85084251}],"asks":[],"checksum":2013996341,"timestamp":"2024-06-01T22:43:00.383826Z"}]}
{"channel":"book","type":"update","data":[{"symbol":"ETH/CHF","bids":[{"price":3448.97,"qty":0.00000000},{"price":3442.91,"qty":1.66000000},{"price":3449.01,"qty":0.85083265}],"asks":[],"checksum":2656839213,"timestamp":"2024-06-01T22:43:00.534113Z"}]}
{"channel":"book","type":"update","data":[{"symbol":"ETH/CHF","bids":[{"price":3444.77,"qty":0.00000000},{"price":3442.91,"qty":1.66000000}],"asks":[],"checksum":845562686,"timestamp":"2024-06-01T22:43:00.887088Z"}]}
{"channel":"book","type":"update","data":[{"symbol":"ETH/CHF","bids":[{"price":3444.79,"qty":6.14240013}],"asks":[],"checksum":3523829229,"timestamp":"2024-06-01T22:43:00.888398Z"}]}
{"channel":"book","type":"update","data":[{"symbol":"ETH/CHF","bids":[{"price":3444.78,"qty":0.00000000},{"price":3442.91,"qty":1.66000000}],"asks":[],"checksum":3835348968,"timestamp":"2024-06-01T22:43:00.915787Z"}]}
{"channel":"book","type":"update","data":[{"symbol":"ETH/CHF","bids":[{"price":3444.80,"qty":2.99813319}],"asks":[],"checksum":2173878992,"timestamp":"2024-06-01T22:43:00.916035Z"}]}
{"channel":"book","type":"update","data":[{"symbol":"ETH/CHF","bids":[],"asks":[{"price":3450.94,"qty":0.00000000},{"price":3452.96,"qty":1.07000000}],"checksum":1548707861,"timestamp":"2024-06-01T22:43:01.976361Z"}]}
{"channel":"book","type":"update","data":[{"symbol":"ETH/CHF","bids":[],"asks":[{"price":3451.53,"qty":0.00000000},{"price":3453.24,"qty":2.58000000}],"checksum":676164281,"timestamp":"2024-06-01T22:43:01.976424Z"}]}
{"channel":"book","type":"update","data":[{"symbol":"ETH/CHF","bids":[],"asks":[{"price":3450.95,"qty":0.00830798}],"checksum":1802229207,"timestamp":"2024-06-01T22:43:01.976515Z"}]}
{"channel":"book","type":"update","data":[{"symbol":"ETH/CHF","bids":[],"asks":[{"price":3451.55,"qty":22.97691807}],"checksum":2877169623,"timestamp":"2024-06-01T22:43:01.981441Z"}]}
{"channel":"book","type":"update","data":[{"symbol":"ETH/CHF","bids":[],"asks":[{"price":3450.92,"qty":2.02965701}],"checksum":3055455649,"timestamp":"2024-06-01T22:43:01.981468Z"}]}
{"channel":"book","type":"update","data":[{"symbol":"ETH/CHF","bids":[],"asks":[{"price":3450.94,"qty":2.00000000}],"checksum":2022131187,"timestamp":"2024-06-01T22:43:01.983539Z"}]}
{"channel":"book","type":"update","data":[{"symbol":"ETH/CHF","bids":[],"asks":[{"price":3450.93,"qty":0.00000000},{"price":3452.96,"qty":1.07000000}],"checksum":154893018,"timestamp":"2024-06-01T22:43:01.983614Z"}]}
{"channel":"book","type":"update","data":[{"symbol":"ETH/CHF","bids":[],"asks":[{"price":3450.92,"qty":2.02047318},{"price":3450.91,"qty":0.00918397}],"checksum":1559857335,"timestamp":"2024-06-01T22:43:02.034632Z"}]}
{"channel":"book","type":"update","data":[{"symbol":"ETH/CHF","bids":[],"asks":[{"price":3450.91,"qty":2.00918397}],"checksum":275069423,"timestamp":"2024-06-01T22:43:02.040509Z"}]}
{"channel":"book","type":"update","data":[{"symbol":"ETH/CHF","bids":[],"asks":[{"price":3450.94,"qty":0.00000000},{"price":3452.96,"qty":1.07000000}],"checksum":3741118909,"timestamp":"2024-06-01T22:43:02.143166Z"}]}
{"channel":"book","type":"update","data":[{"symbol":"ETH/CHF","bids":[],"asks":[{"price":3450.91,"qty":2.00000000},{"price":3450.90,"qty":0.00918397}],"checksum":2220104379,"timestamp":"2024-06-01T22:43:02.184249Z"}]}
{"channel":"book","type":"update","data":[{"symbol":"ETH/CHF","bids":[],"asks":[{"price":3451.52,"qty":0.00000000},{"price":3452.96,"qty":1.07000000}],"checksum":923404228,"timestamp":"2024-06-01T22:43:02.522492Z"}]}
{"channel":"book","type":"update","data":[{"symbol":"ETH/CHF","bids":[],"asks":[{"price":3450.95,"qty":0.00000000},{"price":3453.24,"qty":2.58000000}],"checksum":2495744127,"timestamp":"2024-06-01T22:43:02.522581Z"}]}
{"channel":"book","type":"update","data":[{"symbol":"ETH/CHF","bids":[],"asks":[{"price":3451.54,"qty":0.08923950}],"checksum":2670087236,"timestamp":"2024-06-01T22:43:02.524351Z"}]}
{"channel":"book","type":"update","data":[{"symbol":"ETH/CHF","bids":[{"price":3449.00,"qty":0.00000000},{"price":3442.91,"qty":1.66000000}],"asks":[],"checksum":1535441037,"timestamp":"2024-06-01T22:43:02.863125Z"}]}
{"channel":"book","type":"update","data":[{"symbol":"ETH/CHF","bids":[{"price":3449.02,"qty":0.02055989}],"asks":[],"checksum":3303165966,"timestamp":"2024-06-01T22:43:02.864549Z"}]}
{"channel":"book","type":"update","data":[{"symbol":"ETH/CHF","bids":[{"price":3444.81,"qty":0.01527915}],"asks":[],"checksum":3897947648,"timestamp":"2024-06-01T22:43:02.864572Z"}]}
{"channel":"book","type":"update","data":[{"symbol":"ETH/CHF","bids":[],"asks":[{"price":3451.56,"qty":0.00000000},{"price":3453.24,"qty":2.58000000}],"checksum":2663526255,"timestamp":"2024-06-01T22:43:02.867765Z"}]}
{"channel":"book","type":"update","data":[{"symbol":"ETH/CHF","bids":[],"asks":[{"price":3451.55,"qty":36.88576642}],"checksum":28964730,"timestamp":"2024-06-01T22:43:02.871231Z"}]}
{"channel":"book","type":"update","data":[{"symbol":"ETH/CHF","bids":[{"price":3449.01,"qty":0.00000000},{"price":3444.14,"qty":0.96000000},{"price":3448.97,"qty":0.85083625}],"asks":[],"checksum":1673843920,"timestamp":"2024-06-01T22:43:02.925771Z"}]}
{"channel":"book","type":"update","data":[{"symbol":"ETH/CHF","bids":[{"price":3444.79,"qty":0.00000000},{"price":3444.14,"qty":0.96000000}],"asks":[],"checksum":282617085,"timestamp":"2024-06-01T22:43:03.022702Z"}]}
{"channel":"book","type":"update","data":[{"symbol":"ETH/CHF","bids":[{"price":3444.81,"qty":6.15767928}],"asks":[],"checksum":2629640044,"timestamp":"2024-06-01T22:43:03.023758Z"}]}
{"channel":"book","type":"update","data":[{"symbol":"ETH/CHF","bids":[{"price":3444.80,"qty":0.00000000},{"price":3442.91,"qty":1.66000000}],"asks":[],"checksum":2009292476,"timestamp":"2024-06-01T22:43:03.028600Z"}]}
{"channel":"book","type":"update","data":[{"symbol":"ETH/CHF","bids":[{"price":3444.82,"qty":2.99811578}],"asks":[],"checksum":3846140426,"timestamp":"2024-06-01T22:43:03.028971Z"}]}
{"channel":"book","type":"update","data":[{"symbol":"ETH/CHF","bids":[{"price":3448.97,"qty":0.00000000},{"price":3442.91,"qty":1.66000000},{"price":3449.03,"qty":0.85082145}],"asks":[],"checksum":841313617,"timestamp":"2024-06-01T22:43:03.062742Z"}]}
{"channel":"book","type":"update","data":[{"symbol":"ETH/CHF","bids":[],"asks":[{"price":3451.55,"qty":22.97691807}],"checksum":1600647778,"timestamp":"2024-06-01T22:43:04.565239Z"}]}
{"channel":"book","type":"update","data":[{"symbol":"ETH/CHF","bids":[],"asks":[{"price":3451.67,"qty":13.90308051}],"checksum":828768387,"timestamp":"2024-06-01T22:43:04.570606Z"}]}
{"channel":"book","type":"update","data":[{"symbol":"ETH/CHF","bids":[],"asks":[{"price":3451.67,"qty":0.00000000},{"price":3453.24,"qty":2.58000000}],"checksum":1600647778,"timestamp":"2024-06-01T22:43:04.572645Z"}]}
{"channel":"book","type":"update","data":[{"symbol":"ETH/CHF","bids":[],"asks":[{"price":3451.68,"qty":13.90882818}],"checksum":2586435043,"timestamp":"2024-06-01T22:43:04.578049Z"}]}
{"channel":"book","type":"update","data":[{"symbol":"ETH/CHF","bids":[],"asks":[{"price":3450.91,"qty":0.00000000},{"price":3453.24,"qty":2.58000000}],"checksum":3410141501,"timestamp":"2024-06-01T22:43:04.591763Z"}]}
{"channel":"book","type":"update","data":[{"symbol":"ETH/CHF","bids":[],"asks":[{"price":3451.68,"qty":0.00000000},{"price":3453.27,"qty":2.53000000}],"checksum":2409181758,"timestamp":"2024-06-01T22:43:04.592060Z"}]}
{"channel":"book","type":"update","data":[{"symbol":"ETH/CHF","bids":[],"asks":[{"price":3451.86,"qty":13.90882818}],"checksum":3030456356,"timestamp":"2024-06-01T22:43:04.596418Z"}]}
{"channel":"book","type":"update","data":[{"symbol":"ETH/CHF","bids":[{"price":3447.95,"qty":2.00000000}],"asks":[],"checksum":900628476,"timestamp":"2024-06-01T22:43:04.598511Z"}]}
{"channel":"book","type":"update","data":[{"symbol":"ETH/CHF","bids":[],"asks":[{"price":3450.90,"qty":0.00000000},{"price":3453.27,"qty":2.53000000},{"price":3450.91,"qty":0.00918417}],"checksum":1224958080,"timestamp":"2024-06-01T22:43:04.625237Z"}]}
{"channel":"book","type":"update","data":[{"symbol":"ETH/CHF","bids":[{"price":3447.50,"qty":0.00000000},{"price":3444.14,"qty":0.96000000}],"asks":[],"checksum":2855897071,"timestamp":"2024-06-01T22:43:04.631239Z"}]}
{"channel":"book","type":"update","data":[{"symbol":"ETH/CHF","bids":[],"asks":[{"price":3451.54,"qty":0.00000000},{"price":3453.27,"qty":2.53000000}],"checksum":3203423908,"timestamp":"2024-06-01T22:43:04.737036Z"}]}
{"channel":"book","type":"update","data":[{"symbol":"ETH/CHF","bids":[],"asks":[{"price":3451.42,"qty":2.00000000}],"checksum":4115755943,"timestamp":"2024-06-01T22:43:04.742762Z"}]}
{"channel":"book","type":"update","data":[{"symbol":"ETH/CHF","bids":[],"asks":[{"price":3451.45,"qty":0.00000000},{"price":3453.27,"qty":2.53000000},{"price":3451.73,"qty":0.06629600}],"checksum":27160652,"timestamp":"2024-06-01T22:43:04.761857Z"}]}
{"channel":"book","type":"update","data":[{"symbol":"ETH/CHF","bids":[{"price":3449.02,"qty":0.00000000},{"price":3442.91,"qty":1.66000000}],"asks":[],"checksum":955988668,"timestamp":"2024-06-01T22:43:05.384502Z"}]}
{"channel":"book","type":"update","data":[{"symbol":"ETH/CHF","bids":[{"price":3444.81,"qty":6.14240013}],"asks":[],"checksum":569961976,"timestamp":"2024-06-01T22:43:05.384585Z"}]}
{"channel":"book","type":"update","data":[{"symbol":"ETH/CHF","bids":[{"price":3449.04,"qty":0.03205008}],"asks":[],"checksum":2382794797,"timestamp":"2024-06-01T22:43:05.385957Z"}]}
{"channel":"book","type":"update","data":[{"symbol":"ETH/CHF","bids":[{"price":3449.03,"qty":0.00000000},{"price":3442.91,"qty":1.66000000},{"price":3448.97,"qty":0.85083877}],"asks":[],"checksum":3003538508,"timestamp":"2024-06-01T22:43:05.408960Z"}]}
{"channel":"book","type":"update","data":[{"symbol":"ETH/CHF","bids":[{"price":3448.97,"qty":0.00000000},{"price":3442.91,"qty":1.66000000},{"price":3449.05,"qty":0.85081903}],"asks":[],"checksum":3284706927,"timestamp":"2024-06-01T22:43:05.502491Z"}]}
{"channel":"book","type":"update","data":[{"symbol":"ETH/CHF","bids":[],"asks":[{"price":3451.55,"qty":0.00000000},{"price":3453.27,"qty":2.53000000}],"checksum":2266954391,"timestamp":"2024-06-01T22:43:06.743709Z"}]}
{"channel":"book","type":"update","data":[{"symbol":"ETH/CHF","bids":[],"asks":[{"price":3450.92,"qty":0.00000000},{"price":3453.34,"qty":0.10500000}],"checksum":137611260,"timestamp":"2024-06-01T22:43:06.743748Z"}]}
{"channel":"book","type":"update","data":[{"symbol":"ETH/CHF","bids":[],"asks":[{"price":3451.41,"qty":3.01835281}],"checksum":1726542494,"timestamp":"2024-06-01T22:43:06.749353Z"}]}
{"channel":"book","type":"update","data":[{"symbol":"ETH/CHF","bids":[],"asks":[{"price":3451.85,"qty":23.97479866}],"checksum":39952432,"timestamp":"2024-06-01T22:43:06.749800Z"}]}
{"channel":"book","type":"update","data":[{"symbol":"ETH/CHF","bids":[],"asks":[{"price":3451.42,"qty":0.00000000},{"price":3453.27,"qty":2.53000000}],"checksum":1541090140,"timestamp":"2024-06-01T22:43:06.750995Z"}]}
{"channel":"book","type":"update","data":[{"symbol":"ETH/CHF","bids":[],"asks":[{"price":3451.85,"qty":25.97479866}],"checksum":2265716403,"timestamp":"2024-06-01T22:43:06.751070Z"}]}
{"channel":"book","type":"update","data":[{"symbol":"ETH/CHF","bids":[],"asks":[{"price":3450.91,"qty":0.00000000},{"price":3453.34,"qty":0.10500000},{"price":3451.40,"qty":0.00918435}],"checksum":2911622622,"timestamp":"2024-06-01T22:43:06.780663Z"}]}
{"channel":"book","type":"update","data":[{"symbol":"ETH/CHF","bids":[],"asks":[{"price":3451.40,"qty":2.00918435}],"checksum":2369207540,"timestamp":"2024-06-01T22:43:06.786910Z"}]}
{"channel":"book","type":"update","data":[{"symbol":"ETH/CHF","bids":[],"asks":[{"price":3451.40,"qty":2.00000000},{"price":3451.39,"qty":0.00918435}],"checksum":2116281834,"timestamp":"2024-06-01T22:43:06.824993Z"}]}
{"channel":"book","type":"update","data":[{"symbol":"ETH/CHF","bids":[],"asks":[{"price":3451.85,"qty":23.97479866}],"checksum":3259610985,"timestamp":"2024-06-01T22:43:06.830227Z"}]}
{"channel":"book","type":"update","data":[{"symbol":"ETH/CHF","bids":[],"asks":[{"price":3451.73,"qty":0.00000000},{"price":3453.27,"qty":2.53000000},{"price":3451.45,"qty":0.06630000}],"checksum":3399972943,"timestamp":"2024-06-01T22:43:06.920885Z"}]}
{"channel":"book","type":"update","data":[{"symbol":"ETH/CHF","bids":[{"price":3444.81,"qty":0.00000000},{"price":3442.91,"qty":1.66000000}],"asks":[],"checksum":3596123655,"timestamp":"2024-06-01T22:43:07.149912Z"}]}
{"channel":"book","type":"update","data":[{"symbol":"ETH/CHF","bids":[{"price":3444.83,"qty":6.14185543}],"asks":[],"checksum":2137019235,"timestamp":"2024-06-01T22:43:07.150788Z"}]}
{"channel":"book","type":"update","data":[{"symbol":"ETH/CHF","bids":[{"price":3444.68,"qty":2.99823765}],"asks":[],"checksum":2661419214,"timestamp":"2024-06-01T22:43:07.153370Z"}]}
{"channel":"book","type":"update","data":[{"symbol":"ETH/CHF","bids":[{"price":3444.82,"qty":0.00000000},{"price":3444.14,"qty":0.96000000}],"asks":[],"checksum":3040201905,"timestamp":"2024-06-01T22:43:07.153416Z"}]}
{"channel":"book","type":"update","data":[{"symbol":"ETH/CHF","bids":[{"price":3444.84,"qty":2.99809839}],"asks":[],"checksum":1577601811,"timestamp":"2024-06-01T22:43:07.175275Z"}]}
{"channel":"book","type":"update","data":[{"symbol":"ETH/CHF","bids":[{"price":3444.68,"qty":0.00000000},{"price":3444.14,"qty":0.96000000}],"asks":[],"checksum":1867457308,"timestamp":"2024-06-01T22:43:07.175404Z"}]}
{"channel":"book","type":"update","data":[{"symbol":"ETH/CHF","bids":[{"price":3448.86,"qty":0.00000000},{"price":3442.91,"qty":1.66000000},{"price":3449.06,"qty":0.06633800}],"asks":[],"checksum":2716600196,"timestamp":"2024-06-01T22:43:07.266701Z"}]}
{"channel":"book","type":"update","data":[{"symbol":"ETH/CHF","bids":[{"price":3449.05,"qty":0.00000000},{"price":3442.91,"qty":1.66000000},{"price":3449.07,"qty":0.85080761}],"asks":[],"checksum":1870270077,"timestamp":"2024-06-01T22:43:07.337496Z"}]}
{"channel":"book","type":"update","data":[{"symbol":"ETH/CHF","bids":[{"price":3449.04,"qty":0.00000000},{"price":3442.91,"qty":1.66000000}],"asks":[],"checksum":3286926667,"timestamp":"2024-06-01T22:43:07.879623Z"}]}
{"channel":"book","type":"update","data":[{"symbol":"ETH/CHF","bids":[{"price":3449.08,"qty":0.02821934}],"asks":[],"checksum":3290740806,"timestamp":"2024-06-01T22:43:07.881067Z"}]}
{"channel":"book","type":"update","data":[{"symbol":"ETH/CHF","bids":[{"price":3449.07,"qty":0.00000000},{"price":3442.91,"qty":1.66000000},{"price":3449.09,"qty":0.85080255}],"asks":[],"checksum":2672985012,"timestamp":"2024-06-01T22:43:07.932526Z"}]}
{"channel":"book","type":"update","data":[{"symbol":"ETH/CHF","bids":[],"asks":[{"price":3451.39,"qty":0.02670825}],"checksum":1544035277,"timestamp":"2024-06-01T22:43:08.223550Z"}]}
{"channel":"book","type":"update","data":[{"symbol":"ETH/CHF","bids":[],"asks":[{"price":3451.84,"qty":0.06960304}],"checksum":1011563735,"timestamp":"2024-06-01T22:43:08.223591Z"}]}
{"channel":"book","type":"update","data":[{"symbol":"ETH/CHF","bids":[],"asks":[{"price":3451.39,"qty":0.01752390},{"price":3451.38,"qty":0.00918436}],"checksum":1128551919,"timestamp":"2024-06-01T22:43:08.291182Z"}]}
{"channel":"book","type":"update","data":[{"symbol":"ETH/CHF","bids":[],"asks":[{"price":3451.41,"qty":0.00000000},{"price":3452.96,"qty":1.07000000}],"checksum":2955075081,"timestamp":"2024-06-01T22:43:08.859283Z"}]}
{"channel":"book","type":"update","data":[{"symbol":"ETH/CHF","bids":[],"asks":[{"price":3451.85,"qty":0.00000000},{"price":3453.24,"qty":2.58000000}],"checksum":3293226724,"timestamp":"2024-06-01T22:43:08.859514Z"}]}
{"channel":"book","type":"update","data":[{"symbol":"ETH/CHF","bids":[],"asks":[{"price":3451.39,"qty":31.89490966}],"checksum":4107916484,"timestamp":"2024-06-01T22:43:08.865214Z"}]}
{"channel":"book","type":"update","data":[{"symbol":"ETH/CHF","bids":[],"asks":[{"price":3451.37,"qty":0.52353658}],"checksum":1057308842,"timestamp":"2024-06-01T22:43:08.865236Z"}]}
{"channel":"book","type":"update","data":[{"symbol":"ETH/CHF","bids":[],"asks":[{"price":3451.38,"qty":1.53064693}],"checksum":1587739816,"timestamp":"2024-06-01T22:43:08.865257Z"}]}
{"channel":"book","type":"update","data":[{"symbol":"ETH/CHF","bids":[],"asks":[{"price":3451.40,"qty":0.00000000},{"price":3453.24,"qty":2.58000000}],"checksum":766979811,"timestamp":"2024-06-01T22:43:08.865833Z"}]}
{"channel":"book","type":"update","data":[{"symbol":"ETH/CHF","bids":[],"asks":[{"price":3451.38,"qty":1.52146257},{"price":3451.36,"qty":0.00918434}],"checksum":954671374,"timestamp":"2024-06-01T22:43:08.919597Z"}]}
{"channel":"book","type":"update","data":[{"symbol":"ETH/CHF","bids":[],"asks":[{"price":3451.36,"qty":2.00918434}],"checksum":2184548767,"timestamp":"2024-06-01T22:43:08.925097Z"}]}
{"channel":"book","type":"update","data":[{"symbol":"ETH/CHF","bids":[],"asks":[{"price":3451.45,"qty":0.00000000},{"price":3453.24,"qty":2.58000000},{"price":3451.80,"qty":0.06629600}],"checksum":560130937,"timestamp":"2024-06-01T22:43:08.935619Z"}]}
{"channel":"book","type":"update","data":[{"symbol":"ETH/CHF","bids":[],"asks":[{"price":3451.36,"qty":2.00000000},{"price":3451.35,"qty":0.00918434}],"checksum":26440675,"timestamp":"2024-06-01T22:43:08.953686Z"}]}
{"channel":"book","type":"update","data":[{"symbol":"ETH/CHF","bids":[{"price":3444.83,"qty":0.00000000},{"price":3442.91,"qty":1.66000000}],"asks":[],"checksum":2137948764,"timestamp":"2024-06-01T22:43:09.245704Z"}]}
{"channel":"book","type":"update","data":[{"symbol":"ETH/CHF","bids":[{"price":3449.10,"qty":0.52351305}],"asks":[],"checksum":1860852569,"timestamp":"2024-06-01T22:43:09.246450Z"}]}
