{"channel":"book","type":"snapshot","data":[{"symbol":"ETH/GBP","bids":[{"price":2996.24,"qty":0.08528100},{"price":2996.15,"qty":13.09252170},{"price":2995.74,"qty":0.31000000},{"price":2995.69,"qty":7.81937086},{"price":2995.41,"qty":1.30957825},{"price":2994.63,"qty":1.30991734},{"price":2993.91,"qty":1.31023505},{"price":2993.78,"qty":0.27600000},{"price":2993.38,"qty":1.33100000},{"price":2993.37,"qty":0.27311159}],"asks":[{"price":2996.75,"qty":1.52150747},{"price":2996.82,"qty":0.08527300},{"price":2997.03,"qty":0.31000000},{"price":2997.09,"qty":13.08845698},{"price":2997.74,"qty":1.30856180},{"price":2998.26,"qty":0.90569250},{"price":2998.33,"qty":1.30830411},{"price":2998.78,"qty":0.27306760},{"price":2998.90,"qty":28.91159097},{"price":2998.91,"qty":9.61753147}],"checksum":3497401144}]}
{"channel":"book","type":"update","data":[{"symbol":"ETH/GBP","bids":[],"asks":[{"price":2996.69,"qty":6.54510146}],"checksum":3292171728,"timestamp":"2024-06-01T22:42:36.490712Z"}]}
{"channel":"book","type":"update","data":[{"symbol":"ETH/GBP","bids":[{"price":2996.52,"qty":6.54545422}],"asks":[],"checksum":62805921,"timestamp":"2024-06-01T22:42:36.490834Z"}]}
{"channel":"book","type":"update","data":[{"symbol":"ETH/GBP","bids":[],"asks":[{"price":2996.69,"qty":0.00000000},{"price":2998.91,"qty":9.61753147}],"checksum":2910548349,"timestamp":"2024-06-01T22:42:36.566239Z"}]}
{"channel":"book","type":"update","data":[{"symbol":"ETH/GBP","bids":[{"price":2996.52,"qty":0.00000000},{"price":2993.37,"qty":0.27311159}],"asks":[],"checksum":3497401144,"timestamp":"2024-06-01T22:42:36.566278Z"}]}
{"channel":"book","type":"update","data":[{"symbol":"ETH/GBP","bids":[],"asks":[{"price":2996.69,"qty":6.54509800}],"checksum":961532174,"timestamp":"2024-06-01T22:42:36.625353Z"}]}
{"channel":"book","type":"update","data":[{"symbol":"ETH/GBP","bids":[{"price":2996.53,"qty":6.54542869}],"asks":[],"checksum":3040183033,"timestamp":"2024-06-01T22:42:36.625411Z"}]}
{"channel":"book","type":"update","data":[{"symbol":"ETH/GBP","bids":[{"price":2996.53,"qty":0.00000000},{"price":2993.37,"qty":0.27311159}],"asks":[],"checksum":961532174,"timestamp":"2024-06-01T22:42:36.775161Z"}]}
{"channel":"book","type":"update","data":[{"symbol":"ETH/GBP","bids":[],"asks":[{"price":2996.69,"qty":0.00000000},{"price":2998.91,"qty":9.61753147}],"checksum":3497401144,"timestamp":"2024-06-01T22:42:36.775249Z"}]}
{"channel":"book","type":"update","data":[{"symbol":"ETH/GBP","bids":[{"price":2996.51,"qty":6.54547255}],"asks":[],"checksum":2762802908,"timestamp":"2024-06-01T22:42:36.780751Z"}]}
{"channel":"book","type":"update","data":[{"symbol":"ETH/GBP","bids":[],"asks":[{"price":2996.68,"qty":6.54512224}],"checksum":3781857182,"timestamp":"2024-06-01T22:42:36.780765Z"}]}
{"channel":"book","type":"update","data":[{"symbol":"ETH/GBP","bids":[{"price":2996.51,"qty":0.00000000},{"price":2993.37,"qty":0.27311159}],"asks":[],"checksum":3366136853,"timestamp":"2024-06-01T22:42:36.787297Z"}]}
{"channel":"book","type":"update","data":[{"symbol":"ETH/GBP","bids":[{"price":2996.51,"qty":6.54547124}],"asks":[],"checksum":2957892490,"timestamp":"2024-06-01T22:42:36.898455Z"}]}
{"channel":"book","type":"update","data":[{"symbol":"ETH/GBP","bids":[],"asks":[{"price":2996.68,"qty":0.00000000},{"price":2998.91,"qty":9.61753147}],"checksum":4119483080,"timestamp":"2024-06-01T22:42:36.917450Z"}]}
{"channel":"book","type":"update","data":[{"symbol":"ETH/GBP","bids":[{"price":2996.51,"qty":0.00000000},{"price":2993.37,"qty":0.27311159}],"asks":[],"checksum":3497401144,"timestamp":"2024-06-01T22:42:36.917589Z"}]}
{"channel":"book","type":"update","data":[{"symbol":"ETH/GBP","bids":[],"asks":[{"price":2996.73,"qty":6.54502195}],"checksum":1013172744,"timestamp":"2024-06-01T22:42:36.923147Z"}]}
{"channel":"book","type":"update","data":[{"symbol":"ETH/GBP","bids":[],"asks":[{"price":2996.73,"qty":0.00000000},{"price":2998.91,"qty":9.61753147}],"checksum":3497401144,"timestamp":"2024-06-01T22:42:36.991178Z"}]}
{"channel":"book","type":"update","data":[{"symbol":"ETH/GBP","bids":[{"price":2996.25,"qty":6.54605913}],"asks":[],"checksum":3264395270,"timestamp":"2024-06-01T22:42:37.076719Z"}]}
{"channel":"book","type":"update","data":[{"symbol":"ETH/GBP","bids":[],"asks":[{"price":2996.72,"qty":6.54505403}],"checksum":344591408,"timestamp":"2024-06-01T22:42:37.076949Z"}]}
{"channel":"book","type":"update","data":[{"symbol":"ETH/GBP","bids":[{"price":2996.25,"qty":0.00000000},{"price":2993.37,"qty":0.27311159}],"asks":[],"checksum":509724056,"timestamp":"2024-06-01T22:42:37.082471Z"}]}
{"channel":"book","type":"update","data":[{"symbol":"ETH/GBP","bids":[],"asks":[{"price":2996.75,"qty":0.00000000},{"price":2998.91,"qty":9.61753147}],"checksum":3607276739,"timestamp":"2024-06-01T22:42:37.112795Z"}]}
{"channel":"book","type":"update","data":[{"symbol":"ETH/GBP","bids":[],"asks":[{"price":2998.90,"qty":0.00000000},{"price":2999.00,"qty":1.00000000}],"checksum":2856296148,"timestamp":"2024-06-01T22:42:37.113090Z"}]}
{"channel":"book","type":"update","data":[{"symbol":"ETH/GBP","bids":[],"asks":[{"price":2998.90,"qty":21.48002647}],"checksum":1369897952,"timestamp":"2024-06-01T22:42:37.118339Z"}]}
{"channel":"book","type":"update","data":[{"symbol":"ETH/GBP","bids":[],"asks":[{"price":2996.72,"qty":0.00000000},{"price":2999.00,"qty":1.00000000}],"checksum":1394627044,"timestamp":"2024-06-01T22:42:37.132879Z"}]}
{"channel":"book","type":"update","data":[{"symbol":"ETH/GBP","bids":[{"price":2996.55,"qty":6.54539072}],"asks":[],"checksum":3858353015,"timestamp":"2024-06-01T22:42:37.183789Z"}]}
{"channel":"book","type":"update","data":[{"symbol":"ETH/GBP","bids":[],"asks":[{"price":2996.72,"qty":6.54503832}],"checksum":2483282627,"timestamp":"2024-06-01T22:42:37.183821Z"}]}
{"channel":"book","type":"update","data":[{"symbol":"ETH/GBP","bids":[],"asks":[{"price":2996.72,"qty":0.00000000},{"price":2999.00,"qty":1.00000000}],"checksum":3858353015,"timestamp":"2024-06-01T22:42:37.188695Z"}]}
{"channel":"book","type":"update","data":[{"symbol":"ETH/GBP","bids":[{"price":2996.55,"qty":0.00000000},{"price":2993.37,"qty":0.27311159}],"asks":[],"checksum":1394627044,"timestamp":"2024-06-01T22:42:37.188712Z"}]}
{"channel":"book","type":"update","data":[{"symbol":"ETH/GBP","bids":[],"asks":[{"price":2997.09,"qty":0.00000000},{"price":2999.31,"qty":1.33100000}],"checksum":388108170,"timestamp":"2024-06-01T22:42:37.232630Z"}]}
{"channel":"book","type":"update","data":[{"symbol":"ETH/GBP","bids":[],"asks":[{"price":2997.03,"qty":0.00000000},{"price":2999.32,"qty":1.30787255}],"checksum":4156367472,"timestamp":"2024-06-01T22:42:37.235287Z"}]}
{"channel":"book","type":"update","data":[{"symbol":"ETH/GBP","bids":[],"asks":[{"price":2997.66,"qty":0.31000000}],"checksum":3158567099,"timestamp":"2024-06-01T22:42:37.235583Z"}]}
{"channel":"book","type":"update","data":[{"symbol":"ETH/GBP","bids":[],"asks":[{"price":2997.04,"qty":13.08868634}],"checksum":1649664334,"timestamp":"2024-06-01T22:42:37.236693Z"}]}
{"channel":"book","type":"update","data":[{"symbol":"ETH/GBP","bids":[],"asks":[{"price":2996.81,"qty":6.54483589}],"checksum":2915953510,"timestamp":"2024-06-01T22:42:37.283114Z"}]}
{"channel":"book","type":"update","data":[{"symbol":"ETH/GBP","bids":[{"price":2996.50,"qty":6.54550724}],"asks":[],"checksum":2012191015,"timestamp":"2024-06-01T22:42:37.283256Z"}]}
{"channel":"book","type":"update","data":[{"symbol":"ETH/GBP","bids":[],"asks":[{"price":2996.81,"qty":0.00000000},{"price":2999.00,"qty":1.00000000}],"checksum":1117106135,"timestamp":"2024-06-01T22:42:37.287899Z"}]}
{"channel":"book","type":"update","data":[{"symbol":"ETH/GBP","bids":[{"price":2996.50,"qty":0.00000000},{"price":2993.37,"qty":0.27311159}],"asks":[],"checksum":1649664334,"timestamp":"2024-06-01T22:42:37.323779Z"}]}
{"channel":"book","type":"update","data":[{"symbol":"ETH/GBP","bids":[],"asks":[{"price":2996.67,"qty":6.54516334}],"checksum":2711958706,"timestamp":"2024-06-01T22:42:37.390770Z"}]}
{"channel":"book","type":"update","data":[{"symbol":"ETH/GBP","bids":[{"price":2996.25,"qty":6.54605913}],"asks":[],"checksum":3482190103,"timestamp":"2024-06-01T22:42:37.390815Z"}]}
{"channel":"book","type":"update","data":[{"symbol":"ETH/GBP","bids":[{"price":2996.25,"qty":0.00000000},{"price":2993.37,"qty":0.27311159}],"asks":[],"checksum":2711958706,"timestamp":"2024-06-01T22:42:37.395572Z"}]}
{"channel":"book","type":"update","data":[{"symbol":"ETH/GBP","bids":[{"price":2996.52,"qty":6.54546746}],"asks":[],"checksum":544387718,"timestamp":"2024-06-01T22:42:37.580854Z"}]}
{"channel":"book","type":"update","data":[{"symbol":"ETH/GBP","bids":[],"asks":[{"price":2996.67,"qty":0.00000000},{"price":2999.00,"qty":1.00000000}],"checksum":2495281764,"timestamp":"2024-06-01T22:42:37.683168Z"}]}
{"channel":"book","type":"update","data":[{"symbol":"ETH/GBP","bids":[{"price":2995.69,"qty":0.00000000},{"price":2993.37,"qty":0.27311159}],"asks":[],"checksum":3347485938,"timestamp":"2024-06-01T22:42:37.686390Z"}]}
{"channel":"book","type":"update","data":[{"symbol":"ETH/GBP","bids":[],"asks":[{"price":2996.69,"qty":6.54511377}],"checksum":2059635689,"timestamp":"2024-06-01T22:42:37.688024Z"}]}
{"channel":"book","type":"update","data":[{"symbol":"ETH/GBP","bids":[{"price":2995.84,"qty":7.81897934}],"asks":[],"checksum":1538955123,"timestamp":"2024-06-01T22:42:37.689653Z"}]}
{"channel":"book","type":"update","data":[{"symbol":"ETH/GBP","bids":[{"price":2996.52,"qty":0.00000000},{"price":2993.37,"qty":0.27311159}],"asks":[],"checksum":1203028470,"timestamp":"2024-06-01T22:42:37.765971Z"}]}
{"channel":"book","type":"update","data":[{"symbol":"ETH/GBP","bids":[{"price":2996.53,"qty":6.54543014}],"asks":[],"checksum":4028463159,"timestamp":"2024-06-01T22:42:37.771170Z"}]}
{"channel":"book","type":"update","data":[{"symbol":"ETH/GBP","bids":[{"price":2996.53,"qty":0.00000000},{"price":2993.37,"qty":0.27311159}],"asks":[],"checksum":1203028470,"timestamp":"2024-06-01T22:42:37.905322Z"}]}
{"channel":"book","type":"update","data":[{"symbol":"ETH/GBP","bids":[],"asks":[{"price":2996.69,"qty":0.00000000},{"price":2999.00,"qty":1.00000000}],"checksum":4210155245,"timestamp":"2024-06-01T22:42:37.905415Z"}]}
{"channel":"book","type":"update","data":[{"symbol":"ETH/GBP","bids":[],"asks":[{"price":2996.68,"qty":6.54513155}],"checksum":1171223308,"timestamp":"2024-06-01T22:42:37.910538Z"}]}
{"channel":"book","type":"update","data":[{"symbol":"ETH/GBP","bids":[{"price":2996.52,"qty":6.54546821}],"asks":[],"checksum":1269947563,"timestamp":"2024-06-01T22:42:37.910577Z"}]}
{"channel":"book","type":"update","data":[{"symbol":"ETH/GBP","bids":[],"asks":[{"price":2996.68,"qty":0.00000000},{"price":2999.00,"qty":1.00000000}],"checksum":2617454824,"timestamp":"2024-06-01T22:42:38.420185Z"}]}
{"channel":"book","type":"update","data":[{"symbol":"ETH/GBP","bids":[{"price":2996.52,"qty":0.00000000},{"price":2993.37,"qty":0.27311159}],"asks":[],"checksum":4210155245,"timestamp":"2024-06-01T22:42:38.420363Z"}]}
{"channel":"book","type":"update","data":[{"symbol":"ETH/GBP","bids":[{"price":2996.49,"qty":6.54552385}],"asks":[],"checksum":2027700422,"timestamp":"2024-06-01T22:42:38.427526Z"}]}
{"channel":"book","type":"update","data":[{"symbol":"ETH/GBP","bids":[],"asks":[{"price":2996.66,"qty":6.54518344}],"checksum":993042788,"timestamp":"2024-06-01T22:42:38.427565Z"}]}
{"channel":"book","type":"update","data":[{"symbol":"ETH/GBP","bids":[{"price":2996.49,"qty":0.00000000},{"price":2993.37,"qty":0.27311159}],"asks":[],"checksum":2147030661,"timestamp":"2024-06-01T22:42:38.473758Z"}]}
{"channel":"book","type":"update","data":[{"symbol":"ETH/GBP","bids":[],"asks":[{"price":2996.66,"qty":0.00000000},{"price":2999.00,"qty":1.00000000}],"checksum":4210155245,"timestamp":"2024-06-01T22:42:38.488575Z"}]}
{"channel":"book","type":"update","data":[{"symbol":"ETH/GBP","bids":[],"asks":[{"price":2996.69,"qty":6.54511738}],"checksum":1695197060,"timestamp":"2024-06-01T22:42:38.530353Z"}]}
{"channel":"book","type":"update","data":[{"symbol":"ETH/GBP","bids":[{"price":2996.53,"qty":6.54544412}],"asks":[],"checksum":3625362297,"timestamp":"2024-06-01T22:42:38.530469Z"}]}
{"channel":"book","type":"update","data":[{"symbol":"ETH/GBP","bids":[],"asks":[{"price":2996.69,"qty":0.00000000},{"price":2999.00,"qty":1.00000000}],"checksum":3974595068,"timestamp":"2024-06-01T22:42:38.573846Z"}]}
{"channel":"book","type":"update","data":[{"symbol":"ETH/GBP","bids":[{"price":2996.53,"qty":0.00000000},{"price":2993.37,"qty":0.27311159}],"asks":[],"checksum":4210155245,"timestamp":"2024-06-01T22:42:38.663008Z"}]}
{"channel":"book","type":"update","data":[{"symbol":"ETH/GBP","bids":[],"asks":[{"price":2996.81,"qty":6.54483589}],"checksum":896521413,"timestamp":"2024-06-01T22:42:38.668760Z"}]}
{"channel":"book","type":"update","data":[{"symbol":"ETH/GBP","bids":[{"price":2996.51,"qty":6.54547423}],"asks":[],"checksum":4294773449,"timestamp":"2024-06-01T22:42:38.668883Z"}]}
{"channel":"book","type":"update","data":[{"symbol":"ETH/GBP","bids":[],"asks":[{"price":2996.81,"qty":0.00000000},{"price":2999.00,"qty":1.00000000}],"checksum":3397860409,"timestamp":"2024-06-01T22:42:38.673276Z"}]}
{"channel":"book","type":"update","data":[{"symbol":"ETH/GBP","bids":[{"price":2996.51,"qty":0.00000000},{"price":2993.37,"qty":0.27311159}],"asks":[],"checksum":4210155245,"timestamp":"2024-06-01T22:42:38.904513Z"}]}
{"channel":"book","type":"update","data":[{"symbol":"ETH/GBP","bids":[],"asks":[{"price":2996.81,"qty":6.54483589}],"checksum":896521413,"timestamp":"2024-06-01T22:42:38.910781Z"}]}
{"channel":"book","type":"update","data":[{"symbol":"ETH/GBP","bids":[{"price":2996.55,"qty":6.54539503}],"asks":[],"checksum":2805639718,"timestamp":"2024-06-01T22:42:38.910851Z"}]}
{"channel":"book","type":"update","data":[{"symbol":"ETH/GBP","bids":[{"price":2996.55,"qty":0.00000000},{"price":2993.37,"qty":0.27311159}],"asks":[],"checksum":896521413,"timestamp":"2024-06-01T22:42:38.916910Z"}]}
{"channel":"book","type":"update","data":[{"symbol":"ETH/GBP","bids":[],"asks":[{"price":2996.81,"qty":0.00000000},{"price":2999.00,"qty":1.00000000}],"checksum":4210155245,"timestamp":"2024-06-01T22:42:38.916926Z"}]}
{"channel":"book","type":"update","data":[{"symbol":"ETH/GBP","bids":[{"price":2996.25,"qty":6.54605913}],"asks":[],"checksum":1050585105,"timestamp":"2024-06-01T22:42:39.097794Z"}]}
{"channel":"book","type":"update","data":[{"symbol":"ETH/GBP","bids":[],"asks":[{"price":2996.69,"qty":6.54511010}],"checksum":2288524027,"timestamp":"2024-06-01T22:42:39.097818Z"}]}
{"channel":"book","type":"update","data":[{"symbol":"ETH/GBP","bids":[{"price":2996.25,"qty":0.00000000},{"price":2993.37,"qty":0.27311159}],"asks":[],"checksum":1785596370,"timestamp":"2024-06-01T22:42:39.102841Z"}]}
{"channel":"book","type":"update","data":[{"symbol":"ETH/GBP","bids":[],"asks":[{"price":2996.69,"qty":0.00000000},{"price":2999.00,"qty":1.00000000}],"checksum":4210155245,"timestamp":"2024-06-01T22:42:39.296553Z"}]}
{"channel":"book","type":"update","data":[{"symbol":"ETH/GBP","bids":[{"price":2996.52,"qty":6.54545518}],"asks":[],"checksum":2782436219,"timestamp":"2024-06-01T22:42:39.302667Z"}]}
{"channel":"book","type":"update","data":[{"symbol":"ETH/GBP","bids":[],"asks":[{"price":2996.68,"qty":6.54511992}],"checksum":1118394895,"timestamp":"2024-06-01T22:42:39.302732Z"}]}
{"channel":"book","type":"update","data":[{"symbol":"ETH/GBP","bids":[],"asks":[{"price":2996.68,"qty":0.00000000},{"price":2999.00,"qty":1.00000000}],"checksum":2782436219,"timestamp":"2024-06-01T22:42:39.307190Z"}]}
{"channel":"book","type":"update","data":[{"symbol":"ETH/GBP","bids":[{"price":2996.52,"qty":0.00000000},{"price":2993.37,"qty":0.27311159}],"asks":[],"checksum":4210155245,"timestamp":"2024-06-01T22:42:39.312515Z"}]}
{"channel":"book","type":"update","data":[{"symbol":"ETH/GBP","bids":[],"asks":[{"price":2998.90,"qty":0.00000000},{"price":2999.31,"qty":1.33100000}],"checksum":1079299023,"timestamp":"2024-06-01T22:42:39.377382Z"}]}
{"channel":"book","type":"update","data":[{"symbol":"ETH/GBP","bids":[],"asks":[{"price":2998.90,"qty":23.34820253}],"checksum":3602409093,"timestamp":"2024-06-01T22:42:39.382438Z"}]}
{"channel":"book","type":"update","data":[{"symbol":"ETH/GBP","bids":[],"asks":[{"price":2997.03,"qty":5.01424830}],"checksum":1767491953,"timestamp":"2024-06-01T22:42:39.382454Z"}]}
{"channel":"book","type":"update","data":[{"symbol":"ETH/GBP","bids":[],"asks":[{"price":2996.68,"qty":6.54513254}],"checksum":3871636165,"timestamp":"2024-06-01T22:42:39.402908Z"}]}
{"channel":"book","type":"update","data":[{"symbol":"ETH/GBP","bids":[{"price":2996.25,"qty":6.54605913}],"asks":[],"checksum":188167503,"timestamp":"2024-06-01T22:42:39.403070Z"}]}
{"channel":"book","type":"update","data":[{"symbol":"ETH/GBP","bids":[{"price":2996.25,"qty":0.00000000},{"price":2993.37,"qty":0.27311159}],"asks":[],"checksum":3871636165,"timestamp":"2024-06-01T22:42:39.410146Z"}]}
{"channel":"book","type":"update","data":[{"symbol":"ETH/GBP","bids":[{"price":2996.25,"qty":6.54605913}],"asks":[],"checksum":188167503,"timestamp":"2024-06-01T22:42:39.509915Z"}]}
{"channel":"book","type":"update","data":[{"symbol":"ETH/GBP","bids":[{"price":2996.25,"qty":0.00000000},{"price":2993.37,"qty":0.27311159}],"asks":[],"checksum":3871636165,"timestamp":"2024-06-01T22:42:39.514976Z"}]}
{"channel":"book","type":"update","data":[{"symbol":"ETH/GBP","bids":[],"asks":[{"price":2996.68,"qty":0.00000000},{"price":2998.91,"qty":9.61753147}],"checksum":1767491953,"timestamp":"2024-06-01T22:42:39.790251Z"}]}
{"channel":"book","type":"update","data":[{"symbol":"ETH/GBP","bids":[],"asks":[{"price":2996.67,"qty":6.54514526}],"checksum":1053199602,"timestamp":"2024-06-01T22:42:39.794618Z"}]}
{"channel":"book","type":"update","data":[{"symbol":"ETH/GBP","bids":[{"price":2996.51,"qty":6.54548521}],"asks":[],"checksum":357488627,"timestamp":"2024-06-01T22:42:39.794761Z"}]}
{"channel":"book","type":"update","data":[{"symbol":"ETH/GBP","bids":[{"price":2996.51,"qty":0.00000000},{"price":2993.37,"qty":0.27311159}],"asks":[],"checksum":1053199602,"timestamp":"2024-06-01T22:42:39.837923Z"}]}
{"channel":"book","type":"update","data":[{"symbol":"ETH/GBP","bids":[],"asks":[{"price":2996.67,"qty":0.00000000},{"price":2998.91,"qty":9.61753147}],"checksum":1767491953,"timestamp":"2024-06-01T22:42:39.838220Z"}]}
{"channel":"book","type":"update","data":[{"symbol":"ETH/GBP","bids":[],"asks":[{"price":2996.65,"qty":6.54519223}],"checksum":245730875,"timestamp":"2024-06-01T22:42:39.916068Z"}]}
{"channel":"book","type":"update","data":[{"symbol":"ETH/GBP","bids":[{"price":2996.25,"qty":6.54605913}],"asks":[],"checksum":1373277088,"timestamp":"2024-06-01T22:42:39.916086Z"}]}
{"channel":"book","type":"update","data":[{"symbol":"ETH/GBP","bids":[{"price":2996.25,"qty":0.00000000},{"price":2993.37,"qty":0.27311159}],"asks":[],"checksum":245730875,"timestamp":"2024-06-01T22:42:39.921121Z"}]}
{"channel":"book","type":"update","data":[{"symbol":"ETH/GBP","bids":[],"asks":[{"price":2996.65,"qty":0.00000000},{"price":2998.91,"qty":9.61753147}],"checksum":1767491953,"timestamp":"2024-06-01T22:42:40.016111Z"}]}
{"channel":"book","type":"update","data":[{"symbol":"ETH/GBP","bids":[{"price":2996.50,"qty":6.54550824}],"asks":[],"checksum":2475450830,"timestamp":"2024-06-01T22:42:40.020881Z"}]}
{"channel":"book","type":"update","data":[{"symbol":"ETH/GBP","bids":[],"asks":[{"price":2996.66,"qty":6.54516801}],"checksum":3463937272,"timestamp":"2024-06-01T22:42:40.020974Z"}]}
{"channel":"book","type":"update","data":[{"symbol":"ETH/GBP","bids":[{"price":2996.50,"qty":0.00000000},{"price":2993.37,"qty":0.27311159}],"asks":[],"checksum":4200594827,"timestamp":"2024-06-01T22:42:40.192950Z"}]}
{"channel":"book","type":"update","data":[{"symbol":"ETH/GBP","bids":[],"asks":[{"price":2996.66,"qty":0.00000000},{"price":2998.91,"qty":9.61753147}],"checksum":1767491953,"timestamp":"2024-06-01T22:42:40.193081Z"}]}
{"channel":"book","type":"update","data":[{"symbol":"ETH/GBP","bids":[{"price":2996.51,"qty":6.54548533}],"asks":[],"checksum":2687403782,"timestamp":"2024-06-01T22:42:40.200230Z"}]}
{"channel":"book","type":"update","data":[{"symbol":"ETH/GBP","bids":[],"asks":[{"price":2996.67,"qty":6.54514510}],"checksum":470562144,"timestamp":"2024-06-01T22:42:40.200301Z"}]}
{"channel":"book","type":"update","data":[{"symbol":"ETH/GBP","bids":[{"price":2996.51,"qty":0.00000000},{"price":2993.37,"qty":0.27311159}],"asks":[],"checksum":761836992,"timestamp":"2024-06-01T22:42:40.204916Z"}]}
{"channel":"book","type":"update","data":[{"symbol":"ETH/GBP","bids":[{"price":2996.51,"qty":6.54547369}],"asks":[],"checksum":2780501888,"timestamp":"2024-06-01T22:42:40.738304Z"}]}
{"channel":"book","type":"update","data":[{"symbol":"ETH/GBP","bids":[],"asks":[{"price":2996.67,"qty":0.00000000},{"price":2998.91,"qty":9.61753147}],"checksum":429499878,"timestamp":"2024-06-01T22:42:40.984235Z"}]}
{"channel":"book","type":"update","data":[{"symbol":"ETH/GBP","bids":[{"price":2996.51,"qty":0.00000000},{"price":2993.37,"qty":0.27311159}],"asks":[],"checksum":1767491953,"timestamp":"2024-06-01T22:42:40.984259Z"}]}
{"channel":"book","type":"update","data":[{"symbol":"ETH/GBP","bids":[],"asks":[{"price":2996.70,"qty":6.54508506}],"checksum":500881237,"timestamp":"2024-06-01T22:42:40.989583Z"}]}
{"channel":"book","type":"update","data":[{"symbol":"ETH/GBP","bids":[{"price":2996.54,"qty":6.54542031}],"asks":[],"checksum":3103303078,"timestamp":"2024-06-01T22:42:40.989791Z"}]}
{"channel":"book","type":"update","data":[{"symbol":"ETH/GBP","bids":[],"asks":[{"price":2996.70,"qty":0.00000000},{"price":2998.91,"qty":9.61753147}],"checksum":2224013929,"timestamp":"2024-06-01T22:42:41.021499Z"}]}
{"channel":"book","type":"update","data":[{"symbol":"ETH/GBP","bids":[{"price":2996.54,"qty":0.00000000},{"price":2993.37,"qty":0.27311159}],"asks":[],"checksum":1767491953,"timestamp":"2024-06-01T22:42:41.094975Z"}]}
{"channel":"book","type":"update","data":[{"symbol":"ETH/GBP","bids":[{"price":2996.50,"qty":6.54550672}],"asks":[],"checksum":3796862821,"timestamp":"2024-06-01T22:42:41.100609Z"}]}
{"channel":"book","type":"update","data":[{"symbol":"ETH/GBP","bids":[],"asks":[{"price":2996.66,"qty":6.54517146}],"checksum":2659242781,"timestamp":"2024-06-01T22:42:41.100642Z"}]}
{"channel":"book","type":"update","data":[{"symbol":"ETH/GBP","bids":[{"price":2996.50,"qty":0.00000000},{"price":2993.37,"qty":0.27311159}],"asks":[],"checksum":2061633215,"timestamp":"2024-06-01T22:42:41.175671Z"}]}
{"channel":"book","type":"update","data":[{"symbol":"ETH/GBP","bids":[],"asks":[{"price":2996.66,"qty":0.00000000},{"price":2998.91,"qty":9.61753147}],"checksum":1767491953,"timestamp":"2024-06-01T22:42:41.263224Z"}]}
{"channel":"book","type":"update","data":[{"symbol":"ETH/GBP","bids":[],"asks":[{"price":2996.67,"qty":6.54514201}],"checksum":1142987675,"timestamp":"2024-06-01T22:42:41.267409Z"}]}
{"channel":"book","type":"update","data":[{"symbol":"ETH/GBP","bids":[{"price":2996.51,"qty":6.54548577}],"asks":[],"checksum":3378311568,"timestamp":"2024-06-01T22:42:41.267501Z"}]}
{"channel":"book","type":"update","data":[{"symbol":"ETH/GBP","bids":[],"asks":[{"price":2996.67,"qty":0.00000000},{"price":2998.91,"qty":9.61753147}],"checksum":2309915556,"timestamp":"2024-06-01T22:42:41.308585Z"}]}
{"channel":"book","type":"update","data":[{"symbol":"ETH/GBP","bids":[{"price":2996.51,"qty":0.00000000},{"price":2993.37,"qty":0.27311159}],"asks":[],"checksum":1767491953,"timestamp":"2024-06-01T22:42:41.308761Z"}]}
{"channel":"book","type":"update","data":[{"symbol":"ETH/GBP","bids":[{"price":2996.15,"qty":0.00000000},{"price":2993.00,"qty":0.94850883}],"asks":[],"checksum":1093367339,"timestamp":"2024-06-01T22:42:41.361662Z"}]}
{"channel":"book","type":"update","data":[{"symbol":"ETH/GBP","bids":[],"asks":[{"price":2997.66,"qty":0.00000000},{"price":2999.00,"qty":1.00000000}],"checksum":3271473906,"timestamp":"2024-06-01T22:42:41.364490Z"}]}
{"channel":"book","type":"update","data":[{"symbol":"ETH/GBP","bids":[],"asks":[{"price":2996.95,"qty":0.31000000}],"checksum":2129138257,"timestamp":"2024-06-01T22:42:41.364552Z"}]}
{"channel":"book","type":"update","data":[{"symbol":"ETH/GBP","bids":[{"price":2996.10,"qty":13.09276235}],"asks":[],"checksum":471813185,"timestamp":"2024-06-01T22:42:41.365262Z"}]}
{"channel":"book","type":"update","data":[{"symbol":"ETH/GBP","bids":[{"price":2996.47,"qty":6.54557153}],"asks":[],"checksum":775978090,"timestamp":"2024-06-01T22:42:41.370207Z"}]}
{"channel":"book","type":"update","data":[{"symbol":"ETH/GBP","bids":[],"asks":[{"price":2996.63,"qty":6.54523252}],"checksum":3759423835,"timestamp":"2024-06-01T22:42:41.370232Z"}]}
{"channel":"book","type":"update","data":[{"symbol":"ETH/GBP","bids":[],"asks":[{"price":2997.04,"qty":0.00000000},{"price":2998.91,"qty":9.61753147}],"checksum":2794966137,"timestamp":"2024-06-01T22:42:41.388485Z"}]}
{"channel":"book","type":"update","data":[{"symbol":"ETH/GBP","bids":[],"asks":[{"price":2997.00,"qty":13.08886830}],"checksum":1338785217,"timestamp":"2024-06-01T22:42:41.392461Z"}]}
{"channel":"book","type":"update","data":[{"symbol":"ETH/GBP","bids":[],"asks":[{"price":2996.63,"qty":0.00000000},{"price":2998.91,"qty":9.61753147}],"checksum":2058462850,"timestamp":"2024-06-01T22:42:41.421544Z"}]}
{"channel":"book","type":"update","data":[{"symbol":"ETH/GBP","bids":[],"asks":[{"price":2997.00,"qty":0.00000000},{"price":2999.00,"qty":1.00000000}],"checksum":979457759,"timestamp":"2024-06-01T22:42:41.482293Z"}]}
{"channel":"book","type":"update","data":[{"symbol":"ETH/GBP","bids":[{"price":2996.47,"qty":0.00000000},{"price":2993.37,"qty":0.27311159}],"asks":[],"checksum":1013560925,"timestamp":"2024-06-01T22:42:41.482343Z"}]}
{"channel":"book","type":"update","data":[{"symbol":"ETH/GBP","bids":[{"price":2996.10,"qty":0.00000000},{"price":2993.00,"qty":0.94850883}],"asks":[],"checksum":1836127943,"timestamp":"2024-06-01T22:42:41.482416Z"}]}
{"channel":"book","type":"update","data":[{"symbol":"ETH/GBP","bids":[],"asks":[{"price":2996.81,"qty":6.54483589}],"checksum":231794401,"timestamp":"2024-06-01T22:42:41.482497Z"}]}
{"channel":"book","type":"update","data":[{"symbol":"ETH/GBP","bids":[],"asks":[{"price":2996.81,"qty":0.00000000},{"price":2999.00,"qty":1.00000000}],"checksum":1836127943,"timestamp":"2024-06-01T22:42:41.487667Z"}]}
{"channel":"book","type":"update","data":[{"symbol":"ETH/GBP","bids":[{"price":2996.42,"qty":6.54568407}],"asks":[],"checksum":86406194,"timestamp":"2024-06-01T22:42:41.494935Z"}]}
{"channel":"book","type":"update","data":[{"symbol":"ETH/GBP","bids":[{"price":2996.05,"qty":13.09298745}],"asks":[],"checksum":1401934767,"timestamp":"2024-06-01T22:42:41.575545Z"}]}
{"channel":"book","type":"update","data":[{"symbol":"ETH/GBP","bids":[],"asks":[{"price":2996.59,"qty":6.54533589}],"checksum":1143798756,"timestamp":"2024-06-01T22:42:41.586247Z"}]}
{"channel":"book","type":"update","data":[{"symbol":"ETH/GBP","bids":[],"asks":[{"price":2996.95,"qty":13.39907109}],"checksum":58618457,"timestamp":"2024-06-01T22:42:41.594273Z"}]}
{"channel":"book","type":"update","data":[{"symbol":"ETH/GBP","bids":[],"asks":[{"price":2997.03,"qty":0.00000000},{"price":2999.00,"qty":1.00000000}],"checksum":3223900521,"timestamp":"2024-06-01T22:42:41.639838Z"}]}
{"channel":"book","type":"update","data":[{"symbol":"ETH/GBP","bids":[],"asks":[{"price":2998.90,"qty":0.00000000},{"price":2999.31,"qty":1.33100000}],"checksum":2678177560,"timestamp":"2024-06-01T22:42:41.639968Z"}]}
{"channel":"book","type":"update","data":[{"symbol":"ETH/GBP","bids":[],"asks":[{"price":2998.90,"qty":21.97898945}],"checksum":1764362288,"timestamp":"2024-06-01T22:42:41.644992Z"}]}
{"channel":"book","type":"update","data":[{"symbol":"ETH/GBP","bids":[],"asks":[{"price":2996.59,"qty":0.00000000},{"price":2999.31,"qty":1.33100000}],"checksum":643517268,"timestamp":"2024-06-01T22:42:41.720039Z"}]}
{"channel":"book","type":"update","data":[{"symbol":"ETH/GBP","bids":[],"asks":[{"price":2996.58,"qty":6.54534456}],"checksum":1603848258,"timestamp":"2024-06-01T22:42:41.725626Z"}]}
{"channel":"book","type":"update","data":[{"symbol":"ETH/GBP","bids":[{"price":2996.42,"qty":0.00000000},{"price":2993.37,"qty":0.27311159}],"asks":[],"checksum":495751904,"timestamp":"2024-06-01T22:42:41.788968Z"}]}
{"channel":"book","type":"update","data":[{"symbol":"ETH/GBP","bids":[{"price":2996.25,"qty":6.54605913}],"asks":[],"checksum":1114218836,"timestamp":"2024-06-01T22:42:41.794384Z"}]}
{"channel":"book","type":"update","data":[{"symbol":"ETH/GBP","bids":[{"price":2996.25,"qty":0.00000000},{"price":2993.37,"qty":0.27311159}],"asks":[],"checksum":495751904,"timestamp":"2024-06-01T22:42:41.798906Z"}]}
{"channel":"book","type":"update","data":[{"symbol":"ETH/GBP","bids":[],"asks":[{"price":2996.58,"qty":0.00000000},{"price":2999.31,"qty":1.33100000}],"checksum":45555945,"timestamp":"2024-06-01T22:42:41.804784Z"}]}
{"channel":"book","type":"update","data":[{"symbol":"ETH/GBP","bids":[],"asks":[{"price":2996.60,"qty":6.54531183}],"checksum":69633892,"timestamp":"2024-06-01T22:42:41.844743Z"}]}
{"channel":"book","type":"update","data":[{"symbol":"ETH/GBP","bids":[{"price":2996.43,"qty":6.54564451}],"asks":[],"checksum":3602452232,"timestamp":"2024-06-01T22:42:42.027122Z"}]}
{"channel":"book","type":"update","data":[{"symbol":"ETH/GBP","bids":[{"price":2996.43,"qty":0.00000000},{"price":2993.37,"qty":0.27311159}],"asks":[],"checksum":69633892,"timestamp":"2024-06-01T22:42:42.076314Z"}]}
{"channel":"book","type":"update","data":[{"symbol":"ETH/GBP","bids":[{"price":2996.45,"qty":6.54562046}],"asks":[],"checksum":2986551153,"timestamp":"2024-06-01T22:42:42.253066Z"}]}
{"channel":"book","type":"update","data":[{"symbol":"ETH/GBP","bids":[{"price":2996.45,"qty":0.00000000},{"price":2993.37,"qty":0.27311159}],"asks":[],"checksum":69633892,"timestamp":"2024-06-01T22:42:42.302570Z"}]}
{"channel":"book","type":"update","data":[{"symbol":"ETH/GBP","bids":[],"asks":[{"price":2996.95,"qty":0.31000000}],"checksum":2968782410,"timestamp":"2024-06-01T22:42:42.302618Z"}]}
{"channel":"book","type":"update","data":[{"symbol":"ETH/GBP","bids":[{"price":2996.05,"qty":0.00000000},{"price":2993.00,"qty":0.94850883}],"asks":[],"checksum":1456226992,"timestamp":"2024-06-01T22:42:42.302679Z"}]}
{"channel":"book","type":"update","data":[{"symbol":"ETH/GBP","bids":[],"asks":[{"price":2996.60,"qty":0.00000000},{"price":2999.31,"qty":1.33100000}],"checksum":2307097365,"timestamp":"2024-06-01T22:42:42.302695Z"}]}
{"channel":"book","type":"update","data":[{"symbol":"ETH/GBP","bids":[],"asks":[{"price":2996.95,"qty":0.00000000},{"price":2999.32,"qty":1.30787255}],"checksum":2025110813,"timestamp":"2024-06-01T22:42:42.305419Z"}]}
{"channel":"book","type":"update","data":[{"symbol":"ETH/GBP","bids":[{"price":2995.74,"qty":0.00000000},{"price":2992.73,"qty":0.12935847}],"asks":[],"checksum":2081597968,"timestamp":"2024-06-01T22:42:42.305599Z"}]}
{"channel":"book","type":"update","data":[{"symbol":"ETH/GBP","bids":[{"price":2995.87,"qty":0.31000000}],"asks":[],"checksum":2280840758,"timestamp":"2024-06-01T22:42:42.305887Z"}]}
{"channel":"book","type":"update","data":[{"symbol":"ETH/GBP","bids":[],"asks":[{"price":2997.66,"qty":0.31000000}],"checksum":2260132538,"timestamp":"2024-06-01T22:42:42.305951Z"}]}
{"channel":"book","type":"update","data":[{"symbol":"ETH/GBP","bids":[],"asks":[{"price":2996.63,"qty":6.54523720}],"checksum":3004924321,"timestamp":"2024-06-01T22:42:42.309078Z"}]}
{"channel":"book","type":"update","data":[{"symbol":"ETH/GBP","bids":[{"price":2996.09,"qty":13.09277491}],"asks":[],"checksum":2033200340,"timestamp":"2024-06-01T22:42:42.309243Z"}]}
{"channel":"book","type":"update","data":[{"symbol":"ETH/GBP","bids":[],"asks":[{"price":2997.00,"qty":13.08885823}],"checksum":3440315354,"timestamp":"2024-06-01T22:42:42.309257Z"}]}
{"channel":"book","type":"update","data":[{"symbol":"ETH/GBP","bids":[],"asks":[{"price":2996.63,"qty":0.00000000},{"price":2999.00,"qty":1.00000000}],"checksum":1157460578,"timestamp":"2024-06-01T22:42:42.313845Z"}]}
{"channel":"book","type":"update","data":[{"symbol":"ETH/GBP","bids":[],"asks":[{"price":2997.66,"qty":0.00000000},{"price":2999.31,"qty":1.33100000}],"checksum":888246030,"timestamp":"2024-06-01T22:42:42.316866Z"}]}
{"channel":"book","type":"update","data":[{"symbol":"ETH/GBP","bids":[],"asks":[{"price":2996.98,"qty":0.31000000}],"checksum":4292771603,"timestamp":"2024-06-01T22:42:42.317119Z"}]}
{"channel":"book","type":"update","data":[{"symbol":"ETH/GBP","bids":[{"price":2996.47,"qty":6.54556940}],"asks":[],"checksum":1345154579,"timestamp":"2024-06-01T22:42:42.395653Z"}]}
{"channel":"book","type":"update","data":[{"symbol":"ETH/GBP","bids":[],"asks":[{"price":2996.82,"qty":0.00000000},{"price":2999.31,"qty":1.33100000},{"price":2997.65,"qty":0.08525900}],"checksum":2545395942,"timestamp":"2024-06-01T22:42:42.483497Z"}]}
{"channel":"book","type":"update","data":[{"symbol":"ETH/GBP","bids":[{"price":2996.47,"qty":0.00000000},{"price":2993.37,"qty":0.27311159}],"asks":[],"checksum":2997894760,"timestamp":"2024-06-01T22:42:42.573010Z"}]}
{"channel":"book","type":"update","data":[{"symbol":"ETH/GBP","bids":[],"asks":[{"price":2996.62,"qty":6.54526010}],"checksum":2849855012,"timestamp":"2024-06-01T22:42:42.578156Z"}]}
{"channel":"book","type":"update","data":[{"symbol":"ETH/GBP","bids":[{"price":2996.45,"qty":6.54560212}],"asks":[],"checksum":1521679415,"timestamp":"2024-06-01T22:42:42.578214Z"}]}
{"channel":"book","type":"update","data":[{"symbol":"ETH/GBP","bids":[{"price":2993.38,"qty":0.00000000},{"price":2993.00,"qty":0.94850883},{"price":2993.01,"qty":1.33100000}],"asks":[],"checksum":1061532156,"timestamp":"2024-06-01T22:42:42.610766Z"}]}
{"channel":"book","type":"update","data":[{"symbol":"ETH/GBP","bids":[{"price":2996.45,"qty":0.00000000},{"price":2993.00,"qty":0.94850883}],"asks":[],"checksum":1369306197,"timestamp":"2024-06-01T22:42:42.645355Z"}]}
{"channel":"book","type":"update","data":[{"symbol":"ETH/GBP","bids":[{"price":2996.25,"qty":6.54605913}],"asks":[],"checksum":3151966392,"timestamp":"2024-06-01T22:42:42.696040Z"}]}
{"channel":"book","type":"update","data":[{"symbol":"ETH/GBP","bids":[{"price":2996.25,"qty":0.00000000},{"price":2993.00,"qty":0.94850883}],"asks":[],"checksum":1369306197,"timestamp":"2024-06-01T22:42:42.700702Z"}]}
{"channel":"book","type":"update","data":[{"symbol":"ETH/GBP","bids":[{"price":2993.55,"qty":0.27305540}],"asks":[],"checksum":141551491,"timestamp":"2024-06-01T22:42:42.858091Z"}]}
{"channel":"book","type":"update","data":[{"symbol":"ETH/GBP","bids":[],"asks":[{"price":2996.62,"qty":0.00000000},{"price":2999.00,"qty":1.00000000}],"checksum":318934991,"timestamp":"2024-06-01T22:42:42.883021Z"}]}
{"channel":"book","type":"update","data":[{"symbol":"ETH/GBP","bids":[],"asks":[{"price":2996.61,"qty":6.54528029}],"checksum":4265707430,"timestamp":"2024-06-01T22:42:42.887955Z"}]}
{"channel":"book","type":"update","data":[{"symbol":"ETH/GBP","bids":[{"price":2996.45,"qty":6.54561424}],"asks":[],"checksum":3612101714,"timestamp":"2024-06-01T22:42:42.888123Z"}]}
{"channel":"book","type":"update","data":[{"symbol":"ETH/GBP","bids":[],"asks":[{"price":2996.61,"qty":0.00000000},{"price":2999.00,"qty":1.00000000}],"checksum":974079035,"timestamp":"2024-06-01T22:42:42.911861Z"}]}
{"channel":"book","type":"update","data":[{"symbol":"ETH/GBP","bids":[],"asks":[{"price":2997.00,"qty":0.00000000},{"price":2999.31,"qty":1.33100000}],"checksum":790526924,"timestamp":"2024-06-01T22:42:42.916723Z"}]}
{"channel":"book","type":"update","data":[{"symbol":"ETH/GBP","bids":[{"price":2996.45,"qty":0.00000000},{"price":2993.01,"qty":1.33100000}],"asks":[],"checksum":101953592,"timestamp":"2024-06-01T22:42:42.916851Z"}]}
{"channel":"book","type":"update","data":[{"symbol":"ETH/GBP","bids":[],"asks":[{"price":2997.57,"qty":0.31000000}],"checksum":3893666007,"timestamp":"2024-06-01T22:42:42.919412Z"}]}
{"channel":"book","type":"update","data":[{"symbol":"ETH/GBP","bids":[],"asks":[{"price":2996.98,"qty":0.00000000},{"price":2999.31,"qty":1.33100000}],"checksum":3671315733,"timestamp":"2024-06-01T22:42:42.919510Z"}]}
{"channel":"book","type":"update","data":[{"symbol":"ETH/GBP","bids":[{"price":2995.87,"qty":0.00000000},{"price":2993.00,"qty":0.94850883}],"asks":[],"checksum":4088202663,"timestamp":"2024-06-01T22:42:42.919863Z"}]}
{"channel":"book","type":"update","data":[{"symbol":"ETH/GBP","bids":[{"price":2996.12,"qty":0.31000000}],"asks":[],"checksum":1510334354,"timestamp":"2024-06-01T22:42:42.920029Z"}]}
{"channel":"book","type":"update","data":[{"symbol":"ETH/GBP","bids":[],"asks":[{"price":2996.97,"qty":13.08897297}],"checksum":2712929432,"timestamp":"2024-06-01T22:42:42.921519Z"}]}
{"channel":"book","type":"update","data":[{"symbol":"ETH/GBP","bids":[],"asks":[{"price":2997.54,"qty":1.30919895}],"checksum":1403231658,"timestamp":"2024-06-01T22:42:42.922597Z"}]}
{"channel":"book","type":"update","data":[{"symbol":"ETH/GBP","bids":[],"asks":[{"price":2996.62,"qty":6.54525982}],"checksum":2606035902,"timestamp":"2024-06-01T22:42:43.208098Z"}]}
{"channel":"book","type":"update","data":[{"symbol":"ETH/GBP","bids":[{"price":2996.46,"qty":6.54559395}],"asks":[],"checksum":2458698219,"timestamp":"2024-06-01T22:42:43.208116Z"}]}
{"channel":"book","type":"update","data":[{"symbol":"ETH/GBP","bids":[],"asks":[{"price":2996.62,"qty":0.00000000},{"price":2998.91,"qty":9.61753147}],"checksum":1518055423,"timestamp":"2024-06-01T22:42:43.237526Z"}]}
{"channel":"book","type":"update","data":[{"symbol":"ETH/GBP","bids":[],"asks":[{"price":2996.61,"qty":6.54527357}],"checksum":225183658,"timestamp":"2024-06-01T22:42:43.331125Z"}]}
{"channel":"book","type":"update","data":[{"symbol":"ETH/GBP","bids":[],"asks":[{"price":2996.61,"qty":0.00000000},{"price":2998.91,"qty":9.61753147}],"checksum":1518055423,"timestamp":"2024-06-01T22:42:43.382621Z"}]}
{"channel":"book","type":"update","data":[{"symbol":"ETH/GBP","bids":[],"asks":[{"price":2996.62,"qty":6.54526941}],"checksum":3344009155,"timestamp":"2024-06-01T22:42:43.596131Z"}]}
{"channel":"book","type":"update","data":[{"symbol":"ETH/GBP","bids":[],"asks":[{"price":2996.62,"qty":0.00000000},{"price":2998.91,"qty":9.61753147}],"checksum":1518055423,"timestamp":"2024-06-01T22:42:43.731181Z"}]}
{"channel":"book","type":"update","data":[{"symbol":"ETH/GBP","bids":[],"asks":[{"price":2996.61,"qty":6.54527661}],"checksum":1193079530,"timestamp":"2024-06-01T22:42:43.735753Z"}]}
{"channel":"book","type":"update","data":[{"symbol":"ETH/GBP","bids":[],"asks":[{"price":2996.61,"qty":0.00000000},{"price":2998.91,"qty":9.61753147}],"checksum":1518055423,"timestamp":"2024-06-01T22:42:43.835435Z"}]}
{"channel":"book","type":"update","data":[{"symbol":"ETH/GBP","bids":[{"price":2996.46,"qty":0.00000000},{"price":2993.01,"qty":1.33100000}],"asks":[],"checksum":1403231658,"timestamp":"2024-06-01T22:42:43.835447Z"}]}
{"channel":"book","type":"update","data":[{"symbol":"ETH/GBP","bids":[{"price":2996.47,"qty":6.54557509}],"asks":[],"checksum":3449107954,"timestamp":"2024-06-01T22:42:43.840928Z"}]}
{"channel":"book","type":"update","data":[{"symbol":"ETH/GBP","bids":[],"asks":[{"price":2996.63,"qty":6.54523724}],"checksum":3910406437,"timestamp":"2024-06-01T22:42:43.841075Z"}]}
{"channel":"book","type":"update","data":[{"symbol":"ETH/GBP","bids":[],"asks":[{"price":2998.90,"qty":0.00000000},{"price":2998.91,"qty":9.61753147}],"checksum":360716433,"timestamp":"2024-06-01T22:42:43.875095Z"}]}
{"channel":"book","type":"update","data":[{"symbol":"ETH/GBP","bids":[],"asks":[{"price":2998.90,"qty":22.85143226}],"checksum":676949251,"timestamp":"2024-06-01T22:42:43.880142Z"}]}
{"channel":"book","type":"update","data":[{"symbol":"ETH/GBP","bids":[],"asks":[{"price":2996.96,"qty":5.01424830}],"checksum":3416611341,"timestamp":"2024-06-01T22:42:43.880184Z"}]}
{"channel":"book","type":"update","data":[{"symbol":"ETH/GBP","bids":[],"asks":[{"price":2997.65,"qty":0.00000000},{"price":2998.90,"qty":22.85143226},{"price":2996.96,"qty":5.09951830}],"checksum":3148945413,"timestamp":"2024-06-01T22:42:43.905931Z"}]}
{"channel":"book","type":"update","data":[{"symbol":"ETH/GBP","bids":[{"price":2996.47,"qty":0.00000000},{"price":2993.01,"qty":1.33100000}],"asks":[],"checksum":629649501,"timestamp":"2024-06-01T22:42:44.196132Z"}]}
{"channel":"book","type":"update","data":[{"symbol":"ETH/GBP","bids":[],"asks":[{"price":2996.63,"qty":0.00000000},{"price":2998.91,"qty":9.61753147}],"checksum":3968427887,"timestamp":"2024-06-01T22:42:44.196296Z"}]}
{"channel":"book","type":"update","data":[{"symbol":"ETH/GBP","bids":[{"price":2996.45,"qty":6.54560324}],"asks":[],"checksum":4088607545,"timestamp":"2024-06-01T22:42:44.202119Z"}]}
{"channel":"book","type":"update","data":[{"symbol":"ETH/GBP","bids":[],"asks":[{"price":2996.62,"qty":6.54526539}],"checksum":3067643024,"timestamp":"2024-06-01T22:42:44.202309Z"}]}
{"channel":"book","type":"update","data":[{"symbol":"ETH/GBP","bids":[{"price":2996.45,"qty":0.00000000},{"price":2993.01,"qty":1.33100000}],"asks":[],"checksum":2850214086,"timestamp":"2024-06-01T22:42:44.328192Z"}]}
{"channel":"book","type":"update","data":[{"symbol":"ETH/GBP","bids":[{"price":2996.09,"qty":0.00000000},{"price":2993.00,"qty":0.94850883}],"asks":[],"checksum":3744608363,"timestamp":"2024-06-01T22:42:44.328237Z"}]}
{"channel":"book","type":"update","data":[{"symbol":"ETH/GBP","bids":[],"asks":[{"price":2996.97,"qty":0.00000000},{"price":2998.91,"qty":9.61753147}],"checksum":1495313757,"timestamp":"2024-06-01T22:42:44.328309Z"}]}
{"channel":"book","type":"update","data":[{"symbol":"ETH/GBP","bids":[],"asks":[{"price":2996.62,"qty":0.00000000},{"price":2999.00,"qty":1.00000000}],"checksum":2534225108,"timestamp":"2024-06-01T22:42:44.328330Z"}]}
{"channel":"book","type":"update","data":[{"symbol":"ETH/GBP","bids":[{"price":2996.12,"qty":0.00000000},{"price":2992.73,"qty":0.12935847}],"asks":[],"checksum":1480658946,"timestamp":"2024-06-01T22:42:44.331208Z"}]}
{"channel":"book","type":"update","data":[{"symbol":"ETH/GBP","bids":[{"price":2995.90,"qty":0.31000000}],"asks":[],"checksum":3946029915,"timestamp":"2024-06-01T22:42:44.331510Z"}]}
{"channel":"book","type":"update","data":[{"symbol":"ETH/GBP","bids":[],"asks":[{"price":2996.52,"qty":6.54547940}],"checksum":1728508976,"timestamp":"2024-06-01T22:42:44.334968Z"}]}
{"channel":"book","type":"update","data":[{"symbol":"ETH/GBP","bids":[{"price":2996.34,"qty":6.54584345}],"asks":[],"checksum":974557348,"timestamp":"2024-06-01T22:42:44.335088Z"}]}
{"channel":"book","type":"update","data":[{"symbol":"ETH/GBP","bids":[],"asks":[{"price":2996.95,"qty":13.08906032}],"checksum":1906518383,"timestamp":"2024-06-01T22:42:44.335181Z"}]}
{"channel":"book","type":"update","data":[{"symbol":"ETH/GBP","bids":[{"price":2995.99,"qty":13.09323126}],"asks":[],"checksum":364407324,"timestamp":"2024-06-01T22:42:44.335193Z"}]}
{"channel":"book","type":"update","data":[{"symbol":"ETH/GBP","bids":[],"asks":[{"price":2996.52,"qty":0.00000000},{"price":2998.91,"qty":9.61753147}],"checksum":2733167661,"timestamp":"2024-06-01T22:42:44.341269Z"}]}
{"channel":"book","type":"update","data":[{"symbol":"ETH/GBP","bids":[{"price":2996.34,"qty":0.00000000},{"price":2993.01,"qty":1.33100000}],"asks":[],"checksum":3378662899,"timestamp":"2024-06-01T22:42:44.341332Z"}]}
{"channel":"book","type":"update","data":[{"symbol":"ETH/GBP","bids":[],"asks":[{"price":2996.95,"qty":0.00000000},{"price":2999.00,"qty":1.00000000}],"checksum":29992781,"timestamp":"2024-06-01T22:42:44.341368Z"}]}
{"channel":"book","type":"update","data":[{"symbol":"ETH/GBP","bids":[{"price":2995.99,"qty":0.00000000},{"price":2993.00,"qty":0.94850883}],"asks":[],"checksum":3946029915,"timestamp":"2024-06-01T22:42:44.394668Z"}]}
{"channel":"book","type":"update","data":[{"symbol":"ETH/GBP","bids":[],"asks":[{"price":2996.56,"qty":6.54538673}],"checksum":2079097774,"timestamp":"2024-06-01T22:42:44.501615Z"}]}
{"channel":"book","type":"update","data":[{"symbol":"ETH/GBP","bids":[{"price":2996.38,"qty":6.54575489}],"asks":[],"checksum":3708399026,"timestamp":"2024-06-01T22:42:44.501733Z"}]}
{"channel":"book","type":"update","data":[{"symbol":"ETH/GBP","bids":[],"asks":[{"price":2996.96,"qty":5.01424830},{"price":2997.53,"qty":0.08526100}],"checksum":818960712,"timestamp":"2024-06-01T22:42:44.509954Z"}]}
{"channel":"book","type":"update","data":[{"symbol":"ETH/GBP","bids":[{"price":2996.24,"qty":0.00000000},{"price":2993.00,"qty":0.94850883},{"price":2995.91,"qty":0.08528400}],"asks":[],"checksum":2943886968,"timestamp":"2024-06-01T22:42:44.511687Z"}]}
{"channel":"book","type":"update","data":[{"symbol":"ETH/GBP","bids":[],"asks":[{"price":2996.94,"qty":13.08910399}],"checksum":3695152117,"timestamp":"2024-06-01T22:42:44.565565Z"}]}
{"channel":"book","type":"update","data":[{"symbol":"ETH/GBP","bids":[{"price":2996.04,"qty":13.09303070}],"asks":[],"checksum":927421407,"timestamp":"2024-06-01T22:42:44.565720Z"}]}
{"channel":"book","type":"update","data":[{"symbol":"ETH/GBP","bids":[{"price":2996.38,"qty":0.00000000},{"price":2993.01,"qty":1.33100000}],"asks":[],"checksum":2462593541,"timestamp":"2024-06-01T22:42:44.724640Z"}]}
{"channel":"book","type":"update","data":[{"symbol":"ETH/GBP","bids":[{"price":2996.39,"qty":6.54575292}],"asks":[],"checksum":2121596464,"timestamp":"2024-06-01T22:42:44.729907Z"}]}
{"channel":"book","type":"update","data":[{"symbol":"ETH/GBP","bids":[],"asks":[{"price":2996.56,"qty":0.00000000},{"price":2998.90,"qty":22.85143226}],"checksum":2057345980,"timestamp":"2024-06-01T22:42:44.734569Z"}]}
{"channel":"book","type":"update","data":[{"symbol":"ETH/GBP","bids":[],"asks":[{"price":2996.57,"qty":6.54536251}],"checksum":1257416156,"timestamp":"2024-06-01T22:42:44.738923Z"}]}
{"channel":"book","type":"update","data":[{"symbol":"ETH/GBP","bids":[],"asks":[{"price":2996.57,"qty":0.00000000},{"price":2998.90,"qty":22.85143226}],"checksum":2057345980,"timestamp":"2024-06-01T22:42:44.824457Z"}]}
{"channel":"book","type":"update","data":[{"symbol":"ETH/GBP","bids":[{"price":2996.39,"qty":0.00000000},{"price":2993.01,"qty":1.33100000}],"asks":[],"checksum":2518439817,"timestamp":"2024-06-01T22:42:44.824865Z"}]}
{"channel":"book","type":"update","data":[{"symbol":"ETH/GBP","bids":[],"asks":[{"price":2996.94,"qty":0.00000000},{"price":2998.91,"qty":9.61753147}],"checksum":1423808005,"timestamp":"2024-06-01T22:42:44.830061Z"}]}
{"channel":"book","type":"update","data":[{"symbol":"ETH/GBP","bids":[],"asks":[{"price":2996.93,"qty":13.08914767}],"checksum":1031439503,"timestamp":"2024-06-01T22:42:44.834053Z"}]}
{"channel":"book","type":"update","data":[{"symbol":"ETH/GBP","bids":[{"price":2996.37,"qty":6.54577826}],"asks":[],"checksum":1846131938,"timestamp":"2024-06-01T22:42:44.834130Z"}]}
{"channel":"book","type":"update","data":[{"symbol":"ETH/GBP","bids":[],"asks":[{"price":2996.93,"qty":0.00000000},{"price":2998.91,"qty":9.61753147}],"checksum":128888424,"timestamp":"2024-06-01T22:42:44.839143Z"}]}
{"channel":"book","type":"update","data":[{"symbol":"ETH/GBP","bids":[],"asks":[{"price":2996.55,"qty":6.54541027}],"checksum":601046821,"timestamp":"2024-06-01T22:42:44.844564Z"}]}
{"channel":"book","type":"update","data":[{"symbol":"ETH/GBP","bids":[],"asks":[{"price":2996.55,"qty":0.00000000},{"price":2998.91,"qty":9.61753147}],"checksum":128888424,"timestamp":"2024-06-01T22:42:44.878662Z"}]}
{"channel":"book","type":"update","data":[{"symbol":"ETH/GBP","bids":[{"price":2996.37,"qty":0.00000000},{"price":2993.01,"qty":1.33100000}],"asks":[],"checksum":1423808005,"timestamp":"2024-06-01T22:42:44.878800Z"}]}
{"channel":"book","type":"update","data":[{"symbol":"ETH/GBP","bids":[],"asks":[{"price":2996.55,"qty":6.54540504}],"checksum":4059067596,"timestamp":"2024-06-01T22:42:44.967377Z"}]}
{"channel":"book","type":"update","data":[{"symbol":"ETH/GBP","bids":[{"price":2996.05,"qty":6.54649610}],"asks":[],"checksum":2467733571,"timestamp":"2024-06-01T22:42:44.967458Z"}]}
{"channel":"book","type":"update","data":[{"symbol":"ETH/GBP","bids":[{"price":2996.05,"qty":0.00000000},{"price":2993.01,"qty":1.33100000}],"asks":[],"checksum":4059067596,"timestamp":"2024-06-01T22:42:44.972393Z"}]}
{"channel":"book","type":"update","data":[{"symbol":"ETH/GBP","bids":[],"asks":[{"price":2996.55,"qty":0.00000000},{"price":2998.91,"qty":9.61753147}],"checksum":1423808005,"timestamp":"2024-06-01T22:42:45.018799Z"}]}
{"channel":"book","type":"update","data":[{"symbol":"ETH/GBP","bids":[],"asks":[{"price":2996.57,"qty":6.54537938}],"checksum":2348760493,"timestamp":"2024-06-01T22:42:45.118320Z"}]}
{"channel":"book","type":"update","data":[{"symbol":"ETH/GBP","bids":[{"price":2996.39,"qty":6.54574447}],"asks":[],"checksum":899805966,"timestamp":"2024-06-01T22:42:45.118449Z"}]}
{"channel":"book","type":"update","data":[{"symbol":"ETH/GBP","bids":[],"asks":[{"price":2996.92,"qty":13.08919134}],"checksum":4186475095,"timestamp":"2024-06-01T22:42:45.118587Z"}]}
{"channel":"book","type":"update","data":[{"symbol":"ETH/GBP","bids":[],"asks":[{"price":2996.57,"qty":0.00000000},{"price":2998.90,"qty":22.85143226}],"checksum":2221885023,"timestamp":"2024-06-01T22:42:45.155252Z"}]}
{"channel":"book","type":"update","data":[{"symbol":"ETH/GBP","bids":[{"price":2996.39,"qty":0.00000000},{"price":2993.01,"qty":1.33100000}],"asks":[],"checksum":976324860,"timestamp":"2024-06-01T22:42:45.329501Z"}]}
{"channel":"book","type":"update","data":[{"symbol":"ETH/GBP","bids":[],"asks":[{"price":2996.55,"qty":6.54541407}],"checksum":1764946364,"timestamp":"2024-06-01T22:42:45.335010Z"}]}
{"channel":"book","type":"update","data":[{"symbol":"ETH/GBP","bids":[{"price":2996.05,"qty":6.54649610}],"asks":[],"checksum":198452531,"timestamp":"2024-06-01T22:42:45.335046Z"}]}
{"channel":"book","type":"update","data":[{"symbol":"ETH/GBP","bids":[{"price":2996.05,"qty":0.00000000},{"price":2993.01,"qty":1.33100000}],"asks":[],"checksum":1764946364,"timestamp":"2024-06-01T22:42:45.340122Z"}]}
{"channel":"book","type":"update","data":[{"symbol":"ETH/GBP","bids":[],"asks":[{"price":2996.55,"qty":0.00000000},{"price":2998.90,"qty":22.85143226}],"checksum":976324860,"timestamp":"2024-06-01T22:42:45.346372Z"}]}
{"channel":"book","type":"update","data":[{"symbol":"ETH/GBP","bids":[],"asks":[{"price":2996.92,"qty":0.00000000},{"price":2998.91,"qty":9.61753147}],"checksum":1423808005,"timestamp":"2024-06-01T22:42:45.350736Z"}]}
{"channel":"book","type":"update","data":[{"symbol":"ETH/GBP","bids":[],"asks":[{"price":2996.91,"qty":13.08923502}],"checksum":4280063717,"timestamp":"2024-06-01T22:42:45.355198Z"}]}
{"channel":"book","type":"update","data":[{"symbol":"ETH/GBP","bids":[],"asks":[{"price":2996.55,"qty":6.54542055}],"checksum":3510799032,"timestamp":"2024-06-01T22:42:45.453942Z"}]}
{"channel":"book","type":"update","data":[{"symbol":"ETH/GBP","bids":[{"price":2996.37,"qty":6.54577982}],"asks":[],"checksum":2197874958,"timestamp":"2024-06-01T22:42:45.454006Z"}]}
{"channel":"book","type":"update","data":[{"symbol":"ETH/GBP","bids":[],"asks":[{"price":2996.55,"qty":0.00000000},{"price":2998.90,"qty":22.85143226}],"checksum":2908681555,"timestamp":"2024-06-01T22:42:45.516818Z"}]}
{"channel":"book","type":"update","data":[{"symbol":"ETH/GBP","bids":[{"price":2996.37,"qty":0.00000000},{"price":2993.01,"qty":1.33100000}],"asks":[],"checksum":4280063717,"timestamp":"2024-06-01T22:42:45.559782Z"}]}
{"channel":"book","type":"update","data":[{"symbol":"ETH/GBP","bids":[],"asks":[{"price":2996.57,"qty":6.54537342}],"checksum":3844476292,"timestamp":"2024-06-01T22:42:45.566083Z"}]}
{"channel":"book","type":"update","data":[{"symbol":"ETH/GBP","bids":[{"price":2996.39,"qty":6.54574840}],"asks":[],"checksum":298439288,"timestamp":"2024-06-01T22:42:45.566232Z"}]}
{"channel":"book","type":"update","data":[{"symbol":"ETH/GBP","bids":[{"price":2996.39,"qty":0.00000000},{"price":2993.01,"qty":1.33100000}],"asks":[],"checksum":3844476292,"timestamp":"2024-06-01T22:42:45.586202Z"}]}
{"channel":"book","type":"update","data":[{"symbol":"ETH/GBP","bids":[],"asks":[{"price":2996.57,"qty":0.00000000},{"price":2998.90,"qty":22.85143226}],"checksum":4280063717,"timestamp":"2024-06-01T22:42:45.586242Z"}]}
{"channel":"book","type":"update","data":[{"symbol":"ETH/GBP","bids":[{"price":2996.05,"qty":6.54649610}],"asks":[],"checksum":2650423914,"timestamp":"2024-06-01T22:42:45.666566Z"}]}
{"channel":"book","type":"update","data":[{"symbol":"ETH/GBP","bids":[],"asks":[{"price":2996.57,"qty":6.54537174}],"checksum":2798332321,"timestamp":"2024-06-01T22:42:45.666706Z"}]}
{"channel":"book","type":"update","data":[{"symbol":"ETH/GBP","bids":[{"price":2996.05,"qty":0.00000000},{"price":2993.01,"qty":1.33100000}],"asks":[],"checksum":3291348270,"timestamp":"2024-06-01T22:42:45.672564Z"}]}
{"channel":"book","type":"update","data":[{"symbol":"ETH/GBP","bids":[],"asks":[{"price":2997.53,"qty":0.00000000},{"price":2998.90,"qty":22.85143226},{"price":2996.90,"qty":0.08526900}],"checksum":3759350174,"timestamp":"2024-06-01T22:42:45.690783Z"}]}
{"channel":"book","type":"update","data":[{"symbol":"ETH/GBP","bids":[],"asks":[{"price":2996.57,"qty":0.00000000},{"price":2998.90,"qty":22.85143226}],"checksum":3298341832,"timestamp":"2024-06-01T22:42:45.873207Z"}]}
{"channel":"book","type":"update","data":[{"symbol":"ETH/GBP","bids":[],"asks":[{"price":2996.56,"qty":6.54539020}],"checksum":864762951,"timestamp":"2024-06-01T22:42:45.877917Z"}]}
{"channel":"book","type":"update","data":[{"symbol":"ETH/GBP","bids":[{"price":2996.38,"qty":6.54575436}],"asks":[],"checksum":2861291132,"timestamp":"2024-06-01T22:42:45.878064Z"}]}
{"channel":"book","type":"update","data":[{"symbol":"ETH/GBP","bids":[{"price":2996.38,"qty":0.00000000},{"price":2993.01,"qty":1.33100000}],"asks":[],"checksum":864762951,"timestamp":"2024-06-01T22:42:45.967451Z"}]}
{"channel":"book","type":"update","data":[{"symbol":"ETH/GBP","bids":[],"asks":[{"price":2996.96,"qty":0.00000000},{"price":2998.91,"qty":9.61753147}],"checksum":4043950949,"timestamp":"2024-06-01T22:42:46.182829Z"}]}
{"channel":"book","type":"update","data":[{"symbol":"ETH/GBP","bids":[],"asks":[{"price":2998.25,"qty":5.51321127}],"checksum":3568124362,"timestamp":"2024-06-01T22:42:46.187826Z"}]}
{"channel":"book","type":"update","data":[{"symbol":"ETH/GBP","bids":[],"asks":[{"price":2998.32,"qty":18.86801203}],"checksum":1751779393,"timestamp":"2024-06-01T22:42:46.187889Z"}]}
{"channel":"book","type":"update","data":[{"symbol":"ETH/GBP","bids":[{"price":2996.05,"qty":6.54649610}],"asks":[],"checksum":177003726,"timestamp":"2024-06-01T22:42:46.226616Z"}]}
{"channel":"book","type":"update","data":[{"symbol":"ETH/GBP","bids":[{"price":2996.05,"qty":0.00000000},{"price":2993.01,"qty":1.33100000}],"asks":[],"checksum":1751779393,"timestamp":"2024-06-01T22:42:46.231064Z"}]}
{"channel":"book","type":"update","data":[{"symbol":"ETH/GBP","bids":[{"price":2996.38,"qty":6.54575436}],"asks":[],"checksum":4050313850,"timestamp":"2024-06-01T22:42:46.340248Z"}]}
{"channel":"book","type":"update","data":[{"symbol":"ETH/GBP","bids":[{"price":2996.38,"qty":0.00000000},{"price":2993.01,"qty":1.33100000}],"asks":[],"checksum":1751779393,"timestamp":"2024-06-01T22:42:46.489077Z"}]}
{"channel":"book","type":"update","data":[{"symbol":"ETH/GBP","bids":[],"asks":[{"price":2996.56,"qty":0.00000000},{"price":2998.78,"qty":0.27306760}],"checksum":3686083639,"timestamp":"2024-06-01T22:42:46.489179Z"}]}
{"channel":"book","type":"update","data":[{"symbol":"ETH/GBP","bids":[],"asks":[{"price":2996.58,"qty":6.54535457}],"checksum":1706187896,"timestamp":"2024-06-01T22:42:46.494828Z"}]}
{"channel":"book","type":"update","data":[{"symbol":"ETH/GBP","bids":[{"price":2996.40,"qty":6.54571360}],"asks":[],"checksum":1150286527,"timestamp":"2024-06-01T22:42:46.494912Z"}]}
{"channel":"book","type":"update","data":[{"symbol":"ETH/GBP","bids":[{"price":2996.40,"qty":0.00000000},{"price":2993.01,"qty":1.33100000}],"asks":[],"checksum":1706187896,"timestamp":"2024-06-01T22:42:46.589081Z"}]}
{"channel":"book","type":"update","data":[{"symbol":"ETH/GBP","bids":[],"asks":[{"price":2996.91,"qty":0.00000000},{"price":2998.78,"qty":0.27306760}],"checksum":1254675255,"timestamp":"2024-06-01T22:42:46.644290Z"}]}
{"channel":"book","type":"update","data":[{"symbol":"ETH/GBP","bids":[{"price":2996.04,"qty":0.00000000},{"price":2993.00,"qty":0.94850883}],"asks":[],"checksum":619047762,"timestamp":"2024-06-01T22:42:46.644315Z"}]}
{"channel":"book","type":"update","data":[{"symbol":"ETH/GBP","bids":[],"asks":[{"price":2996.58,"qty":0.00000000},{"price":2998.91,"qty":9.61753147}],"checksum":4129578564,"timestamp":"2024-06-01T22:42:46.644353Z"}]}
{"channel":"book","type":"update","data":[{"symbol":"ETH/GBP","bids":[],"asks":[{"price":2996.59,"qty":6.54532118}],"checksum":1026295430,"timestamp":"2024-06-01T22:42:46.649900Z"}]}
{"channel":"book","type":"update","data":[{"symbol":"ETH/GBP","bids":[{"price":2996.42,"qty":6.54568021}],"asks":[],"checksum":1582651252,"timestamp":"2024-06-01T22:42:46.650033Z"}]}
{"channel":"book","type":"update","data":[{"symbol":"ETH/GBP","bids":[{"price":2995.92,"qty":13.09356035}],"asks":[],"checksum":3251691888,"timestamp":"2024-06-01T22:42:46.650063Z"}]}
{"channel":"book","type":"update","data":[{"symbol":"ETH/GBP","bids":[],"asks":[{"price":2996.96,"qty":13.08902978}],"checksum":907062184,"timestamp":"2024-06-01T22:42:46.650100Z"}]}
{"channel":"book","type":"update","data":[{"symbol":"ETH/GBP","bids":[{"price":2995.92,"qty":0.00000000},{"price":2993.01,"qty":1.33100000}],"asks":[],"checksum":4232631008,"timestamp":"2024-06-01T22:42:46.656699Z"}]}
{"channel":"book","type":"update","data":[{"symbol":"ETH/GBP","bids":[{"price":2996.42,"qty":0.00000000},{"price":2993.00,"qty":0.94850883}],"asks":[],"checksum":1205395621,"timestamp":"2024-06-01T22:42:47.108590Z"}]}
{"channel":"book","type":"update","data":[{"symbol":"ETH/GBP","bids":[],"asks":[{"price":2996.59,"qty":0.00000000},{"price":2998.78,"qty":0.27306760}],"checksum":2249002506,"timestamp":"2024-06-01T22:42:47.108665Z"}]}
{"channel":"book","type":"update","data":[{"symbol":"ETH/GBP","bids":[{"price":2996.41,"qty":6.54570486}],"asks":[],"checksum":1645292728,"timestamp":"2024-06-01T22:42:47.115124Z"}]}
{"channel":"book","type":"update","data":[{"symbol":"ETH/GBP","bids":[],"asks":[{"price":2996.58,"qty":6.54534958}],"checksum":3763111860,"timestamp":"2024-06-01T22:42:47.115154Z"}]}
{"channel":"book","type":"update","data":[{"symbol":"ETH/GBP","bids":[{"price":2995.92,"qty":13.09356035}],"asks":[],"checksum":1510619664,"timestamp":"2024-06-01T22:42:47.115346Z"}]}
{"channel":"book","type":"update","data":[{"symbol":"ETH/GBP","bids":[{"price":2995.92,"qty":0.00000000},{"price":2993.01,"qty":1.33100000}],"asks":[],"checksum":3763111860,"timestamp":"2024-06-01T22:42:47.120957Z"}]}
{"channel":"book","type":"update","data":[{"symbol":"ETH/GBP","bids":[{"price":2993.02,"qty":6.14236800}],"asks":[],"checksum":47476375,"timestamp":"2024-06-01T22:42:47.133865Z"}]}
{"channel":"book","type":"update","data":[{"symbol":"ETH/GBP","bids":[{"price":2993.03,"qty":1.33100000}],"asks":[],"checksum":3837351817,"timestamp":"2024-06-01T22:42:47.136766Z"}]}
{"channel":"book","type":"update","data":[{"symbol":"ETH/GBP","bids":[],"asks":[{"price":2996.58,"qty":0.00000000},{"price":2998.78,"qty":0.27306760}],"checksum":1726282885,"timestamp":"2024-06-01T22:42:47.498829Z"}]}
{"channel":"book","type":"update","data":[{"symbol":"ETH/GBP","bids":[{"price":2996.41,"qty":0.00000000},{"price":2993.02,"qty":6.14236800}],"asks":[],"checksum":1102383112,"timestamp":"2024-06-01T22:42:47.499029Z"}]}
{"channel":"book","type":"update","data":[{"symbol":"ETH/GBP","bids":[{"price":2996.43,"qty":6.54565565}],"asks":[],"checksum":3737199857,"timestamp":"2024-06-01T22:42:47.504243Z"}]}
{"channel":"book","type":"update","data":[{"symbol":"ETH/GBP","bids":[],"asks":[{"price":2996.60,"qty":6.54530242}],"checksum":3464816113,"timestamp":"2024-06-01T22:42:47.504296Z"}]}
{"channel":"book","type":"update","data":[{"symbol":"ETH/GBP","bids":[{"price":2996.04,"qty":13.09302261}],"asks":[],"checksum":3379769281,"timestamp":"2024-06-01T22:42:47.504437Z"}]}
{"channel":"book","type":"update","data":[{"symbol":"ETH/GBP","bids":[{"price":2996.04,"qty":0.00000000},{"price":2993.03,"qty":1.33100000}],"asks":[],"checksum":3464816113,"timestamp":"2024-06-01T22:42:47.509772Z"}]}
{"channel":"book","type":"update","data":[{"symbol":"ETH/GBP","bids":[],"asks":[{"price":2996.60,"qty":0.00000000},{"price":2998.78,"qty":0.27306760}],"checksum":3737199857,"timestamp":"2024-06-01T22:42:48.285284Z"}]}
{"channel":"book","type":"update","data":[{"symbol":"ETH/GBP","bids":[{"price":2996.06,"qty":13.09292418}],"asks":[],"checksum":466498233,"timestamp":"2024-06-01T22:42:48.290205Z"}]}
{"channel":"book","type":"update","data":[{"symbol":"ETH/GBP","bids":[],"asks":[{"price":2996.59,"qty":6.54532655}],"checksum":4102152570,"timestamp":"2024-06-01T22:42:48.290276Z"}]}
{"channel":"book","type":"update","data":[{"symbol":"ETH/GBP","bids":[],"asks":[{"price":2998.32,"qty":0.00000000},{"price":2998.78,"qty":0.27306760}],"checksum":1043733822,"timestamp":"2024-06-01T22:42:48.432487Z"}]}
{"channel":"book","type":"update","data":[{"symbol":"ETH/GBP","bids":[],"asks":[{"price":2998.25,"qty":0.00000000},{"price":2998.91,"qty":9.61753147}],"checksum":462591889,"timestamp":"2024-06-01T22:42:48.432634Z"}]}
{"channel":"book","type":"update","data":[{"symbol":"ETH/GBP","bids":[],"asks":[{"price":2998.25,"qty":6.51113722}],"checksum":4008416645,"timestamp":"2024-06-01T22:42:48.437508Z"}]}
{"channel":"book","type":"update","data":[{"symbol":"ETH/GBP","bids":[],"asks":[{"price":2998.32,"qty":7.93662982}],"checksum":102164475,"timestamp":"2024-06-01T22:42:48.437582Z"}]}
{"channel":"book","type":"update","data":[{"symbol":"ETH/GBP","bids":[{"price":2996.43,"qty":0.00000000},{"price":2993.03,"qty":1.33100000}],"asks":[],"checksum":727664127,"timestamp":"2024-06-01T22:42:48.499294Z"}]}
{"channel":"book","type":"update","data":[{"symbol":"ETH/GBP","bids":[],"asks":[{"price":2996.59,"qty":0.00000000},{"price":2998.78,"qty":0.27306760}],"checksum":964400454,"timestamp":"2024-06-01T22:42:48.499309Z"}]}
{"channel":"book","type":"update","data":[{"symbol":"ETH/GBP","bids":[{"price":2996.06,"qty":0.00000000},{"price":2993.02,"qty":6.14236800}],"asks":[],"checksum":3175728961,"timestamp":"2024-06-01T22:42:48.504842Z"}]}
{"channel":"book","type":"update","data":[{"symbol":"ETH/GBP","bids":[{"price":2995.92,"qty":13.09356035}],"asks":[],"checksum":2479803766,"timestamp":"2024-06-01T22:42:48.510057Z"}]}
{"channel":"book","type":"update","data":[{"symbol":"ETH/GBP","bids":[],"asks":[{"price":2996.61,"qty":6.54528889}],"checksum":2485507070,"timestamp":"2024-06-01T22:42:48.510167Z"}]}
{"channel":"book","type":"update","data":[{"symbol":"ETH/GBP","bids":[{"price":2996.44,"qty":6.54563558}],"asks":[],"checksum":3760568759,"timestamp":"2024-06-01T22:42:48.510205Z"}]}
{"channel":"book","type":"update","data":[{"symbol":"ETH/GBP","bids":[{"price":2995.92,"qty":0.00000000},{"price":2993.03,"qty":1.33100000}],"asks":[],"checksum":453834109,"timestamp":"2024-06-01T22:42:48.517445Z"}]}
{"channel":"book","type":"update","data":[{"symbol":"ETH/GBP","bids":[],"asks":[{"price":2996.61,"qty":0.00000000},{"price":2998.78,"qty":0.27306760}],"checksum":2648073337,"timestamp":"2024-06-01T22:42:48.540245Z"}]}
{"channel":"book","type":"update","data":[{"symbol":"ETH/GBP","bids":[{"price":2993.04,"qty":6.14236800}],"asks":[],"checksum":1990536480,"timestamp":"2024-06-01T22:42:49.205752Z"}]}
{"channel":"book","type":"update","data":[{"symbol":"ETH/GBP","bids":[{"price":2996.44,"qty":0.00000000},{"price":2993.01,"qty":1.33100000}],"asks":[],"checksum":1995203106,"timestamp":"2024-06-01T22:42:49.262263Z"}]}
{"channel":"book","type":"update","data":[{"symbol":"ETH/GBP","bids":[{"price":2996.07,"qty":13.09288131}],"asks":[],"checksum":407467047,"timestamp":"2024-06-01T22:42:49.268015Z"}]}
{"channel":"book","type":"update","data":[{"symbol":"ETH/GBP","bids":[{"price":2996.46,"qty":6.54559598}],"asks":[],"checksum":2113746797,"timestamp":"2024-06-01T22:42:49.268124Z"}]}
{"channel":"book","type":"update","data":[{"symbol":"ETH/GBP","bids":[],"asks":[{"price":2996.89,"qty":6.54466118}],"checksum":53216545,"timestamp":"2024-06-01T22:42:49.268140Z"}]}
{"channel":"book","type":"update","data":[{"symbol":"ETH/GBP","bids":[{"price":2996.07,"qty":0.00000000},{"price":2993.04,"qty":6.14236800}],"asks":[],"checksum":3950199022,"timestamp":"2024-06-01T22:42:49.273456Z"}]}
{"channel":"book","type":"update","data":[{"symbol":"ETH/GBP","bids":[],"asks":[{"price":2996.89,"qty":0.00000000},{"price":2998.78,"qty":0.27306760}],"checksum":2336076259,"timestamp":"2024-06-01T22:42:49.273488Z"}]}
{"channel":"book","type":"update","data":[{"symbol":"ETH/GBP","bids":[{"price":2996.46,"qty":0.00000000},{"price":2993.01,"qty":1.33100000}],"asks":[],"checksum":1995203106,"timestamp":"2024-06-01T22:42:49.325478Z"}]}
{"channel":"book","type":"update","data":[{"symbol":"ETH/GBP","bids":[],"asks":[{"price":2996.96,"qty":0.00000000},{"price":2998.91,"qty":9.61753147}],"checksum":816956307,"timestamp":"2024-06-01T22:42:49.325501Z"}]}
{"channel":"book","type":"update","data":[{"symbol":"ETH/GBP","bids":[],"asks":[{"price":2997.04,"qty":13.08869296}],"checksum":291780911,"timestamp":"2024-06-01T22:42:49.330940Z"}]}
{"channel":"book","type":"update","data":[{"symbol":"ETH/GBP","bids":[],"asks":[{"price":2996.66,"qty":6.54517692}],"checksum":2715264005,"timestamp":"2024-06-01T22:42:49.420596Z"}]}
{"channel":"book","type":"update","data":[{"symbol":"ETH/GBP","bids":[{"price":2995.92,"qty":6.54678017}],"asks":[],"checksum":61488701,"timestamp":"2024-06-01T22:42:49.420619Z"}]}
{"channel":"book","type":"update","data":[{"symbol":"ETH/GBP","bids":[{"price":2995.92,"qty":0.00000000},{"price":2993.01,"qty":1.33100000}],"asks":[],"checksum":2715264005,"timestamp":"2024-06-01T22:42:49.426158Z"}]}
{"channel":"book","type":"update","data":[{"symbol":"ETH/GBP","bids":[],"asks":[{"price":2996.66,"qty":0.00000000},{"price":2998.78,"qty":0.27306760}],"checksum":291780911,"timestamp":"2024-06-01T22:42:49.451515Z"}]}
{"channel":"book","type":"update","data":[{"symbol":"ETH/GBP","bids":[],"asks":[{"price":2996.65,"qty":6.54520611}],"checksum":3814228611,"timestamp":"2024-06-01T22:42:49.730345Z"}]}
{"channel":"book","type":"update","data":[{"symbol":"ETH/GBP","bids":[{"price":2995.92,"qty":6.54678017}],"asks":[],"checksum":1092950203,"timestamp":"2024-06-01T22:42:49.730373Z"}]}
{"channel":"book","type":"update","data":[{"symbol":"ETH/GBP","bids":[{"price":2995.93,"qty":13.09351665}],"asks":[],"checksum":251610249,"timestamp":"2024-06-01T22:42:49.730411Z"}]}
{"channel":"book","type":"update","data":[{"symbol":"ETH/GBP","bids":[{"price":2995.92,"qty":0.00000000},{"price":2993.05,"qty":1.33100000}],"asks":[],"checksum":1411730735,"timestamp":"2024-06-01T22:42:49.736014Z"}]}
{"channel":"book","type":"update","data":[{"symbol":"ETH/GBP","bids":[{"price":2995.93,"qty":0.00000000},{"price":2993.04,"qty":6.14236800}],"asks":[],"checksum":1312307969,"timestamp":"2024-06-01T22:42:49.736076Z"}]}
{"channel":"book","type":"update","data":[{"symbol":"ETH/GBP","bids":[],"asks":[{"price":2996.65,"qty":0.00000000},{"price":2998.78,"qty":0.27306760}],"checksum":3154411693,"timestamp":"2024-06-01T22:42:49.788901Z"}]}
{"channel":"book","type":"update","data":[{"symbol":"ETH/GBP","bids":[],"asks":[{"price":2997.04,"qty":0.00000000},{"price":2998.91,"qty":9.61753147}],"checksum":2647751185,"timestamp":"2024-06-01T22:42:49.788921Z"}]}
{"channel":"book","type":"update","data":[{"symbol":"ETH/GBP","bids":[],"asks":[{"price":2996.88,"qty":0.31000000}],"checksum":1541625830,"timestamp":"2024-06-01T22:42:49.791843Z"}]}
{"channel":"book","type":"update","data":[{"symbol":"ETH/GBP","bids":[],"asks":[{"price":2997.57,"qty":0.00000000},{"price":2998.91,"qty":9.61753147}],"checksum":3168842162,"timestamp":"2024-06-01T22:42:49.791933Z"}]}
{"channel":"book","type":"update","data":[{"symbol":"ETH/GBP","bids":[],"asks":[{"price":2996.99,"qty":13.08890188}],"checksum":3664922852,"timestamp":"2024-06-01T22:42:49.793899Z"}]}
{"channel":"book","type":"update","data":[{"symbol":"ETH/GBP","bids":[],"asks":[{"price":2996.63,"qty":6.54523897}],"checksum":340134869,"timestamp":"2024-06-01T22:42:49.837001Z"}]}
{"channel":"book","type":"update","data":[{"symbol":"ETH/GBP","bids":[{"price":2996.46,"qty":6.54558157}],"asks":[],"checksum":176499699,"timestamp":"2024-06-01T22:42:49.837058Z"}]}
{"channel":"book","type":"update","data":[{"symbol":"ETH/GBP","bids":[{"price":2996.46,"qty":0.00000000},{"price":2993.04,"qty":6.14236800}],"asks":[],"checksum":340134869,"timestamp":"2024-06-01T22:42:49.873162Z"}]}
{"channel":"book","type":"update","data":[{"symbol":"ETH/GBP","bids":[],"asks":[{"price":2996.63,"qty":0.00000000},{"price":2998.78,"qty":0.27306760}],"checksum":3664922852,"timestamp":"2024-06-01T22:42:49.915879Z"}]}
{"channel":"book","type":"update","data":[{"symbol":"ETH/GBP","bids":[{"price":2996.48,"qty":6.54554688}],"asks":[],"checksum":1107185198,"timestamp":"2024-06-01T22:42:49.939811Z"}]}
{"channel":"book","type":"update","data":[{"symbol":"ETH/GBP","bids":[],"asks":[{"price":2996.65,"qty":6.54520428}],"checksum":3280717556,"timestamp":"2024-06-01T22:42:49.939991Z"}]}
{"channel":"book","type":"update","data":[{"symbol":"ETH/GBP","bids":[{"price":2995.92,"qty":13.09356035}],"asks":[],"checksum":2620182339,"timestamp":"2024-06-01T22:42:49.940017Z"}]}
{"channel":"book","type":"update","data":[{"symbol":"ETH/GBP","bids":[{"price":2996.48,"qty":0.00000000},{"price":2993.05,"qty":1.33100000}],"asks":[],"checksum":2313455721,"timestamp":"2024-06-01T22:42:49.946019Z"}]}
{"channel":"book","type":"update","data":[{"symbol":"ETH/GBP","bids":[{"price":2995.92,"qty":0.00000000},{"price":2993.04,"qty":6.14236800}],"asks":[],"checksum":1476902974,"timestamp":"2024-06-01T22:42:49.946035Z"}]}
{"channel":"book","type":"update","data":[{"symbol":"ETH/GBP","bids":[],"asks":[{"price":2996.65,"qty":0.00000000},{"price":2998.78,"qty":0.27306760}],"checksum":3664922852,"timestamp":"2024-06-01T22:42:49.946055Z"}]}
{"channel":"book","type":"update","data":[{"symbol":"ETH/GBP","bids":[{"price":2996.46,"qty":6.54558092}],"asks":[],"checksum":2555448877,"timestamp":"2024-06-01T22:42:50.041497Z"}]}
{"channel":"book","type":"update","data":[{"symbol":"ETH/GBP","bids":[],"asks":[{"price":2996.63,"qty":6.54523831}],"checksum":1620539362,"timestamp":"2024-06-01T22:42:50.041570Z"}]}
{"channel":"book","type":"update","data":[{"symbol":"ETH/GBP","bids":[{"price":2996.46,"qty":0.00000000},{"price":2993.04,"qty":6.14236800}],"asks":[],"checksum":582234411,"timestamp":"2024-06-01T22:42:50.057348Z"}]}
{"channel":"book","type":"update","data":[{"symbol":"ETH/GBP","bids":[],"asks":[{"price":2996.99,"qty":0.00000000},{"price":2998.78,"qty":0.27306760}],"checksum":1207061227,"timestamp":"2024-06-01T22:42:50.161976Z"}]}
{"channel":"book","type":"update","data":[{"symbol":"ETH/GBP","bids":[],"asks":[{"price":2996.63,"qty":0.00000000},{"price":2998.91,"qty":9.61753147}],"checksum":3168842162,"timestamp":"2024-06-01T22:42:50.162062Z"}]}
{"channel":"book","type":"update","data":[{"symbol":"ETH/GBP","bids":[{"price":2996.31,"qty":6.54591254}],"asks":[],"checksum":2235498858,"timestamp":"2024-06-01T22:42:50.167602Z"}]}
{"channel":"book","type":"update","data":[{"symbol":"ETH/GBP","bids":[{"price":2995.92,"qty":13.09356035}],"asks":[],"checksum":2346567111,"timestamp":"2024-06-01T22:42:50.167624Z"}]}
{"channel":"book","type":"update","data":[{"symbol":"ETH/GBP","bids":[],"asks":[{"price":2996.51,"qty":6.54550663}],"checksum":145176636,"timestamp":"2024-06-01T22:42:50.167682Z"}]}
{"channel":"book","type":"update","data":[{"symbol":"ETH/GBP","bids":[],"asks":[{"price":2996.90,"qty":13.17455108}],"checksum":2118055263,"timestamp":"2024-06-01T22:42:50.167729Z"}]}
{"channel":"book","type":"update","data":[{"symbol":"ETH/GBP","bids":[],"asks":[{"price":2996.88,"qty":0.00000000},{"price":2998.91,"qty":9.61753147}],"checksum":3660155374,"timestamp":"2024-06-01T22:42:50.170265Z"}]}
{"channel":"book","type":"update","data":[{"symbol":"ETH/GBP","bids":[],"asks":[{"price":2997.46,"qty":0.31000000}],"checksum":1373698508,"timestamp":"2024-06-01T22:42:50.170432Z"}]}
{"channel":"book","type":"update","data":[{"symbol":"ETH/GBP","bids":[{"price":2996.31,"qty":0.00000000},{"price":2993.05,"qty":1.33100000}],"asks":[],"checksum":3073612824,"timestamp":"2024-06-01T22:42:50.192492Z"}]}
{"channel":"book","type":"update","data":[{"symbol":"ETH/GBP","bids":[],"asks":[{"price":2997.74,"qty":0.00000000},{"price":2998.91,"qty":9.61753147}],"checksum":3095328682,"timestamp":"2024-06-01T22:42:50.192536Z"}]}
{"channel":"book","type":"update","data":[{"symbol":"ETH/GBP","bids":[],"asks":[{"price":2996.90,"qty":0.08526900}],"checksum":2110557257,"timestamp":"2024-06-01T22:42:50.192562Z"}]}
{"channel":"book","type":"update","data":[{"symbol":"ETH/GBP","bids":[],"asks":[{"price":2996.51,"qty":0.00000000},{"price":2999.00,"qty":1.00000000}],"checksum":3309104328,"timestamp":"2024-06-01T22:42:50.192657Z"}]}
{"channel":"book","type":"update","data":[{"symbol":"ETH/GBP","bids":[{"price":2995.92,"qty":0.00000000},{"price":2993.04,"qty":6.14236800}],"asks":[],"checksum":3916644127,"timestamp":"2024-06-01T22:42:50.200880Z"}]}
{"channel":"book","type":"update","data":[{"symbol":"ETH/GBP","bids":[{"price":2995.41,"qty":0.00000000},{"price":2993.00,"qty":0.94850883}],"asks":[],"checksum":2119051809,"timestamp":"2024-06-01T22:42:50.201886Z"}]}
{"channel":"book","type":"update","data":[{"symbol":"ETH/GBP","bids":[],"asks":[{"price":2997.55,"qty":1.30864760}],"checksum":3032937398,"timestamp":"2024-06-01T22:42:50.205975Z"}]}
{"channel":"book","type":"update","data":[{"symbol":"ETH/GBP","bids":[{"price":2995.20,"qty":1.30966729}],"asks":[],"checksum":426814480,"timestamp":"2024-06-01T22:42:50.206122Z"}]}
{"channel":"book","type":"update","data":[{"symbol":"ETH/GBP","bids":[{"price":2996.30,"qty":6.54593826}],"asks":[],"checksum":2428691195,"timestamp":"2024-06-01T22:42:50.276042Z"}]}
{"channel":"book","type":"update","data":[{"symbol":"ETH/GBP","bids":[],"asks":[{"price":2996.49,"qty":6.54555602}],"checksum":2753872911,"timestamp":"2024-06-01T22:42:50.276086Z"}]}
{"channel":"book","type":"update","data":[{"symbol":"ETH/GBP","bids":[{"price":2996.30,"qty":0.00000000},{"price":2993.04,"qty":6.14236800}],"asks":[],"checksum":764840676,"timestamp":"2024-06-01T22:42:50.340722Z"}]}
{"channel":"book","type":"update","data":[{"symbol":"ETH/GBP","bids":[],"asks":[{"price":2996.49,"qty":0.00000000},{"price":2998.91,"qty":9.61753147}],"checksum":426814480,"timestamp":"2024-06-01T22:42:50.340769Z"}]}
{"channel":"book","type":"update","data":[{"symbol":"ETH/GBP","bids":[{"price":2995.93,"qty":13.09351665}],"asks":[],"checksum":3129272632,"timestamp":"2024-06-01T22:42:50.377530Z"}]}
{"channel":"book","type":"update","data":[{"symbol":"ETH/GBP","bids":[],"asks":[{"price":2996.50,"qty":6.54551335}],"checksum":1162163726,"timestamp":"2024-06-01T22:42:50.377554Z"}]}
{"channel":"book","type":"update","data":[{"symbol":"ETH/GBP","bids":[{"price":2995.92,"qty":6.54678017}],"asks":[],"checksum":197011209,"timestamp":"2024-06-01T22:42:50.377656Z"}]}
{"channel":"book","type":"update","data":[{"symbol":"ETH/GBP","bids":[],"asks":[{"price":2996.85,"qty":13.08953588}],"checksum":1700543516,"timestamp":"2024-06-01T22:42:50.377691Z"}]}
{"channel":"book","type":"update","data":[{"symbol":"ETH/GBP","bids":[{"price":2995.93,"qty":0.00000000},{"price":2993.05,"qty":1.33100000}],"asks":[],"checksum":4228673950,"timestamp":"2024-06-01T22:42:50.384634Z"}]}
{"channel":"book","type":"update","data":[{"symbol":"ETH/GBP","bids":[],"asks":[{"price":2996.50,"qty":0.00000000},{"price":2998.78,"qty":0.27306760}],"checksum":4234492553,"timestamp":"2024-06-01T22:42:50.384661Z"}]}
{"channel":"book","type":"update","data":[{"symbol":"ETH/GBP","bids":[{"price":2995.92,"qty":0.00000000},{"price":2993.04,"qty":6.14236800}],"asks":[],"checksum":1588679497,"timestamp":"2024-06-01T22:42:50.384714Z"}]}
{"channel":"book","type":"update","data":[{"symbol":"ETH/GBP","bids":[],"asks":[{"price":2997.46,"qty":0.00000000},{"price":2998.91,"qty":9.61753147}],"checksum":2856737370,"timestamp":"2024-06-01T22:42:50.387663Z"}]}
{"channel":"book","type":"update","data":[{"symbol":"ETH/GBP","bids":[{"price":2995.90,"qty":0.00000000},{"price":2993.00,"qty":0.94850883}],"asks":[],"checksum":1637651078,"timestamp":"2024-06-01T22:42:50.387716Z"}]}
{"channel":"book","type":"update","data":[{"symbol":"ETH/GBP","bids":[],"asks":[{"price":2996.77,"qty":0.31000000}],"checksum":137910408,"timestamp":"2024-06-01T22:42:50.387806Z"}]}
{"channel":"book","type":"update","data":[{"symbol":"ETH/GBP","bids":[],"asks":[{"price":2996.85,"qty":0.00000000},{"price":2998.91,"qty":9.61753147}],"checksum":1403913918,"timestamp":"2024-06-01T22:42:50.419727Z"}]}
{"channel":"book","type":"update","data":[{"symbol":"ETH/GBP","bids":[],"asks":[{"price":2996.90,"qty":0.00000000},{"price":2999.00,"qty":1.00000000},{"price":2997.45,"qty":0.08525900}],"checksum":2747145950,"timestamp":"2024-06-01T22:42:50.450660Z"}]}
{"channel":"book","type":"update","data":[{"symbol":"ETH/GBP","bids":[],"asks":[{"price":2996.77,"qty":0.00000000},{"price":2999.00,"qty":1.00000000}],"checksum":3458039556,"timestamp":"2024-06-01T22:42:50.453324Z"}]}
{"channel":"book","type":"update","data":[{"symbol":"ETH/GBP","bids":[{"price":2996.34,"qty":6.54584948}],"asks":[],"checksum":1240405985,"timestamp":"2024-06-01T22:42:50.494314Z"}]}
{"channel":"book","type":"update","data":[{"symbol":"ETH/GBP","bids":[],"asks":[{"price":2996.54,"qty":6.54544644}],"checksum":1128463008,"timestamp":"2024-06-01T22:42:50.494412Z"}]}
{"channel":"book","type":"update","data":[{"symbol":"ETH/GBP","bids":[{"price":2996.34,"qty":0.00000000},{"price":2993.00,"qty":0.94850883}],"asks":[],"checksum":1667111306,"timestamp":"2024-06-01T22:42:50.627068Z"}]}
{"channel":"book","type":"update","data":[{"symbol":"ETH/GBP","bids":[],"asks":[{"price":2996.54,"qty":0.00000000},{"price":2999.00,"qty":1.00000000}],"checksum":3458039556,"timestamp":"2024-06-01T22:42:50.627084Z"}]}
{"channel":"book","type":"update","data":[{"symbol":"ETH/GBP","bids":[],"asks":[{"price":2996.53,"qty":6.54546673}],"checksum":4131323618,"timestamp":"2024-06-01T22:42:50.633485Z"}]}
{"channel":"book","type":"update","data":[{"symbol":"ETH/GBP","bids":[],"asks":[{"price":2997.44,"qty":13.08694419}],"checksum":214606841,"timestamp":"2024-06-01T22:42:50.633636Z"}]}
{"channel":"book","type":"update","data":[{"symbol":"ETH/GBP","bids":[{"price":2996.33,"qty":6.54587959}],"asks":[],"checksum":3157441206,"timestamp":"2024-06-01T22:42:50.633670Z"}]}
{"channel":"book","type":"update","data":[{"symbol":"ETH/GBP","bids":[{"price":2995.94,"qty":13.09347294}],"asks":[],"checksum":2613944426,"timestamp":"2024-06-01T22:42:50.633696Z"}]}
{"channel":"book","type":"update","data":[{"symbol":"ETH/GBP","bids":[],"asks":[{"price":2997.44,"qty":0.00000000},{"price":2998.91,"qty":9.61753147}],"checksum":656522317,"timestamp":"2024-06-01T22:42:50.639198Z"}]}
{"channel":"book","type":"update","data":[{"symbol":"ETH/GBP","bids":[{"price":2996.33,"qty":0.00000000},{"price":2993.04,"qty":6.14236800}],"asks":[],"checksum":2762370266,"timestamp":"2024-06-01T22:42:50.651427Z"}]}
{"channel":"book","type":"update","data":[{"symbol":"ETH/GBP","bids":[],"asks":[{"price":2996.53,"qty":0.00000000},{"price":2999.00,"qty":1.00000000}],"checksum":910013221,"timestamp":"2024-06-01T22:42:50.651485Z"}]}
{"channel":"book","type":"update","data":[{"symbol":"ETH/GBP","bids":[],"asks":[{"price":2998.25,"qty":0.00000000},{"price":2999.31,"qty":1.33100000}],"checksum":4283300998,"timestamp":"2024-06-01T22:42:50.719698Z"}]}
{"channel":"book","type":"update","data":[{"symbol":"ETH/GBP","bids":[],"asks":[{"price":2998.32,"qty":0.00000000},{"price":2999.32,"qty":1.30787255}],"checksum":4033463882,"timestamp":"2024-06-01T22:42:50.719748Z"}]}
{"channel":"book","type":"update","data":[{"symbol":"ETH/GBP","bids":[{"price":2995.95,"qty":0.31000000}],"asks":[],"checksum":567052307,"timestamp":"2024-06-01T22:42:50.722864Z"}]}
{"channel":"book","type":"update","data":[{"symbol":"ETH/GBP","bids":[],"asks":[{"price":2997.37,"qty":0.31000000}],"checksum":1169318649,"timestamp":"2024-06-01T22:42:50.723130Z"}]}
{"channel":"book","type":"update","data":[{"symbol":"ETH/GBP","bids":[],"asks":[{"price":2998.90,"qty":27.29556489}],"checksum":3015585789,"timestamp":"2024-06-01T22:42:50.725060Z"}]}
{"channel":"book","type":"update","data":[{"symbol":"ETH/GBP","bids":[],"asks":[{"price":2997.45,"qty":6.09743325}],"checksum":3115742873,"timestamp":"2024-06-01T22:42:50.725073Z"}]}
{"channel":"book","type":"update","data":[{"symbol":"ETH/GBP","bids":[],"asks":[{"price":2996.49,"qty":6.54554070}],"checksum":1216852970,"timestamp":"2024-06-01T22:42:50.742222Z"}]}
{"channel":"book","type":"update","data":[{"symbol":"ETH/GBP","bids":[{"price":2996.29,"qty":6.54595357}],"asks":[],"checksum":945894888,"timestamp":"2024-06-01T22:42:50.742390Z"}]}
{"channel":"book","type":"update","data":[{"symbol":"ETH/GBP","bids":[{"price":2996.29,"qty":0.00000000},{"price":2993.05,"qty":1.33100000}],"asks":[],"checksum":1216852970,"timestamp":"2024-06-01T22:42:50.784228Z"}]}
{"channel":"book","type":"update","data":[{"symbol":"ETH/GBP","bids":[],"asks":[{"price":2996.49,"qty":0.00000000},{"price":2999.00,"qty":1.00000000}],"checksum":3115742873,"timestamp":"2024-06-01T22:42:50.818137Z"}]}
{"channel":"book","type":"update","data":[{"symbol":"ETH/GBP","bids":[{"price":2996.30,"qty":6.54593000}],"asks":[],"checksum":3035503335,"timestamp":"2024-06-01T22:42:50.842870Z"}]}
{"channel":"book","type":"update","data":[{"symbol":"ETH/GBP","bids":[],"asks":[{"price":2997.36,"qty":13.08728824}],"checksum":2140961471,"timestamp":"2024-06-01T22:42:50.842902Z"}]}
{"channel":"book","type":"update","data":[{"symbol":"ETH/GBP","bids":[],"asks":[{"price":2996.50,"qty":6.54551713}],"checksum":1452134990,"timestamp":"2024-06-01T22:42:50.842954Z"}]}
{"channel":"book","type":"update","data":[{"symbol":"ETH/GBP","bids":[],"asks":[{"price":2997.36,"qty":0.00000000},{"price":2998.91,"qty":9.61753147}],"checksum":1753708994,"timestamp":"2024-06-01T22:42:50.849047Z"}]}
{"channel":"book","type":"update","data":[{"symbol":"ETH/GBP","bids":[],"asks":[{"price":2996.50,"qty":0.00000000},{"price":2999.00,"qty":1.00000000}],"checksum":3035503335,"timestamp":"2024-06-01T22:42:50.849140Z"}]}
{"channel":"book","type":"update","data":[{"symbol":"ETH/GBP","bids":[{"price":2996.30,"qty":0.00000000},{"price":2993.05,"qty":1.33100000}],"asks":[],"checksum":3115742873,"timestamp":"2024-06-01T22:42:50.849170Z"}]}
{"channel":"book","type":"update","data":[{"symbol":"ETH/GBP","bids":[],"asks":[{"price":2996.50,"qty":6.54551844}],"checksum":2883353893,"timestamp":"2024-06-01T22:42:50.962324Z"}]}
{"channel":"book","type":"update","data":[{"symbol":"ETH/GBP","bids":[{"price":2995.96,"qty":6.54668359}],"asks":[],"checksum":123420573,"timestamp":"2024-06-01T22:42:50.962390Z"}]}
{"channel":"book","type":"update","data":[{"symbol":"ETH/GBP","bids":[{"price":2995.96,"qty":0.00000000},{"price":2993.05,"qty":1.33100000}],"asks":[],"checksum":2883353893,"timestamp":"2024-06-01T22:42:50.968204Z"}]}
{"channel":"book","type":"update","data":[{"symbol":"ETH/GBP","bids":[],"asks":[{"price":2996.87,"qty":13.08942971}],"checksum":2905301324,"timestamp":"2024-06-01T22:42:51.043128Z"}]}
{"channel":"book","type":"update","data":[{"symbol":"ETH/GBP","bids":[{"price":2996.31,"qty":6.54591494}],"asks":[],"checksum":4025030014,"timestamp":"2024-06-01T22:42:51.101549Z"}]}
{"channel":"book","type":"update","data":[{"symbol":"ETH/GBP","bids":[],"asks":[{"price":2996.50,"qty":0.00000000},{"price":2998.91,"qty":9.61753147}],"checksum":3153942242,"timestamp":"2024-06-01T22:42:51.119780Z"}]}
{"channel":"book","type":"update","data":[{"symbol":"ETH/GBP","bids":[],"asks":[{"price":2996.48,"qty":6.54557378}],"checksum":851837952,"timestamp":"2024-06-01T22:42:51.125084Z"}]}
{"channel":"book","type":"update","data":[{"symbol":"ETH/GBP","bids":[],"asks":[{"price":2996.87,"qty":0.00000000},{"price":2998.91,"qty":9.61753147}],"checksum":3413360248,"timestamp":"2024-06-01T22:42:51.125155Z"}]}
{"channel":"book","type":"update","data":[{"symbol":"ETH/GBP","bids":[],"asks":[{"price":2996.48,"qty":0.00000000},{"price":2999.00,"qty":1.00000000}],"checksum":4218684075,"timestamp":"2024-06-01T22:42:51.149709Z"}]}
{"channel":"book","type":"update","data":[{"symbol":"ETH/GBP","bids":[{"price":2996.31,"qty":0.00000000},{"price":2993.05,"qty":1.33100000}],"asks":[],"checksum":3115742873,"timestamp":"2024-06-01T22:42:51.164632Z"}]}
{"channel":"book","type":"update","data":[{"symbol":"ETH/GBP","bids":[{"price":2996.31,"qty":6.54592362}],"asks":[],"checksum":3700677162,"timestamp":"2024-06-01T22:42:51.214288Z"}]}
{"channel":"book","type":"update","data":[{"symbol":"ETH/GBP","bids":[{"price":2996.31,"qty":0.00000000},{"price":2993.05,"qty":1.33100000}],"asks":[],"checksum":3115742873,"timestamp":"2024-06-01T22:42:51.230993Z"}]}
{"channel":"book","type":"update","data":[{"symbol":"ETH/GBP","bids":[],"asks":[{"price":2997.36,"qty":6.54363626}],"checksum":1454422577,"timestamp":"2024-06-01T22:42:51.235993Z"}]}
{"channel":"book","type":"update","data":[{"symbol":"ETH/GBP","bids":[],"asks":[{"price":2997.37,"qty":0.00000000},{"price":2999.00,"qty":1.00000000}],"checksum":1785210702,"timestamp":"2024-06-01T22:42:51.238822Z"}]}
{"channel":"book","type":"update","data":[{"symbol":"ETH/GBP","bids":[],"asks":[{"price":2997.28,"qty":0.31000000}],"checksum":2620995910,"timestamp":"2024-06-01T22:42:51.238900Z"}]}
{"channel":"book","type":"update","data":[{"symbol":"ETH/GBP","bids":[],"asks":[{"price":2997.36,"qty":0.00000000},{"price":2999.00,"qty":1.00000000}],"checksum":1637360445,"timestamp":"2024-06-01T22:42:51.240235Z"}]}
{"channel":"book","type":"update","data":[{"symbol":"ETH/GBP","bids":[],"asks":[{"price":2997.27,"qty":13.08767729}],"checksum":2746727953,"timestamp":"2024-06-01T22:42:51.244116Z"}]}
{"channel":"book","type":"update","data":[{"symbol":"ETH/GBP","bids":[],"asks":[{"price":2997.28,"qty":0.00000000},{"price":2999.00,"qty":1.00000000}],"checksum":4150676724,"timestamp":"2024-06-01T22:42:51.246842Z"}]}
{"channel":"book","type":"update","data":[{"symbol":"ETH/GBP","bids":[],"asks":[{"price":2997.19,"qty":0.31000000}],"checksum":3430568139,"timestamp":"2024-06-01T22:42:51.247083Z"}]}
{"channel":"book","type":"update","data":[{"symbol":"ETH/GBP","bids":[],"asks":[{"price":2997.27,"qty":0.00000000},{"price":2999.00,"qty":1.00000000}],"checksum":542208183,"timestamp":"2024-06-01T22:42:51.250087Z"}]}
{"channel":"book","type":"update","data":[{"symbol":"ETH/GBP","bids":[],"asks":[{"price":2997.19,"qty":0.00000000},{"price":2999.31,"qty":1.33100000}],"checksum":245892310,"timestamp":"2024-06-01T22:42:51.252668Z"}]}
{"channel":"book","type":"update","data":[{"symbol":"ETH/GBP","bids":[{"price":2993.05,"qty":0.00000000},{"price":2993.00,"qty":0.94850883},{"price":2993.01,"qty":1.33100000}],"asks":[],"checksum":121873580,"timestamp":"2024-06-01T22:42:51.300647Z"}]}
{"channel":"book","type":"update","data":[{"symbol":"ETH/GBP","bids":[{"price":2995.96,"qty":6.54668184}],"asks":[],"checksum":126087046,"timestamp":"2024-06-01T22:42:51.331678Z"}]}
{"channel":"book","type":"update","data":[{"symbol":"ETH/GBP","bids":[{"price":2995.96,"qty":0.00000000},{"price":2993.01,"qty":1.33100000}],"asks":[],"checksum":121873580,"timestamp":"2024-06-01T22:42:51.336387Z"}]}
{"channel":"book","type":"update","data":[{"symbol":"ETH/GBP","bids":[],"asks":[{"price":2996.47,"qty":6.54558098}],"checksum":2891660146,"timestamp":"2024-06-01T22:42:51.336496Z"}]}
{"channel":"book","type":"update","data":[{"symbol":"ETH/GBP","bids":[],"asks":[{"price":2996.47,"qty":0.00000000},{"price":2999.31,"qty":1.33100000}],"checksum":121873580,"timestamp":"2024-06-01T22:42:51.342585Z"}]}
{"channel":"book","type":"update","data":[{"symbol":"ETH/GBP","bids":[],"asks":[{"price":2996.49,"qty":6.54554404}],"checksum":3068044723,"timestamp":"2024-06-01T22:42:51.437093Z"}]}
{"channel":"book","type":"update","data":[{"symbol":"ETH/GBP","bids":[{"price":2995.96,"qty":6.54668184}],"asks":[],"checksum":3055480473,"timestamp":"2024-06-01T22:42:51.437212Z"}]}
{"channel":"book","type":"update","data":[{"symbol":"ETH/GBP","bids":[],"asks":[{"price":2996.49,"qty":0.00000000},{"price":2999.31,"qty":1.33100000}],"checksum":126087046,"timestamp":"2024-06-01T22:42:51.444289Z"}]}
{"channel":"book","type":"update","data":[{"symbol":"ETH/GBP","bids":[{"price":2995.96,"qty":0.00000000},{"price":2993.01,"qty":1.33100000}],"asks":[],"checksum":121873580,"timestamp":"2024-06-01T22:42:51.444434Z"}]}
{"channel":"book","type":"update","data":[{"symbol":"ETH/GBP","bids":[{"price":2995.94,"qty":0.00000000},{"price":2993.00,"qty":0.94850883}],"asks":[],"checksum":786954657,"timestamp":"2024-06-01T22:42:51.449971Z"}]}
{"channel":"book","type":"update","data":[{"symbol":"ETH/GBP","bids":[{"price":2995.96,"qty":13.09336368}],"asks":[],"checksum":1196587326,"timestamp":"2024-06-01T22:42:51.454095Z"}]}
{"channel":"book","type":"update","data":[{"symbol":"ETH/GBP","bids":[],"asks":[{"price":2996.87,"qty":13.08941806}],"checksum":3089946703,"timestamp":"2024-06-01T22:42:51.454211Z"}]}
{"channel":"book","type":"update","data":[{"symbol":"ETH/GBP","bids":[],"asks":[{"price":2996.87,"qty":0.00000000},{"price":2999.31,"qty":1.33100000}],"checksum":1196587326,"timestamp":"2024-06-01T22:42:51.525277Z"}]}
{"channel":"book","type":"update","data":[{"symbol":"ETH/GBP","bids":[],"asks":[{"price":2996.49,"qty":6.54553946}],"checksum":1330849410,"timestamp":"2024-06-01T22:42:51.557306Z"}]}
{"channel":"book","type":"update","data":[{"symbol":"ETH/GBP","bids":[{"price":2996.32,"qty":6.54589512}],"asks":[],"checksum":4091985657,"timestamp":"2024-06-01T22:42:51.557420Z"}]}
{"channel":"book","type":"update","data":[{"symbol":"ETH/GBP","bids":[],"asks":[{"price":2997.45,"qty":6.01217425},{"price":2996.86,"qty":0.08526700}],"checksum":2621012549,"timestamp":"2024-06-01T22:42:51.630013Z"}]}
{"channel":"book","type":"update","data":[{"symbol":"ETH/GBP","bids":[],"asks":[{"price":2996.49,"qty":0.00000000},{"price":2999.00,"qty":1.00000000}],"checksum":2778124119,"timestamp":"2024-06-01T22:42:51.668277Z"}]}
{"channel":"book","type":"update","data":[{"symbol":"ETH/GBP","bids":[{"price":2995.84,"qty":0.00000000},{"price":2993.01,"qty":1.33100000}],"asks":[],"checksum":4144338908,"timestamp":"2024-06-01T22:42:51.672372Z"}]}
{"channel":"book","type":"update","data":[{"symbol":"ETH/GBP","bids":[],"asks":[{"price":2996.86,"qty":13.17473874}],"checksum":2074511663,"timestamp":"2024-06-01T22:42:51.673494Z"}]}
{"channel":"book","type":"update","data":[{"symbol":"ETH/GBP","bids":[],"asks":[{"price":2996.48,"qty":6.54555779}],"checksum":1879140210,"timestamp":"2024-06-01T22:42:51.673612Z"}]}
{"channel":"book","type":"update","data":[{"symbol":"ETH/GBP","bids":[{"price":2995.83,"qty":7.65819808}],"asks":[],"checksum":3544123882,"timestamp":"2024-06-01T22:42:51.678043Z"}]}
{"channel":"book","type":"update","data":[{"symbol":"ETH/GBP","bids":[],"asks":[{"price":2996.86,"qty":0.08526700}],"checksum":1009536096,"timestamp":"2024-06-01T22:42:51.678183Z"}]}
{"channel":"book","type":"update","data":[{"symbol":"ETH/GBP","bids":[{"price":2996.32,"qty":0.00000000},{"price":2993.01,"qty":1.33100000}],"asks":[],"checksum":4230984923,"timestamp":"2024-06-01T22:42:51.680116Z"}]}
{"channel":"book","type":"update","data":[{"symbol":"ETH/GBP","bids":[],"asks":[{"price":2996.48,"qty":0.00000000},{"price":2999.00,"qty":1.00000000}],"checksum":2486698495,"timestamp":"2024-06-01T22:42:51.686983Z"}]}
{"channel":"book","type":"update","data":[{"symbol":"ETH/GBP","bids":[{"price":2996.29,"qty":6.54595993}],"asks":[],"checksum":2865711472,"timestamp":"2024-06-01T22:42:51.690623Z"}]}
{"channel":"book","type":"update","data":[{"symbol":"ETH/GBP","bids":[{"price":2995.96,"qty":0.00000000},{"price":2993.01,"qty":1.33100000}],"asks":[],"checksum":588883849,"timestamp":"2024-06-01T22:42:51.695985Z"}]}
{"channel":"book","type":"update","data":[{"symbol":"ETH/GBP","bids":[{"price":2996.29,"qty":0.00000000},{"price":2993.00,"qty":0.94850883}],"asks":[],"checksum":1130960234,"timestamp":"2024-06-01T22:42:51.696009Z"}]}
{"channel":"book","type":"update","data":[{"symbol":"ETH/GBP","bids":[{"price":2995.91,"qty":13.17887926}],"asks":[],"checksum":2102671108,"timestamp":"2024-06-01T22:42:51.700390Z"}]}
{"channel":"book","type":"update","data":[{"symbol":"ETH/GBP","bids":[],"asks":[{"price":2996.44,"qty":6.54566526}],"checksum":4128346924,"timestamp":"2024-06-01T22:42:51.792790Z"}]}
{"channel":"book","type":"update","data":[{"symbol":"ETH/GBP","bids":[{"price":2996.26,"qty":6.54602661}],"asks":[],"checksum":1492875432,"timestamp":"2024-06-01T22:42:51.792821Z"}]}
{"channel":"book","type":"update","data":[{"symbol":"ETH/GBP","bids":[],"asks":[{"price":2996.86,"qty":0.00000000},{"price":2999.00,"qty":1.00000000},{"price":2997.53,"qty":0.08525800}],"checksum":1899126940,"timestamp":"2024-06-01T22:42:51.806257Z"}]}
{"channel":"book","type":"update","data":[{"symbol":"ETH/GBP","bids":[],"asks":[{"price":2996.80,"qty":13.08972330}],"checksum":4213351067,"timestamp":"2024-06-01T22:42:51.892235Z"}]}
{"channel":"book","type":"update","data":[{"symbol":"ETH/GBP","bids":[{"price":2996.26,"qty":0.00000000},{"price":2993.00,"qty":0.94850883}],"asks":[],"checksum":2479608910,"timestamp":"2024-06-01T22:42:51.898434Z"}]}
{"channel":"book","type":"update","data":[{"symbol":"ETH/GBP","bids":[{"price":2995.95,"qty":0.00000000},{"price":2992.73,"qty":0.12935847}],"asks":[],"checksum":3005261707,"timestamp":"2024-06-01T22:42:51.901114Z"}]}
{"channel":"book","type":"update","data":[{"symbol":"ETH/GBP","bids":[{"price":2996.27,"qty":6.54600959}],"asks":[],"checksum":4174334871,"timestamp":"2024-06-01T22:42:51.901950Z"}]}
{"channel":"book","type":"update","data":[{"symbol":"ETH/GBP","bids":[{"price":2996.27,"qty":0.00000000},{"price":2992.73,"qty":0.12935847}],"asks":[],"checksum":3005261707,"timestamp":"2024-06-01T22:42:51.957800Z"}]}
{"channel":"book","type":"update","data":[{"symbol":"ETH/GBP","bids":[],"asks":[{"price":2996.44,"qty":0.00000000},{"price":2998.91,"qty":9.61753147}],"checksum":1287690398,"timestamp":"2024-06-01T22:42:51.974064Z"}]}
{"channel":"book","type":"update","data":[{"symbol":"ETH/GBP","bids":[],"asks":[{"price":2996.45,"qty":6.54562401}],"checksum":988453726,"timestamp":"2024-06-01T22:42:51.978382Z"}]}
{"channel":"book","type":"update","data":[{"symbol":"ETH/GBP","bids":[],"asks":[{"price":2996.45,"qty":0.00000000},{"price":2998.91,"qty":9.61753147}],"checksum":1287690398,"timestamp":"2024-06-01T22:42:52.136281Z"}]}
{"channel":"book","type":"update","data":[{"symbol":"ETH/GBP","bids":[],"asks":[{"price":2996.44,"qty":6.54565431}],"checksum":2643456323,"timestamp":"2024-06-01T22:42:52.140835Z"}]}
{"channel":"book","type":"update","data":[{"symbol":"ETH/GBP","bids":[{"price":2995.92,"qty":6.54678017}],"asks":[],"checksum":4067206344,"timestamp":"2024-06-01T22:42:52.140886Z"}]}
{"channel":"book","type":"update","data":[{"symbol":"ETH/GBP","bids":[{"price":2995.92,"qty":0.00000000},{"price":2992.73,"qty":0.12935847}],"asks":[],"checksum":2643456323,"timestamp":"2024-06-01T22:42:52.144818Z"}]}
{"channel":"book","type":"update","data":[{"symbol":"ETH/GBP","bids":[],"asks":[{"price":2996.44,"qty":0.00000000},{"price":2998.91,"qty":9.61753147}],"checksum":1287690398,"timestamp":"2024-06-01T22:42:52.157831Z"}]}
{"channel":"book","type":"update","data":[{"symbol":"ETH/GBP","bids":[],"asks":[{"price":2996.80,"qty":0.00000000},{"price":2999.00,"qty":1.00000000}],"checksum":824027402,"timestamp":"2024-06-01T22:42:52.162385Z"}]}
{"channel":"book","type":"update","data":[{"symbol":"ETH/GBP","bids":[],"asks":[{"price":2997.42,"qty":1.30923223}],"checksum":1308689698,"timestamp":"2024-06-01T22:42:52.165625Z"}]}
{"channel":"book","type":"update","data":[{"symbol":"ETH/GBP","bids":[],"asks":[{"price":2996.79,"qty":13.08975915}],"checksum":2819441300,"timestamp":"2024-06-01T22:42:52.167332Z"}]}
{"channel":"book","type":"update","data":[{"symbol":"ETH/GBP","bids":[],"asks":[{"price":2997.54,"qty":0.00000000},{"price":2998.91,"qty":9.61753147}],"checksum":1510819683,"timestamp":"2024-06-01T22:42:52.168407Z"}]}
{"channel":"book","type":"update","data":[{"symbol":"ETH/GBP","bids":[],"asks":[{"price":2996.79,"qty":0.00000000},{"price":2999.00,"qty":1.00000000}],"checksum":2389939651,"timestamp":"2024-06-01T22:42:52.172185Z"}]}
{"channel":"book","type":"update","data":[{"symbol":"ETH/GBP","bids":[{"price":2995.91,"qty":0.08528400}],"asks":[],"checksum":1616358834,"timestamp":"2024-06-01T22:42:52.205954Z"}]}
{"channel":"book","type":"update","data":[{"symbol":"ETH/GBP","bids":[],"asks":[{"price":2997.34,"qty":0.31000000}],"checksum":2128467026,"timestamp":"2024-06-01T22:42:52.208728Z"}]}
{"channel":"book","type":"update","data":[{"symbol":"ETH/GBP","bids":[{"price":2995.86,"qty":13.09379833}],"asks":[],"checksum":2766352313,"timestamp":"2024-06-01T22:42:52.210039Z"}]}
{"channel":"book","type":"update","data":[{"symbol":"ETH/GBP","bids":[],"asks":[{"price":2996.41,"qty":6.54572577}],"checksum":1805747841,"timestamp":"2024-06-01T22:42:52.243868Z"}]}
{"channel":"book","type":"update","data":[{"symbol":"ETH/GBP","bids":[{"price":2996.24,"qty":6.54607314}],"asks":[],"checksum":2894970347,"timestamp":"2024-06-01T22:42:52.243906Z"}]}
{"channel":"book","type":"update","data":[{"symbol":"ETH/GBP","bids":[],"asks":[{"price":2996.41,"qty":0.00000000},{"price":2998.91,"qty":9.61753147}],"checksum":2218805212,"timestamp":"2024-06-01T22:42:52.284936Z"}]}
{"channel":"book","type":"update","data":[{"symbol":"ETH/GBP","bids":[{"price":2996.24,"qty":0.00000000},{"price":2993.00,"qty":0.94850883}],"asks":[],"checksum":2766352313,"timestamp":"2024-06-01T22:42:52.284973Z"}]}
{"channel":"book","type":"update","data":[{"symbol":"ETH/GBP","bids":[{"price":2995.86,"qty":0.00000000},{"price":2992.73,"qty":0.12935847}],"asks":[],"checksum":2128467026,"timestamp":"2024-06-01T22:42:52.295620Z"}]}
{"channel":"book","type":"update","data":[{"symbol":"ETH/GBP","bids":[],"asks":[{"price":2996.48,"qty":6.54556223}],"checksum":1219251931,"timestamp":"2024-06-01T22:42:52.352254Z"}]}
{"channel":"book","type":"update","data":[{"symbol":"ETH/GBP","bids":[{"price":2995.92,"qty":6.54677078}],"asks":[],"checksum":410555392,"timestamp":"2024-06-01T22:42:52.352479Z"}]}
{"channel":"book","type":"update","data":[{"symbol":"ETH/GBP","bids":[{"price":2995.92,"qty":0.00000000},{"price":2992.73,"qty":0.12935847}],"asks":[],"checksum":1219251931,"timestamp":"2024-06-01T22:42:52.358143Z"}]}
{"channel":"book","type":"update","data":[{"symbol":"ETH/GBP","bids":[],"asks":[{"price":2996.48,"qty":0.00000000},{"price":2998.91,"qty":9.61753147}],"checksum":2128467026,"timestamp":"2024-06-01T22:42:52.385716Z"}]}
{"channel":"book","type":"update","data":[{"symbol":"ETH/GBP","bids":[],"asks":[{"price":2996.85,"qty":13.08951727}],"checksum":3933686097,"timestamp":"2024-06-01T22:42:52.391323Z"}]}
{"channel":"book","type":"update","data":[{"symbol":"ETH/GBP","bids":[],"asks":[{"price":2997.34,"qty":0.00000000},{"price":2998.91,"qty":9.61753147}],"checksum":1433385833,"timestamp":"2024-06-01T22:42:52.393989Z"}]}
{"channel":"book","type":"update","data":[{"symbol":"ETH/GBP","bids":[],"asks":[{"price":2996.77,"qty":0.31000000}],"checksum":2309430929,"timestamp":"2024-06-01T22:42:52.394317Z"}]}
{"channel":"book","type":"update","data":[{"symbol":"ETH/GBP","bids":[],"asks":[{"price":2996.85,"qty":0.00000000},{"price":2998.91,"qty":9.61753147}],"checksum":1594677072,"timestamp":"2024-06-01T22:42:52.395845Z"}]}
{"channel":"book","type":"update","data":[{"symbol":"ETH/GBP","bids":[],"asks":[{"price":2996.77,"qty":0.00000000},{"price":2999.00,"qty":1.00000000}],"checksum":1616358834,"timestamp":"2024-06-01T22:42:52.398432Z"}]}
{"channel":"book","type":"update","data":[{"symbol":"ETH/GBP","bids":[],"asks":[{"price":2997.34,"qty":0.31000000}],"checksum":2128467026,"timestamp":"2024-06-01T22:42:52.398820Z"}]}
{"channel":"book","type":"update","data":[{"symbol":"ETH/GBP","bids":[{"price":2996.30,"qty":6.54594243}],"asks":[],"checksum":2882951593,"timestamp":"2024-06-01T22:42:52.453896Z"}]}
{"channel":"book","type":"update","data":[{"symbol":"ETH/GBP","bids":[],"asks":[{"price":2996.46,"qty":6.54560702}],"checksum":1750300495,"timestamp":"2024-06-01T22:42:52.453985Z"}]}
{"channel":"book","type":"update","data":[{"symbol":"ETH/GBP","bids":[{"price":2995.93,"qty":13.09351665}],"asks":[],"checksum":812967715,"timestamp":"2024-06-01T22:42:52.454187Z"}]}
{"channel":"book","type":"update","data":[{"symbol":"ETH/GBP","bids":[{"price":2996.30,"qty":0.00000000},{"price":2993.00,"qty":0.94850883}],"asks":[],"checksum":2191222270,"timestamp":"2024-06-01T22:42:52.494044Z"}]}
{"channel":"book","type":"update","data":[{"symbol":"ETH/GBP","bids":[{"price":2996.27,"qty":6.54599497}],"asks":[],"checksum":4216722339,"timestamp":"2024-06-01T22:42:52.562637Z"}]}
{"channel":"book","type":"update","data":[{"symbol":"ETH/GBP","bids":[],"asks":[{"price":2996.46,"qty":0.00000000},{"price":2998.91,"qty":9.61753147}],"checksum":799312259,"timestamp":"2024-06-01T22:42:52.683345Z"}]}
{"channel":"book","type":"update","data":[{"symbol":"ETH/GBP","bids":[{"price":2995.93,"qty":0.00000000},{"price":2993.00,"qty":0.94850883}],"asks":[],"checksum":2234745793,"timestamp":"2024-06-01T22:42:52.683412Z"}]}
{"channel":"book","type":"update","data":[{"symbol":"ETH/GBP","bids":[{"price":2996.27,"qty":0.00000000},{"price":2992.73,"qty":0.12935847}],"asks":[],"checksum":2128467026,"timestamp":"2024-06-01T22:42:52.683431Z"}]}
{"channel":"book","type":"update","data":[{"symbol":"ETH/GBP","bids":[],"asks":[{"price":2996.43,"qty":6.54567715}],"checksum":1949914593,"timestamp":"2024-06-01T22:42:52.689504Z"}]}
{"channel":"book","type":"update","data":[{"symbol":"ETH/GBP","bids":[{"price":2996.24,"qty":6.54608051}],"asks":[],"checksum":1935253775,"timestamp":"2024-06-01T22:42:52.689590Z"}]}
{"channel":"book","type":"update","data":[{"symbol":"ETH/GBP","bids":[],"asks":[{"price":2997.33,"qty":13.08740395}],"checksum":2399984948,"timestamp":"2024-06-01T22:42:52.689617Z"}]}
{"channel":"book","type":"update","data":[{"symbol":"ETH/GBP","bids":[{"price":2995.88,"qty":13.09371599}],"asks":[],"checksum":176083378,"timestamp":"2024-06-01T22:42:52.689706Z"}]}
{"channel":"book","type":"update","data":[{"symbol":"ETH/GBP","bids":[],"asks":[{"price":2997.33,"qty":0.00000000},{"price":2998.90,"qty":27.29556489}],"checksum":1870659528,"timestamp":"2024-06-01T22:42:52.696099Z"}]}
{"channel":"book","type":"update","data":[{"symbol":"ETH/GBP","bids":[],"asks":[{"price":2997.45,"qty":0.00000000},{"price":2998.91,"qty":9.61753147}],"checksum":1895267886,"timestamp":"2024-06-01T22:42:52.923798Z"}]}
{"channel":"book","type":"update","data":[{"symbol":"ETH/GBP","bids":[],"asks":[{"price":2998.90,"qty":0.00000000},{"price":2999.00,"qty":1.00000000}],"checksum":4266409976,"timestamp":"2024-06-01T22:42:52.924072Z"}]}
{"channel":"book","type":"update","data":[{"symbol":"ETH/GBP","bids":[],"asks":[{"price":2998.90,"qty":36.94789283}],"checksum":3627930859,"timestamp":"2024-06-01T22:42:52.928917Z"}]}
{"channel":"book","type":"update","data":[{"symbol":"ETH/GBP","bids":[],"asks":[{"price":2996.80,"qty":13.08973499}],"checksum":2546979488,"timestamp":"2024-06-01T22:42:53.062475Z"}]}
{"channel":"book","type":"update","data":[{"symbol":"ETH/GBP","bids":[],"asks":[{"price":2996.43,"qty":0.00000000},{"price":2998.91,"qty":9.61753147}],"checksum":3671740948,"timestamp":"2024-06-01T22:42:53.106053Z"}]}
{"channel":"book","type":"update","data":[{"symbol":"ETH/GBP","bids":[{"price":2996.24,"qty":0.00000000},{"price":2993.00,"qty":0.94850883}],"asks":[],"checksum":2451658775,"timestamp":"2024-06-01T22:42:53.106199Z"}]}
{"channel":"book","type":"update","data":[{"symbol":"ETH/GBP","bids":[],"asks":[{"price":2996.80,"qty":0.00000000},{"price":2999.00,"qty":1.00000000}],"checksum":4125347103,"timestamp":"2024-06-01T22:42:53.111294Z"}]}
{"channel":"book","type":"update","data":[{"symbol":"ETH/GBP","bids":[{"price":2996.22,"qty":6.54610851}],"asks":[],"checksum":2738968367,"timestamp":"2024-06-01T22:42:53.116453Z"}]}
{"channel":"book","type":"update","data":[{"symbol":"ETH/GBP","bids":[],"asks":[{"price":2996.42,"qty":6.54569745}],"checksum":172888657,"timestamp":"2024-06-01T22:42:53.116485Z"}]}
{"channel":"book","type":"update","data":[{"symbol":"ETH/GBP","bids":[{"price":2995.90,"qty":0.31000000}],"asks":[],"checksum":896233408,"timestamp":"2024-06-01T22:42:53.117757Z"}]}
{"channel":"book","type":"update","data":[{"symbol":"ETH/GBP","bids":[],"asks":[{"price":2997.53,"qty":0.00000000},{"price":2999.00,"qty":1.00000000},{"price":2996.79,"qty":0.08526800}],"checksum":3425639711,"timestamp":"2024-06-01T22:42:53.237959Z"}]}
{"channel":"book","type":"update","data":[{"symbol":"ETH/GBP","bids":[],"asks":[{"price":2996.42,"qty":0.00000000},{"price":2999.00,"qty":1.00000000}],"checksum":3171405160,"timestamp":"2024-06-01T22:42:53.335797Z"}]}
{"channel":"book","type":"update","data":[{"symbol":"ETH/GBP","bids":[],"asks":[{"price":2996.39,"qty":6.54577264}],"checksum":3270363234,"timestamp":"2024-06-01T22:42:53.341177Z"}]}
{"channel":"book","type":"update","data":[{"symbol":"ETH/GBP","bids":[],"asks":[{"price":2996.78,"qty":13.08980283}],"checksum":2486396204,"timestamp":"2024-06-01T22:42:53.341201Z"}]}
{"channel":"book","type":"update","data":[{"symbol":"ETH/GBP","bids":[],"asks":[{"price":2996.79,"qty":0.00000000},{"price":2998.91,"qty":9.61753147},{"price":2997.33,"qty":0.08526000}],"checksum":3639730256,"timestamp":"2024-06-01T22:42:53.414994Z"}]}
{"channel":"book","type":"update","data":[{"symbol":"ETH/GBP","bids":[{"price":2996.22,"qty":0.00000000},{"price":2993.01,"qty":1.33100000}],"asks":[],"checksum":2279811303,"timestamp":"2024-06-01T22:42:53.474257Z"}]}
{"channel":"book","type":"update","data":[{"symbol":"ETH/GBP","bids":[{"price":2996.23,"qty":6.54610131}],"asks":[],"checksum":745487042,"timestamp":"2024-06-01T22:42:53.481101Z"}]}
{"channel":"book","type":"update","data":[{"symbol":"ETH/GBP","bids":[{"price":2996.23,"qty":0.00000000},{"price":2993.01,"qty":1.33100000}],"asks":[],"checksum":2279811303,"timestamp":"2024-06-01T22:42:53.705022Z"}]}
{"channel":"book","type":"update","data":[{"symbol":"ETH/GBP","bids":[{"price":2996.24,"qty":6.54608052}],"asks":[],"checksum":2132894817,"timestamp":"2024-06-01T22:42:53.711470Z"}]}
{"channel":"book","type":"update","data":[{"symbol":"ETH/GBP","bids":[],"asks":[{"price":2996.39,"qty":0.00000000},{"price":2998.91,"qty":9.61753147}],"checksum":3716123390,"timestamp":"2024-06-01T22:42:53.752425Z"}]}
{"channel":"book","type":"update","data":[{"symbol":"ETH/GBP","bids":[{"price":2996.24,"qty":0.00000000},{"price":2993.01,"qty":1.33100000}],"asks":[],"checksum":633194104,"timestamp":"2024-06-01T22:42:53.752655Z"}]}
{"channel":"book","type":"update","data":[{"symbol":"ETH/GBP","bids":[],"asks":[{"price":2996.41,"qty":6.54571432}],"checksum":2560989227,"timestamp":"2024-06-01T22:42:53.757463Z"}]}
{"channel":"book","type":"update","data":[{"symbol":"ETH/GBP","bids":[{"price":2995.92,"qty":6.54678017}],"asks":[],"checksum":218404811,"timestamp":"2024-06-01T22:42:53.862974Z"}]}
{"channel":"book","type":"update","data":[{"symbol":"ETH/GBP","bids":[{"price":2995.92,"qty":0.00000000},{"price":2993.01,"qty":1.33100000}],"asks":[],"checksum":2560989227,"timestamp":"2024-06-01T22:42:53.867563Z"}]}
{"channel":"book","type":"update","data":[{"symbol":"ETH/GBP","bids":[],"asks":[{"price":2996.78,"qty":0.00000000},{"price":2998.91,"qty":9.61753147}],"checksum":224897863,"timestamp":"2024-06-01T22:42:53.954908Z"}]}
{"channel":"book","type":"update","data":[{"symbol":"ETH/GBP","bids":[{"price":2995.88,"qty":0.00000000},{"price":2993.00,"qty":0.94850883}],"asks":[],"checksum":2150777783,"timestamp":"2024-06-01T22:42:53.954945Z"}]}
{"channel":"book","type":"update","data":[{"symbol":"ETH/GBP","bids":[],"asks":[{"price":2996.41,"qty":0.00000000},{"price":2999.00,"qty":1.00000000}],"checksum":1819594350,"timestamp":"2024-06-01T22:42:53.955019Z"}]}
{"channel":"book","type":"update","data":[{"symbol":"ETH/GBP","bids":[{"price":2995.92,"qty":13.09356035}],"asks":[],"checksum":3568101169,"timestamp":"2024-06-01T22:42:53.962919Z"}]}
{"channel":"book","type":"update","data":[{"symbol":"ETH/GBP","bids":[],"asks":[{"price":2997.32,"qty":13.08746290}],"checksum":1608332713,"timestamp":"2024-06-01T22:42:53.962956Z"}]}
{"channel":"book","type":"update","data":[{"symbol":"ETH/GBP","bids":[],"asks":[{"price":2996.52,"qty":6.54548484}],"checksum":3171847484,"timestamp":"2024-06-01T22:42:53.962988Z"}]}
{"channel":"book","type":"update","data":[{"symbol":"ETH/GBP","bids":[{"price":2995.92,"qty":0.00000000},{"price":2993.00,"qty":0.94850883}],"asks":[],"checksum":356724744,"timestamp":"2024-06-01T22:42:53.968069Z"}]}
{"channel":"book","type":"update","data":[{"symbol":"ETH/GBP","bids":[],"asks":[{"price":2997.32,"qty":0.00000000},{"price":2998.91,"qty":9.61753147}],"checksum":328921735,"timestamp":"2024-06-01T22:42:53.968089Z"}]}
{"channel":"book","type":"update","data":[{"symbol":"ETH/GBP","bids":[{"price":2995.90,"qty":0.00000000},{"price":2992.73,"qty":0.12935847}],"asks":[],"checksum":3564620205,"timestamp":"2024-06-01T22:42:53.970812Z"}]}
{"channel":"book","type":"update","data":[{"symbol":"ETH/GBP","bids":[{"price":2996.35,"qty":6.54583040}],"asks":[],"checksum":1691315567,"timestamp":"2024-06-01T22:42:53.972801Z"}]}
{"channel":"book","type":"update","data":[{"symbol":"ETH/GBP","bids":[],"asks":[{"price":2996.52,"qty":0.00000000},{"price":2999.00,"qty":1.00000000}],"checksum":3177634191,"timestamp":"2024-06-01T22:42:53.978179Z"}]}
{"channel":"book","type":"update","data":[{"symbol":"ETH/GBP","bids":[{"price":2996.35,"qty":0.00000000},{"price":2992.73,"qty":0.12935847}],"asks":[],"checksum":2878993732,"timestamp":"2024-06-01T22:42:53.978204Z"}]}
{"channel":"book","type":"update","data":[{"symbol":"ETH/GBP","bids":[{"price":2995.83,"qty":7.96819808}],"asks":[],"checksum":673503232,"timestamp":"2024-06-01T22:42:54.027759Z"}]}
{"channel":"book","type":"update","data":[{"symbol":"ETH/GBP","bids":[{"price":2995.83,"qty":7.65819808}],"asks":[],"checksum":2878993732,"timestamp":"2024-06-01T22:42:54.030726Z"}]}
{"channel":"book","type":"update","data":[{"symbol":"ETH/GBP","bids":[{"price":2995.84,"qty":0.31000000}],"asks":[],"checksum":244669230,"timestamp":"2024-06-01T22:42:54.030988Z"}]}
{"channel":"book","type":"update","data":[{"symbol":"ETH/GBP","bids":[],"asks":[{"price":2996.51,"qty":6.54550680}],"checksum":3278735852,"timestamp":"2024-06-01T22:42:54.069755Z"}]}
{"channel":"book","type":"update","data":[{"symbol":"ETH/GBP","bids":[{"price":2996.34,"qty":6.54584319}],"asks":[],"checksum":3445625327,"timestamp":"2024-06-01T22:42:54.076102Z"}]}
{"channel":"book","type":"update","data":[{"symbol":"ETH/GBP","bids":[{"price":2996.34,"qty":0.00000000},{"price":2993.00,"qty":0.94850883}],"asks":[],"checksum":3278735852,"timestamp":"2024-06-01T22:42:54.080494Z"}]}
{"channel":"book","type":"update","data":[{"symbol":"ETH/GBP","bids":[],"asks":[{"price":2996.88,"qty":13.08937469}],"checksum":1315801008,"timestamp":"2024-06-01T22:42:54.163804Z"}]}
{"channel":"book","type":"update","data":[{"symbol":"ETH/GBP","bids":[{"price":2995.92,"qty":13.09356035}],"asks":[],"checksum":3317467987,"timestamp":"2024-06-01T22:42:54.163843Z"}]}
{"channel":"book","type":"update","data":[{"symbol":"ETH/GBP","bids":[{"price":2995.92,"qty":0.00000000},{"price":2993.00,"qty":0.94850883}],"asks":[],"checksum":1315801008,"timestamp":"2024-06-01T22:42:54.168439Z"}]}
{"channel":"book","type":"update","data":[{"symbol":"ETH/GBP","bids":[],"asks":[{"price":2996.51,"qty":0.00000000},{"price":2998.91,"qty":9.61753147}],"checksum":858544293,"timestamp":"2024-06-01T22:42:54.176350Z"}]}
{"channel":"book","type":"update","data":[{"symbol":"ETH/GBP","bids":[],"asks":[{"price":2997.34,"qty":0.00000000},{"price":2999.00,"qty":1.00000000}],"checksum":3853713853,"timestamp":"2024-06-01T22:42:54.179100Z"}]}
{"channel":"book","type":"update","data":[{"symbol":"ETH/GBP","bids":[],"asks":[{"price":2996.80,"qty":0.31000000}],"checksum":970555319,"timestamp":"2024-06-01T22:42:54.179324Z"}]}
{"channel":"book","type":"update","data":[{"symbol":"ETH/GBP","bids":[],"asks":[{"price":2996.53,"qty":6.54546294}],"checksum":795343138,"timestamp":"2024-06-01T22:42:54.180568Z"}]}
{"channel":"book","type":"update","data":[{"symbol":"ETH/GBP","bids":[{"price":2996.36,"qty":6.54580914}],"asks":[],"checksum":1917734532,"timestamp":"2024-06-01T22:42:54.180610Z"}]}
{"channel":"book","type":"update","data":[{"symbol":"ETH/GBP","bids":[],"asks":[{"price":2996.53,"qty":0.00000000},{"price":2998.91,"qty":9.61753147}],"checksum":4064122825,"timestamp":"2024-06-01T22:42:54.388989Z"}]}
{"channel":"book","type":"update","data":[{"symbol":"ETH/GBP","bids":[],"asks":[{"price":2996.52,"qty":6.54547312}],"checksum":1680347151,"timestamp":"2024-06-01T22:42:54.393604Z"}]}
{"channel":"book","type":"update","data":[{"symbol":"ETH/GBP","bids":[{"price":2995.99,"qty":13.09323785}],"asks":[],"checksum":280864101,"timestamp":"2024-06-01T22:42:54.393630Z"}]}
{"channel":"book","type":"update","data":[{"symbol":"ETH/GBP","bids":[{"price":2996.36,"qty":0.00000000},{"price":2993.01,"qty":1.33100000}],"asks":[],"checksum":2315090528,"timestamp":"2024-06-01T22:42:54.426456Z"}]}
{"channel":"book","type":"update","data":[{"symbol":"ETH/GBP","bids":[{"price":2995.99,"qty":0.00000000},{"price":2993.00,"qty":0.94850883}],"asks":[],"checksum":636893181,"timestamp":"2024-06-01T22:42:54.431215Z"}]}
{"channel":"book","type":"update","data":[{"symbol":"ETH/GBP","bids":[{"price":2995.92,"qty":6.54678017}],"asks":[],"checksum":2250976094,"timestamp":"2024-06-01T22:42:54.435859Z"}]}
{"channel":"book","type":"update","data":[{"symbol":"ETH/GBP","bids":[{"price":2995.92,"qty":0.00000000},{"price":2993.00,"qty":0.94850883}],"asks":[],"checksum":636893181,"timestamp":"2024-06-01T22:42:54.440245Z"}]}
{"channel":"book","type":"update","data":[{"symbol":"ETH/GBP","bids":[],"asks":[{"price":2996.52,"qty":0.00000000},{"price":2998.91,"qty":9.61753147}],"checksum":970555319,"timestamp":"2024-06-01T22:42:54.453385Z"}]}
{"channel":"book","type":"update","data":[{"symbol":"ETH/GBP","bids":[],"asks":[{"price":2996.47,"qty":6.54558198}],"checksum":1903544086,"timestamp":"2024-06-01T22:42:54.501855Z"}]}
{"channel":"book","type":"update","data":[{"symbol":"ETH/GBP","bids":[],"asks":[{"price":2996.88,"qty":0.00000000},{"price":2998.91,"qty":9.61753147}],"checksum":76816052,"timestamp":"2024-06-01T22:42:54.501911Z"}]}
{"channel":"book","type":"update","data":[{"symbol":"ETH/GBP","bids":[],"asks":[{"price":2996.80,"qty":0.00000000},{"price":2999.00,"qty":1.00000000}],"checksum":2269887684,"timestamp":"2024-06-01T22:42:54.504765Z"}]}
{"channel":"book","type":"update","data":[{"symbol":"ETH/GBP","bids":[],"asks":[{"price":2996.47,"qty":0.00000000},{"price":2999.31,"qty":1.33100000}],"checksum":3337157671,"timestamp":"2024-06-01T22:42:54.506779Z"}]}
{"channel":"book","type":"update","data":[{"symbol":"ETH/GBP","bids":[],"asks":[{"price":2997.25,"qty":0.31000000}],"checksum":1085323360,"timestamp":"2024-06-01T22:42:54.509797Z"}]}
{"channel":"book","type":"update","data":[{"symbol":"ETH/GBP","bids":[],"asks":[{"price":2997.32,"qty":13.08746290}],"checksum":2152936447,"timestamp":"2024-06-01T22:42:54.511554Z"}]}
{"channel":"book","type":"update","data":[{"symbol":"ETH/GBP","bids":[],"asks":[{"price":2997.32,"qty":0.00000000},{"price":2999.00,"qty":1.00000000}],"checksum":1085323360,"timestamp":"2024-06-01T22:42:54.515497Z"}]}
{"channel":"book","type":"update","data":[{"symbol":"ETH/GBP","bids":[{"price":2996.32,"qty":6.54589321}],"asks":[],"checksum":2714507248,"timestamp":"2024-06-01T22:42:54.560029Z"}]}
{"channel":"book","type":"update","data":[{"symbol":"ETH/GBP","bids":[{"price":2996.32,"qty":0.00000000},{"price":2993.00,"qty":0.94850883}],"asks":[],"checksum":1085323360,"timestamp":"2024-06-01T22:42:54.564981Z"}]}
{"channel":"book","type":"update","data":[{"symbol":"ETH/GBP","bids":[],"asks":[{"price":2997.33,"qty":0.00000000},{"price":2999.31,"qty":1.33100000},{"price":2996.79,"qty":0.08526700}],"checksum":3721964982,"timestamp":"2024-06-01T22:42:54.601297Z"}]}
{"channel":"book","type":"update","data":[{"symbol":"ETH/GBP","bids":[],"asks":[{"price":2997.24,"qty":6.54390436}],"checksum":473395391,"timestamp":"2024-06-01T22:42:54.605387Z"}]}
{"channel":"book","type":"update","data":[{"symbol":"ETH/GBP","bids":[{"price":2995.92,"qty":13.09354549}],"asks":[],"checksum":2082802628,"timestamp":"2024-06-01T22:42:54.605573Z"}]}
{"channel":"book","type":"update","data":[{"symbol":"ETH/GBP","bids":[],"asks":[{"price":2997.25,"qty":0.00000000},{"price":2999.00,"qty":1.00000000}],"checksum":3980578426,"timestamp":"2024-06-01T22:42:54.608078Z"}]}
{"channel":"book","type":"update","data":[{"symbol":"ETH/GBP","bids":[],"asks":[{"price":2997.16,"qty":0.31000000}],"checksum":996675818,"timestamp":"2024-06-01T22:42:54.608245Z"}]}
{"channel":"book","type":"update","data":[{"symbol":"ETH/GBP","bids":[{"price":2995.92,"qty":0.00000000},{"price":2993.00,"qty":0.94850883}],"asks":[],"checksum":3339513446,"timestamp":"2024-06-01T22:42:54.613335Z"}]}
{"channel":"book","type":"update","data":[{"symbol":"ETH/GBP","bids":[],"asks":[{"price":2997.24,"qty":0.00000000},{"price":2999.00,"qty":1.00000000}],"checksum":743290837,"timestamp":"2024-06-01T22:42:54.613383Z"}]}
{"channel":"book","type":"update","data":[{"symbol":"ETH/GBP","bids":[],"asks":[{"price":2997.16,"qty":0.00000000},{"price":2999.31,"qty":1.33100000}],"checksum":1960195599,"timestamp":"2024-06-01T22:42:54.616201Z"}]}
{"channel":"book","type":"update","data":[{"symbol":"ETH/GBP","bids":[],"asks":[{"price":2997.34,"qty":0.31000000}],"checksum":2371115927,"timestamp":"2024-06-01T22:42:54.616560Z"}]}
{"channel":"book","type":"update","data":[{"symbol":"ETH/GBP","bids":[{"price":2996.34,"qty":6.54584804}],"asks":[],"checksum":743566403,"timestamp":"2024-06-01T22:42:54.664566Z"}]}
{"channel":"book","type":"update","data":[{"symbol":"ETH/GBP","bids":[],"asks":[{"price":2996.49,"qty":6.54553707}],"checksum":1227303973,"timestamp":"2024-06-01T22:42:54.715356Z"}]}
{"channel":"book","type":"update","data":[{"symbol":"ETH/GBP","bids":[],"asks":[{"price":2996.89,"qty":13.08934620}],"checksum":3949102034,"timestamp":"2024-06-01T22:42:54.715541Z"}]}
{"channel":"book","type":"update","data":[{"symbol":"ETH/GBP","bids":[],"asks":[{"price":2996.79,"qty":0.00000000},{"price":2998.91,"qty":9.61753147},{"price":2997.24,"qty":0.08526400}],"checksum":1359933698,"timestamp":"2024-06-01T22:42:54.779677Z"}]}
{"channel":"book","type":"update","data":[{"symbol":"ETH/GBP","bids":[{"price":2996.34,"qty":0.00000000},{"price":2993.00,"qty":0.94850883}],"asks":[],"checksum":3587681048,"timestamp":"2024-06-01T22:42:55.019978Z"}]}
{"channel":"book","type":"update","data":[{"symbol":"ETH/GBP","bids":[],"asks":[{"price":2996.49,"qty":0.00000000},{"price":2998.91,"qty":9.61753147}],"checksum":1214897094,"timestamp":"2024-06-01T22:42:55.019996Z"}]}
{"channel":"book","type":"update","data":[{"symbol":"ETH/GBP","bids":[],"asks":[{"price":2997.34,"qty":0.00000000},{"price":2999.00,"qty":1.00000000}],"checksum":829650140,"timestamp":"2024-06-01T22:42:55.022975Z"}]}
{"channel":"book","type":"update","data":[{"symbol":"ETH/GBP","bids":[],"asks":[{"price":2996.81,"qty":0.31000000}],"checksum":638495245,"timestamp":"2024-06-01T22:42:55.023222Z"}]}
{"channel":"book","type":"update","data":[{"symbol":"ETH/GBP","bids":[{"price":2996.35,"qty":6.54582971}],"asks":[],"checksum":2793653339,"timestamp":"2024-06-01T22:42:55.025368Z"}]}
{"channel":"book","type":"update","data":[{"symbol":"ETH/GBP","bids":[],"asks":[{"price":2996.52,"qty":6.54549059}],"checksum":456937487,"timestamp":"2024-06-01T22:42:55.025473Z"}]}
{"channel":"book","type":"update","data":[{"symbol":"ETH/GBP","bids":[{"price":2995.92,"qty":13.09356035}],"asks":[],"checksum":2682399172,"timestamp":"2024-06-01T22:42:55.025513Z"}]}
{"channel":"book","type":"update","data":[{"symbol":"ETH/GBP","bids":[{"price":2995.92,"qty":0.00000000},{"price":2993.01,"qty":1.33100000}],"asks":[],"checksum":456937487,"timestamp":"2024-06-01T22:42:55.031279Z"}]}
{"channel":"book","type":"update","data":[{"symbol":"ETH/GBP","bids":[],"asks":[{"price":2996.52,"qty":0.00000000},{"price":2998.91,"qty":9.61753147}],"checksum":2793653339,"timestamp":"2024-06-01T22:42:55.071306Z"}]}
{"channel":"book","type":"update","data":[{"symbol":"ETH/GBP","bids":[],"asks":[{"price":2996.50,"qty":6.54551678}],"checksum":760509346,"timestamp":"2024-06-01T22:42:55.165507Z"}]}
{"channel":"book","type":"update","data":[{"symbol":"ETH/GBP","bids":[],"asks":[{"price":2998.90,"qty":0.00000000},{"price":2998.91,"qty":9.61753147}],"checksum":3182802987,"timestamp":"2024-06-01T22:42:55.226399Z"}]}
{"channel":"book","type":"update","data":[{"symbol":"ETH/GBP","bids":[],"asks":[{"price":2998.25,"qty":12.87292504}],"checksum":836114467,"timestamp":"2024-06-01T22:42:55.228497Z"}]}
{"channel":"book","type":"update","data":[{"symbol":"ETH/GBP","bids":[{"price":2993.02,"qty":6.14248545}],"asks":[],"checksum":2641361147,"timestamp":"2024-06-01T22:42:55.383554Z"}]}
{"channel":"book","type":"update","data":[{"symbol":"ETH/GBP","bids":[{"price":2993.03,"qty":1.33100000}],"asks":[],"checksum":891537438,"timestamp":"2024-06-01T22:42:55.386520Z"}]}
{"channel":"book","type":"update","data":[{"symbol":"ETH/GBP","bids":[],"asks":[{"price":2996.50,"qty":0.00000000},{"price":2998.91,"qty":9.61753147}],"checksum":1607187408,"timestamp":"2024-06-01T22:42:55.399130Z"}]}
{"channel":"book","type":"update","data":[{"symbol":"ETH/GBP","bids":[{"price":2996.35,"qty":0.00000000},{"price":2993.02,"qty":6.14248545}],"asks":[],"checksum":1827485762,"timestamp":"2024-06-01T22:42:55.399164Z"}]}
{"channel":"book","type":"update","data":[{"symbol":"ETH/GBP","bids":[{"price":2996.36,"qty":6.54581661}],"asks":[],"checksum":4272173178,"timestamp":"2024-06-01T22:42:55.404818Z"}]}
{"channel":"book","type":"update","data":[{"symbol":"ETH/GBP","bids":[],"asks":[{"price":2996.52,"qty":6.54547750}],"checksum":1395740237,"timestamp":"2024-06-01T22:42:55.404859Z"}]}
{"channel":"book","type":"update","data":[{"symbol":"ETH/GBP","bids":[{"price":2995.98,"qty":13.09327898}],"asks":[],"checksum":2189263358,"timestamp":"2024-06-01T22:42:55.405072Z"}]}
{"channel":"book","type":"update","data":[{"symbol":"ETH/GBP","bids":[{"price":2995.98,"qty":0.00000000},{"price":2993.03,"qty":1.33100000}],"asks":[],"checksum":1395740237,"timestamp":"2024-06-01T22:42:55.410040Z"}]}
{"channel":"book","type":"update","data":[{"symbol":"ETH/GBP","bids":[{"price":2996.36,"qty":0.00000000},{"price":2993.02,"qty":6.14248545}],"asks":[],"checksum":3245885045,"timestamp":"2024-06-01T22:42:55.540504Z"}]}
{"channel":"book","type":"update","data":[{"symbol":"ETH/GBP","bids":[],"asks":[{"price":2996.52,"qty":0.00000000},{"price":2998.91,"qty":9.61753147}],"checksum":1827485762,"timestamp":"2024-06-01T22:42:55.540640Z"}]}
{"channel":"book","type":"update","data":[{"symbol":"ETH/GBP","bids":[],"asks":[{"price":2996.50,"qty":6.54551687}],"checksum":2610778481,"timestamp":"2024-06-01T22:42:55.545367Z"}]}
{"channel":"book","type":"update","data":[{"symbol":"ETH/GBP","bids":[{"price":2996.34,"qty":6.54585224}],"asks":[],"checksum":3876035498,"timestamp":"2024-06-01T22:42:55.545518Z"}]}
{"channel":"book","type":"update","data":[{"symbol":"ETH/GBP","bids":[{"price":2996.34,"qty":0.00000000},{"price":2993.02,"qty":6.14248545}],"asks":[],"checksum":2610778481,"timestamp":"2024-06-01T22:42:55.588891Z"}]}
{"channel":"book","type":"update","data":[{"symbol":"ETH/GBP","bids":[{"price":2995.97,"qty":13.09332277}],"asks":[],"checksum":659242540,"timestamp":"2024-06-01T22:42:55.614073Z"}]}
{"channel":"book","type":"update","data":[{"symbol":"ETH/GBP","bids":[{"price":2995.97,"qty":0.00000000},{"price":2993.02,"qty":6.14248545}],"asks":[],"checksum":2610778481,"timestamp":"2024-06-01T22:42:56.346086Z"}]}
{"channel":"book","type":"update","data":[{"symbol":"ETH/GBP","bids":[],"asks":[{"price":2996.50,"qty":0.00000000},{"price":2998.91,"qty":9.61753147}],"checksum":1827485762,"timestamp":"2024-06-01T22:42:56.346132Z"}]}
{"channel":"book","type":"update","data":[{"symbol":"ETH/GBP","bids":[],"asks":[{"price":2996.89,"qty":0.00000000},{"price":2999.00,"qty":1.00000000}],"checksum":1802160621,"timestamp":"2024-06-01T22:42:56.346143Z"}]}
{"channel":"book","type":"update","data":[{"symbol":"ETH/GBP","bids":[],"asks":[{"price":2996.81,"qty":0.00000000},{"price":2999.31,"qty":1.33100000}],"checksum":2240425039,"timestamp":"2024-06-01T22:42:56.349265Z"}]}
{"channel":"book","type":"update","data":[{"symbol":"ETH/GBP","bids":[],"asks":[{"price":2996.57,"qty":6.54536756}],"checksum":553733146,"timestamp":"2024-06-01T22:42:56.351785Z"}]}
{"channel":"book","type":"update","data":[{"symbol":"ETH/GBP","bids":[{"price":2996.03,"qty":13.09307156}],"asks":[],"checksum":1607405285,"timestamp":"2024-06-01T22:42:56.351911Z"}]}
{"channel":"book","type":"update","data":[{"symbol":"ETH/GBP","bids":[],"asks":[{"price":2996.96,"qty":13.08903796}],"checksum":3760038391,"timestamp":"2024-06-01T22:42:56.351927Z"}]}
{"channel":"book","type":"update","data":[{"symbol":"ETH/GBP","bids":[{"price":2996.40,"qty":6.54572601}],"asks":[],"checksum":4189032501,"timestamp":"2024-06-01T22:42:56.351976Z"}]}
{"channel":"book","type":"update","data":[{"symbol":"ETH/GBP","bids":[{"price":2995.20,"qty":0.00000000},{"price":2993.03,"qty":1.33100000}],"asks":[],"checksum":3724075842,"timestamp":"2024-06-01T22:42:56.355733Z"}]}
{"channel":"book","type":"update","data":[{"symbol":"ETH/GBP","bids":[],"asks":[{"price":2996.57,"qty":0.00000000},{"price":2999.00,"qty":1.00000000}],"checksum":1984488343,"timestamp":"2024-06-01T22:42:56.358761Z"}]}
{"channel":"book","type":"update","data":[{"symbol":"ETH/GBP","bids":[{"price":2996.03,"qty":0.00000000},{"price":2993.02,"qty":6.14248545}],"asks":[],"checksum":1458977434,"timestamp":"2024-06-01T22:42:56.358853Z"}]}
{"channel":"book","type":"update","data":[{"symbol":"ETH/GBP","bids":[],"asks":[{"price":2996.96,"qty":0.00000000},{"price":2999.31,"qty":1.33100000}],"checksum":2442056403,"timestamp":"2024-06-01T22:42:56.358912Z"}]}
{"channel":"book","type":"update","data":[{"symbol":"ETH/GBP","bids":[{"price":2996.40,"qty":0.00000000},{"price":2993.00,"qty":0.94850883}],"asks":[],"checksum":3414959217,"timestamp":"2024-06-01T22:42:56.358921Z"}]}
{"channel":"book","type":"update","data":[{"symbol":"ETH/GBP","bids":[],"asks":[{"price":2997.55,"qty":0.00000000},{"price":2999.32,"qty":1.30787255}],"checksum":668156151,"timestamp":"2024-06-01T22:42:56.365575Z"}]}
{"channel":"book","type":"update","data":[{"symbol":"ETH/GBP","bids":[],"asks":[{"price":2997.42,"qty":0.00000000},{"price":2999.72,"qty":0.34280000}],"checksum":2207207063,"timestamp":"2024-06-01T22:42:56.365821Z"}]}
{"channel":"book","type":"update","data":[{"symbol":"ETH/GBP","bids":[],"asks":[{"price":2997.76,"qty":1.30855669}],"checksum":46943096,"timestamp":"2024-06-01T22:42:56.369185Z"}]}
{"channel":"book","type":"update","data":[{"symbol":"ETH/GBP","bids":[{"price":2995.41,"qty":1.30957631}],"asks":[],"checksum":2457894561,"timestamp":"2024-06-01T22:42:56.369271Z"}]}
{"channel":"book","type":"update","data":[{"symbol":"ETH/GBP","bids":[],"asks":[{"price":2998.78,"qty":0.00000000},{"price":2999.72,"qty":0.34280000}],"checksum":3221421242,"timestamp":"2024-06-01T22:42:56.405417Z"}]}
{"channel":"book","type":"update","data":[{"symbol":"ETH/GBP","bids":[{"price":2995.92,"qty":6.54677296}],"asks":[],"checksum":183754619,"timestamp":"2024-06-01T22:42:56.462728Z"}]}
{"channel":"book","type":"update","data":[{"symbol":"ETH/GBP","bids":[],"asks":[{"price":2996.84,"qty":6.54477715}],"checksum":803842064,"timestamp":"2024-06-01T22:42:56.462837Z"}]}
{"channel":"book","type":"update","data":[{"symbol":"ETH/GBP","bids":[{"price":2995.92,"qty":0.00000000},{"price":2993.02,"qty":6.14248545}],"asks":[],"checksum":3843591121,"timestamp":"2024-06-01T22:42:56.468109Z"}]}
{"channel":"book","type":"update","data":[{"symbol":"ETH/GBP","bids":[],"asks":[{"price":2996.84,"qty":0.00000000},{"price":2999.72,"qty":0.34280000}],"checksum":3221421242,"timestamp":"2024-06-01T22:42:56.480155Z"}]}
{"channel":"book","type":"update","data":[{"symbol":"ETH/GBP","bids":[],"asks":[{"price":2997.23,"qty":13.08785196}],"checksum":1798621945,"timestamp":"2024-06-01T22:42:56.560005Z"}]}
{"channel":"book","type":"update","data":[{"symbol":"ETH/GBP","bids":[{"price":2996.28,"qty":13.09197371}],"asks":[],"checksum":2257719259,"timestamp":"2024-06-01T22:42:56.560163Z"}]}
{"channel":"book","type":"update","data":[{"symbol":"ETH/GBP","bids":[],"asks":[{"price":2997.23,"qty":0.00000000},{"price":2999.72,"qty":0.34280000}],"checksum":1777084871,"timestamp":"2024-06-01T22:42:56.568100Z"}]}
{"channel":"book","type":"update","data":[{"symbol":"ETH/GBP","bids":[],"asks":[{"price":2996.84,"qty":6.54478927}],"checksum":3366085517,"timestamp":"2024-06-01T22:42:56.572643Z"}]}
{"channel":"book","type":"update","data":[{"symbol":"ETH/GBP","bids":[{"price":2996.65,"qty":6.54517715}],"asks":[],"checksum":1400540014,"timestamp":"2024-06-01T22:42:56.572739Z"}]}
{"channel":"book","type":"update","data":[{"symbol":"ETH/GBP","bids":[{"price":2996.65,"qty":0.00000000},{"price":2993.03,"qty":1.33100000}],"asks":[],"checksum":3366085517,"timestamp":"2024-06-01T22:42:56.578322Z"}]}
{"channel":"book","type":"update","data":[{"symbol":"ETH/GBP","bids":[],"asks":[{"price":2996.84,"qty":0.00000000},{"price":2999.72,"qty":0.34280000}],"checksum":1777084871,"timestamp":"2024-06-01T22:42:56.586908Z"}]}
{"channel":"book","type":"update","data":[{"symbol":"ETH/GBP","bids":[{"price":2996.28,"qty":0.00000000},{"price":2993.02,"qty":6.14248545}],"asks":[],"checksum":3221421242,"timestamp":"2024-06-01T22:42:56.635500Z"}]}
{"channel":"book","type":"update","data":[{"symbol":"ETH/GBP","bids":[],"asks":[{"price":2997.24,"qty":0.00000000},{"price":2999.73,"qty":1.30769587},{"price":2997.75,"qty":0.08525500}],"checksum":1354847344,"timestamp":"2024-06-01T22:42:56.637060Z"}]}
{"channel":"book","type":"update","data":[{"symbol":"ETH/GBP","bids":[],"asks":[{"price":2999.09,"qty":0.27304802}],"checksum":3678356715,"timestamp":"2024-06-01T22:42:56.657837Z"}]}
{"channel":"book","type":"update","data":[{"symbol":"ETH/GBP","bids":[],"asks":[{"price":2997.72,"qty":1.30910587}],"checksum":2827543582,"timestamp":"2024-06-01T22:42:56.682305Z"}]}
{"channel":"book","type":"update","data":[{"symbol":"ETH/GBP","bids":[{"price":2996.56,"qty":6.54536869}],"asks":[],"checksum":2175558878,"timestamp":"2024-06-01T22:42:56.683202Z"}]}
{"channel":"book","type":"update","data":[{"symbol":"ETH/GBP","bids":[],"asks":[{"price":2996.75,"qty":6.54497495}],"checksum":3197430771,"timestamp":"2024-06-01T22:42:56.683396Z"}]}
{"channel":"book","type":"update","data":[{"symbol":"ETH/GBP","bids":[],"asks":[{"price":2996.75,"qty":0.00000000},{"price":2999.31,"qty":1.33100000}],"checksum":2175558878,"timestamp":"2024-06-01T22:42:56.691063Z"}]}
{"channel":"book","type":"update","data":[{"symbol":"ETH/GBP","bids":[{"price":2996.56,"qty":0.00000000},{"price":2993.02,"qty":6.14248545}],"asks":[],"checksum":2827543582,"timestamp":"2024-06-01T22:42:56.691072Z"}]}
{"channel":"book","type":"update","data":[{"symbol":"ETH/GBP","bids":[],"asks":[{"price":2997.71,"qty":13.08577725}],"checksum":2572739950,"timestamp":"2024-06-01T22:42:56.762757Z"}]}
{"channel":"book","type":"update","data":[{"symbol":"ETH/GBP","bids":[{"price":2995.92,"qty":13.09352495}],"asks":[],"checksum":941440158,"timestamp":"2024-06-01T22:42:56.762783Z"}]}
{"channel":"book","type":"update","data":[{"symbol":"ETH/GBP","bids":[{"price":2995.91,"qty":0.00000000},{"price":2993.02,"qty":6.14248545},{"price":2996.29,"qty":0.08527500}],"asks":[],"checksum":641515611,"timestamp":"2024-06-01T22:42:56.763096Z"}]}
{"channel":"book","type":"update","data":[{"symbol":"ETH/GBP","bids":[],"asks":[{"price":2997.72,"qty":0.00000000},{"price":2999.31,"qty":1.33100000}],"checksum":2545691174,"timestamp":"2024-06-01T22:42:56.765885Z"}]}
{"channel":"book","type":"update","data":[{"symbol":"ETH/GBP","bids":[],"asks":[{"price":2997.68,"qty":1.30914209}],"checksum":2692056785,"timestamp":"2024-06-01T22:42:56.765905Z"}]}
{"channel":"book","type":"update","data":[{"symbol":"ETH/GBP","bids":[{"price":2995.92,"qty":0.00000000},{"price":2993.02,"qty":6.14248545}],"asks":[],"checksum":113281125,"timestamp":"2024-06-01T22:42:56.771362Z"}]}
{"channel":"book","type":"update","data":[{"symbol":"ETH/GBP","bids":[],"asks":[{"price":2997.71,"qty":0.00000000},{"price":2999.31,"qty":1.33100000}],"checksum":3704167016,"timestamp":"2024-06-01T22:42:56.771553Z"}]}
{"channel":"book","type":"update","data":[{"symbol":"ETH/GBP","bids":[{"price":2996.52,"qty":6.54545156}],"asks":[],"checksum":2879770724,"timestamp":"2024-06-01T22:42:56.817333Z"}]}
{"channel":"book","type":"update","data":[{"symbol":"ETH/GBP","bids":[],"asks":[{"price":2996.71,"qty":6.54507478}],"checksum":2782707311,"timestamp":"2024-06-01T22:42:56.817354Z"}]}
{"channel":"book","type":"update","data":[{"symbol":"ETH/GBP","bids":[{"price":2996.52,"qty":0.00000000},{"price":2993.02,"qty":6.14248545}],"asks":[],"checksum":3534779491,"timestamp":"2024-06-01T22:42:56.829416Z"}]}
{"channel":"book","type":"update","data":[{"symbol":"ETH/GBP","bids":[{"price":2996.29,"qty":0.00000000},{"price":2993.00,"qty":0.94850883},{"price":2995.85,"qty":0.08528500}],"asks":[],"checksum":2967553871,"timestamp":"2024-06-01T22:42:56.944546Z"}]}
{"channel":"book","type":"update","data":[{"symbol":"ETH/GBP","bids":[{"price":2996.53,"qty":6.54542931}],"asks":[],"checksum":1118366343,"timestamp":"2024-06-01T22:42:56.950373Z"}]}
{"channel":"book","type":"update","data":[{"symbol":"ETH/GBP","bids":[],"asks":[{"price":2996.71,"qty":0.00000000},{"price":2999.31,"qty":1.33100000}],"checksum":1288799372,"timestamp":"2024-06-01T22:42:56.972285Z"}]}
{"channel":"book","type":"update","data":[{"symbol":"ETH/GBP","bids":[{"price":2996.53,"qty":0.00000000},{"price":2993.02,"qty":6.14248545}],"asks":[],"checksum":3197643076,"timestamp":"2024-06-01T22:42:56.972355Z"}]}
{"channel":"book","type":"update","data":[{"symbol":"ETH/GBP","bids":[],"asks":[{"price":2997.67,"qty":13.08595274}],"checksum":3890884148,"timestamp":"2024-06-01T22:42:56.978642Z"}]}
{"channel":"book","type":"update","data":[{"symbol":"ETH/GBP","bids":[{"price":2995.86,"qty":13.09378631}],"asks":[],"checksum":1279602159,"timestamp":"2024-06-01T22:42:56.978798Z"}]}
{"channel":"book","type":"update","data":[{"symbol":"ETH/GBP","bids":[],"asks":[{"price":2996.72,"qty":6.54503419}],"checksum":752967295,"timestamp":"2024-06-01T22:42:56.980313Z"}]}
{"channel":"book","type":"update","data":[{"symbol":"ETH/GBP","bids":[],"asks":[{"price":2997.64,"qty":1.30915802}],"checksum":3103364590,"timestamp":"2024-06-01T22:42:56.981521Z"}]}
{"channel":"book","type":"update","data":[{"symbol":"ETH/GBP","bids":[],"asks":[{"price":2997.68,"qty":0.00000000},{"price":2999.00,"qty":1.00000000}],"checksum":4230305365,"timestamp":"2024-06-01T22:42:56.981732Z"}]}
{"channel":"book","type":"update","data":[{"symbol":"ETH/GBP","bids":[],"asks":[{"price":2997.67,"qty":0.00000000},{"price":2999.09,"qty":0.27304802}],"checksum":1985457192,"timestamp":"2024-06-01T22:42:56.985144Z"}]}
{"channel":"book","type":"update","data":[{"symbol":"ETH/GBP","bids":[{"price":2995.86,"qty":0.00000000},{"price":2993.02,"qty":6.14248545}],"asks":[],"checksum":1077552981,"timestamp":"2024-06-01T22:42:56.985233Z"}]}
{"channel":"book","type":"update","data":[{"symbol":"ETH/GBP","bids":[],"asks":[{"price":2996.72,"qty":0.00000000},{"price":2999.31,"qty":1.33100000}],"checksum":2915378830,"timestamp":"2024-06-01T22:42:57.060579Z"}]}
{"channel":"book","type":"update","data":[{"symbol":"ETH/GBP","bids":[{"price":2996.55,"qty":6.54539461}],"asks":[],"checksum":4132685864,"timestamp":"2024-06-01T22:42:57.065176Z"}]}
{"channel":"book","type":"update","data":[{"symbol":"ETH/GBP","bids":[{"price":2996.55,"qty":0.00000000},{"price":2993.02,"qty":6.14248545}],"asks":[],"checksum":2915378830,"timestamp":"2024-06-01T22:42:57.087191Z"}]}
{"channel":"book","type":"update","data":[{"symbol":"ETH/GBP","bids":[],"asks":[{"price":2996.76,"qty":6.54496219}],"checksum":1206704227,"timestamp":"2024-06-01T22:42:57.092316Z"}]}
{"channel":"book","type":"update","data":[{"symbol":"ETH/GBP","bids":[{"price":2996.57,"qty":6.54534093}],"asks":[],"checksum":2554368602,"timestamp":"2024-06-01T22:42:57.167692Z"}]}
{"channel":"book","type":"update","data":[{"symbol":"ETH/GBP","bids":[{"price":2996.57,"qty":0.00000000},{"price":2993.02,"qty":6.14248545}],"asks":[],"checksum":1206704227,"timestamp":"2024-06-01T22:42:57.191299Z"}]}
{"channel":"book","type":"update","data":[{"symbol":"ETH/GBP","bids":[],"asks":[{"price":2996.76,"qty":0.00000000},{"price":2999.31,"qty":1.33100000}],"checksum":2915378830,"timestamp":"2024-06-01T22:42:57.191316Z"}]}
{"channel":"book","type":"update","data":[{"symbol":"ETH/GBP","bids":[],"asks":[{"price":2996.74,"qty":6.54500146}],"checksum":1420530134,"timestamp":"2024-06-01T22:42:57.197275Z"}]}
{"channel":"book","type":"update","data":[{"symbol":"ETH/GBP","bids":[],"asks":[{"price":2997.63,"qty":13.08612561}],"checksum":3382527321,"timestamp":"2024-06-01T22:42:57.197414Z"}]}
{"channel":"book","type":"update","data":[{"symbol":"ETH/GBP","bids":[{"price":2995.86,"qty":13.09382258}],"asks":[],"checksum":3768596753,"timestamp":"2024-06-01T22:42:57.197428Z"}]}
{"channel":"book","type":"update","data":[{"symbol":"ETH/GBP","bids":[],"asks":[{"price":2997.63,"qty":0.00000000},{"price":2999.09,"qty":0.27304802}],"checksum":2637861236,"timestamp":"2024-06-01T22:42:57.203482Z"}]}
{"channel":"book","type":"update","data":[{"symbol":"ETH/GBP","bids":[{"price":2995.86,"qty":0.00000000},{"price":2993.02,"qty":6.14248545}],"asks":[],"checksum":1420530134,"timestamp":"2024-06-01T22:42:57.203495Z"}]}
{"channel":"book","type":"update","data":[{"symbol":"ETH/GBP","bids":[],"asks":[{"price":2996.74,"qty":0.00000000},{"price":2999.31,"qty":1.33100000}],"checksum":2915378830,"timestamp":"2024-06-01T22:42:57.270434Z"}]}
{"channel":"book","type":"update","data":[{"symbol":"ETH/GBP","bids":[{"price":2995.86,"qty":6.54691129}],"asks":[],"checksum":2090187750,"timestamp":"2024-06-01T22:42:57.277077Z"}]}
{"channel":"book","type":"update","data":[{"symbol":"ETH/GBP","bids":[{"price":2995.86,"qty":0.00000000},{"price":2993.02,"qty":6.14248545}],"asks":[],"checksum":2915378830,"timestamp":"2024-06-01T22:42:57.282570Z"}]}
{"channel":"book","type":"update","data":[{"symbol":"ETH/GBP","bids":[],"asks":[{"price":2996.59,"qty":6.54533109}],"checksum":66685025,"timestamp":"2024-06-01T22:42:57.301601Z"}]}
{"channel":"book","type":"update","data":[{"symbol":"ETH/GBP","bids":[],"asks":[{"price":2996.59,"qty":0.00000000},{"price":2999.31,"qty":1.33100000}],"checksum":2915378830,"timestamp":"2024-06-01T22:42:57.320706Z"}]}
{"channel":"book","type":"update","data":[{"symbol":"ETH/GBP","bids":[{"price":2995.86,"qty":6.54689403}],"asks":[],"checksum":3251612502,"timestamp":"2024-06-01T22:42:57.385542Z"}]}
{"channel":"book","type":"update","data":[{"symbol":"ETH/GBP","bids":[{"price":2995.86,"qty":0.00000000},{"price":2993.02,"qty":6.14248545}],"asks":[],"checksum":2915378830,"timestamp":"2024-06-01T22:42:57.389784Z"}]}
{"channel":"book","type":"update","data":[{"symbol":"ETH/GBP","bids":[],"asks":[{"price":2996.61,"qty":6.54528260}],"checksum":882939840,"timestamp":"2024-06-01T22:42:57.407885Z"}]}
{"channel":"book","type":"update","data":[{"symbol":"ETH/GBP","bids":[],"asks":[{"price":2997.63,"qty":13.08612561}],"checksum":1013331376,"timestamp":"2024-06-01T22:42:57.408039Z"}]}
{"channel":"book","type":"update","data":[{"symbol":"ETH/GBP","bids":[{"price":2995.86,"qty":13.09378806}],"asks":[],"checksum":1959042213,"timestamp":"2024-06-01T22:42:57.408089Z"}]}
{"channel":"book","type":"update","data":[{"symbol":"ETH/GBP","bids":[{"price":2995.86,"qty":0.00000000},{"price":2993.02,"qty":6.14248545}],"asks":[],"checksum":1013331376,"timestamp":"2024-06-01T22:42:57.413818Z"}]}
{"channel":"book","type":"update","data":[{"symbol":"ETH/GBP","bids":[],"asks":[{"price":2997.63,"qty":0.00000000},{"price":2999.09,"qty":0.27304802}],"checksum":882939840,"timestamp":"2024-06-01T22:42:57.413835Z"}]}
{"channel":"book","type":"update","data":[{"symbol":"ETH/GBP","bids":[],"asks":[{"price":2996.61,"qty":0.00000000},{"price":2999.31,"qty":1.33100000}],"checksum":2915378830,"timestamp":"2024-06-01T22:42:57.442755Z"}]}
{"channel":"book","type":"update","data":[{"symbol":"ETH/GBP","bids":[{"price":2996.41,"qty":6.54570475}],"asks":[],"checksum":1774145964,"timestamp":"2024-06-01T22:42:57.493188Z"}]}
{"channel":"book","type":"update","data":[{"symbol":"ETH/GBP","bids":[],"asks":[{"price":2998.25,"qty":0.00000000},{"price":2999.32,"qty":1.30787255}],"checksum":902441018,"timestamp":"2024-06-01T22:42:57.516235Z"}]}
{"channel":"book","type":"update","data":[{"symbol":"ETH/GBP","bids":[],"asks":[{"price":2998.90,"qty":40.87500782}],"checksum":976580623,"timestamp":"2024-06-01T22:42:57.521876Z"}]}
{"channel":"book","type":"update","data":[{"symbol":"ETH/GBP","bids":[],"asks":[{"price":2996.75,"qty":1.52151021}],"checksum":4034171123,"timestamp":"2024-06-01T22:42:57.522105Z"}]}
{"channel":"book","type":"update","data":[{"symbol":"ETH/GBP","bids":[{"price":2996.41,"qty":0.00000000},{"price":2993.02,"qty":6.14248545}],"asks":[],"checksum":873392081,"timestamp":"2024-06-01T22:42:57.527914Z"}]}
{"channel":"book","type":"update","data":[{"symbol":"ETH/GBP","bids":[],"asks":[{"price":2996.60,"qty":6.54531402}],"checksum":3857763374,"timestamp":"2024-06-01T22:42:57.532233Z"}]}
{"channel":"book","type":"update","data":[{"symbol":"ETH/GBP","bids":[{"price":2993.02,"qty":0.00000000},{"price":2993.00,"qty":0.94850883}],"asks":[],"checksum":4005308033,"timestamp":"2024-06-01T22:42:57.561207Z"}]}
{"channel":"book","type":"update","data":[{"symbol":"ETH/GBP","bids":[{"price":2993.04,"qty":11.76121600}],"asks":[],"checksum":3948999341,"timestamp":"2024-06-01T22:42:57.562191Z"}]}
{"channel":"book","type":"update","data":[{"symbol":"ETH/GBP","bids":[{"price":2993.03,"qty":0.00000000},{"price":2993.00,"qty":0.94850883},{"price":2993.01,"qty":1.33100000}],"asks":[],"checksum":4019528336,"timestamp":"2024-06-01T22:42:57.564229Z"}]}
{"channel":"book","type":"update","data":[{"symbol":"ETH/GBP","bids":[],"asks":[{"price":2996.60,"qty":0.00000000},{"price":2999.09,"qty":0.27304802}],"checksum":3259380534,"timestamp":"2024-06-01T22:42:57.577134Z"}]}
{"channel":"book","type":"update","data":[{"symbol":"ETH/GBP","bids":[{"price":2996.43,"qty":6.54566559}],"asks":[],"checksum":1714954393,"timestamp":"2024-06-01T22:42:57.597517Z"}]}
{"channel":"book","type":"update","data":[{"symbol":"ETH/GBP","bids":[],"asks":[{"price":2996.74,"qty":6.54498877}],"checksum":1387865473,"timestamp":"2024-06-01T22:42:57.668730Z"}]}
{"channel":"book","type":"update","data":[{"symbol":"ETH/GBP","bids":[],"asks":[{"price":2996.97,"qty":13.08900881}],"checksum":1457992457,"timestamp":"2024-06-01T22:42:57.668853Z"}]}
{"channel":"book","type":"update","data":[{"symbol":"ETH/GBP","bids":[{"price":2996.05,"qty":13.09295071}],"asks":[],"checksum":110906563,"timestamp":"2024-06-01T22:42:57.668871Z"}]}
{"channel":"book","type":"update","data":[{"symbol":"ETH/GBP","bids":[],"asks":[{"price":2996.74,"qty":0.00000000},{"price":2999.00,"qty":1.00000000}],"checksum":567004369,"timestamp":"2024-06-01T22:42:57.674110Z"}]}
{"channel":"book","type":"update","data":[{"symbol":"ETH/GBP","bids":[],"asks":[{"price":2996.59,"qty":6.54533023}],"checksum":1992847665,"timestamp":"2024-06-01T22:42:57.770768Z"}]}
{"channel":"book","type":"update","data":[{"symbol":"ETH/GBP","bids":[{"price":2996.43,"qty":0.00000000},{"price":2993.04,"qty":11.76121600}],"asks":[],"checksum":4085755833,"timestamp":"2024-06-01T22:42:57.784747Z"}]}
{"channel":"book","type":"update","data":[{"symbol":"ETH/GBP","bids":[],"asks":[{"price":2996.59,"qty":0.00000000},{"price":2999.00,"qty":1.00000000}],"checksum":1406815868,"timestamp":"2024-06-01T22:42:57.784835Z"}]}
{"channel":"book","type":"update","data":[{"symbol":"ETH/GBP","bids":[{"price":2996.41,"qty":6.54568916}],"asks":[],"checksum":4260055166,"timestamp":"2024-06-01T22:42:57.789656Z"}]}
{"channel":"book","type":"update","data":[{"symbol":"ETH/GBP","bids":[],"asks":[{"price":2996.58,"qty":6.54534065}],"checksum":4242186702,"timestamp":"2024-06-01T22:42:57.887226Z"}]}
{"channel":"book","type":"update","data":[{"symbol":"ETH/GBP","bids":[{"price":2996.41,"qty":0.00000000},{"price":2993.04,"qty":11.76121600}],"asks":[],"checksum":2562378777,"timestamp":"2024-06-01T22:42:57.943046Z"}]}
{"channel":"book","type":"update","data":[{"symbol":"ETH/GBP","bids":[],"asks":[{"price":2996.58,"qty":0.00000000},{"price":2999.00,"qty":1.00000000}],"checksum":1406815868,"timestamp":"2024-06-01T22:42:57.948416Z"}]}
{"channel":"book","type":"update","data":[{"symbol":"ETH/GBP","bids":[{"price":2996.43,"qty":6.54566559}],"asks":[],"checksum":567004369,"timestamp":"2024-06-01T22:42:57.952898Z"}]}
{"channel":"book","type":"update","data":[{"symbol":"ETH/GBP","bids":[],"asks":[{"price":2996.74,"qty":6.54498877}],"checksum":110906563,"timestamp":"2024-06-01T22:42:58.028538Z"}]}
{"channel":"book","type":"update","data":[{"symbol":"ETH/GBP","bids":[],"asks":[{"price":2996.74,"qty":0.00000000},{"price":2999.00,"qty":1.00000000}],"checksum":567004369,"timestamp":"2024-06-01T22:42:58.033511Z"}]}
{"channel":"book","type":"update","data":[{"symbol":"ETH/GBP","bids":[{"price":2996.43,"qty":0.00000000},{"price":2993.05,"qty":1.33100000}],"asks":[],"checksum":3807078534,"timestamp":"2024-06-01T22:42:58.054381Z"}]}
{"channel":"book","type":"update","data":[{"symbol":"ETH/GBP","bids":[{"price":2996.05,"qty":0.00000000},{"price":2993.04,"qty":11.76121600}],"asks":[],"checksum":3056120083,"timestamp":"2024-06-01T22:42:58.058588Z"}]}
{"channel":"book","type":"update","data":[{"symbol":"ETH/GBP","bids":[{"price":2996.44,"qty":6.54562697}],"asks":[],"checksum":1867386908,"timestamp":"2024-06-01T22:42:58.063473Z"}]}
{"channel":"book","type":"update","data":[{"symbol":"ETH/GBP","bids":[{"price":2996.06,"qty":13.09294851}],"asks":[],"checksum":1149407207,"timestamp":"2024-06-01T22:42:58.063555Z"}]}
{"channel":"book","type":"update","data":[{"symbol":"ETH/GBP","bids":[{"price":2996.06,"qty":0.00000000},{"price":2993.05,"qty":1.33100000}],"asks":[],"checksum":1867386908,"timestamp":"2024-06-01T22:42:58.068846Z"}]}
{"channel":"book","type":"update","data":[{"symbol":"ETH/GBP","bids":[],"asks":[{"price":2996.60,"qty":6.54529680}],"checksum":1184905700,"timestamp":"2024-06-01T22:42:58.173257Z"}]}
{"channel":"book","type":"update","data":[{"symbol":"ETH/GBP","bids":[],"asks":[{"price":2996.60,"qty":0.00000000},{"price":2999.00,"qty":1.00000000}],"checksum":1867386908,"timestamp":"2024-06-01T22:42:58.178781Z"}]}
{"channel":"book","type":"update","data":[{"symbol":"ETH/GBP","bids":[{"price":2996.44,"qty":0.00000000},{"price":2993.04,"qty":11.76121600}],"asks":[],"checksum":3056120083,"timestamp":"2024-06-01T22:42:58.235958Z"}]}
{"channel":"book","type":"update","data":[{"symbol":"ETH/GBP","bids":[{"price":2996.45,"qty":6.54560929}],"asks":[],"checksum":2087554729,"timestamp":"2024-06-01T22:42:58.245044Z"}]}
{"channel":"book","type":"update","data":[{"symbol":"ETH/GBP","bids":[{"price":2996.45,"qty":0.00000000},{"price":2993.04,"qty":11.76121600}],"asks":[],"checksum":3056120083,"timestamp":"2024-06-01T22:42:58.249457Z"}]}
{"channel":"book","type":"update","data":[{"symbol":"ETH/GBP","bids":[],"asks":[{"price":2996.64,"qty":6.54522479}],"checksum":3866760028,"timestamp":"2024-06-01T22:42:58.276332Z"}]}
{"channel":"book","type":"update","data":[{"symbol":"ETH/GBP","bids":[{"price":2995.86,"qty":13.09382258}],"asks":[],"checksum":1241178155,"timestamp":"2024-06-01T22:42:58.276389Z"}]}
{"channel":"book","type":"update","data":[{"symbol":"ETH/GBP","bids":[{"price":2995.86,"qty":0.00000000},{"price":2993.04,"qty":11.76121600}],"asks":[],"checksum":3866760028,"timestamp":"2024-06-01T22:42:58.283217Z"}]}
{"channel":"book","type":"update","data":[{"symbol":"ETH/GBP","bids":[],"asks":[{"price":2996.64,"qty":0.00000000},{"price":2999.00,"qty":1.00000000}],"checksum":3056120083,"timestamp":"2024-06-01T22:42:58.283308Z"}]}
{"channel":"book","type":"update","data":[{"symbol":"ETH/GBP","bids":[],"asks":[{"price":2996.62,"qty":6.54526627}],"checksum":967600457,"timestamp":"2024-06-01T22:42:58.388279Z"}]}
{"channel":"book","type":"update","data":[{"symbol":"ETH/GBP","bids":[{"price":2995.86,"qty":6.54691129}],"asks":[],"checksum":908816060,"timestamp":"2024-06-01T22:42:58.388341Z"}]}
{"channel":"book","type":"update","data":[{"symbol":"ETH/GBP","bids":[{"price":2995.86,"qty":0.00000000},{"price":2993.04,"qty":11.76121600}],"asks":[],"checksum":967600457,"timestamp":"2024-06-01T22:42:58.393941Z"}]}
{"channel":"book","type":"update","data":[{"symbol":"ETH/GBP","bids":[],"asks":[{"price":2996.62,"qty":0.00000000},{"price":2999.00,"qty":1.00000000}],"checksum":3056120083,"timestamp":"2024-06-01T22:42:58.454052Z"}]}
{"channel":"book","type":"update","data":[{"symbol":"ETH/GBP","bids":[{"price":2995.86,"qty":13.09382258}],"asks":[],"checksum":430457444,"timestamp":"2024-06-01T22:42:58.528710Z"}]}
{"channel":"book","type":"update","data":[{"symbol":"ETH/GBP","bids":[{"price":2996.44,"qty":6.54564292}],"asks":[],"checksum":984517549,"timestamp":"2024-06-01T22:42:58.528738Z"}]}
{"channel":"book","type":"update","data":[{"symbol":"ETH/GBP","bids":[],"asks":[{"price":2996.74,"qty":6.54498877}],"checksum":502860735,"timestamp":"2024-06-01T22:42:58.528804Z"}]}
{"channel":"book","type":"update","data":[{"symbol":"ETH/GBP","bids":[],"asks":[{"price":2996.74,"qty":0.00000000},{"price":2999.00,"qty":1.00000000}],"checksum":984517549,"timestamp":"2024-06-01T22:42:58.534403Z"}]}
{"channel":"book","type":"update","data":[{"symbol":"ETH/GBP","bids":[{"price":2995.86,"qty":0.00000000},{"price":2993.05,"qty":1.33100000}],"asks":[],"checksum":1537072417,"timestamp":"2024-06-01T22:42:58.534486Z"}]}
{"channel":"book","type":"update","data":[{"symbol":"ETH/GBP","bids":[{"price":2996.44,"qty":0.00000000},{"price":2993.04,"qty":11.76121600}],"asks":[],"checksum":3056120083,"timestamp":"2024-06-01T22:42:58.660994Z"}]}
{"channel":"book","type":"update","data":[{"symbol":"ETH/GBP","bids":[],"asks":[{"price":2996.61,"qty":6.54528678}],"checksum":2429169619,"timestamp":"2024-06-01T22:42:58.666632Z"}]}
{"channel":"book","type":"update","data":[{"symbol":"ETH/GBP","bids":[{"price":2996.45,"qty":6.54562214}],"asks":[],"checksum":3035992606,"timestamp":"2024-06-01T22:42:58.666709Z"}]}
{"channel":"book","type":"update","data":[{"symbol":"ETH/GBP","bids":[],"asks":[{"price":2996.61,"qty":0.00000000},{"price":2999.00,"qty":1.00000000}],"checksum":2405170734,"timestamp":"2024-06-01T22:42:58.688442Z"}]}
{"channel":"book","type":"update","data":[{"symbol":"ETH/GBP","bids":[{"price":2996.07,"qty":13.09286380}],"asks":[],"checksum":2297851493,"timestamp":"2024-06-01T22:42:58.730624Z"}]}
{"channel":"book","type":"update","data":[{"symbol":"ETH/GBP","bids":[],"asks":[{"price":2997.75,"qty":0.00000000},{"price":2999.09,"qty":0.27304802},{"price":2996.96,"qty":0.08526700}],"checksum":124836056,"timestamp":"2024-06-01T22:42:58.836615Z"}]}
{"channel":"book","type":"update","data":[{"symbol":"ETH/GBP","bids":[],"asks":[{"price":2996.74,"qty":6.54498877}],"checksum":2684568085,"timestamp":"2024-06-01T22:42:59.210688Z"}]}
{"channel":"book","type":"update","data":[{"symbol":"ETH/GBP","bids":[],"asks":[{"price":2996.74,"qty":0.00000000},{"price":2999.00,"qty":1.00000000}],"checksum":124836056,"timestamp":"2024-06-01T22:42:59.215231Z"}]}
{"channel":"book","type":"update","data":[{"symbol":"ETH/GBP","bids":[],"asks":[{"price":2998.91,"qty":0.00000000},{"price":2999.09,"qty":0.27304802}],"checksum":2902552572,"timestamp":"2024-06-01T22:42:59.216020Z"}]}
{"channel":"book","type":"update","data":[{"symbol":"ETH/GBP","bids":[],"asks":[{"price":2998.90,"qty":50.49450659}],"checksum":3962191952,"timestamp":"2024-06-01T22:42:59.221771Z"}]}
{"channel":"book","type":"update","data":[{"symbol":"ETH/GBP","bids":[],"asks":[{"price":2996.75,"qty":0.00000000},{"price":2999.31,"qty":1.33100000}],"checksum":1375765982,"timestamp":"2024-06-01T22:42:59.725366Z"}]}
{"channel":"book","type":"update","data":[{"symbol":"ETH/GBP","bids":[],"asks":[{"price":2998.90,"qty":9.61949877}],"checksum":3621891019,"timestamp":"2024-06-01T22:42:59.725387Z"}]}
{"channel":"book","type":"update","data":[{"symbol":"ETH/GBP","bids":[],"asks":[{"price":2996.95,"qty":2.02047318}],"checksum":349462989,"timestamp":"2024-06-01T22:42:59.730645Z"}]}
{"channel":"book","type":"update","data":[{"symbol":"ETH/GBP","bids":[],"asks":[{"price":2996.96,"qty":5.09951802}],"checksum":3090082070,"timestamp":"2024-06-01T22:42:59.730755Z"}]}
{"channel":"book","type":"update","data":[{"symbol":"ETH/GBP","bids":[],"asks":[{"price":2998.89,"qty":16.85679690}],"checksum":433345947,"timestamp":"2024-06-01T22:42:59.730788Z"}]}
{"channel":"book","type":"update","data":[{"symbol":"ETH/GBP","bids":[{"price":2996.45,"qty":0.00000000},{"price":2993.01,"qty":1.33100000}],"asks":[],"checksum":3469126632,"timestamp":"2024-06-01T22:43:00.059167Z"}]}
{"channel":"book","type":"update","data":[{"symbol":"ETH/GBP","bids":[{"price":2996.07,"qty":0.00000000},{"price":2993.00,"qty":0.94850883}],"asks":[],"checksum":3571159075,"timestamp":"2024-06-01T22:43:00.064016Z"}]}
{"channel":"book","type":"update","data":[{"symbol":"ETH/GBP","bids":[],"asks":[{"price":2996.87,"qty":0.31000000}],"checksum":2467504519,"timestamp":"2024-06-01T22:43:00.067224Z"}]}
{"channel":"book","type":"update","data":[{"symbol":"ETH/GBP","bids":[],"asks":[{"price":2996.62,"qty":6.54525980}],"checksum":404210711,"timestamp":"2024-06-01T22:43:00.068798Z"}]}
{"channel":"book","type":"update","data":[{"symbol":"ETH/GBP","bids":[{"price":2996.46,"qty":6.54559647}],"asks":[],"checksum":2070278156,"timestamp":"2024-06-01T22:43:00.068998Z"}]}
{"channel":"book","type":"update","data":[{"symbol":"ETH/GBP","bids":[{"price":2996.08,"qty":13.09286111}],"asks":[],"checksum":3662085271,"timestamp":"2024-06-01T22:43:00.069375Z"}]}
{"channel":"book","type":"update","data":[{"symbol":"ETH/GBP","bids":[{"price":2996.08,"qty":0.00000000},{"price":2993.01,"qty":1.33100000}],"asks":[],"checksum":2070278156,"timestamp":"2024-06-01T22:43:00.074236Z"}]}
{"channel":"book","type":"update","data":[{"symbol":"ETH/GBP","bids":[],"asks":[{"price":2996.62,"qty":0.00000000},{"price":2998.90,"qty":9.61949877}],"checksum":2346805165,"timestamp":"2024-06-01T22:43:00.109879Z"}]}
{"channel":"book","type":"update","data":[{"symbol":"ETH/GBP","bids":[{"price":2996.46,"qty":0.00000000},{"price":2993.00,"qty":0.94850883}],"asks":[],"checksum":2467504519,"timestamp":"2024-06-01T22:43:00.166889Z"}]}
{"channel":"book","type":"update","data":[{"symbol":"ETH/GBP","bids":[],"asks":[{"price":2996.61,"qty":6.54528390}],"checksum":3801510401,"timestamp":"2024-06-01T22:43:00.172540Z"}]}
{"channel":"book","type":"update","data":[{"symbol":"ETH/GBP","bids":[{"price":2996.45,"qty":6.54562069}],"asks":[],"checksum":346984473,"timestamp":"2024-06-01T22:43:00.172653Z"}]}
{"channel":"book","type":"update","data":[{"symbol":"ETH/GBP","bids":[],"asks":[{"price":2996.61,"qty":0.00000000},{"price":2998.90,"qty":9.61949877}],"checksum":268710751,"timestamp":"2024-06-01T22:43:00.254629Z"}]}
{"channel":"book","type":"update","data":[{"symbol":"ETH/GBP","bids":[{"price":2996.45,"qty":0.00000000},{"price":2993.00,"qty":0.94850883}],"asks":[],"checksum":2467504519,"timestamp":"2024-06-01T22:43:00.254688Z"}]}
{"channel":"book","type":"update","data":[{"symbol":"ETH/GBP","bids":[{"price":2996.45,"qty":6.54560171}],"asks":[],"checksum":4265137350,"timestamp":"2024-06-01T22:43:00.322092Z"}]}
{"channel":"book","type":"update","data":[{"symbol":"ETH/GBP","bids":[],"asks":[{"price":2996.62,"qty":6.54526448}],"checksum":3284960556,"timestamp":"2024-06-01T22:43:00.322117Z"}]}
{"channel":"book","type":"update","data":[{"symbol":"ETH/GBP","bids":[{"price":2996.08,"qty":13.09282292}],"asks":[],"checksum":2987116543,"timestamp":"2024-06-01T22:43:00.322168Z"}]}
{"channel":"book","type":"update","data":[{"symbol":"ETH/GBP","bids":[{"price":2996.45,"qty":0.00000000},{"price":2993.01,"qty":1.33100000}],"asks":[],"checksum":76147201,"timestamp":"2024-06-01T22:43:00.328672Z"}]}
{"channel":"book","type":"update","data":[{"symbol":"ETH/GBP","bids":[{"price":2996.08,"qty":0.00000000},{"price":2993.00,"qty":0.94850883}],"asks":[],"checksum":3218545890,"timestamp":"2024-06-01T22:43:00.333124Z"}]}
{"channel":"book","type":"update","data":[{"symbol":"ETH/GBP","bids":[{"price":2995.86,"qty":13.09382258}],"asks":[],"checksum":3079576552,"timestamp":"2024-06-01T22:43:00.690244Z"}]}
{"channel":"book","type":"update","data":[{"symbol":"ETH/GBP","bids":[{"price":2995.86,"qty":19.64073387}],"asks":[],"checksum":3050936139,"timestamp":"2024-06-01T22:43:00.690358Z"}]}
{"channel":"book","type":"update","data":[{"symbol":"ETH/GBP","bids":[{"price":2995.86,"qty":13.09382258}],"asks":[],"checksum":3079576552,"timestamp":"2024-06-01T22:43:00.695552Z"}]}
{"channel":"book","type":"update","data":[{"symbol":"ETH/GBP","bids":[{"price":2995.86,"qty":0.00000000},{"price":2993.00,"qty":0.94850883}],"asks":[],"checksum":3218545890,"timestamp":"2024-06-01T22:43:00.695579Z"}]}
{"channel":"book","type":"update","data":[{"symbol":"ETH/GBP","bids":[{"price":2996.45,"qty":6.54560666}],"asks":[],"checksum":403756682,"timestamp":"2024-06-01T22:43:00.810200Z"}]}
{"channel":"book","type":"update","data":[{"symbol":"ETH/GBP","bids":[{"price":2996.45,"qty":0.00000000},{"price":2993.00,"qty":0.94850883}],"asks":[],"checksum":3218545890,"timestamp":"2024-06-01T22:43:00.869363Z"}]}
{"channel":"book","type":"update","data":[{"symbol":"ETH/GBP","bids":[],"asks":[{"price":2996.62,"qty":0.00000000},{"price":2998.90,"qty":9.61949877}],"checksum":2467504519,"timestamp":"2024-06-01T22:43:00.869382Z"}]}
{"channel":"book","type":"update","data":[{"symbol":"ETH/GBP","bids":[],"asks":[{"price":2996.64,"qty":6.54521239}],"checksum":2739492747,"timestamp":"2024-06-01T22:43:00.874721Z"}]}
{"channel":"book","type":"update","data":[{"symbol":"ETH/GBP","bids":[{"price":2995.86,"qty":6.54691129}],"asks":[],"checksum":1084996425,"timestamp":"2024-06-01T22:43:00.945707Z"}]}
{"channel":"book","type":"update","data":[{"symbol":"ETH/GBP","bids":[{"price":2995.86,"qty":19.64073387}],"asks":[],"checksum":3773350691,"timestamp":"2024-06-01T22:43:00.945793Z"}]}
{"channel":"book","type":"update","data":[{"symbol":"ETH/GBP","bids":[{"price":2995.86,"qty":6.54691129}],"asks":[],"checksum":1084996425,"timestamp":"2024-06-01T22:43:00.951351Z"}]}
{"channel":"book","type":"update","data":[{"symbol":"ETH/GBP","bids":[{"price":2995.86,"qty":0.00000000},{"price":2993.00,"qty":0.94850883}],"asks":[],"checksum":2739492747,"timestamp":"2024-06-01T22:43:00.951450Z"}]}
{"channel":"book","type":"update","data":[{"symbol":"ETH/GBP","bids":[{"price":2995.86,"qty":6.54691129}],"asks":[],"checksum":1084996425,"timestamp":"2024-06-01T22:43:01.126501Z"}]}
{"channel":"book","type":"update","data":[{"symbol":"ETH/GBP","bids":[{"price":2995.86,"qty":0.00000000},{"price":2993.00,"qty":0.94850883}],"asks":[],"checksum":2739492747,"timestamp":"2024-06-01T22:43:01.131016Z"}]}
{"channel":"book","type":"update","data":[{"symbol":"ETH/GBP","bids":[{"price":2995.86,"qty":13.09382258}],"asks":[],"checksum":3804221312,"timestamp":"2024-06-01T22:43:01.162432Z"}]}
{"channel":"book","type":"update","data":[{"symbol":"ETH/GBP","bids":[{"price":2995.86,"qty":0.00000000},{"price":2993.00,"qty":0.94850883}],"asks":[],"checksum":2739492747,"timestamp":"2024-06-01T22:43:01.166901Z"}]}
{"channel":"book","type":"update","data":[{"symbol":"ETH/GBP","bids":[{"price":2996.47,"qty":6.54555822}],"asks":[],"checksum":1216522528,"timestamp":"2024-06-01T22:43:01.232232Z"}]}
{"channel":"book","type":"update","data":[{"symbol":"ETH/GBP","bids":[],"asks":[{"price":2996.64,"qty":0.00000000},{"price":2998.90,"qty":9.61949877}],"checksum":1090830205,"timestamp":"2024-06-01T22:43:01.337806Z"}]}
{"channel":"book","type":"update","data":[{"symbol":"ETH/GBP","bids":[],"asks":[{"price":2996.63,"qty":6.54524656}],"checksum":3053740104,"timestamp":"2024-06-01T22:43:01.342470Z"}]}
{"channel":"book","type":"update","data":[{"symbol":"ETH/GBP","bids":[{"price":2996.10,"qty":13.09273594}],"asks":[],"checksum":19083055,"timestamp":"2024-06-01T22:43:01.540675Z"}]}
{"channel":"book","type":"update","data":[{"symbol":"ETH/GBP","bids":[],"asks":[{"price":2996.63,"qty":0.00000000},{"price":2998.90,"qty":9.61949877}],"checksum":1466428371,"timestamp":"2024-06-01T22:43:01.889383Z"}]}
{"channel":"book","type":"update","data":[{"symbol":"ETH/GBP","bids":[{"price":2996.47,"qty":0.00000000},{"price":2993.03,"qty":1.33100000}],"asks":[],"checksum":3531390866,"timestamp":"2024-06-01T22:43:01.889434Z"}]}
{"channel":"book","type":"update","data":[{"symbol":"ETH/GBP","bids":[{"price":2996.46,"qty":6.54559609}],"asks":[],"checksum":800116356,"timestamp":"2024-06-01T22:43:01.894149Z"}]}
{"channel":"book","type":"update","data":[{"symbol":"ETH/GBP","bids":[],"asks":[{"price":2996.62,"qty":6.54525504}],"checksum":800898281,"timestamp":"2024-06-01T22:43:01.894243Z"}]}
{"channel":"book","type":"update","data":[{"symbol":"ETH/GBP","bids":[],"asks":[{"price":2996.96,"qty":0.08526700}],"checksum":1603623086,"timestamp":"2024-06-01T22:43:01.975793Z"}]}
{"channel":"book","type":"update","data":[{"symbol":"ETH/GBP","bids":[],"asks":[{"price":2996.95,"qty":0.00000000},{"price":2998.90,"qty":9.61949877}],"checksum":1659783347,"timestamp":"2024-06-01T22:43:01.975994Z"}]}
{"channel":"book","type":"update","data":[{"symbol":"ETH/GBP","bids":[],"asks":[{"price":2998.89,"qty":0.00000000},{"price":2999.00,"qty":1.00000000}],"checksum":3241828244,"timestamp":"2024-06-01T22:43:01.976064Z"}]}
{"channel":"book","type":"update","data":[{"symbol":"ETH/GBP","bids":[],"asks":[{"price":2998.25,"qty":13.99558455}],"checksum":727362679,"timestamp":"2024-06-01T22:43:01.980938Z"}]}
{"channel":"book","type":"update","data":[{"symbol":"ETH/GBP","bids":[],"asks":[{"price":2998.32,"qty":1.96953939}],"checksum":3643247317,"timestamp":"2024-06-01T22:43:01.981257Z"}]}
{"channel":"book","type":"update","data":[{"symbol":"ETH/GBP","bids":[],"asks":[{"price":2996.62,"qty":0.00000000},{"price":2998.90,"qty":9.61949877}],"checksum":728250680,"timestamp":"2024-06-01T22:43:02.268940Z"}]}
{"channel":"book","type":"update","data":[{"symbol":"ETH/GBP","bids":[{"price":2996.46,"qty":0.00000000},{"price":2993.03,"qty":1.33100000}],"asks":[],"checksum":3601090606,"timestamp":"2024-06-01T22:43:02.268983Z"}]}
{"channel":"book","type":"update","data":[{"symbol":"ETH/GBP","bids":[],"asks":[{"price":2996.87,"qty":0.00000000},{"price":2999.00,"qty":1.00000000}],"checksum":3723642773,"timestamp":"2024-06-01T22:43:02.271690Z"}]}
{"channel":"book","type":"update","data":[{"symbol":"ETH/GBP","bids":[{"price":2996.47,"qty":6.54557252}],"asks":[],"checksum":2830456922,"timestamp":"2024-06-01T22:43:02.276476Z"}]}
{"channel":"book","type":"update","data":[{"symbol":"ETH/GBP","bids":[],"asks":[{"price":2996.63,"qty":6.54523141}],"checksum":3785789315,"timestamp":"2024-06-01T22:43:02.276523Z"}]}
{"channel":"book","type":"update","data":[{"symbol":"ETH/GBP","bids":[{"price":2996.47,"qty":0.00000000},{"price":2993.03,"qty":1.33100000}],"asks":[],"checksum":2497810508,"timestamp":"2024-06-01T22:43:02.924928Z"}]}
{"channel":"book","type":"update","data":[{"symbol":"ETH/GBP","bids":[],"asks":[{"price":2996.63,"qty":0.00000000},{"price":2999.00,"qty":1.00000000}],"checksum":3723642773,"timestamp":"2024-06-01T22:43:02.924982Z"}]}
{"channel":"book","type":"update","data":[{"symbol":"ETH/GBP","bids":[{"price":2996.10,"qty":0.00000000},{"price":2993.02,"qty":7.16400302}],"asks":[],"checksum":2324010821,"timestamp":"2024-06-01T22:43:02.929806Z"}]}
{"channel":"book","type":"update","data":[{"symbol":"ETH/GBP","bids":[],"asks":[{"price":2996.96,"qty":0.39526700}],"checksum":43202353,"timestamp":"2024-06-01T22:43:02.932599Z"}]}
{"channel":"book","type":"update","data":[{"symbol":"ETH/GBP","bids":[{"price":2996.11,"qty":13.09273002}],"asks":[],"checksum":2853540467,"timestamp":"2024-06-01T22:43:02.934469Z"}]}
{"channel":"book","type":"update","data":[{"symbol":"ETH/GBP","bids":[],"asks":[{"price":2996.64,"qty":6.54520766}],"checksum":3020181445,"timestamp":"2024-06-01T22:43:02.934513Z"}]}
{"channel":"book","type":"update","data":[{"symbol":"ETH/GBP","bids":[{"price":2996.48,"qty":6.54555218}],"asks":[],"checksum":1921939424,"timestamp":"2024-06-01T22:43:02.934602Z"}]}
{"channel":"book","type":"update","data":[{"symbol":"ETH/GBP","bids":[],"asks":[{"price":2996.64,"qty":0.00000000},{"price":2999.00,"qty":1.00000000}],"checksum":1822403158,"timestamp":"2024-06-01T22:43:02.997861Z"}]}
{"channel":"book","type":"update","data":[{"symbol":"ETH/GBP","bids":[],"asks":[{"price":2996.96,"qty":0.08526700}],"checksum":998181331,"timestamp":"2024-06-01T22:43:03.000638Z"}]}
{"channel":"book","type":"update","data":[{"symbol":"ETH/GBP","bids":[],"asks":[{"price":2996.95,"qty":6.54453016}],"checksum":3627915040,"timestamp":"2024-06-01T22:43:03.167793Z"}]}
{"channel":"book","type":"update","data":[{"symbol":"ETH/GBP","bids":[],"asks":[{"price":2996.95,"qty":0.00000000},{"price":2999.00,"qty":1.00000000}],"checksum":998181331,"timestamp":"2024-06-01T22:43:03.172398Z"}]}
{"channel":"book","type":"update","data":[{"symbol":"ETH/GBP","bids":[],"asks":[{"price":2996.64,"qty":6.54522403}],"checksum":3166844079,"timestamp":"2024-06-01T22:43:03.321324Z"}]}
{"channel":"book","type":"update","data":[{"symbol":"ETH/GBP","bids":[],"asks":[{"price":2996.64,"qty":0.00000000},{"price":2999.00,"qty":1.00000000}],"checksum":998181331,"timestamp":"2024-06-01T22:43:03.403897Z"}]}
{"channel":"book","type":"update","data":[{"symbol":"ETH/GBP","bids":[],"asks":[{"price":2996.97,"qty":0.00000000},{"price":2999.09,"qty":0.27304802}],"checksum":17810285,"timestamp":"2024-06-01T22:43:03.532481Z"}]}
{"channel":"book","type":"update","data":[{"symbol":"ETH/GBP","bids":[{"price":2996.48,"qty":0.00000000},{"price":2993.03,"qty":1.33100000}],"asks":[],"checksum":3347446600,"timestamp":"2024-06-01T22:43:03.532508Z"}]}
{"channel":"book","type":"update","data":[{"symbol":"ETH/GBP","bids":[],"asks":[{"price":2997.56,"qty":0.31000000}],"checksum":3291770229,"timestamp":"2024-06-01T22:43:03.535355Z"}]}
{"channel":"book","type":"update","data":[{"symbol":"ETH/GBP","bids":[{"price":2996.11,"qty":0.00000000},{"price":2993.02,"qty":7.16400302}],"asks":[],"checksum":1214961318,"timestamp":"2024-06-01T22:43:03.540002Z"}]}
{"channel":"book","type":"update","data":[{"symbol":"ETH/GBP","bids":[{"price":2996.63,"qty":6.54520792}],"asks":[],"checksum":538542211,"timestamp":"2024-06-01T22:43:03.544802Z"}]}
{"channel":"book","type":"update","data":[{"symbol":"ETH/GBP","bids":[],"asks":[{"price":2996.79,"qty":6.54488035}],"checksum":1846123752,"timestamp":"2024-06-01T22:43:03.544839Z"}]}
{"channel":"book","type":"update","data":[{"symbol":"ETH/GBP","bids":[{"price":2996.12,"qty":13.09268632}],"asks":[],"checksum":1112490576,"timestamp":"2024-06-01T22:43:03.544860Z"}]}
{"channel":"book","type":"update","data":[{"symbol":"ETH/GBP","bids":[],"asks":[{"price":2997.14,"qty":13.08823459}],"checksum":2904175586,"timestamp":"2024-06-01T22:43:03.544888Z"}]}
{"channel":"book","type":"update","data":[{"symbol":"ETH/GBP","bids":[{"price":2996.63,"qty":0.00000000},{"price":2993.03,"qty":1.33100000}],"asks":[],"checksum":2091961803,"timestamp":"2024-06-01T22:43:03.550719Z"}]}
{"channel":"book","type":"update","data":[{"symbol":"ETH/GBP","bids":[{"price":2996.12,"qty":0.00000000},{"price":2993.02,"qty":7.16400302}],"asks":[],"checksum":2249937550,"timestamp":"2024-06-01T22:43:03.550766Z"}]}
{"channel":"book","type":"update","data":[{"symbol":"ETH/GBP","bids":[],"asks":[{"price":2996.79,"qty":0.00000000},{"price":2998.90,"qty":9.61949877}],"checksum":2325907196,"timestamp":"2024-06-01T22:43:03.573809Z"}]}
{"channel":"book","type":"update","data":[{"symbol":"ETH/GBP","bids":[],"asks":[{"price":2997.06,"qty":0.31000000}],"checksum":3786360224,"timestamp":"2024-06-01T22:43:03.576633Z"}]}
{"channel":"book","type":"update","data":[{"symbol":"ETH/GBP","bids":[],"asks":[{"price":2997.56,"qty":0.00000000},{"price":2998.90,"qty":9.61949877}],"checksum":3903514920,"timestamp":"2024-06-01T22:43:03.576704Z"}]}
{"channel":"book","type":"update","data":[{"symbol":"ETH/GBP","bids":[],"asks":[{"price":2997.14,"qty":0.00000000},{"price":2999.00,"qty":1.00000000}],"checksum":2119172560,"timestamp":"2024-06-01T22:43:03.606241Z"}]}
{"channel":"book","type":"update","data":[{"symbol":"ETH/GBP","bids":[{"price":2995.41,"qty":0.00000000},{"price":2993.00,"qty":0.94850883}],"asks":[],"checksum":2190265596,"timestamp":"2024-06-01T22:43:03.606362Z"}]}
{"channel":"book","type":"update","data":[{"symbol":"ETH/GBP","bids":[],"asks":[{"price":2997.06,"qty":0.00000000},{"price":2999.09,"qty":0.27304802}],"checksum":2732906322,"timestamp":"2024-06-01T22:43:03.609261Z"}]}
{"channel":"book","type":"update","data":[{"symbol":"ETH/GBP","bids":[{"price":2995.61,"qty":1.30948997}],"asks":[],"checksum":2900750917,"timestamp":"2024-06-01T22:43:03.610573Z"}]}
{"channel":"book","type":"update","data":[{"symbol":"ETH/GBP","bids":[],"asks":[{"price":2996.86,"qty":6.54474714}],"checksum":561300717,"timestamp":"2024-06-01T22:43:03.677285Z"}]}
{"channel":"book","type":"update","data":[{"symbol":"ETH/GBP","bids":[{"price":2996.68,"qty":6.54510484}],"asks":[],"checksum":855648537,"timestamp":"2024-06-01T22:43:03.677584Z"}]}
{"channel":"book","type":"update","data":[{"symbol":"ETH/GBP","bids":[],"asks":[{"price":2996.86,"qty":0.00000000},{"price":2999.09,"qty":0.27304802}],"checksum":3197181873,"timestamp":"2024-06-01T22:43:03.682918Z"}]}
{"channel":"book","type":"update","data":[{"symbol":"ETH/GBP","bids":[{"price":2996.68,"qty":0.00000000},{"price":2993.02,"qty":7.16400302}],"asks":[],"checksum":2900750917,"timestamp":"2024-06-01T22:43:03.721781Z"}]}
{"channel":"book","type":"update","data":[{"symbol":"ETH/GBP","bids":[],"asks":[{"price":2996.96,"qty":0.00000000},{"price":2999.32,"qty":1.30787255},{"price":2997.55,"qty":0.08525900}],"checksum":544671401,"timestamp":"2024-06-01T22:43:03.723780Z"}]}
{"channel":"book","type":"update","data":[{"symbol":"ETH/GBP","bids":[{"price":2996.33,"qty":13.09176683}],"asks":[],"checksum":2355320712,"timestamp":"2024-06-01T22:43:03.747732Z"}]}
{"channel":"book","type":"update","data":[{"symbol":"ETH/GBP","bids":[],"asks":[{"price":2997.54,"qty":13.08651459}],"checksum":2423335402,"timestamp":"2024-06-01T22:43:03.747902Z"}]}
{"channel":"book","type":"update","data":[{"symbol":"ETH/GBP","bids":[{"price":2993.03,"qty":0.00000000},{"price":2993.00,"qty":0.94850883},{"price":2993.01,"qty":1.33100000}],"asks":[],"checksum":2491742679,"timestamp":"2024-06-01T22:43:03.751417Z"}]}
{"channel":"book","type":"update","data":[{"symbol":"ETH/GBP","bids":[],"asks":[{"price":2997.54,"qty":0.00000000},{"price":2999.09,"qty":0.27304802}],"checksum":2291566517,"timestamp":"2024-06-01T22:43:03.753208Z"}]}
{"channel":"book","type":"update","data":[{"symbol":"ETH/GBP","bids":[],"asks":[{"price":2997.64,"qty":0.00000000},{"price":2999.32,"qty":1.30787255}],"checksum":4129366411,"timestamp":"2024-06-01T22:43:03.774331Z"}]}
{"channel":"book","type":"update","data":[{"symbol":"ETH/GBP","bids":[],"asks":[{"price":2996.87,"qty":6.54471134}],"checksum":2149473876,"timestamp":"2024-06-01T22:43:03.821141Z"}]}
{"channel":"book","type":"update","data":[{"symbol":"ETH/GBP","bids":[{"price":2996.70,"qty":6.54506481}],"asks":[],"checksum":334683421,"timestamp":"2024-06-01T22:43:03.821198Z"}]}
{"channel":"book","type":"update","data":[{"symbol":"ETH/GBP","bids":[],"asks":[{"price":2997.24,"qty":13.08780672}],"checksum":2569493516,"timestamp":"2024-06-01T22:43:03.998874Z"}]}
{"channel":"book","type":"update","data":[{"symbol":"ETH/GBP","bids":[{"price":2995.85,"qty":0.00000000},{"price":2993.01,"qty":1.33100000},{"price":2996.23,"qty":0.08528000}],"asks":[],"checksum":1149786635,"timestamp":"2024-06-01T22:43:04.172397Z"}]}
{"channel":"book","type":"update","data":[{"symbol":"ETH/GBP","bids":[],"asks":[{"price":2996.87,"qty":0.00000000},{"price":2999.09,"qty":0.27304802}],"checksum":3034810745,"timestamp":"2024-06-01T22:43:04.233410Z"}]}
{"channel":"book","type":"update","data":[{"symbol":"ETH/GBP","bids":[],"asks":[{"price":2997.24,"qty":0.00000000},{"price":2999.32,"qty":1.30787255}],"checksum":3093472453,"timestamp":"2024-06-01T22:43:04.238153Z"}]}
{"channel":"book","type":"update","data":[{"symbol":"ETH/GBP","bids":[],"asks":[{"price":2997.47,"qty":0.31000000}],"checksum":2605555894,"timestamp":"2024-06-01T22:43:04.240848Z"}]}
{"channel":"book","type":"update","data":[{"symbol":"ETH/GBP","bids":[],"asks":[{"price":2996.86,"qty":6.54473359}],"checksum":2405505693,"timestamp":"2024-06-01T22:43:04.242693Z"}]}
{"channel":"book","type":"update","data":[{"symbol":"ETH/GBP","bids":[],"asks":[{"price":2997.54,"qty":13.08648403}],"checksum":3376968965,"timestamp":"2024-06-01T22:43:04.242828Z"}]}
{"channel":"book","type":"update","data":[{"symbol":"ETH/GBP","bids":[],"asks":[{"price":2997.54,"qty":0.00000000},{"price":2999.00,"qty":1.00000000}],"checksum":2405505693,"timestamp":"2024-06-01T22:43:04.247916Z"}]}
{"channel":"book","type":"update","data":[{"symbol":"ETH/GBP","bids":[{"price":2996.70,"qty":0.00000000},{"price":2993.01,"qty":1.33100000}],"asks":[],"checksum":1419138218,"timestamp":"2024-06-01T22:43:04.247988Z"}]}
{"channel":"book","type":"update","data":[{"symbol":"ETH/GBP","bids":[{"price":2996.69,"qty":6.54509439}],"asks":[],"checksum":1231701647,"timestamp":"2024-06-01T22:43:04.252039Z"}]}
{"channel":"book","type":"update","data":[{"symbol":"ETH/GBP","bids":[],"asks":[{"price":2996.86,"qty":0.00000000},{"price":2999.09,"qty":0.27304802}],"checksum":1564933284,"timestamp":"2024-06-01T22:43:04.280585Z"}]}
{"channel":"book","type":"update","data":[{"symbol":"ETH/GBP","bids":[{"price":2996.69,"qty":0.00000000},{"price":2993.01,"qty":1.33100000}],"asks":[],"checksum":1085992577,"timestamp":"2024-06-01T22:43:04.280598Z"}]}
{"channel":"book","type":"update","data":[{"symbol":"ETH/GBP","bids":[],"asks":[{"price":2996.84,"qty":6.54477155}],"checksum":2991396997,"timestamp":"2024-06-01T22:43:04.379909Z"}]}
{"channel":"book","type":"update","data":[{"symbol":"ETH/GBP","bids":[{"price":2996.67,"qty":6.54512516}],"asks":[],"checksum":1447715843,"timestamp":"2024-06-01T22:43:04.379943Z"}]}
{"channel":"book","type":"update","data":[{"symbol":"ETH/GBP","bids":[],"asks":[{"price":2997.21,"qty":13.08792646}],"checksum":3947761871,"timestamp":"2024-06-01T22:43:04.533159Z"}]}
{"channel":"book","type":"update","data":[{"symbol":"ETH/GBP","bids":[{"price":2993.55,"qty":1.60405540}],"asks":[],"checksum":234556035,"timestamp":"2024-06-01T22:43:04.557484Z"}]}
{"channel":"book","type":"update","data":[{"symbol":"ETH/GBP","bids":[{"price":2996.67,"qty":0.00000000},{"price":2993.00,"qty":0.94850883}],"asks":[],"checksum":3203620837,"timestamp":"2024-06-01T22:43:04.563127Z"}]}
{"channel":"book","type":"update","data":[{"symbol":"ETH/GBP","bids":[],"asks":[{"price":2997.21,"qty":0.00000000},{"price":2999.00,"qty":1.00000000}],"checksum":66530089,"timestamp":"2024-06-01T22:43:04.563169Z"}]}
{"channel":"book","type":"update","data":[{"symbol":"ETH/GBP","bids":[],"asks":[{"price":2996.84,"qty":0.00000000},{"price":2999.09,"qty":0.27304802}],"checksum":4043365677,"timestamp":"2024-06-01T22:43:04.563223Z"}]}
{"channel":"book","type":"update","data":[{"symbol":"ETH/GBP","bids":[],"asks":[{"price":2997.76,"qty":0.00000000},{"price":2999.32,"qty":1.30787255}],"checksum":2873598537,"timestamp":"2024-06-01T22:43:04.563295Z"}]}
{"channel":"book","type":"update","data":[{"symbol":"ETH/GBP","bids":[],"asks":[{"price":2998.90,"qty":0.00000000},{"price":2999.64,"qty":1.33100000}],"checksum":2316306742,"timestamp":"2024-06-01T22:43:04.565132Z"}]}
{"channel":"book","type":"update","data":[{"symbol":"ETH/GBP","bids":[],"asks":[{"price":2999.00,"qty":0.00000000},{"price":2999.72,"qty":0.34280000}],"checksum":4066284397,"timestamp":"2024-06-01T22:43:04.566356Z"}]}
{"channel":"book","type":"update","data":[{"symbol":"ETH/GBP","bids":[],"asks":[{"price":2999.00,"qty":9.62103943}],"checksum":3465736814,"timestamp":"2024-06-01T22:43:04.569653Z"}]}
{"channel":"book","type":"update","data":[{"symbol":"ETH/GBP","bids":[{"price":2996.33,"qty":0.00000000},{"price":2992.73,"qty":0.12935847}],"asks":[],"checksum":2228483299,"timestamp":"2024-06-01T22:43:04.569760Z"}]}
{"channel":"book","type":"update","data":[{"symbol":"ETH/GBP","bids":[],"asks":[{"price":2998.33,"qty":0.00000000},{"price":2999.72,"qty":0.34280000}],"checksum":1680032288,"timestamp":"2024-06-01T22:43:04.571888Z"}]}
{"channel":"book","type":"update","data":[{"symbol":"ETH/GBP","bids":[],"asks":[{"price":2999.00,"qty":0.00000000},{"price":2999.73,"qty":1.30769587}],"checksum":1804643100,"timestamp":"2024-06-01T22:43:04.572615Z"}]}
{"channel":"book","type":"update","data":[{"symbol":"ETH/GBP","bids":[],"asks":[{"price":2999.02,"qty":9.62036971}],"checksum":1234316135,"timestamp":"2024-06-01T22:43:04.577074Z"}]}
{"channel":"book","type":"update","data":[{"symbol":"ETH/GBP","bids":[],"asks":[{"price":2996.96,"qty":6.54450963}],"checksum":1388162466,"timestamp":"2024-06-01T22:43:04.580441Z"}]}
{"channel":"book","type":"update","data":[{"symbol":"ETH/GBP","bids":[{"price":2996.79,"qty":6.54487026}],"asks":[],"checksum":3473760278,"timestamp":"2024-06-01T22:43:04.580458Z"}]}
{"channel":"book","type":"update","data":[{"symbol":"ETH/GBP","bids":[],"asks":[{"price":2997.97,"qty":1.30846436}],"checksum":3408428164,"timestamp":"2024-06-01T22:43:04.580477Z"}]}
{"channel":"book","type":"update","data":[{"symbol":"ETH/GBP","bids":[],"asks":[{"price":2998.71,"qty":1.30814089}],"checksum":3446489807,"timestamp":"2024-06-01T22:43:04.580540Z"}]}
{"channel":"book","type":"update","data":[{"symbol":"ETH/GBP","bids":[{"price":2996.24,"qty":13.09215146}],"asks":[],"checksum":299537016,"timestamp":"2024-06-01T22:43:04.580578Z"}]}
{"channel":"book","type":"update","data":[{"symbol":"ETH/GBP","bids":[{"price":2995.00,"qty":1.30975736}],"asks":[],"checksum":371091596,"timestamp":"2024-06-01T22:43:04.580589Z"}]}
{"channel":"book","type":"update","data":[{"symbol":"ETH/GBP","bids":[{"price":2996.24,"qty":0.00000000},{"price":2993.55,"qty":1.60405540}],"asks":[],"checksum":205787463,"timestamp":"2024-06-01T22:43:04.587092Z"}]}
{"channel":"book","type":"update","data":[{"symbol":"ETH/GBP","bids":[],"asks":[{"price":2996.96,"qty":0.00000000},{"price":2999.32,"qty":1.30787255}],"checksum":1294711687,"timestamp":"2024-06-01T22:43:04.587355Z"}]}
{"channel":"book","type":"update","data":[{"symbol":"ETH/GBP","bids":[{"price":2996.79,"qty":0.00000000},{"price":2993.00,"qty":0.94850883}],"asks":[],"checksum":2998877743,"timestamp":"2024-06-01T22:43:04.587515Z"}]}
{"channel":"book","type":"update","data":[{"symbol":"ETH/GBP","bids":[],"asks":[{"price":2999.02,"qty":0.00000000},{"price":2999.64,"qty":1.33100000}],"checksum":4015419603,"timestamp":"2024-06-01T22:43:04.592101Z"}]}
{"channel":"book","type":"update","data":[{"symbol":"ETH/GBP","bids":[],"asks":[{"price":2999.17,"qty":9.61848665}],"checksum":1987821200,"timestamp":"2024-06-01T22:43:04.596648Z"}]}
{"channel":"book","type":"update","data":[{"symbol":"ETH/GBP","bids":[],"asks":[{"price":2998.26,"qty":0.00000000},{"price":2999.64,"qty":1.33100000}],"checksum":2474586554,"timestamp":"2024-06-01T22:43:04.599486Z"}]}
{"channel":"book","type":"update","data":[{"symbol":"ETH/GBP","bids":[{"price":2995.61,"qty":0.00000000},{"price":2992.73,"qty":0.12935847}],"asks":[],"checksum":3910261479,"timestamp":"2024-06-01T22:43:04.607135Z"}]}
{"channel":"book","type":"update","data":[{"symbol":"ETH/GBP","bids":[{"price":2995.80,"qty":1.30940490}],"asks":[],"checksum":3375245346,"timestamp":"2024-06-01T22:43:04.610820Z"}]}
{"channel":"book","type":"update","data":[{"symbol":"ETH/GBP","bids":[],"asks":[{"price":2999.45,"qty":1.00000000}],"checksum":4126352439,"timestamp":"2024-06-01T22:43:04.727019Z"}]}
{"channel":"book","type":"update","data":[{"symbol":"ETH/GBP","bids":[{"price":2996.24,"qty":6.54607573}],"asks":[],"checksum":3091334987,"timestamp":"2024-06-01T22:43:04.727296Z"}]}
{"channel":"book","type":"update","data":[{"symbol":"ETH/GBP","bids":[],"asks":[{"price":2997.02,"qty":6.54437754}],"checksum":3590169745,"timestamp":"2024-06-01T22:43:04.727326Z"}]}
{"channel":"book","type":"update","data":[{"symbol":"ETH/GBP","bids":[{"price":2995.84,"qty":0.00000000},{"price":2993.00,"qty":0.94850883}],"asks":[],"checksum":1157784343,"timestamp":"2024-06-01T22:43:04.730297Z"}]}
{"channel":"book","type":"update","data":[{"symbol":"ETH/GBP","bids":[{"price":2996.28,"qty":0.31000000}],"asks":[],"checksum":1649964993,"timestamp":"2024-06-01T22:43:04.730416Z"}]}
{"channel":"book","type":"update","data":[{"symbol":"ETH/GBP","bids":[],"asks":[{"price":2998.57,"qty":0.90569250}],"checksum":4007655308,"timestamp":"2024-06-01T22:43:04.732228Z"}]}
{"channel":"book","type":"update","data":[{"symbol":"ETH/GBP","bids":[{"price":2996.24,"qty":0.00000000},{"price":2993.00,"qty":0.94850883}],"asks":[],"checksum":3671123227,"timestamp":"2024-06-01T22:43:04.732552Z"}]}
{"channel":"book","type":"update","data":[{"symbol":"ETH/GBP","bids":[],"asks":[{"price":2997.42,"qty":13.08705021}],"checksum":3832394782,"timestamp":"2024-06-01T22:43:04.735990Z"}]}
{"channel":"book","type":"update","data":[{"symbol":"ETH/GBP","bids":[],"asks":[{"price":2997.42,"qty":0.00000000},{"price":2999.17,"qty":9.61848665}],"checksum":3671123227,"timestamp":"2024-06-01T22:43:04.786386Z"}]}
{"channel":"book","type":"update","data":[{"symbol":"ETH/GBP","bids":[],"asks":[{"price":2997.02,"qty":0.00000000},{"price":2999.32,"qty":1.30787255}],"checksum":3115343410,"timestamp":"2024-06-01T22:43:04.786476Z"}]}
{"channel":"book","type":"update","data":[{"symbol":"ETH/GBP","bids":[{"price":2996.49,"qty":13.09106692}],"asks":[],"checksum":972953759,"timestamp":"2024-06-01T22:43:04.791807Z"}]}
{"channel":"book","type":"update","data":[{"symbol":"ETH/GBP","bids":[],"asks":[{"price":2997.02,"qty":6.54438719}],"checksum":2561994151,"timestamp":"2024-06-01T22:43:04.830152Z"}]}
{"channel":"book","type":"update","data":[{"symbol":"ETH/GBP","bids":[{"price":2996.86,"qty":6.54472538}],"asks":[],"checksum":2220514727,"timestamp":"2024-06-01T22:43:04.830212Z"}]}
{"channel":"book","type":"update","data":[{"symbol":"ETH/GBP","bids":[],"asks":[{"price":2997.02,"qty":0.00000000},{"price":2999.32,"qty":1.30787255}],"checksum":621848735,"timestamp":"2024-06-01T22:43:04.834866Z"}]}
{"channel":"book","type":"update","data":[{"symbol":"ETH/GBP","bids":[{"price":2996.86,"qty":0.00000000},{"price":2993.55,"qty":1.60405540}],"asks":[],"checksum":972953759,"timestamp":"2024-06-01T22:43:04.834931Z"}]}
{"channel":"book","type":"update","data":[{"symbol":"ETH/GBP","bids":[{"price":2996.49,"qty":0.00000000},{"price":2993.00,"qty":0.94850883}],"asks":[],"checksum":3115343410,"timestamp":"2024-06-01T22:43:04.867072Z"}]}
{"channel":"book","type":"update","data":[{"symbol":"ETH/GBP","bids":[{"price":2996.89,"qty":6.54464991}],"asks":[],"checksum":1904396714,"timestamp":"2024-06-01T22:43:04.992767Z"}]}
{"channel":"book","type":"update","data":[{"symbol":"ETH/GBP","bids":[{"price":2996.29,"qty":13.09193518}],"asks":[],"checksum":2163223242,"timestamp":"2024-06-01T22:43:04.992898Z"}]}
{"channel":"book","type":"update","data":[{"symbol":"ETH/GBP","bids":[],"asks":[{"price":2997.46,"qty":6.54342079}],"checksum":148796009,"timestamp":"2024-06-01T22:43:04.992912Z"}]}
{"channel":"book","type":"update","data":[{"symbol":"ETH/GBP","bids":[],"asks":[{"price":2997.46,"qty":19.63026238}],"checksum":487360213,"timestamp":"2024-06-01T22:43:04.992952Z"}]}
{"channel":"book","type":"update","data":[{"symbol":"ETH/GBP","bids":[],"asks":[{"price":2997.47,"qty":0.00000000},{"price":2999.32,"qty":1.30787255}],"checksum":152287046,"timestamp":"2024-06-01T22:43:04.995706Z"}]}
{"channel":"book","type":"update","data":[{"symbol":"ETH/GBP","bids":[],"asks":[{"price":2997.39,"qty":0.31000000}],"checksum":947107533,"timestamp":"2024-06-01T22:43:04.995877Z"}]}
{"channel":"book","type":"update","data":[{"symbol":"ETH/GBP","bids":[{"price":2996.29,"qty":0.00000000},{"price":2993.55,"qty":1.60405540}],"asks":[],"checksum":1337704861,"timestamp":"2024-06-01T22:43:04.998008Z"}]}
{"channel":"book","type":"update","data":[{"symbol":"ETH/GBP","bids":[],"asks":[{"price":2997.46,"qty":6.54342079}],"checksum":1128732137,"timestamp":"2024-06-01T22:43:04.998163Z"}]}
{"channel":"book","type":"update","data":[{"symbol":"ETH/GBP","bids":[{"price":2996.89,"qty":0.00000000},{"price":2993.00,"qty":0.94850883}],"asks":[],"checksum":2751528478,"timestamp":"2024-06-01T22:43:05.071758Z"}]}
{"channel":"book","type":"update","data":[{"symbol":"ETH/GBP","bids":[],"asks":[{"price":2997.07,"qty":6.54427313}],"checksum":3733951805,"timestamp":"2024-06-01T22:43:05.092367Z"}]}
{"channel":"book","type":"update","data":[{"symbol":"ETH/GBP","bids":[{"price":2996.90,"qty":6.54461784}],"asks":[],"checksum":3488434439,"timestamp":"2024-06-01T22:43:05.092482Z"}]}
{"channel":"book","type":"update","data":[{"symbol":"ETH/GBP","bids":[],"asks":[{"price":2997.07,"qty":0.00000000},{"price":2999.17,"qty":9.61848665}],"checksum":1844492062,"timestamp":"2024-06-01T22:43:05.102204Z"}]}
{"channel":"book","type":"update","data":[{"symbol":"ETH/GBP","bids":[{"price":2996.90,"qty":0.00000000},{"price":2993.00,"qty":0.94850883}],"asks":[],"checksum":2751528478,"timestamp":"2024-06-01T22:43:05.130927Z"}]}
{"channel":"book","type":"update","data":[{"symbol":"ETH/GBP","bids":[{"price":2996.88,"qty":6.54466165}],"asks":[],"checksum":2744795791,"timestamp":"2024-06-01T22:43:05.239810Z"}]}
{"channel":"book","type":"update","data":[{"symbol":"ETH/GBP","bids":[{"price":2996.29,"qty":13.09193867}],"asks":[],"checksum":627914069,"timestamp":"2024-06-01T22:43:05.239951Z"}]}
{"channel":"book","type":"update","data":[{"symbol":"ETH/GBP","bids":[],"asks":[{"price":2997.05,"qty":6.54431698}],"checksum":3098082690,"timestamp":"2024-06-01T22:43:05.240090Z"}]}
{"channel":"book","type":"update","data":[{"symbol":"ETH/GBP","bids":[{"price":2996.29,"qty":0.00000000},{"price":2993.55,"qty":1.60405540}],"asks":[],"checksum":3022338570,"timestamp":"2024-06-01T22:43:05.245340Z"}]}
{"channel":"book","type":"update","data":[{"symbol":"ETH/GBP","bids":[],"asks":[{"price":2997.46,"qty":0.00000000},{"price":2999.17,"qty":9.61848665}],"checksum":1053830824,"timestamp":"2024-06-01T22:43:05.566661Z"}]}
{"channel":"book","type":"update","data":[{"symbol":"ETH/GBP","bids":[],"asks":[{"price":2997.42,"qty":13.08702858}],"checksum":365480995,"timestamp":"2024-06-01T22:43:05.572793Z"}]}
{"channel":"book","type":"update","data":[{"symbol":"ETH/GBP","bids":[{"price":2996.51,"qty":13.09097087}],"asks":[],"checksum":1346252809,"timestamp":"2024-06-01T22:43:05.572929Z"}]}
{"channel":"book","type":"update","data":[{"symbol":"ETH/GBP","bids":[],"asks":[{"price":2997.05,"qty":0.00000000},{"price":2999.17,"qty":9.61848665}],"checksum":2965931465,"timestamp":"2024-06-01T22:43:05.594952Z"}]}
{"channel":"book","type":"update","data":[{"symbol":"ETH/GBP","bids":[],"asks":[{"price":2997.04,"qty":6.54433400}],"checksum":2009939647,"timestamp":"2024-06-01T22:43:05.599716Z"}]}
{"channel":"book","type":"update","data":[{"symbol":"ETH/GBP","bids":[],"asks":[{"price":2997.04,"qty":0.00000000},{"price":2999.17,"qty":9.61848665}],"checksum":2965931465,"timestamp":"2024-06-01T22:43:05.803064Z"}]}
{"channel":"book","type":"update","data":[{"symbol":"ETH/GBP","bids":[{"price":2996.88,"qty":0.00000000},{"price":2993.55,"qty":1.60405540}],"asks":[],"checksum":862333008,"timestamp":"2024-06-01T22:43:05.804887Z"}]}
{"channel":"book","type":"update","data":[{"symbol":"ETH/GBP","bids":[{"price":2996.51,"qty":0.00000000},{"price":2993.00,"qty":0.94850883}],"asks":[],"checksum":354081494,"timestamp":"2024-06-01T22:43:05.810065Z"}]}
{"channel":"book","type":"update","data":[{"symbol":"ETH/GBP","bids":[{"price":2996.29,"qty":13.09193867}],"asks":[],"checksum":4203156458,"timestamp":"2024-06-01T22:43:05.814626Z"}]}
{"channel":"book","type":"update","data":[{"symbol":"ETH/GBP","bids":[],"asks":[{"price":2997.06,"qty":6.54430782}],"checksum":1344116614,"timestamp":"2024-06-01T22:43:05.814760Z"}]}
{"channel":"book","type":"update","data":[{"symbol":"ETH/GBP","bids":[{"price":2996.89,"qty":6.54465903}],"asks":[],"checksum":1467102314,"timestamp":"2024-06-01T22:43:05.814848Z"}]}
{"channel":"book","type":"update","data":[{"symbol":"ETH/GBP","bids":[{"price":2996.29,"qty":0.00000000},{"price":2993.55,"qty":1.60405540}],"asks":[],"checksum":3153918025,"timestamp":"2024-06-01T22:43:05.819924Z"}]}
{"channel":"book","type":"update","data":[{"symbol":"ETH/GBP","bids":[],"asks":[{"price":2997.06,"qty":0.00000000},{"price":2999.17,"qty":9.61848665}],"checksum":724880167,"timestamp":"2024-06-01T22:43:05.904270Z"}]}
{"channel":"book","type":"update","data":[{"symbol":"ETH/GBP","bids":[{"price":2996.89,"qty":0.00000000},{"price":2993.00,"qty":0.94850883}],"asks":[],"checksum":354081494,"timestamp":"2024-06-01T22:43:05.904471Z"}]}
{"channel":"book","type":"update","data":[{"symbol":"ETH/GBP","bids":[{"price":2996.90,"qty":6.54462882}],"asks":[],"checksum":3715005735,"timestamp":"2024-06-01T22:43:05.930576Z"}]}
{"channel":"book","type":"update","data":[{"symbol":"ETH/GBP","bids":[],"asks":[{"price":2997.07,"qty":6.54427325}],"checksum":345040886,"timestamp":"2024-06-01T22:43:05.930747Z"}]}
{"channel":"book","type":"update","data":[{"symbol":"ETH/GBP","bids":[],"asks":[{"price":2997.55,"qty":0.00000000},{"price":2999.17,"qty":9.61848665},{"price":2997.05,"qty":0.08526700}],"checksum":2017526088,"timestamp":"2024-06-01T22:43:05.988338Z"}]}
{"channel":"book","type":"update","data":[{"symbol":"ETH/GBP","bids":[{"price":2996.53,"qty":13.09088008}],"asks":[],"checksum":2520647204,"timestamp":"2024-06-01T22:43:06.090061Z"}]}
{"channel":"book","type":"update","data":[{"symbol":"ETH/GBP","bids":[],"asks":[{"price":2997.07,"qty":0.00000000},{"price":2999.17,"qty":9.61848665}],"checksum":3782643479,"timestamp":"2024-06-01T22:43:06.261274Z"}]}
{"channel":"book","type":"update","data":[{"symbol":"ETH/GBP","bids":[],"asks":[{"price":2997.06,"qty":6.54429157}],"checksum":3270461276,"timestamp":"2024-06-01T22:43:06.265329Z"}]}
{"channel":"book","type":"update","data":[{"symbol":"ETH/GBP","bids":[{"price":2996.90,"qty":0.00000000},{"price":2993.55,"qty":1.60405540}],"asks":[],"checksum":1565258127,"timestamp":"2024-06-01T22:43:06.275430Z"}]}
{"channel":"book","type":"update","data":[{"symbol":"ETH/GBP","bids":[{"price":2996.89,"qty":6.54465829}],"asks":[],"checksum":3433304301,"timestamp":"2024-06-01T22:43:06.279141Z"}]}
{"channel":"book","type":"update","data":[{"symbol":"ETH/GBP","bids":[{"price":2996.89,"qty":0.00000000},{"price":2993.55,"qty":1.60405540}],"asks":[],"checksum":1565258127,"timestamp":"2024-06-01T22:43:06.311218Z"}]}
{"channel":"book","type":"update","data":[{"symbol":"ETH/GBP","bids":[],"asks":[{"price":2997.06,"qty":0.00000000},{"price":2999.17,"qty":9.61848665}],"checksum":2127706564,"timestamp":"2024-06-01T22:43:06.311268Z"}]}
{"channel":"book","type":"update","data":[{"symbol":"ETH/GBP","bids":[],"asks":[{"price":2997.06,"qty":6.54429354}],"checksum":1568698137,"timestamp":"2024-06-01T22:43:06.406211Z"}]}
{"channel":"book","type":"update","data":[{"symbol":"ETH/GBP","bids":[{"price":2996.89,"qty":6.54464062}],"asks":[],"checksum":2839242045,"timestamp":"2024-06-01T22:43:06.406382Z"}]}
{"channel":"book","type":"update","data":[{"symbol":"ETH/GBP","bids":[],"asks":[{"price":2998.25,"qty":0.00000000},{"price":2999.17,"qty":9.61848665}],"checksum":2381468107,"timestamp":"2024-06-01T22:43:06.743504Z"}]}
{"channel":"book","type":"update","data":[{"symbol":"ETH/GBP","bids":[],"asks":[{"price":2998.32,"qty":0.00000000},{"price":2999.32,"qty":1.30787255}],"checksum":149498704,"timestamp":"2024-06-01T22:43:06.743768Z"}]}
{"channel":"book","type":"update","data":[{"symbol":"ETH/GBP","bids":[],"asks":[{"price":2997.38,"qty":6.01213079}],"checksum":4201053267,"timestamp":"2024-06-01T22:43:06.749071Z"}]}
{"channel":"book","type":"update","data":[{"symbol":"ETH/GBP","bids":[],"asks":[{"price":2999.16,"qty":26.79928304}],"checksum":3809188180,"timestamp":"2024-06-01T22:43:06.749128Z"}]}
{"channel":"book","type":"update","data":[{"symbol":"ETH/GBP","bids":[{"price":2996.89,"qty":0.00000000},{"price":2993.55,"qty":1.60405540}],"asks":[],"checksum":397448048,"timestamp":"2024-06-01T22:43:06.761377Z"}]}
{"channel":"book","type":"update","data":[{"symbol":"ETH/GBP","bids":[],"asks":[{"price":2997.06,"qty":0.00000000},{"price":2999.17,"qty":9.61848665}],"checksum":3562673276,"timestamp":"2024-06-01T22:43:06.761438Z"}]}
{"channel":"book","type":"update","data":[{"symbol":"ETH/GBP","bids":[{"price":2995.83,"qty":0.00000000},{"price":2993.00,"qty":0.94850883}],"asks":[],"checksum":1174496293,"timestamp":"2024-06-01T22:43:06.764828Z"}]}
{"channel":"book","type":"update","data":[{"symbol":"ETH/GBP","bids":[{"price":2996.90,"qty":6.54463735}],"asks":[],"checksum":2903898470,"timestamp":"2024-06-01T22:43:06.765840Z"}]}
{"channel":"book","type":"update","data":[{"symbol":"ETH/GBP","bids":[],"asks":[{"price":2997.07,"qty":6.54427234}],"checksum":2786232387,"timestamp":"2024-06-01T22:43:06.765879Z"}]}
{"channel":"book","type":"update","data":[{"symbol":"ETH/GBP","bids":[{"price":2996.10,"qty":7.65750795}],"asks":[],"checksum":1482825687,"timestamp":"2024-06-01T22:43:06.768244Z"}]}
{"channel":"book","type":"update","data":[{"symbol":"ETH/GBP","bids":[{"price":2996.90,"qty":0.00000000},{"price":2993.55,"qty":1.60405540}],"asks":[],"checksum":2155924376,"timestamp":"2024-06-01T22:43:06.901897Z"}]}
{"channel":"book","type":"update","data":[{"symbol":"ETH/GBP","bids":[{"price":2996.53,"qty":0.00000000},{"price":2993.00,"qty":0.94850883}],"asks":[],"checksum":3640435965,"timestamp":"2024-06-01T22:43:06.906571Z"}]}
{"channel":"book","type":"update","data":[{"symbol":"ETH/GBP","bids":[{"price":2996.91,"qty":6.54461600}],"asks":[],"checksum":3602739237,"timestamp":"2024-06-01T22:43:06.911075Z"}]}
{"channel":"book","type":"update","data":[{"symbol":"ETH/GBP","bids":[{"price":2996.29,"qty":13.09194348}],"asks":[],"checksum":2082854408,"timestamp":"2024-06-01T22:43:06.911210Z"}]}
{"channel":"book","type":"update","data":[{"symbol":"ETH/GBP","bids":[{"price":2996.29,"qty":0.00000000},{"price":2993.55,"qty":1.60405540}],"asks":[],"checksum":3602739237,"timestamp":"2024-06-01T22:43:06.915241Z"}]}
{"channel":"book","type":"update","data":[{"symbol":"ETH/GBP","bids":[],"asks":[{"price":2997.07,"qty":0.00000000},{"price":2999.17,"qty":9.61848665}],"checksum":169047274,"timestamp":"2024-06-01T22:43:07.049243Z"}]}
{"channel":"book","type":"update","data":[{"symbol":"ETH/GBP","bids":[{"price":2996.91,"qty":0.00000000},{"price":2993.00,"qty":0.94850883}],"asks":[],"checksum":2700453075,"timestamp":"2024-06-01T22:43:07.049305Z"}]}
{"channel":"book","type":"update","data":[{"symbol":"ETH/GBP","bids":[],"asks":[{"price":2997.39,"qty":0.00000000},{"price":2999.32,"qty":1.30787255}],"checksum":3919277227,"timestamp":"2024-06-01T22:43:07.052316Z"}]}
{"channel":"book","type":"update","data":[{"symbol":"ETH/GBP","bids":[],"asks":[{"price":2997.30,"qty":0.31000000}],"checksum":1569575355,"timestamp":"2024-06-01T22:43:07.052353Z"}]}
{"channel":"book","type":"update","data":[{"symbol":"ETH/GBP","bids":[],"asks":[{"price":2997.09,"qty":6.54422894}],"checksum":3563139659,"timestamp":"2024-06-01T22:43:07.054707Z"}]}
{"channel":"book","type":"update","data":[{"symbol":"ETH/GBP","bids":[{"price":2996.92,"qty":6.54458589}],"asks":[],"checksum":1283506514,"timestamp":"2024-06-01T22:43:07.054733Z"}]}
{"channel":"book","type":"update","data":[{"symbol":"ETH/GBP","bids":[],"asks":[{"price":2997.97,"qty":0.00000000},{"price":2999.17,"qty":9.61848665}],"checksum":2811351202,"timestamp":"2024-06-01T22:43:07.106504Z"}]}
{"channel":"book","type":"update","data":[{"symbol":"ETH/GBP","bids":[{"price":2996.92,"qty":0.00000000},{"price":2993.00,"qty":0.94850883}],"asks":[],"checksum":3410427278,"timestamp":"2024-06-01T22:43:07.106562Z"}]}
{"channel":"book","type":"update","data":[{"symbol":"ETH/GBP","bids":[],"asks":[{"price":2998.17,"qty":1.30837515}],"checksum":1560916119,"timestamp":"2024-06-01T22:43:07.111437Z"}]}
{"channel":"book","type":"update","data":[{"symbol":"ETH/GBP","bids":[{"price":2996.29,"qty":13.09194348}],"asks":[],"checksum":765754852,"timestamp":"2024-06-01T22:43:07.115145Z"}]}
{"channel":"book","type":"update","data":[{"symbol":"ETH/GBP","bids":[{"price":2996.29,"qty":0.00000000},{"price":2993.00,"qty":0.94850883}],"asks":[],"checksum":1560916119,"timestamp":"2024-06-01T22:43:07.119624Z"}]}
{"channel":"book","type":"update","data":[{"symbol":"ETH/GBP","bids":[{"price":2996.29,"qty":6.54597174}],"asks":[],"checksum":1212398849,"timestamp":"2024-06-01T22:43:07.154758Z"}]}
{"channel":"book","type":"update","data":[{"symbol":"ETH/GBP","bids":[{"price":2996.29,"qty":0.00000000},{"price":2993.00,"qty":0.94850883}],"asks":[],"checksum":1560916119,"timestamp":"2024-06-01T22:43:07.159493Z"}]}
{"channel":"book","type":"update","data":[{"symbol":"ETH/GBP","bids":[],"asks":[{"price":2997.42,"qty":0.00000000},{"price":2999.17,"qty":9.61848665}],"checksum":2900994156,"timestamp":"2024-06-01T22:43:07.179249Z"}]}
{"channel":"book","type":"update","data":[{"symbol":"ETH/GBP","bids":[],"asks":[{"price":2997.09,"qty":0.00000000},{"price":2999.32,"qty":1.30787255}],"checksum":686207323,"timestamp":"2024-06-01T22:43:07.179459Z"}]}
{"channel":"book","type":"update","data":[{"symbol":"ETH/GBP","bids":[],"asks":[{"price":2999.32,"qty":0.00000000},{"price":2999.45,"qty":1.00000000}],"checksum":3480474351,"timestamp":"2024-06-01T22:43:07.179498Z"}]}
{"channel":"book","type":"update","data":[{"symbol":"ETH/GBP","bids":[],"asks":[{"price":2997.53,"qty":13.08654705}],"checksum":99734135,"timestamp":"2024-06-01T22:43:07.186300Z"}]}
{"channel":"book","type":"update","data":[{"symbol":"ETH/GBP","bids":[],"asks":[{"price":2997.18,"qty":6.54404486}],"checksum":1230790162,"timestamp":"2024-06-01T22:43:07.186383Z"}]}
{"channel":"book","type":"update","data":[{"symbol":"ETH/GBP","bids":[],"asks":[{"price":2997.18,"qty":0.00000000},{"price":2999.17,"qty":9.61848665}],"checksum":99734135,"timestamp":"2024-06-01T22:43:07.193351Z"}]}
