{"channel":"book","type":"snapshot","data":[{"symbol":"ETH/USD","bids":[{"price":3819.68,"qty":26.93397119},{"price":3819.50,"qty":26.18142119},{"price":3819.44,"qty":26.18184293},{"price":3819.43,"qty":0.77000000},{"price":3819.34,"qty":0.42254793},{"price":3819.32,"qty":26.18263166},{"price":3819.31,"qty":3.92678381},{"price":3819.25,"qty":0.01368441},{"price":3819.11,"qty":3.92678381},{"price":3819.07,"qty":4.86841079}],"asks":[{"price":3819.69,"qty":0.23357680},{"price":3819.72,"qty":0.78588958},{"price":3819.74,"qty":0.05100000},{"price":3819.77,"qty":26.17962560},{"price":3819.94,"qty":0.23357680},{"price":3819.98,"qty":26.17818348},{"price":3820.02,"qty":0.77000000},{"price":3820.10,"qty":2.09900000},{"price":3820.23,"qty":0.48396891},{"price":3820.24,"qty":26.17640149}],"checksum":560470210}]}
{"channel":"book","type":"update","data":[{"symbol":"ETH/USD","bids":[{"price":3819.50,"qty":0.00000000},{"price":3819.00,"qty":26.18482923}],"asks":[],"checksum":1096056463,"timestamp":"2024-06-01T22:42:41.347146Z"}]}
{"channel":"book","type":"update","data":[{"symbol":"ETH/USD","bids":[],"asks":[{"price":3819.69,"qty":26.41371183}],"checksum":3435044088,"timestamp":"2024-06-01T22:42:41.351320Z"}]}
{"channel":"book","type":"update","data":[{"symbol":"ETH/USD","bids":[{"price":3819.68,"qty":0.76606754}],"asks":[],"checksum":611661381,"timestamp":"2024-06-01T22:42:41.386313Z"}]}
{"channel":"book","type":"update","data":[{"symbol":"ETH/USD","bids":[{"price":3819.52,"qty":26.16790696}],"asks":[],"checksum":3027927768,"timestamp":"2024-06-01T22:42:41.386503Z"}]}
{"channel":"book","type":"update","data":[{"symbol":"ETH/USD","bids":[],"asks":[{"price":3819.98,"qty":0.00000000},{"price":3820.51,"qty":3.67833330}],"checksum":117528740,"timestamp":"2024-06-01T22:42:41.388651Z"}]}
{"channel":"book","type":"update","data":[{"symbol":"ETH/USD","bids":[],"asks":[{"price":3819.89,"qty":26.17881918}],"checksum":763229252,"timestamp":"2024-06-01T22:42:41.392735Z"}]}
{"channel":"book","type":"update","data":[{"symbol":"ETH/USD","bids":[{"price":3819.46,"qty":26.18167255}],"asks":[],"checksum":2859453230,"timestamp":"2024-06-01T22:42:41.392929Z"}]}
{"channel":"book","type":"update","data":[{"symbol":"ETH/USD","bids":[],"asks":[{"price":3819.89,"qty":0.00000000},{"price":3820.51,"qty":3.67833330}],"checksum":172971514,"timestamp":"2024-06-01T22:42:41.482068Z"}]}
{"channel":"book","type":"update","data":[{"symbol":"ETH/USD","bids":[{"price":3819.44,"qty":0.00000000},{"price":3819.07,"qty":4.86841079}],"asks":[],"checksum":1454025126,"timestamp":"2024-06-01T22:42:41.482114Z"}]}
{"channel":"book","type":"update","data":[{"symbol":"ETH/USD","bids":[],"asks":[{"price":3820.24,"qty":0.00000000},{"price":3820.60,"qty":3.30000000}],"checksum":2278308346,"timestamp":"2024-06-01T22:42:41.482278Z"}]}
{"channel":"book","type":"update","data":[{"symbol":"ETH/USD","bids":[{"price":3819.46,"qty":0.00000000},{"price":3819.00,"qty":26.18482923}],"asks":[],"checksum":1444297673,"timestamp":"2024-06-01T22:42:41.482385Z"}]}
{"channel":"book","type":"update","data":[{"symbol":"ETH/USD","bids":[],"asks":[{"price":3819.69,"qty":52.59384686}],"checksum":1581112353,"timestamp":"2024-06-01T22:42:41.487547Z"}]}
{"channel":"book","type":"update","data":[{"symbol":"ETH/USD","bids":[{"price":3819.21,"qty":26.18339530}],"asks":[],"checksum":3635704340,"timestamp":"2024-06-01T22:42:41.487629Z"}]}
{"channel":"book","type":"update","data":[{"symbol":"ETH/USD","bids":[{"price":3819.40,"qty":26.18212270}],"asks":[],"checksum":3560904030,"timestamp":"2024-06-01T22:42:41.487643Z"}]}
{"channel":"book","type":"update","data":[{"symbol":"ETH/USD","bids":[],"asks":[{"price":3820.08,"qty":26.17752870}],"checksum":1822686975,"timestamp":"2024-06-01T22:42:41.487717Z"}]}
{"channel":"book","type":"update","data":[{"symbol":"ETH/USD","bids":[{"price":3819.52,"qty":0.00000000},{"price":3819.07,"qty":4.86841079}],"asks":[],"checksum":1921923319,"timestamp":"2024-06-01T22:42:41.577802Z"}]}
{"channel":"book","type":"update","data":[{"symbol":"ETH/USD","bids":[{"price":3819.68,"qty":26.93396820}],"asks":[],"checksum":1978632515,"timestamp":"2024-06-01T22:42:41.577989Z"}]}
{"channel":"book","type":"update","data":[{"symbol":"ETH/USD","bids":[{"price":3819.40,"qty":0.00000000},{"price":3819.01,"qty":0.00908090}],"asks":[],"checksum":1800637919,"timestamp":"2024-06-01T22:42:41.789267Z"}]}
{"channel":"book","type":"update","data":[{"symbol":"ETH/USD","bids":[{"price":3819.41,"qty":26.18202194}],"asks":[],"checksum":1041832701,"timestamp":"2024-06-01T22:42:41.794927Z"}]}
{"channel":"book","type":"update","data":[{"symbol":"ETH/USD","bids":[{"price":3819.33,"qty":0.00908014}],"asks":[],"checksum":3091033767,"timestamp":"2024-06-01T22:42:41.840885Z"}]}
{"channel":"book","type":"update","data":[{"symbol":"ETH/USD","bids":[{"price":3819.33,"qty":0.00000000},{"price":3819.07,"qty":4.86841079}],"asks":[],"checksum":1041832701,"timestamp":"2024-06-01T22:42:41.885247Z"}]}
{"channel":"book","type":"update","data":[{"symbol":"ETH/USD","bids":[{"price":3819.41,"qty":0.00000000},{"price":3819.01,"qty":0.00908090}],"asks":[],"checksum":1800637919,"timestamp":"2024-06-01T22:42:42.027457Z"}]}
{"channel":"book","type":"update","data":[{"symbol":"ETH/USD","bids":[{"price":3819.42,"qty":26.18196447}],"asks":[],"checksum":1774959997,"timestamp":"2024-06-01T22:42:42.032045Z"}]}
{"channel":"book","type":"update","data":[{"symbol":"ETH/USD","bids":[{"price":3819.33,"qty":0.00908014}],"asks":[],"checksum":4239605019,"timestamp":"2024-06-01T22:42:42.079610Z"}]}
{"channel":"book","type":"update","data":[{"symbol":"ETH/USD","bids":[{"price":3819.33,"qty":0.00000000},{"price":3819.07,"qty":4.86841079}],"asks":[],"checksum":1774959997,"timestamp":"2024-06-01T22:42:42.144458Z"}]}
{"channel":"book","type":"update","data":[{"symbol":"ETH/USD","bids":[{"price":3819.32,"qty":0.00000000},{"price":3819.01,"qty":0.00908090}],"asks":[],"checksum":454529388,"timestamp":"2024-06-01T22:42:42.252781Z"}]}
{"channel":"book","type":"update","data":[{"symbol":"ETH/USD","bids":[{"price":3819.43,"qty":26.95186827}],"asks":[],"checksum":2216884994,"timestamp":"2024-06-01T22:42:42.256560Z"}]}
{"channel":"book","type":"update","data":[{"symbol":"ETH/USD","bids":[{"price":3819.01,"qty":0.00000000},{"price":3819.00,"qty":26.18482923},{"price":3819.22,"qty":0.00907986}],"asks":[],"checksum":382317789,"timestamp":"2024-06-01T22:42:42.286929Z"}]}
{"channel":"book","type":"update","data":[{"symbol":"ETH/USD","bids":[],"asks":[{"price":3819.77,"qty":0.00000000},{"price":3820.60,"qty":3.30000000}],"checksum":1802141160,"timestamp":"2024-06-01T22:42:42.300742Z"}]}
{"channel":"book","type":"update","data":[{"symbol":"ETH/USD","bids":[{"price":3819.43,"qty":0.77000000}],"asks":[],"checksum":263994581,"timestamp":"2024-06-01T22:42:42.300756Z"}]}
{"channel":"book","type":"update","data":[{"symbol":"ETH/USD","bids":[],"asks":[{"price":3819.89,"qty":26.17879656}],"checksum":3412274243,"timestamp":"2024-06-01T22:42:42.305798Z"}]}
{"channel":"book","type":"update","data":[{"symbol":"ETH/USD","bids":[{"price":3819.46,"qty":26.18170331}],"asks":[],"checksum":2176807493,"timestamp":"2024-06-01T22:42:42.309877Z"}]}
{"channel":"book","type":"update","data":[{"symbol":"ETH/USD","bids":[{"price":3819.22,"qty":0.00000000},{"price":3819.07,"qty":4.86841079}],"asks":[],"checksum":1485624748,"timestamp":"2024-06-01T22:42:42.310814Z"}]}
{"channel":"book","type":"update","data":[{"symbol":"ETH/USD","bids":[{"price":3819.46,"qty":0.00000000},{"price":3819.00,"qty":26.18482923}],"asks":[],"checksum":3031205078,"timestamp":"2024-06-01T22:42:42.313818Z"}]}
{"channel":"book","type":"update","data":[{"symbol":"ETH/USD","bids":[{"price":3819.45,"qty":26.18171899}],"asks":[],"checksum":2054304340,"timestamp":"2024-06-01T22:42:42.480692Z"}]}
{"channel":"book","type":"update","data":[{"symbol":"ETH/USD","bids":[{"price":3819.45,"qty":0.00000000},{"price":3819.00,"qty":26.18482923}],"asks":[],"checksum":3031205078,"timestamp":"2024-06-01T22:42:42.912617Z"}]}
{"channel":"book","type":"update","data":[{"symbol":"ETH/USD","bids":[{"price":3819.43,"qty":26.95190363}],"asks":[],"checksum":3799951095,"timestamp":"2024-06-01T22:42:42.916913Z"}]}
{"channel":"book","type":"update","data":[{"symbol":"ETH/USD","bids":[{"price":3819.43,"qty":0.77000000}],"asks":[],"checksum":3031205078,"timestamp":"2024-06-01T22:42:43.207916Z"}]}
{"channel":"book","type":"update","data":[{"symbol":"ETH/USD","bids":[{"price":3819.44,"qty":15.70639512}],"asks":[],"checksum":310863890,"timestamp":"2024-06-01T22:42:43.211711Z"}]}
{"channel":"book","type":"update","data":[{"symbol":"ETH/USD","bids":[{"price":3819.45,"qty":26.18176224}],"asks":[],"checksum":2523843750,"timestamp":"2024-06-01T22:42:43.211771Z"}]}
{"channel":"book","type":"update","data":[{"symbol":"ETH/USD","bids":[{"price":3819.22,"qty":0.00907986}],"asks":[],"checksum":3625021358,"timestamp":"2024-06-01T22:42:43.241323Z"}]}
{"channel":"book","type":"update","data":[{"symbol":"ETH/USD","bids":[{"price":3819.22,"qty":0.00000000},{"price":3819.11,"qty":3.92678381}],"asks":[],"checksum":2523843750,"timestamp":"2024-06-01T22:42:43.295151Z"}]}
{"channel":"book","type":"update","data":[{"symbol":"ETH/USD","bids":[{"price":3819.45,"qty":0.00000000},{"price":3819.07,"qty":4.86841079}],"asks":[],"checksum":310863890,"timestamp":"2024-06-01T22:42:43.835562Z"}]}
{"channel":"book","type":"update","data":[{"symbol":"ETH/USD","bids":[{"price":3819.46,"qty":26.18168680}],"asks":[],"checksum":203153129,"timestamp":"2024-06-01T22:42:43.842017Z"}]}
{"channel":"book","type":"update","data":[{"symbol":"ETH/USD","bids":[{"price":3819.46,"qty":0.00000000},{"price":3819.07,"qty":4.86841079}],"asks":[],"checksum":310863890,"timestamp":"2024-06-01T22:42:44.196324Z"}]}
{"channel":"book","type":"update","data":[{"symbol":"ETH/USD","bids":[{"price":3819.44,"qty":41.88819451}],"asks":[],"checksum":3232538497,"timestamp":"2024-06-01T22:42:44.200835Z"}]}
{"channel":"book","type":"update","data":[{"symbol":"ETH/USD","bids":[{"price":3819.44,"qty":15.70639512}],"asks":[],"checksum":310863890,"timestamp":"2024-06-01T22:42:44.291576Z"}]}
{"channel":"book","type":"update","data":[{"symbol":"ETH/USD","bids":[{"price":3819.45,"qty":26.18176797}],"asks":[],"checksum":3082245820,"timestamp":"2024-06-01T22:42:44.295714Z"}]}
{"channel":"book","type":"update","data":[{"symbol":"ETH/USD","bids":[{"price":3819.68,"qty":26.16790066}],"asks":[],"checksum":3060172243,"timestamp":"2024-06-01T22:42:44.319317Z"}]}
{"channel":"book","type":"update","data":[{"symbol":"ETH/USD","bids":[{"price":3819.43,"qty":0.00000000},{"price":3819.07,"qty":4.86841079}],"asks":[],"checksum":1172110959,"timestamp":"2024-06-01T22:42:44.320291Z"}]}
{"channel":"book","type":"update","data":[{"symbol":"ETH/USD","bids":[{"price":3819.34,"qty":0.00000000},{"price":3819.00,"qty":26.18482923}],"asks":[],"checksum":3489002997,"timestamp":"2024-06-01T22:42:44.322630Z"}]}
{"channel":"book","type":"update","data":[{"symbol":"ETH/USD","bids":[{"price":3819.22,"qty":0.81295805}],"asks":[],"checksum":863922781,"timestamp":"2024-06-01T22:42:44.322831Z"}]}
{"channel":"book","type":"update","data":[{"symbol":"ETH/USD","bids":[{"price":3819.44,"qty":0.00000000},{"price":3819.00,"qty":26.18482923}],"asks":[],"checksum":2298651471,"timestamp":"2024-06-01T22:42:44.323096Z"}]}
{"channel":"book","type":"update","data":[{"symbol":"ETH/USD","bids":[{"price":3819.19,"qty":0.42254793}],"asks":[],"checksum":876413048,"timestamp":"2024-06-01T22:42:44.325777Z"}]}
{"channel":"book","type":"update","data":[{"symbol":"ETH/USD","bids":[{"price":3819.45,"qty":0.00000000},{"price":3819.00,"qty":26.18482923}],"asks":[],"checksum":1830926014,"timestamp":"2024-06-01T22:42:44.329513Z"}]}
{"channel":"book","type":"update","data":[{"symbol":"ETH/USD","bids":[{"price":3819.42,"qty":0.00000000},{"price":3818.91,"qty":3.30000000}],"asks":[],"checksum":2961150398,"timestamp":"2024-06-01T22:42:44.329647Z"}]}
{"channel":"book","type":"update","data":[{"symbol":"ETH/USD","bids":[],"asks":[{"price":3819.89,"qty":0.00000000},{"price":3820.60,"qty":3.30000000}],"checksum":357533740,"timestamp":"2024-06-01T22:42:44.329656Z"}]}
{"channel":"book","type":"update","data":[{"symbol":"ETH/USD","bids":[{"price":3819.00,"qty":0.00000000},{"price":3818.82,"qty":0.07349757}],"asks":[],"checksum":787982546,"timestamp":"2024-06-01T22:42:44.332665Z"}]}
{"channel":"book","type":"update","data":[{"symbol":"ETH/USD","bids":[{"price":3819.47,"qty":26.16800110}],"asks":[],"checksum":2552543767,"timestamp":"2024-06-01T22:42:44.335214Z"}]}
{"channel":"book","type":"update","data":[{"symbol":"ETH/USD","bids":[{"price":3819.68,"qty":0.00000000},{"price":3818.82,"qty":0.07349757}],"asks":[],"checksum":37507582,"timestamp":"2024-06-01T22:42:44.335281Z"}]}
{"channel":"book","type":"update","data":[{"symbol":"ETH/USD","bids":[],"asks":[{"price":3819.77,"qty":26.17960678}],"checksum":990051409,"timestamp":"2024-06-01T22:42:44.337570Z"}]}
{"channel":"book","type":"update","data":[{"symbol":"ETH/USD","bids":[{"price":3819.11,"qty":30.11089151}],"asks":[],"checksum":1408518670,"timestamp":"2024-06-01T22:42:44.337603Z"}]}
{"channel":"book","type":"update","data":[{"symbol":"ETH/USD","bids":[{"price":3818.85,"qty":26.18584885}],"asks":[],"checksum":3794992445,"timestamp":"2024-06-01T22:42:44.337615Z"}]}
{"channel":"book","type":"update","data":[{"symbol":"ETH/USD","bids":[],"asks":[{"price":3819.48,"qty":0.23358413}],"checksum":2483278657,"timestamp":"2024-06-01T22:42:44.340286Z"}]}
{"channel":"book","type":"update","data":[{"symbol":"ETH/USD","bids":[],"asks":[{"price":3819.69,"qty":26.41371183}],"checksum":2388957630,"timestamp":"2024-06-01T22:42:44.341714Z"}]}
{"channel":"book","type":"update","data":[{"symbol":"ETH/USD","bids":[],"asks":[{"price":3819.69,"qty":0.23357680}],"checksum":1871293865,"timestamp":"2024-06-01T22:42:44.341734Z"}]}
{"channel":"book","type":"update","data":[{"symbol":"ETH/USD","bids":[],"asks":[{"price":3819.94,"qty":0.00000000},{"price":3820.51,"qty":3.67833330}],"checksum":776760626,"timestamp":"2024-06-01T22:42:44.343160Z"}]}
{"channel":"book","type":"update","data":[{"symbol":"ETH/USD","bids":[{"price":3819.29,"qty":26.18285276}],"asks":[],"checksum":3267416540,"timestamp":"2024-06-01T22:42:44.346147Z"}]}
{"channel":"book","type":"update","data":[{"symbol":"ETH/USD","bids":[],"asks":[{"price":3819.58,"qty":26.18092305}],"checksum":3571151925,"timestamp":"2024-06-01T22:42:44.346178Z"}]}
{"channel":"book","type":"update","data":[{"symbol":"ETH/USD","bids":[],"asks":[{"price":3819.52,"qty":26.18135157}],"checksum":1902894667,"timestamp":"2024-06-01T22:42:44.346212Z"}]}
{"channel":"book","type":"update","data":[{"symbol":"ETH/USD","bids":[],"asks":[{"price":3819.52,"qty":0.00000000},{"price":3820.23,"qty":0.48396891}],"checksum":3571151925,"timestamp":"2024-06-01T22:42:44.361586Z"}]}
{"channel":"book","type":"update","data":[{"symbol":"ETH/USD","bids":[{"price":3819.29,"qty":0.00000000},{"price":3818.85,"qty":26.18584885}],"asks":[],"checksum":945277147,"timestamp":"2024-06-01T22:42:44.361680Z"}]}
{"channel":"book","type":"update","data":[{"symbol":"ETH/USD","bids":[{"price":3819.21,"qty":0.00000000},{"price":3818.82,"qty":0.07349757}],"asks":[],"checksum":3271625029,"timestamp":"2024-06-01T22:42:44.363121Z"}]}
{"channel":"book","type":"update","data":[{"symbol":"ETH/USD","bids":[{"price":3819.01,"qty":0.00908081}],"asks":[],"checksum":3529832517,"timestamp":"2024-06-01T22:42:44.374736Z"}]}
{"channel":"book","type":"update","data":[{"symbol":"ETH/USD","bids":[{"price":3819.25,"qty":26.19680174}],"asks":[],"checksum":1992499510,"timestamp":"2024-06-01T22:42:44.384717Z"}]}
{"channel":"book","type":"update","data":[{"symbol":"ETH/USD","bids":[{"price":3819.25,"qty":0.01368441}],"asks":[],"checksum":3529832517,"timestamp":"2024-06-01T22:42:44.389764Z"}]}
{"channel":"book","type":"update","data":[{"symbol":"ETH/USD","bids":[],"asks":[{"price":3819.58,"qty":0.00000000},{"price":3820.31,"qty":0.72912968}],"checksum":1853536853,"timestamp":"2024-06-01T22:42:44.391088Z"}]}
{"channel":"book","type":"update","data":[{"symbol":"ETH/USD","bids":[{"price":3819.31,"qty":0.00000000},{"price":3818.82,"qty":0.07349757}],"asks":[],"checksum":2204258499,"timestamp":"2024-06-01T22:42:44.396507Z"}]}
{"channel":"book","type":"update","data":[{"symbol":"ETH/USD","bids":[],"asks":[{"price":3819.60,"qty":26.18077367}],"checksum":1604379441,"timestamp":"2024-06-01T22:42:44.397792Z"}]}
{"channel":"book","type":"update","data":[{"symbol":"ETH/USD","bids":[{"price":3819.38,"qty":26.18221485}],"asks":[],"checksum":2095253046,"timestamp":"2024-06-01T22:42:44.397810Z"}]}
{"channel":"book","type":"update","data":[{"symbol":"ETH/USD","bids":[{"price":3818.92,"qty":3.92659878}],"asks":[],"checksum":2427517680,"timestamp":"2024-06-01T22:42:44.401572Z"}]}
{"channel":"book","type":"update","data":[{"symbol":"ETH/USD","bids":[{"price":3819.38,"qty":0.00000000},{"price":3818.85,"qty":26.18584885}],"asks":[],"checksum":1077373101,"timestamp":"2024-06-01T22:42:44.431596Z"}]}
{"channel":"book","type":"update","data":[{"symbol":"ETH/USD","bids":[{"price":3819.38,"qty":0.77000000}],"asks":[],"checksum":325319327,"timestamp":"2024-06-01T22:42:44.431740Z"}]}
{"channel":"book","type":"update","data":[{"symbol":"ETH/USD","bids":[],"asks":[{"price":3819.60,"qty":0.00000000},{"price":3820.31,"qty":0.72912968}],"checksum":3483453805,"timestamp":"2024-06-01T22:42:44.434051Z"}]}
{"channel":"book","type":"update","data":[{"symbol":"ETH/USD","bids":[{"price":3819.32,"qty":26.16908086}],"asks":[],"checksum":2073825568,"timestamp":"2024-06-01T22:42:44.486871Z"}]}
{"channel":"book","type":"update","data":[{"symbol":"ETH/USD","bids":[{"price":3819.47,"qty":0.00000000},{"price":3818.91,"qty":3.30000000}],"asks":[],"checksum":4292043182,"timestamp":"2024-06-01T22:42:44.486900Z"}]}
{"channel":"book","type":"update","data":[{"symbol":"ETH/USD","bids":[],"asks":[{"price":3819.39,"qty":0.23359331}],"checksum":2595432355,"timestamp":"2024-06-01T22:42:44.491960Z"}]}
{"channel":"book","type":"update","data":[{"symbol":"ETH/USD","bids":[],"asks":[{"price":3819.72,"qty":0.55231370}],"checksum":3553140287,"timestamp":"2024-06-01T22:42:44.494791Z"}]}
{"channel":"book","type":"update","data":[{"symbol":"ETH/USD","bids":[],"asks":[{"price":3819.58,"qty":26.18093338}],"checksum":446089553,"timestamp":"2024-06-01T22:42:44.501318Z"}]}
{"channel":"book","type":"update","data":[{"symbol":"ETH/USD","bids":[{"price":3819.34,"qty":26.18246622}],"asks":[],"checksum":6554553,"timestamp":"2024-06-01T22:42:44.501339Z"}]}
{"channel":"book","type":"update","data":[{"symbol":"ETH/USD","bids":[],"asks":[{"price":3819.58,"qty":0.00000000},{"price":3820.23,"qty":0.48396891}],"checksum":2863075761,"timestamp":"2024-06-01T22:42:44.565156Z"}]}
{"channel":"book","type":"update","data":[{"symbol":"ETH/USD","bids":[{"price":3819.38,"qty":1.29364519}],"asks":[],"checksum":827611924,"timestamp":"2024-06-01T22:42:44.569456Z"}]}
{"channel":"book","type":"update","data":[{"symbol":"ETH/USD","bids":[{"price":3819.32,"qty":52.35169895}],"asks":[],"checksum":1941932981,"timestamp":"2024-06-01T22:42:44.570249Z"}]}
{"channel":"book","type":"update","data":[{"symbol":"ETH/USD","bids":[],"asks":[{"price":3819.57,"qty":26.18098575}],"checksum":797284008,"timestamp":"2024-06-01T22:42:44.570277Z"}]}
{"channel":"book","type":"update","data":[{"symbol":"ETH/USD","bids":[],"asks":[{"price":3819.64,"qty":26.18049702}],"checksum":4190930705,"timestamp":"2024-06-01T22:42:44.570379Z"}]}
{"channel":"book","type":"update","data":[{"symbol":"ETH/USD","bids":[{"price":3819.38,"qty":0.77000000}],"asks":[],"checksum":4270426379,"timestamp":"2024-06-01T22:42:44.574293Z"}]}
{"channel":"book","type":"update","data":[{"symbol":"ETH/USD","bids":[{"price":3819.01,"qty":0.00000000},{"price":3818.91,"qty":3.30000000},{"price":3819.35,"qty":0.00908000}],"asks":[],"checksum":1077088466,"timestamp":"2024-06-01T22:42:44.588071Z"}]}
{"channel":"book","type":"update","data":[{"symbol":"ETH/USD","bids":[{"price":3819.34,"qty":0.00000000},{"price":3818.91,"qty":3.30000000}],"asks":[],"checksum":3329179888,"timestamp":"2024-06-01T22:42:44.711229Z"}]}
{"channel":"book","type":"update","data":[{"symbol":"ETH/USD","bids":[{"price":3819.35,"qty":26.19151742}],"asks":[],"checksum":2198866477,"timestamp":"2024-06-01T22:42:44.715992Z"}]}
{"channel":"book","type":"update","data":[{"symbol":"ETH/USD","bids":[{"price":3819.32,"qty":26.18261809}],"asks":[],"checksum":3242184717,"timestamp":"2024-06-01T22:42:44.724349Z"}]}
{"channel":"book","type":"update","data":[{"symbol":"ETH/USD","bids":[{"price":3819.38,"qty":26.93995638}],"asks":[],"checksum":3994983384,"timestamp":"2024-06-01T22:42:44.724597Z"}]}
{"channel":"book","type":"update","data":[{"symbol":"ETH/USD","bids":[],"asks":[{"price":3819.57,"qty":0.00000000},{"price":3820.10,"qty":2.09900000}],"checksum":2770552943,"timestamp":"2024-06-01T22:42:44.724627Z"}]}
{"channel":"book","type":"update","data":[{"symbol":"ETH/USD","bids":[],"asks":[{"price":3819.59,"qty":26.18086531}],"checksum":2466200070,"timestamp":"2024-06-01T22:42:44.728721Z"}]}
{"channel":"book","type":"update","data":[{"symbol":"ETH/USD","bids":[{"price":3819.35,"qty":26.18243742},{"price":3819.33,"qty":0.00908005}],"asks":[],"checksum":3654219065,"timestamp":"2024-06-01T22:42:44.771491Z"}]}
{"channel":"book","type":"update","data":[{"symbol":"ETH/USD","bids":[],"asks":[{"price":3819.59,"qty":0.00000000},{"price":3820.10,"qty":2.09900000}],"checksum":3032410357,"timestamp":"2024-06-01T22:42:44.824466Z"}]}
{"channel":"book","type":"update","data":[{"symbol":"ETH/USD","bids":[{"price":3819.33,"qty":0.00000000},{"price":3818.91,"qty":3.30000000},{"price":3819.36,"qty":0.00907998}],"asks":[],"checksum":1289002780,"timestamp":"2024-06-01T22:42:44.826633Z"}]}
{"channel":"book","type":"update","data":[{"symbol":"ETH/USD","bids":[],"asks":[{"price":3819.56,"qty":26.18102756}],"checksum":2335055849,"timestamp":"2024-06-01T22:42:44.829044Z"}]}
{"channel":"book","type":"update","data":[{"symbol":"ETH/USD","bids":[{"price":3819.35,"qty":0.00000000},{"price":3818.91,"qty":3.30000000}],"asks":[],"checksum":1922242402,"timestamp":"2024-06-01T22:42:44.830806Z"}]}
{"channel":"book","type":"update","data":[{"symbol":"ETH/USD","bids":[{"price":3819.33,"qty":26.18257016}],"asks":[],"checksum":4179390434,"timestamp":"2024-06-01T22:42:44.835089Z"}]}
{"channel":"book","type":"update","data":[{"symbol":"ETH/USD","bids":[{"price":3819.33,"qty":0.00000000},{"price":3818.91,"qty":3.30000000}],"asks":[],"checksum":1922242402,"timestamp":"2024-06-01T22:42:44.846926Z"}]}
{"channel":"book","type":"update","data":[{"symbol":"ETH/USD","bids":[],"asks":[{"price":3819.56,"qty":0.00000000},{"price":3820.10,"qty":2.09900000}],"checksum":1606112793,"timestamp":"2024-06-01T22:42:44.878931Z"}]}
{"channel":"book","type":"update","data":[{"symbol":"ETH/USD","bids":[],"asks":[{"price":3819.58,"qty":26.18091759}],"checksum":3573655819,"timestamp":"2024-06-01T22:42:44.883484Z"}]}
{"channel":"book","type":"update","data":[{"symbol":"ETH/USD","bids":[{"price":3819.35,"qty":26.18242091}],"asks":[],"checksum":902062164,"timestamp":"2024-06-01T22:42:44.889163Z"}]}
{"channel":"book","type":"update","data":[{"symbol":"ETH/USD","bids":[],"asks":[{"price":3819.58,"qty":0.00000000},{"price":3820.10,"qty":2.09900000}],"checksum":3338120163,"timestamp":"2024-06-01T22:42:44.903368Z"}]}
{"channel":"book","type":"update","data":[{"symbol":"ETH/USD","bids":[{"price":3819.36,"qty":0.00000000},{"price":3818.91,"qty":3.30000000},{"price":3819.34,"qty":0.00908002}],"asks":[],"checksum":3635887355,"timestamp":"2024-06-01T22:42:44.938693Z"}]}
{"channel":"book","type":"update","data":[{"symbol":"ETH/USD","bids":[{"price":3819.35,"qty":0.00000000},{"price":3818.91,"qty":3.30000000}],"asks":[],"checksum":3120692505,"timestamp":"2024-06-01T22:42:45.018143Z"}]}
{"channel":"book","type":"update","data":[{"symbol":"ETH/USD","bids":[{"price":3819.36,"qty":26.18236432}],"asks":[],"checksum":546697064,"timestamp":"2024-06-01T22:42:45.023671Z"}]}
{"channel":"book","type":"update","data":[{"symbol":"ETH/USD","bids":[],"asks":[{"price":3819.59,"qty":26.18087518}],"checksum":3992607360,"timestamp":"2024-06-01T22:42:45.023723Z"}]}
{"channel":"book","type":"update","data":[{"symbol":"ETH/USD","bids":[{"price":3819.34,"qty":0.00000000},{"price":3818.91,"qty":3.30000000},{"price":3819.37,"qty":0.00907995}],"asks":[],"checksum":3879352782,"timestamp":"2024-06-01T22:42:45.148806Z"}]}
{"channel":"book","type":"update","data":[{"symbol":"ETH/USD","bids":[{"price":3819.22,"qty":0.00000000},{"price":3818.91,"qty":3.30000000}],"asks":[],"checksum":1127901694,"timestamp":"2024-06-01T22:42:45.152455Z"}]}
{"channel":"book","type":"update","data":[{"symbol":"ETH/USD","bids":[],"asks":[{"price":3819.59,"qty":0.00000000},{"price":3820.10,"qty":2.09900000}],"checksum":3978718209,"timestamp":"2024-06-01T22:42:45.155270Z"}]}
{"channel":"book","type":"update","data":[{"symbol":"ETH/USD","bids":[],"asks":[{"price":3819.58,"qty":26.18095635}],"checksum":1382805952,"timestamp":"2024-06-01T22:42:45.159584Z"}]}
{"channel":"book","type":"update","data":[{"symbol":"ETH/USD","bids":[{"price":3819.38,"qty":27.75291443}],"asks":[],"checksum":3325225909,"timestamp":"2024-06-01T22:42:45.284048Z"}]}
{"channel":"book","type":"update","data":[{"symbol":"ETH/USD","bids":[],"asks":[{"price":3819.58,"qty":0.00000000},{"price":3820.10,"qty":2.09900000}],"checksum":2038396532,"timestamp":"2024-06-01T22:42:45.330188Z"}]}
{"channel":"book","type":"update","data":[{"symbol":"ETH/USD","bids":[{"price":3819.36,"qty":0.00000000},{"price":3818.85,"qty":26.18584885}],"asks":[],"checksum":3496553078,"timestamp":"2024-06-01T22:42:45.330218Z"}]}
{"channel":"book","type":"update","data":[{"symbol":"ETH/USD","bids":[{"price":3819.34,"qty":26.18248215}],"asks":[],"checksum":1856058050,"timestamp":"2024-06-01T22:42:45.334972Z"}]}
{"channel":"book","type":"update","data":[{"symbol":"ETH/USD","bids":[],"asks":[{"price":3819.56,"qty":26.18104275}],"checksum":1547232911,"timestamp":"2024-06-01T22:42:45.335078Z"}]}
{"channel":"book","type":"update","data":[{"symbol":"ETH/USD","bids":[],"asks":[{"price":3819.56,"qty":0.00000000},{"price":3820.10,"qty":2.09900000}],"checksum":1856058050,"timestamp":"2024-06-01T22:42:45.347083Z"}]}
{"channel":"book","type":"update","data":[{"symbol":"ETH/USD","bids":[{"price":3819.37,"qty":0.00000000},{"price":3818.85,"qty":26.18584885},{"price":3819.33,"qty":0.00908005}],"asks":[],"checksum":3211135419,"timestamp":"2024-06-01T22:42:45.356657Z"}]}
{"channel":"book","type":"update","data":[{"symbol":"ETH/USD","bids":[],"asks":[{"price":3819.56,"qty":26.18106865}],"checksum":1543908793,"timestamp":"2024-06-01T22:42:45.431830Z"}]}
{"channel":"book","type":"update","data":[{"symbol":"ETH/USD","bids":[],"asks":[{"price":3819.56,"qty":0.00000000},{"price":3820.10,"qty":2.09900000}],"checksum":3211135419,"timestamp":"2024-06-01T22:42:45.516802Z"}]}
{"channel":"book","type":"update","data":[{"symbol":"ETH/USD","bids":[],"asks":[{"price":3819.55,"qty":26.18109484}],"checksum":340031787,"timestamp":"2024-06-01T22:42:45.520755Z"}]}
{"channel":"book","type":"update","data":[{"symbol":"ETH/USD","bids":[{"price":3819.33,"qty":0.00000000},{"price":3818.85,"qty":26.18584885},{"price":3819.35,"qty":0.00908000}],"asks":[],"checksum":1704713847,"timestamp":"2024-06-01T22:42:45.524438Z"}]}
{"channel":"book","type":"update","data":[{"symbol":"ETH/USD","bids":[],"asks":[{"price":3819.55,"qty":0.00000000},{"price":3820.10,"qty":2.09900000}],"checksum":3468275431,"timestamp":"2024-06-01T22:42:45.559915Z"}]}
{"channel":"book","type":"update","data":[{"symbol":"ETH/USD","bids":[{"price":3819.34,"qty":0.00000000},{"price":3818.85,"qty":26.18584885}],"asks":[],"checksum":1886500435,"timestamp":"2024-06-01T22:42:45.560050Z"}]}
{"channel":"book","type":"update","data":[{"symbol":"ETH/USD","bids":[{"price":3819.38,"qty":43.45930955}],"asks":[],"checksum":3639358479,"timestamp":"2024-06-01T22:42:45.564046Z"}]}
{"channel":"book","type":"update","data":[{"symbol":"ETH/USD","bids":[{"price":3819.35,"qty":26.19148883}],"asks":[],"checksum":998419237,"timestamp":"2024-06-01T22:42:45.565052Z"}]}
{"channel":"book","type":"update","data":[{"symbol":"ETH/USD","bids":[{"price":3819.35,"qty":0.00908000}],"asks":[],"checksum":3639358479,"timestamp":"2024-06-01T22:42:45.586188Z"}]}
{"channel":"book","type":"update","data":[{"symbol":"ETH/USD","bids":[],"asks":[{"price":3819.60,"qty":26.18075824}],"checksum":1528572305,"timestamp":"2024-06-01T22:42:45.590569Z"}]}
{"channel":"book","type":"update","data":[{"symbol":"ETH/USD","bids":[{"price":3819.35,"qty":0.00000000},{"price":3818.82,"qty":0.07349757},{"price":3819.12,"qty":0.00908055}],"asks":[],"checksum":2143781259,"timestamp":"2024-06-01T22:42:45.611263Z"}]}
{"channel":"book","type":"update","data":[{"symbol":"ETH/USD","bids":[],"asks":[{"price":3819.60,"qty":0.00000000},{"price":3820.10,"qty":2.09900000}],"checksum":4231502869,"timestamp":"2024-06-01T22:42:45.660825Z"}]}
{"channel":"book","type":"update","data":[{"symbol":"ETH/USD","bids":[{"price":3819.38,"qty":69.64156949}],"asks":[],"checksum":2762829713,"timestamp":"2024-06-01T22:42:45.664957Z"}]}
{"channel":"book","type":"update","data":[{"symbol":"ETH/USD","bids":[],"asks":[{"price":3819.59,"qty":26.18084465}],"checksum":1372616758,"timestamp":"2024-06-01T22:42:45.665010Z"}]}
{"channel":"book","type":"update","data":[{"symbol":"ETH/USD","bids":[{"price":3819.38,"qty":43.45930955}],"asks":[],"checksum":155880370,"timestamp":"2024-06-01T22:42:45.669361Z"}]}
{"channel":"book","type":"update","data":[{"symbol":"ETH/USD","bids":[],"asks":[{"price":3819.59,"qty":0.00000000},{"price":3820.10,"qty":2.09900000}],"checksum":4231502869,"timestamp":"2024-06-01T22:42:45.672099Z"}]}
{"channel":"book","type":"update","data":[{"symbol":"ETH/USD","bids":[],"asks":[{"price":3819.39,"qty":0.00000000},{"price":3820.23,"qty":0.48396891}],"checksum":3427223319,"timestamp":"2024-06-01T22:42:45.710805Z"}]}
{"channel":"book","type":"update","data":[{"symbol":"ETH/USD","bids":[],"asks":[{"price":3819.48,"qty":0.00000000},{"price":3820.31,"qty":0.72912968}],"checksum":3133574224,"timestamp":"2024-06-01T22:42:45.713697Z"}]}
{"channel":"book","type":"update","data":[{"symbol":"ETH/USD","bids":[{"price":3819.38,"qty":43.88189067}],"asks":[],"checksum":409230108,"timestamp":"2024-06-01T22:42:45.714096Z"}]}
{"channel":"book","type":"update","data":[{"symbol":"ETH/USD","bids":[{"price":3819.49,"qty":0.42256729}],"asks":[],"checksum":1575959683,"timestamp":"2024-06-01T22:42:45.718717Z"}]}
{"channel":"book","type":"update","data":[{"symbol":"ETH/USD","bids":[{"price":3819.49,"qty":0.00000000},{"price":3818.85,"qty":26.18584885}],"asks":[],"checksum":409230108,"timestamp":"2024-06-01T22:42:45.758441Z"}]}
{"channel":"book","type":"update","data":[{"symbol":"ETH/USD","bids":[{"price":3819.38,"qty":43.45930955}],"asks":[],"checksum":3133574224,"timestamp":"2024-06-01T22:42:45.761211Z"}]}
{"channel":"book","type":"update","data":[{"symbol":"ETH/USD","bids":[],"asks":[{"price":3819.50,"qty":0.23358505}],"checksum":1583560152,"timestamp":"2024-06-01T22:42:45.761454Z"}]}
{"channel":"book","type":"update","data":[{"symbol":"ETH/USD","bids":[],"asks":[{"price":3819.39,"qty":0.23358842}],"checksum":322192239,"timestamp":"2024-06-01T22:42:45.765618Z"}]}
{"channel":"book","type":"update","data":[{"symbol":"ETH/USD","bids":[{"price":3819.36,"qty":26.18234503}],"asks":[],"checksum":1585252556,"timestamp":"2024-06-01T22:42:46.237691Z"}]}
{"channel":"book","type":"update","data":[{"symbol":"ETH/USD","bids":[],"asks":[{"price":3819.57,"qty":26.18097605}],"checksum":95557830,"timestamp":"2024-06-01T22:42:46.237713Z"}]}
{"channel":"book","type":"update","data":[{"symbol":"ETH/USD","bids":[],"asks":[{"price":3819.57,"qty":0.00000000},{"price":3820.10,"qty":2.09900000}],"checksum":1585252556,"timestamp":"2024-06-01T22:42:46.489230Z"}]}
{"channel":"book","type":"update","data":[{"symbol":"ETH/USD","bids":[{"price":3819.36,"qty":0.00000000},{"price":3818.85,"qty":26.18584885}],"asks":[],"checksum":322192239,"timestamp":"2024-06-01T22:42:46.489328Z"}]}
{"channel":"book","type":"update","data":[{"symbol":"ETH/USD","bids":[],"asks":[{"price":3819.60,"qty":26.18080474}],"checksum":1016604689,"timestamp":"2024-06-01T22:42:46.494026Z"}]}
{"channel":"book","type":"update","data":[{"symbol":"ETH/USD","bids":[{"price":3819.38,"qty":69.64156949}],"asks":[],"checksum":1677908885,"timestamp":"2024-06-01T22:42:46.494040Z"}]}
{"channel":"book","type":"update","data":[{"symbol":"ETH/USD","bids":[],"asks":[{"price":3819.60,"qty":0.00000000},{"price":3820.10,"qty":2.09900000}],"checksum":1269739755,"timestamp":"2024-06-01T22:42:46.644748Z"}]}
{"channel":"book","type":"update","data":[{"symbol":"ETH/USD","bids":[],"asks":[{"price":3819.62,"qty":26.18067121}],"checksum":3669093452,"timestamp":"2024-06-01T22:42:46.648961Z"}]}
{"channel":"book","type":"update","data":[{"symbol":"ETH/USD","bids":[],"asks":[{"price":3819.62,"qty":0.00000000},{"price":3820.10,"qty":2.09900000}],"checksum":1269739755,"timestamp":"2024-06-01T22:42:46.699079Z"}]}
{"channel":"book","type":"update","data":[{"symbol":"ETH/USD","bids":[],"asks":[{"price":3819.61,"qty":26.18073405}],"checksum":3572150088,"timestamp":"2024-06-01T22:42:46.703241Z"}]}
{"channel":"book","type":"update","data":[{"symbol":"ETH/USD","bids":[],"asks":[{"price":3819.61,"qty":0.00000000},{"price":3820.10,"qty":2.09900000}],"checksum":1269739755,"timestamp":"2024-06-01T22:42:47.109559Z"}]}
{"channel":"book","type":"update","data":[{"symbol":"ETH/USD","bids":[],"asks":[{"price":3819.60,"qty":26.18078479}],"checksum":1322215094,"timestamp":"2024-06-01T22:42:47.113784Z"}]}
{"channel":"book","type":"update","data":[{"symbol":"ETH/USD","bids":[],"asks":[{"price":3819.60,"qty":0.00000000},{"price":3820.10,"qty":2.09900000}],"checksum":1269739755,"timestamp":"2024-06-01T22:42:47.494473Z"}]}
{"channel":"book","type":"update","data":[{"symbol":"ETH/USD","bids":[],"asks":[{"price":3819.63,"qty":26.18059615}],"checksum":1818204012,"timestamp":"2024-06-01T22:42:47.498848Z"}]}
{"channel":"book","type":"update","data":[{"symbol":"ETH/USD","bids":[],"asks":[{"price":3819.63,"qty":0.00000000},{"price":3820.10,"qty":2.09900000}],"checksum":1269739755,"timestamp":"2024-06-01T22:42:47.984563Z"}]}
{"channel":"book","type":"update","data":[{"symbol":"ETH/USD","bids":[],"asks":[{"price":3819.62,"qty":26.18062985}],"checksum":4158839126,"timestamp":"2024-06-01T22:42:47.989054Z"}]}
{"channel":"book","type":"update","data":[{"symbol":"ETH/USD","bids":[],"asks":[{"price":3819.62,"qty":0.00000000},{"price":3820.10,"qty":2.09900000}],"checksum":1269739755,"timestamp":"2024-06-01T22:42:48.284936Z"}]}
{"channel":"book","type":"update","data":[{"symbol":"ETH/USD","bids":[],"asks":[{"price":3819.61,"qty":26.18069269}],"checksum":2697318004,"timestamp":"2024-06-01T22:42:48.289869Z"}]}
{"channel":"book","type":"update","data":[{"symbol":"ETH/USD","bids":[],"asks":[{"price":3819.61,"qty":0.00000000},{"price":3820.10,"qty":2.09900000}],"checksum":1269739755,"timestamp":"2024-06-01T22:42:48.499480Z"}]}
{"channel":"book","type":"update","data":[{"symbol":"ETH/USD","bids":[],"asks":[{"price":3819.86,"qty":26.17901039}],"checksum":752186280,"timestamp":"2024-06-01T22:42:48.503980Z"}]}
{"channel":"book","type":"update","data":[{"symbol":"ETH/USD","bids":[],"asks":[{"price":3819.77,"qty":0.00000000},{"price":3820.10,"qty":2.09900000}],"checksum":4183248549,"timestamp":"2024-06-01T22:42:48.540917Z"}]}
{"channel":"book","type":"update","data":[{"symbol":"ETH/USD","bids":[],"asks":[{"price":3819.63,"qty":26.18057083}],"checksum":1921841672,"timestamp":"2024-06-01T22:42:48.545457Z"}]}
{"channel":"book","type":"update","data":[{"symbol":"ETH/USD","bids":[],"asks":[{"price":3819.63,"qty":0.00000000},{"price":3820.10,"qty":2.09900000}],"checksum":4183248549,"timestamp":"2024-06-01T22:42:49.262791Z"}]}
{"channel":"book","type":"update","data":[{"symbol":"ETH/USD","bids":[{"price":3818.85,"qty":0.00000000},{"price":3818.82,"qty":0.07349757}],"asks":[],"checksum":536863361,"timestamp":"2024-06-01T22:42:49.262809Z"}]}
{"channel":"book","type":"update","data":[{"symbol":"ETH/USD","bids":[],"asks":[{"price":3819.71,"qty":26.18000059}],"checksum":2531125461,"timestamp":"2024-06-01T22:42:49.268098Z"}]}
{"channel":"book","type":"update","data":[{"symbol":"ETH/USD","bids":[{"price":3819.22,"qty":26.18330215}],"asks":[],"checksum":624810696,"timestamp":"2024-06-01T22:42:49.268153Z"}]}
{"channel":"book","type":"update","data":[{"symbol":"ETH/USD","bids":[{"price":3819.12,"qty":0.00000000},{"price":3818.82,"qty":0.07349757}],"asks":[],"checksum":1669004502,"timestamp":"2024-06-01T22:42:49.320450Z"}]}
{"channel":"book","type":"update","data":[{"symbol":"ETH/USD","bids":[],"asks":[{"price":3819.64,"qty":0.00000000},{"price":3820.10,"qty":2.09900000}],"checksum":514252726,"timestamp":"2024-06-01T22:42:49.325983Z"}]}
{"channel":"book","type":"update","data":[{"symbol":"ETH/USD","bids":[],"asks":[{"price":3819.71,"qty":0.00000000},{"price":3820.23,"qty":0.48396891}],"checksum":3966522928,"timestamp":"2024-06-01T22:42:49.330569Z"}]}
{"channel":"book","type":"update","data":[{"symbol":"ETH/USD","bids":[{"price":3819.38,"qty":70.16521468}],"asks":[],"checksum":463608255,"timestamp":"2024-06-01T22:42:49.334879Z"}]}
{"channel":"book","type":"update","data":[{"symbol":"ETH/USD","bids":[],"asks":[{"price":3819.70,"qty":26.18009417}],"checksum":3015178835,"timestamp":"2024-06-01T22:42:49.335409Z"}]}
{"channel":"book","type":"update","data":[{"symbol":"ETH/USD","bids":[{"price":3819.38,"qty":69.64156949}],"asks":[],"checksum":1148827100,"timestamp":"2024-06-01T22:42:49.339504Z"}]}
{"channel":"book","type":"update","data":[{"symbol":"ETH/USD","bids":[],"asks":[{"price":3819.70,"qty":0.00000000},{"price":3820.23,"qty":0.48396891}],"checksum":3966522928,"timestamp":"2024-06-01T22:42:49.451775Z"}]}
{"channel":"book","type":"update","data":[{"symbol":"ETH/USD","bids":[{"price":3819.38,"qty":70.16521468}],"asks":[],"checksum":463608255,"timestamp":"2024-06-01T22:42:49.455956Z"}]}
{"channel":"book","type":"update","data":[{"symbol":"ETH/USD","bids":[],"asks":[{"price":3819.69,"qty":26.41372229}],"checksum":1275610440,"timestamp":"2024-06-01T22:42:49.456039Z"}]}
{"channel":"book","type":"update","data":[{"symbol":"ETH/USD","bids":[{"price":3819.38,"qty":69.64156949}],"asks":[],"checksum":3150318279,"timestamp":"2024-06-01T22:42:49.460252Z"}]}
{"channel":"book","type":"update","data":[{"symbol":"ETH/USD","bids":[],"asks":[{"price":3819.69,"qty":0.23357680}],"checksum":3966522928,"timestamp":"2024-06-01T22:42:49.729446Z"}]}
{"channel":"book","type":"update","data":[{"symbol":"ETH/USD","bids":[{"price":3819.38,"qty":70.16521468}],"asks":[],"checksum":463608255,"timestamp":"2024-06-01T22:42:49.733672Z"}]}
{"channel":"book","type":"update","data":[{"symbol":"ETH/USD","bids":[],"asks":[{"price":3819.78,"qty":26.17956598}],"checksum":886152735,"timestamp":"2024-06-01T22:42:49.734170Z"}]}
{"channel":"book","type":"update","data":[{"symbol":"ETH/USD","bids":[],"asks":[{"price":3819.68,"qty":26.18021095}],"checksum":1755686039,"timestamp":"2024-06-01T22:42:49.734322Z"}]}
{"channel":"book","type":"update","data":[{"symbol":"ETH/USD","bids":[{"price":3819.38,"qty":69.64156949}],"asks":[],"checksum":2674649880,"timestamp":"2024-06-01T22:42:49.738545Z"}]}
{"channel":"book","type":"update","data":[{"symbol":"ETH/USD","bids":[],"asks":[{"price":3819.78,"qty":0.00000000},{"price":3820.10,"qty":2.09900000}],"checksum":1374274996,"timestamp":"2024-06-01T22:42:49.789301Z"}]}
{"channel":"book","type":"update","data":[{"symbol":"ETH/USD","bids":[],"asks":[{"price":3819.65,"qty":26.18040993}],"checksum":3463377038,"timestamp":"2024-06-01T22:42:49.793359Z"}]}
{"channel":"book","type":"update","data":[{"symbol":"ETH/USD","bids":[],"asks":[{"price":3819.65,"qty":0.00000000},{"price":3820.10,"qty":2.09900000}],"checksum":1374274996,"timestamp":"2024-06-01T22:42:49.838004Z"}]}
{"channel":"book","type":"update","data":[{"symbol":"ETH/USD","bids":[],"asks":[{"price":3819.68,"qty":0.00000000},{"price":3820.23,"qty":0.48396891}],"checksum":3966522928,"timestamp":"2024-06-01T22:42:49.941812Z"}]}
{"channel":"book","type":"update","data":[{"symbol":"ETH/USD","bids":[],"asks":[{"price":3819.66,"qty":26.18035022}],"checksum":3469146097,"timestamp":"2024-06-01T22:42:49.946423Z"}]}
{"channel":"book","type":"update","data":[{"symbol":"ETH/USD","bids":[],"asks":[{"price":3819.75,"qty":26.17977751}],"checksum":3658615820,"timestamp":"2024-06-01T22:42:49.946610Z"}]}
{"channel":"book","type":"update","data":[{"symbol":"ETH/USD","bids":[],"asks":[{"price":3819.75,"qty":0.00000000},{"price":3820.10,"qty":2.09900000}],"checksum":3469146097,"timestamp":"2024-06-01T22:42:49.952133Z"}]}
{"channel":"book","type":"update","data":[{"symbol":"ETH/USD","bids":[{"price":3819.38,"qty":68.82861144}],"asks":[],"checksum":2604629574,"timestamp":"2024-06-01T22:42:50.157196Z"}]}
{"channel":"book","type":"update","data":[{"symbol":"ETH/USD","bids":[{"price":3819.38,"qty":68.05861144}],"asks":[],"checksum":3617057964,"timestamp":"2024-06-01T22:42:50.158339Z"}]}
{"channel":"book","type":"update","data":[{"symbol":"ETH/USD","bids":[{"price":3819.19,"qty":0.00000000},{"price":3818.64,"qty":0.00908133}],"asks":[],"checksum":916913282,"timestamp":"2024-06-01T22:42:50.159040Z"}]}
{"channel":"book","type":"update","data":[{"symbol":"ETH/USD","bids":[{"price":3819.38,"qty":41.88865506}],"asks":[],"checksum":2231663853,"timestamp":"2024-06-01T22:42:50.160603Z"}]}
{"channel":"book","type":"update","data":[{"symbol":"ETH/USD","bids":[{"price":3819.23,"qty":26.17061070}],"asks":[],"checksum":2052384505,"timestamp":"2024-06-01T22:42:50.160660Z"}]}
{"channel":"book","type":"update","data":[{"symbol":"ETH/USD","bids":[{"price":3819.11,"qty":30.53347263}],"asks":[],"checksum":88367667,"timestamp":"2024-06-01T22:42:50.162148Z"}]}
{"channel":"book","type":"update","data":[{"symbol":"ETH/USD","bids":[],"asks":[{"price":3819.86,"qty":0.00000000},{"price":3820.23,"qty":0.48396891}],"checksum":3749855214,"timestamp":"2024-06-01T22:42:50.162230Z"}]}
{"channel":"book","type":"update","data":[{"symbol":"ETH/USD","bids":[{"price":3819.38,"qty":15.70639512}],"asks":[],"checksum":3961110567,"timestamp":"2024-06-01T22:42:50.162313Z"}]}
{"channel":"book","type":"update","data":[{"symbol":"ETH/USD","bids":[{"price":3819.32,"qty":0.00000000},{"price":3818.64,"qty":0.00908133}],"asks":[],"checksum":4172574365,"timestamp":"2024-06-01T22:42:50.164458Z"}]}
{"channel":"book","type":"update","data":[{"symbol":"ETH/USD","bids":[],"asks":[{"price":3819.66,"qty":0.00000000},{"price":3820.31,"qty":0.72912968}],"checksum":2734098408,"timestamp":"2024-06-01T22:42:50.164557Z"}]}
{"channel":"book","type":"update","data":[{"symbol":"ETH/USD","bids":[{"price":3819.11,"qty":30.11089151}],"asks":[],"checksum":3622370408,"timestamp":"2024-06-01T22:42:50.165970Z"}]}
{"channel":"book","type":"update","data":[{"symbol":"ETH/USD","bids":[],"asks":[{"price":3820.08,"qty":31.40952870}],"checksum":1093946207,"timestamp":"2024-06-01T22:42:50.168445Z"}]}
{"channel":"book","type":"update","data":[{"symbol":"ETH/USD","bids":[{"price":3819.26,"qty":15.70725859}],"asks":[],"checksum":3029321169,"timestamp":"2024-06-01T22:42:50.169299Z"}]}
{"channel":"book","type":"update","data":[{"symbol":"ETH/USD","bids":[{"price":3818.84,"qty":26.18594618}],"asks":[],"checksum":1177075561,"timestamp":"2024-06-01T22:42:50.169379Z"}]}
{"channel":"book","type":"update","data":[{"symbol":"ETH/USD","bids":[{"price":3819.26,"qty":41.89029516}],"asks":[],"checksum":1794948698,"timestamp":"2024-06-01T22:42:50.169418Z"}]}
{"channel":"book","type":"update","data":[{"symbol":"ETH/USD","bids":[],"asks":[{"price":3819.73,"qty":26.17991365}],"checksum":3349183922,"timestamp":"2024-06-01T22:42:50.169464Z"}]}
{"channel":"book","type":"update","data":[{"symbol":"ETH/USD","bids":[],"asks":[{"price":3819.51,"qty":26.18141299}],"checksum":2352485264,"timestamp":"2024-06-01T22:42:50.169484Z"}]}
{"channel":"book","type":"update","data":[{"symbol":"ETH/USD","bids":[],"asks":[{"price":3820.08,"qty":26.17752870}],"checksum":512486703,"timestamp":"2024-06-01T22:42:50.177921Z"}]}
{"channel":"book","type":"update","data":[{"symbol":"ETH/USD","bids":[{"price":3819.07,"qty":0.00000000},{"price":3818.82,"qty":0.07349757}],"asks":[],"checksum":2497442461,"timestamp":"2024-06-01T22:42:50.183859Z"}]}
{"channel":"book","type":"update","data":[{"symbol":"ETH/USD","bids":[],"asks":[{"price":3819.39,"qty":13.32769339}],"checksum":1019314407,"timestamp":"2024-06-01T22:42:50.184965Z"}]}
{"channel":"book","type":"update","data":[{"symbol":"ETH/USD","bids":[{"price":3819.23,"qty":0.00000000},{"price":3818.64,"qty":0.00908133}],"asks":[],"checksum":2798292125,"timestamp":"2024-06-01T22:42:50.186718Z"}]}
{"channel":"book","type":"update","data":[{"symbol":"ETH/USD","bids":[{"price":3819.38,"qty":41.87619867}],"asks":[],"checksum":562405680,"timestamp":"2024-06-01T22:42:50.186997Z"}]}
{"channel":"book","type":"update","data":[{"symbol":"ETH/USD","bids":[{"price":3818.74,"qty":0.42258112}],"asks":[],"checksum":1375893962,"timestamp":"2024-06-01T22:42:50.190830Z"}]}
{"channel":"book","type":"update","data":[{"symbol":"ETH/USD","bids":[],"asks":[{"price":3820.08,"qty":0.00000000},{"price":3820.23,"qty":0.48396891}],"checksum":1557070533,"timestamp":"2024-06-01T22:42:50.192714Z"}]}
{"channel":"book","type":"update","data":[{"symbol":"ETH/USD","bids":[],"asks":[{"price":3819.51,"qty":0.00000000},{"price":3820.31,"qty":0.72912968}],"checksum":2970570389,"timestamp":"2024-06-01T22:42:50.192732Z"}]}
{"channel":"book","type":"update","data":[{"symbol":"ETH/USD","bids":[{"price":3819.26,"qty":15.70725859}],"asks":[],"checksum":3780329455,"timestamp":"2024-06-01T22:42:50.192791Z"}]}
{"channel":"book","type":"update","data":[{"symbol":"ETH/USD","bids":[],"asks":[{"price":3820.02,"qty":0.00000000},{"price":3820.51,"qty":3.67833330},{"price":3819.90,"qty":0.77000000}],"checksum":557654893,"timestamp":"2024-06-01T22:42:50.194545Z"}]}
{"channel":"book","type":"update","data":[{"symbol":"ETH/USD","bids":[],"asks":[{"price":3819.90,"qty":1.54000000}],"checksum":549994005,"timestamp":"2024-06-01T22:42:50.197594Z"}]}
{"channel":"book","type":"update","data":[{"symbol":"ETH/USD","bids":[],"asks":[{"price":3819.94,"qty":26.17845828}],"checksum":1374977026,"timestamp":"2024-06-01T22:42:50.198904Z"}]}
{"channel":"book","type":"update","data":[{"symbol":"ETH/USD","bids":[{"price":3818.99,"qty":26.18492877}],"asks":[],"checksum":3323887257,"timestamp":"2024-06-01T22:42:50.203073Z"}]}
{"channel":"book","type":"update","data":[{"symbol":"ETH/USD","bids":[],"asks":[{"price":3819.39,"qty":0.23358842}],"checksum":3149091124,"timestamp":"2024-06-01T22:42:50.207835Z"}]}
{"channel":"book","type":"update","data":[{"symbol":"ETH/USD","bids":[{"price":3819.27,"qty":0.00907983}],"asks":[],"checksum":2353161211,"timestamp":"2024-06-01T22:42:50.208625Z"}]}
{"channel":"book","type":"update","data":[{"symbol":"ETH/USD","bids":[],"asks":[{"price":3819.90,"qty":0.77000000}],"checksum":4126866556,"timestamp":"2024-06-01T22:42:50.224990Z"}]}
{"channel":"book","type":"update","data":[{"symbol":"ETH/USD","bids":[{"price":3819.28,"qty":0.78654282}],"asks":[],"checksum":4204761287,"timestamp":"2024-06-01T22:42:50.225413Z"}]}
{"channel":"book","type":"update","data":[{"symbol":"ETH/USD","bids":[],"asks":[{"price":3820.23,"qty":0.00000000},{"price":3820.31,"qty":0.72912968}],"checksum":4160140093,"timestamp":"2024-06-01T22:42:50.225699Z"}]}
{"channel":"book","type":"update","data":[{"symbol":"ETH/USD","bids":[{"price":3819.11,"qty":26.18410770}],"asks":[],"checksum":2954644912,"timestamp":"2024-06-01T22:42:50.245969Z"}]}
{"channel":"book","type":"update","data":[{"symbol":"ETH/USD","bids":[{"price":3819.38,"qty":15.70639512}],"asks":[],"checksum":419225032,"timestamp":"2024-06-01T22:42:50.246060Z"}]}
{"channel":"book","type":"update","data":[{"symbol":"ETH/USD","bids":[{"price":3819.11,"qty":0.00000000},{"price":3818.84,"qty":26.18594618}],"asks":[],"checksum":3492240077,"timestamp":"2024-06-01T22:42:50.246300Z"}]}
{"channel":"book","type":"update","data":[{"symbol":"ETH/USD","bids":[{"price":3819.08,"qty":26.17199376}],"asks":[],"checksum":475909081,"timestamp":"2024-06-01T22:42:50.246502Z"}]}
{"channel":"book","type":"update","data":[{"symbol":"ETH/USD","bids":[],"asks":[{"price":3819.50,"qty":26.41502738}],"checksum":1813734011,"timestamp":"2024-06-01T22:42:50.250681Z"}]}
{"channel":"book","type":"update","data":[{"symbol":"ETH/USD","bids":[{"price":3819.24,"qty":26.18316167}],"asks":[],"checksum":2667582081,"timestamp":"2024-06-01T22:42:50.250886Z"}]}
{"channel":"book","type":"update","data":[{"symbol":"ETH/USD","bids":[],"asks":[{"price":3819.50,"qty":0.23358505}],"checksum":2812843756,"timestamp":"2024-06-01T22:42:50.256358Z"}]}
{"channel":"book","type":"update","data":[{"symbol":"ETH/USD","bids":[{"price":3819.24,"qty":0.00000000},{"price":3818.91,"qty":3.30000000}],"asks":[],"checksum":475909081,"timestamp":"2024-06-01T22:42:50.256445Z"}]}
{"channel":"book","type":"update","data":[{"symbol":"ETH/USD","bids":[{"price":3819.07,"qty":4.86841079}],"asks":[],"checksum":1708791817,"timestamp":"2024-06-01T22:42:50.303579Z"}]}
{"channel":"book","type":"update","data":[{"symbol":"ETH/USD","bids":[],"asks":[{"price":3819.49,"qty":26.18156339}],"checksum":408406186,"timestamp":"2024-06-01T22:42:50.310723Z"}]}
{"channel":"book","type":"update","data":[{"symbol":"ETH/USD","bids":[{"price":3819.26,"qty":41.89033522}],"asks":[],"checksum":2186693442,"timestamp":"2024-06-01T22:42:50.310798Z"}]}
{"channel":"book","type":"update","data":[{"symbol":"ETH/USD","bids":[{"price":3819.18,"qty":0.77000000}],"asks":[],"checksum":635225946,"timestamp":"2024-06-01T22:42:50.313155Z"}]}
{"channel":"book","type":"update","data":[{"symbol":"ETH/USD","bids":[],"asks":[{"price":3819.49,"qty":0.00000000},{"price":3820.31,"qty":0.72912968}],"checksum":2945635797,"timestamp":"2024-06-01T22:42:50.340628Z"}]}
{"channel":"book","type":"update","data":[{"symbol":"ETH/USD","bids":[],"asks":[{"price":3819.89,"qty":0.49647792}],"checksum":28613433,"timestamp":"2024-06-01T22:42:50.344018Z"}]}
{"channel":"book","type":"update","data":[{"symbol":"ETH/USD","bids":[{"price":3819.26,"qty":15.70725859}],"asks":[],"checksum":3213149624,"timestamp":"2024-06-01T22:42:50.352059Z"}]}
{"channel":"book","type":"update","data":[{"symbol":"ETH/USD","bids":[],"asks":[{"price":3819.50,"qty":26.41502491}],"checksum":2039596157,"timestamp":"2024-06-01T22:42:50.377106Z"}]}
{"channel":"book","type":"update","data":[{"symbol":"ETH/USD","bids":[{"price":3819.27,"qty":26.19206159}],"asks":[],"checksum":3906165467,"timestamp":"2024-06-01T22:42:50.377189Z"}]}
{"channel":"book","type":"update","data":[{"symbol":"ETH/USD","bids":[],"asks":[{"price":3819.50,"qty":0.23358505}],"checksum":3979390793,"timestamp":"2024-06-01T22:42:50.384026Z"}]}
{"channel":"book","type":"update","data":[{"symbol":"ETH/USD","bids":[{"price":3819.27,"qty":0.00907983}],"asks":[],"checksum":3213149624,"timestamp":"2024-06-01T22:42:50.384151Z"}]}
{"channel":"book","type":"update","data":[{"symbol":"ETH/USD","bids":[{"price":3818.99,"qty":0.00000000},{"price":3818.92,"qty":3.92659878}],"asks":[],"checksum":1095235055,"timestamp":"2024-06-01T22:42:50.423156Z"}]}
{"channel":"book","type":"update","data":[{"symbol":"ETH/USD","bids":[{"price":3819.31,"qty":26.18270379}],"asks":[],"checksum":3737327296,"timestamp":"2024-06-01T22:42:50.427641Z"}]}
{"channel":"book","type":"update","data":[{"symbol":"ETH/USD","bids":[],"asks":[{"price":3819.54,"qty":26.18117042}],"checksum":2919039886,"timestamp":"2024-06-01T22:42:50.427663Z"}]}
{"channel":"book","type":"update","data":[{"symbol":"ETH/USD","bids":[],"asks":[{"price":3819.62,"qty":26.18068170}],"checksum":1022148868,"timestamp":"2024-06-01T22:42:50.427792Z"}]}
{"channel":"book","type":"update","data":[{"symbol":"ETH/USD","bids":[{"price":3819.18,"qty":0.00000000},{"price":3818.92,"qty":3.92659878},{"price":3819.29,"qty":0.77000000}],"asks":[],"checksum":831579378,"timestamp":"2024-06-01T22:42:50.451210Z"}]}
{"channel":"book","type":"update","data":[{"symbol":"ETH/USD","bids":[{"price":3819.29,"qty":0.00000000},{"price":3818.92,"qty":3.92659878}],"asks":[],"checksum":3367568438,"timestamp":"2024-06-01T22:42:50.452403Z"}]}
{"channel":"book","type":"update","data":[{"symbol":"ETH/USD","bids":[{"price":3819.29,"qty":0.77000000}],"asks":[],"checksum":831579378,"timestamp":"2024-06-01T22:42:50.452528Z"}]}
{"channel":"book","type":"update","data":[{"symbol":"ETH/USD","bids":[],"asks":[{"price":3819.90,"qty":0.00000000},{"price":3819.94,"qty":26.17845828}],"checksum":1758461661,"timestamp":"2024-06-01T22:42:50.454333Z"}]}
{"channel":"book","type":"update","data":[{"symbol":"ETH/USD","bids":[{"price":3819.27,"qty":0.00000000},{"price":3818.92,"qty":3.92659878},{"price":3819.32,"qty":0.00907944}],"asks":[],"checksum":327847067,"timestamp":"2024-06-01T22:42:50.493793Z"}]}
{"channel":"book","type":"update","data":[{"symbol":"ETH/USD","bids":[{"price":3819.31,"qty":0.00000000},{"price":3818.92,"qty":3.92659878}],"asks":[],"checksum":1432112200,"timestamp":"2024-06-01T22:42:50.494477Z"}]}
{"channel":"book","type":"update","data":[{"symbol":"ETH/USD","bids":[{"price":3819.29,"qty":26.95282361}],"asks":[],"checksum":1330535425,"timestamp":"2024-06-01T22:42:50.500329Z"}]}
{"channel":"book","type":"update","data":[{"symbol":"ETH/USD","bids":[{"price":3819.09,"qty":26.18423256}],"asks":[],"checksum":1784750146,"timestamp":"2024-06-01T22:42:50.505157Z"}]}
{"channel":"book","type":"update","data":[{"symbol":"ETH/USD","bids":[{"price":3819.32,"qty":0.00000000},{"price":3818.92,"qty":3.92659878},{"price":3819.30,"qty":0.00907949}],"asks":[],"checksum":1910198102,"timestamp":"2024-06-01T22:42:50.564192Z"}]}
{"channel":"book","type":"update","data":[{"symbol":"ETH/USD","bids":[],"asks":[{"price":3819.54,"qty":0.00000000},{"price":3820.03,"qty":0.77000000}],"checksum":1681689176,"timestamp":"2024-06-01T22:42:50.627140Z"}]}
{"channel":"book","type":"update","data":[{"symbol":"ETH/USD","bids":[],"asks":[{"price":3819.53,"qty":26.18125339}],"checksum":1408571303,"timestamp":"2024-06-01T22:42:50.631462Z"}]}
{"channel":"book","type":"update","data":[{"symbol":"ETH/USD","bids":[],"asks":[{"price":3819.62,"qty":0.00000000},{"price":3820.03,"qty":0.77000000}],"checksum":1080183823,"timestamp":"2024-06-01T22:42:50.650211Z"}]}
{"channel":"book","type":"update","data":[{"symbol":"ETH/USD","bids":[{"price":3819.29,"qty":0.77000000}],"asks":[],"checksum":607640882,"timestamp":"2024-06-01T22:42:50.650226Z"}]}
{"channel":"book","type":"update","data":[{"symbol":"ETH/USD","bids":[{"price":3819.25,"qty":26.19678820}],"asks":[],"checksum":3046454795,"timestamp":"2024-06-01T22:42:50.654713Z"}]}
{"channel":"book","type":"update","data":[{"symbol":"ETH/USD","bids":[{"price":3819.30,"qty":0.00000000},{"price":3818.92,"qty":3.92659878},{"price":3819.27,"qty":0.00907956}],"asks":[],"checksum":3315052183,"timestamp":"2024-06-01T22:42:50.730227Z"}]}
{"channel":"book","type":"update","data":[{"symbol":"ETH/USD","bids":[{"price":3819.08,"qty":0.00000000},{"price":3818.92,"qty":3.92659878}],"asks":[],"checksum":3888001741,"timestamp":"2024-06-01T22:42:50.773824Z"}]}
{"channel":"book","type":"update","data":[{"symbol":"ETH/USD","bids":[{"price":3819.38,"qty":41.87633022}],"asks":[],"checksum":788800585,"timestamp":"2024-06-01T22:42:50.774034Z"}]}
{"channel":"book","type":"update","data":[{"symbol":"ETH/USD","bids":[{"price":3819.25,"qty":0.01368441}],"asks":[],"checksum":3556003368,"timestamp":"2024-06-01T22:42:50.843013Z"}]}
{"channel":"book","type":"update","data":[{"symbol":"ETH/USD","bids":[{"price":3819.26,"qty":41.89033881}],"asks":[],"checksum":2490281803,"timestamp":"2024-06-01T22:42:50.847908Z"}]}
{"channel":"book","type":"update","data":[{"symbol":"ETH/USD","bids":[],"asks":[{"price":3819.51,"qty":26.18142881}],"checksum":2585230026,"timestamp":"2024-06-01T22:42:50.847993Z"}]}
{"channel":"book","type":"update","data":[{"symbol":"ETH/USD","bids":[],"asks":[{"price":3819.51,"qty":0.00000000},{"price":3820.03,"qty":0.77000000}],"checksum":2490281803,"timestamp":"2024-06-01T22:42:50.932145Z"}]}
{"channel":"book","type":"update","data":[{"symbol":"ETH/USD","bids":[],"asks":[{"price":3819.50,"qty":26.41504790}],"checksum":1207318964,"timestamp":"2024-06-01T22:42:50.937441Z"}]}
{"channel":"book","type":"update","data":[{"symbol":"ETH/USD","bids":[],"asks":[{"price":3819.50,"qty":0.23358505}],"checksum":2490281803,"timestamp":"2024-06-01T22:42:51.121344Z"}]}
{"channel":"book","type":"update","data":[{"symbol":"ETH/USD","bids":[],"asks":[{"price":3819.47,"qty":26.18168158}],"checksum":759772913,"timestamp":"2024-06-01T22:42:51.125207Z"}]}
{"channel":"book","type":"update","data":[{"symbol":"ETH/USD","bids":[],"asks":[{"price":3819.47,"qty":0.00000000},{"price":3820.03,"qty":0.77000000}],"checksum":2490281803,"timestamp":"2024-06-01T22:42:51.161724Z"}]}
{"channel":"book","type":"update","data":[{"symbol":"ETH/USD","bids":[{"price":3819.26,"qty":15.70725859}],"asks":[],"checksum":3556003368,"timestamp":"2024-06-01T22:42:51.161759Z"}]}
{"channel":"book","type":"update","data":[{"symbol":"ETH/USD","bids":[{"price":3819.26,"qty":41.89033949}],"asks":[],"checksum":3362697831,"timestamp":"2024-06-01T22:42:51.166533Z"}]}
{"channel":"book","type":"update","data":[{"symbol":"ETH/USD","bids":[{"price":3819.38,"qty":26.16993510}],"asks":[],"checksum":3000903712,"timestamp":"2024-06-01T22:42:51.170050Z"}]}
{"channel":"book","type":"update","data":[{"symbol":"ETH/USD","bids":[{"price":3819.26,"qty":26.18308090}],"asks":[],"checksum":3309931127,"timestamp":"2024-06-01T22:42:51.170175Z"}]}
{"channel":"book","type":"update","data":[{"symbol":"ETH/USD","bids":[],"asks":[{"price":3819.47,"qty":26.18169206}],"checksum":3677763789,"timestamp":"2024-06-01T22:42:51.184977Z"}]}
{"channel":"book","type":"update","data":[{"symbol":"ETH/USD","bids":[],"asks":[{"price":3819.47,"qty":0.00000000},{"price":3820.03,"qty":0.77000000}],"checksum":3309931127,"timestamp":"2024-06-01T22:42:51.214422Z"}]}
{"channel":"book","type":"update","data":[{"symbol":"ETH/USD","bids":[{"price":3819.26,"qty":0.00000000},{"price":3818.91,"qty":3.30000000}],"asks":[],"checksum":2788790863,"timestamp":"2024-06-01T22:42:51.231373Z"}]}
{"channel":"book","type":"update","data":[{"symbol":"ETH/USD","bids":[],"asks":[{"price":3819.47,"qty":26.18164493}],"checksum":3371999140,"timestamp":"2024-06-01T22:42:51.235159Z"}]}
{"channel":"book","type":"update","data":[{"symbol":"ETH/USD","bids":[{"price":3819.27,"qty":26.19208714}],"asks":[],"checksum":3655967667,"timestamp":"2024-06-01T22:42:51.235244Z"}]}
{"channel":"book","type":"update","data":[{"symbol":"ETH/USD","bids":[{"price":3819.27,"qty":0.00907956}],"asks":[],"checksum":3371999140,"timestamp":"2024-06-01T22:42:51.266948Z"}]}
{"channel":"book","type":"update","data":[{"symbol":"ETH/USD","bids":[],"asks":[{"price":3819.47,"qty":0.00000000},{"price":3820.03,"qty":0.77000000}],"checksum":2788790863,"timestamp":"2024-06-01T22:42:51.267030Z"}]}
{"channel":"book","type":"update","data":[{"symbol":"ETH/USD","bids":[{"price":3819.27,"qty":0.00000000},{"price":3818.84,"qty":26.18594618},{"price":3819.28,"qty":0.79562236}],"asks":[],"checksum":2730055291,"timestamp":"2024-06-01T22:42:51.298302Z"}]}
{"channel":"book","type":"update","data":[{"symbol":"ETH/USD","bids":[{"price":3819.28,"qty":0.78654282},{"price":3819.23,"qty":0.00907966}],"asks":[],"checksum":2257276363,"timestamp":"2024-06-01T22:42:51.342463Z"}]}
{"channel":"book","type":"update","data":[{"symbol":"ETH/USD","bids":[],"asks":[{"price":3819.48,"qty":26.18162718}],"checksum":3108668983,"timestamp":"2024-06-01T22:42:51.401400Z"}]}
{"channel":"book","type":"update","data":[{"symbol":"ETH/USD","bids":[{"price":3819.26,"qty":26.18304686}],"asks":[],"checksum":2102708665,"timestamp":"2024-06-01T22:42:51.401540Z"}]}
{"channel":"book","type":"update","data":[{"symbol":"ETH/USD","bids":[{"price":3819.26,"qty":0.00000000},{"price":3818.91,"qty":3.30000000}],"asks":[],"checksum":3108668983,"timestamp":"2024-06-01T22:42:51.423470Z"}]}
{"channel":"book","type":"update","data":[{"symbol":"ETH/USD","bids":[],"asks":[{"price":3819.48,"qty":0.00000000},{"price":3820.03,"qty":0.77000000}],"checksum":2257276363,"timestamp":"2024-06-01T22:42:51.444081Z"}]}
{"channel":"book","type":"update","data":[{"symbol":"ETH/USD","bids":[],"asks":[{"price":3819.49,"qty":26.18151025}],"checksum":3049425171,"timestamp":"2024-06-01T22:42:51.525751Z"}]}
{"channel":"book","type":"update","data":[{"symbol":"ETH/USD","bids":[{"price":3819.28,"qty":26.96948616}],"asks":[],"checksum":3518377862,"timestamp":"2024-06-01T22:42:51.525981Z"}]}
{"channel":"book","type":"update","data":[{"symbol":"ETH/USD","bids":[{"price":3819.23,"qty":0.00000000},{"price":3818.84,"qty":26.18594618},{"price":3819.29,"qty":0.77907952}],"asks":[],"checksum":3277803914,"timestamp":"2024-06-01T22:42:51.591435Z"}]}
{"channel":"book","type":"update","data":[{"symbol":"ETH/USD","bids":[{"price":3819.28,"qty":26.18294334}],"asks":[],"checksum":1268588973,"timestamp":"2024-06-01T22:42:51.661007Z"}]}
{"channel":"book","type":"update","data":[{"symbol":"ETH/USD","bids":[],"asks":[{"price":3819.89,"qty":0.00000000},{"price":3820.03,"qty":0.77000000}],"checksum":2994119557,"timestamp":"2024-06-01T22:42:51.661206Z"}]}
{"channel":"book","type":"update","data":[{"symbol":"ETH/USD","bids":[],"asks":[{"price":3819.49,"qty":0.00000000},{"price":3820.10,"qty":2.09900000}],"checksum":2972320969,"timestamp":"2024-06-01T22:42:51.668183Z"}]}
{"channel":"book","type":"update","data":[{"symbol":"ETH/USD","bids":[{"price":3819.28,"qty":0.00000000},{"price":3818.80,"qty":3.92681465}],"asks":[],"checksum":2203255746,"timestamp":"2024-06-01T22:42:51.668196Z"}]}
{"channel":"book","type":"update","data":[{"symbol":"ETH/USD","bids":[{"price":3819.26,"qty":26.18307427}],"asks":[],"checksum":1729245875,"timestamp":"2024-06-01T22:42:51.672724Z"}]}
{"channel":"book","type":"update","data":[{"symbol":"ETH/USD","bids":[],"asks":[{"price":3819.48,"qty":26.18161760}],"checksum":832825846,"timestamp":"2024-06-01T22:42:51.672754Z"}]}
{"channel":"book","type":"update","data":[{"symbol":"ETH/USD","bids":[],"asks":[{"price":3819.48,"qty":0.00000000},{"price":3820.10,"qty":2.09900000}],"checksum":1729245875,"timestamp":"2024-06-01T22:42:51.680103Z"}]}
{"channel":"book","type":"update","data":[{"symbol":"ETH/USD","bids":[{"price":3819.07,"qty":0.00000000},{"price":3818.80,"qty":3.92681465}],"asks":[],"checksum":630771520,"timestamp":"2024-06-01T22:42:51.684392Z"}]}
{"channel":"book","type":"update","data":[{"symbol":"ETH/USD","bids":[{"price":3819.26,"qty":0.00000000},{"price":3818.74,"qty":0.42258112}],"asks":[],"checksum":1516769236,"timestamp":"2024-06-01T22:42:51.685011Z"}]}
{"channel":"book","type":"update","data":[{"symbol":"ETH/USD","bids":[],"asks":[{"price":3819.53,"qty":0.00000000},{"price":3820.31,"qty":0.72912968}],"checksum":3605358720,"timestamp":"2024-06-01T22:42:51.695022Z"}]}
{"channel":"book","type":"update","data":[{"symbol":"ETH/USD","bids":[{"price":3818.99,"qty":26.18489074}],"asks":[],"checksum":3387255734,"timestamp":"2024-06-01T22:42:51.698827Z"}]}
{"channel":"book","type":"update","data":[{"symbol":"ETH/USD","bids":[],"asks":[{"price":3820.03,"qty":0.00000000},{"price":3820.46,"qty":5.23200000},{"price":3819.89,"qty":0.77000000}],"checksum":984897662,"timestamp":"2024-06-01T22:42:51.703400Z"}]}
{"channel":"book","type":"update","data":[{"symbol":"ETH/USD","bids":[],"asks":[{"price":3819.89,"qty":1.54000000}],"checksum":572740737,"timestamp":"2024-06-01T22:42:51.706428Z"}]}
{"channel":"book","type":"update","data":[{"symbol":"ETH/USD","bids":[{"price":3819.29,"qty":0.77000000},{"price":3819.27,"qty":0.00907957}],"asks":[],"checksum":3326520616,"timestamp":"2024-06-01T22:42:51.722424Z"}]}
{"channel":"book","type":"update","data":[{"symbol":"ETH/USD","bids":[{"price":3819.29,"qty":0.00000000},{"price":3818.80,"qty":3.92681465}],"asks":[],"checksum":662622593,"timestamp":"2024-06-01T22:42:51.732465Z"}]}
{"channel":"book","type":"update","data":[{"symbol":"ETH/USD","bids":[{"price":3819.22,"qty":0.00000000},{"price":3818.74,"qty":0.42258112}],"asks":[],"checksum":148270003,"timestamp":"2024-06-01T22:42:51.738484Z"}]}
{"channel":"book","type":"update","data":[{"symbol":"ETH/USD","bids":[],"asks":[{"price":3819.73,"qty":0.00000000},{"price":3820.46,"qty":5.23200000}],"checksum":3445950342,"timestamp":"2024-06-01T22:42:51.738609Z"}]}
{"channel":"book","type":"update","data":[{"symbol":"ETH/USD","bids":[],"asks":[{"price":3819.41,"qty":26.18207626}],"checksum":3957673000,"timestamp":"2024-06-01T22:42:51.744147Z"}]}
{"channel":"book","type":"update","data":[{"symbol":"ETH/USD","bids":[{"price":3819.20,"qty":26.18349285}],"asks":[],"checksum":1275017315,"timestamp":"2024-06-01T22:42:51.744221Z"}]}
{"channel":"book","type":"update","data":[{"symbol":"ETH/USD","bids":[],"asks":[{"price":3819.64,"qty":26.18052143}],"checksum":3070776399,"timestamp":"2024-06-01T22:42:51.744235Z"}]}
{"channel":"book","type":"update","data":[{"symbol":"ETH/USD","bids":[{"price":3819.27,"qty":0.00000000},{"price":3818.74,"qty":0.42258112},{"price":3819.23,"qty":0.00907966}],"asks":[],"checksum":891903112,"timestamp":"2024-06-01T22:42:51.779294Z"}]}
{"channel":"book","type":"update","data":[{"symbol":"ETH/USD","bids":[{"price":3819.21,"qty":0.76952211}],"asks":[],"checksum":244828469,"timestamp":"2024-06-01T22:42:51.782907Z"}]}
{"channel":"book","type":"update","data":[{"symbol":"ETH/USD","bids":[],"asks":[{"price":3819.68,"qty":0.49352658}],"checksum":651092158,"timestamp":"2024-06-01T22:42:51.783018Z"}]}
{"channel":"book","type":"update","data":[{"symbol":"ETH/USD","bids":[{"price":3819.25,"qty":0.78368441}],"asks":[],"checksum":1335128466,"timestamp":"2024-06-01T22:42:51.842543Z"}]}
{"channel":"book","type":"update","data":[{"symbol":"ETH/USD","bids":[{"price":3819.23,"qty":0.00000000},{"price":3818.80,"qty":3.92681465},{"price":3819.22,"qty":0.00907968}],"asks":[],"checksum":1666131617,"timestamp":"2024-06-01T22:42:51.845645Z"}]}
{"channel":"book","type":"update","data":[{"symbol":"ETH/USD","bids":[],"asks":[{"price":3819.89,"qty":0.77000000}],"checksum":1183771251,"timestamp":"2024-06-01T22:42:51.848050Z"}]}
{"channel":"book","type":"update","data":[{"symbol":"ETH/USD","bids":[],"asks":[{"price":3819.41,"qty":0.00000000},{"price":3820.10,"qty":2.09900000}],"checksum":3554950689,"timestamp":"2024-06-01T22:42:51.899195Z"}]}
{"channel":"book","type":"update","data":[{"symbol":"ETH/USD","bids":[{"price":3819.09,"qty":0.00000000},{"price":3818.80,"qty":3.92681465}],"asks":[],"checksum":3388093773,"timestamp":"2024-06-01T22:42:51.899310Z"}]}
{"channel":"book","type":"update","data":[{"symbol":"ETH/USD","bids":[],"asks":[{"price":3819.43,"qty":26.18198200}],"checksum":2071125330,"timestamp":"2024-06-01T22:42:51.904021Z"}]}
{"channel":"book","type":"update","data":[{"symbol":"ETH/USD","bids":[{"price":3819.21,"qty":26.95294688}],"asks":[],"checksum":1203116264,"timestamp":"2024-06-01T22:42:51.904038Z"}]}
{"channel":"book","type":"update","data":[{"symbol":"ETH/USD","bids":[{"price":3819.21,"qty":0.76952211}],"asks":[],"checksum":2071125330,"timestamp":"2024-06-01T22:42:51.958095Z"}]}
{"channel":"book","type":"update","data":[{"symbol":"ETH/USD","bids":[],"asks":[{"price":3819.46,"qty":26.18173804}],"checksum":2136692420,"timestamp":"2024-06-01T22:42:51.962435Z"}]}
{"channel":"book","type":"update","data":[{"symbol":"ETH/USD","bids":[{"price":3819.22,"qty":26.19243113}],"asks":[],"checksum":1771979154,"timestamp":"2024-06-01T22:42:51.962465Z"}]}
{"channel":"book","type":"update","data":[{"symbol":"ETH/USD","bids":[{"price":3819.22,"qty":26.18335145},{"price":3819.23,"qty":0.00907966}],"asks":[],"checksum":3187650921,"timestamp":"2024-06-01T22:42:52.024892Z"}]}
{"channel":"book","type":"update","data":[{"symbol":"ETH/USD","bids":[{"price":3819.22,"qty":0.00000000},{"price":3818.80,"qty":3.92681465}],"asks":[],"checksum":2106781306,"timestamp":"2024-06-01T22:42:52.136670Z"}]}
{"channel":"book","type":"update","data":[{"symbol":"ETH/USD","bids":[],"asks":[{"price":3819.43,"qty":0.00000000},{"price":3819.94,"qty":26.17845828}],"checksum":1330892298,"timestamp":"2024-06-01T22:42:52.136701Z"}]}
{"channel":"book","type":"update","data":[{"symbol":"ETH/USD","bids":[{"price":3819.13,"qty":26.18390596}],"asks":[],"checksum":990297203,"timestamp":"2024-06-01T22:42:52.141358Z"}]}
{"channel":"book","type":"update","data":[{"symbol":"ETH/USD","bids":[],"asks":[{"price":3819.42,"qty":26.18200369}],"checksum":1711714981,"timestamp":"2024-06-01T22:42:52.141433Z"}]}
{"channel":"book","type":"update","data":[{"symbol":"ETH/USD","bids":[{"price":3818.84,"qty":0.00000000},{"price":3818.80,"qty":3.92681465}],"asks":[],"checksum":4193839867,"timestamp":"2024-06-01T22:42:52.158745Z"}]}
{"channel":"book","type":"update","data":[{"symbol":"ETH/USD","bids":[{"price":3819.20,"qty":0.00000000},{"price":3818.74,"qty":0.42258112}],"asks":[],"checksum":3243920397,"timestamp":"2024-06-01T22:42:52.158872Z"}]}
{"channel":"book","type":"update","data":[{"symbol":"ETH/USD","bids":[],"asks":[{"price":3819.42,"qty":0.00000000},{"price":3819.94,"qty":26.17845828}],"checksum":1896422975,"timestamp":"2024-06-01T22:42:52.158895Z"}]}
{"channel":"book","type":"update","data":[{"symbol":"ETH/USD","bids":[{"price":3819.17,"qty":26.18363797}],"asks":[],"checksum":203982523,"timestamp":"2024-06-01T22:42:52.164429Z"}]}
{"channel":"book","type":"update","data":[{"symbol":"ETH/USD","bids":[{"price":3819.23,"qty":0.00000000},{"price":3818.74,"qty":0.42258112},{"price":3819.22,"qty":0.00907968}],"asks":[],"checksum":249642501,"timestamp":"2024-06-01T22:42:52.202091Z"}]}
{"channel":"book","type":"update","data":[{"symbol":"ETH/USD","bids":[{"price":3819.17,"qty":0.00000000},{"price":3818.74,"qty":0.42258112}],"asks":[],"checksum":2340008025,"timestamp":"2024-06-01T22:42:52.206437Z"}]}
{"channel":"book","type":"update","data":[{"symbol":"ETH/USD","bids":[],"asks":[{"price":3819.39,"qty":26.41577981}],"checksum":1692918882,"timestamp":"2024-06-01T22:42:52.210823Z"}]}
{"channel":"book","type":"update","data":[{"symbol":"ETH/USD","bids":[{"price":3819.17,"qty":26.18367897}],"asks":[],"checksum":2280237056,"timestamp":"2024-06-01T22:42:52.214603Z"}]}
{"channel":"book","type":"update","data":[{"symbol":"ETH/USD","bids":[{"price":3819.22,"qty":0.00000000},{"price":3818.69,"qty":26.18694719},{"price":3819.18,"qty":0.00908031}],"asks":[],"checksum":3760136692,"timestamp":"2024-06-01T22:42:52.257688Z"}]}
{"channel":"book","type":"update","data":[{"symbol":"ETH/USD","bids":[{"price":3819.17,"qty":0.00000000},{"price":3818.69,"qty":26.18694719}],"asks":[],"checksum":2603549050,"timestamp":"2024-06-01T22:42:52.284965Z"}]}
{"channel":"book","type":"update","data":[{"symbol":"ETH/USD","bids":[{"price":3819.15,"qty":26.18380824}],"asks":[],"checksum":2165027448,"timestamp":"2024-06-01T22:42:52.289363Z"}]}
{"channel":"book","type":"update","data":[{"symbol":"ETH/USD","bids":[],"asks":[{"price":3819.39,"qty":0.23358842}],"checksum":3518965555,"timestamp":"2024-06-01T22:42:52.297743Z"}]}
{"channel":"book","type":"update","data":[{"symbol":"ETH/USD","bids":[{"price":3819.13,"qty":0.00000000},{"price":3818.69,"qty":26.18694719}],"asks":[],"checksum":1794504761,"timestamp":"2024-06-01T22:42:52.297754Z"}]}
{"channel":"book","type":"update","data":[{"symbol":"ETH/USD","bids":[{"price":3819.15,"qty":0.00000000},{"price":3818.63,"qty":0.01407082}],"asks":[],"checksum":4094944017,"timestamp":"2024-06-01T22:42:52.297843Z"}]}
{"channel":"book","type":"update","data":[{"symbol":"ETH/USD","bids":[{"price":3818.95,"qty":0.42258112}],"asks":[],"checksum":912491440,"timestamp":"2024-06-01T22:42:52.302593Z"}]}
{"channel":"book","type":"update","data":[{"symbol":"ETH/USD","bids":[],"asks":[{"price":3819.43,"qty":26.18195498}],"checksum":1356919649,"timestamp":"2024-06-01T22:42:52.303097Z"}]}
{"channel":"book","type":"update","data":[{"symbol":"ETH/USD","bids":[],"asks":[{"price":3819.43,"qty":0.00000000},{"price":3819.94,"qty":26.17845828}],"checksum":912491440,"timestamp":"2024-06-01T22:42:52.313706Z"}]}
{"channel":"book","type":"update","data":[{"symbol":"ETH/USD","bids":[],"asks":[{"price":3819.89,"qty":0.00000000},{"price":3820.10,"qty":2.09900000}],"checksum":3408744383,"timestamp":"2024-06-01T22:42:52.314056Z"}]}
{"channel":"book","type":"update","data":[{"symbol":"ETH/USD","bids":[],"asks":[{"price":3819.52,"qty":26.18133876}],"checksum":3458883705,"timestamp":"2024-06-01T22:42:52.317660Z"}]}
{"channel":"book","type":"update","data":[{"symbol":"ETH/USD","bids":[{"price":3819.18,"qty":0.00000000},{"price":3818.63,"qty":0.01407082},{"price":3819.16,"qty":0.00908036}],"asks":[],"checksum":4216215143,"timestamp":"2024-06-01T22:42:52.336352Z"}]}
{"channel":"book","type":"update","data":[{"symbol":"ETH/USD","bids":[],"asks":[{"price":3819.46,"qty":0.00000000},{"price":3820.10,"qty":2.09900000}],"checksum":3132990506,"timestamp":"2024-06-01T22:42:52.338791Z"}]}
{"channel":"book","type":"update","data":[{"symbol":"ETH/USD","bids":[{"price":3819.29,"qty":26.18283929}],"asks":[],"checksum":2429160394,"timestamp":"2024-06-01T22:42:52.342921Z"}]}
{"channel":"book","type":"update","data":[{"symbol":"ETH/USD","bids":[],"asks":[{"price":3819.68,"qty":0.00000000},{"price":3820.31,"qty":0.72912968}],"checksum":2573963055,"timestamp":"2024-06-01T22:42:52.345944Z"}]}
{"channel":"book","type":"update","data":[{"symbol":"ETH/USD","bids":[{"price":3819.29,"qty":0.00000000},{"price":3818.69,"qty":26.18694719}],"asks":[],"checksum":3004965071,"timestamp":"2024-06-01T22:42:52.352668Z"}]}
{"channel":"book","type":"update","data":[{"symbol":"ETH/USD","bids":[],"asks":[{"price":3819.48,"qty":26.18163536}],"checksum":3836273424,"timestamp":"2024-06-01T22:42:52.356707Z"}]}
{"channel":"book","type":"update","data":[{"symbol":"ETH/USD","bids":[],"asks":[{"price":3820.09,"qty":0.49352658}],"checksum":1151742625,"timestamp":"2024-06-01T22:42:52.365889Z"}]}
{"channel":"book","type":"update","data":[{"symbol":"ETH/USD","bids":[],"asks":[{"price":3819.48,"qty":0.00000000},{"price":3820.10,"qty":2.09900000}],"checksum":3894803407,"timestamp":"2024-06-01T22:42:52.385536Z"}]}
{"channel":"book","type":"update","data":[{"symbol":"ETH/USD","bids":[{"price":3819.16,"qty":0.00000000},{"price":3818.63,"qty":0.01407082},{"price":3819.30,"qty":0.00908002}],"asks":[],"checksum":4186621525,"timestamp":"2024-06-01T22:42:52.393468Z"}]}
{"channel":"book","type":"update","data":[{"symbol":"ETH/USD","bids":[{"price":3819.25,"qty":26.96677508}],"asks":[],"checksum":3793644979,"timestamp":"2024-06-01T22:42:52.404456Z"}]}
{"channel":"book","type":"update","data":[{"symbol":"ETH/USD","bids":[],"asks":[{"price":3819.45,"qty":26.18181450}],"checksum":3666043175,"timestamp":"2024-06-01T22:42:52.409228Z"}]}
{"channel":"book","type":"update","data":[{"symbol":"ETH/USD","bids":[{"price":3819.30,"qty":0.00000000},{"price":3818.63,"qty":0.01407082},{"price":3819.00,"qty":0.00908074}],"asks":[],"checksum":1062063127,"timestamp":"2024-06-01T22:42:52.448766Z"}]}
{"channel":"book","type":"update","data":[{"symbol":"ETH/USD","bids":[],"asks":[{"price":3819.86,"qty":0.77000000}],"checksum":1716370647,"timestamp":"2024-06-01T22:42:52.452162Z"}]}
{"channel":"book","type":"update","data":[{"symbol":"ETH/USD","bids":[{"price":3819.25,"qty":0.78368441}],"asks":[],"checksum":1047539244,"timestamp":"2024-06-01T22:42:52.494575Z"}]}
{"channel":"book","type":"update","data":[{"symbol":"ETH/USD","bids":[{"price":3819.21,"qty":26.95294076}],"asks":[],"checksum":2564131511,"timestamp":"2024-06-01T22:42:52.498672Z"}]}
{"channel":"book","type":"update","data":[{"symbol":"ETH/USD","bids":[{"price":3818.95,"qty":0.00000000},{"price":3818.63,"qty":0.01407082}],"asks":[],"checksum":2473635577,"timestamp":"2024-06-01T22:42:52.608537Z"}]}
{"channel":"book","type":"update","data":[{"symbol":"ETH/USD","bids":[{"price":3818.86,"qty":0.42258112}],"asks":[],"checksum":4109955584,"timestamp":"2024-06-01T22:42:52.611734Z"}]}
{"channel":"book","type":"update","data":[{"symbol":"ETH/USD","bids":[{"price":3819.21,"qty":0.76952211}],"asks":[],"checksum":1381848731,"timestamp":"2024-06-01T22:42:52.683544Z"}]}
{"channel":"book","type":"update","data":[{"symbol":"ETH/USD","bids":[],"asks":[{"price":3819.52,"qty":0.00000000},{"price":3820.09,"qty":0.49352658}],"checksum":421713542,"timestamp":"2024-06-01T22:42:52.683606Z"}]}
{"channel":"book","type":"update","data":[{"symbol":"ETH/USD","bids":[],"asks":[{"price":3819.45,"qty":0.00000000},{"price":3820.31,"qty":0.72912968}],"checksum":1036326989,"timestamp":"2024-06-01T22:42:52.683632Z"}]}
{"channel":"book","type":"update","data":[{"symbol":"ETH/USD","bids":[],"asks":[{"price":3819.77,"qty":2.09600000}],"checksum":2575193642,"timestamp":"2024-06-01T22:42:52.684208Z"}]}
{"channel":"book","type":"update","data":[{"symbol":"ETH/USD","bids":[],"asks":[{"price":3819.41,"qty":26.18209504}],"checksum":3112269994,"timestamp":"2024-06-01T22:42:52.688793Z"}]}
{"channel":"book","type":"update","data":[{"symbol":"ETH/USD","bids":[{"price":3819.18,"qty":26.18357914}],"asks":[],"checksum":4245797561,"timestamp":"2024-06-01T22:42:52.688809Z"}]}
{"channel":"book","type":"update","data":[{"symbol":"ETH/USD","bids":[{"price":3818.83,"qty":4.86871675}],"asks":[],"checksum":3899087728,"timestamp":"2024-06-01T22:42:52.839049Z"}]}
{"channel":"book","type":"update","data":[{"symbol":"ETH/USD","bids":[],"asks":[{"price":3819.71,"qty":0.49352658}],"checksum":2356733693,"timestamp":"2024-06-01T22:42:52.842508Z"}]}
{"channel":"book","type":"update","data":[{"symbol":"ETH/USD","bids":[{"price":3819.00,"qty":0.00000000},{"price":3818.80,"qty":3.92681465},{"price":3819.19,"qty":0.00908028}],"asks":[],"checksum":190572222,"timestamp":"2024-06-01T22:42:52.904302Z"}]}
{"channel":"book","type":"update","data":[{"symbol":"ETH/USD","bids":[{"price":3819.18,"qty":0.00000000},{"price":3818.80,"qty":3.92681465}],"asks":[],"checksum":709557775,"timestamp":"2024-06-01T22:42:53.062463Z"}]}
{"channel":"book","type":"update","data":[{"symbol":"ETH/USD","bids":[],"asks":[{"price":3819.41,"qty":0.00000000},{"price":3819.94,"qty":26.17845828}],"checksum":314826458,"timestamp":"2024-06-01T22:42:53.062520Z"}]}
{"channel":"book","type":"update","data":[{"symbol":"ETH/USD","bids":[],"asks":[{"price":3819.40,"qty":26.18212384}],"checksum":1831782740,"timestamp":"2024-06-01T22:42:53.067615Z"}]}
{"channel":"book","type":"update","data":[{"symbol":"ETH/USD","bids":[{"price":3819.16,"qty":26.18370844}],"asks":[],"checksum":2377869012,"timestamp":"2024-06-01T22:42:53.067704Z"}]}
{"channel":"book","type":"update","data":[{"symbol":"ETH/USD","bids":[{"price":3819.09,"qty":26.18419775}],"asks":[],"checksum":719879177,"timestamp":"2024-06-01T22:42:53.067823Z"}]}
{"channel":"book","type":"update","data":[{"symbol":"ETH/USD","bids":[{"price":3819.19,"qty":0.00000000},{"price":3818.83,"qty":4.86871675},{"price":3819.17,"qty":0.00908033}],"asks":[],"checksum":3410163624,"timestamp":"2024-06-01T22:42:53.118789Z"}]}
{"channel":"book","type":"update","data":[{"symbol":"ETH/USD","bids":[{"price":3819.25,"qty":0.01368441},{"price":3819.11,"qty":0.77000000}],"asks":[],"checksum":1271784428,"timestamp":"2024-06-01T22:42:53.253463Z"}]}
{"channel":"book","type":"update","data":[{"symbol":"ETH/USD","bids":[{"price":3819.11,"qty":1.54000000}],"asks":[],"checksum":79936886,"timestamp":"2024-06-01T22:42:53.256489Z"}]}
{"channel":"book","type":"update","data":[{"symbol":"ETH/USD","bids":[{"price":3819.11,"qty":0.77000000}],"asks":[],"checksum":1271784428,"timestamp":"2024-06-01T22:42:53.324948Z"}]}
{"channel":"book","type":"update","data":[{"symbol":"ETH/USD","bids":[],"asks":[{"price":3819.39,"qty":26.41577981}],"checksum":9040559,"timestamp":"2024-06-01T22:42:53.338169Z"}]}
{"channel":"book","type":"update","data":[{"symbol":"ETH/USD","bids":[{"price":3819.16,"qty":0.00000000},{"price":3818.86,"qty":0.42258112}],"asks":[],"checksum":527533008,"timestamp":"2024-06-01T22:42:53.753970Z"}]}
{"channel":"book","type":"update","data":[{"symbol":"ETH/USD","bids":[{"price":3819.18,"qty":26.18360635}],"asks":[],"checksum":6000811,"timestamp":"2024-06-01T22:42:53.757992Z"}]}
{"channel":"book","type":"update","data":[{"symbol":"ETH/USD","bids":[{"price":3819.17,"qty":0.00000000},{"price":3818.86,"qty":0.42258112},{"price":3819.10,"qty":0.00908050}],"asks":[],"checksum":1107601784,"timestamp":"2024-06-01T22:42:53.781120Z"}]}
{"channel":"book","type":"update","data":[{"symbol":"ETH/USD","bids":[{"price":3819.21,"qty":0.00000000},{"price":3818.86,"qty":0.42258112}],"asks":[],"checksum":3263855230,"timestamp":"2024-06-01T22:42:53.950521Z"}]}
{"channel":"book","type":"update","data":[{"symbol":"ETH/USD","bids":[],"asks":[{"price":3819.71,"qty":0.00000000},{"price":3819.94,"qty":26.17845828}],"checksum":452626920,"timestamp":"2024-06-01T22:42:53.950664Z"}]}
{"channel":"book","type":"update","data":[{"symbol":"ETH/USD","bids":[],"asks":[{"price":3819.86,"qty":0.00000000},{"price":3820.31,"qty":0.72912968}],"checksum":616559510,"timestamp":"2024-06-01T22:42:53.950702Z"}]}
{"channel":"book","type":"update","data":[{"symbol":"ETH/USD","bids":[],"asks":[{"price":3819.39,"qty":26.18219139}],"checksum":3434369298,"timestamp":"2024-06-01T22:42:53.954554Z"}]}
{"channel":"book","type":"update","data":[{"symbol":"ETH/USD","bids":[{"price":3819.11,"qty":0.00000000},{"price":3818.83,"qty":4.86871675},{"price":3819.24,"qty":0.77000000}],"asks":[],"checksum":2530843352,"timestamp":"2024-06-01T22:42:53.955901Z"}]}
{"channel":"book","type":"update","data":[{"symbol":"ETH/USD","bids":[],"asks":[{"price":3819.39,"qty":0.00000000},{"price":3820.46,"qty":5.23200000}],"checksum":3670105593,"timestamp":"2024-06-01T22:42:53.955926Z"}]}
{"channel":"book","type":"update","data":[{"symbol":"ETH/USD","bids":[{"price":3819.18,"qty":0.00000000},{"price":3818.83,"qty":4.86871675}],"asks":[],"checksum":1002295919,"timestamp":"2024-06-01T22:42:53.955972Z"}]}
{"channel":"book","type":"update","data":[{"symbol":"ETH/USD","bids":[],"asks":[{"price":3819.40,"qty":0.00000000},{"price":3820.51,"qty":3.67833330}],"checksum":3669317620,"timestamp":"2024-06-01T22:42:53.956028Z"}]}
{"channel":"book","type":"update","data":[{"symbol":"ETH/USD","bids":[{"price":3819.09,"qty":0.00000000},{"price":3818.80,"qty":3.92681465}],"asks":[],"checksum":2437033102,"timestamp":"2024-06-01T22:42:53.956120Z"}]}
{"channel":"book","type":"update","data":[{"symbol":"ETH/USD","bids":[{"price":3819.12,"qty":3.92695857}],"asks":[],"checksum":3905435896,"timestamp":"2024-06-01T22:42:53.957341Z"}]}
{"channel":"book","type":"update","data":[{"symbol":"ETH/USD","bids":[],"asks":[{"price":3819.50,"qty":0.00000000},{"price":3820.60,"qty":3.30000000}],"checksum":4104488048,"timestamp":"2024-06-01T22:42:53.957579Z"}]}
{"channel":"book","type":"update","data":[{"symbol":"ETH/USD","bids":[],"asks":[{"price":3819.69,"qty":0.00000000},{"price":3820.71,"qty":0.79784635}],"checksum":2213328007,"timestamp":"2024-06-01T22:42:53.957777Z"}]}
{"channel":"book","type":"update","data":[{"symbol":"ETH/USD","bids":[{"price":3819.38,"qty":26.59251622}],"asks":[],"checksum":811129679,"timestamp":"2024-06-01T22:42:53.958128Z"}]}
{"channel":"book","type":"update","data":[{"symbol":"ETH/USD","bids":[],"asks":[{"price":3819.81,"qty":0.23359606}],"checksum":4076987222,"timestamp":"2024-06-01T22:42:53.958430Z"}]}
{"channel":"book","type":"update","data":[{"symbol":"ETH/USD","bids":[{"price":3818.99,"qty":0.00000000},{"price":3818.80,"qty":3.92681465}],"asks":[],"checksum":1745946941,"timestamp":"2024-06-01T22:42:53.958859Z"}]}
{"channel":"book","type":"update","data":[{"symbol":"ETH/USD","bids":[{"price":3819.24,"qty":1.54000000}],"asks":[],"checksum":1911132529,"timestamp":"2024-06-01T22:42:53.959285Z"}]}
{"channel":"book","type":"update","data":[{"symbol":"ETH/USD","bids":[{"price":3818.80,"qty":0.00000000},{"price":3818.63,"qty":0.01407082}],"asks":[],"checksum":2161485603,"timestamp":"2024-06-01T22:42:53.961045Z"}]}
{"channel":"book","type":"update","data":[{"symbol":"ETH/USD","bids":[],"asks":[{"price":3819.63,"qty":0.52361092}],"checksum":461331935,"timestamp":"2024-06-01T22:42:53.961473Z"}]}
{"channel":"book","type":"update","data":[{"symbol":"ETH/USD","bids":[],"asks":[{"price":3820.30,"qty":0.49352658}],"checksum":3047750466,"timestamp":"2024-06-01T22:42:53.962214Z"}]}
{"channel":"book","type":"update","data":[{"symbol":"ETH/USD","bids":[{"price":3819.26,"qty":0.76952211}],"asks":[],"checksum":4066454684,"timestamp":"2024-06-01T22:42:53.962232Z"}]}
{"channel":"book","type":"update","data":[{"symbol":"ETH/USD","bids":[{"price":3819.24,"qty":0.77000000}],"asks":[],"checksum":905647113,"timestamp":"2024-06-01T22:42:53.963410Z"}]}
{"channel":"book","type":"update","data":[{"symbol":"ETH/USD","bids":[],"asks":[{"price":3819.64,"qty":0.00000000},{"price":3820.51,"qty":3.67833330}],"checksum":3161134190,"timestamp":"2024-06-01T22:42:53.964889Z"}]}
{"channel":"book","type":"update","data":[{"symbol":"ETH/USD","bids":[],"asks":[{"price":3819.63,"qty":0.00000000},{"price":3820.60,"qty":3.30000000},{"price":3819.62,"qty":0.52361229}],"checksum":2765224783,"timestamp":"2024-06-01T22:42:53.965369Z"}]}
{"channel":"book","type":"update","data":[{"symbol":"ETH/USD","bids":[],"asks":[{"price":3819.64,"qty":0.23358842}],"checksum":1667664453,"timestamp":"2024-06-01T22:42:53.966558Z"}]}
{"channel":"book","type":"update","data":[{"symbol":"ETH/USD","bids":[],"asks":[{"price":3819.62,"qty":0.00000000},{"price":3820.51,"qty":3.67833330}],"checksum":3974299091,"timestamp":"2024-06-01T22:42:53.969012Z"}]}
{"channel":"book","type":"update","data":[{"symbol":"ETH/USD","bids":[{"price":3819.39,"qty":0.42256784}],"asks":[],"checksum":3343532553,"timestamp":"2024-06-01T22:42:53.969603Z"}]}
{"channel":"book","type":"update","data":[{"symbol":"ETH/USD","bids":[],"asks":[{"price":3819.75,"qty":26.17978364}],"checksum":1312357467,"timestamp":"2024-06-01T22:42:53.970627Z"}]}
{"channel":"book","type":"update","data":[{"symbol":"ETH/USD","bids":[],"asks":[{"price":3819.52,"qty":26.18132363}],"checksum":3657835401,"timestamp":"2024-06-01T22:42:53.970669Z"}]}
{"channel":"book","type":"update","data":[{"symbol":"ETH/USD","bids":[{"price":3819.31,"qty":26.18270802}],"asks":[],"checksum":1110709678,"timestamp":"2024-06-01T22:42:53.970773Z"}]}
{"channel":"book","type":"update","data":[{"symbol":"ETH/USD","bids":[{"price":3819.08,"qty":26.18425038}],"asks":[],"checksum":3663831892,"timestamp":"2024-06-01T22:42:53.970785Z"}]}
{"channel":"book","type":"update","data":[{"symbol":"ETH/USD","bids":[],"asks":[{"price":3819.55,"qty":0.23358903}],"checksum":3153935162,"timestamp":"2024-06-01T22:42:53.972389Z"}]}
{"channel":"book","type":"update","data":[{"symbol":"ETH/USD","bids":[],"asks":[{"price":3819.63,"qty":0.52361092}],"checksum":3670488754,"timestamp":"2024-06-01T22:42:53.974351Z"}]}
{"channel":"book","type":"update","data":[{"symbol":"ETH/USD","bids":[{"price":3819.39,"qty":0.00000000},{"price":3818.91,"qty":3.30000000}],"asks":[],"checksum":3727247101,"timestamp":"2024-06-01T22:42:53.975597Z"}]}
{"channel":"book","type":"update","data":[{"symbol":"ETH/USD","bids":[],"asks":[{"price":3819.52,"qty":0.00000000},{"price":3820.30,"qty":0.49352658}],"checksum":131102910,"timestamp":"2024-06-01T22:42:53.978400Z"}]}
{"channel":"book","type":"update","data":[{"symbol":"ETH/USD","bids":[{"price":3819.38,"qty":26.16993510}],"asks":[],"checksum":2463925843,"timestamp":"2024-06-01T22:42:53.978443Z"}]}
{"channel":"book","type":"update","data":[{"symbol":"ETH/USD","bids":[],"asks":[{"price":3819.42,"qty":0.23359178}],"checksum":936401754,"timestamp":"2024-06-01T22:42:53.978761Z"}]}
{"channel":"book","type":"update","data":[{"symbol":"ETH/USD","bids":[],"asks":[{"price":3819.81,"qty":0.00000000},{"price":3820.30,"qty":0.49352658}],"checksum":674769778,"timestamp":"2024-06-01T22:42:53.978800Z"}]}
{"channel":"book","type":"update","data":[{"symbol":"ETH/USD","bids":[{"price":3819.26,"qty":1.19209548}],"asks":[],"checksum":2684601272,"timestamp":"2024-06-01T22:42:53.979050Z"}]}
{"channel":"book","type":"update","data":[{"symbol":"ETH/USD","bids":[],"asks":[{"price":3819.56,"qty":26.18108372}],"checksum":2095107627,"timestamp":"2024-06-01T22:42:53.983134Z"}]}
{"channel":"book","type":"update","data":[{"symbol":"ETH/USD","bids":[{"price":3819.26,"qty":0.76952211}],"asks":[],"checksum":490239836,"timestamp":"2024-06-01T22:42:53.983828Z"}]}
{"channel":"book","type":"update","data":[{"symbol":"ETH/USD","bids":[],"asks":[{"price":3819.39,"qty":0.23359514}],"checksum":3563057365,"timestamp":"2024-06-01T22:42:53.986724Z"}]}
{"channel":"book","type":"update","data":[{"symbol":"ETH/USD","bids":[],"asks":[{"price":3819.64,"qty":0.00000000},{"price":3819.94,"qty":26.17845828}],"checksum":100816474,"timestamp":"2024-06-01T22:42:53.986937Z"}]}
{"channel":"book","type":"update","data":[{"symbol":"ETH/USD","bids":[],"asks":[{"price":3819.56,"qty":0.00000000},{"price":3820.30,"qty":0.49352658}],"checksum":606979112,"timestamp":"2024-06-01T22:42:54.025572Z"}]}
{"channel":"book","type":"update","data":[{"symbol":"ETH/USD","bids":[{"price":3819.34,"qty":26.18246850}],"asks":[],"checksum":252297441,"timestamp":"2024-06-01T22:42:54.029844Z"}]}
{"channel":"book","type":"update","data":[{"symbol":"ETH/USD","bids":[],"asks":[{"price":3819.54,"qty":26.18117798}],"checksum":87996906,"timestamp":"2024-06-01T22:42:54.034072Z"}]}
{"channel":"book","type":"update","data":[{"symbol":"ETH/USD","bids":[],"asks":[{"price":3819.63,"qty":0.00000000},{"price":3820.30,"qty":0.49352658}],"checksum":2740531231,"timestamp":"2024-06-01T22:42:54.034486Z"}]}
{"channel":"book","type":"update","data":[{"symbol":"ETH/USD","bids":[{"price":3819.34,"qty":0.00000000},{"price":3818.91,"qty":3.30000000}],"asks":[],"checksum":3357833731,"timestamp":"2024-06-01T22:42:54.039005Z"}]}
{"channel":"book","type":"update","data":[{"symbol":"ETH/USD","bids":[],"asks":[{"price":3819.54,"qty":0.00000000},{"price":3820.31,"qty":0.72912968}],"checksum":3344115441,"timestamp":"2024-06-01T22:42:54.039019Z"}]}
{"channel":"book","type":"update","data":[{"symbol":"ETH/USD","bids":[],"asks":[{"price":3819.39,"qty":0.00000000},{"price":3820.46,"qty":5.23200000}],"checksum":2373625612,"timestamp":"2024-06-01T22:42:54.069833Z"}]}
{"channel":"book","type":"update","data":[{"symbol":"ETH/USD","bids":[{"price":3819.23,"qty":26.18322814}],"asks":[],"checksum":3098060147,"timestamp":"2024-06-01T22:42:54.070480Z"}]}
{"channel":"book","type":"update","data":[{"symbol":"ETH/USD","bids":[],"asks":[{"price":3819.42,"qty":0.00000000},{"price":3820.60,"qty":3.30000000}],"checksum":2098106420,"timestamp":"2024-06-01T22:42:54.072733Z"}]}
{"channel":"book","type":"update","data":[{"symbol":"ETH/USD","bids":[{"price":3819.38,"qty":26.59251622}],"asks":[],"checksum":2736783887,"timestamp":"2024-06-01T22:42:54.073002Z"}]}
{"channel":"book","type":"update","data":[{"symbol":"ETH/USD","bids":[{"price":3819.26,"qty":0.00000000},{"price":3818.91,"qty":3.30000000}],"asks":[],"checksum":3391613559,"timestamp":"2024-06-01T22:42:54.073284Z"}]}
{"channel":"book","type":"update","data":[{"symbol":"ETH/USD","bids":[],"asks":[{"price":3820.30,"qty":0.00000000},{"price":3820.71,"qty":0.79784635}],"checksum":3754276901,"timestamp":"2024-06-01T22:42:54.073429Z"}]}
{"channel":"book","type":"update","data":[{"symbol":"ETH/USD","bids":[],"asks":[{"price":3820.00,"qty":0.77000000}],"checksum":4126633178,"timestamp":"2024-06-01T22:42:54.073835Z"}]}
{"channel":"book","type":"update","data":[{"symbol":"ETH/USD","bids":[],"asks":[{"price":3819.53,"qty":0.23359117}],"checksum":2073468056,"timestamp":"2024-06-01T22:42:54.078124Z"}]}
{"channel":"book","type":"update","data":[{"symbol":"ETH/USD","bids":[],"asks":[{"price":3820.32,"qty":3.67833330}],"checksum":2901998769,"timestamp":"2024-06-01T22:42:54.118392Z"}]}
{"channel":"book","type":"update","data":[{"symbol":"ETH/USD","bids":[{"price":3819.38,"qty":26.16993510}],"asks":[],"checksum":489503495,"timestamp":"2024-06-01T22:42:54.126383Z"}]}
{"channel":"book","type":"update","data":[{"symbol":"ETH/USD","bids":[],"asks":[{"price":3819.39,"qty":0.23359178}],"checksum":2137351668,"timestamp":"2024-06-01T22:42:54.129293Z"}]}
{"channel":"book","type":"update","data":[{"symbol":"ETH/USD","bids":[{"price":3819.31,"qty":0.00000000},{"price":3818.86,"qty":0.42258112}],"asks":[],"checksum":3481933401,"timestamp":"2024-06-01T22:42:54.176866Z"}]}
{"channel":"book","type":"update","data":[{"symbol":"ETH/USD","bids":[{"price":3819.26,"qty":0.76952211}],"asks":[],"checksum":538629562,"timestamp":"2024-06-01T22:42:54.180136Z"}]}
{"channel":"book","type":"update","data":[{"symbol":"ETH/USD","bids":[],"asks":[{"price":3819.93,"qty":0.49352658}],"checksum":1441910837,"timestamp":"2024-06-01T22:42:54.180215Z"}]}
{"channel":"book","type":"update","data":[{"symbol":"ETH/USD","bids":[],"asks":[{"price":3819.52,"qty":26.18130026}],"checksum":2487242844,"timestamp":"2024-06-01T22:42:54.181056Z"}]}
{"channel":"book","type":"update","data":[{"symbol":"ETH/USD","bids":[{"price":3819.32,"qty":26.18262299}],"asks":[],"checksum":890744530,"timestamp":"2024-06-01T22:42:54.181075Z"}]}
{"channel":"book","type":"update","data":[{"symbol":"ETH/USD","bids":[],"asks":[{"price":3819.61,"qty":26.18068336}],"checksum":1115796805,"timestamp":"2024-06-01T22:42:54.181174Z"}]}
{"channel":"book","type":"update","data":[{"symbol":"ETH/USD","bids":[{"price":3819.10,"qty":0.00000000},{"price":3818.91,"qty":3.30000000},{"price":3819.33,"qty":0.00907995}],"asks":[],"checksum":1095745033,"timestamp":"2024-06-01T22:42:54.281501Z"}]}
{"channel":"book","type":"update","data":[{"symbol":"ETH/USD","bids":[{"price":3819.32,"qty":0.00000000},{"price":3818.91,"qty":3.30000000}],"asks":[],"checksum":4193777740,"timestamp":"2024-06-01T22:42:54.426687Z"}]}
{"channel":"book","type":"update","data":[{"symbol":"ETH/USD","bids":[],"asks":[{"price":3819.52,"qty":0.00000000},{"price":3819.94,"qty":26.17845828}],"checksum":70324187,"timestamp":"2024-06-01T22:42:54.426705Z"}]}
{"channel":"book","type":"update","data":[{"symbol":"ETH/USD","bids":[],"asks":[{"price":3819.54,"qty":26.18120374}],"checksum":3855471026,"timestamp":"2024-06-01T22:42:54.431380Z"}]}
{"channel":"book","type":"update","data":[{"symbol":"ETH/USD","bids":[{"price":3819.33,"qty":26.19164272}],"asks":[],"checksum":3281567314,"timestamp":"2024-06-01T22:42:54.431536Z"}]}
{"channel":"book","type":"update","data":[{"symbol":"ETH/USD","bids":[],"asks":[{"price":3819.54,"qty":0.00000000},{"price":3819.94,"qty":26.17845828}],"checksum":1839555262,"timestamp":"2024-06-01T22:42:54.438326Z"}]}
{"channel":"book","type":"update","data":[{"symbol":"ETH/USD","bids":[{"price":3819.33,"qty":0.00907995}],"asks":[],"checksum":70324187,"timestamp":"2024-06-01T22:42:54.454406Z"}]}
{"channel":"book","type":"update","data":[{"symbol":"ETH/USD","bids":[],"asks":[{"price":3819.61,"qty":0.00000000},{"price":3820.00,"qty":0.77000000}],"checksum":2842523940,"timestamp":"2024-06-01T22:42:54.454428Z"}]}
{"channel":"book","type":"update","data":[{"symbol":"ETH/USD","bids":[],"asks":[{"price":3819.48,"qty":26.18161483}],"checksum":872573504,"timestamp":"2024-06-01T22:42:54.486993Z"}]}
{"channel":"book","type":"update","data":[{"symbol":"ETH/USD","bids":[{"price":3819.27,"qty":26.18297388}],"asks":[],"checksum":3413949890,"timestamp":"2024-06-01T22:42:54.487015Z"}]}
{"channel":"book","type":"update","data":[{"symbol":"ETH/USD","bids":[],"asks":[{"price":3819.48,"qty":0.00000000},{"price":3820.00,"qty":0.77000000}],"checksum":2168354704,"timestamp":"2024-06-01T22:42:54.502080Z"}]}
{"channel":"book","type":"update","data":[{"symbol":"ETH/USD","bids":[{"price":3819.27,"qty":0.00000000},{"price":3818.91,"qty":3.30000000}],"asks":[],"checksum":2842523940,"timestamp":"2024-06-01T22:42:54.502181Z"}]}
{"channel":"book","type":"update","data":[{"symbol":"ETH/USD","bids":[{"price":3819.33,"qty":0.00000000},{"price":3818.86,"qty":0.42258112},{"price":3819.25,"qty":0.02276455}],"asks":[],"checksum":122169661,"timestamp":"2024-06-01T22:42:54.527198Z"}]}
{"channel":"book","type":"update","data":[{"symbol":"ETH/USD","bids":[],"asks":[{"price":3819.48,"qty":26.18160279}],"checksum":950186746,"timestamp":"2024-06-01T22:42:54.560777Z"}]}
{"channel":"book","type":"update","data":[{"symbol":"ETH/USD","bids":[{"price":3819.27,"qty":26.18295923}],"asks":[],"checksum":2945697169,"timestamp":"2024-06-01T22:42:54.560863Z"}]}
{"channel":"book","type":"update","data":[{"symbol":"ETH/USD","bids":[],"asks":[{"price":3819.48,"qty":0.00000000},{"price":3820.00,"qty":0.77000000}],"checksum":1291186494,"timestamp":"2024-06-01T22:42:54.565305Z"}]}
{"channel":"book","type":"update","data":[{"symbol":"ETH/USD","bids":[{"price":3819.27,"qty":0.00000000},{"price":3818.86,"qty":0.42258112}],"asks":[],"checksum":122169661,"timestamp":"2024-06-01T22:42:54.565444Z"}]}
{"channel":"book","type":"update","data":[{"symbol":"ETH/USD","bids":[{"price":3819.29,"qty":26.18281259}],"asks":[],"checksum":2565591399,"timestamp":"2024-06-01T22:42:54.665342Z"}]}
{"channel":"book","type":"update","data":[{"symbol":"ETH/USD","bids":[],"asks":[{"price":3819.50,"qty":26.18146925}],"checksum":2375433819,"timestamp":"2024-06-01T22:42:54.665802Z"}]}
{"channel":"book","type":"update","data":[{"symbol":"ETH/USD","bids":[],"asks":[{"price":3819.39,"qty":0.00000000},{"price":3820.00,"qty":0.77000000}],"checksum":61313261,"timestamp":"2024-06-01T22:42:54.710787Z"}]}
{"channel":"book","type":"update","data":[{"symbol":"ETH/USD","bids":[{"price":3819.38,"qty":26.59251622}],"asks":[],"checksum":3023601429,"timestamp":"2024-06-01T22:42:54.713954Z"}]}
{"channel":"book","type":"update","data":[{"symbol":"ETH/USD","bids":[],"asks":[{"price":3819.50,"qty":0.00000000},{"price":3820.31,"qty":0.72912968}],"checksum":889809159,"timestamp":"2024-06-01T22:42:54.716245Z"}]}
{"channel":"book","type":"update","data":[{"symbol":"ETH/USD","bids":[{"price":3819.44,"qty":0.42257503}],"asks":[],"checksum":1404590214,"timestamp":"2024-06-01T22:42:54.719081Z"}]}
{"channel":"book","type":"update","data":[{"symbol":"ETH/USD","bids":[],"asks":[{"price":3819.49,"qty":26.18153471}],"checksum":3530155198,"timestamp":"2024-06-01T22:42:54.720699Z"}]}
{"channel":"book","type":"update","data":[{"symbol":"ETH/USD","bids":[{"price":3819.25,"qty":0.01368441},{"price":3819.39,"qty":0.00907982}],"asks":[],"checksum":2754879249,"timestamp":"2024-06-01T22:42:54.808717Z"}]}
{"channel":"book","type":"update","data":[{"symbol":"ETH/USD","bids":[{"price":3819.29,"qty":0.00000000},{"price":3818.92,"qty":3.92659878}],"asks":[],"checksum":2585308625,"timestamp":"2024-06-01T22:42:55.020475Z"}]}
{"channel":"book","type":"update","data":[{"symbol":"ETH/USD","bids":[],"asks":[{"price":3819.49,"qty":0.00000000},{"price":3820.31,"qty":0.72912968}],"checksum":335522028,"timestamp":"2024-06-01T22:42:55.020572Z"}]}
{"channel":"book","type":"update","data":[{"symbol":"ETH/USD","bids":[],"asks":[{"price":3819.52,"qty":26.18131109}],"checksum":3348825965,"timestamp":"2024-06-01T22:42:55.026147Z"}]}
{"channel":"book","type":"update","data":[{"symbol":"ETH/USD","bids":[{"price":3819.31,"qty":26.18270523}],"asks":[],"checksum":4291634888,"timestamp":"2024-06-01T22:42:55.026164Z"}]}
{"channel":"book","type":"update","data":[{"symbol":"ETH/USD","bids":[],"asks":[{"price":3819.58,"qty":26.18091913}],"checksum":2379653667,"timestamp":"2024-06-01T22:42:55.026219Z"}]}
{"channel":"book","type":"update","data":[{"symbol":"ETH/USD","bids":[{"price":3819.44,"qty":0.00000000},{"price":3818.92,"qty":3.92659878}],"asks":[],"checksum":889651728,"timestamp":"2024-06-01T22:42:55.063385Z"}]}
{"channel":"book","type":"update","data":[{"symbol":"ETH/USD","bids":[{"price":3819.38,"qty":26.16993510}],"asks":[],"checksum":2704287104,"timestamp":"2024-06-01T22:42:55.066350Z"}]}
{"channel":"book","type":"update","data":[{"symbol":"ETH/USD","bids":[],"asks":[{"price":3819.45,"qty":0.23359025}],"checksum":3360234340,"timestamp":"2024-06-01T22:42:55.066700Z"}]}
{"channel":"book","type":"update","data":[{"symbol":"ETH/USD","bids":[],"asks":[{"price":3819.55,"qty":0.00000000},{"price":3819.94,"qty":26.17845828}],"checksum":3736302935,"timestamp":"2024-06-01T22:42:55.069261Z"}]}
{"channel":"book","type":"update","data":[{"symbol":"ETH/USD","bids":[],"asks":[{"price":3819.52,"qty":0.00000000},{"price":3820.00,"qty":0.77000000}],"checksum":1277343546,"timestamp":"2024-06-01T22:42:55.069298Z"}]}
{"channel":"book","type":"update","data":[{"symbol":"ETH/USD","bids":[],"asks":[{"price":3819.40,"qty":0.23359392}],"checksum":1838311102,"timestamp":"2024-06-01T22:42:55.072296Z"}]}
{"channel":"book","type":"update","data":[{"symbol":"ETH/USD","bids":[{"price":3819.31,"qty":0.00000000},{"price":3818.91,"qty":3.30000000}],"asks":[],"checksum":142842249,"timestamp":"2024-06-01T22:42:55.165530Z"}]}
{"channel":"book","type":"update","data":[{"symbol":"ETH/USD","bids":[{"price":3819.29,"qty":26.18280998}],"asks":[],"checksum":1940630056,"timestamp":"2024-06-01T22:42:55.169685Z"}]}
{"channel":"book","type":"update","data":[{"symbol":"ETH/USD","bids":[],"asks":[{"price":3819.50,"qty":26.18145354}],"checksum":2706214554,"timestamp":"2024-06-01T22:42:55.169770Z"}]}
{"channel":"book","type":"update","data":[{"symbol":"ETH/USD","bids":[{"price":3819.26,"qty":0.00000000},{"price":3818.91,"qty":3.30000000}],"asks":[],"checksum":2163582118,"timestamp":"2024-06-01T22:42:55.229200Z"}]}
{"channel":"book","type":"update","data":[{"symbol":"ETH/USD","bids":[{"price":3819.23,"qty":0.00000000},{"price":3818.86,"qty":0.42258112}],"asks":[],"checksum":4022438909,"timestamp":"2024-06-01T22:42:55.399598Z"}]}
{"channel":"book","type":"update","data":[{"symbol":"ETH/USD","bids":[],"asks":[{"price":3819.50,"qty":0.00000000},{"price":3819.94,"qty":26.17845828}],"checksum":73450715,"timestamp":"2024-06-01T22:42:55.399742Z"}]}
{"channel":"book","type":"update","data":[{"symbol":"ETH/USD","bids":[{"price":3819.39,"qty":0.81876187}],"asks":[],"checksum":1806118078,"timestamp":"2024-06-01T22:42:55.402751Z"}]}
{"channel":"book","type":"update","data":[{"symbol":"ETH/USD","bids":[],"asks":[{"price":3819.53,"qty":26.41488761}],"checksum":4051680409,"timestamp":"2024-06-01T22:42:55.404248Z"}]}
{"channel":"book","type":"update","data":[{"symbol":"ETH/USD","bids":[{"price":3819.32,"qty":26.18265286}],"asks":[],"checksum":3129439443,"timestamp":"2024-06-01T22:42:55.404450Z"}]}
{"channel":"book","type":"update","data":[{"symbol":"ETH/USD","bids":[],"asks":[{"price":3819.53,"qty":0.23359117}],"checksum":2421018410,"timestamp":"2024-06-01T22:42:55.419460Z"}]}
{"channel":"book","type":"update","data":[{"symbol":"ETH/USD","bids":[{"price":3819.39,"qty":4.74562792}],"asks":[],"checksum":3224221409,"timestamp":"2024-06-01T22:42:55.490453Z"}]}
{"channel":"book","type":"update","data":[{"symbol":"ETH/USD","bids":[{"price":3819.12,"qty":0.00000000},{"price":3818.86,"qty":0.42258112}],"asks":[],"checksum":2389310599,"timestamp":"2024-06-01T22:42:55.494441Z"}]}
{"channel":"book","type":"update","data":[{"symbol":"ETH/USD","bids":[{"price":3819.32,"qty":0.00000000},{"price":3818.84,"qty":26.18594706}],"asks":[],"checksum":1854826853,"timestamp":"2024-06-01T22:42:55.540857Z"}]}
{"channel":"book","type":"update","data":[{"symbol":"ETH/USD","bids":[],"asks":[{"price":3819.50,"qty":26.18145392}],"checksum":1184450415,"timestamp":"2024-06-01T22:42:55.545613Z"}]}
{"channel":"book","type":"update","data":[{"symbol":"ETH/USD","bids":[{"price":3819.30,"qty":26.18279538}],"asks":[],"checksum":1071382902,"timestamp":"2024-06-01T22:42:55.545756Z"}]}
{"channel":"book","type":"update","data":[{"symbol":"ETH/USD","bids":[{"price":3819.38,"qty":0.00000000},{"price":3818.84,"qty":26.18594706}],"asks":[],"checksum":2742202496,"timestamp":"2024-06-01T22:42:55.557317Z"}]}
{"channel":"book","type":"update","data":[{"symbol":"ETH/USD","bids":[{"price":3819.39,"qty":30.91277574}],"asks":[],"checksum":3692734272,"timestamp":"2024-06-01T22:42:55.557531Z"}]}
{"channel":"book","type":"update","data":[{"symbol":"ETH/USD","bids":[{"price":3819.39,"qty":30.90369592},{"price":3819.31,"qty":0.00908001}],"asks":[],"checksum":2974053126,"timestamp":"2024-06-01T22:42:55.600784Z"}]}
{"channel":"book","type":"update","data":[{"symbol":"ETH/USD","bids":[],"asks":[{"price":3819.77,"qty":0.00000000},{"price":3819.94,"qty":26.17845828}],"checksum":1188837269,"timestamp":"2024-06-01T22:42:56.323438Z"}]}
{"channel":"book","type":"update","data":[{"symbol":"ETH/USD","bids":[{"price":3819.24,"qty":0.00000000},{"price":3818.84,"qty":26.18594706},{"price":3819.35,"qty":0.77000000}],"asks":[],"checksum":1184821695,"timestamp":"2024-06-01T22:42:56.342642Z"}]}
{"channel":"book","type":"update","data":[{"symbol":"ETH/USD","bids":[{"price":3819.35,"qty":1.54000000}],"asks":[],"checksum":2255226776,"timestamp":"2024-06-01T22:42:56.343672Z"}]}
{"channel":"book","type":"update","data":[{"symbol":"ETH/USD","bids":[{"price":3819.35,"qty":0.77000000}],"asks":[],"checksum":1184821695,"timestamp":"2024-06-01T22:42:56.345915Z"}]}
{"channel":"book","type":"update","data":[{"symbol":"ETH/USD","bids":[{"price":3819.35,"qty":0.00000000},{"price":3818.84,"qty":26.18594706}],"asks":[],"checksum":2185258948,"timestamp":"2024-06-01T22:42:56.346253Z"}]}
{"channel":"book","type":"update","data":[{"symbol":"ETH/USD","bids":[],"asks":[{"price":3819.40,"qty":0.00000000},{"price":3820.31,"qty":0.72912968}],"checksum":3743456494,"timestamp":"2024-06-01T22:42:56.347355Z"}]}
{"channel":"book","type":"update","data":[{"symbol":"ETH/USD","bids":[],"asks":[{"price":3819.50,"qty":0.00000000},{"price":3820.32,"qty":3.67833330}],"checksum":1068522209,"timestamp":"2024-06-01T22:42:56.348850Z"}]}
{"channel":"book","type":"update","data":[{"symbol":"ETH/USD","bids":[],"asks":[{"price":3819.58,"qty":0.00000000},{"price":3820.60,"qty":3.30000000}],"checksum":742979011,"timestamp":"2024-06-01T22:42:56.348870Z"}]}
{"channel":"book","type":"update","data":[{"symbol":"ETH/USD","bids":[{"price":3819.29,"qty":0.00000000},{"price":3818.83,"qty":4.86871675}],"asks":[],"checksum":2189017353,"timestamp":"2024-06-01T22:42:56.348901Z"}]}
{"channel":"book","type":"update","data":[{"symbol":"ETH/USD","bids":[],"asks":[{"price":3819.45,"qty":0.00000000},{"price":3820.63,"qty":5.23200000}],"checksum":3388547070,"timestamp":"2024-06-01T22:42:56.350496Z"}]}
{"channel":"book","type":"update","data":[{"symbol":"ETH/USD","bids":[],"asks":[{"price":3819.53,"qty":0.00000000},{"price":3820.73,"qty":0.85621698}],"checksum":1573483158,"timestamp":"2024-06-01T22:42:56.350821Z"}]}
{"channel":"book","type":"update","data":[{"symbol":"ETH/USD","bids":[{"price":3819.39,"qty":31.32627593}],"asks":[],"checksum":1827813649,"timestamp":"2024-06-01T22:42:56.350993Z"}]}
{"channel":"book","type":"update","data":[{"symbol":"ETH/USD","bids":[],"asks":[{"price":3819.62,"qty":0.23359545}],"checksum":843901360,"timestamp":"2024-06-01T22:42:56.351260Z"}]}
{"channel":"book","type":"update","data":[{"symbol":"ETH/USD","bids":[{"price":3819.44,"qty":0.77000000}],"asks":[],"checksum":1514066812,"timestamp":"2024-06-01T22:42:56.352872Z"}]}
{"channel":"book","type":"update","data":[{"symbol":"ETH/USD","bids":[{"price":3819.39,"qty":31.84991975}],"asks":[],"checksum":2958700917,"timestamp":"2024-06-01T22:42:56.353201Z"}]}
{"channel":"book","type":"update","data":[{"symbol":"ETH/USD","bids":[{"price":3819.40,"qty":3.92686605}],"asks":[],"checksum":4000299387,"timestamp":"2024-06-01T22:42:56.353758Z"}]}
{"channel":"book","type":"update","data":[{"symbol":"ETH/USD","bids":[],"asks":[{"price":3819.62,"qty":0.00000000},{"price":3820.73,"qty":0.85621698}],"checksum":2001605860,"timestamp":"2024-06-01T22:42:56.355243Z"}]}
{"channel":"book","type":"update","data":[{"symbol":"ETH/USD","bids":[{"price":3819.45,"qty":3.92686605}],"asks":[],"checksum":2534630080,"timestamp":"2024-06-01T22:42:56.357007Z"}]}
{"channel":"book","type":"update","data":[{"symbol":"ETH/USD","bids":[{"price":3819.52,"qty":0.42257282}],"asks":[],"checksum":155062714,"timestamp":"2024-06-01T22:42:56.358452Z"}]}
{"channel":"book","type":"update","data":[{"symbol":"ETH/USD","bids":[],"asks":[{"price":3820.05,"qty":0.23359147}],"checksum":1897179548,"timestamp":"2024-06-01T22:42:56.358806Z"}]}
{"channel":"book","type":"update","data":[{"symbol":"ETH/USD","bids":[{"price":3819.39,"qty":27.92305370}],"asks":[],"checksum":3463581872,"timestamp":"2024-06-01T22:42:56.359030Z"}]}
{"channel":"book","type":"update","data":[{"symbol":"ETH/USD","bids":[{"price":3819.40,"qty":0.00000000},{"price":3818.91,"qty":3.30000000}],"asks":[],"checksum":2568607747,"timestamp":"2024-06-01T22:42:56.359561Z"}]}
{"channel":"book","type":"update","data":[{"symbol":"ETH/USD","bids":[],"asks":[{"price":3819.93,"qty":0.00000000},{"price":3820.73,"qty":0.85621698}],"checksum":1442100190,"timestamp":"2024-06-01T22:42:56.361676Z"}]}
{"channel":"book","type":"update","data":[{"symbol":"ETH/USD","bids":[{"price":3819.71,"qty":0.42255899}],"asks":[],"checksum":1513677149,"timestamp":"2024-06-01T22:42:56.361701Z"}]}
{"channel":"book","type":"update","data":[{"symbol":"ETH/USD","bids":[{"price":3819.67,"qty":0.42255512}],"asks":[],"checksum":316999643,"timestamp":"2024-06-01T22:42:56.368710Z"}]}
{"channel":"book","type":"update","data":[{"symbol":"ETH/USD","bids":[],"asks":[{"price":3820.32,"qty":0.00000000},{"price":3820.74,"qty":86.84418536}],"checksum":2629696211,"timestamp":"2024-06-01T22:42:56.369527Z"}]}
{"channel":"book","type":"update","data":[{"symbol":"ETH/USD","bids":[{"price":3819.50,"qty":26.18140463}],"asks":[],"checksum":1835472818,"timestamp":"2024-06-01T22:42:56.370519Z"}]}
{"channel":"book","type":"update","data":[{"symbol":"ETH/USD","bids":[],"asks":[{"price":3820.18,"qty":26.17681099}],"checksum":528684091,"timestamp":"2024-06-01T22:42:56.370675Z"}]}
{"channel":"book","type":"update","data":[{"symbol":"ETH/USD","bids":[],"asks":[{"price":3819.73,"qty":26.17989723}],"checksum":1095830111,"timestamp":"2024-06-01T22:42:56.370696Z"}]}
{"channel":"book","type":"update","data":[{"symbol":"ETH/USD","bids":[{"price":3819.44,"qty":0.00000000},{"price":3819.08,"qty":26.18425038},{"price":3819.57,"qty":0.77000000}],"asks":[],"checksum":3962152146,"timestamp":"2024-06-01T22:42:56.370744Z"}]}
{"channel":"book","type":"update","data":[{"symbol":"ETH/USD","bids":[{"price":3819.71,"qty":0.00000000},{"price":3819.08,"qty":26.18425038}],"asks":[],"checksum":3204848578,"timestamp":"2024-06-01T22:42:56.371487Z"}]}
{"channel":"book","type":"update","data":[{"symbol":"ETH/USD","bids":[{"price":3819.39,"qty":27.50047369}],"asks":[],"checksum":1874876260,"timestamp":"2024-06-01T22:42:56.371748Z"}]}
{"channel":"book","type":"update","data":[{"symbol":"ETH/USD","bids":[{"price":3819.57,"qty":1.54000000}],"asks":[],"checksum":1037930816,"timestamp":"2024-06-01T22:42:56.376162Z"}]}
{"channel":"book","type":"update","data":[{"symbol":"ETH/USD","bids":[{"price":3819.67,"qty":0.00000000},{"price":3818.92,"qty":3.92659878}],"asks":[],"checksum":1323651124,"timestamp":"2024-06-01T22:42:56.380454Z"}]}
{"channel":"book","type":"update","data":[{"symbol":"ETH/USD","bids":[{"price":3819.57,"qty":0.77000000}],"asks":[],"checksum":970303241,"timestamp":"2024-06-01T22:42:56.381475Z"}]}
{"channel":"book","type":"update","data":[{"symbol":"ETH/USD","bids":[{"price":3819.57,"qty":1.19255235}],"asks":[],"checksum":55440849,"timestamp":"2024-06-01T22:42:56.386042Z"}]}
{"channel":"book","type":"update","data":[{"symbol":"ETH/USD","bids":[],"asks":[{"price":3819.75,"qty":0.00000000},{"price":3820.73,"qty":0.85621698}],"checksum":3527454507,"timestamp":"2024-06-01T22:42:56.386500Z"}]}
{"channel":"book","type":"update","data":[{"symbol":"ETH/USD","bids":[],"asks":[{"price":3819.73,"qty":0.00000000},{"price":3820.74,"qty":86.84418536}],"checksum":1471493806,"timestamp":"2024-06-01T22:42:56.386656Z"}]}
{"channel":"book","type":"update","data":[{"symbol":"ETH/USD","bids":[{"price":3819.30,"qty":0.00000000},{"price":3818.91,"qty":3.30000000}],"asks":[],"checksum":1720553177,"timestamp":"2024-06-01T22:42:56.386667Z"}]}
{"channel":"book","type":"update","data":[{"symbol":"ETH/USD","bids":[{"price":3819.50,"qty":0.00000000},{"price":3818.83,"qty":4.86871675}],"asks":[],"checksum":938355861,"timestamp":"2024-06-01T22:42:56.386675Z"}]}
{"channel":"book","type":"update","data":[{"symbol":"ETH/USD","bids":[{"price":3819.39,"qty":53.68259938}],"asks":[],"checksum":3641453011,"timestamp":"2024-06-01T22:42:56.391731Z"}]}
{"channel":"book","type":"update","data":[{"symbol":"ETH/USD","bids":[{"price":3819.57,"qty":0.77000000}],"asks":[],"checksum":1101592444,"timestamp":"2024-06-01T22:42:56.392016Z"}]}
{"channel":"book","type":"update","data":[{"symbol":"ETH/USD","bids":[],"asks":[{"price":3819.64,"qty":0.23358016}],"checksum":652837250,"timestamp":"2024-06-01T22:42:56.394982Z"}]}
{"channel":"book","type":"update","data":[{"symbol":"ETH/USD","bids":[{"price":3819.31,"qty":0.00000000},{"price":3818.63,"qty":0.01407082},{"price":3819.41,"qty":0.00907965}],"asks":[],"checksum":179522716,"timestamp":"2024-06-01T22:42:56.397222Z"}]}
{"channel":"book","type":"update","data":[{"symbol":"ETH/USD","bids":[],"asks":[{"price":3819.64,"qty":0.00000000},{"price":3820.74,"qty":86.84418536}],"checksum":1844591202,"timestamp":"2024-06-01T22:42:56.404161Z"}]}
{"channel":"book","type":"update","data":[{"symbol":"ETH/USD","bids":[{"price":3818.91,"qty":0.00000000},{"price":3818.63,"qty":0.01407082}],"asks":[],"checksum":3444717558,"timestamp":"2024-06-01T22:42:56.406985Z"}]}
{"channel":"book","type":"update","data":[{"symbol":"ETH/USD","bids":[{"price":3819.39,"qty":56.98259938}],"asks":[],"checksum":2033186763,"timestamp":"2024-06-01T22:42:56.407011Z"}]}
{"channel":"book","type":"update","data":[{"symbol":"ETH/USD","bids":[{"price":3819.58,"qty":0.42255678}],"asks":[],"checksum":703282241,"timestamp":"2024-06-01T22:42:56.407080Z"}]}
{"channel":"book","type":"update","data":[{"symbol":"ETH/USD","bids":[{"price":3819.58,"qty":0.00000000},{"price":3818.63,"qty":0.01407082}],"asks":[],"checksum":2033186763,"timestamp":"2024-06-01T22:42:56.413573Z"}]}
{"channel":"book","type":"update","data":[{"symbol":"ETH/USD","bids":[{"price":3819.39,"qty":53.68259938}],"asks":[],"checksum":3444717558,"timestamp":"2024-06-01T22:42:56.419228Z"}]}
{"channel":"book","type":"update","data":[{"symbol":"ETH/USD","bids":[],"asks":[{"price":3819.62,"qty":0.23358016}],"checksum":218854124,"timestamp":"2024-06-01T22:42:56.419413Z"}]}
{"channel":"book","type":"update","data":[{"symbol":"ETH/USD","bids":[{"price":3819.41,"qty":3.30907965}],"asks":[],"checksum":1101759528,"timestamp":"2024-06-01T22:42:56.419434Z"}]}
{"channel":"book","type":"update","data":[{"symbol":"ETH/USD","bids":[],"asks":[{"price":3820.34,"qty":2.09600000}],"checksum":1042275796,"timestamp":"2024-06-01T22:42:56.422025Z"}]}
{"channel":"book","type":"update","data":[{"symbol":"ETH/USD","bids":[],"asks":[{"price":3819.87,"qty":26.17893686}],"checksum":332902153,"timestamp":"2024-06-01T22:42:56.424558Z"}]}
{"channel":"book","type":"update","data":[{"symbol":"ETH/USD","bids":[{"price":3819.58,"qty":26.18088899}],"asks":[],"checksum":1135880531,"timestamp":"2024-06-01T22:42:56.424669Z"}]}
{"channel":"book","type":"update","data":[{"symbol":"ETH/USD","bids":[],"asks":[{"price":3819.87,"qty":0.00000000},{"price":3820.63,"qty":5.23200000}],"checksum":1314119403,"timestamp":"2024-06-01T22:42:56.430792Z"}]}
{"channel":"book","type":"update","data":[{"symbol":"ETH/USD","bids":[{"price":3819.58,"qty":0.00000000},{"price":3818.63,"qty":0.01407082}],"asks":[],"checksum":1042275796,"timestamp":"2024-06-01T22:42:56.430805Z"}]}
{"channel":"book","type":"update","data":[{"symbol":"ETH/USD","bids":[],"asks":[{"price":3820.00,"qty":26.17801576}],"checksum":591729258,"timestamp":"2024-06-01T22:42:56.437155Z"}]}
{"channel":"book","type":"update","data":[{"symbol":"ETH/USD","bids":[],"asks":[{"price":3819.94,"qty":0.00000000},{"price":3820.63,"qty":5.23200000}],"checksum":1485726381,"timestamp":"2024-06-01T22:42:56.441851Z"}]}
{"channel":"book","type":"update","data":[{"symbol":"ETH/USD","bids":[{"price":3819.08,"qty":0.00000000},{"price":3818.55,"qty":6.22500000}],"asks":[],"checksum":3725597888,"timestamp":"2024-06-01T22:42:56.446417Z"}]}
{"channel":"book","type":"update","data":[{"symbol":"ETH/USD","bids":[{"price":3819.22,"qty":26.18333780}],"asks":[],"checksum":2487428274,"timestamp":"2024-06-01T22:42:56.450284Z"}]}
{"channel":"book","type":"update","data":[{"symbol":"ETH/USD","bids":[],"asks":[{"price":3819.62,"qty":0.00000000},{"price":3820.73,"qty":0.85621698}],"checksum":841590440,"timestamp":"2024-06-01T22:42:56.457557Z"}]}
{"channel":"book","type":"update","data":[{"symbol":"ETH/USD","bids":[{"price":3819.41,"qty":0.00907965}],"asks":[],"checksum":2087089927,"timestamp":"2024-06-01T22:42:56.459248Z"}]}
{"channel":"book","type":"update","data":[{"symbol":"ETH/USD","bids":[{"price":3819.46,"qty":3.30000000}],"asks":[],"checksum":39593259,"timestamp":"2024-06-01T22:42:56.459292Z"}]}
{"channel":"book","type":"update","data":[{"symbol":"ETH/USD","bids":[{"price":3819.57,"qty":0.00000000},{"price":3818.63,"qty":0.01407082},{"price":3819.71,"qty":0.77000000}],"asks":[],"checksum":2420726549,"timestamp":"2024-06-01T22:42:56.461469Z"}]}
{"channel":"book","type":"update","data":[{"symbol":"ETH/USD","bids":[],"asks":[{"price":3820.72,"qty":0.47389664}],"checksum":1224763479,"timestamp":"2024-06-01T22:42:56.462634Z"}]}
{"channel":"book","type":"update","data":[{"symbol":"ETH/USD","bids":[{"price":3819.71,"qty":1.54000000}],"asks":[],"checksum":3316683149,"timestamp":"2024-06-01T22:42:56.464674Z"}]}
{"channel":"book","type":"update","data":[{"symbol":"ETH/USD","bids":[{"price":3819.71,"qty":0.77000000}],"asks":[],"checksum":1224763479,"timestamp":"2024-06-01T22:42:56.467363Z"}]}
{"channel":"book","type":"update","data":[{"symbol":"ETH/USD","bids":[],"asks":[{"price":3820.40,"qty":0.77000000}],"checksum":3489903532,"timestamp":"2024-06-01T22:42:56.469446Z"}]}
{"channel":"book","type":"update","data":[{"symbol":"ETH/USD","bids":[],"asks":[{"price":3819.94,"qty":26.17847942}],"checksum":1352602941,"timestamp":"2024-06-01T22:42:56.481265Z"}]}
{"channel":"book","type":"update","data":[{"symbol":"ETH/USD","bids":[{"price":3819.68,"qty":26.18015667}],"asks":[],"checksum":1088843389,"timestamp":"2024-06-01T22:42:56.481360Z"}]}
{"channel":"book","type":"update","data":[{"symbol":"ETH/USD","bids":[],"asks":[{"price":3820.00,"qty":0.00000000},{"price":3820.63,"qty":5.23200000}],"checksum":2397807624,"timestamp":"2024-06-01T22:42:56.481424Z"}]}
{"channel":"book","type":"update","data":[{"symbol":"ETH/USD","bids":[{"price":3819.68,"qty":0.00000000},{"price":3818.83,"qty":4.86871675}],"asks":[],"checksum":1018298186,"timestamp":"2024-06-01T22:42:56.487042Z"}]}
{"channel":"book","type":"update","data":[{"symbol":"ETH/USD","bids":[{"price":3819.41,"qty":0.00000000},{"price":3818.63,"qty":0.01407082},{"price":3819.40,"qty":0.00907967}],"asks":[],"checksum":841251378,"timestamp":"2024-06-01T22:42:56.520414Z"}]}
{"channel":"book","type":"update","data":[{"symbol":"ETH/USD","bids":[{"price":3819.39,"qty":27.51545156}],"asks":[],"checksum":2187269166,"timestamp":"2024-06-01T22:42:56.520786Z"}]}
{"channel":"book","type":"update","data":[{"symbol":"ETH/USD","bids":[{"price":3819.71,"qty":26.93460904}],"asks":[],"checksum":3922336944,"timestamp":"2024-06-01T22:42:56.521004Z"}]}
{"channel":"book","type":"update","data":[{"symbol":"ETH/USD","bids":[],"asks":[{"price":3819.89,"qty":26.17876816}],"checksum":3859728754,"timestamp":"2024-06-01T22:42:56.539526Z"}]}
{"channel":"book","type":"update","data":[{"symbol":"ETH/USD","bids":[{"price":3819.65,"qty":26.18039358}],"asks":[],"checksum":2271672803,"timestamp":"2024-06-01T22:42:56.539643Z"}]}
{"channel":"book","type":"update","data":[{"symbol":"ETH/USD","bids":[],"asks":[{"price":3819.89,"qty":0.00000000},{"price":3820.63,"qty":5.23200000}],"checksum":4060323498,"timestamp":"2024-06-01T22:42:56.560355Z"}]}
{"channel":"book","type":"update","data":[{"symbol":"ETH/USD","bids":[{"price":3819.40,"qty":0.00000000},{"price":3818.83,"qty":4.86871675}],"asks":[],"checksum":577888810,"timestamp":"2024-06-01T22:42:56.577886Z"}]}
{"channel":"book","type":"update","data":[{"symbol":"ETH/USD","bids":[{"price":3819.71,"qty":26.16460904}],"asks":[],"checksum":936306850,"timestamp":"2024-06-01T22:42:56.588952Z"}]}
{"channel":"book","type":"update","data":[{"symbol":"ETH/USD","bids":[{"price":3819.52,"qty":0.00000000},{"price":3818.63,"qty":0.01407082}],"asks":[],"checksum":3971242199,"timestamp":"2024-06-01T22:42:56.592127Z"}]}
{"channel":"book","type":"update","data":[{"symbol":"ETH/USD","bids":[],"asks":[{"price":3819.92,"qty":26.17855930}],"checksum":1726972333,"timestamp":"2024-06-01T22:42:56.594978Z"}]}
{"channel":"book","type":"update","data":[{"symbol":"ETH/USD","bids":[{"price":3819.69,"qty":26.18009510}],"asks":[],"checksum":1744497319,"timestamp":"2024-06-01T22:42:56.595232Z"}]}
{"channel":"book","type":"update","data":[{"symbol":"ETH/USD","bids":[],"asks":[{"price":3819.92,"qty":0.00000000},{"price":3820.63,"qty":5.23200000}],"checksum":2464149889,"timestamp":"2024-06-01T22:42:56.610508Z"}]}
{"channel":"book","type":"update","data":[{"symbol":"ETH/USD","bids":[{"price":3819.69,"qty":0.00000000},{"price":3818.63,"qty":0.01407082}],"asks":[],"checksum":3971242199,"timestamp":"2024-06-01T22:42:56.610545Z"}]}
{"channel":"book","type":"update","data":[{"symbol":"ETH/USD","bids":[{"price":3819.59,"qty":26.18079706}],"asks":[],"checksum":1113819263,"timestamp":"2024-06-01T22:42:56.615095Z"}]}
{"channel":"book","type":"update","data":[{"symbol":"ETH/USD","bids":[],"asks":[{"price":3820.18,"qty":0.00000000},{"price":3820.64,"qty":3.67833330}],"checksum":3827789418,"timestamp":"2024-06-01T22:42:56.635889Z"}]}
{"channel":"book","type":"update","data":[{"symbol":"ETH/USD","bids":[{"price":3819.65,"qty":0.00000000},{"price":3818.63,"qty":0.01407082}],"asks":[],"checksum":2335097528,"timestamp":"2024-06-01T22:42:56.635943Z"}]}
{"channel":"book","type":"update","data":[{"symbol":"ETH/USD","bids":[],"asks":[{"price":3820.08,"qty":26.17746933}],"checksum":2065461541,"timestamp":"2024-06-01T22:42:56.640891Z"}]}
{"channel":"book","type":"update","data":[{"symbol":"ETH/USD","bids":[{"price":3819.62,"qty":26.18055488}],"asks":[],"checksum":490458456,"timestamp":"2024-06-01T22:42:56.648991Z"}]}
{"channel":"book","type":"update","data":[{"symbol":"ETH/USD","bids":[],"asks":[{"price":3819.85,"qty":26.17906637}],"checksum":3041374133,"timestamp":"2024-06-01T22:42:56.649022Z"}]}
{"channel":"book","type":"update","data":[{"symbol":"ETH/USD","bids":[],"asks":[{"price":3819.85,"qty":0.00000000},{"price":3820.63,"qty":5.23200000}],"checksum":490458456,"timestamp":"2024-06-01T22:42:56.653378Z"}]}
{"channel":"book","type":"update","data":[{"symbol":"ETH/USD","bids":[{"price":3819.62,"qty":0.00000000},{"price":3818.63,"qty":0.01407082}],"asks":[],"checksum":2065461541,"timestamp":"2024-06-01T22:42:56.653413Z"}]}
{"channel":"book","type":"update","data":[{"symbol":"ETH/USD","bids":[],"asks":[{"price":3819.94,"qty":0.00000000},{"price":3820.64,"qty":3.67833330}],"checksum":903988438,"timestamp":"2024-06-01T22:42:56.667462Z"}]}
{"channel":"book","type":"update","data":[{"symbol":"ETH/USD","bids":[],"asks":[{"price":3820.64,"qty":0.00000000},{"price":3820.72,"qty":0.47389664}],"checksum":1590659491,"timestamp":"2024-06-01T22:42:56.687909Z"}]}
{"channel":"book","type":"update","data":[{"symbol":"ETH/USD","bids":[{"price":3819.59,"qty":0.00000000},{"price":3818.55,"qty":6.22500000}],"asks":[],"checksum":620834040,"timestamp":"2024-06-01T22:42:56.689037Z"}]}
{"channel":"book","type":"update","data":[{"symbol":"ETH/USD","bids":[],"asks":[{"price":3820.08,"qty":0.00000000},{"price":3820.73,"qty":0.85621698}],"checksum":2203114163,"timestamp":"2024-06-01T22:42:56.689046Z"}]}
{"channel":"book","type":"update","data":[{"symbol":"ETH/USD","bids":[],"asks":[{"price":3820.60,"qty":0.00000000},{"price":3820.74,"qty":86.84418536}],"checksum":2444785036,"timestamp":"2024-06-01T22:42:56.691903Z"}]}
{"channel":"book","type":"update","data":[{"symbol":"ETH/USD","bids":[],"asks":[{"price":3820.30,"qty":3.30000000}],"checksum":1602573855,"timestamp":"2024-06-01T22:42:56.692068Z"}]}
{"channel":"book","type":"update","data":[{"symbol":"ETH/USD","bids":[{"price":3819.57,"qty":0.77000000}],"asks":[],"checksum":2331644867,"timestamp":"2024-06-01T22:42:56.707915Z"}]}
{"channel":"book","type":"update","data":[{"symbol":"ETH/USD","bids":[{"price":3819.71,"qty":26.58715365}],"asks":[],"checksum":3690372494,"timestamp":"2024-06-01T22:42:56.708828Z"}]}
{"channel":"book","type":"update","data":[{"symbol":"ETH/USD","bids":[],"asks":[{"price":3820.40,"qty":0.00000000},{"price":3820.74,"qty":86.84418536},{"price":3820.27,"qty":0.77000000}],"checksum":606881978,"timestamp":"2024-06-01T22:42:56.711113Z"}]}
{"channel":"book","type":"update","data":[{"symbol":"ETH/USD","bids":[],"asks":[{"price":3820.27,"qty":1.54000000}],"checksum":1437561710,"timestamp":"2024-06-01T22:42:56.711219Z"}]}
{"channel":"book","type":"update","data":[{"symbol":"ETH/USD","bids":[{"price":3819.71,"qty":26.16460904}],"asks":[],"checksum":77856035,"timestamp":"2024-06-01T22:42:56.722548Z"}]}
{"channel":"book","type":"update","data":[{"symbol":"ETH/USD","bids":[{"price":3819.22,"qty":0.00000000},{"price":3818.55,"qty":6.22500000}],"asks":[],"checksum":2178161871,"timestamp":"2024-06-01T22:42:56.736000Z"}]}
{"channel":"book","type":"update","data":[{"symbol":"ETH/USD","bids":[{"price":3819.54,"qty":26.18116127}],"asks":[],"checksum":3823785739,"timestamp":"2024-06-01T22:42:56.742079Z"}]}
{"channel":"book","type":"update","data":[{"symbol":"ETH/USD","bids":[],"asks":[{"price":3819.76,"qty":26.17971701}],"checksum":4294509703,"timestamp":"2024-06-01T22:42:56.742103Z"}]}
{"channel":"book","type":"update","data":[{"symbol":"ETH/USD","bids":[],"asks":[{"price":3820.27,"qty":0.77000000}],"checksum":1162332930,"timestamp":"2024-06-01T22:42:56.755215Z"}]}
{"channel":"book","type":"update","data":[{"symbol":"ETH/USD","bids":[],"asks":[{"price":3820.48,"qty":3.67833330}],"checksum":3422200572,"timestamp":"2024-06-01T22:42:56.811979Z"}]}
{"channel":"book","type":"update","data":[{"symbol":"ETH/USD","bids":[],"asks":[{"price":3819.76,"qty":0.00000000},{"price":3820.73,"qty":0.85621698}],"checksum":442598642,"timestamp":"2024-06-01T22:42:56.853908Z"}]}
{"channel":"book","type":"update","data":[{"symbol":"ETH/USD","bids":[],"asks":[{"price":3819.78,"qty":26.17955468}],"checksum":1972774949,"timestamp":"2024-06-01T22:42:56.859871Z"}]}
{"channel":"book","type":"update","data":[{"symbol":"ETH/USD","bids":[{"price":3819.52,"qty":26.18125948}],"asks":[],"checksum":3569893878,"timestamp":"2024-06-01T22:42:56.859917Z"}]}
{"channel":"book","type":"update","data":[{"symbol":"ETH/USD","bids":[{"price":3819.54,"qty":0.00000000},{"price":3818.63,"qty":0.01407082}],"asks":[],"checksum":958667292,"timestamp":"2024-06-01T22:42:56.972255Z"}]}
{"channel":"book","type":"update","data":[{"symbol":"ETH/USD","bids":[],"asks":[{"price":3820.26,"qty":0.47389664}],"checksum":3395242654,"timestamp":"2024-06-01T22:42:56.975660Z"}]}
{"channel":"book","type":"update","data":[{"symbol":"ETH/USD","bids":[],"asks":[{"price":3819.98,"qty":26.17817492}],"checksum":2078846329,"timestamp":"2024-06-01T22:42:56.977418Z"}]}
{"channel":"book","type":"update","data":[{"symbol":"ETH/USD","bids":[{"price":3819.55,"qty":26.18107224}],"asks":[],"checksum":3496757823,"timestamp":"2024-06-01T22:42:56.977487Z"}]}
{"channel":"book","type":"update","data":[{"symbol":"ETH/USD","bids":[{"price":3819.05,"qty":26.18450487}],"asks":[],"checksum":28006877,"timestamp":"2024-06-01T22:42:56.977508Z"}]}
{"channel":"book","type":"update","data":[{"symbol":"ETH/USD","bids":[],"asks":[{"price":3820.34,"qty":28.27169868}],"checksum":663107685,"timestamp":"2024-06-01T22:42:56.977524Z"}]}
{"channel":"book","type":"update","data":[{"symbol":"ETH/USD","bids":[],"asks":[{"price":3819.83,"qty":26.17918942}],"checksum":1039105170,"timestamp":"2024-06-01T22:42:56.977640Z"}]}
{"channel":"book","type":"update","data":[{"symbol":"ETH/USD","bids":[],"asks":[{"price":3820.26,"qty":0.49142102}],"checksum":618559904,"timestamp":"2024-06-01T22:42:57.028942Z"}]}
{"channel":"book","type":"update","data":[{"symbol":"ETH/USD","bids":[{"price":3819.55,"qty":0.00000000},{"price":3818.83,"qty":4.86871675}],"asks":[],"checksum":957096376,"timestamp":"2024-06-01T22:42:57.047040Z"}]}
{"channel":"book","type":"update","data":[{"symbol":"ETH/USD","bids":[{"price":3819.56,"qty":26.18100155}],"asks":[],"checksum":1390367475,"timestamp":"2024-06-01T22:42:57.051307Z"}]}
{"channel":"book","type":"update","data":[{"symbol":"ETH/USD","bids":[],"asks":[{"price":3819.78,"qty":0.00000000},{"price":3820.34,"qty":28.27169868}],"checksum":2565191064,"timestamp":"2024-06-01T22:42:57.060683Z"}]}
{"channel":"book","type":"update","data":[{"symbol":"ETH/USD","bids":[],"asks":[{"price":3819.80,"qty":26.17941591}],"checksum":1650292562,"timestamp":"2024-06-01T22:42:57.064941Z"}]}
{"channel":"book","type":"update","data":[{"symbol":"ETH/USD","bids":[],"asks":[{"price":3819.80,"qty":0.00000000},{"price":3820.34,"qty":28.27169868}],"checksum":2565191064,"timestamp":"2024-06-01T22:42:57.077632Z"}]}
{"channel":"book","type":"update","data":[{"symbol":"ETH/USD","bids":[{"price":3819.56,"qty":0.00000000},{"price":3818.83,"qty":4.86871675}],"asks":[],"checksum":3106521161,"timestamp":"2024-06-01T22:42:57.086845Z"}]}
{"channel":"book","type":"update","data":[{"symbol":"ETH/USD","bids":[],"asks":[{"price":3819.89,"qty":26.17880562}],"checksum":2789852901,"timestamp":"2024-06-01T22:42:57.091212Z"}]}
{"channel":"book","type":"update","data":[{"symbol":"ETH/USD","bids":[{"price":3819.60,"qty":26.18071353}],"asks":[],"checksum":3601045832,"timestamp":"2024-06-01T22:42:57.125479Z"}]}
{"channel":"book","type":"update","data":[{"symbol":"ETH/USD","bids":[{"price":3819.60,"qty":0.00000000},{"price":3818.83,"qty":4.86871675}],"asks":[],"checksum":2789852901,"timestamp":"2024-06-01T22:42:57.191641Z"}]}
{"channel":"book","type":"update","data":[{"symbol":"ETH/USD","bids":[],"asks":[{"price":3819.83,"qty":0.00000000},{"price":3820.34,"qty":28.27169868}],"checksum":980884398,"timestamp":"2024-06-01T22:42:57.191748Z"}]}
{"channel":"book","type":"update","data":[{"symbol":"ETH/USD","bids":[],"asks":[{"price":3819.80,"qty":26.17939235}],"checksum":1962113969,"timestamp":"2024-06-01T22:42:57.196520Z"}]}
{"channel":"book","type":"update","data":[{"symbol":"ETH/USD","bids":[{"price":3819.57,"qty":26.95094132}],"asks":[],"checksum":1860814799,"timestamp":"2024-06-01T22:42:57.196543Z"}]}
{"channel":"book","type":"update","data":[{"symbol":"ETH/USD","bids":[{"price":3819.57,"qty":0.77000000}],"asks":[],"checksum":1962113969,"timestamp":"2024-06-01T22:42:57.204198Z"}]}
{"channel":"book","type":"update","data":[{"symbol":"ETH/USD","bids":[],"asks":[{"price":3819.72,"qty":0.78588958}],"checksum":3765189023,"timestamp":"2024-06-01T22:42:57.267525Z"}]}
{"channel":"book","type":"update","data":[{"symbol":"ETH/USD","bids":[],"asks":[{"price":3819.89,"qty":0.00000000},{"price":3820.34,"qty":28.27169868}],"checksum":4278992691,"timestamp":"2024-06-01T22:42:57.270933Z"}]}
{"channel":"book","type":"update","data":[{"symbol":"ETH/USD","bids":[],"asks":[{"price":3819.74,"qty":26.23082547}],"checksum":4062055611,"timestamp":"2024-06-01T22:42:57.277709Z"}]}
{"channel":"book","type":"update","data":[{"symbol":"ETH/USD","bids":[{"price":3819.28,"qty":26.18290827}],"asks":[],"checksum":2959004285,"timestamp":"2024-06-01T22:42:57.277810Z"}]}
{"channel":"book","type":"update","data":[{"symbol":"ETH/USD","bids":[{"price":3819.57,"qty":0.00000000},{"price":3818.83,"qty":4.86871675}],"asks":[],"checksum":3333091827,"timestamp":"2024-06-01T22:42:57.279000Z"}]}
{"channel":"book","type":"update","data":[{"symbol":"ETH/USD","bids":[],"asks":[{"price":3820.34,"qty":2.09600000}],"checksum":475221924,"timestamp":"2024-06-01T22:42:57.280128Z"}]}
{"channel":"book","type":"update","data":[{"symbol":"ETH/USD","bids":[],"asks":[{"price":3819.80,"qty":0.00000000},{"price":3820.48,"qty":3.67833330}],"checksum":3850833324,"timestamp":"2024-06-01T22:42:57.280137Z"}]}
{"channel":"book","type":"update","data":[{"symbol":"ETH/USD","bids":[{"price":3819.52,"qty":0.00000000},{"price":3818.63,"qty":0.01407082}],"asks":[],"checksum":3455893777,"timestamp":"2024-06-01T22:42:57.280145Z"}]}
{"channel":"book","type":"update","data":[{"symbol":"ETH/USD","bids":[],"asks":[{"price":3820.27,"qty":0.00000000},{"price":3820.62,"qty":0.23564588},{"price":3820.15,"qty":0.77000000}],"checksum":2280873399,"timestamp":"2024-06-01T22:42:57.285558Z"}]}
{"channel":"book","type":"update","data":[{"symbol":"ETH/USD","bids":[],"asks":[{"price":3820.48,"qty":0.00000000},{"price":3820.62,"qty":0.23564588}],"checksum":3202421540,"timestamp":"2024-06-01T22:42:57.287157Z"}]}
