{"channel":"book","type":"snapshot","data":[{"symbol":"ETH/JPY","bids":[{"price":599941,"qty":0.25315745},{"price":599940,"qty":0.00317723},{"price":599199,"qty":0.14289800},{"price":599198,"qty":5.45568227},{"price":599194,"qty":4.10464164},{"price":598926,"qty":7.38926496},{"price":598685,"qty":21.38438245},{"price":598460,"qty":20.30632296},{"price":597987,"qty":21.38218141},{"price":593219,"qty":25.42309572}],"asks":[{"price":602186,"qty":0.17926959},{"price":602651,"qty":0.00737190},{"price":602652,"qty":0.00368349},{"price":602943,"qty":0.22990165},{"price":602945,"qty":3.89168978},{"price":602946,"qty":4.10464164},{"price":603342,"qty":21.46517125},{"price":604064,"qty":7.38926496},{"price":604067,"qty":21.46749857},{"price":604229,"qty":20.30632296}],"checksum":2092420985}]}
{"channel":"book","type":"update","data":[{"symbol":"ETH/JPY","bids":[],"asks":[{"price":604064,"qty":0.00000000},{"price":607723,"qty":15.24971184}],"checksum":3813462789,"timestamp":"2024-06-01T22:42:37.707798Z"}]}
{"channel":"book","type":"update","data":[{"symbol":"ETH/JPY","bids":[],"asks":[{"price":607723,"qty":0.00000000},{"price":607729,"qty":10.17338388}],"checksum":2008902197,"timestamp":"2024-06-01T22:42:37.708167Z"}]}
{"channel":"book","type":"update","data":[{"symbol":"ETH/JPY","bids":[],"asks":[{"price":604063,"qty":7.38926496}],"checksum":255272654,"timestamp":"2024-06-01T22:42:37.710526Z"}]}
{"channel":"book","type":"update","data":[{"symbol":"ETH/JPY","bids":[{"price":599199,"qty":0.00000000},{"price":593218,"qty":10.17338388}],"asks":[],"checksum":357948983,"timestamp":"2024-06-01T22:42:37.756849Z"}]}
{"channel":"book","type":"update","data":[{"symbol":"ETH/JPY","bids":[{"price":599199,"qty":0.01186961}],"asks":[],"checksum":1363180610,"timestamp":"2024-06-01T22:42:37.756989Z"}]}
{"channel":"book","type":"update","data":[{"symbol":"ETH/JPY","bids":[],"asks":[{"price":602652,"qty":0.00000000},{"price":607722,"qty":15.24971184}],"checksum":1708759824,"timestamp":"2024-06-01T22:42:37.879159Z"}]}
{"channel":"book","type":"update","data":[{"symbol":"ETH/JPY","bids":[],"asks":[{"price":602669,"qty":0.00367399}],"checksum":1474055580,"timestamp":"2024-06-01T22:42:37.944584Z"}]}
{"channel":"book","type":"update","data":[{"symbol":"ETH/JPY","bids":[],"asks":[{"price":603342,"qty":0.00000000},{"price":607722,"qty":15.24971184}],"checksum":1549920369,"timestamp":"2024-06-01T22:42:41.113506Z"}]}
{"channel":"book","type":"update","data":[{"symbol":"ETH/JPY","bids":[],"asks":[{"price":603343,"qty":21.46430118}],"checksum":1992121020,"timestamp":"2024-06-01T22:42:41.153919Z"}]}
{"channel":"book","type":"update","data":[{"symbol":"ETH/JPY","bids":[{"price":599940,"qty":0.00000000},{"price":593218,"qty":10.17338388}],"asks":[],"checksum":2172717232,"timestamp":"2024-06-01T22:42:41.925900Z"}]}
{"channel":"book","type":"update","data":[{"symbol":"ETH/JPY","bids":[{"price":599785,"qty":0.00316949}],"asks":[],"checksum":1290509198,"timestamp":"2024-06-01T22:42:42.015618Z"}]}
{"channel":"book","type":"update","data":[{"symbol":"ETH/JPY","bids":[{"price":593219,"qty":10.17338388}],"asks":[],"checksum":1800392919,"timestamp":"2024-06-01T22:42:43.592838Z"}]}
{"channel":"book","type":"update","data":[{"symbol":"ETH/JPY","bids":[{"price":593219,"qty":0.00000000},{"price":593218,"qty":10.17338388}],"asks":[],"checksum":2864779031,"timestamp":"2024-06-01T22:42:43.592967Z"}]}
{"channel":"book","type":"update","data":[{"symbol":"ETH/JPY","bids":[{"price":593220,"qty":15.24971184}],"asks":[],"checksum":2974627578,"timestamp":"2024-06-01T22:42:43.595485Z"}]}
{"channel":"book","type":"update","data":[{"symbol":"ETH/JPY","bids":[{"price":593220,"qty":25.42309572}],"asks":[],"checksum":1077442555,"timestamp":"2024-06-01T22:42:43.595691Z"}]}
{"channel":"book","type":"update","data":[{"symbol":"ETH/JPY","bids":[{"price":598685,"qty":0.00000000},{"price":593218,"qty":10.17338388}],"asks":[],"checksum":120594,"timestamp":"2024-06-01T22:42:44.875821Z"}]}
{"channel":"book","type":"update","data":[{"symbol":"ETH/JPY","bids":[{"price":598713,"qty":21.38574954}],"asks":[],"checksum":2008946358,"timestamp":"2024-06-01T22:42:44.916195Z"}]}
{"channel":"book","type":"update","data":[{"symbol":"ETH/JPY","bids":[{"price":593220,"qty":15.24971184}],"asks":[],"checksum":2261473207,"timestamp":"2024-06-01T22:42:49.479377Z"}]}
{"channel":"book","type":"update","data":[{"symbol":"ETH/JPY","bids":[{"price":593220,"qty":0.00000000},{"price":593218,"qty":10.17338388}],"asks":[],"checksum":2638704218,"timestamp":"2024-06-01T22:42:49.479413Z"}]}
{"channel":"book","type":"update","data":[{"symbol":"ETH/JPY","bids":[],"asks":[{"price":604063,"qty":0.00000000},{"price":607729,"qty":10.17338388}],"checksum":1830630353,"timestamp":"2024-06-01T22:42:49.479421Z"}]}
{"channel":"book","type":"update","data":[{"symbol":"ETH/JPY","bids":[],"asks":[{"price":607721,"qty":15.24971184}],"checksum":2533253704,"timestamp":"2024-06-01T22:42:49.482028Z"}]}
{"channel":"book","type":"update","data":[{"symbol":"ETH/JPY","bids":[{"price":593219,"qty":10.17338388}],"asks":[],"checksum":1467006344,"timestamp":"2024-06-01T22:42:49.482212Z"}]}
{"channel":"book","type":"update","data":[{"symbol":"ETH/JPY","bids":[{"price":593219,"qty":25.42309572}],"asks":[],"checksum":1893005009,"timestamp":"2024-06-01T22:42:49.482335Z"}]}
{"channel":"book","type":"update","data":[{"symbol":"ETH/JPY","bids":[],"asks":[{"price":604062,"qty":7.38926496}],"checksum":2870232431,"timestamp":"2024-06-01T22:42:49.482351Z"}]}
{"channel":"book","type":"update","data":[{"symbol":"ETH/JPY","bids":[{"price":593219,"qty":15.24971184}],"asks":[],"checksum":1516307566,"timestamp":"2024-06-01T22:42:55.364000Z"}]}
{"channel":"book","type":"update","data":[{"symbol":"ETH/JPY","bids":[{"price":593219,"qty":0.00000000},{"price":593218,"qty":10.17338388}],"asks":[],"checksum":1295962614,"timestamp":"2024-06-01T22:42:55.364199Z"}]}
{"channel":"book","type":"update","data":[{"symbol":"ETH/JPY","bids":[],"asks":[{"price":604062,"qty":0.00000000},{"price":607729,"qty":10.17338388}],"checksum":1830630353,"timestamp":"2024-06-01T22:42:55.364213Z"}]}
{"channel":"book","type":"update","data":[{"symbol":"ETH/JPY","bids":[],"asks":[{"price":607720,"qty":15.24971184}],"checksum":2714669248,"timestamp":"2024-06-01T22:42:55.366771Z"}]}
{"channel":"book","type":"update","data":[{"symbol":"ETH/JPY","bids":[{"price":593220,"qty":10.17338388}],"asks":[],"checksum":1821614965,"timestamp":"2024-06-01T22:42:55.366820Z"}]}
{"channel":"book","type":"update","data":[{"symbol":"ETH/JPY","bids":[{"price":593220,"qty":25.42309572}],"asks":[],"checksum":1261955116,"timestamp":"2024-06-01T22:42:55.366840Z"}]}
{"channel":"book","type":"update","data":[{"symbol":"ETH/JPY","bids":[],"asks":[{"price":604061,"qty":7.38926496}],"checksum":205287343,"timestamp":"2024-06-01T22:42:55.367153Z"}]}
{"channel":"book","type":"update","data":[{"symbol":"ETH/JPY","bids":[],"asks":[{"price":603343,"qty":0.00000000},{"price":607720,"qty":15.24971184}],"checksum":1196512384,"timestamp":"2024-06-01T22:43:00.159002Z"}]}
{"channel":"book","type":"update","data":[{"symbol":"ETH/JPY","bids":[],"asks":[{"price":603350,"qty":21.46396016}],"checksum":1834853416,"timestamp":"2024-06-01T22:43:00.199184Z"}]}
{"channel":"book","type":"update","data":[{"symbol":"ETH/JPY","bids":[{"price":593220,"qty":15.24971184}],"asks":[],"checksum":2619925801,"timestamp":"2024-06-01T22:43:01.248605Z"}]}
{"channel":"book","type":"update","data":[{"symbol":"ETH/JPY","bids":[{"price":593220,"qty":0.00000000},{"price":593218,"qty":10.17338388}],"asks":[],"checksum":2275728580,"timestamp":"2024-06-01T22:43:01.248784Z"}]}
{"channel":"book","type":"update","data":[{"symbol":"ETH/JPY","bids":[],"asks":[{"price":604061,"qty":0.00000000},{"price":607729,"qty":10.17338388}],"checksum":513819801,"timestamp":"2024-06-01T22:43:01.249042Z"}]}
{"channel":"book","type":"update","data":[{"symbol":"ETH/JPY","bids":[],"asks":[{"price":607719,"qty":15.24971184}],"checksum":2033765728,"timestamp":"2024-06-01T22:43:01.251323Z"}]}
{"channel":"book","type":"update","data":[{"symbol":"ETH/JPY","bids":[{"price":593221,"qty":15.24971184}],"asks":[],"checksum":2738498381,"timestamp":"2024-06-01T22:43:01.251374Z"}]}
{"channel":"book","type":"update","data":[{"symbol":"ETH/JPY","bids":[{"price":593221,"qty":25.42309572}],"asks":[],"checksum":1380936268,"timestamp":"2024-06-01T22:43:01.251422Z"}]}
{"channel":"book","type":"update","data":[{"symbol":"ETH/JPY","bids":[],"asks":[{"price":604060,"qty":7.38926496}],"checksum":2091566148,"timestamp":"2024-06-01T22:43:01.251893Z"}]}
{"channel":"book","type":"update","data":[{"symbol":"ETH/JPY","bids":[{"price":598713,"qty":0.00000000},{"price":593218,"qty":10.17338388}],"asks":[],"checksum":2753020257,"timestamp":"2024-06-01T22:43:03.805604Z"}]}
{"channel":"book","type":"update","data":[{"symbol":"ETH/JPY","bids":[{"price":598728,"qty":21.38900061}],"asks":[],"checksum":3465524118,"timestamp":"2024-06-01T22:43:03.845908Z"}]}
{"channel":"book","type":"update","data":[{"symbol":"ETH/JPY","bids":[{"price":599199,"qty":0.00000000},{"price":593218,"qty":10.17338388}],"asks":[],"checksum":1116180931,"timestamp":"2024-06-01T22:43:04.598259Z"}]}
{"channel":"book","type":"update","data":[{"symbol":"ETH/JPY","bids":[{"price":599786,"qty":0.01186907}],"asks":[],"checksum":1094409681,"timestamp":"2024-06-01T22:43:04.598430Z"}]}
{"channel":"book","type":"update","data":[{"symbol":"ETH/JPY","bids":[],"asks":[{"price":604060,"qty":0.00000000},{"price":607729,"qty":10.17338388}],"checksum":138836512,"timestamp":"2024-06-01T22:43:07.133367Z"}]}
{"channel":"book","type":"update","data":[{"symbol":"ETH/JPY","bids":[{"price":593221,"qty":15.24971184}],"asks":[],"checksum":4180884257,"timestamp":"2024-06-01T22:43:07.133376Z"}]}
{"channel":"book","type":"update","data":[{"symbol":"ETH/JPY","bids":[{"price":593221,"qty":0.00000000},{"price":593218,"qty":10.17338388}],"asks":[],"checksum":590470412,"timestamp":"2024-06-01T22:43:07.133441Z"}]}
{"channel":"book","type":"update","data":[{"symbol":"ETH/JPY","bids":[{"price":593222,"qty":15.24971184}],"asks":[],"checksum":1624333600,"timestamp":"2024-06-01T22:43:07.135987Z"}]}
{"channel":"book","type":"update","data":[{"symbol":"ETH/JPY","bids":[{"price":593222,"qty":25.42309572}],"asks":[],"checksum":2443451425,"timestamp":"2024-06-01T22:43:07.136071Z"}]}
{"channel":"book","type":"update","data":[{"symbol":"ETH/JPY","bids":[],"asks":[{"price":604059,"qty":7.38926496}],"checksum":2256067228,"timestamp":"2024-06-01T22:43:07.136122Z"}]}
{"channel":"book","type":"update","data":[{"symbol":"ETH/JPY","bids":[{"price":599786,"qty":0.02373807}],"asks":[],"checksum":3817966122,"timestamp":"2024-06-01T22:43:07.153225Z"}]}
{"channel":"book","type":"update","data":[{"symbol":"ETH/JPY","bids":[{"price":599786,"qty":0.01186900}],"asks":[],"checksum":3659595620,"timestamp":"2024-06-01T22:43:07.153285Z"}]}
{"channel":"book","type":"update","data":[{"symbol":"ETH/JPY","bids":[{"price":599786,"qty":0.00000000},{"price":593218,"qty":10.17338388}],"asks":[],"checksum":1848088873,"timestamp":"2024-06-01T22:43:07.190233Z"}]}
{"channel":"book","type":"update","data":[{"symbol":"ETH/JPY","bids":[{"price":599786,"qty":0.01186880}],"asks":[],"checksum":389114414,"timestamp":"2024-06-01T22:43:07.190270Z"}]}
{"channel":"book","type":"update","data":[{"symbol":"ETH/JPY","bids":[{"price":599786,"qty":0.02373652}],"asks":[],"checksum":3182830390,"timestamp":"2024-06-01T22:43:07.204020Z"}]}
{"channel":"book","type":"update","data":[{"symbol":"ETH/JPY","bids":[{"price":599786,"qty":0.01186772}],"asks":[],"checksum":1837001415,"timestamp":"2024-06-01T22:43:07.204049Z"}]}
{"channel":"book","type":"update","data":[{"symbol":"ETH/JPY","bids":[{"price":599786,"qty":0.00000000},{"price":593218,"qty":10.17338388}],"asks":[],"checksum":1848088873,"timestamp":"2024-06-01T22:43:07.232139Z"}]}
{"channel":"book","type":"update","data":[{"symbol":"ETH/JPY","bids":[{"price":599786,"qty":0.01186769}],"asks":[],"checksum":3479731697,"timestamp":"2024-06-01T22:43:07.232230Z"}]}
{"channel":"book","type":"update","data":[{"symbol":"ETH/JPY","bids":[],"asks":[{"price":604059,"qty":0.00000000},{"price":607729,"qty":10.17338388}],"checksum":3635723084,"timestamp":"2024-06-01T22:43:07.559000Z"}]}
{"channel":"book","type":"update","data":[{"symbol":"ETH/JPY","bids":[{"price":593222,"qty":15.24971184}],"asks":[],"checksum":700578381,"timestamp":"2024-06-01T22:43:07.559228Z"}]}
{"channel":"book","type":"update","data":[{"symbol":"ETH/JPY","bids":[{"price":593222,"qty":0.00000000},{"price":593218,"qty":10.17338388}],"asks":[],"checksum":1780578913,"timestamp":"2024-06-01T22:43:07.559289Z"}]}
{"channel":"book","type":"update","data":[{"symbol":"ETH/JPY","bids":[],"asks":[{"price":604066,"qty":7.38926496}],"checksum":2950354619,"timestamp":"2024-06-01T22:43:07.561842Z"}]}
{"channel":"book","type":"update","data":[{"symbol":"ETH/JPY","bids":[{"price":593219,"qty":15.24971184}],"asks":[],"checksum":3095724835,"timestamp":"2024-06-01T22:43:07.562020Z"}]}
{"channel":"book","type":"update","data":[{"symbol":"ETH/JPY","bids":[{"price":593219,"qty":25.42309572}],"asks":[],"checksum":1240482338,"timestamp":"2024-06-01T22:43:07.562033Z"}]}
