{"channel":"book","type":"snapshot","data":[{"symbol":"ETH/BTC","bids":[{"price":0.05640,"qty":10.58969414},{"price":0.05639,"qty":20.74677584},{"price":0.05638,"qty":19.89863089},{"price":0.05637,"qty":3.14564260},{"price":0.05636,"qty":1.93320637},{"price":0.05635,"qty":13.09916324},{"price":0.05634,"qty":16.62986199},{"price":0.05633,"qty":8.43627606},{"price":0.05632,"qty":48.22576364},{"price":0.05631,"qty":4.66320898}],"asks":[{"price":0.05641,"qty":3.44655138},{"price":0.05642,"qty":7.77160463},{"price":0.05643,"qty":14.88229909},{"price":0.05644,"qty":21.61296132},{"price":0.05645,"qty":2.50167899},{"price":0.05646,"qty":1.88263959},{"price":0.05647,"qty":21.68932930},{"price":0.05648,"qty":16.07172915},{"price":0.05649,"qty":8.25475460},{"price":0.05650,"qty":16.78183198}],"checksum":1520758397}]}
{"channel":"book","type":"update","data":[{"symbol":"ETH/BTC","bids":[],"asks":[{"price":0.05647,"qty":21.68608697}],"checksum":1793341681,"timestamp":"2024-06-01T22:42:34.027688Z"}]}
{"channel":"book","type":"update","data":[{"symbol":"ETH/BTC","bids":[],"asks":[{"price":0.05647,"qty":21.68932938}],"checksum":3484919112,"timestamp":"2024-06-01T22:42:34.125627Z"}]}
{"channel":"book","type":"update","data":[{"symbol":"ETH/BTC","bids":[],"asks":[{"price":0.05647,"qty":14.39438535}],"checksum":2457017112,"timestamp":"2024-06-01T22:42:34.211723Z"}]}
{"channel":"book","type":"update","data":[{"symbol":"ETH/BTC","bids":[],"asks":[{"price":0.05646,"qty":9.17791142}],"checksum":2723649828,"timestamp":"2024-06-01T22:42:34.250997Z"}]}
{"channel":"book","type":"update","data":[{"symbol":"ETH/BTC","bids":[],"asks":[{"price":0.05648,"qty":15.93102915}],"checksum":3911284048,"timestamp":"2024-06-01T22:42:34.909396Z"}]}
{"channel":"book","type":"update","data":[{"symbol":"ETH/BTC","bids":[{"price":0.05631,"qty":4.51340898}],"asks":[],"checksum":759806365,"timestamp":"2024-06-01T22:42:34.939166Z"}]}
{"channel":"book","type":"update","data":[{"symbol":"ETH/BTC","bids":[],"asks":[{"price":0.05649,"qty":7.53545460}],"checksum":974514576,"timestamp":"2024-06-01T22:42:34.940204Z"}]}
{"channel":"book","type":"update","data":[{"symbol":"ETH/BTC","bids":[],"asks":[{"price":0.05649,"qty":7.38055460}],"checksum":246710302,"timestamp":"2024-06-01T22:42:34.957918Z"}]}
{"channel":"book","type":"update","data":[{"symbol":"ETH/BTC","bids":[],"asks":[{"price":0.05647,"qty":14.31708535}],"checksum":3788518597,"timestamp":"2024-06-01T22:42:34.963755Z"}]}
{"channel":"book","type":"update","data":[{"symbol":"ETH/BTC","bids":[{"price":0.05633,"qty":8.36097606}],"asks":[],"checksum":3358986833,"timestamp":"2024-06-01T22:42:34.970297Z"}]}
{"channel":"book","type":"update","data":[{"symbol":"ETH/BTC","bids":[],"asks":[{"price":0.05649,"qty":7.51645460}],"checksum":942184861,"timestamp":"2024-06-01T22:42:34.978789Z"}]}
{"channel":"book","type":"update","data":[{"symbol":"ETH/BTC","bids":[{"price":0.05631,"qty":4.64830898}],"asks":[],"checksum":1014537482,"timestamp":"2024-06-01T22:42:34.978823Z"}]}
{"channel":"book","type":"update","data":[{"symbol":"ETH/BTC","bids":[{"price":0.05633,"qty":7.80776000}],"asks":[],"checksum":577506296,"timestamp":"2024-06-01T22:42:34.982562Z"}]}
{"channel":"book","type":"update","data":[{"symbol":"ETH/BTC","bids":[],"asks":[{"price":0.05650,"qty":17.52183198}],"checksum":741560317,"timestamp":"2024-06-01T22:42:35.015254Z"}]}
{"channel":"book","type":"update","data":[{"symbol":"ETH/BTC","bids":[],"asks":[{"price":0.05650,"qty":17.66643198}],"checksum":2219210345,"timestamp":"2024-06-01T22:42:35.016658Z"}]}
{"channel":"book","type":"update","data":[{"symbol":"ETH/BTC","bids":[{"price":0.05632,"qty":48.37156364}],"asks":[],"checksum":3702145929,"timestamp":"2024-06-01T22:42:35.033733Z"}]}
{"channel":"book","type":"update","data":[{"symbol":"ETH/BTC","bids":[],"asks":[{"price":0.05649,"qty":7.38055460}],"checksum":750045253,"timestamp":"2024-06-01T22:42:36.301149Z"}]}
{"channel":"book","type":"update","data":[{"symbol":"ETH/BTC","bids":[{"price":0.05631,"qty":4.51340898}],"asks":[],"checksum":686083282,"timestamp":"2024-06-01T22:42:36.301181Z"}]}
{"channel":"book","type":"update","data":[{"symbol":"ETH/BTC","bids":[],"asks":[{"price":0.05650,"qty":16.92643198}],"checksum":216348244,"timestamp":"2024-06-01T22:42:36.333678Z"}]}
{"channel":"book","type":"update","data":[{"symbol":"ETH/BTC","bids":[{"price":0.05632,"qty":48.22576364}],"asks":[],"checksum":1409876916,"timestamp":"2024-06-01T22:42:36.341589Z"}]}
{"channel":"book","type":"update","data":[{"symbol":"ETH/BTC","bids":[],"asks":[{"price":0.05650,"qty":16.78183198}],"checksum":3592586403,"timestamp":"2024-06-01T22:42:36.360257Z"}]}
{"channel":"book","type":"update","data":[{"symbol":"ETH/BTC","bids":[{"price":0.05631,"qty":4.65790898}],"asks":[],"checksum":3487769076,"timestamp":"2024-06-01T22:42:37.484006Z"}]}
{"channel":"book","type":"update","data":[{"symbol":"ETH/BTC","bids":[],"asks":[{"price":0.05649,"qty":7.52865460}],"checksum":115823400,"timestamp":"2024-06-01T22:42:37.487360Z"}]}
{"channel":"book","type":"update","data":[{"symbol":"ETH/BTC","bids":[],"asks":[{"price":0.05650,"qty":17.52363198}],"checksum":1603966300,"timestamp":"2024-06-01T22:42:37.502362Z"}]}
{"channel":"book","type":"update","data":[{"symbol":"ETH/BTC","bids":[{"price":0.05632,"qty":48.38426364}],"asks":[],"checksum":2756532035,"timestamp":"2024-06-01T22:42:37.515271Z"}]}
{"channel":"book","type":"update","data":[{"symbol":"ETH/BTC","bids":[],"asks":[{"price":0.05650,"qty":17.67303198}],"checksum":2901882702,"timestamp":"2024-06-01T22:42:37.530892Z"}]}
{"channel":"book","type":"update","data":[{"symbol":"ETH/BTC","bids":[],"asks":[{"price":0.05641,"qty":0.27154164}],"checksum":1063778187,"timestamp":"2024-06-01T22:42:37.770257Z"}]}
{"channel":"book","type":"update","data":[{"symbol":"ETH/BTC","bids":[],"asks":[{"price":0.05642,"qty":10.54973948}],"checksum":2594253136,"timestamp":"2024-06-01T22:42:38.027072Z"}]}
{"channel":"book","type":"update","data":[{"symbol":"ETH/BTC","bids":[],"asks":[{"price":0.05648,"qty":16.00602915}],"checksum":4137961297,"timestamp":"2024-06-01T22:42:38.091781Z"}]}
{"channel":"book","type":"update","data":[{"symbol":"ETH/BTC","bids":[{"price":0.05634,"qty":16.71046199}],"asks":[],"checksum":3100903423,"timestamp":"2024-06-01T22:42:38.091805Z"}]}
{"channel":"book","type":"update","data":[{"symbol":"ETH/BTC","bids":[],"asks":[{"price":0.05642,"qty":7.77160463}],"checksum":487774500,"timestamp":"2024-06-01T22:42:38.281635Z"}]}
{"channel":"book","type":"update","data":[{"symbol":"ETH/BTC","bids":[],"asks":[{"price":0.05641,"qty":3.04967627}],"checksum":1973721201,"timestamp":"2024-06-01T22:42:38.539841Z"}]}
{"channel":"book","type":"update","data":[{"symbol":"ETH/BTC","bids":[],"asks":[{"price":0.05641,"qty":0.27154164}],"checksum":487774500,"timestamp":"2024-06-01T22:42:39.080913Z"}]}
{"channel":"book","type":"update","data":[{"symbol":"ETH/BTC","bids":[],"asks":[{"price":0.05642,"qty":10.20247312}],"checksum":3263939242,"timestamp":"2024-06-01T22:42:39.337771Z"}]}
{"channel":"book","type":"update","data":[{"symbol":"ETH/BTC","bids":[],"asks":[{"price":0.05642,"qty":7.77160463}],"checksum":487774500,"timestamp":"2024-06-01T22:42:39.606739Z"}]}
{"channel":"book","type":"update","data":[{"symbol":"ETH/BTC","bids":[],"asks":[{"price":0.05641,"qty":2.70240974}],"checksum":3721257836,"timestamp":"2024-06-01T22:42:39.863767Z"}]}
{"channel":"book","type":"update","data":[{"symbol":"ETH/BTC","bids":[],"asks":[{"price":0.05641,"qty":0.27154164}],"checksum":487774500,"timestamp":"2024-06-01T22:42:41.009549Z"}]}
{"channel":"book","type":"update","data":[{"symbol":"ETH/BTC","bids":[],"asks":[{"price":0.05650,"qty":3.56661016}],"checksum":3222895394,"timestamp":"2024-06-01T22:42:41.028448Z"}]}
{"channel":"book","type":"update","data":[{"symbol":"ETH/BTC","bids":[{"price":0.05633,"qty":8.36097606}],"asks":[],"checksum":3725454800,"timestamp":"2024-06-01T22:42:41.046952Z"}]}
{"channel":"book","type":"update","data":[{"symbol":"ETH/BTC","bids":[],"asks":[{"price":0.05648,"qty":30.11228120}],"checksum":1019206279,"timestamp":"2024-06-01T22:42:41.068611Z"}]}
{"channel":"book","type":"update","data":[{"symbol":"ETH/BTC","bids":[],"asks":[{"price":0.05642,"qty":10.06693060}],"checksum":1165565135,"timestamp":"2024-06-01T22:42:41.260029Z"}]}
{"channel":"book","type":"update","data":[{"symbol":"ETH/BTC","bids":[{"price":0.05633,"qty":7.80776000}],"asks":[],"checksum":1533905469,"timestamp":"2024-06-01T22:42:42.465481Z"}]}
{"channel":"book","type":"update","data":[{"symbol":"ETH/BTC","bids":[],"asks":[{"price":0.05642,"qty":7.77160463}],"checksum":581651573,"timestamp":"2024-06-01T22:42:43.453302Z"}]}
{"channel":"book","type":"update","data":[{"symbol":"ETH/BTC","bids":[],"asks":[{"price":0.05648,"qty":17.03805858}],"checksum":1735822752,"timestamp":"2024-06-01T22:42:44.334301Z"}]}
{"channel":"book","type":"update","data":[{"symbol":"ETH/BTC","bids":[],"asks":[{"price":0.05643,"qty":27.96821483}],"checksum":4241756311,"timestamp":"2024-06-01T22:42:44.338217Z"}]}
{"channel":"book","type":"update","data":[{"symbol":"ETH/BTC","bids":[{"price":0.05640,"qty":7.97150372}],"asks":[],"checksum":3674782452,"timestamp":"2024-06-01T22:42:44.381984Z"}]}
{"channel":"book","type":"update","data":[{"symbol":"ETH/BTC","bids":[{"price":0.05639,"qty":23.36508359}],"asks":[],"checksum":59955487,"timestamp":"2024-06-01T22:42:44.386066Z"}]}
{"channel":"book","type":"update","data":[{"symbol":"ETH/BTC","bids":[],"asks":[{"price":0.05641,"qty":2.56681733}],"checksum":1391392910,"timestamp":"2024-06-01T22:42:44.442910Z"}]}
{"channel":"book","type":"update","data":[{"symbol":"ETH/BTC","bids":[{"price":0.05631,"qty":4.56450000},{"price":0.05632,"qty":48.47765604}],"asks":[],"checksum":3378048298,"timestamp":"2024-06-01T22:42:44.615967Z"}]}
{"channel":"book","type":"update","data":[{"symbol":"ETH/BTC","bids":[{"price":0.05632,"qty":38.71765604}],"asks":[],"checksum":1088187058,"timestamp":"2024-06-01T22:42:45.565649Z"}]}
{"channel":"book","type":"update","data":[{"symbol":"ETH/BTC","bids":[{"price":0.05633,"qty":14.37776000}],"asks":[],"checksum":1215416333,"timestamp":"2024-06-01T22:42:45.565666Z"}]}
{"channel":"book","type":"update","data":[{"symbol":"ETH/BTC","bids":[],"asks":[{"price":0.05646,"qty":1.88263959}],"checksum":3641449954,"timestamp":"2024-06-01T22:42:46.879993Z"}]}
{"channel":"book","type":"update","data":[{"symbol":"ETH/BTC","bids":[],"asks":[{"price":0.05643,"qty":14.88229909}],"checksum":1118732501,"timestamp":"2024-06-01T22:42:47.494041Z"}]}
{"channel":"book","type":"update","data":[{"symbol":"ETH/BTC","bids":[],"asks":[{"price":0.05648,"qty":30.11232867}],"checksum":3790785166,"timestamp":"2024-06-01T22:42:47.498375Z"}]}
{"channel":"book","type":"update","data":[{"symbol":"ETH/BTC","bids":[],"asks":[{"price":0.05647,"qty":21.61239487}],"checksum":4223115605,"timestamp":"2024-06-01T22:42:48.028696Z"}]}
{"channel":"book","type":"update","data":[{"symbol":"ETH/BTC","bids":[{"price":0.05633,"qty":14.93097606}],"asks":[],"checksum":1328091204,"timestamp":"2024-06-01T22:42:48.072882Z"}]}
{"channel":"book","type":"update","data":[{"symbol":"ETH/BTC","bids":[],"asks":[{"price":0.05648,"qty":17.03805858}],"checksum":3967113759,"timestamp":"2024-06-01T22:42:50.161941Z"}]}
{"channel":"book","type":"update","data":[{"symbol":"ETH/BTC","bids":[],"asks":[{"price":0.05643,"qty":27.96846462}],"checksum":46959482,"timestamp":"2024-06-01T22:42:50.167141Z"}]}
{"channel":"book","type":"update","data":[{"symbol":"ETH/BTC","bids":[],"asks":[{"price":0.05641,"qty":5.18545146}],"checksum":2652942544,"timestamp":"2024-06-01T22:42:50.184267Z"}]}
{"channel":"book","type":"update","data":[{"symbol":"ETH/BTC","bids":[],"asks":[{"price":0.05643,"qty":14.88229909}],"checksum":1889100213,"timestamp":"2024-06-01T22:42:50.192570Z"}]}
{"channel":"book","type":"update","data":[{"symbol":"ETH/BTC","bids":[],"asks":[{"price":0.05642,"qty":5.15394483}],"checksum":3678496386,"timestamp":"2024-06-01T22:42:50.192674Z"}]}
{"channel":"book","type":"update","data":[{"symbol":"ETH/BTC","bids":[],"asks":[{"price":0.05641,"qty":7.80317460}],"checksum":2021067884,"timestamp":"2024-06-01T22:42:50.198247Z"}]}
{"channel":"book","type":"update","data":[{"symbol":"ETH/BTC","bids":[{"price":0.05640,"qty":5.35331330}],"asks":[],"checksum":3763254141,"timestamp":"2024-06-01T22:42:50.263247Z"}]}
{"channel":"book","type":"update","data":[{"symbol":"ETH/BTC","bids":[{"price":0.05639,"qty":25.98348753}],"asks":[],"checksum":259024141,"timestamp":"2024-06-01T22:42:50.267579Z"}]}
{"channel":"book","type":"update","data":[{"symbol":"ETH/BTC","bids":[],"asks":[{"price":0.05641,"qty":5.18454047}],"checksum":1507153241,"timestamp":"2024-06-01T22:42:50.403925Z"}]}
{"channel":"book","type":"update","data":[{"symbol":"ETH/BTC","bids":[],"asks":[{"price":0.05646,"qty":0.83599470}],"checksum":2433827058,"timestamp":"2024-06-01T22:42:50.479038Z"}]}
{"channel":"book","type":"update","data":[{"symbol":"ETH/BTC","bids":[],"asks":[{"price":0.05646,"qty":1.88265866}],"checksum":62092651,"timestamp":"2024-06-01T22:42:50.740035Z"}]}
{"channel":"book","type":"update","data":[{"symbol":"ETH/BTC","bids":[],"asks":[{"price":0.05642,"qty":18.24024286}],"checksum":2153500778,"timestamp":"2024-06-01T22:42:51.120270Z"}]}
{"channel":"book","type":"update","data":[{"symbol":"ETH/BTC","bids":[],"asks":[{"price":0.05646,"qty":0.83599470}],"checksum":2855372517,"timestamp":"2024-06-01T22:42:52.042658Z"}]}
{"channel":"book","type":"update","data":[{"symbol":"ETH/BTC","bids":[{"price":0.05632,"qty":38.62426364},{"price":0.05631,"qty":4.65790898}],"asks":[],"checksum":344763244,"timestamp":"2024-06-01T22:42:52.316218Z"}]}
{"channel":"book","type":"update","data":[{"symbol":"ETH/BTC","bids":[],"asks":[{"price":0.05644,"qty":21.53946375}],"checksum":2815721788,"timestamp":"2024-06-01T22:42:52.348785Z"}]}
{"channel":"book","type":"update","data":[{"symbol":"ETH/BTC","bids":[],"asks":[{"price":0.05644,"qty":21.61296132}],"checksum":344763244,"timestamp":"2024-06-01T22:42:52.429996Z"}]}
{"channel":"book","type":"update","data":[{"symbol":"ETH/BTC","bids":[],"asks":[{"price":0.05644,"qty":22.65963252}],"checksum":1346334822,"timestamp":"2024-06-01T22:42:52.485774Z"}]}
{"channel":"book","type":"update","data":[{"symbol":"ETH/BTC","bids":[{"price":0.05633,"qty":14.37776000}],"asks":[],"checksum":3835806071,"timestamp":"2024-06-01T22:42:53.536490Z"}]}
{"channel":"book","type":"update","data":[{"symbol":"ETH/BTC","bids":[{"price":0.05631,"qty":4.51340898}],"asks":[],"checksum":4250952736,"timestamp":"2024-06-01T22:42:53.813628Z"}]}
{"channel":"book","type":"update","data":[{"symbol":"ETH/BTC","bids":[],"asks":[{"price":0.05649,"qty":7.38055460}],"checksum":4113710675,"timestamp":"2024-06-01T22:42:53.816399Z"}]}
{"channel":"book","type":"update","data":[{"symbol":"ETH/BTC","bids":[],"asks":[{"price":0.05650,"qty":3.41721016}],"checksum":515690874,"timestamp":"2024-06-01T22:42:53.835782Z"}]}
{"channel":"book","type":"update","data":[{"symbol":"ETH/BTC","bids":[{"price":0.05634,"qty":16.62986199}],"asks":[],"checksum":798765013,"timestamp":"2024-06-01T22:42:53.838959Z"}]}
{"channel":"book","type":"update","data":[{"symbol":"ETH/BTC","bids":[],"asks":[{"price":0.05648,"qty":16.96305858}],"checksum":2138235825,"timestamp":"2024-06-01T22:42:53.850349Z"}]}
{"channel":"book","type":"update","data":[{"symbol":"ETH/BTC","bids":[{"price":0.05632,"qty":38.46576364}],"asks":[],"checksum":3863210026,"timestamp":"2024-06-01T22:42:53.852661Z"}]}
{"channel":"book","type":"update","data":[{"symbol":"ETH/BTC","bids":[],"asks":[{"price":0.05650,"qty":2.67541016}],"checksum":2372559737,"timestamp":"2024-06-01T22:42:53.856910Z"}]}
{"channel":"book","type":"update","data":[{"symbol":"ETH/BTC","bids":[],"asks":[{"price":0.05649,"qty":7.52385460}],"checksum":980811719,"timestamp":"2024-06-01T22:42:53.890663Z"}]}
{"channel":"book","type":"update","data":[{"symbol":"ETH/BTC","bids":[{"price":0.05631,"qty":4.65920898}],"asks":[],"checksum":1852705521,"timestamp":"2024-06-01T22:42:53.891334Z"}]}
{"channel":"book","type":"update","data":[{"symbol":"ETH/BTC","bids":[{"price":0.05634,"qty":16.71466199}],"asks":[],"checksum":3729320109,"timestamp":"2024-06-01T22:42:53.908620Z"}]}
{"channel":"book","type":"update","data":[{"symbol":"ETH/BTC","bids":[],"asks":[{"price":0.05648,"qty":17.03715858}],"checksum":2317358886,"timestamp":"2024-06-01T22:42:53.910972Z"}]}
{"channel":"book","type":"update","data":[{"symbol":"ETH/BTC","bids":[],"asks":[{"price":0.05650,"qty":2.83401016}],"checksum":3425110085,"timestamp":"2024-06-01T22:42:53.923285Z"}]}
{"channel":"book","type":"update","data":[{"symbol":"ETH/BTC","bids":[],"asks":[{"price":0.05650,"qty":3.58761016}],"checksum":636240168,"timestamp":"2024-06-01T22:42:53.925105Z"}]}
{"channel":"book","type":"update","data":[{"symbol":"ETH/BTC","bids":[{"price":0.05632,"qty":38.61556364}],"asks":[],"checksum":632851781,"timestamp":"2024-06-01T22:42:53.944262Z"}]}
{"channel":"book","type":"update","data":[{"symbol":"ETH/BTC","bids":[{"price":0.05639,"qty":23.36508359}],"asks":[],"checksum":3397802805,"timestamp":"2024-06-01T22:42:53.955059Z"}]}
{"channel":"book","type":"update","data":[{"symbol":"ETH/BTC","bids":[{"price":0.05640,"qty":7.97150393}],"asks":[],"checksum":1267812507,"timestamp":"2024-06-01T22:42:53.960360Z"}]}
{"channel":"book","type":"update","data":[{"symbol":"ETH/BTC","bids":[],"asks":[{"price":0.05641,"qty":2.56681733}],"checksum":586033547,"timestamp":"2024-06-01T22:42:53.978320Z"}]}
{"channel":"book","type":"update","data":[{"symbol":"ETH/BTC","bids":[],"asks":[{"price":0.05642,"qty":20.85792249}],"checksum":1782027434,"timestamp":"2024-06-01T22:42:53.982177Z"}]}
{"channel":"book","type":"update","data":[{"symbol":"ETH/BTC","bids":[],"asks":[{"price":0.05644,"qty":21.61296132}],"checksum":780423072,"timestamp":"2024-06-01T22:42:54.055290Z"}]}
{"channel":"book","type":"update","data":[{"symbol":"ETH/BTC","bids":[],"asks":[{"price":0.05646,"qty":1.88264995}],"checksum":400674800,"timestamp":"2024-06-01T22:42:54.302620Z"}]}
