{"channel":"book","type":"snapshot","data":[{"symbol":"ETH/EUR","bids":[{"price":3522.39,"qty":1.68730308},{"price":3522.21,"qty":0.08527900},{"price":3522.20,"qty":0.47901350},{"price":3522.10,"qty":0.47732883},{"price":3522.02,"qty":0.04465342},{"price":3522.01,"qty":1.60000000},{"price":3522.00,"qty":26.17350276},{"price":3521.95,"qty":26.17168639},{"price":3521.88,"qty":1.58991313},{"price":3521.83,"qty":0.60373223}],"asks":[{"price":3522.40,"qty":78.50507980},{"price":3522.70,"qty":26.16615962},{"price":3522.91,"qty":0.00676685},{"price":3522.93,"qty":0.84644082},{"price":3523.07,"qty":6.00000000},{"price":3523.12,"qty":1.04900000},{"price":3523.14,"qty":0.08526300},{"price":3523.18,"qty":0.08386355},{"price":3523.24,"qty":0.72912968},{"price":3523.32,"qty":1.70774845}],"checksum":2069598913}]}
{"channel":"book","type":"update","data":[{"symbol":"ETH/EUR","bids":[],"asks":[{"price":3522.40,"qty":52.33668866}],"checksum":307817961,"timestamp":"2024-06-01T22:42:33.165318Z"}]}
{"channel":"book","type":"update","data":[{"symbol":"ETH/EUR","bids":[],"asks":[{"price":3522.41,"qty":26.16833547}],"checksum":1279376737,"timestamp":"2024-06-01T22:42:33.169214Z"}]}
{"channel":"book","type":"update","data":[{"symbol":"ETH/EUR","bids":[],"asks":[{"price":3522.41,"qty":0.00000000},{"price":3523.32,"qty":1.70774845}],"checksum":307817961,"timestamp":"2024-06-01T22:42:33.201273Z"}]}
{"channel":"book","type":"update","data":[{"symbol":"ETH/EUR","bids":[{"price":3522.02,"qty":0.00000000},{"price":3521.80,"qty":0.00220000},{"price":3522.11,"qty":0.04445157}],"asks":[],"checksum":3978668788,"timestamp":"2024-06-01T22:42:33.221812Z"}]}
{"channel":"book","type":"update","data":[{"symbol":"ETH/EUR","bids":[],"asks":[{"price":3523.32,"qty":0.00000000},{"price":3523.48,"qty":0.14040970}],"checksum":2079626661,"timestamp":"2024-06-01T22:42:33.374413Z"}]}
{"channel":"book","type":"update","data":[{"symbol":"ETH/EUR","bids":[],"asks":[{"price":3523.31,"qty":1.70774845}],"checksum":154586245,"timestamp":"2024-06-01T22:42:33.499564Z"}]}
{"channel":"book","type":"update","data":[{"symbol":"ETH/EUR","bids":[],"asks":[{"price":3523.31,"qty":0.00000000},{"price":3523.48,"qty":0.14040970}],"checksum":2079626661,"timestamp":"2024-06-01T22:42:33.624371Z"}]}
{"channel":"book","type":"update","data":[{"symbol":"ETH/EUR","bids":[],"asks":[{"price":3522.40,"qty":78.50503299}],"checksum":2308777492,"timestamp":"2024-06-01T22:42:33.734214Z"}]}
{"channel":"book","type":"update","data":[{"symbol":"ETH/EUR","bids":[{"price":3522.00,"qty":0.00220000}],"asks":[],"checksum":2256761736,"timestamp":"2024-06-01T22:42:33.763932Z"}]}
{"channel":"book","type":"update","data":[{"symbol":"ETH/EUR","bids":[{"price":3521.99,"qty":26.17138909}],"asks":[],"checksum":491974567,"timestamp":"2024-06-01T22:42:33.767919Z"}]}
{"channel":"book","type":"update","data":[{"symbol":"ETH/EUR","bids":[],"asks":[{"price":3523.35,"qty":1.70774845}],"checksum":1679198076,"timestamp":"2024-06-01T22:42:33.820642Z"}]}
{"channel":"book","type":"update","data":[{"symbol":"ETH/EUR","bids":[{"price":3521.99,"qty":0.00000000},{"price":3521.83,"qty":0.60373223}],"asks":[],"checksum":2229061322,"timestamp":"2024-06-01T22:42:34.437676Z"}]}
{"channel":"book","type":"update","data":[{"symbol":"ETH/EUR","bids":[{"price":3522.00,"qty":26.17351019}],"asks":[],"checksum":482833912,"timestamp":"2024-06-01T22:42:34.441406Z"}]}
{"channel":"book","type":"update","data":[{"symbol":"ETH/EUR","bids":[],"asks":[{"price":3523.35,"qty":0.00000000},{"price":3523.48,"qty":0.14040970}],"checksum":1029896450,"timestamp":"2024-06-01T22:42:34.803455Z"}]}
{"channel":"book","type":"update","data":[{"symbol":"ETH/EUR","bids":[],"asks":[{"price":3523.48,"qty":0.00000000},{"price":3523.49,"qty":35.45098977}],"checksum":621495049,"timestamp":"2024-06-01T22:42:34.828443Z"}]}
{"channel":"book","type":"update","data":[{"symbol":"ETH/EUR","bids":[],"asks":[{"price":3523.48,"qty":0.36160334}],"checksum":3584706947,"timestamp":"2024-06-01T22:42:34.830077Z"}]}
{"channel":"book","type":"update","data":[{"symbol":"ETH/EUR","bids":[],"asks":[{"price":3522.40,"qty":52.33668866}],"checksum":667154994,"timestamp":"2024-06-01T22:42:34.912091Z"}]}
{"channel":"book","type":"update","data":[{"symbol":"ETH/EUR","bids":[{"price":3522.00,"qty":0.00220000}],"asks":[],"checksum":3071114263,"timestamp":"2024-06-01T22:42:34.912197Z"}]}
{"channel":"book","type":"update","data":[{"symbol":"ETH/EUR","bids":[],"asks":[{"price":3523.37,"qty":1.70774845}],"checksum":2449258311,"timestamp":"2024-06-01T22:42:34.922283Z"}]}
{"channel":"book","type":"update","data":[{"symbol":"ETH/EUR","bids":[],"asks":[{"price":3522.41,"qty":26.16831907}],"checksum":3446728781,"timestamp":"2024-06-01T22:42:34.923726Z"}]}
{"channel":"book","type":"update","data":[{"symbol":"ETH/EUR","bids":[{"price":3522.01,"qty":27.77124151}],"asks":[],"checksum":3486999566,"timestamp":"2024-06-01T22:42:34.923752Z"}]}
{"channel":"book","type":"update","data":[{"symbol":"ETH/EUR","bids":[],"asks":[{"price":3522.41,"qty":0.00000000},{"price":3523.37,"qty":1.70774845}],"checksum":794689871,"timestamp":"2024-06-01T22:42:34.937706Z"}]}
{"channel":"book","type":"update","data":[{"symbol":"ETH/EUR","bids":[],"asks":[{"price":3522.40,"qty":78.50503299}],"checksum":1199469440,"timestamp":"2024-06-01T22:42:35.230229Z"}]}
{"channel":"book","type":"update","data":[{"symbol":"ETH/EUR","bids":[{"price":3522.01,"qty":1.60000000}],"asks":[],"checksum":1815969941,"timestamp":"2024-06-01T22:42:35.335567Z"}]}
{"channel":"book","type":"update","data":[{"symbol":"ETH/EUR","bids":[{"price":3521.99,"qty":26.17134952}],"asks":[],"checksum":1130813392,"timestamp":"2024-06-01T22:42:35.339463Z"}]}
{"channel":"book","type":"update","data":[{"symbol":"ETH/EUR","bids":[{"price":3522.11,"qty":0.00000000},{"price":3521.83,"qty":0.60373223},{"price":3522.02,"qty":0.04444222}],"asks":[],"checksum":1371506317,"timestamp":"2024-06-01T22:42:35.525518Z"}]}
{"channel":"book","type":"update","data":[{"symbol":"ETH/EUR","bids":[],"asks":[{"price":3523.37,"qty":0.00000000},{"price":3523.48,"qty":0.36160334}],"checksum":2216782732,"timestamp":"2024-06-01T22:42:35.572826Z"}]}
{"channel":"book","type":"update","data":[{"symbol":"ETH/EUR","bids":[],"asks":[{"price":3523.37,"qty":1.70774845}],"checksum":1371506317,"timestamp":"2024-06-01T22:42:35.706661Z"}]}
{"channel":"book","type":"update","data":[{"symbol":"ETH/EUR","bids":[],"asks":[{"price":3523.37,"qty":0.00000000},{"price":3523.48,"qty":0.36160334}],"checksum":2216782732,"timestamp":"2024-06-01T22:42:35.714307Z"}]}
{"channel":"book","type":"update","data":[{"symbol":"ETH/EUR","bids":[{"price":3521.95,"qty":0.00000000},{"price":3521.83,"qty":0.60373223}],"asks":[],"checksum":1838682239,"timestamp":"2024-06-01T22:42:35.758399Z"}]}
{"channel":"book","type":"update","data":[{"symbol":"ETH/EUR","bids":[{"price":3521.99,"qty":0.00000000},{"price":3521.80,"qty":0.00220000}],"asks":[],"checksum":301772626,"timestamp":"2024-06-01T22:42:35.758491Z"}]}
{"channel":"book","type":"update","data":[{"symbol":"ETH/EUR","bids":[],"asks":[{"price":3522.70,"qty":0.00000000},{"price":3523.49,"qty":34.95202679}],"checksum":426263223,"timestamp":"2024-06-01T22:42:35.758510Z"}]}
{"channel":"book","type":"update","data":[{"symbol":"ETH/EUR","bids":[],"asks":[{"price":3522.56,"qty":26.16716348}],"checksum":3044531999,"timestamp":"2024-06-01T22:42:35.767992Z"}]}
{"channel":"book","type":"update","data":[{"symbol":"ETH/EUR","bids":[{"price":3521.93,"qty":26.17182310}],"asks":[],"checksum":437600026,"timestamp":"2024-06-01T22:42:35.768033Z"}]}
{"channel":"book","type":"update","data":[{"symbol":"ETH/EUR","bids":[{"price":3521.87,"qty":26.17225577}],"asks":[],"checksum":3039027350,"timestamp":"2024-06-01T22:42:35.768079Z"}]}
{"channel":"book","type":"update","data":[{"symbol":"ETH/EUR","bids":[{"price":3521.93,"qty":0.00000000},{"price":3521.83,"qty":0.60373223}],"asks":[],"checksum":1764334252,"timestamp":"2024-06-01T22:42:35.774430Z"}]}
{"channel":"book","type":"update","data":[{"symbol":"ETH/EUR","bids":[{"price":3521.87,"qty":0.00000000},{"price":3521.80,"qty":0.00220000}],"asks":[],"checksum":3044531999,"timestamp":"2024-06-01T22:42:35.827183Z"}]}
{"channel":"book","type":"update","data":[{"symbol":"ETH/EUR","bids":[{"price":3521.86,"qty":26.17229461}],"asks":[],"checksum":3681549704,"timestamp":"2024-06-01T22:42:35.831923Z"}]}
{"channel":"book","type":"update","data":[{"symbol":"ETH/EUR","bids":[{"price":3522.01,"qty":0.00000000},{"price":3521.80,"qty":0.00220000}],"asks":[],"checksum":939211920,"timestamp":"2024-06-01T22:42:35.834469Z"}]}
{"channel":"book","type":"update","data":[{"symbol":"ETH/EUR","bids":[],"asks":[{"price":3523.25,"qty":1.70774845}],"checksum":2389194187,"timestamp":"2024-06-01T22:42:35.836671Z"}]}
{"channel":"book","type":"update","data":[{"symbol":"ETH/EUR","bids":[],"asks":[{"price":3523.06,"qty":0.60420449}],"checksum":4021670337,"timestamp":"2024-06-01T22:42:35.878643Z"}]}
{"channel":"book","type":"update","data":[{"symbol":"ETH/EUR","bids":[{"price":3521.86,"qty":0.00000000},{"price":3521.58,"qty":26.17437120}],"asks":[],"checksum":1268843355,"timestamp":"2024-06-01T22:42:35.880289Z"}]}
{"channel":"book","type":"update","data":[{"symbol":"ETH/EUR","bids":[{"price":3521.82,"qty":26.17260182}],"asks":[],"checksum":704939361,"timestamp":"2024-06-01T22:42:35.884789Z"}]}
{"channel":"book","type":"update","data":[{"symbol":"ETH/EUR","bids":[{"price":3522.02,"qty":0.00000000},{"price":3521.58,"qty":26.17437120},{"price":3521.89,"qty":0.04444386}],"asks":[],"checksum":4277468720,"timestamp":"2024-06-01T22:42:35.886090Z"}]}
{"channel":"book","type":"update","data":[{"symbol":"ETH/EUR","bids":[{"price":3521.82,"qty":0.00000000},{"price":3521.58,"qty":26.17437120}],"asks":[],"checksum":2672916490,"timestamp":"2024-06-01T22:42:35.891424Z"}]}
{"channel":"book","type":"update","data":[{"symbol":"ETH/EUR","bids":[{"price":3521.58,"qty":0.00000000},{"price":3521.50,"qty":0.00220000}],"asks":[],"checksum":1407883266,"timestamp":"2024-06-01T22:42:35.919455Z"}]}
{"channel":"book","type":"update","data":[{"symbol":"ETH/EUR","bids":[{"price":3521.67,"qty":26.17372811}],"asks":[],"checksum":4153893036,"timestamp":"2024-06-01T22:42:35.923120Z"}]}
{"channel":"book","type":"update","data":[{"symbol":"ETH/EUR","bids":[{"price":3521.90,"qty":26.17203158}],"asks":[],"checksum":3242067186,"timestamp":"2024-06-01T22:42:35.944009Z"}]}
{"channel":"book","type":"update","data":[{"symbol":"ETH/EUR","bids":[{"price":3521.90,"qty":0.00000000},{"price":3521.67,"qty":26.17372811}],"asks":[],"checksum":4153893036,"timestamp":"2024-06-01T22:42:35.959348Z"}]}
{"channel":"book","type":"update","data":[{"symbol":"ETH/EUR","bids":[{"price":3521.91,"qty":26.17197402}],"asks":[],"checksum":1054466732,"timestamp":"2024-06-01T22:42:36.023460Z"}]}
{"channel":"book","type":"update","data":[{"symbol":"ETH/EUR","bids":[{"price":3521.83,"qty":26.77626602}],"asks":[],"checksum":145609682,"timestamp":"2024-06-01T22:42:36.082418Z"}]}
{"channel":"book","type":"update","data":[{"symbol":"ETH/EUR","bids":[{"price":3521.91,"qty":0.00000000},{"price":3521.67,"qty":26.17372811}],"asks":[],"checksum":135414232,"timestamp":"2024-06-01T22:42:36.084906Z"}]}
{"channel":"book","type":"update","data":[{"symbol":"ETH/EUR","bids":[{"price":3521.92,"qty":26.17190337}],"asks":[],"checksum":1030409922,"timestamp":"2024-06-01T22:42:36.134027Z"}]}
{"channel":"book","type":"update","data":[{"symbol":"ETH/EUR","bids":[{"price":3521.83,"qty":0.60373223}],"asks":[],"checksum":2354335594,"timestamp":"2024-06-01T22:42:36.155599Z"}]}
{"channel":"book","type":"update","data":[{"symbol":"ETH/EUR","bids":[{"price":3521.93,"qty":26.17177778}],"asks":[],"checksum":1631043548,"timestamp":"2024-06-01T22:42:36.190760Z"}]}
{"channel":"book","type":"update","data":[{"symbol":"ETH/EUR","bids":[{"price":3521.93,"qty":0.00000000},{"price":3521.80,"qty":0.00220000}],"asks":[],"checksum":2354335594,"timestamp":"2024-06-01T22:42:36.206598Z"}]}
{"channel":"book","type":"update","data":[{"symbol":"ETH/EUR","bids":[{"price":3521.86,"qty":26.17233415}],"asks":[],"checksum":701706878,"timestamp":"2024-06-01T22:42:36.242807Z"}]}
{"channel":"book","type":"update","data":[{"symbol":"ETH/EUR","bids":[{"price":3521.92,"qty":0.00000000},{"price":3521.80,"qty":0.00220000}],"asks":[],"checksum":274530886,"timestamp":"2024-06-01T22:42:36.275155Z"}]}
{"channel":"book","type":"update","data":[{"symbol":"ETH/EUR","bids":[{"price":3521.90,"qty":26.17200036}],"asks":[],"checksum":1160140918,"timestamp":"2024-06-01T22:42:36.279188Z"}]}
{"channel":"book","type":"update","data":[{"symbol":"ETH/EUR","bids":[{"price":3521.90,"qty":0.00000000},{"price":3521.80,"qty":0.00220000}],"asks":[],"checksum":274530886,"timestamp":"2024-06-01T22:42:36.413688Z"}]}
{"channel":"book","type":"update","data":[{"symbol":"ETH/EUR","bids":[{"price":3521.91,"qty":26.17197230}],"asks":[],"checksum":2169786304,"timestamp":"2024-06-01T22:42:36.416889Z"}]}
{"channel":"book","type":"update","data":[{"symbol":"ETH/EUR","bids":[{"price":3521.91,"qty":0.00000000},{"price":3521.80,"qty":0.00220000}],"asks":[],"checksum":274530886,"timestamp":"2024-06-01T22:42:36.425464Z"}]}
{"channel":"book","type":"update","data":[{"symbol":"ETH/EUR","bids":[{"price":3521.92,"qty":26.17188072}],"asks":[],"checksum":3307126126,"timestamp":"2024-06-01T22:42:36.491810Z"}]}
{"channel":"book","type":"update","data":[{"symbol":"ETH/EUR","bids":[{"price":3521.92,"qty":0.00000000},{"price":3521.80,"qty":0.00220000}],"asks":[],"checksum":274530886,"timestamp":"2024-06-01T22:42:36.775546Z"}]}
{"channel":"book","type":"update","data":[{"symbol":"ETH/EUR","bids":[{"price":3521.90,"qty":26.17205079}],"asks":[],"checksum":3799660839,"timestamp":"2024-06-01T22:42:36.779069Z"}]}
{"channel":"book","type":"update","data":[{"symbol":"ETH/EUR","bids":[{"price":3521.86,"qty":0.00000000},{"price":3521.80,"qty":0.00220000}],"asks":[],"checksum":2774426883,"timestamp":"2024-06-01T22:42:36.917944Z"}]}
{"channel":"book","type":"update","data":[{"symbol":"ETH/EUR","bids":[{"price":3521.89,"qty":0.00000000},{"price":3521.67,"qty":26.17372811},{"price":3521.91,"qty":0.04444842}],"asks":[],"checksum":2233413214,"timestamp":"2024-06-01T22:42:36.918014Z"}]}
{"channel":"book","type":"update","data":[{"symbol":"ETH/EUR","bids":[{"price":3521.95,"qty":26.17165830}],"asks":[],"checksum":666946896,"timestamp":"2024-06-01T22:42:36.921837Z"}]}
{"channel":"book","type":"update","data":[{"symbol":"ETH/EUR","bids":[{"price":3521.95,"qty":0.00000000},{"price":3521.80,"qty":0.00220000}],"asks":[],"checksum":2233413214,"timestamp":"2024-06-01T22:42:37.076464Z"}]}
{"channel":"book","type":"update","data":[{"symbol":"ETH/EUR","bids":[{"price":3521.93,"qty":26.17179048}],"asks":[],"checksum":1546181149,"timestamp":"2024-06-01T22:42:37.080666Z"}]}
{"channel":"book","type":"update","data":[{"symbol":"ETH/EUR","bids":[{"price":3521.93,"qty":0.00000000},{"price":3521.80,"qty":0.00220000}],"asks":[],"checksum":2233413214,"timestamp":"2024-06-01T22:42:37.164191Z"}]}
{"channel":"book","type":"update","data":[{"symbol":"ETH/EUR","bids":[{"price":3521.94,"qty":26.17172769}],"asks":[],"checksum":654141550,"timestamp":"2024-06-01T22:42:37.167830Z"}]}
{"channel":"book","type":"update","data":[{"symbol":"ETH/EUR","bids":[{"price":3521.94,"qty":0.00000000},{"price":3521.80,"qty":0.00220000}],"asks":[],"checksum":2233413214,"timestamp":"2024-06-01T22:42:37.183544Z"}]}
{"channel":"book","type":"update","data":[{"symbol":"ETH/EUR","bids":[{"price":3521.91,"qty":26.21643252}],"asks":[],"checksum":2265514956,"timestamp":"2024-06-01T22:42:37.234218Z"}]}
{"channel":"book","type":"update","data":[{"symbol":"ETH/EUR","bids":[{"price":3521.90,"qty":0.00000000},{"price":3521.67,"qty":26.17372811}],"asks":[],"checksum":1990104824,"timestamp":"2024-06-01T22:42:37.234339Z"}]}
{"channel":"book","type":"update","data":[{"symbol":"ETH/EUR","bids":[{"price":3521.91,"qty":0.04444842}],"asks":[],"checksum":1955117930,"timestamp":"2024-06-01T22:42:37.238939Z"}]}
{"channel":"book","type":"update","data":[{"symbol":"ETH/EUR","bids":[{"price":3521.82,"qty":26.17262141}],"asks":[],"checksum":1836383606,"timestamp":"2024-06-01T22:42:37.242578Z"}]}
{"channel":"book","type":"update","data":[{"symbol":"ETH/EUR","bids":[{"price":3521.88,"qty":27.76210394}],"asks":[],"checksum":1424848691,"timestamp":"2024-06-01T22:42:37.283360Z"}]}
{"channel":"book","type":"update","data":[{"symbol":"ETH/EUR","bids":[{"price":3521.91,"qty":0.00000000},{"price":3521.67,"qty":26.17372811},{"price":3521.89,"qty":0.04444867}],"asks":[],"checksum":2729049723,"timestamp":"2024-06-01T22:42:37.313352Z"}]}
{"channel":"book","type":"update","data":[{"symbol":"ETH/EUR","bids":[{"price":3521.88,"qty":1.58991313}],"asks":[],"checksum":2430332579,"timestamp":"2024-06-01T22:42:37.325046Z"}]}
{"channel":"book","type":"update","data":[{"symbol":"ETH/EUR","bids":[{"price":3522.10,"qty":2.06715620}],"asks":[],"checksum":3324447203,"timestamp":"2024-06-01T22:42:37.331004Z"}]}
{"channel":"book","type":"update","data":[{"symbol":"ETH/EUR","bids":[{"price":3521.88,"qty":0.00000000},{"price":3521.67,"qty":26.17372811}],"asks":[],"checksum":2569847327,"timestamp":"2024-06-01T22:42:37.333380Z"}]}
{"channel":"book","type":"update","data":[{"symbol":"ETH/EUR","bids":[{"price":3522.39,"qty":1.21000000}],"asks":[],"checksum":3233856819,"timestamp":"2024-06-01T22:42:37.333599Z"}]}
{"channel":"book","type":"update","data":[{"symbol":"ETH/EUR","bids":[{"price":3521.89,"qty":26.21655836}],"asks":[],"checksum":567116394,"timestamp":"2024-06-01T22:42:37.337580Z"}]}
{"channel":"book","type":"update","data":[{"symbol":"ETH/EUR","bids":[{"price":3522.39,"qty":1.68730308}],"asks":[],"checksum":293730013,"timestamp":"2024-06-01T22:42:37.349051Z"}]}
{"channel":"book","type":"update","data":[{"symbol":"ETH/EUR","bids":[{"price":3521.89,"qty":0.04444867}],"asks":[],"checksum":2569847327,"timestamp":"2024-06-01T22:42:37.390299Z"}]}
{"channel":"book","type":"update","data":[{"symbol":"ETH/EUR","bids":[{"price":3521.87,"qty":26.17222744}],"asks":[],"checksum":1933034469,"timestamp":"2024-06-01T22:42:37.394179Z"}]}
{"channel":"book","type":"update","data":[{"symbol":"ETH/EUR","bids":[{"price":3521.87,"qty":0.00000000},{"price":3521.67,"qty":26.17372811}],"asks":[],"checksum":2569847327,"timestamp":"2024-06-01T22:42:37.404553Z"}]}
{"channel":"book","type":"update","data":[{"symbol":"ETH/EUR","bids":[{"price":3521.90,"qty":26.17203439}],"asks":[],"checksum":521250638,"timestamp":"2024-06-01T22:42:37.579344Z"}]}
{"channel":"book","type":"update","data":[{"symbol":"ETH/EUR","bids":[{"price":3521.89,"qty":0.00000000},{"price":3521.67,"qty":26.17372811},{"price":3522.11,"qty":0.04444590}],"asks":[],"checksum":3001835270,"timestamp":"2024-06-01T22:42:37.657488Z"}]}
{"channel":"book","type":"update","data":[{"symbol":"ETH/EUR","bids":[{"price":3521.90,"qty":0.00000000},{"price":3521.67,"qty":26.17372811}],"asks":[],"checksum":1797336163,"timestamp":"2024-06-01T22:42:37.686336Z"}]}
{"channel":"book","type":"update","data":[{"symbol":"ETH/EUR","bids":[{"price":3521.91,"qty":26.17196636}],"asks":[],"checksum":2188400656,"timestamp":"2024-06-01T22:42:37.690717Z"}]}
{"channel":"book","type":"update","data":[{"symbol":"ETH/EUR","bids":[{"price":3521.82,"qty":0.00000000},{"price":3521.67,"qty":26.17372811}],"asks":[],"checksum":2609651212,"timestamp":"2024-06-01T22:42:37.765486Z"}]}
{"channel":"book","type":"update","data":[{"symbol":"ETH/EUR","bids":[{"price":3521.92,"qty":26.17188525}],"asks":[],"checksum":2024633530,"timestamp":"2024-06-01T22:42:37.769553Z"}]}
{"channel":"book","type":"update","data":[{"symbol":"ETH/EUR","bids":[{"price":3521.92,"qty":0.00000000},{"price":3521.67,"qty":26.17372811}],"asks":[],"checksum":2609651212,"timestamp":"2024-06-01T22:42:37.905098Z"}]}
{"channel":"book","type":"update","data":[{"symbol":"ETH/EUR","bids":[{"price":3521.84,"qty":26.17246803}],"asks":[],"checksum":131966511,"timestamp":"2024-06-01T22:42:37.909861Z"}]}
{"channel":"book","type":"update","data":[{"symbol":"ETH/EUR","bids":[{"price":3521.91,"qty":0.00000000},{"price":3521.67,"qty":26.17372811}],"asks":[],"checksum":4124265917,"timestamp":"2024-06-01T22:42:38.420019Z"}]}
{"channel":"book","type":"update","data":[{"symbol":"ETH/EUR","bids":[{"price":3521.87,"qty":26.17225983}],"asks":[],"checksum":4017117674,"timestamp":"2024-06-01T22:42:38.424205Z"}]}
{"channel":"book","type":"update","data":[{"symbol":"ETH/EUR","bids":[{"price":3521.87,"qty":0.00000000},{"price":3521.67,"qty":26.17372811}],"asks":[],"checksum":4124265917,"timestamp":"2024-06-01T22:42:38.473736Z"}]}
{"channel":"book","type":"update","data":[{"symbol":"ETH/EUR","bids":[{"price":3521.89,"qty":26.17209290}],"asks":[],"checksum":214946343,"timestamp":"2024-06-01T22:42:38.477627Z"}]}
{"channel":"book","type":"update","data":[{"symbol":"ETH/EUR","bids":[{"price":3521.89,"qty":0.00000000},{"price":3521.67,"qty":26.17372811}],"asks":[],"checksum":4124265917,"timestamp":"2024-06-01T22:42:38.488544Z"}]}
{"channel":"book","type":"update","data":[{"symbol":"ETH/EUR","bids":[{"price":3521.92,"qty":26.17187050}],"asks":[],"checksum":1484503591,"timestamp":"2024-06-01T22:42:38.530645Z"}]}
{"channel":"book","type":"update","data":[{"symbol":"ETH/EUR","bids":[{"price":3521.92,"qty":0.00000000},{"price":3521.67,"qty":26.17372811}],"asks":[],"checksum":4124265917,"timestamp":"2024-06-01T22:42:38.573744Z"}]}
{"channel":"book","type":"update","data":[{"symbol":"ETH/EUR","bids":[{"price":3521.91,"qty":26.17196732}],"asks":[],"checksum":1668633550,"timestamp":"2024-06-01T22:42:38.590927Z"}]}
{"channel":"book","type":"update","data":[{"symbol":"ETH/EUR","bids":[{"price":3521.91,"qty":0.00000000},{"price":3521.67,"qty":26.17372811}],"asks":[],"checksum":4124265917,"timestamp":"2024-06-01T22:42:38.662753Z"}]}
{"channel":"book","type":"update","data":[{"symbol":"ETH/EUR","bids":[{"price":3521.89,"qty":26.17206151}],"asks":[],"checksum":3122948658,"timestamp":"2024-06-01T22:42:38.667776Z"}]}
{"channel":"book","type":"update","data":[{"symbol":"ETH/EUR","bids":[{"price":3521.84,"qty":0.00000000},{"price":3521.67,"qty":26.17372811}],"asks":[],"checksum":645255697,"timestamp":"2024-06-01T22:42:38.905177Z"}]}
{"channel":"book","type":"update","data":[{"symbol":"ETH/EUR","bids":[{"price":3521.94,"qty":26.17174492}],"asks":[],"checksum":1827724974,"timestamp":"2024-06-01T22:42:38.910569Z"}]}
{"channel":"book","type":"update","data":[{"symbol":"ETH/EUR","bids":[{"price":3521.94,"qty":0.00000000},{"price":3521.67,"qty":26.17372811}],"asks":[],"checksum":645255697,"timestamp":"2024-06-01T22:42:39.097202Z"}]}
{"channel":"book","type":"update","data":[{"symbol":"ETH/EUR","bids":[{"price":3521.91,"qty":26.17194610}],"asks":[],"checksum":4215061857,"timestamp":"2024-06-01T22:42:39.101447Z"}]}
{"channel":"book","type":"update","data":[{"symbol":"ETH/EUR","bids":[{"price":3521.91,"qty":0.00000000},{"price":3521.67,"qty":26.17372811}],"asks":[],"checksum":645255697,"timestamp":"2024-06-01T22:42:39.804210Z"}]}
{"channel":"book","type":"update","data":[{"symbol":"ETH/EUR","bids":[{"price":3521.82,"qty":26.17258455}],"asks":[],"checksum":4136714446,"timestamp":"2024-06-01T22:42:39.807911Z"}]}
{"channel":"book","type":"update","data":[{"symbol":"ETH/EUR","bids":[{"price":3521.89,"qty":0.00000000},{"price":3521.67,"qty":26.17372811}],"asks":[],"checksum":3046207099,"timestamp":"2024-06-01T22:42:39.827944Z"}]}
{"channel":"book","type":"update","data":[{"symbol":"ETH/EUR","bids":[{"price":3521.90,"qty":26.17205829}],"asks":[],"checksum":1966413528,"timestamp":"2024-06-01T22:42:39.830923Z"}]}
{"channel":"book","type":"update","data":[{"symbol":"ETH/EUR","bids":[{"price":3521.90,"qty":0.00000000},{"price":3521.67,"qty":26.17372811}],"asks":[],"checksum":3046207099,"timestamp":"2024-06-01T22:42:39.838733Z"}]}
{"channel":"book","type":"update","data":[{"symbol":"ETH/EUR","bids":[{"price":3521.86,"qty":26.17229430}],"asks":[],"checksum":3491970978,"timestamp":"2024-06-01T22:42:39.915866Z"}]}
{"channel":"book","type":"update","data":[{"symbol":"ETH/EUR","bids":[{"price":3521.86,"qty":0.00000000},{"price":3521.67,"qty":26.17372811}],"asks":[],"checksum":3046207099,"timestamp":"2024-06-01T22:42:39.928661Z"}]}
{"channel":"book","type":"update","data":[{"symbol":"ETH/EUR","bids":[{"price":3521.87,"qty":26.17225505}],"asks":[],"checksum":2680257608,"timestamp":"2024-06-01T22:42:39.992444Z"}]}
{"channel":"book","type":"update","data":[{"symbol":"ETH/EUR","bids":[{"price":3521.87,"qty":0.00000000},{"price":3521.67,"qty":26.17372811}],"asks":[],"checksum":3046207099,"timestamp":"2024-06-01T22:42:40.016175Z"}]}
{"channel":"book","type":"update","data":[{"symbol":"ETH/EUR","bids":[{"price":3521.88,"qty":26.17219749}],"asks":[],"checksum":220305179,"timestamp":"2024-06-01T22:42:40.051777Z"}]}
{"channel":"book","type":"update","data":[{"symbol":"ETH/EUR","bids":[{"price":3521.88,"qty":0.00000000},{"price":3521.67,"qty":26.17372811}],"asks":[],"checksum":3046207099,"timestamp":"2024-06-01T22:42:40.193097Z"}]}
{"channel":"book","type":"update","data":[{"symbol":"ETH/EUR","bids":[{"price":3521.89,"qty":26.17210591}],"asks":[],"checksum":2239208362,"timestamp":"2024-06-01T22:42:40.197232Z"}]}
{"channel":"book","type":"update","data":[{"symbol":"ETH/EUR","bids":[{"price":3521.89,"qty":0.00000000},{"price":3521.67,"qty":26.17372811}],"asks":[],"checksum":3046207099,"timestamp":"2024-06-01T22:42:40.738372Z"}]}
{"channel":"book","type":"update","data":[{"symbol":"ETH/EUR","bids":[{"price":3521.90,"qty":26.17205934}],"asks":[],"checksum":699044027,"timestamp":"2024-06-01T22:42:40.742615Z"}]}
{"channel":"book","type":"update","data":[{"symbol":"ETH/EUR","bids":[{"price":3521.90,"qty":0.00000000},{"price":3521.67,"qty":26.17372811}],"asks":[],"checksum":3046207099,"timestamp":"2024-06-01T22:42:40.919490Z"}]}
{"channel":"book","type":"update","data":[{"symbol":"ETH/EUR","bids":[{"price":3521.88,"qty":26.17215474}],"asks":[],"checksum":4115304306,"timestamp":"2024-06-01T22:42:40.923313Z"}]}
{"channel":"book","type":"update","data":[{"symbol":"ETH/EUR","bids":[{"price":3521.82,"qty":0.00000000},{"price":3521.67,"qty":26.17372811}],"asks":[],"checksum":632167853,"timestamp":"2024-06-01T22:42:40.984076Z"}]}
{"channel":"book","type":"update","data":[{"symbol":"ETH/EUR","bids":[{"price":3521.92,"qty":26.17184600}],"asks":[],"checksum":3380458936,"timestamp":"2024-06-01T22:42:40.988549Z"}]}
{"channel":"book","type":"update","data":[{"symbol":"ETH/EUR","bids":[{"price":3521.92,"qty":0.00000000},{"price":3521.67,"qty":26.17372811}],"asks":[],"checksum":632167853,"timestamp":"2024-06-01T22:42:41.095075Z"}]}
{"channel":"book","type":"update","data":[{"symbol":"ETH/EUR","bids":[{"price":3521.82,"qty":26.17262083}],"asks":[],"checksum":3472925759,"timestamp":"2024-06-01T22:42:41.099833Z"}]}
{"channel":"book","type":"update","data":[{"symbol":"ETH/EUR","bids":[{"price":3521.88,"qty":0.00000000},{"price":3521.67,"qty":26.17372811}],"asks":[],"checksum":1782375643,"timestamp":"2024-06-01T22:42:41.175819Z"}]}
{"channel":"book","type":"update","data":[{"symbol":"ETH/EUR","bids":[{"price":3521.89,"qty":26.17210765}],"asks":[],"checksum":3098957804,"timestamp":"2024-06-01T22:42:41.179895Z"}]}
{"channel":"book","type":"update","data":[{"symbol":"ETH/EUR","bids":[{"price":3521.89,"qty":0.00000000},{"price":3521.67,"qty":26.17372811}],"asks":[],"checksum":1782375643,"timestamp":"2024-06-01T22:42:41.308693Z"}]}
{"channel":"book","type":"update","data":[{"symbol":"ETH/EUR","bids":[{"price":3521.87,"qty":26.17224894}],"asks":[],"checksum":1643255110,"timestamp":"2024-06-01T22:42:41.312657Z"}]}
{"channel":"book","type":"update","data":[{"symbol":"ETH/EUR","bids":[{"price":3521.87,"qty":0.00000000},{"price":3521.67,"qty":26.17372811}],"asks":[],"checksum":1782375643,"timestamp":"2024-06-01T22:42:41.327488Z"}]}
{"channel":"book","type":"update","data":[{"symbol":"ETH/EUR","bids":[{"price":3521.84,"qty":26.17245041}],"asks":[],"checksum":2772829507,"timestamp":"2024-06-01T22:42:41.389010Z"}]}
{"channel":"book","type":"update","data":[{"symbol":"ETH/EUR","bids":[{"price":3521.84,"qty":0.00000000},{"price":3521.67,"qty":26.17372811}],"asks":[],"checksum":1782375643,"timestamp":"2024-06-01T22:42:41.483835Z"}]}
{"channel":"book","type":"update","data":[{"symbol":"ETH/EUR","bids":[{"price":3521.67,"qty":0.00000000},{"price":3521.51,"qty":1.79563660}],"asks":[],"checksum":895299988,"timestamp":"2024-06-01T22:42:41.484049Z"}]}
{"channel":"book","type":"update","data":[{"symbol":"ETH/EUR","bids":[{"price":3521.82,"qty":0.00000000},{"price":3521.50,"qty":0.00220000}],"asks":[],"checksum":3221643105,"timestamp":"2024-06-01T22:42:41.484077Z"}]}
{"channel":"book","type":"update","data":[{"symbol":"ETH/EUR","bids":[],"asks":[{"price":3522.56,"qty":0.00000000},{"price":3523.25,"qty":1.70774845}],"checksum":615823993,"timestamp":"2024-06-01T22:42:41.484120Z"}]}
{"channel":"book","type":"update","data":[{"symbol":"ETH/EUR","bids":[],"asks":[{"price":3522.40,"qty":80.10503299}],"checksum":3009107789,"timestamp":"2024-06-01T22:42:41.487371Z"}]}
{"channel":"book","type":"update","data":[{"symbol":"ETH/EUR","bids":[],"asks":[{"price":3522.41,"qty":26.16830796}],"checksum":2730202244,"timestamp":"2024-06-01T22:42:41.488893Z"}]}
{"channel":"book","type":"update","data":[{"symbol":"ETH/EUR","bids":[{"price":3521.57,"qty":26.17444188}],"asks":[],"checksum":2027509178,"timestamp":"2024-06-01T22:42:41.488977Z"}]}
{"channel":"book","type":"update","data":[{"symbol":"ETH/EUR","bids":[{"price":3521.78,"qty":26.17290033}],"asks":[],"checksum":24518854,"timestamp":"2024-06-01T22:42:41.489086Z"}]}
{"channel":"book","type":"update","data":[{"symbol":"ETH/EUR","bids":[{"price":3521.76,"qty":26.17306041}],"asks":[],"checksum":3135546101,"timestamp":"2024-06-01T22:42:41.489136Z"}]}
{"channel":"book","type":"update","data":[{"symbol":"ETH/EUR","bids":[{"price":3521.78,"qty":0.00000000},{"price":3521.57,"qty":26.17444188}],"asks":[],"checksum":1671185109,"timestamp":"2024-06-01T22:42:41.556274Z"}]}
{"channel":"book","type":"update","data":[{"symbol":"ETH/EUR","bids":[{"price":3521.79,"qty":26.17286109}],"asks":[],"checksum":3235456412,"timestamp":"2024-06-01T22:42:41.560113Z"}]}
{"channel":"book","type":"update","data":[{"symbol":"ETH/EUR","bids":[{"price":3521.79,"qty":0.00000000},{"price":3521.57,"qty":26.17444188}],"asks":[],"checksum":1671185109,"timestamp":"2024-06-01T22:42:41.789473Z"}]}
{"channel":"book","type":"update","data":[{"symbol":"ETH/EUR","bids":[{"price":3521.80,"qty":26.17499965}],"asks":[],"checksum":3346675472,"timestamp":"2024-06-01T22:42:41.795012Z"}]}
{"channel":"book","type":"update","data":[{"symbol":"ETH/EUR","bids":[{"price":3521.80,"qty":0.00220000}],"asks":[],"checksum":1671185109,"timestamp":"2024-06-01T22:42:42.075637Z"}]}
{"channel":"book","type":"update","data":[{"symbol":"ETH/EUR","bids":[{"price":3521.81,"qty":26.17270558}],"asks":[],"checksum":3012675951,"timestamp":"2024-06-01T22:42:42.079061Z"}]}
{"channel":"book","type":"update","data":[{"symbol":"ETH/EUR","bids":[{"price":3521.81,"qty":0.00000000},{"price":3521.57,"qty":26.17444188}],"asks":[],"checksum":1671185109,"timestamp":"2024-06-01T22:42:42.251904Z"}]}
{"channel":"book","type":"update","data":[{"symbol":"ETH/EUR","bids":[{"price":3521.82,"qty":26.17264609}],"asks":[],"checksum":2596196402,"timestamp":"2024-06-01T22:42:42.255724Z"}]}
{"channel":"book","type":"update","data":[{"symbol":"ETH/EUR","bids":[{"price":3521.82,"qty":0.00000000},{"price":3521.57,"qty":26.17444188}],"asks":[],"checksum":1671185109,"timestamp":"2024-06-01T22:42:42.301501Z"}]}
{"channel":"book","type":"update","data":[{"symbol":"ETH/EUR","bids":[{"price":3521.85,"qty":26.17238705}],"asks":[],"checksum":2612578550,"timestamp":"2024-06-01T22:42:42.312662Z"}]}
{"channel":"book","type":"update","data":[{"symbol":"ETH/EUR","bids":[{"price":3521.85,"qty":0.00000000},{"price":3521.57,"qty":26.17444188}],"asks":[],"checksum":1671185109,"timestamp":"2024-06-01T22:42:42.573786Z"}]}
{"channel":"book","type":"update","data":[{"symbol":"ETH/EUR","bids":[{"price":3521.83,"qty":26.77630503}],"asks":[],"checksum":484555082,"timestamp":"2024-06-01T22:42:42.577440Z"}]}
{"channel":"book","type":"update","data":[{"symbol":"ETH/EUR","bids":[{"price":3521.83,"qty":0.60373223}],"asks":[],"checksum":1671185109,"timestamp":"2024-06-01T22:42:42.912308Z"}]}
{"channel":"book","type":"update","data":[{"symbol":"ETH/EUR","bids":[{"price":3521.81,"qty":26.17268144}],"asks":[],"checksum":2553973495,"timestamp":"2024-06-01T22:42:42.916282Z"}]}
{"channel":"book","type":"update","data":[{"symbol":"ETH/EUR","bids":[{"price":3521.81,"qty":0.00000000},{"price":3521.57,"qty":26.17444188}],"asks":[],"checksum":1671185109,"timestamp":"2024-06-01T22:42:42.998561Z"}]}
{"channel":"book","type":"update","data":[{"symbol":"ETH/EUR","bids":[{"price":3521.82,"qty":26.17263172}],"asks":[],"checksum":3026870118,"timestamp":"2024-06-01T22:42:43.002265Z"}]}
{"channel":"book","type":"update","data":[{"symbol":"ETH/EUR","bids":[],"asks":[{"price":3523.24,"qty":0.77151911}],"checksum":3928148142,"timestamp":"2024-06-01T22:42:43.192509Z"}]}
{"channel":"book","type":"update","data":[{"symbol":"ETH/EUR","bids":[{"price":3521.82,"qty":0.00000000},{"price":3521.57,"qty":26.17444188}],"asks":[],"checksum":1037358365,"timestamp":"2024-06-01T22:42:43.208618Z"}]}
{"channel":"book","type":"update","data":[{"symbol":"ETH/EUR","bids":[{"price":3521.83,"qty":26.77627237}],"asks":[],"checksum":3899335832,"timestamp":"2024-06-01T22:42:43.212562Z"}]}
{"channel":"book","type":"update","data":[{"symbol":"ETH/EUR","bids":[{"price":3521.83,"qty":0.60373223}],"asks":[],"checksum":1037358365,"timestamp":"2024-06-01T22:42:43.835422Z"}]}
{"channel":"book","type":"update","data":[{"symbol":"ETH/EUR","bids":[{"price":3521.84,"qty":26.17246477}],"asks":[],"checksum":2322099321,"timestamp":"2024-06-01T22:42:43.840425Z"}]}
{"channel":"book","type":"update","data":[{"symbol":"ETH/EUR","bids":[],"asks":[{"price":3523.23,"qty":6.01217425}],"checksum":825825973,"timestamp":"2024-06-01T22:42:43.879797Z"}]}
{"channel":"book","type":"update","data":[{"symbol":"ETH/EUR","bids":[{"price":3521.84,"qty":0.00000000},{"price":3521.57,"qty":26.17444188}],"asks":[],"checksum":2256905169,"timestamp":"2024-06-01T22:42:44.196152Z"}]}
{"channel":"book","type":"update","data":[{"symbol":"ETH/EUR","bids":[{"price":3521.83,"qty":26.77630951}],"asks":[],"checksum":3959198337,"timestamp":"2024-06-01T22:42:44.200562Z"}]}
{"channel":"book","type":"update","data":[{"symbol":"ETH/EUR","bids":[{"price":3521.83,"qty":26.17257728}],"asks":[],"checksum":1449610995,"timestamp":"2024-06-01T22:42:44.319560Z"}]}
{"channel":"book","type":"update","data":[{"symbol":"ETH/EUR","bids":[{"price":3522.39,"qty":1.21000000}],"asks":[],"checksum":2951483420,"timestamp":"2024-06-01T22:42:44.322119Z"}]}
{"channel":"book","type":"update","data":[{"symbol":"ETH/EUR","bids":[{"price":3521.76,"qty":0.00000000},{"price":3521.51,"qty":1.79563660}],"asks":[],"checksum":83626254,"timestamp":"2024-06-01T22:42:44.328839Z"}]}
{"channel":"book","type":"update","data":[{"symbol":"ETH/EUR","bids":[],"asks":[{"price":3522.41,"qty":0.00000000},{"price":3523.24,"qty":0.77151911}],"checksum":276888761,"timestamp":"2024-06-01T22:42:44.328899Z"}]}
{"channel":"book","type":"update","data":[{"symbol":"ETH/EUR","bids":[{"price":3521.83,"qty":0.00000000},{"price":3521.50,"qty":0.00220000}],"asks":[],"checksum":3119833239,"timestamp":"2024-06-01T22:42:44.328910Z"}]}
{"channel":"book","type":"update","data":[{"symbol":"ETH/EUR","bids":[{"price":3521.66,"qty":26.17376892}],"asks":[],"checksum":3730383879,"timestamp":"2024-06-01T22:42:44.337053Z"}]}
{"channel":"book","type":"update","data":[{"symbol":"ETH/EUR","bids":[],"asks":[{"price":3522.40,"qty":106.27337732}],"checksum":1947489860,"timestamp":"2024-06-01T22:42:44.337130Z"}]}
{"channel":"book","type":"update","data":[{"symbol":"ETH/EUR","bids":[{"price":3521.57,"qty":0.00000000},{"price":3521.50,"qty":0.00220000}],"asks":[],"checksum":3072475829,"timestamp":"2024-06-01T22:42:44.340248Z"}]}
{"channel":"book","type":"update","data":[{"symbol":"ETH/EUR","bids":[{"price":3521.75,"qty":26.17316029}],"asks":[],"checksum":1292070995,"timestamp":"2024-06-01T22:42:44.389239Z"}]}
{"channel":"book","type":"update","data":[{"symbol":"ETH/EUR","bids":[],"asks":[{"price":3522.40,"qty":80.10503299}],"checksum":3880649232,"timestamp":"2024-06-01T22:42:44.391001Z"}]}
{"channel":"book","type":"update","data":[{"symbol":"ETH/EUR","bids":[{"price":3521.66,"qty":0.00000000},{"price":3521.50,"qty":0.00220000}],"asks":[],"checksum":2898419524,"timestamp":"2024-06-01T22:42:44.395721Z"}]}
{"channel":"book","type":"update","data":[{"symbol":"ETH/EUR","bids":[{"price":3521.75,"qty":0.00000000},{"price":3521.47,"qty":4.00000000}],"asks":[],"checksum":3792311790,"timestamp":"2024-06-01T22:42:44.395787Z"}]}
{"channel":"book","type":"update","data":[{"symbol":"ETH/EUR","bids":[{"price":3522.11,"qty":0.00000000},{"price":3521.46,"qty":0.72912968},{"price":3521.67,"qty":0.04445100}],"asks":[],"checksum":521609711,"timestamp":"2024-06-01T22:42:44.398862Z"}]}
{"channel":"book","type":"update","data":[{"symbol":"ETH/EUR","bids":[{"price":3521.67,"qty":0.00000000},{"price":3521.46,"qty":0.72912968},{"price":3521.52,"qty":0.04445289}],"asks":[],"checksum":3299325897,"timestamp":"2024-06-01T22:42:44.433237Z"}]}
{"channel":"book","type":"update","data":[{"symbol":"ETH/EUR","bids":[{"price":3521.76,"qty":26.17309226}],"asks":[],"checksum":7401601,"timestamp":"2024-06-01T22:42:44.454875Z"}]}
{"channel":"book","type":"update","data":[{"symbol":"ETH/EUR","bids":[{"price":3521.76,"qty":0.00000000},{"price":3521.47,"qty":4.00000000}],"asks":[],"checksum":3299325897,"timestamp":"2024-06-01T22:42:44.501229Z"}]}
{"channel":"book","type":"update","data":[{"symbol":"ETH/EUR","bids":[{"price":3521.74,"qty":26.17318384}],"asks":[],"checksum":437709594,"timestamp":"2024-06-01T22:42:44.504876Z"}]}
{"channel":"book","type":"update","data":[{"symbol":"ETH/EUR","bids":[{"price":3521.68,"qty":26.17367241}],"asks":[],"checksum":515708076,"timestamp":"2024-06-01T22:42:44.504890Z"}]}
{"channel":"book","type":"update","data":[{"symbol":"ETH/EUR","bids":[{"price":3521.55,"qty":26.17463065}],"asks":[],"checksum":40625905,"timestamp":"2024-06-01T22:42:44.712219Z"}]}
{"channel":"book","type":"update","data":[{"symbol":"ETH/EUR","bids":[{"price":3521.52,"qty":0.00000000},{"price":3521.51,"qty":1.79563660},{"price":3522.11,"qty":0.04444545}],"asks":[],"checksum":23803961,"timestamp":"2024-06-01T22:42:44.782736Z"}]}
{"channel":"book","type":"update","data":[{"symbol":"ETH/EUR","bids":[{"price":3521.74,"qty":0.00000000},{"price":3521.51,"qty":1.79563660}],"asks":[],"checksum":1190849305,"timestamp":"2024-06-01T22:42:44.830711Z"}]}
{"channel":"book","type":"update","data":[{"symbol":"ETH/EUR","bids":[{"price":3521.72,"qty":26.17334789}],"asks":[],"checksum":3545549024,"timestamp":"2024-06-01T22:42:44.834114Z"}]}
{"channel":"book","type":"update","data":[{"symbol":"ETH/EUR","bids":[],"asks":[{"price":3522.40,"qty":106.27337732}],"checksum":1009489336,"timestamp":"2024-06-01T22:42:44.837442Z"}]}
{"channel":"book","type":"update","data":[{"symbol":"ETH/EUR","bids":[{"price":3521.72,"qty":0.00000000},{"price":3521.51,"qty":1.79563660}],"asks":[],"checksum":3971455322,"timestamp":"2024-06-01T22:42:44.847742Z"}]}
{"channel":"book","type":"update","data":[{"symbol":"ETH/EUR","bids":[{"price":3521.74,"qty":26.17319874}],"asks":[],"checksum":975050395,"timestamp":"2024-06-01T22:42:44.904735Z"}]}
{"channel":"book","type":"update","data":[{"symbol":"ETH/EUR","bids":[{"price":3522.11,"qty":0.00000000},{"price":3521.51,"qty":1.79563660},{"price":3521.69,"qty":0.04445076}],"asks":[],"checksum":912360697,"timestamp":"2024-06-01T22:42:44.962309Z"}]}
{"channel":"book","type":"update","data":[{"symbol":"ETH/EUR","bids":[{"price":3521.74,"qty":0.00000000},{"price":3521.51,"qty":1.79563660}],"asks":[],"checksum":2020218364,"timestamp":"2024-06-01T22:42:45.017892Z"}]}
{"channel":"book","type":"update","data":[{"symbol":"ETH/EUR","bids":[{"price":3521.75,"qty":26.17314214}],"asks":[],"checksum":3024283562,"timestamp":"2024-06-01T22:42:45.023270Z"}]}
{"channel":"book","type":"update","data":[{"symbol":"ETH/EUR","bids":[{"price":3522.39,"qty":0.11000000}],"asks":[],"checksum":4013887301,"timestamp":"2024-06-01T22:42:45.120079Z"}]}
{"channel":"book","type":"update","data":[{"symbol":"ETH/EUR","bids":[{"price":3521.75,"qty":0.00000000},{"price":3521.51,"qty":1.79563660}],"asks":[],"checksum":3677153091,"timestamp":"2024-06-01T22:42:45.329913Z"}]}
{"channel":"book","type":"update","data":[{"symbol":"ETH/EUR","bids":[{"price":3521.73,"qty":26.17325989}],"asks":[],"checksum":2373209720,"timestamp":"2024-06-01T22:42:45.334934Z"}]}
{"channel":"book","type":"update","data":[{"symbol":"ETH/EUR","bids":[{"price":3521.69,"qty":0.00000000},{"price":3521.51,"qty":1.79563660},{"price":3522.22,"qty":0.04444407}],"asks":[],"checksum":939755304,"timestamp":"2024-06-01T22:42:45.524722Z"}]}
{"channel":"book","type":"update","data":[{"symbol":"ETH/EUR","bids":[{"price":3521.73,"qty":0.00000000},{"price":3521.51,"qty":1.79563660}],"asks":[],"checksum":3225039402,"timestamp":"2024-06-01T22:42:45.559501Z"}]}
{"channel":"book","type":"update","data":[{"symbol":"ETH/EUR","bids":[{"price":3521.74,"qty":26.17318662}],"asks":[],"checksum":1803081459,"timestamp":"2024-06-01T22:42:45.563912Z"}]}
{"channel":"book","type":"update","data":[{"symbol":"ETH/EUR","bids":[{"price":3521.68,"qty":0.00000000},{"price":3521.51,"qty":1.79563660}],"asks":[],"checksum":3297274699,"timestamp":"2024-06-01T22:42:45.586354Z"}]}
{"channel":"book","type":"update","data":[{"symbol":"ETH/EUR","bids":[],"asks":[{"price":3522.40,"qty":80.10503299}],"checksum":2209773349,"timestamp":"2024-06-01T22:42:45.586398Z"}]}
{"channel":"book","type":"update","data":[{"symbol":"ETH/EUR","bids":[],"asks":[{"price":3522.41,"qty":26.16830543}],"checksum":4057376148,"timestamp":"2024-06-01T22:42:45.590488Z"}]}
{"channel":"book","type":"update","data":[{"symbol":"ETH/EUR","bids":[{"price":3522.22,"qty":0.00000000},{"price":3521.50,"qty":0.00220000},{"price":3522.11,"qty":0.04444546}],"asks":[],"checksum":1399570054,"timestamp":"2024-06-01T22:42:45.600389Z"}]}
{"channel":"book","type":"update","data":[{"symbol":"ETH/EUR","bids":[],"asks":[{"price":3522.41,"qty":0.00000000},{"price":3523.24,"qty":0.77151911}],"checksum":554396727,"timestamp":"2024-06-01T22:42:45.611106Z"}]}
{"channel":"book","type":"update","data":[{"symbol":"ETH/EUR","bids":[{"price":3521.77,"qty":26.17300768}],"asks":[],"checksum":3455904102,"timestamp":"2024-06-01T22:42:45.614495Z"}]}
{"channel":"book","type":"update","data":[{"symbol":"ETH/EUR","bids":[{"price":3521.77,"qty":0.00000000},{"price":3521.51,"qty":1.79563660}],"asks":[],"checksum":554396727,"timestamp":"2024-06-01T22:42:45.660657Z"}]}
{"channel":"book","type":"update","data":[{"symbol":"ETH/EUR","bids":[{"price":3521.76,"qty":26.17309403}],"asks":[],"checksum":135500359,"timestamp":"2024-06-01T22:42:45.666310Z"}]}
{"channel":"book","type":"update","data":[{"symbol":"ETH/EUR","bids":[{"price":3522.39,"qty":0.58730308}],"asks":[],"checksum":4053322920,"timestamp":"2024-06-01T22:42:45.710826Z"}]}
{"channel":"book","type":"update","data":[{"symbol":"ETH/EUR","bids":[{"price":3522.39,"qty":0.11000000}],"asks":[],"checksum":135500359,"timestamp":"2024-06-01T22:42:45.758055Z"}]}
{"channel":"book","type":"update","data":[{"symbol":"ETH/EUR","bids":[{"price":3521.76,"qty":0.00000000},{"price":3521.51,"qty":1.79563660}],"asks":[],"checksum":554396727,"timestamp":"2024-06-01T22:42:45.806684Z"}]}
{"channel":"book","type":"update","data":[{"symbol":"ETH/EUR","bids":[{"price":3521.74,"qty":52.34636822}],"asks":[],"checksum":847306317,"timestamp":"2024-06-01T22:42:45.811010Z"}]}
{"channel":"book","type":"update","data":[{"symbol":"ETH/EUR","bids":[],"asks":[{"price":3523.24,"qty":0.72912968}],"checksum":1825065349,"timestamp":"2024-06-01T22:42:45.955986Z"}]}
{"channel":"book","type":"update","data":[{"symbol":"ETH/EUR","bids":[],"asks":[{"price":3523.22,"qty":0.22028519}],"checksum":3352376670,"timestamp":"2024-06-01T22:42:45.957747Z"}]}
{"channel":"book","type":"update","data":[{"symbol":"ETH/EUR","bids":[{"price":3521.74,"qty":26.17318160}],"asks":[],"checksum":319831475,"timestamp":"2024-06-01T22:42:45.968267Z"}]}
{"channel":"book","type":"update","data":[{"symbol":"ETH/EUR","bids":[{"price":3521.75,"qty":26.17313973}],"asks":[],"checksum":2824919364,"timestamp":"2024-06-01T22:42:45.972180Z"}]}
{"channel":"book","type":"update","data":[{"symbol":"ETH/EUR","bids":[],"asks":[{"price":3522.40,"qty":106.27337732}],"checksum":36547335,"timestamp":"2024-06-01T22:42:46.108155Z"}]}
{"channel":"book","type":"update","data":[{"symbol":"ETH/EUR","bids":[],"asks":[{"price":3523.23,"qty":0.00000000},{"price":3523.24,"qty":0.72912968}],"checksum":4028231263,"timestamp":"2024-06-01T22:42:46.182510Z"}]}
{"channel":"book","type":"update","data":[{"symbol":"ETH/EUR","bids":[],"asks":[{"price":3523.23,"qty":46.92713819}],"checksum":1821397453,"timestamp":"2024-06-01T22:42:46.187354Z"}]}
{"channel":"book","type":"update","data":[{"symbol":"ETH/EUR","bids":[{"price":3522.11,"qty":0.00000000},{"price":3521.51,"qty":1.79563660},{"price":3522.22,"qty":0.04444407}],"asks":[],"checksum":2676727198,"timestamp":"2024-06-01T22:42:46.266431Z"}]}
{"channel":"book","type":"update","data":[{"symbol":"ETH/EUR","bids":[{"price":3522.22,"qty":0.00000000},{"price":3521.51,"qty":1.79563660},{"price":3522.11,"qty":0.04443633}],"asks":[],"checksum":2324725453,"timestamp":"2024-06-01T22:42:46.322609Z"}]}
{"channel":"book","type":"update","data":[{"symbol":"ETH/EUR","bids":[{"price":3521.75,"qty":0.00000000},{"price":3521.51,"qty":1.79563660}],"asks":[],"checksum":3785428229,"timestamp":"2024-06-01T22:42:46.489277Z"}]}
{"channel":"book","type":"update","data":[{"symbol":"ETH/EUR","bids":[{"price":3521.77,"qty":26.17301864}],"asks":[],"checksum":504799080,"timestamp":"2024-06-01T22:42:46.492911Z"}]}
{"channel":"book","type":"update","data":[{"symbol":"ETH/EUR","bids":[{"price":3521.77,"qty":0.00000000},{"price":3521.51,"qty":1.79563660}],"asks":[],"checksum":3785428229,"timestamp":"2024-06-01T22:42:46.589559Z"}]}
{"channel":"book","type":"update","data":[{"symbol":"ETH/EUR","bids":[],"asks":[{"price":3522.40,"qty":80.10503299}],"checksum":1273790278,"timestamp":"2024-06-01T22:42:46.589622Z"}]}
{"channel":"book","type":"update","data":[{"symbol":"ETH/EUR","bids":[{"price":3521.78,"qty":26.17292967}],"asks":[],"checksum":2346197803,"timestamp":"2024-06-01T22:42:46.593824Z"}]}
{"channel":"book","type":"update","data":[{"symbol":"ETH/EUR","bids":[{"price":3522.11,"qty":0.00000000},{"price":3521.51,"qty":1.79563660},{"price":3522.22,"qty":0.04443494}],"asks":[],"checksum":3387004772,"timestamp":"2024-06-01T22:42:47.057137Z"}]}
{"channel":"book","type":"update","data":[{"symbol":"ETH/EUR","bids":[],"asks":[{"price":3522.40,"qty":106.27337732}],"checksum":647940668,"timestamp":"2024-06-01T22:42:47.130021Z"}]}
{"channel":"book","type":"update","data":[{"symbol":"ETH/EUR","bids":[],"asks":[{"price":3522.40,"qty":80.10503299}],"checksum":3387004772,"timestamp":"2024-06-01T22:42:47.186585Z"}]}
{"channel":"book","type":"update","data":[{"symbol":"ETH/EUR","bids":[{"price":3522.39,"qty":3.00500000}],"asks":[],"checksum":50149465,"timestamp":"2024-06-01T22:42:47.257899Z"}]}
{"channel":"book","type":"update","data":[{"symbol":"ETH/EUR","bids":[{"price":3522.22,"qty":0.00000000},{"price":3521.51,"qty":1.79563660},{"price":3521.79,"qty":0.04444037}],"asks":[],"checksum":3804482577,"timestamp":"2024-06-01T22:42:47.307305Z"}]}
{"channel":"book","type":"update","data":[{"symbol":"ETH/EUR","bids":[{"price":3521.78,"qty":0.00000000},{"price":3521.51,"qty":1.79563660}],"asks":[],"checksum":1455537109,"timestamp":"2024-06-01T22:42:47.494323Z"}]}
{"channel":"book","type":"update","data":[{"symbol":"ETH/EUR","bids":[{"price":3521.80,"qty":26.17498643}],"asks":[],"checksum":2649215952,"timestamp":"2024-06-01T22:42:47.499017Z"}]}
{"channel":"book","type":"update","data":[{"symbol":"ETH/EUR","bids":[{"price":3521.79,"qty":0.00000000},{"price":3521.50,"qty":0.00220000},{"price":3521.75,"qty":0.04444087}],"asks":[],"checksum":905681723,"timestamp":"2024-06-01T22:42:47.542800Z"}]}
{"channel":"book","type":"update","data":[{"symbol":"ETH/EUR","bids":[],"asks":[{"price":3523.23,"qty":0.00000000},{"price":3523.24,"qty":0.72912968}],"checksum":1782571584,"timestamp":"2024-06-01T22:42:48.432192Z"}]}
{"channel":"book","type":"update","data":[{"symbol":"ETH/EUR","bids":[],"asks":[{"price":3523.23,"qty":24.47380432}],"checksum":1205665800,"timestamp":"2024-06-01T22:42:48.437354Z"}]}
{"channel":"book","type":"update","data":[{"symbol":"ETH/EUR","bids":[{"price":3521.80,"qty":0.00220000}],"asks":[],"checksum":3023114414,"timestamp":"2024-06-01T22:42:48.499095Z"}]}
{"channel":"book","type":"update","data":[{"symbol":"ETH/EUR","bids":[{"price":3521.81,"qty":26.17270617}],"asks":[],"checksum":136084440,"timestamp":"2024-06-01T22:42:48.503336Z"}]}
{"channel":"book","type":"update","data":[{"symbol":"ETH/EUR","bids":[],"asks":[{"price":3522.41,"qty":26.16833057}],"checksum":3292772743,"timestamp":"2024-06-01T22:42:48.503409Z"}]}
{"channel":"book","type":"update","data":[{"symbol":"ETH/EUR","bids":[],"asks":[{"price":3523.22,"qty":0.00000000},{"price":3523.23,"qty":24.47380432}],"checksum":4263531470,"timestamp":"2024-06-01T22:42:48.783492Z"}]}
{"channel":"book","type":"update","data":[{"symbol":"ETH/EUR","bids":[],"asks":[{"price":3523.22,"qty":0.18956385}],"checksum":3053915921,"timestamp":"2024-06-01T22:42:48.786179Z"}]}
{"channel":"book","type":"update","data":[{"symbol":"ETH/EUR","bids":[{"price":3521.75,"qty":0.00000000},{"price":3521.51,"qty":1.79563660},{"price":3521.82,"qty":0.04445308}],"asks":[],"checksum":347745714,"timestamp":"2024-06-01T22:42:48.848808Z"}]}
{"channel":"book","type":"update","data":[{"symbol":"ETH/EUR","bids":[{"price":3521.74,"qty":0.00000000},{"price":3521.51,"qty":1.79563660}],"asks":[],"checksum":1330044237,"timestamp":"2024-06-01T22:42:49.263739Z"}]}
{"channel":"book","type":"update","data":[{"symbol":"ETH/EUR","bids":[{"price":3521.83,"qty":26.17254780}],"asks":[],"checksum":3098815395,"timestamp":"2024-06-01T22:42:49.267041Z"}]}
{"channel":"book","type":"update","data":[{"symbol":"ETH/EUR","bids":[{"price":3521.81,"qty":0.00000000},{"price":3521.51,"qty":1.79563660}],"asks":[],"checksum":1658747980,"timestamp":"2024-06-01T22:42:49.325871Z"}]}
{"channel":"book","type":"update","data":[{"symbol":"ETH/EUR","bids":[{"price":3521.87,"qty":26.17221550}],"asks":[],"checksum":321761997,"timestamp":"2024-06-01T22:42:49.330866Z"}]}
{"channel":"book","type":"update","data":[{"symbol":"ETH/EUR","bids":[{"price":3521.68,"qty":26.17364469}],"asks":[],"checksum":558547404,"timestamp":"2024-06-01T22:42:49.330921Z"}]}
{"channel":"book","type":"update","data":[{"symbol":"ETH/EUR","bids":[{"price":3522.39,"qty":0.11000000}],"asks":[],"checksum":4269825917,"timestamp":"2024-06-01T22:42:49.408725Z"}]}
{"channel":"book","type":"update","data":[{"symbol":"ETH/EUR","bids":[{"price":3521.87,"qty":0.00000000},{"price":3521.55,"qty":26.17463065}],"asks":[],"checksum":4223789362,"timestamp":"2024-06-01T22:42:49.729793Z"}]}
{"channel":"book","type":"update","data":[{"symbol":"ETH/EUR","bids":[{"price":3521.86,"qty":26.17234895}],"asks":[],"checksum":4077948592,"timestamp":"2024-06-01T22:42:49.733256Z"}]}
{"channel":"book","type":"update","data":[{"symbol":"ETH/EUR","bids":[{"price":3521.82,"qty":0.00000000},{"price":3521.55,"qty":26.17463065},{"price":3522.11,"qty":0.04444942}],"asks":[],"checksum":1557437751,"timestamp":"2024-06-01T22:42:49.747536Z"}]}
{"channel":"book","type":"update","data":[{"symbol":"ETH/EUR","bids":[{"price":3521.86,"qty":0.00000000},{"price":3521.55,"qty":26.17463065}],"asks":[],"checksum":3011078825,"timestamp":"2024-06-01T22:42:49.789495Z"}]}
{"channel":"book","type":"update","data":[{"symbol":"ETH/EUR","bids":[{"price":3521.55,"qty":0.00000000},{"price":3521.51,"qty":1.79563660}],"asks":[],"checksum":1719527340,"timestamp":"2024-06-01T22:42:49.789637Z"}]}
{"channel":"book","type":"update","data":[{"symbol":"ETH/EUR","bids":[{"price":3521.77,"qty":26.17297377}],"asks":[],"checksum":2149586849,"timestamp":"2024-06-01T22:42:49.793927Z"}]}
{"channel":"book","type":"update","data":[{"symbol":"ETH/EUR","bids":[{"price":3521.83,"qty":0.00000000},{"price":3521.51,"qty":1.79563660}],"asks":[],"checksum":3254735962,"timestamp":"2024-06-01T22:42:49.823445Z"}]}
{"channel":"book","type":"update","data":[{"symbol":"ETH/EUR","bids":[{"price":3521.84,"qty":26.17249024}],"asks":[],"checksum":2366792826,"timestamp":"2024-06-01T22:42:49.827221Z"}]}
{"channel":"book","type":"update","data":[{"symbol":"ETH/EUR","bids":[{"price":3521.84,"qty":0.00000000},{"price":3521.51,"qty":1.79563660}],"asks":[],"checksum":3254735962,"timestamp":"2024-06-01T22:42:49.916469Z"}]}
{"channel":"book","type":"update","data":[{"symbol":"ETH/EUR","bids":[{"price":3521.86,"qty":26.17235156}],"asks":[],"checksum":1114605940,"timestamp":"2024-06-01T22:42:49.920766Z"}]}
{"channel":"book","type":"update","data":[{"symbol":"ETH/EUR","bids":[{"price":3521.86,"qty":0.00000000},{"price":3521.51,"qty":1.79563660}],"asks":[],"checksum":3254735962,"timestamp":"2024-06-01T22:42:49.941257Z"}]}
{"channel":"book","type":"update","data":[{"symbol":"ETH/EUR","bids":[{"price":3521.83,"qty":26.17254780}],"asks":[],"checksum":2149586849,"timestamp":"2024-06-01T22:42:49.991580Z"}]}
{"channel":"book","type":"update","data":[{"symbol":"ETH/EUR","bids":[{"price":3521.83,"qty":0.00000000},{"price":3521.51,"qty":1.79563660}],"asks":[],"checksum":3254735962,"timestamp":"2024-06-01T22:42:50.041746Z"}]}
{"channel":"book","type":"update","data":[{"symbol":"ETH/EUR","bids":[{"price":3521.84,"qty":26.17248762}],"asks":[],"checksum":779889659,"timestamp":"2024-06-01T22:42:50.045883Z"}]}
{"channel":"book","type":"update","data":[{"symbol":"ETH/EUR","bids":[{"price":3522.10,"qty":0.47732883}],"asks":[],"checksum":3723316963,"timestamp":"2024-06-01T22:42:50.158809Z"}]}
{"channel":"book","type":"update","data":[{"symbol":"ETH/EUR","bids":[{"price":3521.88,"qty":1.58982737}],"asks":[],"checksum":2105866830,"timestamp":"2024-06-01T22:42:50.160000Z"}]}
{"channel":"book","type":"update","data":[{"symbol":"ETH/EUR","bids":[{"price":3522.20,"qty":0.00168467}],"asks":[],"checksum":3739403338,"timestamp":"2024-06-01T22:42:50.161118Z"}]}
{"channel":"book","type":"update","data":[{"symbol":"ETH/EUR","bids":[{"price":3522.10,"qty":0.00000000},{"price":3521.68,"qty":26.17364469}],"asks":[],"checksum":823207075,"timestamp":"2024-06-01T22:42:50.161306Z"}]}
{"channel":"book","type":"update","data":[{"symbol":"ETH/EUR","bids":[],"asks":[{"price":3522.41,"qty":0.00000000},{"price":3523.23,"qty":24.47380432}],"checksum":576663821,"timestamp":"2024-06-01T22:42:50.162415Z"}]}
{"channel":"book","type":"update","data":[{"symbol":"ETH/EUR","bids":[{"price":3521.84,"qty":0.00000000},{"price":3521.51,"qty":1.79563660}],"asks":[],"checksum":1425971857,"timestamp":"2024-06-01T22:42:50.162620Z"}]}
{"channel":"book","type":"update","data":[{"symbol":"ETH/EUR","bids":[{"price":3521.77,"qty":0.00000000},{"price":3521.50,"qty":0.00220000}],"asks":[],"checksum":1175797862,"timestamp":"2024-06-01T22:42:50.162635Z"}]}
{"channel":"book","type":"update","data":[{"symbol":"ETH/EUR","bids":[{"price":3521.68,"qty":0.00000000},{"price":3521.47,"qty":4.00000000}],"asks":[],"checksum":1578161620,"timestamp":"2024-06-01T22:42:50.164693Z"}]}
{"channel":"book","type":"update","data":[{"symbol":"ETH/EUR","bids":[{"price":3521.88,"qty":0.00000000},{"price":3521.40,"qty":0.00220000}],"asks":[],"checksum":838443235,"timestamp":"2024-06-01T22:42:50.165724Z"}]}
{"channel":"book","type":"update","data":[{"symbol":"ETH/EUR","bids":[{"price":3521.43,"qty":0.47730308}],"asks":[],"checksum":3760275576,"timestamp":"2024-06-01T22:42:50.168339Z"}]}
{"channel":"book","type":"update","data":[{"symbol":"ETH/EUR","bids":[{"price":3521.66,"qty":26.17381360}],"asks":[],"checksum":152419176,"timestamp":"2024-06-01T22:42:50.170105Z"}]}
{"channel":"book","type":"update","data":[{"symbol":"ETH/EUR","bids":[],"asks":[{"price":3522.40,"qty":106.27337732}],"checksum":160563991,"timestamp":"2024-06-01T22:42:50.170121Z"}]}
{"channel":"book","type":"update","data":[{"symbol":"ETH/EUR","bids":[{"price":3521.60,"qty":26.17423960}],"asks":[],"checksum":3542203700,"timestamp":"2024-06-01T22:42:50.170164Z"}]}
{"channel":"book","type":"update","data":[{"symbol":"ETH/EUR","bids":[],"asks":[{"price":3522.40,"qty":112.81996266}],"checksum":3987804806,"timestamp":"2024-06-01T22:42:50.184172Z"}]}
{"channel":"book","type":"update","data":[{"symbol":"ETH/EUR","bids":[{"price":3521.51,"qty":0.00000000},{"price":3521.49,"qty":26.17503431}],"asks":[],"checksum":238878298,"timestamp":"2024-06-01T22:42:50.184282Z"}]}
{"channel":"book","type":"update","data":[{"symbol":"ETH/EUR","bids":[{"price":3521.81,"qty":0.47730308}],"asks":[],"checksum":1118089872,"timestamp":"2024-06-01T22:42:50.190871Z"}]}
{"channel":"book","type":"update","data":[{"symbol":"ETH/EUR","bids":[{"price":3521.66,"qty":0.00000000},{"price":3521.49,"qty":26.17503431}],"asks":[],"checksum":3705767114,"timestamp":"2024-06-01T22:42:50.192510Z"}]}
{"channel":"book","type":"update","data":[{"symbol":"ETH/EUR","bids":[{"price":3521.73,"qty":1.58982737}],"asks":[],"checksum":4288058961,"timestamp":"2024-06-01T22:42:50.203129Z"}]}
{"channel":"book","type":"update","data":[{"symbol":"ETH/EUR","bids":[{"price":3522.11,"qty":0.00000000},{"price":3521.49,"qty":26.17503431},{"price":3521.52,"qty":0.04445686}],"asks":[],"checksum":1980156013,"timestamp":"2024-06-01T22:42:50.208771Z"}]}
{"channel":"book","type":"update","data":[{"symbol":"ETH/EUR","bids":[{"price":3521.61,"qty":26.17417677}],"asks":[],"checksum":3480334178,"timestamp":"2024-06-01T22:42:50.222274Z"}]}
{"channel":"book","type":"update","data":[{"symbol":"ETH/EUR","bids":[{"price":3521.61,"qty":0.00000000},{"price":3521.50,"qty":0.00220000}],"asks":[],"checksum":1980156013,"timestamp":"2024-06-01T22:42:50.245885Z"}]}
{"channel":"book","type":"update","data":[{"symbol":"ETH/EUR","bids":[{"price":3521.65,"qty":26.17391652}],"asks":[],"checksum":2245644887,"timestamp":"2024-06-01T22:42:50.275924Z"}]}
{"channel":"book","type":"update","data":[{"symbol":"ETH/EUR","bids":[{"price":3521.52,"qty":1.84008836}],"asks":[],"checksum":788793085,"timestamp":"2024-06-01T22:42:50.305707Z"}]}
{"channel":"book","type":"update","data":[{"symbol":"ETH/EUR","bids":[{"price":3521.65,"qty":0.00000000},{"price":3521.50,"qty":0.00220000}],"asks":[],"checksum":3292659672,"timestamp":"2024-06-01T22:42:50.340415Z"}]}
{"channel":"book","type":"update","data":[{"symbol":"ETH/EUR","bids":[{"price":3521.66,"qty":26.17379812}],"asks":[],"checksum":2612936912,"timestamp":"2024-06-01T22:42:50.344591Z"}]}
{"channel":"book","type":"update","data":[{"symbol":"ETH/EUR","bids":[{"price":3521.66,"qty":0.00000000},{"price":3521.50,"qty":0.00220000}],"asks":[],"checksum":3292659672,"timestamp":"2024-06-01T22:42:50.352182Z"}]}
{"channel":"book","type":"update","data":[{"symbol":"ETH/EUR","bids":[{"price":3522.21,"qty":0.00000000},{"price":3521.49,"qty":26.17503431},{"price":3521.71,"qty":0.08528700}],"asks":[],"checksum":1151390250,"timestamp":"2024-06-01T22:42:50.357130Z"}]}
{"channel":"book","type":"update","data":[{"symbol":"ETH/EUR","bids":[],"asks":[{"price":3522.40,"qty":106.27337732}],"checksum":2049998232,"timestamp":"2024-06-01T22:42:50.403832Z"}]}
{"channel":"book","type":"update","data":[{"symbol":"ETH/EUR","bids":[{"price":3521.60,"qty":0.00000000},{"price":3521.49,"qty":26.17503431}],"asks":[],"checksum":2334347056,"timestamp":"2024-06-01T22:42:50.423660Z"}]}
{"channel":"book","type":"update","data":[{"symbol":"ETH/EUR","bids":[{"price":3521.69,"qty":26.17359947}],"asks":[],"checksum":3496430737,"timestamp":"2024-06-01T22:42:50.423707Z"}]}
{"channel":"book","type":"update","data":[{"symbol":"ETH/EUR","bids":[{"price":3521.70,"qty":26.17348100}],"asks":[],"checksum":3748468243,"timestamp":"2024-06-01T22:42:50.494393Z"}]}
{"channel":"book","type":"update","data":[{"symbol":"ETH/EUR","bids":[{"price":3521.70,"qty":0.00000000},{"price":3521.50,"qty":0.00220000}],"asks":[],"checksum":3496430737,"timestamp":"2024-06-01T22:42:50.627160Z"}]}
{"channel":"book","type":"update","data":[{"symbol":"ETH/EUR","bids":[{"price":3521.62,"qty":26.17410681}],"asks":[],"checksum":2563758081,"timestamp":"2024-06-01T22:42:50.631423Z"}]}
{"channel":"book","type":"update","data":[{"symbol":"ETH/EUR","bids":[{"price":3521.52,"qty":1.79563150},{"price":3521.82,"qty":0.04445308}],"asks":[],"checksum":696975099,"timestamp":"2024-06-01T22:42:50.641503Z"}]}
{"channel":"book","type":"update","data":[{"symbol":"ETH/EUR","bids":[{"price":3521.69,"qty":0.00000000},{"price":3521.52,"qty":1.79563150}],"asks":[],"checksum":3565361456,"timestamp":"2024-06-01T22:42:50.641892Z"}]}
{"channel":"book","type":"update","data":[{"symbol":"ETH/EUR","bids":[{"price":3521.67,"qty":26.17371064}],"asks":[],"checksum":2789412771,"timestamp":"2024-06-01T22:42:50.645316Z"}]}
{"channel":"book","type":"update","data":[{"symbol":"ETH/EUR","bids":[{"price":3521.67,"qty":0.00000000},{"price":3521.52,"qty":1.79563150}],"asks":[],"checksum":3565361456,"timestamp":"2024-06-01T22:42:50.651816Z"}]}
{"channel":"book","type":"update","data":[{"symbol":"ETH/EUR","bids":[],"asks":[{"price":3523.23,"qty":0.00000000},{"price":3523.24,"qty":0.72912968}],"checksum":2380497413,"timestamp":"2024-06-01T22:42:50.719667Z"}]}
{"channel":"book","type":"update","data":[{"symbol":"ETH/EUR","bids":[{"price":3521.65,"qty":26.17388072}],"asks":[],"checksum":3514760874,"timestamp":"2024-06-01T22:42:50.742660Z"}]}
{"channel":"book","type":"update","data":[{"symbol":"ETH/EUR","bids":[{"price":3521.65,"qty":0.00000000},{"price":3521.52,"qty":1.79563150}],"asks":[],"checksum":2380497413,"timestamp":"2024-06-01T22:42:50.884983Z"}]}
{"channel":"book","type":"update","data":[{"symbol":"ETH/EUR","bids":[{"price":3521.66,"qty":26.17379176}],"asks":[],"checksum":4017275030,"timestamp":"2024-06-01T22:42:50.889055Z"}]}
{"channel":"book","type":"update","data":[{"symbol":"ETH/EUR","bids":[{"price":3521.66,"qty":0.00000000},{"price":3521.52,"qty":1.79563150}],"asks":[],"checksum":2380497413,"timestamp":"2024-06-01T22:42:51.161817Z"}]}
{"channel":"book","type":"update","data":[{"symbol":"ETH/EUR","bids":[{"price":3521.65,"qty":26.17385412}],"asks":[],"checksum":2151369056,"timestamp":"2024-06-01T22:42:51.165863Z"}]}
{"channel":"book","type":"update","data":[{"symbol":"ETH/EUR","bids":[{"price":3521.65,"qty":0.00000000},{"price":3521.52,"qty":1.79563150}],"asks":[],"checksum":2380497413,"timestamp":"2024-06-01T22:42:51.231461Z"}]}
{"channel":"book","type":"update","data":[{"symbol":"ETH/EUR","bids":[{"price":3521.66,"qty":26.17378086}],"asks":[],"checksum":2877874144,"timestamp":"2024-06-01T22:42:51.235105Z"}]}
{"channel":"book","type":"update","data":[{"symbol":"ETH/EUR","bids":[{"price":3521.66,"qty":0.00000000},{"price":3521.52,"qty":1.79563150}],"asks":[],"checksum":2380497413,"timestamp":"2024-06-01T22:42:51.252643Z"}]}
{"channel":"book","type":"update","data":[{"symbol":"ETH/EUR","bids":[{"price":3521.66,"qty":26.17382011}],"asks":[],"checksum":1746506838,"timestamp":"2024-06-01T22:42:51.293025Z"}]}
{"channel":"book","type":"update","data":[{"symbol":"ETH/EUR","bids":[{"price":3521.66,"qty":0.00000000},{"price":3521.52,"qty":1.79563150}],"asks":[],"checksum":2380497413,"timestamp":"2024-06-01T22:42:51.423932Z"}]}
{"channel":"book","type":"update","data":[{"symbol":"ETH/EUR","bids":[{"price":3521.67,"qty":26.17374804}],"asks":[],"checksum":3707689476,"timestamp":"2024-06-01T22:42:51.427920Z"}]}
{"channel":"book","type":"update","data":[{"symbol":"ETH/EUR","bids":[{"price":3521.67,"qty":0.00000000},{"price":3521.52,"qty":1.79563150}],"asks":[],"checksum":2380497413,"timestamp":"2024-06-01T22:42:51.446365Z"}]}
{"channel":"book","type":"update","data":[{"symbol":"ETH/EUR","bids":[],"asks":[{"price":3523.22,"qty":0.00000000},{"price":3523.25,"qty":1.70774845}],"checksum":1738292067,"timestamp":"2024-06-01T22:42:51.452201Z"}]}
{"channel":"book","type":"update","data":[{"symbol":"ETH/EUR","bids":[{"price":3521.68,"qty":26.17366692}],"asks":[],"checksum":4140613053,"timestamp":"2024-06-01T22:42:51.493802Z"}]}
{"channel":"book","type":"update","data":[{"symbol":"ETH/EUR","bids":[{"price":3521.71,"qty":0.00000000},{"price":3521.52,"qty":1.79563150},{"price":3522.17,"qty":0.08527800}],"asks":[],"checksum":1951789798,"timestamp":"2024-06-01T22:42:51.541431Z"}]}
{"channel":"book","type":"update","data":[{"symbol":"ETH/EUR","bids":[{"price":3521.68,"qty":0.00000000},{"price":3521.52,"qty":1.79563150}],"asks":[],"checksum":4129792309,"timestamp":"2024-06-01T22:42:51.557773Z"}]}
{"channel":"book","type":"update","data":[{"symbol":"ETH/EUR","bids":[{"price":3521.66,"qty":26.17377420}],"asks":[],"checksum":2909545515,"timestamp":"2024-06-01T22:42:51.561729Z"}]}
{"channel":"book","type":"update","data":[{"symbol":"ETH/EUR","bids":[{"price":3521.66,"qty":0.00000000},{"price":3521.52,"qty":1.79563150}],"asks":[],"checksum":4129792309,"timestamp":"2024-06-01T22:42:51.574897Z"}]}
{"channel":"book","type":"update","data":[{"symbol":"ETH/EUR","bids":[{"price":3521.67,"qty":26.17374019}],"asks":[],"checksum":236005117,"timestamp":"2024-06-01T22:42:51.626179Z"}]}
{"channel":"book","type":"update","data":[{"symbol":"ETH/EUR","bids":[{"price":3521.67,"qty":0.00000000},{"price":3521.52,"qty":1.79563150}],"asks":[],"checksum":4129792309,"timestamp":"2024-06-01T22:42:51.668223Z"}]}
{"channel":"book","type":"update","data":[{"symbol":"ETH/EUR","bids":[{"price":3521.65,"qty":26.17384747}],"asks":[],"checksum":1895599467,"timestamp":"2024-06-01T22:42:51.679787Z"}]}
{"channel":"book","type":"update","data":[{"symbol":"ETH/EUR","bids":[{"price":3521.65,"qty":0.00000000},{"price":3521.50,"qty":0.00220000}],"asks":[],"checksum":2850516589,"timestamp":"2024-06-01T22:42:51.685596Z"}]}
{"channel":"book","type":"update","data":[{"symbol":"ETH/EUR","bids":[{"price":3521.62,"qty":0.00000000},{"price":3521.49,"qty":26.17503431}],"asks":[],"checksum":840866053,"timestamp":"2024-06-01T22:42:51.738027Z"}]}
{"channel":"book","type":"update","data":[{"symbol":"ETH/EUR","bids":[{"price":3521.60,"qty":26.17426580}],"asks":[],"checksum":2291219480,"timestamp":"2024-06-01T22:42:51.744110Z"}]}
{"channel":"book","type":"update","data":[{"symbol":"ETH/EUR","bids":[{"price":3521.61,"qty":26.17419777}],"asks":[],"checksum":3715996491,"timestamp":"2024-06-01T22:42:51.903209Z"}]}
{"channel":"book","type":"update","data":[{"symbol":"ETH/EUR","bids":[{"price":3521.61,"qty":0.00000000},{"price":3521.50,"qty":0.00220000}],"asks":[],"checksum":2291219480,"timestamp":"2024-06-01T22:42:51.957533Z"}]}
{"channel":"book","type":"update","data":[{"symbol":"ETH/EUR","bids":[{"price":3521.62,"qty":26.17412450}],"asks":[],"checksum":3666590865,"timestamp":"2024-06-01T22:42:51.962176Z"}]}
{"channel":"book","type":"update","data":[{"symbol":"ETH/EUR","bids":[{"price":3521.62,"qty":0.00000000},{"price":3521.50,"qty":0.00220000}],"asks":[],"checksum":2291219480,"timestamp":"2024-06-01T22:42:52.157241Z"}]}
{"channel":"book","type":"update","data":[{"symbol":"ETH/EUR","bids":[{"price":3521.60,"qty":0.00000000},{"price":3521.43,"qty":0.47730308}],"asks":[],"checksum":1563447701,"timestamp":"2024-06-01T22:42:52.157356Z"}]}
{"channel":"book","type":"update","data":[{"symbol":"ETH/EUR","bids":[],"asks":[{"price":3523.03,"qty":39.24555490}],"checksum":2237905938,"timestamp":"2024-06-01T22:42:52.162025Z"}]}
{"channel":"book","type":"update","data":[{"symbol":"ETH/EUR","bids":[{"price":3521.51,"qty":26.17493004}],"asks":[],"checksum":3996202201,"timestamp":"2024-06-01T22:42:52.162063Z"}]}
{"channel":"book","type":"update","data":[{"symbol":"ETH/EUR","bids":[{"price":3521.58,"qty":26.17441087}],"asks":[],"checksum":1772522544,"timestamp":"2024-06-01T22:42:52.162111Z"}]}
{"channel":"book","type":"update","data":[{"symbol":"ETH/EUR","bids":[{"price":3521.58,"qty":0.00000000},{"price":3521.50,"qty":0.00220000}],"asks":[],"checksum":3996202201,"timestamp":"2024-06-01T22:42:52.206220Z"}]}
{"channel":"book","type":"update","data":[{"symbol":"ETH/EUR","bids":[{"price":3521.81,"qty":0.00000000},{"price":3521.43,"qty":0.47730308}],"asks":[],"checksum":569097882,"timestamp":"2024-06-01T22:42:52.226264Z"}]}
{"channel":"book","type":"update","data":[{"symbol":"ETH/EUR","bids":[{"price":3521.73,"qty":0.00000000},{"price":3521.42,"qty":1.79568249}],"asks":[],"checksum":3740186747,"timestamp":"2024-06-01T22:42:52.228781Z"}]}
{"channel":"book","type":"update","data":[{"symbol":"ETH/EUR","bids":[{"price":3521.57,"qty":26.17445184}],"asks":[],"checksum":1615564710,"timestamp":"2024-06-01T22:42:52.244686Z"}]}
{"channel":"book","type":"update","data":[{"symbol":"ETH/EUR","bids":[{"price":3521.82,"qty":0.00000000},{"price":3521.42,"qty":1.79568249},{"price":3521.74,"qty":0.04445245}],"asks":[],"checksum":2993298447,"timestamp":"2024-06-01T22:42:52.268884Z"}]}
{"channel":"book","type":"update","data":[{"symbol":"ETH/EUR","bids":[{"price":3521.57,"qty":0.00000000},{"price":3521.42,"qty":1.79568249}],"asks":[],"checksum":4076399709,"timestamp":"2024-06-01T22:42:52.273673Z"}]}
{"channel":"book","type":"update","data":[{"symbol":"ETH/EUR","bids":[{"price":3521.73,"qty":1.58982737}],"asks":[],"checksum":234744508,"timestamp":"2024-06-01T22:42:52.280741Z"}]}
{"channel":"book","type":"update","data":[{"symbol":"ETH/EUR","bids":[{"price":3521.51,"qty":0.00000000},{"price":3521.42,"qty":1.79568249}],"asks":[],"checksum":154541270,"timestamp":"2024-06-01T22:42:52.296760Z"}]}
{"channel":"book","type":"update","data":[{"symbol":"ETH/EUR","bids":[{"price":3521.63,"qty":26.17401795}],"asks":[],"checksum":191737316,"timestamp":"2024-06-01T22:42:52.302320Z"}]}
{"channel":"book","type":"update","data":[{"symbol":"ETH/EUR","bids":[{"price":3521.63,"qty":0.00000000},{"price":3521.42,"qty":1.79568249}],"asks":[],"checksum":154541270,"timestamp":"2024-06-01T22:42:52.306185Z"}]}
{"channel":"book","type":"update","data":[{"symbol":"ETH/EUR","bids":[{"price":3521.74,"qty":0.00000000},{"price":3521.40,"qty":26.17791820},{"price":3521.58,"qty":0.04445446}],"asks":[],"checksum":1774972790,"timestamp":"2024-06-01T22:42:52.325223Z"}]}
{"channel":"book","type":"update","data":[{"symbol":"ETH/EUR","bids":[{"price":3521.67,"qty":26.17374091}],"asks":[],"checksum":1652711684,"timestamp":"2024-06-01T22:42:52.352304Z"}]}
{"channel":"book","type":"update","data":[{"symbol":"ETH/EUR","bids":[{"price":3521.67,"qty":0.00000000},{"price":3521.40,"qty":26.17791820}],"asks":[],"checksum":2749999502,"timestamp":"2024-06-01T22:42:52.404372Z"}]}
{"channel":"book","type":"update","data":[{"symbol":"ETH/EUR","bids":[{"price":3521.65,"qty":26.17387665}],"asks":[],"checksum":1547047748,"timestamp":"2024-06-01T22:42:52.408521Z"}]}
{"channel":"book","type":"update","data":[{"symbol":"ETH/EUR","bids":[{"price":3521.59,"qty":26.17435426}],"asks":[],"checksum":539579523,"timestamp":"2024-06-01T22:42:52.408593Z"}]}
{"channel":"book","type":"update","data":[{"symbol":"ETH/EUR","bids":[{"price":3521.58,"qty":0.00000000},{"price":3521.43,"qty":0.47730308},{"price":3521.74,"qty":0.04445245}],"asks":[],"checksum":2315025467,"timestamp":"2024-06-01T22:42:52.473835Z"}]}
{"channel":"book","type":"update","data":[{"symbol":"ETH/EUR","bids":[{"price":3521.65,"qty":0.00000000},{"price":3521.43,"qty":0.47730308}],"asks":[],"checksum":3153343665,"timestamp":"2024-06-01T22:42:52.494727Z"}]}
{"channel":"book","type":"update","data":[{"symbol":"ETH/EUR","bids":[{"price":3521.61,"qty":26.17419165}],"asks":[],"checksum":1339902762,"timestamp":"2024-06-01T22:42:52.498575Z"}]}
{"channel":"book","type":"update","data":[{"symbol":"ETH/EUR","bids":[{"price":3521.61,"qty":0.00000000},{"price":3521.43,"qty":0.47730308}],"asks":[],"checksum":3153343665,"timestamp":"2024-06-01T22:42:52.562031Z"}]}
{"channel":"book","type":"update","data":[{"symbol":"ETH/EUR","bids":[{"price":3521.62,"qty":26.17413931}],"asks":[],"checksum":2854561249,"timestamp":"2024-06-01T22:42:52.566036Z"}]}
{"channel":"book","type":"update","data":[{"symbol":"ETH/EUR","bids":[{"price":3521.92,"qty":0.47730308}],"asks":[],"checksum":1242830968,"timestamp":"2024-06-01T22:42:52.608417Z"}]}
{"channel":"book","type":"update","data":[{"symbol":"ETH/EUR","bids":[{"price":3521.62,"qty":0.00000000},{"price":3521.50,"qty":0.00220000}],"asks":[],"checksum":2565713260,"timestamp":"2024-06-01T22:42:52.611841Z"}]}
{"channel":"book","type":"update","data":[{"symbol":"ETH/EUR","bids":[{"price":3521.60,"qty":26.17422305}],"asks":[],"checksum":1844344454,"timestamp":"2024-06-01T22:42:52.615845Z"}]}
{"channel":"book","type":"update","data":[{"symbol":"ETH/EUR","bids":[{"price":3521.60,"qty":0.00000000},{"price":3521.50,"qty":0.00220000}],"asks":[],"checksum":2565713260,"timestamp":"2024-06-01T22:42:52.649398Z"}]}
{"channel":"book","type":"update","data":[{"symbol":"ETH/EUR","bids":[{"price":3521.59,"qty":0.00000000},{"price":3521.43,"qty":0.47730308}],"asks":[],"checksum":2476183052,"timestamp":"2024-06-01T22:42:52.683732Z"}]}
{"channel":"book","type":"update","data":[{"symbol":"ETH/EUR","bids":[{"price":3521.53,"qty":26.17478159}],"asks":[],"checksum":2126158155,"timestamp":"2024-06-01T22:42:52.683869Z"}]}
{"channel":"book","type":"update","data":[{"symbol":"ETH/EUR","bids":[{"price":3521.57,"qty":26.17448128}],"asks":[],"checksum":1130574747,"timestamp":"2024-06-01T22:42:52.687967Z"}]}
{"channel":"book","type":"update","data":[{"symbol":"ETH/EUR","bids":[{"price":3521.57,"qty":0.00000000},{"price":3521.50,"qty":0.00220000}],"asks":[],"checksum":2126158155,"timestamp":"2024-06-01T22:42:52.723974Z"}]}
{"channel":"book","type":"update","data":[{"symbol":"ETH/EUR","bids":[{"price":3521.58,"qty":26.17441063}],"asks":[],"checksum":3259501863,"timestamp":"2024-06-01T22:42:52.747505Z"}]}
{"channel":"book","type":"update","data":[{"symbol":"ETH/EUR","bids":[],"asks":[{"price":3523.02,"qty":9.00596664}],"checksum":1977004309,"timestamp":"2024-06-01T22:42:52.928941Z"}]}
{"channel":"book","type":"update","data":[{"symbol":"ETH/EUR","bids":[{"price":3521.58,"qty":0.00000000},{"price":3521.50,"qty":0.00220000}],"asks":[],"checksum":3513487710,"timestamp":"2024-06-01T22:42:53.022157Z"}]}
{"channel":"book","type":"update","data":[{"symbol":"ETH/EUR","bids":[{"price":3521.56,"qty":26.17451205}],"asks":[],"checksum":1227601082,"timestamp":"2024-06-01T22:42:53.025876Z"}]}
{"channel":"book","type":"update","data":[{"symbol":"ETH/EUR","bids":[{"price":3521.56,"qty":0.00000000},{"price":3521.50,"qty":0.00220000}],"asks":[],"checksum":3513487710,"timestamp":"2024-06-01T22:42:53.050274Z"}]}
{"channel":"book","type":"update","data":[{"symbol":"ETH/EUR","bids":[{"price":3521.55,"qty":26.17459317}],"asks":[],"checksum":2347297205,"timestamp":"2024-06-01T22:42:53.106773Z"}]}
{"channel":"book","type":"update","data":[{"symbol":"ETH/EUR","bids":[{"price":3522.17,"qty":0.00000000},{"price":3521.50,"qty":0.00220000},{"price":3521.88,"qty":0.08528300}],"asks":[],"checksum":2784995073,"timestamp":"2024-06-01T22:42:53.107347Z"}]}
{"channel":"book","type":"update","data":[{"symbol":"ETH/EUR","bids":[],"asks":[{"price":3523.14,"qty":0.00000000},{"price":3523.24,"qty":0.72912968},{"price":3522.90,"qty":0.08526500}],"checksum":1776000209,"timestamp":"2024-06-01T22:42:53.107555Z"}]}
{"channel":"book","type":"update","data":[{"symbol":"ETH/EUR","bids":[{"price":3521.55,"qty":0.00000000},{"price":3521.50,"qty":0.00220000}],"asks":[],"checksum":396037027,"timestamp":"2024-06-01T22:42:53.473996Z"}]}
{"channel":"book","type":"update","data":[{"symbol":"ETH/EUR","bids":[{"price":3521.56,"qty":26.17456407}],"asks":[],"checksum":62717081,"timestamp":"2024-06-01T22:42:53.478604Z"}]}
{"channel":"book","type":"update","data":[{"symbol":"ETH/EUR","bids":[{"price":3521.56,"qty":0.00000000},{"price":3521.50,"qty":0.00220000}],"asks":[],"checksum":396037027,"timestamp":"2024-06-01T22:42:53.704930Z"}]}
{"channel":"book","type":"update","data":[{"symbol":"ETH/EUR","bids":[{"price":3521.57,"qty":26.17448098}],"asks":[],"checksum":1023085051,"timestamp":"2024-06-01T22:42:53.709494Z"}]}
{"channel":"book","type":"update","data":[{"symbol":"ETH/EUR","bids":[{"price":3521.57,"qty":0.00000000},{"price":3521.50,"qty":0.00220000}],"asks":[],"checksum":396037027,"timestamp":"2024-06-01T22:42:53.753547Z"}]}
{"channel":"book","type":"update","data":[{"symbol":"ETH/EUR","bids":[{"price":3521.59,"qty":26.17433706}],"asks":[],"checksum":3937203366,"timestamp":"2024-06-01T22:42:53.765347Z"}]}
{"channel":"book","type":"update","data":[{"symbol":"ETH/EUR","bids":[{"price":3521.59,"qty":0.00000000},{"price":3521.50,"qty":0.00220000}],"asks":[],"checksum":396037027,"timestamp":"2024-06-01T22:42:53.897755Z"}]}
{"channel":"book","type":"update","data":[{"symbol":"ETH/EUR","bids":[{"price":3521.57,"qty":26.17444038}],"asks":[],"checksum":4249416095,"timestamp":"2024-06-01T22:42:53.904791Z"}]}
{"channel":"book","type":"update","data":[{"symbol":"ETH/EUR","bids":[{"price":3522.39,"qty":0.58730308}],"asks":[],"checksum":3137045926,"timestamp":"2024-06-01T22:42:53.954493Z"}]}
{"channel":"book","type":"update","data":[{"symbol":"ETH/EUR","bids":[{"price":3521.57,"qty":0.00000000},{"price":3521.50,"qty":0.00220000}],"asks":[],"checksum":2041333298,"timestamp":"2024-06-01T22:42:53.955604Z"}]}
{"channel":"book","type":"update","data":[{"symbol":"ETH/EUR","bids":[{"price":3521.53,"qty":0.00000000},{"price":3521.43,"qty":0.47730308}],"asks":[],"checksum":970728646,"timestamp":"2024-06-01T22:42:53.955773Z"}]}
{"channel":"book","type":"update","data":[{"symbol":"ETH/EUR","bids":[{"price":3522.12,"qty":1.58982737}],"asks":[],"checksum":3219595048,"timestamp":"2024-06-01T22:42:53.960375Z"}]}
{"channel":"book","type":"update","data":[{"symbol":"ETH/EUR","bids":[{"price":3521.73,"qty":0.00000000},{"price":3521.43,"qty":0.47730308}],"asks":[],"checksum":4245609991,"timestamp":"2024-06-01T22:42:53.963011Z"}]}
{"channel":"book","type":"update","data":[{"symbol":"ETH/EUR","bids":[{"price":3521.70,"qty":26.17348089}],"asks":[],"checksum":3847123084,"timestamp":"2024-06-01T22:42:53.964900Z"}]}
{"channel":"book","type":"update","data":[{"symbol":"ETH/EUR","bids":[{"price":3521.50,"qty":26.17722270}],"asks":[],"checksum":2492946235,"timestamp":"2024-06-01T22:42:53.964946Z"}]}
{"channel":"book","type":"update","data":[{"symbol":"ETH/EUR","bids":[{"price":3522.39,"qty":0.11000000}],"asks":[],"checksum":3542360834,"timestamp":"2024-06-01T22:42:53.975554Z"}]}
{"channel":"book","type":"update","data":[{"symbol":"ETH/EUR","bids":[{"price":3522.29,"qty":0.47730308}],"asks":[],"checksum":727619348,"timestamp":"2024-06-01T22:42:53.978259Z"}]}
{"channel":"book","type":"update","data":[{"symbol":"ETH/EUR","bids":[{"price":3522.29,"qty":0.00000000},{"price":3521.50,"qty":26.17722270}],"asks":[],"checksum":3542360834,"timestamp":"2024-06-01T22:42:53.983694Z"}]}
{"channel":"book","type":"update","data":[{"symbol":"ETH/EUR","bids":[{"price":3522.12,"qty":0.00000000},{"price":3521.43,"qty":0.47730308}],"asks":[],"checksum":2842112624,"timestamp":"2024-06-01T22:42:53.986024Z"}]}
{"channel":"book","type":"update","data":[{"symbol":"ETH/EUR","bids":[{"price":3521.94,"qty":1.58982737}],"asks":[],"checksum":2846038290,"timestamp":"2024-06-01T22:42:53.986340Z"}]}
{"channel":"book","type":"update","data":[{"symbol":"ETH/EUR","bids":[{"price":3521.74,"qty":0.00000000},{"price":3521.43,"qty":0.47730308},{"price":3521.71,"qty":0.04445283}],"asks":[],"checksum":220422537,"timestamp":"2024-06-01T22:42:53.999633Z"}]}
{"channel":"book","type":"update","data":[{"symbol":"ETH/EUR","bids":[{"price":3521.74,"qty":26.17324145}],"asks":[],"checksum":1830058670,"timestamp":"2024-06-01T22:42:54.013214Z"}]}
{"channel":"book","type":"update","data":[{"symbol":"ETH/EUR","bids":[{"price":3521.74,"qty":0.00000000},{"price":3521.50,"qty":26.17722270}],"asks":[],"checksum":220422537,"timestamp":"2024-06-01T22:42:54.026299Z"}]}
{"channel":"book","type":"update","data":[{"symbol":"ETH/EUR","bids":[{"price":3522.39,"qty":2.51500000}],"asks":[],"checksum":2524400707,"timestamp":"2024-06-01T22:42:54.067408Z"}]}
{"channel":"book","type":"update","data":[{"symbol":"ETH/EUR","bids":[{"price":3522.39,"qty":2.99230308}],"asks":[],"checksum":1237280988,"timestamp":"2024-06-01T22:42:54.069616Z"}]}
{"channel":"book","type":"update","data":[{"symbol":"ETH/EUR","bids":[{"price":3521.71,"qty":26.21786175}],"asks":[],"checksum":1128287351,"timestamp":"2024-06-01T22:42:54.070175Z"}]}
{"channel":"book","type":"update","data":[{"symbol":"ETH/EUR","bids":[{"price":3522.12,"qty":1.58982737}],"asks":[],"checksum":335682414,"timestamp":"2024-06-01T22:42:54.073851Z"}]}
{"channel":"book","type":"update","data":[{"symbol":"ETH/EUR","bids":[{"price":3521.94,"qty":0.00000000},{"price":3521.50,"qty":26.17722270}],"asks":[],"checksum":152250247,"timestamp":"2024-06-01T22:42:54.076304Z"}]}
{"channel":"book","type":"update","data":[{"symbol":"ETH/EUR","bids":[],"asks":[{"price":3523.08,"qty":1.70774845}],"checksum":2334005520,"timestamp":"2024-06-01T22:42:54.114977Z"}]}
{"channel":"book","type":"update","data":[{"symbol":"ETH/EUR","bids":[{"price":3522.39,"qty":2.51500000}],"asks":[],"checksum":419843366,"timestamp":"2024-06-01T22:42:54.126189Z"}]}
{"channel":"book","type":"update","data":[{"symbol":"ETH/EUR","bids":[{"price":3522.12,"qty":0.00000000},{"price":3521.43,"qty":0.47730308}],"asks":[],"checksum":1925252664,"timestamp":"2024-06-01T22:42:54.128545Z"}]}
{"channel":"book","type":"update","data":[{"symbol":"ETH/EUR","bids":[{"price":3521.87,"qty":1.58982737}],"asks":[],"checksum":3294855786,"timestamp":"2024-06-01T22:42:54.128924Z"}]}
{"channel":"book","type":"update","data":[{"symbol":"ETH/EUR","bids":[{"price":3521.71,"qty":0.04445283}],"asks":[],"checksum":182849077,"timestamp":"2024-06-01T22:42:54.177241Z"}]}
{"channel":"book","type":"update","data":[{"symbol":"ETH/EUR","bids":[{"price":3521.72,"qty":26.17339584}],"asks":[],"checksum":2612882236,"timestamp":"2024-06-01T22:42:54.180496Z"}]}
{"channel":"book","type":"update","data":[{"symbol":"ETH/EUR","bids":[{"price":3521.72,"qty":0.00000000},{"price":3521.50,"qty":26.17722270}],"asks":[],"checksum":182849077,"timestamp":"2024-06-01T22:42:54.453851Z"}]}
{"channel":"book","type":"update","data":[{"symbol":"ETH/EUR","bids":[{"price":3521.63,"qty":26.17401903}],"asks":[],"checksum":3496352888,"timestamp":"2024-06-01T22:42:54.457259Z"}]}
{"channel":"book","type":"update","data":[{"symbol":"ETH/EUR","bids":[{"price":3521.71,"qty":0.00000000},{"price":3521.50,"qty":26.17722270},{"price":3521.93,"qty":0.04443796}],"asks":[],"checksum":739768235,"timestamp":"2024-06-01T22:42:54.461533Z"}]}
{"channel":"book","type":"update","data":[{"symbol":"ETH/EUR","bids":[{"price":3521.70,"qty":0.00000000},{"price":3521.50,"qty":26.17722270}],"asks":[],"checksum":806620863,"timestamp":"2024-06-01T22:42:54.486531Z"}]}
{"channel":"book","type":"update","data":[{"symbol":"ETH/EUR","bids":[{"price":3521.67,"qty":26.17374648}],"asks":[],"checksum":1373391458,"timestamp":"2024-06-01T22:42:54.491024Z"}]}
{"channel":"book","type":"update","data":[{"symbol":"ETH/EUR","bids":[{"price":3521.67,"qty":0.00000000},{"price":3521.50,"qty":26.17722270}],"asks":[],"checksum":806620863,"timestamp":"2024-06-01T22:42:54.501728Z"}]}
{"channel":"book","type":"update","data":[{"symbol":"ETH/EUR","bids":[{"price":3521.67,"qty":26.17373189}],"asks":[],"checksum":1643763187,"timestamp":"2024-06-01T22:42:54.560108Z"}]}
{"channel":"book","type":"update","data":[{"symbol":"ETH/EUR","bids":[{"price":3521.67,"qty":0.00000000},{"price":3521.50,"qty":26.17722270}],"asks":[],"checksum":806620863,"timestamp":"2024-06-01T22:42:54.564614Z"}]}
{"channel":"book","type":"update","data":[{"symbol":"ETH/EUR","bids":[{"price":3521.71,"qty":26.17344667}],"asks":[],"checksum":1417162765,"timestamp":"2024-06-01T22:42:54.611282Z"}]}
{"channel":"book","type":"update","data":[{"symbol":"ETH/EUR","bids":[{"price":3521.71,"qty":0.00000000},{"price":3521.50,"qty":26.17722270}],"asks":[],"checksum":806620863,"timestamp":"2024-06-01T22:42:54.615093Z"}]}
{"channel":"book","type":"update","data":[{"symbol":"ETH/EUR","bids":[{"price":3521.69,"qty":26.17355134}],"asks":[],"checksum":2427196010,"timestamp":"2024-06-01T22:42:54.665010Z"}]}
{"channel":"book","type":"update","data":[{"symbol":"ETH/EUR","bids":[{"price":3522.39,"qty":2.99230308}],"asks":[],"checksum":1331967733,"timestamp":"2024-06-01T22:42:54.710917Z"}]}
{"channel":"book","type":"update","data":[{"symbol":"ETH/EUR","bids":[{"price":3521.69,"qty":0.00000000},{"price":3521.50,"qty":26.17722270}],"asks":[],"checksum":4024183328,"timestamp":"2024-06-01T22:42:55.020143Z"}]}
{"channel":"book","type":"update","data":[{"symbol":"ETH/EUR","bids":[{"price":3521.70,"qty":26.17347807}],"asks":[],"checksum":3499419658,"timestamp":"2024-06-01T22:42:55.024422Z"}]}
{"channel":"book","type":"update","data":[{"symbol":"ETH/EUR","bids":[{"price":3522.39,"qty":2.51500000}],"asks":[],"checksum":257739925,"timestamp":"2024-06-01T22:42:55.063282Z"}]}
{"channel":"book","type":"update","data":[{"symbol":"ETH/EUR","bids":[{"price":3522.39,"qty":0.11000000}],"asks":[],"checksum":2743426587,"timestamp":"2024-06-01T22:42:55.119508Z"}]}
{"channel":"book","type":"update","data":[{"symbol":"ETH/EUR","bids":[],"asks":[{"price":3523.02,"qty":0.00000000},{"price":3523.18,"qty":0.08386355}],"checksum":213252160,"timestamp":"2024-06-01T22:42:55.226427Z"}]}
{"channel":"book","type":"update","data":[{"symbol":"ETH/EUR","bids":[{"price":3521.70,"qty":0.00000000},{"price":3521.50,"qty":26.17722270}],"asks":[],"checksum":872233578,"timestamp":"2024-06-01T22:42:55.399404Z"}]}
{"channel":"book","type":"update","data":[{"symbol":"ETH/EUR","bids":[{"price":3521.71,"qty":26.17342574}],"asks":[],"checksum":3425497793,"timestamp":"2024-06-01T22:42:55.403634Z"}]}
{"channel":"book","type":"update","data":[{"symbol":"ETH/EUR","bids":[{"price":3521.71,"qty":0.00000000},{"price":3521.50,"qty":26.17722270}],"asks":[],"checksum":872233578,"timestamp":"2024-06-01T22:42:55.539363Z"}]}
{"channel":"book","type":"update","data":[{"symbol":"ETH/EUR","bids":[{"price":3521.69,"qty":26.17356817}],"asks":[],"checksum":3034695343,"timestamp":"2024-06-01T22:42:55.543101Z"}]}
{"channel":"book","type":"update","data":[{"symbol":"ETH/EUR","bids":[{"price":3521.69,"qty":0.00000000},{"price":3521.50,"qty":26.17722270}],"asks":[],"checksum":872233578,"timestamp":"2024-06-01T22:42:55.588775Z"}]}
{"channel":"book","type":"update","data":[{"symbol":"ETH/EUR","bids":[{"price":3521.70,"qty":26.17351849}],"asks":[],"checksum":1572915611,"timestamp":"2024-06-01T22:42:55.615559Z"}]}
{"channel":"book","type":"update","data":[{"symbol":"ETH/EUR","bids":[],"asks":[{"price":3523.12,"qty":0.00000000},{"price":3523.24,"qty":0.72912968}],"checksum":3639779669,"timestamp":"2024-06-01T22:42:56.323540Z"}]}
{"channel":"book","type":"update","data":[{"symbol":"ETH/EUR","bids":[{"price":3521.63,"qty":0.00000000},{"price":3521.50,"qty":26.17722270}],"asks":[],"checksum":41071384,"timestamp":"2024-06-01T22:42:56.347176Z"}]}
{"channel":"book","type":"update","data":[{"symbol":"ETH/EUR","bids":[{"price":3522.39,"qty":0.58730308}],"asks":[],"checksum":1170327329,"timestamp":"2024-06-01T22:42:56.347188Z"}]}
{"channel":"book","type":"update","data":[{"symbol":"ETH/EUR","bids":[],"asks":[{"price":3522.40,"qty":80.10503299}],"checksum":1168956031,"timestamp":"2024-06-01T22:42:56.347270Z"}]}
{"channel":"book","type":"update","data":[{"symbol":"ETH/EUR","bids":[{"price":3521.76,"qty":26.17306342}],"asks":[],"checksum":45541630,"timestamp":"2024-06-01T22:42:56.351701Z"}]}
{"channel":"book","type":"update","data":[{"symbol":"ETH/EUR","bids":[],"asks":[{"price":3522.40,"qty":106.27337732}],"checksum":47969696,"timestamp":"2024-06-01T22:42:56.351719Z"}]}
{"channel":"book","type":"update","data":[{"symbol":"ETH/EUR","bids":[],"asks":[{"price":3523.03,"qty":0.00000000},{"price":3523.53,"qty":10.00000000}],"checksum":3052466108,"timestamp":"2024-06-01T22:42:56.354104Z"}]}
{"channel":"book","type":"update","data":[{"symbol":"ETH/EUR","bids":[],"asks":[{"price":3522.40,"qty":80.10503299}],"checksum":3047027426,"timestamp":"2024-06-01T22:42:56.355394Z"}]}
{"channel":"book","type":"update","data":[{"symbol":"ETH/EUR","bids":[],"asks":[{"price":3523.33,"qty":39.24217452}],"checksum":1032832518,"timestamp":"2024-06-01T22:42:56.360256Z"}]}
{"channel":"book","type":"update","data":[{"symbol":"ETH/EUR","bids":[{"price":3521.76,"qty":0.00000000},{"price":3521.50,"qty":26.17722270}],"asks":[],"checksum":2056647815,"timestamp":"2024-06-01T22:42:56.363479Z"}]}
{"channel":"book","type":"update","data":[{"symbol":"ETH/EUR","bids":[],"asks":[{"price":3523.08,"qty":0.00000000},{"price":3523.53,"qty":10.00000000}],"checksum":3657512500,"timestamp":"2024-06-01T22:42:56.370113Z"}]}
{"channel":"book","type":"update","data":[{"symbol":"ETH/EUR","bids":[],"asks":[{"price":3523.32,"qty":1.04800000}],"checksum":2612265814,"timestamp":"2024-06-01T22:42:56.422133Z"}]}
{"channel":"book","type":"update","data":[{"symbol":"ETH/EUR","bids":[{"price":3521.50,"qty":0.00220000}],"asks":[],"checksum":2763852880,"timestamp":"2024-06-01T22:42:56.430050Z"}]}
{"channel":"book","type":"update","data":[{"symbol":"ETH/EUR","bids":[],"asks":[{"price":3522.40,"qty":53.93668866}],"checksum":3064679268,"timestamp":"2024-06-01T22:42:56.430104Z"}]}
{"channel":"book","type":"update","data":[{"symbol":"ETH/EUR","bids":[],"asks":[{"price":3522.40,"qty":52.33668866}],"checksum":922614253,"timestamp":"2024-06-01T22:42:56.430703Z"}]}
{"channel":"book","type":"update","data":[{"symbol":"ETH/EUR","bids":[{"price":3521.93,"qty":1.64443796}],"asks":[],"checksum":1273329306,"timestamp":"2024-06-01T22:42:56.433343Z"}]}
{"channel":"book","type":"update","data":[{"symbol":"ETH/EUR","bids":[],"asks":[{"price":3523.24,"qty":0.00000000},{"price":3523.53,"qty":10.00000000}],"checksum":4120983501,"timestamp":"2024-06-01T22:42:56.435325Z"}]}
{"channel":"book","type":"update","data":[{"symbol":"ETH/EUR","bids":[{"price":3521.53,"qty":0.72912968}],"asks":[],"checksum":3908336484,"timestamp":"2024-06-01T22:42:56.435339Z"}]}
{"channel":"book","type":"update","data":[{"symbol":"ETH/EUR","bids":[],"asks":[{"price":3522.49,"qty":26.16767845}],"checksum":161163943,"timestamp":"2024-06-01T22:42:56.436326Z"}]}
{"channel":"book","type":"update","data":[{"symbol":"ETH/EUR","bids":[{"price":3522.05,"qty":26.17088082}],"asks":[],"checksum":2243101965,"timestamp":"2024-06-01T22:42:56.436372Z"}]}
{"channel":"book","type":"update","data":[{"symbol":"ETH/EUR","bids":[{"price":3521.83,"qty":26.17251930}],"asks":[],"checksum":2751144036,"timestamp":"2024-06-01T22:42:56.441572Z"}]}
{"channel":"book","type":"update","data":[{"symbol":"ETH/EUR","bids":[{"price":3522.05,"qty":0.00000000},{"price":3521.70,"qty":26.17351849}],"asks":[],"checksum":1281013636,"timestamp":"2024-06-01T22:42:56.480165Z"}]}
{"channel":"book","type":"update","data":[{"symbol":"ETH/EUR","bids":[{"price":3522.03,"qty":26.17102076}],"asks":[],"checksum":2661573782,"timestamp":"2024-06-01T22:42:56.486383Z"}]}
{"channel":"book","type":"update","data":[{"symbol":"ETH/EUR","bids":[{"price":3522.03,"qty":0.00000000},{"price":3521.70,"qty":26.17351849}],"asks":[],"checksum":1281013636,"timestamp":"2024-06-01T22:42:56.538922Z"}]}
{"channel":"book","type":"update","data":[{"symbol":"ETH/EUR","bids":[{"price":3522.21,"qty":0.62902689}],"asks":[],"checksum":2317653316,"timestamp":"2024-06-01T22:42:56.542392Z"}]}
{"channel":"book","type":"update","data":[{"symbol":"ETH/EUR","bids":[{"price":3522.02,"qty":26.17116728}],"asks":[],"checksum":1919440271,"timestamp":"2024-06-01T22:42:56.543290Z"}]}
{"channel":"book","type":"update","data":[{"symbol":"ETH/EUR","bids":[{"price":3522.03,"qty":1.60000000}],"asks":[],"checksum":1320004884,"timestamp":"2024-06-01T22:42:56.545893Z"}]}
{"channel":"book","type":"update","data":[{"symbol":"ETH/EUR","bids":[{"price":3521.93,"qty":0.04443796}],"asks":[],"checksum":2501719904,"timestamp":"2024-06-01T22:42:56.545917Z"}]}
{"channel":"book","type":"update","data":[{"symbol":"ETH/EUR","bids":[{"price":3522.02,"qty":0.00000000},{"price":3521.83,"qty":26.17251930}],"asks":[],"checksum":3095601577,"timestamp":"2024-06-01T22:42:56.559321Z"}]}
{"channel":"book","type":"update","data":[{"symbol":"ETH/EUR","bids":[{"price":3522.39,"qty":2.19730308}],"asks":[],"checksum":1957938512,"timestamp":"2024-06-01T22:42:56.568039Z"}]}
{"channel":"book","type":"update","data":[{"symbol":"ETH/EUR","bids":[{"price":3522.06,"qty":26.17086900}],"asks":[],"checksum":46910380,"timestamp":"2024-06-01T22:42:56.595289Z"}]}
{"channel":"book","type":"update","data":[{"symbol":"ETH/EUR","bids":[{"price":3522.06,"qty":0.00000000},{"price":3521.83,"qty":26.17251930}],"asks":[],"checksum":1957938512,"timestamp":"2024-06-01T22:42:56.610418Z"}]}
{"channel":"book","type":"update","data":[{"symbol":"ETH/EUR","bids":[{"price":3521.99,"qty":26.17135701}],"asks":[],"checksum":1864039357,"timestamp":"2024-06-01T22:42:56.648708Z"}]}
{"channel":"book","type":"update","data":[{"symbol":"ETH/EUR","bids":[{"price":3521.93,"qty":26.21625091}],"asks":[],"checksum":3193754916,"timestamp":"2024-06-01T22:42:56.648770Z"}]}
{"channel":"book","type":"update","data":[{"symbol":"ETH/EUR","bids":[],"asks":[{"price":3522.49,"qty":0.00000000},{"price":3523.37,"qty":1.70774845}],"checksum":3693253468,"timestamp":"2024-06-01T22:42:56.651661Z"}]}
{"channel":"book","type":"update","data":[{"symbol":"ETH/EUR","bids":[{"price":3521.99,"qty":0.00000000},{"price":3521.83,"qty":26.17251930}],"asks":[],"checksum":766301211,"timestamp":"2024-06-01T22:42:56.659657Z"}]}
{"channel":"book","type":"update","data":[{"symbol":"ETH/EUR","bids":[{"price":3521.83,"qty":0.00000000},{"price":3521.80,"qty":0.00220000}],"asks":[],"checksum":1295348837,"timestamp":"2024-06-01T22:42:56.686398Z"}]}
{"channel":"book","type":"update","data":[{"symbol":"ETH/EUR","bids":[{"price":3521.93,"qty":0.04443796}],"asks":[],"checksum":3343504074,"timestamp":"2024-06-01T22:42:56.689096Z"}]}
{"channel":"book","type":"update","data":[{"symbol":"ETH/EUR","bids":[],"asks":[{"price":3523.37,"qty":0.00000000},{"price":3523.53,"qty":10.00000000}],"checksum":343908015,"timestamp":"2024-06-01T22:42:56.699483Z"}]}
{"channel":"book","type":"update","data":[{"symbol":"ETH/EUR","bids":[],"asks":[{"price":3523.23,"qty":1.70774845}],"checksum":3058313437,"timestamp":"2024-06-01T22:42:56.816632Z"}]}
{"channel":"book","type":"update","data":[{"symbol":"ETH/EUR","bids":[{"price":3521.84,"qty":26.17246871}],"asks":[],"checksum":2300686392,"timestamp":"2024-06-01T22:42:56.854306Z"}]}
{"channel":"book","type":"update","data":[{"symbol":"ETH/EUR","bids":[{"price":3521.92,"qty":26.64918003}],"asks":[],"checksum":4018986283,"timestamp":"2024-06-01T22:42:56.854363Z"}]}
{"channel":"book","type":"update","data":[{"symbol":"ETH/EUR","bids":[],"asks":[{"price":3522.66,"qty":26.16647401}],"checksum":3248506486,"timestamp":"2024-06-01T22:42:56.854449Z"}]}
{"channel":"book","type":"update","data":[{"symbol":"ETH/EUR","bids":[],"asks":[{"price":3522.40,"qty":78.50503299}],"checksum":1013019044,"timestamp":"2024-06-01T22:42:56.854472Z"}]}
{"channel":"book","type":"update","data":[{"symbol":"ETH/EUR","bids":[],"asks":[{"price":3523.31,"qty":0.63868344}],"checksum":3945811579,"timestamp":"2024-06-01T22:42:57.029142Z"}]}
{"channel":"book","type":"update","data":[{"symbol":"ETH/EUR","bids":[{"price":3521.92,"qty":0.47730308}],"asks":[],"checksum":3777952419,"timestamp":"2024-06-01T22:42:57.030766Z"}]}
{"channel":"book","type":"update","data":[{"symbol":"ETH/EUR","bids":[{"price":3521.93,"qty":26.21625211}],"asks":[],"checksum":1141274118,"timestamp":"2024-06-01T22:42:57.034310Z"}]}
{"channel":"book","type":"update","data":[{"symbol":"ETH/EUR","bids":[{"price":3521.84,"qty":0.00000000},{"price":3521.80,"qty":0.00220000}],"asks":[],"checksum":738377934,"timestamp":"2024-06-01T22:42:57.060154Z"}]}
{"channel":"book","type":"update","data":[{"symbol":"ETH/EUR","bids":[{"price":3521.96,"qty":26.17155773}],"asks":[],"checksum":2291112882,"timestamp":"2024-06-01T22:42:57.087422Z"}]}
{"channel":"book","type":"update","data":[{"symbol":"ETH/EUR","bids":[{"price":3521.96,"qty":0.00000000},{"price":3521.80,"qty":0.00220000}],"asks":[],"checksum":738377934,"timestamp":"2024-06-01T22:42:57.125079Z"}]}
{"channel":"book","type":"update","data":[{"symbol":"ETH/EUR","bids":[{"price":3521.94,"qty":26.17171473}],"asks":[],"checksum":1798958321,"timestamp":"2024-06-01T22:42:57.191933Z"}]}
{"channel":"book","type":"update","data":[{"symbol":"ETH/EUR","bids":[{"price":3521.94,"qty":0.00000000},{"price":3521.80,"qty":0.00220000}],"asks":[],"checksum":738377934,"timestamp":"2024-06-01T22:42:57.203973Z"}]}
{"channel":"book","type":"update","data":[{"symbol":"ETH/EUR","bids":[{"price":3521.93,"qty":26.17181415},{"price":3522.04,"qty":0.04443662}],"asks":[],"checksum":4051343852,"timestamp":"2024-06-01T22:42:57.212790Z"}]}
{"channel":"book","type":"update","data":[{"symbol":"ETH/EUR","bids":[{"price":3521.87,"qty":27.76210768}],"asks":[],"checksum":3692726923,"timestamp":"2024-06-01T22:42:57.270640Z"}]}
{"channel":"book","type":"update","data":[{"symbol":"ETH/EUR","bids":[{"price":3521.93,"qty":0.00000000},{"price":3521.80,"qty":0.00220000}],"asks":[],"checksum":2389482859,"timestamp":"2024-06-01T22:42:57.276699Z"}]}
{"channel":"book","type":"update","data":[{"symbol":"ETH/EUR","bids":[],"asks":[{"price":3522.66,"qty":0.00000000},{"price":3523.32,"qty":1.04800000}],"checksum":188202024,"timestamp":"2024-06-01T22:42:57.279805Z"}]}
{"channel":"book","type":"update","data":[{"symbol":"ETH/EUR","bids":[{"price":3522.12,"qty":1.58982737}],"asks":[],"checksum":2763283247,"timestamp":"2024-06-01T22:42:57.281889Z"}]}
{"channel":"book","type":"update","data":[{"symbol":"ETH/EUR","bids":[{"price":3522.03,"qty":0.00000000},{"price":3521.80,"qty":0.00220000}],"asks":[],"checksum":3692058778,"timestamp":"2024-06-01T22:42:57.282798Z"}]}
{"channel":"book","type":"update","data":[{"symbol":"ETH/EUR","bids":[{"price":3522.21,"qty":0.00000000},{"price":3521.73,"qty":26.17330193}],"asks":[],"checksum":2281732017,"timestamp":"2024-06-01T22:42:57.283022Z"}]}
{"channel":"book","type":"update","data":[{"symbol":"ETH/EUR","bids":[],"asks":[{"price":3523.23,"qty":0.00000000},{"price":3523.33,"qty":39.24217452}],"checksum":562821599,"timestamp":"2024-06-01T22:42:57.283110Z"}]}
{"channel":"book","type":"update","data":[{"symbol":"ETH/EUR","bids":[{"price":3521.87,"qty":26.17228031}],"asks":[],"checksum":933847596,"timestamp":"2024-06-01T22:42:57.284539Z"}]}
{"channel":"book","type":"update","data":[{"symbol":"ETH/EUR","bids":[{"price":3522.39,"qty":1.72000000}],"asks":[],"checksum":1090812803,"timestamp":"2024-06-01T22:42:57.284777Z"}]}
{"channel":"book","type":"update","data":[{"symbol":"ETH/EUR","bids":[{"price":3521.87,"qty":0.00000000},{"price":3521.53,"qty":0.72912968}],"asks":[],"checksum":1481441312,"timestamp":"2024-06-01T22:42:57.288057Z"}]}
{"channel":"book","type":"update","data":[{"symbol":"ETH/EUR","bids":[{"price":3522.29,"qty":0.47730308}],"asks":[],"checksum":2747987543,"timestamp":"2024-06-01T22:42:57.290049Z"}]}
{"channel":"book","type":"update","data":[{"symbol":"ETH/EUR","bids":[{"price":3521.77,"qty":26.17297604}],"asks":[],"checksum":1170296327,"timestamp":"2024-06-01T22:42:57.294227Z"}]}
{"channel":"book","type":"update","data":[{"symbol":"ETH/EUR","bids":[{"price":3521.77,"qty":0.00000000},{"price":3521.73,"qty":26.17330193}],"asks":[],"checksum":2747987543,"timestamp":"2024-06-01T22:42:57.301212Z"}]}
{"channel":"book","type":"update","data":[{"symbol":"ETH/EUR","bids":[{"price":3522.04,"qty":0.00000000},{"price":3521.59,"qty":26.17429441},{"price":3521.78,"qty":0.04443990}],"asks":[],"checksum":1524592000,"timestamp":"2024-06-01T22:42:57.336909Z"}]}
{"channel":"book","type":"update","data":[{"symbol":"ETH/EUR","bids":[{"price":3521.82,"qty":26.17264621}],"asks":[],"checksum":904914669,"timestamp":"2024-06-01T22:42:57.346621Z"}]}
{"channel":"book","type":"update","data":[{"symbol":"ETH/EUR","bids":[],"asks":[{"price":3522.50,"qty":26.16762381}],"checksum":2509942071,"timestamp":"2024-06-01T22:42:57.374443Z"}]}
{"channel":"book","type":"update","data":[{"symbol":"ETH/EUR","bids":[{"price":3521.82,"qty":0.00000000},{"price":3521.73,"qty":26.17330193}],"asks":[],"checksum":4205454938,"timestamp":"2024-06-01T22:42:57.407738Z"}]}
{"channel":"book","type":"update","data":[{"symbol":"ETH/EUR","bids":[{"price":3521.80,"qty":26.17498227}],"asks":[],"checksum":196360901,"timestamp":"2024-06-01T22:42:57.411389Z"}]}
{"channel":"book","type":"update","data":[{"symbol":"ETH/EUR","bids":[],"asks":[{"price":3523.16,"qty":1.70774845}],"checksum":4221637599,"timestamp":"2024-06-01T22:42:57.421830Z"}]}
{"channel":"book","type":"update","data":[{"symbol":"ETH/EUR","bids":[{"price":3521.80,"qty":0.00220000}],"asks":[],"checksum":742029115,"timestamp":"2024-06-01T22:42:57.445493Z"}]}
{"channel":"book","type":"update","data":[{"symbol":"ETH/EUR","bids":[{"price":3521.78,"qty":0.00000000},{"price":3521.59,"qty":26.17429441},{"price":3521.74,"qty":0.04444040}],"asks":[],"checksum":1537024383,"timestamp":"2024-06-01T22:42:57.511207Z"}]}
{"channel":"book","type":"update","data":[{"symbol":"ETH/EUR","bids":[],"asks":[{"price":3523.30,"qty":33.95410349}],"checksum":3301322915,"timestamp":"2024-06-01T22:42:57.521661Z"}]}
{"channel":"book","type":"update","data":[{"symbol":"ETH/EUR","bids":[{"price":3522.29,"qty":0.00000000},{"price":3521.59,"qty":26.17429441}],"asks":[],"checksum":3796852728,"timestamp":"2024-06-01T22:42:57.522621Z"}]}
{"channel":"book","type":"update","data":[{"symbol":"ETH/EUR","bids":[{"price":3522.12,"qty":0.00000000},{"price":3521.54,"qty":0.66536467}],"asks":[],"checksum":2562711445,"timestamp":"2024-06-01T22:42:57.525277Z"}]}
{"channel":"book","type":"update","data":[{"symbol":"ETH/EUR","bids":[{"price":3521.93,"qty":1.58982737}],"asks":[],"checksum":2132693935,"timestamp":"2024-06-01T22:42:57.525706Z"}]}
{"channel":"book","type":"update","data":[{"symbol":"ETH/EUR","bids":[{"price":3521.79,"qty":26.17285553}],"asks":[],"checksum":2761742513,"timestamp":"2024-06-01T22:42:57.543148Z"}]}
{"channel":"book","type":"update","data":[{"symbol":"ETH/EUR","bids":[{"price":3521.79,"qty":0.00000000},{"price":3521.59,"qty":26.17429441}],"asks":[],"checksum":2132693935,"timestamp":"2024-06-01T22:42:57.565409Z"}]}
{"channel":"book","type":"update","data":[{"symbol":"ETH/EUR","bids":[],"asks":[{"price":3522.40,"qty":80.10503299}],"checksum":1190259297,"timestamp":"2024-06-01T22:42:57.641283Z"}]}
{"channel":"book","type":"update","data":[{"symbol":"ETH/EUR","bids":[{"price":3522.35,"qty":0.47730308}],"asks":[],"checksum":431936173,"timestamp":"2024-06-01T22:42:57.647162Z"}]}
{"channel":"book","type":"update","data":[{"symbol":"ETH/EUR","bids":[{"price":3521.80,"qty":26.17499320}],"asks":[],"checksum":3819475644,"timestamp":"2024-06-01T22:42:57.658239Z"}]}
{"channel":"book","type":"update","data":[{"symbol":"ETH/EUR","bids":[{"price":3521.80,"qty":0.00220000}],"asks":[],"checksum":431936173,"timestamp":"2024-06-01T22:42:57.785362Z"}]}
{"channel":"book","type":"update","data":[{"symbol":"ETH/EUR","bids":[{"price":3521.78,"qty":26.17291618}],"asks":[],"checksum":2759921788,"timestamp":"2024-06-01T22:42:57.788969Z"}]}
{"channel":"book","type":"update","data":[{"symbol":"ETH/EUR","bids":[],"asks":[{"price":3522.50,"qty":0.00000000},{"price":3523.31,"qty":0.63868344}],"checksum":1590643864,"timestamp":"2024-06-01T22:42:57.807842Z"}]}
{"channel":"book","type":"update","data":[{"symbol":"ETH/EUR","bids":[{"price":3521.78,"qty":0.00000000},{"price":3521.73,"qty":26.17330193}],"asks":[],"checksum":3824193097,"timestamp":"2024-06-01T22:42:57.942937Z"}]}
{"channel":"book","type":"update","data":[{"symbol":"ETH/EUR","bids":[{"price":3521.79,"qty":26.17284815}],"asks":[],"checksum":1399780642,"timestamp":"2024-06-01T22:42:57.946556Z"}]}
{"channel":"book","type":"update","data":[{"symbol":"ETH/EUR","bids":[],"asks":[{"price":3522.41,"qty":26.16831422}],"checksum":2091464865,"timestamp":"2024-06-01T22:42:57.946611Z"}]}
{"channel":"book","type":"update","data":[{"symbol":"ETH/EUR","bids":[{"price":3521.79,"qty":0.00000000},{"price":3521.73,"qty":26.17330193}],"asks":[],"checksum":3426173898,"timestamp":"2024-06-01T22:42:58.028168Z"}]}
{"channel":"book","type":"update","data":[{"symbol":"ETH/EUR","bids":[{"price":3521.80,"qty":26.17498796}],"asks":[],"checksum":257766794,"timestamp":"2024-06-01T22:42:58.032490Z"}]}
{"channel":"book","type":"update","data":[{"symbol":"ETH/EUR","bids":[{"price":3521.80,"qty":0.00220000}],"asks":[],"checksum":3426173898,"timestamp":"2024-06-01T22:42:58.054564Z"}]}
{"channel":"book","type":"update","data":[{"symbol":"ETH/EUR","bids":[{"price":3521.74,"qty":0.00000000},{"price":3521.59,"qty":26.17429441},{"price":3521.94,"qty":0.04443788}],"asks":[],"checksum":3690723895,"timestamp":"2024-06-01T22:42:58.077370Z"}]}
{"channel":"book","type":"update","data":[{"symbol":"ETH/EUR","bids":[{"price":3521.82,"qty":26.17259695}],"asks":[],"checksum":2063030472,"timestamp":"2024-06-01T22:42:58.235746Z"}]}
{"channel":"book","type":"update","data":[{"symbol":"ETH/EUR","bids":[{"price":3521.80,"qty":26.17496013}],"asks":[],"checksum":1375330967,"timestamp":"2024-06-01T22:42:58.454365Z"}]}
{"channel":"book","type":"update","data":[{"symbol":"ETH/EUR","bids":[{"price":3521.82,"qty":0.00000000},{"price":3521.59,"qty":26.17429441}],"asks":[],"checksum":3323773687,"timestamp":"2024-06-01T22:42:58.528253Z"}]}
{"channel":"book","type":"update","data":[{"symbol":"ETH/EUR","bids":[{"price":3521.80,"qty":52.34772026}],"asks":[],"checksum":4040064351,"timestamp":"2024-06-01T22:42:58.532016Z"}]}
{"channel":"book","type":"update","data":[{"symbol":"ETH/EUR","bids":[{"price":3521.80,"qty":26.17496013}],"asks":[],"checksum":3323773687,"timestamp":"2024-06-01T22:42:58.590054Z"}]}
{"channel":"book","type":"update","data":[{"symbol":"ETH/EUR","bids":[{"price":3521.81,"qty":26.17269278}],"asks":[],"checksum":2072572366,"timestamp":"2024-06-01T22:42:58.594042Z"}]}
{"channel":"book","type":"update","data":[{"symbol":"ETH/EUR","bids":[{"price":3521.81,"qty":0.00000000},{"price":3521.59,"qty":26.17429441}],"asks":[],"checksum":3323773687,"timestamp":"2024-06-01T22:42:58.660874Z"}]}
{"channel":"book","type":"update","data":[{"symbol":"ETH/EUR","bids":[{"price":3521.82,"qty":26.17264830}],"asks":[],"checksum":4007680332,"timestamp":"2024-06-01T22:42:58.664729Z"}]}
{"channel":"book","type":"update","data":[{"symbol":"ETH/EUR","bids":[],"asks":[{"price":3523.30,"qty":0.00000000},{"price":3523.31,"qty":0.63868344}],"checksum":2470346422,"timestamp":"2024-06-01T22:42:59.725164Z"}]}
{"channel":"book","type":"update","data":[{"symbol":"ETH/EUR","bids":[],"asks":[{"price":3523.30,"qty":0.52358426}],"checksum":4273108600,"timestamp":"2024-06-01T22:42:59.730363Z"}]}
{"channel":"book","type":"update","data":[{"symbol":"ETH/EUR","bids":[],"asks":[{"price":3523.29,"qty":0.26636722}],"checksum":811133289,"timestamp":"2024-06-01T22:42:59.812064Z"}]}
{"channel":"book","type":"update","data":[{"symbol":"ETH/EUR","bids":[{"price":3521.82,"qty":0.00000000},{"price":3521.59,"qty":26.17429441}],"asks":[],"checksum":413430482,"timestamp":"2024-06-01T22:43:00.059359Z"}]}
{"channel":"book","type":"update","data":[{"symbol":"ETH/EUR","bids":[{"price":3521.83,"qty":26.17254566}],"asks":[],"checksum":1362048539,"timestamp":"2024-06-01T22:43:00.063207Z"}]}
{"channel":"book","type":"update","data":[{"symbol":"ETH/EUR","bids":[{"price":3521.83,"qty":0.00000000},{"price":3521.59,"qty":26.17429441}],"asks":[],"checksum":413430482,"timestamp":"2024-06-01T22:43:00.332657Z"}]}
{"channel":"book","type":"update","data":[{"symbol":"ETH/EUR","bids":[{"price":3521.84,"qty":26.17247013}],"asks":[],"checksum":2558776731,"timestamp":"2024-06-01T22:43:00.336376Z"}]}
{"channel":"book","type":"update","data":[{"symbol":"ETH/EUR","bids":[{"price":3521.84,"qty":0.00000000},{"price":3521.59,"qty":26.17429441}],"asks":[],"checksum":413430482,"timestamp":"2024-06-01T22:43:00.690415Z"}]}
{"channel":"book","type":"update","data":[{"symbol":"ETH/EUR","bids":[{"price":3521.82,"qty":26.17258413}],"asks":[],"checksum":787969537,"timestamp":"2024-06-01T22:43:00.694255Z"}]}
{"channel":"book","type":"update","data":[{"symbol":"ETH/EUR","bids":[{"price":3521.88,"qty":0.00000000},{"price":3521.59,"qty":26.17429441},{"price":3522.18,"qty":0.08527800}],"asks":[],"checksum":151563653,"timestamp":"2024-06-01T22:43:00.865056Z"}]}
{"channel":"book","type":"update","data":[{"symbol":"ETH/EUR","bids":[{"price":3521.82,"qty":0.00000000},{"price":3521.59,"qty":26.17429441}],"asks":[],"checksum":1062971734,"timestamp":"2024-06-01T22:43:00.869784Z"}]}
{"channel":"book","type":"update","data":[{"symbol":"ETH/EUR","bids":[{"price":3521.86,"qty":26.17234864}],"asks":[],"checksum":1815582885,"timestamp":"2024-06-01T22:43:00.873104Z"}]}
{"channel":"book","type":"update","data":[{"symbol":"ETH/EUR","bids":[{"price":3521.94,"qty":3.84443788}],"asks":[],"checksum":931983443,"timestamp":"2024-06-01T22:43:00.889016Z"}]}
{"channel":"book","type":"update","data":[{"symbol":"ETH/EUR","bids":[{"price":3521.86,"qty":0.00000000},{"price":3521.59,"qty":26.17429441}],"asks":[],"checksum":1692451232,"timestamp":"2024-06-01T22:43:01.337947Z"}]}
{"channel":"book","type":"update","data":[{"symbol":"ETH/EUR","bids":[{"price":3521.84,"qty":26.17248555}],"asks":[],"checksum":172948348,"timestamp":"2024-06-01T22:43:01.341905Z"}]}
{"channel":"book","type":"update","data":[{"symbol":"ETH/EUR","bids":[{"price":3521.84,"qty":0.00000000},{"price":3521.59,"qty":26.17429441}],"asks":[],"checksum":1692451232,"timestamp":"2024-06-01T22:43:01.405279Z"}]}
{"channel":"book","type":"update","data":[{"symbol":"ETH/EUR","bids":[{"price":3521.85,"qty":26.17241752}],"asks":[],"checksum":3361240947,"timestamp":"2024-06-01T22:43:01.409349Z"}]}
{"channel":"book","type":"update","data":[{"symbol":"ETH/EUR","bids":[{"price":3522.39,"qty":0.11000000}],"asks":[],"checksum":1178522395,"timestamp":"2024-06-01T22:43:01.447261Z"}]}
{"channel":"book","type":"update","data":[{"symbol":"ETH/EUR","bids":[{"price":3521.85,"qty":0.00000000},{"price":3521.59,"qty":26.17429441}],"asks":[],"checksum":3934676424,"timestamp":"2024-06-01T22:43:01.540788Z"}]}
{"channel":"book","type":"update","data":[{"symbol":"ETH/EUR","bids":[{"price":3521.83,"qty":26.17251434}],"asks":[],"checksum":1872986214,"timestamp":"2024-06-01T22:43:01.544461Z"}]}
{"channel":"book","type":"update","data":[{"symbol":"ETH/EUR","bids":[{"price":3521.83,"qty":0.00000000},{"price":3521.59,"qty":26.17429441}],"asks":[],"checksum":3934676424,"timestamp":"2024-06-01T22:43:01.594232Z"}]}
{"channel":"book","type":"update","data":[{"symbol":"ETH/EUR","bids":[{"price":3521.84,"qty":26.17247247}],"asks":[],"checksum":2313650776,"timestamp":"2024-06-01T22:43:01.598117Z"}]}
{"channel":"book","type":"update","data":[{"symbol":"ETH/EUR","bids":[{"price":3521.84,"qty":0.00000000},{"price":3521.59,"qty":26.17429441}],"asks":[],"checksum":3934676424,"timestamp":"2024-06-01T22:43:01.682335Z"}]}
{"channel":"book","type":"update","data":[{"symbol":"ETH/EUR","bids":[{"price":3521.85,"qty":26.17242483}],"asks":[],"checksum":1053564112,"timestamp":"2024-06-01T22:43:01.686162Z"}]}
{"channel":"book","type":"update","data":[{"symbol":"ETH/EUR","bids":[{"price":3521.94,"qty":3.80000000},{"price":3521.95,"qty":0.04444982}],"asks":[],"checksum":51242118,"timestamp":"2024-06-01T22:43:01.712899Z"}]}
{"channel":"book","type":"update","data":[{"symbol":"ETH/EUR","bids":[{"price":3521.85,"qty":0.00000000},{"price":3521.80,"qty":26.17496013}],"asks":[],"checksum":87747498,"timestamp":"2024-06-01T22:43:01.748766Z"}]}
{"channel":"book","type":"update","data":[{"symbol":"ETH/EUR","bids":[{"price":3521.84,"qty":26.17250070}],"asks":[],"checksum":1282555860,"timestamp":"2024-06-01T22:43:01.752569Z"}]}
{"channel":"book","type":"update","data":[{"symbol":"ETH/EUR","bids":[{"price":3521.84,"qty":0.00000000},{"price":3521.80,"qty":26.17496013}],"asks":[],"checksum":87747498,"timestamp":"2024-06-01T22:43:02.338130Z"}]}
{"channel":"book","type":"update","data":[{"symbol":"ETH/EUR","bids":[{"price":3521.85,"qty":26.17242367}],"asks":[],"checksum":2678856596,"timestamp":"2024-06-01T22:43:02.342040Z"}]}
{"channel":"book","type":"update","data":[{"symbol":"ETH/EUR","bids":[],"asks":[{"price":3523.29,"qty":0.00000000},{"price":3523.31,"qty":8.00802887}],"checksum":3049880211,"timestamp":"2024-06-01T22:43:02.522270Z"}]}
{"channel":"book","type":"update","data":[{"symbol":"ETH/EUR","bids":[],"asks":[{"price":3523.30,"qty":0.04517358}],"checksum":831003479,"timestamp":"2024-06-01T22:43:02.523938Z"}]}
{"channel":"book","type":"update","data":[{"symbol":"ETH/EUR","bids":[{"price":3521.85,"qty":0.00000000},{"price":3521.80,"qty":26.17496013}],"asks":[],"checksum":2870930281,"timestamp":"2024-06-01T22:43:02.924247Z"}]}
{"channel":"book","type":"update","data":[{"symbol":"ETH/EUR","bids":[{"price":3521.86,"qty":26.17232520}],"asks":[],"checksum":3838807379,"timestamp":"2024-06-01T22:43:02.927930Z"}]}
{"channel":"book","type":"update","data":[{"symbol":"ETH/EUR","bids":[{"price":3521.86,"qty":0.00000000},{"price":3521.80,"qty":26.17496013}],"asks":[],"checksum":2870930281,"timestamp":"2024-06-01T22:43:02.998319Z"}]}
{"channel":"book","type":"update","data":[{"symbol":"ETH/EUR","bids":[{"price":3521.94,"qty":0.00000000},{"price":3521.59,"qty":26.17429441}],"asks":[],"checksum":2874137484,"timestamp":"2024-06-01T22:43:02.999658Z"}]}
{"channel":"book","type":"update","data":[{"symbol":"ETH/EUR","bids":[{"price":3521.84,"qty":26.17243772}],"asks":[],"checksum":2791402257,"timestamp":"2024-06-01T22:43:03.001947Z"}]}
{"channel":"book","type":"update","data":[{"symbol":"ETH/EUR","bids":[{"price":3521.85,"qty":3.80000000}],"asks":[],"checksum":3746159173,"timestamp":"2024-06-01T22:43:03.050275Z"}]}
{"channel":"book","type":"update","data":[{"symbol":"ETH/EUR","bids":[{"price":3521.95,"qty":0.00000000},{"price":3521.80,"qty":26.17496013},{"price":3521.94,"qty":0.04444985}],"asks":[],"checksum":275228571,"timestamp":"2024-06-01T22:43:03.062712Z"}]}
{"channel":"book","type":"update","data":[{"symbol":"ETH/EUR","bids":[{"price":3521.84,"qty":0.00000000},{"price":3521.80,"qty":26.17496013}],"asks":[],"checksum":2646311442,"timestamp":"2024-06-01T22:43:03.168145Z"}]}
{"channel":"book","type":"update","data":[{"symbol":"ETH/EUR","bids":[{"price":3521.85,"qty":29.97238800}],"asks":[],"checksum":3020415762,"timestamp":"2024-06-01T22:43:03.172216Z"}]}
{"channel":"book","type":"update","data":[{"symbol":"ETH/EUR","bids":[{"price":3521.85,"qty":3.80000000}],"asks":[],"checksum":2646311442,"timestamp":"2024-06-01T22:43:03.532851Z"}]}
{"channel":"book","type":"update","data":[{"symbol":"ETH/EUR","bids":[{"price":3521.80,"qty":0.00220000}],"asks":[],"checksum":220803089,"timestamp":"2024-06-01T22:43:03.533017Z"}]}
{"channel":"book","type":"update","data":[{"symbol":"ETH/EUR","bids":[{"price":3522.39,"qty":0.58730308}],"asks":[],"checksum":2320475278,"timestamp":"2024-06-01T22:43:03.533234Z"}]}
{"channel":"book","type":"update","data":[{"symbol":"ETH/EUR","bids":[],"asks":[{"price":3522.41,"qty":0.00000000},{"price":3523.31,"qty":8.00802887}],"checksum":692529353,"timestamp":"2024-06-01T22:43:03.540882Z"}]}
{"channel":"book","type":"update","data":[{"symbol":"ETH/EUR","bids":[{"price":3522.04,"qty":26.17101419}],"asks":[],"checksum":4025017715,"timestamp":"2024-06-01T22:43:03.544962Z"}]}
{"channel":"book","type":"update","data":[{"symbol":"ETH/EUR","bids":[],"asks":[{"price":3522.56,"qty":26.16720977}],"checksum":534267325,"timestamp":"2024-06-01T22:43:03.545030Z"}]}
{"channel":"book","type":"update","data":[{"symbol":"ETH/EUR","bids":[],"asks":[{"price":3522.40,"qty":78.50503299}],"checksum":3890182702,"timestamp":"2024-06-01T22:43:03.553046Z"}]}
{"channel":"book","type":"update","data":[{"symbol":"ETH/EUR","bids":[],"asks":[{"price":3523.16,"qty":0.00000000},{"price":3523.31,"qty":8.00802887}],"checksum":2281748046,"timestamp":"2024-06-01T22:43:03.560296Z"}]}
{"channel":"book","type":"update","data":[{"symbol":"ETH/EUR","bids":[{"price":3522.04,"qty":0.00000000},{"price":3521.80,"qty":0.00220000}],"asks":[],"checksum":1687227908,"timestamp":"2024-06-01T22:43:03.574131Z"}]}
{"channel":"book","type":"update","data":[{"symbol":"ETH/EUR","bids":[],"asks":[{"price":3522.40,"qty":52.33668866}],"checksum":3420800946,"timestamp":"2024-06-01T22:43:03.606001Z"}]}
{"channel":"book","type":"update","data":[{"symbol":"ETH/EUR","bids":[{"price":3522.05,"qty":26.17091694}],"asks":[],"checksum":869589426,"timestamp":"2024-06-01T22:43:03.606150Z"}]}
{"channel":"book","type":"update","data":[{"symbol":"ETH/EUR","bids":[{"price":3521.85,"qty":0.00000000},{"price":3521.80,"qty":0.00220000}],"asks":[],"checksum":3730091580,"timestamp":"2024-06-01T22:43:03.623332Z"}]}
{"channel":"book","type":"update","data":[{"symbol":"ETH/EUR","bids":[{"price":3522.06,"qty":3.80000000}],"asks":[],"checksum":104173944,"timestamp":"2024-06-01T22:43:03.623697Z"}]}
{"channel":"book","type":"update","data":[{"symbol":"ETH/EUR","bids":[],"asks":[{"price":3523.06,"qty":0.00000000},{"price":3523.32,"qty":1.04800000}],"checksum":1716407227,"timestamp":"2024-06-01T22:43:03.659675Z"}]}
{"channel":"book","type":"update","data":[{"symbol":"ETH/EUR","bids":[{"price":3522.12,"qty":26.17042396}],"asks":[],"checksum":412142883,"timestamp":"2024-06-01T22:43:03.727317Z"}]}
{"channel":"book","type":"update","data":[{"symbol":"ETH/EUR","bids":[{"price":3522.12,"qty":0.00000000},{"price":3521.92,"qty":0.47730308}],"asks":[],"checksum":1716407227,"timestamp":"2024-06-01T22:43:03.731409Z"}]}
{"channel":"book","type":"update","data":[{"symbol":"ETH/EUR","bids":[{"price":3522.12,"qty":26.17041318}],"asks":[],"checksum":913313836,"timestamp":"2024-06-01T22:43:03.820672Z"}]}
{"channel":"book","type":"update","data":[{"symbol":"ETH/EUR","bids":[{"price":3522.19,"qty":0.63420649}],"asks":[],"checksum":4237675931,"timestamp":"2024-06-01T22:43:03.895675Z"}]}
{"channel":"book","type":"update","data":[{"symbol":"ETH/EUR","bids":[{"price":3522.06,"qty":0.00000000},{"price":3521.93,"qty":1.58982737}],"asks":[],"checksum":4202508795,"timestamp":"2024-06-01T22:43:03.898245Z"}]}
{"channel":"book","type":"update","data":[{"symbol":"ETH/EUR","bids":[{"price":3522.12,"qty":0.00000000},{"price":3521.92,"qty":0.47730308}],"asks":[],"checksum":1867044249,"timestamp":"2024-06-01T22:43:04.234350Z"}]}
{"channel":"book","type":"update","data":[{"symbol":"ETH/EUR","bids":[],"asks":[{"price":3522.73,"qty":26.16591122}],"checksum":156857593,"timestamp":"2024-06-01T22:43:04.238415Z"}]}
{"channel":"book","type":"update","data":[{"symbol":"ETH/EUR","bids":[{"price":3522.10,"qty":26.17050263}],"asks":[],"checksum":3799804599,"timestamp":"2024-06-01T22:43:04.238537Z"}]}
{"channel":"book","type":"update","data":[{"symbol":"ETH/EUR","bids":[{"price":3521.94,"qty":0.00000000},{"price":3521.92,"qty":0.47730308},{"price":3522.20,"qty":0.04613124}],"asks":[],"checksum":1685780674,"timestamp":"2024-06-01T22:43:04.258422Z"}]}
{"channel":"book","type":"update","data":[{"symbol":"ETH/EUR","bids":[{"price":3522.11,"qty":3.80000000}],"asks":[],"checksum":3361151860,"timestamp":"2024-06-01T22:43:04.277331Z"}]}
{"channel":"book","type":"update","data":[{"symbol":"ETH/EUR","bids":[{"price":3522.10,"qty":0.00000000},{"price":3521.92,"qty":0.47730308}],"asks":[],"checksum":209602360,"timestamp":"2024-06-01T22:43:04.281390Z"}]}
{"channel":"book","type":"update","data":[{"symbol":"ETH/EUR","bids":[{"price":3522.20,"qty":0.00168467},{"price":3522.11,"qty":3.84444530}],"asks":[],"checksum":2762206964,"timestamp":"2024-06-01T22:43:04.303779Z"}]}
{"channel":"book","type":"update","data":[{"symbol":"ETH/EUR","bids":[{"price":3522.08,"qty":26.17065437}],"asks":[],"checksum":1295771343,"timestamp":"2024-06-01T22:43:04.340092Z"}]}
{"channel":"book","type":"update","data":[{"symbol":"ETH/EUR","bids":[{"price":3522.11,"qty":0.04444530}],"asks":[],"checksum":3287484159,"timestamp":"2024-06-01T22:43:04.553827Z"}]}
{"channel":"book","type":"update","data":[{"symbol":"ETH/EUR","bids":[{"price":3522.12,"qty":3.80000000}],"asks":[],"checksum":127032362,"timestamp":"2024-06-01T22:43:04.554005Z"}]}
{"channel":"book","type":"update","data":[{"symbol":"ETH/EUR","bids":[{"price":3522.08,"qty":0.00000000},{"price":3521.93,"qty":1.58982737}],"asks":[],"checksum":2491974659,"timestamp":"2024-06-01T22:43:04.557604Z"}]}
{"channel":"book","type":"update","data":[{"symbol":"ETH/EUR","bids":[{"price":3522.05,"qty":0.00000000},{"price":3521.92,"qty":0.47730308}],"asks":[],"checksum":2034840373,"timestamp":"2024-06-01T22:43:04.563488Z"}]}
