{"channel":"book","type":"snapshot","data":[{"symbol":"EUR/USD","bids":[{"price":1.08442,"qty":1841.23906818},{"price":1.08439,"qty":2305.44361346},{"price":1.08434,"qty":1972.83160000},{"price":1.08425,"qty":147.75982709},{"price":1.08424,"qty":3692.80200547},{"price":1.08423,"qty":10063.08923160},{"price":1.08417,"qty":4611.80010878},{"price":1.08414,"qty":2830.45000000},{"price":1.08406,"qty":342.59570503},{"price":1.08405,"qty":2000.00000000}],"asks":[{"price":1.08452,"qty":3692.32200340},{"price":1.08453,"qty":461.31409960},{"price":1.08458,"qty":2305.05175981},{"price":1.08468,"qty":403.22134173},{"price":1.08469,"qty":19244.78542918},{"price":1.08470,"qty":8603.45176714},{"price":1.08475,"qty":4167.00000000},{"price":1.08479,"qty":4609.18918798},{"price":1.08480,"qty":4167.00000000},{"price":1.08485,"qty":4167.00000000}],"checksum":750895358}]}
{"channel":"book","type":"update","data":[{"symbol":"EUR/USD","bids":[],"asks":[{"price":1.08468,"qty":0.00000000},{"price":1.08489,"qty":175.24140000}],"checksum":4033666643,"timestamp":"2024-06-01T22:43:40.471291Z"}]}
{"channel":"book","type":"update","data":[{"symbol":"EUR/USD","bids":[],"asks":[{"price":1.08468,"qty":415.24583372}],"checksum":2208406505,"timestamp":"2024-06-01T22:43:40.476317Z"}]}
{"channel":"book","type":"update","data":[{"symbol":"EUR/USD","bids":[{"price":1.08423,"qty":0.00000000},{"price":1.08395,"qty":1910.70737694}],"asks":[],"checksum":3305446580,"timestamp":"2024-06-01T22:43:40.842424Z"}]}
{"channel":"book","type":"update","data":[{"symbol":"EUR/USD","bids":[{"price":1.08424,"qty":0.00000000},{"price":1.08382,"qty":5287.20553577},{"price":1.08418,"qty":3693.00637017}],"asks":[],"checksum":197389560,"timestamp":"2024-06-01T22:43:40.845636Z"}]}
{"channel":"book","type":"update","data":[{"symbol":"EUR/USD","bids":[{"price":1.08425,"qty":10210.84905869}],"asks":[],"checksum":2501775555,"timestamp":"2024-06-01T22:43:40.847685Z"}]}
{"channel":"book","type":"update","data":[{"symbol":"EUR/USD","bids":[{"price":1.08396,"qty":75233.48619666}],"asks":[],"checksum":628220782,"timestamp":"2024-06-01T22:43:40.847730Z"}]}
{"channel":"book","type":"update","data":[{"symbol":"EUR/USD","bids":[{"price":1.08418,"qty":0.00000000},{"price":1.08395,"qty":1910.70737694},{"price":1.08426,"qty":3692.73388893}],"asks":[],"checksum":2373729143,"timestamp":"2024-06-01T22:43:40.851111Z"}]}
{"channel":"book","type":"update","data":[{"symbol":"EUR/USD","bids":[{"price":1.08397,"qty":17338.73636606}],"asks":[],"checksum":3876023799,"timestamp":"2024-06-01T22:43:40.887237Z"}]}
{"channel":"book","type":"update","data":[{"symbol":"EUR/USD","bids":[{"price":1.08425,"qty":10063.08923160}],"asks":[],"checksum":160723888,"timestamp":"2024-06-01T22:43:41.537918Z"}]}
{"channel":"book","type":"update","data":[{"symbol":"EUR/USD","bids":[{"price":1.08427,"qty":131.59454845}],"asks":[],"checksum":2975770944,"timestamp":"2024-06-01T22:43:41.541835Z"}]}
{"channel":"book","type":"update","data":[{"symbol":"EUR/USD","bids":[],"asks":[{"price":1.08468,"qty":0.00000000},{"price":1.08489,"qty":175.24140000}],"checksum":3264474362,"timestamp":"2024-06-01T22:43:42.973339Z"}]}
{"channel":"book","type":"update","data":[{"symbol":"EUR/USD","bids":[],"asks":[{"price":1.08468,"qty":403.22134173}],"checksum":507441751,"timestamp":"2024-06-01T22:43:42.978501Z"}]}
{"channel":"book","type":"update","data":[{"symbol":"EUR/USD","bids":[{"price":1.08425,"qty":0.00000000},{"price":1.08398,"qty":1927.30614341}],"asks":[],"checksum":2742359710,"timestamp":"2024-06-01T22:43:44.124181Z"}]}
{"channel":"book","type":"update","data":[{"symbol":"EUR/USD","bids":[{"price":1.08426,"qty":0.00000000},{"price":1.08397,"qty":17338.73636606},{"price":1.08418,"qty":3693.00637017}],"asks":[],"checksum":3524454689,"timestamp":"2024-06-01T22:43:44.128211Z"}]}
{"channel":"book","type":"update","data":[{"symbol":"EUR/USD","bids":[{"price":1.08427,"qty":3345.24258286}],"asks":[],"checksum":569011063,"timestamp":"2024-06-01T22:43:44.129335Z"}]}
{"channel":"book","type":"update","data":[{"symbol":"EUR/USD","bids":[{"price":1.08418,"qty":13756.09560177}],"asks":[],"checksum":1034088559,"timestamp":"2024-06-01T22:43:44.129512Z"}]}
{"channel":"book","type":"update","data":[{"symbol":"EUR/USD","bids":[{"price":1.08399,"qty":66548.31189340}],"asks":[],"checksum":1644666834,"timestamp":"2024-06-01T22:43:44.129584Z"}]}
{"channel":"book","type":"update","data":[{"symbol":"EUR/USD","bids":[{"price":1.08418,"qty":10063.08923160},{"price":1.08419,"qty":3692.97230781}],"asks":[],"checksum":288994099,"timestamp":"2024-06-01T22:43:44.131948Z"}]}
{"channel":"book","type":"update","data":[{"symbol":"EUR/USD","bids":[{"price":1.08419,"qty":0.00000000},{"price":1.08399,"qty":66548.31189340},{"price":1.08428,"qty":3692.66577490}],"asks":[],"checksum":806415942,"timestamp":"2024-06-01T22:43:44.135137Z"}]}
{"channel":"book","type":"update","data":[{"symbol":"EUR/USD","bids":[],"asks":[{"price":1.08468,"qty":0.00000000},{"price":1.08489,"qty":175.24140000}],"checksum":2561383437,"timestamp":"2024-06-01T22:43:45.484332Z"}]}
{"channel":"book","type":"update","data":[{"symbol":"EUR/USD","bids":[],"asks":[{"price":1.08468,"qty":415.24583372}],"checksum":3010202586,"timestamp":"2024-06-01T22:43:45.489109Z"}]}
{"channel":"book","type":"update","data":[{"symbol":"EUR/USD","bids":[{"price":1.08434,"qty":0.00000000},{"price":1.08401,"qty":23.06251787},{"price":1.08443,"qty":1972.83160000}],"asks":[],"checksum":2262431733,"timestamp":"2024-06-01T22:43:46.512139Z"}]}
{"channel":"book","type":"update","data":[{"symbol":"EUR/USD","bids":[],"asks":[{"price":1.08469,"qty":0.00000000},{"price":1.08489,"qty":175.24140000}],"checksum":2594485015,"timestamp":"2024-06-01T22:43:46.744509Z"}]}
{"channel":"book","type":"update","data":[{"symbol":"EUR/USD","bids":[],"asks":[{"price":1.08469,"qty":20826.69685047}],"checksum":2901877500,"timestamp":"2024-06-01T22:43:46.750042Z"}]}
{"channel":"book","type":"update","data":[{"symbol":"EUR/USD","bids":[{"price":1.08418,"qty":0.00000000},{"price":1.08401,"qty":23.06251787}],"asks":[],"checksum":66480726,"timestamp":"2024-06-01T22:43:47.717726Z"}]}
{"channel":"book","type":"update","data":[{"symbol":"EUR/USD","bids":[{"price":1.08427,"qty":131.59454845}],"asks":[],"checksum":227105300,"timestamp":"2024-06-01T22:43:47.717885Z"}]}
{"channel":"book","type":"update","data":[{"symbol":"EUR/USD","bids":[{"price":1.08427,"qty":0.00000000},{"price":1.08400,"qty":17338.73636606}],"asks":[],"checksum":3943660547,"timestamp":"2024-06-01T22:43:47.721121Z"}]}
{"channel":"book","type":"update","data":[{"symbol":"EUR/USD","bids":[{"price":1.08428,"qty":0.00000000},{"price":1.08398,"qty":1904.24298727},{"price":1.08418,"qty":3693.00637017}],"asks":[],"checksum":1470452735,"timestamp":"2024-06-01T22:43:47.721148Z"}]}
{"channel":"book","type":"update","data":[{"symbol":"EUR/USD","bids":[{"price":1.08400,"qty":0.00000000},{"price":1.08398,"qty":1904.24298727}],"asks":[],"checksum":3038219055,"timestamp":"2024-06-01T22:43:47.721172Z"}]}
{"channel":"book","type":"update","data":[{"symbol":"EUR/USD","bids":[{"price":1.08398,"qty":0.00000000},{"price":1.08382,"qty":5287.20553577}],"asks":[],"checksum":2641531637,"timestamp":"2024-06-01T22:43:47.721277Z"}]}
{"channel":"book","type":"update","data":[{"symbol":"EUR/USD","bids":[{"price":1.08429,"qty":1843.75979497}],"asks":[],"checksum":919550235,"timestamp":"2024-06-01T22:43:47.723536Z"}]}
{"channel":"book","type":"update","data":[{"symbol":"EUR/USD","bids":[{"price":1.08418,"qty":15125.98384121}],"asks":[],"checksum":1478246523,"timestamp":"2024-06-01T22:43:47.723558Z"}]}
{"channel":"book","type":"update","data":[{"symbol":"EUR/USD","bids":[{"price":1.08401,"qty":65189.11169311}],"asks":[],"checksum":2371455901,"timestamp":"2024-06-01T22:43:47.723640Z"}]}
{"channel":"book","type":"update","data":[{"symbol":"EUR/USD","bids":[{"price":1.08418,"qty":11432.97747104},{"price":1.08429,"qty":5536.39151380}],"asks":[],"checksum":3265482807,"timestamp":"2024-06-01T22:43:47.724491Z"}]}
{"channel":"book","type":"update","data":[{"symbol":"EUR/USD","bids":[{"price":1.08429,"qty":1843.75979497},{"price":1.08419,"qty":3692.97230781}],"asks":[],"checksum":554844017,"timestamp":"2024-06-01T22:43:47.728385Z"}]}
{"channel":"book","type":"update","data":[{"symbol":"EUR/USD","bids":[{"price":1.08419,"qty":4050.88075727}],"asks":[],"checksum":2280622931,"timestamp":"2024-06-01T22:43:47.732987Z"}]}
{"channel":"book","type":"update","data":[{"symbol":"EUR/USD","bids":[{"price":1.08429,"qty":1910.69322885}],"asks":[],"checksum":2632212849,"timestamp":"2024-06-01T22:43:47.732997Z"}]}
{"channel":"book","type":"update","data":[{"symbol":"EUR/USD","bids":[{"price":1.08443,"qty":0.00000000},{"price":1.08401,"qty":66762.58306099},{"price":1.08430,"qty":1972.83160000}],"asks":[],"checksum":3201389834,"timestamp":"2024-06-01T22:43:47.736627Z"}]}
{"channel":"book","type":"update","data":[{"symbol":"EUR/USD","bids":[{"price":1.08419,"qty":357.90844946},{"price":1.08420,"qty":3692.93824609}],"asks":[],"checksum":2703182171,"timestamp":"2024-06-01T22:43:47.737197Z"}]}
{"channel":"book","type":"update","data":[{"symbol":"EUR/USD","bids":[{"price":1.08420,"qty":0.00000000},{"price":1.08405,"qty":2000.00000000},{"price":1.08431,"qty":3692.56360857}],"asks":[],"checksum":2734612652,"timestamp":"2024-06-01T22:43:47.740326Z"}]}
{"channel":"book","type":"update","data":[{"symbol":"EUR/USD","bids":[],"asks":[{"price":1.08451,"qty":461.31409960}],"checksum":2274440528,"timestamp":"2024-06-01T22:43:47.881189Z"}]}
{"channel":"book","type":"update","data":[{"symbol":"EUR/USD","bids":[],"asks":[{"price":1.08452,"qty":0.00000000},{"price":1.08485,"qty":4167.00000000},{"price":1.08450,"qty":3692.29933977}],"checksum":3146811412,"timestamp":"2024-06-01T22:43:47.885013Z"}]}
{"channel":"book","type":"update","data":[{"symbol":"EUR/USD","bids":[{"price":1.08430,"qty":0.00000000},{"price":1.08405,"qty":2000.00000000},{"price":1.08432,"qty":1972.83160000}],"asks":[],"checksum":567150349,"timestamp":"2024-06-01T22:43:47.892111Z"}]}
{"channel":"book","type":"update","data":[{"symbol":"EUR/USD","bids":[{"price":1.08431,"qty":0.00000000},{"price":1.08405,"qty":2000.00000000},{"price":1.08433,"qty":3692.49550082}],"asks":[],"checksum":3608376874,"timestamp":"2024-06-01T22:43:47.895193Z"}]}
{"channel":"book","type":"update","data":[{"symbol":"EUR/USD","bids":[],"asks":[{"price":1.08468,"qty":0.00000000},{"price":1.08485,"qty":4167.00000000}],"checksum":4109171578,"timestamp":"2024-06-01T22:43:48.018327Z"}]}
{"channel":"book","type":"update","data":[{"symbol":"EUR/USD","bids":[],"asks":[{"price":1.08468,"qty":463.34380170}],"checksum":1706820106,"timestamp":"2024-06-01T22:43:48.025083Z"}]}
{"channel":"book","type":"update","data":[{"symbol":"EUR/USD","bids":[{"price":1.08432,"qty":0.00000000},{"price":1.08405,"qty":2000.00000000},{"price":1.08434,"qty":1972.83160000}],"asks":[],"checksum":2589887092,"timestamp":"2024-06-01T22:43:48.048289Z"}]}
{"channel":"book","type":"update","data":[{"symbol":"EUR/USD","bids":[{"price":1.08433,"qty":0.00000000},{"price":1.08405,"qty":2000.00000000},{"price":1.08420,"qty":3692.93824609}],"asks":[],"checksum":1034437213,"timestamp":"2024-06-01T22:43:48.051396Z"}]}
{"channel":"book","type":"update","data":[{"symbol":"EUR/USD","bids":[],"asks":[{"price":1.08453,"qty":0.00000000},{"price":1.08485,"qty":4167.00000000}],"checksum":500723711,"timestamp":"2024-06-01T22:43:48.083225Z"}]}
{"channel":"book","type":"update","data":[{"symbol":"EUR/USD","bids":[{"price":1.08434,"qty":0.00000000},{"price":1.08405,"qty":2000.00000000},{"price":1.08443,"qty":1972.83160000}],"asks":[],"checksum":495762135,"timestamp":"2024-06-01T22:43:48.508916Z"}]}
{"channel":"book","type":"update","data":[{"symbol":"EUR/USD","bids":[],"asks":[{"price":1.08450,"qty":3468.00416867}],"checksum":2140176957,"timestamp":"2024-06-01T22:43:48.621479Z"}]}
{"channel":"book","type":"update","data":[{"symbol":"EUR/USD","bids":[],"asks":[{"price":1.08469,"qty":0.00000000},{"price":1.08489,"qty":175.24140000}],"checksum":199692080,"timestamp":"2024-06-01T22:43:48.875822Z"}]}
{"channel":"book","type":"update","data":[{"symbol":"EUR/USD","bids":[],"asks":[{"price":1.08469,"qty":22408.60827176}],"checksum":1553125318,"timestamp":"2024-06-01T22:43:48.881020Z"}]}
{"channel":"book","type":"update","data":[{"symbol":"EUR/USD","bids":[{"price":1.08443,"qty":0.00000000},{"price":1.08405,"qty":2000.00000000}],"asks":[],"checksum":1167817952,"timestamp":"2024-06-01T22:43:49.274648Z"}]}
{"channel":"book","type":"update","data":[{"symbol":"EUR/USD","bids":[{"price":1.08443,"qty":1984.80000000}],"asks":[],"checksum":2429717657,"timestamp":"2024-06-01T22:43:49.373268Z"}]}
{"channel":"book","type":"update","data":[{"symbol":"EUR/USD","bids":[],"asks":[{"price":1.08468,"qty":0.00000000},{"price":1.08489,"qty":175.24140000}],"checksum":3501110272,"timestamp":"2024-06-01T22:43:50.466612Z"}]}
{"channel":"book","type":"update","data":[{"symbol":"EUR/USD","bids":[],"asks":[{"price":1.08468,"qty":1058.70255797}],"checksum":1912921198,"timestamp":"2024-06-01T22:43:50.471888Z"}]}
{"channel":"book","type":"update","data":[{"symbol":"EUR/USD","bids":[{"price":1.08419,"qty":0.00000000},{"price":1.08405,"qty":2000.00000000}],"asks":[],"checksum":2068522542,"timestamp":"2024-06-01T22:43:50.485003Z"}]}
{"channel":"book","type":"update","data":[{"symbol":"EUR/USD","bids":[{"price":1.08429,"qty":1843.75979497}],"asks":[],"checksum":1614859276,"timestamp":"2024-06-01T22:43:50.485168Z"}]}
{"channel":"book","type":"update","data":[{"symbol":"EUR/USD","bids":[{"price":1.08420,"qty":0.00000000},{"price":1.08403,"qty":23.06209237},{"price":1.08419,"qty":3692.97230781}],"asks":[],"checksum":1430770876,"timestamp":"2024-06-01T22:43:50.489097Z"}]}
{"channel":"book","type":"update","data":[{"symbol":"EUR/USD","bids":[{"price":1.08421,"qty":419.53978806}],"asks":[],"checksum":2416531808,"timestamp":"2024-06-01T22:43:50.489321Z"}]}
{"channel":"book","type":"update","data":[{"symbol":"EUR/USD","bids":[],"asks":[{"price":1.08467,"qty":12917.13974401}],"checksum":286686170,"timestamp":"2024-06-01T22:43:50.989653Z"}]}
{"channel":"book","type":"update","data":[{"symbol":"EUR/USD","bids":[{"price":1.08443,"qty":0.00000000},{"price":1.08405,"qty":2000.00000000},{"price":1.08430,"qty":1984.80000000}],"asks":[],"checksum":2258654326,"timestamp":"2024-06-01T22:43:51.009091Z"}]}
{"channel":"book","type":"update","data":[{"symbol":"EUR/USD","bids":[{"price":1.08419,"qty":0.00000000},{"price":1.08405,"qty":2000.00000000},{"price":1.08431,"qty":3692.56360857}],"asks":[],"checksum":2623496144,"timestamp":"2024-06-01T22:43:51.012631Z"}]}
{"channel":"book","type":"update","data":[{"symbol":"EUR/USD","bids":[{"price":1.08418,"qty":0.00000000},{"price":1.08405,"qty":2000.00000000}],"asks":[],"checksum":186422998,"timestamp":"2024-06-01T22:43:51.100604Z"}]}
{"channel":"book","type":"update","data":[{"symbol":"EUR/USD","bids":[{"price":1.08429,"qty":0.00000000},{"price":1.08403,"qty":1601.95753554}],"asks":[],"checksum":3643512807,"timestamp":"2024-06-01T22:43:51.100731Z"}]}
{"channel":"book","type":"update","data":[{"symbol":"EUR/USD","bids":[{"price":1.08431,"qty":0.00000000},{"price":1.08382,"qty":5287.20553577},{"price":1.08418,"qty":3693.00637017}],"asks":[],"checksum":137192089,"timestamp":"2024-06-01T22:43:51.106006Z"}]}
{"channel":"book","type":"update","data":[{"symbol":"EUR/USD","bids":[{"price":1.08420,"qty":21022.19514710}],"asks":[],"checksum":4042697074,"timestamp":"2024-06-01T22:43:51.107180Z"}]}
{"channel":"book","type":"update","data":[{"symbol":"EUR/USD","bids":[{"price":1.08406,"qty":39173.33796482}],"asks":[],"checksum":1966081000,"timestamp":"2024-06-01T22:43:51.107300Z"}]}
{"channel":"book","type":"update","data":[{"symbol":"EUR/USD","bids":[{"price":1.08418,"qty":0.00000000},{"price":1.08403,"qty":1601.95753554},{"price":1.08422,"qty":3692.87012452}],"asks":[],"checksum":2377207003,"timestamp":"2024-06-01T22:43:51.110311Z"}]}
{"channel":"book","type":"update","data":[{"symbol":"EUR/USD","bids":[{"price":1.08407,"qty":17338.73636606}],"asks":[],"checksum":2636434114,"timestamp":"2024-06-01T22:43:51.186471Z"}]}
{"channel":"book","type":"update","data":[{"symbol":"EUR/USD","bids":[{"price":1.08406,"qty":38830.74225979}],"asks":[],"checksum":561860027,"timestamp":"2024-06-01T22:43:51.206326Z"}]}
{"channel":"book","type":"update","data":[{"symbol":"EUR/USD","bids":[{"price":1.08408,"qty":342.58938454}],"asks":[],"checksum":1502970395,"timestamp":"2024-06-01T22:43:51.206563Z"}]}
{"channel":"book","type":"update","data":[{"symbol":"EUR/USD","bids":[{"price":1.08422,"qty":0.00000000},{"price":1.08406,"qty":38830.74225979},{"price":1.08431,"qty":3692.56360857}],"asks":[],"checksum":1470475740,"timestamp":"2024-06-01T22:43:51.890806Z"}]}
{"channel":"book","type":"update","data":[{"symbol":"EUR/USD","bids":[{"price":1.08430,"qty":0.00000000},{"price":1.08406,"qty":38830.74225979},{"price":1.08432,"qty":1984.80000000}],"asks":[],"checksum":170271729,"timestamp":"2024-06-01T22:43:51.921318Z"}]}
{"channel":"book","type":"update","data":[{"symbol":"EUR/USD","bids":[{"price":1.08431,"qty":0.00000000},{"price":1.08406,"qty":38830.74225979},{"price":1.08422,"qty":3692.87012452}],"asks":[],"checksum":1381361201,"timestamp":"2024-06-01T22:43:51.924696Z"}]}
{"channel":"book","type":"update","data":[{"symbol":"EUR/USD","bids":[{"price":1.08422,"qty":0.00000000},{"price":1.08406,"qty":38830.74225979},{"price":1.08440,"qty":3692.25714350}],"asks":[],"checksum":3951548089,"timestamp":"2024-06-01T22:43:52.174982Z"}]}
{"channel":"book","type":"update","data":[{"symbol":"EUR/USD","bids":[{"price":1.08440,"qty":0.00000000},{"price":1.08406,"qty":38830.74225979},{"price":1.08441,"qty":3692.22309496}],"asks":[],"checksum":3069284549,"timestamp":"2024-06-01T22:43:52.178141Z"}]}
{"channel":"book","type":"update","data":[{"symbol":"EUR/USD","bids":[{"price":1.08441,"qty":0.00000000},{"price":1.08406,"qty":38830.74225979},{"price":1.08440,"qty":3692.25714350}],"asks":[],"checksum":3951548089,"timestamp":"2024-06-01T22:43:52.181205Z"}]}
{"channel":"book","type":"update","data":[{"symbol":"EUR/USD","bids":[{"price":1.08440,"qty":0.00000000},{"price":1.08406,"qty":38830.74225979},{"price":1.08422,"qty":3692.87012452}],"asks":[],"checksum":1381361201,"timestamp":"2024-06-01T22:43:52.438609Z"}]}
{"channel":"book","type":"update","data":[{"symbol":"EUR/USD","bids":[{"price":1.08422,"qty":0.00000000},{"price":1.08406,"qty":38830.74225979},{"price":1.08423,"qty":3692.83606468}],"asks":[],"checksum":159079403,"timestamp":"2024-06-01T22:43:52.441988Z"}]}
{"channel":"book","type":"update","data":[{"symbol":"EUR/USD","bids":[{"price":1.08423,"qty":0.00000000},{"price":1.08406,"qty":38830.74225979},{"price":1.08422,"qty":3692.87012452}],"asks":[],"checksum":1381361201,"timestamp":"2024-06-01T22:43:52.444832Z"}]}
{"channel":"book","type":"update","data":[{"symbol":"EUR/USD","bids":[{"price":1.08408,"qty":365.65041324}],"asks":[],"checksum":2483794488,"timestamp":"2024-06-01T22:43:52.505288Z"}]}
{"channel":"book","type":"update","data":[{"symbol":"EUR/USD","bids":[],"asks":[{"price":1.08468,"qty":0.00000000},{"price":1.08485,"qty":4167.00000000}],"checksum":819043434,"timestamp":"2024-06-01T22:43:53.059497Z"}]}
{"channel":"book","type":"update","data":[{"symbol":"EUR/USD","bids":[],"asks":[{"price":1.08466,"qty":968.37246541}],"checksum":1350913520,"timestamp":"2024-06-01T22:43:53.064704Z"}]}
{"channel":"book","type":"update","data":[{"symbol":"EUR/USD","bids":[{"price":1.08421,"qty":0.00000000},{"price":1.08406,"qty":38830.74225979}],"asks":[],"checksum":3713321063,"timestamp":"2024-06-01T22:43:53.577666Z"}]}
{"channel":"book","type":"update","data":[{"symbol":"EUR/USD","bids":[{"price":1.08422,"qty":0.00000000},{"price":1.08405,"qty":2000.00000000},{"price":1.08421,"qty":3692.90418499}],"asks":[],"checksum":847088198,"timestamp":"2024-06-01T22:43:53.581190Z"}]}
{"channel":"book","type":"update","data":[{"symbol":"EUR/USD","bids":[{"price":1.08423,"qty":503.39595724}],"asks":[],"checksum":2646341885,"timestamp":"2024-06-01T22:43:53.587076Z"}]}
{"channel":"book","type":"update","data":[{"symbol":"EUR/USD","bids":[{"price":1.08421,"qty":5137.12343955}],"asks":[],"checksum":3072591582,"timestamp":"2024-06-01T22:43:53.587317Z"}]}
{"channel":"book","type":"update","data":[{"symbol":"EUR/USD","bids":[{"price":1.08421,"qty":1444.21925456},{"price":1.08424,"qty":3692.80200547}],"asks":[],"checksum":4019966777,"timestamp":"2024-06-01T22:43:53.591491Z"}]}
{"channel":"book","type":"update","data":[{"symbol":"EUR/USD","bids":[{"price":1.08408,"qty":342.58938454},{"price":1.08415,"qty":23.05953973}],"asks":[],"checksum":1805334355,"timestamp":"2024-06-01T22:43:54.478746Z"}]}
{"channel":"book","type":"update","data":[{"symbol":"EUR/USD","bids":[{"price":1.08432,"qty":0.00000000},{"price":1.08408,"qty":342.58938454},{"price":1.08443,"qty":1984.80000000}],"asks":[],"checksum":3049498381,"timestamp":"2024-06-01T22:43:54.499412Z"}]}
{"channel":"book","type":"update","data":[{"symbol":"EUR/USD","bids":[],"asks":[{"price":1.08467,"qty":0.00000000},{"price":1.08485,"qty":4167.00000000}],"checksum":2549083841,"timestamp":"2024-06-01T22:43:55.237287Z"}]}
{"channel":"book","type":"update","data":[{"symbol":"EUR/USD","bids":[],"asks":[{"price":1.08466,"qty":0.00000000},{"price":1.08489,"qty":175.24140000}],"checksum":3113099193,"timestamp":"2024-06-01T22:43:55.506655Z"}]}
{"channel":"book","type":"update","data":[{"symbol":"EUR/USD","bids":[],"asks":[{"price":1.08466,"qty":1016.47043338}],"checksum":1079675638,"timestamp":"2024-06-01T22:43:55.512161Z"}]}
{"channel":"book","type":"update","data":[{"symbol":"EUR/USD","bids":[{"price":1.08421,"qty":0.00000000},{"price":1.08408,"qty":342.58938454}],"asks":[],"checksum":1335449236,"timestamp":"2024-06-01T22:43:56.413156Z"}]}
{"channel":"book","type":"update","data":[{"symbol":"EUR/USD","bids":[{"price":1.08423,"qty":0.00000000},{"price":1.08407,"qty":17338.73636606}],"asks":[],"checksum":485788897,"timestamp":"2024-06-01T22:43:56.413171Z"}]}
{"channel":"book","type":"update","data":[{"symbol":"EUR/USD","bids":[{"price":1.08424,"qty":0.00000000},{"price":1.08406,"qty":38830.74225979},{"price":1.08421,"qty":3692.90418499}],"asks":[],"checksum":2347823342,"timestamp":"2024-06-01T22:43:56.417297Z"}]}
{"channel":"book","type":"update","data":[{"symbol":"EUR/USD","bids":[{"price":1.08425,"qty":147.75982709}],"asks":[],"checksum":2639058336,"timestamp":"2024-06-01T22:43:56.417769Z"}]}
{"channel":"book","type":"update","data":[{"symbol":"EUR/USD","bids":[{"price":1.08421,"qty":5774.15223748}],"asks":[],"checksum":3574571836,"timestamp":"2024-06-01T22:43:56.417836Z"}]}
{"channel":"book","type":"update","data":[{"symbol":"EUR/USD","bids":[{"price":1.08421,"qty":2081.24805249},{"price":1.08422,"qty":3692.87012452}],"asks":[],"checksum":1367947785,"timestamp":"2024-06-01T22:43:56.422990Z"}]}
{"channel":"book","type":"update","data":[{"symbol":"EUR/USD","bids":[{"price":1.08420,"qty":0.00000000},{"price":1.08408,"qty":342.58938454}],"asks":[],"checksum":3306015920,"timestamp":"2024-06-01T22:43:57.941410Z"}]}
{"channel":"book","type":"update","data":[{"symbol":"EUR/USD","bids":[{"price":1.08423,"qty":21022.19514710}],"asks":[],"checksum":2542002525,"timestamp":"2024-06-01T22:43:57.947068Z"}]}
{"channel":"book","type":"update","data":[{"symbol":"EUR/USD","bids":[{"price":1.08443,"qty":0.00000000},{"price":1.08408,"qty":32323.89044714},{"price":1.08426,"qty":1984.80000000}],"asks":[],"checksum":127015215,"timestamp":"2024-06-01T22:43:57.948911Z"}]}
{"channel":"book","type":"update","data":[{"symbol":"EUR/USD","bids":[{"price":1.08422,"qty":0.00000000},{"price":1.08408,"qty":32323.89044714},{"price":1.08424,"qty":3692.80200547}],"asks":[],"checksum":4038841031,"timestamp":"2024-06-01T22:43:57.950753Z"}]}
{"channel":"book","type":"update","data":[{"symbol":"EUR/USD","bids":[{"price":1.08424,"qty":0.00000000},{"price":1.08408,"qty":32323.89044714},{"price":1.08427,"qty":3692.69983160}],"asks":[],"checksum":3224087693,"timestamp":"2024-06-01T22:43:57.955328Z"}]}
{"channel":"book","type":"update","data":[{"symbol":"EUR/USD","bids":[{"price":1.08426,"qty":0.00000000},{"price":1.08409,"qty":17338.73636606},{"price":1.08443,"qty":1984.80000000}],"asks":[],"checksum":875476272,"timestamp":"2024-06-01T22:43:58.012262Z"}]}
{"channel":"book","type":"update","data":[{"symbol":"EUR/USD","bids":[{"price":1.08427,"qty":0.00000000},{"price":1.08409,"qty":17338.73636606},{"price":1.08424,"qty":3692.80200547}],"asks":[],"checksum":1621764789,"timestamp":"2024-06-01T22:43:58.017812Z"}]}
{"channel":"book","type":"update","data":[{"symbol":"EUR/USD","bids":[],"asks":[{"price":1.08466,"qty":0.00000000},{"price":1.08489,"qty":175.24140000}],"checksum":2575220730,"timestamp":"2024-06-01T22:43:58.084164Z"}]}
{"channel":"book","type":"update","data":[{"symbol":"EUR/USD","bids":[],"asks":[{"price":1.08468,"qty":1052.54390936}],"checksum":1744691909,"timestamp":"2024-06-01T22:43:58.089912Z"}]}
{"channel":"book","type":"update","data":[{"symbol":"EUR/USD","bids":[],"asks":[{"price":1.08467,"qty":12623.84053704}],"checksum":3227741631,"timestamp":"2024-06-01T22:43:59.430870Z"}]}
{"channel":"book","type":"update","data":[{"symbol":"EUR/USD","bids":[{"price":1.08443,"qty":0.00000000},{"price":1.08409,"qty":17338.73636606},{"price":1.08426,"qty":1984.80000000}],"asks":[],"checksum":1349686733,"timestamp":"2024-06-01T22:43:59.468143Z"}]}
{"channel":"book","type":"update","data":[{"symbol":"EUR/USD","bids":[{"price":1.08424,"qty":0.00000000},{"price":1.08409,"qty":17338.73636606},{"price":1.08427,"qty":3692.69983160}],"asks":[],"checksum":1625484167,"timestamp":"2024-06-01T22:43:59.471683Z"}]}
{"channel":"book","type":"update","data":[{"symbol":"EUR/USD","bids":[{"price":1.08425,"qty":0.00000000},{"price":1.08409,"qty":17338.73636606}],"asks":[],"checksum":356658036,"timestamp":"2024-06-01T22:43:59.583654Z"}]}
{"channel":"book","type":"update","data":[{"symbol":"EUR/USD","bids":[{"price":1.08421,"qty":0.00000000},{"price":1.08408,"qty":32323.89044714}],"asks":[],"checksum":2654900428,"timestamp":"2024-06-01T22:43:59.583755Z"}]}
{"channel":"book","type":"update","data":[{"symbol":"EUR/USD","bids":[{"price":1.08410,"qty":1493.46099812}],"asks":[],"checksum":317162529,"timestamp":"2024-06-01T22:43:59.590150Z"}]}
{"channel":"book","type":"update","data":[{"symbol":"EUR/USD","bids":[{"price":1.08425,"qty":454.90012131}],"asks":[],"checksum":2799805286,"timestamp":"2024-06-01T22:43:59.590203Z"}]}
{"channel":"book","type":"update","data":[{"symbol":"EUR/USD","bids":[{"price":1.08426,"qty":0.00000000},{"price":1.08409,"qty":17338.73636606},{"price":1.08428,"qty":1984.80000000}],"asks":[],"checksum":1365132160,"timestamp":"2024-06-01T22:43:59.590884Z"}]}
{"channel":"book","type":"update","data":[{"symbol":"EUR/USD","bids":[{"price":1.08427,"qty":0.00000000},{"price":1.08409,"qty":17338.73636606},{"price":1.08429,"qty":3692.63171883}],"asks":[],"checksum":3864644124,"timestamp":"2024-06-01T22:43:59.594060Z"}]}
{"channel":"book","type":"update","data":[{"symbol":"EUR/USD","bids":[{"price":1.08428,"qty":0.00000000},{"price":1.08409,"qty":17338.73636606},{"price":1.08430,"qty":1984.80000000}],"asks":[],"checksum":1130218034,"timestamp":"2024-06-01T22:43:59.925320Z"}]}
{"channel":"book","type":"update","data":[{"symbol":"EUR/USD","bids":[{"price":1.08429,"qty":0.00000000},{"price":1.08409,"qty":17338.73636606},{"price":1.08424,"qty":3692.80200547}],"asks":[],"checksum":2087760968,"timestamp":"2024-06-01T22:43:59.928582Z"}]}
{"channel":"book","type":"update","data":[{"symbol":"EUR/USD","bids":[],"asks":[{"price":1.08468,"qty":0.00000000},{"price":1.08485,"qty":4167.00000000}],"checksum":1149832493,"timestamp":"2024-06-01T22:44:00.641380Z"}]}
{"channel":"book","type":"update","data":[{"symbol":"EUR/USD","bids":[],"asks":[{"price":1.08466,"qty":1016.47043338}],"checksum":3100232300,"timestamp":"2024-06-01T22:44:00.646556Z"}]}
{"channel":"book","type":"update","data":[{"symbol":"EUR/USD","bids":[{"price":1.08415,"qty":0.00000000},{"price":1.08409,"qty":17338.73636606},{"price":1.08411,"qty":23.06039055}],"asks":[],"checksum":317824506,"timestamp":"2024-06-01T22:44:00.739124Z"}]}
{"channel":"book","type":"update","data":[{"symbol":"EUR/USD","bids":[{"price":1.08423,"qty":0.00000000},{"price":1.08409,"qty":17338.73636606}],"asks":[],"checksum":3280602521,"timestamp":"2024-06-01T22:44:01.362811Z"}]}
{"channel":"book","type":"update","data":[{"symbol":"EUR/USD","bids":[{"price":1.08409,"qty":0.00000000},{"price":1.08408,"qty":342.58938454}],"asks":[],"checksum":3730447567,"timestamp":"2024-06-01T22:44:01.365909Z"}]}
{"channel":"book","type":"update","data":[{"symbol":"EUR/USD","bids":[{"price":1.08424,"qty":0.00000000},{"price":1.08405,"qty":2000.00000000},{"price":1.08418,"qty":3693.00637017}],"asks":[],"checksum":2913929771,"timestamp":"2024-06-01T22:44:01.366307Z"}]}
{"channel":"book","type":"update","data":[{"symbol":"EUR/USD","bids":[{"price":1.08425,"qty":5020.58738199}],"asks":[],"checksum":2980640638,"timestamp":"2024-06-01T22:44:01.367405Z"}]}
{"channel":"book","type":"update","data":[{"symbol":"EUR/USD","bids":[{"price":1.08426,"qty":3204.72352783}],"asks":[],"checksum":305791756,"timestamp":"2024-06-01T22:44:01.367485Z"}]}
{"channel":"book","type":"update","data":[{"symbol":"EUR/USD","bids":[{"price":1.08418,"qty":56260.55003339}],"asks":[],"checksum":2394425165,"timestamp":"2024-06-01T22:44:01.367504Z"}]}
{"channel":"book","type":"update","data":[{"symbol":"EUR/USD","bids":[{"price":1.08418,"qty":52567.54366322},{"price":1.08426,"qty":6897.45741676}],"asks":[],"checksum":2873733870,"timestamp":"2024-06-01T22:44:01.370376Z"}]}
{"channel":"book","type":"update","data":[{"symbol":"EUR/USD","bids":[{"price":1.08426,"qty":3204.72352783},{"price":1.08431,"qty":3692.56360857}],"asks":[],"checksum":4071976080,"timestamp":"2024-06-01T22:44:01.375216Z"}]}
{"channel":"book","type":"update","data":[{"symbol":"EUR/USD","bids":[{"price":1.08430,"qty":0.00000000},{"price":1.08410,"qty":1493.46099812},{"price":1.08432,"qty":1984.80000000}],"asks":[],"checksum":421544810,"timestamp":"2024-06-01T22:44:01.382189Z"}]}
{"channel":"book","type":"update","data":[{"symbol":"EUR/USD","bids":[{"price":1.08431,"qty":0.00000000},{"price":1.08410,"qty":1493.46099812},{"price":1.08427,"qty":3692.69983160}],"asks":[],"checksum":885574775,"timestamp":"2024-06-01T22:44:01.385566Z"}]}
{"channel":"book","type":"update","data":[{"symbol":"EUR/USD","bids":[],"asks":[{"price":1.08449,"qty":461.31409960}],"checksum":450541291,"timestamp":"2024-06-01T22:44:01.530553Z"}]}
{"channel":"book","type":"update","data":[{"symbol":"EUR/USD","bids":[],"asks":[{"price":1.08450,"qty":0.00000000},{"price":1.08480,"qty":4167.00000000},{"price":1.08448,"qty":3692.39455756}],"checksum":1436427158,"timestamp":"2024-06-01T22:44:01.533697Z"}]}
{"channel":"book","type":"update","data":[{"symbol":"EUR/USD","bids":[],"asks":[{"price":1.08467,"qty":0.00000000},{"price":1.08480,"qty":4167.00000000}],"checksum":1848534138,"timestamp":"2024-06-01T22:44:01.554820Z"}]}
{"channel":"book","type":"update","data":[{"symbol":"EUR/USD","bids":[{"price":1.08419,"qty":17338.73636606}],"asks":[],"checksum":3869486056,"timestamp":"2024-06-01T22:44:01.558068Z"}]}
{"channel":"book","type":"update","data":[{"symbol":"EUR/USD","bids":[{"price":1.08432,"qty":0.00000000},{"price":1.08411,"qty":23.06039055},{"price":1.08443,"qty":1984.80000000}],"asks":[],"checksum":594232070,"timestamp":"2024-06-01T22:44:01.566685Z"}]}
{"channel":"book","type":"update","data":[{"symbol":"EUR/USD","bids":[],"asks":[{"price":1.08451,"qty":0.00000000},{"price":1.08485,"qty":4167.00000000}],"checksum":949415880,"timestamp":"2024-06-01T22:44:01.719857Z"}]}
{"channel":"book","type":"update","data":[{"symbol":"EUR/USD","bids":[{"price":1.08419,"qty":17361.79505503}],"asks":[],"checksum":4047273620,"timestamp":"2024-06-01T22:44:02.729157Z"}]}
{"channel":"book","type":"update","data":[{"symbol":"EUR/USD","bids":[{"price":1.08425,"qty":4565.68726068}],"asks":[],"checksum":1089698599,"timestamp":"2024-06-01T22:44:02.967075Z"}]}
{"channel":"book","type":"update","data":[{"symbol":"EUR/USD","bids":[{"price":1.08428,"qty":147.75982709}],"asks":[],"checksum":3110313168,"timestamp":"2024-06-01T22:44:02.976591Z"}]}
{"channel":"book","type":"update","data":[{"symbol":"EUR/USD","bids":[{"price":1.08420,"qty":2000.57952333}],"asks":[],"checksum":3188702304,"timestamp":"2024-06-01T22:44:02.976678Z"}]}
{"channel":"book","type":"update","data":[{"symbol":"EUR/USD","bids":[],"asks":[{"price":1.08466,"qty":0.00000000},{"price":1.08489,"qty":175.24140000}],"checksum":795698624,"timestamp":"2024-06-01T22:44:03.192377Z"}]}
{"channel":"book","type":"update","data":[{"symbol":"EUR/USD","bids":[],"asks":[{"price":1.08468,"qty":1052.54390936}],"checksum":483544358,"timestamp":"2024-06-01T22:44:03.198237Z"}]}
{"channel":"book","type":"update","data":[{"symbol":"EUR/USD","bids":[],"asks":[{"price":1.08469,"qty":0.00000000},{"price":1.08489,"qty":175.24140000}],"checksum":2042303469,"timestamp":"2024-06-01T22:44:03.518724Z"}]}
{"channel":"book","type":"update","data":[{"symbol":"EUR/USD","bids":[],"asks":[{"price":1.08469,"qty":27154.34253564}],"checksum":1843932703,"timestamp":"2024-06-01T22:44:03.524167Z"}]}
{"channel":"book","type":"update","data":[{"symbol":"EUR/USD","bids":[{"price":1.08425,"qty":0.00000000},{"price":1.08417,"qty":4611.80010878}],"asks":[],"checksum":782119239,"timestamp":"2024-06-01T22:44:04.765302Z"}]}
{"channel":"book","type":"update","data":[{"symbol":"EUR/USD","bids":[{"price":1.08418,"qty":0.00000000},{"price":1.08414,"qty":2830.45000000}],"asks":[],"checksum":1724903037,"timestamp":"2024-06-01T22:44:04.765476Z"}]}
{"channel":"book","type":"update","data":[{"symbol":"EUR/USD","bids":[{"price":1.08426,"qty":0.00000000},{"price":1.08408,"qty":342.58938454}],"asks":[],"checksum":316069945,"timestamp":"2024-06-01T22:44:04.765511Z"}]}
{"channel":"book","type":"update","data":[{"symbol":"EUR/USD","bids":[{"price":1.08427,"qty":0.00000000},{"price":1.08405,"qty":2000.00000000},{"price":1.08421,"qty":3692.90418499}],"asks":[],"checksum":2880705797,"timestamp":"2024-06-01T22:44:04.769361Z"}]}
{"channel":"book","type":"update","data":[{"symbol":"EUR/USD","bids":[{"price":1.08419,"qty":23.05868897}],"asks":[],"checksum":1692858068,"timestamp":"2024-06-01T22:44:04.769576Z"}]}
{"channel":"book","type":"update","data":[{"symbol":"EUR/USD","bids":[{"price":1.08428,"qty":3361.40786150}],"asks":[],"checksum":657447620,"timestamp":"2024-06-01T22:44:04.770924Z"}]}
{"channel":"book","type":"update","data":[{"symbol":"EUR/USD","bids":[{"price":1.08421,"qty":30194.65228984}],"asks":[],"checksum":1907116008,"timestamp":"2024-06-01T22:44:04.770955Z"}]}
{"channel":"book","type":"update","data":[{"symbol":"EUR/USD","bids":[{"price":1.08421,"qty":26501.74810485},{"price":1.08429,"qty":3692.63171883}],"asks":[],"checksum":4241997018,"timestamp":"2024-06-01T22:44:04.774089Z"}]}
{"channel":"book","type":"update","data":[{"symbol":"EUR/USD","bids":[{"price":1.08443,"qty":0.00000000},{"price":1.08408,"qty":342.58938454},{"price":1.08429,"qty":5677.43171883}],"asks":[],"checksum":853233313,"timestamp":"2024-06-01T22:44:04.778375Z"}]}
{"channel":"book","type":"update","data":[{"symbol":"EUR/USD","bids":[{"price":1.08429,"qty":1984.80000000},{"price":1.08430,"qty":3692.59766338}],"asks":[],"checksum":1496533610,"timestamp":"2024-06-01T22:44:04.782044Z"}]}
{"channel":"book","type":"update","data":[{"symbol":"EUR/USD","bids":[{"price":1.08429,"qty":0.00000000},{"price":1.08408,"qty":342.58938454},{"price":1.08431,"qty":1984.80000000}],"asks":[],"checksum":452264398,"timestamp":"2024-06-01T22:44:04.901510Z"}]}
{"channel":"book","type":"update","data":[{"symbol":"EUR/USD","bids":[{"price":1.08430,"qty":0.00000000},{"price":1.08408,"qty":342.58938454},{"price":1.08432,"qty":3692.52955438}],"asks":[],"checksum":3654209873,"timestamp":"2024-06-01T22:44:04.904556Z"}]}
{"channel":"book","type":"update","data":[{"symbol":"EUR/USD","bids":[{"price":1.08431,"qty":0.00000000},{"price":1.08408,"qty":342.58938454},{"price":1.08433,"qty":1984.80000000}],"asks":[],"checksum":222001213,"timestamp":"2024-06-01T22:44:05.236258Z"}]}
{"channel":"book","type":"update","data":[{"symbol":"EUR/USD","bids":[{"price":1.08432,"qty":0.00000000},{"price":1.08408,"qty":342.58938454},{"price":1.08429,"qty":3692.63171883}],"asks":[],"checksum":2428477054,"timestamp":"2024-06-01T22:44:05.239596Z"}]}
{"channel":"book","type":"update","data":[{"symbol":"EUR/USD","bids":[{"price":1.08429,"qty":0.00000000},{"price":1.08408,"qty":342.58938454},{"price":1.08422,"qty":3692.87012452}],"asks":[],"checksum":2351667792,"timestamp":"2024-06-01T22:44:05.493137Z"}]}
{"channel":"book","type":"update","data":[{"symbol":"EUR/USD","bids":[],"asks":[{"price":1.08468,"qty":0.00000000},{"price":1.08489,"qty":175.24140000}],"checksum":1325603173,"timestamp":"2024-06-01T22:44:05.636320Z"}]}
{"channel":"book","type":"update","data":[{"symbol":"EUR/USD","bids":[],"asks":[{"price":1.08467,"qty":12917.13974401}],"checksum":3822959385,"timestamp":"2024-06-01T22:44:05.638384Z"}]}
{"channel":"book","type":"update","data":[{"symbol":"EUR/USD","bids":[],"asks":[{"price":1.08468,"qty":1124.69086132}],"checksum":4036972638,"timestamp":"2024-06-01T22:44:05.641924Z"}]}
{"channel":"book","type":"update","data":[{"symbol":"EUR/USD","bids":[],"asks":[{"price":1.08478,"qty":175.24140000}],"checksum":1885650288,"timestamp":"2024-06-01T22:44:05.831577Z"}]}
{"channel":"book","type":"update","data":[{"symbol":"EUR/USD","bids":[{"price":1.08420,"qty":0.00000000},{"price":1.08408,"qty":342.58938454}],"asks":[],"checksum":3511876367,"timestamp":"2024-06-01T22:44:05.968250Z"}]}
{"channel":"book","type":"update","data":[{"symbol":"EUR/USD","bids":[{"price":1.08428,"qty":3213.64803441}],"asks":[],"checksum":4212765643,"timestamp":"2024-06-01T22:44:05.968672Z"}]}
{"channel":"book","type":"update","data":[{"symbol":"EUR/USD","bids":[{"price":1.08430,"qty":18.43759795}],"asks":[],"checksum":1611556652,"timestamp":"2024-06-01T22:44:05.972939Z"}]}
{"channel":"book","type":"update","data":[{"symbol":"EUR/USD","bids":[{"price":1.08422,"qty":3889.12578754}],"asks":[],"checksum":3301046502,"timestamp":"2024-06-01T22:44:05.973204Z"}]}
{"channel":"book","type":"update","data":[{"symbol":"EUR/USD","bids":[{"price":1.08419,"qty":0.00000000},{"price":1.08408,"qty":342.58938454},{"price":1.08418,"qty":23.05890165}],"asks":[],"checksum":599548979,"timestamp":"2024-06-01T22:44:06.753631Z"}]}
{"channel":"book","type":"update","data":[{"symbol":"EUR/USD","bids":[{"price":1.08422,"qty":196.25566302},{"price":1.08429,"qty":3692.63171883}],"asks":[],"checksum":3281265577,"timestamp":"2024-06-01T22:44:07.397413Z"}]}
{"channel":"book","type":"update","data":[{"symbol":"EUR/USD","bids":[],"asks":[{"price":1.08469,"qty":0.00000000},{"price":1.08480,"qty":4167.00000000}],"checksum":3966775911,"timestamp":"2024-06-01T22:44:07.675105Z"}]}
{"channel":"book","type":"update","data":[{"symbol":"EUR/USD","bids":[],"asks":[{"price":1.08467,"qty":0.00000000},{"price":1.08485,"qty":4167.00000000}],"checksum":4191652964,"timestamp":"2024-06-01T22:44:07.675258Z"}]}
{"channel":"book","type":"update","data":[{"symbol":"EUR/USD","bids":[],"asks":[{"price":1.08467,"qty":14499.05116531}],"checksum":2655864638,"timestamp":"2024-06-01T22:44:07.681131Z"}]}
{"channel":"book","type":"update","data":[{"symbol":"EUR/USD","bids":[],"asks":[{"price":1.08469,"qty":35063.89964210}],"checksum":4240522581,"timestamp":"2024-06-01T22:44:07.681168Z"}]}
{"channel":"book","type":"update","data":[{"symbol":"EUR/USD","bids":[],"asks":[{"price":1.08468,"qty":0.00000000},{"price":1.08480,"qty":4167.00000000}],"checksum":3261485482,"timestamp":"2024-06-01T22:44:08.137349Z"}]}
{"channel":"book","type":"update","data":[{"symbol":"EUR/USD","bids":[],"asks":[{"price":1.08466,"qty":1100.64187734}],"checksum":168744068,"timestamp":"2024-06-01T22:44:08.143202Z"}]}
{"channel":"book","type":"update","data":[{"symbol":"EUR/USD","bids":[{"price":1.08428,"qty":0.00000000},{"price":1.08414,"qty":2830.45000000}],"asks":[],"checksum":1647439424,"timestamp":"2024-06-01T22:44:08.250990Z"}]}
{"channel":"book","type":"update","data":[{"symbol":"EUR/USD","bids":[{"price":1.08421,"qty":0.00000000},{"price":1.08408,"qty":342.58938454}],"asks":[],"checksum":985237490,"timestamp":"2024-06-01T22:44:08.251024Z"}]}
{"channel":"book","type":"update","data":[{"symbol":"EUR/USD","bids":[{"price":1.08429,"qty":0.00000000},{"price":1.08405,"qty":2000.00000000},{"price":1.08422,"qty":3889.12578754}],"asks":[],"checksum":3143878750,"timestamp":"2024-06-01T22:44:08.254655Z"}]}
{"channel":"book","type":"update","data":[{"symbol":"EUR/USD","bids":[{"price":1.08418,"qty":1866.81869662}],"asks":[],"checksum":2791688750,"timestamp":"2024-06-01T22:44:08.257075Z"}]}
{"channel":"book","type":"update","data":[{"symbol":"EUR/USD","bids":[{"price":1.08422,"qty":196.25566302},{"price":1.08418,"qty":5559.82506679}],"asks":[],"checksum":1123962661,"timestamp":"2024-06-01T22:44:08.257687Z"}]}
{"channel":"book","type":"update","data":[{"symbol":"EUR/USD","bids":[{"price":1.08418,"qty":1866.81869662},{"price":1.08419,"qty":3692.97230781}],"asks":[],"checksum":866978325,"timestamp":"2024-06-01T22:44:08.260800Z"}]}
{"channel":"book","type":"update","data":[{"symbol":"EUR/USD","bids":[{"price":1.08419,"qty":0.00000000},{"price":1.08405,"qty":2000.00000000},{"price":1.08420,"qty":3692.93824609}],"asks":[],"checksum":3834903700,"timestamp":"2024-06-01T22:44:08.264804Z"}]}
{"channel":"book","type":"update","data":[{"symbol":"EUR/USD","bids":[{"price":1.08420,"qty":0.00000000},{"price":1.08405,"qty":2000.00000000},{"price":1.08419,"qty":3692.97230781}],"asks":[],"checksum":866978325,"timestamp":"2024-06-01T22:44:08.268376Z"}]}
{"channel":"book","type":"update","data":[{"symbol":"EUR/USD","bids":[{"price":1.08419,"qty":0.00000000},{"price":1.08405,"qty":2000.00000000},{"price":1.08420,"qty":3692.93824609}],"asks":[],"checksum":3834903700,"timestamp":"2024-06-01T22:44:08.272204Z"}]}
{"channel":"book","type":"update","data":[{"symbol":"EUR/USD","bids":[{"price":1.08420,"qty":0.00000000},{"price":1.08405,"qty":2000.00000000},{"price":1.08419,"qty":3692.97230781}],"asks":[],"checksum":866978325,"timestamp":"2024-06-01T22:44:08.275364Z"}]}
{"channel":"book","type":"update","data":[{"symbol":"EUR/USD","bids":[{"price":1.08418,"qty":1843.75979497}],"asks":[],"checksum":3304040437,"timestamp":"2024-06-01T22:44:08.603519Z"}]}
{"channel":"book","type":"update","data":[{"symbol":"EUR/USD","bids":[],"asks":[{"price":1.08469,"qty":0.00000000},{"price":1.08480,"qty":4167.00000000}],"checksum":644071066,"timestamp":"2024-06-01T22:44:09.814404Z"}]}
{"channel":"book","type":"update","data":[{"symbol":"EUR/USD","bids":[],"asks":[{"price":1.08467,"qty":0.00000000},{"price":1.08485,"qty":4167.00000000}],"checksum":541561269,"timestamp":"2024-06-01T22:44:09.814505Z"}]}
{"channel":"book","type":"update","data":[{"symbol":"EUR/USD","bids":[],"asks":[{"price":1.08469,"qty":33481.98822080}],"checksum":5227249,"timestamp":"2024-06-01T22:44:09.819704Z"}]}
{"channel":"book","type":"update","data":[{"symbol":"EUR/USD","bids":[],"asks":[{"price":1.08465,"qty":3425.67121627}],"checksum":2378618383,"timestamp":"2024-06-01T22:44:09.819767Z"}]}
{"channel":"book","type":"update","data":[{"symbol":"EUR/USD","bids":[],"asks":[{"price":1.08457,"qty":461.31409960}],"checksum":3122646864,"timestamp":"2024-06-01T22:44:09.971878Z"}]}
{"channel":"book","type":"update","data":[{"symbol":"EUR/USD","bids":[],"asks":[{"price":1.08449,"qty":0.00000000},{"price":1.08479,"qty":4609.18918798}],"checksum":4240773609,"timestamp":"2024-06-01T22:44:10.137261Z"}]}
{"channel":"book","type":"update","data":[{"symbol":"EUR/USD","bids":[],"asks":[{"price":1.08448,"qty":0.00000000},{"price":1.08480,"qty":4167.00000000},{"price":1.08456,"qty":3692.39736426}],"checksum":36651078,"timestamp":"2024-06-01T22:44:10.140577Z"}]}
{"channel":"book","type":"update","data":[{"symbol":"EUR/USD","bids":[],"asks":[{"price":1.08466,"qty":0.00000000},{"price":1.08480,"qty":4167.00000000}],"checksum":1968545724,"timestamp":"2024-06-01T22:44:10.709613Z"}]}
{"channel":"book","type":"update","data":[{"symbol":"EUR/USD","bids":[],"asks":[{"price":1.08464,"qty":174.75599386}],"checksum":3553083516,"timestamp":"2024-06-01T22:44:10.714968Z"}]}
{"channel":"book","type":"update","data":[{"symbol":"EUR/USD","bids":[],"asks":[{"price":1.08468,"qty":901.11311616}],"checksum":1771542305,"timestamp":"2024-06-01T22:44:10.715098Z"}]}
{"channel":"book","type":"update","data":[{"symbol":"EUR/USD","bids":[],"asks":[{"price":1.08455,"qty":90.58454991}],"checksum":2933627267,"timestamp":"2024-06-01T22:44:10.715195Z"}]}
{"channel":"book","type":"update","data":[{"symbol":"EUR/USD","bids":[],"asks":[{"price":1.08456,"qty":0.00000000},{"price":1.08478,"qty":175.24140000},{"price":1.08454,"qty":3692.39645664}],"checksum":144430579,"timestamp":"2024-06-01T22:44:10.718647Z"}]}
{"channel":"book","type":"update","data":[{"symbol":"EUR/USD","bids":[{"price":1.08418,"qty":0.00000000},{"price":1.08405,"qty":2000.00000000}],"asks":[],"checksum":760140718,"timestamp":"2024-06-01T22:44:11.689112Z"}]}
{"channel":"book","type":"update","data":[{"symbol":"EUR/USD","bids":[{"price":1.08419,"qty":0.00000000},{"price":1.08387,"qty":17361.80186284},{"price":1.08418,"qty":3693.00637017}],"asks":[],"checksum":162169966,"timestamp":"2024-06-01T22:44:11.692342Z"}]}
{"channel":"book","type":"update","data":[{"symbol":"EUR/USD","bids":[{"price":1.08420,"qty":8693.20099216}],"asks":[],"checksum":649957541,"timestamp":"2024-06-01T22:44:11.694505Z"}]}
{"channel":"book","type":"update","data":[{"symbol":"EUR/USD","bids":[{"price":1.08418,"qty":0.00000000},{"price":1.08405,"qty":2000.00000000},{"price":1.08421,"qty":3692.90418499}],"asks":[],"checksum":2413551387,"timestamp":"2024-06-01T22:44:11.699065Z"}]}
{"channel":"book","type":"update","data":[{"symbol":"EUR/USD","bids":[{"price":1.08430,"qty":0.00000000},{"price":1.08405,"qty":2000.00000000}],"asks":[],"checksum":3612223095,"timestamp":"2024-06-01T22:44:11.857693Z"}]}
{"channel":"book","type":"update","data":[{"symbol":"EUR/USD","bids":[{"price":1.08422,"qty":0.00000000},{"price":1.08389,"qty":17338.73636606}],"asks":[],"checksum":2608397116,"timestamp":"2024-06-01T22:44:11.857792Z"}]}
{"channel":"book","type":"update","data":[{"symbol":"EUR/USD","bids":[{"price":1.08420,"qty":8776.29970468}],"asks":[],"checksum":1872595179,"timestamp":"2024-06-01T22:44:11.864790Z"}]}
{"channel":"book","type":"update","data":[{"symbol":"EUR/USD","bids":[],"asks":[{"price":1.08465,"qty":0.00000000},{"price":1.08478,"qty":175.24140000}],"checksum":1568276065,"timestamp":"2024-06-01T22:44:11.889634Z"}]}
{"channel":"book","type":"update","data":[{"symbol":"EUR/USD","bids":[],"asks":[{"price":1.08469,"qty":0.00000000},{"price":1.08479,"qty":4609.18918798}],"checksum":3869600207,"timestamp":"2024-06-01T22:44:11.889768Z"}]}
{"channel":"book","type":"update","data":[{"symbol":"EUR/USD","bids":[],"asks":[{"price":1.08453,"qty":6589.49405885}],"checksum":683429528,"timestamp":"2024-06-01T22:44:11.895075Z"}]}
{"channel":"book","type":"update","data":[{"symbol":"EUR/USD","bids":[],"asks":[{"price":1.08467,"qty":12917.13974401}],"checksum":971721928,"timestamp":"2024-06-01T22:44:11.895276Z"}]}
{"channel":"book","type":"update","data":[{"symbol":"EUR/USD","bids":[],"asks":[{"price":1.08469,"qty":117954.36124273}],"checksum":677640581,"timestamp":"2024-06-01T22:44:11.895288Z"}]}
{"channel":"book","type":"update","data":[{"symbol":"EUR/USD","bids":[],"asks":[{"price":1.08454,"qty":0.00000000},{"price":1.08475,"qty":4167.00000000},{"price":1.08452,"qty":3692.39649561}],"checksum":800274060,"timestamp":"2024-06-01T22:44:11.899037Z"}]}
{"channel":"book","type":"update","data":[{"symbol":"EUR/USD","bids":[{"price":1.08390,"qty":23.06485838}],"asks":[],"checksum":3830044246,"timestamp":"2024-06-01T22:44:12.723614Z"}]}
{"channel":"book","type":"update","data":[{"symbol":"EUR/USD","bids":[],"asks":[{"price":1.08468,"qty":0.00000000},{"price":1.08475,"qty":4167.00000000}],"checksum":1019810662,"timestamp":"2024-06-01T22:44:13.198447Z"}]}
{"channel":"book","type":"update","data":[{"symbol":"EUR/USD","bids":[],"asks":[{"price":1.08464,"qty":0.00000000},{"price":1.08478,"qty":175.24140000}],"checksum":655033658,"timestamp":"2024-06-01T22:44:13.198495Z"}]}
{"channel":"book","type":"update","data":[{"symbol":"EUR/USD","bids":[],"asks":[{"price":1.08455,"qty":0.00000000},{"price":1.08479,"qty":4609.18918798}],"checksum":460063455,"timestamp":"2024-06-01T22:44:13.198558Z"}]}
{"channel":"book","type":"update","data":[{"symbol":"EUR/USD","bids":[],"asks":[{"price":1.08451,"qty":54.51107393}],"checksum":3610097340,"timestamp":"2024-06-01T22:44:13.203544Z"}]}
{"channel":"book","type":"update","data":[{"symbol":"EUR/USD","bids":[],"asks":[{"price":1.08466,"qty":1080.61901921}],"checksum":3013227881,"timestamp":"2024-06-01T22:44:13.203683Z"}]}
{"channel":"book","type":"update","data":[{"symbol":"EUR/USD","bids":[],"asks":[{"price":1.08453,"qty":0.00000000},{"price":1.08478,"qty":175.24140000}],"checksum":2469427806,"timestamp":"2024-06-01T22:44:13.940230Z"}]}
{"channel":"book","type":"update","data":[{"symbol":"EUR/USD","bids":[],"asks":[{"price":1.08469,"qty":0.00000000},{"price":1.08479,"qty":4609.18918798}],"checksum":1564897714,"timestamp":"2024-06-01T22:44:13.940242Z"}]}
{"channel":"book","type":"update","data":[{"symbol":"EUR/USD","bids":[],"asks":[{"price":1.08467,"qty":0.00000000},{"price":1.08480,"qty":4167.00000000}],"checksum":1917433767,"timestamp":"2024-06-01T22:44:13.940251Z"}]}
{"channel":"book","type":"update","data":[{"symbol":"EUR/USD","bids":[],"asks":[{"price":1.08451,"qty":5062.09371149}],"checksum":406462074,"timestamp":"2024-06-01T22:44:13.945614Z"}]}
{"channel":"book","type":"update","data":[{"symbol":"EUR/USD","bids":[],"asks":[{"price":1.08469,"qty":33481.98822080}],"checksum":932930487,"timestamp":"2024-06-01T22:44:13.945667Z"}]}
{"channel":"book","type":"update","data":[{"symbol":"EUR/USD","bids":[],"asks":[{"price":1.08452,"qty":0.00000000},{"price":1.08480,"qty":4167.00000000},{"price":1.08456,"qty":3692.39835590}],"checksum":599104996,"timestamp":"2024-06-01T22:44:13.946967Z"}]}
{"channel":"book","type":"update","data":[{"symbol":"EUR/USD","bids":[],"asks":[{"price":1.08456,"qty":0.00000000},{"price":1.08480,"qty":4167.00000000},{"price":1.08450,"qty":3692.39835590}],"checksum":1761412578,"timestamp":"2024-06-01T22:44:13.949822Z"}]}
{"channel":"book","type":"update","data":[{"symbol":"EUR/USD","bids":[{"price":1.08420,"qty":8693.20099216}],"asks":[],"checksum":131857999,"timestamp":"2024-06-01T22:44:14.836617Z"}]}
{"channel":"book","type":"update","data":[{"symbol":"EUR/USD","bids":[{"price":1.08422,"qty":131.59454845}],"asks":[],"checksum":3473717675,"timestamp":"2024-06-01T22:44:14.841023Z"}]}
