{"channel":"book","type":"snapshot","data":[{"symbol":"EUR/CHF","bids":[{"price":0.97912,"qty":1512.98665998},{"price":0.97911,"qty":10548.32378369},{"price":0.97909,"qty":14434.98269170},{"price":0.97905,"qty":126.36236564},{"price":0.97900,"qty":145.13970955},{"price":0.97894,"qty":1021.51306515},{"price":0.97893,"qty":1021.52350014},{"price":0.97892,"qty":1021.53393535},{"price":0.97891,"qty":1021.54437077},{"price":0.97890,"qty":1021.55480641}],"asks":[{"price":0.97984,"qty":77.45026318},{"price":0.97985,"qty":108.62128790},{"price":0.97986,"qty":12917.13974401},{"price":0.97988,"qty":237.14908295},{"price":0.98019,"qty":4140.00000000},{"price":0.98020,"qty":175.24140000},{"price":0.98032,"qty":14188.54047739},{"price":0.98033,"qty":14754.72063908},{"price":0.98034,"qty":322.51872116},{"price":0.98086,"qty":39901.00000000}],"checksum":911330518}]}
{"channel":"book","type":"update","data":[{"symbol":"EUR/CHF","bids":[],"asks":[{"price":0.97986,"qty":0.00000000},{"price":0.98098,"qty":4502.00000000}],"checksum":2130598647,"timestamp":"2024-06-01T22:43:38.370888Z"}]}
{"channel":"book","type":"update","data":[{"symbol":"EUR/CHF","bids":[],"asks":[{"price":0.97984,"qty":1921.21005815}],"checksum":102349347,"timestamp":"2024-06-01T22:43:38.375882Z"}]}
{"channel":"book","type":"update","data":[{"symbol":"EUR/CHF","bids":[],"asks":[{"price":0.97986,"qty":11075.69720210}],"checksum":3608060449,"timestamp":"2024-06-01T22:43:38.375992Z"}]}
{"channel":"book","type":"update","data":[{"symbol":"EUR/CHF","bids":[{"price":0.97905,"qty":0.00000000},{"price":0.97884,"qty":21.41489245}],"asks":[],"checksum":676547526,"timestamp":"2024-06-01T22:43:38.458182Z"}]}
{"channel":"book","type":"update","data":[{"symbol":"EUR/CHF","bids":[{"price":0.97913,"qty":108.37490435}],"asks":[],"checksum":72747725,"timestamp":"2024-06-01T22:43:38.460252Z"}]}
{"channel":"book","type":"update","data":[{"symbol":"EUR/CHF","bids":[],"asks":[{"price":0.98020,"qty":0.00000000},{"price":0.98098,"qty":4502.00000000}],"checksum":1712423298,"timestamp":"2024-06-01T22:43:38.488762Z"}]}
{"channel":"book","type":"update","data":[{"symbol":"EUR/CHF","bids":[{"price":0.97914,"qty":10548.00054445}],"asks":[],"checksum":2791910416,"timestamp":"2024-06-01T22:43:38.488944Z"}]}
{"channel":"book","type":"update","data":[{"symbol":"EUR/CHF","bids":[{"price":0.97911,"qty":0.00000000},{"price":0.97890,"qty":1021.55480641}],"asks":[],"checksum":3130030653,"timestamp":"2024-06-01T22:43:38.488987Z"}]}
{"channel":"book","type":"update","data":[{"symbol":"EUR/CHF","bids":[],"asks":[{"price":0.98018,"qty":175.24140000}],"checksum":1479647275,"timestamp":"2024-06-01T22:43:38.489187Z"}]}
{"channel":"book","type":"update","data":[{"symbol":"EUR/CHF","bids":[],"asks":[{"price":0.98019,"qty":0.00000000},{"price":0.98098,"qty":4502.00000000},{"price":0.98017,"qty":4140.00000000}],"checksum":4045023075,"timestamp":"2024-06-01T22:43:38.507042Z"}]}
{"channel":"book","type":"update","data":[{"symbol":"EUR/CHF","bids":[{"price":0.97912,"qty":0.00000000},{"price":0.97884,"qty":21.41489245},{"price":0.97915,"qty":1512.93343837}],"asks":[],"checksum":1298275496,"timestamp":"2024-06-01T22:43:38.582472Z"}]}
{"channel":"book","type":"update","data":[{"symbol":"EUR/CHF","bids":[],"asks":[{"price":0.97984,"qty":1843.75979497},{"price":0.97983,"qty":77.46462421}],"checksum":3647944806,"timestamp":"2024-06-01T22:43:38.582630Z"}]}
{"channel":"book","type":"update","data":[{"symbol":"EUR/CHF","bids":[{"price":0.97909,"qty":0.00000000},{"price":0.97884,"qty":21.41489245}],"asks":[],"checksum":564744743,"timestamp":"2024-06-01T22:43:38.682820Z"}]}
{"channel":"book","type":"update","data":[{"symbol":"EUR/CHF","bids":[{"price":0.97913,"qty":12744.61146795}],"asks":[],"checksum":2101144340,"timestamp":"2024-06-01T22:43:38.684400Z"}]}
{"channel":"book","type":"update","data":[{"symbol":"EUR/CHF","bids":[],"asks":[{"price":0.98017,"qty":0.00000000},{"price":0.98086,"qty":39901.00000000},{"price":0.97985,"qty":4248.62128790}],"checksum":1506207603,"timestamp":"2024-06-01T22:43:38.692250Z"}]}
{"channel":"book","type":"update","data":[{"symbol":"EUR/CHF","bids":[{"price":0.97914,"qty":0.00000000},{"price":0.97883,"qty":1021.62786183}],"asks":[],"checksum":414280341,"timestamp":"2024-06-01T22:43:39.882971Z"}]}
{"channel":"book","type":"update","data":[{"symbol":"EUR/CHF","bids":[],"asks":[{"price":0.98018,"qty":0.00000000},{"price":0.98098,"qty":4502.00000000}],"checksum":818983305,"timestamp":"2024-06-01T22:43:39.883033Z"}]}
{"channel":"book","type":"update","data":[{"symbol":"EUR/CHF","bids":[],"asks":[{"price":0.98031,"qty":175.24140000}],"checksum":3645112175,"timestamp":"2024-06-01T22:43:39.883051Z"}]}
{"channel":"book","type":"update","data":[{"symbol":"EUR/CHF","bids":[{"price":0.97916,"qty":10547.78513680}],"asks":[],"checksum":1565375876,"timestamp":"2024-06-01T22:43:39.883271Z"}]}
{"channel":"book","type":"update","data":[{"symbol":"EUR/CHF","bids":[{"price":0.97915,"qty":0.00000000},{"price":0.97883,"qty":1021.62786183},{"price":0.97914,"qty":1512.94839673}],"asks":[],"checksum":330963119,"timestamp":"2024-06-01T22:43:39.889030Z"}]}
{"channel":"book","type":"update","data":[{"symbol":"EUR/CHF","bids":[],"asks":[{"price":0.97986,"qty":0.00000000},{"price":0.98098,"qty":4502.00000000}],"checksum":3274146357,"timestamp":"2024-06-01T22:43:40.396378Z"}]}
{"channel":"book","type":"update","data":[{"symbol":"EUR/CHF","bids":[],"asks":[{"price":0.98032,"qty":0.00000000},{"price":0.98108,"qty":2003.00000000}],"checksum":2744365191,"timestamp":"2024-06-01T22:43:40.396434Z"}]}
{"channel":"book","type":"update","data":[{"symbol":"EUR/CHF","bids":[],"asks":[{"price":0.97984,"qty":0.00000000},{"price":0.98110,"qty":3605.00000000}],"checksum":987047121,"timestamp":"2024-06-01T22:43:40.396666Z"}]}
{"channel":"book","type":"update","data":[{"symbol":"EUR/CHF","bids":[],"asks":[{"price":0.97983,"qty":0.00000000},{"price":0.98112,"qty":2004.00000000},{"price":0.97984,"qty":77.46967884}],"checksum":1676762726,"timestamp":"2024-06-01T22:43:40.400118Z"}]}
{"channel":"book","type":"update","data":[{"symbol":"EUR/CHF","bids":[],"asks":[{"price":0.98030,"qty":12917.13974401}],"checksum":2059619286,"timestamp":"2024-06-01T22:43:40.401808Z"}]}
{"channel":"book","type":"update","data":[{"symbol":"EUR/CHF","bids":[],"asks":[{"price":0.97984,"qty":6666.96373769}],"checksum":109136393,"timestamp":"2024-06-01T22:43:40.401883Z"}]}
{"channel":"book","type":"update","data":[{"symbol":"EUR/CHF","bids":[],"asks":[{"price":0.98032,"qty":9175.55091603}],"checksum":147318786,"timestamp":"2024-06-01T22:43:40.402028Z"}]}
{"channel":"book","type":"update","data":[{"symbol":"EUR/CHF","bids":[],"asks":[{"price":0.97985,"qty":108.62128790},{"price":0.98029,"qty":4140.00000000}],"checksum":4030250168,"timestamp":"2024-06-01T22:43:40.417837Z"}]}
{"channel":"book","type":"update","data":[{"symbol":"EUR/CHF","bids":[],"asks":[{"price":0.97985,"qty":0.00000000},{"price":0.98098,"qty":4502.00000000}],"checksum":1453994751,"timestamp":"2024-06-01T22:43:40.471254Z"}]}
{"channel":"book","type":"update","data":[{"symbol":"EUR/CHF","bids":[],"asks":[{"price":0.97983,"qty":113.13047240}],"checksum":2570846775,"timestamp":"2024-06-01T22:43:40.476439Z"}]}
{"channel":"book","type":"update","data":[{"symbol":"EUR/CHF","bids":[{"price":0.97914,"qty":0.00000000},{"price":0.97883,"qty":1021.62786183},{"price":0.97917,"qty":1512.90204273}],"asks":[],"checksum":3797458613,"timestamp":"2024-06-01T22:43:40.508622Z"}]}
{"channel":"book","type":"update","data":[{"symbol":"EUR/CHF","bids":[],"asks":[{"price":0.97984,"qty":6589.49405885},{"price":0.97982,"qty":77.46969196}],"checksum":601423906,"timestamp":"2024-06-01T22:43:40.508977Z"}]}
{"channel":"book","type":"update","data":[{"symbol":"EUR/CHF","bids":[{"price":0.97913,"qty":108.37490435}],"asks":[],"checksum":1571938823,"timestamp":"2024-06-01T22:43:40.830904Z"}]}
{"channel":"book","type":"update","data":[{"symbol":"EUR/CHF","bids":[{"price":0.97918,"qty":10837.49043550}],"asks":[],"checksum":1089517979,"timestamp":"2024-06-01T22:43:40.832142Z"}]}
{"channel":"book","type":"update","data":[{"symbol":"EUR/CHF","bids":[{"price":0.97913,"qty":0.00000000},{"price":0.97884,"qty":21.41489245}],"asks":[],"checksum":4195843450,"timestamp":"2024-06-01T22:43:40.863549Z"}]}
{"channel":"book","type":"update","data":[{"symbol":"EUR/CHF","bids":[{"price":0.97918,"qty":10927.87787857}],"asks":[],"checksum":166822694,"timestamp":"2024-06-01T22:43:40.864728Z"}]}
{"channel":"book","type":"update","data":[{"symbol":"EUR/CHF","bids":[],"asks":[{"price":0.98031,"qty":0.00000000},{"price":0.98086,"qty":39901.00000000}],"checksum":1877556223,"timestamp":"2024-06-01T22:43:40.884294Z"}]}
{"channel":"book","type":"update","data":[{"symbol":"EUR/CHF","bids":[],"asks":[{"price":0.98028,"qty":175.24140000}],"checksum":2141440453,"timestamp":"2024-06-01T22:43:40.884441Z"}]}
{"channel":"book","type":"update","data":[{"symbol":"EUR/CHF","bids":[{"price":0.97916,"qty":0.00000000},{"price":0.97883,"qty":1021.62786183}],"asks":[],"checksum":1475181794,"timestamp":"2024-06-01T22:43:40.884494Z"}]}
{"channel":"book","type":"update","data":[{"symbol":"EUR/CHF","bids":[{"price":0.97919,"qty":10547.46192777}],"asks":[],"checksum":3704210234,"timestamp":"2024-06-01T22:43:40.884655Z"}]}
{"channel":"book","type":"update","data":[{"symbol":"EUR/CHF","bids":[],"asks":[{"price":0.98029,"qty":0.00000000},{"price":0.98086,"qty":39901.00000000},{"price":0.98027,"qty":4140.00000000}],"checksum":4063174418,"timestamp":"2024-06-01T22:43:40.908221Z"}]}
{"channel":"book","type":"update","data":[{"symbol":"EUR/CHF","bids":[{"price":0.97917,"qty":0.00000000},{"price":0.97883,"qty":1021.62786183},{"price":0.97920,"qty":1512.84633440}],"asks":[],"checksum":869409821,"timestamp":"2024-06-01T22:43:41.153280Z"}]}
{"channel":"book","type":"update","data":[{"symbol":"EUR/CHF","bids":[],"asks":[{"price":0.98026,"qty":175.24140000}],"checksum":4232880598,"timestamp":"2024-06-01T22:43:42.272284Z"}]}
{"channel":"book","type":"update","data":[{"symbol":"EUR/CHF","bids":[],"asks":[{"price":0.98028,"qty":0.00000000},{"price":0.98034,"qty":322.51872116}],"checksum":620295532,"timestamp":"2024-06-01T22:43:42.272301Z"}]}
{"channel":"book","type":"update","data":[{"symbol":"EUR/CHF","bids":[],"asks":[{"price":0.98027,"qty":0.00000000},{"price":0.98086,"qty":39901.00000000},{"price":0.98025,"qty":4140.00000000}],"checksum":1157662728,"timestamp":"2024-06-01T22:43:42.300821Z"}]}
{"channel":"book","type":"update","data":[{"symbol":"EUR/CHF","bids":[],"asks":[{"price":0.98030,"qty":0.00000000},{"price":0.98086,"qty":39901.00000000}],"checksum":3354507935,"timestamp":"2024-06-01T22:43:42.489531Z"}]}
{"channel":"book","type":"update","data":[{"symbol":"EUR/CHF","bids":[],"asks":[{"price":0.98032,"qty":0.00000000},{"price":0.98098,"qty":4502.00000000}],"checksum":3390114492,"timestamp":"2024-06-01T22:43:42.489543Z"}]}
{"channel":"book","type":"update","data":[{"symbol":"EUR/CHF","bids":[],"asks":[{"price":0.97984,"qty":0.00000000},{"price":0.98108,"qty":2003.00000000}],"checksum":3932769462,"timestamp":"2024-06-01T22:43:42.489563Z"}]}
{"channel":"book","type":"update","data":[{"symbol":"EUR/CHF","bids":[],"asks":[{"price":0.97982,"qty":0.00000000},{"price":0.98110,"qty":3605.00000000},{"price":0.98024,"qty":77.46776193}],"checksum":856043273,"timestamp":"2024-06-01T22:43:42.493800Z"}]}
{"channel":"book","type":"update","data":[{"symbol":"EUR/CHF","bids":[],"asks":[{"price":0.98026,"qty":33657.22962080}],"checksum":1358789899,"timestamp":"2024-06-01T22:43:42.494481Z"}]}
{"channel":"book","type":"update","data":[{"symbol":"EUR/CHF","bids":[],"asks":[{"price":0.98025,"qty":0.00000000},{"price":0.98110,"qty":3605.00000000},{"price":0.98023,"qty":4140.00000000}],"checksum":2821134025,"timestamp":"2024-06-01T22:43:42.514911Z"}]}
{"channel":"book","type":"update","data":[{"symbol":"EUR/CHF","bids":[{"price":0.97918,"qty":90.38744307}],"asks":[],"checksum":2733817986,"timestamp":"2024-06-01T22:43:42.873488Z"}]}
{"channel":"book","type":"update","data":[{"symbol":"EUR/CHF","bids":[{"price":0.97921,"qty":10837.49043550}],"asks":[],"checksum":3888842337,"timestamp":"2024-06-01T22:43:42.875799Z"}]}
{"channel":"book","type":"update","data":[{"symbol":"EUR/CHF","bids":[],"asks":[{"price":0.97983,"qty":0.00000000},{"price":0.98110,"qty":3605.00000000}],"checksum":958605186,"timestamp":"2024-06-01T22:43:42.973358Z"}]}
{"channel":"book","type":"update","data":[{"symbol":"EUR/CHF","bids":[],"asks":[{"price":0.98024,"qty":276.27273978}],"checksum":2069093337,"timestamp":"2024-06-01T22:43:42.978688Z"}]}
{"channel":"book","type":"update","data":[{"symbol":"EUR/CHF","bids":[],"asks":[{"price":0.98024,"qty":198.80497785},{"price":0.98022,"qty":77.46776193}],"checksum":1421330200,"timestamp":"2024-06-01T22:43:43.127946Z"}]}
{"channel":"book","type":"update","data":[{"symbol":"EUR/CHF","bids":[{"price":0.97920,"qty":0.00000000},{"price":0.97884,"qty":21.41489245},{"price":0.97922,"qty":1512.81266378}],"asks":[],"checksum":3060014645,"timestamp":"2024-06-01T22:43:43.127976Z"}]}
{"channel":"book","type":"update","data":[{"symbol":"EUR/CHF","bids":[],"asks":[{"price":0.98022,"qty":314.61684488}],"checksum":3617521746,"timestamp":"2024-06-01T22:43:43.134706Z"}]}
{"channel":"book","type":"update","data":[{"symbol":"EUR/CHF","bids":[],"asks":[{"price":0.98023,"qty":0.00000000},{"price":0.98110,"qty":3605.00000000},{"price":0.98021,"qty":4140.00000000}],"checksum":2825215948,"timestamp":"2024-06-01T22:43:43.153568Z"}]}
{"channel":"book","type":"update","data":[{"symbol":"EUR/CHF","bids":[],"asks":[{"price":0.98026,"qty":33481.98822080}],"checksum":1626501218,"timestamp":"2024-06-01T22:43:43.264632Z"}]}
{"channel":"book","type":"update","data":[{"symbol":"EUR/CHF","bids":[{"price":0.97919,"qty":0.00000000},{"price":0.97884,"qty":21.41489245}],"asks":[],"checksum":2547321984,"timestamp":"2024-06-01T22:43:43.264692Z"}]}
{"channel":"book","type":"update","data":[{"symbol":"EUR/CHF","bids":[],"asks":[{"price":0.98020,"qty":175.24140000}],"checksum":799251149,"timestamp":"2024-06-01T22:43:43.264708Z"}]}
{"channel":"book","type":"update","data":[{"symbol":"EUR/CHF","bids":[{"price":0.97923,"qty":10547.03103819}],"asks":[],"checksum":3087842210,"timestamp":"2024-06-01T22:43:43.264846Z"}]}
{"channel":"book","type":"update","data":[{"symbol":"EUR/CHF","bids":[],"asks":[{"price":0.98021,"qty":0.00000000},{"price":0.98108,"qty":2003.00000000},{"price":0.98019,"qty":4140.00000000}],"checksum":2842712877,"timestamp":"2024-06-01T22:43:43.277256Z"}]}
{"channel":"book","type":"update","data":[{"symbol":"EUR/CHF","bids":[],"asks":[{"price":0.97988,"qty":0.00000000},{"price":0.98108,"qty":2003.00000000}],"checksum":1614691962,"timestamp":"2024-06-01T22:43:43.308502Z"}]}
{"channel":"book","type":"update","data":[{"symbol":"EUR/CHF","bids":[{"price":0.97918,"qty":0.00000000},{"price":0.97884,"qty":21.41489245}],"asks":[],"checksum":3704293809,"timestamp":"2024-06-01T22:43:43.397026Z"}]}
{"channel":"book","type":"update","data":[{"symbol":"EUR/CHF","bids":[{"price":0.97923,"qty":10619.43101998}],"asks":[],"checksum":2270919060,"timestamp":"2024-06-01T22:43:43.398233Z"}]}
{"channel":"book","type":"update","data":[{"symbol":"EUR/CHF","bids":[],"asks":[{"price":0.98086,"qty":0.00000000},{"price":0.98110,"qty":3605.00000000}],"checksum":4010111142,"timestamp":"2024-06-01T22:43:43.472853Z"}]}
{"channel":"book","type":"update","data":[{"symbol":"EUR/CHF","bids":[],"asks":[{"price":0.98022,"qty":237.14908295},{"price":0.98018,"qty":77.46776304}],"checksum":3784704255,"timestamp":"2024-06-01T22:43:43.752500Z"}]}
{"channel":"book","type":"update","data":[{"symbol":"EUR/CHF","bids":[{"price":0.97922,"qty":0.00000000},{"price":0.97883,"qty":1021.62786183},{"price":0.97924,"qty":1512.78183105}],"asks":[],"checksum":1648793468,"timestamp":"2024-06-01T22:43:43.752665Z"}]}
{"channel":"book","type":"update","data":[{"symbol":"EUR/CHF","bids":[],"asks":[{"price":0.98019,"qty":0.00000000},{"price":0.98110,"qty":3605.00000000},{"price":0.98017,"qty":4140.00000000}],"checksum":1108269528,"timestamp":"2024-06-01T22:43:43.765850Z"}]}
{"channel":"book","type":"update","data":[{"symbol":"EUR/CHF","bids":[{"price":0.97924,"qty":0.00000000},{"price":0.97883,"qty":1021.62786183},{"price":0.97925,"qty":1512.76641973}],"asks":[],"checksum":1602730704,"timestamp":"2024-06-01T22:43:44.367935Z"}]}
{"channel":"book","type":"update","data":[{"symbol":"EUR/CHF","bids":[],"asks":[{"price":0.98018,"qty":0.00000000},{"price":0.98110,"qty":3605.00000000},{"price":0.98016,"qty":77.46776346}],"checksum":386440585,"timestamp":"2024-06-01T22:43:44.368728Z"}]}
{"channel":"book","type":"update","data":[{"symbol":"EUR/CHF","bids":[{"price":0.97925,"qty":0.00000000},{"price":0.97883,"qty":1021.62786183},{"price":0.97924,"qty":1512.77583437}],"asks":[],"checksum":2958280087,"timestamp":"2024-06-01T22:43:44.374510Z"}]}
{"channel":"book","type":"update","data":[{"symbol":"EUR/CHF","bids":[],"asks":[{"price":0.98017,"qty":0.00000000},{"price":0.98110,"qty":3605.00000000},{"price":0.98015,"qty":4140.00000000}],"checksum":1888267262,"timestamp":"2024-06-01T22:43:44.402271Z"}]}
{"channel":"book","type":"update","data":[{"symbol":"EUR/CHF","bids":[],"asks":[{"price":0.98026,"qty":0.00000000},{"price":0.98110,"qty":3605.00000000}],"checksum":2732450037,"timestamp":"2024-06-01T22:43:44.633574Z"}]}
{"channel":"book","type":"update","data":[{"symbol":"EUR/CHF","bids":[],"asks":[{"price":0.98016,"qty":31977.54456297}],"checksum":4006329415,"timestamp":"2024-06-01T22:43:44.638873Z"}]}
{"channel":"book","type":"update","data":[{"symbol":"EUR/CHF","bids":[{"price":0.97923,"qty":72.39998179}],"asks":[],"checksum":1921975314,"timestamp":"2024-06-01T22:43:44.676239Z"}]}
{"channel":"book","type":"update","data":[{"symbol":"EUR/CHF","bids":[],"asks":[{"price":0.98020,"qty":0.00000000},{"price":0.98112,"qty":2004.00000000}],"checksum":1230183574,"timestamp":"2024-06-01T22:43:44.676393Z"}]}
{"channel":"book","type":"update","data":[{"symbol":"EUR/CHF","bids":[],"asks":[{"price":0.98014,"qty":175.24140000}],"checksum":3277027089,"timestamp":"2024-06-01T22:43:44.676504Z"}]}
{"channel":"book","type":"update","data":[{"symbol":"EUR/CHF","bids":[{"price":0.97922,"qty":10547.13884065}],"asks":[],"checksum":1573246016,"timestamp":"2024-06-01T22:43:44.677025Z"}]}
{"channel":"book","type":"update","data":[{"symbol":"EUR/CHF","bids":[],"asks":[{"price":0.98015,"qty":0.00000000},{"price":0.98112,"qty":2004.00000000},{"price":0.98013,"qty":4140.00000000}],"checksum":3498011425,"timestamp":"2024-06-01T22:43:44.708728Z"}]}
{"channel":"book","type":"update","data":[{"symbol":"EUR/CHF","bids":[{"price":0.97921,"qty":0.00000000},{"price":0.97884,"qty":21.41489245}],"asks":[],"checksum":833199197,"timestamp":"2024-06-01T22:43:44.987604Z"}]}
{"channel":"book","type":"update","data":[{"symbol":"EUR/CHF","bids":[{"price":0.97925,"qty":8589.05777537}],"asks":[],"checksum":2349325799,"timestamp":"2024-06-01T22:43:44.989195Z"}]}
{"channel":"book","type":"update","data":[{"symbol":"EUR/CHF","bids":[],"asks":[{"price":0.98016,"qty":31900.07679951},{"price":0.98012,"qty":77.45309264}],"checksum":2363356762,"timestamp":"2024-06-01T22:43:45.050708Z"}]}
{"channel":"book","type":"update","data":[{"symbol":"EUR/CHF","bids":[{"price":0.97924,"qty":0.00000000},{"price":0.97884,"qty":21.41489245},{"price":0.97926,"qty":1512.74627828}],"asks":[],"checksum":3932990740,"timestamp":"2024-06-01T22:43:45.050824Z"}]}
{"channel":"book","type":"update","data":[{"symbol":"EUR/CHF","bids":[],"asks":[{"price":0.98013,"qty":0.00000000},{"price":0.98110,"qty":3605.00000000},{"price":0.98011,"qty":4140.00000000}],"checksum":2946558398,"timestamp":"2024-06-01T22:43:45.074258Z"}]}
{"channel":"book","type":"update","data":[{"symbol":"EUR/CHF","bids":[],"asks":[{"price":0.98024,"qty":0.00000000},{"price":0.98110,"qty":3605.00000000}],"checksum":399398585,"timestamp":"2024-06-01T22:43:45.484144Z"}]}
{"channel":"book","type":"update","data":[{"symbol":"EUR/CHF","bids":[],"asks":[{"price":0.98012,"qty":276.25807049}],"checksum":220351109,"timestamp":"2024-06-01T22:43:45.489296Z"}]}
{"channel":"book","type":"update","data":[{"symbol":"EUR/CHF","bids":[],"asks":[{"price":0.98014,"qty":0.00000000},{"price":0.98112,"qty":2004.00000000}],"checksum":1522953626,"timestamp":"2024-06-01T22:43:45.675441Z"}]}
{"channel":"book","type":"update","data":[{"symbol":"EUR/CHF","bids":[{"price":0.97901,"qty":10549.40117269}],"asks":[],"checksum":3813994545,"timestamp":"2024-06-01T22:43:45.675732Z"}]}
{"channel":"book","type":"update","data":[{"symbol":"EUR/CHF","bids":[{"price":0.97922,"qty":0.00000000},{"price":0.97890,"qty":1021.55480641}],"asks":[],"checksum":757655325,"timestamp":"2024-06-01T22:43:45.675749Z"}]}
{"channel":"book","type":"update","data":[{"symbol":"EUR/CHF","bids":[],"asks":[{"price":0.98010,"qty":175.24140000}],"checksum":3933940725,"timestamp":"2024-06-01T22:43:45.675811Z"}]}
{"channel":"book","type":"update","data":[{"symbol":"EUR/CHF","bids":[],"asks":[{"price":0.98011,"qty":0.00000000},{"price":0.98112,"qty":2004.00000000},{"price":0.98009,"qty":4140.00000000}],"checksum":3556376913,"timestamp":"2024-06-01T22:43:45.712290Z"}]}
{"channel":"book","type":"update","data":[{"symbol":"EUR/CHF","bids":[],"asks":[{"price":0.98012,"qty":198.80497785},{"price":0.98008,"qty":77.45313091}],"checksum":2247030121,"timestamp":"2024-06-01T22:43:45.756955Z"}]}
{"channel":"book","type":"update","data":[{"symbol":"EUR/CHF","bids":[],"asks":[{"price":0.98009,"qty":0.00000000},{"price":0.98110,"qty":3605.00000000},{"price":0.98007,"qty":4140.00000000}],"checksum":3558228437,"timestamp":"2024-06-01T22:43:45.775340Z"}]}
{"channel":"book","type":"update","data":[{"symbol":"EUR/CHF","bids":[{"price":0.97923,"qty":0.00000000},{"price":0.97884,"qty":21.41489245}],"asks":[],"checksum":2461770598,"timestamp":"2024-06-01T22:43:45.938400Z"}]}
{"channel":"book","type":"update","data":[{"symbol":"EUR/CHF","bids":[{"price":0.97927,"qty":72.39998179}],"asks":[],"checksum":2366067439,"timestamp":"2024-06-01T22:43:45.939974Z"}]}
{"channel":"book","type":"update","data":[{"symbol":"EUR/CHF","bids":[{"price":0.97926,"qty":0.00000000},{"price":0.97884,"qty":21.41489245},{"price":0.97928,"qty":1512.71594327}],"asks":[],"checksum":2657195789,"timestamp":"2024-06-01T22:43:46.420639Z"}]}
{"channel":"book","type":"update","data":[{"symbol":"EUR/CHF","bids":[],"asks":[{"price":0.98008,"qty":0.00000000},{"price":0.98110,"qty":3605.00000000},{"price":0.98006,"qty":77.45313091}],"checksum":4002927104,"timestamp":"2024-06-01T22:43:46.420677Z"}]}
{"channel":"book","type":"update","data":[{"symbol":"EUR/CHF","bids":[],"asks":[{"price":0.98007,"qty":0.00000000},{"price":0.98110,"qty":3605.00000000},{"price":0.98005,"qty":4140.00000000}],"checksum":3700175741,"timestamp":"2024-06-01T22:43:46.442829Z"}]}
{"channel":"book","type":"update","data":[{"symbol":"EUR/CHF","bids":[],"asks":[{"price":0.98016,"qty":0.00000000},{"price":0.98110,"qty":3605.00000000}],"checksum":1249355453,"timestamp":"2024-06-01T22:43:46.744697Z"}]}
{"channel":"book","type":"update","data":[{"symbol":"EUR/CHF","bids":[],"asks":[{"price":0.98006,"qty":30395.61850913}],"checksum":2435712107,"timestamp":"2024-06-01T22:43:46.750208Z"}]}
{"channel":"book","type":"update","data":[{"symbol":"EUR/CHF","bids":[],"asks":[{"price":0.98010,"qty":0.00000000},{"price":0.98112,"qty":2004.00000000}],"checksum":1554540266,"timestamp":"2024-06-01T22:43:47.075193Z"}]}
{"channel":"book","type":"update","data":[{"symbol":"EUR/CHF","bids":[],"asks":[{"price":0.98004,"qty":175.24140000}],"checksum":4206621163,"timestamp":"2024-06-01T22:43:47.075349Z"}]}
{"channel":"book","type":"update","data":[{"symbol":"EUR/CHF","bids":[],"asks":[{"price":0.98005,"qty":0.00000000},{"price":0.98112,"qty":2004.00000000},{"price":0.98003,"qty":4140.00000000}],"checksum":1296130744,"timestamp":"2024-06-01T22:43:47.111124Z"}]}
{"channel":"book","type":"update","data":[{"symbol":"EUR/CHF","bids":[{"price":0.97925,"qty":0.00000000},{"price":0.97884,"qty":21.41489245}],"asks":[],"checksum":3172963817,"timestamp":"2024-06-01T22:43:47.133000Z"}]}
{"channel":"book","type":"update","data":[{"symbol":"EUR/CHF","bids":[{"price":0.97902,"qty":14434.98269170}],"asks":[],"checksum":2792956460,"timestamp":"2024-06-01T22:43:47.134229Z"}]}
{"channel":"book","type":"update","data":[{"symbol":"EUR/CHF","bids":[{"price":0.97928,"qty":0.00000000},{"price":0.97884,"qty":21.41489245},{"price":0.97902,"qty":15948.10201019}],"asks":[],"checksum":4093609983,"timestamp":"2024-06-01T22:43:47.136438Z"}]}
{"channel":"book","type":"update","data":[{"symbol":"EUR/CHF","bids":[{"price":0.97902,"qty":14434.98269170},{"price":0.97903,"qty":1513.10386320}],"asks":[],"checksum":234263099,"timestamp":"2024-06-01T22:43:47.150825Z"}]}
{"channel":"book","type":"update","data":[{"symbol":"EUR/CHF","bids":[],"asks":[{"price":0.98006,"qty":30318.16537822},{"price":0.98002,"qty":77.47349285}],"checksum":2809558956,"timestamp":"2024-06-01T22:43:47.150873Z"}]}
{"channel":"book","type":"update","data":[{"symbol":"EUR/CHF","bids":[],"asks":[{"price":0.98003,"qty":0.00000000},{"price":0.98110,"qty":3605.00000000},{"price":0.98001,"qty":4140.00000000}],"checksum":3042583108,"timestamp":"2024-06-01T22:43:47.174642Z"}]}
{"channel":"book","type":"update","data":[{"symbol":"EUR/CHF","bids":[],"asks":[{"price":0.98002,"qty":0.00000000},{"price":0.98110,"qty":3605.00000000},{"price":0.98000,"qty":77.47349316}],"checksum":3094760756,"timestamp":"2024-06-01T22:43:47.904703Z"}]}
{"channel":"book","type":"update","data":[{"symbol":"EUR/CHF","bids":[],"asks":[{"price":0.98012,"qty":0.00000000},{"price":0.98110,"qty":3605.00000000}],"checksum":1487037976,"timestamp":"2024-06-01T22:43:48.018425Z"}]}
{"channel":"book","type":"update","data":[{"symbol":"EUR/CHF","bids":[],"asks":[{"price":0.98000,"qty":240.20499503}],"checksum":2968377690,"timestamp":"2024-06-01T22:43:48.025413Z"}]}
{"channel":"book","type":"update","data":[{"symbol":"EUR/CHF","bids":[{"price":0.97901,"qty":0.00000000},{"price":0.97884,"qty":21.41489245}],"asks":[],"checksum":943634094,"timestamp":"2024-06-01T22:43:48.078327Z"}]}
{"channel":"book","type":"update","data":[{"symbol":"EUR/CHF","bids":[],"asks":[{"price":0.97999,"qty":175.24140000}],"checksum":1146855668,"timestamp":"2024-06-01T22:43:48.078384Z"}]}
{"channel":"book","type":"update","data":[{"symbol":"EUR/CHF","bids":[{"price":0.97904,"qty":10549.07796676}],"asks":[],"checksum":3590795666,"timestamp":"2024-06-01T22:43:48.078503Z"}]}
{"channel":"book","type":"update","data":[{"symbol":"EUR/CHF","bids":[],"asks":[{"price":0.98004,"qty":0.00000000},{"price":0.98110,"qty":3605.00000000}],"checksum":1520612958,"timestamp":"2024-06-01T22:43:48.078517Z"}]}
{"channel":"book","type":"update","data":[{"symbol":"EUR/CHF","bids":[{"price":0.97927,"qty":0.00000000},{"price":0.97884,"qty":21.41489245}],"asks":[],"checksum":2322718779,"timestamp":"2024-06-01T22:43:48.495936Z"}]}
{"channel":"book","type":"update","data":[{"symbol":"EUR/CHF","bids":[{"price":0.97905,"qty":126.36236564}],"asks":[],"checksum":3388043724,"timestamp":"2024-06-01T22:43:48.497225Z"}]}
{"channel":"book","type":"update","data":[{"symbol":"EUR/CHF","bids":[],"asks":[{"price":0.98001,"qty":0.00000000},{"price":0.98112,"qty":2004.00000000},{"price":0.97998,"qty":4140.00000000}],"checksum":3011144956,"timestamp":"2024-06-01T22:43:48.511340Z"}]}
{"channel":"book","type":"update","data":[{"symbol":"EUR/CHF","bids":[],"asks":[{"price":0.98000,"qty":162.73150187},{"price":0.97997,"qty":77.45196983}],"checksum":4122526401,"timestamp":"2024-06-01T22:43:48.615870Z"}]}
{"channel":"book","type":"update","data":[{"symbol":"EUR/CHF","bids":[{"price":0.97903,"qty":0.00000000},{"price":0.97884,"qty":21.41489245},{"price":0.97906,"qty":1513.05445547}],"asks":[],"checksum":1108295811,"timestamp":"2024-06-01T22:43:48.615981Z"}]}
{"channel":"book","type":"update","data":[{"symbol":"EUR/CHF","bids":[],"asks":[{"price":0.97998,"qty":0.00000000},{"price":0.98110,"qty":3605.00000000},{"price":0.97996,"qty":4140.00000000}],"checksum":1992997610,"timestamp":"2024-06-01T22:43:48.635289Z"}]}
{"channel":"book","type":"update","data":[{"symbol":"EUR/CHF","bids":[],"asks":[{"price":0.98006,"qty":0.00000000},{"price":0.98110,"qty":3605.00000000}],"checksum":1367775941,"timestamp":"2024-06-01T22:43:48.875946Z"}]}
{"channel":"book","type":"update","data":[{"symbol":"EUR/CHF","bids":[],"asks":[{"price":0.98032,"qty":12599.67729693}],"checksum":1102837889,"timestamp":"2024-06-01T22:43:48.881150Z"}]}
{"channel":"book","type":"update","data":[{"symbol":"EUR/CHF","bids":[],"asks":[{"price":0.97998,"qty":16080.96258660}],"checksum":102708492,"timestamp":"2024-06-01T22:43:48.881167Z"}]}
{"channel":"book","type":"update","data":[{"symbol":"EUR/CHF","bids":[{"price":0.97902,"qty":0.00000000},{"price":0.97884,"qty":21.41489245}],"asks":[],"checksum":740678525,"timestamp":"2024-06-01T22:43:49.257632Z"}]}
{"channel":"book","type":"update","data":[{"symbol":"EUR/CHF","bids":[{"price":0.97907,"qty":14434.98269170}],"asks":[],"checksum":2143856517,"timestamp":"2024-06-01T22:43:49.259179Z"}]}
{"channel":"book","type":"update","data":[{"symbol":"EUR/CHF","bids":[{"price":0.97906,"qty":0.00000000},{"price":0.97884,"qty":21.41489245},{"price":0.97908,"qty":1513.02268002}],"asks":[],"checksum":999265161,"timestamp":"2024-06-01T22:43:49.411039Z"}]}
{"channel":"book","type":"update","data":[{"symbol":"EUR/CHF","bids":[],"asks":[{"price":0.97997,"qty":0.00000000},{"price":0.98108,"qty":2003.00000000},{"price":0.97995,"qty":76.88837357}],"checksum":2581283035,"timestamp":"2024-06-01T22:43:49.411065Z"}]}
{"channel":"book","type":"update","data":[{"symbol":"EUR/CHF","bids":[],"asks":[{"price":0.97996,"qty":0.00000000},{"price":0.98108,"qty":2003.00000000},{"price":0.97994,"qty":4140.00000000}],"checksum":85434679,"timestamp":"2024-06-01T22:43:49.425798Z"}]}
{"channel":"book","type":"update","data":[{"symbol":"EUR/CHF","bids":[],"asks":[{"price":0.97999,"qty":0.00000000},{"price":0.98108,"qty":2003.00000000}],"checksum":1246618230,"timestamp":"2024-06-01T22:43:49.480269Z"}]}
{"channel":"book","type":"update","data":[{"symbol":"EUR/CHF","bids":[{"price":0.97909,"qty":10548.53916017}],"asks":[],"checksum":805975360,"timestamp":"2024-06-01T22:43:49.480582Z"}]}
{"channel":"book","type":"update","data":[{"symbol":"EUR/CHF","bids":[{"price":0.97904,"qty":0.00000000},{"price":0.97890,"qty":1021.55480641}],"asks":[],"checksum":3362756302,"timestamp":"2024-06-01T22:43:49.480602Z"}]}
{"channel":"book","type":"update","data":[{"symbol":"EUR/CHF","bids":[],"asks":[{"price":0.97993,"qty":175.24140000}],"checksum":2890989758,"timestamp":"2024-06-01T22:43:49.480610Z"}]}
{"channel":"book","type":"update","data":[{"symbol":"EUR/CHF","bids":[],"asks":[{"price":0.97994,"qty":0.00000000},{"price":0.98108,"qty":2003.00000000},{"price":0.97992,"qty":4140.00000000}],"checksum":955304181,"timestamp":"2024-06-01T22:43:49.521023Z"}]}
{"channel":"book","type":"update","data":[{"symbol":"EUR/CHF","bids":[{"price":0.97908,"qty":0.00000000},{"price":0.97884,"qty":21.41489245},{"price":0.97910,"qty":1512.99164875}],"asks":[],"checksum":2523948945,"timestamp":"2024-06-01T22:43:50.179726Z"}]}
{"channel":"book","type":"update","data":[{"symbol":"EUR/CHF","bids":[],"asks":[{"price":0.97995,"qty":0.00000000},{"price":0.98108,"qty":2003.00000000},{"price":0.97991,"qty":76.88836589}],"checksum":2689751056,"timestamp":"2024-06-01T22:43:50.179998Z"}]}
{"channel":"book","type":"update","data":[{"symbol":"EUR/CHF","bids":[],"asks":[{"price":0.98000,"qty":0.00000000},{"price":0.98108,"qty":2003.00000000}],"checksum":4016884579,"timestamp":"2024-06-01T22:43:50.466650Z"}]}
{"channel":"book","type":"update","data":[{"symbol":"EUR/CHF","bids":[],"asks":[{"price":0.97993,"qty":0.00000000},{"price":0.98110,"qty":3605.00000000}],"checksum":1821752386,"timestamp":"2024-06-01T22:43:50.471606Z"}]}
{"channel":"book","type":"update","data":[{"symbol":"EUR/CHF","bids":[{"price":0.97911,"qty":10548.32369438}],"asks":[],"checksum":2574251738,"timestamp":"2024-06-01T22:43:50.471620Z"}]}
{"channel":"book","type":"update","data":[{"symbol":"EUR/CHF","bids":[{"price":0.97909,"qty":0.00000000},{"price":0.97890,"qty":1021.55480641}],"asks":[],"checksum":1877540951,"timestamp":"2024-06-01T22:43:50.471704Z"}]}
{"channel":"book","type":"update","data":[{"symbol":"EUR/CHF","bids":[],"asks":[{"price":0.97990,"qty":175.24140000}],"checksum":528867516,"timestamp":"2024-06-01T22:43:50.471852Z"}]}
{"channel":"book","type":"update","data":[{"symbol":"EUR/CHF","bids":[],"asks":[{"price":0.97991,"qty":229.04751305}],"checksum":380541492,"timestamp":"2024-06-01T22:43:50.471964Z"}]}
{"channel":"book","type":"update","data":[{"symbol":"EUR/CHF","bids":[{"price":0.97910,"qty":0.00000000},{"price":0.97884,"qty":21.41489245},{"price":0.97912,"qty":1512.96957152}],"asks":[],"checksum":3247788128,"timestamp":"2024-06-01T22:43:50.938933Z"}]}
{"channel":"book","type":"update","data":[{"symbol":"EUR/CHF","bids":[],"asks":[{"price":0.97991,"qty":152.15914716},{"price":0.97989,"qty":76.88109881}],"checksum":1233413570,"timestamp":"2024-06-01T22:43:50.938980Z"}]}
{"channel":"book","type":"update","data":[{"symbol":"EUR/CHF","bids":[{"price":0.97905,"qty":0.00000000},{"price":0.97884,"qty":21.41489245}],"asks":[],"checksum":3321957313,"timestamp":"2024-06-01T22:43:50.969558Z"}]}
{"channel":"book","type":"update","data":[{"symbol":"EUR/CHF","bids":[{"price":0.97912,"qty":1621.34447587}],"asks":[],"checksum":658019926,"timestamp":"2024-06-01T22:43:50.970926Z"}]}
{"channel":"book","type":"update","data":[{"symbol":"EUR/CHF","bids":[],"asks":[{"price":0.98032,"qty":0.00000000},{"price":0.98108,"qty":2003.00000000}],"checksum":124593655,"timestamp":"2024-06-01T22:43:50.984406Z"}]}
{"channel":"book","type":"update","data":[{"symbol":"EUR/CHF","bids":[],"asks":[{"price":0.97998,"qty":0.00000000},{"price":0.98110,"qty":3605.00000000}],"checksum":2536001997,"timestamp":"2024-06-01T22:43:50.984485Z"}]}
{"channel":"book","type":"update","data":[{"symbol":"EUR/CHF","bids":[],"asks":[{"price":0.97989,"qty":14575.93226412}],"checksum":43477521,"timestamp":"2024-06-01T22:43:50.989702Z"}]}
{"channel":"book","type":"update","data":[{"symbol":"EUR/CHF","bids":[],"asks":[{"price":0.98032,"qty":15757.32079802}],"checksum":1822019737,"timestamp":"2024-06-01T22:43:50.989817Z"}]}
{"channel":"book","type":"update","data":[{"symbol":"EUR/CHF","bids":[],"asks":[{"price":0.98077,"qty":39901.00000000}],"checksum":3001167141,"timestamp":"2024-06-01T22:43:51.173445Z"}]}
{"channel":"book","type":"update","data":[{"symbol":"EUR/CHF","bids":[{"price":0.97907,"qty":0.00000000},{"price":0.97883,"qty":1021.62786183}],"asks":[],"checksum":3471175102,"timestamp":"2024-06-01T22:43:51.388324Z"}]}
{"channel":"book","type":"update","data":[{"symbol":"EUR/CHF","bids":[{"price":0.97913,"qty":12636.23656360}],"asks":[],"checksum":420377642,"timestamp":"2024-06-01T22:43:51.389192Z"}]}
{"channel":"book","type":"update","data":[{"symbol":"EUR/CHF","bids":[{"price":0.97912,"qty":108.37490435},{"price":0.97914,"qty":1512.94019770}],"asks":[],"checksum":3001882365,"timestamp":"2024-06-01T22:43:51.764709Z"}]}
{"channel":"book","type":"update","data":[{"symbol":"EUR/CHF","bids":[],"asks":[{"price":0.97989,"qty":14499.05116531},{"price":0.97988,"qty":76.88113298}],"checksum":906624131,"timestamp":"2024-06-01T22:43:51.765005Z"}]}
{"channel":"book","type":"update","data":[{"symbol":"EUR/CHF","bids":[],"asks":[{"price":0.97992,"qty":0.00000000},{"price":0.98098,"qty":4502.00000000},{"price":0.97988,"qty":4216.88113298}],"checksum":6216959,"timestamp":"2024-06-01T22:43:51.792403Z"}]}
{"channel":"book","type":"update","data":[{"symbol":"EUR/CHF","bids":[{"price":0.97911,"qty":0.00000000},{"price":0.97884,"qty":21.41489245}],"asks":[],"checksum":539060572,"timestamp":"2024-06-01T22:43:51.881393Z"}]}
{"channel":"book","type":"update","data":[{"symbol":"EUR/CHF","bids":[{"price":0.97915,"qty":10547.89284351}],"asks":[],"checksum":4110028063,"timestamp":"2024-06-01T22:43:51.881509Z"}]}
{"channel":"book","type":"update","data":[{"symbol":"EUR/CHF","bids":[{"price":0.97914,"qty":0.00000000},{"price":0.97884,"qty":21.41489245},{"price":0.97916,"qty":1512.90947137}],"asks":[],"checksum":2395284883,"timestamp":"2024-06-01T22:43:52.581941Z"}]}
{"channel":"book","type":"update","data":[{"symbol":"EUR/CHF","bids":[],"asks":[{"price":0.97988,"qty":4140.00000000},{"price":0.97987,"qty":76.88114162}],"checksum":1989433957,"timestamp":"2024-06-01T22:43:52.581976Z"}]}
{"channel":"book","type":"update","data":[{"symbol":"EUR/CHF","bids":[{"price":0.97915,"qty":0.00000000},{"price":0.97884,"qty":21.41489245}],"asks":[],"checksum":2438530124,"timestamp":"2024-06-01T22:43:52.584782Z"}]}
{"channel":"book","type":"update","data":[{"symbol":"EUR/CHF","bids":[{"price":0.97917,"qty":10547.67735234}],"asks":[],"checksum":1821077160,"timestamp":"2024-06-01T22:43:52.584806Z"}]}
{"channel":"book","type":"update","data":[{"symbol":"EUR/CHF","bids":[{"price":0.97916,"qty":0.00000000},{"price":0.97884,"qty":21.41489245},{"price":0.97914,"qty":1512.94086667}],"asks":[],"checksum":101345116,"timestamp":"2024-06-01T22:43:52.588184Z"}]}
{"channel":"book","type":"update","data":[{"symbol":"EUR/CHF","bids":[{"price":0.97917,"qty":0.00000000},{"price":0.97884,"qty":21.41489245}],"asks":[],"checksum":1110559875,"timestamp":"2024-06-01T22:43:52.883667Z"}]}
{"channel":"book","type":"update","data":[{"symbol":"EUR/CHF","bids":[{"price":0.97915,"qty":10547.89286108}],"asks":[],"checksum":707041567,"timestamp":"2024-06-01T22:43:52.883746Z"}]}
{"channel":"book","type":"update","data":[{"symbol":"EUR/CHF","bids":[],"asks":[{"price":0.97991,"qty":0.00000000},{"price":0.98098,"qty":4502.00000000}],"checksum":1713505186,"timestamp":"2024-06-01T22:43:53.059619Z"}]}
{"channel":"book","type":"update","data":[{"symbol":"EUR/CHF","bids":[],"asks":[{"price":0.97988,"qty":4242.60904190}],"checksum":948603790,"timestamp":"2024-06-01T22:43:53.064782Z"}]}
{"channel":"book","type":"update","data":[{"symbol":"EUR/CHF","bids":[],"asks":[{"price":0.97989,"qty":0.00000000},{"price":0.98108,"qty":2003.00000000}],"checksum":3549022863,"timestamp":"2024-06-01T22:43:53.081345Z"}]}
{"channel":"book","type":"update","data":[{"symbol":"EUR/CHF","bids":[],"asks":[{"price":0.98032,"qty":0.00000000},{"price":0.98110,"qty":3605.00000000}],"checksum":278032736,"timestamp":"2024-06-01T22:43:53.081396Z"}]}
{"channel":"book","type":"update","data":[{"symbol":"EUR/CHF","bids":[],"asks":[{"price":0.97986,"qty":1843.75979497}],"checksum":1901303157,"timestamp":"2024-06-01T22:43:53.087397Z"}]}
{"channel":"book","type":"update","data":[{"symbol":"EUR/CHF","bids":[],"asks":[{"price":0.97987,"qty":12994.02088563}],"checksum":1211114395,"timestamp":"2024-06-01T22:43:53.087462Z"}]}
{"channel":"book","type":"update","data":[{"symbol":"EUR/CHF","bids":[],"asks":[{"price":0.98032,"qty":13921.28517991}],"checksum":3591590827,"timestamp":"2024-06-01T22:43:53.087731Z"}]}
{"channel":"book","type":"update","data":[{"symbol":"EUR/CHF","bids":[{"price":0.97914,"qty":0.00000000},{"price":0.97884,"qty":21.41489245},{"price":0.97916,"qty":1512.91018317}],"asks":[],"checksum":1367077461,"timestamp":"2024-06-01T22:43:53.388834Z"}]}
{"channel":"book","type":"update","data":[{"symbol":"EUR/CHF","bids":[],"asks":[{"price":0.97987,"qty":12917.13974401},{"price":0.97985,"qty":76.90961184}],"checksum":3305781620,"timestamp":"2024-06-01T22:43:53.388875Z"}]}
{"channel":"book","type":"update","data":[{"symbol":"EUR/CHF","bids":[],"asks":[{"price":0.97988,"qty":102.60904190},{"price":0.97985,"qty":4216.90961184}],"checksum":2272619656,"timestamp":"2024-06-01T22:43:53.399689Z"}]}
{"channel":"book","type":"update","data":[{"symbol":"EUR/CHF","bids":[{"price":0.97912,"qty":0.00000000},{"price":0.97884,"qty":21.41489245}],"asks":[],"checksum":2576542270,"timestamp":"2024-06-01T22:43:53.470611Z"}]}
{"channel":"book","type":"update","data":[{"symbol":"EUR/CHF","bids":[{"price":0.97916,"qty":1603.29762624}],"asks":[],"checksum":2979200350,"timestamp":"2024-06-01T22:43:53.471599Z"}]}
{"channel":"book","type":"update","data":[{"symbol":"EUR/CHF","bids":[{"price":0.97913,"qty":0.00000000},{"price":0.97883,"qty":1021.62786183}],"asks":[],"checksum":2877204807,"timestamp":"2024-06-01T22:43:53.565372Z"}]}
{"channel":"book","type":"update","data":[{"symbol":"EUR/CHF","bids":[{"price":0.97916,"qty":14239.53418984}],"asks":[],"checksum":3493086651,"timestamp":"2024-06-01T22:43:53.566881Z"}]}
{"channel":"book","type":"update","data":[{"symbol":"EUR/CHF","bids":[],"asks":[{"price":0.97985,"qty":76.90961184},{"price":0.97984,"qty":4140.00000000}],"checksum":2576902647,"timestamp":"2024-06-01T22:43:53.585349Z"}]}
{"channel":"book","type":"update","data":[{"symbol":"EUR/CHF","bids":[],"asks":[{"price":0.97985,"qty":0.00000000},{"price":0.98077,"qty":39901.00000000},{"price":0.97983,"qty":76.90961558}],"checksum":733892708,"timestamp":"2024-06-01T22:43:54.219270Z"}]}
{"channel":"book","type":"update","data":[{"symbol":"EUR/CHF","bids":[{"price":0.97916,"qty":12726.62400667},{"price":0.97917,"qty":1512.89506142}],"asks":[],"checksum":648587942,"timestamp":"2024-06-01T22:43:54.219398Z"}]}
{"channel":"book","type":"update","data":[{"symbol":"EUR/CHF","bids":[{"price":0.97915,"qty":0.00000000},{"price":0.97883,"qty":1021.62786183}],"asks":[],"checksum":3156254979,"timestamp":"2024-06-01T22:43:54.272620Z"}]}
{"channel":"book","type":"update","data":[{"symbol":"EUR/CHF","bids":[],"asks":[{"price":0.98021,"qty":175.24140000}],"checksum":2515725008,"timestamp":"2024-06-01T22:43:54.272669Z"}]}
{"channel":"book","type":"update","data":[{"symbol":"EUR/CHF","bids":[{"price":0.97918,"qty":9833.83067738}],"asks":[],"checksum":1855085797,"timestamp":"2024-06-01T22:43:54.272733Z"}]}
{"channel":"book","type":"update","data":[{"symbol":"EUR/CHF","bids":[],"asks":[{"price":0.97990,"qty":0.00000000},{"price":0.98034,"qty":322.51872116}],"checksum":1589181676,"timestamp":"2024-06-01T22:43:54.272779Z"}]}
{"channel":"book","type":"update","data":[{"symbol":"EUR/CHF","bids":[{"price":0.97917,"qty":0.00000000},{"price":0.97883,"qty":1021.62786183},{"price":0.97919,"qty":1512.85646838}],"asks":[],"checksum":2995813366,"timestamp":"2024-06-01T22:43:55.040838Z"}]}
{"channel":"book","type":"update","data":[{"symbol":"EUR/CHF","bids":[],"asks":[{"price":0.97986,"qty":0.00000000},{"price":0.98077,"qty":39901.00000000}],"checksum":3721461084,"timestamp":"2024-06-01T22:43:55.237198Z"}]}
{"channel":"book","type":"update","data":[{"symbol":"EUR/CHF","bids":[],"asks":[{"price":0.98032,"qty":0.00000000},{"price":0.98098,"qty":4502.00000000}],"checksum":3671048631,"timestamp":"2024-06-01T22:43:55.237309Z"}]}
{"channel":"book","type":"update","data":[{"symbol":"EUR/CHF","bids":[],"asks":[{"price":0.97987,"qty":0.00000000},{"price":0.98108,"qty":2003.00000000}],"checksum":3202150416,"timestamp":"2024-06-01T22:43:55.237522Z"}]}
{"channel":"book","type":"update","data":[{"symbol":"EUR/CHF","bids":[],"asks":[{"price":0.98032,"qty":22114.31835526}],"checksum":1643693960,"timestamp":"2024-06-01T22:43:55.242730Z"}]}
{"channel":"book","type":"update","data":[{"symbol":"EUR/CHF","bids":[],"asks":[{"price":0.97983,"qty":6666.40367443}],"checksum":137067418,"timestamp":"2024-06-01T22:43:55.242759Z"}]}
{"channel":"book","type":"update","data":[{"symbol":"EUR/CHF","bids":[],"asks":[{"price":0.97984,"qty":0.00000000},{"price":0.98108,"qty":2003.00000000},{"price":0.98020,"qty":4140.00000000}],"checksum":1678112957,"timestamp":"2024-06-01T22:43:55.252883Z"}]}
{"channel":"book","type":"update","data":[{"symbol":"EUR/CHF","bids":[{"price":0.97918,"qty":0.00000000},{"price":0.97883,"qty":1021.62786183}],"asks":[],"checksum":1107486813,"timestamp":"2024-06-01T22:43:55.279671Z"}]}
{"channel":"book","type":"update","data":[{"symbol":"EUR/CHF","bids":[],"asks":[{"price":0.98021,"qty":0.00000000},{"price":0.98108,"qty":2003.00000000}],"checksum":2062586834,"timestamp":"2024-06-01T22:43:55.279725Z"}]}
{"channel":"book","type":"update","data":[{"symbol":"EUR/CHF","bids":[{"price":0.97920,"qty":9958.43155073}],"asks":[],"checksum":2708139608,"timestamp":"2024-06-01T22:43:55.279825Z"}]}
{"channel":"book","type":"update","data":[{"symbol":"EUR/CHF","bids":[],"asks":[{"price":0.98019,"qty":175.24140000}],"checksum":391401709,"timestamp":"2024-06-01T22:43:55.280101Z"}]}
{"channel":"book","type":"update","data":[{"symbol":"EUR/CHF","bids":[{"price":0.97919,"qty":0.00000000},{"price":0.97883,"qty":1021.62786183},{"price":0.97917,"qty":1512.88511036}],"asks":[],"checksum":3472346949,"timestamp":"2024-06-01T22:43:55.287351Z"}]}
{"channel":"book","type":"update","data":[{"symbol":"EUR/CHF","bids":[],"asks":[{"price":0.98020,"qty":0.00000000},{"price":0.98108,"qty":2003.00000000},{"price":0.98018,"qty":4140.00000000}],"checksum":2637074711,"timestamp":"2024-06-01T22:43:55.314457Z"}]}
{"channel":"book","type":"update","data":[{"symbol":"EUR/CHF","bids":[],"asks":[{"price":0.97988,"qty":0.00000000},{"price":0.98108,"qty":2003.00000000}],"checksum":2843733729,"timestamp":"2024-06-01T22:43:55.506908Z"}]}
{"channel":"book","type":"update","data":[{"symbol":"EUR/CHF","bids":[],"asks":[{"price":0.97983,"qty":6775.02496233}],"checksum":1148409222,"timestamp":"2024-06-01T22:43:55.512080Z"}]}
{"channel":"book","type":"update","data":[{"symbol":"EUR/CHF","bids":[{"price":0.97916,"qty":90.38744307}],"asks":[],"checksum":1036211654,"timestamp":"2024-06-01T22:43:55.575764Z"}]}
{"channel":"book","type":"update","data":[{"symbol":"EUR/CHF","bids":[{"price":0.97921,"qty":9038.74430739}],"asks":[],"checksum":3532352661,"timestamp":"2024-06-01T22:43:55.576876Z"}]}
{"channel":"book","type":"update","data":[{"symbol":"EUR/CHF","bids":[{"price":0.97917,"qty":0.00000000},{"price":0.97884,"qty":21.41489245},{"price":0.97922,"qty":1512.80766356}],"asks":[],"checksum":4005171700,"timestamp":"2024-06-01T22:43:55.895522Z"}]}
{"channel":"book","type":"update","data":[{"symbol":"EUR/CHF","bids":[],"asks":[{"price":0.97983,"qty":6698.11534675},{"price":0.97982,"qty":76.90683763}],"checksum":557158434,"timestamp":"2024-06-01T22:43:55.895697Z"}]}
{"channel":"book","type":"update","data":[{"symbol":"EUR/CHF","bids":[{"price":0.97916,"qty":0.00000000},{"price":0.97884,"qty":21.41489245}],"asks":[],"checksum":1835040978,"timestamp":"2024-06-01T22:43:56.004514Z"}]}
{"channel":"book","type":"update","data":[{"symbol":"EUR/CHF","bids":[{"price":0.97922,"qty":1585.20764535}],"asks":[],"checksum":3500776729,"timestamp":"2024-06-01T22:43:56.006184Z"}]}
{"channel":"book","type":"update","data":[{"symbol":"EUR/CHF","bids":[{"price":0.97920,"qty":0.00000000},{"price":0.97883,"qty":1021.62786183}],"asks":[],"checksum":2438145956,"timestamp":"2024-06-01T22:43:56.685960Z"}]}
{"channel":"book","type":"update","data":[{"symbol":"EUR/CHF","bids":[],"asks":[{"price":0.98019,"qty":0.00000000},{"price":0.98108,"qty":2003.00000000}],"checksum":2648071883,"timestamp":"2024-06-01T22:43:56.686004Z"}]}
{"channel":"book","type":"update","data":[{"symbol":"EUR/CHF","bids":[],"asks":[{"price":0.98017,"qty":175.24140000}],"checksum":2077071174,"timestamp":"2024-06-01T22:43:56.686293Z"}]}
{"channel":"book","type":"update","data":[{"symbol":"EUR/CHF","bids":[{"price":0.97923,"qty":10547.03104153}],"asks":[],"checksum":1242881964,"timestamp":"2024-06-01T22:43:56.687587Z"}]}
{"channel":"book","type":"update","data":[{"symbol":"EUR/CHF","bids":[],"asks":[{"price":0.98018,"qty":0.00000000},{"price":0.98108,"qty":2003.00000000},{"price":0.98016,"qty":4140.00000000}],"checksum":3404627607,"timestamp":"2024-06-01T22:43:56.710377Z"}]}
{"channel":"book","type":"update","data":[{"symbol":"EUR/CHF","bids":[{"price":0.97922,"qty":72.39998179},{"price":0.97924,"qty":1512.76294454}],"asks":[],"checksum":4147354617,"timestamp":"2024-06-01T22:43:56.774385Z"}]}
{"channel":"book","type":"update","data":[{"symbol":"EUR/CHF","bids":[],"asks":[{"price":0.98032,"qty":0.00000000},{"price":0.98108,"qty":2003.00000000}],"checksum":1544520690,"timestamp":"2024-06-01T22:43:57.278052Z"}]}
{"channel":"book","type":"update","data":[{"symbol":"EUR/CHF","bids":[],"asks":[{"price":0.97983,"qty":108.62128790}],"checksum":2252017517,"timestamp":"2024-06-01T22:43:57.278247Z"}]}
{"channel":"book","type":"update","data":[{"symbol":"EUR/CHF","bids":[],"asks":[{"price":0.98015,"qty":30318.16537822}],"checksum":1260409262,"timestamp":"2024-06-01T22:43:57.280204Z"}]}
{"channel":"book","type":"update","data":[{"symbol":"EUR/CHF","bids":[],"asks":[{"price":0.97982,"qty":0.00000000},{"price":0.98108,"qty":2003.00000000},{"price":0.98015,"qty":30395.04764350}],"checksum":429654959,"timestamp":"2024-06-01T22:43:57.281970Z"}]}
{"channel":"book","type":"update","data":[{"symbol":"EUR/CHF","bids":[],"asks":[{"price":0.98016,"qty":0.00000000},{"price":0.98110,"qty":3605.00000000},{"price":0.98014,"qty":4140.00000000}],"checksum":2419708105,"timestamp":"2024-06-01T22:43:57.288537Z"}]}
{"channel":"book","type":"update","data":[{"symbol":"EUR/CHF","bids":[],"asks":[{"price":0.98015,"qty":30318.16537822},{"price":0.98013,"qty":76.88226528}],"checksum":3295623337,"timestamp":"2024-06-01T22:43:57.610339Z"}]}
{"channel":"book","type":"update","data":[{"symbol":"EUR/CHF","bids":[],"asks":[{"price":0.98014,"qty":0.00000000},{"price":0.98108,"qty":2003.00000000},{"price":0.98012,"qty":4140.00000000}],"checksum":218381967,"timestamp":"2024-06-01T22:43:57.622726Z"}]}
{"channel":"book","type":"update","data":[{"symbol":"EUR/CHF","bids":[],"asks":[{"price":0.98017,"qty":0.00000000},{"price":0.98108,"qty":2003.00000000}],"checksum":2573547721,"timestamp":"2024-06-01T22:43:57.677148Z"}]}
{"channel":"book","type":"update","data":[{"symbol":"EUR/CHF","bids":[],"asks":[{"price":0.98011,"qty":175.24140000}],"checksum":2888871146,"timestamp":"2024-06-01T22:43:57.677517Z"}]}
{"channel":"book","type":"update","data":[{"symbol":"EUR/CHF","bids":[],"asks":[{"price":0.98012,"qty":0.00000000},{"price":0.98108,"qty":2003.00000000},{"price":0.98010,"qty":4140.00000000}],"checksum":611618304,"timestamp":"2024-06-01T22:43:57.685697Z"}]}
{"channel":"book","type":"update","data":[{"symbol":"EUR/CHF","bids":[{"price":0.97921,"qty":0.00000000},{"price":0.97884,"qty":21.41489245}],"asks":[],"checksum":3348602290,"timestamp":"2024-06-01T22:43:57.702828Z"}]}
{"channel":"book","type":"update","data":[{"symbol":"EUR/CHF","bids":[{"price":0.97925,"qty":9038.74430739}],"asks":[],"checksum":4037366942,"timestamp":"2024-06-01T22:43:57.704299Z"}]}
{"channel":"book","type":"update","data":[{"symbol":"EUR/CHF","bids":[{"price":0.97923,"qty":0.00000000},{"price":0.97884,"qty":21.41489245}],"asks":[],"checksum":1578568423,"timestamp":"2024-06-01T22:43:57.857844Z"}]}
{"channel":"book","type":"update","data":[{"symbol":"EUR/CHF","bids":[{"price":0.97901,"qty":10549.40121616}],"asks":[],"checksum":4144606348,"timestamp":"2024-06-01T22:43:57.858003Z"}]}
{"channel":"book","type":"update","data":[{"symbol":"EUR/CHF","bids":[],"asks":[{"price":0.97983,"qty":0.00000000},{"price":0.98108,"qty":2003.00000000}],"checksum":541200686,"timestamp":"2024-06-01T22:43:58.084177Z"}]}
{"channel":"book","type":"update","data":[{"symbol":"EUR/CHF","bids":[],"asks":[{"price":0.98011,"qty":374.04637785}],"checksum":1865486331,"timestamp":"2024-06-01T22:43:58.089941Z"}]}
{"channel":"book","type":"update","data":[{"symbol":"EUR/CHF","bids":[],"asks":[{"price":0.98009,"qty":237.14908295}],"checksum":840652693,"timestamp":"2024-06-01T22:43:58.265793Z"}]}
{"channel":"book","type":"update","data":[{"symbol":"EUR/CHF","bids":[],"asks":[{"price":0.98010,"qty":0.00000000},{"price":0.98108,"qty":2003.00000000},{"price":0.98008,"qty":4140.00000000}],"checksum":3392293721,"timestamp":"2024-06-01T22:43:58.294002Z"}]}
{"channel":"book","type":"update","data":[{"symbol":"EUR/CHF","bids":[],"asks":[{"price":0.98077,"qty":0.00000000},{"price":0.98108,"qty":2003.00000000}],"checksum":502092717,"timestamp":"2024-06-01T22:43:58.294605Z"}]}
{"channel":"book","type":"update","data":[{"symbol":"EUR/CHF","bids":[],"asks":[{"price":0.98022,"qty":0.00000000},{"price":0.98110,"qty":3605.00000000}],"checksum":483647119,"timestamp":"2024-06-01T22:43:58.434466Z"}]}
{"channel":"book","type":"update","data":[{"symbol":"EUR/CHF","bids":[],"asks":[{"price":0.98013,"qty":0.00000000},{"price":0.98112,"qty":2004.00000000},{"price":0.98007,"qty":76.91218602}],"checksum":2818181424,"timestamp":"2024-06-01T22:43:58.436335Z"}]}
{"channel":"book","type":"update","data":[{"symbol":"EUR/CHF","bids":[],"asks":[{"price":0.98008,"qty":0.00000000},{"price":0.98112,"qty":2004.00000000},{"price":0.98006,"qty":4140.00000000}],"checksum":106211520,"timestamp":"2024-06-01T22:43:58.447806Z"}]}
{"channel":"book","type":"update","data":[{"symbol":"EUR/CHF","bids":[{"price":0.97922,"qty":0.00000000},{"price":0.97884,"qty":21.41489245}],"asks":[],"checksum":330560250,"timestamp":"2024-06-01T22:43:58.585535Z"}]}
{"channel":"book","type":"update","data":[{"symbol":"EUR/CHF","bids":[{"price":0.97926,"qty":72.39998179}],"asks":[],"checksum":3999727734,"timestamp":"2024-06-01T22:43:58.586717Z"}]}
{"channel":"book","type":"update","data":[{"symbol":"EUR/CHF","bids":[],"asks":[{"price":0.98011,"qty":198.80497785}],"checksum":1609809965,"timestamp":"2024-06-01T22:43:59.086086Z"}]}
{"channel":"book","type":"update","data":[{"symbol":"EUR/CHF","bids":[],"asks":[{"price":0.98005,"qty":175.24140000}],"checksum":1507513836,"timestamp":"2024-06-01T22:43:59.086446Z"}]}
{"channel":"book","type":"update","data":[{"symbol":"EUR/CHF","bids":[],"asks":[{"price":0.98006,"qty":0.00000000},{"price":0.98110,"qty":3605.00000000},{"price":0.98004,"qty":4140.00000000}],"checksum":382209269,"timestamp":"2024-06-01T22:43:59.121240Z"}]}
{"channel":"book","type":"update","data":[{"symbol":"EUR/CHF","bids":[],"asks":[{"price":0.98007,"qty":0.00000000},{"price":0.98110,"qty":3605.00000000},{"price":0.98003,"qty":76.81978775}],"checksum":2973967462,"timestamp":"2024-06-01T22:43:59.218998Z"}]}
{"channel":"book","type":"update","data":[{"symbol":"EUR/CHF","bids":[{"price":0.97924,"qty":0.00000000},{"price":0.97884,"qty":21.41489245},{"price":0.97927,"qty":1512.70991295}],"asks":[],"checksum":2589984782,"timestamp":"2024-06-01T22:43:59.219098Z"}]}
{"channel":"book","type":"update","data":[{"symbol":"EUR/CHF","bids":[],"asks":[{"price":0.98004,"qty":0.00000000},{"price":0.98110,"qty":3605.00000000},{"price":0.98002,"qty":4140.00000000}],"checksum":922569882,"timestamp":"2024-06-01T22:43:59.244902Z"}]}
{"channel":"book","type":"update","data":[{"symbol":"EUR/CHF","bids":[],"asks":[{"price":0.98015,"qty":0.00000000},{"price":0.98110,"qty":3605.00000000}],"checksum":2635895026,"timestamp":"2024-06-01T22:43:59.425766Z"}]}
{"channel":"book","type":"update","data":[{"symbol":"EUR/CHF","bids":[],"asks":[{"price":0.98005,"qty":29739.20881742}],"checksum":913621208,"timestamp":"2024-06-01T22:43:59.430997Z"}]}
{"channel":"book","type":"update","data":[{"symbol":"EUR/CHF","bids":[{"price":0.97925,"qty":0.00000000},{"price":0.97884,"qty":21.41489245}],"asks":[],"checksum":501339072,"timestamp":"2024-06-01T22:43:59.851364Z"}]}
{"channel":"book","type":"update","data":[{"symbol":"EUR/CHF","bids":[{"price":0.97902,"qty":12636.23656360}],"asks":[],"checksum":562866792,"timestamp":"2024-06-01T22:43:59.853048Z"}]}
{"channel":"book","type":"update","data":[{"symbol":"EUR/CHF","bids":[{"price":0.97927,"qty":0.00000000},{"price":0.97884,"qty":21.41489245},{"price":0.97902,"qty":14149.33242757}],"asks":[],"checksum":1384683618,"timestamp":"2024-06-01T22:43:59.854354Z"}]}
{"channel":"book","type":"update","data":[{"symbol":"EUR/CHF","bids":[{"price":0.97902,"qty":12636.23656360},{"price":0.97903,"qty":1513.08040892}],"asks":[],"checksum":319498304,"timestamp":"2024-06-01T22:44:00.068987Z"}]}
{"channel":"book","type":"update","data":[{"symbol":"EUR/CHF","bids":[],"asks":[{"price":0.98003,"qty":0.00000000},{"price":0.98112,"qty":2004.00000000},{"price":0.98001,"qty":76.81978679}],"checksum":3296316186,"timestamp":"2024-06-01T22:44:00.069114Z"}]}
{"channel":"book","type":"update","data":[{"symbol":"EUR/CHF","bids":[],"asks":[{"price":0.98005,"qty":29563.96741742}],"checksum":2901140875,"timestamp":"2024-06-01T22:44:00.088627Z"}]}
{"channel":"book","type":"update","data":[{"symbol":"EUR/CHF","bids":[{"price":0.97904,"qty":10549.07794412}],"asks":[],"checksum":1837914967,"timestamp":"2024-06-01T22:44:00.088782Z"}]}
{"channel":"book","type":"update","data":[{"symbol":"EUR/CHF","bids":[],"asks":[{"price":0.98000,"qty":175.24140000}],"checksum":1348818395,"timestamp":"2024-06-01T22:44:00.088852Z"}]}
{"channel":"book","type":"update","data":[{"symbol":"EUR/CHF","bids":[{"price":0.97901,"qty":0.00000000},{"price":0.97890,"qty":1021.55480641}],"asks":[],"checksum":2055817352,"timestamp":"2024-06-01T22:44:00.088983Z"}]}
{"channel":"book","type":"update","data":[{"symbol":"EUR/CHF","bids":[],"asks":[{"price":0.98002,"qty":0.00000000},{"price":0.98110,"qty":3605.00000000},{"price":0.97999,"qty":4140.00000000}],"checksum":3937843046,"timestamp":"2024-06-01T22:44:00.125674Z"}]}
{"channel":"book","type":"update","data":[{"symbol":"EUR/CHF","bids":[],"asks":[{"price":0.98011,"qty":0.00000000},{"price":0.98110,"qty":3605.00000000}],"checksum":1634076087,"timestamp":"2024-06-01T22:44:00.641154Z"}]}
{"channel":"book","type":"update","data":[{"symbol":"EUR/CHF","bids":[],"asks":[{"price":0.97998,"qty":162.73150187}],"checksum":678181342,"timestamp":"2024-06-01T22:44:00.646469Z"}]}
{"channel":"book","type":"update","data":[{"symbol":"EUR/CHF","bids":[],"asks":[{"price":0.97999,"qty":0.00000000},{"price":0.98110,"qty":3605.00000000},{"price":0.97997,"qty":4140.00000000}],"checksum":1911303917,"timestamp":"2024-06-01T22:44:00.671844Z"}]}
{"channel":"book","type":"update","data":[{"symbol":"EUR/CHF","bids":[{"price":0.97903,"qty":0.00000000},{"price":0.97884,"qty":21.41489245},{"price":0.97905,"qty":1513.04948062}],"asks":[],"checksum":2048186657,"timestamp":"2024-06-01T22:44:00.943882Z"}]}
{"channel":"book","type":"update","data":[{"symbol":"EUR/CHF","bids":[],"asks":[{"price":0.98001,"qty":0.00000000},{"price":0.98110,"qty":3605.00000000},{"price":0.97996,"qty":76.79661517}],"checksum":3714938760,"timestamp":"2024-06-01T22:44:00.944003Z"}]}
{"channel":"book","type":"update","data":[{"symbol":"EUR/CHF","bids":[{"price":0.97926,"qty":0.00000000},{"price":0.97884,"qty":21.41489245}],"asks":[],"checksum":2730563050,"timestamp":"2024-06-01T22:44:01.079645Z"}]}
{"channel":"book","type":"update","data":[{"symbol":"EUR/CHF","bids":[{"price":0.97905,"qty":1621.42438497}],"asks":[],"checksum":2257134658,"timestamp":"2024-06-01T22:44:01.080893Z"}]}
{"channel":"book","type":"update","data":[{"symbol":"EUR/CHF","bids":[],"asks":[{"price":0.97997,"qty":0.00000000},{"price":0.98110,"qty":3605.00000000},{"price":0.97995,"qty":4140.00000000}],"checksum":3110851762,"timestamp":"2024-06-01T22:44:01.097870Z"}]}
{"channel":"book","type":"update","data":[{"symbol":"EUR/CHF","bids":[],"asks":[{"price":0.98000,"qty":0.00000000},{"price":0.98110,"qty":3605.00000000}],"checksum":1789362878,"timestamp":"2024-06-01T22:44:01.492643Z"}]}
{"channel":"book","type":"update","data":[{"symbol":"EUR/CHF","bids":[{"price":0.97906,"qty":10548.86241769}],"asks":[],"checksum":3621276619,"timestamp":"2024-06-01T22:44:01.492810Z"}]}
{"channel":"book","type":"update","data":[{"symbol":"EUR/CHF","bids":[{"price":0.97904,"qty":0.00000000},{"price":0.97884,"qty":21.41489245}],"asks":[],"checksum":369301607,"timestamp":"2024-06-01T22:44:01.492823Z"}]}
{"channel":"book","type":"update","data":[{"symbol":"EUR/CHF","bids":[],"asks":[{"price":0.97994,"qty":175.24140000}],"checksum":3603624812,"timestamp":"2024-06-01T22:44:01.492944Z"}]}
{"channel":"book","type":"update","data":[{"symbol":"EUR/CHF","bids":[],"asks":[{"price":0.97995,"qty":0.00000000},{"price":0.98110,"qty":3605.00000000},{"price":0.97993,"qty":4140.00000000}],"checksum":866775573,"timestamp":"2024-06-01T22:44:01.524212Z"}]}
{"channel":"book","type":"update","data":[{"symbol":"EUR/CHF","bids":[],"asks":[{"price":0.98005,"qty":0.00000000},{"price":0.98110,"qty":3605.00000000}],"checksum":2855429198,"timestamp":"2024-06-01T22:44:01.554783Z"}]}
{"channel":"book","type":"update","data":[{"symbol":"EUR/CHF","bids":[],"asks":[{"price":0.97995,"qty":1843.75979497}],"checksum":1602851196,"timestamp":"2024-06-01T22:44:01.560205Z"}]}
{"channel":"book","type":"update","data":[{"symbol":"EUR/CHF","bids":[],"asks":[{"price":0.98032,"qty":9180.95783984}],"checksum":3389168961,"timestamp":"2024-06-01T22:44:01.560221Z"}]}
{"channel":"book","type":"update","data":[{"symbol":"EUR/CHF","bids":[],"asks":[{"price":0.97996,"qty":16157.75920177}],"checksum":3871536941,"timestamp":"2024-06-01T22:44:01.560472Z"}]}
{"channel":"book","type":"update","data":[{"symbol":"EUR/CHF","bids":[{"price":0.97905,"qty":108.37490435},{"price":0.97907,"qty":1513.00524057}],"asks":[],"checksum":4227092940,"timestamp":"2024-06-01T22:44:01.808631Z"}]}
{"channel":"book","type":"update","data":[{"symbol":"EUR/CHF","bids":[],"asks":[{"price":0.97996,"qty":16080.96258660},{"price":0.97992,"qty":76.79661244}],"checksum":2837213701,"timestamp":"2024-06-01T22:44:01.808676Z"}]}
{"channel":"book","type":"update","data":[{"symbol":"EUR/CHF","bids":[{"price":0.97902,"qty":0.00000000},{"price":0.97884,"qty":21.41489245}],"asks":[],"checksum":3893804195,"timestamp":"2024-06-01T22:44:01.821348Z"}]}
{"channel":"book","type":"update","data":[{"symbol":"EUR/CHF","bids":[{"price":0.97907,"qty":15947.98793227}],"asks":[],"checksum":1406065845,"timestamp":"2024-06-01T22:44:01.822396Z"}]}
{"channel":"book","type":"update","data":[{"symbol":"EUR/CHF","bids":[],"asks":[{"price":0.97993,"qty":0.00000000},{"price":0.98098,"qty":4502.00000000},{"price":0.97991,"qty":4140.00000000}],"checksum":2721357618,"timestamp":"2024-06-01T22:44:01.829702Z"}]}
{"channel":"book","type":"update","data":[{"symbol":"EUR/CHF","bids":[{"price":0.97906,"qty":0.00000000},{"price":0.97883,"qty":1021.62786183}],"asks":[],"checksum":87288041,"timestamp":"2024-06-01T22:44:02.491399Z"}]}
{"channel":"book","type":"update","data":[{"symbol":"EUR/CHF","bids":[],"asks":[{"price":0.97994,"qty":0.00000000},{"price":0.98079,"qty":39901.00000000}],"checksum":3195381343,"timestamp":"2024-06-01T22:44:02.491419Z"}]}
{"channel":"book","type":"update","data":[{"symbol":"EUR/CHF","bids":[],"asks":[{"price":0.97990,"qty":175.24140000}],"checksum":3553569037,"timestamp":"2024-06-01T22:44:02.491477Z"}]}
{"channel":"book","type":"update","data":[{"symbol":"EUR/CHF","bids":[{"price":0.97908,"qty":10548.64697946}],"asks":[],"checksum":1867650288,"timestamp":"2024-06-01T22:44:02.491676Z"}]}
{"channel":"book","type":"update","data":[{"symbol":"EUR/CHF","bids":[],"asks":[{"price":0.97991,"qty":0.00000000},{"price":0.98079,"qty":39901.00000000},{"price":0.97989,"qty":4140.00000000}],"checksum":3618754338,"timestamp":"2024-06-01T22:44:02.527635Z"}]}
{"channel":"book","type":"update","data":[{"symbol":"EUR/CHF","bids":[],"asks":[{"price":0.97992,"qty":0.00000000},{"price":0.98079,"qty":39901.00000000},{"price":0.97988,"qty":76.79582353}],"checksum":1938192239,"timestamp":"2024-06-01T22:44:02.664477Z"}]}
{"channel":"book","type":"update","data":[{"symbol":"EUR/CHF","bids":[{"price":0.97907,"qty":14434.98269170},{"price":0.97909,"qty":1512.98128975}],"asks":[],"checksum":3831676299,"timestamp":"2024-06-01T22:44:02.664504Z"}]}
{"channel":"book","type":"update","data":[{"symbol":"EUR/CHF","bids":[],"asks":[{"price":0.97989,"qty":0.00000000},{"price":0.98079,"qty":39901.00000000},{"price":0.97987,"qty":4140.00000000}],"checksum":1551528463,"timestamp":"2024-06-01T22:44:02.681839Z"}]}
{"channel":"book","type":"update","data":[{"symbol":"EUR/CHF","bids":[],"asks":[{"price":0.97998,"qty":0.00000000},{"price":0.98079,"qty":39901.00000000}],"checksum":1080675958,"timestamp":"2024-06-01T22:44:03.192445Z"}]}
{"channel":"book","type":"update","data":[{"symbol":"EUR/CHF","bids":[],"asks":[{"price":0.97988,"qty":212.47221841}],"checksum":1813046529,"timestamp":"2024-06-01T22:44:03.198472Z"}]}
{"channel":"book","type":"update","data":[{"symbol":"EUR/CHF","bids":[],"asks":[{"price":0.97988,"qty":135.67639488},{"price":0.97986,"qty":76.79582221}],"checksum":1733492807,"timestamp":"2024-06-01T22:44:03.509405Z"}]}
{"channel":"book","type":"update","data":[{"symbol":"EUR/CHF","bids":[],"asks":[{"price":0.97995,"qty":0.00000000},{"price":0.98079,"qty":39901.00000000}],"checksum":3017762833,"timestamp":"2024-06-01T22:44:03.518736Z"}]}
{"channel":"book","type":"update","data":[{"symbol":"EUR/CHF","bids":[],"asks":[{"price":0.97996,"qty":0.00000000},{"price":0.98098,"qty":4502.00000000}],"checksum":2671317870,"timestamp":"2024-06-01T22:44:03.518758Z"}]}
{"channel":"book","type":"update","data":[{"symbol":"EUR/CHF","bids":[],"asks":[{"price":0.98032,"qty":0.00000000},{"price":0.98108,"qty":2003.00000000}],"checksum":4270787307,"timestamp":"2024-06-01T22:44:03.518918Z"}]}
{"channel":"book","type":"update","data":[{"symbol":"EUR/CHF","bids":[],"asks":[{"price":0.97986,"qty":12993.93556622}],"checksum":4151366628,"timestamp":"2024-06-01T22:44:03.524262Z"}]}
{"channel":"book","type":"update","data":[{"symbol":"EUR/CHF","bids":[],"asks":[{"price":0.98032,"qty":14188.54047739}],"checksum":2968541871,"timestamp":"2024-06-01T22:44:03.524389Z"}]}
{"channel":"book","type":"update","data":[{"symbol":"EUR/CHF","bids":[],"asks":[{"price":0.97987,"qty":0.00000000},{"price":0.98108,"qty":2003.00000000},{"price":0.98008,"qty":4140.00000000}],"checksum":1750607878,"timestamp":"2024-06-01T22:44:03.530063Z"}]}
{"channel":"book","type":"update","data":[{"symbol":"EUR/CHF","bids":[{"price":0.97905,"qty":0.00000000},{"price":0.97884,"qty":21.41489245}],"asks":[],"checksum":1115229133,"timestamp":"2024-06-01T22:44:03.534787Z"}]}
{"channel":"book","type":"update","data":[{"symbol":"EUR/CHF","bids":[{"price":0.97910,"qty":90.38744307}],"asks":[],"checksum":3813819807,"timestamp":"2024-06-01T22:44:03.536093Z"}]}
{"channel":"book","type":"update","data":[{"symbol":"EUR/CHF","bids":[],"asks":[{"price":0.98007,"qty":175.24140000}],"checksum":579710172,"timestamp":"2024-06-01T22:44:03.880173Z"}]}
{"channel":"book","type":"update","data":[{"symbol":"EUR/CHF","bids":[],"asks":[{"price":0.97990,"qty":0.00000000},{"price":0.98098,"qty":4502.00000000}],"checksum":1581220085,"timestamp":"2024-06-01T22:44:03.880274Z"}]}
{"channel":"book","type":"update","data":[{"symbol":"EUR/CHF","bids":[],"asks":[{"price":0.98008,"qty":0.00000000},{"price":0.98108,"qty":2003.00000000},{"price":0.98006,"qty":4140.00000000}],"checksum":3993201636,"timestamp":"2024-06-01T22:44:03.895917Z"}]}
{"channel":"book","type":"update","data":[{"symbol":"EUR/CHF","bids":[{"price":0.97907,"qty":0.00000000},{"price":0.97884,"qty":21.41489245}],"asks":[],"checksum":465129473,"timestamp":"2024-06-01T22:44:03.933355Z"}]}
{"channel":"book","type":"update","data":[{"symbol":"EUR/CHF","bids":[{"price":0.97910,"qty":10882.86421170}],"asks":[],"checksum":190133522,"timestamp":"2024-06-01T22:44:03.934461Z"}]}
{"channel":"book","type":"update","data":[{"symbol":"EUR/CHF","bids":[{"price":0.97911,"qty":1843.75979497}],"asks":[],"checksum":2232758570,"timestamp":"2024-06-01T22:44:03.934530Z"}]}
{"channel":"book","type":"update","data":[{"symbol":"EUR/CHF","bids":[],"asks":[{"price":0.97986,"qty":12917.13974401},{"price":0.97985,"qty":76.79582044}],"checksum":4011069593,"timestamp":"2024-06-01T22:44:04.388651Z"}]}
{"channel":"book","type":"update","data":[{"symbol":"EUR/CHF","bids":[{"price":0.97909,"qty":0.00000000},{"price":0.97884,"qty":21.41489245},{"price":0.97912,"qty":1512.93471238}],"asks":[],"checksum":1045556960,"timestamp":"2024-06-01T22:44:04.388783Z"}]}
{"channel":"book","type":"update","data":[{"symbol":"EUR/CHF","bids":[{"price":0.97908,"qty":0.00000000},{"price":0.97884,"qty":21.41489245}],"asks":[],"checksum":950896993,"timestamp":"2024-06-01T22:44:04.881355Z"}]}
{"channel":"book","type":"update","data":[{"symbol":"EUR/CHF","bids":[],"asks":[{"price":0.98007,"qty":0.00000000},{"price":0.98098,"qty":4502.00000000}],"checksum":477925293,"timestamp":"2024-06-01T22:44:04.881390Z"}]}
{"channel":"book","type":"update","data":[{"symbol":"EUR/CHF","bids":[],"asks":[{"price":0.98005,"qty":175.24140000}],"checksum":2823431963,"timestamp":"2024-06-01T22:44:04.881437Z"}]}
{"channel":"book","type":"update","data":[{"symbol":"EUR/CHF","bids":[{"price":0.97913,"qty":10548.10827885}],"asks":[],"checksum":3575786041,"timestamp":"2024-06-01T22:44:04.881635Z"}]}
{"channel":"book","type":"update","data":[{"symbol":"EUR/CHF","bids":[],"asks":[{"price":0.98006,"qty":0.00000000},{"price":0.98098,"qty":4502.00000000},{"price":0.98004,"qty":4140.00000000}],"checksum":2270570738,"timestamp":"2024-06-01T22:44:04.897385Z"}]}
{"channel":"book","type":"update","data":[{"symbol":"EUR/CHF","bids":[{"price":0.97912,"qty":0.00000000},{"price":0.97884,"qty":21.41489245},{"price":0.97914,"qty":1512.90680387}],"asks":[],"checksum":3013863817,"timestamp":"2024-06-01T22:44:05.258007Z"}]}
{"channel":"book","type":"update","data":[{"symbol":"EUR/CHF","bids":[],"asks":[{"price":0.98032,"qty":0.00000000},{"price":0.98098,"qty":4502.00000000}],"checksum":3474647004,"timestamp":"2024-06-01T22:44:05.633006Z"}]}
{"channel":"book","type":"update","data":[{"symbol":"EUR/CHF","bids":[],"asks":[{"price":0.97986,"qty":0.00000000},{"price":0.98108,"qty":2003.00000000}],"checksum":3508123207,"timestamp":"2024-06-01T22:44:05.633022Z"}]}
{"channel":"book","type":"update","data":[{"symbol":"EUR/CHF","bids":[],"asks":[{"price":0.97988,"qty":0.00000000},{"price":0.98110,"qty":3605.00000000}],"checksum":2777878469,"timestamp":"2024-06-01T22:44:05.636419Z"}]}
{"channel":"book","type":"update","data":[{"symbol":"EUR/CHF","bids":[],"asks":[{"price":0.97985,"qty":0.00000000},{"price":0.98112,"qty":2004.00000000},{"price":0.98003,"qty":76.78614034}],"checksum":3265104447,"timestamp":"2024-06-01T22:44:05.636707Z"}]}
{"channel":"book","type":"update","data":[{"symbol":"EUR/CHF","bids":[],"asks":[{"price":0.98003,"qty":16157.74872694}],"checksum":3738523960,"timestamp":"2024-06-01T22:44:05.638402Z"}]}
{"channel":"book","type":"update","data":[{"symbol":"EUR/CHF","bids":[],"asks":[{"price":0.98032,"qty":12599.67729693}],"checksum":1260921377,"timestamp":"2024-06-01T22:44:05.638675Z"}]}
{"channel":"book","type":"update","data":[{"symbol":"EUR/CHF","bids":[],"asks":[{"price":0.97985,"qty":126.65802589}],"checksum":3612884648,"timestamp":"2024-06-01T22:44:05.641849Z"}]}
{"channel":"book","type":"update","data":[{"symbol":"EUR/CHF","bids":[],"asks":[{"price":0.98004,"qty":0.00000000},{"price":0.98108,"qty":2003.00000000},{"price":0.98002,"qty":4140.00000000}],"checksum":1374332958,"timestamp":"2024-06-01T22:44:05.659474Z"}]}
{"channel":"book","type":"update","data":[{"symbol":"EUR/CHF","bids":[{"price":0.97910,"qty":90.38744307}],"asks":[],"checksum":2887641957,"timestamp":"2024-06-01T22:44:06.018428Z"}]}
{"channel":"book","type":"update","data":[{"symbol":"EUR/CHF","bids":[{"price":0.97911,"qty":0.00000000},{"price":0.97884,"qty":21.41489245}],"asks":[],"checksum":2088865172,"timestamp":"2024-06-01T22:44:06.018486Z"}]}
{"channel":"book","type":"update","data":[{"symbol":"EUR/CHF","bids":[{"price":0.97915,"qty":10837.49043550}],"asks":[],"checksum":1923588173,"timestamp":"2024-06-01T22:44:06.019022Z"}]}
{"channel":"book","type":"update","data":[{"symbol":"EUR/CHF","bids":[{"price":0.97910,"qty":0.00000000},{"price":0.97884,"qty":21.41489245}],"asks":[],"checksum":2598506559,"timestamp":"2024-06-01T22:44:06.043510Z"}]}
{"channel":"book","type":"update","data":[{"symbol":"EUR/CHF","bids":[{"price":0.97915,"qty":10927.87787857}],"asks":[],"checksum":1761930851,"timestamp":"2024-06-01T22:44:06.045316Z"}]}
{"channel":"book","type":"update","data":[{"symbol":"EUR/CHF","bids":[{"price":0.97914,"qty":0.00000000},{"price":0.97883,"qty":1021.62786183},{"price":0.97916,"qty":1512.87563727}],"asks":[],"checksum":2100279721,"timestamp":"2024-06-01T22:44:06.084662Z"}]}
{"channel":"book","type":"update","data":[{"symbol":"EUR/CHF","bids":[],"asks":[{"price":0.98003,"qty":16080.96258660},{"price":0.98001,"qty":76.78614034}],"checksum":279979257,"timestamp":"2024-06-01T22:44:06.084738Z"}]}
{"channel":"book","type":"update","data":[{"symbol":"EUR/CHF","bids":[],"asks":[{"price":0.98002,"qty":0.00000000},{"price":0.98098,"qty":4502.00000000},{"price":0.98000,"qty":4140.00000000}],"checksum":3227804611,"timestamp":"2024-06-01T22:44:06.117175Z"}]}
{"channel":"book","type":"update","data":[{"symbol":"EUR/CHF","bids":[],"asks":[{"price":0.98005,"qty":0.00000000},{"price":0.98098,"qty":4502.00000000}],"checksum":4079144766,"timestamp":"2024-06-01T22:44:06.288071Z"}]}
{"channel":"book","type":"update","data":[{"symbol":"EUR/CHF","bids":[{"price":0.97901,"qty":10549.40118033}],"asks":[],"checksum":2749489773,"timestamp":"2024-06-01T22:44:06.288193Z"}]}
{"channel":"book","type":"update","data":[{"symbol":"EUR/CHF","bids":[{"price":0.97913,"qty":0.00000000},{"price":0.97884,"qty":21.41489245}],"asks":[],"checksum":2843316096,"timestamp":"2024-06-01T22:44:06.288381Z"}]}
{"channel":"book","type":"update","data":[{"symbol":"EUR/CHF","bids":[],"asks":[{"price":0.97999,"qty":175.24140000}],"checksum":2471019392,"timestamp":"2024-06-01T22:44:06.288448Z"}]}
{"channel":"book","type":"update","data":[{"symbol":"EUR/CHF","bids":[],"asks":[{"price":0.98000,"qty":0.00000000},{"price":0.98098,"qty":4502.00000000},{"price":0.97998,"qty":4140.00000000}],"checksum":3700944387,"timestamp":"2024-06-01T22:44:06.331020Z"}]}
{"channel":"book","type":"update","data":[{"symbol":"EUR/CHF","bids":[],"asks":[{"price":0.98001,"qty":0.00000000},{"price":0.98098,"qty":4502.00000000},{"price":0.97997,"qty":76.78994284}],"checksum":2834950699,"timestamp":"2024-06-01T22:44:06.934851Z"}]}
{"channel":"book","type":"update","data":[{"symbol":"EUR/CHF","bids":[],"asks":[{"price":0.97998,"qty":0.00000000},{"price":0.98098,"qty":4502.00000000},{"price":0.97996,"qty":4140.00000000}],"checksum":1483441311,"timestamp":"2024-06-01T22:44:06.967583Z"}]}
{"channel":"book","type":"update","data":[{"symbol":"EUR/CHF","bids":[],"asks":[{"price":0.97999,"qty":0.00000000},{"price":0.98098,"qty":4502.00000000}],"checksum":4275832759,"timestamp":"2024-06-01T22:44:07.283732Z"}]}
{"channel":"book","type":"update","data":[{"symbol":"EUR/CHF","bids":[],"asks":[{"price":0.97995,"qty":175.24140000}],"checksum":3377559416,"timestamp":"2024-06-01T22:44:07.283830Z"}]}
{"channel":"book","type":"update","data":[{"symbol":"EUR/CHF","bids":[],"asks":[{"price":0.97996,"qty":0.00000000},{"price":0.98098,"qty":4502.00000000},{"price":0.97994,"qty":4140.00000000}],"checksum":3672567568,"timestamp":"2024-06-01T22:44:07.302022Z"}]}
{"channel":"book","type":"update","data":[{"symbol":"EUR/CHF","bids":[],"asks":[{"price":0.97995,"qty":0.00000000},{"price":0.98098,"qty":4502.00000000}],"checksum":541580322,"timestamp":"2024-06-01T22:44:07.307150Z"}]}
{"channel":"book","type":"update","data":[{"symbol":"EUR/CHF","bids":[],"asks":[{"price":0.97993,"qty":175.24140000}],"checksum":79260534,"timestamp":"2024-06-01T22:44:07.307310Z"}]}
{"channel":"book","type":"update","data":[{"symbol":"EUR/CHF","bids":[],"asks":[{"price":0.97994,"qty":0.00000000},{"price":0.98098,"qty":4502.00000000},{"price":0.97992,"qty":4140.00000000}],"checksum":2055643033,"timestamp":"2024-06-01T22:44:07.333734Z"}]}
{"channel":"book","type":"update","data":[{"symbol":"EUR/CHF","bids":[],"asks":[{"price":0.98003,"qty":0.00000000},{"price":0.98098,"qty":4502.00000000}],"checksum":3737991835,"timestamp":"2024-06-01T22:44:07.675337Z"}]}
{"channel":"book","type":"update","data":[{"symbol":"EUR/CHF","bids":[],"asks":[{"price":0.97995,"qty":16080.96258659}],"checksum":3448458899,"timestamp":"2024-06-01T22:44:07.681360Z"}]}
{"channel":"book","type":"update","data":[{"symbol":"EUR/CHF","bids":[],"asks":[{"price":0.97997,"qty":0.00000000},{"price":0.98098,"qty":4502.00000000},{"price":0.97984,"qty":76.78989276}],"checksum":3390829646,"timestamp":"2024-06-01T22:44:07.741252Z"}]}
{"channel":"book","type":"update","data":[{"symbol":"EUR/CHF","bids":[{"price":0.97915,"qty":90.38744307}],"asks":[],"checksum":2196129983,"timestamp":"2024-06-01T22:44:08.086826Z"}]}
{"channel":"book","type":"update","data":[{"symbol":"EUR/CHF","bids":[{"price":0.97917,"qty":1843.75979497}],"asks":[],"checksum":3487121413,"timestamp":"2024-06-01T22:44:08.088083Z"}]}
{"channel":"book","type":"update","data":[{"symbol":"EUR/CHF","bids":[{"price":0.97902,"qty":10792.47676863}],"asks":[],"checksum":2471099856,"timestamp":"2024-06-01T22:44:08.088199Z"}]}
{"channel":"book","type":"update","data":[{"symbol":"EUR/CHF","bids":[{"price":0.97916,"qty":0.00000000},{"price":0.97890,"qty":1021.55480641},{"price":0.97902,"qty":12305.56653096}],"asks":[],"checksum":2337561984,"timestamp":"2024-06-01T22:44:08.090005Z"}]}
{"channel":"book","type":"update","data":[{"symbol":"EUR/CHF","bids":[],"asks":[{"price":0.97985,"qty":0.00000000},{"price":0.98098,"qty":4502.00000000}],"checksum":1165068211,"timestamp":"2024-06-01T22:44:08.137554Z"}]}
{"channel":"book","type":"update","data":[{"symbol":"EUR/CHF","bids":[],"asks":[{"price":0.97984,"qty":0.00000000},{"price":0.98108,"qty":2003.00000000},{"price":0.97991,"qty":76.78988861}],"checksum":1129411756,"timestamp":"2024-06-01T22:44:08.141169Z"}]}
