{"channel":"book","type":"snapshot","data":[{"symbol":"EUR/CAD","bids":[{"price":1.48104,"qty":4420.82154383},{"price":1.48103,"qty":215.66494264},{"price":1.47770,"qty":49.77700000},{"price":1.47511,"qty":3472.25630000},{"price":1.47510,"qty":1458.66895555},{"price":1.47334,"qty":10.46507585},{"price":1.47333,"qty":50.00000000},{"price":1.47010,"qty":500.18604176},{"price":1.47000,"qty":77.70000000},{"price":1.46918,"qty":5830.41355106}],"asks":[{"price":1.48372,"qty":175.24140000},{"price":1.48373,"qty":1619.21080079},{"price":1.48397,"qty":3238.42160159},{"price":1.48879,"qty":367.49218911},{"price":1.48880,"qty":50.00000000},{"price":1.48988,"qty":12955.04515525},{"price":1.49000,"qty":55.99990000},{"price":1.49123,"qty":50.69794167},{"price":1.49486,"qty":5.00000000},{"price":1.49500,"qty":79.00000000}],"checksum":2681005353}]}
{"channel":"book","type":"update","data":[{"symbol":"EUR/CAD","bids":[],"asks":[{"price":1.48373,"qty":0.00000000},{"price":1.49838,"qty":6476.74875184}],"checksum":2979501761,"timestamp":"2024-06-01T22:43:37.042410Z"}]}
{"channel":"book","type":"update","data":[{"symbol":"EUR/CAD","bids":[],"asks":[{"price":1.48372,"qty":0.00000000},{"price":1.50000,"qty":30.00000000}],"checksum":376938983,"timestamp":"2024-06-01T22:43:37.055388Z"}]}
{"channel":"book","type":"update","data":[{"symbol":"EUR/CAD","bids":[],"asks":[{"price":1.48396,"qty":175.24140000}],"checksum":3021163864,"timestamp":"2024-06-01T22:43:37.055633Z"}]}
{"channel":"book","type":"update","data":[{"symbol":"EUR/CAD","bids":[],"asks":[{"price":1.48371,"qty":1619.21080079}],"checksum":20894395,"timestamp":"2024-06-01T22:43:37.082615Z"}]}
{"channel":"book","type":"update","data":[{"symbol":"EUR/CAD","bids":[],"asks":[{"price":1.48396,"qty":0.00000000},{"price":1.49838,"qty":6476.74875184}],"checksum":3249015216,"timestamp":"2024-06-01T22:43:37.116796Z"}]}
{"channel":"book","type":"update","data":[{"symbol":"EUR/CAD","bids":[],"asks":[{"price":1.48370,"qty":175.24140000}],"checksum":554872621,"timestamp":"2024-06-01T22:43:37.116811Z"}]}
{"channel":"book","type":"update","data":[{"symbol":"EUR/CAD","bids":[{"price":1.48105,"qty":587.39720776}],"asks":[],"checksum":80923538,"timestamp":"2024-06-01T22:43:37.119179Z"}]}
{"channel":"book","type":"update","data":[{"symbol":"EUR/CAD","bids":[{"price":1.48104,"qty":0.00000000},{"price":1.46918,"qty":5830.41355106}],"asks":[],"checksum":1272750883,"timestamp":"2024-06-01T22:43:37.137985Z"}]}
{"channel":"book","type":"update","data":[{"symbol":"EUR/CAD","bids":[{"price":1.48106,"qty":4420.76183949}],"asks":[],"checksum":856188195,"timestamp":"2024-06-01T22:43:37.138368Z"}]}
{"channel":"book","type":"update","data":[{"symbol":"EUR/CAD","bids":[{"price":1.48105,"qty":0.00000000},{"price":1.46918,"qty":5830.41355106}],"asks":[],"checksum":1860364763,"timestamp":"2024-06-01T22:43:37.218728Z"}]}
{"channel":"book","type":"update","data":[{"symbol":"EUR/CAD","bids":[{"price":1.48107,"qty":572.56910381}],"asks":[],"checksum":1719319137,"timestamp":"2024-06-01T22:43:37.318976Z"}]}
{"channel":"book","type":"update","data":[{"symbol":"EUR/CAD","bids":[{"price":1.48106,"qty":0.00000000},{"price":1.46918,"qty":5830.41355106}],"asks":[],"checksum":1350512237,"timestamp":"2024-06-01T22:43:37.343827Z"}]}
{"channel":"book","type":"update","data":[{"symbol":"EUR/CAD","bids":[{"price":1.48108,"qty":4420.70213677}],"asks":[],"checksum":590843403,"timestamp":"2024-06-01T22:43:37.343937Z"}]}
{"channel":"book","type":"update","data":[{"symbol":"EUR/CAD","bids":[{"price":1.48107,"qty":0.00000000},{"price":1.46918,"qty":5830.41355106}],"asks":[],"checksum":2667023910,"timestamp":"2024-06-01T22:43:37.419085Z"}]}
{"channel":"book","type":"update","data":[{"symbol":"EUR/CAD","bids":[{"price":1.48109,"qty":603.99942912}],"asks":[],"checksum":1822306353,"timestamp":"2024-06-01T22:43:39.568304Z"}]}
{"channel":"book","type":"update","data":[{"symbol":"EUR/CAD","bids":[{"price":1.48108,"qty":0.00000000},{"price":1.46918,"qty":5830.41355106}],"asks":[],"checksum":3736623292,"timestamp":"2024-06-01T22:43:39.606963Z"}]}
{"channel":"book","type":"update","data":[{"symbol":"EUR/CAD","bids":[{"price":1.48110,"qty":4420.64247201}],"asks":[],"checksum":655315454,"timestamp":"2024-06-01T22:43:39.607188Z"}]}
{"channel":"book","type":"update","data":[{"symbol":"EUR/CAD","bids":[{"price":1.48109,"qty":0.00000000},{"price":1.46918,"qty":5830.41355106}],"asks":[],"checksum":247065707,"timestamp":"2024-06-01T22:43:39.620954Z"}]}
{"channel":"book","type":"update","data":[{"symbol":"EUR/CAD","bids":[],"asks":[{"price":1.48371,"qty":0.00000000},{"price":1.49838,"qty":6476.74875184}],"checksum":171426294,"timestamp":"2024-06-01T22:43:41.723100Z"}]}
{"channel":"book","type":"update","data":[{"symbol":"EUR/CAD","bids":[],"asks":[{"price":1.48370,"qty":0.00000000},{"price":1.50000,"qty":30.00000000}],"checksum":970777249,"timestamp":"2024-06-01T22:43:41.752167Z"}]}
{"channel":"book","type":"update","data":[{"symbol":"EUR/CAD","bids":[],"asks":[{"price":1.48396,"qty":175.24140000}],"checksum":2612530718,"timestamp":"2024-06-01T22:43:41.752302Z"}]}
{"channel":"book","type":"update","data":[{"symbol":"EUR/CAD","bids":[],"asks":[{"price":1.48369,"qty":1619.21080079}],"checksum":14806949,"timestamp":"2024-06-01T22:43:41.763211Z"}]}
{"channel":"book","type":"update","data":[{"symbol":"EUR/CAD","bids":[],"asks":[{"price":1.48396,"qty":0.00000000},{"price":1.49838,"qty":6476.74875184}],"checksum":2342381390,"timestamp":"2024-06-01T22:43:41.779157Z"}]}
{"channel":"book","type":"update","data":[{"symbol":"EUR/CAD","bids":[],"asks":[{"price":1.48368,"qty":175.24140000}],"checksum":1979891889,"timestamp":"2024-06-01T22:43:41.779452Z"}]}
{"channel":"book","type":"update","data":[{"symbol":"EUR/CAD","bids":[{"price":1.48111,"qty":596.54293826}],"asks":[],"checksum":1467470069,"timestamp":"2024-06-01T22:43:41.823420Z"}]}
{"channel":"book","type":"update","data":[{"symbol":"EUR/CAD","bids":[{"price":1.48110,"qty":0.00000000},{"price":1.46918,"qty":5830.41355106}],"asks":[],"checksum":4149784087,"timestamp":"2024-06-01T22:43:41.846050Z"}]}
{"channel":"book","type":"update","data":[{"symbol":"EUR/CAD","bids":[{"price":1.48112,"qty":4420.58275801}],"asks":[],"checksum":2917472588,"timestamp":"2024-06-01T22:43:41.846254Z"}]}
{"channel":"book","type":"update","data":[{"symbol":"EUR/CAD","bids":[{"price":1.48111,"qty":0.00000000},{"price":1.46918,"qty":5830.41355106}],"asks":[],"checksum":2302493997,"timestamp":"2024-06-01T22:43:41.923346Z"}]}
{"channel":"book","type":"update","data":[{"symbol":"EUR/CAD","bids":[{"price":1.48113,"qty":580.35159514}],"asks":[],"checksum":4126361434,"timestamp":"2024-06-01T22:43:44.571020Z"}]}
{"channel":"book","type":"update","data":[{"symbol":"EUR/CAD","bids":[{"price":1.48112,"qty":0.00000000},{"price":1.46918,"qty":5830.41355106}],"asks":[],"checksum":699794696,"timestamp":"2024-06-01T22:43:44.580881Z"}]}
{"channel":"book","type":"update","data":[{"symbol":"EUR/CAD","bids":[{"price":1.48114,"qty":4420.52306260}],"asks":[],"checksum":1710619712,"timestamp":"2024-06-01T22:43:44.581117Z"}]}
{"channel":"book","type":"update","data":[{"symbol":"EUR/CAD","bids":[{"price":1.48113,"qty":0.00000000},{"price":1.46918,"qty":5830.41355106}],"asks":[],"checksum":297622581,"timestamp":"2024-06-01T22:43:44.626370Z"}]}
{"channel":"book","type":"update","data":[{"symbol":"EUR/CAD","bids":[{"price":1.48114,"qty":0.00000000},{"price":1.46889,"qty":5.00000000}],"asks":[],"checksum":2420139312,"timestamp":"2024-06-01T22:43:44.658533Z"}]}
{"channel":"book","type":"update","data":[{"symbol":"EUR/CAD","bids":[{"price":1.48104,"qty":4420.82153652}],"asks":[],"checksum":1028137602,"timestamp":"2024-06-01T22:43:44.658567Z"}]}
{"channel":"book","type":"update","data":[{"symbol":"EUR/CAD","bids":[],"asks":[{"price":1.48369,"qty":0.00000000},{"price":1.49838,"qty":6476.74875184}],"checksum":1862884765,"timestamp":"2024-06-01T22:43:46.261979Z"}]}
{"channel":"book","type":"update","data":[{"symbol":"EUR/CAD","bids":[],"asks":[{"price":1.48396,"qty":175.24140000}],"checksum":2682822975,"timestamp":"2024-06-01T22:43:46.276298Z"}]}
{"channel":"book","type":"update","data":[{"symbol":"EUR/CAD","bids":[],"asks":[{"price":1.48368,"qty":0.00000000},{"price":1.49838,"qty":6476.74875184}],"checksum":3505581101,"timestamp":"2024-06-01T22:43:46.276349Z"}]}
{"channel":"book","type":"update","data":[{"symbol":"EUR/CAD","bids":[],"asks":[{"price":1.48367,"qty":1619.21080079}],"checksum":293104707,"timestamp":"2024-06-01T22:43:46.302452Z"}]}
{"channel":"book","type":"update","data":[{"symbol":"EUR/CAD","bids":[],"asks":[{"price":1.48396,"qty":0.00000000},{"price":1.49838,"qty":6476.74875184}],"checksum":909439047,"timestamp":"2024-06-01T22:43:46.315888Z"}]}
{"channel":"book","type":"update","data":[{"symbol":"EUR/CAD","bids":[],"asks":[{"price":1.48366,"qty":175.24140000}],"checksum":3014776860,"timestamp":"2024-06-01T22:43:46.316104Z"}]}
{"channel":"book","type":"update","data":[{"symbol":"EUR/CAD","bids":[{"price":1.48105,"qty":565.24777118}],"asks":[],"checksum":530589078,"timestamp":"2024-06-01T22:43:46.328195Z"}]}
{"channel":"book","type":"update","data":[{"symbol":"EUR/CAD","bids":[{"price":1.48104,"qty":0.00000000},{"price":1.46918,"qty":5830.41355106}],"asks":[],"checksum":2513865717,"timestamp":"2024-06-01T22:43:46.344243Z"}]}
{"channel":"book","type":"update","data":[{"symbol":"EUR/CAD","bids":[{"price":1.48106,"qty":4420.76187888}],"asks":[],"checksum":2010110277,"timestamp":"2024-06-01T22:43:46.344347Z"}]}
{"channel":"book","type":"update","data":[{"symbol":"EUR/CAD","bids":[{"price":1.48105,"qty":0.00000000},{"price":1.46918,"qty":5830.41355106}],"asks":[],"checksum":3445254496,"timestamp":"2024-06-01T22:43:46.427927Z"}]}
{"channel":"book","type":"update","data":[{"symbol":"EUR/CAD","bids":[],"asks":[{"price":1.48367,"qty":0.00000000},{"price":1.49837,"qty":6476.74875457}],"checksum":2664895916,"timestamp":"2024-06-01T22:43:50.822265Z"}]}
{"channel":"book","type":"update","data":[{"symbol":"EUR/CAD","bids":[],"asks":[{"price":1.48878,"qty":14.62174743}],"checksum":3097419233,"timestamp":"2024-06-01T22:43:50.825565Z"}]}
{"channel":"book","type":"update","data":[{"symbol":"EUR/CAD","bids":[{"price":1.48107,"qty":563.27629858}],"asks":[],"checksum":1628532635,"timestamp":"2024-06-01T22:43:50.831994Z"}]}
{"channel":"book","type":"update","data":[{"symbol":"EUR/CAD","bids":[],"asks":[{"price":1.48396,"qty":175.24140000}],"checksum":4256180427,"timestamp":"2024-06-01T22:43:50.841674Z"}]}
{"channel":"book","type":"update","data":[{"symbol":"EUR/CAD","bids":[{"price":1.48106,"qty":0.00000000},{"price":1.46918,"qty":5830.41355106}],"asks":[],"checksum":1685991820,"timestamp":"2024-06-01T22:43:50.841751Z"}]}
{"channel":"book","type":"update","data":[{"symbol":"EUR/CAD","bids":[],"asks":[{"price":1.48366,"qty":0.00000000},{"price":1.49500,"qty":79.00000000}],"checksum":3748877335,"timestamp":"2024-06-01T22:43:50.841769Z"}]}
{"channel":"book","type":"update","data":[{"symbol":"EUR/CAD","bids":[{"price":1.48108,"qty":4420.70212758}],"asks":[],"checksum":270323011,"timestamp":"2024-06-01T22:43:50.841868Z"}]}
{"channel":"book","type":"update","data":[{"symbol":"EUR/CAD","bids":[],"asks":[{"price":1.48365,"qty":1619.21080079}],"checksum":2188496492,"timestamp":"2024-06-01T22:43:50.862417Z"}]}
{"channel":"book","type":"update","data":[{"symbol":"EUR/CAD","bids":[],"asks":[{"price":1.48396,"qty":0.00000000},{"price":1.49500,"qty":79.00000000}],"checksum":2384446449,"timestamp":"2024-06-01T22:43:50.872094Z"}]}
{"channel":"book","type":"update","data":[{"symbol":"EUR/CAD","bids":[],"asks":[{"price":1.48364,"qty":175.24140000}],"checksum":2529231540,"timestamp":"2024-06-01T22:43:50.872151Z"}]}
{"channel":"book","type":"update","data":[{"symbol":"EUR/CAD","bids":[{"price":1.48107,"qty":0.00000000},{"price":1.46918,"qty":5830.41355106}],"asks":[],"checksum":3023246469,"timestamp":"2024-06-01T22:43:50.931967Z"}]}
{"channel":"book","type":"update","data":[{"symbol":"EUR/CAD","bids":[{"price":1.48109,"qty":578.28403858}],"asks":[],"checksum":1024459292,"timestamp":"2024-06-01T22:43:51.032441Z"}]}
{"channel":"book","type":"update","data":[{"symbol":"EUR/CAD","bids":[{"price":1.48108,"qty":0.00000000},{"price":1.46918,"qty":5830.41355106}],"asks":[],"checksum":3436559661,"timestamp":"2024-06-01T22:43:51.035005Z"}]}
{"channel":"book","type":"update","data":[{"symbol":"EUR/CAD","bids":[{"price":1.48110,"qty":4420.64248415}],"asks":[],"checksum":2643706556,"timestamp":"2024-06-01T22:43:51.035500Z"}]}
