{"channel":"book","type":"snapshot","data":[{"symbol":"GBP/USD","bids":[{"price":1.27461,"qty":2153.34170350},{"price":1.27460,"qty":301.68169626},{"price":1.27458,"qty":2694.16075591},{"price":1.27452,"qty":1961.51856367},{"price":1.27438,"qty":3818.67840942},{"price":1.27437,"qty":3923.50730164},{"price":1.27420,"qty":19.62015382},{"price":1.27419,"qty":291.47481929},{"price":1.27418,"qty":509.38310000},{"price":1.27395,"qty":14540.74651318}],"asks":[{"price":1.27468,"qty":90.90000000},{"price":1.27469,"qty":3442.07637856},{"price":1.27477,"qty":900.60000000},{"price":1.27478,"qty":1961.12629919},{"price":1.27503,"qty":1388.66460316},{"price":1.27504,"qty":4632.28657759},{"price":1.27507,"qty":387.13500000},{"price":1.27509,"qty":3921.30483545},{"price":1.27533,"qty":509.38310000},{"price":1.27544,"qty":35151.61012100}],"checksum":3795723540}]}
{"channel":"book","type":"update","data":[{"symbol":"GBP/USD","bids":[{"price":1.27458,"qty":0.00000000},{"price":1.27394,"qty":9669.49354296}],"asks":[],"checksum":3072851821,"timestamp":"2024-06-01T22:41:57.811026Z"}]}
{"channel":"book","type":"update","data":[{"symbol":"GBP/USD","bids":[{"price":1.27394,"qty":0.00000000},{"price":1.27393,"qty":601.92255534}],"asks":[],"checksum":4226363707,"timestamp":"2024-06-01T22:41:57.811041Z"}]}
{"channel":"book","type":"update","data":[{"symbol":"GBP/USD","bids":[{"price":1.27395,"qty":0.00000000},{"price":1.27391,"qty":3924.89588349}],"asks":[],"checksum":2222328701,"timestamp":"2024-06-01T22:41:57.814812Z"}]}
{"channel":"book","type":"update","data":[{"symbol":"GBP/USD","bids":[{"price":1.27396,"qty":14071.25750468}],"asks":[],"checksum":3421139253,"timestamp":"2024-06-01T22:41:57.816255Z"}]}
{"channel":"book","type":"update","data":[{"symbol":"GBP/USD","bids":[{"price":1.27397,"qty":14540.74651318}],"asks":[],"checksum":2737799168,"timestamp":"2024-06-01T22:41:57.859375Z"}]}
{"channel":"book","type":"update","data":[{"symbol":"GBP/USD","bids":[],"asks":[{"price":1.27504,"qty":0.00000000},{"price":1.27545,"qty":3920.19258238}],"checksum":3075132713,"timestamp":"2024-06-01T22:41:58.656783Z"}]}
{"channel":"book","type":"update","data":[{"symbol":"GBP/USD","bids":[],"asks":[{"price":1.27544,"qty":0.00000000},{"price":1.27547,"qty":29222.00000000}],"checksum":25223131,"timestamp":"2024-06-01T22:41:58.656882Z"}]}
{"channel":"book","type":"update","data":[{"symbol":"GBP/USD","bids":[],"asks":[{"price":1.27544,"qty":36715.83134905}],"checksum":2782619897,"timestamp":"2024-06-01T22:41:58.657516Z"}]}
{"channel":"book","type":"update","data":[{"symbol":"GBP/USD","bids":[],"asks":[{"price":1.27502,"qty":3100.96483999}],"checksum":2782350887,"timestamp":"2024-06-01T22:41:58.657613Z"}]}
{"channel":"book","type":"update","data":[{"symbol":"GBP/USD","bids":[],"asks":[{"price":1.27503,"qty":0.00000000},{"price":1.27545,"qty":3920.19258238},{"price":1.27506,"qty":1388.65938064}],"checksum":755449529,"timestamp":"2024-06-01T22:41:58.660161Z"}]}
{"channel":"book","type":"update","data":[{"symbol":"GBP/USD","bids":[],"asks":[{"price":1.27506,"qty":0.00000000},{"price":1.27545,"qty":3920.19258238},{"price":1.27501,"qty":1388.65938064}],"checksum":3415276792,"timestamp":"2024-06-01T22:41:58.665315Z"}]}
{"channel":"book","type":"update","data":[{"symbol":"GBP/USD","bids":[],"asks":[{"price":1.27502,"qty":0.00000000},{"price":1.27545,"qty":3920.19258238}],"checksum":2822643883,"timestamp":"2024-06-01T22:42:00.731790Z"}]}
{"channel":"book","type":"update","data":[{"symbol":"GBP/USD","bids":[],"asks":[{"price":1.27500,"qty":3100.96484000}],"checksum":1091956188,"timestamp":"2024-06-01T22:42:00.732997Z"}]}
{"channel":"book","type":"update","data":[{"symbol":"GBP/USD","bids":[],"asks":[{"price":1.27501,"qty":0.00000000},{"price":1.27545,"qty":3920.19258238},{"price":1.27506,"qty":1388.65940392}],"checksum":139671558,"timestamp":"2024-06-01T22:42:00.735040Z"}]}
{"channel":"book","type":"update","data":[{"symbol":"GBP/USD","bids":[],"asks":[{"price":1.27506,"qty":0.00000000},{"price":1.27545,"qty":3920.19258238},{"price":1.27499,"qty":1388.65940392}],"checksum":3108796562,"timestamp":"2024-06-01T22:42:00.737929Z"}]}
{"channel":"book","type":"update","data":[{"symbol":"GBP/USD","bids":[{"price":1.27396,"qty":0.00000000},{"price":1.27393,"qty":601.92255534}],"asks":[],"checksum":2887646703,"timestamp":"2024-06-01T22:42:01.273820Z"}]}
{"channel":"book","type":"update","data":[{"symbol":"GBP/USD","bids":[{"price":1.27397,"qty":0.00000000},{"price":1.27391,"qty":3924.89588349}],"asks":[],"checksum":1624128537,"timestamp":"2024-06-01T22:42:01.277333Z"}]}
{"channel":"book","type":"update","data":[{"symbol":"GBP/USD","bids":[{"price":1.27398,"qty":12905.60365312}],"asks":[],"checksum":2883755835,"timestamp":"2024-06-01T22:42:01.278662Z"}]}
{"channel":"book","type":"update","data":[{"symbol":"GBP/USD","bids":[{"price":1.27399,"qty":14540.74651318}],"asks":[],"checksum":337354500,"timestamp":"2024-06-01T22:42:01.385966Z"}]}
{"channel":"book","type":"update","data":[{"symbol":"GBP/USD","bids":[],"asks":[{"price":1.27500,"qty":0.00000000},{"price":1.27545,"qty":3920.19258238}],"checksum":3324211612,"timestamp":"2024-06-01T22:42:02.819194Z"}]}
{"channel":"book","type":"update","data":[{"symbol":"GBP/USD","bids":[],"asks":[{"price":1.27498,"qty":1605.53345563}],"checksum":2856441528,"timestamp":"2024-06-01T22:42:02.819465Z"}]}
{"channel":"book","type":"update","data":[{"symbol":"GBP/USD","bids":[],"asks":[{"price":1.27499,"qty":0.00000000},{"price":1.27545,"qty":3920.19258238},{"price":1.27506,"qty":1388.68090949}],"checksum":2551185260,"timestamp":"2024-06-01T22:42:02.822490Z"}]}
{"channel":"book","type":"update","data":[{"symbol":"GBP/USD","bids":[],"asks":[{"price":1.27506,"qty":0.00000000},{"price":1.27545,"qty":3920.19258238},{"price":1.27497,"qty":1388.68090949}],"checksum":1346441499,"timestamp":"2024-06-01T22:42:02.825508Z"}]}
{"channel":"book","type":"update","data":[{"symbol":"GBP/USD","bids":[{"price":1.27398,"qty":0.00000000},{"price":1.27393,"qty":601.92255534}],"asks":[],"checksum":2162666489,"timestamp":"2024-06-01T22:42:04.675124Z"}]}
{"channel":"book","type":"update","data":[{"symbol":"GBP/USD","bids":[{"price":1.27438,"qty":0.00000000},{"price":1.27391,"qty":3924.89588349}],"asks":[],"checksum":1673033576,"timestamp":"2024-06-01T22:42:04.675158Z"}]}
{"channel":"book","type":"update","data":[{"symbol":"GBP/USD","bids":[{"price":1.27399,"qty":0.00000000},{"price":1.27380,"qty":818.32721381}],"asks":[],"checksum":685826188,"timestamp":"2024-06-01T22:42:04.678655Z"}]}
{"channel":"book","type":"update","data":[{"symbol":"GBP/USD","bids":[{"price":1.27438,"qty":5046.09848586}],"asks":[],"checksum":2728496326,"timestamp":"2024-06-01T22:42:04.680097Z"}]}
{"channel":"book","type":"update","data":[{"symbol":"GBP/USD","bids":[{"price":1.27400,"qty":10421.72745446}],"asks":[],"checksum":3858006473,"timestamp":"2024-06-01T22:42:04.680213Z"}]}
{"channel":"book","type":"update","data":[{"symbol":"GBP/USD","bids":[{"price":1.27401,"qty":14540.74651318}],"asks":[],"checksum":471763074,"timestamp":"2024-06-01T22:42:04.707800Z"}]}
{"channel":"book","type":"update","data":[{"symbol":"GBP/USD","bids":[],"asks":[{"price":1.27498,"qty":0.00000000},{"price":1.27545,"qty":3920.19258238}],"checksum":2714610561,"timestamp":"2024-06-01T22:42:04.917629Z"}]}
{"channel":"book","type":"update","data":[{"symbol":"GBP/USD","bids":[],"asks":[{"price":1.27506,"qty":1605.53345563}],"checksum":2364749785,"timestamp":"2024-06-01T22:42:04.917981Z"}]}
{"channel":"book","type":"update","data":[{"symbol":"GBP/USD","bids":[],"asks":[{"price":1.27497,"qty":0.00000000},{"price":1.27545,"qty":3920.19258238},{"price":1.27506,"qty":2994.23085680}],"checksum":178089809,"timestamp":"2024-06-01T22:42:04.920871Z"}]}
{"channel":"book","type":"update","data":[{"symbol":"GBP/USD","bids":[],"asks":[{"price":1.27506,"qty":1605.53345563},{"price":1.27505,"qty":1388.69740117}],"checksum":3803400177,"timestamp":"2024-06-01T22:42:04.923672Z"}]}
{"channel":"book","type":"update","data":[{"symbol":"GBP/USD","bids":[],"asks":[{"price":1.27544,"qty":0.00000000},{"price":1.27545,"qty":3920.19258238}],"checksum":1805689591,"timestamp":"2024-06-01T22:42:06.991805Z"}]}
{"channel":"book","type":"update","data":[{"symbol":"GBP/USD","bids":[],"asks":[{"price":1.27506,"qty":0.00000000},{"price":1.27547,"qty":29222.00000000}],"checksum":1809214603,"timestamp":"2024-06-01T22:42:06.991847Z"}]}
{"channel":"book","type":"update","data":[{"symbol":"GBP/USD","bids":[],"asks":[{"price":1.27504,"qty":4632.28657759}],"checksum":729172942,"timestamp":"2024-06-01T22:42:06.992194Z"}]}
{"channel":"book","type":"update","data":[{"symbol":"GBP/USD","bids":[],"asks":[{"price":1.27544,"qty":35151.61012100}],"checksum":1302931716,"timestamp":"2024-06-01T22:42:06.992223Z"}]}
{"channel":"book","type":"update","data":[{"symbol":"GBP/USD","bids":[],"asks":[{"price":1.27505,"qty":0.00000000},{"price":1.27545,"qty":3920.19258238},{"price":1.27506,"qty":1388.69500490}],"checksum":239753273,"timestamp":"2024-06-01T22:42:06.995197Z"}]}
{"channel":"book","type":"update","data":[{"symbol":"GBP/USD","bids":[],"asks":[{"price":1.27506,"qty":0.00000000},{"price":1.27545,"qty":3920.19258238},{"price":1.27503,"qty":1388.69500490}],"checksum":290869043,"timestamp":"2024-06-01T22:42:06.998377Z"}]}
{"channel":"book","type":"update","data":[{"symbol":"GBP/USD","bids":[{"price":1.27400,"qty":0.00000000},{"price":1.27393,"qty":601.92255534}],"asks":[],"checksum":3433940585,"timestamp":"2024-06-01T22:42:08.102251Z"}]}
{"channel":"book","type":"update","data":[{"symbol":"GBP/USD","bids":[{"price":1.27402,"qty":9345.16753867}],"asks":[],"checksum":710792221,"timestamp":"2024-06-01T22:42:08.104788Z"}]}
{"channel":"book","type":"update","data":[{"symbol":"GBP/USD","bids":[{"price":1.27401,"qty":0.00000000},{"price":1.27393,"qty":601.92255534}],"asks":[],"checksum":4001987588,"timestamp":"2024-06-01T22:42:08.105894Z"}]}
{"channel":"book","type":"update","data":[{"symbol":"GBP/USD","bids":[],"asks":[{"price":1.27504,"qty":0.00000000},{"price":1.27545,"qty":3920.19258238}],"checksum":1242549647,"timestamp":"2024-06-01T22:42:09.106856Z"}]}
{"channel":"book","type":"update","data":[{"symbol":"GBP/USD","bids":[],"asks":[{"price":1.27544,"qty":0.00000000},{"price":1.27547,"qty":29222.00000000}],"checksum":2952077720,"timestamp":"2024-06-01T22:42:09.106931Z"}]}
{"channel":"book","type":"update","data":[{"symbol":"GBP/USD","bids":[],"asks":[{"price":1.27544,"qty":32126.35243042}],"checksum":3507418155,"timestamp":"2024-06-01T22:42:09.108142Z"}]}
{"channel":"book","type":"update","data":[{"symbol":"GBP/USD","bids":[],"asks":[{"price":1.27502,"qty":3100.96483999}],"checksum":1797671773,"timestamp":"2024-06-01T22:42:09.108309Z"}]}
{"channel":"book","type":"update","data":[{"symbol":"GBP/USD","bids":[{"price":1.27403,"qty":14540.74651318}],"asks":[],"checksum":2595638699,"timestamp":"2024-06-01T22:42:09.110099Z"}]}
{"channel":"book","type":"update","data":[{"symbol":"GBP/USD","bids":[],"asks":[{"price":1.27503,"qty":0.00000000},{"price":1.27545,"qty":3920.19258238},{"price":1.27506,"qty":1388.69682112}],"checksum":1636252525,"timestamp":"2024-06-01T22:42:09.110289Z"}]}
{"channel":"book","type":"update","data":[{"symbol":"GBP/USD","bids":[],"asks":[{"price":1.27506,"qty":0.00000000},{"price":1.27545,"qty":3920.19258238},{"price":1.27501,"qty":1388.69682112}],"checksum":766786005,"timestamp":"2024-06-01T22:42:09.113261Z"}]}
{"channel":"book","type":"update","data":[{"symbol":"GBP/USD","bids":[{"price":1.27461,"qty":0.00000000},{"price":1.27393,"qty":601.92255534},{"price":1.27453,"qty":2152.54984375}],"asks":[],"checksum":3628350484,"timestamp":"2024-06-01T22:42:09.200600Z"}]}
{"channel":"book","type":"update","data":[{"symbol":"GBP/USD","bids":[{"price":1.27453,"qty":0.00000000},{"price":1.27393,"qty":601.92255534},{"price":1.27461,"qty":2152.41474048}],"asks":[],"checksum":535644626,"timestamp":"2024-06-01T22:42:09.205457Z"}]}
{"channel":"book","type":"update","data":[{"symbol":"GBP/USD","bids":[{"price":1.27461,"qty":0.00000000},{"price":1.27393,"qty":601.92255534},{"price":1.27453,"qty":2152.54984375}],"asks":[],"checksum":3628350484,"timestamp":"2024-06-01T22:42:09.228005Z"}]}
{"channel":"book","type":"update","data":[{"symbol":"GBP/USD","bids":[{"price":1.27453,"qty":0.00000000},{"price":1.27393,"qty":601.92255534},{"price":1.27461,"qty":2152.41474048}],"asks":[],"checksum":535644626,"timestamp":"2024-06-01T22:42:09.312469Z"}]}
{"channel":"book","type":"update","data":[{"symbol":"GBP/USD","bids":[{"price":1.27461,"qty":0.00000000},{"price":1.27393,"qty":601.92255534},{"price":1.27453,"qty":2152.54993108}],"asks":[],"checksum":1992239486,"timestamp":"2024-06-01T22:42:09.332165Z"}]}
{"channel":"book","type":"update","data":[{"symbol":"GBP/USD","bids":[{"price":1.27454,"qty":301.68169626}],"asks":[],"checksum":3351372084,"timestamp":"2024-06-01T22:42:09.364819Z"}]}
{"channel":"book","type":"update","data":[{"symbol":"GBP/USD","bids":[{"price":1.27453,"qty":0.00000000},{"price":1.27402,"qty":9345.16753867},{"price":1.27461,"qty":2152.41482780}],"asks":[],"checksum":941093721,"timestamp":"2024-06-01T22:42:09.367748Z"}]}
{"channel":"book","type":"update","data":[{"symbol":"GBP/USD","bids":[{"price":1.27460,"qty":0.00000000},{"price":1.27402,"qty":9345.16753867}],"asks":[],"checksum":1287527411,"timestamp":"2024-06-01T22:42:09.534617Z"}]}
{"channel":"book","type":"update","data":[{"symbol":"GBP/USD","bids":[{"price":1.27461,"qty":0.00000000},{"price":1.27393,"qty":601.92255534},{"price":1.27455,"qty":2152.51621242}],"asks":[],"checksum":2828098252,"timestamp":"2024-06-01T22:42:09.537766Z"}]}
{"channel":"book","type":"update","data":[{"symbol":"GBP/USD","bids":[],"asks":[{"price":1.27507,"qty":0.00000000},{"price":1.27545,"qty":3920.19258238}],"checksum":2894184953,"timestamp":"2024-06-01T22:42:10.845326Z"}]}
{"channel":"book","type":"update","data":[{"symbol":"GBP/USD","bids":[],"asks":[{"price":1.27532,"qty":387.13500000}],"checksum":1818740433,"timestamp":"2024-06-01T22:42:10.845641Z"}]}
{"channel":"book","type":"update","data":[{"symbol":"GBP/USD","bids":[],"asks":[{"price":1.27544,"qty":0.00000000},{"price":1.27545,"qty":3920.19258238}],"checksum":1118816616,"timestamp":"2024-06-01T22:42:11.167826Z"}]}
{"channel":"book","type":"update","data":[{"symbol":"GBP/USD","bids":[],"asks":[{"price":1.27502,"qty":0.00000000},{"price":1.27547,"qty":29222.00000000}],"checksum":3832720126,"timestamp":"2024-06-01T22:42:11.168007Z"}]}
{"channel":"book","type":"update","data":[{"symbol":"GBP/USD","bids":[],"asks":[{"price":1.27500,"qty":3100.96483999}],"checksum":4251415470,"timestamp":"2024-06-01T22:42:11.169022Z"}]}
{"channel":"book","type":"update","data":[{"symbol":"GBP/USD","bids":[],"asks":[{"price":1.27544,"qty":36715.83134905}],"checksum":1261972540,"timestamp":"2024-06-01T22:42:11.169101Z"}]}
{"channel":"book","type":"update","data":[{"symbol":"GBP/USD","bids":[],"asks":[{"price":1.27501,"qty":0.00000000},{"price":1.27545,"qty":3920.19258238},{"price":1.27508,"qty":1388.70339613}],"checksum":2064386298,"timestamp":"2024-06-01T22:42:11.171674Z"}]}
{"channel":"book","type":"update","data":[{"symbol":"GBP/USD","bids":[],"asks":[{"price":1.27508,"qty":0.00000000},{"price":1.27545,"qty":3920.19258238},{"price":1.27499,"qty":1388.70339613}],"checksum":1330661263,"timestamp":"2024-06-01T22:42:11.174289Z"}]}
{"channel":"book","type":"update","data":[{"symbol":"GBP/USD","bids":[{"price":1.27402,"qty":0.00000000},{"price":1.27393,"qty":601.92255534}],"asks":[],"checksum":1159434638,"timestamp":"2024-06-01T22:42:11.476979Z"}]}
{"channel":"book","type":"update","data":[{"symbol":"GBP/USD","bids":[{"price":1.27438,"qty":0.00000000},{"price":1.27391,"qty":3924.89588349}],"asks":[],"checksum":873397539,"timestamp":"2024-06-01T22:42:11.477082Z"}]}
{"channel":"book","type":"update","data":[{"symbol":"GBP/USD","bids":[{"price":1.27403,"qty":0.00000000},{"price":1.27380,"qty":818.32721381}],"asks":[],"checksum":2465029511,"timestamp":"2024-06-01T22:42:11.480500Z"}]}
{"channel":"book","type":"update","data":[{"symbol":"GBP/USD","bids":[{"price":1.27456,"qty":3902.08969545}],"asks":[],"checksum":4051318438,"timestamp":"2024-06-01T22:42:11.482217Z"}]}
{"channel":"book","type":"update","data":[{"symbol":"GBP/USD","bids":[{"price":1.27404,"qty":5418.58555724}],"asks":[],"checksum":692384418,"timestamp":"2024-06-01T22:42:11.482250Z"}]}
{"channel":"book","type":"update","data":[{"symbol":"GBP/USD","bids":[{"price":1.27438,"qty":6234.53628849}],"asks":[],"checksum":1251235743,"timestamp":"2024-06-01T22:42:11.482282Z"}]}
{"channel":"book","type":"update","data":[{"symbol":"GBP/USD","bids":[{"price":1.27455,"qty":0.00000000},{"price":1.27393,"qty":601.92255534},{"price":1.27457,"qty":2152.54267161}],"asks":[],"checksum":3630795012,"timestamp":"2024-06-01T22:42:11.485578Z"}]}
{"channel":"book","type":"update","data":[{"symbol":"GBP/USD","bids":[],"asks":[{"price":1.27543,"qty":90.90000000}],"checksum":1004619675,"timestamp":"2024-06-01T22:42:11.661336Z"}]}
{"channel":"book","type":"update","data":[{"symbol":"GBP/USD","bids":[],"asks":[{"price":1.27468,"qty":0.00000000},{"price":1.27544,"qty":36715.83134905}],"checksum":4124306920,"timestamp":"2024-06-01T22:42:11.823585Z"}]}
{"channel":"book","type":"update","data":[{"symbol":"GBP/USD","bids":[],"asks":[{"price":1.27544,"qty":0.00000000},{"price":1.27545,"qty":3920.19258238}],"checksum":3238087098,"timestamp":"2024-06-01T22:42:13.305936Z"}]}
{"channel":"book","type":"update","data":[{"symbol":"GBP/USD","bids":[],"asks":[{"price":1.27500,"qty":0.00000000},{"price":1.27547,"qty":29222.00000000}],"checksum":207041395,"timestamp":"2024-06-01T22:42:13.305983Z"}]}
{"channel":"book","type":"update","data":[{"symbol":"GBP/USD","bids":[],"asks":[{"price":1.27508,"qty":3100.96483999}],"checksum":515000981,"timestamp":"2024-06-01T22:42:13.306342Z"}]}
{"channel":"book","type":"update","data":[{"symbol":"GBP/USD","bids":[],"asks":[{"price":1.27544,"qty":35186.00504284}],"checksum":98786579,"timestamp":"2024-06-01T22:42:13.306422Z"}]}
{"channel":"book","type":"update","data":[{"symbol":"GBP/USD","bids":[],"asks":[{"price":1.27499,"qty":0.00000000},{"price":1.27545,"qty":3920.19258238},{"price":1.27508,"qty":4489.66800213}],"checksum":1363339979,"timestamp":"2024-06-01T22:42:13.309224Z"}]}
{"channel":"book","type":"update","data":[{"symbol":"GBP/USD","bids":[],"asks":[{"price":1.27508,"qty":3100.96483999},{"price":1.27507,"qty":1388.70316214}],"checksum":3751525963,"timestamp":"2024-06-01T22:42:13.312030Z"}]}
{"channel":"book","type":"update","data":[{"symbol":"GBP/USD","bids":[{"price":1.27456,"qty":0.00000000},{"price":1.27393,"qty":601.92255534}],"asks":[],"checksum":168454100,"timestamp":"2024-06-01T22:42:14.995792Z"}]}
{"channel":"book","type":"update","data":[{"symbol":"GBP/USD","bids":[{"price":1.27438,"qty":0.00000000},{"price":1.27391,"qty":3924.89588349}],"asks":[],"checksum":2543463272,"timestamp":"2024-06-01T22:42:14.996129Z"}]}
{"channel":"book","type":"update","data":[{"symbol":"GBP/USD","bids":[{"price":1.27404,"qty":0.00000000},{"price":1.27380,"qty":818.32721381}],"asks":[],"checksum":56679779,"timestamp":"2024-06-01T22:42:14.996195Z"}]}
{"channel":"book","type":"update","data":[{"symbol":"GBP/USD","bids":[{"price":1.27457,"qty":0.00000000},{"price":1.27368,"qty":14540.74651318},{"price":1.27455,"qty":2152.52154306}],"asks":[],"checksum":1316898818,"timestamp":"2024-06-01T22:42:14.999513Z"}]}
{"channel":"book","type":"update","data":[{"symbol":"GBP/USD","bids":[{"price":1.27458,"qty":2735.86639892}],"asks":[],"checksum":222261598,"timestamp":"2024-06-01T22:42:15.000790Z"}]}
{"channel":"book","type":"update","data":[{"symbol":"GBP/USD","bids":[{"price":1.27438,"qty":3902.08969545}],"asks":[],"checksum":2351632689,"timestamp":"2024-06-01T22:42:15.000840Z"}]}
{"channel":"book","type":"update","data":[{"symbol":"GBP/USD","bids":[{"price":1.27394,"qty":10086.32596817}],"asks":[],"checksum":183732228,"timestamp":"2024-06-01T22:42:15.000999Z"}]}
{"channel":"book","type":"update","data":[{"symbol":"GBP/USD","bids":[{"price":1.27395,"qty":14540.74651318}],"asks":[],"checksum":692586989,"timestamp":"2024-06-01T22:42:15.004386Z"}]}
{"channel":"book","type":"update","data":[{"symbol":"GBP/USD","bids":[{"price":1.27455,"qty":0.00000000},{"price":1.27394,"qty":10086.32596817},{"price":1.27459,"qty":2152.45399125}],"asks":[],"checksum":3227937774,"timestamp":"2024-06-01T22:42:15.004631Z"}]}
{"channel":"book","type":"update","data":[{"symbol":"GBP/USD","bids":[],"asks":[{"price":1.27468,"qty":90.90000000}],"checksum":1035397403,"timestamp":"2024-06-01T22:42:15.159900Z"}]}
{"channel":"book","type":"update","data":[{"symbol":"GBP/USD","bids":[],"asks":[{"price":1.27507,"qty":0.00000000},{"price":1.27544,"qty":35186.00504284},{"price":1.27468,"qty":1479.60356090}],"checksum":553486445,"timestamp":"2024-06-01T22:42:15.174365Z"}]}
{"channel":"book","type":"update","data":[{"symbol":"GBP/USD","bids":[],"asks":[{"price":1.27468,"qty":90.90000000},{"price":1.27507,"qty":1388.70355779}],"checksum":143973855,"timestamp":"2024-06-01T22:42:15.313994Z"}]}
{"channel":"book","type":"update","data":[{"symbol":"GBP/USD","bids":[],"asks":[{"price":1.27543,"qty":0.00000000},{"price":1.27544,"qty":35186.00504284}],"checksum":2918923042,"timestamp":"2024-06-01T22:42:15.325126Z"}]}
{"channel":"book","type":"update","data":[{"symbol":"GBP/USD","bids":[],"asks":[{"price":1.27507,"qty":0.00000000},{"price":1.27545,"qty":3920.19258238},{"price":1.27468,"qty":1479.60355572}],"checksum":1785103281,"timestamp":"2024-06-01T22:42:15.398070Z"}]}
{"channel":"book","type":"update","data":[{"symbol":"GBP/USD","bids":[],"asks":[{"price":1.27468,"qty":90.90000000},{"price":1.27507,"qty":1388.70355572}],"checksum":2359107686,"timestamp":"2024-06-01T22:42:15.429192Z"}]}
{"channel":"book","type":"update","data":[{"symbol":"GBP/USD","bids":[],"asks":[{"price":1.27544,"qty":0.00000000},{"price":1.27545,"qty":3920.19258238}],"checksum":3924789424,"timestamp":"2024-06-01T22:42:15.440156Z"}]}
{"channel":"book","type":"update","data":[{"symbol":"GBP/USD","bids":[],"asks":[{"price":1.27508,"qty":0.00000000},{"price":1.27547,"qty":29222.00000000}],"checksum":1506895023,"timestamp":"2024-06-01T22:42:15.440199Z"}]}
{"channel":"book","type":"update","data":[{"symbol":"GBP/USD","bids":[],"asks":[{"price":1.27508,"qty":1569.64310240}],"checksum":1199981491,"timestamp":"2024-06-01T22:42:15.440814Z"}]}
{"channel":"book","type":"update","data":[{"symbol":"GBP/USD","bids":[],"asks":[{"price":1.27544,"qty":36751.72170228}],"checksum":2782874922,"timestamp":"2024-06-01T22:42:15.440861Z"}]}
{"channel":"book","type":"update","data":[{"symbol":"GBP/USD","bids":[],"asks":[{"price":1.27507,"qty":0.00000000},{"price":1.27545,"qty":3920.19258238},{"price":1.27508,"qty":2958.34665812}],"checksum":700046690,"timestamp":"2024-06-01T22:42:15.443313Z"}]}
{"channel":"book","type":"update","data":[{"symbol":"GBP/USD","bids":[],"asks":[{"price":1.27508,"qty":1569.64310240},{"price":1.27507,"qty":1388.70355572}],"checksum":2782874922,"timestamp":"2024-06-01T22:42:15.446315Z"}]}
{"channel":"book","type":"update","data":[{"symbol":"GBP/USD","bids":[],"asks":[{"price":1.27507,"qty":0.00000000},{"price":1.27545,"qty":3920.19258238},{"price":1.27468,"qty":1479.60355572}],"checksum":4196435119,"timestamp":"2024-06-01T22:42:15.470740Z"}]}
{"channel":"book","type":"update","data":[{"symbol":"GBP/USD","bids":[],"asks":[{"price":1.27468,"qty":90.90000000},{"price":1.27507,"qty":1388.70355572}],"checksum":2782874922,"timestamp":"2024-06-01T22:42:15.530330Z"}]}
{"channel":"book","type":"update","data":[{"symbol":"GBP/USD","bids":[],"asks":[{"price":1.27507,"qty":0.00000000},{"price":1.27545,"qty":3920.19258238},{"price":1.27468,"qty":1479.60355572}],"checksum":4196435119,"timestamp":"2024-06-01T22:42:15.595214Z"}]}
{"channel":"book","type":"update","data":[{"symbol":"GBP/USD","bids":[],"asks":[{"price":1.27468,"qty":90.90000000},{"price":1.27507,"qty":1388.70355341}],"checksum":2450171737,"timestamp":"2024-06-01T22:42:15.907396Z"}]}
{"channel":"book","type":"update","data":[{"symbol":"GBP/USD","bids":[],"asks":[{"price":1.27507,"qty":0.00000000},{"price":1.27545,"qty":3920.19258238},{"price":1.27468,"qty":1479.61691660}],"checksum":3033353841,"timestamp":"2024-06-01T22:42:16.378702Z"}]}
{"channel":"book","type":"update","data":[{"symbol":"GBP/USD","bids":[],"asks":[{"price":1.27468,"qty":90.90000000},{"price":1.27507,"qty":1388.71691660}],"checksum":3591345982,"timestamp":"2024-06-01T22:42:16.384506Z"}]}
{"channel":"book","type":"update","data":[{"symbol":"GBP/USD","bids":[],"asks":[{"price":1.27507,"qty":0.00000000},{"price":1.27545,"qty":3920.19258238},{"price":1.27506,"qty":1388.71691660}],"checksum":1920406311,"timestamp":"2024-06-01T22:42:16.412948Z"}]}
{"channel":"book","type":"update","data":[{"symbol":"GBP/USD","bids":[],"asks":[{"price":1.27506,"qty":0.00000000},{"price":1.27545,"qty":3920.19258238},{"price":1.27507,"qty":1388.71691660}],"checksum":3591345982,"timestamp":"2024-06-01T22:42:16.416516Z"}]}
{"channel":"book","type":"update","data":[{"symbol":"GBP/USD","bids":[],"asks":[{"price":1.27507,"qty":0.00000000},{"price":1.27545,"qty":3920.19258238},{"price":1.27468,"qty":1479.61709059}],"checksum":3288258203,"timestamp":"2024-06-01T22:42:17.610245Z"}]}
{"channel":"book","type":"update","data":[{"symbol":"GBP/USD","bids":[],"asks":[{"price":1.27468,"qty":90.90000000},{"price":1.27507,"qty":1388.71709059}],"checksum":1314119029,"timestamp":"2024-06-01T22:42:17.616459Z"}]}
{"channel":"book","type":"update","data":[{"symbol":"GBP/USD","bids":[],"asks":[{"price":1.27508,"qty":0.00000000},{"price":1.27545,"qty":3920.19258238}],"checksum":1895236650,"timestamp":"2024-06-01T22:42:17.618390Z"}]}
{"channel":"book","type":"update","data":[{"symbol":"GBP/USD","bids":[],"asks":[{"price":1.27544,"qty":0.00000000},{"price":1.27547,"qty":29222.00000000}],"checksum":2992502000,"timestamp":"2024-06-01T22:42:17.618501Z"}]}
{"channel":"book","type":"update","data":[{"symbol":"GBP/USD","bids":[],"asks":[{"price":1.27506,"qty":6163.60831518}],"checksum":2120091370,"timestamp":"2024-06-01T22:42:17.620014Z"}]}
{"channel":"book","type":"update","data":[{"symbol":"GBP/USD","bids":[],"asks":[{"price":1.27544,"qty":30536.70886884}],"checksum":1251874961,"timestamp":"2024-06-01T22:42:17.620048Z"}]}
{"channel":"book","type":"update","data":[{"symbol":"GBP/USD","bids":[],"asks":[{"price":1.27507,"qty":0.00000000},{"price":1.27545,"qty":3920.19258238},{"price":1.27508,"qty":1388.71709059}],"checksum":3073423583,"timestamp":"2024-06-01T22:42:17.622415Z"}]}
{"channel":"book","type":"update","data":[{"symbol":"GBP/USD","bids":[],"asks":[{"price":1.27477,"qty":0.00000000},{"price":1.27545,"qty":3920.19258238},{"price":1.27506,"qty":7064.20831518}],"checksum":3300846880,"timestamp":"2024-06-01T22:42:17.626846Z"}]}
{"channel":"book","type":"update","data":[{"symbol":"GBP/USD","bids":[],"asks":[{"price":1.27506,"qty":6163.60831518},{"price":1.27477,"qty":900.60000000}],"checksum":3073423583,"timestamp":"2024-06-01T22:42:17.657749Z"}]}
{"channel":"book","type":"update","data":[{"symbol":"GBP/USD","bids":[],"asks":[{"price":1.27508,"qty":0.00000000},{"price":1.27545,"qty":3920.19258238},{"price":1.27505,"qty":1388.71709059}],"checksum":1717728095,"timestamp":"2024-06-01T22:42:17.701547Z"}]}
{"channel":"book","type":"update","data":[{"symbol":"GBP/USD","bids":[],"asks":[{"price":1.27505,"qty":0.00000000},{"price":1.27545,"qty":3920.19258238},{"price":1.27468,"qty":1479.61709739}],"checksum":985831918,"timestamp":"2024-06-01T22:42:17.959197Z"}]}
{"channel":"book","type":"update","data":[{"symbol":"GBP/USD","bids":[],"asks":[{"price":1.27468,"qty":90.90000000},{"price":1.27505,"qty":1388.71709739}],"checksum":2911595067,"timestamp":"2024-06-01T22:42:17.971411Z"}]}
{"channel":"book","type":"update","data":[{"symbol":"GBP/USD","bids":[],"asks":[{"price":1.27505,"qty":0.00000000},{"price":1.27545,"qty":3920.19258238},{"price":1.27468,"qty":1479.61709739}],"checksum":985831918,"timestamp":"2024-06-01T22:42:18.196633Z"}]}
{"channel":"book","type":"update","data":[{"symbol":"GBP/USD","bids":[],"asks":[{"price":1.27468,"qty":90.90000000},{"price":1.27504,"qty":1388.71709739}],"checksum":166981154,"timestamp":"2024-06-01T22:42:18.201097Z"}]}
{"channel":"book","type":"update","data":[{"symbol":"GBP/USD","bids":[],"asks":[{"price":1.27504,"qty":0.00000000},{"price":1.27545,"qty":3920.19258238},{"price":1.27505,"qty":1388.69529060}],"checksum":3859298226,"timestamp":"2024-06-01T22:42:18.220327Z"}]}
{"channel":"book","type":"update","data":[{"symbol":"GBP/USD","bids":[{"price":1.27458,"qty":0.00000000},{"price":1.27394,"qty":10086.32596817}],"asks":[],"checksum":3488359312,"timestamp":"2024-06-01T22:42:18.373033Z"}]}
{"channel":"book","type":"update","data":[{"symbol":"GBP/USD","bids":[{"price":1.27394,"qty":0.00000000},{"price":1.27393,"qty":601.92255534}],"asks":[],"checksum":380944918,"timestamp":"2024-06-01T22:42:18.373070Z"}]}
{"channel":"book","type":"update","data":[{"symbol":"GBP/USD","bids":[{"price":1.27459,"qty":0.00000000},{"price":1.27391,"qty":3924.89588349},{"price":1.27455,"qty":2152.88247943}],"asks":[],"checksum":2170682508,"timestamp":"2024-06-01T22:42:18.376478Z"}]}
{"channel":"book","type":"update","data":[{"symbol":"GBP/USD","bids":[{"price":1.27395,"qty":0.00000000},{"price":1.27391,"qty":3924.89588349}],"asks":[],"checksum":1726026998,"timestamp":"2024-06-01T22:42:18.376568Z"}]}
{"channel":"book","type":"update","data":[{"symbol":"GBP/USD","bids":[{"price":1.27460,"qty":1569.64310240}],"asks":[],"checksum":280341878,"timestamp":"2024-06-01T22:42:18.378021Z"}]}
{"channel":"book","type":"update","data":[{"symbol":"GBP/USD","bids":[{"price":1.27396,"qty":10086.89541314}],"asks":[],"checksum":956628141,"timestamp":"2024-06-01T22:42:18.378103Z"}]}
{"channel":"book","type":"update","data":[{"symbol":"GBP/USD","bids":[{"price":1.27455,"qty":0.00000000},{"price":1.27393,"qty":601.92255534},{"price":1.27461,"qty":2152.78113632}],"asks":[],"checksum":3039844535,"timestamp":"2024-06-01T22:42:18.412296Z"}]}
{"channel":"book","type":"update","data":[{"symbol":"GBP/USD","bids":[],"asks":[{"price":1.27505,"qty":0.00000000},{"price":1.27545,"qty":3920.19258238},{"price":1.27468,"qty":1479.59529060}],"checksum":1248155943,"timestamp":"2024-06-01T22:42:18.412391Z"}]}
{"channel":"book","type":"update","data":[{"symbol":"GBP/USD","bids":[{"price":1.27397,"qty":14540.74651318}],"asks":[],"checksum":3332952625,"timestamp":"2024-06-01T22:42:18.415411Z"}]}
{"channel":"book","type":"update","data":[{"symbol":"GBP/USD","bids":[],"asks":[{"price":1.27468,"qty":90.90000000},{"price":1.27505,"qty":1388.69522193}],"checksum":2401584113,"timestamp":"2024-06-01T22:42:18.654879Z"}]}
{"channel":"book","type":"update","data":[{"symbol":"GBP/USD","bids":[],"asks":[{"price":1.27505,"qty":0.00000000},{"price":1.27545,"qty":3920.19258238},{"price":1.27468,"qty":1479.59521206}],"checksum":897116645,"timestamp":"2024-06-01T22:42:18.893617Z"}]}
{"channel":"book","type":"update","data":[{"symbol":"GBP/USD","bids":[],"asks":[{"price":1.27468,"qty":90.90000000},{"price":1.27505,"qty":1388.69521206}],"checksum":433801622,"timestamp":"2024-06-01T22:42:18.900910Z"}]}
{"channel":"book","type":"update","data":[{"symbol":"GBP/USD","bids":[],"asks":[{"price":1.27544,"qty":0.00000000},{"price":1.27545,"qty":3920.19258238}],"checksum":3261203879,"timestamp":"2024-06-01T22:42:19.691262Z"}]}
{"channel":"book","type":"update","data":[{"symbol":"GBP/USD","bids":[],"asks":[{"price":1.27506,"qty":0.00000000},{"price":1.27547,"qty":29222.00000000}],"checksum":1583661130,"timestamp":"2024-06-01T22:42:19.691353Z"}]}
{"channel":"book","type":"update","data":[{"symbol":"GBP/USD","bids":[],"asks":[{"price":1.27505,"qty":0.00000000},{"price":1.27556,"qty":818.33244942},{"price":1.27508,"qty":1388.69519911}],"checksum":1461241896,"timestamp":"2024-06-01T22:42:19.694814Z"}]}
{"channel":"book","type":"update","data":[{"symbol":"GBP/USD","bids":[],"asks":[{"price":1.27504,"qty":4632.28657759}],"checksum":161190707,"timestamp":"2024-06-01T22:42:19.732556Z"}]}
{"channel":"book","type":"update","data":[{"symbol":"GBP/USD","bids":[],"asks":[{"price":1.27544,"qty":29038.28662170}],"checksum":2729709329,"timestamp":"2024-06-01T22:42:19.732617Z"}]}
{"channel":"book","type":"update","data":[{"symbol":"GBP/USD","bids":[],"asks":[{"price":1.27508,"qty":0.00000000},{"price":1.27545,"qty":3920.19258238},{"price":1.27503,"qty":1388.69519809}],"checksum":1620664815,"timestamp":"2024-06-01T22:42:20.136655Z"}]}
{"channel":"book","type":"update","data":[{"symbol":"GBP/USD","bids":[],"asks":[{"price":1.27503,"qty":0.00000000},{"price":1.27545,"qty":3920.19258238},{"price":1.27468,"qty":1479.58526176}],"checksum":12685008,"timestamp":"2024-06-01T22:42:21.339088Z"}]}
{"channel":"book","type":"update","data":[{"symbol":"GBP/USD","bids":[],"asks":[{"price":1.27468,"qty":90.90000000},{"price":1.27503,"qty":1388.68526176}],"checksum":850379717,"timestamp":"2024-06-01T22:42:21.345165Z"}]}
{"channel":"book","type":"update","data":[{"symbol":"GBP/USD","bids":[],"asks":[{"price":1.27504,"qty":0.00000000},{"price":1.27545,"qty":3920.19258238}],"checksum":2996776962,"timestamp":"2024-06-01T22:42:21.754869Z"}]}
{"channel":"book","type":"update","data":[{"symbol":"GBP/USD","bids":[],"asks":[{"price":1.27544,"qty":0.00000000},{"price":1.27547,"qty":29222.00000000}],"checksum":4118127215,"timestamp":"2024-06-01T22:42:21.755060Z"}]}
{"channel":"book","type":"update","data":[{"symbol":"GBP/USD","bids":[],"asks":[{"price":1.27502,"qty":3100.96483999}],"checksum":4126673760,"timestamp":"2024-06-01T22:42:21.755968Z"}]}
{"channel":"book","type":"update","data":[{"symbol":"GBP/USD","bids":[],"asks":[{"price":1.27544,"qty":35186.00504284}],"checksum":1371976984,"timestamp":"2024-06-01T22:42:21.756098Z"}]}
{"channel":"book","type":"update","data":[{"symbol":"GBP/USD","bids":[],"asks":[{"price":1.27503,"qty":0.00000000},{"price":1.27545,"qty":3920.19258238},{"price":1.27508,"qty":1388.68527679}],"checksum":708918715,"timestamp":"2024-06-01T22:42:21.758189Z"}]}
{"channel":"book","type":"update","data":[{"symbol":"GBP/USD","bids":[{"price":1.27460,"qty":0.00000000},{"price":1.27396,"qty":10086.89541314}],"asks":[],"checksum":960813434,"timestamp":"2024-06-01T22:42:21.824916Z"}]}
{"channel":"book","type":"update","data":[{"symbol":"GBP/USD","bids":[{"price":1.27396,"qty":0.00000000},{"price":1.27393,"qty":601.92255534}],"asks":[],"checksum":3932801948,"timestamp":"2024-06-01T22:42:21.825076Z"}]}
{"channel":"book","type":"update","data":[{"symbol":"GBP/USD","bids":[{"price":1.27397,"qty":0.00000000},{"price":1.27391,"qty":3924.89588349}],"asks":[],"checksum":2101753526,"timestamp":"2024-06-01T22:42:21.828490Z"}]}
{"channel":"book","type":"update","data":[{"symbol":"GBP/USD","bids":[{"price":1.27461,"qty":0.00000000},{"price":1.27380,"qty":818.32721381},{"price":1.27455,"qty":2152.76523538}],"asks":[],"checksum":1673086420,"timestamp":"2024-06-01T22:42:21.828792Z"}]}
{"channel":"book","type":"update","data":[{"symbol":"GBP/USD","bids":[{"price":1.27398,"qty":12822.19236709}],"asks":[],"checksum":404669535,"timestamp":"2024-06-01T22:42:21.830147Z"}]}
{"channel":"book","type":"update","data":[{"symbol":"GBP/USD","bids":[{"price":1.27399,"qty":14540.74651318}],"asks":[],"checksum":461251044,"timestamp":"2024-06-01T22:42:21.885416Z"}]}
{"channel":"book","type":"update","data":[{"symbol":"GBP/USD","bids":[],"asks":[{"price":1.27508,"qty":0.00000000},{"price":1.27545,"qty":3920.19258238},{"price":1.27501,"qty":1388.68528362}],"checksum":1754622391,"timestamp":"2024-06-01T22:42:22.180774Z"}]}
{"channel":"book","type":"update","data":[{"symbol":"GBP/USD","bids":[{"price":1.27456,"qty":301.68169626}],"asks":[],"checksum":3032696196,"timestamp":"2024-06-01T22:42:22.329831Z"}]}
{"channel":"book","type":"update","data":[{"symbol":"GBP/USD","bids":[{"price":1.27454,"qty":0.00000000},{"price":1.27398,"qty":12822.19236709}],"asks":[],"checksum":3382948271,"timestamp":"2024-06-01T22:42:22.511275Z"}]}
{"channel":"book","type":"update","data":[{"symbol":"GBP/USD","bids":[{"price":1.27455,"qty":0.00000000},{"price":1.27393,"qty":601.92255534},{"price":1.27457,"qty":2152.73159648}],"asks":[],"checksum":1848452701,"timestamp":"2024-06-01T22:42:22.594442Z"}]}
{"channel":"book","type":"update","data":[{"symbol":"GBP/USD","bids":[],"asks":[{"price":1.27501,"qty":0.00000000},{"price":1.27545,"qty":3920.19258238},{"price":1.27468,"qty":1479.59076980}],"checksum":1389382849,"timestamp":"2024-06-01T22:42:23.041105Z"}]}
{"channel":"book","type":"update","data":[{"symbol":"GBP/USD","bids":[],"asks":[{"price":1.27468,"qty":90.90000000},{"price":1.27501,"qty":1388.69076925}],"checksum":2391929542,"timestamp":"2024-06-01T22:42:23.103941Z"}]}
{"channel":"book","type":"update","data":[{"symbol":"GBP/USD","bids":[],"asks":[{"price":1.27501,"qty":0.00000000},{"price":1.27545,"qty":3920.19258238},{"price":1.27468,"qty":1479.59076925}],"checksum":361387155,"timestamp":"2024-06-01T22:42:23.521623Z"}]}
{"channel":"book","type":"update","data":[{"symbol":"GBP/USD","bids":[],"asks":[{"price":1.27502,"qty":0.00000000},{"price":1.27547,"qty":29222.00000000}],"checksum":3136811382,"timestamp":"2024-06-01T22:42:23.853775Z"}]}
{"channel":"book","type":"update","data":[{"symbol":"GBP/USD","bids":[],"asks":[{"price":1.27544,"qty":0.00000000},{"price":1.27556,"qty":818.33244942}],"checksum":3170695687,"timestamp":"2024-06-01T22:42:23.853791Z"}]}
{"channel":"book","type":"update","data":[{"symbol":"GBP/USD","bids":[],"asks":[{"price":1.27508,"qty":1569.64310240}],"checksum":3503460583,"timestamp":"2024-06-01T22:42:23.853884Z"}]}
{"channel":"book","type":"update","data":[{"symbol":"GBP/USD","bids":[],"asks":[{"price":1.27544,"qty":36751.72170228}],"checksum":3054895581,"timestamp":"2024-06-01T22:42:23.854216Z"}]}
