{"channel":"book","type":"snapshot","data":[{"symbol":"LINK/USD","bids":[{"price":18.44673,"qty":19.20000000},{"price":18.44323,"qty":33.00000000},{"price":18.44276,"qty":406.66358115},{"price":18.44044,"qty":2.34929424},{"price":18.44043,"qty":265.98306169},{"price":18.44000,"qty":62.50503732},{"price":18.43854,"qty":1084.08557829},{"price":18.43721,"qty":135.59535309},{"price":18.43680,"qty":49.17000000},{"price":18.43656,"qty":542.40026605}],"asks":[{"price":18.45172,"qty":9.75909125},{"price":18.45392,"qty":33.00000000},{"price":18.45439,"qty":1.20306513},{"price":18.45441,"qty":203.19885470},{"price":18.45480,"qty":135.28864495},{"price":18.45484,"qty":19.20000000},{"price":18.45560,"qty":186.96555600},{"price":18.45628,"qty":49.18000000},{"price":18.45712,"qty":243.48672997},{"price":18.45870,"qty":765.31384334}],"checksum":1253125702}]}
{"channel":"book","type":"update","data":[{"symbol":"LINK/USD","bids":[],"asks":[{"price":18.45480,"qty":0.00000000},{"price":18.45871,"qty":1421.95697000}],"checksum":464154903,"timestamp":"2024-06-01T22:42:52.492081Z"}]}
{"channel":"book","type":"update","data":[{"symbol":"LINK/USD","bids":[],"asks":[{"price":18.45559,"qty":70.48169080}],"checksum":117709011,"timestamp":"2024-06-01T22:42:52.494225Z"}]}
{"channel":"book","type":"update","data":[{"symbol":"LINK/USD","bids":[{"price":18.44276,"qty":0.00000000},{"price":18.43606,"qty":186.96555600}],"asks":[],"checksum":385994544,"timestamp":"2024-06-01T22:42:52.507983Z"}]}
{"channel":"book","type":"update","data":[{"symbol":"LINK/USD","bids":[{"price":18.44323,"qty":0.00000000},{"price":18.43155,"qty":19.20000000}],"asks":[],"checksum":1140315008,"timestamp":"2024-06-01T22:42:52.510811Z"}]}
{"channel":"book","type":"update","data":[{"symbol":"LINK/USD","bids":[{"price":18.44091,"qty":33.00000000}],"asks":[],"checksum":136105264,"timestamp":"2024-06-01T22:42:52.511088Z"}]}
{"channel":"book","type":"update","data":[{"symbol":"LINK/USD","bids":[],"asks":[{"price":18.45390,"qty":40.00000000}],"checksum":2533615781,"timestamp":"2024-06-01T22:42:52.512712Z"}]}
{"channel":"book","type":"update","data":[{"symbol":"LINK/USD","bids":[],"asks":[{"price":18.45391,"qty":200.00000000}],"checksum":318039953,"timestamp":"2024-06-01T22:42:52.513423Z"}]}
{"channel":"book","type":"update","data":[{"symbol":"LINK/USD","bids":[],"asks":[{"price":18.45559,"qty":0.00000000},{"price":18.45712,"qty":243.48672997}],"checksum":2050652804,"timestamp":"2024-06-01T22:42:52.514698Z"}]}
{"channel":"book","type":"update","data":[{"symbol":"LINK/USD","bids":[],"asks":[{"price":18.45392,"qty":0.00000000},{"price":18.45870,"qty":765.31384334}],"checksum":670169194,"timestamp":"2024-06-01T22:42:52.515934Z"}]}
{"channel":"book","type":"update","data":[{"symbol":"LINK/USD","bids":[{"price":18.44673,"qty":0.00000000},{"price":18.43155,"qty":19.20000000},{"price":18.44482,"qty":19.20000000}],"asks":[],"checksum":2973345208,"timestamp":"2024-06-01T22:42:52.516080Z"}]}
{"channel":"book","type":"update","data":[{"symbol":"LINK/USD","bids":[],"asks":[{"price":18.45343,"qty":33.00000000}],"checksum":837391739,"timestamp":"2024-06-01T22:42:52.516278Z"}]}
{"channel":"book","type":"update","data":[{"symbol":"LINK/USD","bids":[],"asks":[{"price":18.45171,"qty":32.06000335}],"checksum":4206664096,"timestamp":"2024-06-01T22:42:52.519394Z"}]}
{"channel":"book","type":"update","data":[{"symbol":"LINK/USD","bids":[{"price":18.44482,"qty":38.40000000}],"asks":[],"checksum":87185245,"timestamp":"2024-06-01T22:42:52.520218Z"}]}
{"channel":"book","type":"update","data":[{"symbol":"LINK/USD","bids":[],"asks":[{"price":18.45484,"qty":0.00000000},{"price":18.45712,"qty":243.48672997},{"price":18.45303,"qty":19.20000000}],"checksum":4116865783,"timestamp":"2024-06-01T22:42:52.520251Z"}]}
{"channel":"book","type":"update","data":[{"symbol":"LINK/USD","bids":[],"asks":[{"price":18.45303,"qty":38.40000000}],"checksum":3675346264,"timestamp":"2024-06-01T22:42:52.520411Z"}]}
{"channel":"book","type":"update","data":[{"symbol":"LINK/USD","bids":[],"asks":[{"price":18.45171,"qty":114.39456950}],"checksum":3536050215,"timestamp":"2024-06-01T22:42:52.521375Z"}]}
{"channel":"book","type":"update","data":[{"symbol":"LINK/USD","bids":[],"asks":[{"price":18.45389,"qty":272.85735600}],"checksum":524773562,"timestamp":"2024-06-01T22:42:52.522261Z"}]}
{"channel":"book","type":"update","data":[{"symbol":"LINK/USD","bids":[],"asks":[{"price":18.45343,"qty":0.00000000},{"price":18.45628,"qty":49.18000000}],"checksum":3858486180,"timestamp":"2024-06-01T22:42:52.524922Z"}]}
{"channel":"book","type":"update","data":[{"symbol":"LINK/USD","bids":[],"asks":[{"price":18.45165,"qty":33.00000000}],"checksum":391475822,"timestamp":"2024-06-01T22:42:52.525038Z"}]}
{"channel":"book","type":"update","data":[{"symbol":"LINK/USD","bids":[],"asks":[{"price":18.45171,"qty":32.06000335}],"checksum":1040142915,"timestamp":"2024-06-01T22:42:52.526793Z"}]}
{"channel":"book","type":"update","data":[{"symbol":"LINK/USD","bids":[{"price":18.44482,"qty":19.20000000}],"asks":[],"checksum":3262225598,"timestamp":"2024-06-01T22:42:52.542530Z"}]}
{"channel":"book","type":"update","data":[{"symbol":"LINK/USD","bids":[],"asks":[{"price":18.45390,"qty":0.00000000},{"price":18.45628,"qty":49.18000000}],"checksum":2568432416,"timestamp":"2024-06-01T22:42:52.546559Z"}]}
{"channel":"book","type":"update","data":[{"symbol":"LINK/USD","bids":[],"asks":[{"price":18.45391,"qty":0.00000000},{"price":18.45712,"qty":243.48672997}],"checksum":3165092497,"timestamp":"2024-06-01T22:42:52.547671Z"}]}
{"channel":"book","type":"update","data":[{"symbol":"LINK/USD","bids":[],"asks":[{"price":18.45164,"qty":200.00000000}],"checksum":4202143640,"timestamp":"2024-06-01T22:42:52.547736Z"}]}
{"channel":"book","type":"update","data":[{"symbol":"LINK/USD","bids":[],"asks":[{"price":18.45164,"qty":287.30992310}],"checksum":862040479,"timestamp":"2024-06-01T22:42:52.547892Z"}]}
{"channel":"book","type":"update","data":[{"symbol":"LINK/USD","bids":[],"asks":[{"price":18.45165,"qty":0.00000000},{"price":18.45712,"qty":243.48672997}],"checksum":4073150215,"timestamp":"2024-06-01T22:42:52.550402Z"}]}
{"channel":"book","type":"update","data":[{"symbol":"LINK/USD","bids":[],"asks":[{"price":18.45117,"qty":33.00000000}],"checksum":2954098262,"timestamp":"2024-06-01T22:42:52.550782Z"}]}
{"channel":"book","type":"update","data":[{"symbol":"LINK/USD","bids":[{"price":18.44092,"qty":243.48672997}],"asks":[],"checksum":3533142343,"timestamp":"2024-06-01T22:42:52.555015Z"}]}
{"channel":"book","type":"update","data":[{"symbol":"LINK/USD","bids":[],"asks":[{"price":18.45164,"qty":200.00000000}],"checksum":2673911578,"timestamp":"2024-06-01T22:42:52.555394Z"}]}
{"channel":"book","type":"update","data":[{"symbol":"LINK/USD","bids":[{"price":18.44091,"qty":0.00000000},{"price":18.43155,"qty":19.20000000}],"asks":[],"checksum":2390443623,"timestamp":"2024-06-01T22:42:52.557637Z"}]}
{"channel":"book","type":"update","data":[{"symbol":"LINK/USD","bids":[{"price":18.44139,"qty":33.00000000}],"asks":[],"checksum":2726739563,"timestamp":"2024-06-01T22:42:52.557796Z"}]}
{"channel":"book","type":"update","data":[{"symbol":"LINK/USD","bids":[],"asks":[{"price":18.45163,"qty":70.72221879}],"checksum":2203462232,"timestamp":"2024-06-01T22:42:52.562816Z"}]}
{"channel":"book","type":"update","data":[{"symbol":"LINK/USD","bids":[{"price":18.44482,"qty":0.00000000},{"price":18.43155,"qty":19.20000000},{"price":18.44257,"qty":19.20000000}],"asks":[],"checksum":615012730,"timestamp":"2024-06-01T22:42:52.575721Z"}]}
{"channel":"book","type":"update","data":[{"symbol":"LINK/USD","bids":[{"price":18.44140,"qty":243.48672997}],"asks":[],"checksum":176884712,"timestamp":"2024-06-01T22:42:52.579623Z"}]}
{"channel":"book","type":"update","data":[{"symbol":"LINK/USD","bids":[{"price":18.44257,"qty":38.40000000}],"asks":[],"checksum":4110796053,"timestamp":"2024-06-01T22:42:52.579747Z"}]}
{"channel":"book","type":"update","data":[{"symbol":"LINK/USD","bids":[],"asks":[{"price":18.45303,"qty":19.20000000}],"checksum":999854295,"timestamp":"2024-06-01T22:42:52.579770Z"}]}
{"channel":"book","type":"update","data":[{"symbol":"LINK/USD","bids":[],"asks":[{"price":18.45303,"qty":0.00000000},{"price":18.45628,"qty":49.18000000},{"price":18.45081,"qty":19.20000000}],"checksum":2417571859,"timestamp":"2024-06-01T22:42:52.579855Z"}]}
{"channel":"book","type":"update","data":[{"symbol":"LINK/USD","bids":[],"asks":[{"price":18.45115,"qty":40.00000000}],"checksum":1261732581,"timestamp":"2024-06-01T22:42:52.580163Z"}]}
{"channel":"book","type":"update","data":[{"symbol":"LINK/USD","bids":[],"asks":[{"price":18.45164,"qty":0.00000000},{"price":18.45560,"qty":186.96555600}],"checksum":1361307202,"timestamp":"2024-06-01T22:42:52.581264Z"}]}
{"channel":"book","type":"update","data":[{"symbol":"LINK/USD","bids":[],"asks":[{"price":18.45116,"qty":200.00000000}],"checksum":965468751,"timestamp":"2024-06-01T22:42:52.581371Z"}]}
{"channel":"book","type":"update","data":[{"symbol":"LINK/USD","bids":[{"price":18.44139,"qty":0.00000000},{"price":18.43656,"qty":542.40026605}],"asks":[],"checksum":292355225,"timestamp":"2024-06-01T22:42:52.582474Z"}]}
{"channel":"book","type":"update","data":[{"symbol":"LINK/USD","bids":[{"price":18.44304,"qty":33.00000000}],"asks":[],"checksum":2185998856,"timestamp":"2024-06-01T22:42:52.582505Z"}]}
{"channel":"book","type":"update","data":[{"symbol":"LINK/USD","bids":[],"asks":[{"price":18.45117,"qty":0.00000000},{"price":18.45559,"qty":1421.95697000}],"checksum":2659507087,"timestamp":"2024-06-01T22:42:52.584315Z"}]}
{"channel":"book","type":"update","data":[{"symbol":"LINK/USD","bids":[],"asks":[{"price":18.45090,"qty":33.00000000}],"checksum":330238755,"timestamp":"2024-06-01T22:42:52.584358Z"}]}
{"channel":"book","type":"update","data":[{"symbol":"LINK/USD","bids":[],"asks":[{"price":18.45081,"qty":0.00000000},{"price":18.45558,"qty":732.50600000}],"checksum":3104046186,"timestamp":"2024-06-01T22:42:52.585794Z"}]}
{"channel":"book","type":"update","data":[{"symbol":"LINK/USD","bids":[{"price":18.43721,"qty":0.00000000},{"price":18.43656,"qty":542.40026605}],"asks":[],"checksum":708745303,"timestamp":"2024-06-01T22:42:52.587094Z"}]}
{"channel":"book","type":"update","data":[{"symbol":"LINK/USD","bids":[],"asks":[{"price":18.45081,"qty":19.20000000}],"checksum":2157080350,"timestamp":"2024-06-01T22:42:52.589762Z"}]}
{"channel":"book","type":"update","data":[{"symbol":"LINK/USD","bids":[{"price":18.44000,"qty":0.00000000},{"price":18.43155,"qty":19.20000000}],"asks":[],"checksum":1406300593,"timestamp":"2024-06-01T22:42:52.591444Z"}]}
{"channel":"book","type":"update","data":[{"symbol":"LINK/USD","bids":[{"price":18.43800,"qty":62.51181734}],"asks":[],"checksum":3177631165,"timestamp":"2024-06-01T22:42:52.596940Z"}]}
{"channel":"book","type":"update","data":[{"symbol":"LINK/USD","bids":[{"price":18.43800,"qty":0.00000000},{"price":18.43155,"qty":19.20000000}],"asks":[],"checksum":1406300593,"timestamp":"2024-06-01T22:42:52.727966Z"}]}
{"channel":"book","type":"update","data":[{"symbol":"LINK/USD","bids":[{"price":18.44393,"qty":271.09181932}],"asks":[],"checksum":672293488,"timestamp":"2024-06-01T22:42:52.729252Z"}]}
{"channel":"book","type":"update","data":[{"symbol":"LINK/USD","bids":[],"asks":[{"price":18.44873,"qty":271.02142509}],"checksum":2340396008,"timestamp":"2024-06-01T22:42:52.729333Z"}]}
{"channel":"book","type":"update","data":[{"symbol":"LINK/USD","bids":[{"price":18.43982,"qty":406.72845037}],"asks":[],"checksum":2612989666,"timestamp":"2024-06-01T22:42:52.729380Z"}]}
{"channel":"book","type":"update","data":[{"symbol":"LINK/USD","bids":[{"price":18.44433,"qty":33.00000000}],"asks":[],"checksum":3469641182,"timestamp":"2024-06-01T22:42:52.732166Z"}]}
{"channel":"book","type":"update","data":[{"symbol":"LINK/USD","bids":[{"price":18.44304,"qty":0.00000000},{"price":18.43680,"qty":49.17000000}],"asks":[],"checksum":881272726,"timestamp":"2024-06-01T22:42:52.732191Z"}]}
{"channel":"book","type":"update","data":[{"symbol":"LINK/USD","bids":[{"price":18.43700,"qty":62.51520791}],"asks":[],"checksum":127967812,"timestamp":"2024-06-01T22:42:52.732537Z"}]}
{"channel":"book","type":"update","data":[{"symbol":"LINK/USD","bids":[],"asks":[{"price":18.45200,"qty":89.93735595}],"checksum":399073373,"timestamp":"2024-06-01T22:42:52.732614Z"}]}
{"channel":"book","type":"update","data":[{"symbol":"LINK/USD","bids":[{"price":18.44092,"qty":0.00000000},{"price":18.43680,"qty":49.17000000}],"asks":[],"checksum":2028531031,"timestamp":"2024-06-01T22:42:52.733165Z"}]}
{"channel":"book","type":"update","data":[{"symbol":"LINK/USD","bids":[],"asks":[{"price":18.45115,"qty":0.00000000},{"price":18.45439,"qty":1.20306513}],"checksum":2892378293,"timestamp":"2024-06-01T22:42:52.733764Z"}]}
{"channel":"book","type":"update","data":[{"symbol":"LINK/USD","bids":[],"asks":[{"price":18.45116,"qty":0.00000000},{"price":18.45441,"qty":203.19885470}],"checksum":2161056504,"timestamp":"2024-06-01T22:42:52.734586Z"}]}
{"channel":"book","type":"update","data":[{"symbol":"LINK/USD","bids":[],"asks":[{"price":18.44871,"qty":40.00000000}],"checksum":2377985386,"timestamp":"2024-06-01T22:42:52.753873Z"}]}
{"channel":"book","type":"update","data":[{"symbol":"LINK/USD","bids":[],"asks":[{"price":18.44873,"qty":0.00000000},{"price":18.45441,"qty":203.19885470}],"checksum":2602003474,"timestamp":"2024-06-01T22:42:52.758310Z"}]}
{"channel":"book","type":"update","data":[{"symbol":"LINK/USD","bids":[],"asks":[{"price":18.45439,"qty":0.00000000},{"price":18.45558,"qty":732.50600000},{"price":18.44870,"qty":1.20306513}],"checksum":46151454,"timestamp":"2024-06-01T22:42:52.887556Z"}]}
{"channel":"book","type":"update","data":[{"symbol":"LINK/USD","bids":[],"asks":[{"price":18.45171,"qty":0.00000000},{"price":18.45558,"qty":732.50600000}],"checksum":1194728667,"timestamp":"2024-06-01T22:42:52.891019Z"}]}
{"channel":"book","type":"update","data":[{"symbol":"LINK/USD","bids":[],"asks":[{"price":18.45558,"qty":0.00000000},{"price":18.45559,"qty":1421.95697000}],"checksum":3026830630,"timestamp":"2024-06-01T22:42:52.988025Z"}]}
{"channel":"book","type":"update","data":[{"symbol":"LINK/USD","bids":[{"price":18.44092,"qty":129.20764155}],"asks":[],"checksum":3989490060,"timestamp":"2024-06-01T22:42:53.023793Z"}]}
{"channel":"book","type":"update","data":[{"symbol":"LINK/USD","bids":[],"asks":[{"price":18.44870,"qty":33.26306848}],"checksum":3504111613,"timestamp":"2024-06-01T22:42:53.027192Z"}]}
{"channel":"book","type":"update","data":[{"symbol":"LINK/USD","bids":[{"price":18.44257,"qty":19.20000000}],"asks":[],"checksum":913111215,"timestamp":"2024-06-01T22:42:53.059221Z"}]}
{"channel":"book","type":"update","data":[{"symbol":"LINK/USD","bids":[],"asks":[{"price":18.44868,"qty":40.00000000}],"checksum":2134588607,"timestamp":"2024-06-01T22:42:53.063692Z"}]}
{"channel":"book","type":"update","data":[{"symbol":"LINK/USD","bids":[],"asks":[{"price":18.44871,"qty":0.00000000},{"price":18.45559,"qty":1421.95697000}],"checksum":2150832581,"timestamp":"2024-06-01T22:42:53.254435Z"}]}
{"channel":"book","type":"update","data":[{"symbol":"LINK/USD","bids":[],"asks":[{"price":18.45080,"qty":13.55230630}],"checksum":2393197216,"timestamp":"2024-06-01T22:42:53.258613Z"}]}
{"channel":"book","type":"update","data":[{"symbol":"LINK/USD","bids":[],"asks":[{"price":18.44870,"qty":32.06000335},{"price":18.44867,"qty":1.20306513}],"checksum":1531952002,"timestamp":"2024-06-01T22:42:53.283137Z"}]}
{"channel":"book","type":"update","data":[{"symbol":"LINK/USD","bids":[],"asks":[{"price":18.45090,"qty":0.00000000},{"price":18.45441,"qty":203.19885470}],"checksum":2687901856,"timestamp":"2024-06-01T22:42:53.285898Z"}]}
{"channel":"book","type":"update","data":[{"symbol":"LINK/USD","bids":[],"asks":[{"price":18.45033,"qty":33.00000000}],"checksum":876444768,"timestamp":"2024-06-01T22:42:53.286188Z"}]}
{"channel":"book","type":"update","data":[{"symbol":"LINK/USD","bids":[],"asks":[{"price":18.45080,"qty":0.00000000},{"price":18.45441,"qty":203.19885470}],"checksum":2802817768,"timestamp":"2024-06-01T22:42:53.290250Z"}]}
{"channel":"book","type":"update","data":[{"symbol":"LINK/USD","bids":[],"asks":[{"price":18.44867,"qty":272.22536808}],"checksum":443083436,"timestamp":"2024-06-01T22:42:53.631206Z"}]}
{"channel":"book","type":"update","data":[{"symbol":"LINK/USD","bids":[],"asks":[{"price":18.45339,"qty":406.42959848}],"checksum":2454839144,"timestamp":"2024-06-01T22:42:53.631544Z"}]}
{"channel":"book","type":"update","data":[{"symbol":"LINK/USD","bids":[],"asks":[{"price":18.44865,"qty":40.00000000}],"checksum":1883860390,"timestamp":"2024-06-01T22:42:53.636271Z"}]}
{"channel":"book","type":"update","data":[{"symbol":"LINK/USD","bids":[],"asks":[{"price":18.44867,"qty":271.02230295},{"price":18.44864,"qty":1.20306513}],"checksum":1479770008,"timestamp":"2024-06-01T22:42:53.711260Z"}]}
{"channel":"book","type":"update","data":[{"symbol":"LINK/USD","bids":[],"asks":[{"price":18.44868,"qty":0.00000000},{"price":18.45339,"qty":406.42959848}],"checksum":2948317490,"timestamp":"2024-06-01T22:42:53.715812Z"}]}
{"channel":"book","type":"update","data":[{"symbol":"LINK/USD","bids":[],"asks":[{"price":18.44867,"qty":0.00000000},{"price":18.45389,"qty":272.85735600}],"checksum":742355332,"timestamp":"2024-06-01T22:42:53.749646Z"}]}
{"channel":"book","type":"update","data":[{"symbol":"LINK/USD","bids":[],"asks":[{"price":18.44864,"qty":136.49171008}],"checksum":4262995474,"timestamp":"2024-06-01T22:42:54.046719Z"}]}
{"channel":"book","type":"update","data":[{"symbol":"LINK/USD","bids":[{"price":18.44043,"qty":0.00000000},{"price":18.43693,"qty":40.00000000},{"price":18.43701,"qty":265.98306169}],"asks":[],"checksum":3421014778,"timestamp":"2024-06-01T22:42:54.050276Z"}]}
{"channel":"book","type":"update","data":[{"symbol":"LINK/USD","bids":[],"asks":[{"price":18.44862,"qty":40.00000000}],"checksum":3560313798,"timestamp":"2024-06-01T22:42:54.051573Z"}]}
{"channel":"book","type":"update","data":[{"symbol":"LINK/USD","bids":[{"price":18.44044,"qty":0.00000000},{"price":18.43693,"qty":40.00000000}],"asks":[],"checksum":3698234377,"timestamp":"2024-06-01T22:42:54.067447Z"}]}
{"channel":"book","type":"update","data":[{"symbol":"LINK/USD","bids":[{"price":18.43983,"qty":2.34929424}],"asks":[],"checksum":948564005,"timestamp":"2024-06-01T22:42:54.067726Z"}]}
{"channel":"book","type":"update","data":[{"symbol":"LINK/USD","bids":[],"asks":[{"price":18.44864,"qty":135.28864495},{"price":18.44861,"qty":1.20306513}],"checksum":1865970973,"timestamp":"2024-06-01T22:42:54.095926Z"}]}
{"channel":"book","type":"update","data":[{"symbol":"LINK/USD","bids":[],"asks":[{"price":18.44865,"qty":0.00000000},{"price":18.45339,"qty":406.42959848}],"checksum":272105759,"timestamp":"2024-06-01T22:42:54.100458Z"}]}
{"channel":"book","type":"update","data":[{"symbol":"LINK/USD","bids":[],"asks":[{"price":18.44864,"qty":0.00000000},{"price":18.45389,"qty":272.85735600}],"checksum":1799155340,"timestamp":"2024-06-01T22:42:54.105062Z"}]}
{"channel":"book","type":"update","data":[{"symbol":"LINK/USD","bids":[],"asks":[{"price":18.45162,"qty":1.08427940}],"checksum":1243007616,"timestamp":"2024-06-01T22:42:54.110769Z"}]}
{"channel":"book","type":"update","data":[{"symbol":"LINK/USD","bids":[],"asks":[{"price":18.45338,"qty":26.47166515}],"checksum":4066046480,"timestamp":"2024-06-01T22:42:54.110918Z"}]}
{"channel":"book","type":"update","data":[{"symbol":"LINK/USD","bids":[],"asks":[{"price":18.44860,"qty":135.28864495}],"checksum":3600417741,"timestamp":"2024-06-01T22:42:54.226444Z"}]}
{"channel":"book","type":"update","data":[{"symbol":"LINK/USD","bids":[],"asks":[{"price":18.44858,"qty":40.00000000}],"checksum":2206217721,"timestamp":"2024-06-01T22:42:54.231699Z"}]}
{"channel":"book","type":"update","data":[{"symbol":"LINK/USD","bids":[],"asks":[{"price":18.44862,"qty":0.00000000},{"price":18.45200,"qty":89.93735595}],"checksum":2091434655,"timestamp":"2024-06-01T22:42:54.255384Z"}]}
{"channel":"book","type":"update","data":[{"symbol":"LINK/USD","bids":[],"asks":[{"price":18.45032,"qty":13.55212802}],"checksum":160811861,"timestamp":"2024-06-01T22:42:54.322997Z"}]}
{"channel":"book","type":"update","data":[{"symbol":"LINK/USD","bids":[],"asks":[{"price":18.44861,"qty":0.00000000},{"price":18.45200,"qty":89.93735595},{"price":18.44857,"qty":1.20306513}],"checksum":755916932,"timestamp":"2024-06-01T22:42:54.514093Z"}]}
{"channel":"book","type":"update","data":[{"symbol":"LINK/USD","bids":[],"asks":[{"price":18.44853,"qty":271.02433909}],"checksum":3667529296,"timestamp":"2024-06-01T22:42:54.519197Z"}]}
{"channel":"book","type":"update","data":[{"symbol":"LINK/USD","bids":[{"price":18.44433,"qty":0.00000000},{"price":18.43693,"qty":40.00000000}],"asks":[],"checksum":3906959807,"timestamp":"2024-06-01T22:42:54.521922Z"}]}
{"channel":"book","type":"update","data":[{"symbol":"LINK/USD","bids":[],"asks":[{"price":18.45032,"qty":0.00000000},{"price":18.45172,"qty":9.75909125}],"checksum":1228376888,"timestamp":"2024-06-01T22:42:54.523069Z"}]}
{"channel":"book","type":"update","data":[{"symbol":"LINK/USD","bids":[{"price":18.43693,"qty":0.00000000},{"price":18.43680,"qty":49.17000000}],"asks":[],"checksum":4007536925,"timestamp":"2024-06-01T22:42:54.567092Z"}]}
{"channel":"book","type":"update","data":[{"symbol":"LINK/USD","bids":[],"asks":[{"price":18.44851,"qty":40.00000000}],"checksum":1919642291,"timestamp":"2024-06-01T22:42:54.754787Z"}]}
{"channel":"book","type":"update","data":[{"symbol":"LINK/USD","bids":[],"asks":[{"price":18.44858,"qty":0.00000000},{"price":18.45172,"qty":9.75909125}],"checksum":2333721901,"timestamp":"2024-06-01T22:42:54.758932Z"}]}
{"channel":"book","type":"update","data":[{"symbol":"LINK/USD","bids":[],"asks":[{"price":18.44853,"qty":0.00000000},{"price":18.45200,"qty":89.93735595}],"checksum":2644966992,"timestamp":"2024-06-01T22:42:54.760627Z"}]}
{"channel":"book","type":"update","data":[{"symbol":"LINK/USD","bids":[],"asks":[{"price":18.45032,"qty":13.55213135}],"checksum":952194934,"timestamp":"2024-06-01T22:42:54.765176Z"}]}
{"channel":"book","type":"update","data":[{"symbol":"LINK/USD","bids":[],"asks":[{"price":18.44857,"qty":0.00000000},{"price":18.45200,"qty":89.93735595},{"price":18.44850,"qty":1.20306513}],"checksum":2870418378,"timestamp":"2024-06-01T22:42:54.966208Z"}]}
{"channel":"book","type":"update","data":[{"symbol":"LINK/USD","bids":[{"price":18.43701,"qty":0.00000000},{"price":18.43656,"qty":542.40026605}],"asks":[],"checksum":3862786647,"timestamp":"2024-06-01T22:42:55.564045Z"}]}
{"channel":"book","type":"update","data":[{"symbol":"LINK/USD","bids":[],"asks":[{"price":18.44847,"qty":271.02527049}],"checksum":1656541124,"timestamp":"2024-06-01T22:42:55.630240Z"}]}
{"channel":"book","type":"update","data":[{"symbol":"LINK/USD","bids":[],"asks":[{"price":18.44850,"qty":0.00000000},{"price":18.45172,"qty":9.75909125},{"price":18.44846,"qty":1.20306513}],"checksum":3486211620,"timestamp":"2024-06-01T22:42:55.634094Z"}]}
{"channel":"book","type":"update","data":[{"symbol":"LINK/USD","bids":[],"asks":[{"price":18.45032,"qty":0.00000000},{"price":18.45172,"qty":9.75909125}],"checksum":349946521,"timestamp":"2024-06-01T22:42:55.634341Z"}]}
{"channel":"book","type":"update","data":[{"symbol":"LINK/USD","bids":[],"asks":[{"price":18.44845,"qty":40.00000000}],"checksum":1340740604,"timestamp":"2024-06-01T22:42:55.635225Z"}]}
{"channel":"book","type":"update","data":[{"symbol":"LINK/USD","bids":[],"asks":[{"price":18.44847,"qty":0.00000000},{"price":18.45172,"qty":9.75909125}],"checksum":835997561,"timestamp":"2024-06-01T22:42:55.638661Z"}]}
{"channel":"book","type":"update","data":[{"symbol":"LINK/USD","bids":[],"asks":[{"price":18.45032,"qty":13.55213327}],"checksum":193536038,"timestamp":"2024-06-01T22:42:55.642654Z"}]}
{"channel":"book","type":"update","data":[{"symbol":"LINK/USD","bids":[],"asks":[{"price":18.44845,"qty":0.00000000},{"price":18.45172,"qty":9.75909125}],"checksum":2697091589,"timestamp":"2024-06-01T22:42:55.754625Z"}]}
{"channel":"book","type":"update","data":[{"symbol":"LINK/USD","bids":[],"asks":[{"price":18.44846,"qty":0.00000000},{"price":18.45200,"qty":89.93735595},{"price":18.44850,"qty":1.20306513}],"checksum":1990893304,"timestamp":"2024-06-01T22:42:55.757988Z"}]}
{"channel":"book","type":"update","data":[{"symbol":"LINK/USD","bids":[],"asks":[{"price":18.45100,"qty":186.96555600}],"checksum":2587931629,"timestamp":"2024-06-01T22:42:55.830671Z"}]}
{"channel":"book","type":"update","data":[{"symbol":"LINK/USD","bids":[],"asks":[{"price":18.44858,"qty":40.00000000}],"checksum":25755279,"timestamp":"2024-06-01T22:42:56.254172Z"}]}
{"channel":"book","type":"update","data":[{"symbol":"LINK/USD","bids":[],"asks":[{"price":18.44851,"qty":0.00000000},{"price":18.45163,"qty":70.72221879}],"checksum":4169642371,"timestamp":"2024-06-01T22:42:56.254215Z"}]}
{"channel":"book","type":"update","data":[{"symbol":"LINK/USD","bids":[],"asks":[{"price":18.44850,"qty":0.00000000},{"price":18.45172,"qty":9.75909125},{"price":18.44857,"qty":1.20306513}],"checksum":3504127146,"timestamp":"2024-06-01T22:42:56.257533Z"}]}
{"channel":"book","type":"update","data":[{"symbol":"LINK/USD","bids":[{"price":18.44396,"qty":33.00000000}],"asks":[],"checksum":130584757,"timestamp":"2024-06-01T22:42:56.422867Z"}]}
{"channel":"book","type":"update","data":[{"symbol":"LINK/USD","bids":[],"asks":[{"price":18.44842,"qty":271.02599769}],"checksum":589338092,"timestamp":"2024-06-01T22:42:56.630213Z"}]}
{"channel":"book","type":"update","data":[{"symbol":"LINK/USD","bids":[],"asks":[{"price":18.45032,"qty":0.00000000},{"price":18.45163,"qty":70.72221879}],"checksum":2471411638,"timestamp":"2024-06-01T22:42:56.634422Z"}]}
{"channel":"book","type":"update","data":[{"symbol":"LINK/USD","bids":[],"asks":[{"price":18.44840,"qty":40.00000000}],"checksum":3217878966,"timestamp":"2024-06-01T22:42:56.634937Z"}]}
{"channel":"book","type":"update","data":[{"symbol":"LINK/USD","bids":[],"asks":[{"price":18.44842,"qty":0.00000000},{"price":18.45163,"qty":70.72221879}],"checksum":11015933,"timestamp":"2024-06-01T22:42:56.639500Z"}]}
{"channel":"book","type":"update","data":[{"symbol":"LINK/USD","bids":[],"asks":[{"price":18.45032,"qty":13.55185477}],"checksum":177604411,"timestamp":"2024-06-01T22:42:56.642922Z"}]}
{"channel":"book","type":"update","data":[{"symbol":"LINK/USD","bids":[{"price":18.43854,"qty":0.00000000},{"price":18.43656,"qty":542.40026605}],"asks":[],"checksum":2987039384,"timestamp":"2024-06-01T22:42:56.689153Z"}]}
{"channel":"book","type":"update","data":[{"symbol":"LINK/USD","bids":[],"asks":[{"price":18.44857,"qty":0.00000000},{"price":18.45163,"qty":70.72221879},{"price":18.44839,"qty":1.20306513}],"checksum":3766378498,"timestamp":"2024-06-01T22:42:56.690649Z"}]}
{"channel":"book","type":"update","data":[{"symbol":"LINK/USD","bids":[],"asks":[{"price":18.44840,"qty":0.00000000},{"price":18.45163,"qty":70.72221879}],"checksum":2969607929,"timestamp":"2024-06-01T22:42:56.694994Z"}]}
{"channel":"book","type":"update","data":[{"symbol":"LINK/USD","bids":[],"asks":[{"price":18.44839,"qty":0.00000000},{"price":18.45172,"qty":9.75909125},{"price":18.44857,"qty":1.20306513}],"checksum":874203164,"timestamp":"2024-06-01T22:42:56.705703Z"}]}
{"channel":"book","type":"update","data":[{"symbol":"LINK/USD","bids":[],"asks":[{"price":18.45162,"qty":0.00000000},{"price":18.45172,"qty":9.75909125}],"checksum":3017980352,"timestamp":"2024-06-01T22:42:56.840787Z"}]}
{"channel":"book","type":"update","data":[{"symbol":"LINK/USD","bids":[],"asks":[{"price":18.45099,"qty":1.08427940}],"checksum":1841207407,"timestamp":"2024-06-01T22:42:56.841820Z"}]}
{"channel":"book","type":"update","data":[{"symbol":"LINK/USD","bids":[],"asks":[{"price":18.44836,"qty":271.02683981}],"checksum":1145567899,"timestamp":"2024-06-01T22:42:57.630943Z"}]}
{"channel":"book","type":"update","data":[{"symbol":"LINK/USD","bids":[],"asks":[{"price":18.44857,"qty":0.00000000},{"price":18.45163,"qty":70.72221879},{"price":18.44835,"qty":1.20306513}],"checksum":2297134792,"timestamp":"2024-06-01T22:42:57.634023Z"}]}
{"channel":"book","type":"update","data":[{"symbol":"LINK/USD","bids":[],"asks":[{"price":18.45032,"qty":0.00000000},{"price":18.45163,"qty":70.72221879}],"checksum":1833318964,"timestamp":"2024-06-01T22:42:57.634668Z"}]}
{"channel":"book","type":"update","data":[{"symbol":"LINK/USD","bids":[],"asks":[{"price":18.44836,"qty":0.00000000},{"price":18.45172,"qty":9.75909125}],"checksum":692699752,"timestamp":"2024-06-01T22:42:57.638745Z"}]}
{"channel":"book","type":"update","data":[{"symbol":"LINK/USD","bids":[],"asks":[{"price":18.44835,"qty":0.00000000},{"price":18.45200,"qty":89.93735595},{"price":18.44857,"qty":1.20306513}],"checksum":4070669171,"timestamp":"2024-06-01T22:42:57.642217Z"}]}
{"channel":"book","type":"update","data":[{"symbol":"LINK/USD","bids":[],"asks":[{"price":18.45032,"qty":13.55181997}],"checksum":262239853,"timestamp":"2024-06-01T22:42:57.643236Z"}]}
{"channel":"book","type":"update","data":[{"symbol":"LINK/USD","bids":[],"asks":[{"price":18.45032,"qty":0.00000000},{"price":18.45172,"qty":9.75909125}],"checksum":4070669171,"timestamp":"2024-06-01T22:42:57.733050Z"}]}
{"channel":"book","type":"update","data":[{"symbol":"LINK/USD","bids":[],"asks":[{"price":18.44869,"qty":9.72891506}],"checksum":4287140455,"timestamp":"2024-06-01T22:42:57.733174Z"}]}
{"channel":"book","type":"update","data":[{"symbol":"LINK/USD","bids":[],"asks":[{"price":18.44869,"qty":0.00000000},{"price":18.45172,"qty":9.75909125}],"checksum":4070669171,"timestamp":"2024-06-01T22:42:57.736399Z"}]}
{"channel":"book","type":"update","data":[{"symbol":"LINK/USD","bids":[],"asks":[{"price":18.44857,"qty":14.75488470}],"checksum":104334700,"timestamp":"2024-06-01T22:42:57.736473Z"}]}
{"channel":"book","type":"update","data":[{"symbol":"LINK/USD","bids":[{"price":18.44092,"qty":0.00000000},{"price":18.43397,"qty":135.28864495}],"asks":[],"checksum":2855041014,"timestamp":"2024-06-01T22:42:57.756645Z"}]}
{"channel":"book","type":"update","data":[{"symbol":"LINK/USD","bids":[{"price":18.43397,"qty":0.00000000},{"price":18.43155,"qty":19.20000000}],"asks":[],"checksum":4293806548,"timestamp":"2024-06-01T22:42:57.848290Z"}]}
{"channel":"book","type":"update","data":[{"symbol":"LINK/USD","bids":[{"price":18.44075,"qty":129.20883268}],"asks":[],"checksum":2100619211,"timestamp":"2024-06-01T22:42:57.876968Z"}]}
{"channel":"book","type":"update","data":[{"symbol":"LINK/USD","bids":[],"asks":[{"price":18.44857,"qty":13.55181957},{"price":18.44856,"qty":1.20306513}],"checksum":1210600588,"timestamp":"2024-06-01T22:42:58.090569Z"}]}
{"channel":"book","type":"update","data":[{"symbol":"LINK/USD","bids":[],"asks":[{"price":18.44857,"qty":0.00000000},{"price":18.45172,"qty":9.75909125}],"checksum":168311701,"timestamp":"2024-06-01T22:42:58.094220Z"}]}
{"channel":"book","type":"update","data":[{"symbol":"LINK/USD","bids":[],"asks":[{"price":18.44856,"qty":0.00000000},{"price":18.45200,"qty":89.93735595},{"price":18.44857,"qty":1.20306513}],"checksum":2309855700,"timestamp":"2024-06-01T22:42:58.097280Z"}]}
{"channel":"book","type":"update","data":[{"symbol":"LINK/USD","bids":[{"price":18.44396,"qty":0.00000000},{"price":18.43379,"qty":135.28864495}],"asks":[],"checksum":1437898498,"timestamp":"2024-06-01T22:42:58.361193Z"}]}
{"channel":"book","type":"update","data":[{"symbol":"LINK/USD","bids":[{"price":18.44393,"qty":0.00000000},{"price":18.43155,"qty":19.20000000}],"asks":[],"checksum":223829099,"timestamp":"2024-06-01T22:42:58.520328Z"}]}
{"channel":"book","type":"update","data":[{"symbol":"LINK/USD","bids":[],"asks":[{"price":18.45033,"qty":0.00000000},{"price":18.45200,"qty":89.93735595}],"checksum":1851295897,"timestamp":"2024-06-01T22:42:58.523120Z"}]}
{"channel":"book","type":"update","data":[{"symbol":"LINK/USD","bids":[{"price":18.44187,"qty":33.00000000}],"asks":[],"checksum":512399283,"timestamp":"2024-06-01T22:42:58.523197Z"}]}
{"channel":"book","type":"update","data":[{"symbol":"LINK/USD","bids":[],"asks":[{"price":18.44857,"qty":34.20306513}],"checksum":3234830336,"timestamp":"2024-06-01T22:42:58.523234Z"}]}
{"channel":"book","type":"update","data":[{"symbol":"LINK/USD","bids":[{"price":18.44076,"qty":243.48672997}],"asks":[],"checksum":441200090,"timestamp":"2024-06-01T22:42:58.524489Z"}]}
{"channel":"book","type":"update","data":[{"symbol":"LINK/USD","bids":[{"price":18.44140,"qty":0.00000000},{"price":18.43379,"qty":135.28864495}],"asks":[],"checksum":1232168550,"timestamp":"2024-06-01T22:42:58.524522Z"}]}
{"channel":"book","type":"update","data":[{"symbol":"LINK/USD","bids":[{"price":18.44267,"qty":271.11036381}],"asks":[],"checksum":1156607966,"timestamp":"2024-06-01T22:42:58.524703Z"}]}
{"channel":"book","type":"update","data":[{"symbol":"LINK/USD","bids":[],"asks":[{"price":18.44831,"qty":271.02759315}],"checksum":2525768952,"timestamp":"2024-06-01T22:42:58.524730Z"}]}
{"channel":"book","type":"update","data":[{"symbol":"LINK/USD","bids":[],"asks":[{"price":18.44857,"qty":33.00000000},{"price":18.44830,"qty":1.20306513}],"checksum":1409183343,"timestamp":"2024-06-01T22:42:58.537349Z"}]}
{"channel":"book","type":"update","data":[{"symbol":"LINK/USD","bids":[],"asks":[{"price":18.44831,"qty":0.00000000},{"price":18.45172,"qty":9.75909125}],"checksum":3288943568,"timestamp":"2024-06-01T22:42:58.541647Z"}]}
{"channel":"book","type":"update","data":[{"symbol":"LINK/USD","bids":[],"asks":[{"price":18.44830,"qty":0.00000000},{"price":18.45200,"qty":89.93735595},{"price":18.44856,"qty":1.20306513}],"checksum":2095345932,"timestamp":"2024-06-01T22:42:58.544779Z"}]}
{"channel":"book","type":"update","data":[{"symbol":"LINK/USD","bids":[{"price":18.43656,"qty":0.00000000},{"price":18.43379,"qty":135.28864495}],"asks":[],"checksum":1224209544,"timestamp":"2024-06-01T22:42:58.551563Z"}]}
{"channel":"book","type":"update","data":[{"symbol":"LINK/USD","bids":[{"price":18.43379,"qty":0.00000000},{"price":18.43184,"qty":542.53916880}],"asks":[],"checksum":2650687419,"timestamp":"2024-06-01T22:42:58.560382Z"}]}
{"channel":"book","type":"update","data":[{"symbol":"LINK/USD","bids":[{"price":18.44187,"qty":0.00000000},{"price":18.43155,"qty":19.20000000}],"asks":[],"checksum":493593536,"timestamp":"2024-06-01T22:42:58.571365Z"}]}
{"channel":"book","type":"update","data":[{"symbol":"LINK/USD","bids":[{"price":18.44281,"qty":33.00000000}],"asks":[],"checksum":748391816,"timestamp":"2024-06-01T22:42:58.571536Z"}]}
{"channel":"book","type":"update","data":[{"symbol":"LINK/USD","bids":[],"asks":[{"price":18.44855,"qty":40.00000000}],"checksum":2202291920,"timestamp":"2024-06-01T22:42:58.575958Z"}]}
{"channel":"book","type":"update","data":[{"symbol":"LINK/USD","bids":[],"asks":[{"price":18.45114,"qty":406.47905419}],"checksum":446107539,"timestamp":"2024-06-01T22:42:58.594665Z"}]}
{"channel":"book","type":"update","data":[{"symbol":"LINK/USD","bids":[],"asks":[{"price":18.44858,"qty":0.00000000},{"price":18.45163,"qty":70.72221879}],"checksum":7164140,"timestamp":"2024-06-01T22:42:58.754632Z"}]}
{"channel":"book","type":"update","data":[{"symbol":"LINK/USD","bids":[],"asks":[{"price":18.44857,"qty":0.00000000},{"price":18.45172,"qty":9.75909125}],"checksum":3317753616,"timestamp":"2024-06-01T22:42:58.757389Z"}]}
{"channel":"book","type":"update","data":[{"symbol":"LINK/USD","bids":[],"asks":[{"price":18.44848,"qty":33.00000000}],"checksum":545167599,"timestamp":"2024-06-01T22:42:58.757637Z"}]}
{"channel":"book","type":"update","data":[{"symbol":"LINK/USD","bids":[{"price":18.43627,"qty":40.00000000}],"asks":[],"checksum":1129693057,"timestamp":"2024-06-01T22:42:58.894693Z"}]}
{"channel":"book","type":"update","data":[{"symbol":"LINK/USD","bids":[],"asks":[{"price":18.44856,"qty":0.00000000},{"price":18.45172,"qty":9.75909125},{"price":18.44847,"qty":1.20306513}],"checksum":148084851,"timestamp":"2024-06-01T22:42:59.051713Z"}]}
{"channel":"book","type":"update","data":[{"symbol":"LINK/USD","bids":[],"asks":[{"price":18.44846,"qty":40.00000000}],"checksum":1038823253,"timestamp":"2024-06-01T22:42:59.056711Z"}]}
{"channel":"book","type":"update","data":[{"symbol":"LINK/USD","bids":[],"asks":[{"price":18.44718,"qty":271.04422934}],"checksum":1752372121,"timestamp":"2024-06-01T22:42:59.070499Z"}]}
{"channel":"book","type":"update","data":[{"symbol":"LINK/USD","bids":[],"asks":[{"price":18.44845,"qty":13.55347717}],"checksum":3359269032,"timestamp":"2024-06-01T22:42:59.160977Z"}]}
{"channel":"book","type":"update","data":[{"symbol":"LINK/USD","bids":[],"asks":[{"price":18.44846,"qty":0.00000000},{"price":18.45100,"qty":186.96555600}],"checksum":206596578,"timestamp":"2024-06-01T22:42:59.166188Z"}]}
{"channel":"book","type":"update","data":[{"symbol":"LINK/USD","bids":[{"price":18.43627,"qty":0.00000000},{"price":18.43184,"qty":542.53916880}],"asks":[],"checksum":4102729179,"timestamp":"2024-06-01T22:42:59.352300Z"}]}
{"channel":"book","type":"update","data":[{"symbol":"LINK/USD","bids":[],"asks":[{"price":18.44847,"qty":0.00000000},{"price":18.45114,"qty":406.47905419},{"price":18.44717,"qty":1.20306513}],"checksum":3490670079,"timestamp":"2024-06-01T22:42:59.556052Z"}]}
{"channel":"book","type":"update","data":[{"symbol":"LINK/USD","bids":[],"asks":[{"price":18.45099,"qty":0.00000000},{"price":18.45114,"qty":406.47905419}],"checksum":4275050601,"timestamp":"2024-06-01T22:42:59.579833Z"}]}
{"channel":"book","type":"update","data":[{"symbol":"LINK/USD","bids":[],"asks":[{"price":18.45099,"qty":5.31553646}],"checksum":1578272058,"timestamp":"2024-06-01T22:42:59.580858Z"}]}
{"channel":"book","type":"update","data":[{"symbol":"LINK/USD","bids":[{"price":18.44257,"qty":0.00000000},{"price":18.43155,"qty":19.20000000},{"price":18.44066,"qty":19.20000000}],"asks":[],"checksum":884284493,"timestamp":"2024-06-01T22:43:00.074454Z"}]}
{"channel":"book","type":"update","data":[{"symbol":"LINK/USD","bids":[],"asks":[{"price":18.45081,"qty":0.00000000},{"price":18.45114,"qty":406.47905419},{"price":18.44902,"qty":19.20000000}],"checksum":3101852831,"timestamp":"2024-06-01T22:43:00.078627Z"}]}
{"channel":"book","type":"update","data":[{"symbol":"LINK/USD","bids":[],"asks":[{"price":18.44902,"qty":38.40000000}],"checksum":2438386523,"timestamp":"2024-06-01T22:43:00.078745Z"}]}
{"channel":"book","type":"update","data":[{"symbol":"LINK/USD","bids":[{"price":18.44281,"qty":0.00000000},{"price":18.43142,"qty":13.80000000}],"asks":[],"checksum":1549750495,"timestamp":"2024-06-01T22:43:01.671672Z"}]}
{"channel":"book","type":"update","data":[{"symbol":"LINK/USD","bids":[],"asks":[{"price":18.44718,"qty":0.00000000},{"price":18.45114,"qty":406.47905419}],"checksum":2329582243,"timestamp":"2024-06-01T22:43:01.823909Z"}]}
{"channel":"book","type":"update","data":[{"symbol":"LINK/USD","bids":[],"asks":[{"price":18.44717,"qty":0.00000000},{"price":18.45163,"qty":70.72221879},{"price":18.44844,"qty":1.20306513}],"checksum":1194632950,"timestamp":"2024-06-01T22:43:01.827204Z"}]}
{"channel":"book","type":"update","data":[{"symbol":"LINK/USD","bids":[],"asks":[{"price":18.44713,"qty":271.04494602}],"checksum":2163846288,"timestamp":"2024-06-01T22:43:01.827428Z"}]}
{"channel":"book","type":"update","data":[{"symbol":"LINK/USD","bids":[],"asks":[{"price":18.44846,"qty":40.00000000}],"checksum":767862266,"timestamp":"2024-06-01T22:43:01.828865Z"}]}
{"channel":"book","type":"update","data":[{"symbol":"LINK/USD","bids":[],"asks":[{"price":18.44843,"qty":9.72725786}],"checksum":741438332,"timestamp":"2024-06-01T22:43:01.831258Z"}]}
{"channel":"book","type":"update","data":[{"symbol":"LINK/USD","bids":[],"asks":[{"price":18.44845,"qty":0.00000000},{"price":18.45099,"qty":5.31553646}],"checksum":3929488702,"timestamp":"2024-06-01T22:43:01.831294Z"}]}
{"channel":"book","type":"update","data":[{"symbol":"LINK/USD","bids":[{"price":18.43982,"qty":0.00000000},{"price":18.42879,"qty":270.40000000}],"asks":[],"checksum":2612900914,"timestamp":"2024-06-01T22:43:01.974523Z"}]}
{"channel":"book","type":"update","data":[{"symbol":"LINK/USD","bids":[{"price":18.43760,"qty":406.77741718}],"asks":[],"checksum":4096241515,"timestamp":"2024-06-01T22:43:01.977999Z"}]}
{"channel":"book","type":"update","data":[{"symbol":"LINK/USD","bids":[],"asks":[{"price":18.45098,"qty":76.08123619}],"checksum":1920367659,"timestamp":"2024-06-01T22:43:01.980375Z"}]}
{"channel":"book","type":"update","data":[{"symbol":"LINK/USD","bids":[{"price":18.43761,"qty":2.34929424}],"asks":[],"checksum":655577385,"timestamp":"2024-06-01T22:43:01.991829Z"}]}
{"channel":"book","type":"update","data":[{"symbol":"LINK/USD","bids":[{"price":18.43983,"qty":0.00000000},{"price":18.43142,"qty":13.80000000}],"asks":[],"checksum":1209987291,"timestamp":"2024-06-01T22:43:01.991980Z"}]}
{"channel":"book","type":"update","data":[{"symbol":"LINK/USD","bids":[],"asks":[{"price":18.44846,"qty":0.00000000},{"price":18.45099,"qty":5.31553646}],"checksum":3012141202,"timestamp":"2024-06-01T22:43:01.996188Z"}]}
{"channel":"book","type":"update","data":[{"symbol":"LINK/USD","bids":[],"asks":[{"price":18.44844,"qty":0.00000000},{"price":18.45100,"qty":186.96555600},{"price":18.44712,"qty":1.20306513}],"checksum":755036452,"timestamp":"2024-06-01T22:43:02.245796Z"}]}
{"channel":"book","type":"update","data":[{"symbol":"LINK/USD","bids":[],"asks":[{"price":18.45099,"qty":0.00000000},{"price":18.45100,"qty":186.96555600}],"checksum":42656519,"timestamp":"2024-06-01T22:43:02.284248Z"}]}
{"channel":"book","type":"update","data":[{"symbol":"LINK/USD","bids":[],"asks":[{"price":18.45097,"qty":9.54751753}],"checksum":3141863111,"timestamp":"2024-06-01T22:43:02.285306Z"}]}
{"channel":"book","type":"update","data":[{"symbol":"LINK/USD","bids":[],"asks":[{"price":18.45097,"qty":0.00000000},{"price":18.45100,"qty":186.96555600}],"checksum":42656519,"timestamp":"2024-06-01T22:43:04.984943Z"}]}
{"channel":"book","type":"update","data":[{"symbol":"LINK/USD","bids":[],"asks":[{"price":18.45097,"qty":18.01066707}],"checksum":1460998317,"timestamp":"2024-06-01T22:43:04.986015Z"}]}
{"channel":"book","type":"update","data":[{"symbol":"LINK/USD","bids":[],"asks":[{"price":18.44713,"qty":0.00000000},{"price":18.45100,"qty":186.96555600}],"checksum":44609657,"timestamp":"2024-06-01T22:43:07.267187Z"}]}
{"channel":"book","type":"update","data":[{"symbol":"LINK/USD","bids":[],"asks":[{"price":18.44708,"qty":271.04567333}],"checksum":1394877151,"timestamp":"2024-06-01T22:43:07.271408Z"}]}
{"channel":"book","type":"update","data":[{"symbol":"LINK/USD","bids":[],"asks":[{"price":18.44843,"qty":0.00000000},{"price":18.45100,"qty":186.96555600}],"checksum":2826945844,"timestamp":"2024-06-01T22:43:07.271444Z"}]}
{"channel":"book","type":"update","data":[{"symbol":"LINK/USD","bids":[],"asks":[{"price":18.44847,"qty":13.55305443}],"checksum":4145961177,"timestamp":"2024-06-01T22:43:07.271614Z"}]}
{"channel":"book","type":"update","data":[{"symbol":"LINK/USD","bids":[],"asks":[{"price":18.44712,"qty":0.00000000},{"price":18.45100,"qty":186.96555600},{"price":18.44842,"qty":1.20306513}],"checksum":1550641732,"timestamp":"2024-06-01T22:43:07.272098Z"}]}
{"channel":"book","type":"update","data":[{"symbol":"LINK/USD","bids":[],"asks":[{"price":18.44846,"qty":40.00000000}],"checksum":1601262540,"timestamp":"2024-06-01T22:43:07.272353Z"}]}
{"channel":"book","type":"update","data":[{"symbol":"LINK/USD","bids":[],"asks":[{"price":18.44847,"qty":0.00000000},{"price":18.45098,"qty":76.08123619}],"checksum":867230847,"timestamp":"2024-06-01T22:43:07.275078Z"}]}
{"channel":"book","type":"update","data":[{"symbol":"LINK/USD","bids":[],"asks":[{"price":18.44846,"qty":49.72768060}],"checksum":1157133661,"timestamp":"2024-06-01T22:43:07.275255Z"}]}
{"channel":"book","type":"update","data":[{"symbol":"LINK/USD","bids":[],"asks":[{"price":18.44841,"qty":13.55305443}],"checksum":4015299436,"timestamp":"2024-06-01T22:43:07.277943Z"}]}
{"channel":"book","type":"update","data":[{"symbol":"LINK/USD","bids":[],"asks":[{"price":18.44846,"qty":40.00000000}],"checksum":1576475207,"timestamp":"2024-06-01T22:43:07.277973Z"}]}
{"channel":"book","type":"update","data":[{"symbol":"LINK/USD","bids":[],"asks":[{"price":18.44860,"qty":0.00000000},{"price":18.45098,"qty":76.08123619}],"checksum":1293325847,"timestamp":"2024-06-01T22:43:07.330126Z"}]}
{"channel":"book","type":"update","data":[{"symbol":"LINK/USD","bids":[],"asks":[{"price":18.44842,"qty":0.00000000},{"price":18.45100,"qty":186.96555600},{"price":18.44707,"qty":1.20306513}],"checksum":1657653382,"timestamp":"2024-06-01T22:43:07.373801Z"}]}
{"channel":"book","type":"update","data":[{"symbol":"LINK/USD","bids":[],"asks":[{"price":18.44870,"qty":0.00000000},{"price":18.45100,"qty":186.96555600}],"checksum":3640043764,"timestamp":"2024-06-01T22:43:07.377100Z"}]}
{"channel":"book","type":"update","data":[{"symbol":"LINK/USD","bids":[],"asks":[{"price":18.44846,"qty":0.00000000},{"price":18.45114,"qty":406.47905419}],"checksum":439784054,"timestamp":"2024-06-01T22:43:07.378196Z"}]}
{"channel":"book","type":"update","data":[{"symbol":"LINK/USD","bids":[],"asks":[{"price":18.44708,"qty":0.00000000},{"price":18.45172,"qty":9.75909125}],"checksum":2970076704,"timestamp":"2024-06-01T22:43:07.378398Z"}]}
{"channel":"book","type":"update","data":[{"symbol":"LINK/USD","bids":[],"asks":[{"price":18.44707,"qty":0.00000000},{"price":18.45200,"qty":89.93735595},{"price":18.44840,"qty":1.20306513}],"checksum":1558474080,"timestamp":"2024-06-01T22:43:07.381958Z"}]}
{"channel":"book","type":"update","data":[{"symbol":"LINK/USD","bids":[],"asks":[{"price":18.44841,"qty":0.00000000},{"price":18.45200,"qty":89.93735595}],"checksum":315456187,"timestamp":"2024-06-01T22:43:07.385586Z"}]}
{"channel":"book","type":"update","data":[{"symbol":"LINK/USD","bids":[],"asks":[{"price":18.44839,"qty":9.72768060}],"checksum":228116522,"timestamp":"2024-06-01T22:43:07.385651Z"}]}
{"channel":"book","type":"update","data":[{"symbol":"LINK/USD","bids":[],"asks":[{"price":18.44840,"qty":0.00000000},{"price":18.45200,"qty":89.93735595},{"price":18.44847,"qty":1.20306513}],"checksum":1198435906,"timestamp":"2024-06-01T22:43:07.388550Z"}]}
{"channel":"book","type":"update","data":[{"symbol":"LINK/USD","bids":[],"asks":[{"price":18.44839,"qty":0.00000000},{"price":18.45200,"qty":89.93735595}],"checksum":340219335,"timestamp":"2024-06-01T22:43:07.389374Z"}]}
{"channel":"book","type":"update","data":[{"symbol":"LINK/USD","bids":[],"asks":[{"price":18.44838,"qty":13.55298152}],"checksum":2600745312,"timestamp":"2024-06-01T22:43:07.389593Z"}]}
{"channel":"book","type":"update","data":[{"symbol":"LINK/USD","bids":[],"asks":[{"price":18.44838,"qty":0.00000000},{"price":18.45200,"qty":89.93735595}],"checksum":340219335,"timestamp":"2024-06-01T22:43:07.393768Z"}]}
{"channel":"book","type":"update","data":[{"symbol":"LINK/USD","bids":[],"asks":[{"price":18.44837,"qty":9.72775351}],"checksum":4032785752,"timestamp":"2024-06-01T22:43:07.393876Z"}]}
{"channel":"book","type":"update","data":[{"symbol":"LINK/USD","bids":[],"asks":[{"price":18.44847,"qty":0.00000000},{"price":18.45200,"qty":89.93735595},{"price":18.44836,"qty":1.20306513}],"checksum":3263989020,"timestamp":"2024-06-01T22:43:07.432618Z"}]}
{"channel":"book","type":"update","data":[{"symbol":"LINK/USD","bids":[],"asks":[{"price":18.44837,"qty":0.00000000},{"price":18.45200,"qty":89.93735595}],"checksum":1286223451,"timestamp":"2024-06-01T22:43:07.436368Z"}]}
{"channel":"book","type":"update","data":[{"symbol":"LINK/USD","bids":[],"asks":[{"price":18.44835,"qty":13.55297520}],"checksum":445964474,"timestamp":"2024-06-01T22:43:07.436449Z"}]}
{"channel":"book","type":"update","data":[{"symbol":"LINK/USD","bids":[],"asks":[{"price":18.44846,"qty":40.00000000}],"checksum":1006067311,"timestamp":"2024-06-01T22:43:07.437345Z"}]}
{"channel":"book","type":"update","data":[{"symbol":"LINK/USD","bids":[],"asks":[{"price":18.44836,"qty":0.00000000},{"price":18.45172,"qty":9.75909125},{"price":18.44847,"qty":1.20306513}],"checksum":628169796,"timestamp":"2024-06-01T22:43:07.439285Z"}]}
{"channel":"book","type":"update","data":[{"symbol":"LINK/USD","bids":[],"asks":[{"price":18.44836,"qty":135.28864495}],"checksum":2313946943,"timestamp":"2024-06-01T22:43:07.454823Z"}]}
{"channel":"book","type":"update","data":[{"symbol":"LINK/USD","bids":[],"asks":[{"price":18.44848,"qty":0.00000000},{"price":18.45114,"qty":406.47905419}],"checksum":460052763,"timestamp":"2024-06-01T22:43:07.457471Z"}]}
{"channel":"book","type":"update","data":[{"symbol":"LINK/USD","bids":[],"asks":[{"price":18.44838,"qty":33.00000000}],"checksum":1252291111,"timestamp":"2024-06-01T22:43:07.457747Z"}]}
{"channel":"book","type":"update","data":[{"symbol":"LINK/USD","bids":[],"asks":[{"price":18.44834,"qty":31.62427630}],"checksum":1767085605,"timestamp":"2024-06-01T22:43:07.487991Z"}]}
{"channel":"book","type":"update","data":[{"symbol":"LINK/USD","bids":[{"price":18.44077,"qty":10.84239599}],"asks":[],"checksum":3991515992,"timestamp":"2024-06-01T22:43:07.492043Z"}]}
{"channel":"book","type":"update","data":[{"symbol":"LINK/USD","bids":[],"asks":[{"price":18.44835,"qty":0.00000000},{"price":18.45100,"qty":186.96555600}],"checksum":2108975996,"timestamp":"2024-06-01T22:43:07.492072Z"}]}
{"channel":"book","type":"update","data":[{"symbol":"LINK/USD","bids":[],"asks":[{"price":18.44833,"qty":9.72775983}],"checksum":3274739759,"timestamp":"2024-06-01T22:43:07.492134Z"}]}
{"channel":"book","type":"update","data":[{"symbol":"LINK/USD","bids":[],"asks":[{"price":18.44846,"qty":0.00000000},{"price":18.45100,"qty":186.96555600}],"checksum":75584134,"timestamp":"2024-06-01T22:43:07.492423Z"}]}
{"channel":"book","type":"update","data":[{"symbol":"LINK/USD","bids":[{"price":18.43185,"qty":265.97116089}],"asks":[],"checksum":4009225395,"timestamp":"2024-06-01T22:43:07.581543Z"}]}
{"channel":"book","type":"update","data":[{"symbol":"LINK/USD","bids":[],"asks":[{"price":18.44847,"qty":0.00000000},{"price":18.45114,"qty":406.47905419},{"price":18.44832,"qty":1.20306513}],"checksum":2278291493,"timestamp":"2024-06-01T22:43:07.591557Z"}]}
{"channel":"book","type":"update","data":[{"symbol":"LINK/USD","bids":[],"asks":[{"price":18.44833,"qty":0.00000000},{"price":18.45114,"qty":406.47905419}],"checksum":2767661032,"timestamp":"2024-06-01T22:43:07.595780Z"}]}
{"channel":"book","type":"update","data":[{"symbol":"LINK/USD","bids":[],"asks":[{"price":18.44831,"qty":13.55297520}],"checksum":2521580072,"timestamp":"2024-06-01T22:43:07.595843Z"}]}
{"channel":"book","type":"update","data":[{"symbol":"LINK/USD","bids":[],"asks":[{"price":18.44832,"qty":0.00000000},{"price":18.45114,"qty":406.47905419},{"price":18.44833,"qty":1.20306513}],"checksum":129692330,"timestamp":"2024-06-01T22:43:07.599157Z"}]}
{"channel":"book","type":"update","data":[{"symbol":"LINK/USD","bids":[],"asks":[{"price":18.44831,"qty":0.00000000},{"price":18.45114,"qty":406.47905419}],"checksum":4012001680,"timestamp":"2024-06-01T22:43:07.600289Z"}]}
{"channel":"book","type":"update","data":[{"symbol":"LINK/USD","bids":[],"asks":[{"price":18.44830,"qty":9.72775983}],"checksum":1824979120,"timestamp":"2024-06-01T22:43:07.600312Z"}]}
{"channel":"book","type":"update","data":[{"symbol":"LINK/USD","bids":[],"asks":[{"price":18.44830,"qty":0.00000000},{"price":18.45114,"qty":406.47905419}],"checksum":4012001680,"timestamp":"2024-06-01T22:43:07.603889Z"}]}
{"channel":"book","type":"update","data":[{"symbol":"LINK/USD","bids":[],"asks":[{"price":18.44825,"qty":271.02850988}],"checksum":1003081659,"timestamp":"2024-06-01T22:43:07.605519Z"}]}
{"channel":"book","type":"update","data":[{"symbol":"LINK/USD","bids":[],"asks":[{"price":18.44838,"qty":0.00000000},{"price":18.45114,"qty":406.47905419}],"checksum":1298232915,"timestamp":"2024-06-01T22:43:07.608091Z"}]}
{"channel":"book","type":"update","data":[{"symbol":"LINK/USD","bids":[],"asks":[{"price":18.44819,"qty":33.00000000}],"checksum":2300917688,"timestamp":"2024-06-01T22:43:07.608304Z"}]}
{"channel":"book","type":"update","data":[{"symbol":"LINK/USD","bids":[],"asks":[{"price":18.44825,"qty":0.00000000},{"price":18.45114,"qty":406.47905419}],"checksum":3202157396,"timestamp":"2024-06-01T22:43:07.612575Z"}]}
{"channel":"book","type":"update","data":[{"symbol":"LINK/USD","bids":[],"asks":[{"price":18.45097,"qty":0.00000000},{"price":18.45172,"qty":9.75909125}],"checksum":3111497719,"timestamp":"2024-06-01T22:43:07.728083Z"}]}
{"channel":"book","type":"update","data":[{"symbol":"LINK/USD","bids":[],"asks":[{"price":18.44834,"qty":33.76653756}],"checksum":865678736,"timestamp":"2024-06-01T22:43:07.729184Z"}]}
{"channel":"book","type":"update","data":[{"symbol":"LINK/USD","bids":[],"asks":[{"price":18.45097,"qty":21.18434823}],"checksum":3265781930,"timestamp":"2024-06-01T22:43:07.729483Z"}]}
{"channel":"book","type":"update","data":[{"symbol":"LINK/USD","bids":[{"price":18.44077,"qty":0.00000000},{"price":18.43184,"qty":542.53916880}],"asks":[],"checksum":974990872,"timestamp":"2024-06-01T22:43:07.731808Z"}]}
{"channel":"book","type":"update","data":[{"symbol":"LINK/USD","bids":[],"asks":[{"price":18.44833,"qty":0.00000000},{"price":18.45172,"qty":9.75909125},{"price":18.44818,"qty":1.20306513}],"checksum":3575371955,"timestamp":"2024-06-01T22:43:07.817907Z"}]}
{"channel":"book","type":"update","data":[{"symbol":"LINK/USD","bids":[],"asks":[{"price":18.44817,"qty":33.76653756}],"checksum":2112617938,"timestamp":"2024-06-01T22:43:08.095613Z"}]}
{"channel":"book","type":"update","data":[{"symbol":"LINK/USD","bids":[],"asks":[{"price":18.44818,"qty":0.00000000},{"price":18.45114,"qty":406.47905419},{"price":18.44816,"qty":1.20306513}],"checksum":1126942035,"timestamp":"2024-06-01T22:43:08.111063Z"}]}
{"channel":"book","type":"update","data":[{"symbol":"LINK/USD","bids":[],"asks":[{"price":18.44814,"qty":271.03010977}],"checksum":3375971717,"timestamp":"2024-06-01T22:43:08.632160Z"}]}
{"channel":"book","type":"update","data":[{"symbol":"LINK/USD","bids":[],"asks":[{"price":18.44813,"qty":13.55300151}],"checksum":2425755816,"timestamp":"2024-06-01T22:43:08.636311Z"}]}
{"channel":"book","type":"update","data":[{"symbol":"LINK/USD","bids":[],"asks":[{"price":18.44816,"qty":0.00000000},{"price":18.45098,"qty":76.08123619},{"price":18.44813,"qty":14.75606664}],"checksum":85979991,"timestamp":"2024-06-01T22:43:08.636380Z"}]}
{"channel":"book","type":"update","data":[{"symbol":"LINK/USD","bids":[],"asks":[{"price":18.44813,"qty":1.20306513}],"checksum":837378094,"timestamp":"2024-06-01T22:43:08.639341Z"}]}
{"channel":"book","type":"update","data":[{"symbol":"LINK/USD","bids":[],"asks":[{"price":18.44814,"qty":0.00000000},{"price":18.45100,"qty":186.96555600}],"checksum":4242150538,"timestamp":"2024-06-01T22:43:08.640748Z"}]}
{"channel":"book","type":"update","data":[{"symbol":"LINK/USD","bids":[],"asks":[{"price":18.44813,"qty":0.00000000},{"price":18.45114,"qty":406.47905419},{"price":18.44816,"qty":1.20306513}],"checksum":1126942035,"timestamp":"2024-06-01T22:43:08.643577Z"}]}
{"channel":"book","type":"update","data":[{"symbol":"LINK/USD","bids":[],"asks":[{"price":18.44808,"qty":271.03098245}],"checksum":3199496835,"timestamp":"2024-06-01T22:43:09.630879Z"}]}
{"channel":"book","type":"update","data":[{"symbol":"LINK/USD","bids":[],"asks":[{"price":18.44816,"qty":0.00000000},{"price":18.45100,"qty":186.96555600},{"price":18.44807,"qty":1.20306513}],"checksum":1523894866,"timestamp":"2024-06-01T22:43:09.634209Z"}]}
{"channel":"book","type":"update","data":[{"symbol":"LINK/USD","bids":[],"asks":[{"price":18.44808,"qty":0.00000000},{"price":18.45100,"qty":186.96555600}],"checksum":1449887563,"timestamp":"2024-06-01T22:43:09.639346Z"}]}
{"channel":"book","type":"update","data":[{"symbol":"LINK/USD","bids":[],"asks":[{"price":18.44807,"qty":0.00000000},{"price":18.45114,"qty":406.47905419},{"price":18.44816,"qty":1.20306513}],"checksum":1126942035,"timestamp":"2024-06-01T22:43:09.642272Z"}]}
