{"channel":"book","type":"snapshot","data":[{"symbol":"LINK/BTC","bids":[{"price":0.00027244,"qty":664.40875000},{"price":0.00027242,"qty":27.10160438},{"price":0.00027232,"qty":200.00000000},{"price":0.00027231,"qty":27.11257033},{"price":0.00027229,"qty":45.20000000},{"price":0.00027225,"qty":27.11567071},{"price":0.00027219,"qty":149.84610000},{"price":0.00027214,"qty":217.68605000},{"price":0.00027208,"qty":3.92437002},{"price":0.00027207,"qty":915.42645000}],"asks":[{"price":0.00027252,"qty":45.20000000},{"price":0.00027256,"qty":27.08937958},{"price":0.00027263,"qty":200.00000000},{"price":0.00027266,"qty":27.07529139},{"price":0.00027278,"qty":27.06721570},{"price":0.00027280,"qty":91.64222873},{"price":0.00027297,"qty":13.77428390},{"price":0.00027299,"qty":268.78162032},{"price":0.00027300,"qty":88.51378950},{"price":0.00027311,"qty":70.54889631}],"checksum":2756960087}]}
{"channel":"book","type":"update","data":[{"symbol":"LINK/BTC","bids":[],"asks":[{"price":0.00027297,"qty":0.00000000},{"price":0.00027312,"qty":42.28000000}],"checksum":812965156,"timestamp":"2024-06-01T22:42:45.956301Z"}]}
{"channel":"book","type":"update","data":[{"symbol":"LINK/BTC","bids":[],"asks":[{"price":0.00027298,"qty":14.83095738}],"checksum":847123178,"timestamp":"2024-06-01T22:42:45.957434Z"}]}
{"channel":"book","type":"update","data":[{"symbol":"LINK/BTC","bids":[{"price":0.00027244,"qty":205.20000000}],"asks":[],"checksum":759178166,"timestamp":"2024-06-01T22:42:46.957576Z"}]}
{"channel":"book","type":"update","data":[{"symbol":"LINK/BTC","bids":[{"price":0.00027245,"qty":459.20875000}],"asks":[],"checksum":1888929208,"timestamp":"2024-06-01T22:42:46.960653Z"}]}
{"channel":"book","type":"update","data":[{"symbol":"LINK/BTC","bids":[{"price":0.00027208,"qty":0.00000000},{"price":0.00027207,"qty":915.42645000}],"asks":[],"checksum":875087612,"timestamp":"2024-06-01T22:42:47.287215Z"}]}
{"channel":"book","type":"update","data":[{"symbol":"LINK/BTC","bids":[{"price":0.00027208,"qty":5.26756262}],"asks":[],"checksum":1310660596,"timestamp":"2024-06-01T22:42:47.291838Z"}]}
{"channel":"book","type":"update","data":[{"symbol":"LINK/BTC","bids":[],"asks":[{"price":0.00027299,"qty":123.59000000}],"checksum":2263711392,"timestamp":"2024-06-01T22:42:50.361407Z"}]}
{"channel":"book","type":"update","data":[{"symbol":"LINK/BTC","bids":[],"asks":[{"price":0.00027306,"qty":145.19162032}],"checksum":730266805,"timestamp":"2024-06-01T22:42:50.455407Z"}]}
{"channel":"book","type":"update","data":[{"symbol":"LINK/BTC","bids":[],"asks":[{"price":0.00027305,"qty":70.54889631}],"checksum":3992019529,"timestamp":"2024-06-01T22:42:50.490459Z"}]}
{"channel":"book","type":"update","data":[{"symbol":"LINK/BTC","bids":[],"asks":[{"price":0.00027298,"qty":0.00000000},{"price":0.00027306,"qty":145.19162032}],"checksum":2597441999,"timestamp":"2024-06-01T22:42:51.392893Z"}]}
{"channel":"book","type":"update","data":[{"symbol":"LINK/BTC","bids":[],"asks":[{"price":0.00027298,"qty":28.57798782}],"checksum":1508492771,"timestamp":"2024-06-01T22:42:51.393574Z"}]}
{"channel":"book","type":"update","data":[{"symbol":"LINK/BTC","bids":[{"price":0.00027232,"qty":0.00000000},{"price":0.00027207,"qty":915.42645000}],"asks":[],"checksum":1378828590,"timestamp":"2024-06-01T22:42:52.441345Z"}]}
{"channel":"book","type":"update","data":[{"symbol":"LINK/BTC","bids":[],"asks":[{"price":0.00027257,"qty":200.00000000}],"checksum":2642044861,"timestamp":"2024-06-01T22:42:52.445581Z"}]}
{"channel":"book","type":"update","data":[{"symbol":"LINK/BTC","bids":[],"asks":[{"price":0.00027251,"qty":40.00000000}],"checksum":506185831,"timestamp":"2024-06-01T22:42:52.447272Z"}]}
{"channel":"book","type":"update","data":[{"symbol":"LINK/BTC","bids":[],"asks":[{"price":0.00027256,"qty":0.00000000},{"price":0.00027300,"qty":88.51378950}],"checksum":3185523358,"timestamp":"2024-06-01T22:42:52.449976Z"}]}
{"channel":"book","type":"update","data":[{"symbol":"LINK/BTC","bids":[{"price":0.00027242,"qty":0.00000000},{"price":0.00027201,"qty":2.34929424}],"asks":[],"checksum":737867463,"timestamp":"2024-06-01T22:42:52.450086Z"}]}
{"channel":"book","type":"update","data":[{"symbol":"LINK/BTC","bids":[{"price":0.00027238,"qty":27.10565014}],"asks":[],"checksum":2160245837,"timestamp":"2024-06-01T22:42:52.455007Z"}]}
{"channel":"book","type":"update","data":[{"symbol":"LINK/BTC","bids":[],"asks":[{"price":0.00027254,"qty":27.09107329}],"checksum":3159213173,"timestamp":"2024-06-01T22:42:52.455024Z"}]}
{"channel":"book","type":"update","data":[{"symbol":"LINK/BTC","bids":[],"asks":[{"price":0.00027250,"qty":4.87935038}],"checksum":1741818981,"timestamp":"2024-06-01T22:42:52.466199Z"}]}
{"channel":"book","type":"update","data":[{"symbol":"LINK/BTC","bids":[],"asks":[{"price":0.00027297,"qty":70.54889631}],"checksum":1337142888,"timestamp":"2024-06-01T22:42:52.471537Z"}]}
{"channel":"book","type":"update","data":[{"symbol":"LINK/BTC","bids":[],"asks":[{"price":0.00027254,"qty":0.00000000},{"price":0.00027298,"qty":28.57798782}],"checksum":340061938,"timestamp":"2024-06-01T22:42:52.507777Z"}]}
{"channel":"book","type":"update","data":[{"symbol":"LINK/BTC","bids":[{"price":0.00027231,"qty":0.00000000},{"price":0.00027201,"qty":2.34929424}],"asks":[],"checksum":3116728005,"timestamp":"2024-06-01T22:42:52.507929Z"}]}
{"channel":"book","type":"update","data":[{"symbol":"LINK/BTC","bids":[{"price":0.00027212,"qty":27.13192941}],"asks":[],"checksum":3361426310,"timestamp":"2024-06-01T22:42:52.511800Z"}]}
{"channel":"book","type":"update","data":[{"symbol":"LINK/BTC","bids":[],"asks":[{"price":0.00027263,"qty":0.00000000},{"price":0.00027299,"qty":123.59000000}],"checksum":1065771574,"timestamp":"2024-06-01T22:42:52.511925Z"}]}
{"channel":"book","type":"update","data":[{"symbol":"LINK/BTC","bids":[{"price":0.00027244,"qty":200.00000000}],"asks":[],"checksum":2130305916,"timestamp":"2024-06-01T22:42:52.538007Z"}]}
{"channel":"book","type":"update","data":[{"symbol":"LINK/BTC","bids":[{"price":0.00027229,"qty":0.00000000},{"price":0.00027201,"qty":2.34929424}],"asks":[],"checksum":601751629,"timestamp":"2024-06-01T22:42:52.555571Z"}]}
{"channel":"book","type":"update","data":[{"symbol":"LINK/BTC","bids":[{"price":0.00027224,"qty":200.00000000}],"asks":[],"checksum":3211467278,"timestamp":"2024-06-01T22:42:52.559870Z"}]}
{"channel":"book","type":"update","data":[{"symbol":"LINK/BTC","bids":[{"price":0.00027244,"qty":0.00000000},{"price":0.00027201,"qty":2.34929424}],"asks":[],"checksum":136685759,"timestamp":"2024-06-01T22:42:52.575848Z"}]}
{"channel":"book","type":"update","data":[{"symbol":"LINK/BTC","bids":[{"price":0.00027238,"qty":0.00000000},{"price":0.00027200,"qty":91.91176470}],"asks":[],"checksum":3271784020,"timestamp":"2024-06-01T22:42:52.586661Z"}]}
{"channel":"book","type":"update","data":[{"symbol":"LINK/BTC","bids":[],"asks":[{"price":0.00027266,"qty":0.00000000},{"price":0.00027300,"qty":88.51378950}],"checksum":4116037560,"timestamp":"2024-06-01T22:42:52.728155Z"}]}
{"channel":"book","type":"update","data":[{"symbol":"LINK/BTC","bids":[],"asks":[{"price":0.00027260,"qty":27.08561172}],"checksum":3481469423,"timestamp":"2024-06-01T22:42:52.731616Z"}]}
{"channel":"book","type":"update","data":[{"symbol":"LINK/BTC","bids":[{"price":0.00027245,"qty":0.00000000},{"price":0.00027189,"qty":88.51378950}],"asks":[],"checksum":1144629370,"timestamp":"2024-06-01T22:42:52.843257Z"}]}
{"channel":"book","type":"update","data":[{"symbol":"LINK/BTC","bids":[{"price":0.00027226,"qty":5.20000000}],"asks":[],"checksum":1659760912,"timestamp":"2024-06-01T22:42:52.845984Z"}]}
{"channel":"book","type":"update","data":[{"symbol":"LINK/BTC","bids":[],"asks":[{"price":0.00027249,"qty":5.20000000}],"checksum":2124450204,"timestamp":"2024-06-01T22:42:52.846161Z"}]}
{"channel":"book","type":"update","data":[{"symbol":"LINK/BTC","bids":[{"price":0.00027239,"qty":459.20875000}],"asks":[],"checksum":2006283040,"timestamp":"2024-06-01T22:42:52.846187Z"}]}
{"channel":"book","type":"update","data":[{"symbol":"LINK/BTC","bids":[{"price":0.00027226,"qty":10.07942687}],"asks":[],"checksum":2875317210,"timestamp":"2024-06-01T22:42:52.846219Z"}]}
{"channel":"book","type":"update","data":[{"symbol":"LINK/BTC","bids":[],"asks":[{"price":0.00027250,"qty":204.87935038}],"checksum":2354854235,"timestamp":"2024-06-01T22:42:52.847607Z"}]}
{"channel":"book","type":"update","data":[{"symbol":"LINK/BTC","bids":[{"price":0.00027239,"qty":0.00000000},{"price":0.00027200,"qty":91.91176470}],"asks":[],"checksum":2485928474,"timestamp":"2024-06-01T22:42:52.848784Z"}]}
{"channel":"book","type":"update","data":[{"symbol":"LINK/BTC","bids":[],"asks":[{"price":0.00027249,"qty":0.00000000},{"price":0.00027299,"qty":123.59000000}],"checksum":1187281632,"timestamp":"2024-06-01T22:42:52.848833Z"}]}
{"channel":"book","type":"update","data":[{"symbol":"LINK/BTC","bids":[],"asks":[{"price":0.00027249,"qty":4.87942687}],"checksum":896116940,"timestamp":"2024-06-01T22:42:52.849242Z"}]}
{"channel":"book","type":"update","data":[{"symbol":"LINK/BTC","bids":[{"price":0.00027227,"qty":459.20875000}],"asks":[],"checksum":3297382183,"timestamp":"2024-06-01T22:42:52.851488Z"}]}
{"channel":"book","type":"update","data":[{"symbol":"LINK/BTC","bids":[],"asks":[{"price":0.00027250,"qty":200.00000000}],"checksum":3889245360,"timestamp":"2024-06-01T22:42:52.852280Z"}]}
{"channel":"book","type":"update","data":[{"symbol":"LINK/BTC","bids":[{"price":0.00027226,"qty":210.07942687}],"asks":[],"checksum":2589159212,"timestamp":"2024-06-01T22:42:52.852556Z"}]}
{"channel":"book","type":"update","data":[{"symbol":"LINK/BTC","bids":[],"asks":[{"price":0.00027249,"qty":10.07942687}],"checksum":923063355,"timestamp":"2024-06-01T22:42:52.852704Z"}]}
{"channel":"book","type":"update","data":[{"symbol":"LINK/BTC","bids":[{"price":0.00027226,"qty":204.87942687}],"asks":[],"checksum":202484471,"timestamp":"2024-06-01T22:42:52.854540Z"}]}
{"channel":"book","type":"update","data":[{"symbol":"LINK/BTC","bids":[{"price":0.00027228,"qty":5.20000000}],"asks":[],"checksum":1336986379,"timestamp":"2024-06-01T22:42:52.854887Z"}]}
{"channel":"book","type":"update","data":[{"symbol":"LINK/BTC","bids":[{"price":0.00027227,"qty":464.08817687}],"asks":[],"checksum":2718555441,"timestamp":"2024-06-01T22:42:52.854959Z"}]}
{"channel":"book","type":"update","data":[{"symbol":"LINK/BTC","bids":[{"price":0.00027226,"qty":200.00000000}],"asks":[],"checksum":3371714031,"timestamp":"2024-06-01T22:42:52.857706Z"}]}
{"channel":"book","type":"update","data":[{"symbol":"LINK/BTC","bids":[],"asks":[{"price":0.00027249,"qty":50.07942687}],"checksum":1237752284,"timestamp":"2024-06-01T22:42:52.896912Z"}]}
{"channel":"book","type":"update","data":[{"symbol":"LINK/BTC","bids":[],"asks":[{"price":0.00027251,"qty":0.00000000},{"price":0.00027299,"qty":123.59000000}],"checksum":1517227919,"timestamp":"2024-06-01T22:42:52.902334Z"}]}
{"channel":"book","type":"update","data":[{"symbol":"LINK/BTC","bids":[],"asks":[{"price":0.00027257,"qty":0.00000000},{"price":0.00027300,"qty":88.51378950}],"checksum":1758305360,"timestamp":"2024-06-01T22:42:52.904197Z"}]}
{"channel":"book","type":"update","data":[{"symbol":"LINK/BTC","bids":[{"price":0.00027223,"qty":45.20000000}],"asks":[],"checksum":2457806718,"timestamp":"2024-06-01T22:42:53.088990Z"}]}
{"channel":"book","type":"update","data":[{"symbol":"LINK/BTC","bids":[],"asks":[{"price":0.00027298,"qty":0.00000000},{"price":0.00027306,"qty":145.19162032}],"checksum":3673516650,"timestamp":"2024-06-01T22:42:54.109812Z"}]}
{"channel":"book","type":"update","data":[{"symbol":"LINK/BTC","bids":[],"asks":[{"price":0.00027296,"qty":27.52947289}],"checksum":1309495260,"timestamp":"2024-06-01T22:42:54.111167Z"}]}
{"channel":"book","type":"update","data":[{"symbol":"LINK/BTC","bids":[],"asks":[{"price":0.00027298,"qty":200.00000000}],"checksum":419865065,"timestamp":"2024-06-01T22:42:54.381881Z"}]}
{"channel":"book","type":"update","data":[{"symbol":"LINK/BTC","bids":[{"price":0.00027234,"qty":27.11033820}],"asks":[],"checksum":892202734,"timestamp":"2024-06-01T22:42:54.924000Z"}]}
{"channel":"book","type":"update","data":[{"symbol":"LINK/BTC","bids":[],"asks":[{"price":0.00027250,"qty":227.09476310}],"checksum":359347814,"timestamp":"2024-06-01T22:42:54.924119Z"}]}
{"channel":"book","type":"update","data":[{"symbol":"LINK/BTC","bids":[{"price":0.00027230,"qty":200.00000000}],"asks":[],"checksum":1430319367,"timestamp":"2024-06-01T22:42:55.045168Z"}]}
{"channel":"book","type":"update","data":[{"symbol":"LINK/BTC","bids":[{"price":0.00027228,"qty":0.00000000},{"price":0.00027212,"qty":27.13192941}],"asks":[],"checksum":2116827154,"timestamp":"2024-06-01T22:42:55.047778Z"}]}
{"channel":"book","type":"update","data":[{"symbol":"LINK/BTC","bids":[{"price":0.00027231,"qty":5.20000000}],"asks":[],"checksum":478418155,"timestamp":"2024-06-01T22:42:55.047802Z"}]}
{"channel":"book","type":"update","data":[{"symbol":"LINK/BTC","bids":[{"price":0.00027226,"qty":0.00000000},{"price":0.00027212,"qty":27.13192941}],"asks":[],"checksum":2182690175,"timestamp":"2024-06-01T22:42:55.225166Z"}]}
{"channel":"book","type":"update","data":[{"symbol":"LINK/BTC","bids":[],"asks":[{"price":0.00027280,"qty":0.00000000},{"price":0.00027300,"qty":88.51378950}],"checksum":1050372387,"timestamp":"2024-06-01T22:42:55.883032Z"}]}
{"channel":"book","type":"update","data":[{"symbol":"LINK/BTC","bids":[],"asks":[{"price":0.00027264,"qty":91.69600938}],"checksum":1900249015,"timestamp":"2024-06-01T22:42:56.035941Z"}]}
{"channel":"book","type":"update","data":[{"symbol":"LINK/BTC","bids":[],"asks":[{"price":0.00027296,"qty":0.00000000},{"price":0.00027300,"qty":88.51378950}],"checksum":2998570615,"timestamp":"2024-06-01T22:42:56.841086Z"}]}
{"channel":"book","type":"update","data":[{"symbol":"LINK/BTC","bids":[],"asks":[{"price":0.00027296,"qty":26.47166515}],"checksum":1629070810,"timestamp":"2024-06-01T22:42:56.842245Z"}]}
{"channel":"book","type":"update","data":[{"symbol":"LINK/BTC","bids":[{"price":0.00027235,"qty":200.00000000}],"asks":[],"checksum":2105182254,"timestamp":"2024-06-01T22:42:57.228277Z"}]}
{"channel":"book","type":"update","data":[{"symbol":"LINK/BTC","bids":[{"price":0.00027230,"qty":0.00000000},{"price":0.00027212,"qty":27.13192941}],"asks":[],"checksum":1022468181,"timestamp":"2024-06-01T22:42:57.403147Z"}]}
{"channel":"book","type":"update","data":[{"symbol":"LINK/BTC","bids":[],"asks":[{"price":0.00027250,"qty":200.00000000}],"checksum":481786077,"timestamp":"2024-06-01T22:42:58.551506Z"}]}
{"channel":"book","type":"update","data":[{"symbol":"LINK/BTC","bids":[],"asks":[{"price":0.00027248,"qty":27.09734603}],"checksum":3641360907,"timestamp":"2024-06-01T22:42:58.555706Z"}]}
{"channel":"book","type":"update","data":[{"symbol":"LINK/BTC","bids":[],"asks":[{"price":0.00027247,"qty":4.87969135}],"checksum":1655560907,"timestamp":"2024-06-01T22:42:58.558527Z"}]}
{"channel":"book","type":"update","data":[{"symbol":"LINK/BTC","bids":[],"asks":[{"price":0.00027249,"qty":45.20000000}],"checksum":789521527,"timestamp":"2024-06-01T22:42:58.561111Z"}]}
{"channel":"book","type":"update","data":[{"symbol":"LINK/BTC","bids":[{"price":0.00027227,"qty":459.20875000}],"asks":[],"checksum":3732402705,"timestamp":"2024-06-01T22:42:58.575309Z"}]}
{"channel":"book","type":"update","data":[{"symbol":"LINK/BTC","bids":[{"price":0.00027223,"qty":0.00000000},{"price":0.00027207,"qty":915.42645000}],"asks":[],"checksum":2768026076,"timestamp":"2024-06-01T22:42:58.643365Z"}]}
{"channel":"book","type":"update","data":[{"symbol":"LINK/BTC","bids":[{"price":0.00027227,"qty":0.00000000},{"price":0.00027201,"qty":2.34929424}],"asks":[],"checksum":921892475,"timestamp":"2024-06-01T22:42:58.728396Z"}]}
{"channel":"book","type":"update","data":[{"symbol":"LINK/BTC","bids":[{"price":0.00027231,"qty":0.00000000},{"price":0.00027200,"qty":91.91176470}],"asks":[],"checksum":857654163,"timestamp":"2024-06-01T22:42:58.731011Z"}]}
{"channel":"book","type":"update","data":[{"symbol":"LINK/BTC","bids":[{"price":0.00027235,"qty":659.20875000}],"asks":[],"checksum":4092735709,"timestamp":"2024-06-01T22:42:58.731107Z"}]}
{"channel":"book","type":"update","data":[{"symbol":"LINK/BTC","bids":[],"asks":[{"price":0.00027247,"qty":44.87969135}],"checksum":3733356330,"timestamp":"2024-06-01T22:42:58.734894Z"}]}
{"channel":"book","type":"update","data":[{"symbol":"LINK/BTC","bids":[],"asks":[{"price":0.00027249,"qty":5.20000000}],"checksum":987237096,"timestamp":"2024-06-01T22:42:58.894188Z"}]}
{"channel":"book","type":"update","data":[{"symbol":"LINK/BTC","bids":[{"price":0.00027223,"qty":45.20000000}],"asks":[],"checksum":23640455,"timestamp":"2024-06-01T22:42:58.937760Z"}]}
{"channel":"book","type":"update","data":[{"symbol":"LINK/BTC","bids":[{"price":0.00027234,"qty":0.00000000},{"price":0.00027200,"qty":91.91176470}],"asks":[],"checksum":2845392174,"timestamp":"2024-06-01T22:42:59.554762Z"}]}
{"channel":"book","type":"update","data":[{"symbol":"LINK/BTC","bids":[{"price":0.00027231,"qty":27.11269967}],"asks":[],"checksum":4272879666,"timestamp":"2024-06-01T22:42:59.558384Z"}]}
{"channel":"book","type":"update","data":[{"symbol":"LINK/BTC","bids":[],"asks":[{"price":0.00027296,"qty":0.00000000},{"price":0.00027298,"qty":200.00000000}],"checksum":3440861981,"timestamp":"2024-06-01T22:42:59.580049Z"}]}
{"channel":"book","type":"update","data":[{"symbol":"LINK/BTC","bids":[],"asks":[{"price":0.00027296,"qty":27.52960808}],"checksum":1405085805,"timestamp":"2024-06-01T22:42:59.581255Z"}]}
{"channel":"book","type":"update","data":[{"symbol":"LINK/BTC","bids":[{"price":0.00027223,"qty":0.00000000},{"price":0.00027200,"qty":91.91176470}],"asks":[],"checksum":1745836802,"timestamp":"2024-06-01T22:43:01.897378Z"}]}
{"channel":"book","type":"update","data":[{"symbol":"LINK/BTC","bids":[],"asks":[{"price":0.00027296,"qty":0.00000000},{"price":0.00027298,"qty":200.00000000}],"checksum":4138193010,"timestamp":"2024-06-01T22:43:02.284469Z"}]}
{"channel":"book","type":"update","data":[{"symbol":"LINK/BTC","bids":[],"asks":[{"price":0.00027296,"qty":28.58960494}],"checksum":4092595116,"timestamp":"2024-06-01T22:43:02.285576Z"}]}
{"channel":"book","type":"update","data":[{"symbol":"LINK/BTC","bids":[{"price":0.00027222,"qty":44.87969135}],"asks":[],"checksum":886919801,"timestamp":"2024-06-01T22:43:02.303162Z"}]}
{"channel":"book","type":"update","data":[{"symbol":"LINK/BTC","bids":[],"asks":[{"price":0.00027296,"qty":0.00000000},{"price":0.00027298,"qty":200.00000000}],"checksum":831162791,"timestamp":"2024-06-01T22:43:04.985218Z"}]}
{"channel":"book","type":"update","data":[{"symbol":"LINK/BTC","bids":[],"asks":[{"price":0.00027296,"qty":27.53171056}],"checksum":1249208379,"timestamp":"2024-06-01T22:43:04.986085Z"}]}
