{"channel":"book","type":"snapshot","data":[{"symbol":"LINK/ETH","bids":[{"price":0.00482969,"qty":4.87779820},{"price":0.00482963,"qty":131.75171000},{"price":0.00482730,"qty":27.11487790},{"price":0.00482702,"qty":27.09734113},{"price":0.00482593,"qty":71.53689000},{"price":0.00482442,"qty":438.16674000},{"price":0.00482412,"qty":27.13602433},{"price":0.00482049,"qty":47.69259010},{"price":0.00482048,"qty":263.85422000},{"price":0.00482046,"qty":0.20000000}],"asks":[{"price":0.00483179,"qty":27.08961957},{"price":0.00483246,"qty":27.08776539},{"price":0.00483396,"qty":27.07864145},{"price":0.00483596,"qty":27.06603375},{"price":0.00484109,"qty":0.53367795},{"price":0.00484497,"qty":70.54889631},{"price":0.00484498,"qty":71.53689000},{"price":0.00487031,"qty":569.91845000},{"price":0.00487032,"qty":58.49766978},{"price":0.00487054,"qty":146.13526317}],"checksum":1132484939}]}
{"channel":"book","type":"update","data":[{"symbol":"LINK/ETH","bids":[],"asks":[{"price":0.00487031,"qty":853.21508722}],"checksum":2306922356,"timestamp":"2024-06-01T22:42:50.338679Z"}]}
{"channel":"book","type":"update","data":[{"symbol":"LINK/ETH","bids":[{"price":0.00482969,"qty":0.00000000},{"price":0.00482006,"qty":7.43385780}],"asks":[],"checksum":1374089690,"timestamp":"2024-06-01T22:42:50.904143Z"}]}
{"channel":"book","type":"update","data":[{"symbol":"LINK/ETH","bids":[{"price":0.00482981,"qty":27.10257562}],"asks":[],"checksum":1082658660,"timestamp":"2024-06-01T22:42:51.781225Z"}]}
{"channel":"book","type":"update","data":[{"symbol":"LINK/ETH","bids":[{"price":0.00482981,"qty":0.00000000},{"price":0.00482006,"qty":7.43385780}],"asks":[],"checksum":1374089690,"timestamp":"2024-06-01T22:42:52.450187Z"}]}
{"channel":"book","type":"update","data":[{"symbol":"LINK/ETH","bids":[],"asks":[{"price":0.00483246,"qty":0.00000000},{"price":0.00487060,"qty":89.99641505}],"checksum":366917548,"timestamp":"2024-06-01T22:42:52.450255Z"}]}
{"channel":"book","type":"update","data":[{"symbol":"LINK/ETH","bids":[],"asks":[{"price":0.00483183,"qty":27.09162462}],"checksum":2495752230,"timestamp":"2024-06-01T22:42:52.455108Z"}]}
{"channel":"book","type":"update","data":[{"symbol":"LINK/ETH","bids":[],"asks":[{"price":0.00483174,"qty":4.87935038}],"checksum":665202985,"timestamp":"2024-06-01T22:42:52.466065Z"}]}
{"channel":"book","type":"update","data":[{"symbol":"LINK/ETH","bids":[],"asks":[{"price":0.00483183,"qty":0.00000000},{"price":0.00487054,"qty":146.13526317}],"checksum":1105989899,"timestamp":"2024-06-01T22:42:52.507823Z"}]}
{"channel":"book","type":"update","data":[{"symbol":"LINK/ETH","bids":[{"price":0.00482702,"qty":0.00000000},{"price":0.00481834,"qty":0.52215357}],"asks":[],"checksum":246385379,"timestamp":"2024-06-01T22:42:52.652164Z"}]}
{"channel":"book","type":"update","data":[{"symbol":"LINK/ETH","bids":[{"price":0.00482049,"qty":78.14188434}],"asks":[],"checksum":1547359692,"timestamp":"2024-06-01T22:42:52.974634Z"}]}
{"channel":"book","type":"update","data":[{"symbol":"LINK/ETH","bids":[{"price":0.00482049,"qty":30.44929424}],"asks":[],"checksum":3419848330,"timestamp":"2024-06-01T22:42:52.974840Z"}]}
{"channel":"book","type":"update","data":[{"symbol":"LINK/ETH","bids":[{"price":0.00482644,"qty":27.08961957}],"asks":[],"checksum":1833591232,"timestamp":"2024-06-01T22:42:53.092817Z"}]}
{"channel":"book","type":"update","data":[{"symbol":"LINK/ETH","bids":[],"asks":[{"price":0.00483396,"qty":0.00000000},{"price":0.00487060,"qty":89.99641505}],"checksum":36910997,"timestamp":"2024-06-01T22:42:53.336770Z"}]}
{"channel":"book","type":"update","data":[{"symbol":"LINK/ETH","bids":[{"price":0.00482841,"qty":27.11080815}],"asks":[],"checksum":100113606,"timestamp":"2024-06-01T22:42:53.340397Z"}]}
{"channel":"book","type":"update","data":[{"symbol":"LINK/ETH","bids":[],"asks":[{"price":0.00487060,"qty":0.00000000},{"price":0.00487084,"qty":263.85422000}],"checksum":2057055617,"timestamp":"2024-06-01T22:42:53.357314Z"}]}
{"channel":"book","type":"update","data":[{"symbol":"LINK/ETH","bids":[{"price":0.00482644,"qty":0.00000000},{"price":0.00482006,"qty":7.43385780}],"asks":[],"checksum":1929148378,"timestamp":"2024-06-01T22:42:53.393636Z"}]}
{"channel":"book","type":"update","data":[{"symbol":"LINK/ETH","bids":[{"price":0.00482643,"qty":27.08961957}],"asks":[],"checksum":1940004198,"timestamp":"2024-06-01T22:42:53.689940Z"}]}
{"channel":"book","type":"update","data":[{"symbol":"LINK/ETH","bids":[{"price":0.00482643,"qty":0.00000000},{"price":0.00482006,"qty":7.43385780}],"asks":[],"checksum":1929148378,"timestamp":"2024-06-01T22:42:54.081857Z"}]}
{"channel":"book","type":"update","data":[{"symbol":"LINK/ETH","bids":[{"price":0.00482633,"qty":27.08961957}],"asks":[],"checksum":1304777869,"timestamp":"2024-06-01T22:42:54.358168Z"}]}
{"channel":"book","type":"update","data":[{"symbol":"LINK/ETH","bids":[],"asks":[{"price":0.00483107,"qty":27.09591370}],"checksum":2576614886,"timestamp":"2024-06-01T22:42:54.780976Z"}]}
{"channel":"book","type":"update","data":[{"symbol":"LINK/ETH","bids":[{"price":0.00482963,"qty":0.00000000},{"price":0.00482006,"qty":7.43385780}],"asks":[],"checksum":1428224130,"timestamp":"2024-06-01T22:42:55.810397Z"}]}
{"channel":"book","type":"update","data":[{"symbol":"LINK/ETH","bids":[],"asks":[{"price":0.00487031,"qty":721.46337722}],"checksum":4253876815,"timestamp":"2024-06-01T22:42:55.810431Z"}]}
{"channel":"book","type":"update","data":[{"symbol":"LINK/ETH","bids":[],"asks":[{"price":0.00487031,"qty":283.29663722}],"checksum":4147093121,"timestamp":"2024-06-01T22:42:55.810511Z"}]}
{"channel":"book","type":"update","data":[{"symbol":"LINK/ETH","bids":[],"asks":[{"price":0.00487030,"qty":263.85422000}],"checksum":2465608455,"timestamp":"2024-06-01T22:42:55.812800Z"}]}
{"channel":"book","type":"update","data":[{"symbol":"LINK/ETH","bids":[],"asks":[{"price":0.00487030,"qty":395.60593000}],"checksum":1306601902,"timestamp":"2024-06-01T22:42:55.813126Z"}]}
{"channel":"book","type":"update","data":[{"symbol":"LINK/ETH","bids":[],"asks":[{"price":0.00487030,"qty":833.77267000}],"checksum":4232028022,"timestamp":"2024-06-01T22:42:55.813168Z"}]}
{"channel":"book","type":"update","data":[{"symbol":"LINK/ETH","bids":[{"price":0.00482842,"qty":131.75171000}],"asks":[],"checksum":744454810,"timestamp":"2024-06-01T22:42:55.813275Z"}]}
{"channel":"book","type":"update","data":[{"symbol":"LINK/ETH","bids":[{"price":0.00482841,"qty":0.00000000},{"price":0.00482006,"qty":7.43385780}],"asks":[],"checksum":490473716,"timestamp":"2024-06-01T22:42:56.345353Z"}]}
{"channel":"book","type":"update","data":[{"symbol":"LINK/ETH","bids":[],"asks":[{"price":0.00483107,"qty":0.00000000},{"price":0.00487054,"qty":146.13526317}],"checksum":4119483765,"timestamp":"2024-06-01T22:42:56.345375Z"}]}
{"channel":"book","type":"update","data":[{"symbol":"LINK/ETH","bids":[],"asks":[{"price":0.00483070,"qty":27.09640420}],"checksum":1499744589,"timestamp":"2024-06-01T22:42:56.349525Z"}]}
{"channel":"book","type":"update","data":[{"symbol":"LINK/ETH","bids":[{"price":0.00482807,"qty":27.11112433}],"asks":[],"checksum":2839618695,"timestamp":"2024-06-01T22:42:56.349589Z"}]}
{"channel":"book","type":"update","data":[{"symbol":"LINK/ETH","bids":[{"price":0.00482633,"qty":0.00000000},{"price":0.00482006,"qty":7.43385780}],"asks":[],"checksum":4165170774,"timestamp":"2024-06-01T22:42:56.461992Z"}]}
{"channel":"book","type":"update","data":[{"symbol":"LINK/ETH","bids":[{"price":0.00482807,"qty":0.00000000},{"price":0.00481834,"qty":0.52215357}],"asks":[],"checksum":1328138526,"timestamp":"2024-06-01T22:42:56.633961Z"}]}
{"channel":"book","type":"update","data":[{"symbol":"LINK/ETH","bids":[{"price":0.00482730,"qty":0.00000000},{"price":0.00480547,"qty":175.83850000}],"asks":[],"checksum":2763834801,"timestamp":"2024-06-01T22:42:56.634084Z"}]}
{"channel":"book","type":"update","data":[{"symbol":"LINK/ETH","bids":[],"asks":[{"price":0.00483070,"qty":0.00000000},{"price":0.00487054,"qty":146.13526317}],"checksum":4133076378,"timestamp":"2024-06-01T22:42:56.634109Z"}]}
{"channel":"book","type":"update","data":[{"symbol":"LINK/ETH","bids":[{"price":0.00482608,"qty":27.12056330}],"asks":[],"checksum":3477285820,"timestamp":"2024-06-01T22:42:56.638068Z"}]}
{"channel":"book","type":"update","data":[{"symbol":"LINK/ETH","bids":[{"price":0.00482605,"qty":27.09640420}],"asks":[],"checksum":2166272108,"timestamp":"2024-06-01T22:42:56.767228Z"}]}
{"channel":"book","type":"update","data":[{"symbol":"LINK/ETH","bids":[],"asks":[{"price":0.00487031,"qty":0.00000000},{"price":0.00487404,"qty":89.99641505},{"price":0.00487029,"qty":283.29663722}],"checksum":1908419584,"timestamp":"2024-06-01T22:42:57.568930Z"}]}
{"channel":"book","type":"update","data":[{"symbol":"LINK/ETH","bids":[],"asks":[{"price":0.00487054,"qty":0.00000000},{"price":0.00487404,"qty":89.99641505}],"checksum":3435231560,"timestamp":"2024-06-01T22:42:57.601271Z"}]}
{"channel":"book","type":"update","data":[{"symbol":"LINK/ETH","bids":[],"asks":[{"price":0.00487330,"qty":2.45536752}],"checksum":3541776346,"timestamp":"2024-06-01T22:42:57.603746Z"}]}
{"channel":"book","type":"update","data":[{"symbol":"LINK/ETH","bids":[],"asks":[{"price":0.00487029,"qty":429.37654359}],"checksum":717614779,"timestamp":"2024-06-01T22:42:57.641365Z"}]}
{"channel":"book","type":"update","data":[{"symbol":"LINK/ETH","bids":[{"price":0.00482803,"qty":27.11135884}],"asks":[],"checksum":3784865633,"timestamp":"2024-06-01T22:42:58.590458Z"}]}
{"channel":"book","type":"update","data":[{"symbol":"LINK/ETH","bids":[],"asks":[{"price":0.00483041,"qty":27.09816467}],"checksum":118202248,"timestamp":"2024-06-01T22:42:58.590498Z"}]}
{"channel":"book","type":"update","data":[{"symbol":"LINK/ETH","bids":[{"price":0.00482605,"qty":0.00000000},{"price":0.00482006,"qty":7.43385780}],"asks":[],"checksum":1404810860,"timestamp":"2024-06-01T22:42:58.647630Z"}]}
{"channel":"book","type":"update","data":[{"symbol":"LINK/ETH","bids":[{"price":0.00482600,"qty":27.09816467}],"asks":[],"checksum":3906848444,"timestamp":"2024-06-01T22:42:58.940675Z"}]}
{"channel":"book","type":"update","data":[{"symbol":"LINK/ETH","bids":[{"price":0.00482600,"qty":0.00000000},{"price":0.00482006,"qty":7.43385780}],"asks":[],"checksum":1404810860,"timestamp":"2024-06-01T22:42:59.604500Z"}]}
{"channel":"book","type":"update","data":[{"symbol":"LINK/ETH","bids":[{"price":0.00482599,"qty":27.09816467}],"asks":[],"checksum":633591915,"timestamp":"2024-06-01T22:42:59.898553Z"}]}
{"channel":"book","type":"update","data":[{"symbol":"LINK/ETH","bids":[],"asks":[{"price":0.00483154,"qty":27.09323179}],"checksum":2488208257,"timestamp":"2024-06-01T22:43:00.781438Z"}]}
{"channel":"book","type":"update","data":[{"symbol":"LINK/ETH","bids":[],"asks":[{"price":0.00487030,"qty":395.60593000}],"checksum":3384635059,"timestamp":"2024-06-01T22:43:01.694998Z"}]}
{"channel":"book","type":"update","data":[{"symbol":"LINK/ETH","bids":[],"asks":[{"price":0.00487030,"qty":263.85422000}],"checksum":463389996,"timestamp":"2024-06-01T22:43:01.695045Z"}]}
{"channel":"book","type":"update","data":[{"symbol":"LINK/ETH","bids":[{"price":0.00482842,"qty":0.00000000},{"price":0.00482006,"qty":7.43385780}],"asks":[],"checksum":2666419203,"timestamp":"2024-06-01T22:43:01.695086Z"}]}
{"channel":"book","type":"update","data":[{"symbol":"LINK/ETH","bids":[],"asks":[{"price":0.00487030,"qty":0.00000000},{"price":0.00487032,"qty":58.49766978}],"checksum":955813838,"timestamp":"2024-06-01T22:43:01.695300Z"}]}
{"channel":"book","type":"update","data":[{"symbol":"LINK/ETH","bids":[],"asks":[{"price":0.00487028,"qty":131.75171000}],"checksum":2764131066,"timestamp":"2024-06-01T22:43:01.697557Z"}]}
{"channel":"book","type":"update","data":[{"symbol":"LINK/ETH","bids":[],"asks":[{"price":0.00487028,"qty":569.91845000}],"checksum":798356975,"timestamp":"2024-06-01T22:43:01.697593Z"}]}
{"channel":"book","type":"update","data":[{"symbol":"LINK/ETH","bids":[{"price":0.00482843,"qty":131.75171000}],"asks":[],"checksum":1440322957,"timestamp":"2024-06-01T22:43:01.697869Z"}]}
{"channel":"book","type":"update","data":[{"symbol":"LINK/ETH","bids":[],"asks":[{"price":0.00487028,"qty":833.77267000}],"checksum":461148269,"timestamp":"2024-06-01T22:43:01.698369Z"}]}
{"channel":"book","type":"update","data":[{"symbol":"LINK/ETH","bids":[{"price":0.00482803,"qty":0.00000000},{"price":0.00482006,"qty":7.43385780}],"asks":[],"checksum":2165341109,"timestamp":"2024-06-01T22:43:01.822963Z"}]}
{"channel":"book","type":"update","data":[{"symbol":"LINK/ETH","bids":[{"price":0.00482765,"qty":27.11346672}],"asks":[],"checksum":4137561804,"timestamp":"2024-06-01T22:43:01.827183Z"}]}
{"channel":"book","type":"update","data":[{"symbol":"LINK/ETH","bids":[{"price":0.00482599,"qty":0.00000000},{"price":0.00482006,"qty":7.43385780}],"asks":[],"checksum":3636062731,"timestamp":"2024-06-01T22:43:01.884640Z"}]}
{"channel":"book","type":"update","data":[{"symbol":"LINK/ETH","bids":[{"price":0.00482593,"qty":98.63505467}],"asks":[],"checksum":1345524768,"timestamp":"2024-06-01T22:43:02.304501Z"}]}
{"channel":"book","type":"update","data":[{"symbol":"LINK/ETH","bids":[],"asks":[{"price":0.00483036,"qty":4.87991333}],"checksum":4117331020,"timestamp":"2024-06-01T22:43:03.567131Z"}]}
{"channel":"book","type":"update","data":[{"symbol":"LINK/ETH","bids":[],"asks":[{"price":0.00483174,"qty":0.00000000},{"price":0.00487029,"qty":429.37654359}],"checksum":2121040561,"timestamp":"2024-06-01T22:43:03.570016Z"}]}
{"channel":"book","type":"update","data":[{"symbol":"LINK/ETH","bids":[],"asks":[{"price":0.00483041,"qty":0.00000000},{"price":0.00487032,"qty":58.49766978}],"checksum":3799945623,"timestamp":"2024-06-01T22:43:03.571287Z"}]}
{"channel":"book","type":"update","data":[{"symbol":"LINK/ETH","bids":[],"asks":[{"price":0.00483011,"qty":27.09886694}],"checksum":3580089336,"timestamp":"2024-06-01T22:43:03.575119Z"}]}
{"channel":"book","type":"update","data":[{"symbol":"LINK/ETH","bids":[{"price":0.00482593,"qty":71.53689000}],"asks":[],"checksum":1575562707,"timestamp":"2024-06-01T22:43:03.634394Z"}]}
{"channel":"book","type":"update","data":[{"symbol":"LINK/ETH","bids":[],"asks":[{"price":0.00487005,"qty":90.04127178}],"checksum":1934543995,"timestamp":"2024-06-01T22:43:03.895997Z"}]}
{"channel":"book","type":"update","data":[{"symbol":"LINK/ETH","bids":[],"asks":[{"price":0.00487004,"qty":49.52269948}],"checksum":2558364387,"timestamp":"2024-06-01T22:43:03.896096Z"}]}
{"channel":"book","type":"update","data":[{"symbol":"LINK/ETH","bids":[],"asks":[{"price":0.00487004,"qty":58.52682666}],"checksum":1404762975,"timestamp":"2024-06-01T22:43:03.897282Z"}]}
{"channel":"book","type":"update","data":[{"symbol":"LINK/ETH","bids":[{"price":0.00482580,"qty":27.09886694}],"asks":[],"checksum":244642360,"timestamp":"2024-06-01T22:43:04.015423Z"}]}
{"channel":"book","type":"update","data":[{"symbol":"LINK/ETH","bids":[{"price":0.00482765,"qty":0.00000000},{"price":0.00482006,"qty":7.43385780}],"asks":[],"checksum":3839103264,"timestamp":"2024-06-01T22:43:04.429062Z"}]}
{"channel":"book","type":"update","data":[{"symbol":"LINK/ETH","bids":[{"price":0.00482732,"qty":27.11356503}],"asks":[],"checksum":3217868119,"timestamp":"2024-06-01T22:43:04.432355Z"}]}
{"channel":"book","type":"update","data":[{"symbol":"LINK/ETH","bids":[],"asks":[{"price":0.00483009,"qty":4.87991425}],"checksum":2841380264,"timestamp":"2024-06-01T22:43:04.590142Z"}]}
{"channel":"book","type":"update","data":[{"symbol":"LINK/ETH","bids":[],"asks":[{"price":0.00483036,"qty":0.00000000},{"price":0.00487005,"qty":90.04127178}],"checksum":458671801,"timestamp":"2024-06-01T22:43:04.591154Z"}]}
{"channel":"book","type":"update","data":[{"symbol":"LINK/ETH","bids":[],"asks":[{"price":0.00483011,"qty":0.00000000},{"price":0.00487028,"qty":833.77267000}],"checksum":1606431658,"timestamp":"2024-06-01T22:43:04.594171Z"}]}
{"channel":"book","type":"update","data":[{"symbol":"LINK/ETH","bids":[{"price":0.00482580,"qty":0.00000000},{"price":0.00482006,"qty":7.43385780}],"asks":[],"checksum":3648738158,"timestamp":"2024-06-01T22:43:04.673406Z"}]}
{"channel":"book","type":"update","data":[{"symbol":"LINK/ETH","bids":[{"price":0.00482552,"qty":27.09323179}],"asks":[],"checksum":3786560285,"timestamp":"2024-06-01T22:43:05.221323Z"}]}
{"channel":"book","type":"update","data":[{"symbol":"LINK/ETH","bids":[],"asks":[{"price":0.00482980,"qty":27.09882340}],"checksum":3254058285,"timestamp":"2024-06-01T22:43:05.782201Z"}]}
{"channel":"book","type":"update","data":[{"symbol":"LINK/ETH","bids":[{"price":0.00482732,"qty":0.00000000},{"price":0.00482006,"qty":7.43385780}],"asks":[],"checksum":3328959283,"timestamp":"2024-06-01T22:43:06.743858Z"}]}
{"channel":"book","type":"update","data":[{"symbol":"LINK/ETH","bids":[{"price":0.00482699,"qty":27.11362013}],"asks":[],"checksum":522496699,"timestamp":"2024-06-01T22:43:06.747356Z"}]}
{"channel":"book","type":"update","data":[{"symbol":"LINK/ETH","bids":[],"asks":[{"price":0.00483596,"qty":0.00000000},{"price":0.00487027,"qty":145.91902040}],"checksum":1161634294,"timestamp":"2024-06-01T22:43:07.172114Z"}]}
{"channel":"book","type":"update","data":[{"symbol":"LINK/ETH","bids":[],"asks":[{"price":0.00483373,"qty":27.07510849}],"checksum":1048267294,"timestamp":"2024-06-01T22:43:07.177335Z"}]}
{"channel":"book","type":"update","data":[{"symbol":"LINK/ETH","bids":[],"asks":[{"price":0.00482975,"qty":4.87989006}],"checksum":261159275,"timestamp":"2024-06-01T22:43:07.188581Z"}]}
{"channel":"book","type":"update","data":[{"symbol":"LINK/ETH","bids":[],"asks":[{"price":0.00483009,"qty":0.00000000},{"price":0.00487005,"qty":90.04127178}],"checksum":3904541911,"timestamp":"2024-06-01T22:43:07.190551Z"}]}
{"channel":"book","type":"update","data":[{"symbol":"LINK/ETH","bids":[],"asks":[{"price":0.00482980,"qty":0.00000000},{"price":0.00487027,"qty":145.91902040}],"checksum":373236686,"timestamp":"2024-06-01T22:43:07.193224Z"}]}
{"channel":"book","type":"update","data":[{"symbol":"LINK/ETH","bids":[{"price":0.00482049,"qty":0.00000000},{"price":0.00482006,"qty":7.43385780}],"asks":[],"checksum":4216348817,"timestamp":"2024-06-01T22:43:07.286915Z"}]}
{"channel":"book","type":"update","data":[{"symbol":"LINK/ETH","bids":[{"price":0.00482049,"qty":2.34929424}],"asks":[],"checksum":35641767,"timestamp":"2024-06-01T22:43:07.286940Z"}]}
{"channel":"book","type":"update","data":[{"symbol":"LINK/ETH","bids":[{"price":0.00482049,"qty":0.00000000},{"price":0.00482006,"qty":7.43385780}],"asks":[],"checksum":4216348817,"timestamp":"2024-06-01T22:43:07.298789Z"}]}
{"channel":"book","type":"update","data":[{"symbol":"LINK/ETH","bids":[{"price":0.00482049,"qty":30.44929424}],"asks":[],"checksum":373236686,"timestamp":"2024-06-01T22:43:07.298829Z"}]}
{"channel":"book","type":"update","data":[{"symbol":"LINK/ETH","bids":[{"price":0.00482552,"qty":0.00000000},{"price":0.00482006,"qty":7.43385780}],"asks":[],"checksum":912055802,"timestamp":"2024-06-01T22:43:07.316960Z"}]}
{"channel":"book","type":"update","data":[{"symbol":"LINK/ETH","bids":[{"price":0.00482608,"qty":0.00000000},{"price":0.00481834,"qty":0.52215357}],"asks":[],"checksum":2508885417,"timestamp":"2024-06-01T22:43:07.569213Z"}]}
{"channel":"book","type":"update","data":[{"symbol":"LINK/ETH","bids":[{"price":0.00482247,"qty":27.13766567}],"asks":[],"checksum":4257785420,"timestamp":"2024-06-01T22:43:07.573093Z"}]}
{"channel":"book","type":"update","data":[{"symbol":"LINK/ETH","bids":[],"asks":[{"price":0.00482949,"qty":27.09890043}],"checksum":3651431775,"timestamp":"2024-06-01T22:43:07.573203Z"}]}
{"channel":"book","type":"update","data":[{"symbol":"LINK/ETH","bids":[{"price":0.00482843,"qty":0.00000000},{"price":0.00481834,"qty":0.52215357}],"asks":[],"checksum":1492734149,"timestamp":"2024-06-01T22:43:07.579335Z"}]}
{"channel":"book","type":"update","data":[{"symbol":"LINK/ETH","bids":[],"asks":[{"price":0.00484498,"qty":0.00000000},{"price":0.00487027,"qty":145.91902040}],"checksum":3562377242,"timestamp":"2024-06-01T22:43:07.579672Z"}]}
{"channel":"book","type":"update","data":[{"symbol":"LINK/ETH","bids":[],"asks":[{"price":0.00487003,"qty":263.85422000}],"checksum":1196868155,"timestamp":"2024-06-01T22:43:07.581884Z"}]}
{"channel":"book","type":"update","data":[{"symbol":"LINK/ETH","bids":[],"asks":[{"price":0.00487003,"qty":702.02096000}],"checksum":2221309725,"timestamp":"2024-06-01T22:43:07.581968Z"}]}
{"channel":"book","type":"update","data":[{"symbol":"LINK/ETH","bids":[],"asks":[{"price":0.00487003,"qty":833.77267000}],"checksum":2008380110,"timestamp":"2024-06-01T22:43:07.582165Z"}]}
{"channel":"book","type":"update","data":[{"symbol":"LINK/ETH","bids":[],"asks":[{"price":0.00484277,"qty":71.53689000}],"checksum":4197052081,"timestamp":"2024-06-01T22:43:07.582182Z"}]}
{"channel":"book","type":"update","data":[{"symbol":"LINK/ETH","bids":[{"price":0.00482700,"qty":131.75171000}],"asks":[],"checksum":1394500316,"timestamp":"2024-06-01T22:43:07.582204Z"}]}
{"channel":"book","type":"update","data":[{"symbol":"LINK/ETH","bids":[],"asks":[{"price":0.00484497,"qty":0.00000000},{"price":0.00487005,"qty":90.04127178}],"checksum":577616455,"timestamp":"2024-06-01T22:43:07.589794Z"}]}
{"channel":"book","type":"update","data":[{"symbol":"LINK/ETH","bids":[],"asks":[{"price":0.00484108,"qty":70.54889631}],"checksum":3226510772,"timestamp":"2024-06-01T22:43:07.590018Z"}]}
{"channel":"book","type":"update","data":[{"symbol":"LINK/ETH","bids":[{"price":0.00482536,"qty":27.09323179}],"asks":[],"checksum":3008543722,"timestamp":"2024-06-01T22:43:07.663292Z"}]}
{"channel":"book","type":"update","data":[{"symbol":"LINK/ETH","bids":[{"price":0.00482536,"qty":0.00000000},{"price":0.00482006,"qty":7.43385780}],"asks":[],"checksum":3226510772,"timestamp":"2024-06-01T22:43:07.959859Z"}]}
{"channel":"book","type":"update","data":[{"symbol":"LINK/ETH","bids":[],"asks":[{"price":0.00487002,"qty":283.29663722}],"checksum":2616291374,"timestamp":"2024-06-01T22:43:08.192310Z"}]}
{"channel":"book","type":"update","data":[{"symbol":"LINK/ETH","bids":[{"price":0.00482535,"qty":27.09890043}],"asks":[],"checksum":526314200,"timestamp":"2024-06-01T22:43:08.271877Z"}]}
{"channel":"book","type":"update","data":[{"symbol":"LINK/ETH","bids":[{"price":0.00482535,"qty":0.00000000},{"price":0.00482006,"qty":7.43385780}],"asks":[],"checksum":2616291374,"timestamp":"2024-06-01T22:43:09.079703Z"}]}
{"channel":"book","type":"update","data":[{"symbol":"LINK/ETH","bids":[{"price":0.00482530,"qty":27.09890043}],"asks":[],"checksum":2589118027,"timestamp":"2024-06-01T22:43:09.392630Z"}]}
{"channel":"book","type":"update","data":[{"symbol":"LINK/ETH","bids":[{"price":0.00482699,"qty":0.00000000},{"price":0.00482006,"qty":7.43385780}],"asks":[],"checksum":323124052,"timestamp":"2024-06-01T22:43:11.283377Z"}]}
{"channel":"book","type":"update","data":[{"symbol":"LINK/ETH","bids":[{"price":0.00482659,"qty":27.11385377}],"asks":[],"checksum":2239591863,"timestamp":"2024-06-01T22:43:11.287626Z"}]}
{"channel":"book","type":"update","data":[{"symbol":"LINK/ETH","bids":[],"asks":[{"price":0.00482949,"qty":0.00000000},{"price":0.00487004,"qty":58.52682666}],"checksum":4114714958,"timestamp":"2024-06-01T22:43:11.295930Z"}]}
{"channel":"book","type":"update","data":[{"symbol":"LINK/ETH","bids":[],"asks":[{"price":0.00482916,"qty":27.09910496}],"checksum":3378182734,"timestamp":"2024-06-01T22:43:11.300595Z"}]}
{"channel":"book","type":"update","data":[{"symbol":"LINK/ETH","bids":[{"price":0.00482049,"qty":0.00000000},{"price":0.00482006,"qty":7.43385780}],"asks":[],"checksum":4268106557,"timestamp":"2024-06-01T22:43:11.325552Z"}]}
{"channel":"book","type":"update","data":[{"symbol":"LINK/ETH","bids":[{"price":0.00482049,"qty":2.34929424}],"asks":[],"checksum":120166923,"timestamp":"2024-06-01T22:43:11.325686Z"}]}
