{"channel":"book","type":"snapshot","data":[{"symbol":"LINK/JPY","bids":[{"price":2900.5,"qty":42.88900000},{"price":2893.6,"qty":2.45563001},{"price":2893.5,"qty":299.50250000},{"price":2893.4,"qty":11281.99806592},{"price":2882.0,"qty":167.16150000},{"price":2881.8,"qty":108.24000000},{"price":2876.3,"qty":108.24000000},{"price":2875.1,"qty":3386.86917744},{"price":2853.3,"qty":53.74600000},{"price":2852.4,"qty":4.27881707}],"asks":[{"price":2907.0,"qty":42.88900000},{"price":2914.2,"qty":70.54889631},{"price":2914.3,"qty":80.33850000},{"price":2914.9,"qty":219.16400000},{"price":2930.5,"qty":167.16150000},{"price":2930.8,"qty":108.24000000},{"price":2932.7,"qty":3387.31847735},{"price":2937.6,"qty":108.24000000},{"price":2980.5,"qty":53.74600000},{"price":2980.7,"qty":0.39108579}],"checksum":1554167732}]}
{"channel":"book","type":"update","data":[{"symbol":"LINK/JPY","bids":[{"price":2893.6,"qty":45.39685927}],"asks":[],"checksum":2932796730,"timestamp":"2024-06-01T22:42:49.462758Z"}]}
{"channel":"book","type":"update","data":[{"symbol":"LINK/JPY","bids":[{"price":2893.6,"qty":42.94122926}],"asks":[],"checksum":1126078940,"timestamp":"2024-06-01T22:42:49.462862Z"}]}
{"channel":"book","type":"update","data":[{"symbol":"LINK/JPY","bids":[{"price":2893.6,"qty":0.00000000},{"price":2833.1,"qty":0.60181426}],"asks":[],"checksum":2652630135,"timestamp":"2024-06-01T22:42:49.507478Z"}]}
{"channel":"book","type":"update","data":[{"symbol":"LINK/JPY","bids":[{"price":2893.6,"qty":2.45563001}],"asks":[],"checksum":1554167732,"timestamp":"2024-06-01T22:42:49.507714Z"}]}
{"channel":"book","type":"update","data":[{"symbol":"LINK/JPY","bids":[],"asks":[{"price":2907.0,"qty":51.00698132}],"checksum":1357269349,"timestamp":"2024-06-01T22:42:52.474273Z"}]}
{"channel":"book","type":"update","data":[{"symbol":"LINK/JPY","bids":[],"asks":[{"price":2914.3,"qty":0.00000000},{"price":2983.9,"qty":27.45050000}],"checksum":1357616664,"timestamp":"2024-06-01T22:42:55.014510Z"}]}
{"channel":"book","type":"update","data":[{"symbol":"LINK/JPY","bids":[],"asks":[{"price":2930.5,"qty":0.00000000},{"price":3015.1,"qty":27.45050000}],"checksum":701562420,"timestamp":"2024-06-01T22:42:55.014624Z"}]}
{"channel":"book","type":"update","data":[{"symbol":"LINK/JPY","bids":[],"asks":[{"price":2980.5,"qty":0.00000000},{"price":3044.4,"qty":27.45050000}],"checksum":1667678770,"timestamp":"2024-06-01T22:42:55.014636Z"}]}
{"channel":"book","type":"update","data":[{"symbol":"LINK/JPY","bids":[{"price":2893.5,"qty":219.16400000}],"asks":[],"checksum":1245638239,"timestamp":"2024-06-01T22:42:55.014688Z"}]}
{"channel":"book","type":"update","data":[{"symbol":"LINK/JPY","bids":[{"price":2882.0,"qty":0.00000000},{"price":2833.1,"qty":0.60181426}],"asks":[],"checksum":229352174,"timestamp":"2024-06-01T22:42:55.014974Z"}]}
{"channel":"book","type":"update","data":[{"symbol":"LINK/JPY","bids":[{"price":2893.7,"qty":80.33850000}],"asks":[],"checksum":239560190,"timestamp":"2024-06-01T22:42:55.017242Z"}]}
{"channel":"book","type":"update","data":[{"symbol":"LINK/JPY","bids":[],"asks":[{"price":2980.4,"qty":53.74600000}],"checksum":3898455826,"timestamp":"2024-06-01T22:42:55.017325Z"}]}
{"channel":"book","type":"update","data":[{"symbol":"LINK/JPY","bids":[],"asks":[{"price":2930.7,"qty":2.45464660}],"checksum":2514440045,"timestamp":"2024-06-01T22:42:55.017342Z"}]}
{"channel":"book","type":"update","data":[{"symbol":"LINK/JPY","bids":[],"asks":[{"price":2914.1,"qty":80.33850000}],"checksum":1589129990,"timestamp":"2024-06-01T22:42:55.017404Z"}]}
{"channel":"book","type":"update","data":[{"symbol":"LINK/JPY","bids":[],"asks":[{"price":2930.4,"qty":167.16150000}],"checksum":2582172846,"timestamp":"2024-06-01T22:42:55.017531Z"}]}
{"channel":"book","type":"update","data":[{"symbol":"LINK/JPY","bids":[{"price":2882.1,"qty":167.16150000}],"asks":[],"checksum":938601604,"timestamp":"2024-06-01T22:42:55.017678Z"}]}
{"channel":"book","type":"update","data":[{"symbol":"LINK/JPY","bids":[{"price":2893.8,"qty":2.45563001}],"asks":[],"checksum":672266366,"timestamp":"2024-06-01T22:42:55.045536Z"}]}
{"channel":"book","type":"update","data":[{"symbol":"LINK/JPY","bids":[],"asks":[{"price":2914.2,"qty":0.00000000},{"price":2980.7,"qty":0.39108579}],"checksum":159081291,"timestamp":"2024-06-01T22:42:55.045567Z"}]}
{"channel":"book","type":"update","data":[{"symbol":"LINK/JPY","bids":[{"price":2893.6,"qty":0.00000000},{"price":2853.3,"qty":53.74600000}],"asks":[],"checksum":3930672889,"timestamp":"2024-06-01T22:42:55.045641Z"}]}
{"channel":"book","type":"update","data":[{"symbol":"LINK/JPY","bids":[],"asks":[{"price":2914.0,"qty":70.54889631}],"checksum":855135745,"timestamp":"2024-06-01T22:42:55.045737Z"}]}
{"channel":"book","type":"update","data":[{"symbol":"LINK/JPY","bids":[{"price":2893.4,"qty":0.00000000},{"price":2852.4,"qty":4.27881707}],"asks":[],"checksum":64193425,"timestamp":"2024-06-01T22:42:55.747965Z"}]}
{"channel":"book","type":"update","data":[{"symbol":"LINK/JPY","bids":[{"price":2892.6,"qty":11290.57947076}],"asks":[],"checksum":3279023367,"timestamp":"2024-06-01T22:42:55.788047Z"}]}
{"channel":"book","type":"update","data":[{"symbol":"LINK/JPY","bids":[],"asks":[{"price":2930.7,"qty":0.00000000},{"price":2980.7,"qty":0.39108579},{"price":2930.3,"qty":2.45498167}],"checksum":3699893432,"timestamp":"2024-06-01T22:42:57.410562Z"}]}
{"channel":"book","type":"update","data":[{"symbol":"LINK/JPY","bids":[],"asks":[{"price":2907.0,"qty":42.88900000},{"price":2906.9,"qty":8.11798132}],"checksum":3498375899,"timestamp":"2024-06-01T22:42:58.010870Z"}]}
{"channel":"book","type":"update","data":[{"symbol":"LINK/JPY","bids":[{"price":2893.7,"qty":0.00000000},{"price":2852.4,"qty":4.27881707}],"asks":[],"checksum":2299131517,"timestamp":"2024-06-01T22:43:00.899143Z"}]}
{"channel":"book","type":"update","data":[{"symbol":"LINK/JPY","bids":[],"asks":[{"price":2914.1,"qty":0.00000000},{"price":2980.4,"qty":53.74600000}],"checksum":3854541468,"timestamp":"2024-06-01T22:43:00.899201Z"}]}
{"channel":"book","type":"update","data":[{"symbol":"LINK/JPY","bids":[],"asks":[{"price":2930.4,"qty":0.00000000},{"price":2980.7,"qty":0.39108579}],"checksum":5606004,"timestamp":"2024-06-01T22:43:00.899271Z"}]}
{"channel":"book","type":"update","data":[{"symbol":"LINK/JPY","bids":[],"asks":[{"price":2980.4,"qty":0.00000000},{"price":2983.9,"qty":27.45050000}],"checksum":985305261,"timestamp":"2024-06-01T22:43:00.899386Z"}]}
{"channel":"book","type":"update","data":[{"symbol":"LINK/JPY","bids":[],"asks":[{"price":2914.9,"qty":0.00000000},{"price":3015.1,"qty":27.45050000}],"checksum":3997372331,"timestamp":"2024-06-01T22:43:00.899402Z"}]}
{"channel":"book","type":"update","data":[{"symbol":"LINK/JPY","bids":[{"price":2882.1,"qty":0.00000000},{"price":2833.1,"qty":0.60181426}],"asks":[],"checksum":3374387097,"timestamp":"2024-06-01T22:43:00.899469Z"}]}
{"channel":"book","type":"update","data":[{"symbol":"LINK/JPY","bids":[{"price":2893.9,"qty":80.33850000}],"asks":[],"checksum":420136848,"timestamp":"2024-06-01T22:43:00.901811Z"}]}
{"channel":"book","type":"update","data":[{"symbol":"LINK/JPY","bids":[],"asks":[{"price":2913.9,"qty":80.33850000}],"checksum":4036558633,"timestamp":"2024-06-01T22:43:00.902117Z"}]}
{"channel":"book","type":"update","data":[{"symbol":"LINK/JPY","bids":[],"asks":[{"price":2930.2,"qty":167.16150000}],"checksum":2950113895,"timestamp":"2024-06-01T22:43:00.902134Z"}]}
{"channel":"book","type":"update","data":[{"symbol":"LINK/JPY","bids":[{"price":2882.2,"qty":167.16150000}],"asks":[],"checksum":1048231076,"timestamp":"2024-06-01T22:43:00.902268Z"}]}
{"channel":"book","type":"update","data":[{"symbol":"LINK/JPY","bids":[],"asks":[{"price":2980.3,"qty":53.74600000}],"checksum":1096787042,"timestamp":"2024-06-01T22:43:00.902934Z"}]}
{"channel":"book","type":"update","data":[{"symbol":"LINK/JPY","bids":[],"asks":[{"price":2913.9,"qty":299.50250000}],"checksum":2327091245,"timestamp":"2024-06-01T22:43:00.903195Z"}]}
{"channel":"book","type":"update","data":[{"symbol":"LINK/JPY","bids":[],"asks":[{"price":2930.3,"qty":0.00000000},{"price":2980.7,"qty":0.39108579},{"price":2930.1,"qty":2.45514924}],"checksum":1851082435,"timestamp":"2024-06-01T22:43:00.913147Z"}]}
{"channel":"book","type":"update","data":[{"symbol":"LINK/JPY","bids":[],"asks":[{"price":2914.0,"qty":0.00000000},{"price":2980.7,"qty":0.39108579}],"checksum":660209533,"timestamp":"2024-06-01T22:43:00.938358Z"}]}
{"channel":"book","type":"update","data":[{"symbol":"LINK/JPY","bids":[{"price":2894.0,"qty":2.45563001}],"asks":[],"checksum":190900737,"timestamp":"2024-06-01T22:43:00.938394Z"}]}
{"channel":"book","type":"update","data":[{"symbol":"LINK/JPY","bids":[{"price":2893.8,"qty":0.00000000},{"price":2853.3,"qty":53.74600000}],"asks":[],"checksum":4073771191,"timestamp":"2024-06-01T22:43:00.938518Z"}]}
{"channel":"book","type":"update","data":[{"symbol":"LINK/JPY","bids":[],"asks":[{"price":2913.8,"qty":70.54889631}],"checksum":2634456656,"timestamp":"2024-06-01T22:43:00.938561Z"}]}
{"channel":"book","type":"update","data":[{"symbol":"LINK/JPY","bids":[],"asks":[{"price":2932.7,"qty":0.00000000},{"price":2980.7,"qty":0.39108579}],"checksum":1284598192,"timestamp":"2024-06-01T22:43:01.341648Z"}]}
{"channel":"book","type":"update","data":[{"symbol":"LINK/JPY","bids":[],"asks":[{"price":2931.0,"qty":3387.99823493}],"checksum":802779751,"timestamp":"2024-06-01T22:43:01.382568Z"}]}
{"channel":"book","type":"update","data":[{"symbol":"LINK/JPY","bids":[],"asks":[{"price":2980.3,"qty":0.00000000},{"price":2980.7,"qty":0.39108579}],"checksum":2384016360,"timestamp":"2024-06-01T22:43:06.783626Z"}]}
{"channel":"book","type":"update","data":[{"symbol":"LINK/JPY","bids":[{"price":2882.2,"qty":0.00000000},{"price":2852.4,"qty":4.27881707}],"asks":[],"checksum":3737353887,"timestamp":"2024-06-01T22:43:06.783814Z"}]}
{"channel":"book","type":"update","data":[{"symbol":"LINK/JPY","bids":[{"price":2881.9,"qty":167.16150000}],"asks":[],"checksum":4158430706,"timestamp":"2024-06-01T22:43:06.786564Z"}]}
{"channel":"book","type":"update","data":[{"symbol":"LINK/JPY","bids":[],"asks":[{"price":2980.6,"qty":53.74600000}],"checksum":154736086,"timestamp":"2024-06-01T22:43:06.786832Z"}]}
{"channel":"book","type":"update","data":[{"symbol":"LINK/JPY","bids":[{"price":2892.6,"qty":0.00000000},{"price":2852.4,"qty":4.27881707}],"asks":[],"checksum":2932027099,"timestamp":"2024-06-01T22:43:09.949998Z"}]}
{"channel":"book","type":"update","data":[{"symbol":"LINK/JPY","bids":[{"price":2892.5,"qty":11291.71217298}],"asks":[],"checksum":789239209,"timestamp":"2024-06-01T22:43:09.990235Z"}]}
{"channel":"book","type":"update","data":[{"symbol":"LINK/JPY","bids":[],"asks":[{"price":2913.9,"qty":219.16400000}],"checksum":3891101400,"timestamp":"2024-06-01T22:43:12.668287Z"}]}
{"channel":"book","type":"update","data":[{"symbol":"LINK/JPY","bids":[],"asks":[{"price":2930.2,"qty":0.00000000},{"price":2980.7,"qty":0.39108579}],"checksum":522010375,"timestamp":"2024-06-01T22:43:12.668716Z"}]}
{"channel":"book","type":"update","data":[{"symbol":"LINK/JPY","bids":[{"price":2893.9,"qty":0.00000000},{"price":2852.4,"qty":4.27881707}],"asks":[],"checksum":830102525,"timestamp":"2024-06-01T22:43:12.668782Z"}]}
{"channel":"book","type":"update","data":[{"symbol":"LINK/JPY","bids":[],"asks":[{"price":2913.7,"qty":80.33850000}],"checksum":3525767189,"timestamp":"2024-06-01T22:43:12.670921Z"}]}
{"channel":"book","type":"update","data":[{"symbol":"LINK/JPY","bids":[{"price":2894.1,"qty":80.33850000}],"asks":[],"checksum":2980011509,"timestamp":"2024-06-01T22:43:12.671412Z"}]}
{"channel":"book","type":"update","data":[{"symbol":"LINK/JPY","bids":[],"asks":[{"price":2930.0,"qty":167.16150000}],"checksum":3873762568,"timestamp":"2024-06-01T22:43:12.671482Z"}]}
{"channel":"book","type":"update","data":[{"symbol":"LINK/JPY","bids":[],"asks":[{"price":2930.1,"qty":0.00000000},{"price":2980.6,"qty":53.74600000},{"price":2929.9,"qty":2.45531684}],"checksum":3012728052,"timestamp":"2024-06-01T22:43:12.679096Z"}]}
{"channel":"book","type":"update","data":[{"symbol":"LINK/JPY","bids":[],"asks":[{"price":2913.8,"qty":0.00000000},{"price":2980.6,"qty":53.74600000}],"checksum":1598662654,"timestamp":"2024-06-01T22:43:12.703003Z"}]}
{"channel":"book","type":"update","data":[{"symbol":"LINK/JPY","bids":[{"price":2894.0,"qty":0.00000000},{"price":2852.4,"qty":4.27881707}],"asks":[],"checksum":3965517336,"timestamp":"2024-06-01T22:43:12.703163Z"}]}
{"channel":"book","type":"update","data":[{"symbol":"LINK/JPY","bids":[{"price":2894.2,"qty":2.45563001}],"asks":[],"checksum":3800038153,"timestamp":"2024-06-01T22:43:12.703253Z"}]}
{"channel":"book","type":"update","data":[{"symbol":"LINK/JPY","bids":[],"asks":[{"price":2913.6,"qty":70.54889631}],"checksum":1166028073,"timestamp":"2024-06-01T22:43:12.703321Z"}]}
{"channel":"book","type":"update","data":[{"symbol":"LINK/JPY","bids":[{"price":2881.9,"qty":0.00000000},{"price":2852.4,"qty":4.27881707}],"asks":[],"checksum":1806229460,"timestamp":"2024-06-01T22:43:18.553406Z"}]}
{"channel":"book","type":"update","data":[{"symbol":"LINK/JPY","bids":[{"price":2882.0,"qty":167.16150000}],"asks":[],"checksum":4222740238,"timestamp":"2024-06-01T22:43:18.555933Z"}]}
