{"channel":"book","type":"snapshot","data":[{"symbol":"LINK/EUR","bids":[{"price":17.02639,"qty":2.34929424},{"price":17.01685,"qty":28.10000000},{"price":17.01344,"qty":21.00000000},{"price":17.01292,"qty":135.44903017},{"price":17.01029,"qty":305.00000000},{"price":17.01028,"qty":34.35853179},{"price":17.00990,"qty":47.43738600},{"price":17.00830,"qty":149.28697600},{"price":17.00820,"qty":270.97319284},{"price":17.00811,"qty":30.72615257}],"asks":[{"price":17.02640,"qty":1243.68745821},{"price":17.02655,"qty":189.76235595},{"price":17.03037,"qty":6.37161196},{"price":17.03038,"qty":16.50000000},{"price":17.03060,"qty":47.43738600},{"price":17.03065,"qty":270.61619934},{"price":17.03097,"qty":13.72604916},{"price":17.03551,"qty":270.40000000},{"price":17.03877,"qty":70.02006900},{"price":17.03878,"qty":17.30000000}],"checksum":1141552950}]}
{"channel":"book","type":"update","data":[{"symbol":"LINK/EUR","bids":[],"asks":[{"price":17.03037,"qty":0.00000000},{"price":17.04179,"qty":70.54889631}],"checksum":2668547427,"timestamp":"2024-06-01T22:42:45.956130Z"}]}
{"channel":"book","type":"update","data":[{"symbol":"LINK/EUR","bids":[],"asks":[{"price":17.03037,"qty":5.31378246}],"checksum":3728470583,"timestamp":"2024-06-01T22:42:45.957341Z"}]}
{"channel":"book","type":"update","data":[{"symbol":"LINK/EUR","bids":[],"asks":[{"price":17.02640,"qty":1198.38655042}],"checksum":3882918890,"timestamp":"2024-06-01T22:42:46.305751Z"}]}
{"channel":"book","type":"update","data":[{"symbol":"LINK/EUR","bids":[],"asks":[{"price":17.02640,"qty":1243.68745821}],"checksum":3728470583,"timestamp":"2024-06-01T22:42:46.434879Z"}]}
{"channel":"book","type":"update","data":[{"symbol":"LINK/EUR","bids":[{"price":17.01292,"qty":0.00000000},{"price":17.00623,"qty":467.47688400}],"asks":[],"checksum":1390390105,"timestamp":"2024-06-01T22:42:49.451143Z"}]}
{"channel":"book","type":"update","data":[{"symbol":"LINK/EUR","bids":[{"price":17.01344,"qty":0.00000000},{"price":17.00379,"qty":270.80000000}],"asks":[],"checksum":3486308107,"timestamp":"2024-06-01T22:42:49.453762Z"}]}
{"channel":"book","type":"update","data":[{"symbol":"LINK/EUR","bids":[{"price":17.01081,"qty":21.00000000}],"asks":[],"checksum":491668021,"timestamp":"2024-06-01T22:42:49.453982Z"}]}
{"channel":"book","type":"update","data":[{"symbol":"LINK/EUR","bids":[{"price":17.01358,"qty":135.44375478}],"asks":[],"checksum":2425401452,"timestamp":"2024-06-01T22:42:49.455328Z"}]}
{"channel":"book","type":"update","data":[{"symbol":"LINK/EUR","bids":[{"price":17.01081,"qty":0.00000000},{"price":17.00623,"qty":467.47688400}],"asks":[],"checksum":2609935111,"timestamp":"2024-06-01T22:42:49.457768Z"}]}
{"channel":"book","type":"update","data":[{"symbol":"LINK/EUR","bids":[{"price":17.01410,"qty":21.00000000}],"asks":[],"checksum":916582491,"timestamp":"2024-06-01T22:42:49.458064Z"}]}
{"channel":"book","type":"update","data":[{"symbol":"LINK/EUR","bids":[{"price":17.01358,"qty":0.00000000},{"price":17.00623,"qty":467.47688400}],"asks":[],"checksum":583505753,"timestamp":"2024-06-01T22:42:49.503757Z"}]}
{"channel":"book","type":"update","data":[{"symbol":"LINK/EUR","bids":[{"price":17.01081,"qty":21.00000000}],"asks":[],"checksum":2711676698,"timestamp":"2024-06-01T22:42:49.506648Z"}]}
{"channel":"book","type":"update","data":[{"symbol":"LINK/EUR","bids":[{"price":17.01410,"qty":0.00000000},{"price":17.00623,"qty":467.47688400}],"asks":[],"checksum":491668021,"timestamp":"2024-06-01T22:42:49.506673Z"}]}
{"channel":"book","type":"update","data":[{"symbol":"LINK/EUR","bids":[{"price":17.01288,"qty":135.44934190}],"asks":[],"checksum":1729808816,"timestamp":"2024-06-01T22:42:50.176244Z"}]}
{"channel":"book","type":"update","data":[{"symbol":"LINK/EUR","bids":[{"price":17.01081,"qty":0.00000000},{"price":17.00623,"qty":467.47688400}],"asks":[],"checksum":335701889,"timestamp":"2024-06-01T22:42:50.178863Z"}]}
{"channel":"book","type":"update","data":[{"symbol":"LINK/EUR","bids":[{"price":17.01340,"qty":21.00000000}],"asks":[],"checksum":1687589827,"timestamp":"2024-06-01T22:42:50.178986Z"}]}
{"channel":"book","type":"update","data":[{"symbol":"LINK/EUR","bids":[{"price":17.01028,"qty":0.00000000},{"price":17.00623,"qty":467.47688400}],"asks":[],"checksum":1384573254,"timestamp":"2024-06-01T22:42:50.904522Z"}]}
{"channel":"book","type":"update","data":[{"symbol":"LINK/EUR","bids":[{"price":17.01029,"qty":0.00000000},{"price":17.00379,"qty":270.80000000},{"price":17.00991,"qty":305.00000000}],"asks":[],"checksum":2766717307,"timestamp":"2024-06-01T22:42:50.907292Z"}]}
{"channel":"book","type":"update","data":[{"symbol":"LINK/EUR","bids":[{"price":17.01288,"qty":0.00000000},{"price":17.00379,"qty":270.80000000}],"asks":[],"checksum":3808580289,"timestamp":"2024-06-01T22:42:51.425259Z"}]}
{"channel":"book","type":"update","data":[{"symbol":"LINK/EUR","bids":[{"price":17.01340,"qty":0.00000000},{"price":17.00344,"qty":1084.05035269}],"asks":[],"checksum":812511778,"timestamp":"2024-06-01T22:42:51.427990Z"}]}
{"channel":"book","type":"update","data":[{"symbol":"LINK/EUR","bids":[{"price":17.01043,"qty":21.00000000}],"asks":[],"checksum":776065333,"timestamp":"2024-06-01T22:42:51.428257Z"}]}
{"channel":"book","type":"update","data":[{"symbol":"LINK/EUR","bids":[{"price":17.01343,"qty":135.44495515}],"asks":[],"checksum":988659677,"timestamp":"2024-06-01T22:42:51.428908Z"}]}
{"channel":"book","type":"update","data":[{"symbol":"LINK/EUR","bids":[{"price":17.01043,"qty":0.00000000},{"price":17.00379,"qty":270.80000000}],"asks":[],"checksum":1257655464,"timestamp":"2024-06-01T22:42:51.431536Z"}]}
{"channel":"book","type":"update","data":[{"symbol":"LINK/EUR","bids":[{"price":17.01395,"qty":21.00000000}],"asks":[],"checksum":3867837123,"timestamp":"2024-06-01T22:42:51.431873Z"}]}
{"channel":"book","type":"update","data":[{"symbol":"LINK/EUR","bids":[{"price":17.01343,"qty":0.00000000},{"price":17.00379,"qty":270.80000000}],"asks":[],"checksum":2454301566,"timestamp":"2024-06-01T22:42:51.526800Z"}]}
{"channel":"book","type":"update","data":[{"symbol":"LINK/EUR","bids":[{"price":17.01395,"qty":0.00000000},{"price":17.00344,"qty":1084.05035269}],"asks":[],"checksum":812511778,"timestamp":"2024-06-01T22:42:51.529723Z"}]}
{"channel":"book","type":"update","data":[{"symbol":"LINK/EUR","bids":[{"price":17.01043,"qty":21.00000000}],"asks":[],"checksum":776065333,"timestamp":"2024-06-01T22:42:51.529903Z"}]}
{"channel":"book","type":"update","data":[{"symbol":"LINK/EUR","bids":[{"price":17.01042,"qty":34.35824901}],"asks":[],"checksum":1372034552,"timestamp":"2024-06-01T22:42:51.869860Z"}]}
{"channel":"book","type":"update","data":[{"symbol":"LINK/EUR","bids":[{"price":17.00991,"qty":0.00000000},{"price":17.00379,"qty":270.80000000},{"price":17.01043,"qty":326.00000000}],"asks":[],"checksum":1239520011,"timestamp":"2024-06-01T22:42:51.872611Z"}]}
{"channel":"book","type":"update","data":[{"symbol":"LINK/EUR","bids":[{"price":17.00379,"qty":0.00000000},{"price":17.00344,"qty":1084.05035269}],"asks":[],"checksum":4245665797,"timestamp":"2024-06-01T22:42:52.178291Z"}]}
{"channel":"book","type":"update","data":[{"symbol":"LINK/EUR","bids":[{"price":17.00379,"qty":270.80000000}],"asks":[],"checksum":1239520011,"timestamp":"2024-06-01T22:42:52.297154Z"}]}
{"channel":"book","type":"update","data":[{"symbol":"LINK/EUR","bids":[{"price":17.00811,"qty":0.00000000},{"price":17.00344,"qty":1084.05035269}],"asks":[],"checksum":2807675433,"timestamp":"2024-06-01T22:42:52.440431Z"}]}
{"channel":"book","type":"update","data":[{"symbol":"LINK/EUR","bids":[{"price":17.01043,"qty":21.00000000}],"asks":[],"checksum":3154737386,"timestamp":"2024-06-01T22:42:52.443539Z"}]}
{"channel":"book","type":"update","data":[{"symbol":"LINK/EUR","bids":[{"price":17.00379,"qty":0.00000000},{"price":17.00321,"qty":1084.05035269}],"asks":[],"checksum":3818043675,"timestamp":"2024-06-01T22:42:52.443948Z"}]}
{"channel":"book","type":"update","data":[{"symbol":"LINK/EUR","bids":[{"price":17.00443,"qty":67.18712490}],"asks":[],"checksum":3263797674,"timestamp":"2024-06-01T22:42:52.445692Z"}]}
{"channel":"book","type":"update","data":[{"symbol":"LINK/EUR","bids":[{"price":17.00774,"qty":305.00000000}],"asks":[],"checksum":3874758385,"timestamp":"2024-06-01T22:42:52.448316Z"}]}
{"channel":"book","type":"update","data":[{"symbol":"LINK/EUR","bids":[{"price":17.00820,"qty":0.00000000},{"price":17.00344,"qty":1084.05035269}],"asks":[],"checksum":2745041953,"timestamp":"2024-06-01T22:42:52.448438Z"}]}
{"channel":"book","type":"update","data":[{"symbol":"LINK/EUR","bids":[{"price":17.01049,"qty":135.46842406}],"asks":[],"checksum":4187198491,"timestamp":"2024-06-01T22:42:52.455329Z"}]}
{"channel":"book","type":"update","data":[{"symbol":"LINK/EUR","bids":[{"price":17.00567,"qty":271.01352496}],"asks":[],"checksum":1778653438,"timestamp":"2024-06-01T22:42:52.455354Z"}]}
{"channel":"book","type":"update","data":[{"symbol":"LINK/EUR","bids":[{"price":17.01043,"qty":0.00000000},{"price":17.00443,"qty":67.18712490}],"asks":[],"checksum":748961796,"timestamp":"2024-06-01T22:42:52.457838Z"}]}
{"channel":"book","type":"update","data":[{"symbol":"LINK/EUR","bids":[{"price":17.01101,"qty":21.00000000}],"asks":[],"checksum":633964817,"timestamp":"2024-06-01T22:42:52.457891Z"}]}
{"channel":"book","type":"update","data":[{"symbol":"LINK/EUR","bids":[],"asks":[{"price":17.02640,"qty":1198.38655042}],"checksum":3717360681,"timestamp":"2024-06-01T22:42:52.465498Z"}]}
{"channel":"book","type":"update","data":[{"symbol":"LINK/EUR","bids":[{"price":17.01042,"qty":0.00000000},{"price":17.00443,"qty":67.18712490}],"asks":[],"checksum":741164015,"timestamp":"2024-06-01T22:42:52.466215Z"}]}
{"channel":"book","type":"update","data":[{"symbol":"LINK/EUR","bids":[{"price":17.01049,"qty":0.00000000},{"price":17.00230,"qty":28.10000000}],"asks":[],"checksum":900950604,"timestamp":"2024-06-01T22:42:52.470956Z"}]}
{"channel":"book","type":"update","data":[{"symbol":"LINK/EUR","bids":[{"price":17.00567,"qty":0.00000000},{"price":17.00161,"qty":70.02006900}],"asks":[],"checksum":879980821,"timestamp":"2024-06-01T22:42:52.484558Z"}]}
{"channel":"book","type":"update","data":[{"symbol":"LINK/EUR","bids":[{"price":17.00774,"qty":0.00000000},{"price":17.00000,"qty":3.00000000}],"asks":[],"checksum":670661800,"timestamp":"2024-06-01T22:42:52.531772Z"}]}
{"channel":"book","type":"update","data":[{"symbol":"LINK/EUR","bids":[],"asks":[{"price":17.03097,"qty":0.00000000},{"price":17.04178,"qty":32.65332801},{"price":17.02640,"qty":1212.11259958}],"checksum":2863578246,"timestamp":"2024-06-01T22:42:52.532190Z"}]}
{"channel":"book","type":"update","data":[{"symbol":"LINK/EUR","bids":[{"price":17.00230,"qty":0.00000000},{"price":16.99927,"qty":271.11556958}],"asks":[],"checksum":3720078701,"timestamp":"2024-06-01T22:42:52.560807Z"}]}
{"channel":"book","type":"update","data":[{"symbol":"LINK/EUR","bids":[],"asks":[{"price":17.03146,"qty":37.87897436}],"checksum":3939328123,"timestamp":"2024-06-01T22:42:52.571873Z"}]}
{"channel":"book","type":"update","data":[{"symbol":"LINK/EUR","bids":[{"price":17.00443,"qty":0.00000000},{"price":16.99841,"qty":27.08000000}],"asks":[],"checksum":3688092791,"timestamp":"2024-06-01T22:42:52.588682Z"}]}
{"channel":"book","type":"update","data":[{"symbol":"LINK/EUR","bids":[{"price":17.00259,"qty":67.19440608}],"asks":[],"checksum":2686713700,"timestamp":"2024-06-01T22:42:52.594139Z"}]}
{"channel":"book","type":"update","data":[{"symbol":"LINK/EUR","bids":[{"price":16.99927,"qty":0.00000000},{"price":16.99841,"qty":27.08000000}],"asks":[],"checksum":874250246,"timestamp":"2024-06-01T22:42:52.611015Z"}]}
{"channel":"book","type":"update","data":[{"symbol":"LINK/EUR","bids":[{"price":16.99841,"qty":0.00000000},{"price":16.99840,"qty":220.47746800}],"asks":[],"checksum":838161122,"timestamp":"2024-06-01T22:42:52.646046Z"}]}
{"channel":"book","type":"update","data":[{"symbol":"LINK/EUR","bids":[{"price":17.00259,"qty":0.00000000},{"price":16.99795,"qty":1084.08557829}],"asks":[],"checksum":3870423108,"timestamp":"2024-06-01T22:42:52.725317Z"}]}
{"channel":"book","type":"update","data":[{"symbol":"LINK/EUR","bids":[{"price":17.00167,"qty":67.19804726}],"asks":[],"checksum":3402740352,"timestamp":"2024-06-01T22:42:52.730825Z"}]}
{"channel":"book","type":"update","data":[{"symbol":"LINK/EUR","bids":[],"asks":[{"price":17.03550,"qty":70.54889631}],"checksum":433573349,"timestamp":"2024-06-01T22:42:52.752137Z"}]}
{"channel":"book","type":"update","data":[{"symbol":"LINK/EUR","bids":[],"asks":[{"price":17.02655,"qty":0.00000000},{"price":17.03878,"qty":17.30000000}],"checksum":1796762251,"timestamp":"2024-06-01T22:42:52.877845Z"}]}
{"channel":"book","type":"update","data":[{"symbol":"LINK/EUR","bids":[],"asks":[{"price":17.02655,"qty":294.22485595}],"checksum":3450903487,"timestamp":"2024-06-01T22:42:52.881072Z"}]}
{"channel":"book","type":"update","data":[{"symbol":"LINK/EUR","bids":[{"price":17.00697,"qty":135.49642354}],"asks":[],"checksum":532944680,"timestamp":"2024-06-01T22:42:52.995680Z"}]}
{"channel":"book","type":"update","data":[{"symbol":"LINK/EUR","bids":[{"price":17.00184,"qty":271.07464904}],"asks":[],"checksum":4259029330,"timestamp":"2024-06-01T22:42:52.995766Z"}]}
{"channel":"book","type":"update","data":[{"symbol":"LINK/EUR","bids":[],"asks":[{"price":17.02640,"qty":1257.41350737}],"checksum":1594392082,"timestamp":"2024-06-01T22:42:53.024194Z"}]}
{"channel":"book","type":"update","data":[{"symbol":"LINK/EUR","bids":[{"price":17.00403,"qty":34.37116061}],"asks":[],"checksum":1789564959,"timestamp":"2024-06-01T22:42:53.024458Z"}]}
{"channel":"book","type":"update","data":[{"symbol":"LINK/EUR","bids":[{"price":17.00697,"qty":0.00000000},{"price":17.00161,"qty":70.02006900}],"asks":[],"checksum":518213761,"timestamp":"2024-06-01T22:42:53.179608Z"}]}
{"channel":"book","type":"update","data":[{"symbol":"LINK/EUR","bids":[],"asks":[{"price":17.03065,"qty":0.00000000},{"price":17.03878,"qty":17.30000000}],"checksum":61860809,"timestamp":"2024-06-01T22:42:53.460830Z"}]}
{"channel":"book","type":"update","data":[{"symbol":"LINK/EUR","bids":[{"price":17.00589,"qty":305.00000000}],"asks":[],"checksum":567040389,"timestamp":"2024-06-01T22:42:53.463576Z"}]}
{"channel":"book","type":"update","data":[{"symbol":"LINK/EUR","bids":[],"asks":[{"price":17.02684,"qty":270.67685140}],"checksum":199192377,"timestamp":"2024-06-01T22:42:53.464358Z"}]}
{"channel":"book","type":"update","data":[{"symbol":"LINK/EUR","bids":[{"price":17.00731,"qty":135.49372427}],"asks":[],"checksum":2474108519,"timestamp":"2024-06-01T22:42:53.571012Z"}]}
{"channel":"book","type":"update","data":[{"symbol":"LINK/EUR","bids":[{"price":17.00731,"qty":0.00000000},{"price":17.00167,"qty":67.19804726}],"asks":[],"checksum":199192377,"timestamp":"2024-06-01T22:42:53.749570Z"}]}
{"channel":"book","type":"update","data":[{"symbol":"LINK/EUR","bids":[],"asks":[{"price":17.02640,"qty":1212.11259958}],"checksum":2836181113,"timestamp":"2024-06-01T22:42:54.105171Z"}]}
{"channel":"book","type":"update","data":[{"symbol":"LINK/EUR","bids":[],"asks":[{"price":17.03037,"qty":0.00000000},{"price":17.03878,"qty":17.30000000}],"checksum":3809338116,"timestamp":"2024-06-01T22:42:54.109795Z"}]}
{"channel":"book","type":"update","data":[{"symbol":"LINK/EUR","bids":[],"asks":[{"price":17.02654,"qty":9.54674132}],"checksum":3645590034,"timestamp":"2024-06-01T22:42:54.111086Z"}]}
{"channel":"book","type":"update","data":[{"symbol":"LINK/EUR","bids":[],"asks":[{"price":17.03549,"qty":27.28813403}],"checksum":619567397,"timestamp":"2024-06-01T22:42:54.111096Z"}]}
{"channel":"book","type":"update","data":[{"symbol":"LINK/EUR","bids":[],"asks":[{"price":17.02640,"qty":1257.41350737}],"checksum":2252211813,"timestamp":"2024-06-01T22:42:54.224835Z"}]}
{"channel":"book","type":"update","data":[{"symbol":"LINK/EUR","bids":[{"price":17.00589,"qty":0.00000000},{"price":17.00161,"qty":70.02006900},{"price":17.00404,"qty":305.00000000}],"asks":[],"checksum":1868480992,"timestamp":"2024-06-01T22:42:54.572606Z"}]}
{"channel":"book","type":"update","data":[{"symbol":"LINK/EUR","bids":[{"price":17.00727,"qty":135.49400108}],"asks":[],"checksum":2401014421,"timestamp":"2024-06-01T22:42:55.706035Z"}]}
{"channel":"book","type":"update","data":[{"symbol":"LINK/EUR","bids":[{"price":17.00404,"qty":0.00000000},{"price":17.00167,"qty":67.19804726},{"price":17.00624,"qty":305.00000000}],"asks":[],"checksum":4194075163,"timestamp":"2024-06-01T22:42:56.191827Z"}]}
{"channel":"book","type":"update","data":[{"symbol":"LINK/EUR","bids":[{"price":17.00727,"qty":0.00000000},{"price":17.00167,"qty":67.19804726}],"asks":[],"checksum":1824883115,"timestamp":"2024-06-01T22:42:56.393800Z"}]}
{"channel":"book","type":"update","data":[{"symbol":"LINK/EUR","bids":[{"price":17.00756,"qty":135.49169840}],"asks":[],"checksum":2606978068,"timestamp":"2024-06-01T22:42:56.398294Z"}]}
{"channel":"book","type":"update","data":[{"symbol":"LINK/EUR","bids":[{"price":17.00756,"qty":0.00000000},{"price":17.00167,"qty":67.19804726}],"asks":[],"checksum":1824883115,"timestamp":"2024-06-01T22:42:56.508869Z"}]}
{"channel":"book","type":"update","data":[{"symbol":"LINK/EUR","bids":[],"asks":[{"price":17.03549,"qty":0.00000000},{"price":17.03877,"qty":70.02006900}],"checksum":2439189148,"timestamp":"2024-06-01T22:42:56.841267Z"}]}
{"channel":"book","type":"update","data":[{"symbol":"LINK/EUR","bids":[],"asks":[{"price":17.03549,"qty":26.23859041}],"checksum":1812194313,"timestamp":"2024-06-01T22:42:56.842424Z"}]}
{"channel":"book","type":"update","data":[{"symbol":"LINK/EUR","bids":[{"price":17.00694,"qty":135.49667549}],"asks":[],"checksum":744694384,"timestamp":"2024-06-01T22:42:57.295644Z"}]}
{"channel":"book","type":"update","data":[{"symbol":"LINK/EUR","bids":[{"price":17.00403,"qty":0.00000000},{"price":17.00167,"qty":67.19804726}],"asks":[],"checksum":1057911108,"timestamp":"2024-06-01T22:42:57.756997Z"}]}
{"channel":"book","type":"update","data":[{"symbol":"LINK/EUR","bids":[{"price":17.00373,"qty":34.37176702}],"asks":[],"checksum":313458209,"timestamp":"2024-06-01T22:42:57.874089Z"}]}
{"channel":"book","type":"update","data":[{"symbol":"LINK/EUR","bids":[{"price":17.00624,"qty":0.00000000},{"price":17.00167,"qty":67.19804726}],"asks":[],"checksum":2893486804,"timestamp":"2024-06-01T22:42:58.389348Z"}]}
{"channel":"book","type":"update","data":[{"symbol":"LINK/EUR","bids":[{"price":17.00694,"qty":0.00000000},{"price":17.00161,"qty":70.02006900}],"asks":[],"checksum":1156539691,"timestamp":"2024-06-01T22:42:58.520048Z"}]}
{"channel":"book","type":"update","data":[{"symbol":"LINK/EUR","bids":[{"price":17.00497,"qty":305.00000000}],"asks":[],"checksum":2669686144,"timestamp":"2024-06-01T22:42:58.522792Z"}]}
{"channel":"book","type":"update","data":[{"symbol":"LINK/EUR","bids":[{"price":17.00662,"qty":135.49924147}],"asks":[],"checksum":850263632,"timestamp":"2024-06-01T22:42:58.523362Z"}]}
{"channel":"book","type":"update","data":[{"symbol":"LINK/EUR","bids":[{"price":17.00662,"qty":0.00000000},{"price":17.00167,"qty":67.19804726}],"asks":[],"checksum":2669686144,"timestamp":"2024-06-01T22:42:58.551170Z"}]}
{"channel":"book","type":"update","data":[{"symbol":"LINK/EUR","bids":[],"asks":[{"price":17.02684,"qty":0.00000000},{"price":17.03877,"qty":70.02006900}],"checksum":3973381060,"timestamp":"2024-06-01T22:42:58.551351Z"}]}
{"channel":"book","type":"update","data":[{"symbol":"LINK/EUR","bids":[],"asks":[{"price":17.02640,"qty":1528.09719879}],"checksum":1403443617,"timestamp":"2024-06-01T22:42:58.556509Z"}]}
{"channel":"book","type":"update","data":[{"symbol":"LINK/EUR","bids":[{"price":17.00620,"qty":135.50253079}],"asks":[],"checksum":1064430333,"timestamp":"2024-06-01T22:42:59.068859Z"}]}
{"channel":"book","type":"update","data":[{"symbol":"LINK/EUR","bids":[{"price":17.00990,"qty":0.00000000},{"price":17.00167,"qty":67.19804726}],"asks":[],"checksum":3709114158,"timestamp":"2024-06-01T22:42:59.172980Z"}]}
{"channel":"book","type":"update","data":[{"symbol":"LINK/EUR","bids":[{"price":17.00720,"qty":47.43738600}],"asks":[],"checksum":885180035,"timestamp":"2024-06-01T22:42:59.175616Z"}]}
{"channel":"book","type":"update","data":[{"symbol":"LINK/EUR","bids":[{"price":17.00883,"qty":21.00000000}],"asks":[],"checksum":3452281271,"timestamp":"2024-06-01T22:42:59.175634Z"}]}
{"channel":"book","type":"update","data":[{"symbol":"LINK/EUR","bids":[{"price":17.01101,"qty":0.00000000},{"price":17.00184,"qty":271.07464904}],"asks":[],"checksum":4046835269,"timestamp":"2024-06-01T22:42:59.175793Z"}]}
{"channel":"book","type":"update","data":[{"symbol":"LINK/EUR","bids":[],"asks":[{"price":17.02640,"qty":1257.41350737}],"checksum":3427936688,"timestamp":"2024-06-01T22:42:59.481054Z"}]}
{"channel":"book","type":"update","data":[{"symbol":"LINK/EUR","bids":[{"price":17.00620,"qty":0.00000000},{"price":17.00167,"qty":67.19804726}],"asks":[],"checksum":3373587635,"timestamp":"2024-06-01T22:42:59.481070Z"}]}
{"channel":"book","type":"update","data":[{"symbol":"LINK/EUR","bids":[],"asks":[{"price":17.02652,"qty":270.68178907}],"checksum":253768864,"timestamp":"2024-06-01T22:42:59.484863Z"}]}
{"channel":"book","type":"update","data":[{"symbol":"LINK/EUR","bids":[],"asks":[{"price":17.02652,"qty":0.00000000},{"price":17.03877,"qty":70.02006900}],"checksum":3373587635,"timestamp":"2024-06-01T22:42:59.554832Z"}]}
{"channel":"book","type":"update","data":[{"symbol":"LINK/EUR","bids":[{"price":17.00497,"qty":0.00000000},{"price":17.00161,"qty":70.02006900},{"price":17.00374,"qty":305.00000000}],"asks":[],"checksum":3443296561,"timestamp":"2024-06-01T22:42:59.557606Z"}]}
{"channel":"book","type":"update","data":[{"symbol":"LINK/EUR","bids":[{"price":17.00649,"qty":135.50028215}],"asks":[],"checksum":2000487514,"timestamp":"2024-06-01T22:42:59.571142Z"}]}
{"channel":"book","type":"update","data":[{"symbol":"LINK/EUR","bids":[],"asks":[{"price":17.03549,"qty":0.00000000},{"price":17.03878,"qty":17.30000000}],"checksum":1524639715,"timestamp":"2024-06-01T22:42:59.580073Z"}]}
{"channel":"book","type":"update","data":[{"symbol":"LINK/EUR","bids":[],"asks":[{"price":17.02654,"qty":0.00000000},{"price":17.04000,"qty":85.93000000}],"checksum":2140937617,"timestamp":"2024-06-01T22:42:59.580211Z"}]}
{"channel":"book","type":"update","data":[{"symbol":"LINK/EUR","bids":[],"asks":[{"price":17.03549,"qty":37.04992448}],"checksum":1403726073,"timestamp":"2024-06-01T22:42:59.581096Z"}]}
{"channel":"book","type":"update","data":[{"symbol":"LINK/EUR","bids":[{"price":17.00649,"qty":0.00000000},{"price":17.00167,"qty":67.19804726}],"asks":[],"checksum":4021521602,"timestamp":"2024-06-01T22:42:59.643444Z"}]}
{"channel":"book","type":"update","data":[{"symbol":"LINK/EUR","bids":[{"price":17.00612,"qty":135.50317382}],"asks":[],"checksum":91289420,"timestamp":"2024-06-01T22:43:00.577247Z"}]}
{"channel":"book","type":"update","data":[{"symbol":"LINK/EUR","bids":[],"asks":[{"price":17.02640,"qty":1528.09719879}],"checksum":3365574200,"timestamp":"2024-06-01T22:43:00.577282Z"}]}
{"channel":"book","type":"update","data":[{"symbol":"LINK/EUR","bids":[{"price":17.00612,"qty":0.00000000},{"price":17.00167,"qty":67.19804726}],"asks":[],"checksum":3537136439,"timestamp":"2024-06-01T22:43:01.934890Z"}]}
{"channel":"book","type":"update","data":[{"symbol":"LINK/EUR","bids":[{"price":17.00583,"qty":135.50554903}],"asks":[],"checksum":133495796,"timestamp":"2024-06-01T22:43:01.938873Z"}]}
{"channel":"book","type":"update","data":[{"symbol":"LINK/EUR","bids":[{"price":17.00583,"qty":0.00000000},{"price":17.00167,"qty":67.19804726}],"asks":[],"checksum":3537136439,"timestamp":"2024-06-01T22:43:02.103398Z"}]}
{"channel":"book","type":"update","data":[{"symbol":"LINK/EUR","bids":[],"asks":[{"price":17.03549,"qty":0.00000000},{"price":17.04000,"qty":85.93000000}],"checksum":1014990985,"timestamp":"2024-06-01T22:43:02.284295Z"}]}
{"channel":"book","type":"update","data":[{"symbol":"LINK/EUR","bids":[],"asks":[{"price":17.03549,"qty":38.11064865}],"checksum":2392793421,"timestamp":"2024-06-01T22:43:02.285446Z"}]}
{"channel":"book","type":"update","data":[{"symbol":"LINK/EUR","bids":[{"price":17.00609,"qty":135.50340870}],"asks":[],"checksum":2852187436,"timestamp":"2024-06-01T22:43:02.463914Z"}]}
{"channel":"book","type":"update","data":[{"symbol":"LINK/EUR","bids":[],"asks":[{"price":17.03060,"qty":0.00000000},{"price":17.04000,"qty":85.93000000}],"checksum":3657643426,"timestamp":"2024-06-01T22:43:04.709338Z"}]}
{"channel":"book","type":"update","data":[{"symbol":"LINK/EUR","bids":[],"asks":[{"price":17.02640,"qty":1575.53458479}],"checksum":2017910917,"timestamp":"2024-06-01T22:43:04.712192Z"}]}
{"channel":"book","type":"update","data":[{"symbol":"LINK/EUR","bids":[],"asks":[{"price":17.02640,"qty":1530.23367700}],"checksum":2665127755,"timestamp":"2024-06-01T22:43:07.324819Z"}]}
{"channel":"book","type":"update","data":[{"symbol":"LINK/EUR","bids":[],"asks":[{"price":17.02640,"qty":1575.53458479}],"checksum":2017910917,"timestamp":"2024-06-01T22:43:07.447134Z"}]}
{"channel":"book","type":"update","data":[{"symbol":"LINK/EUR","bids":[],"asks":[{"price":17.03549,"qty":0.00000000},{"price":17.04181,"qty":150.00000000}],"checksum":4092258731,"timestamp":"2024-06-01T22:43:07.728290Z"}]}
{"channel":"book","type":"update","data":[{"symbol":"LINK/EUR","bids":[],"asks":[{"price":17.03549,"qty":43.40011637}],"checksum":2804592232,"timestamp":"2024-06-01T22:43:07.729370Z"}]}
{"channel":"book","type":"update","data":[{"symbol":"LINK/EUR","bids":[],"asks":[{"price":17.02655,"qty":0.00000000},{"price":17.04181,"qty":150.00000000}],"checksum":2248473321,"timestamp":"2024-06-01T22:43:07.959673Z"}]}
{"channel":"book","type":"update","data":[{"symbol":"LINK/EUR","bids":[],"asks":[{"price":17.02655,"qty":294.22485595}],"checksum":2804592232,"timestamp":"2024-06-01T22:43:07.965604Z"}]}
{"channel":"book","type":"update","data":[{"symbol":"LINK/EUR","bids":[{"price":17.00374,"qty":0.00000000},{"price":17.00167,"qty":67.19804726},{"price":17.00624,"qty":305.00000000}],"asks":[],"checksum":3971724242,"timestamp":"2024-06-01T22:43:09.939617Z"}]}
{"channel":"book","type":"update","data":[{"symbol":"LINK/EUR","bids":[],"asks":[{"price":17.02640,"qty":1530.23367700}],"checksum":170380316,"timestamp":"2024-06-01T22:43:11.289431Z"}]}
{"channel":"book","type":"update","data":[{"symbol":"LINK/EUR","bids":[],"asks":[{"price":17.02640,"qty":1259.54998558}],"checksum":2971305911,"timestamp":"2024-06-01T22:43:11.294119Z"}]}
{"channel":"book","type":"update","data":[{"symbol":"LINK/EUR","bids":[{"price":17.00609,"qty":0.00000000},{"price":17.00167,"qty":67.19804726}],"asks":[],"checksum":295340378,"timestamp":"2024-06-01T22:43:11.294154Z"}]}
{"channel":"book","type":"update","data":[{"symbol":"LINK/EUR","bids":[],"asks":[{"price":17.02649,"qty":270.68240514}],"checksum":4016234606,"timestamp":"2024-06-01T22:43:11.298626Z"}]}
{"channel":"book","type":"update","data":[{"symbol":"LINK/EUR","bids":[{"price":17.00642,"qty":135.50078727}],"asks":[],"checksum":3907401729,"timestamp":"2024-06-01T22:43:11.298807Z"}]}
{"channel":"book","type":"update","data":[{"symbol":"LINK/EUR","bids":[{"price":17.00642,"qty":0.00000000},{"price":17.00167,"qty":67.19804726}],"asks":[],"checksum":4016234606,"timestamp":"2024-06-01T22:43:11.327832Z"}]}
{"channel":"book","type":"update","data":[{"symbol":"LINK/EUR","bids":[],"asks":[{"price":17.02640,"qty":1304.85089337}],"checksum":1138461436,"timestamp":"2024-06-01T22:43:11.408819Z"}]}
{"channel":"book","type":"update","data":[{"symbol":"LINK/EUR","bids":[],"asks":[{"price":17.02649,"qty":0.00000000},{"price":17.04000,"qty":85.93000000}],"checksum":336157553,"timestamp":"2024-06-01T22:43:12.437395Z"}]}
{"channel":"book","type":"update","data":[{"symbol":"LINK/EUR","bids":[],"asks":[{"price":17.02640,"qty":1575.53458479}],"checksum":3635801760,"timestamp":"2024-06-01T22:43:12.441232Z"}]}
{"channel":"book","type":"update","data":[{"symbol":"LINK/EUR","bids":[{"price":17.00619,"qty":135.50266181}],"asks":[],"checksum":2276443543,"timestamp":"2024-06-01T22:43:12.441338Z"}]}
{"channel":"book","type":"update","data":[{"symbol":"LINK/EUR","bids":[],"asks":[{"price":17.02640,"qty":1304.85089337}],"checksum":1991744352,"timestamp":"2024-06-01T22:43:12.580383Z"}]}
{"channel":"book","type":"update","data":[{"symbol":"LINK/EUR","bids":[],"asks":[{"price":17.03549,"qty":0.00000000},{"price":17.04181,"qty":150.00000000}],"checksum":4031249845,"timestamp":"2024-06-01T22:43:13.123093Z"}]}
{"channel":"book","type":"update","data":[{"symbol":"LINK/EUR","bids":[{"price":17.00624,"qty":0.00000000},{"price":17.00167,"qty":67.19804726}],"asks":[],"checksum":1985897771,"timestamp":"2024-06-01T22:43:13.123157Z"}]}
{"channel":"book","type":"update","data":[{"symbol":"LINK/EUR","bids":[],"asks":[{"price":17.03549,"qty":44.45801009}],"checksum":2447189695,"timestamp":"2024-06-01T22:43:13.124027Z"}]}
{"channel":"book","type":"update","data":[{"symbol":"LINK/EUR","bids":[],"asks":[{"price":17.02640,"qty":1575.53458479}],"checksum":1566675822,"timestamp":"2024-06-01T22:43:13.420588Z"}]}
{"channel":"book","type":"update","data":[{"symbol":"LINK/EUR","bids":[{"price":17.01685,"qty":0.00000000},{"price":17.00161,"qty":70.02006900}],"asks":[],"checksum":245062424,"timestamp":"2024-06-01T22:43:14.819321Z"}]}
{"channel":"book","type":"update","data":[{"symbol":"LINK/EUR","bids":[{"price":17.01420,"qty":28.09000000}],"asks":[],"checksum":1960246085,"timestamp":"2024-06-01T22:43:14.821832Z"}]}
{"channel":"book","type":"update","data":[{"symbol":"LINK/EUR","bids":[{"price":17.00624,"qty":305.00000000}],"asks":[],"checksum":1515141492,"timestamp":"2024-06-01T22:43:14.822281Z"}]}
{"channel":"book","type":"update","data":[{"symbol":"LINK/EUR","bids":[{"price":17.00624,"qty":0.00000000},{"price":17.00167,"qty":67.19804726}],"asks":[],"checksum":1960246085,"timestamp":"2024-06-01T22:43:15.092828Z"}]}
{"channel":"book","type":"update","data":[{"symbol":"LINK/EUR","bids":[{"price":17.00619,"qty":0.00000000},{"price":17.00161,"qty":70.02006900}],"asks":[],"checksum":2861029656,"timestamp":"2024-06-01T22:43:15.301441Z"}]}
{"channel":"book","type":"update","data":[{"symbol":"LINK/EUR","bids":[],"asks":[{"price":17.02640,"qty":1304.85089337}],"checksum":440769964,"timestamp":"2024-06-01T22:43:15.301558Z"}]}
{"channel":"book","type":"update","data":[{"symbol":"LINK/EUR","bids":[],"asks":[{"price":17.02689,"qty":270.67604227}],"checksum":1908552,"timestamp":"2024-06-01T22:43:15.307071Z"}]}
{"channel":"book","type":"update","data":[{"symbol":"LINK/EUR","bids":[{"price":17.00662,"qty":135.49925514}],"asks":[],"checksum":2085034908,"timestamp":"2024-06-01T22:43:15.307110Z"}]}
{"channel":"book","type":"update","data":[{"symbol":"LINK/EUR","bids":[{"price":17.00662,"qty":0.00000000},{"price":17.00161,"qty":70.02006900}],"asks":[],"checksum":1908552,"timestamp":"2024-06-01T22:43:15.686632Z"}]}
{"channel":"book","type":"update","data":[{"symbol":"LINK/EUR","bids":[],"asks":[{"price":17.03549,"qty":0.00000000},{"price":17.04000,"qty":85.93000000}],"checksum":1192421621,"timestamp":"2024-06-01T22:43:15.776219Z"}]}
{"channel":"book","type":"update","data":[{"symbol":"LINK/EUR","bids":[],"asks":[{"price":17.02654,"qty":9.54751730}],"checksum":1339907827,"timestamp":"2024-06-01T22:43:15.777477Z"}]}
{"channel":"book","type":"update","data":[{"symbol":"LINK/EUR","bids":[],"asks":[{"price":17.03549,"qty":28.33998100}],"checksum":375591994,"timestamp":"2024-06-01T22:43:15.777652Z"}]}
{"channel":"book","type":"update","data":[{"symbol":"LINK/EUR","bids":[],"asks":[{"price":17.02689,"qty":0.00000000},{"price":17.03878,"qty":17.30000000}],"checksum":304693036,"timestamp":"2024-06-01T22:43:16.690731Z"}]}
{"channel":"book","type":"update","data":[{"symbol":"LINK/EUR","bids":[{"price":17.00624,"qty":305.00000000}],"asks":[],"checksum":339320476,"timestamp":"2024-06-01T22:43:16.693423Z"}]}
{"channel":"book","type":"update","data":[{"symbol":"LINK/EUR","bids":[{"price":17.00596,"qty":135.50444654}],"asks":[],"checksum":1613398541,"timestamp":"2024-06-01T22:43:16.695144Z"}]}
{"channel":"book","type":"update","data":[{"symbol":"LINK/EUR","bids":[],"asks":[{"price":17.02640,"qty":1575.53458479}],"checksum":2895525852,"timestamp":"2024-06-01T22:43:16.695168Z"}]}
{"channel":"book","type":"update","data":[{"symbol":"LINK/EUR","bids":[{"price":17.00624,"qty":0.00000000},{"price":17.00167,"qty":67.19804726}],"asks":[],"checksum":2415111573,"timestamp":"2024-06-01T22:43:17.222641Z"}]}
{"channel":"book","type":"update","data":[{"symbol":"LINK/EUR","bids":[{"price":17.00624,"qty":305.00000000}],"asks":[],"checksum":2895525852,"timestamp":"2024-06-01T22:43:17.942258Z"}]}
{"channel":"book","type":"update","data":[{"symbol":"LINK/EUR","bids":[],"asks":[{"price":17.02640,"qty":1304.85089337}],"checksum":1613398541,"timestamp":"2024-06-01T22:43:18.225609Z"}]}
