{"channel":"book","type":"snapshot","data":[{"symbol":"LINK/USDT","bids":[{"price":18.46727,"qty":54.19545287},{"price":18.46666,"qty":81.23287565},{"price":18.46323,"qty":9.00000000},{"price":18.46320,"qty":9.40000000},{"price":18.46271,"qty":243.48672997},{"price":18.46270,"qty":33.73844400},{"price":18.46160,"qty":135.53026507},{"price":18.46000,"qty":121.61826868},{"price":18.45359,"qty":49.18000000},{"price":18.45329,"qty":2.34929424}],"asks":[{"price":18.46998,"qty":54.18753263},{"price":18.47258,"qty":9.00000000},{"price":18.47261,"qty":4.87794363},{"price":18.47279,"qty":9.40000000},{"price":18.47334,"qty":9.00000000},{"price":18.47410,"qty":135.43862671},{"price":18.47500,"qty":131.24451078},{"price":18.47618,"qty":49.15000000},{"price":18.47768,"qty":243.48672997},{"price":18.48050,"qty":33.73844400}],"checksum":2959058364}]}
{"channel":"book","type":"update","data":[{"symbol":"LINK/USDT","bids":[{"price":18.46727,"qty":0.00000000},{"price":18.45328,"qty":48.75805200}],"asks":[],"checksum":1256668458,"timestamp":"2024-06-01T22:42:51.526587Z"}]}
{"channel":"book","type":"update","data":[{"symbol":"LINK/USDT","bids":[],"asks":[{"price":18.46998,"qty":0.00000000},{"price":18.48096,"qty":270.77670071}],"checksum":2847354374,"timestamp":"2024-06-01T22:42:51.526659Z"}]}
{"channel":"book","type":"update","data":[{"symbol":"LINK/USDT","bids":[],"asks":[{"price":18.47279,"qty":0.00000000},{"price":18.48860,"qty":69.08000000}],"checksum":3086795750,"timestamp":"2024-06-01T22:42:51.529285Z"}]}
{"channel":"book","type":"update","data":[{"symbol":"LINK/USDT","bids":[],"asks":[{"price":18.47203,"qty":9.40000000}],"checksum":2428188538,"timestamp":"2024-06-01T22:42:51.529501Z"}]}
{"channel":"book","type":"update","data":[{"symbol":"LINK/USDT","bids":[],"asks":[{"price":18.47251,"qty":4.87792245}],"checksum":3006598943,"timestamp":"2024-06-01T22:42:51.529652Z"}]}
{"channel":"book","type":"update","data":[{"symbol":"LINK/USDT","bids":[],"asks":[{"price":18.47258,"qty":0.00000000},{"price":18.48096,"qty":270.77670071}],"checksum":2355254915,"timestamp":"2024-06-01T22:42:51.531227Z"}]}
{"channel":"book","type":"update","data":[{"symbol":"LINK/USDT","bids":[],"asks":[{"price":18.46995,"qty":9.00000000}],"checksum":1462699963,"timestamp":"2024-06-01T22:42:51.531434Z"}]}
{"channel":"book","type":"update","data":[{"symbol":"LINK/USDT","bids":[],"asks":[{"price":18.47261,"qty":0.00000000},{"price":18.48096,"qty":270.77670071}],"checksum":5197801,"timestamp":"2024-06-01T22:42:51.532082Z"}]}
{"channel":"book","type":"update","data":[{"symbol":"LINK/USDT","bids":[],"asks":[{"price":18.47334,"qty":0.00000000},{"price":18.48860,"qty":69.08000000}],"checksum":105859174,"timestamp":"2024-06-01T22:42:51.584203Z"}]}
{"channel":"book","type":"update","data":[{"symbol":"LINK/USDT","bids":[],"asks":[{"price":18.46995,"qty":0.00000000},{"price":18.48861,"qty":48.75805200}],"checksum":57285296,"timestamp":"2024-06-01T22:42:52.084787Z"}]}
{"channel":"book","type":"update","data":[{"symbol":"LINK/USDT","bids":[],"asks":[{"price":18.47200,"qty":9.00000000}],"checksum":1296127777,"timestamp":"2024-06-01T22:42:52.084873Z"}]}
{"channel":"book","type":"update","data":[{"symbol":"LINK/USDT","bids":[{"price":18.46666,"qty":0.00000000},{"price":18.45288,"qty":135.48020688}],"asks":[],"checksum":3478418785,"timestamp":"2024-06-01T22:42:52.371315Z"}]}
{"channel":"book","type":"update","data":[{"symbol":"LINK/USDT","bids":[],"asks":[{"price":18.46962,"qty":54.18860008}],"checksum":1952532489,"timestamp":"2024-06-01T22:42:52.375930Z"}]}
{"channel":"book","type":"update","data":[{"symbol":"LINK/USDT","bids":[{"price":18.46331,"qty":54.20707020}],"asks":[],"checksum":2085160485,"timestamp":"2024-06-01T22:42:52.376190Z"}]}
{"channel":"book","type":"update","data":[{"symbol":"LINK/USDT","bids":[{"price":18.46320,"qty":0.00000000},{"price":18.45288,"qty":135.48020688}],"asks":[],"checksum":1833057219,"timestamp":"2024-06-01T22:42:52.378814Z"}]}
{"channel":"book","type":"update","data":[{"symbol":"LINK/USDT","bids":[{"price":18.46339,"qty":9.40000000}],"asks":[],"checksum":880859174,"timestamp":"2024-06-01T22:42:52.379266Z"}]}
{"channel":"book","type":"update","data":[{"symbol":"LINK/USDT","bids":[{"price":18.46331,"qty":0.00000000},{"price":18.45288,"qty":135.48020688}],"asks":[],"checksum":1900399754,"timestamp":"2024-06-01T22:42:52.380561Z"}]}
{"channel":"book","type":"update","data":[{"symbol":"LINK/USDT","bids":[{"price":18.46663,"qty":81.23285583}],"asks":[],"checksum":1860209755,"timestamp":"2024-06-01T22:42:52.411515Z"}]}
{"channel":"book","type":"update","data":[{"symbol":"LINK/USDT","bids":[{"price":18.46323,"qty":0.00000000},{"price":18.45288,"qty":135.48020688}],"asks":[],"checksum":2804811891,"timestamp":"2024-06-01T22:42:52.441546Z"}]}
{"channel":"book","type":"update","data":[{"symbol":"LINK/USDT","bids":[{"price":18.46000,"qty":0.00000000},{"price":18.45265,"qty":271.19199748}],"asks":[],"checksum":1262990685,"timestamp":"2024-06-01T22:42:52.443078Z"}]}
{"channel":"book","type":"update","data":[{"symbol":"LINK/USDT","bids":[],"asks":[{"price":18.48095,"qty":69.08000000}],"checksum":2898887517,"timestamp":"2024-06-01T22:42:52.443743Z"}]}
{"channel":"book","type":"update","data":[{"symbol":"LINK/USDT","bids":[],"asks":[{"price":18.46959,"qty":9.00000000}],"checksum":4239640267,"timestamp":"2024-06-01T22:42:52.446259Z"}]}
{"channel":"book","type":"update","data":[{"symbol":"LINK/USDT","bids":[{"price":18.46271,"qty":0.00000000},{"price":18.44868,"qty":271.25031961}],"asks":[],"checksum":842178780,"timestamp":"2024-06-01T22:42:52.446280Z"}]}
{"channel":"book","type":"update","data":[{"symbol":"LINK/USDT","bids":[],"asks":[{"price":18.46962,"qty":0.00000000},{"price":18.48095,"qty":69.08000000}],"checksum":527920551,"timestamp":"2024-06-01T22:42:52.448515Z"}]}
{"channel":"book","type":"update","data":[{"symbol":"LINK/USDT","bids":[{"price":18.45600,"qty":153.86510377}],"asks":[],"checksum":784336361,"timestamp":"2024-06-01T22:42:52.448525Z"}]}
{"channel":"book","type":"update","data":[{"symbol":"LINK/USDT","bids":[{"price":18.45360,"qty":151.76061931}],"asks":[],"checksum":1076605065,"timestamp":"2024-06-01T22:42:52.451669Z"}]}
{"channel":"book","type":"update","data":[{"symbol":"LINK/USDT","bids":[],"asks":[{"price":18.47410,"qty":0.00000000},{"price":18.48096,"qty":270.77670071}],"checksum":2129156662,"timestamp":"2024-06-01T22:42:52.452128Z"}]}
{"channel":"book","type":"update","data":[{"symbol":"LINK/USDT","bids":[{"price":18.46160,"qty":0.00000000},{"price":18.45265,"qty":271.19199748}],"asks":[],"checksum":2611340067,"timestamp":"2024-06-01T22:42:52.452306Z"}]}
{"channel":"book","type":"update","data":[{"symbol":"LINK/USDT","bids":[{"price":18.45601,"qty":125.91747722}],"asks":[],"checksum":3982829203,"timestamp":"2024-06-01T22:42:52.453396Z"}]}
{"channel":"book","type":"update","data":[{"symbol":"LINK/USDT","bids":[{"price":18.45360,"qty":0.00000000},{"price":18.45265,"qty":271.19199748}],"asks":[],"checksum":2207159283,"timestamp":"2024-06-01T22:42:52.455893Z"}]}
{"channel":"book","type":"update","data":[{"symbol":"LINK/USDT","bids":[],"asks":[{"price":18.47201,"qty":135.45397142}],"checksum":2748012642,"timestamp":"2024-06-01T22:42:52.457299Z"}]}
{"channel":"book","type":"update","data":[{"symbol":"LINK/USDT","bids":[{"price":18.45885,"qty":135.55046055}],"asks":[],"checksum":234114763,"timestamp":"2024-06-01T22:42:52.457443Z"}]}
{"channel":"book","type":"update","data":[{"symbol":"LINK/USDT","bids":[],"asks":[{"price":18.47203,"qty":0.00000000},{"price":18.48096,"qty":270.77670071}],"checksum":1062329339,"timestamp":"2024-06-01T22:42:52.459974Z"}]}
{"channel":"book","type":"update","data":[{"symbol":"LINK/USDT","bids":[],"asks":[{"price":18.47145,"qty":9.40000000}],"checksum":341128821,"timestamp":"2024-06-01T22:42:52.460050Z"}]}
{"channel":"book","type":"update","data":[{"symbol":"LINK/USDT","bids":[],"asks":[{"price":18.46941,"qty":4.87884603}],"checksum":3523392474,"timestamp":"2024-06-01T22:42:52.465176Z"}]}
{"channel":"book","type":"update","data":[{"symbol":"LINK/USDT","bids":[],"asks":[{"price":18.47251,"qty":0.00000000},{"price":18.48095,"qty":69.08000000}],"checksum":1804891779,"timestamp":"2024-06-01T22:42:52.465964Z"}]}
{"channel":"book","type":"update","data":[{"symbol":"LINK/USDT","bids":[{"price":18.45885,"qty":0.00000000},{"price":18.45265,"qty":271.19199748}],"asks":[],"checksum":3316342826,"timestamp":"2024-06-01T22:42:52.491385Z"}]}
{"channel":"book","type":"update","data":[{"symbol":"LINK/USDT","bids":[],"asks":[{"price":18.47200,"qty":252.48672997}],"checksum":1156931875,"timestamp":"2024-06-01T22:42:52.495226Z"}]}
{"channel":"book","type":"update","data":[{"symbol":"LINK/USDT","bids":[],"asks":[{"price":18.47629,"qty":270.84508036}],"checksum":3931521259,"timestamp":"2024-06-01T22:42:52.495400Z"}]}
{"channel":"book","type":"update","data":[{"symbol":"LINK/USDT","bids":[],"asks":[{"price":18.46959,"qty":0.00000000},{"price":18.48095,"qty":69.08000000}],"checksum":2401980577,"timestamp":"2024-06-01T22:42:52.496014Z"}]}
{"channel":"book","type":"update","data":[{"symbol":"LINK/USDT","bids":[],"asks":[{"price":18.46938,"qty":9.00000000}],"checksum":290862439,"timestamp":"2024-06-01T22:42:52.496320Z"}]}
{"channel":"book","type":"update","data":[{"symbol":"LINK/USDT","bids":[],"asks":[{"price":18.47145,"qty":0.00000000},{"price":18.48095,"qty":69.08000000}],"checksum":628045693,"timestamp":"2024-06-01T22:42:52.497772Z"}]}
{"channel":"book","type":"update","data":[{"symbol":"LINK/USDT","bids":[],"asks":[{"price":18.46939,"qty":9.40000000}],"checksum":3062891284,"timestamp":"2024-06-01T22:42:52.498098Z"}]}
{"channel":"book","type":"update","data":[{"symbol":"LINK/USDT","bids":[],"asks":[{"price":18.46920,"qty":4.87947551}],"checksum":683453589,"timestamp":"2024-06-01T22:42:52.499110Z"}]}
{"channel":"book","type":"update","data":[{"symbol":"LINK/USDT","bids":[],"asks":[{"price":18.46941,"qty":0.00000000},{"price":18.48050,"qty":33.73844400}],"checksum":1645412222,"timestamp":"2024-06-01T22:42:52.500586Z"}]}
{"channel":"book","type":"update","data":[{"symbol":"LINK/USDT","bids":[],"asks":[{"price":18.46907,"qty":9.40000000}],"checksum":3208463802,"timestamp":"2024-06-01T22:42:52.501845Z"}]}
{"channel":"book","type":"update","data":[{"symbol":"LINK/USDT","bids":[],"asks":[{"price":18.46939,"qty":0.00000000},{"price":18.48050,"qty":33.73844400}],"checksum":3421215557,"timestamp":"2024-06-01T22:42:52.502038Z"}]}
{"channel":"book","type":"update","data":[{"symbol":"LINK/USDT","bids":[],"asks":[{"price":18.46889,"qty":4.87947551}],"checksum":165037292,"timestamp":"2024-06-01T22:42:52.504508Z"}]}
{"channel":"book","type":"update","data":[{"symbol":"LINK/USDT","bids":[],"asks":[{"price":18.46920,"qty":0.00000000},{"price":18.48050,"qty":33.73844400}],"checksum":967851443,"timestamp":"2024-06-01T22:42:52.505044Z"}]}
{"channel":"book","type":"update","data":[{"symbol":"LINK/USDT","bids":[{"price":18.45265,"qty":0.00000000},{"price":18.44868,"qty":271.25031961}],"asks":[],"checksum":2161132670,"timestamp":"2024-06-01T22:42:52.507403Z"}]}
{"channel":"book","type":"update","data":[{"symbol":"LINK/USDT","bids":[],"asks":[{"price":18.47201,"qty":0.00000000},{"price":18.48095,"qty":69.08000000}],"checksum":747339654,"timestamp":"2024-06-01T22:42:52.507468Z"}]}
{"channel":"book","type":"update","data":[{"symbol":"LINK/USDT","bids":[{"price":18.46339,"qty":0.00000000},{"price":18.44660,"qty":100.82355200}],"asks":[],"checksum":4125659981,"timestamp":"2024-06-01T22:42:52.514575Z"}]}
{"channel":"book","type":"update","data":[{"symbol":"LINK/USDT","bids":[],"asks":[{"price":18.47768,"qty":0.00000000},{"price":18.48096,"qty":270.77670071}],"checksum":2160177446,"timestamp":"2024-06-01T22:42:52.560294Z"}]}
{"channel":"book","type":"update","data":[{"symbol":"LINK/USDT","bids":[{"price":18.45790,"qty":243.48672997}],"asks":[],"checksum":962715647,"timestamp":"2024-06-01T22:42:52.560411Z"}]}
{"channel":"book","type":"update","data":[{"symbol":"LINK/USDT","bids":[{"price":18.45601,"qty":0.00000000},{"price":18.44660,"qty":100.82355200}],"asks":[],"checksum":1345070409,"timestamp":"2024-06-01T22:42:52.564540Z"}]}
{"channel":"book","type":"update","data":[{"symbol":"LINK/USDT","bids":[],"asks":[{"price":18.46886,"qty":9.00000000}],"checksum":484904384,"timestamp":"2024-06-01T22:42:52.585140Z"}]}
{"channel":"book","type":"update","data":[{"symbol":"LINK/USDT","bids":[],"asks":[{"price":18.46938,"qty":0.00000000},{"price":18.48096,"qty":270.77670071}],"checksum":4123791268,"timestamp":"2024-06-01T22:42:52.585245Z"}]}
{"channel":"book","type":"update","data":[{"symbol":"LINK/USDT","bids":[{"price":18.45288,"qty":0.00000000},{"price":18.44220,"qty":271.34566116}],"asks":[],"checksum":2796432263,"timestamp":"2024-06-01T22:42:52.587236Z"}]}
{"channel":"book","type":"update","data":[{"symbol":"LINK/USDT","bids":[],"asks":[{"price":18.46868,"qty":4.87945163}],"checksum":3539775841,"timestamp":"2024-06-01T22:42:52.588013Z"}]}
{"channel":"book","type":"update","data":[{"symbol":"LINK/USDT","bids":[],"asks":[{"price":18.46889,"qty":0.00000000},{"price":18.48096,"qty":270.77670071}],"checksum":1778677338,"timestamp":"2024-06-01T22:42:52.588047Z"}]}
{"channel":"book","type":"update","data":[{"symbol":"LINK/USDT","bids":[],"asks":[{"price":18.46907,"qty":0.00000000},{"price":18.48861,"qty":48.75805200}],"checksum":3537277072,"timestamp":"2024-06-01T22:42:52.588055Z"}]}
{"channel":"book","type":"update","data":[{"symbol":"LINK/USDT","bids":[],"asks":[{"price":18.46831,"qty":9.40000000}],"checksum":935160592,"timestamp":"2024-06-01T22:42:52.588151Z"}]}
{"channel":"book","type":"update","data":[{"symbol":"LINK/USDT","bids":[],"asks":[{"price":18.47199,"qty":243.48672997}],"checksum":887937461,"timestamp":"2024-06-01T22:42:52.589059Z"}]}
{"channel":"book","type":"update","data":[{"symbol":"LINK/USDT","bids":[],"asks":[{"price":18.47200,"qty":243.48672997}],"checksum":1624918316,"timestamp":"2024-06-01T22:42:52.590082Z"}]}
{"channel":"book","type":"update","data":[{"symbol":"LINK/USDT","bids":[{"price":18.45600,"qty":0.00000000},{"price":18.44000,"qty":40.55000000}],"asks":[],"checksum":1432565132,"timestamp":"2024-06-01T22:42:52.591431Z"}]}
{"channel":"book","type":"update","data":[{"symbol":"LINK/USDT","bids":[],"asks":[{"price":18.46813,"qty":4.87945163}],"checksum":2606776084,"timestamp":"2024-06-01T22:42:52.591638Z"}]}
{"channel":"book","type":"update","data":[{"symbol":"LINK/USDT","bids":[],"asks":[{"price":18.46868,"qty":0.00000000},{"price":18.48095,"qty":69.08000000}],"checksum":2085894519,"timestamp":"2024-06-01T22:42:52.591853Z"}]}
{"channel":"book","type":"update","data":[{"symbol":"LINK/USDT","bids":[{"price":18.45400,"qty":108.96536333}],"asks":[],"checksum":2377758300,"timestamp":"2024-06-01T22:42:52.597185Z"}]}
{"channel":"book","type":"update","data":[{"symbol":"LINK/USDT","bids":[{"price":18.45329,"qty":0.00000000},{"price":18.44000,"qty":40.55000000}],"asks":[],"checksum":2284148735,"timestamp":"2024-06-01T22:42:52.614725Z"}]}
{"channel":"book","type":"update","data":[{"symbol":"LINK/USDT","bids":[{"price":18.45401,"qty":2.34929424}],"asks":[],"checksum":784411612,"timestamp":"2024-06-01T22:42:52.614825Z"}]}
{"channel":"book","type":"update","data":[{"symbol":"LINK/USDT","bids":[],"asks":[{"price":18.47500,"qty":0.00000000},{"price":18.48096,"qty":270.77670071}],"checksum":3736388319,"timestamp":"2024-06-01T22:42:52.728330Z"}]}
{"channel":"book","type":"update","data":[{"symbol":"LINK/USDT","bids":[{"price":18.45400,"qty":0.00000000},{"price":18.44000,"qty":40.55000000}],"asks":[],"checksum":192650098,"timestamp":"2024-06-01T22:42:52.728385Z"}]}
{"channel":"book","type":"update","data":[{"symbol":"LINK/USDT","bids":[],"asks":[{"price":18.46900,"qty":89.93735595}],"checksum":790565190,"timestamp":"2024-06-01T22:42:52.732857Z"}]}
{"channel":"book","type":"update","data":[{"symbol":"LINK/USDT","bids":[{"price":18.45300,"qty":91.87779574}],"asks":[],"checksum":498244441,"timestamp":"2024-06-01T22:42:52.733627Z"}]}
{"channel":"book","type":"update","data":[{"symbol":"LINK/USDT","bids":[{"price":18.45993,"qty":54.21699732}],"asks":[],"checksum":1093024104,"timestamp":"2024-06-01T22:42:52.897106Z"}]}
{"channel":"book","type":"update","data":[{"symbol":"LINK/USDT","bids":[],"asks":[{"price":18.46678,"qty":54.19692230}],"checksum":928577692,"timestamp":"2024-06-01T22:42:52.898739Z"}]}
{"channel":"book","type":"update","data":[{"symbol":"LINK/USDT","bids":[],"asks":[{"price":18.48049,"qty":69.08000000}],"checksum":3647084382,"timestamp":"2024-06-01T22:42:52.900408Z"}]}
{"channel":"book","type":"update","data":[{"symbol":"LINK/USDT","bids":[],"asks":[{"price":18.47199,"qty":0.00000000},{"price":18.48050,"qty":33.73844400}],"checksum":429721814,"timestamp":"2024-06-01T22:42:52.900809Z"}]}
{"channel":"book","type":"update","data":[{"symbol":"LINK/USDT","bids":[],"asks":[{"price":18.46831,"qty":0.00000000},{"price":18.48096,"qty":270.77670071}],"checksum":4230446461,"timestamp":"2024-06-01T22:42:52.901558Z"}]}
{"channel":"book","type":"update","data":[{"symbol":"LINK/USDT","bids":[],"asks":[{"price":18.46664,"qty":9.40000000}],"checksum":3082440636,"timestamp":"2024-06-01T22:42:52.902036Z"}]}
{"channel":"book","type":"update","data":[{"symbol":"LINK/USDT","bids":[],"asks":[{"price":18.46810,"qty":9.00000000}],"checksum":2587293536,"timestamp":"2024-06-01T22:42:52.904696Z"}]}
{"channel":"book","type":"update","data":[{"symbol":"LINK/USDT","bids":[{"price":18.46663,"qty":0.00000000},{"price":18.44220,"qty":271.34566116}],"asks":[],"checksum":516107068,"timestamp":"2024-06-01T22:42:52.942167Z"}]}
{"channel":"book","type":"update","data":[{"symbol":"LINK/USDT","bids":[{"price":18.46270,"qty":0.00000000},{"price":18.44000,"qty":40.55000000}],"asks":[],"checksum":4186411480,"timestamp":"2024-06-01T22:42:52.944944Z"}]}
{"channel":"book","type":"update","data":[{"symbol":"LINK/USDT","bids":[],"asks":[{"price":18.46678,"qty":0.00000000},{"price":18.48050,"qty":33.73844400}],"checksum":3563177589,"timestamp":"2024-06-01T22:42:52.946585Z"}]}
{"channel":"book","type":"update","data":[{"symbol":"LINK/USDT","bids":[],"asks":[{"price":18.46810,"qty":0.00000000},{"price":18.48096,"qty":270.77670071}],"checksum":3643198076,"timestamp":"2024-06-01T22:42:52.946716Z"}]}
{"channel":"book","type":"update","data":[{"symbol":"LINK/USDT","bids":[],"asks":[{"price":18.46661,"qty":9.00000000}],"checksum":2745091099,"timestamp":"2024-06-01T22:42:52.946762Z"}]}
{"channel":"book","type":"update","data":[{"symbol":"LINK/USDT","bids":[{"price":18.45890,"qty":33.73844400}],"asks":[],"checksum":1985120382,"timestamp":"2024-06-01T22:42:52.947826Z"}]}
{"channel":"book","type":"update","data":[{"symbol":"LINK/USDT","bids":[],"asks":[{"price":18.46664,"qty":0.00000000},{"price":18.48096,"qty":270.77670071}],"checksum":3048650269,"timestamp":"2024-06-01T22:42:52.949553Z"}]}
{"channel":"book","type":"update","data":[{"symbol":"LINK/USDT","bids":[],"asks":[{"price":18.46758,"qty":9.40000000}],"checksum":1113122694,"timestamp":"2024-06-01T22:42:52.949806Z"}]}
{"channel":"book","type":"update","data":[{"symbol":"LINK/USDT","bids":[{"price":18.46192,"qty":81.29569159}],"asks":[],"checksum":131092246,"timestamp":"2024-06-01T22:42:52.982442Z"}]}
{"channel":"book","type":"update","data":[{"symbol":"LINK/USDT","bids":[],"asks":[{"price":18.46886,"qty":0.00000000},{"price":18.48096,"qty":270.77670071}],"checksum":3309089817,"timestamp":"2024-06-01T22:42:52.986815Z"}]}
{"channel":"book","type":"update","data":[{"symbol":"LINK/USDT","bids":[{"price":18.45993,"qty":0.00000000},{"price":18.44220,"qty":271.34566116}],"asks":[],"checksum":3967417488,"timestamp":"2024-06-01T22:42:52.995091Z"}]}
{"channel":"book","type":"update","data":[{"symbol":"LINK/USDT","bids":[{"price":18.45468,"qty":135.58103617}],"asks":[],"checksum":4033108515,"timestamp":"2024-06-01T22:42:52.998843Z"}]}
{"channel":"book","type":"update","data":[{"symbol":"LINK/USDT","bids":[],"asks":[{"price":18.46948,"qty":135.47246839}],"checksum":2007729134,"timestamp":"2024-06-01T22:42:52.998941Z"}]}
{"channel":"book","type":"update","data":[{"symbol":"LINK/USDT","bids":[{"price":18.45401,"qty":0.00000000},{"price":18.44220,"qty":271.34566116}],"asks":[],"checksum":2173108236,"timestamp":"2024-06-01T22:42:53.004540Z"}]}
{"channel":"book","type":"update","data":[{"symbol":"LINK/USDT","bids":[{"price":18.45469,"qty":2.34929424}],"asks":[],"checksum":1713546459,"timestamp":"2024-06-01T22:42:53.004701Z"}]}
{"channel":"book","type":"update","data":[{"symbol":"LINK/USDT","bids":[{"price":18.46192,"qty":0.00000000},{"price":18.44220,"qty":271.34566116}],"asks":[],"checksum":1464621397,"timestamp":"2024-06-01T22:42:53.436411Z"}]}
{"channel":"book","type":"update","data":[{"symbol":"LINK/USDT","bids":[{"price":18.45891,"qty":243.48672997}],"asks":[],"checksum":2532982159,"timestamp":"2024-06-01T22:42:53.440767Z"}]}
{"channel":"book","type":"update","data":[{"symbol":"LINK/USDT","bids":[],"asks":[{"price":18.46654,"qty":54.19763275}],"checksum":4233638104,"timestamp":"2024-06-01T22:42:53.441571Z"}]}
{"channel":"book","type":"update","data":[{"symbol":"LINK/USDT","bids":[{"price":18.45997,"qty":54.21687262}],"asks":[],"checksum":593839408,"timestamp":"2024-06-01T22:42:53.441592Z"}]}
{"channel":"book","type":"update","data":[{"symbol":"LINK/USDT","bids":[],"asks":[{"price":18.46599,"qty":9.40000000}],"checksum":2421645105,"timestamp":"2024-06-01T22:42:53.444567Z"}]}
{"channel":"book","type":"update","data":[{"symbol":"LINK/USDT","bids":[],"asks":[{"price":18.46758,"qty":0.00000000},{"price":18.48049,"qty":69.08000000}],"checksum":2007813483,"timestamp":"2024-06-01T22:42:53.444588Z"}]}
{"channel":"book","type":"update","data":[{"symbol":"LINK/USDT","bids":[],"asks":[{"price":18.46654,"qty":0.00000000},{"price":18.48050,"qty":33.73844400}],"checksum":1679666429,"timestamp":"2024-06-01T22:42:53.446085Z"}]}
{"channel":"book","type":"update","data":[{"symbol":"LINK/USDT","bids":[{"price":18.46135,"qty":81.30310921}],"asks":[],"checksum":109386148,"timestamp":"2024-06-01T22:42:53.476608Z"}]}
{"channel":"book","type":"update","data":[{"symbol":"LINK/USDT","bids":[{"price":18.45891,"qty":0.00000000},{"price":18.44868,"qty":271.25031961}],"asks":[],"checksum":1567529358,"timestamp":"2024-06-01T22:42:53.480296Z"}]}
{"channel":"book","type":"update","data":[{"symbol":"LINK/USDT","bids":[],"asks":[{"price":18.46596,"qty":9.00000000}],"checksum":410345396,"timestamp":"2024-06-01T22:42:53.481217Z"}]}
{"channel":"book","type":"update","data":[{"symbol":"LINK/USDT","bids":[{"price":18.45997,"qty":0.00000000},{"price":18.44660,"qty":100.82355200}],"asks":[],"checksum":4108262664,"timestamp":"2024-06-01T22:42:53.490180Z"}]}
{"channel":"book","type":"update","data":[{"symbol":"LINK/USDT","bids":[],"asks":[{"price":18.46661,"qty":0.00000000},{"price":18.48050,"qty":33.73844400}],"checksum":350378236,"timestamp":"2024-06-01T22:42:53.584654Z"}]}
{"channel":"book","type":"update","data":[{"symbol":"LINK/USDT","bids":[],"asks":[{"price":18.46599,"qty":0.00000000},{"price":18.48096,"qty":270.77670071}],"checksum":2363374274,"timestamp":"2024-06-01T22:42:53.587291Z"}]}
{"channel":"book","type":"update","data":[{"symbol":"LINK/USDT","bids":[],"asks":[{"price":18.46758,"qty":9.40000000}],"checksum":4272569751,"timestamp":"2024-06-01T22:42:53.587466Z"}]}
{"channel":"book","type":"update","data":[{"symbol":"LINK/USDT","bids":[],"asks":[{"price":18.46348,"qty":54.20661265}],"checksum":3792609141,"timestamp":"2024-06-01T22:42:53.959724Z"}]}
{"channel":"book","type":"update","data":[{"symbol":"LINK/USDT","bids":[{"price":18.46059,"qty":54.21507938}],"asks":[],"checksum":1878514413,"timestamp":"2024-06-01T22:42:53.959885Z"}]}
{"channel":"book","type":"update","data":[{"symbol":"LINK/USDT","bids":[],"asks":[{"price":18.46345,"qty":9.00000000}],"checksum":2543500143,"timestamp":"2024-06-01T22:42:53.965058Z"}]}
{"channel":"book","type":"update","data":[{"symbol":"LINK/USDT","bids":[],"asks":[{"price":18.46596,"qty":0.00000000},{"price":18.48049,"qty":69.08000000}],"checksum":1801453433,"timestamp":"2024-06-01T22:42:54.086825Z"}]}
{"channel":"book","type":"update","data":[{"symbol":"LINK/USDT","bids":[],"asks":[{"price":18.46348,"qty":0.00000000},{"price":18.48050,"qty":33.73844400}],"checksum":472190293,"timestamp":"2024-06-01T22:42:54.509238Z"}]}
{"channel":"book","type":"update","data":[{"symbol":"LINK/USDT","bids":[],"asks":[{"price":18.46343,"qty":54.20674407}],"checksum":1065331161,"timestamp":"2024-06-01T22:42:54.512637Z"}]}
{"channel":"book","type":"update","data":[{"symbol":"LINK/USDT","bids":[],"asks":[{"price":18.46345,"qty":0.00000000},{"price":18.48050,"qty":33.73844400}],"checksum":2614115187,"timestamp":"2024-06-01T22:42:54.514079Z"}]}
{"channel":"book","type":"update","data":[{"symbol":"LINK/USDT","bids":[],"asks":[{"price":18.46755,"qty":9.00000000}],"checksum":386343918,"timestamp":"2024-06-01T22:42:54.514174Z"}]}
{"channel":"book","type":"update","data":[{"symbol":"LINK/USDT","bids":[{"price":18.46135,"qty":0.00000000},{"price":18.44660,"qty":100.82355200}],"asks":[],"checksum":3346522580,"timestamp":"2024-06-01T22:42:54.516823Z"}]}
{"channel":"book","type":"update","data":[{"symbol":"LINK/USDT","bids":[{"price":18.46132,"qty":81.30289485}],"asks":[],"checksum":3242801714,"timestamp":"2024-06-01T22:42:54.557115Z"}]}
{"channel":"book","type":"update","data":[{"symbol":"LINK/USDT","bids":[],"asks":[{"price":18.46340,"qty":9.00000000}],"checksum":2296062841,"timestamp":"2024-06-01T22:42:54.561670Z"}]}
{"channel":"book","type":"update","data":[{"symbol":"LINK/USDT","bids":[],"asks":[{"price":18.46755,"qty":0.00000000},{"price":18.48049,"qty":69.08000000}],"checksum":2764138823,"timestamp":"2024-06-01T22:42:54.584552Z"}]}
{"channel":"book","type":"update","data":[{"symbol":"LINK/USDT","bids":[{"price":18.46132,"qty":0.00000000},{"price":18.44660,"qty":100.82355200}],"asks":[],"checksum":3883789364,"timestamp":"2024-06-01T22:42:55.003686Z"}]}
{"channel":"book","type":"update","data":[{"symbol":"LINK/USDT","bids":[{"price":18.46125,"qty":81.30423981}],"asks":[],"checksum":3182725817,"timestamp":"2024-06-01T22:42:55.043956Z"}]}
{"channel":"book","type":"update","data":[{"symbol":"LINK/USDT","bids":[{"price":18.46125,"qty":0.00000000},{"price":18.44660,"qty":100.82355200}],"asks":[],"checksum":3883789364,"timestamp":"2024-06-01T22:42:55.554508Z"}]}
{"channel":"book","type":"update","data":[{"symbol":"LINK/USDT","bids":[],"asks":[{"price":18.46343,"qty":0.00000000},{"price":18.48050,"qty":33.73844400}],"checksum":2070907000,"timestamp":"2024-06-01T22:42:55.558638Z"}]}
{"channel":"book","type":"update","data":[{"symbol":"LINK/USDT","bids":[],"asks":[{"price":18.46338,"qty":54.20691171}],"checksum":3238457997,"timestamp":"2024-06-01T22:42:55.562628Z"}]}
{"channel":"book","type":"update","data":[{"symbol":"LINK/USDT","bids":[],"asks":[{"price":18.46335,"qty":9.00000000}],"checksum":57678630,"timestamp":"2024-06-01T22:42:55.584798Z"}]}
{"channel":"book","type":"update","data":[{"symbol":"LINK/USDT","bids":[{"price":18.46123,"qty":81.30423981}],"asks":[],"checksum":1569311587,"timestamp":"2024-06-01T22:42:55.594673Z"}]}
{"channel":"book","type":"update","data":[{"symbol":"LINK/USDT","bids":[],"asks":[{"price":18.46340,"qty":0.00000000},{"price":18.48049,"qty":69.08000000}],"checksum":3878143789,"timestamp":"2024-06-01T22:42:56.084509Z"}]}
{"channel":"book","type":"update","data":[{"symbol":"LINK/USDT","bids":[{"price":18.46123,"qty":0.00000000},{"price":18.44660,"qty":100.82355200}],"asks":[],"checksum":2460932541,"timestamp":"2024-06-01T22:42:56.173533Z"}]}
{"channel":"book","type":"update","data":[{"symbol":"LINK/USDT","bids":[{"price":18.46122,"qty":81.30423981}],"asks":[],"checksum":3361317684,"timestamp":"2024-06-01T22:42:56.213773Z"}]}
{"channel":"book","type":"update","data":[{"symbol":"LINK/USDT","bids":[{"price":18.46059,"qty":0.00000000},{"price":18.44660,"qty":100.82355200}],"asks":[],"checksum":497441660,"timestamp":"2024-06-01T22:42:56.393550Z"}]}
{"channel":"book","type":"update","data":[{"symbol":"LINK/USDT","bids":[{"price":18.46090,"qty":54.21415769}],"asks":[],"checksum":1210587580,"timestamp":"2024-06-01T22:42:56.397527Z"}]}
{"channel":"book","type":"update","data":[{"symbol":"LINK/USDT","bids":[{"price":18.46090,"qty":0.00000000},{"price":18.44660,"qty":100.82355200}],"asks":[],"checksum":497441660,"timestamp":"2024-06-01T22:42:56.508751Z"}]}
{"channel":"book","type":"update","data":[{"symbol":"LINK/USDT","bids":[],"asks":[{"price":18.46338,"qty":0.00000000},{"price":18.48050,"qty":33.73844400}],"checksum":307037251,"timestamp":"2024-06-01T22:42:56.508810Z"}]}
{"channel":"book","type":"update","data":[{"symbol":"LINK/USDT","bids":[],"asks":[{"price":18.46333,"qty":54.20703788}],"checksum":738477129,"timestamp":"2024-06-01T22:42:56.513831Z"}]}
{"channel":"book","type":"update","data":[{"symbol":"LINK/USDT","bids":[],"asks":[{"price":18.46330,"qty":9.00000000}],"checksum":2548053739,"timestamp":"2024-06-01T22:42:56.585975Z"}]}
{"channel":"book","type":"update","data":[{"symbol":"LINK/USDT","bids":[{"price":18.46122,"qty":0.00000000},{"price":18.44221,"qty":69.08000000}],"asks":[],"checksum":975497119,"timestamp":"2024-06-01T22:42:56.661687Z"}]}
{"channel":"book","type":"update","data":[{"symbol":"LINK/USDT","bids":[{"price":18.45836,"qty":9.40000000}],"asks":[],"checksum":3033509122,"timestamp":"2024-06-01T22:42:56.664788Z"}]}
{"channel":"book","type":"update","data":[{"symbol":"LINK/USDT","bids":[{"price":18.45891,"qty":243.48672997}],"asks":[],"checksum":91007073,"timestamp":"2024-06-01T22:42:56.665600Z"}]}
{"channel":"book","type":"update","data":[{"symbol":"LINK/USDT","bids":[],"asks":[{"price":18.46335,"qty":0.00000000},{"price":18.48049,"qty":69.08000000}],"checksum":3008397343,"timestamp":"2024-06-01T22:42:56.666601Z"}]}
{"channel":"book","type":"update","data":[{"symbol":"LINK/USDT","bids":[],"asks":[{"price":18.46333,"qty":0.00000000},{"price":18.48050,"qty":33.73844400}],"checksum":3097903161,"timestamp":"2024-06-01T22:42:56.755039Z"}]}
{"channel":"book","type":"update","data":[{"symbol":"LINK/USDT","bids":[{"price":18.45790,"qty":0.00000000},{"price":18.44660,"qty":100.82355200}],"asks":[],"checksum":422991174,"timestamp":"2024-06-01T22:42:56.759452Z"}]}
{"channel":"book","type":"update","data":[{"symbol":"LINK/USDT","bids":[{"price":18.45836,"qty":0.00000000},{"price":18.44221,"qty":69.08000000}],"asks":[],"checksum":4167120135,"timestamp":"2024-06-01T22:42:56.762208Z"}]}
{"channel":"book","type":"update","data":[{"symbol":"LINK/USDT","bids":[{"price":18.46044,"qty":54.21549922}],"asks":[],"checksum":4230585570,"timestamp":"2024-06-01T22:42:56.923833Z"}]}
{"channel":"book","type":"update","data":[{"symbol":"LINK/USDT","bids":[{"price":18.46117,"qty":81.30501172}],"asks":[],"checksum":2584596301,"timestamp":"2024-06-01T22:42:57.219164Z"}]}
{"channel":"book","type":"update","data":[{"symbol":"LINK/USDT","bids":[],"asks":[{"price":18.46755,"qty":9.00000000}],"checksum":508882126,"timestamp":"2024-06-01T22:42:57.224026Z"}]}
{"channel":"book","type":"update","data":[{"symbol":"LINK/USDT","bids":[],"asks":[{"price":18.46330,"qty":0.00000000},{"price":18.48050,"qty":33.73844400}],"checksum":1436140755,"timestamp":"2024-06-01T22:42:57.224047Z"}]}
{"channel":"book","type":"update","data":[{"symbol":"LINK/USDT","bids":[],"asks":[{"price":18.46737,"qty":4.87937889}],"checksum":2926199827,"timestamp":"2024-06-01T22:42:57.226929Z"}]}
{"channel":"book","type":"update","data":[{"symbol":"LINK/USDT","bids":[],"asks":[{"price":18.46813,"qty":0.00000000},{"price":18.48050,"qty":33.73844400}],"checksum":3793051559,"timestamp":"2024-06-01T22:42:57.229599Z"}]}
{"channel":"book","type":"update","data":[{"symbol":"LINK/USDT","bids":[],"asks":[{"price":18.46758,"qty":0.00000000},{"price":18.48096,"qty":270.77670071}],"checksum":2928288122,"timestamp":"2024-06-01T22:42:57.229784Z"}]}
{"channel":"book","type":"update","data":[{"symbol":"LINK/USDT","bids":[],"asks":[{"price":18.46682,"qty":9.40000000}],"checksum":2648242284,"timestamp":"2024-06-01T22:42:57.229926Z"}]}
{"channel":"book","type":"update","data":[{"symbol":"LINK/USDT","bids":[],"asks":[{"price":18.46749,"qty":54.19483468}],"checksum":886022792,"timestamp":"2024-06-01T22:42:57.231214Z"}]}
{"channel":"book","type":"update","data":[{"symbol":"LINK/USDT","bids":[],"asks":[{"price":18.46749,"qty":0.00000000},{"price":18.48050,"qty":33.73844400}],"checksum":2648242284,"timestamp":"2024-06-01T22:42:57.235054Z"}]}
{"channel":"book","type":"update","data":[{"symbol":"LINK/USDT","bids":[],"asks":[{"price":18.46679,"qty":9.00000000}],"checksum":3451639712,"timestamp":"2024-06-01T22:42:57.583311Z"}]}
{"channel":"book","type":"update","data":[{"symbol":"LINK/USDT","bids":[{"price":18.46044,"qty":0.00000000},{"price":18.44660,"qty":100.82355200}],"asks":[],"checksum":2324097240,"timestamp":"2024-06-01T22:42:57.691118Z"}]}
{"channel":"book","type":"update","data":[{"symbol":"LINK/USDT","bids":[],"asks":[{"price":18.46755,"qty":0.00000000},{"price":18.48050,"qty":33.73844400}],"checksum":2105203784,"timestamp":"2024-06-01T22:42:57.695747Z"}]}
{"channel":"book","type":"update","data":[{"symbol":"LINK/USDT","bids":[{"price":18.46005,"qty":54.21665404}],"asks":[],"checksum":4141673099,"timestamp":"2024-06-01T22:42:57.696236Z"}]}
{"channel":"book","type":"update","data":[{"symbol":"LINK/USDT","bids":[{"price":18.46117,"qty":0.00000000},{"price":18.44660,"qty":100.82355200}],"asks":[],"checksum":17047516,"timestamp":"2024-06-01T22:42:57.730259Z"}]}
{"channel":"book","type":"update","data":[{"symbol":"LINK/USDT","bids":[{"price":18.45891,"qty":0.00000000},{"price":18.44221,"qty":69.08000000}],"asks":[],"checksum":482820626,"timestamp":"2024-06-01T22:42:57.731092Z"}]}
{"channel":"book","type":"update","data":[{"symbol":"LINK/USDT","bids":[],"asks":[{"price":18.46673,"qty":54.19707564}],"checksum":691601733,"timestamp":"2024-06-01T22:42:57.750461Z"}]}
{"channel":"book","type":"update","data":[{"symbol":"LINK/USDT","bids":[],"asks":[{"price":18.46682,"qty":0.00000000},{"price":18.48050,"qty":33.73844400}],"checksum":482249327,"timestamp":"2024-06-01T22:42:57.753036Z"}]}
{"channel":"book","type":"update","data":[{"symbol":"LINK/USDT","bids":[],"asks":[{"price":18.46618,"qty":9.40000000}],"checksum":4180720509,"timestamp":"2024-06-01T22:42:57.753174Z"}]}
{"channel":"book","type":"update","data":[{"symbol":"LINK/USDT","bids":[],"asks":[{"price":18.46673,"qty":0.00000000},{"price":18.48050,"qty":33.73844400}],"checksum":2633443516,"timestamp":"2024-06-01T22:42:57.754367Z"}]}
{"channel":"book","type":"update","data":[{"symbol":"LINK/USDT","bids":[],"asks":[{"price":18.46655,"qty":4.87951231}],"checksum":2035084532,"timestamp":"2024-06-01T22:42:57.755336Z"}]}
{"channel":"book","type":"update","data":[{"symbol":"LINK/USDT","bids":[],"asks":[{"price":18.46737,"qty":0.00000000},{"price":18.48050,"qty":33.73844400}],"checksum":2046969615,"timestamp":"2024-06-01T22:42:57.755777Z"}]}
{"channel":"book","type":"update","data":[{"symbol":"LINK/USDT","bids":[],"asks":[{"price":18.46618,"qty":14.27959412}],"checksum":1974727582,"timestamp":"2024-06-01T22:42:57.758020Z"}]}
{"channel":"book","type":"update","data":[{"symbol":"LINK/USDT","bids":[],"asks":[{"price":18.46655,"qty":0.00000000},{"price":18.48096,"qty":270.77670071}],"checksum":330337731,"timestamp":"2024-06-01T22:42:57.758259Z"}]}
{"channel":"book","type":"update","data":[{"symbol":"LINK/USDT","bids":[],"asks":[{"price":18.46615,"qty":9.00000000}],"checksum":585801915,"timestamp":"2024-06-01T22:42:57.762573Z"}]}
{"channel":"book","type":"update","data":[{"symbol":"LINK/USDT","bids":[],"asks":[{"price":18.46597,"qty":4.87964774}],"checksum":1982766632,"timestamp":"2024-06-01T22:42:57.765468Z"}]}
{"channel":"book","type":"update","data":[{"symbol":"LINK/USDT","bids":[],"asks":[{"price":18.46618,"qty":4.87959412}],"checksum":1028967490,"timestamp":"2024-06-01T22:42:57.768082Z"}]}
{"channel":"book","type":"update","data":[{"symbol":"LINK/USDT","bids":[],"asks":[{"price":18.46566,"qty":9.40000000}],"checksum":509801499,"timestamp":"2024-06-01T22:42:57.768151Z"}]}
{"channel":"book","type":"update","data":[{"symbol":"LINK/USDT","bids":[],"asks":[{"price":18.46618,"qty":0.00000000},{"price":18.48049,"qty":69.08000000}],"checksum":230246971,"timestamp":"2024-06-01T22:42:57.768202Z"}]}
{"channel":"book","type":"update","data":[{"symbol":"LINK/USDT","bids":[{"price":18.46121,"qty":81.30443432}],"asks":[],"checksum":1115653326,"timestamp":"2024-06-01T22:42:57.770421Z"}]}
{"channel":"book","type":"update","data":[{"symbol":"LINK/USDT","bids":[],"asks":[{"price":18.48049,"qty":0.00000000},{"price":18.48050,"qty":33.73844400},{"price":18.47617,"qty":69.08000000}],"checksum":2821461802,"timestamp":"2024-06-01T22:42:57.781166Z"}]}
{"channel":"book","type":"update","data":[{"symbol":"LINK/USDT","bids":[{"price":18.46005,"qty":0.00000000},{"price":18.44221,"qty":69.08000000}],"asks":[],"checksum":536385890,"timestamp":"2024-06-01T22:42:57.803672Z"}]}
{"channel":"book","type":"update","data":[{"symbol":"LINK/USDT","bids":[],"asks":[{"price":18.46615,"qty":0.00000000},{"price":18.48050,"qty":33.73844400}],"checksum":3788824085,"timestamp":"2024-06-01T22:42:57.808877Z"}]}
{"channel":"book","type":"update","data":[{"symbol":"LINK/USDT","bids":[],"asks":[{"price":18.46563,"qty":9.00000000}],"checksum":982738355,"timestamp":"2024-06-01T22:42:57.808980Z"}]}
{"channel":"book","type":"update","data":[{"symbol":"LINK/USDT","bids":[],"asks":[{"price":18.46553,"qty":4.87976541}],"checksum":2006813129,"timestamp":"2024-06-01T22:42:57.904277Z"}]}
{"channel":"book","type":"update","data":[{"symbol":"LINK/USDT","bids":[],"asks":[{"price":18.46597,"qty":0.00000000},{"price":18.47629,"qty":270.84508036}],"checksum":834436654,"timestamp":"2024-06-01T22:42:57.906994Z"}]}
{"channel":"book","type":"update","data":[{"symbol":"LINK/USDT","bids":[],"asks":[{"price":18.46566,"qty":0.00000000},{"price":18.48050,"qty":33.73844400}],"checksum":2934997265,"timestamp":"2024-06-01T22:42:57.907094Z"}]}
{"channel":"book","type":"update","data":[{"symbol":"LINK/USDT","bids":[],"asks":[{"price":18.46523,"qty":9.40000000}],"checksum":439839484,"timestamp":"2024-06-01T22:42:57.907398Z"}]}
{"channel":"book","type":"update","data":[{"symbol":"LINK/USDT","bids":[{"price":18.45691,"qty":243.48672997}],"asks":[],"checksum":3398064306,"timestamp":"2024-06-01T22:42:57.908387Z"}]}
{"channel":"book","type":"update","data":[{"symbol":"LINK/USDT","bids":[],"asks":[{"price":18.46563,"qty":0.00000000},{"price":18.48050,"qty":33.73844400}],"checksum":1417010210,"timestamp":"2024-06-01T22:42:57.909044Z"}]}
{"channel":"book","type":"update","data":[{"symbol":"LINK/USDT","bids":[],"asks":[{"price":18.46550,"qty":9.00000000}],"checksum":151725450,"timestamp":"2024-06-01T22:42:57.909154Z"}]}
{"channel":"book","type":"update","data":[{"symbol":"LINK/USDT","bids":[],"asks":[{"price":18.46550,"qty":0.00000000},{"price":18.48050,"qty":33.73844400}],"checksum":1417010210,"timestamp":"2024-06-01T22:42:58.084869Z"}]}
{"channel":"book","type":"update","data":[{"symbol":"LINK/USDT","bids":[],"asks":[{"price":18.46520,"qty":9.00000000}],"checksum":3813905304,"timestamp":"2024-06-01T22:42:58.085072Z"}]}
{"channel":"book","type":"update","data":[{"symbol":"LINK/USDT","bids":[],"asks":[{"price":18.46679,"qty":0.00000000},{"price":18.48050,"qty":33.73844400}],"checksum":927651391,"timestamp":"2024-06-01T22:42:58.090228Z"}]}
{"channel":"book","type":"update","data":[{"symbol":"LINK/USDT","bids":[{"price":18.46121,"qty":0.00000000},{"price":18.44221,"qty":69.08000000}],"asks":[],"checksum":674424037,"timestamp":"2024-06-01T22:42:58.282577Z"}]}
{"channel":"book","type":"update","data":[{"symbol":"LINK/USDT","bids":[{"price":18.45746,"qty":9.40000000}],"asks":[],"checksum":815473993,"timestamp":"2024-06-01T22:42:58.285706Z"}]}
{"channel":"book","type":"update","data":[{"symbol":"LINK/USDT","bids":[{"price":18.46030,"qty":54.21591838}],"asks":[],"checksum":3264889476,"timestamp":"2024-06-01T22:42:58.323457Z"}]}
{"channel":"book","type":"update","data":[{"symbol":"LINK/USDT","bids":[],"asks":[{"price":18.46514,"qty":54.20172911}],"checksum":4229008148,"timestamp":"2024-06-01T22:42:58.323527Z"}]}
{"channel":"book","type":"update","data":[{"symbol":"LINK/USDT","bids":[],"asks":[{"price":18.46514,"qty":0.00000000},{"price":18.48050,"qty":33.73844400}],"checksum":3264889476,"timestamp":"2024-06-01T22:42:58.328096Z"}]}
{"channel":"book","type":"update","data":[{"symbol":"LINK/USDT","bids":[],"asks":[{"price":18.46511,"qty":9.00000000}],"checksum":1737468940,"timestamp":"2024-06-01T22:42:58.329059Z"}]}
{"channel":"book","type":"update","data":[{"symbol":"LINK/USDT","bids":[{"price":18.46030,"qty":0.00000000},{"price":18.44660,"qty":100.82355200}],"asks":[],"checksum":3546102709,"timestamp":"2024-06-01T22:42:58.516696Z"}]}
{"channel":"book","type":"update","data":[{"symbol":"LINK/USDT","bids":[],"asks":[{"price":18.46511,"qty":0.00000000},{"price":18.48050,"qty":33.73844400}],"checksum":815473993,"timestamp":"2024-06-01T22:42:58.521251Z"}]}
{"channel":"book","type":"update","data":[{"symbol":"LINK/USDT","bids":[],"asks":[{"price":18.46948,"qty":0.00000000},{"price":18.48096,"qty":270.77670071}],"checksum":4000747394,"timestamp":"2024-06-01T22:42:58.551138Z"}]}
{"channel":"book","type":"update","data":[{"symbol":"LINK/USDT","bids":[],"asks":[{"price":18.46733,"qty":135.48824700}],"checksum":2792459335,"timestamp":"2024-06-01T22:42:58.554693Z"}]}
{"channel":"book","type":"update","data":[{"symbol":"LINK/USDT","bids":[],"asks":[{"price":18.46503,"qty":4.87989712}],"checksum":4216373600,"timestamp":"2024-06-01T22:42:58.575347Z"}]}
{"channel":"book","type":"update","data":[{"symbol":"LINK/USDT","bids":[],"asks":[{"price":18.46553,"qty":0.00000000},{"price":18.48050,"qty":33.73844400}],"checksum":3602429199,"timestamp":"2024-06-01T22:42:58.578061Z"}]}
{"channel":"book","type":"update","data":[{"symbol":"LINK/USDT","bids":[],"asks":[{"price":18.46500,"qty":9.00000000}],"checksum":1484356595,"timestamp":"2024-06-01T22:42:58.584386Z"}]}
{"channel":"book","type":"update","data":[{"symbol":"LINK/USDT","bids":[],"asks":[{"price":18.46484,"qty":4.87994858}],"checksum":294044113,"timestamp":"2024-06-01T22:42:58.611535Z"}]}
{"channel":"book","type":"update","data":[{"symbol":"LINK/USDT","bids":[],"asks":[{"price":18.46503,"qty":0.00000000},{"price":18.47629,"qty":270.84508036}],"checksum":1997208214,"timestamp":"2024-06-01T22:42:58.614195Z"}]}
{"channel":"book","type":"update","data":[{"symbol":"LINK/USDT","bids":[{"price":18.46102,"qty":81.30757942}],"asks":[],"checksum":711581446,"timestamp":"2024-06-01T22:42:58.771614Z"}]}
{"channel":"book","type":"update","data":[{"symbol":"LINK/USDT","bids":[],"asks":[{"price":18.46500,"qty":0.00000000},{"price":18.48050,"qty":33.73844400}],"checksum":3982287893,"timestamp":"2024-06-01T22:42:58.776138Z"}]}
{"channel":"book","type":"update","data":[{"symbol":"LINK/USDT","bids":[],"asks":[{"price":18.46481,"qty":9.00000000}],"checksum":1676398061,"timestamp":"2024-06-01T22:42:58.776417Z"}]}
{"channel":"book","type":"update","data":[{"symbol":"LINK/USDT","bids":[],"asks":[{"price":18.46478,"qty":4.87996364}],"checksum":2324774403,"timestamp":"2024-06-01T22:42:58.779151Z"}]}
{"channel":"book","type":"update","data":[{"symbol":"LINK/USDT","bids":[],"asks":[{"price":18.46484,"qty":0.00000000},{"price":18.47629,"qty":270.84508036}],"checksum":3611295292,"timestamp":"2024-06-01T22:42:58.782030Z"}]}
{"channel":"book","type":"update","data":[{"symbol":"LINK/USDT","bids":[{"price":18.45924,"qty":54.21901869}],"asks":[],"checksum":3138683153,"timestamp":"2024-06-01T22:42:58.979332Z"}]}
{"channel":"book","type":"update","data":[{"symbol":"LINK/USDT","bids":[],"asks":[{"price":18.46475,"qty":54.20288743}],"checksum":2890381723,"timestamp":"2024-06-01T22:42:58.979361Z"}]}
{"channel":"book","type":"update","data":[{"symbol":"LINK/USDT","bids":[],"asks":[{"price":18.46475,"qty":0.00000000},{"price":18.47629,"qty":270.84508036}],"checksum":3138683153,"timestamp":"2024-06-01T22:42:58.983546Z"}]}
{"channel":"book","type":"update","data":[{"symbol":"LINK/USDT","bids":[],"asks":[{"price":18.46475,"qty":9.00000000}],"checksum":382860556,"timestamp":"2024-06-01T22:42:58.984316Z"}]}
{"channel":"book","type":"update","data":[{"symbol":"LINK/USDT","bids":[],"asks":[{"price":18.46481,"qty":0.00000000},{"price":18.47629,"qty":270.84508036}],"checksum":2250419561,"timestamp":"2024-06-01T22:42:58.984345Z"}]}
{"channel":"book","type":"update","data":[{"symbol":"LINK/USDT","bids":[],"asks":[{"price":18.46475,"qty":0.00000000},{"price":18.48050,"qty":33.73844400}],"checksum":1931151087,"timestamp":"2024-06-01T22:42:59.084866Z"}]}
{"channel":"book","type":"update","data":[{"symbol":"LINK/USDT","bids":[],"asks":[{"price":18.46472,"qty":9.00000000}],"checksum":1190370979,"timestamp":"2024-06-01T22:42:59.084935Z"}]}
{"channel":"book","type":"update","data":[{"symbol":"LINK/USDT","bids":[],"asks":[{"price":18.46520,"qty":0.00000000},{"price":18.48050,"qty":33.73844400}],"checksum":891326181,"timestamp":"2024-06-01T22:42:59.089779Z"}]}
{"channel":"book","type":"update","data":[{"symbol":"LINK/USDT","bids":[{"price":18.46102,"qty":0.00000000},{"price":18.44868,"qty":271.25031961}],"asks":[],"checksum":267076438,"timestamp":"2024-06-01T22:42:59.283165Z"}]}
{"channel":"book","type":"update","data":[{"symbol":"LINK/USDT","bids":[{"price":18.46080,"qty":81.31132917}],"asks":[],"checksum":1387481759,"timestamp":"2024-06-01T22:42:59.323188Z"}]}
{"channel":"book","type":"update","data":[{"symbol":"LINK/USDT","bids":[{"price":18.45924,"qty":0.00000000},{"price":18.44868,"qty":271.25031961}],"asks":[],"checksum":3721852880,"timestamp":"2024-06-01T22:42:59.334978Z"}]}
{"channel":"book","type":"update","data":[{"symbol":"LINK/USDT","bids":[],"asks":[{"price":18.46247,"qty":54.20956654}],"checksum":1070486002,"timestamp":"2024-06-01T22:42:59.480582Z"}]}
{"channel":"book","type":"update","data":[{"symbol":"LINK/USDT","bids":[{"price":18.45954,"qty":54.21815659}],"asks":[],"checksum":2035942601,"timestamp":"2024-06-01T22:42:59.480664Z"}]}
{"channel":"book","type":"update","data":[{"symbol":"LINK/USDT","bids":[],"asks":[{"price":18.46247,"qty":0.00000000},{"price":18.48050,"qty":33.73844400}],"checksum":3649450496,"timestamp":"2024-06-01T22:42:59.643137Z"}]}
{"channel":"book","type":"update","data":[{"symbol":"LINK/USDT","bids":[],"asks":[{"price":18.46523,"qty":0.00000000},{"price":18.48096,"qty":270.77670071}],"checksum":1557636532,"timestamp":"2024-06-01T22:42:59.645832Z"}]}
{"channel":"book","type":"update","data":[{"symbol":"LINK/USDT","bids":[],"asks":[{"price":18.46446,"qty":9.40000000}],"checksum":1336823076,"timestamp":"2024-06-01T22:42:59.646010Z"}]}
{"channel":"book","type":"update","data":[{"symbol":"LINK/USDT","bids":[],"asks":[{"price":18.46472,"qty":0.00000000},{"price":18.48096,"qty":270.77670071}],"checksum":1334562391,"timestamp":"2024-06-01T22:42:59.648287Z"}]}
{"channel":"book","type":"update","data":[{"symbol":"LINK/USDT","bids":[],"asks":[{"price":18.46475,"qty":9.00000000}],"checksum":1971734832,"timestamp":"2024-06-01T22:42:59.648339Z"}]}
{"channel":"book","type":"update","data":[{"symbol":"LINK/USDT","bids":[],"asks":[{"price":18.46443,"qty":9.00000000}],"checksum":786487679,"timestamp":"2024-06-01T22:43:00.085523Z"}]}
{"channel":"book","type":"update","data":[{"symbol":"LINK/USDT","bids":[],"asks":[{"price":18.46440,"qty":54.20391148}],"checksum":457000340,"timestamp":"2024-06-01T22:43:00.090621Z"}]}
{"channel":"book","type":"update","data":[{"symbol":"LINK/USDT","bids":[],"asks":[{"price":18.46440,"qty":0.00000000},{"price":18.47629,"qty":270.84508036}],"checksum":786487679,"timestamp":"2024-06-01T22:43:00.095357Z"}]}
{"channel":"book","type":"update","data":[{"symbol":"LINK/USDT","bids":[{"price":18.46080,"qty":0.00000000},{"price":18.44868,"qty":271.25031961}],"asks":[],"checksum":545724604,"timestamp":"2024-06-01T22:43:00.281207Z"}]}
{"channel":"book","type":"update","data":[{"symbol":"LINK/USDT","bids":[],"asks":[{"price":18.46475,"qty":0.00000000},{"price":18.48050,"qty":33.73844400}],"checksum":69421018,"timestamp":"2024-06-01T22:43:00.285691Z"}]}
{"channel":"book","type":"update","data":[{"symbol":"LINK/USDT","bids":[{"price":18.46066,"qty":81.31189438}],"asks":[],"checksum":35998404,"timestamp":"2024-06-01T22:43:00.391265Z"}]}
{"channel":"book","type":"update","data":[{"symbol":"LINK/USDT","bids":[{"price":18.46066,"qty":0.00000000},{"price":18.44868,"qty":271.25031961}],"asks":[],"checksum":69421018,"timestamp":"2024-06-01T22:43:01.459971Z"}]}
{"channel":"book","type":"update","data":[{"symbol":"LINK/USDT","bids":[],"asks":[{"price":18.46439,"qty":54.20394885}],"checksum":2825203414,"timestamp":"2024-06-01T22:43:01.464979Z"}]}
{"channel":"book","type":"update","data":[{"symbol":"LINK/USDT","bids":[],"asks":[{"price":18.46446,"qty":0.00000000},{"price":18.48050,"qty":33.73844400}],"checksum":3338798505,"timestamp":"2024-06-01T22:43:01.467557Z"}]}
{"channel":"book","type":"update","data":[{"symbol":"LINK/USDT","bids":[],"asks":[{"price":18.46433,"qty":9.40000000}],"checksum":2594195863,"timestamp":"2024-06-01T22:43:01.467739Z"}]}
{"channel":"book","type":"update","data":[{"symbol":"LINK/USDT","bids":[],"asks":[{"price":18.46439,"qty":0.00000000},{"price":18.48050,"qty":33.73844400}],"checksum":3021102318,"timestamp":"2024-06-01T22:43:01.468747Z"}]}
{"channel":"book","type":"update","data":[{"symbol":"LINK/USDT","bids":[{"price":18.46064,"qty":81.31189438}],"asks":[],"checksum":3498876168,"timestamp":"2024-06-01T22:43:01.500412Z"}]}
{"channel":"book","type":"update","data":[{"symbol":"LINK/USDT","bids":[],"asks":[{"price":18.46430,"qty":9.00000000}],"checksum":1607559376,"timestamp":"2024-06-01T22:43:01.506359Z"}]}
{"channel":"book","type":"update","data":[{"symbol":"LINK/USDT","bids":[],"asks":[{"price":18.46443,"qty":0.00000000},{"price":18.48050,"qty":33.73844400}],"checksum":1975802216,"timestamp":"2024-06-01T22:43:01.584467Z"}]}
{"channel":"book","type":"update","data":[{"symbol":"LINK/USDT","bids":[{"price":18.45954,"qty":0.00000000},{"price":18.44868,"qty":271.25031961}],"asks":[],"checksum":2652069073,"timestamp":"2024-06-01T22:43:01.821328Z"}]}
{"channel":"book","type":"update","data":[{"symbol":"LINK/USDT","bids":[{"price":18.45917,"qty":54.21923208}],"asks":[],"checksum":2333405328,"timestamp":"2024-06-01T22:43:01.825832Z"}]}
{"channel":"book","type":"update","data":[{"symbol":"LINK/USDT","bids":[{"price":18.46064,"qty":0.00000000},{"price":18.44868,"qty":271.25031961}],"asks":[],"checksum":1304609674,"timestamp":"2024-06-01T22:43:01.960949Z"}]}
{"channel":"book","type":"update","data":[{"symbol":"LINK/USDT","bids":[{"price":18.46049,"qty":81.31263290}],"asks":[],"checksum":2388930707,"timestamp":"2024-06-01T22:43:02.001280Z"}]}
{"channel":"book","type":"update","data":[{"symbol":"LINK/USDT","bids":[],"asks":[{"price":18.46427,"qty":54.20429878}],"checksum":918613672,"timestamp":"2024-06-01T22:43:02.103219Z"}]}
{"channel":"book","type":"update","data":[{"symbol":"LINK/USDT","bids":[],"asks":[{"price":18.46433,"qty":0.00000000},{"price":18.48050,"qty":33.73844400}],"checksum":3114514103,"timestamp":"2024-06-01T22:43:02.105933Z"}]}
{"channel":"book","type":"update","data":[{"symbol":"LINK/USDT","bids":[],"asks":[{"price":18.46425,"qty":9.40000000}],"checksum":3541157471,"timestamp":"2024-06-01T22:43:02.106097Z"}]}
{"channel":"book","type":"update","data":[{"symbol":"LINK/USDT","bids":[],"asks":[{"price":18.46424,"qty":9.00000000}],"checksum":526648929,"timestamp":"2024-06-01T22:43:02.108290Z"}]}
{"channel":"book","type":"update","data":[{"symbol":"LINK/USDT","bids":[],"asks":[{"price":18.46427,"qty":0.00000000},{"price":18.47629,"qty":270.84508036}],"checksum":2457741682,"timestamp":"2024-06-01T22:43:02.109002Z"}]}
{"channel":"book","type":"update","data":[{"symbol":"LINK/USDT","bids":[{"price":18.46049,"qty":0.00000000},{"price":18.44868,"qty":271.25031961}],"asks":[],"checksum":2597522301,"timestamp":"2024-06-01T22:43:02.511544Z"}]}
{"channel":"book","type":"update","data":[{"symbol":"LINK/USDT","bids":[],"asks":[{"price":18.46424,"qty":0.00000000},{"price":18.48050,"qty":33.73844400}],"checksum":3939851838,"timestamp":"2024-06-01T22:43:02.516477Z"}]}
{"channel":"book","type":"update","data":[{"symbol":"LINK/USDT","bids":[],"asks":[{"price":18.46422,"qty":9.00000000}],"checksum":4067022015,"timestamp":"2024-06-01T22:43:02.516506Z"}]}
{"channel":"book","type":"update","data":[{"symbol":"LINK/USDT","bids":[{"price":18.46025,"qty":81.31375162}],"asks":[],"checksum":3947462111,"timestamp":"2024-06-01T22:43:02.551756Z"}]}
{"channel":"book","type":"update","data":[{"symbol":"LINK/USDT","bids":[],"asks":[{"price":18.46430,"qty":0.00000000},{"price":18.48050,"qty":33.73844400}],"checksum":3035498468,"timestamp":"2024-06-01T22:43:02.556135Z"}]}
{"channel":"book","type":"update","data":[{"symbol":"LINK/USDT","bids":[],"asks":[{"price":18.46192,"qty":54.21118423}],"checksum":463376691,"timestamp":"2024-06-01T22:43:02.733554Z"}]}
{"channel":"book","type":"update","data":[{"symbol":"LINK/USDT","bids":[{"price":18.46025,"qty":0.00000000},{"price":18.44868,"qty":271.25031961}],"asks":[],"checksum":1529195776,"timestamp":"2024-06-01T22:43:03.507930Z"}]}
{"channel":"book","type":"update","data":[{"symbol":"LINK/USDT","bids":[{"price":18.46022,"qty":81.31375162}],"asks":[],"checksum":1467265842,"timestamp":"2024-06-01T22:43:03.548198Z"}]}
{"channel":"book","type":"update","data":[{"symbol":"LINK/USDT","bids":[{"price":18.45917,"qty":0.00000000},{"price":18.44868,"qty":271.25031961}],"asks":[],"checksum":2786590294,"timestamp":"2024-06-01T22:43:03.550013Z"}]}
{"channel":"book","type":"update","data":[{"symbol":"LINK/USDT","bids":[],"asks":[{"price":18.46192,"qty":0.00000000},{"price":18.48050,"qty":33.73844400}],"checksum":3188705719,"timestamp":"2024-06-01T22:43:03.550085Z"}]}
{"channel":"book","type":"update","data":[{"symbol":"LINK/USDT","bids":[{"price":18.45950,"qty":54.21825966}],"asks":[],"checksum":3503813810,"timestamp":"2024-06-01T22:43:03.553467Z"}]}
{"channel":"book","type":"update","data":[{"symbol":"LINK/USDT","bids":[],"asks":[{"price":18.46226,"qty":54.21018905}],"checksum":2656335909,"timestamp":"2024-06-01T22:43:03.553485Z"}]}
{"channel":"book","type":"update","data":[{"symbol":"LINK/USDT","bids":[{"price":18.46022,"qty":0.00000000},{"price":18.44868,"qty":271.25031961}],"asks":[],"checksum":3573917391,"timestamp":"2024-06-01T22:43:04.151479Z"}]}
{"channel":"book","type":"update","data":[{"symbol":"LINK/USDT","bids":[{"price":18.46020,"qty":81.31375162}],"asks":[],"checksum":2910763411,"timestamp":"2024-06-01T22:43:04.191897Z"}]}
{"channel":"book","type":"update","data":[{"symbol":"LINK/USDT","bids":[{"price":18.46020,"qty":0.00000000},{"price":18.44868,"qty":271.25031961}],"asks":[],"checksum":3573917391,"timestamp":"2024-06-01T22:43:04.703301Z"}]}
{"channel":"book","type":"update","data":[{"symbol":"LINK/USDT","bids":[{"price":18.46019,"qty":81.31375162}],"asks":[],"checksum":1265204692,"timestamp":"2024-06-01T22:43:04.743429Z"}]}
{"channel":"book","type":"update","data":[{"symbol":"LINK/USDT","bids":[{"price":18.46019,"qty":0.00000000},{"price":18.44868,"qty":271.25031961}],"asks":[],"checksum":3573917391,"timestamp":"2024-06-01T22:43:05.253994Z"}]}
{"channel":"book","type":"update","data":[{"symbol":"LINK/USDT","bids":[{"price":18.46016,"qty":81.31375162}],"asks":[],"checksum":3408419085,"timestamp":"2024-06-01T22:43:05.294231Z"}]}
{"channel":"book","type":"update","data":[{"symbol":"LINK/USDT","bids":[],"asks":[{"price":18.47618,"qty":0.00000000},{"price":18.48050,"qty":33.73844400}],"checksum":1426711126,"timestamp":"2024-06-01T22:43:05.699747Z"}]}
{"channel":"book","type":"update","data":[{"symbol":"LINK/USDT","bids":[],"asks":[{"price":18.47118,"qty":49.16000000}],"checksum":10581773,"timestamp":"2024-06-01T22:43:05.702146Z"}]}
{"channel":"book","type":"update","data":[{"symbol":"LINK/USDT","bids":[],"asks":[{"price":18.47617,"qty":0.00000000},{"price":18.48050,"qty":33.73844400},{"price":18.47628,"qty":69.08000000}],"checksum":744791333,"timestamp":"2024-06-01T22:43:05.702917Z"}]}
{"channel":"book","type":"update","data":[{"symbol":"LINK/USDT","bids":[{"price":18.46016,"qty":0.00000000},{"price":18.44868,"qty":271.25031961}],"asks":[],"checksum":3763815153,"timestamp":"2024-06-01T22:43:06.252241Z"}]}
{"channel":"book","type":"update","data":[{"symbol":"LINK/USDT","bids":[{"price":18.46013,"qty":81.31375162}],"asks":[],"checksum":1403289234,"timestamp":"2024-06-01T22:43:06.292527Z"}]}
{"channel":"book","type":"update","data":[{"symbol":"LINK/USDT","bids":[],"asks":[{"price":18.46226,"qty":0.00000000},{"price":18.48050,"qty":33.73844400}],"checksum":1896285266,"timestamp":"2024-06-01T22:43:07.097401Z"}]}
{"channel":"book","type":"update","data":[{"symbol":"LINK/USDT","bids":[],"asks":[{"price":18.46198,"qty":54.21102325}],"checksum":2633252626,"timestamp":"2024-06-01T22:43:07.101480Z"}]}
{"channel":"book","type":"update","data":[{"symbol":"LINK/USDT","bids":[],"asks":[{"price":18.46198,"qty":0.00000000},{"price":18.48050,"qty":33.73844400}],"checksum":1896285266,"timestamp":"2024-06-01T22:43:07.207068Z"}]}
{"channel":"book","type":"update","data":[{"symbol":"LINK/USDT","bids":[{"price":18.46013,"qty":0.00000000},{"price":18.44868,"qty":271.25031961}],"asks":[],"checksum":2064720699,"timestamp":"2024-06-01T22:43:07.256042Z"}]}
{"channel":"book","type":"update","data":[{"symbol":"LINK/USDT","bids":[{"price":18.45950,"qty":0.00000000},{"price":18.44660,"qty":100.82355200}],"asks":[],"checksum":150011440,"timestamp":"2024-06-01T22:43:07.266364Z"}]}
{"channel":"book","type":"update","data":[{"symbol":"LINK/USDT","bids":[{"price":18.45908,"qty":54.21949358}],"asks":[],"checksum":3652582619,"timestamp":"2024-06-01T22:43:07.270162Z"}]}
{"channel":"book","type":"update","data":[{"symbol":"LINK/USDT","bids":[{"price":18.46015,"qty":81.31355937}],"asks":[],"checksum":2822850079,"timestamp":"2024-06-01T22:43:07.296071Z"}]}
{"channel":"book","type":"update","data":[{"symbol":"LINK/USDT","bids":[{"price":18.45908,"qty":0.00000000},{"price":18.44868,"qty":271.25031961}],"asks":[],"checksum":2994524059,"timestamp":"2024-06-01T22:43:07.428142Z"}]}
{"channel":"book","type":"update","data":[{"symbol":"LINK/USDT","bids":[{"price":18.46015,"qty":0.00000000},{"price":18.44660,"qty":100.82355200}],"asks":[],"checksum":150011440,"timestamp":"2024-06-01T22:43:07.808750Z"}]}
{"channel":"book","type":"update","data":[{"symbol":"LINK/USDT","bids":[],"asks":[{"price":18.46900,"qty":0.00000000},{"price":18.48096,"qty":270.77670071}],"checksum":442717323,"timestamp":"2024-06-01T22:43:07.812167Z"}]}
{"channel":"book","type":"update","data":[{"symbol":"LINK/USDT","bids":[],"asks":[{"price":18.46417,"qty":54.20457753}],"checksum":1170490658,"timestamp":"2024-06-01T22:43:07.813554Z"}]}
{"channel":"book","type":"update","data":[{"symbol":"LINK/USDT","bids":[{"price":18.45936,"qty":54.21868028}],"asks":[],"checksum":1709312758,"timestamp":"2024-06-01T22:43:07.813658Z"}]}
{"channel":"book","type":"update","data":[{"symbol":"LINK/USDT","bids":[],"asks":[{"price":18.46800,"qty":96.11010579}],"checksum":2089202727,"timestamp":"2024-06-01T22:43:07.815685Z"}]}
{"channel":"book","type":"update","data":[{"symbol":"LINK/USDT","bids":[],"asks":[{"price":18.46417,"qty":0.00000000},{"price":18.48050,"qty":33.73844400}],"checksum":191221821,"timestamp":"2024-06-01T22:43:07.818534Z"}]}
{"channel":"book","type":"update","data":[{"symbol":"LINK/USDT","bids":[{"price":18.46031,"qty":81.31285054}],"asks":[],"checksum":3601608148,"timestamp":"2024-06-01T22:43:07.848905Z"}]}
{"channel":"book","type":"update","data":[{"symbol":"LINK/USDT","bids":[{"price":18.46031,"qty":0.00000000},{"price":18.44868,"qty":271.25031961}],"asks":[],"checksum":191221821,"timestamp":"2024-06-01T22:43:08.441746Z"}]}
{"channel":"book","type":"update","data":[{"symbol":"LINK/USDT","bids":[{"price":18.46025,"qty":81.31306266}],"asks":[],"checksum":3889028456,"timestamp":"2024-06-01T22:43:08.481832Z"}]}
{"channel":"book","type":"update","data":[{"symbol":"LINK/USDT","bids":[],"asks":[{"price":18.46215,"qty":54.21050449}],"checksum":875604213,"timestamp":"2024-06-01T22:43:09.595792Z"}]}
{"channel":"book","type":"update","data":[{"symbol":"LINK/USDT","bids":[{"price":18.46025,"qty":0.00000000},{"price":18.44868,"qty":271.25031961}],"asks":[],"checksum":2231943857,"timestamp":"2024-06-01T22:43:09.949524Z"}]}
{"channel":"book","type":"update","data":[{"symbol":"LINK/USDT","bids":[{"price":18.46020,"qty":81.31325491}],"asks":[],"checksum":1856200239,"timestamp":"2024-06-01T22:43:09.989545Z"}]}
{"channel":"book","type":"update","data":[{"symbol":"LINK/USDT","bids":[{"price":18.45359,"qty":0.00000000},{"price":18.44868,"qty":271.25031961}],"asks":[],"checksum":1677167619,"timestamp":"2024-06-01T22:43:10.428949Z"}]}
{"channel":"book","type":"update","data":[{"symbol":"LINK/USDT","bids":[{"price":18.45024,"qty":49.16000000}],"asks":[],"checksum":2048062585,"timestamp":"2024-06-01T22:43:10.431557Z"}]}
{"channel":"book","type":"update","data":[{"symbol":"LINK/USDT","bids":[{"price":18.46020,"qty":0.00000000},{"price":18.44868,"qty":271.25031961}],"asks":[],"checksum":1959442349,"timestamp":"2024-06-01T22:43:10.436327Z"}]}
{"channel":"book","type":"update","data":[{"symbol":"LINK/USDT","bids":[{"price":18.46024,"qty":81.31306266}],"asks":[],"checksum":957637240,"timestamp":"2024-06-01T22:43:10.476669Z"}]}
{"channel":"book","type":"update","data":[{"symbol":"LINK/USDT","bids":[{"price":18.46024,"qty":0.00000000},{"price":18.44868,"qty":271.25031961}],"asks":[],"checksum":1959442349,"timestamp":"2024-06-01T22:43:10.546409Z"}]}
{"channel":"book","type":"update","data":[{"symbol":"LINK/USDT","bids":[{"price":18.46026,"qty":81.31307591}],"asks":[],"checksum":3683270654,"timestamp":"2024-06-01T22:43:10.586630Z"}]}
{"channel":"book","type":"update","data":[{"symbol":"LINK/USDT","bids":[{"price":18.45936,"qty":0.00000000},{"price":18.44868,"qty":271.25031961}],"asks":[],"checksum":1668379676,"timestamp":"2024-06-01T22:43:11.293979Z"}]}
{"channel":"book","type":"update","data":[{"symbol":"LINK/USDT","bids":[{"price":18.45965,"qty":54.21782026}],"asks":[],"checksum":3650842647,"timestamp":"2024-06-01T22:43:11.298699Z"}]}
{"channel":"book","type":"update","data":[{"symbol":"LINK/USDT","bids":[],"asks":[{"price":18.46215,"qty":0.00000000},{"price":18.48050,"qty":33.73844400}],"checksum":174458250,"timestamp":"2024-06-01T22:43:11.310485Z"}]}
{"channel":"book","type":"update","data":[{"symbol":"LINK/USDT","bids":[],"asks":[{"price":18.46425,"qty":0.00000000},{"price":18.48096,"qty":270.77670071}],"checksum":2414439637,"timestamp":"2024-06-01T22:43:11.314298Z"}]}
{"channel":"book","type":"update","data":[{"symbol":"LINK/USDT","bids":[],"asks":[{"price":18.46678,"qty":9.40000000}],"checksum":1393279405,"timestamp":"2024-06-01T22:43:11.314393Z"}]}
{"channel":"book","type":"update","data":[{"symbol":"LINK/USDT","bids":[],"asks":[{"price":18.46251,"qty":54.20946069}],"checksum":3457663837,"timestamp":"2024-06-01T22:43:11.314819Z"}]}
{"channel":"book","type":"update","data":[{"symbol":"LINK/USDT","bids":[],"asks":[{"price":18.46251,"qty":0.00000000},{"price":18.48050,"qty":33.73844400}],"checksum":1393279405,"timestamp":"2024-06-01T22:43:11.320882Z"}]}
{"channel":"book","type":"update","data":[{"symbol":"LINK/USDT","bids":[{"price":18.45965,"qty":0.00000000},{"price":18.44868,"qty":271.25031961}],"asks":[],"checksum":1213185599,"timestamp":"2024-06-01T22:43:11.327571Z"}]}
{"channel":"book","type":"update","data":[{"symbol":"LINK/USDT","bids":[],"asks":[{"price":18.46422,"qty":0.00000000},{"price":18.48096,"qty":270.77670071}],"checksum":1957058885,"timestamp":"2024-06-01T22:43:11.333280Z"}]}
{"channel":"book","type":"update","data":[{"symbol":"LINK/USDT","bids":[],"asks":[{"price":18.46475,"qty":9.00000000}],"checksum":3007494198,"timestamp":"2024-06-01T22:43:11.333428Z"}]}
{"channel":"book","type":"update","data":[{"symbol":"LINK/USDT","bids":[{"price":18.46026,"qty":0.00000000},{"price":18.44660,"qty":100.82355200}],"asks":[],"checksum":3501476284,"timestamp":"2024-06-01T22:43:11.542940Z"}]}
{"channel":"book","type":"update","data":[{"symbol":"LINK/USDT","bids":[{"price":18.46024,"qty":81.31310241}],"asks":[],"checksum":1549638772,"timestamp":"2024-06-01T22:43:11.583059Z"}]}
{"channel":"book","type":"update","data":[{"symbol":"LINK/USDT","bids":[{"price":18.46024,"qty":0.00000000},{"price":18.44660,"qty":100.82355200}],"asks":[],"checksum":3501476284,"timestamp":"2024-06-01T22:43:12.093710Z"}]}
{"channel":"book","type":"update","data":[{"symbol":"LINK/USDT","bids":[],"asks":[{"price":18.46265,"qty":54.20904572}],"checksum":4137893878,"timestamp":"2024-06-01T22:43:12.099081Z"}]}
{"channel":"book","type":"update","data":[{"symbol":"LINK/USDT","bids":[{"price":18.45970,"qty":54.21768441}],"asks":[],"checksum":2158681453,"timestamp":"2024-06-01T22:43:12.099261Z"}]}
{"channel":"book","type":"update","data":[{"symbol":"LINK/USDT","bids":[{"price":18.46023,"qty":81.31314215}],"asks":[],"checksum":3439850632,"timestamp":"2024-06-01T22:43:12.134124Z"}]}
{"channel":"book","type":"update","data":[{"symbol":"LINK/USDT","bids":[{"price":18.45970,"qty":0.00000000},{"price":18.44868,"qty":271.25031961}],"asks":[],"checksum":2233939016,"timestamp":"2024-06-01T22:43:12.186125Z"}]}
{"channel":"book","type":"update","data":[{"symbol":"LINK/USDT","bids":[],"asks":[{"price":18.46265,"qty":0.00000000},{"price":18.48050,"qty":33.73844400}],"checksum":1264702072,"timestamp":"2024-06-01T22:43:12.437432Z"}]}
{"channel":"book","type":"update","data":[{"symbol":"LINK/USDT","bids":[{"price":18.46023,"qty":0.00000000},{"price":18.44660,"qty":100.82355200}],"asks":[],"checksum":3501476284,"timestamp":"2024-06-01T22:43:12.582335Z"}]}
{"channel":"book","type":"update","data":[{"symbol":"LINK/USDT","bids":[{"price":18.46018,"qty":81.31325477}],"asks":[],"checksum":2399958702,"timestamp":"2024-06-01T22:43:13.224726Z"}]}
{"channel":"book","type":"update","data":[{"symbol":"LINK/USDT","bids":[],"asks":[{"price":18.46220,"qty":54.21036228}],"checksum":504407652,"timestamp":"2024-06-01T22:43:13.229704Z"}]}
{"channel":"book","type":"update","data":[{"symbol":"LINK/USDT","bids":[{"price":18.45935,"qty":54.21871546}],"asks":[],"checksum":4264340388,"timestamp":"2024-06-01T22:43:13.229894Z"}]}
{"channel":"book","type":"update","data":[{"symbol":"LINK/USDT","bids":[{"price":18.46018,"qty":0.00000000},{"price":18.44868,"qty":271.25031961}],"asks":[],"checksum":4185560211,"timestamp":"2024-06-01T22:43:13.738576Z"}]}
{"channel":"book","type":"update","data":[{"symbol":"LINK/USDT","bids":[{"price":18.46017,"qty":81.31328789}],"asks":[],"checksum":2897667614,"timestamp":"2024-06-01T22:43:13.778730Z"}]}
{"channel":"book","type":"update","data":[{"symbol":"LINK/USDT","bids":[{"price":18.46017,"qty":0.00000000},{"price":18.44868,"qty":271.25031961}],"asks":[],"checksum":4185560211,"timestamp":"2024-06-01T22:43:14.227961Z"}]}
{"channel":"book","type":"update","data":[{"symbol":"LINK/USDT","bids":[{"price":18.46014,"qty":81.31332102}],"asks":[],"checksum":2222246684,"timestamp":"2024-06-01T22:43:14.268268Z"}]}
{"channel":"book","type":"update","data":[{"symbol":"LINK/USDT","bids":[{"price":18.46014,"qty":0.00000000},{"price":18.44868,"qty":271.25031961}],"asks":[],"checksum":4185560211,"timestamp":"2024-06-01T22:43:15.294270Z"}]}
{"channel":"book","type":"update","data":[{"symbol":"LINK/USDT","bids":[],"asks":[{"price":18.46220,"qty":0.00000000},{"price":18.48050,"qty":33.73844400}],"checksum":1751532633,"timestamp":"2024-06-01T22:43:15.301161Z"}]}
{"channel":"book","type":"update","data":[{"symbol":"LINK/USDT","bids":[{"price":18.45935,"qty":0.00000000},{"price":18.44660,"qty":100.82355200}],"asks":[],"checksum":3501476284,"timestamp":"2024-06-01T22:43:15.301210Z"}]}
{"channel":"book","type":"update","data":[{"symbol":"LINK/USDT","bids":[{"price":18.45986,"qty":54.21721180}],"asks":[],"checksum":1122688446,"timestamp":"2024-06-01T22:43:15.305804Z"}]}
{"channel":"book","type":"update","data":[{"symbol":"LINK/USDT","bids":[],"asks":[{"price":18.46270,"qty":54.20890566}],"checksum":2934160355,"timestamp":"2024-06-01T22:43:15.305817Z"}]}
{"channel":"book","type":"update","data":[{"symbol":"LINK/USDT","bids":[{"price":18.46012,"qty":81.31338726}],"asks":[],"checksum":641334482,"timestamp":"2024-06-01T22:43:15.334574Z"}]}
{"channel":"book","type":"update","data":[{"symbol":"LINK/USDT","bids":[],"asks":[{"price":18.46270,"qty":0.00000000},{"price":18.48050,"qty":33.73844400}],"checksum":1286440723,"timestamp":"2024-06-01T22:43:15.686344Z"}]}
{"channel":"book","type":"update","data":[{"symbol":"LINK/USDT","bids":[{"price":18.45986,"qty":0.00000000},{"price":18.44868,"qty":271.25031961}],"asks":[],"checksum":3561602986,"timestamp":"2024-06-01T22:43:15.686406Z"}]}
{"channel":"book","type":"update","data":[{"symbol":"LINK/USDT","bids":[{"price":18.46012,"qty":0.00000000},{"price":18.44660,"qty":100.82355200}],"asks":[],"checksum":3501476284,"timestamp":"2024-06-01T22:43:15.782076Z"}]}
