{"channel":"book","type":"snapshot","data":[{"symbol":"LTC/GBP","bids":[{"price":65.40411,"qty":7.53588000},{"price":65.36914,"qty":1.30000000},{"price":65.35915,"qty":8.75754278},{"price":65.35914,"qty":6.01117861},{"price":65.35910,"qty":20.04593710},{"price":65.35140,"qty":4.82112449},{"price":65.28691,"qty":1.85300390},{"price":65.28690,"qty":5.92975059},{"price":65.28096,"qty":9.13893827},{"price":65.20835,"qty":43.84190449}],"asks":[{"price":65.43759,"qty":1.14412000},{"price":65.43760,"qty":19.11951633},{"price":65.50478,"qty":1.23482247},{"price":65.50479,"qty":1.27161510},{"price":65.50579,"qty":8.79128501},{"price":65.50580,"qty":4.82112449},{"price":65.54742,"qty":6.00000000},{"price":65.56639,"qty":0.14229288},{"price":65.58053,"qty":9.13893827},{"price":65.67332,"qty":17.82430478}],"checksum":3833584113}]}
{"channel":"book","type":"update","data":[{"symbol":"LTC/GBP","bids":[],"asks":[{"price":65.43760,"qty":0.00000000},{"price":65.84019,"qty":17.82430478}],"checksum":165517940,"timestamp":"2024-06-01T22:42:14.291872Z"}]}
{"channel":"book","type":"update","data":[{"symbol":"LTC/GBP","bids":[],"asks":[{"price":65.81713,"qty":0.29357700}],"checksum":3779095976,"timestamp":"2024-06-01T22:42:14.294578Z"}]}
{"channel":"book","type":"update","data":[{"symbol":"LTC/GBP","bids":[{"price":65.36914,"qty":0.00000000},{"price":65.20834,"qty":17.82430478}],"asks":[],"checksum":811145163,"timestamp":"2024-06-01T22:42:14.294709Z"}]}
{"channel":"book","type":"update","data":[{"symbol":"LTC/GBP","bids":[{"price":65.40914,"qty":1.30000000}],"asks":[],"checksum":3107754726,"timestamp":"2024-06-01T22:42:14.294898Z"}]}
{"channel":"book","type":"update","data":[{"symbol":"LTC/GBP","bids":[],"asks":[{"price":65.43760,"qty":17.31067866}],"checksum":2783031936,"timestamp":"2024-06-01T22:42:14.297578Z"}]}
{"channel":"book","type":"update","data":[{"symbol":"LTC/GBP","bids":[],"asks":[{"price":65.50579,"qty":0.00000000},{"price":65.81713,"qty":0.29357700}],"checksum":4043425350,"timestamp":"2024-06-01T22:42:14.300108Z"}]}
{"channel":"book","type":"update","data":[{"symbol":"LTC/GBP","bids":[{"price":65.40914,"qty":0.00000000},{"price":65.20834,"qty":17.82430478}],"asks":[],"checksum":3871836535,"timestamp":"2024-06-01T22:42:14.300230Z"}]}
{"channel":"book","type":"update","data":[{"symbol":"LTC/GBP","bids":[],"asks":[{"price":65.50477,"qty":8.79128501}],"checksum":3307183086,"timestamp":"2024-06-01T22:42:14.300257Z"}]}
{"channel":"book","type":"update","data":[{"symbol":"LTC/GBP","bids":[{"price":65.36418,"qty":1.30000000}],"asks":[],"checksum":531568993,"timestamp":"2024-06-01T22:42:14.300420Z"}]}
{"channel":"book","type":"update","data":[{"symbol":"LTC/GBP","bids":[{"price":65.35915,"qty":0.00000000},{"price":65.20834,"qty":17.82430478},{"price":65.36419,"qty":8.75711406}],"asks":[],"checksum":100187767,"timestamp":"2024-06-01T22:42:14.303999Z"}]}
{"channel":"book","type":"update","data":[{"symbol":"LTC/GBP","bids":[{"price":65.36418,"qty":0.00000000},{"price":65.20834,"qty":17.82430478}],"asks":[],"checksum":2144974710,"timestamp":"2024-06-01T22:42:14.306672Z"}]}
{"channel":"book","type":"update","data":[{"symbol":"LTC/GBP","bids":[{"price":65.36922,"qty":1.30000000}],"asks":[],"checksum":3565965763,"timestamp":"2024-06-01T22:42:14.307011Z"}]}
{"channel":"book","type":"update","data":[{"symbol":"LTC/GBP","bids":[{"price":65.36419,"qty":0.00000000},{"price":65.20834,"qty":17.82430478},{"price":65.35915,"qty":8.75778934}],"asks":[],"checksum":1809229592,"timestamp":"2024-06-01T22:42:14.310021Z"}]}
{"channel":"book","type":"update","data":[{"symbol":"LTC/GBP","bids":[],"asks":[{"price":65.50478,"qty":0.00000000},{"price":65.81713,"qty":0.29357700},{"price":65.50476,"qty":1.23482247}],"checksum":423586166,"timestamp":"2024-06-01T22:42:14.349536Z"}]}
{"channel":"book","type":"update","data":[{"symbol":"LTC/GBP","bids":[{"price":65.40412,"qty":6.01117861}],"asks":[],"checksum":2997175838,"timestamp":"2024-06-01T22:42:14.465385Z"}]}
{"channel":"book","type":"update","data":[{"symbol":"LTC/GBP","bids":[{"price":65.35914,"qty":0.00000000},{"price":65.20835,"qty":43.84190449}],"asks":[],"checksum":2238956775,"timestamp":"2024-06-01T22:42:14.631576Z"}]}
{"channel":"book","type":"update","data":[{"symbol":"LTC/GBP","bids":[{"price":65.35915,"qty":0.00000000},{"price":65.20834,"qty":17.82430478},{"price":65.35911,"qty":8.75779458}],"asks":[],"checksum":2867957543,"timestamp":"2024-06-01T22:42:14.634667Z"}]}
{"channel":"book","type":"update","data":[{"symbol":"LTC/GBP","bids":[{"price":65.36922,"qty":0.00000000},{"price":65.20834,"qty":17.82430478}],"asks":[],"checksum":2870569233,"timestamp":"2024-06-01T22:42:14.999327Z"}]}
{"channel":"book","type":"update","data":[{"symbol":"LTC/GBP","bids":[{"price":65.40500,"qty":1.30000000}],"asks":[],"checksum":2165263409,"timestamp":"2024-06-01T22:42:14.999634Z"}]}
{"channel":"book","type":"update","data":[{"symbol":"LTC/GBP","bids":[{"price":65.35911,"qty":0.00000000},{"price":65.20834,"qty":17.82430478},{"price":65.35911,"qty":8.38517354}],"asks":[],"checksum":3993481840,"timestamp":"2024-06-01T22:42:28.059980Z"}]}
{"channel":"book","type":"update","data":[{"symbol":"LTC/GBP","bids":[{"price":65.35912,"qty":6.01117861}],"asks":[],"checksum":3499984849,"timestamp":"2024-06-01T22:42:38.925817Z"}]}
{"channel":"book","type":"update","data":[{"symbol":"LTC/GBP","bids":[{"price":65.35911,"qty":0.00000000},{"price":65.20835,"qty":43.84190449},{"price":65.35913,"qty":8.38517083}],"asks":[],"checksum":3431135418,"timestamp":"2024-06-01T22:42:38.929125Z"}]}
{"channel":"book","type":"update","data":[{"symbol":"LTC/GBP","bids":[{"price":65.40412,"qty":0.00000000},{"price":65.20835,"qty":43.84190449}],"asks":[],"checksum":2555418307,"timestamp":"2024-06-01T22:42:39.089631Z"}]}
{"channel":"book","type":"update","data":[{"symbol":"LTC/GBP","bids":[{"price":65.40411,"qty":0.00000000},{"price":65.20834,"qty":17.82430478},{"price":65.35914,"qty":7.53588000}],"asks":[],"checksum":1723288012,"timestamp":"2024-06-01T22:42:39.101959Z"}]}
{"channel":"book","type":"update","data":[{"symbol":"LTC/GBP","bids":[{"price":65.40500,"qty":0.00000000},{"price":65.20834,"qty":17.82430478}],"asks":[],"checksum":973882728,"timestamp":"2024-06-01T22:42:39.104640Z"}]}
{"channel":"book","type":"update","data":[{"symbol":"LTC/GBP","bids":[{"price":65.36418,"qty":1.30000000}],"asks":[],"checksum":1654725907,"timestamp":"2024-06-01T22:42:39.104834Z"}]}
{"channel":"book","type":"update","data":[{"symbol":"LTC/GBP","bids":[{"price":65.35913,"qty":0.00000000},{"price":65.20834,"qty":17.82430478},{"price":65.35915,"qty":8.38516827}],"asks":[],"checksum":2841995545,"timestamp":"2024-06-01T22:42:39.105116Z"}]}
{"channel":"book","type":"update","data":[{"symbol":"LTC/GBP","bids":[{"price":65.35915,"qty":0.00000000},{"price":65.20834,"qty":17.82430478},{"price":65.36419,"qty":8.38452172}],"asks":[],"checksum":3799150896,"timestamp":"2024-06-01T22:42:39.109715Z"}]}
{"channel":"book","type":"update","data":[{"symbol":"LTC/GBP","bids":[{"price":65.36418,"qty":0.00000000},{"price":65.20834,"qty":17.82430478}],"asks":[],"checksum":112158919,"timestamp":"2024-06-01T22:42:39.112298Z"}]}
{"channel":"book","type":"update","data":[{"symbol":"LTC/GBP","bids":[{"price":65.36923,"qty":1.30000000}],"asks":[],"checksum":2958352348,"timestamp":"2024-06-01T22:42:39.112996Z"}]}
{"channel":"book","type":"update","data":[{"symbol":"LTC/GBP","bids":[{"price":65.36419,"qty":0.00000000},{"price":65.20834,"qty":17.82430478},{"price":65.35915,"qty":8.38516827}],"asks":[],"checksum":538536101,"timestamp":"2024-06-01T22:42:39.115700Z"}]}
{"channel":"book","type":"update","data":[{"symbol":"LTC/GBP","bids":[{"price":65.35914,"qty":0.00000000},{"price":65.20834,"qty":17.82430478},{"price":65.36924,"qty":7.53588000}],"asks":[],"checksum":3738125104,"timestamp":"2024-06-01T22:42:39.435600Z"}]}
{"channel":"book","type":"update","data":[{"symbol":"LTC/GBP","bids":[{"price":65.36923,"qty":0.00000000},{"price":65.20834,"qty":17.82430478}],"asks":[],"checksum":4197027153,"timestamp":"2024-06-01T22:42:39.438236Z"}]}
{"channel":"book","type":"update","data":[{"symbol":"LTC/GBP","bids":[{"price":65.37428,"qty":1.30000000}],"asks":[],"checksum":3505096323,"timestamp":"2024-06-01T22:42:39.438495Z"}]}
{"channel":"book","type":"update","data":[{"symbol":"LTC/GBP","bids":[{"price":65.35915,"qty":0.00000000},{"price":65.20834,"qty":17.82430478},{"price":65.36925,"qty":8.38387271}],"asks":[],"checksum":3009337623,"timestamp":"2024-06-01T22:42:39.439127Z"}]}
{"channel":"book","type":"update","data":[{"symbol":"LTC/GBP","bids":[{"price":65.36925,"qty":0.00000000},{"price":65.20834,"qty":17.82430478},{"price":65.37429,"qty":8.38322636}],"asks":[],"checksum":3394372683,"timestamp":"2024-06-01T22:42:39.443122Z"}]}
{"channel":"book","type":"update","data":[{"symbol":"LTC/GBP","bids":[{"price":65.37428,"qty":0.00000000},{"price":65.20834,"qty":17.82430478}],"asks":[],"checksum":735892676,"timestamp":"2024-06-01T22:42:39.445859Z"}]}
{"channel":"book","type":"update","data":[{"symbol":"LTC/GBP","bids":[{"price":65.37933,"qty":1.30000000}],"asks":[],"checksum":4123389419,"timestamp":"2024-06-01T22:42:39.446059Z"}]}
{"channel":"book","type":"update","data":[{"symbol":"LTC/GBP","bids":[{"price":65.37429,"qty":0.00000000},{"price":65.20834,"qty":17.82430478},{"price":65.37430,"qty":8.38322507}],"asks":[],"checksum":2085142929,"timestamp":"2024-06-01T22:42:39.446891Z"}]}
{"channel":"book","type":"update","data":[{"symbol":"LTC/GBP","bids":[{"price":65.37430,"qty":0.00000000},{"price":65.20834,"qty":17.82430478},{"price":65.36925,"qty":8.38387271}],"asks":[],"checksum":3648743461,"timestamp":"2024-06-01T22:42:39.450332Z"}]}
{"channel":"book","type":"update","data":[{"symbol":"LTC/GBP","bids":[{"price":65.36924,"qty":0.00000000},{"price":65.20834,"qty":17.82430478},{"price":65.37934,"qty":7.53588000}],"asks":[],"checksum":1077892039,"timestamp":"2024-06-01T22:42:39.741060Z"}]}
{"channel":"book","type":"update","data":[{"symbol":"LTC/GBP","bids":[{"price":65.37933,"qty":0.00000000},{"price":65.20834,"qty":17.82430478}],"asks":[],"checksum":2961850569,"timestamp":"2024-06-01T22:42:39.743711Z"}]}
{"channel":"book","type":"update","data":[{"symbol":"LTC/GBP","bids":[{"price":65.38438,"qty":1.30000000}],"asks":[],"checksum":2655988549,"timestamp":"2024-06-01T22:42:39.743924Z"}]}
{"channel":"book","type":"update","data":[{"symbol":"LTC/GBP","bids":[{"price":65.36925,"qty":0.00000000},{"price":65.20834,"qty":17.82430478},{"price":65.37935,"qty":8.38257754}],"asks":[],"checksum":194615223,"timestamp":"2024-06-01T22:42:39.744592Z"}]}
{"channel":"book","type":"update","data":[{"symbol":"LTC/GBP","bids":[{"price":65.37935,"qty":0.00000000},{"price":65.20834,"qty":17.82430478},{"price":65.38439,"qty":8.38193139}],"asks":[],"checksum":3165545886,"timestamp":"2024-06-01T22:42:39.747709Z"}]}
{"channel":"book","type":"update","data":[{"symbol":"LTC/GBP","bids":[{"price":65.38438,"qty":0.00000000},{"price":65.20834,"qty":17.82430478}],"asks":[],"checksum":2261362097,"timestamp":"2024-06-01T22:42:39.750220Z"}]}
{"channel":"book","type":"update","data":[{"symbol":"LTC/GBP","bids":[{"price":65.38943,"qty":1.30000000}],"asks":[],"checksum":2156959756,"timestamp":"2024-06-01T22:42:39.750459Z"}]}
{"channel":"book","type":"update","data":[{"symbol":"LTC/GBP","bids":[{"price":65.38439,"qty":0.00000000},{"price":65.20834,"qty":17.82430478},{"price":65.37935,"qty":8.38257754}],"asks":[],"checksum":2670195030,"timestamp":"2024-06-01T22:42:39.753089Z"}]}
{"channel":"book","type":"update","data":[{"symbol":"LTC/GBP","bids":[{"price":65.37934,"qty":0.00000000},{"price":65.20834,"qty":17.82430478},{"price":65.38944,"qty":7.53588000}],"asks":[],"checksum":1424371813,"timestamp":"2024-06-01T22:42:39.805040Z"}]}
{"channel":"book","type":"update","data":[{"symbol":"LTC/GBP","bids":[{"price":65.38943,"qty":0.00000000},{"price":65.20834,"qty":17.82430478}],"asks":[],"checksum":459397310,"timestamp":"2024-06-01T22:42:39.807873Z"}]}
{"channel":"book","type":"update","data":[{"symbol":"LTC/GBP","bids":[{"price":65.39448,"qty":1.30000000}],"asks":[],"checksum":1522726358,"timestamp":"2024-06-01T22:42:39.808004Z"}]}
{"channel":"book","type":"update","data":[{"symbol":"LTC/GBP","bids":[{"price":65.37935,"qty":0.00000000},{"price":65.20834,"qty":17.82430478},{"price":65.38945,"qty":8.38128278}],"asks":[],"checksum":2765560997,"timestamp":"2024-06-01T22:42:39.808495Z"}]}
{"channel":"book","type":"update","data":[{"symbol":"LTC/GBP","bids":[{"price":65.38944,"qty":0.00000000},{"price":65.20834,"qty":17.82430478},{"price":65.39449,"qty":7.53588000}],"asks":[],"checksum":3141882191,"timestamp":"2024-06-01T22:42:40.139731Z"}]}
{"channel":"book","type":"update","data":[{"symbol":"LTC/GBP","bids":[{"price":65.39448,"qty":0.00000000},{"price":65.20834,"qty":17.82430478}],"asks":[],"checksum":1945061542,"timestamp":"2024-06-01T22:42:40.142483Z"}]}
{"channel":"book","type":"update","data":[{"symbol":"LTC/GBP","bids":[{"price":65.39953,"qty":1.30000000}],"asks":[],"checksum":193988412,"timestamp":"2024-06-01T22:42:40.142629Z"}]}
{"channel":"book","type":"update","data":[{"symbol":"LTC/GBP","bids":[{"price":65.38945,"qty":0.00000000},{"price":65.20834,"qty":17.82430478},{"price":65.39450,"qty":8.38063554}],"asks":[],"checksum":2332120870,"timestamp":"2024-06-01T22:42:40.143410Z"}]}
{"channel":"book","type":"update","data":[{"symbol":"LTC/GBP","bids":[{"price":65.39450,"qty":0.00000000},{"price":65.20834,"qty":17.82430478},{"price":65.35913,"qty":8.38517084}],"asks":[],"checksum":1533567974,"timestamp":"2024-06-01T22:42:40.146760Z"}]}
{"channel":"book","type":"update","data":[{"symbol":"LTC/GBP","bids":[{"price":65.39449,"qty":0.00000000},{"price":65.20834,"qty":17.82430478},{"price":65.39954,"qty":7.53588000}],"asks":[],"checksum":1558744475,"timestamp":"2024-06-01T22:42:40.474870Z"}]}
{"channel":"book","type":"update","data":[{"symbol":"LTC/GBP","bids":[{"price":65.39953,"qty":0.00000000},{"price":65.20834,"qty":17.82430478}],"asks":[],"checksum":3394760561,"timestamp":"2024-06-01T22:42:40.477588Z"}]}
{"channel":"book","type":"update","data":[{"symbol":"LTC/GBP","bids":[{"price":65.40158,"qty":1.30000000}],"asks":[],"checksum":134997135,"timestamp":"2024-06-01T22:42:40.477811Z"}]}
{"channel":"book","type":"update","data":[{"symbol":"LTC/GBP","bids":[{"price":65.40159,"qty":6.01117861}],"asks":[],"checksum":1607258219,"timestamp":"2024-06-01T22:42:59.918896Z"}]}
{"channel":"book","type":"update","data":[{"symbol":"LTC/GBP","bids":[{"price":65.40158,"qty":0.00000000},{"price":65.20835,"qty":43.84190449}],"asks":[],"checksum":3396593764,"timestamp":"2024-06-01T22:42:59.921545Z"}]}
{"channel":"book","type":"update","data":[{"symbol":"LTC/GBP","bids":[{"price":65.40211,"qty":1.30000000}],"asks":[],"checksum":2483736043,"timestamp":"2024-06-01T22:42:59.922019Z"}]}
{"channel":"book","type":"update","data":[{"symbol":"LTC/GBP","bids":[{"price":65.35912,"qty":0.00000000},{"price":65.20835,"qty":43.84190449}],"asks":[],"checksum":685680473,"timestamp":"2024-06-01T22:43:00.081414Z"}]}
{"channel":"book","type":"update","data":[{"symbol":"LTC/GBP","bids":[{"price":65.35913,"qty":0.00000000},{"price":65.20834,"qty":17.82430478},{"price":65.35911,"qty":8.38517377}],"asks":[],"checksum":2054872471,"timestamp":"2024-06-01T22:43:00.084777Z"}]}
{"channel":"book","type":"update","data":[{"symbol":"LTC/GBP","bids":[],"asks":[{"price":65.43760,"qty":0.00000000},{"price":65.84019,"qty":17.82430478}],"checksum":3542874332,"timestamp":"2024-06-01T22:43:14.641095Z"}]}
{"channel":"book","type":"update","data":[{"symbol":"LTC/GBP","bids":[],"asks":[{"price":65.81713,"qty":0.29357700}],"checksum":404353962,"timestamp":"2024-06-01T22:43:14.643285Z"}]}
{"channel":"book","type":"update","data":[{"symbol":"LTC/GBP","bids":[],"asks":[{"price":65.44545,"qty":53.56017866}],"checksum":599101467,"timestamp":"2024-06-01T22:43:14.646447Z"}]}
{"channel":"book","type":"update","data":[{"symbol":"LTC/GBP","bids":[],"asks":[{"price":65.43759,"qty":0.00000000},{"price":65.81713,"qty":0.29357700},{"price":65.44544,"qty":1.14412000}],"checksum":876470973,"timestamp":"2024-06-01T22:43:14.664478Z"}]}
{"channel":"book","type":"update","data":[{"symbol":"LTC/GBP","bids":[{"price":65.35911,"qty":0.00000000},{"price":65.20834,"qty":17.82430478},{"price":65.40212,"qty":8.37965949}],"asks":[],"checksum":3186736977,"timestamp":"2024-06-01T22:43:14.948978Z"}]}
{"channel":"book","type":"update","data":[{"symbol":"LTC/GBP","bids":[{"price":65.39954,"qty":0.00000000},{"price":65.20834,"qty":17.82430478},{"price":65.40213,"qty":7.53588000}],"asks":[],"checksum":1498812964,"timestamp":"2024-06-01T22:43:14.970200Z"}]}
{"channel":"book","type":"update","data":[{"symbol":"LTC/GBP","bids":[{"price":65.40212,"qty":0.00000000},{"price":65.20834,"qty":17.82430478},{"price":65.40214,"qty":8.37965693}],"asks":[],"checksum":764668144,"timestamp":"2024-06-01T22:43:14.973627Z"}]}
{"channel":"book","type":"update","data":[{"symbol":"LTC/GBP","bids":[{"price":65.40213,"qty":0.00000000},{"price":65.20834,"qty":17.82430478},{"price":65.40215,"qty":7.53588000}],"asks":[],"checksum":1952007030,"timestamp":"2024-06-01T22:43:15.304133Z"}]}
{"channel":"book","type":"update","data":[{"symbol":"LTC/GBP","bids":[{"price":65.40214,"qty":0.00000000},{"price":65.20834,"qty":17.82430478},{"price":65.40216,"qty":8.37965436}],"asks":[],"checksum":1944106409,"timestamp":"2024-06-01T22:43:15.307754Z"}]}
{"channel":"book","type":"update","data":[{"symbol":"LTC/GBP","bids":[{"price":65.40215,"qty":0.00000000},{"price":65.20834,"qty":17.82430478},{"price":65.40217,"qty":7.53588000}],"asks":[],"checksum":1002583456,"timestamp":"2024-06-01T22:43:15.640138Z"}]}
{"channel":"book","type":"update","data":[{"symbol":"LTC/GBP","bids":[{"price":65.40216,"qty":0.00000000},{"price":65.20834,"qty":17.82430478},{"price":65.40218,"qty":8.37965180}],"asks":[],"checksum":2078715086,"timestamp":"2024-06-01T22:43:15.643729Z"}]}
{"channel":"book","type":"update","data":[{"symbol":"LTC/GBP","bids":[{"price":65.40217,"qty":0.00000000},{"price":65.20834,"qty":17.82430478},{"price":65.40219,"qty":7.53588000}],"asks":[],"checksum":3570197746,"timestamp":"2024-06-01T22:43:15.975790Z"}]}
{"channel":"book","type":"update","data":[{"symbol":"LTC/GBP","bids":[{"price":65.40218,"qty":0.00000000},{"price":65.20834,"qty":17.82430478},{"price":65.40220,"qty":8.37964924}],"asks":[],"checksum":259122933,"timestamp":"2024-06-01T22:43:15.979539Z"}]}
{"channel":"book","type":"update","data":[{"symbol":"LTC/GBP","bids":[{"price":65.40219,"qty":0.00000000},{"price":65.20834,"qty":17.82430478},{"price":65.40221,"qty":7.53588000}],"asks":[],"checksum":1300427573,"timestamp":"2024-06-01T22:43:16.310345Z"}]}
{"channel":"book","type":"update","data":[{"symbol":"LTC/GBP","bids":[{"price":65.40220,"qty":0.00000000},{"price":65.20834,"qty":17.82430478},{"price":65.40222,"qty":8.37964667}],"asks":[],"checksum":1970023298,"timestamp":"2024-06-01T22:43:16.314071Z"}]}
{"channel":"book","type":"update","data":[{"symbol":"LTC/GBP","bids":[{"price":65.40222,"qty":14.39082528}],"asks":[],"checksum":2600399484,"timestamp":"2024-06-01T22:43:16.473014Z"}]}
{"channel":"book","type":"update","data":[{"symbol":"LTC/GBP","bids":[{"price":65.40211,"qty":0.00000000},{"price":65.20834,"qty":17.82430478}],"asks":[],"checksum":3304001474,"timestamp":"2024-06-01T22:43:16.475552Z"}]}
{"channel":"book","type":"update","data":[{"symbol":"LTC/GBP","bids":[{"price":65.40266,"qty":1.30000000}],"asks":[],"checksum":4106244005,"timestamp":"2024-06-01T22:43:16.475992Z"}]}
{"channel":"book","type":"update","data":[{"symbol":"LTC/GBP","bids":[{"price":65.40222,"qty":6.01117861},{"price":65.40223,"qty":8.37964540}],"asks":[],"checksum":1905295622,"timestamp":"2024-06-01T22:43:16.476278Z"}]}
{"channel":"book","type":"update","data":[{"symbol":"LTC/GBP","bids":[{"price":65.40223,"qty":0.00000000},{"price":65.20835,"qty":43.84190449},{"price":65.40267,"qty":8.37958903}],"asks":[],"checksum":1894430669,"timestamp":"2024-06-01T22:43:16.480820Z"}]}
{"channel":"book","type":"update","data":[{"symbol":"LTC/GBP","bids":[{"price":65.40266,"qty":0.00000000},{"price":65.20835,"qty":43.84190449}],"asks":[],"checksum":2180600254,"timestamp":"2024-06-01T22:43:16.483506Z"}]}
{"channel":"book","type":"update","data":[{"symbol":"LTC/GBP","bids":[{"price":65.40268,"qty":1.30000000}],"asks":[],"checksum":123055673,"timestamp":"2024-06-01T22:43:16.483571Z"}]}
{"channel":"book","type":"update","data":[{"symbol":"LTC/GBP","bids":[{"price":65.40267,"qty":0.00000000},{"price":65.20835,"qty":43.84190449},{"price":65.40223,"qty":8.37964540}],"asks":[],"checksum":1509052961,"timestamp":"2024-06-01T22:43:16.486988Z"}]}
{"channel":"book","type":"update","data":[{"symbol":"LTC/GBP","bids":[{"price":65.40223,"qty":0.00000000},{"price":65.20835,"qty":43.84190449},{"price":65.40269,"qty":8.37958647}],"asks":[],"checksum":2014426298,"timestamp":"2024-06-01T22:43:16.489781Z"}]}
{"channel":"book","type":"update","data":[{"symbol":"LTC/GBP","bids":[{"price":65.40221,"qty":0.00000000},{"price":65.20835,"qty":43.84190449},{"price":65.40269,"qty":15.91546647}],"asks":[],"checksum":883511364,"timestamp":"2024-06-01T22:43:16.494995Z"}]}
{"channel":"book","type":"update","data":[{"symbol":"LTC/GBP","bids":[{"price":65.40268,"qty":0.00000000},{"price":65.20834,"qty":17.82430478}],"asks":[],"checksum":1317977215,"timestamp":"2024-06-01T22:43:16.497749Z"}]}
{"channel":"book","type":"update","data":[{"symbol":"LTC/GBP","bids":[{"price":65.40270,"qty":1.30000000}],"asks":[],"checksum":2359900672,"timestamp":"2024-06-01T22:43:16.498146Z"}]}
{"channel":"book","type":"update","data":[{"symbol":"LTC/GBP","bids":[{"price":65.40269,"qty":7.53588000},{"price":65.40270,"qty":9.67958518}],"asks":[],"checksum":1161574637,"timestamp":"2024-06-01T22:43:16.498189Z"}]}
{"channel":"book","type":"update","data":[{"symbol":"LTC/GBP","bids":[{"price":65.40270,"qty":1.30000000},{"price":65.40271,"qty":8.37958390}],"asks":[],"checksum":863581725,"timestamp":"2024-06-01T22:43:16.501585Z"}]}
{"channel":"book","type":"update","data":[{"symbol":"LTC/GBP","bids":[{"price":65.40270,"qty":0.00000000},{"price":65.20835,"qty":43.84190449}],"asks":[],"checksum":3379257486,"timestamp":"2024-06-01T22:43:16.637088Z"}]}
{"channel":"book","type":"update","data":[{"symbol":"LTC/GBP","bids":[{"price":65.40346,"qty":1.30000000}],"asks":[],"checksum":2898574566,"timestamp":"2024-06-01T22:43:16.637189Z"}]}
{"channel":"book","type":"update","data":[{"symbol":"LTC/GBP","bids":[{"price":65.40271,"qty":0.00000000},{"price":65.20835,"qty":43.84190449},{"price":65.40270,"qty":8.37958519}],"asks":[],"checksum":4091691221,"timestamp":"2024-06-01T22:43:16.640326Z"}]}
{"channel":"book","type":"update","data":[{"symbol":"LTC/GBP","bids":[{"price":65.40159,"qty":0.00000000},{"price":65.20835,"qty":43.84190449}],"asks":[],"checksum":105304067,"timestamp":"2024-06-01T22:43:16.643450Z"}]}
{"channel":"book","type":"update","data":[{"symbol":"LTC/GBP","bids":[{"price":65.40270,"qty":0.00000000},{"price":65.20834,"qty":17.82430478},{"price":65.40347,"qty":8.37948654}],"asks":[],"checksum":2236369080,"timestamp":"2024-06-01T22:43:16.643846Z"}]}
{"channel":"book","type":"update","data":[{"symbol":"LTC/GBP","bids":[{"price":65.40347,"qty":0.00000000},{"price":65.20834,"qty":17.82430478},{"price":65.40348,"qty":8.37948526}],"asks":[],"checksum":4210272588,"timestamp":"2024-06-01T22:43:16.647950Z"}]}
{"channel":"book","type":"update","data":[{"symbol":"LTC/GBP","bids":[{"price":65.40269,"qty":0.00000000},{"price":65.20834,"qty":17.82430478},{"price":65.40347,"qty":7.53588000}],"asks":[],"checksum":605300261,"timestamp":"2024-06-01T22:43:16.649346Z"}]}
{"channel":"book","type":"update","data":[{"symbol":"LTC/GBP","bids":[{"price":65.40348,"qty":0.00000000},{"price":65.20834,"qty":17.82430478},{"price":65.40347,"qty":15.91536654}],"asks":[],"checksum":2626073475,"timestamp":"2024-06-01T22:43:16.651470Z"}]}
{"channel":"book","type":"update","data":[{"symbol":"LTC/GBP","bids":[{"price":65.40347,"qty":7.53588000},{"price":65.40348,"qty":8.37948526}],"asks":[],"checksum":605300261,"timestamp":"2024-06-01T22:43:16.663267Z"}]}
{"channel":"book","type":"update","data":[{"symbol":"LTC/GBP","bids":[{"price":65.40347,"qty":0.00000000},{"price":65.20834,"qty":17.82430478},{"price":65.40349,"qty":7.53588000}],"asks":[],"checksum":3617065235,"timestamp":"2024-06-01T22:43:16.985159Z"}]}
{"channel":"book","type":"update","data":[{"symbol":"LTC/GBP","bids":[{"price":65.40348,"qty":0.00000000},{"price":65.20834,"qty":17.82430478},{"price":65.40350,"qty":8.37948270}],"asks":[],"checksum":1392335041,"timestamp":"2024-06-01T22:43:16.990057Z"}]}
{"channel":"book","type":"update","data":[{"symbol":"LTC/GBP","bids":[{"price":65.40349,"qty":0.00000000},{"price":65.20834,"qty":17.82430478},{"price":65.40351,"qty":7.53588000}],"asks":[],"checksum":4232456034,"timestamp":"2024-06-01T22:43:17.049310Z"}]}
{"channel":"book","type":"update","data":[{"symbol":"LTC/GBP","bids":[{"price":65.40350,"qty":0.00000000},{"price":65.20834,"qty":17.82430478},{"price":65.40352,"qty":8.37948015}],"asks":[],"checksum":2888187210,"timestamp":"2024-06-01T22:43:17.104225Z"}]}
{"channel":"book","type":"update","data":[{"symbol":"LTC/GBP","bids":[{"price":65.40351,"qty":0.00000000},{"price":65.20834,"qty":17.82430478},{"price":65.40353,"qty":7.53588000}],"asks":[],"checksum":3236979639,"timestamp":"2024-06-01T22:43:17.112876Z"}]}
{"channel":"book","type":"update","data":[{"symbol":"LTC/GBP","bids":[{"price":65.40352,"qty":0.00000000},{"price":65.20834,"qty":17.82430478},{"price":65.40354,"qty":8.37947758}],"asks":[],"checksum":3834013261,"timestamp":"2024-06-01T22:43:17.253516Z"}]}
{"channel":"book","type":"update","data":[{"symbol":"LTC/GBP","bids":[{"price":65.40353,"qty":0.00000000},{"price":65.20834,"qty":17.82430478},{"price":65.40355,"qty":7.53588000}],"asks":[],"checksum":3799134462,"timestamp":"2024-06-01T22:43:17.267977Z"}]}
{"channel":"book","type":"update","data":[{"symbol":"LTC/GBP","bids":[{"price":65.40354,"qty":0.00000000},{"price":65.20834,"qty":17.82430478},{"price":65.40356,"qty":8.37947502}],"asks":[],"checksum":1174248997,"timestamp":"2024-06-01T22:43:17.437079Z"}]}
{"channel":"book","type":"update","data":[{"symbol":"LTC/GBP","bids":[{"price":65.40355,"qty":0.00000000},{"price":65.20834,"qty":17.82430478},{"price":65.40357,"qty":7.53588000}],"asks":[],"checksum":258119693,"timestamp":"2024-06-01T22:43:17.453381Z"}]}
{"channel":"book","type":"update","data":[{"symbol":"LTC/GBP","bids":[{"price":65.40356,"qty":0.00000000},{"price":65.20834,"qty":17.82430478},{"price":65.40358,"qty":8.37947246}],"asks":[],"checksum":3135438630,"timestamp":"2024-06-01T22:43:17.576563Z"}]}
{"channel":"book","type":"update","data":[{"symbol":"LTC/GBP","bids":[{"price":65.40357,"qty":0.00000000},{"price":65.20834,"qty":17.82430478},{"price":65.40359,"qty":7.53588000}],"asks":[],"checksum":3937623118,"timestamp":"2024-06-01T22:43:17.607181Z"}]}
{"channel":"book","type":"update","data":[{"symbol":"LTC/GBP","bids":[{"price":65.40358,"qty":0.00000000},{"price":65.20834,"qty":17.82430478},{"price":65.40360,"qty":8.37946990}],"asks":[],"checksum":162876693,"timestamp":"2024-06-01T22:43:17.749786Z"}]}
{"channel":"book","type":"update","data":[{"symbol":"LTC/GBP","bids":[{"price":65.40359,"qty":0.00000000},{"price":65.20834,"qty":17.82430478},{"price":65.40361,"qty":7.53588000}],"asks":[],"checksum":958527364,"timestamp":"2024-06-01T22:43:17.759928Z"}]}
{"channel":"book","type":"update","data":[{"symbol":"LTC/GBP","bids":[{"price":65.40360,"qty":0.00000000},{"price":65.20834,"qty":17.82430478},{"price":65.40362,"qty":8.37946734}],"asks":[],"checksum":4034332802,"timestamp":"2024-06-01T22:43:17.956953Z"}]}
{"channel":"book","type":"update","data":[{"symbol":"LTC/GBP","bids":[{"price":65.40361,"qty":0.00000000},{"price":65.20834,"qty":17.82430478},{"price":65.40363,"qty":7.53588000}],"asks":[],"checksum":2367970389,"timestamp":"2024-06-01T22:43:17.975656Z"}]}
{"channel":"book","type":"update","data":[{"symbol":"LTC/GBP","bids":[{"price":65.40362,"qty":0.00000000},{"price":65.20834,"qty":17.82430478},{"price":65.40364,"qty":8.37946478}],"asks":[],"checksum":3112786476,"timestamp":"2024-06-01T22:43:18.197264Z"}]}
{"channel":"book","type":"update","data":[{"symbol":"LTC/GBP","bids":[{"price":65.40363,"qty":0.00000000},{"price":65.20834,"qty":17.82430478},{"price":65.40365,"qty":7.53588000}],"asks":[],"checksum":2362905854,"timestamp":"2024-06-01T22:43:18.223712Z"}]}
{"channel":"book","type":"update","data":[{"symbol":"LTC/GBP","bids":[{"price":65.40364,"qty":0.00000000},{"price":65.20834,"qty":17.82430478},{"price":65.40366,"qty":8.37946285}],"asks":[],"checksum":3642734155,"timestamp":"2024-06-01T22:43:18.471577Z"}]}
{"channel":"book","type":"update","data":[{"symbol":"LTC/GBP","bids":[{"price":65.40365,"qty":0.00000000},{"price":65.20834,"qty":17.82430478},{"price":65.40367,"qty":7.53588000}],"asks":[],"checksum":1176707771,"timestamp":"2024-06-01T22:43:18.498371Z"}]}
{"channel":"book","type":"update","data":[{"symbol":"LTC/GBP","bids":[{"price":65.40366,"qty":0.00000000},{"price":65.20834,"qty":17.82430478},{"price":65.40368,"qty":8.37946029}],"asks":[],"checksum":3209317300,"timestamp":"2024-06-01T22:43:18.703073Z"}]}
{"channel":"book","type":"update","data":[{"symbol":"LTC/GBP","bids":[{"price":65.40367,"qty":0.00000000},{"price":65.20834,"qty":17.82430478},{"price":65.40369,"qty":7.53588000}],"asks":[],"checksum":3778117959,"timestamp":"2024-06-01T22:43:18.743350Z"}]}
{"channel":"book","type":"update","data":[{"symbol":"LTC/GBP","bids":[{"price":65.40368,"qty":0.00000000},{"price":65.20834,"qty":17.82430478},{"price":65.40370,"qty":8.37945773}],"asks":[],"checksum":2902687483,"timestamp":"2024-06-01T22:43:18.968285Z"}]}
{"channel":"book","type":"update","data":[{"symbol":"LTC/GBP","bids":[{"price":65.40369,"qty":0.00000000},{"price":65.20834,"qty":17.82430478},{"price":65.40371,"qty":7.53588000}],"asks":[],"checksum":4002230474,"timestamp":"2024-06-01T22:43:18.987717Z"}]}
{"channel":"book","type":"update","data":[{"symbol":"LTC/GBP","bids":[{"price":65.40370,"qty":0.00000000},{"price":65.20834,"qty":17.82430478},{"price":65.40372,"qty":8.37945517}],"asks":[],"checksum":2262500534,"timestamp":"2024-06-01T22:43:19.266746Z"}]}
{"channel":"book","type":"update","data":[{"symbol":"LTC/GBP","bids":[{"price":65.40371,"qty":0.00000000},{"price":65.20834,"qty":17.82430478},{"price":65.40373,"qty":7.53588000}],"asks":[],"checksum":2967459216,"timestamp":"2024-06-01T22:43:19.294700Z"}]}
{"channel":"book","type":"update","data":[{"symbol":"LTC/GBP","bids":[{"price":65.40372,"qty":0.00000000},{"price":65.20834,"qty":17.82430478},{"price":65.40374,"qty":8.37945260}],"asks":[],"checksum":2687015984,"timestamp":"2024-06-01T22:43:19.598290Z"}]}
{"channel":"book","type":"update","data":[{"symbol":"LTC/GBP","bids":[{"price":65.40373,"qty":0.00000000},{"price":65.20834,"qty":17.82430478},{"price":65.40375,"qty":7.53588000}],"asks":[],"checksum":1195386136,"timestamp":"2024-06-01T22:43:19.628282Z"}]}
{"channel":"book","type":"update","data":[{"symbol":"LTC/GBP","bids":[{"price":65.40374,"qty":0.00000000},{"price":65.20834,"qty":17.82430478},{"price":65.40376,"qty":8.37945004}],"asks":[],"checksum":454124244,"timestamp":"2024-06-01T22:43:19.887890Z"}]}
{"channel":"book","type":"update","data":[{"symbol":"LTC/GBP","bids":[{"price":65.40375,"qty":0.00000000},{"price":65.20834,"qty":17.82430478},{"price":65.40377,"qty":7.53588000}],"asks":[],"checksum":420659266,"timestamp":"2024-06-01T22:43:19.903044Z"}]}
{"channel":"book","type":"update","data":[{"symbol":"LTC/GBP","bids":[{"price":65.40376,"qty":0.00000000},{"price":65.20834,"qty":17.82430478},{"price":65.40378,"qty":8.37944748}],"asks":[],"checksum":1003640737,"timestamp":"2024-06-01T22:43:20.209925Z"}]}
{"channel":"book","type":"update","data":[{"symbol":"LTC/GBP","bids":[{"price":65.40377,"qty":0.00000000},{"price":65.20834,"qty":17.82430478},{"price":65.40379,"qty":7.53588000}],"asks":[],"checksum":2803299309,"timestamp":"2024-06-01T22:43:20.238252Z"}]}
{"channel":"book","type":"update","data":[{"symbol":"LTC/GBP","bids":[{"price":65.40378,"qty":0.00000000},{"price":65.20834,"qty":17.82430478},{"price":65.40380,"qty":8.37944497}],"asks":[],"checksum":559498805,"timestamp":"2024-06-01T22:43:20.565497Z"}]}
{"channel":"book","type":"update","data":[{"symbol":"LTC/GBP","bids":[{"price":65.40379,"qty":0.00000000},{"price":65.20834,"qty":17.82430478},{"price":65.40381,"qty":7.53588000}],"asks":[],"checksum":1478049957,"timestamp":"2024-06-01T22:43:20.575027Z"}]}
{"channel":"book","type":"update","data":[{"symbol":"LTC/GBP","bids":[{"price":65.40380,"qty":0.00000000},{"price":65.20834,"qty":17.82430478},{"price":65.40382,"qty":8.37944240}],"asks":[],"checksum":2740785704,"timestamp":"2024-06-01T22:43:20.955574Z"}]}
{"channel":"book","type":"update","data":[{"symbol":"LTC/GBP","bids":[{"price":65.40381,"qty":0.00000000},{"price":65.20834,"qty":17.82430478},{"price":65.40383,"qty":7.53588000}],"asks":[],"checksum":204063012,"timestamp":"2024-06-01T22:43:20.971919Z"}]}
{"channel":"book","type":"update","data":[{"symbol":"LTC/GBP","bids":[{"price":65.40382,"qty":0.00000000},{"price":65.20834,"qty":17.82430478},{"price":65.40384,"qty":8.37943984}],"asks":[],"checksum":2063452571,"timestamp":"2024-06-01T22:43:21.302125Z"}]}
{"channel":"book","type":"update","data":[{"symbol":"LTC/GBP","bids":[{"price":65.40383,"qty":0.00000000},{"price":65.20834,"qty":17.82430478},{"price":65.40385,"qty":7.53588000}],"asks":[],"checksum":2489856550,"timestamp":"2024-06-01T22:43:21.312066Z"}]}
{"channel":"book","type":"update","data":[{"symbol":"LTC/GBP","bids":[{"price":65.40384,"qty":0.00000000},{"price":65.20834,"qty":17.82430478},{"price":65.40386,"qty":8.37943728}],"asks":[],"checksum":684166009,"timestamp":"2024-06-01T22:43:21.681882Z"}]}
{"channel":"book","type":"update","data":[{"symbol":"LTC/GBP","bids":[{"price":65.40385,"qty":0.00000000},{"price":65.20834,"qty":17.82430478},{"price":65.40387,"qty":7.53588000}],"asks":[],"checksum":2175441165,"timestamp":"2024-06-01T22:43:21.708208Z"}]}
{"channel":"book","type":"update","data":[{"symbol":"LTC/GBP","bids":[{"price":65.40386,"qty":0.00000000},{"price":65.20834,"qty":17.82430478},{"price":65.40388,"qty":8.37943472}],"asks":[],"checksum":1788642618,"timestamp":"2024-06-01T22:43:22.018687Z"}]}
{"channel":"book","type":"update","data":[{"symbol":"LTC/GBP","bids":[{"price":65.40387,"qty":0.00000000},{"price":65.20834,"qty":17.82430478},{"price":65.40389,"qty":7.53588000}],"asks":[],"checksum":1524248767,"timestamp":"2024-06-01T22:43:22.043143Z"}]}
{"channel":"book","type":"update","data":[{"symbol":"LTC/GBP","bids":[{"price":65.40388,"qty":0.00000000},{"price":65.20834,"qty":17.82430478},{"price":65.40390,"qty":8.37943215}],"asks":[],"checksum":1319690632,"timestamp":"2024-06-01T22:43:22.388826Z"}]}
{"channel":"book","type":"update","data":[{"symbol":"LTC/GBP","bids":[{"price":65.40389,"qty":0.00000000},{"price":65.20834,"qty":17.82430478},{"price":65.40391,"qty":7.53588000}],"asks":[],"checksum":2307212399,"timestamp":"2024-06-01T22:43:22.409671Z"}]}
{"channel":"book","type":"update","data":[{"symbol":"LTC/GBP","bids":[],"asks":[{"price":65.56639,"qty":0.00000000},{"price":65.84019,"qty":17.82430478}],"checksum":42861580,"timestamp":"2024-06-01T22:43:22.791752Z"}]}
{"channel":"book","type":"update","data":[{"symbol":"LTC/GBP","bids":[{"price":65.40390,"qty":0.00000000},{"price":65.20834,"qty":17.82430478},{"price":65.40392,"qty":8.37942941}],"asks":[],"checksum":764488389,"timestamp":"2024-06-01T22:43:22.792534Z"}]}
{"channel":"book","type":"update","data":[{"symbol":"LTC/GBP","bids":[],"asks":[{"price":65.82503,"qty":0.29354176}],"checksum":1119709572,"timestamp":"2024-06-01T22:43:22.794086Z"}]}
{"channel":"book","type":"update","data":[{"symbol":"LTC/GBP","bids":[{"price":65.40391,"qty":0.00000000},{"price":65.20834,"qty":17.82430478},{"price":65.40393,"qty":7.53588000}],"asks":[],"checksum":3184789215,"timestamp":"2024-06-01T22:43:22.806877Z"}]}
{"channel":"book","type":"update","data":[{"symbol":"LTC/GBP","bids":[],"asks":[{"price":65.56047,"qty":0.14236075}],"checksum":86835579,"timestamp":"2024-06-01T22:43:22.858777Z"}]}
{"channel":"book","type":"update","data":[{"symbol":"LTC/GBP","bids":[{"price":65.40392,"qty":0.00000000},{"price":65.20834,"qty":17.82430478},{"price":65.40394,"qty":8.37942685}],"asks":[],"checksum":1249973409,"timestamp":"2024-06-01T22:43:23.153850Z"}]}
{"channel":"book","type":"update","data":[{"symbol":"LTC/GBP","bids":[{"price":65.40393,"qty":0.00000000},{"price":65.20834,"qty":17.82430478},{"price":65.40395,"qty":7.53588000}],"asks":[],"checksum":1638590880,"timestamp":"2024-06-01T22:43:23.173501Z"}]}
{"channel":"book","type":"update","data":[{"symbol":"LTC/GBP","bids":[{"price":65.40394,"qty":0.00000000},{"price":65.20834,"qty":17.82430478},{"price":65.40396,"qty":8.37942429}],"asks":[],"checksum":3747395403,"timestamp":"2024-06-01T22:43:23.548163Z"}]}
{"channel":"book","type":"update","data":[{"symbol":"LTC/GBP","bids":[{"price":65.40395,"qty":0.00000000},{"price":65.20834,"qty":17.82430478},{"price":65.40397,"qty":7.53588000}],"asks":[],"checksum":3977395715,"timestamp":"2024-06-01T22:43:23.573139Z"}]}
{"channel":"book","type":"update","data":[{"symbol":"LTC/GBP","bids":[{"price":65.40396,"qty":0.00000000},{"price":65.20834,"qty":17.82430478},{"price":65.40398,"qty":8.37942173}],"asks":[],"checksum":4277422476,"timestamp":"2024-06-01T22:43:23.976114Z"}]}
{"channel":"book","type":"update","data":[{"symbol":"LTC/GBP","bids":[{"price":65.40397,"qty":0.00000000},{"price":65.20834,"qty":17.82430478},{"price":65.40399,"qty":7.53588000}],"asks":[],"checksum":2061478389,"timestamp":"2024-06-01T22:43:23.998433Z"}]}
{"channel":"book","type":"update","data":[{"symbol":"LTC/GBP","bids":[],"asks":[{"price":65.44544,"qty":0.00000000},{"price":65.82503,"qty":0.29354176}],"checksum":4131142491,"timestamp":"2024-06-01T22:43:24.334803Z"}]}
{"channel":"book","type":"update","data":[{"symbol":"LTC/GBP","bids":[{"price":65.40398,"qty":0.00000000},{"price":65.20834,"qty":17.82430478},{"price":65.40400,"qty":8.37941916}],"asks":[],"checksum":2506637445,"timestamp":"2024-06-01T22:43:24.361294Z"}]}
{"channel":"book","type":"update","data":[{"symbol":"LTC/GBP","bids":[{"price":65.40399,"qty":0.00000000},{"price":65.20834,"qty":17.82430478},{"price":65.40401,"qty":7.53588000}],"asks":[],"checksum":2955706802,"timestamp":"2024-06-01T22:43:24.396752Z"}]}
{"channel":"book","type":"update","data":[{"symbol":"LTC/GBP","bids":[{"price":65.40400,"qty":0.00000000},{"price":65.20834,"qty":17.82430478},{"price":65.40402,"qty":8.37941635}],"asks":[],"checksum":3558479942,"timestamp":"2024-06-01T22:43:24.780043Z"}]}
{"channel":"book","type":"update","data":[{"symbol":"LTC/GBP","bids":[{"price":65.40401,"qty":0.00000000},{"price":65.20834,"qty":17.82430478},{"price":65.40403,"qty":7.53588000}],"asks":[],"checksum":3018121619,"timestamp":"2024-06-01T22:43:24.792455Z"}]}
{"channel":"book","type":"update","data":[{"symbol":"LTC/GBP","bids":[{"price":65.40402,"qty":0.00000000},{"price":65.20834,"qty":17.82430478},{"price":65.40404,"qty":8.37941377}],"asks":[],"checksum":1931678030,"timestamp":"2024-06-01T22:43:25.154791Z"}]}
{"channel":"book","type":"update","data":[{"symbol":"LTC/GBP","bids":[],"asks":[{"price":65.82503,"qty":0.00000000},{"price":65.84019,"qty":17.82430478}],"checksum":1386183774,"timestamp":"2024-06-01T22:43:25.190499Z"}]}
{"channel":"book","type":"update","data":[{"symbol":"LTC/GBP","bids":[{"price":65.40403,"qty":0.00000000},{"price":65.20834,"qty":17.82430478},{"price":65.40405,"qty":7.53588000}],"asks":[],"checksum":3959110133,"timestamp":"2024-06-01T22:43:25.195247Z"}]}
{"channel":"book","type":"update","data":[{"symbol":"LTC/GBP","bids":[{"price":65.40404,"qty":0.00000000},{"price":65.20834,"qty":17.82430478},{"price":65.40406,"qty":8.37941121}],"asks":[],"checksum":262608601,"timestamp":"2024-06-01T22:43:25.563644Z"}]}
{"channel":"book","type":"update","data":[{"symbol":"LTC/GBP","bids":[{"price":65.40405,"qty":0.00000000},{"price":65.20834,"qty":17.82430478},{"price":65.40407,"qty":7.53588000}],"asks":[],"checksum":4157542785,"timestamp":"2024-06-01T22:43:25.591938Z"}]}
{"channel":"book","type":"update","data":[{"symbol":"LTC/GBP","bids":[{"price":65.40406,"qty":0.00000000},{"price":65.20834,"qty":17.82430478},{"price":65.40408,"qty":8.37940864}],"asks":[],"checksum":41708651,"timestamp":"2024-06-01T22:43:26.005608Z"}]}
{"channel":"book","type":"update","data":[{"symbol":"LTC/GBP","bids":[{"price":65.40407,"qty":0.00000000},{"price":65.20834,"qty":17.82430478},{"price":65.40409,"qty":7.53588000}],"asks":[],"checksum":671487471,"timestamp":"2024-06-01T22:43:26.016997Z"}]}
{"channel":"book","type":"update","data":[{"symbol":"LTC/GBP","bids":[{"price":65.40408,"qty":0.00000000},{"price":65.20834,"qty":17.82430478},{"price":65.40410,"qty":8.37940608}],"asks":[],"checksum":433360471,"timestamp":"2024-06-01T22:43:26.404633Z"}]}
{"channel":"book","type":"update","data":[{"symbol":"LTC/GBP","bids":[{"price":65.40409,"qty":0.00000000},{"price":65.20834,"qty":17.82430478},{"price":65.40411,"qty":7.53588000}],"asks":[],"checksum":333458340,"timestamp":"2024-06-01T22:43:26.418064Z"}]}
{"channel":"book","type":"update","data":[{"symbol":"LTC/GBP","bids":[{"price":65.40410,"qty":0.00000000},{"price":65.20834,"qty":17.82430478},{"price":65.40412,"qty":8.37940316}],"asks":[],"checksum":2848148895,"timestamp":"2024-06-01T22:43:26.837149Z"}]}
{"channel":"book","type":"update","data":[{"symbol":"LTC/GBP","bids":[{"price":65.40411,"qty":0.00000000},{"price":65.20834,"qty":17.82430478},{"price":65.40413,"qty":7.53588000}],"asks":[],"checksum":3514869361,"timestamp":"2024-06-01T22:43:26.846848Z"}]}
{"channel":"book","type":"update","data":[{"symbol":"LTC/GBP","bids":[{"price":65.40412,"qty":0.00000000},{"price":65.20834,"qty":17.82430478},{"price":65.40414,"qty":8.37940060}],"asks":[],"checksum":412183079,"timestamp":"2024-06-01T22:43:27.304376Z"}]}
{"channel":"book","type":"update","data":[{"symbol":"LTC/GBP","bids":[{"price":65.40413,"qty":0.00000000},{"price":65.20834,"qty":17.82430478},{"price":65.40415,"qty":7.53588000}],"asks":[],"checksum":869409550,"timestamp":"2024-06-01T22:43:27.334963Z"}]}
{"channel":"book","type":"update","data":[{"symbol":"LTC/GBP","bids":[{"price":65.40414,"qty":0.00000000},{"price":65.20834,"qty":17.82430478},{"price":65.40416,"qty":8.37939804}],"asks":[],"checksum":7302078,"timestamp":"2024-06-01T22:43:27.727046Z"}]}
{"channel":"book","type":"update","data":[{"symbol":"LTC/GBP","bids":[],"asks":[{"price":65.44545,"qty":0.00000000},{"price":65.98424,"qty":127.07534252}],"checksum":3335113816,"timestamp":"2024-06-01T22:43:27.736233Z"}]}
{"channel":"book","type":"update","data":[{"symbol":"LTC/GBP","bids":[],"asks":[{"price":65.88469,"qty":0.29395882}],"checksum":4239101487,"timestamp":"2024-06-01T22:43:27.739019Z"}]}
{"channel":"book","type":"update","data":[{"symbol":"LTC/GBP","bids":[{"price":65.40921,"qty":1.30000000}],"asks":[],"checksum":2111667282,"timestamp":"2024-06-01T22:43:27.739510Z"}]}
{"channel":"book","type":"update","data":[{"symbol":"LTC/GBP","bids":[{"price":65.40346,"qty":0.00000000},{"price":65.20835,"qty":43.84190449}],"asks":[],"checksum":2817791759,"timestamp":"2024-06-01T22:43:27.739541Z"}]}
{"channel":"book","type":"update","data":[{"symbol":"LTC/GBP","bids":[],"asks":[{"price":65.45330,"qty":53.56017866}],"checksum":283588736,"timestamp":"2024-06-01T22:43:27.742468Z"}]}
{"channel":"book","type":"update","data":[{"symbol":"LTC/GBP","bids":[],"asks":[{"price":65.50477,"qty":0.00000000},{"price":65.88469,"qty":0.29395882}],"checksum":2731873355,"timestamp":"2024-06-01T22:43:27.745955Z"}]}
{"channel":"book","type":"update","data":[{"symbol":"LTC/GBP","bids":[],"asks":[{"price":65.50475,"qty":8.79128501}],"checksum":764928962,"timestamp":"2024-06-01T22:43:27.746070Z"}]}
{"channel":"book","type":"update","data":[{"symbol":"LTC/GBP","bids":[{"price":65.40921,"qty":0.00000000},{"price":65.20834,"qty":17.82430478}],"asks":[],"checksum":1044907676,"timestamp":"2024-06-01T22:43:27.746293Z"}]}
{"channel":"book","type":"update","data":[{"symbol":"LTC/GBP","bids":[{"price":65.40415,"qty":0.00000000},{"price":65.17694,"qty":0.14332488},{"price":65.40922,"qty":7.53588000}],"asks":[],"checksum":1877240757,"timestamp":"2024-06-01T22:43:27.761685Z"}]}
{"channel":"book","type":"update","data":[{"symbol":"LTC/GBP","bids":[{"price":65.40449,"qty":1.30000000}],"asks":[],"checksum":3749405473,"timestamp":"2024-06-01T22:43:27.770383Z"}]}
{"channel":"book","type":"update","data":[{"symbol":"LTC/GBP","bids":[],"asks":[{"price":65.45329,"qty":1.14412000}],"checksum":38439842,"timestamp":"2024-06-01T22:43:27.794488Z"}]}
{"channel":"book","type":"update","data":[{"symbol":"LTC/GBP","bids":[],"asks":[{"price":65.50476,"qty":0.00000000},{"price":65.84019,"qty":17.82430478},{"price":65.50474,"qty":1.23482247}],"checksum":1949406490,"timestamp":"2024-06-01T22:43:27.828555Z"}]}
{"channel":"book","type":"update","data":[{"symbol":"LTC/GBP","bids":[{"price":65.40449,"qty":0.00000000},{"price":65.20834,"qty":17.82430478}],"asks":[],"checksum":3729049703,"timestamp":"2024-06-01T22:43:27.875717Z"}]}
{"channel":"book","type":"update","data":[{"symbol":"LTC/GBP","bids":[{"price":65.40971,"qty":1.30000000}],"asks":[],"checksum":2530143291,"timestamp":"2024-06-01T22:43:27.875833Z"}]}
{"channel":"book","type":"update","data":[{"symbol":"LTC/GBP","bids":[],"asks":[{"price":65.45330,"qty":0.00000000},{"price":65.84019,"qty":17.82430478}],"checksum":661009108,"timestamp":"2024-06-01T22:43:27.881469Z"}]}
{"channel":"book","type":"update","data":[{"symbol":"LTC/GBP","bids":[],"asks":[{"price":65.50475,"qty":0.00000000},{"price":65.88469,"qty":0.29395882}],"checksum":50241636,"timestamp":"2024-06-01T22:43:27.884977Z"}]}
{"channel":"book","type":"update","data":[{"symbol":"LTC/GBP","bids":[],"asks":[{"price":65.50473,"qty":8.79128501}],"checksum":2603103653,"timestamp":"2024-06-01T22:43:27.884991Z"}]}
{"channel":"book","type":"update","data":[{"symbol":"LTC/GBP","bids":[],"asks":[{"price":65.46115,"qty":53.56017866}],"checksum":1656646280,"timestamp":"2024-06-01T22:43:27.887178Z"}]}
{"channel":"book","type":"update","data":[{"symbol":"LTC/GBP","bids":[{"price":65.40922,"qty":0.00000000},{"price":65.20834,"qty":17.82430478},{"price":65.40972,"qty":7.53588000}],"asks":[],"checksum":3981406165,"timestamp":"2024-06-01T22:43:27.891543Z"}]}
{"channel":"book","type":"update","data":[{"symbol":"LTC/GBP","bids":[{"price":65.40971,"qty":0.00000000},{"price":65.20834,"qty":17.82430478}],"asks":[],"checksum":1909902610,"timestamp":"2024-06-01T22:43:27.894201Z"}]}
{"channel":"book","type":"update","data":[{"symbol":"LTC/GBP","bids":[{"price":65.41207,"qty":1.30000000}],"asks":[],"checksum":3906606090,"timestamp":"2024-06-01T22:43:27.894475Z"}]}
{"channel":"book","type":"update","data":[{"symbol":"LTC/GBP","bids":[{"price":65.40417,"qty":6.01117861}],"asks":[],"checksum":748280650,"timestamp":"2024-06-01T22:43:27.903571Z"}]}
{"channel":"book","type":"update","data":[{"symbol":"LTC/GBP","bids":[],"asks":[{"price":65.54742,"qty":0.00000000},{"price":65.84019,"qty":17.82430478}],"checksum":1047664657,"timestamp":"2024-06-01T22:43:27.915431Z"}]}
{"channel":"book","type":"update","data":[{"symbol":"LTC/GBP","bids":[{"price":65.40972,"qty":0.00000000},{"price":65.20835,"qty":43.84190449},{"price":65.41208,"qty":7.53588000}],"asks":[],"checksum":1344669609,"timestamp":"2024-06-01T22:43:27.926147Z"}]}
{"channel":"book","type":"update","data":[{"symbol":"LTC/GBP","bids":[{"price":65.41207,"qty":0.00000000},{"price":65.20835,"qty":43.84190449}],"asks":[],"checksum":544396585,"timestamp":"2024-06-01T22:43:27.928671Z"}]}
{"channel":"book","type":"update","data":[{"symbol":"LTC/GBP","bids":[{"price":65.41343,"qty":1.30000000}],"asks":[],"checksum":3256554662,"timestamp":"2024-06-01T22:43:27.928810Z"}]}
{"channel":"book","type":"update","data":[{"symbol":"LTC/GBP","bids":[],"asks":[{"price":65.45329,"qty":0.00000000},{"price":65.88469,"qty":0.29395882}],"checksum":1986779354,"timestamp":"2024-06-01T22:43:27.966270Z"}]}
{"channel":"book","type":"update","data":[{"symbol":"LTC/GBP","bids":[{"price":65.41208,"qty":0.00000000},{"price":65.20835,"qty":43.84190449},{"price":65.41344,"qty":7.53588000}],"asks":[],"checksum":1121046721,"timestamp":"2024-06-01T22:43:27.990122Z"}]}
{"channel":"book","type":"update","data":[{"symbol":"LTC/GBP","bids":[{"price":65.41343,"qty":0.00000000},{"price":65.20835,"qty":43.84190449}],"asks":[],"checksum":333958260,"timestamp":"2024-06-01T22:43:27.993140Z"}]}
