{"channel":"book","type":"snapshot","data":[{"symbol":"LTC/BTC","bids":[{"price":0.001231,"qty":35.13018683},{"price":0.001230,"qty":243.71086189},{"price":0.001229,"qty":228.79258704},{"price":0.001228,"qty":369.79399814},{"price":0.001227,"qty":549.67630821},{"price":0.001226,"qty":126.18400000},{"price":0.001225,"qty":22.98320816},{"price":0.001224,"qty":102.32784914},{"price":0.001223,"qty":61.98008208},{"price":0.001222,"qty":0.10050000}],"asks":[{"price":0.001232,"qty":103.29581060},{"price":0.001233,"qty":89.94396832},{"price":0.001234,"qty":217.11525928},{"price":0.001235,"qty":424.45278193},{"price":0.001236,"qty":34.30473375},{"price":0.001237,"qty":19.15050000},{"price":0.001238,"qty":130.12593096},{"price":0.001239,"qty":24.74633121},{"price":0.001240,"qty":92.61466181},{"price":0.001241,"qty":2.62540223}],"checksum":2453623811}]}
{"channel":"book","type":"update","data":[{"symbol":"LTC/BTC","bids":[],"asks":[{"price":0.001233,"qty":84.26744945}],"checksum":735932164,"timestamp":"2024-06-01T22:42:10.111057Z"}]}
{"channel":"book","type":"update","data":[{"symbol":"LTC/BTC","bids":[],"asks":[{"price":0.001233,"qty":89.94396832}],"checksum":2453623811,"timestamp":"2024-06-01T22:42:10.216508Z"}]}
{"channel":"book","type":"update","data":[{"symbol":"LTC/BTC","bids":[{"price":0.001223,"qty":63.97902877}],"asks":[],"checksum":476472210,"timestamp":"2024-06-01T22:42:10.334753Z"}]}
{"channel":"book","type":"update","data":[{"symbol":"LTC/BTC","bids":[{"price":0.001224,"qty":100.32984094}],"asks":[],"checksum":839163206,"timestamp":"2024-06-01T22:42:10.334994Z"}]}
{"channel":"book","type":"update","data":[{"symbol":"LTC/BTC","bids":[{"price":0.001224,"qty":89.34079579}],"asks":[],"checksum":3848509291,"timestamp":"2024-06-01T22:42:10.335081Z"}]}
{"channel":"book","type":"update","data":[{"symbol":"LTC/BTC","bids":[{"price":0.001223,"qty":74.97323555}],"asks":[],"checksum":2386670272,"timestamp":"2024-06-01T22:42:10.335268Z"}]}
{"channel":"book","type":"update","data":[{"symbol":"LTC/BTC","bids":[],"asks":[{"price":0.001233,"qty":88.53362352}],"checksum":832504907,"timestamp":"2024-06-01T22:42:10.484504Z"}]}
{"channel":"book","type":"update","data":[{"symbol":"LTC/BTC","bids":[],"asks":[{"price":0.001233,"qty":89.47580601}],"checksum":2101938085,"timestamp":"2024-06-01T22:42:10.485613Z"}]}
{"channel":"book","type":"update","data":[{"symbol":"LTC/BTC","bids":[],"asks":[{"price":0.001232,"qty":100.28581060}],"checksum":1263426903,"timestamp":"2024-06-01T22:42:10.920782Z"}]}
{"channel":"book","type":"update","data":[{"symbol":"LTC/BTC","bids":[],"asks":[{"price":0.001234,"qty":199.97661223}],"checksum":2554121762,"timestamp":"2024-06-01T22:42:11.001100Z"}]}
{"channel":"book","type":"update","data":[{"symbol":"LTC/BTC","bids":[],"asks":[{"price":0.001234,"qty":217.11525928}],"checksum":1263426903,"timestamp":"2024-06-01T22:42:11.107724Z"}]}
{"channel":"book","type":"update","data":[{"symbol":"LTC/BTC","bids":[{"price":0.001228,"qty":352.65535109}],"asks":[],"checksum":3943176862,"timestamp":"2024-06-01T22:42:11.746427Z"}]}
{"channel":"book","type":"update","data":[{"symbol":"LTC/BTC","bids":[{"price":0.001228,"qty":369.79399814}],"asks":[],"checksum":1263426903,"timestamp":"2024-06-01T22:42:11.852801Z"}]}
{"channel":"book","type":"update","data":[{"symbol":"LTC/BTC","bids":[{"price":0.001228,"qty":321.84410734}],"asks":[],"checksum":1901045725,"timestamp":"2024-06-01T22:42:12.045832Z"}]}
{"channel":"book","type":"update","data":[{"symbol":"LTC/BTC","bids":[{"price":0.001228,"qty":369.79466698}],"asks":[],"checksum":423847120,"timestamp":"2024-06-01T22:42:12.398729Z"}]}
{"channel":"book","type":"update","data":[{"symbol":"LTC/BTC","bids":[{"price":0.001228,"qty":321.84410734}],"asks":[],"checksum":1901045725,"timestamp":"2024-06-01T22:42:12.660506Z"}]}
{"channel":"book","type":"update","data":[{"symbol":"LTC/BTC","bids":[{"price":0.001228,"qty":369.79466719}],"asks":[],"checksum":2981626611,"timestamp":"2024-06-01T22:42:12.931354Z"}]}
{"channel":"book","type":"update","data":[{"symbol":"LTC/BTC","bids":[{"price":0.001228,"qty":321.84410734}],"asks":[],"checksum":1901045725,"timestamp":"2024-06-01T22:42:13.203299Z"}]}
{"channel":"book","type":"update","data":[{"symbol":"LTC/BTC","bids":[],"asks":[{"price":0.001233,"qty":88.53362352}],"checksum":1033479219,"timestamp":"2024-06-01T22:42:13.240868Z"}]}
{"channel":"book","type":"update","data":[{"symbol":"LTC/BTC","bids":[{"price":0.001228,"qty":369.79465089}],"asks":[],"checksum":1711526980,"timestamp":"2024-06-01T22:42:13.646833Z"}]}
{"channel":"book","type":"update","data":[{"symbol":"LTC/BTC","bids":[{"price":0.001228,"qty":321.84410734}],"asks":[],"checksum":1033479219,"timestamp":"2024-06-01T22:42:13.922072Z"}]}
{"channel":"book","type":"update","data":[{"symbol":"LTC/BTC","bids":[],"asks":[{"price":0.001232,"qty":98.56012694}],"checksum":1862459609,"timestamp":"2024-06-01T22:42:14.161017Z"}]}
{"channel":"book","type":"update","data":[{"symbol":"LTC/BTC","bids":[],"asks":[{"price":0.001234,"qty":218.84094294}],"checksum":2959630075,"timestamp":"2024-06-01T22:42:14.165255Z"}]}
{"channel":"book","type":"update","data":[{"symbol":"LTC/BTC","bids":[{"price":0.001228,"qty":369.79465563}],"asks":[],"checksum":817402825,"timestamp":"2024-06-01T22:42:14.175172Z"}]}
{"channel":"book","type":"update","data":[{"symbol":"LTC/BTC","bids":[{"price":0.001228,"qty":321.84410734}],"asks":[],"checksum":2959630075,"timestamp":"2024-06-01T22:42:14.463562Z"}]}
{"channel":"book","type":"update","data":[{"symbol":"LTC/BTC","bids":[{"price":0.001227,"qty":604.67630821}],"asks":[],"checksum":1569048542,"timestamp":"2024-06-01T22:42:14.478913Z"}]}
{"channel":"book","type":"update","data":[{"symbol":"LTC/BTC","bids":[{"price":0.001227,"qty":526.67630821}],"asks":[],"checksum":3458771784,"timestamp":"2024-06-01T22:42:14.479565Z"}]}
{"channel":"book","type":"update","data":[{"symbol":"LTC/BTC","bids":[{"price":0.001228,"qty":369.79464399}],"asks":[],"checksum":1974854545,"timestamp":"2024-06-01T22:42:14.918230Z"}]}
{"channel":"book","type":"update","data":[{"symbol":"LTC/BTC","bids":[{"price":0.001228,"qty":321.84410734}],"asks":[],"checksum":3458771784,"timestamp":"2024-06-01T22:42:15.201211Z"}]}
{"channel":"book","type":"update","data":[{"symbol":"LTC/BTC","bids":[{"price":0.001228,"qty":369.79460554}],"asks":[],"checksum":3681636158,"timestamp":"2024-06-01T22:42:15.451733Z"}]}
{"channel":"book","type":"update","data":[{"symbol":"LTC/BTC","bids":[{"price":0.001228,"qty":321.84410734}],"asks":[],"checksum":3458771784,"timestamp":"2024-06-01T22:42:15.709795Z"}]}
{"channel":"book","type":"update","data":[{"symbol":"LTC/BTC","bids":[],"asks":[{"price":0.001233,"qty":89.24172486}],"checksum":491803975,"timestamp":"2024-06-01T22:42:15.951021Z"}]}
{"channel":"book","type":"update","data":[{"symbol":"LTC/BTC","bids":[{"price":0.001228,"qty":369.79464574}],"asks":[],"checksum":1651832193,"timestamp":"2024-06-01T22:42:16.132821Z"}]}
{"channel":"book","type":"update","data":[{"symbol":"LTC/BTC","bids":[{"price":0.001228,"qty":321.84410734}],"asks":[],"checksum":491803975,"timestamp":"2024-06-01T22:42:16.385952Z"}]}
{"channel":"book","type":"update","data":[{"symbol":"LTC/BTC","bids":[{"price":0.001228,"qty":369.79464895}],"asks":[],"checksum":2517383464,"timestamp":"2024-06-01T22:42:16.642155Z"}]}
{"channel":"book","type":"update","data":[{"symbol":"LTC/BTC","bids":[{"price":0.001228,"qty":321.84410734}],"asks":[],"checksum":491803975,"timestamp":"2024-06-01T22:42:16.896192Z"}]}
{"channel":"book","type":"update","data":[{"symbol":"LTC/BTC","bids":[{"price":0.001228,"qty":369.79464896}],"asks":[],"checksum":2324585643,"timestamp":"2024-06-01T22:42:17.358047Z"}]}
{"channel":"book","type":"update","data":[{"symbol":"LTC/BTC","bids":[],"asks":[{"price":0.001237,"qty":21.14369710}],"checksum":1613787977,"timestamp":"2024-06-01T22:42:17.445762Z"}]}
{"channel":"book","type":"update","data":[{"symbol":"LTC/BTC","bids":[],"asks":[{"price":0.001239,"qty":4.84236483}],"checksum":3824478676,"timestamp":"2024-06-01T22:42:17.446286Z"}]}
{"channel":"book","type":"update","data":[{"symbol":"LTC/BTC","bids":[],"asks":[{"price":0.001238,"qty":128.13249475}],"checksum":785266785,"timestamp":"2024-06-01T22:42:17.446349Z"}]}
{"channel":"book","type":"update","data":[{"symbol":"LTC/BTC","bids":[],"asks":[{"price":0.001240,"qty":112.54663281}],"checksum":225736047,"timestamp":"2024-06-01T22:42:17.446497Z"}]}
{"channel":"book","type":"update","data":[{"symbol":"LTC/BTC","bids":[{"price":0.001228,"qty":321.84410734}],"asks":[],"checksum":2594864259,"timestamp":"2024-06-01T22:42:17.610702Z"}]}
{"channel":"book","type":"update","data":[{"symbol":"LTC/BTC","bids":[{"price":0.001228,"qty":369.79464896}],"asks":[],"checksum":225736047,"timestamp":"2024-06-01T22:42:17.872029Z"}]}
{"channel":"book","type":"update","data":[{"symbol":"LTC/BTC","bids":[{"price":0.001228,"qty":321.84410734}],"asks":[],"checksum":2594864259,"timestamp":"2024-06-01T22:42:18.153323Z"}]}
{"channel":"book","type":"update","data":[{"symbol":"LTC/BTC","bids":[{"price":0.001228,"qty":369.79464880}],"asks":[],"checksum":2932116483,"timestamp":"2024-06-01T22:42:18.693964Z"}]}
{"channel":"book","type":"update","data":[{"symbol":"LTC/BTC","bids":[{"price":0.001228,"qty":321.84410734}],"asks":[],"checksum":2594864259,"timestamp":"2024-06-01T22:42:18.983944Z"}]}
{"channel":"book","type":"update","data":[{"symbol":"LTC/BTC","bids":[{"price":0.001228,"qty":369.79464881}],"asks":[],"checksum":2772783234,"timestamp":"2024-06-01T22:42:19.239855Z"}]}
{"channel":"book","type":"update","data":[{"symbol":"LTC/BTC","bids":[{"price":0.001228,"qty":321.84410734}],"asks":[],"checksum":2594864259,"timestamp":"2024-06-01T22:42:19.496324Z"}]}
{"channel":"book","type":"update","data":[{"symbol":"LTC/BTC","bids":[{"price":0.001228,"qty":369.79464865}],"asks":[],"checksum":1822361006,"timestamp":"2024-06-01T22:42:19.907694Z"}]}
{"channel":"book","type":"update","data":[{"symbol":"LTC/BTC","bids":[{"price":0.001228,"qty":321.84410734}],"asks":[],"checksum":2594864259,"timestamp":"2024-06-01T22:42:20.155245Z"}]}
{"channel":"book","type":"update","data":[{"symbol":"LTC/BTC","bids":[{"price":0.001228,"qty":369.79463703}],"asks":[],"checksum":1480972529,"timestamp":"2024-06-01T22:42:20.402350Z"}]}
{"channel":"book","type":"update","data":[{"symbol":"LTC/BTC","bids":[{"price":0.001228,"qty":321.84410734}],"asks":[],"checksum":2594864259,"timestamp":"2024-06-01T22:42:20.648340Z"}]}
{"channel":"book","type":"update","data":[{"symbol":"LTC/BTC","bids":[{"price":0.001223,"qty":63.97902877}],"asks":[],"checksum":4052244776,"timestamp":"2024-06-01T22:42:20.838504Z"}]}
{"channel":"book","type":"update","data":[{"symbol":"LTC/BTC","bids":[{"price":0.001224,"qty":91.33974248}],"asks":[],"checksum":1460636525,"timestamp":"2024-06-01T22:42:20.838828Z"}]}
{"channel":"book","type":"update","data":[{"symbol":"LTC/BTC","bids":[{"price":0.001223,"qty":83.96849564}],"asks":[],"checksum":1360343698,"timestamp":"2024-06-01T22:42:20.839040Z"}]}
{"channel":"book","type":"update","data":[{"symbol":"LTC/BTC","bids":[{"price":0.001223,"qty":81.96954895}],"asks":[],"checksum":2741179243,"timestamp":"2024-06-01T22:42:20.839197Z"}]}
{"channel":"book","type":"update","data":[{"symbol":"LTC/BTC","bids":[{"price":0.001224,"qty":102.33394926}],"asks":[],"checksum":2442286045,"timestamp":"2024-06-01T22:42:20.839490Z"}]}
{"channel":"book","type":"update","data":[{"symbol":"LTC/BTC","bids":[{"price":0.001223,"qty":61.98946687}],"asks":[],"checksum":3732642723,"timestamp":"2024-06-01T22:42:20.839536Z"}]}
{"channel":"book","type":"update","data":[{"symbol":"LTC/BTC","bids":[{"price":0.001228,"qty":369.79464785}],"asks":[],"checksum":26358647,"timestamp":"2024-06-01T22:42:21.134847Z"}]}
{"channel":"book","type":"update","data":[{"symbol":"LTC/BTC","bids":[{"price":0.001228,"qty":321.84410734}],"asks":[],"checksum":3732642723,"timestamp":"2024-06-01T22:42:21.421984Z"}]}
{"channel":"book","type":"update","data":[{"symbol":"LTC/BTC","bids":[{"price":0.001228,"qty":369.79463781}],"asks":[],"checksum":3776313061,"timestamp":"2024-06-01T22:42:21.699039Z"}]}
{"channel":"book","type":"update","data":[{"symbol":"LTC/BTC","bids":[{"price":0.001228,"qty":321.84410734}],"asks":[],"checksum":3732642723,"timestamp":"2024-06-01T22:42:21.982343Z"}]}
{"channel":"book","type":"update","data":[{"symbol":"LTC/BTC","bids":[{"price":0.001228,"qty":369.79464785}],"asks":[],"checksum":26358647,"timestamp":"2024-06-01T22:42:22.315836Z"}]}
{"channel":"book","type":"update","data":[{"symbol":"LTC/BTC","bids":[{"price":0.001228,"qty":321.84410734}],"asks":[],"checksum":3732642723,"timestamp":"2024-06-01T22:42:22.605564Z"}]}
{"channel":"book","type":"update","data":[{"symbol":"LTC/BTC","bids":[{"price":0.001228,"qty":369.79463758}],"asks":[],"checksum":1828877657,"timestamp":"2024-06-01T22:42:22.884199Z"}]}
{"channel":"book","type":"update","data":[{"symbol":"LTC/BTC","bids":[{"price":0.001228,"qty":321.84410734}],"asks":[],"checksum":3732642723,"timestamp":"2024-06-01T22:42:23.130787Z"}]}
{"channel":"book","type":"update","data":[{"symbol":"LTC/BTC","bids":[{"price":0.001228,"qty":369.79463779}],"asks":[],"checksum":2000501146,"timestamp":"2024-06-01T22:42:23.548052Z"}]}
{"channel":"book","type":"update","data":[{"symbol":"LTC/BTC","bids":[{"price":0.001228,"qty":321.84410734}],"asks":[],"checksum":3732642723,"timestamp":"2024-06-01T22:42:23.832414Z"}]}
{"channel":"book","type":"update","data":[{"symbol":"LTC/BTC","bids":[{"price":0.001228,"qty":369.79461198}],"asks":[],"checksum":994906922,"timestamp":"2024-06-01T22:42:24.113479Z"}]}
{"channel":"book","type":"update","data":[{"symbol":"LTC/BTC","bids":[{"price":0.001228,"qty":321.84410734}],"asks":[],"checksum":3732642723,"timestamp":"2024-06-01T22:42:24.404902Z"}]}
{"channel":"book","type":"update","data":[{"symbol":"LTC/BTC","bids":[{"price":0.001228,"qty":369.79454120}],"asks":[],"checksum":2798036335,"timestamp":"2024-06-01T22:42:24.740552Z"}]}
{"channel":"book","type":"update","data":[{"symbol":"LTC/BTC","bids":[{"price":0.001228,"qty":321.84410734}],"asks":[],"checksum":3732642723,"timestamp":"2024-06-01T22:42:24.999079Z"}]}
{"channel":"book","type":"update","data":[{"symbol":"LTC/BTC","bids":[{"price":0.001228,"qty":369.79458484}],"asks":[],"checksum":1099978325,"timestamp":"2024-06-01T22:42:25.252852Z"}]}
{"channel":"book","type":"update","data":[{"symbol":"LTC/BTC","bids":[{"price":0.001228,"qty":321.84410734}],"asks":[],"checksum":3732642723,"timestamp":"2024-06-01T22:42:25.513314Z"}]}
{"channel":"book","type":"update","data":[{"symbol":"LTC/BTC","bids":[{"price":0.001228,"qty":369.79532292}],"asks":[],"checksum":2524451905,"timestamp":"2024-06-01T22:42:26.006864Z"}]}
{"channel":"book","type":"update","data":[{"symbol":"LTC/BTC","bids":[{"price":0.001228,"qty":321.84410734}],"asks":[],"checksum":3732642723,"timestamp":"2024-06-01T22:42:26.271450Z"}]}
{"channel":"book","type":"update","data":[{"symbol":"LTC/BTC","bids":[{"price":0.001228,"qty":369.79532293}],"asks":[],"checksum":214705707,"timestamp":"2024-06-01T22:42:26.532598Z"}]}
{"channel":"book","type":"update","data":[{"symbol":"LTC/BTC","bids":[{"price":0.001228,"qty":321.84410734}],"asks":[],"checksum":3732642723,"timestamp":"2024-06-01T22:42:26.791639Z"}]}
{"channel":"book","type":"update","data":[{"symbol":"LTC/BTC","bids":[{"price":0.001228,"qty":369.79528646}],"asks":[],"checksum":2969914018,"timestamp":"2024-06-01T22:42:27.250760Z"}]}
