{"channel":"book","type":"snapshot","data":[{"symbol":"LTC/EUR","bids":[{"price":76.86,"qty":59.40592152},{"price":76.85,"qty":6.25454919},{"price":76.84,"qty":59.97739636},{"price":76.83,"qty":11.19506000},{"price":76.82,"qty":232.88354632},{"price":76.81,"qty":171.23000243},{"price":76.80,"qty":62.87423434},{"price":76.79,"qty":125.92445062},{"price":76.78,"qty":47.94843290},{"price":76.77,"qty":78.87052265}],"asks":[{"price":76.88,"qty":10.61476643},{"price":76.89,"qty":82.56823471},{"price":76.90,"qty":133.95657179},{"price":76.91,"qty":2.92000000},{"price":76.92,"qty":59.91775455},{"price":76.93,"qty":77.74200000},{"price":76.94,"qty":47.95062428},{"price":76.96,"qty":2.44784509},{"price":76.97,"qty":113.13062968},{"price":76.98,"qty":59.96000000}],"checksum":4131485836}]}
{"channel":"book","type":"update","data":[{"symbol":"LTC/EUR","bids":[{"price":76.82,"qty":165.26354632},{"price":76.83,"qty":78.81506000}],"asks":[],"checksum":4149627015,"timestamp":"2024-06-01T22:42:09.736540Z"}]}
{"channel":"book","type":"update","data":[{"symbol":"LTC/EUR","bids":[{"price":76.83,"qty":11.19506000}],"asks":[],"checksum":4105983531,"timestamp":"2024-06-01T22:42:10.139544Z"}]}
{"channel":"book","type":"update","data":[{"symbol":"LTC/EUR","bids":[{"price":76.82,"qty":232.88354632}],"asks":[],"checksum":4131485836,"timestamp":"2024-06-01T22:42:10.432692Z"}]}
{"channel":"book","type":"update","data":[{"symbol":"LTC/EUR","bids":[{"price":76.77,"qty":75.46322724}],"asks":[],"checksum":3619821799,"timestamp":"2024-06-01T22:42:11.705366Z"}]}
{"channel":"book","type":"update","data":[{"symbol":"LTC/EUR","bids":[{"price":76.77,"qty":78.71564559}],"asks":[],"checksum":1499718344,"timestamp":"2024-06-01T22:42:11.709828Z"}]}
{"channel":"book","type":"update","data":[{"symbol":"LTC/EUR","bids":[],"asks":[{"price":76.88,"qty":0.61476643}],"checksum":1497322586,"timestamp":"2024-06-01T22:42:12.133945Z"}]}
{"channel":"book","type":"update","data":[{"symbol":"LTC/EUR","bids":[{"price":76.82,"qty":165.26354632},{"price":76.83,"qty":78.81506000}],"asks":[],"checksum":1479042129,"timestamp":"2024-06-01T22:42:12.320582Z"}]}
{"channel":"book","type":"update","data":[{"symbol":"LTC/EUR","bids":[{"price":76.83,"qty":11.19506000}],"asks":[],"checksum":1539472125,"timestamp":"2024-06-01T22:42:12.980307Z"}]}
{"channel":"book","type":"update","data":[{"symbol":"LTC/EUR","bids":[{"price":76.82,"qty":232.88354632}],"asks":[],"checksum":1497322586,"timestamp":"2024-06-01T22:42:14.192506Z"}]}
{"channel":"book","type":"update","data":[{"symbol":"LTC/EUR","bids":[{"price":76.82,"qty":172.89520441}],"asks":[],"checksum":2926131030,"timestamp":"2024-06-01T22:42:14.239289Z"}]}
{"channel":"book","type":"update","data":[{"symbol":"LTC/EUR","bids":[{"price":76.85,"qty":66.22508446}],"asks":[],"checksum":655409883,"timestamp":"2024-06-01T22:42:14.243077Z"}]}
{"channel":"book","type":"update","data":[{"symbol":"LTC/EUR","bids":[{"price":76.83,"qty":7.66900711}],"asks":[],"checksum":1468495602,"timestamp":"2024-06-01T22:42:14.246607Z"}]}
{"channel":"book","type":"update","data":[{"symbol":"LTC/EUR","bids":[{"price":76.77,"qty":75.46322724}],"asks":[],"checksum":3643182301,"timestamp":"2024-06-01T22:42:14.246620Z"}]}
{"channel":"book","type":"update","data":[{"symbol":"LTC/EUR","bids":[{"price":76.77,"qty":79.65109694}],"asks":[],"checksum":1323345087,"timestamp":"2024-06-01T22:42:14.251847Z"}]}
{"channel":"book","type":"update","data":[{"symbol":"LTC/EUR","bids":[{"price":76.83,"qty":10.72561516}],"asks":[],"checksum":2388254972,"timestamp":"2024-06-01T22:42:14.251968Z"}]}
{"channel":"book","type":"update","data":[{"symbol":"LTC/EUR","bids":[],"asks":[{"price":76.91,"qty":0.00000000},{"price":76.99,"qty":28.79253805}],"checksum":994185869,"timestamp":"2024-06-01T22:42:14.350952Z"}]}
{"channel":"book","type":"update","data":[{"symbol":"LTC/EUR","bids":[{"price":76.86,"qty":59.86047071}],"asks":[],"checksum":2194967973,"timestamp":"2024-06-01T22:42:14.434620Z"}]}
{"channel":"book","type":"update","data":[{"symbol":"LTC/EUR","bids":[{"price":76.85,"qty":65.77053527}],"asks":[],"checksum":3668904140,"timestamp":"2024-06-01T22:42:14.603097Z"}]}
{"channel":"book","type":"update","data":[{"symbol":"LTC/EUR","bids":[{"price":76.84,"qty":62.04739636}],"asks":[],"checksum":3405163061,"timestamp":"2024-06-01T22:42:14.930479Z"}]}
{"channel":"book","type":"update","data":[{"symbol":"LTC/EUR","bids":[{"price":76.82,"qty":105.27520441},{"price":76.83,"qty":78.34561516}],"asks":[],"checksum":3798058053,"timestamp":"2024-06-01T22:42:14.933906Z"}]}
{"channel":"book","type":"update","data":[{"symbol":"LTC/EUR","bids":[{"price":76.83,"qty":10.72561516}],"asks":[],"checksum":2335784283,"timestamp":"2024-06-01T22:42:15.418524Z"}]}
{"channel":"book","type":"update","data":[{"symbol":"LTC/EUR","bids":[{"price":76.83,"qty":34.57868028}],"asks":[],"checksum":2657459941,"timestamp":"2024-06-01T22:42:16.014810Z"}]}
{"channel":"book","type":"update","data":[{"symbol":"LTC/EUR","bids":[{"price":76.83,"qty":102.19868028}],"asks":[],"checksum":4055560842,"timestamp":"2024-06-01T22:42:16.457440Z"}]}
{"channel":"book","type":"update","data":[{"symbol":"LTC/EUR","bids":[{"price":76.82,"qty":81.42213929}],"asks":[],"checksum":1787723683,"timestamp":"2024-06-01T22:42:16.462114Z"}]}
{"channel":"book","type":"update","data":[{"symbol":"LTC/EUR","bids":[{"price":76.83,"qty":34.57868028}],"asks":[],"checksum":93712757,"timestamp":"2024-06-01T22:42:16.486648Z"}]}
{"channel":"book","type":"update","data":[{"symbol":"LTC/EUR","bids":[{"price":76.83,"qty":31.52207223}],"asks":[],"checksum":2615405961,"timestamp":"2024-06-01T22:42:16.732913Z"}]}
{"channel":"book","type":"update","data":[{"symbol":"LTC/EUR","bids":[{"price":76.77,"qty":75.46322724}],"asks":[],"checksum":203802091,"timestamp":"2024-06-01T22:42:16.733215Z"}]}
{"channel":"book","type":"update","data":[{"symbol":"LTC/EUR","bids":[{"price":76.78,"qty":51.94393062}],"asks":[],"checksum":2546179997,"timestamp":"2024-06-01T22:42:16.738352Z"}]}
{"channel":"book","type":"update","data":[{"symbol":"LTC/EUR","bids":[{"price":76.83,"qty":34.10923545}],"asks":[],"checksum":475561567,"timestamp":"2024-06-01T22:42:16.738393Z"}]}
{"channel":"book","type":"update","data":[{"symbol":"LTC/EUR","bids":[{"price":76.77,"qty":75.81437304}],"asks":[],"checksum":2899605242,"timestamp":"2024-06-01T22:42:16.738405Z"}]}
{"channel":"book","type":"update","data":[{"symbol":"LTC/EUR","bids":[{"price":76.82,"qty":149.04213929}],"asks":[],"checksum":3026859620,"timestamp":"2024-06-01T22:42:19.127130Z"}]}
{"channel":"book","type":"update","data":[{"symbol":"LTC/EUR","bids":[{"price":76.77,"qty":75.46322724}],"asks":[],"checksum":82198209,"timestamp":"2024-06-01T22:42:19.179763Z"}]}
{"channel":"book","type":"update","data":[{"symbol":"LTC/EUR","bids":[{"price":76.83,"qty":31.52207223}],"asks":[],"checksum":1896285884,"timestamp":"2024-06-01T22:42:19.179854Z"}]}
{"channel":"book","type":"update","data":[{"symbol":"LTC/EUR","bids":[{"price":76.83,"qty":33.95275384}],"asks":[],"checksum":3749078636,"timestamp":"2024-06-01T22:42:19.186504Z"}]}
{"channel":"book","type":"update","data":[{"symbol":"LTC/EUR","bids":[{"price":76.77,"qty":77.67198093}],"asks":[],"checksum":950560944,"timestamp":"2024-06-01T22:42:19.187159Z"}]}
{"channel":"book","type":"update","data":[{"symbol":"LTC/EUR","bids":[{"price":76.82,"qty":81.42213929},{"price":76.83,"qty":101.57275384}],"asks":[],"checksum":359533554,"timestamp":"2024-06-01T22:42:20.455425Z"}]}
{"channel":"book","type":"update","data":[{"symbol":"LTC/EUR","bids":[{"price":76.83,"qty":33.95275384}],"asks":[],"checksum":3491171241,"timestamp":"2024-06-01T22:42:21.258950Z"}]}
{"channel":"book","type":"update","data":[{"symbol":"LTC/EUR","bids":[{"price":76.87,"qty":9.39516496}],"asks":[],"checksum":1710172886,"timestamp":"2024-06-01T22:42:23.569395Z"}]}
{"channel":"book","type":"update","data":[{"symbol":"LTC/EUR","bids":[{"price":76.78,"qty":47.94843290}],"asks":[],"checksum":24290717,"timestamp":"2024-06-01T22:42:24.285631Z"}]}
{"channel":"book","type":"update","data":[{"symbol":"LTC/EUR","bids":[{"price":76.83,"qty":31.52207223}],"asks":[],"checksum":2564471958,"timestamp":"2024-06-01T22:42:24.285784Z"}]}
{"channel":"book","type":"update","data":[{"symbol":"LTC/EUR","bids":[{"price":76.83,"qty":99.14207223}],"asks":[],"checksum":3888525273,"timestamp":"2024-06-01T22:42:24.289294Z"}]}
{"channel":"book","type":"update","data":[{"symbol":"LTC/EUR","bids":[],"asks":[{"price":76.89,"qty":83.18300114}],"checksum":1140300737,"timestamp":"2024-06-01T22:42:24.465970Z"}]}
{"channel":"book","type":"update","data":[{"symbol":"LTC/EUR","bids":[{"price":76.81,"qty":111.23155181}],"asks":[],"checksum":3870313004,"timestamp":"2024-06-01T22:42:24.503900Z"}]}
{"channel":"book","type":"update","data":[{"symbol":"LTC/EUR","bids":[],"asks":[{"price":76.88,"qty":0.00000000},{"price":77.00,"qty":35.75888501}],"checksum":3021274700,"timestamp":"2024-06-01T22:42:24.631353Z"}]}
{"channel":"book","type":"update","data":[{"symbol":"LTC/EUR","bids":[],"asks":[{"price":76.90,"qty":114.08662930}],"checksum":1635492749,"timestamp":"2024-06-01T22:42:24.634841Z"}]}
{"channel":"book","type":"update","data":[{"symbol":"LTC/EUR","bids":[],"asks":[{"price":76.90,"qty":130.94055796}],"checksum":549868796,"timestamp":"2024-06-01T22:42:24.638409Z"}]}
{"channel":"book","type":"update","data":[{"symbol":"LTC/EUR","bids":[{"price":76.83,"qty":31.52207223}],"asks":[],"checksum":1608173491,"timestamp":"2024-06-01T22:42:24.725221Z"}]}
{"channel":"book","type":"update","data":[{"symbol":"LTC/EUR","bids":[{"price":76.81,"qty":171.22476897}],"asks":[],"checksum":1896601223,"timestamp":"2024-06-01T22:42:24.884549Z"}]}
{"channel":"book","type":"update","data":[{"symbol":"LTC/EUR","bids":[{"price":76.81,"qty":111.23155181}],"asks":[],"checksum":1608173491,"timestamp":"2024-06-01T22:42:24.994288Z"}]}
{"channel":"book","type":"update","data":[{"symbol":"LTC/EUR","bids":[{"price":76.81,"qty":171.22476897}],"asks":[],"checksum":1896601223,"timestamp":"2024-06-01T22:42:25.709063Z"}]}
{"channel":"book","type":"update","data":[{"symbol":"LTC/EUR","bids":[{"price":76.83,"qty":99.14207223}],"asks":[],"checksum":236406216,"timestamp":"2024-06-01T22:42:25.712221Z"}]}
{"channel":"book","type":"update","data":[{"symbol":"LTC/EUR","bids":[{"price":76.87,"qty":0.00000000},{"price":76.77,"qty":75.46322724}],"asks":[],"checksum":2203162667,"timestamp":"2024-06-01T22:42:25.745279Z"}]}
{"channel":"book","type":"update","data":[{"symbol":"LTC/EUR","bids":[{"price":76.87,"qty":9.39516496}],"asks":[],"checksum":236406216,"timestamp":"2024-06-01T22:42:26.231782Z"}]}
{"channel":"book","type":"update","data":[{"symbol":"LTC/EUR","bids":[{"price":76.83,"qty":31.52207223}],"asks":[],"checksum":1896601223,"timestamp":"2024-06-01T22:42:26.490511Z"}]}
{"channel":"book","type":"update","data":[{"symbol":"LTC/EUR","bids":[{"price":76.82,"qty":82.60352121}],"asks":[],"checksum":1884693305,"timestamp":"2024-06-01T22:42:26.930588Z"}]}
{"channel":"book","type":"update","data":[{"symbol":"LTC/EUR","bids":[{"price":76.82,"qty":150.22352121}],"asks":[],"checksum":3443501237,"timestamp":"2024-06-01T22:42:26.934276Z"}]}
{"channel":"book","type":"update","data":[{"symbol":"LTC/EUR","bids":[{"price":76.82,"qty":82.60352121}],"asks":[],"checksum":1884693305,"timestamp":"2024-06-01T22:42:26.980074Z"}]}
{"channel":"book","type":"update","data":[{"symbol":"LTC/EUR","bids":[{"price":76.87,"qty":0.00000000},{"price":76.77,"qty":82.03064529}],"asks":[],"checksum":3063191147,"timestamp":"2024-06-01T22:42:28.392107Z"}]}
{"channel":"book","type":"update","data":[{"symbol":"LTC/EUR","bids":[{"price":76.82,"qty":150.22352121}],"asks":[],"checksum":3459767337,"timestamp":"2024-06-01T22:42:28.395471Z"}]}
{"channel":"book","type":"update","data":[{"symbol":"LTC/EUR","bids":[{"price":76.87,"qty":9.39516496}],"asks":[],"checksum":3443501237,"timestamp":"2024-06-01T22:42:28.863976Z"}]}
{"channel":"book","type":"update","data":[{"symbol":"LTC/EUR","bids":[{"price":76.82,"qty":82.60352121},{"price":76.83,"qty":99.14207223}],"asks":[],"checksum":256553078,"timestamp":"2024-06-01T22:42:29.125417Z"}]}
{"channel":"book","type":"update","data":[{"symbol":"LTC/EUR","bids":[{"price":76.82,"qty":81.42213929}],"asks":[],"checksum":236406216,"timestamp":"2024-06-01T22:42:29.399471Z"}]}
{"channel":"book","type":"update","data":[{"symbol":"LTC/EUR","bids":[{"price":76.83,"qty":101.17850903}],"asks":[],"checksum":2961833150,"timestamp":"2024-06-01T22:42:29.404099Z"}]}
{"channel":"book","type":"update","data":[{"symbol":"LTC/EUR","bids":[{"price":76.87,"qty":0.00000000},{"price":76.77,"qty":80.96990326}],"asks":[],"checksum":1003976116,"timestamp":"2024-06-01T22:42:31.017525Z"}]}
{"channel":"book","type":"update","data":[{"symbol":"LTC/EUR","bids":[{"price":76.83,"qty":33.55850903}],"asks":[],"checksum":3378657122,"timestamp":"2024-06-01T22:42:31.257660Z"}]}
{"channel":"book","type":"update","data":[{"symbol":"LTC/EUR","bids":[{"price":76.87,"qty":9.39516496}],"asks":[],"checksum":170724229,"timestamp":"2024-06-01T22:42:31.522561Z"}]}
{"channel":"book","type":"update","data":[{"symbol":"LTC/EUR","bids":[{"price":76.83,"qty":101.17850903}],"asks":[],"checksum":2961833150,"timestamp":"2024-06-01T22:42:31.525794Z"}]}
{"channel":"book","type":"update","data":[{"symbol":"LTC/EUR","bids":[{"price":76.83,"qty":99.14207223}],"asks":[],"checksum":236406216,"timestamp":"2024-06-01T22:42:31.939010Z"}]}
{"channel":"book","type":"update","data":[{"symbol":"LTC/EUR","bids":[{"price":76.83,"qty":99.51933937}],"asks":[],"checksum":2403975797,"timestamp":"2024-06-01T22:42:31.944089Z"}]}
{"channel":"book","type":"update","data":[{"symbol":"LTC/EUR","bids":[{"price":76.82,"qty":83.30976735}],"asks":[],"checksum":2787737990,"timestamp":"2024-06-01T22:42:31.944225Z"}]}
{"channel":"book","type":"update","data":[{"symbol":"LTC/EUR","bids":[{"price":76.83,"qty":31.89933937}],"asks":[],"checksum":1964035992,"timestamp":"2024-06-01T22:42:33.395785Z"}]}
{"channel":"book","type":"update","data":[{"symbol":"LTC/EUR","bids":[{"price":76.87,"qty":0.00000000},{"price":76.77,"qty":81.63800877}],"asks":[],"checksum":2116192014,"timestamp":"2024-06-01T22:42:33.681654Z"}]}
{"channel":"book","type":"update","data":[{"symbol":"LTC/EUR","bids":[{"price":76.83,"qty":99.51933937}],"asks":[],"checksum":2338189782,"timestamp":"2024-06-01T22:42:33.685116Z"}]}
{"channel":"book","type":"update","data":[{"symbol":"LTC/EUR","bids":[{"price":76.87,"qty":9.39516496}],"asks":[],"checksum":2787737990,"timestamp":"2024-06-01T22:42:34.206399Z"}]}
{"channel":"book","type":"update","data":[{"symbol":"LTC/EUR","bids":[{"price":76.83,"qty":99.14207223}],"asks":[],"checksum":662111803,"timestamp":"2024-06-01T22:42:34.574382Z"}]}
{"channel":"book","type":"update","data":[{"symbol":"LTC/EUR","bids":[{"price":76.82,"qty":81.42213929}],"asks":[],"checksum":236406216,"timestamp":"2024-06-01T22:42:34.574734Z"}]}
{"channel":"book","type":"update","data":[{"symbol":"LTC/EUR","bids":[{"price":76.82,"qty":82.75757518}],"asks":[],"checksum":3344717990,"timestamp":"2024-06-01T22:42:34.579521Z"}]}
{"channel":"book","type":"update","data":[{"symbol":"LTC/EUR","bids":[{"price":76.78,"qty":49.90985410}],"asks":[],"checksum":474099941,"timestamp":"2024-06-01T22:42:34.579604Z"}]}
{"channel":"book","type":"update","data":[{"symbol":"LTC/EUR","bids":[],"asks":[{"price":77.00,"qty":32.77128501}],"checksum":1931501438,"timestamp":"2024-06-01T22:42:34.953665Z"}]}
{"channel":"book","type":"update","data":[{"symbol":"LTC/EUR","bids":[],"asks":[{"price":77.00,"qty":35.67698501}],"checksum":119855343,"timestamp":"2024-06-01T22:42:35.005546Z"}]}
{"channel":"book","type":"update","data":[{"symbol":"LTC/EUR","bids":[{"price":76.83,"qty":31.52207223}],"asks":[],"checksum":2016955296,"timestamp":"2024-06-01T22:42:35.501551Z"}]}
{"channel":"book","type":"update","data":[{"symbol":"LTC/EUR","bids":[{"price":76.82,"qty":150.37757518}],"asks":[],"checksum":1056548816,"timestamp":"2024-06-01T22:42:35.803845Z"}]}
{"channel":"book","type":"update","data":[{"symbol":"LTC/EUR","bids":[{"price":76.82,"qty":82.75757518},{"price":76.83,"qty":99.14207223}],"asks":[],"checksum":119855343,"timestamp":"2024-06-01T22:42:36.312446Z"}]}
{"channel":"book","type":"update","data":[{"symbol":"LTC/EUR","bids":[],"asks":[{"price":76.91,"qty":23.85306512}],"checksum":1115951542,"timestamp":"2024-06-01T22:42:36.319042Z"}]}
{"channel":"book","type":"update","data":[{"symbol":"LTC/EUR","bids":[],"asks":[{"price":76.90,"qty":107.08749284}],"checksum":2441199919,"timestamp":"2024-06-01T22:42:36.319062Z"}]}
{"channel":"book","type":"update","data":[{"symbol":"LTC/EUR","bids":[{"price":76.83,"qty":31.52207223}],"asks":[],"checksum":4003287648,"timestamp":"2024-06-01T22:42:36.334723Z"}]}
{"channel":"book","type":"update","data":[{"symbol":"LTC/EUR","bids":[{"price":76.87,"qty":0.00000000},{"price":76.77,"qty":75.59545485}],"asks":[],"checksum":3702158604,"timestamp":"2024-06-01T22:42:36.364142Z"}]}
{"channel":"book","type":"update","data":[{"symbol":"LTC/EUR","bids":[{"price":76.87,"qty":9.39516496}],"asks":[],"checksum":4003287648,"timestamp":"2024-06-01T22:42:36.950532Z"}]}
{"channel":"book","type":"update","data":[{"symbol":"LTC/EUR","bids":[{"price":76.83,"qty":99.14207223}],"asks":[],"checksum":2441199919,"timestamp":"2024-06-01T22:42:36.953812Z"}]}
{"channel":"book","type":"update","data":[{"symbol":"LTC/EUR","bids":[{"price":76.78,"qty":47.94843290}],"asks":[],"checksum":1251977580,"timestamp":"2024-06-01T22:42:37.001496Z"}]}
{"channel":"book","type":"update","data":[{"symbol":"LTC/EUR","bids":[{"price":76.82,"qty":81.42213929}],"asks":[],"checksum":2211755010,"timestamp":"2024-06-01T22:42:37.001641Z"}]}
{"channel":"book","type":"update","data":[{"symbol":"LTC/EUR","bids":[{"price":76.82,"qty":83.69633928}],"asks":[],"checksum":3466805198,"timestamp":"2024-06-01T22:42:37.006837Z"}]}
{"channel":"book","type":"update","data":[{"symbol":"LTC/EUR","bids":[{"price":76.83,"qty":101.25979061}],"asks":[],"checksum":3465759645,"timestamp":"2024-06-01T22:42:37.006902Z"}]}
{"channel":"book","type":"update","data":[{"symbol":"LTC/EUR","bids":[{"price":76.83,"qty":33.63979061}],"asks":[],"checksum":1985773110,"timestamp":"2024-06-01T22:42:37.146821Z"}]}
{"channel":"book","type":"update","data":[{"symbol":"LTC/EUR","bids":[{"price":76.87,"qty":0.00000000},{"price":76.77,"qty":79.41554168}],"asks":[],"checksum":4163298215,"timestamp":"2024-06-01T22:42:39.110296Z"}]}
{"channel":"book","type":"update","data":[{"symbol":"LTC/EUR","bids":[{"price":76.83,"qty":101.25979061}],"asks":[],"checksum":373905286,"timestamp":"2024-06-01T22:42:39.113443Z"}]}
{"channel":"book","type":"update","data":[{"symbol":"LTC/EUR","bids":[{"price":76.87,"qty":9.39516496}],"asks":[],"checksum":3465759645,"timestamp":"2024-06-01T22:42:39.565593Z"}]}
{"channel":"book","type":"update","data":[{"symbol":"LTC/EUR","bids":[{"price":76.83,"qty":33.63979061}],"asks":[],"checksum":1985773110,"timestamp":"2024-06-01T22:42:39.697268Z"}]}
{"channel":"book","type":"update","data":[{"symbol":"LTC/EUR","bids":[{"price":76.82,"qty":81.42213929}],"asks":[],"checksum":992736762,"timestamp":"2024-06-01T22:42:39.708015Z"}]}
{"channel":"book","type":"update","data":[{"symbol":"LTC/EUR","bids":[{"price":76.83,"qty":31.52207223}],"asks":[],"checksum":4240975693,"timestamp":"2024-06-01T22:42:39.708253Z"}]}
{"channel":"book","type":"update","data":[{"symbol":"LTC/EUR","bids":[{"price":76.84,"qty":62.75678023}],"asks":[],"checksum":2918013368,"timestamp":"2024-06-01T22:42:39.715026Z"}]}
{"channel":"book","type":"update","data":[{"symbol":"LTC/EUR","bids":[{"price":76.83,"qty":33.32682739}],"asks":[],"checksum":2785161407,"timestamp":"2024-06-01T22:42:39.715077Z"}]}
{"channel":"book","type":"update","data":[{"symbol":"LTC/EUR","bids":[{"price":76.80,"qty":67.45924688}],"asks":[],"checksum":2883883973,"timestamp":"2024-06-01T22:42:39.715302Z"}]}
{"channel":"book","type":"update","data":[{"symbol":"LTC/EUR","bids":[{"price":76.87,"qty":0.00000000},{"price":76.77,"qty":75.31372724}],"asks":[],"checksum":3197333371,"timestamp":"2024-06-01T22:42:41.734651Z"}]}
{"channel":"book","type":"update","data":[{"symbol":"LTC/EUR","bids":[],"asks":[{"price":76.90,"qty":90.23356418}],"checksum":1990710427,"timestamp":"2024-06-01T22:42:41.737927Z"}]}
{"channel":"book","type":"update","data":[{"symbol":"LTC/EUR","bids":[{"price":76.83,"qty":100.94682739}],"asks":[],"checksum":1168709332,"timestamp":"2024-06-01T22:42:41.737975Z"}]}
{"channel":"book","type":"update","data":[{"symbol":"LTC/EUR","bids":[],"asks":[{"price":76.90,"qty":106.11174284}],"checksum":2254869557,"timestamp":"2024-06-01T22:42:41.741351Z"}]}
{"channel":"book","type":"update","data":[{"symbol":"LTC/EUR","bids":[{"price":76.83,"qty":33.32682739}],"asks":[],"checksum":3047920742,"timestamp":"2024-06-01T22:42:41.769641Z"}]}
{"channel":"book","type":"update","data":[{"symbol":"LTC/EUR","bids":[{"price":76.84,"qty":62.04739636}],"asks":[],"checksum":564426900,"timestamp":"2024-06-01T22:42:42.077575Z"}]}
{"channel":"book","type":"update","data":[{"symbol":"LTC/EUR","bids":[{"price":76.83,"qty":31.52207223}],"asks":[],"checksum":3559856447,"timestamp":"2024-06-01T22:42:42.077660Z"}]}
{"channel":"book","type":"update","data":[{"symbol":"LTC/EUR","bids":[{"price":76.80,"qty":62.87423434}],"asks":[],"checksum":781556162,"timestamp":"2024-06-01T22:42:42.077889Z"}]}
{"channel":"book","type":"update","data":[{"symbol":"LTC/EUR","bids":[{"price":76.83,"qty":33.79627222}],"asks":[],"checksum":2378351307,"timestamp":"2024-06-01T22:42:42.083745Z"}]}
{"channel":"book","type":"update","data":[{"symbol":"LTC/EUR","bids":[{"price":76.78,"qty":51.63096740}],"asks":[],"checksum":3888038449,"timestamp":"2024-06-01T22:42:42.083799Z"}]}
{"channel":"book","type":"update","data":[{"symbol":"LTC/EUR","bids":[{"price":76.77,"qty":76.13554039}],"asks":[],"checksum":3768474744,"timestamp":"2024-06-01T22:42:42.084132Z"}]}
{"channel":"book","type":"update","data":[{"symbol":"LTC/EUR","bids":[{"price":76.87,"qty":9.39516496}],"asks":[],"checksum":3982032965,"timestamp":"2024-06-01T22:42:42.527462Z"}]}
{"channel":"book","type":"update","data":[{"symbol":"LTC/EUR","bids":[{"price":76.82,"qty":149.04213929}],"asks":[],"checksum":3004457142,"timestamp":"2024-06-01T22:42:43.903243Z"}]}
{"channel":"book","type":"update","data":[{"symbol":"LTC/EUR","bids":[{"price":76.83,"qty":31.52207223}],"asks":[],"checksum":3617413721,"timestamp":"2024-06-01T22:42:44.597133Z"}]}
{"channel":"book","type":"update","data":[{"symbol":"LTC/EUR","bids":[{"price":76.78,"qty":47.94843290}],"asks":[],"checksum":3350883975,"timestamp":"2024-06-01T22:42:44.597517Z"}]}
{"channel":"book","type":"update","data":[{"symbol":"LTC/EUR","bids":[{"price":76.82,"qty":81.42213929},{"price":76.83,"qty":99.14207223}],"asks":[],"checksum":1626376397,"timestamp":"2024-06-01T22:42:44.600687Z"}]}
{"channel":"book","type":"update","data":[{"symbol":"LTC/EUR","bids":[{"price":76.83,"qty":101.72923545}],"asks":[],"checksum":360135526,"timestamp":"2024-06-01T22:42:44.602039Z"}]}
{"channel":"book","type":"update","data":[{"symbol":"LTC/EUR","bids":[{"price":76.78,"qty":51.98532230}],"asks":[],"checksum":48366471,"timestamp":"2024-06-01T22:42:44.602049Z"}]}
{"channel":"book","type":"update","data":[{"symbol":"LTC/EUR","bids":[{"price":76.87,"qty":0.00000000},{"price":76.77,"qty":75.31372724}],"asks":[],"checksum":593254705,"timestamp":"2024-06-01T22:42:44.700047Z"}]}
{"channel":"book","type":"update","data":[{"symbol":"LTC/EUR","bids":[{"price":76.87,"qty":9.39516496}],"asks":[],"checksum":48366471,"timestamp":"2024-06-01T22:42:45.319420Z"}]}
{"channel":"book","type":"update","data":[{"symbol":"LTC/EUR","bids":[{"price":76.83,"qty":34.10923545}],"asks":[],"checksum":1155421385,"timestamp":"2024-06-01T22:42:45.974621Z"}]}
{"channel":"book","type":"update","data":[{"symbol":"LTC/EUR","bids":[{"price":76.78,"qty":47.94843290}],"asks":[],"checksum":1397451816,"timestamp":"2024-06-01T22:42:47.148276Z"}]}
{"channel":"book","type":"update","data":[{"symbol":"LTC/EUR","bids":[{"price":76.83,"qty":31.52207223}],"asks":[],"checksum":535567234,"timestamp":"2024-06-01T22:42:47.148292Z"}]}
{"channel":"book","type":"update","data":[{"symbol":"LTC/EUR","bids":[{"price":76.83,"qty":33.79627222}],"asks":[],"checksum":4252906651,"timestamp":"2024-06-01T22:42:47.151855Z"}]}
{"channel":"book","type":"update","data":[{"symbol":"LTC/EUR","bids":[{"price":76.78,"qty":51.78744901}],"asks":[],"checksum":1973268539,"timestamp":"2024-06-01T22:42:47.152155Z"}]}
{"channel":"book","type":"update","data":[{"symbol":"LTC/EUR","bids":[{"price":76.83,"qty":101.41627222}],"asks":[],"checksum":545656773,"timestamp":"2024-06-01T22:42:47.155364Z"}]}
{"channel":"book","type":"update","data":[{"symbol":"LTC/EUR","bids":[{"price":76.87,"qty":0.00000000},{"price":76.77,"qty":76.44346075}],"asks":[],"checksum":1243125597,"timestamp":"2024-06-01T22:42:47.474945Z"}]}
{"channel":"book","type":"update","data":[{"symbol":"LTC/EUR","bids":[],"asks":[{"price":76.94,"qty":0.00000000},{"price":77.00,"qty":35.60978501}],"checksum":1778517860,"timestamp":"2024-06-01T22:42:47.788559Z"}]}
{"channel":"book","type":"update","data":[{"symbol":"LTC/EUR","bids":[],"asks":[{"price":76.92,"qty":107.86930989}],"checksum":3257338479,"timestamp":"2024-06-01T22:42:48.041861Z"}]}
{"channel":"book","type":"update","data":[{"symbol":"LTC/EUR","bids":[{"price":76.87,"qty":9.39516496}],"asks":[],"checksum":390191901,"timestamp":"2024-06-01T22:42:48.058585Z"}]}
{"channel":"book","type":"update","data":[{"symbol":"LTC/EUR","bids":[],"asks":[{"price":76.92,"qty":59.91775455}],"checksum":1435731376,"timestamp":"2024-06-01T22:42:49.471462Z"}]}
{"channel":"book","type":"update","data":[{"symbol":"LTC/EUR","bids":[{"price":76.78,"qty":47.94843290}],"asks":[],"checksum":3715105040,"timestamp":"2024-06-01T22:42:49.712679Z"}]}
{"channel":"book","type":"update","data":[{"symbol":"LTC/EUR","bids":[{"price":76.83,"qty":99.14207223}],"asks":[],"checksum":534339855,"timestamp":"2024-06-01T22:42:49.712709Z"}]}
{"channel":"book","type":"update","data":[{"symbol":"LTC/EUR","bids":[{"price":76.82,"qty":82.60107885}],"asks":[],"checksum":3834391782,"timestamp":"2024-06-01T22:42:49.717529Z"}]}
{"channel":"book","type":"update","data":[{"symbol":"LTC/EUR","bids":[],"asks":[{"price":76.94,"qty":47.95047125}],"checksum":2959409402,"timestamp":"2024-06-01T22:42:49.742823Z"}]}
{"channel":"book","type":"update","data":[{"symbol":"LTC/EUR","bids":[{"price":76.83,"qty":31.52207223}],"asks":[],"checksum":3480851381,"timestamp":"2024-06-01T22:42:50.134784Z"}]}
{"channel":"book","type":"update","data":[{"symbol":"LTC/EUR","bids":[{"price":76.87,"qty":0.00000000},{"price":76.77,"qty":80.30693817}],"asks":[],"checksum":3915652411,"timestamp":"2024-06-01T22:42:50.222980Z"}]}
{"channel":"book","type":"update","data":[{"symbol":"LTC/EUR","bids":[{"price":76.83,"qty":99.14207223}],"asks":[],"checksum":858175351,"timestamp":"2024-06-01T22:42:50.226146Z"}]}
{"channel":"book","type":"update","data":[{"symbol":"LTC/EUR","bids":[{"price":76.87,"qty":9.39516496}],"asks":[],"checksum":2959409402,"timestamp":"2024-06-01T22:42:50.682568Z"}]}
