{"channel":"book","type":"snapshot","data":[{"symbol":"LTC/USD","bids":[{"price":83.37,"qty":39.84856706},{"price":83.36,"qty":97.21449757},{"price":83.35,"qty":37.52624309},{"price":83.33,"qty":70.39239888},{"price":83.32,"qty":95.75737934},{"price":83.31,"qty":168.35317763},{"price":83.30,"qty":261.33361137},{"price":83.28,"qty":124.34812701},{"price":83.27,"qty":203.20930600},{"price":83.26,"qty":60.04681310}],"asks":[{"price":83.38,"qty":15.10000000},{"price":83.39,"qty":54.06694032},{"price":83.40,"qty":18.85092058},{"price":83.41,"qty":79.94984382},{"price":83.42,"qty":24.74994697},{"price":83.43,"qty":45.62849585},{"price":83.44,"qty":191.45297347},{"price":83.45,"qty":102.59398439},{"price":83.46,"qty":0.17336383},{"price":83.47,"qty":76.11736323}],"checksum":693285292}]}
{"channel":"book","type":"update","data":[{"symbol":"LTC/USD","bids":[{"price":83.35,"qty":40.39624309}],"asks":[],"checksum":3878802065,"timestamp":"2024-06-01T22:42:15.208988Z"}]}
{"channel":"book","type":"update","data":[{"symbol":"LTC/USD","bids":[],"asks":[{"price":83.43,"qty":47.89849585}],"checksum":3004198354,"timestamp":"2024-06-01T22:42:15.321295Z"}]}
{"channel":"book","type":"update","data":[{"symbol":"LTC/USD","bids":[{"price":83.33,"qty":62.84239888}],"asks":[],"checksum":1730958154,"timestamp":"2024-06-01T22:42:15.386523Z"}]}
{"channel":"book","type":"update","data":[{"symbol":"LTC/USD","bids":[{"price":83.32,"qty":88.20737934}],"asks":[],"checksum":1256354654,"timestamp":"2024-06-01T22:42:15.387748Z"}]}
{"channel":"book","type":"update","data":[{"symbol":"LTC/USD","bids":[{"price":83.31,"qty":108.41317763}],"asks":[],"checksum":832467874,"timestamp":"2024-06-01T22:42:15.418440Z"}]}
{"channel":"book","type":"update","data":[{"symbol":"LTC/USD","bids":[{"price":83.33,"qty":70.39239888},{"price":83.32,"qty":95.75737934}],"asks":[],"checksum":3362549038,"timestamp":"2024-06-01T22:42:15.675756Z"}]}
{"channel":"book","type":"update","data":[{"symbol":"LTC/USD","bids":[],"asks":[{"price":83.43,"qty":46.97680131}],"checksum":3378177396,"timestamp":"2024-06-01T22:42:15.950153Z"}]}
{"channel":"book","type":"update","data":[{"symbol":"LTC/USD","bids":[],"asks":[{"price":83.43,"qty":48.44566640}],"checksum":2389926847,"timestamp":"2024-06-01T22:42:15.950889Z"}]}
{"channel":"book","type":"update","data":[{"symbol":"LTC/USD","bids":[{"price":83.30,"qty":321.27361137}],"asks":[],"checksum":1563642036,"timestamp":"2024-06-01T22:42:15.952966Z"}]}
{"channel":"book","type":"update","data":[{"symbol":"LTC/USD","bids":[],"asks":[{"price":83.42,"qty":24.13798570}],"checksum":1633320352,"timestamp":"2024-06-01T22:42:15.953198Z"}]}
{"channel":"book","type":"update","data":[{"symbol":"LTC/USD","bids":[],"asks":[{"price":83.42,"qty":25.66968305}],"checksum":3585009532,"timestamp":"2024-06-01T22:42:15.956551Z"}]}
{"channel":"book","type":"update","data":[{"symbol":"LTC/USD","bids":[],"asks":[{"price":83.39,"qty":67.74028414}],"checksum":384450828,"timestamp":"2024-06-01T22:42:16.063392Z"}]}
{"channel":"book","type":"update","data":[{"symbol":"LTC/USD","bids":[{"price":83.37,"qty":34.44856706}],"asks":[],"checksum":1913721671,"timestamp":"2024-06-01T22:42:16.066057Z"}]}
{"channel":"book","type":"update","data":[{"symbol":"LTC/USD","bids":[{"price":83.36,"qty":102.61449757}],"asks":[],"checksum":2444298666,"timestamp":"2024-06-01T22:42:16.066382Z"}]}
{"channel":"book","type":"update","data":[{"symbol":"LTC/USD","bids":[],"asks":[{"price":83.39,"qty":68.02520472}],"checksum":1014674212,"timestamp":"2024-06-01T22:42:16.067275Z"}]}
{"channel":"book","type":"update","data":[{"symbol":"LTC/USD","bids":[],"asks":[{"price":83.39,"qty":91.87826984}],"checksum":4208252960,"timestamp":"2024-06-01T22:42:16.067433Z"}]}
{"channel":"book","type":"update","data":[{"symbol":"LTC/USD","bids":[],"asks":[{"price":83.39,"qty":92.16319042}],"checksum":1965911614,"timestamp":"2024-06-01T22:42:16.068983Z"}]}
{"channel":"book","type":"update","data":[{"symbol":"LTC/USD","bids":[],"asks":[{"price":83.39,"qty":92.44811100}],"checksum":4232326781,"timestamp":"2024-06-01T22:42:16.080516Z"}]}
{"channel":"book","type":"update","data":[{"symbol":"LTC/USD","bids":[],"asks":[{"price":83.42,"qty":25.38476247}],"checksum":4085416222,"timestamp":"2024-06-01T22:42:16.245131Z"}]}
{"channel":"book","type":"update","data":[{"symbol":"LTC/USD","bids":[],"asks":[{"price":83.42,"qty":1.53169735}],"checksum":1924081162,"timestamp":"2024-06-01T22:42:16.248940Z"}]}
{"channel":"book","type":"update","data":[{"symbol":"LTC/USD","bids":[{"price":83.32,"qty":89.66180167}],"asks":[],"checksum":4201648533,"timestamp":"2024-06-01T22:42:16.381692Z"}]}
{"channel":"book","type":"update","data":[{"symbol":"LTC/USD","bids":[{"price":83.31,"qty":104.24523200}],"asks":[],"checksum":831560135,"timestamp":"2024-06-01T22:42:16.381753Z"}]}
{"channel":"book","type":"update","data":[{"symbol":"LTC/USD","bids":[{"price":83.32,"qty":93.67642621}],"asks":[],"checksum":2475540330,"timestamp":"2024-06-01T22:42:16.385649Z"}]}
{"channel":"book","type":"update","data":[{"symbol":"LTC/USD","bids":[{"price":83.31,"qty":111.15586363}],"asks":[],"checksum":573801600,"timestamp":"2024-06-01T22:42:16.385698Z"}]}
{"channel":"book","type":"update","data":[{"symbol":"LTC/USD","bids":[{"price":83.30,"qty":261.33361137},{"price":83.31,"qty":171.09586363}],"asks":[],"checksum":834115614,"timestamp":"2024-06-01T22:42:16.457343Z"}]}
{"channel":"book","type":"update","data":[{"symbol":"LTC/USD","bids":[{"price":83.31,"qty":111.15586363}],"asks":[],"checksum":4050890635,"timestamp":"2024-06-01T22:42:16.486361Z"}]}
{"channel":"book","type":"update","data":[{"symbol":"LTC/USD","bids":[],"asks":[{"price":83.44,"qty":137.49697347}],"checksum":4259192123,"timestamp":"2024-06-01T22:42:16.822104Z"}]}
{"channel":"book","type":"update","data":[{"symbol":"LTC/USD","bids":[],"asks":[{"price":83.45,"qty":156.55498439}],"checksum":3158626421,"timestamp":"2024-06-01T22:42:16.824721Z"}]}
{"channel":"book","type":"update","data":[{"symbol":"LTC/USD","bids":[{"price":83.31,"qty":171.09586363}],"asks":[],"checksum":2088822752,"timestamp":"2024-06-01T22:42:16.977557Z"}]}
{"channel":"book","type":"update","data":[{"symbol":"LTC/USD","bids":[{"price":83.33,"qty":62.84239888}],"asks":[],"checksum":2830948728,"timestamp":"2024-06-01T22:42:17.596875Z"}]}
{"channel":"book","type":"update","data":[{"symbol":"LTC/USD","bids":[{"price":83.33,"qty":70.39239888}],"asks":[],"checksum":2088822752,"timestamp":"2024-06-01T22:42:17.786458Z"}]}
{"channel":"book","type":"update","data":[{"symbol":"LTC/USD","bids":[],"asks":[{"price":83.38,"qty":16.68525976}],"checksum":388735227,"timestamp":"2024-06-01T22:42:18.169806Z"}]}
{"channel":"book","type":"update","data":[{"symbol":"LTC/USD","bids":[],"asks":[{"price":83.43,"qty":46.97680131}],"checksum":467309125,"timestamp":"2024-06-01T22:42:18.727973Z"}]}
{"channel":"book","type":"update","data":[{"symbol":"LTC/USD","bids":[],"asks":[{"price":83.43,"qty":48.59928215}],"checksum":3154272746,"timestamp":"2024-06-01T22:42:18.728436Z"}]}
{"channel":"book","type":"update","data":[{"symbol":"LTC/USD","bids":[{"price":83.31,"qty":111.15586363}],"asks":[],"checksum":2093373055,"timestamp":"2024-06-01T22:42:19.126893Z"}]}
{"channel":"book","type":"update","data":[{"symbol":"LTC/USD","bids":[{"price":83.31,"qty":171.09586363}],"asks":[],"checksum":3154272746,"timestamp":"2024-06-01T22:42:19.252756Z"}]}
{"channel":"book","type":"update","data":[{"symbol":"LTC/USD","bids":[],"asks":[{"price":83.38,"qty":16.21688337}],"checksum":3461234736,"timestamp":"2024-06-01T22:42:19.650277Z"}]}
{"channel":"book","type":"update","data":[{"symbol":"LTC/USD","bids":[],"asks":[{"price":83.38,"qty":9.13525976}],"checksum":594176122,"timestamp":"2024-06-01T22:42:19.662203Z"}]}
{"channel":"book","type":"update","data":[{"symbol":"LTC/USD","bids":[{"price":83.30,"qty":317.95908870}],"asks":[],"checksum":4185815914,"timestamp":"2024-06-01T22:42:19.683032Z"}]}
{"channel":"book","type":"update","data":[{"symbol":"LTC/USD","bids":[],"asks":[{"price":83.38,"qty":16.68525976}],"checksum":1712747258,"timestamp":"2024-06-01T22:42:19.827417Z"}]}
{"channel":"book","type":"update","data":[{"symbol":"LTC/USD","bids":[{"price":83.37,"qty":33.73659356}],"asks":[],"checksum":3035434509,"timestamp":"2024-06-01T22:42:20.391462Z"}]}
{"channel":"book","type":"update","data":[{"symbol":"LTC/USD","bids":[{"price":83.31,"qty":111.15586363}],"asks":[],"checksum":1948858776,"timestamp":"2024-06-01T22:42:20.454490Z"}]}
{"channel":"book","type":"update","data":[{"symbol":"LTC/USD","bids":[{"price":83.37,"qty":33.14299782}],"asks":[],"checksum":577516207,"timestamp":"2024-06-01T22:42:20.832861Z"}]}
{"channel":"book","type":"update","data":[{"symbol":"LTC/USD","bids":[{"price":83.30,"qty":377.89908870}],"asks":[],"checksum":925268485,"timestamp":"2024-06-01T22:42:21.259498Z"}]}
{"channel":"book","type":"update","data":[{"symbol":"LTC/USD","bids":[{"price":83.30,"qty":321.27361137},{"price":83.29,"qty":56.62547733}],"asks":[],"checksum":1432378642,"timestamp":"2024-06-01T22:42:21.262773Z"}]}
{"channel":"book","type":"update","data":[{"symbol":"LTC/USD","bids":[{"price":83.37,"qty":32.54365709}],"asks":[],"checksum":2629081230,"timestamp":"2024-06-01T22:42:21.941610Z"}]}
{"channel":"book","type":"update","data":[{"symbol":"LTC/USD","bids":[{"price":83.30,"qty":261.33361137},{"price":83.31,"qty":171.09586363}],"asks":[],"checksum":2402321424,"timestamp":"2024-06-01T22:42:21.945042Z"}]}
{"channel":"book","type":"update","data":[{"symbol":"LTC/USD","bids":[{"price":83.31,"qty":164.18523200}],"asks":[],"checksum":4286345483,"timestamp":"2024-06-01T22:42:22.772555Z"}]}
{"channel":"book","type":"update","data":[{"symbol":"LTC/USD","bids":[{"price":83.32,"qty":89.66180167}],"asks":[],"checksum":1566660518,"timestamp":"2024-06-01T22:42:22.772673Z"}]}
{"channel":"book","type":"update","data":[{"symbol":"LTC/USD","bids":[{"price":83.29,"qty":0.00000000},{"price":83.26,"qty":60.04681310},{"price":83.30,"qty":317.95908870}],"asks":[],"checksum":4180480784,"timestamp":"2024-06-01T22:42:22.777665Z"}]}
{"channel":"book","type":"update","data":[{"symbol":"LTC/USD","bids":[{"price":83.32,"qty":96.92721339}],"asks":[],"checksum":2015291790,"timestamp":"2024-06-01T22:42:22.783804Z"}]}
{"channel":"book","type":"update","data":[{"symbol":"LTC/USD","bids":[{"price":83.31,"qty":169.92288969}],"asks":[],"checksum":3410221409,"timestamp":"2024-06-01T22:42:22.784246Z"}]}
{"channel":"book","type":"update","data":[{"symbol":"LTC/USD","bids":[{"price":83.37,"qty":32.31375709}],"asks":[],"checksum":1062292540,"timestamp":"2024-06-01T22:42:23.023497Z"}]}
{"channel":"book","type":"update","data":[{"symbol":"LTC/USD","bids":[],"asks":[{"price":83.38,"qty":9.13525976}],"checksum":2688107948,"timestamp":"2024-06-01T22:42:24.326586Z"}]}
{"channel":"book","type":"update","data":[{"symbol":"LTC/USD","bids":[{"price":83.30,"qty":261.33361137},{"price":83.29,"qty":56.62547733}],"asks":[],"checksum":74776858,"timestamp":"2024-06-01T22:42:24.329218Z"}]}
{"channel":"book","type":"update","data":[{"symbol":"LTC/USD","bids":[],"asks":[{"price":83.38,"qty":1.58525976}],"checksum":41795331,"timestamp":"2024-06-01T22:42:24.330774Z"}]}
{"channel":"book","type":"update","data":[{"symbol":"LTC/USD","bids":[],"asks":[{"price":83.38,"qty":9.13525976},{"price":83.38,"qty":16.68525976}],"checksum":2602371210,"timestamp":"2024-06-01T22:42:24.474638Z"}]}
{"channel":"book","type":"update","data":[{"symbol":"LTC/USD","bids":[{"price":83.32,"qty":36.92876277}],"asks":[],"checksum":2077795904,"timestamp":"2024-06-01T22:42:24.503597Z"}]}
{"channel":"book","type":"update","data":[{"symbol":"LTC/USD","bids":[],"asks":[{"price":83.38,"qty":9.13525976}],"checksum":3836784592,"timestamp":"2024-06-01T22:42:24.867695Z"}]}
{"channel":"book","type":"update","data":[{"symbol":"LTC/USD","bids":[],"asks":[{"price":83.38,"qty":1.58525976}],"checksum":3803713993,"timestamp":"2024-06-01T22:42:24.870896Z"}]}
{"channel":"book","type":"update","data":[{"symbol":"LTC/USD","bids":[{"price":83.32,"qty":96.92197993}],"asks":[],"checksum":3892294628,"timestamp":"2024-06-01T22:42:24.883940Z"}]}
{"channel":"book","type":"update","data":[{"symbol":"LTC/USD","bids":[{"price":83.32,"qty":36.92876277}],"asks":[],"checksum":3803713993,"timestamp":"2024-06-01T22:42:24.993884Z"}]}
{"channel":"book","type":"update","data":[{"symbol":"LTC/USD","bids":[],"asks":[{"price":83.38,"qty":9.13525976},{"price":83.38,"qty":16.68525976}],"checksum":2077795904,"timestamp":"2024-06-01T22:42:25.041456Z"}]}
{"channel":"book","type":"update","data":[{"symbol":"LTC/USD","bids":[{"price":83.29,"qty":116.62844616}],"asks":[],"checksum":1330786258,"timestamp":"2024-06-01T22:42:25.282171Z"}]}
{"channel":"book","type":"update","data":[{"symbol":"LTC/USD","bids":[{"price":83.37,"qty":31.01635709}],"asks":[],"checksum":1523813846,"timestamp":"2024-06-01T22:42:25.416821Z"}]}
{"channel":"book","type":"update","data":[{"symbol":"LTC/USD","bids":[{"price":83.32,"qty":96.93173160}],"asks":[],"checksum":3551211944,"timestamp":"2024-06-01T22:42:25.708444Z"}]}
{"channel":"book","type":"update","data":[{"symbol":"LTC/USD","bids":[{"price":83.29,"qty":56.62547733}],"asks":[],"checksum":2344646020,"timestamp":"2024-06-01T22:42:25.712088Z"}]}
{"channel":"book","type":"update","data":[{"symbol":"LTC/USD","bids":[{"price":83.29,"qty":0.00000000},{"price":83.26,"qty":60.04681310},{"price":83.30,"qty":317.95908870}],"asks":[],"checksum":797716786,"timestamp":"2024-06-01T22:42:26.330836Z"}]}
{"channel":"book","type":"update","data":[{"symbol":"LTC/USD","bids":[{"price":83.31,"qty":109.98288969}],"asks":[],"checksum":218958588,"timestamp":"2024-06-01T22:42:26.490804Z"}]}
{"channel":"book","type":"update","data":[{"symbol":"LTC/USD","bids":[{"price":83.33,"qty":62.84239888},{"price":83.28,"qty":131.89812701}],"asks":[],"checksum":449286230,"timestamp":"2024-06-01T22:42:26.663554Z"}]}
{"channel":"book","type":"update","data":[{"symbol":"LTC/USD","bids":[{"price":83.28,"qty":139.44812701}],"asks":[],"checksum":3268652077,"timestamp":"2024-06-01T22:42:26.666903Z"}]}
{"channel":"book","type":"update","data":[{"symbol":"LTC/USD","bids":[{"price":83.30,"qty":377.89908870}],"asks":[],"checksum":3617186951,"timestamp":"2024-06-01T22:42:26.669705Z"}]}
{"channel":"book","type":"update","data":[{"symbol":"LTC/USD","bids":[{"price":83.28,"qty":131.89812701}],"asks":[],"checksum":260954364,"timestamp":"2024-06-01T22:42:26.695498Z"}]}
{"channel":"book","type":"update","data":[{"symbol":"LTC/USD","bids":[],"asks":[{"price":83.38,"qty":9.13525976},{"price":83.42,"qty":9.08169735}],"checksum":3676159071,"timestamp":"2024-06-01T22:42:27.226717Z"}]}
{"channel":"book","type":"update","data":[{"symbol":"LTC/USD","bids":[],"asks":[{"price":83.42,"qty":16.63169735}],"checksum":309671215,"timestamp":"2024-06-01T22:42:27.232294Z"}]}
{"channel":"book","type":"update","data":[{"symbol":"LTC/USD","bids":[{"price":83.30,"qty":317.95908870},{"price":83.31,"qty":169.92288969}],"asks":[],"checksum":633226827,"timestamp":"2024-06-01T22:42:27.242237Z"}]}
{"channel":"book","type":"update","data":[{"symbol":"LTC/USD","bids":[{"price":83.31,"qty":109.98288969}],"asks":[],"checksum":121601413,"timestamp":"2024-06-01T22:42:27.667526Z"}]}
{"channel":"book","type":"update","data":[{"symbol":"LTC/USD","bids":[],"asks":[{"price":83.42,"qty":9.08169735}],"checksum":3461870837,"timestamp":"2024-06-01T22:42:27.781218Z"}]}
{"channel":"book","type":"update","data":[{"symbol":"LTC/USD","bids":[{"price":83.37,"qty":30.77998074}],"asks":[],"checksum":1615553072,"timestamp":"2024-06-01T22:42:28.122469Z"}]}
{"channel":"book","type":"update","data":[{"symbol":"LTC/USD","bids":[{"price":83.30,"qty":377.89908870}],"asks":[],"checksum":1963010714,"timestamp":"2024-06-01T22:42:28.125948Z"}]}
{"channel":"book","type":"update","data":[{"symbol":"LTC/USD","bids":[{"price":83.30,"qty":321.27361137},{"price":83.29,"qty":56.62547733}],"asks":[],"checksum":495937810,"timestamp":"2024-06-01T22:42:28.126294Z"}]}
{"channel":"book","type":"update","data":[{"symbol":"LTC/USD","bids":[{"price":83.30,"qty":261.33361137},{"price":83.31,"qty":169.92288969}],"asks":[],"checksum":3964565975,"timestamp":"2024-06-01T22:42:28.779288Z"}]}
{"channel":"book","type":"update","data":[{"symbol":"LTC/USD","bids":[{"price":83.32,"qty":89.66631988}],"asks":[],"checksum":4118932725,"timestamp":"2024-06-01T22:42:29.130665Z"}]}
{"channel":"book","type":"update","data":[{"symbol":"LTC/USD","bids":[{"price":83.31,"qty":164.18523200}],"asks":[],"checksum":1188879386,"timestamp":"2024-06-01T22:42:29.130794Z"}]}
{"channel":"book","type":"update","data":[{"symbol":"LTC/USD","bids":[{"price":83.31,"qty":173.45769068}],"asks":[],"checksum":1930493941,"timestamp":"2024-06-01T22:42:29.137297Z"}]}
{"channel":"book","type":"update","data":[{"symbol":"LTC/USD","bids":[{"price":83.29,"qty":57.23471381}],"asks":[],"checksum":3480861877,"timestamp":"2024-06-01T22:42:29.137435Z"}]}
{"channel":"book","type":"update","data":[{"symbol":"LTC/USD","bids":[],"asks":[{"price":83.43,"qty":46.97680131}],"checksum":1755402010,"timestamp":"2024-06-01T22:42:29.794376Z"}]}
{"channel":"book","type":"update","data":[{"symbol":"LTC/USD","bids":[],"asks":[{"price":83.43,"qty":48.44580452}],"checksum":2024790692,"timestamp":"2024-06-01T22:42:29.794646Z"}]}
{"channel":"book","type":"update","data":[{"symbol":"LTC/USD","bids":[{"price":83.29,"qty":0.60923648},{"price":83.30,"qty":317.95908870}],"asks":[],"checksum":1584000897,"timestamp":"2024-06-01T22:42:29.797656Z"}]}
{"channel":"book","type":"update","data":[{"symbol":"LTC/USD","bids":[],"asks":[{"price":83.39,"qty":68.36293234}],"checksum":3994655493,"timestamp":"2024-06-01T22:42:30.260795Z"}]}
{"channel":"book","type":"update","data":[{"symbol":"LTC/USD","bids":[],"asks":[{"price":83.38,"qty":14.30493842}],"checksum":3749941172,"timestamp":"2024-06-01T22:42:30.266451Z"}]}
{"channel":"book","type":"update","data":[{"symbol":"LTC/USD","bids":[{"price":83.37,"qty":30.60036154}],"asks":[],"checksum":1668409897,"timestamp":"2024-06-01T22:42:30.417107Z"}]}
{"channel":"book","type":"update","data":[{"symbol":"LTC/USD","bids":[{"price":83.30,"qty":261.33361137}],"asks":[],"checksum":2036538282,"timestamp":"2024-06-01T22:42:31.627502Z"}]}
{"channel":"book","type":"update","data":[{"symbol":"LTC/USD","bids":[{"price":83.29,"qty":0.00000000},{"price":83.26,"qty":60.04681310}],"asks":[],"checksum":2799850923,"timestamp":"2024-06-01T22:42:32.272385Z"}]}
{"channel":"book","type":"update","data":[{"symbol":"LTC/USD","bids":[{"price":83.31,"qty":164.18523200}],"asks":[],"checksum":2469295684,"timestamp":"2024-06-01T22:42:32.272403Z"}]}
{"channel":"book","type":"update","data":[{"symbol":"LTC/USD","bids":[{"price":83.31,"qty":170.03211516}],"asks":[],"checksum":3106063817,"timestamp":"2024-06-01T22:42:32.281026Z"}]}
{"channel":"book","type":"update","data":[{"symbol":"LTC/USD","bids":[{"price":83.32,"qty":94.31172561}],"asks":[],"checksum":1933250309,"timestamp":"2024-06-01T22:42:32.281076Z"}]}
{"channel":"book","type":"update","data":[{"symbol":"LTC/USD","bids":[{"price":83.28,"qty":127.52012701}],"asks":[],"checksum":1247970153,"timestamp":"2024-06-01T22:42:34.937303Z"}]}
{"channel":"book","type":"update","data":[{"symbol":"LTC/USD","bids":[{"price":83.28,"qty":131.97482701}],"asks":[],"checksum":3549786792,"timestamp":"2024-06-01T22:42:35.026611Z"}]}
{"channel":"book","type":"update","data":[{"symbol":"LTC/USD","bids":[],"asks":[{"price":83.43,"qty":46.97680131}],"checksum":3281774358,"timestamp":"2024-06-01T22:42:35.261737Z"}]}
{"channel":"book","type":"update","data":[{"symbol":"LTC/USD","bids":[],"asks":[{"price":83.43,"qty":48.66527624}],"checksum":2297153292,"timestamp":"2024-06-01T22:42:35.263083Z"}]}
{"channel":"book","type":"update","data":[{"symbol":"LTC/USD","bids":[{"price":83.32,"qty":86.76172561}],"asks":[],"checksum":2537949617,"timestamp":"2024-06-01T22:42:35.758223Z"}]}
{"channel":"book","type":"update","data":[{"symbol":"LTC/USD","bids":[{"price":83.31,"qty":110.09211516}],"asks":[],"checksum":3049730687,"timestamp":"2024-06-01T22:42:35.803749Z"}]}
{"channel":"book","type":"update","data":[{"symbol":"LTC/USD","bids":[{"price":83.30,"qty":321.27361137}],"asks":[],"checksum":1720129908,"timestamp":"2024-06-01T22:42:35.810830Z"}]}
{"channel":"book","type":"update","data":[{"symbol":"LTC/USD","bids":[{"price":83.35,"qty":37.52624309}],"asks":[],"checksum":2833545801,"timestamp":"2024-06-01T22:42:35.820165Z"}]}
{"channel":"book","type":"update","data":[{"symbol":"LTC/USD","bids":[{"price":83.32,"qty":94.31172561}],"asks":[],"checksum":3075060980,"timestamp":"2024-06-01T22:42:35.903307Z"}]}
{"channel":"book","type":"update","data":[{"symbol":"LTC/USD","bids":[{"price":83.30,"qty":261.33361137},{"price":83.31,"qty":170.03211516}],"asks":[],"checksum":1183360049,"timestamp":"2024-06-01T22:42:36.313532Z"}]}
{"channel":"book","type":"update","data":[{"symbol":"LTC/USD","bids":[{"price":83.31,"qty":110.09211516}],"asks":[],"checksum":1678352383,"timestamp":"2024-06-01T22:42:36.334756Z"}]}
{"channel":"book","type":"update","data":[{"symbol":"LTC/USD","bids":[{"price":83.28,"qty":127.52012701}],"asks":[],"checksum":4261310014,"timestamp":"2024-06-01T22:42:36.363349Z"}]}
{"channel":"book","type":"update","data":[{"symbol":"LTC/USD","bids":[{"price":83.31,"qty":130.09211516}],"asks":[],"checksum":2357563527,"timestamp":"2024-06-01T22:42:37.117462Z"}]}
{"channel":"book","type":"update","data":[{"symbol":"LTC/USD","bids":[{"price":83.31,"qty":190.03211516}],"asks":[],"checksum":1382918814,"timestamp":"2024-06-01T22:42:37.120584Z"}]}
{"channel":"book","type":"update","data":[{"symbol":"LTC/USD","bids":[{"price":83.31,"qty":130.09211516}],"asks":[],"checksum":2357563527,"timestamp":"2024-06-01T22:42:37.146806Z"}]}
{"channel":"book","type":"update","data":[{"symbol":"LTC/USD","bids":[{"price":83.28,"qty":132.23892701}],"asks":[],"checksum":2152728633,"timestamp":"2024-06-01T22:42:37.535668Z"}]}
{"channel":"book","type":"update","data":[{"symbol":"LTC/USD","bids":[{"price":83.35,"qty":40.38624309}],"asks":[],"checksum":2337217146,"timestamp":"2024-06-01T22:42:37.963387Z"}]}
{"channel":"book","type":"update","data":[{"symbol":"LTC/USD","bids":[{"price":83.31,"qty":124.24523200}],"asks":[],"checksum":2197056349,"timestamp":"2024-06-01T22:42:38.831372Z"}]}
{"channel":"book","type":"update","data":[{"symbol":"LTC/USD","bids":[{"price":83.31,"qty":184.18523200}],"asks":[],"checksum":2141950958,"timestamp":"2024-06-01T22:42:38.834651Z"}]}
{"channel":"book","type":"update","data":[{"symbol":"LTC/USD","bids":[{"price":83.31,"qty":189.83549972}],"asks":[],"checksum":2259764929,"timestamp":"2024-06-01T22:42:38.837927Z"}]}
{"channel":"book","type":"update","data":[{"symbol":"LTC/USD","bids":[{"price":83.31,"qty":184.18523200}],"asks":[],"checksum":2141950958,"timestamp":"2024-06-01T22:42:41.928486Z"}]}
{"channel":"book","type":"update","data":[{"symbol":"LTC/USD","bids":[{"price":83.32,"qty":89.66631988}],"asks":[],"checksum":3048364322,"timestamp":"2024-06-01T22:42:41.928531Z"}]}
{"channel":"book","type":"update","data":[{"symbol":"LTC/USD","bids":[{"price":83.31,"qty":187.32067140}],"asks":[],"checksum":1631130055,"timestamp":"2024-06-01T22:42:41.934396Z"}]}
{"channel":"book","type":"update","data":[{"symbol":"LTC/USD","bids":[{"price":83.32,"qty":96.82844876}],"asks":[],"checksum":4069236121,"timestamp":"2024-06-01T22:42:41.934531Z"}]}
{"channel":"book","type":"update","data":[{"symbol":"LTC/USD","bids":[{"price":83.30,"qty":201.40361137},{"price":83.32,"qty":156.75844876}],"asks":[],"checksum":1316394511,"timestamp":"2024-06-01T22:42:42.456448Z"}]}
{"channel":"book","type":"update","data":[{"symbol":"LTC/USD","bids":[{"price":83.32,"qty":96.82844876}],"asks":[],"checksum":3027470523,"timestamp":"2024-06-01T22:42:42.459492Z"}]}
{"channel":"book","type":"update","data":[{"symbol":"LTC/USD","bids":[{"price":83.31,"qty":247.25067140}],"asks":[],"checksum":136077461,"timestamp":"2024-06-01T22:42:43.135819Z"}]}
{"channel":"book","type":"update","data":[{"symbol":"LTC/USD","bids":[{"price":83.30,"qty":258.02477006}],"asks":[],"checksum":1621282096,"timestamp":"2024-06-01T22:42:43.621869Z"}]}
{"channel":"book","type":"update","data":[{"symbol":"LTC/USD","bids":[{"price":83.32,"qty":89.27844876}],"asks":[],"checksum":2946497965,"timestamp":"2024-06-01T22:42:44.321783Z"}]}
{"channel":"book","type":"update","data":[{"symbol":"LTC/USD","bids":[{"price":83.32,"qty":96.82844876}],"asks":[],"checksum":1621282096,"timestamp":"2024-06-01T22:42:44.460687Z"}]}
{"channel":"book","type":"update","data":[{"symbol":"LTC/USD","bids":[{"price":83.31,"qty":187.32067140},{"price":83.32,"qty":156.75844876}],"asks":[],"checksum":650656682,"timestamp":"2024-06-01T22:42:44.461665Z"}]}
{"channel":"book","type":"update","data":[{"symbol":"LTC/USD","bids":[{"price":83.32,"qty":96.82844876}],"asks":[],"checksum":3704431902,"timestamp":"2024-06-01T22:42:44.464449Z"}]}
{"channel":"book","type":"update","data":[{"symbol":"LTC/USD","bids":[{"price":83.32,"qty":89.66631988}],"asks":[],"checksum":1333766464,"timestamp":"2024-06-01T22:42:44.763896Z"}]}
{"channel":"book","type":"update","data":[{"symbol":"LTC/USD","bids":[{"price":83.31,"qty":184.18523200}],"asks":[],"checksum":2616517029,"timestamp":"2024-06-01T22:42:44.763922Z"}]}
{"channel":"book","type":"update","data":[{"symbol":"LTC/USD","bids":[{"price":83.32,"qty":98.08702873}],"asks":[],"checksum":1252903982,"timestamp":"2024-06-01T22:42:44.773692Z"}]}
{"channel":"book","type":"update","data":[{"symbol":"LTC/USD","bids":[{"price":83.31,"qty":185.43940776}],"asks":[],"checksum":2951250166,"timestamp":"2024-06-01T22:42:44.773716Z"}]}
{"channel":"book","type":"update","data":[{"symbol":"LTC/USD","bids":[],"asks":[{"price":83.38,"qty":9.13525976}],"checksum":1223490280,"timestamp":"2024-06-01T22:42:45.333463Z"}]}
{"channel":"book","type":"update","data":[{"symbol":"LTC/USD","bids":[],"asks":[{"price":83.38,"qty":12.16318842}],"checksum":75944670,"timestamp":"2024-06-01T22:42:45.336668Z"}]}
{"channel":"book","type":"update","data":[{"symbol":"LTC/USD","bids":[{"price":83.31,"qty":245.36940776}],"asks":[],"checksum":2992387484,"timestamp":"2024-06-01T22:42:45.336746Z"}]}
{"channel":"book","type":"update","data":[{"symbol":"LTC/USD","bids":[{"price":83.30,"qty":201.40361137},{"price":83.29,"qty":56.62115869}],"asks":[],"checksum":349174332,"timestamp":"2024-06-01T22:42:45.337013Z"}]}
{"channel":"book","type":"update","data":[{"symbol":"LTC/USD","bids":[],"asks":[{"price":83.44,"qty":132.76910770}],"checksum":3206028369,"timestamp":"2024-06-01T22:42:46.550576Z"}]}
{"channel":"book","type":"update","data":[{"symbol":"LTC/USD","bids":[{"price":83.29,"qty":0.00000000},{"price":83.26,"qty":60.04681310},{"price":83.30,"qty":258.02477006}],"asks":[],"checksum":428594161,"timestamp":"2024-06-01T22:42:47.271007Z"}]}
{"channel":"book","type":"update","data":[{"symbol":"LTC/USD","bids":[{"price":83.32,"qty":89.66631988}],"asks":[],"checksum":3369270906,"timestamp":"2024-06-01T22:42:47.890938Z"}]}
{"channel":"book","type":"update","data":[{"symbol":"LTC/USD","bids":[{"price":83.31,"qty":244.11523200}],"asks":[],"checksum":3887715246,"timestamp":"2024-06-01T22:42:47.890979Z"}]}
{"channel":"book","type":"update","data":[{"symbol":"LTC/USD","bids":[{"price":83.32,"qty":95.57042393}],"asks":[],"checksum":4176595686,"timestamp":"2024-06-01T22:42:47.895361Z"}]}
{"channel":"book","type":"update","data":[{"symbol":"LTC/USD","bids":[{"price":83.31,"qty":247.86909898}],"asks":[],"checksum":2980804097,"timestamp":"2024-06-01T22:42:47.895419Z"}]}
{"channel":"book","type":"update","data":[{"symbol":"LTC/USD","bids":[{"price":83.30,"qty":201.40361137},{"price":83.29,"qty":56.62115869}],"asks":[],"checksum":389593505,"timestamp":"2024-06-01T22:42:49.361169Z"}]}
{"channel":"book","type":"update","data":[{"symbol":"LTC/USD","bids":[{"price":83.32,"qty":88.02042393}],"asks":[],"checksum":989239733,"timestamp":"2024-06-01T22:42:50.159799Z"}]}
{"channel":"book","type":"update","data":[{"symbol":"LTC/USD","bids":[{"price":83.32,"qty":95.57042393}],"asks":[],"checksum":389593505,"timestamp":"2024-06-01T22:42:50.304396Z"}]}
{"channel":"book","type":"update","data":[{"symbol":"LTC/USD","bids":[{"price":83.29,"qty":0.00000000},{"price":83.26,"qty":60.04681310},{"price":83.30,"qty":258.02477006}],"asks":[],"checksum":2980804097,"timestamp":"2024-06-01T22:42:51.412550Z"}]}
{"channel":"book","type":"update","data":[{"symbol":"LTC/USD","bids":[{"price":83.31,"qty":187.92909898}],"asks":[],"checksum":3623774478,"timestamp":"2024-06-01T22:42:51.522731Z"}]}
{"channel":"book","type":"update","data":[{"symbol":"LTC/USD","bids":[{"price":83.30,"qty":317.96477006}],"asks":[],"checksum":526792675,"timestamp":"2024-06-01T22:42:51.642373Z"}]}
