{"channel":"book","type":"snapshot","data":[{"symbol":"LTC/USDT","bids":[{"price":83.41211,"qty":8.99364189},{"price":83.39668,"qty":0.23993904},{"price":83.39667,"qty":1.80000000},{"price":83.39531,"qty":1.99000000},{"price":83.39448,"qty":16.19448355},{"price":83.39413,"qty":1.72568366},{"price":83.38464,"qty":10.00000000},{"price":83.38000,"qty":22.78572865},{"price":83.37926,"qty":23.85306512},{"price":83.37663,"qty":13.36451721}],"asks":[{"price":83.44378,"qty":1.99000000},{"price":83.44398,"qty":1.80000000},{"price":83.44988,"qty":10.00000000},{"price":83.45000,"qty":8.66660859},{"price":83.45545,"qty":4.79435986},{"price":83.45588,"qty":7.87700000},{"price":83.45600,"qty":23.85306512},{"price":83.46171,"qty":13.36451721},{"price":83.46747,"qty":1.72568366},{"price":83.48922,"qty":2.86000000}],"checksum":2071618901}]}
{"channel":"book","type":"update","data":[{"symbol":"LTC/USDT","bids":[{"price":83.41211,"qty":0.00000000},{"price":83.37542,"qty":4.79507557}],"asks":[],"checksum":15740514,"timestamp":"2024-06-01T22:42:14.059854Z"}]}
{"channel":"book","type":"update","data":[{"symbol":"LTC/USDT","bids":[{"price":83.39688,"qty":1.99000000}],"asks":[],"checksum":3351877995,"timestamp":"2024-06-01T22:42:14.064406Z"}]}
{"channel":"book","type":"update","data":[{"symbol":"LTC/USDT","bids":[{"price":83.39667,"qty":0.00000000},{"price":83.37542,"qty":4.79507557}],"asks":[],"checksum":58772422,"timestamp":"2024-06-01T22:42:14.067194Z"}]}
{"channel":"book","type":"update","data":[{"symbol":"LTC/USDT","bids":[{"price":83.39697,"qty":1.80000000}],"asks":[],"checksum":2063909816,"timestamp":"2024-06-01T22:42:14.067688Z"}]}
{"channel":"book","type":"update","data":[{"symbol":"LTC/USDT","bids":[{"price":83.39717,"qty":1.99000000}],"asks":[],"checksum":1849381906,"timestamp":"2024-06-01T22:42:14.086088Z"}]}
{"channel":"book","type":"update","data":[{"symbol":"LTC/USDT","bids":[{"price":83.39688,"qty":0.00000000},{"price":83.37663,"qty":13.36451721}],"asks":[],"checksum":3014540290,"timestamp":"2024-06-01T22:42:14.086235Z"}]}
{"channel":"book","type":"update","data":[{"symbol":"LTC/USDT","bids":[{"price":83.41232,"qty":8.99325452}],"asks":[],"checksum":513137869,"timestamp":"2024-06-01T22:42:14.100045Z"}]}
{"channel":"book","type":"update","data":[{"symbol":"LTC/USDT","bids":[{"price":83.39717,"qty":0.00000000},{"price":83.37663,"qty":13.36451721}],"asks":[],"checksum":258199275,"timestamp":"2024-06-01T22:42:14.104071Z"}]}
{"channel":"book","type":"update","data":[{"symbol":"LTC/USDT","bids":[],"asks":[{"price":83.46747,"qty":0.00000000},{"price":83.50781,"qty":1.53279979}],"checksum":1220217412,"timestamp":"2024-06-01T22:42:14.165208Z"}]}
{"channel":"book","type":"update","data":[{"symbol":"LTC/USDT","bids":[],"asks":[{"price":83.48336,"qty":1.72568366}],"checksum":4143811315,"timestamp":"2024-06-01T22:42:14.345403Z"}]}
{"channel":"book","type":"update","data":[{"symbol":"LTC/USDT","bids":[{"price":83.41232,"qty":0.00000000},{"price":83.37542,"qty":4.79507557}],"asks":[],"checksum":3724162184,"timestamp":"2024-06-01T22:42:14.826422Z"}]}
{"channel":"book","type":"update","data":[{"symbol":"LTC/USDT","bids":[{"price":83.39717,"qty":1.99000000}],"asks":[],"checksum":1244690458,"timestamp":"2024-06-01T22:42:14.832808Z"}]}
{"channel":"book","type":"update","data":[{"symbol":"LTC/USDT","bids":[{"price":83.41466,"qty":8.99262036}],"asks":[],"checksum":1105976765,"timestamp":"2024-06-01T22:42:14.866301Z"}]}
{"channel":"book","type":"update","data":[{"symbol":"LTC/USDT","bids":[{"price":83.39717,"qty":0.00000000},{"price":83.37663,"qty":13.36451721}],"asks":[],"checksum":1597620694,"timestamp":"2024-06-01T22:42:14.871939Z"}]}
{"channel":"book","type":"update","data":[{"symbol":"LTC/USDT","bids":[{"price":83.39369,"qty":2.52000000}],"asks":[],"checksum":1423810787,"timestamp":"2024-06-01T22:42:14.921354Z"}]}
{"channel":"book","type":"update","data":[{"symbol":"LTC/USDT","bids":[],"asks":[{"price":83.48922,"qty":0.00000000},{"price":83.50781,"qty":1.53279979}],"checksum":2876417988,"timestamp":"2024-06-01T22:42:15.223542Z"}]}
{"channel":"book","type":"update","data":[{"symbol":"LTC/USDT","bids":[],"asks":[{"price":83.49206,"qty":2.41000000}],"checksum":894277642,"timestamp":"2024-06-01T22:42:15.381746Z"}]}
{"channel":"book","type":"update","data":[{"symbol":"LTC/USDT","bids":[{"price":83.37926,"qty":0.00000000},{"price":83.37663,"qty":13.36451721}],"asks":[],"checksum":508245676,"timestamp":"2024-06-01T22:42:15.416333Z"}]}
{"channel":"book","type":"update","data":[{"symbol":"LTC/USDT","bids":[{"price":83.41466,"qty":0.00000000},{"price":83.37542,"qty":4.79507557}],"asks":[],"checksum":3226484515,"timestamp":"2024-06-01T22:42:15.626972Z"}]}
{"channel":"book","type":"update","data":[{"symbol":"LTC/USDT","bids":[{"price":83.38562,"qty":23.85306512}],"asks":[],"checksum":1907483399,"timestamp":"2024-06-01T22:42:15.631195Z"}]}
{"channel":"book","type":"update","data":[{"symbol":"LTC/USDT","bids":[{"price":83.39717,"qty":1.99000000}],"asks":[],"checksum":1411657162,"timestamp":"2024-06-01T22:42:15.631597Z"}]}
{"channel":"book","type":"update","data":[{"symbol":"LTC/USDT","bids":[{"price":83.41217,"qty":8.99332636}],"asks":[],"checksum":4085678150,"timestamp":"2024-06-01T22:42:15.668209Z"}]}
{"channel":"book","type":"update","data":[{"symbol":"LTC/USDT","bids":[{"price":83.39717,"qty":0.00000000},{"price":83.38000,"qty":22.78572865}],"asks":[],"checksum":1480435458,"timestamp":"2024-06-01T22:42:15.672585Z"}]}
{"channel":"book","type":"update","data":[{"symbol":"LTC/USDT","bids":[{"price":83.41217,"qty":0.00000000},{"price":83.37663,"qty":13.36451721}],"asks":[],"checksum":1907483399,"timestamp":"2024-06-01T22:42:16.278558Z"}]}
{"channel":"book","type":"update","data":[{"symbol":"LTC/USDT","bids":[{"price":83.39717,"qty":1.99000000}],"asks":[],"checksum":1411657162,"timestamp":"2024-06-01T22:42:16.283095Z"}]}
{"channel":"book","type":"update","data":[{"symbol":"LTC/USDT","bids":[{"price":83.41222,"qty":8.99330986}],"asks":[],"checksum":299036458,"timestamp":"2024-06-01T22:42:16.318786Z"}]}
{"channel":"book","type":"update","data":[{"symbol":"LTC/USDT","bids":[{"price":83.39717,"qty":0.00000000},{"price":83.38000,"qty":22.78572865}],"asks":[],"checksum":484171294,"timestamp":"2024-06-01T22:42:16.323608Z"}]}
{"channel":"book","type":"update","data":[{"symbol":"LTC/USDT","bids":[{"price":83.39668,"qty":0.00000000},{"price":83.37663,"qty":13.36451721}],"asks":[],"checksum":4270709003,"timestamp":"2024-06-01T22:42:17.337539Z"}]}
{"channel":"book","type":"update","data":[{"symbol":"LTC/USDT","bids":[{"price":83.39532,"qty":0.23993904}],"asks":[],"checksum":221915315,"timestamp":"2024-06-01T22:42:17.342538Z"}]}
{"channel":"book","type":"update","data":[{"symbol":"LTC/USDT","bids":[{"price":83.41222,"qty":0.00000000},{"price":83.37663,"qty":13.36451721}],"asks":[],"checksum":1775582628,"timestamp":"2024-06-01T22:42:17.712142Z"}]}
{"channel":"book","type":"update","data":[{"symbol":"LTC/USDT","bids":[{"price":83.39717,"qty":1.99000000}],"asks":[],"checksum":1170594663,"timestamp":"2024-06-01T22:42:17.716962Z"}]}
{"channel":"book","type":"update","data":[{"symbol":"LTC/USDT","bids":[{"price":83.41219,"qty":8.99332004}],"asks":[],"checksum":1690791990,"timestamp":"2024-06-01T22:42:17.752023Z"}]}
{"channel":"book","type":"update","data":[{"symbol":"LTC/USDT","bids":[{"price":83.39717,"qty":0.00000000},{"price":83.38000,"qty":22.78572865}],"asks":[],"checksum":2989018489,"timestamp":"2024-06-01T22:42:17.756538Z"}]}
{"channel":"book","type":"update","data":[{"symbol":"LTC/USDT","bids":[],"asks":[{"price":83.45588,"qty":0.00000000},{"price":83.50781,"qty":1.53279979}],"checksum":1583702172,"timestamp":"2024-06-01T22:42:17.960304Z"}]}
{"channel":"book","type":"update","data":[{"symbol":"LTC/USDT","bids":[],"asks":[{"price":83.45908,"qty":7.86900000}],"checksum":3288010201,"timestamp":"2024-06-01T22:42:17.962667Z"}]}
{"channel":"book","type":"update","data":[{"symbol":"LTC/USDT","bids":[{"price":83.41219,"qty":0.00000000},{"price":83.37663,"qty":13.36451721}],"asks":[],"checksum":3211939212,"timestamp":"2024-06-01T22:42:18.359772Z"}]}
{"channel":"book","type":"update","data":[{"symbol":"LTC/USDT","bids":[{"price":83.39717,"qty":1.99000000}],"asks":[],"checksum":873864135,"timestamp":"2024-06-01T22:42:18.364338Z"}]}
{"channel":"book","type":"update","data":[{"symbol":"LTC/USDT","bids":[{"price":83.41244,"qty":8.99324486}],"asks":[],"checksum":2297579197,"timestamp":"2024-06-01T22:42:18.399846Z"}]}
{"channel":"book","type":"update","data":[{"symbol":"LTC/USDT","bids":[{"price":83.39717,"qty":0.00000000},{"price":83.38000,"qty":22.78572865}],"asks":[],"checksum":3366888167,"timestamp":"2024-06-01T22:42:18.404066Z"}]}
{"channel":"book","type":"update","data":[{"symbol":"LTC/USDT","bids":[{"price":83.41244,"qty":0.00000000},{"price":83.37663,"qty":13.36451721}],"asks":[],"checksum":3211939212,"timestamp":"2024-06-01T22:42:19.094741Z"}]}
{"channel":"book","type":"update","data":[{"symbol":"LTC/USDT","bids":[{"price":83.39717,"qty":1.99000000}],"asks":[],"checksum":873864135,"timestamp":"2024-06-01T22:42:19.099538Z"}]}
{"channel":"book","type":"update","data":[{"symbol":"LTC/USDT","bids":[{"price":83.41267,"qty":8.99446808}],"asks":[],"checksum":3678225141,"timestamp":"2024-06-01T22:42:19.135150Z"}]}
{"channel":"book","type":"update","data":[{"symbol":"LTC/USDT","bids":[{"price":83.39717,"qty":0.00000000},{"price":83.38000,"qty":22.78572865}],"asks":[],"checksum":2969216065,"timestamp":"2024-06-01T22:42:19.139516Z"}]}
{"channel":"book","type":"update","data":[{"symbol":"LTC/USDT","bids":[{"price":83.41267,"qty":0.00000000},{"price":83.37663,"qty":13.36451721}],"asks":[],"checksum":3211939212,"timestamp":"2024-06-01T22:42:19.830372Z"}]}
{"channel":"book","type":"update","data":[{"symbol":"LTC/USDT","bids":[{"price":83.39717,"qty":1.99000000}],"asks":[],"checksum":873864135,"timestamp":"2024-06-01T22:42:19.834873Z"}]}
{"channel":"book","type":"update","data":[{"symbol":"LTC/USDT","bids":[{"price":83.41296,"qty":8.99496343}],"asks":[],"checksum":3935443060,"timestamp":"2024-06-01T22:42:19.870731Z"}]}
{"channel":"book","type":"update","data":[{"symbol":"LTC/USDT","bids":[{"price":83.39717,"qty":0.00000000},{"price":83.38000,"qty":22.78572865}],"asks":[],"checksum":712292525,"timestamp":"2024-06-01T22:42:19.875096Z"}]}
{"channel":"book","type":"update","data":[{"symbol":"LTC/USDT","bids":[{"price":83.41296,"qty":0.00000000},{"price":83.37663,"qty":13.36451721}],"asks":[],"checksum":3211939212,"timestamp":"2024-06-01T22:42:20.470913Z"}]}
{"channel":"book","type":"update","data":[{"symbol":"LTC/USDT","bids":[{"price":83.39717,"qty":1.99000000}],"asks":[],"checksum":873864135,"timestamp":"2024-06-01T22:42:20.475616Z"}]}
{"channel":"book","type":"update","data":[{"symbol":"LTC/USDT","bids":[{"price":83.41230,"qty":8.99515782}],"asks":[],"checksum":3351894422,"timestamp":"2024-06-01T22:42:20.511167Z"}]}
{"channel":"book","type":"update","data":[{"symbol":"LTC/USDT","bids":[{"price":83.39717,"qty":0.00000000},{"price":83.38000,"qty":22.78572865}],"asks":[],"checksum":1683841080,"timestamp":"2024-06-01T22:42:20.515771Z"}]}
{"channel":"book","type":"update","data":[{"symbol":"LTC/USDT","bids":[{"price":83.41230,"qty":0.00000000},{"price":83.37663,"qty":13.36451721}],"asks":[],"checksum":3211939212,"timestamp":"2024-06-01T22:42:20.602031Z"}]}
{"channel":"book","type":"update","data":[{"symbol":"LTC/USDT","bids":[{"price":83.39717,"qty":1.99000000}],"asks":[],"checksum":873864135,"timestamp":"2024-06-01T22:42:20.606727Z"}]}
{"channel":"book","type":"update","data":[{"symbol":"LTC/USDT","bids":[{"price":83.39531,"qty":0.00000000},{"price":83.37663,"qty":13.36451721}],"asks":[],"checksum":1049987851,"timestamp":"2024-06-01T22:42:21.086403Z"}]}
{"channel":"book","type":"update","data":[{"symbol":"LTC/USDT","bids":[{"price":83.41183,"qty":8.99532727}],"asks":[],"checksum":2885908891,"timestamp":"2024-06-01T22:42:21.303822Z"}]}
{"channel":"book","type":"update","data":[{"symbol":"LTC/USDT","bids":[{"price":83.41183,"qty":0.00000000},{"price":83.37663,"qty":13.36451721}],"asks":[],"checksum":1049987851,"timestamp":"2024-06-01T22:42:21.990703Z"}]}
{"channel":"book","type":"update","data":[{"symbol":"LTC/USDT","bids":[{"price":83.41216,"qty":8.99513249}],"asks":[],"checksum":4240773828,"timestamp":"2024-06-01T22:42:22.031002Z"}]}
{"channel":"book","type":"update","data":[{"symbol":"LTC/USDT","bids":[{"price":83.41216,"qty":0.00000000},{"price":83.37663,"qty":13.36451721}],"asks":[],"checksum":1049987851,"timestamp":"2024-06-01T22:42:22.719284Z"}]}
{"channel":"book","type":"update","data":[{"symbol":"LTC/USDT","bids":[{"price":83.41185,"qty":8.99532493}],"asks":[],"checksum":1862228631,"timestamp":"2024-06-01T22:42:22.759457Z"}]}
{"channel":"book","type":"update","data":[{"symbol":"LTC/USDT","bids":[{"price":83.41185,"qty":0.00000000},{"price":83.37663,"qty":13.36451721}],"asks":[],"checksum":1049987851,"timestamp":"2024-06-01T22:42:23.410383Z"}]}
{"channel":"book","type":"update","data":[{"symbol":"LTC/USDT","bids":[{"price":83.41170,"qty":8.99546457}],"asks":[],"checksum":1166901448,"timestamp":"2024-06-01T22:42:23.507298Z"}]}
{"channel":"book","type":"update","data":[{"symbol":"LTC/USDT","bids":[{"price":83.39532,"qty":0.00000000},{"price":83.37663,"qty":13.36451721}],"asks":[],"checksum":3118372598,"timestamp":"2024-06-01T22:42:23.770394Z"}]}
{"channel":"book","type":"update","data":[{"symbol":"LTC/USDT","bids":[{"price":83.39718,"qty":0.23993904}],"asks":[],"checksum":2643610429,"timestamp":"2024-06-01T22:42:23.775792Z"}]}
{"channel":"book","type":"update","data":[{"symbol":"LTC/USDT","bids":[],"asks":[{"price":83.49206,"qty":0.00000000},{"price":83.50781,"qty":1.53279979}],"checksum":61699315,"timestamp":"2024-06-01T22:42:24.049018Z"}]}
{"channel":"book","type":"update","data":[{"symbol":"LTC/USDT","bids":[{"price":83.41170,"qty":0.00000000},{"price":83.37663,"qty":13.36451721}],"asks":[],"checksum":3352487100,"timestamp":"2024-06-01T22:42:24.226225Z"}]}
{"channel":"book","type":"update","data":[{"symbol":"LTC/USDT","bids":[{"price":83.39823,"qty":1.80000000}],"asks":[],"checksum":1547541169,"timestamp":"2024-06-01T22:42:24.228828Z"}]}
{"channel":"book","type":"update","data":[{"symbol":"LTC/USDT","bids":[{"price":83.39697,"qty":0.00000000},{"price":83.37663,"qty":13.36451721}],"asks":[],"checksum":4158893623,"timestamp":"2024-06-01T22:42:24.228853Z"}]}
{"channel":"book","type":"update","data":[{"symbol":"LTC/USDT","bids":[{"price":83.39738,"qty":1.99000000}],"asks":[],"checksum":2230423768,"timestamp":"2024-06-01T22:42:24.230698Z"}]}
{"channel":"book","type":"update","data":[{"symbol":"LTC/USDT","bids":[{"price":83.41219,"qty":8.99524623}],"asks":[],"checksum":1526499560,"timestamp":"2024-06-01T22:42:24.266441Z"}]}
{"channel":"book","type":"update","data":[{"symbol":"LTC/USDT","bids":[{"price":83.39738,"qty":0.00000000},{"price":83.38000,"qty":22.78572865}],"asks":[],"checksum":1428263482,"timestamp":"2024-06-01T22:42:24.270587Z"}]}
{"channel":"book","type":"update","data":[{"symbol":"LTC/USDT","bids":[],"asks":[{"price":83.49333,"qty":2.94000000}],"checksum":3935744329,"timestamp":"2024-06-01T22:42:24.528472Z"}]}
{"channel":"book","type":"update","data":[{"symbol":"LTC/USDT","bids":[{"price":83.41219,"qty":0.00000000},{"price":83.37663,"qty":13.36451721}],"asks":[],"checksum":1045445010,"timestamp":"2024-06-01T22:42:24.916663Z"}]}
{"channel":"book","type":"update","data":[{"symbol":"LTC/USDT","bids":[{"price":83.39843,"qty":1.99000000}],"asks":[],"checksum":417008757,"timestamp":"2024-06-01T22:42:24.921563Z"}]}
{"channel":"book","type":"update","data":[{"symbol":"LTC/USDT","bids":[{"price":83.41351,"qty":8.99484333}],"asks":[],"checksum":636040237,"timestamp":"2024-06-01T22:42:24.956809Z"}]}
{"channel":"book","type":"update","data":[{"symbol":"LTC/USDT","bids":[{"price":83.39843,"qty":0.00000000},{"price":83.38000,"qty":22.78572865}],"asks":[],"checksum":2361530116,"timestamp":"2024-06-01T22:42:24.961051Z"}]}
{"channel":"book","type":"update","data":[{"symbol":"LTC/USDT","bids":[{"price":83.41351,"qty":0.00000000},{"price":83.37663,"qty":13.36451721}],"asks":[],"checksum":1045445010,"timestamp":"2024-06-01T22:42:25.499000Z"}]}
{"channel":"book","type":"update","data":[{"symbol":"LTC/USDT","bids":[{"price":83.38000,"qty":0.00000000},{"price":83.37542,"qty":4.79507557}],"asks":[],"checksum":423614360,"timestamp":"2024-06-01T22:42:25.502319Z"}]}
{"channel":"book","type":"update","data":[{"symbol":"LTC/USDT","bids":[{"price":83.39843,"qty":1.99000000}],"asks":[],"checksum":2067273555,"timestamp":"2024-06-01T22:42:25.504485Z"}]}
{"channel":"book","type":"update","data":[{"symbol":"LTC/USDT","bids":[{"price":83.38000,"qty":41.78247865}],"asks":[],"checksum":1093925549,"timestamp":"2024-06-01T22:42:25.505660Z"}]}
{"channel":"book","type":"update","data":[{"symbol":"LTC/USDT","bids":[{"price":83.41191,"qty":8.99554355}],"asks":[],"checksum":2037585832,"timestamp":"2024-06-01T22:42:25.539430Z"}]}
{"channel":"book","type":"update","data":[{"symbol":"LTC/USDT","bids":[{"price":83.39843,"qty":0.00000000},{"price":83.38000,"qty":41.78247865}],"asks":[],"checksum":1218710608,"timestamp":"2024-06-01T22:42:25.543735Z"}]}
{"channel":"book","type":"update","data":[{"symbol":"LTC/USDT","bids":[{"price":83.41191,"qty":0.00000000},{"price":83.37663,"qty":13.36451721}],"asks":[],"checksum":2998680422,"timestamp":"2024-06-01T22:42:26.154035Z"}]}
{"channel":"book","type":"update","data":[{"symbol":"LTC/USDT","bids":[{"price":83.39843,"qty":1.99000000}],"asks":[],"checksum":1093925549,"timestamp":"2024-06-01T22:42:26.158696Z"}]}
{"channel":"book","type":"update","data":[{"symbol":"LTC/USDT","bids":[{"price":83.41190,"qty":8.99555307}],"asks":[],"checksum":3066209681,"timestamp":"2024-06-01T22:42:26.194394Z"}]}
{"channel":"book","type":"update","data":[{"symbol":"LTC/USDT","bids":[{"price":83.39843,"qty":0.00000000},{"price":83.38000,"qty":41.78247865}],"asks":[],"checksum":393098730,"timestamp":"2024-06-01T22:42:26.199127Z"}]}
{"channel":"book","type":"update","data":[{"symbol":"LTC/USDT","bids":[{"price":83.41190,"qty":0.00000000},{"price":83.37663,"qty":13.36451721}],"asks":[],"checksum":2998680422,"timestamp":"2024-06-01T22:42:26.866511Z"}]}
{"channel":"book","type":"update","data":[{"symbol":"LTC/USDT","bids":[{"price":83.39843,"qty":1.99000000}],"asks":[],"checksum":1093925549,"timestamp":"2024-06-01T22:42:26.871740Z"}]}
{"channel":"book","type":"update","data":[{"symbol":"LTC/USDT","bids":[{"price":83.41371,"qty":8.99503445}],"asks":[],"checksum":263876172,"timestamp":"2024-06-01T22:42:26.906748Z"}]}
{"channel":"book","type":"update","data":[{"symbol":"LTC/USDT","bids":[{"price":83.39843,"qty":0.00000000},{"price":83.38000,"qty":41.78247865}],"asks":[],"checksum":4021674824,"timestamp":"2024-06-01T22:42:26.912952Z"}]}
{"channel":"book","type":"update","data":[{"symbol":"LTC/USDT","bids":[{"price":83.39718,"qty":0.00000000},{"price":83.37663,"qty":13.36451721}],"asks":[],"checksum":3030646459,"timestamp":"2024-06-01T22:42:27.002374Z"}]}
{"channel":"book","type":"update","data":[{"symbol":"LTC/USDT","bids":[{"price":83.39449,"qty":0.23996160}],"asks":[],"checksum":206563218,"timestamp":"2024-06-01T22:42:27.007141Z"}]}
{"channel":"book","type":"update","data":[{"symbol":"LTC/USDT","bids":[{"price":83.41371,"qty":0.00000000},{"price":83.37663,"qty":13.36451721}],"asks":[],"checksum":4162948552,"timestamp":"2024-06-01T22:42:27.447000Z"}]}
{"channel":"book","type":"update","data":[{"symbol":"LTC/USDT","bids":[{"price":83.39843,"qty":1.99000000}],"asks":[],"checksum":2731146871,"timestamp":"2024-06-01T22:42:27.451737Z"}]}
{"channel":"book","type":"update","data":[{"symbol":"LTC/USDT","bids":[{"price":83.39717,"qty":0.00000000},{"price":83.37663,"qty":13.36451721}],"asks":[],"checksum":3920321307,"timestamp":"2024-06-01T22:42:27.587039Z"}]}
{"channel":"book","type":"update","data":[{"symbol":"LTC/USDT","bids":[{"price":83.41478,"qty":8.99452663}],"asks":[],"checksum":2880303767,"timestamp":"2024-06-01T22:42:28.100731Z"}]}
{"channel":"book","type":"update","data":[{"symbol":"LTC/USDT","bids":[],"asks":[{"price":83.45000,"qty":0.00000000},{"price":83.50781,"qty":1.53279979}],"checksum":1113097967,"timestamp":"2024-06-01T22:42:28.104037Z"}]}
{"channel":"book","type":"update","data":[{"symbol":"LTC/USDT","bids":[],"asks":[{"price":83.45000,"qty":5.22942866}],"checksum":458003016,"timestamp":"2024-06-01T22:42:28.107394Z"}]}
{"channel":"book","type":"update","data":[{"symbol":"LTC/USDT","bids":[{"price":83.41478,"qty":0.00000000},{"price":83.37663,"qty":13.36451721}],"asks":[],"checksum":4286018878,"timestamp":"2024-06-01T22:42:28.715421Z"}]}
{"channel":"book","type":"update","data":[{"symbol":"LTC/USDT","bids":[{"price":83.41406,"qty":8.99460659}],"asks":[],"checksum":1583991962,"timestamp":"2024-06-01T22:42:28.754555Z"}]}
{"channel":"book","type":"update","data":[{"symbol":"LTC/USDT","bids":[{"price":83.41406,"qty":0.00000000},{"price":83.37663,"qty":13.36451721}],"asks":[],"checksum":4286018878,"timestamp":"2024-06-01T22:42:29.293187Z"}]}
{"channel":"book","type":"update","data":[{"symbol":"LTC/USDT","bids":[{"price":83.41445,"qty":8.99464657}],"asks":[],"checksum":101037261,"timestamp":"2024-06-01T22:42:29.333293Z"}]}
{"channel":"book","type":"update","data":[{"symbol":"LTC/USDT","bids":[{"price":83.41445,"qty":0.00000000},{"price":83.37663,"qty":13.36451721}],"asks":[],"checksum":4286018878,"timestamp":"2024-06-01T22:42:29.415315Z"}]}
{"channel":"book","type":"update","data":[{"symbol":"LTC/USDT","bids":[{"price":83.41465,"qty":8.99449795}],"asks":[],"checksum":2465516616,"timestamp":"2024-06-01T22:42:29.973245Z"}]}
{"channel":"book","type":"update","data":[{"symbol":"LTC/USDT","bids":[{"price":83.41465,"qty":0.00000000},{"price":83.37663,"qty":13.36451721}],"asks":[],"checksum":4286018878,"timestamp":"2024-06-01T22:42:30.556911Z"}]}
{"channel":"book","type":"update","data":[{"symbol":"LTC/USDT","bids":[{"price":83.41372,"qty":8.99480115}],"asks":[],"checksum":3839640142,"timestamp":"2024-06-01T22:42:30.597144Z"}]}
{"channel":"book","type":"update","data":[{"symbol":"LTC/USDT","bids":[{"price":83.41372,"qty":0.00000000},{"price":83.37663,"qty":13.36451721}],"asks":[],"checksum":4286018878,"timestamp":"2024-06-01T22:42:31.178835Z"}]}
{"channel":"book","type":"update","data":[{"symbol":"LTC/USDT","bids":[{"price":83.41413,"qty":8.99520499}],"asks":[],"checksum":3578101740,"timestamp":"2024-06-01T22:42:31.785342Z"}]}
{"channel":"book","type":"update","data":[{"symbol":"LTC/USDT","bids":[{"price":83.41413,"qty":0.00000000},{"price":83.37663,"qty":13.36451721}],"asks":[],"checksum":4286018878,"timestamp":"2024-06-01T22:42:32.371449Z"}]}
{"channel":"book","type":"update","data":[{"symbol":"LTC/USDT","bids":[{"price":83.41416,"qty":8.99524186}],"asks":[],"checksum":1985650287,"timestamp":"2024-06-01T22:42:32.411636Z"}]}
{"channel":"book","type":"update","data":[{"symbol":"LTC/USDT","bids":[{"price":83.41416,"qty":0.00000000},{"price":83.37663,"qty":13.36451721}],"asks":[],"checksum":4286018878,"timestamp":"2024-06-01T22:42:33.308564Z"}]}
{"channel":"book","type":"update","data":[{"symbol":"LTC/USDT","bids":[{"price":83.41458,"qty":8.99658800}],"asks":[],"checksum":3988661535,"timestamp":"2024-06-01T22:42:33.714125Z"}]}
{"channel":"book","type":"update","data":[{"symbol":"LTC/USDT","bids":[{"price":83.41458,"qty":0.00000000},{"price":83.37663,"qty":13.36451721}],"asks":[],"checksum":4286018878,"timestamp":"2024-06-01T22:42:34.225632Z"}]}
{"channel":"book","type":"update","data":[{"symbol":"LTC/USDT","bids":[{"price":83.41461,"qty":8.99689009}],"asks":[],"checksum":3570489020,"timestamp":"2024-06-01T22:42:34.266006Z"}]}
{"channel":"book","type":"update","data":[{"symbol":"LTC/USDT","bids":[{"price":83.41461,"qty":0.00000000},{"price":83.37663,"qty":13.36451721}],"asks":[],"checksum":4286018878,"timestamp":"2024-06-01T22:42:34.851254Z"}]}
{"channel":"book","type":"update","data":[{"symbol":"LTC/USDT","bids":[{"price":83.41446,"qty":8.99694664}],"asks":[],"checksum":2363578540,"timestamp":"2024-06-01T22:42:34.891676Z"}]}
{"channel":"book","type":"update","data":[{"symbol":"LTC/USDT","bids":[{"price":83.41446,"qty":0.00000000},{"price":83.37663,"qty":13.36451721}],"asks":[],"checksum":4286018878,"timestamp":"2024-06-01T22:42:35.482829Z"}]}
{"channel":"book","type":"update","data":[{"symbol":"LTC/USDT","bids":[{"price":83.41431,"qty":8.99672074}],"asks":[],"checksum":1616096791,"timestamp":"2024-06-01T22:42:35.522979Z"}]}
{"channel":"book","type":"update","data":[{"symbol":"LTC/USDT","bids":[{"price":83.41431,"qty":0.00000000},{"price":83.37663,"qty":13.36451721}],"asks":[],"checksum":4286018878,"timestamp":"2024-06-01T22:42:36.631547Z"}]}
{"channel":"book","type":"update","data":[{"symbol":"LTC/USDT","bids":[{"price":83.41399,"qty":8.99709102}],"asks":[],"checksum":641062542,"timestamp":"2024-06-01T22:42:36.672041Z"}]}
{"channel":"book","type":"update","data":[{"symbol":"LTC/USDT","bids":[{"price":83.41399,"qty":0.00000000},{"price":83.37663,"qty":13.36451721}],"asks":[],"checksum":4286018878,"timestamp":"2024-06-01T22:42:37.326405Z"}]}
{"channel":"book","type":"update","data":[{"symbol":"LTC/USDT","bids":[{"price":83.41402,"qty":8.99712029}],"asks":[],"checksum":1793052014,"timestamp":"2024-06-01T22:42:37.366661Z"}]}
{"channel":"book","type":"update","data":[{"symbol":"LTC/USDT","bids":[{"price":83.41402,"qty":0.00000000},{"price":83.37663,"qty":13.36451721}],"asks":[],"checksum":4286018878,"timestamp":"2024-06-01T22:42:37.740905Z"}]}
{"channel":"book","type":"update","data":[{"symbol":"LTC/USDT","bids":[{"price":83.41436,"qty":8.99705810}],"asks":[],"checksum":2699632518,"timestamp":"2024-06-01T22:42:37.780901Z"}]}
{"channel":"book","type":"update","data":[{"symbol":"LTC/USDT","bids":[{"price":83.41436,"qty":0.00000000},{"price":83.37663,"qty":13.36451721}],"asks":[],"checksum":4286018878,"timestamp":"2024-06-01T22:42:38.299230Z"}]}
{"channel":"book","type":"update","data":[{"symbol":"LTC/USDT","bids":[{"price":83.41456,"qty":8.99672271}],"asks":[],"checksum":3409454542,"timestamp":"2024-06-01T22:42:38.339682Z"}]}
{"channel":"book","type":"update","data":[{"symbol":"LTC/USDT","bids":[{"price":83.41456,"qty":0.00000000},{"price":83.37663,"qty":13.36451721}],"asks":[],"checksum":4286018878,"timestamp":"2024-06-01T22:42:39.522427Z"}]}
{"channel":"book","type":"update","data":[{"symbol":"LTC/USDT","bids":[{"price":83.41473,"qty":8.99666432}],"asks":[],"checksum":138578834,"timestamp":"2024-06-01T22:42:39.562407Z"}]}
{"channel":"book","type":"update","data":[{"symbol":"LTC/USDT","bids":[{"price":83.41473,"qty":0.00000000},{"price":83.37663,"qty":13.36451721}],"asks":[],"checksum":4286018878,"timestamp":"2024-06-01T22:42:40.038083Z"}]}
{"channel":"book","type":"update","data":[{"symbol":"LTC/USDT","bids":[{"price":83.41439,"qty":8.99678375}],"asks":[],"checksum":1281396434,"timestamp":"2024-06-01T22:42:40.078345Z"}]}
{"channel":"book","type":"update","data":[{"symbol":"LTC/USDT","bids":[{"price":83.41439,"qty":0.00000000},{"price":83.37663,"qty":13.36451721}],"asks":[],"checksum":4286018878,"timestamp":"2024-06-01T22:42:40.613124Z"}]}
{"channel":"book","type":"update","data":[{"symbol":"LTC/USDT","bids":[{"price":83.38000,"qty":0.00000000},{"price":83.37542,"qty":4.79507557}],"asks":[],"checksum":1611716600,"timestamp":"2024-06-01T22:42:40.616296Z"}]}
{"channel":"book","type":"update","data":[{"symbol":"LTC/USDT","bids":[{"price":83.38000,"qty":40.35347865}],"asks":[],"checksum":1116386368,"timestamp":"2024-06-01T22:42:40.619609Z"}]}
{"channel":"book","type":"update","data":[{"symbol":"LTC/USDT","bids":[{"price":83.41444,"qty":8.99689110}],"asks":[],"checksum":144500504,"timestamp":"2024-06-01T22:42:40.653247Z"}]}
{"channel":"book","type":"update","data":[{"symbol":"LTC/USDT","bids":[{"price":83.41444,"qty":0.00000000},{"price":83.37663,"qty":13.36451721}],"asks":[],"checksum":1116386368,"timestamp":"2024-06-01T22:42:41.188970Z"}]}
{"channel":"book","type":"update","data":[{"symbol":"LTC/USDT","bids":[{"price":83.41446,"qty":8.99674983}],"asks":[],"checksum":3464005438,"timestamp":"2024-06-01T22:42:41.229130Z"}]}
{"channel":"book","type":"update","data":[{"symbol":"LTC/USDT","bids":[{"price":83.41446,"qty":0.00000000},{"price":83.37663,"qty":13.36451721}],"asks":[],"checksum":1116386368,"timestamp":"2024-06-01T22:42:41.698924Z"}]}
{"channel":"book","type":"update","data":[{"symbol":"LTC/USDT","bids":[{"price":83.41394,"qty":8.99718277}],"asks":[],"checksum":3369700097,"timestamp":"2024-06-01T22:42:42.344061Z"}]}
{"channel":"book","type":"update","data":[{"symbol":"LTC/USDT","bids":[{"price":83.39449,"qty":0.00000000},{"price":83.37663,"qty":13.36451721}],"asks":[],"checksum":3803617162,"timestamp":"2024-06-01T22:42:42.581644Z"}]}
{"channel":"book","type":"update","data":[{"symbol":"LTC/USDT","bids":[{"price":83.39449,"qty":0.47402019}],"asks":[],"checksum":2615198820,"timestamp":"2024-06-01T22:42:42.586976Z"}]}
{"channel":"book","type":"update","data":[{"symbol":"LTC/USDT","bids":[{"price":83.41394,"qty":0.00000000},{"price":83.37663,"qty":13.36451721}],"asks":[],"checksum":2229978874,"timestamp":"2024-06-01T22:42:42.879030Z"}]}
{"channel":"book","type":"update","data":[{"symbol":"LTC/USDT","bids":[{"price":83.41451,"qty":8.99697883}],"asks":[],"checksum":3334677853,"timestamp":"2024-06-01T22:42:42.919230Z"}]}
{"channel":"book","type":"update","data":[{"symbol":"LTC/USDT","bids":[{"price":83.41451,"qty":0.00000000},{"price":83.37663,"qty":13.36451721}],"asks":[],"checksum":2229978874,"timestamp":"2024-06-01T22:42:43.386687Z"}]}
{"channel":"book","type":"update","data":[{"symbol":"LTC/USDT","bids":[],"asks":[{"price":83.45000,"qty":0.00000000},{"price":83.50781,"qty":1.53279979}],"checksum":3422676133,"timestamp":"2024-06-01T22:42:43.390041Z"}]}
{"channel":"book","type":"update","data":[{"symbol":"LTC/USDT","bids":[],"asks":[{"price":83.45000,"qty":3.52792866}],"checksum":1927552665,"timestamp":"2024-06-01T22:42:43.393690Z"}]}
{"channel":"book","type":"update","data":[{"symbol":"LTC/USDT","bids":[{"price":83.41457,"qty":8.99707231}],"asks":[],"checksum":1289005495,"timestamp":"2024-06-01T22:42:43.427043Z"}]}
{"channel":"book","type":"update","data":[{"symbol":"LTC/USDT","bids":[{"price":83.41457,"qty":0.00000000},{"price":83.37663,"qty":13.36451721}],"asks":[],"checksum":1927552665,"timestamp":"2024-06-01T22:42:43.961110Z"}]}
{"channel":"book","type":"update","data":[{"symbol":"LTC/USDT","bids":[{"price":83.41459,"qty":8.99679088}],"asks":[],"checksum":999780839,"timestamp":"2024-06-01T22:42:44.536587Z"}]}
{"channel":"book","type":"update","data":[{"symbol":"LTC/USDT","bids":[{"price":83.41459,"qty":0.00000000},{"price":83.37663,"qty":13.36451721}],"asks":[],"checksum":1927552665,"timestamp":"2024-06-01T22:42:44.986893Z"}]}
{"channel":"book","type":"update","data":[{"symbol":"LTC/USDT","bids":[{"price":83.41461,"qty":8.99678587}],"asks":[],"checksum":2929421430,"timestamp":"2024-06-01T22:42:45.027344Z"}]}
{"channel":"book","type":"update","data":[{"symbol":"LTC/USDT","bids":[{"price":83.41461,"qty":0.00000000},{"price":83.37663,"qty":13.36451721}],"asks":[],"checksum":1927552665,"timestamp":"2024-06-01T22:42:45.097292Z"}]}
{"channel":"book","type":"update","data":[{"symbol":"LTC/USDT","bids":[{"price":83.41482,"qty":8.99674062}],"asks":[],"checksum":3776475409,"timestamp":"2024-06-01T22:42:45.585920Z"}]}
{"channel":"book","type":"update","data":[{"symbol":"LTC/USDT","bids":[{"price":83.41482,"qty":0.00000000},{"price":83.37663,"qty":13.36451721}],"asks":[],"checksum":1927552665,"timestamp":"2024-06-01T22:42:46.097246Z"}]}
{"channel":"book","type":"update","data":[{"symbol":"LTC/USDT","bids":[],"asks":[{"price":83.45908,"qty":0.00000000},{"price":83.50781,"qty":1.53279979}],"checksum":3231644031,"timestamp":"2024-06-01T22:42:46.336494Z"}]}
{"channel":"book","type":"update","data":[{"symbol":"LTC/USDT","bids":[],"asks":[{"price":83.46087,"qty":7.86100000}],"checksum":1957483223,"timestamp":"2024-06-01T22:42:46.338989Z"}]}
{"channel":"book","type":"update","data":[{"symbol":"LTC/USDT","bids":[{"price":83.41481,"qty":8.99674469}],"asks":[],"checksum":2310477295,"timestamp":"2024-06-01T22:42:46.743845Z"}]}
{"channel":"book","type":"update","data":[{"symbol":"LTC/USDT","bids":[{"price":83.41481,"qty":0.00000000},{"price":83.37663,"qty":13.36451721}],"asks":[],"checksum":1957483223,"timestamp":"2024-06-01T22:42:47.196817Z"}]}
{"channel":"book","type":"update","data":[{"symbol":"LTC/USDT","bids":[{"price":83.41488,"qty":8.99668376}],"asks":[],"checksum":3493720451,"timestamp":"2024-06-01T22:42:47.237161Z"}]}
{"channel":"book","type":"update","data":[{"symbol":"LTC/USDT","bids":[{"price":83.41488,"qty":0.00000000},{"price":83.37663,"qty":13.36451721}],"asks":[],"checksum":1957483223,"timestamp":"2024-06-01T22:42:47.759229Z"}]}
{"channel":"book","type":"update","data":[{"symbol":"LTC/USDT","bids":[{"price":83.41481,"qty":8.99682089}],"asks":[],"checksum":578104366,"timestamp":"2024-06-01T22:42:48.359902Z"}]}
{"channel":"book","type":"update","data":[{"symbol":"LTC/USDT","bids":[{"price":83.41481,"qty":0.00000000},{"price":83.37663,"qty":13.36451721}],"asks":[],"checksum":1957483223,"timestamp":"2024-06-01T22:42:48.811499Z"}]}
{"channel":"book","type":"update","data":[{"symbol":"LTC/USDT","bids":[{"price":83.41504,"qty":8.99697864}],"asks":[],"checksum":1223433833,"timestamp":"2024-06-01T22:42:48.851700Z"}]}
{"channel":"book","type":"update","data":[{"symbol":"LTC/USDT","bids":[{"price":83.39449,"qty":0.00000000},{"price":83.37663,"qty":13.36451721}],"asks":[],"checksum":824049921,"timestamp":"2024-06-01T22:42:48.866703Z"}]}
{"channel":"book","type":"update","data":[{"symbol":"LTC/USDT","bids":[{"price":83.39449,"qty":0.24697860}],"asks":[],"checksum":3949725539,"timestamp":"2024-06-01T22:42:48.869766Z"}]}
{"channel":"book","type":"update","data":[{"symbol":"LTC/USDT","bids":[{"price":83.41504,"qty":0.00000000},{"price":83.37663,"qty":13.36451721}],"asks":[],"checksum":19758996,"timestamp":"2024-06-01T22:42:50.859904Z"}]}
{"channel":"book","type":"update","data":[{"symbol":"LTC/USDT","bids":[],"asks":[{"price":83.49333,"qty":0.00000000},{"price":83.50781,"qty":1.53279979}],"checksum":3365857329,"timestamp":"2024-06-01T22:42:50.860878Z"}]}
{"channel":"book","type":"update","data":[{"symbol":"LTC/USDT","bids":[{"price":83.41484,"qty":8.99674250}],"asks":[],"checksum":1879216335,"timestamp":"2024-06-01T22:42:50.899991Z"}]}
{"channel":"book","type":"update","data":[{"symbol":"LTC/USDT","bids":[],"asks":[{"price":83.49348,"qty":3.09000000}],"checksum":3469825879,"timestamp":"2024-06-01T22:42:51.109179Z"}]}
{"channel":"book","type":"update","data":[{"symbol":"LTC/USDT","bids":[{"price":83.41484,"qty":0.00000000},{"price":83.37663,"qty":13.36451721}],"asks":[],"checksum":921968768,"timestamp":"2024-06-01T22:42:51.493094Z"}]}
{"channel":"book","type":"update","data":[{"symbol":"LTC/USDT","bids":[{"price":83.41503,"qty":8.99670298}],"asks":[],"checksum":2960930738,"timestamp":"2024-06-01T22:42:51.532984Z"}]}
{"channel":"book","type":"update","data":[{"symbol":"LTC/USDT","bids":[],"asks":[{"price":83.49348,"qty":0.00000000},{"price":83.50781,"qty":1.53279979}],"checksum":246411306,"timestamp":"2024-06-01T22:42:52.143966Z"}]}
{"channel":"book","type":"update","data":[{"symbol":"LTC/USDT","bids":[],"asks":[{"price":83.49351,"qty":2.29000000}],"checksum":1259005063,"timestamp":"2024-06-01T22:42:52.273512Z"}]}
{"channel":"book","type":"update","data":[{"symbol":"LTC/USDT","bids":[{"price":83.41503,"qty":0.00000000},{"price":83.37663,"qty":13.36451721}],"asks":[],"checksum":1622970992,"timestamp":"2024-06-01T22:42:52.512406Z"}]}
{"channel":"book","type":"update","data":[{"symbol":"LTC/USDT","bids":[{"price":83.41649,"qty":8.99625544}],"asks":[],"checksum":1037415876,"timestamp":"2024-06-01T22:42:52.552480Z"}]}
{"channel":"book","type":"update","data":[{"symbol":"LTC/USDT","bids":[{"price":83.41649,"qty":0.00000000},{"price":83.37663,"qty":13.36451721}],"asks":[],"checksum":1622970992,"timestamp":"2024-06-01T22:42:53.071692Z"}]}
{"channel":"book","type":"update","data":[{"symbol":"LTC/USDT","bids":[{"price":83.41501,"qty":8.99668009}],"asks":[],"checksum":2478798165,"timestamp":"2024-06-01T22:42:53.112075Z"}]}
{"channel":"book","type":"update","data":[{"symbol":"LTC/USDT","bids":[],"asks":[{"price":83.49351,"qty":0.00000000},{"price":83.50781,"qty":1.53279979}],"checksum":3592053240,"timestamp":"2024-06-01T22:42:53.373016Z"}]}
{"channel":"book","type":"update","data":[{"symbol":"LTC/USDT","bids":[{"price":83.41501,"qty":0.00000000},{"price":83.37663,"qty":13.36451721}],"asks":[],"checksum":3365857329,"timestamp":"2024-06-01T22:42:53.631229Z"}]}
{"channel":"book","type":"update","data":[{"symbol":"LTC/USDT","bids":[],"asks":[{"price":83.49392,"qty":2.74000000}],"checksum":132456005,"timestamp":"2024-06-01T22:42:53.635863Z"}]}
{"channel":"book","type":"update","data":[{"symbol":"LTC/USDT","bids":[],"asks":[{"price":83.49392,"qty":0.00000000},{"price":83.50781,"qty":1.53279979}],"checksum":3365857329,"timestamp":"2024-06-01T22:42:53.636141Z"}]}
{"channel":"book","type":"update","data":[{"symbol":"LTC/USDT","bids":[{"price":83.41709,"qty":8.99608261}],"asks":[],"checksum":1339756519,"timestamp":"2024-06-01T22:42:53.671625Z"}]}
{"channel":"book","type":"update","data":[{"symbol":"LTC/USDT","bids":[],"asks":[{"price":83.49417,"qty":2.82000000}],"checksum":3822095349,"timestamp":"2024-06-01T22:42:54.059211Z"}]}
{"channel":"book","type":"update","data":[{"symbol":"LTC/USDT","bids":[{"price":83.41709,"qty":0.00000000},{"price":83.37663,"qty":13.36451721}],"asks":[],"checksum":999002877,"timestamp":"2024-06-01T22:42:54.127968Z"}]}
{"channel":"book","type":"update","data":[{"symbol":"LTC/USDT","bids":[],"asks":[{"price":83.49417,"qty":0.00000000},{"price":83.50781,"qty":1.53279979}],"checksum":3365857329,"timestamp":"2024-06-01T22:42:54.138117Z"}]}
{"channel":"book","type":"update","data":[{"symbol":"LTC/USDT","bids":[{"price":83.41703,"qty":8.99608358}],"asks":[],"checksum":892170330,"timestamp":"2024-06-01T22:42:54.168240Z"}]}
{"channel":"book","type":"update","data":[{"symbol":"LTC/USDT","bids":[],"asks":[{"price":83.49543,"qty":2.23000000}],"checksum":3182966364,"timestamp":"2024-06-01T22:42:54.347087Z"}]}
{"channel":"book","type":"update","data":[{"symbol":"LTC/USDT","bids":[],"asks":[{"price":83.49543,"qty":0.00000000},{"price":83.50781,"qty":1.53279979}],"checksum":892170330,"timestamp":"2024-06-01T22:42:54.589491Z"}]}
{"channel":"book","type":"update","data":[{"symbol":"LTC/USDT","bids":[{"price":83.41703,"qty":0.00000000},{"price":83.37663,"qty":13.36451721}],"asks":[],"checksum":3365857329,"timestamp":"2024-06-01T22:42:54.686813Z"}]}
{"channel":"book","type":"update","data":[{"symbol":"LTC/USDT","bids":[{"price":83.41719,"qty":8.99620457}],"asks":[],"checksum":1738202695,"timestamp":"2024-06-01T22:42:54.727192Z"}]}
{"channel":"book","type":"update","data":[{"symbol":"LTC/USDT","bids":[],"asks":[{"price":83.49599,"qty":2.83000000}],"checksum":2296263229,"timestamp":"2024-06-01T22:42:54.732492Z"}]}
{"channel":"book","type":"update","data":[{"symbol":"LTC/USDT","bids":[{"price":83.41719,"qty":0.00000000},{"price":83.37663,"qty":13.36451721}],"asks":[],"checksum":2023830783,"timestamp":"2024-06-01T22:42:55.240741Z"}]}
{"channel":"book","type":"update","data":[{"symbol":"LTC/USDT","bids":[{"price":83.41713,"qty":8.99601833}],"asks":[],"checksum":1327549019,"timestamp":"2024-06-01T22:42:55.281028Z"}]}
{"channel":"book","type":"update","data":[{"symbol":"LTC/USDT","bids":[],"asks":[{"price":83.49599,"qty":0.00000000},{"price":83.50781,"qty":1.53279979}],"checksum":2690917921,"timestamp":"2024-06-01T22:42:55.641276Z"}]}
{"channel":"book","type":"update","data":[{"symbol":"LTC/USDT","bids":[],"asks":[{"price":83.49649,"qty":2.91000000}],"checksum":3309551312,"timestamp":"2024-06-01T22:42:55.778351Z"}]}
{"channel":"book","type":"update","data":[{"symbol":"LTC/USDT","bids":[{"price":83.41713,"qty":0.00000000},{"price":83.37663,"qty":13.36451721}],"asks":[],"checksum":37817635,"timestamp":"2024-06-01T22:42:56.339872Z"}]}
{"channel":"book","type":"update","data":[{"symbol":"LTC/USDT","bids":[{"price":83.38000,"qty":0.00000000},{"price":83.37542,"qty":4.79507557}],"asks":[],"checksum":1956827666,"timestamp":"2024-06-01T22:42:56.345018Z"}]}
{"channel":"book","type":"update","data":[{"symbol":"LTC/USDT","bids":[{"price":83.38000,"qty":36.72072865}],"asks":[],"checksum":3880908992,"timestamp":"2024-06-01T22:42:56.350690Z"}]}
{"channel":"book","type":"update","data":[{"symbol":"LTC/USDT","bids":[{"price":83.41614,"qty":8.99661651}],"asks":[],"checksum":1550328327,"timestamp":"2024-06-01T22:42:56.379952Z"}]}
{"channel":"book","type":"update","data":[{"symbol":"LTC/USDT","bids":[],"asks":[{"price":83.49649,"qty":0.00000000},{"price":83.50781,"qty":1.53279979}],"checksum":961526518,"timestamp":"2024-06-01T22:42:56.409144Z"}]}
{"channel":"book","type":"update","data":[{"symbol":"LTC/USDT","bids":[],"asks":[{"price":83.50132,"qty":2.58000000}],"checksum":2466070855,"timestamp":"2024-06-01T22:42:56.600270Z"}]}
{"channel":"book","type":"update","data":[{"symbol":"LTC/USDT","bids":[],"asks":[{"price":83.50131,"qty":1.53279979}],"checksum":213331798,"timestamp":"2024-06-01T22:42:56.774581Z"}]}
{"channel":"book","type":"update","data":[{"symbol":"LTC/USDT","bids":[{"price":83.41614,"qty":0.00000000},{"price":83.37663,"qty":13.36451721}],"asks":[],"checksum":4218242735,"timestamp":"2024-06-01T22:42:56.891946Z"}]}
{"channel":"book","type":"update","data":[{"symbol":"LTC/USDT","bids":[{"price":83.41467,"qty":8.99703960}],"asks":[],"checksum":1345976870,"timestamp":"2024-06-01T22:42:56.932322Z"}]}
{"channel":"book","type":"update","data":[{"symbol":"LTC/USDT","bids":[{"price":83.41467,"qty":0.00000000},{"price":83.37663,"qty":13.36451721}],"asks":[],"checksum":4218242735,"timestamp":"2024-06-01T22:42:57.380643Z"}]}
{"channel":"book","type":"update","data":[{"symbol":"LTC/USDT","bids":[{"price":83.41472,"qty":8.99673636}],"asks":[],"checksum":521363393,"timestamp":"2024-06-01T22:42:57.421023Z"}]}
{"channel":"book","type":"update","data":[{"symbol":"LTC/USDT","bids":[{"price":83.41472,"qty":0.00000000},{"price":83.37663,"qty":13.36451721}],"asks":[],"checksum":4218242735,"timestamp":"2024-06-01T22:42:58.443775Z"}]}
{"channel":"book","type":"update","data":[{"symbol":"LTC/USDT","bids":[],"asks":[{"price":83.45000,"qty":0.00000000},{"price":83.50132,"qty":2.58000000}],"checksum":1869592834,"timestamp":"2024-06-01T22:42:58.447104Z"}]}
{"channel":"book","type":"update","data":[{"symbol":"LTC/USDT","bids":[],"asks":[{"price":83.45000,"qty":5.86667866}],"checksum":3441279771,"timestamp":"2024-06-01T22:42:58.450553Z"}]}
{"channel":"book","type":"update","data":[{"symbol":"LTC/USDT","bids":[{"price":83.41475,"qty":8.99673636}],"asks":[],"checksum":3823833855,"timestamp":"2024-06-01T22:42:58.484013Z"}]}
{"channel":"book","type":"update","data":[{"symbol":"LTC/USDT","bids":[{"price":83.41475,"qty":0.00000000},{"price":83.37663,"qty":13.36451721}],"asks":[],"checksum":3441279771,"timestamp":"2024-06-01T22:42:58.934040Z"}]}
{"channel":"book","type":"update","data":[{"symbol":"LTC/USDT","bids":[{"price":83.41442,"qty":8.99685484}],"asks":[],"checksum":2016206573,"timestamp":"2024-06-01T22:42:58.974413Z"}]}
{"channel":"book","type":"update","data":[{"symbol":"LTC/USDT","bids":[{"price":83.41442,"qty":0.00000000},{"price":83.37663,"qty":13.36451721}],"asks":[],"checksum":3441279771,"timestamp":"2024-06-01T22:42:59.491231Z"}]}
{"channel":"book","type":"update","data":[{"symbol":"LTC/USDT","bids":[{"price":83.41485,"qty":8.99674965}],"asks":[],"checksum":395334561,"timestamp":"2024-06-01T22:42:59.531585Z"}]}
{"channel":"book","type":"update","data":[{"symbol":"LTC/USDT","bids":[{"price":83.41485,"qty":0.00000000},{"price":83.37663,"qty":13.36451721}],"asks":[],"checksum":3441279771,"timestamp":"2024-06-01T22:43:00.043488Z"}]}
{"channel":"book","type":"update","data":[{"symbol":"LTC/USDT","bids":[{"price":83.41518,"qty":8.99663225}],"asks":[],"checksum":952730049,"timestamp":"2024-06-01T22:43:00.083842Z"}]}
{"channel":"book","type":"update","data":[{"symbol":"LTC/USDT","bids":[{"price":83.41518,"qty":0.00000000},{"price":83.37663,"qty":13.36451721}],"asks":[],"checksum":3441279771,"timestamp":"2024-06-01T22:43:00.696470Z"}]}
{"channel":"book","type":"update","data":[{"symbol":"LTC/USDT","bids":[{"price":83.41479,"qty":8.99677648}],"asks":[],"checksum":1772624914,"timestamp":"2024-06-01T22:43:00.736493Z"}]}
