{"channel":"book","type":"snapshot","data":[{"symbol":"SOL/GBP","bids":[{"price":130.67,"qty":32.98133690},{"price":130.66,"qty":2.20000000},{"price":130.64,"qty":24.65141906},{"price":130.63,"qty":47.49878506},{"price":130.60,"qty":64.03947017},{"price":130.58,"qty":11.17072981},{"price":130.57,"qty":221.08280718},{"price":130.56,"qty":30.04372253},{"price":130.55,"qty":18.86004365},{"price":130.54,"qty":26.45000000}],"asks":[{"price":130.70,"qty":0.93250500},{"price":130.71,"qty":30.01091377},{"price":130.76,"qty":5.58379308},{"price":130.77,"qty":29.99804105},{"price":130.79,"qty":28.05448351},{"price":130.83,"qty":6.26037837},{"price":130.86,"qty":59.92720458},{"price":130.88,"qty":6.20000000},{"price":130.89,"qty":17.41247203},{"price":130.90,"qty":6.53296266}],"checksum":1107795023}]}
{"channel":"book","type":"update","data":[{"symbol":"SOL/GBP","bids":[{"price":130.57,"qty":251.03280718}],"asks":[],"checksum":4007488962,"timestamp":"2024-06-01T22:42:18.729139Z"}]}
{"channel":"book","type":"update","data":[{"symbol":"SOL/GBP","bids":[],"asks":[{"price":130.76,"qty":0.00000000},{"price":130.94,"qty":5.64000000},{"price":130.70,"qty":6.51629808}],"checksum":2733888187,"timestamp":"2024-06-01T22:42:18.782806Z"}]}
{"channel":"book","type":"update","data":[{"symbol":"SOL/GBP","bids":[{"price":130.55,"qty":12.60000000}],"asks":[],"checksum":3905221448,"timestamp":"2024-06-01T22:42:18.889751Z"}]}
{"channel":"book","type":"update","data":[{"symbol":"SOL/GBP","bids":[{"price":130.56,"qty":36.30430738}],"asks":[],"checksum":3933664123,"timestamp":"2024-06-01T22:42:19.135453Z"}]}
{"channel":"book","type":"update","data":[{"symbol":"SOL/GBP","bids":[],"asks":[{"price":130.71,"qty":0.00000000},{"price":130.95,"qty":18.88107173}],"checksum":3563839493,"timestamp":"2024-06-01T22:42:19.220020Z"}]}
{"channel":"book","type":"update","data":[{"symbol":"SOL/GBP","bids":[],"asks":[{"price":130.72,"qty":30.01050102}],"checksum":1830876654,"timestamp":"2024-06-01T22:42:19.223165Z"}]}
{"channel":"book","type":"update","data":[{"symbol":"SOL/GBP","bids":[],"asks":[{"price":130.70,"qty":0.93250500},{"price":130.76,"qty":5.58379308}],"checksum":554584727,"timestamp":"2024-06-01T22:42:19.223188Z"}]}
{"channel":"book","type":"update","data":[{"symbol":"SOL/GBP","bids":[],"asks":[{"price":130.72,"qty":32.21050102}],"checksum":1258121306,"timestamp":"2024-06-01T22:42:19.226168Z"}]}
{"channel":"book","type":"update","data":[{"symbol":"SOL/GBP","bids":[],"asks":[{"price":130.76,"qty":0.00000000},{"price":130.94,"qty":5.64000000},{"price":130.71,"qty":5.58379308}],"checksum":2571184306,"timestamp":"2024-06-01T22:42:19.477915Z"}]}
{"channel":"book","type":"update","data":[{"symbol":"SOL/GBP","bids":[{"price":130.57,"qty":41.41000000}],"asks":[],"checksum":2802842554,"timestamp":"2024-06-01T22:42:19.691614Z"}]}
{"channel":"book","type":"update","data":[{"symbol":"SOL/GBP","bids":[{"price":130.60,"qty":5.18219342}],"asks":[],"checksum":3097786185,"timestamp":"2024-06-01T22:42:19.691629Z"}]}
{"channel":"book","type":"update","data":[{"symbol":"SOL/GBP","bids":[{"price":130.64,"qty":0.93264000}],"asks":[],"checksum":2260063556,"timestamp":"2024-06-01T22:42:19.691701Z"}]}
{"channel":"book","type":"update","data":[{"symbol":"SOL/GBP","bids":[{"price":130.58,"qty":6.53296266},{"price":130.59,"qty":4.63741228}],"asks":[],"checksum":3849967688,"timestamp":"2024-06-01T22:42:19.695640Z"}]}
{"channel":"book","type":"update","data":[{"symbol":"SOL/GBP","bids":[{"price":130.64,"qty":12.93858649}],"asks":[],"checksum":212867453,"timestamp":"2024-06-01T22:42:19.732915Z"}]}
{"channel":"book","type":"update","data":[{"symbol":"SOL/GBP","bids":[{"price":130.58,"qty":241.08272788}],"asks":[],"checksum":401492543,"timestamp":"2024-06-01T22:42:19.733003Z"}]}
{"channel":"book","type":"update","data":[{"symbol":"SOL/GBP","bids":[],"asks":[{"price":130.72,"qty":2.20000000}],"checksum":3603038382,"timestamp":"2024-06-01T22:42:19.735134Z"}]}
{"channel":"book","type":"update","data":[{"symbol":"SOL/GBP","bids":[],"asks":[{"price":130.72,"qty":0.00000000},{"price":130.94,"qty":5.64000000}],"checksum":1508628389,"timestamp":"2024-06-01T22:42:19.737900Z"}]}
{"channel":"book","type":"update","data":[{"symbol":"SOL/GBP","bids":[],"asks":[{"price":130.71,"qty":0.00000000},{"price":130.95,"qty":18.88107173},{"price":130.76,"qty":5.58379308}],"checksum":3439220084,"timestamp":"2024-06-01T22:42:19.738178Z"}]}
{"channel":"book","type":"update","data":[{"symbol":"SOL/GBP","bids":[],"asks":[{"price":130.71,"qty":30.01105199}],"checksum":3789160799,"timestamp":"2024-06-01T22:42:19.738820Z"}]}
{"channel":"book","type":"update","data":[{"symbol":"SOL/GBP","bids":[],"asks":[{"price":130.75,"qty":2.20000000}],"checksum":1004648862,"timestamp":"2024-06-01T22:42:19.740922Z"}]}
{"channel":"book","type":"update","data":[{"symbol":"SOL/GBP","bids":[],"asks":[{"price":130.76,"qty":0.00000000},{"price":130.90,"qty":6.53296266},{"price":130.70,"qty":6.51629808}],"checksum":3725601614,"timestamp":"2024-06-01T22:42:19.949077Z"}]}
{"channel":"book","type":"update","data":[{"symbol":"SOL/GBP","bids":[],"asks":[{"price":130.75,"qty":0.00000000},{"price":130.94,"qty":5.64000000}],"checksum":4231159729,"timestamp":"2024-06-01T22:42:19.951766Z"}]}
{"channel":"book","type":"update","data":[{"symbol":"SOL/GBP","bids":[],"asks":[{"price":130.71,"qty":0.00000000},{"price":130.95,"qty":18.88107173}],"checksum":1814140541,"timestamp":"2024-06-01T22:42:20.631620Z"}]}
{"channel":"book","type":"update","data":[{"symbol":"SOL/GBP","bids":[],"asks":[{"price":130.70,"qty":0.93250500},{"price":130.76,"qty":5.58379308}],"checksum":3439220084,"timestamp":"2024-06-01T22:42:20.634621Z"}]}
{"channel":"book","type":"update","data":[{"symbol":"SOL/GBP","bids":[],"asks":[{"price":130.72,"qty":30.01046334}],"checksum":3911860663,"timestamp":"2024-06-01T22:42:20.635217Z"}]}
{"channel":"book","type":"update","data":[{"symbol":"SOL/GBP","bids":[],"asks":[{"price":130.75,"qty":2.20000000}],"checksum":856815990,"timestamp":"2024-06-01T22:42:20.637199Z"}]}
{"channel":"book","type":"update","data":[{"symbol":"SOL/GBP","bids":[],"asks":[{"price":130.70,"qty":0.00000000},{"price":130.90,"qty":6.53296266},{"price":130.69,"qty":0.93250800}],"checksum":3247554208,"timestamp":"2024-06-01T22:42:20.683842Z"}]}
{"channel":"book","type":"update","data":[{"symbol":"SOL/GBP","bids":[],"asks":[{"price":130.69,"qty":0.00000000},{"price":130.90,"qty":6.53296266},{"price":130.71,"qty":0.93242800}],"checksum":3538175260,"timestamp":"2024-06-01T22:42:20.841726Z"}]}
{"channel":"book","type":"update","data":[{"symbol":"SOL/GBP","bids":[{"price":130.57,"qty":11.46000000},{"price":130.58,"qty":271.03272788}],"asks":[],"checksum":3183984790,"timestamp":"2024-06-01T22:42:20.878097Z"}]}
{"channel":"book","type":"update","data":[{"symbol":"SOL/GBP","bids":[],"asks":[{"price":130.76,"qty":0.00000000},{"price":130.90,"qty":6.53296266},{"price":130.71,"qty":6.51622108}],"checksum":3327910761,"timestamp":"2024-06-01T22:42:20.903643Z"}]}
{"channel":"book","type":"update","data":[{"symbol":"SOL/GBP","bids":[],"asks":[{"price":130.75,"qty":0.00000000},{"price":130.94,"qty":5.64000000}],"checksum":3833173910,"timestamp":"2024-06-01T22:42:20.906388Z"}]}
{"channel":"book","type":"update","data":[{"symbol":"SOL/GBP","bids":[{"price":130.58,"qty":36.48296266}],"asks":[],"checksum":4072903985,"timestamp":"2024-06-01T22:42:21.755247Z"}]}
{"channel":"book","type":"update","data":[{"symbol":"SOL/GBP","bids":[{"price":130.59,"qty":168.91018211}],"asks":[],"checksum":441486501,"timestamp":"2024-06-01T22:42:21.756347Z"}]}
{"channel":"book","type":"update","data":[{"symbol":"SOL/GBP","bids":[{"price":130.59,"qty":164.27276983},{"price":130.60,"qty":9.81936972}],"asks":[],"checksum":1900511639,"timestamp":"2024-06-01T22:42:21.759571Z"}]}
{"channel":"book","type":"update","data":[{"symbol":"SOL/GBP","bids":[{"price":130.67,"qty":2.96269227}],"asks":[],"checksum":3745501137,"timestamp":"2024-06-01T22:42:22.653650Z"}]}
{"channel":"book","type":"update","data":[{"symbol":"SOL/GBP","bids":[{"price":130.68,"qty":30.01771293}],"asks":[],"checksum":2650693676,"timestamp":"2024-06-01T22:42:22.657498Z"}]}
{"channel":"book","type":"update","data":[{"symbol":"SOL/GBP","bids":[],"asks":[{"price":130.71,"qty":5.58379308},{"price":130.70,"qty":0.93243300}],"checksum":43692382,"timestamp":"2024-06-01T22:42:23.330378Z"}]}
{"channel":"book","type":"update","data":[{"symbol":"SOL/GBP","bids":[{"price":130.58,"qty":6.53296266},{"price":130.59,"qty":194.22276983}],"asks":[],"checksum":2793840920,"timestamp":"2024-06-01T22:42:24.161545Z"}]}
{"channel":"book","type":"update","data":[{"symbol":"SOL/GBP","bids":[],"asks":[{"price":130.72,"qty":0.00000000},{"price":130.94,"qty":5.64000000}],"checksum":4098355847,"timestamp":"2024-06-01T22:42:24.230298Z"}]}
{"channel":"book","type":"update","data":[{"symbol":"SOL/GBP","bids":[],"asks":[{"price":130.73,"qty":30.00833087}],"checksum":366874161,"timestamp":"2024-06-01T22:42:24.233236Z"}]}
{"channel":"book","type":"update","data":[{"symbol":"SOL/GBP","bids":[],"asks":[{"price":130.71,"qty":0.00000000},{"price":130.94,"qty":5.64000000},{"price":130.72,"qty":5.58379308}],"checksum":44731991,"timestamp":"2024-06-01T22:42:24.247264Z"}]}
{"channel":"book","type":"update","data":[{"symbol":"SOL/GBP","bids":[{"price":130.68,"qty":0.00000000},{"price":130.55,"qty":12.60000000}],"asks":[],"checksum":3367661580,"timestamp":"2024-06-01T22:42:24.321504Z"}]}
{"channel":"book","type":"update","data":[{"symbol":"SOL/GBP","bids":[{"price":130.69,"qty":30.01550182}],"asks":[],"checksum":3524846628,"timestamp":"2024-06-01T22:42:24.324828Z"}]}
{"channel":"book","type":"update","data":[{"symbol":"SOL/GBP","bids":[{"price":130.69,"qty":0.00000000},{"price":130.55,"qty":12.60000000}],"asks":[],"checksum":3367661580,"timestamp":"2024-06-01T22:42:24.586384Z"}]}
{"channel":"book","type":"update","data":[{"symbol":"SOL/GBP","bids":[{"price":130.68,"qty":30.01597979}],"asks":[],"checksum":468083965,"timestamp":"2024-06-01T22:42:24.590482Z"}]}
{"channel":"book","type":"update","data":[{"symbol":"SOL/GBP","bids":[{"price":130.66,"qty":0.00000000},{"price":130.55,"qty":12.60000000}],"asks":[],"checksum":3612471799,"timestamp":"2024-06-01T22:42:24.593112Z"}]}
{"channel":"book","type":"update","data":[{"symbol":"SOL/GBP","bids":[{"price":130.68,"qty":32.21597979}],"asks":[],"checksum":1573534832,"timestamp":"2024-06-01T22:42:24.593299Z"}]}
{"channel":"book","type":"update","data":[{"symbol":"SOL/GBP","bids":[{"price":130.67,"qty":0.00000000},{"price":130.54,"qty":26.45000000}],"asks":[],"checksum":70725837,"timestamp":"2024-06-01T22:42:24.595820Z"}]}
{"channel":"book","type":"update","data":[{"symbol":"SOL/GBP","bids":[{"price":130.65,"qty":2.96314580}],"asks":[],"checksum":1146450007,"timestamp":"2024-06-01T22:42:24.596037Z"}]}
{"channel":"book","type":"update","data":[{"symbol":"SOL/GBP","bids":[{"price":130.68,"qty":2.20000000}],"asks":[],"checksum":3117824931,"timestamp":"2024-06-01T22:42:25.204895Z"}]}
{"channel":"book","type":"update","data":[{"symbol":"SOL/GBP","bids":[{"price":130.68,"qty":0.00000000},{"price":130.54,"qty":26.45000000}],"asks":[],"checksum":280259914,"timestamp":"2024-06-01T22:42:25.207616Z"}]}
{"channel":"book","type":"update","data":[{"symbol":"SOL/GBP","bids":[{"price":130.66,"qty":2.20000000}],"asks":[],"checksum":3240812096,"timestamp":"2024-06-01T22:42:25.207632Z"}]}
{"channel":"book","type":"update","data":[{"symbol":"SOL/GBP","bids":[{"price":130.69,"qty":30.01550182}],"asks":[],"checksum":3855070746,"timestamp":"2024-06-01T22:42:25.208189Z"}]}
{"channel":"book","type":"update","data":[{"symbol":"SOL/GBP","bids":[{"price":130.59,"qty":164.27276983},{"price":130.60,"qty":39.76936972}],"asks":[],"checksum":1541293289,"timestamp":"2024-06-01T22:42:25.992064Z"}]}
{"channel":"book","type":"update","data":[{"symbol":"SOL/GBP","bids":[{"price":130.69,"qty":0.00000000},{"price":130.55,"qty":12.60000000}],"asks":[],"checksum":1974819414,"timestamp":"2024-06-01T22:42:26.011981Z"}]}
{"channel":"book","type":"update","data":[{"symbol":"SOL/GBP","bids":[{"price":130.68,"qty":30.01596601}],"asks":[],"checksum":2504083681,"timestamp":"2024-06-01T22:42:26.015497Z"}]}
{"channel":"book","type":"update","data":[{"symbol":"SOL/GBP","bids":[{"price":130.59,"qty":0.00000000},{"price":130.55,"qty":12.60000000}],"asks":[],"checksum":2006674572,"timestamp":"2024-06-01T22:42:26.024371Z"}]}
{"channel":"book","type":"update","data":[{"symbol":"SOL/GBP","bids":[{"price":130.64,"qty":0.93264000}],"asks":[],"checksum":1776715746,"timestamp":"2024-06-01T22:42:26.024534Z"}]}
{"channel":"book","type":"update","data":[{"symbol":"SOL/GBP","bids":[{"price":130.64,"qty":24.65141906}],"asks":[],"checksum":4076320378,"timestamp":"2024-06-01T22:42:26.025437Z"}]}
{"channel":"book","type":"update","data":[{"symbol":"SOL/GBP","bids":[{"price":130.60,"qty":98.62664647}],"asks":[],"checksum":3417169656,"timestamp":"2024-06-01T22:42:26.025513Z"}]}
{"channel":"book","type":"update","data":[{"symbol":"SOL/GBP","bids":[{"price":130.57,"qty":232.74988650}],"asks":[],"checksum":2287918853,"timestamp":"2024-06-01T22:42:26.025586Z"}]}
{"channel":"book","type":"update","data":[{"symbol":"SOL/GBP","bids":[],"asks":[{"price":130.86,"qty":29.97720458}],"checksum":668035304,"timestamp":"2024-06-01T22:42:26.034161Z"}]}
{"channel":"book","type":"update","data":[{"symbol":"SOL/GBP","bids":[{"price":130.60,"qty":93.98947017},{"price":130.59,"qty":4.63750718}],"asks":[],"checksum":1915481891,"timestamp":"2024-06-01T22:42:26.047638Z"}]}
{"channel":"book","type":"update","data":[{"symbol":"SOL/GBP","bids":[{"price":130.68,"qty":0.00000000},{"price":130.55,"qty":12.60000000}],"asks":[],"checksum":234818962,"timestamp":"2024-06-01T22:42:26.048171Z"}]}
{"channel":"book","type":"update","data":[{"symbol":"SOL/GBP","bids":[],"asks":[{"price":130.79,"qty":10.23070234}],"checksum":1897047032,"timestamp":"2024-06-01T22:42:26.057385Z"}]}
{"channel":"book","type":"update","data":[{"symbol":"SOL/GBP","bids":[],"asks":[{"price":130.80,"qty":17.82378117}],"checksum":719421243,"timestamp":"2024-06-01T22:42:26.062929Z"}]}
{"channel":"book","type":"update","data":[{"symbol":"SOL/GBP","bids":[{"price":130.65,"qty":0.00000000},{"price":130.54,"qty":26.45000000}],"asks":[],"checksum":3301017792,"timestamp":"2024-06-01T22:42:26.066093Z"}]}
{"channel":"book","type":"update","data":[{"symbol":"SOL/GBP","bids":[{"price":130.67,"qty":2.96269227}],"asks":[],"checksum":594661751,"timestamp":"2024-06-01T22:42:26.066111Z"}]}
{"channel":"book","type":"update","data":[{"symbol":"SOL/GBP","bids":[],"asks":[{"price":130.73,"qty":0.00000000},{"price":130.90,"qty":6.53296266}],"checksum":1295368986,"timestamp":"2024-06-01T22:42:26.069379Z"}]}
{"channel":"book","type":"update","data":[{"symbol":"SOL/GBP","bids":[{"price":130.59,"qty":0.00000000},{"price":130.54,"qty":26.45000000},{"price":130.58,"qty":11.17082499}],"asks":[],"checksum":3919613095,"timestamp":"2024-06-01T22:42:26.071301Z"}]}
{"channel":"book","type":"update","data":[{"symbol":"SOL/GBP","bids":[{"price":130.66,"qty":0.00000000},{"price":130.52,"qty":27.16000000}],"asks":[],"checksum":3027053868,"timestamp":"2024-06-01T22:42:26.072347Z"}]}
{"channel":"book","type":"update","data":[{"symbol":"SOL/GBP","bids":[{"price":130.68,"qty":2.20000000}],"asks":[],"checksum":2224972724,"timestamp":"2024-06-01T22:42:26.072493Z"}]}
{"channel":"book","type":"update","data":[{"symbol":"SOL/GBP","bids":[],"asks":[{"price":130.74,"qty":30.00595189}],"checksum":703957507,"timestamp":"2024-06-01T22:42:26.072781Z"}]}
{"channel":"book","type":"update","data":[{"symbol":"SOL/GBP","bids":[{"price":130.67,"qty":0.00000000},{"price":130.52,"qty":27.16000000}],"asks":[],"checksum":1154010319,"timestamp":"2024-06-01T22:42:26.085352Z"}]}
{"channel":"book","type":"update","data":[{"symbol":"SOL/GBP","bids":[{"price":130.65,"qty":2.96314580}],"asks":[],"checksum":2354719810,"timestamp":"2024-06-01T22:42:26.085379Z"}]}
{"channel":"book","type":"update","data":[{"symbol":"SOL/GBP","bids":[{"price":130.66,"qty":2.20000000}],"asks":[],"checksum":2238157919,"timestamp":"2024-06-01T22:42:26.088022Z"}]}
{"channel":"book","type":"update","data":[{"symbol":"SOL/GBP","bids":[{"price":130.68,"qty":0.00000000},{"price":130.54,"qty":26.45000000}],"asks":[],"checksum":694805094,"timestamp":"2024-06-01T22:42:26.088058Z"}]}
{"channel":"book","type":"update","data":[{"symbol":"SOL/GBP","bids":[{"price":130.65,"qty":5.16314580}],"asks":[],"checksum":2048374573,"timestamp":"2024-06-01T22:42:26.088268Z"}]}
{"channel":"book","type":"update","data":[{"symbol":"SOL/GBP","bids":[{"price":130.65,"qty":2.96314580}],"asks":[],"checksum":694805094,"timestamp":"2024-06-01T22:42:26.092712Z"}]}
{"channel":"book","type":"update","data":[{"symbol":"SOL/GBP","bids":[],"asks":[{"price":130.72,"qty":0.00000000},{"price":130.90,"qty":6.53296266},{"price":130.73,"qty":5.58379308}],"checksum":2150209024,"timestamp":"2024-06-01T22:42:26.094891Z"}]}
{"channel":"book","type":"update","data":[{"symbol":"SOL/GBP","bids":[{"price":130.65,"qty":0.00000000},{"price":130.52,"qty":27.16000000}],"asks":[],"checksum":3692470217,"timestamp":"2024-06-01T22:42:26.104953Z"}]}
{"channel":"book","type":"update","data":[{"symbol":"SOL/GBP","bids":[{"price":130.67,"qty":2.96269227}],"asks":[],"checksum":3985314166,"timestamp":"2024-06-01T22:42:26.105038Z"}]}
{"channel":"book","type":"update","data":[{"symbol":"SOL/GBP","bids":[{"price":130.66,"qty":0.00000000},{"price":130.52,"qty":27.16000000}],"asks":[],"checksum":1170072819,"timestamp":"2024-06-01T22:42:26.107685Z"}]}
{"channel":"book","type":"update","data":[{"symbol":"SOL/GBP","bids":[{"price":130.68,"qty":2.20000000}],"asks":[],"checksum":2159410789,"timestamp":"2024-06-01T22:42:26.107907Z"}]}
{"channel":"book","type":"update","data":[{"symbol":"SOL/GBP","bids":[{"price":130.67,"qty":0.00000000},{"price":130.52,"qty":27.16000000}],"asks":[],"checksum":3769649366,"timestamp":"2024-06-01T22:42:26.128439Z"}]}
{"channel":"book","type":"update","data":[{"symbol":"SOL/GBP","bids":[{"price":130.65,"qty":2.96314580}],"asks":[],"checksum":622483492,"timestamp":"2024-06-01T22:42:26.128612Z"}]}
{"channel":"book","type":"update","data":[{"symbol":"SOL/GBP","bids":[{"price":130.68,"qty":0.00000000},{"price":130.52,"qty":27.16000000}],"asks":[],"checksum":1415176245,"timestamp":"2024-06-01T22:42:26.131025Z"}]}
{"channel":"book","type":"update","data":[{"symbol":"SOL/GBP","bids":[{"price":130.65,"qty":5.16314580}],"asks":[],"checksum":3892928654,"timestamp":"2024-06-01T22:42:26.131326Z"}]}
{"channel":"book","type":"update","data":[{"symbol":"SOL/GBP","bids":[{"price":130.65,"qty":2.96314580}],"asks":[],"checksum":1415176245,"timestamp":"2024-06-01T22:42:26.131397Z"}]}
{"channel":"book","type":"update","data":[{"symbol":"SOL/GBP","bids":[{"price":130.66,"qty":2.20000000}],"asks":[],"checksum":2150209024,"timestamp":"2024-06-01T22:42:26.132123Z"}]}
{"channel":"book","type":"update","data":[{"symbol":"SOL/GBP","bids":[{"price":130.65,"qty":21.86989824}],"asks":[],"checksum":490939697,"timestamp":"2024-06-01T22:42:26.133629Z"}]}
{"channel":"book","type":"update","data":[{"symbol":"SOL/GBP","bids":[{"price":130.65,"qty":18.90675244}],"asks":[],"checksum":1427133154,"timestamp":"2024-06-01T22:42:26.150465Z"}]}
{"channel":"book","type":"update","data":[{"symbol":"SOL/GBP","bids":[{"price":130.67,"qty":2.96269227}],"asks":[],"checksum":864326467,"timestamp":"2024-06-01T22:42:26.150748Z"}]}
{"channel":"book","type":"update","data":[{"symbol":"SOL/GBP","bids":[{"price":130.66,"qty":0.00000000},{"price":130.54,"qty":26.45000000}],"asks":[],"checksum":3434818008,"timestamp":"2024-06-01T22:42:26.153306Z"}]}
{"channel":"book","type":"update","data":[{"symbol":"SOL/GBP","bids":[{"price":130.68,"qty":2.20000000}],"asks":[],"checksum":1589279824,"timestamp":"2024-06-01T22:42:26.153419Z"}]}
{"channel":"book","type":"update","data":[{"symbol":"SOL/GBP","bids":[{"price":130.66,"qty":2.96291902}],"asks":[],"checksum":1567278280,"timestamp":"2024-06-01T22:42:26.175022Z"}]}
{"channel":"book","type":"update","data":[{"symbol":"SOL/GBP","bids":[{"price":130.67,"qty":0.00000000},{"price":130.55,"qty":12.60000000}],"asks":[],"checksum":4278889629,"timestamp":"2024-06-01T22:42:26.175047Z"}]}
{"channel":"book","type":"update","data":[{"symbol":"SOL/GBP","bids":[{"price":130.64,"qty":23.71877906},{"price":130.66,"qty":3.89551402}],"asks":[],"checksum":1643066822,"timestamp":"2024-06-01T22:42:26.184068Z"}]}
{"channel":"book","type":"update","data":[{"symbol":"SOL/GBP","bids":[],"asks":[{"price":130.70,"qty":0.00000000},{"price":130.90,"qty":6.53296266},{"price":130.72,"qty":0.93241700}],"checksum":3453848600,"timestamp":"2024-06-01T22:42:26.258200Z"}]}
{"channel":"book","type":"update","data":[{"symbol":"SOL/GBP","bids":[{"price":130.69,"qty":30.01550182}],"asks":[],"checksum":3698422650,"timestamp":"2024-06-01T22:42:26.266340Z"}]}
{"channel":"book","type":"update","data":[{"symbol":"SOL/GBP","bids":[],"asks":[{"price":130.74,"qty":0.00000000},{"price":130.90,"qty":6.53296266}],"checksum":116587698,"timestamp":"2024-06-01T22:42:26.471244Z"}]}
{"channel":"book","type":"update","data":[{"symbol":"SOL/GBP","bids":[],"asks":[{"price":130.73,"qty":35.59028958}],"checksum":3041190303,"timestamp":"2024-06-01T22:42:26.474309Z"}]}
{"channel":"book","type":"update","data":[{"symbol":"SOL/GBP","bids":[],"asks":[{"price":130.73,"qty":30.00649650},{"price":130.76,"qty":5.58379308}],"checksum":43218182,"timestamp":"2024-06-01T22:42:26.482659Z"}]}
{"channel":"book","type":"update","data":[{"symbol":"SOL/GBP","bids":[],"asks":[{"price":130.73,"qty":0.00000000},{"price":130.90,"qty":6.53296266}],"checksum":3215069804,"timestamp":"2024-06-01T22:42:26.560001Z"}]}
{"channel":"book","type":"update","data":[{"symbol":"SOL/GBP","bids":[],"asks":[{"price":130.88,"qty":36.15000000}],"checksum":1833727589,"timestamp":"2024-06-01T22:42:26.562949Z"}]}
{"channel":"book","type":"update","data":[{"symbol":"SOL/GBP","bids":[],"asks":[{"price":130.75,"qty":2.20000000}],"checksum":595922935,"timestamp":"2024-06-01T22:42:26.563124Z"}]}
{"channel":"book","type":"update","data":[{"symbol":"SOL/GBP","bids":[],"asks":[{"price":130.89,"qty":7.85200000}],"checksum":1267847936,"timestamp":"2024-06-01T22:42:26.571124Z"}]}
{"channel":"book","type":"update","data":[{"symbol":"SOL/GBP","bids":[],"asks":[{"price":130.87,"qty":9.56047203}],"checksum":2217242466,"timestamp":"2024-06-01T22:42:26.571147Z"}]}
{"channel":"book","type":"update","data":[{"symbol":"SOL/GBP","bids":[],"asks":[{"price":130.76,"qty":0.00000000},{"price":130.89,"qty":7.85200000},{"price":130.74,"qty":5.58379308}],"checksum":3451134152,"timestamp":"2024-06-01T22:42:26.602845Z"}]}
{"channel":"book","type":"update","data":[{"symbol":"SOL/GBP","bids":[],"asks":[{"price":130.75,"qty":0.00000000},{"price":130.89,"qty":7.85200000}],"checksum":3703799860,"timestamp":"2024-06-01T22:42:26.605620Z"}]}
{"channel":"book","type":"update","data":[{"symbol":"SOL/GBP","bids":[],"asks":[{"price":130.74,"qty":0.00000000},{"price":130.90,"qty":6.53296266},{"price":130.76,"qty":5.58379308}],"checksum":4261866925,"timestamp":"2024-06-01T22:42:26.611881Z"}]}
{"channel":"book","type":"update","data":[{"symbol":"SOL/GBP","bids":[],"asks":[{"price":130.75,"qty":2.20000000}],"checksum":2217242466,"timestamp":"2024-06-01T22:42:26.614710Z"}]}
{"channel":"book","type":"update","data":[{"symbol":"SOL/GBP","bids":[],"asks":[{"price":130.76,"qty":0.00000000},{"price":130.89,"qty":7.85200000},{"price":130.74,"qty":5.58379308}],"checksum":3451134152,"timestamp":"2024-06-01T22:42:26.767319Z"}]}
{"channel":"book","type":"update","data":[{"symbol":"SOL/GBP","bids":[],"asks":[{"price":130.75,"qty":0.00000000},{"price":130.89,"qty":7.85200000}],"checksum":3703799860,"timestamp":"2024-06-01T22:42:26.769957Z"}]}
{"channel":"book","type":"update","data":[{"symbol":"SOL/GBP","bids":[],"asks":[{"price":130.74,"qty":0.00000000},{"price":130.90,"qty":6.53296266},{"price":130.76,"qty":5.58379308}],"checksum":4261866925,"timestamp":"2024-06-01T22:42:26.773177Z"}]}
{"channel":"book","type":"update","data":[{"symbol":"SOL/GBP","bids":[],"asks":[{"price":130.75,"qty":2.20000000}],"checksum":2217242466,"timestamp":"2024-06-01T22:42:26.775938Z"}]}
{"channel":"book","type":"update","data":[{"symbol":"SOL/GBP","bids":[],"asks":[{"price":130.74,"qty":30.00606145}],"checksum":2802438902,"timestamp":"2024-06-01T22:42:26.785481Z"}]}
{"channel":"book","type":"update","data":[{"symbol":"SOL/GBP","bids":[],"asks":[{"price":130.76,"qty":0.00000000},{"price":130.88,"qty":36.15000000},{"price":130.73,"qty":5.58379308}],"checksum":1211156899,"timestamp":"2024-06-01T22:42:26.905504Z"}]}
{"channel":"book","type":"update","data":[{"symbol":"SOL/GBP","bids":[],"asks":[{"price":130.75,"qty":0.00000000},{"price":130.88,"qty":36.15000000}],"checksum":2769589708,"timestamp":"2024-06-01T22:42:26.908158Z"}]}
{"channel":"book","type":"update","data":[{"symbol":"SOL/GBP","bids":[],"asks":[{"price":130.74,"qty":0.00000000},{"price":130.89,"qty":7.85200000}],"checksum":1196819315,"timestamp":"2024-06-01T22:42:26.938091Z"}]}
{"channel":"book","type":"update","data":[{"symbol":"SOL/GBP","bids":[],"asks":[{"price":130.73,"qty":0.00000000},{"price":130.90,"qty":6.53296266},{"price":130.76,"qty":5.58379308}],"checksum":4261866925,"timestamp":"2024-06-01T22:42:26.943998Z"}]}
{"channel":"book","type":"update","data":[{"symbol":"SOL/GBP","bids":[],"asks":[{"price":130.75,"qty":2.20000000}],"checksum":2217242466,"timestamp":"2024-06-01T22:42:26.946856Z"}]}
{"channel":"book","type":"update","data":[{"symbol":"SOL/GBP","bids":[],"asks":[{"price":130.73,"qty":30.00674268}],"checksum":3819139566,"timestamp":"2024-06-01T22:42:27.054839Z"}]}
{"channel":"book","type":"update","data":[{"symbol":"SOL/GBP","bids":[],"asks":[{"price":130.73,"qty":0.00000000},{"price":130.88,"qty":36.15000000}],"checksum":2217242466,"timestamp":"2024-06-01T22:42:27.073233Z"}]}
{"channel":"book","type":"update","data":[{"symbol":"SOL/GBP","bids":[],"asks":[{"price":130.76,"qty":0.00000000},{"price":130.89,"qty":7.85200000},{"price":130.74,"qty":5.58379308}],"checksum":3451134152,"timestamp":"2024-06-01T22:42:27.117859Z"}]}
{"channel":"book","type":"update","data":[{"symbol":"SOL/GBP","bids":[],"asks":[{"price":130.75,"qty":0.00000000},{"price":130.89,"qty":7.85200000}],"checksum":3703799860,"timestamp":"2024-06-01T22:42:27.120621Z"}]}
{"channel":"book","type":"update","data":[{"symbol":"SOL/GBP","bids":[],"asks":[{"price":130.74,"qty":0.00000000},{"price":130.90,"qty":6.53296266},{"price":130.76,"qty":5.58379308}],"checksum":4261866925,"timestamp":"2024-06-01T22:42:27.123567Z"}]}
{"channel":"book","type":"update","data":[{"symbol":"SOL/GBP","bids":[],"asks":[{"price":130.75,"qty":2.20000000}],"checksum":2217242466,"timestamp":"2024-06-01T22:42:27.126291Z"}]}
{"channel":"book","type":"update","data":[{"symbol":"SOL/GBP","bids":[],"asks":[{"price":130.73,"qty":30.00641968}],"checksum":813236092,"timestamp":"2024-06-01T22:42:27.329615Z"}]}
{"channel":"book","type":"update","data":[{"symbol":"SOL/GBP","bids":[],"asks":[{"price":130.76,"qty":0.00000000},{"price":130.88,"qty":36.15000000},{"price":130.72,"qty":6.51621008}],"checksum":2568910821,"timestamp":"2024-06-01T22:42:27.406759Z"}]}
{"channel":"book","type":"update","data":[{"symbol":"SOL/GBP","bids":[],"asks":[{"price":130.75,"qty":0.00000000},{"price":130.89,"qty":7.85200000}],"checksum":2288637721,"timestamp":"2024-06-01T22:42:27.409445Z"}]}
{"channel":"book","type":"update","data":[{"symbol":"SOL/GBP","bids":[],"asks":[{"price":130.72,"qty":0.93241700},{"price":130.72,"qty":4.77556454}],"checksum":2174450851,"timestamp":"2024-06-01T22:42:28.052800Z"}]}
{"channel":"book","type":"update","data":[{"symbol":"SOL/GBP","bids":[{"price":130.57,"qty":11.46000000}],"asks":[],"checksum":3920724349,"timestamp":"2024-06-01T22:42:28.163613Z"}]}
{"channel":"book","type":"update","data":[{"symbol":"SOL/GBP","bids":[{"price":130.60,"qty":35.13219342}],"asks":[],"checksum":3297995324,"timestamp":"2024-06-01T22:42:28.163660Z"}]}
{"channel":"book","type":"update","data":[{"symbol":"SOL/GBP","bids":[{"price":130.61,"qty":35.42948660}],"asks":[],"checksum":2309329281,"timestamp":"2024-06-01T22:42:28.164264Z"}]}
{"channel":"book","type":"update","data":[{"symbol":"SOL/GBP","bids":[{"price":130.57,"qty":256.59408199}],"asks":[],"checksum":1023174376,"timestamp":"2024-06-01T22:42:28.164455Z"}]}
{"channel":"book","type":"update","data":[{"symbol":"SOL/GBP","bids":[{"price":130.58,"qty":6.53296266},{"price":130.58,"qty":11.88329556}],"asks":[],"checksum":3731951693,"timestamp":"2024-06-01T22:42:28.388322Z"}]}
{"channel":"book","type":"update","data":[{"symbol":"SOL/GBP","bids":[],"asks":[{"price":130.73,"qty":0.00000000},{"price":130.90,"qty":6.53296266}],"checksum":2895690386,"timestamp":"2024-06-01T22:42:28.471449Z"}]}
{"channel":"book","type":"update","data":[{"symbol":"SOL/GBP","bids":[],"asks":[{"price":130.76,"qty":2.20000000}],"checksum":3305022859,"timestamp":"2024-06-01T22:42:28.474249Z"}]}
{"channel":"book","type":"update","data":[{"symbol":"SOL/GBP","bids":[],"asks":[{"price":130.74,"qty":30.00609233}],"checksum":733710868,"timestamp":"2024-06-01T22:42:28.474390Z"}]}
{"channel":"book","type":"update","data":[{"symbol":"SOL/GBP","bids":[],"asks":[{"price":130.72,"qty":0.93241700},{"price":130.76,"qty":6.04319680}],"checksum":4027688902,"timestamp":"2024-06-01T22:42:28.474734Z"}]}
{"channel":"book","type":"update","data":[{"symbol":"SOL/GBP","bids":[],"asks":[{"price":130.74,"qty":0.00000000},{"price":130.89,"qty":7.85200000}],"checksum":2703195298,"timestamp":"2024-06-01T22:42:28.620811Z"}]}
{"channel":"book","type":"update","data":[{"symbol":"SOL/GBP","bids":[],"asks":[{"price":130.72,"qty":0.00000000},{"price":130.90,"qty":6.53296266},{"price":130.71,"qty":0.93241800}],"checksum":192430626,"timestamp":"2024-06-01T22:42:28.730748Z"}]}
{"channel":"book","type":"update","data":[{"symbol":"SOL/GBP","bids":[],"asks":[{"price":130.73,"qty":30.00641038}],"checksum":1588203776,"timestamp":"2024-06-01T22:42:28.734490Z"}]}
{"channel":"book","type":"update","data":[{"symbol":"SOL/GBP","bids":[],"asks":[{"price":130.76,"qty":2.20000000},{"price":130.72,"qty":3.84319837}],"checksum":804508492,"timestamp":"2024-06-01T22:42:28.758683Z"}]}
{"channel":"book","type":"update","data":[{"symbol":"SOL/GBP","bids":[],"asks":[{"price":130.71,"qty":0.00000000},{"price":130.88,"qty":36.15000000},{"price":130.75,"qty":0.93233700}],"checksum":1815023480,"timestamp":"2024-06-01T22:42:28.889293Z"}]}
{"channel":"book","type":"update","data":[{"symbol":"SOL/GBP","bids":[],"asks":[{"price":130.73,"qty":0.00000000},{"price":130.88,"qty":36.15000000}],"checksum":2531530366,"timestamp":"2024-06-01T22:42:29.135548Z"}]}
{"channel":"book","type":"update","data":[{"symbol":"SOL/GBP","bids":[],"asks":[{"price":130.74,"qty":30.00528095}],"checksum":556468460,"timestamp":"2024-06-01T22:42:29.139229Z"}]}
{"channel":"book","type":"update","data":[{"symbol":"SOL/GBP","bids":[],"asks":[{"price":130.72,"qty":0.00000000},{"price":130.88,"qty":36.15000000},{"price":130.73,"qty":3.84319903}],"checksum":2820441903,"timestamp":"2024-06-01T22:42:29.156462Z"}]}
{"channel":"book","type":"update","data":[{"symbol":"SOL/GBP","bids":[],"asks":[{"price":130.74,"qty":0.00000000},{"price":130.88,"qty":36.15000000}],"checksum":533961149,"timestamp":"2024-06-01T22:42:29.241464Z"}]}
{"channel":"book","type":"update","data":[{"symbol":"SOL/GBP","bids":[],"asks":[{"price":130.73,"qty":0.00000000},{"price":130.89,"qty":7.85200000},{"price":130.74,"qty":3.84319903}],"checksum":1501535574,"timestamp":"2024-06-01T22:42:29.244589Z"}]}
{"channel":"book","type":"update","data":[{"symbol":"SOL/GBP","bids":[],"asks":[{"price":130.74,"qty":0.00000000},{"price":130.89,"qty":7.85200000},{"price":130.75,"qty":4.77553603}],"checksum":2244328550,"timestamp":"2024-06-01T22:42:29.248664Z"}]}
{"channel":"book","type":"update","data":[{"symbol":"SOL/GBP","bids":[],"asks":[{"price":130.73,"qty":30.00665213}],"checksum":3494565626,"timestamp":"2024-06-01T22:42:29.440853Z"}]}
{"channel":"book","type":"update","data":[{"symbol":"SOL/GBP","bids":[{"price":130.63,"qty":30.02908421}],"asks":[],"checksum":232130508,"timestamp":"2024-06-01T22:42:29.444171Z"}]}
{"channel":"book","type":"update","data":[{"symbol":"SOL/GBP","bids":[{"price":130.65,"qty":36.37511615}],"asks":[],"checksum":3938759946,"timestamp":"2024-06-01T22:42:29.447441Z"}]}
{"channel":"book","type":"update","data":[{"symbol":"SOL/GBP","bids":[],"asks":[{"price":130.75,"qty":0.93233700},{"price":130.72,"qty":3.84319920}],"checksum":597536410,"timestamp":"2024-06-01T22:42:29.544558Z"}]}
{"channel":"book","type":"update","data":[{"symbol":"SOL/GBP","bids":[{"price":130.57,"qty":11.46000000}],"asks":[],"checksum":854494546,"timestamp":"2024-06-01T22:42:30.302391Z"}]}
{"channel":"book","type":"update","data":[{"symbol":"SOL/GBP","bids":[{"price":130.64,"qty":0.00000000},{"price":130.56,"qty":36.30430738}],"asks":[],"checksum":1442640398,"timestamp":"2024-06-01T22:42:30.302423Z"}]}
{"channel":"book","type":"update","data":[{"symbol":"SOL/GBP","bids":[{"price":130.57,"qty":210.85930775}],"asks":[],"checksum":448412033,"timestamp":"2024-06-01T22:42:30.303517Z"}]}
{"channel":"book","type":"update","data":[{"symbol":"SOL/GBP","bids":[],"asks":[{"price":130.75,"qty":0.00000000},{"price":130.88,"qty":36.15000000},{"price":130.71,"qty":0.93244200}],"checksum":2653569747,"timestamp":"2024-06-01T22:42:30.458610Z"}]}
{"channel":"book","type":"update","data":[{"symbol":"SOL/GBP","bids":[],"asks":[{"price":130.71,"qty":0.00000000},{"price":130.88,"qty":36.15000000},{"price":130.72,"qty":4.77562720}],"checksum":3236794829,"timestamp":"2024-06-01T22:42:31.652359Z"}]}
{"channel":"book","type":"update","data":[{"symbol":"SOL/GBP","bids":[],"asks":[{"price":130.72,"qty":3.84319920},{"price":130.71,"qty":0.93244200}],"checksum":2653569747,"timestamp":"2024-06-01T22:42:34.161884Z"}]}
{"channel":"book","type":"update","data":[{"symbol":"SOL/GBP","bids":[],"asks":[{"price":130.71,"qty":0.00000000},{"price":130.88,"qty":36.15000000},{"price":130.72,"qty":4.77562720}],"checksum":3236794829,"timestamp":"2024-06-01T22:42:34.317716Z"}]}
{"channel":"book","type":"update","data":[{"symbol":"SOL/GBP","bids":[],"asks":[{"price":130.88,"qty":6.20000000},{"price":130.87,"qty":39.51047203}],"checksum":1223296285,"timestamp":"2024-06-01T22:42:34.330127Z"}]}
{"channel":"book","type":"update","data":[{"symbol":"SOL/GBP","bids":[{"price":130.69,"qty":0.00000000},{"price":130.55,"qty":12.60000000}],"asks":[],"checksum":3643603873,"timestamp":"2024-06-01T22:42:34.512109Z"}]}
{"channel":"book","type":"update","data":[{"symbol":"SOL/GBP","bids":[{"price":130.68,"qty":32.21582012}],"asks":[],"checksum":1683512992,"timestamp":"2024-06-01T22:42:34.515857Z"}]}
{"channel":"book","type":"update","data":[{"symbol":"SOL/GBP","bids":[{"price":130.58,"qty":6.53296266},{"price":130.59,"qty":5.34992343}],"asks":[],"checksum":3969423400,"timestamp":"2024-06-01T22:42:34.533071Z"}]}
{"channel":"book","type":"update","data":[{"symbol":"SOL/GBP","bids":[{"price":130.59,"qty":0.00000000},{"price":130.55,"qty":12.60000000},{"price":130.58,"qty":11.88329580}],"asks":[],"checksum":901209266,"timestamp":"2024-06-01T22:42:34.546993Z"}]}
{"channel":"book","type":"update","data":[{"symbol":"SOL/GBP","bids":[{"price":130.68,"qty":2.20000000}],"asks":[],"checksum":2294544819,"timestamp":"2024-06-01T22:42:34.729786Z"}]}
{"channel":"book","type":"update","data":[{"symbol":"SOL/GBP","bids":[{"price":130.58,"qty":6.53296266},{"price":130.59,"qty":5.34992343}],"asks":[],"checksum":3081104987,"timestamp":"2024-06-01T22:42:34.732650Z"}]}
{"channel":"book","type":"update","data":[{"symbol":"SOL/GBP","bids":[{"price":130.69,"qty":30.01527086}],"asks":[],"checksum":592640439,"timestamp":"2024-06-01T22:42:34.818801Z"}]}
{"channel":"book","type":"update","data":[{"symbol":"SOL/GBP","bids":[{"price":130.59,"qty":0.00000000},{"price":130.56,"qty":36.30430738},{"price":130.58,"qty":11.88329580}],"asks":[],"checksum":2210893609,"timestamp":"2024-06-01T22:42:34.822169Z"}]}
{"channel":"book","type":"update","data":[{"symbol":"SOL/GBP","bids":[{"price":130.69,"qty":0.00000000},{"price":130.55,"qty":12.60000000}],"asks":[],"checksum":2294544819,"timestamp":"2024-06-01T22:42:35.507896Z"}]}
{"channel":"book","type":"update","data":[{"symbol":"SOL/GBP","bids":[{"price":130.68,"qty":32.21579763}],"asks":[],"checksum":1095342457,"timestamp":"2024-06-01T22:42:35.511579Z"}]}
{"channel":"book","type":"update","data":[{"symbol":"SOL/GBP","bids":[{"price":130.58,"qty":6.53296266},{"price":130.59,"qty":5.34992343}],"asks":[],"checksum":607865227,"timestamp":"2024-06-01T22:42:35.520924Z"}]}
{"channel":"book","type":"update","data":[{"symbol":"SOL/GBP","bids":[{"price":130.59,"qty":0.00000000},{"price":130.55,"qty":12.60000000},{"price":130.58,"qty":11.88329580}],"asks":[],"checksum":1095342457,"timestamp":"2024-06-01T22:42:35.523618Z"}]}
{"channel":"book","type":"update","data":[{"symbol":"SOL/GBP","bids":[{"price":130.65,"qty":18.90675244}],"asks":[],"checksum":3327283264,"timestamp":"2024-06-01T22:42:35.726351Z"}]}
{"channel":"book","type":"update","data":[{"symbol":"SOL/GBP","bids":[],"asks":[{"price":130.87,"qty":9.56047203},{"price":130.86,"qty":59.92720458}],"checksum":3328623859,"timestamp":"2024-06-01T22:42:35.726639Z"}]}
{"channel":"book","type":"update","data":[{"symbol":"SOL/GBP","bids":[{"price":130.60,"qty":5.18219342}],"asks":[],"checksum":609706986,"timestamp":"2024-06-01T22:42:35.727924Z"}]}
{"channel":"book","type":"update","data":[{"symbol":"SOL/GBP","bids":[{"price":130.58,"qty":5.35033314}],"asks":[],"checksum":2561218626,"timestamp":"2024-06-01T22:42:35.728570Z"}]}
{"channel":"book","type":"update","data":[{"symbol":"SOL/GBP","bids":[{"price":130.57,"qty":199.39930775}],"asks":[],"checksum":515732237,"timestamp":"2024-06-01T22:42:35.730988Z"}]}
{"channel":"book","type":"update","data":[{"symbol":"SOL/GBP","bids":[],"asks":[{"price":130.79,"qty":0.00000000},{"price":130.89,"qty":7.85200000}],"checksum":1385274690,"timestamp":"2024-06-01T22:42:35.731477Z"}]}
{"channel":"book","type":"update","data":[{"symbol":"SOL/GBP","bids":[{"price":130.55,"qty":0.00000000},{"price":130.51,"qty":6.53296266}],"asks":[],"checksum":443327955,"timestamp":"2024-06-01T22:42:35.732425Z"}]}
{"channel":"book","type":"update","data":[{"symbol":"SOL/GBP","bids":[{"price":130.58,"qty":35.30033314}],"asks":[],"checksum":2862217761,"timestamp":"2024-06-01T22:42:35.732528Z"}]}
{"channel":"book","type":"update","data":[{"symbol":"SOL/GBP","bids":[{"price":130.68,"qty":2.20000000}],"asks":[],"checksum":2944292072,"timestamp":"2024-06-01T22:42:35.736109Z"}]}
{"channel":"book","type":"update","data":[{"symbol":"SOL/GBP","bids":[],"asks":[{"price":130.73,"qty":0.00000000},{"price":130.94,"qty":5.64000000}],"checksum":1892514591,"timestamp":"2024-06-01T22:42:35.736152Z"}]}
{"channel":"book","type":"update","data":[{"symbol":"SOL/GBP","bids":[{"price":130.63,"qty":0.00000000},{"price":130.48,"qty":7.85200000}],"asks":[],"checksum":3137129960,"timestamp":"2024-06-01T22:42:35.736163Z"}]}
{"channel":"book","type":"update","data":[{"symbol":"SOL/GBP","bids":[],"asks":[{"price":130.86,"qty":29.95000000}],"checksum":236784271,"timestamp":"2024-06-01T22:42:35.736213Z"}]}
{"channel":"book","type":"update","data":[{"symbol":"SOL/GBP","bids":[{"price":130.58,"qty":5.35033314}],"asks":[],"checksum":4144225300,"timestamp":"2024-06-01T22:42:35.736912Z"}]}
{"channel":"book","type":"update","data":[{"symbol":"SOL/GBP","bids":[],"asks":[{"price":130.89,"qty":0.00000000},{"price":130.95,"qty":18.88107173},{"price":130.93,"qty":7.85200000}],"checksum":837442954,"timestamp":"2024-06-01T22:42:35.739771Z"}]}
{"channel":"book","type":"update","data":[{"symbol":"SOL/GBP","bids":[{"price":130.59,"qty":30.03695178}],"asks":[],"checksum":2215834940,"timestamp":"2024-06-01T22:42:35.743819Z"}]}
{"channel":"book","type":"update","data":[{"symbol":"SOL/GBP","bids":[],"asks":[{"price":130.74,"qty":30.00500011}],"checksum":2168551829,"timestamp":"2024-06-01T22:42:35.743865Z"}]}
{"channel":"book","type":"update","data":[{"symbol":"SOL/GBP","bids":[],"asks":[{"price":130.69,"qty":30.01550182}],"checksum":809365361,"timestamp":"2024-06-01T22:42:35.743879Z"}]}
{"channel":"book","type":"update","data":[{"symbol":"SOL/GBP","bids":[{"price":130.51,"qty":0.00000000},{"price":130.48,"qty":7.85200000}],"asks":[],"checksum":1993262243,"timestamp":"2024-06-01T22:42:35.743943Z"}]}
{"channel":"book","type":"update","data":[{"symbol":"SOL/GBP","bids":[{"price":130.48,"qty":0.00000000},{"price":130.47,"qty":97.35291683}],"asks":[],"checksum":1191959557,"timestamp":"2024-06-01T22:42:35.745881Z"}]}
{"channel":"book","type":"update","data":[{"symbol":"SOL/GBP","bids":[{"price":130.58,"qty":0.00000000},{"price":130.44,"qty":6.53296266},{"price":130.59,"qty":35.38687521}],"asks":[],"checksum":3202961529,"timestamp":"2024-06-01T22:42:35.746979Z"}]}
{"channel":"book","type":"update","data":[{"symbol":"SOL/GBP","bids":[],"asks":[{"price":130.76,"qty":0.00000000},{"price":130.93,"qty":7.85200000}],"checksum":3539165057,"timestamp":"2024-06-01T22:42:35.746996Z"}]}
{"channel":"book","type":"update","data":[{"symbol":"SOL/GBP","bids":[{"price":130.68,"qty":0.00000000},{"price":130.41,"qty":60.15597937}],"asks":[],"checksum":1277402608,"timestamp":"2024-06-01T22:42:35.747019Z"}]}
{"channel":"book","type":"update","data":[{"symbol":"SOL/GBP","bids":[],"asks":[{"price":130.73,"qty":2.20000000}],"checksum":2780792416,"timestamp":"2024-06-01T22:42:35.747376Z"}]}
{"channel":"book","type":"update","data":[{"symbol":"SOL/GBP","bids":[{"price":130.66,"qty":6.09551402}],"asks":[],"checksum":2033050538,"timestamp":"2024-06-01T22:42:35.747500Z"}]}
{"channel":"book","type":"update","data":[{"symbol":"SOL/GBP","bids":[{"price":130.65,"qty":0.00000000},{"price":130.40,"qty":12.14344872}],"asks":[],"checksum":5239851,"timestamp":"2024-06-01T22:42:35.749069Z"}]}
{"channel":"book","type":"update","data":[{"symbol":"SOL/GBP","bids":[{"price":130.43,"qty":26.30000000}],"asks":[],"checksum":321973557,"timestamp":"2024-06-01T22:42:35.749400Z"}]}
{"channel":"book","type":"update","data":[{"symbol":"SOL/GBP","bids":[{"price":130.47,"qty":109.21291683}],"asks":[],"checksum":1857220834,"timestamp":"2024-06-01T22:42:35.749675Z"}]}
{"channel":"book","type":"update","data":[{"symbol":"SOL/GBP","bids":[{"price":130.44,"qty":31.68296266}],"asks":[],"checksum":2307425218,"timestamp":"2024-06-01T22:42:35.749754Z"}]}
{"channel":"book","type":"update","data":[{"symbol":"SOL/GBP","bids":[{"price":130.59,"qty":5.34992343}],"asks":[],"checksum":398473128,"timestamp":"2024-06-01T22:42:35.751717Z"}]}
{"channel":"book","type":"update","data":[{"symbol":"SOL/GBP","bids":[],"asks":[{"price":130.69,"qty":0.00000000},{"price":130.93,"qty":7.85200000}],"checksum":2281154264,"timestamp":"2024-06-01T22:42:35.751728Z"}]}
{"channel":"book","type":"update","data":[{"symbol":"SOL/GBP","bids":[],"asks":[{"price":130.72,"qty":0.93242800},{"price":130.75,"qty":3.84309275}],"checksum":1527703545,"timestamp":"2024-06-01T22:42:35.758151Z"}]}
{"channel":"book","type":"update","data":[{"symbol":"SOL/GBP","bids":[],"asks":[{"price":130.73,"qty":0.00000000},{"price":130.93,"qty":7.85200000}],"checksum":3539970007,"timestamp":"2024-06-01T22:42:35.760246Z"}]}
{"channel":"book","type":"update","data":[{"symbol":"SOL/GBP","bids":[],"asks":[{"price":130.71,"qty":2.20000000}],"checksum":3918276620,"timestamp":"2024-06-01T22:42:35.760336Z"}]}
{"channel":"book","type":"update","data":[{"symbol":"SOL/GBP","bids":[{"price":130.49,"qty":30.06077538}],"asks":[],"checksum":1595274347,"timestamp":"2024-06-01T22:42:35.760659Z"}]}
{"channel":"book","type":"update","data":[{"symbol":"SOL/GBP","bids":[{"price":130.62,"qty":30.03079973}],"asks":[],"checksum":152704775,"timestamp":"2024-06-01T22:42:35.767088Z"}]}
{"channel":"book","type":"update","data":[{"symbol":"SOL/GBP","bids":[{"price":130.62,"qty":0.00000000},{"price":130.43,"qty":26.30000000}],"asks":[],"checksum":1595274347,"timestamp":"2024-06-01T22:42:35.774716Z"}]}
{"channel":"book","type":"update","data":[{"symbol":"SOL/GBP","bids":[{"price":130.66,"qty":3.89551402}],"asks":[],"checksum":611863968,"timestamp":"2024-06-01T22:42:35.778890Z"}]}
{"channel":"book","type":"update","data":[{"symbol":"SOL/GBP","bids":[{"price":130.62,"qty":2.20000000}],"asks":[],"checksum":432471025,"timestamp":"2024-06-01T22:42:35.779061Z"}]}
{"channel":"book","type":"update","data":[{"symbol":"SOL/GBP","bids":[{"price":130.59,"qty":0.00000000},{"price":130.43,"qty":26.30000000},{"price":130.58,"qty":5.35033314}],"asks":[],"checksum":552059645,"timestamp":"2024-06-01T22:42:35.783165Z"}]}
{"channel":"book","type":"update","data":[{"symbol":"SOL/GBP","bids":[{"price":130.56,"qty":30.04372253}],"asks":[],"checksum":1369499996,"timestamp":"2024-06-01T22:42:35.790406Z"}]}
{"channel":"book","type":"update","data":[{"symbol":"SOL/GBP","bids":[{"price":130.60,"qty":0.49219342}],"asks":[],"checksum":2433118803,"timestamp":"2024-06-01T22:42:35.803737Z"}]}
{"channel":"book","type":"update","data":[{"symbol":"SOL/GBP","bids":[],"asks":[{"price":130.82,"qty":5.77000000}],"checksum":82857184,"timestamp":"2024-06-01T22:42:35.805482Z"}]}
{"channel":"book","type":"update","data":[{"symbol":"SOL/GBP","bids":[{"price":130.58,"qty":0.00000000},{"price":130.43,"qty":26.30000000}],"asks":[],"checksum":666996963,"timestamp":"2024-06-01T22:42:35.812234Z"}]}
{"channel":"book","type":"update","data":[{"symbol":"SOL/GBP","bids":[],"asks":[{"price":130.74,"qty":0.00000000},{"price":130.88,"qty":6.20000000}],"checksum":1520725757,"timestamp":"2024-06-01T22:42:35.834400Z"}]}
{"channel":"book","type":"update","data":[{"symbol":"SOL/GBP","bids":[],"asks":[{"price":130.85,"qty":9.56047203}],"checksum":1210320973,"timestamp":"2024-06-01T22:42:35.835092Z"}]}
{"channel":"book","type":"update","data":[{"symbol":"SOL/GBP","bids":[],"asks":[{"price":130.87,"qty":0.00000000},{"price":130.88,"qty":6.20000000}],"checksum":1618006373,"timestamp":"2024-06-01T22:42:35.835167Z"}]}
{"channel":"book","type":"update","data":[{"symbol":"SOL/GBP","bids":[{"price":130.66,"qty":2.96291902},{"price":130.61,"qty":36.36223760}],"asks":[],"checksum":292771197,"timestamp":"2024-06-01T22:42:35.842755Z"}]}
{"channel":"book","type":"update","data":[{"symbol":"SOL/GBP","bids":[{"price":130.66,"qty":0.00000000},{"price":130.40,"qty":12.14344872}],"asks":[],"checksum":3572315938,"timestamp":"2024-06-01T22:42:35.848388Z"}]}
{"channel":"book","type":"update","data":[{"symbol":"SOL/GBP","bids":[{"price":130.63,"qty":2.96359947}],"asks":[],"checksum":4192177913,"timestamp":"2024-06-01T22:42:35.848963Z"}]}
{"channel":"book","type":"update","data":[{"symbol":"SOL/GBP","bids":[],"asks":[{"price":130.75,"qty":0.00000000},{"price":130.93,"qty":7.85200000},{"price":130.76,"qty":3.84309275}],"checksum":3318579115,"timestamp":"2024-06-01T22:42:35.866798Z"}]}
{"channel":"book","type":"update","data":[{"symbol":"SOL/GBP","bids":[],"asks":[{"price":130.83,"qty":36.24600608}],"checksum":3554224896,"timestamp":"2024-06-01T22:42:35.932559Z"}]}
{"channel":"book","type":"update","data":[{"symbol":"SOL/GBP","bids":[{"price":130.61,"qty":0.93275100}],"asks":[],"checksum":638478195,"timestamp":"2024-06-01T22:42:35.952148Z"}]}
{"channel":"book","type":"update","data":[{"symbol":"SOL/GBP","bids":[{"price":130.56,"qty":34.97372253}],"asks":[],"checksum":4231702561,"timestamp":"2024-06-01T22:42:35.975032Z"}]}
{"channel":"book","type":"update","data":[{"symbol":"SOL/GBP","bids":[],"asks":[{"price":130.70,"qty":30.01320531}],"checksum":1071363799,"timestamp":"2024-06-01T22:42:36.009769Z"}]}
{"channel":"book","type":"update","data":[{"symbol":"SOL/GBP","bids":[],"asks":[{"price":130.71,"qty":0.00000000},{"price":130.88,"qty":6.20000000}],"checksum":44665605,"timestamp":"2024-06-01T22:42:36.012523Z"}]}
{"channel":"book","type":"update","data":[{"symbol":"SOL/GBP","bids":[],"asks":[{"price":130.69,"qty":2.20000000}],"checksum":725037044,"timestamp":"2024-06-01T22:42:36.012859Z"}]}
