{"channel":"book","type":"snapshot","data":[{"symbol":"SOL/EUR","bids":[{"price":153.79,"qty":50.12483663},{"price":153.75,"qty":0.19007555},{"price":153.72,"qty":0.27463912},{"price":153.70,"qty":0.24574469},{"price":153.61,"qty":19.11076424},{"price":153.59,"qty":30.00682445},{"price":153.58,"qty":73.86693725},{"price":153.57,"qty":83.26938011},{"price":153.56,"qty":20.89300179},{"price":153.55,"qty":75.94363468}],"asks":[{"price":153.80,"qty":477.57786311},{"price":153.81,"qty":141.05204983},{"price":153.83,"qty":25.85047203},{"price":153.84,"qty":151.49564664},{"price":153.86,"qty":54.58800000},{"price":153.87,"qty":35.45747758},{"price":153.88,"qty":59.90088921},{"price":153.89,"qty":16.44000000},{"price":153.91,"qty":11.50621102},{"price":153.92,"qty":7.97000000}],"checksum":3760106924}]}
{"channel":"book","type":"update","data":[{"symbol":"SOL/EUR","bids":[{"price":153.55,"qty":69.24642007}],"asks":[],"checksum":3890192045,"timestamp":"2024-06-01T22:42:16.732641Z"}]}
{"channel":"book","type":"update","data":[{"symbol":"SOL/EUR","bids":[{"price":153.55,"qty":76.02193415}],"asks":[],"checksum":1533305816,"timestamp":"2024-06-01T22:42:16.738024Z"}]}
{"channel":"book","type":"update","data":[{"symbol":"SOL/EUR","bids":[{"price":153.55,"qty":63.71308587}],"asks":[],"checksum":1825286660,"timestamp":"2024-06-01T22:42:18.639946Z"}]}
{"channel":"book","type":"update","data":[{"symbol":"SOL/EUR","bids":[{"price":153.55,"qty":76.02193415}],"asks":[],"checksum":1533305816,"timestamp":"2024-06-01T22:42:18.765926Z"}]}
{"channel":"book","type":"update","data":[{"symbol":"SOL/EUR","bids":[{"price":153.55,"qty":69.24642007}],"asks":[],"checksum":3890192045,"timestamp":"2024-06-01T22:42:19.179442Z"}]}
{"channel":"book","type":"update","data":[{"symbol":"SOL/EUR","bids":[{"price":153.56,"qty":20.30314553}],"asks":[],"checksum":2562747711,"timestamp":"2024-06-01T22:42:19.179537Z"}]}
{"channel":"book","type":"update","data":[{"symbol":"SOL/EUR","bids":[{"price":153.56,"qty":20.42320499}],"asks":[],"checksum":135338149,"timestamp":"2024-06-01T22:42:19.186067Z"}]}
{"channel":"book","type":"update","data":[{"symbol":"SOL/EUR","bids":[{"price":153.55,"qty":76.17853308}],"asks":[],"checksum":2854366553,"timestamp":"2024-06-01T22:42:19.186752Z"}]}
{"channel":"book","type":"update","data":[{"symbol":"SOL/EUR","bids":[{"price":153.56,"qty":20.30314553}],"asks":[],"checksum":989026499,"timestamp":"2024-06-01T22:42:21.768008Z"}]}
{"channel":"book","type":"update","data":[{"symbol":"SOL/EUR","bids":[{"price":153.55,"qty":69.24642007}],"asks":[],"checksum":2562747711,"timestamp":"2024-06-01T22:42:21.768099Z"}]}
{"channel":"book","type":"update","data":[{"symbol":"SOL/EUR","bids":[{"price":153.56,"qty":20.97130126}],"asks":[],"checksum":2251804664,"timestamp":"2024-06-01T22:42:21.770406Z"}]}
{"channel":"book","type":"update","data":[{"symbol":"SOL/EUR","bids":[{"price":153.55,"qty":76.10023362}],"asks":[],"checksum":157275247,"timestamp":"2024-06-01T22:42:21.770421Z"}]}
{"channel":"book","type":"update","data":[{"symbol":"SOL/EUR","bids":[],"asks":[{"price":153.80,"qty":472.66326051}],"checksum":2975487697,"timestamp":"2024-06-01T22:42:24.182350Z"}]}
{"channel":"book","type":"update","data":[{"symbol":"SOL/EUR","bids":[],"asks":[{"price":153.80,"qty":442.73326051}],"checksum":1275079273,"timestamp":"2024-06-01T22:42:24.183520Z"}]}
{"channel":"book","type":"update","data":[{"symbol":"SOL/EUR","bids":[],"asks":[{"price":153.83,"qty":55.84047203}],"checksum":3994610120,"timestamp":"2024-06-01T22:42:24.232208Z"}]}
{"channel":"book","type":"update","data":[{"symbol":"SOL/EUR","bids":[],"asks":[{"price":153.80,"qty":430.76326051}],"checksum":2822552485,"timestamp":"2024-06-01T22:42:24.232455Z"}]}
{"channel":"book","type":"update","data":[{"symbol":"SOL/EUR","bids":[{"price":153.59,"qty":0.00000000},{"price":153.54,"qty":129.58323866}],"asks":[],"checksum":2794502892,"timestamp":"2024-06-01T22:42:24.242086Z"}]}
{"channel":"book","type":"update","data":[{"symbol":"SOL/EUR","bids":[],"asks":[{"price":153.83,"qty":67.84047203}],"checksum":198523225,"timestamp":"2024-06-01T22:42:24.245165Z"}]}
{"channel":"book","type":"update","data":[{"symbol":"SOL/EUR","bids":[{"price":153.60,"qty":30.00469243}],"asks":[],"checksum":3800330011,"timestamp":"2024-06-01T22:42:24.245228Z"}]}
{"channel":"book","type":"update","data":[{"symbol":"SOL/EUR","bids":[],"asks":[{"price":153.80,"qty":460.77836751}],"checksum":2280351253,"timestamp":"2024-06-01T22:42:24.295093Z"}]}
{"channel":"book","type":"update","data":[{"symbol":"SOL/EUR","bids":[],"asks":[{"price":153.81,"qty":171.06715683}],"checksum":1626553239,"timestamp":"2024-06-01T22:42:24.295744Z"}]}
{"channel":"book","type":"update","data":[{"symbol":"SOL/EUR","bids":[],"asks":[{"price":153.80,"qty":465.69297011}],"checksum":2190815921,"timestamp":"2024-06-01T22:42:24.306956Z"}]}
{"channel":"book","type":"update","data":[{"symbol":"SOL/EUR","bids":[{"price":153.55,"qty":31.07826376}],"asks":[],"checksum":602490389,"timestamp":"2024-06-01T22:42:24.321830Z"}]}
{"channel":"book","type":"update","data":[{"symbol":"SOL/EUR","bids":[{"price":153.56,"qty":65.98770052}],"asks":[],"checksum":1338804068,"timestamp":"2024-06-01T22:42:24.325403Z"}]}
{"channel":"book","type":"update","data":[{"symbol":"SOL/EUR","bids":[{"price":153.55,"qty":18.76941548}],"asks":[],"checksum":1526464357,"timestamp":"2024-06-01T22:42:24.347230Z"}]}
{"channel":"book","type":"update","data":[{"symbol":"SOL/EUR","bids":[{"price":153.57,"qty":95.57662536}],"asks":[],"checksum":1063847691,"timestamp":"2024-06-01T22:42:24.466382Z"}]}
{"channel":"book","type":"update","data":[{"symbol":"SOL/EUR","bids":[],"asks":[{"price":153.81,"qty":164.85985917}],"checksum":2508351367,"timestamp":"2024-06-01T22:42:24.515933Z"}]}
{"channel":"book","type":"update","data":[{"symbol":"SOL/EUR","bids":[],"asks":[{"price":153.80,"qty":458.31095446}],"checksum":4183516151,"timestamp":"2024-06-01T22:42:24.588429Z"}]}
{"channel":"book","type":"update","data":[{"symbol":"SOL/EUR","bids":[],"asks":[{"price":153.80,"qty":465.45871346}],"checksum":4237091228,"timestamp":"2024-06-01T22:42:24.589128Z"}]}
{"channel":"book","type":"update","data":[{"symbol":"SOL/EUR","bids":[],"asks":[{"price":153.83,"qty":74.04776969}],"checksum":1562789662,"timestamp":"2024-06-01T22:42:24.614444Z"}]}
{"channel":"book","type":"update","data":[{"symbol":"SOL/EUR","bids":[],"asks":[{"price":153.80,"qty":460.54411086}],"checksum":507331131,"timestamp":"2024-06-01T22:42:25.624606Z"}]}
{"channel":"book","type":"update","data":[{"symbol":"SOL/EUR","bids":[],"asks":[{"price":153.80,"qty":465.45871346}],"checksum":1562789662,"timestamp":"2024-06-01T22:42:25.743537Z"}]}
{"channel":"book","type":"update","data":[{"symbol":"SOL/EUR","bids":[],"asks":[{"price":153.80,"qty":460.54411086}],"checksum":507331131,"timestamp":"2024-06-01T22:42:26.022596Z"}]}
{"channel":"book","type":"update","data":[{"symbol":"SOL/EUR","bids":[],"asks":[{"price":153.80,"qty":426.73411086}],"checksum":1992859492,"timestamp":"2024-06-01T22:42:26.044576Z"}]}
{"channel":"book","type":"update","data":[{"symbol":"SOL/EUR","bids":[],"asks":[{"price":153.80,"qty":422.73611086}],"checksum":736645931,"timestamp":"2024-06-01T22:42:26.054089Z"}]}
{"channel":"book","type":"update","data":[{"symbol":"SOL/EUR","bids":[],"asks":[{"price":153.81,"qty":198.66985917}],"checksum":4148788894,"timestamp":"2024-06-01T22:42:26.065840Z"}]}
{"channel":"book","type":"update","data":[{"symbol":"SOL/EUR","bids":[{"price":153.60,"qty":0.00000000},{"price":153.54,"qty":129.58323866}],"asks":[],"checksum":3099282925,"timestamp":"2024-06-01T22:42:26.069395Z"}]}
{"channel":"book","type":"update","data":[{"symbol":"SOL/EUR","bids":[{"price":153.61,"qty":49.11359923}],"asks":[],"checksum":1862048989,"timestamp":"2024-06-01T22:42:26.072864Z"}]}
{"channel":"book","type":"update","data":[{"symbol":"SOL/EUR","bids":[{"price":153.56,"qty":20.97130126}],"asks":[],"checksum":4294679403,"timestamp":"2024-06-01T22:42:26.082487Z"}]}
{"channel":"book","type":"update","data":[{"symbol":"SOL/EUR","bids":[{"price":153.58,"qty":118.88020411}],"asks":[],"checksum":1632019759,"timestamp":"2024-06-01T22:42:26.086610Z"}]}
{"channel":"book","type":"update","data":[{"symbol":"SOL/EUR","bids":[{"price":153.62,"qty":4.05988649}],"asks":[],"checksum":4241439051,"timestamp":"2024-06-01T22:42:26.147035Z"}]}
{"channel":"book","type":"update","data":[{"symbol":"SOL/EUR","bids":[],"asks":[{"price":153.80,"qty":426.72911086}],"checksum":623429590,"timestamp":"2024-06-01T22:42:26.152766Z"}]}
{"channel":"book","type":"update","data":[{"symbol":"SOL/EUR","bids":[],"asks":[{"price":153.80,"qty":431.64371346}],"checksum":117180848,"timestamp":"2024-06-01T22:42:26.180703Z"}]}
{"channel":"book","type":"update","data":[{"symbol":"SOL/EUR","bids":[{"price":153.61,"qty":48.18041423},{"price":153.64,"qty":0.93307400}],"asks":[],"checksum":2401328181,"timestamp":"2024-06-01T22:42:26.183634Z"}]}
{"channel":"book","type":"update","data":[{"symbol":"SOL/EUR","bids":[{"price":153.62,"qty":0.00000000},{"price":153.55,"qty":18.76941548}],"asks":[],"checksum":816903186,"timestamp":"2024-06-01T22:42:26.224497Z"}]}
{"channel":"book","type":"update","data":[{"symbol":"SOL/EUR","bids":[],"asks":[{"price":153.80,"qty":424.49595446}],"checksum":2385252637,"timestamp":"2024-06-01T22:42:27.386170Z"}]}
{"channel":"book","type":"update","data":[{"symbol":"SOL/EUR","bids":[],"asks":[{"price":153.80,"qty":431.87752738}],"checksum":1017571136,"timestamp":"2024-06-01T22:42:27.387371Z"}]}
{"channel":"book","type":"update","data":[{"symbol":"SOL/EUR","bids":[{"price":153.59,"qty":6.68345085}],"asks":[],"checksum":2633453370,"timestamp":"2024-06-01T22:42:27.432009Z"}]}
{"channel":"book","type":"update","data":[{"symbol":"SOL/EUR","bids":[{"price":153.59,"qty":0.00000000},{"price":153.55,"qty":18.76941548}],"asks":[],"checksum":1017571136,"timestamp":"2024-06-01T22:42:27.506636Z"}]}
{"channel":"book","type":"update","data":[{"symbol":"SOL/EUR","bids":[],"asks":[{"price":153.80,"qty":426.96292478}],"checksum":1360911005,"timestamp":"2024-06-01T22:42:27.620800Z"}]}
{"channel":"book","type":"update","data":[{"symbol":"SOL/EUR","bids":[],"asks":[{"price":153.80,"qty":417.52495677}],"checksum":1355674424,"timestamp":"2024-06-01T22:42:27.629378Z"}]}
{"channel":"book","type":"update","data":[{"symbol":"SOL/EUR","bids":[],"asks":[{"price":153.80,"qty":422.43955937}],"checksum":1315061727,"timestamp":"2024-06-01T22:42:27.740697Z"}]}
{"channel":"book","type":"update","data":[{"symbol":"SOL/EUR","bids":[],"asks":[{"price":153.80,"qty":432.62752738}],"checksum":451367501,"timestamp":"2024-06-01T22:42:27.752286Z"}]}
{"channel":"book","type":"update","data":[{"symbol":"SOL/EUR","bids":[{"price":153.55,"qty":6.85381355}],"asks":[],"checksum":4024602659,"timestamp":"2024-06-01T22:42:27.850204Z"}]}
{"channel":"book","type":"update","data":[{"symbol":"SOL/EUR","bids":[{"price":153.56,"qty":32.88612724}],"asks":[],"checksum":1207566459,"timestamp":"2024-06-01T22:42:27.856008Z"}]}
{"channel":"book","type":"update","data":[{"symbol":"SOL/EUR","bids":[],"asks":[{"price":153.80,"qty":423.88775000},{"price":153.80,"qty":431.66201612}],"checksum":2162535243,"timestamp":"2024-06-01T22:42:28.052819Z"}]}
{"channel":"book","type":"update","data":[{"symbol":"SOL/EUR","bids":[],"asks":[{"price":153.80,"qty":256.22545275}],"checksum":85453929,"timestamp":"2024-06-01T22:42:28.613369Z"}]}
{"channel":"book","type":"update","data":[{"symbol":"SOL/EUR","bids":[],"asks":[{"price":153.80,"qty":447.57267107}],"checksum":2188857795,"timestamp":"2024-06-01T22:42:28.613980Z"}]}
{"channel":"book","type":"update","data":[{"symbol":"SOL/EUR","bids":[{"price":153.58,"qty":45.01326686}],"asks":[],"checksum":607549276,"timestamp":"2024-06-01T22:42:29.121738Z"}]}
{"channel":"book","type":"update","data":[{"symbol":"SOL/EUR","bids":[{"price":153.56,"qty":32.21797151}],"asks":[],"checksum":3900417254,"timestamp":"2024-06-01T22:42:29.399134Z"}]}
{"channel":"book","type":"update","data":[{"symbol":"SOL/EUR","bids":[{"price":153.55,"qty":0.00000000},{"price":153.54,"qty":254.94395881}],"asks":[],"checksum":1312721285,"timestamp":"2024-06-01T22:42:29.399205Z"}]}
{"channel":"book","type":"update","data":[{"symbol":"SOL/EUR","bids":[{"price":153.54,"qty":181.07702156},{"price":153.58,"qty":118.88020411}],"asks":[],"checksum":1300978971,"timestamp":"2024-06-01T22:42:29.402542Z"}]}
{"channel":"book","type":"update","data":[{"symbol":"SOL/EUR","bids":[{"price":153.55,"qty":8.58349438}],"asks":[],"checksum":1372202410,"timestamp":"2024-06-01T22:42:29.403730Z"}]}
{"channel":"book","type":"update","data":[{"symbol":"SOL/EUR","bids":[{"price":153.57,"qty":33.35434056}],"asks":[],"checksum":3915941733,"timestamp":"2024-06-01T22:42:29.985486Z"}]}
{"channel":"book","type":"update","data":[{"symbol":"SOL/EUR","bids":[{"price":153.61,"qty":110.40269903}],"asks":[],"checksum":2199959557,"timestamp":"2024-06-01T22:42:29.988108Z"}]}
{"channel":"book","type":"update","data":[{"symbol":"SOL/EUR","bids":[],"asks":[{"price":153.80,"qty":440.19109815}],"checksum":821314487,"timestamp":"2024-06-01T22:42:30.152136Z"}]}
{"channel":"book","type":"update","data":[{"symbol":"SOL/EUR","bids":[],"asks":[{"price":153.80,"qty":447.68979237}],"checksum":3358725972,"timestamp":"2024-06-01T22:42:30.153386Z"}]}
{"channel":"book","type":"update","data":[{"symbol":"SOL/EUR","bids":[{"price":153.55,"qty":0.00000000},{"price":153.54,"qty":181.07702156}],"asks":[],"checksum":258169168,"timestamp":"2024-06-01T22:42:31.938619Z"}]}
{"channel":"book","type":"update","data":[{"symbol":"SOL/EUR","bids":[{"price":153.55,"qty":8.50067886}],"asks":[],"checksum":3925869158,"timestamp":"2024-06-01T22:42:31.943614Z"}]}
{"channel":"book","type":"update","data":[{"symbol":"SOL/EUR","bids":[],"asks":[{"price":153.80,"qty":256.34257405}],"checksum":2409801375,"timestamp":"2024-06-01T22:42:33.211626Z"}]}
{"channel":"book","type":"update","data":[{"symbol":"SOL/EUR","bids":[],"asks":[{"price":153.80,"qty":411.82139399}],"checksum":3306309542,"timestamp":"2024-06-01T22:42:33.212212Z"}]}
{"channel":"book","type":"update","data":[{"symbol":"SOL/EUR","bids":[{"price":153.58,"qty":45.01326686}],"asks":[],"checksum":4266031040,"timestamp":"2024-06-01T22:42:33.397372Z"}]}
{"channel":"book","type":"update","data":[{"symbol":"SOL/EUR","bids":[{"price":153.55,"qty":82.36761611}],"asks":[],"checksum":1603484210,"timestamp":"2024-06-01T22:42:33.438801Z"}]}
{"channel":"book","type":"update","data":[{"symbol":"SOL/EUR","bids":[{"price":153.56,"qty":36.20997151}],"asks":[],"checksum":4067609629,"timestamp":"2024-06-01T22:42:34.567325Z"}]}
{"channel":"book","type":"update","data":[{"symbol":"SOL/EUR","bids":[{"price":153.55,"qty":73.86693725}],"asks":[],"checksum":2280648343,"timestamp":"2024-06-01T22:42:34.574236Z"}]}
{"channel":"book","type":"update","data":[{"symbol":"SOL/EUR","bids":[{"price":153.55,"qty":78.06480615}],"asks":[],"checksum":2662167902,"timestamp":"2024-06-01T22:42:34.579263Z"}]}
{"channel":"book","type":"update","data":[{"symbol":"SOL/EUR","bids":[{"price":153.56,"qty":42.59360537}],"asks":[],"checksum":3920836428,"timestamp":"2024-06-01T22:42:34.579272Z"}]}
{"channel":"book","type":"update","data":[{"symbol":"SOL/EUR","bids":[],"asks":[{"price":153.92,"qty":0.00000000},{"price":153.94,"qty":6.74595890}],"checksum":1181429297,"timestamp":"2024-06-01T22:42:34.946331Z"}]}
{"channel":"book","type":"update","data":[{"symbol":"SOL/EUR","bids":[],"asks":[{"price":153.93,"qty":7.28000000}],"checksum":2817808314,"timestamp":"2024-06-01T22:42:35.006326Z"}]}
{"channel":"book","type":"update","data":[{"symbol":"SOL/EUR","bids":[],"asks":[{"price":153.80,"qty":404.32269977}],"checksum":3888673235,"timestamp":"2024-06-01T22:42:35.706869Z"}]}
{"channel":"book","type":"update","data":[{"symbol":"SOL/EUR","bids":[],"asks":[{"price":153.80,"qty":411.35290878}],"checksum":2316064148,"timestamp":"2024-06-01T22:42:35.707579Z"}]}
{"channel":"book","type":"update","data":[{"symbol":"SOL/EUR","bids":[{"price":153.56,"qty":30.67877939}],"asks":[],"checksum":1845400759,"timestamp":"2024-06-01T22:42:35.723517Z"}]}
{"channel":"book","type":"update","data":[{"symbol":"SOL/EUR","bids":[],"asks":[{"price":153.81,"qty":164.85985917},{"price":153.80,"qty":445.16290878}],"checksum":463655066,"timestamp":"2024-06-01T22:42:35.726897Z"}]}
{"channel":"book","type":"update","data":[{"symbol":"SOL/EUR","bids":[{"price":153.56,"qty":26.68677939}],"asks":[],"checksum":21038644,"timestamp":"2024-06-01T22:42:35.727425Z"}]}
{"channel":"book","type":"update","data":[{"symbol":"SOL/EUR","bids":[{"price":153.61,"qty":48.18041423}],"asks":[],"checksum":1218648180,"timestamp":"2024-06-01T22:42:35.727773Z"}]}
{"channel":"book","type":"update","data":[{"symbol":"SOL/EUR","bids":[{"price":153.57,"qty":12.54742226}],"asks":[],"checksum":4045858113,"timestamp":"2024-06-01T22:42:35.728209Z"}]}
{"channel":"book","type":"update","data":[{"symbol":"SOL/EUR","bids":[{"price":153.61,"qty":30.00283499}],"asks":[],"checksum":2561545466,"timestamp":"2024-06-01T22:42:35.728527Z"}]}
{"channel":"book","type":"update","data":[{"symbol":"SOL/EUR","bids":[],"asks":[{"price":153.87,"qty":17.31719356}],"checksum":2794551321,"timestamp":"2024-06-01T22:42:35.728687Z"}]}
{"channel":"book","type":"update","data":[{"symbol":"SOL/EUR","bids":[],"asks":[{"price":153.84,"qty":59.91874104}],"checksum":1701987523,"timestamp":"2024-06-01T22:42:35.729271Z"}]}
{"channel":"book","type":"update","data":[{"symbol":"SOL/EUR","bids":[{"price":153.56,"qty":22.62689290}],"asks":[],"checksum":1627779394,"timestamp":"2024-06-01T22:42:35.731492Z"}]}
{"channel":"book","type":"update","data":[{"symbol":"SOL/EUR","bids":[],"asks":[{"price":153.92,"qty":91.57690560}],"checksum":1262372869,"timestamp":"2024-06-01T22:42:35.732064Z"}]}
{"channel":"book","type":"update","data":[{"symbol":"SOL/EUR","bids":[{"price":153.79,"qty":49.92483663}],"asks":[],"checksum":693754064,"timestamp":"2024-06-01T22:42:35.734758Z"}]}
{"channel":"book","type":"update","data":[{"symbol":"SOL/EUR","bids":[{"price":153.79,"qty":49.72483663}],"asks":[],"checksum":2963023859,"timestamp":"2024-06-01T22:42:35.735354Z"}]}
{"channel":"book","type":"update","data":[{"symbol":"SOL/EUR","bids":[{"price":153.58,"qty":0.00000000},{"price":153.54,"qty":197.89093986}],"asks":[],"checksum":341308962,"timestamp":"2024-06-01T22:42:35.735635Z"}]}
{"channel":"book","type":"update","data":[{"symbol":"SOL/EUR","bids":[{"price":153.61,"qty":0.00000000},{"price":153.52,"qty":60.03821964}],"asks":[],"checksum":2949903431,"timestamp":"2024-06-01T22:42:35.735771Z"}]}
{"channel":"book","type":"update","data":[{"symbol":"SOL/EUR","bids":[{"price":153.55,"qty":82.12469264}],"asks":[],"checksum":3260647305,"timestamp":"2024-06-01T22:42:35.735785Z"}]}
{"channel":"book","type":"update","data":[{"symbol":"SOL/EUR","bids":[],"asks":[{"price":153.83,"qty":62.04776969},{"price":153.80,"qty":457.16290878}],"checksum":3821740255,"timestamp":"2024-06-01T22:42:35.736452Z"}]}
{"channel":"book","type":"update","data":[{"symbol":"SOL/EUR","bids":[{"price":153.54,"qty":177.08402156}],"asks":[],"checksum":2344786977,"timestamp":"2024-06-01T22:42:35.738137Z"}]}
{"channel":"book","type":"update","data":[{"symbol":"SOL/EUR","bids":[{"price":153.55,"qty":78.06480615}],"asks":[],"checksum":3863539695,"timestamp":"2024-06-01T22:42:35.741457Z"}]}
{"channel":"book","type":"update","data":[{"symbol":"SOL/EUR","bids":[{"price":153.79,"qty":49.32483663}],"asks":[],"checksum":457985543,"timestamp":"2024-06-01T22:42:35.741480Z"}]}
{"channel":"book","type":"update","data":[{"symbol":"SOL/EUR","bids":[{"price":153.79,"qty":48.92483663}],"asks":[],"checksum":4099506792,"timestamp":"2024-06-01T22:42:35.743032Z"}]}
{"channel":"book","type":"update","data":[{"symbol":"SOL/EUR","bids":[{"price":153.55,"qty":108.07939391}],"asks":[],"checksum":3763694579,"timestamp":"2024-06-01T22:42:35.743259Z"}]}
{"channel":"book","type":"update","data":[{"symbol":"SOL/EUR","bids":[],"asks":[{"price":153.83,"qty":32.05776969},{"price":153.80,"qty":487.15290878}],"checksum":1590984609,"timestamp":"2024-06-01T22:42:35.745473Z"}]}
{"channel":"book","type":"update","data":[{"symbol":"SOL/EUR","bids":[{"price":153.52,"qty":0.00000000},{"price":153.51,"qty":243.22046077}],"asks":[],"checksum":2787147458,"timestamp":"2024-06-01T22:42:35.747801Z"}]}
{"channel":"book","type":"update","data":[{"symbol":"SOL/EUR","bids":[{"price":153.57,"qty":0.24017701}],"asks":[],"checksum":4287323384,"timestamp":"2024-06-01T22:42:35.748102Z"}]}
{"channel":"book","type":"update","data":[{"symbol":"SOL/EUR","bids":[{"price":153.55,"qty":78.06480615}],"asks":[],"checksum":3802968069,"timestamp":"2024-06-01T22:42:35.749025Z"}]}
{"channel":"book","type":"update","data":[{"symbol":"SOL/EUR","bids":[{"price":153.79,"qty":31.92483663}],"asks":[],"checksum":1492704858,"timestamp":"2024-06-01T22:42:35.749159Z"}]}
{"channel":"book","type":"update","data":[{"symbol":"SOL/EUR","bids":[],"asks":[{"price":153.80,"qty":482.23830618}],"checksum":2684901701,"timestamp":"2024-06-01T22:42:35.752717Z"}]}
{"channel":"book","type":"update","data":[{"symbol":"SOL/EUR","bids":[{"price":153.51,"qty":242.07889673}],"asks":[],"checksum":3578700365,"timestamp":"2024-06-01T22:42:35.757777Z"}]}
{"channel":"book","type":"update","data":[{"symbol":"SOL/EUR","bids":[{"price":153.51,"qty":231.71618169}],"asks":[],"checksum":338498412,"timestamp":"2024-06-01T22:42:35.794302Z"}]}
{"channel":"book","type":"update","data":[{"symbol":"SOL/EUR","bids":[{"price":153.56,"qty":41.49901761}],"asks":[],"checksum":2842221043,"timestamp":"2024-06-01T22:42:35.825430Z"}]}
{"channel":"book","type":"update","data":[{"symbol":"SOL/EUR","bids":[{"price":153.51,"qty":207.71016170}],"asks":[],"checksum":1728317105,"timestamp":"2024-06-01T22:42:35.826546Z"}]}
{"channel":"book","type":"update","data":[{"symbol":"SOL/EUR","bids":[],"asks":[{"price":153.82,"qty":18.57627294}],"checksum":373191837,"timestamp":"2024-06-01T22:42:35.827363Z"}]}
{"channel":"book","type":"update","data":[{"symbol":"SOL/EUR","bids":[{"price":153.64,"qty":0.00000000},{"price":153.50,"qty":124.91856917},{"price":153.58,"qty":0.93330000}],"asks":[],"checksum":1221862919,"timestamp":"2024-06-01T22:42:35.842478Z"}]}
{"channel":"book","type":"update","data":[{"symbol":"SOL/EUR","bids":[],"asks":[{"price":153.80,"qty":487.52940430}],"checksum":2117140387,"timestamp":"2024-06-01T22:42:35.855854Z"}]}
{"channel":"book","type":"update","data":[{"symbol":"SOL/EUR","bids":[],"asks":[{"price":153.83,"qty":25.85047203}],"checksum":1621243426,"timestamp":"2024-06-01T22:42:35.855963Z"}]}
{"channel":"book","type":"update","data":[{"symbol":"SOL/EUR","bids":[],"asks":[{"price":153.91,"qty":0.00000000},{"price":153.92,"qty":91.57690560}],"checksum":1065696001,"timestamp":"2024-06-01T22:42:35.856111Z"}]}
{"channel":"book","type":"update","data":[{"symbol":"SOL/EUR","bids":[],"asks":[{"price":153.83,"qty":16.29000000}],"checksum":1577241421,"timestamp":"2024-06-01T22:42:35.869297Z"}]}
{"channel":"book","type":"update","data":[{"symbol":"SOL/EUR","bids":[],"asks":[{"price":153.80,"qty":497.08987633}],"checksum":2921073586,"timestamp":"2024-06-01T22:42:35.869566Z"}]}
{"channel":"book","type":"update","data":[{"symbol":"SOL/EUR","bids":[{"price":153.57,"qty":4.30006350}],"asks":[],"checksum":2577278524,"timestamp":"2024-06-01T22:42:35.885816Z"}]}
{"channel":"book","type":"update","data":[{"symbol":"SOL/EUR","bids":[{"price":153.55,"qty":73.86693725}],"asks":[],"checksum":2880764315,"timestamp":"2024-06-01T22:42:35.887748Z"}]}
{"channel":"book","type":"update","data":[{"symbol":"SOL/EUR","bids":[],"asks":[{"price":153.83,"qty":23.98000000}],"checksum":3998761671,"timestamp":"2024-06-01T22:42:35.908413Z"}]}
{"channel":"book","type":"update","data":[{"symbol":"SOL/EUR","bids":[{"price":153.52,"qty":10.36203997}],"asks":[],"checksum":3870897224,"timestamp":"2024-06-01T22:42:35.917947Z"}]}
{"channel":"book","type":"update","data":[{"symbol":"SOL/EUR","bids":[{"price":153.57,"qty":0.24017701}],"asks":[],"checksum":1803332579,"timestamp":"2024-06-01T22:42:35.931397Z"}]}
{"channel":"book","type":"update","data":[{"symbol":"SOL/EUR","bids":[{"price":153.79,"qty":25.66583663}],"asks":[],"checksum":244699646,"timestamp":"2024-06-01T22:42:35.932765Z"}]}
{"channel":"book","type":"update","data":[{"symbol":"SOL/EUR","bids":[{"price":153.56,"qty":35.11538375}],"asks":[],"checksum":4258880877,"timestamp":"2024-06-01T22:42:35.940582Z"}]}
{"channel":"book","type":"update","data":[{"symbol":"SOL/EUR","bids":[],"asks":[{"price":153.89,"qty":17.82222637}],"checksum":1627779765,"timestamp":"2024-06-01T22:42:35.954697Z"}]}
{"channel":"book","type":"update","data":[{"symbol":"SOL/EUR","bids":[],"asks":[{"price":153.88,"qty":66.10818687}],"checksum":2002180836,"timestamp":"2024-06-01T22:42:35.954830Z"}]}
{"channel":"book","type":"update","data":[{"symbol":"SOL/EUR","bids":[{"price":153.79,"qty":0.00000000},{"price":153.51,"qty":207.71016170}],"asks":[],"checksum":1993870604,"timestamp":"2024-06-01T22:42:35.956430Z"}]}
{"channel":"book","type":"update","data":[{"symbol":"SOL/EUR","bids":[{"price":153.57,"qty":4.30006350}],"asks":[],"checksum":4193653421,"timestamp":"2024-06-01T22:42:35.959023Z"}]}
{"channel":"book","type":"update","data":[{"symbol":"SOL/EUR","bids":[{"price":153.59,"qty":8.00000000}],"asks":[],"checksum":1302387915,"timestamp":"2024-06-01T22:42:35.960065Z"}]}
{"channel":"book","type":"update","data":[{"symbol":"SOL/EUR","bids":[{"price":153.52,"qty":44.17203997}],"asks":[],"checksum":305613386,"timestamp":"2024-06-01T22:42:35.960156Z"}]}
{"channel":"book","type":"update","data":[{"symbol":"SOL/EUR","bids":[],"asks":[{"price":153.81,"qty":134.89569701}],"checksum":1004200171,"timestamp":"2024-06-01T22:42:35.960342Z"}]}
{"channel":"book","type":"update","data":[{"symbol":"SOL/EUR","bids":[],"asks":[{"price":153.81,"qty":89.94667277}],"checksum":3513232314,"timestamp":"2024-06-01T22:42:35.960399Z"}]}
{"channel":"book","type":"update","data":[{"symbol":"SOL/EUR","bids":[],"asks":[{"price":153.81,"qty":30.01510700}],"checksum":947680825,"timestamp":"2024-06-01T22:42:35.960588Z"}]}
{"channel":"book","type":"update","data":[{"symbol":"SOL/EUR","bids":[],"asks":[{"price":153.80,"qty":496.88987633}],"checksum":3331922630,"timestamp":"2024-06-01T22:42:35.961583Z"}]}
{"channel":"book","type":"update","data":[{"symbol":"SOL/EUR","bids":[],"asks":[{"price":153.80,"qty":486.70190832}],"checksum":3422004844,"timestamp":"2024-06-01T22:42:35.963375Z"}]}
{"channel":"book","type":"update","data":[{"symbol":"SOL/EUR","bids":[],"asks":[{"price":153.80,"qty":485.88642709},{"price":153.79,"qty":0.81610501}],"checksum":2183526796,"timestamp":"2024-06-01T22:42:35.963816Z"}]}
{"channel":"book","type":"update","data":[{"symbol":"SOL/EUR","bids":[{"price":153.54,"qty":207.09924309}],"asks":[],"checksum":693739493,"timestamp":"2024-06-01T22:42:35.964686Z"}]}
{"channel":"book","type":"update","data":[{"symbol":"SOL/EUR","bids":[],"asks":[{"price":153.76,"qty":44.96067381}],"checksum":3101458317,"timestamp":"2024-06-01T22:42:35.964766Z"}]}
{"channel":"book","type":"update","data":[{"symbol":"SOL/EUR","bids":[],"asks":[{"price":153.79,"qty":60.75197605}],"checksum":2426327970,"timestamp":"2024-06-01T22:42:35.964793Z"}]}
{"channel":"book","type":"update","data":[{"symbol":"SOL/EUR","bids":[{"price":153.54,"qty":30.28986065}],"asks":[],"checksum":3832335544,"timestamp":"2024-06-01T22:42:35.964831Z"}]}
{"channel":"book","type":"update","data":[{"symbol":"SOL/EUR","bids":[],"asks":[{"price":153.76,"qty":74.93445635}],"checksum":2571509395,"timestamp":"2024-06-01T22:42:35.964842Z"}]}
{"channel":"book","type":"update","data":[{"symbol":"SOL/EUR","bids":[],"asks":[{"price":153.79,"qty":120.68784709}],"checksum":1075657529,"timestamp":"2024-06-01T22:42:35.964943Z"}]}
{"channel":"book","type":"update","data":[{"symbol":"SOL/EUR","bids":[],"asks":[{"price":153.80,"qty":481.89342709}],"checksum":2883395295,"timestamp":"2024-06-01T22:42:35.967605Z"}]}
{"channel":"book","type":"update","data":[{"symbol":"SOL/EUR","bids":[],"asks":[{"price":153.80,"qty":473.89342709}],"checksum":342006151,"timestamp":"2024-06-01T22:42:35.967822Z"}]}
{"channel":"book","type":"update","data":[{"symbol":"SOL/EUR","bids":[],"asks":[{"price":153.76,"qty":82.93445635}],"checksum":1262674514,"timestamp":"2024-06-01T22:42:35.967952Z"}]}
{"channel":"book","type":"update","data":[{"symbol":"SOL/EUR","bids":[{"price":153.55,"qty":0.00000000},{"price":153.51,"qty":252.74355055},{"price":153.53,"qty":73.86693725}],"asks":[],"checksum":3277578539,"timestamp":"2024-06-01T22:42:35.968151Z"}]}
{"channel":"book","type":"update","data":[{"symbol":"SOL/EUR","bids":[],"asks":[{"price":153.79,"qty":60.75197605}],"checksum":1624466029,"timestamp":"2024-06-01T22:42:35.969359Z"}]}
{"channel":"book","type":"update","data":[{"symbol":"SOL/EUR","bids":[],"asks":[{"price":153.79,"qty":0.81610501}],"checksum":821347708,"timestamp":"2024-06-01T22:42:35.969468Z"}]}
{"channel":"book","type":"update","data":[{"symbol":"SOL/EUR","bids":[],"asks":[{"price":153.78,"qty":30.01240686}],"checksum":2734408053,"timestamp":"2024-06-01T22:42:35.969513Z"}]}
{"channel":"book","type":"update","data":[{"symbol":"SOL/EUR","bids":[],"asks":[{"price":153.79,"qty":30.82851187}],"checksum":1911296186,"timestamp":"2024-06-01T22:42:35.970297Z"}]}
{"channel":"book","type":"update","data":[{"symbol":"SOL/EUR","bids":[],"asks":[{"price":153.81,"qty":0.00000000},{"price":153.88,"qty":66.10818687}],"checksum":3333012569,"timestamp":"2024-06-01T22:42:35.973241Z"}]}
{"channel":"book","type":"update","data":[{"symbol":"SOL/EUR","bids":[],"asks":[{"price":153.80,"qty":443.87832009}],"checksum":1935884262,"timestamp":"2024-06-01T22:42:35.973910Z"}]}
{"channel":"book","type":"update","data":[{"symbol":"SOL/EUR","bids":[{"price":153.52,"qty":33.81000000},{"price":153.53,"qty":84.22830231}],"asks":[],"checksum":1684532068,"timestamp":"2024-06-01T22:42:35.976947Z"}]}
{"channel":"book","type":"update","data":[{"symbol":"SOL/EUR","bids":[],"asks":[{"price":153.80,"qty":436.10405397},{"price":153.76,"qty":90.70873563}],"checksum":1532657910,"timestamp":"2024-06-01T22:42:35.977070Z"}]}
{"channel":"book","type":"update","data":[{"symbol":"SOL/EUR","bids":[],"asks":[{"price":153.81,"qty":9.56047203}],"checksum":3677837144,"timestamp":"2024-06-01T22:42:35.984379Z"}]}
{"channel":"book","type":"update","data":[{"symbol":"SOL/EUR","bids":[],"asks":[{"price":153.80,"qty":426.54358194}],"checksum":3118270638,"timestamp":"2024-06-01T22:42:35.985042Z"}]}
{"channel":"book","type":"update","data":[{"symbol":"SOL/EUR","bids":[{"price":153.53,"qty":73.86693725}],"asks":[],"checksum":1274126093,"timestamp":"2024-06-01T22:42:36.003692Z"}]}
{"channel":"book","type":"update","data":[{"symbol":"SOL/EUR","bids":[{"price":153.53,"qty":0.00000000},{"price":153.51,"qty":45.03338885}],"asks":[],"checksum":778724815,"timestamp":"2024-06-01T22:42:36.006948Z"}]}
{"channel":"book","type":"update","data":[{"symbol":"SOL/EUR","bids":[{"price":153.58,"qty":0.00000000},{"price":153.50,"qty":47.26980142},{"price":153.54,"qty":31.22333465}],"asks":[],"checksum":3437116673,"timestamp":"2024-06-01T22:42:36.014314Z"}]}
{"channel":"book","type":"update","data":[{"symbol":"SOL/EUR","bids":[{"price":153.56,"qty":55.92771505}],"asks":[],"checksum":1332664196,"timestamp":"2024-06-01T22:42:36.017637Z"}]}
{"channel":"book","type":"update","data":[{"symbol":"SOL/EUR","bids":[{"price":153.59,"qty":0.00000000},{"price":153.47,"qty":15.29000000}],"asks":[],"checksum":3198759196,"timestamp":"2024-06-01T22:42:36.020065Z"}]}
{"channel":"book","type":"update","data":[{"symbol":"SOL/EUR","bids":[{"price":153.54,"qty":1.20811312}],"asks":[],"checksum":2709873286,"timestamp":"2024-06-01T22:42:36.020276Z"}]}
{"channel":"book","type":"update","data":[{"symbol":"SOL/EUR","bids":[{"price":153.58,"qty":8.00000000}],"asks":[],"checksum":2320063130,"timestamp":"2024-06-01T22:42:36.020381Z"}]}
{"channel":"book","type":"update","data":[{"symbol":"SOL/EUR","bids":[{"price":153.50,"qty":46.12816352}],"asks":[],"checksum":508192270,"timestamp":"2024-06-01T22:42:36.021806Z"}]}
{"channel":"book","type":"update","data":[{"symbol":"SOL/EUR","bids":[],"asks":[{"price":153.76,"qty":82.93445635},{"price":153.77,"qty":7.77427928}],"checksum":1293879106,"timestamp":"2024-06-01T22:42:36.022743Z"}]}
{"channel":"book","type":"update","data":[{"symbol":"SOL/EUR","bids":[{"price":153.53,"qty":10.36136501}],"asks":[],"checksum":2867139089,"timestamp":"2024-06-01T22:42:36.051951Z"}]}
{"channel":"book","type":"update","data":[{"symbol":"SOL/EUR","bids":[],"asks":[{"price":153.76,"qty":87.13945635}],"checksum":359224339,"timestamp":"2024-06-01T22:42:36.066338Z"}]}
{"channel":"book","type":"update","data":[{"symbol":"SOL/EUR","bids":[{"price":153.53,"qty":40.37893342}],"asks":[],"checksum":3816958822,"timestamp":"2024-06-01T22:42:36.087782Z"}]}
{"channel":"book","type":"update","data":[{"symbol":"SOL/EUR","bids":[{"price":153.53,"qty":30.01756841}],"asks":[],"checksum":470538791,"timestamp":"2024-06-01T22:42:36.102289Z"}]}
{"channel":"book","type":"update","data":[{"symbol":"SOL/EUR","bids":[],"asks":[{"price":153.79,"qty":36.75722351}],"checksum":2385912237,"timestamp":"2024-06-01T22:42:36.110384Z"}]}
{"channel":"book","type":"update","data":[{"symbol":"SOL/EUR","bids":[],"asks":[{"price":153.80,"qty":425.61130594},{"price":153.76,"qty":88.07212535}],"checksum":828355501,"timestamp":"2024-06-01T22:42:36.122097Z"}]}
{"channel":"book","type":"update","data":[{"symbol":"SOL/EUR","bids":[{"price":153.53,"qty":0.00000000},{"price":153.50,"qty":46.12816352}],"asks":[],"checksum":3754371274,"timestamp":"2024-06-01T22:42:36.150368Z"}]}
{"channel":"book","type":"update","data":[{"symbol":"SOL/EUR","bids":[],"asks":[{"price":153.77,"qty":0.00000000},{"price":153.87,"qty":17.31719356},{"price":153.76,"qty":95.84640463}],"checksum":3749870212,"timestamp":"2024-06-01T22:42:36.159186Z"}]}
{"channel":"book","type":"update","data":[{"symbol":"SOL/EUR","bids":[{"price":153.55,"qty":30.01427969}],"asks":[],"checksum":3350926253,"timestamp":"2024-06-01T22:42:36.188146Z"}]}
{"channel":"book","type":"update","data":[{"symbol":"SOL/EUR","bids":[],"asks":[{"price":153.80,"qty":391.80130594},{"price":153.78,"qty":63.82240686}],"checksum":168103764,"timestamp":"2024-06-01T22:42:36.255334Z"}]}
{"channel":"book","type":"update","data":[{"symbol":"SOL/EUR","bids":[{"price":153.57,"qty":14.65872972}],"asks":[],"checksum":2923945400,"timestamp":"2024-06-01T22:42:36.257714Z"}]}
{"channel":"book","type":"update","data":[{"symbol":"SOL/EUR","bids":[],"asks":[{"price":153.80,"qty":385.54139053}],"checksum":1632052882,"timestamp":"2024-06-01T22:42:36.259754Z"}]}
{"channel":"book","type":"update","data":[{"symbol":"SOL/EUR","bids":[],"asks":[{"price":153.76,"qty":106.03437264}],"checksum":1766360862,"timestamp":"2024-06-01T22:42:36.260624Z"}]}
{"channel":"book","type":"update","data":[{"symbol":"SOL/EUR","bids":[],"asks":[{"price":153.80,"qty":361.53706427}],"checksum":574343714,"timestamp":"2024-06-01T22:42:36.268447Z"}]}
{"channel":"book","type":"update","data":[{"symbol":"SOL/EUR","bids":[],"asks":[{"price":153.76,"qty":165.98193772}],"checksum":3027428370,"timestamp":"2024-06-01T22:42:36.347861Z"}]}
{"channel":"book","type":"update","data":[{"symbol":"SOL/EUR","bids":[],"asks":[{"price":153.83,"qty":16.29000000}],"checksum":3291371476,"timestamp":"2024-06-01T22:42:36.353223Z"}]}
{"channel":"book","type":"update","data":[{"symbol":"SOL/EUR","bids":[],"asks":[{"price":153.77,"qty":14.22000000}],"checksum":324136858,"timestamp":"2024-06-01T22:42:36.492562Z"}]}
{"channel":"book","type":"update","data":[{"symbol":"SOL/EUR","bids":[{"price":153.52,"qty":63.80000000}],"asks":[],"checksum":1515147695,"timestamp":"2024-06-01T22:42:36.496229Z"}]}
{"channel":"book","type":"update","data":[{"symbol":"SOL/EUR","bids":[],"asks":[{"price":153.76,"qty":166.18193772}],"checksum":2370174840,"timestamp":"2024-06-01T22:42:36.497197Z"}]}
{"channel":"book","type":"update","data":[{"symbol":"SOL/EUR","bids":[],"asks":[{"price":153.76,"qty":172.44348632}],"checksum":4218456890,"timestamp":"2024-06-01T22:42:36.506897Z"}]}
{"channel":"book","type":"update","data":[{"symbol":"SOL/EUR","bids":[{"price":153.53,"qty":2.40102942}],"asks":[],"checksum":2407771299,"timestamp":"2024-06-01T22:42:36.525800Z"}]}
{"channel":"book","type":"update","data":[{"symbol":"SOL/EUR","bids":[],"asks":[{"price":153.76,"qty":174.84451312}],"checksum":3875370998,"timestamp":"2024-06-01T22:42:36.571048Z"}]}
{"channel":"book","type":"update","data":[{"symbol":"SOL/EUR","bids":[],"asks":[{"price":153.76,"qty":234.79207820}],"checksum":2533661982,"timestamp":"2024-06-01T22:42:36.607784Z"}]}
{"channel":"book","type":"update","data":[{"symbol":"SOL/EUR","bids":[],"asks":[{"price":153.76,"qty":264.80448506}],"checksum":2015837271,"timestamp":"2024-06-01T22:42:36.690922Z"}]}
{"channel":"book","type":"update","data":[{"symbol":"SOL/EUR","bids":[],"asks":[{"price":153.78,"qty":33.81000000}],"checksum":142986458,"timestamp":"2024-06-01T22:42:36.694497Z"}]}
{"channel":"book","type":"update","data":[{"symbol":"SOL/EUR","bids":[],"asks":[{"price":153.76,"qty":269.71908766}],"checksum":3042706318,"timestamp":"2024-06-01T22:42:36.804203Z"}]}
{"channel":"book","type":"update","data":[{"symbol":"SOL/EUR","bids":[{"price":153.54,"qty":13.51776307}],"asks":[],"checksum":3734978913,"timestamp":"2024-06-01T22:42:36.805443Z"}]}
{"channel":"book","type":"update","data":[{"symbol":"SOL/EUR","bids":[{"price":153.52,"qty":33.81000000}],"asks":[],"checksum":2663481745,"timestamp":"2024-06-01T22:42:36.843103Z"}]}
{"channel":"book","type":"update","data":[{"symbol":"SOL/EUR","bids":[],"asks":[{"price":153.78,"qty":0.00000000},{"price":153.87,"qty":17.31719356},{"price":153.76,"qty":303.52908766}],"checksum":3339910137,"timestamp":"2024-06-01T22:42:36.847503Z"}]}
{"channel":"book","type":"update","data":[{"symbol":"SOL/EUR","bids":[],"asks":[{"price":153.76,"qty":269.71908766}],"checksum":258538214,"timestamp":"2024-06-01T22:42:36.855566Z"}]}
{"channel":"book","type":"update","data":[{"symbol":"SOL/EUR","bids":[{"price":153.54,"qty":1.20811312}],"asks":[],"checksum":940909360,"timestamp":"2024-06-01T22:42:36.862523Z"}]}
{"channel":"book","type":"update","data":[{"symbol":"SOL/EUR","bids":[{"price":153.52,"qty":0.00000000},{"price":153.51,"qty":45.03338885},{"price":153.55,"qty":63.82427969}],"asks":[],"checksum":2459303532,"timestamp":"2024-06-01T22:42:36.880553Z"}]}
{"channel":"book","type":"update","data":[{"symbol":"SOL/EUR","bids":[],"asks":[{"price":153.76,"qty":209.77152258}],"checksum":2812616265,"timestamp":"2024-06-01T22:42:36.882382Z"}]}
{"channel":"book","type":"update","data":[{"symbol":"SOL/EUR","bids":[{"price":153.55,"qty":33.81000000}],"asks":[],"checksum":2821412802,"timestamp":"2024-06-01T22:42:36.882462Z"}]}
{"channel":"book","type":"update","data":[{"symbol":"SOL/EUR","bids":[{"price":153.51,"qty":0.00000000},{"price":153.50,"qty":16.13816352}],"asks":[],"checksum":2917969794,"timestamp":"2024-06-01T22:42:36.882558Z"}]}
{"channel":"book","type":"update","data":[{"symbol":"SOL/EUR","bids":[],"asks":[{"price":153.76,"qty":204.85691998}],"checksum":2371427681,"timestamp":"2024-06-01T22:42:36.885191Z"}]}
{"channel":"book","type":"update","data":[{"symbol":"SOL/EUR","bids":[{"price":153.50,"qty":4.13816352},{"price":153.51,"qty":12.00000000}],"asks":[],"checksum":2300466847,"timestamp":"2024-06-01T22:42:36.885960Z"}]}
{"channel":"book","type":"update","data":[{"symbol":"SOL/EUR","bids":[{"price":153.52,"qty":45.02804176}],"asks":[],"checksum":3254438853,"timestamp":"2024-06-01T22:42:36.887157Z"}]}
{"channel":"book","type":"update","data":[{"symbol":"SOL/EUR","bids":[{"price":153.56,"qty":85.93932896}],"asks":[],"checksum":3266922545,"timestamp":"2024-06-01T22:42:36.887219Z"}]}
{"channel":"book","type":"update","data":[{"symbol":"SOL/EUR","bids":[],"asks":[{"price":153.76,"qty":200.65191998}],"checksum":2525890185,"timestamp":"2024-06-01T22:42:36.888183Z"}]}
{"channel":"book","type":"update","data":[{"symbol":"SOL/EUR","bids":[{"price":153.57,"qty":4.30006350}],"asks":[],"checksum":3164341681,"timestamp":"2024-06-01T22:42:36.891482Z"}]}
{"channel":"book","type":"update","data":[{"symbol":"SOL/EUR","bids":[{"price":153.59,"qty":3.29905569}],"asks":[],"checksum":520988806,"timestamp":"2024-06-01T22:42:36.891529Z"}]}
{"channel":"book","type":"update","data":[{"symbol":"SOL/EUR","bids":[],"asks":[{"price":153.80,"qty":356.24596615}],"checksum":4040345903,"timestamp":"2024-06-01T22:42:36.940318Z"}]}
{"channel":"book","type":"update","data":[{"symbol":"SOL/EUR","bids":[{"price":153.59,"qty":0.00000000},{"price":153.52,"qty":45.02804176}],"asks":[],"checksum":326746524,"timestamp":"2024-06-01T22:42:36.942733Z"}]}
{"channel":"book","type":"update","data":[{"symbol":"SOL/EUR","bids":[],"asks":[{"price":153.76,"qty":204.85691998}],"checksum":4200616042,"timestamp":"2024-06-01T22:42:36.986967Z"}]}
{"channel":"book","type":"update","data":[{"symbol":"SOL/EUR","bids":[{"price":153.52,"qty":75.01804176}],"asks":[],"checksum":549450228,"timestamp":"2024-06-01T22:42:37.010240Z"}]}
{"channel":"book","type":"update","data":[{"symbol":"SOL/EUR","bids":[{"price":153.58,"qty":18.36390900}],"asks":[],"checksum":2007579809,"timestamp":"2024-06-01T22:42:37.086971Z"}]}
{"channel":"book","type":"update","data":[{"symbol":"SOL/EUR","bids":[],"asks":[{"price":153.76,"qty":209.77152258}],"checksum":1461489218,"timestamp":"2024-06-01T22:42:37.115042Z"}]}
{"channel":"book","type":"update","data":[{"symbol":"SOL/EUR","bids":[{"price":153.55,"qty":0.00000000},{"price":153.51,"qty":12.00000000}],"asks":[],"checksum":1797126994,"timestamp":"2024-06-01T22:42:37.124661Z"}]}
{"channel":"book","type":"update","data":[{"symbol":"SOL/EUR","bids":[{"price":153.58,"qty":8.00000000},{"price":153.57,"qty":14.66464736}],"asks":[],"checksum":3780061006,"timestamp":"2024-06-01T22:42:37.127630Z"}]}
{"channel":"book","type":"update","data":[{"symbol":"SOL/EUR","bids":[],"asks":[{"price":153.76,"qty":204.85691998}],"checksum":3254425005,"timestamp":"2024-06-01T22:42:37.152954Z"}]}
{"channel":"book","type":"update","data":[{"symbol":"SOL/EUR","bids":[{"price":153.59,"qty":3.29920983}],"asks":[],"checksum":1934722997,"timestamp":"2024-06-01T22:42:37.153046Z"}]}
{"channel":"book","type":"update","data":[{"symbol":"SOL/EUR","bids":[{"price":153.55,"qty":12.30884828}],"asks":[],"checksum":1262145044,"timestamp":"2024-06-01T22:42:37.156992Z"}]}
{"channel":"book","type":"update","data":[{"symbol":"SOL/EUR","bids":[{"price":153.54,"qty":0.27463912},{"price":153.59,"qty":4.23243583}],"asks":[],"checksum":1668848894,"timestamp":"2024-06-01T22:42:37.234735Z"}]}
{"channel":"book","type":"update","data":[{"symbol":"SOL/EUR","bids":[{"price":153.58,"qty":0.00000000},{"price":153.52,"qty":75.01804176}],"asks":[],"checksum":843157881,"timestamp":"2024-06-01T22:42:37.245443Z"}]}
{"channel":"book","type":"update","data":[{"symbol":"SOL/EUR","bids":[{"price":153.60,"qty":8.00000000}],"asks":[],"checksum":1200422060,"timestamp":"2024-06-01T22:42:37.245617Z"}]}
{"channel":"book","type":"update","data":[{"symbol":"SOL/EUR","bids":[],"asks":[{"price":153.76,"qty":264.80448506}],"checksum":1802213772,"timestamp":"2024-06-01T22:42:37.251916Z"}]}
{"channel":"book","type":"update","data":[{"symbol":"SOL/EUR","bids":[],"asks":[{"price":153.76,"qty":269.71908766}],"checksum":1032563093,"timestamp":"2024-06-01T22:42:37.271719Z"}]}
{"channel":"book","type":"update","data":[{"symbol":"SOL/EUR","bids":[{"price":153.59,"qty":0.93322600}],"asks":[],"checksum":1726864810,"timestamp":"2024-06-01T22:42:37.359803Z"}]}
{"channel":"book","type":"update","data":[{"symbol":"SOL/EUR","bids":[],"asks":[{"price":153.78,"qty":33.81000000}],"checksum":1446065309,"timestamp":"2024-06-01T22:42:37.362866Z"}]}
{"channel":"book","type":"update","data":[{"symbol":"SOL/EUR","bids":[],"asks":[{"price":153.76,"qty":209.77152258}],"checksum":3140414306,"timestamp":"2024-06-01T22:42:37.376779Z"}]}
{"channel":"book","type":"update","data":[{"symbol":"SOL/EUR","bids":[{"price":153.53,"qty":36.21102942}],"asks":[],"checksum":48031558,"timestamp":"2024-06-01T22:42:37.381285Z"}]}
{"channel":"book","type":"update","data":[{"symbol":"SOL/EUR","bids":[],"asks":[{"price":153.76,"qty":204.85691998}],"checksum":1429488173,"timestamp":"2024-06-01T22:42:37.407704Z"}]}
{"channel":"book","type":"update","data":[{"symbol":"SOL/EUR","bids":[{"price":153.58,"qty":3.06813137}],"asks":[],"checksum":3591826715,"timestamp":"2024-06-01T22:42:37.462796Z"}]}
{"channel":"book","type":"update","data":[{"symbol":"SOL/EUR","bids":[],"asks":[{"price":153.76,"qty":209.77152258}],"checksum":1443275631,"timestamp":"2024-06-01T22:42:37.524339Z"}]}
{"channel":"book","type":"update","data":[{"symbol":"SOL/EUR","bids":[{"price":153.58,"qty":0.00000000},{"price":153.53,"qty":36.21102942}],"asks":[],"checksum":48031558,"timestamp":"2024-06-01T22:42:37.532501Z"}]}
{"channel":"book","type":"update","data":[{"symbol":"SOL/EUR","bids":[{"price":153.61,"qty":3.29907672}],"asks":[],"checksum":2713872971,"timestamp":"2024-06-01T22:42:37.532655Z"}]}
{"channel":"book","type":"update","data":[{"symbol":"SOL/EUR","bids":[{"price":153.61,"qty":0.00000000},{"price":153.53,"qty":36.21102942}],"asks":[],"checksum":48031558,"timestamp":"2024-06-01T22:42:37.546193Z"}]}
{"channel":"book","type":"update","data":[{"symbol":"SOL/EUR","bids":[],"asks":[{"price":153.81,"qty":15.38967192}],"checksum":1227864090,"timestamp":"2024-06-01T22:42:37.646501Z"}]}
{"channel":"book","type":"update","data":[{"symbol":"SOL/EUR","bids":[],"asks":[{"price":153.80,"qty":200.76714621}],"checksum":2942175206,"timestamp":"2024-06-01T22:42:37.760354Z"}]}
{"channel":"book","type":"update","data":[{"symbol":"SOL/EUR","bids":[],"asks":[{"price":153.77,"qty":172.66486364}],"checksum":1361856648,"timestamp":"2024-06-01T22:42:37.760846Z"}]}
{"channel":"book","type":"update","data":[{"symbol":"SOL/EUR","bids":[],"asks":[{"price":153.76,"qty":209.97152258}],"checksum":2996509788,"timestamp":"2024-06-01T22:42:37.764114Z"}]}
{"channel":"book","type":"update","data":[{"symbol":"SOL/EUR","bids":[],"asks":[{"price":153.76,"qty":287.13797061}],"checksum":861318564,"timestamp":"2024-06-01T22:42:37.764745Z"}]}
{"channel":"book","type":"update","data":[{"symbol":"SOL/EUR","bids":[],"asks":[{"price":153.76,"qty":287.33797061}],"checksum":333241400,"timestamp":"2024-06-01T22:42:37.765293Z"}]}
{"channel":"book","type":"update","data":[{"symbol":"SOL/EUR","bids":[],"asks":[{"price":153.76,"qty":287.53797061}],"checksum":1916948124,"timestamp":"2024-06-01T22:42:37.765554Z"}]}
{"channel":"book","type":"update","data":[{"symbol":"SOL/EUR","bids":[],"asks":[{"price":153.80,"qty":200.56714621}],"checksum":2263367092,"timestamp":"2024-06-01T22:42:37.848256Z"}]}
{"channel":"book","type":"update","data":[{"symbol":"SOL/EUR","bids":[],"asks":[{"price":153.80,"qty":123.40069818}],"checksum":1249613735,"timestamp":"2024-06-01T22:42:37.852294Z"}]}
{"channel":"book","type":"update","data":[{"symbol":"SOL/EUR","bids":[],"asks":[{"price":153.80,"qty":123.20069818}],"checksum":2364802206,"timestamp":"2024-06-01T22:42:37.852462Z"}]}
{"channel":"book","type":"update","data":[{"symbol":"SOL/EUR","bids":[],"asks":[{"price":153.80,"qty":123.00069818}],"checksum":2019456950,"timestamp":"2024-06-01T22:42:37.853657Z"}]}
{"channel":"book","type":"update","data":[{"symbol":"SOL/EUR","bids":[],"asks":[{"price":153.76,"qty":347.48553569}],"checksum":1282033082,"timestamp":"2024-06-01T22:42:37.905376Z"}]}
{"channel":"book","type":"update","data":[{"symbol":"SOL/EUR","bids":[{"price":153.56,"qty":55.92771505}],"asks":[],"checksum":2098633253,"timestamp":"2024-06-01T22:42:38.057926Z"}]}
{"channel":"book","type":"update","data":[{"symbol":"SOL/EUR","bids":[{"price":153.54,"qty":30.28976741}],"asks":[],"checksum":427742490,"timestamp":"2024-06-01T22:42:38.061489Z"}]}
{"channel":"book","type":"update","data":[{"symbol":"SOL/EUR","bids":[{"price":153.53,"qty":2.40102942},{"price":153.54,"qty":64.09976741}],"asks":[],"checksum":1095556290,"timestamp":"2024-06-01T22:42:38.064440Z"}]}
{"channel":"book","type":"update","data":[{"symbol":"SOL/EUR","bids":[],"asks":[{"price":153.79,"qty":30.82851187}],"checksum":3547408200,"timestamp":"2024-06-01T22:42:38.261427Z"}]}
{"channel":"book","type":"update","data":[{"symbol":"SOL/EUR","bids":[{"price":153.54,"qty":34.08463912}],"asks":[],"checksum":197261125,"timestamp":"2024-06-01T22:42:38.393648Z"}]}
{"channel":"book","type":"update","data":[{"symbol":"SOL/EUR","bids":[{"price":153.55,"qty":42.32301298}],"asks":[],"checksum":3112631818,"timestamp":"2024-06-01T22:42:38.397202Z"}]}
{"channel":"book","type":"update","data":[{"symbol":"SOL/EUR","bids":[],"asks":[{"price":153.80,"qty":115.97048917}],"checksum":2878035364,"timestamp":"2024-06-01T22:42:38.483512Z"}]}
{"channel":"book","type":"update","data":[{"symbol":"SOL/EUR","bids":[],"asks":[{"price":153.76,"qty":355.10317869}],"checksum":2771242676,"timestamp":"2024-06-01T22:42:38.486960Z"}]}
{"channel":"book","type":"update","data":[{"symbol":"SOL/EUR","bids":[],"asks":[{"price":153.76,"qty":350.89817869}],"checksum":325702896,"timestamp":"2024-06-01T22:42:38.805859Z"}]}
{"channel":"book","type":"update","data":[{"symbol":"SOL/EUR","bids":[],"asks":[{"price":153.82,"qty":0.00000000},{"price":153.87,"qty":17.31719356}],"checksum":913813731,"timestamp":"2024-06-01T22:42:38.815247Z"}]}
{"channel":"book","type":"update","data":[{"symbol":"SOL/EUR","bids":[],"asks":[{"price":153.76,"qty":345.98357609}],"checksum":3719329037,"timestamp":"2024-06-01T22:42:38.847055Z"}]}
{"channel":"book","type":"update","data":[{"symbol":"SOL/EUR","bids":[{"price":153.57,"qty":4.30006350}],"asks":[],"checksum":3985446347,"timestamp":"2024-06-01T22:42:38.873803Z"}]}
{"channel":"book","type":"update","data":[{"symbol":"SOL/EUR","bids":[],"asks":[{"price":153.76,"qty":350.18857609}],"checksum":485762029,"timestamp":"2024-06-01T22:42:38.904680Z"}]}
{"channel":"book","type":"update","data":[{"symbol":"SOL/EUR","bids":[],"asks":[{"price":153.81,"qty":5.82919989}],"checksum":2461842229,"timestamp":"2024-06-01T22:42:38.934273Z"}]}
{"channel":"book","type":"update","data":[{"symbol":"SOL/EUR","bids":[],"asks":[{"price":153.82,"qty":9.56047203}],"checksum":4220527843,"timestamp":"2024-06-01T22:42:38.934326Z"}]}
{"channel":"book","type":"update","data":[{"symbol":"SOL/EUR","bids":[],"asks":[{"price":153.86,"qty":73.85178431}],"checksum":503477718,"timestamp":"2024-06-01T22:42:38.937787Z"}]}
{"channel":"book","type":"update","data":[{"symbol":"SOL/EUR","bids":[],"asks":[{"price":153.76,"qty":290.24101101}],"checksum":3925603610,"timestamp":"2024-06-01T22:42:38.951772Z"}]}
{"channel":"book","type":"update","data":[{"symbol":"SOL/EUR","bids":[],"asks":[{"price":153.77,"qty":232.61207574}],"checksum":699318035,"timestamp":"2024-06-01T22:42:38.955353Z"}]}
{"channel":"book","type":"update","data":[{"symbol":"SOL/EUR","bids":[],"asks":[{"price":153.76,"qty":295.15561361}],"checksum":454662249,"timestamp":"2024-06-01T22:42:38.964751Z"}]}
{"channel":"book","type":"update","data":[{"symbol":"SOL/EUR","bids":[],"asks":[{"price":153.77,"qty":172.66486364}],"checksum":3679244896,"timestamp":"2024-06-01T22:42:38.976038Z"}]}
{"channel":"book","type":"update","data":[{"symbol":"SOL/EUR","bids":[{"price":153.58,"qty":10.36310407}],"asks":[],"checksum":4166375872,"timestamp":"2024-06-01T22:42:38.987350Z"}]}
{"channel":"book","type":"update","data":[{"symbol":"SOL/EUR","bids":[{"price":153.61,"qty":3.00813137}],"asks":[],"checksum":442324271,"timestamp":"2024-06-01T22:42:39.086709Z"}]}
{"channel":"book","type":"update","data":[{"symbol":"SOL/EUR","bids":[{"price":153.58,"qty":0.00000000},{"price":153.54,"qty":34.08463912}],"asks":[],"checksum":3982847361,"timestamp":"2024-06-01T22:42:39.099287Z"}]}
{"channel":"book","type":"update","data":[{"symbol":"SOL/EUR","bids":[{"price":153.57,"qty":14.66383769}],"asks":[],"checksum":2180792491,"timestamp":"2024-06-01T22:42:39.119937Z"}]}
{"channel":"book","type":"update","data":[{"symbol":"SOL/EUR","bids":[{"price":153.57,"qty":4.30006350}],"asks":[],"checksum":3982847361,"timestamp":"2024-06-01T22:42:39.180987Z"}]}
{"channel":"book","type":"update","data":[{"symbol":"SOL/EUR","bids":[],"asks":[{"price":153.77,"qty":232.61211174}],"checksum":1378887163,"timestamp":"2024-06-01T22:42:39.491453Z"}]}
{"channel":"book","type":"update","data":[{"symbol":"SOL/EUR","bids":[{"price":153.57,"qty":14.66383093}],"asks":[],"checksum":244288825,"timestamp":"2024-06-01T22:42:39.606695Z"}]}
{"channel":"book","type":"update","data":[{"symbol":"SOL/EUR","bids":[],"asks":[{"price":153.77,"qty":172.66486364}],"checksum":3202367571,"timestamp":"2024-06-01T22:42:39.689081Z"}]}
{"channel":"book","type":"update","data":[{"symbol":"SOL/EUR","bids":[],"asks":[{"price":153.77,"qty":14.22000000}],"checksum":2039956065,"timestamp":"2024-06-01T22:42:39.955310Z"}]}
{"channel":"book","type":"update","data":[{"symbol":"SOL/EUR","bids":[],"asks":[{"price":153.77,"qty":163.51256637}],"checksum":1334986538,"timestamp":"2024-06-01T22:42:39.955875Z"}]}
{"channel":"book","type":"update","data":[{"symbol":"SOL/EUR","bids":[{"price":153.59,"qty":0.00000000},{"price":153.53,"qty":2.40102942},{"price":153.60,"qty":8.93317900}],"asks":[],"checksum":3791167820,"timestamp":"2024-06-01T22:42:40.088582Z"}]}
{"channel":"book","type":"update","data":[{"symbol":"SOL/EUR","bids":[],"asks":[{"price":153.76,"qty":355.10317869}],"checksum":23643563,"timestamp":"2024-06-01T22:42:40.397536Z"}]}
{"channel":"book","type":"update","data":[{"symbol":"SOL/EUR","bids":[{"price":153.61,"qty":0.00000000},{"price":153.52,"qty":75.01804176}],"asks":[],"checksum":2340331889,"timestamp":"2024-06-01T22:42:40.456514Z"}]}
{"channel":"book","type":"update","data":[{"symbol":"SOL/EUR","bids":[{"price":153.55,"qty":30.01416470}],"asks":[],"checksum":2063827145,"timestamp":"2024-06-01T22:42:40.477562Z"}]}
{"channel":"book","type":"update","data":[{"symbol":"SOL/EUR","bids":[{"price":153.57,"qty":4.30006350}],"asks":[],"checksum":504476515,"timestamp":"2024-06-01T22:42:40.519934Z"}]}
{"channel":"book","type":"update","data":[{"symbol":"SOL/EUR","bids":[{"price":153.54,"qty":46.39428907}],"asks":[],"checksum":1162961632,"timestamp":"2024-06-01T22:42:40.609222Z"}]}
{"channel":"book","type":"update","data":[{"symbol":"SOL/EUR","bids":[{"price":153.53,"qty":12.76889451}],"asks":[],"checksum":2322441078,"timestamp":"2024-06-01T22:42:40.674061Z"}]}
