{"channel":"book","type":"snapshot","data":[{"symbol":"SOL/BTC","bids":[{"price":0.0024601,"qty":30.01167193},{"price":0.0024600,"qty":4.60000000},{"price":0.0024599,"qty":30.01157727},{"price":0.0024597,"qty":30.00000000},{"price":0.0024596,"qty":60.03566021},{"price":0.0024591,"qty":13.82000000},{"price":0.0024589,"qty":3.50219454},{"price":0.0024588,"qty":77.19180000},{"price":0.0024587,"qty":82.45540904},{"price":0.0024586,"qty":60.05024071}],"asks":[{"price":0.0024604,"qty":0.12971206},{"price":0.0024605,"qty":34.60794948},{"price":0.0024606,"qty":30.00425276},{"price":0.0024610,"qty":10.27274128},{"price":0.0024611,"qty":60.00277544},{"price":0.0024616,"qty":59.98129811},{"price":0.0024619,"qty":24.00604927},{"price":0.0024625,"qty":14.03776000},{"price":0.0024626,"qty":20.30374401},{"price":0.0024627,"qty":16.47000000}],"checksum":2219148659}]}
{"channel":"book","type":"update","data":[{"symbol":"SOL/BTC","bids":[{"price":0.0024587,"qty":0.00000000},{"price":0.0024584,"qty":267.38524822}],"asks":[],"checksum":3952548840,"timestamp":"2024-06-01T22:42:17.846407Z"}]}
{"channel":"book","type":"update","data":[{"symbol":"SOL/BTC","bids":[{"price":0.0024584,"qty":0.00000000},{"price":0.0024582,"qty":14.03776000}],"asks":[],"checksum":2497495572,"timestamp":"2024-06-01T22:42:17.846432Z"}]}
{"channel":"book","type":"update","data":[{"symbol":"SOL/BTC","bids":[{"price":0.0024588,"qty":0.00000000},{"price":0.0024581,"qty":44.34693369}],"asks":[],"checksum":607375066,"timestamp":"2024-06-01T22:42:17.849957Z"}]}
{"channel":"book","type":"update","data":[{"symbol":"SOL/BTC","bids":[{"price":0.0024582,"qty":184.55499722}],"asks":[],"checksum":2910233684,"timestamp":"2024-06-01T22:42:17.851585Z"}]}
{"channel":"book","type":"update","data":[{"symbol":"SOL/BTC","bids":[{"price":0.0024589,"qty":103.56996921}],"asks":[],"checksum":3971546023,"timestamp":"2024-06-01T22:42:17.851597Z"}]}
{"channel":"book","type":"update","data":[{"symbol":"SOL/BTC","bids":[],"asks":[{"price":0.0024605,"qty":4.60000000}],"checksum":3659318222,"timestamp":"2024-06-01T22:42:18.834846Z"}]}
{"channel":"book","type":"update","data":[{"symbol":"SOL/BTC","bids":[{"price":0.0024583,"qty":77.19180000}],"asks":[],"checksum":1201450418,"timestamp":"2024-06-01T22:42:18.838031Z"}]}
{"channel":"book","type":"update","data":[{"symbol":"SOL/BTC","bids":[],"asks":[{"price":0.0024604,"qty":30.13859738}],"checksum":4257935820,"timestamp":"2024-06-01T22:42:18.838065Z"}]}
{"channel":"book","type":"update","data":[{"symbol":"SOL/BTC","bids":[],"asks":[{"price":0.0024604,"qty":30.00888532},{"price":0.0024603,"qty":0.12971206}],"checksum":922531903,"timestamp":"2024-06-01T22:42:18.844188Z"}]}
{"channel":"book","type":"update","data":[{"symbol":"SOL/BTC","bids":[{"price":0.0024589,"qty":100.06777467}],"asks":[],"checksum":2518631308,"timestamp":"2024-06-01T22:42:19.796893Z"}]}
{"channel":"book","type":"update","data":[{"symbol":"SOL/BTC","bids":[{"price":0.0024590,"qty":3.26623163}],"asks":[],"checksum":1625551609,"timestamp":"2024-06-01T22:42:19.798800Z"}]}
{"channel":"book","type":"update","data":[{"symbol":"SOL/BTC","bids":[{"price":0.0024589,"qty":0.00000000},{"price":0.0024582,"qty":14.03776000}],"asks":[],"checksum":2228985744,"timestamp":"2024-06-01T22:42:20.492622Z"}]}
{"channel":"book","type":"update","data":[{"symbol":"SOL/BTC","bids":[{"price":0.0024587,"qty":91.26159185}],"asks":[],"checksum":3578031724,"timestamp":"2024-06-01T22:42:20.494768Z"}]}
{"channel":"book","type":"update","data":[{"symbol":"SOL/BTC","bids":[{"price":0.0024584,"qty":267.38524822}],"asks":[],"checksum":3058843041,"timestamp":"2024-06-01T22:42:20.494957Z"}]}
{"channel":"book","type":"update","data":[{"symbol":"SOL/BTC","bids":[{"price":0.0024588,"qty":77.19180000}],"asks":[],"checksum":1848201242,"timestamp":"2024-06-01T22:42:20.497987Z"}]}
{"channel":"book","type":"update","data":[{"symbol":"SOL/BTC","bids":[{"price":0.0024592,"qty":30.00000000}],"asks":[],"checksum":288821454,"timestamp":"2024-06-01T22:42:21.021705Z"}]}
{"channel":"book","type":"update","data":[{"symbol":"SOL/BTC","bids":[{"price":0.0024597,"qty":0.00000000},{"price":0.0024586,"qty":60.05024071}],"asks":[],"checksum":850191213,"timestamp":"2024-06-01T22:42:21.204921Z"}]}
{"channel":"book","type":"update","data":[{"symbol":"SOL/BTC","bids":[],"asks":[{"price":0.0024604,"qty":0.00000000},{"price":0.0024627,"qty":16.47000000}],"checksum":1604615493,"timestamp":"2024-06-01T22:42:21.840004Z"}]}
{"channel":"book","type":"update","data":[{"symbol":"SOL/BTC","bids":[],"asks":[{"price":0.0024605,"qty":34.60819110}],"checksum":3238523151,"timestamp":"2024-06-01T22:42:21.843685Z"}]}
{"channel":"book","type":"update","data":[{"symbol":"SOL/BTC","bids":[],"asks":[{"price":0.0024603,"qty":0.00000000},{"price":0.0024629,"qty":59.94958430},{"price":0.0024604,"qty":0.12971206}],"checksum":3753698511,"timestamp":"2024-06-01T22:42:21.848686Z"}]}
{"channel":"book","type":"update","data":[{"symbol":"SOL/BTC","bids":[{"price":0.0024590,"qty":0.00000000},{"price":0.0024584,"qty":267.38524822}],"asks":[],"checksum":1222234424,"timestamp":"2024-06-01T22:42:22.572973Z"}]}
{"channel":"book","type":"update","data":[{"symbol":"SOL/BTC","bids":[{"price":0.0024589,"qty":3.52508529}],"asks":[],"checksum":1984854430,"timestamp":"2024-06-01T22:42:22.575302Z"}]}
{"channel":"book","type":"update","data":[{"symbol":"SOL/BTC","bids":[{"price":0.0024587,"qty":0.00000000},{"price":0.0024582,"qty":14.03776000}],"asks":[],"checksum":3104049862,"timestamp":"2024-06-01T22:42:23.066787Z"}]}
{"channel":"book","type":"update","data":[{"symbol":"SOL/BTC","bids":[{"price":0.0024588,"qty":0.00000000},{"price":0.0024581,"qty":44.34693369}],"asks":[],"checksum":166397448,"timestamp":"2024-06-01T22:42:23.070117Z"}]}
{"channel":"book","type":"update","data":[{"symbol":"SOL/BTC","bids":[{"price":0.0024582,"qty":193.36118004}],"asks":[],"checksum":608081327,"timestamp":"2024-06-01T22:42:23.072474Z"}]}
{"channel":"book","type":"update","data":[{"symbol":"SOL/BTC","bids":[{"price":0.0024589,"qty":103.59285996}],"asks":[],"checksum":1223277082,"timestamp":"2024-06-01T22:42:23.072526Z"}]}
{"channel":"book","type":"update","data":[{"symbol":"SOL/BTC","bids":[],"asks":[{"price":0.0024605,"qty":4.60000000}],"checksum":2978193623,"timestamp":"2024-06-01T22:42:24.201276Z"}]}
{"channel":"book","type":"update","data":[{"symbol":"SOL/BTC","bids":[{"price":0.0024599,"qty":0.00000000},{"price":0.0024579,"qty":29.23595059}],"asks":[],"checksum":3652839097,"timestamp":"2024-06-01T22:42:24.201395Z"}]}
{"channel":"book","type":"update","data":[{"symbol":"SOL/BTC","bids":[],"asks":[{"price":0.0024605,"qty":0.00000000},{"price":0.0024629,"qty":59.94958430}],"checksum":1078271872,"timestamp":"2024-06-01T22:42:24.204065Z"}]}
{"channel":"book","type":"update","data":[{"symbol":"SOL/BTC","bids":[{"price":0.0024583,"qty":77.19180000}],"asks":[],"checksum":3238212991,"timestamp":"2024-06-01T22:42:24.204393Z"}]}
{"channel":"book","type":"update","data":[{"symbol":"SOL/BTC","bids":[{"price":0.0024600,"qty":0.00000000},{"price":0.0024579,"qty":29.23595059}],"asks":[],"checksum":1774591551,"timestamp":"2024-06-01T22:42:24.204460Z"}]}
{"channel":"book","type":"update","data":[{"symbol":"SOL/BTC","bids":[{"price":0.0024602,"qty":30.01060879}],"asks":[],"checksum":2934749192,"timestamp":"2024-06-01T22:42:24.205716Z"}]}
{"channel":"book","type":"update","data":[{"symbol":"SOL/BTC","bids":[],"asks":[{"price":0.0024606,"qty":60.01122286}],"checksum":4249565847,"timestamp":"2024-06-01T22:42:24.205749Z"}]}
{"channel":"book","type":"update","data":[{"symbol":"SOL/BTC","bids":[],"asks":[{"price":0.0024604,"qty":0.00000000},{"price":0.0024631,"qty":20.80320000},{"price":0.0024605,"qty":0.12971206}],"checksum":35919189,"timestamp":"2024-06-01T22:42:24.224145Z"}]}
{"channel":"book","type":"update","data":[{"symbol":"SOL/BTC","bids":[{"price":0.0024597,"qty":30.00000000}],"asks":[],"checksum":3160025944,"timestamp":"2024-06-01T22:42:24.258460Z"}]}
{"channel":"book","type":"update","data":[{"symbol":"SOL/BTC","bids":[{"price":0.0024592,"qty":0.00000000},{"price":0.0024581,"qty":20.34091371}],"asks":[],"checksum":741113352,"timestamp":"2024-06-01T22:42:24.500625Z"}]}
{"channel":"book","type":"update","data":[{"symbol":"SOL/BTC","bids":[{"price":0.0024587,"qty":24.00510497}],"asks":[],"checksum":53742923,"timestamp":"2024-06-01T22:42:24.775054Z"}]}
{"channel":"book","type":"update","data":[{"symbol":"SOL/BTC","bids":[{"price":0.0024582,"qty":179.32342004}],"asks":[],"checksum":2517196138,"timestamp":"2024-06-01T22:42:24.934860Z"}]}
{"channel":"book","type":"update","data":[{"symbol":"SOL/BTC","bids":[{"price":0.0024587,"qty":38.04286497}],"asks":[],"checksum":2915172849,"timestamp":"2024-06-01T22:42:24.937665Z"}]}
{"channel":"book","type":"update","data":[{"symbol":"SOL/BTC","bids":[{"price":0.0024583,"qty":0.00000000},{"price":0.0024581,"qty":20.34091371},{"price":0.0024590,"qty":77.19180000}],"asks":[],"checksum":3356861447,"timestamp":"2024-06-01T22:42:24.940759Z"}]}
{"channel":"book","type":"update","data":[{"symbol":"SOL/BTC","bids":[{"price":0.0024589,"qty":100.06777467}],"asks":[],"checksum":3780481595,"timestamp":"2024-06-01T22:42:25.408031Z"}]}
{"channel":"book","type":"update","data":[{"symbol":"SOL/BTC","bids":[{"price":0.0024591,"qty":16.85026872}],"asks":[],"checksum":906684131,"timestamp":"2024-06-01T22:42:25.410525Z"}]}
{"channel":"book","type":"update","data":[{"symbol":"SOL/BTC","bids":[{"price":0.0024582,"qty":0.00000000},{"price":0.0024581,"qty":20.34091371}],"asks":[],"checksum":1295479499,"timestamp":"2024-06-01T22:42:25.706274Z"}]}
{"channel":"book","type":"update","data":[{"symbol":"SOL/BTC","bids":[{"price":0.0024589,"qty":0.00000000},{"price":0.0024579,"qty":29.23595059}],"asks":[],"checksum":4149612281,"timestamp":"2024-06-01T22:42:25.706315Z"}]}
{"channel":"book","type":"update","data":[{"symbol":"SOL/BTC","bids":[{"price":0.0024591,"qty":46.46858085}],"asks":[],"checksum":2835736675,"timestamp":"2024-06-01T22:42:25.708233Z"}]}
{"channel":"book","type":"update","data":[{"symbol":"SOL/BTC","bids":[{"price":0.0024590,"qty":0.00000000},{"price":0.0024577,"qty":205.74196849}],"asks":[],"checksum":651233141,"timestamp":"2024-06-01T22:42:25.709850Z"}]}
{"channel":"book","type":"update","data":[{"symbol":"SOL/BTC","bids":[],"asks":[{"price":0.0024606,"qty":30.00425276}],"checksum":851486855,"timestamp":"2024-06-01T22:42:26.034631Z"}]}
{"channel":"book","type":"update","data":[{"symbol":"SOL/BTC","bids":[{"price":0.0024578,"qty":77.19180000}],"asks":[],"checksum":965197108,"timestamp":"2024-06-01T22:42:26.037672Z"}]}
{"channel":"book","type":"update","data":[{"symbol":"SOL/BTC","bids":[],"asks":[{"price":0.0024609,"qty":30.00367325}],"checksum":738511530,"timestamp":"2024-06-01T22:42:26.037735Z"}]}
{"channel":"book","type":"update","data":[{"symbol":"SOL/BTC","bids":[{"price":0.0024602,"qty":34.61060879}],"asks":[],"checksum":153262783,"timestamp":"2024-06-01T22:42:26.038051Z"}]}
{"channel":"book","type":"update","data":[{"symbol":"SOL/BTC","bids":[],"asks":[{"price":0.0024610,"qty":0.00000000},{"price":0.0024629,"qty":59.94958430}],"checksum":3395150031,"timestamp":"2024-06-01T22:42:26.059169Z"}]}
{"channel":"book","type":"update","data":[{"symbol":"SOL/BTC","bids":[{"price":0.0024602,"qty":4.60000000}],"asks":[],"checksum":701178140,"timestamp":"2024-06-01T22:42:26.061275Z"}]}
{"channel":"book","type":"update","data":[{"symbol":"SOL/BTC","bids":[{"price":0.0024603,"qty":30.00954716}],"asks":[],"checksum":2521452880,"timestamp":"2024-06-01T22:42:26.064399Z"}]}
{"channel":"book","type":"update","data":[{"symbol":"SOL/BTC","bids":[],"asks":[{"price":0.0024619,"qty":0.00000000},{"price":0.0024631,"qty":20.80320000}],"checksum":2739502375,"timestamp":"2024-06-01T22:42:26.123904Z"}]}
{"channel":"book","type":"update","data":[{"symbol":"SOL/BTC","bids":[{"price":0.0024589,"qty":1.17264119}],"asks":[],"checksum":1718023651,"timestamp":"2024-06-01T22:42:26.147656Z"}]}
{"channel":"book","type":"update","data":[{"symbol":"SOL/BTC","bids":[],"asks":[{"price":0.0024621,"qty":24.00342210}],"checksum":2308516611,"timestamp":"2024-06-01T22:42:26.427274Z"}]}
{"channel":"book","type":"update","data":[{"symbol":"SOL/BTC","bids":[],"asks":[{"price":0.0024612,"qty":10.27274128}],"checksum":673177477,"timestamp":"2024-06-01T22:42:26.525355Z"}]}
{"channel":"book","type":"update","data":[{"symbol":"SOL/BTC","bids":[],"asks":[{"price":0.0024606,"qty":0.00000000},{"price":0.0024629,"qty":59.94958430}],"checksum":2640401506,"timestamp":"2024-06-01T22:42:27.073587Z"}]}
{"channel":"book","type":"update","data":[{"symbol":"SOL/BTC","bids":[],"asks":[{"price":0.0024609,"qty":34.60367325}],"checksum":851196306,"timestamp":"2024-06-01T22:42:27.077193Z"}]}
{"channel":"book","type":"update","data":[{"symbol":"SOL/BTC","bids":[],"asks":[{"price":0.0024607,"qty":30.00544276}],"checksum":657361439,"timestamp":"2024-06-01T22:42:27.078030Z"}]}
{"channel":"book","type":"update","data":[{"symbol":"SOL/BTC","bids":[],"asks":[{"price":0.0024605,"qty":0.00000000},{"price":0.0024629,"qty":59.94958430},{"price":0.0024608,"qty":0.12971206}],"checksum":2542146731,"timestamp":"2024-06-01T22:42:27.089763Z"}]}
{"channel":"book","type":"update","data":[{"symbol":"SOL/BTC","bids":[],"asks":[{"price":0.0024608,"qty":0.00000000},{"price":0.0024629,"qty":59.94958430},{"price":0.0024606,"qty":0.12971206}],"checksum":2686540521,"timestamp":"2024-06-01T22:42:27.101262Z"}]}
{"channel":"book","type":"update","data":[{"symbol":"SOL/BTC","bids":[],"asks":[{"price":0.0024606,"qty":0.00000000},{"price":0.0024629,"qty":59.94958430},{"price":0.0024606,"qty":0.11538235}],"checksum":2296770760,"timestamp":"2024-06-01T22:42:28.052678Z"}]}
{"channel":"book","type":"update","data":[{"symbol":"SOL/BTC","bids":[{"price":0.0024591,"qty":43.43831213}],"asks":[],"checksum":2063533319,"timestamp":"2024-06-01T22:42:28.165275Z"}]}
{"channel":"book","type":"update","data":[{"symbol":"SOL/BTC","bids":[{"price":0.0024588,"qty":3.62118778}],"asks":[],"checksum":4069123625,"timestamp":"2024-06-01T22:42:28.166921Z"}]}
{"channel":"book","type":"update","data":[{"symbol":"SOL/BTC","bids":[{"price":0.0024591,"qty":13.82000000}],"asks":[],"checksum":3909920506,"timestamp":"2024-06-01T22:42:28.402712Z"}]}
{"channel":"book","type":"update","data":[{"symbol":"SOL/BTC","bids":[{"price":0.0024588,"qty":68.46034219}],"asks":[],"checksum":1444385064,"timestamp":"2024-06-01T22:42:28.407362Z"}]}
{"channel":"book","type":"update","data":[{"symbol":"SOL/BTC","bids":[{"price":0.0024589,"qty":78.36444119}],"asks":[],"checksum":3816116368,"timestamp":"2024-06-01T22:42:28.410755Z"}]}
{"channel":"book","type":"update","data":[{"symbol":"SOL/BTC","bids":[{"price":0.0024603,"qty":0.00000000},{"price":0.0024581,"qty":20.34091371}],"asks":[],"checksum":2003366350,"timestamp":"2024-06-01T22:42:29.071981Z"}]}
{"channel":"book","type":"update","data":[{"symbol":"SOL/BTC","bids":[],"asks":[{"price":0.0024609,"qty":30.00367325}],"checksum":2902032058,"timestamp":"2024-06-01T22:42:29.074634Z"}]}
{"channel":"book","type":"update","data":[{"symbol":"SOL/BTC","bids":[],"asks":[{"price":0.0024607,"qty":34.60544276}],"checksum":300634571,"timestamp":"2024-06-01T22:42:29.074779Z"}]}
{"channel":"book","type":"update","data":[{"symbol":"SOL/BTC","bids":[{"price":0.0024604,"qty":30.00845919}],"asks":[],"checksum":2708635168,"timestamp":"2024-06-01T22:42:29.076074Z"}]}
{"channel":"book","type":"update","data":[{"symbol":"SOL/BTC","bids":[],"asks":[{"price":0.0024627,"qty":0.00000000},{"price":0.0024629,"qty":59.94958430}],"checksum":3422735373,"timestamp":"2024-06-01T22:42:30.308455Z"}]}
{"channel":"book","type":"update","data":[{"symbol":"SOL/BTC","bids":[{"price":0.0024588,"qty":64.83915441}],"asks":[],"checksum":4070691680,"timestamp":"2024-06-01T22:42:30.927669Z"}]}
{"channel":"book","type":"update","data":[{"symbol":"SOL/BTC","bids":[{"price":0.0024590,"qty":3.58063408}],"asks":[],"checksum":2959883838,"timestamp":"2024-06-01T22:42:30.931069Z"}]}
{"channel":"book","type":"update","data":[{"symbol":"SOL/BTC","bids":[{"price":0.0024588,"qty":0.00000000},{"price":0.0024586,"qty":60.05024071}],"asks":[],"checksum":509782918,"timestamp":"2024-06-01T22:42:31.050934Z"}]}
{"channel":"book","type":"update","data":[{"symbol":"SOL/BTC","bids":[{"price":0.0024589,"qty":1.17264119}],"asks":[],"checksum":1948001986,"timestamp":"2024-06-01T22:42:31.054162Z"}]}
{"channel":"book","type":"update","data":[{"symbol":"SOL/BTC","bids":[{"price":0.0024590,"qty":130.05937114}],"asks":[],"checksum":898508405,"timestamp":"2024-06-01T22:42:31.055537Z"}]}
{"channel":"book","type":"update","data":[{"symbol":"SOL/BTC","bids":[{"price":0.0024591,"qty":91.01180000}],"asks":[],"checksum":2759317957,"timestamp":"2024-06-01T22:42:31.666613Z"}]}
{"channel":"book","type":"update","data":[{"symbol":"SOL/BTC","bids":[{"price":0.0024590,"qty":126.47873706}],"asks":[],"checksum":650652925,"timestamp":"2024-06-01T22:42:33.676394Z"}]}
{"channel":"book","type":"update","data":[{"symbol":"SOL/BTC","bids":[{"price":0.0024592,"qty":3.18738615}],"asks":[],"checksum":468552610,"timestamp":"2024-06-01T22:42:33.678718Z"}]}
{"channel":"book","type":"update","data":[{"symbol":"SOL/BTC","bids":[{"price":0.0024590,"qty":0.00000000},{"price":0.0024586,"qty":60.05024071}],"asks":[],"checksum":484067157,"timestamp":"2024-06-01T22:42:33.681679Z"}]}
{"channel":"book","type":"update","data":[{"symbol":"SOL/BTC","bids":[{"price":0.0024592,"qty":41.60957657}],"asks":[],"checksum":1767269664,"timestamp":"2024-06-01T22:42:33.684362Z"}]}
{"channel":"book","type":"update","data":[{"symbol":"SOL/BTC","bids":[{"price":0.0024588,"qty":64.83915441}],"asks":[],"checksum":3344494744,"timestamp":"2024-06-01T22:42:33.684451Z"}]}
{"channel":"book","type":"update","data":[{"symbol":"SOL/BTC","bids":[{"price":0.0024591,"qty":13.82000000}],"asks":[],"checksum":1873106779,"timestamp":"2024-06-01T22:42:33.685350Z"}]}
{"channel":"book","type":"update","data":[{"symbol":"SOL/BTC","bids":[{"price":0.0024589,"qty":78.36444119}],"asks":[],"checksum":4239432068,"timestamp":"2024-06-01T22:42:34.176903Z"}]}
{"channel":"book","type":"update","data":[{"symbol":"SOL/BTC","bids":[{"price":0.0024604,"qty":0.00000000},{"price":0.0024586,"qty":60.05024071}],"asks":[],"checksum":2126523489,"timestamp":"2024-06-01T22:42:34.343654Z"}]}
{"channel":"book","type":"update","data":[{"symbol":"SOL/BTC","bids":[{"price":0.0024603,"qty":30.00903511}],"asks":[],"checksum":487079682,"timestamp":"2024-06-01T22:42:34.347710Z"}]}
{"channel":"book","type":"update","data":[{"symbol":"SOL/BTC","bids":[{"price":0.0024589,"qty":77.19180000}],"asks":[],"checksum":3723453646,"timestamp":"2024-06-01T22:42:34.652626Z"}]}
{"channel":"book","type":"update","data":[{"symbol":"SOL/BTC","bids":[{"price":0.0024587,"qty":24.00510497}],"asks":[],"checksum":354997730,"timestamp":"2024-06-01T22:42:35.728313Z"}]}
{"channel":"book","type":"update","data":[{"symbol":"SOL/BTC","bids":[],"asks":[{"price":0.0024625,"qty":0.00000000},{"price":0.0024635,"qty":16.47000000}],"checksum":3476547994,"timestamp":"2024-06-01T22:42:35.728445Z"}]}
{"channel":"book","type":"update","data":[{"symbol":"SOL/BTC","bids":[],"asks":[{"price":0.0024634,"qty":14.03776000}],"checksum":3143409071,"timestamp":"2024-06-01T22:42:35.731446Z"}]}
