{"channel":"book","type":"snapshot","data":[{"symbol":"SOL/USDT","bids":[{"price":166.71,"qty":30.01709078},{"price":166.69,"qty":13.29728921},{"price":166.68,"qty":68.91976128},{"price":166.67,"qty":54.50088623},{"price":166.66,"qty":49.68249406},{"price":166.65,"qty":16.42852234},{"price":166.64,"qty":80.47960261},{"price":166.63,"qty":24.00601998},{"price":166.61,"qty":0.85605006},{"price":166.60,"qty":26.33476417}],"asks":[{"price":166.73,"qty":7.00000000},{"price":166.74,"qty":16.60816745},{"price":166.75,"qty":3.50000000},{"price":166.76,"qty":30.00960440},{"price":166.79,"qty":1.72704781},{"price":166.80,"qty":45.00279555},{"price":166.83,"qty":5.59500000},{"price":166.84,"qty":5.10892122},{"price":166.85,"qty":76.59570643},{"price":166.86,"qty":72.34668532}],"checksum":3904805949}]}
{"channel":"book","type":"update","data":[{"symbol":"SOL/USDT","bids":[{"price":166.60,"qty":24.23027201}],"asks":[],"checksum":366671584,"timestamp":"2024-06-01T22:42:22.776563Z"}]}
{"channel":"book","type":"update","data":[{"symbol":"SOL/USDT","bids":[{"price":166.60,"qty":26.33487156}],"asks":[],"checksum":3354549232,"timestamp":"2024-06-01T22:42:22.780240Z"}]}
{"channel":"book","type":"update","data":[{"symbol":"SOL/USDT","bids":[{"price":166.69,"qty":12.00594649}],"asks":[],"checksum":189248609,"timestamp":"2024-06-01T22:42:23.770033Z"}]}
{"channel":"book","type":"update","data":[{"symbol":"SOL/USDT","bids":[{"price":166.65,"qty":13.42710900}],"asks":[],"checksum":1830101795,"timestamp":"2024-06-01T22:42:23.770190Z"}]}
{"channel":"book","type":"update","data":[{"symbol":"SOL/USDT","bids":[{"price":166.65,"qty":17.67301080}],"asks":[],"checksum":973177920,"timestamp":"2024-06-01T22:42:23.775596Z"}]}
{"channel":"book","type":"update","data":[{"symbol":"SOL/USDT","bids":[{"price":166.69,"qty":13.41441754}],"asks":[],"checksum":981674174,"timestamp":"2024-06-01T22:42:23.775750Z"}]}
{"channel":"book","type":"update","data":[{"symbol":"SOL/USDT","bids":[],"asks":[{"price":166.75,"qty":0.00000000},{"price":166.87,"qty":6.26037837}],"checksum":1805682363,"timestamp":"2024-06-01T22:42:24.178822Z"}]}
{"channel":"book","type":"update","data":[{"symbol":"SOL/USDT","bids":[],"asks":[{"price":166.74,"qty":0.00000000},{"price":166.88,"qty":59.97689353},{"price":166.75,"qty":16.60816745}],"checksum":136124128,"timestamp":"2024-06-01T22:42:24.202918Z"}]}
{"channel":"book","type":"update","data":[{"symbol":"SOL/USDT","bids":[],"asks":[{"price":166.86,"qty":0.00000000},{"price":166.88,"qty":132.32357885}],"checksum":3068473828,"timestamp":"2024-06-01T22:42:24.212119Z"}]}
{"channel":"book","type":"update","data":[{"symbol":"SOL/USDT","bids":[],"asks":[{"price":166.76,"qty":0.00000000},{"price":166.89,"qty":13.42710900}],"checksum":1007185425,"timestamp":"2024-06-01T22:42:24.241950Z"}]}
{"channel":"book","type":"update","data":[{"symbol":"SOL/USDT","bids":[],"asks":[{"price":166.78,"qty":30.00621396}],"checksum":2644335703,"timestamp":"2024-06-01T22:42:24.244954Z"}]}
{"channel":"book","type":"update","data":[{"symbol":"SOL/USDT","bids":[],"asks":[{"price":166.75,"qty":0.00000000},{"price":166.89,"qty":13.42710900},{"price":166.78,"qty":46.61438141}],"checksum":2608651245,"timestamp":"2024-06-01T22:42:24.265650Z"}]}
{"channel":"book","type":"update","data":[{"symbol":"SOL/USDT","bids":[],"asks":[{"price":166.77,"qty":3.50000000}],"checksum":1686968330,"timestamp":"2024-06-01T22:42:24.268583Z"}]}
{"channel":"book","type":"update","data":[{"symbol":"SOL/USDT","bids":[],"asks":[{"price":166.85,"qty":16.60816745}],"checksum":3137385842,"timestamp":"2024-06-01T22:42:24.287790Z"}]}
{"channel":"book","type":"update","data":[{"symbol":"SOL/USDT","bids":[],"asks":[{"price":166.78,"qty":30.00621396},{"price":166.76,"qty":16.60816745}],"checksum":3521141428,"timestamp":"2024-06-01T22:42:24.291092Z"}]}
{"channel":"book","type":"update","data":[{"symbol":"SOL/USDT","bids":[],"asks":[{"price":166.84,"qty":0.96257556}],"checksum":3574854168,"timestamp":"2024-06-01T22:42:24.588318Z"}]}
{"channel":"book","type":"update","data":[{"symbol":"SOL/USDT","bids":[],"asks":[{"price":166.87,"qty":10.94844254}],"checksum":4201644404,"timestamp":"2024-06-01T22:42:24.589086Z"}]}
{"channel":"book","type":"update","data":[{"symbol":"SOL/USDT","bids":[],"asks":[{"price":166.76,"qty":0.00000000},{"price":166.88,"qty":132.32357885},{"price":166.77,"qty":20.10816745}],"checksum":3551134021,"timestamp":"2024-06-01T22:42:26.038937Z"}]}
{"channel":"book","type":"update","data":[{"symbol":"SOL/USDT","bids":[],"asks":[{"price":166.83,"qty":0.00000000},{"price":166.89,"qty":13.42710900}],"checksum":3401529817,"timestamp":"2024-06-01T22:42:26.054348Z"}]}
{"channel":"book","type":"update","data":[{"symbol":"SOL/USDT","bids":[],"asks":[{"price":166.79,"qty":0.00000000},{"price":166.90,"qty":5.72700000}],"checksum":2885312047,"timestamp":"2024-06-01T22:42:26.060099Z"}]}
{"channel":"book","type":"update","data":[{"symbol":"SOL/USDT","bids":[],"asks":[{"price":166.80,"qty":46.72984336}],"checksum":3185036038,"timestamp":"2024-06-01T22:42:26.065959Z"}]}
{"channel":"book","type":"update","data":[{"symbol":"SOL/USDT","bids":[{"price":166.68,"qty":23.88547393}],"asks":[],"checksum":385354532,"timestamp":"2024-06-01T22:42:26.068958Z"}]}
{"channel":"book","type":"update","data":[{"symbol":"SOL/USDT","bids":[],"asks":[{"price":166.80,"qty":1.72704781}],"checksum":1511595718,"timestamp":"2024-06-01T22:42:26.068982Z"}]}
{"channel":"book","type":"update","data":[{"symbol":"SOL/USDT","bids":[{"price":166.70,"qty":45.02888322}],"asks":[],"checksum":3174523341,"timestamp":"2024-06-01T22:42:26.072280Z"}]}
{"channel":"book","type":"update","data":[{"symbol":"SOL/USDT","bids":[],"asks":[{"price":166.83,"qty":44.99639484}],"checksum":3256507041,"timestamp":"2024-06-01T22:42:26.072329Z"}]}
{"channel":"book","type":"update","data":[{"symbol":"SOL/USDT","bids":[],"asks":[{"price":166.77,"qty":16.60816745}],"checksum":468510622,"timestamp":"2024-06-01T22:42:26.077881Z"}]}
{"channel":"book","type":"update","data":[{"symbol":"SOL/USDT","bids":[],"asks":[{"price":166.78,"qty":33.50621396}],"checksum":3666007617,"timestamp":"2024-06-01T22:42:26.077930Z"}]}
{"channel":"book","type":"update","data":[{"symbol":"SOL/USDT","bids":[],"asks":[{"price":166.84,"qty":6.55257556}],"checksum":4258856690,"timestamp":"2024-06-01T22:42:26.152986Z"}]}
{"channel":"book","type":"update","data":[{"symbol":"SOL/USDT","bids":[],"asks":[{"price":166.85,"qty":0.00000000},{"price":166.90,"qty":5.72700000}],"checksum":3677728404,"timestamp":"2024-06-01T22:42:26.164018Z"}]}
{"channel":"book","type":"update","data":[{"symbol":"SOL/USDT","bids":[{"price":166.67,"qty":5.59000000}],"asks":[],"checksum":3880719126,"timestamp":"2024-06-01T22:42:26.247524Z"}]}
{"channel":"book","type":"update","data":[{"symbol":"SOL/USDT","bids":[{"price":166.67,"qty":60.65170952}],"asks":[],"checksum":3160640769,"timestamp":"2024-06-01T22:42:26.253439Z"}]}
{"channel":"book","type":"update","data":[{"symbol":"SOL/USDT","bids":[],"asks":[{"price":166.88,"qty":156.32699320}],"checksum":1480623591,"timestamp":"2024-06-01T22:42:26.477138Z"}]}
{"channel":"book","type":"update","data":[{"symbol":"SOL/USDT","bids":[{"price":166.65,"qty":13.42710900}],"asks":[],"checksum":3184700699,"timestamp":"2024-06-01T22:42:27.002121Z"}]}
{"channel":"book","type":"update","data":[{"symbol":"SOL/USDT","bids":[{"price":166.69,"qty":12.00594649}],"asks":[],"checksum":1419432764,"timestamp":"2024-06-01T22:42:27.002213Z"}]}
{"channel":"book","type":"update","data":[{"symbol":"SOL/USDT","bids":[{"price":166.68,"qty":28.63547762}],"asks":[],"checksum":2107289385,"timestamp":"2024-06-01T22:42:27.007119Z"}]}
{"channel":"book","type":"update","data":[{"symbol":"SOL/USDT","bids":[],"asks":[{"price":166.87,"qty":6.26037837}],"checksum":4285796439,"timestamp":"2024-06-01T22:42:27.386147Z"}]}
{"channel":"book","type":"update","data":[{"symbol":"SOL/USDT","bids":[],"asks":[{"price":166.87,"qty":10.83104007}],"checksum":3758709881,"timestamp":"2024-06-01T22:42:27.387416Z"}]}
{"channel":"book","type":"update","data":[{"symbol":"SOL/USDT","bids":[{"price":166.72,"qty":2.10303849}],"asks":[],"checksum":3619152054,"timestamp":"2024-06-01T22:42:27.431986Z"}]}
{"channel":"book","type":"update","data":[{"symbol":"SOL/USDT","bids":[{"price":166.72,"qty":0.00000000},{"price":166.61,"qty":0.85605006}],"asks":[],"checksum":3758709881,"timestamp":"2024-06-01T22:42:27.506295Z"}]}
{"channel":"book","type":"update","data":[{"symbol":"SOL/USDT","bids":[],"asks":[{"price":166.78,"qty":30.00621396}],"checksum":560426406,"timestamp":"2024-06-01T22:42:27.618159Z"}]}
{"channel":"book","type":"update","data":[{"symbol":"SOL/USDT","bids":[],"asks":[{"price":166.77,"qty":20.10816745}],"checksum":4170305689,"timestamp":"2024-06-01T22:42:27.618576Z"}]}
{"channel":"book","type":"update","data":[{"symbol":"SOL/USDT","bids":[],"asks":[{"price":166.90,"qty":78.07368532}],"checksum":426709896,"timestamp":"2024-06-01T22:42:27.712827Z"}]}
{"channel":"book","type":"update","data":[{"symbol":"SOL/USDT","bids":[],"asks":[{"price":166.88,"qty":83.98030788}],"checksum":1483127731,"timestamp":"2024-06-01T22:42:27.713064Z"}]}
{"channel":"book","type":"update","data":[{"symbol":"SOL/USDT","bids":[],"asks":[{"price":166.77,"qty":3.50000000},{"price":166.77,"qty":18.27340989}],"checksum":355727013,"timestamp":"2024-06-01T22:42:28.052648Z"}]}
{"channel":"book","type":"update","data":[{"symbol":"SOL/USDT","bids":[],"asks":[{"price":166.73,"qty":10.60000000}],"checksum":267887999,"timestamp":"2024-06-01T22:42:28.124888Z"}]}
{"channel":"book","type":"update","data":[{"symbol":"SOL/USDT","bids":[],"asks":[{"price":166.72,"qty":4.34680807}],"checksum":3898415147,"timestamp":"2024-06-01T22:42:28.276232Z"}]}
{"channel":"book","type":"update","data":[{"symbol":"SOL/USDT","bids":[{"price":166.69,"qty":0.00000000},{"price":166.60,"qty":27.43545880}],"asks":[],"checksum":2308659872,"timestamp":"2024-06-01T22:42:29.663425Z"}]}
{"channel":"book","type":"update","data":[{"symbol":"SOL/USDT","bids":[{"price":166.67,"qty":5.59000000}],"asks":[],"checksum":1748148708,"timestamp":"2024-06-01T22:42:29.663578Z"}]}
{"channel":"book","type":"update","data":[{"symbol":"SOL/USDT","bids":[{"price":166.60,"qty":24.23027201}],"asks":[],"checksum":1344079734,"timestamp":"2024-06-01T22:42:29.667125Z"}]}
{"channel":"book","type":"update","data":[{"symbol":"SOL/USDT","bids":[{"price":166.67,"qty":79.09977034}],"asks":[],"checksum":3928876632,"timestamp":"2024-06-01T22:42:29.668272Z"}]}
{"channel":"book","type":"update","data":[{"symbol":"SOL/USDT","bids":[{"price":166.60,"qty":27.43536873}],"asks":[],"checksum":1812364865,"timestamp":"2024-06-01T22:42:29.671316Z"}]}
{"channel":"book","type":"update","data":[{"symbol":"SOL/USDT","bids":[{"price":166.68,"qty":23.88547393}],"asks":[],"checksum":1591843972,"timestamp":"2024-06-01T22:42:30.096896Z"}]}
{"channel":"book","type":"update","data":[{"symbol":"SOL/USDT","bids":[{"price":166.68,"qty":28.35731453}],"asks":[],"checksum":3441548915,"timestamp":"2024-06-01T22:42:30.099263Z"}]}
{"channel":"book","type":"update","data":[{"symbol":"SOL/USDT","bids":[],"asks":[{"price":166.87,"qty":6.26037837}],"checksum":1818152242,"timestamp":"2024-06-01T22:42:30.152383Z"}]}
{"channel":"book","type":"update","data":[{"symbol":"SOL/USDT","bids":[],"asks":[{"price":166.87,"qty":10.94816137}],"checksum":1849678658,"timestamp":"2024-06-01T22:42:30.153400Z"}]}
{"channel":"book","type":"update","data":[{"symbol":"SOL/USDT","bids":[{"price":166.60,"qty":24.23027201}],"asks":[],"checksum":3893642075,"timestamp":"2024-06-01T22:42:33.086246Z"}]}
{"channel":"book","type":"update","data":[{"symbol":"SOL/USDT","bids":[{"price":166.60,"qty":27.43543361}],"asks":[],"checksum":276908268,"timestamp":"2024-06-01T22:42:33.103471Z"}]}
{"channel":"book","type":"update","data":[{"symbol":"SOL/USDT","bids":[{"price":166.68,"qty":23.88547393}],"asks":[],"checksum":2202077723,"timestamp":"2024-06-01T22:42:33.232686Z"}]}
{"channel":"book","type":"update","data":[{"symbol":"SOL/USDT","bids":[{"price":166.68,"qty":28.45613563}],"asks":[],"checksum":2448273662,"timestamp":"2024-06-01T22:42:33.235369Z"}]}
{"channel":"book","type":"update","data":[{"symbol":"SOL/USDT","bids":[{"price":166.67,"qty":73.50977034}],"asks":[],"checksum":2544330960,"timestamp":"2024-06-01T22:42:33.382439Z"}]}
{"channel":"book","type":"update","data":[{"symbol":"SOL/USDT","bids":[{"price":166.70,"qty":50.61188322}],"asks":[],"checksum":416675982,"timestamp":"2024-06-01T22:42:33.384853Z"}]}
{"channel":"book","type":"update","data":[{"symbol":"SOL/USDT","bids":[],"asks":[{"price":166.87,"qty":6.26037837}],"checksum":448065278,"timestamp":"2024-06-01T22:42:35.706947Z"}]}
{"channel":"book","type":"update","data":[{"symbol":"SOL/USDT","bids":[],"asks":[{"price":166.87,"qty":10.24543356}],"checksum":1945782134,"timestamp":"2024-06-01T22:42:35.707599Z"}]}
{"channel":"book","type":"update","data":[{"symbol":"SOL/USDT","bids":[{"price":166.66,"qty":14.96708755}],"asks":[],"checksum":1590556294,"timestamp":"2024-06-01T22:42:35.726285Z"}]}
{"channel":"book","type":"update","data":[{"symbol":"SOL/USDT","bids":[{"price":166.70,"qty":45.02888322}],"asks":[],"checksum":3518981848,"timestamp":"2024-06-01T22:42:35.727340Z"}]}
{"channel":"book","type":"update","data":[{"symbol":"SOL/USDT","bids":[],"asks":[{"price":166.89,"qty":0.00000000},{"price":166.90,"qty":78.07368532}],"checksum":42101617,"timestamp":"2024-06-01T22:42:35.727902Z"}]}
{"channel":"book","type":"update","data":[{"symbol":"SOL/USDT","bids":[{"price":166.64,"qty":60.05960161}],"asks":[],"checksum":1381439972,"timestamp":"2024-06-01T22:42:35.728009Z"}]}
{"channel":"book","type":"update","data":[{"symbol":"SOL/USDT","bids":[{"price":166.65,"qty":0.00000000},{"price":166.59,"qty":425.17368641}],"asks":[],"checksum":2397122881,"timestamp":"2024-06-01T22:42:35.728580Z"}]}
{"channel":"book","type":"update","data":[{"symbol":"SOL/USDT","bids":[{"price":166.60,"qty":40.86254261}],"asks":[],"checksum":2481873643,"timestamp":"2024-06-01T22:42:35.731187Z"}]}
{"channel":"book","type":"update","data":[{"symbol":"SOL/USDT","bids":[{"price":166.60,"qty":27.43543361}],"asks":[],"checksum":2397122881,"timestamp":"2024-06-01T22:42:35.732041Z"}]}
{"channel":"book","type":"update","data":[{"symbol":"SOL/USDT","bids":[],"asks":[{"price":166.90,"qty":115.28159424}],"checksum":615323013,"timestamp":"2024-06-01T22:42:35.733430Z"}]}
{"channel":"book","type":"update","data":[{"symbol":"SOL/USDT","bids":[],"asks":[{"price":166.90,"qty":109.55459424},{"price":166.86,"qty":5.72700000}],"checksum":832065789,"timestamp":"2024-06-01T22:42:35.736496Z"}]}
{"channel":"book","type":"update","data":[{"symbol":"SOL/USDT","bids":[],"asks":[{"price":166.83,"qty":0.00000000},{"price":166.90,"qty":109.55459424}],"checksum":2406431169,"timestamp":"2024-06-01T22:42:35.736587Z"}]}
{"channel":"book","type":"update","data":[{"symbol":"SOL/USDT","bids":[{"price":166.71,"qty":0.00000000},{"price":166.56,"qty":60.08849717}],"asks":[],"checksum":3626934611,"timestamp":"2024-06-01T22:42:35.738359Z"}]}
{"channel":"book","type":"update","data":[{"symbol":"SOL/USDT","bids":[],"asks":[{"price":166.78,"qty":0.00000000},{"price":166.92,"qty":62.99600000}],"checksum":468417204,"timestamp":"2024-06-01T22:42:35.738481Z"}]}
{"channel":"book","type":"update","data":[{"symbol":"SOL/USDT","bids":[{"price":166.70,"qty":0.00000000},{"price":166.53,"qty":243.73238863}],"asks":[],"checksum":718801733,"timestamp":"2024-06-01T22:42:35.739643Z"}]}
{"channel":"book","type":"update","data":[{"symbol":"SOL/USDT","bids":[{"price":166.67,"qty":103.53273248}],"asks":[],"checksum":3403398221,"timestamp":"2024-06-01T22:42:35.747102Z"}]}
{"channel":"book","type":"update","data":[{"symbol":"SOL/USDT","bids":[],"asks":[{"price":166.77,"qty":63.28386271}],"checksum":2568956354,"timestamp":"2024-06-01T22:42:35.747145Z"}]}
{"channel":"book","type":"update","data":[{"symbol":"SOL/USDT","bids":[],"asks":[{"price":166.72,"qty":34.36393198}],"checksum":2573014342,"timestamp":"2024-06-01T22:42:35.747247Z"}]}
{"channel":"book","type":"update","data":[{"symbol":"SOL/USDT","bids":[{"price":166.64,"qty":0.00000000},{"price":166.46,"qty":60.12458193}],"asks":[],"checksum":247932338,"timestamp":"2024-06-01T22:42:35.747272Z"}]}
{"channel":"book","type":"update","data":[{"symbol":"SOL/USDT","bids":[],"asks":[{"price":166.83,"qty":59.99386917}],"checksum":147158599,"timestamp":"2024-06-01T22:42:35.747282Z"}]}
{"channel":"book","type":"update","data":[{"symbol":"SOL/USDT","bids":[{"price":166.47,"qty":12.82000000}],"asks":[],"checksum":3319981086,"timestamp":"2024-06-01T22:42:35.749636Z"}]}
{"channel":"book","type":"update","data":[{"symbol":"SOL/USDT","bids":[{"price":166.67,"qty":73.50977034}],"asks":[],"checksum":4055464031,"timestamp":"2024-06-01T22:42:35.752080Z"}]}
{"channel":"book","type":"update","data":[{"symbol":"SOL/USDT","bids":[],"asks":[{"price":166.83,"qty":0.00000000},{"price":166.92,"qty":62.99600000}],"checksum":1163891226,"timestamp":"2024-06-01T22:42:35.753465Z"}]}
{"channel":"book","type":"update","data":[{"symbol":"SOL/USDT","bids":[],"asks":[{"price":166.72,"qty":4.34680807}],"checksum":123934234,"timestamp":"2024-06-01T22:42:35.753485Z"}]}
{"channel":"book","type":"update","data":[{"symbol":"SOL/USDT","bids":[],"asks":[{"price":166.77,"qty":18.27340989}],"checksum":1885710824,"timestamp":"2024-06-01T22:42:35.753683Z"}]}
{"channel":"book","type":"update","data":[{"symbol":"SOL/USDT","bids":[{"price":166.66,"qty":0.00000000},{"price":166.46,"qty":60.12458193}],"asks":[],"checksum":1716494987,"timestamp":"2024-06-01T22:42:35.754012Z"}]}
{"channel":"book","type":"update","data":[{"symbol":"SOL/USDT","bids":[{"price":166.60,"qty":72.48975445}],"asks":[],"checksum":1105549109,"timestamp":"2024-06-01T22:42:35.757979Z"}]}
{"channel":"book","type":"update","data":[{"symbol":"SOL/USDT","bids":[],"asks":[{"price":166.78,"qty":72.34668532}],"checksum":3306954773,"timestamp":"2024-06-01T22:42:35.757995Z"}]}
{"channel":"book","type":"update","data":[{"symbol":"SOL/USDT","bids":[],"asks":[{"price":166.77,"qty":3.50000000},{"price":166.83,"qty":14.77343491}],"checksum":631142822,"timestamp":"2024-06-01T22:42:35.766008Z"}]}
{"channel":"book","type":"update","data":[{"symbol":"SOL/USDT","bids":[{"price":166.46,"qty":73.55169093}],"asks":[],"checksum":472905752,"timestamp":"2024-06-01T22:42:35.769159Z"}]}
{"channel":"book","type":"update","data":[{"symbol":"SOL/USDT","bids":[],"asks":[{"price":166.77,"qty":0.00000000},{"price":166.90,"qty":109.55459424}],"checksum":2313761787,"timestamp":"2024-06-01T22:42:35.775988Z"}]}
{"channel":"book","type":"update","data":[{"symbol":"SOL/USDT","bids":[],"asks":[{"price":166.72,"qty":7.84680807}],"checksum":2848840155,"timestamp":"2024-06-01T22:42:35.776149Z"}]}
{"channel":"book","type":"update","data":[{"symbol":"SOL/USDT","bids":[{"price":166.60,"qty":27.43543361}],"asks":[],"checksum":2389126245,"timestamp":"2024-06-01T22:42:35.776278Z"}]}
{"channel":"book","type":"update","data":[{"symbol":"SOL/USDT","bids":[],"asks":[{"price":166.84,"qty":0.96257556}],"checksum":3973591682,"timestamp":"2024-06-01T22:42:35.780693Z"}]}
{"channel":"book","type":"update","data":[{"symbol":"SOL/USDT","bids":[],"asks":[{"price":166.78,"qty":0.00000000},{"price":166.92,"qty":62.99600000}],"checksum":3207150016,"timestamp":"2024-06-01T22:42:35.783366Z"}]}
{"channel":"book","type":"update","data":[{"symbol":"SOL/USDT","bids":[],"asks":[{"price":166.77,"qty":5.88800000}],"checksum":1259564610,"timestamp":"2024-06-01T22:42:35.783403Z"}]}
{"channel":"book","type":"update","data":[{"symbol":"SOL/USDT","bids":[{"price":166.60,"qty":21.17516160}],"asks":[],"checksum":2867815014,"timestamp":"2024-06-01T22:42:35.790429Z"}]}
{"channel":"book","type":"update","data":[{"symbol":"SOL/USDT","bids":[],"asks":[{"price":166.88,"qty":96.71030788}],"checksum":2097971304,"timestamp":"2024-06-01T22:42:35.797935Z"}]}
{"channel":"book","type":"update","data":[{"symbol":"SOL/USDT","bids":[{"price":166.60,"qty":3.20516160}],"asks":[],"checksum":2291563272,"timestamp":"2024-06-01T22:42:35.798795Z"}]}
{"channel":"book","type":"update","data":[{"symbol":"SOL/USDT","bids":[],"asks":[{"price":166.83,"qty":0.00000000},{"price":166.92,"qty":62.99600000},{"price":166.77,"qty":20.66143491}],"checksum":4067687326,"timestamp":"2024-06-01T22:42:35.801218Z"}]}
{"channel":"book","type":"update","data":[{"symbol":"SOL/USDT","bids":[{"price":166.60,"qty":0.00000000},{"price":166.45,"qty":82.03169990},{"price":166.61,"qty":4.06110587}],"asks":[],"checksum":1799427926,"timestamp":"2024-06-01T22:42:35.806597Z"}]}
{"channel":"book","type":"update","data":[{"symbol":"SOL/USDT","bids":[],"asks":[{"price":166.72,"qty":4.34680807}],"checksum":1264975222,"timestamp":"2024-06-01T22:42:35.821369Z"}]}
{"channel":"book","type":"update","data":[{"symbol":"SOL/USDT","bids":[],"asks":[{"price":166.71,"qty":3.50000000}],"checksum":933250626,"timestamp":"2024-06-01T22:42:35.821927Z"}]}
{"channel":"book","type":"update","data":[{"symbol":"SOL/USDT","bids":[],"asks":[{"price":166.77,"qty":5.88800000},{"price":166.71,"qty":18.27343491}],"checksum":2928145097,"timestamp":"2024-06-01T22:42:35.825795Z"}]}
{"channel":"book","type":"update","data":[{"symbol":"SOL/USDT","bids":[{"price":166.61,"qty":0.85605006},{"price":166.47,"qty":16.02775124}],"asks":[],"checksum":1924654131,"timestamp":"2024-06-01T22:42:35.827376Z"}]}
{"channel":"book","type":"update","data":[{"symbol":"SOL/USDT","bids":[],"asks":[{"price":166.88,"qty":72.70689353}],"checksum":3786962631,"timestamp":"2024-06-01T22:42:35.829743Z"}]}
{"channel":"book","type":"update","data":[{"symbol":"SOL/USDT","bids":[{"price":166.56,"qty":0.00000000},{"price":166.44,"qty":0.05001010}],"asks":[],"checksum":1255033730,"timestamp":"2024-06-01T22:42:35.834623Z"}]}
{"channel":"book","type":"update","data":[{"symbol":"SOL/USDT","bids":[{"price":166.51,"qty":60.10483401}],"asks":[],"checksum":1867914801,"timestamp":"2024-06-01T22:42:35.838648Z"}]}
{"channel":"book","type":"update","data":[{"symbol":"SOL/USDT","bids":[],"asks":[{"price":166.82,"qty":17.12000000}],"checksum":2788600820,"timestamp":"2024-06-01T22:42:35.842919Z"}]}
{"channel":"book","type":"update","data":[{"symbol":"SOL/USDT","bids":[{"price":166.45,"qty":102.45170090}],"asks":[],"checksum":3762779438,"timestamp":"2024-06-01T22:42:35.846679Z"}]}
{"channel":"book","type":"update","data":[{"symbol":"SOL/USDT","bids":[],"asks":[{"price":166.71,"qty":3.50000000},{"price":166.70,"qty":14.77343490}],"checksum":1401168566,"timestamp":"2024-06-01T22:42:35.859199Z"}]}
{"channel":"book","type":"update","data":[{"symbol":"SOL/USDT","bids":[],"asks":[{"price":166.71,"qty":0.00000000},{"price":166.88,"qty":72.70689353}],"checksum":3902179475,"timestamp":"2024-06-01T22:42:35.861978Z"}]}
{"channel":"book","type":"update","data":[{"symbol":"SOL/USDT","bids":[],"asks":[{"price":166.69,"qty":3.50000000}],"checksum":2280122003,"timestamp":"2024-06-01T22:42:35.862022Z"}]}
{"channel":"book","type":"update","data":[{"symbol":"SOL/USDT","bids":[{"price":166.62,"qty":30.03249841}],"asks":[],"checksum":2724399749,"timestamp":"2024-06-01T22:42:35.863722Z"}]}
{"channel":"book","type":"update","data":[{"symbol":"SOL/USDT","bids":[],"asks":[{"price":166.70,"qty":44.79358188}],"checksum":2951929826,"timestamp":"2024-06-01T22:42:35.863802Z"}]}
{"channel":"book","type":"update","data":[{"symbol":"SOL/USDT","bids":[{"price":166.62,"qty":0.00000000},{"price":166.45,"qty":102.45170090}],"asks":[],"checksum":1413252029,"timestamp":"2024-06-01T22:42:35.867643Z"}]}
{"channel":"book","type":"update","data":[{"symbol":"SOL/USDT","bids":[{"price":166.68,"qty":23.88547393}],"asks":[],"checksum":855694897,"timestamp":"2024-06-01T22:42:35.874577Z"}]}
{"channel":"book","type":"update","data":[{"symbol":"SOL/USDT","bids":[{"price":166.51,"qty":0.00000000},{"price":166.44,"qty":0.05001010}],"asks":[],"checksum":3496669122,"timestamp":"2024-06-01T22:42:35.888977Z"}]}
{"channel":"book","type":"update","data":[{"symbol":"SOL/USDT","bids":[],"asks":[{"price":166.70,"qty":30.02014698},{"price":166.69,"qty":18.27343490}],"checksum":85586644,"timestamp":"2024-06-01T22:42:35.889241Z"}]}
{"channel":"book","type":"update","data":[{"symbol":"SOL/USDT","bids":[{"price":166.47,"qty":12.82000000},{"price":166.54,"qty":3.20640296}],"asks":[],"checksum":269988037,"timestamp":"2024-06-01T22:42:35.889293Z"}]}
{"channel":"book","type":"update","data":[{"symbol":"SOL/USDT","bids":[],"asks":[{"price":166.83,"qty":72.34668532}],"checksum":2307001800,"timestamp":"2024-06-01T22:42:35.893132Z"}]}
{"channel":"book","type":"update","data":[{"symbol":"SOL/USDT","bids":[{"price":166.51,"qty":5.72700000}],"asks":[],"checksum":2038774074,"timestamp":"2024-06-01T22:42:35.893940Z"}]}
{"channel":"book","type":"update","data":[{"symbol":"SOL/USDT","bids":[{"price":166.59,"qty":0.00000000},{"price":166.45,"qty":102.45170090}],"asks":[],"checksum":1790448616,"timestamp":"2024-06-01T22:42:35.896091Z"}]}
{"channel":"book","type":"update","data":[{"symbol":"SOL/USDT","bids":[],"asks":[{"price":166.69,"qty":14.77343490}],"checksum":1301530477,"timestamp":"2024-06-01T22:42:35.898410Z"}]}
{"channel":"book","type":"update","data":[{"symbol":"SOL/USDT","bids":[],"asks":[{"price":166.70,"qty":33.52014698}],"checksum":1957179273,"timestamp":"2024-06-01T22:42:35.898622Z"}]}
{"channel":"book","type":"update","data":[{"symbol":"SOL/USDT","bids":[{"price":166.67,"qty":0.00000000},{"price":166.44,"qty":0.05001010}],"asks":[],"checksum":2262260496,"timestamp":"2024-06-01T22:42:35.902520Z"}]}
{"channel":"book","type":"update","data":[{"symbol":"SOL/USDT","bids":[],"asks":[{"price":166.70,"qty":30.02014698}],"checksum":2977250823,"timestamp":"2024-06-01T22:42:35.905478Z"}]}
{"channel":"book","type":"update","data":[{"symbol":"SOL/USDT","bids":[],"asks":[{"price":166.69,"qty":18.27343490}],"checksum":1049368870,"timestamp":"2024-06-01T22:42:35.905689Z"}]}
{"channel":"book","type":"update","data":[{"symbol":"SOL/USDT","bids":[{"price":166.64,"qty":23.89120736}],"asks":[],"checksum":2360913560,"timestamp":"2024-06-01T22:42:35.914084Z"}]}
{"channel":"book","type":"update","data":[{"symbol":"SOL/USDT","bids":[{"price":166.68,"qty":0.00000000},{"price":166.44,"qty":0.05001010}],"asks":[],"checksum":2456348460,"timestamp":"2024-06-01T22:42:35.914278Z"}]}
{"channel":"book","type":"update","data":[{"symbol":"SOL/USDT","bids":[{"price":166.64,"qty":25.09217385}],"asks":[],"checksum":3884472625,"timestamp":"2024-06-01T22:42:35.915311Z"}]}
{"channel":"book","type":"update","data":[{"symbol":"SOL/USDT","bids":[{"price":166.54,"qty":0.00000000},{"price":166.43,"qty":28.94000000},{"price":166.60,"qty":3.20524819}],"asks":[],"checksum":1783047601,"timestamp":"2024-06-01T22:42:35.917805Z"}]}
{"channel":"book","type":"update","data":[{"symbol":"SOL/USDT","bids":[],"asks":[{"price":166.70,"qty":0.00000000},{"price":166.87,"qty":10.24543356}],"checksum":350221889,"timestamp":"2024-06-01T22:42:35.932955Z"}]}
{"channel":"book","type":"update","data":[{"symbol":"SOL/USDT","bids":[{"price":166.60,"qty":0.00000000},{"price":166.43,"qty":28.94000000},{"price":166.55,"qty":3.20621044}],"asks":[],"checksum":3819251752,"timestamp":"2024-06-01T22:42:35.934877Z"}]}
{"channel":"book","type":"update","data":[{"symbol":"SOL/USDT","bids":[],"asks":[{"price":166.69,"qty":14.77343490}],"checksum":1817972489,"timestamp":"2024-06-01T22:42:35.948031Z"}]}
{"channel":"book","type":"update","data":[{"symbol":"SOL/USDT","bids":[{"price":166.55,"qty":0.00000000},{"price":166.43,"qty":28.94000000},{"price":166.54,"qty":3.20640296}],"asks":[],"checksum":384413152,"timestamp":"2024-06-01T22:42:35.952043Z"}]}
{"channel":"book","type":"update","data":[{"symbol":"SOL/USDT","bids":[],"asks":[{"price":166.69,"qty":0.00000000},{"price":166.88,"qty":72.70689353},{"price":166.71,"qty":14.77343490}],"checksum":991274753,"timestamp":"2024-06-01T22:42:35.955966Z"}]}
{"channel":"book","type":"update","data":[{"symbol":"SOL/USDT","bids":[],"asks":[{"price":166.70,"qty":3.50000000}],"checksum":3326583189,"timestamp":"2024-06-01T22:42:35.959130Z"}]}
{"channel":"book","type":"update","data":[{"symbol":"SOL/USDT","bids":[],"asks":[{"price":166.77,"qty":0.00000000},{"price":166.87,"qty":10.24543356}],"checksum":507215377,"timestamp":"2024-06-01T22:42:35.967780Z"}]}
{"channel":"book","type":"update","data":[{"symbol":"SOL/USDT","bids":[],"asks":[{"price":166.73,"qty":40.61397714}],"checksum":719498319,"timestamp":"2024-06-01T22:42:35.974527Z"}]}
{"channel":"book","type":"update","data":[{"symbol":"SOL/USDT","bids":[{"price":166.67,"qty":30.02417946}],"asks":[],"checksum":3191956954,"timestamp":"2024-06-01T22:42:35.974607Z"}]}
{"channel":"book","type":"update","data":[{"symbol":"SOL/USDT","bids":[{"price":166.63,"qty":69.05284888}],"asks":[],"checksum":2748412720,"timestamp":"2024-06-01T22:42:35.974664Z"}]}
{"channel":"book","type":"update","data":[{"symbol":"SOL/USDT","bids":[{"price":166.56,"qty":12.77000000}],"asks":[],"checksum":213563122,"timestamp":"2024-06-01T22:42:35.974793Z"}]}
{"channel":"book","type":"update","data":[{"symbol":"SOL/USDT","bids":[{"price":166.56,"qty":18.65800000}],"asks":[],"checksum":3227852789,"timestamp":"2024-06-01T22:42:35.982206Z"}]}
{"channel":"book","type":"update","data":[{"symbol":"SOL/USDT","bids":[],"asks":[{"price":166.70,"qty":0.00000000},{"price":166.88,"qty":72.70689353}],"checksum":2631754352,"timestamp":"2024-06-01T22:42:35.983848Z"}]}
{"channel":"book","type":"update","data":[{"symbol":"SOL/USDT","bids":[],"asks":[{"price":166.71,"qty":18.27343490}],"checksum":3153508085,"timestamp":"2024-06-01T22:42:35.984073Z"}]}
{"channel":"book","type":"update","data":[{"symbol":"SOL/USDT","bids":[],"asks":[{"price":166.77,"qty":45.01153663}],"checksum":2478793210,"timestamp":"2024-06-01T22:42:35.993649Z"}]}
{"channel":"book","type":"update","data":[{"symbol":"SOL/USDT","bids":[{"price":166.54,"qty":0.00000000},{"price":166.45,"qty":102.45170090}],"asks":[],"checksum":115168531,"timestamp":"2024-06-01T22:42:35.994620Z"}]}
{"channel":"book","type":"update","data":[{"symbol":"SOL/USDT","bids":[],"asks":[{"price":166.84,"qty":0.00000000},{"price":166.88,"qty":72.70689353}],"checksum":2356994146,"timestamp":"2024-06-01T22:42:35.997338Z"}]}
{"channel":"book","type":"update","data":[{"symbol":"SOL/USDT","bids":[],"asks":[{"price":166.83,"qty":0.00000000},{"price":166.90,"qty":37.20790892}],"checksum":2329219685,"timestamp":"2024-06-01T22:42:36.013118Z"}]}
{"channel":"book","type":"update","data":[{"symbol":"SOL/USDT","bids":[{"price":166.64,"qty":23.89120736}],"asks":[],"checksum":1756245089,"timestamp":"2024-06-01T22:42:36.015086Z"}]}
{"channel":"book","type":"update","data":[{"symbol":"SOL/USDT","bids":[],"asks":[{"price":166.73,"qty":10.60000000}],"checksum":305193950,"timestamp":"2024-06-01T22:42:36.020349Z"}]}
{"channel":"book","type":"update","data":[{"symbol":"SOL/USDT","bids":[],"asks":[{"price":166.82,"qty":0.00000000},{"price":166.92,"qty":62.99600000}],"checksum":1624403207,"timestamp":"2024-06-01T22:42:36.031433Z"}]}
{"channel":"book","type":"update","data":[{"symbol":"SOL/USDT","bids":[{"price":166.56,"qty":12.77000000}],"asks":[],"checksum":2157522003,"timestamp":"2024-06-01T22:42:36.043752Z"}]}
{"channel":"book","type":"update","data":[{"symbol":"SOL/USDT","bids":[],"asks":[{"price":166.70,"qty":1.38400000}],"checksum":886258057,"timestamp":"2024-06-01T22:42:36.065468Z"}]}
{"channel":"book","type":"update","data":[{"symbol":"SOL/USDT","bids":[],"asks":[{"price":166.77,"qty":50.89953663}],"checksum":492338144,"timestamp":"2024-06-01T22:42:36.066215Z"}]}
{"channel":"book","type":"update","data":[{"symbol":"SOL/USDT","bids":[{"price":166.63,"qty":45.04682890}],"asks":[],"checksum":170608316,"timestamp":"2024-06-01T22:42:36.072646Z"}]}
{"channel":"book","type":"update","data":[{"symbol":"SOL/USDT","bids":[],"asks":[{"price":166.71,"qty":14.77343490}],"checksum":3443461985,"timestamp":"2024-06-01T22:42:36.073437Z"}]}
{"channel":"book","type":"update","data":[{"symbol":"SOL/USDT","bids":[{"price":166.67,"qty":0.00000000},{"price":166.44,"qty":3.25833952}],"asks":[],"checksum":2735734024,"timestamp":"2024-06-01T22:42:36.087745Z"}]}
{"channel":"book","type":"update","data":[{"symbol":"SOL/USDT","bids":[],"asks":[{"price":166.71,"qty":18.27343490}],"checksum":1626248307,"timestamp":"2024-06-01T22:42:36.091088Z"}]}
{"channel":"book","type":"update","data":[{"symbol":"SOL/USDT","bids":[{"price":166.65,"qty":30.02724990}],"asks":[],"checksum":1332343246,"timestamp":"2024-06-01T22:42:36.092099Z"}]}
{"channel":"book","type":"update","data":[{"symbol":"SOL/USDT","bids":[],"asks":[{"price":166.72,"qty":34.36278105}],"checksum":2267859446,"timestamp":"2024-06-01T22:42:36.092147Z"}]}
{"channel":"book","type":"update","data":[{"symbol":"SOL/USDT","bids":[],"asks":[{"price":166.83,"qty":59.99237456}],"checksum":1475836099,"timestamp":"2024-06-01T22:42:36.092276Z"}]}
{"channel":"book","type":"update","data":[{"symbol":"SOL/USDT","bids":[],"asks":[{"price":166.71,"qty":3.50000000},{"price":166.76,"qty":14.77343490}],"checksum":389369925,"timestamp":"2024-06-01T22:42:36.107365Z"}]}
{"channel":"book","type":"update","data":[{"symbol":"SOL/USDT","bids":[],"asks":[{"price":166.71,"qty":0.00000000},{"price":166.88,"qty":72.70689353}],"checksum":2713132583,"timestamp":"2024-06-01T22:42:36.140283Z"}]}
{"channel":"book","type":"update","data":[{"symbol":"SOL/USDT","bids":[],"asks":[{"price":166.72,"qty":37.86278105}],"checksum":1885370597,"timestamp":"2024-06-01T22:42:36.140462Z"}]}
{"channel":"book","type":"update","data":[{"symbol":"SOL/USDT","bids":[{"price":166.58,"qty":5.88800000}],"asks":[],"checksum":1441890936,"timestamp":"2024-06-01T22:42:36.142204Z"}]}
{"channel":"book","type":"update","data":[{"symbol":"SOL/USDT","bids":[],"asks":[{"price":166.85,"qty":72.34668532}],"checksum":2207989940,"timestamp":"2024-06-01T22:42:36.144238Z"}]}
{"channel":"book","type":"update","data":[{"symbol":"SOL/USDT","bids":[{"price":166.65,"qty":0.00000000},{"price":166.45,"qty":102.45170090}],"asks":[],"checksum":2214023162,"timestamp":"2024-06-01T22:42:36.150294Z"}]}
{"channel":"book","type":"update","data":[{"symbol":"SOL/USDT","bids":[],"asks":[{"price":166.72,"qty":7.84680807}],"checksum":423552191,"timestamp":"2024-06-01T22:42:36.150454Z"}]}
{"channel":"book","type":"update","data":[{"symbol":"SOL/USDT","bids":[],"asks":[{"price":166.72,"qty":4.34680807}],"checksum":1967118107,"timestamp":"2024-06-01T22:42:36.153012Z"}]}
{"channel":"book","type":"update","data":[{"symbol":"SOL/USDT","bids":[],"asks":[{"price":166.71,"qty":3.50000000}],"checksum":1565006007,"timestamp":"2024-06-01T22:42:36.153271Z"}]}
{"channel":"book","type":"update","data":[{"symbol":"SOL/USDT","bids":[{"price":166.58,"qty":0.00000000},{"price":166.44,"qty":3.25833952}],"asks":[],"checksum":2430259649,"timestamp":"2024-06-01T22:42:36.153566Z"}]}
{"channel":"book","type":"update","data":[{"symbol":"SOL/USDT","bids":[{"price":166.55,"qty":60.09238799}],"asks":[],"checksum":2687506851,"timestamp":"2024-06-01T22:42:36.154761Z"}]}
{"channel":"book","type":"update","data":[{"symbol":"SOL/USDT","bids":[],"asks":[{"price":166.74,"qty":30.01268362}],"checksum":2353727303,"timestamp":"2024-06-01T22:42:36.193390Z"}]}
{"channel":"book","type":"update","data":[{"symbol":"SOL/USDT","bids":[{"price":166.67,"qty":30.02416020}],"asks":[],"checksum":1225486161,"timestamp":"2024-06-01T22:42:36.193500Z"}]}
{"channel":"book","type":"update","data":[{"symbol":"SOL/USDT","bids":[],"asks":[{"price":166.71,"qty":0.00000000},{"price":166.86,"qty":5.72700000}],"checksum":3174829447,"timestamp":"2024-06-01T22:42:36.196221Z"}]}
{"channel":"book","type":"update","data":[{"symbol":"SOL/USDT","bids":[],"asks":[{"price":166.72,"qty":7.84680807}],"checksum":3510451747,"timestamp":"2024-06-01T22:42:36.196877Z"}]}
{"channel":"book","type":"update","data":[{"symbol":"SOL/USDT","bids":[],"asks":[{"price":166.74,"qty":0.00000000},{"price":166.87,"qty":10.24543356}],"checksum":2952658151,"timestamp":"2024-06-01T22:42:36.230113Z"}]}
{"channel":"book","type":"update","data":[{"symbol":"SOL/USDT","bids":[],"asks":[{"price":166.76,"qty":0.00000000},{"price":166.88,"qty":72.70689353},{"price":166.71,"qty":14.77343490}],"checksum":3905183633,"timestamp":"2024-06-01T22:42:36.246917Z"}]}
{"channel":"book","type":"update","data":[{"symbol":"SOL/USDT","bids":[{"price":166.65,"qty":3.20428652}],"asks":[],"checksum":264890897,"timestamp":"2024-06-01T22:42:36.246962Z"}]}
{"channel":"book","type":"update","data":[{"symbol":"SOL/USDT","bids":[],"asks":[{"price":166.84,"qty":2.44999272}],"checksum":59326263,"timestamp":"2024-06-01T22:42:36.249860Z"}]}
{"channel":"book","type":"update","data":[{"symbol":"SOL/USDT","bids":[{"price":166.60,"qty":5.88800000}],"asks":[],"checksum":3474794939,"timestamp":"2024-06-01T22:42:36.252257Z"}]}
{"channel":"book","type":"update","data":[{"symbol":"SOL/USDT","bids":[{"price":166.53,"qty":238.46238863}],"asks":[],"checksum":1006784178,"timestamp":"2024-06-01T22:42:36.337408Z"}]}
{"channel":"book","type":"update","data":[{"symbol":"SOL/USDT","bids":[],"asks":[{"price":166.72,"qty":37.86381642}],"checksum":3626776415,"timestamp":"2024-06-01T22:42:36.349298Z"}]}
{"channel":"book","type":"update","data":[{"symbol":"SOL/USDT","bids":[{"price":166.54,"qty":5.97790994}],"asks":[],"checksum":813144127,"timestamp":"2024-06-01T22:42:36.502799Z"}]}
{"channel":"book","type":"update","data":[{"symbol":"SOL/USDT","bids":[],"asks":[{"price":166.80,"qty":16.50048271}],"checksum":3744842994,"timestamp":"2024-06-01T22:42:36.526307Z"}]}
{"channel":"book","type":"update","data":[{"symbol":"SOL/USDT","bids":[{"price":166.62,"qty":14.77343490}],"asks":[],"checksum":374675739,"timestamp":"2024-06-01T22:42:36.566754Z"}]}
{"channel":"book","type":"update","data":[{"symbol":"SOL/USDT","bids":[],"asks":[{"price":166.72,"qty":34.36381642}],"checksum":1289184449,"timestamp":"2024-06-01T22:42:36.866685Z"}]}
{"channel":"book","type":"update","data":[{"symbol":"SOL/USDT","bids":[],"asks":[{"price":166.71,"qty":18.27343490}],"checksum":328120641,"timestamp":"2024-06-01T22:42:36.866914Z"}]}
{"channel":"book","type":"update","data":[{"symbol":"SOL/USDT","bids":[],"asks":[{"price":166.71,"qty":14.77343490}],"checksum":1289184449,"timestamp":"2024-06-01T22:42:36.874232Z"}]}
{"channel":"book","type":"update","data":[{"symbol":"SOL/USDT","bids":[],"asks":[{"price":166.71,"qty":0.00000000},{"price":166.87,"qty":10.24543356},{"price":166.70,"qty":16.15818852}],"checksum":1582893,"timestamp":"2024-06-01T22:42:36.881719Z"}]}
{"channel":"book","type":"update","data":[{"symbol":"SOL/USDT","bids":[],"asks":[{"price":166.72,"qty":4.34680807}],"checksum":2963409340,"timestamp":"2024-06-01T22:42:36.882347Z"}]}
{"channel":"book","type":"update","data":[{"symbol":"SOL/USDT","bids":[{"price":166.67,"qty":0.00000000},{"price":166.53,"qty":238.46238863}],"asks":[],"checksum":1769341907,"timestamp":"2024-06-01T22:42:36.882366Z"}]}
{"channel":"book","type":"update","data":[{"symbol":"SOL/USDT","bids":[{"price":166.55,"qty":65.81938799}],"asks":[],"checksum":3106782631,"timestamp":"2024-06-01T22:42:36.886068Z"}]}
{"channel":"book","type":"update","data":[{"symbol":"SOL/USDT","bids":[],"asks":[{"price":166.74,"qty":30.01219704}],"checksum":1891146105,"timestamp":"2024-06-01T22:42:36.886983Z"}]}
{"channel":"book","type":"update","data":[{"symbol":"SOL/USDT","bids":[{"price":166.59,"qty":60.07692406}],"asks":[],"checksum":4005774185,"timestamp":"2024-06-01T22:42:36.887194Z"}]}
{"channel":"book","type":"update","data":[{"symbol":"SOL/USDT","bids":[{"price":166.68,"qty":30.02129091}],"asks":[],"checksum":234613347,"timestamp":"2024-06-01T22:42:36.887246Z"}]}
{"channel":"book","type":"update","data":[{"symbol":"SOL/USDT","bids":[],"asks":[{"price":166.77,"qty":45.01153663}],"checksum":2109688811,"timestamp":"2024-06-01T22:42:36.888377Z"}]}
{"channel":"book","type":"update","data":[{"symbol":"SOL/USDT","bids":[{"price":166.65,"qty":0.00000000},{"price":166.54,"qty":5.97790994}],"asks":[],"checksum":2484058315,"timestamp":"2024-06-01T22:42:36.891207Z"}]}
{"channel":"book","type":"update","data":[{"symbol":"SOL/USDT","bids":[{"price":166.63,"qty":0.00000000},{"price":166.53,"qty":238.46238863}],"asks":[],"checksum":3155013101,"timestamp":"2024-06-01T22:42:36.893684Z"}]}
{"channel":"book","type":"update","data":[{"symbol":"SOL/USDT","bids":[{"price":166.65,"qty":45.04139102}],"asks":[],"checksum":3370272396,"timestamp":"2024-06-01T22:42:36.897431Z"}]}
{"channel":"book","type":"update","data":[{"symbol":"SOL/USDT","bids":[{"price":166.63,"qty":23.89264115}],"asks":[],"checksum":897942364,"timestamp":"2024-06-01T22:42:36.904765Z"}]}
{"channel":"book","type":"update","data":[{"symbol":"SOL/USDT","bids":[{"price":166.64,"qty":0.00000000},{"price":166.54,"qty":5.97790994}],"asks":[],"checksum":2026260858,"timestamp":"2024-06-01T22:42:36.904884Z"}]}
{"channel":"book","type":"update","data":[{"symbol":"SOL/USDT","bids":[],"asks":[{"price":166.70,"qty":1.38400000},{"price":166.71,"qty":14.77418852}],"checksum":3084395718,"timestamp":"2024-06-01T22:42:36.905242Z"}]}
{"channel":"book","type":"update","data":[{"symbol":"SOL/USDT","bids":[],"asks":[{"price":166.71,"qty":0.00000000},{"price":166.86,"qty":5.72700000},{"price":166.72,"qty":19.12099659}],"checksum":1407619430,"timestamp":"2024-06-01T22:42:36.921778Z"}]}
{"channel":"book","type":"update","data":[{"symbol":"SOL/USDT","bids":[],"asks":[{"price":166.72,"qty":22.62099659}],"checksum":2522828636,"timestamp":"2024-06-01T22:42:36.924531Z"}]}
{"channel":"book","type":"update","data":[{"symbol":"SOL/USDT","bids":[],"asks":[{"price":166.72,"qty":7.84680807},{"price":166.73,"qty":25.37418852}],"checksum":3477312286,"timestamp":"2024-06-01T22:42:36.946102Z"}]}
{"channel":"book","type":"update","data":[{"symbol":"SOL/USDT","bids":[],"asks":[{"price":166.80,"qty":1.72704781}],"checksum":1331773717,"timestamp":"2024-06-01T22:42:36.967394Z"}]}
{"channel":"book","type":"update","data":[{"symbol":"SOL/USDT","bids":[],"asks":[{"price":166.78,"qty":5.88800000}],"checksum":3727748234,"timestamp":"2024-06-01T22:42:36.986770Z"}]}
