{"channel":"book","type":"snapshot","data":[{"symbol":"SOL/ETH","bids":[{"price":0.043621,"qty":0.20933865},{"price":0.043617,"qty":0.13755841},{"price":0.043616,"qty":30.01238578},{"price":0.043611,"qty":30.01438659},{"price":0.043602,"qty":60.05475785},{"price":0.043592,"qty":60.05625382},{"price":0.043573,"qty":0.78369991},{"price":0.043572,"qty":194.86279828},{"price":0.043571,"qty":14.42000000},{"price":0.043570,"qty":60.08147749}],"asks":[{"price":0.043622,"qty":30.00503584},{"price":0.043625,"qty":5.81790488},{"price":0.043626,"qty":30.00612471},{"price":0.043630,"qty":60.00329289},{"price":0.043636,"qty":60.00293336},{"price":0.043658,"qty":0.82045013},{"price":0.043679,"qty":59.93496633},{"price":0.043680,"qty":10.29000000},{"price":0.043702,"qty":14.63000000},{"price":0.043721,"qty":19.51887542}],"checksum":3688159862}]}
{"channel":"book","type":"update","data":[{"symbol":"SOL/ETH","bids":[{"price":0.043616,"qty":0.00000000},{"price":0.043532,"qty":5.28121045}],"asks":[],"checksum":1380091152,"timestamp":"2024-06-01T22:42:20.838011Z"}]}
{"channel":"book","type":"update","data":[{"symbol":"SOL/ETH","bids":[{"price":0.043617,"qty":30.15018820}],"asks":[],"checksum":2694583593,"timestamp":"2024-06-01T22:42:20.841947Z"}]}
{"channel":"book","type":"update","data":[{"symbol":"SOL/ETH","bids":[{"price":0.043602,"qty":0.00000000},{"price":0.043531,"qty":9.21989450}],"asks":[],"checksum":2413728269,"timestamp":"2024-06-01T22:42:22.840526Z"}]}
{"channel":"book","type":"update","data":[{"symbol":"SOL/ETH","bids":[{"price":0.043607,"qty":60.03744021}],"asks":[],"checksum":4188788891,"timestamp":"2024-06-01T22:42:22.844449Z"}]}
{"channel":"book","type":"update","data":[{"symbol":"SOL/ETH","bids":[{"price":0.043617,"qty":0.13755841}],"asks":[],"checksum":192235682,"timestamp":"2024-06-01T22:42:23.126320Z"}]}
{"channel":"book","type":"update","data":[{"symbol":"SOL/ETH","bids":[{"price":0.043616,"qty":30.01235850}],"asks":[],"checksum":3665137829,"timestamp":"2024-06-01T22:42:23.129746Z"}]}
{"channel":"book","type":"update","data":[{"symbol":"SOL/ETH","bids":[{"price":0.043616,"qty":0.00000000},{"price":0.043532,"qty":5.28121045}],"asks":[],"checksum":192235682,"timestamp":"2024-06-01T22:42:24.201103Z"}]}
{"channel":"book","type":"update","data":[{"symbol":"SOL/ETH","bids":[],"asks":[{"price":0.043636,"qty":0.00000000},{"price":0.043724,"qty":11.96000000}],"checksum":2497359863,"timestamp":"2024-06-01T22:42:24.201159Z"}]}
{"channel":"book","type":"update","data":[{"symbol":"SOL/ETH","bids":[],"asks":[{"price":0.043622,"qty":0.00000000},{"price":0.043741,"qty":9.56047203}],"checksum":1551173313,"timestamp":"2024-06-01T22:42:24.201198Z"}]}
{"channel":"book","type":"update","data":[{"symbol":"SOL/ETH","bids":[],"asks":[{"price":0.043623,"qty":30.00779345}],"checksum":1871749421,"timestamp":"2024-06-01T22:42:24.205731Z"}]}
{"channel":"book","type":"update","data":[{"symbol":"SOL/ETH","bids":[],"asks":[{"price":0.043647,"qty":59.98252779}],"checksum":2587921898,"timestamp":"2024-06-01T22:42:24.205786Z"}]}
{"channel":"book","type":"update","data":[{"symbol":"SOL/ETH","bids":[{"price":0.043617,"qty":30.14886033}],"asks":[],"checksum":781566844,"timestamp":"2024-06-01T22:42:24.205824Z"}]}
{"channel":"book","type":"update","data":[{"symbol":"SOL/ETH","bids":[],"asks":[{"price":0.043625,"qty":0.00000000},{"price":0.043724,"qty":11.96000000},{"price":0.043622,"qty":5.81790488}],"checksum":1255383744,"timestamp":"2024-06-01T22:42:24.224124Z"}]}
{"channel":"book","type":"update","data":[{"symbol":"SOL/ETH","bids":[{"price":0.043617,"qty":0.13755841}],"asks":[],"checksum":1372789013,"timestamp":"2024-06-01T22:42:24.328802Z"}]}
{"channel":"book","type":"update","data":[{"symbol":"SOL/ETH","bids":[],"asks":[{"price":0.043623,"qty":0.00000000},{"price":0.043724,"qty":11.96000000}],"checksum":991529058,"timestamp":"2024-06-01T22:42:24.328824Z"}]}
{"channel":"book","type":"update","data":[{"symbol":"SOL/ETH","bids":[],"asks":[{"price":0.043622,"qty":0.00000000},{"price":0.043741,"qty":9.56047203},{"price":0.043625,"qty":5.81790488}],"checksum":1001429466,"timestamp":"2024-06-01T22:42:24.350540Z"}]}
{"channel":"book","type":"update","data":[{"symbol":"SOL/ETH","bids":[],"asks":[{"price":0.043626,"qty":0.00000000},{"price":0.043741,"qty":9.56047203}],"checksum":3563136588,"timestamp":"2024-06-01T22:42:24.567547Z"}]}
{"channel":"book","type":"update","data":[{"symbol":"SOL/ETH","bids":[],"asks":[{"price":0.043625,"qty":0.00000000},{"price":0.043742,"qty":59.82178350},{"price":0.043629,"qty":5.81790488}],"checksum":2814768187,"timestamp":"2024-06-01T22:42:24.570457Z"}]}
{"channel":"book","type":"update","data":[{"symbol":"SOL/ETH","bids":[],"asks":[{"price":0.043622,"qty":30.00725536}],"checksum":389387622,"timestamp":"2024-06-01T22:42:24.570917Z"}]}
{"channel":"book","type":"update","data":[{"symbol":"SOL/ETH","bids":[],"asks":[{"price":0.043624,"qty":30.00490531}],"checksum":2652108977,"timestamp":"2024-06-01T22:42:24.570952Z"}]}
{"channel":"book","type":"update","data":[{"symbol":"SOL/ETH","bids":[{"price":0.043615,"qty":30.01132023}],"asks":[],"checksum":3396819757,"timestamp":"2024-06-01T22:42:24.571074Z"}]}
{"channel":"book","type":"update","data":[{"symbol":"SOL/ETH","bids":[],"asks":[{"price":0.043629,"qty":0.00000000},{"price":0.043724,"qty":11.96000000},{"price":0.043623,"qty":5.81790488}],"checksum":4203294976,"timestamp":"2024-06-01T22:42:24.586447Z"}]}
{"channel":"book","type":"update","data":[{"symbol":"SOL/ETH","bids":[],"asks":[{"price":0.043623,"qty":0.00000000},{"price":0.043724,"qty":11.96000000},{"price":0.043622,"qty":35.82516024}],"checksum":2191562730,"timestamp":"2024-06-01T22:42:24.605319Z"}]}
{"channel":"book","type":"update","data":[{"symbol":"SOL/ETH","bids":[{"price":0.043615,"qty":0.00000000},{"price":0.043532,"qty":5.28121045}],"asks":[],"checksum":4226380822,"timestamp":"2024-06-01T22:42:24.614717Z"}]}
{"channel":"book","type":"update","data":[{"symbol":"SOL/ETH","bids":[],"asks":[{"price":0.043622,"qty":30.00725536},{"price":0.043623,"qty":5.81790488}],"checksum":3582344286,"timestamp":"2024-06-01T22:42:24.623660Z"}]}
{"channel":"book","type":"update","data":[{"symbol":"SOL/ETH","bids":[],"asks":[{"price":0.043623,"qty":0.00000000},{"price":0.043724,"qty":11.96000000},{"price":0.043622,"qty":35.82516024}],"checksum":4226380822,"timestamp":"2024-06-01T22:42:24.645444Z"}]}
{"channel":"book","type":"update","data":[{"symbol":"SOL/ETH","bids":[],"asks":[{"price":0.043622,"qty":30.00725536},{"price":0.043623,"qty":5.81790488}],"checksum":3582344286,"timestamp":"2024-06-01T22:42:24.650935Z"}]}
{"channel":"book","type":"update","data":[{"symbol":"SOL/ETH","bids":[],"asks":[{"price":0.043623,"qty":0.00000000},{"price":0.043724,"qty":11.96000000},{"price":0.043622,"qty":35.82516024}],"checksum":4226380822,"timestamp":"2024-06-01T22:42:24.654059Z"}]}
{"channel":"book","type":"update","data":[{"symbol":"SOL/ETH","bids":[],"asks":[{"price":0.043622,"qty":30.00725536},{"price":0.043623,"qty":5.81790488}],"checksum":3582344286,"timestamp":"2024-06-01T22:42:24.657245Z"}]}
{"channel":"book","type":"update","data":[{"symbol":"SOL/ETH","bids":[{"price":0.043614,"qty":30.01120634}],"asks":[],"checksum":1610857124,"timestamp":"2024-06-01T22:42:24.899989Z"}]}
{"channel":"book","type":"update","data":[{"symbol":"SOL/ETH","bids":[{"price":0.043614,"qty":0.00000000},{"price":0.043532,"qty":5.28121045}],"asks":[],"checksum":3582344286,"timestamp":"2024-06-01T22:42:24.906158Z"}]}
{"channel":"book","type":"update","data":[{"symbol":"SOL/ETH","bids":[{"price":0.043613,"qty":30.01100968}],"asks":[],"checksum":2447335618,"timestamp":"2024-06-01T22:42:25.670796Z"}]}
{"channel":"book","type":"update","data":[{"symbol":"SOL/ETH","bids":[{"price":0.043613,"qty":0.00000000},{"price":0.043532,"qty":5.28121045}],"asks":[],"checksum":3582344286,"timestamp":"2024-06-01T22:42:26.061123Z"}]}
{"channel":"book","type":"update","data":[{"symbol":"SOL/ETH","bids":[{"price":0.043614,"qty":30.01018856}],"asks":[],"checksum":1271315854,"timestamp":"2024-06-01T22:42:26.064723Z"}]}
{"channel":"book","type":"update","data":[{"symbol":"SOL/ETH","bids":[],"asks":[{"price":0.043623,"qty":0.00000000},{"price":0.043724,"qty":11.96000000},{"price":0.043678,"qty":5.81790488}],"checksum":2494943595,"timestamp":"2024-06-01T22:42:26.065266Z"}]}
{"channel":"book","type":"update","data":[{"symbol":"SOL/ETH","bids":[],"asks":[{"price":0.043678,"qty":0.00000000},{"price":0.043724,"qty":11.96000000},{"price":0.043629,"qty":5.81790488}],"checksum":2067322787,"timestamp":"2024-06-01T22:42:26.105492Z"}]}
{"channel":"book","type":"update","data":[{"symbol":"SOL/ETH","bids":[],"asks":[{"price":0.043629,"qty":0.00000000},{"price":0.043724,"qty":11.96000000},{"price":0.043623,"qty":5.81790488}],"checksum":1271315854,"timestamp":"2024-06-01T22:42:26.128769Z"}]}
{"channel":"book","type":"update","data":[{"symbol":"SOL/ETH","bids":[{"price":0.043614,"qty":0.00000000},{"price":0.043532,"qty":5.28121045}],"asks":[],"checksum":3582344286,"timestamp":"2024-06-01T22:42:26.973328Z"}]}
{"channel":"book","type":"update","data":[{"symbol":"SOL/ETH","bids":[{"price":0.043615,"qty":30.01011941}],"asks":[],"checksum":138619583,"timestamp":"2024-06-01T22:42:26.976651Z"}]}
{"channel":"book","type":"update","data":[{"symbol":"SOL/ETH","bids":[{"price":0.043573,"qty":0.00000000},{"price":0.043532,"qty":5.28121045},{"price":0.043612,"qty":0.78304206}],"asks":[],"checksum":3688314417,"timestamp":"2024-06-01T22:42:27.431862Z"}]}
{"channel":"book","type":"update","data":[{"symbol":"SOL/ETH","bids":[{"price":0.043612,"qty":0.00000000},{"price":0.043532,"qty":5.28121045},{"price":0.043573,"qty":0.78374299}],"asks":[],"checksum":3621861908,"timestamp":"2024-06-01T22:42:27.506422Z"}]}
{"channel":"book","type":"update","data":[{"symbol":"SOL/ETH","bids":[{"price":0.043615,"qty":0.00000000},{"price":0.043532,"qty":5.28121045}],"asks":[],"checksum":1757675689,"timestamp":"2024-06-01T22:42:27.627351Z"}]}
{"channel":"book","type":"update","data":[{"symbol":"SOL/ETH","bids":[{"price":0.043616,"qty":30.00936990}],"asks":[],"checksum":1669611103,"timestamp":"2024-06-01T22:42:27.631158Z"}]}
{"channel":"book","type":"update","data":[{"symbol":"SOL/ETH","bids":[],"asks":[{"price":0.043623,"qty":0.00000000},{"price":0.043724,"qty":11.96000000},{"price":0.043629,"qty":5.81790488}],"checksum":1400525938,"timestamp":"2024-06-01T22:42:27.649811Z"}]}
{"channel":"book","type":"update","data":[{"symbol":"SOL/ETH","bids":[],"asks":[{"price":0.043629,"qty":0.00000000},{"price":0.043724,"qty":11.96000000},{"price":0.043623,"qty":5.81790488}],"checksum":1669611103,"timestamp":"2024-06-01T22:42:27.662152Z"}]}
{"channel":"book","type":"update","data":[{"symbol":"SOL/ETH","bids":[],"asks":[{"price":0.043623,"qty":0.00000000},{"price":0.043724,"qty":11.96000000},{"price":0.043678,"qty":5.81790488}],"checksum":3170325178,"timestamp":"2024-06-01T22:42:27.690021Z"}]}
{"channel":"book","type":"update","data":[{"symbol":"SOL/ETH","bids":[],"asks":[{"price":0.043678,"qty":0.00000000},{"price":0.043724,"qty":11.96000000},{"price":0.043629,"qty":5.81790488}],"checksum":1400525938,"timestamp":"2024-06-01T22:42:27.747500Z"}]}
{"channel":"book","type":"update","data":[{"symbol":"SOL/ETH","bids":[],"asks":[{"price":0.043629,"qty":0.00000000},{"price":0.043724,"qty":11.96000000},{"price":0.043678,"qty":5.81790488}],"checksum":3170325178,"timestamp":"2024-06-01T22:42:27.765379Z"}]}
{"channel":"book","type":"update","data":[{"symbol":"SOL/ETH","bids":[],"asks":[{"price":0.043678,"qty":0.00000000},{"price":0.043724,"qty":11.96000000},{"price":0.043629,"qty":5.81790488}],"checksum":1400525938,"timestamp":"2024-06-01T22:42:27.804713Z"}]}
{"channel":"book","type":"update","data":[{"symbol":"SOL/ETH","bids":[],"asks":[{"price":0.043622,"qty":0.00000000},{"price":0.043724,"qty":11.96000000},{"price":0.043624,"qty":0.00000000},{"price":0.043741,"qty":9.56047203},{"price":0.043629,"qty":0.00000000},{"price":0.043742,"qty":59.82178350},{"price":0.043630,"qty":33.86935844}],"checksum":3174914648,"timestamp":"2024-06-01T22:42:27.849031Z"}]}
{"channel":"book","type":"update","data":[{"symbol":"SOL/ETH","bids":[{"price":0.043573,"qty":0.00000000},{"price":0.043532,"qty":5.28121045},{"price":0.043573,"qty":1.60823970}],"asks":[],"checksum":459664410,"timestamp":"2024-06-01T22:42:28.129823Z"}]}
{"channel":"book","type":"update","data":[{"symbol":"SOL/ETH","bids":[],"asks":[{"price":0.043629,"qty":5.17518226}],"checksum":472053818,"timestamp":"2024-06-01T22:42:28.129946Z"}]}
{"channel":"book","type":"update","data":[{"symbol":"SOL/ETH","bids":[],"asks":[{"price":0.043622,"qty":30.00725536}],"checksum":2253579213,"timestamp":"2024-06-01T22:42:28.133681Z"}]}
{"channel":"book","type":"update","data":[{"symbol":"SOL/ETH","bids":[],"asks":[{"price":0.043628,"qty":30.00126863}],"checksum":1597558113,"timestamp":"2024-06-01T22:42:28.133811Z"}]}
{"channel":"book","type":"update","data":[{"symbol":"SOL/ETH","bids":[],"asks":[{"price":0.043629,"qty":0.00000000},{"price":0.043724,"qty":11.96000000},{"price":0.043627,"qty":5.17518226}],"checksum":1625397273,"timestamp":"2024-06-01T22:42:28.255832Z"}]}
{"channel":"book","type":"update","data":[{"symbol":"SOL/ETH","bids":[],"asks":[{"price":0.043628,"qty":0.00000000},{"price":0.043724,"qty":11.96000000}],"checksum":1997070382,"timestamp":"2024-06-01T22:42:34.343789Z"}]}
{"channel":"book","type":"update","data":[{"symbol":"SOL/ETH","bids":[{"price":0.043616,"qty":0.00000000},{"price":0.043532,"qty":5.28121045}],"asks":[],"checksum":1931228425,"timestamp":"2024-06-01T22:42:34.343894Z"}]}
{"channel":"book","type":"update","data":[{"symbol":"SOL/ETH","bids":[],"asks":[{"price":0.043627,"qty":0.00000000},{"price":0.043741,"qty":9.56047203},{"price":0.043629,"qty":5.17519109}],"checksum":2390637384,"timestamp":"2024-06-01T22:42:34.347126Z"}]}
{"channel":"book","type":"update","data":[{"symbol":"SOL/ETH","bids":[],"asks":[{"price":0.043625,"qty":30.00367558}],"checksum":1347026448,"timestamp":"2024-06-01T22:42:34.348352Z"}]}
{"channel":"book","type":"update","data":[{"symbol":"SOL/ETH","bids":[{"price":0.043615,"qty":30.00991338}],"asks":[],"checksum":423067343,"timestamp":"2024-06-01T22:42:34.348412Z"}]}
{"channel":"book","type":"update","data":[{"symbol":"SOL/ETH","bids":[],"asks":[{"price":0.043629,"qty":0.00000000},{"price":0.043724,"qty":11.96000000},{"price":0.043624,"qty":5.17519109}],"checksum":1971053772,"timestamp":"2024-06-01T22:42:34.352354Z"}]}
{"channel":"book","type":"update","data":[{"symbol":"SOL/ETH","bids":[{"price":0.043615,"qty":0.00000000},{"price":0.043532,"qty":5.28121045}],"asks":[],"checksum":440799300,"timestamp":"2024-06-01T22:42:35.733782Z"}]}
{"channel":"book","type":"update","data":[{"symbol":"SOL/ETH","bids":[],"asks":[{"price":0.043625,"qty":0.00000000},{"price":0.043724,"qty":11.96000000}],"checksum":3282157319,"timestamp":"2024-06-01T22:42:35.736830Z"}]}
{"channel":"book","type":"update","data":[{"symbol":"SOL/ETH","bids":[{"price":0.043607,"qty":0.00000000},{"price":0.043531,"qty":9.21989450}],"asks":[],"checksum":743489687,"timestamp":"2024-06-01T22:42:35.736885Z"}]}
{"channel":"book","type":"update","data":[{"symbol":"SOL/ETH","bids":[{"price":0.043611,"qty":0.00000000},{"price":0.043512,"qty":0.32018436}],"asks":[],"checksum":2508097148,"timestamp":"2024-06-01T22:42:35.736928Z"}]}
{"channel":"book","type":"update","data":[{"symbol":"SOL/ETH","bids":[],"asks":[{"price":0.043679,"qty":0.00000000},{"price":0.043741,"qty":9.56047203}],"checksum":1815219341,"timestamp":"2024-06-01T22:42:35.736989Z"}]}
{"channel":"book","type":"update","data":[{"symbol":"SOL/ETH","bids":[],"asks":[{"price":0.043622,"qty":60.01451072}],"checksum":1388387067,"timestamp":"2024-06-01T22:42:35.744189Z"}]}
{"channel":"book","type":"update","data":[{"symbol":"SOL/ETH","bids":[{"price":0.043602,"qty":30.01903570}],"asks":[],"checksum":56176232,"timestamp":"2024-06-01T22:42:35.744234Z"}]}
{"channel":"book","type":"update","data":[{"symbol":"SOL/ETH","bids":[{"price":0.043549,"qty":60.11035719}],"asks":[],"checksum":4288605677,"timestamp":"2024-06-01T22:42:35.744292Z"}]}
{"channel":"book","type":"update","data":[{"symbol":"SOL/ETH","bids":[],"asks":[{"price":0.043622,"qty":120.02528622}],"checksum":224742674,"timestamp":"2024-06-01T22:42:35.744330Z"}]}
{"channel":"book","type":"update","data":[{"symbol":"SOL/ETH","bids":[{"price":0.043592,"qty":0.00000000},{"price":0.043531,"qty":9.21989450}],"asks":[],"checksum":3915520941,"timestamp":"2024-06-01T22:42:35.746959Z"}]}
{"channel":"book","type":"update","data":[{"symbol":"SOL/ETH","bids":[],"asks":[{"price":0.043741,"qty":0.00000000},{"price":0.043742,"qty":59.82178350}],"checksum":4190820863,"timestamp":"2024-06-01T22:42:35.747897Z"}]}
{"channel":"book","type":"update","data":[{"symbol":"SOL/ETH","bids":[],"asks":[{"price":0.043720,"qty":9.56047203}],"checksum":1062015647,"timestamp":"2024-06-01T22:42:35.747911Z"}]}
{"channel":"book","type":"update","data":[{"symbol":"SOL/ETH","bids":[{"price":0.043602,"qty":0.00000000},{"price":0.043512,"qty":0.32018436}],"asks":[],"checksum":763544975,"timestamp":"2024-06-01T22:42:35.750759Z"}]}
{"channel":"book","type":"update","data":[{"symbol":"SOL/ETH","bids":[],"asks":[{"price":0.043630,"qty":0.00000000},{"price":0.043756,"qty":49.91414100}],"checksum":2589729710,"timestamp":"2024-06-01T22:42:35.755753Z"}]}
{"channel":"book","type":"update","data":[{"symbol":"SOL/ETH","bids":[{"price":0.043532,"qty":0.00000000},{"price":0.043499,"qty":0.60952872}],"asks":[],"checksum":653517144,"timestamp":"2024-06-01T22:42:35.757454Z"}]}
{"channel":"book","type":"update","data":[{"symbol":"SOL/ETH","bids":[{"price":0.043550,"qty":5.27902763}],"asks":[],"checksum":4205645259,"timestamp":"2024-06-01T22:42:35.757759Z"}]}
{"channel":"book","type":"update","data":[{"symbol":"SOL/ETH","bids":[],"asks":[{"price":0.043624,"qty":0.00000000},{"price":0.043876,"qty":59.55460368},{"price":0.043629,"qty":5.17519102}],"checksum":3537509602,"timestamp":"2024-06-01T22:42:35.758116Z"}]}
{"channel":"book","type":"update","data":[{"symbol":"SOL/ETH","bids":[],"asks":[{"price":0.043622,"qty":180.03606172}],"checksum":4286670647,"timestamp":"2024-06-01T22:42:35.760965Z"}]}
{"channel":"book","type":"update","data":[{"symbol":"SOL/ETH","bids":[{"price":0.043585,"qty":30.03062029}],"asks":[],"checksum":3262875553,"timestamp":"2024-06-01T22:42:35.761052Z"}]}
{"channel":"book","type":"update","data":[{"symbol":"SOL/ETH","bids":[],"asks":[{"price":0.043716,"qty":59.88209749}],"checksum":1310996311,"timestamp":"2024-06-01T22:42:35.761176Z"}]}
{"channel":"book","type":"update","data":[{"symbol":"SOL/ETH","bids":[{"price":0.043583,"qty":60.06397865}],"asks":[],"checksum":3322078828,"timestamp":"2024-06-01T22:42:35.761197Z"}]}
{"channel":"book","type":"update","data":[{"symbol":"SOL/ETH","bids":[{"price":0.043585,"qty":0.00000000},{"price":0.043531,"qty":9.21989450}],"asks":[],"checksum":2547618227,"timestamp":"2024-06-01T22:42:35.766583Z"}]}
{"channel":"book","type":"update","data":[{"symbol":"SOL/ETH","bids":[],"asks":[{"price":0.043715,"qty":9.56047203}],"checksum":2565196521,"timestamp":"2024-06-01T22:42:35.769808Z"}]}
{"channel":"book","type":"update","data":[{"symbol":"SOL/ETH","bids":[],"asks":[{"price":0.043720,"qty":0.00000000},{"price":0.043724,"qty":11.96000000}],"checksum":1999794685,"timestamp":"2024-06-01T22:42:35.769923Z"}]}
{"channel":"book","type":"update","data":[{"symbol":"SOL/ETH","bids":[{"price":0.043570,"qty":0.00000000},{"price":0.043512,"qty":0.32018436}],"asks":[],"checksum":354956326,"timestamp":"2024-06-01T22:42:35.774665Z"}]}
{"channel":"book","type":"update","data":[{"symbol":"SOL/ETH","bids":[{"price":0.043567,"qty":60.08565166}],"asks":[],"checksum":3009053343,"timestamp":"2024-06-01T22:42:35.784654Z"}]}
{"channel":"book","type":"update","data":[{"symbol":"SOL/ETH","bids":[],"asks":[{"price":0.043629,"qty":0.00000000},{"price":0.043876,"qty":59.55460368},{"price":0.043875,"qty":5.17519102}],"checksum":2060126576,"timestamp":"2024-06-01T22:42:35.794341Z"}]}
{"channel":"book","type":"update","data":[{"symbol":"SOL/ETH","bids":[],"asks":[{"price":0.043721,"qty":0.00000000},{"price":0.043876,"qty":59.55460368},{"price":0.043701,"qty":17.57345821}],"checksum":1228936672,"timestamp":"2024-06-01T22:42:35.799534Z"}]}
{"channel":"book","type":"update","data":[{"symbol":"SOL/ETH","bids":[{"price":0.043573,"qty":0.00000000},{"price":0.043512,"qty":0.32018436},{"price":0.043584,"qty":1.60791087}],"asks":[],"checksum":2882645910,"timestamp":"2024-06-01T22:42:35.806548Z"}]}
{"channel":"book","type":"update","data":[{"symbol":"SOL/ETH","bids":[],"asks":[{"price":0.043875,"qty":0.00000000},{"price":0.043876,"qty":59.55460368}],"checksum":4168605473,"timestamp":"2024-06-01T22:42:35.821738Z"}]}
{"channel":"book","type":"update","data":[{"symbol":"SOL/ETH","bids":[{"price":0.043584,"qty":0.00000000},{"price":0.043512,"qty":0.32018436}],"asks":[],"checksum":752717986,"timestamp":"2024-06-01T22:42:35.825649Z"}]}
{"channel":"book","type":"update","data":[{"symbol":"SOL/ETH","bids":[{"price":0.043571,"qty":0.00000000},{"price":0.043499,"qty":0.60952872}],"asks":[],"checksum":2960221029,"timestamp":"2024-06-01T22:42:35.876588Z"}]}
{"channel":"book","type":"update","data":[{"symbol":"SOL/ETH","bids":[{"price":0.043573,"qty":1.60831678}],"asks":[],"checksum":85591059,"timestamp":"2024-06-01T22:42:35.889103Z"}]}
{"channel":"book","type":"update","data":[{"symbol":"SOL/ETH","bids":[{"price":0.043573,"qty":0.00000000},{"price":0.043499,"qty":0.60952872},{"price":0.043584,"qty":1.60791087}],"asks":[],"checksum":900383079,"timestamp":"2024-06-01T22:42:35.917786Z"}]}
{"channel":"book","type":"update","data":[{"symbol":"SOL/ETH","bids":[{"price":0.043572,"qty":0.00000000},{"price":0.043499,"qty":0.60952872},{"price":0.043532,"qty":194.97725180}],"asks":[],"checksum":1473176755,"timestamp":"2024-06-01T22:42:35.943477Z"}]}
{"channel":"book","type":"update","data":[{"symbol":"SOL/ETH","bids":[],"asks":[{"price":0.043769,"qty":50.21207900}],"checksum":2252182763,"timestamp":"2024-06-01T22:42:35.955662Z"}]}
{"channel":"book","type":"update","data":[{"symbol":"SOL/ETH","bids":[],"asks":[{"price":0.043769,"qty":0.00000000},{"price":0.043876,"qty":59.55460368}],"checksum":1473176755,"timestamp":"2024-06-01T22:42:35.961777Z"}]}
{"channel":"book","type":"update","data":[{"symbol":"SOL/ETH","bids":[{"price":0.043550,"qty":0.00000000},{"price":0.043499,"qty":0.60952872}],"asks":[],"checksum":2825205702,"timestamp":"2024-06-01T22:42:35.967188Z"}]}
{"channel":"book","type":"update","data":[{"symbol":"SOL/ETH","bids":[{"price":0.043550,"qty":0.46471467}],"asks":[],"checksum":4022120913,"timestamp":"2024-06-01T22:42:35.967242Z"}]}
{"channel":"book","type":"update","data":[{"symbol":"SOL/ETH","bids":[],"asks":[{"price":0.043875,"qty":5.17519102}],"checksum":1186213426,"timestamp":"2024-06-01T22:42:35.977043Z"}]}
{"channel":"book","type":"update","data":[{"symbol":"SOL/ETH","bids":[{"price":0.043567,"qty":74.67565166}],"asks":[],"checksum":631994534,"timestamp":"2024-06-01T22:42:35.989368Z"}]}
{"channel":"book","type":"update","data":[{"symbol":"SOL/ETH","bids":[{"price":0.043584,"qty":0.00000000},{"price":0.043499,"qty":0.60952872},{"price":0.043533,"qty":1.60979458}],"asks":[],"checksum":997591637,"timestamp":"2024-06-01T22:42:35.994653Z"}]}
{"channel":"book","type":"update","data":[{"symbol":"SOL/ETH","bids":[],"asks":[{"price":0.043875,"qty":0.00000000},{"price":0.043876,"qty":59.55460368}],"checksum":2457769398,"timestamp":"2024-06-01T22:42:36.003548Z"}]}
{"channel":"book","type":"update","data":[{"symbol":"SOL/ETH","bids":[{"price":0.043598,"qty":30.02230065}],"asks":[],"checksum":2373515468,"timestamp":"2024-06-01T22:42:36.018146Z"}]}
{"channel":"book","type":"update","data":[{"symbol":"SOL/ETH","bids":[{"price":0.043591,"qty":30.02696095}],"asks":[],"checksum":3320745060,"timestamp":"2024-06-01T22:42:36.018161Z"}]}
{"channel":"book","type":"update","data":[{"symbol":"SOL/ETH","bids":[{"price":0.043567,"qty":14.59000000}],"asks":[],"checksum":367179241,"timestamp":"2024-06-01T22:42:36.020193Z"}]}
{"channel":"book","type":"update","data":[{"symbol":"SOL/ETH","bids":[],"asks":[{"price":0.043622,"qty":120.02528622}],"checksum":2933025374,"timestamp":"2024-06-01T22:42:36.020254Z"}]}
{"channel":"book","type":"update","data":[{"symbol":"SOL/ETH","bids":[{"price":0.043532,"qty":0.00000000},{"price":0.043531,"qty":9.21989450},{"price":0.043550,"qty":195.49376587}],"asks":[],"checksum":1001959210,"timestamp":"2024-06-01T22:42:36.021576Z"}]}
{"channel":"book","type":"update","data":[{"symbol":"SOL/ETH","bids":[{"price":0.043591,"qty":0.00000000},{"price":0.043512,"qty":0.32018436}],"asks":[],"checksum":1908090486,"timestamp":"2024-06-01T22:42:36.023028Z"}]}
{"channel":"book","type":"update","data":[{"symbol":"SOL/ETH","bids":[{"price":0.043533,"qty":0.00000000},{"price":0.043499,"qty":0.60952872}],"asks":[],"checksum":1497898025,"timestamp":"2024-06-01T22:42:36.043434Z"}]}
{"channel":"book","type":"update","data":[{"symbol":"SOL/ETH","bids":[],"asks":[{"price":0.043875,"qty":5.17519102}],"checksum":3140329857,"timestamp":"2024-06-01T22:42:36.107576Z"}]}
{"channel":"book","type":"update","data":[{"symbol":"SOL/ETH","bids":[],"asks":[{"price":0.043775,"qty":49.59679400}],"checksum":1872269419,"timestamp":"2024-06-01T22:42:36.157821Z"}]}
{"channel":"book","type":"update","data":[{"symbol":"SOL/ETH","bids":[],"asks":[{"price":0.043775,"qty":0.00000000},{"price":0.043875,"qty":5.17519102}],"checksum":3140329857,"timestamp":"2024-06-01T22:42:36.163644Z"}]}
{"channel":"book","type":"update","data":[{"symbol":"SOL/ETH","bids":[{"price":0.043599,"qty":1.60735767}],"asks":[],"checksum":1410124884,"timestamp":"2024-06-01T22:42:36.271866Z"}]}
{"channel":"book","type":"update","data":[{"symbol":"SOL/ETH","bids":[{"price":0.043600,"qty":30.02048686}],"asks":[],"checksum":3791904030,"timestamp":"2024-06-01T22:42:36.279263Z"}]}
{"channel":"book","type":"update","data":[{"symbol":"SOL/ETH","bids":[{"price":0.043590,"qty":60.05518546}],"asks":[],"checksum":1115209954,"timestamp":"2024-06-01T22:42:36.279334Z"}]}
{"channel":"book","type":"update","data":[{"symbol":"SOL/ETH","bids":[],"asks":[{"price":0.043635,"qty":59.99457699}],"checksum":2276670432,"timestamp":"2024-06-01T22:42:36.279551Z"}]}
