{"channel":"book","type":"snapshot","data":[{"symbol":"SOL/USD","bids":[{"price":166.70,"qty":0.18317697},{"price":166.68,"qty":7.28629666},{"price":166.67,"qty":55.64101442},{"price":166.64,"qty":11.54402453},{"price":166.63,"qty":14.97384924},{"price":166.62,"qty":23.96931927},{"price":166.61,"qty":14.97379718},{"price":166.60,"qty":0.33144837},{"price":166.58,"qty":42.27454588},{"price":166.57,"qty":75.00669763}],"asks":[{"price":166.71,"qty":1138.54226074},{"price":166.72,"qty":117.01294696},{"price":166.73,"qty":23.40021459},{"price":166.74,"qty":189.56650112},{"price":166.75,"qty":482.93269480},{"price":166.76,"qty":71.99449109},{"price":166.79,"qty":346.43908207},{"price":166.80,"qty":457.54877963},{"price":166.81,"qty":571.87076828},{"price":166.84,"qty":0.17675237}],"checksum":738969666}]}
{"channel":"book","type":"update","data":[{"symbol":"SOL/USD","bids":[{"price":166.57,"qty":44.98968434}],"asks":[],"checksum":1415067713,"timestamp":"2024-06-01T22:42:23.221892Z"}]}
{"channel":"book","type":"update","data":[{"symbol":"SOL/USD","bids":[{"price":166.58,"qty":72.29008786}],"asks":[],"checksum":1458285433,"timestamp":"2024-06-01T22:42:23.224952Z"}]}
{"channel":"book","type":"update","data":[{"symbol":"SOL/USD","bids":[],"asks":[{"price":166.71,"qty":1119.31067690}],"checksum":1011560141,"timestamp":"2024-06-01T22:42:23.229508Z"}]}
{"channel":"book","type":"update","data":[{"symbol":"SOL/USD","bids":[],"asks":[{"price":166.74,"qty":207.61566604}],"checksum":592487370,"timestamp":"2024-06-01T22:42:23.709225Z"}]}
{"channel":"book","type":"update","data":[{"symbol":"SOL/USD","bids":[{"price":166.58,"qty":42.27454588}],"asks":[],"checksum":568537330,"timestamp":"2024-06-01T22:42:24.096277Z"}]}
{"channel":"book","type":"update","data":[{"symbol":"SOL/USD","bids":[{"price":166.57,"qty":75.00564856}],"asks":[],"checksum":2102758131,"timestamp":"2024-06-01T22:42:24.101012Z"}]}
{"channel":"book","type":"update","data":[{"symbol":"SOL/USD","bids":[],"asks":[{"price":166.71,"qty":1089.34067690}],"checksum":631055610,"timestamp":"2024-06-01T22:42:24.155784Z"}]}
{"channel":"book","type":"update","data":[{"symbol":"SOL/USD","bids":[],"asks":[{"price":166.74,"qty":237.58566604}],"checksum":3602808360,"timestamp":"2024-06-01T22:42:24.161044Z"}]}
{"channel":"book","type":"update","data":[{"symbol":"SOL/USD","bids":[{"price":166.57,"qty":44.98968434}],"asks":[],"checksum":2315830313,"timestamp":"2024-06-01T22:42:24.161368Z"}]}
{"channel":"book","type":"update","data":[{"symbol":"SOL/USD","bids":[],"asks":[{"price":166.71,"qty":1073.03237179}],"checksum":3199537531,"timestamp":"2024-06-01T22:42:24.181948Z"}]}
{"channel":"book","type":"update","data":[{"symbol":"SOL/USD","bids":[],"asks":[{"price":166.75,"qty":453.00269480}],"checksum":2857714562,"timestamp":"2024-06-01T22:42:24.200633Z"}]}
{"channel":"book","type":"update","data":[{"symbol":"SOL/USD","bids":[],"asks":[{"price":166.78,"qty":29.99000000}],"checksum":4136135484,"timestamp":"2024-06-01T22:42:24.204775Z"}]}
{"channel":"book","type":"update","data":[{"symbol":"SOL/USD","bids":[{"price":166.58,"qty":72.28959038}],"asks":[],"checksum":3514150590,"timestamp":"2024-06-01T22:42:24.218065Z"}]}
{"channel":"book","type":"update","data":[{"symbol":"SOL/USD","bids":[],"asks":[{"price":166.71,"qty":964.97070219}],"checksum":3467499639,"timestamp":"2024-06-01T22:42:24.246113Z"}]}
{"channel":"book","type":"update","data":[{"symbol":"SOL/USD","bids":[],"asks":[{"price":166.72,"qty":225.06264576}],"checksum":2350634771,"timestamp":"2024-06-01T22:42:24.246365Z"}]}
{"channel":"book","type":"update","data":[{"symbol":"SOL/USD","bids":[],"asks":[{"price":166.79,"qty":158.68908207}],"checksum":2212905000,"timestamp":"2024-06-01T22:42:24.250611Z"}]}
{"channel":"book","type":"update","data":[{"symbol":"SOL/USD","bids":[],"asks":[{"price":166.75,"qty":333.25269480}],"checksum":3701427904,"timestamp":"2024-06-01T22:42:24.255387Z"}]}
{"channel":"book","type":"update","data":[{"symbol":"SOL/USD","bids":[{"price":166.57,"qty":14.97379718}],"asks":[],"checksum":3514763310,"timestamp":"2024-06-01T22:42:24.321997Z"}]}
{"channel":"book","type":"update","data":[{"symbol":"SOL/USD","bids":[{"price":166.58,"qty":102.30391242}],"asks":[],"checksum":3858917562,"timestamp":"2024-06-01T22:42:24.325168Z"}]}
{"channel":"book","type":"update","data":[{"symbol":"SOL/USD","bids":[],"asks":[{"price":166.75,"qty":453.00269480}],"checksum":1217166334,"timestamp":"2024-06-01T22:42:24.328456Z"}]}
{"channel":"book","type":"update","data":[{"symbol":"SOL/USD","bids":[],"asks":[{"price":166.72,"qty":201.05662577}],"checksum":3153851089,"timestamp":"2024-06-01T22:42:24.339265Z"}]}
{"channel":"book","type":"update","data":[{"symbol":"SOL/USD","bids":[],"asks":[{"price":166.81,"qty":759.62076828}],"checksum":469255771,"timestamp":"2024-06-01T22:42:24.347145Z"}]}
{"channel":"book","type":"update","data":[{"symbol":"SOL/USD","bids":[{"price":166.58,"qty":72.28886792}],"asks":[],"checksum":68022232,"timestamp":"2024-06-01T22:42:24.480480Z"}]}
{"channel":"book","type":"update","data":[{"symbol":"SOL/USD","bids":[{"price":166.59,"qty":30.01369177}],"asks":[],"checksum":1841763405,"timestamp":"2024-06-01T22:42:24.484564Z"}]}
{"channel":"book","type":"update","data":[{"symbol":"SOL/USD","bids":[{"price":166.59,"qty":0.00000000},{"price":166.57,"qty":14.97379718}],"asks":[],"checksum":68022232,"timestamp":"2024-06-01T22:42:24.488554Z"}]}
{"channel":"book","type":"update","data":[{"symbol":"SOL/USD","bids":[{"price":166.58,"qty":102.30324098}],"asks":[],"checksum":4107870756,"timestamp":"2024-06-01T22:42:24.586738Z"}]}
{"channel":"book","type":"update","data":[{"symbol":"SOL/USD","bids":[],"asks":[{"price":166.73,"qty":1.17264119}],"checksum":4023582127,"timestamp":"2024-06-01T22:42:24.588234Z"}]}
{"channel":"book","type":"update","data":[{"symbol":"SOL/USD","bids":[],"asks":[{"price":166.71,"qty":965.91065993}],"checksum":955050459,"timestamp":"2024-06-01T22:42:24.588918Z"}]}
{"channel":"book","type":"update","data":[{"symbol":"SOL/USD","bids":[],"asks":[{"price":166.73,"qty":22.22828785}],"checksum":421463227,"timestamp":"2024-06-01T22:42:24.589203Z"}]}
{"channel":"book","type":"update","data":[{"symbol":"SOL/USD","bids":[],"asks":[{"price":166.73,"qty":46.23339282}],"checksum":198154579,"timestamp":"2024-06-01T22:42:24.767219Z"}]}
{"channel":"book","type":"update","data":[{"symbol":"SOL/USD","bids":[],"asks":[{"price":166.71,"qty":982.21896504}],"checksum":3006960393,"timestamp":"2024-06-01T22:42:25.328675Z"}]}
{"channel":"book","type":"update","data":[{"symbol":"SOL/USD","bids":[],"asks":[{"price":166.71,"qty":965.91065993}],"checksum":198154579,"timestamp":"2024-06-01T22:42:25.628649Z"}]}
{"channel":"book","type":"update","data":[{"symbol":"SOL/USD","bids":[],"asks":[{"price":166.71,"qty":982.21896504}],"checksum":3006960393,"timestamp":"2024-06-01T22:42:25.746837Z"}]}
{"channel":"book","type":"update","data":[{"symbol":"SOL/USD","bids":[{"price":166.58,"qty":72.28886792}],"asks":[],"checksum":1433648438,"timestamp":"2024-06-01T22:42:25.790521Z"}]}
{"channel":"book","type":"update","data":[{"symbol":"SOL/USD","bids":[{"price":166.59,"qty":30.01376429}],"asks":[],"checksum":714576107,"timestamp":"2024-06-01T22:42:25.796396Z"}]}
{"channel":"book","type":"update","data":[{"symbol":"SOL/USD","bids":[],"asks":[{"price":166.71,"qty":982.01896504}],"checksum":463376276,"timestamp":"2024-06-01T22:42:25.993300Z"}]}
{"channel":"book","type":"update","data":[{"symbol":"SOL/USD","bids":[],"asks":[{"price":166.71,"qty":981.81896504}],"checksum":2138318083,"timestamp":"2024-06-01T22:42:25.997246Z"}]}
{"channel":"book","type":"update","data":[{"symbol":"SOL/USD","bids":[],"asks":[{"price":166.74,"qty":237.78566604}],"checksum":1748239,"timestamp":"2024-06-01T22:42:25.997373Z"}]}
{"channel":"book","type":"update","data":[{"symbol":"SOL/USD","bids":[],"asks":[{"price":166.71,"qty":904.65251701}],"checksum":196339289,"timestamp":"2024-06-01T22:42:25.997455Z"}]}
{"channel":"book","type":"update","data":[{"symbol":"SOL/USD","bids":[],"asks":[{"price":166.73,"qty":123.39984085}],"checksum":1020025692,"timestamp":"2024-06-01T22:42:25.997567Z"}]}
{"channel":"book","type":"update","data":[{"symbol":"SOL/USD","bids":[],"asks":[{"price":166.71,"qty":904.45251701}],"checksum":4232527598,"timestamp":"2024-06-01T22:42:26.003658Z"}]}
{"channel":"book","type":"update","data":[{"symbol":"SOL/USD","bids":[],"asks":[{"price":166.73,"qty":123.59984085}],"checksum":570793371,"timestamp":"2024-06-01T22:42:26.003709Z"}]}
{"channel":"book","type":"update","data":[{"symbol":"SOL/USD","bids":[{"price":166.59,"qty":0.00000000},{"price":166.57,"qty":14.97379718}],"asks":[],"checksum":1575071814,"timestamp":"2024-06-01T22:42:26.012277Z"}]}
{"channel":"book","type":"update","data":[{"symbol":"SOL/USD","bids":[{"price":166.58,"qty":102.30335252}],"asks":[],"checksum":902656728,"timestamp":"2024-06-01T22:42:26.015654Z"}]}
{"channel":"book","type":"update","data":[{"symbol":"SOL/USD","bids":[],"asks":[{"price":166.71,"qty":888.14421190}],"checksum":2543632428,"timestamp":"2024-06-01T22:42:26.018642Z"}]}
{"channel":"book","type":"update","data":[{"symbol":"SOL/USD","bids":[],"asks":[{"price":166.76,"qty":42.00449109}],"checksum":1644822787,"timestamp":"2024-06-01T22:42:26.034494Z"}]}
{"channel":"book","type":"update","data":[{"symbol":"SOL/USD","bids":[],"asks":[{"price":166.74,"qty":207.81566604}],"checksum":981658568,"timestamp":"2024-06-01T22:42:26.044602Z"}]}
{"channel":"book","type":"update","data":[{"symbol":"SOL/USD","bids":[],"asks":[{"price":166.79,"qty":188.67908207}],"checksum":2523718532,"timestamp":"2024-06-01T22:42:26.044787Z"}]}
{"channel":"book","type":"update","data":[{"symbol":"SOL/USD","bids":[{"price":166.58,"qty":72.28886792}],"asks":[],"checksum":1081120804,"timestamp":"2024-06-01T22:42:26.048620Z"}]}
{"channel":"book","type":"update","data":[{"symbol":"SOL/USD","bids":[],"asks":[{"price":166.76,"qty":71.97449109}],"checksum":903022945,"timestamp":"2024-06-01T22:42:26.051465Z"}]}
{"channel":"book","type":"update","data":[{"symbol":"SOL/USD","bids":[],"asks":[{"price":166.71,"qty":882.55021190}],"checksum":3870938966,"timestamp":"2024-06-01T22:42:26.054208Z"}]}
{"channel":"book","type":"update","data":[{"symbol":"SOL/USD","bids":[],"asks":[{"price":166.73,"qty":122.42719966}],"checksum":3840770772,"timestamp":"2024-06-01T22:42:26.054986Z"}]}
{"channel":"book","type":"update","data":[{"symbol":"SOL/USD","bids":[{"price":166.58,"qty":42.27454588}],"asks":[],"checksum":2394241978,"timestamp":"2024-06-01T22:42:26.082630Z"}]}
{"channel":"book","type":"update","data":[{"symbol":"SOL/USD","bids":[],"asks":[{"price":166.71,"qty":782.55021190}],"checksum":384749326,"timestamp":"2024-06-01T22:42:26.084981Z"}]}
{"channel":"book","type":"update","data":[{"symbol":"SOL/USD","bids":[{"price":166.59,"qty":30.01238190}],"asks":[],"checksum":142431573,"timestamp":"2024-06-01T22:42:26.122067Z"}]}
{"channel":"book","type":"update","data":[{"symbol":"SOL/USD","bids":[],"asks":[{"price":166.81,"qty":717.34622240}],"checksum":2851937997,"timestamp":"2024-06-01T22:42:26.139348Z"}]}
{"channel":"book","type":"update","data":[{"symbol":"SOL/USD","bids":[{"price":166.59,"qty":38.15530540}],"asks":[],"checksum":3312628846,"timestamp":"2024-06-01T22:42:26.146915Z"}]}
{"channel":"book","type":"update","data":[{"symbol":"SOL/USD","bids":[],"asks":[{"price":166.71,"qty":788.14021190}],"checksum":3644541701,"timestamp":"2024-06-01T22:42:26.152864Z"}]}
{"channel":"book","type":"update","data":[{"symbol":"SOL/USD","bids":[],"asks":[{"price":166.75,"qty":454.17533599}],"checksum":1484152119,"timestamp":"2024-06-01T22:42:26.154945Z"}]}
{"channel":"book","type":"update","data":[{"symbol":"SOL/USD","bids":[],"asks":[{"price":166.72,"qty":93.00692697}],"checksum":1874391591,"timestamp":"2024-06-01T22:42:26.160814Z"}]}
{"channel":"book","type":"update","data":[{"symbol":"SOL/USD","bids":[],"asks":[{"price":166.74,"qty":315.85239694}],"checksum":2981067132,"timestamp":"2024-06-01T22:42:26.161069Z"}]}
{"channel":"book","type":"update","data":[{"symbol":"SOL/USD","bids":[],"asks":[{"price":166.73,"qty":98.42209469}],"checksum":2244954184,"timestamp":"2024-06-01T22:42:26.163199Z"}]}
{"channel":"book","type":"update","data":[{"symbol":"SOL/USD","bids":[],"asks":[{"price":166.71,"qty":804.44851701}],"checksum":1850812260,"timestamp":"2024-06-01T22:42:26.172905Z"}]}
{"channel":"book","type":"update","data":[{"symbol":"SOL/USD","bids":[{"price":166.58,"qty":74.17454588}],"asks":[],"checksum":2029249038,"timestamp":"2024-06-01T22:42:26.182166Z"}]}
{"channel":"book","type":"update","data":[{"symbol":"SOL/USD","bids":[{"price":166.58,"qty":31.90000000}],"asks":[],"checksum":823638240,"timestamp":"2024-06-01T22:42:26.189960Z"}]}
{"channel":"book","type":"update","data":[{"symbol":"SOL/USD","bids":[{"price":166.59,"qty":30.01238190}],"asks":[],"checksum":1570247235,"timestamp":"2024-06-01T22:42:26.224648Z"}]}
{"channel":"book","type":"update","data":[{"symbol":"SOL/USD","bids":[{"price":166.60,"qty":30.34314905}],"asks":[],"checksum":1833611819,"timestamp":"2024-06-01T22:42:26.233253Z"}]}
{"channel":"book","type":"update","data":[{"symbol":"SOL/USD","bids":[{"price":166.60,"qty":72.61769493}],"asks":[],"checksum":3757054306,"timestamp":"2024-06-01T22:42:26.240445Z"}]}
{"channel":"book","type":"update","data":[{"symbol":"SOL/USD","bids":[],"asks":[{"price":166.75,"qty":449.05248004}],"checksum":2447017802,"timestamp":"2024-06-01T22:42:26.346459Z"}]}
{"channel":"book","type":"update","data":[{"symbol":"SOL/USD","bids":[],"asks":[{"price":166.73,"qty":98.62209469}],"checksum":2594707499,"timestamp":"2024-06-01T22:42:26.381466Z"}]}
{"channel":"book","type":"update","data":[{"symbol":"SOL/USD","bids":[{"price":166.60,"qty":42.60599425}],"asks":[],"checksum":69440100,"timestamp":"2024-06-01T22:42:26.459109Z"}]}
{"channel":"book","type":"update","data":[{"symbol":"SOL/USD","bids":[{"price":166.59,"qty":60.02514494}],"asks":[],"checksum":273033218,"timestamp":"2024-06-01T22:42:26.462509Z"}]}
{"channel":"book","type":"update","data":[{"symbol":"SOL/USD","bids":[],"asks":[{"price":166.74,"qty":339.85581128}],"checksum":2740499399,"timestamp":"2024-06-01T22:42:26.469829Z"}]}
{"channel":"book","type":"update","data":[{"symbol":"SOL/USD","bids":[],"asks":[{"price":166.80,"qty":27.54877963}],"checksum":4176367153,"timestamp":"2024-06-01T22:42:26.868595Z"}]}
{"channel":"book","type":"update","data":[{"symbol":"SOL/USD","bids":[{"price":166.59,"qty":30.01238190}],"asks":[],"checksum":3968595031,"timestamp":"2024-06-01T22:42:27.012499Z"}]}
{"channel":"book","type":"update","data":[{"symbol":"SOL/USD","bids":[{"price":166.59,"qty":60.02561912}],"asks":[],"checksum":1628081289,"timestamp":"2024-06-01T22:42:27.078001Z"}]}
{"channel":"book","type":"update","data":[{"symbol":"SOL/USD","bids":[],"asks":[{"price":166.71,"qty":803.50855927}],"checksum":3616277078,"timestamp":"2024-06-01T22:42:27.385987Z"}]}
{"channel":"book","type":"update","data":[{"symbol":"SOL/USD","bids":[],"asks":[{"price":166.73,"qty":77.56644803}],"checksum":1662208067,"timestamp":"2024-06-01T22:42:27.386131Z"}]}
{"channel":"book","type":"update","data":[{"symbol":"SOL/USD","bids":[],"asks":[{"price":166.73,"qty":99.51955779}],"checksum":922243668,"timestamp":"2024-06-01T22:42:27.387221Z"}]}
{"channel":"book","type":"update","data":[{"symbol":"SOL/USD","bids":[],"asks":[{"price":166.74,"qty":321.80664636}],"checksum":4006773034,"timestamp":"2024-06-01T22:42:27.598268Z"}]}
{"channel":"book","type":"update","data":[{"symbol":"SOL/USD","bids":[{"price":166.58,"qty":40.04292350}],"asks":[],"checksum":1704325317,"timestamp":"2024-06-01T22:42:27.598946Z"}]}
{"channel":"book","type":"update","data":[{"symbol":"SOL/USD","bids":[],"asks":[{"price":166.71,"qty":803.30855927}],"checksum":915329348,"timestamp":"2024-06-01T22:42:27.603819Z"}]}
{"channel":"book","type":"update","data":[{"symbol":"SOL/USD","bids":[],"asks":[{"price":166.73,"qty":99.71955779}],"checksum":2681115019,"timestamp":"2024-06-01T22:42:27.603849Z"}]}
{"channel":"book","type":"update","data":[{"symbol":"SOL/USD","bids":[{"price":166.59,"qty":30.01238190}],"asks":[],"checksum":307226965,"timestamp":"2024-06-01T22:42:27.616795Z"}]}
{"channel":"book","type":"update","data":[{"symbol":"SOL/USD","bids":[],"asks":[{"price":166.71,"qty":787.00025416}],"checksum":1397039560,"timestamp":"2024-06-01T22:42:27.620400Z"}]}
{"channel":"book","type":"update","data":[{"symbol":"SOL/USD","bids":[],"asks":[{"price":166.77,"qty":18.56478789}],"checksum":3422059000,"timestamp":"2024-06-01T22:42:27.725885Z"}]}
{"channel":"book","type":"update","data":[{"symbol":"SOL/USD","bids":[{"price":166.59,"qty":60.02589981}],"asks":[],"checksum":509503467,"timestamp":"2024-06-01T22:42:27.726377Z"}]}
{"channel":"book","type":"update","data":[{"symbol":"SOL/USD","bids":[],"asks":[{"price":166.71,"qty":803.30855927}],"checksum":283941440,"timestamp":"2024-06-01T22:42:27.742057Z"}]}
{"channel":"book","type":"update","data":[{"symbol":"SOL/USD","bids":[{"price":166.59,"qty":30.01238190}],"asks":[],"checksum":3309995091,"timestamp":"2024-06-01T22:42:28.009920Z"}]}
{"channel":"book","type":"update","data":[{"symbol":"SOL/USD","bids":[],"asks":[{"price":166.71,"qty":798.22353322},{"price":166.71,"qty":802.74680012}],"checksum":3262927837,"timestamp":"2024-06-01T22:42:28.052843Z"}]}
{"channel":"book","type":"update","data":[{"symbol":"SOL/USD","bids":[],"asks":[{"price":166.74,"qty":138.50052361}],"checksum":3763803774,"timestamp":"2024-06-01T22:42:28.613456Z"}]}
{"channel":"book","type":"update","data":[{"symbol":"SOL/USD","bids":[],"asks":[{"price":166.74,"qty":175.10093012}],"checksum":1320271554,"timestamp":"2024-06-01T22:42:28.614067Z"}]}
{"channel":"book","type":"update","data":[{"symbol":"SOL/USD","bids":[],"asks":[{"price":166.73,"qty":240.55821513}],"checksum":3547322295,"timestamp":"2024-06-01T22:42:28.614119Z"}]}
{"channel":"book","type":"update","data":[{"symbol":"SOL/USD","bids":[{"price":166.59,"qty":60.02580699}],"asks":[],"checksum":3661669405,"timestamp":"2024-06-01T22:42:29.139613Z"}]}
{"channel":"book","type":"update","data":[{"symbol":"SOL/USD","bids":[{"price":166.59,"qty":30.01238190}],"asks":[],"checksum":3547322295,"timestamp":"2024-06-01T22:42:29.196835Z"}]}
{"channel":"book","type":"update","data":[{"symbol":"SOL/USD","bids":[],"asks":[{"price":166.73,"qty":218.60510537}],"checksum":3853467811,"timestamp":"2024-06-01T22:42:30.152083Z"}]}
{"channel":"book","type":"update","data":[{"symbol":"SOL/USD","bids":[],"asks":[{"price":166.72,"qty":110.10956785}],"checksum":820001259,"timestamp":"2024-06-01T22:42:30.153109Z"}]}
{"channel":"book","type":"update","data":[{"symbol":"SOL/USD","bids":[],"asks":[{"price":166.73,"qty":223.28927115}],"checksum":4158642902,"timestamp":"2024-06-01T22:42:30.153206Z"}]}
{"channel":"book","type":"update","data":[{"symbol":"SOL/USD","bids":[{"price":166.58,"qty":8.14292350}],"asks":[],"checksum":1028407336,"timestamp":"2024-06-01T22:42:32.428370Z"}]}
{"channel":"book","type":"update","data":[{"symbol":"SOL/USD","bids":[],"asks":[{"price":166.74,"qty":67.06419922}],"checksum":3279377833,"timestamp":"2024-06-01T22:42:32.430429Z"}]}
{"channel":"book","type":"update","data":[{"symbol":"SOL/USD","bids":[],"asks":[{"price":166.73,"qty":331.33148601}],"checksum":1773644910,"timestamp":"2024-06-01T22:42:32.430463Z"}]}
{"channel":"book","type":"update","data":[{"symbol":"SOL/USD","bids":[],"asks":[{"price":166.80,"qty":457.54877963}],"checksum":4015448579,"timestamp":"2024-06-01T22:42:32.869173Z"}]}
{"channel":"book","type":"update","data":[{"symbol":"SOL/USD","bids":[],"asks":[{"price":166.72,"qty":93.00692697}],"checksum":3228454433,"timestamp":"2024-06-01T22:42:32.882914Z"}]}
{"channel":"book","type":"update","data":[{"symbol":"SOL/USD","bids":[],"asks":[{"price":166.73,"qty":326.64732023}],"checksum":463310934,"timestamp":"2024-06-01T22:42:32.883173Z"}]}
{"channel":"book","type":"update","data":[{"symbol":"SOL/USD","bids":[],"asks":[{"price":166.72,"qty":110.46093176}],"checksum":1263390225,"timestamp":"2024-06-01T22:42:32.885730Z"}]}
{"channel":"book","type":"update","data":[{"symbol":"SOL/USD","bids":[],"asks":[{"price":166.74,"qty":71.42879770}],"checksum":1656883415,"timestamp":"2024-06-01T22:42:32.886018Z"}]}
{"channel":"book","type":"update","data":[{"symbol":"SOL/USD","bids":[],"asks":[{"price":166.71,"qty":466.01835772}],"checksum":231419672,"timestamp":"2024-06-01T22:42:32.920290Z"}]}
{"channel":"book","type":"update","data":[{"symbol":"SOL/USD","bids":[],"asks":[{"price":166.74,"qty":408.15724010}],"checksum":2666062587,"timestamp":"2024-06-01T22:42:32.923152Z"}]}
{"channel":"book","type":"update","data":[{"symbol":"SOL/USD","bids":[],"asks":[{"price":166.74,"qty":371.55683359}],"checksum":2152146536,"timestamp":"2024-06-01T22:42:33.211484Z"}]}
{"channel":"book","type":"update","data":[{"symbol":"SOL/USD","bids":[],"asks":[{"price":166.73,"qty":185.80866289}],"checksum":3372318136,"timestamp":"2024-06-01T22:42:33.211670Z"}]}
{"channel":"book","type":"update","data":[{"symbol":"SOL/USD","bids":[],"asks":[{"price":166.71,"qty":571.72062481}],"checksum":1415528949,"timestamp":"2024-06-01T22:42:33.212089Z"}]}
{"channel":"book","type":"update","data":[{"symbol":"SOL/USD","bids":[],"asks":[{"price":166.72,"qty":192.14846403}],"checksum":340132015,"timestamp":"2024-06-01T22:42:33.212337Z"}]}
{"channel":"book","type":"update","data":[{"symbol":"SOL/USD","bids":[],"asks":[{"price":166.76,"qty":54.40449109}],"checksum":3015531107,"timestamp":"2024-06-01T22:42:34.092545Z"}]}
{"channel":"book","type":"update","data":[{"symbol":"SOL/USD","bids":[{"price":166.59,"qty":0.00000000},{"price":166.57,"qty":413.61812243}],"asks":[],"checksum":2660068512,"timestamp":"2024-06-01T22:42:34.343971Z"}]}
{"channel":"book","type":"update","data":[{"symbol":"SOL/USD","bids":[{"price":166.58,"qty":38.15715551}],"asks":[],"checksum":3336178919,"timestamp":"2024-06-01T22:42:34.348447Z"}]}
{"channel":"book","type":"update","data":[{"symbol":"SOL/USD","bids":[],"asks":[{"price":166.71,"qty":571.92062481}],"checksum":983287830,"timestamp":"2024-06-01T22:42:34.456698Z"}]}
{"channel":"book","type":"update","data":[{"symbol":"SOL/USD","bids":[],"asks":[{"price":166.71,"qty":649.08707284}],"checksum":1059570008,"timestamp":"2024-06-01T22:42:34.711595Z"}]}
{"channel":"book","type":"update","data":[{"symbol":"SOL/USD","bids":[],"asks":[{"price":166.73,"qty":185.60866289}],"checksum":259661183,"timestamp":"2024-06-01T22:42:34.716332Z"}]}
{"channel":"book","type":"update","data":[{"symbol":"SOL/USD","bids":[],"asks":[{"price":166.71,"qty":649.28707284}],"checksum":3830547481,"timestamp":"2024-06-01T22:42:34.716876Z"}]}
{"channel":"book","type":"update","data":[{"symbol":"SOL/USD","bids":[],"asks":[{"price":166.73,"qty":185.40866289}],"checksum":4012055416,"timestamp":"2024-06-01T22:42:34.848514Z"}]}
{"channel":"book","type":"update","data":[{"symbol":"SOL/USD","bids":[],"asks":[{"price":166.73,"qty":108.24221486}],"checksum":1277110791,"timestamp":"2024-06-01T22:42:34.852454Z"}]}
{"channel":"book","type":"update","data":[{"symbol":"SOL/USD","bids":[],"asks":[{"price":166.73,"qty":0.20000000}],"checksum":4016115619,"timestamp":"2024-06-01T22:42:34.917107Z"}]}
{"channel":"book","type":"update","data":[{"symbol":"SOL/USD","bids":[],"asks":[{"price":166.74,"qty":479.59357179}],"checksum":531406554,"timestamp":"2024-06-01T22:42:34.917583Z"}]}
{"channel":"book","type":"update","data":[{"symbol":"SOL/USD","bids":[{"price":166.68,"qty":4.34309966}],"asks":[],"checksum":4217049509,"timestamp":"2024-06-01T22:42:35.278529Z"}]}
{"channel":"book","type":"update","data":[{"symbol":"SOL/USD","bids":[],"asks":[{"price":166.71,"qty":543.58480575}],"checksum":397204640,"timestamp":"2024-06-01T22:42:35.432542Z"}]}
{"channel":"book","type":"update","data":[{"symbol":"SOL/USD","bids":[],"asks":[{"price":166.72,"qty":110.46093176}],"checksum":3521568842,"timestamp":"2024-06-01T22:42:35.432816Z"}]}
{"channel":"book","type":"update","data":[{"symbol":"SOL/USD","bids":[],"asks":[{"price":166.72,"qty":93.00692697}],"checksum":3096388427,"timestamp":"2024-06-01T22:42:35.706846Z"}]}
{"channel":"book","type":"update","data":[{"symbol":"SOL/USD","bids":[],"asks":[{"price":166.74,"qty":475.22897331}],"checksum":1051130035,"timestamp":"2024-06-01T22:42:35.706927Z"}]}
{"channel":"book","type":"update","data":[{"symbol":"SOL/USD","bids":[],"asks":[{"price":166.73,"qty":23.18615623}],"checksum":1216191799,"timestamp":"2024-06-01T22:42:35.707552Z"}]}
{"channel":"book","type":"update","data":[{"symbol":"SOL/USD","bids":[{"price":166.58,"qty":30.01423201}],"asks":[],"checksum":2374931182,"timestamp":"2024-06-01T22:42:35.724398Z"}]}
{"channel":"book","type":"update","data":[{"symbol":"SOL/USD","bids":[{"price":166.64,"qty":0.00000000},{"price":166.56,"qty":83.76419286}],"asks":[],"checksum":3376625859,"timestamp":"2024-06-01T22:42:35.727395Z"}]}
{"channel":"book","type":"update","data":[{"symbol":"SOL/USD","bids":[{"price":166.57,"qty":76.88968003}],"asks":[],"checksum":4214834777,"timestamp":"2024-06-01T22:42:35.728169Z"}]}
{"channel":"book","type":"update","data":[{"symbol":"SOL/USD","bids":[],"asks":[{"price":166.77,"qty":0.00000000},{"price":166.81,"qty":717.34622240}],"checksum":1131387676,"timestamp":"2024-06-01T22:42:35.728222Z"}]}
{"channel":"book","type":"update","data":[{"symbol":"SOL/USD","bids":[],"asks":[{"price":166.71,"qty":543.78480575}],"checksum":2212822702,"timestamp":"2024-06-01T22:42:35.728280Z"}]}
{"channel":"book","type":"update","data":[{"symbol":"SOL/USD","bids":[],"asks":[{"price":166.81,"qty":205.26000000}],"checksum":4258638175,"timestamp":"2024-06-01T22:42:35.728727Z"}]}
{"channel":"book","type":"update","data":[{"symbol":"SOL/USD","bids":[],"asks":[{"price":166.74,"qty":138.50053091}],"checksum":2797539965,"timestamp":"2024-06-01T22:42:35.728867Z"}]}
{"channel":"book","type":"update","data":[{"symbol":"SOL/USD","bids":[],"asks":[{"price":166.79,"qty":525.40752447}],"checksum":2304245558,"timestamp":"2024-06-01T22:42:35.731533Z"}]}
{"channel":"book","type":"update","data":[{"symbol":"SOL/USD","bids":[{"price":166.56,"qty":2.22979286}],"asks":[],"checksum":3796027816,"timestamp":"2024-06-01T22:42:35.731698Z"}]}
{"channel":"book","type":"update","data":[{"symbol":"SOL/USD","bids":[],"asks":[{"price":166.73,"qty":95.15880662}],"checksum":3385827619,"timestamp":"2024-06-01T22:42:35.733808Z"}]}
{"channel":"book","type":"update","data":[{"symbol":"SOL/USD","bids":[],"asks":[{"price":166.74,"qty":30.46379271}],"checksum":529203468,"timestamp":"2024-06-01T22:42:35.735619Z"}]}
{"channel":"book","type":"update","data":[{"symbol":"SOL/USD","bids":[],"asks":[{"price":166.71,"qty":651.83325917}],"checksum":1508030474,"timestamp":"2024-06-01T22:42:35.735739Z"}]}
{"channel":"book","type":"update","data":[{"symbol":"SOL/USD","bids":[],"asks":[{"price":166.76,"qty":24.43449109},{"price":166.71,"qty":681.80325917}],"checksum":1672012911,"timestamp":"2024-06-01T22:42:35.738490Z"}]}
{"channel":"book","type":"update","data":[{"symbol":"SOL/USD","bids":[{"price":166.70,"qty":0.00000000},{"price":166.55,"qty":296.64169702}],"asks":[],"checksum":1354507583,"timestamp":"2024-06-01T22:42:35.744673Z"}]}
{"channel":"book","type":"update","data":[{"symbol":"SOL/USD","bids":[{"price":166.57,"qty":46.87379718}],"asks":[],"checksum":3987243301,"timestamp":"2024-06-01T22:42:35.745740Z"}]}
{"channel":"book","type":"update","data":[{"symbol":"SOL/USD","bids":[{"price":166.55,"qty":266.62215709}],"asks":[],"checksum":2529371932,"timestamp":"2024-06-01T22:42:35.745856Z"}]}
{"channel":"book","type":"update","data":[{"symbol":"SOL/USD","bids":[{"price":166.58,"qty":0.00000000},{"price":166.54,"qty":15.85000000}],"asks":[],"checksum":4134140240,"timestamp":"2024-06-01T22:42:35.745967Z"}]}
{"channel":"book","type":"update","data":[{"symbol":"SOL/USD","bids":[],"asks":[{"price":166.79,"qty":375.51844240}],"checksum":1912100970,"timestamp":"2024-06-01T22:42:35.746030Z"}]}
{"channel":"book","type":"update","data":[{"symbol":"SOL/USD","bids":[],"asks":[{"price":166.71,"qty":682.00325917}],"checksum":2046519979,"timestamp":"2024-06-01T22:42:35.746199Z"}]}
{"channel":"book","type":"update","data":[{"symbol":"SOL/USD","bids":[],"asks":[{"price":166.70,"qty":1.06750865}],"checksum":1271798374,"timestamp":"2024-06-01T22:42:35.748836Z"}]}
{"channel":"book","type":"update","data":[{"symbol":"SOL/USD","bids":[],"asks":[{"price":166.71,"qty":658.82326503},{"price":166.69,"qty":23.99664047}],"checksum":4020921757,"timestamp":"2024-06-01T22:42:35.749653Z"}]}
{"channel":"book","type":"update","data":[{"symbol":"SOL/USD","bids":[],"asks":[{"price":166.71,"qty":658.62326503}],"checksum":126462834,"timestamp":"2024-06-01T22:42:35.751473Z"}]}
{"channel":"book","type":"update","data":[{"symbol":"SOL/USD","bids":[],"asks":[{"price":166.69,"qty":33.93995010}],"checksum":2713155398,"timestamp":"2024-06-01T22:42:35.751582Z"}]}
{"channel":"book","type":"update","data":[{"symbol":"SOL/USD","bids":[],"asks":[{"price":166.76,"qty":14.49624910}],"checksum":206442907,"timestamp":"2024-06-01T22:42:35.751677Z"}]}
{"channel":"book","type":"update","data":[{"symbol":"SOL/USD","bids":[],"asks":[{"price":166.71,"qty":642.31495992}],"checksum":817861663,"timestamp":"2024-06-01T22:42:35.751954Z"}]}
{"channel":"book","type":"update","data":[{"symbol":"SOL/USD","bids":[{"price":166.55,"qty":215.21621706}],"asks":[],"checksum":1158147813,"timestamp":"2024-06-01T22:42:35.754450Z"}]}
{"channel":"book","type":"update","data":[{"symbol":"SOL/USD","bids":[],"asks":[{"price":166.71,"qty":642.11495992}],"checksum":3964120618,"timestamp":"2024-06-01T22:42:35.754492Z"}]}
{"channel":"book","type":"update","data":[{"symbol":"SOL/USD","bids":[],"asks":[{"price":166.69,"qty":53.53630060}],"checksum":663899983,"timestamp":"2024-06-01T22:42:35.754994Z"}]}
{"channel":"book","type":"update","data":[{"symbol":"SOL/USD","bids":[],"asks":[{"price":166.73,"qty":94.95880662}],"checksum":2687667038,"timestamp":"2024-06-01T22:42:35.755994Z"}]}
{"channel":"book","type":"update","data":[{"symbol":"SOL/USD","bids":[{"price":166.57,"qty":31.90000000}],"asks":[],"checksum":3803562184,"timestamp":"2024-06-01T22:42:35.757077Z"}]}
{"channel":"book","type":"update","data":[{"symbol":"SOL/USD","bids":[{"price":166.63,"qty":0.00000000},{"price":166.53,"qty":81.53440000}],"asks":[],"checksum":2623862249,"timestamp":"2024-06-01T22:42:35.757432Z"}]}
{"channel":"book","type":"update","data":[{"symbol":"SOL/USD","bids":[{"price":166.61,"qty":0.00000000},{"price":166.52,"qty":126.40372786}],"asks":[],"checksum":280093262,"timestamp":"2024-06-01T22:42:35.757621Z"}]}
{"channel":"book","type":"update","data":[{"symbol":"SOL/USD","bids":[{"price":166.60,"qty":0.33144837}],"asks":[],"checksum":46492064,"timestamp":"2024-06-01T22:42:35.758738Z"}]}
{"channel":"book","type":"update","data":[{"symbol":"SOL/USD","bids":[{"price":166.53,"qty":0.00000000},{"price":166.51,"qty":33.57193252},{"price":166.51,"qty":115.10633252}],"asks":[],"checksum":507617556,"timestamp":"2024-06-01T22:42:35.761211Z"}]}
{"channel":"book","type":"update","data":[{"symbol":"SOL/USD","bids":[],"asks":[{"price":166.71,"qty":641.17411952},{"price":166.69,"qty":54.47653905}],"checksum":1507114697,"timestamp":"2024-06-01T22:42:35.761503Z"}]}
{"channel":"book","type":"update","data":[{"symbol":"SOL/USD","bids":[],"asks":[{"price":166.70,"qty":0.00000000},{"price":166.80,"qty":457.54877963}],"checksum":1737899812,"timestamp":"2024-06-01T22:42:35.762281Z"}]}
{"channel":"book","type":"update","data":[{"symbol":"SOL/USD","bids":[],"asks":[{"price":166.71,"qty":611.18191750}],"checksum":3004347492,"timestamp":"2024-06-01T22:42:35.764256Z"}]}
{"channel":"book","type":"update","data":[{"symbol":"SOL/USD","bids":[],"asks":[{"price":166.71,"qty":551.19751345}],"checksum":1932983550,"timestamp":"2024-06-01T22:42:35.764265Z"}]}
{"channel":"book","type":"update","data":[{"symbol":"SOL/USD","bids":[],"asks":[{"price":166.71,"qty":521.20531143}],"checksum":3259800716,"timestamp":"2024-06-01T22:42:35.764290Z"}]}
{"channel":"book","type":"update","data":[{"symbol":"SOL/USD","bids":[],"asks":[{"price":166.75,"qty":299.12744256}],"checksum":4052030255,"timestamp":"2024-06-01T22:42:35.764301Z"}]}
{"channel":"book","type":"update","data":[{"symbol":"SOL/USD","bids":[],"asks":[{"price":166.71,"qty":461.22090738}],"checksum":2486636535,"timestamp":"2024-06-01T22:42:35.764311Z"}]}
{"channel":"book","type":"update","data":[{"symbol":"SOL/USD","bids":[],"asks":[{"price":166.75,"qty":179.37744256}],"checksum":447488111,"timestamp":"2024-06-01T22:42:35.764909Z"}]}
{"channel":"book","type":"update","data":[{"symbol":"SOL/USD","bids":[],"asks":[{"price":166.69,"qty":174.22653905}],"checksum":1930266384,"timestamp":"2024-06-01T22:42:35.765093Z"}]}
{"channel":"book","type":"update","data":[{"symbol":"SOL/USD","bids":[],"asks":[{"price":166.74,"qty":218.21379271}],"checksum":2277965970,"timestamp":"2024-06-01T22:42:35.769225Z"}]}
{"channel":"book","type":"update","data":[{"symbol":"SOL/USD","bids":[{"price":166.57,"qty":0.00000000},{"price":166.50,"qty":251.27950862}],"asks":[],"checksum":2534396360,"timestamp":"2024-06-01T22:42:35.772730Z"}]}
{"channel":"book","type":"update","data":[{"symbol":"SOL/USD","bids":[],"asks":[{"price":166.69,"qty":251.39298708}],"checksum":75852020,"timestamp":"2024-06-01T22:42:35.774097Z"}]}
{"channel":"book","type":"update","data":[{"symbol":"SOL/USD","bids":[],"asks":[{"price":166.71,"qty":451.03086305}],"checksum":2275048419,"timestamp":"2024-06-01T22:42:35.774119Z"}]}
{"channel":"book","type":"update","data":[{"symbol":"SOL/USD","bids":[],"asks":[{"price":166.71,"qty":446.50759615},{"price":166.70,"qty":4.52327456}],"checksum":1352967837,"timestamp":"2024-06-01T22:42:35.774379Z"}]}
{"channel":"book","type":"update","data":[{"symbol":"SOL/USD","bids":[],"asks":[{"price":166.69,"qty":251.59298708}],"checksum":1045777618,"timestamp":"2024-06-01T22:42:35.776063Z"}]}
{"channel":"book","type":"update","data":[{"symbol":"SOL/USD","bids":[],"asks":[{"price":166.78,"qty":0.00000000},{"price":166.80,"qty":457.54877963},{"price":166.69,"qty":281.58298708}],"checksum":1593783074,"timestamp":"2024-06-01T22:42:35.776850Z"}]}
{"channel":"book","type":"update","data":[{"symbol":"SOL/USD","bids":[{"price":166.50,"qty":283.17950862}],"asks":[],"checksum":192452599,"timestamp":"2024-06-01T22:42:35.777251Z"}]}
{"channel":"book","type":"update","data":[{"symbol":"SOL/USD","bids":[],"asks":[{"price":166.69,"qty":311.59539394}],"checksum":3347026645,"timestamp":"2024-06-01T22:42:35.777741Z"}]}
{"channel":"book","type":"update","data":[{"symbol":"SOL/USD","bids":[],"asks":[{"price":166.69,"qty":311.79539394}],"checksum":743705523,"timestamp":"2024-06-01T22:42:35.778508Z"}]}
{"channel":"book","type":"update","data":[{"symbol":"SOL/USD","bids":[],"asks":[{"price":166.79,"qty":345.52844240},{"price":166.69,"qty":341.78539394}],"checksum":1953854862,"timestamp":"2024-06-01T22:42:35.779457Z"}]}
{"channel":"book","type":"update","data":[{"symbol":"SOL/USD","bids":[{"price":166.62,"qty":0.00000000},{"price":166.49,"qty":313.73622098},{"price":166.54,"qty":39.81931927}],"asks":[],"checksum":946271434,"timestamp":"2024-06-01T22:42:35.781608Z"}]}
{"channel":"book","type":"update","data":[{"symbol":"SOL/USD","bids":[],"asks":[{"price":166.76,"qty":20.07413838}],"checksum":3998108143,"timestamp":"2024-06-01T22:42:35.783205Z"}]}
{"channel":"book","type":"update","data":[{"symbol":"SOL/USD","bids":[{"price":166.50,"qty":313.20908031}],"asks":[],"checksum":2993200754,"timestamp":"2024-06-01T22:42:35.783807Z"}]}
{"channel":"book","type":"update","data":[{"symbol":"SOL/USD","bids":[],"asks":[{"price":166.69,"qty":371.78119452}],"checksum":3185242377,"timestamp":"2024-06-01T22:42:35.783854Z"}]}
{"channel":"book","type":"update","data":[{"symbol":"SOL/USD","bids":[],"asks":[{"price":166.69,"qty":431.77279569}],"checksum":1882636238,"timestamp":"2024-06-01T22:42:35.783894Z"}]}
{"channel":"book","type":"update","data":[{"symbol":"SOL/USD","bids":[{"price":166.49,"qty":343.76690050}],"asks":[],"checksum":3146802569,"timestamp":"2024-06-01T22:42:35.783925Z"}]}
{"channel":"book","type":"update","data":[{"symbol":"SOL/USD","bids":[],"asks":[{"price":166.69,"qty":491.76439686}],"checksum":327339903,"timestamp":"2024-06-01T22:42:35.783951Z"}]}
{"channel":"book","type":"update","data":[{"symbol":"SOL/USD","bids":[],"asks":[{"price":166.69,"qty":521.76019744}],"checksum":1759056800,"timestamp":"2024-06-01T22:42:35.783964Z"}]}
{"channel":"book","type":"update","data":[{"symbol":"SOL/USD","bids":[],"asks":[{"price":166.69,"qty":671.73920037}],"checksum":3693646928,"timestamp":"2024-06-01T22:42:35.784106Z"}]}
{"channel":"book","type":"update","data":[{"symbol":"SOL/USD","bids":[],"asks":[{"price":166.80,"qty":757.31967458}],"checksum":1194909051,"timestamp":"2024-06-01T22:42:35.784367Z"}]}
{"channel":"book","type":"update","data":[{"symbol":"SOL/USD","bids":[],"asks":[{"price":166.69,"qty":821.71820330}],"checksum":3895416312,"timestamp":"2024-06-01T22:42:35.784469Z"}]}
{"channel":"book","type":"update","data":[{"symbol":"SOL/USD","bids":[],"asks":[{"price":166.74,"qty":211.95341434}],"checksum":3352395220,"timestamp":"2024-06-01T22:42:35.790493Z"}]}
{"channel":"book","type":"update","data":[{"symbol":"SOL/USD","bids":[{"price":166.49,"qty":313.73622098}],"asks":[],"checksum":209168275,"timestamp":"2024-06-01T22:42:35.794388Z"}]}
{"channel":"book","type":"update","data":[{"symbol":"SOL/USD","bids":[{"price":166.50,"qty":283.17950862}],"asks":[],"checksum":1347514382,"timestamp":"2024-06-01T22:42:35.794528Z"}]}
{"channel":"book","type":"update","data":[{"symbol":"SOL/USD","bids":[{"price":166.54,"qty":23.96931927}],"asks":[],"checksum":2506397619,"timestamp":"2024-06-01T22:42:35.794572Z"}]}
{"channel":"book","type":"update","data":[{"symbol":"SOL/USD","bids":[],"asks":[{"price":166.75,"qty":178.20480137}],"checksum":3914246372,"timestamp":"2024-06-01T22:42:35.795901Z"}]}
{"channel":"book","type":"update","data":[{"symbol":"SOL/USD","bids":[],"asks":[{"price":166.76,"qty":38.98413838}],"checksum":676986223,"timestamp":"2024-06-01T22:42:35.795924Z"}]}
{"channel":"book","type":"update","data":[{"symbol":"SOL/USD","bids":[],"asks":[{"price":166.71,"qty":447.68023734}],"checksum":464638106,"timestamp":"2024-06-01T22:42:35.796913Z"}]}
{"channel":"book","type":"update","data":[{"symbol":"SOL/USD","bids":[],"asks":[{"price":166.71,"qty":465.71023734}],"checksum":1859925631,"timestamp":"2024-06-01T22:42:35.802064Z"}]}
{"channel":"book","type":"update","data":[{"symbol":"SOL/USD","bids":[],"asks":[{"price":166.71,"qty":388.54378931}],"checksum":2494755566,"timestamp":"2024-06-01T22:42:35.806236Z"}]}
{"channel":"book","type":"update","data":[{"symbol":"SOL/USD","bids":[],"asks":[{"price":166.71,"qty":388.34378931}],"checksum":2533071493,"timestamp":"2024-06-01T22:42:35.806881Z"}]}
{"channel":"book","type":"update","data":[{"symbol":"SOL/USD","bids":[{"price":166.49,"qty":297.43622098}],"asks":[],"checksum":2546029406,"timestamp":"2024-06-01T22:42:35.808956Z"}]}
{"channel":"book","type":"update","data":[{"symbol":"SOL/USD","bids":[],"asks":[{"price":166.71,"qty":388.14378931}],"checksum":2517005447,"timestamp":"2024-06-01T22:42:35.811538Z"}]}
{"channel":"book","type":"update","data":[{"symbol":"SOL/USD","bids":[],"asks":[{"price":166.76,"qty":32.77613561}],"checksum":3755424996,"timestamp":"2024-06-01T22:42:35.813420Z"}]}
{"channel":"book","type":"update","data":[{"symbol":"SOL/USD","bids":[],"asks":[{"price":166.72,"qty":101.61198310}],"checksum":1390194099,"timestamp":"2024-06-01T22:42:35.813462Z"}]}
{"channel":"book","type":"update","data":[{"symbol":"SOL/USD","bids":[],"asks":[{"price":166.71,"qty":358.12886234}],"checksum":866756572,"timestamp":"2024-06-01T22:42:35.822343Z"}]}
{"channel":"book","type":"update","data":[{"symbol":"SOL/USD","bids":[{"price":166.51,"qty":91.10031253}],"asks":[],"checksum":4165620230,"timestamp":"2024-06-01T22:42:35.825903Z"}]}
{"channel":"book","type":"update","data":[{"symbol":"SOL/USD","bids":[],"asks":[{"price":166.71,"qty":367.93080234}],"checksum":1526815196,"timestamp":"2024-06-01T22:42:35.828796Z"}]}
{"channel":"book","type":"update","data":[{"symbol":"SOL/USD","bids":[],"asks":[{"price":166.76,"qty":24.48788928}],"checksum":552280858,"timestamp":"2024-06-01T22:42:35.828848Z"}]}
{"channel":"book","type":"update","data":[{"symbol":"SOL/USD","bids":[],"asks":[{"price":166.71,"qty":217.96979221}],"checksum":3642791378,"timestamp":"2024-06-01T22:42:35.836760Z"}]}
{"channel":"book","type":"update","data":[{"symbol":"SOL/USD","bids":[{"price":166.51,"qty":9.56591253}],"asks":[],"checksum":12171665,"timestamp":"2024-06-01T22:42:35.840576Z"}]}
{"channel":"book","type":"update","data":[{"symbol":"SOL/USD","bids":[],"asks":[{"price":166.69,"qty":971.69720623}],"checksum":2280008328,"timestamp":"2024-06-01T22:42:35.844400Z"}]}
{"channel":"book","type":"update","data":[{"symbol":"SOL/USD","bids":[],"asks":[{"price":166.80,"qty":747.75920255}],"checksum":1820687942,"timestamp":"2024-06-01T22:42:35.848457Z"}]}
{"channel":"book","type":"update","data":[{"symbol":"SOL/USD","bids":[],"asks":[{"price":166.78,"qty":9.56047203}],"checksum":1330459214,"timestamp":"2024-06-01T22:42:35.848800Z"}]}
{"channel":"book","type":"update","data":[{"symbol":"SOL/USD","bids":[{"price":166.50,"qty":251.27950862}],"asks":[],"checksum":529899726,"timestamp":"2024-06-01T22:42:35.860433Z"}]}
{"channel":"book","type":"update","data":[{"symbol":"SOL/USD","bids":[{"price":166.52,"qty":119.04184939}],"asks":[],"checksum":3350214177,"timestamp":"2024-06-01T22:42:35.862082Z"}]}
{"channel":"book","type":"update","data":[{"symbol":"SOL/USD","bids":[],"asks":[{"price":166.70,"qty":0.00000000},{"price":166.80,"qty":790.03374843},{"price":166.69,"qty":976.22048079}],"checksum":4100122635,"timestamp":"2024-06-01T22:42:35.871541Z"}]}
{"channel":"book","type":"update","data":[{"symbol":"SOL/USD","bids":[{"price":166.52,"qty":127.18574994}],"asks":[],"checksum":2472108859,"timestamp":"2024-06-01T22:42:35.872564Z"}]}
{"channel":"book","type":"update","data":[{"symbol":"SOL/USD","bids":[{"price":166.50,"qty":281.30952367}],"asks":[],"checksum":1760723563,"timestamp":"2024-06-01T22:42:35.872786Z"}]}
{"channel":"book","type":"update","data":[{"symbol":"SOL/USD","bids":[],"asks":[{"price":166.69,"qty":976.42048079}],"checksum":2399088512,"timestamp":"2024-06-01T22:42:35.876136Z"}]}
{"channel":"book","type":"update","data":[{"symbol":"SOL/USD","bids":[],"asks":[{"price":166.74,"qty":24.20341434}],"checksum":3898653252,"timestamp":"2024-06-01T22:42:35.877058Z"}]}
{"channel":"book","type":"update","data":[{"symbol":"SOL/USD","bids":[],"asks":[{"price":166.76,"qty":18.91000000}],"checksum":4200355307,"timestamp":"2024-06-01T22:42:35.878801Z"}]}
{"channel":"book","type":"update","data":[{"symbol":"SOL/USD","bids":[],"asks":[{"price":166.69,"qty":982.90769158}],"checksum":2027041063,"timestamp":"2024-06-01T22:42:35.879568Z"}]}
{"channel":"book","type":"update","data":[{"symbol":"SOL/USD","bids":[],"asks":[{"price":166.69,"qty":863.15769158}],"checksum":916742215,"timestamp":"2024-06-01T22:42:35.881393Z"}]}
{"channel":"book","type":"update","data":[{"symbol":"SOL/USD","bids":[{"price":166.64,"qty":3.30070000}],"asks":[],"checksum":3309569875,"timestamp":"2024-06-01T22:42:35.886002Z"}]}
{"channel":"book","type":"update","data":[{"symbol":"SOL/USD","bids":[],"asks":[{"price":166.69,"qty":833.16769158}],"checksum":623690722,"timestamp":"2024-06-01T22:42:35.886703Z"}]}
{"channel":"book","type":"update","data":[{"symbol":"SOL/USD","bids":[],"asks":[{"price":166.69,"qty":803.17769158}],"checksum":3424943538,"timestamp":"2024-06-01T22:42:35.886911Z"}]}
{"channel":"book","type":"update","data":[{"symbol":"SOL/USD","bids":[],"asks":[{"price":166.71,"qty":216.79715102}],"checksum":1074131325,"timestamp":"2024-06-01T22:42:35.896665Z"}]}
{"channel":"book","type":"update","data":[{"symbol":"SOL/USD","bids":[],"asks":[{"price":166.69,"qty":804.35033277}],"checksum":2412699047,"timestamp":"2024-06-01T22:42:35.905700Z"}]}
{"channel":"book","type":"update","data":[{"symbol":"SOL/USD","bids":[],"asks":[{"price":166.71,"qty":108.74869760}],"checksum":709869397,"timestamp":"2024-06-01T22:42:35.907208Z"}]}
{"channel":"book","type":"update","data":[{"symbol":"SOL/USD","bids":[],"asks":[{"price":166.69,"qty":912.43243974}],"checksum":4061055476,"timestamp":"2024-06-01T22:42:35.907362Z"}]}
{"channel":"book","type":"update","data":[{"symbol":"SOL/USD","bids":[],"asks":[{"price":166.74,"qty":24.00341434}],"checksum":3424030798,"timestamp":"2024-06-01T22:42:35.910357Z"}]}
{"channel":"book","type":"update","data":[{"symbol":"SOL/USD","bids":[],"asks":[{"price":166.72,"qty":93.00692697}],"checksum":2670091091,"timestamp":"2024-06-01T22:42:35.910762Z"}]}
{"channel":"book","type":"update","data":[{"symbol":"SOL/USD","bids":[],"asks":[{"price":166.69,"qty":907.90916518},{"price":166.70,"qty":4.52327456}],"checksum":204917498,"timestamp":"2024-06-01T22:42:35.912456Z"}]}
{"channel":"book","type":"update","data":[{"symbol":"SOL/USD","bids":[{"price":166.51,"qty":0.00000000},{"price":166.49,"qty":297.43622098}],"asks":[],"checksum":3118451109,"timestamp":"2024-06-01T22:42:35.920247Z"}]}
{"channel":"book","type":"update","data":[{"symbol":"SOL/USD","bids":[{"price":166.50,"qty":251.27950862}],"asks":[],"checksum":1114908917,"timestamp":"2024-06-01T22:42:35.932896Z"}]}
{"channel":"book","type":"update","data":[{"symbol":"SOL/USD","bids":[],"asks":[{"price":166.69,"qty":915.84971354}],"checksum":496343563,"timestamp":"2024-06-01T22:42:35.951901Z"}]}
{"channel":"book","type":"update","data":[{"symbol":"SOL/USD","bids":[{"price":166.56,"qty":13.49867371}],"asks":[],"checksum":4045886034,"timestamp":"2024-06-01T22:42:35.958161Z"}]}
{"channel":"book","type":"update","data":[{"symbol":"SOL/USD","bids":[{"price":166.49,"qty":0.00000000},{"price":166.47,"qty":31.90000000}],"asks":[],"checksum":3270940545,"timestamp":"2024-06-01T22:42:35.959425Z"}]}
{"channel":"book","type":"update","data":[{"symbol":"SOL/USD","bids":[{"price":166.55,"qty":257.49076294}],"asks":[],"checksum":2117729737,"timestamp":"2024-06-01T22:42:35.960599Z"}]}
{"channel":"book","type":"update","data":[{"symbol":"SOL/USD","bids":[{"price":166.56,"qty":11.26888085}],"asks":[],"checksum":1183687619,"timestamp":"2024-06-01T22:42:35.967254Z"}]}
{"channel":"book","type":"update","data":[{"symbol":"SOL/USD","bids":[{"price":166.51,"qty":0.46471467}],"asks":[],"checksum":3170685909,"timestamp":"2024-06-01T22:42:35.967349Z"}]}
{"channel":"book","type":"update","data":[{"symbol":"SOL/USD","bids":[],"asks":[{"price":166.71,"qty":103.15869760}],"checksum":1381936341,"timestamp":"2024-06-01T22:42:35.967713Z"}]}
{"channel":"book","type":"update","data":[{"symbol":"SOL/USD","bids":[{"price":166.54,"qty":53.99190952}],"asks":[],"checksum":1575038378,"timestamp":"2024-06-01T22:42:35.974388Z"}]}
{"channel":"book","type":"update","data":[{"symbol":"SOL/USD","bids":[{"price":166.50,"qty":231.64499340}],"asks":[],"checksum":827724944,"timestamp":"2024-06-01T22:42:35.974753Z"}]}
{"channel":"book","type":"update","data":[{"symbol":"SOL/USD","bids":[],"asks":[{"price":166.73,"qty":214.70880662}],"checksum":221247806,"timestamp":"2024-06-01T22:42:35.979431Z"}]}
{"channel":"book","type":"update","data":[{"symbol":"SOL/USD","bids":[{"price":166.54,"qty":23.96931927}],"asks":[],"checksum":43022401,"timestamp":"2024-06-01T22:42:35.993197Z"}]}
{"channel":"book","type":"update","data":[{"symbol":"SOL/USD","bids":[{"price":166.51,"qty":30.49161860}],"asks":[],"checksum":1006571696,"timestamp":"2024-06-01T22:42:35.996699Z"}]}
{"channel":"book","type":"update","data":[{"symbol":"SOL/USD","bids":[],"asks":[{"price":166.71,"qty":102.19612204}],"checksum":4067017700,"timestamp":"2024-06-01T22:42:36.004212Z"}]}
{"channel":"book","type":"update","data":[{"symbol":"SOL/USD","bids":[],"asks":[{"price":166.69,"qty":914.67707235}],"checksum":3619855109,"timestamp":"2024-06-01T22:42:36.006090Z"}]}
{"channel":"book","type":"update","data":[{"symbol":"SOL/USD","bids":[{"price":166.51,"qty":0.46471467}],"asks":[],"checksum":2784671545,"timestamp":"2024-06-01T22:42:36.010256Z"}]}
{"channel":"book","type":"update","data":[{"symbol":"SOL/USD","bids":[{"price":166.50,"qty":249.64301361}],"asks":[],"checksum":1819158122,"timestamp":"2024-06-01T22:42:36.015243Z"}]}
{"channel":"book","type":"update","data":[{"symbol":"SOL/USD","bids":[{"price":166.50,"qty":281.54301361}],"asks":[],"checksum":1124426527,"timestamp":"2024-06-01T22:42:36.016391Z"}]}
{"channel":"book","type":"update","data":[{"symbol":"SOL/USD","bids":[],"asks":[{"price":166.74,"qty":26.99841139}],"checksum":2887464191,"timestamp":"2024-06-01T22:42:36.034226Z"}]}
{"channel":"book","type":"update","data":[{"symbol":"SOL/USD","bids":[],"asks":[{"price":166.71,"qty":108.45757989}],"checksum":993532239,"timestamp":"2024-06-01T22:42:36.040964Z"}]}
{"channel":"book","type":"update","data":[{"symbol":"SOL/USD","bids":[],"asks":[{"price":166.69,"qty":914.47707235}],"checksum":2011331540,"timestamp":"2024-06-01T22:42:36.045379Z"}]}
{"channel":"book","type":"update","data":[{"symbol":"SOL/USD","bids":[],"asks":[{"price":166.71,"qty":108.65757989}],"checksum":553053071,"timestamp":"2024-06-01T22:42:36.045403Z"}]}
{"channel":"book","type":"update","data":[{"symbol":"SOL/USD","bids":[{"price":166.51,"qty":10.63626659}],"asks":[],"checksum":191392054,"timestamp":"2024-06-01T22:42:36.051975Z"}]}
{"channel":"book","type":"update","data":[{"symbol":"SOL/USD","bids":[],"asks":[{"price":166.72,"qty":135.28147285}],"checksum":3568558997,"timestamp":"2024-06-01T22:42:36.061240Z"}]}
{"channel":"book","type":"update","data":[{"symbol":"SOL/USD","bids":[],"asks":[{"price":166.69,"qty":920.36507235}],"checksum":1767343029,"timestamp":"2024-06-01T22:42:36.066264Z"}]}
{"channel":"book","type":"update","data":[{"symbol":"SOL/USD","bids":[{"price":166.54,"qty":53.99162875}],"asks":[],"checksum":3677643496,"timestamp":"2024-06-01T22:42:36.079676Z"}]}
{"channel":"book","type":"update","data":[{"symbol":"SOL/USD","bids":[],"asks":[{"price":166.71,"qty":98.85563989}],"checksum":1704923033,"timestamp":"2024-06-01T22:42:36.083191Z"}]}
{"channel":"book","type":"update","data":[{"symbol":"SOL/USD","bids":[],"asks":[{"price":166.69,"qty":920.56507235}],"checksum":914632216,"timestamp":"2024-06-01T22:42:36.087162Z"}]}
{"channel":"book","type":"update","data":[{"symbol":"SOL/USD","bids":[{"price":166.54,"qty":23.96931927}],"asks":[],"checksum":2229784389,"timestamp":"2024-06-01T22:42:36.087907Z"}]}
{"channel":"book","type":"update","data":[{"symbol":"SOL/USD","bids":[],"asks":[{"price":166.75,"qty":27.93427182}],"checksum":3004290243,"timestamp":"2024-06-01T22:42:36.101025Z"}]}
{"channel":"book","type":"update","data":[{"symbol":"SOL/USD","bids":[{"price":166.51,"qty":0.46471467}],"asks":[],"checksum":1497785462,"timestamp":"2024-06-01T22:42:36.102261Z"}]}
{"channel":"book","type":"update","data":[{"symbol":"SOL/USD","bids":[],"asks":[{"price":166.69,"qty":900.96872185}],"checksum":389395124,"timestamp":"2024-06-01T22:42:36.108468Z"}]}
{"channel":"book","type":"update","data":[{"symbol":"SOL/USD","bids":[{"price":166.55,"qty":215.21621706}],"asks":[],"checksum":1120489560,"timestamp":"2024-06-01T22:42:36.111570Z"}]}
{"channel":"book","type":"update","data":[{"symbol":"SOL/USD","bids":[],"asks":[{"price":166.73,"qty":94.95880662}],"checksum":3003059596,"timestamp":"2024-06-01T22:42:36.126416Z"}]}
{"channel":"book","type":"update","data":[{"symbol":"SOL/USD","bids":[],"asks":[{"price":166.71,"qty":98.65563989}],"checksum":494170241,"timestamp":"2024-06-01T22:42:36.130215Z"}]}
{"channel":"book","type":"update","data":[{"symbol":"SOL/USD","bids":[{"price":166.50,"qty":341.60200048}],"asks":[],"checksum":2253044864,"timestamp":"2024-06-01T22:42:36.150347Z"}]}
{"channel":"book","type":"update","data":[{"symbol":"SOL/USD","bids":[{"price":166.51,"qty":42.73926055}],"asks":[],"checksum":1637676998,"timestamp":"2024-06-01T22:42:36.161972Z"}]}
{"channel":"book","type":"update","data":[{"symbol":"SOL/USD","bids":[],"asks":[{"price":166.72,"qty":154.87782335}],"checksum":1637810415,"timestamp":"2024-06-01T22:42:36.165446Z"}]}
{"channel":"book","type":"update","data":[{"symbol":"SOL/USD","bids":[],"asks":[{"price":166.71,"qty":80.62563989}],"checksum":2114174560,"timestamp":"2024-06-01T22:42:36.186658Z"}]}
{"channel":"book","type":"update","data":[{"symbol":"SOL/USD","bids":[{"price":166.53,"qty":30.02357347}],"asks":[],"checksum":1724574315,"timestamp":"2024-06-01T22:42:36.187405Z"}]}
{"channel":"book","type":"update","data":[{"symbol":"SOL/USD","bids":[{"price":166.53,"qty":40.19390380}],"asks":[],"checksum":1664923157,"timestamp":"2024-06-01T22:42:36.210240Z"}]}
{"channel":"book","type":"update","data":[{"symbol":"SOL/USD","bids":[],"asks":[{"price":166.72,"qty":112.60327747}],"checksum":60023452,"timestamp":"2024-06-01T22:42:36.212277Z"}]}
{"channel":"book","type":"update","data":[{"symbol":"SOL/USD","bids":[{"price":166.51,"qty":72.76668161}],"asks":[],"checksum":1930946803,"timestamp":"2024-06-01T22:42:36.229867Z"}]}
{"channel":"book","type":"update","data":[{"symbol":"SOL/USD","bids":[],"asks":[{"price":166.73,"qty":214.70880662}],"checksum":3114509000,"timestamp":"2024-06-01T22:42:36.232273Z"}]}
{"channel":"book","type":"update","data":[{"symbol":"SOL/USD","bids":[],"asks":[{"price":166.74,"qty":2.99499705}],"checksum":653522228,"timestamp":"2024-06-01T22:42:36.232544Z"}]}
{"channel":"book","type":"update","data":[{"symbol":"SOL/USD","bids":[],"asks":[{"price":166.78,"qty":197.31047203}],"checksum":266307375,"timestamp":"2024-06-01T22:42:36.247407Z"}]}
{"channel":"book","type":"update","data":[{"symbol":"SOL/USD","bids":[],"asks":[{"price":166.70,"qty":6.97326010}],"checksum":2178080656,"timestamp":"2024-06-01T22:42:36.263719Z"}]}
{"channel":"book","type":"update","data":[{"symbol":"SOL/USD","bids":[{"price":166.52,"qty":8.14390055}],"asks":[],"checksum":3159661808,"timestamp":"2024-06-01T22:42:36.295417Z"}]}
{"channel":"book","type":"update","data":[{"symbol":"SOL/USD","bids":[],"asks":[{"price":166.75,"qty":57.92427182}],"checksum":4078185285,"timestamp":"2024-06-01T22:42:36.298284Z"}]}
{"channel":"book","type":"update","data":[{"symbol":"SOL/USD","bids":[{"price":166.53,"qty":30.02357347},{"price":166.52,"qty":18.31949187}],"asks":[],"checksum":245378794,"timestamp":"2024-06-01T22:42:36.298431Z"}]}
{"channel":"book","type":"update","data":[{"symbol":"SOL/USD","bids":[],"asks":[{"price":166.74,"qty":32.98499705}],"checksum":2802393674,"timestamp":"2024-06-01T22:42:36.298648Z"}]}
{"channel":"book","type":"update","data":[{"symbol":"SOL/USD","bids":[{"price":166.51,"qty":42.73926055}],"asks":[],"checksum":3616352293,"timestamp":"2024-06-01T22:42:36.303958Z"}]}
{"channel":"book","type":"update","data":[{"symbol":"SOL/USD","bids":[{"price":166.53,"qty":60.04736912}],"asks":[],"checksum":2024210565,"timestamp":"2024-06-01T22:42:36.314662Z"}]}
{"channel":"book","type":"update","data":[{"symbol":"SOL/USD","bids":[{"price":166.52,"qty":8.14390055},{"price":166.51,"qty":52.91546298}],"asks":[],"checksum":1084168347,"timestamp":"2024-06-01T22:42:36.328937Z"}]}
{"channel":"book","type":"update","data":[{"symbol":"SOL/USD","bids":[{"price":166.53,"qty":30.02357347}],"asks":[],"checksum":1621947442,"timestamp":"2024-06-01T22:42:36.340012Z"}]}
{"channel":"book","type":"update","data":[{"symbol":"SOL/USD","bids":[],"asks":[{"price":166.73,"qty":363.06419781}],"checksum":1281511917,"timestamp":"2024-06-01T22:42:36.342381Z"}]}
{"channel":"book","type":"update","data":[{"symbol":"SOL/USD","bids":[{"price":166.51,"qty":42.73926055},{"price":166.52,"qty":18.31949187}],"asks":[],"checksum":3251448261,"timestamp":"2024-06-01T22:42:36.356262Z"}]}
{"channel":"book","type":"update","data":[{"symbol":"SOL/USD","bids":[{"price":166.52,"qty":8.14390055},{"price":166.51,"qty":52.91546298}],"asks":[],"checksum":1281511917,"timestamp":"2024-06-01T22:42:36.411989Z"}]}
{"channel":"book","type":"update","data":[{"symbol":"SOL/USD","bids":[{"price":166.51,"qty":82.94275292}],"asks":[],"checksum":1130494306,"timestamp":"2024-06-01T22:42:36.445973Z"}]}
{"channel":"book","type":"update","data":[{"symbol":"SOL/USD","bids":[{"price":166.51,"qty":52.91546298}],"asks":[],"checksum":1281511917,"timestamp":"2024-06-01T22:42:36.488785Z"}]}
{"channel":"book","type":"update","data":[{"symbol":"SOL/USD","bids":[{"price":166.53,"qty":60.04702784}],"asks":[],"checksum":2161953488,"timestamp":"2024-06-01T22:42:36.492367Z"}]}
{"channel":"book","type":"update","data":[{"symbol":"SOL/USD","bids":[],"asks":[{"price":166.69,"qty":924.97901606}],"checksum":708079212,"timestamp":"2024-06-01T22:42:36.534015Z"}]}
{"channel":"book","type":"update","data":[{"symbol":"SOL/USD","bids":[],"asks":[{"price":166.69,"qty":925.17901606}],"checksum":4058262038,"timestamp":"2024-06-01T22:42:36.538777Z"}]}
{"channel":"book","type":"update","data":[{"symbol":"SOL/USD","bids":[{"price":166.53,"qty":30.02345437}],"asks":[],"checksum":3827255641,"timestamp":"2024-06-01T22:42:36.641354Z"}]}
{"channel":"book","type":"update","data":[{"symbol":"SOL/USD","bids":[{"price":166.54,"qty":53.99200804}],"asks":[],"checksum":1871407518,"timestamp":"2024-06-01T22:42:36.644871Z"}]}
{"channel":"book","type":"update","data":[{"symbol":"SOL/USD","bids":[],"asks":[{"price":166.74,"qty":41.50509382}],"checksum":691140928,"timestamp":"2024-06-01T22:42:36.645410Z"}]}
{"channel":"book","type":"update","data":[{"symbol":"SOL/USD","bids":[],"asks":[{"price":166.69,"qty":941.48732117}],"checksum":108664846,"timestamp":"2024-06-01T22:42:36.711702Z"}]}
{"channel":"book","type":"update","data":[{"symbol":"SOL/USD","bids":[],"asks":[{"price":166.69,"qty":951.67736550}],"checksum":3524658625,"timestamp":"2024-06-01T22:42:36.717093Z"}]}
{"channel":"book","type":"update","data":[{"symbol":"SOL/USD","bids":[],"asks":[{"price":166.69,"qty":935.36906039}],"checksum":297908838,"timestamp":"2024-06-01T22:42:36.721257Z"}]}
{"channel":"book","type":"update","data":[{"symbol":"SOL/USD","bids":[{"price":166.51,"qty":104.33375204}],"asks":[],"checksum":1256074264,"timestamp":"2024-06-01T22:42:36.803791Z"}]}
{"channel":"book","type":"update","data":[{"symbol":"SOL/USD","bids":[{"price":166.51,"qty":94.15754961},{"price":166.52,"qty":18.31948779}],"asks":[],"checksum":2794274332,"timestamp":"2024-06-01T22:42:36.815248Z"}]}
{"channel":"book","type":"update","data":[{"symbol":"SOL/USD","bids":[{"price":166.53,"qty":0.00000000},{"price":166.50,"qty":341.60200048}],"asks":[],"checksum":469347919,"timestamp":"2024-06-01T22:42:36.823149Z"}]}
{"channel":"book","type":"update","data":[{"symbol":"SOL/USD","bids":[{"price":166.55,"qty":245.23710756}],"asks":[],"checksum":3407917491,"timestamp":"2024-06-01T22:42:36.828804Z"}]}
{"channel":"book","type":"update","data":[{"symbol":"SOL/USD","bids":[],"asks":[{"price":166.69,"qty":951.67736550}],"checksum":1907947095,"timestamp":"2024-06-01T22:42:36.841803Z"}]}
{"channel":"book","type":"update","data":[{"symbol":"SOL/USD","bids":[],"asks":[{"price":166.71,"qty":50.65563989},{"price":166.69,"qty":981.64736550}],"checksum":882974371,"timestamp":"2024-06-01T22:42:36.847602Z"}]}
{"channel":"book","type":"update","data":[{"symbol":"SOL/USD","bids":[{"price":166.55,"qty":215.21621706}],"asks":[],"checksum":3833069919,"timestamp":"2024-06-01T22:42:36.849362Z"}]}
{"channel":"book","type":"update","data":[{"symbol":"SOL/USD","bids":[],"asks":[{"price":166.69,"qty":951.67736550}],"checksum":2460852986,"timestamp":"2024-06-01T22:42:36.855617Z"}]}
{"channel":"book","type":"update","data":[{"symbol":"SOL/USD","bids":[{"price":166.52,"qty":48.34490202}],"asks":[],"checksum":2208552927,"timestamp":"2024-06-01T22:42:36.856922Z"}]}
{"channel":"book","type":"update","data":[{"symbol":"SOL/USD","bids":[{"price":166.51,"qty":42.73926055}],"asks":[],"checksum":41512322,"timestamp":"2024-06-01T22:42:36.862514Z"}]}
{"channel":"book","type":"update","data":[{"symbol":"SOL/USD","bids":[{"price":166.56,"qty":19.41278140}],"asks":[],"checksum":3735700079,"timestamp":"2024-06-01T22:42:36.865652Z"}]}
{"channel":"book","type":"update","data":[{"symbol":"SOL/USD","bids":[{"price":166.52,"qty":18.31948779}],"asks":[],"checksum":3483645770,"timestamp":"2024-06-01T22:42:36.867549Z"}]}
{"channel":"book","type":"update","data":[{"symbol":"SOL/USD","bids":[{"price":166.52,"qty":8.14390055},{"price":166.51,"qty":52.91545475}],"asks":[],"checksum":1012928193,"timestamp":"2024-06-01T22:42:36.881828Z"}]}
{"channel":"book","type":"update","data":[{"symbol":"SOL/USD","bids":[],"asks":[{"price":166.69,"qty":935.36906039}],"checksum":1947332405,"timestamp":"2024-06-01T22:42:36.884850Z"}]}
{"channel":"book","type":"update","data":[{"symbol":"SOL/USD","bids":[{"price":166.52,"qty":68.19552017}],"asks":[],"checksum":3636311408,"timestamp":"2024-06-01T22:42:36.885930Z"}]}
{"channel":"book","type":"update","data":[{"symbol":"SOL/USD","bids":[{"price":166.56,"qty":11.26888085}],"asks":[],"checksum":74357405,"timestamp":"2024-06-01T22:42:36.887860Z"}]}
{"channel":"book","type":"update","data":[{"symbol":"SOL/USD","bids":[],"asks":[{"price":166.69,"qty":929.48106039}],"checksum":3054745096,"timestamp":"2024-06-01T22:42:36.888148Z"}]}
{"channel":"book","type":"update","data":[{"symbol":"SOL/USD","bids":[],"asks":[{"price":166.69,"qty":929.28106039}],"checksum":3842545545,"timestamp":"2024-06-01T22:42:36.888885Z"}]}
{"channel":"book","type":"update","data":[{"symbol":"SOL/USD","bids":[],"asks":[{"price":166.71,"qty":50.85563989}],"checksum":3579136942,"timestamp":"2024-06-01T22:42:36.889051Z"}]}
{"channel":"book","type":"update","data":[{"symbol":"SOL/USD","bids":[{"price":166.54,"qty":23.96931927}],"asks":[],"checksum":1786814843,"timestamp":"2024-06-01T22:42:36.893571Z"}]}
{"channel":"book","type":"update","data":[{"symbol":"SOL/USD","bids":[{"price":166.51,"qty":42.73926055}],"asks":[],"checksum":1391534470,"timestamp":"2024-06-01T22:42:36.909073Z"}]}
{"channel":"book","type":"update","data":[{"symbol":"SOL/USD","bids":[],"asks":[{"price":166.69,"qty":921.34051203}],"checksum":3805037760,"timestamp":"2024-06-01T22:42:36.928612Z"}]}
{"channel":"book","type":"update","data":[{"symbol":"SOL/USD","bids":[{"price":166.55,"qty":245.23629055}],"asks":[],"checksum":600076973,"timestamp":"2024-06-01T22:42:36.938255Z"}]}
{"channel":"book","type":"update","data":[{"symbol":"SOL/USD","bids":[],"asks":[{"price":166.69,"qty":927.22851203}],"checksum":213838714,"timestamp":"2024-06-01T22:42:36.986707Z"}]}
{"channel":"book","type":"update","data":[{"symbol":"SOL/USD","bids":[{"price":166.55,"qty":275.25671226}],"asks":[],"checksum":4179373301,"timestamp":"2024-06-01T22:42:37.043761Z"}]}
{"channel":"book","type":"update","data":[{"symbol":"SOL/USD","bids":[{"price":166.56,"qty":0.00000000},{"price":166.48,"qty":24.01026797}],"asks":[],"checksum":3646128186,"timestamp":"2024-06-01T22:42:37.047022Z"}]}
{"channel":"book","type":"update","data":[{"symbol":"SOL/USD","bids":[{"price":166.68,"qty":0.00000000},{"price":166.47,"qty":17.13000000},{"price":166.67,"qty":47.98411408}],"asks":[],"checksum":3231129976,"timestamp":"2024-06-01T22:42:37.050943Z"}]}
{"channel":"book","type":"update","data":[{"symbol":"SOL/USD","bids":[],"asks":[{"price":166.71,"qty":17.85563989}],"checksum":74572681,"timestamp":"2024-06-01T22:42:37.053988Z"}]}
{"channel":"book","type":"update","data":[{"symbol":"SOL/USD","bids":[],"asks":[{"price":166.68,"qty":33.00000000}],"checksum":1772964717,"timestamp":"2024-06-01T22:42:37.054152Z"}]}
{"channel":"book","type":"update","data":[{"symbol":"SOL/USD","bids":[],"asks":[{"price":166.68,"qty":34.06750865}],"checksum":3025657799,"timestamp":"2024-06-01T22:42:37.055067Z"}]}
{"channel":"book","type":"update","data":[{"symbol":"SOL/USD","bids":[],"asks":[{"price":166.69,"qty":867.23691086}],"checksum":1266078295,"timestamp":"2024-06-01T22:42:37.055087Z"}]}
{"channel":"book","type":"update","data":[{"symbol":"SOL/USD","bids":[],"asks":[{"price":166.69,"qty":843.24027039},{"price":166.68,"qty":58.06558880}],"checksum":997572731,"timestamp":"2024-06-01T22:42:37.055854Z"}]}
{"channel":"book","type":"update","data":[{"symbol":"SOL/USD","bids":[],"asks":[{"price":166.68,"qty":68.00979326}],"checksum":191139964,"timestamp":"2024-06-01T22:42:37.057509Z"}]}
{"channel":"book","type":"update","data":[{"symbol":"SOL/USD","bids":[],"asks":[{"price":166.69,"qty":813.24446981}],"checksum":3495935682,"timestamp":"2024-06-01T22:42:37.057638Z"}]}
{"channel":"book","type":"update","data":[{"symbol":"SOL/USD","bids":[{"price":166.61,"qty":11.07416277}],"asks":[],"checksum":4112952638,"timestamp":"2024-06-01T22:42:37.057735Z"}]}
{"channel":"book","type":"update","data":[{"symbol":"SOL/USD","bids":[],"asks":[{"price":166.69,"qty":753.25286864}],"checksum":4007442209,"timestamp":"2024-06-01T22:42:37.057760Z"}]}
{"channel":"book","type":"update","data":[{"symbol":"SOL/USD","bids":[],"asks":[{"price":166.69,"qty":723.25706806}],"checksum":2963701802,"timestamp":"2024-06-01T22:42:37.057960Z"}]}
{"channel":"book","type":"update","data":[{"symbol":"SOL/USD","bids":[],"asks":[{"price":166.75,"qty":47.98424184}],"checksum":1081419420,"timestamp":"2024-06-01T22:42:37.058941Z"}]}
{"channel":"book","type":"update","data":[{"symbol":"SOL/USD","bids":[],"asks":[{"price":166.68,"qty":98.00739345}],"checksum":3504425933,"timestamp":"2024-06-01T22:42:37.061745Z"}]}
{"channel":"book","type":"update","data":[{"symbol":"SOL/USD","bids":[],"asks":[{"price":166.68,"qty":158.00259383}],"checksum":2051473708,"timestamp":"2024-06-01T22:42:37.061776Z"}]}
{"channel":"book","type":"update","data":[{"symbol":"SOL/USD","bids":[],"asks":[{"price":166.68,"qty":188.00019402}],"checksum":1770849006,"timestamp":"2024-06-01T22:42:37.061871Z"}]}
{"channel":"book","type":"update","data":[{"symbol":"SOL/USD","bids":[],"asks":[{"price":166.68,"qty":247.99539440}],"checksum":624022405,"timestamp":"2024-06-01T22:42:37.061970Z"}]}
{"channel":"book","type":"update","data":[{"symbol":"SOL/USD","bids":[],"asks":[{"price":166.78,"qty":187.75000000}],"checksum":3033848024,"timestamp":"2024-06-01T22:42:37.079893Z"}]}
{"channel":"book","type":"update","data":[{"symbol":"SOL/USD","bids":[],"asks":[{"price":166.68,"qty":264.30369951}],"checksum":941065680,"timestamp":"2024-06-01T22:42:37.084497Z"}]}
{"channel":"book","type":"update","data":[{"symbol":"SOL/USD","bids":[],"asks":[{"price":166.68,"qty":264.50369951}],"checksum":2734370119,"timestamp":"2024-06-01T22:42:37.089017Z"}]}
{"channel":"book","type":"update","data":[{"symbol":"SOL/USD","bids":[],"asks":[{"price":166.68,"qty":274.69374384}],"checksum":2480688612,"timestamp":"2024-06-01T22:42:37.089423Z"}]}
{"channel":"book","type":"update","data":[{"symbol":"SOL/USD","bids":[],"asks":[{"price":166.68,"qty":304.70615070}],"checksum":3814683986,"timestamp":"2024-06-01T22:42:37.094151Z"}]}
{"channel":"book","type":"update","data":[{"symbol":"SOL/USD","bids":[],"asks":[{"price":166.69,"qty":693.24466120}],"checksum":1764787024,"timestamp":"2024-06-01T22:42:37.097606Z"}]}
{"channel":"book","type":"update","data":[{"symbol":"SOL/USD","bids":[],"asks":[{"price":166.69,"qty":693.04466120}],"checksum":2695832536,"timestamp":"2024-06-01T22:42:37.101879Z"}]}
{"channel":"book","type":"update","data":[{"symbol":"SOL/USD","bids":[{"price":166.51,"qty":0.46471467}],"asks":[],"checksum":2940770853,"timestamp":"2024-06-01T22:42:37.105257Z"}]}
{"channel":"book","type":"update","data":[{"symbol":"SOL/USD","bids":[],"asks":[{"price":166.78,"qty":188.92264119}],"checksum":4060212115,"timestamp":"2024-06-01T22:42:37.105295Z"}]}
{"channel":"book","type":"update","data":[{"symbol":"SOL/USD","bids":[],"asks":[{"price":166.70,"qty":2.44998554},{"price":166.68,"qty":309.22965605}],"checksum":1366552247,"timestamp":"2024-06-01T22:42:37.116585Z"}]}
{"channel":"book","type":"update","data":[{"symbol":"SOL/USD","bids":[{"price":166.53,"qty":10.17496889}],"asks":[],"checksum":522604757,"timestamp":"2024-06-01T22:42:37.116833Z"}]}
{"channel":"book","type":"update","data":[{"symbol":"SOL/USD","bids":[],"asks":[{"price":166.69,"qty":682.85461687}],"checksum":1321941934,"timestamp":"2024-06-01T22:42:37.120965Z"}]}
{"channel":"book","type":"update","data":[{"symbol":"SOL/USD","bids":[],"asks":[{"price":166.69,"qty":682.65461687}],"checksum":1174191759,"timestamp":"2024-06-01T22:42:37.120999Z"}]}
{"channel":"book","type":"update","data":[{"symbol":"SOL/USD","bids":[{"price":166.56,"qty":8.14438916}],"asks":[],"checksum":802924402,"timestamp":"2024-06-01T22:42:37.128191Z"}]}
{"channel":"book","type":"update","data":[{"symbol":"SOL/USD","bids":[{"price":166.56,"qty":0.00000000},{"price":166.50,"qty":341.60200048}],"asks":[],"checksum":1174191759,"timestamp":"2024-06-01T22:42:37.132132Z"}]}
{"channel":"book","type":"update","data":[{"symbol":"SOL/USD","bids":[{"price":166.53,"qty":0.00000000},{"price":166.48,"qty":24.01026797},{"price":166.51,"qty":10.64090571}],"asks":[],"checksum":3203501608,"timestamp":"2024-06-01T22:42:37.139529Z"}]}
{"channel":"book","type":"update","data":[{"symbol":"SOL/USD","bids":[],"asks":[{"price":166.68,"qty":292.92135094}],"checksum":377071847,"timestamp":"2024-06-01T22:42:37.152973Z"}]}
{"channel":"book","type":"update","data":[{"symbol":"SOL/USD","bids":[],"asks":[{"price":166.77,"qty":42.27454588}],"checksum":2153151069,"timestamp":"2024-06-01T22:42:37.155853Z"}]}
{"channel":"book","type":"update","data":[{"symbol":"SOL/USD","bids":[],"asks":[{"price":166.68,"qty":370.08779897}],"checksum":474478525,"timestamp":"2024-06-01T22:42:37.158173Z"}]}
{"channel":"book","type":"update","data":[{"symbol":"SOL/USD","bids":[{"price":166.52,"qty":119.61072142}],"asks":[],"checksum":3623002821,"timestamp":"2024-06-01T22:42:37.159081Z"}]}
{"channel":"book","type":"update","data":[{"symbol":"SOL/USD","bids":[{"price":166.53,"qty":42.27454588}],"asks":[],"checksum":289253764,"timestamp":"2024-06-01T22:42:37.206178Z"}]}
{"channel":"book","type":"update","data":[{"symbol":"SOL/USD","bids":[],"asks":[{"price":166.69,"qty":574.57250990}],"checksum":1700563564,"timestamp":"2024-06-01T22:42:37.207160Z"}]}
{"channel":"book","type":"update","data":[{"symbol":"SOL/USD","bids":[],"asks":[{"price":166.68,"qty":478.15049352}],"checksum":1542614843,"timestamp":"2024-06-01T22:42:37.207515Z"}]}
{"channel":"book","type":"update","data":[{"symbol":"SOL/USD","bids":[],"asks":[{"price":166.69,"qty":497.40606187}],"checksum":1783201401,"timestamp":"2024-06-01T22:42:37.209621Z"}]}
{"channel":"book","type":"update","data":[{"symbol":"SOL/USD","bids":[{"price":166.55,"qty":245.23629055}],"asks":[],"checksum":267110780,"timestamp":"2024-06-01T22:42:37.243254Z"}]}
{"channel":"book","type":"update","data":[{"symbol":"SOL/USD","bids":[{"price":166.53,"qty":72.29804891}],"asks":[],"checksum":3699460597,"timestamp":"2024-06-01T22:42:37.246373Z"}]}
{"channel":"book","type":"update","data":[{"symbol":"SOL/USD","bids":[],"asks":[{"price":166.68,"qty":494.45879863}],"checksum":2215440166,"timestamp":"2024-06-01T22:42:37.271880Z"}]}
{"channel":"book","type":"update","data":[{"symbol":"SOL/USD","bids":[],"asks":[{"price":166.69,"qty":347.42705894}],"checksum":3943112471,"timestamp":"2024-06-01T22:42:37.306204Z"}]}
{"channel":"book","type":"update","data":[{"symbol":"SOL/USD","bids":[{"price":166.55,"qty":215.21621706}],"asks":[],"checksum":3329873637,"timestamp":"2024-06-01T22:42:37.306216Z"}]}
{"channel":"book","type":"update","data":[{"symbol":"SOL/USD","bids":[],"asks":[{"price":166.68,"qty":644.44679958}],"checksum":1043924749,"timestamp":"2024-06-01T22:42:37.309853Z"}]}
{"channel":"book","type":"update","data":[{"symbol":"SOL/USD","bids":[{"price":166.54,"qty":53.99097655}],"asks":[],"checksum":756964642,"timestamp":"2024-06-01T22:42:37.309871Z"}]}
{"channel":"book","type":"update","data":[{"symbol":"SOL/USD","bids":[],"asks":[{"price":166.68,"qty":644.64679958}],"checksum":3985979536,"timestamp":"2024-06-01T22:42:37.311619Z"}]}
{"channel":"book","type":"update","data":[{"symbol":"SOL/USD","bids":[],"asks":[{"price":166.73,"qty":368.89410281}],"checksum":2646635424,"timestamp":"2024-06-01T22:42:37.341571Z"}]}
{"channel":"book","type":"update","data":[{"symbol":"SOL/USD","bids":[],"asks":[{"price":166.69,"qty":347.22705894}],"checksum":470914169,"timestamp":"2024-06-01T22:42:37.348228Z"}]}
