{"channel":"book","type":"snapshot","data":[{"symbol":"USD/CHF","bids":[{"price":0.90309,"qty":78.53515625},{"price":0.90304,"qty":3922.12539805},{"price":0.90303,"qty":3071.32719112},{"price":0.90302,"qty":1107.39518504},{"price":0.90301,"qty":1107.40744842},{"price":0.90300,"qty":1107.41971207},{"price":0.90299,"qty":1107.43197599},{"price":0.90298,"qty":2214.88848036},{"price":0.90297,"qty":1107.45650464},{"price":0.90296,"qty":2214.93753876}],"asks":[{"price":0.90334,"qty":1645.38070077},{"price":0.90335,"qty":498.42003632},{"price":0.90350,"qty":20.00000000},{"price":0.90351,"qty":3477.01647979},{"price":0.90352,"qty":6349.85924750},{"price":0.90405,"qty":749.61774687},{"price":0.90406,"qty":371.39430000},{"price":0.90426,"qty":578.65910373},{"price":0.90427,"qty":49034.07891406},{"price":0.90430,"qty":5901.00000000}],"checksum":691251371}]}
{"channel":"book","type":"update","data":[{"symbol":"USD/CHF","bids":[],"asks":[{"price":0.90427,"qty":0.00000000},{"price":0.90439,"qty":8502.00000000}],"checksum":1051501233,"timestamp":"2024-06-01T22:43:51.100583Z"}]}
{"channel":"book","type":"update","data":[{"symbol":"USD/CHF","bids":[],"asks":[{"price":0.90425,"qty":13887.78055078}],"checksum":1982328741,"timestamp":"2024-06-01T22:43:51.106736Z"}]}
{"channel":"book","type":"update","data":[{"symbol":"USD/CHF","bids":[],"asks":[{"price":0.90429,"qty":36565.88104441}],"checksum":2834490626,"timestamp":"2024-06-01T22:43:51.106944Z"}]}
{"channel":"book","type":"update","data":[{"symbol":"USD/CHF","bids":[{"price":0.90303,"qty":1071.32719112}],"asks":[],"checksum":1832625692,"timestamp":"2024-06-01T22:43:51.388189Z"}]}
{"channel":"book","type":"update","data":[{"symbol":"USD/CHF","bids":[{"price":0.90305,"qty":3951.17187500}],"asks":[],"checksum":3221256012,"timestamp":"2024-06-01T22:43:51.388995Z"}]}
{"channel":"book","type":"update","data":[{"symbol":"USD/CHF","bids":[{"price":0.90304,"qty":0.00000000},{"price":0.90296,"qty":2214.93753876},{"price":0.90306,"qty":3922.03751115}],"asks":[],"checksum":2823580038,"timestamp":"2024-06-01T22:43:51.392716Z"}]}
{"channel":"book","type":"update","data":[{"symbol":"USD/CHF","bids":[{"price":0.90309,"qty":0.00000000},{"price":0.90296,"qty":2214.93753876}],"asks":[],"checksum":3805973622,"timestamp":"2024-06-01T22:43:53.470670Z"}]}
{"channel":"book","type":"update","data":[{"symbol":"USD/CHF","bids":[{"price":0.90307,"qty":93.16894531}],"asks":[],"checksum":358105045,"timestamp":"2024-06-01T22:43:53.471521Z"}]}
{"channel":"book","type":"update","data":[{"symbol":"USD/CHF","bids":[{"price":0.90306,"qty":0.00000000},{"price":0.90296,"qty":2214.93753876},{"price":0.90308,"qty":3921.94655334}],"asks":[],"checksum":2241038807,"timestamp":"2024-06-01T22:43:53.475300Z"}]}
{"channel":"book","type":"update","data":[{"symbol":"USD/CHF","bids":[{"price":0.90305,"qty":0.00000000},{"price":0.90296,"qty":2214.93753876}],"asks":[],"checksum":4201319897,"timestamp":"2024-06-01T22:43:53.565283Z"}]}
{"channel":"book","type":"update","data":[{"symbol":"USD/CHF","bids":[{"price":0.90307,"qty":2093.16894531}],"asks":[],"checksum":76157694,"timestamp":"2024-06-01T22:43:53.566690Z"}]}
{"channel":"book","type":"update","data":[{"symbol":"USD/CHF","bids":[{"price":0.90304,"qty":3951.17187500}],"asks":[],"checksum":102231264,"timestamp":"2024-06-01T22:43:53.566859Z"}]}
{"channel":"book","type":"update","data":[{"symbol":"USD/CHF","bids":[{"price":0.90308,"qty":0.00000000},{"price":0.90296,"qty":2214.93753876},{"price":0.90304,"qty":7873.29198767}],"asks":[],"checksum":3299455014,"timestamp":"2024-06-01T22:43:53.568627Z"}]}
{"channel":"book","type":"update","data":[{"symbol":"USD/CHF","bids":[{"price":0.90304,"qty":3951.17187500},{"price":0.90308,"qty":3921.94639074}],"asks":[],"checksum":84509616,"timestamp":"2024-06-01T22:43:53.572631Z"}]}
{"channel":"book","type":"update","data":[{"symbol":"USD/CHF","bids":[],"asks":[{"price":0.90426,"qty":0.00000000},{"price":0.90430,"qty":5901.00000000}],"checksum":2287694945,"timestamp":"2024-06-01T22:43:53.577312Z"}]}
{"channel":"book","type":"update","data":[{"symbol":"USD/CHF","bids":[],"asks":[{"price":0.90424,"qty":578.65910373}],"checksum":2075284228,"timestamp":"2024-06-01T22:43:53.587012Z"}]}
{"channel":"book","type":"update","data":[{"symbol":"USD/CHF","bids":[],"asks":[{"price":0.90425,"qty":0.00000000},{"price":0.90430,"qty":5901.00000000}],"checksum":4139403473,"timestamp":"2024-06-01T22:43:54.467262Z"}]}
{"channel":"book","type":"update","data":[{"symbol":"USD/CHF","bids":[],"asks":[{"price":0.90429,"qty":0.00000000},{"price":0.90439,"qty":8502.00000000}],"checksum":69782941,"timestamp":"2024-06-01T22:43:54.467379Z"}]}
{"channel":"book","type":"update","data":[{"symbol":"USD/CHF","bids":[],"asks":[{"price":0.90429,"qty":50539.61459649}],"checksum":2171954199,"timestamp":"2024-06-01T22:43:54.473294Z"}]}
{"channel":"book","type":"update","data":[{"symbol":"USD/CHF","bids":[],"asks":[{"price":0.90350,"qty":518.42003632}],"checksum":2612852952,"timestamp":"2024-06-01T22:43:55.419876Z"}]}
{"channel":"book","type":"update","data":[{"symbol":"USD/CHF","bids":[{"price":0.90307,"qty":93.16894531}],"asks":[],"checksum":1205457614,"timestamp":"2024-06-01T22:43:55.575483Z"}]}
{"channel":"book","type":"update","data":[{"symbol":"USD/CHF","bids":[{"price":0.90304,"qty":0.00000000},{"price":0.90296,"qty":2214.93753876}],"asks":[],"checksum":1162095824,"timestamp":"2024-06-01T22:43:55.575832Z"}]}
{"channel":"book","type":"update","data":[{"symbol":"USD/CHF","bids":[{"price":0.90304,"qty":2000.00000000}],"asks":[],"checksum":224449499,"timestamp":"2024-06-01T22:43:55.576832Z"}]}
{"channel":"book","type":"update","data":[{"symbol":"USD/CHF","bids":[],"asks":[{"price":0.90335,"qty":0.00000000},{"price":0.90439,"qty":8502.00000000}],"checksum":1075185557,"timestamp":"2024-06-01T22:43:55.588483Z"}]}
{"channel":"book","type":"update","data":[{"symbol":"USD/CHF","bids":[{"price":0.90308,"qty":0.00000000},{"price":0.90296,"qty":2214.93753876},{"price":0.90304,"qty":5922.15444181}],"asks":[],"checksum":424436909,"timestamp":"2024-06-01T22:43:55.591270Z"}]}
{"channel":"book","type":"update","data":[{"symbol":"USD/CHF","bids":[{"price":0.90304,"qty":2000.00000000},{"price":0.90308,"qty":3921.98071835}],"asks":[],"checksum":2614216142,"timestamp":"2024-06-01T22:43:55.594476Z"}]}
{"channel":"book","type":"update","data":[{"symbol":"USD/CHF","bids":[],"asks":[{"price":0.90334,"qty":0.00000000},{"price":0.90457,"qty":20503.00000000},{"price":0.90349,"qty":1652.57609126}],"checksum":1682906140,"timestamp":"2024-06-01T22:43:55.595320Z"}]}
{"channel":"book","type":"update","data":[{"symbol":"USD/CHF","bids":[{"price":0.90308,"qty":0.00000000},{"price":0.90296,"qty":2214.93753876},{"price":0.90309,"qty":3921.93728989}],"asks":[],"checksum":125760657,"timestamp":"2024-06-01T22:43:55.600701Z"}]}
{"channel":"book","type":"update","data":[{"symbol":"USD/CHF","bids":[{"price":0.90309,"qty":0.00000000},{"price":0.90296,"qty":2214.93753876},{"price":0.90310,"qty":3921.89386239}],"asks":[],"checksum":2414439996,"timestamp":"2024-06-01T22:43:55.607779Z"}]}
{"channel":"book","type":"update","data":[{"symbol":"USD/CHF","bids":[{"price":0.90310,"qty":0.00000000},{"price":0.90296,"qty":2214.93753876},{"price":0.90308,"qty":3921.98071835}],"asks":[],"checksum":1682906140,"timestamp":"2024-06-01T22:43:55.611282Z"}]}
{"channel":"book","type":"update","data":[{"symbol":"USD/CHF","bids":[{"price":0.90307,"qty":0.00000000},{"price":0.90296,"qty":2214.93753876}],"asks":[],"checksum":347464325,"timestamp":"2024-06-01T22:43:56.004330Z"}]}
{"channel":"book","type":"update","data":[{"symbol":"USD/CHF","bids":[{"price":0.90309,"qty":78.53515625}],"asks":[],"checksum":2733957969,"timestamp":"2024-06-01T22:43:56.006061Z"}]}
{"channel":"book","type":"update","data":[{"symbol":"USD/CHF","bids":[{"price":0.90308,"qty":0.00000000},{"price":0.90296,"qty":2214.93753876},{"price":0.90305,"qty":3922.11131083}],"asks":[],"checksum":1758834236,"timestamp":"2024-06-01T22:43:56.007566Z"}]}
{"channel":"book","type":"update","data":[{"symbol":"USD/CHF","bids":[],"asks":[{"price":0.90424,"qty":0.00000000},{"price":0.90457,"qty":20503.00000000}],"checksum":50752863,"timestamp":"2024-06-01T22:43:56.412942Z"}]}
{"channel":"book","type":"update","data":[{"symbol":"USD/CHF","bids":[],"asks":[{"price":0.90350,"qty":498.42003632}],"checksum":1229516689,"timestamp":"2024-06-01T22:43:56.413000Z"}]}
{"channel":"book","type":"update","data":[{"symbol":"USD/CHF","bids":[],"asks":[{"price":0.90348,"qty":37.53512436}],"checksum":1067698254,"timestamp":"2024-06-01T22:43:56.417554Z"}]}
{"channel":"book","type":"update","data":[{"symbol":"USD/CHF","bids":[],"asks":[{"price":0.90428,"qty":560.98698621}],"checksum":4274416497,"timestamp":"2024-06-01T22:43:56.417747Z"}]}
{"channel":"book","type":"update","data":[{"symbol":"USD/CHF","bids":[{"price":0.90304,"qty":0.00000000},{"price":0.90296,"qty":2214.93753876}],"asks":[],"checksum":3068302458,"timestamp":"2024-06-01T22:43:57.702991Z"}]}
{"channel":"book","type":"update","data":[{"symbol":"USD/CHF","bids":[{"price":0.90306,"qty":5902.34375000}],"asks":[],"checksum":3345469029,"timestamp":"2024-06-01T22:43:57.703956Z"}]}
{"channel":"book","type":"update","data":[{"symbol":"USD/CHF","bids":[{"price":0.90305,"qty":0.00000000},{"price":0.90296,"qty":2214.93753876},{"price":0.90304,"qty":3922.20088774}],"asks":[],"checksum":3446320610,"timestamp":"2024-06-01T22:43:57.715034Z"}]}
{"channel":"book","type":"update","data":[{"symbol":"USD/CHF","bids":[{"price":0.90304,"qty":0.00000000},{"price":0.90296,"qty":2214.93753876},{"price":0.90310,"qty":3921.94030524}],"asks":[],"checksum":3380869534,"timestamp":"2024-06-01T22:43:57.718308Z"}]}
{"channel":"book","type":"update","data":[{"symbol":"USD/CHF","bids":[],"asks":[{"price":0.90351,"qty":0.00000000},{"price":0.90439,"qty":8502.00000000}],"checksum":850505886,"timestamp":"2024-06-01T22:43:57.941027Z"}]}
{"channel":"book","type":"update","data":[{"symbol":"USD/CHF","bids":[],"asks":[{"price":0.90429,"qty":0.00000000},{"price":0.90457,"qty":20503.00000000}],"checksum":3810465315,"timestamp":"2024-06-01T22:43:57.941063Z"}]}
{"channel":"book","type":"update","data":[{"symbol":"USD/CHF","bids":[],"asks":[{"price":0.90348,"qty":6495.45283090}],"checksum":2878264701,"timestamp":"2024-06-01T22:43:57.946671Z"}]}
{"channel":"book","type":"update","data":[{"symbol":"USD/CHF","bids":[],"asks":[{"price":0.90427,"qty":47516.29472104}],"checksum":3059701501,"timestamp":"2024-06-01T22:43:57.946724Z"}]}
{"channel":"book","type":"update","data":[{"symbol":"USD/CHF","bids":[],"asks":[{"price":0.90349,"qty":0.00000000},{"price":0.90457,"qty":20503.00000000},{"price":0.90347,"qty":1652.70927504}],"checksum":3626311809,"timestamp":"2024-06-01T22:43:57.949776Z"}]}
{"channel":"book","type":"update","data":[{"symbol":"USD/CHF","bids":[{"price":0.90309,"qty":0.00000000},{"price":0.90296,"qty":2214.93753876}],"asks":[],"checksum":3129418613,"timestamp":"2024-06-01T22:43:58.585439Z"}]}
{"channel":"book","type":"update","data":[{"symbol":"USD/CHF","bids":[{"price":0.90311,"qty":78.53515625}],"asks":[],"checksum":2629159488,"timestamp":"2024-06-01T22:43:58.586667Z"}]}
{"channel":"book","type":"update","data":[{"symbol":"USD/CHF","bids":[{"price":0.90310,"qty":0.00000000},{"price":0.90296,"qty":2214.93753876},{"price":0.90307,"qty":3922.09320166}],"asks":[],"checksum":1493808811,"timestamp":"2024-06-01T22:43:58.589126Z"}]}
{"channel":"book","type":"update","data":[{"symbol":"USD/CHF","bids":[],"asks":[{"price":0.90348,"qty":6457.91770654}],"checksum":3044535273,"timestamp":"2024-06-01T22:43:59.583402Z"}]}
{"channel":"book","type":"update","data":[{"symbol":"USD/CHF","bids":[],"asks":[{"price":0.90428,"qty":0.00000000},{"price":0.90457,"qty":20503.00000000}],"checksum":3440703282,"timestamp":"2024-06-01T22:43:59.583538Z"}]}
{"channel":"book","type":"update","data":[{"symbol":"USD/CHF","bids":[],"asks":[{"price":0.90426,"qty":560.98698621}],"checksum":3247254487,"timestamp":"2024-06-01T22:43:59.589801Z"}]}
{"channel":"book","type":"update","data":[{"symbol":"USD/CHF","bids":[],"asks":[{"price":0.90346,"qty":37.53512436}],"checksum":547758369,"timestamp":"2024-06-01T22:43:59.589833Z"}]}
{"channel":"book","type":"update","data":[{"symbol":"USD/CHF","bids":[{"price":0.90306,"qty":0.00000000},{"price":0.90296,"qty":2214.93753876}],"asks":[],"checksum":2804888658,"timestamp":"2024-06-01T22:43:59.851172Z"}]}
{"channel":"book","type":"update","data":[{"symbol":"USD/CHF","bids":[{"price":0.90308,"qty":2000.00000000}],"asks":[],"checksum":3517200718,"timestamp":"2024-06-01T22:43:59.852402Z"}]}
{"channel":"book","type":"update","data":[{"symbol":"USD/CHF","bids":[{"price":0.90304,"qty":5902.34375000}],"asks":[],"checksum":3475851932,"timestamp":"2024-06-01T22:43:59.852644Z"}]}
{"channel":"book","type":"update","data":[{"symbol":"USD/CHF","bids":[{"price":0.90307,"qty":0.00000000},{"price":0.90297,"qty":1107.45650464},{"price":0.90304,"qty":9824.56836105}],"asks":[],"checksum":264024732,"timestamp":"2024-06-01T22:43:59.854332Z"}]}
{"channel":"book","type":"update","data":[{"symbol":"USD/CHF","bids":[{"price":0.90304,"qty":5902.34375000},{"price":0.90309,"qty":3922.00745525}],"asks":[],"checksum":229602113,"timestamp":"2024-06-01T22:43:59.858802Z"}]}
{"channel":"book","type":"update","data":[{"symbol":"USD/CHF","bids":[{"price":0.90311,"qty":0.00000000},{"price":0.90297,"qty":1107.45650464}],"asks":[],"checksum":2600280290,"timestamp":"2024-06-01T22:44:01.079509Z"}]}
{"channel":"book","type":"update","data":[{"symbol":"USD/CHF","bids":[{"price":0.90310,"qty":105.36376953}],"asks":[],"checksum":524302095,"timestamp":"2024-06-01T22:44:01.080651Z"}]}
{"channel":"book","type":"update","data":[{"symbol":"USD/CHF","bids":[{"price":0.90309,"qty":0.00000000},{"price":0.90297,"qty":1107.45650464},{"price":0.90311,"qty":3921.96537462}],"asks":[],"checksum":3520701609,"timestamp":"2024-06-01T22:44:01.084331Z"}]}
{"channel":"book","type":"update","data":[{"symbol":"USD/CHF","bids":[],"asks":[{"price":0.90348,"qty":0.00000000},{"price":0.90439,"qty":8502.00000000}],"checksum":645627286,"timestamp":"2024-06-01T22:44:01.362556Z"}]}
{"channel":"book","type":"update","data":[{"symbol":"USD/CHF","bids":[],"asks":[{"price":0.90427,"qty":0.00000000},{"price":0.90457,"qty":20503.00000000}],"checksum":3632006191,"timestamp":"2024-06-01T22:44:01.362762Z"}]}
{"channel":"book","type":"update","data":[{"symbol":"USD/CHF","bids":[],"asks":[{"price":0.90347,"qty":0.00000000},{"price":0.90466,"qty":2505.00000000},{"price":0.90349,"qty":1652.73956692}],"checksum":3384621743,"timestamp":"2024-06-01T22:44:01.366195Z"}]}
{"channel":"book","type":"update","data":[{"symbol":"USD/CHF","bids":[],"asks":[{"price":0.90425,"qty":13810.33439661}],"checksum":4186469549,"timestamp":"2024-06-01T22:44:01.367018Z"}]}
{"channel":"book","type":"update","data":[{"symbol":"USD/CHF","bids":[],"asks":[{"price":0.90429,"qty":34826.56028162}],"checksum":1997421866,"timestamp":"2024-06-01T22:44:01.367098Z"}]}
{"channel":"book","type":"update","data":[{"symbol":"USD/CHF","bids":[],"asks":[{"price":0.90346,"qty":6466.41052309}],"checksum":168054065,"timestamp":"2024-06-01T22:44:01.367244Z"}]}
{"channel":"book","type":"update","data":[{"symbol":"USD/CHF","bids":[],"asks":[{"price":0.90349,"qty":0.00000000},{"price":0.90439,"qty":8502.00000000},{"price":0.90345,"qty":1652.73956692}],"checksum":116484904,"timestamp":"2024-06-01T22:44:01.370725Z"}]}
{"channel":"book","type":"update","data":[{"symbol":"USD/CHF","bids":[{"price":0.90308,"qty":0.00000000},{"price":0.90297,"qty":1107.45650464}],"asks":[],"checksum":1580348577,"timestamp":"2024-06-01T22:44:01.821043Z"}]}
{"channel":"book","type":"update","data":[{"symbol":"USD/CHF","bids":[{"price":0.90311,"qty":0.00000000},{"price":0.90296,"qty":2214.93753876},{"price":0.90305,"qty":3922.22620140}],"asks":[],"checksum":3679944289,"timestamp":"2024-06-01T22:44:01.824385Z"}]}
{"channel":"book","type":"update","data":[{"symbol":"USD/CHF","bids":[],"asks":[{"price":0.90344,"qty":498.42003632}],"checksum":3517183619,"timestamp":"2024-06-01T22:44:01.984383Z"}]}
{"channel":"book","type":"update","data":[{"symbol":"USD/CHF","bids":[],"asks":[{"price":0.90345,"qty":0.00000000},{"price":0.90430,"qty":5901.00000000},{"price":0.90343,"qty":1652.73976350}],"checksum":2172920085,"timestamp":"2024-06-01T22:44:01.987886Z"}]}
{"channel":"book","type":"update","data":[{"symbol":"USD/CHF","bids":[],"asks":[{"price":0.90350,"qty":0.00000000},{"price":0.90430,"qty":5901.00000000}],"checksum":2216368045,"timestamp":"2024-06-01T22:44:02.152268Z"}]}
{"channel":"book","type":"update","data":[{"symbol":"USD/CHF","bids":[],"asks":[{"price":0.90346,"qty":6428.87539873}],"checksum":2845189137,"timestamp":"2024-06-01T22:44:02.966907Z"}]}
{"channel":"book","type":"update","data":[{"symbol":"USD/CHF","bids":[],"asks":[{"price":0.90426,"qty":0.00000000},{"price":0.90439,"qty":8502.00000000}],"checksum":3333011252,"timestamp":"2024-06-01T22:44:02.967009Z"}]}
{"channel":"book","type":"update","data":[{"symbol":"USD/CHF","bids":[],"asks":[{"price":0.90342,"qty":20.00000000}],"checksum":2933482688,"timestamp":"2024-06-01T22:44:02.976249Z"}]}
{"channel":"book","type":"update","data":[{"symbol":"USD/CHF","bids":[],"asks":[{"price":0.90424,"qty":578.65910373}],"checksum":886344168,"timestamp":"2024-06-01T22:44:02.976425Z"}]}
{"channel":"book","type":"update","data":[{"symbol":"USD/CHF","bids":[{"price":0.90310,"qty":0.00000000},{"price":0.90296,"qty":2214.93753876}],"asks":[],"checksum":754162710,"timestamp":"2024-06-01T22:44:03.534774Z"}]}
{"channel":"book","type":"update","data":[{"symbol":"USD/CHF","bids":[{"price":0.90306,"qty":105.36376953}],"asks":[],"checksum":2113513849,"timestamp":"2024-06-01T22:44:03.535974Z"}]}
{"channel":"book","type":"update","data":[{"symbol":"USD/CHF","bids":[{"price":0.90305,"qty":0.00000000},{"price":0.90296,"qty":2214.93753876},{"price":0.90307,"qty":3922.11652479}],"asks":[],"checksum":1398833778,"timestamp":"2024-06-01T22:44:03.539917Z"}]}
{"channel":"book","type":"update","data":[{"symbol":"USD/CHF","bids":[{"price":0.90308,"qty":2000.00000000}],"asks":[],"checksum":1799950908,"timestamp":"2024-06-01T22:44:03.934333Z"}]}
{"channel":"book","type":"update","data":[{"symbol":"USD/CHF","bids":[{"price":0.90307,"qty":0.00000000},{"price":0.90297,"qty":1107.45650464},{"price":0.90309,"qty":3922.02972546}],"asks":[],"checksum":3433278646,"timestamp":"2024-06-01T22:44:03.938635Z"}]}
{"channel":"book","type":"update","data":[{"symbol":"USD/CHF","bids":[],"asks":[{"price":0.90425,"qty":0.00000000},{"price":0.90430,"qty":5901.00000000}],"checksum":2146675190,"timestamp":"2024-06-01T22:44:04.765146Z"}]}
{"channel":"book","type":"update","data":[{"symbol":"USD/CHF","bids":[],"asks":[{"price":0.90429,"qty":0.00000000},{"price":0.90439,"qty":8502.00000000}],"checksum":4061266501,"timestamp":"2024-06-01T22:44:04.765168Z"}]}
{"channel":"book","type":"update","data":[{"symbol":"USD/CHF","bids":[],"asks":[{"price":0.90346,"qty":0.00000000},{"price":0.90457,"qty":20503.00000000}],"checksum":1159014455,"timestamp":"2024-06-01T22:44:04.765177Z"}]}
{"channel":"book","type":"update","data":[{"symbol":"USD/CHF","bids":[],"asks":[{"price":0.90342,"qty":4991.94513770}],"checksum":2766914820,"timestamp":"2024-06-01T22:44:04.770479Z"}]}
{"channel":"book","type":"update","data":[{"symbol":"USD/CHF","bids":[],"asks":[{"price":0.90429,"qty":49013.15087804}],"checksum":252189924,"timestamp":"2024-06-01T22:44:04.770705Z"}]}
{"channel":"book","type":"update","data":[{"symbol":"USD/CHF","bids":[],"asks":[{"price":0.90343,"qty":0.00000000},{"price":0.90457,"qty":20503.00000000},{"price":0.90341,"qty":1652.51257556}],"checksum":2900857588,"timestamp":"2024-06-01T22:44:04.773850Z"}]}
{"channel":"book","type":"update","data":[{"symbol":"USD/CHF","bids":[],"asks":[{"price":0.90424,"qty":0.00000000},{"price":0.90457,"qty":20503.00000000}],"checksum":1320487089,"timestamp":"2024-06-01T22:44:05.967962Z"}]}
{"channel":"book","type":"update","data":[{"symbol":"USD/CHF","bids":[],"asks":[{"price":0.90342,"qty":4971.94513770}],"checksum":2171665663,"timestamp":"2024-06-01T22:44:05.968390Z"}]}
{"channel":"book","type":"update","data":[{"symbol":"USD/CHF","bids":[],"asks":[{"price":0.90428,"qty":598.65910373}],"checksum":3350901494,"timestamp":"2024-06-01T22:44:05.972770Z"}]}
{"channel":"book","type":"update","data":[{"symbol":"USD/CHF","bids":[{"price":0.90308,"qty":0.00000000},{"price":0.90297,"qty":1107.45650464}],"asks":[],"checksum":2741377390,"timestamp":"2024-06-01T22:44:06.018359Z"}]}
{"channel":"book","type":"update","data":[{"symbol":"USD/CHF","bids":[{"price":0.90309,"qty":0.00000000},{"price":0.90296,"qty":2214.93753876},{"price":0.90307,"qty":3922.10739327}],"asks":[],"checksum":2958453206,"timestamp":"2024-06-01T22:44:06.021598Z"}]}
{"channel":"book","type":"update","data":[{"symbol":"USD/CHF","bids":[{"price":0.90306,"qty":0.00000000},{"price":0.90296,"qty":2214.93753876}],"asks":[],"checksum":2940385158,"timestamp":"2024-06-01T22:44:06.043378Z"}]}
{"channel":"book","type":"update","data":[{"symbol":"USD/CHF","bids":[{"price":0.90310,"qty":78.53515625}],"asks":[],"checksum":3198185212,"timestamp":"2024-06-01T22:44:06.045235Z"}]}
{"channel":"book","type":"update","data":[{"symbol":"USD/CHF","bids":[{"price":0.90307,"qty":0.00000000},{"price":0.90296,"qty":2214.93753876},{"price":0.90305,"qty":3922.19425684}],"asks":[],"checksum":3897847037,"timestamp":"2024-06-01T22:44:06.046635Z"}]}
{"channel":"book","type":"update","data":[{"symbol":"USD/CHF","bids":[{"price":0.90304,"qty":0.00000000},{"price":0.90296,"qty":2214.93753876}],"asks":[],"checksum":2501348782,"timestamp":"2024-06-01T22:44:08.086533Z"}]}
{"channel":"book","type":"update","data":[{"symbol":"USD/CHF","bids":[{"price":0.90306,"qty":7853.51562500}],"asks":[],"checksum":132821221,"timestamp":"2024-06-01T22:44:08.088097Z"}]}
{"channel":"book","type":"update","data":[{"symbol":"USD/CHF","bids":[{"price":0.90305,"qty":0.00000000},{"price":0.90296,"qty":2214.93753876},{"price":0.90304,"qty":3922.24515111}],"asks":[],"checksum":2461430674,"timestamp":"2024-06-01T22:44:08.089740Z"}]}
{"channel":"book","type":"update","data":[{"symbol":"USD/CHF","bids":[{"price":0.90304,"qty":0.00000000},{"price":0.90296,"qty":2214.93753876},{"price":0.90307,"qty":3922.11489828}],"asks":[],"checksum":175723105,"timestamp":"2024-06-01T22:44:08.093767Z"}]}
{"channel":"book","type":"update","data":[{"symbol":"USD/CHF","bids":[],"asks":[{"price":0.90342,"qty":0.00000000},{"price":0.90457,"qty":20503.00000000}],"checksum":342319928,"timestamp":"2024-06-01T22:44:08.250666Z"}]}
{"channel":"book","type":"update","data":[{"symbol":"USD/CHF","bids":[],"asks":[{"price":0.90429,"qty":0.00000000},{"price":0.90466,"qty":2505.00000000}],"checksum":265968601,"timestamp":"2024-06-01T22:44:08.250914Z"}]}
{"channel":"book","type":"update","data":[{"symbol":"USD/CHF","bids":[],"asks":[{"price":0.90341,"qty":0.00000000},{"price":0.90475,"qty":2504.00000000},{"price":0.90343,"qty":1657.72101649}],"checksum":2353902153,"timestamp":"2024-06-01T22:44:08.254046Z"}]}
{"channel":"book","type":"update","data":[{"symbol":"USD/CHF","bids":[],"asks":[{"price":0.90427,"qty":50510.73260758}],"checksum":3073958637,"timestamp":"2024-06-01T22:44:08.256511Z"}]}
{"channel":"book","type":"update","data":[{"symbol":"USD/CHF","bids":[],"asks":[{"price":0.90340,"qty":3485.97256885}],"checksum":3074465645,"timestamp":"2024-06-01T22:44:08.256554Z"}]}
{"channel":"book","type":"update","data":[{"symbol":"USD/CHF","bids":[],"asks":[{"price":0.90343,"qty":0.00000000},{"price":0.90457,"qty":20503.00000000},{"price":0.90339,"qty":1657.72101649}],"checksum":2758011567,"timestamp":"2024-06-01T22:44:08.260252Z"}]}
{"channel":"book","type":"update","data":[{"symbol":"USD/CHF","bids":[{"price":0.90310,"qty":0.00000000},{"price":0.90296,"qty":2214.93753876}],"asks":[],"checksum":1371379941,"timestamp":"2024-06-01T22:44:08.579433Z"}]}
{"channel":"book","type":"update","data":[{"symbol":"USD/CHF","bids":[{"price":0.90308,"qty":93.16894531}],"asks":[],"checksum":1561354266,"timestamp":"2024-06-01T22:44:08.580787Z"}]}
{"channel":"book","type":"update","data":[{"symbol":"USD/CHF","bids":[{"price":0.90307,"qty":0.00000000},{"price":0.90296,"qty":2214.93753876},{"price":0.90309,"qty":3922.01033486}],"asks":[],"checksum":1779330554,"timestamp":"2024-06-01T22:44:08.584864Z"}]}
{"channel":"book","type":"update","data":[{"symbol":"USD/CHF","bids":[{"price":0.90306,"qty":0.00000000},{"price":0.90296,"qty":2214.93753876}],"asks":[],"checksum":2071076208,"timestamp":"2024-06-01T22:44:10.157623Z"}]}
{"channel":"book","type":"update","data":[{"symbol":"USD/CHF","bids":[{"price":0.90304,"qty":5902.34375000}],"asks":[],"checksum":103939107,"timestamp":"2024-06-01T22:44:10.158385Z"}]}
{"channel":"book","type":"update","data":[{"symbol":"USD/CHF","bids":[{"price":0.90309,"qty":0.00000000},{"price":0.90296,"qty":2214.93753876},{"price":0.90304,"qty":9824.56593964}],"asks":[],"checksum":2625248692,"timestamp":"2024-06-01T22:44:10.161350Z"}]}
{"channel":"book","type":"update","data":[{"symbol":"USD/CHF","bids":[{"price":0.90304,"qty":5902.34375000},{"price":0.90305,"qty":3922.17875659}],"asks":[],"checksum":131952694,"timestamp":"2024-06-01T22:44:10.165407Z"}]}
{"channel":"book","type":"update","data":[{"symbol":"USD/CHF","bids":[{"price":0.90308,"qty":0.00000000},{"price":0.90296,"qty":2214.93753876}],"asks":[],"checksum":2171540508,"timestamp":"2024-06-01T22:44:11.092715Z"}]}
{"channel":"book","type":"update","data":[{"symbol":"USD/CHF","bids":[{"price":0.90306,"qty":98.04687500}],"asks":[],"checksum":2594293777,"timestamp":"2024-06-01T22:44:11.094219Z"}]}
{"channel":"book","type":"update","data":[{"symbol":"USD/CHF","bids":[{"price":0.90305,"qty":0.00000000},{"price":0.90296,"qty":2214.93753876},{"price":0.90307,"qty":3922.07719816}],"asks":[],"checksum":3839782407,"timestamp":"2024-06-01T22:44:11.103580Z"}]}
{"channel":"book","type":"update","data":[{"symbol":"USD/CHF","bids":[],"asks":[{"price":0.90427,"qty":0.00000000},{"price":0.90457,"qty":20503.00000000}],"checksum":280272063,"timestamp":"2024-06-01T22:44:11.688639Z"}]}
{"channel":"book","type":"update","data":[{"symbol":"USD/CHF","bids":[],"asks":[{"price":0.90340,"qty":0.00000000},{"price":0.90466,"qty":2505.00000000}],"checksum":733450451,"timestamp":"2024-06-01T22:44:11.688850Z"}]}
{"channel":"book","type":"update","data":[{"symbol":"USD/CHF","bids":[],"asks":[{"price":0.90339,"qty":0.00000000},{"price":0.90475,"qty":2504.00000000},{"price":0.90343,"qty":1656.50339457}],"checksum":596808296,"timestamp":"2024-06-01T22:44:11.692851Z"}]}
{"channel":"book","type":"update","data":[{"symbol":"USD/CHF","bids":[],"asks":[{"price":0.90338,"qty":2000.00000000}],"checksum":1779056976,"timestamp":"2024-06-01T22:44:11.694002Z"}]}
{"channel":"book","type":"update","data":[{"symbol":"USD/CHF","bids":[],"asks":[{"price":0.90351,"qty":3485.97256885}],"checksum":831131493,"timestamp":"2024-06-01T22:44:11.694145Z"}]}
{"channel":"book","type":"update","data":[{"symbol":"USD/CHF","bids":[],"asks":[{"price":0.90427,"qty":48510.73260758}],"checksum":661863502,"timestamp":"2024-06-01T22:44:11.694174Z"}]}
{"channel":"book","type":"update","data":[{"symbol":"USD/CHF","bids":[],"asks":[{"price":0.90343,"qty":0.00000000},{"price":0.90439,"qty":8502.00000000},{"price":0.90337,"qty":1656.50339457}],"checksum":1070098975,"timestamp":"2024-06-01T22:44:11.697303Z"}]}
{"channel":"book","type":"update","data":[{"symbol":"USD/CHF","bids":[],"asks":[{"price":0.90428,"qty":0.00000000},{"price":0.90439,"qty":8502.00000000}],"checksum":4264032100,"timestamp":"2024-06-01T22:44:11.857622Z"}]}
{"channel":"book","type":"update","data":[{"symbol":"USD/CHF","bids":[],"asks":[{"price":0.90426,"qty":598.65910373}],"checksum":3134756857,"timestamp":"2024-06-01T22:44:11.864722Z"}]}
{"channel":"book","type":"update","data":[{"symbol":"USD/CHF","bids":[{"price":0.90308,"qty":3951.17187500}],"asks":[],"checksum":655208769,"timestamp":"2024-06-01T22:44:12.231710Z"}]}
{"channel":"book","type":"update","data":[{"symbol":"USD/CHF","bids":[{"price":0.90307,"qty":0.00000000},{"price":0.90297,"qty":1107.45650464},{"price":0.90309,"qty":3921.99035713}],"asks":[],"checksum":2947439718,"timestamp":"2024-06-01T22:44:12.235038Z"}]}
{"channel":"book","type":"update","data":[{"symbol":"USD/CHF","bids":[{"price":0.90308,"qty":0.00000000},{"price":0.90297,"qty":1107.45650464}],"asks":[],"checksum":4193067174,"timestamp":"2024-06-01T22:44:13.304626Z"}]}
{"channel":"book","type":"update","data":[{"symbol":"USD/CHF","bids":[{"price":0.90309,"qty":0.00000000},{"price":0.90296,"qty":2214.93753876},{"price":0.90307,"qty":3922.07142281}],"asks":[],"checksum":2747165510,"timestamp":"2024-06-01T22:44:13.307891Z"}]}
{"channel":"book","type":"update","data":[{"symbol":"USD/CHF","bids":[{"price":0.90304,"qty":0.00000000},{"price":0.90296,"qty":2214.93753876}],"asks":[],"checksum":3741157909,"timestamp":"2024-06-01T22:44:14.285692Z"}]}
{"channel":"book","type":"update","data":[{"symbol":"USD/CHF","bids":[],"asks":[{"price":0.90336,"qty":498.42003632}],"checksum":3323818406,"timestamp":"2024-06-01T22:44:14.453763Z"}]}
{"channel":"book","type":"update","data":[{"symbol":"USD/CHF","bids":[],"asks":[{"price":0.90337,"qty":0.00000000},{"price":0.90430,"qty":5901.00000000},{"price":0.90335,"qty":1656.44794004}],"checksum":486876289,"timestamp":"2024-06-01T22:44:14.457039Z"}]}
{"channel":"book","type":"update","data":[{"symbol":"USD/CHF","bids":[],"asks":[{"price":0.90344,"qty":0.00000000},{"price":0.90430,"qty":5901.00000000}],"checksum":3260814647,"timestamp":"2024-06-01T22:44:14.620182Z"}]}
{"channel":"book","type":"update","data":[{"symbol":"USD/CHF","bids":[],"asks":[{"price":0.90338,"qty":0.00000000},{"price":0.90439,"qty":8502.00000000}],"checksum":3597966039,"timestamp":"2024-06-01T22:44:15.133075Z"}]}
{"channel":"book","type":"update","data":[{"symbol":"USD/CHF","bids":[],"asks":[{"price":0.90427,"qty":0.00000000},{"price":0.90457,"qty":20503.00000000}],"checksum":2544217986,"timestamp":"2024-06-01T22:44:15.133372Z"}]}
{"channel":"book","type":"update","data":[{"symbol":"USD/CHF","bids":[],"asks":[{"price":0.90425,"qty":13887.78055078}],"checksum":3176572539,"timestamp":"2024-06-01T22:44:15.139322Z"}]}
{"channel":"book","type":"update","data":[{"symbol":"USD/CHF","bids":[],"asks":[{"price":0.90429,"qty":35073.85467668}],"checksum":3017972676,"timestamp":"2024-06-01T22:44:15.139443Z"}]}
{"channel":"book","type":"update","data":[{"symbol":"USD/CHF","bids":[{"price":0.90306,"qty":0.00000000},{"price":0.90295,"qty":21034.98690288}],"asks":[],"checksum":1949223075,"timestamp":"2024-06-01T22:44:16.122987Z"}]}
{"channel":"book","type":"update","data":[{"symbol":"USD/CHF","bids":[{"price":0.90308,"qty":59.02343750}],"asks":[],"checksum":3722150747,"timestamp":"2024-06-01T22:44:16.124537Z"}]}
