{"channel":"book","type":"snapshot","data":[{"symbol":"USD/CAD","bids":[{"price":1.36676,"qty":137.20620000},{"price":1.36675,"qty":1550.73136786},{"price":1.36674,"qty":20.00000000},{"price":1.36671,"qty":2000.00000000},{"price":1.36663,"qty":364.48677681},{"price":1.36656,"qty":39.51171875},{"price":1.36655,"qty":5902.34375000},{"price":1.36654,"qty":11395.35572984},{"price":1.36641,"qty":182.04638432},{"price":1.36632,"qty":4792.00593005}],"asks":[{"price":1.36700,"qty":130.00277897},{"price":1.36702,"qty":260.43587771},{"price":1.36720,"qty":646.19380000},{"price":1.36721,"qty":3759.39882364},{"price":1.36724,"qty":371.39430000},{"price":1.36728,"qty":2767.88736429},{"price":1.36829,"qty":37.53512436},{"price":1.36830,"qty":3485.97256885},{"price":1.36831,"qty":3417.27454042},{"price":1.36871,"qty":157.81611920}],"checksum":3943474261}]}
{"channel":"book","type":"update","data":[{"symbol":"USD/CAD","bids":[],"asks":[{"price":1.36871,"qty":0.00000000},{"price":1.36874,"qty":16341.70760834}],"checksum":2295152407,"timestamp":"2024-06-01T22:43:53.577465Z"}]}
{"channel":"book","type":"update","data":[{"symbol":"USD/CAD","bids":[],"asks":[{"price":1.36873,"qty":157.81611919}],"checksum":1991290431,"timestamp":"2024-06-01T22:43:53.586706Z"}]}
{"channel":"book","type":"update","data":[{"symbol":"USD/CAD","bids":[{"price":1.36675,"qty":0.00000000},{"price":1.36631,"qty":1117.30712667},{"price":1.36677,"qty":1550.71108177}],"asks":[],"checksum":3797074331,"timestamp":"2024-06-01T22:43:53.991746Z"}]}
{"channel":"book","type":"update","data":[{"symbol":"USD/CAD","bids":[],"asks":[{"price":1.36721,"qty":0.00000000},{"price":1.36874,"qty":16341.70760834},{"price":1.36719,"qty":3759.39882364}],"checksum":404446346,"timestamp":"2024-06-01T22:43:53.991873Z"}]}
{"channel":"book","type":"update","data":[{"symbol":"USD/CAD","bids":[{"price":1.36676,"qty":0.00000000},{"price":1.36631,"qty":1117.30712667},{"price":1.36678,"qty":137.20620000}],"asks":[],"checksum":2791274393,"timestamp":"2024-06-01T22:43:54.007363Z"}]}
{"channel":"book","type":"update","data":[{"symbol":"USD/CAD","bids":[],"asks":[{"price":1.36720,"qty":0.00000000},{"price":1.36874,"qty":16341.70760834},{"price":1.36718,"qty":646.19380000}],"checksum":2427018112,"timestamp":"2024-06-01T22:43:54.039123Z"}]}
{"channel":"book","type":"update","data":[{"symbol":"USD/CAD","bids":[],"asks":[{"price":1.36831,"qty":0.00000000},{"price":1.36874,"qty":16341.70760834}],"checksum":2505687803,"timestamp":"2024-06-01T22:43:54.657301Z"}]}
{"channel":"book","type":"update","data":[{"symbol":"USD/CAD","bids":[],"asks":[{"price":1.36826,"qty":3417.27454042}],"checksum":3762779932,"timestamp":"2024-06-01T22:43:54.684863Z"}]}
{"channel":"book","type":"update","data":[{"symbol":"USD/CAD","bids":[],"asks":[{"price":1.36719,"qty":0.00000000},{"price":1.36874,"qty":16341.70760834},{"price":1.36717,"qty":3759.39882364}],"checksum":3674882114,"timestamp":"2024-06-01T22:43:54.760947Z"}]}
{"channel":"book","type":"update","data":[{"symbol":"USD/CAD","bids":[{"price":1.36677,"qty":0.00000000},{"price":1.36631,"qty":1117.30712667},{"price":1.36679,"qty":1550.68890411}],"asks":[],"checksum":2998407009,"timestamp":"2024-06-01T22:43:54.761009Z"}]}
{"channel":"book","type":"update","data":[{"symbol":"USD/CAD","bids":[{"price":1.36678,"qty":0.00000000},{"price":1.36631,"qty":1117.30712667},{"price":1.36680,"qty":137.20620000}],"asks":[],"checksum":1394047780,"timestamp":"2024-06-01T22:43:54.797893Z"}]}
{"channel":"book","type":"update","data":[{"symbol":"USD/CAD","bids":[{"price":1.36679,"qty":0.00000000},{"price":1.36631,"qty":1117.30712667},{"price":1.36672,"qty":1550.78527005}],"asks":[],"checksum":3517037086,"timestamp":"2024-06-01T22:43:54.801112Z"}]}
{"channel":"book","type":"update","data":[{"symbol":"USD/CAD","bids":[],"asks":[{"price":1.36718,"qty":0.00000000},{"price":1.36874,"qty":16341.70760834},{"price":1.36716,"qty":646.19380000}],"checksum":476502547,"timestamp":"2024-06-01T22:43:54.830225Z"}]}
{"channel":"book","type":"update","data":[{"symbol":"USD/CAD","bids":[{"price":1.36671,"qty":0.00000000},{"price":1.36631,"qty":1117.30712667}],"asks":[],"checksum":3882771976,"timestamp":"2024-06-01T22:43:55.002095Z"}]}
{"channel":"book","type":"update","data":[{"symbol":"USD/CAD","bids":[{"price":1.36672,"qty":0.00000000},{"price":1.36557,"qty":2199.89593041},{"price":1.36664,"qty":1550.87531106}],"asks":[],"checksum":2716011847,"timestamp":"2024-06-01T22:43:55.005435Z"}]}
{"channel":"book","type":"update","data":[{"symbol":"USD/CAD","bids":[],"asks":[{"price":1.36717,"qty":0.00000000},{"price":1.36874,"qty":16341.70760834},{"price":1.36715,"qty":3759.39882364}],"checksum":1490589875,"timestamp":"2024-06-01T22:43:55.596214Z"}]}
{"channel":"book","type":"update","data":[{"symbol":"USD/CAD","bids":[],"asks":[{"price":1.36716,"qty":0.00000000},{"price":1.36874,"qty":16341.70760834},{"price":1.36714,"qty":646.19380000}],"checksum":1229984375,"timestamp":"2024-06-01T22:43:55.618856Z"}]}
{"channel":"book","type":"update","data":[{"symbol":"USD/CAD","bids":[{"price":1.36656,"qty":0.00000000},{"price":1.36557,"qty":2199.89593041}],"asks":[],"checksum":2111415162,"timestamp":"2024-06-01T22:43:56.213447Z"}]}
{"channel":"book","type":"update","data":[{"symbol":"USD/CAD","bids":[{"price":1.36674,"qty":0.00000000},{"price":1.36551,"qty":776.15000000}],"asks":[],"checksum":2820684154,"timestamp":"2024-06-01T22:43:56.213561Z"}]}
{"channel":"book","type":"update","data":[{"symbol":"USD/CAD","bids":[{"price":1.36665,"qty":59.02343750}],"asks":[],"checksum":465399070,"timestamp":"2024-06-01T22:43:56.214842Z"}]}
{"channel":"book","type":"update","data":[{"symbol":"USD/CAD","bids":[{"price":1.36656,"qty":78.53515625}],"asks":[],"checksum":4059744797,"timestamp":"2024-06-01T22:43:56.215113Z"}]}
{"channel":"book","type":"update","data":[{"symbol":"USD/CAD","bids":[],"asks":[{"price":1.36829,"qty":0.00000000},{"price":1.36874,"qty":16341.70760834}],"checksum":685128593,"timestamp":"2024-06-01T22:43:56.412710Z"}]}
{"channel":"book","type":"update","data":[{"symbol":"USD/CAD","bids":[],"asks":[{"price":1.36825,"qty":37.53512436}],"checksum":547865321,"timestamp":"2024-06-01T22:43:56.417432Z"}]}
{"channel":"book","type":"update","data":[{"symbol":"USD/CAD","bids":[],"asks":[{"price":1.36715,"qty":0.00000000},{"price":1.36874,"qty":16341.70760834},{"price":1.36713,"qty":3759.39882364}],"checksum":3385993702,"timestamp":"2024-06-01T22:43:56.455901Z"}]}
{"channel":"book","type":"update","data":[{"symbol":"USD/CAD","bids":[{"price":1.36664,"qty":0.00000000},{"price":1.36557,"qty":2199.89593041},{"price":1.36666,"qty":1550.85120133}],"asks":[],"checksum":1233687649,"timestamp":"2024-06-01T22:43:56.455987Z"}]}
{"channel":"book","type":"update","data":[{"symbol":"USD/CAD","bids":[],"asks":[{"price":1.36714,"qty":0.00000000},{"price":1.36874,"qty":16341.70760834},{"price":1.36712,"qty":646.19380000}],"checksum":1113151615,"timestamp":"2024-06-01T22:43:56.468020Z"}]}
{"channel":"book","type":"update","data":[{"symbol":"USD/CAD","bids":[],"asks":[{"price":1.36713,"qty":0.00000000},{"price":1.36874,"qty":16341.70760834},{"price":1.36711,"qty":3759.39882364}],"checksum":797466232,"timestamp":"2024-06-01T22:43:57.323860Z"}]}
{"channel":"book","type":"update","data":[{"symbol":"USD/CAD","bids":[],"asks":[{"price":1.36712,"qty":0.00000000},{"price":1.36874,"qty":16341.70760834},{"price":1.36710,"qty":646.19380000}],"checksum":2867480399,"timestamp":"2024-06-01T22:43:57.346567Z"}]}
{"channel":"book","type":"update","data":[{"symbol":"USD/CAD","bids":[{"price":1.36655,"qty":0.00000000},{"price":1.36557,"qty":2199.89593041}],"asks":[],"checksum":3916757925,"timestamp":"2024-06-01T22:43:57.887554Z"}]}
{"channel":"book","type":"update","data":[{"symbol":"USD/CAD","bids":[{"price":1.36655,"qty":7853.51562500}],"asks":[],"checksum":3753208561,"timestamp":"2024-06-01T22:43:57.888571Z"}]}
{"channel":"book","type":"update","data":[{"symbol":"USD/CAD","bids":[{"price":1.36667,"qty":5902.34375000}],"asks":[],"checksum":1388696622,"timestamp":"2024-06-01T22:43:57.888609Z"}]}
{"channel":"book","type":"update","data":[{"symbol":"USD/CAD","bids":[],"asks":[{"price":1.36830,"qty":0.00000000},{"price":1.36874,"qty":16341.70760834}],"checksum":3952271841,"timestamp":"2024-06-01T22:43:57.940967Z"}]}
{"channel":"book","type":"update","data":[{"symbol":"USD/CAD","bids":[],"asks":[{"price":1.36874,"qty":0.00000000},{"price":1.36875,"qty":13500.40000000}],"checksum":2732027696,"timestamp":"2024-06-01T22:43:57.941015Z"}]}
{"channel":"book","type":"update","data":[{"symbol":"USD/CAD","bids":[],"asks":[{"price":1.36825,"qty":2037.53512436}],"checksum":3701593321,"timestamp":"2024-06-01T22:43:57.946293Z"}]}
{"channel":"book","type":"update","data":[{"symbol":"USD/CAD","bids":[],"asks":[{"price":1.36872,"qty":3485.97256885}],"checksum":763872492,"timestamp":"2024-06-01T22:43:57.946457Z"}]}
{"channel":"book","type":"update","data":[{"symbol":"USD/CAD","bids":[],"asks":[{"price":1.36701,"qty":130.00277897}],"checksum":486311120,"timestamp":"2024-06-01T22:43:58.056265Z"}]}
{"channel":"book","type":"update","data":[{"symbol":"USD/CAD","bids":[{"price":1.36666,"qty":0.00000000},{"price":1.36631,"qty":1117.30712667},{"price":1.36668,"qty":1550.72629982}],"asks":[],"checksum":2326240508,"timestamp":"2024-06-01T22:43:58.130314Z"}]}
{"channel":"book","type":"update","data":[{"symbol":"USD/CAD","bids":[],"asks":[{"price":1.36711,"qty":0.00000000},{"price":1.36873,"qty":157.81611919},{"price":1.36709,"qty":3759.39882364}],"checksum":1084301990,"timestamp":"2024-06-01T22:43:58.130357Z"}]}
{"channel":"book","type":"update","data":[{"symbol":"USD/CAD","bids":[],"asks":[{"price":1.36710,"qty":0.00000000},{"price":1.36873,"qty":157.81611919},{"price":1.36708,"qty":646.19380000}],"checksum":418977432,"timestamp":"2024-06-01T22:43:58.167774Z"}]}
{"channel":"book","type":"update","data":[{"symbol":"USD/CAD","bids":[],"asks":[{"price":1.36709,"qty":0.00000000},{"price":1.36873,"qty":157.81611919},{"price":1.36723,"qty":3759.39882364}],"checksum":953689064,"timestamp":"2024-06-01T22:43:58.170953Z"}]}
{"channel":"book","type":"update","data":[{"symbol":"USD/CAD","bids":[],"asks":[{"price":1.36700,"qty":0.00000000},{"price":1.36873,"qty":157.81611919}],"checksum":2518031502,"timestamp":"2024-06-01T22:43:58.263289Z"}]}
{"channel":"book","type":"update","data":[{"symbol":"USD/CAD","bids":[],"asks":[{"price":1.36723,"qty":0.00000000},{"price":1.36874,"qty":14341.70760834},{"price":1.36824,"qty":3759.39882364}],"checksum":814602507,"timestamp":"2024-06-01T22:43:58.264717Z"}]}
{"channel":"book","type":"update","data":[{"symbol":"USD/CAD","bids":[{"price":1.36668,"qty":0.00000000},{"price":1.36631,"qty":1117.30712667},{"price":1.36668,"qty":1945.79866990}],"asks":[],"checksum":1222616164,"timestamp":"2024-06-01T22:43:58.927624Z"}]}
{"channel":"book","type":"update","data":[{"symbol":"USD/CAD","bids":[],"asks":[{"price":1.36825,"qty":2000.00000000}],"checksum":2091484645,"timestamp":"2024-06-01T22:43:59.583306Z"}]}
{"channel":"book","type":"update","data":[{"symbol":"USD/CAD","bids":[],"asks":[{"price":1.36873,"qty":0.00000000},{"price":1.36874,"qty":14341.70760834}],"checksum":2777474,"timestamp":"2024-06-01T22:43:59.583415Z"}]}
{"channel":"book","type":"update","data":[{"symbol":"USD/CAD","bids":[],"asks":[{"price":1.36823,"qty":72.60537307}],"checksum":1448258276,"timestamp":"2024-06-01T22:43:59.589750Z"}]}
{"channel":"book","type":"update","data":[{"symbol":"USD/CAD","bids":[],"asks":[{"price":1.36871,"qty":122.74587049}],"checksum":4065007832,"timestamp":"2024-06-01T22:43:59.589812Z"}]}
{"channel":"book","type":"update","data":[{"symbol":"USD/CAD","bids":[],"asks":[{"price":1.36708,"qty":0.00000000},{"price":1.36872,"qty":3485.97256885},{"price":1.36723,"qty":646.19380000}],"checksum":3075417036,"timestamp":"2024-06-01T22:43:59.595346Z"}]}
{"channel":"book","type":"update","data":[{"symbol":"USD/CAD","bids":[{"price":1.36665,"qty":0.00000000},{"price":1.36631,"qty":1117.30712667}],"asks":[],"checksum":3603340626,"timestamp":"2024-06-01T22:43:59.614283Z"}]}
{"channel":"book","type":"update","data":[{"symbol":"USD/CAD","bids":[{"price":1.36656,"qty":0.00000000},{"price":1.36553,"qty":2199.96037121}],"asks":[],"checksum":364966919,"timestamp":"2024-06-01T22:43:59.614491Z"}]}
{"channel":"book","type":"update","data":[{"symbol":"USD/CAD","bids":[{"price":1.36669,"qty":59.02343750}],"asks":[],"checksum":3825982416,"timestamp":"2024-06-01T22:43:59.615112Z"}]}
{"channel":"book","type":"update","data":[{"symbol":"USD/CAD","bids":[],"asks":[{"price":1.36824,"qty":0.00000000},{"price":1.36872,"qty":3485.97256885},{"price":1.36722,"qty":3759.39882364}],"checksum":3270906344,"timestamp":"2024-06-01T22:43:59.825544Z"}]}
{"channel":"book","type":"update","data":[{"symbol":"USD/CAD","bids":[{"price":1.36668,"qty":0.00000000},{"price":1.36553,"qty":2199.96037121},{"price":1.36681,"qty":1945.61193398}],"asks":[],"checksum":2785833261,"timestamp":"2024-06-01T22:43:59.825614Z"}]}
{"channel":"book","type":"update","data":[{"symbol":"USD/CAD","bids":[{"price":1.36680,"qty":0.00000000},{"price":1.36553,"qty":2199.96037121},{"price":1.36682,"qty":137.20620000}],"asks":[],"checksum":2635932215,"timestamp":"2024-06-01T22:43:59.839162Z"}]}
{"channel":"book","type":"update","data":[{"symbol":"USD/CAD","bids":[{"price":1.36681,"qty":0.00000000},{"price":1.36553,"qty":2199.96037121},{"price":1.36670,"qty":1945.76846794}],"asks":[],"checksum":3172067661,"timestamp":"2024-06-01T22:43:59.842865Z"}]}
{"channel":"book","type":"update","data":[{"symbol":"USD/CAD","bids":[],"asks":[{"price":1.36723,"qty":0.00000000},{"price":1.36872,"qty":3485.97256885},{"price":1.36721,"qty":646.19380000}],"checksum":1933739597,"timestamp":"2024-06-01T22:43:59.871311Z"}]}
{"channel":"book","type":"update","data":[{"symbol":"USD/CAD","bids":[],"asks":[{"price":1.36722,"qty":0.00000000},{"price":1.36872,"qty":3485.97256885},{"price":1.36720,"qty":3759.39882364}],"checksum":3289696461,"timestamp":"2024-06-01T22:44:00.713789Z"}]}
{"channel":"book","type":"update","data":[{"symbol":"USD/CAD","bids":[],"asks":[{"price":1.36721,"qty":0.00000000},{"price":1.36872,"qty":3485.97256885},{"price":1.36719,"qty":646.19380000}],"checksum":3782116439,"timestamp":"2024-06-01T22:44:00.751485Z"}]}
{"channel":"book","type":"update","data":[{"symbol":"USD/CAD","bids":[{"price":1.36667,"qty":0.00000000},{"price":1.36553,"qty":2199.96037121}],"asks":[],"checksum":2161695366,"timestamp":"2024-06-01T22:44:00.779543Z"}]}
{"channel":"book","type":"update","data":[{"symbol":"USD/CAD","bids":[{"price":1.36671,"qty":5902.34375000}],"asks":[],"checksum":3108562338,"timestamp":"2024-06-01T22:44:00.780225Z"}]}
{"channel":"book","type":"update","data":[{"symbol":"USD/CAD","bids":[{"price":1.36670,"qty":0.00000000},{"price":1.36553,"qty":2199.96037121},{"price":1.36664,"qty":1945.26580794}],"asks":[],"checksum":2317635031,"timestamp":"2024-06-01T22:44:00.782770Z"}]}
{"channel":"book","type":"update","data":[{"symbol":"USD/CAD","bids":[],"asks":[{"price":1.36720,"qty":0.00000000},{"price":1.36874,"qty":17715.50159492},{"price":1.36718,"qty":3759.39882364}],"checksum":3869394733,"timestamp":"2024-06-01T22:44:01.596909Z"}]}
{"channel":"book","type":"update","data":[{"symbol":"USD/CAD","bids":[{"price":1.36664,"qty":0.00000000},{"price":1.36553,"qty":2199.96037121},{"price":1.36672,"qty":1945.15194316}],"asks":[],"checksum":3911794029,"timestamp":"2024-06-01T22:44:01.596938Z"}]}
{"channel":"book","type":"update","data":[{"symbol":"USD/CAD","bids":[],"asks":[{"price":1.36719,"qty":0.00000000},{"price":1.36874,"qty":17715.50159492},{"price":1.36717,"qty":646.19380000}],"checksum":2377230799,"timestamp":"2024-06-01T22:44:01.631495Z"}]}
{"channel":"book","type":"update","data":[{"symbol":"USD/CAD","bids":[{"price":1.36672,"qty":0.00000000},{"price":1.36553,"qty":2199.96037121},{"price":1.36683,"qty":1944.99448546}],"asks":[],"checksum":870668808,"timestamp":"2024-06-01T22:44:02.499545Z"}]}
{"channel":"book","type":"update","data":[{"symbol":"USD/CAD","bids":[],"asks":[{"price":1.36718,"qty":0.00000000},{"price":1.36874,"qty":17715.50159492},{"price":1.36716,"qty":3759.39882364}],"checksum":3809946731,"timestamp":"2024-06-01T22:44:02.499727Z"}]}
{"channel":"book","type":"update","data":[{"symbol":"USD/CAD","bids":[{"price":1.36683,"qty":0.00000000},{"price":1.36553,"qty":2199.96037121},{"price":1.36672,"qty":1945.14522641}],"asks":[],"checksum":35348619,"timestamp":"2024-06-01T22:44:02.503409Z"}]}
{"channel":"book","type":"update","data":[{"symbol":"USD/CAD","bids":[{"price":1.36682,"qty":0.00000000},{"price":1.36553,"qty":2199.96037121},{"price":1.36684,"qty":137.20620000}],"asks":[],"checksum":3362332521,"timestamp":"2024-06-01T22:44:02.509848Z"}]}
{"channel":"book","type":"update","data":[{"symbol":"USD/CAD","bids":[],"asks":[{"price":1.36717,"qty":0.00000000},{"price":1.36874,"qty":17715.50159492},{"price":1.36715,"qty":646.19380000}],"checksum":3233931034,"timestamp":"2024-06-01T22:44:02.541356Z"}]}
{"channel":"book","type":"update","data":[{"symbol":"USD/CAD","bids":[],"asks":[{"price":1.36716,"qty":0.00000000},{"price":1.36874,"qty":17715.50159492},{"price":1.36822,"qty":3759.39882364}],"checksum":2091902524,"timestamp":"2024-06-01T22:44:02.544609Z"}]}
{"channel":"book","type":"update","data":[{"symbol":"USD/CAD","bids":[],"asks":[{"price":1.36823,"qty":0.00000000},{"price":1.36874,"qty":17715.50159492}],"checksum":1850204484,"timestamp":"2024-06-01T22:44:02.966680Z"}]}
{"channel":"book","type":"update","data":[{"symbol":"USD/CAD","bids":[],"asks":[{"price":1.36871,"qty":0.00000000},{"price":1.36875,"qty":13500.40000000}],"checksum":3044915813,"timestamp":"2024-06-01T22:44:02.966838Z"}]}
{"channel":"book","type":"update","data":[{"symbol":"USD/CAD","bids":[],"asks":[{"price":1.36822,"qty":0.00000000},{"price":1.36895,"qty":776.15000000},{"price":1.36824,"qty":3759.39882364}],"checksum":1799297296,"timestamp":"2024-06-01T22:44:02.969976Z"}]}
{"channel":"book","type":"update","data":[{"symbol":"USD/CAD","bids":[],"asks":[{"price":1.36824,"qty":3779.39882364}],"checksum":2460932830,"timestamp":"2024-06-01T22:44:02.976224Z"}]}
{"channel":"book","type":"update","data":[{"symbol":"USD/CAD","bids":[],"asks":[{"price":1.36873,"qty":175.35124355}],"checksum":512264740,"timestamp":"2024-06-01T22:44:02.976308Z"}]}
{"channel":"book","type":"update","data":[{"symbol":"USD/CAD","bids":[{"price":1.36669,"qty":0.00000000},{"price":1.36553,"qty":2199.96037121}],"asks":[],"checksum":3513738129,"timestamp":"2024-06-01T22:44:03.016550Z"}]}
{"channel":"book","type":"update","data":[{"symbol":"USD/CAD","bids":[{"price":1.36673,"qty":59.02343750}],"asks":[],"checksum":1501375833,"timestamp":"2024-06-01T22:44:03.017054Z"}]}
{"channel":"book","type":"update","data":[{"symbol":"USD/CAD","bids":[{"price":1.36673,"qty":423.51021431}],"asks":[],"checksum":135529530,"timestamp":"2024-06-01T22:44:03.138989Z"}]}
{"channel":"book","type":"update","data":[{"symbol":"USD/CAD","bids":[{"price":1.36663,"qty":0.00000000},{"price":1.36553,"qty":2199.96037121}],"asks":[],"checksum":489320857,"timestamp":"2024-06-01T22:44:03.307080Z"}]}
{"channel":"book","type":"update","data":[{"symbol":"USD/CAD","bids":[{"price":1.36672,"qty":0.00000000},{"price":1.36551,"qty":776.15000000},{"price":1.36674,"qty":1945.11631896}],"asks":[],"checksum":1331377084,"timestamp":"2024-06-01T22:44:03.392855Z"}]}
{"channel":"book","type":"update","data":[{"symbol":"USD/CAD","bids":[{"price":1.36671,"qty":0.00000000},{"price":1.36551,"qty":776.15000000}],"asks":[],"checksum":793285858,"timestamp":"2024-06-01T22:44:03.628119Z"}]}
{"channel":"book","type":"update","data":[{"symbol":"USD/CAD","bids":[{"price":1.36675,"qty":3951.17187500}],"asks":[],"checksum":2913120761,"timestamp":"2024-06-01T22:44:03.628468Z"}]}
{"channel":"book","type":"update","data":[{"symbol":"USD/CAD","bids":[{"price":1.36674,"qty":0.00000000},{"price":1.36551,"qty":776.15000000},{"price":1.36685,"qty":1944.95948037}],"asks":[],"checksum":257605393,"timestamp":"2024-06-01T22:44:04.343538Z"}]}
{"channel":"book","type":"update","data":[{"symbol":"USD/CAD","bids":[{"price":1.36684,"qty":0.00000000},{"price":1.36551,"qty":776.15000000},{"price":1.36686,"qty":137.20620000}],"asks":[],"checksum":3021689371,"timestamp":"2024-06-01T22:44:04.365035Z"}]}
{"channel":"book","type":"update","data":[{"symbol":"USD/CAD","bids":[{"price":1.36685,"qty":0.00000000},{"price":1.36551,"qty":776.15000000},{"price":1.36676,"qty":1945.07049766}],"asks":[],"checksum":367218252,"timestamp":"2024-06-01T22:44:04.368675Z"}]}
{"channel":"book","type":"update","data":[{"symbol":"USD/CAD","bids":[],"asks":[{"price":1.36825,"qty":0.00000000},{"price":1.36875,"qty":13500.40000000}],"checksum":2606533671,"timestamp":"2024-06-01T22:44:04.765025Z"}]}
{"channel":"book","type":"update","data":[{"symbol":"USD/CAD","bids":[],"asks":[{"price":1.36874,"qty":0.00000000},{"price":1.36895,"qty":776.15000000}],"checksum":2784917993,"timestamp":"2024-06-01T22:44:04.765096Z"}]}
{"channel":"book","type":"update","data":[{"symbol":"USD/CAD","bids":[],"asks":[{"price":1.36824,"qty":20.00000000},{"price":1.36825,"qty":3759.39882364}],"checksum":1772594024,"timestamp":"2024-06-01T22:44:04.768218Z"}]}
{"channel":"book","type":"update","data":[{"symbol":"USD/CAD","bids":[],"asks":[{"price":1.36874,"qty":10389.11046242}],"checksum":423752309,"timestamp":"2024-06-01T22:44:04.770495Z"}]}
{"channel":"book","type":"update","data":[{"symbol":"USD/CAD","bids":[],"asks":[{"price":1.36823,"qty":9429.86284424}],"checksum":2178481684,"timestamp":"2024-06-01T22:44:04.770717Z"}]}
{"channel":"book","type":"update","data":[{"symbol":"USD/CAD","bids":[],"asks":[{"price":1.36825,"qty":0.00000000},{"price":1.36874,"qty":10389.11046242},{"price":1.36822,"qty":3759.39882364}],"checksum":3603981762,"timestamp":"2024-06-01T22:44:05.251671Z"}]}
{"channel":"book","type":"update","data":[{"symbol":"USD/CAD","bids":[],"asks":[{"price":1.36824,"qty":0.00000000},{"price":1.36874,"qty":10389.11046242}],"checksum":4224191613,"timestamp":"2024-06-01T22:44:05.967754Z"}]}
{"channel":"book","type":"update","data":[{"symbol":"USD/CAD","bids":[],"asks":[{"price":1.36873,"qty":0.00000000},{"price":1.36875,"qty":13500.40000000}],"checksum":985380971,"timestamp":"2024-06-01T22:44:05.967796Z"}]}
{"channel":"book","type":"update","data":[{"symbol":"USD/CAD","bids":[],"asks":[{"price":1.36821,"qty":72.60537307}],"checksum":4117061284,"timestamp":"2024-06-01T22:44:05.972540Z"}]}
{"channel":"book","type":"update","data":[{"symbol":"USD/CAD","bids":[],"asks":[{"price":1.36873,"qty":122.74587049}],"checksum":3949968033,"timestamp":"2024-06-01T22:44:05.972583Z"}]}
{"channel":"book","type":"update","data":[{"symbol":"USD/CAD","bids":[],"asks":[{"price":1.36822,"qty":0.00000000},{"price":1.36874,"qty":10389.11046242},{"price":1.36820,"qty":3759.39882364}],"checksum":3222657880,"timestamp":"2024-06-01T22:44:06.259778Z"}]}
{"channel":"book","type":"update","data":[{"symbol":"USD/CAD","bids":[],"asks":[{"price":1.36819,"qty":130.00277897}],"checksum":1167339102,"timestamp":"2024-06-01T22:44:06.448836Z"}]}
{"channel":"book","type":"update","data":[{"symbol":"USD/CAD","bids":[],"asks":[{"price":1.36715,"qty":0.00000000},{"price":1.36873,"qty":122.74587049},{"price":1.36700,"qty":646.19380000}],"checksum":2575204036,"timestamp":"2024-06-01T22:44:06.455909Z"}]}
{"channel":"book","type":"update","data":[{"symbol":"USD/CAD","bids":[{"price":1.36654,"qty":0.00000000},{"price":1.36551,"qty":776.15000000}],"asks":[],"checksum":4276543641,"timestamp":"2024-06-01T22:44:06.459296Z"}]}
{"channel":"book","type":"update","data":[{"symbol":"USD/CAD","bids":[{"price":1.36661,"qty":11394.77204107}],"asks":[],"checksum":212043278,"timestamp":"2024-06-01T22:44:06.463120Z"}]}
{"channel":"book","type":"update","data":[{"symbol":"USD/CAD","bids":[{"price":1.36655,"qty":0.00000000},{"price":1.36551,"qty":776.15000000}],"asks":[],"checksum":3914056928,"timestamp":"2024-06-01T22:44:06.485473Z"}]}
{"channel":"book","type":"update","data":[{"symbol":"USD/CAD","bids":[{"price":1.36675,"qty":0.00000000},{"price":1.36478,"qty":1455.02000000}],"asks":[],"checksum":760044089,"timestamp":"2024-06-01T22:44:06.485603Z"}]}
{"channel":"book","type":"update","data":[{"symbol":"USD/CAD","bids":[{"price":1.36673,"qty":364.48677681}],"asks":[],"checksum":245541267,"timestamp":"2024-06-01T22:44:06.486009Z"}]}
{"channel":"book","type":"update","data":[{"symbol":"USD/CAD","bids":[{"price":1.36655,"qty":3951.17187500}],"asks":[],"checksum":3242222947,"timestamp":"2024-06-01T22:44:06.486551Z"}]}
{"channel":"book","type":"update","data":[{"symbol":"USD/CAD","bids":[{"price":1.36677,"qty":20.00000000}],"asks":[],"checksum":2977475330,"timestamp":"2024-06-01T22:44:06.487018Z"}]}
{"channel":"book","type":"update","data":[{"symbol":"USD/CAD","bids":[{"price":1.36676,"qty":0.00000000},{"price":1.36551,"qty":776.15000000},{"price":1.36674,"qty":1945.07219845}],"asks":[],"checksum":3195277257,"timestamp":"2024-06-01T22:44:06.489074Z"}]}
{"channel":"book","type":"update","data":[{"symbol":"USD/CAD","bids":[],"asks":[{"price":1.36701,"qty":0.00000000},{"price":1.36873,"qty":122.74587049}],"checksum":1907352273,"timestamp":"2024-06-01T22:44:06.612551Z"}]}
{"channel":"book","type":"update","data":[{"symbol":"USD/CAD","bids":[],"asks":[{"price":1.36820,"qty":0.00000000},{"price":1.36874,"qty":10389.11046242},{"price":1.36818,"qty":3759.39882364}],"checksum":4113200360,"timestamp":"2024-06-01T22:44:07.225246Z"}]}
{"channel":"book","type":"update","data":[{"symbol":"USD/CAD","bids":[],"asks":[{"price":1.36823,"qty":0.00000000},{"price":1.36875,"qty":13500.40000000}],"checksum":1652966747,"timestamp":"2024-06-01T22:44:08.250900Z"}]}
{"channel":"book","type":"update","data":[{"symbol":"USD/CAD","bids":[],"asks":[{"price":1.36874,"qty":11879.07368026}],"checksum":47670644,"timestamp":"2024-06-01T22:44:08.256421Z"}]}
{"channel":"book","type":"update","data":[{"symbol":"USD/CAD","bids":[],"asks":[{"price":1.36817,"qty":6457.91770654}],"checksum":897712971,"timestamp":"2024-06-01T22:44:08.256482Z"}]}
{"channel":"book","type":"update","data":[{"symbol":"USD/CAD","bids":[],"asks":[{"price":1.36818,"qty":0.00000000},{"price":1.36874,"qty":11879.07368026},{"price":1.36816,"qty":3759.39882364}],"checksum":3100353305,"timestamp":"2024-06-01T22:44:08.260009Z"}]}
{"channel":"book","type":"update","data":[{"symbol":"USD/CAD","bids":[],"asks":[{"price":1.36821,"qty":0.00000000},{"price":1.36874,"qty":11879.07368026}],"checksum":3572146416,"timestamp":"2024-06-01T22:44:08.847459Z"}]}
{"channel":"book","type":"update","data":[{"symbol":"USD/CAD","bids":[],"asks":[{"price":1.36873,"qty":0.00000000},{"price":1.36875,"qty":13500.40000000}],"checksum":867087077,"timestamp":"2024-06-01T22:44:08.847501Z"}]}
{"channel":"book","type":"update","data":[{"symbol":"USD/CAD","bids":[],"asks":[{"price":1.36817,"qty":6512.98795525}],"checksum":37019468,"timestamp":"2024-06-01T22:44:08.852997Z"}]}
{"channel":"book","type":"update","data":[{"symbol":"USD/CAD","bids":[],"asks":[{"price":1.36873,"qty":140.28099484}],"checksum":1386719811,"timestamp":"2024-06-01T22:44:08.853047Z"}]}
{"channel":"book","type":"update","data":[{"symbol":"USD/CAD","bids":[],"asks":[{"price":1.36700,"qty":0.00000000},{"price":1.36875,"qty":13500.40000000},{"price":1.36723,"qty":646.19380000}],"checksum":1018524740,"timestamp":"2024-06-01T22:44:08.882127Z"}]}
{"channel":"book","type":"update","data":[{"symbol":"USD/CAD","bids":[],"asks":[{"price":1.36816,"qty":0.00000000},{"price":1.36875,"qty":13500.40000000},{"price":1.36722,"qty":3759.39882364}],"checksum":2873962608,"timestamp":"2024-06-01T22:44:09.172512Z"}]}
{"channel":"book","type":"update","data":[{"symbol":"USD/CAD","bids":[],"asks":[{"price":1.36723,"qty":0.00000000},{"price":1.36875,"qty":13500.40000000},{"price":1.36721,"qty":646.19380000}],"checksum":1528339218,"timestamp":"2024-06-01T22:44:09.186142Z"}]}
{"channel":"book","type":"update","data":[{"symbol":"USD/CAD","bids":[{"price":1.36655,"qty":0.00000000},{"price":1.36551,"qty":776.15000000}],"asks":[],"checksum":2303188405,"timestamp":"2024-06-01T22:44:09.367281Z"}]}
{"channel":"book","type":"update","data":[{"symbol":"USD/CAD","bids":[{"price":1.36675,"qty":3951.17187500}],"asks":[],"checksum":2833469898,"timestamp":"2024-06-01T22:44:09.367381Z"}]}
{"channel":"book","type":"update","data":[{"symbol":"USD/CAD","bids":[],"asks":[{"price":1.36826,"qty":0.00000000},{"price":1.36875,"qty":13500.40000000}],"checksum":3899736734,"timestamp":"2024-06-01T22:44:09.684940Z"}]}
{"channel":"book","type":"update","data":[{"symbol":"USD/CAD","bids":[],"asks":[{"price":1.36831,"qty":3417.27454042}],"checksum":623470899,"timestamp":"2024-06-01T22:44:09.712719Z"}]}
{"channel":"book","type":"update","data":[{"symbol":"USD/CAD","bids":[{"price":1.36677,"qty":0.00000000},{"price":1.36551,"qty":776.15000000}],"asks":[],"checksum":3648246649,"timestamp":"2024-06-01T22:44:09.915893Z"}]}
{"channel":"book","type":"update","data":[{"symbol":"USD/CAD","bids":[{"price":1.36676,"qty":20.00000000}],"asks":[],"checksum":776880311,"timestamp":"2024-06-01T22:44:09.916674Z"}]}
{"channel":"book","type":"update","data":[{"symbol":"USD/CAD","bids":[{"price":1.36674,"qty":0.00000000},{"price":1.36551,"qty":776.15000000},{"price":1.36687,"qty":1941.45919625}],"asks":[],"checksum":649016758,"timestamp":"2024-06-01T22:44:10.041866Z"}]}
{"channel":"book","type":"update","data":[{"symbol":"USD/CAD","bids":[],"asks":[{"price":1.36722,"qty":0.00000000},{"price":1.36875,"qty":13500.40000000},{"price":1.36720,"qty":3759.39882364}],"checksum":2912224253,"timestamp":"2024-06-01T22:44:10.041991Z"}]}
{"channel":"book","type":"update","data":[{"symbol":"USD/CAD","bids":[{"price":1.36686,"qty":0.00000000},{"price":1.36551,"qty":776.15000000},{"price":1.36688,"qty":137.20620000}],"asks":[],"checksum":1564917695,"timestamp":"2024-06-01T22:44:10.068181Z"}]}
{"channel":"book","type":"update","data":[{"symbol":"USD/CAD","bids":[{"price":1.36687,"qty":0.00000000},{"price":1.36551,"qty":776.15000000},{"price":1.36677,"qty":1941.60136631}],"asks":[],"checksum":306165090,"timestamp":"2024-06-01T22:44:10.071538Z"}]}
{"channel":"book","type":"update","data":[{"symbol":"USD/CAD","bids":[],"asks":[{"price":1.36721,"qty":0.00000000},{"price":1.36875,"qty":13500.40000000},{"price":1.36719,"qty":646.19380000}],"checksum":1648135595,"timestamp":"2024-06-01T22:44:10.099835Z"}]}
{"channel":"book","type":"update","data":[{"symbol":"USD/CAD","bids":[],"asks":[{"price":1.36720,"qty":0.00000000},{"price":1.36875,"qty":13500.40000000},{"price":1.36718,"qty":3759.39882364}],"checksum":2867153070,"timestamp":"2024-06-01T22:44:10.901526Z"}]}
{"channel":"book","type":"update","data":[{"symbol":"USD/CAD","bids":[],"asks":[{"price":1.36719,"qty":0.00000000},{"price":1.36875,"qty":13500.40000000},{"price":1.36717,"qty":646.19380000}],"checksum":3865683177,"timestamp":"2024-06-01T22:44:10.918181Z"}]}
{"channel":"book","type":"update","data":[{"symbol":"USD/CAD","bids":[],"asks":[{"price":1.36874,"qty":0.00000000},{"price":1.36875,"qty":13500.40000000}],"checksum":2251850950,"timestamp":"2024-06-01T22:44:11.688596Z"}]}
{"channel":"book","type":"update","data":[{"symbol":"USD/CAD","bids":[],"asks":[{"price":1.36817,"qty":55.07024871}],"checksum":4088801101,"timestamp":"2024-06-01T22:44:11.688788Z"}]}
{"channel":"book","type":"update","data":[{"symbol":"USD/CAD","bids":[],"asks":[{"price":1.36874,"qty":16859.72568848}],"checksum":1358062751,"timestamp":"2024-06-01T22:44:11.693955Z"}]}
{"channel":"book","type":"update","data":[{"symbol":"USD/CAD","bids":[],"asks":[{"price":1.36718,"qty":0.00000000},{"price":1.36875,"qty":13500.40000000},{"price":1.36716,"qty":3759.39882364}],"checksum":1511679953,"timestamp":"2024-06-01T22:44:11.751847Z"}]}
{"channel":"book","type":"update","data":[{"symbol":"USD/CAD","bids":[],"asks":[{"price":1.36717,"qty":0.00000000},{"price":1.36875,"qty":13500.40000000},{"price":1.36715,"qty":646.19380000}],"checksum":1768310182,"timestamp":"2024-06-01T22:44:11.768823Z"}]}
{"channel":"book","type":"update","data":[{"symbol":"USD/CAD","bids":[],"asks":[{"price":1.36716,"qty":0.00000000},{"price":1.36875,"qty":13500.40000000},{"price":1.36830,"qty":3759.39882364}],"checksum":1883929455,"timestamp":"2024-06-01T22:44:11.772097Z"}]}
{"channel":"book","type":"update","data":[{"symbol":"USD/CAD","bids":[],"asks":[{"price":1.36817,"qty":0.00000000},{"price":1.36875,"qty":13500.40000000}],"checksum":3100043365,"timestamp":"2024-06-01T22:44:11.857423Z"}]}
{"channel":"book","type":"update","data":[{"symbol":"USD/CAD","bids":[],"asks":[{"price":1.36873,"qty":0.00000000},{"price":1.36895,"qty":776.15000000}],"checksum":39728728,"timestamp":"2024-06-01T22:44:11.857634Z"}]}
{"channel":"book","type":"update","data":[{"symbol":"USD/CAD","bids":[],"asks":[{"price":1.36873,"qty":195.35124355}],"checksum":124484012,"timestamp":"2024-06-01T22:44:11.864478Z"}]}
{"channel":"book","type":"update","data":[{"symbol":"USD/CAD","bids":[{"price":1.36675,"qty":0.00000000},{"price":1.36551,"qty":776.15000000}],"asks":[],"checksum":4032868162,"timestamp":"2024-06-01T22:44:12.230767Z"}]}
{"channel":"book","type":"update","data":[{"symbol":"USD/CAD","bids":[{"price":1.36662,"qty":3951.17187500}],"asks":[],"checksum":2595932204,"timestamp":"2024-06-01T22:44:12.231503Z"}]}
{"channel":"book","type":"update","data":[{"symbol":"USD/CAD","bids":[{"price":1.36678,"qty":2000.00000000}],"asks":[],"checksum":3221559696,"timestamp":"2024-06-01T22:44:12.231637Z"}]}
{"channel":"book","type":"update","data":[{"symbol":"USD/CAD","bids":[{"price":1.36677,"qty":0.00000000},{"price":1.36553,"qty":2199.96037121},{"price":1.36674,"qty":1942.42263708}],"asks":[],"checksum":643708363,"timestamp":"2024-06-01T22:44:12.234216Z"}]}
{"channel":"book","type":"update","data":[{"symbol":"USD/CAD","bids":[{"price":1.36674,"qty":0.00000000},{"price":1.36553,"qty":2199.96037121},{"price":1.36679,"qty":1942.35157925}],"asks":[],"checksum":1981202497,"timestamp":"2024-06-01T22:44:12.558561Z"}]}
{"channel":"book","type":"update","data":[{"symbol":"USD/CAD","bids":[{"price":1.36676,"qty":0.00000000},{"price":1.36558,"qty":2199.87982080}],"asks":[],"checksum":2806816344,"timestamp":"2024-06-01T22:44:13.343706Z"}]}
{"channel":"book","type":"update","data":[{"symbol":"USD/CAD","bids":[{"price":1.36680,"qty":20.00000000}],"asks":[],"checksum":842121464,"timestamp":"2024-06-01T22:44:13.344492Z"}]}
{"channel":"book","type":"update","data":[{"symbol":"USD/CAD","bids":[{"price":1.36679,"qty":0.00000000},{"price":1.36558,"qty":2199.87982080},{"price":1.36689,"qty":1942.20298815}],"asks":[],"checksum":1072105006,"timestamp":"2024-06-01T22:44:13.466469Z"}]}
{"channel":"book","type":"update","data":[{"symbol":"USD/CAD","bids":[{"price":1.36688,"qty":0.00000000},{"price":1.36558,"qty":2199.87982080},{"price":1.36690,"qty":137.20620000}],"asks":[],"checksum":727860525,"timestamp":"2024-06-01T22:44:13.500175Z"}]}
{"channel":"book","type":"update","data":[{"symbol":"USD/CAD","bids":[{"price":1.36689,"qty":0.00000000},{"price":1.36558,"qty":2199.87982080},{"price":1.36679,"qty":1942.34503085}],"asks":[],"checksum":137823553,"timestamp":"2024-06-01T22:44:13.504633Z"}]}
{"channel":"book","type":"update","data":[{"symbol":"USD/CAD","bids":[],"asks":[{"price":1.36873,"qty":0.00000000},{"price":1.36895,"qty":776.15000000}],"checksum":218254005,"timestamp":"2024-06-01T22:44:14.836401Z"}]}
{"channel":"book","type":"update","data":[{"symbol":"USD/CAD","bids":[],"asks":[{"price":1.36829,"qty":55.07024871}],"checksum":179291386,"timestamp":"2024-06-01T22:44:14.840712Z"}]}
{"channel":"book","type":"update","data":[{"symbol":"USD/CAD","bids":[],"asks":[{"price":1.36873,"qty":140.28099484}],"checksum":3537617730,"timestamp":"2024-06-01T22:44:14.840900Z"}]}
{"channel":"book","type":"update","data":[{"symbol":"USD/CAD","bids":[],"asks":[{"price":1.36830,"qty":0.00000000},{"price":1.36875,"qty":13500.40000000},{"price":1.36828,"qty":3759.39882364}],"checksum":1008036816,"timestamp":"2024-06-01T22:44:14.843699Z"}]}
{"channel":"book","type":"update","data":[{"symbol":"USD/CAD","bids":[{"price":1.36678,"qty":0.00000000},{"price":1.36558,"qty":2199.87982080}],"asks":[],"checksum":3185699613,"timestamp":"2024-06-01T22:44:15.123857Z"}]}
{"channel":"book","type":"update","data":[{"symbol":"USD/CAD","bids":[{"price":1.36680,"qty":2020.00000000}],"asks":[],"checksum":1544157604,"timestamp":"2024-06-01T22:44:15.124838Z"}]}
{"channel":"book","type":"update","data":[{"symbol":"USD/CAD","bids":[{"price":1.36679,"qty":0.00000000},{"price":1.36551,"qty":776.15000000},{"price":1.36674,"qty":1942.41458140}],"asks":[],"checksum":2380050829,"timestamp":"2024-06-01T22:44:15.127400Z"}]}
{"channel":"book","type":"update","data":[{"symbol":"USD/CAD","bids":[],"asks":[{"price":1.36874,"qty":0.00000000},{"price":1.36875,"qty":13500.40000000}],"checksum":3506939262,"timestamp":"2024-06-01T22:44:15.133105Z"}]}
{"channel":"book","type":"update","data":[{"symbol":"USD/CAD","bids":[],"asks":[{"price":1.36829,"qty":7998.96052410}],"checksum":35673129,"timestamp":"2024-06-01T22:44:15.139144Z"}]}
{"channel":"book","type":"update","data":[{"symbol":"USD/CAD","bids":[],"asks":[{"price":1.36874,"qty":8907.12854257}],"checksum":665885236,"timestamp":"2024-06-01T22:44:15.139359Z"}]}
{"channel":"book","type":"update","data":[{"symbol":"USD/CAD","bids":[{"price":1.36663,"qty":364.48677681}],"asks":[],"checksum":3067778188,"timestamp":"2024-06-01T22:44:15.290355Z"}]}
{"channel":"book","type":"update","data":[{"symbol":"USD/CAD","bids":[{"price":1.36673,"qty":0.00000000},{"price":1.36558,"qty":2199.87982080}],"asks":[],"checksum":3410126588,"timestamp":"2024-06-01T22:44:15.459987Z"}]}
{"channel":"book","type":"update","data":[{"symbol":"USD/CAD","bids":[{"price":1.36674,"qty":0.00000000},{"price":1.36551,"qty":776.15000000},{"price":1.36681,"qty":1942.31510230}],"asks":[],"checksum":2026664306,"timestamp":"2024-06-01T22:44:15.621689Z"}]}
{"channel":"book","type":"update","data":[{"symbol":"USD/CAD","bids":[{"price":1.36680,"qty":2000.00000000}],"asks":[],"checksum":1272985727,"timestamp":"2024-06-01T22:44:16.806652Z"}]}
{"channel":"book","type":"update","data":[{"symbol":"USD/CAD","bids":[{"price":1.36664,"qty":39.51171875}],"asks":[],"checksum":3992189596,"timestamp":"2024-06-01T22:44:16.807762Z"}]}
{"channel":"book","type":"update","data":[{"symbol":"USD/CAD","bids":[],"asks":[{"price":1.36827,"qty":130.00277897}],"checksum":3445460060,"timestamp":"2024-06-01T22:44:16.921188Z"}]}
{"channel":"book","type":"update","data":[{"symbol":"USD/CAD","bids":[],"asks":[{"price":1.36828,"qty":0.00000000},{"price":1.36874,"qty":8907.12854257},{"price":1.36826,"qty":3759.39882364}],"checksum":1888269627,"timestamp":"2024-06-01T22:44:16.924840Z"}]}
{"channel":"book","type":"update","data":[{"symbol":"USD/CAD","bids":[],"asks":[{"price":1.36819,"qty":0.00000000},{"price":1.36874,"qty":8907.12854257}],"checksum":3414134750,"timestamp":"2024-06-01T22:44:17.126755Z"}]}
{"channel":"book","type":"update","data":[{"symbol":"USD/CAD","bids":[],"asks":[{"price":1.36829,"qty":7943.89027539}],"checksum":2315208414,"timestamp":"2024-06-01T22:44:17.781005Z"}]}
{"channel":"book","type":"update","data":[{"symbol":"USD/CAD","bids":[],"asks":[{"price":1.36873,"qty":0.00000000},{"price":1.36875,"qty":13500.40000000}],"checksum":1996394058,"timestamp":"2024-06-01T22:44:17.781127Z"}]}
{"channel":"book","type":"update","data":[{"symbol":"USD/CAD","bids":[],"asks":[{"price":1.36825,"qty":86.95897440}],"checksum":757573913,"timestamp":"2024-06-01T22:44:17.786019Z"}]}
{"channel":"book","type":"update","data":[{"symbol":"USD/CAD","bids":[],"asks":[{"price":1.36873,"qty":100.43846160}],"checksum":354110667,"timestamp":"2024-06-01T22:44:17.786343Z"}]}
{"channel":"book","type":"update","data":[{"symbol":"USD/CAD","bids":[],"asks":[{"price":1.36826,"qty":0.00000000},{"price":1.36874,"qty":8907.12854257},{"price":1.36824,"qty":3759.39882364}],"checksum":2616391248,"timestamp":"2024-06-01T22:44:17.789397Z"}]}
{"channel":"book","type":"update","data":[{"symbol":"USD/CAD","bids":[{"price":1.36680,"qty":0.00000000},{"price":1.36558,"qty":2199.87982080}],"asks":[],"checksum":527951646,"timestamp":"2024-06-01T22:44:17.955277Z"}]}
{"channel":"book","type":"update","data":[{"symbol":"USD/CAD","bids":[{"price":1.36662,"qty":0.00000000},{"price":1.36551,"qty":776.15000000}],"asks":[],"checksum":1482243006,"timestamp":"2024-06-01T22:44:17.955309Z"}]}
{"channel":"book","type":"update","data":[{"symbol":"USD/CAD","bids":[{"price":1.36664,"qty":3990.68359375}],"asks":[],"checksum":337764458,"timestamp":"2024-06-01T22:44:17.956448Z"}]}
{"channel":"book","type":"update","data":[{"symbol":"USD/CAD","bids":[{"price":1.36681,"qty":0.00000000},{"price":1.36483,"qty":5902.34375000},{"price":1.36665,"qty":1942.54535301}],"asks":[],"checksum":229567571,"timestamp":"2024-06-01T22:44:17.958843Z"}]}
{"channel":"book","type":"update","data":[{"symbol":"USD/CAD","bids":[{"price":1.36690,"qty":0.00000000},{"price":1.36483,"qty":5902.34375000},{"price":1.36666,"qty":137.20620000}],"asks":[],"checksum":2050288803,"timestamp":"2024-06-01T22:44:17.967018Z"}]}
{"channel":"book","type":"update","data":[{"symbol":"USD/CAD","bids":[],"asks":[{"price":1.36715,"qty":0.00000000},{"price":1.36874,"qty":8907.12854257},{"price":1.36701,"qty":646.19380000}],"checksum":782178924,"timestamp":"2024-06-01T22:44:17.998489Z"}]}
{"channel":"book","type":"update","data":[{"symbol":"USD/CAD","bids":[{"price":1.36665,"qty":0.00000000},{"price":1.36483,"qty":5902.34375000},{"price":1.36667,"qty":1942.51692559}],"asks":[],"checksum":65100301,"timestamp":"2024-06-01T22:44:18.549324Z"}]}
{"channel":"book","type":"update","data":[{"symbol":"USD/CAD","bids":[{"price":1.36666,"qty":0.00000000},{"price":1.36483,"qty":5902.34375000},{"price":1.36668,"qty":137.20620000}],"asks":[],"checksum":2944213497,"timestamp":"2024-06-01T22:44:18.574827Z"}]}
{"channel":"book","type":"update","data":[{"symbol":"USD/CAD","bids":[],"asks":[{"price":1.36829,"qty":0.00000000},{"price":1.36874,"qty":8907.12854257}],"checksum":46027498,"timestamp":"2024-06-01T22:44:18.619766Z"}]}
{"channel":"book","type":"update","data":[{"symbol":"USD/CAD","bids":[],"asks":[{"price":1.36874,"qty":0.00000000},{"price":1.36875,"qty":13500.40000000}],"checksum":1997254913,"timestamp":"2024-06-01T22:44:18.619798Z"}]}
{"channel":"book","type":"update","data":[{"symbol":"USD/CAD","bids":[],"asks":[{"price":1.36823,"qty":6457.91770654}],"checksum":2800720488,"timestamp":"2024-06-01T22:44:18.628006Z"}]}
{"channel":"book","type":"update","data":[{"symbol":"USD/CAD","bids":[{"price":1.36667,"qty":0.00000000},{"price":1.36483,"qty":5902.34375000},{"price":1.36669,"qty":1942.43918985}],"asks":[],"checksum":1388242539,"timestamp":"2024-06-01T22:44:19.299466Z"}]}
{"channel":"book","type":"update","data":[{"symbol":"USD/CAD","bids":[],"asks":[{"price":1.36824,"qty":0.00000000},{"price":1.36874,"qty":10394.18947023},{"price":1.36822,"qty":3759.39882364}],"checksum":2939328499,"timestamp":"2024-06-01T22:44:19.299708Z"}]}
{"channel":"book","type":"update","data":[{"symbol":"USD/CAD","bids":[{"price":1.36668,"qty":0.00000000},{"price":1.36483,"qty":5902.34375000},{"price":1.36670,"qty":137.20620000}],"asks":[],"checksum":2501056976,"timestamp":"2024-06-01T22:44:19.334621Z"}]}
{"channel":"book","type":"update","data":[{"symbol":"USD/CAD","bids":[{"price":1.36669,"qty":0.00000000},{"price":1.36483,"qty":5902.34375000},{"price":1.36671,"qty":1942.40989893}],"asks":[],"checksum":474910674,"timestamp":"2024-06-01T22:44:20.039394Z"}]}
{"channel":"book","type":"update","data":[{"symbol":"USD/CAD","bids":[],"asks":[{"price":1.36822,"qty":0.00000000},{"price":1.36874,"qty":10394.18947023},{"price":1.36821,"qty":3759.39882364}],"checksum":3260143527,"timestamp":"2024-06-01T22:44:20.039483Z"}]}
{"channel":"book","type":"update","data":[{"symbol":"USD/CAD","bids":[],"asks":[{"price":1.36821,"qty":0.00000000},{"price":1.36874,"qty":10394.18947023},{"price":1.36822,"qty":3759.39882364}],"checksum":474910674,"timestamp":"2024-06-01T22:44:20.042920Z"}]}
{"channel":"book","type":"update","data":[{"symbol":"USD/CAD","bids":[{"price":1.36670,"qty":0.00000000},{"price":1.36483,"qty":5902.34375000},{"price":1.36672,"qty":137.20620000}],"asks":[],"checksum":3509899803,"timestamp":"2024-06-01T22:44:20.062692Z"}]}
{"channel":"book","type":"update","data":[{"symbol":"USD/CAD","bids":[{"price":1.36664,"qty":3951.17187500}],"asks":[],"checksum":2059964079,"timestamp":"2024-06-01T22:44:20.213583Z"}]}
{"channel":"book","type":"update","data":[{"symbol":"USD/CAD","bids":[{"price":1.36670,"qty":39.51171875}],"asks":[],"checksum":4187085518,"timestamp":"2024-06-01T22:44:20.213923Z"}]}
{"channel":"book","type":"update","data":[{"symbol":"USD/CAD","bids":[{"price":1.36671,"qty":0.00000000},{"price":1.36551,"qty":776.15000000},{"price":1.36673,"qty":1942.38130180}],"asks":[],"checksum":498037281,"timestamp":"2024-06-01T22:44:20.769175Z"}]}
{"channel":"book","type":"update","data":[{"symbol":"USD/CAD","bids":[{"price":1.36672,"qty":0.00000000},{"price":1.36551,"qty":776.15000000},{"price":1.36674,"qty":137.20620000}],"asks":[],"checksum":3356211046,"timestamp":"2024-06-01T22:44:20.790958Z"}]}
{"channel":"book","type":"update","data":[{"symbol":"USD/CAD","bids":[{"price":1.36664,"qty":0.00000000},{"price":1.36551,"qty":776.15000000}],"asks":[],"checksum":4135006937,"timestamp":"2024-06-01T22:44:20.826237Z"}]}
{"channel":"book","type":"update","data":[{"symbol":"USD/CAD","bids":[{"price":1.36673,"qty":3942.38130180}],"asks":[],"checksum":223059962,"timestamp":"2024-06-01T22:44:20.827464Z"}]}
{"channel":"book","type":"update","data":[{"symbol":"USD/CAD","bids":[{"price":1.36672,"qty":3951.17187500}],"asks":[],"checksum":1381494406,"timestamp":"2024-06-01T22:44:20.827572Z"}]}
{"channel":"book","type":"update","data":[{"symbol":"USD/CAD","bids":[],"asks":[{"price":1.36825,"qty":0.00000000},{"price":1.36874,"qty":10394.18947023}],"checksum":1195578048,"timestamp":"2024-06-01T22:44:20.829269Z"}]}
{"channel":"book","type":"update","data":[{"symbol":"USD/CAD","bids":[],"asks":[{"price":1.36821,"qty":94.91278205}],"checksum":1177144585,"timestamp":"2024-06-01T22:44:20.837811Z"}]}
{"channel":"book","type":"update","data":[{"symbol":"USD/CAD","bids":[{"price":1.36673,"qty":2000.00000000},{"price":1.36675,"qty":1942.35967656}],"asks":[],"checksum":3751571105,"timestamp":"2024-06-01T22:44:21.566370Z"}]}
{"channel":"book","type":"update","data":[{"symbol":"USD/CAD","bids":[],"asks":[{"price":1.36822,"qty":0.00000000},{"price":1.36874,"qty":10394.18947023},{"price":1.36820,"qty":3759.39882364}],"checksum":289792822,"timestamp":"2024-06-01T22:44:21.566446Z"}]}
{"channel":"book","type":"update","data":[{"symbol":"USD/CAD","bids":[{"price":1.36661,"qty":0.00000000},{"price":1.36558,"qty":2199.87982080}],"asks":[],"checksum":286730759,"timestamp":"2024-06-01T22:44:21.569514Z"}]}
{"channel":"book","type":"update","data":[{"symbol":"USD/CAD","bids":[{"price":1.36662,"qty":11394.68866185}],"asks":[],"checksum":1798318677,"timestamp":"2024-06-01T22:44:21.573222Z"}]}
{"channel":"book","type":"update","data":[{"symbol":"USD/CAD","bids":[{"price":1.36674,"qty":0.00000000},{"price":1.36558,"qty":2199.87982080},{"price":1.36676,"qty":137.20620000}],"asks":[],"checksum":983847109,"timestamp":"2024-06-01T22:44:21.579445Z"}]}
{"channel":"book","type":"update","data":[{"symbol":"USD/CAD","bids":[],"asks":[{"price":1.36701,"qty":0.00000000},{"price":1.36874,"qty":10394.18947023},{"price":1.36723,"qty":646.19380000}],"checksum":1211272024,"timestamp":"2024-06-01T22:44:21.611537Z"}]}
{"channel":"book","type":"update","data":[{"symbol":"USD/CAD","bids":[{"price":1.36677,"qty":364.48677681}],"asks":[],"checksum":1513795982,"timestamp":"2024-06-01T22:44:21.776909Z"}]}
{"channel":"book","type":"update","data":[{"symbol":"USD/CAD","bids":[{"price":1.36676,"qty":0.00000000},{"price":1.36631,"qty":1117.30712667},{"price":1.36678,"qty":137.20620000}],"asks":[],"checksum":3197503348,"timestamp":"2024-06-01T22:44:21.795236Z"}]}
