{"channel":"book","type":"snapshot","data":[{"symbol":"USDC/AUD","bids":[{"price":1.5046,"qty":246.92395593},{"price":1.5045,"qty":2075.31836063},{"price":1.5044,"qty":5902.35640961},{"price":1.5043,"qty":5782.63011363},{"price":1.5042,"qty":17352.44465678},{"price":1.5041,"qty":4950.74000000},{"price":1.5040,"qty":4839.83000000},{"price":1.5038,"qty":19659.84000000},{"price":1.5029,"qty":97701.00000000},{"price":1.5027,"qty":18420.04000000}],"asks":[{"price":1.5054,"qty":105.36395674},{"price":1.5055,"qty":14015.83035817},{"price":1.5056,"qty":7094.83188822},{"price":1.5057,"qty":26387.05000000},{"price":1.5058,"qty":32279.99576996},{"price":1.5060,"qty":5193.37000000},{"price":1.5069,"qty":2102.00000000},{"price":1.5072,"qty":1003.00000000},{"price":1.5073,"qty":2004.00000000},{"price":1.5132,"qty":473.72249292}],"checksum":529384183}]}
{"channel":"book","type":"update","data":[{"symbol":"USDC/AUD","bids":[],"asks":[{"price":1.5054,"qty":169.90047259}],"checksum":784432323,"timestamp":"2024-06-01T22:42:57.850827Z"}]}
{"channel":"book","type":"update","data":[{"symbol":"USDC/AUD","bids":[],"asks":[{"price":1.5054,"qty":105.36395674},{"price":1.5053,"qty":64.53651585}],"checksum":2745431937,"timestamp":"2024-06-01T22:42:57.855485Z"}]}
{"channel":"book","type":"update","data":[{"symbol":"USDC/AUD","bids":[],"asks":[{"price":1.5053,"qty":0.00000000},{"price":1.5132,"qty":473.72249292},{"price":1.5054,"qty":169.90047259}],"checksum":784432323,"timestamp":"2024-06-01T22:42:57.859675Z"}]}
{"channel":"book","type":"update","data":[{"symbol":"USDC/AUD","bids":[],"asks":[{"price":1.5054,"qty":465.90047259}],"checksum":2860464057,"timestamp":"2024-06-01T22:42:58.116674Z"}]}
{"channel":"book","type":"update","data":[{"symbol":"USDC/AUD","bids":[],"asks":[{"price":1.5054,"qty":401.36395674},{"price":1.5053,"qty":64.53651536}],"checksum":3433902908,"timestamp":"2024-06-01T22:42:58.119758Z"}]}
{"channel":"book","type":"update","data":[{"symbol":"USDC/AUD","bids":[],"asks":[{"price":1.5054,"qty":105.36395674}],"checksum":3858049675,"timestamp":"2024-06-01T22:42:58.120929Z"}]}
{"channel":"book","type":"update","data":[{"symbol":"USDC/AUD","bids":[{"price":1.5042,"qty":0.00000000},{"price":1.5026,"qty":47603.00000000}],"asks":[],"checksum":2557594647,"timestamp":"2024-06-01T22:42:58.123324Z"}]}
{"channel":"book","type":"update","data":[{"symbol":"USDC/AUD","bids":[],"asks":[{"price":1.5053,"qty":0.00000000},{"price":1.5132,"qty":473.72249292},{"price":1.5054,"qty":169.90047210}],"checksum":1736307860,"timestamp":"2024-06-01T22:42:58.123564Z"}]}
{"channel":"book","type":"update","data":[{"symbol":"USDC/AUD","bids":[],"asks":[{"price":1.5058,"qty":0.00000000},{"price":1.5136,"qty":40.17512311}],"checksum":2765013220,"timestamp":"2024-06-01T22:42:58.126054Z"}]}
{"channel":"book","type":"update","data":[{"symbol":"USDC/AUD","bids":[],"asks":[{"price":1.5054,"qty":105.36395674},{"price":1.5053,"qty":64.53651536}],"checksum":2737350006,"timestamp":"2024-06-01T22:42:58.127485Z"}]}
{"channel":"book","type":"update","data":[{"symbol":"USDC/AUD","bids":[{"price":1.5042,"qty":17352.44465678}],"asks":[],"checksum":3735831530,"timestamp":"2024-06-01T22:42:58.128943Z"}]}
{"channel":"book","type":"update","data":[{"symbol":"USDC/AUD","bids":[],"asks":[{"price":1.5053,"qty":0.00000000},{"price":1.5136,"qty":40.17512311},{"price":1.5054,"qty":169.90047210}],"checksum":3645515384,"timestamp":"2024-06-01T22:42:58.131180Z"}]}
{"channel":"book","type":"update","data":[{"symbol":"USDC/AUD","bids":[],"asks":[{"price":1.5058,"qty":32279.99576996}],"checksum":452530696,"timestamp":"2024-06-01T22:42:58.131824Z"}]}
{"channel":"book","type":"update","data":[{"symbol":"USDC/AUD","bids":[],"asks":[{"price":1.5054,"qty":105.36395674},{"price":1.5053,"qty":64.53651536}],"checksum":3858049675,"timestamp":"2024-06-01T22:42:58.135368Z"}]}
{"channel":"book","type":"update","data":[{"symbol":"USDC/AUD","bids":[],"asks":[{"price":1.5053,"qty":0.00000000},{"price":1.5132,"qty":473.72249292},{"price":1.5054,"qty":169.90047210}],"checksum":452530696,"timestamp":"2024-06-01T22:42:58.139229Z"}]}
{"channel":"book","type":"update","data":[{"symbol":"USDC/AUD","bids":[],"asks":[{"price":1.5054,"qty":105.36395674},{"price":1.5053,"qty":64.53651536}],"checksum":3858049675,"timestamp":"2024-06-01T22:42:58.142795Z"}]}
{"channel":"book","type":"update","data":[{"symbol":"USDC/AUD","bids":[],"asks":[{"price":1.5053,"qty":0.00000000},{"price":1.5132,"qty":473.72249292},{"price":1.5054,"qty":169.90047210}],"checksum":452530696,"timestamp":"2024-06-01T22:42:58.146191Z"}]}
{"channel":"book","type":"update","data":[{"symbol":"USDC/AUD","bids":[],"asks":[{"price":1.5054,"qty":105.36395674},{"price":1.5053,"qty":64.53651536}],"checksum":3858049675,"timestamp":"2024-06-01T22:42:58.152019Z"}]}
{"channel":"book","type":"update","data":[{"symbol":"USDC/AUD","bids":[],"asks":[{"price":1.5053,"qty":0.00000000},{"price":1.5132,"qty":473.72249292},{"price":1.5054,"qty":169.90047210}],"checksum":452530696,"timestamp":"2024-06-01T22:42:58.155088Z"}]}
{"channel":"book","type":"update","data":[{"symbol":"USDC/AUD","bids":[],"asks":[{"price":1.5054,"qty":105.36395674},{"price":1.5053,"qty":64.53651536}],"checksum":3858049675,"timestamp":"2024-06-01T22:42:58.191295Z"}]}
{"channel":"book","type":"update","data":[{"symbol":"USDC/AUD","bids":[],"asks":[{"price":1.5055,"qty":13950.94866545}],"checksum":3179443187,"timestamp":"2024-06-01T22:42:58.483427Z"}]}
{"channel":"book","type":"update","data":[{"symbol":"USDC/AUD","bids":[],"asks":[{"price":1.5054,"qty":488.36395674}],"checksum":525554026,"timestamp":"2024-06-01T22:42:59.263176Z"}]}
{"channel":"book","type":"update","data":[{"symbol":"USDC/AUD","bids":[{"price":1.5042,"qty":0.00000000},{"price":1.5026,"qty":47603.00000000}],"asks":[],"checksum":1658304502,"timestamp":"2024-06-01T22:43:13.381022Z"}]}
{"channel":"book","type":"update","data":[{"symbol":"USDC/AUD","bids":[],"asks":[{"price":1.5058,"qty":0.00000000},{"price":1.5132,"qty":473.72249292}],"checksum":1493493914,"timestamp":"2024-06-01T22:43:13.381062Z"}]}
{"channel":"book","type":"update","data":[{"symbol":"USDC/AUD","bids":[],"asks":[{"price":1.5058,"qty":32279.99576996}],"checksum":1658304502,"timestamp":"2024-06-01T22:43:13.386573Z"}]}
{"channel":"book","type":"update","data":[{"symbol":"USDC/AUD","bids":[{"price":1.5042,"qty":17352.44465678}],"asks":[],"checksum":525554026,"timestamp":"2024-06-01T22:43:13.386607Z"}]}
{"channel":"book","type":"update","data":[{"symbol":"USDC/AUD","bids":[{"price":1.5045,"qty":2100.63165087}],"asks":[],"checksum":438243282,"timestamp":"2024-06-01T22:43:13.559823Z"}]}
{"channel":"book","type":"update","data":[{"symbol":"USDC/AUD","bids":[],"asks":[{"price":1.5055,"qty":14015.83035817}],"checksum":1114134186,"timestamp":"2024-06-01T22:43:13.728619Z"}]}
{"channel":"book","type":"update","data":[{"symbol":"USDC/AUD","bids":[{"price":1.5046,"qty":221.61066569}],"asks":[],"checksum":45113787,"timestamp":"2024-06-01T22:43:13.728660Z"}]}
{"channel":"book","type":"update","data":[{"symbol":"USDC/AUD","bids":[],"asks":[{"price":1.5054,"qty":383.00000000}],"checksum":4260716486,"timestamp":"2024-06-01T22:43:18.123090Z"}]}
{"channel":"book","type":"update","data":[{"symbol":"USDC/AUD","bids":[],"asks":[{"price":1.5054,"qty":500.55879844}],"checksum":372092206,"timestamp":"2024-06-01T22:43:18.125332Z"}]}
{"channel":"book","type":"update","data":[{"symbol":"USDC/AUD","bids":[],"asks":[{"price":1.5055,"qty":14074.07979965}],"checksum":3939329683,"timestamp":"2024-06-01T22:43:18.125379Z"}]}
{"channel":"book","type":"update","data":[{"symbol":"USDC/AUD","bids":[],"asks":[{"price":1.5055,"qty":123.13113420}],"checksum":1829915376,"timestamp":"2024-06-01T22:43:18.520746Z"}]}
{"channel":"book","type":"update","data":[{"symbol":"USDC/AUD","bids":[],"asks":[{"price":1.5055,"qty":15781.36152337}],"checksum":2494354765,"timestamp":"2024-06-01T22:43:18.522771Z"}]}
{"channel":"book","type":"update","data":[{"symbol":"USDC/AUD","bids":[{"price":1.5047,"qty":25.31329024}],"asks":[],"checksum":2091732354,"timestamp":"2024-06-01T22:43:18.686023Z"}]}
{"channel":"book","type":"update","data":[{"symbol":"USDC/AUD","bids":[{"price":1.5045,"qty":2075.31836063}],"asks":[],"checksum":4167781490,"timestamp":"2024-06-01T22:43:18.849361Z"}]}
{"channel":"book","type":"update","data":[{"symbol":"USDC/AUD","bids":[],"asks":[{"price":1.5054,"qty":383.00000000}],"checksum":1001372715,"timestamp":"2024-06-01T22:43:21.197284Z"}]}
{"channel":"book","type":"update","data":[{"symbol":"USDC/AUD","bids":[],"asks":[{"price":1.5055,"qty":15723.11208189}],"checksum":2473378696,"timestamp":"2024-06-01T22:43:21.197528Z"}]}
{"channel":"book","type":"update","data":[{"symbol":"USDC/AUD","bids":[],"asks":[{"price":1.5054,"qty":481.04704538}],"checksum":1135007856,"timestamp":"2024-06-01T22:43:21.199485Z"}]}
{"channel":"book","type":"update","data":[{"symbol":"USDC/AUD","bids":[],"asks":[{"price":1.5055,"qty":15800.85422138}],"checksum":783297458,"timestamp":"2024-06-01T22:43:21.199552Z"}]}
{"channel":"book","type":"update","data":[{"symbol":"USDC/AUD","bids":[],"asks":[{"price":1.5055,"qty":142.62383221}],"checksum":1312664770,"timestamp":"2024-06-01T22:43:21.905722Z"}]}
{"channel":"book","type":"update","data":[{"symbol":"USDC/AUD","bids":[],"asks":[{"price":1.5055,"qty":14093.57580917}],"checksum":1624009247,"timestamp":"2024-06-01T22:43:21.906793Z"}]}
{"channel":"book","type":"update","data":[{"symbol":"USDC/AUD","bids":[],"asks":[{"price":1.5054,"qty":383.00000000}],"checksum":2953212391,"timestamp":"2024-06-01T22:43:24.350469Z"}]}
{"channel":"book","type":"update","data":[{"symbol":"USDC/AUD","bids":[],"asks":[{"price":1.5055,"qty":14015.83366968}],"checksum":2771771187,"timestamp":"2024-06-01T22:43:24.350519Z"}]}
{"channel":"book","type":"update","data":[{"symbol":"USDC/AUD","bids":[],"asks":[{"price":1.5054,"qty":500.55878354}],"checksum":94948907,"timestamp":"2024-06-01T22:43:24.353410Z"}]}
{"channel":"book","type":"update","data":[{"symbol":"USDC/AUD","bids":[],"asks":[{"price":1.5055,"qty":14074.08310377}],"checksum":3182103233,"timestamp":"2024-06-01T22:43:24.353489Z"}]}
{"channel":"book","type":"update","data":[{"symbol":"USDC/AUD","bids":[],"asks":[{"price":1.5055,"qty":123.13112681}],"checksum":3694009128,"timestamp":"2024-06-01T22:43:25.415581Z"}]}
{"channel":"book","type":"update","data":[{"symbol":"USDC/AUD","bids":[],"asks":[{"price":1.5055,"qty":15781.35953178}],"checksum":529877296,"timestamp":"2024-06-01T22:43:25.417099Z"}]}
