{"channel":"book","type":"snapshot","data":[{"symbol":"USDC/USDT","bids":[{"price":1.0008,"qty":98663.55891342},{"price":1.0007,"qty":156673.26252322},{"price":1.0006,"qty":152054.50223513},{"price":1.0005,"qty":66983.65353039},{"price":1.0004,"qty":315634.82935766},{"price":1.0003,"qty":161258.19400000},{"price":1.0002,"qty":8014.35175000},{"price":1.0001,"qty":20320.59211869},{"price":1.0000,"qty":33854974.88247514},{"price":0.9996,"qty":10148.99075000}],"asks":[{"price":1.0009,"qty":105536.83261474},{"price":1.0010,"qty":151520.52732071},{"price":1.0011,"qty":141002.33872739},{"price":1.0012,"qty":158502.28923527},{"price":1.0013,"qty":8007.00000000},{"price":1.0016,"qty":4370.89615878},{"price":1.0021,"qty":300.00000000},{"price":1.0022,"qty":10570.65051720},{"price":1.0023,"qty":21286.06977047},{"price":1.0028,"qty":10280.15375162}],"checksum":1578695630}]}
{"channel":"book","type":"update","data":[{"symbol":"USDC/USDT","bids":[{"price":1.0008,"qty":97242.55891342}],"asks":[],"checksum":3930772272,"timestamp":"2024-06-01T22:42:59.144908Z"}]}
{"channel":"book","type":"update","data":[{"symbol":"USDC/USDT","bids":[{"price":1.0004,"qty":67723.31743975}],"asks":[],"checksum":1543887671,"timestamp":"2024-06-01T22:43:00.433315Z"}]}
{"channel":"book","type":"update","data":[{"symbol":"USDC/USDT","bids":[{"price":1.0004,"qty":331004.29796710}],"asks":[],"checksum":2823859542,"timestamp":"2024-06-01T22:43:00.438006Z"}]}
{"channel":"book","type":"update","data":[{"symbol":"USDC/USDT","bids":[{"price":1.0005,"qty":66358.78914171}],"asks":[],"checksum":1398857555,"timestamp":"2024-06-01T22:43:01.278536Z"}]}
{"channel":"book","type":"update","data":[{"symbol":"USDC/USDT","bids":[{"price":1.0005,"qty":67042.18880152}],"asks":[],"checksum":4077734312,"timestamp":"2024-06-01T22:43:01.280708Z"}]}
{"channel":"book","type":"update","data":[{"symbol":"USDC/USDT","bids":[],"asks":[{"price":1.0009,"qty":124.53543036}],"checksum":813561201,"timestamp":"2024-06-01T22:43:01.396134Z"}]}
{"channel":"book","type":"update","data":[{"symbol":"USDC/USDT","bids":[],"asks":[{"price":1.0009,"qty":103585.65820195}],"checksum":53491661,"timestamp":"2024-06-01T22:43:01.397290Z"}]}
{"channel":"book","type":"update","data":[{"symbol":"USDC/USDT","bids":[{"price":1.0008,"qty":98965.55891342}],"asks":[],"checksum":361008352,"timestamp":"2024-06-01T22:43:01.669210Z"}]}
{"channel":"book","type":"update","data":[{"symbol":"USDC/USDT","bids":[{"price":1.0008,"qty":97242.55891342}],"asks":[],"checksum":53491661,"timestamp":"2024-06-01T22:43:01.919514Z"}]}
{"channel":"book","type":"update","data":[{"symbol":"USDC/USDT","bids":[{"price":1.0004,"qty":329997.70591702},{"price":1.0005,"qty":68048.68024270}],"asks":[],"checksum":13829049,"timestamp":"2024-06-01T22:43:02.398070Z"}]}
{"channel":"book","type":"update","data":[{"symbol":"USDC/USDT","bids":[{"price":1.0004,"qty":66716.72538967}],"asks":[],"checksum":1221648441,"timestamp":"2024-06-01T22:43:03.923028Z"}]}
{"channel":"book","type":"update","data":[{"symbol":"USDC/USDT","bids":[{"price":1.0004,"qty":322825.29231397}],"asks":[],"checksum":31595996,"timestamp":"2024-06-01T22:43:03.927816Z"}]}
{"channel":"book","type":"update","data":[{"symbol":"USDC/USDT","bids":[{"price":1.0004,"qty":66716.72538967}],"asks":[],"checksum":1221648441,"timestamp":"2024-06-01T22:43:07.325651Z"}]}
{"channel":"book","type":"update","data":[{"symbol":"USDC/USDT","bids":[{"price":1.0004,"qty":394549.47867369}],"asks":[],"checksum":2079020241,"timestamp":"2024-06-01T22:43:07.330416Z"}]}
{"channel":"book","type":"update","data":[{"symbol":"USDC/USDT","bids":[{"price":1.0005,"qty":67365.28058289}],"asks":[],"checksum":1232574328,"timestamp":"2024-06-01T22:43:07.703679Z"}]}
{"channel":"book","type":"update","data":[{"symbol":"USDC/USDT","bids":[{"price":1.0005,"qty":67951.12146650}],"asks":[],"checksum":3762897582,"timestamp":"2024-06-01T22:43:07.705854Z"}]}
{"channel":"book","type":"update","data":[{"symbol":"USDC/USDT","bids":[{"price":1.0004,"qty":66716.72538967}],"asks":[],"checksum":2382639097,"timestamp":"2024-06-01T22:43:10.672164Z"}]}
{"channel":"book","type":"update","data":[{"symbol":"USDC/USDT","bids":[{"price":1.0004,"qty":405820.42044361}],"asks":[],"checksum":1934838953,"timestamp":"2024-06-01T22:43:10.676842Z"}]}
{"channel":"book","type":"update","data":[{"symbol":"USDC/USDT","bids":[{"price":1.0005,"qty":67365.28058289}],"asks":[],"checksum":3664615807,"timestamp":"2024-06-01T22:43:10.898916Z"}]}
{"channel":"book","type":"update","data":[{"symbol":"USDC/USDT","bids":[{"price":1.0005,"qty":68848.66211277}],"asks":[],"checksum":4178602647,"timestamp":"2024-06-01T22:43:10.903617Z"}]}
{"channel":"book","type":"update","data":[{"symbol":"USDC/USDT","bids":[],"asks":[{"price":1.0009,"qty":124.53543036}],"checksum":3395135531,"timestamp":"2024-06-01T22:43:11.620132Z"}]}
{"channel":"book","type":"update","data":[{"symbol":"USDC/USDT","bids":[],"asks":[{"price":1.0009,"qty":99683.30397460}],"checksum":2574938273,"timestamp":"2024-06-01T22:43:11.621270Z"}]}
{"channel":"book","type":"update","data":[{"symbol":"USDC/USDT","bids":[{"price":1.0008,"qty":99016.55891342}],"asks":[],"checksum":1388429522,"timestamp":"2024-06-01T22:43:11.870465Z"}]}
{"channel":"book","type":"update","data":[{"symbol":"USDC/USDT","bids":[{"price":1.0008,"qty":97242.55891342}],"asks":[],"checksum":2574938273,"timestamp":"2024-06-01T22:43:11.889667Z"}]}
{"channel":"book","type":"update","data":[{"symbol":"USDC/USDT","bids":[{"price":1.0004,"qty":66716.72538967}],"asks":[],"checksum":1920933501,"timestamp":"2024-06-01T22:43:14.117033Z"}]}
{"channel":"book","type":"update","data":[{"symbol":"USDC/USDT","bids":[{"price":1.0004,"qty":396598.73430072}],"asks":[],"checksum":2430362315,"timestamp":"2024-06-01T22:43:14.127321Z"}]}
{"channel":"book","type":"update","data":[{"symbol":"USDC/USDT","bids":[],"asks":[{"price":1.0009,"qty":124.53543036}],"checksum":3288054337,"timestamp":"2024-06-01T22:43:15.068644Z"}]}
{"channel":"book","type":"update","data":[{"symbol":"USDC/USDT","bids":[],"asks":[{"price":1.0009,"qty":111390.35436481}],"checksum":15904270,"timestamp":"2024-06-01T22:43:15.069823Z"}]}
{"channel":"book","type":"update","data":[{"symbol":"USDC/USDT","bids":[{"price":1.0004,"qty":394404.25960072}],"asks":[],"checksum":1129177151,"timestamp":"2024-06-01T22:43:15.169717Z"}]}
{"channel":"book","type":"update","data":[{"symbol":"USDC/USDT","bids":[{"price":1.0001,"qty":2051.25291869}],"asks":[],"checksum":832535387,"timestamp":"2024-06-01T22:43:15.170022Z"}]}
{"channel":"book","type":"update","data":[{"symbol":"USDC/USDT","bids":[{"price":1.0008,"qty":99079.55891342}],"asks":[],"checksum":1153614958,"timestamp":"2024-06-01T22:43:15.323862Z"}]}
{"channel":"book","type":"update","data":[{"symbol":"USDC/USDT","bids":[{"price":1.0004,"qty":400869.87740072}],"asks":[],"checksum":866392850,"timestamp":"2024-06-01T22:43:15.369610Z"}]}
{"channel":"book","type":"update","data":[{"symbol":"USDC/USDT","bids":[{"price":1.0003,"qty":163169.64510000}],"asks":[],"checksum":2243845176,"timestamp":"2024-06-01T22:43:15.369891Z"}]}
{"channel":"book","type":"update","data":[{"symbol":"USDC/USDT","bids":[{"price":1.0008,"qty":97242.55891342}],"asks":[],"checksum":4041466637,"timestamp":"2024-06-01T22:43:15.604958Z"}]}
{"channel":"book","type":"update","data":[{"symbol":"USDC/USDT","bids":[{"price":1.0004,"qty":70987.86848967}],"asks":[],"checksum":3019807886,"timestamp":"2024-06-01T22:43:17.428786Z"}]}
{"channel":"book","type":"update","data":[{"symbol":"USDC/USDT","bids":[{"price":1.0004,"qty":395412.50569266}],"asks":[],"checksum":1979984997,"timestamp":"2024-06-01T22:43:17.430649Z"}]}
{"channel":"book","type":"update","data":[{"symbol":"USDC/USDT","bids":[{"price":1.0005,"qty":74436.97242170}],"asks":[],"checksum":3108019503,"timestamp":"2024-06-01T22:43:17.430732Z"}]}
{"channel":"book","type":"update","data":[{"symbol":"USDC/USDT","bids":[],"asks":[{"price":1.0009,"qty":111976.19522863}],"checksum":2799463759,"timestamp":"2024-06-01T22:43:18.125273Z"}]}
{"channel":"book","type":"update","data":[{"symbol":"USDC/USDT","bids":[],"asks":[{"price":1.0009,"qty":710.37629418}],"checksum":1307786664,"timestamp":"2024-06-01T22:43:18.520512Z"}]}
{"channel":"book","type":"update","data":[{"symbol":"USDC/USDT","bids":[],"asks":[{"price":1.0009,"qty":119780.89612022}],"checksum":4030759369,"timestamp":"2024-06-01T22:43:18.522723Z"}]}
{"channel":"book","type":"update","data":[{"symbol":"USDC/USDT","bids":[{"price":1.0008,"qty":98857.55891342}],"asks":[],"checksum":4014375668,"timestamp":"2024-06-01T22:43:18.791267Z"}]}
{"channel":"book","type":"update","data":[{"symbol":"USDC/USDT","bids":[{"price":1.0008,"qty":97242.55891342}],"asks":[],"checksum":4030759369,"timestamp":"2024-06-01T22:43:19.080737Z"}]}
{"channel":"book","type":"update","data":[{"symbol":"USDC/USDT","bids":[{"price":1.0005,"qty":68848.66211277}],"asks":[],"checksum":1057239171,"timestamp":"2024-06-01T22:43:20.870916Z"}]}
{"channel":"book","type":"update","data":[{"symbol":"USDC/USDT","bids":[{"price":1.0004,"qty":70987.86848967}],"asks":[],"checksum":3668260712,"timestamp":"2024-06-01T22:43:20.870950Z"}]}
{"channel":"book","type":"update","data":[{"symbol":"USDC/USDT","bids":[{"price":1.0005,"qty":107735.39075668}],"asks":[],"checksum":347085945,"timestamp":"2024-06-01T22:43:20.875518Z"}]}
{"channel":"book","type":"update","data":[{"symbol":"USDC/USDT","bids":[{"price":1.0004,"qty":307628.65805238}],"asks":[],"checksum":3666792927,"timestamp":"2024-06-01T22:43:20.875697Z"}]}
{"channel":"book","type":"update","data":[{"symbol":"USDC/USDT","bids":[],"asks":[{"price":1.0009,"qty":119195.05525640}],"checksum":3346181496,"timestamp":"2024-06-01T22:43:21.197838Z"}]}
{"channel":"book","type":"update","data":[{"symbol":"USDC/USDT","bids":[],"asks":[{"price":1.0009,"qty":119293.10230178}],"checksum":791528974,"timestamp":"2024-06-01T22:43:21.199374Z"}]}
{"channel":"book","type":"update","data":[{"symbol":"USDC/USDT","bids":[],"asks":[{"price":1.0009,"qty":222.58247574}],"checksum":3162158126,"timestamp":"2024-06-01T22:43:21.905885Z"}]}
{"channel":"book","type":"update","data":[{"symbol":"USDC/USDT","bids":[],"asks":[{"price":1.0009,"qty":105634.87502579}],"checksum":1301214236,"timestamp":"2024-06-01T22:43:21.906775Z"}]}
{"channel":"book","type":"update","data":[{"symbol":"USDC/USDT","bids":[{"price":1.0008,"qty":98924.55891342}],"asks":[],"checksum":1461789832,"timestamp":"2024-06-01T22:43:22.162364Z"}]}
{"channel":"book","type":"update","data":[{"symbol":"USDC/USDT","bids":[{"price":1.0008,"qty":97242.55891342}],"asks":[],"checksum":1301214236,"timestamp":"2024-06-01T22:43:22.165057Z"}]}
{"channel":"book","type":"update","data":[{"symbol":"USDC/USDT","bids":[{"price":1.0005,"qty":106252.00922680}],"asks":[],"checksum":131159335,"timestamp":"2024-06-01T22:43:23.483875Z"}]}
{"channel":"book","type":"update","data":[{"symbol":"USDC/USDT","bids":[{"price":1.0006,"qty":152352.54474523}],"asks":[],"checksum":1743106277,"timestamp":"2024-06-01T22:43:23.488516Z"}]}
{"channel":"book","type":"update","data":[{"symbol":"USDC/USDT","bids":[],"asks":[{"price":1.0009,"qty":105536.82798041}],"checksum":651741288,"timestamp":"2024-06-01T22:43:24.350453Z"}]}
{"channel":"book","type":"update","data":[{"symbol":"USDC/USDT","bids":[],"asks":[{"price":1.0009,"qty":106337.29802268}],"checksum":20513593,"timestamp":"2024-06-01T22:43:24.353289Z"}]}
{"channel":"book","type":"update","data":[{"symbol":"USDC/USDT","bids":[],"asks":[{"price":1.0009,"qty":925.00547263}],"checksum":876747279,"timestamp":"2024-06-01T22:43:25.415648Z"}]}
{"channel":"book","type":"update","data":[{"symbol":"USDC/USDT","bids":[],"asks":[{"price":1.0009,"qty":123897.86026043}],"checksum":1826948866,"timestamp":"2024-06-01T22:43:25.416920Z"}]}
{"channel":"book","type":"update","data":[{"symbol":"USDC/USDT","bids":[{"price":1.0008,"qty":99282.55891342}],"asks":[],"checksum":4267205160,"timestamp":"2024-06-01T22:43:25.681950Z"}]}
{"channel":"book","type":"update","data":[{"symbol":"USDC/USDT","bids":[{"price":1.0008,"qty":97242.55891342}],"asks":[],"checksum":1826948866,"timestamp":"2024-06-01T22:43:25.940941Z"}]}
{"channel":"book","type":"update","data":[{"symbol":"USDC/USDT","bids":[{"price":1.0006,"qty":152054.50223513}],"asks":[],"checksum":215081664,"timestamp":"2024-06-01T22:43:26.852300Z"}]}
{"channel":"book","type":"update","data":[{"symbol":"USDC/USDT","bids":[{"price":1.0006,"qty":152167.18308111}],"asks":[],"checksum":1430823156,"timestamp":"2024-06-01T22:43:26.857683Z"}]}
{"channel":"book","type":"update","data":[{"symbol":"USDC/USDT","bids":[],"asks":[{"price":1.0009,"qty":123097.39021816}],"checksum":70934546,"timestamp":"2024-06-01T22:43:27.593283Z"}]}
{"channel":"book","type":"update","data":[{"symbol":"USDC/USDT","bids":[],"asks":[{"price":1.0009,"qty":123488.11350523}],"checksum":1629493633,"timestamp":"2024-06-01T22:43:27.594403Z"}]}
{"channel":"book","type":"update","data":[{"symbol":"USDC/USDT","bids":[{"price":1.0004,"qty":70987.86848967}],"asks":[],"checksum":2973712844,"timestamp":"2024-06-01T22:43:27.816591Z"}]}
{"channel":"book","type":"update","data":[{"symbol":"USDC/USDT","bids":[{"price":1.0005,"qty":67365.28058289}],"asks":[],"checksum":2076433596,"timestamp":"2024-06-01T22:43:27.816645Z"}]}
{"channel":"book","type":"update","data":[{"symbol":"USDC/USDT","bids":[{"price":1.0004,"qty":352744.38814896}],"asks":[],"checksum":1058084651,"timestamp":"2024-06-01T22:43:27.821394Z"}]}
{"channel":"book","type":"update","data":[{"symbol":"USDC/USDT","bids":[{"price":1.0005,"qty":74791.62716584}],"asks":[],"checksum":2209352621,"timestamp":"2024-06-01T22:43:27.821567Z"}]}
{"channel":"book","type":"update","data":[{"symbol":"USDC/USDT","bids":[{"price":1.0005,"qty":73785.13572466},{"price":1.0004,"qty":353750.98019904}],"asks":[],"checksum":4293158500,"timestamp":"2024-06-01T22:43:28.200439Z"}]}
{"channel":"book","type":"update","data":[{"symbol":"USDC/USDT","bids":[],"asks":[{"price":1.0009,"qty":515.25871743}],"checksum":199884878,"timestamp":"2024-06-01T22:43:28.814083Z"}]}
{"channel":"book","type":"update","data":[{"symbol":"USDC/USDT","bids":[],"asks":[{"price":1.0009,"qty":119585.76345912}],"checksum":3310622230,"timestamp":"2024-06-01T22:43:28.814634Z"}]}
{"channel":"book","type":"update","data":[{"symbol":"USDC/USDT","bids":[{"price":1.0008,"qty":99077.55891342}],"asks":[],"checksum":101714135,"timestamp":"2024-06-01T22:43:29.074667Z"}]}
{"channel":"book","type":"update","data":[{"symbol":"USDC/USDT","bids":[{"price":1.0008,"qty":97242.55891342}],"asks":[],"checksum":3310622230,"timestamp":"2024-06-01T22:43:29.076997Z"}]}
{"channel":"book","type":"update","data":[{"symbol":"USDC/USDT","bids":[{"price":1.0006,"qty":152054.50223513}],"asks":[],"checksum":4012586346,"timestamp":"2024-06-01T22:43:29.783241Z"}]}
{"channel":"book","type":"update","data":[{"symbol":"USDC/USDT","bids":[{"price":1.0005,"qty":74292.92951224}],"asks":[],"checksum":3744912608,"timestamp":"2024-06-01T22:43:29.787949Z"}]}
{"channel":"book","type":"update","data":[{"symbol":"USDC/USDT","bids":[],"asks":[{"price":1.0009,"qty":119195.04017205}],"checksum":1461345263,"timestamp":"2024-06-01T22:43:30.624142Z"}]}
{"channel":"book","type":"update","data":[{"symbol":"USDC/USDT","bids":[],"asks":[{"price":1.0009,"qty":119273.57545494}],"checksum":2814741740,"timestamp":"2024-06-01T22:43:30.624951Z"}]}
{"channel":"book","type":"update","data":[{"symbol":"USDC/USDT","bids":[{"price":1.0005,"qty":66866.58292929}],"asks":[],"checksum":2835863506,"timestamp":"2024-06-01T22:43:31.382662Z"}]}
{"channel":"book","type":"update","data":[{"symbol":"USDC/USDT","bids":[{"price":1.0004,"qty":71994.46053975}],"asks":[],"checksum":3136702833,"timestamp":"2024-06-01T22:43:31.382967Z"}]}
{"channel":"book","type":"update","data":[{"symbol":"USDC/USDT","bids":[{"price":1.0005,"qty":122147.40440234}],"asks":[],"checksum":3589602852,"timestamp":"2024-06-01T22:43:31.387743Z"}]}
{"channel":"book","type":"update","data":[{"symbol":"USDC/USDT","bids":[{"price":1.0004,"qty":276342.32834029}],"asks":[],"checksum":279921702,"timestamp":"2024-06-01T22:43:31.387885Z"}]}
{"channel":"book","type":"update","data":[{"symbol":"USDC/USDT","bids":[{"price":1.0005,"qty":121639.61061476}],"asks":[],"checksum":2661928069,"timestamp":"2024-06-01T22:43:32.796961Z"}]}
{"channel":"book","type":"update","data":[{"symbol":"USDC/USDT","bids":[{"price":1.0006,"qty":152229.98652672}],"asks":[],"checksum":914333822,"timestamp":"2024-06-01T22:43:32.801962Z"}]}
