{"channel":"book","type":"snapshot","data":[{"symbol":"USDT/AUD","bids":[{"price":1.5037,"qty":6895.79458545},{"price":1.5036,"qty":2000.00000000},{"price":1.5035,"qty":2000.00000000},{"price":1.5034,"qty":1000.00000000},{"price":1.5033,"qty":5253.48992577},{"price":1.5032,"qty":2255.00000000},{"price":1.5031,"qty":2683.47540373},{"price":1.5030,"qty":13596.58246793},{"price":1.5029,"qty":7311.35000000},{"price":1.5028,"qty":7323.08253599}],"asks":[{"price":1.5038,"qty":42537.54007376},{"price":1.5039,"qty":2213.87583805},{"price":1.5040,"qty":374.00000000},{"price":1.5041,"qty":940.43874045},{"price":1.5042,"qty":4059.83236983},{"price":1.5043,"qty":25723.72937793},{"price":1.5044,"qty":42784.68681959},{"price":1.5045,"qty":25891.82000000},{"price":1.5046,"qty":20000.00000000},{"price":1.5048,"qty":4719.38000000}],"checksum":3895939629}]}
{"channel":"book","type":"update","data":[{"symbol":"USDT/AUD","bids":[],"asks":[{"price":1.5042,"qty":4195.46201747}],"checksum":399508577,"timestamp":"2024-06-01T22:43:17.637690Z"}]}
{"channel":"book","type":"update","data":[{"symbol":"USDT/AUD","bids":[],"asks":[{"price":1.5043,"qty":25588.09973029}],"checksum":4019831870,"timestamp":"2024-06-01T22:43:17.801187Z"}]}
{"channel":"book","type":"update","data":[{"symbol":"USDT/AUD","bids":[{"price":1.5032,"qty":3783.39961415}],"asks":[],"checksum":4012368306,"timestamp":"2024-06-01T22:43:20.249113Z"}]}
{"channel":"book","type":"update","data":[{"symbol":"USDT/AUD","bids":[{"price":1.5030,"qty":12067.97946765}],"asks":[],"checksum":1126429245,"timestamp":"2024-06-01T22:43:20.249366Z"}]}
{"channel":"book","type":"update","data":[{"symbol":"USDT/AUD","bids":[{"price":1.5032,"qty":2255.00000000}],"asks":[],"checksum":1134417841,"timestamp":"2024-06-01T22:43:20.308131Z"}]}
{"channel":"book","type":"update","data":[{"symbol":"USDT/AUD","bids":[{"price":1.5031,"qty":4211.97672512}],"asks":[],"checksum":2125630491,"timestamp":"2024-06-01T22:43:20.308323Z"}]}
{"channel":"book","type":"update","data":[{"symbol":"USDT/AUD","bids":[],"asks":[{"price":1.5043,"qty":0.00000000},{"price":1.5051,"qty":7301.00000000}],"checksum":212528989,"timestamp":"2024-06-01T22:43:20.871269Z"}]}
{"channel":"book","type":"update","data":[{"symbol":"USDT/AUD","bids":[],"asks":[{"price":1.5043,"qty":23537.10770411}],"checksum":3893084751,"timestamp":"2024-06-01T22:43:20.876049Z"}]}
{"channel":"book","type":"update","data":[{"symbol":"USDT/AUD","bids":[],"asks":[{"price":1.5041,"qty":402.00000000},{"price":1.5042,"qty":4713.95725446}],"checksum":2124709020,"timestamp":"2024-06-01T22:43:21.189096Z"}]}
{"channel":"book","type":"update","data":[{"symbol":"USDT/AUD","bids":[{"price":1.5031,"qty":4155.34439815}],"asks":[],"checksum":4241165911,"timestamp":"2024-06-01T22:43:22.743023Z"}]}
{"channel":"book","type":"update","data":[{"symbol":"USDT/AUD","bids":[{"price":1.5031,"qty":4248.59213780}],"asks":[],"checksum":2128641890,"timestamp":"2024-06-01T22:43:22.743974Z"}]}
{"channel":"book","type":"update","data":[{"symbol":"USDT/AUD","bids":[],"asks":[{"price":1.5042,"qty":4635.35567988}],"checksum":1669218414,"timestamp":"2024-06-01T22:43:23.484142Z"}]}
{"channel":"book","type":"update","data":[{"symbol":"USDT/AUD","bids":[],"asks":[{"price":1.5042,"qty":4655.37259417}],"checksum":3342265551,"timestamp":"2024-06-01T22:43:23.488808Z"}]}
{"channel":"book","type":"update","data":[{"symbol":"USDT/AUD","bids":[{"price":1.5030,"qty":2255.00000000}],"asks":[],"checksum":3057862149,"timestamp":"2024-06-01T22:43:24.151230Z"}]}
{"channel":"book","type":"update","data":[{"symbol":"USDT/AUD","bids":[{"price":1.5028,"qty":0.00000000},{"price":1.5027,"qty":4986.87000000}],"asks":[],"checksum":1163061005,"timestamp":"2024-06-01T22:43:24.151457Z"}]}
{"channel":"book","type":"update","data":[{"symbol":"USDT/AUD","bids":[{"price":1.5028,"qty":15671.44549644}],"asks":[],"checksum":276851674,"timestamp":"2024-06-01T22:43:24.152907Z"}]}
{"channel":"book","type":"update","data":[{"symbol":"USDT/AUD","bids":[{"price":1.5030,"qty":2626.84307676}],"asks":[],"checksum":2641569574,"timestamp":"2024-06-01T22:43:24.318939Z"}]}
{"channel":"book","type":"update","data":[{"symbol":"USDT/AUD","bids":[{"price":1.5031,"qty":3876.74906104}],"asks":[],"checksum":2459462921,"timestamp":"2024-06-01T22:43:24.483359Z"}]}
{"channel":"book","type":"update","data":[{"symbol":"USDT/AUD","bids":[{"price":1.5031,"qty":3783.50132139}],"asks":[],"checksum":265070413,"timestamp":"2024-06-01T22:43:26.198035Z"}]}
{"channel":"book","type":"update","data":[{"symbol":"USDT/AUD","bids":[{"price":1.5030,"qty":2695.68054129}],"asks":[],"checksum":899560543,"timestamp":"2024-06-01T22:43:26.198926Z"}]}
{"channel":"book","type":"update","data":[{"symbol":"USDT/AUD","bids":[{"price":1.5028,"qty":0.00000000},{"price":1.5027,"qty":4986.87000000}],"asks":[],"checksum":887079615,"timestamp":"2024-06-01T22:43:27.038145Z"}]}
{"channel":"book","type":"update","data":[{"symbol":"USDT/AUD","bids":[{"price":1.5028,"qty":7323.08253599}],"asks":[],"checksum":3352191927,"timestamp":"2024-06-01T22:43:27.039787Z"}]}
{"channel":"book","type":"update","data":[{"symbol":"USDT/AUD","bids":[{"price":1.5030,"qty":12508.66000894}],"asks":[],"checksum":642271567,"timestamp":"2024-06-01T22:43:27.039884Z"}]}
{"channel":"book","type":"update","data":[{"symbol":"USDT/AUD","bids":[],"asks":[{"price":1.5041,"qty":537.62964764}],"checksum":2312428159,"timestamp":"2024-06-01T22:43:27.976171Z"}]}
{"channel":"book","type":"update","data":[{"symbol":"USDT/AUD","bids":[],"asks":[{"price":1.5042,"qty":4519.74294653}],"checksum":808575031,"timestamp":"2024-06-01T22:43:28.145708Z"}]}
{"channel":"book","type":"update","data":[{"symbol":"USDT/AUD","bids":[{"price":1.5030,"qty":12439.82254441}],"asks":[],"checksum":2625201214,"timestamp":"2024-06-01T22:43:29.728818Z"}]}
{"channel":"book","type":"update","data":[{"symbol":"USDT/AUD","bids":[{"price":1.5031,"qty":3827.92851080}],"asks":[],"checksum":2409431594,"timestamp":"2024-06-01T22:43:29.729828Z"}]}
{"channel":"book","type":"update","data":[{"symbol":"USDT/AUD","bids":[],"asks":[{"price":1.5042,"qty":4499.72603224}],"checksum":1783192409,"timestamp":"2024-06-01T22:43:29.783193Z"}]}
{"channel":"book","type":"update","data":[{"symbol":"USDT/AUD","bids":[],"asks":[{"price":1.5042,"qty":4539.27116663}],"checksum":3028841387,"timestamp":"2024-06-01T22:43:29.788028Z"}]}
{"channel":"book","type":"update","data":[{"symbol":"USDT/AUD","bids":[],"asks":[{"price":1.5043,"qty":0.00000000},{"price":1.5051,"qty":7301.00000000}],"checksum":710551293,"timestamp":"2024-06-01T22:43:31.382942Z"}]}
{"channel":"book","type":"update","data":[{"symbol":"USDT/AUD","bids":[],"asks":[{"price":1.5042,"qty":4020.77592964},{"price":1.5043,"qty":518.61327443}],"checksum":460002666,"timestamp":"2024-06-01T22:43:31.386277Z"}]}
{"channel":"book","type":"update","data":[{"symbol":"USDT/AUD","bids":[],"asks":[{"price":1.5043,"qty":23030.22496545}],"checksum":471878438,"timestamp":"2024-06-01T22:43:31.388394Z"}]}
{"channel":"book","type":"update","data":[{"symbol":"USDT/AUD","bids":[],"asks":[{"price":1.5043,"qty":22511.61169102},{"price":1.5042,"qty":4539.38920407}],"checksum":2281597458,"timestamp":"2024-06-01T22:43:31.391926Z"}]}
{"channel":"book","type":"update","data":[{"symbol":"USDT/AUD","bids":[],"asks":[{"price":1.5042,"qty":4499.84406968}],"checksum":2853201033,"timestamp":"2024-06-01T22:43:32.797346Z"}]}
{"channel":"book","type":"update","data":[{"symbol":"USDT/AUD","bids":[],"asks":[{"price":1.5042,"qty":4519.86098397}],"checksum":826166587,"timestamp":"2024-06-01T22:43:32.802278Z"}]}
{"channel":"book","type":"update","data":[{"symbol":"USDT/AUD","bids":[{"price":1.5031,"qty":3783.50132139}],"asks":[],"checksum":584723247,"timestamp":"2024-06-01T22:43:33.126080Z"}]}
{"channel":"book","type":"update","data":[{"symbol":"USDT/AUD","bids":[{"price":1.5031,"qty":3840.13364836}],"asks":[],"checksum":2938325260,"timestamp":"2024-06-01T22:43:33.127116Z"}]}
{"channel":"book","type":"update","data":[{"symbol":"USDT/AUD","bids":[],"asks":[{"price":1.5043,"qty":0.00000000},{"price":1.5051,"qty":7301.00000000}],"checksum":3170504233,"timestamp":"2024-06-01T22:43:34.835064Z"}]}
{"channel":"book","type":"update","data":[{"symbol":"USDT/AUD","bids":[],"asks":[{"price":1.5043,"qty":25588.09973029}],"checksum":2233939750,"timestamp":"2024-06-01T22:43:34.839948Z"}]}
{"channel":"book","type":"update","data":[{"symbol":"USDT/AUD","bids":[{"price":1.5031,"qty":4211.97672512}],"asks":[],"checksum":2586171024,"timestamp":"2024-06-01T22:43:34.906579Z"}]}
{"channel":"book","type":"update","data":[{"symbol":"USDT/AUD","bids":[{"price":1.5030,"qty":12067.97946765}],"asks":[],"checksum":1168930674,"timestamp":"2024-06-01T22:43:35.071861Z"}]}
{"channel":"book","type":"update","data":[{"symbol":"USDT/AUD","bids":[{"price":1.5031,"qty":4155.34439815}],"asks":[],"checksum":3351446969,"timestamp":"2024-06-01T22:43:36.468358Z"}]}
{"channel":"book","type":"update","data":[{"symbol":"USDT/AUD","bids":[{"price":1.5031,"qty":4199.77158756}],"asks":[],"checksum":3294349612,"timestamp":"2024-06-01T22:43:36.469120Z"}]}
{"channel":"book","type":"update","data":[{"symbol":"USDT/AUD","bids":[],"asks":[{"price":1.5043,"qty":0.00000000},{"price":1.5051,"qty":7301.00000000}],"checksum":4253478947,"timestamp":"2024-06-01T22:43:38.322185Z"}]}
{"channel":"book","type":"update","data":[{"symbol":"USDT/AUD","bids":[],"asks":[{"price":1.5043,"qty":23537.10770411}],"checksum":1390577528,"timestamp":"2024-06-01T22:43:38.326934Z"}]}
{"channel":"book","type":"update","data":[{"symbol":"USDT/AUD","bids":[],"asks":[{"price":1.5043,"qty":23672.73735175}],"checksum":2192987318,"timestamp":"2024-06-01T22:43:38.495999Z"}]}
{"channel":"book","type":"update","data":[{"symbol":"USDT/AUD","bids":[],"asks":[{"price":1.5041,"qty":402.00000000}],"checksum":757778310,"timestamp":"2024-06-01T22:43:38.662473Z"}]}
{"channel":"book","type":"update","data":[{"symbol":"USDT/AUD","bids":[],"asks":[{"price":1.5042,"qty":4499.84406968}],"checksum":3053776436,"timestamp":"2024-06-01T22:43:39.186289Z"}]}
{"channel":"book","type":"update","data":[{"symbol":"USDT/AUD","bids":[],"asks":[{"price":1.5042,"qty":4558.91742416}],"checksum":2976594110,"timestamp":"2024-06-01T22:43:39.193275Z"}]}
{"channel":"book","type":"update","data":[{"symbol":"USDT/AUD","bids":[],"asks":[{"price":1.5043,"qty":135.62964764}],"checksum":2173297279,"timestamp":"2024-06-01T22:43:41.689261Z"}]}
{"channel":"book","type":"update","data":[{"symbol":"USDT/AUD","bids":[],"asks":[{"price":1.5043,"qty":22647.24133866}],"checksum":1632297635,"timestamp":"2024-06-01T22:43:41.693918Z"}]}
{"channel":"book","type":"update","data":[{"symbol":"USDT/AUD","bids":[],"asks":[{"price":1.5042,"qty":4499.84406968}],"checksum":1713714217,"timestamp":"2024-06-01T22:43:42.167823Z"}]}
{"channel":"book","type":"update","data":[{"symbol":"USDT/AUD","bids":[],"asks":[{"price":1.5042,"qty":4534.50714904}],"checksum":1365175405,"timestamp":"2024-06-01T22:43:42.172466Z"}]}
{"channel":"book","type":"update","data":[{"symbol":"USDT/AUD","bids":[],"asks":[{"price":1.5042,"qty":553.27635379}],"checksum":3983457413,"timestamp":"2024-06-01T22:43:44.852767Z"}]}
{"channel":"book","type":"update","data":[{"symbol":"USDT/AUD","bids":[],"asks":[{"price":1.5043,"qty":26628.47213391}],"checksum":277489951,"timestamp":"2024-06-01T22:43:44.852844Z"}]}
{"channel":"book","type":"update","data":[{"symbol":"USDT/AUD","bids":[],"asks":[{"price":1.5043,"qty":4116.86044289}],"checksum":3236496358,"timestamp":"2024-06-01T22:43:45.075155Z"}]}
{"channel":"book","type":"update","data":[{"symbol":"USDT/AUD","bids":[],"asks":[{"price":1.5043,"qty":29704.96017318}],"checksum":3848948849,"timestamp":"2024-06-01T22:43:45.080240Z"}]}
{"channel":"book","type":"update","data":[{"symbol":"USDT/AUD","bids":[{"price":1.5031,"qty":2671.27026617}],"asks":[],"checksum":1586650138,"timestamp":"2024-06-01T22:43:45.177669Z"}]}
{"channel":"book","type":"update","data":[{"symbol":"USDT/AUD","bids":[{"price":1.5033,"qty":6781.78787029}],"asks":[],"checksum":2455315297,"timestamp":"2024-06-01T22:43:45.177946Z"}]}
{"channel":"book","type":"update","data":[{"symbol":"USDT/AUD","bids":[{"price":1.5033,"qty":5253.48992577}],"asks":[],"checksum":1586650138,"timestamp":"2024-06-01T22:43:45.206366Z"}]}
{"channel":"book","type":"update","data":[{"symbol":"USDT/AUD","bids":[{"price":1.5031,"qty":4199.77157442}],"asks":[],"checksum":513479215,"timestamp":"2024-06-01T22:43:45.206547Z"}]}
{"channel":"book","type":"update","data":[{"symbol":"USDT/AUD","bids":[],"asks":[{"price":1.5042,"qty":688.90600143}],"checksum":2752710823,"timestamp":"2024-06-01T22:43:47.907440Z"}]}
{"channel":"book","type":"update","data":[{"symbol":"USDT/AUD","bids":[],"asks":[{"price":1.5043,"qty":29569.33052554}],"checksum":1075371093,"timestamp":"2024-06-01T22:43:48.069204Z"}]}
{"channel":"book","type":"update","data":[{"symbol":"USDT/AUD","bids":[],"asks":[{"price":1.5043,"qty":3981.23079525}],"checksum":1388484778,"timestamp":"2024-06-01T22:43:48.485974Z"}]}
{"channel":"book","type":"update","data":[{"symbol":"USDT/AUD","bids":[],"asks":[{"price":1.5043,"qty":28543.83451245}],"checksum":316576934,"timestamp":"2024-06-01T22:43:48.487737Z"}]}
{"channel":"book","type":"update","data":[{"symbol":"USDT/AUD","bids":[{"price":1.5031,"qty":4155.34438501}],"asks":[],"checksum":3086326488,"timestamp":"2024-06-01T22:43:50.192130Z"}]}
{"channel":"book","type":"update","data":[{"symbol":"USDT/AUD","bids":[{"price":1.5031,"qty":4211.97671198}],"asks":[],"checksum":1993486119,"timestamp":"2024-06-01T22:43:50.193128Z"}]}
{"channel":"book","type":"update","data":[{"symbol":"USDT/AUD","bids":[],"asks":[{"price":1.5042,"qty":654.24292207}],"checksum":739226874,"timestamp":"2024-06-01T22:43:51.195832Z"}]}
{"channel":"book","type":"update","data":[{"symbol":"USDT/AUD","bids":[],"asks":[{"price":1.5042,"qty":732.84449665}],"checksum":4169834502,"timestamp":"2024-06-01T22:43:51.200475Z"}]}
{"channel":"book","type":"update","data":[{"symbol":"USDT/AUD","bids":[],"asks":[{"price":1.5043,"qty":3981.23079525}],"checksum":3501128630,"timestamp":"2024-06-01T22:43:51.954414Z"}]}
{"channel":"book","type":"update","data":[{"symbol":"USDT/AUD","bids":[],"asks":[{"price":1.5043,"qty":25467.34647318}],"checksum":2944330663,"timestamp":"2024-06-01T22:43:51.961089Z"}]}
