{"channel":"book","type":"snapshot","data":[{"symbol":"USDT/CHF","bids":[{"price":0.90244,"qty":435.51554389},{"price":0.90234,"qty":78.60157458},{"price":0.90233,"qty":3889.32867263},{"price":0.90232,"qty":393.00000000},{"price":0.90225,"qty":499.00000000},{"price":0.90215,"qty":175.23907662},{"price":0.90214,"qty":33246.84358283},{"price":0.90203,"qty":11449.69593993},{"price":0.90202,"qty":1108.62286867},{"price":0.90201,"qty":1108.63515925}],"asks":[{"price":0.90252,"qty":182.54331752},{"price":0.90261,"qty":374.60000000},{"price":0.90270,"qty":113.20103977},{"price":0.90271,"qty":98.12979468},{"price":0.90272,"qty":3027.18744235},{"price":0.90273,"qty":62.95351306},{"price":0.90275,"qty":474.00000000},{"price":0.90276,"qty":213.97131785},{"price":0.90277,"qty":116927.42136480},{"price":0.90278,"qty":9927.50000000}],"checksum":2851702439}]}
{"channel":"book","type":"update","data":[{"symbol":"USDT/CHF","bids":[{"price":0.90214,"qty":0.00000000},{"price":0.90200,"qty":1108.64745011}],"asks":[],"checksum":2951519328,"timestamp":"2024-06-01T22:43:19.689345Z"}]}
{"channel":"book","type":"update","data":[{"symbol":"USDT/CHF","bids":[{"price":0.90204,"qty":48869.41965961}],"asks":[],"checksum":3335328705,"timestamp":"2024-06-01T22:43:19.689646Z"}]}
{"channel":"book","type":"update","data":[{"symbol":"USDT/CHF","bids":[{"price":0.90203,"qty":0.00000000},{"price":0.90200,"qty":1108.64745011}],"asks":[],"checksum":234750837,"timestamp":"2024-06-01T22:43:19.702961Z"}]}
{"channel":"book","type":"update","data":[{"symbol":"USDT/CHF","bids":[{"price":0.90205,"qty":11449.44212701}],"asks":[],"checksum":2645022524,"timestamp":"2024-06-01T22:43:19.703264Z"}]}
{"channel":"book","type":"update","data":[{"symbol":"USDT/CHF","bids":[],"asks":[{"price":0.90278,"qty":4758.30000000}],"checksum":4085248022,"timestamp":"2024-06-01T22:43:20.123237Z"}]}
{"channel":"book","type":"update","data":[{"symbol":"USDT/CHF","bids":[{"price":0.90234,"qty":0.00000000},{"price":0.90200,"qty":1108.64745011}],"asks":[],"checksum":1722680770,"timestamp":"2024-06-01T22:43:20.554305Z"}]}
{"channel":"book","type":"update","data":[{"symbol":"USDT/CHF","bids":[{"price":0.90215,"qty":0.00000000},{"price":0.90197,"qty":1108.68432431}],"asks":[],"checksum":2127613558,"timestamp":"2024-06-01T22:43:20.554333Z"}]}
{"channel":"book","type":"update","data":[{"symbol":"USDT/CHF","bids":[{"price":0.90206,"qty":254.35555544}],"asks":[],"checksum":3501659673,"timestamp":"2024-06-01T22:43:20.554879Z"}]}
{"channel":"book","type":"update","data":[{"symbol":"USDT/CHF","bids":[],"asks":[{"price":0.90277,"qty":0.00000000},{"price":0.90280,"qty":8294.78247541}],"checksum":2344322747,"timestamp":"2024-06-01T22:43:20.871219Z"}]}
{"channel":"book","type":"update","data":[{"symbol":"USDT/CHF","bids":[],"asks":[{"price":0.90272,"qty":0.00000000},{"price":0.90281,"qty":14679.36000000}],"checksum":2129833896,"timestamp":"2024-06-01T22:43:20.871260Z"}]}
{"channel":"book","type":"update","data":[{"symbol":"USDT/CHF","bids":[],"asks":[{"price":0.90279,"qty":6804.15470657}],"checksum":1974581715,"timestamp":"2024-06-01T22:43:20.875909Z"}]}
{"channel":"book","type":"update","data":[{"symbol":"USDT/CHF","bids":[],"asks":[{"price":0.90274,"qty":11231.15554705}],"checksum":202531459,"timestamp":"2024-06-01T22:43:20.875926Z"}]}
{"channel":"book","type":"update","data":[{"symbol":"USDT/CHF","bids":[],"asks":[{"price":0.90277,"qty":98398.31665955}],"checksum":974890758,"timestamp":"2024-06-01T22:43:20.875960Z"}]}
{"channel":"book","type":"update","data":[{"symbol":"USDT/CHF","bids":[{"price":0.90233,"qty":0.00000000},{"price":0.90197,"qty":1108.68432431},{"price":0.90207,"qty":3890.49761286}],"asks":[],"checksum":1931713068,"timestamp":"2024-06-01T22:43:20.975039Z"}]}
{"channel":"book","type":"update","data":[{"symbol":"USDT/CHF","bids":[{"price":0.90207,"qty":0.00000000},{"price":0.90197,"qty":1108.68432431},{"price":0.90233,"qty":3889.37659353}],"asks":[],"checksum":2141347830,"timestamp":"2024-06-01T22:43:20.979068Z"}]}
{"channel":"book","type":"update","data":[{"symbol":"USDT/CHF","bids":[{"price":0.90208,"qty":11449.06129227}],"asks":[],"checksum":2049722952,"timestamp":"2024-06-01T22:43:20.981821Z"}]}
{"channel":"book","type":"update","data":[{"symbol":"USDT/CHF","bids":[{"price":0.90205,"qty":0.00000000},{"price":0.90200,"qty":1108.64745011}],"asks":[],"checksum":1045327995,"timestamp":"2024-06-01T22:43:20.981863Z"}]}
{"channel":"book","type":"update","data":[{"symbol":"USDT/CHF","bids":[{"price":0.90233,"qty":0.00000000},{"price":0.90197,"qty":1108.68432431},{"price":0.90207,"qty":3890.49761286}],"asks":[],"checksum":3938082449,"timestamp":"2024-06-01T22:43:20.983043Z"}]}
{"channel":"book","type":"update","data":[{"symbol":"USDT/CHF","bids":[{"price":0.90207,"qty":0.00000000},{"price":0.90197,"qty":1108.68432431},{"price":0.90233,"qty":3889.37659353}],"asks":[],"checksum":1045327995,"timestamp":"2024-06-01T22:43:20.986588Z"}]}
{"channel":"book","type":"update","data":[{"symbol":"USDT/CHF","bids":[{"price":0.90204,"qty":0.00000000},{"price":0.90197,"qty":1108.68432431}],"asks":[],"checksum":3943714456,"timestamp":"2024-06-01T22:43:21.828818Z"}]}
{"channel":"book","type":"update","data":[{"symbol":"USDT/CHF","bids":[{"price":0.90209,"qty":46916.59765001}],"asks":[],"checksum":2526426192,"timestamp":"2024-06-01T22:43:21.829583Z"}]}
{"channel":"book","type":"update","data":[{"symbol":"USDT/CHF","bids":[{"price":0.90208,"qty":0.00000000},{"price":0.90197,"qty":1108.68432431}],"asks":[],"checksum":774725838,"timestamp":"2024-06-01T22:43:21.852304Z"}]}
{"channel":"book","type":"update","data":[{"symbol":"USDT/CHF","bids":[{"price":0.90210,"qty":11448.80749526}],"asks":[],"checksum":4280077402,"timestamp":"2024-06-01T22:43:21.852761Z"}]}
{"channel":"book","type":"update","data":[{"symbol":"USDT/CHF","bids":[{"price":0.90206,"qty":0.00000000},{"price":0.90197,"qty":1108.68432431}],"asks":[],"checksum":851953206,"timestamp":"2024-06-01T22:43:23.099323Z"}]}
{"channel":"book","type":"update","data":[{"symbol":"USDT/CHF","bids":[{"price":0.90234,"qty":39.54513439}],"asks":[],"checksum":1113166454,"timestamp":"2024-06-01T22:43:23.100872Z"}]}
{"channel":"book","type":"update","data":[{"symbol":"USDT/CHF","bids":[{"price":0.90211,"qty":221.52324671}],"asks":[],"checksum":3558807075,"timestamp":"2024-06-01T22:43:23.100910Z"}]}
{"channel":"book","type":"update","data":[{"symbol":"USDT/CHF","bids":[{"price":0.90244,"qty":326.02493497}],"asks":[],"checksum":963130498,"timestamp":"2024-06-01T22:43:23.392867Z"}]}
{"channel":"book","type":"update","data":[{"symbol":"USDT/CHF","bids":[],"asks":[{"price":0.90271,"qty":0.00000000},{"price":0.90279,"qty":6804.15470657}],"checksum":800870788,"timestamp":"2024-06-01T22:43:23.483915Z"}]}
{"channel":"book","type":"update","data":[{"symbol":"USDT/CHF","bids":[],"asks":[{"price":0.90276,"qty":0.00000000},{"price":0.90280,"qty":8294.78247541}],"checksum":997762389,"timestamp":"2024-06-01T22:43:23.483982Z"}]}
{"channel":"book","type":"update","data":[{"symbol":"USDT/CHF","bids":[],"asks":[{"price":0.90270,"qty":0.00000000},{"price":0.90281,"qty":14679.36000000},{"price":0.90272,"qty":113.21089967}],"checksum":2825201039,"timestamp":"2024-06-01T22:43:23.487217Z"}]}
{"channel":"book","type":"update","data":[{"symbol":"USDT/CHF","bids":[],"asks":[{"price":0.90273,"qty":258.72440822}],"checksum":2756798371,"timestamp":"2024-06-01T22:43:23.488647Z"}]}
{"channel":"book","type":"update","data":[{"symbol":"USDT/CHF","bids":[],"asks":[{"price":0.90276,"qty":85.43596292}],"checksum":3162019524,"timestamp":"2024-06-01T22:43:23.488754Z"}]}
{"channel":"book","type":"update","data":[{"symbol":"USDT/CHF","bids":[{"price":0.90209,"qty":0.00000000},{"price":0.90200,"qty":1108.64745011}],"asks":[],"checksum":3901288612,"timestamp":"2024-06-01T22:43:23.907549Z"}]}
{"channel":"book","type":"update","data":[{"symbol":"USDT/CHF","bids":[{"price":0.90212,"qty":7860.15745805}],"asks":[],"checksum":1483864234,"timestamp":"2024-06-01T22:43:23.908860Z"}]}
{"channel":"book","type":"update","data":[{"symbol":"USDT/CHF","bids":[{"price":0.90211,"qty":36836.93592667}],"asks":[],"checksum":2373971185,"timestamp":"2024-06-01T22:43:23.909046Z"}]}
{"channel":"book","type":"update","data":[{"symbol":"USDT/CHF","bids":[{"price":0.90210,"qty":0.00000000},{"price":0.90200,"qty":1108.64745011}],"asks":[],"checksum":1022028891,"timestamp":"2024-06-01T22:43:23.918125Z"}]}
{"channel":"book","type":"update","data":[{"symbol":"USDT/CHF","bids":[{"price":0.90213,"qty":11448.42674966}],"asks":[],"checksum":1570264818,"timestamp":"2024-06-01T22:43:23.918426Z"}]}
{"channel":"book","type":"update","data":[{"symbol":"USDT/CHF","bids":[],"asks":[{"price":0.90272,"qty":230.90971719}],"checksum":1496390736,"timestamp":"2024-06-01T22:43:24.071913Z"}]}
{"channel":"book","type":"update","data":[{"symbol":"USDT/CHF","bids":[],"asks":[{"price":0.90272,"qty":117.69881752},{"price":0.90271,"qty":113.21091421}],"checksum":4097184251,"timestamp":"2024-06-01T22:43:24.075374Z"}]}
{"channel":"book","type":"update","data":[{"symbol":"USDT/CHF","bids":[],"asks":[{"price":0.90273,"qty":195.77089516}],"checksum":3327543841,"timestamp":"2024-06-01T22:43:24.233907Z"}]}
{"channel":"book","type":"update","data":[{"symbol":"USDT/CHF","bids":[],"asks":[{"price":0.90277,"qty":0.00000000},{"price":0.90280,"qty":8294.78247541}],"checksum":3662494959,"timestamp":"2024-06-01T22:43:24.323709Z"}]}
{"channel":"book","type":"update","data":[{"symbol":"USDT/CHF","bids":[],"asks":[{"price":0.90274,"qty":0.00000000},{"price":0.90281,"qty":14679.36000000}],"checksum":1446823907,"timestamp":"2024-06-01T22:43:24.323826Z"}]}
{"channel":"book","type":"update","data":[{"symbol":"USDT/CHF","bids":[],"asks":[{"price":0.90272,"qty":2119.39024678}],"checksum":1315099999,"timestamp":"2024-06-01T22:43:24.328127Z"}]}
{"channel":"book","type":"update","data":[{"symbol":"USDT/CHF","bids":[],"asks":[{"price":0.90277,"qty":110064.54338282}],"checksum":713916312,"timestamp":"2024-06-01T22:43:24.328358Z"}]}
{"channel":"book","type":"update","data":[{"symbol":"USDT/CHF","bids":[],"asks":[{"price":0.90274,"qty":3753.58176340}],"checksum":2571868038,"timestamp":"2024-06-01T22:43:24.328388Z"}]}
{"channel":"book","type":"update","data":[{"symbol":"USDT/CHF","bids":[{"price":0.90235,"qty":380.77023943}],"asks":[],"checksum":758244996,"timestamp":"2024-06-01T22:43:24.488595Z"}]}
{"channel":"book","type":"update","data":[{"symbol":"USDT/CHF","bids":[{"price":0.90233,"qty":0.00000000},{"price":0.90201,"qty":1108.63515925},{"price":0.90236,"qty":3889.24565644}],"asks":[],"checksum":1755766914,"timestamp":"2024-06-01T22:43:24.491890Z"}]}
{"channel":"book","type":"update","data":[{"symbol":"USDT/CHF","bids":[],"asks":[{"price":0.90272,"qty":2001.69142926}],"checksum":2463169583,"timestamp":"2024-06-01T22:43:24.549890Z"}]}
{"channel":"book","type":"update","data":[{"symbol":"USDT/CHF","bids":[{"price":0.90244,"qty":0.00000000},{"price":0.90201,"qty":1108.63515925}],"asks":[],"checksum":2720227245,"timestamp":"2024-06-01T22:43:24.654168Z"}]}
{"channel":"book","type":"update","data":[{"symbol":"USDT/CHF","bids":[{"price":0.90212,"qty":0.00000000},{"price":0.90200,"qty":1108.64745011}],"asks":[],"checksum":2245739536,"timestamp":"2024-06-01T22:43:25.960680Z"}]}
{"channel":"book","type":"update","data":[{"symbol":"USDT/CHF","bids":[{"price":0.90211,"qty":221.52324671}],"asks":[],"checksum":1179123725,"timestamp":"2024-06-01T22:43:25.960916Z"}]}
{"channel":"book","type":"update","data":[{"symbol":"USDT/CHF","bids":[{"price":0.90214,"qty":9812.97946765}],"asks":[],"checksum":2174096996,"timestamp":"2024-06-01T22:43:25.962233Z"}]}
{"channel":"book","type":"update","data":[{"symbol":"USDT/CHF","bids":[],"asks":[{"price":0.90276,"qty":0.00000000},{"price":0.90280,"qty":8294.78247541}],"checksum":1168595064,"timestamp":"2024-06-01T22:43:26.852442Z"}]}
{"channel":"book","type":"update","data":[{"symbol":"USDT/CHF","bids":[],"asks":[{"price":0.90273,"qty":0.00000000},{"price":0.90281,"qty":14679.36000000}],"checksum":1480554025,"timestamp":"2024-06-01T22:43:26.852582Z"}]}
{"channel":"book","type":"update","data":[{"symbol":"USDT/CHF","bids":[],"asks":[{"price":0.90271,"qty":0.00000000},{"price":0.90286,"qty":3981.23079525},{"price":0.90260,"qty":113.22019193}],"checksum":2355962685,"timestamp":"2024-06-01T22:43:26.855997Z"}]}
{"channel":"book","type":"update","data":[{"symbol":"USDT/CHF","bids":[],"asks":[{"price":0.90271,"qty":98.12979468}],"checksum":850636278,"timestamp":"2024-06-01T22:43:26.857665Z"}]}
{"channel":"book","type":"update","data":[{"symbol":"USDT/CHF","bids":[],"asks":[{"price":0.90276,"qty":57.33314499}],"checksum":1221894560,"timestamp":"2024-06-01T22:43:26.857811Z"}]}
{"channel":"book","type":"update","data":[{"symbol":"USDT/CHF","bids":[],"asks":[{"price":0.90273,"qty":117.65801477}],"checksum":1618266259,"timestamp":"2024-06-01T22:43:26.857896Z"}]}
{"channel":"book","type":"update","data":[{"symbol":"USDT/CHF","bids":[],"asks":[{"price":0.90261,"qty":0.00000000},{"price":0.90278,"qty":4758.30000000},{"price":0.90259,"qty":374.60000000}],"checksum":3346748869,"timestamp":"2024-06-01T22:43:26.887071Z"}]}
{"channel":"book","type":"update","data":[{"symbol":"USDT/CHF","bids":[],"asks":[{"price":0.90260,"qty":0.00000000},{"price":0.90278,"qty":4758.30000000},{"price":0.90270,"qty":113.22019193}],"checksum":4105411986,"timestamp":"2024-06-01T22:43:26.890346Z"}]}
{"channel":"book","type":"update","data":[{"symbol":"USDT/CHF","bids":[],"asks":[{"price":0.90272,"qty":0.00000000},{"price":0.90278,"qty":4758.30000000}],"checksum":114165267,"timestamp":"2024-06-01T22:43:27.816734Z"}]}
{"channel":"book","type":"update","data":[{"symbol":"USDT/CHF","bids":[],"asks":[{"price":0.90277,"qty":0.00000000},{"price":0.90280,"qty":8294.78247541}],"checksum":2889527807,"timestamp":"2024-06-01T22:43:27.816806Z"}]}
{"channel":"book","type":"update","data":[{"symbol":"USDT/CHF","bids":[],"asks":[{"price":0.90277,"qty":94327.39473348}],"checksum":1746640249,"timestamp":"2024-06-01T22:43:27.821280Z"}]}
{"channel":"book","type":"update","data":[{"symbol":"USDT/CHF","bids":[{"price":0.90234,"qty":0.00000000},{"price":0.90200,"qty":1108.64745011}],"asks":[],"checksum":3050854162,"timestamp":"2024-06-01T22:43:28.225836Z"}]}
{"channel":"book","type":"update","data":[{"symbol":"USDT/CHF","bids":[{"price":0.90211,"qty":0.00000000},{"price":0.90197,"qty":1108.68432431}],"asks":[],"checksum":734914185,"timestamp":"2024-06-01T22:43:28.225987Z"}]}
{"channel":"book","type":"update","data":[{"symbol":"USDT/CHF","bids":[{"price":0.90215,"qty":234.82733535}],"asks":[],"checksum":294026171,"timestamp":"2024-06-01T22:43:28.226780Z"}]}
{"channel":"book","type":"update","data":[{"symbol":"USDT/CHF","bids":[{"price":0.90213,"qty":0.00000000},{"price":0.90197,"qty":1108.68432431}],"asks":[],"checksum":3860836405,"timestamp":"2024-06-01T22:43:28.235823Z"}]}
{"channel":"book","type":"update","data":[{"symbol":"USDT/CHF","bids":[{"price":0.90203,"qty":11449.69592023}],"asks":[],"checksum":3656595098,"timestamp":"2024-06-01T22:43:28.236040Z"}]}
{"channel":"book","type":"update","data":[{"symbol":"USDT/CHF","bids":[],"asks":[{"price":0.90271,"qty":0.00000000},{"price":0.90279,"qty":19194.36921202}],"checksum":1824400951,"timestamp":"2024-06-01T22:43:29.783228Z"}]}
{"channel":"book","type":"update","data":[{"symbol":"USDT/CHF","bids":[],"asks":[{"price":0.90276,"qty":0.00000000},{"price":0.90280,"qty":8294.78247541}],"checksum":615188293,"timestamp":"2024-06-01T22:43:29.783374Z"}]}
{"channel":"book","type":"update","data":[{"symbol":"USDT/CHF","bids":[],"asks":[{"price":0.90270,"qty":0.00000000},{"price":0.90281,"qty":14679.36000000},{"price":0.90272,"qty":113.22571278}],"checksum":4046452560,"timestamp":"2024-06-01T22:43:29.786559Z"}]}
{"channel":"book","type":"update","data":[{"symbol":"USDT/CHF","bids":[],"asks":[{"price":0.90276,"qty":174.53346711}],"checksum":1377044767,"timestamp":"2024-06-01T22:43:29.788068Z"}]}
{"channel":"book","type":"update","data":[{"symbol":"USDT/CHF","bids":[{"price":0.90214,"qty":0.00000000},{"price":0.90197,"qty":1108.68432431}],"asks":[],"checksum":1181904253,"timestamp":"2024-06-01T22:43:30.263259Z"}]}
{"channel":"book","type":"update","data":[{"symbol":"USDT/CHF","bids":[{"price":0.90204,"qty":48015.06003041}],"asks":[],"checksum":4036737225,"timestamp":"2024-06-01T22:43:30.264484Z"}]}
{"channel":"book","type":"update","data":[{"symbol":"USDT/CHF","bids":[{"price":0.90203,"qty":0.00000000},{"price":0.90197,"qty":1108.68432431}],"asks":[],"checksum":1465416524,"timestamp":"2024-06-01T22:43:30.285839Z"}]}
{"channel":"book","type":"update","data":[{"symbol":"USDT/CHF","bids":[{"price":0.90205,"qty":11449.44214513}],"asks":[],"checksum":386518191,"timestamp":"2024-06-01T22:43:30.285975Z"}]}
{"channel":"book","type":"update","data":[{"symbol":"USDT/CHF","bids":[{"price":0.90215,"qty":0.00000000},{"price":0.90197,"qty":1108.68432431}],"asks":[],"checksum":532182333,"timestamp":"2024-06-01T22:43:30.681006Z"}]}
{"channel":"book","type":"update","data":[{"symbol":"USDT/CHF","bids":[{"price":0.90206,"qty":285.47865622}],"asks":[],"checksum":3285661703,"timestamp":"2024-06-01T22:43:30.682632Z"}]}
{"channel":"book","type":"update","data":[{"symbol":"USDT/CHF","bids":[],"asks":[{"price":0.90274,"qty":0.00000000},{"price":0.90280,"qty":8294.78247541}],"checksum":1866783726,"timestamp":"2024-06-01T22:43:31.382718Z"}]}
{"channel":"book","type":"update","data":[{"symbol":"USDT/CHF","bids":[],"asks":[{"price":0.90277,"qty":0.00000000},{"price":0.90281,"qty":14679.36000000}],"checksum":4022726648,"timestamp":"2024-06-01T22:43:31.382779Z"}]}
{"channel":"book","type":"update","data":[{"symbol":"USDT/CHF","bids":[],"asks":[{"price":0.90279,"qty":0.00000000},{"price":0.90287,"qty":57175.72598313}],"checksum":3171810439,"timestamp":"2024-06-01T22:43:31.383071Z"}]}
{"channel":"book","type":"update","data":[{"symbol":"USDT/CHF","bids":[],"asks":[{"price":0.90277,"qty":98398.31665955}],"checksum":358245979,"timestamp":"2024-06-01T22:43:31.388038Z"}]}
{"channel":"book","type":"update","data":[{"symbol":"USDT/CHF","bids":[],"asks":[{"price":0.90274,"qty":11231.15554705}],"checksum":772903989,"timestamp":"2024-06-01T22:43:31.388062Z"}]}
{"channel":"book","type":"update","data":[{"symbol":"USDT/CHF","bids":[],"asks":[{"price":0.90279,"qty":4800.23134505}],"checksum":2102426630,"timestamp":"2024-06-01T22:43:31.388097Z"}]}
{"channel":"book","type":"update","data":[{"symbol":"USDT/CHF","bids":[{"price":0.90204,"qty":0.00000000},{"price":0.90197,"qty":1108.68432431}],"asks":[],"checksum":832683568,"timestamp":"2024-06-01T22:43:32.380917Z"}]}
{"channel":"book","type":"update","data":[{"symbol":"USDT/CHF","bids":[{"price":0.90207,"qty":7860.15745805}],"asks":[],"checksum":1458494857,"timestamp":"2024-06-01T22:43:32.381265Z"}]}
{"channel":"book","type":"update","data":[{"symbol":"USDT/CHF","bids":[{"price":0.90206,"qty":37437.96625824}],"asks":[],"checksum":881484669,"timestamp":"2024-06-01T22:43:32.381309Z"}]}
{"channel":"book","type":"update","data":[{"symbol":"USDT/CHF","bids":[{"price":0.90205,"qty":0.00000000},{"price":0.90197,"qty":1108.68432431}],"asks":[],"checksum":3817399032,"timestamp":"2024-06-01T22:43:32.397162Z"}]}
{"channel":"book","type":"update","data":[{"symbol":"USDT/CHF","bids":[{"price":0.90208,"qty":11449.06132527}],"asks":[],"checksum":1647145385,"timestamp":"2024-06-01T22:43:32.397250Z"}]}
{"channel":"book","type":"update","data":[{"symbol":"USDT/CHF","bids":[],"asks":[{"price":0.90276,"qty":0.00000000},{"price":0.90280,"qty":8294.78247541}],"checksum":1182641562,"timestamp":"2024-06-01T22:43:32.796943Z"}]}
{"channel":"book","type":"update","data":[{"symbol":"USDT/CHF","bids":[],"asks":[{"price":0.90273,"qty":0.00000000},{"price":0.90281,"qty":14679.36000000}],"checksum":3859961989,"timestamp":"2024-06-01T22:43:32.797178Z"}]}
{"channel":"book","type":"update","data":[{"symbol":"USDT/CHF","bids":[],"asks":[{"price":0.90272,"qty":0.00000000},{"price":0.90287,"qty":57175.72598313},{"price":0.90273,"qty":113.22904315}],"checksum":3681643752,"timestamp":"2024-06-01T22:43:32.800586Z"}]}
{"channel":"book","type":"update","data":[{"symbol":"USDT/CHF","bids":[],"asks":[{"price":0.90273,"qty":308.99993831}],"checksum":675933015,"timestamp":"2024-06-01T22:43:32.802228Z"}]}
{"channel":"book","type":"update","data":[{"symbol":"USDT/CHF","bids":[],"asks":[{"price":0.90276,"qty":68.34877034}],"checksum":3986736362,"timestamp":"2024-06-01T22:43:32.802264Z"}]}
{"channel":"book","type":"update","data":[{"symbol":"USDT/CHF","bids":[],"asks":[{"price":0.90273,"qty":195.77089516},{"price":0.90272,"qty":113.22904315}],"checksum":527903195,"timestamp":"2024-06-01T22:43:32.805429Z"}]}
{"channel":"book","type":"update","data":[{"symbol":"USDT/CHF","bids":[{"price":0.90206,"qty":37152.48760202}],"asks":[],"checksum":2970199565,"timestamp":"2024-06-01T22:43:33.329343Z"}]}
{"channel":"book","type":"update","data":[{"symbol":"USDT/CHF","bids":[{"price":0.90209,"qty":258.01709671}],"asks":[],"checksum":1886680806,"timestamp":"2024-06-01T22:43:33.330728Z"}]}
{"channel":"book","type":"update","data":[{"symbol":"USDT/CHF","bids":[{"price":0.90207,"qty":0.00000000},{"price":0.90200,"qty":1108.64745011}],"asks":[],"checksum":1551592230,"timestamp":"2024-06-01T22:43:34.458189Z"}]}
{"channel":"book","type":"update","data":[{"symbol":"USDT/CHF","bids":[{"price":0.90206,"qty":0.00000000},{"price":0.90197,"qty":1108.68432431}],"asks":[],"checksum":3739571281,"timestamp":"2024-06-01T22:43:34.458431Z"}]}
{"channel":"book","type":"update","data":[{"symbol":"USDT/CHF","bids":[{"price":0.90210,"qty":7860.15745805}],"asks":[],"checksum":3603028635,"timestamp":"2024-06-01T22:43:34.459511Z"}]}
{"channel":"book","type":"update","data":[{"symbol":"USDT/CHF","bids":[{"price":0.90209,"qty":15929.46259315}],"asks":[],"checksum":1622400999,"timestamp":"2024-06-01T22:43:34.459608Z"}]}
{"channel":"book","type":"update","data":[{"symbol":"USDT/CHF","bids":[{"price":0.90211,"qty":11448.68055122}],"asks":[],"checksum":4053195464,"timestamp":"2024-06-01T22:43:34.533872Z"}]}
{"channel":"book","type":"update","data":[{"symbol":"USDT/CHF","bids":[{"price":0.90208,"qty":0.00000000},{"price":0.90200,"qty":1108.64745011}],"asks":[],"checksum":3637158306,"timestamp":"2024-06-01T22:43:34.533991Z"}]}
{"channel":"book","type":"update","data":[{"symbol":"USDT/CHF","bids":[],"asks":[{"price":0.90274,"qty":0.00000000},{"price":0.90280,"qty":8294.78247541}],"checksum":3942819160,"timestamp":"2024-06-01T22:43:34.835035Z"}]}
{"channel":"book","type":"update","data":[{"symbol":"USDT/CHF","bids":[],"asks":[{"price":0.90279,"qty":0.00000000},{"price":0.90281,"qty":14679.36000000}],"checksum":921824680,"timestamp":"2024-06-01T22:43:34.835225Z"}]}
{"channel":"book","type":"update","data":[{"symbol":"USDT/CHF","bids":[],"asks":[{"price":0.90279,"qty":19015.96953430}],"checksum":331947310,"timestamp":"2024-06-01T22:43:34.839915Z"}]}
{"channel":"book","type":"update","data":[{"symbol":"USDT/CHF","bids":[],"asks":[{"price":0.90274,"qty":3027.18744235}],"checksum":174212194,"timestamp":"2024-06-01T22:43:34.839935Z"}]}
{"channel":"book","type":"update","data":[{"symbol":"USDT/CHF","bids":[{"price":0.90209,"qty":15671.44549644}],"asks":[],"checksum":1284528866,"timestamp":"2024-06-01T22:43:35.872764Z"}]}
{"channel":"book","type":"update","data":[{"symbol":"USDT/CHF","bids":[{"price":0.90210,"qty":8036.40013311}],"asks":[],"checksum":3996775209,"timestamp":"2024-06-01T22:43:35.873267Z"}]}
{"channel":"book","type":"update","data":[{"symbol":"USDT/CHF","bids":[],"asks":[{"price":0.90273,"qty":0.00000000},{"price":0.90280,"qty":8294.78247541}],"checksum":1952944899,"timestamp":"2024-06-01T22:43:35.979874Z"}]}
{"channel":"book","type":"update","data":[{"symbol":"USDT/CHF","bids":[],"asks":[{"price":0.90276,"qty":0.00000000},{"price":0.90281,"qty":14679.36000000}],"checksum":2527660023,"timestamp":"2024-06-01T22:43:35.980097Z"}]}
{"channel":"book","type":"update","data":[{"symbol":"USDT/CHF","bids":[],"asks":[{"price":0.90272,"qty":0.00000000},{"price":0.90287,"qty":3981.23079525},{"price":0.90273,"qty":113.23613775}],"checksum":4200375353,"timestamp":"2024-06-01T22:43:35.983121Z"}]}
{"channel":"book","type":"update","data":[{"symbol":"USDT/CHF","bids":[],"asks":[{"price":0.90273,"qty":230.89415252}],"checksum":2671556756,"timestamp":"2024-06-01T22:43:35.984652Z"}]}
{"channel":"book","type":"update","data":[{"symbol":"USDT/CHF","bids":[],"asks":[{"price":0.90276,"qty":174.53346711}],"checksum":4228903582,"timestamp":"2024-06-01T22:43:35.984813Z"}]}
{"channel":"book","type":"update","data":[{"symbol":"USDT/CHF","bids":[],"asks":[{"price":0.90273,"qty":117.65801477},{"price":0.90272,"qty":113.23613775}],"checksum":4185602851,"timestamp":"2024-06-01T22:43:35.988031Z"}]}
{"channel":"book","type":"update","data":[{"symbol":"USDT/CHF","bids":[{"price":0.90210,"qty":176.24267506}],"asks":[],"checksum":2057808145,"timestamp":"2024-06-01T22:43:36.596338Z"}]}
{"channel":"book","type":"update","data":[{"symbol":"USDT/CHF","bids":[{"price":0.90209,"qty":0.00000000},{"price":0.90197,"qty":1108.68432431}],"asks":[],"checksum":1927083054,"timestamp":"2024-06-01T22:43:36.596355Z"}]}
{"channel":"book","type":"update","data":[{"symbol":"USDT/CHF","bids":[{"price":0.90212,"qty":13718.62348685}],"asks":[],"checksum":3775886000,"timestamp":"2024-06-01T22:43:36.596657Z"}]}
{"channel":"book","type":"update","data":[{"symbol":"USDT/CHF","bids":[{"price":0.90213,"qty":11448.42681620}],"asks":[],"checksum":3502254409,"timestamp":"2024-06-01T22:43:36.687685Z"}]}
{"channel":"book","type":"update","data":[{"symbol":"USDT/CHF","bids":[{"price":0.90211,"qty":0.00000000},{"price":0.90200,"qty":1108.64745011}],"asks":[],"checksum":1636935782,"timestamp":"2024-06-01T22:43:36.687714Z"}]}
{"channel":"book","type":"update","data":[{"symbol":"USDT/CHF","bids":[],"asks":[{"price":0.90273,"qty":235.35683229}],"checksum":2389398113,"timestamp":"2024-06-01T22:43:36.757715Z"}]}
{"channel":"book","type":"update","data":[{"symbol":"USDT/CHF","bids":[],"asks":[{"price":0.90274,"qty":0.00000000},{"price":0.90280,"qty":8294.78247541}],"checksum":2935539398,"timestamp":"2024-06-01T22:43:38.321934Z"}]}
{"channel":"book","type":"update","data":[{"symbol":"USDT/CHF","bids":[],"asks":[{"price":0.90279,"qty":0.00000000},{"price":0.90281,"qty":14679.36000000}],"checksum":4191871092,"timestamp":"2024-06-01T22:43:38.321948Z"}]}
{"channel":"book","type":"update","data":[{"symbol":"USDT/CHF","bids":[],"asks":[{"price":0.90274,"qty":11231.15554705}],"checksum":3264287258,"timestamp":"2024-06-01T22:43:38.326629Z"}]}
{"channel":"book","type":"update","data":[{"symbol":"USDT/CHF","bids":[],"asks":[{"price":0.90279,"qty":5802.19302581}],"checksum":3833846521,"timestamp":"2024-06-01T22:43:38.326738Z"}]}
{"channel":"book","type":"update","data":[{"symbol":"USDT/CHF","bids":[{"price":0.90210,"qty":0.00000000},{"price":0.90197,"qty":1108.68432431}],"asks":[],"checksum":2985676621,"timestamp":"2024-06-01T22:43:38.458255Z"}]}
{"channel":"book","type":"update","data":[{"symbol":"USDT/CHF","bids":[{"price":0.90214,"qty":239.70939037}],"asks":[],"checksum":3737616742,"timestamp":"2024-06-01T22:43:38.460193Z"}]}
{"channel":"book","type":"update","data":[{"symbol":"USDT/CHF","bids":[{"price":0.90237,"qty":380.77023943}],"asks":[],"checksum":3381435099,"timestamp":"2024-06-01T22:43:38.519794Z"}]}
{"channel":"book","type":"update","data":[{"symbol":"USDT/CHF","bids":[{"price":0.90236,"qty":0.00000000},{"price":0.90200,"qty":1108.64745011},{"price":0.90238,"qty":3889.14637537}],"asks":[],"checksum":101798153,"timestamp":"2024-06-01T22:43:38.523037Z"}]}
{"channel":"book","type":"update","data":[{"symbol":"USDT/CHF","bids":[{"price":0.90212,"qty":0.00000000},{"price":0.90200,"qty":1108.64745011}],"asks":[],"checksum":263992750,"timestamp":"2024-06-01T22:43:38.682846Z"}]}
{"channel":"book","type":"update","data":[{"symbol":"USDT/CHF","bids":[{"price":0.90214,"qty":12005.51086762}],"asks":[],"checksum":188239761,"timestamp":"2024-06-01T22:43:38.684114Z"}]}
{"channel":"book","type":"update","data":[{"symbol":"USDT/CHF","bids":[{"price":0.90213,"qty":0.00000000},{"price":0.90197,"qty":1108.68432431}],"asks":[],"checksum":4003472174,"timestamp":"2024-06-01T22:43:38.703537Z"}]}
{"channel":"book","type":"update","data":[{"symbol":"USDT/CHF","bids":[{"price":0.90203,"qty":11449.69594431}],"asks":[],"checksum":876610566,"timestamp":"2024-06-01T22:43:38.703671Z"}]}
{"channel":"book","type":"update","data":[{"symbol":"USDT/CHF","bids":[{"price":0.90235,"qty":0.00000000},{"price":0.90197,"qty":1108.68432431}],"asks":[],"checksum":861080956,"timestamp":"2024-06-01T22:43:38.757054Z"}]}
{"channel":"book","type":"update","data":[{"symbol":"USDT/CHF","bids":[],"asks":[{"price":0.90273,"qty":117.69881752}],"checksum":2371684003,"timestamp":"2024-06-01T22:43:39.186115Z"}]}
{"channel":"book","type":"update","data":[{"symbol":"USDT/CHF","bids":[],"asks":[{"price":0.90276,"qty":0.00000000},{"price":0.90280,"qty":8294.78247541}],"checksum":780009780,"timestamp":"2024-06-01T22:43:39.186388Z"}]}
{"channel":"book","type":"update","data":[{"symbol":"USDT/CHF","bids":[],"asks":[{"price":0.90276,"qty":102.52315550}],"checksum":3813926262,"timestamp":"2024-06-01T22:43:39.193103Z"}]}
{"channel":"book","type":"update","data":[{"symbol":"USDT/CHF","bids":[],"asks":[{"price":0.90273,"qty":313.46971268}],"checksum":335205803,"timestamp":"2024-06-01T22:43:39.193130Z"}]}
{"channel":"book","type":"update","data":[{"symbol":"USDT/CHF","bids":[{"price":0.90214,"qty":239.70939037}],"asks":[],"checksum":3700736765,"timestamp":"2024-06-01T22:43:40.830722Z"}]}
{"channel":"book","type":"update","data":[{"symbol":"USDT/CHF","bids":[{"price":0.90204,"qty":48869.41965961}],"asks":[],"checksum":2652286644,"timestamp":"2024-06-01T22:43:40.831971Z"}]}
{"channel":"book","type":"update","data":[{"symbol":"USDT/CHF","bids":[{"price":0.90203,"qty":0.00000000},{"price":0.90197,"qty":1108.68432431}],"asks":[],"checksum":2990984768,"timestamp":"2024-06-01T22:43:40.838024Z"}]}
{"channel":"book","type":"update","data":[{"symbol":"USDT/CHF","bids":[{"price":0.90205,"qty":11449.44214150}],"asks":[],"checksum":1635937329,"timestamp":"2024-06-01T22:43:40.838198Z"}]}
{"channel":"book","type":"update","data":[{"symbol":"USDT/CHF","bids":[{"price":0.90214,"qty":0.00000000},{"price":0.90197,"qty":1108.68432431}],"asks":[],"checksum":579576086,"timestamp":"2024-06-01T22:43:40.863496Z"}]}
{"channel":"book","type":"update","data":[{"symbol":"USDT/CHF","bids":[{"price":0.90215,"qty":225.06322530}],"asks":[],"checksum":3570138328,"timestamp":"2024-06-01T22:43:40.864783Z"}]}
{"channel":"book","type":"update","data":[{"symbol":"USDT/CHF","bids":[],"asks":[{"price":0.90274,"qty":0.00000000},{"price":0.90280,"qty":8294.78247541}],"checksum":3221585449,"timestamp":"2024-06-01T22:43:41.689004Z"}]}
{"channel":"book","type":"update","data":[{"symbol":"USDT/CHF","bids":[],"asks":[{"price":0.90279,"qty":0.00000000},{"price":0.90281,"qty":14679.36000000}],"checksum":1308834162,"timestamp":"2024-06-01T22:43:41.689234Z"}]}
{"channel":"book","type":"update","data":[{"symbol":"USDT/CHF","bids":[],"asks":[{"price":0.90279,"qty":13004.19944976}],"checksum":3954495919,"timestamp":"2024-06-01T22:43:41.693847Z"}]}
{"channel":"book","type":"update","data":[{"symbol":"USDT/CHF","bids":[],"asks":[{"price":0.90272,"qty":3140.42358010}],"checksum":3334530892,"timestamp":"2024-06-01T22:43:41.693980Z"}]}
{"channel":"book","type":"update","data":[{"symbol":"USDT/CHF","bids":[],"asks":[{"price":0.90272,"qty":3027.18744235},{"price":0.90271,"qty":113.23584388}],"checksum":414195122,"timestamp":"2024-06-01T22:43:41.697612Z"}]}
{"channel":"book","type":"update","data":[{"symbol":"USDT/CHF","bids":[],"asks":[{"price":0.90276,"qty":0.00000000},{"price":0.90280,"qty":8294.78247541}],"checksum":1747023330,"timestamp":"2024-06-01T22:43:42.167630Z"}]}
{"channel":"book","type":"update","data":[{"symbol":"USDT/CHF","bids":[],"asks":[{"price":0.90273,"qty":117.69881752}],"checksum":3746319983,"timestamp":"2024-06-01T22:43:42.167757Z"}]}
{"channel":"book","type":"update","data":[{"symbol":"USDT/CHF","bids":[],"asks":[{"price":0.90271,"qty":211.36563856}],"checksum":201620913,"timestamp":"2024-06-01T22:43:42.172380Z"}]}
{"channel":"book","type":"update","data":[{"symbol":"USDT/CHF","bids":[],"asks":[{"price":0.90276,"qty":190.40014594}],"checksum":544799505,"timestamp":"2024-06-01T22:43:42.172418Z"}]}
{"channel":"book","type":"update","data":[{"symbol":"USDT/CHF","bids":[],"asks":[{"price":0.90271,"qty":98.12979468},{"price":0.90270,"qty":113.23584232}],"checksum":2286447198,"timestamp":"2024-06-01T22:43:42.176050Z"}]}
{"channel":"book","type":"update","data":[{"symbol":"USDT/CHF","bids":[{"price":0.90204,"qty":0.00000000},{"price":0.90197,"qty":1108.68432431}],"asks":[],"checksum":2334611111,"timestamp":"2024-06-01T22:43:42.873340Z"}]}
{"channel":"book","type":"update","data":[{"symbol":"USDT/CHF","bids":[{"price":0.90206,"qty":48015.06003041}],"asks":[],"checksum":2357478317,"timestamp":"2024-06-01T22:43:42.875906Z"}]}
{"channel":"book","type":"update","data":[{"symbol":"USDT/CHF","bids":[{"price":0.90207,"qty":11449.18830752}],"asks":[],"checksum":1950948029,"timestamp":"2024-06-01T22:43:42.887635Z"}]}
{"channel":"book","type":"update","data":[{"symbol":"USDT/CHF","bids":[{"price":0.90205,"qty":0.00000000},{"price":0.90200,"qty":1108.64745011}],"asks":[],"checksum":2014775859,"timestamp":"2024-06-01T22:43:42.887968Z"}]}
{"channel":"book","type":"update","data":[{"symbol":"USDT/CHF","bids":[{"price":0.90215,"qty":0.00000000},{"price":0.90197,"qty":1108.68432431}],"asks":[],"checksum":3441100294,"timestamp":"2024-06-01T22:43:43.397011Z"}]}
{"channel":"book","type":"update","data":[{"symbol":"USDT/CHF","bids":[{"price":0.90208,"qty":285.47865622}],"asks":[],"checksum":3281656682,"timestamp":"2024-06-01T22:43:43.398198Z"}]}
{"channel":"book","type":"update","data":[{"symbol":"USDT/CHF","bids":[{"price":0.90206,"qty":0.00000000},{"price":0.90197,"qty":1108.68432431}],"asks":[],"checksum":902668073,"timestamp":"2024-06-01T22:43:44.987625Z"}]}
{"channel":"book","type":"update","data":[{"symbol":"USDT/CHF","bids":[{"price":0.90209,"qty":7860.15745805}],"asks":[],"checksum":3395856989,"timestamp":"2024-06-01T22:43:44.989018Z"}]}
{"channel":"book","type":"update","data":[{"symbol":"USDT/CHF","bids":[{"price":0.90208,"qty":39170.28410124}],"asks":[],"checksum":1934176531,"timestamp":"2024-06-01T22:43:44.989278Z"}]}
{"channel":"book","type":"update","data":[{"symbol":"USDT/CHF","bids":[{"price":0.90207,"qty":0.00000000},{"price":0.90197,"qty":1108.68432431}],"asks":[],"checksum":2491899865,"timestamp":"2024-06-01T22:43:44.994265Z"}]}
{"channel":"book","type":"update","data":[{"symbol":"USDT/CHF","bids":[{"price":0.90210,"qty":11448.80754193}],"asks":[],"checksum":1602046990,"timestamp":"2024-06-01T22:43:44.994349Z"}]}
{"channel":"book","type":"update","data":[{"symbol":"USDT/CHF","bids":[],"asks":[{"price":0.90272,"qty":0.00000000},{"price":0.90280,"qty":8294.78247541}],"checksum":494344664,"timestamp":"2024-06-01T22:43:45.075066Z"}]}
{"channel":"book","type":"update","data":[{"symbol":"USDT/CHF","bids":[],"asks":[{"price":0.90279,"qty":10812.00142959}],"checksum":4022460366,"timestamp":"2024-06-01T22:43:45.080202Z"}]}
{"channel":"book","type":"update","data":[{"symbol":"USDT/CHF","bids":[],"asks":[{"price":0.90274,"qty":11231.15554705}],"checksum":1143442347,"timestamp":"2024-06-01T22:43:45.080284Z"}]}
{"channel":"book","type":"update","data":[{"symbol":"USDT/CHF","bids":[{"price":0.90208,"qty":38884.80544502}],"asks":[],"checksum":3340268369,"timestamp":"2024-06-01T22:43:45.938436Z"}]}
{"channel":"book","type":"update","data":[{"symbol":"USDT/CHF","bids":[{"price":0.90211,"qty":267.17094988}],"asks":[],"checksum":581224646,"timestamp":"2024-06-01T22:43:45.939806Z"}]}
{"channel":"book","type":"update","data":[{"symbol":"USDT/CHF","bids":[{"price":0.90209,"qty":0.00000000},{"price":0.90200,"qty":1108.64745011}],"asks":[],"checksum":2123714727,"timestamp":"2024-06-01T22:43:47.132841Z"}]}
{"channel":"book","type":"update","data":[{"symbol":"USDT/CHF","bids":[{"price":0.90208,"qty":0.00000000},{"price":0.90197,"qty":1108.68432431}],"asks":[],"checksum":3936978216,"timestamp":"2024-06-01T22:43:47.132914Z"}]}
{"channel":"book","type":"update","data":[{"symbol":"USDT/CHF","bids":[{"price":0.90212,"qty":7860.15745805}],"asks":[],"checksum":2575618476,"timestamp":"2024-06-01T22:43:47.134148Z"}]}
{"channel":"book","type":"update","data":[{"symbol":"USDT/CHF","bids":[{"price":0.90211,"qty":15938.61644632}],"asks":[],"checksum":27982315,"timestamp":"2024-06-01T22:43:47.134372Z"}]}
{"channel":"book","type":"update","data":[{"symbol":"USDT/CHF","bids":[{"price":0.90213,"qty":11448.42682880}],"asks":[],"checksum":136320640,"timestamp":"2024-06-01T22:43:47.138690Z"}]}
{"channel":"book","type":"update","data":[{"symbol":"USDT/CHF","bids":[{"price":0.90210,"qty":0.00000000},{"price":0.90200,"qty":1108.64745011}],"asks":[],"checksum":1994425936,"timestamp":"2024-06-01T22:43:47.138887Z"}]}
{"channel":"book","type":"update","data":[{"symbol":"USDT/CHF","bids":[],"asks":[{"price":0.90276,"qty":0.00000000},{"price":0.90279,"qty":10812.00142959}],"checksum":1648077046,"timestamp":"2024-06-01T22:43:48.250046Z"}]}
{"channel":"book","type":"update","data":[{"symbol":"USDT/CHF","bids":[],"asks":[{"price":0.90271,"qty":0.00000000},{"price":0.90280,"qty":8294.78247541}],"checksum":2997242258,"timestamp":"2024-06-01T22:43:48.250084Z"}]}
{"channel":"book","type":"update","data":[{"symbol":"USDT/CHF","bids":[],"asks":[{"price":0.90273,"qty":313.46971268}],"checksum":2699637445,"timestamp":"2024-06-01T22:43:48.252596Z"}]}
{"channel":"book","type":"update","data":[{"symbol":"USDT/CHF","bids":[],"asks":[{"price":0.90276,"qty":85.43596292}],"checksum":2304433691,"timestamp":"2024-06-01T22:43:48.252779Z"}]}
{"channel":"book","type":"update","data":[{"symbol":"USDT/CHF","bids":[],"asks":[{"price":0.90270,"qty":0.00000000},{"price":0.90280,"qty":8294.78247541},{"price":0.90272,"qty":113.24257322}],"checksum":3859744223,"timestamp":"2024-06-01T22:43:48.253448Z"}]}
{"channel":"book","type":"update","data":[{"symbol":"USDT/CHF","bids":[{"price":0.90211,"qty":15671.44549644}],"asks":[],"checksum":3365264877,"timestamp":"2024-06-01T22:43:48.495909Z"}]}
{"channel":"book","type":"update","data":[{"symbol":"USDT/CHF","bids":[{"price":0.90212,"qty":8016.87191301}],"asks":[],"checksum":2906956343,"timestamp":"2024-06-01T22:43:48.496967Z"}]}
{"channel":"book","type":"update","data":[{"symbol":"USDT/CHF","bids":[{"price":0.90212,"qty":156.71445496}],"asks":[],"checksum":3899461620,"timestamp":"2024-06-01T22:43:49.257349Z"}]}
{"channel":"book","type":"update","data":[{"symbol":"USDT/CHF","bids":[{"price":0.90211,"qty":0.00000000},{"price":0.90197,"qty":1108.68432431}],"asks":[],"checksum":1217503530,"timestamp":"2024-06-01T22:43:49.257500Z"}]}
{"channel":"book","type":"update","data":[{"symbol":"USDT/CHF","bids":[{"price":0.90214,"qty":13718.62348685}],"asks":[],"checksum":766311638,"timestamp":"2024-06-01T22:43:49.259020Z"}]}
