{"channel":"book","type":"snapshot","data":[{"symbol":"USDT/GBP","bids":[{"price":0.7838,"qty":18472.45069012},{"price":0.7837,"qty":34576.62303553},{"price":0.7836,"qty":73742.78105306},{"price":0.7835,"qty":153197.22650779},{"price":0.7834,"qty":53116.00410650},{"price":0.7833,"qty":228157.69317384},{"price":0.7832,"qty":11462.76692807},{"price":0.7831,"qty":13442.70239342},{"price":0.7830,"qty":34161.11000000},{"price":0.7829,"qty":252552.58825512}],"asks":[{"price":0.7839,"qty":9284.73496573},{"price":0.7840,"qty":9398.29660404},{"price":0.7841,"qty":270202.31207504},{"price":0.7842,"qty":28992.20295000},{"price":0.7843,"qty":25006.92207306},{"price":0.7844,"qty":25004.85901351},{"price":0.7845,"qty":281460.39788280},{"price":0.7846,"qty":18863.57000000},{"price":0.7847,"qty":29214.56000000},{"price":0.7848,"qty":8219.88000000}],"checksum":1364459722}]}
{"channel":"book","type":"update","data":[{"symbol":"USDT/GBP","bids":[{"price":0.7835,"qty":37785.49460996}],"asks":[],"checksum":2652061551,"timestamp":"2024-06-01T22:43:18.337335Z"}]}
{"channel":"book","type":"update","data":[{"symbol":"USDT/GBP","bids":[{"price":0.7835,"qty":172153.33078065}],"asks":[],"checksum":2248152523,"timestamp":"2024-06-01T22:43:18.338132Z"}]}
{"channel":"book","type":"update","data":[{"symbol":"USDT/GBP","bids":[],"asks":[{"price":0.7839,"qty":9243.12936573}],"checksum":743832811,"timestamp":"2024-06-01T22:43:19.827264Z"}]}
{"channel":"book","type":"update","data":[{"symbol":"USDT/GBP","bids":[{"price":0.7836,"qty":13156.42933586}],"asks":[],"checksum":251718867,"timestamp":"2024-06-01T22:43:20.440965Z"}]}
{"channel":"book","type":"update","data":[{"symbol":"USDT/GBP","bids":[{"price":0.7838,"qty":12565.11524167}],"asks":[],"checksum":1456436290,"timestamp":"2024-06-01T22:43:20.441065Z"}]}
{"channel":"book","type":"update","data":[{"symbol":"USDT/GBP","bids":[{"price":0.7835,"qty":37785.49460996}],"asks":[],"checksum":828653962,"timestamp":"2024-06-01T22:43:20.441152Z"}]}
{"channel":"book","type":"update","data":[{"symbol":"USDT/GBP","bids":[{"price":0.7838,"qty":16519.62868053}],"asks":[],"checksum":207898589,"timestamp":"2024-06-01T22:43:20.442595Z"}]}
{"channel":"book","type":"update","data":[{"symbol":"USDT/GBP","bids":[{"price":0.7835,"qty":159067.13485305}],"asks":[],"checksum":4163134807,"timestamp":"2024-06-01T22:43:20.442611Z"}]}
{"channel":"book","type":"update","data":[{"symbol":"USDT/GBP","bids":[{"price":0.7836,"qty":71789.95904346}],"asks":[],"checksum":3472323047,"timestamp":"2024-06-01T22:43:20.442672Z"}]}
{"channel":"book","type":"update","data":[{"symbol":"USDT/GBP","bids":[{"price":0.7837,"qty":14309.42303553},{"price":0.7836,"qty":92057.15904346}],"asks":[],"checksum":1269611654,"timestamp":"2024-06-01T22:43:20.444251Z"}]}
{"channel":"book","type":"update","data":[{"symbol":"USDT/GBP","bids":[],"asks":[{"price":0.7841,"qty":8750.12933446}],"checksum":409592401,"timestamp":"2024-06-01T22:43:20.871024Z"}]}
{"channel":"book","type":"update","data":[{"symbol":"USDT/GBP","bids":[],"asks":[{"price":0.7842,"qty":46477.71114191}],"checksum":2362532743,"timestamp":"2024-06-01T22:43:20.875681Z"}]}
{"channel":"book","type":"update","data":[{"symbol":"USDT/GBP","bids":[],"asks":[{"price":0.7841,"qty":232258.95959077}],"checksum":2029123979,"timestamp":"2024-06-01T22:43:20.875749Z"}]}
{"channel":"book","type":"update","data":[{"symbol":"USDT/GBP","bids":[],"asks":[{"price":0.7840,"qty":9358.20305813},{"price":0.7841,"qty":232299.06067377}],"checksum":1693925883,"timestamp":"2024-06-01T22:43:20.893133Z"}]}
{"channel":"book","type":"update","data":[{"symbol":"USDT/GBP","bids":[{"price":0.7836,"qty":71789.95904346},{"price":0.7837,"qty":34576.62303553}],"asks":[],"checksum":3786181786,"timestamp":"2024-06-01T22:43:20.893331Z"}]}
{"channel":"book","type":"update","data":[{"symbol":"USDT/GBP","bids":[],"asks":[{"price":0.7841,"qty":232258.95959077},{"price":0.7840,"qty":9398.30414113}],"checksum":3717559747,"timestamp":"2024-06-01T22:43:20.910939Z"}]}
{"channel":"book","type":"update","data":[{"symbol":"USDT/GBP","bids":[{"price":0.7838,"qty":12565.11524167}],"asks":[],"checksum":682078610,"timestamp":"2024-06-01T22:43:22.592578Z"}]}
{"channel":"book","type":"update","data":[{"symbol":"USDT/GBP","bids":[{"price":0.7835,"qty":37785.49460996}],"asks":[],"checksum":4020663608,"timestamp":"2024-06-01T22:43:22.592600Z"}]}
{"channel":"book","type":"update","data":[{"symbol":"USDT/GBP","bids":[{"price":0.7838,"qty":18472.45069012}],"asks":[],"checksum":2466509636,"timestamp":"2024-06-01T22:43:22.632525Z"}]}
{"channel":"book","type":"update","data":[{"symbol":"USDT/GBP","bids":[{"price":0.7835,"qty":160909.34780351}],"asks":[],"checksum":4142561809,"timestamp":"2024-06-01T22:43:22.632627Z"}]}
{"channel":"book","type":"update","data":[{"symbol":"USDT/GBP","bids":[{"price":0.7838,"qty":18623.37768888}],"asks":[],"checksum":2737396481,"timestamp":"2024-06-01T22:43:22.754104Z"}]}
{"channel":"book","type":"update","data":[{"symbol":"USDT/GBP","bids":[{"price":0.7837,"qty":34425.69603677}],"asks":[],"checksum":4258016899,"timestamp":"2024-06-01T22:43:22.920405Z"}]}
{"channel":"book","type":"update","data":[{"symbol":"USDT/GBP","bids":[],"asks":[{"price":0.7841,"qty":8750.12933446}],"checksum":3896032470,"timestamp":"2024-06-01T22:43:24.323517Z"}]}
{"channel":"book","type":"update","data":[{"symbol":"USDT/GBP","bids":[],"asks":[{"price":0.7842,"qty":28992.20295000}],"checksum":2088779008,"timestamp":"2024-06-01T22:43:24.323530Z"}]}
{"channel":"book","type":"update","data":[{"symbol":"USDT/GBP","bids":[],"asks":[{"price":0.7840,"qty":9358.20305813},{"price":0.7841,"qty":8790.23505513}],"checksum":1521500682,"timestamp":"2024-06-01T22:43:24.326679Z"}]}
{"channel":"book","type":"update","data":[{"symbol":"USDT/GBP","bids":[],"asks":[{"price":0.7841,"qty":212259.31491059}],"checksum":832043669,"timestamp":"2024-06-01T22:43:24.328020Z"}]}
{"channel":"book","type":"update","data":[{"symbol":"USDT/GBP","bids":[],"asks":[{"price":0.7842,"qty":71983.66018303}],"checksum":4226611435,"timestamp":"2024-06-01T22:43:24.328180Z"}]}
{"channel":"book","type":"update","data":[{"symbol":"USDT/GBP","bids":[],"asks":[{"price":0.7841,"qty":212219.20918992},{"price":0.7840,"qty":9398.30877880}],"checksum":2361602986,"timestamp":"2024-06-01T22:43:24.331314Z"}]}
{"channel":"book","type":"update","data":[{"symbol":"USDT/GBP","bids":[{"price":0.7831,"qty":12398.70239342}],"asks":[],"checksum":3278674938,"timestamp":"2024-06-01T22:43:24.614096Z"}]}
{"channel":"book","type":"update","data":[{"symbol":"USDT/GBP","bids":[{"price":0.7831,"qty":13442.70239342}],"asks":[],"checksum":2361602986,"timestamp":"2024-06-01T22:43:24.859012Z"}]}
{"channel":"book","type":"update","data":[{"symbol":"USDT/GBP","bids":[],"asks":[{"price":0.7840,"qty":9358.20305813},{"price":0.7844,"qty":25044.96489042}],"checksum":3275540358,"timestamp":"2024-06-01T22:43:27.997487Z"}]}
{"channel":"book","type":"update","data":[{"symbol":"USDT/GBP","bids":[],"asks":[{"price":0.7844,"qty":25004.85901351},{"price":0.7840,"qty":9398.30893504}],"checksum":2746151200,"timestamp":"2024-06-01T22:43:28.009564Z"}]}
{"channel":"book","type":"update","data":[{"symbol":"USDT/GBP","bids":[],"asks":[{"price":0.7840,"qty":9358.20305813},{"price":0.7844,"qty":25044.96489102}],"checksum":437835516,"timestamp":"2024-06-01T22:43:28.099574Z"}]}
{"channel":"book","type":"update","data":[{"symbol":"USDT/GBP","bids":[],"asks":[{"price":0.7844,"qty":25004.85901351},{"price":0.7840,"qty":9398.30893564}],"checksum":1753924497,"timestamp":"2024-06-01T22:43:28.224461Z"}]}
{"channel":"book","type":"update","data":[{"symbol":"USDT/GBP","bids":[],"asks":[{"price":0.7840,"qty":9358.20305813},{"price":0.7844,"qty":25044.96489102}],"checksum":437835516,"timestamp":"2024-06-01T22:43:28.227625Z"}]}
{"channel":"book","type":"update","data":[{"symbol":"USDT/GBP","bids":[],"asks":[{"price":0.7844,"qty":25004.85901351},{"price":0.7840,"qty":9398.31630522}],"checksum":1081212856,"timestamp":"2024-06-01T22:43:28.314007Z"}]}
{"channel":"book","type":"update","data":[{"symbol":"USDT/GBP","bids":[],"asks":[{"price":0.7840,"qty":9358.20305813},{"price":0.7844,"qty":25044.97223091}],"checksum":1354360272,"timestamp":"2024-06-01T22:43:28.717111Z"}]}
{"channel":"book","type":"update","data":[{"symbol":"USDT/GBP","bids":[],"asks":[{"price":0.7844,"qty":25004.85901351},{"price":0.7840,"qty":9398.31627553}],"checksum":980203667,"timestamp":"2024-06-01T22:43:28.720247Z"}]}
{"channel":"book","type":"update","data":[{"symbol":"USDT/GBP","bids":[{"price":0.7836,"qty":13156.42933586}],"asks":[],"checksum":213888035,"timestamp":"2024-06-01T22:43:28.925209Z"}]}
{"channel":"book","type":"update","data":[{"symbol":"USDT/GBP","bids":[{"price":0.7838,"qty":12716.04224043}],"asks":[],"checksum":1171836451,"timestamp":"2024-06-01T22:43:28.925312Z"}]}
{"channel":"book","type":"update","data":[{"symbol":"USDT/GBP","bids":[{"price":0.7835,"qty":37785.49460996}],"asks":[],"checksum":3352162236,"timestamp":"2024-06-01T22:43:28.925395Z"}]}
{"channel":"book","type":"update","data":[{"symbol":"USDT/GBP","bids":[{"price":0.7836,"qty":69837.13703386}],"asks":[],"checksum":4130878064,"timestamp":"2024-06-01T22:43:28.927355Z"}]}
{"channel":"book","type":"update","data":[{"symbol":"USDT/GBP","bids":[{"price":0.7835,"qty":174441.79407314}],"asks":[],"checksum":2904306200,"timestamp":"2024-06-01T22:43:28.927459Z"}]}
{"channel":"book","type":"update","data":[{"symbol":"USDT/GBP","bids":[{"price":0.7838,"qty":14717.73366969}],"asks":[],"checksum":1642898413,"timestamp":"2024-06-01T22:43:28.927507Z"}]}
{"channel":"book","type":"update","data":[{"symbol":"USDT/GBP","bids":[{"price":0.7837,"qty":14158.49603677},{"price":0.7836,"qty":90104.33703386}],"asks":[],"checksum":586925317,"timestamp":"2024-06-01T22:43:28.929963Z"}]}
{"channel":"book","type":"update","data":[{"symbol":"USDT/GBP","bids":[],"asks":[{"price":0.7840,"qty":9358.20305813},{"price":0.7844,"qty":25044.97220454}],"checksum":1451636934,"timestamp":"2024-06-01T22:43:29.373493Z"}]}
{"channel":"book","type":"update","data":[{"symbol":"USDT/GBP","bids":[{"price":0.7836,"qty":69837.13703386},{"price":0.7837,"qty":34425.69603677}],"asks":[],"checksum":361848366,"timestamp":"2024-06-01T22:43:29.377026Z"}]}
{"channel":"book","type":"update","data":[{"symbol":"USDT/GBP","bids":[],"asks":[{"price":0.7844,"qty":25004.85901351},{"price":0.7840,"qty":9398.31624513}],"checksum":454524605,"timestamp":"2024-06-01T22:43:29.569442Z"}]}
{"channel":"book","type":"update","data":[{"symbol":"USDT/GBP","bids":[],"asks":[{"price":0.7840,"qty":9358.20305813},{"price":0.7844,"qty":25044.97220051}],"checksum":2727211616,"timestamp":"2024-06-01T22:43:29.574231Z"}]}
{"channel":"book","type":"update","data":[{"symbol":"USDT/GBP","bids":[],"asks":[{"price":0.7844,"qty":25004.85901351},{"price":0.7840,"qty":9398.31624513}],"checksum":454524605,"timestamp":"2024-06-01T22:43:29.615254Z"}]}
{"channel":"book","type":"update","data":[{"symbol":"USDT/GBP","bids":[],"asks":[{"price":0.7840,"qty":9358.20305813},{"price":0.7844,"qty":25044.97219469}],"checksum":1486135042,"timestamp":"2024-06-01T22:43:30.063810Z"}]}
{"channel":"book","type":"update","data":[{"symbol":"USDT/GBP","bids":[],"asks":[{"price":0.7844,"qty":25004.85901351},{"price":0.7840,"qty":9398.31623931}],"checksum":309081163,"timestamp":"2024-06-01T22:43:30.138138Z"}]}
{"channel":"book","type":"update","data":[{"symbol":"USDT/GBP","bids":[],"asks":[{"price":0.7840,"qty":9358.20305813},{"price":0.7844,"qty":25044.97219469}],"checksum":1486135042,"timestamp":"2024-06-01T22:43:30.184357Z"}]}
{"channel":"book","type":"update","data":[{"symbol":"USDT/GBP","bids":[],"asks":[{"price":0.7844,"qty":25004.85901351},{"price":0.7840,"qty":9398.31439213}],"checksum":2248756558,"timestamp":"2024-06-01T22:43:30.666453Z"}]}
{"channel":"book","type":"update","data":[{"symbol":"USDT/GBP","bids":[],"asks":[{"price":0.7840,"qty":9358.20305813},{"price":0.7844,"qty":25044.97034751}],"checksum":2511523442,"timestamp":"2024-06-01T22:43:30.682862Z"}]}
{"channel":"book","type":"update","data":[{"symbol":"USDT/GBP","bids":[],"asks":[{"price":0.7844,"qty":25004.85901351},{"price":0.7840,"qty":9398.31439213}],"checksum":2248756558,"timestamp":"2024-06-01T22:43:30.715463Z"}]}
{"channel":"book","type":"update","data":[{"symbol":"USDT/GBP","bids":[],"asks":[{"price":0.7840,"qty":9358.20305813},{"price":0.7844,"qty":25044.97034672}],"checksum":3576444039,"timestamp":"2024-06-01T22:43:30.815200Z"}]}
{"channel":"book","type":"update","data":[{"symbol":"USDT/GBP","bids":[],"asks":[{"price":0.7844,"qty":25004.85901351},{"price":0.7840,"qty":9398.31439134}],"checksum":1940768114,"timestamp":"2024-06-01T22:43:30.908226Z"}]}
{"channel":"book","type":"update","data":[{"symbol":"USDT/GBP","bids":[],"asks":[{"price":0.7840,"qty":9358.20305813},{"price":0.7844,"qty":25044.97034672}],"checksum":3576444039,"timestamp":"2024-06-01T22:43:30.921486Z"}]}
{"channel":"book","type":"update","data":[{"symbol":"USDT/GBP","bids":[{"price":0.7836,"qty":13156.42933586}],"asks":[],"checksum":1204768705,"timestamp":"2024-06-01T22:43:31.061985Z"}]}
{"channel":"book","type":"update","data":[{"symbol":"USDT/GBP","bids":[{"price":0.7838,"qty":12716.04224043}],"asks":[],"checksum":2336218676,"timestamp":"2024-06-01T22:43:31.062080Z"}]}
{"channel":"book","type":"update","data":[{"symbol":"USDT/GBP","bids":[{"price":0.7835,"qty":37785.49460996}],"asks":[],"checksum":216314432,"timestamp":"2024-06-01T22:43:31.062128Z"}]}
{"channel":"book","type":"update","data":[{"symbol":"USDT/GBP","bids":[{"price":0.7836,"qty":73742.78105306}],"asks":[],"checksum":2157131191,"timestamp":"2024-06-01T22:43:31.064392Z"}]}
{"channel":"book","type":"update","data":[{"symbol":"USDT/GBP","bids":[{"price":0.7838,"qty":18623.37768888}],"asks":[],"checksum":2394323025,"timestamp":"2024-06-01T22:43:31.064467Z"}]}
{"channel":"book","type":"update","data":[{"symbol":"USDT/GBP","bids":[{"price":0.7835,"qty":136136.73266222}],"asks":[],"checksum":1626280175,"timestamp":"2024-06-01T22:43:31.064552Z"}]}
{"channel":"book","type":"update","data":[{"symbol":"USDT/GBP","bids":[{"price":0.7837,"qty":14158.49603677},{"price":0.7836,"qty":94009.98105306}],"asks":[],"checksum":1098414860,"timestamp":"2024-06-01T22:43:31.064942Z"}]}
{"channel":"book","type":"update","data":[{"symbol":"USDT/GBP","bids":[],"asks":[{"price":0.7844,"qty":25004.85901351},{"price":0.7840,"qty":9398.31439093}],"checksum":266871327,"timestamp":"2024-06-01T22:43:31.109578Z"}]}
{"channel":"book","type":"update","data":[{"symbol":"USDT/GBP","bids":[{"price":0.7836,"qty":73742.78105306},{"price":0.7837,"qty":34425.69603677}],"asks":[],"checksum":780093948,"timestamp":"2024-06-01T22:43:31.112620Z"}]}
{"channel":"book","type":"update","data":[{"symbol":"USDT/GBP","bids":[],"asks":[{"price":0.7840,"qty":9358.20305813},{"price":0.7844,"qty":25044.97034631}],"checksum":2251280835,"timestamp":"2024-06-01T22:43:31.115657Z"}]}
{"channel":"book","type":"update","data":[{"symbol":"USDT/GBP","bids":[],"asks":[{"price":0.7841,"qty":8750.12933446}],"checksum":2971687021,"timestamp":"2024-06-01T22:43:31.382592Z"}]}
{"channel":"book","type":"update","data":[{"symbol":"USDT/GBP","bids":[],"asks":[{"price":0.7842,"qty":28992.20295000}],"checksum":2069584403,"timestamp":"2024-06-01T22:43:31.382636Z"}]}
{"channel":"book","type":"update","data":[{"symbol":"USDT/GBP","bids":[],"asks":[{"price":0.7844,"qty":25004.85901351},{"price":0.7841,"qty":8790.24066689}],"checksum":2994761718,"timestamp":"2024-06-01T22:43:31.385728Z"}]}
{"channel":"book","type":"update","data":[{"symbol":"USDT/GBP","bids":[],"asks":[{"price":0.7841,"qty":122570.99752276}],"checksum":1315118233,"timestamp":"2024-06-01T22:43:31.387977Z"}]}
{"channel":"book","type":"update","data":[{"symbol":"USDT/GBP","bids":[],"asks":[{"price":0.7842,"qty":144784.12240439}],"checksum":2274028038,"timestamp":"2024-06-01T22:43:31.388086Z"}]}
{"channel":"book","type":"update","data":[{"symbol":"USDT/GBP","bids":[],"asks":[{"price":0.7841,"qty":122530.88619033},{"price":0.7844,"qty":25044.97034594}],"checksum":2710394065,"timestamp":"2024-06-01T22:43:31.391515Z"}]}
{"channel":"book","type":"update","data":[{"symbol":"USDT/GBP","bids":[],"asks":[{"price":0.7844,"qty":25004.85901351},{"price":0.7841,"qty":122570.99752276}],"checksum":2274028038,"timestamp":"2024-06-01T22:43:31.626046Z"}]}
{"channel":"book","type":"update","data":[{"symbol":"USDT/GBP","bids":[{"price":0.7838,"qty":18350.57768888},{"price":0.7837,"qty":34698.49603677}],"asks":[],"checksum":3712190587,"timestamp":"2024-06-01T22:43:32.011842Z"}]}
{"channel":"book","type":"update","data":[{"symbol":"USDT/GBP","bids":[],"asks":[{"price":0.7841,"qty":122530.88619033},{"price":0.7840,"qty":9398.31754043}],"checksum":1941228198,"timestamp":"2024-06-01T22:43:32.650891Z"}]}
{"channel":"book","type":"update","data":[{"symbol":"USDT/GBP","bids":[],"asks":[{"price":0.7840,"qty":9358.20305813},{"price":0.7841,"qty":122571.00067263}],"checksum":3069585132,"timestamp":"2024-06-01T22:43:32.704269Z"}]}
{"channel":"book","type":"update","data":[{"symbol":"USDT/GBP","bids":[],"asks":[{"price":0.7841,"qty":122530.88619033},{"price":0.7840,"qty":9398.31754043}],"checksum":1941228198,"timestamp":"2024-06-01T22:43:32.915163Z"}]}
{"channel":"book","type":"update","data":[{"symbol":"USDT/GBP","bids":[{"price":0.7835,"qty":37785.49460996}],"asks":[],"checksum":3119802185,"timestamp":"2024-06-01T22:43:33.195795Z"}]}
{"channel":"book","type":"update","data":[{"symbol":"USDT/GBP","bids":[{"price":0.7835,"qty":141823.56394408}],"asks":[],"checksum":3227282713,"timestamp":"2024-06-01T22:43:33.196843Z"}]}
{"channel":"book","type":"update","data":[{"symbol":"USDT/GBP","bids":[],"asks":[{"price":0.7841,"qty":8750.12933446}],"checksum":3624108929,"timestamp":"2024-06-01T22:43:34.835150Z"}]}
{"channel":"book","type":"update","data":[{"symbol":"USDT/GBP","bids":[],"asks":[{"price":0.7842,"qty":28992.20295000}],"checksum":1774428516,"timestamp":"2024-06-01T22:43:34.835164Z"}]}
{"channel":"book","type":"update","data":[{"symbol":"USDT/GBP","bids":[],"asks":[{"price":0.7840,"qty":9358.20305813},{"price":0.7841,"qty":8790.24238543}],"checksum":1530556571,"timestamp":"2024-06-01T22:43:34.838542Z"}]}
{"channel":"book","type":"update","data":[{"symbol":"USDT/GBP","bids":[],"asks":[{"price":0.7841,"qty":128723.97531983}],"checksum":3027167107,"timestamp":"2024-06-01T22:43:34.839900Z"}]}
{"channel":"book","type":"update","data":[{"symbol":"USDT/GBP","bids":[],"asks":[{"price":0.7842,"qty":154576.90830672}],"checksum":3730020881,"timestamp":"2024-06-01T22:43:34.840026Z"}]}
{"channel":"book","type":"update","data":[{"symbol":"USDT/GBP","bids":[{"price":0.7837,"qty":34425.69603677},{"price":0.7838,"qty":18623.37768888}],"asks":[],"checksum":2224748652,"timestamp":"2024-06-01T22:43:34.868302Z"}]}
{"channel":"book","type":"update","data":[{"symbol":"USDT/GBP","bids":[],"asks":[{"price":0.7841,"qty":128683.86226886},{"price":0.7840,"qty":9398.31610910}],"checksum":3281326585,"timestamp":"2024-06-01T22:43:35.049761Z"}]}
{"channel":"book","type":"update","data":[{"symbol":"USDT/GBP","bids":[{"price":0.7835,"qty":37785.49460996}],"asks":[],"checksum":3328871371,"timestamp":"2024-06-01T22:43:35.252247Z"}]}
{"channel":"book","type":"update","data":[{"symbol":"USDT/GBP","bids":[{"price":0.7835,"qty":172153.33078065}],"asks":[],"checksum":1474497422,"timestamp":"2024-06-01T22:43:35.253491Z"}]}
{"channel":"book","type":"update","data":[{"symbol":"USDT/GBP","bids":[{"price":0.7835,"qty":37785.49460996}],"asks":[],"checksum":3328871371,"timestamp":"2024-06-01T22:43:37.420680Z"}]}
{"channel":"book","type":"update","data":[{"symbol":"USDT/GBP","bids":[{"price":0.7835,"qty":160779.66821694}],"asks":[],"checksum":2953431559,"timestamp":"2024-06-01T22:43:37.421005Z"}]}
{"channel":"book","type":"update","data":[{"symbol":"USDT/GBP","bids":[],"asks":[{"price":0.7841,"qty":8750.12933446}],"checksum":603013184,"timestamp":"2024-06-01T22:43:38.321760Z"}]}
{"channel":"book","type":"update","data":[{"symbol":"USDT/GBP","bids":[],"asks":[{"price":0.7842,"qty":28992.20295000}],"checksum":3513282147,"timestamp":"2024-06-01T22:43:38.321899Z"}]}
{"channel":"book","type":"update","data":[{"symbol":"USDT/GBP","bids":[],"asks":[{"price":0.7840,"qty":9358.20305813},{"price":0.7841,"qty":8790.24135191}],"checksum":3359160412,"timestamp":"2024-06-01T22:43:38.326580Z"}]}
{"channel":"book","type":"update","data":[{"symbol":"USDT/GBP","bids":[],"asks":[{"price":0.7842,"qty":136528.07833027}],"checksum":1066380800,"timestamp":"2024-06-01T22:43:38.326646Z"}]}
{"channel":"book","type":"update","data":[{"symbol":"USDT/GBP","bids":[],"asks":[{"price":0.7841,"qty":132825.95833867}],"checksum":1161228453,"timestamp":"2024-06-01T22:43:38.326699Z"}]}
{"channel":"book","type":"update","data":[{"symbol":"USDT/GBP","bids":[],"asks":[{"price":0.7841,"qty":132785.84632122},{"price":0.7840,"qty":9398.31507558}],"checksum":162754143,"timestamp":"2024-06-01T22:43:38.330324Z"}]}
{"channel":"book","type":"update","data":[{"symbol":"USDT/GBP","bids":[],"asks":[{"price":0.7841,"qty":132916.39004542}],"checksum":2320378658,"timestamp":"2024-06-01T22:43:38.490840Z"}]}
{"channel":"book","type":"update","data":[{"symbol":"USDT/GBP","bids":[],"asks":[{"price":0.7840,"qty":9267.77135138}],"checksum":667238250,"timestamp":"2024-06-01T22:43:38.654557Z"}]}
{"channel":"book","type":"update","data":[{"symbol":"USDT/GBP","bids":[],"asks":[{"price":0.7840,"qty":9227.65933393},{"price":0.7841,"qty":132956.50208146}],"checksum":3507340562,"timestamp":"2024-06-01T22:43:39.315842Z"}]}
{"channel":"book","type":"update","data":[{"symbol":"USDT/GBP","bids":[],"asks":[{"price":0.7841,"qty":132916.39004542},{"price":0.7840,"qty":9267.77137103}],"checksum":2335320192,"timestamp":"2024-06-01T22:43:39.402935Z"}]}
{"channel":"book","type":"update","data":[{"symbol":"USDT/GBP","bids":[{"price":0.7835,"qty":37785.49460996}],"asks":[],"checksum":2477311211,"timestamp":"2024-06-01T22:43:39.486099Z"}]}
{"channel":"book","type":"update","data":[{"symbol":"USDT/GBP","bids":[{"price":0.7835,"qty":147510.39522594}],"asks":[],"checksum":2094205212,"timestamp":"2024-06-01T22:43:39.527672Z"}]}
{"channel":"book","type":"update","data":[{"symbol":"USDT/GBP","bids":[{"price":0.7835,"qty":37785.49460996}],"asks":[],"checksum":2477311211,"timestamp":"2024-06-01T22:43:41.572119Z"}]}
{"channel":"book","type":"update","data":[{"symbol":"USDT/GBP","bids":[{"price":0.7836,"qty":13156.42933586}],"asks":[],"checksum":534725404,"timestamp":"2024-06-01T22:43:41.572926Z"}]}
{"channel":"book","type":"update","data":[{"symbol":"USDT/GBP","bids":[{"price":0.7835,"qty":159011.83032348}],"asks":[],"checksum":486066035,"timestamp":"2024-06-01T22:43:41.573374Z"}]}
{"channel":"book","type":"update","data":[{"symbol":"USDT/GBP","bids":[{"price":0.7836,"qty":71789.95904346}],"asks":[],"checksum":707515331,"timestamp":"2024-06-01T22:43:41.573393Z"}]}
{"channel":"book","type":"update","data":[{"symbol":"USDT/GBP","bids":[{"price":0.7837,"qty":14158.49603677},{"price":0.7836,"qty":92057.15904346}],"asks":[],"checksum":3526823634,"timestamp":"2024-06-01T22:43:41.576106Z"}]}
{"channel":"book","type":"update","data":[{"symbol":"USDT/GBP","bids":[],"asks":[{"price":0.7842,"qty":28992.20295000}],"checksum":654649842,"timestamp":"2024-06-01T22:43:41.688844Z"}]}
{"channel":"book","type":"update","data":[{"symbol":"USDT/GBP","bids":[],"asks":[{"price":0.7841,"qty":8880.67305866}],"checksum":3095447404,"timestamp":"2024-06-01T22:43:41.689072Z"}]}
{"channel":"book","type":"update","data":[{"symbol":"USDT/GBP","bids":[{"price":0.7836,"qty":71789.95904346},{"price":0.7837,"qty":34425.69603677}],"asks":[],"checksum":1083972221,"timestamp":"2024-06-01T22:43:41.691887Z"}]}
{"channel":"book","type":"update","data":[{"symbol":"USDT/GBP","bids":[],"asks":[{"price":0.7840,"qty":9227.65933393},{"price":0.7841,"qty":8920.78521627}],"checksum":796717401,"timestamp":"2024-06-01T22:43:41.692651Z"}]}
{"channel":"book","type":"update","data":[{"symbol":"USDT/GBP","bids":[],"asks":[{"price":0.7841,"qty":137058.48625538}],"checksum":2572898127,"timestamp":"2024-06-01T22:43:41.693644Z"}]}
{"channel":"book","type":"update","data":[{"symbol":"USDT/GBP","bids":[],"asks":[{"price":0.7842,"qty":130451.71401444}],"checksum":3504689464,"timestamp":"2024-06-01T22:43:41.693897Z"}]}
{"channel":"book","type":"update","data":[{"symbol":"USDT/GBP","bids":[],"asks":[{"price":0.7841,"qty":137018.37409777},{"price":0.7840,"qty":9267.77149154}],"checksum":2431892438,"timestamp":"2024-06-01T22:43:41.697077Z"}]}
{"channel":"book","type":"update","data":[{"symbol":"USDT/GBP","bids":[],"asks":[{"price":0.7842,"qty":28992.20295000}],"checksum":1354418085,"timestamp":"2024-06-01T22:43:45.074941Z"}]}
{"channel":"book","type":"update","data":[{"symbol":"USDT/GBP","bids":[],"asks":[{"price":0.7841,"qty":8880.67305866}],"checksum":1649806301,"timestamp":"2024-06-01T22:43:45.075010Z"}]}
{"channel":"book","type":"update","data":[{"symbol":"USDT/GBP","bids":[],"asks":[{"price":0.7840,"qty":9227.65933393},{"price":0.7841,"qty":8920.78654444}],"checksum":960202893,"timestamp":"2024-06-01T22:43:45.078658Z"}]}
{"channel":"book","type":"update","data":[{"symbol":"USDT/GBP","bids":[],"asks":[{"price":0.7841,"qty":142185.96764899}],"checksum":4257079117,"timestamp":"2024-06-01T22:43:45.080098Z"}]}
{"channel":"book","type":"update","data":[{"symbol":"USDT/GBP","bids":[],"asks":[{"price":0.7842,"qty":142245.41889543}],"checksum":3982620763,"timestamp":"2024-06-01T22:43:45.080111Z"}]}
{"channel":"book","type":"update","data":[{"symbol":"USDT/GBP","bids":[],"asks":[{"price":0.7841,"qty":142145.85416321},{"price":0.7840,"qty":9267.77281971}],"checksum":255897388,"timestamp":"2024-06-01T22:43:45.083683Z"}]}
{"channel":"book","type":"update","data":[{"symbol":"USDT/GBP","bids":[{"price":0.7838,"qty":12716.04224043}],"asks":[],"checksum":1177013548,"timestamp":"2024-06-01T22:43:47.944945Z"}]}
{"channel":"book","type":"update","data":[{"symbol":"USDT/GBP","bids":[{"price":0.7835,"qty":37785.49460996}],"asks":[],"checksum":3305768930,"timestamp":"2024-06-01T22:43:47.944966Z"}]}
{"channel":"book","type":"update","data":[{"symbol":"USDT/GBP","bids":[{"price":0.7836,"qty":13156.42933586}],"asks":[],"checksum":357843272,"timestamp":"2024-06-01T22:43:47.945031Z"}]}
{"channel":"book","type":"update","data":[{"symbol":"USDT/GBP","bids":[{"price":0.7838,"qty":20576.19969848}],"asks":[],"checksum":780051918,"timestamp":"2024-06-01T22:43:47.946344Z"}]}
{"channel":"book","type":"update","data":[{"symbol":"USDT/GBP","bids":[{"price":0.7836,"qty":73742.78105306}],"asks":[],"checksum":2718507577,"timestamp":"2024-06-01T22:43:47.946402Z"}]}
{"channel":"book","type":"update","data":[{"symbol":"USDT/GBP","bids":[{"price":0.7835,"qty":160722.45663462}],"asks":[],"checksum":3643473566,"timestamp":"2024-06-01T22:43:47.946539Z"}]}
{"channel":"book","type":"update","data":[{"symbol":"USDT/GBP","bids":[{"price":0.7837,"qty":14158.49603677},{"price":0.7836,"qty":94009.98105306}],"asks":[],"checksum":4173174141,"timestamp":"2024-06-01T22:43:47.948242Z"}]}
{"channel":"book","type":"update","data":[{"symbol":"USDT/GBP","bids":[{"price":0.7837,"qty":14309.42303553}],"asks":[],"checksum":3676303503,"timestamp":"2024-06-01T22:43:48.181182Z"}]}
{"channel":"book","type":"update","data":[{"symbol":"USDT/GBP","bids":[{"price":0.7836,"qty":73742.78105306},{"price":0.7837,"qty":34576.62303553}],"asks":[],"checksum":2278525724,"timestamp":"2024-06-01T22:43:48.184468Z"}]}
