{"channel":"book","type":"snapshot","data":[{"symbol":"USDT/EUR","bids":[{"price":0.9213,"qty":187838.25625366},{"price":0.9212,"qty":260443.39069699},{"price":0.9211,"qty":201481.59429913},{"price":0.9210,"qty":587558.90622686},{"price":0.9209,"qty":104179.84643667},{"price":0.9208,"qty":303131.30638085},{"price":0.9207,"qty":196182.85389433},{"price":0.9206,"qty":84962.30851302},{"price":0.9205,"qty":64385.46479999},{"price":0.9204,"qty":73736.52261194}],"asks":[{"price":0.9214,"qty":310758.36035943},{"price":0.9215,"qty":378211.64272452},{"price":0.9216,"qty":118027.55149382},{"price":0.9217,"qty":160740.46854464},{"price":0.9218,"qty":60393.25104117},{"price":0.9219,"qty":94291.57012969},{"price":0.9220,"qty":75874.00466837},{"price":0.9221,"qty":37634.02504700},{"price":0.9222,"qty":25580.98000000},{"price":0.9223,"qty":99352.80285822}],"checksum":453329764}]}
{"channel":"book","type":"update","data":[{"symbol":"USDT/EUR","bids":[],"asks":[{"price":0.9215,"qty":377211.64272452}],"checksum":1307101019,"timestamp":"2024-06-01T22:43:15.484804Z"}]}
{"channel":"book","type":"update","data":[{"symbol":"USDT/EUR","bids":[],"asks":[{"price":0.9215,"qty":378211.64272452}],"checksum":453329764,"timestamp":"2024-06-01T22:43:15.493091Z"}]}
{"channel":"book","type":"update","data":[{"symbol":"USDT/EUR","bids":[{"price":0.9210,"qty":63720.85964676}],"asks":[],"checksum":790558670,"timestamp":"2024-06-01T22:43:17.219119Z"}]}
{"channel":"book","type":"update","data":[{"symbol":"USDT/EUR","bids":[{"price":0.9213,"qty":355.87336589}],"asks":[],"checksum":1672014472,"timestamp":"2024-06-01T22:43:17.219202Z"}]}
{"channel":"book","type":"update","data":[{"symbol":"USDT/EUR","bids":[{"price":0.9210,"qty":650999.23315023}],"asks":[],"checksum":2510188287,"timestamp":"2024-06-01T22:43:17.224732Z"}]}
{"channel":"book","type":"update","data":[{"symbol":"USDT/EUR","bids":[{"price":0.9213,"qty":189555.67006346}],"asks":[],"checksum":4266951007,"timestamp":"2024-06-01T22:43:17.224856Z"}]}
{"channel":"book","type":"update","data":[{"symbol":"USDT/EUR","bids":[],"asks":[{"price":0.9215,"qty":168034.26063835}],"checksum":3934714193,"timestamp":"2024-06-01T22:43:17.428421Z"}]}
{"channel":"book","type":"update","data":[{"symbol":"USDT/EUR","bids":[],"asks":[{"price":0.9216,"qty":114128.86401437}],"checksum":2579851687,"timestamp":"2024-06-01T22:43:17.428563Z"}]}
{"channel":"book","type":"update","data":[{"symbol":"USDT/EUR","bids":[],"asks":[{"price":0.9215,"qty":306506.69186924}],"checksum":811948204,"timestamp":"2024-06-01T22:43:17.430482Z"}]}
{"channel":"book","type":"update","data":[{"symbol":"USDT/EUR","bids":[],"asks":[{"price":0.9216,"qty":193664.31418967}],"checksum":1274914633,"timestamp":"2024-06-01T22:43:17.430629Z"}]}
{"channel":"book","type":"update","data":[{"symbol":"USDT/EUR","bids":[{"price":0.9211,"qty":199694.05936485}],"asks":[],"checksum":1348510985,"timestamp":"2024-06-01T22:43:17.574413Z"}]}
{"channel":"book","type":"update","data":[{"symbol":"USDT/EUR","bids":[{"price":0.9211,"qty":202329.77641768}],"asks":[],"checksum":677743803,"timestamp":"2024-06-01T22:43:17.580733Z"}]}
{"channel":"book","type":"update","data":[{"symbol":"USDT/EUR","bids":[{"price":0.9212,"qty":260476.46208976}],"asks":[],"checksum":2373645938,"timestamp":"2024-06-01T22:43:17.580747Z"}]}
{"channel":"book","type":"update","data":[{"symbol":"USDT/EUR","bids":[{"price":0.9210,"qty":645460.93944789},{"price":0.9209,"qty":109718.74153912}],"asks":[],"checksum":492213091,"timestamp":"2024-06-01T22:43:17.666090Z"}]}
{"channel":"book","type":"update","data":[{"symbol":"USDT/EUR","bids":[{"price":0.9213,"qty":355.87336589}],"asks":[],"checksum":3917785597,"timestamp":"2024-06-01T22:43:19.330085Z"}]}
{"channel":"book","type":"update","data":[{"symbol":"USDT/EUR","bids":[{"price":0.9210,"qty":58182.56594442}],"asks":[],"checksum":1479929260,"timestamp":"2024-06-01T22:43:19.330159Z"}]}
{"channel":"book","type":"update","data":[{"symbol":"USDT/EUR","bids":[{"price":0.9213,"qty":191273.08387326}],"asks":[],"checksum":3574795968,"timestamp":"2024-06-01T22:43:19.335273Z"}]}
{"channel":"book","type":"update","data":[{"symbol":"USDT/EUR","bids":[{"price":0.9210,"qty":659730.23309417}],"asks":[],"checksum":2289597989,"timestamp":"2024-06-01T22:43:19.335343Z"}]}
{"channel":"book","type":"update","data":[{"symbol":"USDT/EUR","bids":[{"price":0.9209,"qty":95492.48668522}],"asks":[],"checksum":3361176005,"timestamp":"2024-06-01T22:43:19.380976Z"}]}
{"channel":"book","type":"update","data":[{"symbol":"USDT/EUR","bids":[{"price":0.9209,"qty":109718.74153912}],"asks":[],"checksum":2289597989,"timestamp":"2024-06-01T22:43:19.409508Z"}]}
{"channel":"book","type":"update","data":[{"symbol":"USDT/EUR","bids":[],"asks":[{"price":0.9218,"qty":49047.71000000}],"checksum":950223954,"timestamp":"2024-06-01T22:43:19.510109Z"}]}
{"channel":"book","type":"update","data":[{"symbol":"USDT/EUR","bids":[],"asks":[{"price":0.9218,"qty":60393.25104117}],"checksum":2289597989,"timestamp":"2024-06-01T22:43:19.539610Z"}]}
{"channel":"book","type":"update","data":[{"symbol":"USDT/EUR","bids":[{"price":0.9211,"qty":199694.05936485}],"asks":[],"checksum":4034746263,"timestamp":"2024-06-01T22:43:20.038173Z"}]}
{"channel":"book","type":"update","data":[{"symbol":"USDT/EUR","bids":[{"price":0.9212,"qty":260443.39069699}],"asks":[],"checksum":1432497502,"timestamp":"2024-06-01T22:43:20.038361Z"}]}
{"channel":"book","type":"update","data":[{"symbol":"USDT/EUR","bids":[{"price":0.9212,"qty":260463.40761128}],"asks":[],"checksum":2798927295,"timestamp":"2024-06-01T22:43:20.043093Z"}]}
{"channel":"book","type":"update","data":[{"symbol":"USDT/EUR","bids":[{"price":0.9211,"qty":202226.62818978}],"asks":[],"checksum":1973787859,"timestamp":"2024-06-01T22:43:20.043140Z"}]}
{"channel":"book","type":"update","data":[{"symbol":"USDT/EUR","bids":[],"asks":[{"price":0.9216,"qty":114128.86401437}],"checksum":238904118,"timestamp":"2024-06-01T22:43:20.870802Z"}]}
{"channel":"book","type":"update","data":[{"symbol":"USDT/EUR","bids":[],"asks":[{"price":0.9215,"qty":168034.26063835}],"checksum":2812105277,"timestamp":"2024-06-01T22:43:20.870847Z"}]}
{"channel":"book","type":"update","data":[{"symbol":"USDT/EUR","bids":[],"asks":[{"price":0.9215,"qty":343248.63802829}],"checksum":3398234008,"timestamp":"2024-06-01T22:43:20.875579Z"}]}
{"channel":"book","type":"update","data":[{"symbol":"USDT/EUR","bids":[],"asks":[{"price":0.9214,"qty":314701.36035943}],"checksum":311928884,"timestamp":"2024-06-01T22:43:20.986923Z"}]}
{"channel":"book","type":"update","data":[{"symbol":"USDT/EUR","bids":[],"asks":[{"price":0.9214,"qty":310758.36035943}],"checksum":3398234008,"timestamp":"2024-06-01T22:43:21.043808Z"}]}
{"channel":"book","type":"update","data":[{"symbol":"USDT/EUR","bids":[{"price":0.9209,"qty":104179.84643667},{"price":0.9210,"qty":665268.52679649}],"asks":[],"checksum":1038539360,"timestamp":"2024-06-01T22:43:21.286988Z"}]}
{"channel":"book","type":"update","data":[{"symbol":"USDT/EUR","bids":[{"price":0.9213,"qty":355.87336589}],"asks":[],"checksum":2502387604,"timestamp":"2024-06-01T22:43:21.353507Z"}]}
{"channel":"book","type":"update","data":[{"symbol":"USDT/EUR","bids":[{"price":0.9210,"qty":63720.85964674}],"asks":[],"checksum":3135097855,"timestamp":"2024-06-01T22:43:21.353768Z"}]}
{"channel":"book","type":"update","data":[{"symbol":"USDT/EUR","bids":[{"price":0.9212,"qty":399176.77099830}],"asks":[],"checksum":1166203808,"timestamp":"2024-06-01T22:43:21.358547Z"}]}
{"channel":"book","type":"update","data":[{"symbol":"USDT/EUR","bids":[{"price":0.9213,"qty":124421.55761458}],"asks":[],"checksum":195684540,"timestamp":"2024-06-01T22:43:21.358575Z"}]}
{"channel":"book","type":"update","data":[{"symbol":"USDT/EUR","bids":[{"price":0.9210,"qty":592055.42951979}],"asks":[],"checksum":3859559580,"timestamp":"2024-06-01T22:43:21.358588Z"}]}
{"channel":"book","type":"update","data":[{"symbol":"USDT/EUR","bids":[{"price":0.9212,"qty":399156.75408401}],"asks":[],"checksum":258162522,"timestamp":"2024-06-01T22:43:22.604411Z"}]}
{"channel":"book","type":"update","data":[{"symbol":"USDT/EUR","bids":[{"price":0.9211,"qty":199694.05936485}],"asks":[],"checksum":3692207670,"timestamp":"2024-06-01T22:43:22.604427Z"}]}
{"channel":"book","type":"update","data":[{"symbol":"USDT/EUR","bids":[{"price":0.9211,"qty":201332.83161054}],"asks":[],"checksum":3521151685,"timestamp":"2024-06-01T22:43:22.609652Z"}]}
{"channel":"book","type":"update","data":[{"symbol":"USDT/EUR","bids":[{"price":0.9213,"qty":355.87336589}],"asks":[],"checksum":3316643257,"timestamp":"2024-06-01T22:43:23.524539Z"}]}
{"channel":"book","type":"update","data":[{"symbol":"USDT/EUR","bids":[{"price":0.9210,"qty":63720.85964674}],"asks":[],"checksum":1896837707,"timestamp":"2024-06-01T22:43:23.524679Z"}]}
{"channel":"book","type":"update","data":[{"symbol":"USDT/EUR","bids":[{"price":0.9212,"qty":260443.39069699}],"asks":[],"checksum":2376022016,"timestamp":"2024-06-01T22:43:23.524695Z"}]}
{"channel":"book","type":"update","data":[{"symbol":"USDT/EUR","bids":[{"price":0.9212,"qty":415294.91119854}],"asks":[],"checksum":826231983,"timestamp":"2024-06-01T22:43:23.526826Z"}]}
{"channel":"book","type":"update","data":[{"symbol":"USDT/EUR","bids":[{"price":0.9213,"qty":150055.15243804}],"asks":[],"checksum":2429132464,"timestamp":"2024-06-01T22:43:23.526938Z"}]}
{"channel":"book","type":"update","data":[{"symbol":"USDT/EUR","bids":[{"price":0.9210,"qty":538278.02017034}],"asks":[],"checksum":2013607474,"timestamp":"2024-06-01T22:43:23.526986Z"}]}
{"channel":"book","type":"update","data":[{"symbol":"USDT/EUR","bids":[],"asks":[{"price":0.9215,"qty":168034.26063835}],"checksum":353667991,"timestamp":"2024-06-01T22:43:24.323367Z"}]}
{"channel":"book","type":"update","data":[{"symbol":"USDT/EUR","bids":[],"asks":[{"price":0.9216,"qty":166554.69551266}],"checksum":395704215,"timestamp":"2024-06-01T22:43:24.327910Z"}]}
{"channel":"book","type":"update","data":[{"symbol":"USDT/EUR","bids":[],"asks":[{"price":0.9215,"qty":294420.16579161}],"checksum":2827982756,"timestamp":"2024-06-01T22:43:24.327971Z"}]}
{"channel":"book","type":"update","data":[{"symbol":"USDT/EUR","bids":[],"asks":[{"price":0.9214,"qty":292758.36035943}],"checksum":3880493399,"timestamp":"2024-06-01T22:43:24.606775Z"}]}
{"channel":"book","type":"update","data":[{"symbol":"USDT/EUR","bids":[{"price":0.9211,"qty":199694.05936485}],"asks":[],"checksum":3938041252,"timestamp":"2024-06-01T22:43:25.151626Z"}]}
{"channel":"book","type":"update","data":[{"symbol":"USDT/EUR","bids":[{"price":0.9211,"qty":201659.19357251}],"asks":[],"checksum":962887880,"timestamp":"2024-06-01T22:43:25.156530Z"}]}
{"channel":"book","type":"update","data":[{"symbol":"USDT/EUR","bids":[],"asks":[{"price":0.9214,"qty":310758.36035943}],"checksum":1990243899,"timestamp":"2024-06-01T22:43:25.253299Z"}]}
{"channel":"book","type":"update","data":[{"symbol":"USDT/EUR","bids":[{"price":0.9213,"qty":355.87336589}],"asks":[],"checksum":3494033366,"timestamp":"2024-06-01T22:43:25.628061Z"}]}
{"channel":"book","type":"update","data":[{"symbol":"USDT/EUR","bids":[{"price":0.9212,"qty":260443.39069699}],"asks":[],"checksum":2526521819,"timestamp":"2024-06-01T22:43:25.628157Z"}]}
{"channel":"book","type":"update","data":[{"symbol":"USDT/EUR","bids":[{"price":0.9210,"qty":63720.85964674}],"asks":[],"checksum":204954546,"timestamp":"2024-06-01T22:43:25.628190Z"}]}
{"channel":"book","type":"update","data":[{"symbol":"USDT/EUR","bids":[{"price":0.9213,"qty":144902.91100863}],"asks":[],"checksum":1729610045,"timestamp":"2024-06-01T22:43:25.633032Z"}]}
{"channel":"book","type":"update","data":[{"symbol":"USDT/EUR","bids":[{"price":0.9210,"qty":520738.26077298}],"asks":[],"checksum":2787842947,"timestamp":"2024-06-01T22:43:25.633052Z"}]}
{"channel":"book","type":"update","data":[{"symbol":"USDT/EUR","bids":[{"price":0.9212,"qty":413577.49738874}],"asks":[],"checksum":3552790315,"timestamp":"2024-06-01T22:43:25.633115Z"}]}
{"channel":"book","type":"update","data":[{"symbol":"USDT/EUR","bids":[{"price":0.9213,"qty":355.87336589}],"asks":[],"checksum":2930768128,"timestamp":"2024-06-01T22:43:27.691737Z"}]}
{"channel":"book","type":"update","data":[{"symbol":"USDT/EUR","bids":[{"price":0.9210,"qty":63720.85964674}],"asks":[],"checksum":2395500400,"timestamp":"2024-06-01T22:43:27.691924Z"}]}
{"channel":"book","type":"update","data":[{"symbol":"USDT/EUR","bids":[{"price":0.9212,"qty":260443.39069699}],"asks":[],"checksum":204954546,"timestamp":"2024-06-01T22:43:27.691957Z"}]}
{"channel":"book","type":"update","data":[{"symbol":"USDT/EUR","bids":[{"price":0.9213,"qty":132901.59079386}],"asks":[],"checksum":762839209,"timestamp":"2024-06-01T22:43:27.693895Z"}]}
{"channel":"book","type":"update","data":[{"symbol":"USDT/EUR","bids":[{"price":0.9212,"qty":408051.88035558}],"asks":[],"checksum":2001584402,"timestamp":"2024-06-01T22:43:27.694002Z"}]}
{"channel":"book","type":"update","data":[{"symbol":"USDT/EUR","bids":[{"price":0.9210,"qty":597833.56665489}],"asks":[],"checksum":2112711986,"timestamp":"2024-06-01T22:43:27.694071Z"}]}
{"channel":"book","type":"update","data":[{"symbol":"USDT/EUR","bids":[{"price":0.9207,"qty":207432.82491826}],"asks":[],"checksum":1442295989,"timestamp":"2024-06-01T22:43:27.697862Z"}]}
{"channel":"book","type":"update","data":[{"symbol":"USDT/EUR","bids":[{"price":0.9211,"qty":199694.05936485}],"asks":[],"checksum":2250935769,"timestamp":"2024-06-01T22:43:27.720320Z"}]}
{"channel":"book","type":"update","data":[{"symbol":"USDT/EUR","bids":[{"price":0.9211,"qty":201815.84731426}],"asks":[],"checksum":1461510745,"timestamp":"2024-06-01T22:43:27.724879Z"}]}
{"channel":"book","type":"update","data":[{"symbol":"USDT/EUR","bids":[],"asks":[{"price":0.9215,"qty":168034.26063835}],"checksum":3892740714,"timestamp":"2024-06-01T22:43:27.816512Z"}]}
{"channel":"book","type":"update","data":[{"symbol":"USDT/EUR","bids":[],"asks":[{"price":0.9216,"qty":114128.86401437}],"checksum":3934781034,"timestamp":"2024-06-01T22:43:27.816570Z"}]}
{"channel":"book","type":"update","data":[{"symbol":"USDT/EUR","bids":[],"asks":[{"price":0.9215,"qty":318481.20051754}],"checksum":1889257810,"timestamp":"2024-06-01T22:43:27.821112Z"}]}
{"channel":"book","type":"update","data":[{"symbol":"USDT/EUR","bids":[],"asks":[{"price":0.9216,"qty":143671.88691413}],"checksum":2218506060,"timestamp":"2024-06-01T22:43:27.821238Z"}]}
{"channel":"book","type":"update","data":[{"symbol":"USDT/EUR","bids":[{"price":0.9213,"qty":355.87336589}],"asks":[],"checksum":3151898924,"timestamp":"2024-06-01T22:43:29.786323Z"}]}
{"channel":"book","type":"update","data":[{"symbol":"USDT/EUR","bids":[{"price":0.9212,"qty":260443.39069699}],"asks":[],"checksum":3879171817,"timestamp":"2024-06-01T22:43:29.786686Z"}]}
{"channel":"book","type":"update","data":[{"symbol":"USDT/EUR","bids":[{"price":0.9210,"qty":63720.85964674}],"asks":[],"checksum":580544556,"timestamp":"2024-06-01T22:43:29.786726Z"}]}
{"channel":"book","type":"update","data":[{"symbol":"USDT/EUR","bids":[{"price":0.9213,"qty":185315.84510919}],"asks":[],"checksum":170371841,"timestamp":"2024-06-01T22:43:29.792168Z"}]}
{"channel":"book","type":"update","data":[{"symbol":"USDT/EUR","bids":[{"price":0.9210,"qty":679748.39730623}],"asks":[],"checksum":1637775770,"timestamp":"2024-06-01T22:43:29.792325Z"}]}
{"channel":"book","type":"update","data":[{"symbol":"USDT/EUR","bids":[{"price":0.9211,"qty":199694.05936485}],"asks":[],"checksum":2963805722,"timestamp":"2024-06-01T22:43:30.287583Z"}]}
{"channel":"book","type":"update","data":[{"symbol":"USDT/EUR","bids":[{"price":0.9211,"qty":201749.59913479}],"asks":[],"checksum":4097706547,"timestamp":"2024-06-01T22:43:30.293208Z"}]}
{"channel":"book","type":"update","data":[{"symbol":"USDT/EUR","bids":[],"asks":[{"price":0.9214,"qty":310731.50070623}],"checksum":3817982872,"timestamp":"2024-06-01T22:43:30.639931Z"}]}
{"channel":"book","type":"update","data":[{"symbol":"USDT/EUR","bids":[],"asks":[{"price":0.9214,"qty":310614.61082945}],"checksum":3867877404,"timestamp":"2024-06-01T22:43:30.689091Z"}]}
{"channel":"book","type":"update","data":[{"symbol":"USDT/EUR","bids":[],"asks":[{"price":0.9214,"qty":310547.84444199}],"checksum":2495016185,"timestamp":"2024-06-01T22:43:30.813116Z"}]}
{"channel":"book","type":"update","data":[{"symbol":"USDT/EUR","bids":[],"asks":[{"price":0.9214,"qty":310529.19392827}],"checksum":2285761415,"timestamp":"2024-06-01T22:43:30.858591Z"}]}
{"channel":"book","type":"update","data":[{"symbol":"USDT/EUR","bids":[],"asks":[{"price":0.9216,"qty":114128.86401437}],"checksum":2090700185,"timestamp":"2024-06-01T22:43:31.382561Z"}]}
{"channel":"book","type":"update","data":[{"symbol":"USDT/EUR","bids":[],"asks":[{"price":0.9215,"qty":168034.26063835}],"checksum":3867261601,"timestamp":"2024-06-01T22:43:31.382923Z"}]}
{"channel":"book","type":"update","data":[{"symbol":"USDT/EUR","bids":[],"asks":[{"price":0.9215,"qty":328859.64709465}],"checksum":456310385,"timestamp":"2024-06-01T22:43:31.387844Z"}]}
{"channel":"book","type":"update","data":[{"symbol":"USDT/EUR","bids":[{"price":0.9213,"qty":355.87336589}],"asks":[],"checksum":2217838403,"timestamp":"2024-06-01T22:43:32.006710Z"}]}
{"channel":"book","type":"update","data":[{"symbol":"USDT/EUR","bids":[{"price":0.9210,"qty":63720.85964674}],"asks":[],"checksum":1885831116,"timestamp":"2024-06-01T22:43:32.006789Z"}]}
{"channel":"book","type":"update","data":[{"symbol":"USDT/EUR","bids":[{"price":0.9213,"qty":192990.49768306}],"asks":[],"checksum":3195875470,"timestamp":"2024-06-01T22:43:32.011794Z"}]}
{"channel":"book","type":"update","data":[{"symbol":"USDT/EUR","bids":[{"price":0.9210,"qty":625439.28543403}],"asks":[],"checksum":2771522874,"timestamp":"2024-06-01T22:43:32.011939Z"}]}
{"channel":"book","type":"update","data":[{"symbol":"USDT/EUR","bids":[{"price":0.9213,"qty":355.87336589}],"asks":[],"checksum":1026437065,"timestamp":"2024-06-01T22:43:32.397889Z"}]}
{"channel":"book","type":"update","data":[{"symbol":"USDT/EUR","bids":[],"asks":[{"price":0.9214,"qty":304849.19392827}],"checksum":2211262650,"timestamp":"2024-06-01T22:43:34.041136Z"}]}
{"channel":"book","type":"update","data":[{"symbol":"USDT/EUR","bids":[{"price":0.9210,"qty":63720.85964674}],"asks":[],"checksum":2556959934,"timestamp":"2024-06-01T22:43:34.173673Z"}]}
{"channel":"book","type":"update","data":[{"symbol":"USDT/EUR","bids":[{"price":0.9210,"qty":708614.77803940}],"asks":[],"checksum":516115206,"timestamp":"2024-06-01T22:43:34.178843Z"}]}
{"channel":"book","type":"update","data":[{"symbol":"USDT/EUR","bids":[{"price":0.9212,"qty":329424.22070849}],"asks":[],"checksum":2342102878,"timestamp":"2024-06-01T22:43:34.178860Z"}]}
{"channel":"book","type":"update","data":[{"symbol":"USDT/EUR","bids":[{"price":0.9213,"qty":4074.97860495}],"asks":[],"checksum":1947104637,"timestamp":"2024-06-01T22:43:34.178876Z"}]}
{"channel":"book","type":"update","data":[{"symbol":"USDT/EUR","bids":[],"asks":[{"price":0.9214,"qty":310529.19392827}],"checksum":3183261412,"timestamp":"2024-06-01T22:43:34.240193Z"}]}
{"channel":"book","type":"update","data":[{"symbol":"USDT/EUR","bids":[{"price":0.9209,"qty":89953.59158277}],"asks":[],"checksum":1626551890,"timestamp":"2024-06-01T22:43:34.410035Z"}]}
{"channel":"book","type":"update","data":[{"symbol":"USDT/EUR","bids":[{"price":0.9209,"qty":104179.84643667}],"asks":[],"checksum":3183261412,"timestamp":"2024-06-01T22:43:34.439493Z"}]}
{"channel":"book","type":"update","data":[{"symbol":"USDT/EUR","bids":[],"asks":[{"price":0.9218,"qty":49047.71000000}],"checksum":3291933995,"timestamp":"2024-06-01T22:43:34.540093Z"}]}
{"channel":"book","type":"update","data":[{"symbol":"USDT/EUR","bids":[],"asks":[{"price":0.9218,"qty":60393.25104117}],"checksum":3183261412,"timestamp":"2024-06-01T22:43:34.568723Z"}]}
{"channel":"book","type":"update","data":[{"symbol":"USDT/EUR","bids":[{"price":0.9213,"qty":4029.10352695}],"asks":[],"checksum":524225339,"timestamp":"2024-06-01T22:43:34.585595Z"}]}
{"channel":"book","type":"update","data":[{"symbol":"USDT/EUR","bids":[],"asks":[{"price":0.9215,"qty":326365.62239465}],"checksum":1974574787,"timestamp":"2024-06-01T22:43:34.820840Z"}]}
{"channel":"book","type":"update","data":[{"symbol":"USDT/EUR","bids":[],"asks":[{"price":0.9215,"qty":165540.23593835}],"checksum":1720730478,"timestamp":"2024-06-01T22:43:34.834913Z"}]}
{"channel":"book","type":"update","data":[{"symbol":"USDT/EUR","bids":[],"asks":[{"price":0.9215,"qty":373474.34549589}],"checksum":914024367,"timestamp":"2024-06-01T22:43:34.839630Z"}]}
{"channel":"book","type":"update","data":[{"symbol":"USDT/EUR","bids":[],"asks":[{"price":0.9214,"qty":313026.10732827}],"checksum":4132608068,"timestamp":"2024-06-01T22:43:35.060626Z"}]}
{"channel":"book","type":"update","data":[{"symbol":"USDT/EUR","bids":[{"price":0.9211,"qty":199694.05936485}],"asks":[],"checksum":2999223405,"timestamp":"2024-06-01T22:43:35.405241Z"}]}
{"channel":"book","type":"update","data":[{"symbol":"USDT/EUR","bids":[{"price":0.9211,"qty":202285.80853951}],"asks":[],"checksum":1459449366,"timestamp":"2024-06-01T22:43:35.410742Z"}]}
{"channel":"book","type":"update","data":[{"symbol":"USDT/EUR","bids":[{"price":0.9210,"qty":703076.48433708},{"price":0.9209,"qty":109718.74153910}],"asks":[],"checksum":1117349441,"timestamp":"2024-06-01T22:43:35.933067Z"}]}
{"channel":"book","type":"update","data":[{"symbol":"USDT/EUR","bids":[{"price":0.9213,"qty":309.99828789}],"asks":[],"checksum":1145345432,"timestamp":"2024-06-01T22:43:36.207831Z"}]}
{"channel":"book","type":"update","data":[{"symbol":"USDT/EUR","bids":[{"price":0.9210,"qty":58182.56594442}],"asks":[],"checksum":1595057365,"timestamp":"2024-06-01T22:43:36.207856Z"}]}
{"channel":"book","type":"update","data":[{"symbol":"USDT/EUR","bids":[{"price":0.9212,"qty":260443.39069699}],"asks":[],"checksum":3132390941,"timestamp":"2024-06-01T22:43:36.207974Z"}]}
{"channel":"book","type":"update","data":[{"symbol":"USDT/EUR","bids":[{"price":0.9213,"qty":7463.93114655}],"asks":[],"checksum":3195560251,"timestamp":"2024-06-01T22:43:36.212754Z"}]}
{"channel":"book","type":"update","data":[{"symbol":"USDT/EUR","bids":[{"price":0.9210,"qty":695629.88539615}],"asks":[],"checksum":3014873061,"timestamp":"2024-06-01T22:43:36.212868Z"}]}
{"channel":"book","type":"update","data":[{"symbol":"USDT/EUR","bids":[{"price":0.9212,"qty":332859.04832809}],"asks":[],"checksum":1486773126,"timestamp":"2024-06-01T22:43:36.212912Z"}]}
{"channel":"book","type":"update","data":[{"symbol":"USDT/EUR","bids":[{"price":0.9213,"qty":7421.44729903}],"asks":[],"checksum":1917048595,"timestamp":"2024-06-01T22:43:37.231275Z"}]}
{"channel":"book","type":"update","data":[{"symbol":"USDT/EUR","bids":[{"price":0.9211,"qty":199694.05936485}],"asks":[],"checksum":2524593512,"timestamp":"2024-06-01T22:43:37.865399Z"}]}
{"channel":"book","type":"update","data":[{"symbol":"USDT/EUR","bids":[{"price":0.9211,"qty":202468.57123821}],"asks":[],"checksum":745548404,"timestamp":"2024-06-01T22:43:37.870642Z"}]}
{"channel":"book","type":"update","data":[{"symbol":"USDT/EUR","bids":[],"asks":[{"price":0.9215,"qty":165540.23593835}],"checksum":2090503861,"timestamp":"2024-06-01T22:43:38.321563Z"}]}
{"channel":"book","type":"update","data":[{"symbol":"USDT/EUR","bids":[],"asks":[{"price":0.9215,"qty":334128.94768123}],"checksum":2761348631,"timestamp":"2024-06-01T22:43:38.326422Z"}]}
{"channel":"book","type":"update","data":[{"symbol":"USDT/EUR","bids":[{"price":0.9213,"qty":267.51444037}],"asks":[],"checksum":120972248,"timestamp":"2024-06-01T22:43:38.370770Z"}]}
{"channel":"book","type":"update","data":[{"symbol":"USDT/EUR","bids":[{"price":0.9212,"qty":260443.39069699}],"asks":[],"checksum":3961059259,"timestamp":"2024-06-01T22:43:38.370902Z"}]}
{"channel":"book","type":"update","data":[{"symbol":"USDT/EUR","bids":[{"price":0.9210,"qty":58182.56594442}],"asks":[],"checksum":273168130,"timestamp":"2024-06-01T22:43:38.370929Z"}]}
{"channel":"book","type":"update","data":[{"symbol":"USDT/EUR","bids":[{"price":0.9213,"qty":14291.10253824}],"asks":[],"checksum":3415504076,"timestamp":"2024-06-01T22:43:38.375719Z"}]}
{"channel":"book","type":"update","data":[{"symbol":"USDT/EUR","bids":[{"price":0.9210,"qty":711635.88021435}],"asks":[],"checksum":302390198,"timestamp":"2024-06-01T22:43:38.375779Z"}]}
{"channel":"book","type":"update","data":[{"symbol":"USDT/EUR","bids":[{"price":0.9212,"qty":327706.80689869}],"asks":[],"checksum":536880255,"timestamp":"2024-06-01T22:43:38.375805Z"}]}
{"channel":"book","type":"update","data":[{"symbol":"USDT/EUR","bids":[{"price":0.9207,"qty":196182.85389433}],"asks":[],"checksum":135985656,"timestamp":"2024-06-01T22:43:39.544227Z"}]}
{"channel":"book","type":"update","data":[{"symbol":"USDT/EUR","bids":[{"price":0.9212,"qty":260443.39069699}],"asks":[],"checksum":974964273,"timestamp":"2024-06-01T22:43:40.396230Z"}]}
{"channel":"book","type":"update","data":[{"symbol":"USDT/EUR","bids":[{"price":0.9210,"qty":58182.56594442}],"asks":[],"checksum":3817777483,"timestamp":"2024-06-01T22:43:40.396321Z"}]}
{"channel":"book","type":"update","data":[{"symbol":"USDT/EUR","bids":[{"price":0.9213,"qty":267.51444037}],"asks":[],"checksum":944958085,"timestamp":"2024-06-01T22:43:40.396369Z"}]}
{"channel":"book","type":"update","data":[{"symbol":"USDT/EUR","bids":[{"price":0.9213,"qty":21160.75777744}],"asks":[],"checksum":3895433920,"timestamp":"2024-06-01T22:43:40.401524Z"}]}
{"channel":"book","type":"update","data":[{"symbol":"USDT/EUR","bids":[{"price":0.9210,"qty":739463.35085128}],"asks":[],"checksum":3542618937,"timestamp":"2024-06-01T22:43:40.401703Z"}]}
{"channel":"book","type":"update","data":[{"symbol":"USDT/EUR","bids":[{"price":0.9212,"qty":331141.63451829}],"asks":[],"checksum":1950919553,"timestamp":"2024-06-01T22:43:40.401898Z"}]}
{"channel":"book","type":"update","data":[{"symbol":"USDT/EUR","bids":[{"price":0.9211,"qty":199694.05936485}],"asks":[],"checksum":3460480157,"timestamp":"2024-06-01T22:43:40.471117Z"}]}
{"channel":"book","type":"update","data":[{"symbol":"USDT/EUR","bids":[{"price":0.9211,"qty":202690.49737236}],"asks":[],"checksum":1253405273,"timestamp":"2024-06-01T22:43:40.476114Z"}]}
