{"channel":"book","type":"snapshot","data":[{"symbol":"XRP/AUD","bids":[{"price":0.78151,"qty":134.77812478},{"price":0.78150,"qty":3591.59618221},{"price":0.78115,"qty":205.24697405},{"price":0.78083,"qty":2942.36940179},{"price":0.78082,"qty":16169.86800000},{"price":0.78081,"qty":3684.81000000},{"price":0.78080,"qty":1188.39600000},{"price":0.78013,"qty":3885.15600000},{"price":0.78012,"qty":3933.66000000},{"price":0.77976,"qty":26.25648959}],"asks":[{"price":0.78251,"qty":3600.00000000},{"price":0.78252,"qty":33.62580430},{"price":0.78256,"qty":27019.32306509},{"price":0.78302,"qty":22.96618060},{"price":0.78413,"qty":3117.68895674},{"price":0.78414,"qty":7428.91000000},{"price":0.78437,"qty":1188.39600000},{"price":0.78438,"qty":6783.15000000},{"price":0.78458,"qty":3273.23000000},{"price":0.78525,"qty":16169.86800000}],"checksum":1444000772}]}
{"channel":"book","type":"update","data":[{"symbol":"XRP/AUD","bids":[{"price":0.78013,"qty":0.00000000},{"price":0.77973,"qty":390.45600000}],"asks":[],"checksum":2677221691,"timestamp":"2024-06-01T22:43:32.059856Z"}]}
{"channel":"book","type":"update","data":[{"symbol":"XRP/AUD","bids":[{"price":0.78084,"qty":3885.15600000}],"asks":[],"checksum":1602400726,"timestamp":"2024-06-01T22:43:32.062492Z"}]}
{"channel":"book","type":"update","data":[{"symbol":"XRP/AUD","bids":[{"price":0.78083,"qty":0.00000000},{"price":0.77973,"qty":390.45600000}],"asks":[],"checksum":3326832186,"timestamp":"2024-06-01T22:43:32.076126Z"}]}
{"channel":"book","type":"update","data":[{"symbol":"XRP/AUD","bids":[{"price":0.78085,"qty":2942.29410837}],"asks":[],"checksum":2495986484,"timestamp":"2024-06-01T22:43:32.076293Z"}]}
{"channel":"book","type":"update","data":[{"symbol":"XRP/AUD","bids":[],"asks":[{"price":0.78251,"qty":3537.20202000}],"checksum":639426313,"timestamp":"2024-06-01T22:43:32.170491Z"}]}
{"channel":"book","type":"update","data":[{"symbol":"XRP/AUD","bids":[],"asks":[{"price":0.78250,"qty":33.62580430}],"checksum":2494974417,"timestamp":"2024-06-01T22:43:34.907236Z"}]}
{"channel":"book","type":"update","data":[{"symbol":"XRP/AUD","bids":[{"price":0.78150,"qty":0.00000000},{"price":0.77973,"qty":390.45600000}],"asks":[],"checksum":734014636,"timestamp":"2024-06-01T22:43:34.910551Z"}]}
{"channel":"book","type":"update","data":[{"symbol":"XRP/AUD","bids":[],"asks":[{"price":0.78256,"qty":0.00000000},{"price":0.78525,"qty":16169.86800000}],"checksum":40931022,"timestamp":"2024-06-01T22:43:34.913255Z"}]}
{"channel":"book","type":"update","data":[{"symbol":"XRP/AUD","bids":[{"price":0.78150,"qty":3591.59618221}],"asks":[],"checksum":925104391,"timestamp":"2024-06-01T22:43:34.915998Z"}]}
{"channel":"book","type":"update","data":[{"symbol":"XRP/AUD","bids":[],"asks":[{"price":0.78256,"qty":5123.91344550}],"checksum":3403399366,"timestamp":"2024-06-01T22:43:34.918915Z"}]}
{"channel":"book","type":"update","data":[{"symbol":"XRP/AUD","bids":[{"price":0.78116,"qty":134.77812478}],"asks":[],"checksum":748802299,"timestamp":"2024-06-01T22:43:35.073417Z"}]}
{"channel":"book","type":"update","data":[{"symbol":"XRP/AUD","bids":[],"asks":[{"price":0.78252,"qty":0.00000000},{"price":0.78525,"qty":16169.86800000}],"checksum":2496950231,"timestamp":"2024-06-01T22:43:35.073641Z"}]}
{"channel":"book","type":"update","data":[{"symbol":"XRP/AUD","bids":[{"price":0.78151,"qty":0.00000000},{"price":0.77976,"qty":26.25648959}],"asks":[],"checksum":160457691,"timestamp":"2024-06-01T22:43:35.240943Z"}]}
{"channel":"book","type":"update","data":[{"symbol":"XRP/AUD","bids":[],"asks":[{"price":0.78251,"qty":0.00000000},{"price":0.78529,"qty":3885.15600000}],"checksum":3864180988,"timestamp":"2024-06-01T22:43:36.011270Z"}]}
{"channel":"book","type":"update","data":[{"symbol":"XRP/AUD","bids":[],"asks":[{"price":0.78501,"qty":3600.00000000}],"checksum":3416362931,"timestamp":"2024-06-01T22:43:36.141468Z"}]}
{"channel":"book","type":"update","data":[{"symbol":"XRP/AUD","bids":[{"price":0.78084,"qty":0.00000000},{"price":0.77973,"qty":390.45600000}],"asks":[],"checksum":3806222787,"timestamp":"2024-06-01T22:43:37.944423Z"}]}
{"channel":"book","type":"update","data":[{"symbol":"XRP/AUD","bids":[{"price":0.78086,"qty":3885.15600000}],"asks":[],"checksum":2985282149,"timestamp":"2024-06-01T22:43:37.947119Z"}]}
{"channel":"book","type":"update","data":[{"symbol":"XRP/AUD","bids":[{"price":0.78085,"qty":0.00000000},{"price":0.77973,"qty":390.45600000}],"asks":[],"checksum":271142232,"timestamp":"2024-06-01T22:43:37.977051Z"}]}
{"channel":"book","type":"update","data":[{"symbol":"XRP/AUD","bids":[{"price":0.78087,"qty":2942.21877077}],"asks":[],"checksum":212781377,"timestamp":"2024-06-01T22:43:37.977278Z"}]}
{"channel":"book","type":"update","data":[{"symbol":"XRP/AUD","bids":[{"price":0.78086,"qty":0.00000000},{"price":0.77973,"qty":390.45600000}],"asks":[],"checksum":1598816893,"timestamp":"2024-06-01T22:43:43.828074Z"}]}
{"channel":"book","type":"update","data":[{"symbol":"XRP/AUD","bids":[{"price":0.78088,"qty":3885.15600000}],"asks":[],"checksum":2943335632,"timestamp":"2024-06-01T22:43:43.831154Z"}]}
{"channel":"book","type":"update","data":[{"symbol":"XRP/AUD","bids":[{"price":0.78087,"qty":0.00000000},{"price":0.77973,"qty":390.45600000}],"asks":[],"checksum":2714895451,"timestamp":"2024-06-01T22:43:43.847586Z"}]}
{"channel":"book","type":"update","data":[{"symbol":"XRP/AUD","bids":[{"price":0.78089,"qty":2942.14343702}],"asks":[],"checksum":1116919796,"timestamp":"2024-06-01T22:43:43.847808Z"}]}
{"channel":"book","type":"update","data":[{"symbol":"XRP/AUD","bids":[],"asks":[{"price":0.78412,"qty":33.62580430}],"checksum":2392826408,"timestamp":"2024-06-01T22:43:47.564888Z"}]}
{"channel":"book","type":"update","data":[{"symbol":"XRP/AUD","bids":[],"asks":[{"price":0.78413,"qty":2534.06131170}],"checksum":158374466,"timestamp":"2024-06-01T22:43:47.599271Z"}]}
{"channel":"book","type":"update","data":[{"symbol":"XRP/AUD","bids":[],"asks":[{"price":0.78411,"qty":583.62764504}],"checksum":1059213721,"timestamp":"2024-06-01T22:43:47.599417Z"}]}
{"channel":"book","type":"update","data":[{"symbol":"XRP/AUD","bids":[],"asks":[{"price":0.78250,"qty":0.00000000},{"price":0.78501,"qty":3600.00000000}],"checksum":1511861233,"timestamp":"2024-06-01T22:43:47.739571Z"}]}
{"channel":"book","type":"update","data":[{"symbol":"XRP/AUD","bids":[],"asks":[{"price":0.78255,"qty":3600.00000000}],"checksum":988151656,"timestamp":"2024-06-01T22:43:47.744849Z"}]}
{"channel":"book","type":"update","data":[{"symbol":"XRP/AUD","bids":[{"price":0.78151,"qty":134.77812478}],"asks":[],"checksum":1629592698,"timestamp":"2024-06-01T22:43:47.912670Z"}]}
{"channel":"book","type":"update","data":[{"symbol":"XRP/AUD","bids":[{"price":0.78116,"qty":0.00000000},{"price":0.77976,"qty":26.25648959}],"asks":[],"checksum":833912642,"timestamp":"2024-06-01T22:43:48.086302Z"}]}
{"channel":"book","type":"update","data":[{"symbol":"XRP/AUD","bids":[],"asks":[{"price":0.78255,"qty":0.00000000},{"price":0.78525,"qty":16169.86800000}],"checksum":1270611037,"timestamp":"2024-06-01T22:43:49.645464Z"}]}
{"channel":"book","type":"update","data":[{"symbol":"XRP/AUD","bids":[],"asks":[{"price":0.78256,"qty":0.00000000},{"price":0.78529,"qty":3885.15600000}],"checksum":3693199224,"timestamp":"2024-06-01T22:43:49.647443Z"}]}
{"channel":"book","type":"update","data":[{"symbol":"XRP/AUD","bids":[],"asks":[{"price":0.78271,"qty":16974.41344550}],"checksum":2620902740,"timestamp":"2024-06-01T22:43:49.652986Z"}]}
{"channel":"book","type":"update","data":[{"symbol":"XRP/AUD","bids":[{"price":0.78088,"qty":0.00000000},{"price":0.77973,"qty":390.45600000}],"asks":[],"checksum":2555433320,"timestamp":"2024-06-01T22:43:49.711894Z"}]}
{"channel":"book","type":"update","data":[{"symbol":"XRP/AUD","bids":[{"price":0.78090,"qty":3885.15600000}],"asks":[],"checksum":3433670307,"timestamp":"2024-06-01T22:43:49.714394Z"}]}
{"channel":"book","type":"update","data":[{"symbol":"XRP/AUD","bids":[{"price":0.78116,"qty":2941.12646316}],"asks":[],"checksum":4071999129,"timestamp":"2024-06-01T22:43:49.718180Z"}]}
{"channel":"book","type":"update","data":[{"symbol":"XRP/AUD","bids":[{"price":0.78089,"qty":0.00000000},{"price":0.77976,"qty":26.25648959}],"asks":[],"checksum":2565599375,"timestamp":"2024-06-01T22:43:49.718283Z"}]}
{"channel":"book","type":"update","data":[{"symbol":"XRP/AUD","bids":[],"asks":[{"price":0.78271,"qty":0.00000000},{"price":0.78529,"qty":3885.15600000}],"checksum":3640492707,"timestamp":"2024-06-01T22:43:50.017873Z"}]}
{"channel":"book","type":"update","data":[{"symbol":"XRP/AUD","bids":[{"price":0.78150,"qty":0.00000000},{"price":0.77973,"qty":390.45600000}],"asks":[],"checksum":1011745548,"timestamp":"2024-06-01T22:43:50.018092Z"}]}
{"channel":"book","type":"update","data":[{"symbol":"XRP/AUD","bids":[],"asks":[{"price":0.78301,"qty":3600.00000000}],"checksum":420552860,"timestamp":"2024-06-01T22:43:50.023508Z"}]}
{"channel":"book","type":"update","data":[{"symbol":"XRP/AUD","bids":[{"price":0.78165,"qty":3590.90575618}],"asks":[],"checksum":3238897338,"timestamp":"2024-06-01T22:43:50.023657Z"}]}
{"channel":"book","type":"update","data":[{"symbol":"XRP/AUD","bids":[],"asks":[{"price":0.78286,"qty":21838.54998536}],"checksum":2469845337,"timestamp":"2024-06-01T22:43:50.023711Z"}]}
{"channel":"book","type":"update","data":[{"symbol":"XRP/AUD","bids":[],"asks":[{"price":0.78285,"qty":3600.00000000}],"checksum":2759967164,"timestamp":"2024-06-01T22:43:50.143294Z"}]}
{"channel":"book","type":"update","data":[{"symbol":"XRP/AUD","bids":[],"asks":[{"price":0.78301,"qty":0.00000000},{"price":0.78458,"qty":3273.23000000}],"checksum":2220630428,"timestamp":"2024-06-01T22:43:50.149840Z"}]}
{"channel":"book","type":"update","data":[{"symbol":"XRP/AUD","bids":[],"asks":[{"price":0.78284,"qty":33.62580430}],"checksum":2500250511,"timestamp":"2024-06-01T22:43:52.745715Z"}]}
{"channel":"book","type":"update","data":[{"symbol":"XRP/AUD","bids":[],"asks":[{"price":0.78283,"qty":3600.00000000}],"checksum":1765788079,"timestamp":"2024-06-01T22:43:52.751096Z"}]}
