{"channel":"book","type":"snapshot","data":[{"symbol":"XRP/USD","bids":[{"price":0.51971,"qty":1700.85042521},{"price":0.51968,"qty":3078.25501418},{"price":0.51960,"qty":4811.31200731},{"price":0.51958,"qty":1360.00000000},{"price":0.51956,"qty":4478.72886981},{"price":0.51955,"qty":112.39730000},{"price":0.51953,"qty":6895.44266928},{"price":0.51952,"qty":21016.43171641},{"price":0.51951,"qty":2652.20422216},{"price":0.51950,"qty":5951.31952087}],"asks":[{"price":0.51974,"qty":4829.31089354},{"price":0.51975,"qty":16355.93616406},{"price":0.51976,"qty":1400.00000000},{"price":0.51977,"qty":1392.88897099},{"price":0.51978,"qty":680.00000000},{"price":0.51983,"qty":16061.70898686},{"price":0.51989,"qty":1610.98627466},{"price":0.51990,"qty":12578.07576841},{"price":0.51991,"qty":60.45016443},{"price":0.51993,"qty":4051.36799558}],"checksum":3445164751}]}
{"channel":"book","type":"update","data":[{"symbol":"XRP/USD","bids":[],"asks":[{"price":0.51975,"qty":0.00000000},{"price":0.51994,"qty":68.14614838}],"checksum":1913440395,"timestamp":"2024-06-01T22:43:34.045499Z"}]}
{"channel":"book","type":"update","data":[{"symbol":"XRP/USD","bids":[],"asks":[{"price":0.51973,"qty":16355.76791602}],"checksum":4217768123,"timestamp":"2024-06-01T22:43:34.085744Z"}]}
{"channel":"book","type":"update","data":[{"symbol":"XRP/USD","bids":[{"price":0.51958,"qty":680.00000000}],"asks":[],"checksum":152193756,"timestamp":"2024-06-01T22:43:34.489359Z"}]}
{"channel":"book","type":"update","data":[{"symbol":"XRP/USD","bids":[{"price":0.51950,"qty":6367.31070089}],"asks":[],"checksum":342942981,"timestamp":"2024-06-01T22:43:34.494530Z"}]}
{"channel":"book","type":"update","data":[{"symbol":"XRP/USD","bids":[{"price":0.51950,"qty":415.99118002}],"asks":[],"checksum":803992254,"timestamp":"2024-06-01T22:43:35.147546Z"}]}
{"channel":"book","type":"update","data":[{"symbol":"XRP/USD","bids":[],"asks":[{"price":0.51983,"qty":11011.70898686}],"checksum":1561618661,"timestamp":"2024-06-01T22:43:36.011469Z"}]}
{"channel":"book","type":"update","data":[{"symbol":"XRP/USD","bids":[],"asks":[{"price":0.51989,"qty":18.24915592}],"checksum":982752033,"timestamp":"2024-06-01T22:43:36.011636Z"}]}
{"channel":"book","type":"update","data":[{"symbol":"XRP/USD","bids":[],"asks":[{"price":0.51974,"qty":4810.15743531}],"checksum":4056194004,"timestamp":"2024-06-01T22:43:36.037408Z"}]}
{"channel":"book","type":"update","data":[{"symbol":"XRP/USD","bids":[],"asks":[{"price":0.51983,"qty":16061.70898686}],"checksum":1857303561,"timestamp":"2024-06-01T22:43:36.114696Z"}]}
{"channel":"book","type":"update","data":[{"symbol":"XRP/USD","bids":[],"asks":[{"price":0.51973,"qty":0.00000000},{"price":0.51994,"qty":68.14614838}],"checksum":4255091077,"timestamp":"2024-06-01T22:43:36.143897Z"}]}
{"channel":"book","type":"update","data":[{"symbol":"XRP/USD","bids":[{"price":0.51950,"qty":6367.31070089}],"asks":[],"checksum":2779347034,"timestamp":"2024-06-01T22:43:36.147294Z"}]}
{"channel":"book","type":"update","data":[{"symbol":"XRP/USD","bids":[],"asks":[{"price":0.51989,"qty":1610.98627466}],"checksum":1095383963,"timestamp":"2024-06-01T22:43:36.149475Z"}]}
{"channel":"book","type":"update","data":[{"symbol":"XRP/USD","bids":[],"asks":[{"price":0.51978,"qty":699.15345823}],"checksum":3798405088,"timestamp":"2024-06-01T22:43:36.157481Z"}]}
{"channel":"book","type":"update","data":[{"symbol":"XRP/USD","bids":[],"asks":[{"price":0.51978,"qty":19.15345823}],"checksum":3840951332,"timestamp":"2024-06-01T22:43:37.706932Z"}]}
{"channel":"book","type":"update","data":[{"symbol":"XRP/USD","bids":[],"asks":[{"price":0.51973,"qty":16355.80931330}],"checksum":2799885199,"timestamp":"2024-06-01T22:43:37.733141Z"}]}
{"channel":"book","type":"update","data":[{"symbol":"XRP/USD","bids":[],"asks":[{"price":0.51977,"qty":2072.88897099}],"checksum":312092721,"timestamp":"2024-06-01T22:43:37.865310Z"}]}
{"channel":"book","type":"update","data":[{"symbol":"XRP/USD","bids":[{"price":0.51958,"qty":0.00000000},{"price":0.51949,"qty":57812.64803106}],"asks":[],"checksum":9259649,"timestamp":"2024-06-01T22:43:39.045660Z"}]}
{"channel":"book","type":"update","data":[{"symbol":"XRP/USD","bids":[{"price":0.51956,"qty":5158.72886981}],"asks":[],"checksum":2838398994,"timestamp":"2024-06-01T22:43:39.267332Z"}]}
{"channel":"book","type":"update","data":[{"symbol":"XRP/USD","bids":[{"price":0.51949,"qty":9697.27709795}],"asks":[],"checksum":389093891,"timestamp":"2024-06-01T22:43:39.765248Z"}]}
{"channel":"book","type":"update","data":[{"symbol":"XRP/USD","bids":[{"price":0.51950,"qty":415.99118002}],"asks":[],"checksum":1017659991,"timestamp":"2024-06-01T22:43:39.768518Z"}]}
{"channel":"book","type":"update","data":[{"symbol":"XRP/USD","bids":[],"asks":[{"price":0.51977,"qty":1392.88897099}],"checksum":2295378409,"timestamp":"2024-06-01T22:43:42.536660Z"}]}
{"channel":"book","type":"update","data":[{"symbol":"XRP/USD","bids":[],"asks":[{"price":0.51977,"qty":2072.88897099}],"checksum":1017659991,"timestamp":"2024-06-01T22:43:42.727043Z"}]}
{"channel":"book","type":"update","data":[{"symbol":"XRP/USD","bids":[],"asks":[{"price":0.51973,"qty":0.00000000},{"price":0.51994,"qty":68.14614838}],"checksum":670290771,"timestamp":"2024-06-01T22:43:43.269535Z"}]}
{"channel":"book","type":"update","data":[{"symbol":"XRP/USD","bids":[],"asks":[{"price":0.51990,"qty":75.91232291}],"checksum":1604288230,"timestamp":"2024-06-01T22:43:43.275405Z"}]}
{"channel":"book","type":"update","data":[{"symbol":"XRP/USD","bids":[],"asks":[{"price":0.51990,"qty":2324.57576841}],"checksum":445064901,"timestamp":"2024-06-01T22:43:43.278837Z"}]}
{"channel":"book","type":"update","data":[{"symbol":"XRP/USD","bids":[{"price":0.51952,"qty":9610.00000000}],"asks":[],"checksum":1172012576,"timestamp":"2024-06-01T22:43:43.463842Z"}]}
{"channel":"book","type":"update","data":[{"symbol":"XRP/USD","bids":[],"asks":[{"price":0.51977,"qty":1392.88897099}],"checksum":3904970425,"timestamp":"2024-06-01T22:43:44.380476Z"}]}
{"channel":"book","type":"update","data":[{"symbol":"XRP/USD","bids":[{"price":0.51954,"qty":38.48296507}],"asks":[],"checksum":3966421935,"timestamp":"2024-06-01T22:43:44.478204Z"}]}
{"channel":"book","type":"update","data":[{"symbol":"XRP/USD","bids":[],"asks":[{"price":0.51977,"qty":2072.88897099}],"checksum":53153824,"timestamp":"2024-06-01T22:43:44.493198Z"}]}
{"channel":"book","type":"update","data":[{"symbol":"XRP/USD","bids":[],"asks":[{"price":0.51978,"qty":0.00000000},{"price":0.51995,"qty":23.94113765}],"checksum":2297788939,"timestamp":"2024-06-01T22:43:49.139124Z"}]}
{"channel":"book","type":"update","data":[{"symbol":"XRP/USD","bids":[],"asks":[{"price":0.51978,"qty":19.15345823}],"checksum":53153824,"timestamp":"2024-06-01T22:43:49.258568Z"}]}
{"channel":"book","type":"update","data":[{"symbol":"XRP/USD","bids":[{"price":0.51952,"qty":0.00000000},{"price":0.51949,"qty":9697.27709795},{"price":0.51961,"qty":9610.00000000}],"asks":[],"checksum":1928128022,"timestamp":"2024-06-01T22:43:49.645603Z"}]}
{"channel":"book","type":"update","data":[{"symbol":"XRP/USD","bids":[],"asks":[{"price":0.51983,"qty":11011.70898686}],"checksum":1001360771,"timestamp":"2024-06-01T22:43:49.645649Z"}]}
{"channel":"book","type":"update","data":[{"symbol":"XRP/USD","bids":[],"asks":[{"price":0.51977,"qty":680.00000000}],"checksum":437656048,"timestamp":"2024-06-01T22:43:49.645732Z"}]}
{"channel":"book","type":"update","data":[{"symbol":"XRP/USD","bids":[],"asks":[{"price":0.51989,"qty":18.24915592}],"checksum":85918073,"timestamp":"2024-06-01T22:43:49.645843Z"}]}
{"channel":"book","type":"update","data":[{"symbol":"XRP/USD","bids":[{"price":0.51959,"qty":36.23516623}],"asks":[],"checksum":4141260961,"timestamp":"2024-06-01T22:43:49.646167Z"}]}
{"channel":"book","type":"update","data":[{"symbol":"XRP/USD","bids":[],"asks":[{"price":0.51990,"qty":75.91232291}],"checksum":2542516762,"timestamp":"2024-06-01T22:43:49.647286Z"}]}
{"channel":"book","type":"update","data":[{"symbol":"XRP/USD","bids":[{"price":0.51953,"qty":16505.44266928}],"asks":[],"checksum":2101744009,"timestamp":"2024-06-01T22:43:49.647691Z"}]}
{"channel":"book","type":"update","data":[{"symbol":"XRP/USD","bids":[],"asks":[{"price":0.51976,"qty":0.00000000},{"price":0.51995,"qty":23.94113765}],"checksum":2163346864,"timestamp":"2024-06-01T22:43:49.648771Z"}]}
{"channel":"book","type":"update","data":[{"symbol":"XRP/USD","bids":[{"price":0.51973,"qty":1393.00957324}],"asks":[],"checksum":1591043626,"timestamp":"2024-06-01T22:43:49.648990Z"}]}
{"channel":"book","type":"update","data":[{"symbol":"XRP/USD","bids":[{"price":0.51958,"qty":36.23516623}],"asks":[],"checksum":710132422,"timestamp":"2024-06-01T22:43:49.650264Z"}]}
{"channel":"book","type":"update","data":[{"symbol":"XRP/USD","bids":[{"price":0.51957,"qty":3011.74580865}],"asks":[],"checksum":3312464675,"timestamp":"2024-06-01T22:43:49.651048Z"}]}
{"channel":"book","type":"update","data":[{"symbol":"XRP/USD","bids":[],"asks":[{"price":0.51983,"qty":1393.08998634}],"checksum":2654647666,"timestamp":"2024-06-01T22:43:49.651753Z"}]}
{"channel":"book","type":"update","data":[{"symbol":"XRP/USD","bids":[{"price":0.51960,"qty":0.00000000},{"price":0.51954,"qty":38.48296507}],"asks":[],"checksum":3230272631,"timestamp":"2024-06-01T22:43:49.651762Z"}]}
{"channel":"book","type":"update","data":[{"symbol":"XRP/USD","bids":[],"asks":[{"price":0.51974,"qty":0.00000000},{"price":0.51996,"qty":66.22800365}],"checksum":3350608912,"timestamp":"2024-06-01T22:43:49.651771Z"}]}
{"channel":"book","type":"update","data":[{"symbol":"XRP/USD","bids":[{"price":0.51957,"qty":51120.69589321}],"asks":[],"checksum":1996002207,"timestamp":"2024-06-01T22:43:49.651951Z"}]}
{"channel":"book","type":"update","data":[{"symbol":"XRP/USD","bids":[],"asks":[{"price":0.51982,"qty":1400.00000000}],"checksum":2202889835,"timestamp":"2024-06-01T22:43:49.655151Z"}]}
{"channel":"book","type":"update","data":[{"symbol":"XRP/USD","bids":[{"price":0.51955,"qty":148.63246623}],"asks":[],"checksum":3628225277,"timestamp":"2024-06-01T22:43:49.656028Z"}]}
{"channel":"book","type":"update","data":[{"symbol":"XRP/USD","bids":[{"price":0.51976,"qty":1392.94256941}],"asks":[],"checksum":3585830840,"timestamp":"2024-06-01T22:43:49.657208Z"}]}
{"channel":"book","type":"update","data":[{"symbol":"XRP/USD","bids":[{"price":0.51964,"qty":4811.00393439}],"asks":[],"checksum":3337831224,"timestamp":"2024-06-01T22:43:49.658530Z"}]}
{"channel":"book","type":"update","data":[{"symbol":"XRP/USD","bids":[{"price":0.51956,"qty":4478.72886981},{"price":0.51960,"qty":680.00000000}],"asks":[],"checksum":441406000,"timestamp":"2024-06-01T22:43:49.669210Z"}]}
{"channel":"book","type":"update","data":[{"symbol":"XRP/USD","bids":[{"price":0.51960,"qty":1360.00000000}],"asks":[],"checksum":1791286240,"timestamp":"2024-06-01T22:43:49.674200Z"}]}
{"channel":"book","type":"update","data":[{"symbol":"XRP/USD","bids":[],"asks":[{"price":0.51981,"qty":680.00000000}],"checksum":2315311040,"timestamp":"2024-06-01T22:43:49.674431Z"}]}
{"channel":"book","type":"update","data":[{"symbol":"XRP/USD","bids":[],"asks":[{"price":0.51977,"qty":0.00000000},{"price":0.51995,"qty":23.94113765},{"price":0.51981,"qty":1360.00000000}],"checksum":3241746324,"timestamp":"2024-06-01T22:43:49.674449Z"}]}
{"channel":"book","type":"update","data":[{"symbol":"XRP/USD","bids":[],"asks":[{"price":0.51978,"qty":0.00000000},{"price":0.51996,"qty":66.22800365}],"checksum":873191298,"timestamp":"2024-06-01T22:43:49.676146Z"}]}
{"channel":"book","type":"update","data":[{"symbol":"XRP/USD","bids":[{"price":0.51977,"qty":1392.88897099}],"asks":[],"checksum":2779294069,"timestamp":"2024-06-01T22:43:49.679488Z"}]}
{"channel":"book","type":"update","data":[{"symbol":"XRP/USD","bids":[],"asks":[{"price":0.51981,"qty":680.00000000}],"checksum":1666494459,"timestamp":"2024-06-01T22:43:49.682037Z"}]}
{"channel":"book","type":"update","data":[{"symbol":"XRP/USD","bids":[{"price":0.51971,"qty":0.00000000},{"price":0.51957,"qty":51120.69589321}],"asks":[],"checksum":1977288502,"timestamp":"2024-06-01T22:43:49.682223Z"}]}
{"channel":"book","type":"update","data":[{"symbol":"XRP/USD","bids":[{"price":0.51973,"qty":0.00000000},{"price":0.51956,"qty":4478.72886981}],"asks":[],"checksum":3634024949,"timestamp":"2024-06-01T22:43:49.682453Z"}]}
{"channel":"book","type":"update","data":[{"symbol":"XRP/USD","bids":[],"asks":[{"price":0.51981,"qty":0.00000000},{"price":0.51997,"qty":461.12958895}],"checksum":950254520,"timestamp":"2024-06-01T22:43:49.686336Z"}]}
{"channel":"book","type":"update","data":[{"symbol":"XRP/USD","bids":[{"price":0.51960,"qty":680.00000000}],"asks":[],"checksum":2710511773,"timestamp":"2024-06-01T22:43:49.686430Z"}]}
{"channel":"book","type":"update","data":[{"symbol":"XRP/USD","bids":[{"price":0.51978,"qty":1392.83537669}],"asks":[],"checksum":3670409981,"timestamp":"2024-06-01T22:43:49.686911Z"}]}
{"channel":"book","type":"update","data":[{"symbol":"XRP/USD","bids":[{"price":0.51962,"qty":4961.82544078}],"asks":[],"checksum":1584257576,"timestamp":"2024-06-01T22:43:49.689932Z"}]}
{"channel":"book","type":"update","data":[{"symbol":"XRP/USD","bids":[],"asks":[{"price":0.51983,"qty":0.00000000},{"price":0.51999,"qty":54.77720972}],"checksum":269256860,"timestamp":"2024-06-01T22:43:49.696293Z"}]}
{"channel":"book","type":"update","data":[{"symbol":"XRP/USD","bids":[{"price":0.51960,"qty":0.00000000},{"price":0.51957,"qty":51120.69589321},{"price":0.51964,"qty":5491.00393439}],"asks":[],"checksum":1362681405,"timestamp":"2024-06-01T22:43:49.696523Z"}]}
{"channel":"book","type":"update","data":[{"symbol":"XRP/USD","bids":[{"price":0.51964,"qty":6171.00393439}],"asks":[],"checksum":3497841217,"timestamp":"2024-06-01T22:43:49.696744Z"}]}
{"channel":"book","type":"update","data":[{"symbol":"XRP/USD","bids":[],"asks":[{"price":0.51982,"qty":0.00000000},{"price":0.52000,"qty":26691.60964604}],"checksum":3747579876,"timestamp":"2024-06-01T22:43:49.699053Z"}]}
{"channel":"book","type":"update","data":[{"symbol":"XRP/USD","bids":[{"price":0.51981,"qty":1392.80858109}],"asks":[],"checksum":1246908315,"timestamp":"2024-06-01T22:43:49.699208Z"}]}
{"channel":"book","type":"update","data":[{"symbol":"XRP/USD","bids":[],"asks":[{"price":0.51988,"qty":1400.00000000}],"checksum":3366899083,"timestamp":"2024-06-01T22:43:49.699296Z"}]}
{"channel":"book","type":"update","data":[{"symbol":"XRP/USD","bids":[{"price":0.51976,"qty":0.00000000},{"price":0.51957,"qty":51120.69589321}],"asks":[],"checksum":629808898,"timestamp":"2024-06-01T22:43:49.699329Z"}]}
{"channel":"book","type":"update","data":[{"symbol":"XRP/USD","bids":[],"asks":[{"price":0.51990,"qty":1776.56642063}],"checksum":970764357,"timestamp":"2024-06-01T22:43:49.699594Z"}]}
{"channel":"book","type":"update","data":[{"symbol":"XRP/USD","bids":[{"price":0.51964,"qty":5491.00393439}],"asks":[],"checksum":3097017401,"timestamp":"2024-06-01T22:43:49.703120Z"}]}
{"channel":"book","type":"update","data":[{"symbol":"XRP/USD","bids":[{"price":0.51985,"qty":1392.71480460}],"asks":[],"checksum":4112490755,"timestamp":"2024-06-01T22:43:49.703994Z"}]}
