{"channel":"book","type":"snapshot","data":[{"symbol":"XRP/USDT","bids":[{"price":0.52007,"qty":9622.16334093},{"price":0.52003,"qty":9622.75394614},{"price":0.51999,"qty":16799.57948697},{"price":0.51998,"qty":9623.68349048},{"price":0.51993,"qty":3011.74580865},{"price":0.51991,"qty":415.99118002},{"price":0.51986,"qty":9625.94631056},{"price":0.51984,"qty":3000.00000000},{"price":0.51980,"qty":9939.22400916},{"price":0.51979,"qty":13661.98967880}],"asks":[{"price":0.52018,"qty":800.00000000},{"price":0.52021,"qty":3470.00000000},{"price":0.52030,"qty":12168.66344550},{"price":0.52031,"qty":1582.65411094},{"price":0.52036,"qty":415.99118002},{"price":0.52037,"qty":1730.43066871},{"price":0.52038,"qty":1262.50000000},{"price":0.52045,"qty":3011.74580865},{"price":0.52049,"qty":2007.02973057},{"price":0.52071,"qty":151.14234120}],"checksum":158273952}]}
{"channel":"book","type":"update","data":[{"symbol":"XRP/USDT","bids":[],"asks":[{"price":0.52015,"qty":9620.73824703}],"checksum":7919339,"timestamp":"2024-06-01T22:43:33.972376Z"}]}
{"channel":"book","type":"update","data":[{"symbol":"XRP/USDT","bids":[{"price":0.51999,"qty":5240.35312964}],"asks":[],"checksum":249400426,"timestamp":"2024-06-01T22:43:34.572183Z"}]}
{"channel":"book","type":"update","data":[{"symbol":"XRP/USDT","bids":[{"price":0.51999,"qty":1336.07806000}],"asks":[],"checksum":3038330992,"timestamp":"2024-06-01T22:43:35.082773Z"}]}
{"channel":"book","type":"update","data":[{"symbol":"XRP/USDT","bids":[{"price":0.51993,"qty":0.00000000},{"price":0.51975,"qty":3188.39852000}],"asks":[],"checksum":3813434986,"timestamp":"2024-06-01T22:43:35.144114Z"}]}
{"channel":"book","type":"update","data":[{"symbol":"XRP/USDT","bids":[{"price":0.51993,"qty":3011.74580865}],"asks":[],"checksum":3038330992,"timestamp":"2024-06-01T22:43:35.507200Z"}]}
{"channel":"book","type":"update","data":[{"symbol":"XRP/USDT","bids":[],"asks":[{"price":0.52031,"qty":0.00000000},{"price":0.52065,"qty":2452.00000000}],"checksum":1309860949,"timestamp":"2024-06-01T22:43:36.010902Z"}]}
{"channel":"book","type":"update","data":[{"symbol":"XRP/USDT","bids":[],"asks":[{"price":0.52021,"qty":470.00000000}],"checksum":1383560271,"timestamp":"2024-06-01T22:43:36.011050Z"}]}
{"channel":"book","type":"update","data":[{"symbol":"XRP/USDT","bids":[],"asks":[{"price":0.52018,"qty":0.00000000},{"price":0.52066,"qty":11946.75522345}],"checksum":1235224212,"timestamp":"2024-06-01T22:43:36.011430Z"}]}
{"channel":"book","type":"update","data":[{"symbol":"XRP/USDT","bids":[],"asks":[{"price":0.52021,"qty":0.00000000},{"price":0.52067,"qty":38.49036493}],"checksum":526943053,"timestamp":"2024-06-01T22:43:36.013782Z"}]}
{"channel":"book","type":"update","data":[{"symbol":"XRP/USDT","bids":[{"price":0.51984,"qty":4262.50000000}],"asks":[],"checksum":2383291561,"timestamp":"2024-06-01T22:43:36.086064Z"}]}
{"channel":"book","type":"update","data":[{"symbol":"XRP/USDT","bids":[],"asks":[{"price":0.52015,"qty":0.00000000},{"price":0.52072,"qty":2454.00000000}],"checksum":581624446,"timestamp":"2024-06-01T22:43:36.125235Z"}]}
{"channel":"book","type":"update","data":[{"symbol":"XRP/USDT","bids":[{"price":0.52003,"qty":0.00000000},{"price":0.51975,"qty":1924.59852000}],"asks":[],"checksum":3373834035,"timestamp":"2024-06-01T22:43:36.125399Z"}]}
{"channel":"book","type":"update","data":[{"symbol":"XRP/USDT","bids":[],"asks":[{"price":0.52029,"qty":470.00000000}],"checksum":1566365102,"timestamp":"2024-06-01T22:43:36.128090Z"}]}
{"channel":"book","type":"update","data":[{"symbol":"XRP/USDT","bids":[],"asks":[{"price":0.52030,"qty":0.00000000},{"price":0.52072,"qty":2454.00000000}],"checksum":3674510594,"timestamp":"2024-06-01T22:43:36.128537Z"}]}
{"channel":"book","type":"update","data":[{"symbol":"XRP/USDT","bids":[],"asks":[{"price":0.52072,"qty":0.00000000},{"price":0.52073,"qty":583.62764504},{"price":0.52073,"qty":3037.62764504}],"checksum":318598233,"timestamp":"2024-06-01T22:43:36.128696Z"}]}
{"channel":"book","type":"update","data":[{"symbol":"XRP/USDT","bids":[{"price":0.52008,"qty":9621.92438519}],"asks":[],"checksum":3158086544,"timestamp":"2024-06-01T22:43:36.129867Z"}]}
{"channel":"book","type":"update","data":[{"symbol":"XRP/USDT","bids":[],"asks":[{"price":0.52028,"qty":3000.00000000}],"checksum":4267650739,"timestamp":"2024-06-01T22:43:36.130018Z"}]}
{"channel":"book","type":"update","data":[{"symbol":"XRP/USDT","bids":[],"asks":[{"price":0.52027,"qty":800.00000000}],"checksum":1352750209,"timestamp":"2024-06-01T22:43:36.130312Z"}]}
{"channel":"book","type":"update","data":[{"symbol":"XRP/USDT","bids":[],"asks":[{"price":0.52035,"qty":470.00000000}],"checksum":1578697172,"timestamp":"2024-06-01T22:43:36.131274Z"}]}
{"channel":"book","type":"update","data":[{"symbol":"XRP/USDT","bids":[],"asks":[{"price":0.52029,"qty":0.00000000},{"price":0.52066,"qty":11946.75522345}],"checksum":3405767239,"timestamp":"2024-06-01T22:43:36.131324Z"}]}
{"channel":"book","type":"update","data":[{"symbol":"XRP/USDT","bids":[],"asks":[{"price":0.52030,"qty":2257.66344550}],"checksum":2302726146,"timestamp":"2024-06-01T22:43:36.131812Z"}]}
{"channel":"book","type":"update","data":[{"symbol":"XRP/USDT","bids":[],"asks":[{"price":0.52029,"qty":1582.65411094}],"checksum":2436609704,"timestamp":"2024-06-01T22:43:36.132346Z"}]}
{"channel":"book","type":"update","data":[{"symbol":"XRP/USDT","bids":[],"asks":[{"price":0.52035,"qty":0.00000000},{"price":0.52065,"qty":2452.00000000}],"checksum":1095366584,"timestamp":"2024-06-01T22:43:36.132722Z"}]}
{"channel":"book","type":"update","data":[{"symbol":"XRP/USDT","bids":[],"asks":[{"price":0.52027,"qty":1270.00000000}],"checksum":1682134984,"timestamp":"2024-06-01T22:43:36.133198Z"}]}
{"channel":"book","type":"update","data":[{"symbol":"XRP/USDT","bids":[],"asks":[{"price":0.52027,"qty":800.00000000}],"checksum":1095366584,"timestamp":"2024-06-01T22:43:36.134362Z"}]}
{"channel":"book","type":"update","data":[{"symbol":"XRP/USDT","bids":[],"asks":[{"price":0.52026,"qty":470.00000000}],"checksum":1526850,"timestamp":"2024-06-01T22:43:36.134454Z"}]}
{"channel":"book","type":"update","data":[{"symbol":"XRP/USDT","bids":[],"asks":[{"price":0.52025,"qty":3000.00000000}],"checksum":32859840,"timestamp":"2024-06-01T22:43:36.211582Z"}]}
{"channel":"book","type":"update","data":[{"symbol":"XRP/USDT","bids":[],"asks":[{"price":0.52026,"qty":0.00000000},{"price":0.52049,"qty":2007.02973057}],"checksum":2818246105,"timestamp":"2024-06-01T22:43:36.214502Z"}]}
{"channel":"book","type":"update","data":[{"symbol":"XRP/USDT","bids":[],"asks":[{"price":0.52024,"qty":470.00000000}],"checksum":3265835682,"timestamp":"2024-06-01T22:43:36.214863Z"}]}
{"channel":"book","type":"update","data":[{"symbol":"XRP/USDT","bids":[],"asks":[{"price":0.52028,"qty":0.00000000},{"price":0.52049,"qty":2007.02973057}],"checksum":1023746281,"timestamp":"2024-06-01T22:43:36.216432Z"}]}
{"channel":"book","type":"update","data":[{"symbol":"XRP/USDT","bids":[],"asks":[{"price":0.52022,"qty":800.00000000}],"checksum":1482802684,"timestamp":"2024-06-01T22:43:36.216605Z"}]}
{"channel":"book","type":"update","data":[{"symbol":"XRP/USDT","bids":[],"asks":[{"price":0.52024,"qty":0.00000000},{"price":0.52049,"qty":2007.02973057}],"checksum":3620645404,"timestamp":"2024-06-01T22:43:36.219468Z"}]}
{"channel":"book","type":"update","data":[{"symbol":"XRP/USDT","bids":[],"asks":[{"price":0.52021,"qty":470.00000000}],"checksum":1906297774,"timestamp":"2024-06-01T22:43:36.219706Z"}]}
{"channel":"book","type":"update","data":[{"symbol":"XRP/USDT","bids":[],"asks":[{"price":0.52022,"qty":0.00000000},{"price":0.52049,"qty":2007.02973057}],"checksum":1776224082,"timestamp":"2024-06-01T22:43:36.590168Z"}]}
{"channel":"book","type":"update","data":[{"symbol":"XRP/USDT","bids":[],"asks":[{"price":0.52018,"qty":800.00000000}],"checksum":3461246345,"timestamp":"2024-06-01T22:43:36.590339Z"}]}
{"channel":"book","type":"update","data":[{"symbol":"XRP/USDT","bids":[],"asks":[{"price":0.52024,"qty":470.00000000}],"checksum":437188997,"timestamp":"2024-06-01T22:43:36.592941Z"}]}
{"channel":"book","type":"update","data":[{"symbol":"XRP/USDT","bids":[],"asks":[{"price":0.52021,"qty":0.00000000},{"price":0.52045,"qty":3011.74580865}],"checksum":1664548217,"timestamp":"2024-06-01T22:43:36.593014Z"}]}
{"channel":"book","type":"update","data":[{"symbol":"XRP/USDT","bids":[],"asks":[{"price":0.52022,"qty":3000.00000000}],"checksum":4159213651,"timestamp":"2024-06-01T22:43:36.711815Z"}]}
{"channel":"book","type":"update","data":[{"symbol":"XRP/USDT","bids":[],"asks":[{"price":0.52024,"qty":0.00000000},{"price":0.52045,"qty":3011.74580865}],"checksum":2702441473,"timestamp":"2024-06-01T22:43:36.714532Z"}]}
{"channel":"book","type":"update","data":[{"symbol":"XRP/USDT","bids":[],"asks":[{"price":0.52021,"qty":470.00000000}],"checksum":1727726820,"timestamp":"2024-06-01T22:43:36.714880Z"}]}
{"channel":"book","type":"update","data":[{"symbol":"XRP/USDT","bids":[],"asks":[{"price":0.52025,"qty":0.00000000},{"price":0.52045,"qty":3011.74580865}],"checksum":785601410,"timestamp":"2024-06-01T22:43:36.715863Z"}]}
{"channel":"book","type":"update","data":[{"symbol":"XRP/USDT","bids":[],"asks":[{"price":0.52027,"qty":0.00000000},{"price":0.52049,"qty":2007.02973057}],"checksum":2890449623,"timestamp":"2024-06-01T22:43:36.716301Z"}]}
{"channel":"book","type":"update","data":[{"symbol":"XRP/USDT","bids":[],"asks":[{"price":0.52017,"qty":9620.50196008}],"checksum":2832056473,"timestamp":"2024-06-01T22:43:37.292169Z"}]}
{"channel":"book","type":"update","data":[{"symbol":"XRP/USDT","bids":[],"asks":[{"price":0.52017,"qty":0.00000000},{"price":0.52049,"qty":2007.02973057}],"checksum":2890449623,"timestamp":"2024-06-01T22:43:37.476296Z"}]}
{"channel":"book","type":"update","data":[{"symbol":"XRP/USDT","bids":[],"asks":[{"price":0.52017,"qty":9620.49985522}],"checksum":433061608,"timestamp":"2024-06-01T22:43:37.796956Z"}]}
{"channel":"book","type":"update","data":[{"symbol":"XRP/USDT","bids":[],"asks":[{"price":0.52017,"qty":0.00000000},{"price":0.52049,"qty":2007.02973057}],"checksum":2890449623,"timestamp":"2024-06-01T22:43:37.968588Z"}]}
{"channel":"book","type":"update","data":[{"symbol":"XRP/USDT","bids":[{"price":0.52007,"qty":0.00000000},{"price":0.51975,"qty":1924.59852000}],"asks":[],"checksum":84667463,"timestamp":"2024-06-01T22:43:37.968746Z"}]}
{"channel":"book","type":"update","data":[{"symbol":"XRP/USDT","bids":[{"price":0.52004,"qty":9622.58910613}],"asks":[],"checksum":983171609,"timestamp":"2024-06-01T22:43:37.972465Z"}]}
{"channel":"book","type":"update","data":[{"symbol":"XRP/USDT","bids":[],"asks":[{"price":0.52017,"qty":9620.34020511}],"checksum":2695608030,"timestamp":"2024-06-01T22:43:38.400881Z"}]}
{"channel":"book","type":"update","data":[{"symbol":"XRP/USDT","bids":[],"asks":[{"price":0.52017,"qty":0.00000000},{"price":0.52049,"qty":2007.02973057}],"checksum":983171609,"timestamp":"2024-06-01T22:43:39.476661Z"}]}
{"channel":"book","type":"update","data":[{"symbol":"XRP/USDT","bids":[{"price":0.51987,"qty":73.72633435}],"asks":[],"checksum":2614274462,"timestamp":"2024-06-01T22:43:45.418516Z"}]}
{"channel":"book","type":"update","data":[{"symbol":"XRP/USDT","bids":[],"asks":[{"price":0.52021,"qty":0.00000000},{"price":0.52064,"qty":76.02640463}],"checksum":737290342,"timestamp":"2024-06-01T22:43:49.120849Z"}]}
{"channel":"book","type":"update","data":[{"symbol":"XRP/USDT","bids":[],"asks":[{"price":0.52018,"qty":0.00000000},{"price":0.52065,"qty":2452.00000000}],"checksum":1975195016,"timestamp":"2024-06-01T22:43:49.125488Z"}]}
{"channel":"book","type":"update","data":[{"symbol":"XRP/USDT","bids":[],"asks":[{"price":0.52019,"qty":800.00000000}],"checksum":3963216884,"timestamp":"2024-06-01T22:43:49.125610Z"}]}
{"channel":"book","type":"update","data":[{"symbol":"XRP/USDT","bids":[],"asks":[{"price":0.52022,"qty":0.00000000},{"price":0.52065,"qty":2452.00000000}],"checksum":3533498355,"timestamp":"2024-06-01T22:43:49.125626Z"}]}
{"channel":"book","type":"update","data":[{"symbol":"XRP/USDT","bids":[],"asks":[{"price":0.52027,"qty":3000.00000000}],"checksum":247633736,"timestamp":"2024-06-01T22:43:49.125757Z"}]}
{"channel":"book","type":"update","data":[{"symbol":"XRP/USDT","bids":[],"asks":[{"price":0.52028,"qty":470.00000000}],"checksum":2941981048,"timestamp":"2024-06-01T22:43:49.128627Z"}]}
{"channel":"book","type":"update","data":[{"symbol":"XRP/USDT","bids":[],"asks":[{"price":0.52026,"qty":470.00000000}],"checksum":3540838215,"timestamp":"2024-06-01T22:43:49.128819Z"}]}
{"channel":"book","type":"update","data":[{"symbol":"XRP/USDT","bids":[],"asks":[{"price":0.52028,"qty":0.00000000},{"price":0.52049,"qty":2007.02973057}],"checksum":602915913,"timestamp":"2024-06-01T22:43:49.131211Z"}]}
{"channel":"book","type":"update","data":[{"symbol":"XRP/USDT","bids":[],"asks":[{"price":0.52024,"qty":3000.00000000}],"checksum":3137996503,"timestamp":"2024-06-01T22:43:49.212304Z"}]}
{"channel":"book","type":"update","data":[{"symbol":"XRP/USDT","bids":[],"asks":[{"price":0.52027,"qty":0.00000000},{"price":0.52049,"qty":2007.02973057}],"checksum":2754008071,"timestamp":"2024-06-01T22:43:49.216346Z"}]}
{"channel":"book","type":"update","data":[{"symbol":"XRP/USDT","bids":[],"asks":[{"price":0.52021,"qty":800.00000000}],"checksum":367815216,"timestamp":"2024-06-01T22:43:49.217398Z"}]}
{"channel":"book","type":"update","data":[{"symbol":"XRP/USDT","bids":[],"asks":[{"price":0.52019,"qty":0.00000000},{"price":0.52049,"qty":2007.02973057}],"checksum":2186560930,"timestamp":"2024-06-01T22:43:49.217419Z"}]}
{"channel":"book","type":"update","data":[{"symbol":"XRP/USDT","bids":[],"asks":[{"price":0.52026,"qty":0.00000000},{"price":0.52064,"qty":76.02640463}],"checksum":4214574572,"timestamp":"2024-06-01T22:43:49.219275Z"}]}
{"channel":"book","type":"update","data":[{"symbol":"XRP/USDT","bids":[],"asks":[{"price":0.52024,"qty":3470.00000000}],"checksum":2647818611,"timestamp":"2024-06-01T22:43:49.221037Z"}]}
{"channel":"book","type":"update","data":[{"symbol":"XRP/USDT","bids":[],"asks":[{"price":0.52029,"qty":0.00000000},{"price":0.52066,"qty":11946.75522345}],"checksum":2473773267,"timestamp":"2024-06-01T22:43:49.645352Z"}]}
{"channel":"book","type":"update","data":[{"symbol":"XRP/USDT","bids":[],"asks":[{"price":0.52024,"qty":470.00000000}],"checksum":1149711607,"timestamp":"2024-06-01T22:43:49.645432Z"}]}
{"channel":"book","type":"update","data":[{"symbol":"XRP/USDT","bids":[],"asks":[{"price":0.52021,"qty":0.00000000},{"price":0.52073,"qty":583.62764504}],"checksum":3589237395,"timestamp":"2024-06-01T22:43:49.645550Z"}]}
{"channel":"book","type":"update","data":[{"symbol":"XRP/USDT","bids":[{"price":0.51987,"qty":2525.72633435}],"asks":[],"checksum":301683160,"timestamp":"2024-06-01T22:43:49.645660Z"}]}
{"channel":"book","type":"update","data":[{"symbol":"XRP/USDT","bids":[],"asks":[{"price":0.52045,"qty":0.00000000},{"price":0.52074,"qty":1336.07806000}],"checksum":1204594568,"timestamp":"2024-06-01T22:43:49.646108Z"}]}
{"channel":"book","type":"update","data":[{"symbol":"XRP/USDT","bids":[],"asks":[{"price":0.52030,"qty":0.00000000},{"price":0.52075,"qty":1924.59852000}],"checksum":3573321340,"timestamp":"2024-06-01T22:43:49.647636Z"}]}
{"channel":"book","type":"update","data":[{"symbol":"XRP/USDT","bids":[],"asks":[{"price":0.52024,"qty":0.00000000},{"price":0.52079,"qty":23.85100935}],"checksum":2718306441,"timestamp":"2024-06-01T22:43:49.648427Z"}]}
{"channel":"book","type":"update","data":[{"symbol":"XRP/USDT","bids":[],"asks":[{"price":0.52073,"qty":3037.62764504}],"checksum":1761975282,"timestamp":"2024-06-01T22:43:49.648581Z"}]}
{"channel":"book","type":"update","data":[{"symbol":"XRP/USDT","bids":[],"asks":[{"price":0.52029,"qty":470.00000000}],"checksum":1440623862,"timestamp":"2024-06-01T22:43:49.648722Z"}]}
{"channel":"book","type":"update","data":[{"symbol":"XRP/USDT","bids":[],"asks":[{"price":0.52029,"qty":0.00000000},{"price":0.52079,"qty":23.85100935}],"checksum":1761975282,"timestamp":"2024-06-01T22:43:49.650842Z"}]}
{"channel":"book","type":"update","data":[{"symbol":"XRP/USDT","bids":[],"asks":[{"price":0.52035,"qty":470.00000000}],"checksum":1274158745,"timestamp":"2024-06-01T22:43:49.651092Z"}]}
{"channel":"book","type":"update","data":[{"symbol":"XRP/USDT","bids":[{"price":0.52008,"qty":0.00000000},{"price":0.51979,"qty":11209.98967880}],"asks":[],"checksum":3901862551,"timestamp":"2024-06-01T22:43:49.651303Z"}]}
{"channel":"book","type":"update","data":[{"symbol":"XRP/USDT","bids":[{"price":0.51986,"qty":0.00000000},{"price":0.51975,"qty":1924.59852000}],"asks":[],"checksum":3225335820,"timestamp":"2024-06-01T22:43:49.651387Z"}]}
{"channel":"book","type":"update","data":[{"symbol":"XRP/USDT","bids":[],"asks":[{"price":0.52074,"qty":0.00000000},{"price":0.52079,"qty":23.85100935}],"checksum":290672612,"timestamp":"2024-06-01T22:43:49.651411Z"}]}
{"channel":"book","type":"update","data":[{"symbol":"XRP/USDT","bids":[{"price":0.51975,"qty":0.00000000},{"price":0.51971,"qty":1955.01365000}],"asks":[],"checksum":4025669857,"timestamp":"2024-06-01T22:43:49.651434Z"}]}
{"channel":"book","type":"update","data":[{"symbol":"XRP/USDT","bids":[{"price":0.51971,"qty":0.00000000},{"price":0.51969,"qty":4210.28820000}],"asks":[],"checksum":2938379012,"timestamp":"2024-06-01T22:43:49.651939Z"}]}
