{"channel":"book","type":"snapshot","data":[{"symbol":"XRP/BTC","bids":[{"price":0.00000767,"qty":15935.64033809},{"price":0.00000766,"qty":55815.40600440},{"price":0.00000765,"qty":142063.43562625},{"price":0.00000764,"qty":7249.43337897},{"price":0.00000763,"qty":27919.38898111},{"price":0.00000762,"qty":17857.44309601},{"price":0.00000761,"qty":27340.23644103},{"price":0.00000760,"qty":29107.04926050},{"price":0.00000759,"qty":832.56506902},{"price":0.00000758,"qty":393262.77081764}],"asks":[{"price":0.00000768,"qty":16780.64930785},{"price":0.00000769,"qty":65559.24211769},{"price":0.00000770,"qty":138572.71463288},{"price":0.00000771,"qty":26814.75417692},{"price":0.00000773,"qty":44664.80774933},{"price":0.00000774,"qty":1000.00000000},{"price":0.00000775,"qty":9814.71986989},{"price":0.00000776,"qty":8097.49127549},{"price":0.00000777,"qty":212270.27131837},{"price":0.00000778,"qty":196.62250630}],"checksum":2544315213}]}
{"channel":"book","type":"update","data":[{"symbol":"XRP/BTC","bids":[],"asks":[{"price":0.00000769,"qty":57864.96418701}],"checksum":793114202,"timestamp":"2024-06-01T22:43:28.502196Z"}]}
{"channel":"book","type":"update","data":[{"symbol":"XRP/BTC","bids":[{"price":0.00000766,"qty":48121.12807372}],"asks":[],"checksum":1051568697,"timestamp":"2024-06-01T22:43:28.549525Z"}]}
{"channel":"book","type":"update","data":[{"symbol":"XRP/BTC","bids":[{"price":0.00000766,"qty":55815.40452279}],"asks":[],"checksum":2067060015,"timestamp":"2024-06-01T22:43:28.847245Z"}]}
{"channel":"book","type":"update","data":[{"symbol":"XRP/BTC","bids":[{"price":0.00000766,"qty":48121.12807372}],"asks":[],"checksum":1051568697,"timestamp":"2024-06-01T22:43:29.134547Z"}]}
{"channel":"book","type":"update","data":[{"symbol":"XRP/BTC","bids":[{"price":0.00000766,"qty":55815.40452280}],"asks":[],"checksum":2051456817,"timestamp":"2024-06-01T22:43:29.431078Z"}]}
{"channel":"book","type":"update","data":[{"symbol":"XRP/BTC","bids":[{"price":0.00000767,"qty":16801.53000622}],"asks":[],"checksum":3331848743,"timestamp":"2024-06-01T22:43:29.630054Z"}]}
{"channel":"book","type":"update","data":[{"symbol":"XRP/BTC","bids":[{"price":0.00000766,"qty":57448.38237240}],"asks":[],"checksum":3002634319,"timestamp":"2024-06-01T22:43:29.672750Z"}]}
{"channel":"book","type":"update","data":[{"symbol":"XRP/BTC","bids":[{"price":0.00000766,"qty":49754.10592332}],"asks":[],"checksum":3861601305,"timestamp":"2024-06-01T22:43:29.770189Z"}]}
{"channel":"book","type":"update","data":[{"symbol":"XRP/BTC","bids":[{"price":0.00000766,"qty":57448.13136526}],"asks":[],"checksum":2682625238,"timestamp":"2024-06-01T22:43:30.047696Z"}]}
{"channel":"book","type":"update","data":[{"symbol":"XRP/BTC","bids":[{"price":0.00000766,"qty":49754.10592332}],"asks":[],"checksum":3861601305,"timestamp":"2024-06-01T22:43:30.386118Z"}]}
{"channel":"book","type":"update","data":[{"symbol":"XRP/BTC","bids":[{"price":0.00000766,"qty":57448.01146045}],"asks":[],"checksum":1345517469,"timestamp":"2024-06-01T22:43:30.656097Z"}]}
{"channel":"book","type":"update","data":[{"symbol":"XRP/BTC","bids":[{"price":0.00000766,"qty":49754.10592332}],"asks":[],"checksum":3861601305,"timestamp":"2024-06-01T22:43:30.968668Z"}]}
{"channel":"book","type":"update","data":[{"symbol":"XRP/BTC","bids":[{"price":0.00000767,"qty":16687.39130643}],"asks":[],"checksum":449850274,"timestamp":"2024-06-01T22:43:31.514752Z"}]}
{"channel":"book","type":"update","data":[{"symbol":"XRP/BTC","bids":[{"price":0.00000766,"qty":49225.34327024}],"asks":[],"checksum":3264320971,"timestamp":"2024-06-01T22:43:31.514835Z"}]}
{"channel":"book","type":"update","data":[{"symbol":"XRP/BTC","bids":[{"price":0.00000766,"qty":49779.57655426}],"asks":[],"checksum":3495967289,"timestamp":"2024-06-01T22:43:31.519791Z"}]}
{"channel":"book","type":"update","data":[{"symbol":"XRP/BTC","bids":[{"price":0.00000767,"qty":16776.31576741}],"asks":[],"checksum":2129362399,"timestamp":"2024-06-01T22:43:31.519997Z"}]}
{"channel":"book","type":"update","data":[{"symbol":"XRP/BTC","bids":[],"asks":[{"price":0.00000770,"qty":146266.61938196}],"checksum":2031531182,"timestamp":"2024-06-01T22:43:31.629906Z"}]}
{"channel":"book","type":"update","data":[{"symbol":"XRP/BTC","bids":[{"price":0.00000766,"qty":57473.48130334}],"asks":[],"checksum":2186209511,"timestamp":"2024-06-01T22:43:31.672130Z"}]}
{"channel":"book","type":"update","data":[{"symbol":"XRP/BTC","bids":[],"asks":[{"price":0.00000770,"qty":138572.71463288}],"checksum":2243109270,"timestamp":"2024-06-01T22:43:31.920280Z"}]}
{"channel":"book","type":"update","data":[{"symbol":"XRP/BTC","bids":[{"price":0.00000766,"qty":49779.57655426}],"asks":[],"checksum":2129362399,"timestamp":"2024-06-01T22:43:32.004689Z"}]}
{"channel":"book","type":"update","data":[{"symbol":"XRP/BTC","bids":[],"asks":[{"price":0.00000770,"qty":146266.62134506}],"checksum":1136941429,"timestamp":"2024-06-01T22:43:32.810957Z"}]}
{"channel":"book","type":"update","data":[{"symbol":"XRP/BTC","bids":[{"price":0.00000766,"qty":57473.48326644}],"asks":[],"checksum":1027773300,"timestamp":"2024-06-01T22:43:32.847257Z"}]}
{"channel":"book","type":"update","data":[{"symbol":"XRP/BTC","bids":[],"asks":[{"price":0.00000770,"qty":138572.71463288}],"checksum":7190494,"timestamp":"2024-06-01T22:43:33.071118Z"}]}
{"channel":"book","type":"update","data":[{"symbol":"XRP/BTC","bids":[{"price":0.00000766,"qty":49779.57655426}],"asks":[],"checksum":2129362399,"timestamp":"2024-06-01T22:43:33.115045Z"}]}
{"channel":"book","type":"update","data":[{"symbol":"XRP/BTC","bids":[],"asks":[{"price":0.00000770,"qty":146266.62134506}],"checksum":1136941429,"timestamp":"2024-06-01T22:43:33.970102Z"}]}
{"channel":"book","type":"update","data":[{"symbol":"XRP/BTC","bids":[{"price":0.00000766,"qty":48146.59870466}],"asks":[],"checksum":3381079475,"timestamp":"2024-06-01T22:43:34.005263Z"}]}
{"channel":"book","type":"update","data":[{"symbol":"XRP/BTC","bids":[{"price":0.00000766,"qty":55840.50541684}],"asks":[],"checksum":1877741350,"timestamp":"2024-06-01T22:43:34.010379Z"}]}
{"channel":"book","type":"update","data":[{"symbol":"XRP/BTC","bids":[],"asks":[{"price":0.00000769,"qty":35776.08418701}],"checksum":4260793880,"timestamp":"2024-06-01T22:43:34.013195Z"}]}
{"channel":"book","type":"update","data":[{"symbol":"XRP/BTC","bids":[],"asks":[{"price":0.00000770,"qty":168355.50134506}],"checksum":1569294272,"timestamp":"2024-06-01T22:43:34.015831Z"}]}
{"channel":"book","type":"update","data":[{"symbol":"XRP/BTC","bids":[],"asks":[{"price":0.00000770,"qty":160661.59463288}],"checksum":1708901516,"timestamp":"2024-06-01T22:43:34.259370Z"}]}
{"channel":"book","type":"update","data":[{"symbol":"XRP/BTC","bids":[{"price":0.00000766,"qty":48146.59870466}],"asks":[],"checksum":3283150361,"timestamp":"2024-06-01T22:43:34.300123Z"}]}
{"channel":"book","type":"update","data":[{"symbol":"XRP/BTC","bids":[],"asks":[{"price":0.00000770,"qty":168355.50213069}],"checksum":491945645,"timestamp":"2024-06-01T22:43:35.160140Z"}]}
{"channel":"book","type":"update","data":[{"symbol":"XRP/BTC","bids":[{"price":0.00000766,"qty":49779.57655426}],"asks":[],"checksum":2534476395,"timestamp":"2024-06-01T22:43:35.200559Z"}]}
{"channel":"book","type":"update","data":[{"symbol":"XRP/BTC","bids":[{"price":0.00000766,"qty":57473.48405207}],"asks":[],"checksum":3320558315,"timestamp":"2024-06-01T22:43:35.209944Z"}]}
{"channel":"book","type":"update","data":[{"symbol":"XRP/BTC","bids":[],"asks":[{"price":0.00000770,"qty":160661.59463288}],"checksum":453585503,"timestamp":"2024-06-01T22:43:35.470578Z"}]}
{"channel":"book","type":"update","data":[{"symbol":"XRP/BTC","bids":[{"price":0.00000766,"qty":49779.57655426}],"asks":[],"checksum":1240699615,"timestamp":"2024-06-01T22:43:35.709320Z"}]}
{"channel":"book","type":"update","data":[{"symbol":"XRP/BTC","bids":[],"asks":[{"price":0.00000768,"qty":16610.73163727}],"checksum":2273646105,"timestamp":"2024-06-01T22:43:35.739857Z"}]}
{"channel":"book","type":"update","data":[{"symbol":"XRP/BTC","bids":[],"asks":[{"price":0.00000768,"qty":16649.22200220}],"checksum":4015127439,"timestamp":"2024-06-01T22:43:35.741912Z"}]}
{"channel":"book","type":"update","data":[{"symbol":"XRP/BTC","bids":[],"asks":[{"price":0.00000769,"qty":35963.83748080}],"checksum":1087669923,"timestamp":"2024-06-01T22:43:35.742065Z"}]}
{"channel":"book","type":"update","data":[{"symbol":"XRP/BTC","bids":[{"price":0.00000766,"qty":57473.48435721}],"asks":[],"checksum":1182442514,"timestamp":"2024-06-01T22:43:36.012573Z"}]}
{"channel":"book","type":"update","data":[{"symbol":"XRP/BTC","bids":[{"price":0.00000766,"qty":49779.57655426}],"asks":[],"checksum":1087669923,"timestamp":"2024-06-01T22:43:36.278210Z"}]}
{"channel":"book","type":"update","data":[{"symbol":"XRP/BTC","bids":[{"price":0.00000766,"qty":57473.47857717}],"asks":[],"checksum":1259238526,"timestamp":"2024-06-01T22:43:36.531564Z"}]}
{"channel":"book","type":"update","data":[{"symbol":"XRP/BTC","bids":[{"price":0.00000766,"qty":49779.57655426}],"asks":[],"checksum":1087669923,"timestamp":"2024-06-01T22:43:36.827219Z"}]}
{"channel":"book","type":"update","data":[{"symbol":"XRP/BTC","bids":[{"price":0.00000766,"qty":49225.34327024}],"asks":[],"checksum":1378167121,"timestamp":"2024-06-01T22:43:36.962896Z"}]}
{"channel":"book","type":"update","data":[{"symbol":"XRP/BTC","bids":[{"price":0.00000767,"qty":16687.39130643}],"asks":[],"checksum":4239290039,"timestamp":"2024-06-01T22:43:36.962909Z"}]}
{"channel":"book","type":"update","data":[{"symbol":"XRP/BTC","bids":[{"price":0.00000767,"qty":16851.96691148}],"asks":[],"checksum":4054055753,"timestamp":"2024-06-01T22:43:36.965220Z"}]}
{"channel":"book","type":"update","data":[{"symbol":"XRP/BTC","bids":[{"price":0.00000766,"qty":49627.83099769}],"asks":[],"checksum":1987639657,"timestamp":"2024-06-01T22:43:36.965346Z"}]}
{"channel":"book","type":"update","data":[{"symbol":"XRP/BTC","bids":[{"price":0.00000766,"qty":57321.69634453}],"asks":[],"checksum":2099818632,"timestamp":"2024-06-01T22:43:37.094178Z"}]}
{"channel":"book","type":"update","data":[{"symbol":"XRP/BTC","bids":[{"price":0.00000766,"qty":49627.83099769}],"asks":[],"checksum":1987639657,"timestamp":"2024-06-01T22:43:37.397739Z"}]}
{"channel":"book","type":"update","data":[{"symbol":"XRP/BTC","bids":[{"price":0.00000766,"qty":57321.69664967}],"asks":[],"checksum":870170812,"timestamp":"2024-06-01T22:43:37.695493Z"}]}
{"channel":"book","type":"update","data":[{"symbol":"XRP/BTC","bids":[{"price":0.00000765,"qty":136784.02772258}],"asks":[],"checksum":3608264326,"timestamp":"2024-06-01T22:43:37.976946Z"}]}
{"channel":"book","type":"update","data":[{"symbol":"XRP/BTC","bids":[{"price":0.00000766,"qty":49627.83099769}],"asks":[],"checksum":2461304659,"timestamp":"2024-06-01T22:43:38.005539Z"}]}
{"channel":"book","type":"update","data":[{"symbol":"XRP/BTC","bids":[{"price":0.00000765,"qty":142063.43562625}],"asks":[],"checksum":1987639657,"timestamp":"2024-06-01T22:43:38.098667Z"}]}
{"channel":"book","type":"update","data":[{"symbol":"XRP/BTC","bids":[{"price":0.00000766,"qty":57321.71595355}],"asks":[],"checksum":3554225963,"timestamp":"2024-06-01T22:43:38.273476Z"}]}
{"channel":"book","type":"update","data":[{"symbol":"XRP/BTC","bids":[{"price":0.00000766,"qty":49627.83099769}],"asks":[],"checksum":1987639657,"timestamp":"2024-06-01T22:43:38.581712Z"}]}
{"channel":"book","type":"update","data":[{"symbol":"XRP/BTC","bids":[],"asks":[{"price":0.00000770,"qty":168355.48019901}],"checksum":374581216,"timestamp":"2024-06-01T22:43:38.716345Z"}]}
{"channel":"book","type":"update","data":[{"symbol":"XRP/BTC","bids":[{"price":0.00000766,"qty":47822.72978063}],"asks":[],"checksum":2773598259,"timestamp":"2024-06-01T22:43:38.748091Z"}]}
{"channel":"book","type":"update","data":[{"symbol":"XRP/BTC","bids":[{"price":0.00000766,"qty":55516.61565190}],"asks":[],"checksum":3237720738,"timestamp":"2024-06-01T22:43:38.841393Z"}]}
{"channel":"book","type":"update","data":[{"symbol":"XRP/BTC","bids":[{"price":0.00000766,"qty":57321.71686896}],"asks":[],"checksum":719685761,"timestamp":"2024-06-01T22:43:38.855192Z"}]}
{"channel":"book","type":"update","data":[{"symbol":"XRP/BTC","bids":[],"asks":[{"price":0.00000770,"qty":160661.59463288}],"checksum":1255069192,"timestamp":"2024-06-01T22:43:38.979562Z"}]}
{"channel":"book","type":"update","data":[{"symbol":"XRP/BTC","bids":[{"price":0.00000766,"qty":49627.83099769}],"asks":[],"checksum":1987639657,"timestamp":"2024-06-01T22:43:39.147199Z"}]}
{"channel":"book","type":"update","data":[{"symbol":"XRP/BTC","bids":[],"asks":[{"price":0.00000769,"qty":34249.33342876}],"checksum":2273998141,"timestamp":"2024-06-01T22:43:39.564660Z"}]}
{"channel":"book","type":"update","data":[{"symbol":"XRP/BTC","bids":[{"price":0.00000767,"qty":16687.39130643}],"asks":[],"checksum":2324160707,"timestamp":"2024-06-01T22:43:39.643335Z"}]}
{"channel":"book","type":"update","data":[{"symbol":"XRP/BTC","bids":[{"price":0.00000766,"qty":49225.34327024}],"asks":[],"checksum":224191203,"timestamp":"2024-06-01T22:43:39.643347Z"}]}
{"channel":"book","type":"update","data":[{"symbol":"XRP/BTC","bids":[{"price":0.00000767,"qty":16776.31576741}],"asks":[],"checksum":2748818693,"timestamp":"2024-06-01T22:43:39.648084Z"}]}
{"channel":"book","type":"update","data":[{"symbol":"XRP/BTC","bids":[{"price":0.00000766,"qty":49804.76897626}],"asks":[],"checksum":4202564064,"timestamp":"2024-06-01T22:43:39.648128Z"}]}
{"channel":"book","type":"update","data":[{"symbol":"XRP/BTC","bids":[],"asks":[{"price":0.00000769,"qty":35963.83748080}],"checksum":193758644,"timestamp":"2024-06-01T22:43:39.664880Z"}]}
{"channel":"book","type":"update","data":[{"symbol":"XRP/BTC","bids":[],"asks":[{"price":0.00000770,"qty":168355.48050415}],"checksum":2720228528,"timestamp":"2024-06-01T22:43:39.999966Z"}]}
{"channel":"book","type":"update","data":[{"symbol":"XRP/BTC","bids":[{"price":0.00000766,"qty":57498.65484753}],"asks":[],"checksum":1614052261,"timestamp":"2024-06-01T22:43:40.036826Z"}]}
{"channel":"book","type":"update","data":[{"symbol":"XRP/BTC","bids":[],"asks":[{"price":0.00000770,"qty":160661.59463288}],"checksum":3382418081,"timestamp":"2024-06-01T22:43:40.282655Z"}]}
{"channel":"book","type":"update","data":[{"symbol":"XRP/BTC","bids":[{"price":0.00000766,"qty":49804.76897626}],"asks":[],"checksum":193758644,"timestamp":"2024-06-01T22:43:40.364287Z"}]}
{"channel":"book","type":"update","data":[{"symbol":"XRP/BTC","bids":[{"price":0.00000766,"qty":48171.79112666}],"asks":[],"checksum":3728419640,"timestamp":"2024-06-01T22:43:40.970682Z"}]}
{"channel":"book","type":"update","data":[{"symbol":"XRP/BTC","bids":[{"price":0.00000760,"qty":9864.43819943}],"asks":[],"checksum":2999108983,"timestamp":"2024-06-01T22:43:41.021170Z"}]}
{"channel":"book","type":"update","data":[{"symbol":"XRP/BTC","bids":[{"price":0.00000759,"qty":20074.82261297}],"asks":[],"checksum":3925030451,"timestamp":"2024-06-01T22:43:41.061526Z"}]}
{"channel":"book","type":"update","data":[{"symbol":"XRP/BTC","bids":[],"asks":[{"price":0.00000770,"qty":168355.48180908}],"checksum":2811528523,"timestamp":"2024-06-01T22:43:41.234613Z"}]}
{"channel":"book","type":"update","data":[{"symbol":"XRP/BTC","bids":[{"price":0.00000766,"qty":55865.67830285}],"asks":[],"checksum":226630031,"timestamp":"2024-06-01T22:43:41.277426Z"}]}
{"channel":"book","type":"update","data":[{"symbol":"XRP/BTC","bids":[{"price":0.00000766,"qty":48171.79112666}],"asks":[],"checksum":2811528523,"timestamp":"2024-06-01T22:43:41.533673Z"}]}
{"channel":"book","type":"update","data":[{"symbol":"XRP/BTC","bids":[],"asks":[{"price":0.00000770,"qty":160661.59463288}],"checksum":3925030451,"timestamp":"2024-06-01T22:43:41.771899Z"}]}
{"channel":"book","type":"update","data":[{"symbol":"XRP/BTC","bids":[],"asks":[{"price":0.00000770,"qty":168355.48032768}],"checksum":395892091,"timestamp":"2024-06-01T22:43:42.600179Z"}]}
{"channel":"book","type":"update","data":[{"symbol":"XRP/BTC","bids":[{"price":0.00000766,"qty":55865.67682146}],"asks":[],"checksum":268276074,"timestamp":"2024-06-01T22:43:42.642380Z"}]}
{"channel":"book","type":"update","data":[{"symbol":"XRP/BTC","bids":[],"asks":[{"price":0.00000770,"qty":160661.59463288}],"checksum":4053168674,"timestamp":"2024-06-01T22:43:42.898988Z"}]}
{"channel":"book","type":"update","data":[{"symbol":"XRP/BTC","bids":[{"price":0.00000766,"qty":48171.79112666}],"asks":[],"checksum":3925030451,"timestamp":"2024-06-01T22:43:42.941339Z"}]}
{"channel":"book","type":"update","data":[{"symbol":"XRP/BTC","bids":[],"asks":[{"price":0.00000770,"qty":168355.47819165}],"checksum":3036803229,"timestamp":"2024-06-01T22:43:43.812887Z"}]}
{"channel":"book","type":"update","data":[{"symbol":"XRP/BTC","bids":[{"price":0.00000766,"qty":55865.67468542}],"asks":[],"checksum":1159926597,"timestamp":"2024-06-01T22:43:43.844048Z"}]}
{"channel":"book","type":"update","data":[{"symbol":"XRP/BTC","bids":[],"asks":[{"price":0.00000768,"qty":16610.73163727}],"checksum":1546121689,"timestamp":"2024-06-01T22:43:43.923716Z"}]}
{"channel":"book","type":"update","data":[{"symbol":"XRP/BTC","bids":[],"asks":[{"price":0.00000769,"qty":35776.08418701}],"checksum":1850742855,"timestamp":"2024-06-01T22:43:43.923738Z"}]}
{"channel":"book","type":"update","data":[{"symbol":"XRP/BTC","bids":[],"asks":[{"price":0.00000769,"qty":36002.28434988}],"checksum":1112203291,"timestamp":"2024-06-01T22:43:43.924605Z"}]}
{"channel":"book","type":"update","data":[{"symbol":"XRP/BTC","bids":[],"asks":[{"price":0.00000770,"qty":160661.59463288}],"checksum":515385013,"timestamp":"2024-06-01T22:43:44.092230Z"}]}
{"channel":"book","type":"update","data":[{"symbol":"XRP/BTC","bids":[{"price":0.00000766,"qty":48171.79112666}],"asks":[],"checksum":4003120493,"timestamp":"2024-06-01T22:43:44.135237Z"}]}
{"channel":"book","type":"update","data":[{"symbol":"XRP/BTC","bids":[{"price":0.00000766,"qty":49804.76897626}],"asks":[],"checksum":172080584,"timestamp":"2024-06-01T22:43:44.147570Z"}]}
{"channel":"book","type":"update","data":[{"symbol":"XRP/BTC","bids":[],"asks":[{"price":0.00000770,"qty":168355.47819165}],"checksum":1454603110,"timestamp":"2024-06-01T22:43:44.991556Z"}]}
{"channel":"book","type":"update","data":[{"symbol":"XRP/BTC","bids":[{"price":0.00000766,"qty":57498.65253502}],"asks":[],"checksum":3268220243,"timestamp":"2024-06-01T22:43:45.042113Z"}]}
{"channel":"book","type":"update","data":[{"symbol":"XRP/BTC","bids":[],"asks":[{"price":0.00000770,"qty":160661.59463288}],"checksum":2654983165,"timestamp":"2024-06-01T22:43:45.253961Z"}]}
{"channel":"book","type":"update","data":[{"symbol":"XRP/BTC","bids":[{"price":0.00000767,"qty":16687.39130643}],"asks":[],"checksum":3623362551,"timestamp":"2024-06-01T22:43:45.260595Z"}]}
{"channel":"book","type":"update","data":[{"symbol":"XRP/BTC","bids":[{"price":0.00000766,"qty":56919.22682900}],"asks":[],"checksum":4159849204,"timestamp":"2024-06-01T22:43:45.260634Z"}]}
{"channel":"book","type":"update","data":[{"symbol":"XRP/BTC","bids":[{"price":0.00000766,"qty":57421.99355147}],"asks":[],"checksum":4153071121,"timestamp":"2024-06-01T22:43:45.262879Z"}]}
{"channel":"book","type":"update","data":[{"symbol":"XRP/BTC","bids":[{"price":0.00000767,"qty":16877.14747145}],"asks":[],"checksum":2603228109,"timestamp":"2024-06-01T22:43:45.262936Z"}]}
{"channel":"book","type":"update","data":[{"symbol":"XRP/BTC","bids":[{"price":0.00000766,"qty":49728.10999271}],"asks":[],"checksum":2295878186,"timestamp":"2024-06-01T22:43:45.298567Z"}]}
{"channel":"book","type":"update","data":[{"symbol":"XRP/BTC","bids":[{"price":0.00000759,"qty":832.56506902}],"asks":[],"checksum":4127423901,"timestamp":"2024-06-01T22:43:45.517439Z"}]}
{"channel":"book","type":"update","data":[{"symbol":"XRP/BTC","bids":[{"price":0.00000760,"qty":29105.81872558}],"asks":[],"checksum":611220750,"timestamp":"2024-06-01T22:43:45.557465Z"}]}
{"channel":"book","type":"update","data":[{"symbol":"XRP/BTC","bids":[],"asks":[{"price":0.00000770,"qty":168355.47819165}],"checksum":1707268021,"timestamp":"2024-06-01T22:43:46.165652Z"}]}
{"channel":"book","type":"update","data":[{"symbol":"XRP/BTC","bids":[{"price":0.00000766,"qty":57421.99355148}],"asks":[],"checksum":610403053,"timestamp":"2024-06-01T22:43:46.200157Z"}]}
{"channel":"book","type":"update","data":[{"symbol":"XRP/BTC","bids":[],"asks":[{"price":0.00000770,"qty":160661.59463288}],"checksum":1708042326,"timestamp":"2024-06-01T22:43:46.443997Z"}]}
{"channel":"book","type":"update","data":[{"symbol":"XRP/BTC","bids":[{"price":0.00000766,"qty":49728.10999271}],"asks":[],"checksum":611220750,"timestamp":"2024-06-01T22:43:46.491378Z"}]}
{"channel":"book","type":"update","data":[{"symbol":"XRP/BTC","bids":[{"price":0.00000766,"qty":57421.99355148}],"asks":[],"checksum":1708042326,"timestamp":"2024-06-01T22:43:46.787197Z"}]}
{"channel":"book","type":"update","data":[{"symbol":"XRP/BTC","bids":[{"price":0.00000766,"qty":49728.10999271}],"asks":[],"checksum":611220750,"timestamp":"2024-06-01T22:43:47.054947Z"}]}
{"channel":"book","type":"update","data":[{"symbol":"XRP/BTC","bids":[{"price":0.00000766,"qty":48472.90999271}],"asks":[],"checksum":1473823907,"timestamp":"2024-06-01T22:43:47.163437Z"}]}
{"channel":"book","type":"update","data":[{"symbol":"XRP/BTC","bids":[{"price":0.00000765,"qty":107340.54562625}],"asks":[],"checksum":793767798,"timestamp":"2024-06-01T22:43:47.165197Z"}]}
{"channel":"book","type":"update","data":[{"symbol":"XRP/BTC","bids":[],"asks":[{"price":0.00000770,"qty":124058.26463288}],"checksum":4165860491,"timestamp":"2024-06-01T22:43:47.166640Z"}]}
{"channel":"book","type":"update","data":[{"symbol":"XRP/BTC","bids":[],"asks":[{"price":0.00000769,"qty":35061.59434988}],"checksum":2406811524,"timestamp":"2024-06-01T22:43:47.191806Z"}]}
{"channel":"book","type":"update","data":[{"symbol":"XRP/BTC","bids":[{"price":0.00000766,"qty":56166.79355148}],"asks":[],"checksum":3837657235,"timestamp":"2024-06-01T22:43:47.342750Z"}]}
{"channel":"book","type":"update","data":[{"symbol":"XRP/BTC","bids":[{"price":0.00000766,"qty":48472.90999271}],"asks":[],"checksum":2406811524,"timestamp":"2024-06-01T22:43:47.672827Z"}]}
{"channel":"book","type":"update","data":[{"symbol":"XRP/BTC","bids":[{"price":0.00000766,"qty":56166.79355147}],"asks":[],"checksum":1003447507,"timestamp":"2024-06-01T22:43:47.953358Z"}]}
{"channel":"book","type":"update","data":[{"symbol":"XRP/BTC","bids":[{"price":0.00000766,"qty":55664.02682900}],"asks":[],"checksum":3265138462,"timestamp":"2024-06-01T22:43:48.011159Z"}]}
{"channel":"book","type":"update","data":[{"symbol":"XRP/BTC","bids":[{"price":0.00000767,"qty":16687.39130643}],"asks":[],"checksum":1690713674,"timestamp":"2024-06-01T22:43:48.011207Z"}]}
{"channel":"book","type":"update","data":[{"symbol":"XRP/BTC","bids":[{"price":0.00000767,"qty":16927.57187143}],"asks":[],"checksum":4246612320,"timestamp":"2024-06-01T22:43:48.015979Z"}]}
{"channel":"book","type":"update","data":[{"symbol":"XRP/BTC","bids":[{"price":0.00000766,"qty":56065.84626635}],"asks":[],"checksum":4159524358,"timestamp":"2024-06-01T22:43:48.016231Z"}]}
{"channel":"book","type":"update","data":[{"symbol":"XRP/BTC","bids":[{"price":0.00000765,"qty":140551.17562625}],"asks":[],"checksum":124585916,"timestamp":"2024-06-01T22:43:48.220611Z"}]}
{"channel":"book","type":"update","data":[{"symbol":"XRP/BTC","bids":[],"asks":[{"price":0.00000770,"qty":159312.89463288}],"checksum":1161972251,"timestamp":"2024-06-01T22:43:48.220677Z"}]}
{"channel":"book","type":"update","data":[{"symbol":"XRP/BTC","bids":[{"price":0.00000766,"qty":57380.43626635}],"asks":[],"checksum":3415508018,"timestamp":"2024-06-01T22:43:48.233551Z"}]}
{"channel":"book","type":"update","data":[{"symbol":"XRP/BTC","bids":[{"price":0.00000766,"qty":49686.55270759}],"asks":[],"checksum":1907302882,"timestamp":"2024-06-01T22:43:48.257764Z"}]}
{"channel":"book","type":"update","data":[{"symbol":"XRP/BTC","bids":[],"asks":[{"price":0.00000769,"qty":35968.14434988}],"checksum":3819123485,"timestamp":"2024-06-01T22:43:48.264457Z"}]}
{"channel":"book","type":"update","data":[{"symbol":"XRP/BTC","bids":[{"price":0.00000766,"qty":57380.43626636}],"asks":[],"checksum":228100504,"timestamp":"2024-06-01T22:43:48.545170Z"}]}
{"channel":"book","type":"update","data":[{"symbol":"XRP/BTC","bids":[{"price":0.00000766,"qty":49686.55270759}],"asks":[],"checksum":3819123485,"timestamp":"2024-06-01T22:43:48.855197Z"}]}
{"channel":"book","type":"update","data":[{"symbol":"XRP/BTC","bids":[{"price":0.00000766,"qty":57380.43626635}],"asks":[],"checksum":1503172301,"timestamp":"2024-06-01T22:43:49.118944Z"}]}
{"channel":"book","type":"update","data":[{"symbol":"XRP/BTC","bids":[{"price":0.00000766,"qty":49686.55270759}],"asks":[],"checksum":3819123485,"timestamp":"2024-06-01T22:43:49.412823Z"}]}
{"channel":"book","type":"update","data":[{"symbol":"XRP/BTC","bids":[{"price":0.00000767,"qty":65036.52195599}],"asks":[],"checksum":3759221161,"timestamp":"2024-06-01T22:43:49.653675Z"}]}
{"channel":"book","type":"update","data":[{"symbol":"XRP/BTC","bids":[{"price":0.00000767,"qty":69036.52195599}],"asks":[],"checksum":3334388975,"timestamp":"2024-06-01T22:43:49.660988Z"}]}
{"channel":"book","type":"update","data":[{"symbol":"XRP/BTC","bids":[{"price":0.00000766,"qty":57380.13093464}],"asks":[],"checksum":660003616,"timestamp":"2024-06-01T22:43:49.694735Z"}]}
{"channel":"book","type":"update","data":[{"symbol":"XRP/BTC","bids":[{"price":0.00000766,"qty":53380.13093464}],"asks":[],"checksum":819336052,"timestamp":"2024-06-01T22:43:49.699506Z"}]}
{"channel":"book","type":"update","data":[{"symbol":"XRP/BTC","bids":[],"asks":[{"price":0.00000768,"qty":16484.47455613}],"checksum":2084146591,"timestamp":"2024-06-01T22:43:49.820226Z"}]}
{"channel":"book","type":"update","data":[{"symbol":"XRP/BTC","bids":[],"asks":[{"price":0.00000768,"qty":17349.99868044}],"checksum":992375580,"timestamp":"2024-06-01T22:43:49.896852Z"}]}
{"channel":"book","type":"update","data":[{"symbol":"XRP/BTC","bids":[{"price":0.00000766,"qty":45686.55270759}],"asks":[],"checksum":4124017787,"timestamp":"2024-06-01T22:43:49.971800Z"}]}
{"channel":"book","type":"update","data":[{"symbol":"XRP/BTC","bids":[{"price":0.00000765,"qty":118462.29562625}],"asks":[],"checksum":3375512743,"timestamp":"2024-06-01T22:43:50.017643Z"}]}
{"channel":"book","type":"update","data":[{"symbol":"XRP/BTC","bids":[{"price":0.00000766,"qty":67775.43270759}],"asks":[],"checksum":510879812,"timestamp":"2024-06-01T22:43:50.020838Z"}]}
{"channel":"book","type":"update","data":[{"symbol":"XRP/BTC","bids":[{"price":0.00000766,"qty":75467.16419805}],"asks":[],"checksum":1015855789,"timestamp":"2024-06-01T22:43:50.237469Z"}]}
{"channel":"book","type":"update","data":[{"symbol":"XRP/BTC","bids":[{"price":0.00000760,"qty":9864.43819943}],"asks":[],"checksum":2743314762,"timestamp":"2024-06-01T22:43:50.483342Z"}]}
{"channel":"book","type":"update","data":[{"symbol":"XRP/BTC","bids":[{"price":0.00000766,"qty":67775.43270759}],"asks":[],"checksum":1581775356,"timestamp":"2024-06-01T22:43:50.526240Z"}]}
{"channel":"book","type":"update","data":[{"symbol":"XRP/BTC","bids":[{"price":0.00000766,"qty":75467.10182907}],"asks":[],"checksum":3196641879,"timestamp":"2024-06-01T22:43:50.812883Z"}]}
{"channel":"book","type":"update","data":[{"symbol":"XRP/BTC","bids":[],"asks":[{"price":0.00000768,"qty":16934.00750042}],"checksum":1135752516,"timestamp":"2024-06-01T22:43:50.823920Z"}]}
{"channel":"book","type":"update","data":[{"symbol":"XRP/BTC","bids":[],"asks":[{"price":0.00000769,"qty":36384.13552990}],"checksum":2138221481,"timestamp":"2024-06-01T22:43:50.925516Z"}]}
{"channel":"book","type":"update","data":[{"symbol":"XRP/BTC","bids":[{"price":0.00000766,"qty":67775.43270759}],"asks":[],"checksum":2680008706,"timestamp":"2024-06-01T22:43:51.106148Z"}]}
{"channel":"book","type":"update","data":[{"symbol":"XRP/BTC","bids":[{"price":0.00000766,"qty":66142.45485799}],"asks":[],"checksum":291849230,"timestamp":"2024-06-01T22:43:51.276337Z"}]}
{"channel":"book","type":"update","data":[{"symbol":"XRP/BTC","bids":[{"price":0.00000766,"qty":73834.11928646}],"asks":[],"checksum":2064619785,"timestamp":"2024-06-01T22:43:51.386852Z"}]}
{"channel":"book","type":"update","data":[{"symbol":"XRP/BTC","bids":[{"price":0.00000766,"qty":73418.12810644}],"asks":[],"checksum":1313137462,"timestamp":"2024-06-01T22:43:51.588796Z"}]}
{"channel":"book","type":"update","data":[{"symbol":"XRP/BTC","bids":[{"price":0.00000766,"qty":75051.10595604}],"asks":[],"checksum":2375537859,"timestamp":"2024-06-01T22:43:51.648009Z"}]}
{"channel":"book","type":"update","data":[{"symbol":"XRP/BTC","bids":[{"price":0.00000766,"qty":67359.44152757}],"asks":[],"checksum":1760578366,"timestamp":"2024-06-01T22:43:51.659245Z"}]}
{"channel":"book","type":"update","data":[{"symbol":"XRP/BTC","bids":[{"price":0.00000767,"qty":69452.51313601}],"asks":[],"checksum":2547012645,"timestamp":"2024-06-01T22:43:51.689154Z"}]}
{"channel":"book","type":"update","data":[{"symbol":"XRP/BTC","bids":[{"price":0.00000766,"qty":75051.09638019}],"asks":[],"checksum":1731997621,"timestamp":"2024-06-01T22:43:51.951490Z"}]}
{"channel":"book","type":"update","data":[{"symbol":"XRP/BTC","bids":[],"asks":[{"price":0.00000769,"qty":36157.93536703}],"checksum":4050668098,"timestamp":"2024-06-01T22:43:52.005245Z"}]}
{"channel":"book","type":"update","data":[{"symbol":"XRP/BTC","bids":[{"price":0.00000766,"qty":67359.44152757}],"asks":[],"checksum":27013586,"timestamp":"2024-06-01T22:43:52.250148Z"}]}
{"channel":"book","type":"update","data":[{"symbol":"XRP/BTC","bids":[{"price":0.00000766,"qty":75051.09335353}],"asks":[],"checksum":396835457,"timestamp":"2024-06-01T22:43:52.541759Z"}]}
{"channel":"book","type":"update","data":[{"symbol":"XRP/BTC","bids":[{"price":0.00000766,"qty":67359.44152757}],"asks":[],"checksum":27013586,"timestamp":"2024-06-01T22:43:52.815668Z"}]}
{"channel":"book","type":"update","data":[{"symbol":"XRP/BTC","bids":[{"price":0.00000766,"qty":75051.10036246}],"asks":[],"checksum":3874653734,"timestamp":"2024-06-01T22:43:53.106876Z"}]}
{"channel":"book","type":"update","data":[{"symbol":"XRP/BTC","bids":[{"price":0.00000766,"qty":67359.44152757}],"asks":[],"checksum":27013586,"timestamp":"2024-06-01T22:43:53.391649Z"}]}
{"channel":"book","type":"update","data":[{"symbol":"XRP/BTC","bids":[{"price":0.00000767,"qty":69212.33257101}],"asks":[],"checksum":1326065563,"timestamp":"2024-06-01T22:43:53.589796Z"}]}
{"channel":"book","type":"update","data":[{"symbol":"XRP/BTC","bids":[{"price":0.00000766,"qty":66957.62209022}],"asks":[],"checksum":707076346,"timestamp":"2024-06-01T22:43:53.590023Z"}]}
{"channel":"book","type":"update","data":[{"symbol":"XRP/BTC","bids":[{"price":0.00000767,"qty":69770.60769472}],"asks":[],"checksum":782220562,"timestamp":"2024-06-01T22:43:53.595947Z"}]}
{"channel":"book","type":"update","data":[{"symbol":"XRP/BTC","bids":[{"price":0.00000766,"qty":74649.27944473}],"asks":[],"checksum":1356872465,"timestamp":"2024-06-01T22:43:53.721173Z"}]}
{"channel":"book","type":"update","data":[{"symbol":"XRP/BTC","bids":[{"price":0.00000766,"qty":66957.62209022}],"asks":[],"checksum":782220562,"timestamp":"2024-06-01T22:43:53.975422Z"}]}
{"channel":"book","type":"update","data":[{"symbol":"XRP/BTC","bids":[{"price":0.00000766,"qty":74649.27769920}],"asks":[],"checksum":636321243,"timestamp":"2024-06-01T22:43:54.265512Z"}]}
{"channel":"book","type":"update","data":[{"symbol":"XRP/BTC","bids":[{"price":0.00000766,"qty":66957.62209022}],"asks":[],"checksum":782220562,"timestamp":"2024-06-01T22:43:54.557839Z"}]}
{"channel":"book","type":"update","data":[{"symbol":"XRP/BTC","bids":[],"asks":[{"price":0.00000770,"qty":167004.54320819}],"checksum":1625669003,"timestamp":"2024-06-01T22:43:54.714282Z"}]}
{"channel":"book","type":"update","data":[{"symbol":"XRP/BTC","bids":[],"asks":[{"price":0.00000769,"qty":36421.62827391}],"checksum":1091304652,"timestamp":"2024-06-01T22:43:54.739817Z"}]}
{"channel":"book","type":"update","data":[{"symbol":"XRP/BTC","bids":[{"price":0.00000766,"qty":74649.27066553}],"asks":[],"checksum":1903512574,"timestamp":"2024-06-01T22:43:54.834272Z"}]}
{"channel":"book","type":"update","data":[{"symbol":"XRP/BTC","bids":[],"asks":[{"price":0.00000770,"qty":159312.89463288}],"checksum":1057966951,"timestamp":"2024-06-01T22:43:55.000645Z"}]}
{"channel":"book","type":"update","data":[{"symbol":"XRP/BTC","bids":[{"price":0.00000766,"qty":66957.62209022}],"asks":[],"checksum":259128405,"timestamp":"2024-06-01T22:43:55.132676Z"}]}
{"channel":"book","type":"update","data":[{"symbol":"XRP/BTC","bids":[],"asks":[{"price":0.00000770,"qty":124058.26463288}],"checksum":2460235644,"timestamp":"2024-06-01T22:43:55.573134Z"}]}
{"channel":"book","type":"update","data":[{"symbol":"XRP/BTC","bids":[{"price":0.00000765,"qty":85251.66562625}],"asks":[],"checksum":410282622,"timestamp":"2024-06-01T22:43:55.573252Z"}]}
