{"channel":"book","type":"snapshot","data":[{"symbol":"XRP/EUR","bids":[{"price":0.47916,"qty":1146.47250443},{"price":0.47915,"qty":1069.63590637},{"price":0.47911,"qty":9619.34814271},{"price":0.47909,"qty":11289.44268378},{"price":0.47907,"qty":1069.60242095},{"price":0.47902,"qty":1718.19785542},{"price":0.47900,"qty":88.69507014},{"price":0.47899,"qty":4748.59159921},{"price":0.47898,"qty":19243.88791199},{"price":0.47896,"qty":3011.74580865}],"asks":[{"price":0.47917,"qty":9618.30832123},{"price":0.47919,"qty":651.58070679},{"price":0.47921,"qty":9617.56534675},{"price":0.47925,"qty":15.61864759},{"price":0.47928,"qty":7050.00000000},{"price":0.47929,"qty":9615.82508217},{"price":0.47934,"qty":1594.00653543},{"price":0.47940,"qty":71.34719134},{"price":0.47941,"qty":9615.00000000},{"price":0.47942,"qty":3612.35526608}],"checksum":3622006929}]}
{"channel":"book","type":"update","data":[{"symbol":"XRP/EUR","bids":[],"asks":[{"price":0.47940,"qty":0.00000000},{"price":0.47943,"qty":19714.27419596}],"checksum":2018123819,"timestamp":"2024-06-01T22:43:27.515981Z"}]}
{"channel":"book","type":"update","data":[{"symbol":"XRP/EUR","bids":[],"asks":[{"price":0.47940,"qty":104.20401776}],"checksum":2667621120,"timestamp":"2024-06-01T22:43:27.516691Z"}]}
{"channel":"book","type":"update","data":[{"symbol":"XRP/EUR","bids":[],"asks":[{"price":0.47941,"qty":0.00000000},{"price":0.47943,"qty":19714.27419596}],"checksum":4186253303,"timestamp":"2024-06-01T22:43:29.599832Z"}]}
{"channel":"book","type":"update","data":[{"symbol":"XRP/EUR","bids":[],"asks":[{"price":0.47919,"qty":0.00000000},{"price":0.47945,"qty":21871.66882122}],"checksum":2645506742,"timestamp":"2024-06-01T22:43:29.603139Z"}]}
{"channel":"book","type":"update","data":[{"symbol":"XRP/EUR","bids":[{"price":0.47911,"qty":0.00000000},{"price":0.47894,"qty":133.79680000}],"asks":[],"checksum":762898601,"timestamp":"2024-06-01T22:43:29.606961Z"}]}
{"channel":"book","type":"update","data":[{"symbol":"XRP/EUR","bids":[{"price":0.47908,"qty":3011.74580865}],"asks":[],"checksum":935821694,"timestamp":"2024-06-01T22:43:29.609202Z"}]}
{"channel":"book","type":"update","data":[{"symbol":"XRP/EUR","bids":[{"price":0.47912,"qty":9619.23133147}],"asks":[],"checksum":3990688975,"timestamp":"2024-06-01T22:43:29.611627Z"}]}
{"channel":"book","type":"update","data":[{"symbol":"XRP/EUR","bids":[],"asks":[{"price":0.47925,"qty":0.00000000},{"price":0.47948,"qty":1262.70000000}],"checksum":89974480,"timestamp":"2024-06-01T22:43:29.627178Z"}]}
{"channel":"book","type":"update","data":[{"symbol":"XRP/EUR","bids":[{"price":0.47915,"qty":2269.63590637}],"asks":[],"checksum":3814552243,"timestamp":"2024-06-01T22:43:29.639947Z"}]}
{"channel":"book","type":"update","data":[{"symbol":"XRP/EUR","bids":[],"asks":[{"price":0.47928,"qty":7701.53991203}],"checksum":4270609010,"timestamp":"2024-06-01T22:43:29.649793Z"}]}
{"channel":"book","type":"update","data":[{"symbol":"XRP/EUR","bids":[],"asks":[{"price":0.47928,"qty":7050.00000000}],"checksum":3814552243,"timestamp":"2024-06-01T22:43:29.653624Z"}]}
{"channel":"book","type":"update","data":[{"symbol":"XRP/EUR","bids":[],"asks":[{"price":0.47929,"qty":10267.36499420}],"checksum":3184854137,"timestamp":"2024-06-01T22:43:29.668282Z"}]}
{"channel":"book","type":"update","data":[{"symbol":"XRP/EUR","bids":[{"price":0.47915,"qty":1069.63590637}],"asks":[],"checksum":1540657178,"timestamp":"2024-06-01T22:43:29.698956Z"}]}
{"channel":"book","type":"update","data":[{"symbol":"XRP/EUR","bids":[{"price":0.47916,"qty":2346.47250443}],"asks":[],"checksum":1540879336,"timestamp":"2024-06-01T22:43:29.699002Z"}]}
{"channel":"book","type":"update","data":[{"symbol":"XRP/EUR","bids":[{"price":0.47909,"qty":1669.60586866}],"asks":[],"checksum":4284421869,"timestamp":"2024-06-01T22:43:29.708151Z"}]}
{"channel":"book","type":"update","data":[{"symbol":"XRP/EUR","bids":[],"asks":[{"price":0.47917,"qty":0.00000000},{"price":0.47950,"qty":9615.00000000}],"checksum":1327835356,"timestamp":"2024-06-01T22:43:29.708269Z"}]}
{"channel":"book","type":"update","data":[{"symbol":"XRP/EUR","bids":[],"asks":[{"price":0.47921,"qty":0.00000000},{"price":0.47952,"qty":3846.00000000}],"checksum":1610351551,"timestamp":"2024-06-01T22:43:29.708401Z"}]}
{"channel":"book","type":"update","data":[{"symbol":"XRP/EUR","bids":[{"price":0.47899,"qty":138.89977536}],"asks":[],"checksum":840877265,"timestamp":"2024-06-01T22:43:29.711546Z"}]}
{"channel":"book","type":"update","data":[{"symbol":"XRP/EUR","bids":[{"price":0.47916,"qty":1146.47250443}],"asks":[],"checksum":3876505683,"timestamp":"2024-06-01T22:43:29.711644Z"}]}
{"channel":"book","type":"update","data":[{"symbol":"XRP/EUR","bids":[{"price":0.47917,"qty":1200.00000000}],"asks":[],"checksum":3818041107,"timestamp":"2024-06-01T22:43:29.711720Z"}]}
{"channel":"book","type":"update","data":[{"symbol":"XRP/EUR","bids":[],"asks":[{"price":0.47943,"qty":0.00000000},{"price":0.47959,"qty":2007.02973057},{"price":0.47958,"qty":19714.27419596}],"checksum":3540945507,"timestamp":"2024-06-01T22:43:29.711939Z"}]}
{"channel":"book","type":"update","data":[{"symbol":"XRP/EUR","bids":[{"price":0.47916,"qty":1069.56893763},{"price":0.47917,"qty":1276.92064528}],"asks":[],"checksum":3080284292,"timestamp":"2024-06-01T22:43:29.712617Z"}]}
{"channel":"book","type":"update","data":[{"symbol":"XRP/EUR","bids":[{"price":0.47906,"qty":19240.67216377}],"asks":[],"checksum":2604290104,"timestamp":"2024-06-01T22:43:29.714995Z"}]}
{"channel":"book","type":"update","data":[{"symbol":"XRP/EUR","bids":[{"price":0.47914,"qty":9618.74243385}],"asks":[],"checksum":510389750,"timestamp":"2024-06-01T22:43:29.715016Z"}]}
{"channel":"book","type":"update","data":[{"symbol":"XRP/EUR","bids":[{"price":0.47917,"qty":1200.00000000},{"price":0.47918,"qty":76.91904002}],"asks":[],"checksum":2103155713,"timestamp":"2024-06-01T22:43:29.717580Z"}]}
{"channel":"book","type":"update","data":[{"symbol":"XRP/EUR","bids":[{"price":0.47914,"qty":0.00000000},{"price":0.47902,"qty":1718.19785542}],"asks":[],"checksum":1236320414,"timestamp":"2024-06-01T22:43:29.719212Z"}]}
{"channel":"book","type":"update","data":[{"symbol":"XRP/EUR","bids":[{"price":0.47919,"qty":1069.52429646}],"asks":[],"checksum":1297340371,"timestamp":"2024-06-01T22:43:29.719681Z"}]}
{"channel":"book","type":"update","data":[{"symbol":"XRP/EUR","bids":[{"price":0.47918,"qty":0.00000000},{"price":0.47902,"qty":1718.19785542},{"price":0.47920,"qty":76.91582971}],"asks":[],"checksum":564770000,"timestamp":"2024-06-01T22:43:29.723408Z"}]}
{"channel":"book","type":"update","data":[{"symbol":"XRP/EUR","bids":[],"asks":[{"price":0.47928,"qty":7065.61864759}],"checksum":3231974119,"timestamp":"2024-06-01T22:43:29.749688Z"}]}
{"channel":"book","type":"update","data":[{"symbol":"XRP/EUR","bids":[],"asks":[{"price":0.47929,"qty":9615.82508217}],"checksum":575771795,"timestamp":"2024-06-01T22:43:29.754557Z"}]}
{"channel":"book","type":"update","data":[{"symbol":"XRP/EUR","bids":[{"price":0.47927,"qty":1069.40155245}],"asks":[],"checksum":394005203,"timestamp":"2024-06-01T22:43:29.757281Z"}]}
{"channel":"book","type":"update","data":[{"symbol":"XRP/EUR","bids":[{"price":0.47915,"qty":0.00000000},{"price":0.47906,"qty":19240.67216377}],"asks":[],"checksum":1684694958,"timestamp":"2024-06-01T22:43:29.757440Z"}]}
{"channel":"book","type":"update","data":[{"symbol":"XRP/EUR","bids":[{"price":0.47913,"qty":4911.62517620}],"asks":[],"checksum":1566701589,"timestamp":"2024-06-01T22:43:29.761024Z"}]}
{"channel":"book","type":"update","data":[{"symbol":"XRP/EUR","bids":[{"price":0.47924,"qty":1069.40155245}],"asks":[],"checksum":1108530877,"timestamp":"2024-06-01T22:43:29.761595Z"}]}
{"channel":"book","type":"update","data":[{"symbol":"XRP/EUR","bids":[{"price":0.47927,"qty":0.00000000},{"price":0.47907,"qty":1069.60242095}],"asks":[],"checksum":2011060600,"timestamp":"2024-06-01T22:43:29.763943Z"}]}
{"channel":"book","type":"update","data":[{"symbol":"XRP/EUR","bids":[],"asks":[{"price":0.47929,"qty":10267.26302965}],"checksum":2592087558,"timestamp":"2024-06-01T22:43:29.764198Z"}]}
{"channel":"book","type":"update","data":[{"symbol":"XRP/EUR","bids":[{"price":0.47909,"qty":0.00000000},{"price":0.47906,"qty":19240.67216377}],"asks":[],"checksum":3312294495,"timestamp":"2024-06-01T22:43:29.767790Z"}]}
{"channel":"book","type":"update","data":[{"symbol":"XRP/EUR","bids":[{"price":0.47920,"qty":0.00000000},{"price":0.47902,"qty":1718.19785542},{"price":0.47925,"qty":76.90780511}],"asks":[],"checksum":565096756,"timestamp":"2024-06-01T22:43:29.768515Z"}]}
{"channel":"book","type":"update","data":[{"symbol":"XRP/EUR","bids":[{"price":0.47917,"qty":2869.18783579}],"asks":[],"checksum":416626827,"timestamp":"2024-06-01T22:43:29.770220Z"}]}
{"channel":"book","type":"update","data":[{"symbol":"XRP/EUR","bids":[{"price":0.47924,"qty":0.00000000},{"price":0.47902,"qty":1718.19785542}],"asks":[],"checksum":4041600456,"timestamp":"2024-06-01T22:43:29.777476Z"}]}
{"channel":"book","type":"update","data":[{"symbol":"XRP/EUR","bids":[{"price":0.47925,"qty":0.00000000},{"price":0.47900,"qty":88.69507014},{"price":0.47920,"qty":76.91582971}],"asks":[],"checksum":2076587822,"timestamp":"2024-06-01T22:43:29.781010Z"}]}
{"channel":"book","type":"update","data":[{"symbol":"XRP/EUR","bids":[{"price":0.47920,"qty":1146.31738216}],"asks":[],"checksum":3573921661,"timestamp":"2024-06-01T22:43:29.786410Z"}]}
{"channel":"book","type":"update","data":[{"symbol":"XRP/EUR","bids":[{"price":0.47920,"qty":1069.40155245},{"price":0.47921,"qty":76.91422466}],"asks":[],"checksum":1832369529,"timestamp":"2024-06-01T22:43:29.789771Z"}]}
{"channel":"book","type":"update","data":[{"symbol":"XRP/EUR","bids":[],"asks":[{"price":0.47927,"qty":821.30000000}],"checksum":1589875419,"timestamp":"2024-06-01T22:43:29.839009Z"}]}
{"channel":"book","type":"update","data":[{"symbol":"XRP/EUR","bids":[],"asks":[{"price":0.47927,"qty":2821.30000000}],"checksum":1360066907,"timestamp":"2024-06-01T22:43:29.844018Z"}]}
{"channel":"book","type":"update","data":[{"symbol":"XRP/EUR","bids":[{"price":0.47914,"qty":9618.72224145}],"asks":[],"checksum":2854028604,"timestamp":"2024-06-01T22:43:29.845354Z"}]}
{"channel":"book","type":"update","data":[{"symbol":"XRP/EUR","bids":[],"asks":[{"price":0.47922,"qty":9617.22967245}],"checksum":4219246076,"timestamp":"2024-06-01T22:43:29.845410Z"}]}
{"channel":"book","type":"update","data":[{"symbol":"XRP/EUR","bids":[],"asks":[{"price":0.47949,"qty":19714.27419596}],"checksum":3646755112,"timestamp":"2024-06-01T22:43:29.848498Z"}]}
{"channel":"book","type":"update","data":[{"symbol":"XRP/EUR","bids":[{"price":0.47914,"qty":0.00000000},{"price":0.47906,"qty":19240.67216377}],"asks":[],"checksum":1270443314,"timestamp":"2024-06-01T22:43:29.948662Z"}]}
{"channel":"book","type":"update","data":[{"symbol":"XRP/EUR","bids":[{"price":0.47915,"qty":9618.59051218}],"asks":[],"checksum":2629654305,"timestamp":"2024-06-01T22:43:29.952548Z"}]}
{"channel":"book","type":"update","data":[{"symbol":"XRP/EUR","bids":[],"asks":[{"price":0.47924,"qty":9616.91827795}],"checksum":1617662782,"timestamp":"2024-06-01T22:43:29.952565Z"}]}
{"channel":"book","type":"update","data":[{"symbol":"XRP/EUR","bids":[],"asks":[{"price":0.47944,"qty":19714.27419596}],"checksum":896239827,"timestamp":"2024-06-01T22:43:29.955632Z"}]}
{"channel":"book","type":"update","data":[{"symbol":"XRP/EUR","bids":[],"asks":[{"price":0.47927,"qty":821.30000000}],"checksum":2406622566,"timestamp":"2024-06-01T22:43:29.957540Z"}]}
{"channel":"book","type":"update","data":[{"symbol":"XRP/EUR","bids":[],"asks":[{"price":0.47928,"qty":7050.00000000}],"checksum":1518575060,"timestamp":"2024-06-01T22:43:30.030728Z"}]}
{"channel":"book","type":"update","data":[{"symbol":"XRP/EUR","bids":[],"asks":[{"price":0.47930,"qty":15.61864759}],"checksum":3782009527,"timestamp":"2024-06-01T22:43:30.149025Z"}]}
{"channel":"book","type":"update","data":[{"symbol":"XRP/EUR","bids":[],"asks":[{"price":0.47927,"qty":0.00000000},{"price":0.47945,"qty":21871.66882122}],"checksum":800642122,"timestamp":"2024-06-01T22:43:30.176398Z"}]}
{"channel":"book","type":"update","data":[{"symbol":"XRP/EUR","bids":[{"price":0.47915,"qty":0.00000000},{"price":0.47906,"qty":19240.67216377}],"asks":[],"checksum":2439696481,"timestamp":"2024-06-01T22:43:30.208678Z"}]}
{"channel":"book","type":"update","data":[{"symbol":"XRP/EUR","bids":[{"price":0.47916,"qty":10687.99407219}],"asks":[],"checksum":457491798,"timestamp":"2024-06-01T22:43:30.212371Z"}]}
{"channel":"book","type":"update","data":[{"symbol":"XRP/EUR","bids":[],"asks":[{"price":0.47940,"qty":0.00000000},{"price":0.47948,"qty":1262.70000000}],"checksum":187288948,"timestamp":"2024-06-01T22:43:30.319903Z"}]}
{"channel":"book","type":"update","data":[{"symbol":"XRP/EUR","bids":[],"asks":[{"price":0.47943,"qty":101.85710158}],"checksum":1206652005,"timestamp":"2024-06-01T22:43:30.321062Z"}]}
{"channel":"book","type":"update","data":[{"symbol":"XRP/EUR","bids":[{"price":0.47921,"qty":0.00000000},{"price":0.47904,"qty":1718.12612037},{"price":0.47920,"qty":0.00000000},{"price":0.47899,"qty":38.49036493},{"price":0.47919,"qty":0.00000000},{"price":0.47898,"qty":19243.88791199},{"price":0.47917,"qty":2646.19127886}],"asks":[],"checksum":2021039858,"timestamp":"2024-06-01T22:43:30.381654Z"}]}
{"channel":"book","type":"update","data":[{"symbol":"XRP/EUR","bids":[{"price":0.47921,"qty":76.91422466}],"asks":[],"checksum":4005301948,"timestamp":"2024-06-01T22:43:30.384989Z"}]}
{"channel":"book","type":"update","data":[{"symbol":"XRP/EUR","bids":[],"asks":[{"price":0.47922,"qty":0.00000000},{"price":0.47948,"qty":1262.70000000}],"checksum":1912536837,"timestamp":"2024-06-01T22:43:30.386254Z"}]}
{"channel":"book","type":"update","data":[{"symbol":"XRP/EUR","bids":[{"price":0.47917,"qty":977.00344307}],"asks":[],"checksum":2791325870,"timestamp":"2024-06-01T22:43:30.387366Z"}]}
{"channel":"book","type":"update","data":[{"symbol":"XRP/EUR","bids":[{"price":0.47921,"qty":0.00000000},{"price":0.47898,"qty":19243.88791199},{"price":0.47918,"qty":76.91813216}],"asks":[],"checksum":1081771809,"timestamp":"2024-06-01T22:43:30.388002Z"}]}
{"channel":"book","type":"update","data":[{"symbol":"XRP/EUR","bids":[],"asks":[{"price":0.47944,"qty":0.00000000},{"price":0.47950,"qty":9615.00000000},{"price":0.47949,"qty":19714.27419596}],"checksum":3400942794,"timestamp":"2024-06-01T22:43:30.389555Z"}]}
{"channel":"book","type":"update","data":[{"symbol":"XRP/EUR","bids":[],"asks":[{"price":0.47923,"qty":1373.83180820}],"checksum":891731958,"timestamp":"2024-06-01T22:43:30.389922Z"}]}
{"channel":"book","type":"update","data":[{"symbol":"XRP/EUR","bids":[],"asks":[{"price":0.47923,"qty":10990.86079977}],"checksum":2056883022,"timestamp":"2024-06-01T22:43:30.392136Z"}]}
{"channel":"book","type":"update","data":[{"symbol":"XRP/EUR","bids":[],"asks":[{"price":0.47923,"qty":1373.83180820}],"checksum":891731958,"timestamp":"2024-06-01T22:43:30.396466Z"}]}
{"channel":"book","type":"update","data":[{"symbol":"XRP/EUR","bids":[],"asks":[{"price":0.47944,"qty":19714.27419596}],"checksum":731329927,"timestamp":"2024-06-01T22:43:30.486603Z"}]}
{"channel":"book","type":"update","data":[{"symbol":"XRP/EUR","bids":[],"asks":[{"price":0.47923,"qty":2207.53180820}],"checksum":2923401069,"timestamp":"2024-06-01T22:43:30.490422Z"}]}
{"channel":"book","type":"update","data":[{"symbol":"XRP/EUR","bids":[{"price":0.47916,"qty":1069.56893763}],"asks":[],"checksum":1129151115,"timestamp":"2024-06-01T22:43:30.569910Z"}]}
{"channel":"book","type":"update","data":[{"symbol":"XRP/EUR","bids":[],"asks":[{"price":0.47921,"qty":9617.53846802}],"checksum":2797476346,"timestamp":"2024-06-01T22:43:30.573902Z"}]}
{"channel":"book","type":"update","data":[{"symbol":"XRP/EUR","bids":[{"price":0.47915,"qty":9618.52075106}],"asks":[],"checksum":1206490117,"timestamp":"2024-06-01T22:43:30.574032Z"}]}
{"channel":"book","type":"update","data":[{"symbol":"XRP/EUR","bids":[{"price":0.47918,"qty":0.00000000},{"price":0.47899,"qty":38.49036493}],"asks":[],"checksum":282175266,"timestamp":"2024-06-01T22:43:30.654080Z"}]}
{"channel":"book","type":"update","data":[{"symbol":"XRP/EUR","bids":[],"asks":[{"price":0.47941,"qty":77.82598747}],"checksum":2043915422,"timestamp":"2024-06-01T22:43:30.654390Z"}]}
{"channel":"book","type":"update","data":[{"symbol":"XRP/EUR","bids":[{"price":0.47918,"qty":507.18498859}],"asks":[],"checksum":2680137536,"timestamp":"2024-06-01T22:43:30.659496Z"}]}
{"channel":"book","type":"update","data":[{"symbol":"XRP/EUR","bids":[{"price":0.47912,"qty":10084.85784665}],"asks":[],"checksum":3667997602,"timestamp":"2024-06-01T22:43:30.664538Z"}]}
{"channel":"book","type":"update","data":[{"symbol":"XRP/EUR","bids":[],"asks":[{"price":0.47921,"qty":0.00000000},{"price":0.47944,"qty":19714.27419596}],"checksum":2547256522,"timestamp":"2024-06-01T22:43:30.709852Z"}]}
{"channel":"book","type":"update","data":[{"symbol":"XRP/EUR","bids":[],"asks":[{"price":0.47920,"qty":9617.64361553}],"checksum":269358399,"timestamp":"2024-06-01T22:43:30.714411Z"}]}
{"channel":"book","type":"update","data":[{"symbol":"XRP/EUR","bids":[{"price":0.47915,"qty":0.00000000},{"price":0.47899,"qty":38.49036493}],"asks":[],"checksum":3402043116,"timestamp":"2024-06-01T22:43:31.103032Z"}]}
{"channel":"book","type":"update","data":[{"symbol":"XRP/EUR","bids":[{"price":0.47914,"qty":9618.77443939}],"asks":[],"checksum":1531896468,"timestamp":"2024-06-01T22:43:31.106974Z"}]}
{"channel":"book","type":"update","data":[{"symbol":"XRP/EUR","bids":[],"asks":[{"price":0.47923,"qty":1373.83180820}],"checksum":2932304615,"timestamp":"2024-06-01T22:43:31.242664Z"}]}
{"channel":"book","type":"update","data":[{"symbol":"XRP/EUR","bids":[],"asks":[{"price":0.47920,"qty":0.00000000},{"price":0.47944,"qty":19714.27419596}],"checksum":1497121163,"timestamp":"2024-06-01T22:43:31.709999Z"}]}
{"channel":"book","type":"update","data":[{"symbol":"XRP/EUR","bids":[{"price":0.47904,"qty":0.00000000},{"price":0.47899,"qty":38.49036493}],"asks":[],"checksum":1218171424,"timestamp":"2024-06-01T22:43:32.402798Z"}]}
{"channel":"book","type":"update","data":[{"symbol":"XRP/EUR","bids":[{"price":0.47899,"qty":1756.79583415}],"asks":[],"checksum":3841326848,"timestamp":"2024-06-01T22:43:32.541507Z"}]}
{"channel":"book","type":"update","data":[{"symbol":"XRP/EUR","bids":[],"asks":[{"price":0.47943,"qty":0.00000000},{"price":0.47945,"qty":21871.66882122}],"checksum":3652226645,"timestamp":"2024-06-01T22:43:33.015150Z"}]}
{"channel":"book","type":"update","data":[{"symbol":"XRP/EUR","bids":[],"asks":[{"price":0.47943,"qty":207.46832934}],"checksum":3287036637,"timestamp":"2024-06-01T22:43:33.016230Z"}]}
{"channel":"book","type":"update","data":[{"symbol":"XRP/EUR","bids":[{"price":0.47914,"qty":0.00000000},{"price":0.47898,"qty":19243.88791199}],"asks":[],"checksum":3868543884,"timestamp":"2024-06-01T22:43:34.715667Z"}]}
{"channel":"book","type":"update","data":[{"symbol":"XRP/EUR","bids":[{"price":0.47913,"qty":14530.54119593}],"asks":[],"checksum":337142539,"timestamp":"2024-06-01T22:43:34.719511Z"}]}
{"channel":"book","type":"update","data":[{"symbol":"XRP/EUR","bids":[{"price":0.47908,"qty":0.00000000},{"price":0.47894,"qty":133.79680000}],"asks":[],"checksum":147344106,"timestamp":"2024-06-01T22:43:35.144210Z"}]}
{"channel":"book","type":"update","data":[{"symbol":"XRP/EUR","bids":[{"price":0.47899,"qty":1718.30546922}],"asks":[],"checksum":3950884520,"timestamp":"2024-06-01T22:43:35.406356Z"}]}
{"channel":"book","type":"update","data":[{"symbol":"XRP/EUR","bids":[{"price":0.47905,"qty":3011.74580865}],"asks":[],"checksum":3309850241,"timestamp":"2024-06-01T22:43:35.517197Z"}]}
{"channel":"book","type":"update","data":[{"symbol":"XRP/EUR","bids":[],"asks":[{"price":0.47934,"qty":0.00000000},{"price":0.47945,"qty":21871.66882122}],"checksum":2741449239,"timestamp":"2024-06-01T22:43:36.010916Z"}]}
{"channel":"book","type":"update","data":[{"symbol":"XRP/EUR","bids":[],"asks":[{"price":0.47928,"qty":5050.00000000}],"checksum":239132462,"timestamp":"2024-06-01T22:43:36.011257Z"}]}
{"channel":"book","type":"update","data":[{"symbol":"XRP/EUR","bids":[],"asks":[{"price":0.47928,"qty":0.00000000},{"price":0.47948,"qty":1262.70000000}],"checksum":3153218675,"timestamp":"2024-06-01T22:43:36.011389Z"}]}
{"channel":"book","type":"update","data":[{"symbol":"XRP/EUR","bids":[],"asks":[{"price":0.47930,"qty":0.00000000},{"price":0.47950,"qty":9615.00000000}],"checksum":1850019713,"timestamp":"2024-06-01T22:43:36.037533Z"}]}
{"channel":"book","type":"update","data":[{"symbol":"XRP/EUR","bids":[{"price":0.47913,"qty":4911.62517620}],"asks":[],"checksum":3954786089,"timestamp":"2024-06-01T22:43:36.125454Z"}]}
{"channel":"book","type":"update","data":[{"symbol":"XRP/EUR","bids":[],"asks":[{"price":0.47934,"qty":1594.00653543}],"checksum":3988832582,"timestamp":"2024-06-01T22:43:36.130081Z"}]}
{"channel":"book","type":"update","data":[{"symbol":"XRP/EUR","bids":[],"asks":[{"price":0.47931,"qty":5050.00000000}],"checksum":2300581112,"timestamp":"2024-06-01T22:43:36.130114Z"}]}
{"channel":"book","type":"update","data":[{"symbol":"XRP/EUR","bids":[{"price":0.47915,"qty":9618.57422670}],"asks":[],"checksum":437155350,"timestamp":"2024-06-01T22:43:36.130215Z"}]}
{"channel":"book","type":"update","data":[{"symbol":"XRP/EUR","bids":[],"asks":[{"price":0.47934,"qty":1609.62518302}],"checksum":1574423457,"timestamp":"2024-06-01T22:43:36.156370Z"}]}
{"channel":"book","type":"update","data":[{"symbol":"XRP/EUR","bids":[{"price":0.47899,"qty":2032.92171282}],"asks":[],"checksum":598367364,"timestamp":"2024-06-01T22:43:37.871531Z"}]}
