{"table":"orderBookL2_25","action":"insert","data":[{"symbol":"XBTUSDT","id":32402490187,"side":"Sell","size":375000,"price":66809.7,"timestamp":"2024-05-18T15:46:09.303Z"},{"symbol":"XBTUSDT","id":32402242406,"side":"Sell","size":138000,"price":66822.2,"timestamp":"2024-05-18T15:46:09.303Z"},{"symbol":"XBTUSDT","id":32402490192,"side":"Sell","size":20000,"price":66809.6,"timestamp":"2024-05-18T15:46:09.303Z"},{"symbol":"XBTUSDT","id":32402490213,"side":"Buy","size":8000,"price":66788.3,"timestamp":"2024-05-18T15:46:09.303Z"},{"symbol":"XBTUSDT","id":32402490215,"side":"Buy","size":351000,"price":66775.1,"timestamp":"2024-05-18T15:46:09.303Z"}]}
{"table":"orderBookL2_25","action":"delete","data":[{"symbol":"XBTUSDT","id":32402489956,"side":"Sell","price":66808.5,"timestamp":"2024-05-18T15:46:09.352Z"},{"symbol":"XBTUSDT","id":32402242406,"side":"Sell","price":66822.2,"timestamp":"2024-05-18T15:46:09.352Z"},{"symbol":"XBTUSDT","id":32402471671,"side":"Sell","price":66821.7,"timestamp":"2024-05-18T15:46:09.352Z"},{"symbol":"XBTUSDT","id":32402490215,"side":"Buy","price":66775.1,"timestamp":"2024-05-18T15:46:09.352Z"}]}
{"table":"orderBookL2_25","action":"update","data":[{"symbol":"XBTUSDT","id":32402490187,"side":"Sell","size":20000,"price":66809.7,"timestamp":"2024-05-18T15:46:09.352Z"}]}
{"table":"orderBookL2_25","action":"insert","data":[{"symbol":"XBTUSDT","id":32402490241,"side":"Sell","size":209000,"price":66808.3,"timestamp":"2024-05-18T15:46:09.352Z"},{"symbol":"XBTUSDT","id":32402490243,"side":"Sell","size":15000,"price":66809.5,"timestamp":"2024-05-18T15:46:09.352Z"},{"symbol":"XBTUSDT","id":32402490236,"side":"Sell","size":347000,"price":66808.4,"timestamp":"2024-05-18T15:46:09.352Z"},{"symbol":"XBTUSDT","id":32402490234,"side":"Buy","size":370000,"price":66772.7,"timestamp":"2024-05-18T15:46:09.352Z"}]}
{"table":"orderBookL2_25","action":"delete","data":[{"symbol":"XBTUSDT","id":32402489767,"side":"Sell","price":66805.2,"timestamp":"2024-05-18T15:46:09.401Z"},{"symbol":"XBTUSDT","id":32402489787,"side":"Sell","price":66805.1,"timestamp":"2024-05-18T15:46:09.401Z"},{"symbol":"XBTUSDT","id":32402489843,"side":"Buy","price":66788.2,"timestamp":"2024-05-18T15:46:09.401Z"}]}
{"table":"orderBookL2_25","action":"insert","data":[{"symbol":"XBTUSDT","id":32402471671,"side":"Sell","size":74000,"price":66821.7,"timestamp":"2024-05-18T15:46:09.401Z"},{"symbol":"XBTUSDT","id":32402490315,"side":"Sell","size":155000,"price":66805.0,"timestamp":"2024-05-18T15:46:09.401Z"},{"symbol":"XBTUSDT","id":32402363228,"side":"Buy","size":1502000,"price":66766.1,"timestamp":"2024-05-18T15:46:09.401Z"}]}
{"table":"orderBookL2_25","action":"delete","data":[{"symbol":"XBTUSDT","id":32402363228,"side":"Buy","price":66766.1,"timestamp":"2024-05-18T15:46:09.712Z"}]}
{"table":"orderBookL2_25","action":"insert","data":[{"symbol":"XBTUSDT","id":32402490547,"side":"Buy","size":225000,"price":66772.8,"timestamp":"2024-05-18T15:46:09.712Z"}]}
{"table":"orderBookL2_25","action":"delete","data":[{"symbol":"XBTUSDT","id":32402489893,"side":"Sell","price":66815.9,"timestamp":"2024-05-18T15:46:09.825Z"}]}
{"table":"orderBookL2_25","action":"update","data":[{"symbol":"XBTUSDT","id":32402461579,"side":"Sell","size":101000,"price":66815.7,"timestamp":"2024-05-18T15:46:09.825Z"}]}
{"table":"orderBookL2_25","action":"insert","data":[{"symbol":"XBTUSDT","id":32402242406,"side":"Sell","size":138000,"price":66822.2,"timestamp":"2024-05-18T15:46:09.825Z"}]}
{"table":"orderBookL2_25","action":"delete","data":[{"symbol":"ETHUSDT","id":32402490178,"side":"Buy","price":3109.36,"timestamp":"2024-05-18T15:46:09.826Z"}]}
{"table":"orderBookL2_25","action":"insert","data":[{"symbol":"ETHUSDT","id":32402490638,"side":"Buy","size":1000,"price":3109.38,"timestamp":"2024-05-18T15:46:09.826Z"}]}
{"table":"orderBookL2_25","action":"delete","data":[{"symbol":"XBTUSDT","id":32402490187,"side":"Sell","price":66809.7,"timestamp":"2024-05-18T15:46:09.875Z"},{"symbol":"XBTUSDT","id":32402490173,"side":"Sell","price":66815.8,"timestamp":"2024-05-18T15:46:09.875Z"},{"symbol":"XBTUSDT","id":32402489414,"side":"Buy","price":66780.7,"timestamp":"2024-05-18T15:46:09.875Z"}]}
{"table":"orderBookL2_25","action":"update","data":[{"symbol":"XBTUSDT","id":32402490243,"side":"Sell","size":35000,"price":66809.5,"timestamp":"2024-05-18T15:46:09.875Z"},{"symbol":"XBTUSDT","id":32402489763,"side":"Buy","size":40000,"price":66780.9,"timestamp":"2024-05-18T15:46:09.875Z"}]}
{"table":"orderBookL2_25","action":"insert","data":[{"symbol":"XBTUSDT","id":32402455289,"side":"Sell","size":22000,"price":66822.3,"timestamp":"2024-05-18T15:46:09.875Z"},{"symbol":"XBTUSDT","id":32402490640,"side":"Sell","size":67000,"price":66815.6,"timestamp":"2024-05-18T15:46:09.875Z"},{"symbol":"XBTUSDT","id":32402363228,"side":"Buy","size":1502000,"price":66766.1,"timestamp":"2024-05-18T15:46:09.875Z"}]}
{"table":"orderBookL2_25","action":"delete","data":[{"symbol":"ETHUSDT","id":32402461791,"side":"Sell","price":3112.06,"timestamp":"2024-05-18T15:46:09.875Z"},{"symbol":"ETHUSDT","id":32402490190,"side":"Buy","price":3109.61,"timestamp":"2024-05-18T15:46:09.875Z"}]}
{"table":"orderBookL2_25","action":"update","data":[{"symbol":"ETHUSDT","id":32402489313,"side":"Sell","size":66000,"price":3110.88,"timestamp":"2024-05-18T15:46:09.875Z"}]}
{"table":"orderBookL2_25","action":"insert","data":[{"symbol":"ETHUSDT","id":32402490651,"side":"Sell","size":32000,"price":3110.86,"timestamp":"2024-05-18T15:46:09.875Z"},{"symbol":"ETHUSDT","id":32402490643,"side":"Buy","size":32000,"price":3109.63,"timestamp":"2024-05-18T15:46:09.875Z"}]}
{"table":"orderBookL2_25","action":"delete","data":[{"symbol":"XBTUSDT","id":32402455289,"side":"Sell","price":66822.3,"timestamp":"2024-05-18T15:46:09.924Z"},{"symbol":"XBTUSDT","id":32402490236,"side":"Sell","price":66808.4,"timestamp":"2024-05-18T15:46:09.924Z"},{"symbol":"XBTUSDT","id":32402490241,"side":"Sell","price":66808.3,"timestamp":"2024-05-18T15:46:09.924Z"},{"symbol":"XBTUSDT","id":32402363228,"side":"Buy","price":66766.1,"timestamp":"2024-05-18T15:46:09.924Z"}]}
{"table":"orderBookL2_25","action":"update","data":[{"symbol":"XBTUSDT","id":32402490243,"side":"Sell","size":20000,"price":66809.5,"timestamp":"2024-05-18T15:46:09.924Z"}]}
{"table":"orderBookL2_25","action":"insert","data":[{"symbol":"XBTUSDT","id":32402490718,"side":"Sell","size":349000,"price":66809.4,"timestamp":"2024-05-18T15:46:09.924Z"},{"symbol":"XBTUSDT","id":32402490729,"side":"Sell","size":67000,"price":66805.2,"timestamp":"2024-05-18T15:46:09.924Z"},{"symbol":"XBTUSDT","id":32402490733,"side":"Sell","size":217000,"price":66808.6,"timestamp":"2024-05-18T15:46:09.924Z"},{"symbol":"XBTUSDT","id":32402490740,"side":"Buy","size":155000,"price":66766.3,"timestamp":"2024-05-18T15:46:09.924Z"}]}
{"table":"orderBookL2_25","action":"delete","data":[{"symbol":"XBTUSDT","id":32402489427,"side":"Sell","price":66807.3,"timestamp":"2024-05-18T15:46:09.973Z"},{"symbol":"XBTUSDT","id":32402489186,"side":"Sell","price":66807.5,"timestamp":"2024-05-18T15:46:09.973Z"},{"symbol":"XBTUSDT","id":32402490234,"side":"Buy","price":66772.7,"timestamp":"2024-05-18T15:46:09.973Z"},{"symbol":"XBTUSDT","id":32402490547,"side":"Buy","price":66772.8,"timestamp":"2024-05-18T15:46:09.973Z"}]}
{"table":"orderBookL2_25","action":"insert","data":[{"symbol":"XBTUSDT","id":32402474116,"side":"Sell","size":102000,"price":66824.2,"timestamp":"2024-05-18T15:46:09.973Z"},{"symbol":"XBTUSDT","id":32402455289,"side":"Sell","size":22000,"price":66822.3,"timestamp":"2024-05-18T15:46:09.973Z"},{"symbol":"XBTUSDT","id":32402490808,"side":"Buy","size":100000,"price":66788.2,"timestamp":"2024-05-18T15:46:09.973Z"},{"symbol":"XBTUSDT","id":32402490782,"side":"Buy","size":348000,"price":66775.1,"timestamp":"2024-05-18T15:46:09.973Z"}]}
{"table":"orderBookL2_25","action":"delete","data":[{"symbol":"XBTUSDT","id":32402489089,"side":"Buy","price":66787.9,"timestamp":"2024-05-18T15:46:10.022Z"}]}
{"table":"orderBookL2_25","action":"update","data":[{"symbol":"XBTUSDT","id":32402479097,"side":"Sell","size":4000,"price":66815.5,"timestamp":"2024-05-18T15:46:10.022Z"},{"symbol":"XBTUSDT","id":32402490640,"side":"Sell","size":1000,"price":66815.6,"timestamp":"2024-05-18T15:46:10.022Z"},{"symbol":"XBTUSDT","id":32402462668,"side":"Sell","size":320000,"price":66801.9,"timestamp":"2024-05-18T15:46:10.022Z"},{"symbol":"XBTUSDT","id":32402461579,"side":"Sell","size":100000,"price":66815.7,"timestamp":"2024-05-18T15:46:10.022Z"},{"symbol":"XBTUSDT","id":32402474116,"side":"Sell","size":102000,"price":66824.2,"timestamp":"2024-05-18T15:46:10.022Z"},{"symbol":"XBTUSDT","id":32402490808,"side":"Buy","size":108000,"price":66788.2,"timestamp":"2024-05-18T15:46:10.022Z"}]}
{"table":"orderBookL2_25","action":"insert","data":[{"symbol":"XBTUSDT","id":32402363228,"side":"Buy","size":1502000,"price":66766.1,"timestamp":"2024-05-18T15:46:10.022Z"}]}
{"table":"orderBookL2_25","action":"delete","data":[{"symbol":"XBTUSDT","id":32402490640,"side":"Sell","price":66815.6,"timestamp":"2024-05-18T15:46:10.071Z"},{"symbol":"XBTUSDT","id":32402490243,"side":"Sell","price":66809.5,"timestamp":"2024-05-18T15:46:10.071Z"},{"symbol":"XBTUSDT","id":32402474116,"side":"Sell","price":66824.2,"timestamp":"2024-05-18T15:46:10.071Z"},{"symbol":"XBTUSDT","id":32402490192,"side":"Sell","price":66809.6,"timestamp":"2024-05-18T15:46:10.071Z"},{"symbol":"XBTUSDT","id":32402489763,"side":"Buy","price":66780.9,"timestamp":"2024-05-18T15:46:10.071Z"},{"symbol":"XBTUSDT","id":32402489412,"side":"Buy","price":66780.8,"timestamp":"2024-05-18T15:46:10.071Z"},{"symbol":"XBTUSDT","id":32402363228,"side":"Buy","price":66766.1,"timestamp":"2024-05-18T15:46:10.071Z"},{"symbol":"XBTUSDT","id":32402464305,"side":"Buy","price":66766.2,"timestamp":"2024-05-18T15:46:10.071Z"}]}
{"table":"orderBookL2_25","action":"update","data":[{"symbol":"XBTUSDT","id":32402490718,"side":"Sell","size":349000,"price":66809.4,"timestamp":"2024-05-18T15:46:10.071Z"},{"symbol":"XBTUSDT","id":32402479097,"side":"Sell","size":3000,"price":66815.5,"timestamp":"2024-05-18T15:46:10.071Z"},{"symbol":"XBTUSDT","id":32402461579,"side":"Sell","size":101000,"price":66815.7,"timestamp":"2024-05-18T15:46:10.071Z"},{"symbol":"XBTUSDT","id":32402490740,"side":"Buy","size":155000,"price":66766.3,"timestamp":"2024-05-18T15:46:10.071Z"}]}
{"table":"orderBookL2_25","action":"insert","data":[{"symbol":"XBTUSDT","id":32402490937,"side":"Sell","size":20000,"price":66809.5,"timestamp":"2024-05-18T15:46:10.071Z"},{"symbol":"XBTUSDT","id":32402490922,"side":"Sell","size":64000,"price":66815.6,"timestamp":"2024-05-18T15:46:10.071Z"},{"symbol":"XBTUSDT","id":32402490907,"side":"Sell","size":1000,"price":66815.8,"timestamp":"2024-05-18T15:46:10.071Z"},{"symbol":"XBTUSDT","id":32402490932,"side":"Sell","size":20000,"price":66809.6,"timestamp":"2024-05-18T15:46:10.071Z"},{"symbol":"XBTUSDT","id":32402490930,"side":"Buy","size":64000,"price":66779.5,"timestamp":"2024-05-18T15:46:10.071Z"},{"symbol":"XBTUSDT","id":32402490935,"side":"Buy","size":20000,"price":66780.7,"timestamp":"2024-05-18T15:46:10.071Z"},{"symbol":"XBTUSDT","id":32402490924,"side":"Buy","size":100000,"price":66779.4,"timestamp":"2024-05-18T15:46:10.071Z"},{"symbol":"XBTUSDT","id":32402490928,"side":"Buy","size":20000,"price":66780.6,"timestamp":"2024-05-18T15:46:10.071Z"}]}
{"table":"orderBookL2_25","action":"delete","data":[{"symbol":"XBTUSDT","id":32402455289,"side":"Sell","price":66822.3,"timestamp":"2024-05-18T15:46:10.120Z"},{"symbol":"XBTUSDT","id":32402490782,"side":"Buy","price":66775.1,"timestamp":"2024-05-18T15:46:10.120Z"}]}
{"table":"orderBookL2_25","action":"insert","data":[{"symbol":"XBTUSDT","id":32402490959,"side":"Sell","size":2000,"price":66821.5,"timestamp":"2024-05-18T15:46:10.120Z"},{"symbol":"XBTUSDT","id":32402490991,"side":"Buy","size":369000,"price":66772.7,"timestamp":"2024-05-18T15:46:10.120Z"}]}
{"table":"orderBookL2_25","action":"delete","data":[{"symbol":"XBTUSDT","id":32402490935,"side":"Buy","price":66780.7,"timestamp":"2024-05-18T15:46:10.265Z"}]}
{"table":"orderBookL2_25","action":"insert","data":[{"symbol":"XBTUSDT","id":32402491126,"side":"Buy","size":20000,"price":66780.2,"timestamp":"2024-05-18T15:46:10.265Z"}]}
{"table":"orderBookL2_25","action":"delete","data":[{"symbol":"XBTUSDT","id":32402490937,"side":"Sell","price":66809.5,"timestamp":"2024-05-18T15:46:10.315Z"},{"symbol":"XBTUSDT","id":32402490907,"side":"Sell","price":66815.8,"timestamp":"2024-05-18T15:46:10.315Z"},{"symbol":"XBTUSDT","id":32402490922,"side":"Sell","price":66815.6,"timestamp":"2024-05-18T15:46:10.315Z"},{"symbol":"XBTUSDT","id":32402490928,"side":"Buy","price":66780.6,"timestamp":"2024-05-18T15:46:10.315Z"}]}
{"table":"orderBookL2_25","action":"update","data":[{"symbol":"XBTUSDT","id":32402461579,"side":"Sell","size":100000,"price":66815.7,"timestamp":"2024-05-18T15:46:10.315Z"},{"symbol":"XBTUSDT","id":32402242406,"side":"Sell","size":138000,"price":66822.2,"timestamp":"2024-05-18T15:46:10.315Z"}]}
{"table":"orderBookL2_25","action":"insert","data":[{"symbol":"XBTUSDT","id":32402491137,"side":"Sell","size":1000,"price":66816.0,"timestamp":"2024-05-18T15:46:10.315Z"},{"symbol":"XBTUSDT","id":32402491130,"side":"Sell","size":20000,"price":66809.7,"timestamp":"2024-05-18T15:46:10.315Z"},{"symbol":"XBTUSDT","id":32402491135,"side":"Sell","size":1000,"price":66815.9,"timestamp":"2024-05-18T15:46:10.315Z"},{"symbol":"XBTUSDT","id":32402491128,"side":"Buy","size":20000,"price":66780.1,"timestamp":"2024-05-18T15:46:10.315Z"}]}
{"table":"orderBookL2_25","action":"delete","data":[{"symbol":"XBTUSDT","id":32402491130,"side":"Sell","price":66809.7,"timestamp":"2024-05-18T15:46:10.364Z"},{"symbol":"XBTUSDT","id":32402491128,"side":"Buy","price":66780.1,"timestamp":"2024-05-18T15:46:10.364Z"},{"symbol":"XBTUSDT","id":32402491126,"side":"Buy","price":66780.2,"timestamp":"2024-05-18T15:46:10.364Z"}]}
{"table":"orderBookL2_25","action":"insert","data":[{"symbol":"XBTUSDT","id":32402491185,"side":"Sell","size":20000,"price":66809.5,"timestamp":"2024-05-18T15:46:10.364Z"},{"symbol":"XBTUSDT","id":32402491180,"side":"Buy","size":20000,"price":66780.7,"timestamp":"2024-05-18T15:46:10.364Z"},{"symbol":"XBTUSDT","id":32402491182,"side":"Buy","size":20000,"price":66780.6,"timestamp":"2024-05-18T15:46:10.364Z"}]}
{"table":"orderBookL2_25","action":"update","data":[{"symbol":"ETHUSDT","id":32402490643,"side":"Buy","size":273000,"price":3109.63,"timestamp":"2024-05-18T15:46:10.391Z"}]}
{"table":"orderBookL2_25","action":"delete","data":[{"symbol":"XBTUSDT","id":32402491135,"side":"Sell","price":66815.9,"timestamp":"2024-05-18T15:46:10.413Z"},{"symbol":"XBTUSDT","id":32402490932,"side":"Sell","price":66809.6,"timestamp":"2024-05-18T15:46:10.413Z"},{"symbol":"XBTUSDT","id":32402491137,"side":"Sell","price":66816.0,"timestamp":"2024-05-18T15:46:10.413Z"},{"symbol":"XBTUSDT","id":32402491180,"side":"Buy","price":66780.7,"timestamp":"2024-05-18T15:46:10.413Z"},{"symbol":"XBTUSDT","id":32402491182,"side":"Buy","price":66780.6,"timestamp":"2024-05-18T15:46:10.413Z"},{"symbol":"XBTUSDT","id":32402489986,"side":"Buy","price":66786.8,"timestamp":"2024-05-18T15:46:10.413Z"}]}
{"table":"orderBookL2_25","action":"update","data":[{"symbol":"XBTUSDT","id":32402490718,"side":"Sell","size":369000,"price":66809.4,"timestamp":"2024-05-18T15:46:10.413Z"},{"symbol":"XBTUSDT","id":32402461579,"side":"Sell","size":101000,"price":66815.7,"timestamp":"2024-05-18T15:46:10.413Z"},{"symbol":"XBTUSDT","id":32402490740,"side":"Buy","size":155000,"price":66766.3,"timestamp":"2024-05-18T15:46:10.413Z"}]}
{"table":"orderBookL2_25","action":"insert","data":[{"symbol":"XBTUSDT","id":32402474116,"side":"Sell","size":102000,"price":66824.2,"timestamp":"2024-05-18T15:46:10.413Z"},{"symbol":"XBTUSDT","id":32402455289,"side":"Sell","size":22000,"price":66822.3,"timestamp":"2024-05-18T15:46:10.413Z"},{"symbol":"XBTUSDT","id":32402491227,"side":"Sell","size":67000,"price":66815.6,"timestamp":"2024-05-18T15:46:10.413Z"},{"symbol":"XBTUSDT","id":32402491237,"side":"Buy","size":20000,"price":66780.9,"timestamp":"2024-05-18T15:46:10.413Z"},{"symbol":"XBTUSDT","id":32402491239,"side":"Buy","size":20000,"price":66781.0,"timestamp":"2024-05-18T15:46:10.413Z"},{"symbol":"XBTUSDT","id":32402491243,"side":"Buy","size":10000,"price":66796.7,"timestamp":"2024-05-18T15:46:10.413Z"}]}
{"table":"orderBookL2_25","action":"delete","data":[{"symbol":"ETHUSDT","id":32402490175,"side":"Buy","price":3109.37,"timestamp":"2024-05-18T15:46:10.448Z"}]}
{"table":"orderBookL2_25","action":"insert","data":[{"symbol":"ETHUSDT","id":32402491270,"side":"Buy","size":1000,"price":3109.39,"timestamp":"2024-05-18T15:46:10.448Z"}]}
{"table":"orderBookL2_25","action":"delete","data":[{"symbol":"XBTUSDT","id":32402490959,"side":"Sell","price":66821.5,"timestamp":"2024-05-18T15:46:10.462Z"},{"symbol":"XBTUSDT","id":32402473887,"side":"Sell","price":66818.3,"timestamp":"2024-05-18T15:46:10.462Z"},{"symbol":"XBTUSDT","id":32402491243,"side":"Buy","price":66796.7,"timestamp":"2024-05-18T15:46:10.462Z"},{"symbol":"XBTUSDT","id":32402491239,"side":"Buy","price":66781.0,"timestamp":"2024-05-18T15:46:10.462Z"}]}
{"table":"orderBookL2_25","action":"update","data":[{"symbol":"XBTUSDT","id":32402490718,"side":"Sell","size":349000,"price":66809.4,"timestamp":"2024-05-18T15:46:10.462Z"},{"symbol":"XBTUSDT","id":32402474116,"side":"Sell","size":102000,"price":66824.2,"timestamp":"2024-05-18T15:46:10.462Z"}]}
{"table":"orderBookL2_25","action":"insert","data":[{"symbol":"XBTUSDT","id":32402491265,"side":"Sell","size":20000,"price":66809.6,"timestamp":"2024-05-18T15:46:10.462Z"},{"symbol":"XBTUSDT","id":32402491274,"side":"Sell","size":20000,"price":66811.2,"timestamp":"2024-05-18T15:46:10.462Z"},{"symbol":"XBTUSDT","id":32402464305,"side":"Buy","size":804000,"price":66766.2,"timestamp":"2024-05-18T15:46:10.462Z"},{"symbol":"XBTUSDT","id":32402491260,"side":"Buy","size":20000,"price":66780.8,"timestamp":"2024-05-18T15:46:10.462Z"}]}
{"table":"orderBookL2_25","action":"delete","data":[{"symbol":"ETHUSDT","id":32402490185,"side":"Sell","price":3110.87,"timestamp":"2024-05-18T15:46:10.497Z"},{"symbol":"ETHUSDT","id":32402490638,"side":"Buy","price":3109.38,"timestamp":"2024-05-18T15:46:10.497Z"}]}
{"table":"orderBookL2_25","action":"update","data":[{"symbol":"ETHUSDT","id":32402489700,"side":"Buy","size":49000,"price":3109.62,"timestamp":"2024-05-18T15:46:10.497Z"},{"symbol":"ETHUSDT","id":32401945550,"side":"Buy","size":2000,"price":3109.40,"timestamp":"2024-05-18T15:46:10.497Z"}]}
{"table":"orderBookL2_25","action":"insert","data":[{"symbol":"ETHUSDT","id":32402491285,"side":"Sell","size":32000,"price":3110.85,"timestamp":"2024-05-18T15:46:10.497Z"},{"symbol":"ETHUSDT","id":32402491288,"side":"Buy","size":32000,"price":3109.64,"timestamp":"2024-05-18T15:46:10.497Z"}]}
{"table":"orderBookL2_25","action":"delete","data":[{"symbol":"XBTUSDT","id":32402491265,"side":"Sell","price":66809.6,"timestamp":"2024-05-18T15:46:10.511Z"},{"symbol":"XBTUSDT","id":32402491185,"side":"Sell","price":66809.5,"timestamp":"2024-05-18T15:46:10.511Z"},{"symbol":"XBTUSDT","id":32402474116,"side":"Sell","price":66824.2,"timestamp":"2024-05-18T15:46:10.511Z"},{"symbol":"XBTUSDT","id":32402490733,"side":"Sell","price":66808.6,"timestamp":"2024-05-18T15:46:10.511Z"},{"symbol":"XBTUSDT","id":32402490718,"side":"Sell","price":66809.4,"timestamp":"2024-05-18T15:46:10.511Z"},{"symbol":"XBTUSDT","id":32402455289,"side":"Sell","price":66822.3,"timestamp":"2024-05-18T15:46:10.511Z"},{"symbol":"XBTUSDT","id":32402491260,"side":"Buy","price":66780.8,"timestamp":"2024-05-18T15:46:10.511Z"},{"symbol":"XBTUSDT","id":32402491237,"side":"Buy","price":66780.9,"timestamp":"2024-05-18T15:46:10.511Z"},{"symbol":"XBTUSDT","id":32402490991,"side":"Buy","price":66772.7,"timestamp":"2024-05-18T15:46:10.511Z"}]}
{"table":"orderBookL2_25","action":"update","data":[{"symbol":"XBTUSDT","id":32402461579,"side":"Sell","size":100000,"price":66815.7,"timestamp":"2024-05-18T15:46:10.511Z"},{"symbol":"XBTUSDT","id":32402491227,"side":"Sell","size":66000,"price":66815.6,"timestamp":"2024-05-18T15:46:10.511Z"}]}
{"table":"orderBookL2_25","action":"insert","data":[{"symbol":"XBTUSDT","id":32402491292,"side":"Sell","size":20000,"price":66809.2,"timestamp":"2024-05-18T15:46:10.511Z"},{"symbol":"XBTUSDT","id":32402491306,"side":"Sell","size":218000,"price":66809.0,"timestamp":"2024-05-18T15:46:10.511Z"},{"symbol":"XBTUSDT","id":32402491333,"side":"Sell","size":351000,"price":66808.5,"timestamp":"2024-05-18T15:46:10.511Z"},{"symbol":"XBTUSDT","id":32402491329,"side":"Sell","size":1000,"price":66815.4,"timestamp":"2024-05-18T15:46:10.511Z"},{"symbol":"XBTUSDT","id":32402491327,"side":"Sell","size":1000,"price":66815.3,"timestamp":"2024-05-18T15:46:10.511Z"},{"symbol":"XBTUSDT","id":32402491294,"side":"Sell","size":20000,"price":66809.1,"timestamp":"2024-05-18T15:46:10.511Z"},{"symbol":"XBTUSDT","id":32402491296,"side":"Buy","size":20000,"price":66781.0,"timestamp":"2024-05-18T15:46:10.511Z"},{"symbol":"XBTUSDT","id":32402491298,"side":"Buy","size":20000,"price":66781.1,"timestamp":"2024-05-18T15:46:10.511Z"},{"symbol":"XBTUSDT","id":32402491331,"side":"Buy","size":367000,"price":66772.7,"timestamp":"2024-05-18T15:46:10.511Z"}]}
{"table":"orderBookL2_25","action":"delete","data":[{"symbol":"ETHUSDT","id":32402488916,"side":"Sell","price":3111.64,"timestamp":"2024-05-18T15:46:10.546Z"},{"symbol":"ETHUSDT","id":32402476196,"side":"Buy","price":3107.95,"timestamp":"2024-05-18T15:46:10.546Z"},{"symbol":"ETHUSDT","id":32402400155,"side":"Buy","price":3107.38,"timestamp":"2024-05-18T15:46:10.546Z"},{"symbol":"ETHUSDT","id":32402482245,"side":"Buy","price":3108.46,"timestamp":"2024-05-18T15:46:10.546Z"},{"symbol":"ETHUSDT","id":32402466556,"side":"Buy","price":3108.41,"timestamp":"2024-05-18T15:46:10.546Z"},{"symbol":"ETHUSDT","id":32402485570,"side":"Buy","price":3108.50,"timestamp":"2024-05-18T15:46:10.546Z"},{"symbol":"ETHUSDT","id":32402480534,"side":"Buy","price":3108.49,"timestamp":"2024-05-18T15:46:10.546Z"},{"symbol":"ETHUSDT","id":32402458908,"side":"Buy","price":3107.30,"timestamp":"2024-05-18T15:46:10.546Z"}]}
{"table":"orderBookL2_25","action":"update","data":[{"symbol":"ETHUSDT","id":32402487294,"side":"Sell","size":2346000,"price":3111.54,"timestamp":"2024-05-18T15:46:10.546Z"},{"symbol":"ETHUSDT","id":32402455680,"side":"Sell","size":100000,"price":3112.02,"timestamp":"2024-05-18T15:46:10.546Z"},{"symbol":"ETHUSDT","id":32401945550,"side":"Buy","size":1000,"price":3109.40,"timestamp":"2024-05-18T15:46:10.546Z"}]}
{"table":"orderBookL2_25","action":"insert","data":[{"symbol":"ETHUSDT","id":32402491370,"side":"Sell","size":920000,"price":3111.53,"timestamp":"2024-05-18T15:46:10.546Z"},{"symbol":"ETHUSDT","id":32402491354,"side":"Buy","size":192000,"price":3108.31,"timestamp":"2024-05-18T15:46:10.546Z"},{"symbol":"ETHUSDT","id":32402491357,"side":"Buy","size":2300000,"price":3107.78,"timestamp":"2024-05-18T15:46:10.546Z"},{"symbol":"ETHUSDT","id":32402491320,"side":"Buy","size":1000,"price":3109.38,"timestamp":"2024-05-18T15:46:10.546Z"},{"symbol":"ETHUSDT","id":32402491349,"side":"Buy","size":61000,"price":3108.62,"timestamp":"2024-05-18T15:46:10.546Z"},{"symbol":"ETHUSDT","id":32402491372,"side":"Buy","size":120000,"price":3108.32,"timestamp":"2024-05-18T15:46:10.546Z"},{"symbol":"ETHUSDT","id":32402491374,"side":"Buy","size":1386000,"price":3107.79,"timestamp":"2024-05-18T15:46:10.546Z"},{"symbol":"ETHUSDT","id":32402491363,"side":"Buy","size":935000,"price":3107.39,"timestamp":"2024-05-18T15:46:10.546Z"}]}
{"table":"orderBookL2_25","action":"delete","data":[{"symbol":"XBTUSDT","id":32402491227,"side":"Sell","price":66815.6,"timestamp":"2024-05-18T15:46:10.560Z"},{"symbol":"XBTUSDT","id":32402490729,"side":"Sell","price":66805.2,"timestamp":"2024-05-18T15:46:10.560Z"}]}
{"table":"orderBookL2_25","action":"update","data":[{"symbol":"XBTUSDT","id":32402491306,"side":"Sell","size":19000,"price":66809.0,"timestamp":"2024-05-18T15:46:10.560Z"},{"symbol":"XBTUSDT","id":32402490808,"side":"Buy","size":8000,"price":66788.2,"timestamp":"2024-05-18T15:46:10.560Z"}]}
{"table":"orderBookL2_25","action":"insert","data":[{"symbol":"XBTUSDT","id":32402455289,"side":"Sell","size":22000,"price":66822.3,"timestamp":"2024-05-18T15:46:10.560Z"},{"symbol":"XBTUSDT","id":32402491339,"side":"Sell","size":219000,"price":66808.4,"timestamp":"2024-05-18T15:46:10.560Z"}]}
{"table":"orderBookL2_25","action":"delete","data":[{"symbol":"ETHUSDT","id":32402491349,"side":"Buy","price":3108.62,"timestamp":"2024-05-18T15:46:10.595Z"},{"symbol":"ETHUSDT","id":32402489457,"side":"Buy","price":3108.98,"timestamp":"2024-05-18T15:46:10.595Z"},{"symbol":"ETHUSDT","id":32402491363,"side":"Buy","price":3107.39,"timestamp":"2024-05-18T15:46:10.595Z"},{"symbol":"ETHUSDT","id":32402489460,"side":"Buy","price":3108.99,"timestamp":"2024-05-18T15:46:10.595Z"}]}
{"table":"orderBookL2_25","action":"update","data":[{"symbol":"ETHUSDT","id":32401850719,"side":"Buy","size":160000,"price":3107.70,"timestamp":"2024-05-18T15:46:10.595Z"},{"symbol":"ETHUSDT","id":32402397491,"side":"Buy","size":100000,"price":3107.56,"timestamp":"2024-05-18T15:46:10.595Z"}]}
{"table":"orderBookL2_25","action":"insert","data":[{"symbol":"ETHUSDT","id":32402491393,"side":"Buy","size":69000,"price":3108.46,"timestamp":"2024-05-18T15:46:10.595Z"},{"symbol":"ETHUSDT","id":32402491384,"side":"Buy","size":389000,"price":3107.99,"timestamp":"2024-05-18T15:46:10.595Z"},{"symbol":"ETHUSDT","id":32402491386,"side":"Buy","size":100000,"price":3108.82,"timestamp":"2024-05-18T15:46:10.595Z"},{"symbol":"ETHUSDT","id":32402491391,"side":"Buy","size":68000,"price":3108.83,"timestamp":"2024-05-18T15:46:10.595Z"}]}
{"table":"orderBookL2_25","action":"delete","data":[{"symbol":"XBTUSDT","id":32402455289,"side":"Sell","price":66822.3,"timestamp":"2024-05-18T15:46:10.609Z"},{"symbol":"XBTUSDT","id":32402489266,"side":"Buy","price":66786.5,"timestamp":"2024-05-18T15:46:10.609Z"},{"symbol":"XBTUSDT","id":32402489350,"side":"Buy","price":66800.8,"timestamp":"2024-05-18T15:46:10.609Z"},{"symbol":"XBTUSDT","id":32402490740,"side":"Buy","price":66766.3,"timestamp":"2024-05-18T15:46:10.609Z"}]}
{"table":"orderBookL2_25","action":"update","data":[{"symbol":"XBTUSDT","id":32402242406,"side":"Sell","size":138000,"price":66822.2,"timestamp":"2024-05-18T15:46:10.609Z"}]}
{"table":"orderBookL2_25","action":"insert","data":[{"symbol":"XBTUSDT","id":32402491497,"side":"Sell","size":2000,"price":66816.5,"timestamp":"2024-05-18T15:46:10.609Z"},{"symbol":"XBTUSDT","id":32402363228,"side":"Buy","size":1502000,"price":66766.1,"timestamp":"2024-05-18T15:46:10.609Z"},{"symbol":"XBTUSDT","id":32402491522,"side":"Buy","size":155000,"price":66762.3,"timestamp":"2024-05-18T15:46:10.609Z"},{"symbol":"XBTUSDT","id":32402360485,"side":"Buy","size":100000,"price":66764.4,"timestamp":"2024-05-18T15:46:10.609Z"}]}
{"table":"orderBookL2_25","action":"delete","data":[{"symbol":"ETHUSDT","id":32402491285,"side":"Sell","price":3110.85,"timestamp":"2024-05-18T15:46:10.644Z"},{"symbol":"ETHUSDT","id":32402491270,"side":"Buy","price":3109.39,"timestamp":"2024-05-18T15:46:10.644Z"},{"symbol":"ETHUSDT","id":32402491288,"side":"Buy","price":3109.64,"timestamp":"2024-05-18T15:46:10.644Z"}]}
{"table":"orderBookL2_25","action":"update","data":[{"symbol":"ETHUSDT","id":32402489700,"side":"Buy","size":81000,"price":3109.62,"timestamp":"2024-05-18T15:46:10.644Z"},{"symbol":"ETHUSDT","id":32402490643,"side":"Buy","size":32000,"price":3109.63,"timestamp":"2024-05-18T15:46:10.644Z"},{"symbol":"ETHUSDT","id":32401945550,"side":"Buy","size":2000,"price":3109.40,"timestamp":"2024-05-18T15:46:10.644Z"}]}
{"table":"orderBookL2_25","action":"insert","data":[{"symbol":"ETHUSDT","id":32402491652,"side":"Sell","size":32000,"price":3110.87,"timestamp":"2024-05-18T15:46:10.644Z"},{"symbol":"ETHUSDT","id":32402400155,"side":"Buy","size":17414000,"price":3107.38,"timestamp":"2024-05-18T15:46:10.644Z"},{"symbol":"ETHUSDT","id":32402491363,"side":"Buy","size":935000,"price":3107.39,"timestamp":"2024-05-18T15:46:10.644Z"}]}
{"table":"orderBookL2_25","action":"delete","data":[{"symbol":"XBTUSDT","id":32402491329,"side":"Sell","price":66815.4,"timestamp":"2024-05-18T15:46:10.658Z"},{"symbol":"XBTUSDT","id":32402242406,"side":"Sell","price":66822.2,"timestamp":"2024-05-18T15:46:10.658Z"},{"symbol":"XBTUSDT","id":32402476497,"side":"Sell","price":66821.6,"timestamp":"2024-05-18T15:46:10.658Z"},{"symbol":"XBTUSDT","id":32402471671,"side":"Sell","price":66821.7,"timestamp":"2024-05-18T15:46:10.658Z"},{"symbol":"XBTUSDT","id":32402479097,"side":"Sell","price":66815.5,"timestamp":"2024-05-18T15:46:10.658Z"},{"symbol":"XBTUSDT","id":32402491497,"side":"Sell","price":66816.5,"timestamp":"2024-05-18T15:46:10.658Z"},{"symbol":"XBTUSDT","id":32402491327,"side":"Sell","price":66815.3,"timestamp":"2024-05-18T15:46:10.658Z"},{"symbol":"XBTUSDT","id":32402491292,"side":"Sell","price":66809.2,"timestamp":"2024-05-18T15:46:10.658Z"},{"symbol":"XBTUSDT","id":32402491294,"side":"Sell","price":66809.1,"timestamp":"2024-05-18T15:46:10.658Z"},{"symbol":"XBTUSDT","id":32402461579,"side":"Sell","price":66815.7,"timestamp":"2024-05-18T15:46:10.658Z"},{"symbol":"XBTUSDT","id":32402464305,"side":"Buy","price":66766.2,"timestamp":"2024-05-18T15:46:10.658Z"},{"symbol":"XBTUSDT","id":32402490808,"side":"Buy","price":66788.2,"timestamp":"2024-05-18T15:46:10.658Z"},{"symbol":"XBTUSDT","id":32402483246,"side":"Buy","price":66791.7,"timestamp":"2024-05-18T15:46:10.658Z"},{"symbol":"XBTUSDT","id":32402455981,"side":"Buy","price":66801.8,"timestamp":"2024-05-18T15:46:10.658Z"},{"symbol":"XBTUSDT","id":32402476745,"side":"Buy","price":66795.4,"timestamp":"2024-05-18T15:46:10.658Z"},{"symbol":"XBTUSDT","id":32402462688,"side":"Buy","price":66784.1,"timestamp":"2024-05-18T15:46:10.658Z"},{"symbol":"XBTUSDT","id":32402156627,"side":"Buy","price":66782.8,"timestamp":"2024-05-18T15:46:10.658Z"},{"symbol":"XBTUSDT","id":32402490930,"side":"Buy","price":66779.5,"timestamp":"2024-05-18T15:46:10.658Z"},{"symbol":"XBTUSDT","id":32402478801,"side":"Buy","price":66795.5,"timestamp":"2024-05-18T15:46:10.658Z"},{"symbol":"XBTUSDT","id":32402491296,"side":"Buy","price":66781.0,"timestamp":"2024-05-18T15:46:10.658Z"},{"symbol":"XBTUSDT","id":32402491298,"side":"Buy","price":66781.1,"timestamp":"2024-05-18T15:46:10.658Z"},{"symbol":"XBTUSDT","id":32402463841,"side":"Buy","price":66784.3,"timestamp":"2024-05-18T15:46:10.658Z"},{"symbol":"XBTUSDT","id":32402490213,"side":"Buy","price":66788.3,"timestamp":"2024-05-18T15:46:10.658Z"},{"symbol":"XBTUSDT","id":32402491522,"side":"Buy","price":66762.3,"timestamp":"2024-05-18T15:46:10.658Z"}]}
{"table":"orderBookL2_25","action":"update","data":[{"symbol":"XBTUSDT","id":32402462668,"side":"Sell","size":104000,"price":66801.9,"timestamp":"2024-05-18T15:46:10.658Z"},{"symbol":"XBTUSDT","id":32402258708,"side":"Buy","size":16000,"price":66795.3,"timestamp":"2024-05-18T15:46:10.658Z"}]}
{"table":"orderBookL2_25","action":"insert","data":[{"symbol":"XBTUSDT","id":32402491670,"side":"Sell","size":312000,"price":66795.5,"timestamp":"2024-05-18T15:46:10.658Z"},{"symbol":"XBTUSDT","id":32402491708,"side":"Sell","size":20000,"price":66809.3,"timestamp":"2024-05-18T15:46:10.658Z"},{"symbol":"XBTUSDT","id":32402491663,"side":"Sell","size":100000,"price":66798.6,"timestamp":"2024-05-18T15:46:10.658Z"},{"symbol":"XBTUSDT","id":32402491828,"side":"Sell","size":2000,"price":66811.0,"timestamp":"2024-05-18T15:46:10.658Z"},{"symbol":"XBTUSDT","id":32402491799,"side":"Sell","size":293000,"price":66795.4,"timestamp":"2024-05-18T15:46:10.658Z"},{"symbol":"XBTUSDT","id":32402491835,"side":"Sell","size":20000,"price":66809.5,"timestamp":"2024-05-18T15:46:10.658Z"},{"symbol":"XBTUSDT","id":32402491650,"side":"Sell","size":48000,"price":66795.6,"timestamp":"2024-05-18T15:46:10.658Z"},{"symbol":"XBTUSDT","id":32402491693,"side":"Sell","size":74000,"price":66808.3,"timestamp":"2024-05-18T15:46:10.658Z"},{"symbol":"XBTUSDT","id":32402491733,"side":"Sell","size":101000,"price":66804.9,"timestamp":"2024-05-18T15:46:10.658Z"},{"symbol":"XBTUSDT","id":32402491728,"side":"Sell","size":64000,"price":66801.8,"timestamp":"2024-05-18T15:46:10.658Z"},{"symbol":"XBTUSDT","id":32402456061,"side":"Buy","size":100000,"price":66761.0,"timestamp":"2024-05-18T15:46:10.658Z"},{"symbol":"XBTUSDT","id":32402434478,"side":"Buy","size":100000,"price":66747.4,"timestamp":"2024-05-18T15:46:10.658Z"},{"symbol":"XBTUSDT","id":32402491710,"side":"Buy","size":396000,"price":66734.4,"timestamp":"2024-05-18T15:46:10.658Z"},{"symbol":"XBTUSDT","id":32402490802,"side":"Buy","size":651000,"price":66734.3,"timestamp":"2024-05-18T15:46:10.658Z"},{"symbol":"XBTUSDT","id":32402489416,"side":"Buy","size":100000,"price":66757.6,"timestamp":"2024-05-18T15:46:10.658Z"},{"symbol":"XBTUSDT","id":32402491723,"side":"Buy","size":543000,"price":66744.7,"timestamp":"2024-05-18T15:46:10.658Z"},{"symbol":"XBTUSDT","id":32402491820,"side":"Buy","size":20000,"price":66779.8,"timestamp":"2024-05-18T15:46:10.658Z"},{"symbol":"XBTUSDT","id":32402491624,"side":"Buy","size":229000,"price":66772.8,"timestamp":"2024-05-18T15:46:10.658Z"},{"symbol":"XBTUSDT","id":32402491808,"side":"Buy","size":35000,"price":66781.4,"timestamp":"2024-05-18T15:46:10.658Z"},{"symbol":"XBTUSDT","id":32402491801,"side":"Buy","size":20000,"price":66779.9,"timestamp":"2024-05-18T15:46:10.658Z"},{"symbol":"XBTUSDT","id":32402491466,"side":"Buy","size":74000,"price":66760.3,"timestamp":"2024-05-18T15:46:10.658Z"},{"symbol":"XBTUSDT","id":32402491833,"side":"Buy","size":100000,"price":66744.0,"timestamp":"2024-05-18T15:46:10.658Z"},{"symbol":"XBTUSDT","id":32402463843,"side":"Buy","size":1348000,"price":66760.9,"timestamp":"2024-05-18T15:46:10.658Z"},{"symbol":"XBTUSDT","id":32402491719,"side":"Buy","size":442000,"price":66778.1,"timestamp":"2024-05-18T15:46:10.658Z"}]}
{"table":"orderBookL2_25","action":"delete","data":[{"symbol":"ETHUSDT","id":32402486025,"side":"Sell","price":3111.72,"timestamp":"2024-05-18T15:46:10.693Z"},{"symbol":"ETHUSDT","id":32402488923,"side":"Sell","price":3110.11,"timestamp":"2024-05-18T15:46:10.693Z"},{"symbol":"ETHUSDT","id":32402490651,"side":"Sell","price":3110.86,"timestamp":"2024-05-18T15:46:10.693Z"},{"symbol":"ETHUSDT","id":32402455680,"side":"Sell","price":3112.02,"timestamp":"2024-05-18T15:46:10.693Z"},{"symbol":"ETHUSDT","id":32402491320,"side":"Buy","price":3109.38,"timestamp":"2024-05-18T15:46:10.693Z"},{"symbol":"ETHUSDT","id":32402490643,"side":"Buy","price":3109.63,"timestamp":"2024-05-18T15:46:10.693Z"},{"symbol":"ETHUSDT","id":32402491374,"side":"Buy","price":3107.79,"timestamp":"2024-05-18T15:46:10.693Z"},{"symbol":"ETHUSDT","id":32402489369,"side":"Buy","price":3110.09,"timestamp":"2024-05-18T15:46:10.693Z"},{"symbol":"ETHUSDT","id":32402491363,"side":"Buy","price":3107.39,"timestamp":"2024-05-18T15:46:10.693Z"}]}
{"table":"orderBookL2_25","action":"update","data":[{"symbol":"ETHUSDT","id":32402489501,"side":"Sell","size":109000,"price":3110.10,"timestamp":"2024-05-18T15:46:10.693Z"},{"symbol":"ETHUSDT","id":32402489313,"side":"Sell","size":98000,"price":3110.88,"timestamp":"2024-05-18T15:46:10.693Z"},{"symbol":"ETHUSDT","id":32402489700,"side":"Buy","size":49000,"price":3109.62,"timestamp":"2024-05-18T15:46:10.693Z"},{"symbol":"ETHUSDT","id":32401945550,"side":"Buy","size":1000,"price":3109.40,"timestamp":"2024-05-18T15:46:10.693Z"}]}
{"table":"orderBookL2_25","action":"insert","data":[{"symbol":"ETHUSDT","id":32402491918,"side":"Sell","size":100000,"price":3109.95,"timestamp":"2024-05-18T15:46:10.693Z"},{"symbol":"ETHUSDT","id":32402492119,"side":"Sell","size":63000,"price":3109.94,"timestamp":"2024-05-18T15:46:10.693Z"},{"symbol":"ETHUSDT","id":32402492156,"side":"Sell","size":69000,"price":3110.08,"timestamp":"2024-05-18T15:46:10.693Z"},{"symbol":"ETHUSDT","id":32402491846,"side":"Sell","size":43000,"price":3110.09,"timestamp":"2024-05-18T15:46:10.693Z"},{"symbol":"ETHUSDT","id":32402492076,"side":"Buy","size":32000,"price":3109.59,"timestamp":"2024-05-18T15:46:10.693Z"},{"symbol":"ETHUSDT","id":32402492082,"side":"Buy","size":32000,"price":3109.64,"timestamp":"2024-05-18T15:46:10.693Z"},{"symbol":"ETHUSDT","id":32402492143,"side":"Buy","size":1000,"price":3109.38,"timestamp":"2024-05-18T15:46:10.693Z"},{"symbol":"ETHUSDT","id":32402492187,"side":"Buy","size":1000,"price":3109.37,"timestamp":"2024-05-18T15:46:10.693Z"},{"symbol":"ETHUSDT","id":32402491923,"side":"Buy","size":689000,"price":3107.79,"timestamp":"2024-05-18T15:46:10.693Z"}]}
{"table":"orderBookL2_25","action":"delete","data":[{"symbol":"XBTUSDT","id":32402491708,"side":"Sell","price":66809.3,"timestamp":"2024-05-18T15:46:10.707Z"},{"symbol":"XBTUSDT","id":32402491339,"side":"Sell","price":66808.4,"timestamp":"2024-05-18T15:46:10.707Z"},{"symbol":"XBTUSDT","id":32402491828,"side":"Sell","price":66811.0,"timestamp":"2024-05-18T15:46:10.707Z"},{"symbol":"XBTUSDT","id":32402491835,"side":"Sell","price":66809.5,"timestamp":"2024-05-18T15:46:10.707Z"},{"symbol":"XBTUSDT","id":32402491306,"side":"Sell","price":66809.0,"timestamp":"2024-05-18T15:46:10.707Z"},{"symbol":"XBTUSDT","id":32402491663,"side":"Sell","price":66798.6,"timestamp":"2024-05-18T15:46:10.707Z"},{"symbol":"XBTUSDT","id":32402491333,"side":"Sell","price":66808.5,"timestamp":"2024-05-18T15:46:10.707Z"},{"symbol":"XBTUSDT","id":32402363228,"side":"Buy","price":66766.1,"timestamp":"2024-05-18T15:46:10.707Z"},{"symbol":"XBTUSDT","id":32402491331,"side":"Buy","price":66772.7,"timestamp":"2024-05-18T15:46:10.707Z"},{"symbol":"XBTUSDT","id":32402490924,"side":"Buy","price":66779.4,"timestamp":"2024-05-18T15:46:10.707Z"},{"symbol":"XBTUSDT","id":32402491801,"side":"Buy","price":66779.9,"timestamp":"2024-05-18T15:46:10.707Z"},{"symbol":"XBTUSDT","id":32402491820,"side":"Buy","price":66779.8,"timestamp":"2024-05-18T15:46:10.707Z"},{"symbol":"XBTUSDT","id":32402491624,"side":"Buy","price":66772.8,"timestamp":"2024-05-18T15:46:10.707Z"}]}
{"table":"orderBookL2_25","action":"update","data":[{"symbol":"XBTUSDT","id":32402491670,"side":"Sell","size":300000,"price":66795.5,"timestamp":"2024-05-18T15:46:10.707Z"},{"symbol":"XBTUSDT","id":32402491650,"side":"Sell","size":8000,"price":66795.6,"timestamp":"2024-05-18T15:46:10.707Z"},{"symbol":"XBTUSDT","id":32402491799,"side":"Sell","size":439000,"price":66795.4,"timestamp":"2024-05-18T15:46:10.707Z"},{"symbol":"XBTUSDT","id":32402491733,"side":"Sell","size":202000,"price":66804.9,"timestamp":"2024-05-18T15:46:10.707Z"},{"symbol":"XBTUSDT","id":32402490802,"side":"Buy","size":651000,"price":66734.3,"timestamp":"2024-05-18T15:46:10.707Z"}]}
{"table":"orderBookL2_25","action":"insert","data":[{"symbol":"XBTUSDT","id":32402492032,"side":"Sell","size":2000,"price":66814.0,"timestamp":"2024-05-18T15:46:10.707Z"},{"symbol":"XBTUSDT","id":32402492137,"side":"Sell","size":49000,"price":66808.2,"timestamp":"2024-05-18T15:46:10.707Z"},{"symbol":"XBTUSDT","id":32402492221,"side":"Sell","size":1000,"price":66815.3,"timestamp":"2024-05-18T15:46:10.707Z"},{"symbol":"XBTUSDT","id":32402491967,"side":"Sell","size":347000,"price":66805.1,"timestamp":"2024-05-18T15:46:10.707Z"},{"symbol":"XBTUSDT","id":32402492086,"side":"Sell","size":20000,"price":66810.1,"timestamp":"2024-05-18T15:46:10.707Z"},{"symbol":"XBTUSDT","id":32402492145,"side":"Sell","size":67000,"price":66808.6,"timestamp":"2024-05-18T15:46:10.707Z"},{"symbol":"XBTUSDT","id":32402492020,"side":"Sell","size":20000,"price":66809.6,"timestamp":"2024-05-18T15:46:10.707Z"},{"symbol":"XBTUSDT","id":32402492214,"side":"Buy","size":20000,"price":66777.6,"timestamp":"2024-05-18T15:46:10.707Z"},{"symbol":"XBTUSDT","id":32402492129,"side":"Buy","size":1502000,"price":66752.1,"timestamp":"2024-05-18T15:46:10.707Z"},{"symbol":"XBTUSDT","id":32402491950,"side":"Buy","size":8000,"price":66786.6,"timestamp":"2024-05-18T15:46:10.707Z"},{"symbol":"XBTUSDT","id":32402492196,"side":"Buy","size":20000,"price":66777.5,"timestamp":"2024-05-18T15:46:10.707Z"},{"symbol":"XBTUSDT","id":32402491878,"side":"Buy","size":385000,"price":66767.9,"timestamp":"2024-05-18T15:46:10.707Z"},{"symbol":"XBTUSDT","id":32402478137,"side":"Buy","size":15000,"price":66734.1,"timestamp":"2024-05-18T15:46:10.707Z"}]}
{"table":"orderBookL2_25","action":"delete","data":[{"symbol":"ETHUSDT","id":32402487294,"side":"Sell","price":3111.54,"timestamp":"2024-05-18T15:46:10.742Z"},{"symbol":"ETHUSDT","id":32402489501,"side":"Sell","price":3110.10,"timestamp":"2024-05-18T15:46:10.742Z"},{"symbol":"ETHUSDT","id":32402487132,"side":"Sell","price":3111.71,"timestamp":"2024-05-18T15:46:10.742Z"},{"symbol":"ETHUSDT","id":32402488587,"side":"Sell","price":3110.48,"timestamp":"2024-05-18T15:46:10.742Z"},{"symbol":"ETHUSDT","id":32402492156,"side":"Sell","price":3110.08,"timestamp":"2024-05-18T15:46:10.742Z"},{"symbol":"ETHUSDT","id":32402491652,"side":"Sell","price":3110.87,"timestamp":"2024-05-18T15:46:10.742Z"},{"symbol":"ETHUSDT","id":32402487305,"side":"Sell","price":3111.65,"timestamp":"2024-05-18T15:46:10.742Z"},{"symbol":"ETHUSDT","id":32402400155,"side":"Buy","price":3107.38,"timestamp":"2024-05-18T15:46:10.742Z"},{"symbol":"ETHUSDT","id":32402481323,"side":"Buy","price":3109.32,"timestamp":"2024-05-18T15:46:10.742Z"},{"symbol":"ETHUSDT","id":32402492082,"side":"Buy","price":3109.64,"timestamp":"2024-05-18T15:46:10.742Z"},{"symbol":"ETHUSDT","id":32402491391,"side":"Buy","price":3108.83,"timestamp":"2024-05-18T15:46:10.742Z"},{"symbol":"ETHUSDT","id":32402491372,"side":"Buy","price":3108.32,"timestamp":"2024-05-18T15:46:10.742Z"},{"symbol":"ETHUSDT","id":32402492076,"side":"Buy","price":3109.59,"timestamp":"2024-05-18T15:46:10.742Z"},{"symbol":"ETHUSDT","id":32402480605,"side":"Buy","price":3108.45,"timestamp":"2024-05-18T15:46:10.742Z"},{"symbol":"ETHUSDT","id":32402034609,"side":"Buy","price":3108.61,"timestamp":"2024-05-18T15:46:10.742Z"},{"symbol":"ETHUSDT","id":32402491354,"side":"Buy","price":3108.31,"timestamp":"2024-05-18T15:46:10.742Z"},{"symbol":"ETHUSDT","id":32402491393,"side":"Buy","price":3108.46,"timestamp":"2024-05-18T15:46:10.742Z"},{"symbol":"ETHUSDT","id":32402489700,"side":"Buy","price":3109.62,"timestamp":"2024-05-18T15:46:10.742Z"},{"symbol":"ETHUSDT","id":32402491386,"side":"Buy","price":3108.82,"timestamp":"2024-05-18T15:46:10.742Z"},{"symbol":"ETHUSDT","id":32402492187,"side":"Buy","price":3109.37,"timestamp":"2024-05-18T15:46:10.742Z"},{"symbol":"ETHUSDT","id":32402492143,"side":"Buy","price":3109.38,"timestamp":"2024-05-18T15:46:10.742Z"}]}
{"table":"orderBookL2_25","action":"update","data":[{"symbol":"ETHUSDT","id":32402491918,"side":"Sell","size":109000,"price":3109.95,"timestamp":"2024-05-18T15:46:10.742Z"},{"symbol":"ETHUSDT","id":32402492119,"side":"Sell","size":63000,"price":3109.94,"timestamp":"2024-05-18T15:46:10.742Z"},{"symbol":"ETHUSDT","id":32402485810,"side":"Sell","size":24000,"price":3111.07,"timestamp":"2024-05-18T15:46:10.742Z"},{"symbol":"ETHUSDT","id":32402489313,"side":"Sell","size":66000,"price":3110.88,"timestamp":"2024-05-18T15:46:10.742Z"}]}
{"table":"orderBookL2_25","action":"insert","data":[{"symbol":"ETHUSDT","id":32402492368,"side":"Sell","size":32000,"price":3110.86,"timestamp":"2024-05-18T15:46:10.742Z"},{"symbol":"ETHUSDT","id":32402492330,"side":"Sell","size":100000,"price":3109.79,"timestamp":"2024-05-18T15:46:10.742Z"},{"symbol":"ETHUSDT","id":32402492564,"side":"Sell","size":25000,"price":3110.47,"timestamp":"2024-05-18T15:46:10.742Z"},{"symbol":"ETHUSDT","id":32402492623,"side":"Sell","size":43000,"price":3110.78,"timestamp":"2024-05-18T15:46:10.742Z"},{"symbol":"ETHUSDT","id":32402492302,"side":"Sell","size":32000,"price":3110.85,"timestamp":"2024-05-18T15:46:10.742Z"},{"symbol":"ETHUSDT","id":32402492643,"side":"Sell","size":21000,"price":3109.78,"timestamp":"2024-05-18T15:46:10.742Z"},{"symbol":"ETHUSDT","id":32402492641,"side":"Sell","size":21000,"price":3109.61,"timestamp":"2024-05-18T15:46:10.742Z"},{"symbol":"ETHUSDT","id":32402492418,"side":"Buy","size":100000,"price":3108.68,"timestamp":"2024-05-18T15:46:10.742Z"},{"symbol":"ETHUSDT","id":32402492452,"side":"Buy","size":1000,"price":3109.21,"timestamp":"2024-05-18T15:46:10.742Z"},{"symbol":"ETHUSDT","id":32402458908,"side":"Buy","size":1114000,"price":3107.30,"timestamp":"2024-05-18T15:46:10.742Z"},{"symbol":"ETHUSDT","id":32402492501,"side":"Buy","size":1000,"price":3109.22,"timestamp":"2024-05-18T15:46:10.742Z"},{"symbol":"ETHUSDT","id":32402492409,"side":"Buy","size":1156000,"price":3108.48,"timestamp":"2024-05-18T15:46:10.742Z"},{"symbol":"ETHUSDT","id":32402492538,"side":"Buy","size":928000,"price":3107.18,"timestamp":"2024-05-18T15:46:10.742Z"},{"symbol":"ETHUSDT","id":32402492550,"side":"Buy","size":182000,"price":3108.32,"timestamp":"2024-05-18T15:46:10.742Z"},{"symbol":"ETHUSDT","id":32402492600,"side":"Buy","size":32000,"price":3109.49,"timestamp":"2024-05-18T15:46:10.742Z"},{"symbol":"ETHUSDT","id":32402492383,"side":"Buy","size":100000,"price":3108.52,"timestamp":"2024-05-18T15:46:10.742Z"},{"symbol":"ETHUSDT","id":32402480382,"side":"Buy","size":100000,"price":3107.24,"timestamp":"2024-05-18T15:46:10.742Z"},{"symbol":"ETHUSDT","id":32402488025,"side":"Buy","size":100000,"price":3107.08,"timestamp":"2024-05-18T15:46:10.742Z"},{"symbol":"ETHUSDT","id":32402480341,"side":"Buy","size":942000,"price":3106.76,"timestamp":"2024-05-18T15:46:10.742Z"},{"symbol":"ETHUSDT","id":32402488018,"side":"Buy","size":1620000,"price":3107.17,"timestamp":"2024-05-18T15:46:10.742Z"},{"symbol":"ETHUSDT","id":32402492235,"side":"Buy","size":32000,"price":3109.60,"timestamp":"2024-05-18T15:46:10.742Z"}]}
{"table":"orderBookL2_25","action":"delete","data":[{"symbol":"XBTUSDT","id":32402492145,"side":"Sell","price":66808.6,"timestamp":"2024-05-18T15:46:10.756Z"},{"symbol":"XBTUSDT","id":32402492032,"side":"Sell","price":66814.0,"timestamp":"2024-05-18T15:46:10.756Z"},{"symbol":"XBTUSDT","id":32402492137,"side":"Sell","price":66808.2,"timestamp":"2024-05-18T15:46:10.756Z"},{"symbol":"XBTUSDT","id":32402492221,"side":"Sell","price":66815.3,"timestamp":"2024-05-18T15:46:10.756Z"},{"symbol":"XBTUSDT","id":32402491466,"side":"Buy","price":66760.3,"timestamp":"2024-05-18T15:46:10.756Z"},{"symbol":"XBTUSDT","id":32402478137,"side":"Buy","price":66734.1,"timestamp":"2024-05-18T15:46:10.756Z"},{"symbol":"XBTUSDT","id":32402492196,"side":"Buy","price":66777.5,"timestamp":"2024-05-18T15:46:10.756Z"},{"symbol":"XBTUSDT","id":32402492214,"side":"Buy","price":66777.6,"timestamp":"2024-05-18T15:46:10.756Z"},{"symbol":"XBTUSDT","id":32402491719,"side":"Buy","price":66778.1,"timestamp":"2024-05-18T15:46:10.756Z"},{"symbol":"XBTUSDT","id":32402480644,"side":"Buy","price":66784.4,"timestamp":"2024-05-18T15:46:10.756Z"},{"symbol":"XBTUSDT","id":32402463843,"side":"Buy","price":66760.9,"timestamp":"2024-05-18T15:46:10.756Z"},{"symbol":"XBTUSDT","id":32402491808,"side":"Buy","price":66781.4,"timestamp":"2024-05-18T15:46:10.756Z"}]}
{"table":"orderBookL2_25","action":"update","data":[{"symbol":"XBTUSDT","id":32402455324,"side":"Sell","size":101000,"price":66812.3,"timestamp":"2024-05-18T15:46:10.756Z"},{"symbol":"XBTUSDT","id":32402492020,"side":"Sell","size":20000,"price":66809.6,"timestamp":"2024-05-18T15:46:10.756Z"},{"symbol":"XBTUSDT","id":32402490802,"side":"Buy","size":651000,"price":66734.3,"timestamp":"2024-05-18T15:46:10.756Z"},{"symbol":"XBTUSDT","id":32402491710,"side":"Buy","size":396000,"price":66734.4,"timestamp":"2024-05-18T15:46:10.756Z"}]}
{"table":"orderBookL2_25","action":"insert","data":[{"symbol":"XBTUSDT","id":32402492758,"side":"Sell","size":1000,"price":66809.8,"timestamp":"2024-05-18T15:46:10.756Z"},{"symbol":"XBTUSDT","id":32402492572,"side":"Sell","size":55000,"price":66808.1,"timestamp":"2024-05-18T15:46:10.756Z"},{"symbol":"XBTUSDT","id":32402492707,"side":"Sell","size":159000,"price":66810.7,"timestamp":"2024-05-18T15:46:10.756Z"},{"symbol":"XBTUSDT","id":32402492366,"side":"Sell","size":61000,"price":66808.6,"timestamp":"2024-05-18T15:46:10.756Z"},{"symbol":"XBTUSDT","id":32402492728,"side":"Buy","size":20000,"price":66773.6,"timestamp":"2024-05-18T15:46:10.756Z"},{"symbol":"XBTUSDT","id":32402492533,"side":"Buy","size":442000,"price":66772.1,"timestamp":"2024-05-18T15:46:10.756Z"},{"symbol":"XBTUSDT","id":32402492791,"side":"Buy","size":11000,"price":66793.0,"timestamp":"2024-05-18T15:46:10.756Z"},{"symbol":"XBTUSDT","id":32402492339,"side":"Buy","size":837000,"price":66768.0,"timestamp":"2024-05-18T15:46:10.756Z"},{"symbol":"XBTUSDT","id":32402492536,"side":"Buy","size":1348000,"price":66748.7,"timestamp":"2024-05-18T15:46:10.756Z"},{"symbol":"XBTUSDT","id":32402492445,"side":"Buy","size":15000,"price":66730.5,"timestamp":"2024-05-18T15:46:10.756Z"},{"symbol":"XBTUSDT","id":32402492726,"side":"Buy","size":20000,"price":66773.5,"timestamp":"2024-05-18T15:46:10.756Z"},{"symbol":"XBTUSDT","id":32402462262,"side":"Buy","size":100000,"price":66733.8,"timestamp":"2024-05-18T15:46:10.756Z"}]}
{"table":"orderBookL2_25","action":"delete","data":[{"symbol":"ETHUSDT","id":32402492368,"side":"Sell","price":3110.86,"timestamp":"2024-05-18T15:46:10.791Z"},{"symbol":"ETHUSDT","id":32402492564,"side":"Sell","price":3110.47,"timestamp":"2024-05-18T15:46:10.791Z"},{"symbol":"ETHUSDT","id":32402476896,"side":"Sell","price":3110.80,"timestamp":"2024-05-18T15:46:10.791Z"},{"symbol":"ETHUSDT","id":32402476904,"side":"Sell","price":3110.79,"timestamp":"2024-05-18T15:46:10.791Z"},{"symbol":"ETHUSDT","id":32402492643,"side":"Sell","price":3109.78,"timestamp":"2024-05-18T15:46:10.791Z"},{"symbol":"ETHUSDT","id":32402492641,"side":"Sell","price":3109.61,"timestamp":"2024-05-18T15:46:10.791Z"},{"symbol":"ETHUSDT","id":32402492452,"side":"Buy","price":3109.21,"timestamp":"2024-05-18T15:46:10.791Z"},{"symbol":"ETHUSDT","id":32402492501,"side":"Buy","price":3109.22,"timestamp":"2024-05-18T15:46:10.791Z"},{"symbol":"ETHUSDT","id":32402492550,"side":"Buy","price":3108.32,"timestamp":"2024-05-18T15:46:10.791Z"},{"symbol":"ETHUSDT","id":32402480348,"side":"Buy","price":3108.95,"timestamp":"2024-05-18T15:46:10.791Z"},{"symbol":"ETHUSDT","id":32402491384,"side":"Buy","price":3107.99,"timestamp":"2024-05-18T15:46:10.791Z"},{"symbol":"ETHUSDT","id":32402492235,"side":"Buy","price":3109.60,"timestamp":"2024-05-18T15:46:10.791Z"},{"symbol":"ETHUSDT","id":32402492600,"side":"Buy","price":3109.49,"timestamp":"2024-05-18T15:46:10.791Z"}]}
{"table":"orderBookL2_25","action":"update","data":[{"symbol":"ETHUSDT","id":32402491918,"side":"Sell","size":100000,"price":3109.95,"timestamp":"2024-05-18T15:46:10.791Z"},{"symbol":"ETHUSDT","id":32402488478,"side":"Sell","size":305000,"price":3111.05,"timestamp":"2024-05-18T15:46:10.791Z"}]}
{"table":"orderBookL2_25","action":"insert","data":[{"symbol":"ETHUSDT","id":32402492800,"side":"Sell","size":905000,"price":3110.25,"timestamp":"2024-05-18T15:46:10.791Z"},{"symbol":"ETHUSDT","id":32402493118,"side":"Sell","size":32000,"price":3110.63,"timestamp":"2024-05-18T15:46:10.791Z"},{"symbol":"ETHUSDT","id":32402493008,"side":"Sell","size":29000,"price":3109.97,"timestamp":"2024-05-18T15:46:10.791Z"},{"symbol":"ETHUSDT","id":32402487294,"side":"Sell","size":2346000,"price":3111.54,"timestamp":"2024-05-18T15:46:10.791Z"},{"symbol":"ETHUSDT","id":32402487305,"side":"Sell","size":100000,"price":3111.65,"timestamp":"2024-05-18T15:46:10.791Z"},{"symbol":"ETHUSDT","id":32402492940,"side":"Sell","size":21000,"price":3109.60,"timestamp":"2024-05-18T15:46:10.791Z"},{"symbol":"ETHUSDT","id":32402493016,"side":"Buy","size":32000,"price":3109.37,"timestamp":"2024-05-18T15:46:10.791Z"},{"symbol":"ETHUSDT","id":32402493066,"side":"Buy","size":1000,"price":3109.11,"timestamp":"2024-05-18T15:46:10.791Z"},{"symbol":"ETHUSDT","id":32402493083,"side":"Buy","size":1000,"price":3109.12,"timestamp":"2024-05-18T15:46:10.791Z"},{"symbol":"ETHUSDT","id":32402492798,"side":"Buy","size":311000,"price":3108.69,"timestamp":"2024-05-18T15:46:10.791Z"},{"symbol":"ETHUSDT","id":32402231045,"side":"Buy","size":100000,"price":3105.80,"timestamp":"2024-05-18T15:46:10.791Z"},{"symbol":"ETHUSDT","id":32402354519,"side":"Buy","size":100000,"price":3106.60,"timestamp":"2024-05-18T15:46:10.791Z"},{"symbol":"ETHUSDT","id":32401445960,"side":"Buy","size":100000,"price":3105.40,"timestamp":"2024-05-18T15:46:10.791Z"}]}
{"table":"orderBookL2_25","action":"delete","data":[{"symbol":"XBTUSDT","id":32402492758,"side":"Sell","price":66809.8,"timestamp":"2024-05-18T15:46:10.805Z"},{"symbol":"XBTUSDT","id":32402491274,"side":"Sell","price":66811.2,"timestamp":"2024-05-18T15:46:10.805Z"},{"symbol":"XBTUSDT","id":32402490315,"side":"Sell","price":66805.0,"timestamp":"2024-05-18T15:46:10.805Z"},{"symbol":"XBTUSDT","id":32402492366,"side":"Sell","price":66808.6,"timestamp":"2024-05-18T15:46:10.805Z"},{"symbol":"XBTUSDT","id":32402492728,"side":"Buy","price":66773.6,"timestamp":"2024-05-18T15:46:10.805Z"},{"symbol":"XBTUSDT","id":32402492726,"side":"Buy","price":66773.5,"timestamp":"2024-05-18T15:46:10.805Z"},{"symbol":"XBTUSDT","id":32402492791,"side":"Buy","price":66793.0,"timestamp":"2024-05-18T15:46:10.805Z"},{"symbol":"XBTUSDT","id":32402492445,"side":"Buy","price":66730.5,"timestamp":"2024-05-18T15:46:10.805Z"},{"symbol":"XBTUSDT","id":32402462262,"side":"Buy","price":66733.8,"timestamp":"2024-05-18T15:46:10.805Z"}]}
{"table":"orderBookL2_25","action":"update","data":[{"symbol":"XBTUSDT","id":32402455324,"side":"Sell","size":100000,"price":66812.3,"timestamp":"2024-05-18T15:46:10.805Z"},{"symbol":"XBTUSDT","id":32402492020,"side":"Sell","size":20000,"price":66809.6,"timestamp":"2024-05-18T15:46:10.805Z"},{"symbol":"XBTUSDT","id":32402248654,"side":"Buy","size":102000,"price":66776.0,"timestamp":"2024-05-18T15:46:10.805Z"}]}
{"table":"orderBookL2_25","action":"insert","data":[{"symbol":"XBTUSDT","id":32402492665,"side":"Sell","size":2000,"price":66813.5,"timestamp":"2024-05-18T15:46:10.805Z"},{"symbol":"XBTUSDT","id":32402493006,"side":"Sell","size":3000,"price":66811.3,"timestamp":"2024-05-18T15:46:10.805Z"},{"symbol":"XBTUSDT","id":32402493060,"side":"Sell","size":1000,"price":66809.3,"timestamp":"2024-05-18T15:46:10.805Z"},{"symbol":"XBTUSDT","id":32402492996,"side":"Sell","size":1000,"price":66809.7,"timestamp":"2024-05-18T15:46:10.805Z"},{"symbol":"XBTUSDT","id":32402493101,"side":"Buy","size":20000,"price":66772.4,"timestamp":"2024-05-18T15:46:10.805Z"},{"symbol":"XBTUSDT","id":32402492817,"side":"Buy","size":35000,"price":66774.8,"timestamp":"2024-05-18T15:46:10.805Z"},{"symbol":"XBTUSDT","id":32402493110,"side":"Buy","size":20000,"price":66772.5,"timestamp":"2024-05-18T15:46:10.805Z"},{"symbol":"XBTUSDT","id":32402492889,"side":"Buy","size":100000,"price":66750.8,"timestamp":"2024-05-18T15:46:10.805Z"},{"symbol":"XBTUSDT","id":32402492823,"side":"Buy","size":20000,"price":66788.7,"timestamp":"2024-05-18T15:46:10.805Z"}]}
{"table":"orderBookL2_25","action":"delete","data":[{"symbol":"ETHUSDT","id":32402493118,"side":"Sell","price":3110.63,"timestamp":"2024-05-18T15:46:10.840Z"},{"symbol":"ETHUSDT","id":32402492302,"side":"Sell","price":3110.85,"timestamp":"2024-05-18T15:46:10.840Z"},{"symbol":"ETHUSDT","id":32402487305,"side":"Sell","price":3111.65,"timestamp":"2024-05-18T15:46:10.840Z"},{"symbol":"ETHUSDT","id":32402493066,"side":"Buy","price":3109.11,"timestamp":"2024-05-18T15:46:10.840Z"},{"symbol":"ETHUSDT","id":32402231045,"side":"Buy","price":3105.80,"timestamp":"2024-05-18T15:46:10.840Z"},{"symbol":"ETHUSDT","id":32401445960,"side":"Buy","price":3105.40,"timestamp":"2024-05-18T15:46:10.840Z"}]}
{"table":"orderBookL2_25","action":"insert","data":[{"symbol":"ETHUSDT","id":32402493271,"side":"Sell","size":32000,"price":3110.61,"timestamp":"2024-05-18T15:46:10.840Z"},{"symbol":"ETHUSDT","id":32402493223,"side":"Sell","size":100000,"price":3110.56,"timestamp":"2024-05-18T15:46:10.840Z"},{"symbol":"ETHUSDT","id":32402493283,"side":"Sell","size":32000,"price":3110.60,"timestamp":"2024-05-18T15:46:10.840Z"},{"symbol":"ETHUSDT","id":32402493214,"side":"Buy","size":32000,"price":3109.36,"timestamp":"2024-05-18T15:46:10.840Z"},{"symbol":"ETHUSDT","id":32402493174,"side":"Buy","size":43000,"price":3109.41,"timestamp":"2024-05-18T15:46:10.840Z"},{"symbol":"ETHUSDT","id":32402493131,"side":"Buy","size":1000,"price":3109.13,"timestamp":"2024-05-18T15:46:10.840Z"}]}
{"table":"orderBookL2_25","action":"delete","data":[{"symbol":"XBTUSDT","id":32402492665,"side":"Sell","price":66813.5,"timestamp":"2024-05-18T15:46:10.854Z"},{"symbol":"XBTUSDT","id":32402492086,"side":"Sell","price":66810.1,"timestamp":"2024-05-18T15:46:10.854Z"},{"symbol":"XBTUSDT","id":32402492020,"side":"Sell","price":66809.6,"timestamp":"2024-05-18T15:46:10.854Z"},{"symbol":"XBTUSDT","id":32402489038,"side":"Sell","price":66812.2,"timestamp":"2024-05-18T15:46:10.854Z"},{"symbol":"XBTUSDT","id":32402493101,"side":"Buy","price":66772.4,"timestamp":"2024-05-18T15:46:10.854Z"},{"symbol":"XBTUSDT","id":32402491710,"side":"Buy","price":66734.4,"timestamp":"2024-05-18T15:46:10.854Z"},{"symbol":"XBTUSDT","id":32402491878,"side":"Buy","price":66767.9,"timestamp":"2024-05-18T15:46:10.854Z"},{"symbol":"XBTUSDT","id":32402490802,"side":"Buy","price":66734.3,"timestamp":"2024-05-18T15:46:10.854Z"},{"symbol":"XBTUSDT","id":32402493110,"side":"Buy","price":66772.5,"timestamp":"2024-05-18T15:46:10.854Z"}]}
{"table":"orderBookL2_25","action":"update","data":[{"symbol":"XBTUSDT","id":32402480133,"side":"Sell","size":30000,"price":66803.0,"timestamp":"2024-05-18T15:46:10.854Z"},{"symbol":"XBTUSDT","id":32402492533,"side":"Buy","size":442000,"price":66772.1,"timestamp":"2024-05-18T15:46:10.854Z"},{"symbol":"XBTUSDT","id":32402492339,"side":"Buy","size":538000,"price":66768.0,"timestamp":"2024-05-18T15:46:10.854Z"}]}
{"table":"orderBookL2_25","action":"insert","data":[{"symbol":"XBTUSDT","id":32402493236,"side":"Sell","size":2000,"price":66812.0,"timestamp":"2024-05-18T15:46:10.854Z"},{"symbol":"XBTUSDT","id":32402493293,"side":"Sell","size":20000,"price":66803.1,"timestamp":"2024-05-18T15:46:10.854Z"},{"symbol":"XBTUSDT","id":32402493155,"side":"Sell","size":20000,"price":66804.1,"timestamp":"2024-05-18T15:46:10.854Z"},{"symbol":"XBTUSDT","id":32402493286,"side":"Sell","size":101000,"price":66809.9,"timestamp":"2024-05-18T15:46:10.854Z"},{"symbol":"XBTUSDT","id":32402493144,"side":"Buy","size":355000,"price":66766.3,"timestamp":"2024-05-18T15:46:10.854Z"},{"symbol":"XBTUSDT","id":32402493297,"side":"Buy","size":20000,"price":66772.4,"timestamp":"2024-05-18T15:46:10.854Z"},{"symbol":"XBTUSDT","id":32402493180,"side":"Buy","size":166000,"price":66772.2,"timestamp":"2024-05-18T15:46:10.854Z"},{"symbol":"XBTUSDT","id":32402493295,"side":"Buy","size":20000,"price":66772.0,"timestamp":"2024-05-18T15:46:10.854Z"},{"symbol":"XBTUSDT","id":32402493239,"side":"Buy","size":20000,"price":66750.5,"timestamp":"2024-05-18T15:46:10.854Z"}]}
{"table":"orderBookL2_25","action":"delete","data":[{"symbol":"ETHUSDT","id":32402487294,"side":"Sell","price":3111.54,"timestamp":"2024-05-18T15:46:10.889Z"},{"symbol":"ETHUSDT","id":32402471335,"side":"Sell","price":3111.40,"timestamp":"2024-05-18T15:46:10.889Z"},{"symbol":"ETHUSDT","id":32402491918,"side":"Sell","price":3109.95,"timestamp":"2024-05-18T15:46:10.889Z"},{"symbol":"ETHUSDT","id":32402492119,"side":"Sell","price":3109.94,"timestamp":"2024-05-18T15:46:10.889Z"},{"symbol":"ETHUSDT","id":32402493271,"side":"Sell","price":3110.61,"timestamp":"2024-05-18T15:46:10.889Z"},{"symbol":"ETHUSDT","id":32402485576,"side":"Sell","price":3111.48,"timestamp":"2024-05-18T15:46:10.889Z"},{"symbol":"ETHUSDT","id":32402493016,"side":"Buy","price":3109.37,"timestamp":"2024-05-18T15:46:10.889Z"},{"symbol":"ETHUSDT","id":32402493214,"side":"Buy","price":3109.36,"timestamp":"2024-05-18T15:46:10.889Z"},{"symbol":"ETHUSDT","id":32402480341,"side":"Buy","price":3106.76,"timestamp":"2024-05-18T15:46:10.889Z"},{"symbol":"ETHUSDT","id":32402354519,"side":"Buy","price":3106.60,"timestamp":"2024-05-18T15:46:10.889Z"}]}
{"table":"orderBookL2_25","action":"update","data":[{"symbol":"ETHUSDT","id":32401945550,"side":"Buy","size":1000,"price":3109.40,"timestamp":"2024-05-18T15:46:10.889Z"}]}
{"table":"orderBookL2_25","action":"insert","data":[{"symbol":"ETHUSDT","id":32402493315,"side":"Sell","size":60000,"price":3109.78,"timestamp":"2024-05-18T15:46:10.889Z"},{"symbol":"ETHUSDT","id":32402493423,"side":"Sell","size":64000,"price":3110.55,"timestamp":"2024-05-18T15:46:10.889Z"},{"symbol":"ETHUSDT","id":32402493446,"side":"Sell","size":65000,"price":3110.74,"timestamp":"2024-05-18T15:46:10.889Z"},{"symbol":"ETHUSDT","id":32402493419,"side":"Sell","size":546000,"price":3110.24,"timestamp":"2024-05-18T15:46:10.889Z"},{"symbol":"ETHUSDT","id":32402493406,"side":"Sell","size":28000,"price":3110.08,"timestamp":"2024-05-18T15:46:10.889Z"},{"symbol":"ETHUSDT","id":32402493421,"side":"Sell","size":32000,"price":3110.61,"timestamp":"2024-05-18T15:46:10.889Z"},{"symbol":"ETHUSDT","id":32402493425,"side":"Buy","size":32000,"price":3109.36,"timestamp":"2024-05-18T15:46:10.889Z"},{"symbol":"ETHUSDT","id":32402493347,"side":"Buy","size":383000,"price":3107.99,"timestamp":"2024-05-18T15:46:10.889Z"},{"symbol":"ETHUSDT","id":32402493432,"side":"Buy","size":32000,"price":3109.37,"timestamp":"2024-05-18T15:46:10.889Z"},{"symbol":"ETHUSDT","id":32402493317,"side":"Buy","size":256000,"price":3108.70,"timestamp":"2024-05-18T15:46:10.889Z"}]}
{"table":"orderBookL2_25","action":"delete","data":[{"symbol":"XBTUSDT","id":32402493060,"side":"Sell","price":66809.3,"timestamp":"2024-05-18T15:46:10.903Z"},{"symbol":"XBTUSDT","id":32402491728,"side":"Sell","price":66801.8,"timestamp":"2024-05-18T15:46:10.903Z"},{"symbol":"XBTUSDT","id":32402492996,"side":"Sell","price":66809.7,"timestamp":"2024-05-18T15:46:10.903Z"},{"symbol":"XBTUSDT","id":32402479032,"side":"Sell","price":66806.9,"timestamp":"2024-05-18T15:46:10.903Z"},{"symbol":"XBTUSDT","id":32402491967,"side":"Sell","price":66805.1,"timestamp":"2024-05-18T15:46:10.903Z"},{"symbol":"XBTUSDT","id":32402492572,"side":"Sell","price":66808.1,"timestamp":"2024-05-18T15:46:10.903Z"},{"symbol":"XBTUSDT","id":32402491733,"side":"Sell","price":66804.9,"timestamp":"2024-05-18T15:46:10.903Z"},{"symbol":"XBTUSDT","id":32402493144,"side":"Buy","price":66766.3,"timestamp":"2024-05-18T15:46:10.903Z"},{"symbol":"XBTUSDT","id":32402493297,"side":"Buy","price":66772.4,"timestamp":"2024-05-18T15:46:10.903Z"},{"symbol":"XBTUSDT","id":32402493295,"side":"Buy","price":66772.0,"timestamp":"2024-05-18T15:46:10.903Z"}]}
{"table":"orderBookL2_25","action":"update","data":[{"symbol":"XBTUSDT","id":32402480133,"side":"Sell","size":30000,"price":66803.0,"timestamp":"2024-05-18T15:46:10.903Z"},{"symbol":"XBTUSDT","id":32402455324,"side":"Sell","size":100000,"price":66812.3,"timestamp":"2024-05-18T15:46:10.903Z"},{"symbol":"XBTUSDT","id":32402492533,"side":"Buy","size":462000,"price":66772.1,"timestamp":"2024-05-18T15:46:10.903Z"}]}
{"table":"orderBookL2_25","action":"insert","data":[{"symbol":"XBTUSDT","id":32402461579,"side":"Sell","size":100000,"price":66815.7,"timestamp":"2024-05-18T15:46:10.903Z"},{"symbol":"XBTUSDT","id":32402493343,"side":"Sell","size":1000,"price":66809.5,"timestamp":"2024-05-18T15:46:10.903Z"},{"symbol":"XBTUSDT","id":32402242406,"side":"Sell","size":138000,"price":66822.2,"timestamp":"2024-05-18T15:46:10.903Z"},{"symbol":"XBTUSDT","id":32402493384,"side":"Sell","size":1000,"price":66809.4,"timestamp":"2024-05-18T15:46:10.903Z"},{"symbol":"XBTUSDT","id":32402493444,"side":"Sell","size":366000,"price":66801.7,"timestamp":"2024-05-18T15:46:10.903Z"},{"symbol":"XBTUSDT","id":32402493337,"side":"Sell","size":3000,"price":66804.2,"timestamp":"2024-05-18T15:46:10.903Z"},{"symbol":"XBTUSDT","id":32402492566,"side":"Sell","size":543000,"price":66817.9,"timestamp":"2024-05-18T15:46:10.903Z"},{"symbol":"XBTUSDT","id":32402493440,"side":"Buy","size":366000,"price":66764.5,"timestamp":"2024-05-18T15:46:10.903Z"},{"symbol":"XBTUSDT","id":32402493448,"side":"Buy","size":20000,"price":66772.0,"timestamp":"2024-05-18T15:46:10.903Z"},{"symbol":"XBTUSDT","id":32402491710,"side":"Buy","size":396000,"price":66734.4,"timestamp":"2024-05-18T15:46:10.903Z"}]}
{"table":"orderBookL2_25","action":"delete","data":[{"symbol":"ETHUSDT","id":32402493421,"side":"Sell","price":3110.61,"timestamp":"2024-05-18T15:46:10.938Z"},{"symbol":"ETHUSDT","id":32402493425,"side":"Buy","price":3109.36,"timestamp":"2024-05-18T15:46:10.938Z"}]}
{"table":"orderBookL2_25","action":"insert","data":[{"symbol":"ETHUSDT","id":32402493503,"side":"Sell","size":32000,"price":3110.59,"timestamp":"2024-05-18T15:46:10.938Z"},{"symbol":"ETHUSDT","id":32402493495,"side":"Buy","size":32000,"price":3109.38,"timestamp":"2024-05-18T15:46:10.938Z"}]}
{"table":"orderBookL2_25","action":"delete","data":[{"symbol":"XBTUSDT","id":32402242406,"side":"Sell","price":66822.2,"timestamp":"2024-05-18T15:46:10.952Z"},{"symbol":"XBTUSDT","id":32402492566,"side":"Sell","price":66817.9,"timestamp":"2024-05-18T15:46:10.952Z"},{"symbol":"XBTUSDT","id":32402493448,"side":"Buy","price":66772.0,"timestamp":"2024-05-18T15:46:10.952Z"},{"symbol":"XBTUSDT","id":32402491710,"side":"Buy","price":66734.4,"timestamp":"2024-05-18T15:46:10.952Z"}]}
{"table":"orderBookL2_25","action":"update","data":[{"symbol":"XBTUSDT","id":32402492533,"side":"Buy","size":442000,"price":66772.1,"timestamp":"2024-05-18T15:46:10.952Z"}]}
{"table":"orderBookL2_25","action":"insert","data":[{"symbol":"XBTUSDT","id":32402493542,"side":"Sell","size":68000,"price":66805.2,"timestamp":"2024-05-18T15:46:10.952Z"},{"symbol":"XBTUSDT","id":32402493533,"side":"Sell","size":227000,"price":66801.6,"timestamp":"2024-05-18T15:46:10.952Z"},{"symbol":"XBTUSDT","id":32402493529,"side":"Buy","size":20000,"price":66771.8,"timestamp":"2024-05-18T15:46:10.952Z"},{"symbol":"XBTUSDT","id":32402493535,"side":"Buy","size":20000,"price":66771.9,"timestamp":"2024-05-18T15:46:10.952Z"}]}
{"table":"orderBookL2_25","action":"delete","data":[{"symbol":"XBTUSDT","id":32402491833,"side":"Buy","price":66744.0,"timestamp":"2024-05-18T15:46:11.001Z"}]}
{"table":"orderBookL2_25","action":"update","data":[{"symbol":"XBTUSDT","id":32402227172,"side":"Buy","size":11000,"price":66780.0,"timestamp":"2024-05-18T15:46:11.001Z"}]}
{"table":"orderBookL2_25","action":"insert","data":[{"symbol":"XBTUSDT","id":32402493571,"side":"Buy","size":8000,"price":66776.1,"timestamp":"2024-05-18T15:46:11.001Z"}]}
{"table":"orderBookL2_25","action":"delete","data":[{"symbol":"ETHUSDT","id":32402493083,"side":"Buy","price":3109.12,"timestamp":"2024-05-18T15:46:11.039Z"}]}
{"table":"orderBookL2_25","action":"insert","data":[{"symbol":"ETHUSDT","id":32402493640,"side":"Buy","size":1000,"price":3109.15,"timestamp":"2024-05-18T15:46:11.039Z"}]}
{"table":"orderBookL2_25","action":"delete","data":[{"symbol":"XBTUSDT","id":32402492823,"side":"Buy","price":66788.7,"timestamp":"2024-05-18T15:46:11.050Z"}]}
{"table":"orderBookL2_25","action":"update","data":[{"symbol":"XBTUSDT","id":32402248654,"side":"Buy","size":2000,"price":66776.0,"timestamp":"2024-05-18T15:46:11.050Z"}]}
{"table":"orderBookL2_25","action":"insert","data":[{"symbol":"XBTUSDT","id":32402491833,"side":"Buy","size":100000,"price":66744.0,"timestamp":"2024-05-18T15:46:11.050Z"}]}
{"table":"orderBookL2_25","action":"delete","data":[{"symbol":"ETHUSDT","id":32402493406,"side":"Sell","price":3110.08,"timestamp":"2024-05-18T15:46:11.089Z"},{"symbol":"ETHUSDT","id":32402493640,"side":"Buy","price":3109.15,"timestamp":"2024-05-18T15:46:11.089Z"},{"symbol":"ETHUSDT","id":32402493432,"side":"Buy","price":3109.37,"timestamp":"2024-05-18T15:46:11.089Z"},{"symbol":"ETHUSDT","id":32402493131,"side":"Buy","price":3109.13,"timestamp":"2024-05-18T15:46:11.089Z"},{"symbol":"ETHUSDT","id":32402493495,"side":"Buy","price":3109.38,"timestamp":"2024-05-18T15:46:11.089Z"}]}
{"table":"orderBookL2_25","action":"update","data":[{"symbol":"ETHUSDT","id":32402491846,"side":"Sell","size":20000,"price":3110.09,"timestamp":"2024-05-18T15:46:11.089Z"},{"symbol":"ETHUSDT","id":32401945550,"side":"Buy","size":33000,"price":3109.40,"timestamp":"2024-05-18T15:46:11.089Z"}]}
{"table":"orderBookL2_25","action":"insert","data":[{"symbol":"ETHUSDT","id":32402487294,"side":"Sell","size":2346000,"price":3111.54,"timestamp":"2024-05-18T15:46:11.089Z"},{"symbol":"ETHUSDT","id":32402493683,"side":"Buy","size":1000,"price":3109.13,"timestamp":"2024-05-18T15:46:11.089Z"},{"symbol":"ETHUSDT","id":32402493653,"side":"Buy","size":32000,"price":3109.39,"timestamp":"2024-05-18T15:46:11.089Z"},{"symbol":"ETHUSDT","id":32402480341,"side":"Buy","size":942000,"price":3106.76,"timestamp":"2024-05-18T15:46:11.089Z"},{"symbol":"ETHUSDT","id":32402493681,"side":"Buy","size":1000,"price":3109.12,"timestamp":"2024-05-18T15:46:11.089Z"}]}
{"table":"orderBookL2_25","action":"update","data":[{"symbol":"XBTUSDT","id":32402491799,"side":"Sell","size":595000,"price":66795.4,"timestamp":"2024-05-18T15:46:11.099Z"},{"symbol":"XBTUSDT","id":32402462668,"side":"Sell","size":102000,"price":66801.9,"timestamp":"2024-05-18T15:46:11.099Z"},{"symbol":"XBTUSDT","id":32402491833,"side":"Buy","size":100000,"price":66744.0,"timestamp":"2024-05-18T15:46:11.099Z"}]}
{"table":"orderBookL2_25","action":"delete","data":[{"symbol":"ETHUSDT","id":32402493503,"side":"Sell","price":3110.59,"timestamp":"2024-05-18T15:46:11.138Z"},{"symbol":"ETHUSDT","id":32402491846,"side":"Sell","price":3110.09,"timestamp":"2024-05-18T15:46:11.138Z"},{"symbol":"ETHUSDT","id":32402493681,"side":"Buy","price":3109.12,"timestamp":"2024-05-18T15:46:11.138Z"},{"symbol":"ETHUSDT","id":32402493653,"side":"Buy","price":3109.39,"timestamp":"2024-05-18T15:46:11.138Z"},{"symbol":"ETHUSDT","id":32402480341,"side":"Buy","price":3106.76,"timestamp":"2024-05-18T15:46:11.138Z"}]}
{"table":"orderBookL2_25","action":"update","data":[{"symbol":"ETHUSDT","id":32401945550,"side":"Buy","size":1000,"price":3109.40,"timestamp":"2024-05-18T15:46:11.138Z"}]}
{"table":"orderBookL2_25","action":"insert","data":[{"symbol":"ETHUSDT","id":32402493704,"side":"Sell","size":32000,"price":3110.61,"timestamp":"2024-05-18T15:46:11.138Z"},{"symbol":"ETHUSDT","id":32402487305,"side":"Sell","size":100000,"price":3111.65,"timestamp":"2024-05-18T15:46:11.138Z"},{"symbol":"ETHUSDT","id":32402493717,"side":"Buy","size":32000,"price":3109.38,"timestamp":"2024-05-18T15:46:11.138Z"},{"symbol":"ETHUSDT","id":32402493700,"side":"Buy","size":1000,"price":3109.14,"timestamp":"2024-05-18T15:46:11.138Z"},{"symbol":"ETHUSDT","id":32402493715,"side":"Buy","size":32000,"price":3109.39,"timestamp":"2024-05-18T15:46:11.138Z"}]}
{"table":"orderBookL2_25","action":"delete","data":[{"symbol":"XBTUSDT","id":32402461579,"side":"Sell","price":66815.7,"timestamp":"2024-05-18T15:46:11.148Z"},{"symbol":"XBTUSDT","id":32402491950,"side":"Buy","price":66786.6,"timestamp":"2024-05-18T15:46:11.148Z"}]}
{"table":"orderBookL2_25","action":"update","data":[{"symbol":"XBTUSDT","id":32402491833,"side":"Buy","size":100000,"price":66744.0,"timestamp":"2024-05-18T15:46:11.148Z"}]}
{"table":"orderBookL2_25","action":"insert","data":[{"symbol":"XBTUSDT","id":32402493768,"side":"Sell","size":2000,"price":66801.4,"timestamp":"2024-05-18T15:46:11.148Z"},{"symbol":"XBTUSDT","id":32402493723,"side":"Buy","size":20000,"price":66786.1,"timestamp":"2024-05-18T15:46:11.148Z"}]}
{"table":"orderBookL2_25","action":"delete","data":[{"symbol":"ETHUSDT","id":32402493700,"side":"Buy","price":3109.14,"timestamp":"2024-05-18T15:46:11.187Z"},{"symbol":"ETHUSDT","id":32402493717,"side":"Buy","price":3109.38,"timestamp":"2024-05-18T15:46:11.187Z"},{"symbol":"ETHUSDT","id":32402493715,"side":"Buy","price":3109.39,"timestamp":"2024-05-18T15:46:11.187Z"},{"symbol":"ETHUSDT","id":32402487978,"side":"Buy","price":3107.98,"timestamp":"2024-05-18T15:46:11.187Z"},{"symbol":"ETHUSDT","id":32402488025,"side":"Buy","price":3107.08,"timestamp":"2024-05-18T15:46:11.187Z"}]}
{"table":"orderBookL2_25","action":"update","data":[{"symbol":"ETHUSDT","id":32402493347,"side":"Buy","size":66000,"price":3107.99,"timestamp":"2024-05-18T15:46:11.187Z"},{"symbol":"ETHUSDT","id":32401945550,"side":"Buy","size":25000,"price":3109.40,"timestamp":"2024-05-18T15:46:11.187Z"}]}
{"table":"orderBookL2_25","action":"insert","data":[{"symbol":"ETHUSDT","id":32402493816,"side":"Buy","size":675000,"price":3107.31,"timestamp":"2024-05-18T15:46:11.187Z"},{"symbol":"ETHUSDT","id":32402493830,"side":"Buy","size":32000,"price":3109.37,"timestamp":"2024-05-18T15:46:11.187Z"},{"symbol":"ETHUSDT","id":32402493824,"side":"Buy","size":32000,"price":3109.36,"timestamp":"2024-05-18T15:46:11.187Z"},{"symbol":"ETHUSDT","id":32402493804,"side":"Buy","size":533000,"price":3107.80,"timestamp":"2024-05-18T15:46:11.187Z"},{"symbol":"ETHUSDT","id":32402493799,"side":"Buy","size":1000,"price":3109.12,"timestamp":"2024-05-18T15:46:11.187Z"}]}
{"table":"orderBookL2_25","action":"delete","data":[{"symbol":"XBTUSDT","id":32402493529,"side":"Buy","price":66771.8,"timestamp":"2024-05-18T15:46:11.197Z"},{"symbol":"XBTUSDT","id":32402491833,"side":"Buy","price":66744.0,"timestamp":"2024-05-18T15:46:11.197Z"},{"symbol":"XBTUSDT","id":32402493535,"side":"Buy","price":66771.9,"timestamp":"2024-05-18T15:46:11.197Z"}]}
{"table":"orderBookL2_25","action":"update","data":[{"symbol":"XBTUSDT","id":32402492533,"side":"Buy","size":462000,"price":66772.1,"timestamp":"2024-05-18T15:46:11.197Z"}]}
{"table":"orderBookL2_25","action":"insert","data":[{"symbol":"XBTUSDT","id":32402493917,"side":"Buy","size":20000,"price":66772.0,"timestamp":"2024-05-18T15:46:11.197Z"},{"symbol":"XBTUSDT","id":32402493835,"side":"Buy","size":100000,"price":66778.3,"timestamp":"2024-05-18T15:46:11.197Z"},{"symbol":"XBTUSDT","id":32402493931,"side":"Buy","size":8000,"price":66780.1,"timestamp":"2024-05-18T15:46:11.197Z"}]}
{"table":"orderBookL2_25","action":"delete","data":[{"symbol":"ETHUSDT","id":32402493315,"side":"Sell","price":3109.78,"timestamp":"2024-05-18T15:46:11.236Z"},{"symbol":"ETHUSDT","id":32402493704,"side":"Sell","price":3110.61,"timestamp":"2024-05-18T15:46:11.236Z"},{"symbol":"ETHUSDT","id":32402492330,"side":"Sell","price":3109.79,"timestamp":"2024-05-18T15:46:11.236Z"},{"symbol":"ETHUSDT","id":32402493283,"side":"Sell","price":3110.60,"timestamp":"2024-05-18T15:46:11.236Z"},{"symbol":"ETHUSDT","id":32402493683,"side":"Buy","price":3109.13,"timestamp":"2024-05-18T15:46:11.236Z"},{"symbol":"ETHUSDT","id":32402493824,"side":"Buy","price":3109.36,"timestamp":"2024-05-18T15:46:11.236Z"},{"symbol":"ETHUSDT","id":32402493799,"side":"Buy","price":3109.12,"timestamp":"2024-05-18T15:46:11.236Z"},{"symbol":"ETHUSDT","id":32402493830,"side":"Buy","price":3109.37,"timestamp":"2024-05-18T15:46:11.236Z"}]}
{"table":"orderBookL2_25","action":"update","data":[{"symbol":"ETHUSDT","id":32402487305,"side":"Sell","size":100000,"price":3111.65,"timestamp":"2024-05-18T15:46:11.236Z"},{"symbol":"ETHUSDT","id":32402493174,"side":"Buy","size":75000,"price":3109.41,"timestamp":"2024-05-18T15:46:11.236Z"},{"symbol":"ETHUSDT","id":32401945550,"side":"Buy","size":57000,"price":3109.40,"timestamp":"2024-05-18T15:46:11.236Z"}]}
{"table":"orderBookL2_25","action":"insert","data":[{"symbol":"ETHUSDT","id":32402486025,"side":"Sell","size":337000,"price":3111.72,"timestamp":"2024-05-18T15:46:11.236Z"},{"symbol":"ETHUSDT","id":32402494049,"side":"Sell","size":25000,"price":3109.96,"timestamp":"2024-05-18T15:46:11.236Z"},{"symbol":"ETHUSDT","id":32402493971,"side":"Sell","size":32000,"price":3110.59,"timestamp":"2024-05-18T15:46:11.236Z"},{"symbol":"ETHUSDT","id":32402494039,"side":"Sell","size":32000,"price":3110.58,"timestamp":"2024-05-18T15:46:11.236Z"},{"symbol":"ETHUSDT","id":32402480341,"side":"Buy","size":942000,"price":3106.76,"timestamp":"2024-05-18T15:46:11.236Z"},{"symbol":"ETHUSDT","id":32402493928,"side":"Buy","size":1000,"price":3109.15,"timestamp":"2024-05-18T15:46:11.236Z"},{"symbol":"ETHUSDT","id":32402488025,"side":"Buy","size":100000,"price":3107.08,"timestamp":"2024-05-18T15:46:11.236Z"},{"symbol":"ETHUSDT","id":32402493982,"side":"Buy","size":1000,"price":3109.16,"timestamp":"2024-05-18T15:46:11.236Z"}]}
{"table":"orderBookL2_25","action":"delete","data":[{"symbol":"XBTUSDT","id":32402493384,"side":"Sell","price":66809.4,"timestamp":"2024-05-18T15:46:11.246Z"},{"symbol":"XBTUSDT","id":32402493293,"side":"Sell","price":66803.1,"timestamp":"2024-05-18T15:46:11.246Z"},{"symbol":"XBTUSDT","id":32402493440,"side":"Buy","price":66764.5,"timestamp":"2024-05-18T15:46:11.246Z"},{"symbol":"XBTUSDT","id":32402492536,"side":"Buy","price":66748.7,"timestamp":"2024-05-18T15:46:11.246Z"},{"symbol":"XBTUSDT","id":32402434478,"side":"Buy","price":66747.4,"timestamp":"2024-05-18T15:46:11.246Z"},{"symbol":"XBTUSDT","id":32402493917,"side":"Buy","price":66772.0,"timestamp":"2024-05-18T15:46:11.246Z"},{"symbol":"XBTUSDT","id":32402491723,"side":"Buy","price":66744.7,"timestamp":"2024-05-18T15:46:11.246Z"}]}
{"table":"orderBookL2_25","action":"update","data":[{"symbol":"XBTUSDT","id":32402492533,"side":"Buy","size":442000,"price":66772.1,"timestamp":"2024-05-18T15:46:11.246Z"},{"symbol":"XBTUSDT","id":32402493180,"side":"Buy","size":166000,"price":66772.2,"timestamp":"2024-05-18T15:46:11.246Z"}]}
{"table":"orderBookL2_25","action":"insert","data":[{"symbol":"XBTUSDT","id":32402494009,"side":"Sell","size":20000,"price":66803.1,"timestamp":"2024-05-18T15:46:11.246Z"},{"symbol":"XBTUSDT","id":32402493946,"side":"Sell","size":1000,"price":66809.6,"timestamp":"2024-05-18T15:46:11.246Z"},{"symbol":"XBTUSDT","id":32402493969,"side":"Buy","size":8000,"price":66776.2,"timestamp":"2024-05-18T15:46:11.246Z"},{"symbol":"XBTUSDT","id":32402494062,"side":"Buy","size":348000,"price":66767.9,"timestamp":"2024-05-18T15:46:11.246Z"},{"symbol":"XBTUSDT","id":32402494033,"side":"Buy","size":20000,"price":66771.9,"timestamp":"2024-05-18T15:46:11.246Z"},{"symbol":"XBTUSDT","id":32402494005,"side":"Buy","size":20000,"price":66771.8,"timestamp":"2024-05-18T15:46:11.246Z"},{"symbol":"XBTUSDT","id":32402494037,"side":"Buy","size":69000,"price":66772.7,"timestamp":"2024-05-18T15:46:11.246Z"}]}
{"table":"orderBookL2_25","action":"delete","data":[{"symbol":"ETHUSDT","id":32402493423,"side":"Sell","price":3110.55,"timestamp":"2024-05-18T15:46:11.285Z"},{"symbol":"ETHUSDT","id":32402486121,"side":"Sell","price":3111.30,"timestamp":"2024-05-18T15:46:11.285Z"},{"symbol":"ETHUSDT","id":32402493446,"side":"Sell","price":3110.74,"timestamp":"2024-05-18T15:46:11.285Z"},{"symbol":"ETHUSDT","id":32402493971,"side":"Sell","price":3110.59,"timestamp":"2024-05-18T15:46:11.285Z"},{"symbol":"ETHUSDT","id":32402492940,"side":"Sell","price":3109.60,"timestamp":"2024-05-18T15:46:11.285Z"},{"symbol":"ETHUSDT","id":32402493223,"side":"Sell","price":3110.56,"timestamp":"2024-05-18T15:46:11.285Z"},{"symbol":"ETHUSDT","id":32402489171,"side":"Sell","price":3110.75,"timestamp":"2024-05-18T15:46:11.285Z"},{"symbol":"ETHUSDT","id":32402486117,"side":"Sell","price":3111.31,"timestamp":"2024-05-18T15:46:11.285Z"},{"symbol":"ETHUSDT","id":32402480341,"side":"Buy","price":3106.76,"timestamp":"2024-05-18T15:46:11.285Z"},{"symbol":"ETHUSDT","id":32402493928,"side":"Buy","price":3109.15,"timestamp":"2024-05-18T15:46:11.285Z"},{"symbol":"ETHUSDT","id":32402492418,"side":"Buy","price":3108.68,"timestamp":"2024-05-18T15:46:11.285Z"},{"symbol":"ETHUSDT","id":32402488025,"side":"Buy","price":3107.08,"timestamp":"2024-05-18T15:46:11.285Z"},{"symbol":"ETHUSDT","id":32402493982,"side":"Buy","price":3109.16,"timestamp":"2024-05-18T15:46:11.285Z"}]}
{"table":"orderBookL2_25","action":"update","data":[{"symbol":"ETHUSDT","id":32402486025,"side":"Sell","size":337000,"price":3111.72,"timestamp":"2024-05-18T15:46:11.285Z"},{"symbol":"ETHUSDT","id":32402488018,"side":"Buy","size":1620000,"price":3107.17,"timestamp":"2024-05-18T15:46:11.285Z"},{"symbol":"ETHUSDT","id":32402493174,"side":"Buy","size":43000,"price":3109.41,"timestamp":"2024-05-18T15:46:11.285Z"},{"symbol":"ETHUSDT","id":32401945550,"side":"Buy","size":72000,"price":3109.40,"timestamp":"2024-05-18T15:46:11.285Z"}]}
{"table":"orderBookL2_25","action":"insert","data":[{"symbol":"ETHUSDT","id":32402494152,"side":"Sell","size":26000,"price":3110.74,"timestamp":"2024-05-18T15:46:11.285Z"},{"symbol":"ETHUSDT","id":32402494206,"side":"Sell","size":32000,"price":3110.57,"timestamp":"2024-05-18T15:46:11.285Z"},{"symbol":"ETHUSDT","id":32402461791,"side":"Sell","size":942000,"price":3112.06,"timestamp":"2024-05-18T15:46:11.285Z"},{"symbol":"ETHUSDT","id":32402494115,"side":"Sell","size":21000,"price":3109.59,"timestamp":"2024-05-18T15:46:11.285Z"},{"symbol":"ETHUSDT","id":32402494228,"side":"Sell","size":566000,"price":3112.00,"timestamp":"2024-05-18T15:46:11.285Z"},{"symbol":"ETHUSDT","id":32402493837,"side":"Sell","size":561000,"price":3112.01,"timestamp":"2024-05-18T15:46:11.285Z"},{"symbol":"ETHUSDT","id":32402455680,"side":"Sell","size":100000,"price":3112.02,"timestamp":"2024-05-18T15:46:11.285Z"},{"symbol":"ETHUSDT","id":32402493850,"side":"Sell","size":100000,"price":3111.81,"timestamp":"2024-05-18T15:46:11.285Z"},{"symbol":"ETHUSDT","id":32402494074,"side":"Buy","size":100000,"price":3108.93,"timestamp":"2024-05-18T15:46:11.285Z"},{"symbol":"ETHUSDT","id":32402494101,"side":"Buy","size":32000,"price":3109.43,"timestamp":"2024-05-18T15:46:11.285Z"},{"symbol":"ETHUSDT","id":32402494163,"side":"Buy","size":32000,"price":3109.44,"timestamp":"2024-05-18T15:46:11.285Z"},{"symbol":"ETHUSDT","id":32402494098,"side":"Buy","size":1000,"price":3109.19,"timestamp":"2024-05-18T15:46:11.285Z"},{"symbol":"ETHUSDT","id":32402494094,"side":"Buy","size":1000,"price":3109.18,"timestamp":"2024-05-18T15:46:11.285Z"}]}
{"table":"orderBookL2_25","action":"delete","data":[{"symbol":"XBTUSDT","id":32402493006,"side":"Sell","price":66811.3,"timestamp":"2024-05-18T15:46:11.295Z"},{"symbol":"XBTUSDT","id":32402493946,"side":"Sell","price":66809.6,"timestamp":"2024-05-18T15:46:11.295Z"},{"symbol":"XBTUSDT","id":32402493444,"side":"Sell","price":66801.7,"timestamp":"2024-05-18T15:46:11.295Z"},{"symbol":"XBTUSDT","id":32402493533,"side":"Sell","price":66801.6,"timestamp":"2024-05-18T15:46:11.295Z"},{"symbol":"XBTUSDT","id":32402494062,"side":"Buy","price":66767.9,"timestamp":"2024-05-18T15:46:11.295Z"}]}
{"table":"orderBookL2_25","action":"update","data":[{"symbol":"XBTUSDT","id":32402493768,"side":"Sell","size":207000,"price":66801.4,"timestamp":"2024-05-18T15:46:11.295Z"}]}
{"table":"orderBookL2_25","action":"insert","data":[{"symbol":"XBTUSDT","id":32402494160,"side":"Sell","size":349000,"price":66801.8,"timestamp":"2024-05-18T15:46:11.295Z"},{"symbol":"XBTUSDT","id":32402494175,"side":"Sell","size":3000,"price":66804.3,"timestamp":"2024-05-18T15:46:11.295Z"},{"symbol":"XBTUSDT","id":32402494078,"side":"Sell","size":1000,"price":66809.4,"timestamp":"2024-05-18T15:46:11.295Z"},{"symbol":"XBTUSDT","id":32402461579,"side":"Sell","size":100000,"price":66815.7,"timestamp":"2024-05-18T15:46:11.295Z"},{"symbol":"XBTUSDT","id":32402494156,"side":"Buy","size":347000,"price":66768.1,"timestamp":"2024-05-18T15:46:11.295Z"}]}
{"table":"orderBookL2_25","action":"delete","data":[{"symbol":"ETHUSDT","id":32402487998,"side":"Sell","price":3110.94,"timestamp":"2024-05-18T15:46:11.334Z"},{"symbol":"ETHUSDT","id":32402494206,"side":"Sell","price":3110.57,"timestamp":"2024-05-18T15:46:11.334Z"},{"symbol":"ETHUSDT","id":32402494039,"side":"Sell","price":3110.58,"timestamp":"2024-05-18T15:46:11.334Z"},{"symbol":"ETHUSDT","id":32402461791,"side":"Sell","price":3112.06,"timestamp":"2024-05-18T15:46:11.334Z"},{"symbol":"ETHUSDT","id":32402489313,"side":"Sell","price":3110.88,"timestamp":"2024-05-18T15:46:11.334Z"},{"symbol":"ETHUSDT","id":32402494094,"side":"Buy","price":3109.18,"timestamp":"2024-05-18T15:46:11.334Z"},{"symbol":"ETHUSDT","id":32402494098,"side":"Buy","price":3109.19,"timestamp":"2024-05-18T15:46:11.334Z"},{"symbol":"ETHUSDT","id":32402494101,"side":"Buy","price":3109.43,"timestamp":"2024-05-18T15:46:11.334Z"},{"symbol":"ETHUSDT","id":32402494163,"side":"Buy","price":3109.44,"timestamp":"2024-05-18T15:46:11.334Z"}]}
{"table":"orderBookL2_25","action":"insert","data":[{"symbol":"ETHUSDT","id":32402494311,"side":"Sell","size":32000,"price":3110.61,"timestamp":"2024-05-18T15:46:11.334Z"},{"symbol":"ETHUSDT","id":32402494234,"side":"Sell","size":62000,"price":3111.48,"timestamp":"2024-05-18T15:46:11.334Z"},{"symbol":"ETHUSDT","id":32402494289,"side":"Sell","size":2000,"price":3109.80,"timestamp":"2024-05-18T15:46:11.334Z"},{"symbol":"ETHUSDT","id":32402494335,"side":"Sell","size":32000,"price":3110.62,"timestamp":"2024-05-18T15:46:11.334Z"},{"symbol":"ETHUSDT","id":32402494285,"side":"Sell","size":100000,"price":3110.87,"timestamp":"2024-05-18T15:46:11.334Z"},{"symbol":"ETHUSDT","id":32402494315,"side":"Buy","size":32000,"price":3109.47,"timestamp":"2024-05-18T15:46:11.334Z"},{"symbol":"ETHUSDT","id":32402494276,"side":"Buy","size":1000,"price":3109.22,"timestamp":"2024-05-18T15:46:11.334Z"},{"symbol":"ETHUSDT","id":32402494309,"side":"Buy","size":1000,"price":3109.23,"timestamp":"2024-05-18T15:46:11.334Z"},{"symbol":"ETHUSDT","id":32402494239,"side":"Buy","size":32000,"price":3109.45,"timestamp":"2024-05-18T15:46:11.334Z"}]}
{"table":"orderBookL2_25","action":"delete","data":[{"symbol":"XBTUSDT","id":32402494009,"side":"Sell","price":66803.1,"timestamp":"2024-05-18T15:46:11.344Z"},{"symbol":"XBTUSDT","id":32402455324,"side":"Sell","price":66812.3,"timestamp":"2024-05-18T15:46:11.344Z"},{"symbol":"XBTUSDT","id":32402493343,"side":"Sell","price":66809.5,"timestamp":"2024-05-18T15:46:11.344Z"},{"symbol":"XBTUSDT","id":32402493236,"side":"Sell","price":66812.0,"timestamp":"2024-05-18T15:46:11.344Z"},{"symbol":"XBTUSDT","id":32402493337,"side":"Sell","price":66804.2,"timestamp":"2024-05-18T15:46:11.344Z"},{"symbol":"XBTUSDT","id":32402110415,"side":"Buy","price":66767.8,"timestamp":"2024-05-18T15:46:11.344Z"},{"symbol":"XBTUSDT","id":32402493239,"side":"Buy","price":66750.5,"timestamp":"2024-05-18T15:46:11.344Z"},{"symbol":"XBTUSDT","id":32402494033,"side":"Buy","price":66771.9,"timestamp":"2024-05-18T15:46:11.344Z"},{"symbol":"XBTUSDT","id":32402494005,"side":"Buy","price":66771.8,"timestamp":"2024-05-18T15:46:11.344Z"}]}
{"table":"orderBookL2_25","action":"update","data":[{"symbol":"XBTUSDT","id":32402461579,"side":"Sell","size":100000,"price":66815.7,"timestamp":"2024-05-18T15:46:11.344Z"},{"symbol":"XBTUSDT","id":32402480133,"side":"Sell","size":30000,"price":66803.0,"timestamp":"2024-05-18T15:46:11.344Z"},{"symbol":"XBTUSDT","id":32402492533,"side":"Buy","size":462000,"price":66772.1,"timestamp":"2024-05-18T15:46:11.344Z"},{"symbol":"XBTUSDT","id":32402493180,"side":"Buy","size":186000,"price":66772.2,"timestamp":"2024-05-18T15:46:11.344Z"}]}
{"table":"orderBookL2_25","action":"insert","data":[{"symbol":"XBTUSDT","id":32402492566,"side":"Sell","size":543000,"price":66817.9,"timestamp":"2024-05-18T15:46:11.344Z"},{"symbol":"XBTUSDT","id":32402494294,"side":"Sell","size":20000,"price":66802.9,"timestamp":"2024-05-18T15:46:11.344Z"},{"symbol":"XBTUSDT","id":32402494260,"side":"Sell","size":1000,"price":66809.3,"timestamp":"2024-05-18T15:46:11.344Z"},{"symbol":"XBTUSDT","id":32402493538,"side":"Sell","size":538000,"price":66821.2,"timestamp":"2024-05-18T15:46:11.344Z"},{"symbol":"XBTUSDT","id":32402494269,"side":"Sell","size":3000,"price":66800.4,"timestamp":"2024-05-18T15:46:11.344Z"},{"symbol":"XBTUSDT","id":32402494271,"side":"Buy","size":35000,"price":66778.0,"timestamp":"2024-05-18T15:46:11.344Z"},{"symbol":"XBTUSDT","id":32402434478,"side":"Buy","size":100000,"price":66747.4,"timestamp":"2024-05-18T15:46:11.344Z"},{"symbol":"XBTUSDT","id":32402494319,"side":"Buy","size":100000,"price":66769.2,"timestamp":"2024-05-18T15:46:11.344Z"},{"symbol":"XBTUSDT","id":32402492536,"side":"Buy","size":1348000,"price":66748.7,"timestamp":"2024-05-18T15:46:11.344Z"}]}
{"table":"orderBookL2_25","action":"delete","data":[{"symbol":"ETHUSDT","id":32402455680,"side":"Sell","price":3112.02,"timestamp":"2024-05-18T15:46:11.383Z"},{"symbol":"ETHUSDT","id":32402494335,"side":"Sell","price":3110.62,"timestamp":"2024-05-18T15:46:11.383Z"},{"symbol":"ETHUSDT","id":32402494234,"side":"Sell","price":3111.48,"timestamp":"2024-05-18T15:46:11.383Z"},{"symbol":"ETHUSDT","id":32402494289,"side":"Sell","price":3109.80,"timestamp":"2024-05-18T15:46:11.383Z"},{"symbol":"ETHUSDT","id":32402493837,"side":"Sell","price":3112.01,"timestamp":"2024-05-18T15:46:11.383Z"},{"symbol":"ETHUSDT","id":32402494115,"side":"Sell","price":3109.59,"timestamp":"2024-05-18T15:46:11.383Z"},{"symbol":"ETHUSDT","id":32402494315,"side":"Buy","price":3109.47,"timestamp":"2024-05-18T15:46:11.383Z"},{"symbol":"ETHUSDT","id":32402494276,"side":"Buy","price":3109.22,"timestamp":"2024-05-18T15:46:11.383Z"},{"symbol":"ETHUSDT","id":32402494309,"side":"Buy","price":3109.23,"timestamp":"2024-05-18T15:46:11.383Z"},{"symbol":"ETHUSDT","id":32402494239,"side":"Buy","price":3109.45,"timestamp":"2024-05-18T15:46:11.383Z"}]}
{"table":"orderBookL2_25","action":"update","data":[{"symbol":"ETHUSDT","id":32402488478,"side":"Sell","size":145000,"price":3111.05,"timestamp":"2024-05-18T15:46:11.383Z"},{"symbol":"ETHUSDT","id":32402494228,"side":"Sell","size":566000,"price":3112.00,"timestamp":"2024-05-18T15:46:11.383Z"}]}
{"table":"orderBookL2_25","action":"insert","data":[{"symbol":"ETHUSDT","id":32402494480,"side":"Sell","size":22000,"price":3110.67,"timestamp":"2024-05-18T15:46:11.383Z"},{"symbol":"ETHUSDT","id":32402494493,"side":"Sell","size":100000,"price":3111.26,"timestamp":"2024-05-18T15:46:11.383Z"},{"symbol":"ETHUSDT","id":32402494475,"side":"Sell","size":160000,"price":3111.21,"timestamp":"2024-05-18T15:46:11.383Z"},{"symbol":"ETHUSDT","id":32402494489,"side":"Sell","size":21000,"price":3109.58,"timestamp":"2024-05-18T15:46:11.383Z"},{"symbol":"ETHUSDT","id":32402494486,"side":"Sell","size":100000,"price":3111.20,"timestamp":"2024-05-18T15:46:11.383Z"},{"symbol":"ETHUSDT","id":32402494467,"side":"Sell","size":32000,"price":3110.68,"timestamp":"2024-05-18T15:46:11.383Z"},{"symbol":"ETHUSDT","id":32402494441,"side":"Buy","size":1000,"price":3109.21,"timestamp":"2024-05-18T15:46:11.383Z"},{"symbol":"ETHUSDT","id":32402494501,"side":"Buy","size":1000,"price":3109.20,"timestamp":"2024-05-18T15:46:11.383Z"},{"symbol":"ETHUSDT","id":32402494471,"side":"Buy","size":32000,"price":3109.46,"timestamp":"2024-05-18T15:46:11.383Z"},{"symbol":"ETHUSDT","id":32402494477,"side":"Buy","size":32000,"price":3109.45,"timestamp":"2024-05-18T15:46:11.383Z"}]}
{"table":"orderBookL2_25","action":"delete","data":[{"symbol":"XBTUSDT","id":32402494260,"side":"Sell","price":66809.3,"timestamp":"2024-05-18T15:46:11.393Z"},{"symbol":"XBTUSDT","id":32402493155,"side":"Sell","price":66804.1,"timestamp":"2024-05-18T15:46:11.393Z"},{"symbol":"XBTUSDT","id":32402494294,"side":"Sell","price":66802.9,"timestamp":"2024-05-18T15:46:11.393Z"},{"symbol":"XBTUSDT","id":32402494160,"side":"Sell","price":66801.8,"timestamp":"2024-05-18T15:46:11.393Z"},{"symbol":"XBTUSDT","id":32402493538,"side":"Sell","price":66821.2,"timestamp":"2024-05-18T15:46:11.393Z"},{"symbol":"XBTUSDT","id":32402494078,"side":"Sell","price":66809.4,"timestamp":"2024-05-18T15:46:11.393Z"},{"symbol":"XBTUSDT","id":32402492817,"side":"Buy","price":66774.8,"timestamp":"2024-05-18T15:46:11.393Z"},{"symbol":"XBTUSDT","id":32402492889,"side":"Buy","price":66750.8,"timestamp":"2024-05-18T15:46:11.393Z"},{"symbol":"XBTUSDT","id":32402492536,"side":"Buy","price":66748.7,"timestamp":"2024-05-18T15:46:11.393Z"},{"symbol":"XBTUSDT","id":32402434478,"side":"Buy","price":66747.4,"timestamp":"2024-05-18T15:46:11.393Z"},{"symbol":"XBTUSDT","id":32402494156,"side":"Buy","price":66768.1,"timestamp":"2024-05-18T15:46:11.393Z"}]}
{"table":"orderBookL2_25","action":"update","data":[{"symbol":"XBTUSDT","id":32402480133,"side":"Sell","size":10000,"price":66803.0,"timestamp":"2024-05-18T15:46:11.393Z"},{"symbol":"XBTUSDT","id":32402493768,"side":"Sell","size":2000,"price":66801.4,"timestamp":"2024-05-18T15:46:11.393Z"},{"symbol":"XBTUSDT","id":32402492533,"side":"Buy","size":442000,"price":66772.1,"timestamp":"2024-05-18T15:46:11.393Z"},{"symbol":"XBTUSDT","id":32402493180,"side":"Buy","size":166000,"price":66772.2,"timestamp":"2024-05-18T15:46:11.393Z"}]}
{"table":"orderBookL2_25","action":"insert","data":[{"symbol":"XBTUSDT","id":32402494510,"side":"Sell","size":20000,"price":66802.7,"timestamp":"2024-05-18T15:46:11.393Z"},{"symbol":"XBTUSDT","id":32402494448,"side":"Sell","size":349000,"price":66801.8,"timestamp":"2024-05-18T15:46:11.393Z"},{"symbol":"XBTUSDT","id":32402494521,"side":"Sell","size":1000,"price":66809.0,"timestamp":"2024-05-18T15:46:11.393Z"},{"symbol":"XBTUSDT","id":32402494412,"side":"Sell","size":207000,"price":66801.2,"timestamp":"2024-05-18T15:46:11.393Z"},{"symbol":"XBTUSDT","id":32402494469,"side":"Sell","size":1000,"price":66809.1,"timestamp":"2024-05-18T15:46:11.393Z"},{"symbol":"XBTUSDT","id":32402494512,"side":"Sell","size":20000,"price":66802.8,"timestamp":"2024-05-18T15:46:11.393Z"},{"symbol":"XBTUSDT","id":32402494393,"side":"Buy","size":156000,"price":66757.7,"timestamp":"2024-05-18T15:46:11.393Z"},{"symbol":"XBTUSDT","id":32402494517,"side":"Buy","size":20000,"price":66771.9,"timestamp":"2024-05-18T15:46:11.393Z"},{"symbol":"XBTUSDT","id":32402494533,"side":"Buy","size":22000,"price":66777.4,"timestamp":"2024-05-18T15:46:11.393Z"},{"symbol":"XBTUSDT","id":32402494445,"side":"Buy","size":347000,"price":66768.1,"timestamp":"2024-05-18T15:46:11.393Z"},{"symbol":"XBTUSDT","id":32402494508,"side":"Buy","size":20000,"price":66772.0,"timestamp":"2024-05-18T15:46:11.393Z"}]}
{"table":"orderBookL2_25","action":"delete","data":[{"symbol":"ETHUSDT","id":32402494480,"side":"Sell","price":3110.67,"timestamp":"2024-05-18T15:46:11.432Z"},{"symbol":"ETHUSDT","id":32402494152,"side":"Sell","price":3110.74,"timestamp":"2024-05-18T15:46:11.432Z"},{"symbol":"ETHUSDT","id":32402494467,"side":"Sell","price":3110.68,"timestamp":"2024-05-18T15:46:11.432Z"},{"symbol":"ETHUSDT","id":32402494311,"side":"Sell","price":3110.61,"timestamp":"2024-05-18T15:46:11.432Z"},{"symbol":"ETHUSDT","id":32402494228,"side":"Sell","price":3112.00,"timestamp":"2024-05-18T15:46:11.432Z"},{"symbol":"ETHUSDT","id":32402494471,"side":"Buy","price":3109.46,"timestamp":"2024-05-18T15:46:11.432Z"},{"symbol":"ETHUSDT","id":32402494501,"side":"Buy","price":3109.20,"timestamp":"2024-05-18T15:46:11.432Z"},{"symbol":"ETHUSDT","id":32402494441,"side":"Buy","price":3109.21,"timestamp":"2024-05-18T15:46:11.432Z"},{"symbol":"ETHUSDT","id":32402494477,"side":"Buy","price":3109.45,"timestamp":"2024-05-18T15:46:11.432Z"}]}
{"table":"orderBookL2_25","action":"update","data":[{"symbol":"ETHUSDT","id":32402493174,"side":"Buy","size":75000,"price":3109.41,"timestamp":"2024-05-18T15:46:11.432Z"}]}
{"table":"orderBookL2_25","action":"insert","data":[{"symbol":"ETHUSDT","id":32402494586,"side":"Sell","size":66000,"price":3110.86,"timestamp":"2024-05-18T15:46:11.432Z"},{"symbol":"ETHUSDT","id":32402494506,"side":"Sell","size":65000,"price":3111.48,"timestamp":"2024-05-18T15:46:11.432Z"},{"symbol":"ETHUSDT","id":32402494611,"side":"Sell","size":100000,"price":3110.70,"timestamp":"2024-05-18T15:46:11.432Z"},{"symbol":"ETHUSDT","id":32402494579,"side":"Sell","size":32000,"price":3110.84,"timestamp":"2024-05-18T15:46:11.432Z"},{"symbol":"ETHUSDT","id":32402494573,"side":"Sell","size":32000,"price":3110.83,"timestamp":"2024-05-18T15:46:11.432Z"},{"symbol":"ETHUSDT","id":32402488025,"side":"Buy","size":100000,"price":3107.08,"timestamp":"2024-05-18T15:46:11.432Z"},{"symbol":"ETHUSDT","id":32402494528,"side":"Buy","size":1000,"price":3109.17,"timestamp":"2024-05-18T15:46:11.432Z"},{"symbol":"ETHUSDT","id":32402494524,"side":"Buy","size":1000,"price":3109.18,"timestamp":"2024-05-18T15:46:11.432Z"},{"symbol":"ETHUSDT","id":32402494563,"side":"Buy","size":32000,"price":3109.42,"timestamp":"2024-05-18T15:46:11.432Z"}]}
{"table":"orderBookL2_25","action":"delete","data":[{"symbol":"XBTUSDT","id":32402494469,"side":"Sell","price":66809.1,"timestamp":"2024-05-18T15:46:11.442Z"},{"symbol":"XBTUSDT","id":32402494521,"side":"Sell","price":66809.0,"timestamp":"2024-05-18T15:46:11.442Z"},{"symbol":"XBTUSDT","id":32402494512,"side":"Sell","price":66802.8,"timestamp":"2024-05-18T15:46:11.442Z"},{"symbol":"XBTUSDT","id":32402494448,"side":"Sell","price":66801.8,"timestamp":"2024-05-18T15:46:11.442Z"},{"symbol":"XBTUSDT","id":32402493542,"side":"Sell","price":66805.2,"timestamp":"2024-05-18T15:46:11.442Z"},{"symbol":"XBTUSDT","id":32402494510,"side":"Sell","price":66802.7,"timestamp":"2024-05-18T15:46:11.442Z"},{"symbol":"XBTUSDT","id":32402494517,"side":"Buy","price":66771.9,"timestamp":"2024-05-18T15:46:11.442Z"},{"symbol":"XBTUSDT","id":32402494533,"side":"Buy","price":66777.4,"timestamp":"2024-05-18T15:46:11.442Z"},{"symbol":"XBTUSDT","id":32402494393,"side":"Buy","price":66757.7,"timestamp":"2024-05-18T15:46:11.442Z"},{"symbol":"XBTUSDT","id":32402494508,"side":"Buy","price":66772.0,"timestamp":"2024-05-18T15:46:11.442Z"}]}
{"table":"orderBookL2_25","action":"update","data":[{"symbol":"XBTUSDT","id":32402492566,"side":"Sell","size":543000,"price":66817.9,"timestamp":"2024-05-18T15:46:11.442Z"},{"symbol":"XBTUSDT","id":32402494412,"side":"Sell","size":66000,"price":66801.2,"timestamp":"2024-05-18T15:46:11.442Z"},{"symbol":"XBTUSDT","id":32402492533,"side":"Buy","size":462000,"price":66772.1,"timestamp":"2024-05-18T15:46:11.442Z"}]}
{"table":"orderBookL2_25","action":"insert","data":[{"symbol":"XBTUSDT","id":32402494555,"side":"Sell","size":375000,"price":66802.9,"timestamp":"2024-05-18T15:46:11.442Z"},{"symbol":"XBTUSDT","id":32402494569,"side":"Sell","size":220000,"price":66802.4,"timestamp":"2024-05-18T15:46:11.442Z"},{"symbol":"XBTUSDT","id":32402494599,"side":"Sell","size":1000,"price":66809.3,"timestamp":"2024-05-18T15:46:11.442Z"},{"symbol":"XBTUSDT","id":32402494597,"side":"Sell","size":1000,"price":66809.2,"timestamp":"2024-05-18T15:46:11.442Z"},{"symbol":"XBTUSDT","id":32402494626,"side":"Sell","size":20000,"price":66802.8,"timestamp":"2024-05-18T15:46:11.442Z"},{"symbol":"XBTUSDT","id":32402494575,"side":"Sell","size":52000,"price":66808.2,"timestamp":"2024-05-18T15:46:11.442Z"},{"symbol":"XBTUSDT","id":32402434478,"side":"Buy","size":100000,"price":66747.4,"timestamp":"2024-05-18T15:46:11.442Z"},{"symbol":"XBTUSDT","id":32402492536,"side":"Buy","size":1348000,"price":66748.7,"timestamp":"2024-05-18T15:46:11.442Z"},{"symbol":"XBTUSDT","id":32402494624,"side":"Buy","size":20000,"price":66772.0,"timestamp":"2024-05-18T15:46:11.442Z"},{"symbol":"XBTUSDT","id":32402492889,"side":"Buy","size":100000,"price":66750.8,"timestamp":"2024-05-18T15:46:11.442Z"}]}
{"table":"orderBookL2_25","action":"delete","data":[{"symbol":"ETHUSDT","id":32402493850,"side":"Sell","price":3111.81,"timestamp":"2024-05-18T15:46:11.481Z"},{"symbol":"ETHUSDT","id":32402494579,"side":"Sell","price":3110.84,"timestamp":"2024-05-18T15:46:11.481Z"},{"symbol":"ETHUSDT","id":32402494573,"side":"Sell","price":3110.83,"timestamp":"2024-05-18T15:46:11.481Z"},{"symbol":"ETHUSDT","id":32402494528,"side":"Buy","price":3109.17,"timestamp":"2024-05-18T15:46:11.481Z"},{"symbol":"ETHUSDT","id":32402488018,"side":"Buy","price":3107.17,"timestamp":"2024-05-18T15:46:11.481Z"},{"symbol":"ETHUSDT","id":32402494563,"side":"Buy","price":3109.42,"timestamp":"2024-05-18T15:46:11.481Z"},{"symbol":"ETHUSDT","id":32402488025,"side":"Buy","price":3107.08,"timestamp":"2024-05-18T15:46:11.481Z"},{"symbol":"ETHUSDT","id":32402494524,"side":"Buy","price":3109.18,"timestamp":"2024-05-18T15:46:11.481Z"}]}
{"table":"orderBookL2_25","action":"update","data":[{"symbol":"ETHUSDT","id":32402494285,"side":"Sell","size":132000,"price":3110.87,"timestamp":"2024-05-18T15:46:11.481Z"},{"symbol":"ETHUSDT","id":32402494586,"side":"Sell","size":98000,"price":3110.86,"timestamp":"2024-05-18T15:46:11.481Z"},{"symbol":"ETHUSDT","id":32402493174,"side":"Buy","size":43000,"price":3109.41,"timestamp":"2024-05-18T15:46:11.481Z"}]}
{"table":"orderBookL2_25","action":"insert","data":[{"symbol":"ETHUSDT","id":32402494707,"side":"Sell","size":68000,"price":3110.69,"timestamp":"2024-05-18T15:46:11.481Z"},{"symbol":"ETHUSDT","id":32402494704,"side":"Sell","size":25000,"price":3110.59,"timestamp":"2024-05-18T15:46:11.481Z"},{"symbol":"ETHUSDT","id":32402494719,"side":"Sell","size":21000,"price":3109.57,"timestamp":"2024-05-18T15:46:11.481Z"},{"symbol":"ETHUSDT","id":32402494665,"side":"Buy","size":32000,"price":3109.45,"timestamp":"2024-05-18T15:46:11.481Z"},{"symbol":"ETHUSDT","id":32402494717,"side":"Buy","size":1000,"price":3109.19,"timestamp":"2024-05-18T15:46:11.481Z"},{"symbol":"ETHUSDT","id":32402494641,"side":"Buy","size":1000,"price":3109.20,"timestamp":"2024-05-18T15:46:11.481Z"},{"symbol":"ETHUSDT","id":32402494676,"side":"Buy","size":462000,"price":3108.53,"timestamp":"2024-05-18T15:46:11.481Z"},{"symbol":"ETHUSDT","id":32402494713,"side":"Buy","size":32000,"price":3109.44,"timestamp":"2024-05-18T15:46:11.481Z"}]}
{"table":"orderBookL2_25","action":"delete","data":[{"symbol":"XBTUSDT","id":32402492566,"side":"Sell","price":66817.9,"timestamp":"2024-05-18T15:46:11.491Z"},{"symbol":"XBTUSDT","id":32402494599,"side":"Sell","price":66809.3,"timestamp":"2024-05-18T15:46:11.491Z"}]}
{"table":"orderBookL2_25","action":"insert","data":[{"symbol":"XBTUSDT","id":32402494644,"side":"Sell","size":1000,"price":66809.1,"timestamp":"2024-05-18T15:46:11.491Z"},{"symbol":"XBTUSDT","id":32402494673,"side":"Sell","size":20000,"price":66799.1,"timestamp":"2024-05-18T15:46:11.491Z"}]}
{"table":"orderBookL2_25","action":"delete","data":[{"symbol":"ETHUSDT","id":32402486025,"side":"Sell","price":3111.72,"timestamp":"2024-05-18T15:46:11.530Z"},{"symbol":"ETHUSDT","id":32402494489,"side":"Sell","price":3109.58,"timestamp":"2024-05-18T15:46:11.530Z"},{"symbol":"ETHUSDT","id":32402494074,"side":"Buy","price":3108.93,"timestamp":"2024-05-18T15:46:11.530Z"},{"symbol":"ETHUSDT","id":32402494665,"side":"Buy","price":3109.45,"timestamp":"2024-05-18T15:46:11.530Z"},{"symbol":"ETHUSDT","id":32402492538,"side":"Buy","price":3107.18,"timestamp":"2024-05-18T15:46:11.530Z"}]}
{"table":"orderBookL2_25","action":"update","data":[{"symbol":"ETHUSDT","id":32402494285,"side":"Sell","size":100000,"price":3110.87,"timestamp":"2024-05-18T15:46:11.530Z"}]}
{"table":"orderBookL2_25","action":"insert","data":[{"symbol":"ETHUSDT","id":32402494805,"side":"Sell","size":32000,"price":3110.85,"timestamp":"2024-05-18T15:46:11.530Z"},{"symbol":"ETHUSDT","id":32402494821,"side":"Sell","size":2000,"price":3109.80,"timestamp":"2024-05-18T15:46:11.530Z"},{"symbol":"ETHUSDT","id":32402494729,"side":"Buy","size":100000,"price":3108.81,"timestamp":"2024-05-18T15:46:11.530Z"},{"symbol":"ETHUSDT","id":32402494815,"side":"Buy","size":32000,"price":3109.43,"timestamp":"2024-05-18T15:46:11.530Z"},{"symbol":"ETHUSDT","id":32402494734,"side":"Buy","size":69000,"price":3108.82,"timestamp":"2024-05-18T15:46:11.530Z"}]}
{"table":"orderBookL2_25","action":"delete","data":[{"symbol":"XBTUSDT","id":32402494626,"side":"Sell","price":66802.8,"timestamp":"2024-05-18T15:46:11.540Z"},{"symbol":"XBTUSDT","id":32402461579,"side":"Sell","price":66815.7,"timestamp":"2024-05-18T15:46:11.540Z"},{"symbol":"XBTUSDT","id":32402494597,"side":"Sell","price":66809.2,"timestamp":"2024-05-18T15:46:11.540Z"},{"symbol":"XBTUSDT","id":32402494624,"side":"Buy","price":66772.0,"timestamp":"2024-05-18T15:46:11.540Z"},{"symbol":"XBTUSDT","id":32402434478,"side":"Buy","price":66747.4,"timestamp":"2024-05-18T15:46:11.540Z"}]}
{"table":"orderBookL2_25","action":"update","data":[{"symbol":"XBTUSDT","id":32402494555,"side":"Sell","size":355000,"price":66802.9,"timestamp":"2024-05-18T15:46:11.540Z"},{"symbol":"XBTUSDT","id":32402492533,"side":"Buy","size":442000,"price":66772.1,"timestamp":"2024-05-18T15:46:11.540Z"},{"symbol":"XBTUSDT","id":32402258708,"side":"Buy","size":14000,"price":66795.3,"timestamp":"2024-05-18T15:46:11.540Z"},{"symbol":"XBTUSDT","id":32402493180,"side":"Buy","size":166000,"price":66772.2,"timestamp":"2024-05-18T15:46:11.540Z"}]}
{"table":"orderBookL2_25","action":"insert","data":[{"symbol":"XBTUSDT","id":32402494779,"side":"Sell","size":1000,"price":66809.2,"timestamp":"2024-05-18T15:46:11.540Z"},{"symbol":"XBTUSDT","id":32402494777,"side":"Sell","size":20000,"price":66802.6,"timestamp":"2024-05-18T15:46:11.540Z"},{"symbol":"XBTUSDT","id":32402494782,"side":"Sell","size":20000,"price":66802.7,"timestamp":"2024-05-18T15:46:11.540Z"},{"symbol":"XBTUSDT","id":32402494855,"side":"Buy","size":20000,"price":66772.0,"timestamp":"2024-05-18T15:46:11.540Z"},{"symbol":"XBTUSDT","id":32402494794,"side":"Buy","size":20000,"price":66772.3,"timestamp":"2024-05-18T15:46:11.540Z"}]}
{"table":"orderBookL2_25","action":"delete","data":[{"symbol":"ETHUSDT","id":32402494821,"side":"Sell","price":3109.80,"timestamp":"2024-05-18T15:46:11.579Z"},{"symbol":"ETHUSDT","id":32402494717,"side":"Buy","price":3109.19,"timestamp":"2024-05-18T15:46:11.579Z"},{"symbol":"ETHUSDT","id":32402493347,"side":"Buy","price":3107.99,"timestamp":"2024-05-18T15:46:11.579Z"},{"symbol":"ETHUSDT","id":32402494641,"side":"Buy","price":3109.20,"timestamp":"2024-05-18T15:46:11.579Z"}]}
{"table":"orderBookL2_25","action":"update","data":[{"symbol":"ETHUSDT","id":32402480382,"side":"Buy","size":100000,"price":3107.24,"timestamp":"2024-05-18T15:46:11.579Z"}]}
{"table":"orderBookL2_25","action":"insert","data":[{"symbol":"ETHUSDT","id":32402486025,"side":"Sell","size":337000,"price":3111.72,"timestamp":"2024-05-18T15:46:11.579Z"},{"symbol":"ETHUSDT","id":32402494925,"side":"Buy","size":192000,"price":3108.23,"timestamp":"2024-05-18T15:46:11.579Z"},{"symbol":"ETHUSDT","id":32402494933,"side":"Buy","size":1000,"price":3109.18,"timestamp":"2024-05-18T15:46:11.579Z"},{"symbol":"ETHUSDT","id":32402494930,"side":"Buy","size":1000,"price":3109.17,"timestamp":"2024-05-18T15:46:11.579Z"}]}
{"table":"orderBookL2_25","action":"delete","data":[{"symbol":"XBTUSDT","id":32402494794,"side":"Buy","price":66772.3,"timestamp":"2024-05-18T15:46:11.589Z"}]}
{"table":"orderBookL2_25","action":"update","data":[{"symbol":"XBTUSDT","id":32402492533,"side":"Buy","size":462000,"price":66772.1,"timestamp":"2024-05-18T15:46:11.589Z"},{"symbol":"XBTUSDT","id":32402227172,"side":"Buy","size":19000,"price":66780.0,"timestamp":"2024-05-18T15:46:11.589Z"}]}
{"table":"orderBookL2_25","action":"insert","data":[{"symbol":"XBTUSDT","id":32402494904,"side":"Buy","size":8000,"price":66780.2,"timestamp":"2024-05-18T15:46:11.589Z"}]}
{"table":"orderBookL2_25","action":"delete","data":[{"symbol":"ETHUSDT","id":32402494719,"side":"Sell","price":3109.57,"timestamp":"2024-05-18T15:46:11.628Z"},{"symbol":"ETHUSDT","id":32402494815,"side":"Buy","price":3109.43,"timestamp":"2024-05-18T15:46:11.628Z"},{"symbol":"ETHUSDT","id":32402494713,"side":"Buy","price":3109.44,"timestamp":"2024-05-18T15:46:11.628Z"},{"symbol":"ETHUSDT","id":32402494930,"side":"Buy","price":3109.17,"timestamp":"2024-05-18T15:46:11.628Z"},{"symbol":"ETHUSDT","id":32402494933,"side":"Buy","price":3109.18,"timestamp":"2024-05-18T15:46:11.628Z"},{"symbol":"ETHUSDT","id":32402480382,"side":"Buy","price":3107.24,"timestamp":"2024-05-18T15:46:11.628Z"}]}
{"table":"orderBookL2_25","action":"update","data":[{"symbol":"ETHUSDT","id":32402486025,"side":"Sell","size":337000,"price":3111.72,"timestamp":"2024-05-18T15:46:11.628Z"},{"symbol":"ETHUSDT","id":32402487799,"side":"Sell","size":288000,"price":3111.06,"timestamp":"2024-05-18T15:46:11.628Z"},{"symbol":"ETHUSDT","id":32402493174,"side":"Buy","size":43000,"price":3109.41,"timestamp":"2024-05-18T15:46:11.628Z"}]}
{"table":"orderBookL2_25","action":"insert","data":[{"symbol":"ETHUSDT","id":32402494952,"side":"Sell","size":21000,"price":3109.56,"timestamp":"2024-05-18T15:46:11.628Z"},{"symbol":"ETHUSDT","id":32402494965,"side":"Buy","size":32000,"price":3109.44,"timestamp":"2024-05-18T15:46:11.628Z"},{"symbol":"ETHUSDT","id":32402494940,"side":"Buy","size":100000,"price":3108.13,"timestamp":"2024-05-18T15:46:11.628Z"},{"symbol":"ETHUSDT","id":32402494959,"side":"Buy","size":1000,"price":3109.18,"timestamp":"2024-05-18T15:46:11.628Z"},{"symbol":"ETHUSDT","id":32402494946,"side":"Buy","size":1000,"price":3109.19,"timestamp":"2024-05-18T15:46:11.628Z"},{"symbol":"ETHUSDT","id":32402494963,"side":"Buy","size":32000,"price":3109.43,"timestamp":"2024-05-18T15:46:11.628Z"}]}
{"table":"orderBookL2_25","action":"delete","data":[{"symbol":"XBTUSDT","id":32402492707,"side":"Sell","price":66810.7,"timestamp":"2024-05-18T15:46:11.638Z"},{"symbol":"XBTUSDT","id":32402494555,"side":"Sell","price":66802.9,"timestamp":"2024-05-18T15:46:11.638Z"},{"symbol":"XBTUSDT","id":32402494445,"side":"Buy","price":66768.1,"timestamp":"2024-05-18T15:46:11.638Z"}]}
{"table":"orderBookL2_25","action":"update","data":[{"symbol":"XBTUSDT","id":32402494412,"side":"Sell","size":202000,"price":66801.2,"timestamp":"2024-05-18T15:46:11.638Z"}]}
{"table":"orderBookL2_25","action":"insert","data":[{"symbol":"XBTUSDT","id":32402494978,"side":"Sell","size":69000,"price":66805.2,"timestamp":"2024-05-18T15:46:11.638Z"},{"symbol":"XBTUSDT","id":32402494973,"side":"Sell","size":350000,"price":66801.8,"timestamp":"2024-05-18T15:46:11.638Z"},{"symbol":"XBTUSDT","id":32402494971,"side":"Buy","size":383000,"price":66764.5,"timestamp":"2024-05-18T15:46:11.638Z"}]}
{"table":"orderBookL2_25","action":"delete","data":[{"symbol":"ETHUSDT","id":32402494946,"side":"Buy","price":3109.19,"timestamp":"2024-05-18T15:46:11.681Z"}]}
{"table":"orderBookL2_25","action":"insert","data":[{"symbol":"ETHUSDT","id":32402495012,"side":"Buy","size":1000,"price":3109.17,"timestamp":"2024-05-18T15:46:11.681Z"}]}
{"table":"orderBookL2_25","action":"delete","data":[{"symbol":"XBTUSDT","id":32402494575,"side":"Sell","price":66808.2,"timestamp":"2024-05-18T15:46:11.687Z"},{"symbol":"XBTUSDT","id":32402494569,"side":"Sell","price":66802.4,"timestamp":"2024-05-18T15:46:11.687Z"},{"symbol":"XBTUSDT","id":32402492536,"side":"Buy","price":66748.7,"timestamp":"2024-05-18T15:46:11.687Z"},{"symbol":"XBTUSDT","id":32402494971,"side":"Buy","price":66764.5,"timestamp":"2024-05-18T15:46:11.687Z"}]}
{"table":"orderBookL2_25","action":"insert","data":[{"symbol":"XBTUSDT","id":32402492707,"side":"Sell","size":159000,"price":66810.7,"timestamp":"2024-05-18T15:46:11.687Z"},{"symbol":"XBTUSDT","id":32402461579,"side":"Sell","size":100000,"price":66815.7,"timestamp":"2024-05-18T15:46:11.687Z"},{"symbol":"XBTUSDT","id":32402494980,"side":"Buy","size":74000,"price":66751.4,"timestamp":"2024-05-18T15:46:11.687Z"},{"symbol":"XBTUSDT","id":32402495023,"side":"Buy","size":348000,"price":66768.1,"timestamp":"2024-05-18T15:46:11.687Z"}]}
{"table":"orderBookL2_25","action":"delete","data":[{"symbol":"ETHUSDT","id":32402494965,"side":"Buy","price":3109.44,"timestamp":"2024-05-18T15:46:11.731Z"},{"symbol":"ETHUSDT","id":32402495012,"side":"Buy","price":3109.17,"timestamp":"2024-05-18T15:46:11.731Z"},{"symbol":"ETHUSDT","id":32402494963,"side":"Buy","price":3109.43,"timestamp":"2024-05-18T15:46:11.731Z"}]}
{"table":"orderBookL2_25","action":"update","data":[{"symbol":"ETHUSDT","id":32402486025,"side":"Sell","size":337000,"price":3111.72,"timestamp":"2024-05-18T15:46:11.731Z"},{"symbol":"ETHUSDT","id":32402494586,"side":"Sell","size":98000,"price":3110.86,"timestamp":"2024-05-18T15:46:11.731Z"},{"symbol":"ETHUSDT","id":32402493174,"side":"Buy","size":43000,"price":3109.41,"timestamp":"2024-05-18T15:46:11.731Z"}]}
{"table":"orderBookL2_25","action":"insert","data":[{"symbol":"ETHUSDT","id":32402495088,"side":"Buy","size":1000,"price":3109.19,"timestamp":"2024-05-18T15:46:11.731Z"},{"symbol":"ETHUSDT","id":32402495053,"side":"Buy","size":32000,"price":3109.43,"timestamp":"2024-05-18T15:46:11.731Z"},{"symbol":"ETHUSDT","id":32402495091,"side":"Buy","size":32000,"price":3109.44,"timestamp":"2024-05-18T15:46:11.731Z"}]}
{"table":"orderBookL2_25","action":"delete","data":[{"symbol":"XBTUSDT","id":32402494973,"side":"Sell","price":66801.8,"timestamp":"2024-05-18T15:46:11.736Z"},{"symbol":"XBTUSDT","id":32402494412,"side":"Sell","price":66801.2,"timestamp":"2024-05-18T15:46:11.736Z"},{"symbol":"XBTUSDT","id":32402492889,"side":"Buy","price":66750.8,"timestamp":"2024-05-18T15:46:11.736Z"},{"symbol":"XBTUSDT","id":32402495023,"side":"Buy","price":66768.1,"timestamp":"2024-05-18T15:46:11.736Z"}]}
{"table":"orderBookL2_25","action":"update","data":[{"symbol":"XBTUSDT","id":32402461579,"side":"Sell","size":100000,"price":66815.7,"timestamp":"2024-05-18T15:46:11.736Z"}]}
{"table":"orderBookL2_25","action":"insert","data":[{"symbol":"XBTUSDT","id":32402495043,"side":"Sell","size":209000,"price":66801.0,"timestamp":"2024-05-18T15:46:11.736Z"},{"symbol":"XBTUSDT","id":32402495039,"side":"Sell","size":347000,"price":66801.1,"timestamp":"2024-05-18T15:46:11.736Z"},{"symbol":"XBTUSDT","id":32402495049,"side":"Buy","size":878000,"price":66752.2,"timestamp":"2024-05-18T15:46:11.736Z"},{"symbol":"XBTUSDT","id":32402495037,"side":"Buy","size":379000,"price":66764.5,"timestamp":"2024-05-18T15:46:11.736Z"}]}
{"table":"orderBookL2_25","action":"delete","data":[{"symbol":"ETHUSDT","id":32402494959,"side":"Buy","price":3109.18,"timestamp":"2024-05-18T15:46:11.780Z"}]}
{"table":"orderBookL2_25","action":"insert","data":[{"symbol":"ETHUSDT","id":32402495118,"side":"Buy","size":1000,"price":3109.20,"timestamp":"2024-05-18T15:46:11.780Z"}]}
{"table":"orderBookL2_25","action":"delete","data":[{"symbol":"XBTUSDT","id":32402494777,"side":"Sell","price":66802.6,"timestamp":"2024-05-18T15:46:11.785Z"},{"symbol":"XBTUSDT","id":32402494175,"side":"Sell","price":66804.3,"timestamp":"2024-05-18T15:46:11.785Z"},{"symbol":"XBTUSDT","id":32402494644,"side":"Sell","price":66809.1,"timestamp":"2024-05-18T15:46:11.785Z"},{"symbol":"XBTUSDT","id":32402494779,"side":"Sell","price":66809.2,"timestamp":"2024-05-18T15:46:11.785Z"},{"symbol":"XBTUSDT","id":32402494980,"side":"Buy","price":66751.4,"timestamp":"2024-05-18T15:46:11.785Z"},{"symbol":"XBTUSDT","id":32402494855,"side":"Buy","price":66772.0,"timestamp":"2024-05-18T15:46:11.785Z"}]}
{"table":"orderBookL2_25","action":"update","data":[{"symbol":"XBTUSDT","id":32402492533,"side":"Buy","size":442000,"price":66772.1,"timestamp":"2024-05-18T15:46:11.785Z"},{"symbol":"XBTUSDT","id":32402493180,"side":"Buy","size":166000,"price":66772.2,"timestamp":"2024-05-18T15:46:11.785Z"}]}
{"table":"orderBookL2_25","action":"insert","data":[{"symbol":"XBTUSDT","id":32402495137,"side":"Sell","size":20000,"price":66802.8,"timestamp":"2024-05-18T15:46:11.785Z"},{"symbol":"XBTUSDT","id":32402495121,"side":"Sell","size":1000,"price":66809.2,"timestamp":"2024-05-18T15:46:11.785Z"},{"symbol":"XBTUSDT","id":32402495133,"side":"Sell","size":3000,"price":66800.3,"timestamp":"2024-05-18T15:46:11.785Z"},{"symbol":"XBTUSDT","id":32402495131,"side":"Sell","size":1000,"price":66809.1,"timestamp":"2024-05-18T15:46:11.785Z"},{"symbol":"XBTUSDT","id":32402495112,"side":"Buy","size":20000,"price":66772.3,"timestamp":"2024-05-18T15:46:11.785Z"},{"symbol":"XBTUSDT","id":32402495135,"side":"Buy","size":20000,"price":66772.4,"timestamp":"2024-05-18T15:46:11.785Z"}]}
{"table":"orderBookL2_25","action":"delete","data":[{"symbol":"XBTUSDT","id":32402492129,"side":"Buy","price":66752.1,"timestamp":"2024-05-18T15:46:11.834Z"}]}
{"table":"orderBookL2_25","action":"insert","data":[{"symbol":"XBTUSDT","id":32402495155,"side":"Buy","size":156000,"price":66752.3,"timestamp":"2024-05-18T15:46:11.834Z"}]}
{"table":"orderBookL2_25","action":"delete","data":[{"symbol":"XBTUSDT","id":32402493571,"side":"Buy","price":66776.1,"timestamp":"2024-05-18T15:46:11.883Z"},{"symbol":"XBTUSDT","id":32402493969,"side":"Buy","price":66776.2,"timestamp":"2024-05-18T15:46:11.883Z"}]}
{"table":"orderBookL2_25","action":"update","data":[{"symbol":"XBTUSDT","id":32402495049,"side":"Buy","size":878000,"price":66752.2,"timestamp":"2024-05-18T15:46:11.883Z"},{"symbol":"XBTUSDT","id":32402493931,"side":"Buy","size":16000,"price":66780.1,"timestamp":"2024-05-18T15:46:11.883Z"}]}
{"table":"orderBookL2_25","action":"insert","data":[{"symbol":"XBTUSDT","id":32402492129,"side":"Buy","size":1502000,"price":66752.1,"timestamp":"2024-05-18T15:46:11.883Z"},{"symbol":"XBTUSDT","id":32402495229,"side":"Buy","size":8000,"price":66780.3,"timestamp":"2024-05-18T15:46:11.883Z"}]}
{"table":"orderBookL2_25","action":"delete","data":[{"symbol":"XBTUSDT","id":32402461579,"side":"Sell","price":66815.7,"timestamp":"2024-05-18T15:46:11.932Z"},{"symbol":"XBTUSDT","id":32402495137,"side":"Sell","price":66802.8,"timestamp":"2024-05-18T15:46:11.932Z"},{"symbol":"XBTUSDT","id":32402495112,"side":"Buy","price":66772.3,"timestamp":"2024-05-18T15:46:11.932Z"},{"symbol":"XBTUSDT","id":32402492129,"side":"Buy","price":66752.1,"timestamp":"2024-05-18T15:46:11.932Z"}]}
{"table":"orderBookL2_25","action":"insert","data":[{"symbol":"XBTUSDT","id":32402495303,"side":"Sell","size":20000,"price":66802.6,"timestamp":"2024-05-18T15:46:11.932Z"},{"symbol":"XBTUSDT","id":32402495317,"side":"Sell","size":21000,"price":66797.7,"timestamp":"2024-05-18T15:46:11.932Z"},{"symbol":"XBTUSDT","id":32402495301,"side":"Buy","size":20000,"price":66772.5,"timestamp":"2024-05-18T15:46:11.932Z"},{"symbol":"XBTUSDT","id":32402495313,"side":"Buy","size":21000,"price":66776.9,"timestamp":"2024-05-18T15:46:11.932Z"}]}
{"table":"orderBookL2_25","action":"delete","data":[{"symbol":"XBTUSDT","id":32402495121,"side":"Sell","price":66809.2,"timestamp":"2024-05-18T15:46:12.023Z"}]}
{"table":"orderBookL2_25","action":"insert","data":[{"symbol":"XBTUSDT","id":32402495444,"side":"Sell","size":1000,"price":66809.0,"timestamp":"2024-05-18T15:46:12.023Z"}]}
{"table":"orderBookL2_25","action":"delete","data":[{"symbol":"XBTUSDT","id":32402495444,"side":"Sell","price":66809.0,"timestamp":"2024-05-18T15:46:12.072Z"},{"symbol":"XBTUSDT","id":32402494782,"side":"Sell","price":66802.7,"timestamp":"2024-05-18T15:46:12.072Z"},{"symbol":"XBTUSDT","id":32402472077,"side":"Sell","price":66810.2,"timestamp":"2024-05-18T15:46:12.072Z"},{"symbol":"XBTUSDT","id":32402495303,"side":"Sell","price":66802.6,"timestamp":"2024-05-18T15:46:12.072Z"},{"symbol":"XBTUSDT","id":32402495049,"side":"Buy","price":66752.2,"timestamp":"2024-05-18T15:46:12.072Z"}]}
{"table":"orderBookL2_25","action":"insert","data":[{"symbol":"XBTUSDT","id":32402495493,"side":"Sell","size":20000,"price":66802.7,"timestamp":"2024-05-18T15:46:12.072Z"},{"symbol":"XBTUSDT","id":32402495490,"side":"Sell","size":1000,"price":66809.2,"timestamp":"2024-05-18T15:46:12.072Z"},{"symbol":"XBTUSDT","id":32402461579,"side":"Sell","size":100000,"price":66815.7,"timestamp":"2024-05-18T15:46:12.072Z"},{"symbol":"XBTUSDT","id":32402495495,"side":"Sell","size":20000,"price":66802.6,"timestamp":"2024-05-18T15:46:12.072Z"},{"symbol":"XBTUSDT","id":32402495447,"side":"Buy","size":11000,"price":66787.3,"timestamp":"2024-05-18T15:46:12.072Z"}]}
{"table":"orderBookL2_25","action":"delete","data":[{"symbol":"XBTUSDT","id":32402495155,"side":"Buy","price":66752.3,"timestamp":"2024-05-18T15:46:12.121Z"}]}
{"table":"orderBookL2_25","action":"update","data":[{"symbol":"XBTUSDT","id":32402227172,"side":"Buy","size":3000,"price":66780.0,"timestamp":"2024-05-18T15:46:12.121Z"},{"symbol":"XBTUSDT","id":32402494904,"side":"Buy","size":16000,"price":66780.2,"timestamp":"2024-05-18T15:46:12.121Z"}]}
{"table":"orderBookL2_25","action":"insert","data":[{"symbol":"XBTUSDT","id":32402495535,"side":"Buy","size":8000,"price":66780.4,"timestamp":"2024-05-18T15:46:12.121Z"}]}
{"table":"orderBookL2_25","action":"delete","data":[{"symbol":"XBTUSDT","id":32402461579,"side":"Sell","price":66815.7,"timestamp":"2024-05-18T15:46:12.170Z"}]}
{"table":"orderBookL2_25","action":"update","data":[{"symbol":"XBTUSDT","id":32402491670,"side":"Sell","size":240000,"price":66795.5,"timestamp":"2024-05-18T15:46:12.170Z"},{"symbol":"XBTUSDT","id":32402491799,"side":"Sell","size":439000,"price":66795.4,"timestamp":"2024-05-18T15:46:12.170Z"},{"symbol":"XBTUSDT","id":32402492707,"side":"Sell","size":159000,"price":66810.7,"timestamp":"2024-05-18T15:46:12.170Z"}]}
{"table":"orderBookL2_25","action":"insert","data":[{"symbol":"XBTUSDT","id":32402495583,"side":"Sell","size":156000,"price":66797.6,"timestamp":"2024-05-18T15:46:12.170Z"}]}
{"table":"orderBookL2_25","action":"delete","data":[{"symbol":"XBTUSDT","id":32402489416,"side":"Buy","price":66757.6,"timestamp":"2024-05-18T15:46:12.219Z"}]}
{"table":"orderBookL2_25","action":"insert","data":[{"symbol":"XBTUSDT","id":32402495643,"side":"Buy","size":35000,"price":66781.4,"timestamp":"2024-05-18T15:46:12.219Z"}]}
{"table":"orderBookL2_25","action":"delete","data":[{"symbol":"XBTUSDT","id":32402495133,"side":"Sell","price":66800.3,"timestamp":"2024-05-18T15:46:12.268Z"},{"symbol":"XBTUSDT","id":32402494271,"side":"Buy","price":66778.0,"timestamp":"2024-05-18T15:46:12.268Z"}]}
{"table":"orderBookL2_25","action":"insert","data":[{"symbol":"XBTUSDT","id":32402495688,"side":"Sell","size":3000,"price":66803.3,"timestamp":"2024-05-18T15:46:12.268Z"},{"symbol":"XBTUSDT","id":32402489416,"side":"Buy","size":100000,"price":66757.6,"timestamp":"2024-05-18T15:46:12.268Z"}]}
{"table":"orderBookL2_25","action":"update","data":[{"symbol":"XBTUSDT","id":32402491799,"side":"Sell","size":440000,"price":66795.4,"timestamp":"2024-05-18T15:46:12.364Z"},{"symbol":"XBTUSDT","id":32402462668,"side":"Sell","size":101000,"price":66801.9,"timestamp":"2024-05-18T15:46:12.364Z"}]}
{"table":"orderBookL2_25","action":"delete","data":[{"symbol":"XBTUSDT","id":32402495490,"side":"Sell","price":66809.2,"timestamp":"2024-05-18T15:46:12.434Z"}]}
{"table":"orderBookL2_25","action":"insert","data":[{"symbol":"XBTUSDT","id":32402495842,"side":"Sell","size":1000,"price":66809.0,"timestamp":"2024-05-18T15:46:12.434Z"}]}
{"table":"orderBookL2_25","action":"delete","data":[{"symbol":"ETHUSDT","id":32402495088,"side":"Buy","price":3109.19,"timestamp":"2024-05-18T15:46:12.449Z"}]}
{"table":"orderBookL2_25","action":"insert","data":[{"symbol":"ETHUSDT","id":32402495866,"side":"Buy","size":1000,"price":3109.18,"timestamp":"2024-05-18T15:46:12.449Z"}]}
{"table":"orderBookL2_25","action":"delete","data":[{"symbol":"XBTUSDT","id":32402495317,"side":"Sell","price":66797.7,"timestamp":"2024-05-18T15:46:12.483Z"},{"symbol":"XBTUSDT","id":32402493931,"side":"Buy","price":66780.1,"timestamp":"2024-05-18T15:46:12.483Z"},{"symbol":"XBTUSDT","id":32402495447,"side":"Buy","price":66787.3,"timestamp":"2024-05-18T15:46:12.483Z"},{"symbol":"XBTUSDT","id":32402495313,"side":"Buy","price":66776.9,"timestamp":"2024-05-18T15:46:12.483Z"}]}
{"table":"orderBookL2_25","action":"update","data":[{"symbol":"XBTUSDT","id":32402489416,"side":"Buy","size":100000,"price":66757.6,"timestamp":"2024-05-18T15:46:12.483Z"}]}
{"table":"orderBookL2_25","action":"insert","data":[{"symbol":"XBTUSDT","id":32402461579,"side":"Sell","size":100000,"price":66815.7,"timestamp":"2024-05-18T15:46:12.483Z"},{"symbol":"XBTUSDT","id":32402495155,"side":"Buy","size":156000,"price":66752.3,"timestamp":"2024-05-18T15:46:12.483Z"},{"symbol":"XBTUSDT","id":32402495049,"side":"Buy","size":878000,"price":66752.2,"timestamp":"2024-05-18T15:46:12.483Z"},{"symbol":"XBTUSDT","id":32402495912,"side":"Buy","size":8000,"price":66781.5,"timestamp":"2024-05-18T15:46:12.483Z"}]}
{"table":"orderBookL2_25","action":"delete","data":[{"symbol":"ETHUSDT","id":32402493008,"side":"Sell","price":3109.97,"timestamp":"2024-05-18T15:46:12.498Z"},{"symbol":"ETHUSDT","id":32402494049,"side":"Sell","price":3109.96,"timestamp":"2024-05-18T15:46:12.498Z"},{"symbol":"ETHUSDT","id":32402494952,"side":"Sell","price":3109.56,"timestamp":"2024-05-18T15:46:12.498Z"},{"symbol":"ETHUSDT","id":32402495118,"side":"Buy","price":3109.20,"timestamp":"2024-05-18T15:46:12.498Z"},{"symbol":"ETHUSDT","id":32402495091,"side":"Buy","price":3109.44,"timestamp":"2024-05-18T15:46:12.498Z"},{"symbol":"ETHUSDT","id":32402494729,"side":"Buy","price":3108.81,"timestamp":"2024-05-18T15:46:12.498Z"},{"symbol":"ETHUSDT","id":32402495866,"side":"Buy","price":3109.18,"timestamp":"2024-05-18T15:46:12.498Z"},{"symbol":"ETHUSDT","id":32402494734,"side":"Buy","price":3108.82,"timestamp":"2024-05-18T15:46:12.498Z"},{"symbol":"ETHUSDT","id":32402495053,"side":"Buy","price":3109.43,"timestamp":"2024-05-18T15:46:12.498Z"}]}
{"table":"orderBookL2_25","action":"update","data":[{"symbol":"ETHUSDT","id":32402486025,"side":"Sell","size":337000,"price":3111.72,"timestamp":"2024-05-18T15:46:12.498Z"},{"symbol":"ETHUSDT","id":32402493174,"side":"Buy","size":43000,"price":3109.41,"timestamp":"2024-05-18T15:46:12.498Z"}]}
{"table":"orderBookL2_25","action":"insert","data":[{"symbol":"ETHUSDT","id":32402494228,"side":"Sell","size":566000,"price":3112.00,"timestamp":"2024-05-18T15:46:12.498Z"},{"symbol":"ETHUSDT","id":32402495895,"side":"Sell","size":21000,"price":3109.55,"timestamp":"2024-05-18T15:46:12.498Z"},{"symbol":"ETHUSDT","id":32402493850,"side":"Sell","size":100000,"price":3111.81,"timestamp":"2024-05-18T15:46:12.498Z"},{"symbol":"ETHUSDT","id":32402495905,"side":"Buy","size":32000,"price":3109.44,"timestamp":"2024-05-18T15:46:12.498Z"},{"symbol":"ETHUSDT","id":32402495956,"side":"Buy","size":60000,"price":3108.81,"timestamp":"2024-05-18T15:46:12.498Z"},{"symbol":"ETHUSDT","id":32402495945,"side":"Buy","size":100000,"price":3108.80,"timestamp":"2024-05-18T15:46:12.498Z"},{"symbol":"ETHUSDT","id":32402495899,"side":"Buy","size":1000,"price":3109.19,"timestamp":"2024-05-18T15:46:12.498Z"},{"symbol":"ETHUSDT","id":32402495962,"side":"Buy","size":1000,"price":3109.20,"timestamp":"2024-05-18T15:46:12.498Z"},{"symbol":"ETHUSDT","id":32402495914,"side":"Buy","size":32000,"price":3109.43,"timestamp":"2024-05-18T15:46:12.498Z"}]}
{"table":"orderBookL2_25","action":"delete","data":[{"symbol":"XBTUSDT","id":32402495155,"side":"Buy","price":66752.3,"timestamp":"2024-05-18T15:46:12.532Z"}]}
{"table":"orderBookL2_25","action":"update","data":[{"symbol":"XBTUSDT","id":32402495912,"side":"Buy","size":16000,"price":66781.5,"timestamp":"2024-05-18T15:46:12.532Z"}]}
{"table":"orderBookL2_25","action":"insert","data":[{"symbol":"XBTUSDT","id":32402495966,"side":"Buy","size":156000,"price":66757.7,"timestamp":"2024-05-18T15:46:12.532Z"}]}
{"table":"orderBookL2_25","action":"delete","data":[{"symbol":"ETHUSDT","id":32402486025,"side":"Sell","price":3111.72,"timestamp":"2024-05-18T15:46:12.547Z"},{"symbol":"ETHUSDT","id":32402494228,"side":"Sell","price":3112.00,"timestamp":"2024-05-18T15:46:12.547Z"},{"symbol":"ETHUSDT","id":32402493850,"side":"Sell","price":3111.81,"timestamp":"2024-05-18T15:46:12.547Z"}]}
{"table":"orderBookL2_25","action":"insert","data":[{"symbol":"ETHUSDT","id":32402495989,"side":"Sell","size":2000,"price":3110.08,"timestamp":"2024-05-18T15:46:12.547Z"},{"symbol":"ETHUSDT","id":32402495997,"side":"Sell","size":18000,"price":3109.89,"timestamp":"2024-05-18T15:46:12.547Z"},{"symbol":"ETHUSDT","id":32402495987,"side":"Sell","size":29000,"price":3109.90,"timestamp":"2024-05-18T15:46:12.547Z"}]}
{"table":"orderBookL2_25","action":"delete","data":[{"symbol":"XBTUSDT","id":32402495842,"side":"Sell","price":66809.0,"timestamp":"2024-05-18T15:46:12.581Z"}]}
{"table":"orderBookL2_25","action":"insert","data":[{"symbol":"XBTUSDT","id":32402496013,"side":"Sell","size":1000,"price":66809.2,"timestamp":"2024-05-18T15:46:12.581Z"}]}
{"table":"orderBookL2_25","action":"delete","data":[{"symbol":"XBTUSDT","id":32402495049,"side":"Buy","price":66752.2,"timestamp":"2024-05-18T15:46:12.725Z"}]}
{"table":"orderBookL2_25","action":"insert","data":[{"symbol":"XBTUSDT","id":32402496187,"side":"Buy","size":22000,"price":66775.6,"timestamp":"2024-05-18T15:46:12.725Z"}]}
{"table":"orderBookL2_25","action":"delete","data":[{"symbol":"XBTUSDT","id":32402489416,"side":"Buy","price":66757.6,"timestamp":"2024-05-18T15:46:12.775Z"}]}
{"table":"orderBookL2_25","action":"insert","data":[{"symbol":"XBTUSDT","id":32402496190,"side":"Buy","size":99000,"price":66757.8,"timestamp":"2024-05-18T15:46:12.775Z"}]}
{"table":"orderBookL2_25","action":"delete","data":[{"symbol":"XBTUSDT","id":32402496187,"side":"Buy","price":66775.6,"timestamp":"2024-05-18T15:46:12.825Z"}]}
{"table":"orderBookL2_25","action":"insert","data":[{"symbol":"XBTUSDT","id":32402489416,"side":"Buy","size":100000,"price":66757.6,"timestamp":"2024-05-18T15:46:12.825Z"}]}
{"table":"orderBookL2_25","action":"delete","data":[{"symbol":"ETHUSDT","id":32402495962,"side":"Buy","price":3109.20,"timestamp":"2024-05-18T15:46:12.850Z"}]}
{"table":"orderBookL2_25","action":"insert","data":[{"symbol":"ETHUSDT","id":32402496268,"side":"Buy","size":1000,"price":3109.18,"timestamp":"2024-05-18T15:46:12.850Z"}]}
{"table":"orderBookL2_25","action":"delete","data":[{"symbol":"XBTUSDT","id":32402496013,"side":"Sell","price":66809.2,"timestamp":"2024-05-18T15:46:12.875Z"}]}
{"table":"orderBookL2_25","action":"update","data":[{"symbol":"XBTUSDT","id":32402258708,"side":"Buy","size":4000,"price":66795.3,"timestamp":"2024-05-18T15:46:12.875Z"}]}
{"table":"orderBookL2_25","action":"insert","data":[{"symbol":"XBTUSDT","id":32402496265,"side":"Sell","size":1000,"price":66809.0,"timestamp":"2024-05-18T15:46:12.875Z"}]}
{"table":"orderBookL2_25","action":"delete","data":[{"symbol":"ETHUSDT","id":32402496268,"side":"Buy","price":3109.18,"timestamp":"2024-05-18T15:46:12.900Z"}]}
{"table":"orderBookL2_25","action":"insert","data":[{"symbol":"ETHUSDT","id":32402496272,"side":"Buy","size":1000,"price":3109.20,"timestamp":"2024-05-18T15:46:12.900Z"}]}
{"table":"orderBookL2_25","action":"delete","data":[{"symbol":"XBTUSDT","id":32402496265,"side":"Sell","price":66809.0,"timestamp":"2024-05-18T15:46:12.924Z"}]}
{"table":"orderBookL2_25","action":"insert","data":[{"symbol":"XBTUSDT","id":32402496302,"side":"Sell","size":1000,"price":66809.0,"timestamp":"2024-05-18T15:46:12.924Z"}]}
{"table":"orderBookL2_25","action":"delete","data":[{"symbol":"XBTUSDT","id":32402494904,"side":"Buy","price":66780.2,"timestamp":"2024-05-18T15:46:12.973Z"}]}
{"table":"orderBookL2_25","action":"update","data":[{"symbol":"XBTUSDT","id":32402495643,"side":"Buy","size":51000,"price":66781.4,"timestamp":"2024-05-18T15:46:12.973Z"}]}
{"table":"orderBookL2_25","action":"insert","data":[{"symbol":"XBTUSDT","id":32402495049,"side":"Buy","size":878000,"price":66752.2,"timestamp":"2024-05-18T15:46:12.973Z"}]}
{"table":"orderBookL2_25","action":"delete","data":[{"symbol":"XBTUSDT","id":32402496302,"side":"Sell","price":66809.0,"timestamp":"2024-05-18T15:46:13.024Z"}]}
{"table":"orderBookL2_25","action":"insert","data":[{"symbol":"XBTUSDT","id":32402496374,"side":"Sell","size":1000,"price":66809.2,"timestamp":"2024-05-18T15:46:13.024Z"}]}
{"table":"orderBookL2_25","action":"delete","data":[{"symbol":"XBTUSDT","id":32402496374,"side":"Sell","price":66809.2,"timestamp":"2024-05-18T15:46:13.073Z"},{"symbol":"XBTUSDT","id":32402495495,"side":"Sell","price":66802.6,"timestamp":"2024-05-18T15:46:13.073Z"},{"symbol":"XBTUSDT","id":32402495131,"side":"Sell","price":66809.1,"timestamp":"2024-05-18T15:46:13.073Z"},{"symbol":"XBTUSDT","id":32402248654,"side":"Buy","price":66776.0,"timestamp":"2024-05-18T15:46:13.073Z"},{"symbol":"XBTUSDT","id":32402495135,"side":"Buy","price":66772.4,"timestamp":"2024-05-18T15:46:13.073Z"}]}
{"table":"orderBookL2_25","action":"update","data":[{"symbol":"XBTUSDT","id":32402494037,"side":"Buy","size":71000,"price":66772.7,"timestamp":"2024-05-18T15:46:13.073Z"},{"symbol":"XBTUSDT","id":32402489150,"side":"Buy","size":100000,"price":66772.6,"timestamp":"2024-05-18T15:46:13.073Z"}]}
{"table":"orderBookL2_25","action":"insert","data":[{"symbol":"XBTUSDT","id":32402496404,"side":"Sell","size":1000,"price":66809.0,"timestamp":"2024-05-18T15:46:13.073Z"},{"symbol":"XBTUSDT","id":32402496408,"side":"Sell","size":20000,"price":66802.6,"timestamp":"2024-05-18T15:46:13.073Z"},{"symbol":"XBTUSDT","id":32402496390,"side":"Sell","size":1000,"price":66809.1,"timestamp":"2024-05-18T15:46:13.073Z"},{"symbol":"XBTUSDT","id":32402496406,"side":"Buy","size":20000,"price":66772.4,"timestamp":"2024-05-18T15:46:13.073Z"},{"symbol":"XBTUSDT","id":32402492129,"side":"Buy","size":1502000,"price":66752.1,"timestamp":"2024-05-18T15:46:13.073Z"}]}
{"table":"orderBookL2_25","action":"delete","data":[{"symbol":"XBTUSDT","id":32402492129,"side":"Buy","price":66752.1,"timestamp":"2024-05-18T15:46:13.185Z"}]}
{"table":"orderBookL2_25","action":"insert","data":[{"symbol":"XBTUSDT","id":32402496547,"side":"Buy","size":13000,"price":66768.5,"timestamp":"2024-05-18T15:46:13.185Z"}]}
{"table":"orderBookL2_25","action":"delete","data":[{"symbol":"XBTUSDT","id":32402495229,"side":"Buy","price":66780.3,"timestamp":"2024-05-18T15:46:13.234Z"}]}
{"table":"orderBookL2_25","action":"insert","data":[{"symbol":"XBTUSDT","id":32402496594,"side":"Buy","size":8000,"price":66780.5,"timestamp":"2024-05-18T15:46:13.234Z"}]}
{"table":"orderBookL2_25","action":"update","data":[{"symbol":"XBTUSDT","id":32402491799,"side":"Sell","size":441000,"price":66795.4,"timestamp":"2024-05-18T15:46:13.283Z"},{"symbol":"XBTUSDT","id":32402462668,"side":"Sell","size":100000,"price":66801.9,"timestamp":"2024-05-18T15:46:13.283Z"}]}
{"table":"orderBookL2_25","action":"delete","data":[{"symbol":"XBTUSDT","id":32402496404,"side":"Sell","price":66809.0,"timestamp":"2024-05-18T15:46:13.350Z"}]}
{"table":"orderBookL2_25","action":"insert","data":[{"symbol":"XBTUSDT","id":32402496704,"side":"Sell","size":1000,"price":66809.2,"timestamp":"2024-05-18T15:46:13.350Z"}]}
{"table":"orderBookL2_25","action":"delete","data":[{"symbol":"ETHUSDT","id":32402494805,"side":"Sell","price":3110.85,"timestamp":"2024-05-18T15:46:13.365Z"}]}
{"table":"orderBookL2_25","action":"insert","data":[{"symbol":"ETHUSDT","id":32402496731,"side":"Sell","size":32000,"price":3110.88,"timestamp":"2024-05-18T15:46:13.365Z"}]}
{"table":"orderBookL2_25","action":"delete","data":[{"symbol":"XBTUSDT","id":32402495493,"side":"Sell","price":66802.7,"timestamp":"2024-05-18T15:46:13.399Z"},{"symbol":"XBTUSDT","id":32402496408,"side":"Sell","price":66802.6,"timestamp":"2024-05-18T15:46:13.399Z"},{"symbol":"XBTUSDT","id":32402496406,"side":"Buy","price":66772.4,"timestamp":"2024-05-18T15:46:13.399Z"},{"symbol":"XBTUSDT","id":32402495301,"side":"Buy","price":66772.5,"timestamp":"2024-05-18T15:46:13.399Z"},{"symbol":"XBTUSDT","id":32402495535,"side":"Buy","price":66780.4,"timestamp":"2024-05-18T15:46:13.399Z"}]}
{"table":"orderBookL2_25","action":"update","data":[{"symbol":"XBTUSDT","id":32402480133,"side":"Sell","size":10000,"price":66803.0,"timestamp":"2024-05-18T15:46:13.399Z"},{"symbol":"XBTUSDT","id":32402494037,"side":"Buy","size":71000,"price":66772.7,"timestamp":"2024-05-18T15:46:13.399Z"}]}
{"table":"orderBookL2_25","action":"insert","data":[{"symbol":"XBTUSDT","id":32402496782,"side":"Sell","size":20000,"price":66802.7,"timestamp":"2024-05-18T15:46:13.399Z"},{"symbol":"XBTUSDT","id":32402496772,"side":"Sell","size":20000,"price":66802.6,"timestamp":"2024-05-18T15:46:13.399Z"},{"symbol":"XBTUSDT","id":32402496767,"side":"Buy","size":20000,"price":66772.5,"timestamp":"2024-05-18T15:46:13.399Z"},{"symbol":"XBTUSDT","id":32402496751,"side":"Buy","size":8000,"price":66780.6,"timestamp":"2024-05-18T15:46:13.399Z"},{"symbol":"XBTUSDT","id":32402496770,"side":"Buy","size":20000,"price":66772.4,"timestamp":"2024-05-18T15:46:13.399Z"}]}
{"table":"orderBookL2_25","action":"delete","data":[{"symbol":"ETHUSDT","id":32402494707,"side":"Sell","price":3110.69,"timestamp":"2024-05-18T15:46:13.415Z"},{"symbol":"ETHUSDT","id":32402496731,"side":"Sell","price":3110.88,"timestamp":"2024-05-18T15:46:13.415Z"},{"symbol":"ETHUSDT","id":32402494611,"side":"Sell","price":3110.70,"timestamp":"2024-05-18T15:46:13.415Z"},{"symbol":"ETHUSDT","id":32402495905,"side":"Buy","price":3109.44,"timestamp":"2024-05-18T15:46:13.415Z"},{"symbol":"ETHUSDT","id":32402495914,"side":"Buy","price":3109.43,"timestamp":"2024-05-18T15:46:13.415Z"},{"symbol":"ETHUSDT","id":32402458908,"side":"Buy","price":3107.30,"timestamp":"2024-05-18T15:46:13.415Z"}]}
{"table":"orderBookL2_25","action":"update","data":[{"symbol":"ETHUSDT","id":32402494285,"side":"Sell","size":100000,"price":3110.87,"timestamp":"2024-05-18T15:46:13.415Z"},{"symbol":"ETHUSDT","id":32402494586,"side":"Sell","size":98000,"price":3110.86,"timestamp":"2024-05-18T15:46:13.415Z"}]}
{"table":"orderBookL2_25","action":"insert","data":[{"symbol":"ETHUSDT","id":32402486025,"side":"Sell","size":337000,"price":3111.72,"timestamp":"2024-05-18T15:46:13.415Z"},{"symbol":"ETHUSDT","id":32402496785,"side":"Sell","size":32000,"price":3110.85,"timestamp":"2024-05-18T15:46:13.415Z"},{"symbol":"ETHUSDT","id":32402493850,"side":"Sell","size":100000,"price":3111.81,"timestamp":"2024-05-18T15:46:13.415Z"},{"symbol":"ETHUSDT","id":32402496774,"side":"Buy","size":241000,"price":3109.47,"timestamp":"2024-05-18T15:46:13.415Z"},{"symbol":"ETHUSDT","id":32402496787,"side":"Buy","size":32000,"price":3109.43,"timestamp":"2024-05-18T15:46:13.415Z"},{"symbol":"ETHUSDT","id":32402496790,"side":"Buy","size":32000,"price":3109.44,"timestamp":"2024-05-18T15:46:13.415Z"}]}
{"table":"orderBookL2_25","action":"delete","data":[{"symbol":"XBTUSDT","id":32402496704,"side":"Sell","price":66809.2,"timestamp":"2024-05-18T15:46:13.448Z"},{"symbol":"XBTUSDT","id":32402496772,"side":"Sell","price":66802.6,"timestamp":"2024-05-18T15:46:13.448Z"},{"symbol":"XBTUSDT","id":32402495049,"side":"Buy","price":66752.2,"timestamp":"2024-05-18T15:46:13.448Z"},{"symbol":"XBTUSDT","id":32402496770,"side":"Buy","price":66772.4,"timestamp":"2024-05-18T15:46:13.448Z"}]}
{"table":"orderBookL2_25","action":"update","data":[{"symbol":"XBTUSDT","id":32402491799,"side":"Sell","size":452000,"price":66795.4,"timestamp":"2024-05-18T15:46:13.448Z"},{"symbol":"XBTUSDT","id":32402489150,"side":"Buy","size":120000,"price":66772.6,"timestamp":"2024-05-18T15:46:13.448Z"},{"symbol":"XBTUSDT","id":32402489416,"side":"Buy","size":100000,"price":66757.6,"timestamp":"2024-05-18T15:46:13.448Z"}]}
{"table":"orderBookL2_25","action":"insert","data":[{"symbol":"XBTUSDT","id":32402496825,"side":"Sell","size":20000,"price":66802.8,"timestamp":"2024-05-18T15:46:13.448Z"},{"symbol":"XBTUSDT","id":32402496823,"side":"Sell","size":1000,"price":66809.0,"timestamp":"2024-05-18T15:46:13.448Z"},{"symbol":"XBTUSDT","id":32402496802,"side":"Buy","size":10000,"price":66785.1,"timestamp":"2024-05-18T15:46:13.448Z"},{"symbol":"XBTUSDT","id":32402496808,"side":"Buy","size":22000,"price":66775.1,"timestamp":"2024-05-18T15:46:13.448Z"}]}
{"table":"orderBookL2_25","action":"delete","data":[{"symbol":"ETHUSDT","id":32402495989,"side":"Sell","price":3110.08,"timestamp":"2024-05-18T15:46:13.464Z"}]}
{"table":"orderBookL2_25","action":"insert","data":[{"symbol":"ETHUSDT","id":32402494228,"side":"Sell","size":566000,"price":3112.00,"timestamp":"2024-05-18T15:46:13.464Z"}]}
{"table":"orderBookL2_25","action":"delete","data":[{"symbol":"XBTUSDT","id":32402496825,"side":"Sell","price":66802.8,"timestamp":"2024-05-18T15:46:13.497Z"},{"symbol":"XBTUSDT","id":32402491650,"side":"Sell","price":66795.6,"timestamp":"2024-05-18T15:46:13.497Z"},{"symbol":"XBTUSDT","id":32402496190,"side":"Buy","price":66757.8,"timestamp":"2024-05-18T15:46:13.497Z"},{"symbol":"XBTUSDT","id":32402495966,"side":"Buy","price":66757.7,"timestamp":"2024-05-18T15:46:13.497Z"}]}
{"table":"orderBookL2_25","action":"update","data":[{"symbol":"XBTUSDT","id":32402491670,"side":"Sell","size":208000,"price":66795.5,"timestamp":"2024-05-18T15:46:13.497Z"},{"symbol":"XBTUSDT","id":32402489150,"side":"Buy","size":100000,"price":66772.6,"timestamp":"2024-05-18T15:46:13.497Z"},{"symbol":"XBTUSDT","id":32402489416,"side":"Buy","size":100000,"price":66757.6,"timestamp":"2024-05-18T15:46:13.497Z"}]}
{"table":"orderBookL2_25","action":"insert","data":[{"symbol":"XBTUSDT","id":32402496833,"side":"Sell","size":20000,"price":66802.6,"timestamp":"2024-05-18T15:46:13.497Z"},{"symbol":"XBTUSDT","id":32402496194,"side":"Sell","size":332000,"price":66817.8,"timestamp":"2024-05-18T15:46:13.497Z"},{"symbol":"XBTUSDT","id":32402496879,"side":"Buy","size":156000,"price":66752.3,"timestamp":"2024-05-18T15:46:13.497Z"},{"symbol":"XBTUSDT","id":32402496835,"side":"Buy","size":20000,"price":66772.4,"timestamp":"2024-05-18T15:46:13.497Z"}]}
{"table":"orderBookL2_25","action":"delete","data":[{"symbol":"ETHUSDT","id":32402495987,"side":"Sell","price":3109.90,"timestamp":"2024-05-18T15:46:13.513Z"},{"symbol":"ETHUSDT","id":32402495895,"side":"Sell","price":3109.55,"timestamp":"2024-05-18T15:46:13.513Z"},{"symbol":"ETHUSDT","id":32402495997,"side":"Sell","price":3109.89,"timestamp":"2024-05-18T15:46:13.513Z"},{"symbol":"ETHUSDT","id":32402494285,"side":"Sell","price":3110.87,"timestamp":"2024-05-18T15:46:13.513Z"}]}
{"table":"orderBookL2_25","action":"update","data":[{"symbol":"ETHUSDT","id":32402494586,"side":"Sell","size":32000,"price":3110.86,"timestamp":"2024-05-18T15:46:13.513Z"}]}
{"table":"orderBookL2_25","action":"insert","data":[{"symbol":"ETHUSDT","id":32402496883,"side":"Sell","size":28000,"price":3110.60,"timestamp":"2024-05-18T15:46:13.513Z"},{"symbol":"ETHUSDT","id":32402496877,"side":"Sell","size":63000,"price":3110.84,"timestamp":"2024-05-18T15:46:13.513Z"},{"symbol":"ETHUSDT","id":32402493837,"side":"Sell","size":561000,"price":3112.01,"timestamp":"2024-05-18T15:46:13.513Z"},{"symbol":"ETHUSDT","id":32402496871,"side":"Sell","size":100000,"price":3110.88,"timestamp":"2024-05-18T15:46:13.513Z"}]}
{"table":"orderBookL2_25","action":"update","data":[{"symbol":"XBTETH","id":32402417548,"side":"Buy","size":7,"price":20.969,"timestamp":"2024-05-18T15:46:13.530Z"}]}
{"table":"orderBookL2_25","action":"delete","data":[{"symbol":"ETHUSDT","id":32402493837,"side":"Sell","price":3112.01,"timestamp":"2024-05-18T15:46:13.562Z"}]}
{"table":"orderBookL2_25","action":"insert","data":[{"symbol":"ETHUSDT","id":32402496937,"side":"Sell","size":2000,"price":3110.08,"timestamp":"2024-05-18T15:46:13.562Z"}]}
{"table":"orderBookL2_25","action":"delete","data":[{"symbol":"XBTUSDT","id":32402495688,"side":"Sell","price":66803.3,"timestamp":"2024-05-18T15:46:13.570Z"}]}
{"table":"orderBookL2_25","action":"insert","data":[{"symbol":"XBTUSDT","id":32402496941,"side":"Sell","size":3000,"price":66807.4,"timestamp":"2024-05-18T15:46:13.570Z"}]}
{"table":"orderBookL2_25","action":"update","data":[{"symbol":"XBTETH","id":32402417798,"side":"Sell","size":7,"price":22.044,"timestamp":"2024-05-18T15:46:13.579Z"}]}
{"table":"orderBookL2_25","action":"delete","data":[{"symbol":"ETHUSDT","id":32402493850,"side":"Sell","price":3111.81,"timestamp":"2024-05-18T15:46:13.611Z"},{"symbol":"ETHUSDT","id":32402494228,"side":"Sell","price":3112.00,"timestamp":"2024-05-18T15:46:13.611Z"}]}
{"table":"orderBookL2_25","action":"insert","data":[{"symbol":"ETHUSDT","id":32402496943,"side":"Sell","size":28000,"price":3110.44,"timestamp":"2024-05-18T15:46:13.611Z"},{"symbol":"ETHUSDT","id":32402496946,"side":"Sell","size":21000,"price":3110.58,"timestamp":"2024-05-18T15:46:13.611Z"}]}
{"table":"orderBookL2_25","action":"delete","data":[{"symbol":"ETHUSDT","id":32402496883,"side":"Sell","price":3110.60,"timestamp":"2024-05-18T15:46:13.660Z"}]}
{"table":"orderBookL2_25","action":"insert","data":[{"symbol":"ETHUSDT","id":32402493850,"side":"Sell","size":100000,"price":3111.81,"timestamp":"2024-05-18T15:46:13.660Z"}]}
{"table":"orderBookL2_25","action":"delete","data":[{"symbol":"XBTUSDT","id":32402496751,"side":"Buy","price":66780.6,"timestamp":"2024-05-18T15:46:13.676Z"}]}
{"table":"orderBookL2_25","action":"insert","data":[{"symbol":"XBTUSDT","id":32402495049,"side":"Buy","size":878000,"price":66752.2,"timestamp":"2024-05-18T15:46:13.676Z"}]}
{"table":"orderBookL2_25","action":"delete","data":[{"symbol":"XBTUSDT","id":32402495049,"side":"Buy","price":66752.2,"timestamp":"2024-05-18T15:46:13.726Z"}]}
{"table":"orderBookL2_25","action":"insert","data":[{"symbol":"XBTUSDT","id":32402496991,"side":"Buy","size":8000,"price":66786.2,"timestamp":"2024-05-18T15:46:13.726Z"}]}
{"table":"orderBookL2_25","action":"delete","data":[{"symbol":"XBTUSDT","id":32402496767,"side":"Buy","price":66772.5,"timestamp":"2024-05-18T15:46:13.775Z"},{"symbol":"XBTUSDT","id":32402496835,"side":"Buy","price":66772.4,"timestamp":"2024-05-18T15:46:13.775Z"}]}
{"table":"orderBookL2_25","action":"update","data":[{"symbol":"XBTUSDT","id":32402494037,"side":"Buy","size":91000,"price":66772.7,"timestamp":"2024-05-18T15:46:13.775Z"},{"symbol":"XBTUSDT","id":32402489150,"side":"Buy","size":120000,"price":66772.6,"timestamp":"2024-05-18T15:46:13.775Z"}]}
{"table":"orderBookL2_25","action":"insert","data":[{"symbol":"XBTUSDT","id":32402495049,"side":"Buy","size":878000,"price":66752.2,"timestamp":"2024-05-18T15:46:13.775Z"},{"symbol":"XBTUSDT","id":32402497038,"side":"Buy","size":68000,"price":66761.1,"timestamp":"2024-05-18T15:46:13.775Z"}]}
{"table":"orderBookL2_25","action":"delete","data":[{"symbol":"XBTUSDT","id":32402496782,"side":"Sell","price":66802.7,"timestamp":"2024-05-18T15:46:13.824Z"},{"symbol":"XBTUSDT","id":32402495049,"side":"Buy","price":66752.2,"timestamp":"2024-05-18T15:46:13.824Z"},{"symbol":"XBTUSDT","id":32402496879,"side":"Buy","price":66752.3,"timestamp":"2024-05-18T15:46:13.824Z"},{"symbol":"XBTUSDT","id":32402489416,"side":"Buy","price":66757.6,"timestamp":"2024-05-18T15:46:13.824Z"}]}
{"table":"orderBookL2_25","action":"update","data":[{"symbol":"XBTUSDT","id":32402494037,"side":"Buy","size":71000,"price":66772.7,"timestamp":"2024-05-18T15:46:13.824Z"},{"symbol":"XBTUSDT","id":32402489150,"side":"Buy","size":100000,"price":66772.6,"timestamp":"2024-05-18T15:46:13.824Z"}]}
{"table":"orderBookL2_25","action":"insert","data":[{"symbol":"XBTUSDT","id":32402497065,"side":"Sell","size":20000,"price":66802.7,"timestamp":"2024-05-18T15:46:13.824Z"},{"symbol":"XBTUSDT","id":32402497060,"side":"Buy","size":156000,"price":66757.7,"timestamp":"2024-05-18T15:46:13.824Z"},{"symbol":"XBTUSDT","id":32402497062,"side":"Buy","size":20000,"price":66772.9,"timestamp":"2024-05-18T15:46:13.824Z"},{"symbol":"XBTUSDT","id":32402497057,"side":"Buy","size":20000,"price":66772.8,"timestamp":"2024-05-18T15:46:13.824Z"}]}
{"table":"orderBookL2_25","action":"delete","data":[{"symbol":"ETHUSDT","id":32402493850,"side":"Sell","price":3111.81,"timestamp":"2024-05-18T15:46:13.845Z"}]}
{"table":"orderBookL2_25","action":"insert","data":[{"symbol":"ETHUSDT","id":32402497089,"side":"Sell","size":2000,"price":3109.92,"timestamp":"2024-05-18T15:46:13.845Z"}]}
{"table":"orderBookL2_25","action":"delete","data":[{"symbol":"XBTUSDT","id":32402496594,"side":"Buy","price":66780.5,"timestamp":"2024-05-18T15:46:13.877Z"}]}
{"table":"orderBookL2_25","action":"insert","data":[{"symbol":"XBTUSDT","id":32402489416,"side":"Buy","size":100000,"price":66757.6,"timestamp":"2024-05-18T15:46:13.877Z"}]}
{"table":"orderBookL2_25","action":"delete","data":[{"symbol":"ETHUSDT","id":32402496937,"side":"Sell","price":3110.08,"timestamp":"2024-05-18T15:46:13.895Z"}]}
{"table":"orderBookL2_25","action":"insert","data":[{"symbol":"ETHUSDT","id":32402497099,"side":"Sell","size":28000,"price":3110.28,"timestamp":"2024-05-18T15:46:13.895Z"}]}
{"table":"orderBookL2_25","action":"delete","data":[{"symbol":"XBTUSDT","id":32402489416,"side":"Buy","price":66757.6,"timestamp":"2024-05-18T15:46:13.927Z"}]}
{"table":"orderBookL2_25","action":"insert","data":[{"symbol":"XBTUSDT","id":32402497110,"side":"Buy","size":8000,"price":66786.3,"timestamp":"2024-05-18T15:46:13.927Z"}]}
{"table":"orderBookL2_25","action":"delete","data":[{"symbol":"ETHUSDT","id":32402496943,"side":"Sell","price":3110.44,"timestamp":"2024-05-18T15:46:13.944Z"},{"symbol":"ETHUSDT","id":32402496946,"side":"Sell","price":3110.58,"timestamp":"2024-05-18T15:46:13.944Z"},{"symbol":"ETHUSDT","id":32402496272,"side":"Buy","price":3109.20,"timestamp":"2024-05-18T15:46:13.944Z"}]}
{"table":"orderBookL2_25","action":"insert","data":[{"symbol":"ETHUSDT","id":32402494228,"side":"Sell","size":566000,"price":3112.00,"timestamp":"2024-05-18T15:46:13.944Z"},{"symbol":"ETHUSDT","id":32402493850,"side":"Sell","size":100000,"price":3111.81,"timestamp":"2024-05-18T15:46:13.944Z"},{"symbol":"ETHUSDT","id":32402497159,"side":"Buy","size":1000,"price":3109.18,"timestamp":"2024-05-18T15:46:13.944Z"}]}
{"table":"orderBookL2_25","action":"delete","data":[{"symbol":"XBTUSDT","id":32402497065,"side":"Sell","price":66802.7,"timestamp":"2024-05-18T15:46:13.976Z"},{"symbol":"XBTUSDT","id":32402497060,"side":"Buy","price":66757.7,"timestamp":"2024-05-18T15:46:13.976Z"},{"symbol":"XBTUSDT","id":32402497062,"side":"Buy","price":66772.9,"timestamp":"2024-05-18T15:46:13.976Z"}]}
{"table":"orderBookL2_25","action":"update","data":[{"symbol":"XBTUSDT","id":32402494037,"side":"Buy","size":91000,"price":66772.7,"timestamp":"2024-05-18T15:46:13.976Z"},{"symbol":"XBTUSDT","id":32402493723,"side":"Buy","size":28000,"price":66786.1,"timestamp":"2024-05-18T15:46:13.976Z"},{"symbol":"XBTUSDT","id":32402495643,"side":"Buy","size":43000,"price":66781.4,"timestamp":"2024-05-18T15:46:13.976Z"}]}
{"table":"orderBookL2_25","action":"insert","data":[{"symbol":"XBTUSDT","id":32402497155,"side":"Sell","size":20000,"price":66802.5,"timestamp":"2024-05-18T15:46:13.976Z"},{"symbol":"XBTUSDT","id":32402495049,"side":"Buy","size":878000,"price":66752.2,"timestamp":"2024-05-18T15:46:13.976Z"},{"symbol":"XBTUSDT","id":32402489416,"side":"Buy","size":100000,"price":66757.6,"timestamp":"2024-05-18T15:46:13.976Z"}]}
{"table":"orderBookL2_25","action":"delete","data":[{"symbol":"XBTUSDT","id":32402497155,"side":"Sell","price":66802.5,"timestamp":"2024-05-18T15:46:14.025Z"},{"symbol":"XBTUSDT","id":32402497057,"side":"Buy","price":66772.8,"timestamp":"2024-05-18T15:46:14.025Z"}]}
{"table":"orderBookL2_25","action":"update","data":[{"symbol":"XBTUSDT","id":32402489150,"side":"Buy","size":100000,"price":66772.6,"timestamp":"2024-05-18T15:46:14.025Z"}]}
{"table":"orderBookL2_25","action":"insert","data":[{"symbol":"XBTUSDT","id":32402497214,"side":"Sell","size":20000,"price":66802.5,"timestamp":"2024-05-18T15:46:14.025Z"},{"symbol":"XBTUSDT","id":32402497212,"side":"Buy","size":20000,"price":66772.8,"timestamp":"2024-05-18T15:46:14.025Z"}]}
{"table":"orderBookL2_25","action":"delete","data":[{"symbol":"XBTUSDT","id":32402495049,"side":"Buy","price":66752.2,"timestamp":"2024-05-18T15:46:14.092Z"}]}
{"table":"orderBookL2_25","action":"insert","data":[{"symbol":"XBTUSDT","id":32402497256,"side":"Buy","size":156000,"price":66752.3,"timestamp":"2024-05-18T15:46:14.092Z"}]}
{"table":"orderBookL2_25","action":"delete","data":[{"symbol":"XBTUSDT","id":32402496941,"side":"Sell","price":66807.4,"timestamp":"2024-05-18T15:46:14.141Z"}]}
{"table":"orderBookL2_25","action":"update","data":[{"symbol":"XBTUSDT","id":32402494037,"side":"Buy","size":89000,"price":66772.7,"timestamp":"2024-05-18T15:46:14.141Z"}]}
{"table":"orderBookL2_25","action":"insert","data":[{"symbol":"XBTUSDT","id":32402497284,"side":"Sell","size":3000,"price":66803.3,"timestamp":"2024-05-18T15:46:14.141Z"}]}
{"table":"orderBookL2_25","action":"delete","data":[{"symbol":"ETHUSDT","id":32402494228,"side":"Sell","price":3112.00,"timestamp":"2024-05-18T15:46:14.160Z"}]}
{"table":"orderBookL2_25","action":"insert","data":[{"symbol":"ETHUSDT","id":32402497307,"side":"Sell","size":2000,"price":3109.76,"timestamp":"2024-05-18T15:46:14.160Z"}]}
{"table":"orderBookL2_25","action":"update","data":[{"symbol":"XBTUSDT","id":32402493835,"side":"Buy","size":102000,"price":66778.3,"timestamp":"2024-05-18T15:46:14.190Z"}]}
{"table":"orderBookL2_25","action":"delete","data":[{"symbol":"ETHUSDT","id":32402497089,"side":"Sell","price":3109.92,"timestamp":"2024-05-18T15:46:14.210Z"},{"symbol":"ETHUSDT","id":32402497307,"side":"Sell","price":3109.76,"timestamp":"2024-05-18T15:46:14.210Z"},{"symbol":"ETHUSDT","id":32402493804,"side":"Buy","price":3107.80,"timestamp":"2024-05-18T15:46:14.210Z"}]}
{"table":"orderBookL2_25","action":"insert","data":[{"symbol":"ETHUSDT","id":32402493837,"side":"Sell","size":561000,"price":3112.01,"timestamp":"2024-05-18T15:46:14.210Z"},{"symbol":"ETHUSDT","id":32402494228,"side":"Sell","size":566000,"price":3112.00,"timestamp":"2024-05-18T15:46:14.210Z"},{"symbol":"ETHUSDT","id":32402497351,"side":"Buy","size":515000,"price":3108.30,"timestamp":"2024-05-18T15:46:14.210Z"}]}
{"table":"orderBookL2_25","action":"delete","data":[{"symbol":"XBTUSDT","id":32402497256,"side":"Buy","price":66752.3,"timestamp":"2024-05-18T15:46:14.239Z"}]}
{"table":"orderBookL2_25","action":"update","data":[{"symbol":"XBTUSDT","id":32402495643,"side":"Buy","size":35000,"price":66781.4,"timestamp":"2024-05-18T15:46:14.239Z"},{"symbol":"XBTUSDT","id":32402495912,"side":"Buy","size":8000,"price":66781.5,"timestamp":"2024-05-18T15:46:14.239Z"}]}
{"table":"orderBookL2_25","action":"insert","data":[{"symbol":"XBTUSDT","id":32402497374,"side":"Buy","size":16000,"price":66785.2,"timestamp":"2024-05-18T15:46:14.239Z"}]}
{"table":"orderBookL2_25","action":"delete","data":[{"symbol":"ETHUSDT","id":32402497099,"side":"Sell","price":3110.28,"timestamp":"2024-05-18T15:46:14.259Z"}]}
{"table":"orderBookL2_25","action":"update","data":[{"symbol":"ETHUSDT","id":32402493837,"side":"Sell","size":561000,"price":3112.01,"timestamp":"2024-05-18T15:46:14.259Z"}]}
{"table":"orderBookL2_25","action":"insert","data":[{"symbol":"ETHUSDT","id":32402497388,"side":"Sell","size":28000,"price":3110.60,"timestamp":"2024-05-18T15:46:14.259Z"}]}
{"table":"orderBookL2_25","action":"delete","data":[{"symbol":"XBTUSDT","id":32402489416,"side":"Buy","price":66757.6,"timestamp":"2024-05-18T15:46:14.298Z"}]}
{"table":"orderBookL2_25","action":"insert","data":[{"symbol":"XBTUSDT","id":32402497537,"side":"Buy","size":156000,"price":66757.7,"timestamp":"2024-05-18T15:46:14.298Z"}]}
{"table":"orderBookL2_25","action":"delete","data":[{"symbol":"ETHUSDT","id":32402494228,"side":"Sell","price":3112.00,"timestamp":"2024-05-18T15:46:14.308Z"},{"symbol":"ETHUSDT","id":32402493837,"side":"Sell","price":3112.01,"timestamp":"2024-05-18T15:46:14.308Z"},{"symbol":"ETHUSDT","id":32402493850,"side":"Sell","price":3111.81,"timestamp":"2024-05-18T15:46:14.308Z"},{"symbol":"ETHUSDT","id":32402486025,"side":"Sell","price":3111.72,"timestamp":"2024-05-18T15:46:14.308Z"}]}
{"table":"orderBookL2_25","action":"insert","data":[{"symbol":"ETHUSDT","id":32402497513,"side":"Sell","size":23000,"price":3110.58,"timestamp":"2024-05-18T15:46:14.308Z"},{"symbol":"ETHUSDT","id":32402497480,"side":"Sell","size":65000,"price":3110.08,"timestamp":"2024-05-18T15:46:14.308Z"},{"symbol":"ETHUSDT","id":32402497462,"side":"Sell","size":100000,"price":3110.09,"timestamp":"2024-05-18T15:46:14.308Z"},{"symbol":"ETHUSDT","id":32402497507,"side":"Sell","size":28000,"price":3110.44,"timestamp":"2024-05-18T15:46:14.308Z"}]}
{"table":"orderBookL2_25","action":"delete","data":[{"symbol":"XBTUSDT","id":32402496390,"side":"Sell","price":66809.1,"timestamp":"2024-05-18T15:46:14.347Z"}]}
{"table":"orderBookL2_25","action":"insert","data":[{"symbol":"XBTUSDT","id":32402497572,"side":"Sell","size":1000,"price":66808.9,"timestamp":"2024-05-18T15:46:14.347Z"}]}
{"table":"orderBookL2_25","action":"delete","data":[{"symbol":"ETHUSDT","id":32402497388,"side":"Sell","price":3110.60,"timestamp":"2024-05-18T15:46:14.357Z"}]}
{"table":"orderBookL2_25","action":"insert","data":[{"symbol":"ETHUSDT","id":32402486025,"side":"Sell","size":337000,"price":3111.72,"timestamp":"2024-05-18T15:46:14.357Z"}]}
{"table":"orderBookL2_25","action":"delete","data":[{"symbol":"XBTUSDT","id":32402497572,"side":"Sell","price":66808.9,"timestamp":"2024-05-18T15:46:14.462Z"}]}
{"table":"orderBookL2_25","action":"insert","data":[{"symbol":"XBTUSDT","id":32402497669,"side":"Sell","size":1000,"price":66809.1,"timestamp":"2024-05-18T15:46:14.462Z"}]}
{"table":"orderBookL2_25","action":"delete","data":[{"symbol":"ETHUSDT","id":32402497159,"side":"Buy","price":3109.18,"timestamp":"2024-05-18T15:46:14.463Z"}]}
{"table":"orderBookL2_25","action":"insert","data":[{"symbol":"ETHUSDT","id":32402497676,"side":"Buy","size":1000,"price":3109.20,"timestamp":"2024-05-18T15:46:14.463Z"}]}
{"table":"orderBookL2_25","action":"delete","data":[{"symbol":"ETHUSDT","id":32402494940,"side":"Buy","price":3108.13,"timestamp":"2024-05-18T15:46:14.513Z"},{"symbol":"ETHUSDT","id":32402497676,"side":"Buy","price":3109.20,"timestamp":"2024-05-18T15:46:14.513Z"}]}
{"table":"orderBookL2_25","action":"insert","data":[{"symbol":"ETHUSDT","id":32402458908,"side":"Buy","size":1114000,"price":3107.30,"timestamp":"2024-05-18T15:46:14.513Z"},{"symbol":"ETHUSDT","id":32402497686,"side":"Buy","size":1000,"price":3109.18,"timestamp":"2024-05-18T15:46:14.513Z"}]}
{"table":"orderBookL2_25","action":"delete","data":[{"symbol":"XBTUSDT","id":32402497669,"side":"Sell","price":66809.1,"timestamp":"2024-05-18T15:46:14.515Z"}]}
{"table":"orderBookL2_25","action":"insert","data":[{"symbol":"XBTUSDT","id":32402497705,"side":"Sell","size":1000,"price":66808.9,"timestamp":"2024-05-18T15:46:14.515Z"}]}
{"table":"orderBookL2_25","action":"delete","data":[{"symbol":"XBTUSDT","id":32402497705,"side":"Sell","price":66808.9,"timestamp":"2024-05-18T15:46:14.565Z"}]}
{"table":"orderBookL2_25","action":"update","data":[{"symbol":"XBTUSDT","id":32402491799,"side":"Sell","size":454000,"price":66795.4,"timestamp":"2024-05-18T15:46:14.565Z"},{"symbol":"XBTUSDT","id":32402258708,"side":"Buy","size":6000,"price":66795.3,"timestamp":"2024-05-18T15:46:14.565Z"}]}
{"table":"orderBookL2_25","action":"insert","data":[{"symbol":"XBTUSDT","id":32402497719,"side":"Sell","size":1000,"price":66809.1,"timestamp":"2024-05-18T15:46:14.565Z"}]}
{"table":"orderBookL2_25","action":"delete","data":[{"symbol":"XBTUSDT","id":32402495912,"side":"Buy","price":66781.5,"timestamp":"2024-05-18T15:46:14.614Z"}]}
{"table":"orderBookL2_25","action":"update","data":[{"symbol":"XBTUSDT","id":32402497374,"side":"Buy","size":8000,"price":66785.2,"timestamp":"2024-05-18T15:46:14.614Z"},{"symbol":"XBTUSDT","id":32402496991,"side":"Buy","size":16000,"price":66786.2,"timestamp":"2024-05-18T15:46:14.614Z"}]}
{"table":"orderBookL2_25","action":"insert","data":[{"symbol":"XBTUSDT","id":32402497765,"side":"Buy","size":8000,"price":66786.4,"timestamp":"2024-05-18T15:46:14.614Z"}]}
{"table":"orderBookL2_25","action":"delete","data":[{"symbol":"ETHUSDT","id":32402497686,"side":"Buy","price":3109.18,"timestamp":"2024-05-18T15:46:14.655Z"}]}
{"table":"orderBookL2_25","action":"insert","data":[{"symbol":"ETHUSDT","id":32402497821,"side":"Buy","size":1000,"price":3109.20,"timestamp":"2024-05-18T15:46:14.655Z"}]}
{"table":"orderBookL2_25","action":"delete","data":[{"symbol":"XBTUSDT","id":32402497284,"side":"Sell","price":66803.3,"timestamp":"2024-05-18T15:46:14.663Z"}]}
{"table":"orderBookL2_25","action":"update","data":[{"symbol":"XBTUSDT","id":32402258708,"side":"Buy","size":2000,"price":66795.3,"timestamp":"2024-05-18T15:46:14.663Z"}]}
{"table":"orderBookL2_25","action":"insert","data":[{"symbol":"XBTUSDT","id":32402497814,"side":"Sell","size":3000,"price":66806.1,"timestamp":"2024-05-18T15:46:14.663Z"}]}
{"table":"orderBookL2_25","action":"delete","data":[{"symbol":"ETHUSDT","id":32402458908,"side":"Buy","price":3107.30,"timestamp":"2024-05-18T15:46:14.705Z"},{"symbol":"ETHUSDT","id":32402497351,"side":"Buy","price":3108.30,"timestamp":"2024-05-18T15:46:14.705Z"}]}
{"table":"orderBookL2_25","action":"insert","data":[{"symbol":"ETHUSDT","id":32402497834,"side":"Buy","size":592000,"price":3107.98,"timestamp":"2024-05-18T15:46:14.705Z"},{"symbol":"ETHUSDT","id":32402497836,"side":"Buy","size":100000,"price":3108.13,"timestamp":"2024-05-18T15:46:14.705Z"}]}
{"table":"orderBookL2_25","action":"delete","data":[{"symbol":"ETHUSDT","id":32402497821,"side":"Buy","price":3109.20,"timestamp":"2024-05-18T15:46:14.754Z"}]}
{"table":"orderBookL2_25","action":"insert","data":[{"symbol":"ETHUSDT","id":32402497841,"side":"Buy","size":1000,"price":3109.18,"timestamp":"2024-05-18T15:46:14.754Z"}]}
{"table":"orderBookL2_25","action":"delete","data":[{"symbol":"ETHUSDT","id":32402495899,"side":"Buy","price":3109.19,"timestamp":"2024-05-18T15:46:14.803Z"}]}
{"table":"orderBookL2_25","action":"insert","data":[{"symbol":"ETHUSDT","id":32402497866,"side":"Buy","size":1000,"price":3109.17,"timestamp":"2024-05-18T15:46:14.803Z"}]}
{"table":"orderBookL2_25","action":"delete","data":[{"symbol":"ETHUSDT","id":32402486025,"side":"Sell","price":3111.72,"timestamp":"2024-05-18T15:46:14.852Z"},{"symbol":"ETHUSDT","id":32402497513,"side":"Sell","price":3110.58,"timestamp":"2024-05-18T15:46:14.852Z"},{"symbol":"ETHUSDT","id":32402496787,"side":"Buy","price":3109.43,"timestamp":"2024-05-18T15:46:14.852Z"},{"symbol":"ETHUSDT","id":32402496790,"side":"Buy","price":3109.44,"timestamp":"2024-05-18T15:46:14.852Z"}]}
{"table":"orderBookL2_25","action":"update","data":[{"symbol":"ETHUSDT","id":32402487305,"side":"Sell","size":100000,"price":3111.65,"timestamp":"2024-05-18T15:46:14.852Z"},{"symbol":"ETHUSDT","id":32402493174,"side":"Buy","size":43000,"price":3109.41,"timestamp":"2024-05-18T15:46:14.852Z"}]}
{"table":"orderBookL2_25","action":"insert","data":[{"symbol":"ETHUSDT","id":32402497879,"side":"Sell","size":28000,"price":3110.28,"timestamp":"2024-05-18T15:46:14.852Z"},{"symbol":"ETHUSDT","id":32402497868,"side":"Sell","size":2000,"price":3109.92,"timestamp":"2024-05-18T15:46:14.852Z"},{"symbol":"ETHUSDT","id":32402497875,"side":"Buy","size":32000,"price":3109.43,"timestamp":"2024-05-18T15:46:14.852Z"},{"symbol":"ETHUSDT","id":32402497877,"side":"Buy","size":32000,"price":3109.44,"timestamp":"2024-05-18T15:46:14.852Z"}]}
{"table":"orderBookL2_25","action":"delete","data":[{"symbol":"XBTUSDT","id":32402497537,"side":"Buy","price":66757.7,"timestamp":"2024-05-18T15:46:14.881Z"}]}
{"table":"orderBookL2_25","action":"insert","data":[{"symbol":"XBTUSDT","id":32402497914,"side":"Buy","size":8000,"price":66786.5,"timestamp":"2024-05-18T15:46:14.881Z"}]}
{"table":"orderBookL2_25","action":"delete","data":[{"symbol":"ETHUSDT","id":32402497507,"side":"Sell","price":3110.44,"timestamp":"2024-05-18T15:46:14.901Z"},{"symbol":"ETHUSDT","id":32402497866,"side":"Buy","price":3109.17,"timestamp":"2024-05-18T15:46:14.901Z"}]}
{"table":"orderBookL2_25","action":"update","data":[{"symbol":"ETHUSDT","id":32402497868,"side":"Sell","size":11000,"price":3109.92,"timestamp":"2024-05-18T15:46:14.901Z"}]}
{"table":"orderBookL2_25","action":"insert","data":[{"symbol":"ETHUSDT","id":32402497912,"side":"Sell","size":22000,"price":3110.58,"timestamp":"2024-05-18T15:46:14.901Z"},{"symbol":"ETHUSDT","id":32402497927,"side":"Buy","size":1000,"price":3109.19,"timestamp":"2024-05-18T15:46:14.901Z"}]}
{"table":"orderBookL2_25","action":"delete","data":[{"symbol":"XBTUSDT","id":32402497374,"side":"Buy","price":66785.2,"timestamp":"2024-05-18T15:46:14.930Z"}]}
{"table":"orderBookL2_25","action":"update","data":[{"symbol":"XBTUSDT","id":32402493723,"side":"Buy","size":20000,"price":66786.1,"timestamp":"2024-05-18T15:46:14.930Z"},{"symbol":"XBTUSDT","id":32402497110,"side":"Buy","size":16000,"price":66786.3,"timestamp":"2024-05-18T15:46:14.930Z"}]}
{"table":"orderBookL2_25","action":"insert","data":[{"symbol":"XBTUSDT","id":32402497916,"side":"Buy","size":94000,"price":66757.8,"timestamp":"2024-05-18T15:46:14.930Z"}]}
{"table":"orderBookL2_25","action":"delete","data":[{"symbol":"XBTUSDT","id":32402497719,"side":"Sell","price":66809.1,"timestamp":"2024-05-18T15:46:14.979Z"},{"symbol":"XBTUSDT","id":32402496194,"side":"Sell","price":66817.8,"timestamp":"2024-05-18T15:46:14.979Z"}]}
{"table":"orderBookL2_25","action":"insert","data":[{"symbol":"XBTUSDT","id":32402497969,"side":"Sell","size":1000,"price":66808.9,"timestamp":"2024-05-18T15:46:14.979Z"},{"symbol":"XBTUSDT","id":32402497966,"side":"Sell","size":2000,"price":66800.9,"timestamp":"2024-05-18T15:46:14.979Z"}]}
{"table":"orderBookL2_25","action":"update","data":[{"symbol":"XBTUSDT","id":32402496547,"side":"Buy","size":17000,"price":66768.5,"timestamp":"2024-05-18T15:46:15.028Z"}]}
{"table":"orderBookL2_25","action":"delete","data":[{"symbol":"ETHUSDT","id":32402487305,"side":"Sell","price":3111.65,"timestamp":"2024-05-18T15:46:15.059Z"}]}
{"table":"orderBookL2_25","action":"insert","data":[{"symbol":"ETHUSDT","id":32402498106,"side":"Sell","size":100000,"price":3110.72,"timestamp":"2024-05-18T15:46:15.059Z"}]}
{"table":"orderBookL2_25","action":"delete","data":[{"symbol":"ETHUSDT","id":32402497912,"side":"Sell","price":3110.58,"timestamp":"2024-05-18T15:46:15.108Z"}]}
{"table":"orderBookL2_25","action":"insert","data":[{"symbol":"ETHUSDT","id":32402498109,"side":"Sell","size":68000,"price":3110.71,"timestamp":"2024-05-18T15:46:15.108Z"}]}
{"table":"orderBookL2_25","action":"update","data":[{"symbol":"XBTETH","id":32402421084,"side":"Buy","size":7,"price":20.883,"timestamp":"2024-05-18T15:46:15.154Z"}]}
{"table":"orderBookL2_25","action":"delete","data":[{"symbol":"ETHUSDT","id":32402497927,"side":"Buy","price":3109.19,"timestamp":"2024-05-18T15:46:15.157Z"}]}
{"table":"orderBookL2_25","action":"insert","data":[{"symbol":"ETHUSDT","id":32402498214,"side":"Buy","size":1000,"price":3109.17,"timestamp":"2024-05-18T15:46:15.157Z"}]}
{"table":"orderBookL2_25","action":"delete","data":[{"symbol":"XBTUSDT","id":32402497814,"side":"Sell","price":66806.1,"timestamp":"2024-05-18T15:46:15.158Z"}]}
{"table":"orderBookL2_25","action":"insert","data":[{"symbol":"XBTUSDT","id":32402498232,"side":"Sell","size":3000,"price":66803.3,"timestamp":"2024-05-18T15:46:15.158Z"}]}
{"table":"orderBookL2_25","action":"update","data":[{"symbol":"XBTETH","id":32402421121,"side":"Sell","size":7,"price":22.130,"timestamp":"2024-05-18T15:46:15.204Z"}]}
{"table":"orderBookL2_25","action":"delete","data":[{"symbol":"ETHUSDT","id":32402497875,"side":"Buy","price":3109.43,"timestamp":"2024-05-18T15:46:15.206Z"}]}
{"table":"orderBookL2_25","action":"insert","data":[{"symbol":"ETHUSDT","id":32402498245,"side":"Buy","size":32000,"price":3109.42,"timestamp":"2024-05-18T15:46:15.206Z"}]}
{"table":"orderBookL2_25","action":"update","data":[{"symbol":"XBTUSDT","id":32402496991,"side":"Buy","size":8000,"price":66786.2,"timestamp":"2024-05-18T15:46:15.225Z"}]}
{"table":"orderBookL2_25","action":"delete","data":[{"symbol":"ETHUSDT","id":32402497877,"side":"Buy","price":3109.44,"timestamp":"2024-05-18T15:46:15.256Z"}]}
{"table":"orderBookL2_25","action":"update","data":[{"symbol":"ETHUSDT","id":32402493174,"side":"Buy","size":75000,"price":3109.41,"timestamp":"2024-05-18T15:46:15.256Z"}]}
{"table":"orderBookL2_25","action":"insert","data":[{"symbol":"ETHUSDT","id":32402458908,"side":"Buy","size":1114000,"price":3107.30,"timestamp":"2024-05-18T15:46:15.256Z"}]}
{"table":"orderBookL2_25","action":"delete","data":[{"symbol":"XBTUSDT","id":32402496808,"side":"Buy","price":66775.1,"timestamp":"2024-05-18T15:46:15.275Z"},{"symbol":"XBTUSDT","id":32402496991,"side":"Buy","price":66786.2,"timestamp":"2024-05-18T15:46:15.275Z"},{"symbol":"XBTUSDT","id":32402497916,"side":"Buy","price":66757.8,"timestamp":"2024-05-18T15:46:15.275Z"},{"symbol":"XBTUSDT","id":32402496802,"side":"Buy","price":66785.1,"timestamp":"2024-05-18T15:46:15.275Z"}]}
{"table":"orderBookL2_25","action":"update","data":[{"symbol":"XBTUSDT","id":32402493835,"side":"Buy","size":2000,"price":66778.3,"timestamp":"2024-05-18T15:46:15.275Z"},{"symbol":"XBTUSDT","id":32402497765,"side":"Buy","size":16000,"price":66786.4,"timestamp":"2024-05-18T15:46:15.275Z"}]}
{"table":"orderBookL2_25","action":"insert","data":[{"symbol":"XBTUSDT","id":32402498305,"side":"Buy","size":8000,"price":66786.6,"timestamp":"2024-05-18T15:46:15.275Z"},{"symbol":"XBTUSDT","id":32402492129,"side":"Buy","size":1502000,"price":66752.1,"timestamp":"2024-05-18T15:46:15.275Z"},{"symbol":"XBTUSDT","id":32402495049,"side":"Buy","size":878000,"price":66752.2,"timestamp":"2024-05-18T15:46:15.275Z"},{"symbol":"XBTUSDT","id":32402489416,"side":"Buy","size":100000,"price":66757.6,"timestamp":"2024-05-18T15:46:15.275Z"}]}
{"table":"orderBookL2_25","action":"delete","data":[{"symbol":"ETHUSDT","id":32402491370,"side":"Sell","price":3111.53,"timestamp":"2024-05-18T15:46:15.305Z"},{"symbol":"ETHUSDT","id":32402484839,"side":"Sell","price":3111.49,"timestamp":"2024-05-18T15:46:15.305Z"},{"symbol":"ETHUSDT","id":32402487294,"side":"Sell","price":3111.54,"timestamp":"2024-05-18T15:46:15.305Z"},{"symbol":"ETHUSDT","id":32402497480,"side":"Sell","price":3110.08,"timestamp":"2024-05-18T15:46:15.305Z"},{"symbol":"ETHUSDT","id":32402495956,"side":"Buy","price":3108.81,"timestamp":"2024-05-18T15:46:15.305Z"},{"symbol":"ETHUSDT","id":32402495945,"side":"Buy","price":3108.80,"timestamp":"2024-05-18T15:46:15.305Z"}]}
{"table":"orderBookL2_25","action":"insert","data":[{"symbol":"ETHUSDT","id":32402498377,"side":"Sell","size":69000,"price":3109.83,"timestamp":"2024-05-18T15:46:15.305Z"},{"symbol":"ETHUSDT","id":32402498418,"side":"Sell","size":17000,"price":3110.18,"timestamp":"2024-05-18T15:46:15.305Z"},{"symbol":"ETHUSDT","id":32402498371,"side":"Sell","size":100000,"price":3109.84,"timestamp":"2024-05-18T15:46:15.305Z"},{"symbol":"ETHUSDT","id":32402498401,"side":"Sell","size":28000,"price":3110.19,"timestamp":"2024-05-18T15:46:15.305Z"},{"symbol":"ETHUSDT","id":32402480382,"side":"Buy","size":100000,"price":3107.24,"timestamp":"2024-05-18T15:46:15.305Z"},{"symbol":"ETHUSDT","id":32402492538,"side":"Buy","size":928000,"price":3107.18,"timestamp":"2024-05-18T15:46:15.305Z"}]}
{"table":"orderBookL2_25","action":"delete","data":[{"symbol":"XBTUSDT","id":32402495583,"side":"Sell","price":66797.6,"timestamp":"2024-05-18T15:46:15.324Z"},{"symbol":"XBTUSDT","id":32402496823,"side":"Sell","price":66809.0,"timestamp":"2024-05-18T15:46:15.324Z"},{"symbol":"XBTUSDT","id":32402492129,"side":"Buy","price":66752.1,"timestamp":"2024-05-18T15:46:15.324Z"}]}
{"table":"orderBookL2_25","action":"update","data":[{"symbol":"XBTUSDT","id":32402491799,"side":"Sell","size":610000,"price":66795.4,"timestamp":"2024-05-18T15:46:15.324Z"}]}
{"table":"orderBookL2_25","action":"insert","data":[{"symbol":"XBTUSDT","id":32402498571,"side":"Sell","size":1000,"price":66809.2,"timestamp":"2024-05-18T15:46:15.324Z"},{"symbol":"XBTUSDT","id":32402496194,"side":"Sell","size":332000,"price":66817.8,"timestamp":"2024-05-18T15:46:15.324Z"},{"symbol":"XBTUSDT","id":32402498422,"side":"Buy","size":156000,"price":66752.3,"timestamp":"2024-05-18T15:46:15.324Z"}]}
{"table":"orderBookL2_25","action":"delete","data":[{"symbol":"ETHUSDT","id":32402497879,"side":"Sell","price":3110.28,"timestamp":"2024-05-18T15:46:15.354Z"},{"symbol":"ETHUSDT","id":32402498418,"side":"Sell","price":3110.18,"timestamp":"2024-05-18T15:46:15.354Z"},{"symbol":"ETHUSDT","id":32402497462,"side":"Sell","price":3110.09,"timestamp":"2024-05-18T15:46:15.354Z"},{"symbol":"ETHUSDT","id":32402497841,"side":"Buy","price":3109.18,"timestamp":"2024-05-18T15:46:15.354Z"}]}
{"table":"orderBookL2_25","action":"update","data":[{"symbol":"ETHUSDT","id":32402497868,"side":"Sell","size":9000,"price":3109.92,"timestamp":"2024-05-18T15:46:15.354Z"},{"symbol":"ETHUSDT","id":32402494506,"side":"Sell","size":65000,"price":3111.48,"timestamp":"2024-05-18T15:46:15.354Z"}]}
{"table":"orderBookL2_25","action":"insert","data":[{"symbol":"ETHUSDT","id":32402498698,"side":"Sell","size":2000,"price":3109.67,"timestamp":"2024-05-18T15:46:15.354Z"},{"symbol":"ETHUSDT","id":32402484839,"side":"Sell","size":100000,"price":3111.49,"timestamp":"2024-05-18T15:46:15.354Z"},{"symbol":"ETHUSDT","id":32402498480,"side":"Sell","size":100000,"price":3109.79,"timestamp":"2024-05-18T15:46:15.354Z"},{"symbol":"ETHUSDT","id":32402498701,"side":"Buy","size":1000,"price":3109.16,"timestamp":"2024-05-18T15:46:15.354Z"}]}
{"table":"orderBookL2_25","action":"delete","data":[{"symbol":"XBTUSDT","id":32402497969,"side":"Sell","price":66808.9,"timestamp":"2024-05-18T15:46:15.373Z"},{"symbol":"XBTUSDT","id":32402497214,"side":"Sell","price":66802.5,"timestamp":"2024-05-18T15:46:15.373Z"},{"symbol":"XBTUSDT","id":32402496833,"side":"Sell","price":66802.6,"timestamp":"2024-05-18T15:46:15.373Z"},{"symbol":"XBTUSDT","id":32402496194,"side":"Sell","price":66817.8,"timestamp":"2024-05-18T15:46:15.373Z"},{"symbol":"XBTUSDT","id":32402493835,"side":"Buy","price":66778.3,"timestamp":"2024-05-18T15:46:15.373Z"},{"symbol":"XBTUSDT","id":32402497212,"side":"Buy","price":66772.8,"timestamp":"2024-05-18T15:46:15.373Z"},{"symbol":"XBTUSDT","id":32402495643,"side":"Buy","price":66781.4,"timestamp":"2024-05-18T15:46:15.373Z"}]}
{"table":"orderBookL2_25","action":"update","data":[{"symbol":"XBTUSDT","id":32402492533,"side":"Buy","size":462000,"price":66772.1,"timestamp":"2024-05-18T15:46:15.373Z"},{"symbol":"XBTUSDT","id":32402494037,"side":"Buy","size":69000,"price":66772.7,"timestamp":"2024-05-18T15:46:15.373Z"},{"symbol":"XBTUSDT","id":32402493180,"side":"Buy","size":186000,"price":66772.2,"timestamp":"2024-05-18T15:46:15.373Z"}]}
{"table":"orderBookL2_25","action":"insert","data":[{"symbol":"XBTUSDT","id":32402498769,"side":"Sell","size":2000,"price":66814.5,"timestamp":"2024-05-18T15:46:15.373Z"},{"symbol":"XBTUSDT","id":32402498596,"side":"Sell","size":1000,"price":66809.1,"timestamp":"2024-05-18T15:46:15.373Z"},{"symbol":"XBTUSDT","id":32402498670,"side":"Sell","size":20000,"price":66802.8,"timestamp":"2024-05-18T15:46:15.373Z"},{"symbol":"XBTUSDT","id":32402498667,"side":"Sell","size":20000,"price":66802.7,"timestamp":"2024-05-18T15:46:15.373Z"},{"symbol":"XBTUSDT","id":32402492889,"side":"Buy","size":100000,"price":66750.8,"timestamp":"2024-05-18T15:46:15.373Z"},{"symbol":"XBTUSDT","id":32402494980,"side":"Buy","size":74000,"price":66751.4,"timestamp":"2024-05-18T15:46:15.373Z"},{"symbol":"XBTUSDT","id":32402492129,"side":"Buy","size":1502000,"price":66752.1,"timestamp":"2024-05-18T15:46:15.373Z"}]}
{"table":"orderBookL2_25","action":"delete","data":[{"symbol":"ETHUSDT","id":32402494586,"side":"Sell","price":3110.86,"timestamp":"2024-05-18T15:46:15.403Z"},{"symbol":"ETHUSDT","id":32402498698,"side":"Sell","price":3109.67,"timestamp":"2024-05-18T15:46:15.403Z"},{"symbol":"ETHUSDT","id":32402498371,"side":"Sell","price":3109.84,"timestamp":"2024-05-18T15:46:15.403Z"},{"symbol":"ETHUSDT","id":32402496785,"side":"Sell","price":3110.85,"timestamp":"2024-05-18T15:46:15.403Z"},{"symbol":"ETHUSDT","id":32402498377,"side":"Sell","price":3109.83,"timestamp":"2024-05-18T15:46:15.403Z"},{"symbol":"ETHUSDT","id":32402498214,"side":"Buy","price":3109.17,"timestamp":"2024-05-18T15:46:15.403Z"},{"symbol":"ETHUSDT","id":32402498245,"side":"Buy","price":3109.42,"timestamp":"2024-05-18T15:46:15.403Z"},{"symbol":"ETHUSDT","id":32402492383,"side":"Buy","price":3108.52,"timestamp":"2024-05-18T15:46:15.403Z"},{"symbol":"ETHUSDT","id":32402498701,"side":"Buy","price":3109.16,"timestamp":"2024-05-18T15:46:15.403Z"},{"symbol":"ETHUSDT","id":32402494925,"side":"Buy","price":3108.23,"timestamp":"2024-05-18T15:46:15.403Z"},{"symbol":"ETHUSDT","id":32402492538,"side":"Buy","price":3107.18,"timestamp":"2024-05-18T15:46:15.403Z"}]}
{"table":"orderBookL2_25","action":"update","data":[{"symbol":"ETHUSDT","id":32402484839,"side":"Sell","size":100000,"price":3111.49,"timestamp":"2024-05-18T15:46:15.403Z"},{"symbol":"ETHUSDT","id":32402496877,"side":"Sell","size":63000,"price":3110.84,"timestamp":"2024-05-18T15:46:15.403Z"},{"symbol":"ETHUSDT","id":32402494506,"side":"Sell","size":65000,"price":3111.48,"timestamp":"2024-05-18T15:46:15.403Z"},{"symbol":"ETHUSDT","id":32402480382,"side":"Buy","size":100000,"price":3107.24,"timestamp":"2024-05-18T15:46:15.403Z"},{"symbol":"ETHUSDT","id":32402493174,"side":"Buy","size":43000,"price":3109.41,"timestamp":"2024-05-18T15:46:15.403Z"},{"symbol":"ETHUSDT","id":32401945550,"side":"Buy","size":72000,"price":3109.40,"timestamp":"2024-05-18T15:46:15.403Z"}]}
{"table":"orderBookL2_25","action":"insert","data":[{"symbol":"ETHUSDT","id":32402498964,"side":"Sell","size":100000,"price":3109.75,"timestamp":"2024-05-18T15:46:15.403Z"},{"symbol":"ETHUSDT","id":32402498926,"side":"Sell","size":32000,"price":3110.82,"timestamp":"2024-05-18T15:46:15.403Z"},{"symbol":"ETHUSDT","id":32402491370,"side":"Sell","size":920000,"price":3111.53,"timestamp":"2024-05-18T15:46:15.403Z"},{"symbol":"ETHUSDT","id":32402498911,"side":"Sell","size":32000,"price":3110.83,"timestamp":"2024-05-18T15:46:15.403Z"},{"symbol":"ETHUSDT","id":32402487294,"side":"Sell","size":2346000,"price":3111.54,"timestamp":"2024-05-18T15:46:15.403Z"},{"symbol":"ETHUSDT","id":32402498818,"side":"Buy","size":1000,"price":3109.14,"timestamp":"2024-05-18T15:46:15.403Z"},{"symbol":"ETHUSDT","id":32402498806,"side":"Buy","size":1000,"price":3109.15,"timestamp":"2024-05-18T15:46:15.403Z"},{"symbol":"ETHUSDT","id":32402498900,"side":"Buy","size":32000,"price":3109.38,"timestamp":"2024-05-18T15:46:15.403Z"},{"symbol":"ETHUSDT","id":32402498785,"side":"Buy","size":100000,"price":3108.51,"timestamp":"2024-05-18T15:46:15.403Z"},{"symbol":"ETHUSDT","id":32402498771,"side":"Buy","size":100000,"price":3108.67,"timestamp":"2024-05-18T15:46:15.403Z"},{"symbol":"ETHUSDT","id":32402498923,"side":"Buy","size":32000,"price":3109.39,"timestamp":"2024-05-18T15:46:15.403Z"}]}
{"table":"orderBookL2_25","action":"delete","data":[{"symbol":"XBTUSDT","id":32402495043,"side":"Sell","price":66801.0,"timestamp":"2024-05-18T15:46:15.422Z"},{"symbol":"XBTUSDT","id":32402498571,"side":"Sell","price":66809.2,"timestamp":"2024-05-18T15:46:15.422Z"},{"symbol":"XBTUSDT","id":32402498596,"side":"Sell","price":66809.1,"timestamp":"2024-05-18T15:46:15.422Z"},{"symbol":"XBTUSDT","id":32402498670,"side":"Sell","price":66802.8,"timestamp":"2024-05-18T15:46:15.422Z"},{"symbol":"XBTUSDT","id":32402495039,"side":"Sell","price":66801.1,"timestamp":"2024-05-18T15:46:15.422Z"},{"symbol":"XBTUSDT","id":32402498667,"side":"Sell","price":66802.7,"timestamp":"2024-05-18T15:46:15.422Z"},{"symbol":"XBTUSDT","id":32402495037,"side":"Buy","price":66764.5,"timestamp":"2024-05-18T15:46:15.422Z"},{"symbol":"XBTUSDT","id":32402497038,"side":"Buy","price":66761.1,"timestamp":"2024-05-18T15:46:15.422Z"},{"symbol":"XBTUSDT","id":32402494980,"side":"Buy","price":66751.4,"timestamp":"2024-05-18T15:46:15.422Z"},{"symbol":"XBTUSDT","id":32402492889,"side":"Buy","price":66750.8,"timestamp":"2024-05-18T15:46:15.422Z"}]}
{"table":"orderBookL2_25","action":"update","data":[{"symbol":"XBTUSDT","id":32402480133,"side":"Sell","size":10000,"price":66803.0,"timestamp":"2024-05-18T15:46:15.422Z"},{"symbol":"XBTUSDT","id":32402461579,"side":"Sell","size":100000,"price":66815.7,"timestamp":"2024-05-18T15:46:15.422Z"},{"symbol":"XBTUSDT","id":32402497966,"side":"Sell","size":65000,"price":66800.9,"timestamp":"2024-05-18T15:46:15.422Z"},{"symbol":"XBTUSDT","id":32402493180,"side":"Buy","size":166000,"price":66772.2,"timestamp":"2024-05-18T15:46:15.422Z"}]}
{"table":"orderBookL2_25","action":"insert","data":[{"symbol":"XBTUSDT","id":32402498856,"side":"Sell","size":215000,"price":66797.4,"timestamp":"2024-05-18T15:46:15.422Z"},{"symbol":"XBTUSDT","id":32402499005,"side":"Sell","size":1000,"price":66806.9,"timestamp":"2024-05-18T15:46:15.422Z"},{"symbol":"XBTUSDT","id":32402498953,"side":"Sell","size":20000,"price":66802.8,"timestamp":"2024-05-18T15:46:15.422Z"},{"symbol":"XBTUSDT","id":32402498816,"side":"Sell","size":20000,"price":66802.9,"timestamp":"2024-05-18T15:46:15.422Z"},{"symbol":"XBTUSDT","id":32402498829,"side":"Sell","size":352000,"price":66797.5,"timestamp":"2024-05-18T15:46:15.422Z"},{"symbol":"XBTUSDT","id":32402499034,"side":"Sell","size":1000,"price":66806.8,"timestamp":"2024-05-18T15:46:15.422Z"},{"symbol":"XBTUSDT","id":32402498827,"side":"Buy","size":371000,"price":66761.2,"timestamp":"2024-05-18T15:46:15.422Z"},{"symbol":"XBTUSDT","id":32402498978,"side":"Buy","size":36000,"price":66777.3,"timestamp":"2024-05-18T15:46:15.422Z"},{"symbol":"XBTUSDT","id":32402498943,"side":"Buy","size":20000,"price":66772.0,"timestamp":"2024-05-18T15:46:15.422Z"},{"symbol":"XBTUSDT","id":32402498824,"side":"Buy","size":2000,"price":66772.8,"timestamp":"2024-05-18T15:46:15.422Z"}]}
{"table":"orderBookL2_25","action":"delete","data":[{"symbol":"ETHUSDT","id":32402498401,"side":"Sell","price":3110.19,"timestamp":"2024-05-18T15:46:15.452Z"},{"symbol":"ETHUSDT","id":32402498964,"side":"Sell","price":3109.75,"timestamp":"2024-05-18T15:46:15.452Z"},{"symbol":"ETHUSDT","id":32402498480,"side":"Sell","price":3109.79,"timestamp":"2024-05-18T15:46:15.452Z"},{"symbol":"ETHUSDT","id":32402498818,"side":"Buy","price":3109.14,"timestamp":"2024-05-18T15:46:15.452Z"},{"symbol":"ETHUSDT","id":32402498806,"side":"Buy","price":3109.15,"timestamp":"2024-05-18T15:46:15.452Z"},{"symbol":"ETHUSDT","id":32402480382,"side":"Buy","price":3107.24,"timestamp":"2024-05-18T15:46:15.452Z"}]}
{"table":"orderBookL2_25","action":"update","data":[{"symbol":"ETHUSDT","id":32402484839,"side":"Sell","size":100000,"price":3111.49,"timestamp":"2024-05-18T15:46:15.452Z"},{"symbol":"ETHUSDT","id":32402494506,"side":"Sell","size":65000,"price":3111.48,"timestamp":"2024-05-18T15:46:15.452Z"},{"symbol":"ETHUSDT","id":32402487294,"side":"Sell","size":2346000,"price":3111.54,"timestamp":"2024-05-18T15:46:15.452Z"},{"symbol":"ETHUSDT","id":32402491370,"side":"Sell","size":920000,"price":3111.53,"timestamp":"2024-05-18T15:46:15.452Z"}]}
{"table":"orderBookL2_25","action":"insert","data":[{"symbol":"ETHUSDT","id":32402499024,"side":"Sell","size":100000,"price":3110.55,"timestamp":"2024-05-18T15:46:15.452Z"},{"symbol":"ETHUSDT","id":32402499069,"side":"Sell","size":100000,"price":3109.73,"timestamp":"2024-05-18T15:46:15.452Z"},{"symbol":"ETHUSDT","id":32402499050,"side":"Sell","size":28000,"price":3110.11,"timestamp":"2024-05-18T15:46:15.452Z"},{"symbol":"ETHUSDT","id":32402499017,"side":"Buy","size":1000,"price":3109.16,"timestamp":"2024-05-18T15:46:15.452Z"},{"symbol":"ETHUSDT","id":32402499045,"side":"Buy","size":1000,"price":3109.15,"timestamp":"2024-05-18T15:46:15.452Z"},{"symbol":"ETHUSDT","id":32402499021,"side":"Buy","size":192000,"price":3108.08,"timestamp":"2024-05-18T15:46:15.452Z"}]}
{"table":"orderBookL2_25","action":"delete","data":[{"symbol":"XBTUSDT","id":32402461579,"side":"Sell","price":66815.7,"timestamp":"2024-05-18T15:46:15.471Z"},{"symbol":"XBTUSDT","id":32402499005,"side":"Sell","price":66806.9,"timestamp":"2024-05-18T15:46:15.471Z"},{"symbol":"XBTUSDT","id":32402498953,"side":"Sell","price":66802.8,"timestamp":"2024-05-18T15:46:15.471Z"},{"symbol":"XBTUSDT","id":32402494978,"side":"Sell","price":66805.2,"timestamp":"2024-05-18T15:46:15.471Z"},{"symbol":"XBTUSDT","id":32402498816,"side":"Sell","price":66802.9,"timestamp":"2024-05-18T15:46:15.471Z"},{"symbol":"XBTUSDT","id":32402258708,"side":"Buy","price":66795.3,"timestamp":"2024-05-18T15:46:15.471Z"},{"symbol":"XBTUSDT","id":32402498943,"side":"Buy","price":66772.0,"timestamp":"2024-05-18T15:46:15.471Z"}]}
{"table":"orderBookL2_25","action":"update","data":[{"symbol":"XBTUSDT","id":32402491670,"side":"Sell","size":108000,"price":66795.5,"timestamp":"2024-05-18T15:46:15.471Z"},{"symbol":"XBTUSDT","id":32402498769,"side":"Sell","size":2000,"price":66814.5,"timestamp":"2024-05-18T15:46:15.471Z"},{"symbol":"XBTUSDT","id":32402494269,"side":"Sell","size":23000,"price":66800.4,"timestamp":"2024-05-18T15:46:15.471Z"},{"symbol":"XBTUSDT","id":32402498856,"side":"Sell","size":2000,"price":66797.4,"timestamp":"2024-05-18T15:46:15.471Z"},{"symbol":"XBTUSDT","id":32402491799,"side":"Sell","size":161000,"price":66795.4,"timestamp":"2024-05-18T15:46:15.471Z"},{"symbol":"XBTUSDT","id":32402492533,"side":"Buy","size":442000,"price":66772.1,"timestamp":"2024-05-18T15:46:15.471Z"},{"symbol":"XBTUSDT","id":32402493180,"side":"Buy","size":166000,"price":66772.2,"timestamp":"2024-05-18T15:46:15.471Z"},{"symbol":"XBTUSDT","id":32402492129,"side":"Buy","size":1502000,"price":66752.1,"timestamp":"2024-05-18T15:46:15.471Z"}]}
{"table":"orderBookL2_25","action":"insert","data":[{"symbol":"XBTUSDT","id":32402499120,"side":"Sell","size":1000,"price":66806.7,"timestamp":"2024-05-18T15:46:15.471Z"},{"symbol":"XBTUSDT","id":32402499075,"side":"Sell","size":20000,"price":66801.0,"timestamp":"2024-05-18T15:46:15.471Z"},{"symbol":"XBTUSDT","id":32402499136,"side":"Sell","size":156000,"price":66795.2,"timestamp":"2024-05-18T15:46:15.471Z"},{"symbol":"XBTUSDT","id":32402499098,"side":"Sell","size":240000,"price":66792.1,"timestamp":"2024-05-18T15:46:15.471Z"},{"symbol":"XBTUSDT","id":32402499096,"side":"Sell","size":40000,"price":66795.3,"timestamp":"2024-05-18T15:46:15.471Z"},{"symbol":"XBTUSDT","id":32402499142,"side":"Buy","size":20000,"price":66772.4,"timestamp":"2024-05-18T15:46:15.471Z"},{"symbol":"XBTUSDT","id":32402499128,"side":"Buy","size":20000,"price":66772.5,"timestamp":"2024-05-18T15:46:15.471Z"}]}
{"table":"orderBookL2_25","action":"delete","data":[{"symbol":"ETHUSDT","id":32402498926,"side":"Sell","price":3110.82,"timestamp":"2024-05-18T15:46:15.501Z"},{"symbol":"ETHUSDT","id":32402499045,"side":"Buy","price":3109.15,"timestamp":"2024-05-18T15:46:15.501Z"},{"symbol":"ETHUSDT","id":32402499017,"side":"Buy","price":3109.16,"timestamp":"2024-05-18T15:46:15.501Z"},{"symbol":"ETHUSDT","id":32402498900,"side":"Buy","price":3109.38,"timestamp":"2024-05-18T15:46:15.501Z"}]}
{"table":"orderBookL2_25","action":"update","data":[{"symbol":"ETHUSDT","id":32402496877,"side":"Sell","size":95000,"price":3110.84,"timestamp":"2024-05-18T15:46:15.501Z"},{"symbol":"ETHUSDT","id":32401945550,"side":"Buy","size":104000,"price":3109.40,"timestamp":"2024-05-18T15:46:15.501Z"}]}
{"table":"orderBookL2_25","action":"insert","data":[{"symbol":"ETHUSDT","id":32402487305,"side":"Sell","size":100000,"price":3111.65,"timestamp":"2024-05-18T15:46:15.501Z"},{"symbol":"ETHUSDT","id":32402499177,"side":"Buy","size":1000,"price":3109.13,"timestamp":"2024-05-18T15:46:15.501Z"},{"symbol":"ETHUSDT","id":32402480382,"side":"Buy","size":100000,"price":3107.24,"timestamp":"2024-05-18T15:46:15.501Z"},{"symbol":"ETHUSDT","id":32402499172,"side":"Buy","size":1000,"price":3109.14,"timestamp":"2024-05-18T15:46:15.501Z"}]}
{"table":"orderBookL2_25","action":"delete","data":[{"symbol":"XBTUSDT","id":32402498856,"side":"Sell","price":66797.4,"timestamp":"2024-05-18T15:46:15.520Z"},{"symbol":"XBTUSDT","id":32402498769,"side":"Sell","price":66814.5,"timestamp":"2024-05-18T15:46:15.520Z"},{"symbol":"XBTUSDT","id":32402499136,"side":"Sell","price":66795.2,"timestamp":"2024-05-18T15:46:15.520Z"},{"symbol":"XBTUSDT","id":32402499075,"side":"Sell","price":66801.0,"timestamp":"2024-05-18T15:46:15.520Z"},{"symbol":"XBTUSDT","id":32402499120,"side":"Sell","price":66806.7,"timestamp":"2024-05-18T15:46:15.520Z"},{"symbol":"XBTUSDT","id":32402499142,"side":"Buy","price":66772.4,"timestamp":"2024-05-18T15:46:15.520Z"},{"symbol":"XBTUSDT","id":32402499128,"side":"Buy","price":66772.5,"timestamp":"2024-05-18T15:46:15.520Z"},{"symbol":"XBTUSDT","id":32402492129,"side":"Buy","price":66752.1,"timestamp":"2024-05-18T15:46:15.520Z"},{"symbol":"XBTUSDT","id":32402495049,"side":"Buy","price":66752.2,"timestamp":"2024-05-18T15:46:15.520Z"}]}
{"table":"orderBookL2_25","action":"update","data":[{"symbol":"XBTUSDT","id":32402498422,"side":"Buy","size":156000,"price":66752.3,"timestamp":"2024-05-18T15:46:15.520Z"},{"symbol":"XBTUSDT","id":32402493180,"side":"Buy","size":186000,"price":66772.2,"timestamp":"2024-05-18T15:46:15.520Z"},{"symbol":"XBTUSDT","id":32402489150,"side":"Buy","size":100000,"price":66772.6,"timestamp":"2024-05-18T15:46:15.520Z"}]}
{"table":"orderBookL2_25","action":"insert","data":[{"symbol":"XBTUSDT","id":32402499210,"side":"Sell","size":1000,"price":66806.9,"timestamp":"2024-05-18T15:46:15.520Z"},{"symbol":"XBTUSDT","id":32402499179,"side":"Sell","size":2000,"price":66795.1,"timestamp":"2024-05-18T15:46:15.520Z"},{"symbol":"XBTUSDT","id":32402499206,"side":"Sell","size":156000,"price":66795.0,"timestamp":"2024-05-18T15:46:15.520Z"},{"symbol":"XBTUSDT","id":32402461579,"side":"Sell","size":100000,"price":66815.7,"timestamp":"2024-05-18T15:46:15.520Z"},{"symbol":"XBTUSDT","id":32402499197,"side":"Sell","size":20000,"price":66800.5,"timestamp":"2024-05-18T15:46:15.520Z"},{"symbol":"XBTUSDT","id":32402499181,"side":"Buy","size":67000,"price":66757.7,"timestamp":"2024-05-18T15:46:15.520Z"},{"symbol":"XBTUSDT","id":32402499167,"side":"Buy","size":100000,"price":66776.4,"timestamp":"2024-05-18T15:46:15.520Z"},{"symbol":"XBTUSDT","id":32402499183,"side":"Buy","size":20000,"price":66772.3,"timestamp":"2024-05-18T15:46:15.520Z"},{"symbol":"XBTUSDT","id":32402499174,"side":"Buy","size":229000,"price":66761.3,"timestamp":"2024-05-18T15:46:15.520Z"}]}
{"table":"orderBookL2_25","action":"delete","data":[{"symbol":"ETHUSDT","id":32402494704,"side":"Sell","price":3110.59,"timestamp":"2024-05-18T15:46:15.550Z"},{"symbol":"ETHUSDT","id":32402493419,"side":"Sell","price":3110.24,"timestamp":"2024-05-18T15:46:15.550Z"},{"symbol":"ETHUSDT","id":32402499024,"side":"Sell","price":3110.55,"timestamp":"2024-05-18T15:46:15.550Z"},{"symbol":"ETHUSDT","id":32402499069,"side":"Sell","price":3109.73,"timestamp":"2024-05-18T15:46:15.550Z"},{"symbol":"ETHUSDT","id":32402499050,"side":"Sell","price":3110.11,"timestamp":"2024-05-18T15:46:15.550Z"},{"symbol":"ETHUSDT","id":32402498911,"side":"Sell","price":3110.83,"timestamp":"2024-05-18T15:46:15.550Z"},{"symbol":"ETHUSDT","id":32402499172,"side":"Buy","price":3109.14,"timestamp":"2024-05-18T15:46:15.550Z"},{"symbol":"ETHUSDT","id":32402499177,"side":"Buy","price":3109.13,"timestamp":"2024-05-18T15:46:15.550Z"},{"symbol":"ETHUSDT","id":32402480382,"side":"Buy","price":3107.24,"timestamp":"2024-05-18T15:46:15.550Z"}]}
{"table":"orderBookL2_25","action":"update","data":[{"symbol":"ETHUSDT","id":32402487799,"side":"Sell","size":241000,"price":3111.06,"timestamp":"2024-05-18T15:46:15.550Z"},{"symbol":"ETHUSDT","id":32401945550,"side":"Buy","size":104000,"price":3109.40,"timestamp":"2024-05-18T15:46:15.550Z"}]}
{"table":"orderBookL2_25","action":"insert","data":[{"symbol":"ETHUSDT","id":32402499240,"side":"Sell","size":32000,"price":3110.83,"timestamp":"2024-05-18T15:46:15.550Z"},{"symbol":"ETHUSDT","id":32402494228,"side":"Sell","size":566000,"price":3112.00,"timestamp":"2024-05-18T15:46:15.550Z"},{"symbol":"ETHUSDT","id":32402486025,"side":"Sell","size":337000,"price":3111.72,"timestamp":"2024-05-18T15:46:15.550Z"},{"symbol":"ETHUSDT","id":32402493837,"side":"Sell","size":561000,"price":3112.01,"timestamp":"2024-05-18T15:46:15.550Z"},{"symbol":"ETHUSDT","id":32402455680,"side":"Sell","size":100000,"price":3112.02,"timestamp":"2024-05-18T15:46:15.550Z"},{"symbol":"ETHUSDT","id":32402493850,"side":"Sell","size":100000,"price":3111.81,"timestamp":"2024-05-18T15:46:15.550Z"},{"symbol":"ETHUSDT","id":32402499267,"side":"Buy","size":100000,"price":3108.83,"timestamp":"2024-05-18T15:46:15.550Z"},{"symbol":"ETHUSDT","id":32402499215,"side":"Buy","size":1000,"price":3109.16,"timestamp":"2024-05-18T15:46:15.550Z"},{"symbol":"ETHUSDT","id":32402499311,"side":"Buy","size":1000,"price":3109.15,"timestamp":"2024-05-18T15:46:15.550Z"}]}
{"table":"orderBookL2_25","action":"delete","data":[{"symbol":"XBTUSDT","id":32402461579,"side":"Sell","price":66815.7,"timestamp":"2024-05-18T15:46:15.569Z"},{"symbol":"XBTUSDT","id":32402493286,"side":"Sell","price":66809.9,"timestamp":"2024-05-18T15:46:15.569Z"},{"symbol":"XBTUSDT","id":32402492707,"side":"Sell","price":66810.7,"timestamp":"2024-05-18T15:46:15.569Z"},{"symbol":"XBTUSDT","id":32402485051,"side":"Sell","price":66810.0,"timestamp":"2024-05-18T15:46:15.569Z"}]}
{"table":"orderBookL2_25","action":"update","data":[{"symbol":"XBTUSDT","id":32402491670,"side":"Sell","size":100000,"price":66795.5,"timestamp":"2024-05-18T15:46:15.569Z"},{"symbol":"XBTUSDT","id":32402499098,"side":"Sell","size":200000,"price":66792.1,"timestamp":"2024-05-18T15:46:15.569Z"},{"symbol":"XBTUSDT","id":32402491799,"side":"Sell","size":55000,"price":66795.4,"timestamp":"2024-05-18T15:46:15.569Z"}]}
{"table":"orderBookL2_25","action":"insert","data":[{"symbol":"XBTUSDT","id":32402499271,"side":"Sell","size":100000,"price":66788.7,"timestamp":"2024-05-18T15:46:15.569Z"},{"symbol":"XBTUSDT","id":32402499236,"side":"Sell","size":148000,"price":66786.7,"timestamp":"2024-05-18T15:46:15.569Z"},{"symbol":"XBTUSDT","id":32402499234,"side":"Sell","size":198000,"price":66792.0,"timestamp":"2024-05-18T15:46:15.569Z"},{"symbol":"XBTUSDT","id":32402499309,"side":"Sell","size":2000,"price":66794.9,"timestamp":"2024-05-18T15:46:15.569Z"}]}
{"table":"orderBookL2_25","action":"delete","data":[{"symbol":"ETHUSDT","id":32402493850,"side":"Sell","price":3111.81,"timestamp":"2024-05-18T15:46:15.599Z"},{"symbol":"ETHUSDT","id":32402493837,"side":"Sell","price":3112.01,"timestamp":"2024-05-18T15:46:15.599Z"},{"symbol":"ETHUSDT","id":32402455680,"side":"Sell","price":3112.02,"timestamp":"2024-05-18T15:46:15.599Z"},{"symbol":"ETHUSDT","id":32402494228,"side":"Sell","price":3112.00,"timestamp":"2024-05-18T15:46:15.599Z"},{"symbol":"ETHUSDT","id":32402499215,"side":"Buy","price":3109.16,"timestamp":"2024-05-18T15:46:15.599Z"},{"symbol":"ETHUSDT","id":32402499311,"side":"Buy","price":3109.15,"timestamp":"2024-05-18T15:46:15.599Z"},{"symbol":"ETHUSDT","id":32402458908,"side":"Buy","price":3107.30,"timestamp":"2024-05-18T15:46:15.599Z"}]}
{"table":"orderBookL2_25","action":"insert","data":[{"symbol":"ETHUSDT","id":32402499418,"side":"Sell","size":28000,"price":3110.19,"timestamp":"2024-05-18T15:46:15.599Z"},{"symbol":"ETHUSDT","id":32402499401,"side":"Sell","size":100000,"price":3109.83,"timestamp":"2024-05-18T15:46:15.599Z"},{"symbol":"ETHUSDT","id":32402499433,"side":"Sell","size":25000,"price":3110.18,"timestamp":"2024-05-18T15:46:15.599Z"},{"symbol":"ETHUSDT","id":32402499416,"side":"Sell","size":319000,"price":3110.24,"timestamp":"2024-05-18T15:46:15.599Z"},{"symbol":"ETHUSDT","id":32402499463,"side":"Buy","size":1000,"price":3109.21,"timestamp":"2024-05-18T15:46:15.599Z"},{"symbol":"ETHUSDT","id":32402499421,"side":"Buy","size":66000,"price":3108.84,"timestamp":"2024-05-18T15:46:15.599Z"},{"symbol":"ETHUSDT","id":32402499461,"side":"Buy","size":1000,"price":3109.20,"timestamp":"2024-05-18T15:46:15.599Z"}]}
{"table":"orderBookL2_25","action":"delete","data":[{"symbol":"XBTUSDT","id":32402499210,"side":"Sell","price":66806.9,"timestamp":"2024-05-18T15:46:15.618Z"},{"symbol":"XBTUSDT","id":32402499179,"side":"Sell","price":66795.1,"timestamp":"2024-05-18T15:46:15.618Z"},{"symbol":"XBTUSDT","id":32402491693,"side":"Sell","price":66808.3,"timestamp":"2024-05-18T15:46:15.618Z"},{"symbol":"XBTUSDT","id":32402471489,"side":"Sell","price":66808.7,"timestamp":"2024-05-18T15:46:15.618Z"},{"symbol":"XBTUSDT","id":32402481228,"side":"Sell","price":66807.9,"timestamp":"2024-05-18T15:46:15.618Z"},{"symbol":"XBTUSDT","id":32402499197,"side":"Sell","price":66800.5,"timestamp":"2024-05-18T15:46:15.618Z"},{"symbol":"XBTUSDT","id":32402499183,"side":"Buy","price":66772.3,"timestamp":"2024-05-18T15:46:15.618Z"},{"symbol":"XBTUSDT","id":32402498422,"side":"Buy","price":66752.3,"timestamp":"2024-05-18T15:46:15.618Z"}]}
{"table":"orderBookL2_25","action":"update","data":[{"symbol":"XBTUSDT","id":32402494269,"side":"Sell","size":20000,"price":66800.4,"timestamp":"2024-05-18T15:46:15.618Z"},{"symbol":"XBTUSDT","id":32402493180,"side":"Buy","size":166000,"price":66772.2,"timestamp":"2024-05-18T15:46:15.618Z"}]}
{"table":"orderBookL2_25","action":"insert","data":[{"symbol":"XBTUSDT","id":32402499471,"side":"Sell","size":212000,"price":66797.4,"timestamp":"2024-05-18T15:46:15.618Z"},{"symbol":"XBTUSDT","id":32402499518,"side":"Sell","size":20000,"price":66800.3,"timestamp":"2024-05-18T15:46:15.618Z"},{"symbol":"XBTUSDT","id":32402499467,"side":"Sell","size":3000,"price":66797.1,"timestamp":"2024-05-18T15:46:15.618Z"},{"symbol":"XBTUSDT","id":32402499454,"side":"Sell","size":30000,"price":66791.9,"timestamp":"2024-05-18T15:46:15.618Z"},{"symbol":"XBTUSDT","id":32402499500,"side":"Sell","size":1000,"price":66806.9,"timestamp":"2024-05-18T15:46:15.618Z"},{"symbol":"XBTUSDT","id":32402499449,"side":"Sell","size":69000,"price":66788.6,"timestamp":"2024-05-18T15:46:15.618Z"},{"symbol":"XBTUSDT","id":32402499446,"side":"Buy","size":20000,"price":66772.4,"timestamp":"2024-05-18T15:46:15.618Z"},{"symbol":"XBTUSDT","id":32402499465,"side":"Buy","size":20000,"price":66772.5,"timestamp":"2024-05-18T15:46:15.618Z"}]}
{"table":"orderBookL2_25","action":"delete","data":[{"symbol":"ETHUSDT","id":32402499240,"side":"Sell","price":3110.83,"timestamp":"2024-05-18T15:46:15.648Z"},{"symbol":"ETHUSDT","id":32402499433,"side":"Sell","price":3110.18,"timestamp":"2024-05-18T15:46:15.648Z"},{"symbol":"ETHUSDT","id":32402497868,"side":"Sell","price":3109.92,"timestamp":"2024-05-18T15:46:15.648Z"},{"symbol":"ETHUSDT","id":32402493816,"side":"Buy","price":3107.31,"timestamp":"2024-05-18T15:46:15.648Z"},{"symbol":"ETHUSDT","id":32402499461,"side":"Buy","price":3109.20,"timestamp":"2024-05-18T15:46:15.648Z"},{"symbol":"ETHUSDT","id":32402499463,"side":"Buy","price":3109.21,"timestamp":"2024-05-18T15:46:15.648Z"},{"symbol":"ETHUSDT","id":32402498923,"side":"Buy","price":3109.39,"timestamp":"2024-05-18T15:46:15.648Z"}]}
{"table":"orderBookL2_25","action":"update","data":[{"symbol":"ETHUSDT","id":32402496877,"side":"Sell","size":63000,"price":3110.84,"timestamp":"2024-05-18T15:46:15.648Z"},{"symbol":"ETHUSDT","id":32402496871,"side":"Sell","size":100000,"price":3110.88,"timestamp":"2024-05-18T15:46:15.648Z"},{"symbol":"ETHUSDT","id":32402496774,"side":"Buy","size":241000,"price":3109.47,"timestamp":"2024-05-18T15:46:15.648Z"},{"symbol":"ETHUSDT","id":32401945550,"side":"Buy","size":72000,"price":3109.40,"timestamp":"2024-05-18T15:46:15.648Z"}]}
{"table":"orderBookL2_25","action":"insert","data":[{"symbol":"ETHUSDT","id":32402499546,"side":"Sell","size":24000,"price":3109.82,"timestamp":"2024-05-18T15:46:15.648Z"},{"symbol":"ETHUSDT","id":32402499571,"side":"Sell","size":32000,"price":3110.90,"timestamp":"2024-05-18T15:46:15.648Z"},{"symbol":"ETHUSDT","id":32402499536,"side":"Sell","size":32000,"price":3110.89,"timestamp":"2024-05-18T15:46:15.648Z"},{"symbol":"ETHUSDT","id":32402499525,"side":"Buy","size":1000,"price":3109.23,"timestamp":"2024-05-18T15:46:15.648Z"},{"symbol":"ETHUSDT","id":32402499532,"side":"Buy","size":32000,"price":3109.46,"timestamp":"2024-05-18T15:46:15.648Z"},{"symbol":"ETHUSDT","id":32402499573,"side":"Buy","size":32000,"price":3109.45,"timestamp":"2024-05-18T15:46:15.648Z"},{"symbol":"ETHUSDT","id":32402499556,"side":"Buy","size":1000,"price":3109.24,"timestamp":"2024-05-18T15:46:15.648Z"}]}
{"table":"orderBookL2_25","action":"delete","data":[{"symbol":"XBTUSDT","id":32402494269,"side":"Sell","price":66800.4,"timestamp":"2024-05-18T15:46:15.667Z"},{"symbol":"XBTUSDT","id":32402499309,"side":"Sell","price":66794.9,"timestamp":"2024-05-18T15:46:15.667Z"},{"symbol":"XBTUSDT","id":32402499518,"side":"Sell","price":66800.3,"timestamp":"2024-05-18T15:46:15.667Z"},{"symbol":"XBTUSDT","id":32402499465,"side":"Buy","price":66772.5,"timestamp":"2024-05-18T15:46:15.667Z"}]}
