{"table":"orderBookL2_25","action":"delete","data":[{"symbol":"ETHUSDT","id":32402519425,"side":"Sell","price":3110.57,"timestamp":"2024-05-18T15:46:24.931Z"},{"symbol":"ETHUSDT","id":32402476065,"side":"Sell","price":3112.99,"timestamp":"2024-05-18T15:46:24.931Z"},{"symbol":"ETHUSDT","id":32402519462,"side":"Sell","price":3110.58,"timestamp":"2024-05-18T15:46:24.931Z"},{"symbol":"ETHUSDT","id":32402519423,"side":"Buy","price":3108.94,"timestamp":"2024-05-18T15:46:24.931Z"},{"symbol":"ETHUSDT","id":32402519404,"side":"Buy","price":3108.95,"timestamp":"2024-05-18T15:46:24.931Z"},{"symbol":"ETHUSDT","id":32402488025,"side":"Buy","price":3107.08,"timestamp":"2024-05-18T15:46:24.931Z"},{"symbol":"ETHUSDT","id":32402519440,"side":"Buy","price":3108.82,"timestamp":"2024-05-18T15:46:24.931Z"}]}
{"table":"orderBookL2_25","action":"update","data":[{"symbol":"ETHUSDT","id":32402517386,"side":"Sell","size":905000,"price":3110.02,"timestamp":"2024-05-18T15:46:24.931Z"},{"symbol":"ETHUSDT","id":32402519363,"side":"Sell","size":109000,"price":3109.83,"timestamp":"2024-05-18T15:46:24.931Z"},{"symbol":"ETHUSDT","id":32402512820,"side":"Buy","size":241000,"price":3108.83,"timestamp":"2024-05-18T15:46:24.931Z"},{"symbol":"ETHUSDT","id":32402512570,"side":"Buy","size":24000,"price":3108.81,"timestamp":"2024-05-18T15:46:24.931Z"}]}
{"table":"orderBookL2_25","action":"insert","data":[{"symbol":"ETHUSDT","id":32402519557,"side":"Sell","size":32000,"price":3110.61,"timestamp":"2024-05-18T15:46:24.931Z"},{"symbol":"ETHUSDT","id":32402519560,"side":"Sell","size":32000,"price":3110.62,"timestamp":"2024-05-18T15:46:24.931Z"},{"symbol":"ETHUSDT","id":32402519465,"side":"Sell","size":28000,"price":3110.19,"timestamp":"2024-05-18T15:46:24.931Z"},{"symbol":"ETHUSDT","id":32402519491,"side":"Buy","size":1000,"price":3108.85,"timestamp":"2024-05-18T15:46:24.931Z"},{"symbol":"ETHUSDT","id":32402519539,"side":"Buy","size":32000,"price":3109.09,"timestamp":"2024-05-18T15:46:24.931Z"},{"symbol":"ETHUSDT","id":32402519544,"side":"Buy","size":32000,"price":3109.10,"timestamp":"2024-05-18T15:46:24.931Z"},{"symbol":"ETHUSDT","id":32402519562,"side":"Buy","size":1000,"price":3108.86,"timestamp":"2024-05-18T15:46:24.931Z"}]}
{"table":"orderBookL2_25","action":"delete","data":[{"symbol":"XBTETH","id":32402423015,"side":"Sell","price":21.786,"timestamp":"2024-05-18T15:46:24.950Z"}]}
{"table":"orderBookL2_25","action":"insert","data":[{"symbol":"XBTETH","id":32402519521,"side":"Sell","size":5,"price":21.782,"timestamp":"2024-05-18T15:46:24.950Z"}]}
{"table":"orderBookL2_25","action":"delete","data":[{"symbol":"XBTUSDT","id":32402499271,"side":"Sell","price":66788.7,"timestamp":"2024-05-18T15:46:24.974Z"},{"symbol":"XBTUSDT","id":32402519501,"side":"Sell","price":66777.4,"timestamp":"2024-05-18T15:46:24.974Z"},{"symbol":"XBTUSDT","id":32402519498,"side":"Sell","price":66777.3,"timestamp":"2024-05-18T15:46:24.974Z"},{"symbol":"XBTUSDT","id":32402519448,"side":"Sell","price":66774.2,"timestamp":"2024-05-18T15:46:24.974Z"},{"symbol":"XBTUSDT","id":32402519546,"side":"Sell","price":66784.1,"timestamp":"2024-05-18T15:46:24.974Z"},{"symbol":"XBTUSDT","id":32402518359,"side":"Buy","price":66732.5,"timestamp":"2024-05-18T15:46:24.974Z"},{"symbol":"XBTUSDT","id":32402518361,"side":"Buy","price":66734.0,"timestamp":"2024-05-18T15:46:24.974Z"},{"symbol":"XBTUSDT","id":32402519474,"side":"Buy","price":66748.3,"timestamp":"2024-05-18T15:46:24.974Z"}]}
{"table":"orderBookL2_25","action":"update","data":[{"symbol":"XBTUSDT","id":32402502861,"side":"Sell","size":100000,"price":66784.3,"timestamp":"2024-05-18T15:46:24.974Z"},{"symbol":"XBTUSDT","id":32402519552,"side":"Sell","size":156000,"price":66776.8,"timestamp":"2024-05-18T15:46:24.974Z"}]}
{"table":"orderBookL2_25","action":"insert","data":[{"symbol":"XBTUSDT","id":32402519671,"side":"Sell","size":218000,"price":66778.3,"timestamp":"2024-05-18T15:46:24.974Z"},{"symbol":"XBTUSDT","id":32402519578,"side":"Sell","size":20000,"price":66776.7,"timestamp":"2024-05-18T15:46:24.974Z"},{"symbol":"XBTUSDT","id":32402519635,"side":"Sell","size":20000,"price":66776.6,"timestamp":"2024-05-18T15:46:24.974Z"},{"symbol":"XBTUSDT","id":32402519620,"side":"Sell","size":1000,"price":66783.9,"timestamp":"2024-05-18T15:46:24.974Z"},{"symbol":"XBTUSDT","id":32402519631,"side":"Sell","size":65000,"price":66767.8,"timestamp":"2024-05-18T15:46:24.974Z"},{"symbol":"XBTUSDT","id":32402510029,"side":"Buy","size":74000,"price":66730.1,"timestamp":"2024-05-18T15:46:24.974Z"},{"symbol":"XBTUSDT","id":32402505149,"side":"Buy","size":100000,"price":66730.4,"timestamp":"2024-05-18T15:46:24.974Z"},{"symbol":"XBTUSDT","id":32402519649,"side":"Buy","size":20000,"price":66748.5,"timestamp":"2024-05-18T15:46:24.974Z"}]}
{"table":"orderBookL2_25","action":"delete","data":[{"symbol":"ETHUSDT","id":32402519560,"side":"Sell","price":3110.62,"timestamp":"2024-05-18T15:46:24.980Z"},{"symbol":"ETHUSDT","id":32402519557,"side":"Sell","price":3110.61,"timestamp":"2024-05-18T15:46:24.980Z"},{"symbol":"ETHUSDT","id":32402519539,"side":"Buy","price":3109.09,"timestamp":"2024-05-18T15:46:24.980Z"}]}
{"table":"orderBookL2_25","action":"insert","data":[{"symbol":"ETHUSDT","id":32402519662,"side":"Sell","size":32000,"price":3110.58,"timestamp":"2024-05-18T15:46:24.980Z"},{"symbol":"ETHUSDT","id":32402519599,"side":"Sell","size":32000,"price":3110.59,"timestamp":"2024-05-18T15:46:24.980Z"},{"symbol":"ETHUSDT","id":32402519664,"side":"Buy","size":32000,"price":3109.11,"timestamp":"2024-05-18T15:46:24.980Z"}]}
{"table":"orderBookL2_25","action":"delete","data":[{"symbol":"XBTUSDT","id":32402519550,"side":"Sell","price":66784.0,"timestamp":"2024-05-18T15:46:25.023Z"},{"symbol":"XBTUSDT","id":32402519578,"side":"Sell","price":66776.7,"timestamp":"2024-05-18T15:46:25.023Z"},{"symbol":"XBTUSDT","id":32402519635,"side":"Sell","price":66776.6,"timestamp":"2024-05-18T15:46:25.023Z"},{"symbol":"XBTUSDT","id":32402519620,"side":"Sell","price":66783.9,"timestamp":"2024-05-18T15:46:25.023Z"},{"symbol":"XBTUSDT","id":32402519442,"side":"Buy","price":66748.4,"timestamp":"2024-05-18T15:46:25.023Z"}]}
{"table":"orderBookL2_25","action":"update","data":[{"symbol":"XBTUSDT","id":32402510159,"side":"Sell","size":30000,"price":66776.9,"timestamp":"2024-05-18T15:46:25.023Z"}]}
{"table":"orderBookL2_25","action":"insert","data":[{"symbol":"XBTUSDT","id":32402499271,"side":"Sell","size":100000,"price":66788.7,"timestamp":"2024-05-18T15:46:25.023Z"},{"symbol":"XBTUSDT","id":32402519677,"side":"Sell","size":1000,"price":66784.2,"timestamp":"2024-05-18T15:46:25.023Z"},{"symbol":"XBTUSDT","id":32402519675,"side":"Sell","size":1000,"price":66784.1,"timestamp":"2024-05-18T15:46:25.023Z"},{"symbol":"XBTUSDT","id":32402519703,"side":"Sell","size":20000,"price":66777.0,"timestamp":"2024-05-18T15:46:25.023Z"},{"symbol":"XBTUSDT","id":32402519723,"side":"Buy","size":20000,"price":66748.6,"timestamp":"2024-05-18T15:46:25.023Z"}]}
{"table":"orderBookL2_25","action":"delete","data":[{"symbol":"ETHUSDT","id":32402519662,"side":"Sell","price":3110.58,"timestamp":"2024-05-18T15:46:25.029Z"},{"symbol":"ETHUSDT","id":32402519599,"side":"Sell","price":3110.59,"timestamp":"2024-05-18T15:46:25.029Z"},{"symbol":"ETHUSDT","id":32402470274,"side":"Sell","price":3112.84,"timestamp":"2024-05-18T15:46:25.029Z"},{"symbol":"ETHUSDT","id":32402519664,"side":"Buy","price":3109.11,"timestamp":"2024-05-18T15:46:25.029Z"},{"symbol":"ETHUSDT","id":32402480382,"side":"Buy","price":3107.24,"timestamp":"2024-05-18T15:46:25.029Z"},{"symbol":"ETHUSDT","id":32402518836,"side":"Buy","price":3107.25,"timestamp":"2024-05-18T15:46:25.029Z"}]}
{"table":"orderBookL2_25","action":"insert","data":[{"symbol":"ETHUSDT","id":32402519754,"side":"Sell","size":32000,"price":3110.60,"timestamp":"2024-05-18T15:46:25.029Z"},{"symbol":"ETHUSDT","id":32402519742,"side":"Sell","size":32000,"price":3110.59,"timestamp":"2024-05-18T15:46:25.029Z"},{"symbol":"ETHUSDT","id":32402519752,"side":"Sell","size":69000,"price":3109.82,"timestamp":"2024-05-18T15:46:25.029Z"},{"symbol":"ETHUSDT","id":32402519694,"side":"Buy","size":161000,"price":3108.84,"timestamp":"2024-05-18T15:46:25.029Z"},{"symbol":"ETHUSDT","id":32402519681,"side":"Buy","size":32000,"price":3109.09,"timestamp":"2024-05-18T15:46:25.029Z"},{"symbol":"ETHUSDT","id":32402519746,"side":"Buy","size":314000,"price":3108.20,"timestamp":"2024-05-18T15:46:25.029Z"}]}
{"table":"orderBookL2_25","action":"delete","data":[{"symbol":"XBTUSDT","id":32402499271,"side":"Sell","price":66788.7,"timestamp":"2024-05-18T15:46:25.072Z"},{"symbol":"XBTUSDT","id":32402519677,"side":"Sell","price":66784.2,"timestamp":"2024-05-18T15:46:25.072Z"},{"symbol":"XBTUSDT","id":32402519675,"side":"Sell","price":66784.1,"timestamp":"2024-05-18T15:46:25.072Z"},{"symbol":"XBTUSDT","id":32402519703,"side":"Sell","price":66777.0,"timestamp":"2024-05-18T15:46:25.072Z"},{"symbol":"XBTUSDT","id":32402519723,"side":"Buy","price":66748.6,"timestamp":"2024-05-18T15:46:25.072Z"}]}
{"table":"orderBookL2_25","action":"update","data":[{"symbol":"XBTUSDT","id":32402502861,"side":"Sell","size":101000,"price":66784.3,"timestamp":"2024-05-18T15:46:25.072Z"},{"symbol":"XBTUSDT","id":32402510159,"side":"Sell","size":10000,"price":66776.9,"timestamp":"2024-05-18T15:46:25.072Z"},{"symbol":"XBTUSDT","id":32402512008,"side":"Sell","size":68000,"price":66788.6,"timestamp":"2024-05-18T15:46:25.072Z"}]}
{"table":"orderBookL2_25","action":"insert","data":[{"symbol":"XBTUSDT","id":32402519770,"side":"Sell","size":20000,"price":66774.9,"timestamp":"2024-05-18T15:46:25.072Z"},{"symbol":"XBTUSDT","id":32402519814,"side":"Sell","size":20000,"price":66777.0,"timestamp":"2024-05-18T15:46:25.072Z"},{"symbol":"XBTUSDT","id":32402519798,"side":"Sell","size":1000,"price":66784.4,"timestamp":"2024-05-18T15:46:25.072Z"},{"symbol":"XBTUSDT","id":32402519812,"side":"Sell","size":20000,"price":66777.1,"timestamp":"2024-05-18T15:46:25.072Z"},{"symbol":"XBTUSDT","id":32402519776,"side":"Buy","size":20000,"price":66748.4,"timestamp":"2024-05-18T15:46:25.072Z"}]}
{"table":"orderBookL2_25","action":"delete","data":[{"symbol":"ETHUSDT","id":32402519742,"side":"Sell","price":3110.59,"timestamp":"2024-05-18T15:46:25.078Z"},{"symbol":"ETHUSDT","id":32402519754,"side":"Sell","price":3110.60,"timestamp":"2024-05-18T15:46:25.078Z"},{"symbol":"ETHUSDT","id":32402519544,"side":"Buy","price":3109.10,"timestamp":"2024-05-18T15:46:25.078Z"},{"symbol":"ETHUSDT","id":32402519491,"side":"Buy","price":3108.85,"timestamp":"2024-05-18T15:46:25.078Z"},{"symbol":"ETHUSDT","id":32402519681,"side":"Buy","price":3109.09,"timestamp":"2024-05-18T15:46:25.078Z"},{"symbol":"ETHUSDT","id":32402519562,"side":"Buy","price":3108.86,"timestamp":"2024-05-18T15:46:25.078Z"}]}
{"table":"orderBookL2_25","action":"update","data":[{"symbol":"ETHUSDT","id":32402519694,"side":"Buy","size":162000,"price":3108.84,"timestamp":"2024-05-18T15:46:25.078Z"},{"symbol":"ETHUSDT","id":32402512820,"side":"Buy","size":242000,"price":3108.83,"timestamp":"2024-05-18T15:46:25.078Z"}]}
{"table":"orderBookL2_25","action":"insert","data":[{"symbol":"ETHUSDT","id":32402519788,"side":"Sell","size":32000,"price":3110.62,"timestamp":"2024-05-18T15:46:25.078Z"},{"symbol":"ETHUSDT","id":32402519816,"side":"Sell","size":32000,"price":3110.63,"timestamp":"2024-05-18T15:46:25.078Z"},{"symbol":"ETHUSDT","id":32402519792,"side":"Buy","size":32000,"price":3109.08,"timestamp":"2024-05-18T15:46:25.078Z"},{"symbol":"ETHUSDT","id":32402519810,"side":"Buy","size":32000,"price":3109.09,"timestamp":"2024-05-18T15:46:25.078Z"},{"symbol":"ETHUSDT","id":32402480382,"side":"Buy","size":100000,"price":3107.24,"timestamp":"2024-05-18T15:46:25.078Z"},{"symbol":"ETHUSDT","id":32402518836,"side":"Buy","size":65000,"price":3107.25,"timestamp":"2024-05-18T15:46:25.078Z"}]}
{"table":"orderBookL2_25","action":"delete","data":[{"symbol":"XBTUSDT","id":32402519814,"side":"Sell","price":66777.0,"timestamp":"2024-05-18T15:46:25.121Z"},{"symbol":"XBTUSDT","id":32402519798,"side":"Sell","price":66784.4,"timestamp":"2024-05-18T15:46:25.121Z"},{"symbol":"XBTUSDT","id":32402519552,"side":"Sell","price":66776.8,"timestamp":"2024-05-18T15:46:25.121Z"},{"symbol":"XBTUSDT","id":32402519649,"side":"Buy","price":66748.5,"timestamp":"2024-05-18T15:46:25.121Z"}]}
{"table":"orderBookL2_25","action":"update","data":[{"symbol":"XBTUSDT","id":32402502861,"side":"Sell","size":100000,"price":66784.3,"timestamp":"2024-05-18T15:46:25.121Z"},{"symbol":"XBTUSDT","id":32402512008,"side":"Sell","size":68000,"price":66788.6,"timestamp":"2024-05-18T15:46:25.121Z"}]}
{"table":"orderBookL2_25","action":"insert","data":[{"symbol":"XBTUSDT","id":32402519843,"side":"Sell","size":1000,"price":66784.4,"timestamp":"2024-05-18T15:46:25.121Z"},{"symbol":"XBTUSDT","id":32402519828,"side":"Sell","size":20000,"price":66777.2,"timestamp":"2024-05-18T15:46:25.121Z"},{"symbol":"XBTUSDT","id":32402519848,"side":"Sell","size":1000,"price":66784.5,"timestamp":"2024-05-18T15:46:25.121Z"},{"symbol":"XBTUSDT","id":32402519824,"side":"Buy","size":20000,"price":66748.3,"timestamp":"2024-05-18T15:46:25.121Z"}]}
{"table":"orderBookL2_25","action":"delete","data":[{"symbol":"ETHUSDT","id":32402519788,"side":"Sell","price":3110.62,"timestamp":"2024-05-18T15:46:25.127Z"},{"symbol":"ETHUSDT","id":32402447682,"side":"Sell","price":3112.68,"timestamp":"2024-05-18T15:46:25.127Z"},{"symbol":"ETHUSDT","id":32402519810,"side":"Buy","price":3109.09,"timestamp":"2024-05-18T15:46:25.127Z"}]}
{"table":"orderBookL2_25","action":"update","data":[{"symbol":"ETHUSDT","id":32402519363,"side":"Sell","size":100000,"price":3109.83,"timestamp":"2024-05-18T15:46:25.127Z"},{"symbol":"ETHUSDT","id":32402519752,"side":"Sell","size":78000,"price":3109.82,"timestamp":"2024-05-18T15:46:25.127Z"},{"symbol":"ETHUSDT","id":32402518340,"side":"Sell","size":96000,"price":3110.64,"timestamp":"2024-05-18T15:46:25.127Z"}]}
{"table":"orderBookL2_25","action":"insert","data":[{"symbol":"ETHUSDT","id":32402519845,"side":"Sell","size":297000,"price":3110.01,"timestamp":"2024-05-18T15:46:25.127Z"},{"symbol":"ETHUSDT","id":32402519852,"side":"Sell","size":100000,"price":3109.77,"timestamp":"2024-05-18T15:46:25.127Z"},{"symbol":"ETHUSDT","id":32402519835,"side":"Buy","size":32000,"price":3109.07,"timestamp":"2024-05-18T15:46:25.127Z"}]}
{"table":"orderBookL2_25","action":"delete","data":[{"symbol":"XBTUSDT","id":32402512008,"side":"Sell","price":66788.6,"timestamp":"2024-05-18T15:46:25.170Z"},{"symbol":"XBTUSDT","id":32402519843,"side":"Sell","price":66784.4,"timestamp":"2024-05-18T15:46:25.170Z"},{"symbol":"XBTUSDT","id":32402518994,"side":"Sell","price":66786.9,"timestamp":"2024-05-18T15:46:25.170Z"}]}
{"table":"orderBookL2_25","action":"insert","data":[{"symbol":"XBTUSDT","id":32402519878,"side":"Sell","size":20000,"price":66781.7,"timestamp":"2024-05-18T15:46:25.170Z"},{"symbol":"XBTUSDT","id":32402519871,"side":"Sell","size":1000,"price":66784.6,"timestamp":"2024-05-18T15:46:25.170Z"},{"symbol":"XBTUSDT","id":32402519875,"side":"Sell","size":74000,"price":66786.4,"timestamp":"2024-05-18T15:46:25.170Z"}]}
{"table":"orderBookL2_25","action":"delete","data":[{"symbol":"ETHUSDT","id":32402488716,"side":"Sell","price":3112.18,"timestamp":"2024-05-18T15:46:25.176Z"},{"symbol":"ETHUSDT","id":32402519132,"side":"Sell","price":3111.64,"timestamp":"2024-05-18T15:46:25.176Z"}]}
{"table":"orderBookL2_25","action":"update","data":[{"symbol":"ETHUSDT","id":32402519852,"side":"Sell","size":109000,"price":3109.77,"timestamp":"2024-05-18T15:46:25.176Z"},{"symbol":"ETHUSDT","id":32402515605,"side":"Sell","size":574000,"price":3112.01,"timestamp":"2024-05-18T15:46:25.176Z"},{"symbol":"ETHUSDT","id":32402519752,"side":"Sell","size":69000,"price":3109.82,"timestamp":"2024-05-18T15:46:25.176Z"},{"symbol":"ETHUSDT","id":32402455680,"side":"Sell","size":100000,"price":3112.02,"timestamp":"2024-05-18T15:46:25.176Z"}]}
{"table":"orderBookL2_25","action":"insert","data":[{"symbol":"ETHUSDT","id":32402519865,"side":"Sell","size":100000,"price":3111.04,"timestamp":"2024-05-18T15:46:25.176Z"},{"symbol":"ETHUSDT","id":32402519856,"side":"Sell","size":32000,"price":3110.39,"timestamp":"2024-05-18T15:46:25.176Z"}]}
{"table":"orderBookL2_25","action":"delete","data":[{"symbol":"XBTUSDT","id":32402519828,"side":"Sell","price":66777.2,"timestamp":"2024-05-18T15:46:25.219Z"},{"symbol":"XBTUSDT","id":32402519812,"side":"Sell","price":66777.1,"timestamp":"2024-05-18T15:46:25.219Z"},{"symbol":"XBTUSDT","id":32402519871,"side":"Sell","price":66784.6,"timestamp":"2024-05-18T15:46:25.219Z"},{"symbol":"XBTUSDT","id":32402518553,"side":"Sell","price":66785.6,"timestamp":"2024-05-18T15:46:25.219Z"},{"symbol":"XBTUSDT","id":32402518498,"side":"Buy","price":66760.8,"timestamp":"2024-05-18T15:46:25.219Z"}]}
{"table":"orderBookL2_25","action":"insert","data":[{"symbol":"XBTUSDT","id":32402519914,"side":"Sell","size":20000,"price":66777.3,"timestamp":"2024-05-18T15:46:25.219Z"},{"symbol":"XBTUSDT","id":32402519880,"side":"Sell","size":1000,"price":66784.4,"timestamp":"2024-05-18T15:46:25.219Z"},{"symbol":"XBTUSDT","id":32402519919,"side":"Sell","size":20000,"price":66777.4,"timestamp":"2024-05-18T15:46:25.219Z"},{"symbol":"XBTUSDT","id":32402512008,"side":"Sell","size":68000,"price":66788.6,"timestamp":"2024-05-18T15:46:25.219Z"},{"symbol":"XBTUSDT","id":32402511466,"side":"Buy","size":62000,"price":66727.1,"timestamp":"2024-05-18T15:46:25.219Z"}]}
{"table":"orderBookL2_25","action":"delete","data":[{"symbol":"ETHUSDT","id":32402455680,"side":"Sell","price":3112.02,"timestamp":"2024-05-18T15:46:25.225Z"},{"symbol":"ETHUSDT","id":32402519835,"side":"Buy","price":3109.07,"timestamp":"2024-05-18T15:46:25.225Z"},{"symbol":"ETHUSDT","id":32402480382,"side":"Buy","price":3107.24,"timestamp":"2024-05-18T15:46:25.225Z"},{"symbol":"ETHUSDT","id":32402519792,"side":"Buy","price":3109.08,"timestamp":"2024-05-18T15:46:25.225Z"}]}
{"table":"orderBookL2_25","action":"update","data":[{"symbol":"ETHUSDT","id":32402519694,"side":"Buy","size":161000,"price":3108.84,"timestamp":"2024-05-18T15:46:25.225Z"}]}
{"table":"orderBookL2_25","action":"insert","data":[{"symbol":"ETHUSDT","id":32402519906,"side":"Sell","size":68000,"price":3111.48,"timestamp":"2024-05-18T15:46:25.225Z"},{"symbol":"ETHUSDT","id":32402519887,"side":"Buy","size":1000,"price":3108.82,"timestamp":"2024-05-18T15:46:25.225Z"},{"symbol":"ETHUSDT","id":32402519939,"side":"Buy","size":32000,"price":3109.08,"timestamp":"2024-05-18T15:46:25.225Z"},{"symbol":"ETHUSDT","id":32402519935,"side":"Buy","size":32000,"price":3109.07,"timestamp":"2024-05-18T15:46:25.225Z"}]}
{"table":"orderBookL2_25","action":"delete","data":[{"symbol":"XBTUSDT","id":32402519919,"side":"Sell","price":66777.4,"timestamp":"2024-05-18T15:46:25.268Z"},{"symbol":"XBTUSDT","id":32402519914,"side":"Sell","price":66777.3,"timestamp":"2024-05-18T15:46:25.268Z"}]}
{"table":"orderBookL2_25","action":"insert","data":[{"symbol":"XBTUSDT","id":32402519983,"side":"Sell","size":20000,"price":66777.1,"timestamp":"2024-05-18T15:46:25.268Z"},{"symbol":"XBTUSDT","id":32402519981,"side":"Sell","size":20000,"price":66777.2,"timestamp":"2024-05-18T15:46:25.268Z"}]}
{"table":"orderBookL2_25","action":"delete","data":[{"symbol":"ETHUSDT","id":32402519887,"side":"Buy","price":3108.82,"timestamp":"2024-05-18T15:46:25.274Z"}]}
{"table":"orderBookL2_25","action":"update","data":[{"symbol":"ETHUSDT","id":32402519694,"side":"Buy","size":162000,"price":3108.84,"timestamp":"2024-05-18T15:46:25.274Z"}]}
{"table":"orderBookL2_25","action":"insert","data":[{"symbol":"ETHUSDT","id":32402480382,"side":"Buy","size":100000,"price":3107.24,"timestamp":"2024-05-18T15:46:25.274Z"}]}
{"table":"orderBookL2_25","action":"delete","data":[{"symbol":"XBTUSDT","id":32402511466,"side":"Buy","price":66727.1,"timestamp":"2024-05-18T15:46:25.317Z"}]}
{"table":"orderBookL2_25","action":"insert","data":[{"symbol":"XBTUSDT","id":32402520016,"side":"Buy","size":20000,"price":66762.1,"timestamp":"2024-05-18T15:46:25.317Z"}]}
{"table":"orderBookL2_25","action":"delete","data":[{"symbol":"XBTUSDT","id":32402519770,"side":"Sell","price":66774.9,"timestamp":"2024-05-18T15:46:25.366Z"},{"symbol":"XBTUSDT","id":32402511337,"side":"Buy","price":66761.3,"timestamp":"2024-05-18T15:46:25.366Z"}]}
{"table":"orderBookL2_25","action":"update","data":[{"symbol":"XBTUSDT","id":32402512008,"side":"Sell","size":68000,"price":66788.6,"timestamp":"2024-05-18T15:46:25.366Z"},{"symbol":"XBTUSDT","id":32402510029,"side":"Buy","size":74000,"price":66730.1,"timestamp":"2024-05-18T15:46:25.366Z"}]}
{"table":"orderBookL2_25","action":"insert","data":[{"symbol":"XBTUSDT","id":32402520084,"side":"Sell","size":156000,"price":66776.8,"timestamp":"2024-05-18T15:46:25.366Z"},{"symbol":"XBTUSDT","id":32402520105,"side":"Buy","size":16000,"price":66762.2,"timestamp":"2024-05-18T15:46:25.366Z"}]}
{"table":"orderBookL2_25","action":"delete","data":[{"symbol":"ETHUSDT","id":32402515605,"side":"Sell","price":3112.01,"timestamp":"2024-05-18T15:46:25.392Z"}]}
{"table":"orderBookL2_25","action":"update","data":[{"symbol":"ETHUSDT","id":32402518340,"side":"Sell","size":64000,"price":3110.64,"timestamp":"2024-05-18T15:46:25.392Z"}]}
{"table":"orderBookL2_25","action":"insert","data":[{"symbol":"ETHUSDT","id":32402520144,"side":"Sell","size":32000,"price":3110.62,"timestamp":"2024-05-18T15:46:25.392Z"}]}
{"table":"orderBookL2_25","action":"delete","data":[{"symbol":"XBTUSDT","id":32402519880,"side":"Sell","price":66784.4,"timestamp":"2024-05-18T15:46:25.415Z"},{"symbol":"XBTUSDT","id":32402519983,"side":"Sell","price":66777.1,"timestamp":"2024-05-18T15:46:25.415Z"},{"symbol":"XBTUSDT","id":32402519824,"side":"Buy","price":66748.3,"timestamp":"2024-05-18T15:46:25.415Z"}]}
{"table":"orderBookL2_25","action":"insert","data":[{"symbol":"XBTUSDT","id":32402520139,"side":"Sell","size":20000,"price":66777.3,"timestamp":"2024-05-18T15:46:25.415Z"},{"symbol":"XBTUSDT","id":32402520170,"side":"Sell","size":1000,"price":66784.6,"timestamp":"2024-05-18T15:46:25.415Z"},{"symbol":"XBTUSDT","id":32402520137,"side":"Buy","size":20000,"price":66748.5,"timestamp":"2024-05-18T15:46:25.415Z"}]}
{"table":"orderBookL2_25","action":"delete","data":[{"symbol":"ETHUSDT","id":32402519816,"side":"Sell","price":3110.63,"timestamp":"2024-05-18T15:46:25.441Z"},{"symbol":"ETHUSDT","id":32402519935,"side":"Buy","price":3109.07,"timestamp":"2024-05-18T15:46:25.441Z"}]}
{"table":"orderBookL2_25","action":"insert","data":[{"symbol":"ETHUSDT","id":32402520172,"side":"Sell","size":32000,"price":3110.63,"timestamp":"2024-05-18T15:46:25.441Z"},{"symbol":"ETHUSDT","id":32402520174,"side":"Buy","size":32000,"price":3109.09,"timestamp":"2024-05-18T15:46:25.441Z"}]}
{"table":"orderBookL2_25","action":"delete","data":[{"symbol":"XBTUSDT","id":32402512008,"side":"Sell","price":66788.6,"timestamp":"2024-05-18T15:46:25.464Z"}]}
{"table":"orderBookL2_25","action":"insert","data":[{"symbol":"XBTUSDT","id":32402520207,"side":"Sell","size":20000,"price":66774.7,"timestamp":"2024-05-18T15:46:25.464Z"}]}
{"table":"orderBookL2_25","action":"delete","data":[{"symbol":"ETHUSDT","id":32402520144,"side":"Sell","price":3110.62,"timestamp":"2024-05-18T15:46:25.490Z"},{"symbol":"ETHUSDT","id":32402520174,"side":"Buy","price":3109.09,"timestamp":"2024-05-18T15:46:25.490Z"}]}
{"table":"orderBookL2_25","action":"update","data":[{"symbol":"ETHUSDT","id":32402518340,"side":"Sell","size":64000,"price":3110.64,"timestamp":"2024-05-18T15:46:25.490Z"}]}
{"table":"orderBookL2_25","action":"insert","data":[{"symbol":"ETHUSDT","id":32402520235,"side":"Sell","size":32000,"price":3110.62,"timestamp":"2024-05-18T15:46:25.490Z"},{"symbol":"ETHUSDT","id":32402520233,"side":"Buy","size":32000,"price":3109.09,"timestamp":"2024-05-18T15:46:25.490Z"}]}
{"table":"orderBookL2_25","action":"delete","data":[{"symbol":"ETHUSDT","id":32402520235,"side":"Sell","price":3110.62,"timestamp":"2024-05-18T15:46:25.539Z"},{"symbol":"ETHUSDT","id":32402520172,"side":"Sell","price":3110.63,"timestamp":"2024-05-18T15:46:25.539Z"},{"symbol":"ETHUSDT","id":32402520233,"side":"Buy","price":3109.09,"timestamp":"2024-05-18T15:46:25.539Z"}]}
{"table":"orderBookL2_25","action":"update","data":[{"symbol":"ETHUSDT","id":32402518340,"side":"Sell","size":96000,"price":3110.64,"timestamp":"2024-05-18T15:46:25.539Z"}]}
{"table":"orderBookL2_25","action":"insert","data":[{"symbol":"ETHUSDT","id":32402520305,"side":"Sell","size":32000,"price":3110.63,"timestamp":"2024-05-18T15:46:25.539Z"},{"symbol":"ETHUSDT","id":32402515605,"side":"Sell","size":574000,"price":3112.01,"timestamp":"2024-05-18T15:46:25.539Z"},{"symbol":"ETHUSDT","id":32402520274,"side":"Buy","size":32000,"price":3109.07,"timestamp":"2024-05-18T15:46:25.539Z"}]}
{"table":"orderBookL2_25","action":"delete","data":[{"symbol":"XBTUSDT","id":32402520137,"side":"Buy","price":66748.5,"timestamp":"2024-05-18T15:46:25.547Z"}]}
{"table":"orderBookL2_25","action":"insert","data":[{"symbol":"XBTUSDT","id":32402520316,"side":"Buy","size":20000,"price":66748.3,"timestamp":"2024-05-18T15:46:25.547Z"}]}
{"table":"orderBookL2_25","action":"delete","data":[{"symbol":"ETHUSDT","id":32402515605,"side":"Sell","price":3112.01,"timestamp":"2024-05-18T15:46:25.588Z"},{"symbol":"ETHUSDT","id":32402520274,"side":"Buy","price":3109.07,"timestamp":"2024-05-18T15:46:25.588Z"}]}
{"table":"orderBookL2_25","action":"update","data":[{"symbol":"ETHUSDT","id":32402518340,"side":"Sell","size":64000,"price":3110.64,"timestamp":"2024-05-18T15:46:25.588Z"}]}
{"table":"orderBookL2_25","action":"insert","data":[{"symbol":"ETHUSDT","id":32402520352,"side":"Sell","size":32000,"price":3110.62,"timestamp":"2024-05-18T15:46:25.588Z"},{"symbol":"ETHUSDT","id":32402520350,"side":"Buy","size":32000,"price":3109.09,"timestamp":"2024-05-18T15:46:25.588Z"}]}
{"table":"orderBookL2_25","action":"delete","data":[{"symbol":"XBTUSDT","id":32402520139,"side":"Sell","price":66777.3,"timestamp":"2024-05-18T15:46:25.596Z"}]}
{"table":"orderBookL2_25","action":"insert","data":[{"symbol":"XBTUSDT","id":32402520318,"side":"Sell","size":20000,"price":66777.1,"timestamp":"2024-05-18T15:46:25.596Z"}]}
{"table":"orderBookL2_25","action":"delete","data":[{"symbol":"ETHUSDT","id":32402520350,"side":"Buy","price":3109.09,"timestamp":"2024-05-18T15:46:25.637Z"},{"symbol":"ETHUSDT","id":32402480382,"side":"Buy","price":3107.24,"timestamp":"2024-05-18T15:46:25.637Z"},{"symbol":"ETHUSDT","id":32402519939,"side":"Buy","price":3109.08,"timestamp":"2024-05-18T15:46:25.637Z"}]}
{"table":"orderBookL2_25","action":"update","data":[{"symbol":"ETHUSDT","id":32402519694,"side":"Buy","size":161000,"price":3108.84,"timestamp":"2024-05-18T15:46:25.637Z"}]}
{"table":"orderBookL2_25","action":"insert","data":[{"symbol":"ETHUSDT","id":32402520394,"side":"Buy","size":32000,"price":3109.06,"timestamp":"2024-05-18T15:46:25.637Z"},{"symbol":"ETHUSDT","id":32402520379,"side":"Buy","size":1000,"price":3108.82,"timestamp":"2024-05-18T15:46:25.637Z"},{"symbol":"ETHUSDT","id":32402520400,"side":"Buy","size":32000,"price":3109.07,"timestamp":"2024-05-18T15:46:25.637Z"}]}
{"table":"orderBookL2_25","action":"delete","data":[{"symbol":"XBTUSDT","id":32402520318,"side":"Sell","price":66777.1,"timestamp":"2024-05-18T15:46:25.645Z"},{"symbol":"XBTUSDT","id":32402519981,"side":"Sell","price":66777.2,"timestamp":"2024-05-18T15:46:25.645Z"},{"symbol":"XBTUSDT","id":32402520207,"side":"Sell","price":66774.7,"timestamp":"2024-05-18T15:46:25.645Z"},{"symbol":"XBTUSDT","id":32402520170,"side":"Sell","price":66784.6,"timestamp":"2024-05-18T15:46:25.645Z"}]}
{"table":"orderBookL2_25","action":"insert","data":[{"symbol":"XBTUSDT","id":32402520436,"side":"Sell","size":1000,"price":66784.4,"timestamp":"2024-05-18T15:46:25.645Z"},{"symbol":"XBTUSDT","id":32402520408,"side":"Sell","size":20000,"price":66777.4,"timestamp":"2024-05-18T15:46:25.645Z"},{"symbol":"XBTUSDT","id":32402520402,"side":"Sell","size":20000,"price":66777.3,"timestamp":"2024-05-18T15:46:25.645Z"},{"symbol":"XBTUSDT","id":32402512008,"side":"Sell","size":68000,"price":66788.6,"timestamp":"2024-05-18T15:46:25.645Z"}]}
{"table":"orderBookL2_25","action":"delete","data":[{"symbol":"ETHUSDT","id":32402520352,"side":"Sell","price":3110.62,"timestamp":"2024-05-18T15:46:25.686Z"},{"symbol":"ETHUSDT","id":32402520394,"side":"Buy","price":3109.06,"timestamp":"2024-05-18T15:46:25.686Z"},{"symbol":"ETHUSDT","id":32402520400,"side":"Buy","price":3109.07,"timestamp":"2024-05-18T15:46:25.686Z"}]}
{"table":"orderBookL2_25","action":"update","data":[{"symbol":"ETHUSDT","id":32402518340,"side":"Sell","size":96000,"price":3110.64,"timestamp":"2024-05-18T15:46:25.686Z"}]}
{"table":"orderBookL2_25","action":"insert","data":[{"symbol":"ETHUSDT","id":32402515605,"side":"Sell","size":574000,"price":3112.01,"timestamp":"2024-05-18T15:46:25.686Z"},{"symbol":"ETHUSDT","id":32402520508,"side":"Buy","size":32000,"price":3109.07,"timestamp":"2024-05-18T15:46:25.686Z"},{"symbol":"ETHUSDT","id":32402520466,"side":"Buy","size":32000,"price":3109.08,"timestamp":"2024-05-18T15:46:25.686Z"}]}
{"table":"orderBookL2_25","action":"delete","data":[{"symbol":"XBTUSDT","id":32402512008,"side":"Sell","price":66788.6,"timestamp":"2024-05-18T15:46:25.694Z"},{"symbol":"XBTUSDT","id":32402520408,"side":"Sell","price":66777.4,"timestamp":"2024-05-18T15:46:25.694Z"},{"symbol":"XBTUSDT","id":32402520402,"side":"Sell","price":66777.3,"timestamp":"2024-05-18T15:46:25.694Z"}]}
{"table":"orderBookL2_25","action":"insert","data":[{"symbol":"XBTUSDT","id":32402520519,"side":"Sell","size":3000,"price":66787.9,"timestamp":"2024-05-18T15:46:25.694Z"},{"symbol":"XBTUSDT","id":32402520454,"side":"Sell","size":20000,"price":66777.2,"timestamp":"2024-05-18T15:46:25.694Z"},{"symbol":"XBTUSDT","id":32402520447,"side":"Sell","size":20000,"price":66777.1,"timestamp":"2024-05-18T15:46:25.694Z"}]}
{"table":"orderBookL2_25","action":"delete","data":[{"symbol":"XBTETH","id":32402424310,"side":"Buy","price":21.184,"timestamp":"2024-05-18T15:46:25.715Z"}]}
{"table":"orderBookL2_25","action":"insert","data":[{"symbol":"XBTETH","id":32402520545,"side":"Buy","size":6,"price":21.179,"timestamp":"2024-05-18T15:46:25.715Z"}]}
{"table":"orderBookL2_25","action":"delete","data":[{"symbol":"ETHUSDT","id":32402519865,"side":"Sell","price":3111.04,"timestamp":"2024-05-18T15:46:25.735Z"},{"symbol":"ETHUSDT","id":32402520508,"side":"Buy","price":3109.07,"timestamp":"2024-05-18T15:46:25.735Z"},{"symbol":"ETHUSDT","id":32402505498,"side":"Buy","price":3107.91,"timestamp":"2024-05-18T15:46:25.735Z"},{"symbol":"ETHUSDT","id":32402520379,"side":"Buy","price":3108.82,"timestamp":"2024-05-18T15:46:25.735Z"}]}
{"table":"orderBookL2_25","action":"update","data":[{"symbol":"ETHUSDT","id":32402518340,"side":"Sell","size":96000,"price":3110.64,"timestamp":"2024-05-18T15:46:25.735Z"},{"symbol":"ETHUSDT","id":32402515605,"side":"Sell","size":574000,"price":3112.01,"timestamp":"2024-05-18T15:46:25.735Z"},{"symbol":"ETHUSDT","id":32402519694,"side":"Buy","size":162000,"price":3108.84,"timestamp":"2024-05-18T15:46:25.735Z"}]}
{"table":"orderBookL2_25","action":"insert","data":[{"symbol":"ETHUSDT","id":32402455680,"side":"Sell","size":100000,"price":3112.02,"timestamp":"2024-05-18T15:46:25.735Z"},{"symbol":"ETHUSDT","id":32402480382,"side":"Buy","size":100000,"price":3107.24,"timestamp":"2024-05-18T15:46:25.735Z"},{"symbol":"ETHUSDT","id":32402520605,"side":"Buy","size":32000,"price":3109.07,"timestamp":"2024-05-18T15:46:25.735Z"},{"symbol":"ETHUSDT","id":32402488025,"side":"Buy","size":100000,"price":3107.08,"timestamp":"2024-05-18T15:46:25.735Z"}]}
{"table":"orderBookL2_25","action":"delete","data":[{"symbol":"XBTUSDT","id":32402518202,"side":"Sell","price":66765.8,"timestamp":"2024-05-18T15:46:25.743Z"},{"symbol":"XBTUSDT","id":32402519631,"side":"Sell","price":66767.8,"timestamp":"2024-05-18T15:46:25.743Z"},{"symbol":"XBTUSDT","id":32402519527,"side":"Sell","price":66767.9,"timestamp":"2024-05-18T15:46:25.743Z"},{"symbol":"XBTUSDT","id":32402520084,"side":"Sell","price":66776.8,"timestamp":"2024-05-18T15:46:25.743Z"},{"symbol":"XBTUSDT","id":32402520316,"side":"Buy","price":66748.3,"timestamp":"2024-05-18T15:46:25.743Z"},{"symbol":"XBTUSDT","id":32402519776,"side":"Buy","price":66748.4,"timestamp":"2024-05-18T15:46:25.743Z"},{"symbol":"XBTUSDT","id":32402510029,"side":"Buy","price":66730.1,"timestamp":"2024-05-18T15:46:25.743Z"},{"symbol":"XBTUSDT","id":32402505149,"side":"Buy","price":66730.4,"timestamp":"2024-05-18T15:46:25.743Z"}]}
{"table":"orderBookL2_25","action":"update","data":[{"symbol":"XBTUSDT","id":32402506378,"side":"Sell","size":32000,"price":66764.5,"timestamp":"2024-05-18T15:46:25.743Z"},{"symbol":"XBTUSDT","id":32402511770,"side":"Buy","size":8000,"price":66761.4,"timestamp":"2024-05-18T15:46:25.743Z"},{"symbol":"XBTUSDT","id":32402520016,"side":"Buy","size":36000,"price":66762.1,"timestamp":"2024-05-18T15:46:25.743Z"},{"symbol":"XBTUSDT","id":32402505821,"side":"Buy","size":152000,"price":66764.4,"timestamp":"2024-05-18T15:46:25.743Z"}]}
{"table":"orderBookL2_25","action":"insert","data":[{"symbol":"XBTUSDT","id":32402499098,"side":"Sell","size":100000,"price":66792.1,"timestamp":"2024-05-18T15:46:25.743Z"},{"symbol":"XBTUSDT","id":32402519930,"side":"Sell","size":3000,"price":66788.9,"timestamp":"2024-05-18T15:46:25.743Z"},{"symbol":"XBTUSDT","id":32402499271,"side":"Sell","size":100000,"price":66788.7,"timestamp":"2024-05-18T15:46:25.743Z"},{"symbol":"XBTUSDT","id":32402512008,"side":"Sell","size":68000,"price":66788.6,"timestamp":"2024-05-18T15:46:25.743Z"},{"symbol":"XBTUSDT","id":32402520578,"side":"Buy","size":20000,"price":66748.7,"timestamp":"2024-05-18T15:46:25.743Z"},{"symbol":"XBTUSDT","id":32402520645,"side":"Buy","size":18000,"price":66733.0,"timestamp":"2024-05-18T15:46:25.743Z"},{"symbol":"XBTUSDT","id":32402520586,"side":"Buy","size":20000,"price":66748.8,"timestamp":"2024-05-18T15:46:25.743Z"},{"symbol":"XBTUSDT","id":32402520649,"side":"Buy","size":20000,"price":66734.5,"timestamp":"2024-05-18T15:46:25.743Z"}]}
{"table":"orderBookL2_25","action":"delete","data":[{"symbol":"XBTETH","id":32402424419,"side":"Sell","price":21.829,"timestamp":"2024-05-18T15:46:25.764Z"}]}
{"table":"orderBookL2_25","action":"insert","data":[{"symbol":"XBTETH","id":32402520561,"side":"Sell","size":6,"price":21.825,"timestamp":"2024-05-18T15:46:25.764Z"}]}
{"table":"orderBookL2_25","action":"delete","data":[{"symbol":"ETHUSDT","id":32402519856,"side":"Sell","price":3110.39,"timestamp":"2024-05-18T15:46:25.784Z"},{"symbol":"ETHUSDT","id":32402506255,"side":"Sell","price":3110.98,"timestamp":"2024-05-18T15:46:25.784Z"},{"symbol":"ETHUSDT","id":32402517979,"side":"Sell","price":3110.65,"timestamp":"2024-05-18T15:46:25.784Z"},{"symbol":"ETHUSDT","id":32402519752,"side":"Sell","price":3109.82,"timestamp":"2024-05-18T15:46:25.784Z"},{"symbol":"ETHUSDT","id":32402519906,"side":"Sell","price":3111.48,"timestamp":"2024-05-18T15:46:25.784Z"},{"symbol":"ETHUSDT","id":32402496871,"side":"Sell","price":3110.88,"timestamp":"2024-05-18T15:46:25.784Z"},{"symbol":"ETHUSDT","id":32402519845,"side":"Sell","price":3110.01,"timestamp":"2024-05-18T15:46:25.784Z"},{"symbol":"ETHUSDT","id":32402519363,"side":"Sell","price":3109.83,"timestamp":"2024-05-18T15:46:25.784Z"},{"symbol":"ETHUSDT","id":32402519374,"side":"Sell","price":3110.40,"timestamp":"2024-05-18T15:46:25.784Z"},{"symbol":"ETHUSDT","id":32402518836,"side":"Buy","price":3107.25,"timestamp":"2024-05-18T15:46:25.784Z"},{"symbol":"ETHUSDT","id":32402480382,"side":"Buy","price":3107.24,"timestamp":"2024-05-18T15:46:25.784Z"},{"symbol":"ETHUSDT","id":32402488025,"side":"Buy","price":3107.08,"timestamp":"2024-05-18T15:46:25.784Z"}]}
{"table":"orderBookL2_25","action":"update","data":[{"symbol":"ETHUSDT","id":32402519852,"side":"Sell","size":9000,"price":3109.77,"timestamp":"2024-05-18T15:46:25.784Z"},{"symbol":"ETHUSDT","id":32402518340,"side":"Sell","size":32000,"price":3110.64,"timestamp":"2024-05-18T15:46:25.784Z"}]}
{"table":"orderBookL2_25","action":"insert","data":[{"symbol":"ETHUSDT","id":32402476053,"side":"Sell","size":292000,"price":3113.00,"timestamp":"2024-05-18T15:46:25.784Z"},{"symbol":"ETHUSDT","id":32402488716,"side":"Sell","size":100000,"price":3112.18,"timestamp":"2024-05-18T15:46:25.784Z"},{"symbol":"ETHUSDT","id":32402447682,"side":"Sell","size":100000,"price":3112.68,"timestamp":"2024-05-18T15:46:25.784Z"},{"symbol":"ETHUSDT","id":32402450797,"side":"Sell","size":100000,"price":3114.61,"timestamp":"2024-05-18T15:46:25.784Z"},{"symbol":"ETHUSDT","id":32402441505,"side":"Sell","size":101000,"price":3113.30,"timestamp":"2024-05-18T15:46:25.784Z"},{"symbol":"ETHUSDT","id":32402476065,"side":"Sell","size":120000,"price":3112.99,"timestamp":"2024-05-18T15:46:25.784Z"},{"symbol":"ETHUSDT","id":32402500495,"side":"Sell","size":17234000,"price":3115.00,"timestamp":"2024-05-18T15:46:25.784Z"},{"symbol":"ETHUSDT","id":32402358267,"side":"Sell","size":100000,"price":3114.29,"timestamp":"2024-05-18T15:46:25.784Z"},{"symbol":"ETHUSDT","id":32402470274,"side":"Sell","size":100000,"price":3112.84,"timestamp":"2024-05-18T15:46:25.784Z"},{"symbol":"ETHUSDT","id":32402520621,"side":"Buy","size":100000,"price":3108.01,"timestamp":"2024-05-18T15:46:25.784Z"},{"symbol":"ETHUSDT","id":32402520893,"side":"Buy","size":100000,"price":3109.09,"timestamp":"2024-05-18T15:46:25.784Z"},{"symbol":"ETHUSDT","id":32402520681,"side":"Buy","size":100000,"price":3108.93,"timestamp":"2024-05-18T15:46:25.784Z"}]}
{"table":"orderBookL2_25","action":"delete","data":[{"symbol":"XBTUSDT","id":32402518042,"side":"Sell","price":66771.9,"timestamp":"2024-05-18T15:46:25.792Z"},{"symbol":"XBTUSDT","id":32402519203,"side":"Sell","price":66778.4,"timestamp":"2024-05-18T15:46:25.792Z"},{"symbol":"XBTUSDT","id":32402519878,"side":"Sell","price":66781.7,"timestamp":"2024-05-18T15:46:25.792Z"},{"symbol":"XBTUSDT","id":32402520436,"side":"Sell","price":66784.4,"timestamp":"2024-05-18T15:46:25.792Z"},{"symbol":"XBTUSDT","id":32402519848,"side":"Sell","price":66784.5,"timestamp":"2024-05-18T15:46:25.792Z"},{"symbol":"XBTUSDT","id":32402519671,"side":"Sell","price":66778.3,"timestamp":"2024-05-18T15:46:25.792Z"},{"symbol":"XBTUSDT","id":32402518415,"side":"Sell","price":66771.8,"timestamp":"2024-05-18T15:46:25.792Z"},{"symbol":"XBTUSDT","id":32402506714,"side":"Sell","price":66772.0,"timestamp":"2024-05-18T15:46:25.792Z"},{"symbol":"XBTUSDT","id":32402506980,"side":"Sell","price":66781.8,"timestamp":"2024-05-18T15:46:25.792Z"},{"symbol":"XBTUSDT","id":32402520645,"side":"Buy","price":66733.0,"timestamp":"2024-05-18T15:46:25.792Z"},{"symbol":"XBTUSDT","id":32402520578,"side":"Buy","price":66748.7,"timestamp":"2024-05-18T15:46:25.792Z"},{"symbol":"XBTUSDT","id":32402519196,"side":"Buy","price":66740.9,"timestamp":"2024-05-18T15:46:25.792Z"},{"symbol":"XBTUSDT","id":32402520586,"side":"Buy","price":66748.8,"timestamp":"2024-05-18T15:46:25.792Z"},{"symbol":"XBTUSDT","id":32402520649,"side":"Buy","price":66734.5,"timestamp":"2024-05-18T15:46:25.792Z"}]}
{"table":"orderBookL2_25","action":"update","data":[{"symbol":"XBTUSDT","id":32402462262,"side":"Buy","size":100000,"price":66733.8,"timestamp":"2024-05-18T15:46:25.792Z"},{"symbol":"XBTUSDT","id":32402505821,"side":"Buy","size":292000,"price":66764.4,"timestamp":"2024-05-18T15:46:25.792Z"},{"symbol":"XBTUSDT","id":32402519393,"side":"Buy","size":3000,"price":66741.0,"timestamp":"2024-05-18T15:46:25.792Z"}]}
{"table":"orderBookL2_25","action":"insert","data":[{"symbol":"XBTUSDT","id":32402520916,"side":"Sell","size":1000,"price":66784.7,"timestamp":"2024-05-18T15:46:25.792Z"},{"symbol":"XBTUSDT","id":32402491670,"side":"Sell","size":100000,"price":66795.5,"timestamp":"2024-05-18T15:46:25.792Z"},{"symbol":"XBTUSDT","id":32402520768,"side":"Sell","size":1000,"price":66784.6,"timestamp":"2024-05-18T15:46:25.792Z"},{"symbol":"XBTUSDT","id":32402520713,"side":"Sell","size":370000,"price":66781.6,"timestamp":"2024-05-18T15:46:25.792Z"},{"symbol":"XBTUSDT","id":32402511631,"side":"Sell","size":328000,"price":66795.4,"timestamp":"2024-05-18T15:46:25.792Z"},{"symbol":"XBTUSDT","id":32402502112,"side":"Sell","size":62000,"price":66800.6,"timestamp":"2024-05-18T15:46:25.792Z"},{"symbol":"XBTUSDT","id":32402504870,"side":"Sell","size":538000,"price":66795.7,"timestamp":"2024-05-18T15:46:25.792Z"},{"symbol":"XBTUSDT","id":32402520966,"side":"Sell","size":100000,"price":66774.7,"timestamp":"2024-05-18T15:46:25.792Z"},{"symbol":"XBTUSDT","id":32402502274,"side":"Sell","size":22000,"price":66799.8,"timestamp":"2024-05-18T15:46:25.792Z"},{"symbol":"XBTUSDT","id":32402520709,"side":"Buy","size":357000,"price":66744.1,"timestamp":"2024-05-18T15:46:25.792Z"},{"symbol":"XBTUSDT","id":32402520846,"side":"Buy","size":20000,"price":66748.9,"timestamp":"2024-05-18T15:46:25.792Z"},{"symbol":"XBTUSDT","id":32402520949,"side":"Buy","size":18000,"price":66739.5,"timestamp":"2024-05-18T15:46:25.792Z"},{"symbol":"XBTUSDT","id":32402520862,"side":"Buy","size":20000,"price":66749.0,"timestamp":"2024-05-18T15:46:25.792Z"},{"symbol":"XBTUSDT","id":32402520961,"side":"Buy","size":20000,"price":66740.5,"timestamp":"2024-05-18T15:46:25.792Z"}]}
{"table":"orderBookL2_25","action":"delete","data":[{"symbol":"ETHUSDT","id":32402520305,"side":"Sell","price":3110.63,"timestamp":"2024-05-18T15:46:25.833Z"},{"symbol":"ETHUSDT","id":32402517386,"side":"Sell","price":3110.02,"timestamp":"2024-05-18T15:46:25.833Z"},{"symbol":"ETHUSDT","id":32402518976,"side":"Sell","price":3111.00,"timestamp":"2024-05-18T15:46:25.833Z"},{"symbol":"ETHUSDT","id":32402519465,"side":"Sell","price":3110.19,"timestamp":"2024-05-18T15:46:25.833Z"},{"symbol":"ETHUSDT","id":32402505072,"side":"Sell","price":3110.74,"timestamp":"2024-05-18T15:46:25.833Z"},{"symbol":"ETHUSDT","id":32402519135,"side":"Sell","price":3110.73,"timestamp":"2024-05-18T15:46:25.833Z"},{"symbol":"ETHUSDT","id":32402518340,"side":"Sell","price":3110.64,"timestamp":"2024-05-18T15:46:25.833Z"},{"symbol":"ETHUSDT","id":32402520605,"side":"Buy","price":3109.07,"timestamp":"2024-05-18T15:46:25.833Z"},{"symbol":"ETHUSDT","id":32402520466,"side":"Buy","price":3109.08,"timestamp":"2024-05-18T15:46:25.833Z"}]}
{"table":"orderBookL2_25","action":"update","data":[{"symbol":"ETHUSDT","id":32402517483,"side":"Buy","size":143000,"price":3109.41,"timestamp":"2024-05-18T15:46:25.833Z"},{"symbol":"ETHUSDT","id":32402520893,"side":"Buy","size":132000,"price":3109.09,"timestamp":"2024-05-18T15:46:25.833Z"},{"symbol":"ETHUSDT","id":32402397491,"side":"Buy","size":2400000,"price":3107.56,"timestamp":"2024-05-18T15:46:25.833Z"}]}
{"table":"orderBookL2_25","action":"insert","data":[{"symbol":"ETHUSDT","id":32402521186,"side":"Sell","size":32000,"price":3110.69,"timestamp":"2024-05-18T15:46:25.833Z"},{"symbol":"ETHUSDT","id":32402521307,"side":"Sell","size":32000,"price":3110.68,"timestamp":"2024-05-18T15:46:25.833Z"},{"symbol":"ETHUSDT","id":32398201667,"side":"Sell","size":100000,"price":3115.60,"timestamp":"2024-05-18T15:46:25.833Z"},{"symbol":"ETHUSDT","id":32393962149,"side":"Sell","size":1000,"price":3115.66,"timestamp":"2024-05-18T15:46:25.833Z"},{"symbol":"ETHUSDT","id":32402521006,"side":"Sell","size":2300000,"price":3111.44,"timestamp":"2024-05-18T15:46:25.833Z"},{"symbol":"ETHUSDT","id":32402520990,"side":"Sell","size":905000,"price":3110.36,"timestamp":"2024-05-18T15:46:25.833Z"},{"symbol":"ETHUSDT","id":32402521273,"side":"Sell","size":160000,"price":3111.28,"timestamp":"2024-05-18T15:46:25.833Z"},{"symbol":"ETHUSDT","id":32402480382,"side":"Buy","size":100000,"price":3107.24,"timestamp":"2024-05-18T15:46:25.833Z"},{"symbol":"ETHUSDT","id":32402521331,"side":"Buy","size":32000,"price":3109.19,"timestamp":"2024-05-18T15:46:25.833Z"}]}
{"table":"orderBookL2_25","action":"delete","data":[{"symbol":"XBTUSDT","id":32402520713,"side":"Sell","price":66781.6,"timestamp":"2024-05-18T15:46:25.841Z"},{"symbol":"XBTUSDT","id":32402511631,"side":"Sell","price":66795.4,"timestamp":"2024-05-18T15:46:25.841Z"},{"symbol":"XBTUSDT","id":32402519875,"side":"Sell","price":66786.4,"timestamp":"2024-05-18T15:46:25.841Z"},{"symbol":"XBTUSDT","id":32402520447,"side":"Sell","price":66777.1,"timestamp":"2024-05-18T15:46:25.841Z"},{"symbol":"XBTUSDT","id":32402504870,"side":"Sell","price":66795.7,"timestamp":"2024-05-18T15:46:25.841Z"},{"symbol":"XBTUSDT","id":32402520768,"side":"Sell","price":66784.6,"timestamp":"2024-05-18T15:46:25.841Z"},{"symbol":"XBTUSDT","id":32402520454,"side":"Sell","price":66777.2,"timestamp":"2024-05-18T15:46:25.841Z"},{"symbol":"XBTUSDT","id":32402511770,"side":"Buy","price":66761.4,"timestamp":"2024-05-18T15:46:25.841Z"},{"symbol":"XBTUSDT","id":32402520949,"side":"Buy","price":66739.5,"timestamp":"2024-05-18T15:46:25.841Z"},{"symbol":"XBTUSDT","id":32402520862,"side":"Buy","price":66749.0,"timestamp":"2024-05-18T15:46:25.841Z"},{"symbol":"XBTUSDT","id":32402520961,"side":"Buy","price":66740.5,"timestamp":"2024-05-18T15:46:25.841Z"},{"symbol":"XBTUSDT","id":32402520846,"side":"Buy","price":66748.9,"timestamp":"2024-05-18T15:46:25.841Z"}]}
{"table":"orderBookL2_25","action":"update","data":[{"symbol":"XBTUSDT","id":32402506378,"side":"Sell","size":24000,"price":66764.5,"timestamp":"2024-05-18T15:46:25.841Z"},{"symbol":"XBTUSDT","id":32402517625,"side":"Buy","size":100000,"price":66744.0,"timestamp":"2024-05-18T15:46:25.841Z"}]}
{"table":"orderBookL2_25","action":"insert","data":[{"symbol":"XBTUSDT","id":32402521038,"side":"Sell","size":1000,"price":66785.2,"timestamp":"2024-05-18T15:46:25.841Z"},{"symbol":"XBTUSDT","id":32402521477,"side":"Sell","size":353000,"price":66784.2,"timestamp":"2024-05-18T15:46:25.841Z"},{"symbol":"XBTUSDT","id":32402462668,"side":"Sell","size":100000,"price":66801.9,"timestamp":"2024-05-18T15:46:25.841Z"},{"symbol":"XBTUSDT","id":32402516811,"side":"Sell","size":15000,"price":66808.4,"timestamp":"2024-05-18T15:46:25.841Z"},{"symbol":"XBTUSDT","id":32402521456,"side":"Sell","size":20000,"price":66779.6,"timestamp":"2024-05-18T15:46:25.841Z"},{"symbol":"XBTUSDT","id":32402521346,"side":"Sell","size":20000,"price":66778.9,"timestamp":"2024-05-18T15:46:25.841Z"},{"symbol":"XBTUSDT","id":32402521469,"side":"Sell","size":543000,"price":66792.2,"timestamp":"2024-05-18T15:46:25.841Z"},{"symbol":"XBTUSDT","id":32402521342,"side":"Buy","size":20000,"price":66745.5,"timestamp":"2024-05-18T15:46:25.841Z"},{"symbol":"XBTUSDT","id":32402521388,"side":"Buy","size":20000,"price":66750.2,"timestamp":"2024-05-18T15:46:25.841Z"},{"symbol":"XBTUSDT","id":32402521460,"side":"Buy","size":442000,"price":66752.7,"timestamp":"2024-05-18T15:46:25.841Z"},{"symbol":"XBTUSDT","id":32402521320,"side":"Buy","size":18000,"price":66746.0,"timestamp":"2024-05-18T15:46:25.841Z"},{"symbol":"XBTUSDT","id":32402521373,"side":"Buy","size":20000,"price":66750.4,"timestamp":"2024-05-18T15:46:25.841Z"}]}
{"table":"orderBookL2_25","action":"delete","data":[{"symbol":"ETHUSDT","id":32402521186,"side":"Sell","price":3110.69,"timestamp":"2024-05-18T15:46:25.882Z"},{"symbol":"ETHUSDT","id":32402521307,"side":"Sell","price":3110.68,"timestamp":"2024-05-18T15:46:25.882Z"},{"symbol":"ETHUSDT","id":32402521273,"side":"Sell","price":3111.28,"timestamp":"2024-05-18T15:46:25.882Z"},{"symbol":"ETHUSDT","id":32402397491,"side":"Buy","price":3107.56,"timestamp":"2024-05-18T15:46:25.882Z"},{"symbol":"ETHUSDT","id":32402505210,"side":"Buy","price":3107.48,"timestamp":"2024-05-18T15:46:25.882Z"},{"symbol":"ETHUSDT","id":32402521331,"side":"Buy","price":3109.19,"timestamp":"2024-05-18T15:46:25.882Z"},{"symbol":"ETHUSDT","id":32402480382,"side":"Buy","price":3107.24,"timestamp":"2024-05-18T15:46:25.882Z"},{"symbol":"ETHUSDT","id":32402506278,"side":"Buy","price":3107.40,"timestamp":"2024-05-18T15:46:25.882Z"}]}
{"table":"orderBookL2_25","action":"update","data":[{"symbol":"ETHUSDT","id":32402500495,"side":"Sell","size":17234000,"price":3115.00,"timestamp":"2024-05-18T15:46:25.882Z"},{"symbol":"ETHUSDT","id":32398201667,"side":"Sell","size":100000,"price":3115.60,"timestamp":"2024-05-18T15:46:25.882Z"},{"symbol":"ETHUSDT","id":32393962149,"side":"Sell","size":1000,"price":3115.66,"timestamp":"2024-05-18T15:46:25.882Z"},{"symbol":"ETHUSDT","id":32402520893,"side":"Buy","size":100000,"price":3109.09,"timestamp":"2024-05-18T15:46:25.882Z"}]}
{"table":"orderBookL2_25","action":"insert","data":[{"symbol":"ETHUSDT","id":32402521870,"side":"Sell","size":32000,"price":3111.00,"timestamp":"2024-05-18T15:46:25.882Z"},{"symbol":"ETHUSDT","id":32402521803,"side":"Sell","size":1157000,"price":3112.09,"timestamp":"2024-05-18T15:46:25.882Z"},{"symbol":"ETHUSDT","id":32402521864,"side":"Sell","size":32000,"price":3110.99,"timestamp":"2024-05-18T15:46:25.882Z"},{"symbol":"ETHUSDT","id":32402521474,"side":"Buy","size":100000,"price":3109.42,"timestamp":"2024-05-18T15:46:25.882Z"},{"symbol":"ETHUSDT","id":32402521771,"side":"Buy","size":100000,"price":3109.26,"timestamp":"2024-05-18T15:46:25.882Z"},{"symbol":"ETHUSDT","id":32402521570,"side":"Buy","size":32000,"price":3109.23,"timestamp":"2024-05-18T15:46:25.882Z"},{"symbol":"ETHUSDT","id":32402521785,"side":"Buy","size":192000,"price":3108.47,"timestamp":"2024-05-18T15:46:25.882Z"},{"symbol":"ETHUSDT","id":32402521434,"side":"Buy","size":32000,"price":3109.24,"timestamp":"2024-05-18T15:46:25.882Z"}]}
{"table":"orderBookL2_25","action":"delete","data":[{"symbol":"XBTUSDT","id":32402512008,"side":"Sell","price":66788.6,"timestamp":"2024-05-18T15:46:25.890Z"},{"symbol":"XBTUSDT","id":32402521346,"side":"Sell","price":66778.9,"timestamp":"2024-05-18T15:46:25.890Z"},{"symbol":"XBTUSDT","id":32402521456,"side":"Sell","price":66779.6,"timestamp":"2024-05-18T15:46:25.890Z"},{"symbol":"XBTUSDT","id":32402521477,"side":"Sell","price":66784.2,"timestamp":"2024-05-18T15:46:25.890Z"},{"symbol":"XBTUSDT","id":32402519119,"side":"Buy","price":66754.3,"timestamp":"2024-05-18T15:46:25.890Z"},{"symbol":"XBTUSDT","id":32402520709,"side":"Buy","price":66744.1,"timestamp":"2024-05-18T15:46:25.890Z"},{"symbol":"XBTUSDT","id":32402521373,"side":"Buy","price":66750.4,"timestamp":"2024-05-18T15:46:25.890Z"},{"symbol":"XBTUSDT","id":32402521320,"side":"Buy","price":66746.0,"timestamp":"2024-05-18T15:46:25.890Z"},{"symbol":"XBTUSDT","id":32402521342,"side":"Buy","price":66745.5,"timestamp":"2024-05-18T15:46:25.890Z"}]}
{"table":"orderBookL2_25","action":"update","data":[{"symbol":"XBTUSDT","id":32402508983,"side":"Buy","size":40000,"price":66747.5,"timestamp":"2024-05-18T15:46:25.890Z"},{"symbol":"XBTUSDT","id":32402462262,"side":"Buy","size":100000,"price":66733.8,"timestamp":"2024-05-18T15:46:25.890Z"}]}
{"table":"orderBookL2_25","action":"insert","data":[{"symbol":"XBTUSDT","id":32402521872,"side":"Sell","size":538000,"price":66799.4,"timestamp":"2024-05-18T15:46:25.890Z"},{"symbol":"XBTUSDT","id":32402521886,"side":"Sell","size":20000,"price":66782.7,"timestamp":"2024-05-18T15:46:25.890Z"},{"symbol":"XBTUSDT","id":32402521896,"side":"Sell","size":20000,"price":66782.8,"timestamp":"2024-05-18T15:46:25.890Z"},{"symbol":"XBTUSDT","id":32402521696,"side":"Sell","size":359000,"price":66786.3,"timestamp":"2024-05-18T15:46:25.890Z"},{"symbol":"XBTUSDT","id":32402510029,"side":"Buy","size":74000,"price":66730.1,"timestamp":"2024-05-18T15:46:25.890Z"},{"symbol":"XBTUSDT","id":32402521682,"side":"Buy","size":20000,"price":66746.0,"timestamp":"2024-05-18T15:46:25.890Z"},{"symbol":"XBTUSDT","id":32402521658,"side":"Buy","size":20000,"price":66750.3,"timestamp":"2024-05-18T15:46:25.890Z"},{"symbol":"XBTUSDT","id":32402521686,"side":"Buy","size":371000,"price":66748.5,"timestamp":"2024-05-18T15:46:25.890Z"},{"symbol":"XBTUSDT","id":32402505149,"side":"Buy","size":100000,"price":66730.4,"timestamp":"2024-05-18T15:46:25.890Z"}]}
{"table":"orderBookL2_25","action":"delete","data":[{"symbol":"ETHUSDT","id":32393962149,"side":"Sell","price":3115.66,"timestamp":"2024-05-18T15:46:25.931Z"},{"symbol":"ETHUSDT","id":32402521864,"side":"Sell","price":3110.99,"timestamp":"2024-05-18T15:46:25.931Z"},{"symbol":"ETHUSDT","id":32402521870,"side":"Sell","price":3111.00,"timestamp":"2024-05-18T15:46:25.931Z"},{"symbol":"ETHUSDT","id":32402507985,"side":"Buy","price":3108.25,"timestamp":"2024-05-18T15:46:25.931Z"}]}
{"table":"orderBookL2_25","action":"insert","data":[{"symbol":"ETHUSDT","id":32402521993,"side":"Sell","size":32000,"price":3111.15,"timestamp":"2024-05-18T15:46:25.931Z"},{"symbol":"ETHUSDT","id":32402521918,"side":"Sell","size":32000,"price":3111.14,"timestamp":"2024-05-18T15:46:25.931Z"},{"symbol":"ETHUSDT","id":32402521905,"side":"Sell","size":43000,"price":3111.01,"timestamp":"2024-05-18T15:46:25.931Z"},{"symbol":"ETHUSDT","id":32402397491,"side":"Buy","size":2400000,"price":3107.56,"timestamp":"2024-05-18T15:46:25.931Z"}]}
{"table":"orderBookL2_25","action":"delete","data":[{"symbol":"XBTUSDT","id":32402521896,"side":"Sell","price":66782.8,"timestamp":"2024-05-18T15:46:25.939Z"},{"symbol":"XBTUSDT","id":32402510159,"side":"Sell","price":66776.9,"timestamp":"2024-05-18T15:46:25.939Z"},{"symbol":"XBTUSDT","id":32402521886,"side":"Sell","price":66782.7,"timestamp":"2024-05-18T15:46:25.939Z"},{"symbol":"XBTUSDT","id":32402510029,"side":"Buy","price":66730.1,"timestamp":"2024-05-18T15:46:25.939Z"},{"symbol":"XBTUSDT","id":32402521682,"side":"Buy","price":66746.0,"timestamp":"2024-05-18T15:46:25.939Z"}]}
{"table":"orderBookL2_25","action":"update","data":[{"symbol":"XBTUSDT","id":32402516811,"side":"Sell","size":15000,"price":66808.4,"timestamp":"2024-05-18T15:46:25.939Z"},{"symbol":"XBTUSDT","id":32402521686,"side":"Buy","size":20000,"price":66748.5,"timestamp":"2024-05-18T15:46:25.939Z"},{"symbol":"XBTUSDT","id":32402508983,"side":"Buy","size":22000,"price":66747.5,"timestamp":"2024-05-18T15:46:25.939Z"}]}
{"table":"orderBookL2_25","action":"insert","data":[{"symbol":"XBTUSDT","id":32402522052,"side":"Sell","size":20000,"price":66784.2,"timestamp":"2024-05-18T15:46:25.939Z"},{"symbol":"XBTUSDT","id":32402521927,"side":"Sell","size":20000,"price":66778.8,"timestamp":"2024-05-18T15:46:25.939Z"},{"symbol":"XBTUSDT","id":32402522036,"side":"Sell","size":20000,"price":66784.1,"timestamp":"2024-05-18T15:46:25.939Z"},{"symbol":"XBTUSDT","id":32402522058,"side":"Buy","size":355000,"price":66750.9,"timestamp":"2024-05-18T15:46:25.939Z"},{"symbol":"XBTUSDT","id":32402522045,"side":"Buy","size":18000,"price":66749.5,"timestamp":"2024-05-18T15:46:25.939Z"}]}
{"table":"orderBookL2_25","action":"delete","data":[{"symbol":"ETHUSDT","id":32402521918,"side":"Sell","price":3111.14,"timestamp":"2024-05-18T15:46:25.980Z"},{"symbol":"ETHUSDT","id":32402519852,"side":"Sell","price":3109.77,"timestamp":"2024-05-18T15:46:25.980Z"},{"symbol":"ETHUSDT","id":32402494493,"side":"Sell","price":3111.26,"timestamp":"2024-05-18T15:46:25.980Z"},{"symbol":"ETHUSDT","id":32402521570,"side":"Buy","price":3109.23,"timestamp":"2024-05-18T15:46:25.980Z"},{"symbol":"ETHUSDT","id":32402397491,"side":"Buy","price":3107.56,"timestamp":"2024-05-18T15:46:25.980Z"},{"symbol":"ETHUSDT","id":32402521434,"side":"Buy","price":3109.24,"timestamp":"2024-05-18T15:46:25.980Z"}]}
{"table":"orderBookL2_25","action":"update","data":[{"symbol":"ETHUSDT","id":32402519694,"side":"Buy","size":161000,"price":3108.84,"timestamp":"2024-05-18T15:46:25.980Z"},{"symbol":"ETHUSDT","id":32402512820,"side":"Buy","size":241000,"price":3108.83,"timestamp":"2024-05-18T15:46:25.980Z"},{"symbol":"ETHUSDT","id":32402520681,"side":"Buy","size":101000,"price":3108.93,"timestamp":"2024-05-18T15:46:25.980Z"}]}
{"table":"orderBookL2_25","action":"insert","data":[{"symbol":"ETHUSDT","id":32393962149,"side":"Sell","size":1000,"price":3115.66,"timestamp":"2024-05-18T15:46:25.980Z"},{"symbol":"ETHUSDT","id":32402522125,"side":"Sell","size":100000,"price":3111.21,"timestamp":"2024-05-18T15:46:25.980Z"},{"symbol":"ETHUSDT","id":32402522047,"side":"Sell","size":32000,"price":3111.16,"timestamp":"2024-05-18T15:46:25.980Z"},{"symbol":"ETHUSDT","id":32402522225,"side":"Buy","size":32000,"price":3109.59,"timestamp":"2024-05-18T15:46:25.980Z"},{"symbol":"ETHUSDT","id":32402522127,"side":"Buy","size":1000,"price":3108.82,"timestamp":"2024-05-18T15:46:25.980Z"},{"symbol":"ETHUSDT","id":32402522088,"side":"Buy","size":32000,"price":3109.58,"timestamp":"2024-05-18T15:46:25.980Z"}]}
{"table":"orderBookL2_25","action":"delete","data":[{"symbol":"XBTUSDT","id":32402518035,"side":"Sell","price":66765.9,"timestamp":"2024-05-18T15:46:25.988Z"},{"symbol":"XBTUSDT","id":32402522052,"side":"Sell","price":66784.2,"timestamp":"2024-05-18T15:46:25.988Z"},{"symbol":"XBTUSDT","id":32402522036,"side":"Sell","price":66784.1,"timestamp":"2024-05-18T15:46:25.988Z"},{"symbol":"XBTUSDT","id":32402521038,"side":"Sell","price":66785.2,"timestamp":"2024-05-18T15:46:25.988Z"},{"symbol":"XBTUSDT","id":32402520916,"side":"Sell","price":66784.7,"timestamp":"2024-05-18T15:46:25.988Z"},{"symbol":"XBTUSDT","id":32402518388,"side":"Sell","price":66765.7,"timestamp":"2024-05-18T15:46:25.988Z"},{"symbol":"XBTUSDT","id":32402519393,"side":"Buy","price":66741.0,"timestamp":"2024-05-18T15:46:25.988Z"},{"symbol":"XBTUSDT","id":32402521658,"side":"Buy","price":66750.3,"timestamp":"2024-05-18T15:46:25.988Z"}]}
{"table":"orderBookL2_25","action":"update","data":[{"symbol":"XBTUSDT","id":32402506378,"side":"Sell","size":4000,"price":66764.5,"timestamp":"2024-05-18T15:46:25.988Z"},{"symbol":"XBTUSDT","id":32402505149,"side":"Buy","size":100000,"price":66730.4,"timestamp":"2024-05-18T15:46:25.988Z"}]}
{"table":"orderBookL2_25","action":"insert","data":[{"symbol":"XBTUSDT","id":32402522203,"side":"Sell","size":20000,"price":66783.8,"timestamp":"2024-05-18T15:46:25.988Z"},{"symbol":"XBTUSDT","id":32402471489,"side":"Sell","size":100000,"price":66808.7,"timestamp":"2024-05-18T15:46:25.988Z"},{"symbol":"XBTUSDT","id":32402522149,"side":"Sell","size":1000,"price":66785.3,"timestamp":"2024-05-18T15:46:25.988Z"},{"symbol":"XBTUSDT","id":32402520906,"side":"Sell","size":100000,"price":66812.1,"timestamp":"2024-05-18T15:46:25.988Z"},{"symbol":"XBTUSDT","id":32402522131,"side":"Sell","size":1000,"price":66786.1,"timestamp":"2024-05-18T15:46:25.988Z"},{"symbol":"XBTUSDT","id":32402522205,"side":"Sell","size":20000,"price":66783.7,"timestamp":"2024-05-18T15:46:25.988Z"},{"symbol":"XBTUSDT","id":32402522201,"side":"Buy","size":20000,"price":66755.8,"timestamp":"2024-05-18T15:46:25.988Z"},{"symbol":"XBTUSDT","id":32402522190,"side":"Buy","size":3000,"price":66752.8,"timestamp":"2024-05-18T15:46:25.988Z"}]}
{"table":"orderBookL2_25","action":"delete","data":[{"symbol":"ETHUSDT","id":32402500495,"side":"Sell","price":3115.00,"timestamp":"2024-05-18T15:46:26.029Z"},{"symbol":"ETHUSDT","id":32402515605,"side":"Sell","price":3112.01,"timestamp":"2024-05-18T15:46:26.029Z"},{"symbol":"ETHUSDT","id":32398201667,"side":"Sell","price":3115.60,"timestamp":"2024-05-18T15:46:26.029Z"},{"symbol":"ETHUSDT","id":32402521993,"side":"Sell","price":3111.15,"timestamp":"2024-05-18T15:46:26.029Z"},{"symbol":"ETHUSDT","id":32393962149,"side":"Sell","price":3115.66,"timestamp":"2024-05-18T15:46:26.029Z"},{"symbol":"ETHUSDT","id":32402520990,"side":"Sell","price":3110.36,"timestamp":"2024-05-18T15:46:26.029Z"},{"symbol":"ETHUSDT","id":32402522127,"side":"Buy","price":3108.82,"timestamp":"2024-05-18T15:46:26.029Z"},{"symbol":"ETHUSDT","id":32402520621,"side":"Buy","price":3108.01,"timestamp":"2024-05-18T15:46:26.029Z"},{"symbol":"ETHUSDT","id":32402522225,"side":"Buy","price":3109.59,"timestamp":"2024-05-18T15:46:26.029Z"},{"symbol":"ETHUSDT","id":32402522088,"side":"Buy","price":3109.58,"timestamp":"2024-05-18T15:46:26.029Z"},{"symbol":"ETHUSDT","id":32402511235,"side":"Buy","price":3108.13,"timestamp":"2024-05-18T15:46:26.029Z"},{"symbol":"ETHUSDT","id":32402517862,"side":"Buy","price":3108.46,"timestamp":"2024-05-18T15:46:26.029Z"}]}
{"table":"orderBookL2_25","action":"update","data":[{"symbol":"ETHUSDT","id":32402520681,"side":"Buy","size":100000,"price":3108.93,"timestamp":"2024-05-18T15:46:26.029Z"},{"symbol":"ETHUSDT","id":32402505580,"side":"Buy","size":1157000,"price":3108.12,"timestamp":"2024-05-18T15:46:26.029Z"},{"symbol":"ETHUSDT","id":32402517388,"side":"Buy","size":100000,"price":3108.45,"timestamp":"2024-05-18T15:46:26.029Z"}]}
{"table":"orderBookL2_25","action":"insert","data":[{"symbol":"ETHUSDT","id":32402522496,"side":"Sell","size":100000,"price":3110.86,"timestamp":"2024-05-18T15:46:26.029Z"},{"symbol":"ETHUSDT","id":32402522434,"side":"Sell","size":651000,"price":3112.67,"timestamp":"2024-05-18T15:46:26.029Z"},{"symbol":"ETHUSDT","id":32402522374,"side":"Sell","size":28000,"price":3110.72,"timestamp":"2024-05-18T15:46:26.029Z"},{"symbol":"ETHUSDT","id":32402522236,"side":"Sell","size":905000,"price":3110.81,"timestamp":"2024-05-18T15:46:26.029Z"},{"symbol":"ETHUSDT","id":32402522500,"side":"Sell","size":32000,"price":3111.17,"timestamp":"2024-05-18T15:46:26.029Z"},{"symbol":"ETHUSDT","id":32402522498,"side":"Sell","size":100000,"price":3110.66,"timestamp":"2024-05-18T15:46:26.029Z"},{"symbol":"ETHUSDT","id":32402522474,"side":"Buy","size":1000,"price":3109.43,"timestamp":"2024-05-18T15:46:26.029Z"},{"symbol":"ETHUSDT","id":32402522241,"side":"Buy","size":2300000,"price":3108.15,"timestamp":"2024-05-18T15:46:26.029Z"},{"symbol":"ETHUSDT","id":32402522476,"side":"Buy","size":32000,"price":3109.68,"timestamp":"2024-05-18T15:46:26.029Z"},{"symbol":"ETHUSDT","id":32402522470,"side":"Buy","size":32000,"price":3109.69,"timestamp":"2024-05-18T15:46:26.029Z"},{"symbol":"ETHUSDT","id":32402522480,"side":"Buy","size":1000,"price":3109.44,"timestamp":"2024-05-18T15:46:26.029Z"},{"symbol":"ETHUSDT","id":32402522239,"side":"Buy","size":311000,"price":3109.20,"timestamp":"2024-05-18T15:46:26.029Z"}]}
{"table":"orderBookL2_25","action":"delete","data":[{"symbol":"XBTUSDT","id":32402506723,"side":"Sell","price":66783.4,"timestamp":"2024-05-18T15:46:26.037Z"},{"symbol":"XBTUSDT","id":32402522205,"side":"Sell","price":66783.7,"timestamp":"2024-05-18T15:46:26.037Z"},{"symbol":"XBTUSDT","id":32402522203,"side":"Sell","price":66783.8,"timestamp":"2024-05-18T15:46:26.037Z"},{"symbol":"XBTUSDT","id":32402522131,"side":"Sell","price":66786.1,"timestamp":"2024-05-18T15:46:26.037Z"},{"symbol":"XBTUSDT","id":32402516811,"side":"Sell","price":66808.4,"timestamp":"2024-05-18T15:46:26.037Z"},{"symbol":"XBTUSDT","id":32402521927,"side":"Sell","price":66778.8,"timestamp":"2024-05-18T15:46:26.037Z"},{"symbol":"XBTUSDT","id":32402506378,"side":"Sell","price":66764.5,"timestamp":"2024-05-18T15:46:26.037Z"},{"symbol":"XBTUSDT","id":32402522149,"side":"Sell","price":66785.3,"timestamp":"2024-05-18T15:46:26.037Z"},{"symbol":"XBTUSDT","id":32402521696,"side":"Sell","price":66786.3,"timestamp":"2024-05-18T15:46:26.037Z"},{"symbol":"XBTUSDT","id":32402521388,"side":"Buy","price":66750.2,"timestamp":"2024-05-18T15:46:26.037Z"},{"symbol":"XBTUSDT","id":32402521686,"side":"Buy","price":66748.5,"timestamp":"2024-05-18T15:46:26.037Z"},{"symbol":"XBTUSDT","id":32402522045,"side":"Buy","price":66749.5,"timestamp":"2024-05-18T15:46:26.037Z"}]}
{"table":"orderBookL2_25","action":"update","data":[{"symbol":"XBTUSDT","id":32402511708,"side":"Sell","size":102000,"price":66783.3,"timestamp":"2024-05-18T15:46:26.037Z"}]}
{"table":"orderBookL2_25","action":"insert","data":[{"symbol":"XBTUSDT","id":32402522382,"side":"Sell","size":8000,"price":66783.2,"timestamp":"2024-05-18T15:46:26.037Z"},{"symbol":"XBTUSDT","id":32402522450,"side":"Sell","size":159000,"price":66797.2,"timestamp":"2024-05-18T15:46:26.037Z"},{"symbol":"XBTUSDT","id":32402522530,"side":"Sell","size":20000,"price":66785.1,"timestamp":"2024-05-18T15:46:26.037Z"},{"symbol":"XBTUSDT","id":32402522502,"side":"Sell","size":20000,"price":66785.2,"timestamp":"2024-05-18T15:46:26.037Z"},{"symbol":"XBTUSDT","id":32402522541,"side":"Sell","size":22000,"price":66789.6,"timestamp":"2024-05-18T15:46:26.037Z"},{"symbol":"XBTUSDT","id":32402522472,"side":"Sell","size":1000,"price":66792.3,"timestamp":"2024-05-18T15:46:26.037Z"},{"symbol":"XBTUSDT","id":32402522549,"side":"Sell","size":361000,"price":66787.8,"timestamp":"2024-05-18T15:46:26.037Z"},{"symbol":"XBTUSDT","id":32402522478,"side":"Sell","size":1000,"price":66792.4,"timestamp":"2024-05-18T15:46:26.037Z"},{"symbol":"XBTUSDT","id":32402522515,"side":"Sell","size":8000,"price":66778.4,"timestamp":"2024-05-18T15:46:26.037Z"},{"symbol":"XBTUSDT","id":32402522463,"side":"Buy","size":38000,"price":66748.0,"timestamp":"2024-05-18T15:46:26.037Z"},{"symbol":"XBTUSDT","id":32402522297,"side":"Buy","size":20000,"price":66755.7,"timestamp":"2024-05-18T15:46:26.037Z"},{"symbol":"XBTUSDT","id":32402522365,"side":"Buy","size":39000,"price":66774.6,"timestamp":"2024-05-18T15:46:26.037Z"}]}
{"table":"orderBookL2_25","action":"delete","data":[{"symbol":"ETHUSDT","id":32402522047,"side":"Sell","price":3111.16,"timestamp":"2024-05-18T15:46:26.078Z"},{"symbol":"ETHUSDT","id":32402522500,"side":"Sell","price":3111.17,"timestamp":"2024-05-18T15:46:26.078Z"},{"symbol":"ETHUSDT","id":32402522374,"side":"Sell","price":3110.72,"timestamp":"2024-05-18T15:46:26.078Z"},{"symbol":"ETHUSDT","id":32402522474,"side":"Buy","price":3109.43,"timestamp":"2024-05-18T15:46:26.078Z"},{"symbol":"ETHUSDT","id":32402522480,"side":"Buy","price":3109.44,"timestamp":"2024-05-18T15:46:26.078Z"},{"symbol":"ETHUSDT","id":32402505580,"side":"Buy","price":3108.12,"timestamp":"2024-05-18T15:46:26.078Z"}]}
{"table":"orderBookL2_25","action":"update","data":[{"symbol":"ETHUSDT","id":32402358267,"side":"Sell","size":100000,"price":3114.29,"timestamp":"2024-05-18T15:46:26.078Z"},{"symbol":"ETHUSDT","id":32402450797,"side":"Sell","size":100000,"price":3114.61,"timestamp":"2024-05-18T15:46:26.078Z"},{"symbol":"ETHUSDT","id":32402521474,"side":"Buy","size":106000,"price":3109.42,"timestamp":"2024-05-18T15:46:26.078Z"},{"symbol":"ETHUSDT","id":32402517483,"side":"Buy","size":144000,"price":3109.41,"timestamp":"2024-05-18T15:46:26.078Z"}]}
{"table":"orderBookL2_25","action":"insert","data":[{"symbol":"ETHUSDT","id":32402500495,"side":"Sell","size":17234000,"price":3115.00,"timestamp":"2024-05-18T15:46:26.078Z"},{"symbol":"ETHUSDT","id":32402522722,"side":"Sell","size":32000,"price":3111.19,"timestamp":"2024-05-18T15:46:26.078Z"},{"symbol":"ETHUSDT","id":32402522826,"side":"Sell","size":32000,"price":3111.18,"timestamp":"2024-05-18T15:46:26.078Z"},{"symbol":"ETHUSDT","id":32402397491,"side":"Buy","size":100000,"price":3107.56,"timestamp":"2024-05-18T15:46:26.078Z"},{"symbol":"ETHUSDT","id":32402520621,"side":"Buy","size":100000,"price":3108.01,"timestamp":"2024-05-18T15:46:26.078Z"},{"symbol":"ETHUSDT","id":32402522745,"side":"Buy","size":1157000,"price":3109.25,"timestamp":"2024-05-18T15:46:26.078Z"}]}
{"table":"orderBookL2_25","action":"delete","data":[{"symbol":"XBTUSDT","id":32402522502,"side":"Sell","price":66785.2,"timestamp":"2024-05-18T15:46:26.086Z"},{"symbol":"XBTUSDT","id":32402522541,"side":"Sell","price":66789.6,"timestamp":"2024-05-18T15:46:26.086Z"},{"symbol":"XBTUSDT","id":32402521469,"side":"Sell","price":66792.2,"timestamp":"2024-05-18T15:46:26.086Z"},{"symbol":"XBTUSDT","id":32402522478,"side":"Sell","price":66792.4,"timestamp":"2024-05-18T15:46:26.086Z"},{"symbol":"XBTUSDT","id":32402511708,"side":"Sell","price":66783.3,"timestamp":"2024-05-18T15:46:26.086Z"},{"symbol":"XBTUSDT","id":32402520966,"side":"Sell","price":66774.7,"timestamp":"2024-05-18T15:46:26.086Z"},{"symbol":"XBTUSDT","id":32402522472,"side":"Sell","price":66792.3,"timestamp":"2024-05-18T15:46:26.086Z"},{"symbol":"XBTUSDT","id":32402462262,"side":"Buy","price":66733.8,"timestamp":"2024-05-18T15:46:26.086Z"},{"symbol":"XBTUSDT","id":32402522058,"side":"Buy","price":66750.9,"timestamp":"2024-05-18T15:46:26.086Z"},{"symbol":"XBTUSDT","id":32402509182,"side":"Buy","price":66753.8,"timestamp":"2024-05-18T15:46:26.086Z"},{"symbol":"XBTUSDT","id":32402505149,"side":"Buy","price":66730.4,"timestamp":"2024-05-18T15:46:26.086Z"},{"symbol":"XBTUSDT","id":32402522297,"side":"Buy","price":66755.7,"timestamp":"2024-05-18T15:46:26.086Z"},{"symbol":"XBTUSDT","id":32402522190,"side":"Buy","price":66752.8,"timestamp":"2024-05-18T15:46:26.086Z"},{"symbol":"XBTUSDT","id":32402522201,"side":"Buy","price":66755.8,"timestamp":"2024-05-18T15:46:26.086Z"},{"symbol":"XBTUSDT","id":32402505951,"side":"Buy","price":66736.2,"timestamp":"2024-05-18T15:46:26.086Z"},{"symbol":"XBTUSDT","id":32402522463,"side":"Buy","price":66748.0,"timestamp":"2024-05-18T15:46:26.086Z"}]}
{"table":"orderBookL2_25","action":"update","data":[{"symbol":"XBTUSDT","id":32402505821,"side":"Buy","size":161000,"price":66764.4,"timestamp":"2024-05-18T15:46:26.086Z"},{"symbol":"XBTUSDT","id":32402522365,"side":"Buy","size":148000,"price":66774.6,"timestamp":"2024-05-18T15:46:26.086Z"},{"symbol":"XBTUSDT","id":32402517532,"side":"Buy","size":100000,"price":66757.6,"timestamp":"2024-05-18T15:46:26.086Z"},{"symbol":"XBTUSDT","id":32402520016,"side":"Buy","size":16000,"price":66762.1,"timestamp":"2024-05-18T15:46:26.086Z"}]}
{"table":"orderBookL2_25","action":"insert","data":[{"symbol":"XBTUSDT","id":32402520719,"side":"Sell","size":1363000,"price":66815.6,"timestamp":"2024-05-18T15:46:26.086Z"},{"symbol":"XBTUSDT","id":32402522790,"side":"Sell","size":650000,"price":66815.5,"timestamp":"2024-05-18T15:46:26.086Z"},{"symbol":"XBTUSDT","id":32402522857,"side":"Sell","size":543000,"price":66800.3,"timestamp":"2024-05-18T15:46:26.086Z"},{"symbol":"XBTUSDT","id":32402522865,"side":"Sell","size":1000,"price":66792.8,"timestamp":"2024-05-18T15:46:26.086Z"},{"symbol":"XBTUSDT","id":32402522775,"side":"Sell","size":20000,"price":66785.2,"timestamp":"2024-05-18T15:46:26.086Z"},{"symbol":"XBTUSDT","id":32402461579,"side":"Sell","size":100000,"price":66815.7,"timestamp":"2024-05-18T15:46:26.086Z"},{"symbol":"XBTUSDT","id":32402522893,"side":"Sell","size":1000,"price":66792.7,"timestamp":"2024-05-18T15:46:26.086Z"},{"symbol":"XBTUSDT","id":32402522780,"side":"Buy","size":20000,"price":66758.0,"timestamp":"2024-05-18T15:46:26.086Z"},{"symbol":"XBTUSDT","id":32402522898,"side":"Buy","size":373000,"price":66747.6,"timestamp":"2024-05-18T15:46:26.086Z"},{"symbol":"XBTUSDT","id":32402522805,"side":"Buy","size":100000,"price":66775.7,"timestamp":"2024-05-18T15:46:26.086Z"},{"symbol":"XBTUSDT","id":32402522792,"side":"Buy","size":100000,"price":66767.8,"timestamp":"2024-05-18T15:46:26.086Z"},{"symbol":"XBTUSDT","id":32402522611,"side":"Buy","size":50000,"price":66764.5,"timestamp":"2024-05-18T15:46:26.086Z"},{"symbol":"XBTUSDT","id":32402522785,"side":"Buy","size":26000,"price":66778.3,"timestamp":"2024-05-18T15:46:26.086Z"},{"symbol":"XBTUSDT","id":32402522829,"side":"Buy","size":20000,"price":66770.9,"timestamp":"2024-05-18T15:46:26.086Z"},{"symbol":"XBTUSDT","id":32402522817,"side":"Buy","size":100000,"price":66761.0,"timestamp":"2024-05-18T15:46:26.086Z"},{"symbol":"XBTUSDT","id":32402522794,"side":"Buy","size":20000,"price":66757.9,"timestamp":"2024-05-18T15:46:26.086Z"}]}
{"table":"orderBookL2_25","action":"delete","data":[{"symbol":"ETHUSDT","id":32402450797,"side":"Sell","price":3114.61,"timestamp":"2024-05-18T15:46:26.127Z"},{"symbol":"ETHUSDT","id":32402500495,"side":"Sell","price":3115.00,"timestamp":"2024-05-18T15:46:26.127Z"},{"symbol":"ETHUSDT","id":32402522470,"side":"Buy","price":3109.69,"timestamp":"2024-05-18T15:46:26.127Z"},{"symbol":"ETHUSDT","id":32402522476,"side":"Buy","price":3109.68,"timestamp":"2024-05-18T15:46:26.127Z"}]}
{"table":"orderBookL2_25","action":"update","data":[{"symbol":"ETHUSDT","id":32402521474,"side":"Buy","size":101000,"price":3109.42,"timestamp":"2024-05-18T15:46:26.127Z"},{"symbol":"ETHUSDT","id":32402517483,"side":"Buy","size":144000,"price":3109.41,"timestamp":"2024-05-18T15:46:26.127Z"},{"symbol":"ETHUSDT","id":32402397491,"side":"Buy","size":100000,"price":3107.56,"timestamp":"2024-05-18T15:46:26.127Z"}]}
{"table":"orderBookL2_25","action":"insert","data":[{"symbol":"ETHUSDT","id":32402522885,"side":"Sell","size":28000,"price":3111.02,"timestamp":"2024-05-18T15:46:26.127Z"},{"symbol":"ETHUSDT","id":32402522941,"side":"Sell","size":21000,"price":3110.65,"timestamp":"2024-05-18T15:46:26.127Z"},{"symbol":"ETHUSDT","id":32402522934,"side":"Buy","size":32000,"price":3109.66,"timestamp":"2024-05-18T15:46:26.127Z"},{"symbol":"ETHUSDT","id":32402522949,"side":"Buy","size":32000,"price":3109.67,"timestamp":"2024-05-18T15:46:26.127Z"}]}
{"table":"orderBookL2_25","action":"delete","data":[{"symbol":"XBTUSDT","id":32402520719,"side":"Sell","price":66815.6,"timestamp":"2024-05-18T15:46:26.135Z"},{"symbol":"XBTUSDT","id":32402522530,"side":"Sell","price":66785.1,"timestamp":"2024-05-18T15:46:26.135Z"},{"symbol":"XBTUSDT","id":32402522865,"side":"Sell","price":66792.8,"timestamp":"2024-05-18T15:46:26.135Z"},{"symbol":"XBTUSDT","id":32402522775,"side":"Sell","price":66785.2,"timestamp":"2024-05-18T15:46:26.135Z"},{"symbol":"XBTUSDT","id":32402461579,"side":"Sell","price":66815.7,"timestamp":"2024-05-18T15:46:26.135Z"},{"symbol":"XBTUSDT","id":32402522794,"side":"Buy","price":66757.9,"timestamp":"2024-05-18T15:46:26.135Z"},{"symbol":"XBTUSDT","id":32402513876,"side":"Buy","price":66737.2,"timestamp":"2024-05-18T15:46:26.135Z"},{"symbol":"XBTUSDT","id":32402522365,"side":"Buy","price":66774.6,"timestamp":"2024-05-18T15:46:26.135Z"},{"symbol":"XBTUSDT","id":32402522780,"side":"Buy","price":66758.0,"timestamp":"2024-05-18T15:46:26.135Z"}]}
{"table":"orderBookL2_25","action":"update","data":[{"symbol":"XBTUSDT","id":32402522515,"side":"Sell","size":108000,"price":66778.4,"timestamp":"2024-05-18T15:46:26.135Z"},{"symbol":"XBTUSDT","id":32402505821,"side":"Buy","size":121000,"price":66764.4,"timestamp":"2024-05-18T15:46:26.135Z"},{"symbol":"XBTUSDT","id":32402514918,"side":"Buy","size":388000,"price":66737.4,"timestamp":"2024-05-18T15:46:26.135Z"}]}
{"table":"orderBookL2_25","action":"insert","data":[{"symbol":"XBTUSDT","id":32402522977,"side":"Sell","size":20000,"price":66785.3,"timestamp":"2024-05-18T15:46:26.135Z"},{"symbol":"XBTUSDT","id":32402522947,"side":"Sell","size":20000,"price":66784.4,"timestamp":"2024-05-18T15:46:26.135Z"},{"symbol":"XBTUSDT","id":32402522913,"side":"Sell","size":1000,"price":66792.6,"timestamp":"2024-05-18T15:46:26.135Z"},{"symbol":"XBTUSDT","id":32402522925,"side":"Sell","size":2000,"price":66802.0,"timestamp":"2024-05-18T15:46:26.135Z"},{"symbol":"XBTUSDT","id":32402522994,"side":"Sell","size":20000,"price":66785.4,"timestamp":"2024-05-18T15:46:26.135Z"},{"symbol":"XBTUSDT","id":32402522965,"side":"Buy","size":2000,"price":66758.4,"timestamp":"2024-05-18T15:46:26.135Z"},{"symbol":"XBTUSDT","id":32402522956,"side":"Buy","size":36000,"price":66767.6,"timestamp":"2024-05-18T15:46:26.135Z"},{"symbol":"XBTUSDT","id":32402522979,"side":"Buy","size":20000,"price":66757.8,"timestamp":"2024-05-18T15:46:26.135Z"},{"symbol":"XBTUSDT","id":32402522975,"side":"Buy","size":20000,"price":66757.7,"timestamp":"2024-05-18T15:46:26.135Z"}]}
{"table":"orderBookL2_25","action":"delete","data":[{"symbol":"ETHUSDT","id":32402441505,"side":"Sell","price":3113.30,"timestamp":"2024-05-18T15:46:26.176Z"},{"symbol":"ETHUSDT","id":32402358267,"side":"Sell","price":3114.29,"timestamp":"2024-05-18T15:46:26.176Z"},{"symbol":"ETHUSDT","id":32402397491,"side":"Buy","price":3107.56,"timestamp":"2024-05-18T15:46:26.176Z"}]}
{"table":"orderBookL2_25","action":"update","data":[{"symbol":"ETHUSDT","id":32402517483,"side":"Buy","size":191000,"price":3109.41,"timestamp":"2024-05-18T15:46:26.176Z"},{"symbol":"ETHUSDT","id":32402521474,"side":"Buy","size":101000,"price":3109.42,"timestamp":"2024-05-18T15:46:26.176Z"}]}
{"table":"orderBookL2_25","action":"insert","data":[{"symbol":"ETHUSDT","id":32402523129,"side":"Sell","size":48000,"price":3111.75,"timestamp":"2024-05-18T15:46:26.176Z"},{"symbol":"ETHUSDT","id":32402523121,"side":"Sell","size":24000,"price":3111.23,"timestamp":"2024-05-18T15:46:26.176Z"},{"symbol":"ETHUSDT","id":32402523026,"side":"Buy","size":1000,"price":3109.43,"timestamp":"2024-05-18T15:46:26.176Z"}]}
{"table":"orderBookL2_25","action":"delete","data":[{"symbol":"XBTUSDT","id":32402519930,"side":"Sell","price":66788.9,"timestamp":"2024-05-18T15:46:26.184Z"},{"symbol":"XBTUSDT","id":32402522790,"side":"Sell","price":66815.5,"timestamp":"2024-05-18T15:46:26.184Z"},{"symbol":"XBTUSDT","id":32402520906,"side":"Sell","price":66812.1,"timestamp":"2024-05-18T15:46:26.184Z"}]}
{"table":"orderBookL2_25","action":"update","data":[{"symbol":"XBTUSDT","id":32402505821,"side":"Buy","size":131000,"price":66764.4,"timestamp":"2024-05-18T15:46:26.184Z"},{"symbol":"XBTUSDT","id":32402522611,"side":"Buy","size":40000,"price":66764.5,"timestamp":"2024-05-18T15:46:26.184Z"}]}
{"table":"orderBookL2_25","action":"insert","data":[{"symbol":"XBTUSDT","id":32402523116,"side":"Sell","size":74000,"price":66790.4,"timestamp":"2024-05-18T15:46:26.184Z"},{"symbol":"XBTUSDT","id":32402523103,"side":"Sell","size":3000,"price":66796.1,"timestamp":"2024-05-18T15:46:26.184Z"},{"symbol":"XBTUSDT","id":32402523148,"side":"Sell","size":11000,"price":66780.5,"timestamp":"2024-05-18T15:46:26.184Z"}]}
{"table":"orderBookL2_25","action":"delete","data":[{"symbol":"ETHUSDT","id":32402523129,"side":"Sell","price":3111.75,"timestamp":"2024-05-18T15:46:26.225Z"},{"symbol":"ETHUSDT","id":32402523121,"side":"Sell","price":3111.23,"timestamp":"2024-05-18T15:46:26.225Z"}]}
{"table":"orderBookL2_25","action":"update","data":[{"symbol":"ETHUSDT","id":32402517483,"side":"Buy","size":216000,"price":3109.41,"timestamp":"2024-05-18T15:46:26.225Z"}]}
{"table":"orderBookL2_25","action":"insert","data":[{"symbol":"ETHUSDT","id":32402441505,"side":"Sell","size":101000,"price":3113.30,"timestamp":"2024-05-18T15:46:26.225Z"},{"symbol":"ETHUSDT","id":32402358267,"side":"Sell","size":100000,"price":3114.29,"timestamp":"2024-05-18T15:46:26.225Z"}]}
{"table":"orderBookL2_25","action":"delete","data":[{"symbol":"XBTUSDT","id":32402522947,"side":"Sell","price":66784.4,"timestamp":"2024-05-18T15:46:26.233Z"},{"symbol":"XBTUSDT","id":32402520519,"side":"Sell","price":66787.9,"timestamp":"2024-05-18T15:46:26.233Z"}]}
{"table":"orderBookL2_25","action":"insert","data":[{"symbol":"XBTUSDT","id":32402520906,"side":"Sell","size":100000,"price":66812.1,"timestamp":"2024-05-18T15:46:26.233Z"},{"symbol":"XBTUSDT","id":32402523170,"side":"Sell","size":3000,"price":66790.7,"timestamp":"2024-05-18T15:46:26.233Z"}]}
{"table":"orderBookL2_25","action":"delete","data":[{"symbol":"XBTUSDT","id":32402505006,"side":"Sell","price":66778.5,"timestamp":"2024-05-18T15:46:26.282Z"},{"symbol":"XBTUSDT","id":32402471489,"side":"Sell","price":66808.7,"timestamp":"2024-05-18T15:46:26.282Z"},{"symbol":"XBTUSDT","id":32402507156,"side":"Buy","price":66747.4,"timestamp":"2024-05-18T15:46:26.282Z"},{"symbol":"XBTUSDT","id":32402522898,"side":"Buy","price":66747.6,"timestamp":"2024-05-18T15:46:26.282Z"},{"symbol":"XBTUSDT","id":32402522805,"side":"Buy","price":66775.7,"timestamp":"2024-05-18T15:46:26.282Z"}]}
{"table":"orderBookL2_25","action":"update","data":[{"symbol":"XBTUSDT","id":32402522785,"side":"Buy","size":126000,"price":66778.3,"timestamp":"2024-05-18T15:46:26.282Z"}]}
{"table":"orderBookL2_25","action":"insert","data":[{"symbol":"XBTUSDT","id":32402523220,"side":"Sell","size":156000,"price":66783.1,"timestamp":"2024-05-18T15:46:26.282Z"},{"symbol":"XBTUSDT","id":32402520719,"side":"Sell","size":1365000,"price":66815.6,"timestamp":"2024-05-18T15:46:26.282Z"},{"symbol":"XBTUSDT","id":32402505951,"side":"Buy","size":22000,"price":66736.2,"timestamp":"2024-05-18T15:46:26.282Z"},{"symbol":"XBTUSDT","id":32402523291,"side":"Buy","size":351000,"price":66750.9,"timestamp":"2024-05-18T15:46:26.282Z"},{"symbol":"XBTUSDT","id":32402513876,"side":"Buy","size":638000,"price":66737.2,"timestamp":"2024-05-18T15:46:26.282Z"}]}
{"table":"orderBookL2_25","action":"delete","data":[{"symbol":"ETHUSDT","id":32402523026,"side":"Buy","price":3109.43,"timestamp":"2024-05-18T15:46:26.288Z"}]}
{"table":"orderBookL2_25","action":"update","data":[{"symbol":"ETHUSDT","id":32402517483,"side":"Buy","size":217000,"price":3109.41,"timestamp":"2024-05-18T15:46:26.288Z"}]}
{"table":"orderBookL2_25","action":"insert","data":[{"symbol":"ETHUSDT","id":32402397491,"side":"Buy","size":100000,"price":3107.56,"timestamp":"2024-05-18T15:46:26.288Z"}]}
{"table":"orderBookL2_25","action":"delete","data":[{"symbol":"XBTUSDT","id":32402520719,"side":"Sell","price":66815.6,"timestamp":"2024-05-18T15:46:26.331Z"},{"symbol":"XBTUSDT","id":32402522977,"side":"Sell","price":66785.3,"timestamp":"2024-05-18T15:46:26.331Z"},{"symbol":"XBTUSDT","id":32402522913,"side":"Sell","price":66792.6,"timestamp":"2024-05-18T15:46:26.331Z"},{"symbol":"XBTUSDT","id":32402522994,"side":"Sell","price":66785.4,"timestamp":"2024-05-18T15:46:26.331Z"},{"symbol":"XBTUSDT","id":32402522893,"side":"Sell","price":66792.7,"timestamp":"2024-05-18T15:46:26.331Z"},{"symbol":"XBTUSDT","id":32402505951,"side":"Buy","price":66736.2,"timestamp":"2024-05-18T15:46:26.331Z"},{"symbol":"XBTUSDT","id":32402522979,"side":"Buy","price":66757.8,"timestamp":"2024-05-18T15:46:26.331Z"},{"symbol":"XBTUSDT","id":32402522975,"side":"Buy","price":66757.7,"timestamp":"2024-05-18T15:46:26.331Z"},{"symbol":"XBTUSDT","id":32402520016,"side":"Buy","price":66762.1,"timestamp":"2024-05-18T15:46:26.331Z"}]}
{"table":"orderBookL2_25","action":"update","data":[{"symbol":"XBTUSDT","id":32402522515,"side":"Sell","size":208000,"price":66778.4,"timestamp":"2024-05-18T15:46:26.331Z"},{"symbol":"XBTUSDT","id":32402522785,"side":"Buy","size":34000,"price":66778.3,"timestamp":"2024-05-18T15:46:26.331Z"},{"symbol":"XBTUSDT","id":32402513876,"side":"Buy","size":638000,"price":66737.2,"timestamp":"2024-05-18T15:46:26.331Z"}]}
{"table":"orderBookL2_25","action":"insert","data":[{"symbol":"XBTUSDT","id":32402523327,"side":"Sell","size":20000,"price":66785.6,"timestamp":"2024-05-18T15:46:26.331Z"},{"symbol":"XBTUSDT","id":32402523384,"side":"Sell","size":20000,"price":66784.5,"timestamp":"2024-05-18T15:46:26.331Z"},{"symbol":"XBTUSDT","id":32402523308,"side":"Sell","size":1000,"price":66792.8,"timestamp":"2024-05-18T15:46:26.331Z"},{"symbol":"XBTUSDT","id":32402523321,"side":"Sell","size":20000,"price":66785.5,"timestamp":"2024-05-18T15:46:26.331Z"},{"symbol":"XBTUSDT","id":32402523331,"side":"Sell","size":1000,"price":66792.9,"timestamp":"2024-05-18T15:46:26.331Z"},{"symbol":"XBTUSDT","id":32402523334,"side":"Buy","size":20000,"price":66758.0,"timestamp":"2024-05-18T15:46:26.331Z"},{"symbol":"XBTUSDT","id":32402523325,"side":"Buy","size":100000,"price":66771.5,"timestamp":"2024-05-18T15:46:26.331Z"},{"symbol":"XBTUSDT","id":32402523317,"side":"Buy","size":8000,"price":66771.0,"timestamp":"2024-05-18T15:46:26.331Z"},{"symbol":"XBTUSDT","id":32402523344,"side":"Buy","size":20000,"price":66757.9,"timestamp":"2024-05-18T15:46:26.331Z"}]}
{"table":"orderBookL2_25","action":"delete","data":[{"symbol":"ETHUSDT","id":32402522496,"side":"Sell","price":3110.86,"timestamp":"2024-05-18T15:46:26.337Z"},{"symbol":"ETHUSDT","id":32402522722,"side":"Sell","price":3111.19,"timestamp":"2024-05-18T15:46:26.337Z"},{"symbol":"ETHUSDT","id":32402522885,"side":"Sell","price":3111.02,"timestamp":"2024-05-18T15:46:26.337Z"},{"symbol":"ETHUSDT","id":32402522941,"side":"Sell","price":3110.65,"timestamp":"2024-05-18T15:46:26.337Z"},{"symbol":"ETHUSDT","id":32402522826,"side":"Sell","price":3111.18,"timestamp":"2024-05-18T15:46:26.337Z"},{"symbol":"ETHUSDT","id":32402397491,"side":"Buy","price":3107.56,"timestamp":"2024-05-18T15:46:26.337Z"},{"symbol":"ETHUSDT","id":32402522949,"side":"Buy","price":3109.67,"timestamp":"2024-05-18T15:46:26.337Z"}]}
{"table":"orderBookL2_25","action":"update","data":[{"symbol":"ETHUSDT","id":32402522125,"side":"Sell","size":132000,"price":3111.21,"timestamp":"2024-05-18T15:46:26.337Z"}]}
{"table":"orderBookL2_25","action":"insert","data":[{"symbol":"ETHUSDT","id":32402523400,"side":"Sell","size":32000,"price":3111.22,"timestamp":"2024-05-18T15:46:26.337Z"},{"symbol":"ETHUSDT","id":32398201667,"side":"Sell","size":100000,"price":3115.60,"timestamp":"2024-05-18T15:46:26.337Z"},{"symbol":"ETHUSDT","id":32402500495,"side":"Sell","size":17234000,"price":3115.00,"timestamp":"2024-05-18T15:46:26.337Z"},{"symbol":"ETHUSDT","id":32402523408,"side":"Sell","size":100000,"price":3110.49,"timestamp":"2024-05-18T15:46:26.337Z"},{"symbol":"ETHUSDT","id":32402450797,"side":"Sell","size":100000,"price":3114.61,"timestamp":"2024-05-18T15:46:26.337Z"},{"symbol":"ETHUSDT","id":32402523391,"side":"Buy","size":32000,"price":3109.65,"timestamp":"2024-05-18T15:46:26.337Z"},{"symbol":"ETHUSDT","id":32402523355,"side":"Buy","size":1126000,"price":3107.65,"timestamp":"2024-05-18T15:46:26.337Z"}]}
{"table":"orderBookL2_25","action":"delete","data":[{"symbol":"XBTUSDT","id":32402523384,"side":"Sell","price":66784.5,"timestamp":"2024-05-18T15:46:26.380Z"}]}
{"table":"orderBookL2_25","action":"insert","data":[{"symbol":"XBTUSDT","id":32402520719,"side":"Sell","size":1365000,"price":66815.6,"timestamp":"2024-05-18T15:46:26.380Z"}]}
{"table":"orderBookL2_25","action":"delete","data":[{"symbol":"ETHUSDT","id":32402522498,"side":"Sell","price":3110.66,"timestamp":"2024-05-18T15:46:26.386Z"}]}
{"table":"orderBookL2_25","action":"insert","data":[{"symbol":"ETHUSDT","id":32393962149,"side":"Sell","size":1000,"price":3115.66,"timestamp":"2024-05-18T15:46:26.386Z"}]}
{"table":"orderBookL2_25","action":"delete","data":[{"symbol":"XBTUSDT","id":32402520719,"side":"Sell","price":66815.6,"timestamp":"2024-05-18T15:46:26.433Z"}]}
{"table":"orderBookL2_25","action":"insert","data":[{"symbol":"XBTUSDT","id":32402523596,"side":"Sell","size":20000,"price":66785.9,"timestamp":"2024-05-18T15:46:26.433Z"}]}
{"table":"orderBookL2_25","action":"delete","data":[{"symbol":"ETHUSDT","id":32393962149,"side":"Sell","price":3115.66,"timestamp":"2024-05-18T15:46:26.435Z"}]}
{"table":"orderBookL2_25","action":"insert","data":[{"symbol":"ETHUSDT","id":32402523523,"side":"Sell","size":28000,"price":3110.85,"timestamp":"2024-05-18T15:46:26.435Z"}]}
{"table":"orderBookL2_25","action":"update","data":[{"symbol":"XBTUSDT","id":32402505821,"side":"Buy","size":129000,"price":66764.4,"timestamp":"2024-05-18T15:46:26.502Z"}]}
{"table":"orderBookL2_25","action":"update","data":[{"symbol":"XBTUSDT","id":32402520105,"side":"Buy","size":8000,"price":66762.2,"timestamp":"2024-05-18T15:46:26.558Z"}]}
{"table":"orderBookL2_25","action":"delete","data":[{"symbol":"XBTUSDT","id":32402520105,"side":"Buy","price":66762.2,"timestamp":"2024-05-18T15:46:26.607Z"}]}
{"table":"orderBookL2_25","action":"update","data":[{"symbol":"XBTUSDT","id":32402513876,"side":"Buy","size":638000,"price":66737.2,"timestamp":"2024-05-18T15:46:26.607Z"}]}
{"table":"orderBookL2_25","action":"insert","data":[{"symbol":"XBTUSDT","id":32402523767,"side":"Buy","size":16000,"price":66771.6,"timestamp":"2024-05-18T15:46:26.607Z"}]}
{"table":"orderBookL2_25","action":"delete","data":[{"symbol":"XBTUSDT","id":32402520906,"side":"Sell","price":66812.1,"timestamp":"2024-05-18T15:46:26.656Z"},{"symbol":"XBTUSDT","id":32402523327,"side":"Sell","price":66785.6,"timestamp":"2024-05-18T15:46:26.656Z"},{"symbol":"XBTUSDT","id":32402522925,"side":"Sell","price":66802.0,"timestamp":"2024-05-18T15:46:26.656Z"},{"symbol":"XBTUSDT","id":32402523331,"side":"Sell","price":66792.9,"timestamp":"2024-05-18T15:46:26.656Z"},{"symbol":"XBTUSDT","id":32402518323,"side":"Buy","price":66737.5,"timestamp":"2024-05-18T15:46:26.656Z"},{"symbol":"XBTUSDT","id":32402523344,"side":"Buy","price":66757.9,"timestamp":"2024-05-18T15:46:26.656Z"}]}
{"table":"orderBookL2_25","action":"update","data":[{"symbol":"XBTUSDT","id":32402517532,"side":"Buy","size":120000,"price":66757.6,"timestamp":"2024-05-18T15:46:26.656Z"},{"symbol":"XBTUSDT","id":32402514918,"side":"Buy","size":388000,"price":66737.4,"timestamp":"2024-05-18T15:46:26.656Z"},{"symbol":"XBTUSDT","id":32402513876,"side":"Buy","size":638000,"price":66737.2,"timestamp":"2024-05-18T15:46:26.656Z"}]}
{"table":"orderBookL2_25","action":"insert","data":[{"symbol":"XBTUSDT","id":32402523896,"side":"Sell","size":158000,"price":66783.0,"timestamp":"2024-05-18T15:46:26.656Z"},{"symbol":"XBTUSDT","id":32402523908,"side":"Sell","size":20000,"price":66785.4,"timestamp":"2024-05-18T15:46:26.656Z"},{"symbol":"XBTUSDT","id":32402523891,"side":"Sell","size":1000,"price":66792.7,"timestamp":"2024-05-18T15:46:26.656Z"},{"symbol":"XBTUSDT","id":32402523906,"side":"Sell","size":218000,"price":66787.7,"timestamp":"2024-05-18T15:46:26.656Z"},{"symbol":"XBTUSDT","id":32402523898,"side":"Buy","size":69000,"price":66761.1,"timestamp":"2024-05-18T15:46:26.656Z"},{"symbol":"XBTUSDT","id":32402523902,"side":"Buy","size":156000,"price":66747.6,"timestamp":"2024-05-18T15:46:26.656Z"}]}
{"table":"orderBookL2_25","action":"delete","data":[{"symbol":"ETHUSDT","id":32402523355,"side":"Buy","price":3107.65,"timestamp":"2024-05-18T15:46:26.665Z"}]}
{"table":"orderBookL2_25","action":"update","data":[{"symbol":"ETHUSDT","id":32402521474,"side":"Buy","size":100000,"price":3109.42,"timestamp":"2024-05-18T15:46:26.665Z"}]}
{"table":"orderBookL2_25","action":"insert","data":[{"symbol":"ETHUSDT","id":32402523924,"side":"Buy","size":1000,"price":3109.44,"timestamp":"2024-05-18T15:46:26.665Z"}]}
{"table":"orderBookL2_25","action":"delete","data":[{"symbol":"XBTUSDT","id":32402523891,"side":"Sell","price":66792.7,"timestamp":"2024-05-18T15:46:26.705Z"},{"symbol":"XBTUSDT","id":32402523308,"side":"Sell","price":66792.8,"timestamp":"2024-05-18T15:46:26.705Z"},{"symbol":"XBTUSDT","id":32402462668,"side":"Sell","price":66801.9,"timestamp":"2024-05-18T15:46:26.705Z"},{"symbol":"XBTUSDT","id":32402523908,"side":"Sell","price":66785.4,"timestamp":"2024-05-18T15:46:26.705Z"},{"symbol":"XBTUSDT","id":32402523321,"side":"Sell","price":66785.5,"timestamp":"2024-05-18T15:46:26.705Z"},{"symbol":"XBTUSDT","id":32402523334,"side":"Buy","price":66758.0,"timestamp":"2024-05-18T15:46:26.705Z"},{"symbol":"XBTUSDT","id":32402513876,"side":"Buy","price":66737.2,"timestamp":"2024-05-18T15:46:26.705Z"}]}
{"table":"orderBookL2_25","action":"update","data":[{"symbol":"XBTUSDT","id":32402517532,"side":"Buy","size":100000,"price":66757.6,"timestamp":"2024-05-18T15:46:26.705Z"}]}
{"table":"orderBookL2_25","action":"insert","data":[{"symbol":"XBTUSDT","id":32402523992,"side":"Sell","size":20000,"price":66785.4,"timestamp":"2024-05-18T15:46:26.705Z"},{"symbol":"XBTUSDT","id":32402523945,"side":"Sell","size":1000,"price":66792.7,"timestamp":"2024-05-18T15:46:26.705Z"},{"symbol":"XBTUSDT","id":32402523954,"side":"Sell","size":1000,"price":66792.6,"timestamp":"2024-05-18T15:46:26.705Z"},{"symbol":"XBTUSDT","id":32402523922,"side":"Sell","size":62000,"price":66792.0,"timestamp":"2024-05-18T15:46:26.705Z"},{"symbol":"XBTUSDT","id":32402523994,"side":"Sell","size":20000,"price":66785.3,"timestamp":"2024-05-18T15:46:26.705Z"},{"symbol":"XBTUSDT","id":32402523961,"side":"Buy","size":20000,"price":66757.8,"timestamp":"2024-05-18T15:46:26.705Z"},{"symbol":"XBTUSDT","id":32402523986,"side":"Buy","size":20000,"price":66757.7,"timestamp":"2024-05-18T15:46:26.705Z"}]}
{"table":"orderBookL2_25","action":"delete","data":[{"symbol":"ETHUSDT","id":32402523924,"side":"Buy","price":3109.44,"timestamp":"2024-05-18T15:46:26.715Z"}]}
{"table":"orderBookL2_25","action":"update","data":[{"symbol":"ETHUSDT","id":32402517483,"side":"Buy","size":216000,"price":3109.41,"timestamp":"2024-05-18T15:46:26.715Z"},{"symbol":"ETHUSDT","id":32402520621,"side":"Buy","size":100000,"price":3108.01,"timestamp":"2024-05-18T15:46:26.715Z"},{"symbol":"ETHUSDT","id":32402521474,"side":"Buy","size":101000,"price":3109.42,"timestamp":"2024-05-18T15:46:26.715Z"}]}
{"table":"orderBookL2_25","action":"insert","data":[{"symbol":"ETHUSDT","id":32402523981,"side":"Buy","size":1000,"price":3109.43,"timestamp":"2024-05-18T15:46:26.715Z"}]}
{"table":"orderBookL2_25","action":"delete","data":[{"symbol":"XBTUSDT","id":32402523170,"side":"Sell","price":66790.7,"timestamp":"2024-05-18T15:46:26.754Z"},{"symbol":"XBTUSDT","id":32402523992,"side":"Sell","price":66785.4,"timestamp":"2024-05-18T15:46:26.754Z"},{"symbol":"XBTUSDT","id":32402523986,"side":"Buy","price":66757.7,"timestamp":"2024-05-18T15:46:26.754Z"}]}
{"table":"orderBookL2_25","action":"insert","data":[{"symbol":"XBTUSDT","id":32402524068,"side":"Sell","size":20000,"price":66785.2,"timestamp":"2024-05-18T15:46:26.754Z"},{"symbol":"XBTUSDT","id":32402524011,"side":"Sell","size":3000,"price":66792.8,"timestamp":"2024-05-18T15:46:26.754Z"},{"symbol":"XBTUSDT","id":32402524087,"side":"Buy","size":20000,"price":66757.9,"timestamp":"2024-05-18T15:46:26.754Z"}]}
{"table":"orderBookL2_25","action":"delete","data":[{"symbol":"ETHUSDT","id":32398201667,"side":"Sell","price":3115.60,"timestamp":"2024-05-18T15:46:26.764Z"},{"symbol":"ETHUSDT","id":32402522934,"side":"Buy","price":3109.66,"timestamp":"2024-05-18T15:46:26.764Z"},{"symbol":"ETHUSDT","id":32402523391,"side":"Buy","price":3109.65,"timestamp":"2024-05-18T15:46:26.764Z"},{"symbol":"ETHUSDT","id":32402518973,"side":"Buy","price":3108.62,"timestamp":"2024-05-18T15:46:26.764Z"}]}
{"table":"orderBookL2_25","action":"update","data":[{"symbol":"ETHUSDT","id":32402521771,"side":"Buy","size":548000,"price":3109.26,"timestamp":"2024-05-18T15:46:26.764Z"}]}
{"table":"orderBookL2_25","action":"insert","data":[{"symbol":"ETHUSDT","id":32402524076,"side":"Sell","size":81000,"price":3110.48,"timestamp":"2024-05-18T15:46:26.764Z"},{"symbol":"ETHUSDT","id":32402524070,"side":"Buy","size":32000,"price":3109.68,"timestamp":"2024-05-18T15:46:26.764Z"},{"symbol":"ETHUSDT","id":32402524074,"side":"Buy","size":32000,"price":3109.67,"timestamp":"2024-05-18T15:46:26.764Z"},{"symbol":"ETHUSDT","id":32402523355,"side":"Buy","size":1126000,"price":3107.65,"timestamp":"2024-05-18T15:46:26.764Z"}]}
{"table":"orderBookL2_25","action":"delete","data":[{"symbol":"XBTUSDT","id":32402524068,"side":"Sell","price":66785.2,"timestamp":"2024-05-18T15:46:26.803Z"},{"symbol":"XBTUSDT","id":32402524087,"side":"Buy","price":66757.9,"timestamp":"2024-05-18T15:46:26.803Z"}]}
{"table":"orderBookL2_25","action":"insert","data":[{"symbol":"XBTUSDT","id":32402524156,"side":"Sell","size":20000,"price":66785.4,"timestamp":"2024-05-18T15:46:26.803Z"},{"symbol":"XBTUSDT","id":32402524151,"side":"Buy","size":20000,"price":66757.7,"timestamp":"2024-05-18T15:46:26.803Z"}]}
{"table":"orderBookL2_25","action":"delete","data":[{"symbol":"ETHUSDT","id":32402500495,"side":"Sell","price":3115.00,"timestamp":"2024-05-18T15:46:26.828Z"}]}
{"table":"orderBookL2_25","action":"insert","data":[{"symbol":"ETHUSDT","id":32402524191,"side":"Sell","size":100000,"price":3110.33,"timestamp":"2024-05-18T15:46:26.828Z"}]}
{"table":"orderBookL2_25","action":"delete","data":[{"symbol":"XBTUSDT","id":32402524156,"side":"Sell","price":66785.4,"timestamp":"2024-05-18T15:46:26.852Z"},{"symbol":"XBTUSDT","id":32402523945,"side":"Sell","price":66792.7,"timestamp":"2024-05-18T15:46:26.852Z"},{"symbol":"XBTUSDT","id":32402524151,"side":"Buy","price":66757.7,"timestamp":"2024-05-18T15:46:26.852Z"}]}
{"table":"orderBookL2_25","action":"update","data":[{"symbol":"XBTUSDT","id":32402523325,"side":"Buy","size":16000,"price":66771.5,"timestamp":"2024-05-18T15:46:26.852Z"},{"symbol":"XBTUSDT","id":32402505821,"side":"Buy","size":113000,"price":66764.4,"timestamp":"2024-05-18T15:46:26.852Z"}]}
{"table":"orderBookL2_25","action":"insert","data":[{"symbol":"XBTUSDT","id":32402524187,"side":"Sell","size":1000,"price":66792.7,"timestamp":"2024-05-18T15:46:26.852Z"},{"symbol":"XBTUSDT","id":32402524258,"side":"Sell","size":20000,"price":66785.4,"timestamp":"2024-05-18T15:46:26.852Z"},{"symbol":"XBTUSDT","id":32402524241,"side":"Buy","size":20000,"price":66757.7,"timestamp":"2024-05-18T15:46:26.852Z"}]}
{"table":"orderBookL2_25","action":"delete","data":[{"symbol":"ETHUSDT","id":32402524076,"side":"Sell","price":3110.48,"timestamp":"2024-05-18T15:46:26.878Z"},{"symbol":"ETHUSDT","id":32402523400,"side":"Sell","price":3111.22,"timestamp":"2024-05-18T15:46:26.878Z"},{"symbol":"ETHUSDT","id":32402523408,"side":"Sell","price":3110.49,"timestamp":"2024-05-18T15:46:26.878Z"},{"symbol":"ETHUSDT","id":32402523523,"side":"Sell","price":3110.85,"timestamp":"2024-05-18T15:46:26.878Z"},{"symbol":"ETHUSDT","id":32402524070,"side":"Buy","price":3109.68,"timestamp":"2024-05-18T15:46:26.878Z"},{"symbol":"ETHUSDT","id":32402523355,"side":"Buy","price":3107.65,"timestamp":"2024-05-18T15:46:26.878Z"}]}
{"table":"orderBookL2_25","action":"update","data":[{"symbol":"ETHUSDT","id":32402358267,"side":"Sell","size":100000,"price":3114.29,"timestamp":"2024-05-18T15:46:26.878Z"},{"symbol":"ETHUSDT","id":32402450797,"side":"Sell","size":100000,"price":3114.61,"timestamp":"2024-05-18T15:46:26.878Z"},{"symbol":"ETHUSDT","id":32402521771,"side":"Buy","size":448000,"price":3109.26,"timestamp":"2024-05-18T15:46:26.878Z"}]}
{"table":"orderBookL2_25","action":"insert","data":[{"symbol":"ETHUSDT","id":32402500495,"side":"Sell","size":17234000,"price":3115.00,"timestamp":"2024-05-18T15:46:26.878Z"},{"symbol":"ETHUSDT","id":32402524262,"side":"Sell","size":32000,"price":3111.20,"timestamp":"2024-05-18T15:46:26.878Z"},{"symbol":"ETHUSDT","id":32402524290,"side":"Sell","size":160000,"price":3111.60,"timestamp":"2024-05-18T15:46:26.878Z"},{"symbol":"ETHUSDT","id":32402524292,"side":"Sell","size":75000,"price":3110.31,"timestamp":"2024-05-18T15:46:26.878Z"},{"symbol":"ETHUSDT","id":32402524237,"side":"Buy","size":32000,"price":3109.66,"timestamp":"2024-05-18T15:46:26.878Z"},{"symbol":"ETHUSDT","id":32402524228,"side":"Buy","size":677000,"price":3107.66,"timestamp":"2024-05-18T15:46:26.878Z"}]}
{"table":"orderBookL2_25","action":"delete","data":[{"symbol":"XBTUSDT","id":32402524258,"side":"Sell","price":66785.4,"timestamp":"2024-05-18T15:46:26.901Z"},{"symbol":"XBTUSDT","id":32402524187,"side":"Sell","price":66792.7,"timestamp":"2024-05-18T15:46:26.901Z"},{"symbol":"XBTUSDT","id":32402523954,"side":"Sell","price":66792.6,"timestamp":"2024-05-18T15:46:26.901Z"},{"symbol":"XBTUSDT","id":32402523994,"side":"Sell","price":66785.3,"timestamp":"2024-05-18T15:46:26.901Z"},{"symbol":"XBTUSDT","id":32402523961,"side":"Buy","price":66757.8,"timestamp":"2024-05-18T15:46:26.901Z"},{"symbol":"XBTUSDT","id":32402524241,"side":"Buy","price":66757.7,"timestamp":"2024-05-18T15:46:26.901Z"}]}
{"table":"orderBookL2_25","action":"update","data":[{"symbol":"XBTUSDT","id":32402524011,"side":"Sell","size":3000,"price":66792.8,"timestamp":"2024-05-18T15:46:26.901Z"},{"symbol":"XBTUSDT","id":32402517532,"side":"Buy","size":120000,"price":66757.6,"timestamp":"2024-05-18T15:46:26.901Z"},{"symbol":"XBTUSDT","id":32402510162,"side":"Buy","size":30000,"price":66757.5,"timestamp":"2024-05-18T15:46:26.901Z"}]}
{"table":"orderBookL2_25","action":"insert","data":[{"symbol":"XBTUSDT","id":32402524355,"side":"Sell","size":1000,"price":66793.0,"timestamp":"2024-05-18T15:46:26.901Z"},{"symbol":"XBTUSDT","id":32402524339,"side":"Sell","size":20000,"price":66785.7,"timestamp":"2024-05-18T15:46:26.901Z"},{"symbol":"XBTUSDT","id":32402524381,"side":"Sell","size":20000,"price":66785.8,"timestamp":"2024-05-18T15:46:26.901Z"},{"symbol":"XBTUSDT","id":32402524350,"side":"Sell","size":1000,"price":66793.1,"timestamp":"2024-05-18T15:46:26.901Z"},{"symbol":"XBTUSDT","id":32402462262,"side":"Buy","size":100000,"price":66733.8,"timestamp":"2024-05-18T15:46:26.901Z"},{"symbol":"XBTUSDT","id":32402513876,"side":"Buy","size":638000,"price":66737.2,"timestamp":"2024-05-18T15:46:26.901Z"}]}
{"table":"orderBookL2_25","action":"delete","data":[{"symbol":"ETHUSDT","id":32402450797,"side":"Sell","price":3114.61,"timestamp":"2024-05-18T15:46:26.927Z"},{"symbol":"ETHUSDT","id":32402524262,"side":"Sell","price":3111.20,"timestamp":"2024-05-18T15:46:26.927Z"},{"symbol":"ETHUSDT","id":32402358267,"side":"Sell","price":3114.29,"timestamp":"2024-05-18T15:46:26.927Z"},{"symbol":"ETHUSDT","id":32402500495,"side":"Sell","price":3115.00,"timestamp":"2024-05-18T15:46:26.927Z"},{"symbol":"ETHUSDT","id":32402524237,"side":"Buy","price":3109.66,"timestamp":"2024-05-18T15:46:26.927Z"},{"symbol":"ETHUSDT","id":32402523981,"side":"Buy","price":3109.43,"timestamp":"2024-05-18T15:46:26.927Z"},{"symbol":"ETHUSDT","id":32402524074,"side":"Buy","price":3109.67,"timestamp":"2024-05-18T15:46:26.927Z"},{"symbol":"ETHUSDT","id":32402524228,"side":"Buy","price":3107.66,"timestamp":"2024-05-18T15:46:26.927Z"}]}
{"table":"orderBookL2_25","action":"update","data":[{"symbol":"ETHUSDT","id":32402517483,"side":"Buy","size":216000,"price":3109.41,"timestamp":"2024-05-18T15:46:26.927Z"},{"symbol":"ETHUSDT","id":32402517379,"side":"Buy","size":1000,"price":3109.40,"timestamp":"2024-05-18T15:46:26.927Z"},{"symbol":"ETHUSDT","id":32402521474,"side":"Buy","size":101000,"price":3109.42,"timestamp":"2024-05-18T15:46:26.927Z"}]}
{"table":"orderBookL2_25","action":"insert","data":[{"symbol":"ETHUSDT","id":32402524337,"side":"Sell","size":546000,"price":3110.80,"timestamp":"2024-05-18T15:46:26.927Z"},{"symbol":"ETHUSDT","id":32402524422,"side":"Sell","size":836000,"price":3111.43,"timestamp":"2024-05-18T15:46:26.927Z"},{"symbol":"ETHUSDT","id":32402524406,"side":"Sell","size":32000,"price":3111.20,"timestamp":"2024-05-18T15:46:26.927Z"},{"symbol":"ETHUSDT","id":32402524328,"side":"Sell","size":28000,"price":3110.67,"timestamp":"2024-05-18T15:46:26.927Z"},{"symbol":"ETHUSDT","id":32402524401,"side":"Buy","size":32000,"price":3109.66,"timestamp":"2024-05-18T15:46:26.927Z"},{"symbol":"ETHUSDT","id":32402524392,"side":"Buy","size":119000,"price":3108.48,"timestamp":"2024-05-18T15:46:26.927Z"},{"symbol":"ETHUSDT","id":32402524412,"side":"Buy","size":32000,"price":3109.67,"timestamp":"2024-05-18T15:46:26.927Z"},{"symbol":"ETHUSDT","id":32402524385,"side":"Buy","size":1000,"price":3109.43,"timestamp":"2024-05-18T15:46:26.927Z"}]}
{"table":"orderBookL2_25","action":"delete","data":[{"symbol":"XBTUSDT","id":32402524339,"side":"Sell","price":66785.7,"timestamp":"2024-05-18T15:46:26.950Z"},{"symbol":"XBTUSDT","id":32402524381,"side":"Sell","price":66785.8,"timestamp":"2024-05-18T15:46:26.950Z"},{"symbol":"XBTUSDT","id":32402524350,"side":"Sell","price":66793.1,"timestamp":"2024-05-18T15:46:26.950Z"},{"symbol":"XBTUSDT","id":32402524355,"side":"Sell","price":66793.0,"timestamp":"2024-05-18T15:46:26.950Z"},{"symbol":"XBTUSDT","id":32402462262,"side":"Buy","price":66733.8,"timestamp":"2024-05-18T15:46:26.950Z"}]}
{"table":"orderBookL2_25","action":"update","data":[{"symbol":"XBTUSDT","id":32402524011,"side":"Sell","size":4000,"price":66792.8,"timestamp":"2024-05-18T15:46:26.950Z"},{"symbol":"XBTUSDT","id":32402517532,"side":"Buy","size":120000,"price":66757.6,"timestamp":"2024-05-18T15:46:26.950Z"},{"symbol":"XBTUSDT","id":32402510162,"side":"Buy","size":10000,"price":66757.5,"timestamp":"2024-05-18T15:46:26.950Z"},{"symbol":"XBTUSDT","id":32402513876,"side":"Buy","size":638000,"price":66737.2,"timestamp":"2024-05-18T15:46:26.950Z"}]}
{"table":"orderBookL2_25","action":"insert","data":[{"symbol":"XBTUSDT","id":32402462668,"side":"Sell","size":100000,"price":66801.9,"timestamp":"2024-05-18T15:46:26.950Z"},{"symbol":"XBTUSDT","id":32402524472,"side":"Sell","size":20000,"price":66785.5,"timestamp":"2024-05-18T15:46:26.950Z"},{"symbol":"XBTUSDT","id":32402524394,"side":"Sell","size":20000,"price":66785.4,"timestamp":"2024-05-18T15:46:26.950Z"},{"symbol":"XBTUSDT","id":32402524388,"side":"Sell","size":1000,"price":66792.7,"timestamp":"2024-05-18T15:46:26.950Z"},{"symbol":"XBTUSDT","id":32402524399,"side":"Buy","size":20000,"price":66757.7,"timestamp":"2024-05-18T15:46:26.950Z"}]}
{"table":"orderBookL2_25","action":"delete","data":[{"symbol":"ETHUSDT","id":32402441505,"side":"Sell","price":3113.30,"timestamp":"2024-05-18T15:46:26.976Z"},{"symbol":"ETHUSDT","id":32402476053,"side":"Sell","price":3113.00,"timestamp":"2024-05-18T15:46:26.976Z"},{"symbol":"ETHUSDT","id":32402524412,"side":"Buy","price":3109.67,"timestamp":"2024-05-18T15:46:26.976Z"},{"symbol":"ETHUSDT","id":32402524385,"side":"Buy","price":3109.43,"timestamp":"2024-05-18T15:46:26.976Z"}]}
{"table":"orderBookL2_25","action":"update","data":[{"symbol":"ETHUSDT","id":32402522125,"side":"Sell","size":100000,"price":3111.21,"timestamp":"2024-05-18T15:46:26.976Z"},{"symbol":"ETHUSDT","id":32402524406,"side":"Sell","size":117000,"price":3111.20,"timestamp":"2024-05-18T15:46:26.976Z"},{"symbol":"ETHUSDT","id":32402517483,"side":"Buy","size":216000,"price":3109.41,"timestamp":"2024-05-18T15:46:26.976Z"}]}
{"table":"orderBookL2_25","action":"insert","data":[{"symbol":"ETHUSDT","id":32402524519,"side":"Sell","size":21000,"price":3110.30,"timestamp":"2024-05-18T15:46:26.976Z"},{"symbol":"ETHUSDT","id":32402524517,"side":"Sell","size":32000,"price":3111.22,"timestamp":"2024-05-18T15:46:26.976Z"},{"symbol":"ETHUSDT","id":32402524507,"side":"Buy","size":1000,"price":3109.43,"timestamp":"2024-05-18T15:46:26.976Z"},{"symbol":"ETHUSDT","id":32402524546,"side":"Buy","size":32000,"price":3109.67,"timestamp":"2024-05-18T15:46:26.976Z"}]}
{"table":"orderBookL2_25","action":"delete","data":[{"symbol":"XBTUSDT","id":32402462668,"side":"Sell","price":66801.9,"timestamp":"2024-05-18T15:46:26.999Z"},{"symbol":"XBTUSDT","id":32402524472,"side":"Sell","price":66785.5,"timestamp":"2024-05-18T15:46:26.999Z"},{"symbol":"XBTUSDT","id":32402513876,"side":"Buy","price":66737.2,"timestamp":"2024-05-18T15:46:26.999Z"}]}
{"table":"orderBookL2_25","action":"update","data":[{"symbol":"XBTUSDT","id":32402524011,"side":"Sell","size":3000,"price":66792.8,"timestamp":"2024-05-18T15:46:26.999Z"},{"symbol":"XBTUSDT","id":32402517532,"side":"Buy","size":100000,"price":66757.6,"timestamp":"2024-05-18T15:46:26.999Z"}]}
{"table":"orderBookL2_25","action":"insert","data":[{"symbol":"XBTUSDT","id":32402524562,"side":"Sell","size":20000,"price":66785.3,"timestamp":"2024-05-18T15:46:26.999Z"},{"symbol":"XBTUSDT","id":32402524544,"side":"Sell","size":1000,"price":66792.6,"timestamp":"2024-05-18T15:46:26.999Z"},{"symbol":"XBTUSDT","id":32402524564,"side":"Buy","size":20000,"price":66757.8,"timestamp":"2024-05-18T15:46:26.999Z"}]}
{"table":"orderBookL2_25","action":"delete","data":[{"symbol":"ETHUSDT","id":32402524517,"side":"Sell","price":3111.22,"timestamp":"2024-05-18T15:46:27.025Z"}]}
{"table":"orderBookL2_25","action":"update","data":[{"symbol":"ETHUSDT","id":32402522125,"side":"Sell","size":132000,"price":3111.21,"timestamp":"2024-05-18T15:46:27.025Z"},{"symbol":"ETHUSDT","id":32402476065,"side":"Sell","size":120000,"price":3112.99,"timestamp":"2024-05-18T15:46:27.025Z"}]}
{"table":"orderBookL2_25","action":"insert","data":[{"symbol":"ETHUSDT","id":32402524554,"side":"Sell","size":26000,"price":3111.19,"timestamp":"2024-05-18T15:46:27.025Z"}]}
{"table":"orderBookL2_25","action":"delete","data":[{"symbol":"XBTUSDT","id":32402522965,"side":"Buy","price":66758.4,"timestamp":"2024-05-18T15:46:27.048Z"}]}
{"table":"orderBookL2_25","action":"update","data":[{"symbol":"XBTUSDT","id":32402523325,"side":"Buy","size":116000,"price":66771.5,"timestamp":"2024-05-18T15:46:27.048Z"}]}
{"table":"orderBookL2_25","action":"insert","data":[{"symbol":"XBTUSDT","id":32402524597,"side":"Buy","size":22000,"price":66762.7,"timestamp":"2024-05-18T15:46:27.048Z"}]}
{"table":"orderBookL2_25","action":"delete","data":[{"symbol":"ETHUSDT","id":32402476065,"side":"Sell","price":3112.99,"timestamp":"2024-05-18T15:46:27.074Z"},{"symbol":"ETHUSDT","id":32402470274,"side":"Sell","price":3112.84,"timestamp":"2024-05-18T15:46:27.074Z"}]}
{"table":"orderBookL2_25","action":"insert","data":[{"symbol":"ETHUSDT","id":32402524611,"side":"Sell","size":48000,"price":3111.77,"timestamp":"2024-05-18T15:46:27.074Z"},{"symbol":"ETHUSDT","id":32402524613,"side":"Sell","size":25000,"price":3111.27,"timestamp":"2024-05-18T15:46:27.074Z"}]}
{"table":"orderBookL2_25","action":"delete","data":[{"symbol":"XBTUSDT","id":32402523116,"side":"Sell","price":66790.4,"timestamp":"2024-05-18T15:46:27.097Z"},{"symbol":"XBTUSDT","id":32402523896,"side":"Sell","price":66783.0,"timestamp":"2024-05-18T15:46:27.097Z"},{"symbol":"XBTUSDT","id":32402523220,"side":"Sell","price":66783.1,"timestamp":"2024-05-18T15:46:27.097Z"},{"symbol":"XBTUSDT","id":32402523922,"side":"Sell","price":66792.0,"timestamp":"2024-05-18T15:46:27.097Z"},{"symbol":"XBTUSDT","id":32402514918,"side":"Buy","price":66737.4,"timestamp":"2024-05-18T15:46:27.097Z"}]}
{"table":"orderBookL2_25","action":"insert","data":[{"symbol":"XBTUSDT","id":32402524656,"side":"Sell","size":101000,"price":66797.1,"timestamp":"2024-05-18T15:46:27.097Z"},{"symbol":"XBTUSDT","id":32402524671,"side":"Sell","size":156000,"price":66782.9,"timestamp":"2024-05-18T15:46:27.097Z"},{"symbol":"XBTUSDT","id":32402524668,"side":"Sell","size":91000,"price":66784.2,"timestamp":"2024-05-18T15:46:27.097Z"},{"symbol":"XBTUSDT","id":32402524647,"side":"Sell","size":8000,"price":66780.4,"timestamp":"2024-05-18T15:46:27.097Z"},{"symbol":"XBTUSDT","id":32402524654,"side":"Buy","size":268000,"price":66752.8,"timestamp":"2024-05-18T15:46:27.097Z"}]}
{"table":"orderBookL2_25","action":"delete","data":[{"symbol":"ETHUSDT","id":32402524554,"side":"Sell","price":3111.19,"timestamp":"2024-05-18T15:46:27.123Z"},{"symbol":"ETHUSDT","id":32402524401,"side":"Buy","price":3109.66,"timestamp":"2024-05-18T15:46:27.123Z"}]}
{"table":"orderBookL2_25","action":"update","data":[{"symbol":"ETHUSDT","id":32402447682,"side":"Sell","size":100000,"price":3112.68,"timestamp":"2024-05-18T15:46:27.123Z"},{"symbol":"ETHUSDT","id":32402524406,"side":"Sell","size":85000,"price":3111.20,"timestamp":"2024-05-18T15:46:27.123Z"}]}
{"table":"orderBookL2_25","action":"insert","data":[{"symbol":"ETHUSDT","id":32402524741,"side":"Sell","size":32000,"price":3111.22,"timestamp":"2024-05-18T15:46:27.123Z"},{"symbol":"ETHUSDT","id":32402524734,"side":"Buy","size":32000,"price":3109.68,"timestamp":"2024-05-18T15:46:27.123Z"}]}
{"table":"orderBookL2_25","action":"delete","data":[{"symbol":"XBTUSDT","id":32402523596,"side":"Sell","price":66785.9,"timestamp":"2024-05-18T15:46:27.146Z"},{"symbol":"XBTUSDT","id":32402524388,"side":"Sell","price":66792.7,"timestamp":"2024-05-18T15:46:27.146Z"},{"symbol":"XBTUSDT","id":32402524671,"side":"Sell","price":66782.9,"timestamp":"2024-05-18T15:46:27.146Z"},{"symbol":"XBTUSDT","id":32402524668,"side":"Sell","price":66784.2,"timestamp":"2024-05-18T15:46:27.146Z"}]}
{"table":"orderBookL2_25","action":"update","data":[{"symbol":"XBTUSDT","id":32402524647,"side":"Sell","size":16000,"price":66780.4,"timestamp":"2024-05-18T15:46:27.146Z"},{"symbol":"XBTUSDT","id":32402522515,"side":"Sell","size":180000,"price":66778.4,"timestamp":"2024-05-18T15:46:27.146Z"},{"symbol":"XBTUSDT","id":32402522785,"side":"Buy","size":134000,"price":66778.3,"timestamp":"2024-05-18T15:46:27.146Z"}]}
{"table":"orderBookL2_25","action":"insert","data":[{"symbol":"XBTUSDT","id":32402462668,"side":"Sell","size":100000,"price":66801.9,"timestamp":"2024-05-18T15:46:27.146Z"},{"symbol":"XBTUSDT","id":32402520906,"side":"Sell","size":100000,"price":66812.1,"timestamp":"2024-05-18T15:46:27.146Z"},{"symbol":"XBTUSDT","id":32402522925,"side":"Sell","size":2000,"price":66802.0,"timestamp":"2024-05-18T15:46:27.146Z"},{"symbol":"XBTUSDT","id":32402524794,"side":"Sell","size":1000,"price":66792.7,"timestamp":"2024-05-18T15:46:27.146Z"}]}
{"table":"orderBookL2_25","action":"delete","data":[{"symbol":"ETHUSDT","id":32402447682,"side":"Sell","price":3112.68,"timestamp":"2024-05-18T15:46:27.172Z"},{"symbol":"ETHUSDT","id":32402524519,"side":"Sell","price":3110.30,"timestamp":"2024-05-18T15:46:27.172Z"},{"symbol":"ETHUSDT","id":32402524734,"side":"Buy","price":3109.68,"timestamp":"2024-05-18T15:46:27.172Z"}]}
{"table":"orderBookL2_25","action":"update","data":[{"symbol":"ETHUSDT","id":32402522125,"side":"Sell","size":100000,"price":3111.21,"timestamp":"2024-05-18T15:46:27.172Z"}]}
{"table":"orderBookL2_25","action":"insert","data":[{"symbol":"ETHUSDT","id":32402524820,"side":"Sell","size":21000,"price":3110.29,"timestamp":"2024-05-18T15:46:27.172Z"},{"symbol":"ETHUSDT","id":32402524830,"side":"Sell","size":32000,"price":3111.23,"timestamp":"2024-05-18T15:46:27.172Z"},{"symbol":"ETHUSDT","id":32402524814,"side":"Buy","size":32000,"price":3109.66,"timestamp":"2024-05-18T15:46:27.172Z"}]}
{"table":"orderBookL2_25","action":"delete","data":[{"symbol":"XBTUSDT","id":32402524562,"side":"Sell","price":66785.3,"timestamp":"2024-05-18T15:46:27.195Z"},{"symbol":"XBTUSDT","id":32402520906,"side":"Sell","price":66812.1,"timestamp":"2024-05-18T15:46:27.195Z"},{"symbol":"XBTUSDT","id":32402522925,"side":"Sell","price":66802.0,"timestamp":"2024-05-18T15:46:27.195Z"},{"symbol":"XBTUSDT","id":32402524544,"side":"Sell","price":66792.6,"timestamp":"2024-05-18T15:46:27.195Z"},{"symbol":"XBTUSDT","id":32402524399,"side":"Buy","price":66757.7,"timestamp":"2024-05-18T15:46:27.195Z"},{"symbol":"XBTUSDT","id":32402524564,"side":"Buy","price":66757.8,"timestamp":"2024-05-18T15:46:27.195Z"}]}
{"table":"orderBookL2_25","action":"update","data":[{"symbol":"XBTUSDT","id":32402524011,"side":"Sell","size":3000,"price":66792.8,"timestamp":"2024-05-18T15:46:27.195Z"}]}
{"table":"orderBookL2_25","action":"insert","data":[{"symbol":"XBTUSDT","id":32402524868,"side":"Sell","size":69000,"price":66784.2,"timestamp":"2024-05-18T15:46:27.195Z"},{"symbol":"XBTUSDT","id":32402524881,"side":"Sell","size":20000,"price":66785.3,"timestamp":"2024-05-18T15:46:27.195Z"},{"symbol":"XBTUSDT","id":32402524844,"side":"Sell","size":2000,"price":66802.5,"timestamp":"2024-05-18T15:46:27.195Z"},{"symbol":"XBTUSDT","id":32402524857,"side":"Sell","size":1000,"price":66792.6,"timestamp":"2024-05-18T15:46:27.195Z"},{"symbol":"XBTUSDT","id":32402524904,"side":"Buy","size":20000,"price":66757.7,"timestamp":"2024-05-18T15:46:27.195Z"},{"symbol":"XBTUSDT","id":32402524906,"side":"Buy","size":20000,"price":66758.0,"timestamp":"2024-05-18T15:46:27.195Z"}]}
{"table":"orderBookL2_25","action":"delete","data":[{"symbol":"ETHUSDT","id":32402524741,"side":"Sell","price":3111.22,"timestamp":"2024-05-18T15:46:27.221Z"},{"symbol":"ETHUSDT","id":32402524830,"side":"Sell","price":3111.23,"timestamp":"2024-05-18T15:46:27.221Z"}]}
{"table":"orderBookL2_25","action":"insert","data":[{"symbol":"ETHUSDT","id":32402524958,"side":"Sell","size":32000,"price":3111.25,"timestamp":"2024-05-18T15:46:27.221Z"},{"symbol":"ETHUSDT","id":32402524960,"side":"Sell","size":32000,"price":3111.24,"timestamp":"2024-05-18T15:46:27.221Z"}]}
{"table":"orderBookL2_25","action":"delete","data":[{"symbol":"XBTUSDT","id":32402524844,"side":"Sell","price":66802.5,"timestamp":"2024-05-18T15:46:27.244Z"},{"symbol":"XBTUSDT","id":32402523148,"side":"Sell","price":66780.5,"timestamp":"2024-05-18T15:46:27.244Z"},{"symbol":"XBTUSDT","id":32402524904,"side":"Buy","price":66757.7,"timestamp":"2024-05-18T15:46:27.244Z"},{"symbol":"XBTUSDT","id":32402524906,"side":"Buy","price":66758.0,"timestamp":"2024-05-18T15:46:27.244Z"}]}
{"table":"orderBookL2_25","action":"update","data":[{"symbol":"XBTUSDT","id":32402462668,"side":"Sell","size":100000,"price":66801.9,"timestamp":"2024-05-18T15:46:27.244Z"}]}
{"table":"orderBookL2_25","action":"insert","data":[{"symbol":"XBTUSDT","id":32402524955,"side":"Sell","size":74000,"price":66797.4,"timestamp":"2024-05-18T15:46:27.244Z"},{"symbol":"XBTUSDT","id":32402524922,"side":"Sell","size":20000,"price":66785.7,"timestamp":"2024-05-18T15:46:27.244Z"},{"symbol":"XBTUSDT","id":32402524933,"side":"Buy","size":20000,"price":66758.2,"timestamp":"2024-05-18T15:46:27.244Z"},{"symbol":"XBTUSDT","id":32402524962,"side":"Buy","size":20000,"price":66758.1,"timestamp":"2024-05-18T15:46:27.244Z"}]}
{"table":"orderBookL2_25","action":"delete","data":[{"symbol":"ETHUSDT","id":32402521905,"side":"Sell","price":3111.01,"timestamp":"2024-05-18T15:46:27.270Z"},{"symbol":"ETHUSDT","id":32402524958,"side":"Sell","price":3111.25,"timestamp":"2024-05-18T15:46:27.270Z"},{"symbol":"ETHUSDT","id":32402524406,"side":"Sell","price":3111.20,"timestamp":"2024-05-18T15:46:27.270Z"},{"symbol":"ETHUSDT","id":32402524507,"side":"Buy","price":3109.43,"timestamp":"2024-05-18T15:46:27.270Z"},{"symbol":"ETHUSDT","id":32402524814,"side":"Buy","price":3109.66,"timestamp":"2024-05-18T15:46:27.270Z"}]}
{"table":"orderBookL2_25","action":"update","data":[{"symbol":"ETHUSDT","id":32402521474,"side":"Buy","size":101000,"price":3109.42,"timestamp":"2024-05-18T15:46:27.270Z"},{"symbol":"ETHUSDT","id":32402520621,"side":"Buy","size":100000,"price":3108.01,"timestamp":"2024-05-18T15:46:27.270Z"},{"symbol":"ETHUSDT","id":32402517483,"side":"Buy","size":217000,"price":3109.41,"timestamp":"2024-05-18T15:46:27.270Z"}]}
{"table":"orderBookL2_25","action":"insert","data":[{"symbol":"ETHUSDT","id":32402524979,"side":"Sell","size":32000,"price":3111.23,"timestamp":"2024-05-18T15:46:27.270Z"},{"symbol":"ETHUSDT","id":32402525003,"side":"Sell","size":44000,"price":3111.19,"timestamp":"2024-05-18T15:46:27.270Z"},{"symbol":"ETHUSDT","id":32402447682,"side":"Sell","size":100000,"price":3112.68,"timestamp":"2024-05-18T15:46:27.270Z"},{"symbol":"ETHUSDT","id":32402524986,"side":"Buy","size":32000,"price":3109.68,"timestamp":"2024-05-18T15:46:27.270Z"},{"symbol":"ETHUSDT","id":32402524228,"side":"Buy","size":677000,"price":3107.66,"timestamp":"2024-05-18T15:46:27.270Z"}]}
{"table":"orderBookL2_25","action":"delete","data":[{"symbol":"XBTUSDT","id":32402524794,"side":"Sell","price":66792.7,"timestamp":"2024-05-18T15:46:27.293Z"},{"symbol":"XBTUSDT","id":32402524857,"side":"Sell","price":66792.6,"timestamp":"2024-05-18T15:46:27.293Z"},{"symbol":"XBTUSDT","id":32402523906,"side":"Sell","price":66787.7,"timestamp":"2024-05-18T15:46:27.293Z"},{"symbol":"XBTUSDT","id":32402522549,"side":"Sell","price":66787.8,"timestamp":"2024-05-18T15:46:27.293Z"},{"symbol":"XBTUSDT","id":32402524394,"side":"Sell","price":66785.4,"timestamp":"2024-05-18T15:46:27.293Z"},{"symbol":"XBTUSDT","id":32402524881,"side":"Sell","price":66785.3,"timestamp":"2024-05-18T15:46:27.293Z"},{"symbol":"XBTUSDT","id":32402523291,"side":"Buy","price":66750.9,"timestamp":"2024-05-18T15:46:27.293Z"},{"symbol":"XBTUSDT","id":32402524962,"side":"Buy","price":66758.1,"timestamp":"2024-05-18T15:46:27.293Z"},{"symbol":"XBTUSDT","id":32402524933,"side":"Buy","price":66758.2,"timestamp":"2024-05-18T15:46:27.293Z"}]}
{"table":"orderBookL2_25","action":"update","data":[{"symbol":"XBTUSDT","id":32402522515,"side":"Sell","size":78000,"price":66778.4,"timestamp":"2024-05-18T15:46:27.293Z"},{"symbol":"XBTUSDT","id":32402524654,"side":"Buy","size":625000,"price":66752.8,"timestamp":"2024-05-18T15:46:27.293Z"},{"symbol":"XBTUSDT","id":32402505821,"side":"Buy","size":114000,"price":66764.4,"timestamp":"2024-05-18T15:46:27.293Z"}]}
{"table":"orderBookL2_25","action":"insert","data":[{"symbol":"XBTUSDT","id":32402525087,"side":"Sell","size":20000,"price":66785.8,"timestamp":"2024-05-18T15:46:27.293Z"},{"symbol":"XBTUSDT","id":32402525057,"side":"Sell","size":1000,"price":66793.3,"timestamp":"2024-05-18T15:46:27.293Z"},{"symbol":"XBTUSDT","id":32402524997,"side":"Sell","size":364000,"price":66790.3,"timestamp":"2024-05-18T15:46:27.293Z"},{"symbol":"XBTUSDT","id":32402525080,"side":"Sell","size":20000,"price":66785.1,"timestamp":"2024-05-18T15:46:27.293Z"},{"symbol":"XBTUSDT","id":32402525066,"side":"Sell","size":1000,"price":66793.2,"timestamp":"2024-05-18T15:46:27.293Z"},{"symbol":"XBTUSDT","id":32402524844,"side":"Sell","size":2000,"price":66802.5,"timestamp":"2024-05-18T15:46:27.293Z"},{"symbol":"XBTUSDT","id":32402525083,"side":"Buy","size":20000,"price":66758.5,"timestamp":"2024-05-18T15:46:27.293Z"},{"symbol":"XBTUSDT","id":32402525035,"side":"Buy","size":20000,"price":66758.4,"timestamp":"2024-05-18T15:46:27.293Z"},{"symbol":"XBTUSDT","id":32402514918,"side":"Buy","size":388000,"price":66737.4,"timestamp":"2024-05-18T15:46:27.293Z"}]}
{"table":"orderBookL2_25","action":"delete","data":[{"symbol":"ETHUSDT","id":32402525003,"side":"Sell","price":3111.19,"timestamp":"2024-05-18T15:46:27.319Z"},{"symbol":"ETHUSDT","id":32402524292,"side":"Sell","price":3110.31,"timestamp":"2024-05-18T15:46:27.319Z"},{"symbol":"ETHUSDT","id":32402524820,"side":"Sell","price":3110.29,"timestamp":"2024-05-18T15:46:27.319Z"},{"symbol":"ETHUSDT","id":32402524979,"side":"Sell","price":3111.23,"timestamp":"2024-05-18T15:46:27.319Z"},{"symbol":"ETHUSDT","id":32402524986,"side":"Buy","price":3109.68,"timestamp":"2024-05-18T15:46:27.319Z"},{"symbol":"ETHUSDT","id":32402524228,"side":"Buy","price":3107.66,"timestamp":"2024-05-18T15:46:27.319Z"},{"symbol":"ETHUSDT","id":32402524546,"side":"Buy","price":3109.67,"timestamp":"2024-05-18T15:46:27.319Z"}]}
{"table":"orderBookL2_25","action":"update","data":[{"symbol":"ETHUSDT","id":32402447682,"side":"Sell","size":100000,"price":3112.68,"timestamp":"2024-05-18T15:46:27.319Z"},{"symbol":"ETHUSDT","id":32402521474,"side":"Buy","size":101000,"price":3109.42,"timestamp":"2024-05-18T15:46:27.319Z"},{"symbol":"ETHUSDT","id":32402517379,"side":"Buy","size":1000,"price":3109.40,"timestamp":"2024-05-18T15:46:27.319Z"}]}
{"table":"orderBookL2_25","action":"insert","data":[{"symbol":"ETHUSDT","id":32402525115,"side":"Sell","size":32000,"price":3111.25,"timestamp":"2024-05-18T15:46:27.319Z"},{"symbol":"ETHUSDT","id":32402476065,"side":"Sell","size":120000,"price":3112.99,"timestamp":"2024-05-18T15:46:27.319Z"},{"symbol":"ETHUSDT","id":32402525070,"side":"Sell","size":21000,"price":3110.28,"timestamp":"2024-05-18T15:46:27.319Z"},{"symbol":"ETHUSDT","id":32402470274,"side":"Sell","size":100000,"price":3112.84,"timestamp":"2024-05-18T15:46:27.319Z"},{"symbol":"ETHUSDT","id":32402525099,"side":"Buy","size":32000,"price":3109.67,"timestamp":"2024-05-18T15:46:27.319Z"},{"symbol":"ETHUSDT","id":32402525174,"side":"Buy","size":100000,"price":3109.35,"timestamp":"2024-05-18T15:46:27.319Z"},{"symbol":"ETHUSDT","id":32402525117,"side":"Buy","size":32000,"price":3109.66,"timestamp":"2024-05-18T15:46:27.319Z"}]}
{"table":"orderBookL2_25","action":"update","data":[{"symbol":"XBTETH","id":32402511021,"side":"Sell","size":7,"price":21.911,"timestamp":"2024-05-18T15:46:27.341Z"}]}
{"table":"orderBookL2_25","action":"delete","data":[{"symbol":"XBTUSDT","id":32402525087,"side":"Sell","price":66785.8,"timestamp":"2024-05-18T15:46:27.342Z"},{"symbol":"XBTUSDT","id":32402525080,"side":"Sell","price":66785.1,"timestamp":"2024-05-18T15:46:27.342Z"},{"symbol":"XBTUSDT","id":32402523103,"side":"Sell","price":66796.1,"timestamp":"2024-05-18T15:46:27.342Z"},{"symbol":"XBTUSDT","id":32402525057,"side":"Sell","price":66793.3,"timestamp":"2024-05-18T15:46:27.342Z"},{"symbol":"XBTUSDT","id":32402524922,"side":"Sell","price":66785.7,"timestamp":"2024-05-18T15:46:27.342Z"},{"symbol":"XBTUSDT","id":32402514918,"side":"Buy","price":66737.4,"timestamp":"2024-05-18T15:46:27.342Z"},{"symbol":"XBTUSDT","id":32402525035,"side":"Buy","price":66758.4,"timestamp":"2024-05-18T15:46:27.342Z"},{"symbol":"XBTUSDT","id":32402525083,"side":"Buy","price":66758.5,"timestamp":"2024-05-18T15:46:27.342Z"}]}
{"table":"orderBookL2_25","action":"update","data":[{"symbol":"XBTUSDT","id":32402522515,"side":"Sell","size":122000,"price":66778.4,"timestamp":"2024-05-18T15:46:27.342Z"}]}
{"table":"orderBookL2_25","action":"insert","data":[{"symbol":"XBTUSDT","id":32402525229,"side":"Sell","size":1000,"price":66793.1,"timestamp":"2024-05-18T15:46:27.342Z"},{"symbol":"XBTUSDT","id":32402525107,"side":"Sell","size":3000,"price":66798.4,"timestamp":"2024-05-18T15:46:27.342Z"},{"symbol":"XBTUSDT","id":32402525205,"side":"Sell","size":20000,"price":66785.8,"timestamp":"2024-05-18T15:46:27.342Z"},{"symbol":"XBTUSDT","id":32402525129,"side":"Sell","size":20000,"price":66785.9,"timestamp":"2024-05-18T15:46:27.342Z"},{"symbol":"XBTUSDT","id":32402520906,"side":"Sell","size":100000,"price":66812.1,"timestamp":"2024-05-18T15:46:27.342Z"},{"symbol":"XBTUSDT","id":32402525119,"side":"Buy","size":20000,"price":66758.0,"timestamp":"2024-05-18T15:46:27.342Z"},{"symbol":"XBTUSDT","id":32402525224,"side":"Buy","size":100000,"price":66774.9,"timestamp":"2024-05-18T15:46:27.342Z"},{"symbol":"XBTUSDT","id":32402525207,"side":"Buy","size":20000,"price":66758.1,"timestamp":"2024-05-18T15:46:27.342Z"}]}
{"table":"orderBookL2_25","action":"delete","data":[{"symbol":"ETHUSDT","id":32402524611,"side":"Sell","price":3111.77,"timestamp":"2024-05-18T15:46:27.368Z"},{"symbol":"ETHUSDT","id":32402524290,"side":"Sell","price":3111.60,"timestamp":"2024-05-18T15:46:27.368Z"},{"symbol":"ETHUSDT","id":32402476065,"side":"Sell","price":3112.99,"timestamp":"2024-05-18T15:46:27.368Z"},{"symbol":"ETHUSDT","id":32402524191,"side":"Sell","price":3110.33,"timestamp":"2024-05-18T15:46:27.368Z"},{"symbol":"ETHUSDT","id":32402524960,"side":"Sell","price":3111.24,"timestamp":"2024-05-18T15:46:27.368Z"}]}
{"table":"orderBookL2_25","action":"update","data":[{"symbol":"ETHUSDT","id":32402517483,"side":"Buy","size":117000,"price":3109.41,"timestamp":"2024-05-18T15:46:27.368Z"},{"symbol":"ETHUSDT","id":32402520621,"side":"Buy","size":100000,"price":3108.01,"timestamp":"2024-05-18T15:46:27.368Z"},{"symbol":"ETHUSDT","id":32402525099,"side":"Buy","size":132000,"price":3109.67,"timestamp":"2024-05-18T15:46:27.368Z"}]}
{"table":"orderBookL2_25","action":"insert","data":[{"symbol":"ETHUSDT","id":32402358267,"side":"Sell","size":100000,"price":3114.29,"timestamp":"2024-05-18T15:46:27.368Z"},{"symbol":"ETHUSDT","id":32402476053,"side":"Sell","size":100000,"price":3113.00,"timestamp":"2024-05-18T15:46:27.368Z"},{"symbol":"ETHUSDT","id":32402525330,"side":"Sell","size":32000,"price":3111.26,"timestamp":"2024-05-18T15:46:27.368Z"},{"symbol":"ETHUSDT","id":32402441505,"side":"Sell","size":101000,"price":3113.30,"timestamp":"2024-05-18T15:46:27.368Z"},{"symbol":"ETHUSDT","id":32402450797,"side":"Sell","size":100000,"price":3114.61,"timestamp":"2024-05-18T15:46:27.368Z"}]}
{"table":"orderBookL2_25","action":"update","data":[{"symbol":"XBTETH","id":32402510917,"side":"Buy","size":7,"price":21.093,"timestamp":"2024-05-18T15:46:27.390Z"}]}
{"table":"orderBookL2_25","action":"delete","data":[{"symbol":"XBTUSDT","id":32402525229,"side":"Sell","price":66793.1,"timestamp":"2024-05-18T15:46:27.391Z"},{"symbol":"XBTUSDT","id":32402525205,"side":"Sell","price":66785.8,"timestamp":"2024-05-18T15:46:27.391Z"},{"symbol":"XBTUSDT","id":32402524844,"side":"Sell","price":66802.5,"timestamp":"2024-05-18T15:46:27.391Z"},{"symbol":"XBTUSDT","id":32402524955,"side":"Sell","price":66797.4,"timestamp":"2024-05-18T15:46:27.391Z"},{"symbol":"XBTUSDT","id":32402524997,"side":"Sell","price":66790.3,"timestamp":"2024-05-18T15:46:27.391Z"},{"symbol":"XBTUSDT","id":32402525066,"side":"Sell","price":66793.2,"timestamp":"2024-05-18T15:46:27.391Z"},{"symbol":"XBTUSDT","id":32402523317,"side":"Buy","price":66771.0,"timestamp":"2024-05-18T15:46:27.391Z"},{"symbol":"XBTUSDT","id":32402525207,"side":"Buy","price":66758.1,"timestamp":"2024-05-18T15:46:27.391Z"},{"symbol":"XBTUSDT","id":32402505864,"side":"Buy","price":66740.6,"timestamp":"2024-05-18T15:46:27.391Z"}]}
{"table":"orderBookL2_25","action":"update","data":[{"symbol":"XBTUSDT","id":32402524011,"side":"Sell","size":4000,"price":66792.8,"timestamp":"2024-05-18T15:46:27.391Z"},{"symbol":"XBTUSDT","id":32402522785,"side":"Buy","size":142000,"price":66778.3,"timestamp":"2024-05-18T15:46:27.391Z"},{"symbol":"XBTUSDT","id":32402517625,"side":"Buy","size":100000,"price":66744.0,"timestamp":"2024-05-18T15:46:27.391Z"},{"symbol":"XBTUSDT","id":32402524654,"side":"Buy","size":268000,"price":66752.8,"timestamp":"2024-05-18T15:46:27.391Z"},{"symbol":"XBTUSDT","id":32402523325,"side":"Buy","size":108000,"price":66771.5,"timestamp":"2024-05-18T15:46:27.391Z"}]}
{"table":"orderBookL2_25","action":"insert","data":[{"symbol":"XBTUSDT","id":32402525440,"side":"Sell","size":20000,"price":66785.6,"timestamp":"2024-05-18T15:46:27.391Z"},{"symbol":"XBTUSDT","id":32402520719,"side":"Sell","size":1363000,"price":66815.6,"timestamp":"2024-05-18T15:46:27.391Z"},{"symbol":"XBTUSDT","id":32402525363,"side":"Sell","size":1000,"price":66792.9,"timestamp":"2024-05-18T15:46:27.391Z"},{"symbol":"XBTUSDT","id":32402524651,"side":"Sell","size":823000,"price":66815.5,"timestamp":"2024-05-18T15:46:27.391Z"},{"symbol":"XBTUSDT","id":32402525338,"side":"Sell","size":74000,"price":66795.4,"timestamp":"2024-05-18T15:46:27.391Z"},{"symbol":"XBTUSDT","id":32402525311,"side":"Sell","size":350000,"price":66788.6,"timestamp":"2024-05-18T15:46:27.391Z"},{"symbol":"XBTUSDT","id":32402525279,"side":"Buy","size":8000,"price":66775.0,"timestamp":"2024-05-18T15:46:27.391Z"},{"symbol":"XBTUSDT","id":32402525434,"side":"Buy","size":20000,"price":66758.2,"timestamp":"2024-05-18T15:46:27.391Z"},{"symbol":"XBTUSDT","id":32402525313,"side":"Buy","size":359000,"price":66752.9,"timestamp":"2024-05-18T15:46:27.391Z"}]}
{"table":"orderBookL2_25","action":"delete","data":[{"symbol":"ETHUSDT","id":32402484839,"side":"Sell","price":3111.49,"timestamp":"2024-05-18T15:46:27.417Z"},{"symbol":"ETHUSDT","id":32402522434,"side":"Sell","price":3112.67,"timestamp":"2024-05-18T15:46:27.417Z"},{"symbol":"ETHUSDT","id":32402525330,"side":"Sell","price":3111.26,"timestamp":"2024-05-18T15:46:27.417Z"},{"symbol":"ETHUSDT","id":32402522125,"side":"Sell","price":3111.21,"timestamp":"2024-05-18T15:46:27.417Z"},{"symbol":"ETHUSDT","id":32402525070,"side":"Sell","price":3110.28,"timestamp":"2024-05-18T15:46:27.417Z"},{"symbol":"ETHUSDT","id":32402524613,"side":"Sell","price":3111.27,"timestamp":"2024-05-18T15:46:27.417Z"},{"symbol":"ETHUSDT","id":32402521474,"side":"Buy","price":3109.42,"timestamp":"2024-05-18T15:46:27.417Z"},{"symbol":"ETHUSDT","id":32402522241,"side":"Buy","price":3108.15,"timestamp":"2024-05-18T15:46:27.417Z"},{"symbol":"ETHUSDT","id":32402520621,"side":"Buy","price":3108.01,"timestamp":"2024-05-18T15:46:27.417Z"},{"symbol":"ETHUSDT","id":32402525099,"side":"Buy","price":3109.67,"timestamp":"2024-05-18T15:46:27.417Z"},{"symbol":"ETHUSDT","id":32402525117,"side":"Buy","price":3109.66,"timestamp":"2024-05-18T15:46:27.417Z"}]}
{"table":"orderBookL2_25","action":"update","data":[{"symbol":"ETHUSDT","id":32402450797,"side":"Sell","size":100000,"price":3114.61,"timestamp":"2024-05-18T15:46:27.417Z"},{"symbol":"ETHUSDT","id":32402517483,"side":"Buy","size":116000,"price":3109.41,"timestamp":"2024-05-18T15:46:27.417Z"},{"symbol":"ETHUSDT","id":32402512804,"side":"Buy","size":100000,"price":3108.17,"timestamp":"2024-05-18T15:46:27.417Z"}]}
{"table":"orderBookL2_25","action":"insert","data":[{"symbol":"ETHUSDT","id":32402525382,"side":"Sell","size":28000,"price":3111.03,"timestamp":"2024-05-18T15:46:27.417Z"},{"symbol":"ETHUSDT","id":32402525429,"side":"Sell","size":32000,"price":3111.24,"timestamp":"2024-05-18T15:46:27.417Z"},{"symbol":"ETHUSDT","id":32402525402,"side":"Sell","size":100000,"price":3111.31,"timestamp":"2024-05-18T15:46:27.417Z"},{"symbol":"ETHUSDT","id":32402525501,"side":"Sell","size":44000,"price":3111.19,"timestamp":"2024-05-18T15:46:27.417Z"},{"symbol":"ETHUSDT","id":32402525424,"side":"Sell","size":100000,"price":3111.47,"timestamp":"2024-05-18T15:46:27.417Z"},{"symbol":"ETHUSDT","id":32402525486,"side":"Sell","size":555000,"price":3112.98,"timestamp":"2024-05-18T15:46:27.417Z"},{"symbol":"ETHUSDT","id":32402525499,"side":"Buy","size":1000,"price":3109.46,"timestamp":"2024-05-18T15:46:27.417Z"},{"symbol":"ETHUSDT","id":32402525374,"side":"Buy","size":32000,"price":3109.68,"timestamp":"2024-05-18T15:46:27.417Z"},{"symbol":"ETHUSDT","id":32402525418,"side":"Buy","size":1000,"price":3109.45,"timestamp":"2024-05-18T15:46:27.417Z"},{"symbol":"ETHUSDT","id":32402525444,"side":"Buy","size":152000,"price":3109.69,"timestamp":"2024-05-18T15:46:27.417Z"},{"symbol":"ETHUSDT","id":32402525488,"side":"Buy","size":100000,"price":3109.70,"timestamp":"2024-05-18T15:46:27.417Z"}]}
{"table":"orderBookL2_25","action":"delete","data":[{"symbol":"XBTUSDT","id":32402525440,"side":"Sell","price":66785.6,"timestamp":"2024-05-18T15:46:27.440Z"},{"symbol":"XBTUSDT","id":32402520719,"side":"Sell","price":66815.6,"timestamp":"2024-05-18T15:46:27.440Z"},{"symbol":"XBTUSDT","id":32402525129,"side":"Sell","price":66785.9,"timestamp":"2024-05-18T15:46:27.440Z"},{"symbol":"XBTUSDT","id":32402524651,"side":"Sell","price":66815.5,"timestamp":"2024-05-18T15:46:27.440Z"},{"symbol":"XBTUSDT","id":32402524011,"side":"Sell","price":66792.8,"timestamp":"2024-05-18T15:46:27.440Z"},{"symbol":"XBTUSDT","id":32402525363,"side":"Sell","price":66792.9,"timestamp":"2024-05-18T15:46:27.440Z"},{"symbol":"XBTUSDT","id":32402525434,"side":"Buy","price":66758.2,"timestamp":"2024-05-18T15:46:27.440Z"},{"symbol":"XBTUSDT","id":32402525119,"side":"Buy","price":66758.0,"timestamp":"2024-05-18T15:46:27.440Z"},{"symbol":"XBTUSDT","id":32402523898,"side":"Buy","price":66761.1,"timestamp":"2024-05-18T15:46:27.440Z"}]}
{"table":"orderBookL2_25","action":"insert","data":[{"symbol":"XBTUSDT","id":32402525454,"side":"Sell","size":3000,"price":66795.8,"timestamp":"2024-05-18T15:46:27.440Z"},{"symbol":"XBTUSDT","id":32402525574,"side":"Sell","size":20000,"price":66785.9,"timestamp":"2024-05-18T15:46:27.440Z"},{"symbol":"XBTUSDT","id":32402525588,"side":"Sell","size":20000,"price":66785.2,"timestamp":"2024-05-18T15:46:27.440Z"},{"symbol":"XBTUSDT","id":32402525581,"side":"Sell","size":1000,"price":66793.0,"timestamp":"2024-05-18T15:46:27.440Z"},{"symbol":"XBTUSDT","id":32402525557,"side":"Sell","size":1000,"price":66792.9,"timestamp":"2024-05-18T15:46:27.440Z"},{"symbol":"XBTUSDT","id":32402525517,"side":"Sell","size":20000,"price":66785.4,"timestamp":"2024-05-18T15:46:27.440Z"},{"symbol":"XBTUSDT","id":32402525511,"side":"Buy","size":93000,"price":66764.6,"timestamp":"2024-05-18T15:46:27.440Z"},{"symbol":"XBTUSDT","id":32402525586,"side":"Buy","size":20000,"price":66758.4,"timestamp":"2024-05-18T15:46:27.440Z"},{"symbol":"XBTUSDT","id":32402525583,"side":"Buy","size":20000,"price":66758.5,"timestamp":"2024-05-18T15:46:27.440Z"}]}
{"table":"orderBookL2_25","action":"delete","data":[{"symbol":"ETHUSDT","id":32402450797,"side":"Sell","price":3114.61,"timestamp":"2024-05-18T15:46:27.466Z"},{"symbol":"ETHUSDT","id":32402525115,"side":"Sell","price":3111.25,"timestamp":"2024-05-18T15:46:27.466Z"},{"symbol":"ETHUSDT","id":32402525429,"side":"Sell","price":3111.24,"timestamp":"2024-05-18T15:46:27.466Z"},{"symbol":"ETHUSDT","id":32402525418,"side":"Buy","price":3109.45,"timestamp":"2024-05-18T15:46:27.466Z"},{"symbol":"ETHUSDT","id":32402519746,"side":"Buy","price":3108.20,"timestamp":"2024-05-18T15:46:27.466Z"},{"symbol":"ETHUSDT","id":32402525374,"side":"Buy","price":3109.68,"timestamp":"2024-05-18T15:46:27.466Z"},{"symbol":"ETHUSDT","id":32402517388,"side":"Buy","price":3108.45,"timestamp":"2024-05-18T15:46:27.466Z"},{"symbol":"ETHUSDT","id":32402519342,"side":"Buy","price":3108.19,"timestamp":"2024-05-18T15:46:27.466Z"},{"symbol":"ETHUSDT","id":32402525499,"side":"Buy","price":3109.46,"timestamp":"2024-05-18T15:46:27.466Z"},{"symbol":"ETHUSDT","id":32402512804,"side":"Buy","price":3108.17,"timestamp":"2024-05-18T15:46:27.466Z"},{"symbol":"ETHUSDT","id":32402525488,"side":"Buy","price":3109.70,"timestamp":"2024-05-18T15:46:27.466Z"}]}
{"table":"orderBookL2_25","action":"update","data":[{"symbol":"ETHUSDT","id":32402525402,"side":"Sell","size":100000,"price":3111.31,"timestamp":"2024-05-18T15:46:27.466Z"},{"symbol":"ETHUSDT","id":32402517483,"side":"Buy","size":73000,"price":3109.41,"timestamp":"2024-05-18T15:46:27.466Z"},{"symbol":"ETHUSDT","id":32402525444,"side":"Buy","size":20000,"price":3109.69,"timestamp":"2024-05-18T15:46:27.466Z"}]}
{"table":"orderBookL2_25","action":"insert","data":[{"symbol":"ETHUSDT","id":32402525602,"side":"Sell","size":241000,"price":3111.69,"timestamp":"2024-05-18T15:46:27.466Z"},{"symbol":"ETHUSDT","id":32402525684,"side":"Sell","size":32000,"price":3111.34,"timestamp":"2024-05-18T15:46:27.466Z"},{"symbol":"ETHUSDT","id":32402525709,"side":"Sell","size":32000,"price":3111.33,"timestamp":"2024-05-18T15:46:27.466Z"},{"symbol":"ETHUSDT","id":32402525610,"side":"Buy","size":32000,"price":3109.85,"timestamp":"2024-05-18T15:46:27.466Z"},{"symbol":"ETHUSDT","id":32402525566,"side":"Buy","size":1000,"price":3109.62,"timestamp":"2024-05-18T15:46:27.466Z"},{"symbol":"ETHUSDT","id":32402525643,"side":"Buy","size":100000,"price":3109.54,"timestamp":"2024-05-18T15:46:27.466Z"},{"symbol":"ETHUSDT","id":32402525578,"side":"Buy","size":144000,"price":3109.71,"timestamp":"2024-05-18T15:46:27.466Z"},{"symbol":"ETHUSDT","id":32402525633,"side":"Buy","size":1000,"price":3109.63,"timestamp":"2024-05-18T15:46:27.466Z"},{"symbol":"ETHUSDT","id":32402525604,"side":"Buy","size":32000,"price":3109.86,"timestamp":"2024-05-18T15:46:27.466Z"},{"symbol":"ETHUSDT","id":32402525606,"side":"Buy","size":69000,"price":3109.36,"timestamp":"2024-05-18T15:46:27.466Z"},{"symbol":"ETHUSDT","id":32402525608,"side":"Buy","size":100000,"price":3109.73,"timestamp":"2024-05-18T15:46:27.466Z"}]}
{"table":"orderBookL2_25","action":"delete","data":[{"symbol":"XBTUSDT","id":32402525588,"side":"Sell","price":66785.2,"timestamp":"2024-05-18T15:46:27.489Z"},{"symbol":"XBTUSDT","id":32402525574,"side":"Sell","price":66785.9,"timestamp":"2024-05-18T15:46:27.489Z"},{"symbol":"XBTUSDT","id":32402525311,"side":"Sell","price":66788.6,"timestamp":"2024-05-18T15:46:27.489Z"},{"symbol":"XBTUSDT","id":32402525517,"side":"Sell","price":66785.4,"timestamp":"2024-05-18T15:46:27.489Z"},{"symbol":"XBTUSDT","id":32402510162,"side":"Buy","price":66757.5,"timestamp":"2024-05-18T15:46:27.489Z"},{"symbol":"XBTUSDT","id":32402525586,"side":"Buy","price":66758.4,"timestamp":"2024-05-18T15:46:27.489Z"},{"symbol":"XBTUSDT","id":32402525583,"side":"Buy","price":66758.5,"timestamp":"2024-05-18T15:46:27.489Z"},{"symbol":"XBTUSDT","id":32402525313,"side":"Buy","price":66752.9,"timestamp":"2024-05-18T15:46:27.489Z"}]}
{"table":"orderBookL2_25","action":"update","data":[{"symbol":"XBTUSDT","id":32402520906,"side":"Sell","size":100000,"price":66812.1,"timestamp":"2024-05-18T15:46:27.489Z"},{"symbol":"XBTUSDT","id":32402524647,"side":"Sell","size":8000,"price":66780.4,"timestamp":"2024-05-18T15:46:27.489Z"},{"symbol":"XBTUSDT","id":32402522785,"side":"Buy","size":147000,"price":66778.3,"timestamp":"2024-05-18T15:46:27.489Z"}]}
{"table":"orderBookL2_25","action":"insert","data":[{"symbol":"XBTUSDT","id":32402525786,"side":"Sell","size":2000,"price":66805.5,"timestamp":"2024-05-18T15:46:27.489Z"},{"symbol":"XBTUSDT","id":32402525791,"side":"Sell","size":20000,"price":66786.1,"timestamp":"2024-05-18T15:46:27.489Z"},{"symbol":"XBTUSDT","id":32402525771,"side":"Sell","size":20000,"price":66786.2,"timestamp":"2024-05-18T15:46:27.489Z"},{"symbol":"XBTUSDT","id":32402525782,"side":"Sell","size":350000,"price":66788.6,"timestamp":"2024-05-18T15:46:27.489Z"},{"symbol":"XBTUSDT","id":32402525761,"side":"Buy","size":20000,"price":66758.8,"timestamp":"2024-05-18T15:46:27.489Z"},{"symbol":"XBTUSDT","id":32402505864,"side":"Buy","size":100000,"price":66740.6,"timestamp":"2024-05-18T15:46:27.489Z"},{"symbol":"XBTUSDT","id":32402525776,"side":"Buy","size":359000,"price":66752.9,"timestamp":"2024-05-18T15:46:27.489Z"},{"symbol":"XBTUSDT","id":32402525789,"side":"Buy","size":20000,"price":66758.7,"timestamp":"2024-05-18T15:46:27.489Z"}]}
{"table":"orderBookL2_25","action":"delete","data":[{"symbol":"ETHUSDT","id":32402525684,"side":"Sell","price":3111.34,"timestamp":"2024-05-18T15:46:27.515Z"},{"symbol":"ETHUSDT","id":32402524337,"side":"Sell","price":3110.80,"timestamp":"2024-05-18T15:46:27.515Z"},{"symbol":"ETHUSDT","id":32402525501,"side":"Sell","price":3111.19,"timestamp":"2024-05-18T15:46:27.515Z"},{"symbol":"ETHUSDT","id":32402525604,"side":"Buy","price":3109.86,"timestamp":"2024-05-18T15:46:27.515Z"},{"symbol":"ETHUSDT","id":32402525633,"side":"Buy","price":3109.63,"timestamp":"2024-05-18T15:46:27.515Z"},{"symbol":"ETHUSDT","id":32402525610,"side":"Buy","price":3109.85,"timestamp":"2024-05-18T15:46:27.515Z"},{"symbol":"ETHUSDT","id":32402521785,"side":"Buy","price":3108.47,"timestamp":"2024-05-18T15:46:27.515Z"},{"symbol":"ETHUSDT","id":32402525566,"side":"Buy","price":3109.62,"timestamp":"2024-05-18T15:46:27.515Z"}]}
{"table":"orderBookL2_25","action":"insert","data":[{"symbol":"ETHUSDT","id":32402450797,"side":"Sell","size":100000,"price":3114.61,"timestamp":"2024-05-18T15:46:27.515Z"},{"symbol":"ETHUSDT","id":32402525757,"side":"Sell","size":32000,"price":3111.32,"timestamp":"2024-05-18T15:46:27.515Z"},{"symbol":"ETHUSDT","id":32402500495,"side":"Sell","size":17234000,"price":3115.00,"timestamp":"2024-05-18T15:46:27.515Z"},{"symbol":"ETHUSDT","id":32402525974,"side":"Buy","size":1000,"price":3109.66,"timestamp":"2024-05-18T15:46:27.515Z"},{"symbol":"ETHUSDT","id":32402525831,"side":"Buy","size":32000,"price":3109.89,"timestamp":"2024-05-18T15:46:27.515Z"},{"symbol":"ETHUSDT","id":32402525833,"side":"Buy","size":32000,"price":3109.88,"timestamp":"2024-05-18T15:46:27.515Z"},{"symbol":"ETHUSDT","id":32402525980,"side":"Buy","size":1000,"price":3109.65,"timestamp":"2024-05-18T15:46:27.515Z"},{"symbol":"ETHUSDT","id":32402525773,"side":"Buy","size":60000,"price":3109.55,"timestamp":"2024-05-18T15:46:27.515Z"}]}
{"table":"orderBookL2_25","action":"delete","data":[{"symbol":"XBTUSDT","id":32402525771,"side":"Sell","price":66786.2,"timestamp":"2024-05-18T15:46:27.538Z"},{"symbol":"XBTUSDT","id":32402525782,"side":"Sell","price":66788.6,"timestamp":"2024-05-18T15:46:27.538Z"},{"symbol":"XBTUSDT","id":32402525557,"side":"Sell","price":66792.9,"timestamp":"2024-05-18T15:46:27.538Z"},{"symbol":"XBTUSDT","id":32402525581,"side":"Sell","price":66793.0,"timestamp":"2024-05-18T15:46:27.538Z"},{"symbol":"XBTUSDT","id":32402525786,"side":"Sell","price":66805.5,"timestamp":"2024-05-18T15:46:27.538Z"},{"symbol":"XBTUSDT","id":32402525791,"side":"Sell","price":66786.1,"timestamp":"2024-05-18T15:46:27.538Z"},{"symbol":"XBTUSDT","id":32402525761,"side":"Buy","price":66758.8,"timestamp":"2024-05-18T15:46:27.538Z"},{"symbol":"XBTUSDT","id":32402525789,"side":"Buy","price":66758.7,"timestamp":"2024-05-18T15:46:27.538Z"},{"symbol":"XBTUSDT","id":32402525776,"side":"Buy","price":66752.9,"timestamp":"2024-05-18T15:46:27.538Z"},{"symbol":"XBTUSDT","id":32402505864,"side":"Buy","price":66740.6,"timestamp":"2024-05-18T15:46:27.538Z"}]}
{"table":"orderBookL2_25","action":"insert","data":[{"symbol":"XBTUSDT","id":32402525882,"side":"Sell","size":20000,"price":66788.9,"timestamp":"2024-05-18T15:46:27.538Z"},{"symbol":"XBTUSDT","id":32402525978,"side":"Sell","size":82000,"price":66788.6,"timestamp":"2024-05-18T15:46:27.538Z"},{"symbol":"XBTUSDT","id":32402525990,"side":"Sell","size":1000,"price":66796.0,"timestamp":"2024-05-18T15:46:27.538Z"},{"symbol":"XBTUSDT","id":32402524651,"side":"Sell","size":823000,"price":66815.5,"timestamp":"2024-05-18T15:46:27.538Z"},{"symbol":"XBTUSDT","id":32402525923,"side":"Sell","size":367000,"price":66792.0,"timestamp":"2024-05-18T15:46:27.538Z"},{"symbol":"XBTUSDT","id":32402526044,"side":"Sell","size":1000,"price":66796.1,"timestamp":"2024-05-18T15:46:27.538Z"},{"symbol":"XBTUSDT","id":32402525918,"side":"Buy","size":362000,"price":66754.3,"timestamp":"2024-05-18T15:46:27.538Z"},{"symbol":"XBTUSDT","id":32402525953,"side":"Buy","size":20000,"price":66759.0,"timestamp":"2024-05-18T15:46:27.538Z"},{"symbol":"XBTUSDT","id":32402525894,"side":"Buy","size":20000,"price":66742.0,"timestamp":"2024-05-18T15:46:27.538Z"},{"symbol":"XBTUSDT","id":32402526031,"side":"Buy","size":20000,"price":66759.1,"timestamp":"2024-05-18T15:46:27.538Z"}]}
{"table":"orderBookL2_25","action":"delete","data":[{"symbol":"ETHUSDT","id":32402525757,"side":"Sell","price":3111.32,"timestamp":"2024-05-18T15:46:27.572Z"},{"symbol":"ETHUSDT","id":32402524392,"side":"Buy","price":3108.48,"timestamp":"2024-05-18T15:46:27.572Z"},{"symbol":"ETHUSDT","id":32402525833,"side":"Buy","price":3109.88,"timestamp":"2024-05-18T15:46:27.572Z"}]}
{"table":"orderBookL2_25","action":"insert","data":[{"symbol":"ETHUSDT","id":32402526021,"side":"Sell","size":32000,"price":3111.34,"timestamp":"2024-05-18T15:46:27.572Z"},{"symbol":"ETHUSDT","id":32402526006,"side":"Buy","size":32000,"price":3109.90,"timestamp":"2024-05-18T15:46:27.572Z"},{"symbol":"ETHUSDT","id":32402526017,"side":"Buy","size":517000,"price":3109.10,"timestamp":"2024-05-18T15:46:27.572Z"}]}
{"table":"orderBookL2_25","action":"delete","data":[{"symbol":"XBTUSDT","id":32402525882,"side":"Sell","price":66788.9,"timestamp":"2024-05-18T15:46:27.587Z"},{"symbol":"XBTUSDT","id":32402525978,"side":"Sell","price":66788.6,"timestamp":"2024-05-18T15:46:27.587Z"},{"symbol":"XBTUSDT","id":32402525990,"side":"Sell","price":66796.0,"timestamp":"2024-05-18T15:46:27.587Z"},{"symbol":"XBTUSDT","id":32402525338,"side":"Sell","price":66795.4,"timestamp":"2024-05-18T15:46:27.587Z"},{"symbol":"XBTUSDT","id":32402526044,"side":"Sell","price":66796.1,"timestamp":"2024-05-18T15:46:27.587Z"},{"symbol":"XBTUSDT","id":32402526031,"side":"Buy","price":66759.1,"timestamp":"2024-05-18T15:46:27.587Z"},{"symbol":"XBTUSDT","id":32402525953,"side":"Buy","price":66759.0,"timestamp":"2024-05-18T15:46:27.587Z"}]}
{"table":"orderBookL2_25","action":"update","data":[{"symbol":"XBTUSDT","id":32402524651,"side":"Sell","size":823000,"price":66815.5,"timestamp":"2024-05-18T15:46:27.587Z"},{"symbol":"XBTUSDT","id":32402499271,"side":"Sell","size":100000,"price":66788.7,"timestamp":"2024-05-18T15:46:27.587Z"}]}
{"table":"orderBookL2_25","action":"insert","data":[{"symbol":"XBTUSDT","id":32402526143,"side":"Sell","size":20000,"price":66787.7,"timestamp":"2024-05-18T15:46:27.587Z"},{"symbol":"XBTUSDT","id":32402526094,"side":"Sell","size":20000,"price":66789.1,"timestamp":"2024-05-18T15:46:27.587Z"},{"symbol":"XBTUSDT","id":32402526122,"side":"Sell","size":20000,"price":66789.2,"timestamp":"2024-05-18T15:46:27.587Z"},{"symbol":"XBTUSDT","id":32402526066,"side":"Sell","size":1000,"price":66796.4,"timestamp":"2024-05-18T15:46:27.587Z"},{"symbol":"XBTUSDT","id":32402526133,"side":"Sell","size":1000,"price":66796.3,"timestamp":"2024-05-18T15:46:27.587Z"},{"symbol":"XBTUSDT","id":32402526117,"side":"Buy","size":20000,"price":66760.2,"timestamp":"2024-05-18T15:46:27.587Z"},{"symbol":"XBTUSDT","id":32402526101,"side":"Buy","size":20000,"price":66760.1,"timestamp":"2024-05-18T15:46:27.587Z"}]}
{"table":"orderBookL2_25","action":"delete","data":[{"symbol":"ETHUSDT","id":32402525974,"side":"Buy","price":3109.66,"timestamp":"2024-05-18T15:46:27.622Z"}]}
{"table":"orderBookL2_25","action":"update","data":[{"symbol":"ETHUSDT","id":32402525402,"side":"Sell","size":144000,"price":3111.31,"timestamp":"2024-05-18T15:46:27.622Z"}]}
{"table":"orderBookL2_25","action":"insert","data":[{"symbol":"ETHUSDT","id":32402526224,"side":"Buy","size":1000,"price":3109.66,"timestamp":"2024-05-18T15:46:27.622Z"}]}
{"table":"orderBookL2_25","action":"delete","data":[{"symbol":"XBTUSDT","id":32402526143,"side":"Sell","price":66787.7,"timestamp":"2024-05-18T15:46:27.636Z"},{"symbol":"XBTUSDT","id":32402526133,"side":"Sell","price":66796.3,"timestamp":"2024-05-18T15:46:27.636Z"},{"symbol":"XBTUSDT","id":32402522829,"side":"Buy","price":66770.9,"timestamp":"2024-05-18T15:46:27.636Z"}]}
{"table":"orderBookL2_25","action":"update","data":[{"symbol":"XBTUSDT","id":32402505821,"side":"Buy","size":113000,"price":66764.4,"timestamp":"2024-05-18T15:46:27.636Z"}]}
{"table":"orderBookL2_25","action":"insert","data":[{"symbol":"XBTUSDT","id":32402526247,"side":"Sell","size":1000,"price":66796.3,"timestamp":"2024-05-18T15:46:27.636Z"},{"symbol":"XBTUSDT","id":32402520719,"side":"Sell","size":1348000,"price":66815.6,"timestamp":"2024-05-18T15:46:27.636Z"},{"symbol":"XBTUSDT","id":32402526206,"side":"Buy","size":20000,"price":66777.2,"timestamp":"2024-05-18T15:46:27.636Z"}]}
{"table":"orderBookL2_25","action":"delete","data":[{"symbol":"ETHUSDT","id":32402525709,"side":"Sell","price":3111.33,"timestamp":"2024-05-18T15:46:27.671Z"}]}
{"table":"orderBookL2_25","action":"insert","data":[{"symbol":"ETHUSDT","id":32402526312,"side":"Sell","size":32000,"price":3111.35,"timestamp":"2024-05-18T15:46:27.671Z"}]}
{"table":"orderBookL2_25","action":"delete","data":[{"symbol":"XBTUSDT","id":32402526247,"side":"Sell","price":66796.3,"timestamp":"2024-05-18T15:46:27.685Z"}]}
{"table":"orderBookL2_25","action":"insert","data":[{"symbol":"XBTUSDT","id":32402526332,"side":"Sell","size":1000,"price":66796.5,"timestamp":"2024-05-18T15:46:27.685Z"}]}
{"table":"orderBookL2_25","action":"delete","data":[{"symbol":"ETHUSDT","id":32402524328,"side":"Sell","price":3110.67,"timestamp":"2024-05-18T15:46:27.720Z"},{"symbol":"ETHUSDT","id":32402526312,"side":"Sell","price":3111.35,"timestamp":"2024-05-18T15:46:27.720Z"},{"symbol":"ETHUSDT","id":32402525831,"side":"Buy","price":3109.89,"timestamp":"2024-05-18T15:46:27.720Z"}]}
{"table":"orderBookL2_25","action":"update","data":[{"symbol":"ETHUSDT","id":32402500495,"side":"Sell","size":17234000,"price":3115.00,"timestamp":"2024-05-18T15:46:27.720Z"}]}
{"table":"orderBookL2_25","action":"insert","data":[{"symbol":"ETHUSDT","id":32402526393,"side":"Sell","size":32000,"price":3111.33,"timestamp":"2024-05-18T15:46:27.720Z"},{"symbol":"ETHUSDT","id":32402526396,"side":"Sell","size":21000,"price":3110.66,"timestamp":"2024-05-18T15:46:27.720Z"},{"symbol":"ETHUSDT","id":32402526390,"side":"Buy","size":32000,"price":3109.89,"timestamp":"2024-05-18T15:46:27.720Z"}]}
{"table":"orderBookL2_25","action":"delete","data":[{"symbol":"XBTUSDT","id":32402520719,"side":"Sell","price":66815.6,"timestamp":"2024-05-18T15:46:27.734Z"}]}
{"table":"orderBookL2_25","action":"insert","data":[{"symbol":"XBTUSDT","id":32402526365,"side":"Sell","size":20000,"price":66794.2,"timestamp":"2024-05-18T15:46:27.734Z"}]}
{"table":"orderBookL2_25","action":"delete","data":[{"symbol":"ETHUSDT","id":32402526393,"side":"Sell","price":3111.33,"timestamp":"2024-05-18T15:46:27.769Z"},{"symbol":"ETHUSDT","id":32402500495,"side":"Sell","price":3115.00,"timestamp":"2024-05-18T15:46:27.769Z"},{"symbol":"ETHUSDT","id":32402526390,"side":"Buy","price":3109.89,"timestamp":"2024-05-18T15:46:27.769Z"}]}
{"table":"orderBookL2_25","action":"insert","data":[{"symbol":"ETHUSDT","id":32402526420,"side":"Sell","size":48000,"price":3111.92,"timestamp":"2024-05-18T15:46:27.769Z"},{"symbol":"ETHUSDT","id":32402526448,"side":"Sell","size":32000,"price":3111.35,"timestamp":"2024-05-18T15:46:27.769Z"},{"symbol":"ETHUSDT","id":32402526446,"side":"Buy","size":32000,"price":3109.91,"timestamp":"2024-05-18T15:46:27.769Z"}]}
{"table":"orderBookL2_25","action":"delete","data":[{"symbol":"XBTUSDT","id":32402524651,"side":"Sell","price":66815.5,"timestamp":"2024-05-18T15:46:27.783Z"},{"symbol":"XBTUSDT","id":32402525894,"side":"Buy","price":66742.0,"timestamp":"2024-05-18T15:46:27.783Z"}]}
{"table":"orderBookL2_25","action":"update","data":[{"symbol":"XBTUSDT","id":32402523767,"side":"Buy","size":8000,"price":66771.6,"timestamp":"2024-05-18T15:46:27.783Z"},{"symbol":"XBTUSDT","id":32402522611,"side":"Buy","size":20000,"price":66764.5,"timestamp":"2024-05-18T15:46:27.783Z"},{"symbol":"XBTUSDT","id":32402523325,"side":"Buy","size":100000,"price":66771.5,"timestamp":"2024-05-18T15:46:27.783Z"}]}
{"table":"orderBookL2_25","action":"insert","data":[{"symbol":"XBTUSDT","id":32402526458,"side":"Sell","size":63000,"price":66788.6,"timestamp":"2024-05-18T15:46:27.783Z"},{"symbol":"XBTUSDT","id":32402526442,"side":"Buy","size":16000,"price":66777.3,"timestamp":"2024-05-18T15:46:27.783Z"}]}
{"table":"orderBookL2_25","action":"delete","data":[{"symbol":"ETHUSDT","id":32402526448,"side":"Sell","price":3111.35,"timestamp":"2024-05-18T15:46:27.818Z"},{"symbol":"ETHUSDT","id":32402524422,"side":"Sell","price":3111.43,"timestamp":"2024-05-18T15:46:27.818Z"},{"symbol":"ETHUSDT","id":32402521006,"side":"Sell","price":3111.44,"timestamp":"2024-05-18T15:46:27.818Z"},{"symbol":"ETHUSDT","id":32402526021,"side":"Sell","price":3111.34,"timestamp":"2024-05-18T15:46:27.818Z"},{"symbol":"ETHUSDT","id":32402450797,"side":"Sell","price":3114.61,"timestamp":"2024-05-18T15:46:27.818Z"},{"symbol":"ETHUSDT","id":32402526446,"side":"Buy","price":3109.91,"timestamp":"2024-05-18T15:46:27.818Z"},{"symbol":"ETHUSDT","id":32402525980,"side":"Buy","price":3109.65,"timestamp":"2024-05-18T15:46:27.818Z"}]}
{"table":"orderBookL2_25","action":"update","data":[{"symbol":"ETHUSDT","id":32402441505,"side":"Sell","size":100000,"price":3113.30,"timestamp":"2024-05-18T15:46:27.818Z"},{"symbol":"ETHUSDT","id":32402486025,"side":"Sell","size":337000,"price":3111.72,"timestamp":"2024-05-18T15:46:27.818Z"},{"symbol":"ETHUSDT","id":32402525402,"side":"Sell","size":44000,"price":3111.31,"timestamp":"2024-05-18T15:46:27.818Z"}]}
{"table":"orderBookL2_25","action":"insert","data":[{"symbol":"ETHUSDT","id":32402526652,"side":"Sell","size":1000,"price":3114.00,"timestamp":"2024-05-18T15:46:27.818Z"},{"symbol":"ETHUSDT","id":32402526645,"side":"Sell","size":2300000,"price":3112.06,"timestamp":"2024-05-18T15:46:27.818Z"},{"symbol":"ETHUSDT","id":32402526675,"side":"Sell","size":32000,"price":3111.36,"timestamp":"2024-05-18T15:46:27.818Z"},{"symbol":"ETHUSDT","id":32402526694,"side":"Sell","size":32000,"price":3111.37,"timestamp":"2024-05-18T15:46:27.818Z"},{"symbol":"ETHUSDT","id":32402526692,"side":"Sell","size":942000,"price":3112.52,"timestamp":"2024-05-18T15:46:27.818Z"},{"symbol":"ETHUSDT","id":32402526574,"side":"Buy","size":1000,"price":3109.67,"timestamp":"2024-05-18T15:46:27.818Z"},{"symbol":"ETHUSDT","id":32402526689,"side":"Buy","size":32000,"price":3109.91,"timestamp":"2024-05-18T15:46:27.818Z"}]}
{"table":"orderBookL2_25","action":"delete","data":[{"symbol":"XBTUSDT","id":32402525107,"side":"Sell","price":66798.4,"timestamp":"2024-05-18T15:46:27.833Z"},{"symbol":"XBTUSDT","id":32402522382,"side":"Sell","price":66783.2,"timestamp":"2024-05-18T15:46:27.833Z"},{"symbol":"XBTUSDT","id":32402522515,"side":"Sell","price":66778.4,"timestamp":"2024-05-18T15:46:27.833Z"},{"symbol":"XBTUSDT","id":32402525923,"side":"Sell","price":66792.0,"timestamp":"2024-05-18T15:46:27.833Z"},{"symbol":"XBTUSDT","id":32402524868,"side":"Sell","price":66784.2,"timestamp":"2024-05-18T15:46:27.833Z"},{"symbol":"XBTUSDT","id":32402502861,"side":"Sell","price":66784.3,"timestamp":"2024-05-18T15:46:27.833Z"},{"symbol":"XBTUSDT","id":32402524656,"side":"Sell","price":66797.1,"timestamp":"2024-05-18T15:46:27.833Z"},{"symbol":"XBTUSDT","id":32402517625,"side":"Buy","price":66744.0,"timestamp":"2024-05-18T15:46:27.833Z"},{"symbol":"XBTUSDT","id":32402508983,"side":"Buy","price":66747.5,"timestamp":"2024-05-18T15:46:27.833Z"},{"symbol":"XBTUSDT","id":32402523902,"side":"Buy","price":66747.6,"timestamp":"2024-05-18T15:46:27.833Z"},{"symbol":"XBTUSDT","id":32402525918,"side":"Buy","price":66754.3,"timestamp":"2024-05-18T15:46:27.833Z"}]}
{"table":"orderBookL2_25","action":"update","data":[{"symbol":"XBTUSDT","id":32402522785,"side":"Buy","size":247000,"price":66778.3,"timestamp":"2024-05-18T15:46:27.833Z"}]}
{"table":"orderBookL2_25","action":"insert","data":[{"symbol":"XBTUSDT","id":32402520719,"side":"Sell","size":1348000,"price":66815.6,"timestamp":"2024-05-18T15:46:27.833Z"},{"symbol":"XBTUSDT","id":32402461579,"side":"Sell","size":100000,"price":66815.7,"timestamp":"2024-05-18T15:46:27.833Z"},{"symbol":"XBTUSDT","id":32402526603,"side":"Sell","size":3000,"price":66800.5,"timestamp":"2024-05-18T15:46:27.833Z"},{"symbol":"XBTUSDT","id":32402526543,"side":"Sell","size":380000,"price":66795.4,"timestamp":"2024-05-18T15:46:27.833Z"},{"symbol":"XBTUSDT","id":32402526626,"side":"Sell","size":100000,"price":66785.2,"timestamp":"2024-05-18T15:46:27.833Z"},{"symbol":"XBTUSDT","id":32402524651,"side":"Sell","size":823000,"price":66815.5,"timestamp":"2024-05-18T15:46:27.833Z"},{"symbol":"XBTUSDT","id":32402526058,"side":"Sell","size":15000,"price":66822.0,"timestamp":"2024-05-18T15:46:27.833Z"},{"symbol":"XBTUSDT","id":32402526668,"side":"Buy","size":357000,"price":66757.7,"timestamp":"2024-05-18T15:46:27.833Z"},{"symbol":"XBTUSDT","id":32402526719,"side":"Buy","size":18000,"price":66751.0,"timestamp":"2024-05-18T15:46:27.833Z"},{"symbol":"XBTUSDT","id":32402526723,"side":"Buy","size":20000,"price":66752.0,"timestamp":"2024-05-18T15:46:27.833Z"},{"symbol":"XBTUSDT","id":32402526711,"side":"Buy","size":39000,"price":66780.3,"timestamp":"2024-05-18T15:46:27.833Z"}]}
{"table":"orderBookL2_25","action":"delete","data":[{"symbol":"ETHUSDT","id":32402526420,"side":"Sell","price":3111.92,"timestamp":"2024-05-18T15:46:27.867Z"},{"symbol":"ETHUSDT","id":32402526006,"side":"Buy","price":3109.90,"timestamp":"2024-05-18T15:46:27.867Z"},{"symbol":"ETHUSDT","id":32402517960,"side":"Buy","price":3108.61,"timestamp":"2024-05-18T15:46:27.867Z"},{"symbol":"ETHUSDT","id":32402526574,"side":"Buy","price":3109.67,"timestamp":"2024-05-18T15:46:27.867Z"},{"symbol":"ETHUSDT","id":32402526689,"side":"Buy","price":3109.91,"timestamp":"2024-05-18T15:46:27.867Z"},{"symbol":"ETHUSDT","id":32402526224,"side":"Buy","price":3109.66,"timestamp":"2024-05-18T15:46:27.867Z"}]}
{"table":"orderBookL2_25","action":"update","data":[{"symbol":"ETHUSDT","id":32402358267,"side":"Sell","size":100000,"price":3114.29,"timestamp":"2024-05-18T15:46:27.867Z"},{"symbol":"ETHUSDT","id":32402525578,"side":"Buy","size":44000,"price":3109.71,"timestamp":"2024-05-18T15:46:27.867Z"}]}
{"table":"orderBookL2_25","action":"insert","data":[{"symbol":"ETHUSDT","id":32402526885,"side":"Sell","size":160000,"price":3112.10,"timestamp":"2024-05-18T15:46:27.867Z"},{"symbol":"ETHUSDT","id":32402526841,"side":"Buy","size":100000,"price":3109.92,"timestamp":"2024-05-18T15:46:27.867Z"},{"symbol":"ETHUSDT","id":32402526908,"side":"Buy","size":1000,"price":3109.78,"timestamp":"2024-05-18T15:46:27.867Z"},{"symbol":"ETHUSDT","id":32402526889,"side":"Buy","size":32000,"price":3110.00,"timestamp":"2024-05-18T15:46:27.867Z"},{"symbol":"ETHUSDT","id":32402526865,"side":"Buy","size":1000,"price":3109.77,"timestamp":"2024-05-18T15:46:27.867Z"},{"symbol":"ETHUSDT","id":32402526887,"side":"Buy","size":32000,"price":3110.01,"timestamp":"2024-05-18T15:46:27.867Z"}]}
{"table":"orderBookL2_25","action":"delete","data":[{"symbol":"XBTUSDT","id":32402526066,"side":"Sell","price":66796.4,"timestamp":"2024-05-18T15:46:27.882Z"},{"symbol":"XBTUSDT","id":32402526626,"side":"Sell","price":66785.2,"timestamp":"2024-05-18T15:46:27.882Z"},{"symbol":"XBTUSDT","id":32402526332,"side":"Sell","price":66796.5,"timestamp":"2024-05-18T15:46:27.882Z"},{"symbol":"XBTUSDT","id":32402526122,"side":"Sell","price":66789.2,"timestamp":"2024-05-18T15:46:27.882Z"},{"symbol":"XBTUSDT","id":32402524647,"side":"Sell","price":66780.4,"timestamp":"2024-05-18T15:46:27.882Z"},{"symbol":"XBTUSDT","id":32402502112,"side":"Sell","price":66800.6,"timestamp":"2024-05-18T15:46:27.882Z"},{"symbol":"XBTUSDT","id":32402526094,"side":"Sell","price":66789.1,"timestamp":"2024-05-18T15:46:27.882Z"},{"symbol":"XBTUSDT","id":32402522956,"side":"Buy","price":66767.6,"timestamp":"2024-05-18T15:46:27.882Z"},{"symbol":"XBTUSDT","id":32402526723,"side":"Buy","price":66752.0,"timestamp":"2024-05-18T15:46:27.882Z"},{"symbol":"XBTUSDT","id":32402526117,"side":"Buy","price":66760.2,"timestamp":"2024-05-18T15:46:27.882Z"},{"symbol":"XBTUSDT","id":32402526101,"side":"Buy","price":66760.1,"timestamp":"2024-05-18T15:46:27.882Z"},{"symbol":"XBTUSDT","id":32402526719,"side":"Buy","price":66751.0,"timestamp":"2024-05-18T15:46:27.882Z"}]}
{"table":"orderBookL2_25","action":"update","data":[{"symbol":"XBTUSDT","id":32402526458,"side":"Sell","size":163000,"price":66788.6,"timestamp":"2024-05-18T15:46:27.882Z"},{"symbol":"XBTUSDT","id":32402522450,"side":"Sell","size":160000,"price":66797.2,"timestamp":"2024-05-18T15:46:27.882Z"},{"symbol":"XBTUSDT","id":32402507589,"side":"Buy","size":100000,"price":66750.8,"timestamp":"2024-05-18T15:46:27.882Z"},{"symbol":"XBTUSDT","id":32402522785,"side":"Buy","size":216000,"price":66778.3,"timestamp":"2024-05-18T15:46:27.882Z"},{"symbol":"XBTUSDT","id":32402526711,"side":"Buy","size":188000,"price":66780.3,"timestamp":"2024-05-18T15:46:27.882Z"}]}
{"table":"orderBookL2_25","action":"insert","data":[{"symbol":"XBTUSDT","id":32402526922,"side":"Sell","size":20000,"price":66789.8,"timestamp":"2024-05-18T15:46:27.882Z"},{"symbol":"XBTUSDT","id":32402521481,"side":"Sell","size":643000,"price":66825.6,"timestamp":"2024-05-18T15:46:27.882Z"},{"symbol":"XBTUSDT","id":32402242406,"side":"Sell","size":138000,"price":66822.2,"timestamp":"2024-05-18T15:46:27.882Z"},{"symbol":"XBTUSDT","id":32402526931,"side":"Sell","size":20000,"price":66789.9,"timestamp":"2024-05-18T15:46:27.882Z"},{"symbol":"XBTUSDT","id":32402526929,"side":"Sell","size":1000,"price":66797.1,"timestamp":"2024-05-18T15:46:27.882Z"},{"symbol":"XBTUSDT","id":32402516652,"side":"Sell","size":417000,"price":66826.5,"timestamp":"2024-05-18T15:46:27.882Z"},{"symbol":"XBTUSDT","id":32402526534,"side":"Sell","size":650000,"price":66825.5,"timestamp":"2024-05-18T15:46:27.882Z"},{"symbol":"XBTUSDT","id":32402526894,"side":"Buy","size":100000,"price":66785.1,"timestamp":"2024-05-18T15:46:27.882Z"},{"symbol":"XBTUSDT","id":32402526795,"side":"Buy","size":20000,"price":66753.5,"timestamp":"2024-05-18T15:46:27.882Z"},{"symbol":"XBTUSDT","id":32402526935,"side":"Buy","size":20000,"price":66762.9,"timestamp":"2024-05-18T15:46:27.882Z"},{"symbol":"XBTUSDT","id":32402526946,"side":"Buy","size":24000,"price":66788.5,"timestamp":"2024-05-18T15:46:27.882Z"},{"symbol":"XBTUSDT","id":32402526953,"side":"Buy","size":20000,"price":66762.8,"timestamp":"2024-05-18T15:46:27.882Z"}]}
{"table":"orderBookL2_25","action":"delete","data":[{"symbol":"ETHUSDT","id":32402526694,"side":"Sell","price":3111.37,"timestamp":"2024-05-18T15:46:27.916Z"},{"symbol":"ETHUSDT","id":32402526675,"side":"Sell","price":3111.36,"timestamp":"2024-05-18T15:46:27.916Z"},{"symbol":"ETHUSDT","id":32402526396,"side":"Sell","price":3110.66,"timestamp":"2024-05-18T15:46:27.916Z"},{"symbol":"ETHUSDT","id":32402526889,"side":"Buy","price":3110.00,"timestamp":"2024-05-18T15:46:27.916Z"},{"symbol":"ETHUSDT","id":32402526865,"side":"Buy","price":3109.77,"timestamp":"2024-05-18T15:46:27.916Z"},{"symbol":"ETHUSDT","id":32402525578,"side":"Buy","price":3109.71,"timestamp":"2024-05-18T15:46:27.916Z"},{"symbol":"ETHUSDT","id":32402526908,"side":"Buy","price":3109.78,"timestamp":"2024-05-18T15:46:27.916Z"},{"symbol":"ETHUSDT","id":32402526887,"side":"Buy","price":3110.01,"timestamp":"2024-05-18T15:46:27.916Z"}]}
{"table":"orderBookL2_25","action":"update","data":[{"symbol":"ETHUSDT","id":32402526652,"side":"Sell","size":1000,"price":3114.00,"timestamp":"2024-05-18T15:46:27.916Z"},{"symbol":"ETHUSDT","id":32402358267,"side":"Sell","size":100000,"price":3114.29,"timestamp":"2024-05-18T15:46:27.916Z"}]}
{"table":"orderBookL2_25","action":"insert","data":[{"symbol":"ETHUSDT","id":32402527113,"side":"Sell","size":21000,"price":3110.65,"timestamp":"2024-05-18T15:46:27.916Z"},{"symbol":"ETHUSDT","id":32402527136,"side":"Sell","size":32000,"price":3111.52,"timestamp":"2024-05-18T15:46:27.916Z"},{"symbol":"ETHUSDT","id":32402527041,"side":"Sell","size":32000,"price":3111.46,"timestamp":"2024-05-18T15:46:27.916Z"},{"symbol":"ETHUSDT","id":32402527138,"side":"Buy","size":1000,"price":3109.85,"timestamp":"2024-05-18T15:46:27.916Z"},{"symbol":"ETHUSDT","id":32402527111,"side":"Buy","size":44000,"price":3110.03,"timestamp":"2024-05-18T15:46:27.916Z"},{"symbol":"ETHUSDT","id":32402527123,"side":"Buy","size":32000,"price":3110.05,"timestamp":"2024-05-18T15:46:27.916Z"},{"symbol":"ETHUSDT","id":32402527098,"side":"Buy","size":32000,"price":3110.06,"timestamp":"2024-05-18T15:46:27.916Z"},{"symbol":"ETHUSDT","id":32402527130,"side":"Buy","size":1000,"price":3109.86,"timestamp":"2024-05-18T15:46:27.916Z"}]}
{"table":"orderBookL2_25","action":"delete","data":[{"symbol":"XBTUSDT","id":32402525454,"side":"Sell","price":66795.8,"timestamp":"2024-05-18T15:46:27.931Z"},{"symbol":"XBTUSDT","id":32402520719,"side":"Sell","price":66815.6,"timestamp":"2024-05-18T15:46:27.931Z"},{"symbol":"XBTUSDT","id":32402526922,"side":"Sell","price":66789.8,"timestamp":"2024-05-18T15:46:27.931Z"},{"symbol":"XBTUSDT","id":32402524651,"side":"Sell","price":66815.5,"timestamp":"2024-05-18T15:46:27.931Z"},{"symbol":"XBTUSDT","id":32402526931,"side":"Sell","price":66789.9,"timestamp":"2024-05-18T15:46:27.931Z"},{"symbol":"XBTUSDT","id":32402522857,"side":"Sell","price":66800.3,"timestamp":"2024-05-18T15:46:27.931Z"},{"symbol":"XBTUSDT","id":32402526929,"side":"Sell","price":66797.1,"timestamp":"2024-05-18T15:46:27.931Z"},{"symbol":"XBTUSDT","id":32402526953,"side":"Buy","price":66762.8,"timestamp":"2024-05-18T15:46:27.931Z"},{"symbol":"XBTUSDT","id":32402526795,"side":"Buy","price":66753.5,"timestamp":"2024-05-18T15:46:27.931Z"},{"symbol":"XBTUSDT","id":32402521460,"side":"Buy","price":66752.7,"timestamp":"2024-05-18T15:46:27.931Z"},{"symbol":"XBTUSDT","id":32402526935,"side":"Buy","price":66762.9,"timestamp":"2024-05-18T15:46:27.931Z"},{"symbol":"XBTUSDT","id":32402524654,"side":"Buy","price":66752.8,"timestamp":"2024-05-18T15:46:27.931Z"}]}
{"table":"orderBookL2_25","action":"update","data":[{"symbol":"XBTUSDT","id":32402521481,"side":"Sell","size":100000,"price":66825.6,"timestamp":"2024-05-18T15:46:27.931Z"},{"symbol":"XBTUSDT","id":32402522450,"side":"Sell","size":159000,"price":66797.2,"timestamp":"2024-05-18T15:46:27.931Z"},{"symbol":"XBTUSDT","id":32402522611,"side":"Buy","size":40000,"price":66764.5,"timestamp":"2024-05-18T15:46:27.931Z"},{"symbol":"XBTUSDT","id":32402526711,"side":"Buy","size":140000,"price":66780.3,"timestamp":"2024-05-18T15:46:27.931Z"},{"symbol":"XBTUSDT","id":32402505821,"side":"Buy","size":133000,"price":66764.4,"timestamp":"2024-05-18T15:46:27.931Z"},{"symbol":"XBTUSDT","id":32402525511,"side":"Buy","size":93000,"price":66764.6,"timestamp":"2024-05-18T15:46:27.931Z"},{"symbol":"XBTUSDT","id":32402526946,"side":"Buy","size":72000,"price":66788.5,"timestamp":"2024-05-18T15:46:27.931Z"},{"symbol":"XBTUSDT","id":32402522785,"side":"Buy","size":116000,"price":66778.3,"timestamp":"2024-05-18T15:46:27.931Z"}]}
{"table":"orderBookL2_25","action":"insert","data":[{"symbol":"XBTUSDT","id":32402441693,"side":"Sell","size":100000,"price":66829.0,"timestamp":"2024-05-18T15:46:27.931Z"},{"symbol":"XBTUSDT","id":32402527195,"side":"Sell","size":20000,"price":66791.4,"timestamp":"2024-05-18T15:46:27.931Z"},{"symbol":"XBTUSDT","id":32402527025,"side":"Sell","size":3000,"price":66798.4,"timestamp":"2024-05-18T15:46:27.931Z"},{"symbol":"XBTUSDT","id":32402527009,"side":"Sell","size":543000,"price":66810.5,"timestamp":"2024-05-18T15:46:27.931Z"},{"symbol":"XBTUSDT","id":32402527144,"side":"Sell","size":20000,"price":66791.3,"timestamp":"2024-05-18T15:46:27.931Z"},{"symbol":"XBTUSDT","id":32402527091,"side":"Sell","size":1000,"price":66798.6,"timestamp":"2024-05-18T15:46:27.931Z"},{"symbol":"XBTUSDT","id":32402527076,"side":"Sell","size":1000,"price":66798.5,"timestamp":"2024-05-18T15:46:27.931Z"},{"symbol":"XBTUSDT","id":32402527063,"side":"Buy","size":100000,"price":66781.7,"timestamp":"2024-05-18T15:46:27.931Z"},{"symbol":"XBTUSDT","id":32402527005,"side":"Buy","size":442000,"price":66766.3,"timestamp":"2024-05-18T15:46:27.931Z"},{"symbol":"XBTUSDT","id":32402527127,"side":"Buy","size":35000,"price":66777.9,"timestamp":"2024-05-18T15:46:27.931Z"},{"symbol":"XBTUSDT","id":32402508983,"side":"Buy","size":22000,"price":66747.5,"timestamp":"2024-05-18T15:46:27.931Z"},{"symbol":"XBTUSDT","id":32402523902,"side":"Buy","size":156000,"price":66747.6,"timestamp":"2024-05-18T15:46:27.931Z"}]}
{"table":"orderBookL2_25","action":"delete","data":[{"symbol":"ETHUSDT","id":32402527041,"side":"Sell","price":3111.46,"timestamp":"2024-05-18T15:46:27.965Z"},{"symbol":"ETHUSDT","id":32402525402,"side":"Sell","price":3111.31,"timestamp":"2024-05-18T15:46:27.965Z"},{"symbol":"ETHUSDT","id":32402527136,"side":"Sell","price":3111.52,"timestamp":"2024-05-18T15:46:27.965Z"},{"symbol":"ETHUSDT","id":32402527123,"side":"Buy","price":3110.05,"timestamp":"2024-05-18T15:46:27.965Z"},{"symbol":"ETHUSDT","id":32402527098,"side":"Buy","price":3110.06,"timestamp":"2024-05-18T15:46:27.965Z"}]}
{"table":"orderBookL2_25","action":"insert","data":[{"symbol":"ETHUSDT","id":32402527206,"side":"Sell","size":32000,"price":3111.56,"timestamp":"2024-05-18T15:46:27.965Z"},{"symbol":"ETHUSDT","id":32402527208,"side":"Sell","size":32000,"price":3111.55,"timestamp":"2024-05-18T15:46:27.965Z"},{"symbol":"ETHUSDT","id":32402527257,"side":"Sell","size":44000,"price":3111.49,"timestamp":"2024-05-18T15:46:27.965Z"},{"symbol":"ETHUSDT","id":32402527197,"side":"Buy","size":32000,"price":3110.09,"timestamp":"2024-05-18T15:46:27.965Z"},{"symbol":"ETHUSDT","id":32402527255,"side":"Buy","size":32000,"price":3110.10,"timestamp":"2024-05-18T15:46:27.965Z"}]}
{"table":"orderBookL2_25","action":"delete","data":[{"symbol":"XBTUSDT","id":32402527195,"side":"Sell","price":66791.4,"timestamp":"2024-05-18T15:46:27.980Z"},{"symbol":"XBTUSDT","id":32402527144,"side":"Sell","price":66791.3,"timestamp":"2024-05-18T15:46:27.980Z"},{"symbol":"XBTUSDT","id":32402516652,"side":"Sell","price":66826.5,"timestamp":"2024-05-18T15:46:27.980Z"},{"symbol":"XBTUSDT","id":32402527091,"side":"Sell","price":66798.6,"timestamp":"2024-05-18T15:46:27.980Z"},{"symbol":"XBTUSDT","id":32402508983,"side":"Buy","price":66747.5,"timestamp":"2024-05-18T15:46:27.980Z"}]}
{"table":"orderBookL2_25","action":"update","data":[{"symbol":"XBTUSDT","id":32402441693,"side":"Sell","size":100000,"price":66829.0,"timestamp":"2024-05-18T15:46:27.980Z"},{"symbol":"XBTUSDT","id":32402527025,"side":"Sell","size":4000,"price":66798.4,"timestamp":"2024-05-18T15:46:27.980Z"},{"symbol":"XBTUSDT","id":32402505821,"side":"Buy","size":113000,"price":66764.4,"timestamp":"2024-05-18T15:46:27.980Z"},{"symbol":"XBTUSDT","id":32402525511,"side":"Buy","size":113000,"price":66764.6,"timestamp":"2024-05-18T15:46:27.980Z"}]}
{"table":"orderBookL2_25","action":"insert","data":[{"symbol":"XBTUSDT","id":32402430543,"side":"Sell","size":100000,"price":66832.4,"timestamp":"2024-05-18T15:46:27.980Z"},{"symbol":"XBTUSDT","id":32402527252,"side":"Sell","size":20000,"price":66791.1,"timestamp":"2024-05-18T15:46:27.980Z"},{"symbol":"XBTUSDT","id":32402527219,"side":"Sell","size":176000,"price":66791.2,"timestamp":"2024-05-18T15:46:27.980Z"},{"symbol":"XBTUSDT","id":32402527007,"side":"Sell","size":1348000,"price":66833.8,"timestamp":"2024-05-18T15:46:27.980Z"},{"symbol":"XBTUSDT","id":32402527274,"side":"Buy","size":11000,"price":66776.2,"timestamp":"2024-05-18T15:46:27.980Z"}]}
{"table":"orderBookL2_25","action":"delete","data":[{"symbol":"ETHUSDT","id":32402525444,"side":"Buy","price":3109.69,"timestamp":"2024-05-18T15:46:28.014Z"},{"symbol":"ETHUSDT","id":32402527255,"side":"Buy","price":3110.10,"timestamp":"2024-05-18T15:46:28.014Z"},{"symbol":"ETHUSDT","id":32402527138,"side":"Buy","price":3109.85,"timestamp":"2024-05-18T15:46:28.014Z"},{"symbol":"ETHUSDT","id":32402527130,"side":"Buy","price":3109.86,"timestamp":"2024-05-18T15:46:28.014Z"},{"symbol":"ETHUSDT","id":32402527197,"side":"Buy","price":3110.09,"timestamp":"2024-05-18T15:46:28.014Z"}]}
{"table":"orderBookL2_25","action":"insert","data":[{"symbol":"ETHUSDT","id":32402527291,"side":"Buy","size":1000,"price":3109.84,"timestamp":"2024-05-18T15:46:28.014Z"},{"symbol":"ETHUSDT","id":32402527322,"side":"Buy","size":32000,"price":3110.08,"timestamp":"2024-05-18T15:46:28.014Z"},{"symbol":"ETHUSDT","id":32402527324,"side":"Buy","size":1000,"price":3109.85,"timestamp":"2024-05-18T15:46:28.014Z"},{"symbol":"ETHUSDT","id":32402517960,"side":"Buy","size":100000,"price":3108.61,"timestamp":"2024-05-18T15:46:28.014Z"},{"symbol":"ETHUSDT","id":32402527299,"side":"Buy","size":32000,"price":3110.07,"timestamp":"2024-05-18T15:46:28.014Z"}]}
{"table":"orderBookL2_25","action":"delete","data":[{"symbol":"XBTUSDT","id":32402526365,"side":"Sell","price":66794.2,"timestamp":"2024-05-18T15:46:28.029Z"},{"symbol":"XBTUSDT","id":32402430543,"side":"Sell","price":66832.4,"timestamp":"2024-05-18T15:46:28.029Z"},{"symbol":"XBTUSDT","id":32402527252,"side":"Sell","price":66791.1,"timestamp":"2024-05-18T15:46:28.029Z"},{"symbol":"XBTUSDT","id":32402527076,"side":"Sell","price":66798.5,"timestamp":"2024-05-18T15:46:28.029Z"},{"symbol":"XBTUSDT","id":32402527007,"side":"Sell","price":66833.8,"timestamp":"2024-05-18T15:46:28.029Z"},{"symbol":"XBTUSDT","id":32402523767,"side":"Buy","price":66771.6,"timestamp":"2024-05-18T15:46:28.029Z"},{"symbol":"XBTUSDT","id":32402525279,"side":"Buy","price":66775.0,"timestamp":"2024-05-18T15:46:28.029Z"},{"symbol":"XBTUSDT","id":32402527063,"side":"Buy","price":66781.7,"timestamp":"2024-05-18T15:46:28.029Z"}]}
{"table":"orderBookL2_25","action":"update","data":[{"symbol":"XBTUSDT","id":32402441693,"side":"Sell","size":100000,"price":66829.0,"timestamp":"2024-05-18T15:46:28.029Z"},{"symbol":"XBTUSDT","id":32402527025,"side":"Sell","size":3000,"price":66798.4,"timestamp":"2024-05-18T15:46:28.029Z"},{"symbol":"XBTUSDT","id":32402527219,"side":"Sell","size":156000,"price":66791.2,"timestamp":"2024-05-18T15:46:28.029Z"},{"symbol":"XBTUSDT","id":32402505821,"side":"Buy","size":113000,"price":66764.4,"timestamp":"2024-05-18T15:46:28.029Z"},{"symbol":"XBTUSDT","id":32402525511,"side":"Buy","size":113000,"price":66764.6,"timestamp":"2024-05-18T15:46:28.029Z"},{"symbol":"XBTUSDT","id":32402526946,"side":"Buy","size":88000,"price":66788.5,"timestamp":"2024-05-18T15:46:28.029Z"}]}
{"table":"orderBookL2_25","action":"insert","data":[{"symbol":"XBTUSDT","id":32402527302,"side":"Sell","size":20000,"price":66791.4,"timestamp":"2024-05-18T15:46:28.029Z"},{"symbol":"XBTUSDT","id":32402527313,"side":"Sell","size":2000,"price":66812.5,"timestamp":"2024-05-18T15:46:28.029Z"},{"symbol":"XBTUSDT","id":32402527297,"side":"Sell","size":1000,"price":66798.7,"timestamp":"2024-05-18T15:46:28.029Z"},{"symbol":"XBTUSDT","id":32402527295,"side":"Sell","size":1000,"price":66798.6,"timestamp":"2024-05-18T15:46:28.029Z"},{"symbol":"XBTUSDT","id":32402527307,"side":"Sell","size":20000,"price":66791.5,"timestamp":"2024-05-18T15:46:28.029Z"},{"symbol":"XBTUSDT","id":32402527003,"side":"Buy","size":1348000,"price":66742.9,"timestamp":"2024-05-18T15:46:28.029Z"},{"symbol":"XBTUSDT","id":32402517625,"side":"Buy","size":100000,"price":66744.0,"timestamp":"2024-05-18T15:46:28.029Z"},{"symbol":"XBTUSDT","id":32402508983,"side":"Buy","size":22000,"price":66747.5,"timestamp":"2024-05-18T15:46:28.029Z"}]}
{"table":"orderBookL2_25","action":"delete","data":[{"symbol":"ETHUSDT","id":32402527206,"side":"Sell","price":3111.56,"timestamp":"2024-05-18T15:46:28.063Z"},{"symbol":"ETHUSDT","id":32402527322,"side":"Buy","price":3110.08,"timestamp":"2024-05-18T15:46:28.063Z"},{"symbol":"ETHUSDT","id":32402527299,"side":"Buy","price":3110.07,"timestamp":"2024-05-18T15:46:28.063Z"}]}
{"table":"orderBookL2_25","action":"insert","data":[{"symbol":"ETHUSDT","id":32402527387,"side":"Sell","size":32000,"price":3111.56,"timestamp":"2024-05-18T15:46:28.063Z"},{"symbol":"ETHUSDT","id":32402527392,"side":"Buy","size":32000,"price":3110.10,"timestamp":"2024-05-18T15:46:28.063Z"},{"symbol":"ETHUSDT","id":32402527347,"side":"Buy","size":32000,"price":3110.09,"timestamp":"2024-05-18T15:46:28.063Z"}]}
{"table":"orderBookL2_25","action":"delete","data":[{"symbol":"XBTUSDT","id":32402527297,"side":"Sell","price":66798.7,"timestamp":"2024-05-18T15:46:28.078Z"},{"symbol":"XBTUSDT","id":32402527313,"side":"Sell","price":66812.5,"timestamp":"2024-05-18T15:46:28.078Z"},{"symbol":"XBTUSDT","id":32402527307,"side":"Sell","price":66791.5,"timestamp":"2024-05-18T15:46:28.078Z"}]}
{"table":"orderBookL2_25","action":"insert","data":[{"symbol":"XBTUSDT","id":32402527420,"side":"Sell","size":1000,"price":66798.7,"timestamp":"2024-05-18T15:46:28.078Z"},{"symbol":"XBTUSDT","id":32402527382,"side":"Sell","size":20000,"price":66791.3,"timestamp":"2024-05-18T15:46:28.078Z"},{"symbol":"XBTUSDT","id":32402527367,"side":"Sell","size":2000,"price":66807.5,"timestamp":"2024-05-18T15:46:28.078Z"}]}
{"table":"orderBookL2_25","action":"delete","data":[{"symbol":"ETHUSDT","id":32402527387,"side":"Sell","price":3111.56,"timestamp":"2024-05-18T15:46:28.112Z"},{"symbol":"ETHUSDT","id":32402525382,"side":"Sell","price":3111.03,"timestamp":"2024-05-18T15:46:28.112Z"},{"symbol":"ETHUSDT","id":32402527113,"side":"Sell","price":3110.65,"timestamp":"2024-05-18T15:46:28.112Z"},{"symbol":"ETHUSDT","id":32402527392,"side":"Buy","price":3110.10,"timestamp":"2024-05-18T15:46:28.112Z"},{"symbol":"ETHUSDT","id":32402525773,"side":"Buy","price":3109.55,"timestamp":"2024-05-18T15:46:28.112Z"}]}
{"table":"orderBookL2_25","action":"update","data":[{"symbol":"ETHUSDT","id":32402358267,"side":"Sell","size":100000,"price":3114.29,"timestamp":"2024-05-18T15:46:28.112Z"},{"symbol":"ETHUSDT","id":32402517960,"side":"Buy","size":100000,"price":3108.61,"timestamp":"2024-05-18T15:46:28.112Z"}]}
{"table":"orderBookL2_25","action":"insert","data":[{"symbol":"ETHUSDT","id":32402450797,"side":"Sell","size":100000,"price":3114.61,"timestamp":"2024-05-18T15:46:28.112Z"},{"symbol":"ETHUSDT","id":32402527452,"side":"Sell","size":32000,"price":3111.54,"timestamp":"2024-05-18T15:46:28.112Z"},{"symbol":"ETHUSDT","id":32402527441,"side":"Sell","size":21000,"price":3110.64,"timestamp":"2024-05-18T15:46:28.112Z"},{"symbol":"ETHUSDT","id":32402527439,"side":"Buy","size":32000,"price":3110.10,"timestamp":"2024-05-18T15:46:28.112Z"},{"symbol":"ETHUSDT","id":32402527443,"side":"Buy","size":61000,"price":3109.74,"timestamp":"2024-05-18T15:46:28.112Z"}]}
{"table":"orderBookL2_25","action":"delete","data":[{"symbol":"XBTUSDT","id":32402527420,"side":"Sell","price":66798.7,"timestamp":"2024-05-18T15:46:28.127Z"},{"symbol":"XBTUSDT","id":32402441693,"side":"Sell","price":66829.0,"timestamp":"2024-05-18T15:46:28.127Z"},{"symbol":"XBTUSDT","id":32402526894,"side":"Buy","price":66785.1,"timestamp":"2024-05-18T15:46:28.127Z"},{"symbol":"XBTUSDT","id":32402526711,"side":"Buy","price":66780.3,"timestamp":"2024-05-18T15:46:28.127Z"}]}
{"table":"orderBookL2_25","action":"update","data":[{"symbol":"XBTUSDT","id":32402526458,"side":"Sell","size":203000,"price":66788.6,"timestamp":"2024-05-18T15:46:28.127Z"},{"symbol":"XBTUSDT","id":32402525511,"side":"Buy","size":20000,"price":66764.6,"timestamp":"2024-05-18T15:46:28.127Z"}]}
{"table":"orderBookL2_25","action":"insert","data":[{"symbol":"XBTUSDT","id":32402527485,"side":"Sell","size":1000,"price":66798.7,"timestamp":"2024-05-18T15:46:28.127Z"},{"symbol":"XBTUSDT","id":32402527469,"side":"Sell","size":20000,"price":66793.9,"timestamp":"2024-05-18T15:46:28.127Z"},{"symbol":"XBTUSDT","id":32402505864,"side":"Buy","size":100000,"price":66740.6,"timestamp":"2024-05-18T15:46:28.127Z"},{"symbol":"XBTUSDT","id":32402527481,"side":"Buy","size":270000,"price":66766.4,"timestamp":"2024-05-18T15:46:28.127Z"}]}
{"table":"orderBookL2_25","action":"delete","data":[{"symbol":"ETHUSDT","id":32402450797,"side":"Sell","price":3114.61,"timestamp":"2024-05-18T15:46:28.161Z"},{"symbol":"ETHUSDT","id":32402527452,"side":"Sell","price":3111.54,"timestamp":"2024-05-18T15:46:28.161Z"},{"symbol":"ETHUSDT","id":32402527347,"side":"Buy","price":3110.09,"timestamp":"2024-05-18T15:46:28.161Z"},{"symbol":"ETHUSDT","id":32402527324,"side":"Buy","price":3109.85,"timestamp":"2024-05-18T15:46:28.161Z"},{"symbol":"ETHUSDT","id":32402527439,"side":"Buy","price":3110.10,"timestamp":"2024-05-18T15:46:28.161Z"}]}
{"table":"orderBookL2_25","action":"insert","data":[{"symbol":"ETHUSDT","id":32402527578,"side":"Sell","size":32000,"price":3111.56,"timestamp":"2024-05-18T15:46:28.161Z"},{"symbol":"ETHUSDT","id":32402527535,"side":"Sell","size":28000,"price":3111.00,"timestamp":"2024-05-18T15:46:28.161Z"},{"symbol":"ETHUSDT","id":32402527548,"side":"Buy","size":1000,"price":3109.83,"timestamp":"2024-05-18T15:46:28.161Z"},{"symbol":"ETHUSDT","id":32402527526,"side":"Buy","size":32000,"price":3110.08,"timestamp":"2024-05-18T15:46:28.161Z"},{"symbol":"ETHUSDT","id":32402527571,"side":"Buy","size":32000,"price":3110.07,"timestamp":"2024-05-18T15:46:28.161Z"}]}
{"table":"orderBookL2_25","action":"delete","data":[{"symbol":"XBTUSDT","id":32402527295,"side":"Sell","price":66798.6,"timestamp":"2024-05-18T15:46:28.176Z"},{"symbol":"XBTUSDT","id":32402527382,"side":"Sell","price":66791.3,"timestamp":"2024-05-18T15:46:28.176Z"},{"symbol":"XBTUSDT","id":32402525511,"side":"Buy","price":66764.6,"timestamp":"2024-05-18T15:46:28.176Z"}]}
{"table":"orderBookL2_25","action":"update","data":[{"symbol":"XBTUSDT","id":32402526458,"side":"Sell","size":307000,"price":66788.6,"timestamp":"2024-05-18T15:46:28.176Z"},{"symbol":"XBTUSDT","id":32402522611,"side":"Buy","size":20000,"price":66764.5,"timestamp":"2024-05-18T15:46:28.176Z"},{"symbol":"XBTUSDT","id":32402505821,"side":"Buy","size":133000,"price":66764.4,"timestamp":"2024-05-18T15:46:28.176Z"}]}
{"table":"orderBookL2_25","action":"insert","data":[{"symbol":"XBTUSDT","id":32402527556,"side":"Sell","size":20000,"price":66791.5,"timestamp":"2024-05-18T15:46:28.176Z"},{"symbol":"XBTUSDT","id":32402527592,"side":"Sell","size":1000,"price":66798.8,"timestamp":"2024-05-18T15:46:28.176Z"},{"symbol":"XBTUSDT","id":32402514918,"side":"Buy","size":388000,"price":66737.4,"timestamp":"2024-05-18T15:46:28.176Z"}]}
{"table":"orderBookL2_25","action":"delete","data":[{"symbol":"ETHUSDT","id":32402527578,"side":"Sell","price":3111.56,"timestamp":"2024-05-18T15:46:28.210Z"},{"symbol":"ETHUSDT","id":32402527571,"side":"Buy","price":3110.07,"timestamp":"2024-05-18T15:46:28.210Z"}]}
{"table":"orderBookL2_25","action":"insert","data":[{"symbol":"ETHUSDT","id":32402527614,"side":"Sell","size":32000,"price":3111.54,"timestamp":"2024-05-18T15:46:28.210Z"},{"symbol":"ETHUSDT","id":32402527616,"side":"Buy","size":32000,"price":3110.09,"timestamp":"2024-05-18T15:46:28.210Z"}]}
{"table":"orderBookL2_25","action":"delete","data":[{"symbol":"XBTUSDT","id":32402521481,"side":"Sell","price":66825.6,"timestamp":"2024-05-18T15:46:28.254Z"}]}
{"table":"orderBookL2_25","action":"insert","data":[{"symbol":"XBTUSDT","id":32402527689,"side":"Sell","size":101000,"price":66791.1,"timestamp":"2024-05-18T15:46:28.254Z"}]}
{"table":"orderBookL2_25","action":"delete","data":[{"symbol":"ETHUSDT","id":32402358267,"side":"Sell","price":3114.29,"timestamp":"2024-05-18T15:46:28.259Z"}]}
{"table":"orderBookL2_25","action":"insert","data":[{"symbol":"ETHUSDT","id":32402527654,"side":"Sell","size":48000,"price":3112.01,"timestamp":"2024-05-18T15:46:28.259Z"}]}
{"table":"orderBookL2_25","action":"delete","data":[{"symbol":"XBTUSDT","id":32402526534,"side":"Sell","price":66825.5,"timestamp":"2024-05-18T15:46:28.303Z"},{"symbol":"XBTUSDT","id":32402242406,"side":"Sell","price":66822.2,"timestamp":"2024-05-18T15:46:28.303Z"},{"symbol":"XBTUSDT","id":32402527592,"side":"Sell","price":66798.8,"timestamp":"2024-05-18T15:46:28.303Z"},{"symbol":"XBTUSDT","id":32402526543,"side":"Sell","price":66795.4,"timestamp":"2024-05-18T15:46:28.303Z"},{"symbol":"XBTUSDT","id":32402526442,"side":"Buy","price":66777.3,"timestamp":"2024-05-18T15:46:28.303Z"}]}
{"table":"orderBookL2_25","action":"update","data":[{"symbol":"XBTUSDT","id":32402526058,"side":"Sell","size":15000,"price":66822.0,"timestamp":"2024-05-18T15:46:28.303Z"},{"symbol":"XBTUSDT","id":32402514918,"side":"Buy","size":388000,"price":66737.4,"timestamp":"2024-05-18T15:46:28.303Z"}]}
{"table":"orderBookL2_25","action":"insert","data":[{"symbol":"XBTUSDT","id":32402527737,"side":"Sell","size":95000,"price":66797.1,"timestamp":"2024-05-18T15:46:28.303Z"},{"symbol":"XBTUSDT","id":32402527716,"side":"Sell","size":74000,"price":66797.3,"timestamp":"2024-05-18T15:46:28.303Z"},{"symbol":"XBTUSDT","id":32402527730,"side":"Sell","size":363000,"price":66793.8,"timestamp":"2024-05-18T15:46:28.303Z"},{"symbol":"XBTUSDT","id":32402527742,"side":"Sell","size":1000,"price":66798.6,"timestamp":"2024-05-18T15:46:28.303Z"},{"symbol":"XBTUSDT","id":32402527721,"side":"Buy","size":16000,"price":66778.0,"timestamp":"2024-05-18T15:46:28.303Z"}]}
{"table":"orderBookL2_25","action":"delete","data":[{"symbol":"ETHUSDT","id":32402526652,"side":"Sell","price":3114.00,"timestamp":"2024-05-18T15:46:28.308Z"},{"symbol":"ETHUSDT","id":32402527614,"side":"Sell","price":3111.54,"timestamp":"2024-05-18T15:46:28.308Z"},{"symbol":"ETHUSDT","id":32402527441,"side":"Sell","price":3110.64,"timestamp":"2024-05-18T15:46:28.308Z"},{"symbol":"ETHUSDT","id":32402527616,"side":"Buy","price":3110.09,"timestamp":"2024-05-18T15:46:28.308Z"},{"symbol":"ETHUSDT","id":32402527548,"side":"Buy","price":3109.83,"timestamp":"2024-05-18T15:46:28.308Z"},{"symbol":"ETHUSDT","id":32402512570,"side":"Buy","price":3108.81,"timestamp":"2024-05-18T15:46:28.308Z"}]}
{"table":"orderBookL2_25","action":"insert","data":[{"symbol":"ETHUSDT","id":32402527746,"side":"Sell","size":32000,"price":3111.54,"timestamp":"2024-05-18T15:46:28.308Z"},{"symbol":"ETHUSDT","id":32402527714,"side":"Sell","size":21000,"price":3110.63,"timestamp":"2024-05-18T15:46:28.308Z"},{"symbol":"ETHUSDT","id":32402527723,"side":"Sell","size":24000,"price":3111.51,"timestamp":"2024-05-18T15:46:28.308Z"},{"symbol":"ETHUSDT","id":32402527748,"side":"Buy","size":32000,"price":3110.09,"timestamp":"2024-05-18T15:46:28.308Z"},{"symbol":"ETHUSDT","id":32402524392,"side":"Buy","size":119000,"price":3108.48,"timestamp":"2024-05-18T15:46:28.308Z"},{"symbol":"ETHUSDT","id":32402527744,"side":"Buy","size":1000,"price":3109.85,"timestamp":"2024-05-18T15:46:28.308Z"}]}
{"table":"orderBookL2_25","action":"delete","data":[{"symbol":"XBTUSDT","id":32402527742,"side":"Sell","price":66798.6,"timestamp":"2024-05-18T15:46:28.352Z"},{"symbol":"XBTUSDT","id":32402526603,"side":"Sell","price":66800.5,"timestamp":"2024-05-18T15:46:28.352Z"}]}
{"table":"orderBookL2_25","action":"insert","data":[{"symbol":"XBTUSDT","id":32402527754,"side":"Sell","size":3000,"price":66802.9,"timestamp":"2024-05-18T15:46:28.352Z"},{"symbol":"XBTUSDT","id":32402527789,"side":"Sell","size":1000,"price":66798.8,"timestamp":"2024-05-18T15:46:28.352Z"}]}
{"table":"orderBookL2_25","action":"delete","data":[{"symbol":"ETHUSDT","id":32402441505,"side":"Sell","price":3113.30,"timestamp":"2024-05-18T15:46:28.357Z"},{"symbol":"ETHUSDT","id":32402524392,"side":"Buy","price":3108.48,"timestamp":"2024-05-18T15:46:28.357Z"},{"symbol":"ETHUSDT","id":32402527744,"side":"Buy","price":3109.85,"timestamp":"2024-05-18T15:46:28.357Z"},{"symbol":"ETHUSDT","id":32402527748,"side":"Buy","price":3110.09,"timestamp":"2024-05-18T15:46:28.357Z"}]}
{"table":"orderBookL2_25","action":"insert","data":[{"symbol":"ETHUSDT","id":32402527791,"side":"Sell","size":195000,"price":3110.80,"timestamp":"2024-05-18T15:46:28.357Z"},{"symbol":"ETHUSDT","id":32402527787,"side":"Buy","size":1000,"price":3109.83,"timestamp":"2024-05-18T15:46:28.357Z"},{"symbol":"ETHUSDT","id":32402527793,"side":"Buy","size":62000,"price":3108.62,"timestamp":"2024-05-18T15:46:28.357Z"},{"symbol":"ETHUSDT","id":32402527796,"side":"Buy","size":32000,"price":3110.07,"timestamp":"2024-05-18T15:46:28.357Z"}]}
{"table":"orderBookL2_25","action":"delete","data":[{"symbol":"XBTUSDT","id":32402527025,"side":"Sell","price":66798.4,"timestamp":"2024-05-18T15:46:28.401Z"},{"symbol":"XBTUSDT","id":32402527689,"side":"Sell","price":66791.1,"timestamp":"2024-05-18T15:46:28.401Z"},{"symbol":"XBTUSDT","id":32402527219,"side":"Sell","price":66791.2,"timestamp":"2024-05-18T15:46:28.401Z"},{"symbol":"XBTUSDT","id":32402527730,"side":"Sell","price":66793.8,"timestamp":"2024-05-18T15:46:28.401Z"},{"symbol":"XBTUSDT","id":32402526668,"side":"Buy","price":66757.7,"timestamp":"2024-05-18T15:46:28.401Z"}]}
{"table":"orderBookL2_25","action":"update","data":[{"symbol":"XBTUSDT","id":32402526058,"side":"Sell","size":15000,"price":66822.0,"timestamp":"2024-05-18T15:46:28.401Z"},{"symbol":"XBTUSDT","id":32402526458,"side":"Sell","size":308000,"price":66788.6,"timestamp":"2024-05-18T15:46:28.401Z"}]}
{"table":"orderBookL2_25","action":"insert","data":[{"symbol":"XBTUSDT","id":32402527909,"side":"Sell","size":156000,"price":66791.0,"timestamp":"2024-05-18T15:46:28.401Z"},{"symbol":"XBTUSDT","id":32402242406,"side":"Sell","size":138000,"price":66822.2,"timestamp":"2024-05-18T15:46:28.401Z"},{"symbol":"XBTUSDT","id":32402527894,"side":"Sell","size":364000,"price":66793.8,"timestamp":"2024-05-18T15:46:28.401Z"},{"symbol":"XBTUSDT","id":32402527907,"side":"Sell","size":3000,"price":66794.2,"timestamp":"2024-05-18T15:46:28.401Z"},{"symbol":"XBTUSDT","id":32402527877,"side":"Buy","size":349000,"price":66757.7,"timestamp":"2024-05-18T15:46:28.401Z"}]}
{"table":"orderBookL2_25","action":"delete","data":[{"symbol":"ETHUSDT","id":32402527746,"side":"Sell","price":3111.54,"timestamp":"2024-05-18T15:46:28.406Z"},{"symbol":"ETHUSDT","id":32402447682,"side":"Sell","price":3112.68,"timestamp":"2024-05-18T15:46:28.406Z"},{"symbol":"ETHUSDT","id":32402527714,"side":"Sell","price":3110.63,"timestamp":"2024-05-18T15:46:28.406Z"},{"symbol":"ETHUSDT","id":32402520893,"side":"Buy","price":3109.09,"timestamp":"2024-05-18T15:46:28.406Z"},{"symbol":"ETHUSDT","id":32402527787,"side":"Buy","price":3109.83,"timestamp":"2024-05-18T15:46:28.406Z"},{"symbol":"ETHUSDT","id":32402527796,"side":"Buy","price":3110.07,"timestamp":"2024-05-18T15:46:28.406Z"}]}
{"table":"orderBookL2_25","action":"update","data":[{"symbol":"ETHUSDT","id":32402476053,"side":"Sell","size":100000,"price":3113.00,"timestamp":"2024-05-18T15:46:28.406Z"}]}
{"table":"orderBookL2_25","action":"insert","data":[{"symbol":"ETHUSDT","id":32402527882,"side":"Sell","size":32000,"price":3111.56,"timestamp":"2024-05-18T15:46:28.406Z"},{"symbol":"ETHUSDT","id":32402527875,"side":"Sell","size":21000,"price":3110.62,"timestamp":"2024-05-18T15:46:28.406Z"},{"symbol":"ETHUSDT","id":32402527836,"side":"Sell","size":100000,"price":3112.66,"timestamp":"2024-05-18T15:46:28.406Z"},{"symbol":"ETHUSDT","id":32402527840,"side":"Buy","size":100000,"price":3109.19,"timestamp":"2024-05-18T15:46:28.406Z"},{"symbol":"ETHUSDT","id":32402527914,"side":"Buy","size":1000,"price":3109.85,"timestamp":"2024-05-18T15:46:28.406Z"},{"symbol":"ETHUSDT","id":32402527859,"side":"Buy","size":32000,"price":3110.07,"timestamp":"2024-05-18T15:46:28.406Z"}]}
{"table":"orderBookL2_25","action":"delete","data":[{"symbol":"XBTETH","id":32402513671,"side":"Sell","price":21.483,"timestamp":"2024-05-18T15:46:28.431Z"}]}
{"table":"orderBookL2_25","action":"insert","data":[{"symbol":"XBTETH","id":32402518403,"side":"Sell","size":7,"price":22.169,"timestamp":"2024-05-18T15:46:28.431Z"}]}
{"table":"orderBookL2_25","action":"delete","data":[{"symbol":"ETHUSDT","id":32402515823,"side":"Buy","price":3108.78,"timestamp":"2024-05-18T15:46:28.462Z"}]}
{"table":"orderBookL2_25","action":"insert","data":[{"symbol":"ETHUSDT","id":32402524392,"side":"Buy","size":119000,"price":3108.48,"timestamp":"2024-05-18T15:46:28.462Z"}]}
{"table":"orderBookL2_25","action":"delete","data":[{"symbol":"XBTUSDT","id":32402527789,"side":"Sell","price":66798.8,"timestamp":"2024-05-18T15:46:28.480Z"}]}
{"table":"orderBookL2_25","action":"insert","data":[{"symbol":"XBTUSDT","id":32402528002,"side":"Sell","size":1000,"price":66798.6,"timestamp":"2024-05-18T15:46:28.480Z"}]}
{"table":"orderBookL2_25","action":"delete","data":[{"symbol":"ETHUSDT","id":32402525486,"side":"Sell","price":3112.98,"timestamp":"2024-05-18T15:46:28.511Z"},{"symbol":"ETHUSDT","id":32402527882,"side":"Sell","price":3111.56,"timestamp":"2024-05-18T15:46:28.511Z"},{"symbol":"ETHUSDT","id":32402476053,"side":"Sell","price":3113.00,"timestamp":"2024-05-18T15:46:28.511Z"},{"symbol":"ETHUSDT","id":32402527859,"side":"Buy","price":3110.07,"timestamp":"2024-05-18T15:46:28.511Z"},{"symbol":"ETHUSDT","id":32402527914,"side":"Buy","price":3109.85,"timestamp":"2024-05-18T15:46:28.511Z"}]}
{"table":"orderBookL2_25","action":"insert","data":[{"symbol":"ETHUSDT","id":32402527976,"side":"Sell","size":1237000,"price":3112.05,"timestamp":"2024-05-18T15:46:28.511Z"},{"symbol":"ETHUSDT","id":32402528069,"side":"Sell","size":32000,"price":3111.54,"timestamp":"2024-05-18T15:46:28.511Z"},{"symbol":"ETHUSDT","id":32402527980,"side":"Sell","size":67000,"price":3111.46,"timestamp":"2024-05-18T15:46:28.511Z"},{"symbol":"ETHUSDT","id":32402528047,"side":"Buy","size":32000,"price":3110.09,"timestamp":"2024-05-18T15:46:28.511Z"},{"symbol":"ETHUSDT","id":32402528006,"side":"Buy","size":1000,"price":3109.85,"timestamp":"2024-05-18T15:46:28.511Z"}]}
{"table":"orderBookL2_25","action":"delete","data":[{"symbol":"XBTUSDT","id":32402527556,"side":"Sell","price":66791.5,"timestamp":"2024-05-18T15:46:28.529Z"}]}
{"table":"orderBookL2_25","action":"update","data":[{"symbol":"XBTUSDT","id":32402522785,"side":"Buy","size":16000,"price":66778.3,"timestamp":"2024-05-18T15:46:28.529Z"},{"symbol":"XBTUSDT","id":32402514918,"side":"Buy","size":388000,"price":66737.4,"timestamp":"2024-05-18T15:46:28.529Z"},{"symbol":"XBTUSDT","id":32402505821,"side":"Buy","size":133000,"price":66764.4,"timestamp":"2024-05-18T15:46:28.529Z"}]}
{"table":"orderBookL2_25","action":"insert","data":[{"symbol":"XBTUSDT","id":32402528116,"side":"Sell","size":20000,"price":66791.5,"timestamp":"2024-05-18T15:46:28.529Z"}]}
{"table":"orderBookL2_25","action":"delete","data":[{"symbol":"ETHUSDT","id":32402527875,"side":"Sell","price":3110.62,"timestamp":"2024-05-18T15:46:28.560Z"},{"symbol":"ETHUSDT","id":32402527980,"side":"Sell","price":3111.46,"timestamp":"2024-05-18T15:46:28.560Z"},{"symbol":"ETHUSDT","id":32402528069,"side":"Sell","price":3111.54,"timestamp":"2024-05-18T15:46:28.560Z"},{"symbol":"ETHUSDT","id":32402525424,"side":"Sell","price":3111.47,"timestamp":"2024-05-18T15:46:28.560Z"},{"symbol":"ETHUSDT","id":32402487305,"side":"Sell","price":3111.65,"timestamp":"2024-05-18T15:46:28.560Z"},{"symbol":"ETHUSDT","id":32402528047,"side":"Buy","price":3110.09,"timestamp":"2024-05-18T15:46:28.560Z"},{"symbol":"ETHUSDT","id":32402524392,"side":"Buy","price":3108.48,"timestamp":"2024-05-18T15:46:28.560Z"},{"symbol":"ETHUSDT","id":32402527291,"side":"Buy","price":3109.84,"timestamp":"2024-05-18T15:46:28.560Z"},{"symbol":"ETHUSDT","id":32402528006,"side":"Buy","price":3109.85,"timestamp":"2024-05-18T15:46:28.560Z"}]}
{"table":"orderBookL2_25","action":"update","data":[{"symbol":"ETHUSDT","id":32402470274,"side":"Sell","size":100000,"price":3112.84,"timestamp":"2024-05-18T15:46:28.560Z"}]}
{"table":"orderBookL2_25","action":"insert","data":[{"symbol":"ETHUSDT","id":32402528262,"side":"Sell","size":100000,"price":3111.57,"timestamp":"2024-05-18T15:46:28.560Z"},{"symbol":"ETHUSDT","id":32402476053,"side":"Sell","size":100000,"price":3113.00,"timestamp":"2024-05-18T15:46:28.560Z"},{"symbol":"ETHUSDT","id":32402528241,"side":"Sell","size":21000,"price":3110.61,"timestamp":"2024-05-18T15:46:28.560Z"},{"symbol":"ETHUSDT","id":32402525486,"side":"Sell","size":555000,"price":3112.98,"timestamp":"2024-05-18T15:46:28.560Z"},{"symbol":"ETHUSDT","id":32402528239,"side":"Sell","size":32000,"price":3111.56,"timestamp":"2024-05-18T15:46:28.560Z"},{"symbol":"ETHUSDT","id":32402528255,"side":"Buy","size":32000,"price":3110.09,"timestamp":"2024-05-18T15:46:28.560Z"},{"symbol":"ETHUSDT","id":32402528181,"side":"Buy","size":1000,"price":3109.83,"timestamp":"2024-05-18T15:46:28.560Z"},{"symbol":"ETHUSDT","id":32402528244,"side":"Buy","size":24000,"price":3109.91,"timestamp":"2024-05-18T15:46:28.560Z"},{"symbol":"ETHUSDT","id":32402528249,"side":"Buy","size":1000,"price":3109.84,"timestamp":"2024-05-18T15:46:28.560Z"}]}
{"table":"orderBookL2_25","action":"delete","data":[{"symbol":"XBTUSDT","id":32402527302,"side":"Sell","price":66791.4,"timestamp":"2024-05-18T15:46:28.578Z"},{"symbol":"XBTUSDT","id":32402528116,"side":"Sell","price":66791.5,"timestamp":"2024-05-18T15:46:28.578Z"},{"symbol":"XBTUSDT","id":32402528002,"side":"Sell","price":66798.6,"timestamp":"2024-05-18T15:46:28.578Z"},{"symbol":"XBTUSDT","id":32402527367,"side":"Sell","price":66807.5,"timestamp":"2024-05-18T15:46:28.578Z"},{"symbol":"XBTUSDT","id":32402527894,"side":"Sell","price":66793.8,"timestamp":"2024-05-18T15:46:28.578Z"},{"symbol":"XBTUSDT","id":32402527485,"side":"Sell","price":66798.7,"timestamp":"2024-05-18T15:46:28.578Z"},{"symbol":"XBTUSDT","id":32402514918,"side":"Buy","price":66737.4,"timestamp":"2024-05-18T15:46:28.578Z"},{"symbol":"XBTUSDT","id":32402522611,"side":"Buy","price":66764.5,"timestamp":"2024-05-18T15:46:28.578Z"},{"symbol":"XBTUSDT","id":32402527877,"side":"Buy","price":66757.7,"timestamp":"2024-05-18T15:46:28.578Z"}]}
{"table":"orderBookL2_25","action":"update","data":[{"symbol":"XBTUSDT","id":32402521872,"side":"Sell","size":538000,"price":66799.4,"timestamp":"2024-05-18T15:46:28.578Z"},{"symbol":"XBTUSDT","id":32402522785,"side":"Buy","size":116000,"price":66778.3,"timestamp":"2024-05-18T15:46:28.578Z"},{"symbol":"XBTUSDT","id":32402505821,"side":"Buy","size":113000,"price":66764.4,"timestamp":"2024-05-18T15:46:28.578Z"}]}
{"table":"orderBookL2_25","action":"insert","data":[{"symbol":"XBTUSDT","id":32402528299,"side":"Sell","size":20000,"price":66791.7,"timestamp":"2024-05-18T15:46:28.578Z"},{"symbol":"XBTUSDT","id":32402527732,"side":"Sell","size":650000,"price":66825.5,"timestamp":"2024-05-18T15:46:28.578Z"},{"symbol":"XBTUSDT","id":32402528295,"side":"Sell","size":20000,"price":66791.6,"timestamp":"2024-05-18T15:46:28.578Z"},{"symbol":"XBTUSDT","id":32402528266,"side":"Sell","size":1000,"price":66798.9,"timestamp":"2024-05-18T15:46:28.578Z"},{"symbol":"XBTUSDT","id":32402528264,"side":"Sell","size":351000,"price":66792.0,"timestamp":"2024-05-18T15:46:28.578Z"},{"symbol":"XBTUSDT","id":32402528229,"side":"Sell","size":1000,"price":66799.0,"timestamp":"2024-05-18T15:46:28.578Z"},{"symbol":"XBTUSDT","id":32402528279,"side":"Buy","size":20000,"price":66764.2,"timestamp":"2024-05-18T15:46:28.578Z"},{"symbol":"XBTUSDT","id":32402528284,"side":"Buy","size":378000,"price":66754.3,"timestamp":"2024-05-18T15:46:28.578Z"},{"symbol":"XBTUSDT","id":32402528290,"side":"Buy","size":20000,"price":66764.3,"timestamp":"2024-05-18T15:46:28.578Z"}]}
{"table":"orderBookL2_25","action":"delete","data":[{"symbol":"ETHUSDT","id":32402528239,"side":"Sell","price":3111.56,"timestamp":"2024-05-18T15:46:28.609Z"},{"symbol":"ETHUSDT","id":32402527208,"side":"Sell","price":3111.55,"timestamp":"2024-05-18T15:46:28.609Z"},{"symbol":"ETHUSDT","id":32402528255,"side":"Buy","price":3110.09,"timestamp":"2024-05-18T15:46:28.609Z"}]}
{"table":"orderBookL2_25","action":"update","data":[{"symbol":"ETHUSDT","id":32402528262,"side":"Sell","size":132000,"price":3111.57,"timestamp":"2024-05-18T15:46:28.609Z"}]}
{"table":"orderBookL2_25","action":"insert","data":[{"symbol":"ETHUSDT","id":32402441505,"side":"Sell","size":100000,"price":3113.30,"timestamp":"2024-05-18T15:46:28.609Z"},{"symbol":"ETHUSDT","id":32402528313,"side":"Sell","size":32000,"price":3111.58,"timestamp":"2024-05-18T15:46:28.609Z"},{"symbol":"ETHUSDT","id":32402528317,"side":"Buy","size":32000,"price":3110.07,"timestamp":"2024-05-18T15:46:28.609Z"}]}
