{"table":"orderBookL2_25","action":"insert","data":[{"symbol":"XBTUSDT","id":32402499605,"side":"Sell","size":20000,"price":66800.6,"timestamp":"2024-05-18T15:46:15.667Z"},{"symbol":"XBTUSDT","id":32402481228,"side":"Sell","size":2000,"price":66807.9,"timestamp":"2024-05-18T15:46:15.667Z"},{"symbol":"XBTUSDT","id":32402499565,"side":"Sell","size":20000,"price":66800.5,"timestamp":"2024-05-18T15:46:15.667Z"},{"symbol":"XBTUSDT","id":32402499584,"side":"Buy","size":20000,"price":66772.5,"timestamp":"2024-05-18T15:46:15.667Z"}]}
{"table":"orderBookL2_25","action":"delete","data":[{"symbol":"ETHUSDT","id":32402486025,"side":"Sell","price":3111.72,"timestamp":"2024-05-18T15:46:15.697Z"},{"symbol":"ETHUSDT","id":32402499532,"side":"Buy","price":3109.46,"timestamp":"2024-05-18T15:46:15.697Z"},{"symbol":"ETHUSDT","id":32402499556,"side":"Buy","price":3109.24,"timestamp":"2024-05-18T15:46:15.697Z"},{"symbol":"ETHUSDT","id":32402499573,"side":"Buy","price":3109.45,"timestamp":"2024-05-18T15:46:15.697Z"}]}
{"table":"orderBookL2_25","action":"update","data":[{"symbol":"ETHUSDT","id":32402499546,"side":"Sell","size":57000,"price":3109.82,"timestamp":"2024-05-18T15:46:15.697Z"},{"symbol":"ETHUSDT","id":32402496774,"side":"Buy","size":32000,"price":3109.47,"timestamp":"2024-05-18T15:46:15.697Z"}]}
{"table":"orderBookL2_25","action":"insert","data":[{"symbol":"ETHUSDT","id":32402499578,"side":"Sell","size":21000,"price":3109.81,"timestamp":"2024-05-18T15:46:15.697Z"},{"symbol":"ETHUSDT","id":32402499625,"side":"Buy","size":1000,"price":3109.22,"timestamp":"2024-05-18T15:46:15.697Z"},{"symbol":"ETHUSDT","id":32402499691,"side":"Buy","size":241000,"price":3109.49,"timestamp":"2024-05-18T15:46:15.697Z"},{"symbol":"ETHUSDT","id":32402499586,"side":"Buy","size":32000,"price":3109.48,"timestamp":"2024-05-18T15:46:15.697Z"}]}
{"table":"orderBookL2_25","action":"delete","data":[{"symbol":"XBTUSDT","id":32402498829,"side":"Sell","price":66797.5,"timestamp":"2024-05-18T15:46:15.716Z"},{"symbol":"XBTUSDT","id":32402497966,"side":"Sell","price":66800.9,"timestamp":"2024-05-18T15:46:15.716Z"},{"symbol":"XBTUSDT","id":32402498232,"side":"Sell","price":66803.3,"timestamp":"2024-05-18T15:46:15.716Z"},{"symbol":"XBTUSDT","id":32402499471,"side":"Sell","price":66797.4,"timestamp":"2024-05-18T15:46:15.716Z"},{"symbol":"XBTUSDT","id":32402489416,"side":"Buy","price":66757.6,"timestamp":"2024-05-18T15:46:15.716Z"},{"symbol":"XBTUSDT","id":32402499181,"side":"Buy","price":66757.7,"timestamp":"2024-05-18T15:46:15.716Z"},{"symbol":"XBTUSDT","id":32402499584,"side":"Buy","price":66772.5,"timestamp":"2024-05-18T15:46:15.716Z"}]}
{"table":"orderBookL2_25","action":"update","data":[{"symbol":"XBTUSDT","id":32402499096,"side":"Sell","size":107000,"price":66795.3,"timestamp":"2024-05-18T15:46:15.716Z"}]}
{"table":"orderBookL2_25","action":"insert","data":[{"symbol":"XBTUSDT","id":32402499569,"side":"Sell","size":49000,"price":66808.2,"timestamp":"2024-05-18T15:46:15.716Z"},{"symbol":"XBTUSDT","id":32402499630,"side":"Sell","size":363000,"price":66799.0,"timestamp":"2024-05-18T15:46:15.716Z"},{"symbol":"XBTUSDT","id":32402499648,"side":"Sell","size":226000,"price":66798.9,"timestamp":"2024-05-18T15:46:15.716Z"},{"symbol":"XBTUSDT","id":32402499658,"side":"Sell","size":3000,"price":66800.3,"timestamp":"2024-05-18T15:46:15.716Z"},{"symbol":"XBTUSDT","id":32402499693,"side":"Buy","size":156000,"price":66757.8,"timestamp":"2024-05-18T15:46:15.716Z"},{"symbol":"XBTUSDT","id":32402499696,"side":"Buy","size":20000,"price":66772.3,"timestamp":"2024-05-18T15:46:15.716Z"},{"symbol":"XBTUSDT","id":32402499689,"side":"Buy","size":22000,"price":66773.9,"timestamp":"2024-05-18T15:46:15.716Z"}]}
{"table":"orderBookL2_25","action":"delete","data":[{"symbol":"XBTUSDT","id":32402499500,"side":"Sell","price":66806.9,"timestamp":"2024-05-18T15:46:15.765Z"}]}
{"table":"orderBookL2_25","action":"insert","data":[{"symbol":"XBTUSDT","id":32402499805,"side":"Sell","size":1000,"price":66806.7,"timestamp":"2024-05-18T15:46:15.765Z"}]}
{"table":"orderBookL2_25","action":"delete","data":[{"symbol":"ETHUSDT","id":32402499586,"side":"Buy","price":3109.48,"timestamp":"2024-05-18T15:46:15.770Z"}]}
{"table":"orderBookL2_25","action":"insert","data":[{"symbol":"ETHUSDT","id":32402499854,"side":"Buy","size":32000,"price":3109.46,"timestamp":"2024-05-18T15:46:15.770Z"}]}
{"table":"orderBookL2_25","action":"delete","data":[{"symbol":"XBTUSDT","id":32402499565,"side":"Sell","price":66800.5,"timestamp":"2024-05-18T15:46:15.814Z"},{"symbol":"XBTUSDT","id":32402499805,"side":"Sell","price":66806.7,"timestamp":"2024-05-18T15:46:15.814Z"},{"symbol":"XBTUSDT","id":32402499605,"side":"Sell","price":66800.6,"timestamp":"2024-05-18T15:46:15.814Z"},{"symbol":"XBTUSDT","id":32402499446,"side":"Buy","price":66772.4,"timestamp":"2024-05-18T15:46:15.814Z"},{"symbol":"XBTUSDT","id":32402499696,"side":"Buy","price":66772.3,"timestamp":"2024-05-18T15:46:15.814Z"}]}
{"table":"orderBookL2_25","action":"update","data":[{"symbol":"XBTUSDT","id":32402499658,"side":"Sell","size":23000,"price":66800.3,"timestamp":"2024-05-18T15:46:15.814Z"},{"symbol":"XBTUSDT","id":32402492533,"side":"Buy","size":462000,"price":66772.1,"timestamp":"2024-05-18T15:46:15.814Z"},{"symbol":"XBTUSDT","id":32402493180,"side":"Buy","size":186000,"price":66772.2,"timestamp":"2024-05-18T15:46:15.814Z"}]}
{"table":"orderBookL2_25","action":"insert","data":[{"symbol":"XBTUSDT","id":32402499852,"side":"Sell","size":1000,"price":66806.9,"timestamp":"2024-05-18T15:46:15.814Z"},{"symbol":"XBTUSDT","id":32402499909,"side":"Sell","size":20000,"price":66800.4,"timestamp":"2024-05-18T15:46:15.814Z"},{"symbol":"XBTUSDT","id":32402491693,"side":"Sell","size":74000,"price":66808.3,"timestamp":"2024-05-18T15:46:15.814Z"},{"symbol":"XBTUSDT","id":32402499923,"side":"Buy","size":20000,"price":66754.5,"timestamp":"2024-05-18T15:46:15.814Z"},{"symbol":"XBTUSDT","id":32402489416,"side":"Buy","size":100000,"price":66757.6,"timestamp":"2024-05-18T15:46:15.814Z"}]}
{"table":"orderBookL2_25","action":"delete","data":[{"symbol":"ETHUSDT","id":32402499571,"side":"Sell","price":3110.90,"timestamp":"2024-05-18T15:46:15.819Z"},{"symbol":"ETHUSDT","id":32402499536,"side":"Sell","price":3110.89,"timestamp":"2024-05-18T15:46:15.819Z"}]}
{"table":"orderBookL2_25","action":"update","data":[{"symbol":"ETHUSDT","id":32402499416,"side":"Sell","size":504000,"price":3110.24,"timestamp":"2024-05-18T15:46:15.819Z"},{"symbol":"ETHUSDT","id":32402496877,"side":"Sell","size":95000,"price":3110.84,"timestamp":"2024-05-18T15:46:15.819Z"},{"symbol":"ETHUSDT","id":32402496871,"side":"Sell","size":132000,"price":3110.88,"timestamp":"2024-05-18T15:46:15.819Z"}]}
{"table":"orderBookL2_25","action":"insert","data":[{"symbol":"ETHUSDT","id":32402499932,"side":"Sell","size":24000,"price":3110.68,"timestamp":"2024-05-18T15:46:15.819Z"},{"symbol":"ETHUSDT","id":32402486025,"side":"Sell","size":337000,"price":3111.72,"timestamp":"2024-05-18T15:46:15.819Z"}]}
{"table":"orderBookL2_25","action":"delete","data":[{"symbol":"XBTUSDT","id":32402491693,"side":"Sell","price":66808.3,"timestamp":"2024-05-18T15:46:15.863Z"},{"symbol":"XBTUSDT","id":32402499852,"side":"Sell","price":66806.9,"timestamp":"2024-05-18T15:46:15.863Z"},{"symbol":"XBTUSDT","id":32402499034,"side":"Sell","price":66806.8,"timestamp":"2024-05-18T15:46:15.863Z"},{"symbol":"XBTUSDT","id":32402499909,"side":"Sell","price":66800.4,"timestamp":"2024-05-18T15:46:15.863Z"},{"symbol":"XBTUSDT","id":32402489416,"side":"Buy","price":66757.6,"timestamp":"2024-05-18T15:46:15.863Z"},{"symbol":"XBTUSDT","id":32402499923,"side":"Buy","price":66754.5,"timestamp":"2024-05-18T15:46:15.863Z"}]}
{"table":"orderBookL2_25","action":"update","data":[{"symbol":"XBTUSDT","id":32402499658,"side":"Sell","size":3000,"price":66800.3,"timestamp":"2024-05-18T15:46:15.863Z"},{"symbol":"XBTUSDT","id":32402492533,"side":"Buy","size":442000,"price":66772.1,"timestamp":"2024-05-18T15:46:15.863Z"},{"symbol":"XBTUSDT","id":32402493180,"side":"Buy","size":166000,"price":66772.2,"timestamp":"2024-05-18T15:46:15.863Z"}]}
{"table":"orderBookL2_25","action":"insert","data":[{"symbol":"XBTUSDT","id":32402500006,"side":"Sell","size":1000,"price":66807.0,"timestamp":"2024-05-18T15:46:15.863Z"},{"symbol":"XBTUSDT","id":32402499960,"side":"Sell","size":20000,"price":66800.6,"timestamp":"2024-05-18T15:46:15.863Z"},{"symbol":"XBTUSDT","id":32402500020,"side":"Sell","size":1000,"price":66806.8,"timestamp":"2024-05-18T15:46:15.863Z"},{"symbol":"XBTUSDT","id":32402500000,"side":"Sell","size":20000,"price":66800.5,"timestamp":"2024-05-18T15:46:15.863Z"},{"symbol":"XBTUSDT","id":32402499976,"side":"Buy","size":20000,"price":66772.3,"timestamp":"2024-05-18T15:46:15.863Z"},{"symbol":"XBTUSDT","id":32402499958,"side":"Buy","size":20000,"price":66772.4,"timestamp":"2024-05-18T15:46:15.863Z"}]}
{"table":"orderBookL2_25","action":"delete","data":[{"symbol":"ETHUSDT","id":32402499401,"side":"Sell","price":3109.83,"timestamp":"2024-05-18T15:46:15.868Z"},{"symbol":"ETHUSDT","id":32402486025,"side":"Sell","price":3111.72,"timestamp":"2024-05-18T15:46:15.868Z"},{"symbol":"ETHUSDT","id":32402499578,"side":"Sell","price":3109.81,"timestamp":"2024-05-18T15:46:15.868Z"},{"symbol":"ETHUSDT","id":32402499546,"side":"Sell","price":3109.82,"timestamp":"2024-05-18T15:46:15.868Z"},{"symbol":"ETHUSDT","id":32402499625,"side":"Buy","price":3109.22,"timestamp":"2024-05-18T15:46:15.868Z"},{"symbol":"ETHUSDT","id":32402499854,"side":"Buy","price":3109.46,"timestamp":"2024-05-18T15:46:15.868Z"},{"symbol":"ETHUSDT","id":32402496774,"side":"Buy","price":3109.47,"timestamp":"2024-05-18T15:46:15.868Z"},{"symbol":"ETHUSDT","id":32402499525,"side":"Buy","price":3109.23,"timestamp":"2024-05-18T15:46:15.868Z"},{"symbol":"ETHUSDT","id":32402499421,"side":"Buy","price":3108.84,"timestamp":"2024-05-18T15:46:15.868Z"},{"symbol":"ETHUSDT","id":32402499267,"side":"Buy","price":3108.83,"timestamp":"2024-05-18T15:46:15.868Z"}]}
{"table":"orderBookL2_25","action":"update","data":[{"symbol":"ETHUSDT","id":32402496871,"side":"Sell","size":100000,"price":3110.88,"timestamp":"2024-05-18T15:46:15.868Z"},{"symbol":"ETHUSDT","id":32402487305,"side":"Sell","size":100000,"price":3111.65,"timestamp":"2024-05-18T15:46:15.868Z"},{"symbol":"ETHUSDT","id":32402496877,"side":"Sell","size":63000,"price":3110.84,"timestamp":"2024-05-18T15:46:15.868Z"}]}
{"table":"orderBookL2_25","action":"insert","data":[{"symbol":"ETHUSDT","id":32402499937,"side":"Sell","size":32000,"price":3110.85,"timestamp":"2024-05-18T15:46:15.868Z"},{"symbol":"ETHUSDT","id":32402499945,"side":"Sell","size":100000,"price":3109.80,"timestamp":"2024-05-18T15:46:15.868Z"},{"symbol":"ETHUSDT","id":32402499971,"side":"Sell","size":32000,"price":3110.86,"timestamp":"2024-05-18T15:46:15.868Z"},{"symbol":"ETHUSDT","id":32402499965,"side":"Sell","size":100000,"price":3109.77,"timestamp":"2024-05-18T15:46:15.868Z"},{"symbol":"ETHUSDT","id":32402499943,"side":"Buy","size":32000,"price":3109.45,"timestamp":"2024-05-18T15:46:15.868Z"},{"symbol":"ETHUSDT","id":32402499978,"side":"Buy","size":32000,"price":3109.46,"timestamp":"2024-05-18T15:46:15.868Z"},{"symbol":"ETHUSDT","id":32402499996,"side":"Buy","size":1000,"price":3109.21,"timestamp":"2024-05-18T15:46:15.868Z"},{"symbol":"ETHUSDT","id":32402499998,"side":"Buy","size":1000,"price":3109.20,"timestamp":"2024-05-18T15:46:15.868Z"},{"symbol":"ETHUSDT","id":32402493816,"side":"Buy","size":675000,"price":3107.31,"timestamp":"2024-05-18T15:46:15.868Z"},{"symbol":"ETHUSDT","id":32402458908,"side":"Buy","size":1114000,"price":3107.30,"timestamp":"2024-05-18T15:46:15.868Z"}]}
{"table":"orderBookL2_25","action":"delete","data":[{"symbol":"XBTUSDT","id":32402500006,"side":"Sell","price":66807.0,"timestamp":"2024-05-18T15:46:15.912Z"},{"symbol":"XBTUSDT","id":32402499960,"side":"Sell","price":66800.6,"timestamp":"2024-05-18T15:46:15.912Z"},{"symbol":"XBTUSDT","id":32402499976,"side":"Buy","price":66772.3,"timestamp":"2024-05-18T15:46:15.912Z"},{"symbol":"XBTUSDT","id":32402499958,"side":"Buy","price":66772.4,"timestamp":"2024-05-18T15:46:15.912Z"}]}
{"table":"orderBookL2_25","action":"update","data":[{"symbol":"XBTUSDT","id":32402493180,"side":"Buy","size":186000,"price":66772.2,"timestamp":"2024-05-18T15:46:15.912Z"},{"symbol":"XBTUSDT","id":32402498824,"side":"Buy","size":2000,"price":66772.8,"timestamp":"2024-05-18T15:46:15.912Z"}]}
{"table":"orderBookL2_25","action":"insert","data":[{"symbol":"XBTUSDT","id":32402500064,"side":"Sell","size":1000,"price":66806.9,"timestamp":"2024-05-18T15:46:15.912Z"},{"symbol":"XBTUSDT","id":32402500051,"side":"Sell","size":20000,"price":66800.4,"timestamp":"2024-05-18T15:46:15.912Z"},{"symbol":"XBTUSDT","id":32402500053,"side":"Buy","size":20000,"price":66772.3,"timestamp":"2024-05-18T15:46:15.912Z"},{"symbol":"XBTUSDT","id":32402489416,"side":"Buy","size":100000,"price":66757.6,"timestamp":"2024-05-18T15:46:15.912Z"}]}
{"table":"orderBookL2_25","action":"delete","data":[{"symbol":"ETHUSDT","id":32402499945,"side":"Sell","price":3109.80,"timestamp":"2024-05-18T15:46:15.917Z"},{"symbol":"ETHUSDT","id":32402499971,"side":"Sell","price":3110.86,"timestamp":"2024-05-18T15:46:15.917Z"},{"symbol":"ETHUSDT","id":32402499978,"side":"Buy","price":3109.46,"timestamp":"2024-05-18T15:46:15.917Z"},{"symbol":"ETHUSDT","id":32402499996,"side":"Buy","price":3109.21,"timestamp":"2024-05-18T15:46:15.917Z"}]}
{"table":"orderBookL2_25","action":"update","data":[{"symbol":"ETHUSDT","id":32402492800,"side":"Sell","size":908000,"price":3110.25,"timestamp":"2024-05-18T15:46:15.917Z"},{"symbol":"ETHUSDT","id":32402496877,"side":"Sell","size":95000,"price":3110.84,"timestamp":"2024-05-18T15:46:15.917Z"}]}
{"table":"orderBookL2_25","action":"insert","data":[{"symbol":"ETHUSDT","id":32402486025,"side":"Sell","size":337000,"price":3111.72,"timestamp":"2024-05-18T15:46:15.917Z"},{"symbol":"ETHUSDT","id":32402493850,"side":"Sell","size":100000,"price":3111.81,"timestamp":"2024-05-18T15:46:15.917Z"},{"symbol":"ETHUSDT","id":32402500060,"side":"Buy","size":32000,"price":3109.44,"timestamp":"2024-05-18T15:46:15.917Z"},{"symbol":"ETHUSDT","id":32402500073,"side":"Buy","size":1000,"price":3109.21,"timestamp":"2024-05-18T15:46:15.917Z"}]}
{"table":"orderBookL2_25","action":"delete","data":[{"symbol":"ETHUSDT","id":32402499937,"side":"Sell","price":3110.85,"timestamp":"2024-05-18T15:46:15.966Z"},{"symbol":"ETHUSDT","id":32402493850,"side":"Sell","price":3111.81,"timestamp":"2024-05-18T15:46:15.966Z"},{"symbol":"ETHUSDT","id":32402500060,"side":"Buy","price":3109.44,"timestamp":"2024-05-18T15:46:15.966Z"},{"symbol":"ETHUSDT","id":32402499943,"side":"Buy","price":3109.45,"timestamp":"2024-05-18T15:46:15.966Z"}]}
{"table":"orderBookL2_25","action":"update","data":[{"symbol":"ETHUSDT","id":32402492800,"side":"Sell","size":905000,"price":3110.25,"timestamp":"2024-05-18T15:46:15.966Z"},{"symbol":"ETHUSDT","id":32402493174,"side":"Buy","size":75000,"price":3109.41,"timestamp":"2024-05-18T15:46:15.966Z"}]}
{"table":"orderBookL2_25","action":"insert","data":[{"symbol":"ETHUSDT","id":32402500165,"side":"Sell","size":32000,"price":3110.83,"timestamp":"2024-05-18T15:46:15.966Z"},{"symbol":"ETHUSDT","id":32402500115,"side":"Sell","size":2000,"price":3110.03,"timestamp":"2024-05-18T15:46:15.966Z"},{"symbol":"ETHUSDT","id":32402480382,"side":"Buy","size":100000,"price":3107.24,"timestamp":"2024-05-18T15:46:15.966Z"},{"symbol":"ETHUSDT","id":32402500128,"side":"Buy","size":32000,"price":3109.42,"timestamp":"2024-05-18T15:46:15.966Z"}]}
{"table":"orderBookL2_25","action":"delete","data":[{"symbol":"XBTUSDT","id":32402499569,"side":"Sell","price":66808.2,"timestamp":"2024-05-18T15:46:15.990Z"}]}
{"table":"orderBookL2_25","action":"insert","data":[{"symbol":"XBTUSDT","id":32402500188,"side":"Sell","size":2000,"price":66798.1,"timestamp":"2024-05-18T15:46:15.990Z"}]}
{"table":"orderBookL2_25","action":"update","data":[{"symbol":"XBTETH","id":32402422012,"side":"Buy","size":7,"price":20.840,"timestamp":"2024-05-18T15:46:16.006Z"}]}
{"table":"orderBookL2_25","action":"delete","data":[{"symbol":"ETHUSDT","id":32402500165,"side":"Sell","price":3110.83,"timestamp":"2024-05-18T15:46:16.015Z"},{"symbol":"ETHUSDT","id":32402486025,"side":"Sell","price":3111.72,"timestamp":"2024-05-18T15:46:16.015Z"},{"symbol":"ETHUSDT","id":32402487305,"side":"Sell","price":3111.65,"timestamp":"2024-05-18T15:46:16.015Z"},{"symbol":"ETHUSDT","id":32402487294,"side":"Sell","price":3111.54,"timestamp":"2024-05-18T15:46:16.015Z"},{"symbol":"ETHUSDT","id":32402500073,"side":"Buy","price":3109.21,"timestamp":"2024-05-18T15:46:16.015Z"},{"symbol":"ETHUSDT","id":32402499998,"side":"Buy","price":3109.20,"timestamp":"2024-05-18T15:46:16.015Z"},{"symbol":"ETHUSDT","id":32402480382,"side":"Buy","price":3107.24,"timestamp":"2024-05-18T15:46:16.015Z"}]}
{"table":"orderBookL2_25","action":"update","data":[{"symbol":"ETHUSDT","id":32402491370,"side":"Sell","size":920000,"price":3111.53,"timestamp":"2024-05-18T15:46:16.015Z"},{"symbol":"ETHUSDT","id":32402493174,"side":"Buy","size":43000,"price":3109.41,"timestamp":"2024-05-18T15:46:16.015Z"}]}
{"table":"orderBookL2_25","action":"insert","data":[{"symbol":"ETHUSDT","id":32402500204,"side":"Sell","size":26000,"price":3109.70,"timestamp":"2024-05-18T15:46:16.015Z"},{"symbol":"ETHUSDT","id":32402500182,"side":"Sell","size":100000,"price":3110.56,"timestamp":"2024-05-18T15:46:16.015Z"},{"symbol":"ETHUSDT","id":32402500178,"side":"Sell","size":100000,"price":3109.71,"timestamp":"2024-05-18T15:46:16.015Z"},{"symbol":"ETHUSDT","id":32402500198,"side":"Sell","size":32000,"price":3110.85,"timestamp":"2024-05-18T15:46:16.015Z"},{"symbol":"ETHUSDT","id":32402500184,"side":"Buy","size":1000,"price":3109.18,"timestamp":"2024-05-18T15:46:16.015Z"},{"symbol":"ETHUSDT","id":32402500190,"side":"Buy","size":32000,"price":3109.43,"timestamp":"2024-05-18T15:46:16.015Z"},{"symbol":"ETHUSDT","id":32402500200,"side":"Buy","size":1000,"price":3109.19,"timestamp":"2024-05-18T15:46:16.015Z"}]}
{"table":"orderBookL2_25","action":"delete","data":[{"symbol":"XBTUSDT","id":32402499630,"side":"Sell","price":66799.0,"timestamp":"2024-05-18T15:46:16.040Z"},{"symbol":"XBTUSDT","id":32402498827,"side":"Buy","price":66761.2,"timestamp":"2024-05-18T15:46:16.040Z"}]}
{"table":"orderBookL2_25","action":"update","data":[{"symbol":"XBTUSDT","id":32402499234,"side":"Sell","size":192000,"price":66792.0,"timestamp":"2024-05-18T15:46:16.040Z"}]}
{"table":"orderBookL2_25","action":"insert","data":[{"symbol":"XBTUSDT","id":32402500263,"side":"Sell","size":355000,"price":66798.8,"timestamp":"2024-05-18T15:46:16.040Z"},{"symbol":"XBTUSDT","id":32402500261,"side":"Buy","size":348000,"price":66764.5,"timestamp":"2024-05-18T15:46:16.040Z"}]}
{"table":"orderBookL2_25","action":"delete","data":[{"symbol":"ETHUSDT","id":32402500115,"side":"Sell","price":3110.03,"timestamp":"2024-05-18T15:46:16.064Z"},{"symbol":"ETHUSDT","id":32402499965,"side":"Sell","price":3109.77,"timestamp":"2024-05-18T15:46:16.064Z"},{"symbol":"ETHUSDT","id":32402498771,"side":"Buy","price":3108.67,"timestamp":"2024-05-18T15:46:16.064Z"}]}
{"table":"orderBookL2_25","action":"update","data":[{"symbol":"ETHUSDT","id":32402491370,"side":"Sell","size":920000,"price":3111.53,"timestamp":"2024-05-18T15:46:16.064Z"}]}
{"table":"orderBookL2_25","action":"insert","data":[{"symbol":"ETHUSDT","id":32402500242,"side":"Sell","size":100000,"price":3109.68,"timestamp":"2024-05-18T15:46:16.064Z"},{"symbol":"ETHUSDT","id":32402500254,"side":"Sell","size":28000,"price":3110.04,"timestamp":"2024-05-18T15:46:16.064Z"},{"symbol":"ETHUSDT","id":32402480382,"side":"Buy","size":100000,"price":3107.24,"timestamp":"2024-05-18T15:46:16.064Z"}]}
{"table":"orderBookL2_25","action":"delete","data":[{"symbol":"XBTUSDT","id":32402499648,"side":"Sell","price":66798.9,"timestamp":"2024-05-18T15:46:16.089Z"},{"symbol":"XBTUSDT","id":32402499174,"side":"Buy","price":66761.3,"timestamp":"2024-05-18T15:46:16.089Z"},{"symbol":"XBTUSDT","id":32402500261,"side":"Buy","price":66764.5,"timestamp":"2024-05-18T15:46:16.089Z"}]}
{"table":"orderBookL2_25","action":"insert","data":[{"symbol":"XBTUSDT","id":32402499569,"side":"Sell","size":49000,"price":66808.2,"timestamp":"2024-05-18T15:46:16.089Z"},{"symbol":"XBTUSDT","id":32402499927,"side":"Buy","size":18000,"price":66753.0,"timestamp":"2024-05-18T15:46:16.089Z"},{"symbol":"XBTUSDT","id":32402500285,"side":"Buy","size":378000,"price":66761.4,"timestamp":"2024-05-18T15:46:16.089Z"}]}
{"table":"orderBookL2_25","action":"delete","data":[{"symbol":"ETHUSDT","id":32402499418,"side":"Sell","price":3110.19,"timestamp":"2024-05-18T15:46:16.113Z"}]}
{"table":"orderBookL2_25","action":"update","data":[{"symbol":"ETHUSDT","id":32402492798,"side":"Buy","size":411000,"price":3108.69,"timestamp":"2024-05-18T15:46:16.113Z"}]}
{"table":"orderBookL2_25","action":"insert","data":[{"symbol":"ETHUSDT","id":32402487294,"side":"Sell","size":2346000,"price":3111.54,"timestamp":"2024-05-18T15:46:16.113Z"}]}
{"table":"orderBookL2_25","action":"delete","data":[{"symbol":"XBTUSDT","id":32402499467,"side":"Sell","price":66797.1,"timestamp":"2024-05-18T15:46:16.138Z"},{"symbol":"XBTUSDT","id":32402500020,"side":"Sell","price":66806.8,"timestamp":"2024-05-18T15:46:16.138Z"},{"symbol":"XBTUSDT","id":32402500000,"side":"Sell","price":66800.5,"timestamp":"2024-05-18T15:46:16.138Z"},{"symbol":"XBTUSDT","id":32402500053,"side":"Buy","price":66772.3,"timestamp":"2024-05-18T15:46:16.138Z"}]}
{"table":"orderBookL2_25","action":"update","data":[{"symbol":"XBTUSDT","id":32402499658,"side":"Sell","size":23000,"price":66800.3,"timestamp":"2024-05-18T15:46:16.138Z"},{"symbol":"XBTUSDT","id":32402492533,"side":"Buy","size":462000,"price":66772.1,"timestamp":"2024-05-18T15:46:16.138Z"}]}
{"table":"orderBookL2_25","action":"insert","data":[{"symbol":"XBTUSDT","id":32402500370,"side":"Sell","size":1000,"price":66806.8,"timestamp":"2024-05-18T15:46:16.138Z"},{"symbol":"XBTUSDT","id":32402500325,"side":"Sell","size":3000,"price":66791.7,"timestamp":"2024-05-18T15:46:16.138Z"},{"symbol":"XBTUSDT","id":32402491693,"side":"Sell","size":74000,"price":66808.3,"timestamp":"2024-05-18T15:46:16.138Z"},{"symbol":"XBTUSDT","id":32402500345,"side":"Buy","size":236000,"price":66761.5,"timestamp":"2024-05-18T15:46:16.138Z"}]}
{"table":"orderBookL2_25","action":"delete","data":[{"symbol":"XBTUSDT","id":32402500263,"side":"Sell","price":66798.8,"timestamp":"2024-05-18T15:46:16.187Z"},{"symbol":"XBTUSDT","id":32402491693,"side":"Sell","price":66808.3,"timestamp":"2024-05-18T15:46:16.187Z"},{"symbol":"XBTUSDT","id":32402499693,"side":"Buy","price":66757.8,"timestamp":"2024-05-18T15:46:16.187Z"},{"symbol":"XBTUSDT","id":32402500285,"side":"Buy","price":66761.4,"timestamp":"2024-05-18T15:46:16.187Z"},{"symbol":"XBTUSDT","id":32402500345,"side":"Buy","price":66761.5,"timestamp":"2024-05-18T15:46:16.187Z"}]}
{"table":"orderBookL2_25","action":"update","data":[{"symbol":"XBTUSDT","id":32402499927,"side":"Buy","size":18000,"price":66753.0,"timestamp":"2024-05-18T15:46:16.187Z"}]}
{"table":"orderBookL2_25","action":"insert","data":[{"symbol":"XBTUSDT","id":32402500455,"side":"Sell","size":350000,"price":66798.0,"timestamp":"2024-05-18T15:46:16.187Z"},{"symbol":"XBTUSDT","id":32402500410,"side":"Sell","size":214000,"price":66798.7,"timestamp":"2024-05-18T15:46:16.187Z"},{"symbol":"XBTUSDT","id":32402495049,"side":"Buy","size":878000,"price":66752.2,"timestamp":"2024-05-18T15:46:16.187Z"},{"symbol":"XBTUSDT","id":32402500457,"side":"Buy","size":376000,"price":66761.4,"timestamp":"2024-05-18T15:46:16.187Z"},{"symbol":"XBTUSDT","id":32402500433,"side":"Buy","size":156000,"price":66758.0,"timestamp":"2024-05-18T15:46:16.187Z"}]}
{"table":"orderBookL2_25","action":"delete","data":[{"symbol":"ETHUSDT","id":32402500128,"side":"Buy","price":3109.42,"timestamp":"2024-05-18T15:46:16.198Z"}]}
{"table":"orderBookL2_25","action":"insert","data":[{"symbol":"ETHUSDT","id":32402500480,"side":"Buy","size":32000,"price":3109.44,"timestamp":"2024-05-18T15:46:16.198Z"}]}
{"table":"orderBookL2_25","action":"delete","data":[{"symbol":"XBTUSDT","id":32402500410,"side":"Sell","price":66798.7,"timestamp":"2024-05-18T15:46:16.236Z"}]}
{"table":"orderBookL2_25","action":"update","data":[{"symbol":"XBTUSDT","id":32402499096,"side":"Sell","size":40000,"price":66795.3,"timestamp":"2024-05-18T15:46:16.236Z"}]}
{"table":"orderBookL2_25","action":"insert","data":[{"symbol":"XBTUSDT","id":32402491693,"side":"Sell","size":74000,"price":66808.3,"timestamp":"2024-05-18T15:46:16.236Z"}]}
{"table":"orderBookL2_25","action":"delete","data":[{"symbol":"ETHUSDT","id":32402500198,"side":"Sell","price":3110.85,"timestamp":"2024-05-18T15:46:16.247Z"}]}
{"table":"orderBookL2_25","action":"insert","data":[{"symbol":"ETHUSDT","id":32402500482,"side":"Sell","size":32000,"price":3110.83,"timestamp":"2024-05-18T15:46:16.247Z"}]}
{"table":"orderBookL2_25","action":"delete","data":[{"symbol":"XBTUSDT","id":32402499927,"side":"Buy","price":66753.0,"timestamp":"2024-05-18T15:46:16.285Z"}]}
{"table":"orderBookL2_25","action":"insert","data":[{"symbol":"XBTUSDT","id":32402500552,"side":"Buy","size":228000,"price":66761.5,"timestamp":"2024-05-18T15:46:16.285Z"}]}
{"table":"orderBookL2_25","action":"delete","data":[{"symbol":"ETHUSDT","id":32402500482,"side":"Sell","price":3110.83,"timestamp":"2024-05-18T15:46:16.302Z"}]}
{"table":"orderBookL2_25","action":"insert","data":[{"symbol":"ETHUSDT","id":32402500619,"side":"Sell","size":32000,"price":3110.85,"timestamp":"2024-05-18T15:46:16.302Z"}]}
{"table":"orderBookL2_25","action":"delete","data":[{"symbol":"XBTUSDT","id":32402500455,"side":"Sell","price":66798.0,"timestamp":"2024-05-18T15:46:16.334Z"},{"symbol":"XBTUSDT","id":32402500064,"side":"Sell","price":66806.9,"timestamp":"2024-05-18T15:46:16.334Z"},{"symbol":"XBTUSDT","id":32402500370,"side":"Sell","price":66806.8,"timestamp":"2024-05-18T15:46:16.334Z"},{"symbol":"XBTUSDT","id":32402500552,"side":"Buy","price":66761.5,"timestamp":"2024-05-18T15:46:16.334Z"},{"symbol":"XBTUSDT","id":32402500457,"side":"Buy","price":66761.4,"timestamp":"2024-05-18T15:46:16.334Z"},{"symbol":"XBTUSDT","id":32402499167,"side":"Buy","price":66776.4,"timestamp":"2024-05-18T15:46:16.334Z"}]}
{"table":"orderBookL2_25","action":"update","data":[{"symbol":"XBTUSDT","id":32402491799,"side":"Sell","size":53000,"price":66795.4,"timestamp":"2024-05-18T15:46:16.334Z"},{"symbol":"XBTUSDT","id":32402491693,"side":"Sell","size":74000,"price":66808.3,"timestamp":"2024-05-18T15:46:16.334Z"},{"symbol":"XBTUSDT","id":32402498305,"side":"Buy","size":6000,"price":66786.6,"timestamp":"2024-05-18T15:46:16.334Z"}]}
{"table":"orderBookL2_25","action":"insert","data":[{"symbol":"XBTUSDT","id":32402500641,"side":"Sell","size":1000,"price":66806.7,"timestamp":"2024-05-18T15:46:16.334Z"},{"symbol":"XBTUSDT","id":32402500630,"side":"Sell","size":356000,"price":66799.0,"timestamp":"2024-05-18T15:46:16.334Z"},{"symbol":"XBTUSDT","id":32402500639,"side":"Sell","size":1000,"price":66806.6,"timestamp":"2024-05-18T15:46:16.334Z"},{"symbol":"XBTUSDT","id":32402494980,"side":"Buy","size":74000,"price":66751.4,"timestamp":"2024-05-18T15:46:16.334Z"},{"symbol":"XBTUSDT","id":32402492129,"side":"Buy","size":1502000,"price":66752.1,"timestamp":"2024-05-18T15:46:16.334Z"},{"symbol":"XBTUSDT","id":32402500632,"side":"Buy","size":347000,"price":66764.6,"timestamp":"2024-05-18T15:46:16.334Z"}]}
{"table":"orderBookL2_25","action":"delete","data":[{"symbol":"ETHUSDT","id":32402500480,"side":"Buy","price":3109.44,"timestamp":"2024-05-18T15:46:16.351Z"}]}
{"table":"orderBookL2_25","action":"insert","data":[{"symbol":"ETHUSDT","id":32402500621,"side":"Buy","size":32000,"price":3109.42,"timestamp":"2024-05-18T15:46:16.351Z"}]}
{"table":"orderBookL2_25","action":"delete","data":[{"symbol":"XBTUSDT","id":32402500639,"side":"Sell","price":66806.6,"timestamp":"2024-05-18T15:46:16.383Z"},{"symbol":"XBTUSDT","id":32402500051,"side":"Sell","price":66800.4,"timestamp":"2024-05-18T15:46:16.383Z"},{"symbol":"XBTUSDT","id":32402500632,"side":"Buy","price":66764.6,"timestamp":"2024-05-18T15:46:16.383Z"}]}
{"table":"orderBookL2_25","action":"update","data":[{"symbol":"XBTUSDT","id":32402492533,"side":"Buy","size":442000,"price":66772.1,"timestamp":"2024-05-18T15:46:16.383Z"},{"symbol":"XBTUSDT","id":32402489150,"side":"Buy","size":120000,"price":66772.6,"timestamp":"2024-05-18T15:46:16.383Z"},{"symbol":"XBTUSDT","id":32402494037,"side":"Buy","size":89000,"price":66772.7,"timestamp":"2024-05-18T15:46:16.383Z"},{"symbol":"XBTUSDT","id":32402493180,"side":"Buy","size":166000,"price":66772.2,"timestamp":"2024-05-18T15:46:16.383Z"}]}
{"table":"orderBookL2_25","action":"insert","data":[{"symbol":"XBTUSDT","id":32402500764,"side":"Sell","size":1000,"price":66806.8,"timestamp":"2024-05-18T15:46:16.383Z"},{"symbol":"XBTUSDT","id":32402500760,"side":"Sell","size":20000,"price":66800.4,"timestamp":"2024-05-18T15:46:16.383Z"},{"symbol":"XBTUSDT","id":32402500713,"side":"Buy","size":374000,"price":66761.1,"timestamp":"2024-05-18T15:46:16.383Z"}]}
{"table":"orderBookL2_25","action":"delete","data":[{"symbol":"XBTUSDT","id":32402481228,"side":"Sell","price":66807.9,"timestamp":"2024-05-18T15:46:16.432Z"},{"symbol":"XBTUSDT","id":32402500630,"side":"Sell","price":66799.0,"timestamp":"2024-05-18T15:46:16.432Z"},{"symbol":"XBTUSDT","id":32402500764,"side":"Sell","price":66806.8,"timestamp":"2024-05-18T15:46:16.432Z"},{"symbol":"XBTUSDT","id":32402500641,"side":"Sell","price":66806.7,"timestamp":"2024-05-18T15:46:16.432Z"},{"symbol":"XBTUSDT","id":32402500760,"side":"Sell","price":66800.4,"timestamp":"2024-05-18T15:46:16.432Z"},{"symbol":"XBTUSDT","id":32402494980,"side":"Buy","price":66751.4,"timestamp":"2024-05-18T15:46:16.432Z"}]}
{"table":"orderBookL2_25","action":"update","data":[{"symbol":"XBTUSDT","id":32402491799,"side":"Sell","size":52000,"price":66795.4,"timestamp":"2024-05-18T15:46:16.432Z"},{"symbol":"XBTUSDT","id":32402499658,"side":"Sell","size":3000,"price":66800.3,"timestamp":"2024-05-18T15:46:16.432Z"},{"symbol":"XBTUSDT","id":32402499236,"side":"Sell","size":149000,"price":66786.7,"timestamp":"2024-05-18T15:46:16.432Z"},{"symbol":"XBTUSDT","id":32402492533,"side":"Buy","size":462000,"price":66772.1,"timestamp":"2024-05-18T15:46:16.432Z"},{"symbol":"XBTUSDT","id":32402489150,"side":"Buy","size":100000,"price":66772.6,"timestamp":"2024-05-18T15:46:16.432Z"},{"symbol":"XBTUSDT","id":32402492129,"side":"Buy","size":1502000,"price":66752.1,"timestamp":"2024-05-18T15:46:16.432Z"},{"symbol":"XBTUSDT","id":32402494037,"side":"Buy","size":69000,"price":66772.7,"timestamp":"2024-05-18T15:46:16.432Z"}]}
{"table":"orderBookL2_25","action":"insert","data":[{"symbol":"XBTUSDT","id":32402500787,"side":"Sell","size":353000,"price":66798.0,"timestamp":"2024-05-18T15:46:16.432Z"},{"symbol":"XBTUSDT","id":32402500881,"side":"Sell","size":20000,"price":66800.4,"timestamp":"2024-05-18T15:46:16.432Z"},{"symbol":"XBTUSDT","id":32402500906,"side":"Sell","size":20000,"price":66800.5,"timestamp":"2024-05-18T15:46:16.432Z"},{"symbol":"XBTUSDT","id":32402500884,"side":"Sell","size":1000,"price":66806.9,"timestamp":"2024-05-18T15:46:16.432Z"},{"symbol":"XBTUSDT","id":32402500876,"side":"Sell","size":1000,"price":66806.8,"timestamp":"2024-05-18T15:46:16.432Z"},{"symbol":"XBTUSDT","id":32402500891,"side":"Buy","size":20000,"price":66772.0,"timestamp":"2024-05-18T15:46:16.432Z"}]}
{"table":"orderBookL2_25","action":"delete","data":[{"symbol":"ETHUSDT","id":32402500200,"side":"Buy","price":3109.19,"timestamp":"2024-05-18T15:46:16.458Z"}]}
{"table":"orderBookL2_25","action":"insert","data":[{"symbol":"ETHUSDT","id":32402500980,"side":"Buy","size":1000,"price":3109.17,"timestamp":"2024-05-18T15:46:16.458Z"}]}
{"table":"orderBookL2_25","action":"delete","data":[{"symbol":"XBTUSDT","id":32402500884,"side":"Sell","price":66806.9,"timestamp":"2024-05-18T15:46:16.481Z"},{"symbol":"XBTUSDT","id":32402500713,"side":"Buy","price":66761.1,"timestamp":"2024-05-18T15:46:16.481Z"}]}
{"table":"orderBookL2_25","action":"update","data":[{"symbol":"XBTUSDT","id":32402499236,"side":"Sell","size":155000,"price":66786.7,"timestamp":"2024-05-18T15:46:16.481Z"}]}
{"table":"orderBookL2_25","action":"insert","data":[{"symbol":"XBTUSDT","id":32402501095,"side":"Sell","size":1000,"price":66806.7,"timestamp":"2024-05-18T15:46:16.481Z"},{"symbol":"XBTUSDT","id":32402501098,"side":"Buy","size":371000,"price":66761.6,"timestamp":"2024-05-18T15:46:16.481Z"}]}
{"table":"orderBookL2_25","action":"delete","data":[{"symbol":"ETHUSDT","id":32402500619,"side":"Sell","price":3110.85,"timestamp":"2024-05-18T15:46:16.507Z"},{"symbol":"ETHUSDT","id":32402500190,"side":"Buy","price":3109.43,"timestamp":"2024-05-18T15:46:16.507Z"},{"symbol":"ETHUSDT","id":32402499691,"side":"Buy","price":3109.49,"timestamp":"2024-05-18T15:46:16.507Z"}]}
{"table":"orderBookL2_25","action":"update","data":[{"symbol":"ETHUSDT","id":32402493174,"side":"Buy","size":75000,"price":3109.41,"timestamp":"2024-05-18T15:46:16.507Z"},{"symbol":"ETHUSDT","id":32402492798,"side":"Buy","size":311000,"price":3108.69,"timestamp":"2024-05-18T15:46:16.507Z"}]}
{"table":"orderBookL2_25","action":"insert","data":[{"symbol":"ETHUSDT","id":32402501133,"side":"Sell","size":32000,"price":3110.83,"timestamp":"2024-05-18T15:46:16.507Z"},{"symbol":"ETHUSDT","id":32402488018,"side":"Buy","size":1620000,"price":3107.17,"timestamp":"2024-05-18T15:46:16.507Z"},{"symbol":"ETHUSDT","id":32402492538,"side":"Buy","size":928000,"price":3107.18,"timestamp":"2024-05-18T15:46:16.507Z"}]}
{"table":"orderBookL2_25","action":"delete","data":[{"symbol":"XBTUSDT","id":32402500881,"side":"Sell","price":66800.4,"timestamp":"2024-05-18T15:46:16.530Z"},{"symbol":"XBTUSDT","id":32402501095,"side":"Sell","price":66806.7,"timestamp":"2024-05-18T15:46:16.530Z"},{"symbol":"XBTUSDT","id":32402500876,"side":"Sell","price":66806.8,"timestamp":"2024-05-18T15:46:16.530Z"},{"symbol":"XBTUSDT","id":32402500906,"side":"Sell","price":66800.5,"timestamp":"2024-05-18T15:46:16.530Z"},{"symbol":"XBTUSDT","id":32402500891,"side":"Buy","price":66772.0,"timestamp":"2024-05-18T15:46:16.530Z"},{"symbol":"XBTUSDT","id":32402501098,"side":"Buy","price":66761.6,"timestamp":"2024-05-18T15:46:16.530Z"},{"symbol":"XBTUSDT","id":32402489150,"side":"Buy","price":66772.6,"timestamp":"2024-05-18T15:46:16.530Z"},{"symbol":"XBTUSDT","id":32402494037,"side":"Buy","price":66772.7,"timestamp":"2024-05-18T15:46:16.530Z"},{"symbol":"XBTUSDT","id":32402500433,"side":"Buy","price":66758.0,"timestamp":"2024-05-18T15:46:16.530Z"}]}
{"table":"orderBookL2_25","action":"update","data":[{"symbol":"XBTUSDT","id":32402499658,"side":"Sell","size":3000,"price":66800.3,"timestamp":"2024-05-18T15:46:16.530Z"},{"symbol":"XBTUSDT","id":32402492533,"side":"Buy","size":442000,"price":66772.1,"timestamp":"2024-05-18T15:46:16.530Z"},{"symbol":"XBTUSDT","id":32402493180,"side":"Buy","size":166000,"price":66772.2,"timestamp":"2024-05-18T15:46:16.530Z"}]}
{"table":"orderBookL2_25","action":"insert","data":[{"symbol":"XBTUSDT","id":32402501323,"side":"Sell","size":20000,"price":66800.6,"timestamp":"2024-05-18T15:46:16.530Z"},{"symbol":"XBTUSDT","id":32402501260,"side":"Sell","size":20000,"price":66800.5,"timestamp":"2024-05-18T15:46:16.530Z"},{"symbol":"XBTUSDT","id":32402501328,"side":"Sell","size":1000,"price":66806.9,"timestamp":"2024-05-18T15:46:16.530Z"},{"symbol":"XBTUSDT","id":32402501252,"side":"Sell","size":1000,"price":66807.0,"timestamp":"2024-05-18T15:46:16.530Z"},{"symbol":"XBTUSDT","id":32402494980,"side":"Buy","size":74000,"price":66751.4,"timestamp":"2024-05-18T15:46:16.530Z"},{"symbol":"XBTUSDT","id":32402501242,"side":"Buy","size":20000,"price":66771.9,"timestamp":"2024-05-18T15:46:16.530Z"},{"symbol":"XBTUSDT","id":32402501137,"side":"Buy","size":373000,"price":66761.1,"timestamp":"2024-05-18T15:46:16.530Z"},{"symbol":"XBTUSDT","id":32402501335,"side":"Buy","size":20000,"price":66771.8,"timestamp":"2024-05-18T15:46:16.530Z"},{"symbol":"XBTUSDT","id":32402501170,"side":"Buy","size":156000,"price":66752.3,"timestamp":"2024-05-18T15:46:16.530Z"}]}
{"table":"orderBookL2_25","action":"delete","data":[{"symbol":"ETHUSDT","id":32402501133,"side":"Sell","price":3110.83,"timestamp":"2024-05-18T15:46:16.556Z"},{"symbol":"ETHUSDT","id":32402500178,"side":"Sell","price":3109.71,"timestamp":"2024-05-18T15:46:16.556Z"},{"symbol":"ETHUSDT","id":32402500204,"side":"Sell","price":3109.70,"timestamp":"2024-05-18T15:46:16.556Z"},{"symbol":"ETHUSDT","id":32402500184,"side":"Buy","price":3109.18,"timestamp":"2024-05-18T15:46:16.556Z"},{"symbol":"ETHUSDT","id":32402487994,"side":"Buy","price":3108.29,"timestamp":"2024-05-18T15:46:16.556Z"},{"symbol":"ETHUSDT","id":32402500621,"side":"Buy","price":3109.42,"timestamp":"2024-05-18T15:46:16.556Z"},{"symbol":"ETHUSDT","id":32402492538,"side":"Buy","price":3107.18,"timestamp":"2024-05-18T15:46:16.556Z"},{"symbol":"ETHUSDT","id":32402500980,"side":"Buy","price":3109.17,"timestamp":"2024-05-18T15:46:16.556Z"},{"symbol":"ETHUSDT","id":32402498785,"side":"Buy","price":3108.51,"timestamp":"2024-05-18T15:46:16.556Z"}]}
{"table":"orderBookL2_25","action":"update","data":[{"symbol":"ETHUSDT","id":32402496877,"side":"Sell","size":63000,"price":3110.84,"timestamp":"2024-05-18T15:46:16.556Z"},{"symbol":"ETHUSDT","id":32402493174,"side":"Buy","size":43000,"price":3109.41,"timestamp":"2024-05-18T15:46:16.556Z"},{"symbol":"ETHUSDT","id":32402488018,"side":"Buy","size":1620000,"price":3107.17,"timestamp":"2024-05-18T15:46:16.556Z"}]}
{"table":"orderBookL2_25","action":"insert","data":[{"symbol":"ETHUSDT","id":32402501426,"side":"Sell","size":32000,"price":3110.63,"timestamp":"2024-05-18T15:46:16.556Z"},{"symbol":"ETHUSDT","id":32402487305,"side":"Sell","size":100000,"price":3111.65,"timestamp":"2024-05-18T15:46:16.556Z"},{"symbol":"ETHUSDT","id":32402501430,"side":"Sell","size":32000,"price":3110.62,"timestamp":"2024-05-18T15:46:16.556Z"},{"symbol":"ETHUSDT","id":32402501294,"side":"Buy","size":32000,"price":3109.39,"timestamp":"2024-05-18T15:46:16.556Z"},{"symbol":"ETHUSDT","id":32402501369,"side":"Buy","size":1000,"price":3109.10,"timestamp":"2024-05-18T15:46:16.556Z"},{"symbol":"ETHUSDT","id":32402488025,"side":"Buy","size":100000,"price":3107.08,"timestamp":"2024-05-18T15:46:16.556Z"},{"symbol":"ETHUSDT","id":32402501299,"side":"Buy","size":32000,"price":3109.38,"timestamp":"2024-05-18T15:46:16.556Z"},{"symbol":"ETHUSDT","id":32402501375,"side":"Buy","size":100000,"price":3108.45,"timestamp":"2024-05-18T15:46:16.556Z"},{"symbol":"ETHUSDT","id":32402501412,"side":"Buy","size":1000,"price":3109.09,"timestamp":"2024-05-18T15:46:16.556Z"}]}
{"table":"orderBookL2_25","action":"delete","data":[{"symbol":"XBTUSDT","id":32402501323,"side":"Sell","price":66800.6,"timestamp":"2024-05-18T15:46:16.579Z"},{"symbol":"XBTUSDT","id":32402501260,"side":"Sell","price":66800.5,"timestamp":"2024-05-18T15:46:16.579Z"},{"symbol":"XBTUSDT","id":32402501328,"side":"Sell","price":66806.9,"timestamp":"2024-05-18T15:46:16.579Z"},{"symbol":"XBTUSDT","id":32402501252,"side":"Sell","price":66807.0,"timestamp":"2024-05-18T15:46:16.579Z"},{"symbol":"XBTUSDT","id":32402497914,"side":"Buy","price":66786.5,"timestamp":"2024-05-18T15:46:16.579Z"},{"symbol":"XBTUSDT","id":32402501242,"side":"Buy","price":66771.9,"timestamp":"2024-05-18T15:46:16.579Z"},{"symbol":"XBTUSDT","id":32402501335,"side":"Buy","price":66771.8,"timestamp":"2024-05-18T15:46:16.579Z"}]}
{"table":"orderBookL2_25","action":"update","data":[{"symbol":"XBTUSDT","id":32402492533,"side":"Buy","size":442000,"price":66772.1,"timestamp":"2024-05-18T15:46:16.579Z"},{"symbol":"XBTUSDT","id":32402497765,"side":"Buy","size":8000,"price":66786.4,"timestamp":"2024-05-18T15:46:16.579Z"},{"symbol":"XBTUSDT","id":32402497110,"side":"Buy","size":8000,"price":66786.3,"timestamp":"2024-05-18T15:46:16.579Z"}]}
{"table":"orderBookL2_25","action":"insert","data":[{"symbol":"XBTUSDT","id":32402501447,"side":"Sell","size":1000,"price":66807.1,"timestamp":"2024-05-18T15:46:16.579Z"},{"symbol":"XBTUSDT","id":32402501475,"side":"Sell","size":20000,"price":66800.6,"timestamp":"2024-05-18T15:46:16.579Z"},{"symbol":"XBTUSDT","id":32402501501,"side":"Sell","size":1000,"price":66807.2,"timestamp":"2024-05-18T15:46:16.579Z"},{"symbol":"XBTUSDT","id":32402501494,"side":"Sell","size":20000,"price":66800.7,"timestamp":"2024-05-18T15:46:16.579Z"},{"symbol":"XBTUSDT","id":32402501503,"side":"Buy","size":20000,"price":66770.9,"timestamp":"2024-05-18T15:46:16.579Z"},{"symbol":"XBTUSDT","id":32402501508,"side":"Buy","size":20000,"price":66771.0,"timestamp":"2024-05-18T15:46:16.579Z"},{"symbol":"XBTUSDT","id":32402492889,"side":"Buy","size":100000,"price":66750.8,"timestamp":"2024-05-18T15:46:16.579Z"}]}
{"table":"orderBookL2_25","action":"delete","data":[{"symbol":"ETHUSDT","id":32402501426,"side":"Sell","price":3110.63,"timestamp":"2024-05-18T15:46:16.605Z"},{"symbol":"ETHUSDT","id":32402501430,"side":"Sell","price":3110.62,"timestamp":"2024-05-18T15:46:16.605Z"},{"symbol":"ETHUSDT","id":32402501294,"side":"Buy","price":3109.39,"timestamp":"2024-05-18T15:46:16.605Z"},{"symbol":"ETHUSDT","id":32402501369,"side":"Buy","price":3109.10,"timestamp":"2024-05-18T15:46:16.605Z"}]}
{"table":"orderBookL2_25","action":"update","data":[{"symbol":"ETHUSDT","id":32402500182,"side":"Sell","size":132000,"price":3110.56,"timestamp":"2024-05-18T15:46:16.605Z"}]}
{"table":"orderBookL2_25","action":"insert","data":[{"symbol":"ETHUSDT","id":32402486025,"side":"Sell","size":337000,"price":3111.72,"timestamp":"2024-05-18T15:46:16.605Z"},{"symbol":"ETHUSDT","id":32402501550,"side":"Sell","size":32000,"price":3110.57,"timestamp":"2024-05-18T15:46:16.605Z"},{"symbol":"ETHUSDT","id":32402501552,"side":"Buy","size":32000,"price":3109.39,"timestamp":"2024-05-18T15:46:16.605Z"},{"symbol":"ETHUSDT","id":32402501505,"side":"Buy","size":1000,"price":3109.08,"timestamp":"2024-05-18T15:46:16.605Z"}]}
{"table":"orderBookL2_25","action":"delete","data":[{"symbol":"XBTUSDT","id":32402501447,"side":"Sell","price":66807.1,"timestamp":"2024-05-18T15:46:16.628Z"},{"symbol":"XBTUSDT","id":32402501475,"side":"Sell","price":66800.6,"timestamp":"2024-05-18T15:46:16.628Z"},{"symbol":"XBTUSDT","id":32402491693,"side":"Sell","price":66808.3,"timestamp":"2024-05-18T15:46:16.628Z"},{"symbol":"XBTUSDT","id":32402500787,"side":"Sell","price":66798.0,"timestamp":"2024-05-18T15:46:16.628Z"},{"symbol":"XBTUSDT","id":32402501508,"side":"Buy","price":66771.0,"timestamp":"2024-05-18T15:46:16.628Z"},{"symbol":"XBTUSDT","id":32402498305,"side":"Buy","price":66786.6,"timestamp":"2024-05-18T15:46:16.628Z"},{"symbol":"XBTUSDT","id":32402497765,"side":"Buy","price":66786.4,"timestamp":"2024-05-18T15:46:16.628Z"},{"symbol":"XBTUSDT","id":32402501503,"side":"Buy","price":66770.9,"timestamp":"2024-05-18T15:46:16.628Z"},{"symbol":"XBTUSDT","id":32402498978,"side":"Buy","price":66777.3,"timestamp":"2024-05-18T15:46:16.628Z"},{"symbol":"XBTUSDT","id":32402501170,"side":"Buy","price":66752.3,"timestamp":"2024-05-18T15:46:16.628Z"},{"symbol":"XBTUSDT","id":32402497110,"side":"Buy","price":66786.3,"timestamp":"2024-05-18T15:46:16.628Z"}]}
{"table":"orderBookL2_25","action":"update","data":[{"symbol":"XBTUSDT","id":32402499234,"side":"Sell","size":40000,"price":66792.0,"timestamp":"2024-05-18T15:46:16.628Z"},{"symbol":"XBTUSDT","id":32402499454,"side":"Sell","size":2000,"price":66791.9,"timestamp":"2024-05-18T15:46:16.628Z"},{"symbol":"XBTUSDT","id":32402499098,"side":"Sell","size":100000,"price":66792.1,"timestamp":"2024-05-18T15:46:16.628Z"}]}
{"table":"orderBookL2_25","action":"insert","data":[{"symbol":"XBTUSDT","id":32402501573,"side":"Sell","size":140000,"price":66786.2,"timestamp":"2024-05-18T15:46:16.628Z"},{"symbol":"XBTUSDT","id":32402501582,"side":"Sell","size":349000,"price":66794.9,"timestamp":"2024-05-18T15:46:16.628Z"},{"symbol":"XBTUSDT","id":32402501612,"side":"Sell","size":1000,"price":66807.3,"timestamp":"2024-05-18T15:46:16.628Z"},{"symbol":"XBTUSDT","id":32402501518,"side":"Sell","size":20000,"price":66800.8,"timestamp":"2024-05-18T15:46:16.628Z"},{"symbol":"XBTUSDT","id":32402501627,"side":"Buy","size":20000,"price":66770.4,"timestamp":"2024-05-18T15:46:16.628Z"},{"symbol":"XBTUSDT","id":32402491723,"side":"Buy","size":543000,"price":66744.7,"timestamp":"2024-05-18T15:46:16.628Z"},{"symbol":"XBTUSDT","id":32402434478,"side":"Buy","size":100000,"price":66747.4,"timestamp":"2024-05-18T15:46:16.628Z"},{"symbol":"XBTUSDT","id":32402501542,"side":"Buy","size":20000,"price":66770.5,"timestamp":"2024-05-18T15:46:16.628Z"},{"symbol":"XBTUSDT","id":32402492536,"side":"Buy","size":1348000,"price":66748.7,"timestamp":"2024-05-18T15:46:16.628Z"},{"symbol":"XBTUSDT","id":32402501556,"side":"Buy","size":16000,"price":66777.4,"timestamp":"2024-05-18T15:46:16.628Z"},{"symbol":"XBTUSDT","id":32402501532,"side":"Buy","size":156000,"price":66757.7,"timestamp":"2024-05-18T15:46:16.628Z"}]}
{"table":"orderBookL2_25","action":"delete","data":[{"symbol":"XBTUSDT","id":32402499454,"side":"Sell","price":66791.9,"timestamp":"2024-05-18T15:46:16.677Z"},{"symbol":"XBTUSDT","id":32402501494,"side":"Sell","price":66800.7,"timestamp":"2024-05-18T15:46:16.677Z"},{"symbol":"XBTUSDT","id":32402491723,"side":"Buy","price":66744.7,"timestamp":"2024-05-18T15:46:16.677Z"}]}
{"table":"orderBookL2_25","action":"update","data":[{"symbol":"XBTUSDT","id":32402499569,"side":"Sell","size":49000,"price":66808.2,"timestamp":"2024-05-18T15:46:16.677Z"},{"symbol":"XBTUSDT","id":32402501573,"side":"Sell","size":146000,"price":66786.2,"timestamp":"2024-05-18T15:46:16.677Z"},{"symbol":"XBTUSDT","id":32402499236,"side":"Sell","size":149000,"price":66786.7,"timestamp":"2024-05-18T15:46:16.677Z"}]}
{"table":"orderBookL2_25","action":"insert","data":[{"symbol":"XBTUSDT","id":32402501655,"side":"Sell","size":2000,"price":66794.8,"timestamp":"2024-05-18T15:46:16.677Z"},{"symbol":"XBTUSDT","id":32402501637,"side":"Sell","size":20000,"price":66800.9,"timestamp":"2024-05-18T15:46:16.677Z"},{"symbol":"XBTUSDT","id":32402501662,"side":"Buy","size":36000,"price":66775.5,"timestamp":"2024-05-18T15:46:16.677Z"}]}
{"table":"orderBookL2_25","action":"delete","data":[{"symbol":"ETHUSDT","id":32402501550,"side":"Sell","price":3110.57,"timestamp":"2024-05-18T15:46:16.693Z"}]}
{"table":"orderBookL2_25","action":"insert","data":[{"symbol":"ETHUSDT","id":32402501707,"side":"Sell","size":32000,"price":3110.53,"timestamp":"2024-05-18T15:46:16.693Z"}]}
{"table":"orderBookL2_25","action":"delete","data":[{"symbol":"XBTUSDT","id":32402499096,"side":"Sell","price":66795.3,"timestamp":"2024-05-18T15:46:16.729Z"}]}
{"table":"orderBookL2_25","action":"insert","data":[{"symbol":"XBTUSDT","id":32402491693,"side":"Sell","size":74000,"price":66808.3,"timestamp":"2024-05-18T15:46:16.729Z"}]}
{"table":"orderBookL2_25","action":"delete","data":[{"symbol":"ETHUSDT","id":32402486025,"side":"Sell","price":3111.72,"timestamp":"2024-05-18T15:46:16.743Z"}]}
{"table":"orderBookL2_25","action":"update","data":[{"symbol":"ETHUSDT","id":32402500182,"side":"Sell","size":100000,"price":3110.56,"timestamp":"2024-05-18T15:46:16.743Z"}]}
{"table":"orderBookL2_25","action":"insert","data":[{"symbol":"ETHUSDT","id":32402501712,"side":"Sell","size":32000,"price":3110.52,"timestamp":"2024-05-18T15:46:16.743Z"}]}
{"table":"orderBookL2_25","action":"delete","data":[{"symbol":"XBTUSDT","id":32402499449,"side":"Sell","price":66788.6,"timestamp":"2024-05-18T15:46:16.778Z"},{"symbol":"XBTUSDT","id":32402434478,"side":"Buy","price":66747.4,"timestamp":"2024-05-18T15:46:16.778Z"},{"symbol":"XBTUSDT","id":32402492536,"side":"Buy","price":66748.7,"timestamp":"2024-05-18T15:46:16.778Z"}]}
{"table":"orderBookL2_25","action":"update","data":[{"symbol":"XBTUSDT","id":32402491693,"side":"Sell","size":74000,"price":66808.3,"timestamp":"2024-05-18T15:46:16.778Z"}]}
{"table":"orderBookL2_25","action":"insert","data":[{"symbol":"XBTUSDT","id":32402501736,"side":"Sell","size":40000,"price":66786.6,"timestamp":"2024-05-18T15:46:16.778Z"},{"symbol":"XBTUSDT","id":32402501781,"side":"Buy","size":11000,"price":66784.2,"timestamp":"2024-05-18T15:46:16.778Z"},{"symbol":"XBTUSDT","id":32402501786,"side":"Buy","size":228000,"price":66761.2,"timestamp":"2024-05-18T15:46:16.778Z"}]}
{"table":"orderBookL2_25","action":"delete","data":[{"symbol":"ETHUSDT","id":32402501412,"side":"Buy","price":3109.09,"timestamp":"2024-05-18T15:46:16.806Z"}]}
{"table":"orderBookL2_25","action":"insert","data":[{"symbol":"ETHUSDT","id":32402501865,"side":"Buy","size":1000,"price":3109.06,"timestamp":"2024-05-18T15:46:16.806Z"}]}
{"table":"orderBookL2_25","action":"delete","data":[{"symbol":"XBTUSDT","id":32402501501,"side":"Sell","price":66807.2,"timestamp":"2024-05-18T15:46:16.827Z"},{"symbol":"XBTUSDT","id":32402501612,"side":"Sell","price":66807.3,"timestamp":"2024-05-18T15:46:16.827Z"},{"symbol":"XBTUSDT","id":32402501532,"side":"Buy","price":66757.7,"timestamp":"2024-05-18T15:46:16.827Z"}]}
{"table":"orderBookL2_25","action":"update","data":[{"symbol":"XBTUSDT","id":32402501573,"side":"Sell","size":197000,"price":66786.2,"timestamp":"2024-05-18T15:46:16.827Z"}]}
{"table":"orderBookL2_25","action":"insert","data":[{"symbol":"XBTUSDT","id":32402501901,"side":"Sell","size":1000,"price":66807.2,"timestamp":"2024-05-18T15:46:16.827Z"},{"symbol":"XBTUSDT","id":32402501870,"side":"Sell","size":1000,"price":66807.1,"timestamp":"2024-05-18T15:46:16.827Z"},{"symbol":"XBTUSDT","id":32402501847,"side":"Buy","size":65000,"price":66757.7,"timestamp":"2024-05-18T15:46:16.827Z"}]}
{"table":"orderBookL2_25","action":"delete","data":[{"symbol":"ETHUSDT","id":32402491370,"side":"Sell","price":3111.53,"timestamp":"2024-05-18T15:46:16.856Z"},{"symbol":"ETHUSDT","id":32402487305,"side":"Sell","price":3111.65,"timestamp":"2024-05-18T15:46:16.856Z"},{"symbol":"ETHUSDT","id":32402487294,"side":"Sell","price":3111.54,"timestamp":"2024-05-18T15:46:16.856Z"},{"symbol":"ETHUSDT","id":32402501865,"side":"Buy","price":3109.06,"timestamp":"2024-05-18T15:46:16.856Z"},{"symbol":"ETHUSDT","id":32402493174,"side":"Buy","price":3109.41,"timestamp":"2024-05-18T15:46:16.856Z"},{"symbol":"ETHUSDT","id":32402501505,"side":"Buy","price":3109.08,"timestamp":"2024-05-18T15:46:16.856Z"}]}
{"table":"orderBookL2_25","action":"insert","data":[{"symbol":"ETHUSDT","id":32402501920,"side":"Sell","size":100000,"price":3110.36,"timestamp":"2024-05-18T15:46:16.856Z"},{"symbol":"ETHUSDT","id":32402501905,"side":"Sell","size":100000,"price":3109.56,"timestamp":"2024-05-18T15:46:16.856Z"},{"symbol":"ETHUSDT","id":32402501903,"side":"Sell","size":66000,"price":3109.67,"timestamp":"2024-05-18T15:46:16.856Z"},{"symbol":"ETHUSDT","id":32402480341,"side":"Buy","size":942000,"price":3106.76,"timestamp":"2024-05-18T15:46:16.856Z"},{"symbol":"ETHUSDT","id":32402501908,"side":"Buy","size":1000,"price":3109.15,"timestamp":"2024-05-18T15:46:16.856Z"},{"symbol":"ETHUSDT","id":32402501896,"side":"Buy","size":1000,"price":3109.14,"timestamp":"2024-05-18T15:46:16.856Z"}]}
{"table":"orderBookL2_25","action":"delete","data":[{"symbol":"XBTUSDT","id":32402499569,"side":"Sell","price":66808.2,"timestamp":"2024-05-18T15:46:16.876Z"},{"symbol":"XBTUSDT","id":32402491693,"side":"Sell","price":66808.3,"timestamp":"2024-05-18T15:46:16.876Z"},{"symbol":"XBTUSDT","id":32402501637,"side":"Sell","price":66800.9,"timestamp":"2024-05-18T15:46:16.876Z"},{"symbol":"XBTUSDT","id":32402501542,"side":"Buy","price":66770.5,"timestamp":"2024-05-18T15:46:16.876Z"},{"symbol":"XBTUSDT","id":32402492889,"side":"Buy","price":66750.8,"timestamp":"2024-05-18T15:46:16.876Z"}]}
{"table":"orderBookL2_25","action":"update","data":[{"symbol":"XBTUSDT","id":32402499236,"side":"Sell","size":109000,"price":66786.7,"timestamp":"2024-05-18T15:46:16.876Z"},{"symbol":"XBTUSDT","id":32402491799,"side":"Sell","size":12000,"price":66795.4,"timestamp":"2024-05-18T15:46:16.876Z"}]}
{"table":"orderBookL2_25","action":"insert","data":[{"symbol":"XBTUSDT","id":32402501930,"side":"Sell","size":2000,"price":66792.7,"timestamp":"2024-05-18T15:46:16.876Z"},{"symbol":"XBTUSDT","id":32402501970,"side":"Sell","size":68000,"price":66788.6,"timestamp":"2024-05-18T15:46:16.876Z"},{"symbol":"XBTUSDT","id":32402501964,"side":"Sell","size":20000,"price":66800.7,"timestamp":"2024-05-18T15:46:16.876Z"},{"symbol":"XBTUSDT","id":32402501977,"side":"Buy","size":8000,"price":66780.1,"timestamp":"2024-05-18T15:46:16.876Z"},{"symbol":"XBTUSDT","id":32402501960,"side":"Buy","size":20000,"price":66770.3,"timestamp":"2024-05-18T15:46:16.876Z"}]}
{"table":"orderBookL2_25","action":"delete","data":[{"symbol":"ETHUSDT","id":32402484839,"side":"Sell","price":3111.49,"timestamp":"2024-05-18T15:46:16.905Z"},{"symbol":"ETHUSDT","id":32402501707,"side":"Sell","price":3110.53,"timestamp":"2024-05-18T15:46:16.905Z"},{"symbol":"ETHUSDT","id":32402501299,"side":"Buy","price":3109.38,"timestamp":"2024-05-18T15:46:16.905Z"}]}
{"table":"orderBookL2_25","action":"update","data":[{"symbol":"ETHUSDT","id":32401945550,"side":"Buy","size":104000,"price":3109.40,"timestamp":"2024-05-18T15:46:16.905Z"}]}
{"table":"orderBookL2_25","action":"insert","data":[{"symbol":"ETHUSDT","id":32402501973,"side":"Sell","size":32000,"price":3110.51,"timestamp":"2024-05-18T15:46:16.905Z"},{"symbol":"ETHUSDT","id":32402501981,"side":"Sell","size":28000,"price":3109.92,"timestamp":"2024-05-18T15:46:16.905Z"},{"symbol":"ETHUSDT","id":32402354519,"side":"Buy","size":100000,"price":3106.60,"timestamp":"2024-05-18T15:46:16.905Z"}]}
{"table":"orderBookL2_25","action":"delete","data":[{"symbol":"XBTUSDT","id":32402501901,"side":"Sell","price":66807.2,"timestamp":"2024-05-18T15:46:16.925Z"},{"symbol":"XBTUSDT","id":32402494980,"side":"Buy","price":66751.4,"timestamp":"2024-05-18T15:46:16.925Z"},{"symbol":"XBTUSDT","id":32402492129,"side":"Buy","price":66752.1,"timestamp":"2024-05-18T15:46:16.925Z"}]}
{"table":"orderBookL2_25","action":"insert","data":[{"symbol":"XBTUSDT","id":32402502013,"side":"Sell","size":33000,"price":66791.9,"timestamp":"2024-05-18T15:46:16.925Z"},{"symbol":"XBTUSDT","id":32402502006,"side":"Buy","size":156000,"price":66752.3,"timestamp":"2024-05-18T15:46:16.925Z"},{"symbol":"XBTUSDT","id":32402502027,"side":"Buy","size":8000,"price":66775.6,"timestamp":"2024-05-18T15:46:16.925Z"}]}
{"table":"orderBookL2_25","action":"delete","data":[{"symbol":"ETHUSDT","id":32402500254,"side":"Sell","price":3110.04,"timestamp":"2024-05-18T15:46:16.954Z"},{"symbol":"ETHUSDT","id":32402354519,"side":"Buy","price":3106.60,"timestamp":"2024-05-18T15:46:16.954Z"}]}
{"table":"orderBookL2_25","action":"update","data":[{"symbol":"ETHUSDT","id":32402494506,"side":"Sell","size":65000,"price":3111.48,"timestamp":"2024-05-18T15:46:16.954Z"}]}
{"table":"orderBookL2_25","action":"insert","data":[{"symbol":"ETHUSDT","id":32402502023,"side":"Sell","size":24000,"price":3109.91,"timestamp":"2024-05-18T15:46:16.954Z"},{"symbol":"ETHUSDT","id":32402502019,"side":"Buy","size":43000,"price":3109.41,"timestamp":"2024-05-18T15:46:16.954Z"}]}
{"table":"orderBookL2_25","action":"delete","data":[{"symbol":"XBTUSDT","id":32402501582,"side":"Sell","price":66794.9,"timestamp":"2024-05-18T15:46:16.974Z"},{"symbol":"XBTUSDT","id":32402501847,"side":"Buy","price":66757.7,"timestamp":"2024-05-18T15:46:16.974Z"},{"symbol":"XBTUSDT","id":32402501786,"side":"Buy","price":66761.2,"timestamp":"2024-05-18T15:46:16.974Z"},{"symbol":"XBTUSDT","id":32402501137,"side":"Buy","price":66761.1,"timestamp":"2024-05-18T15:46:16.974Z"}]}
{"table":"orderBookL2_25","action":"insert","data":[{"symbol":"XBTUSDT","id":32402502065,"side":"Sell","size":372000,"price":66798.0,"timestamp":"2024-05-18T15:46:16.974Z"},{"symbol":"XBTUSDT","id":32402494980,"side":"Buy","size":74000,"price":66751.4,"timestamp":"2024-05-18T15:46:16.974Z"},{"symbol":"XBTUSDT","id":32402502067,"side":"Buy","size":355000,"price":66761.3,"timestamp":"2024-05-18T15:46:16.974Z"},{"symbol":"XBTUSDT","id":32402492129,"side":"Buy","size":1502000,"price":66752.1,"timestamp":"2024-05-18T15:46:16.974Z"}]}
{"table":"orderBookL2_25","action":"delete","data":[{"symbol":"ETHUSDT","id":32402497834,"side":"Buy","price":3107.98,"timestamp":"2024-05-18T15:46:17.010Z"}]}
{"table":"orderBookL2_25","action":"insert","data":[{"symbol":"ETHUSDT","id":32402502093,"side":"Buy","size":550000,"price":3107.80,"timestamp":"2024-05-18T15:46:17.010Z"}]}
{"table":"orderBookL2_25","action":"delete","data":[{"symbol":"XBTUSDT","id":32402502065,"side":"Sell","price":66798.0,"timestamp":"2024-05-18T15:46:17.023Z"},{"symbol":"XBTUSDT","id":32402501655,"side":"Sell","price":66794.8,"timestamp":"2024-05-18T15:46:17.023Z"},{"symbol":"XBTUSDT","id":32402494980,"side":"Buy","price":66751.4,"timestamp":"2024-05-18T15:46:17.023Z"}]}
{"table":"orderBookL2_25","action":"update","data":[{"symbol":"XBTUSDT","id":32402501870,"side":"Sell","size":1000,"price":66807.1,"timestamp":"2024-05-18T15:46:17.023Z"}]}
{"table":"orderBookL2_25","action":"insert","data":[{"symbol":"XBTUSDT","id":32402502089,"side":"Sell","size":213000,"price":66794.9,"timestamp":"2024-05-18T15:46:17.023Z"},{"symbol":"XBTUSDT","id":32402502082,"side":"Sell","size":350000,"price":66795.3,"timestamp":"2024-05-18T15:46:17.023Z"},{"symbol":"XBTUSDT","id":32402502086,"side":"Buy","size":213000,"price":66761.4,"timestamp":"2024-05-18T15:46:17.023Z"}]}
{"table":"orderBookL2_25","action":"delete","data":[{"symbol":"ETHUSDT","id":32402480341,"side":"Buy","price":3106.76,"timestamp":"2024-05-18T15:46:17.060Z"},{"symbol":"ETHUSDT","id":32402501896,"side":"Buy","price":3109.14,"timestamp":"2024-05-18T15:46:17.060Z"}]}
{"table":"orderBookL2_25","action":"update","data":[{"symbol":"ETHUSDT","id":32401945550,"side":"Buy","size":72000,"price":3109.40,"timestamp":"2024-05-18T15:46:17.060Z"}]}
{"table":"orderBookL2_25","action":"insert","data":[{"symbol":"ETHUSDT","id":32402502110,"side":"Buy","size":1000,"price":3109.16,"timestamp":"2024-05-18T15:46:17.060Z"},{"symbol":"ETHUSDT","id":32402502137,"side":"Buy","size":32000,"price":3109.38,"timestamp":"2024-05-18T15:46:17.060Z"}]}
{"table":"orderBookL2_25","action":"delete","data":[{"symbol":"XBTUSDT","id":32402501870,"side":"Sell","price":66807.1,"timestamp":"2024-05-18T15:46:17.072Z"},{"symbol":"XBTUSDT","id":32402501964,"side":"Sell","price":66800.7,"timestamp":"2024-05-18T15:46:17.072Z"},{"symbol":"XBTUSDT","id":32402501518,"side":"Sell","price":66800.8,"timestamp":"2024-05-18T15:46:17.072Z"},{"symbol":"XBTUSDT","id":32402501627,"side":"Buy","price":66770.4,"timestamp":"2024-05-18T15:46:17.072Z"},{"symbol":"XBTUSDT","id":32402501960,"side":"Buy","price":66770.3,"timestamp":"2024-05-18T15:46:17.072Z"}]}
{"table":"orderBookL2_25","action":"insert","data":[{"symbol":"XBTUSDT","id":32402502112,"side":"Sell","size":62000,"price":66800.6,"timestamp":"2024-05-18T15:46:17.072Z"},{"symbol":"XBTUSDT","id":32402502155,"side":"Sell","size":20000,"price":66800.8,"timestamp":"2024-05-18T15:46:17.072Z"},{"symbol":"XBTUSDT","id":32402502144,"side":"Sell","size":20000,"price":66800.9,"timestamp":"2024-05-18T15:46:17.072Z"},{"symbol":"XBTUSDT","id":32402502153,"side":"Buy","size":20000,"price":66770.3,"timestamp":"2024-05-18T15:46:17.072Z"},{"symbol":"XBTUSDT","id":32402502128,"side":"Buy","size":20000,"price":66771.2,"timestamp":"2024-05-18T15:46:17.072Z"}]}
{"table":"orderBookL2_25","action":"delete","data":[{"symbol":"ETHUSDT","id":32402501973,"side":"Sell","price":3110.51,"timestamp":"2024-05-18T15:46:17.109Z"},{"symbol":"ETHUSDT","id":32402501712,"side":"Sell","price":3110.52,"timestamp":"2024-05-18T15:46:17.109Z"},{"symbol":"ETHUSDT","id":32402502137,"side":"Buy","price":3109.38,"timestamp":"2024-05-18T15:46:17.109Z"},{"symbol":"ETHUSDT","id":32402501908,"side":"Buy","price":3109.15,"timestamp":"2024-05-18T15:46:17.109Z"},{"symbol":"ETHUSDT","id":32402501552,"side":"Buy","price":3109.39,"timestamp":"2024-05-18T15:46:17.109Z"},{"symbol":"ETHUSDT","id":32402502110,"side":"Buy","price":3109.16,"timestamp":"2024-05-18T15:46:17.109Z"}]}
{"table":"orderBookL2_25","action":"update","data":[{"symbol":"ETHUSDT","id":32402500182,"side":"Sell","size":132000,"price":3110.56,"timestamp":"2024-05-18T15:46:17.109Z"}]}
{"table":"orderBookL2_25","action":"insert","data":[{"symbol":"ETHUSDT","id":32402484839,"side":"Sell","size":100000,"price":3111.49,"timestamp":"2024-05-18T15:46:17.109Z"},{"symbol":"ETHUSDT","id":32402502187,"side":"Sell","size":32000,"price":3110.57,"timestamp":"2024-05-18T15:46:17.109Z"},{"symbol":"ETHUSDT","id":32402502159,"side":"Buy","size":32000,"price":3109.35,"timestamp":"2024-05-18T15:46:17.109Z"},{"symbol":"ETHUSDT","id":32402502190,"side":"Buy","size":32000,"price":3109.34,"timestamp":"2024-05-18T15:46:17.109Z"},{"symbol":"ETHUSDT","id":32402502146,"side":"Buy","size":1000,"price":3109.10,"timestamp":"2024-05-18T15:46:17.109Z"},{"symbol":"ETHUSDT","id":32402502148,"side":"Buy","size":1000,"price":3109.09,"timestamp":"2024-05-18T15:46:17.109Z"}]}
{"table":"orderBookL2_25","action":"delete","data":[{"symbol":"XBTUSDT","id":32402502128,"side":"Buy","price":66771.2,"timestamp":"2024-05-18T15:46:17.121Z"}]}
{"table":"orderBookL2_25","action":"insert","data":[{"symbol":"XBTUSDT","id":32402502157,"side":"Buy","size":20000,"price":66770.2,"timestamp":"2024-05-18T15:46:17.121Z"}]}
{"table":"orderBookL2_25","action":"delete","data":[{"symbol":"ETHUSDT","id":32402502148,"side":"Buy","price":3109.09,"timestamp":"2024-05-18T15:46:17.167Z"}]}
{"table":"orderBookL2_25","action":"insert","data":[{"symbol":"ETHUSDT","id":32402502269,"side":"Buy","size":1000,"price":3109.07,"timestamp":"2024-05-18T15:46:17.167Z"}]}
{"table":"orderBookL2_25","action":"delete","data":[{"symbol":"XBTUSDT","id":32402502155,"side":"Sell","price":66800.8,"timestamp":"2024-05-18T15:46:17.170Z"},{"symbol":"XBTUSDT","id":32402502144,"side":"Sell","price":66800.9,"timestamp":"2024-05-18T15:46:17.170Z"},{"symbol":"XBTUSDT","id":32402492129,"side":"Buy","price":66752.1,"timestamp":"2024-05-18T15:46:17.170Z"},{"symbol":"XBTUSDT","id":32402495049,"side":"Buy","price":66752.2,"timestamp":"2024-05-18T15:46:17.170Z"},{"symbol":"XBTUSDT","id":32402502153,"side":"Buy","price":66770.3,"timestamp":"2024-05-18T15:46:17.170Z"},{"symbol":"XBTUSDT","id":32402502157,"side":"Buy","price":66770.2,"timestamp":"2024-05-18T15:46:17.170Z"}]}
{"table":"orderBookL2_25","action":"update","data":[{"symbol":"XBTUSDT","id":32402502112,"side":"Sell","size":62000,"price":66800.6,"timestamp":"2024-05-18T15:46:17.170Z"},{"symbol":"XBTUSDT","id":32402501662,"side":"Buy","size":44000,"price":66775.5,"timestamp":"2024-05-18T15:46:17.170Z"}]}
{"table":"orderBookL2_25","action":"insert","data":[{"symbol":"XBTUSDT","id":32402502263,"side":"Sell","size":20000,"price":66801.0,"timestamp":"2024-05-18T15:46:17.170Z"},{"symbol":"XBTUSDT","id":32402502261,"side":"Sell","size":20000,"price":66800.9,"timestamp":"2024-05-18T15:46:17.170Z"},{"symbol":"XBTUSDT","id":32402502233,"side":"Buy","size":64000,"price":66757.7,"timestamp":"2024-05-18T15:46:17.170Z"},{"symbol":"XBTUSDT","id":32402502225,"side":"Buy","size":8000,"price":66775.7,"timestamp":"2024-05-18T15:46:17.170Z"},{"symbol":"XBTUSDT","id":32402502257,"side":"Buy","size":20000,"price":66770.1,"timestamp":"2024-05-18T15:46:17.170Z"},{"symbol":"XBTUSDT","id":32402502259,"side":"Buy","size":20000,"price":66770.2,"timestamp":"2024-05-18T15:46:17.170Z"}]}
{"table":"orderBookL2_25","action":"delete","data":[{"symbol":"ETHUSDT","id":32402502187,"side":"Sell","price":3110.57,"timestamp":"2024-05-18T15:46:17.216Z"},{"symbol":"ETHUSDT","id":32402502190,"side":"Buy","price":3109.34,"timestamp":"2024-05-18T15:46:17.216Z"},{"symbol":"ETHUSDT","id":32402502159,"side":"Buy","price":3109.35,"timestamp":"2024-05-18T15:46:17.216Z"},{"symbol":"ETHUSDT","id":32402502146,"side":"Buy","price":3109.10,"timestamp":"2024-05-18T15:46:17.216Z"}]}
{"table":"orderBookL2_25","action":"insert","data":[{"symbol":"ETHUSDT","id":32402502336,"side":"Sell","size":32000,"price":3110.55,"timestamp":"2024-05-18T15:46:17.216Z"},{"symbol":"ETHUSDT","id":32402502342,"side":"Buy","size":32000,"price":3109.31,"timestamp":"2024-05-18T15:46:17.216Z"},{"symbol":"ETHUSDT","id":32402502272,"side":"Buy","size":1000,"price":3109.08,"timestamp":"2024-05-18T15:46:17.216Z"},{"symbol":"ETHUSDT","id":32402502305,"side":"Buy","size":32000,"price":3109.32,"timestamp":"2024-05-18T15:46:17.216Z"}]}
{"table":"orderBookL2_25","action":"delete","data":[{"symbol":"XBTUSDT","id":32402502082,"side":"Sell","price":66795.3,"timestamp":"2024-05-18T15:46:17.219Z"},{"symbol":"XBTUSDT","id":32402499206,"side":"Sell","price":66795.0,"timestamp":"2024-05-18T15:46:17.219Z"},{"symbol":"XBTUSDT","id":32402502067,"side":"Buy","price":66761.3,"timestamp":"2024-05-18T15:46:17.219Z"},{"symbol":"XBTUSDT","id":32402502086,"side":"Buy","price":66761.4,"timestamp":"2024-05-18T15:46:17.219Z"},{"symbol":"XBTUSDT","id":32402502233,"side":"Buy","price":66757.7,"timestamp":"2024-05-18T15:46:17.219Z"}]}
{"table":"orderBookL2_25","action":"update","data":[{"symbol":"XBTUSDT","id":32402472771,"side":"Sell","size":100000,"price":66805.3,"timestamp":"2024-05-18T15:46:17.219Z"},{"symbol":"XBTUSDT","id":32402502089,"side":"Sell","size":2000,"price":66794.9,"timestamp":"2024-05-18T15:46:17.219Z"}]}
{"table":"orderBookL2_25","action":"insert","data":[{"symbol":"XBTUSDT","id":32402502303,"side":"Sell","size":508000,"price":66794.8,"timestamp":"2024-05-18T15:46:17.219Z"},{"symbol":"XBTUSDT","id":32402502274,"side":"Sell","size":22000,"price":66799.8,"timestamp":"2024-05-18T15:46:17.219Z"},{"symbol":"XBTUSDT","id":32402492129,"side":"Buy","size":1502000,"price":66752.1,"timestamp":"2024-05-18T15:46:17.219Z"},{"symbol":"XBTUSDT","id":32402495049,"side":"Buy","size":878000,"price":66752.2,"timestamp":"2024-05-18T15:46:17.219Z"},{"symbol":"XBTUSDT","id":32402502329,"side":"Buy","size":350000,"price":66761.1,"timestamp":"2024-05-18T15:46:17.219Z"}]}
{"table":"orderBookL2_25","action":"delete","data":[{"symbol":"ETHUSDT","id":32402502336,"side":"Sell","price":3110.55,"timestamp":"2024-05-18T15:46:17.265Z"},{"symbol":"ETHUSDT","id":32402502272,"side":"Buy","price":3109.08,"timestamp":"2024-05-18T15:46:17.265Z"},{"symbol":"ETHUSDT","id":32402502269,"side":"Buy","price":3109.07,"timestamp":"2024-05-18T15:46:17.265Z"},{"symbol":"ETHUSDT","id":32402502305,"side":"Buy","price":3109.32,"timestamp":"2024-05-18T15:46:17.265Z"}]}
{"table":"orderBookL2_25","action":"insert","data":[{"symbol":"ETHUSDT","id":32402502388,"side":"Sell","size":32000,"price":3110.57,"timestamp":"2024-05-18T15:46:17.265Z"},{"symbol":"ETHUSDT","id":32402502367,"side":"Buy","size":1000,"price":3109.06,"timestamp":"2024-05-18T15:46:17.265Z"},{"symbol":"ETHUSDT","id":32402502381,"side":"Buy","size":32000,"price":3109.30,"timestamp":"2024-05-18T15:46:17.265Z"},{"symbol":"ETHUSDT","id":32402502369,"side":"Buy","size":1000,"price":3109.05,"timestamp":"2024-05-18T15:46:17.265Z"}]}
{"table":"orderBookL2_25","action":"delete","data":[{"symbol":"XBTUSDT","id":32402493768,"side":"Sell","price":66801.4,"timestamp":"2024-05-18T15:46:17.268Z"},{"symbol":"XBTUSDT","id":32402502089,"side":"Sell","price":66794.9,"timestamp":"2024-05-18T15:46:17.268Z"},{"symbol":"XBTUSDT","id":32402492129,"side":"Buy","price":66752.1,"timestamp":"2024-05-18T15:46:17.268Z"},{"symbol":"XBTUSDT","id":32402495049,"side":"Buy","price":66752.2,"timestamp":"2024-05-18T15:46:17.268Z"}]}
{"table":"orderBookL2_25","action":"insert","data":[{"symbol":"XBTUSDT","id":32402502246,"side":"Sell","size":1000,"price":66807.2,"timestamp":"2024-05-18T15:46:17.268Z"},{"symbol":"XBTUSDT","id":32402502386,"side":"Sell","size":316000,"price":66794.7,"timestamp":"2024-05-18T15:46:17.268Z"},{"symbol":"XBTUSDT","id":32402502384,"side":"Buy","size":217000,"price":66761.2,"timestamp":"2024-05-18T15:46:17.268Z"},{"symbol":"XBTUSDT","id":32402502412,"side":"Buy","size":68000,"price":66757.7,"timestamp":"2024-05-18T15:46:17.268Z"}]}
{"table":"orderBookL2_25","action":"delete","data":[{"symbol":"ETHUSDT","id":32402502381,"side":"Buy","price":3109.30,"timestamp":"2024-05-18T15:46:17.393Z"}]}
{"table":"orderBookL2_25","action":"insert","data":[{"symbol":"ETHUSDT","id":32402502583,"side":"Buy","size":32000,"price":3109.32,"timestamp":"2024-05-18T15:46:17.393Z"}]}
{"table":"orderBookL2_25","action":"delete","data":[{"symbol":"ETHUSDT","id":32402502388,"side":"Sell","price":3110.57,"timestamp":"2024-05-18T15:46:17.442Z"},{"symbol":"ETHUSDT","id":32402484839,"side":"Sell","price":3111.49,"timestamp":"2024-05-18T15:46:17.442Z"},{"symbol":"ETHUSDT","id":32402502583,"side":"Buy","price":3109.32,"timestamp":"2024-05-18T15:46:17.442Z"},{"symbol":"ETHUSDT","id":32402501375,"side":"Buy","price":3108.45,"timestamp":"2024-05-18T15:46:17.442Z"}]}
{"table":"orderBookL2_25","action":"update","data":[{"symbol":"ETHUSDT","id":32402500182,"side":"Sell","size":100000,"price":3110.56,"timestamp":"2024-05-18T15:46:17.442Z"}]}
{"table":"orderBookL2_25","action":"insert","data":[{"symbol":"ETHUSDT","id":32402502596,"side":"Sell","size":32000,"price":3110.54,"timestamp":"2024-05-18T15:46:17.442Z"},{"symbol":"ETHUSDT","id":32402502586,"side":"Sell","size":32000,"price":3110.55,"timestamp":"2024-05-18T15:46:17.442Z"},{"symbol":"ETHUSDT","id":32402480341,"side":"Buy","size":942000,"price":3106.76,"timestamp":"2024-05-18T15:46:17.442Z"},{"symbol":"ETHUSDT","id":32402502594,"side":"Buy","size":32000,"price":3109.30,"timestamp":"2024-05-18T15:46:17.442Z"}]}
{"table":"orderBookL2_25","action":"delete","data":[{"symbol":"XBTUSDT","id":32402502259,"side":"Buy","price":66770.2,"timestamp":"2024-05-18T15:46:17.457Z"}]}
{"table":"orderBookL2_25","action":"insert","data":[{"symbol":"XBTUSDT","id":32402502661,"side":"Buy","size":20000,"price":66770.8,"timestamp":"2024-05-18T15:46:17.457Z"}]}
{"table":"orderBookL2_25","action":"delete","data":[{"symbol":"ETHUSDT","id":32402502596,"side":"Sell","price":3110.54,"timestamp":"2024-05-18T15:46:17.491Z"},{"symbol":"ETHUSDT","id":32402502342,"side":"Buy","price":3109.31,"timestamp":"2024-05-18T15:46:17.491Z"},{"symbol":"ETHUSDT","id":32402502367,"side":"Buy","price":3109.06,"timestamp":"2024-05-18T15:46:17.491Z"}]}
{"table":"orderBookL2_25","action":"update","data":[{"symbol":"ETHUSDT","id":32402500182,"side":"Sell","size":132000,"price":3110.56,"timestamp":"2024-05-18T15:46:17.491Z"}]}
{"table":"orderBookL2_25","action":"insert","data":[{"symbol":"ETHUSDT","id":32402484839,"side":"Sell","size":100000,"price":3111.49,"timestamp":"2024-05-18T15:46:17.491Z"},{"symbol":"ETHUSDT","id":32402502648,"side":"Buy","size":1000,"price":3109.04,"timestamp":"2024-05-18T15:46:17.491Z"},{"symbol":"ETHUSDT","id":32402502656,"side":"Buy","size":32000,"price":3109.29,"timestamp":"2024-05-18T15:46:17.491Z"}]}
{"table":"orderBookL2_25","action":"delete","data":[{"symbol":"XBTUSDT","id":32402502246,"side":"Sell","price":66807.2,"timestamp":"2024-05-18T15:46:17.507Z"},{"symbol":"XBTUSDT","id":32402502263,"side":"Sell","price":66801.0,"timestamp":"2024-05-18T15:46:17.507Z"},{"symbol":"XBTUSDT","id":32402502261,"side":"Sell","price":66800.9,"timestamp":"2024-05-18T15:46:17.507Z"},{"symbol":"XBTUSDT","id":32402502661,"side":"Buy","price":66770.8,"timestamp":"2024-05-18T15:46:17.507Z"},{"symbol":"XBTUSDT","id":32402502225,"side":"Buy","price":66775.7,"timestamp":"2024-05-18T15:46:17.507Z"},{"symbol":"XBTUSDT","id":32402502257,"side":"Buy","price":66770.1,"timestamp":"2024-05-18T15:46:17.507Z"}]}
{"table":"orderBookL2_25","action":"update","data":[{"symbol":"XBTUSDT","id":32402502112,"side":"Sell","size":62000,"price":66800.6,"timestamp":"2024-05-18T15:46:17.507Z"},{"symbol":"XBTUSDT","id":32402502303,"side":"Sell","size":352000,"price":66794.8,"timestamp":"2024-05-18T15:46:17.507Z"},{"symbol":"XBTUSDT","id":32402502386,"side":"Sell","size":213000,"price":66794.7,"timestamp":"2024-05-18T15:46:17.507Z"},{"symbol":"XBTUSDT","id":32402501662,"side":"Buy","size":36000,"price":66775.5,"timestamp":"2024-05-18T15:46:17.507Z"},{"symbol":"XBTUSDT","id":32402227172,"side":"Buy","size":11000,"price":66780.0,"timestamp":"2024-05-18T15:46:17.507Z"}]}
{"table":"orderBookL2_25","action":"insert","data":[{"symbol":"XBTUSDT","id":32402502676,"side":"Sell","size":20000,"price":66801.0,"timestamp":"2024-05-18T15:46:17.507Z"},{"symbol":"XBTUSDT","id":32402502728,"side":"Sell","size":156000,"price":66794.6,"timestamp":"2024-05-18T15:46:17.507Z"},{"symbol":"XBTUSDT","id":32402502681,"side":"Sell","size":20000,"price":66800.9,"timestamp":"2024-05-18T15:46:17.507Z"},{"symbol":"XBTUSDT","id":32402502672,"side":"Buy","size":20000,"price":66770.2,"timestamp":"2024-05-18T15:46:17.507Z"},{"symbol":"XBTUSDT","id":32402502683,"side":"Buy","size":20000,"price":66770.1,"timestamp":"2024-05-18T15:46:17.507Z"},{"symbol":"XBTUSDT","id":32402502755,"side":"Buy","size":8000,"price":66775.8,"timestamp":"2024-05-18T15:46:17.507Z"}]}
{"table":"orderBookL2_25","action":"delete","data":[{"symbol":"ETHUSDT","id":32402484839,"side":"Sell","price":3111.49,"timestamp":"2024-05-18T15:46:17.551Z"}]}
{"table":"orderBookL2_25","action":"update","data":[{"symbol":"ETHUSDT","id":32402500182,"side":"Sell","size":100000,"price":3110.56,"timestamp":"2024-05-18T15:46:17.551Z"}]}
{"table":"orderBookL2_25","action":"insert","data":[{"symbol":"ETHUSDT","id":32402502814,"side":"Sell","size":32000,"price":3110.54,"timestamp":"2024-05-18T15:46:17.551Z"}]}
{"table":"orderBookL2_25","action":"delete","data":[{"symbol":"XBTUSDT","id":32402472771,"side":"Sell","price":66805.3,"timestamp":"2024-05-18T15:46:17.556Z"}]}
{"table":"orderBookL2_25","action":"update","data":[{"symbol":"XBTUSDT","id":32402502386,"side":"Sell","size":211000,"price":66794.7,"timestamp":"2024-05-18T15:46:17.556Z"}]}
{"table":"orderBookL2_25","action":"insert","data":[{"symbol":"XBTUSDT","id":32402502816,"side":"Sell","size":2000,"price":66794.5,"timestamp":"2024-05-18T15:46:17.556Z"}]}
{"table":"orderBookL2_25","action":"delete","data":[{"symbol":"ETHUSDT","id":32402502814,"side":"Sell","price":3110.54,"timestamp":"2024-05-18T15:46:17.600Z"},{"symbol":"ETHUSDT","id":32402502594,"side":"Buy","price":3109.30,"timestamp":"2024-05-18T15:46:17.600Z"}]}
{"table":"orderBookL2_25","action":"update","data":[{"symbol":"ETHUSDT","id":32402500182,"side":"Sell","size":132000,"price":3110.56,"timestamp":"2024-05-18T15:46:17.600Z"}]}
{"table":"orderBookL2_25","action":"insert","data":[{"symbol":"ETHUSDT","id":32402484839,"side":"Sell","size":100000,"price":3111.49,"timestamp":"2024-05-18T15:46:17.600Z"},{"symbol":"ETHUSDT","id":32402502832,"side":"Buy","size":32000,"price":3109.30,"timestamp":"2024-05-18T15:46:17.600Z"}]}
{"table":"orderBookL2_25","action":"delete","data":[{"symbol":"XBTUSDT","id":32402480133,"side":"Sell","price":66803.0,"timestamp":"2024-05-18T15:46:17.605Z"},{"symbol":"XBTUSDT","id":32402501662,"side":"Buy","price":66775.5,"timestamp":"2024-05-18T15:46:17.605Z"},{"symbol":"XBTUSDT","id":32402493723,"side":"Buy","price":66786.1,"timestamp":"2024-05-18T15:46:17.605Z"}]}
{"table":"orderBookL2_25","action":"update","data":[{"symbol":"XBTUSDT","id":32402501573,"side":"Sell","size":140000,"price":66786.2,"timestamp":"2024-05-18T15:46:17.605Z"},{"symbol":"XBTUSDT","id":32402499236,"side":"Sell","size":9000,"price":66786.7,"timestamp":"2024-05-18T15:46:17.605Z"}]}
{"table":"orderBookL2_25","action":"insert","data":[{"symbol":"XBTUSDT","id":32402502861,"side":"Sell","size":305000,"price":66784.3,"timestamp":"2024-05-18T15:46:17.605Z"},{"symbol":"XBTUSDT","id":32402495049,"side":"Buy","size":878000,"price":66752.2,"timestamp":"2024-05-18T15:46:17.605Z"},{"symbol":"XBTUSDT","id":32402502898,"side":"Buy","size":36000,"price":66773.5,"timestamp":"2024-05-18T15:46:17.605Z"}]}
{"table":"orderBookL2_25","action":"delete","data":[{"symbol":"ETHUSDT","id":32402484839,"side":"Sell","price":3111.49,"timestamp":"2024-05-18T15:46:17.649Z"},{"symbol":"ETHUSDT","id":32402502369,"side":"Buy","price":3109.05,"timestamp":"2024-05-18T15:46:17.649Z"},{"symbol":"ETHUSDT","id":32402502832,"side":"Buy","price":3109.30,"timestamp":"2024-05-18T15:46:17.649Z"}]}
{"table":"orderBookL2_25","action":"update","data":[{"symbol":"ETHUSDT","id":32402500182,"side":"Sell","size":100000,"price":3110.56,"timestamp":"2024-05-18T15:46:17.649Z"}]}
{"table":"orderBookL2_25","action":"insert","data":[{"symbol":"ETHUSDT","id":32402502935,"side":"Sell","size":32000,"price":3110.54,"timestamp":"2024-05-18T15:46:17.649Z"},{"symbol":"ETHUSDT","id":32402502929,"side":"Buy","size":32000,"price":3109.28,"timestamp":"2024-05-18T15:46:17.649Z"},{"symbol":"ETHUSDT","id":32402502948,"side":"Buy","size":1000,"price":3109.03,"timestamp":"2024-05-18T15:46:17.649Z"}]}
{"table":"orderBookL2_25","action":"delete","data":[{"symbol":"XBTUSDT","id":32402502303,"side":"Sell","price":66794.8,"timestamp":"2024-05-18T15:46:17.654Z"},{"symbol":"XBTUSDT","id":32402502386,"side":"Sell","price":66794.7,"timestamp":"2024-05-18T15:46:17.654Z"},{"symbol":"XBTUSDT","id":32402502384,"side":"Buy","price":66761.2,"timestamp":"2024-05-18T15:46:17.654Z"},{"symbol":"XBTUSDT","id":32402502672,"side":"Buy","price":66770.2,"timestamp":"2024-05-18T15:46:17.654Z"},{"symbol":"XBTUSDT","id":32402502329,"side":"Buy","price":66761.1,"timestamp":"2024-05-18T15:46:17.654Z"},{"symbol":"XBTUSDT","id":32402502683,"side":"Buy","price":66770.1,"timestamp":"2024-05-18T15:46:17.654Z"},{"symbol":"XBTUSDT","id":32402502412,"side":"Buy","price":66757.7,"timestamp":"2024-05-18T15:46:17.654Z"},{"symbol":"XBTUSDT","id":32402493180,"side":"Buy","price":66772.2,"timestamp":"2024-05-18T15:46:17.654Z"},{"symbol":"XBTUSDT","id":32402502006,"side":"Buy","price":66752.3,"timestamp":"2024-05-18T15:46:17.654Z"}]}
{"table":"orderBookL2_25","action":"update","data":[{"symbol":"XBTUSDT","id":32402502728,"side":"Sell","size":504000,"price":66794.6,"timestamp":"2024-05-18T15:46:17.654Z"}]}
{"table":"orderBookL2_25","action":"insert","data":[{"symbol":"XBTUSDT","id":32402472771,"side":"Sell","size":100000,"price":66805.3,"timestamp":"2024-05-18T15:46:17.654Z"},{"symbol":"XBTUSDT","id":32402480133,"side":"Sell","size":10000,"price":66803.0,"timestamp":"2024-05-18T15:46:17.654Z"},{"symbol":"XBTUSDT","id":32402494980,"side":"Buy","size":74000,"price":66751.4,"timestamp":"2024-05-18T15:46:17.654Z"},{"symbol":"XBTUSDT","id":32402492129,"side":"Buy","size":1502000,"price":66752.1,"timestamp":"2024-05-18T15:46:17.654Z"},{"symbol":"XBTUSDT","id":32402502922,"side":"Buy","size":20000,"price":66769.7,"timestamp":"2024-05-18T15:46:17.654Z"},{"symbol":"XBTUSDT","id":32402492889,"side":"Buy","size":100000,"price":66750.8,"timestamp":"2024-05-18T15:46:17.654Z"},{"symbol":"XBTUSDT","id":32402502969,"side":"Buy","size":194000,"price":66768.6,"timestamp":"2024-05-18T15:46:17.654Z"},{"symbol":"XBTUSDT","id":32402502955,"side":"Buy","size":20000,"price":66769.8,"timestamp":"2024-05-18T15:46:17.654Z"},{"symbol":"XBTUSDT","id":32402502952,"side":"Buy","size":380000,"price":66757.8,"timestamp":"2024-05-18T15:46:17.654Z"}]}
{"table":"orderBookL2_25","action":"delete","data":[{"symbol":"ETHUSDT","id":32402502648,"side":"Buy","price":3109.04,"timestamp":"2024-05-18T15:46:17.698Z"}]}
{"table":"orderBookL2_25","action":"insert","data":[{"symbol":"ETHUSDT","id":32402503080,"side":"Buy","size":1000,"price":3109.02,"timestamp":"2024-05-18T15:46:17.698Z"}]}
{"table":"orderBookL2_25","action":"delete","data":[{"symbol":"XBTUSDT","id":32402502676,"side":"Sell","price":66801.0,"timestamp":"2024-05-18T15:46:17.703Z"},{"symbol":"XBTUSDT","id":32402502681,"side":"Sell","price":66800.9,"timestamp":"2024-05-18T15:46:17.703Z"},{"symbol":"XBTUSDT","id":32402502898,"side":"Buy","price":66773.5,"timestamp":"2024-05-18T15:46:17.703Z"},{"symbol":"XBTUSDT","id":32402501781,"side":"Buy","price":66784.2,"timestamp":"2024-05-18T15:46:17.703Z"},{"symbol":"XBTUSDT","id":32402502922,"side":"Buy","price":66769.7,"timestamp":"2024-05-18T15:46:17.703Z"},{"symbol":"XBTUSDT","id":32402502955,"side":"Buy","price":66769.8,"timestamp":"2024-05-18T15:46:17.703Z"}]}
{"table":"orderBookL2_25","action":"update","data":[{"symbol":"XBTUSDT","id":32402492889,"side":"Buy","size":100000,"price":66750.8,"timestamp":"2024-05-18T15:46:17.703Z"}]}
{"table":"orderBookL2_25","action":"insert","data":[{"symbol":"XBTUSDT","id":32402503152,"side":"Sell","size":20000,"price":66801.2,"timestamp":"2024-05-18T15:46:17.703Z"},{"symbol":"XBTUSDT","id":32402503043,"side":"Sell","size":20000,"price":66801.1,"timestamp":"2024-05-18T15:46:17.703Z"},{"symbol":"XBTUSDT","id":32402492536,"side":"Buy","size":1348000,"price":66748.7,"timestamp":"2024-05-18T15:46:17.703Z"},{"symbol":"XBTUSDT","id":32402503067,"side":"Buy","size":20000,"price":66769.4,"timestamp":"2024-05-18T15:46:17.703Z"},{"symbol":"XBTUSDT","id":32402503084,"side":"Buy","size":20000,"price":66781.7,"timestamp":"2024-05-18T15:46:17.703Z"},{"symbol":"XBTUSDT","id":32402503102,"side":"Buy","size":20000,"price":66769.1,"timestamp":"2024-05-18T15:46:17.703Z"}]}
{"table":"orderBookL2_25","action":"delete","data":[{"symbol":"ETHUSDT","id":32402493317,"side":"Buy","price":3108.70,"timestamp":"2024-05-18T15:46:17.747Z"},{"symbol":"ETHUSDT","id":32402503080,"side":"Buy","price":3109.02,"timestamp":"2024-05-18T15:46:17.747Z"},{"symbol":"ETHUSDT","id":32402502948,"side":"Buy","price":3109.03,"timestamp":"2024-05-18T15:46:17.747Z"},{"symbol":"ETHUSDT","id":32402502019,"side":"Buy","price":3109.41,"timestamp":"2024-05-18T15:46:17.747Z"},{"symbol":"ETHUSDT","id":32402502656,"side":"Buy","price":3109.29,"timestamp":"2024-05-18T15:46:17.747Z"},{"symbol":"ETHUSDT","id":32402502929,"side":"Buy","price":3109.28,"timestamp":"2024-05-18T15:46:17.747Z"},{"symbol":"ETHUSDT","id":32402494676,"side":"Buy","price":3108.53,"timestamp":"2024-05-18T15:46:17.747Z"}]}
{"table":"orderBookL2_25","action":"insert","data":[{"symbol":"ETHUSDT","id":32402231045,"side":"Buy","size":100000,"price":3105.80,"timestamp":"2024-05-18T15:46:17.747Z"},{"symbol":"ETHUSDT","id":32402503234,"side":"Buy","size":1000,"price":3109.00,"timestamp":"2024-05-18T15:46:17.747Z"},{"symbol":"ETHUSDT","id":32402354519,"side":"Buy","size":100000,"price":3106.60,"timestamp":"2024-05-18T15:46:17.747Z"},{"symbol":"ETHUSDT","id":32402494460,"side":"Buy","size":1114000,"price":3106.20,"timestamp":"2024-05-18T15:46:17.747Z"},{"symbol":"ETHUSDT","id":32402503423,"side":"Buy","size":32000,"price":3109.26,"timestamp":"2024-05-18T15:46:17.747Z"},{"symbol":"ETHUSDT","id":32402503333,"side":"Buy","size":32000,"price":3109.27,"timestamp":"2024-05-18T15:46:17.747Z"},{"symbol":"ETHUSDT","id":32402503219,"side":"Buy","size":1000,"price":3109.01,"timestamp":"2024-05-18T15:46:17.747Z"}]}
{"table":"orderBookL2_25","action":"delete","data":[{"symbol":"XBTUSDT","id":32402494673,"side":"Sell","price":66799.1,"timestamp":"2024-05-18T15:46:17.752Z"},{"symbol":"XBTUSDT","id":32402501970,"side":"Sell","price":66788.6,"timestamp":"2024-05-18T15:46:17.752Z"},{"symbol":"XBTUSDT","id":32402495049,"side":"Buy","price":66752.2,"timestamp":"2024-05-18T15:46:17.752Z"},{"symbol":"XBTUSDT","id":32402501977,"side":"Buy","price":66780.1,"timestamp":"2024-05-18T15:46:17.752Z"},{"symbol":"XBTUSDT","id":32402360485,"side":"Buy","price":66764.4,"timestamp":"2024-05-18T15:46:17.752Z"},{"symbol":"XBTUSDT","id":32402492536,"side":"Buy","price":66748.7,"timestamp":"2024-05-18T15:46:17.752Z"},{"symbol":"XBTUSDT","id":32402498824,"side":"Buy","price":66772.8,"timestamp":"2024-05-18T15:46:17.752Z"},{"symbol":"XBTUSDT","id":32402502969,"side":"Buy","price":66768.6,"timestamp":"2024-05-18T15:46:17.752Z"},{"symbol":"XBTUSDT","id":32402503084,"side":"Buy","price":66781.7,"timestamp":"2024-05-18T15:46:17.752Z"},{"symbol":"XBTUSDT","id":32402227172,"side":"Buy","price":66780.0,"timestamp":"2024-05-18T15:46:17.752Z"},{"symbol":"XBTUSDT","id":32402492533,"side":"Buy","price":66772.1,"timestamp":"2024-05-18T15:46:17.752Z"},{"symbol":"XBTUSDT","id":32402229295,"side":"Buy","price":66775.0,"timestamp":"2024-05-18T15:46:17.752Z"},{"symbol":"XBTUSDT","id":32402501556,"side":"Buy","price":66777.4,"timestamp":"2024-05-18T15:46:17.752Z"},{"symbol":"XBTUSDT","id":32402492339,"side":"Buy","price":66768.0,"timestamp":"2024-05-18T15:46:17.752Z"},{"symbol":"XBTUSDT","id":32402503067,"side":"Buy","price":66769.4,"timestamp":"2024-05-18T15:46:17.752Z"},{"symbol":"XBTUSDT","id":32402502027,"side":"Buy","price":66775.6,"timestamp":"2024-05-18T15:46:17.752Z"},{"symbol":"XBTUSDT","id":32402502755,"side":"Buy","price":66775.8,"timestamp":"2024-05-18T15:46:17.752Z"},{"symbol":"XBTUSDT","id":32402499689,"side":"Buy","price":66773.9,"timestamp":"2024-05-18T15:46:17.752Z"}]}
{"table":"orderBookL2_25","action":"update","data":[{"symbol":"XBTUSDT","id":32402501573,"side":"Sell","size":40000,"price":66786.2,"timestamp":"2024-05-18T15:46:17.752Z"},{"symbol":"XBTUSDT","id":32402502861,"side":"Sell","size":246000,"price":66784.3,"timestamp":"2024-05-18T15:46:17.752Z"},{"symbol":"XBTUSDT","id":32402494319,"side":"Buy","size":20000,"price":66769.2,"timestamp":"2024-05-18T15:46:17.752Z"}]}
{"table":"orderBookL2_25","action":"insert","data":[{"symbol":"XBTUSDT","id":32402503304,"side":"Sell","size":100000,"price":66781.8,"timestamp":"2024-05-18T15:46:17.752Z"},{"symbol":"XBTUSDT","id":32402503049,"side":"Sell","size":1000,"price":66807.5,"timestamp":"2024-05-18T15:46:17.752Z"},{"symbol":"XBTUSDT","id":32402497904,"side":"Buy","size":666000,"price":66723.2,"timestamp":"2024-05-18T15:46:17.752Z"},{"symbol":"XBTUSDT","id":32401547573,"side":"Buy","size":100000,"price":66723.1,"timestamp":"2024-05-18T15:46:17.752Z"},{"symbol":"XBTUSDT","id":32402402304,"side":"Buy","size":100000,"price":66716.3,"timestamp":"2024-05-18T15:46:17.752Z"},{"symbol":"XBTUSDT","id":32401436741,"side":"Buy","size":100000,"price":66702.2,"timestamp":"2024-05-18T15:46:17.752Z"},{"symbol":"XBTUSDT","id":32402491833,"side":"Buy","size":100000,"price":66744.0,"timestamp":"2024-05-18T15:46:17.752Z"},{"symbol":"XBTUSDT","id":32402503392,"side":"Buy","size":543000,"price":66707.5,"timestamp":"2024-05-18T15:46:17.752Z"},{"symbol":"XBTUSDT","id":32402503263,"side":"Buy","size":1348000,"price":66719.8,"timestamp":"2024-05-18T15:46:17.752Z"},{"symbol":"XBTUSDT","id":32402503255,"side":"Buy","size":442000,"price":66745.4,"timestamp":"2024-05-18T15:46:17.752Z"},{"symbol":"XBTUSDT","id":32402227830,"side":"Buy","size":100000,"price":66709.5,"timestamp":"2024-05-18T15:46:17.752Z"},{"symbol":"XBTUSDT","id":32402478051,"side":"Buy","size":8101000,"price":66711.0,"timestamp":"2024-05-18T15:46:17.752Z"},{"symbol":"XBTUSDT","id":32402496984,"side":"Buy","size":5000,"price":66702.5,"timestamp":"2024-05-18T15:46:17.752Z"},{"symbol":"XBTUSDT","id":32402462262,"side":"Buy","size":100000,"price":66733.8,"timestamp":"2024-05-18T15:46:17.752Z"},{"symbol":"XBTUSDT","id":32401160404,"side":"Buy","size":123000,"price":66697.3,"timestamp":"2024-05-18T15:46:17.752Z"},{"symbol":"XBTUSDT","id":32401552282,"side":"Buy","size":342000,"price":66720.0,"timestamp":"2024-05-18T15:46:17.752Z"},{"symbol":"XBTUSDT","id":32402434478,"side":"Buy","size":100000,"price":66747.4,"timestamp":"2024-05-18T15:46:17.752Z"},{"symbol":"XBTUSDT","id":32402238752,"side":"Buy","size":1000,"price":66694.4,"timestamp":"2024-05-18T15:46:17.752Z"}]}
{"table":"orderBookL2_25","action":"delete","data":[{"symbol":"ETHUSDT","id":32402494506,"side":"Sell","price":3111.48,"timestamp":"2024-05-18T15:46:17.796Z"},{"symbol":"ETHUSDT","id":32402502586,"side":"Sell","price":3110.55,"timestamp":"2024-05-18T15:46:17.796Z"},{"symbol":"ETHUSDT","id":32402499021,"side":"Buy","price":3108.08,"timestamp":"2024-05-18T15:46:17.796Z"},{"symbol":"ETHUSDT","id":32401850719,"side":"Buy","price":3107.70,"timestamp":"2024-05-18T15:46:17.796Z"},{"symbol":"ETHUSDT","id":32402503219,"side":"Buy","price":3109.01,"timestamp":"2024-05-18T15:46:17.796Z"},{"symbol":"ETHUSDT","id":32402491923,"side":"Buy","price":3107.79,"timestamp":"2024-05-18T15:46:17.796Z"},{"symbol":"ETHUSDT","id":32402503333,"side":"Buy","price":3109.27,"timestamp":"2024-05-18T15:46:17.796Z"},{"symbol":"ETHUSDT","id":32402503234,"side":"Buy","price":3109.00,"timestamp":"2024-05-18T15:46:17.796Z"},{"symbol":"ETHUSDT","id":32402503423,"side":"Buy","price":3109.26,"timestamp":"2024-05-18T15:46:17.796Z"},{"symbol":"ETHUSDT","id":32402493816,"side":"Buy","price":3107.31,"timestamp":"2024-05-18T15:46:17.796Z"}]}
{"table":"orderBookL2_25","action":"update","data":[{"symbol":"ETHUSDT","id":32401945550,"side":"Buy","size":63000,"price":3109.40,"timestamp":"2024-05-18T15:46:17.796Z"}]}
{"table":"orderBookL2_25","action":"insert","data":[{"symbol":"ETHUSDT","id":32402503841,"side":"Sell","size":32000,"price":3110.50,"timestamp":"2024-05-18T15:46:17.796Z"},{"symbol":"ETHUSDT","id":32402503819,"side":"Sell","size":100000,"price":3110.20,"timestamp":"2024-05-18T15:46:17.796Z"},{"symbol":"ETHUSDT","id":32402503821,"side":"Buy","size":1000,"price":3108.81,"timestamp":"2024-05-18T15:46:17.796Z"},{"symbol":"ETHUSDT","id":32400902751,"side":"Buy","size":1000,"price":3105.39,"timestamp":"2024-05-18T15:46:17.796Z"},{"symbol":"ETHUSDT","id":32402492281,"side":"Buy","size":17414000,"price":3105.21,"timestamp":"2024-05-18T15:46:17.796Z"},{"symbol":"ETHUSDT","id":32402503933,"side":"Buy","size":32000,"price":3109.19,"timestamp":"2024-05-18T15:46:17.796Z"},{"symbol":"ETHUSDT","id":32401445960,"side":"Buy","size":100000,"price":3105.40,"timestamp":"2024-05-18T15:46:17.796Z"},{"symbol":"ETHUSDT","id":32402503905,"side":"Buy","size":1000,"price":3108.82,"timestamp":"2024-05-18T15:46:17.796Z"},{"symbol":"ETHUSDT","id":32402481409,"side":"Buy","size":17000,"price":3105.30,"timestamp":"2024-05-18T15:46:17.796Z"},{"symbol":"ETHUSDT","id":32402503723,"side":"Buy","size":32000,"price":3109.25,"timestamp":"2024-05-18T15:46:17.796Z"}]}
{"table":"orderBookL2_25","action":"delete","data":[{"symbol":"XBTUSDT","id":32402503152,"side":"Sell","price":66801.2,"timestamp":"2024-05-18T15:46:17.801Z"},{"symbol":"XBTUSDT","id":32402503043,"side":"Sell","price":66801.1,"timestamp":"2024-05-18T15:46:17.801Z"},{"symbol":"XBTUSDT","id":32402472771,"side":"Sell","price":66805.3,"timestamp":"2024-05-18T15:46:17.801Z"},{"symbol":"XBTUSDT","id":32402503049,"side":"Sell","price":66807.5,"timestamp":"2024-05-18T15:46:17.801Z"},{"symbol":"XBTUSDT","id":32402456061,"side":"Buy","price":66761.0,"timestamp":"2024-05-18T15:46:17.801Z"},{"symbol":"XBTUSDT","id":32402496547,"side":"Buy","price":66768.5,"timestamp":"2024-05-18T15:46:17.801Z"},{"symbol":"XBTUSDT","id":32402494980,"side":"Buy","price":66751.4,"timestamp":"2024-05-18T15:46:17.801Z"},{"symbol":"XBTUSDT","id":32402494319,"side":"Buy","price":66769.2,"timestamp":"2024-05-18T15:46:17.801Z"},{"symbol":"XBTUSDT","id":32402489416,"side":"Buy","price":66757.6,"timestamp":"2024-05-18T15:46:17.801Z"},{"symbol":"XBTUSDT","id":32402502952,"side":"Buy","price":66757.8,"timestamp":"2024-05-18T15:46:17.801Z"},{"symbol":"XBTUSDT","id":32402478051,"side":"Buy","price":66711.0,"timestamp":"2024-05-18T15:46:17.801Z"},{"symbol":"XBTUSDT","id":32402503255,"side":"Buy","price":66745.4,"timestamp":"2024-05-18T15:46:17.801Z"},{"symbol":"XBTUSDT","id":32402503102,"side":"Buy","price":66769.1,"timestamp":"2024-05-18T15:46:17.801Z"}]}
{"table":"orderBookL2_25","action":"update","data":[{"symbol":"XBTUSDT","id":32402502728,"side":"Sell","size":156000,"price":66794.6,"timestamp":"2024-05-18T15:46:17.801Z"},{"symbol":"XBTUSDT","id":32402502861,"side":"Sell","size":240000,"price":66784.3,"timestamp":"2024-05-18T15:46:17.801Z"},{"symbol":"XBTUSDT","id":32402503304,"side":"Sell","size":140000,"price":66781.8,"timestamp":"2024-05-18T15:46:17.801Z"},{"symbol":"XBTUSDT","id":32402480133,"side":"Sell","size":10000,"price":66803.0,"timestamp":"2024-05-18T15:46:17.801Z"},{"symbol":"XBTUSDT","id":32402497904,"side":"Buy","size":651000,"price":66723.2,"timestamp":"2024-05-18T15:46:17.801Z"}]}
{"table":"orderBookL2_25","action":"insert","data":[{"symbol":"XBTUSDT","id":32402504165,"side":"Sell","size":20000,"price":66803.7,"timestamp":"2024-05-18T15:46:17.801Z"},{"symbol":"XBTUSDT","id":32402503875,"side":"Sell","size":20000,"price":66785.2,"timestamp":"2024-05-18T15:46:17.801Z"},{"symbol":"XBTUSDT","id":32402503769,"side":"Sell","size":2000,"price":66797.0,"timestamp":"2024-05-18T15:46:17.801Z"},{"symbol":"XBTUSDT","id":32402503717,"side":"Sell","size":355000,"price":66791.6,"timestamp":"2024-05-18T15:46:17.801Z"},{"symbol":"XBTUSDT","id":32402493632,"side":"Buy","size":8000,"price":66692.8,"timestamp":"2024-05-18T15:46:17.801Z"},{"symbol":"XBTUSDT","id":32402503900,"side":"Buy","size":74000,"price":66737.0,"timestamp":"2024-05-18T15:46:17.801Z"},{"symbol":"XBTUSDT","id":32402503878,"side":"Buy","size":442000,"price":66731.8,"timestamp":"2024-05-18T15:46:17.801Z"},{"symbol":"XBTUSDT","id":32402503867,"side":"Buy","size":394000,"price":66752.4,"timestamp":"2024-05-18T15:46:17.801Z"},{"symbol":"XBTUSDT","id":32401421307,"side":"Buy","size":100000,"price":66687.1,"timestamp":"2024-05-18T15:46:17.801Z"},{"symbol":"XBTUSDT","id":32401820098,"side":"Buy","size":628000,"price":66686.2,"timestamp":"2024-05-18T15:46:17.801Z"},{"symbol":"XBTUSDT","id":32402503916,"side":"Buy","size":15000,"price":66720.1,"timestamp":"2024-05-18T15:46:17.801Z"},{"symbol":"XBTUSDT","id":32402364502,"side":"Buy","size":100000,"price":66690.5,"timestamp":"2024-05-18T15:46:17.801Z"},{"symbol":"XBTUSDT","id":32402462862,"side":"Buy","size":100000,"price":66693.9,"timestamp":"2024-05-18T15:46:17.801Z"}]}
{"table":"orderBookL2_25","action":"delete","data":[{"symbol":"XBTETH","id":32402475262,"side":"Sell","price":21.489,"timestamp":"2024-05-18T15:46:17.835Z"}]}
{"table":"orderBookL2_25","action":"insert","data":[{"symbol":"XBTETH","id":32402422052,"side":"Sell","size":7,"price":22.173,"timestamp":"2024-05-18T15:46:17.835Z"}]}
{"table":"orderBookL2_25","action":"delete","data":[{"symbol":"ETHUSDT","id":32402494493,"side":"Sell","price":3111.26,"timestamp":"2024-05-18T15:46:17.845Z"},{"symbol":"ETHUSDT","id":32402494475,"side":"Sell","price":3111.21,"timestamp":"2024-05-18T15:46:17.845Z"},{"symbol":"ETHUSDT","id":32402503841,"side":"Sell","price":3110.50,"timestamp":"2024-05-18T15:46:17.845Z"},{"symbol":"ETHUSDT","id":32402494486,"side":"Sell","price":3111.20,"timestamp":"2024-05-18T15:46:17.845Z"},{"symbol":"ETHUSDT","id":32402492623,"side":"Sell","price":3110.78,"timestamp":"2024-05-18T15:46:17.845Z"},{"symbol":"ETHUSDT","id":32401945550,"side":"Buy","price":3109.40,"timestamp":"2024-05-18T15:46:17.845Z"},{"symbol":"ETHUSDT","id":32402492409,"side":"Buy","price":3108.48,"timestamp":"2024-05-18T15:46:17.845Z"},{"symbol":"ETHUSDT","id":32402491357,"side":"Buy","price":3107.78,"timestamp":"2024-05-18T15:46:17.845Z"},{"symbol":"ETHUSDT","id":32402503821,"side":"Buy","price":3108.81,"timestamp":"2024-05-18T15:46:17.845Z"},{"symbol":"ETHUSDT","id":32402503723,"side":"Buy","price":3109.25,"timestamp":"2024-05-18T15:46:17.845Z"},{"symbol":"ETHUSDT","id":32402503933,"side":"Buy","price":3109.19,"timestamp":"2024-05-18T15:46:17.845Z"},{"symbol":"ETHUSDT","id":32402492798,"side":"Buy","price":3108.69,"timestamp":"2024-05-18T15:46:17.845Z"},{"symbol":"ETHUSDT","id":32402502093,"side":"Buy","price":3107.80,"timestamp":"2024-05-18T15:46:17.845Z"}]}
{"table":"orderBookL2_25","action":"insert","data":[{"symbol":"ETHUSDT","id":32402504489,"side":"Sell","size":49000,"price":3111.02,"timestamp":"2024-05-18T15:46:17.845Z"},{"symbol":"ETHUSDT","id":32402504603,"side":"Sell","size":21000,"price":3109.55,"timestamp":"2024-05-18T15:46:17.845Z"},{"symbol":"ETHUSDT","id":32402504509,"side":"Sell","size":32000,"price":3110.52,"timestamp":"2024-05-18T15:46:17.845Z"},{"symbol":"ETHUSDT","id":32402504612,"side":"Sell","size":21000,"price":3109.27,"timestamp":"2024-05-18T15:46:17.845Z"},{"symbol":"ETHUSDT","id":32402504595,"side":"Sell","size":43000,"price":3110.29,"timestamp":"2024-05-18T15:46:17.845Z"},{"symbol":"ETHUSDT","id":32402504511,"side":"Buy","size":32000,"price":3109.07,"timestamp":"2024-05-18T15:46:17.845Z"},{"symbol":"ETHUSDT","id":32402504184,"side":"Buy","size":32000,"price":3109.06,"timestamp":"2024-05-18T15:46:17.845Z"},{"symbol":"ETHUSDT","id":32402504544,"side":"Buy","size":539000,"price":3107.57,"timestamp":"2024-05-18T15:46:17.845Z"},{"symbol":"ETHUSDT","id":32402492615,"side":"Buy","size":100000,"price":3105.08,"timestamp":"2024-05-18T15:46:17.845Z"},{"symbol":"ETHUSDT","id":32402504254,"side":"Buy","size":2300000,"price":3106.99,"timestamp":"2024-05-18T15:46:17.845Z"},{"symbol":"ETHUSDT","id":32402466553,"side":"Buy","size":2801000,"price":3104.83,"timestamp":"2024-05-18T15:46:17.845Z"},{"symbol":"ETHUSDT","id":32402504317,"side":"Buy","size":311000,"price":3108.08,"timestamp":"2024-05-18T15:46:17.845Z"},{"symbol":"ETHUSDT","id":32402504484,"side":"Buy","size":1000,"price":3108.84,"timestamp":"2024-05-18T15:46:17.845Z"}]}
{"table":"orderBookL2_25","action":"delete","data":[{"symbol":"XBTUSDT","id":32402480133,"side":"Sell","price":66803.0,"timestamp":"2024-05-18T15:46:17.850Z"},{"symbol":"XBTUSDT","id":32402502013,"side":"Sell","price":66791.9,"timestamp":"2024-05-18T15:46:17.850Z"},{"symbol":"XBTUSDT","id":32402462668,"side":"Sell","price":66801.9,"timestamp":"2024-05-18T15:46:17.850Z"},{"symbol":"XBTUSDT","id":32402503769,"side":"Sell","price":66797.0,"timestamp":"2024-05-18T15:46:17.850Z"},{"symbol":"XBTUSDT","id":32402504165,"side":"Sell","price":66803.7,"timestamp":"2024-05-18T15:46:17.850Z"},{"symbol":"XBTUSDT","id":32402491833,"side":"Buy","price":66744.0,"timestamp":"2024-05-18T15:46:17.850Z"},{"symbol":"XBTUSDT","id":32402503867,"side":"Buy","price":66752.4,"timestamp":"2024-05-18T15:46:17.850Z"},{"symbol":"XBTUSDT","id":32402492129,"side":"Buy","price":66752.1,"timestamp":"2024-05-18T15:46:17.850Z"},{"symbol":"XBTUSDT","id":32402503900,"side":"Buy","price":66737.0,"timestamp":"2024-05-18T15:46:17.850Z"},{"symbol":"XBTUSDT","id":32402497904,"side":"Buy","price":66723.2,"timestamp":"2024-05-18T15:46:17.850Z"},{"symbol":"XBTUSDT","id":32402434478,"side":"Buy","price":66747.4,"timestamp":"2024-05-18T15:46:17.850Z"},{"symbol":"XBTUSDT","id":32402492889,"side":"Buy","price":66750.8,"timestamp":"2024-05-18T15:46:17.850Z"}]}
{"table":"orderBookL2_25","action":"update","data":[{"symbol":"XBTUSDT","id":32402502112,"side":"Sell","size":62000,"price":66800.6,"timestamp":"2024-05-18T15:46:17.850Z"},{"symbol":"XBTUSDT","id":32402491799,"side":"Sell","size":13000,"price":66795.4,"timestamp":"2024-05-18T15:46:17.850Z"},{"symbol":"XBTUSDT","id":32402499236,"side":"Sell","size":1000,"price":66786.7,"timestamp":"2024-05-18T15:46:17.850Z"},{"symbol":"XBTUSDT","id":32401552282,"side":"Buy","size":1000,"price":66720.0,"timestamp":"2024-05-18T15:46:17.850Z"}]}
{"table":"orderBookL2_25","action":"insert","data":[{"symbol":"XBTUSDT","id":32402504628,"side":"Sell","size":2000,"price":66789.0,"timestamp":"2024-05-18T15:46:17.850Z"},{"symbol":"XBTUSDT","id":32402504528,"side":"Sell","size":8000,"price":66780.1,"timestamp":"2024-05-18T15:46:17.850Z"},{"symbol":"XBTUSDT","id":32402504314,"side":"Sell","size":40000,"price":66781.7,"timestamp":"2024-05-18T15:46:17.850Z"},{"symbol":"XBTUSDT","id":32402504235,"side":"Sell","size":2000,"price":66785.5,"timestamp":"2024-05-18T15:46:17.850Z"},{"symbol":"XBTUSDT","id":32402504213,"side":"Sell","size":6000,"price":66780.2,"timestamp":"2024-05-18T15:46:17.850Z"},{"symbol":"XBTUSDT","id":32402504548,"side":"Buy","size":432000,"price":66733.9,"timestamp":"2024-05-18T15:46:17.850Z"},{"symbol":"XBTUSDT","id":32402504383,"side":"Buy","size":341000,"price":66706.5,"timestamp":"2024-05-18T15:46:17.850Z"},{"symbol":"XBTUSDT","id":32402504250,"side":"Buy","size":1502000,"price":66736.2,"timestamp":"2024-05-18T15:46:17.850Z"},{"symbol":"XBTUSDT","id":32402504312,"side":"Buy","size":100000,"price":66757.6,"timestamp":"2024-05-18T15:46:17.850Z"},{"symbol":"XBTUSDT","id":32402485335,"side":"Buy","size":100000,"price":66680.3,"timestamp":"2024-05-18T15:46:17.850Z"},{"symbol":"XBTUSDT","id":32402504632,"side":"Buy","size":651000,"price":66711.1,"timestamp":"2024-05-18T15:46:17.850Z"},{"symbol":"XBTUSDT","id":32402211086,"side":"Buy","size":100000,"price":66683.7,"timestamp":"2024-05-18T15:46:17.850Z"}]}
{"table":"orderBookL2_25","action":"delete","data":[{"symbol":"ETHUSDT","id":32402487799,"side":"Sell","price":3111.06,"timestamp":"2024-05-18T15:46:17.894Z"},{"symbol":"ETHUSDT","id":32402492800,"side":"Sell","price":3110.25,"timestamp":"2024-05-18T15:46:17.894Z"},{"symbol":"ETHUSDT","id":32402487481,"side":"Sell","price":3111.10,"timestamp":"2024-05-18T15:46:17.894Z"},{"symbol":"ETHUSDT","id":32402502935,"side":"Sell","price":3110.54,"timestamp":"2024-05-18T15:46:17.894Z"},{"symbol":"ETHUSDT","id":32402485810,"side":"Sell","price":3111.07,"timestamp":"2024-05-18T15:46:17.894Z"},{"symbol":"ETHUSDT","id":32402504184,"side":"Buy","price":3109.06,"timestamp":"2024-05-18T15:46:17.894Z"},{"symbol":"ETHUSDT","id":32402488018,"side":"Buy","price":3107.17,"timestamp":"2024-05-18T15:46:17.894Z"},{"symbol":"ETHUSDT","id":32402480341,"side":"Buy","price":3106.76,"timestamp":"2024-05-18T15:46:17.894Z"},{"symbol":"ETHUSDT","id":32402503905,"side":"Buy","price":3108.82,"timestamp":"2024-05-18T15:46:17.894Z"},{"symbol":"ETHUSDT","id":32402497836,"side":"Buy","price":3108.13,"timestamp":"2024-05-18T15:46:17.894Z"},{"symbol":"ETHUSDT","id":32402460376,"side":"Buy","price":3107.97,"timestamp":"2024-05-18T15:46:17.894Z"},{"symbol":"ETHUSDT","id":32402458908,"side":"Buy","price":3107.30,"timestamp":"2024-05-18T15:46:17.894Z"}]}
{"table":"orderBookL2_25","action":"insert","data":[{"symbol":"ETHUSDT","id":32402504770,"side":"Sell","size":905000,"price":3109.66,"timestamp":"2024-05-18T15:46:17.894Z"},{"symbol":"ETHUSDT","id":32402505086,"side":"Sell","size":32000,"price":3110.51,"timestamp":"2024-05-18T15:46:17.894Z"},{"symbol":"ETHUSDT","id":32402504961,"side":"Sell","size":2000,"price":3109.42,"timestamp":"2024-05-18T15:46:17.894Z"},{"symbol":"ETHUSDT","id":32402504795,"side":"Sell","size":100000,"price":3109.72,"timestamp":"2024-05-18T15:46:17.894Z"},{"symbol":"ETHUSDT","id":32402505072,"side":"Sell","size":2300000,"price":3110.74,"timestamp":"2024-05-18T15:46:17.894Z"},{"symbol":"ETHUSDT","id":32402504893,"side":"Buy","size":942000,"price":3105.89,"timestamp":"2024-05-18T15:46:17.894Z"},{"symbol":"ETHUSDT","id":32402504834,"side":"Buy","size":1620000,"price":3106.40,"timestamp":"2024-05-18T15:46:17.894Z"},{"symbol":"ETHUSDT","id":32401905150,"side":"Buy","size":100000,"price":3104.76,"timestamp":"2024-05-18T15:46:17.894Z"},{"symbol":"ETHUSDT","id":32400879789,"side":"Buy","size":100000,"price":3103.45,"timestamp":"2024-05-18T15:46:17.894Z"},{"symbol":"ETHUSDT","id":32402400360,"side":"Buy","size":100000,"price":3104.60,"timestamp":"2024-05-18T15:46:17.894Z"},{"symbol":"ETHUSDT","id":32402504658,"side":"Buy","size":32000,"price":3109.03,"timestamp":"2024-05-18T15:46:17.894Z"},{"symbol":"ETHUSDT","id":32402505179,"side":"Buy","size":1000,"price":3108.83,"timestamp":"2024-05-18T15:46:17.894Z"}]}
{"table":"orderBookL2_25","action":"delete","data":[{"symbol":"XBTUSDT","id":32402499658,"side":"Sell","price":66800.3,"timestamp":"2024-05-18T15:46:17.899Z"},{"symbol":"XBTUSDT","id":32402499234,"side":"Sell","price":66792.0,"timestamp":"2024-05-18T15:46:17.899Z"},{"symbol":"XBTUSDT","id":32402502112,"side":"Sell","price":66800.6,"timestamp":"2024-05-18T15:46:17.899Z"},{"symbol":"XBTUSDT","id":32402502816,"side":"Sell","price":66794.5,"timestamp":"2024-05-18T15:46:17.899Z"},{"symbol":"XBTUSDT","id":32402503717,"side":"Sell","price":66791.6,"timestamp":"2024-05-18T15:46:17.899Z"},{"symbol":"XBTUSDT","id":32402501573,"side":"Sell","price":66786.2,"timestamp":"2024-05-18T15:46:17.899Z"},{"symbol":"XBTUSDT","id":32402504235,"side":"Sell","price":66785.5,"timestamp":"2024-05-18T15:46:17.899Z"},{"symbol":"XBTUSDT","id":32402502274,"side":"Sell","price":66799.8,"timestamp":"2024-05-18T15:46:17.899Z"},{"symbol":"XBTUSDT","id":32402504628,"side":"Sell","price":66789.0,"timestamp":"2024-05-18T15:46:17.899Z"},{"symbol":"XBTUSDT","id":32402211086,"side":"Buy","price":66683.7,"timestamp":"2024-05-18T15:46:17.899Z"},{"symbol":"XBTUSDT","id":32402503916,"side":"Buy","price":66720.1,"timestamp":"2024-05-18T15:46:17.899Z"},{"symbol":"XBTUSDT","id":32401820098,"side":"Buy","price":66686.2,"timestamp":"2024-05-18T15:46:17.899Z"},{"symbol":"XBTUSDT","id":32402485335,"side":"Buy","price":66680.3,"timestamp":"2024-05-18T15:46:17.899Z"},{"symbol":"XBTUSDT","id":32402503392,"side":"Buy","price":66707.5,"timestamp":"2024-05-18T15:46:17.899Z"},{"symbol":"XBTUSDT","id":32402503263,"side":"Buy","price":66719.8,"timestamp":"2024-05-18T15:46:17.899Z"},{"symbol":"XBTUSDT","id":32402493632,"side":"Buy","price":66692.8,"timestamp":"2024-05-18T15:46:17.899Z"},{"symbol":"XBTUSDT","id":32402503878,"side":"Buy","price":66731.8,"timestamp":"2024-05-18T15:46:17.899Z"},{"symbol":"XBTUSDT","id":32401421307,"side":"Buy","price":66687.1,"timestamp":"2024-05-18T15:46:17.899Z"}]}
{"table":"orderBookL2_25","action":"update","data":[{"symbol":"XBTUSDT","id":32402503304,"side":"Sell","size":100000,"price":66781.8,"timestamp":"2024-05-18T15:46:17.899Z"},{"symbol":"XBTUSDT","id":32402502861,"side":"Sell","size":654000,"price":66784.3,"timestamp":"2024-05-18T15:46:17.899Z"},{"symbol":"XBTUSDT","id":32402504213,"side":"Sell","size":46000,"price":66780.2,"timestamp":"2024-05-18T15:46:17.899Z"},{"symbol":"XBTUSDT","id":32402491799,"side":"Sell","size":12000,"price":66795.4,"timestamp":"2024-05-18T15:46:17.899Z"},{"symbol":"XBTUSDT","id":32402504528,"side":"Sell","size":16000,"price":66780.1,"timestamp":"2024-05-18T15:46:17.899Z"},{"symbol":"XBTUSDT","id":32402500188,"side":"Sell","size":2000,"price":66798.1,"timestamp":"2024-05-18T15:46:17.899Z"},{"symbol":"XBTUSDT","id":32402364502,"side":"Buy","size":100000,"price":66690.5,"timestamp":"2024-05-18T15:46:17.899Z"}]}
{"table":"orderBookL2_25","action":"insert","data":[{"symbol":"XBTUSDT","id":32402505244,"side":"Sell","size":100000,"price":66776.9,"timestamp":"2024-05-18T15:46:17.899Z"},{"symbol":"XBTUSDT","id":32402505213,"side":"Sell","size":2000,"price":66793.5,"timestamp":"2024-05-18T15:46:17.899Z"},{"symbol":"XBTUSDT","id":32402504913,"side":"Sell","size":1000,"price":66786.9,"timestamp":"2024-05-18T15:46:17.899Z"},{"symbol":"XBTUSDT","id":32402505006,"side":"Sell","size":100000,"price":66778.5,"timestamp":"2024-05-18T15:46:17.899Z"},{"symbol":"XBTUSDT","id":32402505186,"side":"Sell","size":1000,"price":66786.8,"timestamp":"2024-05-18T15:46:17.899Z"},{"symbol":"XBTUSDT","id":32402505084,"side":"Sell","size":2000,"price":66784.2,"timestamp":"2024-05-18T15:46:17.899Z"},{"symbol":"XBTUSDT","id":32402504870,"side":"Sell","size":538000,"price":66795.7,"timestamp":"2024-05-18T15:46:17.899Z"},{"symbol":"XBTUSDT","id":32402504839,"side":"Sell","size":159000,"price":66797.1,"timestamp":"2024-05-18T15:46:17.899Z"},{"symbol":"XBTUSDT","id":32402504725,"side":"Sell","size":74000,"price":66791.5,"timestamp":"2024-05-18T15:46:17.899Z"},{"symbol":"XBTUSDT","id":32402505090,"side":"Buy","size":20000,"price":66740.3,"timestamp":"2024-05-18T15:46:17.899Z"},{"symbol":"XBTUSDT","id":32402504980,"side":"Buy","size":24000,"price":66702.4,"timestamp":"2024-05-18T15:46:17.899Z"},{"symbol":"XBTUSDT","id":32402504789,"side":"Buy","size":36000,"price":66741.8,"timestamp":"2024-05-18T15:46:17.899Z"},{"symbol":"XBTUSDT","id":32402504861,"side":"Buy","size":100000,"price":66744.0,"timestamp":"2024-05-18T15:46:17.899Z"},{"symbol":"XBTUSDT","id":32402504711,"side":"Buy","size":1348000,"price":66699.8,"timestamp":"2024-05-18T15:46:17.899Z"},{"symbol":"XBTUSDT","id":32402505149,"side":"Buy","size":100000,"price":66730.4,"timestamp":"2024-05-18T15:46:17.899Z"},{"symbol":"XBTUSDT","id":32402505136,"side":"Buy","size":15000,"price":66697.4,"timestamp":"2024-05-18T15:46:17.899Z"},{"symbol":"XBTUSDT","id":32402505024,"side":"Buy","size":442000,"price":66718.3,"timestamp":"2024-05-18T15:46:17.899Z"},{"symbol":"XBTUSDT","id":32402505056,"side":"Buy","size":20000,"price":66743.5,"timestamp":"2024-05-18T15:46:17.899Z"}]}
{"table":"orderBookL2_25","action":"delete","data":[{"symbol":"ETHUSDT","id":32402504603,"side":"Sell","price":3109.55,"timestamp":"2024-05-18T15:46:17.944Z"},{"symbol":"ETHUSDT","id":32402488478,"side":"Sell","price":3111.05,"timestamp":"2024-05-18T15:46:17.944Z"},{"symbol":"ETHUSDT","id":32402504509,"side":"Sell","price":3110.52,"timestamp":"2024-05-18T15:46:17.944Z"},{"symbol":"ETHUSDT","id":32402500242,"side":"Sell","price":3109.68,"timestamp":"2024-05-18T15:46:17.944Z"},{"symbol":"ETHUSDT","id":32402505179,"side":"Buy","price":3108.83,"timestamp":"2024-05-18T15:46:17.944Z"},{"symbol":"ETHUSDT","id":32402400360,"side":"Buy","price":3104.60,"timestamp":"2024-05-18T15:46:17.944Z"},{"symbol":"ETHUSDT","id":32402481409,"side":"Buy","price":3105.30,"timestamp":"2024-05-18T15:46:17.944Z"},{"symbol":"ETHUSDT","id":32400879789,"side":"Buy","price":3103.45,"timestamp":"2024-05-18T15:46:17.944Z"},{"symbol":"ETHUSDT","id":32402504544,"side":"Buy","price":3107.57,"timestamp":"2024-05-18T15:46:17.944Z"},{"symbol":"ETHUSDT","id":32402504511,"side":"Buy","price":3109.07,"timestamp":"2024-05-18T15:46:17.944Z"},{"symbol":"ETHUSDT","id":32401905150,"side":"Buy","price":3104.76,"timestamp":"2024-05-18T15:46:17.944Z"},{"symbol":"ETHUSDT","id":32402504658,"side":"Buy","price":3109.03,"timestamp":"2024-05-18T15:46:17.944Z"},{"symbol":"ETHUSDT","id":32402504484,"side":"Buy","price":3108.84,"timestamp":"2024-05-18T15:46:17.944Z"}]}
{"table":"orderBookL2_25","action":"update","data":[{"symbol":"ETHUSDT","id":32402504489,"side":"Sell","size":49000,"price":3111.02,"timestamp":"2024-05-18T15:46:17.944Z"},{"symbol":"ETHUSDT","id":32402501905,"side":"Sell","size":103000,"price":3109.56,"timestamp":"2024-05-18T15:46:17.944Z"},{"symbol":"ETHUSDT","id":32402466553,"side":"Buy","size":2801000,"price":3104.83,"timestamp":"2024-05-18T15:46:17.944Z"}]}
{"table":"orderBookL2_25","action":"insert","data":[{"symbol":"ETHUSDT","id":32402505719,"side":"Sell","size":32000,"price":3110.11,"timestamp":"2024-05-18T15:46:17.944Z"},{"symbol":"ETHUSDT","id":32402505455,"side":"Sell","size":21000,"price":3109.20,"timestamp":"2024-05-18T15:46:17.944Z"},{"symbol":"ETHUSDT","id":32402505650,"side":"Sell","size":100000,"price":3109.12,"timestamp":"2024-05-18T15:46:17.944Z"},{"symbol":"ETHUSDT","id":32402505422,"side":"Sell","size":21000,"price":3109.07,"timestamp":"2024-05-18T15:46:17.944Z"},{"symbol":"ETHUSDT","id":32402505498,"side":"Buy","size":100000,"price":3107.91,"timestamp":"2024-05-18T15:46:17.944Z"},{"symbol":"ETHUSDT","id":32402505606,"side":"Buy","size":1000,"price":3108.36,"timestamp":"2024-05-18T15:46:17.944Z"},{"symbol":"ETHUSDT","id":32402505705,"side":"Buy","size":1000,"price":3108.32,"timestamp":"2024-05-18T15:46:17.944Z"},{"symbol":"ETHUSDT","id":32402505702,"side":"Buy","size":32000,"price":3108.65,"timestamp":"2024-05-18T15:46:17.944Z"},{"symbol":"ETHUSDT","id":32402505321,"side":"Buy","size":570000,"price":3107.32,"timestamp":"2024-05-18T15:46:17.944Z"},{"symbol":"ETHUSDT","id":32402505210,"side":"Buy","size":192000,"price":3107.48,"timestamp":"2024-05-18T15:46:17.944Z"},{"symbol":"ETHUSDT","id":32402505580,"side":"Buy","size":1157000,"price":3108.12,"timestamp":"2024-05-18T15:46:17.944Z"},{"symbol":"ETHUSDT","id":32402505539,"side":"Buy","size":32000,"price":3108.87,"timestamp":"2024-05-18T15:46:17.944Z"},{"symbol":"ETHUSDT","id":32402505366,"side":"Buy","size":100000,"price":3106.92,"timestamp":"2024-05-18T15:46:17.944Z"}]}
{"table":"orderBookL2_25","action":"delete","data":[{"symbol":"XBTUSDT","id":32402505213,"side":"Sell","price":66793.5,"timestamp":"2024-05-18T15:46:17.948Z"},{"symbol":"XBTUSDT","id":32402505186,"side":"Sell","price":66786.8,"timestamp":"2024-05-18T15:46:17.948Z"},{"symbol":"XBTUSDT","id":32402504913,"side":"Sell","price":66786.9,"timestamp":"2024-05-18T15:46:17.948Z"},{"symbol":"XBTUSDT","id":32402500325,"side":"Sell","price":66791.7,"timestamp":"2024-05-18T15:46:17.948Z"},{"symbol":"XBTUSDT","id":32402504213,"side":"Sell","price":66780.2,"timestamp":"2024-05-18T15:46:17.948Z"},{"symbol":"XBTUSDT","id":32402505056,"side":"Buy","price":66743.5,"timestamp":"2024-05-18T15:46:17.948Z"},{"symbol":"XBTUSDT","id":32402462862,"side":"Buy","price":66693.9,"timestamp":"2024-05-18T15:46:17.948Z"},{"symbol":"XBTUSDT","id":32402504632,"side":"Buy","price":66711.1,"timestamp":"2024-05-18T15:46:17.948Z"},{"symbol":"XBTUSDT","id":32402364502,"side":"Buy","price":66690.5,"timestamp":"2024-05-18T15:46:17.948Z"},{"symbol":"XBTUSDT","id":32402504980,"side":"Buy","price":66702.4,"timestamp":"2024-05-18T15:46:17.948Z"}]}
{"table":"orderBookL2_25","action":"update","data":[{"symbol":"XBTUSDT","id":32402504528,"side":"Sell","size":56000,"price":66780.1,"timestamp":"2024-05-18T15:46:17.948Z"},{"symbol":"XBTUSDT","id":32402500188,"side":"Sell","size":2000,"price":66798.1,"timestamp":"2024-05-18T15:46:17.948Z"},{"symbol":"XBTUSDT","id":32402502861,"side":"Sell","size":554000,"price":66784.3,"timestamp":"2024-05-18T15:46:17.948Z"},{"symbol":"XBTUSDT","id":32402504839,"side":"Sell","size":159000,"price":66797.1,"timestamp":"2024-05-18T15:46:17.948Z"},{"symbol":"XBTUSDT","id":32402503875,"side":"Sell","size":20000,"price":66785.2,"timestamp":"2024-05-18T15:46:17.948Z"}]}
{"table":"orderBookL2_25","action":"insert","data":[{"symbol":"XBTUSDT","id":32402505768,"side":"Sell","size":1000,"price":66783.1,"timestamp":"2024-05-18T15:46:17.948Z"},{"symbol":"XBTUSDT","id":32402505599,"side":"Sell","size":15000,"price":66791.6,"timestamp":"2024-05-18T15:46:17.948Z"},{"symbol":"XBTUSDT","id":32402502274,"side":"Sell","size":22000,"price":66799.8,"timestamp":"2024-05-18T15:46:17.948Z"},{"symbol":"XBTUSDT","id":32402505712,"side":"Sell","size":1000,"price":66783.2,"timestamp":"2024-05-18T15:46:17.948Z"},{"symbol":"XBTUSDT","id":32402505757,"side":"Sell","size":3000,"price":66795.8,"timestamp":"2024-05-18T15:46:17.948Z"},{"symbol":"XBTUSDT","id":32402505528,"side":"Buy","size":3000,"price":66736.3,"timestamp":"2024-05-18T15:46:17.948Z"},{"symbol":"XBTUSDT","id":32402505594,"side":"Buy","size":538000,"price":66712.2,"timestamp":"2024-05-18T15:46:17.948Z"},{"symbol":"XBTUSDT","id":32402505684,"side":"Buy","size":651000,"price":66702.3,"timestamp":"2024-05-18T15:46:17.948Z"},{"symbol":"XBTUSDT","id":32402505627,"side":"Buy","size":20000,"price":66740.8,"timestamp":"2024-05-18T15:46:17.948Z"},{"symbol":"XBTUSDT","id":32402505578,"side":"Buy","size":36000,"price":66747.0,"timestamp":"2024-05-18T15:46:17.948Z"}]}
{"table":"orderBookL2_25","action":"delete","data":[{"symbol":"ETHUSDT","id":32402504489,"side":"Sell","price":3111.02,"timestamp":"2024-05-18T15:46:17.993Z"},{"symbol":"ETHUSDT","id":32402504961,"side":"Sell","price":3109.42,"timestamp":"2024-05-18T15:46:17.993Z"},{"symbol":"ETHUSDT","id":32402501903,"side":"Sell","price":3109.67,"timestamp":"2024-05-18T15:46:17.993Z"},{"symbol":"ETHUSDT","id":32402505086,"side":"Sell","price":3110.51,"timestamp":"2024-05-18T15:46:17.993Z"},{"symbol":"ETHUSDT","id":32402505719,"side":"Sell","price":3110.11,"timestamp":"2024-05-18T15:46:17.993Z"},{"symbol":"ETHUSDT","id":32402499416,"side":"Sell","price":3110.24,"timestamp":"2024-05-18T15:46:17.993Z"},{"symbol":"ETHUSDT","id":32402501981,"side":"Sell","price":3109.92,"timestamp":"2024-05-18T15:46:17.993Z"},{"symbol":"ETHUSDT","id":32402505455,"side":"Sell","price":3109.20,"timestamp":"2024-05-18T15:46:17.993Z"},{"symbol":"ETHUSDT","id":32402504612,"side":"Sell","price":3109.27,"timestamp":"2024-05-18T15:46:17.993Z"},{"symbol":"ETHUSDT","id":32402505705,"side":"Buy","price":3108.32,"timestamp":"2024-05-18T15:46:17.993Z"},{"symbol":"ETHUSDT","id":32402466553,"side":"Buy","price":3104.83,"timestamp":"2024-05-18T15:46:17.993Z"},{"symbol":"ETHUSDT","id":32402492281,"side":"Buy","price":3105.21,"timestamp":"2024-05-18T15:46:17.993Z"},{"symbol":"ETHUSDT","id":32402505539,"side":"Buy","price":3108.87,"timestamp":"2024-05-18T15:46:17.993Z"},{"symbol":"ETHUSDT","id":32402505702,"side":"Buy","price":3108.65,"timestamp":"2024-05-18T15:46:17.993Z"},{"symbol":"ETHUSDT","id":32402492615,"side":"Buy","price":3105.08,"timestamp":"2024-05-18T15:46:17.993Z"},{"symbol":"ETHUSDT","id":32402505606,"side":"Buy","price":3108.36,"timestamp":"2024-05-18T15:46:17.993Z"}]}
{"table":"orderBookL2_25","action":"update","data":[{"symbol":"ETHUSDT","id":32402501905,"side":"Sell","size":100000,"price":3109.56,"timestamp":"2024-05-18T15:46:17.993Z"}]}
{"table":"orderBookL2_25","action":"insert","data":[{"symbol":"ETHUSDT","id":32402506255,"side":"Sell","size":942000,"price":3110.98,"timestamp":"2024-05-18T15:46:17.993Z"},{"symbol":"ETHUSDT","id":32402506209,"side":"Sell","size":3000,"price":3109.27,"timestamp":"2024-05-18T15:46:17.993Z"},{"symbol":"ETHUSDT","id":32402506064,"side":"Sell","size":21000,"price":3108.85,"timestamp":"2024-05-18T15:46:17.993Z"},{"symbol":"ETHUSDT","id":32402506289,"side":"Sell","size":32000,"price":3110.05,"timestamp":"2024-05-18T15:46:17.993Z"},{"symbol":"ETHUSDT","id":32402506257,"side":"Sell","size":28000,"price":3109.43,"timestamp":"2024-05-18T15:46:17.993Z"},{"symbol":"ETHUSDT","id":32402505858,"side":"Sell","size":32000,"price":3110.10,"timestamp":"2024-05-18T15:46:17.993Z"},{"symbol":"ETHUSDT","id":32402506166,"side":"Sell","size":21000,"price":3109.03,"timestamp":"2024-05-18T15:46:17.993Z"},{"symbol":"ETHUSDT","id":32402505825,"side":"Sell","size":28000,"price":3109.63,"timestamp":"2024-05-18T15:46:17.993Z"},{"symbol":"ETHUSDT","id":32402506275,"side":"Sell","size":21000,"price":3108.67,"timestamp":"2024-05-18T15:46:17.993Z"},{"symbol":"ETHUSDT","id":32402506278,"side":"Buy","size":100000,"price":3107.40,"timestamp":"2024-05-18T15:46:17.993Z"},{"symbol":"ETHUSDT","id":32402505759,"side":"Buy","size":32000,"price":3108.61,"timestamp":"2024-05-18T15:46:17.993Z"},{"symbol":"ETHUSDT","id":32402505928,"side":"Buy","size":100000,"price":3106.12,"timestamp":"2024-05-18T15:46:17.993Z"},{"symbol":"ETHUSDT","id":32402505870,"side":"Buy","size":100000,"price":3106.28,"timestamp":"2024-05-18T15:46:17.993Z"},{"symbol":"ETHUSDT","id":32402506000,"side":"Buy","size":1000,"price":3108.31,"timestamp":"2024-05-18T15:46:17.993Z"},{"symbol":"ETHUSDT","id":32402506251,"side":"Buy","size":32000,"price":3108.58,"timestamp":"2024-05-18T15:46:17.993Z"},{"symbol":"ETHUSDT","id":32402506155,"side":"Buy","size":1000,"price":3108.32,"timestamp":"2024-05-18T15:46:17.993Z"}]}
{"table":"orderBookL2_25","action":"delete","data":[{"symbol":"XBTUSDT","id":32402503875,"side":"Sell","price":66785.2,"timestamp":"2024-05-18T15:46:17.997Z"},{"symbol":"XBTUSDT","id":32402505712,"side":"Sell","price":66783.2,"timestamp":"2024-05-18T15:46:17.997Z"},{"symbol":"XBTUSDT","id":32402504839,"side":"Sell","price":66797.1,"timestamp":"2024-05-18T15:46:17.997Z"},{"symbol":"XBTUSDT","id":32402502274,"side":"Sell","price":66799.8,"timestamp":"2024-05-18T15:46:17.997Z"},{"symbol":"XBTUSDT","id":32402505768,"side":"Sell","price":66783.1,"timestamp":"2024-05-18T15:46:17.997Z"},{"symbol":"XBTUSDT","id":32402500188,"side":"Sell","price":66798.1,"timestamp":"2024-05-18T15:46:17.997Z"},{"symbol":"XBTUSDT","id":32402504725,"side":"Sell","price":66791.5,"timestamp":"2024-05-18T15:46:17.997Z"},{"symbol":"XBTUSDT","id":32402504548,"side":"Buy","price":66733.9,"timestamp":"2024-05-18T15:46:17.997Z"},{"symbol":"XBTUSDT","id":32402504789,"side":"Buy","price":66741.8,"timestamp":"2024-05-18T15:46:17.997Z"},{"symbol":"XBTUSDT","id":32402504250,"side":"Buy","price":66736.2,"timestamp":"2024-05-18T15:46:17.997Z"},{"symbol":"XBTUSDT","id":32402238752,"side":"Buy","price":66694.4,"timestamp":"2024-05-18T15:46:17.997Z"},{"symbol":"XBTUSDT","id":32401160404,"side":"Buy","price":66697.3,"timestamp":"2024-05-18T15:46:17.997Z"},{"symbol":"XBTUSDT","id":32402505136,"side":"Buy","price":66697.4,"timestamp":"2024-05-18T15:46:17.997Z"},{"symbol":"XBTUSDT","id":32402505627,"side":"Buy","price":66740.8,"timestamp":"2024-05-18T15:46:17.997Z"},{"symbol":"XBTUSDT","id":32402504711,"side":"Buy","price":66699.8,"timestamp":"2024-05-18T15:46:17.997Z"},{"symbol":"XBTUSDT","id":32402505090,"side":"Buy","price":66740.3,"timestamp":"2024-05-18T15:46:17.997Z"}]}
{"table":"orderBookL2_25","action":"update","data":[{"symbol":"XBTUSDT","id":32402503304,"side":"Sell","size":100000,"price":66781.8,"timestamp":"2024-05-18T15:46:17.997Z"},{"symbol":"XBTUSDT","id":32402504314,"side":"Sell","size":40000,"price":66781.7,"timestamp":"2024-05-18T15:46:17.997Z"}]}
{"table":"orderBookL2_25","action":"insert","data":[{"symbol":"XBTUSDT","id":32402506205,"side":"Sell","size":2000,"price":66786.0,"timestamp":"2024-05-18T15:46:17.997Z"},{"symbol":"XBTUSDT","id":32402506112,"side":"Sell","size":1000,"price":66781.3,"timestamp":"2024-05-18T15:46:17.997Z"},{"symbol":"XBTUSDT","id":32402506050,"side":"Sell","size":94000,"price":66778.4,"timestamp":"2024-05-18T15:46:17.997Z"},{"symbol":"XBTUSDT","id":32402506034,"side":"Sell","size":20000,"price":66775.3,"timestamp":"2024-05-18T15:46:17.997Z"},{"symbol":"XBTUSDT","id":32402506139,"side":"Sell","size":20000,"price":66775.4,"timestamp":"2024-05-18T15:46:17.997Z"},{"symbol":"XBTUSDT","id":32402506045,"side":"Sell","size":6000,"price":66776.8,"timestamp":"2024-05-18T15:46:17.997Z"},{"symbol":"XBTUSDT","id":32402506178,"side":"Sell","size":1000,"price":66781.2,"timestamp":"2024-05-18T15:46:17.997Z"},{"symbol":"XBTUSDT","id":32402505864,"side":"Buy","size":100000,"price":66740.6,"timestamp":"2024-05-18T15:46:17.997Z"},{"symbol":"XBTUSDT","id":32402505951,"side":"Buy","size":20000,"price":66736.2,"timestamp":"2024-05-18T15:46:17.997Z"},{"symbol":"XBTUSDT","id":32402505797,"side":"Buy","size":1502000,"price":66718.8,"timestamp":"2024-05-18T15:46:17.997Z"},{"symbol":"XBTUSDT","id":32402506008,"side":"Buy","size":20000,"price":66741.2,"timestamp":"2024-05-18T15:46:17.997Z"},{"symbol":"XBTUSDT","id":32402506188,"side":"Buy","size":21000,"price":66750.9,"timestamp":"2024-05-18T15:46:17.997Z"},{"symbol":"XBTUSDT","id":32402505830,"side":"Buy","size":454000,"price":66723.3,"timestamp":"2024-05-18T15:46:17.997Z"},{"symbol":"XBTUSDT","id":32402505821,"side":"Buy","size":2000,"price":66764.4,"timestamp":"2024-05-18T15:46:17.997Z"},{"symbol":"XBTUSDT","id":32402506005,"side":"Buy","size":20000,"price":66741.1,"timestamp":"2024-05-18T15:46:17.997Z"},{"symbol":"XBTUSDT","id":32402505977,"side":"Buy","size":100000,"price":66706.1,"timestamp":"2024-05-18T15:46:17.997Z"}]}
{"table":"orderBookL2_25","action":"delete","data":[{"symbol":"ETHUSDT","id":32402506209,"side":"Sell","price":3109.27,"timestamp":"2024-05-18T15:46:18.042Z"},{"symbol":"ETHUSDT","id":32402505825,"side":"Sell","price":3109.63,"timestamp":"2024-05-18T15:46:18.042Z"},{"symbol":"ETHUSDT","id":32402506064,"side":"Sell","price":3108.85,"timestamp":"2024-05-18T15:46:18.042Z"},{"symbol":"ETHUSDT","id":32402506289,"side":"Sell","price":3110.05,"timestamp":"2024-05-18T15:46:18.042Z"},{"symbol":"ETHUSDT","id":32402506257,"side":"Sell","price":3109.43,"timestamp":"2024-05-18T15:46:18.042Z"},{"symbol":"ETHUSDT","id":32402505858,"side":"Sell","price":3110.10,"timestamp":"2024-05-18T15:46:18.042Z"},{"symbol":"ETHUSDT","id":32402502023,"side":"Sell","price":3109.91,"timestamp":"2024-05-18T15:46:18.042Z"},{"symbol":"ETHUSDT","id":32402506166,"side":"Sell","price":3109.03,"timestamp":"2024-05-18T15:46:18.042Z"},{"symbol":"ETHUSDT","id":32402504795,"side":"Sell","price":3109.72,"timestamp":"2024-05-18T15:46:18.042Z"},{"symbol":"ETHUSDT","id":32402506275,"side":"Sell","price":3108.67,"timestamp":"2024-05-18T15:46:18.042Z"},{"symbol":"ETHUSDT","id":32402506000,"side":"Buy","price":3108.31,"timestamp":"2024-05-18T15:46:18.042Z"},{"symbol":"ETHUSDT","id":32402505759,"side":"Buy","price":3108.61,"timestamp":"2024-05-18T15:46:18.042Z"},{"symbol":"ETHUSDT","id":32402506251,"side":"Buy","price":3108.58,"timestamp":"2024-05-18T15:46:18.042Z"},{"symbol":"ETHUSDT","id":32402506155,"side":"Buy","price":3108.32,"timestamp":"2024-05-18T15:46:18.042Z"}]}
{"table":"orderBookL2_25","action":"update","data":[{"symbol":"ETHUSDT","id":32402496871,"side":"Sell","size":100000,"price":3110.88,"timestamp":"2024-05-18T15:46:18.042Z"},{"symbol":"ETHUSDT","id":32402496877,"side":"Sell","size":63000,"price":3110.84,"timestamp":"2024-05-18T15:46:18.042Z"},{"symbol":"ETHUSDT","id":32402506255,"side":"Sell","size":942000,"price":3110.98,"timestamp":"2024-05-18T15:46:18.042Z"},{"symbol":"ETHUSDT","id":32402505422,"side":"Sell","size":3000,"price":3109.07,"timestamp":"2024-05-18T15:46:18.042Z"}]}
{"table":"orderBookL2_25","action":"insert","data":[{"symbol":"ETHUSDT","id":32402488478,"side":"Sell","size":145000,"price":3111.05,"timestamp":"2024-05-18T15:46:18.042Z"},{"symbol":"ETHUSDT","id":32402506732,"side":"Sell","size":32000,"price":3109.96,"timestamp":"2024-05-18T15:46:18.042Z"},{"symbol":"ETHUSDT","id":32402506801,"side":"Sell","size":21000,"price":3108.57,"timestamp":"2024-05-18T15:46:18.042Z"},{"symbol":"ETHUSDT","id":32402506660,"side":"Sell","size":32000,"price":3109.97,"timestamp":"2024-05-18T15:46:18.042Z"},{"symbol":"ETHUSDT","id":32402487799,"side":"Sell","size":241000,"price":3111.06,"timestamp":"2024-05-18T15:46:18.042Z"},{"symbol":"ETHUSDT","id":32402506555,"side":"Sell","size":100000,"price":3109.87,"timestamp":"2024-05-18T15:46:18.042Z"},{"symbol":"ETHUSDT","id":32402506566,"side":"Sell","size":100000,"price":3110.03,"timestamp":"2024-05-18T15:46:18.042Z"},{"symbol":"ETHUSDT","id":32402504489,"side":"Sell","size":49000,"price":3111.02,"timestamp":"2024-05-18T15:46:18.042Z"},{"symbol":"ETHUSDT","id":32402485810,"side":"Sell","size":24000,"price":3111.07,"timestamp":"2024-05-18T15:46:18.042Z"},{"symbol":"ETHUSDT","id":32402506431,"side":"Sell","size":21000,"price":3108.61,"timestamp":"2024-05-18T15:46:18.042Z"},{"symbol":"ETHUSDT","id":32402506439,"side":"Buy","size":1000,"price":3108.27,"timestamp":"2024-05-18T15:46:18.042Z"},{"symbol":"ETHUSDT","id":32402506606,"side":"Buy","size":32000,"price":3108.51,"timestamp":"2024-05-18T15:46:18.042Z"},{"symbol":"ETHUSDT","id":32402506597,"side":"Buy","size":1000,"price":3108.26,"timestamp":"2024-05-18T15:46:18.042Z"},{"symbol":"ETHUSDT","id":32402506642,"side":"Buy","size":32000,"price":3108.50,"timestamp":"2024-05-18T15:46:18.042Z"}]}
{"table":"orderBookL2_25","action":"delete","data":[{"symbol":"XBTUSDT","id":32402506034,"side":"Sell","price":66775.3,"timestamp":"2024-05-18T15:46:18.046Z"},{"symbol":"XBTUSDT","id":32402504870,"side":"Sell","price":66795.7,"timestamp":"2024-05-18T15:46:18.046Z"},{"symbol":"XBTUSDT","id":32402506205,"side":"Sell","price":66786.0,"timestamp":"2024-05-18T15:46:18.046Z"},{"symbol":"XBTUSDT","id":32402506045,"side":"Sell","price":66776.8,"timestamp":"2024-05-18T15:46:18.046Z"},{"symbol":"XBTUSDT","id":32402506178,"side":"Sell","price":66781.2,"timestamp":"2024-05-18T15:46:18.046Z"},{"symbol":"XBTUSDT","id":32402506139,"side":"Sell","price":66775.4,"timestamp":"2024-05-18T15:46:18.046Z"},{"symbol":"XBTUSDT","id":32402506112,"side":"Sell","price":66781.3,"timestamp":"2024-05-18T15:46:18.046Z"},{"symbol":"XBTUSDT","id":32402505757,"side":"Sell","price":66795.8,"timestamp":"2024-05-18T15:46:18.046Z"},{"symbol":"XBTUSDT","id":32402503304,"side":"Sell","price":66781.8,"timestamp":"2024-05-18T15:46:18.046Z"},{"symbol":"XBTUSDT","id":32402505830,"side":"Buy","price":66723.3,"timestamp":"2024-05-18T15:46:18.046Z"},{"symbol":"XBTUSDT","id":32401436741,"side":"Buy","price":66702.2,"timestamp":"2024-05-18T15:46:18.046Z"},{"symbol":"XBTUSDT","id":32402506188,"side":"Buy","price":66750.9,"timestamp":"2024-05-18T15:46:18.046Z"},{"symbol":"XBTUSDT","id":32402506005,"side":"Buy","price":66741.1,"timestamp":"2024-05-18T15:46:18.046Z"},{"symbol":"XBTUSDT","id":32402505578,"side":"Buy","price":66747.0,"timestamp":"2024-05-18T15:46:18.046Z"},{"symbol":"XBTUSDT","id":32402506008,"side":"Buy","price":66741.2,"timestamp":"2024-05-18T15:46:18.046Z"}]}
{"table":"orderBookL2_25","action":"update","data":[{"symbol":"XBTUSDT","id":32402502861,"side":"Sell","size":100000,"price":66784.3,"timestamp":"2024-05-18T15:46:18.046Z"},{"symbol":"XBTUSDT","id":32402491670,"side":"Sell","size":100000,"price":66795.5,"timestamp":"2024-05-18T15:46:18.046Z"},{"symbol":"XBTUSDT","id":32402504314,"side":"Sell","size":532000,"price":66781.7,"timestamp":"2024-05-18T15:46:18.046Z"}]}
{"table":"orderBookL2_25","action":"insert","data":[{"symbol":"XBTUSDT","id":32402506723,"side":"Sell","size":159000,"price":66783.4,"timestamp":"2024-05-18T15:46:18.046Z"},{"symbol":"XBTUSDT","id":32402506876,"side":"Sell","size":20000,"price":66773.7,"timestamp":"2024-05-18T15:46:18.046Z"},{"symbol":"XBTUSDT","id":32402506886,"side":"Sell","size":1000,"price":66780.9,"timestamp":"2024-05-18T15:46:18.046Z"},{"symbol":"XBTUSDT","id":32402506656,"side":"Sell","size":11000,"price":66786.2,"timestamp":"2024-05-18T15:46:18.046Z"},{"symbol":"XBTUSDT","id":32402506584,"side":"Sell","size":1000,"price":66781.0,"timestamp":"2024-05-18T15:46:18.046Z"},{"symbol":"XBTUSDT","id":32402506378,"side":"Sell","size":12000,"price":66764.5,"timestamp":"2024-05-18T15:46:18.046Z"},{"symbol":"XBTUSDT","id":32402506758,"side":"Sell","size":2000,"price":66787.0,"timestamp":"2024-05-18T15:46:18.046Z"},{"symbol":"XBTUSDT","id":32402506714,"side":"Sell","size":200000,"price":66772.0,"timestamp":"2024-05-18T15:46:18.046Z"},{"symbol":"XBTUSDT","id":32402506824,"side":"Sell","size":20000,"price":66773.8,"timestamp":"2024-05-18T15:46:18.046Z"},{"symbol":"XBTUSDT","id":32402506662,"side":"Buy","size":20000,"price":66741.8,"timestamp":"2024-05-18T15:46:18.046Z"},{"symbol":"XBTUSDT","id":32402506811,"side":"Buy","size":20000,"price":66741.7,"timestamp":"2024-05-18T15:46:18.046Z"},{"symbol":"XBTUSDT","id":32402506562,"side":"Buy","size":36000,"price":66750.5,"timestamp":"2024-05-18T15:46:18.046Z"},{"symbol":"XBTUSDT","id":32402506821,"side":"Buy","size":8000,"price":66747.1,"timestamp":"2024-05-18T15:46:18.046Z"},{"symbol":"XBTUSDT","id":32402506460,"side":"Buy","size":360000,"price":66731.9,"timestamp":"2024-05-18T15:46:18.046Z"},{"symbol":"XBTUSDT","id":32402506751,"side":"Buy","size":8000,"price":66757.7,"timestamp":"2024-05-18T15:46:18.046Z"}]}
{"table":"orderBookL2_25","action":"delete","data":[{"symbol":"ETHUSDT","id":32402506431,"side":"Sell","price":3108.61,"timestamp":"2024-05-18T15:46:18.091Z"},{"symbol":"ETHUSDT","id":32402506732,"side":"Sell","price":3109.96,"timestamp":"2024-05-18T15:46:18.091Z"},{"symbol":"ETHUSDT","id":32402504595,"side":"Sell","price":3110.29,"timestamp":"2024-05-18T15:46:18.091Z"},{"symbol":"ETHUSDT","id":32402505422,"side":"Sell","price":3109.07,"timestamp":"2024-05-18T15:46:18.091Z"},{"symbol":"ETHUSDT","id":32400902751,"side":"Buy","price":3105.39,"timestamp":"2024-05-18T15:46:18.091Z"},{"symbol":"ETHUSDT","id":32402506642,"side":"Buy","price":3108.50,"timestamp":"2024-05-18T15:46:18.091Z"},{"symbol":"ETHUSDT","id":32402506597,"side":"Buy","price":3108.26,"timestamp":"2024-05-18T15:46:18.091Z"},{"symbol":"ETHUSDT","id":32401445960,"side":"Buy","price":3105.40,"timestamp":"2024-05-18T15:46:18.091Z"}]}
{"table":"orderBookL2_25","action":"update","data":[{"symbol":"ETHUSDT","id":32402487799,"side":"Sell","size":241000,"price":3111.06,"timestamp":"2024-05-18T15:46:18.091Z"},{"symbol":"ETHUSDT","id":32402485810,"side":"Sell","size":24000,"price":3111.07,"timestamp":"2024-05-18T15:46:18.091Z"}]}
{"table":"orderBookL2_25","action":"insert","data":[{"symbol":"ETHUSDT","id":32402506945,"side":"Sell","size":28000,"price":3108.97,"timestamp":"2024-05-18T15:46:18.091Z"},{"symbol":"ETHUSDT","id":32402494486,"side":"Sell","size":100000,"price":3111.20,"timestamp":"2024-05-18T15:46:18.091Z"},{"symbol":"ETHUSDT","id":32402487481,"side":"Sell","size":100000,"price":3111.10,"timestamp":"2024-05-18T15:46:18.091Z"},{"symbol":"ETHUSDT","id":32402507037,"side":"Sell","size":32000,"price":3109.96,"timestamp":"2024-05-18T15:46:18.091Z"},{"symbol":"ETHUSDT","id":32402507018,"side":"Buy","size":32000,"price":3108.50,"timestamp":"2024-05-18T15:46:18.091Z"},{"symbol":"ETHUSDT","id":32402506895,"side":"Buy","size":1000,"price":3108.26,"timestamp":"2024-05-18T15:46:18.091Z"},{"symbol":"ETHUSDT","id":32402507141,"side":"Buy","size":43000,"price":3108.52,"timestamp":"2024-05-18T15:46:18.091Z"},{"symbol":"ETHUSDT","id":32402506878,"side":"Buy","size":160000,"price":3107.03,"timestamp":"2024-05-18T15:46:18.091Z"}]}
{"table":"orderBookL2_25","action":"delete","data":[{"symbol":"XBTUSDT","id":32402506584,"side":"Sell","price":66781.0,"timestamp":"2024-05-18T15:46:18.095Z"},{"symbol":"XBTUSDT","id":32402491670,"side":"Sell","price":66795.5,"timestamp":"2024-05-18T15:46:18.095Z"},{"symbol":"XBTUSDT","id":32402506876,"side":"Sell","price":66773.7,"timestamp":"2024-05-18T15:46:18.095Z"},{"symbol":"XBTUSDT","id":32402506824,"side":"Sell","price":66773.8,"timestamp":"2024-05-18T15:46:18.095Z"},{"symbol":"XBTUSDT","id":32402506758,"side":"Sell","price":66787.0,"timestamp":"2024-05-18T15:46:18.095Z"},{"symbol":"XBTUSDT","id":32402491799,"side":"Sell","price":66795.4,"timestamp":"2024-05-18T15:46:18.095Z"},{"symbol":"XBTUSDT","id":32402506886,"side":"Sell","price":66780.9,"timestamp":"2024-05-18T15:46:18.095Z"},{"symbol":"XBTUSDT","id":32402506811,"side":"Buy","price":66741.7,"timestamp":"2024-05-18T15:46:18.095Z"},{"symbol":"XBTUSDT","id":32402505684,"side":"Buy","price":66702.3,"timestamp":"2024-05-18T15:46:18.095Z"},{"symbol":"XBTUSDT","id":32402506460,"side":"Buy","price":66731.9,"timestamp":"2024-05-18T15:46:18.095Z"},{"symbol":"XBTUSDT","id":32402506662,"side":"Buy","price":66741.8,"timestamp":"2024-05-18T15:46:18.095Z"}]}
{"table":"orderBookL2_25","action":"update","data":[{"symbol":"XBTUSDT","id":32402506378,"side":"Sell","size":12000,"price":66764.5,"timestamp":"2024-05-18T15:46:18.095Z"},{"symbol":"XBTUSDT","id":32402506050,"side":"Sell","size":456000,"price":66778.4,"timestamp":"2024-05-18T15:46:18.095Z"},{"symbol":"XBTUSDT","id":32402504314,"side":"Sell","size":40000,"price":66781.7,"timestamp":"2024-05-18T15:46:18.095Z"}]}
{"table":"orderBookL2_25","action":"insert","data":[{"symbol":"XBTUSDT","id":32402507022,"side":"Sell","size":20000,"price":66766.1,"timestamp":"2024-05-18T15:46:18.095Z"},{"symbol":"XBTUSDT","id":32402507168,"side":"Sell","size":1000,"price":66780.5,"timestamp":"2024-05-18T15:46:18.095Z"},{"symbol":"XBTUSDT","id":32402507091,"side":"Sell","size":1000,"price":66780.6,"timestamp":"2024-05-18T15:46:18.095Z"},{"symbol":"XBTUSDT","id":32402507179,"side":"Sell","size":94000,"price":66773.3,"timestamp":"2024-05-18T15:46:18.095Z"},{"symbol":"XBTUSDT","id":32402507103,"side":"Sell","size":2000,"price":66789.0,"timestamp":"2024-05-18T15:46:18.095Z"},{"symbol":"XBTUSDT","id":32402506980,"side":"Sell","size":3000,"price":66781.8,"timestamp":"2024-05-18T15:46:18.095Z"},{"symbol":"XBTUSDT","id":32402507221,"side":"Sell","size":20000,"price":66773.2,"timestamp":"2024-05-18T15:46:18.095Z"},{"symbol":"XBTUSDT","id":32402507156,"side":"Buy","size":100000,"price":66747.4,"timestamp":"2024-05-18T15:46:18.095Z"},{"symbol":"XBTUSDT","id":32402507225,"side":"Buy","size":450000,"price":66723.2,"timestamp":"2024-05-18T15:46:18.095Z"},{"symbol":"XBTUSDT","id":32402507112,"side":"Buy","size":20000,"price":66741.6,"timestamp":"2024-05-18T15:46:18.095Z"},{"symbol":"XBTUSDT","id":32402507223,"side":"Buy","size":20000,"price":66741.7,"timestamp":"2024-05-18T15:46:18.095Z"}]}
{"table":"orderBookL2_25","action":"delete","data":[{"symbol":"ETHUSDT","id":32402501905,"side":"Sell","price":3109.56,"timestamp":"2024-05-18T15:46:18.140Z"},{"symbol":"ETHUSDT","id":32402506439,"side":"Buy","price":3108.27,"timestamp":"2024-05-18T15:46:18.140Z"}]}
{"table":"orderBookL2_25","action":"update","data":[{"symbol":"ETHUSDT","id":32402506255,"side":"Sell","size":2099000,"price":3110.98,"timestamp":"2024-05-18T15:46:18.140Z"}]}
{"table":"orderBookL2_25","action":"insert","data":[{"symbol":"ETHUSDT","id":32402507306,"side":"Sell","size":43000,"price":3109.90,"timestamp":"2024-05-18T15:46:18.140Z"},{"symbol":"ETHUSDT","id":32402507422,"side":"Buy","size":1000,"price":3108.27,"timestamp":"2024-05-18T15:46:18.140Z"}]}
{"table":"orderBookL2_25","action":"delete","data":[{"symbol":"XBTUSDT","id":32402507221,"side":"Sell","price":66773.2,"timestamp":"2024-05-18T15:46:18.144Z"},{"symbol":"XBTUSDT","id":32402505244,"side":"Sell","price":66776.9,"timestamp":"2024-05-18T15:46:18.144Z"},{"symbol":"XBTUSDT","id":32402506050,"side":"Sell","price":66778.4,"timestamp":"2024-05-18T15:46:18.144Z"},{"symbol":"XBTUSDT","id":32402496984,"side":"Buy","price":66702.5,"timestamp":"2024-05-18T15:46:18.144Z"},{"symbol":"XBTUSDT","id":32402507225,"side":"Buy","price":66723.2,"timestamp":"2024-05-18T15:46:18.144Z"},{"symbol":"XBTUSDT","id":32402507112,"side":"Buy","price":66741.6,"timestamp":"2024-05-18T15:46:18.144Z"},{"symbol":"XBTUSDT","id":32402507223,"side":"Buy","price":66741.7,"timestamp":"2024-05-18T15:46:18.144Z"}]}
{"table":"orderBookL2_25","action":"update","data":[{"symbol":"XBTUSDT","id":32402502728,"side":"Sell","size":156000,"price":66794.6,"timestamp":"2024-05-18T15:46:18.144Z"},{"symbol":"XBTUSDT","id":32402507179,"side":"Sell","size":94000,"price":66773.3,"timestamp":"2024-05-18T15:46:18.144Z"},{"symbol":"XBTUSDT","id":32402506378,"side":"Sell","size":112000,"price":66764.5,"timestamp":"2024-05-18T15:46:18.144Z"},{"symbol":"XBTUSDT","id":32402505864,"side":"Buy","size":100000,"price":66740.6,"timestamp":"2024-05-18T15:46:18.144Z"}]}
{"table":"orderBookL2_25","action":"insert","data":[{"symbol":"XBTUSDT","id":32402507340,"side":"Sell","size":2000,"price":66790.3,"timestamp":"2024-05-18T15:46:18.144Z"},{"symbol":"XBTUSDT","id":32402507440,"side":"Sell","size":20000,"price":66773.4,"timestamp":"2024-05-18T15:46:18.144Z"},{"symbol":"XBTUSDT","id":32402507319,"side":"Sell","size":446000,"price":66776.8,"timestamp":"2024-05-18T15:46:18.144Z"},{"symbol":"XBTUSDT","id":32402507312,"side":"Buy","size":20000,"price":66726.0,"timestamp":"2024-05-18T15:46:18.144Z"},{"symbol":"XBTUSDT","id":32402507432,"side":"Buy","size":20000,"price":66741.3,"timestamp":"2024-05-18T15:46:18.144Z"},{"symbol":"XBTUSDT","id":32402507316,"side":"Buy","size":370000,"price":66730.5,"timestamp":"2024-05-18T15:46:18.144Z"},{"symbol":"XBTUSDT","id":32402507443,"side":"Buy","size":20000,"price":66741.4,"timestamp":"2024-05-18T15:46:18.144Z"}]}
{"table":"orderBookL2_25","action":"delete","data":[{"symbol":"ETHUSDT","id":32402507422,"side":"Buy","price":3108.27,"timestamp":"2024-05-18T15:46:18.189Z"}]}
{"table":"orderBookL2_25","action":"insert","data":[{"symbol":"ETHUSDT","id":32402507553,"side":"Buy","size":1000,"price":3108.25,"timestamp":"2024-05-18T15:46:18.189Z"}]}
{"table":"orderBookL2_25","action":"delete","data":[{"symbol":"XBTUSDT","id":32402507103,"side":"Sell","price":66789.0,"timestamp":"2024-05-18T15:46:18.193Z"},{"symbol":"XBTUSDT","id":32402507312,"side":"Buy","price":66726.0,"timestamp":"2024-05-18T15:46:18.193Z"},{"symbol":"XBTUSDT","id":32402504312,"side":"Buy","price":66757.6,"timestamp":"2024-05-18T15:46:18.193Z"}]}
{"table":"orderBookL2_25","action":"update","data":[{"symbol":"XBTUSDT","id":32402505977,"side":"Buy","size":100000,"price":66706.1,"timestamp":"2024-05-18T15:46:18.193Z"},{"symbol":"XBTUSDT","id":32402505951,"side":"Buy","size":31000,"price":66736.2,"timestamp":"2024-05-18T15:46:18.193Z"}]}
{"table":"orderBookL2_25","action":"insert","data":[{"symbol":"XBTUSDT","id":32402491799,"side":"Sell","size":12000,"price":66795.4,"timestamp":"2024-05-18T15:46:18.193Z"},{"symbol":"XBTUSDT","id":32402507589,"side":"Buy","size":100000,"price":66750.8,"timestamp":"2024-05-18T15:46:18.193Z"},{"symbol":"XBTUSDT","id":32402507600,"side":"Buy","size":18000,"price":66723.5,"timestamp":"2024-05-18T15:46:18.193Z"}]}
{"table":"orderBookL2_25","action":"delete","data":[{"symbol":"ETHUSDT","id":32402506660,"side":"Sell","price":3109.97,"timestamp":"2024-05-18T15:46:18.238Z"},{"symbol":"ETHUSDT","id":32402507037,"side":"Sell","price":3109.96,"timestamp":"2024-05-18T15:46:18.238Z"},{"symbol":"ETHUSDT","id":32402507018,"side":"Buy","price":3108.50,"timestamp":"2024-05-18T15:46:18.238Z"},{"symbol":"ETHUSDT","id":32402506606,"side":"Buy","price":3108.51,"timestamp":"2024-05-18T15:46:18.238Z"},{"symbol":"ETHUSDT","id":32402507553,"side":"Buy","price":3108.25,"timestamp":"2024-05-18T15:46:18.238Z"},{"symbol":"ETHUSDT","id":32402506895,"side":"Buy","price":3108.26,"timestamp":"2024-05-18T15:46:18.238Z"}]}
{"table":"orderBookL2_25","action":"update","data":[{"symbol":"ETHUSDT","id":32402507141,"side":"Buy","size":75000,"price":3108.52,"timestamp":"2024-05-18T15:46:18.238Z"}]}
{"table":"orderBookL2_25","action":"insert","data":[{"symbol":"ETHUSDT","id":32402507808,"side":"Sell","size":32000,"price":3110.01,"timestamp":"2024-05-18T15:46:18.238Z"},{"symbol":"ETHUSDT","id":32402507823,"side":"Sell","size":32000,"price":3110.00,"timestamp":"2024-05-18T15:46:18.238Z"},{"symbol":"ETHUSDT","id":32402507765,"side":"Buy","size":1000,"price":3108.29,"timestamp":"2024-05-18T15:46:18.238Z"},{"symbol":"ETHUSDT","id":32401445960,"side":"Buy","size":100000,"price":3105.40,"timestamp":"2024-05-18T15:46:18.238Z"},{"symbol":"ETHUSDT","id":32402507745,"side":"Buy","size":32000,"price":3108.53,"timestamp":"2024-05-18T15:46:18.238Z"},{"symbol":"ETHUSDT","id":32402507657,"side":"Buy","size":1000,"price":3108.28,"timestamp":"2024-05-18T15:46:18.238Z"}]}
{"table":"orderBookL2_25","action":"delete","data":[{"symbol":"XBTUSDT","id":32402491799,"side":"Sell","price":66795.4,"timestamp":"2024-05-18T15:46:18.242Z"},{"symbol":"XBTUSDT","id":32402506562,"side":"Buy","price":66750.5,"timestamp":"2024-05-18T15:46:18.242Z"},{"symbol":"XBTUSDT","id":32402507600,"side":"Buy","price":66723.5,"timestamp":"2024-05-18T15:46:18.242Z"}]}
{"table":"orderBookL2_25","action":"update","data":[{"symbol":"XBTUSDT","id":32402506378,"side":"Sell","size":212000,"price":66764.5,"timestamp":"2024-05-18T15:46:18.242Z"},{"symbol":"XBTUSDT","id":32402505977,"side":"Buy","size":100000,"price":66706.1,"timestamp":"2024-05-18T15:46:18.242Z"},{"symbol":"XBTUSDT","id":32402505951,"side":"Buy","size":11000,"price":66736.2,"timestamp":"2024-05-18T15:46:18.242Z"}]}
{"table":"orderBookL2_25","action":"insert","data":[{"symbol":"XBTUSDT","id":32402507762,"side":"Sell","size":2000,"price":66787.5,"timestamp":"2024-05-18T15:46:18.242Z"},{"symbol":"XBTUSDT","id":32402507731,"side":"Buy","size":36000,"price":66747.9,"timestamp":"2024-05-18T15:46:18.242Z"},{"symbol":"XBTUSDT","id":32402507770,"side":"Buy","size":20000,"price":66746.9,"timestamp":"2024-05-18T15:46:18.242Z"}]}
{"table":"orderBookL2_25","action":"delete","data":[{"symbol":"ETHUSDT","id":32402507808,"side":"Sell","price":3110.01,"timestamp":"2024-05-18T15:46:18.287Z"},{"symbol":"ETHUSDT","id":32402499932,"side":"Sell","price":3110.68,"timestamp":"2024-05-18T15:46:18.287Z"},{"symbol":"ETHUSDT","id":32402485810,"side":"Sell","price":3111.07,"timestamp":"2024-05-18T15:46:18.287Z"},{"symbol":"ETHUSDT","id":32402231045,"side":"Buy","price":3105.80,"timestamp":"2024-05-18T15:46:18.287Z"},{"symbol":"ETHUSDT","id":32402507657,"side":"Buy","price":3108.28,"timestamp":"2024-05-18T15:46:18.287Z"},{"symbol":"ETHUSDT","id":32401445960,"side":"Buy","price":3105.40,"timestamp":"2024-05-18T15:46:18.287Z"}]}
{"table":"orderBookL2_25","action":"update","data":[{"symbol":"ETHUSDT","id":32402507141,"side":"Buy","size":43000,"price":3108.52,"timestamp":"2024-05-18T15:46:18.287Z"}]}
{"table":"orderBookL2_25","action":"insert","data":[{"symbol":"ETHUSDT","id":32402508052,"side":"Sell","size":32000,"price":3109.99,"timestamp":"2024-05-18T15:46:18.287Z"},{"symbol":"ETHUSDT","id":32402494493,"side":"Sell","size":100000,"price":3111.26,"timestamp":"2024-05-18T15:46:18.287Z"},{"symbol":"ETHUSDT","id":32402494475,"side":"Sell","size":160000,"price":3111.21,"timestamp":"2024-05-18T15:46:18.287Z"},{"symbol":"ETHUSDT","id":32402508086,"side":"Buy","size":1000,"price":3108.30,"timestamp":"2024-05-18T15:46:18.287Z"},{"symbol":"ETHUSDT","id":32402507985,"side":"Buy","size":24000,"price":3108.25,"timestamp":"2024-05-18T15:46:18.287Z"},{"symbol":"ETHUSDT","id":32402508050,"side":"Buy","size":32000,"price":3108.54,"timestamp":"2024-05-18T15:46:18.287Z"}]}
{"table":"orderBookL2_25","action":"delete","data":[{"symbol":"XBTUSDT","id":32402502728,"side":"Sell","price":66794.6,"timestamp":"2024-05-18T15:46:18.291Z"},{"symbol":"XBTUSDT","id":32402507319,"side":"Sell","price":66776.8,"timestamp":"2024-05-18T15:46:18.291Z"},{"symbol":"XBTUSDT","id":32402507168,"side":"Sell","price":66780.5,"timestamp":"2024-05-18T15:46:18.291Z"},{"symbol":"XBTUSDT","id":32402507443,"side":"Buy","price":66741.4,"timestamp":"2024-05-18T15:46:18.291Z"},{"symbol":"XBTUSDT","id":32402507316,"side":"Buy","price":66730.5,"timestamp":"2024-05-18T15:46:18.291Z"}]}
{"table":"orderBookL2_25","action":"update","data":[{"symbol":"XBTUSDT","id":32402507179,"side":"Sell","size":74000,"price":66773.3,"timestamp":"2024-05-18T15:46:18.291Z"},{"symbol":"XBTUSDT","id":32402506980,"side":"Sell","size":25000,"price":66781.8,"timestamp":"2024-05-18T15:46:18.291Z"},{"symbol":"XBTUSDT","id":32402505951,"side":"Buy","size":33000,"price":66736.2,"timestamp":"2024-05-18T15:46:18.291Z"}]}
{"table":"orderBookL2_25","action":"insert","data":[{"symbol":"XBTUSDT","id":32402508078,"side":"Sell","size":20000,"price":66773.5,"timestamp":"2024-05-18T15:46:18.291Z"},{"symbol":"XBTUSDT","id":32402507892,"side":"Sell","size":384000,"price":66771.9,"timestamp":"2024-05-18T15:46:18.291Z"},{"symbol":"XBTUSDT","id":32402508040,"side":"Sell","size":1000,"price":66780.7,"timestamp":"2024-05-18T15:46:18.291Z"},{"symbol":"XBTUSDT","id":32402508042,"side":"Buy","size":350000,"price":66733.9,"timestamp":"2024-05-18T15:46:18.291Z"},{"symbol":"XBTUSDT","id":32402508070,"side":"Buy","size":20000,"price":66741.2,"timestamp":"2024-05-18T15:46:18.291Z"}]}
{"table":"orderBookL2_25","action":"delete","data":[{"symbol":"ETHUSDT","id":32402508052,"side":"Sell","price":3109.99,"timestamp":"2024-05-18T15:46:18.336Z"},{"symbol":"ETHUSDT","id":32402506801,"side":"Sell","price":3108.57,"timestamp":"2024-05-18T15:46:18.336Z"},{"symbol":"ETHUSDT","id":32402508050,"side":"Buy","price":3108.54,"timestamp":"2024-05-18T15:46:18.336Z"},{"symbol":"ETHUSDT","id":32402508086,"side":"Buy","price":3108.30,"timestamp":"2024-05-18T15:46:18.336Z"}]}
{"table":"orderBookL2_25","action":"update","data":[{"symbol":"ETHUSDT","id":32402494493,"side":"Sell","size":100000,"price":3111.26,"timestamp":"2024-05-18T15:46:18.336Z"},{"symbol":"ETHUSDT","id":32402507141,"side":"Buy","size":43000,"price":3108.52,"timestamp":"2024-05-18T15:46:18.336Z"}]}
{"table":"orderBookL2_25","action":"insert","data":[{"symbol":"ETHUSDT","id":32402508159,"side":"Sell","size":32000,"price":3109.99,"timestamp":"2024-05-18T15:46:18.336Z"},{"symbol":"ETHUSDT","id":32402508111,"side":"Sell","size":21000,"price":3108.56,"timestamp":"2024-05-18T15:46:18.336Z"},{"symbol":"ETHUSDT","id":32402508231,"side":"Buy","size":1000,"price":3108.30,"timestamp":"2024-05-18T15:46:18.336Z"},{"symbol":"ETHUSDT","id":32402508146,"side":"Buy","size":32000,"price":3108.54,"timestamp":"2024-05-18T15:46:18.336Z"}]}
{"table":"orderBookL2_25","action":"delete","data":[{"symbol":"XBTUSDT","id":32402507091,"side":"Sell","price":66780.6,"timestamp":"2024-05-18T15:46:18.340Z"},{"symbol":"XBTUSDT","id":32402508040,"side":"Sell","price":66780.7,"timestamp":"2024-05-18T15:46:18.340Z"},{"symbol":"XBTUSDT","id":32402508078,"side":"Sell","price":66773.5,"timestamp":"2024-05-18T15:46:18.340Z"},{"symbol":"XBTUSDT","id":32402507432,"side":"Buy","price":66741.3,"timestamp":"2024-05-18T15:46:18.340Z"},{"symbol":"XBTUSDT","id":32402508070,"side":"Buy","price":66741.2,"timestamp":"2024-05-18T15:46:18.340Z"}]}
{"table":"orderBookL2_25","action":"update","data":[{"symbol":"XBTUSDT","id":32402507179,"side":"Sell","size":94000,"price":66773.3,"timestamp":"2024-05-18T15:46:18.340Z"},{"symbol":"XBTUSDT","id":32402506378,"side":"Sell","size":213000,"price":66764.5,"timestamp":"2024-05-18T15:46:18.340Z"}]}
{"table":"orderBookL2_25","action":"insert","data":[{"symbol":"XBTUSDT","id":32402502728,"side":"Sell","size":156000,"price":66794.6,"timestamp":"2024-05-18T15:46:18.340Z"},{"symbol":"XBTUSDT","id":32402508235,"side":"Sell","size":1000,"price":66780.5,"timestamp":"2024-05-18T15:46:18.340Z"},{"symbol":"XBTUSDT","id":32402508263,"side":"Sell","size":1000,"price":66780.6,"timestamp":"2024-05-18T15:46:18.340Z"},{"symbol":"XBTUSDT","id":32402508105,"side":"Buy","size":20000,"price":66741.6,"timestamp":"2024-05-18T15:46:18.340Z"},{"symbol":"XBTUSDT","id":32402508120,"side":"Buy","size":20000,"price":66741.5,"timestamp":"2024-05-18T15:46:18.340Z"}]}
{"table":"orderBookL2_25","action":"delete","data":[{"symbol":"ETHUSDT","id":32402507306,"side":"Sell","price":3109.90,"timestamp":"2024-05-18T15:46:18.385Z"},{"symbol":"ETHUSDT","id":32402508111,"side":"Sell","price":3108.56,"timestamp":"2024-05-18T15:46:18.385Z"}]}
{"table":"orderBookL2_25","action":"insert","data":[{"symbol":"ETHUSDT","id":32402484839,"side":"Sell","size":100000,"price":3111.49,"timestamp":"2024-05-18T15:46:18.385Z"},{"symbol":"ETHUSDT","id":32402504474,"side":"Sell","size":518000,"price":3111.47,"timestamp":"2024-05-18T15:46:18.385Z"}]}
{"table":"orderBookL2_25","action":"delete","data":[{"symbol":"XBTUSDT","id":32402507762,"side":"Sell","price":66787.5,"timestamp":"2024-05-18T15:46:18.389Z"},{"symbol":"XBTUSDT","id":32402507440,"side":"Sell","price":66773.4,"timestamp":"2024-05-18T15:46:18.389Z"},{"symbol":"XBTUSDT","id":32402508263,"side":"Sell","price":66780.6,"timestamp":"2024-05-18T15:46:18.389Z"},{"symbol":"XBTUSDT","id":32402508235,"side":"Sell","price":66780.5,"timestamp":"2024-05-18T15:46:18.389Z"},{"symbol":"XBTUSDT","id":32402505977,"side":"Buy","price":66706.1,"timestamp":"2024-05-18T15:46:18.389Z"},{"symbol":"XBTUSDT","id":32402508120,"side":"Buy","price":66741.5,"timestamp":"2024-05-18T15:46:18.389Z"}]}
{"table":"orderBookL2_25","action":"insert","data":[{"symbol":"XBTUSDT","id":32402508318,"side":"Sell","size":1000,"price":66780.4,"timestamp":"2024-05-18T15:46:18.389Z"},{"symbol":"XBTUSDT","id":32402508328,"side":"Sell","size":2000,"price":66788.0,"timestamp":"2024-05-18T15:46:18.389Z"},{"symbol":"XBTUSDT","id":32402508403,"side":"Sell","size":1000,"price":66780.3,"timestamp":"2024-05-18T15:46:18.389Z"},{"symbol":"XBTUSDT","id":32402508401,"side":"Sell","size":20000,"price":66773.2,"timestamp":"2024-05-18T15:46:18.389Z"},{"symbol":"XBTUSDT","id":32402508316,"side":"Buy","size":16000,"price":66750.9,"timestamp":"2024-05-18T15:46:18.389Z"},{"symbol":"XBTUSDT","id":32402508418,"side":"Buy","size":20000,"price":66741.7,"timestamp":"2024-05-18T15:46:18.389Z"}]}
{"table":"orderBookL2_25","action":"delete","data":[{"symbol":"ETHUSDT","id":32402506945,"side":"Sell","price":3108.97,"timestamp":"2024-05-18T15:46:18.434Z"},{"symbol":"ETHUSDT","id":32402505650,"side":"Sell","price":3109.12,"timestamp":"2024-05-18T15:46:18.434Z"},{"symbol":"ETHUSDT","id":32402506555,"side":"Sell","price":3109.87,"timestamp":"2024-05-18T15:46:18.434Z"},{"symbol":"ETHUSDT","id":32402508159,"side":"Sell","price":3109.99,"timestamp":"2024-05-18T15:46:18.434Z"},{"symbol":"ETHUSDT","id":32402507745,"side":"Buy","price":3108.53,"timestamp":"2024-05-18T15:46:18.434Z"},{"symbol":"ETHUSDT","id":32402504893,"side":"Buy","price":3105.89,"timestamp":"2024-05-18T15:46:18.434Z"},{"symbol":"ETHUSDT","id":32402508231,"side":"Buy","price":3108.30,"timestamp":"2024-05-18T15:46:18.434Z"},{"symbol":"ETHUSDT","id":32402507765,"side":"Buy","price":3108.29,"timestamp":"2024-05-18T15:46:18.434Z"}]}
{"table":"orderBookL2_25","action":"update","data":[{"symbol":"ETHUSDT","id":32402484839,"side":"Sell","size":100000,"price":3111.49,"timestamp":"2024-05-18T15:46:18.434Z"},{"symbol":"ETHUSDT","id":32402504474,"side":"Sell","size":518000,"price":3111.47,"timestamp":"2024-05-18T15:46:18.434Z"},{"symbol":"ETHUSDT","id":32402507985,"side":"Buy","size":71000,"price":3108.25,"timestamp":"2024-05-18T15:46:18.434Z"}]}
{"table":"orderBookL2_25","action":"insert","data":[{"symbol":"ETHUSDT","id":32402508632,"side":"Sell","size":32000,"price":3110.01,"timestamp":"2024-05-18T15:46:18.434Z"},{"symbol":"ETHUSDT","id":32402486025,"side":"Sell","size":337000,"price":3111.72,"timestamp":"2024-05-18T15:46:18.434Z"},{"symbol":"ETHUSDT","id":32402508644,"side":"Sell","size":28000,"price":3109.48,"timestamp":"2024-05-18T15:46:18.434Z"},{"symbol":"ETHUSDT","id":32402487305,"side":"Sell","size":100000,"price":3111.65,"timestamp":"2024-05-18T15:46:18.434Z"},{"symbol":"ETHUSDT","id":32402508642,"side":"Buy","size":1000,"price":3108.32,"timestamp":"2024-05-18T15:46:18.434Z"},{"symbol":"ETHUSDT","id":32402508629,"side":"Buy","size":32000,"price":3108.55,"timestamp":"2024-05-18T15:46:18.434Z"},{"symbol":"ETHUSDT","id":32402508646,"side":"Buy","size":100000,"price":3108.22,"timestamp":"2024-05-18T15:46:18.434Z"},{"symbol":"ETHUSDT","id":32402508590,"side":"Buy","size":1000,"price":3108.31,"timestamp":"2024-05-18T15:46:18.434Z"}]}
{"table":"orderBookL2_25","action":"delete","data":[{"symbol":"XBTUSDT","id":32402508403,"side":"Sell","price":66780.3,"timestamp":"2024-05-18T15:46:18.438Z"},{"symbol":"XBTUSDT","id":32402508318,"side":"Sell","price":66780.4,"timestamp":"2024-05-18T15:46:18.438Z"},{"symbol":"XBTUSDT","id":32402508401,"side":"Sell","price":66773.2,"timestamp":"2024-05-18T15:46:18.438Z"},{"symbol":"XBTUSDT","id":32402502728,"side":"Sell","price":66794.6,"timestamp":"2024-05-18T15:46:18.438Z"},{"symbol":"XBTUSDT","id":32402501930,"side":"Sell","price":66792.7,"timestamp":"2024-05-18T15:46:18.438Z"},{"symbol":"XBTUSDT","id":32402508105,"side":"Buy","price":66741.6,"timestamp":"2024-05-18T15:46:18.438Z"},{"symbol":"XBTUSDT","id":32402508418,"side":"Buy","price":66741.7,"timestamp":"2024-05-18T15:46:18.438Z"}]}
{"table":"orderBookL2_25","action":"update","data":[{"symbol":"XBTUSDT","id":32402507179,"side":"Sell","size":74000,"price":66773.3,"timestamp":"2024-05-18T15:46:18.438Z"}]}
{"table":"orderBookL2_25","action":"insert","data":[{"symbol":"XBTUSDT","id":32402508582,"side":"Sell","size":1000,"price":66780.3,"timestamp":"2024-05-18T15:46:18.438Z"},{"symbol":"XBTUSDT","id":32402508640,"side":"Sell","size":1000,"price":66780.2,"timestamp":"2024-05-18T15:46:18.438Z"},{"symbol":"XBTUSDT","id":32402508603,"side":"Sell","size":20000,"price":66773.1,"timestamp":"2024-05-18T15:46:18.438Z"},{"symbol":"XBTUSDT","id":32402508661,"side":"Sell","size":20000,"price":66773.0,"timestamp":"2024-05-18T15:46:18.438Z"},{"symbol":"XBTUSDT","id":32402508538,"side":"Sell","size":3000,"price":66785.1,"timestamp":"2024-05-18T15:46:18.438Z"},{"symbol":"XBTUSDT","id":32402508648,"side":"Buy","size":20000,"price":66741.9,"timestamp":"2024-05-18T15:46:18.438Z"},{"symbol":"XBTUSDT","id":32402508612,"side":"Buy","size":20000,"price":66741.8,"timestamp":"2024-05-18T15:46:18.438Z"}]}
{"table":"orderBookL2_25","action":"delete","data":[{"symbol":"ETHUSDT","id":32402508632,"side":"Sell","price":3110.01,"timestamp":"2024-05-18T15:46:18.483Z"},{"symbol":"ETHUSDT","id":32402507823,"side":"Sell","price":3110.00,"timestamp":"2024-05-18T15:46:18.483Z"},{"symbol":"ETHUSDT","id":32402486025,"side":"Sell","price":3111.72,"timestamp":"2024-05-18T15:46:18.483Z"},{"symbol":"ETHUSDT","id":32402494475,"side":"Sell","price":3111.21,"timestamp":"2024-05-18T15:46:18.483Z"},{"symbol":"ETHUSDT","id":32402494486,"side":"Sell","price":3111.20,"timestamp":"2024-05-18T15:46:18.483Z"},{"symbol":"ETHUSDT","id":32402506566,"side":"Sell","price":3110.03,"timestamp":"2024-05-18T15:46:18.483Z"},{"symbol":"ETHUSDT","id":32402505928,"side":"Buy","price":3106.12,"timestamp":"2024-05-18T15:46:18.483Z"},{"symbol":"ETHUSDT","id":32402508590,"side":"Buy","price":3108.31,"timestamp":"2024-05-18T15:46:18.483Z"},{"symbol":"ETHUSDT","id":32402508629,"side":"Buy","price":3108.55,"timestamp":"2024-05-18T15:46:18.483Z"},{"symbol":"ETHUSDT","id":32402508642,"side":"Buy","price":3108.32,"timestamp":"2024-05-18T15:46:18.483Z"},{"symbol":"ETHUSDT","id":32402508146,"side":"Buy","price":3108.54,"timestamp":"2024-05-18T15:46:18.483Z"}]}
{"table":"orderBookL2_25","action":"update","data":[{"symbol":"ETHUSDT","id":32402508644,"side":"Sell","size":31000,"price":3109.48,"timestamp":"2024-05-18T15:46:18.483Z"}]}
{"table":"orderBookL2_25","action":"insert","data":[{"symbol":"ETHUSDT","id":32402508851,"side":"Sell","size":32000,"price":3110.05,"timestamp":"2024-05-18T15:46:18.483Z"},{"symbol":"ETHUSDT","id":32402508925,"side":"Sell","size":43000,"price":3109.92,"timestamp":"2024-05-18T15:46:18.483Z"},{"symbol":"ETHUSDT","id":32402508667,"side":"Sell","size":160000,"price":3110.55,"timestamp":"2024-05-18T15:46:18.483Z"},{"symbol":"ETHUSDT","id":32402508757,"side":"Sell","size":28000,"price":3109.84,"timestamp":"2024-05-18T15:46:18.483Z"},{"symbol":"ETHUSDT","id":32402508859,"side":"Sell","size":2000,"price":3109.50,"timestamp":"2024-05-18T15:46:18.483Z"},{"symbol":"ETHUSDT","id":32402508938,"side":"Sell","size":32000,"price":3110.04,"timestamp":"2024-05-18T15:46:18.483Z"},{"symbol":"ETHUSDT","id":32402508908,"side":"Buy","size":100000,"price":3108.41,"timestamp":"2024-05-18T15:46:18.483Z"},{"symbol":"ETHUSDT","id":32402508693,"side":"Buy","size":132000,"price":3108.56,"timestamp":"2024-05-18T15:46:18.483Z"},{"symbol":"ETHUSDT","id":32402508817,"side":"Buy","size":1000,"price":3108.34,"timestamp":"2024-05-18T15:46:18.483Z"},{"symbol":"ETHUSDT","id":32402508833,"side":"Buy","size":132000,"price":3108.57,"timestamp":"2024-05-18T15:46:18.483Z"},{"symbol":"ETHUSDT","id":32402508699,"side":"Buy","size":1000,"price":3108.33,"timestamp":"2024-05-18T15:46:18.483Z"}]}
{"table":"orderBookL2_25","action":"delete","data":[{"symbol":"XBTUSDT","id":32402508328,"side":"Sell","price":66788.0,"timestamp":"2024-05-18T15:46:18.487Z"},{"symbol":"XBTUSDT","id":32402508661,"side":"Sell","price":66773.0,"timestamp":"2024-05-18T15:46:18.487Z"},{"symbol":"XBTUSDT","id":32402508582,"side":"Sell","price":66780.3,"timestamp":"2024-05-18T15:46:18.487Z"},{"symbol":"XBTUSDT","id":32402508640,"side":"Sell","price":66780.2,"timestamp":"2024-05-18T15:46:18.487Z"},{"symbol":"XBTUSDT","id":32402507022,"side":"Sell","price":66766.1,"timestamp":"2024-05-18T15:46:18.487Z"},{"symbol":"XBTUSDT","id":32402508612,"side":"Buy","price":66741.8,"timestamp":"2024-05-18T15:46:18.487Z"},{"symbol":"XBTUSDT","id":32402504383,"side":"Buy","price":66706.5,"timestamp":"2024-05-18T15:46:18.487Z"},{"symbol":"XBTUSDT","id":32402508648,"side":"Buy","price":66741.9,"timestamp":"2024-05-18T15:46:18.487Z"},{"symbol":"XBTUSDT","id":32402227830,"side":"Buy","price":66709.5,"timestamp":"2024-05-18T15:46:18.487Z"}]}
{"table":"orderBookL2_25","action":"update","data":[{"symbol":"XBTUSDT","id":32402504528,"side":"Sell","size":57000,"price":66780.1,"timestamp":"2024-05-18T15:46:18.487Z"},{"symbol":"XBTUSDT","id":32402505821,"side":"Buy","size":128000,"price":66764.4,"timestamp":"2024-05-18T15:46:18.487Z"}]}
{"table":"orderBookL2_25","action":"insert","data":[{"symbol":"XBTUSDT","id":32402508935,"side":"Sell","size":1000,"price":66780.0,"timestamp":"2024-05-18T15:46:18.487Z"},{"symbol":"XBTUSDT","id":32402501930,"side":"Sell","size":2000,"price":66792.7,"timestamp":"2024-05-18T15:46:18.487Z"},{"symbol":"XBTUSDT","id":32402508958,"side":"Sell","size":20000,"price":66772.7,"timestamp":"2024-05-18T15:46:18.487Z"},{"symbol":"XBTUSDT","id":32402502728,"side":"Sell","size":156000,"price":66794.6,"timestamp":"2024-05-18T15:46:18.487Z"},{"symbol":"XBTUSDT","id":32402491799,"side":"Sell","size":11000,"price":66795.4,"timestamp":"2024-05-18T15:46:18.487Z"},{"symbol":"XBTUSDT","id":32402508989,"side":"Buy","size":20000,"price":66742.2,"timestamp":"2024-05-18T15:46:18.487Z"},{"symbol":"XBTUSDT","id":32402508960,"side":"Buy","size":20000,"price":66742.1,"timestamp":"2024-05-18T15:46:18.487Z"},{"symbol":"XBTUSDT","id":32402508876,"side":"Buy","size":20000,"price":66725.0,"timestamp":"2024-05-18T15:46:18.487Z"},{"symbol":"XBTUSDT","id":32402508983,"side":"Buy","size":22000,"price":66747.5,"timestamp":"2024-05-18T15:46:18.487Z"}]}
{"table":"orderBookL2_25","action":"delete","data":[{"symbol":"XBTETH","id":32402417546,"side":"Buy","price":21.269,"timestamp":"2024-05-18T15:46:18.494Z"}]}
{"table":"orderBookL2_25","action":"insert","data":[{"symbol":"XBTETH","id":32402509003,"side":"Buy","size":1,"price":21.265,"timestamp":"2024-05-18T15:46:18.494Z"}]}
{"table":"orderBookL2_25","action":"delete","data":[{"symbol":"ETHUSDT","id":32402508851,"side":"Sell","price":3110.05,"timestamp":"2024-05-18T15:46:18.532Z"},{"symbol":"ETHUSDT","id":32402508859,"side":"Sell","price":3109.50,"timestamp":"2024-05-18T15:46:18.532Z"},{"symbol":"ETHUSDT","id":32402504474,"side":"Sell","price":3111.47,"timestamp":"2024-05-18T15:46:18.532Z"},{"symbol":"ETHUSDT","id":32402508938,"side":"Sell","price":3110.04,"timestamp":"2024-05-18T15:46:18.532Z"},{"symbol":"ETHUSDT","id":32402501920,"side":"Sell","price":3110.36,"timestamp":"2024-05-18T15:46:18.532Z"},{"symbol":"ETHUSDT","id":32402488478,"side":"Sell","price":3111.05,"timestamp":"2024-05-18T15:46:18.532Z"},{"symbol":"ETHUSDT","id":32402508667,"side":"Sell","price":3110.55,"timestamp":"2024-05-18T15:46:18.532Z"},{"symbol":"ETHUSDT","id":32402508925,"side":"Sell","price":3109.92,"timestamp":"2024-05-18T15:46:18.532Z"},{"symbol":"ETHUSDT","id":32402503819,"side":"Sell","price":3110.20,"timestamp":"2024-05-18T15:46:18.532Z"},{"symbol":"ETHUSDT","id":32402487799,"side":"Sell","price":3111.06,"timestamp":"2024-05-18T15:46:18.532Z"},{"symbol":"ETHUSDT","id":32402508699,"side":"Buy","price":3108.33,"timestamp":"2024-05-18T15:46:18.532Z"},{"symbol":"ETHUSDT","id":32402494460,"side":"Buy","price":3106.20,"timestamp":"2024-05-18T15:46:18.532Z"},{"symbol":"ETHUSDT","id":32402505870,"side":"Buy","price":3106.28,"timestamp":"2024-05-18T15:46:18.532Z"},{"symbol":"ETHUSDT","id":32402505321,"side":"Buy","price":3107.32,"timestamp":"2024-05-18T15:46:18.532Z"},{"symbol":"ETHUSDT","id":32402508693,"side":"Buy","price":3108.56,"timestamp":"2024-05-18T15:46:18.532Z"},{"symbol":"ETHUSDT","id":32402508817,"side":"Buy","price":3108.34,"timestamp":"2024-05-18T15:46:18.532Z"}]}
{"table":"orderBookL2_25","action":"update","data":[{"symbol":"ETHUSDT","id":32402508833,"side":"Buy","size":100000,"price":3108.57,"timestamp":"2024-05-18T15:46:18.532Z"}]}
{"table":"orderBookL2_25","action":"insert","data":[{"symbol":"ETHUSDT","id":32402488716,"side":"Sell","size":100000,"price":3112.18,"timestamp":"2024-05-18T15:46:18.532Z"},{"symbol":"ETHUSDT","id":32402509030,"side":"Sell","size":534000,"price":3111.80,"timestamp":"2024-05-18T15:46:18.532Z"},{"symbol":"ETHUSDT","id":32402447682,"side":"Sell","size":100000,"price":3112.68,"timestamp":"2024-05-18T15:46:18.532Z"},{"symbol":"ETHUSDT","id":32402455680,"side":"Sell","size":100000,"price":3112.02,"timestamp":"2024-05-18T15:46:18.532Z"},{"symbol":"ETHUSDT","id":32402486025,"side":"Sell","size":337000,"price":3111.72,"timestamp":"2024-05-18T15:46:18.532Z"},{"symbol":"ETHUSDT","id":32402470274,"side":"Sell","size":100000,"price":3112.84,"timestamp":"2024-05-18T15:46:18.532Z"},{"symbol":"ETHUSDT","id":32402493850,"side":"Sell","size":100000,"price":3111.81,"timestamp":"2024-05-18T15:46:18.532Z"},{"symbol":"ETHUSDT","id":32402509324,"side":"Sell","size":32000,"price":3110.12,"timestamp":"2024-05-18T15:46:18.532Z"},{"symbol":"ETHUSDT","id":32402505932,"side":"Sell","size":1000,"price":3112.60,"timestamp":"2024-05-18T15:46:18.532Z"},{"symbol":"ETHUSDT","id":32402509320,"side":"Sell","size":32000,"price":3110.11,"timestamp":"2024-05-18T15:46:18.532Z"},{"symbol":"ETHUSDT","id":32402509091,"side":"Buy","size":517000,"price":3107.92,"timestamp":"2024-05-18T15:46:18.532Z"},{"symbol":"ETHUSDT","id":32402509252,"side":"Buy","size":100000,"price":3108.67,"timestamp":"2024-05-18T15:46:18.532Z"},{"symbol":"ETHUSDT","id":32402509337,"side":"Buy","size":1000,"price":3108.47,"timestamp":"2024-05-18T15:46:18.532Z"},{"symbol":"ETHUSDT","id":32402509271,"side":"Buy","size":32000,"price":3108.59,"timestamp":"2024-05-18T15:46:18.532Z"},{"symbol":"ETHUSDT","id":32402509175,"side":"Buy","size":1000,"price":3108.35,"timestamp":"2024-05-18T15:46:18.532Z"},{"symbol":"ETHUSDT","id":32402509151,"side":"Buy","size":52000,"price":3108.58,"timestamp":"2024-05-18T15:46:18.532Z"}]}
{"table":"orderBookL2_25","action":"delete","data":[{"symbol":"XBTUSDT","id":32402507892,"side":"Sell","price":66771.9,"timestamp":"2024-05-18T15:46:18.536Z"},{"symbol":"XBTUSDT","id":32402502728,"side":"Sell","price":66794.6,"timestamp":"2024-05-18T15:46:18.536Z"},{"symbol":"XBTUSDT","id":32402508603,"side":"Sell","price":66773.1,"timestamp":"2024-05-18T15:46:18.536Z"},{"symbol":"XBTUSDT","id":32402505599,"side":"Sell","price":66791.6,"timestamp":"2024-05-18T15:46:18.536Z"},{"symbol":"XBTUSDT","id":32402508935,"side":"Sell","price":66780.0,"timestamp":"2024-05-18T15:46:18.536Z"},{"symbol":"XBTUSDT","id":32402508958,"side":"Sell","price":66772.7,"timestamp":"2024-05-18T15:46:18.536Z"},{"symbol":"XBTUSDT","id":32402507179,"side":"Sell","price":66773.3,"timestamp":"2024-05-18T15:46:18.536Z"},{"symbol":"XBTUSDT","id":32402508989,"side":"Buy","price":66742.2,"timestamp":"2024-05-18T15:46:18.536Z"},{"symbol":"XBTUSDT","id":32402508960,"side":"Buy","price":66742.1,"timestamp":"2024-05-18T15:46:18.536Z"},{"symbol":"XBTUSDT","id":32402508042,"side":"Buy","price":66733.9,"timestamp":"2024-05-18T15:46:18.536Z"},{"symbol":"XBTUSDT","id":32402508876,"side":"Buy","price":66725.0,"timestamp":"2024-05-18T15:46:18.536Z"},{"symbol":"XBTUSDT","id":32402505594,"side":"Buy","price":66712.2,"timestamp":"2024-05-18T15:46:18.536Z"}]}
{"table":"orderBookL2_25","action":"update","data":[{"symbol":"XBTUSDT","id":32402491799,"side":"Sell","size":11000,"price":66795.4,"timestamp":"2024-05-18T15:46:18.536Z"},{"symbol":"XBTUSDT","id":32402506378,"side":"Sell","size":13000,"price":66764.5,"timestamp":"2024-05-18T15:46:18.536Z"},{"symbol":"XBTUSDT","id":32402504528,"side":"Sell","size":56000,"price":66780.1,"timestamp":"2024-05-18T15:46:18.536Z"}]}
{"table":"orderBookL2_25","action":"insert","data":[{"symbol":"XBTUSDT","id":32402491670,"side":"Sell","size":100000,"price":66795.5,"timestamp":"2024-05-18T15:46:18.536Z"},{"symbol":"XBTUSDT","id":32402509107,"side":"Sell","size":370000,"price":66778.4,"timestamp":"2024-05-18T15:46:18.536Z"},{"symbol":"XBTUSDT","id":32402509330,"side":"Sell","size":20000,"price":66773.3,"timestamp":"2024-05-18T15:46:18.536Z"},{"symbol":"XBTUSDT","id":32402509299,"side":"Sell","size":20000,"price":66772.9,"timestamp":"2024-05-18T15:46:18.536Z"},{"symbol":"XBTUSDT","id":32402504870,"side":"Sell","size":538000,"price":66795.7,"timestamp":"2024-05-18T15:46:18.536Z"},{"symbol":"XBTUSDT","id":32402509367,"side":"Sell","size":1000,"price":66781.1,"timestamp":"2024-05-18T15:46:18.536Z"},{"symbol":"XBTUSDT","id":32402509275,"side":"Sell","size":1000,"price":66781.2,"timestamp":"2024-05-18T15:46:18.536Z"},{"symbol":"XBTUSDT","id":32402509307,"side":"Buy","size":100000,"price":66761.0,"timestamp":"2024-05-18T15:46:18.536Z"},{"symbol":"XBTUSDT","id":32402509243,"side":"Buy","size":20000,"price":66743.2,"timestamp":"2024-05-18T15:46:18.536Z"},{"symbol":"XBTUSDT","id":32402509178,"side":"Buy","size":347000,"price":66741.7,"timestamp":"2024-05-18T15:46:18.536Z"},{"symbol":"XBTUSDT","id":32402509182,"side":"Buy","size":36000,"price":66753.8,"timestamp":"2024-05-18T15:46:18.536Z"},{"symbol":"XBTUSDT","id":32402509288,"side":"Buy","size":20000,"price":66743.3,"timestamp":"2024-05-18T15:46:18.536Z"}]}
{"table":"orderBookL2_25","action":"delete","data":[{"symbol":"XBTETH","id":32402417551,"side":"Sell","price":21.743,"timestamp":"2024-05-18T15:46:18.544Z"},{"symbol":"XBTETH","id":32402425343,"side":"Sell","price":21.872,"timestamp":"2024-05-18T15:46:18.544Z"},{"symbol":"XBTETH","id":32402425352,"side":"Buy","price":21.141,"timestamp":"2024-05-18T15:46:18.544Z"}]}
{"table":"orderBookL2_25","action":"insert","data":[{"symbol":"XBTETH","id":32402509391,"side":"Sell","size":6,"price":21.868,"timestamp":"2024-05-18T15:46:18.544Z"},{"symbol":"XBTETH","id":32402509011,"side":"Sell","size":1,"price":21.738,"timestamp":"2024-05-18T15:46:18.544Z"},{"symbol":"XBTETH","id":32402509115,"side":"Buy","size":6,"price":21.136,"timestamp":"2024-05-18T15:46:18.544Z"}]}
{"table":"orderBookL2_25","action":"delete","data":[{"symbol":"ETHUSDT","id":32402509030,"side":"Sell","price":3111.80,"timestamp":"2024-05-18T15:46:18.581Z"},{"symbol":"ETHUSDT","id":32402496877,"side":"Sell","price":3110.84,"timestamp":"2024-05-18T15:46:18.581Z"},{"symbol":"ETHUSDT","id":32402509324,"side":"Sell","price":3110.12,"timestamp":"2024-05-18T15:46:18.581Z"},{"symbol":"ETHUSDT","id":32402509320,"side":"Sell","price":3110.11,"timestamp":"2024-05-18T15:46:18.581Z"},{"symbol":"ETHUSDT","id":32402509271,"side":"Buy","price":3108.59,"timestamp":"2024-05-18T15:46:18.581Z"},{"symbol":"ETHUSDT","id":32402509175,"side":"Buy","price":3108.35,"timestamp":"2024-05-18T15:46:18.581Z"}]}
{"table":"orderBookL2_25","action":"update","data":[{"symbol":"ETHUSDT","id":32402470274,"side":"Sell","size":100000,"price":3112.84,"timestamp":"2024-05-18T15:46:18.581Z"},{"symbol":"ETHUSDT","id":32402508833,"side":"Buy","size":132000,"price":3108.57,"timestamp":"2024-05-18T15:46:18.581Z"}]}
{"table":"orderBookL2_25","action":"insert","data":[{"symbol":"ETHUSDT","id":32402509514,"side":"Sell","size":32000,"price":3110.44,"timestamp":"2024-05-18T15:46:18.581Z"},{"symbol":"ETHUSDT","id":32402509512,"side":"Sell","size":32000,"price":3110.45,"timestamp":"2024-05-18T15:46:18.581Z"},{"symbol":"ETHUSDT","id":32402509402,"side":"Sell","size":562000,"price":3112.01,"timestamp":"2024-05-18T15:46:18.581Z"},{"symbol":"ETHUSDT","id":32402476065,"side":"Sell","size":120000,"price":3112.99,"timestamp":"2024-05-18T15:46:18.581Z"},{"symbol":"ETHUSDT","id":32402505870,"side":"Buy","size":100000,"price":3106.28,"timestamp":"2024-05-18T15:46:18.581Z"},{"symbol":"ETHUSDT","id":32402509558,"side":"Buy","size":1000,"price":3108.60,"timestamp":"2024-05-18T15:46:18.581Z"}]}
{"table":"orderBookL2_25","action":"delete","data":[{"symbol":"XBTUSDT","id":32402509299,"side":"Sell","price":66772.9,"timestamp":"2024-05-18T15:46:18.585Z"},{"symbol":"XBTUSDT","id":32402504870,"side":"Sell","price":66795.7,"timestamp":"2024-05-18T15:46:18.585Z"},{"symbol":"XBTUSDT","id":32402491670,"side":"Sell","price":66795.5,"timestamp":"2024-05-18T15:46:18.585Z"},{"symbol":"XBTUSDT","id":32402509330,"side":"Sell","price":66773.3,"timestamp":"2024-05-18T15:46:18.585Z"},{"symbol":"XBTUSDT","id":32402509367,"side":"Sell","price":66781.1,"timestamp":"2024-05-18T15:46:18.585Z"},{"symbol":"XBTUSDT","id":32402509275,"side":"Sell","price":66781.2,"timestamp":"2024-05-18T15:46:18.585Z"},{"symbol":"XBTUSDT","id":32402509243,"side":"Buy","price":66743.2,"timestamp":"2024-05-18T15:46:18.585Z"},{"symbol":"XBTUSDT","id":32402507731,"side":"Buy","price":66747.9,"timestamp":"2024-05-18T15:46:18.585Z"},{"symbol":"XBTUSDT","id":32402509288,"side":"Buy","price":66743.3,"timestamp":"2024-05-18T15:46:18.585Z"}]}
{"table":"orderBookL2_25","action":"update","data":[{"symbol":"XBTUSDT","id":32402504314,"side":"Sell","size":40000,"price":66781.7,"timestamp":"2024-05-18T15:46:18.585Z"},{"symbol":"XBTUSDT","id":32402506980,"side":"Sell","size":22000,"price":66781.8,"timestamp":"2024-05-18T15:46:18.585Z"}]}
{"table":"orderBookL2_25","action":"insert","data":[{"symbol":"XBTUSDT","id":32402509567,"side":"Sell","size":1000,"price":66782.0,"timestamp":"2024-05-18T15:46:18.585Z"},{"symbol":"XBTUSDT","id":32402509417,"side":"Sell","size":3000,"price":66776.2,"timestamp":"2024-05-18T15:46:18.585Z"},{"symbol":"XBTUSDT","id":32402509562,"side":"Sell","size":20000,"price":66767.2,"timestamp":"2024-05-18T15:46:18.585Z"},{"symbol":"XBTUSDT","id":32402509574,"side":"Sell","size":1000,"price":66781.9,"timestamp":"2024-05-18T15:46:18.585Z"},{"symbol":"XBTUSDT","id":32402509547,"side":"Sell","size":20000,"price":66774.4,"timestamp":"2024-05-18T15:46:18.585Z"},{"symbol":"XBTUSDT","id":32402509545,"side":"Sell","size":20000,"price":66774.5,"timestamp":"2024-05-18T15:46:18.585Z"},{"symbol":"XBTUSDT","id":32402509565,"side":"Buy","size":20000,"price":66747.2,"timestamp":"2024-05-18T15:46:18.585Z"},{"symbol":"XBTUSDT","id":32402509581,"side":"Buy","size":20000,"price":66747.3,"timestamp":"2024-05-18T15:46:18.585Z"},{"symbol":"XBTUSDT","id":32402505594,"side":"Buy","size":538000,"price":66712.2,"timestamp":"2024-05-18T15:46:18.585Z"}]}
{"table":"orderBookL2_25","action":"delete","data":[{"symbol":"ETHUSDT","id":32402476065,"side":"Sell","price":3112.99,"timestamp":"2024-05-18T15:46:18.630Z"},{"symbol":"ETHUSDT","id":32402470274,"side":"Sell","price":3112.84,"timestamp":"2024-05-18T15:46:18.630Z"},{"symbol":"ETHUSDT","id":32402509337,"side":"Buy","price":3108.47,"timestamp":"2024-05-18T15:46:18.630Z"}]}
{"table":"orderBookL2_25","action":"insert","data":[{"symbol":"ETHUSDT","id":32402509607,"side":"Sell","size":43000,"price":3110.02,"timestamp":"2024-05-18T15:46:18.630Z"},{"symbol":"ETHUSDT","id":32402509644,"side":"Sell","size":160000,"price":3110.85,"timestamp":"2024-05-18T15:46:18.630Z"},{"symbol":"ETHUSDT","id":32402509625,"side":"Buy","size":1000,"price":3108.61,"timestamp":"2024-05-18T15:46:18.630Z"}]}
{"table":"orderBookL2_25","action":"delete","data":[{"symbol":"XBTUSDT","id":32402509567,"side":"Sell","price":66782.0,"timestamp":"2024-05-18T15:46:18.634Z"},{"symbol":"XBTUSDT","id":32402509574,"side":"Sell","price":66781.9,"timestamp":"2024-05-18T15:46:18.634Z"},{"symbol":"XBTUSDT","id":32402509547,"side":"Sell","price":66774.4,"timestamp":"2024-05-18T15:46:18.634Z"},{"symbol":"XBTUSDT","id":32402509545,"side":"Sell","price":66774.5,"timestamp":"2024-05-18T15:46:18.634Z"},{"symbol":"XBTUSDT","id":32402509307,"side":"Buy","price":66761.0,"timestamp":"2024-05-18T15:46:18.634Z"},{"symbol":"XBTUSDT","id":32402509565,"side":"Buy","price":66747.2,"timestamp":"2024-05-18T15:46:18.634Z"}]}
{"table":"orderBookL2_25","action":"update","data":[{"symbol":"XBTUSDT","id":32402506378,"side":"Sell","size":213000,"price":66764.5,"timestamp":"2024-05-18T15:46:18.634Z"},{"symbol":"XBTUSDT","id":32402504314,"side":"Sell","size":41000,"price":66781.7,"timestamp":"2024-05-18T15:46:18.634Z"},{"symbol":"XBTUSDT","id":32402506980,"side":"Sell","size":23000,"price":66781.8,"timestamp":"2024-05-18T15:46:18.634Z"},{"symbol":"XBTUSDT","id":32402505821,"side":"Buy","size":28000,"price":66764.4,"timestamp":"2024-05-18T15:46:18.634Z"},{"symbol":"XBTUSDT","id":32402507156,"side":"Buy","size":120000,"price":66747.4,"timestamp":"2024-05-18T15:46:18.634Z"}]}
{"table":"orderBookL2_25","action":"insert","data":[{"symbol":"XBTUSDT","id":32402509666,"side":"Sell","size":20000,"price":66774.5,"timestamp":"2024-05-18T15:46:18.634Z"},{"symbol":"XBTUSDT","id":32402509711,"side":"Sell","size":20000,"price":66774.4,"timestamp":"2024-05-18T15:46:18.634Z"},{"symbol":"XBTUSDT","id":32402504870,"side":"Sell","size":538000,"price":66795.7,"timestamp":"2024-05-18T15:46:18.634Z"},{"symbol":"XBTUSDT","id":32402491670,"side":"Sell","size":100000,"price":66795.5,"timestamp":"2024-05-18T15:46:18.634Z"},{"symbol":"XBTUSDT","id":32402509630,"side":"Buy","size":100000,"price":66757.6,"timestamp":"2024-05-18T15:46:18.634Z"},{"symbol":"XBTUSDT","id":32402509167,"side":"Buy","size":651000,"price":66709.6,"timestamp":"2024-05-18T15:46:18.634Z"}]}
{"table":"orderBookL2_25","action":"delete","data":[{"symbol":"ETHUSDT","id":32402509607,"side":"Sell","price":3110.02,"timestamp":"2024-05-18T15:46:18.679Z"},{"symbol":"ETHUSDT","id":32402509514,"side":"Sell","price":3110.44,"timestamp":"2024-05-18T15:46:18.679Z"},{"symbol":"ETHUSDT","id":32402509512,"side":"Sell","price":3110.45,"timestamp":"2024-05-18T15:46:18.679Z"},{"symbol":"ETHUSDT","id":32402504834,"side":"Buy","price":3106.40,"timestamp":"2024-05-18T15:46:18.679Z"},{"symbol":"ETHUSDT","id":32402505870,"side":"Buy","price":3106.28,"timestamp":"2024-05-18T15:46:18.679Z"},{"symbol":"ETHUSDT","id":32402509625,"side":"Buy","price":3108.61,"timestamp":"2024-05-18T15:46:18.679Z"}]}
{"table":"orderBookL2_25","action":"update","data":[{"symbol":"ETHUSDT","id":32402508644,"side":"Sell","size":28000,"price":3109.48,"timestamp":"2024-05-18T15:46:18.679Z"},{"symbol":"ETHUSDT","id":32402447682,"side":"Sell","size":100000,"price":3112.68,"timestamp":"2024-05-18T15:46:18.679Z"},{"symbol":"ETHUSDT","id":32402508833,"side":"Buy","size":100000,"price":3108.57,"timestamp":"2024-05-18T15:46:18.679Z"},{"symbol":"ETHUSDT","id":32402509151,"side":"Buy","size":20000,"price":3108.58,"timestamp":"2024-05-18T15:46:18.679Z"}]}
{"table":"orderBookL2_25","action":"insert","data":[{"symbol":"ETHUSDT","id":32402509701,"side":"Sell","size":100000,"price":3110.28,"timestamp":"2024-05-18T15:46:18.679Z"},{"symbol":"ETHUSDT","id":32402509778,"side":"Sell","size":32000,"price":3110.49,"timestamp":"2024-05-18T15:46:18.679Z"},{"symbol":"ETHUSDT","id":32402509741,"side":"Sell","size":32000,"price":3110.48,"timestamp":"2024-05-18T15:46:18.679Z"},{"symbol":"ETHUSDT","id":32402509837,"side":"Buy","size":1000,"price":3108.59,"timestamp":"2024-05-18T15:46:18.679Z"},{"symbol":"ETHUSDT","id":32402509822,"side":"Buy","size":32000,"price":3108.84,"timestamp":"2024-05-18T15:46:18.679Z"},{"symbol":"ETHUSDT","id":32402509805,"side":"Buy","size":32000,"price":3108.85,"timestamp":"2024-05-18T15:46:18.679Z"}]}
{"table":"orderBookL2_25","action":"delete","data":[{"symbol":"XBTUSDT","id":32402491670,"side":"Sell","price":66795.5,"timestamp":"2024-05-18T15:46:18.683Z"},{"symbol":"XBTUSDT","id":32402509666,"side":"Sell","price":66774.5,"timestamp":"2024-05-18T15:46:18.683Z"},{"symbol":"XBTUSDT","id":32402509711,"side":"Sell","price":66774.4,"timestamp":"2024-05-18T15:46:18.683Z"},{"symbol":"XBTUSDT","id":32402491799,"side":"Sell","price":66795.4,"timestamp":"2024-05-18T15:46:18.683Z"},{"symbol":"XBTUSDT","id":32402504870,"side":"Sell","price":66795.7,"timestamp":"2024-05-18T15:46:18.683Z"},{"symbol":"XBTUSDT","id":32402509581,"side":"Buy","price":66747.3,"timestamp":"2024-05-18T15:46:18.683Z"},{"symbol":"XBTUSDT","id":32402509167,"side":"Buy","price":66709.6,"timestamp":"2024-05-18T15:46:18.683Z"}]}
{"table":"orderBookL2_25","action":"update","data":[{"symbol":"XBTUSDT","id":32402506980,"side":"Sell","size":22000,"price":66781.8,"timestamp":"2024-05-18T15:46:18.683Z"},{"symbol":"XBTUSDT","id":32402504314,"side":"Sell","size":40000,"price":66781.7,"timestamp":"2024-05-18T15:46:18.683Z"},{"symbol":"XBTUSDT","id":32402505951,"side":"Buy","size":22000,"price":66736.2,"timestamp":"2024-05-18T15:46:18.683Z"},{"symbol":"XBTUSDT","id":32402506821,"side":"Buy","size":28000,"price":66747.1,"timestamp":"2024-05-18T15:46:18.683Z"},{"symbol":"XBTUSDT","id":32402505821,"side":"Buy","size":36000,"price":66764.4,"timestamp":"2024-05-18T15:46:18.683Z"},{"symbol":"XBTUSDT","id":32402505594,"side":"Buy","size":538000,"price":66712.2,"timestamp":"2024-05-18T15:46:18.683Z"},{"symbol":"XBTUSDT","id":32402508983,"side":"Buy","size":22000,"price":66747.5,"timestamp":"2024-05-18T15:46:18.683Z"},{"symbol":"XBTUSDT","id":32402507156,"side":"Buy","size":100000,"price":66747.4,"timestamp":"2024-05-18T15:46:18.683Z"}]}
{"table":"orderBookL2_25","action":"insert","data":[{"symbol":"XBTUSDT","id":32402509820,"side":"Sell","size":1000,"price":66782.1,"timestamp":"2024-05-18T15:46:18.683Z"},{"symbol":"XBTUSDT","id":32402509812,"side":"Sell","size":74000,"price":66777.0,"timestamp":"2024-05-18T15:46:18.683Z"},{"symbol":"XBTUSDT","id":32402509867,"side":"Sell","size":20000,"price":66774.8,"timestamp":"2024-05-18T15:46:18.683Z"},{"symbol":"XBTUSDT","id":32402509771,"side":"Sell","size":20000,"price":66774.7,"timestamp":"2024-05-18T15:46:18.683Z"},{"symbol":"XBTUSDT","id":32402509801,"side":"Sell","size":1000,"price":66782.0,"timestamp":"2024-05-18T15:46:18.683Z"},{"symbol":"XBTUSDT","id":32402509734,"side":"Buy","size":20000,"price":66747.2,"timestamp":"2024-05-18T15:46:18.683Z"},{"symbol":"XBTUSDT","id":32402509728,"side":"Buy","size":8000,"price":66761.1,"timestamp":"2024-05-18T15:46:18.683Z"}]}
{"table":"orderBookL2_25","action":"delete","data":[{"symbol":"ETHUSDT","id":32402509741,"side":"Sell","price":3110.48,"timestamp":"2024-05-18T15:46:18.728Z"},{"symbol":"ETHUSDT","id":32402509778,"side":"Sell","price":3110.49,"timestamp":"2024-05-18T15:46:18.728Z"},{"symbol":"ETHUSDT","id":32402509805,"side":"Buy","price":3108.85,"timestamp":"2024-05-18T15:46:18.728Z"},{"symbol":"ETHUSDT","id":32402507141,"side":"Buy","price":3108.52,"timestamp":"2024-05-18T15:46:18.728Z"}]}
{"table":"orderBookL2_25","action":"insert","data":[{"symbol":"ETHUSDT","id":32402509927,"side":"Sell","size":32000,"price":3110.48,"timestamp":"2024-05-18T15:46:18.728Z"},{"symbol":"ETHUSDT","id":32402509887,"side":"Sell","size":32000,"price":3110.47,"timestamp":"2024-05-18T15:46:18.728Z"},{"symbol":"ETHUSDT","id":32402509922,"side":"Buy","size":32000,"price":3108.83,"timestamp":"2024-05-18T15:46:18.728Z"},{"symbol":"ETHUSDT","id":32402509889,"side":"Buy","size":43000,"price":3108.86,"timestamp":"2024-05-18T15:46:18.728Z"}]}
{"table":"orderBookL2_25","action":"delete","data":[{"symbol":"XBTUSDT","id":32402509801,"side":"Sell","price":66782.0,"timestamp":"2024-05-18T15:46:18.732Z"},{"symbol":"XBTUSDT","id":32402509178,"side":"Buy","price":66741.7,"timestamp":"2024-05-18T15:46:18.732Z"}]}
{"table":"orderBookL2_25","action":"insert","data":[{"symbol":"XBTUSDT","id":32402509913,"side":"Sell","size":1000,"price":66782.2,"timestamp":"2024-05-18T15:46:18.732Z"},{"symbol":"XBTUSDT","id":32402509976,"side":"Buy","size":352000,"price":66740.7,"timestamp":"2024-05-18T15:46:18.732Z"}]}
{"table":"orderBookL2_25","action":"delete","data":[{"symbol":"ETHUSDT","id":32402447682,"side":"Sell","price":3112.68,"timestamp":"2024-05-18T15:46:18.777Z"}]}
{"table":"orderBookL2_25","action":"insert","data":[{"symbol":"ETHUSDT","id":32402509978,"side":"Sell","size":43000,"price":3110.20,"timestamp":"2024-05-18T15:46:18.777Z"}]}
{"table":"orderBookL2_25","action":"delete","data":[{"symbol":"XBTUSDT","id":32402509107,"side":"Sell","price":66778.4,"timestamp":"2024-05-18T15:46:18.781Z"},{"symbol":"XBTUSDT","id":32402509976,"side":"Buy","price":66740.7,"timestamp":"2024-05-18T15:46:18.781Z"},{"symbol":"XBTUSDT","id":32402505594,"side":"Buy","price":66712.2,"timestamp":"2024-05-18T15:46:18.781Z"}]}
{"table":"orderBookL2_25","action":"insert","data":[{"symbol":"XBTUSDT","id":32402509998,"side":"Sell","size":360000,"price":66776.1,"timestamp":"2024-05-18T15:46:18.781Z"},{"symbol":"XBTUSDT","id":32402509996,"side":"Buy","size":388000,"price":66736.4,"timestamp":"2024-05-18T15:46:18.781Z"},{"symbol":"XBTUSDT","id":32402510029,"side":"Buy","size":74000,"price":66730.1,"timestamp":"2024-05-18T15:46:18.781Z"}]}
{"table":"orderBookL2_25","action":"delete","data":[{"symbol":"ETHUSDT","id":32402508644,"side":"Sell","price":3109.48,"timestamp":"2024-05-18T15:46:18.826Z"}]}
{"table":"orderBookL2_25","action":"update","data":[{"symbol":"ETHUSDT","id":32402505932,"side":"Sell","size":1000,"price":3112.60,"timestamp":"2024-05-18T15:46:18.826Z"}]}
{"table":"orderBookL2_25","action":"insert","data":[{"symbol":"ETHUSDT","id":32402510111,"side":"Sell","size":2000,"price":3109.32,"timestamp":"2024-05-18T15:46:18.826Z"}]}
{"table":"orderBookL2_25","action":"delete","data":[{"symbol":"XBTUSDT","id":32402509913,"side":"Sell","price":66782.2,"timestamp":"2024-05-18T15:46:18.830Z"}]}
{"table":"orderBookL2_25","action":"insert","data":[{"symbol":"XBTUSDT","id":32402510126,"side":"Sell","size":1000,"price":66782.2,"timestamp":"2024-05-18T15:46:18.830Z"}]}
{"table":"orderBookL2_25","action":"delete","data":[{"symbol":"ETHUSDT","id":32402509927,"side":"Sell","price":3110.48,"timestamp":"2024-05-18T15:46:18.875Z"},{"symbol":"ETHUSDT","id":32402510111,"side":"Sell","price":3109.32,"timestamp":"2024-05-18T15:46:18.875Z"},{"symbol":"ETHUSDT","id":32402508757,"side":"Sell","price":3109.84,"timestamp":"2024-05-18T15:46:18.875Z"},{"symbol":"ETHUSDT","id":32402508908,"side":"Buy","price":3108.41,"timestamp":"2024-05-18T15:46:18.875Z"}]}
{"table":"orderBookL2_25","action":"update","data":[{"symbol":"ETHUSDT","id":32402505932,"side":"Sell","size":1000,"price":3112.60,"timestamp":"2024-05-18T15:46:18.875Z"}]}
{"table":"orderBookL2_25","action":"insert","data":[{"symbol":"ETHUSDT","id":32402447682,"side":"Sell","size":100000,"price":3112.68,"timestamp":"2024-05-18T15:46:18.875Z"},{"symbol":"ETHUSDT","id":32402510230,"side":"Sell","size":100000,"price":3109.51,"timestamp":"2024-05-18T15:46:18.875Z"},{"symbol":"ETHUSDT","id":32402510249,"side":"Sell","size":32000,"price":3110.45,"timestamp":"2024-05-18T15:46:18.875Z"},{"symbol":"ETHUSDT","id":32402504834,"side":"Buy","size":1620000,"price":3106.40,"timestamp":"2024-05-18T15:46:18.875Z"}]}
{"table":"orderBookL2_25","action":"delete","data":[{"symbol":"XBTUSDT","id":32402501736,"side":"Sell","price":66786.6,"timestamp":"2024-05-18T15:46:18.879Z"},{"symbol":"XBTUSDT","id":32402509771,"side":"Sell","price":66774.7,"timestamp":"2024-05-18T15:46:18.879Z"},{"symbol":"XBTUSDT","id":32402504314,"side":"Sell","price":66781.7,"timestamp":"2024-05-18T15:46:18.879Z"},{"symbol":"XBTUSDT","id":32402509734,"side":"Buy","price":66747.2,"timestamp":"2024-05-18T15:46:18.879Z"},{"symbol":"XBTUSDT","id":32402402304,"side":"Buy","price":66716.3,"timestamp":"2024-05-18T15:46:18.879Z"},{"symbol":"XBTUSDT","id":32402509630,"side":"Buy","price":66757.6,"timestamp":"2024-05-18T15:46:18.879Z"}]}
{"table":"orderBookL2_25","action":"update","data":[{"symbol":"XBTUSDT","id":32402501930,"side":"Sell","size":2000,"price":66792.7,"timestamp":"2024-05-18T15:46:18.879Z"},{"symbol":"XBTUSDT","id":32402506378,"side":"Sell","size":253000,"price":66764.5,"timestamp":"2024-05-18T15:46:18.879Z"},{"symbol":"XBTUSDT","id":32402504528,"side":"Sell","size":16000,"price":66780.1,"timestamp":"2024-05-18T15:46:18.879Z"}]}
{"table":"orderBookL2_25","action":"insert","data":[{"symbol":"XBTUSDT","id":32402491670,"side":"Sell","size":100000,"price":66795.5,"timestamp":"2024-05-18T15:46:18.879Z"},{"symbol":"XBTUSDT","id":32402510211,"side":"Sell","size":20000,"price":66774.9,"timestamp":"2024-05-18T15:46:18.879Z"},{"symbol":"XBTUSDT","id":32402510159,"side":"Sell","size":10000,"price":66776.9,"timestamp":"2024-05-18T15:46:18.879Z"},{"symbol":"XBTUSDT","id":32402510203,"side":"Buy","size":100000,"price":66754.2,"timestamp":"2024-05-18T15:46:18.879Z"},{"symbol":"XBTUSDT","id":32402510162,"side":"Buy","size":10000,"price":66757.5,"timestamp":"2024-05-18T15:46:18.879Z"},{"symbol":"XBTUSDT","id":32402510207,"side":"Buy","size":20000,"price":66747.0,"timestamp":"2024-05-18T15:46:18.879Z"}]}
{"table":"orderBookL2_25","action":"delete","data":[{"symbol":"ETHUSDT","id":32402447682,"side":"Sell","price":3112.68,"timestamp":"2024-05-18T15:46:18.924Z"},{"symbol":"ETHUSDT","id":32402509887,"side":"Sell","price":3110.47,"timestamp":"2024-05-18T15:46:18.924Z"},{"symbol":"ETHUSDT","id":32402509558,"side":"Buy","price":3108.60,"timestamp":"2024-05-18T15:46:18.924Z"}]}
{"table":"orderBookL2_25","action":"update","data":[{"symbol":"ETHUSDT","id":32402509151,"side":"Buy","size":20000,"price":3108.58,"timestamp":"2024-05-18T15:46:18.924Z"}]}
{"table":"orderBookL2_25","action":"insert","data":[{"symbol":"ETHUSDT","id":32402510254,"side":"Sell","size":32000,"price":3110.46,"timestamp":"2024-05-18T15:46:18.924Z"},{"symbol":"ETHUSDT","id":32402510256,"side":"Sell","size":28000,"price":3109.87,"timestamp":"2024-05-18T15:46:18.924Z"},{"symbol":"ETHUSDT","id":32402510314,"side":"Buy","size":1000,"price":3108.60,"timestamp":"2024-05-18T15:46:18.924Z"}]}
{"table":"orderBookL2_25","action":"delete","data":[{"symbol":"XBTUSDT","id":32402508538,"side":"Sell","price":66785.1,"timestamp":"2024-05-18T15:46:18.928Z"},{"symbol":"XBTUSDT","id":32402510126,"side":"Sell","price":66782.2,"timestamp":"2024-05-18T15:46:18.928Z"},{"symbol":"XBTUSDT","id":32402505024,"side":"Buy","price":66718.3,"timestamp":"2024-05-18T15:46:18.928Z"},{"symbol":"XBTUSDT","id":32402505797,"side":"Buy","price":66718.8,"timestamp":"2024-05-18T15:46:18.928Z"}]}
{"table":"orderBookL2_25","action":"update","data":[{"symbol":"XBTUSDT","id":32402508316,"side":"Buy","size":8000,"price":66750.9,"timestamp":"2024-05-18T15:46:18.928Z"}]}
{"table":"orderBookL2_25","action":"insert","data":[{"symbol":"XBTUSDT","id":32402510293,"side":"Sell","size":3000,"price":66769.5,"timestamp":"2024-05-18T15:46:18.928Z"},{"symbol":"XBTUSDT","id":32402510295,"side":"Sell","size":1000,"price":66782.2,"timestamp":"2024-05-18T15:46:18.928Z"},{"symbol":"XBTUSDT","id":32402510331,"side":"Buy","size":8000,"price":66757.8,"timestamp":"2024-05-18T15:46:18.928Z"},{"symbol":"XBTUSDT","id":32402510311,"side":"Buy","size":8000,"price":66761.2,"timestamp":"2024-05-18T15:46:18.928Z"}]}
{"table":"orderBookL2_25","action":"delete","data":[{"symbol":"ETHUSDT","id":32402505932,"side":"Sell","price":3112.60,"timestamp":"2024-05-18T15:46:18.973Z"}]}
{"table":"orderBookL2_25","action":"insert","data":[{"symbol":"ETHUSDT","id":32402510375,"side":"Sell","size":25000,"price":3110.34,"timestamp":"2024-05-18T15:46:18.973Z"}]}
{"table":"orderBookL2_25","action":"delete","data":[{"symbol":"XBTUSDT","id":32401552282,"side":"Buy","price":66720.0,"timestamp":"2024-05-18T15:46:18.977Z"}]}
{"table":"orderBookL2_25","action":"update","data":[{"symbol":"XBTUSDT","id":32402504528,"side":"Sell","size":18000,"price":66780.1,"timestamp":"2024-05-18T15:46:18.977Z"},{"symbol":"XBTUSDT","id":32402506821,"side":"Buy","size":20000,"price":66747.1,"timestamp":"2024-05-18T15:46:18.977Z"}]}
{"table":"orderBookL2_25","action":"insert","data":[{"symbol":"XBTUSDT","id":32402510356,"side":"Buy","size":2000,"price":66757.6,"timestamp":"2024-05-18T15:46:18.977Z"}]}
{"table":"orderBookL2_25","action":"delete","data":[{"symbol":"ETHUSDT","id":32402510314,"side":"Buy","price":3108.60,"timestamp":"2024-05-18T15:46:19.022Z"}]}
{"table":"orderBookL2_25","action":"update","data":[{"symbol":"ETHUSDT","id":32402509151,"side":"Buy","size":21000,"price":3108.58,"timestamp":"2024-05-18T15:46:19.022Z"}]}
{"table":"orderBookL2_25","action":"insert","data":[{"symbol":"ETHUSDT","id":32402505870,"side":"Buy","size":100000,"price":3106.28,"timestamp":"2024-05-18T15:46:19.022Z"}]}
{"table":"orderBookL2_25","action":"delete","data":[{"symbol":"XBTUSDT","id":32402510295,"side":"Sell","price":66782.2,"timestamp":"2024-05-18T15:46:19.026Z"}]}
{"table":"orderBookL2_25","action":"insert","data":[{"symbol":"XBTUSDT","id":32402510493,"side":"Sell","size":1000,"price":66782.0,"timestamp":"2024-05-18T15:46:19.026Z"}]}
{"table":"orderBookL2_25","action":"delete","data":[{"symbol":"ETHUSDT","id":32402510254,"side":"Sell","price":3110.46,"timestamp":"2024-05-18T15:46:19.071Z"},{"symbol":"ETHUSDT","id":32402510249,"side":"Sell","price":3110.45,"timestamp":"2024-05-18T15:46:19.071Z"},{"symbol":"ETHUSDT","id":32402509091,"side":"Buy","price":3107.92,"timestamp":"2024-05-18T15:46:19.071Z"},{"symbol":"ETHUSDT","id":32402509252,"side":"Buy","price":3108.67,"timestamp":"2024-05-18T15:46:19.071Z"},{"symbol":"ETHUSDT","id":32402509822,"side":"Buy","price":3108.84,"timestamp":"2024-05-18T15:46:19.071Z"},{"symbol":"ETHUSDT","id":32402509837,"side":"Buy","price":3108.59,"timestamp":"2024-05-18T15:46:19.071Z"},{"symbol":"ETHUSDT","id":32402509922,"side":"Buy","price":3108.83,"timestamp":"2024-05-18T15:46:19.071Z"}]}
{"table":"orderBookL2_25","action":"update","data":[{"symbol":"ETHUSDT","id":32402508833,"side":"Buy","size":101000,"price":3108.57,"timestamp":"2024-05-18T15:46:19.071Z"},{"symbol":"ETHUSDT","id":32402509151,"side":"Buy","size":20000,"price":3108.58,"timestamp":"2024-05-18T15:46:19.071Z"}]}
{"table":"orderBookL2_25","action":"insert","data":[{"symbol":"ETHUSDT","id":32402510542,"side":"Sell","size":32000,"price":3110.41,"timestamp":"2024-05-18T15:46:19.071Z"},{"symbol":"ETHUSDT","id":32402510550,"side":"Sell","size":32000,"price":3110.40,"timestamp":"2024-05-18T15:46:19.071Z"},{"symbol":"ETHUSDT","id":32402510544,"side":"Buy","size":32000,"price":3108.80,"timestamp":"2024-05-18T15:46:19.071Z"},{"symbol":"ETHUSDT","id":32402510546,"side":"Buy","size":32000,"price":3108.81,"timestamp":"2024-05-18T15:46:19.071Z"},{"symbol":"ETHUSDT","id":32402510532,"side":"Buy","size":1000,"price":3108.56,"timestamp":"2024-05-18T15:46:19.071Z"},{"symbol":"ETHUSDT","id":32402494460,"side":"Buy","size":1114000,"price":3106.20,"timestamp":"2024-05-18T15:46:19.071Z"},{"symbol":"ETHUSDT","id":32402510510,"side":"Buy","size":533000,"price":3107.73,"timestamp":"2024-05-18T15:46:19.071Z"}]}
{"table":"orderBookL2_25","action":"delete","data":[{"symbol":"XBTUSDT","id":32402510211,"side":"Sell","price":66774.9,"timestamp":"2024-05-18T15:46:19.075Z"},{"symbol":"XBTUSDT","id":32402509417,"side":"Sell","price":66776.2,"timestamp":"2024-05-18T15:46:19.075Z"},{"symbol":"XBTUSDT","id":32402491670,"side":"Sell","price":66795.5,"timestamp":"2024-05-18T15:46:19.075Z"},{"symbol":"XBTUSDT","id":32402509820,"side":"Sell","price":66782.1,"timestamp":"2024-05-18T15:46:19.075Z"},{"symbol":"XBTUSDT","id":32402510207,"side":"Buy","price":66747.0,"timestamp":"2024-05-18T15:46:19.075Z"}]}
{"table":"orderBookL2_25","action":"insert","data":[{"symbol":"XBTUSDT","id":32402510571,"side":"Sell","size":3000,"price":66783.2,"timestamp":"2024-05-18T15:46:19.075Z"},{"symbol":"XBTUSDT","id":32402510535,"side":"Sell","size":156000,"price":66769.4,"timestamp":"2024-05-18T15:46:19.075Z"},{"symbol":"XBTUSDT","id":32402510548,"side":"Sell","size":1000,"price":66781.9,"timestamp":"2024-05-18T15:46:19.075Z"},{"symbol":"XBTUSDT","id":32402510529,"side":"Sell","size":20000,"price":66774.7,"timestamp":"2024-05-18T15:46:19.075Z"},{"symbol":"XBTUSDT","id":32402510525,"side":"Buy","size":20000,"price":66747.2,"timestamp":"2024-05-18T15:46:19.075Z"}]}
{"table":"orderBookL2_25","action":"delete","data":[{"symbol":"ETHUSDT","id":32402510550,"side":"Sell","price":3110.40,"timestamp":"2024-05-18T15:46:19.120Z"},{"symbol":"ETHUSDT","id":32402510532,"side":"Buy","price":3108.56,"timestamp":"2024-05-18T15:46:19.120Z"},{"symbol":"ETHUSDT","id":32402510544,"side":"Buy","price":3108.80,"timestamp":"2024-05-18T15:46:19.120Z"}]}
{"table":"orderBookL2_25","action":"update","data":[{"symbol":"ETHUSDT","id":32402509151,"side":"Buy","size":21000,"price":3108.58,"timestamp":"2024-05-18T15:46:19.120Z"}]}
{"table":"orderBookL2_25","action":"insert","data":[{"symbol":"ETHUSDT","id":32402510624,"side":"Sell","size":32000,"price":3110.42,"timestamp":"2024-05-18T15:46:19.120Z"},{"symbol":"ETHUSDT","id":32402510622,"side":"Buy","size":32000,"price":3108.82,"timestamp":"2024-05-18T15:46:19.120Z"},{"symbol":"ETHUSDT","id":32402510660,"side":"Buy","size":100000,"price":3108.38,"timestamp":"2024-05-18T15:46:19.120Z"}]}
{"table":"orderBookL2_25","action":"delete","data":[{"symbol":"XBTUSDT","id":32402505084,"side":"Sell","price":66784.2,"timestamp":"2024-05-18T15:46:19.124Z"},{"symbol":"XBTUSDT","id":32402509812,"side":"Sell","price":66777.0,"timestamp":"2024-05-18T15:46:19.124Z"},{"symbol":"XBTUSDT","id":32402510548,"side":"Sell","price":66781.9,"timestamp":"2024-05-18T15:46:19.124Z"},{"symbol":"XBTUSDT","id":32402509867,"side":"Sell","price":66774.8,"timestamp":"2024-05-18T15:46:19.124Z"},{"symbol":"XBTUSDT","id":32402509562,"side":"Sell","price":66767.2,"timestamp":"2024-05-18T15:46:19.124Z"},{"symbol":"XBTUSDT","id":32402505528,"side":"Buy","price":66736.3,"timestamp":"2024-05-18T15:46:19.124Z"},{"symbol":"XBTUSDT","id":32402507770,"side":"Buy","price":66746.9,"timestamp":"2024-05-18T15:46:19.124Z"},{"symbol":"XBTUSDT","id":32402506821,"side":"Buy","price":66747.1,"timestamp":"2024-05-18T15:46:19.124Z"},{"symbol":"XBTUSDT","id":32402510525,"side":"Buy","price":66747.2,"timestamp":"2024-05-18T15:46:19.124Z"}]}
{"table":"orderBookL2_25","action":"update","data":[{"symbol":"XBTUSDT","id":32402506378,"side":"Sell","size":213000,"price":66764.5,"timestamp":"2024-05-18T15:46:19.124Z"},{"symbol":"XBTUSDT","id":32402505821,"side":"Buy","size":136000,"price":66764.4,"timestamp":"2024-05-18T15:46:19.124Z"}]}
{"table":"orderBookL2_25","action":"insert","data":[{"symbol":"XBTUSDT","id":32402491670,"side":"Sell","size":100000,"price":66795.5,"timestamp":"2024-05-18T15:46:19.124Z"},{"symbol":"XBTUSDT","id":32402504870,"side":"Sell","size":538000,"price":66795.7,"timestamp":"2024-05-18T15:46:19.124Z"},{"symbol":"XBTUSDT","id":32402510630,"side":"Sell","size":1000,"price":66782.1,"timestamp":"2024-05-18T15:46:19.124Z"},{"symbol":"XBTUSDT","id":32402510597,"side":"Sell","size":20000,"price":66774.6,"timestamp":"2024-05-18T15:46:19.124Z"},{"symbol":"XBTUSDT","id":32402509130,"side":"Sell","size":15000,"price":66798.0,"timestamp":"2024-05-18T15:46:19.124Z"},{"symbol":"XBTUSDT","id":32402510644,"side":"Buy","size":20000,"price":66747.2,"timestamp":"2024-05-18T15:46:19.124Z"},{"symbol":"XBTUSDT","id":32402510652,"side":"Buy","size":20000,"price":66747.3,"timestamp":"2024-05-18T15:46:19.124Z"},{"symbol":"XBTUSDT","id":32401552282,"side":"Buy","size":1000,"price":66720.0,"timestamp":"2024-05-18T15:46:19.124Z"},{"symbol":"XBTUSDT","id":32402510648,"side":"Buy","size":20000,"price":66755.4,"timestamp":"2024-05-18T15:46:19.124Z"}]}
{"table":"orderBookL2_25","action":"delete","data":[{"symbol":"ETHUSDT","id":32402510375,"side":"Sell","price":3110.34,"timestamp":"2024-05-18T15:46:19.169Z"},{"symbol":"ETHUSDT","id":32402510624,"side":"Sell","price":3110.42,"timestamp":"2024-05-18T15:46:19.169Z"},{"symbol":"ETHUSDT","id":32402510622,"side":"Buy","price":3108.82,"timestamp":"2024-05-18T15:46:19.169Z"},{"symbol":"ETHUSDT","id":32402494460,"side":"Buy","price":3106.20,"timestamp":"2024-05-18T15:46:19.169Z"}]}
{"table":"orderBookL2_25","action":"update","data":[{"symbol":"ETHUSDT","id":32402509151,"side":"Buy","size":20000,"price":3108.58,"timestamp":"2024-05-18T15:46:19.169Z"}]}
{"table":"orderBookL2_25","action":"insert","data":[{"symbol":"ETHUSDT","id":32402510770,"side":"Sell","size":2000,"price":3109.35,"timestamp":"2024-05-18T15:46:19.169Z"},{"symbol":"ETHUSDT","id":32402510745,"side":"Sell","size":32000,"price":3110.40,"timestamp":"2024-05-18T15:46:19.169Z"},{"symbol":"ETHUSDT","id":32402510780,"side":"Buy","size":1000,"price":3108.56,"timestamp":"2024-05-18T15:46:19.169Z"},{"symbol":"ETHUSDT","id":32402510743,"side":"Buy","size":32000,"price":3108.80,"timestamp":"2024-05-18T15:46:19.169Z"}]}
{"table":"orderBookL2_25","action":"delete","data":[{"symbol":"XBTUSDT","id":32402504870,"side":"Sell","price":66795.7,"timestamp":"2024-05-18T15:46:19.173Z"},{"symbol":"XBTUSDT","id":32402509130,"side":"Sell","price":66798.0,"timestamp":"2024-05-18T15:46:19.173Z"},{"symbol":"XBTUSDT","id":32402509996,"side":"Buy","price":66736.4,"timestamp":"2024-05-18T15:46:19.173Z"},{"symbol":"XBTUSDT","id":32402506751,"side":"Buy","price":66757.7,"timestamp":"2024-05-18T15:46:19.173Z"}]}
{"table":"orderBookL2_25","action":"update","data":[{"symbol":"XBTUSDT","id":32402506378,"side":"Sell","size":13000,"price":66764.5,"timestamp":"2024-05-18T15:46:19.173Z"},{"symbol":"XBTUSDT","id":32402509728,"side":"Buy","size":16000,"price":66761.1,"timestamp":"2024-05-18T15:46:19.173Z"},{"symbol":"XBTUSDT","id":32402510356,"side":"Buy","size":102000,"price":66757.6,"timestamp":"2024-05-18T15:46:19.173Z"}]}
