{"table":"orderBookL2_25","action":"insert","data":[{"symbol":"XBTUSDT","id":32402510723,"side":"Sell","size":2000,"price":66791.0,"timestamp":"2024-05-18T15:46:19.173Z"},{"symbol":"XBTUSDT","id":32402510711,"side":"Sell","size":100000,"price":66767.9,"timestamp":"2024-05-18T15:46:19.173Z"},{"symbol":"XBTUSDT","id":32402505797,"side":"Buy","size":1502000,"price":66718.8,"timestamp":"2024-05-18T15:46:19.173Z"},{"symbol":"XBTUSDT","id":32402510774,"side":"Buy","size":390000,"price":66736.4,"timestamp":"2024-05-18T15:46:19.173Z"}]}
{"table":"orderBookL2_25","action":"delete","data":[{"symbol":"XBTETH","id":32402426122,"side":"Buy","price":21.098,"timestamp":"2024-05-18T15:46:19.217Z"}]}
{"table":"orderBookL2_25","action":"insert","data":[{"symbol":"XBTETH","id":32402510917,"side":"Buy","size":6,"price":21.093,"timestamp":"2024-05-18T15:46:19.217Z"}]}
{"table":"orderBookL2_25","action":"delete","data":[{"symbol":"ETHUSDT","id":32402510770,"side":"Sell","price":3109.35,"timestamp":"2024-05-18T15:46:19.218Z"},{"symbol":"ETHUSDT","id":32402510780,"side":"Buy","price":3108.56,"timestamp":"2024-05-18T15:46:19.218Z"}]}
{"table":"orderBookL2_25","action":"update","data":[{"symbol":"ETHUSDT","id":32402488716,"side":"Sell","size":100000,"price":3112.18,"timestamp":"2024-05-18T15:46:19.218Z"},{"symbol":"ETHUSDT","id":32402509151,"side":"Buy","size":21000,"price":3108.58,"timestamp":"2024-05-18T15:46:19.218Z"}]}
{"table":"orderBookL2_25","action":"insert","data":[{"symbol":"ETHUSDT","id":32402505932,"side":"Sell","size":1000,"price":3112.60,"timestamp":"2024-05-18T15:46:19.218Z"},{"symbol":"ETHUSDT","id":32402494460,"side":"Buy","size":1114000,"price":3106.20,"timestamp":"2024-05-18T15:46:19.218Z"}]}
{"table":"orderBookL2_25","action":"delete","data":[{"symbol":"XBTUSDT","id":32402506656,"side":"Sell","price":66786.2,"timestamp":"2024-05-18T15:46:19.222Z"},{"symbol":"XBTUSDT","id":32402510630,"side":"Sell","price":66782.1,"timestamp":"2024-05-18T15:46:19.222Z"},{"symbol":"XBTUSDT","id":32402510493,"side":"Sell","price":66782.0,"timestamp":"2024-05-18T15:46:19.222Z"},{"symbol":"XBTUSDT","id":32402510597,"side":"Sell","price":66774.6,"timestamp":"2024-05-18T15:46:19.222Z"},{"symbol":"XBTUSDT","id":32402510535,"side":"Sell","price":66769.4,"timestamp":"2024-05-18T15:46:19.222Z"},{"symbol":"XBTUSDT","id":32402510529,"side":"Sell","price":66774.7,"timestamp":"2024-05-18T15:46:19.222Z"},{"symbol":"XBTUSDT","id":32402510652,"side":"Buy","price":66747.3,"timestamp":"2024-05-18T15:46:19.222Z"},{"symbol":"XBTUSDT","id":32402510774,"side":"Buy","price":66736.4,"timestamp":"2024-05-18T15:46:19.222Z"},{"symbol":"XBTUSDT","id":32402508316,"side":"Buy","price":66750.9,"timestamp":"2024-05-18T15:46:19.222Z"},{"symbol":"XBTUSDT","id":32402510644,"side":"Buy","price":66747.2,"timestamp":"2024-05-18T15:46:19.222Z"},{"symbol":"XBTUSDT","id":32402505797,"side":"Buy","price":66718.8,"timestamp":"2024-05-18T15:46:19.222Z"}]}
{"table":"orderBookL2_25","action":"update","data":[{"symbol":"XBTUSDT","id":32402505821,"side":"Buy","size":144000,"price":66764.4,"timestamp":"2024-05-18T15:46:19.222Z"},{"symbol":"XBTUSDT","id":32402507156,"side":"Buy","size":100000,"price":66747.4,"timestamp":"2024-05-18T15:46:19.222Z"}]}
{"table":"orderBookL2_25","action":"insert","data":[{"symbol":"XBTUSDT","id":32402510880,"side":"Sell","size":20000,"price":66775.1,"timestamp":"2024-05-18T15:46:19.222Z"},{"symbol":"XBTUSDT","id":32402504870,"side":"Sell","size":538000,"price":66795.7,"timestamp":"2024-05-18T15:46:19.222Z"},{"symbol":"XBTUSDT","id":32402510889,"side":"Sell","size":1000,"price":66782.2,"timestamp":"2024-05-18T15:46:19.222Z"},{"symbol":"XBTUSDT","id":32402510898,"side":"Sell","size":20000,"price":66769.3,"timestamp":"2024-05-18T15:46:19.222Z"},{"symbol":"XBTUSDT","id":32402510848,"side":"Sell","size":1000,"price":66782.3,"timestamp":"2024-05-18T15:46:19.222Z"},{"symbol":"XBTUSDT","id":32402510882,"side":"Sell","size":20000,"price":66775.0,"timestamp":"2024-05-18T15:46:19.222Z"},{"symbol":"XBTUSDT","id":32402510872,"side":"Buy","size":20000,"price":66747.2,"timestamp":"2024-05-18T15:46:19.222Z"},{"symbol":"XBTUSDT","id":32402510878,"side":"Buy","size":63000,"price":66750.9,"timestamp":"2024-05-18T15:46:19.222Z"},{"symbol":"XBTUSDT","id":32402510860,"side":"Buy","size":388000,"price":66736.4,"timestamp":"2024-05-18T15:46:19.222Z"},{"symbol":"XBTUSDT","id":32402510875,"side":"Buy","size":20000,"price":66747.3,"timestamp":"2024-05-18T15:46:19.222Z"},{"symbol":"XBTUSDT","id":32402510906,"side":"Buy","size":237000,"price":66736.5,"timestamp":"2024-05-18T15:46:19.222Z"}]}
{"table":"orderBookL2_25","action":"delete","data":[{"symbol":"XBTETH","id":32402426126,"side":"Sell","price":21.915,"timestamp":"2024-05-18T15:46:19.267Z"}]}
{"table":"orderBookL2_25","action":"insert","data":[{"symbol":"XBTETH","id":32402511021,"side":"Sell","size":6,"price":21.911,"timestamp":"2024-05-18T15:46:19.267Z"}]}
{"table":"orderBookL2_25","action":"delete","data":[{"symbol":"ETHUSDT","id":32402510542,"side":"Sell","price":3110.41,"timestamp":"2024-05-18T15:46:19.267Z"},{"symbol":"ETHUSDT","id":32402510745,"side":"Sell","price":3110.40,"timestamp":"2024-05-18T15:46:19.267Z"},{"symbol":"ETHUSDT","id":32402504834,"side":"Buy","price":3106.40,"timestamp":"2024-05-18T15:46:19.267Z"},{"symbol":"ETHUSDT","id":32402510743,"side":"Buy","price":3108.80,"timestamp":"2024-05-18T15:46:19.267Z"},{"symbol":"ETHUSDT","id":32402510546,"side":"Buy","price":3108.81,"timestamp":"2024-05-18T15:46:19.267Z"},{"symbol":"ETHUSDT","id":32402494460,"side":"Buy","price":3106.20,"timestamp":"2024-05-18T15:46:19.267Z"},{"symbol":"ETHUSDT","id":32402505870,"side":"Buy","price":3106.28,"timestamp":"2024-05-18T15:46:19.267Z"}]}
{"table":"orderBookL2_25","action":"update","data":[{"symbol":"ETHUSDT","id":32402508833,"side":"Buy","size":100000,"price":3108.57,"timestamp":"2024-05-18T15:46:19.267Z"},{"symbol":"ETHUSDT","id":32402509151,"side":"Buy","size":20000,"price":3108.58,"timestamp":"2024-05-18T15:46:19.267Z"}]}
{"table":"orderBookL2_25","action":"insert","data":[{"symbol":"ETHUSDT","id":32402510984,"side":"Sell","size":32000,"price":3110.47,"timestamp":"2024-05-18T15:46:19.267Z"},{"symbol":"ETHUSDT","id":32402510980,"side":"Sell","size":32000,"price":3110.48,"timestamp":"2024-05-18T15:46:19.267Z"},{"symbol":"ETHUSDT","id":32402510944,"side":"Buy","size":1000,"price":3108.60,"timestamp":"2024-05-18T15:46:19.267Z"},{"symbol":"ETHUSDT","id":32402510998,"side":"Buy","size":68000,"price":3108.39,"timestamp":"2024-05-18T15:46:19.267Z"},{"symbol":"ETHUSDT","id":32402510986,"side":"Buy","size":32000,"price":3108.84,"timestamp":"2024-05-18T15:46:19.267Z"},{"symbol":"ETHUSDT","id":32402510992,"side":"Buy","size":32000,"price":3108.83,"timestamp":"2024-05-18T15:46:19.267Z"},{"symbol":"ETHUSDT","id":32402511017,"side":"Buy","size":1000,"price":3108.61,"timestamp":"2024-05-18T15:46:19.267Z"}]}
{"table":"orderBookL2_25","action":"delete","data":[{"symbol":"XBTUSDT","id":32402510889,"side":"Sell","price":66782.2,"timestamp":"2024-05-18T15:46:19.271Z"},{"symbol":"XBTUSDT","id":32402510882,"side":"Sell","price":66775.0,"timestamp":"2024-05-18T15:46:19.271Z"},{"symbol":"XBTUSDT","id":32402510848,"side":"Sell","price":66782.3,"timestamp":"2024-05-18T15:46:19.271Z"},{"symbol":"XBTUSDT","id":32401552282,"side":"Buy","price":66720.0,"timestamp":"2024-05-18T15:46:19.271Z"},{"symbol":"XBTUSDT","id":32402510875,"side":"Buy","price":66747.3,"timestamp":"2024-05-18T15:46:19.271Z"},{"symbol":"XBTUSDT","id":32401547573,"side":"Buy","price":66723.1,"timestamp":"2024-05-18T15:46:19.271Z"}]}
{"table":"orderBookL2_25","action":"update","data":[{"symbol":"XBTUSDT","id":32402506378,"side":"Sell","size":129000,"price":66764.5,"timestamp":"2024-05-18T15:46:19.271Z"}]}
{"table":"orderBookL2_25","action":"insert","data":[{"symbol":"XBTUSDT","id":32402511015,"side":"Sell","size":1000,"price":66782.2,"timestamp":"2024-05-18T15:46:19.271Z"},{"symbol":"XBTUSDT","id":32402511011,"side":"Sell","size":1000,"price":66782.1,"timestamp":"2024-05-18T15:46:19.271Z"},{"symbol":"XBTUSDT","id":32402511009,"side":"Sell","size":20000,"price":66775.0,"timestamp":"2024-05-18T15:46:19.271Z"},{"symbol":"XBTUSDT","id":32402511005,"side":"Buy","size":65000,"price":66744.1,"timestamp":"2024-05-18T15:46:19.271Z"},{"symbol":"XBTUSDT","id":32402511037,"side":"Buy","size":66000,"price":66733.9,"timestamp":"2024-05-18T15:46:19.271Z"},{"symbol":"XBTUSDT","id":32402511029,"side":"Buy","size":20000,"price":66747.1,"timestamp":"2024-05-18T15:46:19.271Z"}]}
{"table":"orderBookL2_25","action":"delete","data":[{"symbol":"ETHUSDT","id":32402510984,"side":"Sell","price":3110.47,"timestamp":"2024-05-18T15:46:19.316Z"},{"symbol":"ETHUSDT","id":32402510986,"side":"Buy","price":3108.84,"timestamp":"2024-05-18T15:46:19.316Z"},{"symbol":"ETHUSDT","id":32402511017,"side":"Buy","price":3108.61,"timestamp":"2024-05-18T15:46:19.316Z"}]}
{"table":"orderBookL2_25","action":"insert","data":[{"symbol":"ETHUSDT","id":32402511087,"side":"Sell","size":32000,"price":3110.47,"timestamp":"2024-05-18T15:46:19.316Z"},{"symbol":"ETHUSDT","id":32402511089,"side":"Buy","size":32000,"price":3108.84,"timestamp":"2024-05-18T15:46:19.316Z"},{"symbol":"ETHUSDT","id":32402511051,"side":"Buy","size":1000,"price":3108.59,"timestamp":"2024-05-18T15:46:19.316Z"}]}
{"table":"orderBookL2_25","action":"delete","data":[{"symbol":"XBTUSDT","id":32402511011,"side":"Sell","price":66782.1,"timestamp":"2024-05-18T15:46:19.320Z"},{"symbol":"XBTUSDT","id":32402511009,"side":"Sell","price":66775.0,"timestamp":"2024-05-18T15:46:19.320Z"},{"symbol":"XBTUSDT","id":32402511015,"side":"Sell","price":66782.2,"timestamp":"2024-05-18T15:46:19.320Z"}]}
{"table":"orderBookL2_25","action":"insert","data":[{"symbol":"XBTUSDT","id":32402511055,"side":"Sell","size":20000,"price":66775.2,"timestamp":"2024-05-18T15:46:19.320Z"},{"symbol":"XBTUSDT","id":32402511053,"side":"Sell","size":1000,"price":66782.3,"timestamp":"2024-05-18T15:46:19.320Z"},{"symbol":"XBTUSDT","id":32402511047,"side":"Sell","size":1000,"price":66782.4,"timestamp":"2024-05-18T15:46:19.320Z"}]}
{"table":"orderBookL2_25","action":"delete","data":[{"symbol":"XBTUSDT","id":32402504870,"side":"Sell","price":66795.7,"timestamp":"2024-05-18T15:46:19.369Z"}]}
{"table":"orderBookL2_25","action":"update","data":[{"symbol":"XBTUSDT","id":32402506378,"side":"Sell","size":229000,"price":66764.5,"timestamp":"2024-05-18T15:46:19.369Z"},{"symbol":"XBTUSDT","id":32402505821,"side":"Buy","size":44000,"price":66764.4,"timestamp":"2024-05-18T15:46:19.369Z"}]}
{"table":"orderBookL2_25","action":"insert","data":[{"symbol":"XBTUSDT","id":32402511161,"side":"Sell","size":129000,"price":66771.9,"timestamp":"2024-05-18T15:46:19.369Z"}]}
{"table":"orderBookL2_25","action":"delete","data":[{"symbol":"ETHUSDT","id":32402354519,"side":"Buy","price":3106.60,"timestamp":"2024-05-18T15:46:19.392Z"}]}
{"table":"orderBookL2_25","action":"insert","data":[{"symbol":"ETHUSDT","id":32402511227,"side":"Buy","size":1126000,"price":3107.00,"timestamp":"2024-05-18T15:46:19.392Z"}]}
{"table":"orderBookL2_25","action":"delete","data":[{"symbol":"XBTUSDT","id":32402511055,"side":"Sell","price":66775.2,"timestamp":"2024-05-18T15:46:19.418Z"},{"symbol":"XBTUSDT","id":32402510293,"side":"Sell","price":66769.5,"timestamp":"2024-05-18T15:46:19.418Z"},{"symbol":"XBTUSDT","id":32402511029,"side":"Buy","price":66747.1,"timestamp":"2024-05-18T15:46:19.418Z"}]}
{"table":"orderBookL2_25","action":"update","data":[{"symbol":"XBTUSDT","id":32402506378,"side":"Sell","size":329000,"price":66764.5,"timestamp":"2024-05-18T15:46:19.418Z"}]}
{"table":"orderBookL2_25","action":"insert","data":[{"symbol":"XBTUSDT","id":32402511243,"side":"Sell","size":3000,"price":66779.9,"timestamp":"2024-05-18T15:46:19.418Z"},{"symbol":"XBTUSDT","id":32402511191,"side":"Sell","size":20000,"price":66775.0,"timestamp":"2024-05-18T15:46:19.418Z"},{"symbol":"XBTUSDT","id":32402511187,"side":"Buy","size":20000,"price":66747.3,"timestamp":"2024-05-18T15:46:19.418Z"}]}
{"table":"orderBookL2_25","action":"delete","data":[{"symbol":"ETHUSDT","id":32402505366,"side":"Buy","price":3106.92,"timestamp":"2024-05-18T15:46:19.442Z"}]}
{"table":"orderBookL2_25","action":"insert","data":[{"symbol":"ETHUSDT","id":32402511235,"side":"Buy","size":703000,"price":3108.13,"timestamp":"2024-05-18T15:46:19.442Z"}]}
{"table":"orderBookL2_25","action":"delete","data":[{"symbol":"XBTUSDT","id":32402491670,"side":"Sell","price":66795.5,"timestamp":"2024-05-18T15:46:19.468Z"}]}
{"table":"orderBookL2_25","action":"insert","data":[{"symbol":"XBTUSDT","id":32402511319,"side":"Sell","size":8000,"price":66767.8,"timestamp":"2024-05-18T15:46:19.468Z"}]}
{"table":"orderBookL2_25","action":"delete","data":[{"symbol":"ETHUSDT","id":32402505932,"side":"Sell","price":3112.60,"timestamp":"2024-05-18T15:46:19.517Z"}]}
{"table":"orderBookL2_25","action":"insert","data":[{"symbol":"ETHUSDT","id":32402511384,"side":"Sell","size":2000,"price":3109.35,"timestamp":"2024-05-18T15:46:19.517Z"}]}
{"table":"orderBookL2_25","action":"delete","data":[{"symbol":"XBTUSDT","id":32402510331,"side":"Buy","price":66757.8,"timestamp":"2024-05-18T15:46:19.518Z"}]}
{"table":"orderBookL2_25","action":"update","data":[{"symbol":"XBTUSDT","id":32402510029,"side":"Buy","size":74000,"price":66730.1,"timestamp":"2024-05-18T15:46:19.518Z"}]}
{"table":"orderBookL2_25","action":"insert","data":[{"symbol":"XBTUSDT","id":32402511337,"side":"Buy","size":8000,"price":66761.3,"timestamp":"2024-05-18T15:46:19.518Z"}]}
{"table":"orderBookL2_25","action":"delete","data":[{"symbol":"ETHUSDT","id":32402511384,"side":"Sell","price":3109.35,"timestamp":"2024-05-18T15:46:19.566Z"}]}
{"table":"orderBookL2_25","action":"update","data":[{"symbol":"ETHUSDT","id":32402488716,"side":"Sell","size":100000,"price":3112.18,"timestamp":"2024-05-18T15:46:19.566Z"}]}
{"table":"orderBookL2_25","action":"insert","data":[{"symbol":"ETHUSDT","id":32402505932,"side":"Sell","size":1000,"price":3112.60,"timestamp":"2024-05-18T15:46:19.566Z"}]}
{"table":"orderBookL2_25","action":"delete","data":[{"symbol":"XBTUSDT","id":32402501930,"side":"Sell","price":66792.7,"timestamp":"2024-05-18T15:46:19.567Z"},{"symbol":"XBTUSDT","id":32402510723,"side":"Sell","price":66791.0,"timestamp":"2024-05-18T15:46:19.567Z"},{"symbol":"XBTUSDT","id":32402499098,"side":"Sell","price":66792.1,"timestamp":"2024-05-18T15:46:19.567Z"},{"symbol":"XBTUSDT","id":32402511047,"side":"Sell","price":66782.4,"timestamp":"2024-05-18T15:46:19.567Z"},{"symbol":"XBTUSDT","id":32402511187,"side":"Buy","price":66747.3,"timestamp":"2024-05-18T15:46:19.567Z"},{"symbol":"XBTUSDT","id":32402510872,"side":"Buy","price":66747.2,"timestamp":"2024-05-18T15:46:19.567Z"}]}
{"table":"orderBookL2_25","action":"insert","data":[{"symbol":"XBTUSDT","id":32402511500,"side":"Sell","size":219000,"price":66776.0,"timestamp":"2024-05-18T15:46:19.567Z"},{"symbol":"XBTUSDT","id":32402511412,"side":"Sell","size":1000,"price":66782.2,"timestamp":"2024-05-18T15:46:19.567Z"},{"symbol":"XBTUSDT","id":32402511486,"side":"Sell","size":10000,"price":66767.3,"timestamp":"2024-05-18T15:46:19.567Z"},{"symbol":"XBTUSDT","id":32402511458,"side":"Sell","size":156000,"price":66771.8,"timestamp":"2024-05-18T15:46:19.567Z"},{"symbol":"XBTUSDT","id":32402511502,"side":"Buy","size":20000,"price":66747.3,"timestamp":"2024-05-18T15:46:19.567Z"},{"symbol":"XBTUSDT","id":32402511498,"side":"Buy","size":20000,"price":66747.2,"timestamp":"2024-05-18T15:46:19.567Z"}]}
{"table":"orderBookL2_25","action":"delete","data":[{"symbol":"XBTUSDT","id":32402510571,"side":"Sell","price":66783.2,"timestamp":"2024-05-18T15:46:19.616Z"},{"symbol":"XBTUSDT","id":32402511412,"side":"Sell","price":66782.2,"timestamp":"2024-05-18T15:46:19.616Z"}]}
{"table":"orderBookL2_25","action":"insert","data":[{"symbol":"XBTUSDT","id":32402511507,"side":"Sell","size":3000,"price":66786.6,"timestamp":"2024-05-18T15:46:19.616Z"},{"symbol":"XBTUSDT","id":32402511524,"side":"Sell","size":1000,"price":66782.4,"timestamp":"2024-05-18T15:46:19.616Z"}]}
{"table":"orderBookL2_25","action":"delete","data":[{"symbol":"ETHUSDT","id":32402509978,"side":"Sell","price":3110.20,"timestamp":"2024-05-18T15:46:19.660Z"}]}
{"table":"orderBookL2_25","action":"insert","data":[{"symbol":"ETHUSDT","id":32402447682,"side":"Sell","size":100000,"price":3112.68,"timestamp":"2024-05-18T15:46:19.660Z"}]}
{"table":"orderBookL2_25","action":"delete","data":[{"symbol":"XBTUSDT","id":32402511486,"side":"Sell","price":66767.3,"timestamp":"2024-05-18T15:46:19.665Z"}]}
{"table":"orderBookL2_25","action":"insert","data":[{"symbol":"XBTUSDT","id":32402511599,"side":"Sell","size":17000,"price":66781.7,"timestamp":"2024-05-18T15:46:19.665Z"}]}
{"table":"orderBookL2_25","action":"delete","data":[{"symbol":"ETHUSDT","id":32402510980,"side":"Sell","price":3110.48,"timestamp":"2024-05-18T15:46:19.709Z"},{"symbol":"ETHUSDT","id":32402511087,"side":"Sell","price":3110.47,"timestamp":"2024-05-18T15:46:19.709Z"}]}
{"table":"orderBookL2_25","action":"insert","data":[{"symbol":"ETHUSDT","id":32402511673,"side":"Sell","size":32000,"price":3110.41,"timestamp":"2024-05-18T15:46:19.709Z"},{"symbol":"ETHUSDT","id":32402511671,"side":"Sell","size":32000,"price":3110.42,"timestamp":"2024-05-18T15:46:19.709Z"}]}
{"table":"orderBookL2_25","action":"delete","data":[{"symbol":"XBTUSDT","id":32402510880,"side":"Sell","price":66775.1,"timestamp":"2024-05-18T15:46:19.714Z"},{"symbol":"XBTUSDT","id":32402511599,"side":"Sell","price":66781.7,"timestamp":"2024-05-18T15:46:19.714Z"},{"symbol":"XBTUSDT","id":32402507340,"side":"Sell","price":66790.3,"timestamp":"2024-05-18T15:46:19.714Z"},{"symbol":"XBTUSDT","id":32402511524,"side":"Sell","price":66782.4,"timestamp":"2024-05-18T15:46:19.714Z"},{"symbol":"XBTUSDT","id":32402511502,"side":"Buy","price":66747.3,"timestamp":"2024-05-18T15:46:19.714Z"}]}
{"table":"orderBookL2_25","action":"insert","data":[{"symbol":"XBTUSDT","id":32402511677,"side":"Sell","size":50000,"price":66779.5,"timestamp":"2024-05-18T15:46:19.714Z"},{"symbol":"XBTUSDT","id":32402511628,"side":"Sell","size":1000,"price":66782.2,"timestamp":"2024-05-18T15:46:19.714Z"},{"symbol":"XBTUSDT","id":32402511662,"side":"Sell","size":20000,"price":66774.9,"timestamp":"2024-05-18T15:46:19.714Z"},{"symbol":"XBTUSDT","id":32402511633,"side":"Sell","size":74000,"price":66779.6,"timestamp":"2024-05-18T15:46:19.714Z"},{"symbol":"XBTUSDT","id":32402511669,"side":"Buy","size":20000,"price":66747.1,"timestamp":"2024-05-18T15:46:19.714Z"}]}
{"table":"orderBookL2_25","action":"delete","data":[{"symbol":"ETHUSDT","id":32402511671,"side":"Sell","price":3110.42,"timestamp":"2024-05-18T15:46:19.758Z"},{"symbol":"ETHUSDT","id":32402511673,"side":"Sell","price":3110.41,"timestamp":"2024-05-18T15:46:19.758Z"}]}
{"table":"orderBookL2_25","action":"insert","data":[{"symbol":"ETHUSDT","id":32402511713,"side":"Sell","size":32000,"price":3110.44,"timestamp":"2024-05-18T15:46:19.758Z"},{"symbol":"ETHUSDT","id":32402511725,"side":"Sell","size":32000,"price":3110.43,"timestamp":"2024-05-18T15:46:19.758Z"}]}
{"table":"orderBookL2_25","action":"delete","data":[{"symbol":"XBTUSDT","id":32402499271,"side":"Sell","price":66788.7,"timestamp":"2024-05-18T15:46:19.763Z"},{"symbol":"XBTUSDT","id":32402510356,"side":"Buy","price":66757.6,"timestamp":"2024-05-18T15:46:19.763Z"}]}
{"table":"orderBookL2_25","action":"insert","data":[{"symbol":"XBTUSDT","id":32402511708,"side":"Sell","size":102000,"price":66783.3,"timestamp":"2024-05-18T15:46:19.763Z"},{"symbol":"XBTUSDT","id":32402511466,"side":"Buy","size":62000,"price":66727.1,"timestamp":"2024-05-18T15:46:19.763Z"}]}
{"table":"orderBookL2_25","action":"delete","data":[{"symbol":"ETHUSDT","id":32402447682,"side":"Sell","price":3112.68,"timestamp":"2024-05-18T15:46:19.807Z"},{"symbol":"ETHUSDT","id":32402504254,"side":"Buy","price":3106.99,"timestamp":"2024-05-18T15:46:19.807Z"}]}
{"table":"orderBookL2_25","action":"insert","data":[{"symbol":"ETHUSDT","id":32402511735,"side":"Sell","size":43000,"price":3110.34,"timestamp":"2024-05-18T15:46:19.807Z"},{"symbol":"ETHUSDT","id":32402511738,"side":"Buy","size":115000,"price":3107.49,"timestamp":"2024-05-18T15:46:19.807Z"}]}
{"table":"orderBookL2_25","action":"delete","data":[{"symbol":"XBTUSDT","id":32402509728,"side":"Buy","price":66761.1,"timestamp":"2024-05-18T15:46:19.812Z"}]}
{"table":"orderBookL2_25","action":"update","data":[{"symbol":"XBTUSDT","id":32402511466,"side":"Buy","size":62000,"price":66727.1,"timestamp":"2024-05-18T15:46:19.812Z"},{"symbol":"XBTUSDT","id":32402510311,"side":"Buy","size":16000,"price":66761.2,"timestamp":"2024-05-18T15:46:19.812Z"}]}
{"table":"orderBookL2_25","action":"insert","data":[{"symbol":"XBTUSDT","id":32402511770,"side":"Buy","size":8000,"price":66761.4,"timestamp":"2024-05-18T15:46:19.812Z"}]}
{"table":"orderBookL2_25","action":"delete","data":[{"symbol":"ETHUSDT","id":32402510992,"side":"Buy","price":3108.83,"timestamp":"2024-05-18T15:46:19.864Z"}]}
{"table":"orderBookL2_25","action":"insert","data":[{"symbol":"ETHUSDT","id":32402511947,"side":"Buy","size":32000,"price":3108.85,"timestamp":"2024-05-18T15:46:19.864Z"}]}
{"table":"orderBookL2_25","action":"delete","data":[{"symbol":"XBTUSDT","id":32402511669,"side":"Buy","price":66747.1,"timestamp":"2024-05-18T15:46:19.911Z"}]}
{"table":"orderBookL2_25","action":"insert","data":[{"symbol":"XBTUSDT","id":32402512002,"side":"Buy","size":20000,"price":66747.0,"timestamp":"2024-05-18T15:46:19.911Z"}]}
{"table":"orderBookL2_25","action":"delete","data":[{"symbol":"ETHUSDT","id":32402511713,"side":"Sell","price":3110.44,"timestamp":"2024-05-18T15:46:19.914Z"},{"symbol":"ETHUSDT","id":32402505932,"side":"Sell","price":3112.60,"timestamp":"2024-05-18T15:46:19.914Z"},{"symbol":"ETHUSDT","id":32402511947,"side":"Buy","price":3108.85,"timestamp":"2024-05-18T15:46:19.914Z"}]}
{"table":"orderBookL2_25","action":"insert","data":[{"symbol":"ETHUSDT","id":32402511949,"side":"Sell","size":32000,"price":3110.42,"timestamp":"2024-05-18T15:46:19.914Z"},{"symbol":"ETHUSDT","id":32402511995,"side":"Sell","size":2000,"price":3109.35,"timestamp":"2024-05-18T15:46:19.914Z"},{"symbol":"ETHUSDT","id":32402512006,"side":"Buy","size":32000,"price":3108.83,"timestamp":"2024-05-18T15:46:19.914Z"}]}
{"table":"orderBookL2_25","action":"delete","data":[{"symbol":"XBTUSDT","id":32402511243,"side":"Sell","price":66779.9,"timestamp":"2024-05-18T15:46:19.960Z"},{"symbol":"XBTUSDT","id":32402511498,"side":"Buy","price":66747.2,"timestamp":"2024-05-18T15:46:19.960Z"}]}
{"table":"orderBookL2_25","action":"insert","data":[{"symbol":"XBTUSDT","id":32402512015,"side":"Sell","size":3000,"price":66785.5,"timestamp":"2024-05-18T15:46:19.960Z"},{"symbol":"XBTUSDT","id":32402512004,"side":"Buy","size":20000,"price":66746.9,"timestamp":"2024-05-18T15:46:19.960Z"}]}
{"table":"orderBookL2_25","action":"delete","data":[{"symbol":"ETHUSDT","id":32402511949,"side":"Sell","price":3110.42,"timestamp":"2024-05-18T15:46:19.963Z"},{"symbol":"ETHUSDT","id":32402511995,"side":"Sell","price":3109.35,"timestamp":"2024-05-18T15:46:19.963Z"},{"symbol":"ETHUSDT","id":32402511227,"side":"Buy","price":3107.00,"timestamp":"2024-05-18T15:46:19.963Z"}]}
{"table":"orderBookL2_25","action":"update","data":[{"symbol":"ETHUSDT","id":32402488716,"side":"Sell","size":100000,"price":3112.18,"timestamp":"2024-05-18T15:46:19.963Z"}]}
{"table":"orderBookL2_25","action":"insert","data":[{"symbol":"ETHUSDT","id":32402512010,"side":"Sell","size":32000,"price":3110.44,"timestamp":"2024-05-18T15:46:19.963Z"},{"symbol":"ETHUSDT","id":32402505932,"side":"Sell","size":1000,"price":3112.60,"timestamp":"2024-05-18T15:46:19.963Z"},{"symbol":"ETHUSDT","id":32402512025,"side":"Buy","size":1159000,"price":3107.04,"timestamp":"2024-05-18T15:46:19.963Z"}]}
{"table":"orderBookL2_25","action":"delete","data":[{"symbol":"XBTUSDT","id":32402511662,"side":"Sell","price":66774.9,"timestamp":"2024-05-18T15:46:20.009Z"},{"symbol":"XBTUSDT","id":32402511458,"side":"Sell","price":66771.8,"timestamp":"2024-05-18T15:46:20.009Z"},{"symbol":"XBTUSDT","id":32402511053,"side":"Sell","price":66782.3,"timestamp":"2024-05-18T15:46:20.009Z"},{"symbol":"XBTUSDT","id":32402510203,"side":"Buy","price":66754.2,"timestamp":"2024-05-18T15:46:20.009Z"},{"symbol":"XBTUSDT","id":32402512004,"side":"Buy","price":66746.9,"timestamp":"2024-05-18T15:46:20.009Z"}]}
{"table":"orderBookL2_25","action":"insert","data":[{"symbol":"XBTUSDT","id":32402512299,"side":"Sell","size":1000,"price":66782.1,"timestamp":"2024-05-18T15:46:20.009Z"},{"symbol":"XBTUSDT","id":32402512261,"side":"Sell","size":156000,"price":66769.2,"timestamp":"2024-05-18T15:46:20.009Z"},{"symbol":"XBTUSDT","id":32402512302,"side":"Sell","size":20000,"price":66775.1,"timestamp":"2024-05-18T15:46:20.009Z"},{"symbol":"XBTUSDT","id":32402511349,"side":"Buy","size":100000,"price":66727.0,"timestamp":"2024-05-18T15:46:20.009Z"},{"symbol":"XBTUSDT","id":32402512295,"side":"Buy","size":20000,"price":66747.1,"timestamp":"2024-05-18T15:46:20.009Z"}]}
{"table":"orderBookL2_25","action":"delete","data":[{"symbol":"ETHUSDT","id":32402511725,"side":"Sell","price":3110.43,"timestamp":"2024-05-18T15:46:20.012Z"},{"symbol":"ETHUSDT","id":32402509402,"side":"Sell","price":3112.01,"timestamp":"2024-05-18T15:46:20.012Z"},{"symbol":"ETHUSDT","id":32402512010,"side":"Sell","price":3110.44,"timestamp":"2024-05-18T15:46:20.012Z"},{"symbol":"ETHUSDT","id":32402487481,"side":"Sell","price":3111.10,"timestamp":"2024-05-18T15:46:20.012Z"},{"symbol":"ETHUSDT","id":32402510944,"side":"Buy","price":3108.60,"timestamp":"2024-05-18T15:46:20.012Z"},{"symbol":"ETHUSDT","id":32401854083,"side":"Buy","price":3107.72,"timestamp":"2024-05-18T15:46:20.012Z"},{"symbol":"ETHUSDT","id":32402512006,"side":"Buy","price":3108.83,"timestamp":"2024-05-18T15:46:20.012Z"}]}
{"table":"orderBookL2_25","action":"update","data":[{"symbol":"ETHUSDT","id":32402506878,"side":"Buy","size":160000,"price":3107.03,"timestamp":"2024-05-18T15:46:20.012Z"},{"symbol":"ETHUSDT","id":32402509151,"side":"Buy","size":21000,"price":3108.58,"timestamp":"2024-05-18T15:46:20.012Z"}]}
{"table":"orderBookL2_25","action":"insert","data":[{"symbol":"ETHUSDT","id":32402512266,"side":"Sell","size":100000,"price":3111.04,"timestamp":"2024-05-18T15:46:20.012Z"},{"symbol":"ETHUSDT","id":32402512217,"side":"Sell","size":32000,"price":3110.43,"timestamp":"2024-05-18T15:46:20.012Z"},{"symbol":"ETHUSDT","id":32402512198,"side":"Sell","size":32000,"price":3110.42,"timestamp":"2024-05-18T15:46:20.012Z"},{"symbol":"ETHUSDT","id":32402512148,"side":"Sell","size":532000,"price":3111.48,"timestamp":"2024-05-18T15:46:20.012Z"},{"symbol":"ETHUSDT","id":32402512223,"side":"Buy","size":62000,"price":3107.25,"timestamp":"2024-05-18T15:46:20.012Z"},{"symbol":"ETHUSDT","id":32402512215,"side":"Buy","size":32000,"price":3108.85,"timestamp":"2024-05-18T15:46:20.012Z"},{"symbol":"ETHUSDT","id":32402511227,"side":"Buy","size":1126000,"price":3107.00,"timestamp":"2024-05-18T15:46:20.012Z"}]}
{"table":"orderBookL2_25","action":"delete","data":[{"symbol":"XBTETH","id":32402426628,"side":"Buy","price":21.055,"timestamp":"2024-05-18T15:46:20.029Z"}]}
{"table":"orderBookL2_25","action":"insert","data":[{"symbol":"XBTETH","id":32402512374,"side":"Buy","size":7,"price":21.050,"timestamp":"2024-05-18T15:46:20.029Z"}]}
{"table":"orderBookL2_25","action":"delete","data":[{"symbol":"XBTUSDT","id":32402511191,"side":"Sell","price":66775.0,"timestamp":"2024-05-18T15:46:20.058Z"},{"symbol":"XBTUSDT","id":32402512302,"side":"Sell","price":66775.1,"timestamp":"2024-05-18T15:46:20.058Z"},{"symbol":"XBTUSDT","id":32402511677,"side":"Sell","price":66779.5,"timestamp":"2024-05-18T15:46:20.058Z"},{"symbol":"XBTUSDT","id":32402511500,"side":"Sell","price":66776.0,"timestamp":"2024-05-18T15:46:20.058Z"},{"symbol":"XBTUSDT","id":32402509998,"side":"Sell","price":66776.1,"timestamp":"2024-05-18T15:46:20.058Z"},{"symbol":"XBTUSDT","id":32402512002,"side":"Buy","price":66747.0,"timestamp":"2024-05-18T15:46:20.058Z"},{"symbol":"XBTUSDT","id":32402512295,"side":"Buy","price":66747.1,"timestamp":"2024-05-18T15:46:20.058Z"},{"symbol":"XBTUSDT","id":32402510860,"side":"Buy","price":66736.4,"timestamp":"2024-05-18T15:46:20.058Z"},{"symbol":"XBTUSDT","id":32402510906,"side":"Buy","price":66736.5,"timestamp":"2024-05-18T15:46:20.058Z"}]}
{"table":"orderBookL2_25","action":"update","data":[{"symbol":"XBTUSDT","id":32402511161,"side":"Sell","size":347000,"price":66771.9,"timestamp":"2024-05-18T15:46:20.058Z"}]}
{"table":"orderBookL2_25","action":"insert","data":[{"symbol":"XBTUSDT","id":32402512443,"side":"Sell","size":20000,"price":66775.0,"timestamp":"2024-05-18T15:46:20.058Z"},{"symbol":"XBTUSDT","id":32402499271,"side":"Sell","size":100000,"price":66788.7,"timestamp":"2024-05-18T15:46:20.058Z"},{"symbol":"XBTUSDT","id":32402507340,"side":"Sell","size":2000,"price":66790.3,"timestamp":"2024-05-18T15:46:20.058Z"},{"symbol":"XBTUSDT","id":32402512008,"side":"Sell","size":68000,"price":66788.6,"timestamp":"2024-05-18T15:46:20.058Z"},{"symbol":"XBTUSDT","id":32402512353,"side":"Sell","size":20000,"price":66774.9,"timestamp":"2024-05-18T15:46:20.058Z"},{"symbol":"XBTUSDT","id":32402512433,"side":"Buy","size":20000,"price":66746.8,"timestamp":"2024-05-18T15:46:20.058Z"},{"symbol":"XBTUSDT","id":32402512465,"side":"Buy","size":20000,"price":66746.5,"timestamp":"2024-05-18T15:46:20.058Z"},{"symbol":"XBTUSDT","id":32402512394,"side":"Buy","size":357000,"price":66736.6,"timestamp":"2024-05-18T15:46:20.058Z"},{"symbol":"XBTUSDT","id":32401547573,"side":"Buy","size":100000,"price":66723.1,"timestamp":"2024-05-18T15:46:20.058Z"}]}
{"table":"orderBookL2_25","action":"delete","data":[{"symbol":"ETHUSDT","id":32402505932,"side":"Sell","price":3112.60,"timestamp":"2024-05-18T15:46:20.061Z"},{"symbol":"ETHUSDT","id":32402512217,"side":"Sell","price":3110.43,"timestamp":"2024-05-18T15:46:20.061Z"},{"symbol":"ETHUSDT","id":32402488716,"side":"Sell","price":3112.18,"timestamp":"2024-05-18T15:46:20.061Z"},{"symbol":"ETHUSDT","id":32402509644,"side":"Sell","price":3110.85,"timestamp":"2024-05-18T15:46:20.061Z"},{"symbol":"ETHUSDT","id":32402455680,"side":"Sell","price":3112.02,"timestamp":"2024-05-18T15:46:20.061Z"},{"symbol":"ETHUSDT","id":32402512198,"side":"Sell","price":3110.42,"timestamp":"2024-05-18T15:46:20.061Z"},{"symbol":"ETHUSDT","id":32402508833,"side":"Buy","price":3108.57,"timestamp":"2024-05-18T15:46:20.061Z"},{"symbol":"ETHUSDT","id":32402509889,"side":"Buy","price":3108.86,"timestamp":"2024-05-18T15:46:20.061Z"},{"symbol":"ETHUSDT","id":32402512223,"side":"Buy","price":3107.25,"timestamp":"2024-05-18T15:46:20.061Z"},{"symbol":"ETHUSDT","id":32402510998,"side":"Buy","price":3108.39,"timestamp":"2024-05-18T15:46:20.061Z"},{"symbol":"ETHUSDT","id":32402512215,"side":"Buy","price":3108.85,"timestamp":"2024-05-18T15:46:20.061Z"},{"symbol":"ETHUSDT","id":32402510510,"side":"Buy","price":3107.73,"timestamp":"2024-05-18T15:46:20.061Z"},{"symbol":"ETHUSDT","id":32402508646,"side":"Buy","price":3108.22,"timestamp":"2024-05-18T15:46:20.061Z"},{"symbol":"ETHUSDT","id":32402511051,"side":"Buy","price":3108.59,"timestamp":"2024-05-18T15:46:20.061Z"},{"symbol":"ETHUSDT","id":32402511738,"side":"Buy","price":3107.49,"timestamp":"2024-05-18T15:46:20.061Z"},{"symbol":"ETHUSDT","id":32402510660,"side":"Buy","price":3108.38,"timestamp":"2024-05-18T15:46:20.061Z"},{"symbol":"ETHUSDT","id":32402511089,"side":"Buy","price":3108.84,"timestamp":"2024-05-18T15:46:20.061Z"}]}
{"table":"orderBookL2_25","action":"update","data":[{"symbol":"ETHUSDT","id":32402511735,"side":"Sell","size":75000,"price":3110.34,"timestamp":"2024-05-18T15:46:20.061Z"},{"symbol":"ETHUSDT","id":32402493850,"side":"Sell","size":100000,"price":3111.81,"timestamp":"2024-05-18T15:46:20.061Z"},{"symbol":"ETHUSDT","id":32402509151,"side":"Buy","size":1000,"price":3108.58,"timestamp":"2024-05-18T15:46:20.061Z"}]}
{"table":"orderBookL2_25","action":"insert","data":[{"symbol":"ETHUSDT","id":32402512327,"side":"Sell","size":63000,"price":3109.50,"timestamp":"2024-05-18T15:46:20.061Z"},{"symbol":"ETHUSDT","id":32402512368,"side":"Sell","size":28000,"price":3109.71,"timestamp":"2024-05-18T15:46:20.061Z"},{"symbol":"ETHUSDT","id":32402512336,"side":"Sell","size":160000,"price":3110.55,"timestamp":"2024-05-18T15:46:20.061Z"},{"symbol":"ETHUSDT","id":32402512454,"side":"Sell","size":32000,"price":3110.33,"timestamp":"2024-05-18T15:46:20.061Z"},{"symbol":"ETHUSDT","id":32402512407,"side":"Sell","size":24000,"price":3110.35,"timestamp":"2024-05-18T15:46:20.061Z"},{"symbol":"ETHUSDT","id":32402512343,"side":"Sell","size":100000,"price":3109.35,"timestamp":"2024-05-18T15:46:20.061Z"},{"symbol":"ETHUSDT","id":32402504834,"side":"Buy","size":1620000,"price":3106.40,"timestamp":"2024-05-18T15:46:20.061Z"},{"symbol":"ETHUSDT","id":32402505366,"side":"Buy","size":100000,"price":3106.92,"timestamp":"2024-05-18T15:46:20.061Z"},{"symbol":"ETHUSDT","id":32402505928,"side":"Buy","size":100000,"price":3106.12,"timestamp":"2024-05-18T15:46:20.061Z"},{"symbol":"ETHUSDT","id":32402505870,"side":"Buy","size":100000,"price":3106.28,"timestamp":"2024-05-18T15:46:20.061Z"},{"symbol":"ETHUSDT","id":32402512420,"side":"Buy","size":552000,"price":3107.25,"timestamp":"2024-05-18T15:46:20.061Z"},{"symbol":"ETHUSDT","id":32402494460,"side":"Buy","size":1114000,"price":3106.20,"timestamp":"2024-05-18T15:46:20.061Z"},{"symbol":"ETHUSDT","id":32402512458,"side":"Buy","size":32000,"price":3108.83,"timestamp":"2024-05-18T15:46:20.061Z"},{"symbol":"ETHUSDT","id":32402504254,"side":"Buy","size":2300000,"price":3106.99,"timestamp":"2024-05-18T15:46:20.061Z"},{"symbol":"ETHUSDT","id":32402512411,"side":"Buy","size":1000,"price":3108.59,"timestamp":"2024-05-18T15:46:20.061Z"},{"symbol":"ETHUSDT","id":32402512448,"side":"Buy","size":32000,"price":3108.84,"timestamp":"2024-05-18T15:46:20.061Z"},{"symbol":"ETHUSDT","id":32402354519,"side":"Buy","size":100000,"price":3106.60,"timestamp":"2024-05-18T15:46:20.061Z"}]}
{"table":"orderBookL2_25","action":"delete","data":[{"symbol":"XBTETH","id":32402426636,"side":"Sell","price":21.958,"timestamp":"2024-05-18T15:46:20.078Z"}]}
{"table":"orderBookL2_25","action":"insert","data":[{"symbol":"XBTETH","id":32402512376,"side":"Sell","size":7,"price":21.954,"timestamp":"2024-05-18T15:46:20.078Z"}]}
{"table":"orderBookL2_25","action":"delete","data":[{"symbol":"XBTUSDT","id":32402511628,"side":"Sell","price":66782.2,"timestamp":"2024-05-18T15:46:20.107Z"},{"symbol":"XBTUSDT","id":32402512299,"side":"Sell","price":66782.1,"timestamp":"2024-05-18T15:46:20.107Z"},{"symbol":"XBTUSDT","id":32402511507,"side":"Sell","price":66786.6,"timestamp":"2024-05-18T15:46:20.107Z"},{"symbol":"XBTUSDT","id":32402512433,"side":"Buy","price":66746.8,"timestamp":"2024-05-18T15:46:20.107Z"},{"symbol":"XBTUSDT","id":32401547573,"side":"Buy","price":66723.1,"timestamp":"2024-05-18T15:46:20.107Z"}]}
{"table":"orderBookL2_25","action":"insert","data":[{"symbol":"XBTUSDT","id":32402512535,"side":"Sell","size":1000,"price":66782.2,"timestamp":"2024-05-18T15:46:20.107Z"},{"symbol":"XBTUSDT","id":32402512505,"side":"Sell","size":3000,"price":66783.9,"timestamp":"2024-05-18T15:46:20.107Z"},{"symbol":"XBTUSDT","id":32402512580,"side":"Sell","size":1000,"price":66782.1,"timestamp":"2024-05-18T15:46:20.107Z"},{"symbol":"XBTUSDT","id":32402512526,"side":"Buy","size":100000,"price":66754.2,"timestamp":"2024-05-18T15:46:20.107Z"},{"symbol":"XBTUSDT","id":32402512472,"side":"Buy","size":20000,"price":66746.6,"timestamp":"2024-05-18T15:46:20.107Z"}]}
{"table":"orderBookL2_25","action":"delete","data":[{"symbol":"ETHUSDT","id":32402510256,"side":"Sell","price":3109.87,"timestamp":"2024-05-18T15:46:20.110Z"},{"symbol":"ETHUSDT","id":32402512454,"side":"Sell","price":3110.33,"timestamp":"2024-05-18T15:46:20.110Z"},{"symbol":"ETHUSDT","id":32402493850,"side":"Sell","price":3111.81,"timestamp":"2024-05-18T15:46:20.110Z"},{"symbol":"ETHUSDT","id":32402512458,"side":"Buy","price":3108.83,"timestamp":"2024-05-18T15:46:20.110Z"},{"symbol":"ETHUSDT","id":32402512411,"side":"Buy","price":3108.59,"timestamp":"2024-05-18T15:46:20.110Z"},{"symbol":"ETHUSDT","id":32402509151,"side":"Buy","price":3108.58,"timestamp":"2024-05-18T15:46:20.110Z"},{"symbol":"ETHUSDT","id":32402512448,"side":"Buy","price":3108.84,"timestamp":"2024-05-18T15:46:20.110Z"}]}
{"table":"orderBookL2_25","action":"update","data":[{"symbol":"ETHUSDT","id":32402511735,"side":"Sell","size":43000,"price":3110.34,"timestamp":"2024-05-18T15:46:20.110Z"},{"symbol":"ETHUSDT","id":32402510230,"side":"Sell","size":100000,"price":3109.51,"timestamp":"2024-05-18T15:46:20.110Z"},{"symbol":"ETHUSDT","id":32402512343,"side":"Sell","size":103000,"price":3109.35,"timestamp":"2024-05-18T15:46:20.110Z"}]}
{"table":"orderBookL2_25","action":"insert","data":[{"symbol":"ETHUSDT","id":32402512548,"side":"Sell","size":32000,"price":3110.31,"timestamp":"2024-05-18T15:46:20.110Z"},{"symbol":"ETHUSDT","id":32402512591,"side":"Sell","size":32000,"price":3110.27,"timestamp":"2024-05-18T15:46:20.110Z"},{"symbol":"ETHUSDT","id":32402512587,"side":"Sell","size":21000,"price":3109.34,"timestamp":"2024-05-18T15:46:20.110Z"},{"symbol":"ETHUSDT","id":32402512539,"side":"Buy","size":1000,"price":3108.56,"timestamp":"2024-05-18T15:46:20.110Z"},{"symbol":"ETHUSDT","id":32402512570,"side":"Buy","size":32000,"price":3108.81,"timestamp":"2024-05-18T15:46:20.110Z"},{"symbol":"ETHUSDT","id":32402512623,"side":"Buy","size":1000,"price":3108.55,"timestamp":"2024-05-18T15:46:20.110Z"},{"symbol":"ETHUSDT","id":32402512595,"side":"Buy","size":32000,"price":3108.80,"timestamp":"2024-05-18T15:46:20.110Z"}]}
{"table":"orderBookL2_25","action":"delete","data":[{"symbol":"XBTUSDT","id":32402511161,"side":"Sell","price":66771.9,"timestamp":"2024-05-18T15:46:20.156Z"},{"symbol":"XBTUSDT","id":32402512353,"side":"Sell","price":66774.9,"timestamp":"2024-05-18T15:46:20.156Z"},{"symbol":"XBTUSDT","id":32402512580,"side":"Sell","price":66782.1,"timestamp":"2024-05-18T15:46:20.156Z"},{"symbol":"XBTUSDT","id":32402512465,"side":"Buy","price":66746.5,"timestamp":"2024-05-18T15:46:20.156Z"},{"symbol":"XBTUSDT","id":32402511349,"side":"Buy","price":66727.0,"timestamp":"2024-05-18T15:46:20.156Z"},{"symbol":"XBTUSDT","id":32402512472,"side":"Buy","price":66746.6,"timestamp":"2024-05-18T15:46:20.156Z"}]}
{"table":"orderBookL2_25","action":"update","data":[{"symbol":"XBTUSDT","id":32402506378,"side":"Sell","size":337000,"price":66764.5,"timestamp":"2024-05-18T15:46:20.156Z"},{"symbol":"XBTUSDT","id":32402511337,"side":"Buy","size":16000,"price":66761.3,"timestamp":"2024-05-18T15:46:20.156Z"},{"symbol":"XBTUSDT","id":32402510311,"side":"Buy","size":8000,"price":66761.2,"timestamp":"2024-05-18T15:46:20.156Z"}]}
{"table":"orderBookL2_25","action":"insert","data":[{"symbol":"XBTUSDT","id":32402512692,"side":"Sell","size":1000,"price":66782.3,"timestamp":"2024-05-18T15:46:20.156Z"},{"symbol":"XBTUSDT","id":32402512728,"side":"Sell","size":347000,"price":66771.7,"timestamp":"2024-05-18T15:46:20.156Z"},{"symbol":"XBTUSDT","id":32402512730,"side":"Sell","size":20000,"price":66774.7,"timestamp":"2024-05-18T15:46:20.156Z"},{"symbol":"XBTUSDT","id":32402512715,"side":"Buy","size":20000,"price":66746.6,"timestamp":"2024-05-18T15:46:20.156Z"},{"symbol":"XBTUSDT","id":32402512659,"side":"Buy","size":223000,"price":66736.7,"timestamp":"2024-05-18T15:46:20.156Z"},{"symbol":"XBTUSDT","id":32402512750,"side":"Buy","size":20000,"price":66746.5,"timestamp":"2024-05-18T15:46:20.156Z"}]}
{"table":"orderBookL2_25","action":"delete","data":[{"symbol":"ETHUSDT","id":32402512548,"side":"Sell","price":3110.31,"timestamp":"2024-05-18T15:46:20.159Z"},{"symbol":"ETHUSDT","id":32402486025,"side":"Sell","price":3111.72,"timestamp":"2024-05-18T15:46:20.159Z"},{"symbol":"ETHUSDT","id":32402512591,"side":"Sell","price":3110.27,"timestamp":"2024-05-18T15:46:20.159Z"},{"symbol":"ETHUSDT","id":32402512623,"side":"Buy","price":3108.55,"timestamp":"2024-05-18T15:46:20.159Z"}]}
{"table":"orderBookL2_25","action":"update","data":[{"symbol":"ETHUSDT","id":32402512587,"side":"Sell","size":24000,"price":3109.34,"timestamp":"2024-05-18T15:46:20.159Z"},{"symbol":"ETHUSDT","id":32402512343,"side":"Sell","size":100000,"price":3109.35,"timestamp":"2024-05-18T15:46:20.159Z"},{"symbol":"ETHUSDT","id":32402512570,"side":"Buy","size":75000,"price":3108.81,"timestamp":"2024-05-18T15:46:20.159Z"}]}
{"table":"orderBookL2_25","action":"insert","data":[{"symbol":"ETHUSDT","id":32402512758,"side":"Sell","size":32000,"price":3110.19,"timestamp":"2024-05-18T15:46:20.159Z"},{"symbol":"ETHUSDT","id":32402512627,"side":"Sell","size":100000,"price":3109.98,"timestamp":"2024-05-18T15:46:20.159Z"},{"symbol":"ETHUSDT","id":32402512649,"side":"Sell","size":32000,"price":3110.17,"timestamp":"2024-05-18T15:46:20.159Z"},{"symbol":"ETHUSDT","id":32402512769,"side":"Buy","size":1000,"price":3108.58,"timestamp":"2024-05-18T15:46:20.159Z"}]}
{"table":"orderBookL2_25","action":"delete","data":[{"symbol":"XBTUSDT","id":32402512443,"side":"Sell","price":66775.0,"timestamp":"2024-05-18T15:46:20.205Z"},{"symbol":"XBTUSDT","id":32402512730,"side":"Sell","price":66774.7,"timestamp":"2024-05-18T15:46:20.205Z"},{"symbol":"XBTUSDT","id":32402512715,"side":"Buy","price":66746.6,"timestamp":"2024-05-18T15:46:20.205Z"},{"symbol":"XBTUSDT","id":32402512750,"side":"Buy","price":66746.5,"timestamp":"2024-05-18T15:46:20.205Z"}]}
{"table":"orderBookL2_25","action":"update","data":[{"symbol":"XBTUSDT","id":32402504528,"side":"Sell","size":16000,"price":66780.1,"timestamp":"2024-05-18T15:46:20.205Z"}]}
{"table":"orderBookL2_25","action":"insert","data":[{"symbol":"XBTUSDT","id":32402512792,"side":"Sell","size":20000,"price":66775.0,"timestamp":"2024-05-18T15:46:20.205Z"},{"symbol":"XBTUSDT","id":32402512789,"side":"Sell","size":20000,"price":66774.9,"timestamp":"2024-05-18T15:46:20.205Z"},{"symbol":"XBTUSDT","id":32402512827,"side":"Buy","size":20000,"price":66746.3,"timestamp":"2024-05-18T15:46:20.205Z"},{"symbol":"XBTUSDT","id":32402512829,"side":"Buy","size":20000,"price":66746.4,"timestamp":"2024-05-18T15:46:20.205Z"}]}
{"table":"orderBookL2_25","action":"delete","data":[{"symbol":"ETHUSDT","id":32402512649,"side":"Sell","price":3110.17,"timestamp":"2024-05-18T15:46:20.208Z"},{"symbol":"ETHUSDT","id":32402504834,"side":"Buy","price":3106.40,"timestamp":"2024-05-18T15:46:20.208Z"},{"symbol":"ETHUSDT","id":32402512539,"side":"Buy","price":3108.56,"timestamp":"2024-05-18T15:46:20.208Z"},{"symbol":"ETHUSDT","id":32402494460,"side":"Buy","price":3106.20,"timestamp":"2024-05-18T15:46:20.208Z"},{"symbol":"ETHUSDT","id":32402505928,"side":"Buy","price":3106.12,"timestamp":"2024-05-18T15:46:20.208Z"},{"symbol":"ETHUSDT","id":32402505870,"side":"Buy","price":3106.28,"timestamp":"2024-05-18T15:46:20.208Z"},{"symbol":"ETHUSDT","id":32402512595,"side":"Buy","price":3108.80,"timestamp":"2024-05-18T15:46:20.208Z"}]}
{"table":"orderBookL2_25","action":"update","data":[{"symbol":"ETHUSDT","id":32402512570,"side":"Buy","size":43000,"price":3108.81,"timestamp":"2024-05-18T15:46:20.208Z"}]}
{"table":"orderBookL2_25","action":"insert","data":[{"symbol":"ETHUSDT","id":32402512783,"side":"Sell","size":32000,"price":3110.18,"timestamp":"2024-05-18T15:46:20.208Z"},{"symbol":"ETHUSDT","id":32402512832,"side":"Buy","size":1000,"price":3108.59,"timestamp":"2024-05-18T15:46:20.208Z"},{"symbol":"ETHUSDT","id":32402512834,"side":"Buy","size":336000,"price":3107.26,"timestamp":"2024-05-18T15:46:20.208Z"},{"symbol":"ETHUSDT","id":32402512812,"side":"Buy","size":32000,"price":3108.82,"timestamp":"2024-05-18T15:46:20.208Z"},{"symbol":"ETHUSDT","id":32402512804,"side":"Buy","size":100000,"price":3108.17,"timestamp":"2024-05-18T15:46:20.208Z"},{"symbol":"ETHUSDT","id":32402512818,"side":"Buy","size":64000,"price":3108.18,"timestamp":"2024-05-18T15:46:20.208Z"},{"symbol":"ETHUSDT","id":32402512820,"side":"Buy","size":32000,"price":3108.83,"timestamp":"2024-05-18T15:46:20.208Z"}]}
{"table":"orderBookL2_25","action":"delete","data":[{"symbol":"XBTUSDT","id":32402512728,"side":"Sell","price":66771.7,"timestamp":"2024-05-18T15:46:20.254Z"},{"symbol":"XBTUSDT","id":32402512792,"side":"Sell","price":66775.0,"timestamp":"2024-05-18T15:46:20.254Z"},{"symbol":"XBTUSDT","id":32402512827,"side":"Buy","price":66746.3,"timestamp":"2024-05-18T15:46:20.254Z"},{"symbol":"XBTUSDT","id":32402512829,"side":"Buy","price":66746.4,"timestamp":"2024-05-18T15:46:20.254Z"},{"symbol":"XBTUSDT","id":32402512394,"side":"Buy","price":66736.6,"timestamp":"2024-05-18T15:46:20.254Z"},{"symbol":"XBTUSDT","id":32402512659,"side":"Buy","price":66736.7,"timestamp":"2024-05-18T15:46:20.254Z"}]}
{"table":"orderBookL2_25","action":"update","data":[{"symbol":"XBTUSDT","id":32402507340,"side":"Sell","size":2000,"price":66790.3,"timestamp":"2024-05-18T15:46:20.254Z"},{"symbol":"XBTUSDT","id":32402505821,"side":"Buy","size":46000,"price":66764.4,"timestamp":"2024-05-18T15:46:20.254Z"}]}
{"table":"orderBookL2_25","action":"insert","data":[{"symbol":"XBTUSDT","id":32402512916,"side":"Sell","size":20000,"price":66775.0,"timestamp":"2024-05-18T15:46:20.254Z"},{"symbol":"XBTUSDT","id":32402512884,"side":"Sell","size":375000,"price":66774.7,"timestamp":"2024-05-18T15:46:20.254Z"},{"symbol":"XBTUSDT","id":32402511349,"side":"Buy","size":100000,"price":66727.0,"timestamp":"2024-05-18T15:46:20.254Z"},{"symbol":"XBTUSDT","id":32402512907,"side":"Buy","size":20000,"price":66746.5,"timestamp":"2024-05-18T15:46:20.254Z"},{"symbol":"XBTUSDT","id":32402512850,"side":"Buy","size":360000,"price":66736.3,"timestamp":"2024-05-18T15:46:20.254Z"},{"symbol":"XBTUSDT","id":32402512912,"side":"Buy","size":20000,"price":66746.6,"timestamp":"2024-05-18T15:46:20.254Z"}]}
{"table":"orderBookL2_25","action":"delete","data":[{"symbol":"ETHUSDT","id":32402512758,"side":"Sell","price":3110.19,"timestamp":"2024-05-18T15:46:20.257Z"},{"symbol":"ETHUSDT","id":32402512783,"side":"Sell","price":3110.18,"timestamp":"2024-05-18T15:46:20.257Z"},{"symbol":"ETHUSDT","id":32402354519,"side":"Buy","price":3106.60,"timestamp":"2024-05-18T15:46:20.257Z"}]}
{"table":"orderBookL2_25","action":"insert","data":[{"symbol":"ETHUSDT","id":32402512941,"side":"Sell","size":32000,"price":3110.21,"timestamp":"2024-05-18T15:46:20.257Z"},{"symbol":"ETHUSDT","id":32402512939,"side":"Sell","size":32000,"price":3110.20,"timestamp":"2024-05-18T15:46:20.257Z"},{"symbol":"ETHUSDT","id":32402512914,"side":"Buy","size":2000,"price":3108.40,"timestamp":"2024-05-18T15:46:20.257Z"}]}
{"table":"orderBookL2_25","action":"delete","data":[{"symbol":"ETHUSDT","id":32402512914,"side":"Buy","price":3108.40,"timestamp":"2024-05-18T15:46:20.306Z"}]}
{"table":"orderBookL2_25","action":"update","data":[{"symbol":"ETHUSDT","id":32402512570,"side":"Buy","size":91000,"price":3108.81,"timestamp":"2024-05-18T15:46:20.306Z"}]}
{"table":"orderBookL2_25","action":"insert","data":[{"symbol":"ETHUSDT","id":32402354519,"side":"Buy","size":100000,"price":3106.60,"timestamp":"2024-05-18T15:46:20.306Z"}]}
{"table":"orderBookL2_25","action":"delete","data":[{"symbol":"XBTUSDT","id":32402504861,"side":"Buy","price":66744.0,"timestamp":"2024-05-18T15:46:20.341Z"}]}
{"table":"orderBookL2_25","action":"insert","data":[{"symbol":"XBTUSDT","id":32401547573,"side":"Buy","size":100000,"price":66723.1,"timestamp":"2024-05-18T15:46:20.341Z"}]}
{"table":"orderBookL2_25","action":"delete","data":[{"symbol":"ETHUSDT","id":32402512832,"side":"Buy","price":3108.59,"timestamp":"2024-05-18T15:46:20.364Z"}]}
{"table":"orderBookL2_25","action":"insert","data":[{"symbol":"ETHUSDT","id":32402513067,"side":"Buy","size":1000,"price":3108.57,"timestamp":"2024-05-18T15:46:20.364Z"}]}
{"table":"orderBookL2_25","action":"delete","data":[{"symbol":"XBTUSDT","id":32402512916,"side":"Sell","price":66775.0,"timestamp":"2024-05-18T15:46:20.391Z"},{"symbol":"XBTUSDT","id":32402507340,"side":"Sell","price":66790.3,"timestamp":"2024-05-18T15:46:20.391Z"},{"symbol":"XBTUSDT","id":32402499236,"side":"Sell","price":66786.7,"timestamp":"2024-05-18T15:46:20.391Z"},{"symbol":"XBTUSDT","id":32402511005,"side":"Buy","price":66744.1,"timestamp":"2024-05-18T15:46:20.391Z"},{"symbol":"XBTUSDT","id":32402512912,"side":"Buy","price":66746.6,"timestamp":"2024-05-18T15:46:20.391Z"},{"symbol":"XBTUSDT","id":32401547573,"side":"Buy","price":66723.1,"timestamp":"2024-05-18T15:46:20.391Z"}]}
{"table":"orderBookL2_25","action":"update","data":[{"symbol":"XBTUSDT","id":32402506378,"side":"Sell","size":338000,"price":66764.5,"timestamp":"2024-05-18T15:46:20.391Z"},{"symbol":"XBTUSDT","id":32402499271,"side":"Sell","size":100000,"price":66788.7,"timestamp":"2024-05-18T15:46:20.391Z"},{"symbol":"XBTUSDT","id":32402511349,"side":"Buy","size":100000,"price":66727.0,"timestamp":"2024-05-18T15:46:20.391Z"}]}
{"table":"orderBookL2_25","action":"insert","data":[{"symbol":"XBTUSDT","id":32402513064,"side":"Sell","size":20000,"price":66774.8,"timestamp":"2024-05-18T15:46:20.391Z"},{"symbol":"XBTUSDT","id":32402513025,"side":"Sell","size":11000,"price":66767.4,"timestamp":"2024-05-18T15:46:20.391Z"},{"symbol":"XBTUSDT","id":32402513029,"side":"Sell","size":123000,"price":66771.9,"timestamp":"2024-05-18T15:46:20.391Z"},{"symbol":"XBTUSDT","id":32402513031,"side":"Buy","size":218000,"price":66736.4,"timestamp":"2024-05-18T15:46:20.391Z"},{"symbol":"XBTUSDT","id":32402513115,"side":"Buy","size":100000,"price":66744.0,"timestamp":"2024-05-18T15:46:20.391Z"},{"symbol":"XBTUSDT","id":32402513069,"side":"Buy","size":20000,"price":66746.4,"timestamp":"2024-05-18T15:46:20.391Z"}]}
{"table":"orderBookL2_25","action":"delete","data":[{"symbol":"ETHUSDT","id":32402512327,"side":"Sell","price":3109.50,"timestamp":"2024-05-18T15:46:20.414Z"},{"symbol":"ETHUSDT","id":32402512941,"side":"Sell","price":3110.21,"timestamp":"2024-05-18T15:46:20.414Z"},{"symbol":"ETHUSDT","id":32402512939,"side":"Sell","price":3110.20,"timestamp":"2024-05-18T15:46:20.414Z"},{"symbol":"ETHUSDT","id":32402510230,"side":"Sell","price":3109.51,"timestamp":"2024-05-18T15:46:20.414Z"},{"symbol":"ETHUSDT","id":32402513067,"side":"Buy","price":3108.57,"timestamp":"2024-05-18T15:46:20.414Z"}]}
{"table":"orderBookL2_25","action":"update","data":[{"symbol":"ETHUSDT","id":32402512587,"side":"Sell","size":3000,"price":3109.34,"timestamp":"2024-05-18T15:46:20.414Z"},{"symbol":"ETHUSDT","id":32402487305,"side":"Sell","size":100000,"price":3111.65,"timestamp":"2024-05-18T15:46:20.414Z"},{"symbol":"ETHUSDT","id":32402512820,"side":"Buy","size":273000,"price":3108.83,"timestamp":"2024-05-18T15:46:20.414Z"}]}
{"table":"orderBookL2_25","action":"insert","data":[{"symbol":"ETHUSDT","id":32402513124,"side":"Sell","size":32000,"price":3110.18,"timestamp":"2024-05-18T15:46:20.414Z"},{"symbol":"ETHUSDT","id":32402486025,"side":"Sell","size":337000,"price":3111.72,"timestamp":"2024-05-18T15:46:20.414Z"},{"symbol":"ETHUSDT","id":32402513134,"side":"Sell","size":32000,"price":3110.19,"timestamp":"2024-05-18T15:46:20.414Z"},{"symbol":"ETHUSDT","id":32402513117,"side":"Sell","size":80000,"price":3109.33,"timestamp":"2024-05-18T15:46:20.414Z"},{"symbol":"ETHUSDT","id":32402513113,"side":"Buy","size":1000,"price":3108.57,"timestamp":"2024-05-18T15:46:20.414Z"}]}
{"table":"orderBookL2_25","action":"delete","data":[{"symbol":"XBTUSDT","id":32402511349,"side":"Buy","price":66727.0,"timestamp":"2024-05-18T15:46:20.441Z"}]}
{"table":"orderBookL2_25","action":"insert","data":[{"symbol":"XBTUSDT","id":32402513180,"side":"Buy","size":156000,"price":66734.0,"timestamp":"2024-05-18T15:46:20.441Z"}]}
{"table":"orderBookL2_25","action":"delete","data":[{"symbol":"ETHUSDT","id":32402512587,"side":"Sell","price":3109.34,"timestamp":"2024-05-18T15:46:20.463Z"}]}
{"table":"orderBookL2_25","action":"update","data":[{"symbol":"ETHUSDT","id":32402513117,"side":"Sell","size":83000,"price":3109.33,"timestamp":"2024-05-18T15:46:20.463Z"}]}
{"table":"orderBookL2_25","action":"insert","data":[{"symbol":"ETHUSDT","id":32402513182,"side":"Sell","size":446000,"price":3109.65,"timestamp":"2024-05-18T15:46:20.463Z"}]}
{"table":"orderBookL2_25","action":"delete","data":[{"symbol":"XBTUSDT","id":32402499271,"side":"Sell","price":66788.7,"timestamp":"2024-05-18T15:46:20.490Z"},{"symbol":"XBTUSDT","id":32402511037,"side":"Buy","price":66733.9,"timestamp":"2024-05-18T15:46:20.490Z"}]}
{"table":"orderBookL2_25","action":"update","data":[{"symbol":"XBTUSDT","id":32402506378,"side":"Sell","size":346000,"price":66764.5,"timestamp":"2024-05-18T15:46:20.490Z"},{"symbol":"XBTUSDT","id":32402504528,"side":"Sell","size":8000,"price":66780.1,"timestamp":"2024-05-18T15:46:20.490Z"}]}
{"table":"orderBookL2_25","action":"insert","data":[{"symbol":"XBTUSDT","id":32402513233,"side":"Sell","size":8000,"price":66767.3,"timestamp":"2024-05-18T15:46:20.490Z"},{"symbol":"XBTUSDT","id":32402513220,"side":"Buy","size":65000,"price":66744.1,"timestamp":"2024-05-18T15:46:20.490Z"}]}
{"table":"orderBookL2_25","action":"delete","data":[{"symbol":"ETHUSDT","id":32402484839,"side":"Sell","price":3111.49,"timestamp":"2024-05-18T15:46:20.512Z"},{"symbol":"ETHUSDT","id":32402486025,"side":"Sell","price":3111.72,"timestamp":"2024-05-18T15:46:20.512Z"},{"symbol":"ETHUSDT","id":32402487305,"side":"Sell","price":3111.65,"timestamp":"2024-05-18T15:46:20.512Z"},{"symbol":"ETHUSDT","id":32402513113,"side":"Buy","price":3108.57,"timestamp":"2024-05-18T15:46:20.512Z"}]}
{"table":"orderBookL2_25","action":"insert","data":[{"symbol":"ETHUSDT","id":32402513255,"side":"Sell","size":1087000,"price":3110.73,"timestamp":"2024-05-18T15:46:20.512Z"},{"symbol":"ETHUSDT","id":32402513259,"side":"Sell","size":100000,"price":3109.23,"timestamp":"2024-05-18T15:46:20.512Z"},{"symbol":"ETHUSDT","id":32402513257,"side":"Sell","size":68000,"price":3109.97,"timestamp":"2024-05-18T15:46:20.512Z"},{"symbol":"ETHUSDT","id":32402513252,"side":"Buy","size":1000,"price":3108.59,"timestamp":"2024-05-18T15:46:20.512Z"}]}
{"table":"orderBookL2_25","action":"delete","data":[{"symbol":"XBTUSDT","id":32402512692,"side":"Sell","price":66782.3,"timestamp":"2024-05-18T15:46:20.539Z"}]}
{"table":"orderBookL2_25","action":"insert","data":[{"symbol":"XBTUSDT","id":32402513262,"side":"Sell","size":1000,"price":66782.1,"timestamp":"2024-05-18T15:46:20.539Z"}]}
{"table":"orderBookL2_25","action":"delete","data":[{"symbol":"ETHUSDT","id":32402512368,"side":"Sell","price":3109.71,"timestamp":"2024-05-18T15:46:20.561Z"},{"symbol":"ETHUSDT","id":32402513257,"side":"Sell","price":3109.97,"timestamp":"2024-05-18T15:46:20.561Z"},{"symbol":"ETHUSDT","id":32402513117,"side":"Sell","price":3109.33,"timestamp":"2024-05-18T15:46:20.561Z"},{"symbol":"ETHUSDT","id":32402512343,"side":"Sell","price":3109.35,"timestamp":"2024-05-18T15:46:20.561Z"},{"symbol":"ETHUSDT","id":32402513252,"side":"Buy","price":3108.59,"timestamp":"2024-05-18T15:46:20.561Z"},{"symbol":"ETHUSDT","id":32402354519,"side":"Buy","price":3106.60,"timestamp":"2024-05-18T15:46:20.561Z"}]}
{"table":"orderBookL2_25","action":"update","data":[{"symbol":"ETHUSDT","id":32402513259,"side":"Sell","size":103000,"price":3109.23,"timestamp":"2024-05-18T15:46:20.561Z"},{"symbol":"ETHUSDT","id":32402512148,"side":"Sell","size":532000,"price":3111.48,"timestamp":"2024-05-18T15:46:20.561Z"},{"symbol":"ETHUSDT","id":32402494493,"side":"Sell","size":100000,"price":3111.26,"timestamp":"2024-05-18T15:46:20.561Z"}]}
{"table":"orderBookL2_25","action":"insert","data":[{"symbol":"ETHUSDT","id":32402484839,"side":"Sell","size":100000,"price":3111.49,"timestamp":"2024-05-18T15:46:20.561Z"},{"symbol":"ETHUSDT","id":32402513307,"side":"Sell","size":100000,"price":3109.21,"timestamp":"2024-05-18T15:46:20.561Z"},{"symbol":"ETHUSDT","id":32402513289,"side":"Sell","size":33000,"price":3109.22,"timestamp":"2024-05-18T15:46:20.561Z"},{"symbol":"ETHUSDT","id":32402513297,"side":"Sell","size":28000,"price":3109.58,"timestamp":"2024-05-18T15:46:20.561Z"},{"symbol":"ETHUSDT","id":32402513303,"side":"Buy","size":2000,"price":3108.98,"timestamp":"2024-05-18T15:46:20.561Z"},{"symbol":"ETHUSDT","id":32402513282,"side":"Buy","size":1000,"price":3108.57,"timestamp":"2024-05-18T15:46:20.561Z"}]}
{"table":"orderBookL2_25","action":"delete","data":[{"symbol":"XBTUSDT","id":32402512015,"side":"Sell","price":66785.5,"timestamp":"2024-05-18T15:46:20.588Z"},{"symbol":"XBTUSDT","id":32402513069,"side":"Buy","price":66746.4,"timestamp":"2024-05-18T15:46:20.588Z"},{"symbol":"XBTUSDT","id":32402512907,"side":"Buy","price":66746.5,"timestamp":"2024-05-18T15:46:20.588Z"}]}
{"table":"orderBookL2_25","action":"insert","data":[{"symbol":"XBTUSDT","id":32402513321,"side":"Sell","size":3000,"price":66774.3,"timestamp":"2024-05-18T15:46:20.588Z"},{"symbol":"XBTUSDT","id":32402513319,"side":"Buy","size":20000,"price":66746.9,"timestamp":"2024-05-18T15:46:20.588Z"},{"symbol":"XBTUSDT","id":32402513325,"side":"Buy","size":20000,"price":66746.8,"timestamp":"2024-05-18T15:46:20.588Z"}]}
{"table":"orderBookL2_25","action":"delete","data":[{"symbol":"ETHUSDT","id":32402484839,"side":"Sell","price":3111.49,"timestamp":"2024-05-18T15:46:20.610Z"},{"symbol":"ETHUSDT","id":32402494493,"side":"Sell","price":3111.26,"timestamp":"2024-05-18T15:46:20.610Z"},{"symbol":"ETHUSDT","id":32402512148,"side":"Sell","price":3111.48,"timestamp":"2024-05-18T15:46:20.610Z"},{"symbol":"ETHUSDT","id":32402513303,"side":"Buy","price":3108.98,"timestamp":"2024-05-18T15:46:20.610Z"}]}
{"table":"orderBookL2_25","action":"update","data":[{"symbol":"ETHUSDT","id":32402513307,"side":"Sell","size":103000,"price":3109.21,"timestamp":"2024-05-18T15:46:20.610Z"},{"symbol":"ETHUSDT","id":32402513259,"side":"Sell","size":100000,"price":3109.23,"timestamp":"2024-05-18T15:46:20.610Z"}]}
{"table":"orderBookL2_25","action":"insert","data":[{"symbol":"ETHUSDT","id":32402513390,"side":"Sell","size":62000,"price":3110.27,"timestamp":"2024-05-18T15:46:20.610Z"},{"symbol":"ETHUSDT","id":32402513388,"side":"Sell","size":21000,"price":3109.20,"timestamp":"2024-05-18T15:46:20.610Z"},{"symbol":"ETHUSDT","id":32402513386,"side":"Sell","size":97000,"price":3110.54,"timestamp":"2024-05-18T15:46:20.610Z"},{"symbol":"ETHUSDT","id":32402354519,"side":"Buy","size":100000,"price":3106.60,"timestamp":"2024-05-18T15:46:20.610Z"}]}
{"table":"orderBookL2_25","action":"delete","data":[{"symbol":"XBTUSDT","id":32402512505,"side":"Sell","price":66783.9,"timestamp":"2024-05-18T15:46:20.637Z"},{"symbol":"XBTUSDT","id":32402512884,"side":"Sell","price":66774.7,"timestamp":"2024-05-18T15:46:20.637Z"},{"symbol":"XBTUSDT","id":32402513064,"side":"Sell","price":66774.8,"timestamp":"2024-05-18T15:46:20.637Z"},{"symbol":"XBTUSDT","id":32402513029,"side":"Sell","price":66771.9,"timestamp":"2024-05-18T15:46:20.637Z"},{"symbol":"XBTUSDT","id":32402511466,"side":"Buy","price":66727.1,"timestamp":"2024-05-18T15:46:20.637Z"},{"symbol":"XBTUSDT","id":32402510029,"side":"Buy","price":66730.1,"timestamp":"2024-05-18T15:46:20.637Z"},{"symbol":"XBTUSDT","id":32402513325,"side":"Buy","price":66746.8,"timestamp":"2024-05-18T15:46:20.637Z"}]}
{"table":"orderBookL2_25","action":"insert","data":[{"symbol":"XBTUSDT","id":32402499271,"side":"Sell","size":100000,"price":66788.7,"timestamp":"2024-05-18T15:46:20.637Z"},{"symbol":"XBTUSDT","id":32402513426,"side":"Sell","size":20000,"price":66775.0,"timestamp":"2024-05-18T15:46:20.637Z"},{"symbol":"XBTUSDT","id":32402513384,"side":"Sell","size":3000,"price":66780.9,"timestamp":"2024-05-18T15:46:20.637Z"},{"symbol":"XBTUSDT","id":32402513453,"side":"Sell","size":351000,"price":66771.8,"timestamp":"2024-05-18T15:46:20.637Z"},{"symbol":"XBTUSDT","id":32402513421,"side":"Buy","size":20000,"price":66747.0,"timestamp":"2024-05-18T15:46:20.637Z"},{"symbol":"XBTUSDT","id":32402513430,"side":"Buy","size":100000,"price":66734.1,"timestamp":"2024-05-18T15:46:20.637Z"},{"symbol":"XBTUSDT","id":32402513460,"side":"Buy","size":67000,"price":66730.5,"timestamp":"2024-05-18T15:46:20.637Z"}]}
{"table":"orderBookL2_25","action":"delete","data":[{"symbol":"ETHUSDT","id":32402513282,"side":"Buy","price":3108.57,"timestamp":"2024-05-18T15:46:20.674Z"}]}
{"table":"orderBookL2_25","action":"insert","data":[{"symbol":"ETHUSDT","id":32402513522,"side":"Buy","size":1000,"price":3108.59,"timestamp":"2024-05-18T15:46:20.674Z"}]}
{"table":"orderBookL2_25","action":"delete","data":[{"symbol":"XBTUSDT","id":32402499271,"side":"Sell","price":66788.7,"timestamp":"2024-05-18T15:46:20.686Z"},{"symbol":"XBTUSDT","id":32402513453,"side":"Sell","price":66771.8,"timestamp":"2024-05-18T15:46:20.686Z"}]}
{"table":"orderBookL2_25","action":"update","data":[{"symbol":"XBTUSDT","id":32402506378,"side":"Sell","size":348000,"price":66764.5,"timestamp":"2024-05-18T15:46:20.686Z"}]}
{"table":"orderBookL2_25","action":"insert","data":[{"symbol":"XBTUSDT","id":32402513518,"side":"Sell","size":128000,"price":66771.9,"timestamp":"2024-05-18T15:46:20.686Z"},{"symbol":"XBTUSDT","id":32402513493,"side":"Sell","size":375000,"price":66774.7,"timestamp":"2024-05-18T15:46:20.686Z"}]}
{"table":"orderBookL2_25","action":"delete","data":[{"symbol":"ETHUSDT","id":32402512266,"side":"Sell","price":3111.04,"timestamp":"2024-05-18T15:46:20.723Z"},{"symbol":"ETHUSDT","id":32402513124,"side":"Sell","price":3110.18,"timestamp":"2024-05-18T15:46:20.723Z"},{"symbol":"ETHUSDT","id":32402513134,"side":"Sell","price":3110.19,"timestamp":"2024-05-18T15:46:20.723Z"}]}
{"table":"orderBookL2_25","action":"update","data":[{"symbol":"ETHUSDT","id":32402513289,"side":"Sell","size":59000,"price":3109.22,"timestamp":"2024-05-18T15:46:20.723Z"}]}
{"table":"orderBookL2_25","action":"insert","data":[{"symbol":"ETHUSDT","id":32402513566,"side":"Sell","size":23000,"price":3110.18,"timestamp":"2024-05-18T15:46:20.723Z"},{"symbol":"ETHUSDT","id":32402513562,"side":"Sell","size":32000,"price":3110.20,"timestamp":"2024-05-18T15:46:20.723Z"},{"symbol":"ETHUSDT","id":32402513560,"side":"Sell","size":32000,"price":3110.21,"timestamp":"2024-05-18T15:46:20.723Z"}]}
{"table":"orderBookL2_25","action":"delete","data":[{"symbol":"XBTUSDT","id":32402512008,"side":"Sell","price":66788.6,"timestamp":"2024-05-18T15:46:20.735Z"},{"symbol":"XBTUSDT","id":32402513426,"side":"Sell","price":66775.0,"timestamp":"2024-05-18T15:46:20.735Z"},{"symbol":"XBTUSDT","id":32402511319,"side":"Sell","price":66767.8,"timestamp":"2024-05-18T15:46:20.735Z"},{"symbol":"XBTUSDT","id":32402513421,"side":"Buy","price":66747.0,"timestamp":"2024-05-18T15:46:20.735Z"}]}
{"table":"orderBookL2_25","action":"update","data":[{"symbol":"XBTUSDT","id":32402502861,"side":"Sell","size":100000,"price":66784.3,"timestamp":"2024-05-18T15:46:20.735Z"}]}
{"table":"orderBookL2_25","action":"insert","data":[{"symbol":"XBTUSDT","id":32402513580,"side":"Sell","size":234000,"price":66774.6,"timestamp":"2024-05-18T15:46:20.735Z"},{"symbol":"XBTUSDT","id":32402513573,"side":"Sell","size":20000,"price":66774.8,"timestamp":"2024-05-18T15:46:20.735Z"},{"symbol":"XBTUSDT","id":32402513582,"side":"Sell","size":60000,"price":66778.4,"timestamp":"2024-05-18T15:46:20.735Z"},{"symbol":"XBTUSDT","id":32402513575,"side":"Buy","size":20000,"price":66746.8,"timestamp":"2024-05-18T15:46:20.735Z"}]}
{"table":"orderBookL2_25","action":"update","data":[{"symbol":"ETHUSDT","id":32402512570,"side":"Buy","size":115000,"price":3108.81,"timestamp":"2024-05-18T15:46:20.772Z"}]}
{"table":"orderBookL2_25","action":"delete","data":[{"symbol":"XBTUSDT","id":32402502861,"side":"Sell","price":66784.3,"timestamp":"2024-05-18T15:46:20.784Z"},{"symbol":"XBTUSDT","id":32402504528,"side":"Sell","price":66780.1,"timestamp":"2024-05-18T15:46:20.784Z"}]}
{"table":"orderBookL2_25","action":"update","data":[{"symbol":"XBTUSDT","id":32402513025,"side":"Sell","size":19000,"price":66767.4,"timestamp":"2024-05-18T15:46:20.784Z"}]}
{"table":"orderBookL2_25","action":"insert","data":[{"symbol":"XBTUSDT","id":32402513587,"side":"Sell","size":8000,"price":66767.2,"timestamp":"2024-05-18T15:46:20.784Z"},{"symbol":"XBTUSDT","id":32402513615,"side":"Sell","size":14000,"price":66781.7,"timestamp":"2024-05-18T15:46:20.784Z"}]}
{"table":"orderBookL2_25","action":"delete","data":[{"symbol":"XBTETH","id":32402422052,"side":"Sell","price":22.173,"timestamp":"2024-05-18T15:46:20.792Z"}]}
{"table":"orderBookL2_25","action":"insert","data":[{"symbol":"XBTETH","id":32402513671,"side":"Sell","size":110,"price":21.483,"timestamp":"2024-05-18T15:46:20.792Z"}]}
{"table":"orderBookL2_25","action":"delete","data":[{"symbol":"ETHUSDT","id":32402513562,"side":"Sell","price":3110.20,"timestamp":"2024-05-18T15:46:20.821Z"},{"symbol":"ETHUSDT","id":32402513560,"side":"Sell","price":3110.21,"timestamp":"2024-05-18T15:46:20.821Z"}]}
{"table":"orderBookL2_25","action":"update","data":[{"symbol":"ETHUSDT","id":32402513566,"side":"Sell","size":32000,"price":3110.18,"timestamp":"2024-05-18T15:46:20.821Z"}]}
{"table":"orderBookL2_25","action":"insert","data":[{"symbol":"ETHUSDT","id":32402512266,"side":"Sell","size":100000,"price":3111.04,"timestamp":"2024-05-18T15:46:20.821Z"},{"symbol":"ETHUSDT","id":32402513685,"side":"Sell","size":32000,"price":3110.19,"timestamp":"2024-05-18T15:46:20.821Z"}]}
{"table":"orderBookL2_25","action":"delete","data":[{"symbol":"XBTUSDT","id":32402513430,"side":"Buy","price":66734.1,"timestamp":"2024-05-18T15:46:20.833Z"},{"symbol":"XBTUSDT","id":32402513180,"side":"Buy","price":66734.0,"timestamp":"2024-05-18T15:46:20.833Z"},{"symbol":"XBTUSDT","id":32402513460,"side":"Buy","price":66730.5,"timestamp":"2024-05-18T15:46:20.833Z"}]}
{"table":"orderBookL2_25","action":"insert","data":[{"symbol":"XBTUSDT","id":32402511466,"side":"Buy","size":62000,"price":66727.1,"timestamp":"2024-05-18T15:46:20.833Z"},{"symbol":"XBTUSDT","id":32402510029,"side":"Buy","size":74000,"price":66730.1,"timestamp":"2024-05-18T15:46:20.833Z"},{"symbol":"XBTUSDT","id":32402513673,"side":"Buy","size":156000,"price":66734.2,"timestamp":"2024-05-18T15:46:20.833Z"}]}
{"table":"orderBookL2_25","action":"delete","data":[{"symbol":"XBTETH","id":32402427688,"side":"Sell","price":22.001,"timestamp":"2024-05-18T15:46:20.880Z"}]}
{"table":"orderBookL2_25","action":"insert","data":[{"symbol":"XBTETH","id":32402513779,"side":"Sell","size":7,"price":21.997,"timestamp":"2024-05-18T15:46:20.880Z"}]}
{"table":"orderBookL2_25","action":"delete","data":[{"symbol":"ETHUSDT","id":32402513522,"side":"Buy","price":3108.59,"timestamp":"2024-05-18T15:46:20.920Z"}]}
{"table":"orderBookL2_25","action":"insert","data":[{"symbol":"ETHUSDT","id":32402513812,"side":"Buy","size":1000,"price":3108.57,"timestamp":"2024-05-18T15:46:20.920Z"}]}
{"table":"orderBookL2_25","action":"delete","data":[{"symbol":"XBTETH","id":32402427691,"side":"Buy","price":21.012,"timestamp":"2024-05-18T15:46:20.929Z"}]}
{"table":"orderBookL2_25","action":"insert","data":[{"symbol":"XBTETH","id":32402513785,"side":"Buy","size":7,"price":21.007,"timestamp":"2024-05-18T15:46:20.929Z"}]}
{"table":"orderBookL2_25","action":"delete","data":[{"symbol":"ETHUSDT","id":32402512266,"side":"Sell","price":3111.04,"timestamp":"2024-05-18T15:46:20.970Z"}]}
{"table":"orderBookL2_25","action":"insert","data":[{"symbol":"ETHUSDT","id":32402513817,"side":"Sell","size":24000,"price":3110.17,"timestamp":"2024-05-18T15:46:20.970Z"}]}
{"table":"orderBookL2_25","action":"delete","data":[{"symbol":"XBTUSDT","id":32402510898,"side":"Sell","price":66769.3,"timestamp":"2024-05-18T15:46:20.998Z"}]}
{"table":"orderBookL2_25","action":"insert","data":[{"symbol":"XBTUSDT","id":32402502861,"side":"Sell","size":100000,"price":66784.3,"timestamp":"2024-05-18T15:46:20.998Z"}]}
{"table":"orderBookL2_25","action":"delete","data":[{"symbol":"ETHUSDT","id":32402354519,"side":"Buy","price":3106.60,"timestamp":"2024-05-18T15:46:21.029Z"}]}
{"table":"orderBookL2_25","action":"insert","data":[{"symbol":"ETHUSDT","id":32402513884,"side":"Buy","size":2000,"price":3108.98,"timestamp":"2024-05-18T15:46:21.029Z"}]}
{"table":"orderBookL2_25","action":"delete","data":[{"symbol":"XBTUSDT","id":32402513031,"side":"Buy","price":66736.4,"timestamp":"2024-05-18T15:46:21.048Z"},{"symbol":"XBTUSDT","id":32402510311,"side":"Buy","price":66761.2,"timestamp":"2024-05-18T15:46:21.048Z"}]}
{"table":"orderBookL2_25","action":"update","data":[{"symbol":"XBTUSDT","id":32402511770,"side":"Buy","size":16000,"price":66761.4,"timestamp":"2024-05-18T15:46:21.048Z"},{"symbol":"XBTUSDT","id":32402511466,"side":"Buy","size":62000,"price":66727.1,"timestamp":"2024-05-18T15:46:21.048Z"}]}
{"table":"orderBookL2_25","action":"insert","data":[{"symbol":"XBTUSDT","id":32402511349,"side":"Buy","size":100000,"price":66727.0,"timestamp":"2024-05-18T15:46:21.048Z"},{"symbol":"XBTUSDT","id":32402513876,"side":"Buy","size":638000,"price":66737.2,"timestamp":"2024-05-18T15:46:21.048Z"}]}
{"table":"orderBookL2_25","action":"delete","data":[{"symbol":"ETHUSDT","id":32402512627,"side":"Sell","price":3109.98,"timestamp":"2024-05-18T15:46:21.078Z"},{"symbol":"ETHUSDT","id":32402513817,"side":"Sell","price":3110.17,"timestamp":"2024-05-18T15:46:21.078Z"},{"symbol":"ETHUSDT","id":32402513388,"side":"Sell","price":3109.20,"timestamp":"2024-05-18T15:46:21.078Z"},{"symbol":"ETHUSDT","id":32402513884,"side":"Buy","price":3108.98,"timestamp":"2024-05-18T15:46:21.078Z"},{"symbol":"ETHUSDT","id":32402513812,"side":"Buy","price":3108.57,"timestamp":"2024-05-18T15:46:21.078Z"}]}
{"table":"orderBookL2_25","action":"insert","data":[{"symbol":"ETHUSDT","id":32402513961,"side":"Sell","size":21000,"price":3109.19,"timestamp":"2024-05-18T15:46:21.078Z"},{"symbol":"ETHUSDT","id":32402512266,"side":"Sell","size":100000,"price":3111.04,"timestamp":"2024-05-18T15:46:21.078Z"},{"symbol":"ETHUSDT","id":32402494493,"side":"Sell","size":100000,"price":3111.26,"timestamp":"2024-05-18T15:46:21.078Z"},{"symbol":"ETHUSDT","id":32402513918,"side":"Buy","size":1000,"price":3108.59,"timestamp":"2024-05-18T15:46:21.078Z"},{"symbol":"ETHUSDT","id":32402354519,"side":"Buy","size":100000,"price":3106.60,"timestamp":"2024-05-18T15:46:21.078Z"}]}
{"table":"orderBookL2_25","action":"delete","data":[{"symbol":"XBTUSDT","id":32402502861,"side":"Sell","price":66784.3,"timestamp":"2024-05-18T15:46:21.097Z"},{"symbol":"XBTUSDT","id":32402511349,"side":"Buy","price":66727.0,"timestamp":"2024-05-18T15:46:21.097Z"}]}
{"table":"orderBookL2_25","action":"insert","data":[{"symbol":"XBTUSDT","id":32402514037,"side":"Sell","size":20000,"price":66770.7,"timestamp":"2024-05-18T15:46:21.097Z"},{"symbol":"XBTUSDT","id":32402513945,"side":"Buy","size":100000,"price":66757.6,"timestamp":"2024-05-18T15:46:21.097Z"}]}
{"table":"orderBookL2_25","action":"delete","data":[{"symbol":"ETHUSDT","id":32402494493,"side":"Sell","price":3111.26,"timestamp":"2024-05-18T15:46:21.127Z"}]}
{"table":"orderBookL2_25","action":"insert","data":[{"symbol":"ETHUSDT","id":32402514078,"side":"Sell","size":100000,"price":3109.99,"timestamp":"2024-05-18T15:46:21.127Z"}]}
{"table":"orderBookL2_25","action":"delete","data":[{"symbol":"XBTUSDT","id":32402514037,"side":"Sell","price":66770.7,"timestamp":"2024-05-18T15:46:21.146Z"},{"symbol":"XBTUSDT","id":32402513319,"side":"Buy","price":66746.9,"timestamp":"2024-05-18T15:46:21.146Z"},{"symbol":"XBTUSDT","id":32402513575,"side":"Buy","price":66746.8,"timestamp":"2024-05-18T15:46:21.146Z"}]}
{"table":"orderBookL2_25","action":"insert","data":[{"symbol":"XBTUSDT","id":32402502861,"side":"Sell","size":100000,"price":66784.3,"timestamp":"2024-05-18T15:46:21.146Z"},{"symbol":"XBTUSDT","id":32402514096,"side":"Buy","size":20000,"price":66747.1,"timestamp":"2024-05-18T15:46:21.146Z"},{"symbol":"XBTUSDT","id":32402514098,"side":"Buy","size":20000,"price":66747.0,"timestamp":"2024-05-18T15:46:21.146Z"}]}
{"table":"orderBookL2_25","action":"delete","data":[{"symbol":"XBTUSDT","id":32402512261,"side":"Sell","price":66769.2,"timestamp":"2024-05-18T15:46:21.195Z"}]}
{"table":"orderBookL2_25","action":"update","data":[{"symbol":"XBTUSDT","id":32402502861,"side":"Sell","size":100000,"price":66784.3,"timestamp":"2024-05-18T15:46:21.195Z"}]}
{"table":"orderBookL2_25","action":"insert","data":[{"symbol":"XBTUSDT","id":32402514170,"side":"Sell","size":156000,"price":66771.8,"timestamp":"2024-05-18T15:46:21.195Z"}]}
{"table":"orderBookL2_25","action":"delete","data":[{"symbol":"XBTUSDT","id":32402502861,"side":"Sell","price":66784.3,"timestamp":"2024-05-18T15:46:21.244Z"},{"symbol":"XBTUSDT","id":32402513945,"side":"Buy","price":66757.6,"timestamp":"2024-05-18T15:46:21.244Z"}]}
{"table":"orderBookL2_25","action":"insert","data":[{"symbol":"XBTUSDT","id":32402514198,"side":"Sell","size":20000,"price":66770.8,"timestamp":"2024-05-18T15:46:21.244Z"},{"symbol":"XBTUSDT","id":32402511349,"side":"Buy","size":100000,"price":66727.0,"timestamp":"2024-05-18T15:46:21.244Z"}]}
{"table":"orderBookL2_25","action":"delete","data":[{"symbol":"ETHUSDT","id":32402513918,"side":"Buy","price":3108.59,"timestamp":"2024-05-18T15:46:21.290Z"}]}
{"table":"orderBookL2_25","action":"insert","data":[{"symbol":"ETHUSDT","id":32402514274,"side":"Buy","size":1000,"price":3108.57,"timestamp":"2024-05-18T15:46:21.290Z"}]}
{"table":"orderBookL2_25","action":"delete","data":[{"symbol":"XBTUSDT","id":32402513573,"side":"Sell","price":66774.8,"timestamp":"2024-05-18T15:46:21.293Z"},{"symbol":"XBTUSDT","id":32402513321,"side":"Sell","price":66774.3,"timestamp":"2024-05-18T15:46:21.293Z"},{"symbol":"XBTUSDT","id":32402514098,"side":"Buy","price":66747.0,"timestamp":"2024-05-18T15:46:21.293Z"}]}
{"table":"orderBookL2_25","action":"insert","data":[{"symbol":"XBTUSDT","id":32402514267,"side":"Sell","size":3000,"price":66777.9,"timestamp":"2024-05-18T15:46:21.293Z"},{"symbol":"XBTUSDT","id":32402514233,"side":"Sell","size":20000,"price":66775.0,"timestamp":"2024-05-18T15:46:21.293Z"},{"symbol":"XBTUSDT","id":32402514229,"side":"Buy","size":20000,"price":66747.2,"timestamp":"2024-05-18T15:46:21.293Z"}]}
{"table":"orderBookL2_25","action":"delete","data":[{"symbol":"XBTUSDT","id":32402513384,"side":"Sell","price":66780.9,"timestamp":"2024-05-18T15:46:21.342Z"},{"symbol":"XBTUSDT","id":32402514233,"side":"Sell","price":66775.0,"timestamp":"2024-05-18T15:46:21.342Z"},{"symbol":"XBTUSDT","id":32402514229,"side":"Buy","price":66747.2,"timestamp":"2024-05-18T15:46:21.342Z"}]}
{"table":"orderBookL2_25","action":"update","data":[{"symbol":"XBTUSDT","id":32402511708,"side":"Sell","size":105000,"price":66783.3,"timestamp":"2024-05-18T15:46:21.342Z"},{"symbol":"XBTUSDT","id":32402513025,"side":"Sell","size":11000,"price":66767.4,"timestamp":"2024-05-18T15:46:21.342Z"},{"symbol":"XBTUSDT","id":32402506723,"side":"Sell","size":159000,"price":66783.4,"timestamp":"2024-05-18T15:46:21.342Z"}]}
{"table":"orderBookL2_25","action":"insert","data":[{"symbol":"XBTUSDT","id":32402514306,"side":"Sell","size":8000,"price":66767.1,"timestamp":"2024-05-18T15:46:21.342Z"},{"symbol":"XBTUSDT","id":32402514311,"side":"Sell","size":20000,"price":66774.8,"timestamp":"2024-05-18T15:46:21.342Z"},{"symbol":"XBTUSDT","id":32402514308,"side":"Buy","size":20000,"price":66747.0,"timestamp":"2024-05-18T15:46:21.342Z"}]}
{"table":"orderBookL2_25","action":"delete","data":[{"symbol":"ETHUSDT","id":32402514274,"side":"Buy","price":3108.57,"timestamp":"2024-05-18T15:46:21.375Z"}]}
{"table":"orderBookL2_25","action":"insert","data":[{"symbol":"ETHUSDT","id":32402514357,"side":"Buy","size":1000,"price":3108.59,"timestamp":"2024-05-18T15:46:21.375Z"}]}
{"table":"orderBookL2_25","action":"delete","data":[{"symbol":"XBTUSDT","id":32402506723,"side":"Sell","price":66783.4,"timestamp":"2024-05-18T15:46:21.450Z"}]}
{"table":"orderBookL2_25","action":"insert","data":[{"symbol":"XBTUSDT","id":32402514422,"side":"Sell","size":8000,"price":66767.0,"timestamp":"2024-05-18T15:46:21.450Z"}]}
{"table":"orderBookL2_25","action":"delete","data":[{"symbol":"ETHUSDT","id":32402514357,"side":"Buy","price":3108.59,"timestamp":"2024-05-18T15:46:21.490Z"}]}
{"table":"orderBookL2_25","action":"insert","data":[{"symbol":"ETHUSDT","id":32402514465,"side":"Buy","size":1000,"price":3108.57,"timestamp":"2024-05-18T15:46:21.490Z"}]}
{"table":"orderBookL2_25","action":"delete","data":[{"symbol":"XBTUSDT","id":32402513587,"side":"Sell","price":66767.2,"timestamp":"2024-05-18T15:46:21.500Z"}]}
{"table":"orderBookL2_25","action":"insert","data":[{"symbol":"XBTUSDT","id":32402506723,"side":"Sell","size":159000,"price":66783.4,"timestamp":"2024-05-18T15:46:21.500Z"}]}
{"table":"orderBookL2_25","action":"delete","data":[{"symbol":"ETHUSDT","id":32402514465,"side":"Buy","price":3108.57,"timestamp":"2024-05-18T15:46:21.570Z"}]}
{"table":"orderBookL2_25","action":"insert","data":[{"symbol":"ETHUSDT","id":32402514509,"side":"Buy","size":1000,"price":3108.59,"timestamp":"2024-05-18T15:46:21.570Z"}]}
{"table":"orderBookL2_25","action":"delete","data":[{"symbol":"XBTUSDT","id":32402506723,"side":"Sell","price":66783.4,"timestamp":"2024-05-18T15:46:21.592Z"}]}
{"table":"orderBookL2_25","action":"insert","data":[{"symbol":"XBTUSDT","id":32402514522,"side":"Sell","size":156000,"price":66770.7,"timestamp":"2024-05-18T15:46:21.592Z"}]}
{"table":"orderBookL2_25","action":"delete","data":[{"symbol":"XBTUSDT","id":32402514170,"side":"Sell","price":66771.8,"timestamp":"2024-05-18T15:46:21.641Z"}]}
{"table":"orderBookL2_25","action":"insert","data":[{"symbol":"XBTUSDT","id":32402506723,"side":"Sell","size":159000,"price":66783.4,"timestamp":"2024-05-18T15:46:21.641Z"}]}
{"table":"orderBookL2_25","action":"delete","data":[{"symbol":"XBTETH","id":32402417548,"side":"Buy","price":20.969,"timestamp":"2024-05-18T15:46:21.653Z"}]}
{"table":"orderBookL2_25","action":"insert","data":[{"symbol":"XBTETH","id":32402514584,"side":"Buy","size":7,"price":20.964,"timestamp":"2024-05-18T15:46:21.653Z"}]}
{"table":"orderBookL2_25","action":"delete","data":[{"symbol":"XBTUSDT","id":32402513233,"side":"Sell","price":66767.3,"timestamp":"2024-05-18T15:46:21.690Z"}]}
{"table":"orderBookL2_25","action":"update","data":[{"symbol":"XBTUSDT","id":32402506723,"side":"Sell","size":159000,"price":66783.4,"timestamp":"2024-05-18T15:46:21.690Z"}]}
{"table":"orderBookL2_25","action":"insert","data":[{"symbol":"XBTUSDT","id":32402514608,"side":"Sell","size":8000,"price":66766.9,"timestamp":"2024-05-18T15:46:21.690Z"}]}
{"table":"orderBookL2_25","action":"delete","data":[{"symbol":"XBTETH","id":32402417798,"side":"Sell","price":22.044,"timestamp":"2024-05-18T15:46:21.703Z"}]}
{"table":"orderBookL2_25","action":"insert","data":[{"symbol":"XBTETH","id":32402514593,"side":"Sell","size":7,"price":22.040,"timestamp":"2024-05-18T15:46:21.703Z"}]}
{"table":"orderBookL2_25","action":"delete","data":[{"symbol":"ETHUSDT","id":32402514509,"side":"Buy","price":3108.59,"timestamp":"2024-05-18T15:46:21.721Z"}]}
{"table":"orderBookL2_25","action":"insert","data":[{"symbol":"ETHUSDT","id":32402514655,"side":"Buy","size":1000,"price":3108.57,"timestamp":"2024-05-18T15:46:21.721Z"}]}
{"table":"orderBookL2_25","action":"delete","data":[{"symbol":"XBTUSDT","id":32402512526,"side":"Buy","price":66754.2,"timestamp":"2024-05-18T15:46:21.739Z"}]}
{"table":"orderBookL2_25","action":"insert","data":[{"symbol":"XBTUSDT","id":32401547573,"side":"Buy","size":100000,"price":66723.1,"timestamp":"2024-05-18T15:46:21.739Z"}]}
{"table":"orderBookL2_25","action":"delete","data":[{"symbol":"ETHUSDT","id":32402512266,"side":"Sell","price":3111.04,"timestamp":"2024-05-18T15:46:21.771Z"},{"symbol":"ETHUSDT","id":32402514655,"side":"Buy","price":3108.57,"timestamp":"2024-05-18T15:46:21.771Z"}]}
{"table":"orderBookL2_25","action":"update","data":[{"symbol":"ETHUSDT","id":32402504489,"side":"Sell","size":49000,"price":3111.02,"timestamp":"2024-05-18T15:46:21.771Z"}]}
{"table":"orderBookL2_25","action":"insert","data":[{"symbol":"ETHUSDT","id":32402514676,"side":"Sell","size":241000,"price":3110.16,"timestamp":"2024-05-18T15:46:21.771Z"},{"symbol":"ETHUSDT","id":32402514671,"side":"Buy","size":1000,"price":3108.59,"timestamp":"2024-05-18T15:46:21.771Z"}]}
{"table":"orderBookL2_25","action":"delete","data":[{"symbol":"XBTUSDT","id":32402514267,"side":"Sell","price":66777.9,"timestamp":"2024-05-18T15:46:21.788Z"}]}
{"table":"orderBookL2_25","action":"insert","data":[{"symbol":"XBTUSDT","id":32402514712,"side":"Sell","size":3000,"price":66775.1,"timestamp":"2024-05-18T15:46:21.788Z"}]}
{"table":"orderBookL2_25","action":"delete","data":[{"symbol":"ETHUSDT","id":32402514671,"side":"Buy","price":3108.59,"timestamp":"2024-05-18T15:46:21.820Z"}]}
{"table":"orderBookL2_25","action":"insert","data":[{"symbol":"ETHUSDT","id":32402514721,"side":"Buy","size":1000,"price":3108.57,"timestamp":"2024-05-18T15:46:21.820Z"}]}
{"table":"orderBookL2_25","action":"delete","data":[{"symbol":"XBTUSDT","id":32402514422,"side":"Sell","price":66767.0,"timestamp":"2024-05-18T15:46:21.862Z"}]}
{"table":"orderBookL2_25","action":"insert","data":[{"symbol":"XBTUSDT","id":32402502861,"side":"Sell","size":100000,"price":66784.3,"timestamp":"2024-05-18T15:46:21.862Z"}]}
{"table":"orderBookL2_25","action":"delete","data":[{"symbol":"XBTUSDT","id":32402502861,"side":"Sell","price":66784.3,"timestamp":"2024-05-18T15:46:21.911Z"}]}
{"table":"orderBookL2_25","action":"insert","data":[{"symbol":"XBTUSDT","id":32402514769,"side":"Sell","size":8000,"price":66766.8,"timestamp":"2024-05-18T15:46:21.911Z"}]}
{"table":"orderBookL2_25","action":"delete","data":[{"symbol":"XBTUSDT","id":32402513493,"side":"Sell","price":66774.7,"timestamp":"2024-05-18T15:46:21.960Z"},{"symbol":"XBTUSDT","id":32402514306,"side":"Sell","price":66767.1,"timestamp":"2024-05-18T15:46:21.960Z"},{"symbol":"XBTUSDT","id":32402513580,"side":"Sell","price":66774.6,"timestamp":"2024-05-18T15:46:21.960Z"},{"symbol":"XBTUSDT","id":32401547573,"side":"Buy","price":66723.1,"timestamp":"2024-05-18T15:46:21.960Z"},{"symbol":"XBTUSDT","id":32402512850,"side":"Buy","price":66736.3,"timestamp":"2024-05-18T15:46:21.960Z"}]}
{"table":"orderBookL2_25","action":"update","data":[{"symbol":"XBTUSDT","id":32402514522,"side":"Sell","size":368000,"price":66770.7,"timestamp":"2024-05-18T15:46:21.960Z"},{"symbol":"XBTUSDT","id":32402513518,"side":"Sell","size":347000,"price":66771.9,"timestamp":"2024-05-18T15:46:21.960Z"}]}
{"table":"orderBookL2_25","action":"insert","data":[{"symbol":"XBTUSDT","id":32402502861,"side":"Sell","size":100000,"price":66784.3,"timestamp":"2024-05-18T15:46:21.960Z"},{"symbol":"XBTUSDT","id":32402514864,"side":"Sell","size":8000,"price":66766.7,"timestamp":"2024-05-18T15:46:21.960Z"},{"symbol":"XBTUSDT","id":32402512008,"side":"Sell","size":68000,"price":66788.6,"timestamp":"2024-05-18T15:46:21.960Z"},{"symbol":"XBTUSDT","id":32402514824,"side":"Buy","size":350000,"price":66737.3,"timestamp":"2024-05-18T15:46:21.960Z"},{"symbol":"XBTUSDT","id":32402514852,"side":"Buy","size":100000,"price":66754.2,"timestamp":"2024-05-18T15:46:21.960Z"}]}
{"table":"orderBookL2_25","action":"delete","data":[{"symbol":"XBTUSDT","id":32402512008,"side":"Sell","price":66788.6,"timestamp":"2024-05-18T15:46:22.037Z"}]}
{"table":"orderBookL2_25","action":"update","data":[{"symbol":"XBTUSDT","id":32402511708,"side":"Sell","size":102000,"price":66783.3,"timestamp":"2024-05-18T15:46:22.037Z"}]}
{"table":"orderBookL2_25","action":"insert","data":[{"symbol":"XBTUSDT","id":32402514910,"side":"Sell","size":3000,"price":66780.9,"timestamp":"2024-05-18T15:46:22.037Z"}]}
{"table":"orderBookL2_25","action":"delete","data":[{"symbol":"ETHUSDT","id":32402514721,"side":"Buy","price":3108.57,"timestamp":"2024-05-18T15:46:22.067Z"}]}
{"table":"orderBookL2_25","action":"insert","data":[{"symbol":"ETHUSDT","id":32402514949,"side":"Buy","size":1000,"price":3108.59,"timestamp":"2024-05-18T15:46:22.067Z"}]}
{"table":"orderBookL2_25","action":"delete","data":[{"symbol":"XBTUSDT","id":32402513518,"side":"Sell","price":66771.9,"timestamp":"2024-05-18T15:46:22.087Z"},{"symbol":"XBTUSDT","id":32402513673,"side":"Buy","price":66734.2,"timestamp":"2024-05-18T15:46:22.087Z"},{"symbol":"XBTUSDT","id":32402511349,"side":"Buy","price":66727.0,"timestamp":"2024-05-18T15:46:22.087Z"}]}
{"table":"orderBookL2_25","action":"update","data":[{"symbol":"XBTUSDT","id":32402514522,"side":"Sell","size":156000,"price":66770.7,"timestamp":"2024-05-18T15:46:22.087Z"},{"symbol":"XBTUSDT","id":32402511466,"side":"Buy","size":62000,"price":66727.1,"timestamp":"2024-05-18T15:46:22.087Z"}]}
{"table":"orderBookL2_25","action":"insert","data":[{"symbol":"XBTUSDT","id":32402514912,"side":"Sell","size":347000,"price":66771.8,"timestamp":"2024-05-18T15:46:22.087Z"},{"symbol":"XBTUSDT","id":32402514918,"side":"Buy","size":388000,"price":66737.4,"timestamp":"2024-05-18T15:46:22.087Z"},{"symbol":"XBTUSDT","id":32402514930,"side":"Buy","size":156000,"price":66736.3,"timestamp":"2024-05-18T15:46:22.087Z"}]}
{"table":"orderBookL2_25","action":"delete","data":[{"symbol":"ETHUSDT","id":32402514949,"side":"Buy","price":3108.59,"timestamp":"2024-05-18T15:46:22.116Z"}]}
{"table":"orderBookL2_25","action":"update","data":[{"symbol":"ETHUSDT","id":32402512570,"side":"Buy","size":67000,"price":3108.81,"timestamp":"2024-05-18T15:46:22.116Z"}]}
{"table":"orderBookL2_25","action":"insert","data":[{"symbol":"ETHUSDT","id":32402514957,"side":"Buy","size":1000,"price":3108.57,"timestamp":"2024-05-18T15:46:22.116Z"}]}
{"table":"orderBookL2_25","action":"delete","data":[{"symbol":"ETHUSDT","id":32402514957,"side":"Buy","price":3108.57,"timestamp":"2024-05-18T15:46:22.184Z"}]}
{"table":"orderBookL2_25","action":"insert","data":[{"symbol":"ETHUSDT","id":32402515017,"side":"Buy","size":1000,"price":3108.59,"timestamp":"2024-05-18T15:46:22.184Z"}]}
{"table":"orderBookL2_25","action":"delete","data":[{"symbol":"XBTUSDT","id":32402514769,"side":"Sell","price":66766.8,"timestamp":"2024-05-18T15:46:22.191Z"}]}
{"table":"orderBookL2_25","action":"insert","data":[{"symbol":"XBTUSDT","id":32402512008,"side":"Sell","size":68000,"price":66788.6,"timestamp":"2024-05-18T15:46:22.191Z"}]}
{"table":"orderBookL2_25","action":"delete","data":[{"symbol":"XBTUSDT","id":32402514912,"side":"Sell","price":66771.8,"timestamp":"2024-05-18T15:46:22.240Z"},{"symbol":"XBTUSDT","id":32402512008,"side":"Sell","price":66788.6,"timestamp":"2024-05-18T15:46:22.240Z"},{"symbol":"XBTUSDT","id":32402514608,"side":"Sell","price":66766.9,"timestamp":"2024-05-18T15:46:22.240Z"}]}
{"table":"orderBookL2_25","action":"update","data":[{"symbol":"XBTUSDT","id":32402514522,"side":"Sell","size":156000,"price":66770.7,"timestamp":"2024-05-18T15:46:22.240Z"}]}
{"table":"orderBookL2_25","action":"insert","data":[{"symbol":"XBTUSDT","id":32402515084,"side":"Sell","size":348000,"price":66771.9,"timestamp":"2024-05-18T15:46:22.240Z"},{"symbol":"XBTUSDT","id":32402515022,"side":"Sell","size":8000,"price":66766.6,"timestamp":"2024-05-18T15:46:22.240Z"},{"symbol":"XBTUSDT","id":32402515071,"side":"Sell","size":8000,"price":66766.8,"timestamp":"2024-05-18T15:46:22.240Z"}]}
{"table":"orderBookL2_25","action":"update","data":[{"symbol":"ETHUSDT","id":32402513307,"side":"Sell","size":3000,"price":3109.21,"timestamp":"2024-05-18T15:46:22.246Z"}]}
{"table":"orderBookL2_25","action":"delete","data":[{"symbol":"XBTUSDT","id":32402514824,"side":"Buy","price":66737.3,"timestamp":"2024-05-18T15:46:22.289Z"}]}
{"table":"orderBookL2_25","action":"insert","data":[{"symbol":"XBTUSDT","id":32402515163,"side":"Buy","size":348000,"price":66737.5,"timestamp":"2024-05-18T15:46:22.289Z"}]}
{"table":"orderBookL2_25","action":"delete","data":[{"symbol":"ETHUSDT","id":32402513289,"side":"Sell","price":3109.22,"timestamp":"2024-05-18T15:46:22.295Z"},{"symbol":"ETHUSDT","id":32402513685,"side":"Sell","price":3110.19,"timestamp":"2024-05-18T15:46:22.295Z"},{"symbol":"ETHUSDT","id":32402513259,"side":"Sell","price":3109.23,"timestamp":"2024-05-18T15:46:22.295Z"},{"symbol":"ETHUSDT","id":32402513566,"side":"Sell","price":3110.18,"timestamp":"2024-05-18T15:46:22.295Z"},{"symbol":"ETHUSDT","id":32402354519,"side":"Buy","price":3106.60,"timestamp":"2024-05-18T15:46:22.295Z"}]}
{"table":"orderBookL2_25","action":"insert","data":[{"symbol":"ETHUSDT","id":32402512266,"side":"Sell","size":100000,"price":3111.04,"timestamp":"2024-05-18T15:46:22.295Z"},{"symbol":"ETHUSDT","id":32402494493,"side":"Sell","size":100000,"price":3111.26,"timestamp":"2024-05-18T15:46:22.295Z"},{"symbol":"ETHUSDT","id":32402515137,"side":"Sell","size":32000,"price":3110.21,"timestamp":"2024-05-18T15:46:22.295Z"},{"symbol":"ETHUSDT","id":32402515126,"side":"Sell","size":32000,"price":3110.20,"timestamp":"2024-05-18T15:46:22.295Z"},{"symbol":"ETHUSDT","id":32402515154,"side":"Buy","size":100000,"price":3108.35,"timestamp":"2024-05-18T15:46:22.295Z"}]}
{"table":"orderBookL2_25","action":"delete","data":[{"symbol":"ETHUSDT","id":32402514078,"side":"Sell","price":3109.99,"timestamp":"2024-05-18T15:46:22.362Z"}]}
{"table":"orderBookL2_25","action":"insert","data":[{"symbol":"ETHUSDT","id":32402512148,"side":"Sell","size":532000,"price":3111.48,"timestamp":"2024-05-18T15:46:22.362Z"}]}
{"table":"orderBookL2_25","action":"delete","data":[{"symbol":"XBTUSDT","id":32402515163,"side":"Buy","price":66737.5,"timestamp":"2024-05-18T15:46:22.366Z"}]}
{"table":"orderBookL2_25","action":"insert","data":[{"symbol":"XBTUSDT","id":32402515343,"side":"Buy","size":354000,"price":66736.4,"timestamp":"2024-05-18T15:46:22.366Z"}]}
{"table":"orderBookL2_25","action":"delete","data":[{"symbol":"ETHUSDT","id":32402514676,"side":"Sell","price":3110.16,"timestamp":"2024-05-18T15:46:22.412Z"}]}
{"table":"orderBookL2_25","action":"update","data":[{"symbol":"ETHUSDT","id":32402512148,"side":"Sell","size":532000,"price":3111.48,"timestamp":"2024-05-18T15:46:22.412Z"}]}
{"table":"orderBookL2_25","action":"insert","data":[{"symbol":"ETHUSDT","id":32402515338,"side":"Sell","size":24000,"price":3109.57,"timestamp":"2024-05-18T15:46:22.412Z"}]}
{"table":"orderBookL2_25","action":"delete","data":[{"symbol":"XBTUSDT","id":32402515084,"side":"Sell","price":66771.9,"timestamp":"2024-05-18T15:46:22.415Z"},{"symbol":"XBTUSDT","id":32402514930,"side":"Buy","price":66736.3,"timestamp":"2024-05-18T15:46:22.415Z"},{"symbol":"XBTUSDT","id":32402515343,"side":"Buy","price":66736.4,"timestamp":"2024-05-18T15:46:22.415Z"}]}
{"table":"orderBookL2_25","action":"insert","data":[{"symbol":"XBTUSDT","id":32402515416,"side":"Sell","size":347000,"price":66771.9,"timestamp":"2024-05-18T15:46:22.415Z"},{"symbol":"XBTUSDT","id":32402515392,"side":"Buy","size":156000,"price":66736.5,"timestamp":"2024-05-18T15:46:22.415Z"},{"symbol":"XBTUSDT","id":32402515361,"side":"Buy","size":348000,"price":66737.5,"timestamp":"2024-05-18T15:46:22.415Z"}]}
{"table":"orderBookL2_25","action":"delete","data":[{"symbol":"ETHUSDT","id":32402513390,"side":"Sell","price":3110.27,"timestamp":"2024-05-18T15:46:22.461Z"},{"symbol":"ETHUSDT","id":32402515126,"side":"Sell","price":3110.20,"timestamp":"2024-05-18T15:46:22.461Z"},{"symbol":"ETHUSDT","id":32402509701,"side":"Sell","price":3110.28,"timestamp":"2024-05-18T15:46:22.461Z"},{"symbol":"ETHUSDT","id":32402512812,"side":"Buy","price":3108.82,"timestamp":"2024-05-18T15:46:22.461Z"}]}
{"table":"orderBookL2_25","action":"insert","data":[{"symbol":"ETHUSDT","id":32402515470,"side":"Sell","size":32000,"price":3110.22,"timestamp":"2024-05-18T15:46:22.461Z"},{"symbol":"ETHUSDT","id":32402484839,"side":"Sell","size":100000,"price":3111.49,"timestamp":"2024-05-18T15:46:22.461Z"},{"symbol":"ETHUSDT","id":32402487305,"side":"Sell","size":100000,"price":3111.65,"timestamp":"2024-05-18T15:46:22.461Z"},{"symbol":"ETHUSDT","id":32402515484,"side":"Buy","size":32000,"price":3108.84,"timestamp":"2024-05-18T15:46:22.461Z"}]}
{"table":"orderBookL2_25","action":"delete","data":[{"symbol":"XBTUSDT","id":32402515416,"side":"Sell","price":66771.9,"timestamp":"2024-05-18T15:46:22.464Z"},{"symbol":"XBTUSDT","id":32402514198,"side":"Sell","price":66770.8,"timestamp":"2024-05-18T15:46:22.464Z"},{"symbol":"XBTUSDT","id":32402513262,"side":"Sell","price":66782.1,"timestamp":"2024-05-18T15:46:22.464Z"}]}
{"table":"orderBookL2_25","action":"insert","data":[{"symbol":"XBTUSDT","id":32402515468,"side":"Sell","size":129000,"price":66771.8,"timestamp":"2024-05-18T15:46:22.464Z"},{"symbol":"XBTUSDT","id":32402515461,"side":"Sell","size":375000,"price":66774.7,"timestamp":"2024-05-18T15:46:22.464Z"},{"symbol":"XBTUSDT","id":32402515454,"side":"Sell","size":1000,"price":66782.3,"timestamp":"2024-05-18T15:46:22.464Z"}]}
{"table":"orderBookL2_25","action":"delete","data":[{"symbol":"XBTETH","id":32402419432,"side":"Buy","price":20.926,"timestamp":"2024-05-18T15:46:22.466Z"}]}
{"table":"orderBookL2_25","action":"insert","data":[{"symbol":"XBTETH","id":32402515501,"side":"Buy","size":7,"price":20.921,"timestamp":"2024-05-18T15:46:22.466Z"}]}
{"table":"orderBookL2_25","action":"delete","data":[{"symbol":"ETHUSDT","id":32402513386,"side":"Sell","price":3110.54,"timestamp":"2024-05-18T15:46:22.510Z"},{"symbol":"ETHUSDT","id":32402515470,"side":"Sell","price":3110.22,"timestamp":"2024-05-18T15:46:22.510Z"},{"symbol":"ETHUSDT","id":32402515137,"side":"Sell","price":3110.21,"timestamp":"2024-05-18T15:46:22.510Z"},{"symbol":"ETHUSDT","id":32402512148,"side":"Sell","price":3111.48,"timestamp":"2024-05-18T15:46:22.510Z"},{"symbol":"ETHUSDT","id":32402513961,"side":"Sell","price":3109.19,"timestamp":"2024-05-18T15:46:22.510Z"},{"symbol":"ETHUSDT","id":32402513297,"side":"Sell","price":3109.58,"timestamp":"2024-05-18T15:46:22.510Z"},{"symbol":"ETHUSDT","id":32402512336,"side":"Sell","price":3110.55,"timestamp":"2024-05-18T15:46:22.510Z"},{"symbol":"ETHUSDT","id":32402515338,"side":"Sell","price":3109.57,"timestamp":"2024-05-18T15:46:22.510Z"},{"symbol":"ETHUSDT","id":32402513307,"side":"Sell","price":3109.21,"timestamp":"2024-05-18T15:46:22.510Z"},{"symbol":"ETHUSDT","id":32402515484,"side":"Buy","price":3108.84,"timestamp":"2024-05-18T15:46:22.510Z"},{"symbol":"ETHUSDT","id":32402512834,"side":"Buy","price":3107.26,"timestamp":"2024-05-18T15:46:22.510Z"},{"symbol":"ETHUSDT","id":32402512420,"side":"Buy","price":3107.25,"timestamp":"2024-05-18T15:46:22.510Z"},{"symbol":"ETHUSDT","id":32402512769,"side":"Buy","price":3108.58,"timestamp":"2024-05-18T15:46:22.510Z"}]}
{"table":"orderBookL2_25","action":"update","data":[{"symbol":"ETHUSDT","id":32402487305,"side":"Sell","size":100000,"price":3111.65,"timestamp":"2024-05-18T15:46:22.510Z"}]}
{"table":"orderBookL2_25","action":"insert","data":[{"symbol":"ETHUSDT","id":32402515534,"side":"Sell","size":32000,"price":3110.25,"timestamp":"2024-05-18T15:46:22.510Z"},{"symbol":"ETHUSDT","id":32402493850,"side":"Sell","size":100000,"price":3111.81,"timestamp":"2024-05-18T15:46:22.510Z"},{"symbol":"ETHUSDT","id":32402515569,"side":"Sell","size":3000,"price":3109.19,"timestamp":"2024-05-18T15:46:22.510Z"},{"symbol":"ETHUSDT","id":32402515539,"side":"Sell","size":32000,"price":3110.26,"timestamp":"2024-05-18T15:46:22.510Z"},{"symbol":"ETHUSDT","id":32402455680,"side":"Sell","size":100000,"price":3112.02,"timestamp":"2024-05-18T15:46:22.510Z"},{"symbol":"ETHUSDT","id":32402486025,"side":"Sell","size":337000,"price":3111.72,"timestamp":"2024-05-18T15:46:22.510Z"},{"symbol":"ETHUSDT","id":32402515566,"side":"Sell","size":160000,"price":3110.79,"timestamp":"2024-05-18T15:46:22.510Z"},{"symbol":"ETHUSDT","id":32402515495,"side":"Sell","size":532000,"price":3111.71,"timestamp":"2024-05-18T15:46:22.510Z"},{"symbol":"ETHUSDT","id":32402515493,"side":"Sell","size":100000,"price":3110.31,"timestamp":"2024-05-18T15:46:22.510Z"},{"symbol":"ETHUSDT","id":32402515578,"side":"Buy","size":521000,"price":3107.92,"timestamp":"2024-05-18T15:46:22.510Z"},{"symbol":"ETHUSDT","id":32402515537,"side":"Buy","size":32000,"price":3108.84,"timestamp":"2024-05-18T15:46:22.510Z"},{"symbol":"ETHUSDT","id":32402515525,"side":"Buy","size":1000,"price":3108.60,"timestamp":"2024-05-18T15:46:22.510Z"},{"symbol":"ETHUSDT","id":32402354519,"side":"Buy","size":100000,"price":3106.60,"timestamp":"2024-05-18T15:46:22.510Z"}]}
{"table":"orderBookL2_25","action":"delete","data":[{"symbol":"XBTUSDT","id":32402514311,"side":"Sell","price":66774.8,"timestamp":"2024-05-18T15:46:22.513Z"},{"symbol":"XBTUSDT","id":32402511466,"side":"Buy","price":66727.1,"timestamp":"2024-05-18T15:46:22.513Z"},{"symbol":"XBTUSDT","id":32402514096,"side":"Buy","price":66747.1,"timestamp":"2024-05-18T15:46:22.513Z"}]}
{"table":"orderBookL2_25","action":"insert","data":[{"symbol":"XBTUSDT","id":32402515522,"side":"Sell","size":20000,"price":66775.0,"timestamp":"2024-05-18T15:46:22.513Z"},{"symbol":"XBTUSDT","id":32402515528,"side":"Buy","size":100000,"price":66757.6,"timestamp":"2024-05-18T15:46:22.513Z"},{"symbol":"XBTUSDT","id":32402515520,"side":"Buy","size":20000,"price":66746.9,"timestamp":"2024-05-18T15:46:22.513Z"}]}
{"table":"orderBookL2_25","action":"delete","data":[{"symbol":"XBTETH","id":32402419404,"side":"Sell","price":22.087,"timestamp":"2024-05-18T15:46:22.515Z"}]}
{"table":"orderBookL2_25","action":"insert","data":[{"symbol":"XBTETH","id":32402515543,"side":"Sell","size":7,"price":22.083,"timestamp":"2024-05-18T15:46:22.515Z"}]}
{"table":"orderBookL2_25","action":"delete","data":[{"symbol":"ETHUSDT","id":32402515534,"side":"Sell","price":3110.25,"timestamp":"2024-05-18T15:46:22.559Z"},{"symbol":"ETHUSDT","id":32402515569,"side":"Sell","price":3109.19,"timestamp":"2024-05-18T15:46:22.559Z"},{"symbol":"ETHUSDT","id":32402511735,"side":"Sell","price":3110.34,"timestamp":"2024-05-18T15:46:22.559Z"},{"symbol":"ETHUSDT","id":32402515539,"side":"Sell","price":3110.26,"timestamp":"2024-05-18T15:46:22.559Z"},{"symbol":"ETHUSDT","id":32402512407,"side":"Sell","price":3110.35,"timestamp":"2024-05-18T15:46:22.559Z"},{"symbol":"ETHUSDT","id":32402515495,"side":"Sell","price":3111.71,"timestamp":"2024-05-18T15:46:22.559Z"}]}
{"table":"orderBookL2_25","action":"insert","data":[{"symbol":"ETHUSDT","id":32402515675,"side":"Sell","size":32000,"price":3110.27,"timestamp":"2024-05-18T15:46:22.559Z"},{"symbol":"ETHUSDT","id":32402488716,"side":"Sell","size":100000,"price":3112.18,"timestamp":"2024-05-18T15:46:22.559Z"},{"symbol":"ETHUSDT","id":32402515618,"side":"Sell","size":28000,"price":3109.59,"timestamp":"2024-05-18T15:46:22.559Z"},{"symbol":"ETHUSDT","id":32402505932,"side":"Sell","size":1000,"price":3112.60,"timestamp":"2024-05-18T15:46:22.559Z"},{"symbol":"ETHUSDT","id":32402515679,"side":"Sell","size":32000,"price":3110.28,"timestamp":"2024-05-18T15:46:22.559Z"},{"symbol":"ETHUSDT","id":32402515605,"side":"Sell","size":574000,"price":3112.01,"timestamp":"2024-05-18T15:46:22.559Z"}]}
{"table":"orderBookL2_25","action":"delete","data":[{"symbol":"XBTUSDT","id":32402512789,"side":"Sell","price":66774.9,"timestamp":"2024-05-18T15:46:22.562Z"},{"symbol":"XBTUSDT","id":32402515071,"side":"Sell","price":66766.8,"timestamp":"2024-05-18T15:46:22.562Z"},{"symbol":"XBTUSDT","id":32402515520,"side":"Buy","price":66746.9,"timestamp":"2024-05-18T15:46:22.562Z"}]}
{"table":"orderBookL2_25","action":"update","data":[{"symbol":"XBTUSDT","id":32402502861,"side":"Sell","size":100000,"price":66784.3,"timestamp":"2024-05-18T15:46:22.562Z"},{"symbol":"XBTUSDT","id":32402506723,"side":"Sell","size":159000,"price":66783.4,"timestamp":"2024-05-18T15:46:22.562Z"},{"symbol":"XBTUSDT","id":32402514712,"side":"Sell","size":23000,"price":66775.1,"timestamp":"2024-05-18T15:46:22.562Z"}]}
{"table":"orderBookL2_25","action":"insert","data":[{"symbol":"XBTUSDT","id":32402515669,"side":"Sell","size":8000,"price":66766.5,"timestamp":"2024-05-18T15:46:22.562Z"},{"symbol":"XBTUSDT","id":32402515646,"side":"Sell","size":225000,"price":66774.6,"timestamp":"2024-05-18T15:46:22.562Z"},{"symbol":"XBTUSDT","id":32402515671,"side":"Buy","size":20000,"price":66747.1,"timestamp":"2024-05-18T15:46:22.562Z"}]}
{"table":"orderBookL2_25","action":"delete","data":[{"symbol":"ETHUSDT","id":32402513182,"side":"Sell","price":3109.65,"timestamp":"2024-05-18T15:46:22.608Z"},{"symbol":"ETHUSDT","id":32402515675,"side":"Sell","price":3110.27,"timestamp":"2024-05-18T15:46:22.608Z"},{"symbol":"ETHUSDT","id":32402515618,"side":"Sell","price":3109.59,"timestamp":"2024-05-18T15:46:22.608Z"},{"symbol":"ETHUSDT","id":32402515017,"side":"Buy","price":3108.59,"timestamp":"2024-05-18T15:46:22.608Z"},{"symbol":"ETHUSDT","id":32402505366,"side":"Buy","price":3106.92,"timestamp":"2024-05-18T15:46:22.608Z"},{"symbol":"ETHUSDT","id":32402515537,"side":"Buy","price":3108.84,"timestamp":"2024-05-18T15:46:22.608Z"},{"symbol":"ETHUSDT","id":32402354519,"side":"Buy","price":3106.60,"timestamp":"2024-05-18T15:46:22.608Z"}]}
{"table":"orderBookL2_25","action":"update","data":[{"symbol":"ETHUSDT","id":32402505932,"side":"Sell","size":1000,"price":3112.60,"timestamp":"2024-05-18T15:46:22.608Z"},{"symbol":"ETHUSDT","id":32402488716,"side":"Sell","size":100000,"price":3112.18,"timestamp":"2024-05-18T15:46:22.608Z"},{"symbol":"ETHUSDT","id":32402512820,"side":"Buy","size":241000,"price":3108.83,"timestamp":"2024-05-18T15:46:22.608Z"}]}
{"table":"orderBookL2_25","action":"insert","data":[{"symbol":"ETHUSDT","id":32402515742,"side":"Sell","size":21000,"price":3109.58,"timestamp":"2024-05-18T15:46:22.608Z"},{"symbol":"ETHUSDT","id":32402447682,"side":"Sell","size":100000,"price":3112.68,"timestamp":"2024-05-18T15:46:22.608Z"},{"symbol":"ETHUSDT","id":32402515779,"side":"Sell","size":32000,"price":3110.27,"timestamp":"2024-05-18T15:46:22.608Z"},{"symbol":"ETHUSDT","id":32402515760,"side":"Buy","size":1000,"price":3108.61,"timestamp":"2024-05-18T15:46:22.608Z"},{"symbol":"ETHUSDT","id":32402515719,"side":"Buy","size":68000,"price":3108.36,"timestamp":"2024-05-18T15:46:22.608Z"},{"symbol":"ETHUSDT","id":32402515769,"side":"Buy","size":32000,"price":3108.85,"timestamp":"2024-05-18T15:46:22.608Z"},{"symbol":"ETHUSDT","id":32402515800,"side":"Buy","size":32000,"price":3108.84,"timestamp":"2024-05-18T15:46:22.608Z"}]}
{"table":"orderBookL2_25","action":"delete","data":[{"symbol":"XBTUSDT","id":32402502861,"side":"Sell","price":66784.3,"timestamp":"2024-05-18T15:46:22.611Z"},{"symbol":"XBTUSDT","id":32402512535,"side":"Sell","price":66782.2,"timestamp":"2024-05-18T15:46:22.611Z"},{"symbol":"XBTUSDT","id":32402515022,"side":"Sell","price":66766.6,"timestamp":"2024-05-18T15:46:22.611Z"},{"symbol":"XBTUSDT","id":32402515522,"side":"Sell","price":66775.0,"timestamp":"2024-05-18T15:46:22.611Z"},{"symbol":"XBTUSDT","id":32402515454,"side":"Sell","price":66782.3,"timestamp":"2024-05-18T15:46:22.611Z"},{"symbol":"XBTUSDT","id":32402515671,"side":"Buy","price":66747.1,"timestamp":"2024-05-18T15:46:22.611Z"},{"symbol":"XBTUSDT","id":32402514308,"side":"Buy","price":66747.0,"timestamp":"2024-05-18T15:46:22.611Z"}]}
{"table":"orderBookL2_25","action":"update","data":[{"symbol":"XBTUSDT","id":32402514712,"side":"Sell","size":3000,"price":66775.1,"timestamp":"2024-05-18T15:46:22.611Z"}]}
{"table":"orderBookL2_25","action":"insert","data":[{"symbol":"XBTUSDT","id":32402515802,"side":"Sell","size":8000,"price":66766.4,"timestamp":"2024-05-18T15:46:22.611Z"},{"symbol":"XBTUSDT","id":32402515812,"side":"Sell","size":20000,"price":66774.8,"timestamp":"2024-05-18T15:46:22.611Z"},{"symbol":"XBTUSDT","id":32402515750,"side":"Sell","size":1000,"price":66782.2,"timestamp":"2024-05-18T15:46:22.611Z"},{"symbol":"XBTUSDT","id":32402515748,"side":"Sell","size":1000,"price":66782.1,"timestamp":"2024-05-18T15:46:22.611Z"},{"symbol":"XBTUSDT","id":32402515789,"side":"Sell","size":20000,"price":66774.9,"timestamp":"2024-05-18T15:46:22.611Z"},{"symbol":"XBTUSDT","id":32402515814,"side":"Buy","size":20000,"price":66747.3,"timestamp":"2024-05-18T15:46:22.611Z"},{"symbol":"XBTUSDT","id":32402515781,"side":"Buy","size":20000,"price":66747.2,"timestamp":"2024-05-18T15:46:22.611Z"}]}
{"table":"orderBookL2_25","action":"delete","data":[{"symbol":"ETHUSDT","id":32402488716,"side":"Sell","price":3112.18,"timestamp":"2024-05-18T15:46:22.657Z"},{"symbol":"ETHUSDT","id":32402515679,"side":"Sell","price":3110.28,"timestamp":"2024-05-18T15:46:22.657Z"},{"symbol":"ETHUSDT","id":32402447682,"side":"Sell","price":3112.68,"timestamp":"2024-05-18T15:46:22.657Z"},{"symbol":"ETHUSDT","id":32402515566,"side":"Sell","price":3110.79,"timestamp":"2024-05-18T15:46:22.657Z"},{"symbol":"ETHUSDT","id":32402505932,"side":"Sell","price":3112.60,"timestamp":"2024-05-18T15:46:22.657Z"},{"symbol":"ETHUSDT","id":32402515779,"side":"Sell","price":3110.27,"timestamp":"2024-05-18T15:46:22.657Z"},{"symbol":"ETHUSDT","id":32402511227,"side":"Buy","price":3107.00,"timestamp":"2024-05-18T15:46:22.657Z"},{"symbol":"ETHUSDT","id":32402515760,"side":"Buy","price":3108.61,"timestamp":"2024-05-18T15:46:22.657Z"},{"symbol":"ETHUSDT","id":32402504254,"side":"Buy","price":3106.99,"timestamp":"2024-05-18T15:46:22.657Z"},{"symbol":"ETHUSDT","id":32402515769,"side":"Buy","price":3108.85,"timestamp":"2024-05-18T15:46:22.657Z"}]}
{"table":"orderBookL2_25","action":"update","data":[{"symbol":"ETHUSDT","id":32402515493,"side":"Sell","size":100000,"price":3110.31,"timestamp":"2024-05-18T15:46:22.657Z"},{"symbol":"ETHUSDT","id":32402512820,"side":"Buy","size":241000,"price":3108.83,"timestamp":"2024-05-18T15:46:22.657Z"}]}
{"table":"orderBookL2_25","action":"insert","data":[{"symbol":"ETHUSDT","id":32402515861,"side":"Sell","size":276000,"price":3109.65,"timestamp":"2024-05-18T15:46:22.657Z"},{"symbol":"ETHUSDT","id":32402515932,"side":"Sell","size":32000,"price":3110.32,"timestamp":"2024-05-18T15:46:22.657Z"},{"symbol":"ETHUSDT","id":32402515905,"side":"Sell","size":27000,"price":3110.22,"timestamp":"2024-05-18T15:46:22.657Z"},{"symbol":"ETHUSDT","id":32402515865,"side":"Sell","size":28000,"price":3109.94,"timestamp":"2024-05-18T15:46:22.657Z"},{"symbol":"ETHUSDT","id":32402515853,"side":"Sell","size":43000,"price":3110.23,"timestamp":"2024-05-18T15:46:22.657Z"},{"symbol":"ETHUSDT","id":32402515936,"side":"Sell","size":32000,"price":3110.33,"timestamp":"2024-05-18T15:46:22.657Z"},{"symbol":"ETHUSDT","id":32402515939,"side":"Buy","size":100000,"price":3108.53,"timestamp":"2024-05-18T15:46:22.657Z"},{"symbol":"ETHUSDT","id":32402515896,"side":"Buy","size":1000,"price":3108.61,"timestamp":"2024-05-18T15:46:22.657Z"},{"symbol":"ETHUSDT","id":32402515823,"side":"Buy","size":48000,"price":3108.78,"timestamp":"2024-05-18T15:46:22.657Z"},{"symbol":"ETHUSDT","id":32402515887,"side":"Buy","size":32000,"price":3108.85,"timestamp":"2024-05-18T15:46:22.657Z"}]}
{"table":"orderBookL2_25","action":"delete","data":[{"symbol":"XBTUSDT","id":32402515750,"side":"Sell","price":66782.2,"timestamp":"2024-05-18T15:46:22.660Z"},{"symbol":"XBTUSDT","id":32402514522,"side":"Sell","price":66770.7,"timestamp":"2024-05-18T15:46:22.660Z"}]}
{"table":"orderBookL2_25","action":"update","data":[{"symbol":"XBTUSDT","id":32402506723,"side":"Sell","size":159000,"price":66783.4,"timestamp":"2024-05-18T15:46:22.660Z"}]}
{"table":"orderBookL2_25","action":"insert","data":[{"symbol":"XBTUSDT","id":32402515890,"side":"Sell","size":20000,"price":66771.5,"timestamp":"2024-05-18T15:46:22.660Z"},{"symbol":"XBTUSDT","id":32402515874,"side":"Sell","size":1000,"price":66782.0,"timestamp":"2024-05-18T15:46:22.660Z"}]}
{"table":"orderBookL2_25","action":"delete","data":[{"symbol":"ETHUSDT","id":32402515932,"side":"Sell","price":3110.32,"timestamp":"2024-05-18T15:46:22.706Z"},{"symbol":"ETHUSDT","id":32402515936,"side":"Sell","price":3110.33,"timestamp":"2024-05-18T15:46:22.706Z"},{"symbol":"ETHUSDT","id":32402515896,"side":"Buy","price":3108.61,"timestamp":"2024-05-18T15:46:22.706Z"},{"symbol":"ETHUSDT","id":32402515719,"side":"Buy","price":3108.36,"timestamp":"2024-05-18T15:46:22.706Z"},{"symbol":"ETHUSDT","id":32402515800,"side":"Buy","price":3108.84,"timestamp":"2024-05-18T15:46:22.706Z"}]}
{"table":"orderBookL2_25","action":"update","data":[{"symbol":"ETHUSDT","id":32402515493,"side":"Sell","size":100000,"price":3110.31,"timestamp":"2024-05-18T15:46:22.706Z"}]}
{"table":"orderBookL2_25","action":"insert","data":[{"symbol":"ETHUSDT","id":32402516009,"side":"Sell","size":32000,"price":3110.38,"timestamp":"2024-05-18T15:46:22.706Z"},{"symbol":"ETHUSDT","id":32402516015,"side":"Sell","size":32000,"price":3110.39,"timestamp":"2024-05-18T15:46:22.706Z"},{"symbol":"ETHUSDT","id":32402516007,"side":"Buy","size":1000,"price":3108.61,"timestamp":"2024-05-18T15:46:22.706Z"},{"symbol":"ETHUSDT","id":32402515953,"side":"Buy","size":62000,"price":3108.54,"timestamp":"2024-05-18T15:46:22.706Z"},{"symbol":"ETHUSDT","id":32402515974,"side":"Buy","size":32000,"price":3108.84,"timestamp":"2024-05-18T15:46:22.706Z"}]}
{"table":"orderBookL2_25","action":"delete","data":[{"symbol":"XBTUSDT","id":32402515812,"side":"Sell","price":66774.8,"timestamp":"2024-05-18T15:46:22.709Z"},{"symbol":"XBTUSDT","id":32402515748,"side":"Sell","price":66782.1,"timestamp":"2024-05-18T15:46:22.709Z"},{"symbol":"XBTUSDT","id":32402514712,"side":"Sell","price":66775.1,"timestamp":"2024-05-18T15:46:22.709Z"},{"symbol":"XBTUSDT","id":32402515646,"side":"Sell","price":66774.6,"timestamp":"2024-05-18T15:46:22.709Z"},{"symbol":"XBTUSDT","id":32402515461,"side":"Sell","price":66774.7,"timestamp":"2024-05-18T15:46:22.709Z"},{"symbol":"XBTUSDT","id":32402515874,"side":"Sell","price":66782.0,"timestamp":"2024-05-18T15:46:22.709Z"},{"symbol":"XBTUSDT","id":32402515814,"side":"Buy","price":66747.3,"timestamp":"2024-05-18T15:46:22.709Z"},{"symbol":"XBTUSDT","id":32402515528,"side":"Buy","price":66757.6,"timestamp":"2024-05-18T15:46:22.709Z"}]}
{"table":"orderBookL2_25","action":"update","data":[{"symbol":"XBTUSDT","id":32402513615,"side":"Sell","size":17000,"price":66781.7,"timestamp":"2024-05-18T15:46:22.709Z"}]}
{"table":"orderBookL2_25","action":"insert","data":[{"symbol":"XBTUSDT","id":32402512008,"side":"Sell","size":68000,"price":66788.6,"timestamp":"2024-05-18T15:46:22.709Z"},{"symbol":"XBTUSDT","id":32402516019,"side":"Sell","size":392000,"price":66774.8,"timestamp":"2024-05-18T15:46:22.709Z"},{"symbol":"XBTUSDT","id":32402515958,"side":"Sell","size":1000,"price":66782.2,"timestamp":"2024-05-18T15:46:22.709Z"},{"symbol":"XBTUSDT","id":32402516027,"side":"Sell","size":1000,"price":66782.3,"timestamp":"2024-05-18T15:46:22.709Z"},{"symbol":"XBTUSDT","id":32402499271,"side":"Sell","size":100000,"price":66788.7,"timestamp":"2024-05-18T15:46:22.709Z"},{"symbol":"XBTUSDT","id":32402502861,"side":"Sell","size":100000,"price":66784.3,"timestamp":"2024-05-18T15:46:22.709Z"},{"symbol":"XBTUSDT","id":32402511466,"side":"Buy","size":62000,"price":66727.1,"timestamp":"2024-05-18T15:46:22.709Z"},{"symbol":"XBTUSDT","id":32402516022,"side":"Buy","size":20000,"price":66747.3,"timestamp":"2024-05-18T15:46:22.709Z"}]}
{"table":"orderBookL2_25","action":"delete","data":[{"symbol":"ETHUSDT","id":32402516015,"side":"Sell","price":3110.39,"timestamp":"2024-05-18T15:46:22.755Z"},{"symbol":"ETHUSDT","id":32402516009,"side":"Sell","price":3110.38,"timestamp":"2024-05-18T15:46:22.755Z"},{"symbol":"ETHUSDT","id":32402516007,"side":"Buy","price":3108.61,"timestamp":"2024-05-18T15:46:22.755Z"}]}
{"table":"orderBookL2_25","action":"insert","data":[{"symbol":"ETHUSDT","id":32402516067,"side":"Sell","size":32000,"price":3110.42,"timestamp":"2024-05-18T15:46:22.755Z"},{"symbol":"ETHUSDT","id":32402516062,"side":"Sell","size":32000,"price":3110.43,"timestamp":"2024-05-18T15:46:22.755Z"},{"symbol":"ETHUSDT","id":32402516035,"side":"Buy","size":1000,"price":3108.59,"timestamp":"2024-05-18T15:46:22.755Z"}]}
{"table":"orderBookL2_25","action":"delete","data":[{"symbol":"XBTUSDT","id":32402512008,"side":"Sell","price":66788.6,"timestamp":"2024-05-18T15:46:22.758Z"},{"symbol":"XBTUSDT","id":32402499271,"side":"Sell","price":66788.7,"timestamp":"2024-05-18T15:46:22.758Z"},{"symbol":"XBTUSDT","id":32402514910,"side":"Sell","price":66780.9,"timestamp":"2024-05-18T15:46:22.758Z"},{"symbol":"XBTUSDT","id":32402516022,"side":"Buy","price":66747.3,"timestamp":"2024-05-18T15:46:22.758Z"}]}
{"table":"orderBookL2_25","action":"update","data":[{"symbol":"XBTUSDT","id":32402516019,"side":"Sell","size":372000,"price":66774.8,"timestamp":"2024-05-18T15:46:22.758Z"}]}
{"table":"orderBookL2_25","action":"insert","data":[{"symbol":"XBTUSDT","id":32402516054,"side":"Sell","size":236000,"price":66774.7,"timestamp":"2024-05-18T15:46:22.758Z"},{"symbol":"XBTUSDT","id":32402516052,"side":"Sell","size":20000,"price":66775.0,"timestamp":"2024-05-18T15:46:22.758Z"},{"symbol":"XBTUSDT","id":32402516072,"side":"Sell","size":3000,"price":66784.6,"timestamp":"2024-05-18T15:46:22.758Z"},{"symbol":"XBTUSDT","id":32402516050,"side":"Buy","size":20000,"price":66747.1,"timestamp":"2024-05-18T15:46:22.758Z"}]}
{"table":"orderBookL2_25","action":"delete","data":[{"symbol":"ETHUSDT","id":32402455680,"side":"Sell","price":3112.02,"timestamp":"2024-05-18T15:46:22.804Z"},{"symbol":"ETHUSDT","id":32402515605,"side":"Sell","price":3112.01,"timestamp":"2024-05-18T15:46:22.804Z"},{"symbol":"ETHUSDT","id":32402516067,"side":"Sell","price":3110.42,"timestamp":"2024-05-18T15:46:22.804Z"},{"symbol":"ETHUSDT","id":32402516062,"side":"Sell","price":3110.43,"timestamp":"2024-05-18T15:46:22.804Z"}]}
{"table":"orderBookL2_25","action":"insert","data":[{"symbol":"ETHUSDT","id":32402516084,"side":"Sell","size":32000,"price":3110.45,"timestamp":"2024-05-18T15:46:22.804Z"},{"symbol":"ETHUSDT","id":32402516082,"side":"Sell","size":32000,"price":3110.44,"timestamp":"2024-05-18T15:46:22.804Z"},{"symbol":"ETHUSDT","id":32402516080,"side":"Sell","size":63000,"price":3110.30,"timestamp":"2024-05-18T15:46:22.804Z"},{"symbol":"ETHUSDT","id":32402516076,"side":"Sell","size":25000,"price":3110.50,"timestamp":"2024-05-18T15:46:22.804Z"}]}
{"table":"orderBookL2_25","action":"delete","data":[{"symbol":"XBTUSDT","id":32402515958,"side":"Sell","price":66782.2,"timestamp":"2024-05-18T15:46:22.807Z"},{"symbol":"XBTUSDT","id":32402516072,"side":"Sell","price":66784.6,"timestamp":"2024-05-18T15:46:22.807Z"}]}
{"table":"orderBookL2_25","action":"insert","data":[{"symbol":"XBTUSDT","id":32402516112,"side":"Sell","size":1000,"price":66782.2,"timestamp":"2024-05-18T15:46:22.807Z"},{"symbol":"XBTUSDT","id":32402516109,"side":"Sell","size":156000,"price":66771.7,"timestamp":"2024-05-18T15:46:22.807Z"}]}
{"table":"orderBookL2_25","action":"delete","data":[{"symbol":"ETHUSDT","id":32402516082,"side":"Sell","price":3110.44,"timestamp":"2024-05-18T15:46:22.853Z"},{"symbol":"ETHUSDT","id":32402515742,"side":"Sell","price":3109.58,"timestamp":"2024-05-18T15:46:22.853Z"},{"symbol":"ETHUSDT","id":32402515887,"side":"Buy","price":3108.85,"timestamp":"2024-05-18T15:46:22.853Z"}]}
{"table":"orderBookL2_25","action":"update","data":[{"symbol":"ETHUSDT","id":32402493850,"side":"Sell","size":100000,"price":3111.81,"timestamp":"2024-05-18T15:46:22.853Z"},{"symbol":"ETHUSDT","id":32402512820,"side":"Buy","size":273000,"price":3108.83,"timestamp":"2024-05-18T15:46:22.853Z"}]}
{"table":"orderBookL2_25","action":"insert","data":[{"symbol":"ETHUSDT","id":32402516142,"side":"Sell","size":32000,"price":3110.46,"timestamp":"2024-05-18T15:46:22.853Z"},{"symbol":"ETHUSDT","id":32402515605,"side":"Sell","size":574000,"price":3112.01,"timestamp":"2024-05-18T15:46:22.853Z"},{"symbol":"ETHUSDT","id":32402511227,"side":"Buy","size":1126000,"price":3107.00,"timestamp":"2024-05-18T15:46:22.853Z"}]}
{"table":"orderBookL2_25","action":"delete","data":[{"symbol":"XBTUSDT","id":32402514864,"side":"Sell","price":66766.7,"timestamp":"2024-05-18T15:46:22.856Z"}]}
{"table":"orderBookL2_25","action":"insert","data":[{"symbol":"XBTUSDT","id":32402516139,"side":"Sell","size":8000,"price":66766.3,"timestamp":"2024-05-18T15:46:22.856Z"}]}
{"table":"orderBookL2_25","action":"delete","data":[{"symbol":"ETHUSDT","id":32402512266,"side":"Sell","price":3111.04,"timestamp":"2024-05-18T15:46:22.902Z"},{"symbol":"ETHUSDT","id":32402515939,"side":"Buy","price":3108.53,"timestamp":"2024-05-18T15:46:22.902Z"}]}
{"table":"orderBookL2_25","action":"insert","data":[{"symbol":"ETHUSDT","id":32402455680,"side":"Sell","size":100000,"price":3112.02,"timestamp":"2024-05-18T15:46:22.902Z"},{"symbol":"ETHUSDT","id":32402516245,"side":"Buy","size":65000,"price":3108.36,"timestamp":"2024-05-18T15:46:22.902Z"}]}
{"table":"orderBookL2_25","action":"delete","data":[{"symbol":"ETHUSDT","id":32402515953,"side":"Buy","price":3108.54,"timestamp":"2024-05-18T15:46:22.951Z"}]}
{"table":"orderBookL2_25","action":"insert","data":[{"symbol":"ETHUSDT","id":32402504254,"side":"Buy","size":2300000,"price":3106.99,"timestamp":"2024-05-18T15:46:22.951Z"}]}
{"table":"orderBookL2_25","action":"delete","data":[{"symbol":"XBTUSDT","id":32402515802,"side":"Sell","price":66766.4,"timestamp":"2024-05-18T15:46:22.956Z"}]}
{"table":"orderBookL2_25","action":"insert","data":[{"symbol":"XBTUSDT","id":32402516072,"side":"Sell","size":3000,"price":66784.6,"timestamp":"2024-05-18T15:46:22.956Z"}]}
{"table":"orderBookL2_25","action":"delete","data":[{"symbol":"XBTUSDT","id":32402516072,"side":"Sell","price":66784.6,"timestamp":"2024-05-18T15:46:23.006Z"},{"symbol":"XBTUSDT","id":32402511466,"side":"Buy","price":66727.1,"timestamp":"2024-05-18T15:46:23.006Z"}]}
{"table":"orderBookL2_25","action":"insert","data":[{"symbol":"XBTUSDT","id":32402516320,"side":"Sell","size":8000,"price":66766.2,"timestamp":"2024-05-18T15:46:23.006Z"},{"symbol":"XBTUSDT","id":32402516379,"side":"Buy","size":100000,"price":66757.6,"timestamp":"2024-05-18T15:46:23.006Z"}]}
{"table":"orderBookL2_25","action":"delete","data":[{"symbol":"ETHUSDT","id":32402504254,"side":"Buy","price":3106.99,"timestamp":"2024-05-18T15:46:23.042Z"}]}
{"table":"orderBookL2_25","action":"insert","data":[{"symbol":"ETHUSDT","id":32402516431,"side":"Buy","size":100000,"price":3108.52,"timestamp":"2024-05-18T15:46:23.042Z"}]}
{"table":"orderBookL2_25","action":"delete","data":[{"symbol":"XBTUSDT","id":32402511633,"side":"Sell","price":66779.6,"timestamp":"2024-05-18T15:46:23.055Z"}]}
{"table":"orderBookL2_25","action":"update","data":[{"symbol":"XBTUSDT","id":32402513615,"side":"Sell","size":3000,"price":66781.7,"timestamp":"2024-05-18T15:46:23.055Z"}]}
{"table":"orderBookL2_25","action":"insert","data":[{"symbol":"XBTUSDT","id":32402516072,"side":"Sell","size":3000,"price":66784.6,"timestamp":"2024-05-18T15:46:23.055Z"}]}
{"table":"orderBookL2_25","action":"delete","data":[{"symbol":"ETHUSDT","id":32402515493,"side":"Sell","price":3110.31,"timestamp":"2024-05-18T15:46:23.092Z"},{"symbol":"ETHUSDT","id":32402516142,"side":"Sell","price":3110.46,"timestamp":"2024-05-18T15:46:23.092Z"},{"symbol":"ETHUSDT","id":32402500182,"side":"Sell","price":3110.56,"timestamp":"2024-05-18T15:46:23.092Z"},{"symbol":"ETHUSDT","id":32402511227,"side":"Buy","price":3107.00,"timestamp":"2024-05-18T15:46:23.092Z"},{"symbol":"ETHUSDT","id":32402516245,"side":"Buy","price":3108.36,"timestamp":"2024-05-18T15:46:23.092Z"}]}
{"table":"orderBookL2_25","action":"update","data":[{"symbol":"ETHUSDT","id":32402506878,"side":"Buy","size":160000,"price":3107.03,"timestamp":"2024-05-18T15:46:23.092Z"},{"symbol":"ETHUSDT","id":32402512820,"side":"Buy","size":241000,"price":3108.83,"timestamp":"2024-05-18T15:46:23.092Z"}]}
{"table":"orderBookL2_25","action":"insert","data":[{"symbol":"ETHUSDT","id":32402505932,"side":"Sell","size":1000,"price":3112.60,"timestamp":"2024-05-18T15:46:23.092Z"},{"symbol":"ETHUSDT","id":32402488716,"side":"Sell","size":100000,"price":3112.18,"timestamp":"2024-05-18T15:46:23.092Z"},{"symbol":"ETHUSDT","id":32402516463,"side":"Sell","size":32000,"price":3110.44,"timestamp":"2024-05-18T15:46:23.092Z"},{"symbol":"ETHUSDT","id":32402516467,"side":"Buy","size":32000,"price":3108.85,"timestamp":"2024-05-18T15:46:23.092Z"},{"symbol":"ETHUSDT","id":32402516469,"side":"Buy","size":66000,"price":3108.53,"timestamp":"2024-05-18T15:46:23.092Z"}]}
{"table":"orderBookL2_25","action":"delete","data":[{"symbol":"XBTUSDT","id":32402515890,"side":"Sell","price":66771.5,"timestamp":"2024-05-18T15:46:23.104Z"}]}
{"table":"orderBookL2_25","action":"insert","data":[{"symbol":"XBTUSDT","id":32402516488,"side":"Sell","size":74000,"price":66779.6,"timestamp":"2024-05-18T15:46:23.104Z"}]}
{"table":"orderBookL2_25","action":"delete","data":[{"symbol":"ETHUSDT","id":32402516080,"side":"Sell","price":3110.30,"timestamp":"2024-05-18T15:46:23.141Z"},{"symbol":"ETHUSDT","id":32402516463,"side":"Sell","price":3110.44,"timestamp":"2024-05-18T15:46:23.141Z"},{"symbol":"ETHUSDT","id":32402515905,"side":"Sell","price":3110.22,"timestamp":"2024-05-18T15:46:23.141Z"},{"symbol":"ETHUSDT","id":32402515853,"side":"Sell","price":3110.23,"timestamp":"2024-05-18T15:46:23.141Z"},{"symbol":"ETHUSDT","id":32402516467,"side":"Buy","price":3108.85,"timestamp":"2024-05-18T15:46:23.141Z"}]}
{"table":"orderBookL2_25","action":"update","data":[{"symbol":"ETHUSDT","id":32402516084,"side":"Sell","size":100000,"price":3110.45,"timestamp":"2024-05-18T15:46:23.141Z"},{"symbol":"ETHUSDT","id":32402512820,"side":"Buy","size":241000,"price":3108.83,"timestamp":"2024-05-18T15:46:23.141Z"}]}
{"table":"orderBookL2_25","action":"insert","data":[{"symbol":"ETHUSDT","id":32402516542,"side":"Sell","size":32000,"price":3110.47,"timestamp":"2024-05-18T15:46:23.141Z"},{"symbol":"ETHUSDT","id":32402516511,"side":"Sell","size":32000,"price":3110.46,"timestamp":"2024-05-18T15:46:23.141Z"},{"symbol":"ETHUSDT","id":32402516490,"side":"Sell","size":21000,"price":3109.64,"timestamp":"2024-05-18T15:46:23.141Z"},{"symbol":"ETHUSDT","id":32402447682,"side":"Sell","size":100000,"price":3112.68,"timestamp":"2024-05-18T15:46:23.141Z"},{"symbol":"ETHUSDT","id":32402516520,"side":"Buy","size":132000,"price":3108.85,"timestamp":"2024-05-18T15:46:23.141Z"}]}
{"table":"orderBookL2_25","action":"delete","data":[{"symbol":"XBTUSDT","id":32402515789,"side":"Sell","price":66774.9,"timestamp":"2024-05-18T15:46:23.153Z"},{"symbol":"XBTUSDT","id":32402516019,"side":"Sell","price":66774.8,"timestamp":"2024-05-18T15:46:23.153Z"},{"symbol":"XBTUSDT","id":32402516054,"side":"Sell","price":66774.7,"timestamp":"2024-05-18T15:46:23.153Z"},{"symbol":"XBTUSDT","id":32402516112,"side":"Sell","price":66782.2,"timestamp":"2024-05-18T15:46:23.153Z"},{"symbol":"XBTUSDT","id":32402513025,"side":"Sell","price":66767.4,"timestamp":"2024-05-18T15:46:23.153Z"},{"symbol":"XBTUSDT","id":32402515669,"side":"Sell","price":66766.5,"timestamp":"2024-05-18T15:46:23.153Z"},{"symbol":"XBTUSDT","id":32402516488,"side":"Sell","price":66779.6,"timestamp":"2024-05-18T15:46:23.153Z"},{"symbol":"XBTUSDT","id":32402516109,"side":"Sell","price":66771.7,"timestamp":"2024-05-18T15:46:23.153Z"},{"symbol":"XBTUSDT","id":32402513582,"side":"Sell","price":66778.4,"timestamp":"2024-05-18T15:46:23.153Z"},{"symbol":"XBTUSDT","id":32402516050,"side":"Buy","price":66747.1,"timestamp":"2024-05-18T15:46:23.153Z"},{"symbol":"XBTUSDT","id":32402515361,"side":"Buy","price":66737.5,"timestamp":"2024-05-18T15:46:23.153Z"}]}
{"table":"orderBookL2_25","action":"update","data":[{"symbol":"XBTUSDT","id":32402506378,"side":"Sell","size":248000,"price":66764.5,"timestamp":"2024-05-18T15:46:23.153Z"},{"symbol":"XBTUSDT","id":32402505821,"side":"Buy","size":146000,"price":66764.4,"timestamp":"2024-05-18T15:46:23.153Z"}]}
{"table":"orderBookL2_25","action":"insert","data":[{"symbol":"XBTUSDT","id":32402516599,"side":"Sell","size":1000,"price":66782.2,"timestamp":"2024-05-18T15:46:23.153Z"},{"symbol":"XBTUSDT","id":32402516573,"side":"Sell","size":20000,"price":66775.1,"timestamp":"2024-05-18T15:46:23.153Z"},{"symbol":"XBTUSDT","id":32402516604,"side":"Sell","size":364000,"price":66776.8,"timestamp":"2024-05-18T15:46:23.153Z"},{"symbol":"XBTUSDT","id":32402499098,"side":"Sell","size":100000,"price":66792.1,"timestamp":"2024-05-18T15:46:23.153Z"},{"symbol":"XBTUSDT","id":32402516518,"side":"Sell","size":8000,"price":66766.1,"timestamp":"2024-05-18T15:46:23.153Z"},{"symbol":"XBTUSDT","id":32402499271,"side":"Sell","size":100000,"price":66788.7,"timestamp":"2024-05-18T15:46:23.153Z"},{"symbol":"XBTUSDT","id":32402501930,"side":"Sell","size":2000,"price":66792.7,"timestamp":"2024-05-18T15:46:23.153Z"},{"symbol":"XBTUSDT","id":32402507340,"side":"Sell","size":2000,"price":66790.3,"timestamp":"2024-05-18T15:46:23.153Z"},{"symbol":"XBTUSDT","id":32402512008,"side":"Sell","size":68000,"price":66788.6,"timestamp":"2024-05-18T15:46:23.153Z"},{"symbol":"XBTUSDT","id":32402516606,"side":"Buy","size":349000,"price":66740.7,"timestamp":"2024-05-18T15:46:23.153Z"},{"symbol":"XBTUSDT","id":32402516581,"side":"Buy","size":20000,"price":66747.3,"timestamp":"2024-05-18T15:46:23.153Z"}]}
{"table":"orderBookL2_25","action":"delete","data":[{"symbol":"ETHUSDT","id":32402515861,"side":"Sell","price":3109.65,"timestamp":"2024-05-18T15:46:23.190Z"},{"symbol":"ETHUSDT","id":32402516542,"side":"Sell","price":3110.47,"timestamp":"2024-05-18T15:46:23.190Z"}]}
{"table":"orderBookL2_25","action":"update","data":[{"symbol":"ETHUSDT","id":32402516084,"side":"Sell","size":100000,"price":3110.45,"timestamp":"2024-05-18T15:46:23.190Z"},{"symbol":"ETHUSDT","id":32402512820,"side":"Buy","size":241000,"price":3108.83,"timestamp":"2024-05-18T15:46:23.190Z"},{"symbol":"ETHUSDT","id":32402516520,"side":"Buy","size":132000,"price":3108.85,"timestamp":"2024-05-18T15:46:23.190Z"}]}
{"table":"orderBookL2_25","action":"insert","data":[{"symbol":"ETHUSDT","id":32402516733,"side":"Sell","size":32000,"price":3110.47,"timestamp":"2024-05-18T15:46:23.190Z"},{"symbol":"ETHUSDT","id":32402470274,"side":"Sell","size":100000,"price":3112.84,"timestamp":"2024-05-18T15:46:23.190Z"}]}
{"table":"orderBookL2_25","action":"delete","data":[{"symbol":"XBTUSDT","id":32402516599,"side":"Sell","price":66782.2,"timestamp":"2024-05-18T15:46:23.202Z"},{"symbol":"XBTUSDT","id":32402516573,"side":"Sell","price":66775.1,"timestamp":"2024-05-18T15:46:23.202Z"},{"symbol":"XBTUSDT","id":32402516052,"side":"Sell","price":66775.0,"timestamp":"2024-05-18T15:46:23.202Z"},{"symbol":"XBTUSDT","id":32402516027,"side":"Sell","price":66782.3,"timestamp":"2024-05-18T15:46:23.202Z"},{"symbol":"XBTUSDT","id":32402501930,"side":"Sell","price":66792.7,"timestamp":"2024-05-18T15:46:23.202Z"},{"symbol":"XBTUSDT","id":32402516604,"side":"Sell","price":66776.8,"timestamp":"2024-05-18T15:46:23.202Z"},{"symbol":"XBTUSDT","id":32402515781,"side":"Buy","price":66747.2,"timestamp":"2024-05-18T15:46:23.202Z"},{"symbol":"XBTUSDT","id":32402516581,"side":"Buy","price":66747.3,"timestamp":"2024-05-18T15:46:23.202Z"},{"symbol":"XBTUSDT","id":32402515392,"side":"Buy","price":66736.5,"timestamp":"2024-05-18T15:46:23.202Z"}]}
{"table":"orderBookL2_25","action":"update","data":[{"symbol":"XBTUSDT","id":32402506378,"side":"Sell","size":148000,"price":66764.5,"timestamp":"2024-05-18T15:46:23.202Z"},{"symbol":"XBTUSDT","id":32402507156,"side":"Buy","size":120000,"price":66747.4,"timestamp":"2024-05-18T15:46:23.202Z"}]}
{"table":"orderBookL2_25","action":"insert","data":[{"symbol":"XBTUSDT","id":32402516657,"side":"Sell","size":1000,"price":66782.4,"timestamp":"2024-05-18T15:46:23.202Z"},{"symbol":"XBTUSDT","id":32402516647,"side":"Sell","size":1000,"price":66782.5,"timestamp":"2024-05-18T15:46:23.202Z"},{"symbol":"XBTUSDT","id":32402516621,"side":"Sell","size":156000,"price":66774.6,"timestamp":"2024-05-18T15:46:23.202Z"},{"symbol":"XBTUSDT","id":32402516730,"side":"Sell","size":20000,"price":66775.2,"timestamp":"2024-05-18T15:46:23.202Z"},{"symbol":"XBTUSDT","id":32402516661,"side":"Sell","size":20000,"price":66775.1,"timestamp":"2024-05-18T15:46:23.202Z"},{"symbol":"XBTUSDT","id":32402516735,"side":"Sell","size":361000,"price":66778.3,"timestamp":"2024-05-18T15:46:23.202Z"},{"symbol":"XBTUSDT","id":32402516745,"side":"Buy","size":20000,"price":66730.5,"timestamp":"2024-05-18T15:46:23.202Z"},{"symbol":"XBTUSDT","id":32402516739,"side":"Buy","size":18000,"price":66728.5,"timestamp":"2024-05-18T15:46:23.202Z"},{"symbol":"XBTUSDT","id":32402516677,"side":"Buy","size":20000,"price":66747.3,"timestamp":"2024-05-18T15:46:23.202Z"}]}
{"table":"orderBookL2_25","action":"delete","data":[{"symbol":"ETHUSDT","id":32402515865,"side":"Sell","price":3109.94,"timestamp":"2024-05-18T15:46:23.239Z"},{"symbol":"ETHUSDT","id":32402516733,"side":"Sell","price":3110.47,"timestamp":"2024-05-18T15:46:23.239Z"},{"symbol":"ETHUSDT","id":32402516490,"side":"Sell","price":3109.64,"timestamp":"2024-05-18T15:46:23.239Z"},{"symbol":"ETHUSDT","id":32402516035,"side":"Buy","price":3108.59,"timestamp":"2024-05-18T15:46:23.239Z"}]}
{"table":"orderBookL2_25","action":"update","data":[{"symbol":"ETHUSDT","id":32402516084,"side":"Sell","size":132000,"price":3110.45,"timestamp":"2024-05-18T15:46:23.239Z"},{"symbol":"ETHUSDT","id":32402470274,"side":"Sell","size":100000,"price":3112.84,"timestamp":"2024-05-18T15:46:23.239Z"},{"symbol":"ETHUSDT","id":32402512820,"side":"Buy","size":273000,"price":3108.83,"timestamp":"2024-05-18T15:46:23.239Z"},{"symbol":"ETHUSDT","id":32402516520,"side":"Buy","size":100000,"price":3108.85,"timestamp":"2024-05-18T15:46:23.239Z"}]}
{"table":"orderBookL2_25","action":"insert","data":[{"symbol":"ETHUSDT","id":32402516817,"side":"Sell","size":194000,"price":3109.63,"timestamp":"2024-05-18T15:46:23.239Z"},{"symbol":"ETHUSDT","id":32402476065,"side":"Sell","size":120000,"price":3112.99,"timestamp":"2024-05-18T15:46:23.239Z"},{"symbol":"ETHUSDT","id":32402516754,"side":"Sell","size":43000,"price":3110.35,"timestamp":"2024-05-18T15:46:23.239Z"},{"symbol":"ETHUSDT","id":32402516778,"side":"Buy","size":1000,"price":3108.61,"timestamp":"2024-05-18T15:46:23.239Z"}]}
{"table":"orderBookL2_25","action":"delete","data":[{"symbol":"XBTUSDT","id":32402516621,"side":"Sell","price":66774.6,"timestamp":"2024-05-18T15:46:23.251Z"},{"symbol":"XBTUSDT","id":32402513615,"side":"Sell","price":66781.7,"timestamp":"2024-05-18T15:46:23.251Z"},{"symbol":"XBTUSDT","id":32402499098,"side":"Sell","price":66792.1,"timestamp":"2024-05-18T15:46:23.251Z"},{"symbol":"XBTUSDT","id":32402516647,"side":"Sell","price":66782.5,"timestamp":"2024-05-18T15:46:23.251Z"}]}
{"table":"orderBookL2_25","action":"update","data":[{"symbol":"XBTUSDT","id":32402507340,"side":"Sell","size":2000,"price":66790.3,"timestamp":"2024-05-18T15:46:23.251Z"},{"symbol":"XBTUSDT","id":32402505821,"side":"Buy","size":147000,"price":66764.4,"timestamp":"2024-05-18T15:46:23.251Z"}]}
{"table":"orderBookL2_25","action":"insert","data":[{"symbol":"XBTUSDT","id":32402516761,"side":"Sell","size":3000,"price":66777.1,"timestamp":"2024-05-18T15:46:23.251Z"},{"symbol":"XBTUSDT","id":32402516773,"side":"Sell","size":63000,"price":66767.8,"timestamp":"2024-05-18T15:46:23.251Z"},{"symbol":"XBTUSDT","id":32402516771,"side":"Sell","size":1000,"price":66782.3,"timestamp":"2024-05-18T15:46:23.251Z"},{"symbol":"XBTUSDT","id":32402516769,"side":"Sell","size":20000,"price":66771.6,"timestamp":"2024-05-18T15:46:23.251Z"}]}
{"table":"orderBookL2_25","action":"delete","data":[{"symbol":"XBTETH","id":32402421121,"side":"Sell","price":22.130,"timestamp":"2024-05-18T15:46:23.278Z"}]}
{"table":"orderBookL2_25","action":"insert","data":[{"symbol":"XBTETH","id":32402516967,"side":"Sell","size":8,"price":22.126,"timestamp":"2024-05-18T15:46:23.278Z"}]}
{"table":"orderBookL2_25","action":"delete","data":[{"symbol":"ETHUSDT","id":32402470274,"side":"Sell","price":3112.84,"timestamp":"2024-05-18T15:46:23.288Z"},{"symbol":"ETHUSDT","id":32402476065,"side":"Sell","price":3112.99,"timestamp":"2024-05-18T15:46:23.288Z"}]}
{"table":"orderBookL2_25","action":"update","data":[{"symbol":"ETHUSDT","id":32402516084,"side":"Sell","size":100000,"price":3110.45,"timestamp":"2024-05-18T15:46:23.288Z"},{"symbol":"ETHUSDT","id":32402512820,"side":"Buy","size":241000,"price":3108.83,"timestamp":"2024-05-18T15:46:23.288Z"},{"symbol":"ETHUSDT","id":32402516520,"side":"Buy","size":132000,"price":3108.85,"timestamp":"2024-05-18T15:46:23.288Z"}]}
{"table":"orderBookL2_25","action":"insert","data":[{"symbol":"ETHUSDT","id":32402516845,"side":"Sell","size":32000,"price":3110.47,"timestamp":"2024-05-18T15:46:23.288Z"},{"symbol":"ETHUSDT","id":32402517010,"side":"Sell","size":28000,"price":3109.98,"timestamp":"2024-05-18T15:46:23.288Z"}]}
{"table":"orderBookL2_25","action":"delete","data":[{"symbol":"XBTUSDT","id":32402516657,"side":"Sell","price":66782.4,"timestamp":"2024-05-18T15:46:23.300Z"},{"symbol":"XBTUSDT","id":32402516771,"side":"Sell","price":66782.3,"timestamp":"2024-05-18T15:46:23.300Z"},{"symbol":"XBTUSDT","id":32402516072,"side":"Sell","price":66784.6,"timestamp":"2024-05-18T15:46:23.300Z"},{"symbol":"XBTUSDT","id":32402516661,"side":"Sell","price":66775.1,"timestamp":"2024-05-18T15:46:23.300Z"},{"symbol":"XBTUSDT","id":32402516773,"side":"Sell","price":66767.8,"timestamp":"2024-05-18T15:46:23.300Z"},{"symbol":"XBTUSDT","id":32402513220,"side":"Buy","price":66744.1,"timestamp":"2024-05-18T15:46:23.300Z"},{"symbol":"XBTUSDT","id":32402516739,"side":"Buy","price":66728.5,"timestamp":"2024-05-18T15:46:23.300Z"},{"symbol":"XBTUSDT","id":32402516677,"side":"Buy","price":66747.3,"timestamp":"2024-05-18T15:46:23.300Z"},{"symbol":"XBTUSDT","id":32402516745,"side":"Buy","price":66730.5,"timestamp":"2024-05-18T15:46:23.300Z"}]}
{"table":"orderBookL2_25","action":"update","data":[{"symbol":"XBTUSDT","id":32402506378,"side":"Sell","size":348000,"price":66764.5,"timestamp":"2024-05-18T15:46:23.300Z"},{"symbol":"XBTUSDT","id":32402510029,"side":"Buy","size":74000,"price":66730.1,"timestamp":"2024-05-18T15:46:23.300Z"},{"symbol":"XBTUSDT","id":32402505821,"side":"Buy","size":47000,"price":66764.4,"timestamp":"2024-05-18T15:46:23.300Z"},{"symbol":"XBTUSDT","id":32402508983,"side":"Buy","size":42000,"price":66747.5,"timestamp":"2024-05-18T15:46:23.300Z"}]}
{"table":"orderBookL2_25","action":"insert","data":[{"symbol":"XBTUSDT","id":32402516914,"side":"Sell","size":1000,"price":66782.7,"timestamp":"2024-05-18T15:46:23.300Z"},{"symbol":"XBTUSDT","id":32402516924,"side":"Sell","size":20000,"price":66775.3,"timestamp":"2024-05-18T15:46:23.300Z"},{"symbol":"XBTUSDT","id":32402516898,"side":"Sell","size":1000,"price":66782.6,"timestamp":"2024-05-18T15:46:23.300Z"},{"symbol":"XBTUSDT","id":32402499098,"side":"Sell","size":100000,"price":66792.1,"timestamp":"2024-05-18T15:46:23.300Z"},{"symbol":"XBTUSDT","id":32402517031,"side":"Sell","size":3000,"price":66782.3,"timestamp":"2024-05-18T15:46:23.300Z"},{"symbol":"XBTUSDT","id":32402511466,"side":"Buy","size":62000,"price":66727.1,"timestamp":"2024-05-18T15:46:23.300Z"},{"symbol":"XBTUSDT","id":32402517089,"side":"Buy","size":18000,"price":66732.0,"timestamp":"2024-05-18T15:46:23.300Z"},{"symbol":"XBTUSDT","id":32402511349,"side":"Buy","size":100000,"price":66727.0,"timestamp":"2024-05-18T15:46:23.300Z"},{"symbol":"XBTUSDT","id":32402516855,"side":"Buy","size":20000,"price":66735.5,"timestamp":"2024-05-18T15:46:23.300Z"}]}
{"table":"orderBookL2_25","action":"delete","data":[{"symbol":"XBTETH","id":32402421084,"side":"Buy","price":20.883,"timestamp":"2024-05-18T15:46:23.328Z"}]}
{"table":"orderBookL2_25","action":"insert","data":[{"symbol":"XBTETH","id":32402516975,"side":"Buy","size":8,"price":20.878,"timestamp":"2024-05-18T15:46:23.328Z"}]}
{"table":"orderBookL2_25","action":"delete","data":[{"symbol":"ETHUSDT","id":32402516778,"side":"Buy","price":3108.61,"timestamp":"2024-05-18T15:46:23.337Z"}]}
{"table":"orderBookL2_25","action":"insert","data":[{"symbol":"ETHUSDT","id":32402517173,"side":"Buy","size":1000,"price":3108.59,"timestamp":"2024-05-18T15:46:23.337Z"}]}
{"table":"orderBookL2_25","action":"delete","data":[{"symbol":"XBTUSDT","id":32402516898,"side":"Sell","price":66782.6,"timestamp":"2024-05-18T15:46:23.349Z"},{"symbol":"XBTUSDT","id":32402516914,"side":"Sell","price":66782.7,"timestamp":"2024-05-18T15:46:23.349Z"},{"symbol":"XBTUSDT","id":32402516730,"side":"Sell","price":66775.2,"timestamp":"2024-05-18T15:46:23.349Z"},{"symbol":"XBTUSDT","id":32402516924,"side":"Sell","price":66775.3,"timestamp":"2024-05-18T15:46:23.349Z"},{"symbol":"XBTUSDT","id":32402516379,"side":"Buy","price":66757.6,"timestamp":"2024-05-18T15:46:23.349Z"},{"symbol":"XBTUSDT","id":32402516855,"side":"Buy","price":66735.5,"timestamp":"2024-05-18T15:46:23.349Z"}]}
{"table":"orderBookL2_25","action":"update","data":[{"symbol":"XBTUSDT","id":32402508983,"side":"Buy","size":42000,"price":66747.5,"timestamp":"2024-05-18T15:46:23.349Z"}]}
{"table":"orderBookL2_25","action":"insert","data":[{"symbol":"XBTUSDT","id":32402517145,"side":"Sell","size":20000,"price":66775.4,"timestamp":"2024-05-18T15:46:23.349Z"},{"symbol":"XBTUSDT","id":32402517196,"side":"Sell","size":20000,"price":66775.5,"timestamp":"2024-05-18T15:46:23.349Z"},{"symbol":"XBTUSDT","id":32402517198,"side":"Sell","size":1000,"price":66782.9,"timestamp":"2024-05-18T15:46:23.349Z"},{"symbol":"XBTUSDT","id":32402517211,"side":"Sell","size":1000,"price":66782.8,"timestamp":"2024-05-18T15:46:23.349Z"},{"symbol":"XBTUSDT","id":32401547573,"side":"Buy","size":100000,"price":66723.1,"timestamp":"2024-05-18T15:46:23.349Z"},{"symbol":"XBTUSDT","id":32401552282,"side":"Buy","size":1000,"price":66720.0,"timestamp":"2024-05-18T15:46:23.349Z"}]}
{"table":"orderBookL2_25","action":"delete","data":[{"symbol":"ETHUSDT","id":32402516845,"side":"Sell","price":3110.47,"timestamp":"2024-05-18T15:46:23.386Z"},{"symbol":"ETHUSDT","id":32402447682,"side":"Sell","price":3112.68,"timestamp":"2024-05-18T15:46:23.386Z"},{"symbol":"ETHUSDT","id":32402516511,"side":"Sell","price":3110.46,"timestamp":"2024-05-18T15:46:23.386Z"},{"symbol":"ETHUSDT","id":32402515974,"side":"Buy","price":3108.84,"timestamp":"2024-05-18T15:46:23.386Z"},{"symbol":"ETHUSDT","id":32402516431,"side":"Buy","price":3108.52,"timestamp":"2024-05-18T15:46:23.386Z"},{"symbol":"ETHUSDT","id":32402515154,"side":"Buy","price":3108.35,"timestamp":"2024-05-18T15:46:23.386Z"},{"symbol":"ETHUSDT","id":32402516469,"side":"Buy","price":3108.53,"timestamp":"2024-05-18T15:46:23.386Z"},{"symbol":"ETHUSDT","id":32402516520,"side":"Buy","price":3108.85,"timestamp":"2024-05-18T15:46:23.386Z"},{"symbol":"ETHUSDT","id":32402515578,"side":"Buy","price":3107.92,"timestamp":"2024-05-18T15:46:23.386Z"}]}
{"table":"orderBookL2_25","action":"update","data":[{"symbol":"ETHUSDT","id":32402516817,"side":"Sell","size":173000,"price":3109.63,"timestamp":"2024-05-18T15:46:23.386Z"},{"symbol":"ETHUSDT","id":32402516084,"side":"Sell","size":132000,"price":3110.45,"timestamp":"2024-05-18T15:46:23.386Z"},{"symbol":"ETHUSDT","id":32402512820,"side":"Buy","size":273000,"price":3108.83,"timestamp":"2024-05-18T15:46:23.386Z"}]}
{"table":"orderBookL2_25","action":"insert","data":[{"symbol":"ETHUSDT","id":32402517294,"side":"Sell","size":32000,"price":3110.46,"timestamp":"2024-05-18T15:46:23.386Z"},{"symbol":"ETHUSDT","id":32402517253,"side":"Sell","size":21000,"price":3109.62,"timestamp":"2024-05-18T15:46:23.386Z"},{"symbol":"ETHUSDT","id":32402517245,"side":"Sell","size":100000,"price":3110.27,"timestamp":"2024-05-18T15:46:23.386Z"},{"symbol":"ETHUSDT","id":32402511227,"side":"Buy","size":1126000,"price":3107.00,"timestamp":"2024-05-18T15:46:23.386Z"},{"symbol":"ETHUSDT","id":32402505366,"side":"Buy","size":100000,"price":3106.92,"timestamp":"2024-05-18T15:46:23.386Z"},{"symbol":"ETHUSDT","id":32402517241,"side":"Buy","size":596000,"price":3107.57,"timestamp":"2024-05-18T15:46:23.386Z"},{"symbol":"ETHUSDT","id":32402504254,"side":"Buy","size":2300000,"price":3106.99,"timestamp":"2024-05-18T15:46:23.386Z"},{"symbol":"ETHUSDT","id":32402517309,"side":"Buy","size":32000,"price":3108.84,"timestamp":"2024-05-18T15:46:23.386Z"},{"symbol":"ETHUSDT","id":32402354519,"side":"Buy","size":100000,"price":3106.60,"timestamp":"2024-05-18T15:46:23.386Z"}]}
{"table":"orderBookL2_25","action":"delete","data":[{"symbol":"XBTUSDT","id":32402517211,"side":"Sell","price":66782.8,"timestamp":"2024-05-18T15:46:23.398Z"},{"symbol":"XBTUSDT","id":32402517198,"side":"Sell","price":66782.9,"timestamp":"2024-05-18T15:46:23.398Z"},{"symbol":"XBTUSDT","id":32402517196,"side":"Sell","price":66775.5,"timestamp":"2024-05-18T15:46:23.398Z"},{"symbol":"XBTUSDT","id":32402517145,"side":"Sell","price":66775.4,"timestamp":"2024-05-18T15:46:23.398Z"},{"symbol":"XBTUSDT","id":32402516139,"side":"Sell","price":66766.3,"timestamp":"2024-05-18T15:46:23.398Z"},{"symbol":"XBTUSDT","id":32402516320,"side":"Sell","price":66766.2,"timestamp":"2024-05-18T15:46:23.398Z"},{"symbol":"XBTUSDT","id":32402516735,"side":"Sell","price":66778.3,"timestamp":"2024-05-18T15:46:23.398Z"},{"symbol":"XBTUSDT","id":32402516606,"side":"Buy","price":66740.7,"timestamp":"2024-05-18T15:46:23.398Z"},{"symbol":"XBTUSDT","id":32401552282,"side":"Buy","price":66720.0,"timestamp":"2024-05-18T15:46:23.398Z"}]}
{"table":"orderBookL2_25","action":"update","data":[{"symbol":"XBTUSDT","id":32402499098,"side":"Sell","size":100000,"price":66792.1,"timestamp":"2024-05-18T15:46:23.398Z"},{"symbol":"XBTUSDT","id":32402508983,"side":"Buy","size":22000,"price":66747.5,"timestamp":"2024-05-18T15:46:23.398Z"}]}
{"table":"orderBookL2_25","action":"insert","data":[{"symbol":"XBTUSDT","id":32402517343,"side":"Sell","size":20000,"price":66775.5,"timestamp":"2024-05-18T15:46:23.398Z"},{"symbol":"XBTUSDT","id":32402517250,"side":"Sell","size":8000,"price":66766.0,"timestamp":"2024-05-18T15:46:23.398Z"},{"symbol":"XBTUSDT","id":32402517277,"side":"Sell","size":1000,"price":66782.7,"timestamp":"2024-05-18T15:46:23.398Z"},{"symbol":"XBTUSDT","id":32402517275,"side":"Sell","size":1000,"price":66782.6,"timestamp":"2024-05-18T15:46:23.398Z"},{"symbol":"XBTUSDT","id":32402517347,"side":"Sell","size":20000,"price":66775.6,"timestamp":"2024-05-18T15:46:23.398Z"},{"symbol":"XBTUSDT","id":32402517301,"side":"Sell","size":8000,"price":66766.2,"timestamp":"2024-05-18T15:46:23.398Z"},{"symbol":"XBTUSDT","id":32402517329,"side":"Sell","size":350000,"price":66775.0,"timestamp":"2024-05-18T15:46:23.398Z"},{"symbol":"XBTUSDT","id":32402517238,"side":"Buy","size":20000,"price":66747.3,"timestamp":"2024-05-18T15:46:23.398Z"},{"symbol":"XBTUSDT","id":32402517326,"side":"Buy","size":377000,"price":66737.5,"timestamp":"2024-05-18T15:46:23.398Z"}]}
{"table":"orderBookL2_25","action":"delete","data":[{"symbol":"ETHUSDT","id":32402517294,"side":"Sell","price":3110.46,"timestamp":"2024-05-18T15:46:23.435Z"},{"symbol":"ETHUSDT","id":32402504770,"side":"Sell","price":3109.66,"timestamp":"2024-05-18T15:46:23.435Z"},{"symbol":"ETHUSDT","id":32402517253,"side":"Sell","price":3109.62,"timestamp":"2024-05-18T15:46:23.435Z"},{"symbol":"ETHUSDT","id":32402516817,"side":"Sell","price":3109.63,"timestamp":"2024-05-18T15:46:23.435Z"},{"symbol":"ETHUSDT","id":32402517309,"side":"Buy","price":3108.84,"timestamp":"2024-05-18T15:46:23.435Z"},{"symbol":"ETHUSDT","id":32402504317,"side":"Buy","price":3108.08,"timestamp":"2024-05-18T15:46:23.435Z"},{"symbol":"ETHUSDT","id":32402354519,"side":"Buy","price":3106.60,"timestamp":"2024-05-18T15:46:23.435Z"}]}
{"table":"orderBookL2_25","action":"update","data":[{"symbol":"ETHUSDT","id":32402505932,"side":"Sell","size":1000,"price":3112.60,"timestamp":"2024-05-18T15:46:23.435Z"}]}
{"table":"orderBookL2_25","action":"insert","data":[{"symbol":"ETHUSDT","id":32402517418,"side":"Sell","size":32000,"price":3110.44,"timestamp":"2024-05-18T15:46:23.435Z"},{"symbol":"ETHUSDT","id":32402517386,"side":"Sell","size":905000,"price":3110.02,"timestamp":"2024-05-18T15:46:23.435Z"},{"symbol":"ETHUSDT","id":32402517384,"side":"Sell","size":100000,"price":3109.49,"timestamp":"2024-05-18T15:46:23.435Z"},{"symbol":"ETHUSDT","id":32402517429,"side":"Sell","size":28000,"price":3109.85,"timestamp":"2024-05-18T15:46:23.435Z"},{"symbol":"ETHUSDT","id":32402517421,"side":"Buy","size":32000,"price":3108.82,"timestamp":"2024-05-18T15:46:23.435Z"},{"symbol":"ETHUSDT","id":32402517388,"side":"Buy","size":311000,"price":3108.45,"timestamp":"2024-05-18T15:46:23.435Z"},{"symbol":"ETHUSDT","id":32402517379,"side":"Buy","size":1000,"price":3109.40,"timestamp":"2024-05-18T15:46:23.435Z"}]}
{"table":"orderBookL2_25","action":"delete","data":[{"symbol":"XBTUSDT","id":32402517277,"side":"Sell","price":66782.7,"timestamp":"2024-05-18T15:46:23.447Z"},{"symbol":"XBTUSDT","id":32402517275,"side":"Sell","price":66782.6,"timestamp":"2024-05-18T15:46:23.447Z"},{"symbol":"XBTUSDT","id":32402513115,"side":"Buy","price":66744.0,"timestamp":"2024-05-18T15:46:23.447Z"}]}
{"table":"orderBookL2_25","action":"insert","data":[{"symbol":"XBTUSDT","id":32402517395,"side":"Sell","size":1000,"price":66782.8,"timestamp":"2024-05-18T15:46:23.447Z"},{"symbol":"XBTUSDT","id":32402517393,"side":"Sell","size":1000,"price":66782.9,"timestamp":"2024-05-18T15:46:23.447Z"},{"symbol":"XBTUSDT","id":32401552282,"side":"Buy","size":1000,"price":66720.0,"timestamp":"2024-05-18T15:46:23.447Z"}]}
{"table":"orderBookL2_25","action":"delete","data":[{"symbol":"ETHUSDT","id":32402517010,"side":"Sell","price":3109.98,"timestamp":"2024-05-18T15:46:23.484Z"},{"symbol":"ETHUSDT","id":32402517418,"side":"Sell","price":3110.44,"timestamp":"2024-05-18T15:46:23.484Z"},{"symbol":"ETHUSDT","id":32402517421,"side":"Buy","price":3108.82,"timestamp":"2024-05-18T15:46:23.484Z"},{"symbol":"ETHUSDT","id":32402505366,"side":"Buy","price":3106.92,"timestamp":"2024-05-18T15:46:23.484Z"}]}
{"table":"orderBookL2_25","action":"update","data":[{"symbol":"ETHUSDT","id":32402517388,"side":"Buy","size":411000,"price":3108.45,"timestamp":"2024-05-18T15:46:23.484Z"},{"symbol":"ETHUSDT","id":32402512570,"side":"Buy","size":24000,"price":3108.81,"timestamp":"2024-05-18T15:46:23.484Z"}]}
{"table":"orderBookL2_25","action":"insert","data":[{"symbol":"ETHUSDT","id":32402517490,"side":"Sell","size":32000,"price":3110.46,"timestamp":"2024-05-18T15:46:23.484Z"},{"symbol":"ETHUSDT","id":32402447682,"side":"Sell","size":100000,"price":3112.68,"timestamp":"2024-05-18T15:46:23.484Z"},{"symbol":"ETHUSDT","id":32402517483,"side":"Buy","size":43000,"price":3109.41,"timestamp":"2024-05-18T15:46:23.484Z"},{"symbol":"ETHUSDT","id":32402517496,"side":"Buy","size":32000,"price":3108.84,"timestamp":"2024-05-18T15:46:23.484Z"}]}
{"table":"orderBookL2_25","action":"delete","data":[{"symbol":"XBTUSDT","id":32402517393,"side":"Sell","price":66782.9,"timestamp":"2024-05-18T15:46:23.496Z"},{"symbol":"XBTUSDT","id":32402517329,"side":"Sell","price":66775.0,"timestamp":"2024-05-18T15:46:23.496Z"},{"symbol":"XBTUSDT","id":32402517347,"side":"Sell","price":66775.6,"timestamp":"2024-05-18T15:46:23.496Z"},{"symbol":"XBTUSDT","id":32402516769,"side":"Sell","price":66771.6,"timestamp":"2024-05-18T15:46:23.496Z"},{"symbol":"XBTUSDT","id":32402517326,"side":"Buy","price":66737.5,"timestamp":"2024-05-18T15:46:23.496Z"},{"symbol":"XBTUSDT","id":32401552282,"side":"Buy","price":66720.0,"timestamp":"2024-05-18T15:46:23.496Z"},{"symbol":"XBTUSDT","id":32402517089,"side":"Buy","price":66732.0,"timestamp":"2024-05-18T15:46:23.496Z"}]}
{"table":"orderBookL2_25","action":"update","data":[{"symbol":"XBTUSDT","id":32402506378,"side":"Sell","size":232000,"price":66764.5,"timestamp":"2024-05-18T15:46:23.496Z"},{"symbol":"XBTUSDT","id":32402505821,"side":"Buy","size":147000,"price":66764.4,"timestamp":"2024-05-18T15:46:23.496Z"},{"symbol":"XBTUSDT","id":32401547573,"side":"Buy","size":100000,"price":66723.1,"timestamp":"2024-05-18T15:46:23.496Z"},{"symbol":"XBTUSDT","id":32402507156,"side":"Buy","size":100000,"price":66747.4,"timestamp":"2024-05-18T15:46:23.496Z"}]}
{"table":"orderBookL2_25","action":"insert","data":[{"symbol":"XBTUSDT","id":32402517537,"side":"Sell","size":1000,"price":66782.7,"timestamp":"2024-05-18T15:46:23.496Z"},{"symbol":"XBTUSDT","id":32402517579,"side":"Sell","size":10000,"price":66768.9,"timestamp":"2024-05-18T15:46:23.496Z"},{"symbol":"XBTUSDT","id":32402517503,"side":"Sell","size":20000,"price":66775.4,"timestamp":"2024-05-18T15:46:23.496Z"},{"symbol":"XBTUSDT","id":32402517588,"side":"Sell","size":348000,"price":66775.2,"timestamp":"2024-05-18T15:46:23.496Z"},{"symbol":"XBTUSDT","id":32402517584,"side":"Buy","size":349000,"price":66740.7,"timestamp":"2024-05-18T15:46:23.496Z"},{"symbol":"XBTUSDT","id":32402517532,"side":"Buy","size":100000,"price":66757.6,"timestamp":"2024-05-18T15:46:23.496Z"},{"symbol":"XBTUSDT","id":32402517499,"side":"Buy","size":20000,"price":66747.2,"timestamp":"2024-05-18T15:46:23.496Z"}]}
{"table":"orderBookL2_25","action":"delete","data":[{"symbol":"XBTUSDT","id":32402517395,"side":"Sell","price":66782.8,"timestamp":"2024-05-18T15:46:23.545Z"},{"symbol":"XBTUSDT","id":32402517588,"side":"Sell","price":66775.2,"timestamp":"2024-05-18T15:46:23.545Z"},{"symbol":"XBTUSDT","id":32402517343,"side":"Sell","price":66775.5,"timestamp":"2024-05-18T15:46:23.545Z"},{"symbol":"XBTUSDT","id":32402511349,"side":"Buy","price":66727.0,"timestamp":"2024-05-18T15:46:23.545Z"},{"symbol":"XBTUSDT","id":32401547573,"side":"Buy","price":66723.1,"timestamp":"2024-05-18T15:46:23.545Z"},{"symbol":"XBTUSDT","id":32402517499,"side":"Buy","price":66747.2,"timestamp":"2024-05-18T15:46:23.545Z"}]}
{"table":"orderBookL2_25","action":"update","data":[{"symbol":"XBTUSDT","id":32402507156,"side":"Buy","size":120000,"price":66747.4,"timestamp":"2024-05-18T15:46:23.545Z"}]}
{"table":"orderBookL2_25","action":"insert","data":[{"symbol":"XBTUSDT","id":32402517644,"side":"Sell","size":1000,"price":66782.6,"timestamp":"2024-05-18T15:46:23.545Z"},{"symbol":"XBTUSDT","id":32402517649,"side":"Sell","size":20000,"price":66775.3,"timestamp":"2024-05-18T15:46:23.545Z"},{"symbol":"XBTUSDT","id":32402517633,"side":"Sell","size":359000,"price":66776.8,"timestamp":"2024-05-18T15:46:23.545Z"},{"symbol":"XBTUSDT","id":32402517625,"side":"Buy","size":100000,"price":66744.0,"timestamp":"2024-05-18T15:46:23.545Z"},{"symbol":"XBTUSDT","id":32402517699,"side":"Buy","size":20000,"price":66735.0,"timestamp":"2024-05-18T15:46:23.545Z"},{"symbol":"XBTUSDT","id":32402517704,"side":"Buy","size":18000,"price":66733.5,"timestamp":"2024-05-18T15:46:23.545Z"}]}
{"table":"orderBookL2_25","action":"delete","data":[{"symbol":"ETHUSDT","id":32402504254,"side":"Buy","price":3106.99,"timestamp":"2024-05-18T15:46:23.547Z"}]}
{"table":"orderBookL2_25","action":"update","data":[{"symbol":"ETHUSDT","id":32402512820,"side":"Buy","size":241000,"price":3108.83,"timestamp":"2024-05-18T15:46:23.547Z"}]}
{"table":"orderBookL2_25","action":"insert","data":[{"symbol":"ETHUSDT","id":32402517722,"side":"Buy","size":32000,"price":3108.85,"timestamp":"2024-05-18T15:46:23.547Z"}]}
{"table":"orderBookL2_25","action":"delete","data":[{"symbol":"XBTUSDT","id":32402517644,"side":"Sell","price":66782.6,"timestamp":"2024-05-18T15:46:23.594Z"},{"symbol":"XBTUSDT","id":32402517537,"side":"Sell","price":66782.7,"timestamp":"2024-05-18T15:46:23.594Z"},{"symbol":"XBTUSDT","id":32402517579,"side":"Sell","price":66768.9,"timestamp":"2024-05-18T15:46:23.594Z"},{"symbol":"XBTUSDT","id":32402517649,"side":"Sell","price":66775.3,"timestamp":"2024-05-18T15:46:23.594Z"},{"symbol":"XBTUSDT","id":32402515468,"side":"Sell","price":66771.8,"timestamp":"2024-05-18T15:46:23.594Z"},{"symbol":"XBTUSDT","id":32402517238,"side":"Buy","price":66747.3,"timestamp":"2024-05-18T15:46:23.594Z"}]}
{"table":"orderBookL2_25","action":"update","data":[{"symbol":"XBTUSDT","id":32402507340,"side":"Sell","size":2000,"price":66790.3,"timestamp":"2024-05-18T15:46:23.594Z"},{"symbol":"XBTUSDT","id":32402499098,"side":"Sell","size":100000,"price":66792.1,"timestamp":"2024-05-18T15:46:23.594Z"},{"symbol":"XBTUSDT","id":32402508983,"side":"Buy","size":42000,"price":66747.5,"timestamp":"2024-05-18T15:46:23.594Z"}]}
{"table":"orderBookL2_25","action":"insert","data":[{"symbol":"XBTUSDT","id":32402517796,"side":"Sell","size":1000,"price":66782.8,"timestamp":"2024-05-18T15:46:23.594Z"},{"symbol":"XBTUSDT","id":32402517787,"side":"Sell","size":220000,"price":66776.7,"timestamp":"2024-05-18T15:46:23.594Z"},{"symbol":"XBTUSDT","id":32402517718,"side":"Sell","size":70000,"price":66767.8,"timestamp":"2024-05-18T15:46:23.594Z"},{"symbol":"XBTUSDT","id":32402517799,"side":"Sell","size":1000,"price":66782.9,"timestamp":"2024-05-18T15:46:23.594Z"},{"symbol":"XBTUSDT","id":32402517782,"side":"Sell","size":20000,"price":66775.5,"timestamp":"2024-05-18T15:46:23.594Z"},{"symbol":"XBTUSDT","id":32402511349,"side":"Buy","size":100000,"price":66727.0,"timestamp":"2024-05-18T15:46:23.594Z"}]}
{"table":"orderBookL2_25","action":"delete","data":[{"symbol":"ETHUSDT","id":32402447682,"side":"Sell","price":3112.68,"timestamp":"2024-05-18T15:46:23.597Z"},{"symbol":"ETHUSDT","id":32402517490,"side":"Sell","price":3110.46,"timestamp":"2024-05-18T15:46:23.597Z"},{"symbol":"ETHUSDT","id":32402517722,"side":"Buy","price":3108.85,"timestamp":"2024-05-18T15:46:23.597Z"}]}
{"table":"orderBookL2_25","action":"update","data":[{"symbol":"ETHUSDT","id":32402512820,"side":"Buy","size":273000,"price":3108.83,"timestamp":"2024-05-18T15:46:23.597Z"}]}
{"table":"orderBookL2_25","action":"insert","data":[{"symbol":"ETHUSDT","id":32402517777,"side":"Sell","size":32000,"price":3110.46,"timestamp":"2024-05-18T15:46:23.597Z"},{"symbol":"ETHUSDT","id":32402517758,"side":"Sell","size":160000,"price":3110.81,"timestamp":"2024-05-18T15:46:23.597Z"},{"symbol":"ETHUSDT","id":32402504254,"side":"Buy","size":2300000,"price":3106.99,"timestamp":"2024-05-18T15:46:23.597Z"}]}
{"table":"orderBookL2_25","action":"delete","data":[{"symbol":"XBTUSDT","id":32402517782,"side":"Sell","price":66775.5,"timestamp":"2024-05-18T15:46:23.643Z"},{"symbol":"XBTUSDT","id":32402517796,"side":"Sell","price":66782.8,"timestamp":"2024-05-18T15:46:23.643Z"},{"symbol":"XBTUSDT","id":32402499098,"side":"Sell","price":66792.1,"timestamp":"2024-05-18T15:46:23.643Z"},{"symbol":"XBTUSDT","id":32402517503,"side":"Sell","price":66775.4,"timestamp":"2024-05-18T15:46:23.643Z"},{"symbol":"XBTUSDT","id":32402517799,"side":"Sell","price":66782.9,"timestamp":"2024-05-18T15:46:23.643Z"},{"symbol":"XBTUSDT","id":32402517704,"side":"Buy","price":66733.5,"timestamp":"2024-05-18T15:46:23.643Z"},{"symbol":"XBTUSDT","id":32402517699,"side":"Buy","price":66735.0,"timestamp":"2024-05-18T15:46:23.643Z"}]}
{"table":"orderBookL2_25","action":"update","data":[{"symbol":"XBTUSDT","id":32402511466,"side":"Buy","size":62000,"price":66727.1,"timestamp":"2024-05-18T15:46:23.643Z"},{"symbol":"XBTUSDT","id":32402511349,"side":"Buy","size":100000,"price":66727.0,"timestamp":"2024-05-18T15:46:23.643Z"},{"symbol":"XBTUSDT","id":32402508983,"side":"Buy","size":22000,"price":66747.5,"timestamp":"2024-05-18T15:46:23.643Z"},{"symbol":"XBTUSDT","id":32402507156,"side":"Buy","size":100000,"price":66747.4,"timestamp":"2024-05-18T15:46:23.643Z"}]}
{"table":"orderBookL2_25","action":"insert","data":[{"symbol":"XBTUSDT","id":32402517832,"side":"Sell","size":19000,"price":66781.7,"timestamp":"2024-05-18T15:46:23.643Z"},{"symbol":"XBTUSDT","id":32402517852,"side":"Sell","size":1000,"price":66782.9,"timestamp":"2024-05-18T15:46:23.643Z"},{"symbol":"XBTUSDT","id":32402517903,"side":"Sell","size":20000,"price":66775.7,"timestamp":"2024-05-18T15:46:23.643Z"},{"symbol":"XBTUSDT","id":32402517870,"side":"Sell","size":1000,"price":66783.0,"timestamp":"2024-05-18T15:46:23.643Z"},{"symbol":"XBTUSDT","id":32402517829,"side":"Sell","size":20000,"price":66775.6,"timestamp":"2024-05-18T15:46:23.643Z"},{"symbol":"XBTUSDT","id":32402517865,"side":"Buy","size":20000,"price":66748.2,"timestamp":"2024-05-18T15:46:23.643Z"},{"symbol":"XBTUSDT","id":32402517875,"side":"Buy","size":20000,"price":66748.1,"timestamp":"2024-05-18T15:46:23.643Z"}]}
{"table":"orderBookL2_25","action":"delete","data":[{"symbol":"ETHUSDT","id":32402517777,"side":"Sell","price":3110.46,"timestamp":"2024-05-18T15:46:23.646Z"},{"symbol":"ETHUSDT","id":32402504254,"side":"Buy","price":3106.99,"timestamp":"2024-05-18T15:46:23.646Z"}]}
{"table":"orderBookL2_25","action":"update","data":[{"symbol":"ETHUSDT","id":32402512820,"side":"Buy","size":273000,"price":3108.83,"timestamp":"2024-05-18T15:46:23.646Z"},{"symbol":"ETHUSDT","id":32402511227,"side":"Buy","size":1126000,"price":3107.00,"timestamp":"2024-05-18T15:46:23.646Z"}]}
{"table":"orderBookL2_25","action":"insert","data":[{"symbol":"ETHUSDT","id":32402517868,"side":"Sell","size":32000,"price":3110.46,"timestamp":"2024-05-18T15:46:23.646Z"},{"symbol":"ETHUSDT","id":32402517862,"side":"Buy","size":255000,"price":3108.46,"timestamp":"2024-05-18T15:46:23.646Z"}]}
{"table":"orderBookL2_25","action":"delete","data":[{"symbol":"XBTUSDT","id":32402507340,"side":"Sell","price":66790.3,"timestamp":"2024-05-18T15:46:23.692Z"},{"symbol":"XBTUSDT","id":32402517870,"side":"Sell","price":66783.0,"timestamp":"2024-05-18T15:46:23.692Z"},{"symbol":"XBTUSDT","id":32402517852,"side":"Sell","price":66782.9,"timestamp":"2024-05-18T15:46:23.692Z"},{"symbol":"XBTUSDT","id":32402517865,"side":"Buy","price":66748.2,"timestamp":"2024-05-18T15:46:23.692Z"}]}
{"table":"orderBookL2_25","action":"insert","data":[{"symbol":"XBTUSDT","id":32402517964,"side":"Sell","size":20000,"price":66773.3,"timestamp":"2024-05-18T15:46:23.692Z"},{"symbol":"XBTUSDT","id":32402517936,"side":"Sell","size":1000,"price":66782.8,"timestamp":"2024-05-18T15:46:23.692Z"},{"symbol":"XBTUSDT","id":32402517949,"side":"Sell","size":1000,"price":66782.7,"timestamp":"2024-05-18T15:46:23.692Z"},{"symbol":"XBTUSDT","id":32402517907,"side":"Buy","size":20000,"price":66748.0,"timestamp":"2024-05-18T15:46:23.692Z"}]}
{"table":"orderBookL2_25","action":"delete","data":[{"symbol":"ETHUSDT","id":32402517384,"side":"Sell","price":3109.49,"timestamp":"2024-05-18T15:46:23.695Z"},{"symbol":"ETHUSDT","id":32402498106,"side":"Sell","price":3110.72,"timestamp":"2024-05-18T15:46:23.695Z"},{"symbol":"ETHUSDT","id":32402517245,"side":"Sell","price":3110.27,"timestamp":"2024-05-18T15:46:23.695Z"},{"symbol":"ETHUSDT","id":32402511227,"side":"Buy","price":3107.00,"timestamp":"2024-05-18T15:46:23.695Z"}]}
{"table":"orderBookL2_25","action":"update","data":[{"symbol":"ETHUSDT","id":32402516084,"side":"Sell","size":32000,"price":3110.45,"timestamp":"2024-05-18T15:46:23.695Z"}]}
{"table":"orderBookL2_25","action":"insert","data":[{"symbol":"ETHUSDT","id":32402476065,"side":"Sell","size":120000,"price":3112.99,"timestamp":"2024-05-18T15:46:23.695Z"},{"symbol":"ETHUSDT","id":32402447682,"side":"Sell","size":100000,"price":3112.68,"timestamp":"2024-05-18T15:46:23.695Z"},{"symbol":"ETHUSDT","id":32402470274,"side":"Sell","size":100000,"price":3112.84,"timestamp":"2024-05-18T15:46:23.695Z"},{"symbol":"ETHUSDT","id":32402517960,"side":"Buy","size":100000,"price":3108.61,"timestamp":"2024-05-18T15:46:23.695Z"}]}
{"table":"orderBookL2_25","action":"delete","data":[{"symbol":"XBTUSDT","id":32402516761,"side":"Sell","price":66777.1,"timestamp":"2024-05-18T15:46:23.741Z"},{"symbol":"XBTUSDT","id":32402517936,"side":"Sell","price":66782.8,"timestamp":"2024-05-18T15:46:23.741Z"},{"symbol":"XBTUSDT","id":32402517301,"side":"Sell","price":66766.2,"timestamp":"2024-05-18T15:46:23.741Z"},{"symbol":"XBTUSDT","id":32402517949,"side":"Sell","price":66782.7,"timestamp":"2024-05-18T15:46:23.741Z"}]}
{"table":"orderBookL2_25","action":"update","data":[{"symbol":"XBTUSDT","id":32402505821,"side":"Buy","size":47000,"price":66764.4,"timestamp":"2024-05-18T15:46:23.741Z"}]}
{"table":"orderBookL2_25","action":"insert","data":[{"symbol":"XBTUSDT","id":32402507340,"side":"Sell","size":2000,"price":66790.3,"timestamp":"2024-05-18T15:46:23.741Z"},{"symbol":"XBTUSDT","id":32402518019,"side":"Sell","size":3000,"price":66783.9,"timestamp":"2024-05-18T15:46:23.741Z"},{"symbol":"XBTUSDT","id":32402518013,"side":"Sell","size":1000,"price":66783.0,"timestamp":"2024-05-18T15:46:23.741Z"},{"symbol":"XBTUSDT","id":32402518016,"side":"Sell","size":1000,"price":66782.9,"timestamp":"2024-05-18T15:46:23.741Z"}]}
{"table":"orderBookL2_25","action":"delete","data":[{"symbol":"ETHUSDT","id":32402517429,"side":"Sell","price":3109.85,"timestamp":"2024-05-18T15:46:23.744Z"},{"symbol":"ETHUSDT","id":32402470274,"side":"Sell","price":3112.84,"timestamp":"2024-05-18T15:46:23.744Z"},{"symbol":"ETHUSDT","id":32402476065,"side":"Sell","price":3112.99,"timestamp":"2024-05-18T15:46:23.744Z"},{"symbol":"ETHUSDT","id":32402498109,"side":"Sell","price":3110.71,"timestamp":"2024-05-18T15:46:23.744Z"}]}
{"table":"orderBookL2_25","action":"insert","data":[{"symbol":"ETHUSDT","id":32402518022,"side":"Sell","size":28000,"price":3110.10,"timestamp":"2024-05-18T15:46:23.744Z"},{"symbol":"ETHUSDT","id":32402517986,"side":"Sell","size":28000,"price":3110.21,"timestamp":"2024-05-18T15:46:23.744Z"},{"symbol":"ETHUSDT","id":32402517984,"side":"Sell","size":100000,"price":3109.74,"timestamp":"2024-05-18T15:46:23.744Z"},{"symbol":"ETHUSDT","id":32402517979,"side":"Sell","size":100000,"price":3110.65,"timestamp":"2024-05-18T15:46:23.744Z"}]}
{"table":"orderBookL2_25","action":"delete","data":[{"symbol":"XBTUSDT","id":32402507340,"side":"Sell","price":66790.3,"timestamp":"2024-05-18T15:46:23.790Z"},{"symbol":"XBTUSDT","id":32402499271,"side":"Sell","price":66788.7,"timestamp":"2024-05-18T15:46:23.790Z"},{"symbol":"XBTUSDT","id":32402518013,"side":"Sell","price":66783.0,"timestamp":"2024-05-18T15:46:23.790Z"},{"symbol":"XBTUSDT","id":32402517903,"side":"Sell","price":66775.7,"timestamp":"2024-05-18T15:46:23.790Z"},{"symbol":"XBTUSDT","id":32402517907,"side":"Buy","price":66748.0,"timestamp":"2024-05-18T15:46:23.790Z"}]}
{"table":"orderBookL2_25","action":"update","data":[{"symbol":"XBTUSDT","id":32402506714,"side":"Sell","size":356000,"price":66772.0,"timestamp":"2024-05-18T15:46:23.790Z"}]}
{"table":"orderBookL2_25","action":"insert","data":[{"symbol":"XBTUSDT","id":32402518030,"side":"Sell","size":1000,"price":66782.8,"timestamp":"2024-05-18T15:46:23.790Z"},{"symbol":"XBTUSDT","id":32402518071,"side":"Sell","size":20000,"price":66775.5,"timestamp":"2024-05-18T15:46:23.790Z"},{"symbol":"XBTUSDT","id":32402518035,"side":"Sell","size":8000,"price":66765.9,"timestamp":"2024-05-18T15:46:23.790Z"},{"symbol":"XBTUSDT","id":32402518042,"side":"Sell","size":221000,"price":66771.9,"timestamp":"2024-05-18T15:46:23.790Z"},{"symbol":"XBTUSDT","id":32402518064,"side":"Buy","size":20000,"price":66748.2,"timestamp":"2024-05-18T15:46:23.790Z"}]}
{"table":"orderBookL2_25","action":"delete","data":[{"symbol":"ETHUSDT","id":32402517984,"side":"Sell","price":3109.74,"timestamp":"2024-05-18T15:46:23.793Z"},{"symbol":"ETHUSDT","id":32402517986,"side":"Sell","price":3110.21,"timestamp":"2024-05-18T15:46:23.793Z"}]}
{"table":"orderBookL2_25","action":"update","data":[{"symbol":"ETHUSDT","id":32402517386,"side":"Sell","size":914000,"price":3110.02,"timestamp":"2024-05-18T15:46:23.793Z"},{"symbol":"ETHUSDT","id":32402505932,"side":"Sell","size":1000,"price":3112.60,"timestamp":"2024-05-18T15:46:23.793Z"},{"symbol":"ETHUSDT","id":32402447682,"side":"Sell","size":100000,"price":3112.68,"timestamp":"2024-05-18T15:46:23.793Z"}]}
{"table":"orderBookL2_25","action":"insert","data":[{"symbol":"ETHUSDT","id":32402518081,"side":"Sell","size":100000,"price":3109.69,"timestamp":"2024-05-18T15:46:23.793Z"},{"symbol":"ETHUSDT","id":32402518079,"side":"Sell","size":548000,"price":3110.01,"timestamp":"2024-05-18T15:46:23.793Z"}]}
{"table":"orderBookL2_25","action":"delete","data":[{"symbol":"XBTUSDT","id":32402517031,"side":"Sell","price":66782.3,"timestamp":"2024-05-18T15:46:23.839Z"}]}
{"table":"orderBookL2_25","action":"insert","data":[{"symbol":"XBTUSDT","id":32402518107,"side":"Sell","size":3000,"price":66787.7,"timestamp":"2024-05-18T15:46:23.839Z"}]}
{"table":"orderBookL2_25","action":"delete","data":[{"symbol":"ETHUSDT","id":32402515605,"side":"Sell","price":3112.01,"timestamp":"2024-05-18T15:46:23.842Z"},{"symbol":"ETHUSDT","id":32402505932,"side":"Sell","price":3112.60,"timestamp":"2024-05-18T15:46:23.842Z"},{"symbol":"ETHUSDT","id":32402488716,"side":"Sell","price":3112.18,"timestamp":"2024-05-18T15:46:23.842Z"},{"symbol":"ETHUSDT","id":32402455680,"side":"Sell","price":3112.02,"timestamp":"2024-05-18T15:46:23.842Z"},{"symbol":"ETHUSDT","id":32402447682,"side":"Sell","price":3112.68,"timestamp":"2024-05-18T15:46:23.842Z"}]}
{"table":"orderBookL2_25","action":"update","data":[{"symbol":"ETHUSDT","id":32402518081,"side":"Sell","size":109000,"price":3109.69,"timestamp":"2024-05-18T15:46:23.842Z"},{"symbol":"ETHUSDT","id":32402517386,"side":"Sell","size":905000,"price":3110.02,"timestamp":"2024-05-18T15:46:23.842Z"}]}
{"table":"orderBookL2_25","action":"insert","data":[{"symbol":"ETHUSDT","id":32402518143,"side":"Sell","size":100000,"price":3109.61,"timestamp":"2024-05-18T15:46:23.842Z"},{"symbol":"ETHUSDT","id":32402518157,"side":"Sell","size":100000,"price":3110.41,"timestamp":"2024-05-18T15:46:23.842Z"},{"symbol":"ETHUSDT","id":32402518137,"side":"Sell","size":61000,"price":3109.68,"timestamp":"2024-05-18T15:46:23.842Z"},{"symbol":"ETHUSDT","id":32402518151,"side":"Sell","size":28000,"price":3109.97,"timestamp":"2024-05-18T15:46:23.842Z"},{"symbol":"ETHUSDT","id":32402518145,"side":"Sell","size":28000,"price":3110.34,"timestamp":"2024-05-18T15:46:23.842Z"}]}
{"table":"orderBookL2_25","action":"delete","data":[{"symbol":"ETHUSDT","id":32402518022,"side":"Sell","price":3110.10,"timestamp":"2024-05-18T15:46:23.891Z"},{"symbol":"ETHUSDT","id":32402518145,"side":"Sell","price":3110.34,"timestamp":"2024-05-18T15:46:23.891Z"}]}
{"table":"orderBookL2_25","action":"update","data":[{"symbol":"ETHUSDT","id":32402518081,"side":"Sell","size":100000,"price":3109.69,"timestamp":"2024-05-18T15:46:23.891Z"},{"symbol":"ETHUSDT","id":32402518143,"side":"Sell","size":109000,"price":3109.61,"timestamp":"2024-05-18T15:46:23.891Z"}]}
{"table":"orderBookL2_25","action":"insert","data":[{"symbol":"ETHUSDT","id":32402518194,"side":"Sell","size":63000,"price":3110.40,"timestamp":"2024-05-18T15:46:23.891Z"},{"symbol":"ETHUSDT","id":32402515605,"side":"Sell","size":574000,"price":3112.01,"timestamp":"2024-05-18T15:46:23.891Z"}]}
{"table":"orderBookL2_25","action":"delete","data":[{"symbol":"XBTUSDT","id":32402512008,"side":"Sell","price":66788.6,"timestamp":"2024-05-18T15:46:23.896Z"}]}
{"table":"orderBookL2_25","action":"insert","data":[{"symbol":"XBTUSDT","id":32402518202,"side":"Sell","size":8000,"price":66765.8,"timestamp":"2024-05-18T15:46:23.896Z"}]}
{"table":"orderBookL2_25","action":"delete","data":[{"symbol":"XBTUSDT","id":32402517250,"side":"Sell","price":66766.0,"timestamp":"2024-05-18T15:46:23.946Z"}]}
{"table":"orderBookL2_25","action":"insert","data":[{"symbol":"XBTUSDT","id":32402512008,"side":"Sell","size":68000,"price":66788.6,"timestamp":"2024-05-18T15:46:23.946Z"}]}
{"table":"orderBookL2_25","action":"delete","data":[{"symbol":"XBTUSDT","id":32402511349,"side":"Buy","price":66727.0,"timestamp":"2024-05-18T15:46:23.995Z"}]}
{"table":"orderBookL2_25","action":"insert","data":[{"symbol":"XBTUSDT","id":32402518323,"side":"Buy","size":156000,"price":66737.5,"timestamp":"2024-05-18T15:46:23.995Z"}]}
{"table":"orderBookL2_25","action":"delete","data":[{"symbol":"ETHUSDT","id":32402517868,"side":"Sell","price":3110.46,"timestamp":"2024-05-18T15:46:24.007Z"}]}
{"table":"orderBookL2_25","action":"insert","data":[{"symbol":"ETHUSDT","id":32402518335,"side":"Sell","size":32000,"price":3110.44,"timestamp":"2024-05-18T15:46:24.007Z"}]}
{"table":"orderBookL2_25","action":"delete","data":[{"symbol":"XBTUSDT","id":32402511466,"side":"Buy","price":66727.1,"timestamp":"2024-05-18T15:46:24.044Z"},{"symbol":"XBTUSDT","id":32402510029,"side":"Buy","price":66730.1,"timestamp":"2024-05-18T15:46:24.044Z"}]}
{"table":"orderBookL2_25","action":"insert","data":[{"symbol":"XBTUSDT","id":32402518359,"side":"Buy","size":18000,"price":66732.5,"timestamp":"2024-05-18T15:46:24.044Z"},{"symbol":"XBTUSDT","id":32402518361,"side":"Buy","size":20000,"price":66734.0,"timestamp":"2024-05-18T15:46:24.044Z"}]}
{"table":"orderBookL2_25","action":"delete","data":[{"symbol":"ETHUSDT","id":32402515605,"side":"Sell","price":3112.01,"timestamp":"2024-05-18T15:46:24.056Z"},{"symbol":"ETHUSDT","id":32402506878,"side":"Buy","price":3107.03,"timestamp":"2024-05-18T15:46:24.056Z"}]}
{"table":"orderBookL2_25","action":"update","data":[{"symbol":"ETHUSDT","id":32402512820,"side":"Buy","size":241000,"price":3108.83,"timestamp":"2024-05-18T15:46:24.056Z"}]}
{"table":"orderBookL2_25","action":"insert","data":[{"symbol":"ETHUSDT","id":32402518340,"side":"Sell","size":64000,"price":3110.64,"timestamp":"2024-05-18T15:46:24.056Z"},{"symbol":"ETHUSDT","id":32402518338,"side":"Buy","size":32000,"price":3108.85,"timestamp":"2024-05-18T15:46:24.056Z"}]}
{"table":"orderBookL2_25","action":"delete","data":[{"symbol":"XBTETH","id":32402422012,"side":"Buy","price":20.840,"timestamp":"2024-05-18T15:46:24.091Z"}]}
{"table":"orderBookL2_25","action":"insert","data":[{"symbol":"XBTETH","id":32402518398,"side":"Buy","size":7,"price":20.835,"timestamp":"2024-05-18T15:46:24.091Z"}]}
{"table":"orderBookL2_25","action":"delete","data":[{"symbol":"XBTUSDT","id":32402516518,"side":"Sell","price":66766.1,"timestamp":"2024-05-18T15:46:24.093Z"}]}
{"table":"orderBookL2_25","action":"insert","data":[{"symbol":"XBTUSDT","id":32402518388,"side":"Sell","size":8000,"price":66765.7,"timestamp":"2024-05-18T15:46:24.093Z"}]}
{"table":"orderBookL2_25","action":"delete","data":[{"symbol":"XBTUSDT","id":32402512008,"side":"Sell","price":66788.6,"timestamp":"2024-05-18T15:46:24.142Z"}]}
{"table":"orderBookL2_25","action":"update","data":[{"symbol":"XBTUSDT","id":32402502861,"side":"Sell","size":174000,"price":66784.3,"timestamp":"2024-05-18T15:46:24.142Z"}]}
{"table":"orderBookL2_25","action":"insert","data":[{"symbol":"XBTUSDT","id":32402518415,"side":"Sell","size":2000,"price":66771.8,"timestamp":"2024-05-18T15:46:24.142Z"}]}
{"table":"orderBookL2_25","action":"delete","data":[{"symbol":"ETHUSDT","id":32402518338,"side":"Buy","price":3108.85,"timestamp":"2024-05-18T15:46:24.167Z"}]}
{"table":"orderBookL2_25","action":"update","data":[{"symbol":"ETHUSDT","id":32402512820,"side":"Buy","size":273000,"price":3108.83,"timestamp":"2024-05-18T15:46:24.167Z"}]}
{"table":"orderBookL2_25","action":"insert","data":[{"symbol":"ETHUSDT","id":32402506878,"side":"Buy","size":160000,"price":3107.03,"timestamp":"2024-05-18T15:46:24.167Z"}]}
{"table":"orderBookL2_25","action":"delete","data":[{"symbol":"XBTUSDT","id":32402518030,"side":"Sell","price":66782.8,"timestamp":"2024-05-18T15:46:24.191Z"},{"symbol":"XBTUSDT","id":32402518071,"side":"Sell","price":66775.5,"timestamp":"2024-05-18T15:46:24.191Z"},{"symbol":"XBTUSDT","id":32402518064,"side":"Buy","price":66748.2,"timestamp":"2024-05-18T15:46:24.191Z"}]}
{"table":"orderBookL2_25","action":"insert","data":[{"symbol":"XBTUSDT","id":32402518437,"side":"Sell","size":1000,"price":66783.0,"timestamp":"2024-05-18T15:46:24.191Z"},{"symbol":"XBTUSDT","id":32402518441,"side":"Sell","size":20000,"price":66775.7,"timestamp":"2024-05-18T15:46:24.191Z"},{"symbol":"XBTUSDT","id":32402518443,"side":"Buy","size":20000,"price":66748.0,"timestamp":"2024-05-18T15:46:24.191Z"}]}
{"table":"orderBookL2_25","action":"delete","data":[{"symbol":"ETHUSDT","id":32402518335,"side":"Sell","price":3110.44,"timestamp":"2024-05-18T15:46:24.217Z"}]}
{"table":"orderBookL2_25","action":"insert","data":[{"symbol":"ETHUSDT","id":32402518448,"side":"Sell","size":32000,"price":3110.46,"timestamp":"2024-05-18T15:46:24.217Z"}]}
{"table":"orderBookL2_25","action":"delete","data":[{"symbol":"XBTUSDT","id":32402517718,"side":"Sell","price":66767.8,"timestamp":"2024-05-18T15:46:24.240Z"},{"symbol":"XBTUSDT","id":32402517964,"side":"Sell","price":66773.3,"timestamp":"2024-05-18T15:46:24.240Z"},{"symbol":"XBTUSDT","id":32402510648,"side":"Buy","price":66755.4,"timestamp":"2024-05-18T15:46:24.240Z"}]}
{"table":"orderBookL2_25","action":"update","data":[{"symbol":"XBTUSDT","id":32402506378,"side":"Sell","size":182000,"price":66764.5,"timestamp":"2024-05-18T15:46:24.240Z"},{"symbol":"XBTUSDT","id":32402505821,"side":"Buy","size":147000,"price":66764.4,"timestamp":"2024-05-18T15:46:24.240Z"}]}
{"table":"orderBookL2_25","action":"insert","data":[{"symbol":"XBTUSDT","id":32402499271,"side":"Sell","size":100000,"price":66788.7,"timestamp":"2024-05-18T15:46:24.240Z"},{"symbol":"XBTUSDT","id":32402512008,"side":"Sell","size":68000,"price":66788.6,"timestamp":"2024-05-18T15:46:24.240Z"},{"symbol":"XBTUSDT","id":32402518498,"side":"Buy","size":20000,"price":66760.8,"timestamp":"2024-05-18T15:46:24.240Z"}]}
{"table":"orderBookL2_25","action":"delete","data":[{"symbol":"XBTUSDT","id":32402499271,"side":"Sell","price":66788.7,"timestamp":"2024-05-18T15:46:24.289Z"},{"symbol":"XBTUSDT","id":32402518107,"side":"Sell","price":66787.7,"timestamp":"2024-05-18T15:46:24.289Z"},{"symbol":"XBTUSDT","id":32402505149,"side":"Buy","price":66730.4,"timestamp":"2024-05-18T15:46:24.289Z"}]}
{"table":"orderBookL2_25","action":"update","data":[{"symbol":"XBTUSDT","id":32402506378,"side":"Sell","size":138000,"price":66764.5,"timestamp":"2024-05-18T15:46:24.289Z"}]}
{"table":"orderBookL2_25","action":"insert","data":[{"symbol":"XBTUSDT","id":32402518549,"side":"Sell","size":62000,"price":66767.8,"timestamp":"2024-05-18T15:46:24.289Z"},{"symbol":"XBTUSDT","id":32402518553,"side":"Sell","size":3000,"price":66785.6,"timestamp":"2024-05-18T15:46:24.289Z"},{"symbol":"XBTUSDT","id":32402518556,"side":"Buy","size":3000,"price":66740.8,"timestamp":"2024-05-18T15:46:24.289Z"}]}
{"table":"orderBookL2_25","action":"delete","data":[{"symbol":"ETHUSDT","id":32402517173,"side":"Buy","price":3108.59,"timestamp":"2024-05-18T15:46:24.295Z"}]}
{"table":"orderBookL2_25","action":"insert","data":[{"symbol":"ETHUSDT","id":32402518574,"side":"Buy","size":1000,"price":3108.57,"timestamp":"2024-05-18T15:46:24.295Z"}]}
{"table":"orderBookL2_25","action":"delete","data":[{"symbol":"XBTUSDT","id":32402518441,"side":"Sell","price":66775.7,"timestamp":"2024-05-18T15:46:24.338Z"},{"symbol":"XBTUSDT","id":32402518016,"side":"Sell","price":66782.9,"timestamp":"2024-05-18T15:46:24.338Z"},{"symbol":"XBTUSDT","id":32402518437,"side":"Sell","price":66783.0,"timestamp":"2024-05-18T15:46:24.338Z"},{"symbol":"XBTUSDT","id":32402517829,"side":"Sell","price":66775.6,"timestamp":"2024-05-18T15:46:24.338Z"},{"symbol":"XBTUSDT","id":32402518443,"side":"Buy","price":66748.0,"timestamp":"2024-05-18T15:46:24.338Z"},{"symbol":"XBTUSDT","id":32402517875,"side":"Buy","price":66748.1,"timestamp":"2024-05-18T15:46:24.338Z"}]}
{"table":"orderBookL2_25","action":"update","data":[{"symbol":"XBTUSDT","id":32402511708,"side":"Sell","size":102000,"price":66783.3,"timestamp":"2024-05-18T15:46:24.338Z"},{"symbol":"XBTUSDT","id":32402506723,"side":"Sell","size":160000,"price":66783.4,"timestamp":"2024-05-18T15:46:24.338Z"}]}
{"table":"orderBookL2_25","action":"insert","data":[{"symbol":"XBTUSDT","id":32402518678,"side":"Sell","size":20000,"price":66776.0,"timestamp":"2024-05-18T15:46:24.338Z"},{"symbol":"XBTUSDT","id":32402518589,"side":"Sell","size":20000,"price":66773.3,"timestamp":"2024-05-18T15:46:24.338Z"},{"symbol":"XBTUSDT","id":32402518602,"side":"Sell","size":1000,"price":66783.5,"timestamp":"2024-05-18T15:46:24.338Z"},{"symbol":"XBTUSDT","id":32402518660,"side":"Sell","size":20000,"price":66776.3,"timestamp":"2024-05-18T15:46:24.338Z"},{"symbol":"XBTUSDT","id":32402518664,"side":"Buy","size":20000,"price":66747.8,"timestamp":"2024-05-18T15:46:24.338Z"},{"symbol":"XBTUSDT","id":32402518598,"side":"Buy","size":20000,"price":66747.9,"timestamp":"2024-05-18T15:46:24.338Z"}]}
{"table":"orderBookL2_25","action":"delete","data":[{"symbol":"ETHUSDT","id":32402517496,"side":"Buy","price":3108.84,"timestamp":"2024-05-18T15:46:24.345Z"},{"symbol":"ETHUSDT","id":32402515525,"side":"Buy","price":3108.60,"timestamp":"2024-05-18T15:46:24.345Z"}]}
{"table":"orderBookL2_25","action":"update","data":[{"symbol":"ETHUSDT","id":32402512820,"side":"Buy","size":241000,"price":3108.83,"timestamp":"2024-05-18T15:46:24.345Z"},{"symbol":"ETHUSDT","id":32402512570,"side":"Buy","size":56000,"price":3108.81,"timestamp":"2024-05-18T15:46:24.345Z"}]}
{"table":"orderBookL2_25","action":"insert","data":[{"symbol":"ETHUSDT","id":32402518587,"side":"Buy","size":1000,"price":3108.56,"timestamp":"2024-05-18T15:46:24.345Z"},{"symbol":"ETHUSDT","id":32402518627,"side":"Buy","size":32000,"price":3108.82,"timestamp":"2024-05-18T15:46:24.345Z"}]}
{"table":"orderBookL2_25","action":"delete","data":[{"symbol":"XBTUSDT","id":32402518678,"side":"Sell","price":66776.0,"timestamp":"2024-05-18T15:46:24.387Z"},{"symbol":"XBTUSDT","id":32402518660,"side":"Sell","price":66776.3,"timestamp":"2024-05-18T15:46:24.387Z"}]}
{"table":"orderBookL2_25","action":"insert","data":[{"symbol":"XBTUSDT","id":32402518756,"side":"Sell","size":20000,"price":66776.3,"timestamp":"2024-05-18T15:46:24.387Z"},{"symbol":"XBTUSDT","id":32402518754,"side":"Sell","size":20000,"price":66776.2,"timestamp":"2024-05-18T15:46:24.387Z"}]}
{"table":"orderBookL2_25","action":"delete","data":[{"symbol":"ETHUSDT","id":32402518587,"side":"Buy","price":3108.56,"timestamp":"2024-05-18T15:46:24.398Z"}]}
{"table":"orderBookL2_25","action":"insert","data":[{"symbol":"ETHUSDT","id":32402518769,"side":"Buy","size":1000,"price":3108.58,"timestamp":"2024-05-18T15:46:24.398Z"}]}
{"table":"orderBookL2_25","action":"delete","data":[{"symbol":"XBTUSDT","id":32402518756,"side":"Sell","price":66776.3,"timestamp":"2024-05-18T15:46:24.436Z"},{"symbol":"XBTUSDT","id":32402518589,"side":"Sell","price":66773.3,"timestamp":"2024-05-18T15:46:24.436Z"},{"symbol":"XBTUSDT","id":32402518754,"side":"Sell","price":66776.2,"timestamp":"2024-05-18T15:46:24.436Z"},{"symbol":"XBTUSDT","id":32402518602,"side":"Sell","price":66783.5,"timestamp":"2024-05-18T15:46:24.436Z"}]}
{"table":"orderBookL2_25","action":"update","data":[{"symbol":"XBTUSDT","id":32402511708,"side":"Sell","size":103000,"price":66783.3,"timestamp":"2024-05-18T15:46:24.436Z"}]}
{"table":"orderBookL2_25","action":"insert","data":[{"symbol":"XBTUSDT","id":32402499271,"side":"Sell","size":100000,"price":66788.7,"timestamp":"2024-05-18T15:46:24.436Z"},{"symbol":"XBTUSDT","id":32402518784,"side":"Sell","size":20000,"price":66776.0,"timestamp":"2024-05-18T15:46:24.436Z"},{"symbol":"XBTUSDT","id":32402507340,"side":"Sell","size":2000,"price":66790.3,"timestamp":"2024-05-18T15:46:24.436Z"},{"symbol":"XBTUSDT","id":32402518779,"side":"Sell","size":20000,"price":66776.1,"timestamp":"2024-05-18T15:46:24.436Z"}]}
{"table":"orderBookL2_25","action":"delete","data":[{"symbol":"ETHUSDT","id":32402517758,"side":"Sell","price":3110.81,"timestamp":"2024-05-18T15:46:24.447Z"},{"symbol":"ETHUSDT","id":32402506878,"side":"Buy","price":3107.03,"timestamp":"2024-05-18T15:46:24.447Z"}]}
{"table":"orderBookL2_25","action":"update","data":[{"symbol":"ETHUSDT","id":32402516754,"side":"Sell","size":284000,"price":3110.35,"timestamp":"2024-05-18T15:46:24.447Z"}]}
{"table":"orderBookL2_25","action":"insert","data":[{"symbol":"ETHUSDT","id":32402515605,"side":"Sell","size":574000,"price":3112.01,"timestamp":"2024-05-18T15:46:24.447Z"},{"symbol":"ETHUSDT","id":32402518836,"side":"Buy","size":65000,"price":3107.25,"timestamp":"2024-05-18T15:46:24.447Z"}]}
{"table":"orderBookL2_25","action":"delete","data":[{"symbol":"XBTUSDT","id":32402507340,"side":"Sell","price":66790.3,"timestamp":"2024-05-18T15:46:24.485Z"},{"symbol":"XBTUSDT","id":32402518779,"side":"Sell","price":66776.1,"timestamp":"2024-05-18T15:46:24.485Z"},{"symbol":"XBTUSDT","id":32402518664,"side":"Buy","price":66747.8,"timestamp":"2024-05-18T15:46:24.485Z"}]}
{"table":"orderBookL2_25","action":"update","data":[{"symbol":"XBTUSDT","id":32402506714,"side":"Sell","size":200000,"price":66772.0,"timestamp":"2024-05-18T15:46:24.485Z"},{"symbol":"XBTUSDT","id":32402506723,"side":"Sell","size":160000,"price":66783.4,"timestamp":"2024-05-18T15:46:24.485Z"},{"symbol":"XBTUSDT","id":32402518042,"side":"Sell","size":123000,"price":66771.9,"timestamp":"2024-05-18T15:46:24.485Z"}]}
{"table":"orderBookL2_25","action":"insert","data":[{"symbol":"XBTUSDT","id":32402518890,"side":"Sell","size":156000,"price":66775.9,"timestamp":"2024-05-18T15:46:24.485Z"},{"symbol":"XBTUSDT","id":32402518856,"side":"Sell","size":20000,"price":66776.1,"timestamp":"2024-05-18T15:46:24.485Z"},{"symbol":"XBTUSDT","id":32402518864,"side":"Buy","size":20000,"price":66747.8,"timestamp":"2024-05-18T15:46:24.485Z"}]}
{"table":"orderBookL2_25","action":"update","data":[{"symbol":"ETHUSDT","id":32402516754,"side":"Sell","size":43000,"price":3110.35,"timestamp":"2024-05-18T15:46:24.506Z"}]}
{"table":"orderBookL2_25","action":"delete","data":[{"symbol":"XBTUSDT","id":32402499271,"side":"Sell","price":66788.7,"timestamp":"2024-05-18T15:46:24.534Z"}]}
{"table":"orderBookL2_25","action":"insert","data":[{"symbol":"XBTUSDT","id":32402518900,"side":"Sell","size":20000,"price":66773.5,"timestamp":"2024-05-18T15:46:24.534Z"}]}
{"table":"orderBookL2_25","action":"delete","data":[{"symbol":"ETHUSDT","id":32402516084,"side":"Sell","price":3110.45,"timestamp":"2024-05-18T15:46:24.588Z"}]}
{"table":"orderBookL2_25","action":"insert","data":[{"symbol":"ETHUSDT","id":32402518969,"side":"Sell","size":32000,"price":3110.47,"timestamp":"2024-05-18T15:46:24.588Z"}]}
{"table":"orderBookL2_25","action":"delete","data":[{"symbol":"XBTUSDT","id":32402518019,"side":"Sell","price":66783.9,"timestamp":"2024-05-18T15:46:24.630Z"}]}
{"table":"orderBookL2_25","action":"insert","data":[{"symbol":"XBTUSDT","id":32402518994,"side":"Sell","size":3000,"price":66786.9,"timestamp":"2024-05-18T15:46:24.630Z"}]}
{"table":"orderBookL2_25","action":"delete","data":[{"symbol":"ETHUSDT","id":32402515605,"side":"Sell","price":3112.01,"timestamp":"2024-05-18T15:46:24.637Z"},{"symbol":"ETHUSDT","id":32402518969,"side":"Sell","price":3110.47,"timestamp":"2024-05-18T15:46:24.637Z"},{"symbol":"ETHUSDT","id":32402518448,"side":"Sell","price":3110.46,"timestamp":"2024-05-18T15:46:24.637Z"},{"symbol":"ETHUSDT","id":32402512025,"side":"Buy","price":3107.04,"timestamp":"2024-05-18T15:46:24.637Z"}]}
{"table":"orderBookL2_25","action":"insert","data":[{"symbol":"ETHUSDT","id":32402518976,"side":"Sell","size":160000,"price":3111.00,"timestamp":"2024-05-18T15:46:24.637Z"},{"symbol":"ETHUSDT","id":32402518991,"side":"Sell","size":32000,"price":3110.45,"timestamp":"2024-05-18T15:46:24.637Z"},{"symbol":"ETHUSDT","id":32402518989,"side":"Sell","size":32000,"price":3110.46,"timestamp":"2024-05-18T15:46:24.637Z"},{"symbol":"ETHUSDT","id":32402518973,"side":"Buy","size":67000,"price":3108.62,"timestamp":"2024-05-18T15:46:24.637Z"}]}
{"table":"orderBookL2_25","action":"delete","data":[{"symbol":"XBTUSDT","id":32402518856,"side":"Sell","price":66776.1,"timestamp":"2024-05-18T15:46:24.679Z"},{"symbol":"XBTUSDT","id":32402518864,"side":"Buy","price":66747.8,"timestamp":"2024-05-18T15:46:24.679Z"}]}
{"table":"orderBookL2_25","action":"update","data":[{"symbol":"XBTUSDT","id":32402518890,"side":"Sell","size":176000,"price":66775.9,"timestamp":"2024-05-18T15:46:24.679Z"}]}
{"table":"orderBookL2_25","action":"insert","data":[{"symbol":"XBTUSDT","id":32402499271,"side":"Sell","size":100000,"price":66788.7,"timestamp":"2024-05-18T15:46:24.679Z"},{"symbol":"XBTUSDT","id":32402519004,"side":"Buy","size":20000,"price":66748.0,"timestamp":"2024-05-18T15:46:24.679Z"}]}
{"table":"orderBookL2_25","action":"delete","data":[{"symbol":"ETHUSDT","id":32402518991,"side":"Sell","price":3110.45,"timestamp":"2024-05-18T15:46:24.686Z"}]}
{"table":"orderBookL2_25","action":"update","data":[{"symbol":"ETHUSDT","id":32402512820,"side":"Buy","size":273000,"price":3108.83,"timestamp":"2024-05-18T15:46:24.686Z"},{"symbol":"ETHUSDT","id":32402512570,"side":"Buy","size":24000,"price":3108.81,"timestamp":"2024-05-18T15:46:24.686Z"}]}
{"table":"orderBookL2_25","action":"insert","data":[{"symbol":"ETHUSDT","id":32402519013,"side":"Sell","size":32000,"price":3110.47,"timestamp":"2024-05-18T15:46:24.686Z"}]}
{"table":"orderBookL2_25","action":"delete","data":[{"symbol":"ETHUSDT","id":32402518989,"side":"Sell","price":3110.46,"timestamp":"2024-05-18T15:46:24.735Z"},{"symbol":"ETHUSDT","id":32402519013,"side":"Sell","price":3110.47,"timestamp":"2024-05-18T15:46:24.735Z"}]}
{"table":"orderBookL2_25","action":"update","data":[{"symbol":"ETHUSDT","id":32402512820,"side":"Buy","size":241000,"price":3108.83,"timestamp":"2024-05-18T15:46:24.735Z"},{"symbol":"ETHUSDT","id":32402512570,"side":"Buy","size":56000,"price":3108.81,"timestamp":"2024-05-18T15:46:24.735Z"}]}
{"table":"orderBookL2_25","action":"insert","data":[{"symbol":"ETHUSDT","id":32402519027,"side":"Sell","size":32000,"price":3110.48,"timestamp":"2024-05-18T15:46:24.735Z"},{"symbol":"ETHUSDT","id":32402519031,"side":"Sell","size":32000,"price":3110.47,"timestamp":"2024-05-18T15:46:24.735Z"}]}
{"table":"orderBookL2_25","action":"delete","data":[{"symbol":"XBTUSDT","id":32402518900,"side":"Sell","price":66773.5,"timestamp":"2024-05-18T15:46:24.777Z"}]}
{"table":"orderBookL2_25","action":"insert","data":[{"symbol":"XBTUSDT","id":32402499098,"side":"Sell","size":100000,"price":66792.1,"timestamp":"2024-05-18T15:46:24.777Z"}]}
{"table":"orderBookL2_25","action":"delete","data":[{"symbol":"ETHUSDT","id":32402516754,"side":"Sell","price":3110.35,"timestamp":"2024-05-18T15:46:24.784Z"},{"symbol":"ETHUSDT","id":32402518081,"side":"Sell","price":3109.69,"timestamp":"2024-05-18T15:46:24.784Z"},{"symbol":"ETHUSDT","id":32402518137,"side":"Sell","price":3109.68,"timestamp":"2024-05-18T15:46:24.784Z"},{"symbol":"ETHUSDT","id":32402513255,"side":"Sell","price":3110.73,"timestamp":"2024-05-18T15:46:24.784Z"},{"symbol":"ETHUSDT","id":32402518194,"side":"Sell","price":3110.40,"timestamp":"2024-05-18T15:46:24.784Z"},{"symbol":"ETHUSDT","id":32402488025,"side":"Buy","price":3107.08,"timestamp":"2024-05-18T15:46:24.784Z"}]}
{"table":"orderBookL2_25","action":"update","data":[{"symbol":"ETHUSDT","id":32402518143,"side":"Sell","size":9000,"price":3109.61,"timestamp":"2024-05-18T15:46:24.784Z"}]}
{"table":"orderBookL2_25","action":"insert","data":[{"symbol":"ETHUSDT","id":32402519107,"side":"Sell","size":933000,"price":3110.97,"timestamp":"2024-05-18T15:46:24.784Z"},{"symbol":"ETHUSDT","id":32402519064,"side":"Sell","size":26000,"price":3110.46,"timestamp":"2024-05-18T15:46:24.784Z"},{"symbol":"ETHUSDT","id":32402488716,"side":"Sell","size":100000,"price":3112.18,"timestamp":"2024-05-18T15:46:24.784Z"},{"symbol":"ETHUSDT","id":32402515605,"side":"Sell","size":574000,"price":3112.01,"timestamp":"2024-05-18T15:46:24.784Z"},{"symbol":"ETHUSDT","id":32402455680,"side":"Sell","size":100000,"price":3112.02,"timestamp":"2024-05-18T15:46:24.784Z"},{"symbol":"ETHUSDT","id":32402519097,"side":"Buy","size":100000,"price":3108.77,"timestamp":"2024-05-18T15:46:24.784Z"}]}
{"table":"orderBookL2_25","action":"delete","data":[{"symbol":"XBTUSDT","id":32402517832,"side":"Sell","price":66781.7,"timestamp":"2024-05-18T15:46:24.827Z"},{"symbol":"XBTUSDT","id":32402510711,"side":"Sell","price":66767.9,"timestamp":"2024-05-18T15:46:24.827Z"},{"symbol":"XBTUSDT","id":32402518549,"side":"Sell","price":66767.8,"timestamp":"2024-05-18T15:46:24.827Z"},{"symbol":"XBTUSDT","id":32402517787,"side":"Sell","price":66776.7,"timestamp":"2024-05-18T15:46:24.827Z"},{"symbol":"XBTUSDT","id":32402517633,"side":"Sell","price":66776.8,"timestamp":"2024-05-18T15:46:24.827Z"},{"symbol":"XBTUSDT","id":32402510878,"side":"Buy","price":66750.9,"timestamp":"2024-05-18T15:46:24.827Z"},{"symbol":"XBTUSDT","id":32402517584,"side":"Buy","price":66740.7,"timestamp":"2024-05-18T15:46:24.827Z"}]}
{"table":"orderBookL2_25","action":"update","data":[{"symbol":"XBTUSDT","id":32402499098,"side":"Sell","size":100000,"price":66792.1,"timestamp":"2024-05-18T15:46:24.827Z"},{"symbol":"XBTUSDT","id":32402506378,"side":"Sell","size":82000,"price":66764.5,"timestamp":"2024-05-18T15:46:24.827Z"},{"symbol":"XBTUSDT","id":32402506723,"side":"Sell","size":159000,"price":66783.4,"timestamp":"2024-05-18T15:46:24.827Z"}]}
{"table":"orderBookL2_25","action":"insert","data":[{"symbol":"XBTUSDT","id":32402501930,"side":"Sell","size":2000,"price":66792.7,"timestamp":"2024-05-18T15:46:24.827Z"},{"symbol":"XBTUSDT","id":32402511631,"side":"Sell","size":328000,"price":66795.4,"timestamp":"2024-05-18T15:46:24.827Z"},{"symbol":"XBTUSDT","id":32402491670,"side":"Sell","size":100000,"price":66795.5,"timestamp":"2024-05-18T15:46:24.827Z"},{"symbol":"XBTUSDT","id":32402519186,"side":"Sell","size":1000,"price":66783.2,"timestamp":"2024-05-18T15:46:24.827Z"},{"symbol":"XBTUSDT","id":32402519203,"side":"Sell","size":354000,"price":66778.4,"timestamp":"2024-05-18T15:46:24.827Z"},{"symbol":"XBTUSDT","id":32402519119,"side":"Buy","size":86000,"price":66754.3,"timestamp":"2024-05-18T15:46:24.827Z"},{"symbol":"XBTUSDT","id":32402519196,"side":"Buy","size":373000,"price":66740.9,"timestamp":"2024-05-18T15:46:24.827Z"}]}
{"table":"orderBookL2_25","action":"delete","data":[{"symbol":"ETHUSDT","id":32402519064,"side":"Sell","price":3110.46,"timestamp":"2024-05-18T15:46:24.833Z"},{"symbol":"ETHUSDT","id":32402518157,"side":"Sell","price":3110.41,"timestamp":"2024-05-18T15:46:24.833Z"},{"symbol":"ETHUSDT","id":32402519107,"side":"Sell","price":3110.97,"timestamp":"2024-05-18T15:46:24.833Z"},{"symbol":"ETHUSDT","id":32402518079,"side":"Sell","price":3110.01,"timestamp":"2024-05-18T15:46:24.833Z"},{"symbol":"ETHUSDT","id":32402519027,"side":"Sell","price":3110.48,"timestamp":"2024-05-18T15:46:24.833Z"},{"symbol":"ETHUSDT","id":32402504489,"side":"Sell","price":3111.02,"timestamp":"2024-05-18T15:46:24.833Z"},{"symbol":"ETHUSDT","id":32402516076,"side":"Sell","price":3110.50,"timestamp":"2024-05-18T15:46:24.833Z"},{"symbol":"ETHUSDT","id":32402518574,"side":"Buy","price":3108.57,"timestamp":"2024-05-18T15:46:24.833Z"},{"symbol":"ETHUSDT","id":32402518769,"side":"Buy","price":3108.58,"timestamp":"2024-05-18T15:46:24.833Z"}]}
{"table":"orderBookL2_25","action":"update","data":[{"symbol":"ETHUSDT","id":32402486025,"side":"Sell","size":1279000,"price":3111.72,"timestamp":"2024-05-18T15:46:24.833Z"},{"symbol":"ETHUSDT","id":32402506255,"side":"Sell","size":1157000,"price":3110.98,"timestamp":"2024-05-18T15:46:24.833Z"},{"symbol":"ETHUSDT","id":32402488716,"side":"Sell","size":100000,"price":3112.18,"timestamp":"2024-05-18T15:46:24.833Z"},{"symbol":"ETHUSDT","id":32402512820,"side":"Buy","size":273000,"price":3108.83,"timestamp":"2024-05-18T15:46:24.833Z"},{"symbol":"ETHUSDT","id":32402512570,"side":"Buy","size":24000,"price":3108.81,"timestamp":"2024-05-18T15:46:24.833Z"}]}
{"table":"orderBookL2_25","action":"insert","data":[{"symbol":"ETHUSDT","id":32402476065,"side":"Sell","size":120000,"price":3112.99,"timestamp":"2024-05-18T15:46:24.833Z"},{"symbol":"ETHUSDT","id":32402519286,"side":"Sell","size":32000,"price":3110.46,"timestamp":"2024-05-18T15:46:24.833Z"},{"symbol":"ETHUSDT","id":32402519139,"side":"Sell","size":202000,"price":3111.71,"timestamp":"2024-05-18T15:46:24.833Z"},{"symbol":"ETHUSDT","id":32402519135,"side":"Sell","size":663000,"price":3110.73,"timestamp":"2024-05-18T15:46:24.833Z"},{"symbol":"ETHUSDT","id":32402519132,"side":"Sell","size":61000,"price":3111.64,"timestamp":"2024-05-18T15:46:24.833Z"},{"symbol":"ETHUSDT","id":32402470274,"side":"Sell","size":100000,"price":3112.84,"timestamp":"2024-05-18T15:46:24.833Z"},{"symbol":"ETHUSDT","id":32402447682,"side":"Sell","size":100000,"price":3112.68,"timestamp":"2024-05-18T15:46:24.833Z"},{"symbol":"ETHUSDT","id":32402519312,"side":"Buy","size":1000,"price":3108.70,"timestamp":"2024-05-18T15:46:24.833Z"},{"symbol":"ETHUSDT","id":32402519317,"side":"Buy","size":1000,"price":3108.69,"timestamp":"2024-05-18T15:46:24.833Z"}]}
{"table":"orderBookL2_25","action":"delete","data":[{"symbol":"XBTUSDT","id":32402501930,"side":"Sell","price":66792.7,"timestamp":"2024-05-18T15:46:24.876Z"},{"symbol":"XBTUSDT","id":32402519186,"side":"Sell","price":66783.2,"timestamp":"2024-05-18T15:46:24.876Z"},{"symbol":"XBTUSDT","id":32402518784,"side":"Sell","price":66776.0,"timestamp":"2024-05-18T15:46:24.876Z"},{"symbol":"XBTUSDT","id":32402519004,"side":"Buy","price":66748.0,"timestamp":"2024-05-18T15:46:24.876Z"},{"symbol":"XBTUSDT","id":32402518556,"side":"Buy","price":66740.8,"timestamp":"2024-05-18T15:46:24.876Z"},{"symbol":"XBTUSDT","id":32402518598,"side":"Buy","price":66747.9,"timestamp":"2024-05-18T15:46:24.876Z"}]}
{"table":"orderBookL2_25","action":"update","data":[{"symbol":"XBTUSDT","id":32402491670,"side":"Sell","size":100000,"price":66795.5,"timestamp":"2024-05-18T15:46:24.876Z"},{"symbol":"XBTUSDT","id":32402511631,"side":"Sell","size":328000,"price":66795.4,"timestamp":"2024-05-18T15:46:24.876Z"},{"symbol":"XBTUSDT","id":32402502861,"side":"Sell","size":175000,"price":66784.3,"timestamp":"2024-05-18T15:46:24.876Z"},{"symbol":"XBTUSDT","id":32402518890,"side":"Sell","size":176000,"price":66775.9,"timestamp":"2024-05-18T15:46:24.876Z"},{"symbol":"XBTUSDT","id":32402506723,"side":"Sell","size":159000,"price":66783.4,"timestamp":"2024-05-18T15:46:24.876Z"},{"symbol":"XBTUSDT","id":32402511708,"side":"Sell","size":102000,"price":66783.3,"timestamp":"2024-05-18T15:46:24.876Z"},{"symbol":"XBTUSDT","id":32402518359,"side":"Buy","size":18000,"price":66732.5,"timestamp":"2024-05-18T15:46:24.876Z"}]}
{"table":"orderBookL2_25","action":"insert","data":[{"symbol":"XBTUSDT","id":32402519448,"side":"Sell","size":20000,"price":66774.2,"timestamp":"2024-05-18T15:46:24.876Z"},{"symbol":"XBTUSDT","id":32402519435,"side":"Sell","size":1000,"price":66784.4,"timestamp":"2024-05-18T15:46:24.876Z"},{"symbol":"XBTUSDT","id":32402519415,"side":"Sell","size":20000,"price":66776.2,"timestamp":"2024-05-18T15:46:24.876Z"},{"symbol":"XBTUSDT","id":32402519393,"side":"Buy","size":3000,"price":66741.0,"timestamp":"2024-05-18T15:46:24.876Z"},{"symbol":"XBTUSDT","id":32402519446,"side":"Buy","size":20000,"price":66748.5,"timestamp":"2024-05-18T15:46:24.876Z"},{"symbol":"XBTUSDT","id":32402519442,"side":"Buy","size":20000,"price":66748.4,"timestamp":"2024-05-18T15:46:24.876Z"}]}
{"table":"orderBookL2_25","action":"delete","data":[{"symbol":"ETHUSDT","id":32402518143,"side":"Sell","price":3109.61,"timestamp":"2024-05-18T15:46:24.882Z"},{"symbol":"ETHUSDT","id":32402519031,"side":"Sell","price":3110.47,"timestamp":"2024-05-18T15:46:24.882Z"},{"symbol":"ETHUSDT","id":32402519286,"side":"Sell","price":3110.46,"timestamp":"2024-05-18T15:46:24.882Z"},{"symbol":"ETHUSDT","id":32402518151,"side":"Sell","price":3109.97,"timestamp":"2024-05-18T15:46:24.882Z"},{"symbol":"ETHUSDT","id":32402512818,"side":"Buy","price":3108.18,"timestamp":"2024-05-18T15:46:24.882Z"},{"symbol":"ETHUSDT","id":32402519317,"side":"Buy","price":3108.69,"timestamp":"2024-05-18T15:46:24.882Z"},{"symbol":"ETHUSDT","id":32402519312,"side":"Buy","price":3108.70,"timestamp":"2024-05-18T15:46:24.882Z"},{"symbol":"ETHUSDT","id":32402518627,"side":"Buy","price":3108.82,"timestamp":"2024-05-18T15:46:24.882Z"},{"symbol":"ETHUSDT","id":32402517241,"side":"Buy","price":3107.57,"timestamp":"2024-05-18T15:46:24.882Z"}]}
{"table":"orderBookL2_25","action":"update","data":[{"symbol":"ETHUSDT","id":32402476065,"side":"Sell","size":120000,"price":3112.99,"timestamp":"2024-05-18T15:46:24.882Z"},{"symbol":"ETHUSDT","id":32402480382,"side":"Buy","size":100000,"price":3107.24,"timestamp":"2024-05-18T15:46:24.882Z"},{"symbol":"ETHUSDT","id":32402512820,"side":"Buy","size":241000,"price":3108.83,"timestamp":"2024-05-18T15:46:24.882Z"},{"symbol":"ETHUSDT","id":32402512570,"side":"Buy","size":25000,"price":3108.81,"timestamp":"2024-05-18T15:46:24.882Z"}]}
{"table":"orderBookL2_25","action":"insert","data":[{"symbol":"ETHUSDT","id":32402519425,"side":"Sell","size":32000,"price":3110.57,"timestamp":"2024-05-18T15:46:24.882Z"},{"symbol":"ETHUSDT","id":32402519363,"side":"Sell","size":100000,"price":3109.83,"timestamp":"2024-05-18T15:46:24.882Z"},{"symbol":"ETHUSDT","id":32402519374,"side":"Sell","size":43000,"price":3110.40,"timestamp":"2024-05-18T15:46:24.882Z"},{"symbol":"ETHUSDT","id":32402519462,"side":"Sell","size":32000,"price":3110.58,"timestamp":"2024-05-18T15:46:24.882Z"},{"symbol":"ETHUSDT","id":32402519342,"side":"Buy","size":519000,"price":3108.19,"timestamp":"2024-05-18T15:46:24.882Z"},{"symbol":"ETHUSDT","id":32402519423,"side":"Buy","size":32000,"price":3108.94,"timestamp":"2024-05-18T15:46:24.882Z"},{"symbol":"ETHUSDT","id":32402519404,"side":"Buy","size":32000,"price":3108.95,"timestamp":"2024-05-18T15:46:24.882Z"},{"symbol":"ETHUSDT","id":32402488025,"side":"Buy","size":100000,"price":3107.08,"timestamp":"2024-05-18T15:46:24.882Z"},{"symbol":"ETHUSDT","id":32402519440,"side":"Buy","size":1000,"price":3108.82,"timestamp":"2024-05-18T15:46:24.882Z"}]}
{"table":"orderBookL2_25","action":"delete","data":[{"symbol":"XBTETH","id":32402423004,"side":"Buy","price":21.227,"timestamp":"2024-05-18T15:46:24.901Z"}]}
{"table":"orderBookL2_25","action":"insert","data":[{"symbol":"XBTETH","id":32402519507,"side":"Buy","size":5,"price":21.222,"timestamp":"2024-05-18T15:46:24.901Z"}]}
{"table":"orderBookL2_25","action":"delete","data":[{"symbol":"XBTUSDT","id":32402491670,"side":"Sell","price":66795.5,"timestamp":"2024-05-18T15:46:24.925Z"},{"symbol":"XBTUSDT","id":32402511631,"side":"Sell","price":66795.4,"timestamp":"2024-05-18T15:46:24.925Z"},{"symbol":"XBTUSDT","id":32402499098,"side":"Sell","price":66792.1,"timestamp":"2024-05-18T15:46:24.925Z"},{"symbol":"XBTUSDT","id":32402519435,"side":"Sell","price":66784.4,"timestamp":"2024-05-18T15:46:24.925Z"},{"symbol":"XBTUSDT","id":32402518890,"side":"Sell","price":66775.9,"timestamp":"2024-05-18T15:46:24.925Z"},{"symbol":"XBTUSDT","id":32402519415,"side":"Sell","price":66776.2,"timestamp":"2024-05-18T15:46:24.925Z"},{"symbol":"XBTUSDT","id":32402519446,"side":"Buy","price":66748.5,"timestamp":"2024-05-18T15:46:24.925Z"}]}
{"table":"orderBookL2_25","action":"update","data":[{"symbol":"XBTUSDT","id":32402502861,"side":"Sell","size":174000,"price":66784.3,"timestamp":"2024-05-18T15:46:24.925Z"},{"symbol":"XBTUSDT","id":32402510159,"side":"Sell","size":10000,"price":66776.9,"timestamp":"2024-05-18T15:46:24.925Z"},{"symbol":"XBTUSDT","id":32402499271,"side":"Sell","size":100000,"price":66788.7,"timestamp":"2024-05-18T15:46:24.925Z"}]}
{"table":"orderBookL2_25","action":"insert","data":[{"symbol":"XBTUSDT","id":32402519550,"side":"Sell","size":1000,"price":66784.0,"timestamp":"2024-05-18T15:46:24.925Z"},{"symbol":"XBTUSDT","id":32402519546,"side":"Sell","size":1000,"price":66784.1,"timestamp":"2024-05-18T15:46:24.925Z"},{"symbol":"XBTUSDT","id":32402519498,"side":"Sell","size":20000,"price":66777.3,"timestamp":"2024-05-18T15:46:24.925Z"},{"symbol":"XBTUSDT","id":32402519527,"side":"Sell","size":100000,"price":66767.9,"timestamp":"2024-05-18T15:46:24.925Z"},{"symbol":"XBTUSDT","id":32402519501,"side":"Sell","size":20000,"price":66777.4,"timestamp":"2024-05-18T15:46:24.925Z"},{"symbol":"XBTUSDT","id":32402519552,"side":"Sell","size":156000,"price":66776.8,"timestamp":"2024-05-18T15:46:24.925Z"},{"symbol":"XBTUSDT","id":32402519474,"side":"Buy","size":20000,"price":66748.3,"timestamp":"2024-05-18T15:46:24.925Z"}]}
