{"table":"orderBookL2_25","action":"partial","keys":["symbol","id","side"],"types":{"symbol":"symbol","id":"long","side":"symbol","size":"long","price":"float","timestamp":"timestamp"},"filter":{"symbol":"XBTETH"},"data":[{"symbol":"XBTETH","id":32402421121,"side":"Sell","size":8,"price":22.130,"timestamp":"2024-05-18T15:46:02.373Z"},{"symbol":"XBTETH","id":32400693213,"side":"Sell","size":2199,"price":22.097,"timestamp":"2024-05-18T15:46:02.373Z"},{"symbol":"XBTETH","id":32402419404,"side":"Sell","size":7,"price":22.087,"timestamp":"2024-05-18T15:46:02.373Z"},{"symbol":"XBTETH","id":32402417798,"side":"Sell","size":8,"price":22.044,"timestamp":"2024-05-18T15:46:02.373Z"},{"symbol":"XBTETH","id":32402427688,"side":"Sell","size":7,"price":22.001,"timestamp":"2024-05-18T15:46:02.373Z"},{"symbol":"XBTETH","id":32394594262,"side":"Sell","size":2204,"price":21.987,"timestamp":"2024-05-18T15:46:02.373Z"},{"symbol":"XBTETH","id":32402426636,"side":"Sell","size":7,"price":21.958,"timestamp":"2024-05-18T15:46:02.373Z"},{"symbol":"XBTETH","id":32394600053,"side":"Sell","size":2190,"price":21.922,"timestamp":"2024-05-18T15:46:02.373Z"},{"symbol":"XBTETH","id":32402426126,"side":"Sell","size":7,"price":21.915,"timestamp":"2024-05-18T15:46:02.373Z"},{"symbol":"XBTETH","id":32402425343,"side":"Sell","size":6,"price":21.872,"timestamp":"2024-05-18T15:46:02.373Z"},{"symbol":"XBTETH","id":32394606370,"side":"Sell","size":1896,"price":21.858,"timestamp":"2024-05-18T15:46:02.373Z"},{"symbol":"XBTETH","id":32402424419,"side":"Sell","size":6,"price":21.829,"timestamp":"2024-05-18T15:46:02.373Z"},{"symbol":"XBTETH","id":32394613093,"side":"Sell","size":1781,"price":21.789,"timestamp":"2024-05-18T15:46:02.373Z"},{"symbol":"XBTETH","id":32402423015,"side":"Sell","size":6,"price":21.786,"timestamp":"2024-05-18T15:46:02.373Z"},{"symbol":"XBTETH","id":32402417551,"side":"Sell","size":1,"price":21.743,"timestamp":"2024-05-18T15:46:02.373Z"},{"symbol":"XBTETH","id":32394618323,"side":"Sell","size":1478,"price":21.725,"timestamp":"2024-05-18T15:46:02.373Z"},{"symbol":"XBTETH","id":32394632784,"side":"Sell","size":958,"price":21.667,"timestamp":"2024-05-18T15:46:02.373Z"},{"symbol":"XBTETH","id":32402023906,"side":"Sell","size":898,"price":21.633,"timestamp":"2024-05-18T15:46:02.373Z"},{"symbol":"XBTETH","id":32399502388,"side":"Sell","size":578,"price":21.584,"timestamp":"2024-05-18T15:46:02.373Z"},{"symbol":"XBTETH","id":32371421425,"side":"Sell","size":1,"price":21.538,"timestamp":"2024-05-18T15:46:02.373Z"},{"symbol":"XBTETH","id":32371421032,"side":"Sell","size":1,"price":21.527,"timestamp":"2024-05-18T15:46:02.373Z"},{"symbol":"XBTETH","id":32371377483,"side":"Sell","size":1,"price":21.516,"timestamp":"2024-05-18T15:46:02.373Z"},{"symbol":"XBTETH","id":32402156289,"side":"Sell","size":248,"price":21.495,"timestamp":"2024-05-18T15:46:02.373Z"},{"symbol":"XBTETH","id":32402475262,"side":"Sell","size":110,"price":21.489,"timestamp":"2024-05-18T15:46:02.373Z"},{"symbol":"XBTETH","id":32402311951,"side":"Sell","size":16,"price":21.466,"timestamp":"2024-05-18T15:46:02.373Z"},{"symbol":"XBTETH","id":32401042059,"side":"Buy","size":16,"price":21.398,"timestamp":"2024-05-18T15:46:02.373Z"},{"symbol":"XBTETH","id":32401275264,"side":"Buy","size":145,"price":21.373,"timestamp":"2024-05-18T15:46:02.373Z"},{"symbol":"XBTETH","id":32402024130,"side":"Buy","size":331,"price":21.309,"timestamp":"2024-05-18T15:46:02.373Z"},{"symbol":"XBTETH","id":32394632787,"side":"Buy","size":323,"price":21.277,"timestamp":"2024-05-18T15:46:02.373Z"},{"symbol":"XBTETH","id":32402417546,"side":"Buy","size":1,"price":21.269,"timestamp":"2024-05-18T15:46:02.373Z"},{"symbol":"XBTETH","id":32402423004,"side":"Buy","size":6,"price":21.227,"timestamp":"2024-05-18T15:46:02.373Z"},{"symbol":"XBTETH","id":32394618299,"side":"Buy","size":715,"price":21.207,"timestamp":"2024-05-18T15:46:02.373Z"},{"symbol":"XBTETH","id":32402424310,"side":"Buy","size":6,"price":21.184,"timestamp":"2024-05-18T15:46:02.373Z"},{"symbol":"XBTETH","id":32402425352,"side":"Buy","size":6,"price":21.141,"timestamp":"2024-05-18T15:46:02.373Z"},{"symbol":"XBTETH","id":32402426122,"side":"Buy","size":7,"price":21.098,"timestamp":"2024-05-18T15:46:02.373Z"},{"symbol":"XBTETH","id":32394606329,"side":"Buy","size":902,"price":21.082,"timestamp":"2024-05-18T15:46:02.373Z"},{"symbol":"XBTETH","id":32402426628,"side":"Buy","size":7,"price":21.055,"timestamp":"2024-05-18T15:46:02.373Z"},{"symbol":"XBTETH","id":32394600055,"side":"Buy","size":1250,"price":21.017,"timestamp":"2024-05-18T15:46:02.373Z"},{"symbol":"XBTETH","id":32402427691,"side":"Buy","size":7,"price":21.012,"timestamp":"2024-05-18T15:46:02.373Z"},{"symbol":"XBTETH","id":32402417548,"side":"Buy","size":8,"price":20.969,"timestamp":"2024-05-18T15:46:02.373Z"},{"symbol":"XBTETH","id":32394594266,"side":"Buy","size":1250,"price":20.954,"timestamp":"2024-05-18T15:46:02.373Z"},{"symbol":"XBTETH","id":32402419432,"side":"Buy","size":7,"price":20.926,"timestamp":"2024-05-18T15:46:02.373Z"},{"symbol":"XBTETH","id":32394589038,"side":"Buy","size":1250,"price":20.891,"timestamp":"2024-05-18T15:46:02.373Z"},{"symbol":"XBTETH","id":32402421084,"side":"Buy","size":8,"price":20.883,"timestamp":"2024-05-18T15:46:02.373Z"},{"symbol":"XBTETH","id":32401955007,"side":"Buy","size":1238,"price":20.848,"timestamp":"2024-05-18T15:46:02.373Z"},{"symbol":"XBTETH","id":32402422012,"side":"Buy","size":7,"price":20.840,"timestamp":"2024-05-18T15:46:02.373Z"},{"symbol":"XBTETH","id":32399530289,"side":"Buy","size":1247,"price":20.780,"timestamp":"2024-05-18T15:46:02.373Z"},{"symbol":"XBTETH","id":32156052046,"side":"Buy","size":200,"price":20.550,"timestamp":"2024-05-18T15:46:02.373Z"},{"symbol":"XBTETH","id":31760968088,"side":"Buy","size":50,"price":20.451,"timestamp":"2024-05-18T15:46:02.373Z"},{"symbol":"XBTETH","id":31175520323,"side":"Buy","size":200,"price":20.200,"timestamp":"2024-05-18T15:46:02.373Z"}]}
{"table":"orderBookL2_25","action":"partial","keys":["symbol","id","side"],"types":{"symbol":"symbol","id":"long","side":"symbol","size":"long","price":"float","timestamp":"timestamp"},"filter":{"symbol":"XBTUSDT"},"data":[{"symbol":"XBTUSDT","id":32402474116,"side":"Sell","size":102000,"price":66824.2,"timestamp":"2024-05-18T15:46:02.373Z"},{"symbol":"XBTUSDT","id":32402481890,"side":"Sell","size":1000,"price":66822.8,"timestamp":"2024-05-18T15:46:02.373Z"},{"symbol":"XBTUSDT","id":32402481892,"side":"Sell","size":1000,"price":66822.7,"timestamp":"2024-05-18T15:46:02.373Z"},{"symbol":"XBTUSDT","id":32402455289,"side":"Sell","size":22000,"price":66822.3,"timestamp":"2024-05-18T15:46:02.373Z"},{"symbol":"XBTUSDT","id":32402242406,"side":"Sell","size":138000,"price":66822.2,"timestamp":"2024-05-18T15:46:02.373Z"},{"symbol":"XBTUSDT","id":32402471671,"side":"Sell","size":74000,"price":66821.7,"timestamp":"2024-05-18T15:46:02.373Z"},{"symbol":"XBTUSDT","id":32402476497,"side":"Sell","size":50000,"price":66821.6,"timestamp":"2024-05-18T15:46:02.373Z"},{"symbol":"XBTUSDT","id":32402473887,"side":"Sell","size":20000,"price":66818.3,"timestamp":"2024-05-18T15:46:02.373Z"},{"symbol":"XBTUSDT","id":32402481951,"side":"Sell","size":20000,"price":66816.6,"timestamp":"2024-05-18T15:46:02.373Z"},{"symbol":"XBTUSDT","id":32402481947,"side":"Sell","size":20000,"price":66816.5,"timestamp":"2024-05-18T15:46:02.373Z"},{"symbol":"XBTUSDT","id":32402461579,"side":"Sell","size":100000,"price":66815.7,"timestamp":"2024-05-18T15:46:02.373Z"},{"symbol":"XBTUSDT","id":32402481895,"side":"Sell","size":66000,"price":66815.6,"timestamp":"2024-05-18T15:46:02.373Z"},{"symbol":"XBTUSDT","id":32402479097,"side":"Sell","size":3000,"price":66815.5,"timestamp":"2024-05-18T15:46:02.373Z"},{"symbol":"XBTUSDT","id":32402455324,"side":"Sell","size":100000,"price":66812.3,"timestamp":"2024-05-18T15:46:02.373Z"},{"symbol":"XBTUSDT","id":32402481878,"side":"Sell","size":349000,"price":66812.0,"timestamp":"2024-05-18T15:46:02.373Z"},{"symbol":"XBTUSDT","id":32402481887,"side":"Sell","size":214000,"price":66811.9,"timestamp":"2024-05-18T15:46:02.373Z"},{"symbol":"XBTUSDT","id":32402472077,"side":"Sell","size":11000,"price":66810.2,"timestamp":"2024-05-18T15:46:02.373Z"},{"symbol":"XBTUSDT","id":32402471489,"side":"Sell","size":100000,"price":66808.7,"timestamp":"2024-05-18T15:46:02.373Z"},{"symbol":"XBTUSDT","id":32402481228,"side":"Sell","size":157000,"price":66807.9,"timestamp":"2024-05-18T15:46:02.373Z"},{"symbol":"XBTUSDT","id":32402481898,"side":"Sell","size":101000,"price":66807.8,"timestamp":"2024-05-18T15:46:02.373Z"},{"symbol":"XBTUSDT","id":32402481962,"side":"Sell","size":2000,"price":66807.7,"timestamp":"2024-05-18T15:46:02.373Z"},{"symbol":"XBTUSDT","id":32402479032,"side":"Sell","size":3000,"price":66806.9,"timestamp":"2024-05-18T15:46:02.373Z"},{"symbol":"XBTUSDT","id":32402472771,"side":"Sell","size":100000,"price":66805.3,"timestamp":"2024-05-18T15:46:02.373Z"},{"symbol":"XBTUSDT","id":32402480133,"side":"Sell","size":10000,"price":66803.0,"timestamp":"2024-05-18T15:46:02.373Z"},{"symbol":"XBTUSDT","id":32402462668,"side":"Sell","size":319000,"price":66801.9,"timestamp":"2024-05-18T15:46:02.373Z"},{"symbol":"XBTUSDT","id":32402455981,"side":"Buy","size":3000,"price":66801.8,"timestamp":"2024-05-18T15:46:02.373Z"},{"symbol":"XBTUSDT","id":32402479815,"side":"Buy","size":20000,"price":66801.7,"timestamp":"2024-05-18T15:46:02.373Z"},{"symbol":"XBTUSDT","id":32402478801,"side":"Buy","size":8000,"price":66795.5,"timestamp":"2024-05-18T15:46:02.373Z"},{"symbol":"XBTUSDT","id":32402476745,"side":"Buy","size":16000,"price":66795.4,"timestamp":"2024-05-18T15:46:02.373Z"},{"symbol":"XBTUSDT","id":32402258708,"side":"Buy","size":32000,"price":66795.3,"timestamp":"2024-05-18T15:46:02.373Z"},{"symbol":"XBTUSDT","id":32402478470,"side":"Buy","size":8000,"price":66791.2,"timestamp":"2024-05-18T15:46:02.373Z"},{"symbol":"XBTUSDT","id":32402462566,"side":"Buy","size":35000,"price":66791.1,"timestamp":"2024-05-18T15:46:02.373Z"},{"symbol":"XBTUSDT","id":32402480326,"side":"Buy","size":100000,"price":66788.2,"timestamp":"2024-05-18T15:46:02.373Z"},{"symbol":"XBTUSDT","id":32402480644,"side":"Buy","size":228000,"price":66784.4,"timestamp":"2024-05-18T15:46:02.373Z"},{"symbol":"XBTUSDT","id":32402463841,"side":"Buy","size":444000,"price":66784.3,"timestamp":"2024-05-18T15:46:02.373Z"},{"symbol":"XBTUSDT","id":32402462688,"side":"Buy","size":538000,"price":66784.1,"timestamp":"2024-05-18T15:46:02.373Z"},{"symbol":"XBTUSDT","id":32402481846,"side":"Buy","size":20000,"price":66783.1,"timestamp":"2024-05-18T15:46:02.373Z"},{"symbol":"XBTUSDT","id":32402481949,"side":"Buy","size":20000,"price":66783.0,"timestamp":"2024-05-18T15:46:02.373Z"},{"symbol":"XBTUSDT","id":32402156627,"side":"Buy","size":100000,"price":66782.8,"timestamp":"2024-05-18T15:46:02.373Z"},{"symbol":"XBTUSDT","id":32402227172,"side":"Buy","size":3000,"price":66780.0,"timestamp":"2024-05-18T15:46:02.373Z"},{"symbol":"XBTUSDT","id":32402480174,"side":"Buy","size":384000,"price":66776.1,"timestamp":"2024-05-18T15:46:02.373Z"},{"symbol":"XBTUSDT","id":32402248654,"side":"Buy","size":100000,"price":66776.0,"timestamp":"2024-05-18T15:46:02.373Z"},{"symbol":"XBTUSDT","id":32402229295,"side":"Buy","size":3000,"price":66775.0,"timestamp":"2024-05-18T15:46:02.373Z"},{"symbol":"XBTUSDT","id":32402478234,"side":"Buy","size":155000,"price":66767.9,"timestamp":"2024-05-18T15:46:02.373Z"},{"symbol":"XBTUSDT","id":32402110415,"side":"Buy","size":100000,"price":66767.8,"timestamp":"2024-05-18T15:46:02.373Z"},{"symbol":"XBTUSDT","id":32402110404,"side":"Buy","size":74000,"price":66767.4,"timestamp":"2024-05-18T15:46:02.373Z"},{"symbol":"XBTUSDT","id":32402464305,"side":"Buy","size":804000,"price":66766.2,"timestamp":"2024-05-18T15:46:02.373Z"},{"symbol":"XBTUSDT","id":32402363228,"side":"Buy","size":1502000,"price":66766.1,"timestamp":"2024-05-18T15:46:02.373Z"},{"symbol":"XBTUSDT","id":32402360485,"side":"Buy","size":100000,"price":66764.4,"timestamp":"2024-05-18T15:46:02.373Z"},{"symbol":"XBTUSDT","id":32402362888,"side":"Buy","size":543000,"price":66762.2,"timestamp":"2024-05-18T15:46:02.373Z"}]}
{"table":"orderBookL2_25","action":"partial","keys":["symbol","id","side"],"types":{"symbol":"symbol","id":"long","side":"symbol","size":"long","price":"float","timestamp":"timestamp"},"filter":{"symbol":"ETHUSDT"},"data":[{"symbol":"ETHUSDT","id":32402460546,"side":"Sell","size":65000,"price":3112.42,"timestamp":"2024-05-18T15:46:02.373Z"},{"symbol":"ETHUSDT","id":32402450496,"side":"Sell","size":100000,"price":3112.27,"timestamp":"2024-05-18T15:46:02.373Z"},{"symbol":"ETHUSDT","id":32402460525,"side":"Sell","size":160000,"price":3112.25,"timestamp":"2024-05-18T15:46:02.373Z"},{"symbol":"ETHUSDT","id":32402480950,"side":"Sell","size":1156000,"price":3112.19,"timestamp":"2024-05-18T15:46:02.373Z"},{"symbol":"ETHUSDT","id":32402466549,"side":"Sell","size":2300000,"price":3112.15,"timestamp":"2024-05-18T15:46:02.373Z"},{"symbol":"ETHUSDT","id":32402467535,"side":"Sell","size":1095000,"price":3112.14,"timestamp":"2024-05-18T15:46:02.373Z"},{"symbol":"ETHUSDT","id":32402461791,"side":"Sell","size":989000,"price":3112.06,"timestamp":"2024-05-18T15:46:02.373Z"},{"symbol":"ETHUSDT","id":32402455680,"side":"Sell","size":100000,"price":3112.02,"timestamp":"2024-05-18T15:46:02.373Z"},{"symbol":"ETHUSDT","id":32402460817,"side":"Sell","size":24000,"price":3111.78,"timestamp":"2024-05-18T15:46:02.373Z"},{"symbol":"ETHUSDT","id":32402472118,"side":"Sell","size":100000,"price":3111.56,"timestamp":"2024-05-18T15:46:02.373Z"},{"symbol":"ETHUSDT","id":32402472717,"side":"Sell","size":61000,"price":3111.53,"timestamp":"2024-05-18T15:46:02.373Z"},{"symbol":"ETHUSDT","id":32402471335,"side":"Sell","size":24000,"price":3111.40,"timestamp":"2024-05-18T15:46:02.373Z"},{"symbol":"ETHUSDT","id":32402471833,"side":"Sell","size":241000,"price":3111.39,"timestamp":"2024-05-18T15:46:02.373Z"},{"symbol":"ETHUSDT","id":32402477177,"side":"Sell","size":146000,"price":3111.38,"timestamp":"2024-05-18T15:46:02.373Z"},{"symbol":"ETHUSDT","id":32402477488,"side":"Sell","size":100000,"price":3111.33,"timestamp":"2024-05-18T15:46:02.373Z"},{"symbol":"ETHUSDT","id":32402481027,"side":"Sell","size":75000,"price":3111.11,"timestamp":"2024-05-18T15:46:02.373Z"},{"symbol":"ETHUSDT","id":32402481778,"side":"Sell","size":32000,"price":3111.10,"timestamp":"2024-05-18T15:46:02.373Z"},{"symbol":"ETHUSDT","id":32402480356,"side":"Sell","size":100000,"price":3111.09,"timestamp":"2024-05-18T15:46:02.373Z"},{"symbol":"ETHUSDT","id":32402476896,"side":"Sell","size":905000,"price":3110.80,"timestamp":"2024-05-18T15:46:02.373Z"},{"symbol":"ETHUSDT","id":32402476904,"side":"Sell","size":552000,"price":3110.79,"timestamp":"2024-05-18T15:46:02.373Z"},{"symbol":"ETHUSDT","id":32402480977,"side":"Sell","size":29000,"price":3110.48,"timestamp":"2024-05-18T15:46:02.373Z"},{"symbol":"ETHUSDT","id":32402480165,"side":"Sell","size":100000,"price":3110.40,"timestamp":"2024-05-18T15:46:02.373Z"},{"symbol":"ETHUSDT","id":32402480191,"side":"Sell","size":61000,"price":3110.39,"timestamp":"2024-05-18T15:46:02.373Z"},{"symbol":"ETHUSDT","id":32402480282,"side":"Sell","size":100000,"price":3110.29,"timestamp":"2024-05-18T15:46:02.373Z"},{"symbol":"ETHUSDT","id":32402480864,"side":"Sell","size":26000,"price":3110.13,"timestamp":"2024-05-18T15:46:02.373Z"},{"symbol":"ETHUSDT","id":32402480784,"side":"Buy","size":43000,"price":3110.12,"timestamp":"2024-05-18T15:46:02.373Z"},{"symbol":"ETHUSDT","id":32402457345,"side":"Buy","size":24000,"price":3110.10,"timestamp":"2024-05-18T15:46:02.373Z"},{"symbol":"ETHUSDT","id":32402481791,"side":"Buy","size":32000,"price":3109.69,"timestamp":"2024-05-18T15:46:02.373Z"},{"symbol":"ETHUSDT","id":32402481788,"side":"Buy","size":32000,"price":3109.68,"timestamp":"2024-05-18T15:46:02.373Z"},{"symbol":"ETHUSDT","id":32402481746,"side":"Buy","size":1000,"price":3109.44,"timestamp":"2024-05-18T15:46:02.373Z"},{"symbol":"ETHUSDT","id":32402481771,"side":"Buy","size":1000,"price":3109.43,"timestamp":"2024-05-18T15:46:02.373Z"},{"symbol":"ETHUSDT","id":32401945550,"side":"Buy","size":1000,"price":3109.40,"timestamp":"2024-05-18T15:46:02.373Z"},{"symbol":"ETHUSDT","id":32402481323,"side":"Buy","size":1156000,"price":3109.32,"timestamp":"2024-05-18T15:46:02.373Z"},{"symbol":"ETHUSDT","id":32402480842,"side":"Buy","size":100000,"price":3109.00,"timestamp":"2024-05-18T15:46:02.373Z"},{"symbol":"ETHUSDT","id":32402480348,"side":"Buy","size":311000,"price":3108.95,"timestamp":"2024-05-18T15:46:02.373Z"},{"symbol":"ETHUSDT","id":32402480376,"side":"Buy","size":100000,"price":3108.84,"timestamp":"2024-05-18T15:46:02.373Z"},{"symbol":"ETHUSDT","id":32402034609,"side":"Buy","size":100000,"price":3108.61,"timestamp":"2024-05-18T15:46:02.373Z"},{"symbol":"ETHUSDT","id":32402480534,"side":"Buy","size":192000,"price":3108.49,"timestamp":"2024-05-18T15:46:02.373Z"},{"symbol":"ETHUSDT","id":32402480605,"side":"Buy","size":100000,"price":3108.45,"timestamp":"2024-05-18T15:46:02.373Z"},{"symbol":"ETHUSDT","id":32402466556,"side":"Buy","size":2300000,"price":3108.41,"timestamp":"2024-05-18T15:46:02.373Z"},{"symbol":"ETHUSDT","id":32402480869,"side":"Buy","size":100000,"price":3108.29,"timestamp":"2024-05-18T15:46:02.373Z"},{"symbol":"ETHUSDT","id":32402480786,"side":"Buy","size":642000,"price":3107.98,"timestamp":"2024-05-18T15:46:02.373Z"},{"symbol":"ETHUSDT","id":32402460376,"side":"Buy","size":100000,"price":3107.97,"timestamp":"2024-05-18T15:46:02.373Z"},{"symbol":"ETHUSDT","id":32402476196,"side":"Buy","size":1126000,"price":3107.95,"timestamp":"2024-05-18T15:46:02.373Z"},{"symbol":"ETHUSDT","id":32402480249,"side":"Buy","size":975000,"price":3107.80,"timestamp":"2024-05-18T15:46:02.373Z"},{"symbol":"ETHUSDT","id":32402460354,"side":"Buy","size":1620000,"price":3107.79,"timestamp":"2024-05-18T15:46:02.373Z"},{"symbol":"ETHUSDT","id":32401854083,"side":"Buy","size":100000,"price":3107.72,"timestamp":"2024-05-18T15:46:02.373Z"},{"symbol":"ETHUSDT","id":32401850719,"side":"Buy","size":160000,"price":3107.70,"timestamp":"2024-05-18T15:46:02.373Z"},{"symbol":"ETHUSDT","id":32402397491,"side":"Buy","size":100000,"price":3107.56,"timestamp":"2024-05-18T15:46:02.373Z"},{"symbol":"ETHUSDT","id":32402400155,"side":"Buy","size":17414000,"price":3107.38,"timestamp":"2024-05-18T15:46:02.373Z"}]}
{"table":"orderBookL2_25","action":"delete","data":[{"symbol":"ETHUSDT","id":32402481791,"side":"Buy","price":3109.69,"timestamp":"2024-05-18T15:46:02.392Z"}]}
{"table":"orderBookL2_25","action":"insert","data":[{"symbol":"ETHUSDT","id":32402482022,"side":"Buy","size":32000,"price":3109.67,"timestamp":"2024-05-18T15:46:02.392Z"}]}
{"table":"orderBookL2_25","action":"delete","data":[{"symbol":"ETHUSDT","id":32402481778,"side":"Sell","price":3111.10,"timestamp":"2024-05-18T15:46:02.442Z"},{"symbol":"ETHUSDT","id":32402400155,"side":"Buy","price":3107.38,"timestamp":"2024-05-18T15:46:02.442Z"},{"symbol":"ETHUSDT","id":32402482022,"side":"Buy","price":3109.67,"timestamp":"2024-05-18T15:46:02.442Z"}]}
{"table":"orderBookL2_25","action":"insert","data":[{"symbol":"ETHUSDT","id":32402482039,"side":"Sell","size":32000,"price":3111.10,"timestamp":"2024-05-18T15:46:02.442Z"},{"symbol":"ETHUSDT","id":32402482058,"side":"Buy","size":32000,"price":3109.69,"timestamp":"2024-05-18T15:46:02.442Z"},{"symbol":"ETHUSDT","id":32402482060,"side":"Buy","size":47000,"price":3109.91,"timestamp":"2024-05-18T15:46:02.442Z"}]}
{"table":"orderBookL2_25","action":"delete","data":[{"symbol":"XBTUSDT","id":32402481878,"side":"Sell","price":66812.0,"timestamp":"2024-05-18T15:46:02.455Z"}]}
{"table":"orderBookL2_25","action":"insert","data":[{"symbol":"XBTUSDT","id":32402482077,"side":"Sell","size":377000,"price":66815.2,"timestamp":"2024-05-18T15:46:02.455Z"}]}
{"table":"orderBookL2_25","action":"delete","data":[{"symbol":"XBTUSDT","id":32402481887,"side":"Sell","price":66811.9,"timestamp":"2024-05-18T15:46:02.504Z"},{"symbol":"XBTUSDT","id":32402481895,"side":"Sell","price":66815.6,"timestamp":"2024-05-18T15:46:02.504Z"}]}
{"table":"orderBookL2_25","action":"insert","data":[{"symbol":"XBTUSDT","id":32402482085,"side":"Sell","size":226000,"price":66815.1,"timestamp":"2024-05-18T15:46:02.504Z"},{"symbol":"XBTUSDT","id":32402482083,"side":"Sell","size":69000,"price":66811.9,"timestamp":"2024-05-18T15:46:02.504Z"}]}
{"table":"orderBookL2_25","action":"delete","data":[{"symbol":"ETHUSDT","id":32402481771,"side":"Buy","price":3109.43,"timestamp":"2024-05-18T15:46:02.509Z"}]}
{"table":"orderBookL2_25","action":"insert","data":[{"symbol":"ETHUSDT","id":32402482139,"side":"Buy","size":1000,"price":3109.45,"timestamp":"2024-05-18T15:46:02.509Z"}]}
{"table":"orderBookL2_25","action":"delete","data":[{"symbol":"XBTUSDT","id":32402481951,"side":"Sell","price":66816.6,"timestamp":"2024-05-18T15:46:02.553Z"},{"symbol":"XBTUSDT","id":32402481949,"side":"Buy","price":66783.0,"timestamp":"2024-05-18T15:46:02.553Z"}]}
{"table":"orderBookL2_25","action":"insert","data":[{"symbol":"XBTUSDT","id":32402482151,"side":"Sell","size":20000,"price":66816.4,"timestamp":"2024-05-18T15:46:02.553Z"},{"symbol":"XBTUSDT","id":32402482143,"side":"Buy","size":20000,"price":66783.2,"timestamp":"2024-05-18T15:46:02.553Z"}]}
{"table":"orderBookL2_25","action":"delete","data":[{"symbol":"ETHUSDT","id":32402482139,"side":"Buy","price":3109.45,"timestamp":"2024-05-18T15:46:02.558Z"}]}
{"table":"orderBookL2_25","action":"insert","data":[{"symbol":"ETHUSDT","id":32402482159,"side":"Buy","size":1000,"price":3109.43,"timestamp":"2024-05-18T15:46:02.558Z"}]}
{"table":"orderBookL2_25","action":"delete","data":[{"symbol":"XBTUSDT","id":32402481892,"side":"Sell","price":66822.7,"timestamp":"2024-05-18T15:46:02.602Z"},{"symbol":"XBTUSDT","id":32402481890,"side":"Sell","price":66822.8,"timestamp":"2024-05-18T15:46:02.602Z"}]}
{"table":"orderBookL2_25","action":"insert","data":[{"symbol":"XBTUSDT","id":32402482237,"side":"Sell","size":1000,"price":66822.5,"timestamp":"2024-05-18T15:46:02.602Z"},{"symbol":"XBTUSDT","id":32402482235,"side":"Sell","size":1000,"price":66822.6,"timestamp":"2024-05-18T15:46:02.602Z"}]}
{"table":"orderBookL2_25","action":"delete","data":[{"symbol":"ETHUSDT","id":32402482159,"side":"Buy","price":3109.43,"timestamp":"2024-05-18T15:46:02.607Z"},{"symbol":"ETHUSDT","id":32402481746,"side":"Buy","price":3109.44,"timestamp":"2024-05-18T15:46:02.607Z"}]}
{"table":"orderBookL2_25","action":"update","data":[{"symbol":"ETHUSDT","id":32401945550,"side":"Buy","size":2000,"price":3109.40,"timestamp":"2024-05-18T15:46:02.607Z"},{"symbol":"ETHUSDT","id":32402397491,"side":"Buy","size":100000,"price":3107.56,"timestamp":"2024-05-18T15:46:02.607Z"}]}
{"table":"orderBookL2_25","action":"insert","data":[{"symbol":"ETHUSDT","id":32402482249,"side":"Buy","size":1000,"price":3109.39,"timestamp":"2024-05-18T15:46:02.607Z"},{"symbol":"ETHUSDT","id":32402482245,"side":"Buy","size":1051000,"price":3108.46,"timestamp":"2024-05-18T15:46:02.607Z"}]}
{"table":"orderBookL2_25","action":"delete","data":[{"symbol":"XBTUSDT","id":32402482235,"side":"Sell","price":66822.6,"timestamp":"2024-05-18T15:46:02.651Z"},{"symbol":"XBTUSDT","id":32402481947,"side":"Sell","price":66816.5,"timestamp":"2024-05-18T15:46:02.651Z"},{"symbol":"XBTUSDT","id":32402482151,"side":"Sell","price":66816.4,"timestamp":"2024-05-18T15:46:02.651Z"},{"symbol":"XBTUSDT","id":32402481846,"side":"Buy","price":66783.1,"timestamp":"2024-05-18T15:46:02.651Z"},{"symbol":"XBTUSDT","id":32402482143,"side":"Buy","price":66783.2,"timestamp":"2024-05-18T15:46:02.651Z"}]}
{"table":"orderBookL2_25","action":"insert","data":[{"symbol":"XBTUSDT","id":32402482280,"side":"Sell","size":1000,"price":66822.4,"timestamp":"2024-05-18T15:46:02.651Z"},{"symbol":"XBTUSDT","id":32402482297,"side":"Sell","size":20000,"price":66816.1,"timestamp":"2024-05-18T15:46:02.651Z"},{"symbol":"XBTUSDT","id":32402482251,"side":"Sell","size":20000,"price":66816.2,"timestamp":"2024-05-18T15:46:02.651Z"},{"symbol":"XBTUSDT","id":32402482327,"side":"Buy","size":20000,"price":66783.5,"timestamp":"2024-05-18T15:46:02.651Z"},{"symbol":"XBTUSDT","id":32402482255,"side":"Buy","size":20000,"price":66783.6,"timestamp":"2024-05-18T15:46:02.651Z"}]}
{"table":"orderBookL2_25","action":"delete","data":[{"symbol":"ETHUSDT","id":32402482039,"side":"Sell","price":3111.10,"timestamp":"2024-05-18T15:46:02.656Z"},{"symbol":"ETHUSDT","id":32402460546,"side":"Sell","price":3112.42,"timestamp":"2024-05-18T15:46:02.656Z"},{"symbol":"ETHUSDT","id":32402482058,"side":"Buy","price":3109.69,"timestamp":"2024-05-18T15:46:02.656Z"},{"symbol":"ETHUSDT","id":32402481788,"side":"Buy","price":3109.68,"timestamp":"2024-05-18T15:46:02.656Z"}]}
{"table":"orderBookL2_25","action":"update","data":[{"symbol":"ETHUSDT","id":32402480356,"side":"Sell","size":132000,"price":3111.09,"timestamp":"2024-05-18T15:46:02.656Z"},{"symbol":"ETHUSDT","id":32402481027,"side":"Sell","size":43000,"price":3111.11,"timestamp":"2024-05-18T15:46:02.656Z"}]}
{"table":"orderBookL2_25","action":"insert","data":[{"symbol":"ETHUSDT","id":32402482293,"side":"Sell","size":32000,"price":3111.08,"timestamp":"2024-05-18T15:46:02.656Z"},{"symbol":"ETHUSDT","id":32402482300,"side":"Sell","size":519000,"price":3112.18,"timestamp":"2024-05-18T15:46:02.656Z"},{"symbol":"ETHUSDT","id":32402482307,"side":"Buy","size":32000,"price":3109.65,"timestamp":"2024-05-18T15:46:02.656Z"},{"symbol":"ETHUSDT","id":32402482312,"side":"Buy","size":32000,"price":3109.64,"timestamp":"2024-05-18T15:46:02.656Z"}]}
{"table":"orderBookL2_25","action":"delete","data":[{"symbol":"XBTUSDT","id":32402482297,"side":"Sell","price":66816.1,"timestamp":"2024-05-18T15:46:02.700Z"}]}
{"table":"orderBookL2_25","action":"insert","data":[{"symbol":"XBTUSDT","id":32402482334,"side":"Sell","size":20000,"price":66816.3,"timestamp":"2024-05-18T15:46:02.700Z"}]}
{"table":"orderBookL2_25","action":"delete","data":[{"symbol":"XBTUSDT","id":32402482085,"side":"Sell","price":66815.1,"timestamp":"2024-05-18T15:46:02.749Z"},{"symbol":"XBTUSDT","id":32402482083,"side":"Sell","price":66811.9,"timestamp":"2024-05-18T15:46:02.749Z"},{"symbol":"XBTUSDT","id":32402482077,"side":"Sell","price":66815.2,"timestamp":"2024-05-18T15:46:02.749Z"}]}
{"table":"orderBookL2_25","action":"update","data":[{"symbol":"XBTUSDT","id":32402463841,"side":"Buy","size":442000,"price":66784.3,"timestamp":"2024-05-18T15:46:02.749Z"}]}
{"table":"orderBookL2_25","action":"insert","data":[{"symbol":"XBTUSDT","id":32402482420,"side":"Sell","size":226000,"price":66814.9,"timestamp":"2024-05-18T15:46:02.749Z"},{"symbol":"XBTUSDT","id":32402482414,"side":"Sell","size":372000,"price":66815.0,"timestamp":"2024-05-18T15:46:02.749Z"},{"symbol":"XBTUSDT","id":32402458161,"side":"Sell","size":159000,"price":66824.3,"timestamp":"2024-05-18T15:46:02.749Z"}]}
{"table":"orderBookL2_25","action":"delete","data":[{"symbol":"ETHUSDT","id":32402482249,"side":"Buy","price":3109.39,"timestamp":"2024-05-18T15:46:02.787Z"}]}
{"table":"orderBookL2_25","action":"insert","data":[{"symbol":"ETHUSDT","id":32402482441,"side":"Buy","size":1000,"price":3109.41,"timestamp":"2024-05-18T15:46:02.787Z"}]}
{"table":"orderBookL2_25","action":"delete","data":[{"symbol":"XBTUSDT","id":32402482334,"side":"Sell","price":66816.3,"timestamp":"2024-05-18T15:46:02.798Z"},{"symbol":"XBTUSDT","id":32402482327,"side":"Buy","price":66783.5,"timestamp":"2024-05-18T15:46:02.798Z"}]}
{"table":"orderBookL2_25","action":"update","data":[{"symbol":"XBTUSDT","id":32402480326,"side":"Buy","size":102000,"price":66788.2,"timestamp":"2024-05-18T15:46:02.798Z"}]}
{"table":"orderBookL2_25","action":"insert","data":[{"symbol":"XBTUSDT","id":32402482453,"side":"Sell","size":20000,"price":66816.1,"timestamp":"2024-05-18T15:46:02.798Z"},{"symbol":"XBTUSDT","id":32402482457,"side":"Buy","size":20000,"price":66783.7,"timestamp":"2024-05-18T15:46:02.798Z"}]}
{"table":"orderBookL2_25","action":"delete","data":[{"symbol":"ETHUSDT","id":32402450496,"side":"Sell","price":3112.27,"timestamp":"2024-05-18T15:46:02.836Z"},{"symbol":"ETHUSDT","id":32402482312,"side":"Buy","price":3109.64,"timestamp":"2024-05-18T15:46:02.836Z"}]}
{"table":"orderBookL2_25","action":"update","data":[{"symbol":"ETHUSDT","id":32402480356,"side":"Sell","size":100000,"price":3111.09,"timestamp":"2024-05-18T15:46:02.836Z"}]}
{"table":"orderBookL2_25","action":"insert","data":[{"symbol":"ETHUSDT","id":32402482464,"side":"Sell","size":32000,"price":3111.07,"timestamp":"2024-05-18T15:46:02.836Z"},{"symbol":"ETHUSDT","id":32402482445,"side":"Buy","size":32000,"price":3109.66,"timestamp":"2024-05-18T15:46:02.836Z"}]}
{"table":"orderBookL2_25","action":"delete","data":[{"symbol":"XBTUSDT","id":32402482237,"side":"Sell","price":66822.5,"timestamp":"2024-05-18T15:46:02.847Z"},{"symbol":"XBTUSDT","id":32402362888,"side":"Buy","price":66762.2,"timestamp":"2024-05-18T15:46:02.847Z"},{"symbol":"XBTUSDT","id":32402479815,"side":"Buy","price":66801.7,"timestamp":"2024-05-18T15:46:02.847Z"}]}
{"table":"orderBookL2_25","action":"update","data":[{"symbol":"XBTUSDT","id":32402455289,"side":"Sell","size":23000,"price":66822.3,"timestamp":"2024-05-18T15:46:02.847Z"}]}
{"table":"orderBookL2_25","action":"insert","data":[{"symbol":"XBTUSDT","id":32402441693,"side":"Sell","size":102000,"price":66829.0,"timestamp":"2024-05-18T15:46:02.847Z"},{"symbol":"XBTUSDT","id":32402482482,"side":"Buy","size":11000,"price":66798.1,"timestamp":"2024-05-18T15:46:02.847Z"},{"symbol":"XBTUSDT","id":32402482479,"side":"Buy","size":21000,"price":66787.8,"timestamp":"2024-05-18T15:46:02.847Z"}]}
{"table":"orderBookL2_25","action":"delete","data":[{"symbol":"XBTUSDT","id":32402482251,"side":"Sell","price":66816.2,"timestamp":"2024-05-18T15:46:02.896Z"},{"symbol":"XBTUSDT","id":32402482280,"side":"Sell","price":66822.4,"timestamp":"2024-05-18T15:46:02.896Z"},{"symbol":"XBTUSDT","id":32402482453,"side":"Sell","price":66816.1,"timestamp":"2024-05-18T15:46:02.896Z"},{"symbol":"XBTUSDT","id":32402482255,"side":"Buy","price":66783.6,"timestamp":"2024-05-18T15:46:02.896Z"}]}
{"table":"orderBookL2_25","action":"update","data":[{"symbol":"XBTUSDT","id":32402242406,"side":"Sell","size":139000,"price":66822.2,"timestamp":"2024-05-18T15:46:02.896Z"},{"symbol":"XBTUSDT","id":32402455289,"side":"Sell","size":22000,"price":66822.3,"timestamp":"2024-05-18T15:46:02.896Z"}]}
{"table":"orderBookL2_25","action":"insert","data":[{"symbol":"XBTUSDT","id":32402482544,"side":"Sell","size":20000,"price":66815.9,"timestamp":"2024-05-18T15:46:02.896Z"},{"symbol":"XBTUSDT","id":32402482562,"side":"Sell","size":20000,"price":66816.0,"timestamp":"2024-05-18T15:46:02.896Z"},{"symbol":"XBTUSDT","id":32402482536,"side":"Sell","size":1000,"price":66822.1,"timestamp":"2024-05-18T15:46:02.896Z"},{"symbol":"XBTUSDT","id":32402482560,"side":"Buy","size":20000,"price":66783.6,"timestamp":"2024-05-18T15:46:02.896Z"}]}
{"table":"orderBookL2_25","action":"delete","data":[{"symbol":"ETHUSDT","id":32402397491,"side":"Buy","price":3107.56,"timestamp":"2024-05-18T15:46:02.939Z"}]}
{"table":"orderBookL2_25","action":"insert","data":[{"symbol":"ETHUSDT","id":32402482596,"side":"Buy","size":241000,"price":3109.67,"timestamp":"2024-05-18T15:46:02.939Z"}]}
{"table":"orderBookL2_25","action":"delete","data":[{"symbol":"XBTUSDT","id":32402482562,"side":"Sell","price":66816.0,"timestamp":"2024-05-18T15:46:02.945Z"},{"symbol":"XBTUSDT","id":32402482544,"side":"Sell","price":66815.9,"timestamp":"2024-05-18T15:46:02.945Z"},{"symbol":"XBTUSDT","id":32402360485,"side":"Buy","price":66764.4,"timestamp":"2024-05-18T15:46:02.945Z"},{"symbol":"XBTUSDT","id":32402482560,"side":"Buy","price":66783.6,"timestamp":"2024-05-18T15:46:02.945Z"}]}
{"table":"orderBookL2_25","action":"update","data":[{"symbol":"XBTUSDT","id":32402461579,"side":"Sell","size":120000,"price":66815.7,"timestamp":"2024-05-18T15:46:02.945Z"}]}
{"table":"orderBookL2_25","action":"insert","data":[{"symbol":"XBTUSDT","id":32402457533,"side":"Sell","size":331000,"price":66830.8,"timestamp":"2024-05-18T15:46:02.945Z"},{"symbol":"XBTUSDT","id":32402482599,"side":"Sell","size":20000,"price":66815.6,"timestamp":"2024-05-18T15:46:02.945Z"},{"symbol":"XBTUSDT","id":32402482604,"side":"Buy","size":20000,"price":66784.6,"timestamp":"2024-05-18T15:46:02.945Z"},{"symbol":"XBTUSDT","id":32402482567,"side":"Buy","size":20000,"price":66801.7,"timestamp":"2024-05-18T15:46:02.945Z"}]}
{"table":"orderBookL2_25","action":"delete","data":[{"symbol":"ETHUSDT","id":32402482300,"side":"Sell","price":3112.18,"timestamp":"2024-05-18T15:46:02.989Z"},{"symbol":"ETHUSDT","id":32401850719,"side":"Buy","price":3107.70,"timestamp":"2024-05-18T15:46:02.989Z"}]}
{"table":"orderBookL2_25","action":"update","data":[{"symbol":"ETHUSDT","id":32401945550,"side":"Buy","size":1000,"price":3109.40,"timestamp":"2024-05-18T15:46:02.989Z"}]}
{"table":"orderBookL2_25","action":"insert","data":[{"symbol":"ETHUSDT","id":32402450496,"side":"Sell","size":100000,"price":3112.27,"timestamp":"2024-05-18T15:46:02.989Z"},{"symbol":"ETHUSDT","id":32402482639,"side":"Buy","size":1000,"price":3109.42,"timestamp":"2024-05-18T15:46:02.989Z"}]}
{"table":"orderBookL2_25","action":"delete","data":[{"symbol":"XBTUSDT","id":32402457533,"side":"Sell","price":66830.8,"timestamp":"2024-05-18T15:46:02.994Z"},{"symbol":"XBTUSDT","id":32402482599,"side":"Sell","price":66815.6,"timestamp":"2024-05-18T15:46:02.994Z"},{"symbol":"XBTUSDT","id":32402482536,"side":"Sell","price":66822.1,"timestamp":"2024-05-18T15:46:02.994Z"},{"symbol":"XBTUSDT","id":32402482482,"side":"Buy","price":66798.1,"timestamp":"2024-05-18T15:46:02.994Z"},{"symbol":"XBTUSDT","id":32402482604,"side":"Buy","price":66784.6,"timestamp":"2024-05-18T15:46:02.994Z"},{"symbol":"XBTUSDT","id":32402482457,"side":"Buy","price":66783.7,"timestamp":"2024-05-18T15:46:02.994Z"}]}
{"table":"orderBookL2_25","action":"update","data":[{"symbol":"XBTUSDT","id":32402441693,"side":"Sell","size":102000,"price":66829.0,"timestamp":"2024-05-18T15:46:02.994Z"},{"symbol":"XBTUSDT","id":32402242406,"side":"Sell","size":139000,"price":66822.2,"timestamp":"2024-05-18T15:46:02.994Z"},{"symbol":"XBTUSDT","id":32402461579,"side":"Sell","size":100000,"price":66815.7,"timestamp":"2024-05-18T15:46:02.994Z"},{"symbol":"XBTUSDT","id":32402480644,"side":"Buy","size":228000,"price":66784.4,"timestamp":"2024-05-18T15:46:02.994Z"},{"symbol":"XBTUSDT","id":32402463841,"side":"Buy","size":442000,"price":66784.3,"timestamp":"2024-05-18T15:46:02.994Z"}]}
{"table":"orderBookL2_25","action":"insert","data":[{"symbol":"XBTUSDT","id":32402482685,"side":"Sell","size":20000,"price":66815.9,"timestamp":"2024-05-18T15:46:02.994Z"},{"symbol":"XBTUSDT","id":32402482689,"side":"Sell","size":20000,"price":66815.8,"timestamp":"2024-05-18T15:46:02.994Z"},{"symbol":"XBTUSDT","id":32402482656,"side":"Sell","size":1000,"price":66822.1,"timestamp":"2024-05-18T15:46:02.994Z"},{"symbol":"XBTUSDT","id":32402482691,"side":"Buy","size":20000,"price":66783.8,"timestamp":"2024-05-18T15:46:02.994Z"},{"symbol":"XBTUSDT","id":32402482687,"side":"Buy","size":20000,"price":66783.7,"timestamp":"2024-05-18T15:46:02.994Z"},{"symbol":"XBTUSDT","id":32402360485,"side":"Buy","size":100000,"price":66764.4,"timestamp":"2024-05-18T15:46:02.994Z"}]}
{"table":"orderBookL2_25","action":"delete","data":[{"symbol":"ETHUSDT","id":32402482464,"side":"Sell","price":3111.07,"timestamp":"2024-05-18T15:46:03.038Z"},{"symbol":"ETHUSDT","id":32402480165,"side":"Sell","price":3110.40,"timestamp":"2024-05-18T15:46:03.038Z"},{"symbol":"ETHUSDT","id":32402480282,"side":"Sell","price":3110.29,"timestamp":"2024-05-18T15:46:03.038Z"},{"symbol":"ETHUSDT","id":32402480191,"side":"Sell","price":3110.39,"timestamp":"2024-05-18T15:46:03.038Z"},{"symbol":"ETHUSDT","id":32402480356,"side":"Sell","price":3111.09,"timestamp":"2024-05-18T15:46:03.038Z"},{"symbol":"ETHUSDT","id":32402482639,"side":"Buy","price":3109.42,"timestamp":"2024-05-18T15:46:03.038Z"},{"symbol":"ETHUSDT","id":32402482441,"side":"Buy","price":3109.41,"timestamp":"2024-05-18T15:46:03.038Z"},{"symbol":"ETHUSDT","id":32402482445,"side":"Buy","price":3109.66,"timestamp":"2024-05-18T15:46:03.038Z"},{"symbol":"ETHUSDT","id":32402482060,"side":"Buy","price":3109.91,"timestamp":"2024-05-18T15:46:03.038Z"},{"symbol":"ETHUSDT","id":32402482307,"side":"Buy","price":3109.65,"timestamp":"2024-05-18T15:46:03.038Z"},{"symbol":"ETHUSDT","id":32402480786,"side":"Buy","price":3107.98,"timestamp":"2024-05-18T15:46:03.038Z"}]}
{"table":"orderBookL2_25","action":"update","data":[{"symbol":"ETHUSDT","id":32402480864,"side":"Sell","size":2000,"price":3110.13,"timestamp":"2024-05-18T15:46:03.038Z"},{"symbol":"ETHUSDT","id":32402482596,"side":"Buy","size":241000,"price":3109.67,"timestamp":"2024-05-18T15:46:03.038Z"}]}
{"table":"orderBookL2_25","action":"insert","data":[{"symbol":"ETHUSDT","id":32402482738,"side":"Sell","size":25000,"price":3110.47,"timestamp":"2024-05-18T15:46:03.038Z"},{"symbol":"ETHUSDT","id":32402482796,"side":"Sell","size":32000,"price":3111.09,"timestamp":"2024-05-18T15:46:03.038Z"},{"symbol":"ETHUSDT","id":32402449038,"side":"Sell","size":100000,"price":3112.43,"timestamp":"2024-05-18T15:46:03.038Z"},{"symbol":"ETHUSDT","id":32402482714,"side":"Sell","size":563000,"price":3112.67,"timestamp":"2024-05-18T15:46:03.038Z"},{"symbol":"ETHUSDT","id":32402482787,"side":"Sell","size":48000,"price":3111.49,"timestamp":"2024-05-18T15:46:03.038Z"},{"symbol":"ETHUSDT","id":32402482706,"side":"Buy","size":1000,"price":3109.43,"timestamp":"2024-05-18T15:46:03.038Z"},{"symbol":"ETHUSDT","id":32402482806,"side":"Buy","size":32000,"price":3109.69,"timestamp":"2024-05-18T15:46:03.038Z"},{"symbol":"ETHUSDT","id":32402482758,"side":"Buy","size":100000,"price":3109.48,"timestamp":"2024-05-18T15:46:03.038Z"},{"symbol":"ETHUSDT","id":32402482723,"side":"Buy","size":32000,"price":3109.68,"timestamp":"2024-05-18T15:46:03.038Z"},{"symbol":"ETHUSDT","id":32402482712,"side":"Buy","size":538000,"price":3108.62,"timestamp":"2024-05-18T15:46:03.038Z"},{"symbol":"ETHUSDT","id":32402482698,"side":"Buy","size":1000,"price":3109.44,"timestamp":"2024-05-18T15:46:03.038Z"}]}
{"table":"orderBookL2_25","action":"delete","data":[{"symbol":"XBTUSDT","id":32402360485,"side":"Buy","price":66764.4,"timestamp":"2024-05-18T15:46:03.043Z"}]}
{"table":"orderBookL2_25","action":"update","data":[{"symbol":"XBTUSDT","id":32402441693,"side":"Sell","size":100000,"price":66829.0,"timestamp":"2024-05-18T15:46:03.043Z"},{"symbol":"XBTUSDT","id":32402462668,"side":"Sell","size":359000,"price":66801.9,"timestamp":"2024-05-18T15:46:03.043Z"}]}
{"table":"orderBookL2_25","action":"insert","data":[{"symbol":"XBTUSDT","id":32402482743,"side":"Buy","size":100000,"price":66791.6,"timestamp":"2024-05-18T15:46:03.043Z"}]}
{"table":"orderBookL2_25","action":"delete","data":[{"symbol":"ETHUSDT","id":32402482738,"side":"Sell","price":3110.47,"timestamp":"2024-05-18T15:46:03.087Z"},{"symbol":"ETHUSDT","id":32402480977,"side":"Sell","price":3110.48,"timestamp":"2024-05-18T15:46:03.087Z"},{"symbol":"ETHUSDT","id":32402482706,"side":"Buy","price":3109.43,"timestamp":"2024-05-18T15:46:03.087Z"},{"symbol":"ETHUSDT","id":32402482698,"side":"Buy","price":3109.44,"timestamp":"2024-05-18T15:46:03.087Z"},{"symbol":"ETHUSDT","id":32402482806,"side":"Buy","price":3109.69,"timestamp":"2024-05-18T15:46:03.087Z"},{"symbol":"ETHUSDT","id":32402482723,"side":"Buy","price":3109.68,"timestamp":"2024-05-18T15:46:03.087Z"}]}
{"table":"orderBookL2_25","action":"insert","data":[{"symbol":"ETHUSDT","id":32402482842,"side":"Sell","size":29000,"price":3110.64,"timestamp":"2024-05-18T15:46:03.087Z"},{"symbol":"ETHUSDT","id":32402482851,"side":"Sell","size":26000,"price":3110.63,"timestamp":"2024-05-18T15:46:03.087Z"},{"symbol":"ETHUSDT","id":32402482818,"side":"Buy","size":1000,"price":3109.45,"timestamp":"2024-05-18T15:46:03.087Z"},{"symbol":"ETHUSDT","id":32402482872,"side":"Buy","size":32000,"price":3109.71,"timestamp":"2024-05-18T15:46:03.087Z"},{"symbol":"ETHUSDT","id":32402482848,"side":"Buy","size":1000,"price":3109.46,"timestamp":"2024-05-18T15:46:03.087Z"},{"symbol":"ETHUSDT","id":32402482875,"side":"Buy","size":32000,"price":3109.70,"timestamp":"2024-05-18T15:46:03.087Z"}]}
{"table":"orderBookL2_25","action":"delete","data":[{"symbol":"ETHUSDT","id":32402482787,"side":"Sell","price":3111.49,"timestamp":"2024-05-18T15:46:03.136Z"},{"symbol":"ETHUSDT","id":32402482842,"side":"Sell","price":3110.64,"timestamp":"2024-05-18T15:46:03.136Z"},{"symbol":"ETHUSDT","id":32402482851,"side":"Sell","price":3110.63,"timestamp":"2024-05-18T15:46:03.136Z"},{"symbol":"ETHUSDT","id":32402482848,"side":"Buy","price":3109.46,"timestamp":"2024-05-18T15:46:03.136Z"}]}
{"table":"orderBookL2_25","action":"update","data":[{"symbol":"ETHUSDT","id":32402482714,"side":"Sell","size":563000,"price":3112.67,"timestamp":"2024-05-18T15:46:03.136Z"}]}
{"table":"orderBookL2_25","action":"insert","data":[{"symbol":"ETHUSDT","id":32402447682,"side":"Sell","size":100000,"price":3112.68,"timestamp":"2024-05-18T15:46:03.136Z"},{"symbol":"ETHUSDT","id":32402482912,"side":"Sell","size":29000,"price":3110.72,"timestamp":"2024-05-18T15:46:03.136Z"},{"symbol":"ETHUSDT","id":32402482929,"side":"Sell","size":17000,"price":3110.71,"timestamp":"2024-05-18T15:46:03.136Z"},{"symbol":"ETHUSDT","id":32402482947,"side":"Buy","size":1000,"price":3109.44,"timestamp":"2024-05-18T15:46:03.136Z"}]}
{"table":"orderBookL2_25","action":"delete","data":[{"symbol":"XBTUSDT","id":32402482691,"side":"Buy","price":66783.8,"timestamp":"2024-05-18T15:46:03.151Z"}]}
{"table":"orderBookL2_25","action":"insert","data":[{"symbol":"XBTUSDT","id":32402482999,"side":"Buy","size":20000,"price":66783.6,"timestamp":"2024-05-18T15:46:03.151Z"}]}
{"table":"orderBookL2_25","action":"delete","data":[{"symbol":"ETHUSDT","id":32402482293,"side":"Sell","price":3111.08,"timestamp":"2024-05-18T15:46:03.185Z"},{"symbol":"ETHUSDT","id":32402482796,"side":"Sell","price":3111.09,"timestamp":"2024-05-18T15:46:03.185Z"},{"symbol":"ETHUSDT","id":32402482872,"side":"Buy","price":3109.71,"timestamp":"2024-05-18T15:46:03.185Z"},{"symbol":"ETHUSDT","id":32402482875,"side":"Buy","price":3109.70,"timestamp":"2024-05-18T15:46:03.185Z"},{"symbol":"ETHUSDT","id":32402482818,"side":"Buy","price":3109.45,"timestamp":"2024-05-18T15:46:03.185Z"}]}
{"table":"orderBookL2_25","action":"insert","data":[{"symbol":"ETHUSDT","id":32402483012,"side":"Sell","size":32000,"price":3111.17,"timestamp":"2024-05-18T15:46:03.185Z"},{"symbol":"ETHUSDT","id":32402483014,"side":"Sell","size":32000,"price":3111.16,"timestamp":"2024-05-18T15:46:03.185Z"},{"symbol":"ETHUSDT","id":32402482991,"side":"Buy","size":32000,"price":3109.68,"timestamp":"2024-05-18T15:46:03.185Z"},{"symbol":"ETHUSDT","id":32402482997,"side":"Buy","size":32000,"price":3109.69,"timestamp":"2024-05-18T15:46:03.185Z"},{"symbol":"ETHUSDT","id":32402482951,"side":"Buy","size":1000,"price":3109.43,"timestamp":"2024-05-18T15:46:03.185Z"}]}
{"table":"orderBookL2_25","action":"delete","data":[{"symbol":"XBTUSDT","id":32402482689,"side":"Sell","price":66815.8,"timestamp":"2024-05-18T15:46:03.200Z"},{"symbol":"XBTUSDT","id":32402441693,"side":"Sell","price":66829.0,"timestamp":"2024-05-18T15:46:03.200Z"}]}
{"table":"orderBookL2_25","action":"update","data":[{"symbol":"XBTUSDT","id":32402242406,"side":"Sell","size":138000,"price":66822.2,"timestamp":"2024-05-18T15:46:03.200Z"}]}
{"table":"orderBookL2_25","action":"insert","data":[{"symbol":"XBTUSDT","id":32402483028,"side":"Sell","size":1000,"price":66822.0,"timestamp":"2024-05-18T15:46:03.200Z"},{"symbol":"XBTUSDT","id":32402483001,"side":"Sell","size":20000,"price":66816.0,"timestamp":"2024-05-18T15:46:03.200Z"}]}
{"table":"orderBookL2_25","action":"delete","data":[{"symbol":"ETHUSDT","id":32402483012,"side":"Sell","price":3111.17,"timestamp":"2024-05-18T15:46:03.234Z"},{"symbol":"ETHUSDT","id":32402482951,"side":"Buy","price":3109.43,"timestamp":"2024-05-18T15:46:03.234Z"}]}
{"table":"orderBookL2_25","action":"insert","data":[{"symbol":"ETHUSDT","id":32402483059,"side":"Sell","size":32000,"price":3111.15,"timestamp":"2024-05-18T15:46:03.234Z"},{"symbol":"ETHUSDT","id":32402483024,"side":"Buy","size":1000,"price":3109.45,"timestamp":"2024-05-18T15:46:03.234Z"}]}
{"table":"orderBookL2_25","action":"delete","data":[{"symbol":"XBTUSDT","id":32402482687,"side":"Buy","price":66783.7,"timestamp":"2024-05-18T15:46:03.249Z"}]}
{"table":"orderBookL2_25","action":"insert","data":[{"symbol":"XBTUSDT","id":32402483074,"side":"Buy","size":20000,"price":66783.8,"timestamp":"2024-05-18T15:46:03.249Z"}]}
{"table":"orderBookL2_25","action":"delete","data":[{"symbol":"ETHUSDT","id":32402482991,"side":"Buy","price":3109.68,"timestamp":"2024-05-18T15:46:03.283Z"}]}
{"table":"orderBookL2_25","action":"insert","data":[{"symbol":"ETHUSDT","id":32402483066,"side":"Buy","size":32000,"price":3109.70,"timestamp":"2024-05-18T15:46:03.283Z"}]}
{"table":"orderBookL2_25","action":"delete","data":[{"symbol":"XBTUSDT","id":32402482656,"side":"Sell","price":66822.1,"timestamp":"2024-05-18T15:46:03.298Z"},{"symbol":"XBTUSDT","id":32402482685,"side":"Sell","price":66815.9,"timestamp":"2024-05-18T15:46:03.298Z"},{"symbol":"XBTUSDT","id":32402483001,"side":"Sell","price":66816.0,"timestamp":"2024-05-18T15:46:03.298Z"},{"symbol":"XBTUSDT","id":32402483028,"side":"Sell","price":66822.0,"timestamp":"2024-05-18T15:46:03.298Z"},{"symbol":"XBTUSDT","id":32402483074,"side":"Buy","price":66783.8,"timestamp":"2024-05-18T15:46:03.298Z"},{"symbol":"XBTUSDT","id":32402482999,"side":"Buy","price":66783.6,"timestamp":"2024-05-18T15:46:03.298Z"}]}
{"table":"orderBookL2_25","action":"update","data":[{"symbol":"XBTUSDT","id":32402471671,"side":"Sell","size":74000,"price":66821.7,"timestamp":"2024-05-18T15:46:03.298Z"},{"symbol":"XBTUSDT","id":32402461579,"side":"Sell","size":100000,"price":66815.7,"timestamp":"2024-05-18T15:46:03.298Z"},{"symbol":"XBTUSDT","id":32402479097,"side":"Sell","size":3000,"price":66815.5,"timestamp":"2024-05-18T15:46:03.298Z"}]}
{"table":"orderBookL2_25","action":"insert","data":[{"symbol":"XBTUSDT","id":32402483117,"side":"Sell","size":1000,"price":66822.1,"timestamp":"2024-05-18T15:46:03.298Z"},{"symbol":"XBTUSDT","id":32402483136,"side":"Sell","size":20000,"price":66815.9,"timestamp":"2024-05-18T15:46:03.298Z"},{"symbol":"XBTUSDT","id":32402483119,"side":"Sell","size":1000,"price":66822.0,"timestamp":"2024-05-18T15:46:03.298Z"},{"symbol":"XBTUSDT","id":32402483134,"side":"Sell","size":20000,"price":66815.8,"timestamp":"2024-05-18T15:46:03.298Z"},{"symbol":"XBTUSDT","id":32402483138,"side":"Buy","size":20000,"price":66783.8,"timestamp":"2024-05-18T15:46:03.298Z"},{"symbol":"XBTUSDT","id":32402483141,"side":"Buy","size":20000,"price":66783.7,"timestamp":"2024-05-18T15:46:03.298Z"}]}
{"table":"orderBookL2_25","action":"delete","data":[{"symbol":"ETHUSDT","id":32402483059,"side":"Sell","price":3111.15,"timestamp":"2024-05-18T15:46:03.332Z"},{"symbol":"ETHUSDT","id":32402483066,"side":"Buy","price":3109.70,"timestamp":"2024-05-18T15:46:03.332Z"},{"symbol":"ETHUSDT","id":32402483024,"side":"Buy","price":3109.45,"timestamp":"2024-05-18T15:46:03.332Z"}]}
{"table":"orderBookL2_25","action":"insert","data":[{"symbol":"ETHUSDT","id":32402483151,"side":"Sell","size":32000,"price":3111.17,"timestamp":"2024-05-18T15:46:03.332Z"},{"symbol":"ETHUSDT","id":32402483153,"side":"Buy","size":32000,"price":3109.68,"timestamp":"2024-05-18T15:46:03.332Z"},{"symbol":"ETHUSDT","id":32402483144,"side":"Buy","size":1000,"price":3109.43,"timestamp":"2024-05-18T15:46:03.332Z"}]}
{"table":"orderBookL2_25","action":"delete","data":[{"symbol":"XBTUSDT","id":32402483119,"side":"Sell","price":66822.0,"timestamp":"2024-05-18T15:46:03.347Z"}]}
{"table":"orderBookL2_25","action":"update","data":[{"symbol":"XBTUSDT","id":32402242406,"side":"Sell","size":139000,"price":66822.2,"timestamp":"2024-05-18T15:46:03.347Z"}]}
{"table":"orderBookL2_25","action":"insert","data":[{"symbol":"XBTUSDT","id":32402441693,"side":"Sell","size":100000,"price":66829.0,"timestamp":"2024-05-18T15:46:03.347Z"}]}
{"table":"orderBookL2_25","action":"delete","data":[{"symbol":"ETHUSDT","id":32402482947,"side":"Buy","price":3109.44,"timestamp":"2024-05-18T15:46:03.389Z"}]}
{"table":"orderBookL2_25","action":"insert","data":[{"symbol":"ETHUSDT","id":32402483219,"side":"Buy","size":1000,"price":3109.42,"timestamp":"2024-05-18T15:46:03.389Z"}]}
{"table":"orderBookL2_25","action":"delete","data":[{"symbol":"XBTUSDT","id":32402363228,"side":"Buy","price":66766.1,"timestamp":"2024-05-18T15:46:03.408Z"}]}
{"table":"orderBookL2_25","action":"insert","data":[{"symbol":"XBTUSDT","id":32402483246,"side":"Buy","size":8000,"price":66791.7,"timestamp":"2024-05-18T15:46:03.408Z"}]}
{"table":"orderBookL2_25","action":"delete","data":[{"symbol":"ETHUSDT","id":32402483151,"side":"Sell","price":3111.17,"timestamp":"2024-05-18T15:46:03.438Z"},{"symbol":"ETHUSDT","id":32402482997,"side":"Buy","price":3109.69,"timestamp":"2024-05-18T15:46:03.438Z"}]}
{"table":"orderBookL2_25","action":"update","data":[{"symbol":"ETHUSDT","id":32402482596,"side":"Buy","size":241000,"price":3109.67,"timestamp":"2024-05-18T15:46:03.438Z"}]}
{"table":"orderBookL2_25","action":"insert","data":[{"symbol":"ETHUSDT","id":32402483244,"side":"Sell","size":32000,"price":3111.15,"timestamp":"2024-05-18T15:46:03.438Z"},{"symbol":"ETHUSDT","id":32402483287,"side":"Buy","size":32000,"price":3109.66,"timestamp":"2024-05-18T15:46:03.438Z"}]}
{"table":"orderBookL2_25","action":"delete","data":[{"symbol":"XBTUSDT","id":32402483134,"side":"Sell","price":66815.8,"timestamp":"2024-05-18T15:46:03.458Z"},{"symbol":"XBTUSDT","id":32402478470,"side":"Buy","price":66791.2,"timestamp":"2024-05-18T15:46:03.458Z"},{"symbol":"XBTUSDT","id":32402483138,"side":"Buy","price":66783.8,"timestamp":"2024-05-18T15:46:03.458Z"}]}
{"table":"orderBookL2_25","action":"insert","data":[{"symbol":"XBTUSDT","id":32402483249,"side":"Sell","size":20000,"price":66816.0,"timestamp":"2024-05-18T15:46:03.458Z"},{"symbol":"XBTUSDT","id":32402483253,"side":"Buy","size":20000,"price":66783.6,"timestamp":"2024-05-18T15:46:03.458Z"},{"symbol":"XBTUSDT","id":32402363228,"side":"Buy","size":1502000,"price":66766.1,"timestamp":"2024-05-18T15:46:03.458Z"}]}
{"table":"orderBookL2_25","action":"delete","data":[{"symbol":"ETHUSDT","id":32402483244,"side":"Sell","price":3111.15,"timestamp":"2024-05-18T15:46:03.487Z"},{"symbol":"ETHUSDT","id":32402483144,"side":"Buy","price":3109.43,"timestamp":"2024-05-18T15:46:03.487Z"},{"symbol":"ETHUSDT","id":32402483153,"side":"Buy","price":3109.68,"timestamp":"2024-05-18T15:46:03.487Z"}]}
{"table":"orderBookL2_25","action":"update","data":[{"symbol":"ETHUSDT","id":32402482596,"side":"Buy","size":273000,"price":3109.67,"timestamp":"2024-05-18T15:46:03.487Z"}]}
{"table":"orderBookL2_25","action":"insert","data":[{"symbol":"ETHUSDT","id":32402483317,"side":"Sell","size":32000,"price":3111.17,"timestamp":"2024-05-18T15:46:03.487Z"},{"symbol":"ETHUSDT","id":32402483323,"side":"Buy","size":1000,"price":3109.43,"timestamp":"2024-05-18T15:46:03.487Z"},{"symbol":"ETHUSDT","id":32401850719,"side":"Buy","size":160000,"price":3107.70,"timestamp":"2024-05-18T15:46:03.487Z"}]}
{"table":"orderBookL2_25","action":"delete","data":[{"symbol":"XBTUSDT","id":32402483249,"side":"Sell","price":66816.0,"timestamp":"2024-05-18T15:46:03.507Z"},{"symbol":"XBTUSDT","id":32402483253,"side":"Buy","price":66783.6,"timestamp":"2024-05-18T15:46:03.507Z"}]}
{"table":"orderBookL2_25","action":"insert","data":[{"symbol":"XBTUSDT","id":32402483310,"side":"Sell","size":20000,"price":66815.8,"timestamp":"2024-05-18T15:46:03.507Z"},{"symbol":"XBTUSDT","id":32402483308,"side":"Buy","size":20000,"price":66783.8,"timestamp":"2024-05-18T15:46:03.507Z"}]}
{"table":"orderBookL2_25","action":"delete","data":[{"symbol":"ETHUSDT","id":32401850719,"side":"Buy","price":3107.70,"timestamp":"2024-05-18T15:46:03.536Z"},{"symbol":"ETHUSDT","id":32402483219,"side":"Buy","price":3109.42,"timestamp":"2024-05-18T15:46:03.536Z"},{"symbol":"ETHUSDT","id":32402483287,"side":"Buy","price":3109.66,"timestamp":"2024-05-18T15:46:03.536Z"}]}
{"table":"orderBookL2_25","action":"update","data":[{"symbol":"ETHUSDT","id":32402482596,"side":"Buy","size":241000,"price":3109.67,"timestamp":"2024-05-18T15:46:03.536Z"}]}
{"table":"orderBookL2_25","action":"insert","data":[{"symbol":"ETHUSDT","id":32402483341,"side":"Buy","size":32000,"price":3109.69,"timestamp":"2024-05-18T15:46:03.536Z"},{"symbol":"ETHUSDT","id":32402483344,"side":"Buy","size":32000,"price":3109.68,"timestamp":"2024-05-18T15:46:03.536Z"},{"symbol":"ETHUSDT","id":32402483339,"side":"Buy","size":1000,"price":3109.44,"timestamp":"2024-05-18T15:46:03.536Z"}]}
{"table":"orderBookL2_25","action":"delete","data":[{"symbol":"XBTUSDT","id":32402483310,"side":"Sell","price":66815.8,"timestamp":"2024-05-18T15:46:03.636Z"}]}
{"table":"orderBookL2_25","action":"insert","data":[{"symbol":"XBTUSDT","id":32402483475,"side":"Sell","size":20000,"price":66816.0,"timestamp":"2024-05-18T15:46:03.636Z"}]}
{"table":"orderBookL2_25","action":"delete","data":[{"symbol":"ETHUSDT","id":32402483317,"side":"Sell","price":3111.17,"timestamp":"2024-05-18T15:46:03.669Z"}]}
{"table":"orderBookL2_25","action":"insert","data":[{"symbol":"ETHUSDT","id":32402483505,"side":"Sell","size":32000,"price":3111.15,"timestamp":"2024-05-18T15:46:03.669Z"}]}
{"table":"orderBookL2_25","action":"delete","data":[{"symbol":"XBTUSDT","id":32402483475,"side":"Sell","price":66816.0,"timestamp":"2024-05-18T15:46:03.685Z"},{"symbol":"XBTUSDT","id":32402483308,"side":"Buy","price":66783.8,"timestamp":"2024-05-18T15:46:03.685Z"}]}
{"table":"orderBookL2_25","action":"insert","data":[{"symbol":"XBTUSDT","id":32402483503,"side":"Sell","size":20000,"price":66815.8,"timestamp":"2024-05-18T15:46:03.685Z"},{"symbol":"XBTUSDT","id":32402483500,"side":"Buy","size":20000,"price":66783.8,"timestamp":"2024-05-18T15:46:03.685Z"}]}
{"table":"orderBookL2_25","action":"delete","data":[{"symbol":"ETHUSDT","id":32402483505,"side":"Sell","price":3111.15,"timestamp":"2024-05-18T15:46:03.719Z"},{"symbol":"ETHUSDT","id":32402447682,"side":"Sell","price":3112.68,"timestamp":"2024-05-18T15:46:03.719Z"},{"symbol":"ETHUSDT","id":32402483341,"side":"Buy","price":3109.69,"timestamp":"2024-05-18T15:46:03.719Z"},{"symbol":"ETHUSDT","id":32401854083,"side":"Buy","price":3107.72,"timestamp":"2024-05-18T15:46:03.719Z"}]}
{"table":"orderBookL2_25","action":"update","data":[{"symbol":"ETHUSDT","id":32402482596,"side":"Buy","size":241000,"price":3109.67,"timestamp":"2024-05-18T15:46:03.719Z"}]}
{"table":"orderBookL2_25","action":"insert","data":[{"symbol":"ETHUSDT","id":32402483531,"side":"Sell","size":32000,"price":3111.17,"timestamp":"2024-05-18T15:46:03.719Z"},{"symbol":"ETHUSDT","id":32402483511,"side":"Sell","size":62000,"price":3111.32,"timestamp":"2024-05-18T15:46:03.719Z"},{"symbol":"ETHUSDT","id":32402483509,"side":"Buy","size":384000,"price":3108.63,"timestamp":"2024-05-18T15:46:03.719Z"},{"symbol":"ETHUSDT","id":32402483534,"side":"Buy","size":32000,"price":3109.69,"timestamp":"2024-05-18T15:46:03.719Z"}]}
{"table":"orderBookL2_25","action":"delete","data":[{"symbol":"ETHUSDT","id":32402483531,"side":"Sell","price":3111.17,"timestamp":"2024-05-18T15:46:03.768Z"},{"symbol":"ETHUSDT","id":32402483534,"side":"Buy","price":3109.69,"timestamp":"2024-05-18T15:46:03.768Z"},{"symbol":"ETHUSDT","id":32402483339,"side":"Buy","price":3109.44,"timestamp":"2024-05-18T15:46:03.768Z"}]}
{"table":"orderBookL2_25","action":"update","data":[{"symbol":"ETHUSDT","id":32402482596,"side":"Buy","size":273000,"price":3109.67,"timestamp":"2024-05-18T15:46:03.768Z"}]}
{"table":"orderBookL2_25","action":"insert","data":[{"symbol":"ETHUSDT","id":32402483607,"side":"Sell","size":32000,"price":3111.15,"timestamp":"2024-05-18T15:46:03.768Z"},{"symbol":"ETHUSDT","id":32402483633,"side":"Buy","size":1000,"price":3109.44,"timestamp":"2024-05-18T15:46:03.768Z"},{"symbol":"ETHUSDT","id":32401854083,"side":"Buy","size":100000,"price":3107.72,"timestamp":"2024-05-18T15:46:03.768Z"}]}
{"table":"orderBookL2_25","action":"delete","data":[{"symbol":"XBTUSDT","id":32402482743,"side":"Buy","price":66791.6,"timestamp":"2024-05-18T15:46:03.779Z"}]}
{"table":"orderBookL2_25","action":"insert","data":[{"symbol":"XBTUSDT","id":32402360485,"side":"Buy","size":100000,"price":66764.4,"timestamp":"2024-05-18T15:46:03.779Z"}]}
{"table":"orderBookL2_25","action":"delete","data":[{"symbol":"ETHUSDT","id":32402483607,"side":"Sell","price":3111.15,"timestamp":"2024-05-18T15:46:03.817Z"},{"symbol":"ETHUSDT","id":32402481027,"side":"Sell","price":3111.11,"timestamp":"2024-05-18T15:46:03.817Z"},{"symbol":"ETHUSDT","id":32401854083,"side":"Buy","price":3107.72,"timestamp":"2024-05-18T15:46:03.817Z"}]}
{"table":"orderBookL2_25","action":"update","data":[{"symbol":"ETHUSDT","id":32402482596,"side":"Buy","size":241000,"price":3109.67,"timestamp":"2024-05-18T15:46:03.817Z"}]}
{"table":"orderBookL2_25","action":"insert","data":[{"symbol":"ETHUSDT","id":32402447682,"side":"Sell","size":100000,"price":3112.68,"timestamp":"2024-05-18T15:46:03.817Z"},{"symbol":"ETHUSDT","id":32402483651,"side":"Sell","size":32000,"price":3111.17,"timestamp":"2024-05-18T15:46:03.817Z"},{"symbol":"ETHUSDT","id":32402483653,"side":"Buy","size":32000,"price":3109.69,"timestamp":"2024-05-18T15:46:03.817Z"}]}
{"table":"orderBookL2_25","action":"delete","data":[{"symbol":"XBTUSDT","id":32402483117,"side":"Sell","price":66822.1,"timestamp":"2024-05-18T15:46:03.829Z"},{"symbol":"XBTUSDT","id":32402483503,"side":"Sell","price":66815.8,"timestamp":"2024-05-18T15:46:03.829Z"},{"symbol":"XBTUSDT","id":32402360485,"side":"Buy","price":66764.4,"timestamp":"2024-05-18T15:46:03.829Z"},{"symbol":"XBTUSDT","id":32402483500,"side":"Buy","price":66783.8,"timestamp":"2024-05-18T15:46:03.829Z"},{"symbol":"XBTUSDT","id":32402480174,"side":"Buy","price":66776.1,"timestamp":"2024-05-18T15:46:03.829Z"}]}
{"table":"orderBookL2_25","action":"update","data":[{"symbol":"XBTUSDT","id":32402441693,"side":"Sell","size":100000,"price":66829.0,"timestamp":"2024-05-18T15:46:03.829Z"},{"symbol":"XBTUSDT","id":32402242406,"side":"Sell","size":139000,"price":66822.2,"timestamp":"2024-05-18T15:46:03.829Z"},{"symbol":"XBTUSDT","id":32402363228,"side":"Buy","size":1502000,"price":66766.1,"timestamp":"2024-05-18T15:46:03.829Z"}]}
{"table":"orderBookL2_25","action":"insert","data":[{"symbol":"XBTUSDT","id":32402483687,"side":"Sell","size":1000,"price":66822.1,"timestamp":"2024-05-18T15:46:03.829Z"},{"symbol":"XBTUSDT","id":32402483666,"side":"Sell","size":20000,"price":66816.0,"timestamp":"2024-05-18T15:46:03.829Z"},{"symbol":"XBTUSDT","id":32402483689,"side":"Buy","size":100000,"price":66779.4,"timestamp":"2024-05-18T15:46:03.829Z"},{"symbol":"XBTUSDT","id":32402483680,"side":"Buy","size":446000,"price":66776.1,"timestamp":"2024-05-18T15:46:03.829Z"},{"symbol":"XBTUSDT","id":32402483675,"side":"Buy","size":20000,"price":66783.6,"timestamp":"2024-05-18T15:46:03.829Z"}]}
{"table":"orderBookL2_25","action":"delete","data":[{"symbol":"ETHUSDT","id":32402483651,"side":"Sell","price":3111.17,"timestamp":"2024-05-18T15:46:03.866Z"},{"symbol":"ETHUSDT","id":32402483653,"side":"Buy","price":3109.69,"timestamp":"2024-05-18T15:46:03.866Z"}]}
{"table":"orderBookL2_25","action":"update","data":[{"symbol":"ETHUSDT","id":32402482596,"side":"Buy","size":241000,"price":3109.67,"timestamp":"2024-05-18T15:46:03.866Z"}]}
{"table":"orderBookL2_25","action":"insert","data":[{"symbol":"ETHUSDT","id":32402483757,"side":"Sell","size":32000,"price":3111.17,"timestamp":"2024-05-18T15:46:03.866Z"},{"symbol":"ETHUSDT","id":32402483759,"side":"Buy","size":32000,"price":3109.69,"timestamp":"2024-05-18T15:46:03.866Z"}]}
{"table":"orderBookL2_25","action":"delete","data":[{"symbol":"XBTUSDT","id":32402483666,"side":"Sell","price":66816.0,"timestamp":"2024-05-18T15:46:03.878Z"},{"symbol":"XBTUSDT","id":32402483675,"side":"Buy","price":66783.6,"timestamp":"2024-05-18T15:46:03.878Z"}]}
{"table":"orderBookL2_25","action":"insert","data":[{"symbol":"XBTUSDT","id":32402483740,"side":"Sell","size":20000,"price":66816.0,"timestamp":"2024-05-18T15:46:03.878Z"},{"symbol":"XBTUSDT","id":32402483744,"side":"Buy","size":20000,"price":66783.6,"timestamp":"2024-05-18T15:46:03.878Z"}]}
{"table":"orderBookL2_25","action":"delete","data":[{"symbol":"ETHUSDT","id":32402447682,"side":"Sell","price":3112.68,"timestamp":"2024-05-18T15:46:03.915Z"}]}
{"table":"orderBookL2_25","action":"insert","data":[{"symbol":"ETHUSDT","id":32402483812,"side":"Sell","size":43000,"price":3111.04,"timestamp":"2024-05-18T15:46:03.915Z"}]}
{"table":"orderBookL2_25","action":"delete","data":[{"symbol":"XBTUSDT","id":32402363228,"side":"Buy","price":66766.1,"timestamp":"2024-05-18T15:46:03.970Z"}]}
{"table":"orderBookL2_25","action":"update","data":[{"symbol":"XBTUSDT","id":32402483680,"side":"Buy","size":65000,"price":66776.1,"timestamp":"2024-05-18T15:46:03.970Z"}]}
{"table":"orderBookL2_25","action":"insert","data":[{"symbol":"XBTUSDT","id":32402483844,"side":"Buy","size":347000,"price":66779.5,"timestamp":"2024-05-18T15:46:03.970Z"}]}
{"table":"orderBookL2_25","action":"delete","data":[{"symbol":"ETHUSDT","id":32402483757,"side":"Sell","price":3111.17,"timestamp":"2024-05-18T15:46:03.977Z"}]}
{"table":"orderBookL2_25","action":"insert","data":[{"symbol":"ETHUSDT","id":32402483848,"side":"Sell","size":32000,"price":3111.15,"timestamp":"2024-05-18T15:46:03.977Z"}]}
{"table":"orderBookL2_25","action":"delete","data":[{"symbol":"ETHUSDT","id":32402483759,"side":"Buy","price":3109.69,"timestamp":"2024-05-18T15:46:04.026Z"}]}
{"table":"orderBookL2_25","action":"update","data":[{"symbol":"ETHUSDT","id":32402482596,"side":"Buy","size":273000,"price":3109.67,"timestamp":"2024-05-18T15:46:04.026Z"}]}
{"table":"orderBookL2_25","action":"insert","data":[{"symbol":"ETHUSDT","id":32401854083,"side":"Buy","size":100000,"price":3107.72,"timestamp":"2024-05-18T15:46:04.026Z"}]}
{"table":"orderBookL2_25","action":"update","data":[{"symbol":"XBTUSDT","id":32402462668,"side":"Sell","size":319000,"price":66801.9,"timestamp":"2024-05-18T15:46:04.029Z"}]}
{"table":"orderBookL2_25","action":"delete","data":[{"symbol":"ETHUSDT","id":32402483848,"side":"Sell","price":3111.15,"timestamp":"2024-05-18T15:46:04.075Z"},{"symbol":"ETHUSDT","id":32401854083,"side":"Buy","price":3107.72,"timestamp":"2024-05-18T15:46:04.075Z"},{"symbol":"ETHUSDT","id":32402483633,"side":"Buy","price":3109.44,"timestamp":"2024-05-18T15:46:04.075Z"}]}
{"table":"orderBookL2_25","action":"update","data":[{"symbol":"ETHUSDT","id":32402482596,"side":"Buy","size":241000,"price":3109.67,"timestamp":"2024-05-18T15:46:04.075Z"}]}
{"table":"orderBookL2_25","action":"insert","data":[{"symbol":"ETHUSDT","id":32402483929,"side":"Sell","size":32000,"price":3111.17,"timestamp":"2024-05-18T15:46:04.075Z"},{"symbol":"ETHUSDT","id":32402483931,"side":"Buy","size":32000,"price":3109.69,"timestamp":"2024-05-18T15:46:04.075Z"},{"symbol":"ETHUSDT","id":32402483898,"side":"Buy","size":1000,"price":3109.42,"timestamp":"2024-05-18T15:46:04.075Z"}]}
{"table":"orderBookL2_25","action":"delete","data":[{"symbol":"XBTUSDT","id":32402483844,"side":"Buy","price":66779.5,"timestamp":"2024-05-18T15:46:04.084Z"}]}
{"table":"orderBookL2_25","action":"insert","data":[{"symbol":"XBTUSDT","id":32402483941,"side":"Buy","size":380000,"price":66776.2,"timestamp":"2024-05-18T15:46:04.084Z"}]}
{"table":"orderBookL2_25","action":"delete","data":[{"symbol":"ETHUSDT","id":32402460817,"side":"Sell","price":3111.78,"timestamp":"2024-05-18T15:46:04.124Z"},{"symbol":"ETHUSDT","id":32402460354,"side":"Buy","price":3107.79,"timestamp":"2024-05-18T15:46:04.124Z"},{"symbol":"ETHUSDT","id":32402483898,"side":"Buy","price":3109.42,"timestamp":"2024-05-18T15:46:04.124Z"}]}
{"table":"orderBookL2_25","action":"insert","data":[{"symbol":"ETHUSDT","id":32402483957,"side":"Sell","size":49000,"price":3111.51,"timestamp":"2024-05-18T15:46:04.124Z"},{"symbol":"ETHUSDT","id":32402483959,"side":"Buy","size":47000,"price":3109.89,"timestamp":"2024-05-18T15:46:04.124Z"},{"symbol":"ETHUSDT","id":32402483934,"side":"Buy","size":1000,"price":3109.44,"timestamp":"2024-05-18T15:46:04.124Z"}]}
{"table":"orderBookL2_25","action":"delete","data":[{"symbol":"XBTUSDT","id":32402483740,"side":"Sell","price":66816.0,"timestamp":"2024-05-18T15:46:04.133Z"},{"symbol":"XBTUSDT","id":32402482414,"side":"Sell","price":66815.0,"timestamp":"2024-05-18T15:46:04.133Z"},{"symbol":"XBTUSDT","id":32402482420,"side":"Sell","price":66814.9,"timestamp":"2024-05-18T15:46:04.133Z"},{"symbol":"XBTUSDT","id":32402483687,"side":"Sell","price":66822.1,"timestamp":"2024-05-18T15:46:04.133Z"},{"symbol":"XBTUSDT","id":32402483744,"side":"Buy","price":66783.6,"timestamp":"2024-05-18T15:46:04.133Z"},{"symbol":"XBTUSDT","id":32402483680,"side":"Buy","price":66776.1,"timestamp":"2024-05-18T15:46:04.133Z"}]}
{"table":"orderBookL2_25","action":"update","data":[{"symbol":"XBTUSDT","id":32402441693,"side":"Sell","size":100000,"price":66829.0,"timestamp":"2024-05-18T15:46:04.133Z"},{"symbol":"XBTUSDT","id":32402242406,"side":"Sell","size":139000,"price":66822.2,"timestamp":"2024-05-18T15:46:04.133Z"}]}
{"table":"orderBookL2_25","action":"insert","data":[{"symbol":"XBTUSDT","id":32402483984,"side":"Sell","size":20000,"price":66816.0,"timestamp":"2024-05-18T15:46:04.133Z"},{"symbol":"XBTUSDT","id":32402483952,"side":"Sell","size":227000,"price":66814.7,"timestamp":"2024-05-18T15:46:04.133Z"},{"symbol":"XBTUSDT","id":32402483989,"side":"Sell","size":1000,"price":66822.1,"timestamp":"2024-05-18T15:46:04.133Z"},{"symbol":"XBTUSDT","id":32402483943,"side":"Sell","size":366000,"price":66814.8,"timestamp":"2024-05-18T15:46:04.133Z"},{"symbol":"XBTUSDT","id":32402483980,"side":"Buy","size":20000,"price":66783.6,"timestamp":"2024-05-18T15:46:04.133Z"},{"symbol":"XBTUSDT","id":32402363228,"side":"Buy","size":1502000,"price":66766.1,"timestamp":"2024-05-18T15:46:04.133Z"}]}
{"table":"orderBookL2_25","action":"delete","data":[{"symbol":"XBTUSDT","id":32402483984,"side":"Sell","price":66816.0,"timestamp":"2024-05-18T15:46:04.182Z"},{"symbol":"XBTUSDT","id":32402483941,"side":"Buy","price":66776.2,"timestamp":"2024-05-18T15:46:04.182Z"},{"symbol":"XBTUSDT","id":32402483980,"side":"Buy","price":66783.6,"timestamp":"2024-05-18T15:46:04.182Z"}]}
{"table":"orderBookL2_25","action":"insert","data":[{"symbol":"XBTUSDT","id":32402484024,"side":"Sell","size":20000,"price":66816.0,"timestamp":"2024-05-18T15:46:04.182Z"},{"symbol":"XBTUSDT","id":32402484039,"side":"Buy","size":380000,"price":66776.2,"timestamp":"2024-05-18T15:46:04.182Z"},{"symbol":"XBTUSDT","id":32402484034,"side":"Buy","size":20000,"price":66783.6,"timestamp":"2024-05-18T15:46:04.182Z"}]}
{"table":"orderBookL2_25","action":"delete","data":[{"symbol":"XBTUSDT","id":32402484024,"side":"Sell","price":66816.0,"timestamp":"2024-05-18T15:46:04.231Z"},{"symbol":"XBTUSDT","id":32402484039,"side":"Buy","price":66776.2,"timestamp":"2024-05-18T15:46:04.231Z"},{"symbol":"XBTUSDT","id":32402484034,"side":"Buy","price":66783.6,"timestamp":"2024-05-18T15:46:04.231Z"}]}
{"table":"orderBookL2_25","action":"insert","data":[{"symbol":"XBTUSDT","id":32402484076,"side":"Sell","size":20000,"price":66815.8,"timestamp":"2024-05-18T15:46:04.231Z"},{"symbol":"XBTUSDT","id":32402484062,"side":"Buy","size":347000,"price":66779.5,"timestamp":"2024-05-18T15:46:04.231Z"},{"symbol":"XBTUSDT","id":32402484074,"side":"Buy","size":20000,"price":66783.8,"timestamp":"2024-05-18T15:46:04.231Z"}]}
{"table":"orderBookL2_25","action":"delete","data":[{"symbol":"ETHUSDT","id":32402483931,"side":"Buy","price":3109.69,"timestamp":"2024-05-18T15:46:04.273Z"}]}
{"table":"orderBookL2_25","action":"update","data":[{"symbol":"ETHUSDT","id":32402482596,"side":"Buy","size":273000,"price":3109.67,"timestamp":"2024-05-18T15:46:04.273Z"}]}
{"table":"orderBookL2_25","action":"insert","data":[{"symbol":"ETHUSDT","id":32402460354,"side":"Buy","size":1620000,"price":3107.79,"timestamp":"2024-05-18T15:46:04.273Z"}]}
{"table":"orderBookL2_25","action":"delete","data":[{"symbol":"XBTUSDT","id":32402484076,"side":"Sell","price":66815.8,"timestamp":"2024-05-18T15:46:04.312Z"}]}
{"table":"orderBookL2_25","action":"insert","data":[{"symbol":"XBTUSDT","id":32402484121,"side":"Sell","size":20000,"price":66816.0,"timestamp":"2024-05-18T15:46:04.312Z"}]}
{"table":"orderBookL2_25","action":"delete","data":[{"symbol":"ETHUSDT","id":32402483929,"side":"Sell","price":3111.17,"timestamp":"2024-05-18T15:46:04.322Z"},{"symbol":"ETHUSDT","id":32402460354,"side":"Buy","price":3107.79,"timestamp":"2024-05-18T15:46:04.322Z"},{"symbol":"ETHUSDT","id":32402483344,"side":"Buy","price":3109.68,"timestamp":"2024-05-18T15:46:04.322Z"}]}
{"table":"orderBookL2_25","action":"update","data":[{"symbol":"ETHUSDT","id":32402482596,"side":"Buy","size":241000,"price":3109.67,"timestamp":"2024-05-18T15:46:04.322Z"}]}
{"table":"orderBookL2_25","action":"insert","data":[{"symbol":"ETHUSDT","id":32402484125,"side":"Sell","size":32000,"price":3111.17,"timestamp":"2024-05-18T15:46:04.322Z"},{"symbol":"ETHUSDT","id":32402484116,"side":"Buy","size":32000,"price":3109.69,"timestamp":"2024-05-18T15:46:04.322Z"},{"symbol":"ETHUSDT","id":32402484123,"side":"Buy","size":32000,"price":3109.68,"timestamp":"2024-05-18T15:46:04.322Z"}]}
{"table":"orderBookL2_25","action":"delete","data":[{"symbol":"XBTUSDT","id":32402484074,"side":"Buy","price":66783.8,"timestamp":"2024-05-18T15:46:04.361Z"}]}
{"table":"orderBookL2_25","action":"insert","data":[{"symbol":"XBTUSDT","id":32402484129,"side":"Buy","size":20000,"price":66783.6,"timestamp":"2024-05-18T15:46:04.361Z"}]}
{"table":"orderBookL2_25","action":"delete","data":[{"symbol":"ETHUSDT","id":32402484125,"side":"Sell","price":3111.17,"timestamp":"2024-05-18T15:46:04.371Z"},{"symbol":"ETHUSDT","id":32402484116,"side":"Buy","price":3109.69,"timestamp":"2024-05-18T15:46:04.371Z"},{"symbol":"ETHUSDT","id":32402483934,"side":"Buy","price":3109.44,"timestamp":"2024-05-18T15:46:04.371Z"}]}
{"table":"orderBookL2_25","action":"update","data":[{"symbol":"ETHUSDT","id":32402482596,"side":"Buy","size":273000,"price":3109.67,"timestamp":"2024-05-18T15:46:04.371Z"}]}
{"table":"orderBookL2_25","action":"insert","data":[{"symbol":"ETHUSDT","id":32402484163,"side":"Sell","size":32000,"price":3111.15,"timestamp":"2024-05-18T15:46:04.371Z"},{"symbol":"ETHUSDT","id":32402484142,"side":"Buy","size":1000,"price":3109.42,"timestamp":"2024-05-18T15:46:04.371Z"},{"symbol":"ETHUSDT","id":32402460354,"side":"Buy","size":1620000,"price":3107.79,"timestamp":"2024-05-18T15:46:04.371Z"}]}
{"table":"orderBookL2_25","action":"delete","data":[{"symbol":"ETHUSDT","id":32402484163,"side":"Sell","price":3111.15,"timestamp":"2024-05-18T15:46:04.420Z"},{"symbol":"ETHUSDT","id":32402460354,"side":"Buy","price":3107.79,"timestamp":"2024-05-18T15:46:04.420Z"},{"symbol":"ETHUSDT","id":32402484142,"side":"Buy","price":3109.42,"timestamp":"2024-05-18T15:46:04.420Z"}]}
{"table":"orderBookL2_25","action":"update","data":[{"symbol":"ETHUSDT","id":32402482596,"side":"Buy","size":241000,"price":3109.67,"timestamp":"2024-05-18T15:46:04.420Z"}]}
{"table":"orderBookL2_25","action":"insert","data":[{"symbol":"ETHUSDT","id":32402484193,"side":"Sell","size":32000,"price":3111.17,"timestamp":"2024-05-18T15:46:04.420Z"},{"symbol":"ETHUSDT","id":32402484190,"side":"Buy","size":1000,"price":3109.44,"timestamp":"2024-05-18T15:46:04.420Z"},{"symbol":"ETHUSDT","id":32402484195,"side":"Buy","size":32000,"price":3109.69,"timestamp":"2024-05-18T15:46:04.420Z"}]}
{"table":"orderBookL2_25","action":"delete","data":[{"symbol":"XBTUSDT","id":32402483989,"side":"Sell","price":66822.1,"timestamp":"2024-05-18T15:46:04.423Z"}]}
{"table":"orderBookL2_25","action":"insert","data":[{"symbol":"XBTUSDT","id":32402484206,"side":"Sell","size":1000,"price":66821.8,"timestamp":"2024-05-18T15:46:04.423Z"}]}
{"table":"orderBookL2_25","action":"delete","data":[{"symbol":"ETHUSDT","id":32402484193,"side":"Sell","price":3111.17,"timestamp":"2024-05-18T15:46:04.469Z"},{"symbol":"ETHUSDT","id":32402483323,"side":"Buy","price":3109.43,"timestamp":"2024-05-18T15:46:04.469Z"},{"symbol":"ETHUSDT","id":32402484123,"side":"Buy","price":3109.68,"timestamp":"2024-05-18T15:46:04.469Z"}]}
{"table":"orderBookL2_25","action":"insert","data":[{"symbol":"ETHUSDT","id":32402484229,"side":"Sell","size":32000,"price":3111.15,"timestamp":"2024-05-18T15:46:04.469Z"},{"symbol":"ETHUSDT","id":32402484250,"side":"Buy","size":32000,"price":3109.70,"timestamp":"2024-05-18T15:46:04.469Z"},{"symbol":"ETHUSDT","id":32402484208,"side":"Buy","size":1000,"price":3109.45,"timestamp":"2024-05-18T15:46:04.469Z"}]}
{"table":"orderBookL2_25","action":"delete","data":[{"symbol":"XBTUSDT","id":32402484121,"side":"Sell","price":66816.0,"timestamp":"2024-05-18T15:46:04.473Z"},{"symbol":"XBTUSDT","id":32402483136,"side":"Sell","price":66815.9,"timestamp":"2024-05-18T15:46:04.473Z"},{"symbol":"XBTUSDT","id":32402484129,"side":"Buy","price":66783.6,"timestamp":"2024-05-18T15:46:04.473Z"},{"symbol":"XBTUSDT","id":32402483141,"side":"Buy","price":66783.7,"timestamp":"2024-05-18T15:46:04.473Z"}]}
{"table":"orderBookL2_25","action":"update","data":[{"symbol":"XBTUSDT","id":32402441693,"side":"Sell","size":100000,"price":66829.0,"timestamp":"2024-05-18T15:46:04.473Z"},{"symbol":"XBTUSDT","id":32402242406,"side":"Sell","size":138000,"price":66822.2,"timestamp":"2024-05-18T15:46:04.473Z"},{"symbol":"XBTUSDT","id":32402461579,"side":"Sell","size":120000,"price":66815.7,"timestamp":"2024-05-18T15:46:04.473Z"}]}
{"table":"orderBookL2_25","action":"insert","data":[{"symbol":"XBTUSDT","id":32402484215,"side":"Sell","size":1000,"price":66821.9,"timestamp":"2024-05-18T15:46:04.473Z"},{"symbol":"XBTUSDT","id":32402484243,"side":"Sell","size":20000,"price":66815.6,"timestamp":"2024-05-18T15:46:04.473Z"},{"symbol":"XBTUSDT","id":32402484255,"side":"Buy","size":20000,"price":66783.9,"timestamp":"2024-05-18T15:46:04.473Z"},{"symbol":"XBTUSDT","id":32402484257,"side":"Buy","size":20000,"price":66784.0,"timestamp":"2024-05-18T15:46:04.473Z"}]}
{"table":"orderBookL2_25","action":"delete","data":[{"symbol":"XBTUSDT","id":32402484206,"side":"Sell","price":66821.8,"timestamp":"2024-05-18T15:46:04.586Z"}]}
{"table":"orderBookL2_25","action":"insert","data":[{"symbol":"XBTUSDT","id":32402484359,"side":"Sell","size":1000,"price":66822.0,"timestamp":"2024-05-18T15:46:04.586Z"}]}
{"table":"orderBookL2_25","action":"delete","data":[{"symbol":"ETHUSDT","id":32402484250,"side":"Buy","price":3109.70,"timestamp":"2024-05-18T15:46:04.595Z"}]}
{"table":"orderBookL2_25","action":"insert","data":[{"symbol":"ETHUSDT","id":32402484379,"side":"Buy","size":32000,"price":3109.68,"timestamp":"2024-05-18T15:46:04.595Z"}]}
{"table":"orderBookL2_25","action":"update","data":[{"symbol":"XBTETH","id":32402427691,"side":"Buy","size":8,"price":21.012,"timestamp":"2024-05-18T15:46:04.628Z"}]}
{"table":"orderBookL2_25","action":"delete","data":[{"symbol":"XBTUSDT","id":32402484243,"side":"Sell","price":66815.6,"timestamp":"2024-05-18T15:46:04.636Z"},{"symbol":"XBTUSDT","id":32402484359,"side":"Sell","price":66822.0,"timestamp":"2024-05-18T15:46:04.636Z"},{"symbol":"XBTUSDT","id":32402484257,"side":"Buy","price":66784.0,"timestamp":"2024-05-18T15:46:04.636Z"}]}
{"table":"orderBookL2_25","action":"insert","data":[{"symbol":"XBTUSDT","id":32402484418,"side":"Sell","size":1000,"price":66822.0,"timestamp":"2024-05-18T15:46:04.636Z"},{"symbol":"XBTUSDT","id":32402484386,"side":"Sell","size":20000,"price":66815.8,"timestamp":"2024-05-18T15:46:04.636Z"},{"symbol":"XBTUSDT","id":32402484395,"side":"Buy","size":20000,"price":66783.8,"timestamp":"2024-05-18T15:46:04.636Z"}]}
{"table":"orderBookL2_25","action":"delete","data":[{"symbol":"ETHUSDT","id":32402484229,"side":"Sell","price":3111.15,"timestamp":"2024-05-18T15:46:04.644Z"},{"symbol":"ETHUSDT","id":32402484195,"side":"Buy","price":3109.69,"timestamp":"2024-05-18T15:46:04.644Z"}]}
{"table":"orderBookL2_25","action":"update","data":[{"symbol":"ETHUSDT","id":32402482596,"side":"Buy","size":241000,"price":3109.67,"timestamp":"2024-05-18T15:46:04.644Z"}]}
{"table":"orderBookL2_25","action":"insert","data":[{"symbol":"ETHUSDT","id":32402484416,"side":"Sell","size":32000,"price":3111.17,"timestamp":"2024-05-18T15:46:04.644Z"},{"symbol":"ETHUSDT","id":32402484425,"side":"Buy","size":32000,"price":3109.69,"timestamp":"2024-05-18T15:46:04.644Z"}]}
{"table":"orderBookL2_25","action":"update","data":[{"symbol":"XBTETH","id":32402427688,"side":"Sell","size":8,"price":22.001,"timestamp":"2024-05-18T15:46:04.678Z"}]}
{"table":"orderBookL2_25","action":"delete","data":[{"symbol":"XBTUSDT","id":32402484418,"side":"Sell","price":66822.0,"timestamp":"2024-05-18T15:46:04.685Z"},{"symbol":"XBTUSDT","id":32402484386,"side":"Sell","price":66815.8,"timestamp":"2024-05-18T15:46:04.685Z"},{"symbol":"XBTUSDT","id":32402484395,"side":"Buy","price":66783.8,"timestamp":"2024-05-18T15:46:04.685Z"},{"symbol":"XBTUSDT","id":32402484255,"side":"Buy","price":66783.9,"timestamp":"2024-05-18T15:46:04.685Z"}]}
{"table":"orderBookL2_25","action":"update","data":[{"symbol":"XBTUSDT","id":32402461579,"side":"Sell","size":120000,"price":66815.7,"timestamp":"2024-05-18T15:46:04.685Z"},{"symbol":"XBTUSDT","id":32402479097,"side":"Sell","size":3000,"price":66815.5,"timestamp":"2024-05-18T15:46:04.685Z"}]}
{"table":"orderBookL2_25","action":"insert","data":[{"symbol":"XBTUSDT","id":32402484519,"side":"Sell","size":1000,"price":66821.8,"timestamp":"2024-05-18T15:46:04.685Z"},{"symbol":"XBTUSDT","id":32402484516,"side":"Sell","size":20000,"price":66815.8,"timestamp":"2024-05-18T15:46:04.685Z"},{"symbol":"XBTUSDT","id":32402484500,"side":"Buy","size":20000,"price":66783.9,"timestamp":"2024-05-18T15:46:04.685Z"},{"symbol":"XBTUSDT","id":32402484512,"side":"Buy","size":20000,"price":66783.8,"timestamp":"2024-05-18T15:46:04.685Z"}]}
{"table":"orderBookL2_25","action":"delete","data":[{"symbol":"ETHUSDT","id":32402482714,"side":"Sell","price":3112.67,"timestamp":"2024-05-18T15:46:04.693Z"},{"symbol":"ETHUSDT","id":32402484416,"side":"Sell","price":3111.17,"timestamp":"2024-05-18T15:46:04.693Z"},{"symbol":"ETHUSDT","id":32402484208,"side":"Buy","price":3109.45,"timestamp":"2024-05-18T15:46:04.693Z"},{"symbol":"ETHUSDT","id":32402483509,"side":"Buy","price":3108.63,"timestamp":"2024-05-18T15:46:04.693Z"},{"symbol":"ETHUSDT","id":32402484379,"side":"Buy","price":3109.68,"timestamp":"2024-05-18T15:46:04.693Z"}]}
{"table":"orderBookL2_25","action":"insert","data":[{"symbol":"ETHUSDT","id":32402484553,"side":"Sell","size":32000,"price":3111.15,"timestamp":"2024-05-18T15:46:04.693Z"},{"symbol":"ETHUSDT","id":32402484548,"side":"Sell","size":30000,"price":3111.03,"timestamp":"2024-05-18T15:46:04.693Z"},{"symbol":"ETHUSDT","id":32402484544,"side":"Buy","size":32000,"price":3109.70,"timestamp":"2024-05-18T15:46:04.693Z"},{"symbol":"ETHUSDT","id":32402484550,"side":"Buy","size":190000,"price":3108.96,"timestamp":"2024-05-18T15:46:04.693Z"},{"symbol":"ETHUSDT","id":32402484494,"side":"Buy","size":1000,"price":3109.43,"timestamp":"2024-05-18T15:46:04.693Z"}]}
{"table":"orderBookL2_25","action":"delete","data":[{"symbol":"XBTUSDT","id":32402484516,"side":"Sell","price":66815.8,"timestamp":"2024-05-18T15:46:04.734Z"},{"symbol":"XBTUSDT","id":32402484215,"side":"Sell","price":66821.9,"timestamp":"2024-05-18T15:46:04.734Z"}]}
{"table":"orderBookL2_25","action":"update","data":[{"symbol":"XBTUSDT","id":32402471671,"side":"Sell","size":75000,"price":66821.7,"timestamp":"2024-05-18T15:46:04.734Z"}]}
{"table":"orderBookL2_25","action":"insert","data":[{"symbol":"XBTUSDT","id":32402457533,"side":"Sell","size":331000,"price":66830.8,"timestamp":"2024-05-18T15:46:04.734Z"},{"symbol":"XBTUSDT","id":32402484590,"side":"Sell","size":20000,"price":66815.6,"timestamp":"2024-05-18T15:46:04.734Z"}]}
{"table":"orderBookL2_25","action":"delete","data":[{"symbol":"ETHUSDT","id":32402484553,"side":"Sell","price":3111.15,"timestamp":"2024-05-18T15:46:04.742Z"},{"symbol":"ETHUSDT","id":32402484190,"side":"Buy","price":3109.44,"timestamp":"2024-05-18T15:46:04.742Z"},{"symbol":"ETHUSDT","id":32402484544,"side":"Buy","price":3109.70,"timestamp":"2024-05-18T15:46:04.742Z"},{"symbol":"ETHUSDT","id":32402484494,"side":"Buy","price":3109.43,"timestamp":"2024-05-18T15:46:04.742Z"}]}
{"table":"orderBookL2_25","action":"insert","data":[{"symbol":"ETHUSDT","id":32402484599,"side":"Sell","size":32000,"price":3111.15,"timestamp":"2024-05-18T15:46:04.742Z"},{"symbol":"ETHUSDT","id":32402484601,"side":"Buy","size":1000,"price":3109.46,"timestamp":"2024-05-18T15:46:04.742Z"},{"symbol":"ETHUSDT","id":32402484604,"side":"Buy","size":1000,"price":3109.45,"timestamp":"2024-05-18T15:46:04.742Z"},{"symbol":"ETHUSDT","id":32402484596,"side":"Buy","size":32000,"price":3109.70,"timestamp":"2024-05-18T15:46:04.742Z"}]}
{"table":"orderBookL2_25","action":"delete","data":[{"symbol":"XBTUSDT","id":32402484512,"side":"Buy","price":66783.8,"timestamp":"2024-05-18T15:46:04.783Z"}]}
{"table":"orderBookL2_25","action":"update","data":[{"symbol":"XBTUSDT","id":32402461579,"side":"Sell","size":100000,"price":66815.7,"timestamp":"2024-05-18T15:46:04.783Z"},{"symbol":"XBTUSDT","id":32402479097,"side":"Sell","size":23000,"price":66815.5,"timestamp":"2024-05-18T15:46:04.783Z"}]}
{"table":"orderBookL2_25","action":"insert","data":[{"symbol":"XBTUSDT","id":32402484651,"side":"Buy","size":20000,"price":66783.8,"timestamp":"2024-05-18T15:46:04.783Z"}]}
{"table":"orderBookL2_25","action":"delete","data":[{"symbol":"XBTUSDT","id":32402483689,"side":"Buy","price":66779.4,"timestamp":"2024-05-18T15:46:04.832Z"}]}
{"table":"orderBookL2_25","action":"insert","data":[{"symbol":"XBTUSDT","id":32402360485,"side":"Buy","size":100000,"price":66764.4,"timestamp":"2024-05-18T15:46:04.832Z"}]}
{"table":"orderBookL2_25","action":"delete","data":[{"symbol":"ETHUSDT","id":32402484601,"side":"Buy","price":3109.46,"timestamp":"2024-05-18T15:46:04.891Z"}]}
{"table":"orderBookL2_25","action":"insert","data":[{"symbol":"ETHUSDT","id":32402484779,"side":"Buy","size":1000,"price":3109.44,"timestamp":"2024-05-18T15:46:04.891Z"}]}
{"table":"orderBookL2_25","action":"delete","data":[{"symbol":"ETHUSDT","id":32402484779,"side":"Buy","price":3109.44,"timestamp":"2024-05-18T15:46:04.941Z"}]}
{"table":"orderBookL2_25","action":"insert","data":[{"symbol":"ETHUSDT","id":32402484786,"side":"Buy","size":1000,"price":3109.46,"timestamp":"2024-05-18T15:46:04.941Z"}]}
{"table":"orderBookL2_25","action":"delete","data":[{"symbol":"XBTUSDT","id":32402483943,"side":"Sell","price":66814.8,"timestamp":"2024-05-18T15:46:04.950Z"}]}
{"table":"orderBookL2_25","action":"insert","data":[{"symbol":"XBTUSDT","id":32402484810,"side":"Sell","size":362000,"price":66814.6,"timestamp":"2024-05-18T15:46:04.950Z"}]}
{"table":"orderBookL2_25","action":"delete","data":[{"symbol":"ETHUSDT","id":32402472717,"side":"Sell","price":3111.53,"timestamp":"2024-05-18T15:46:04.990Z"},{"symbol":"ETHUSDT","id":32402472118,"side":"Sell","price":3111.56,"timestamp":"2024-05-18T15:46:04.990Z"},{"symbol":"ETHUSDT","id":32402484786,"side":"Buy","price":3109.46,"timestamp":"2024-05-18T15:46:04.990Z"},{"symbol":"ETHUSDT","id":32402480869,"side":"Buy","price":3108.29,"timestamp":"2024-05-18T15:46:04.990Z"}]}
{"table":"orderBookL2_25","action":"insert","data":[{"symbol":"ETHUSDT","id":32402482714,"side":"Sell","size":563000,"price":3112.67,"timestamp":"2024-05-18T15:46:04.990Z"},{"symbol":"ETHUSDT","id":32402484839,"side":"Sell","size":100000,"price":3111.49,"timestamp":"2024-05-18T15:46:04.990Z"},{"symbol":"ETHUSDT","id":32402460354,"side":"Buy","size":1620000,"price":3107.79,"timestamp":"2024-05-18T15:46:04.990Z"},{"symbol":"ETHUSDT","id":32402484807,"side":"Buy","size":1000,"price":3109.44,"timestamp":"2024-05-18T15:46:04.990Z"}]}
{"table":"orderBookL2_25","action":"delete","data":[{"symbol":"XBTUSDT","id":32402483952,"side":"Sell","price":66814.7,"timestamp":"2024-05-18T15:46:04.999Z"},{"symbol":"XBTUSDT","id":32402484062,"side":"Buy","price":66779.5,"timestamp":"2024-05-18T15:46:04.999Z"}]}
{"table":"orderBookL2_25","action":"update","data":[{"symbol":"XBTUSDT","id":32402441693,"side":"Sell","size":100000,"price":66829.0,"timestamp":"2024-05-18T15:46:04.999Z"},{"symbol":"XBTUSDT","id":32402462668,"side":"Sell","size":359000,"price":66801.9,"timestamp":"2024-05-18T15:46:04.999Z"},{"symbol":"XBTUSDT","id":32402457533,"side":"Sell","size":331000,"price":66830.8,"timestamp":"2024-05-18T15:46:04.999Z"}]}
{"table":"orderBookL2_25","action":"insert","data":[{"symbol":"XBTUSDT","id":32402484821,"side":"Sell","size":217000,"price":66814.5,"timestamp":"2024-05-18T15:46:04.999Z"},{"symbol":"XBTUSDT","id":32402484817,"side":"Buy","size":383000,"price":66776.1,"timestamp":"2024-05-18T15:46:04.999Z"}]}
{"table":"orderBookL2_25","action":"delete","data":[{"symbol":"ETHUSDT","id":32402484599,"side":"Sell","price":3111.15,"timestamp":"2024-05-18T15:46:05.039Z"},{"symbol":"ETHUSDT","id":32402484807,"side":"Buy","price":3109.44,"timestamp":"2024-05-18T15:46:05.039Z"},{"symbol":"ETHUSDT","id":32402484425,"side":"Buy","price":3109.69,"timestamp":"2024-05-18T15:46:05.039Z"}]}
{"table":"orderBookL2_25","action":"insert","data":[{"symbol":"ETHUSDT","id":32402484852,"side":"Sell","size":32000,"price":3111.17,"timestamp":"2024-05-18T15:46:05.039Z"},{"symbol":"ETHUSDT","id":32402484861,"side":"Buy","size":32000,"price":3109.71,"timestamp":"2024-05-18T15:46:05.039Z"},{"symbol":"ETHUSDT","id":32402484905,"side":"Buy","size":1000,"price":3109.46,"timestamp":"2024-05-18T15:46:05.039Z"}]}
{"table":"orderBookL2_25","action":"delete","data":[{"symbol":"XBTUSDT","id":32402484817,"side":"Buy","price":66776.1,"timestamp":"2024-05-18T15:46:05.048Z"},{"symbol":"XBTUSDT","id":32402110404,"side":"Buy","price":66767.4,"timestamp":"2024-05-18T15:46:05.048Z"}]}
{"table":"orderBookL2_25","action":"insert","data":[{"symbol":"XBTUSDT","id":32402484911,"side":"Buy","size":348000,"price":66780.1,"timestamp":"2024-05-18T15:46:05.048Z"},{"symbol":"XBTUSDT","id":32402484922,"side":"Buy","size":74000,"price":66765.2,"timestamp":"2024-05-18T15:46:05.048Z"}]}
{"table":"orderBookL2_25","action":"delete","data":[{"symbol":"ETHUSDT","id":32402484604,"side":"Buy","price":3109.45,"timestamp":"2024-05-18T15:46:05.088Z"}]}
{"table":"orderBookL2_25","action":"insert","data":[{"symbol":"ETHUSDT","id":32402484924,"side":"Buy","size":1000,"price":3109.47,"timestamp":"2024-05-18T15:46:05.088Z"}]}
{"table":"orderBookL2_25","action":"delete","data":[{"symbol":"XBTUSDT","id":32402484911,"side":"Buy","price":66780.1,"timestamp":"2024-05-18T15:46:05.097Z"}]}
{"table":"orderBookL2_25","action":"insert","data":[{"symbol":"XBTUSDT","id":32402484932,"side":"Buy","size":382000,"price":66776.1,"timestamp":"2024-05-18T15:46:05.097Z"}]}
{"table":"orderBookL2_25","action":"delete","data":[{"symbol":"XBTUSDT","id":32402484519,"side":"Sell","price":66821.8,"timestamp":"2024-05-18T15:46:05.146Z"},{"symbol":"XBTUSDT","id":32402457533,"side":"Sell","price":66830.8,"timestamp":"2024-05-18T15:46:05.146Z"},{"symbol":"XBTUSDT","id":32402484590,"side":"Sell","price":66815.6,"timestamp":"2024-05-18T15:46:05.146Z"},{"symbol":"XBTUSDT","id":32402484500,"side":"Buy","price":66783.9,"timestamp":"2024-05-18T15:46:05.146Z"},{"symbol":"XBTUSDT","id":32402484651,"side":"Buy","price":66783.8,"timestamp":"2024-05-18T15:46:05.146Z"}]}
{"table":"orderBookL2_25","action":"update","data":[{"symbol":"XBTUSDT","id":32402471671,"side":"Sell","size":75000,"price":66821.7,"timestamp":"2024-05-18T15:46:05.146Z"},{"symbol":"XBTUSDT","id":32402479097,"side":"Sell","size":3000,"price":66815.5,"timestamp":"2024-05-18T15:46:05.146Z"},{"symbol":"XBTUSDT","id":32402441693,"side":"Sell","size":100000,"price":66829.0,"timestamp":"2024-05-18T15:46:05.146Z"}]}
{"table":"orderBookL2_25","action":"insert","data":[{"symbol":"XBTUSDT","id":32402485019,"side":"Sell","size":20000,"price":66815.3,"timestamp":"2024-05-18T15:46:05.146Z"},{"symbol":"XBTUSDT","id":32402485017,"side":"Sell","size":20000,"price":66815.2,"timestamp":"2024-05-18T15:46:05.146Z"},{"symbol":"XBTUSDT","id":32402485024,"side":"Sell","size":1000,"price":66821.8,"timestamp":"2024-05-18T15:46:05.146Z"},{"symbol":"XBTUSDT","id":32402485022,"side":"Buy","size":20000,"price":66784.7,"timestamp":"2024-05-18T15:46:05.146Z"},{"symbol":"XBTUSDT","id":32402485014,"side":"Buy","size":20000,"price":66784.8,"timestamp":"2024-05-18T15:46:05.146Z"}]}
{"table":"orderBookL2_25","action":"delete","data":[{"symbol":"XBTUSDT","id":32402485019,"side":"Sell","price":66815.3,"timestamp":"2024-05-18T15:46:05.195Z"},{"symbol":"XBTUSDT","id":32402485017,"side":"Sell","price":66815.2,"timestamp":"2024-05-18T15:46:05.195Z"},{"symbol":"XBTUSDT","id":32402441693,"side":"Sell","price":66829.0,"timestamp":"2024-05-18T15:46:05.195Z"},{"symbol":"XBTUSDT","id":32402485022,"side":"Buy","price":66784.7,"timestamp":"2024-05-18T15:46:05.195Z"},{"symbol":"XBTUSDT","id":32402485014,"side":"Buy","price":66784.8,"timestamp":"2024-05-18T15:46:05.195Z"}]}
{"table":"orderBookL2_25","action":"update","data":[{"symbol":"XBTUSDT","id":32402479097,"side":"Sell","size":23000,"price":66815.5,"timestamp":"2024-05-18T15:46:05.195Z"}]}
{"table":"orderBookL2_25","action":"insert","data":[{"symbol":"XBTUSDT","id":32402485034,"side":"Sell","size":20000,"price":66815.6,"timestamp":"2024-05-18T15:46:05.195Z"},{"symbol":"XBTUSDT","id":32402485051,"side":"Sell","size":21000,"price":66810.0,"timestamp":"2024-05-18T15:46:05.195Z"},{"symbol":"XBTUSDT","id":32402485060,"side":"Sell","size":14000,"price":66809.9,"timestamp":"2024-05-18T15:46:05.195Z"},{"symbol":"XBTUSDT","id":32402485041,"side":"Buy","size":20000,"price":66783.8,"timestamp":"2024-05-18T15:46:05.195Z"},{"symbol":"XBTUSDT","id":32402485045,"side":"Buy","size":20000,"price":66783.9,"timestamp":"2024-05-18T15:46:05.195Z"}]}
{"table":"orderBookL2_25","action":"delete","data":[{"symbol":"ETHUSDT","id":32402482714,"side":"Sell","price":3112.67,"timestamp":"2024-05-18T15:46:05.290Z"}]}
{"table":"orderBookL2_25","action":"insert","data":[{"symbol":"ETHUSDT","id":32402485143,"side":"Sell","size":241000,"price":3111.02,"timestamp":"2024-05-18T15:46:05.290Z"}]}
{"table":"orderBookL2_25","action":"delete","data":[{"symbol":"ETHUSDT","id":32402477177,"side":"Sell","price":3111.38,"timestamp":"2024-05-18T15:46:05.339Z"},{"symbol":"ETHUSDT","id":32402471833,"side":"Sell","price":3111.39,"timestamp":"2024-05-18T15:46:05.339Z"}]}
{"table":"orderBookL2_25","action":"insert","data":[{"symbol":"ETHUSDT","id":32402482714,"side":"Sell","size":563000,"price":3112.67,"timestamp":"2024-05-18T15:46:05.339Z"},{"symbol":"ETHUSDT","id":32402447682,"side":"Sell","size":100000,"price":3112.68,"timestamp":"2024-05-18T15:46:05.339Z"}]}
{"table":"orderBookL2_25","action":"delete","data":[{"symbol":"ETHUSDT","id":32402482758,"side":"Buy","price":3109.48,"timestamp":"2024-05-18T15:46:05.420Z"}]}
{"table":"orderBookL2_25","action":"insert","data":[{"symbol":"ETHUSDT","id":32401854083,"side":"Buy","size":100000,"price":3107.72,"timestamp":"2024-05-18T15:46:05.420Z"}]}
{"table":"orderBookL2_25","action":"delete","data":[{"symbol":"XBTUSDT","id":32402485024,"side":"Sell","price":66821.8,"timestamp":"2024-05-18T15:46:05.446Z"}]}
{"table":"orderBookL2_25","action":"insert","data":[{"symbol":"XBTUSDT","id":32402485239,"side":"Sell","size":1000,"price":66821.4,"timestamp":"2024-05-18T15:46:05.446Z"}]}
{"table":"orderBookL2_25","action":"delete","data":[{"symbol":"XBTUSDT","id":32402485034,"side":"Sell","price":66815.6,"timestamp":"2024-05-18T15:46:05.496Z"},{"symbol":"XBTUSDT","id":32402458161,"side":"Sell","price":66824.3,"timestamp":"2024-05-18T15:46:05.496Z"},{"symbol":"XBTUSDT","id":32402485041,"side":"Buy","price":66783.8,"timestamp":"2024-05-18T15:46:05.496Z"},{"symbol":"XBTUSDT","id":32402485045,"side":"Buy","price":66783.9,"timestamp":"2024-05-18T15:46:05.496Z"}]}
{"table":"orderBookL2_25","action":"update","data":[{"symbol":"XBTUSDT","id":32402471671,"side":"Sell","size":74000,"price":66821.7,"timestamp":"2024-05-18T15:46:05.496Z"},{"symbol":"XBTUSDT","id":32402474116,"side":"Sell","size":102000,"price":66824.2,"timestamp":"2024-05-18T15:46:05.496Z"},{"symbol":"XBTUSDT","id":32402479097,"side":"Sell","size":23000,"price":66815.5,"timestamp":"2024-05-18T15:46:05.496Z"}]}
{"table":"orderBookL2_25","action":"insert","data":[{"symbol":"XBTUSDT","id":32402485241,"side":"Sell","size":1000,"price":66821.5,"timestamp":"2024-05-18T15:46:05.496Z"},{"symbol":"XBTUSDT","id":32402485285,"side":"Sell","size":20000,"price":66815.6,"timestamp":"2024-05-18T15:46:05.496Z"},{"symbol":"XBTUSDT","id":32402485283,"side":"Buy","size":20000,"price":66783.9,"timestamp":"2024-05-18T15:46:05.496Z"},{"symbol":"XBTUSDT","id":32402485287,"side":"Buy","size":20000,"price":66783.8,"timestamp":"2024-05-18T15:46:05.496Z"}]}
{"table":"orderBookL2_25","action":"delete","data":[{"symbol":"XBTUSDT","id":32402485241,"side":"Sell","price":66821.5,"timestamp":"2024-05-18T15:46:05.545Z"},{"symbol":"XBTUSDT","id":32402485239,"side":"Sell","price":66821.4,"timestamp":"2024-05-18T15:46:05.545Z"}]}
{"table":"orderBookL2_25","action":"update","data":[{"symbol":"XBTUSDT","id":32402471671,"side":"Sell","size":75000,"price":66821.7,"timestamp":"2024-05-18T15:46:05.545Z"}]}
{"table":"orderBookL2_25","action":"insert","data":[{"symbol":"XBTUSDT","id":32402458161,"side":"Sell","size":159000,"price":66824.3,"timestamp":"2024-05-18T15:46:05.545Z"},{"symbol":"XBTUSDT","id":32402485309,"side":"Sell","size":1000,"price":66821.8,"timestamp":"2024-05-18T15:46:05.545Z"}]}
{"table":"orderBookL2_25","action":"delete","data":[{"symbol":"ETHUSDT","id":32402483812,"side":"Sell","price":3111.04,"timestamp":"2024-05-18T15:46:05.850Z"}]}
{"table":"orderBookL2_25","action":"insert","data":[{"symbol":"ETHUSDT","id":32402470274,"side":"Sell","size":100000,"price":3112.84,"timestamp":"2024-05-18T15:46:05.850Z"}]}
{"table":"orderBookL2_25","action":"delete","data":[{"symbol":"XBTUSDT","id":32402360485,"side":"Buy","price":66764.4,"timestamp":"2024-05-18T15:46:05.869Z"}]}
{"table":"orderBookL2_25","action":"insert","data":[{"symbol":"XBTUSDT","id":32402485638,"side":"Buy","size":100000,"price":66791.6,"timestamp":"2024-05-18T15:46:05.869Z"}]}
{"table":"orderBookL2_25","action":"delete","data":[{"symbol":"ETHUSDT","id":32402477488,"side":"Sell","price":3111.33,"timestamp":"2024-05-18T15:46:05.899Z"},{"symbol":"ETHUSDT","id":32402484548,"side":"Sell","price":3111.03,"timestamp":"2024-05-18T15:46:05.899Z"},{"symbol":"ETHUSDT","id":32402483957,"side":"Sell","price":3111.51,"timestamp":"2024-05-18T15:46:05.899Z"},{"symbol":"ETHUSDT","id":32402483511,"side":"Sell","price":3111.32,"timestamp":"2024-05-18T15:46:05.899Z"},{"symbol":"ETHUSDT","id":32402460354,"side":"Buy","price":3107.79,"timestamp":"2024-05-18T15:46:05.899Z"},{"symbol":"ETHUSDT","id":32401854083,"side":"Buy","price":3107.72,"timestamp":"2024-05-18T15:46:05.899Z"}]}
{"table":"orderBookL2_25","action":"update","data":[{"symbol":"ETHUSDT","id":32402470274,"side":"Sell","size":100000,"price":3112.84,"timestamp":"2024-05-18T15:46:05.899Z"}]}
{"table":"orderBookL2_25","action":"insert","data":[{"symbol":"ETHUSDT","id":32402485576,"side":"Sell","size":66000,"price":3111.48,"timestamp":"2024-05-18T15:46:05.899Z"},{"symbol":"ETHUSDT","id":32402476053,"side":"Sell","size":292000,"price":3113.00,"timestamp":"2024-05-18T15:46:05.899Z"},{"symbol":"ETHUSDT","id":32402476065,"side":"Sell","size":120000,"price":3112.99,"timestamp":"2024-05-18T15:46:05.899Z"},{"symbol":"ETHUSDT","id":32402441505,"side":"Sell","size":100000,"price":3113.30,"timestamp":"2024-05-18T15:46:05.899Z"},{"symbol":"ETHUSDT","id":32402485619,"side":"Buy","size":100000,"price":3109.48,"timestamp":"2024-05-18T15:46:05.899Z"},{"symbol":"ETHUSDT","id":32402485570,"side":"Buy","size":120000,"price":3108.50,"timestamp":"2024-05-18T15:46:05.899Z"}]}
{"table":"orderBookL2_25","action":"delete","data":[{"symbol":"ETHUSDT","id":32402484852,"side":"Sell","price":3111.17,"timestamp":"2024-05-18T15:46:05.948Z"},{"symbol":"ETHUSDT","id":32402483014,"side":"Sell","price":3111.16,"timestamp":"2024-05-18T15:46:05.948Z"},{"symbol":"ETHUSDT","id":32402484596,"side":"Buy","price":3109.70,"timestamp":"2024-05-18T15:46:05.948Z"},{"symbol":"ETHUSDT","id":32402484905,"side":"Buy","price":3109.46,"timestamp":"2024-05-18T15:46:05.948Z"},{"symbol":"ETHUSDT","id":32402484861,"side":"Buy","price":3109.71,"timestamp":"2024-05-18T15:46:05.948Z"}]}
{"table":"orderBookL2_25","action":"update","data":[{"symbol":"ETHUSDT","id":32402485619,"side":"Buy","size":101000,"price":3109.48,"timestamp":"2024-05-18T15:46:05.948Z"}]}
{"table":"orderBookL2_25","action":"insert","data":[{"symbol":"ETHUSDT","id":32402485745,"side":"Sell","size":32000,"price":3111.18,"timestamp":"2024-05-18T15:46:05.948Z"},{"symbol":"ETHUSDT","id":32402485790,"side":"Sell","size":32000,"price":3111.19,"timestamp":"2024-05-18T15:46:05.948Z"},{"symbol":"ETHUSDT","id":32402485748,"side":"Buy","size":32000,"price":3109.72,"timestamp":"2024-05-18T15:46:05.948Z"},{"symbol":"ETHUSDT","id":32402460354,"side":"Buy","size":1620000,"price":3107.79,"timestamp":"2024-05-18T15:46:05.948Z"},{"symbol":"ETHUSDT","id":32402485774,"side":"Buy","size":32000,"price":3109.73,"timestamp":"2024-05-18T15:46:05.948Z"}]}
{"table":"orderBookL2_25","action":"update","data":[{"symbol":"XBTUSDT","id":32402461579,"side":"Sell","size":120000,"price":66815.7,"timestamp":"2024-05-18T15:46:05.956Z"},{"symbol":"XBTUSDT","id":32402479097,"side":"Sell","size":3000,"price":66815.5,"timestamp":"2024-05-18T15:46:05.956Z"}]}
{"table":"orderBookL2_25","action":"delete","data":[{"symbol":"ETHUSDT","id":32402482912,"side":"Sell","price":3110.72,"timestamp":"2024-05-18T15:46:05.997Z"},{"symbol":"ETHUSDT","id":32402485745,"side":"Sell","price":3111.18,"timestamp":"2024-05-18T15:46:05.997Z"},{"symbol":"ETHUSDT","id":32402485143,"side":"Sell","price":3111.02,"timestamp":"2024-05-18T15:46:05.997Z"},{"symbol":"ETHUSDT","id":32402485790,"side":"Sell","price":3111.19,"timestamp":"2024-05-18T15:46:05.997Z"},{"symbol":"ETHUSDT","id":32402482929,"side":"Sell","price":3110.71,"timestamp":"2024-05-18T15:46:05.997Z"},{"symbol":"ETHUSDT","id":32402480864,"side":"Sell","price":3110.13,"timestamp":"2024-05-18T15:46:05.997Z"},{"symbol":"ETHUSDT","id":32402460354,"side":"Buy","price":3107.79,"timestamp":"2024-05-18T15:46:05.997Z"},{"symbol":"ETHUSDT","id":32402484924,"side":"Buy","price":3109.47,"timestamp":"2024-05-18T15:46:05.997Z"},{"symbol":"ETHUSDT","id":32402485748,"side":"Buy","price":3109.72,"timestamp":"2024-05-18T15:46:05.997Z"}]}
{"table":"orderBookL2_25","action":"update","data":[{"symbol":"ETHUSDT","id":32402485619,"side":"Buy","size":100000,"price":3109.48,"timestamp":"2024-05-18T15:46:05.997Z"}]}
{"table":"orderBookL2_25","action":"insert","data":[{"symbol":"ETHUSDT","id":32402485856,"side":"Sell","size":19000,"price":3111.20,"timestamp":"2024-05-18T15:46:05.997Z"},{"symbol":"ETHUSDT","id":32402485831,"side":"Sell","size":32000,"price":3111.21,"timestamp":"2024-05-18T15:46:05.997Z"},{"symbol":"ETHUSDT","id":32402438304,"side":"Sell","size":337000,"price":3113.42,"timestamp":"2024-05-18T15:46:05.997Z"},{"symbol":"ETHUSDT","id":32402485837,"side":"Sell","size":346000,"price":3112.66,"timestamp":"2024-05-18T15:46:05.997Z"},{"symbol":"ETHUSDT","id":32402485810,"side":"Sell","size":43000,"price":3111.07,"timestamp":"2024-05-18T15:46:05.997Z"},{"symbol":"ETHUSDT","id":32402485823,"side":"Sell","size":32000,"price":3111.22,"timestamp":"2024-05-18T15:46:05.997Z"},{"symbol":"ETHUSDT","id":32402485806,"side":"Buy","size":32000,"price":3109.74,"timestamp":"2024-05-18T15:46:05.997Z"},{"symbol":"ETHUSDT","id":32402485798,"side":"Buy","size":1000,"price":3109.49,"timestamp":"2024-05-18T15:46:05.997Z"},{"symbol":"ETHUSDT","id":32402485897,"side":"Buy","size":1000,"price":3109.50,"timestamp":"2024-05-18T15:46:05.997Z"}]}
{"table":"orderBookL2_25","action":"delete","data":[{"symbol":"XBTUSDT","id":32402458161,"side":"Sell","price":66824.3,"timestamp":"2024-05-18T15:46:06.006Z"},{"symbol":"XBTUSDT","id":32402485285,"side":"Sell","price":66815.6,"timestamp":"2024-05-18T15:46:06.006Z"},{"symbol":"XBTUSDT","id":32402474116,"side":"Sell","price":66824.2,"timestamp":"2024-05-18T15:46:06.006Z"},{"symbol":"XBTUSDT","id":32402485309,"side":"Sell","price":66821.8,"timestamp":"2024-05-18T15:46:06.006Z"},{"symbol":"XBTUSDT","id":32402485283,"side":"Buy","price":66783.9,"timestamp":"2024-05-18T15:46:06.006Z"},{"symbol":"XBTUSDT","id":32402485287,"side":"Buy","price":66783.8,"timestamp":"2024-05-18T15:46:06.006Z"}]}
{"table":"orderBookL2_25","action":"update","data":[{"symbol":"XBTUSDT","id":32402476497,"side":"Sell","size":50000,"price":66821.6,"timestamp":"2024-05-18T15:46:06.006Z"},{"symbol":"XBTUSDT","id":32402471671,"side":"Sell","size":74000,"price":66821.7,"timestamp":"2024-05-18T15:46:06.006Z"},{"symbol":"XBTUSDT","id":32402461579,"side":"Sell","size":100000,"price":66815.7,"timestamp":"2024-05-18T15:46:06.006Z"},{"symbol":"XBTUSDT","id":32402481228,"side":"Sell","size":155000,"price":66807.9,"timestamp":"2024-05-18T15:46:06.006Z"}]}
{"table":"orderBookL2_25","action":"insert","data":[{"symbol":"XBTUSDT","id":32402485880,"side":"Sell","size":1000,"price":66821.8,"timestamp":"2024-05-18T15:46:06.006Z"},{"symbol":"XBTUSDT","id":32402485878,"side":"Sell","size":20000,"price":66815.4,"timestamp":"2024-05-18T15:46:06.006Z"},{"symbol":"XBTUSDT","id":32402485888,"side":"Sell","size":20000,"price":66815.3,"timestamp":"2024-05-18T15:46:06.006Z"},{"symbol":"XBTUSDT","id":32402485884,"side":"Sell","size":1000,"price":66821.9,"timestamp":"2024-05-18T15:46:06.006Z"},{"symbol":"XBTUSDT","id":32402485949,"side":"Buy","size":20000,"price":66783.9,"timestamp":"2024-05-18T15:46:06.006Z"},{"symbol":"XBTUSDT","id":32402485886,"side":"Buy","size":20000,"price":66784.9,"timestamp":"2024-05-18T15:46:06.006Z"}]}
{"table":"orderBookL2_25","action":"delete","data":[{"symbol":"ETHUSDT","id":32402476065,"side":"Sell","price":3112.99,"timestamp":"2024-05-18T15:46:06.046Z"},{"symbol":"ETHUSDT","id":32402476053,"side":"Sell","price":3113.00,"timestamp":"2024-05-18T15:46:06.046Z"},{"symbol":"ETHUSDT","id":32402438304,"side":"Sell","price":3113.42,"timestamp":"2024-05-18T15:46:06.046Z"},{"symbol":"ETHUSDT","id":32402441505,"side":"Sell","price":3113.30,"timestamp":"2024-05-18T15:46:06.046Z"},{"symbol":"ETHUSDT","id":32402470274,"side":"Sell","price":3112.84,"timestamp":"2024-05-18T15:46:06.046Z"}]}
{"table":"orderBookL2_25","action":"update","data":[{"symbol":"ETHUSDT","id":32402476904,"side":"Sell","size":561000,"price":3110.79,"timestamp":"2024-05-18T15:46:06.046Z"}]}
{"table":"orderBookL2_25","action":"insert","data":[{"symbol":"ETHUSDT","id":32402485981,"side":"Sell","size":29000,"price":3111.15,"timestamp":"2024-05-18T15:46:06.046Z"},{"symbol":"ETHUSDT","id":32402486025,"side":"Sell","size":337000,"price":3111.72,"timestamp":"2024-05-18T15:46:06.046Z"},{"symbol":"ETHUSDT","id":32402485988,"side":"Sell","size":18000,"price":3111.14,"timestamp":"2024-05-18T15:46:06.046Z"},{"symbol":"ETHUSDT","id":32402486013,"side":"Sell","size":100000,"price":3110.64,"timestamp":"2024-05-18T15:46:06.046Z"},{"symbol":"ETHUSDT","id":32402486019,"side":"Sell","size":62000,"price":3110.63,"timestamp":"2024-05-18T15:46:06.046Z"}]}
{"table":"orderBookL2_25","action":"delete","data":[{"symbol":"XBTUSDT","id":32402485878,"side":"Sell","price":66815.4,"timestamp":"2024-05-18T15:46:06.055Z"},{"symbol":"XBTUSDT","id":32402485888,"side":"Sell","price":66815.3,"timestamp":"2024-05-18T15:46:06.055Z"},{"symbol":"XBTUSDT","id":32402485884,"side":"Sell","price":66821.9,"timestamp":"2024-05-18T15:46:06.055Z"},{"symbol":"XBTUSDT","id":32402485886,"side":"Buy","price":66784.9,"timestamp":"2024-05-18T15:46:06.055Z"}]}
{"table":"orderBookL2_25","action":"update","data":[{"symbol":"XBTUSDT","id":32402471671,"side":"Sell","size":75000,"price":66821.7,"timestamp":"2024-05-18T15:46:06.055Z"},{"symbol":"XBTUSDT","id":32402462668,"side":"Sell","size":319000,"price":66801.9,"timestamp":"2024-05-18T15:46:06.055Z"},{"symbol":"XBTUSDT","id":32402479097,"side":"Sell","size":23000,"price":66815.5,"timestamp":"2024-05-18T15:46:06.055Z"}]}
{"table":"orderBookL2_25","action":"insert","data":[{"symbol":"XBTUSDT","id":32402458161,"side":"Sell","size":159000,"price":66824.3,"timestamp":"2024-05-18T15:46:06.055Z"},{"symbol":"XBTUSDT","id":32402474116,"side":"Sell","size":102000,"price":66824.2,"timestamp":"2024-05-18T15:46:06.055Z"},{"symbol":"XBTUSDT","id":32402485959,"side":"Sell","size":20000,"price":66815.6,"timestamp":"2024-05-18T15:46:06.055Z"},{"symbol":"XBTUSDT","id":32402485962,"side":"Buy","size":20000,"price":66783.8,"timestamp":"2024-05-18T15:46:06.055Z"}]}
{"table":"orderBookL2_25","action":"delete","data":[{"symbol":"ETHUSDT","id":32402485981,"side":"Sell","price":3111.15,"timestamp":"2024-05-18T15:46:06.095Z"},{"symbol":"ETHUSDT","id":32402447682,"side":"Sell","price":3112.68,"timestamp":"2024-05-18T15:46:06.095Z"},{"symbol":"ETHUSDT","id":32402482714,"side":"Sell","price":3112.67,"timestamp":"2024-05-18T15:46:06.095Z"},{"symbol":"ETHUSDT","id":32402485856,"side":"Sell","price":3111.20,"timestamp":"2024-05-18T15:46:06.095Z"},{"symbol":"ETHUSDT","id":32402485988,"side":"Sell","price":3111.14,"timestamp":"2024-05-18T15:46:06.095Z"},{"symbol":"ETHUSDT","id":32402485837,"side":"Sell","price":3112.66,"timestamp":"2024-05-18T15:46:06.095Z"}]}
{"table":"orderBookL2_25","action":"update","data":[{"symbol":"ETHUSDT","id":32402476904,"side":"Sell","size":552000,"price":3110.79,"timestamp":"2024-05-18T15:46:06.095Z"},{"symbol":"ETHUSDT","id":32402486019,"side":"Sell","size":11000,"price":3110.63,"timestamp":"2024-05-18T15:46:06.095Z"}]}
{"table":"orderBookL2_25","action":"insert","data":[{"symbol":"ETHUSDT","id":32402486089,"side":"Sell","size":29000,"price":3111.06,"timestamp":"2024-05-18T15:46:06.095Z"},{"symbol":"ETHUSDT","id":32402486097,"side":"Sell","size":100000,"price":3110.52,"timestamp":"2024-05-18T15:46:06.095Z"},{"symbol":"ETHUSDT","id":32402486121,"side":"Sell","size":65000,"price":3111.30,"timestamp":"2024-05-18T15:46:06.095Z"},{"symbol":"ETHUSDT","id":32402486083,"side":"Sell","size":29000,"price":3110.98,"timestamp":"2024-05-18T15:46:06.095Z"},{"symbol":"ETHUSDT","id":32402486106,"side":"Sell","size":64000,"price":3110.51,"timestamp":"2024-05-18T15:46:06.095Z"},{"symbol":"ETHUSDT","id":32402486117,"side":"Sell","size":100000,"price":3111.31,"timestamp":"2024-05-18T15:46:06.095Z"}]}
{"table":"orderBookL2_25","action":"delete","data":[{"symbol":"XBTUSDT","id":32402484810,"side":"Sell","price":66814.6,"timestamp":"2024-05-18T15:46:06.104Z"}]}
{"table":"orderBookL2_25","action":"insert","data":[{"symbol":"XBTUSDT","id":32402486132,"side":"Sell","size":348000,"price":66812.2,"timestamp":"2024-05-18T15:46:06.104Z"}]}
{"table":"orderBookL2_25","action":"delete","data":[{"symbol":"ETHUSDT","id":32402486019,"side":"Sell","price":3110.63,"timestamp":"2024-05-18T15:46:06.144Z"},{"symbol":"ETHUSDT","id":32402486013,"side":"Sell","price":3110.64,"timestamp":"2024-05-18T15:46:06.144Z"}]}
{"table":"orderBookL2_25","action":"update","data":[{"symbol":"ETHUSDT","id":32402449038,"side":"Sell","size":100000,"price":3112.43,"timestamp":"2024-05-18T15:46:06.144Z"},{"symbol":"ETHUSDT","id":32402486106,"side":"Sell","size":73000,"price":3110.51,"timestamp":"2024-05-18T15:46:06.144Z"}]}
{"table":"orderBookL2_25","action":"insert","data":[{"symbol":"ETHUSDT","id":32402486162,"side":"Sell","size":29000,"price":3110.82,"timestamp":"2024-05-18T15:46:06.144Z"},{"symbol":"ETHUSDT","id":32402486135,"side":"Sell","size":100000,"price":3110.46,"timestamp":"2024-05-18T15:46:06.144Z"}]}
{"table":"orderBookL2_25","action":"delete","data":[{"symbol":"XBTUSDT","id":32402486132,"side":"Sell","price":66812.2,"timestamp":"2024-05-18T15:46:06.153Z"},{"symbol":"XBTUSDT","id":32402484821,"side":"Sell","price":66814.5,"timestamp":"2024-05-18T15:46:06.153Z"},{"symbol":"XBTUSDT","id":32402458161,"side":"Sell","price":66824.3,"timestamp":"2024-05-18T15:46:06.153Z"}]}
{"table":"orderBookL2_25","action":"insert","data":[{"symbol":"XBTUSDT","id":32402486148,"side":"Sell","size":65000,"price":66815.4,"timestamp":"2024-05-18T15:46:06.153Z"},{"symbol":"XBTUSDT","id":32402486143,"side":"Sell","size":213000,"price":66812.1,"timestamp":"2024-05-18T15:46:06.153Z"},{"symbol":"XBTUSDT","id":32402486215,"side":"Sell","size":366000,"price":66814.4,"timestamp":"2024-05-18T15:46:06.153Z"}]}
{"table":"orderBookL2_25","action":"delete","data":[{"symbol":"ETHUSDT","id":32402486083,"side":"Sell","price":3110.98,"timestamp":"2024-05-18T15:46:06.193Z"}]}
{"table":"orderBookL2_25","action":"update","data":[{"symbol":"ETHUSDT","id":32402486135,"side":"Sell","size":109000,"price":3110.46,"timestamp":"2024-05-18T15:46:06.193Z"},{"symbol":"ETHUSDT","id":32402486106,"side":"Sell","size":64000,"price":3110.51,"timestamp":"2024-05-18T15:46:06.193Z"}]}
{"table":"orderBookL2_25","action":"insert","data":[{"symbol":"ETHUSDT","id":32402485837,"side":"Sell","size":346000,"price":3112.66,"timestamp":"2024-05-18T15:46:06.193Z"}]}
{"table":"orderBookL2_25","action":"delete","data":[{"symbol":"XBTUSDT","id":32402486148,"side":"Sell","price":66815.4,"timestamp":"2024-05-18T15:46:06.202Z"},{"symbol":"XBTUSDT","id":32402486143,"side":"Sell","price":66812.1,"timestamp":"2024-05-18T15:46:06.202Z"}]}
{"table":"orderBookL2_25","action":"insert","data":[{"symbol":"XBTUSDT","id":32402486222,"side":"Sell","size":227000,"price":66814.3,"timestamp":"2024-05-18T15:46:06.202Z"},{"symbol":"XBTUSDT","id":32402458161,"side":"Sell","size":159000,"price":66824.3,"timestamp":"2024-05-18T15:46:06.202Z"}]}
{"table":"orderBookL2_25","action":"update","data":[{"symbol":"XBTETH","id":32402419404,"side":"Sell","size":8,"price":22.087,"timestamp":"2024-05-18T15:46:06.213Z"}]}
{"table":"orderBookL2_25","action":"delete","data":[{"symbol":"ETHUSDT","id":32402485831,"side":"Sell","price":3111.21,"timestamp":"2024-05-18T15:46:06.242Z"},{"symbol":"ETHUSDT","id":32402485774,"side":"Buy","price":3109.73,"timestamp":"2024-05-18T15:46:06.242Z"}]}
{"table":"orderBookL2_25","action":"insert","data":[{"symbol":"ETHUSDT","id":32402486339,"side":"Sell","size":32000,"price":3111.21,"timestamp":"2024-05-18T15:46:06.242Z"},{"symbol":"ETHUSDT","id":32402486314,"side":"Buy","size":32000,"price":3109.75,"timestamp":"2024-05-18T15:46:06.242Z"}]}
{"table":"orderBookL2_25","action":"update","data":[{"symbol":"XBTETH","id":32402419432,"side":"Buy","size":8,"price":20.926,"timestamp":"2024-05-18T15:46:06.263Z"}]}
{"table":"orderBookL2_25","action":"delete","data":[{"symbol":"ETHUSDT","id":32402485837,"side":"Sell","price":3112.66,"timestamp":"2024-05-18T15:46:06.291Z"},{"symbol":"ETHUSDT","id":32402485619,"side":"Buy","price":3109.48,"timestamp":"2024-05-18T15:46:06.291Z"},{"symbol":"ETHUSDT","id":32402486314,"side":"Buy","price":3109.75,"timestamp":"2024-05-18T15:46:06.291Z"}]}
{"table":"orderBookL2_25","action":"insert","data":[{"symbol":"ETHUSDT","id":32402486393,"side":"Sell","size":2000,"price":3110.30,"timestamp":"2024-05-18T15:46:06.291Z"},{"symbol":"ETHUSDT","id":32402460354,"side":"Buy","size":1620000,"price":3107.79,"timestamp":"2024-05-18T15:46:06.291Z"},{"symbol":"ETHUSDT","id":32402486342,"side":"Buy","size":32000,"price":3109.73,"timestamp":"2024-05-18T15:46:06.291Z"}]}
{"table":"orderBookL2_25","action":"delete","data":[{"symbol":"XBTUSDT","id":32402484922,"side":"Buy","price":66765.2,"timestamp":"2024-05-18T15:46:06.294Z"}]}
{"table":"orderBookL2_25","action":"insert","data":[{"symbol":"XBTUSDT","id":32402486415,"side":"Buy","size":11000,"price":66798.0,"timestamp":"2024-05-18T15:46:06.294Z"}]}
{"table":"orderBookL2_25","action":"delete","data":[{"symbol":"ETHUSDT","id":32402486089,"side":"Sell","price":3111.06,"timestamp":"2024-05-18T15:46:06.340Z"},{"symbol":"ETHUSDT","id":32402486162,"side":"Sell","price":3110.82,"timestamp":"2024-05-18T15:46:06.340Z"}]}
{"table":"orderBookL2_25","action":"update","data":[{"symbol":"ETHUSDT","id":32402449038,"side":"Sell","size":100000,"price":3112.43,"timestamp":"2024-05-18T15:46:06.340Z"},{"symbol":"ETHUSDT","id":32402486135,"side":"Sell","size":100000,"price":3110.46,"timestamp":"2024-05-18T15:46:06.340Z"},{"symbol":"ETHUSDT","id":32402486393,"side":"Sell","size":11000,"price":3110.30,"timestamp":"2024-05-18T15:46:06.340Z"}]}
{"table":"orderBookL2_25","action":"insert","data":[{"symbol":"ETHUSDT","id":32402486447,"side":"Sell","size":29000,"price":3110.65,"timestamp":"2024-05-18T15:46:06.340Z"},{"symbol":"ETHUSDT","id":32402485837,"side":"Sell","size":346000,"price":3112.66,"timestamp":"2024-05-18T15:46:06.340Z"}]}
{"table":"orderBookL2_25","action":"delete","data":[{"symbol":"XBTUSDT","id":32402485880,"side":"Sell","price":66821.8,"timestamp":"2024-05-18T15:46:06.344Z"}]}
{"table":"orderBookL2_25","action":"update","data":[{"symbol":"XBTUSDT","id":32402471671,"side":"Sell","size":74000,"price":66821.7,"timestamp":"2024-05-18T15:46:06.344Z"},{"symbol":"XBTUSDT","id":32402481228,"side":"Sell","size":157000,"price":66807.9,"timestamp":"2024-05-18T15:46:06.344Z"},{"symbol":"XBTUSDT","id":32402476497,"side":"Sell","size":51000,"price":66821.6,"timestamp":"2024-05-18T15:46:06.344Z"}]}
{"table":"orderBookL2_25","action":"insert","data":[{"symbol":"XBTUSDT","id":32402486466,"side":"Sell","size":1000,"price":66821.5,"timestamp":"2024-05-18T15:46:06.344Z"}]}
{"table":"orderBookL2_25","action":"delete","data":[{"symbol":"ETHUSDT","id":32402485806,"side":"Buy","price":3109.74,"timestamp":"2024-05-18T15:46:06.389Z"},{"symbol":"ETHUSDT","id":32402486342,"side":"Buy","price":3109.73,"timestamp":"2024-05-18T15:46:06.389Z"}]}
{"table":"orderBookL2_25","action":"insert","data":[{"symbol":"ETHUSDT","id":32402486505,"side":"Buy","size":32000,"price":3109.76,"timestamp":"2024-05-18T15:46:06.389Z"},{"symbol":"ETHUSDT","id":32402486498,"side":"Buy","size":32000,"price":3109.75,"timestamp":"2024-05-18T15:46:06.389Z"}]}
{"table":"orderBookL2_25","action":"delete","data":[{"symbol":"XBTUSDT","id":32402485962,"side":"Buy","price":66783.8,"timestamp":"2024-05-18T15:46:06.394Z"}]}
{"table":"orderBookL2_25","action":"update","data":[{"symbol":"XBTUSDT","id":32402461579,"side":"Sell","size":100000,"price":66815.7,"timestamp":"2024-05-18T15:46:06.394Z"},{"symbol":"XBTUSDT","id":32402479097,"side":"Sell","size":23000,"price":66815.5,"timestamp":"2024-05-18T15:46:06.394Z"}]}
{"table":"orderBookL2_25","action":"insert","data":[{"symbol":"XBTUSDT","id":32402486490,"side":"Buy","size":20000,"price":66784.0,"timestamp":"2024-05-18T15:46:06.394Z"}]}
{"table":"orderBookL2_25","action":"delete","data":[{"symbol":"XBTUSDT","id":32402485959,"side":"Sell","price":66815.6,"timestamp":"2024-05-18T15:46:06.443Z"}]}
{"table":"orderBookL2_25","action":"insert","data":[{"symbol":"XBTUSDT","id":32402486521,"side":"Sell","size":20000,"price":66815.4,"timestamp":"2024-05-18T15:46:06.443Z"}]}
{"table":"orderBookL2_25","action":"delete","data":[{"symbol":"XBTUSDT","id":32402486215,"side":"Sell","price":66814.4,"timestamp":"2024-05-18T15:46:06.540Z"}]}
{"table":"orderBookL2_25","action":"insert","data":[{"symbol":"XBTUSDT","id":32402486675,"side":"Sell","size":361000,"price":66812.2,"timestamp":"2024-05-18T15:46:06.540Z"}]}
{"table":"orderBookL2_25","action":"delete","data":[{"symbol":"ETHUSDT","id":32402486339,"side":"Sell","price":3111.21,"timestamp":"2024-05-18T15:46:06.540Z"}]}
{"table":"orderBookL2_25","action":"insert","data":[{"symbol":"ETHUSDT","id":32402486679,"side":"Sell","size":32000,"price":3111.23,"timestamp":"2024-05-18T15:46:06.540Z"}]}
{"table":"orderBookL2_25","action":"delete","data":[{"symbol":"XBTUSDT","id":32402458161,"side":"Sell","price":66824.3,"timestamp":"2024-05-18T15:46:06.589Z"},{"symbol":"XBTUSDT","id":32402486222,"side":"Sell","price":66814.3,"timestamp":"2024-05-18T15:46:06.589Z"}]}
{"table":"orderBookL2_25","action":"update","data":[{"symbol":"XBTUSDT","id":32402486675,"side":"Sell","size":361000,"price":66812.2,"timestamp":"2024-05-18T15:46:06.589Z"}]}
{"table":"orderBookL2_25","action":"insert","data":[{"symbol":"XBTUSDT","id":32402486694,"side":"Sell","size":61000,"price":66815.3,"timestamp":"2024-05-18T15:46:06.589Z"},{"symbol":"XBTUSDT","id":32402486691,"side":"Sell","size":217000,"price":66812.1,"timestamp":"2024-05-18T15:46:06.589Z"}]}
{"table":"orderBookL2_25","action":"delete","data":[{"symbol":"ETHUSDT","id":32402486505,"side":"Buy","price":3109.76,"timestamp":"2024-05-18T15:46:06.590Z"}]}
{"table":"orderBookL2_25","action":"insert","data":[{"symbol":"ETHUSDT","id":32402486685,"side":"Buy","size":32000,"price":3109.74,"timestamp":"2024-05-18T15:46:06.590Z"}]}
{"table":"orderBookL2_25","action":"delete","data":[{"symbol":"XBTUSDT","id":32402485638,"side":"Buy","price":66791.6,"timestamp":"2024-05-18T15:46:06.638Z"}]}
{"table":"orderBookL2_25","action":"insert","data":[{"symbol":"XBTUSDT","id":32402484922,"side":"Buy","size":74000,"price":66765.2,"timestamp":"2024-05-18T15:46:06.638Z"}]}
{"table":"orderBookL2_25","action":"delete","data":[{"symbol":"ETHUSDT","id":32402486679,"side":"Sell","price":3111.23,"timestamp":"2024-05-18T15:46:06.639Z"},{"symbol":"ETHUSDT","id":32402485837,"side":"Sell","price":3112.66,"timestamp":"2024-05-18T15:46:06.639Z"},{"symbol":"ETHUSDT","id":32402485823,"side":"Sell","price":3111.22,"timestamp":"2024-05-18T15:46:06.639Z"}]}
{"table":"orderBookL2_25","action":"insert","data":[{"symbol":"ETHUSDT","id":32402486765,"side":"Sell","size":32000,"price":3111.20,"timestamp":"2024-05-18T15:46:06.639Z"},{"symbol":"ETHUSDT","id":32402486772,"side":"Sell","size":32000,"price":3111.21,"timestamp":"2024-05-18T15:46:06.639Z"},{"symbol":"ETHUSDT","id":32402486852,"side":"Sell","size":2000,"price":3110.14,"timestamp":"2024-05-18T15:46:06.639Z"}]}
{"table":"orderBookL2_25","action":"delete","data":[{"symbol":"XBTUSDT","id":32402486466,"side":"Sell","price":66821.5,"timestamp":"2024-05-18T15:46:06.687Z"},{"symbol":"XBTUSDT","id":32402474116,"side":"Sell","price":66824.2,"timestamp":"2024-05-18T15:46:06.687Z"}]}
{"table":"orderBookL2_25","action":"update","data":[{"symbol":"XBTUSDT","id":32402476497,"side":"Sell","size":50000,"price":66821.6,"timestamp":"2024-05-18T15:46:06.687Z"}]}
{"table":"orderBookL2_25","action":"insert","data":[{"symbol":"XBTUSDT","id":32402486898,"side":"Sell","size":1000,"price":66821.3,"timestamp":"2024-05-18T15:46:06.687Z"},{"symbol":"XBTUSDT","id":32402486906,"side":"Sell","size":1000,"price":66821.2,"timestamp":"2024-05-18T15:46:06.687Z"}]}
{"table":"orderBookL2_25","action":"delete","data":[{"symbol":"ETHUSDT","id":32402486772,"side":"Sell","price":3111.21,"timestamp":"2024-05-18T15:46:06.688Z"},{"symbol":"ETHUSDT","id":32402486393,"side":"Sell","price":3110.30,"timestamp":"2024-05-18T15:46:06.688Z"},{"symbol":"ETHUSDT","id":32402486447,"side":"Sell","price":3110.65,"timestamp":"2024-05-18T15:46:06.688Z"},{"symbol":"ETHUSDT","id":32402486852,"side":"Sell","price":3110.14,"timestamp":"2024-05-18T15:46:06.688Z"},{"symbol":"ETHUSDT","id":32402486498,"side":"Buy","price":3109.75,"timestamp":"2024-05-18T15:46:06.688Z"},{"symbol":"ETHUSDT","id":32402485897,"side":"Buy","price":3109.50,"timestamp":"2024-05-18T15:46:06.688Z"}]}
{"table":"orderBookL2_25","action":"insert","data":[{"symbol":"ETHUSDT","id":32402485837,"side":"Sell","size":346000,"price":3112.66,"timestamp":"2024-05-18T15:46:06.688Z"},{"symbol":"ETHUSDT","id":32402482714,"side":"Sell","size":563000,"price":3112.67,"timestamp":"2024-05-18T15:46:06.688Z"},{"symbol":"ETHUSDT","id":32402486896,"side":"Sell","size":57000,"price":3111.19,"timestamp":"2024-05-18T15:46:06.688Z"},{"symbol":"ETHUSDT","id":32402447682,"side":"Sell","size":100000,"price":3112.68,"timestamp":"2024-05-18T15:46:06.688Z"},{"symbol":"ETHUSDT","id":32402486888,"side":"Buy","size":1000,"price":3109.48,"timestamp":"2024-05-18T15:46:06.688Z"},{"symbol":"ETHUSDT","id":32402486900,"side":"Buy","size":32000,"price":3109.73,"timestamp":"2024-05-18T15:46:06.688Z"}]}
{"table":"orderBookL2_25","action":"delete","data":[{"symbol":"XBTUSDT","id":32402486521,"side":"Sell","price":66815.4,"timestamp":"2024-05-18T15:46:06.736Z"},{"symbol":"XBTUSDT","id":32402486898,"side":"Sell","price":66821.3,"timestamp":"2024-05-18T15:46:06.736Z"},{"symbol":"XBTUSDT","id":32402486906,"side":"Sell","price":66821.2,"timestamp":"2024-05-18T15:46:06.736Z"},{"symbol":"XBTUSDT","id":32402486490,"side":"Buy","price":66784.0,"timestamp":"2024-05-18T15:46:06.736Z"},{"symbol":"XBTUSDT","id":32402485949,"side":"Buy","price":66783.9,"timestamp":"2024-05-18T15:46:06.736Z"}]}
{"table":"orderBookL2_25","action":"update","data":[{"symbol":"XBTUSDT","id":32402479097,"side":"Sell","size":23000,"price":66815.5,"timestamp":"2024-05-18T15:46:06.736Z"},{"symbol":"XBTUSDT","id":32402476497,"side":"Sell","size":51000,"price":66821.6,"timestamp":"2024-05-18T15:46:06.736Z"},{"symbol":"XBTUSDT","id":32402471671,"side":"Sell","size":75000,"price":66821.7,"timestamp":"2024-05-18T15:46:06.736Z"},{"symbol":"XBTUSDT","id":32402455289,"side":"Sell","size":22000,"price":66822.3,"timestamp":"2024-05-18T15:46:06.736Z"}]}
{"table":"orderBookL2_25","action":"insert","data":[{"symbol":"XBTUSDT","id":32402486945,"side":"Sell","size":20000,"price":66815.4,"timestamp":"2024-05-18T15:46:06.736Z"},{"symbol":"XBTUSDT","id":32402474116,"side":"Sell","size":102000,"price":66824.2,"timestamp":"2024-05-18T15:46:06.736Z"},{"symbol":"XBTUSDT","id":32402458161,"side":"Sell","size":159000,"price":66824.3,"timestamp":"2024-05-18T15:46:06.736Z"},{"symbol":"XBTUSDT","id":32402486975,"side":"Buy","size":20000,"price":66783.9,"timestamp":"2024-05-18T15:46:06.736Z"},{"symbol":"XBTUSDT","id":32402486949,"side":"Buy","size":20000,"price":66784.0,"timestamp":"2024-05-18T15:46:06.736Z"}]}
{"table":"orderBookL2_25","action":"delete","data":[{"symbol":"ETHUSDT","id":32402482714,"side":"Sell","price":3112.67,"timestamp":"2024-05-18T15:46:06.737Z"},{"symbol":"ETHUSDT","id":32402447682,"side":"Sell","price":3112.68,"timestamp":"2024-05-18T15:46:06.737Z"},{"symbol":"ETHUSDT","id":32402486685,"side":"Buy","price":3109.74,"timestamp":"2024-05-18T15:46:06.737Z"}]}
{"table":"orderBookL2_25","action":"update","data":[{"symbol":"ETHUSDT","id":32402486896,"side":"Sell","size":25000,"price":3111.19,"timestamp":"2024-05-18T15:46:06.737Z"},{"symbol":"ETHUSDT","id":32402486135,"side":"Sell","size":109000,"price":3110.46,"timestamp":"2024-05-18T15:46:06.737Z"}]}
{"table":"orderBookL2_25","action":"insert","data":[{"symbol":"ETHUSDT","id":32402486985,"side":"Sell","size":32000,"price":3111.21,"timestamp":"2024-05-18T15:46:06.737Z"},{"symbol":"ETHUSDT","id":32402486961,"side":"Sell","size":28000,"price":3110.82,"timestamp":"2024-05-18T15:46:06.737Z"},{"symbol":"ETHUSDT","id":32402486978,"side":"Buy","size":32000,"price":3109.72,"timestamp":"2024-05-18T15:46:06.737Z"}]}
{"table":"orderBookL2_25","action":"delete","data":[{"symbol":"XBTUSDT","id":32402486945,"side":"Sell","price":66815.4,"timestamp":"2024-05-18T15:46:06.785Z"},{"symbol":"XBTUSDT","id":32402486675,"side":"Sell","price":66812.2,"timestamp":"2024-05-18T15:46:06.785Z"},{"symbol":"XBTUSDT","id":32402486694,"side":"Sell","price":66815.3,"timestamp":"2024-05-18T15:46:06.785Z"},{"symbol":"XBTUSDT","id":32402486691,"side":"Sell","price":66812.1,"timestamp":"2024-05-18T15:46:06.785Z"},{"symbol":"XBTUSDT","id":32402486949,"side":"Buy","price":66784.0,"timestamp":"2024-05-18T15:46:06.785Z"}]}
{"table":"orderBookL2_25","action":"update","data":[{"symbol":"XBTUSDT","id":32402458161,"side":"Sell","size":159000,"price":66824.3,"timestamp":"2024-05-18T15:46:06.785Z"}]}
{"table":"orderBookL2_25","action":"insert","data":[{"symbol":"XBTUSDT","id":32402487002,"side":"Sell","size":218000,"price":66811.9,"timestamp":"2024-05-18T15:46:06.785Z"},{"symbol":"XBTUSDT","id":32402486988,"side":"Sell","size":359000,"price":66812.0,"timestamp":"2024-05-18T15:46:06.785Z"},{"symbol":"XBTUSDT","id":32402486993,"side":"Sell","size":20000,"price":66815.6,"timestamp":"2024-05-18T15:46:06.785Z"},{"symbol":"XBTUSDT","id":32402487004,"side":"Sell","size":64000,"price":66815.3,"timestamp":"2024-05-18T15:46:06.785Z"},{"symbol":"XBTUSDT","id":32402486990,"side":"Buy","size":20000,"price":66783.8,"timestamp":"2024-05-18T15:46:06.785Z"}]}
{"table":"orderBookL2_25","action":"delete","data":[{"symbol":"ETHUSDT","id":32402486985,"side":"Sell","price":3111.21,"timestamp":"2024-05-18T15:46:06.786Z"},{"symbol":"ETHUSDT","id":32402486978,"side":"Buy","price":3109.72,"timestamp":"2024-05-18T15:46:06.786Z"},{"symbol":"ETHUSDT","id":32402486900,"side":"Buy","price":3109.73,"timestamp":"2024-05-18T15:46:06.786Z"}]}
{"table":"orderBookL2_25","action":"update","data":[{"symbol":"ETHUSDT","id":32402486896,"side":"Sell","size":25000,"price":3111.19,"timestamp":"2024-05-18T15:46:06.786Z"}]}
{"table":"orderBookL2_25","action":"insert","data":[{"symbol":"ETHUSDT","id":32402487053,"side":"Sell","size":32000,"price":3111.21,"timestamp":"2024-05-18T15:46:06.786Z"},{"symbol":"ETHUSDT","id":32402487028,"side":"Buy","size":32000,"price":3109.74,"timestamp":"2024-05-18T15:46:06.786Z"},{"symbol":"ETHUSDT","id":32402487057,"side":"Buy","size":32000,"price":3109.75,"timestamp":"2024-05-18T15:46:06.786Z"}]}
{"table":"orderBookL2_25","action":"delete","data":[{"symbol":"XBTUSDT","id":32402486993,"side":"Sell","price":66815.6,"timestamp":"2024-05-18T15:46:06.834Z"},{"symbol":"XBTUSDT","id":32402486990,"side":"Buy","price":66783.8,"timestamp":"2024-05-18T15:46:06.834Z"}]}
{"table":"orderBookL2_25","action":"insert","data":[{"symbol":"XBTUSDT","id":32402487093,"side":"Sell","size":20000,"price":66815.4,"timestamp":"2024-05-18T15:46:06.834Z"},{"symbol":"XBTUSDT","id":32402487089,"side":"Buy","size":20000,"price":66784.0,"timestamp":"2024-05-18T15:46:06.834Z"}]}
{"table":"orderBookL2_25","action":"delete","data":[{"symbol":"ETHUSDT","id":32402487057,"side":"Buy","price":3109.75,"timestamp":"2024-05-18T15:46:06.835Z"}]}
{"table":"orderBookL2_25","action":"insert","data":[{"symbol":"ETHUSDT","id":32402487108,"side":"Buy","size":32000,"price":3109.73,"timestamp":"2024-05-18T15:46:06.835Z"}]}
{"table":"orderBookL2_25","action":"delete","data":[{"symbol":"XBTUSDT","id":32402487093,"side":"Sell","price":66815.4,"timestamp":"2024-05-18T15:46:06.883Z"},{"symbol":"XBTUSDT","id":32402487089,"side":"Buy","price":66784.0,"timestamp":"2024-05-18T15:46:06.883Z"}]}
{"table":"orderBookL2_25","action":"insert","data":[{"symbol":"XBTUSDT","id":32402487118,"side":"Sell","size":20000,"price":66815.6,"timestamp":"2024-05-18T15:46:06.883Z"},{"symbol":"XBTUSDT","id":32402487126,"side":"Buy","size":20000,"price":66783.8,"timestamp":"2024-05-18T15:46:06.883Z"}]}
{"table":"orderBookL2_25","action":"delete","data":[{"symbol":"ETHUSDT","id":32402485837,"side":"Sell","price":3112.66,"timestamp":"2024-05-18T15:46:06.885Z"},{"symbol":"ETHUSDT","id":32402487053,"side":"Sell","price":3111.21,"timestamp":"2024-05-18T15:46:06.885Z"},{"symbol":"ETHUSDT","id":32402460354,"side":"Buy","price":3107.79,"timestamp":"2024-05-18T15:46:06.885Z"},{"symbol":"ETHUSDT","id":32402487108,"side":"Buy","price":3109.73,"timestamp":"2024-05-18T15:46:06.885Z"},{"symbol":"ETHUSDT","id":32402484550,"side":"Buy","price":3108.96,"timestamp":"2024-05-18T15:46:06.885Z"}]}
{"table":"orderBookL2_25","action":"update","data":[{"symbol":"ETHUSDT","id":32402486896,"side":"Sell","size":25000,"price":3111.19,"timestamp":"2024-05-18T15:46:06.885Z"}]}
{"table":"orderBookL2_25","action":"insert","data":[{"symbol":"ETHUSDT","id":32402487132,"side":"Sell","size":210000,"price":3111.71,"timestamp":"2024-05-18T15:46:06.885Z"},{"symbol":"ETHUSDT","id":32402487139,"side":"Sell","size":32000,"price":3111.21,"timestamp":"2024-05-18T15:46:06.885Z"},{"symbol":"ETHUSDT","id":32402487136,"side":"Buy","size":32000,"price":3109.75,"timestamp":"2024-05-18T15:46:06.885Z"},{"symbol":"ETHUSDT","id":32402487155,"side":"Buy","size":100000,"price":3109.16,"timestamp":"2024-05-18T15:46:06.885Z"},{"symbol":"ETHUSDT","id":32402487143,"side":"Buy","size":67000,"price":3109.01,"timestamp":"2024-05-18T15:46:06.885Z"}]}
{"table":"orderBookL2_25","action":"delete","data":[{"symbol":"XBTUSDT","id":32402458161,"side":"Sell","price":66824.3,"timestamp":"2024-05-18T15:46:06.932Z"},{"symbol":"XBTUSDT","id":32402487118,"side":"Sell","price":66815.6,"timestamp":"2024-05-18T15:46:06.932Z"},{"symbol":"XBTUSDT","id":32402486975,"side":"Buy","price":66783.9,"timestamp":"2024-05-18T15:46:06.932Z"}]}
{"table":"orderBookL2_25","action":"update","data":[{"symbol":"XBTUSDT","id":32402476497,"side":"Sell","size":50000,"price":66821.6,"timestamp":"2024-05-18T15:46:06.932Z"},{"symbol":"XBTUSDT","id":32402471671,"side":"Sell","size":75000,"price":66821.7,"timestamp":"2024-05-18T15:46:06.932Z"},{"symbol":"XBTUSDT","id":32402474116,"side":"Sell","size":102000,"price":66824.2,"timestamp":"2024-05-18T15:46:06.932Z"}]}
{"table":"orderBookL2_25","action":"insert","data":[{"symbol":"XBTUSDT","id":32402487237,"side":"Sell","size":1000,"price":66821.8,"timestamp":"2024-05-18T15:46:06.932Z"},{"symbol":"XBTUSDT","id":32402487243,"side":"Sell","size":20000,"price":66815.6,"timestamp":"2024-05-18T15:46:06.932Z"},{"symbol":"XBTUSDT","id":32402487219,"side":"Buy","size":20000,"price":66783.5,"timestamp":"2024-05-18T15:46:06.932Z"}]}
{"table":"orderBookL2_25","action":"delete","data":[{"symbol":"ETHUSDT","id":32402487139,"side":"Sell","price":3111.21,"timestamp":"2024-05-18T15:46:06.934Z"},{"symbol":"ETHUSDT","id":32402487136,"side":"Buy","price":3109.75,"timestamp":"2024-05-18T15:46:06.934Z"},{"symbol":"ETHUSDT","id":32402487028,"side":"Buy","price":3109.74,"timestamp":"2024-05-18T15:46:06.934Z"},{"symbol":"ETHUSDT","id":32402485798,"side":"Buy","price":3109.49,"timestamp":"2024-05-18T15:46:06.934Z"},{"symbol":"ETHUSDT","id":32402486888,"side":"Buy","price":3109.48,"timestamp":"2024-05-18T15:46:06.934Z"}]}
{"table":"orderBookL2_25","action":"update","data":[{"symbol":"ETHUSDT","id":32402486896,"side":"Sell","size":57000,"price":3111.19,"timestamp":"2024-05-18T15:46:06.934Z"}]}
{"table":"orderBookL2_25","action":"insert","data":[{"symbol":"ETHUSDT","id":32402485837,"side":"Sell","size":346000,"price":3112.66,"timestamp":"2024-05-18T15:46:06.934Z"},{"symbol":"ETHUSDT","id":32402487245,"side":"Buy","size":1000,"price":3109.49,"timestamp":"2024-05-18T15:46:06.934Z"},{"symbol":"ETHUSDT","id":32402487216,"side":"Buy","size":32000,"price":3109.69,"timestamp":"2024-05-18T15:46:06.934Z"},{"symbol":"ETHUSDT","id":32402487241,"side":"Buy","size":1000,"price":3109.48,"timestamp":"2024-05-18T15:46:06.934Z"},{"symbol":"ETHUSDT","id":32402487196,"side":"Buy","size":32000,"price":3109.70,"timestamp":"2024-05-18T15:46:06.934Z"}]}
{"table":"orderBookL2_25","action":"delete","data":[{"symbol":"XBTUSDT","id":32402487243,"side":"Sell","price":66815.6,"timestamp":"2024-05-18T15:46:06.981Z"},{"symbol":"XBTUSDT","id":32402487219,"side":"Buy","price":66783.5,"timestamp":"2024-05-18T15:46:06.981Z"},{"symbol":"XBTUSDT","id":32402487126,"side":"Buy","price":66783.8,"timestamp":"2024-05-18T15:46:06.981Z"}]}
{"table":"orderBookL2_25","action":"update","data":[{"symbol":"XBTUSDT","id":32402479097,"side":"Sell","size":23000,"price":66815.5,"timestamp":"2024-05-18T15:46:06.981Z"},{"symbol":"XBTUSDT","id":32402462668,"side":"Sell","size":359000,"price":66801.9,"timestamp":"2024-05-18T15:46:06.981Z"},{"symbol":"XBTUSDT","id":32402461579,"side":"Sell","size":100000,"price":66815.7,"timestamp":"2024-05-18T15:46:06.981Z"}]}
{"table":"orderBookL2_25","action":"insert","data":[{"symbol":"XBTUSDT","id":32402487302,"side":"Sell","size":20000,"price":66815.6,"timestamp":"2024-05-18T15:46:06.981Z"},{"symbol":"XBTUSDT","id":32402487278,"side":"Buy","size":20000,"price":66783.9,"timestamp":"2024-05-18T15:46:06.981Z"},{"symbol":"XBTUSDT","id":32402487281,"side":"Buy","size":20000,"price":66783.8,"timestamp":"2024-05-18T15:46:06.981Z"}]}
{"table":"orderBookL2_25","action":"delete","data":[{"symbol":"ETHUSDT","id":32402485837,"side":"Sell","price":3112.66,"timestamp":"2024-05-18T15:46:06.983Z"},{"symbol":"ETHUSDT","id":32402449038,"side":"Sell","price":3112.43,"timestamp":"2024-05-18T15:46:06.983Z"},{"symbol":"ETHUSDT","id":32402450496,"side":"Sell","price":3112.27,"timestamp":"2024-05-18T15:46:06.983Z"},{"symbol":"ETHUSDT","id":32402487216,"side":"Buy","price":3109.69,"timestamp":"2024-05-18T15:46:06.983Z"},{"symbol":"ETHUSDT","id":32402487196,"side":"Buy","price":3109.70,"timestamp":"2024-05-18T15:46:06.983Z"}]}
{"table":"orderBookL2_25","action":"update","data":[{"symbol":"ETHUSDT","id":32402486896,"side":"Sell","size":25000,"price":3111.19,"timestamp":"2024-05-18T15:46:06.983Z"}]}
{"table":"orderBookL2_25","action":"insert","data":[{"symbol":"ETHUSDT","id":32402487305,"side":"Sell","size":100000,"price":3111.65,"timestamp":"2024-05-18T15:46:06.983Z"},{"symbol":"ETHUSDT","id":32402487294,"side":"Sell","size":46000,"price":3111.54,"timestamp":"2024-05-18T15:46:06.983Z"},{"symbol":"ETHUSDT","id":32402487272,"side":"Sell","size":32000,"price":3111.21,"timestamp":"2024-05-18T15:46:06.983Z"},{"symbol":"ETHUSDT","id":32402487276,"side":"Buy","size":32000,"price":3109.72,"timestamp":"2024-05-18T15:46:06.983Z"},{"symbol":"ETHUSDT","id":32402487270,"side":"Buy","size":32000,"price":3109.73,"timestamp":"2024-05-18T15:46:06.983Z"}]}
{"table":"orderBookL2_25","action":"delete","data":[{"symbol":"XBTUSDT","id":32402487002,"side":"Sell","price":66811.9,"timestamp":"2024-05-18T15:46:07.030Z"},{"symbol":"XBTUSDT","id":32402485060,"side":"Sell","price":66809.9,"timestamp":"2024-05-18T15:46:07.030Z"},{"symbol":"XBTUSDT","id":32402486988,"side":"Sell","price":66812.0,"timestamp":"2024-05-18T15:46:07.030Z"},{"symbol":"XBTUSDT","id":32402487004,"side":"Sell","price":66815.3,"timestamp":"2024-05-18T15:46:07.030Z"}]}
{"table":"orderBookL2_25","action":"insert","data":[{"symbol":"XBTUSDT","id":32402487315,"side":"Sell","size":217000,"price":66811.7,"timestamp":"2024-05-18T15:46:07.030Z"},{"symbol":"XBTUSDT","id":32402458161,"side":"Sell","size":159000,"price":66824.3,"timestamp":"2024-05-18T15:46:07.030Z"},{"symbol":"XBTUSDT","id":32402487307,"side":"Sell","size":352000,"price":66811.8,"timestamp":"2024-05-18T15:46:07.030Z"},{"symbol":"XBTUSDT","id":32402487321,"side":"Sell","size":67000,"price":66815.4,"timestamp":"2024-05-18T15:46:07.030Z"}]}
{"table":"orderBookL2_25","action":"delete","data":[{"symbol":"ETHUSDT","id":32402460525,"side":"Sell","price":3112.25,"timestamp":"2024-05-18T15:46:07.047Z"}]}
{"table":"orderBookL2_25","action":"insert","data":[{"symbol":"ETHUSDT","id":32402487433,"side":"Sell","size":2000,"price":3110.30,"timestamp":"2024-05-18T15:46:07.047Z"}]}
{"table":"orderBookL2_25","action":"update","data":[{"symbol":"XBTUSDT","id":32402480326,"side":"Buy","size":102000,"price":66788.2,"timestamp":"2024-05-18T15:46:07.079Z"}]}
{"table":"orderBookL2_25","action":"delete","data":[{"symbol":"ETHUSDT","id":32402480950,"side":"Sell","price":3112.19,"timestamp":"2024-05-18T15:46:07.097Z"},{"symbol":"ETHUSDT","id":32402466549,"side":"Sell","price":3112.15,"timestamp":"2024-05-18T15:46:07.097Z"}]}
{"table":"orderBookL2_25","action":"update","data":[{"symbol":"ETHUSDT","id":32402486135,"side":"Sell","size":100000,"price":3110.46,"timestamp":"2024-05-18T15:46:07.097Z"},{"symbol":"ETHUSDT","id":32402487433,"side":"Sell","size":11000,"price":3110.30,"timestamp":"2024-05-18T15:46:07.097Z"}]}
{"table":"orderBookL2_25","action":"insert","data":[{"symbol":"ETHUSDT","id":32402487481,"side":"Sell","size":100000,"price":3111.10,"timestamp":"2024-05-18T15:46:07.097Z"},{"symbol":"ETHUSDT","id":32402487461,"side":"Sell","size":28000,"price":3110.65,"timestamp":"2024-05-18T15:46:07.097Z"}]}
{"table":"orderBookL2_25","action":"delete","data":[{"symbol":"XBTUSDT","id":32402487302,"side":"Sell","price":66815.6,"timestamp":"2024-05-18T15:46:07.128Z"},{"symbol":"XBTUSDT","id":32402487237,"side":"Sell","price":66821.8,"timestamp":"2024-05-18T15:46:07.128Z"},{"symbol":"XBTUSDT","id":32402487281,"side":"Buy","price":66783.8,"timestamp":"2024-05-18T15:46:07.128Z"}]}
{"table":"orderBookL2_25","action":"update","data":[{"symbol":"XBTUSDT","id":32402476497,"side":"Sell","size":51000,"price":66821.6,"timestamp":"2024-05-18T15:46:07.128Z"},{"symbol":"XBTUSDT","id":32402487321,"side":"Sell","size":87000,"price":66815.4,"timestamp":"2024-05-18T15:46:07.128Z"}]}
{"table":"orderBookL2_25","action":"insert","data":[{"symbol":"XBTUSDT","id":32402457533,"side":"Sell","size":331000,"price":66830.8,"timestamp":"2024-05-18T15:46:07.128Z"},{"symbol":"XBTUSDT","id":32402441693,"side":"Sell","size":100000,"price":66829.0,"timestamp":"2024-05-18T15:46:07.128Z"},{"symbol":"XBTUSDT","id":32402487583,"side":"Buy","size":20000,"price":66784.0,"timestamp":"2024-05-18T15:46:07.128Z"}]}
{"table":"orderBookL2_25","action":"delete","data":[{"symbol":"ETHUSDT","id":32402487272,"side":"Sell","price":3111.21,"timestamp":"2024-05-18T15:46:07.146Z"},{"symbol":"ETHUSDT","id":32402486765,"side":"Sell","price":3111.20,"timestamp":"2024-05-18T15:46:07.146Z"},{"symbol":"ETHUSDT","id":32402486961,"side":"Sell","price":3110.82,"timestamp":"2024-05-18T15:46:07.146Z"},{"symbol":"ETHUSDT","id":32402486896,"side":"Sell","price":3111.19,"timestamp":"2024-05-18T15:46:07.146Z"},{"symbol":"ETHUSDT","id":32402487241,"side":"Buy","price":3109.48,"timestamp":"2024-05-18T15:46:07.146Z"},{"symbol":"ETHUSDT","id":32402483959,"side":"Buy","price":3109.89,"timestamp":"2024-05-18T15:46:07.146Z"},{"symbol":"ETHUSDT","id":32402487245,"side":"Buy","price":3109.49,"timestamp":"2024-05-18T15:46:07.146Z"},{"symbol":"ETHUSDT","id":32402487276,"side":"Buy","price":3109.72,"timestamp":"2024-05-18T15:46:07.146Z"},{"symbol":"ETHUSDT","id":32402487270,"side":"Buy","price":3109.73,"timestamp":"2024-05-18T15:46:07.146Z"}]}
{"table":"orderBookL2_25","action":"insert","data":[{"symbol":"ETHUSDT","id":32402487612,"side":"Sell","size":32000,"price":3111.13,"timestamp":"2024-05-18T15:46:07.146Z"},{"symbol":"ETHUSDT","id":32402466549,"side":"Sell","size":2300000,"price":3112.15,"timestamp":"2024-05-18T15:46:07.146Z"},{"symbol":"ETHUSDT","id":32402487597,"side":"Sell","size":32000,"price":3111.14,"timestamp":"2024-05-18T15:46:07.146Z"},{"symbol":"ETHUSDT","id":32402480950,"side":"Sell","size":1156000,"price":3112.19,"timestamp":"2024-05-18T15:46:07.146Z"},{"symbol":"ETHUSDT","id":32402487595,"side":"Buy","size":32000,"price":3109.73,"timestamp":"2024-05-18T15:46:07.146Z"},{"symbol":"ETHUSDT","id":32402460354,"side":"Buy","size":1620000,"price":3107.79,"timestamp":"2024-05-18T15:46:07.146Z"},{"symbol":"ETHUSDT","id":32402487633,"side":"Buy","size":1000,"price":3109.46,"timestamp":"2024-05-18T15:46:07.146Z"},{"symbol":"ETHUSDT","id":32402487604,"side":"Buy","size":1000,"price":3109.47,"timestamp":"2024-05-18T15:46:07.146Z"},{"symbol":"ETHUSDT","id":32402487590,"side":"Buy","size":32000,"price":3109.74,"timestamp":"2024-05-18T15:46:07.146Z"}]}
{"table":"orderBookL2_25","action":"delete","data":[{"symbol":"XBTUSDT","id":32402487278,"side":"Buy","price":66783.9,"timestamp":"2024-05-18T15:46:07.177Z"},{"symbol":"XBTUSDT","id":32402487583,"side":"Buy","price":66784.0,"timestamp":"2024-05-18T15:46:07.177Z"}]}
{"table":"orderBookL2_25","action":"update","data":[{"symbol":"XBTUSDT","id":32402479097,"side":"Sell","size":23000,"price":66815.5,"timestamp":"2024-05-18T15:46:07.177Z"},{"symbol":"XBTUSDT","id":32402476497,"side":"Sell","size":51000,"price":66821.6,"timestamp":"2024-05-18T15:46:07.177Z"},{"symbol":"XBTUSDT","id":32402441693,"side":"Sell","size":100000,"price":66829.0,"timestamp":"2024-05-18T15:46:07.177Z"},{"symbol":"XBTUSDT","id":32402457533,"side":"Sell","size":331000,"price":66830.8,"timestamp":"2024-05-18T15:46:07.177Z"},{"symbol":"XBTUSDT","id":32402458161,"side":"Sell","size":159000,"price":66824.3,"timestamp":"2024-05-18T15:46:07.177Z"},{"symbol":"XBTUSDT","id":32402471671,"side":"Sell","size":75000,"price":66821.7,"timestamp":"2024-05-18T15:46:07.177Z"}]}
{"table":"orderBookL2_25","action":"insert","data":[{"symbol":"XBTUSDT","id":32402487685,"side":"Buy","size":20000,"price":66783.7,"timestamp":"2024-05-18T15:46:07.177Z"},{"symbol":"XBTUSDT","id":32402487621,"side":"Buy","size":20000,"price":66783.8,"timestamp":"2024-05-18T15:46:07.177Z"}]}
{"table":"orderBookL2_25","action":"delete","data":[{"symbol":"ETHUSDT","id":32402487612,"side":"Sell","price":3111.13,"timestamp":"2024-05-18T15:46:07.195Z"},{"symbol":"ETHUSDT","id":32402487597,"side":"Sell","price":3111.14,"timestamp":"2024-05-18T15:46:07.195Z"},{"symbol":"ETHUSDT","id":32402487590,"side":"Buy","price":3109.74,"timestamp":"2024-05-18T15:46:07.195Z"},{"symbol":"ETHUSDT","id":32402487633,"side":"Buy","price":3109.46,"timestamp":"2024-05-18T15:46:07.195Z"},{"symbol":"ETHUSDT","id":32402487595,"side":"Buy","price":3109.73,"timestamp":"2024-05-18T15:46:07.195Z"}]}
{"table":"orderBookL2_25","action":"insert","data":[{"symbol":"ETHUSDT","id":32402487649,"side":"Sell","size":32000,"price":3111.12,"timestamp":"2024-05-18T15:46:07.195Z"},{"symbol":"ETHUSDT","id":32402487651,"side":"Sell","size":32000,"price":3111.11,"timestamp":"2024-05-18T15:46:07.195Z"},{"symbol":"ETHUSDT","id":32402487657,"side":"Buy","size":32000,"price":3109.72,"timestamp":"2024-05-18T15:46:07.195Z"},{"symbol":"ETHUSDT","id":32402487694,"side":"Buy","size":1000,"price":3109.46,"timestamp":"2024-05-18T15:46:07.195Z"},{"symbol":"ETHUSDT","id":32402487639,"side":"Buy","size":32000,"price":3109.71,"timestamp":"2024-05-18T15:46:07.195Z"}]}
{"table":"orderBookL2_25","action":"delete","data":[{"symbol":"ETHUSDT","id":32402480950,"side":"Sell","price":3112.19,"timestamp":"2024-05-18T15:46:07.291Z"}]}
{"table":"orderBookL2_25","action":"insert","data":[{"symbol":"ETHUSDT","id":32402487799,"side":"Sell","size":241000,"price":3111.06,"timestamp":"2024-05-18T15:46:07.291Z"}]}
{"table":"orderBookL2_25","action":"delete","data":[{"symbol":"ETHUSDT","id":32402482712,"side":"Buy","price":3108.62,"timestamp":"2024-05-18T15:46:07.340Z"}]}
{"table":"orderBookL2_25","action":"insert","data":[{"symbol":"ETHUSDT","id":32402487850,"side":"Buy","size":522000,"price":3108.47,"timestamp":"2024-05-18T15:46:07.340Z"}]}
{"table":"orderBookL2_25","action":"delete","data":[{"symbol":"ETHUSDT","id":32402460354,"side":"Buy","price":3107.79,"timestamp":"2024-05-18T15:46:07.423Z"}]}
{"table":"orderBookL2_25","action":"insert","data":[{"symbol":"ETHUSDT","id":32402487930,"side":"Buy","size":48000,"price":3109.88,"timestamp":"2024-05-18T15:46:07.423Z"}]}
{"table":"orderBookL2_25","action":"delete","data":[{"symbol":"XBTUSDT","id":32402457533,"side":"Sell","price":66830.8,"timestamp":"2024-05-18T15:46:07.458Z"}]}
{"table":"orderBookL2_25","action":"update","data":[{"symbol":"XBTUSDT","id":32402471671,"side":"Sell","size":74000,"price":66821.7,"timestamp":"2024-05-18T15:46:07.458Z"}]}
{"table":"orderBookL2_25","action":"insert","data":[{"symbol":"XBTUSDT","id":32402487975,"side":"Sell","size":1000,"price":66821.5,"timestamp":"2024-05-18T15:46:07.458Z"}]}
{"table":"orderBookL2_25","action":"delete","data":[{"symbol":"ETHUSDT","id":32402466549,"side":"Sell","price":3112.15,"timestamp":"2024-05-18T15:46:07.472Z"},{"symbol":"ETHUSDT","id":32402487651,"side":"Sell","price":3111.11,"timestamp":"2024-05-18T15:46:07.472Z"},{"symbol":"ETHUSDT","id":32402480249,"side":"Buy","price":3107.80,"timestamp":"2024-05-18T15:46:07.472Z"},{"symbol":"ETHUSDT","id":32402487694,"side":"Buy","price":3109.46,"timestamp":"2024-05-18T15:46:07.472Z"},{"symbol":"ETHUSDT","id":32402487604,"side":"Buy","price":3109.47,"timestamp":"2024-05-18T15:46:07.472Z"},{"symbol":"ETHUSDT","id":32402487639,"side":"Buy","price":3109.71,"timestamp":"2024-05-18T15:46:07.472Z"},{"symbol":"ETHUSDT","id":32402487850,"side":"Buy","price":3108.47,"timestamp":"2024-05-18T15:46:07.472Z"}]}
{"table":"orderBookL2_25","action":"insert","data":[{"symbol":"ETHUSDT","id":32402488000,"side":"Sell","size":32000,"price":3111.11,"timestamp":"2024-05-18T15:46:07.472Z"},{"symbol":"ETHUSDT","id":32402487998,"side":"Sell","size":100000,"price":3110.94,"timestamp":"2024-05-18T15:46:07.472Z"},{"symbol":"ETHUSDT","id":32402488002,"side":"Buy","size":1000,"price":3109.51,"timestamp":"2024-05-18T15:46:07.472Z"},{"symbol":"ETHUSDT","id":32402487989,"side":"Buy","size":32000,"price":3109.71,"timestamp":"2024-05-18T15:46:07.472Z"},{"symbol":"ETHUSDT","id":32402487978,"side":"Buy","size":637000,"price":3107.98,"timestamp":"2024-05-18T15:46:07.472Z"},{"symbol":"ETHUSDT","id":32402487994,"side":"Buy","size":100000,"price":3108.29,"timestamp":"2024-05-18T15:46:07.472Z"},{"symbol":"ETHUSDT","id":32402487980,"side":"Buy","size":1000,"price":3109.50,"timestamp":"2024-05-18T15:46:07.472Z"}]}
{"table":"orderBookL2_25","action":"delete","data":[{"symbol":"XBTUSDT","id":32402487975,"side":"Sell","price":66821.5,"timestamp":"2024-05-18T15:46:07.508Z"},{"symbol":"XBTUSDT","id":32402487685,"side":"Buy","price":66783.7,"timestamp":"2024-05-18T15:46:07.508Z"}]}
{"table":"orderBookL2_25","action":"update","data":[{"symbol":"XBTUSDT","id":32402471671,"side":"Sell","size":75000,"price":66821.7,"timestamp":"2024-05-18T15:46:07.508Z"},{"symbol":"XBTUSDT","id":32402487321,"side":"Sell","size":87000,"price":66815.4,"timestamp":"2024-05-18T15:46:07.508Z"}]}
{"table":"orderBookL2_25","action":"insert","data":[{"symbol":"XBTUSDT","id":32402457533,"side":"Sell","size":331000,"price":66830.8,"timestamp":"2024-05-18T15:46:07.508Z"},{"symbol":"XBTUSDT","id":32402488054,"side":"Buy","size":20000,"price":66783.7,"timestamp":"2024-05-18T15:46:07.508Z"}]}
{"table":"orderBookL2_25","action":"delete","data":[{"symbol":"ETHUSDT","id":32402487649,"side":"Sell","price":3111.12,"timestamp":"2024-05-18T15:46:07.521Z"},{"symbol":"ETHUSDT","id":32402487657,"side":"Buy","price":3109.72,"timestamp":"2024-05-18T15:46:07.521Z"},{"symbol":"ETHUSDT","id":32402487143,"side":"Buy","price":3109.01,"timestamp":"2024-05-18T15:46:07.521Z"},{"symbol":"ETHUSDT","id":32402480842,"side":"Buy","price":3109.00,"timestamp":"2024-05-18T15:46:07.521Z"},{"symbol":"ETHUSDT","id":32402487980,"side":"Buy","price":3109.50,"timestamp":"2024-05-18T15:46:07.521Z"},{"symbol":"ETHUSDT","id":32402487155,"side":"Buy","price":3109.16,"timestamp":"2024-05-18T15:46:07.521Z"},{"symbol":"ETHUSDT","id":32402488002,"side":"Buy","price":3109.51,"timestamp":"2024-05-18T15:46:07.521Z"}]}
{"table":"orderBookL2_25","action":"update","data":[{"symbol":"ETHUSDT","id":32402467535,"side":"Sell","size":1095000,"price":3112.14,"timestamp":"2024-05-18T15:46:07.521Z"},{"symbol":"ETHUSDT","id":32402487481,"side":"Sell","size":132000,"price":3111.10,"timestamp":"2024-05-18T15:46:07.521Z"}]}
{"table":"orderBookL2_25","action":"insert","data":[{"symbol":"ETHUSDT","id":32402488016,"side":"Sell","size":2000,"price":3110.14,"timestamp":"2024-05-18T15:46:07.521Z"},{"symbol":"ETHUSDT","id":32401850719,"side":"Buy","size":160000,"price":3107.70,"timestamp":"2024-05-18T15:46:07.521Z"},{"symbol":"ETHUSDT","id":32402488059,"side":"Buy","size":32000,"price":3109.70,"timestamp":"2024-05-18T15:46:07.521Z"},{"symbol":"ETHUSDT","id":32402488035,"side":"Buy","size":100000,"price":3109.00,"timestamp":"2024-05-18T15:46:07.521Z"},{"symbol":"ETHUSDT","id":32401854083,"side":"Buy","size":100000,"price":3107.72,"timestamp":"2024-05-18T15:46:07.521Z"},{"symbol":"ETHUSDT","id":32402488050,"side":"Buy","size":1000,"price":3109.47,"timestamp":"2024-05-18T15:46:07.521Z"},{"symbol":"ETHUSDT","id":32402488029,"side":"Buy","size":1000,"price":3109.48,"timestamp":"2024-05-18T15:46:07.521Z"}]}
{"table":"orderBookL2_25","action":"delete","data":[{"symbol":"XBTUSDT","id":32402457533,"side":"Sell","price":66830.8,"timestamp":"2024-05-18T15:46:07.557Z"}]}
{"table":"orderBookL2_25","action":"update","data":[{"symbol":"XBTUSDT","id":32402479097,"side":"Sell","size":3000,"price":66815.5,"timestamp":"2024-05-18T15:46:07.557Z"},{"symbol":"XBTUSDT","id":32402461579,"side":"Sell","size":120000,"price":66815.7,"timestamp":"2024-05-18T15:46:07.557Z"},{"symbol":"XBTUSDT","id":32402487321,"side":"Sell","size":67000,"price":66815.4,"timestamp":"2024-05-18T15:46:07.557Z"}]}
{"table":"orderBookL2_25","action":"insert","data":[{"symbol":"XBTUSDT","id":32402488072,"side":"Sell","size":20000,"price":66815.6,"timestamp":"2024-05-18T15:46:07.557Z"}]}
{"table":"orderBookL2_25","action":"delete","data":[{"symbol":"ETHUSDT","id":32402487433,"side":"Sell","price":3110.30,"timestamp":"2024-05-18T15:46:07.570Z"},{"symbol":"ETHUSDT","id":32402488000,"side":"Sell","price":3111.11,"timestamp":"2024-05-18T15:46:07.570Z"},{"symbol":"ETHUSDT","id":32402488059,"side":"Buy","price":3109.70,"timestamp":"2024-05-18T15:46:07.570Z"},{"symbol":"ETHUSDT","id":32402488029,"side":"Buy","price":3109.48,"timestamp":"2024-05-18T15:46:07.570Z"},{"symbol":"ETHUSDT","id":32402487989,"side":"Buy","price":3109.71,"timestamp":"2024-05-18T15:46:07.570Z"}]}
{"table":"orderBookL2_25","action":"update","data":[{"symbol":"ETHUSDT","id":32402488016,"side":"Sell","size":11000,"price":3110.14,"timestamp":"2024-05-18T15:46:07.570Z"},{"symbol":"ETHUSDT","id":32402485810,"side":"Sell","size":67000,"price":3111.07,"timestamp":"2024-05-18T15:46:07.570Z"}]}
{"table":"orderBookL2_25","action":"insert","data":[{"symbol":"ETHUSDT","id":32402488093,"side":"Sell","size":32000,"price":3111.09,"timestamp":"2024-05-18T15:46:07.570Z"},{"symbol":"ETHUSDT","id":32402466549,"side":"Sell","size":2300000,"price":3112.15,"timestamp":"2024-05-18T15:46:07.570Z"},{"symbol":"ETHUSDT","id":32402488076,"side":"Buy","size":1000,"price":3109.46,"timestamp":"2024-05-18T15:46:07.570Z"},{"symbol":"ETHUSDT","id":32402488078,"side":"Buy","size":32000,"price":3109.69,"timestamp":"2024-05-18T15:46:07.570Z"},{"symbol":"ETHUSDT","id":32402488089,"side":"Buy","size":32000,"price":3109.70,"timestamp":"2024-05-18T15:46:07.570Z"}]}
{"table":"orderBookL2_25","action":"delete","data":[{"symbol":"XBTUSDT","id":32402441693,"side":"Sell","price":66829.0,"timestamp":"2024-05-18T15:46:07.606Z"},{"symbol":"XBTUSDT","id":32402488072,"side":"Sell","price":66815.6,"timestamp":"2024-05-18T15:46:07.606Z"},{"symbol":"XBTUSDT","id":32402482567,"side":"Buy","price":66801.7,"timestamp":"2024-05-18T15:46:07.606Z"}]}
{"table":"orderBookL2_25","action":"update","data":[{"symbol":"XBTUSDT","id":32402479097,"side":"Sell","size":23000,"price":66815.5,"timestamp":"2024-05-18T15:46:07.606Z"},{"symbol":"XBTUSDT","id":32402476497,"side":"Sell","size":50000,"price":66821.6,"timestamp":"2024-05-18T15:46:07.606Z"},{"symbol":"XBTUSDT","id":32402461579,"side":"Sell","size":100000,"price":66815.7,"timestamp":"2024-05-18T15:46:07.606Z"},{"symbol":"XBTUSDT","id":32402458161,"side":"Sell","size":159000,"price":66824.3,"timestamp":"2024-05-18T15:46:07.606Z"},{"symbol":"XBTUSDT","id":32402471671,"side":"Sell","size":74000,"price":66821.7,"timestamp":"2024-05-18T15:46:07.606Z"},{"symbol":"XBTUSDT","id":32402487321,"side":"Sell","size":87000,"price":66815.4,"timestamp":"2024-05-18T15:46:07.606Z"}]}
{"table":"orderBookL2_25","action":"insert","data":[{"symbol":"XBTUSDT","id":32402488106,"side":"Sell","size":1000,"price":66821.5,"timestamp":"2024-05-18T15:46:07.606Z"},{"symbol":"XBTUSDT","id":32402488110,"side":"Sell","size":1000,"price":66821.4,"timestamp":"2024-05-18T15:46:07.606Z"},{"symbol":"XBTUSDT","id":32402360485,"side":"Buy","size":100000,"price":66764.4,"timestamp":"2024-05-18T15:46:07.606Z"}]}
{"table":"orderBookL2_25","action":"delete","data":[{"symbol":"ETHUSDT","id":32402488093,"side":"Sell","price":3111.09,"timestamp":"2024-05-18T15:46:07.619Z"},{"symbol":"ETHUSDT","id":32402488078,"side":"Buy","price":3109.69,"timestamp":"2024-05-18T15:46:07.619Z"},{"symbol":"ETHUSDT","id":32402488076,"side":"Buy","price":3109.46,"timestamp":"2024-05-18T15:46:07.619Z"}]}
{"table":"orderBookL2_25","action":"insert","data":[{"symbol":"ETHUSDT","id":32402488120,"side":"Sell","size":32000,"price":3111.11,"timestamp":"2024-05-18T15:46:07.619Z"},{"symbol":"ETHUSDT","id":32402488118,"side":"Buy","size":32000,"price":3109.71,"timestamp":"2024-05-18T15:46:07.619Z"},{"symbol":"ETHUSDT","id":32402488108,"side":"Buy","size":1000,"price":3109.48,"timestamp":"2024-05-18T15:46:07.619Z"}]}
{"table":"orderBookL2_25","action":"delete","data":[{"symbol":"XBTUSDT","id":32402487315,"side":"Sell","price":66811.7,"timestamp":"2024-05-18T15:46:07.655Z"},{"symbol":"XBTUSDT","id":32402474116,"side":"Sell","price":66824.2,"timestamp":"2024-05-18T15:46:07.655Z"},{"symbol":"XBTUSDT","id":32402458161,"side":"Sell","price":66824.3,"timestamp":"2024-05-18T15:46:07.655Z"},{"symbol":"XBTUSDT","id":32402487307,"side":"Sell","price":66811.8,"timestamp":"2024-05-18T15:46:07.655Z"},{"symbol":"XBTUSDT","id":32402488054,"side":"Buy","price":66783.7,"timestamp":"2024-05-18T15:46:07.655Z"}]}
{"table":"orderBookL2_25","action":"update","data":[{"symbol":"XBTUSDT","id":32402487321,"side":"Sell","size":20000,"price":66815.4,"timestamp":"2024-05-18T15:46:07.655Z"},{"symbol":"XBTUSDT","id":32402455289,"side":"Sell","size":22000,"price":66822.3,"timestamp":"2024-05-18T15:46:07.655Z"},{"symbol":"XBTUSDT","id":32402479097,"side":"Sell","size":3000,"price":66815.5,"timestamp":"2024-05-18T15:46:07.655Z"}]}
{"table":"orderBookL2_25","action":"insert","data":[{"symbol":"XBTUSDT","id":32402488170,"side":"Sell","size":61000,"price":66815.2,"timestamp":"2024-05-18T15:46:07.655Z"},{"symbol":"XBTUSDT","id":32402488168,"side":"Sell","size":212000,"price":66811.5,"timestamp":"2024-05-18T15:46:07.655Z"},{"symbol":"XBTUSDT","id":32402488156,"side":"Sell","size":353000,"price":66811.6,"timestamp":"2024-05-18T15:46:07.655Z"},{"symbol":"XBTUSDT","id":32402488154,"side":"Sell","size":20000,"price":66815.3,"timestamp":"2024-05-18T15:46:07.655Z"},{"symbol":"XBTUSDT","id":32402488162,"side":"Buy","size":20000,"price":66783.9,"timestamp":"2024-05-18T15:46:07.655Z"}]}
{"table":"orderBookL2_25","action":"delete","data":[{"symbol":"XBTUSDT","id":32402487321,"side":"Sell","price":66815.4,"timestamp":"2024-05-18T15:46:07.704Z"},{"symbol":"XBTUSDT","id":32402488154,"side":"Sell","price":66815.3,"timestamp":"2024-05-18T15:46:07.704Z"},{"symbol":"XBTUSDT","id":32402360485,"side":"Buy","price":66764.4,"timestamp":"2024-05-18T15:46:07.704Z"},{"symbol":"XBTUSDT","id":32402488162,"side":"Buy","price":66783.9,"timestamp":"2024-05-18T15:46:07.704Z"},{"symbol":"XBTUSDT","id":32402487621,"side":"Buy","price":66783.8,"timestamp":"2024-05-18T15:46:07.704Z"}]}
{"table":"orderBookL2_25","action":"insert","data":[{"symbol":"XBTUSDT","id":32402488249,"side":"Sell","size":20000,"price":66815.3,"timestamp":"2024-05-18T15:46:07.704Z"},{"symbol":"XBTUSDT","id":32402488253,"side":"Sell","size":20000,"price":66815.4,"timestamp":"2024-05-18T15:46:07.704Z"},{"symbol":"XBTUSDT","id":32402488255,"side":"Buy","size":20000,"price":66783.8,"timestamp":"2024-05-18T15:46:07.704Z"},{"symbol":"XBTUSDT","id":32402488247,"side":"Buy","size":20000,"price":66783.9,"timestamp":"2024-05-18T15:46:07.704Z"},{"symbol":"XBTUSDT","id":32402488203,"side":"Buy","size":20000,"price":66801.0,"timestamp":"2024-05-18T15:46:07.704Z"}]}
{"table":"orderBookL2_25","action":"delete","data":[{"symbol":"XBTUSDT","id":32402488106,"side":"Sell","price":66821.5,"timestamp":"2024-05-18T15:46:07.787Z"}]}
{"table":"orderBookL2_25","action":"insert","data":[{"symbol":"XBTUSDT","id":32402488330,"side":"Sell","size":1000,"price":66821.1,"timestamp":"2024-05-18T15:46:07.787Z"}]}
{"table":"orderBookL2_25","action":"delete","data":[{"symbol":"ETHUSDT","id":32402488108,"side":"Buy","price":3109.48,"timestamp":"2024-05-18T15:46:07.788Z"}]}
{"table":"orderBookL2_25","action":"insert","data":[{"symbol":"ETHUSDT","id":32402488334,"side":"Buy","size":1000,"price":3109.42,"timestamp":"2024-05-18T15:46:07.788Z"}]}
{"table":"orderBookL2_25","action":"delete","data":[{"symbol":"XBTUSDT","id":32402488110,"side":"Sell","price":66821.4,"timestamp":"2024-05-18T15:46:07.837Z"},{"symbol":"XBTUSDT","id":32402488253,"side":"Sell","price":66815.4,"timestamp":"2024-05-18T15:46:07.837Z"},{"symbol":"XBTUSDT","id":32402488249,"side":"Sell","price":66815.3,"timestamp":"2024-05-18T15:46:07.837Z"},{"symbol":"XBTUSDT","id":32402488330,"side":"Sell","price":66821.1,"timestamp":"2024-05-18T15:46:07.837Z"},{"symbol":"XBTUSDT","id":32402488255,"side":"Buy","price":66783.8,"timestamp":"2024-05-18T15:46:07.837Z"},{"symbol":"XBTUSDT","id":32402488247,"side":"Buy","price":66783.9,"timestamp":"2024-05-18T15:46:07.837Z"}]}
{"table":"orderBookL2_25","action":"update","data":[{"symbol":"XBTUSDT","id":32402156627,"side":"Buy","size":120000,"price":66782.8,"timestamp":"2024-05-18T15:46:07.837Z"}]}
{"table":"orderBookL2_25","action":"insert","data":[{"symbol":"XBTUSDT","id":32402488387,"side":"Sell","size":20000,"price":66815.0,"timestamp":"2024-05-18T15:46:07.837Z"},{"symbol":"XBTUSDT","id":32402488356,"side":"Sell","size":1000,"price":66821.3,"timestamp":"2024-05-18T15:46:07.837Z"},{"symbol":"XBTUSDT","id":32402488348,"side":"Sell","size":1000,"price":66821.2,"timestamp":"2024-05-18T15:46:07.837Z"},{"symbol":"XBTUSDT","id":32402488392,"side":"Sell","size":20000,"price":66814.9,"timestamp":"2024-05-18T15:46:07.837Z"},{"symbol":"XBTUSDT","id":32402360485,"side":"Buy","size":100000,"price":66764.4,"timestamp":"2024-05-18T15:46:07.837Z"},{"symbol":"XBTUSDT","id":32402488423,"side":"Buy","size":20000,"price":66783.2,"timestamp":"2024-05-18T15:46:07.837Z"}]}
{"table":"orderBookL2_25","action":"delete","data":[{"symbol":"ETHUSDT","id":32402466549,"side":"Sell","price":3112.15,"timestamp":"2024-05-18T15:46:07.837Z"},{"symbol":"ETHUSDT","id":32402488120,"side":"Sell","price":3111.11,"timestamp":"2024-05-18T15:46:07.837Z"},{"symbol":"ETHUSDT","id":32402488089,"side":"Buy","price":3109.70,"timestamp":"2024-05-18T15:46:07.837Z"},{"symbol":"ETHUSDT","id":32402488050,"side":"Buy","price":3109.47,"timestamp":"2024-05-18T15:46:07.837Z"},{"symbol":"ETHUSDT","id":32402488118,"side":"Buy","price":3109.71,"timestamp":"2024-05-18T15:46:07.837Z"}]}
{"table":"orderBookL2_25","action":"update","data":[{"symbol":"ETHUSDT","id":32402487481,"side":"Sell","size":100000,"price":3111.10,"timestamp":"2024-05-18T15:46:07.837Z"},{"symbol":"ETHUSDT","id":32402485810,"side":"Sell","size":67000,"price":3111.07,"timestamp":"2024-05-18T15:46:07.837Z"},{"symbol":"ETHUSDT","id":32402482596,"side":"Buy","size":273000,"price":3109.67,"timestamp":"2024-05-18T15:46:07.837Z"}]}
{"table":"orderBookL2_25","action":"insert","data":[{"symbol":"ETHUSDT","id":32402488396,"side":"Sell","size":32000,"price":3110.97,"timestamp":"2024-05-18T15:46:07.837Z"},{"symbol":"ETHUSDT","id":32402488414,"side":"Sell","size":32000,"price":3110.96,"timestamp":"2024-05-18T15:46:07.837Z"},{"symbol":"ETHUSDT","id":32402488350,"side":"Buy","size":1000,"price":3109.41,"timestamp":"2024-05-18T15:46:07.837Z"},{"symbol":"ETHUSDT","id":32402397491,"side":"Buy","size":100000,"price":3107.56,"timestamp":"2024-05-18T15:46:07.837Z"},{"symbol":"ETHUSDT","id":32402488400,"side":"Buy","size":32000,"price":3109.66,"timestamp":"2024-05-18T15:46:07.837Z"}]}
{"table":"orderBookL2_25","action":"update","data":[{"symbol":"XBTETH","id":32402422012,"side":"Buy","size":8,"price":20.840,"timestamp":"2024-05-18T15:46:07.843Z"}]}
{"table":"orderBookL2_25","action":"delete","data":[{"symbol":"XBTUSDT","id":32402488392,"side":"Sell","price":66814.9,"timestamp":"2024-05-18T15:46:07.886Z"},{"symbol":"XBTUSDT","id":32402360485,"side":"Buy","price":66764.4,"timestamp":"2024-05-18T15:46:07.886Z"}]}
{"table":"orderBookL2_25","action":"update","data":[{"symbol":"XBTUSDT","id":32402156627,"side":"Buy","size":100000,"price":66782.8,"timestamp":"2024-05-18T15:46:07.886Z"}]}
{"table":"orderBookL2_25","action":"insert","data":[{"symbol":"XBTUSDT","id":32402488427,"side":"Sell","size":20000,"price":66815.1,"timestamp":"2024-05-18T15:46:07.886Z"},{"symbol":"XBTUSDT","id":32402488425,"side":"Buy","size":20000,"price":66783.1,"timestamp":"2024-05-18T15:46:07.886Z"}]}
{"table":"orderBookL2_25","action":"delete","data":[{"symbol":"ETHUSDT","id":32402488414,"side":"Sell","price":3110.96,"timestamp":"2024-05-18T15:46:07.886Z"},{"symbol":"ETHUSDT","id":32402488400,"side":"Buy","price":3109.66,"timestamp":"2024-05-18T15:46:07.886Z"}]}
{"table":"orderBookL2_25","action":"insert","data":[{"symbol":"ETHUSDT","id":32402488438,"side":"Sell","size":32000,"price":3110.98,"timestamp":"2024-05-18T15:46:07.886Z"},{"symbol":"ETHUSDT","id":32402488434,"side":"Buy","size":32000,"price":3109.68,"timestamp":"2024-05-18T15:46:07.886Z"}]}
{"table":"orderBookL2_25","action":"delete","data":[{"symbol":"ETHUSDT","id":32402467535,"side":"Sell","price":3112.14,"timestamp":"2024-05-18T15:46:07.935Z"},{"symbol":"ETHUSDT","id":32402488438,"side":"Sell","price":3110.98,"timestamp":"2024-05-18T15:46:07.935Z"},{"symbol":"ETHUSDT","id":32402488434,"side":"Buy","price":3109.68,"timestamp":"2024-05-18T15:46:07.935Z"},{"symbol":"ETHUSDT","id":32402488350,"side":"Buy","price":3109.41,"timestamp":"2024-05-18T15:46:07.935Z"},{"symbol":"ETHUSDT","id":32402487930,"side":"Buy","price":3109.88,"timestamp":"2024-05-18T15:46:07.935Z"}]}
{"table":"orderBookL2_25","action":"update","data":[{"symbol":"ETHUSDT","id":32402397491,"side":"Buy","size":100000,"price":3107.56,"timestamp":"2024-05-18T15:46:07.935Z"}]}
{"table":"orderBookL2_25","action":"insert","data":[{"symbol":"ETHUSDT","id":32402488478,"side":"Sell","size":145000,"price":3111.05,"timestamp":"2024-05-18T15:46:07.935Z"},{"symbol":"ETHUSDT","id":32402488489,"side":"Sell","size":32000,"price":3110.96,"timestamp":"2024-05-18T15:46:07.935Z"},{"symbol":"ETHUSDT","id":32402488484,"side":"Buy","size":1000,"price":3109.41,"timestamp":"2024-05-18T15:46:07.935Z"},{"symbol":"ETHUSDT","id":32402488476,"side":"Buy","size":196000,"price":3108.96,"timestamp":"2024-05-18T15:46:07.935Z"},{"symbol":"ETHUSDT","id":32402488491,"side":"Buy","size":32000,"price":3109.66,"timestamp":"2024-05-18T15:46:07.935Z"}]}
{"table":"orderBookL2_25","action":"update","data":[{"symbol":"XBTUSDT","id":32402462668,"side":"Sell","size":319000,"price":66801.9,"timestamp":"2024-05-18T15:46:07.981Z"}]}
{"table":"orderBookL2_25","action":"delete","data":[{"symbol":"ETHUSDT","id":32402488489,"side":"Sell","price":3110.96,"timestamp":"2024-05-18T15:46:07.984Z"},{"symbol":"ETHUSDT","id":32402397491,"side":"Buy","price":3107.56,"timestamp":"2024-05-18T15:46:07.984Z"}]}
{"table":"orderBookL2_25","action":"update","data":[{"symbol":"ETHUSDT","id":32402482596,"side":"Buy","size":241000,"price":3109.67,"timestamp":"2024-05-18T15:46:07.984Z"}]}
{"table":"orderBookL2_25","action":"insert","data":[{"symbol":"ETHUSDT","id":32402488520,"side":"Sell","size":32000,"price":3110.98,"timestamp":"2024-05-18T15:46:07.984Z"},{"symbol":"ETHUSDT","id":32402488518,"side":"Buy","size":32000,"price":3109.65,"timestamp":"2024-05-18T15:46:07.984Z"}]}
{"table":"orderBookL2_25","action":"delete","data":[{"symbol":"XBTUSDT","id":32402488427,"side":"Sell","price":66815.1,"timestamp":"2024-05-18T15:46:08.030Z"},{"symbol":"XBTUSDT","id":32402488423,"side":"Buy","price":66783.2,"timestamp":"2024-05-18T15:46:08.030Z"}]}
{"table":"orderBookL2_25","action":"insert","data":[{"symbol":"XBTUSDT","id":32402488546,"side":"Sell","size":20000,"price":66815.1,"timestamp":"2024-05-18T15:46:08.030Z"},{"symbol":"XBTUSDT","id":32402488542,"side":"Buy","size":20000,"price":66783.2,"timestamp":"2024-05-18T15:46:08.030Z"}]}
{"table":"orderBookL2_25","action":"delete","data":[{"symbol":"ETHUSDT","id":32402488520,"side":"Sell","price":3110.98,"timestamp":"2024-05-18T15:46:08.033Z"},{"symbol":"ETHUSDT","id":32402461791,"side":"Sell","price":3112.06,"timestamp":"2024-05-18T15:46:08.033Z"},{"symbol":"ETHUSDT","id":32402488518,"side":"Buy","price":3109.65,"timestamp":"2024-05-18T15:46:08.033Z"}]}
{"table":"orderBookL2_25","action":"update","data":[{"symbol":"ETHUSDT","id":32402482596,"side":"Buy","size":273000,"price":3109.67,"timestamp":"2024-05-18T15:46:08.033Z"}]}
{"table":"orderBookL2_25","action":"insert","data":[{"symbol":"ETHUSDT","id":32402488551,"side":"Sell","size":23000,"price":3110.13,"timestamp":"2024-05-18T15:46:08.033Z"},{"symbol":"ETHUSDT","id":32402488531,"side":"Sell","size":32000,"price":3110.96,"timestamp":"2024-05-18T15:46:08.033Z"},{"symbol":"ETHUSDT","id":32402397491,"side":"Buy","size":100000,"price":3107.56,"timestamp":"2024-05-18T15:46:08.033Z"}]}
{"table":"orderBookL2_25","action":"delete","data":[{"symbol":"XBTUSDT","id":32402488348,"side":"Sell","price":66821.2,"timestamp":"2024-05-18T15:46:08.079Z"}]}
{"table":"orderBookL2_25","action":"insert","data":[{"symbol":"XBTUSDT","id":32402488572,"side":"Sell","size":1000,"price":66821.4,"timestamp":"2024-05-18T15:46:08.079Z"}]}
{"table":"orderBookL2_25","action":"delete","data":[{"symbol":"ETHUSDT","id":32402486106,"side":"Sell","price":3110.51,"timestamp":"2024-05-18T15:46:08.082Z"},{"symbol":"ETHUSDT","id":32402488016,"side":"Sell","price":3110.14,"timestamp":"2024-05-18T15:46:08.082Z"},{"symbol":"ETHUSDT","id":32402488396,"side":"Sell","price":3110.97,"timestamp":"2024-05-18T15:46:08.082Z"},{"symbol":"ETHUSDT","id":32402486097,"side":"Sell","price":3110.52,"timestamp":"2024-05-18T15:46:08.082Z"},{"symbol":"ETHUSDT","id":32402488334,"side":"Buy","price":3109.42,"timestamp":"2024-05-18T15:46:08.082Z"}]}
{"table":"orderBookL2_25","action":"update","data":[{"symbol":"ETHUSDT","id":32402488551,"side":"Sell","size":130000,"price":3110.13,"timestamp":"2024-05-18T15:46:08.082Z"},{"symbol":"ETHUSDT","id":32402482596,"side":"Buy","size":241000,"price":3109.67,"timestamp":"2024-05-18T15:46:08.082Z"},{"symbol":"ETHUSDT","id":32401945550,"side":"Buy","size":2000,"price":3109.40,"timestamp":"2024-05-18T15:46:08.082Z"},{"symbol":"ETHUSDT","id":32402397491,"side":"Buy","size":100000,"price":3107.56,"timestamp":"2024-05-18T15:46:08.082Z"}]}
{"table":"orderBookL2_25","action":"insert","data":[{"symbol":"ETHUSDT","id":32402488587,"side":"Sell","size":28000,"price":3110.48,"timestamp":"2024-05-18T15:46:08.082Z"},{"symbol":"ETHUSDT","id":32402488556,"side":"Sell","size":61000,"price":3110.45,"timestamp":"2024-05-18T15:46:08.082Z"},{"symbol":"ETHUSDT","id":32402461791,"side":"Sell","size":989000,"price":3112.06,"timestamp":"2024-05-18T15:46:08.082Z"},{"symbol":"ETHUSDT","id":32402488581,"side":"Sell","size":32000,"price":3110.95,"timestamp":"2024-05-18T15:46:08.082Z"},{"symbol":"ETHUSDT","id":32402488583,"side":"Buy","size":32000,"price":3109.65,"timestamp":"2024-05-18T15:46:08.082Z"}]}
{"table":"orderBookL2_25","action":"delete","data":[{"symbol":"XBTUSDT","id":32402488572,"side":"Sell","price":66821.4,"timestamp":"2024-05-18T15:46:08.128Z"}]}
{"table":"orderBookL2_25","action":"insert","data":[{"symbol":"XBTUSDT","id":32402488598,"side":"Sell","size":1000,"price":66821.2,"timestamp":"2024-05-18T15:46:08.128Z"}]}
{"table":"orderBookL2_25","action":"delete","data":[{"symbol":"ETHUSDT","id":32402488581,"side":"Sell","price":3110.95,"timestamp":"2024-05-18T15:46:08.131Z"},{"symbol":"ETHUSDT","id":32402487461,"side":"Sell","price":3110.65,"timestamp":"2024-05-18T15:46:08.131Z"},{"symbol":"ETHUSDT","id":32402488491,"side":"Buy","price":3109.66,"timestamp":"2024-05-18T15:46:08.131Z"}]}
{"table":"orderBookL2_25","action":"insert","data":[{"symbol":"ETHUSDT","id":32402467535,"side":"Sell","size":1095000,"price":3112.14,"timestamp":"2024-05-18T15:46:08.131Z"},{"symbol":"ETHUSDT","id":32402488612,"side":"Sell","size":32000,"price":3110.97,"timestamp":"2024-05-18T15:46:08.131Z"},{"symbol":"ETHUSDT","id":32402488622,"side":"Buy","size":32000,"price":3109.64,"timestamp":"2024-05-18T15:46:08.131Z"}]}
{"table":"orderBookL2_25","action":"delete","data":[{"symbol":"XBTUSDT","id":32402488546,"side":"Sell","price":66815.1,"timestamp":"2024-05-18T15:46:08.177Z"},{"symbol":"XBTUSDT","id":32402488542,"side":"Buy","price":66783.2,"timestamp":"2024-05-18T15:46:08.177Z"}]}
{"table":"orderBookL2_25","action":"insert","data":[{"symbol":"XBTUSDT","id":32402488659,"side":"Sell","size":20000,"price":66814.9,"timestamp":"2024-05-18T15:46:08.177Z"},{"symbol":"XBTUSDT","id":32402488657,"side":"Buy","size":20000,"price":66783.0,"timestamp":"2024-05-18T15:46:08.177Z"}]}
{"table":"orderBookL2_25","action":"delete","data":[{"symbol":"ETHUSDT","id":32402480376,"side":"Buy","price":3108.84,"timestamp":"2024-05-18T15:46:08.210Z"}]}
{"table":"orderBookL2_25","action":"insert","data":[{"symbol":"ETHUSDT","id":32402400155,"side":"Buy","size":17414000,"price":3107.38,"timestamp":"2024-05-18T15:46:08.210Z"}]}
{"table":"orderBookL2_25","action":"update","data":[{"symbol":"XBTUSDT","id":32402462668,"side":"Sell","size":320000,"price":66801.9,"timestamp":"2024-05-18T15:46:08.356Z"}]}
{"table":"orderBookL2_25","action":"delete","data":[{"symbol":"XBTUSDT","id":32402488203,"side":"Buy","price":66801.0,"timestamp":"2024-05-18T15:46:08.474Z"}]}
{"table":"orderBookL2_25","action":"insert","data":[{"symbol":"XBTUSDT","id":32402360485,"side":"Buy","size":100000,"price":66764.4,"timestamp":"2024-05-18T15:46:08.474Z"}]}
{"table":"orderBookL2_25","action":"delete","data":[{"symbol":"ETHUSDT","id":32402480784,"side":"Buy","price":3110.12,"timestamp":"2024-05-18T15:46:08.475Z"}]}
{"table":"orderBookL2_25","action":"insert","data":[{"symbol":"ETHUSDT","id":32402458908,"side":"Buy","size":1114000,"price":3107.30,"timestamp":"2024-05-18T15:46:08.475Z"}]}
{"table":"orderBookL2_25","action":"delete","data":[{"symbol":"XBTUSDT","id":32402488356,"side":"Sell","price":66821.3,"timestamp":"2024-05-18T15:46:08.524Z"},{"symbol":"XBTUSDT","id":32402488168,"side":"Sell","price":66811.5,"timestamp":"2024-05-18T15:46:08.524Z"},{"symbol":"XBTUSDT","id":32402488156,"side":"Sell","price":66811.6,"timestamp":"2024-05-18T15:46:08.524Z"},{"symbol":"XBTUSDT","id":32402488598,"side":"Sell","price":66821.2,"timestamp":"2024-05-18T15:46:08.524Z"},{"symbol":"XBTUSDT","id":32402481898,"side":"Sell","price":66807.8,"timestamp":"2024-05-18T15:46:08.524Z"},{"symbol":"XBTUSDT","id":32402488387,"side":"Sell","price":66815.0,"timestamp":"2024-05-18T15:46:08.524Z"},{"symbol":"XBTUSDT","id":32402455289,"side":"Sell","price":66822.3,"timestamp":"2024-05-18T15:46:08.524Z"},{"symbol":"XBTUSDT","id":32402484932,"side":"Buy","price":66776.1,"timestamp":"2024-05-18T15:46:08.524Z"},{"symbol":"XBTUSDT","id":32402488425,"side":"Buy","price":66783.1,"timestamp":"2024-05-18T15:46:08.524Z"},{"symbol":"XBTUSDT","id":32402478234,"side":"Buy","price":66767.9,"timestamp":"2024-05-18T15:46:08.524Z"},{"symbol":"XBTUSDT","id":32402462566,"side":"Buy","price":66791.1,"timestamp":"2024-05-18T15:46:08.524Z"}]}
{"table":"orderBookL2_25","action":"update","data":[{"symbol":"XBTUSDT","id":32402481228,"side":"Sell","size":2000,"price":66807.9,"timestamp":"2024-05-18T15:46:08.524Z"},{"symbol":"XBTUSDT","id":32402481962,"side":"Sell","size":157000,"price":66807.7,"timestamp":"2024-05-18T15:46:08.524Z"},{"symbol":"XBTUSDT","id":32402242406,"side":"Sell","size":138000,"price":66822.2,"timestamp":"2024-05-18T15:46:08.524Z"},{"symbol":"XBTUSDT","id":32402480326,"side":"Buy","size":2000,"price":66788.2,"timestamp":"2024-05-18T15:46:08.524Z"},{"symbol":"XBTUSDT","id":32402476745,"side":"Buy","size":8000,"price":66795.4,"timestamp":"2024-05-18T15:46:08.524Z"},{"symbol":"XBTUSDT","id":32402258708,"side":"Buy","size":24000,"price":66795.3,"timestamp":"2024-05-18T15:46:08.524Z"},{"symbol":"XBTUSDT","id":32402360485,"side":"Buy","size":255000,"price":66764.4,"timestamp":"2024-05-18T15:46:08.524Z"}]}
{"table":"orderBookL2_25","action":"insert","data":[{"symbol":"XBTUSDT","id":32402489099,"side":"Sell","size":20000,"price":66814.8,"timestamp":"2024-05-18T15:46:08.524Z"},{"symbol":"XBTUSDT","id":32402489038,"side":"Sell","size":64000,"price":66812.2,"timestamp":"2024-05-18T15:46:08.524Z"},{"symbol":"XBTUSDT","id":32402489152,"side":"Sell","size":1000,"price":66820.8,"timestamp":"2024-05-18T15:46:08.524Z"},{"symbol":"XBTUSDT","id":32402489035,"side":"Sell","size":214000,"price":66808.6,"timestamp":"2024-05-18T15:46:08.524Z"},{"symbol":"XBTUSDT","id":32402489159,"side":"Sell","size":1000,"price":66820.9,"timestamp":"2024-05-18T15:46:08.524Z"},{"symbol":"XBTUSDT","id":32402489107,"side":"Sell","size":101000,"price":66807.6,"timestamp":"2024-05-18T15:46:08.524Z"},{"symbol":"XBTUSDT","id":32402488982,"side":"Sell","size":352000,"price":66809.9,"timestamp":"2024-05-18T15:46:08.524Z"},{"symbol":"XBTUSDT","id":32402489102,"side":"Buy","size":20000,"price":66782.9,"timestamp":"2024-05-18T15:46:08.524Z"},{"symbol":"XBTUSDT","id":32402489089,"side":"Buy","size":8000,"price":66787.9,"timestamp":"2024-05-18T15:46:08.524Z"},{"symbol":"XBTUSDT","id":32402489150,"side":"Buy","size":100000,"price":66772.6,"timestamp":"2024-05-18T15:46:08.524Z"},{"symbol":"XBTUSDT","id":32402489130,"side":"Buy","size":415000,"price":66768.0,"timestamp":"2024-05-18T15:46:08.524Z"}]}
{"table":"orderBookL2_25","action":"delete","data":[{"symbol":"ETHUSDT","id":32402488556,"side":"Sell","price":3110.45,"timestamp":"2024-05-18T15:46:08.525Z"},{"symbol":"ETHUSDT","id":32402467535,"side":"Sell","price":3112.14,"timestamp":"2024-05-18T15:46:08.525Z"},{"symbol":"ETHUSDT","id":32402486135,"side":"Sell","price":3110.46,"timestamp":"2024-05-18T15:46:08.525Z"},{"symbol":"ETHUSDT","id":32402488035,"side":"Buy","price":3109.00,"timestamp":"2024-05-18T15:46:08.525Z"},{"symbol":"ETHUSDT","id":32402482596,"side":"Buy","price":3109.67,"timestamp":"2024-05-18T15:46:08.525Z"},{"symbol":"ETHUSDT","id":32402488476,"side":"Buy","price":3108.96,"timestamp":"2024-05-18T15:46:08.525Z"}]}
{"table":"orderBookL2_25","action":"update","data":[{"symbol":"ETHUSDT","id":32402488551,"side":"Sell","size":109000,"price":3110.13,"timestamp":"2024-05-18T15:46:08.525Z"},{"symbol":"ETHUSDT","id":32402461791,"side":"Sell","size":989000,"price":3112.06,"timestamp":"2024-05-18T15:46:08.525Z"}]}
{"table":"orderBookL2_25","action":"insert","data":[{"symbol":"ETHUSDT","id":32402488916,"side":"Sell","size":64000,"price":3111.64,"timestamp":"2024-05-18T15:46:08.525Z"},{"symbol":"ETHUSDT","id":32402488868,"side":"Sell","size":81000,"price":3110.12,"timestamp":"2024-05-18T15:46:08.525Z"},{"symbol":"ETHUSDT","id":32402488923,"side":"Sell","size":100000,"price":3110.11,"timestamp":"2024-05-18T15:46:08.525Z"},{"symbol":"ETHUSDT","id":32402488918,"side":"Buy","size":192000,"price":3108.96,"timestamp":"2024-05-18T15:46:08.525Z"},{"symbol":"ETHUSDT","id":32402480382,"side":"Buy","size":100000,"price":3107.24,"timestamp":"2024-05-18T15:46:08.525Z"},{"symbol":"ETHUSDT","id":32402488018,"side":"Buy","size":1620000,"price":3107.17,"timestamp":"2024-05-18T15:46:08.525Z"}]}
{"table":"orderBookL2_25","action":"delete","data":[{"symbol":"XBTUSDT","id":32402489099,"side":"Sell","price":66814.8,"timestamp":"2024-05-18T15:46:08.573Z"},{"symbol":"XBTUSDT","id":32402489159,"side":"Sell","price":66820.9,"timestamp":"2024-05-18T15:46:08.573Z"},{"symbol":"XBTUSDT","id":32402488659,"side":"Sell","price":66814.9,"timestamp":"2024-05-18T15:46:08.573Z"},{"symbol":"XBTUSDT","id":32402489152,"side":"Sell","price":66820.8,"timestamp":"2024-05-18T15:46:08.573Z"},{"symbol":"XBTUSDT","id":32402481962,"side":"Sell","price":66807.7,"timestamp":"2024-05-18T15:46:08.573Z"},{"symbol":"XBTUSDT","id":32402488170,"side":"Sell","price":66815.2,"timestamp":"2024-05-18T15:46:08.573Z"},{"symbol":"XBTUSDT","id":32402489107,"side":"Sell","price":66807.6,"timestamp":"2024-05-18T15:46:08.573Z"},{"symbol":"XBTUSDT","id":32402360485,"side":"Buy","price":66764.4,"timestamp":"2024-05-18T15:46:08.573Z"},{"symbol":"XBTUSDT","id":32402488657,"side":"Buy","price":66783.0,"timestamp":"2024-05-18T15:46:08.573Z"},{"symbol":"XBTUSDT","id":32402489130,"side":"Buy","price":66768.0,"timestamp":"2024-05-18T15:46:08.573Z"},{"symbol":"XBTUSDT","id":32402480326,"side":"Buy","price":66788.2,"timestamp":"2024-05-18T15:46:08.573Z"},{"symbol":"XBTUSDT","id":32402489102,"side":"Buy","price":66782.9,"timestamp":"2024-05-18T15:46:08.573Z"}]}
{"table":"orderBookL2_25","action":"update","data":[{"symbol":"XBTUSDT","id":32402471671,"side":"Sell","size":74000,"price":66821.7,"timestamp":"2024-05-18T15:46:08.573Z"},{"symbol":"XBTUSDT","id":32402242406,"side":"Sell","size":138000,"price":66822.2,"timestamp":"2024-05-18T15:46:08.573Z"},{"symbol":"XBTUSDT","id":32402156627,"side":"Buy","size":100000,"price":66782.8,"timestamp":"2024-05-18T15:46:08.573Z"}]}
{"table":"orderBookL2_25","action":"insert","data":[{"symbol":"XBTUSDT","id":32402489322,"side":"Sell","size":1000,"price":66816.9,"timestamp":"2024-05-18T15:46:08.573Z"},{"symbol":"XBTUSDT","id":32402489186,"side":"Sell","size":157000,"price":66807.5,"timestamp":"2024-05-18T15:46:08.573Z"},{"symbol":"XBTUSDT","id":32402489309,"side":"Sell","size":20000,"price":66811.2,"timestamp":"2024-05-18T15:46:08.573Z"},{"symbol":"XBTUSDT","id":32402489216,"side":"Sell","size":101000,"price":66807.4,"timestamp":"2024-05-18T15:46:08.573Z"},{"symbol":"XBTUSDT","id":32402489246,"side":"Sell","size":2000,"price":66819.5,"timestamp":"2024-05-18T15:46:08.573Z"},{"symbol":"XBTUSDT","id":32402489318,"side":"Sell","size":20000,"price":66811.3,"timestamp":"2024-05-18T15:46:08.573Z"},{"symbol":"XBTUSDT","id":32402489315,"side":"Sell","size":1000,"price":66816.8,"timestamp":"2024-05-18T15:46:08.573Z"},{"symbol":"XBTUSDT","id":32402489266,"side":"Buy","size":35000,"price":66786.5,"timestamp":"2024-05-18T15:46:08.573Z"},{"symbol":"XBTUSDT","id":32402489293,"side":"Buy","size":20000,"price":66782.4,"timestamp":"2024-05-18T15:46:08.573Z"},{"symbol":"XBTUSDT","id":32402489350,"side":"Buy","size":20000,"price":66800.8,"timestamp":"2024-05-18T15:46:08.573Z"},{"symbol":"XBTUSDT","id":32402489320,"side":"Buy","size":350000,"price":66775.1,"timestamp":"2024-05-18T15:46:08.573Z"},{"symbol":"XBTUSDT","id":32402489311,"side":"Buy","size":20000,"price":66782.3,"timestamp":"2024-05-18T15:46:08.573Z"}]}
{"table":"orderBookL2_25","action":"delete","data":[{"symbol":"ETHUSDT","id":32402461791,"side":"Sell","price":3112.06,"timestamp":"2024-05-18T15:46:08.574Z"},{"symbol":"ETHUSDT","id":32402488612,"side":"Sell","price":3110.97,"timestamp":"2024-05-18T15:46:08.574Z"},{"symbol":"ETHUSDT","id":32402455680,"side":"Sell","price":3112.02,"timestamp":"2024-05-18T15:46:08.574Z"},{"symbol":"ETHUSDT","id":32402488531,"side":"Sell","price":3110.96,"timestamp":"2024-05-18T15:46:08.574Z"},{"symbol":"ETHUSDT","id":32402480382,"side":"Buy","price":3107.24,"timestamp":"2024-05-18T15:46:08.574Z"},{"symbol":"ETHUSDT","id":32402488622,"side":"Buy","price":3109.64,"timestamp":"2024-05-18T15:46:08.574Z"},{"symbol":"ETHUSDT","id":32402488018,"side":"Buy","price":3107.17,"timestamp":"2024-05-18T15:46:08.574Z"},{"symbol":"ETHUSDT","id":32402488583,"side":"Buy","price":3109.65,"timestamp":"2024-05-18T15:46:08.574Z"},{"symbol":"ETHUSDT","id":32402488484,"side":"Buy","price":3109.41,"timestamp":"2024-05-18T15:46:08.574Z"}]}
{"table":"orderBookL2_25","action":"update","data":[{"symbol":"ETHUSDT","id":32402487998,"side":"Sell","size":100000,"price":3110.94,"timestamp":"2024-05-18T15:46:08.574Z"},{"symbol":"ETHUSDT","id":32402488551,"side":"Sell","size":100000,"price":3110.13,"timestamp":"2024-05-18T15:46:08.574Z"},{"symbol":"ETHUSDT","id":32402488923,"side":"Sell","size":109000,"price":3110.11,"timestamp":"2024-05-18T15:46:08.574Z"},{"symbol":"ETHUSDT","id":32401945550,"side":"Buy","size":1000,"price":3109.40,"timestamp":"2024-05-18T15:46:08.574Z"}]}
{"table":"orderBookL2_25","action":"insert","data":[{"symbol":"ETHUSDT","id":32402489171,"side":"Sell","size":100000,"price":3110.75,"timestamp":"2024-05-18T15:46:08.574Z"},{"symbol":"ETHUSDT","id":32402489302,"side":"Sell","size":32000,"price":3110.89,"timestamp":"2024-05-18T15:46:08.574Z"},{"symbol":"ETHUSDT","id":32402489360,"side":"Sell","size":32000,"price":3110.91,"timestamp":"2024-05-18T15:46:08.574Z"},{"symbol":"ETHUSDT","id":32402489313,"side":"Sell","size":66000,"price":3110.88,"timestamp":"2024-05-18T15:46:08.574Z"},{"symbol":"ETHUSDT","id":32402489343,"side":"Buy","size":32000,"price":3109.62,"timestamp":"2024-05-18T15:46:08.574Z"},{"symbol":"ETHUSDT","id":32402489336,"side":"Buy","size":1000,"price":3109.36,"timestamp":"2024-05-18T15:46:08.574Z"},{"symbol":"ETHUSDT","id":32402489332,"side":"Buy","size":48000,"price":3109.83,"timestamp":"2024-05-18T15:46:08.574Z"},{"symbol":"ETHUSDT","id":32402489340,"side":"Buy","size":1000,"price":3109.37,"timestamp":"2024-05-18T15:46:08.574Z"},{"symbol":"ETHUSDT","id":32402489357,"side":"Buy","size":32000,"price":3109.63,"timestamp":"2024-05-18T15:46:08.574Z"}]}
{"table":"orderBookL2_25","action":"delete","data":[{"symbol":"XBTUSDT","id":32402489309,"side":"Sell","price":66811.2,"timestamp":"2024-05-18T15:46:08.622Z"},{"symbol":"XBTUSDT","id":32402489322,"side":"Sell","price":66816.9,"timestamp":"2024-05-18T15:46:08.622Z"},{"symbol":"XBTUSDT","id":32402489246,"side":"Sell","price":66819.5,"timestamp":"2024-05-18T15:46:08.622Z"},{"symbol":"XBTUSDT","id":32402489318,"side":"Sell","price":66811.3,"timestamp":"2024-05-18T15:46:08.622Z"},{"symbol":"XBTUSDT","id":32402489315,"side":"Sell","price":66816.8,"timestamp":"2024-05-18T15:46:08.622Z"},{"symbol":"XBTUSDT","id":32402488982,"side":"Sell","price":66809.9,"timestamp":"2024-05-18T15:46:08.622Z"},{"symbol":"XBTUSDT","id":32402489293,"side":"Buy","price":66782.4,"timestamp":"2024-05-18T15:46:08.622Z"},{"symbol":"XBTUSDT","id":32402489320,"side":"Buy","price":66775.1,"timestamp":"2024-05-18T15:46:08.622Z"},{"symbol":"XBTUSDT","id":32402489311,"side":"Buy","price":66782.3,"timestamp":"2024-05-18T15:46:08.622Z"}]}
{"table":"orderBookL2_25","action":"update","data":[{"symbol":"XBTUSDT","id":32402242406,"side":"Sell","size":138000,"price":66822.2,"timestamp":"2024-05-18T15:46:08.622Z"},{"symbol":"XBTUSDT","id":32402489035,"side":"Sell","size":351000,"price":66808.6,"timestamp":"2024-05-18T15:46:08.622Z"},{"symbol":"XBTUSDT","id":32402480644,"side":"Buy","size":230000,"price":66784.4,"timestamp":"2024-05-18T15:46:08.622Z"}]}
{"table":"orderBookL2_25","action":"insert","data":[{"symbol":"XBTUSDT","id":32402489445,"side":"Sell","size":20000,"price":66809.9,"timestamp":"2024-05-18T15:46:08.622Z"},{"symbol":"XBTUSDT","id":32402489427,"side":"Sell","size":2000,"price":66807.3,"timestamp":"2024-05-18T15:46:08.622Z"},{"symbol":"XBTUSDT","id":32402489362,"side":"Sell","size":1000,"price":66816.0,"timestamp":"2024-05-18T15:46:08.622Z"},{"symbol":"XBTUSDT","id":32402489377,"side":"Sell","size":1000,"price":66815.9,"timestamp":"2024-05-18T15:46:08.622Z"},{"symbol":"XBTUSDT","id":32402489452,"side":"Sell","size":212000,"price":66808.5,"timestamp":"2024-05-18T15:46:08.622Z"},{"symbol":"XBTUSDT","id":32402489449,"side":"Sell","size":20000,"price":66809.8,"timestamp":"2024-05-18T15:46:08.622Z"},{"symbol":"XBTUSDT","id":32402489447,"side":"Buy","size":415000,"price":66768.0,"timestamp":"2024-05-18T15:46:08.622Z"},{"symbol":"XBTUSDT","id":32402489412,"side":"Buy","size":20000,"price":66780.8,"timestamp":"2024-05-18T15:46:08.622Z"},{"symbol":"XBTUSDT","id":32402489414,"side":"Buy","size":20000,"price":66780.7,"timestamp":"2024-05-18T15:46:08.622Z"}]}
{"table":"orderBookL2_25","action":"delete","data":[{"symbol":"ETHUSDT","id":32402489302,"side":"Sell","price":3110.89,"timestamp":"2024-05-18T15:46:08.623Z"},{"symbol":"ETHUSDT","id":32402458908,"side":"Buy","price":3107.30,"timestamp":"2024-05-18T15:46:08.623Z"},{"symbol":"ETHUSDT","id":32402489357,"side":"Buy","price":3109.63,"timestamp":"2024-05-18T15:46:08.623Z"},{"symbol":"ETHUSDT","id":32402489332,"side":"Buy","price":3109.83,"timestamp":"2024-05-18T15:46:08.623Z"},{"symbol":"ETHUSDT","id":32402488918,"side":"Buy","price":3108.96,"timestamp":"2024-05-18T15:46:08.623Z"}]}
{"table":"orderBookL2_25","action":"update","data":[{"symbol":"ETHUSDT","id":32402400155,"side":"Buy","size":17414000,"price":3107.38,"timestamp":"2024-05-18T15:46:08.623Z"}]}
{"table":"orderBookL2_25","action":"insert","data":[{"symbol":"ETHUSDT","id":32402489405,"side":"Sell","size":32000,"price":3110.92,"timestamp":"2024-05-18T15:46:08.623Z"},{"symbol":"ETHUSDT","id":32402489457,"side":"Buy","size":100000,"price":3108.98,"timestamp":"2024-05-18T15:46:08.623Z"},{"symbol":"ETHUSDT","id":32402489460,"side":"Buy","size":67000,"price":3108.99,"timestamp":"2024-05-18T15:46:08.623Z"},{"symbol":"ETHUSDT","id":32402489369,"side":"Buy","size":43000,"price":3110.09,"timestamp":"2024-05-18T15:46:08.623Z"},{"symbol":"ETHUSDT","id":32402489408,"side":"Buy","size":32000,"price":3109.61,"timestamp":"2024-05-18T15:46:08.623Z"}]}
{"table":"orderBookL2_25","action":"update","data":[{"symbol":"XBTETH","id":32402423004,"side":"Buy","size":5,"price":21.227,"timestamp":"2024-05-18T15:46:08.662Z"}]}
{"table":"orderBookL2_25","action":"delete","data":[{"symbol":"XBTUSDT","id":32402482479,"side":"Buy","price":66787.8,"timestamp":"2024-05-18T15:46:08.671Z"},{"symbol":"XBTUSDT","id":32402486415,"side":"Buy","price":66798.0,"timestamp":"2024-05-18T15:46:08.671Z"}]}
{"table":"orderBookL2_25","action":"insert","data":[{"symbol":"XBTUSDT","id":32402360485,"side":"Buy","size":100000,"price":66764.4,"timestamp":"2024-05-18T15:46:08.671Z"},{"symbol":"XBTUSDT","id":32402362888,"side":"Buy","size":543000,"price":66762.2,"timestamp":"2024-05-18T15:46:08.671Z"}]}
{"table":"orderBookL2_25","action":"delete","data":[{"symbol":"ETHUSDT","id":32402488868,"side":"Sell","price":3110.12,"timestamp":"2024-05-18T15:46:08.672Z"},{"symbol":"ETHUSDT","id":32402488551,"side":"Sell","price":3110.13,"timestamp":"2024-05-18T15:46:08.672Z"},{"symbol":"ETHUSDT","id":32402457345,"side":"Buy","price":3110.10,"timestamp":"2024-05-18T15:46:08.672Z"}]}
{"table":"orderBookL2_25","action":"update","data":[{"symbol":"ETHUSDT","id":32402486025,"side":"Sell","size":337000,"price":3111.72,"timestamp":"2024-05-18T15:46:08.672Z"}]}
{"table":"orderBookL2_25","action":"insert","data":[{"symbol":"ETHUSDT","id":32402455680,"side":"Sell","size":100000,"price":3112.02,"timestamp":"2024-05-18T15:46:08.672Z"},{"symbol":"ETHUSDT","id":32402489501,"side":"Sell","size":214000,"price":3110.10,"timestamp":"2024-05-18T15:46:08.672Z"},{"symbol":"ETHUSDT","id":32402458908,"side":"Buy","size":1114000,"price":3107.30,"timestamp":"2024-05-18T15:46:08.672Z"}]}
{"table":"orderBookL2_25","action":"update","data":[{"symbol":"XBTETH","id":32402423015,"side":"Sell","size":5,"price":21.786,"timestamp":"2024-05-18T15:46:08.712Z"}]}
{"table":"orderBookL2_25","action":"delete","data":[{"symbol":"XBTUSDT","id":32402489035,"side":"Sell","price":66808.6,"timestamp":"2024-05-18T15:46:08.720Z"},{"symbol":"XBTUSDT","id":32402242406,"side":"Sell","price":66822.2,"timestamp":"2024-05-18T15:46:08.720Z"},{"symbol":"XBTUSDT","id":32402489452,"side":"Sell","price":66808.5,"timestamp":"2024-05-18T15:46:08.720Z"},{"symbol":"XBTUSDT","id":32402489447,"side":"Buy","price":66768.0,"timestamp":"2024-05-18T15:46:08.720Z"}]}
{"table":"orderBookL2_25","action":"update","data":[{"symbol":"XBTUSDT","id":32402489216,"side":"Sell","size":199000,"price":66807.4,"timestamp":"2024-05-18T15:46:08.720Z"}]}
{"table":"orderBookL2_25","action":"insert","data":[{"symbol":"XBTUSDT","id":32402489645,"side":"Sell","size":2000,"price":66819.5,"timestamp":"2024-05-18T15:46:08.720Z"},{"symbol":"XBTUSDT","id":32402489609,"side":"Sell","size":348000,"price":66807.8,"timestamp":"2024-05-18T15:46:08.720Z"},{"symbol":"XBTUSDT","id":32402489616,"side":"Sell","size":15000,"price":66809.7,"timestamp":"2024-05-18T15:46:08.720Z"},{"symbol":"XBTUSDT","id":32402489611,"side":"Buy","size":363000,"price":66772.7,"timestamp":"2024-05-18T15:46:08.720Z"}]}
{"table":"orderBookL2_25","action":"delete","data":[{"symbol":"ETHUSDT","id":32402489405,"side":"Sell","price":3110.92,"timestamp":"2024-05-18T15:46:08.721Z"},{"symbol":"ETHUSDT","id":32402489343,"side":"Buy","price":3109.62,"timestamp":"2024-05-18T15:46:08.721Z"}]}
{"table":"orderBookL2_25","action":"update","data":[{"symbol":"ETHUSDT","id":32402489501,"side":"Sell","size":223000,"price":3110.10,"timestamp":"2024-05-18T15:46:08.721Z"},{"symbol":"ETHUSDT","id":32402488923,"side":"Sell","size":100000,"price":3110.11,"timestamp":"2024-05-18T15:46:08.721Z"}]}
{"table":"orderBookL2_25","action":"insert","data":[{"symbol":"ETHUSDT","id":32402489604,"side":"Sell","size":32000,"price":3110.90,"timestamp":"2024-05-18T15:46:08.721Z"},{"symbol":"ETHUSDT","id":32402489607,"side":"Buy","size":32000,"price":3109.60,"timestamp":"2024-05-18T15:46:08.721Z"}]}
{"table":"orderBookL2_25","action":"delete","data":[{"symbol":"XBTUSDT","id":32402489645,"side":"Sell","price":66819.5,"timestamp":"2024-05-18T15:46:08.769Z"},{"symbol":"XBTUSDT","id":32402489377,"side":"Sell","price":66815.9,"timestamp":"2024-05-18T15:46:08.769Z"}]}
{"table":"orderBookL2_25","action":"insert","data":[{"symbol":"XBTUSDT","id":32402489685,"side":"Sell","size":1000,"price":66816.1,"timestamp":"2024-05-18T15:46:08.769Z"},{"symbol":"XBTUSDT","id":32402242406,"side":"Sell","size":138000,"price":66822.2,"timestamp":"2024-05-18T15:46:08.769Z"}]}
{"table":"orderBookL2_25","action":"delete","data":[{"symbol":"ETHUSDT","id":32402489336,"side":"Buy","price":3109.36,"timestamp":"2024-05-18T15:46:08.770Z"},{"symbol":"ETHUSDT","id":32402489340,"side":"Buy","price":3109.37,"timestamp":"2024-05-18T15:46:08.770Z"}]}
{"table":"orderBookL2_25","action":"insert","data":[{"symbol":"ETHUSDT","id":32402489653,"side":"Buy","size":1000,"price":3109.35,"timestamp":"2024-05-18T15:46:08.770Z"},{"symbol":"ETHUSDT","id":32402489698,"side":"Buy","size":1000,"price":3109.34,"timestamp":"2024-05-18T15:46:08.770Z"}]}
{"table":"orderBookL2_25","action":"delete","data":[{"symbol":"ETHUSDT","id":32402458908,"side":"Buy","price":3107.30,"timestamp":"2024-05-18T15:46:08.819Z"}]}
{"table":"orderBookL2_25","action":"insert","data":[{"symbol":"ETHUSDT","id":32402489700,"side":"Buy","size":49000,"price":3109.62,"timestamp":"2024-05-18T15:46:08.819Z"}]}
{"table":"orderBookL2_25","action":"delete","data":[{"symbol":"XBTUSDT","id":32402362888,"side":"Buy","price":66762.2,"timestamp":"2024-05-18T15:46:08.827Z"}]}
{"table":"orderBookL2_25","action":"insert","data":[{"symbol":"XBTUSDT","id":32402489758,"side":"Buy","size":8000,"price":66786.6,"timestamp":"2024-05-18T15:46:08.827Z"}]}
{"table":"orderBookL2_25","action":"delete","data":[{"symbol":"XBTUSDT","id":32402242406,"side":"Sell","price":66822.2,"timestamp":"2024-05-18T15:46:08.876Z"},{"symbol":"XBTUSDT","id":32402471671,"side":"Sell","price":66821.7,"timestamp":"2024-05-18T15:46:08.876Z"},{"symbol":"XBTUSDT","id":32402360485,"side":"Buy","price":66764.4,"timestamp":"2024-05-18T15:46:08.876Z"}]}
{"table":"orderBookL2_25","action":"update","data":[{"symbol":"XBTUSDT","id":32402489186,"side":"Sell","size":2000,"price":66807.5,"timestamp":"2024-05-18T15:46:08.876Z"},{"symbol":"XBTUSDT","id":32402480644,"side":"Buy","size":2000,"price":66784.4,"timestamp":"2024-05-18T15:46:08.876Z"}]}
{"table":"orderBookL2_25","action":"insert","data":[{"symbol":"XBTUSDT","id":32402489787,"side":"Sell","size":98000,"price":66805.1,"timestamp":"2024-05-18T15:46:08.876Z"},{"symbol":"XBTUSDT","id":32402489767,"side":"Sell","size":155000,"price":66805.2,"timestamp":"2024-05-18T15:46:08.876Z"},{"symbol":"XBTUSDT","id":32402489763,"side":"Buy","size":30000,"price":66780.9,"timestamp":"2024-05-18T15:46:08.876Z"}]}
{"table":"orderBookL2_25","action":"delete","data":[{"symbol":"XBTUSDT","id":32402484922,"side":"Buy","price":66765.2,"timestamp":"2024-05-18T15:46:08.925Z"}]}
{"table":"orderBookL2_25","action":"insert","data":[{"symbol":"XBTUSDT","id":32402489843,"side":"Buy","size":100000,"price":66788.2,"timestamp":"2024-05-18T15:46:08.925Z"}]}
{"table":"orderBookL2_25","action":"delete","data":[{"symbol":"ETHUSDT","id":32402489360,"side":"Sell","price":3110.91,"timestamp":"2024-05-18T15:46:08.935Z"}]}
{"table":"orderBookL2_25","action":"insert","data":[{"symbol":"ETHUSDT","id":32402489848,"side":"Sell","size":32000,"price":3110.89,"timestamp":"2024-05-18T15:46:08.935Z"}]}
{"table":"orderBookL2_25","action":"delete","data":[{"symbol":"XBTUSDT","id":32402489685,"side":"Sell","price":66816.1,"timestamp":"2024-05-18T15:46:08.974Z"}]}
{"table":"orderBookL2_25","action":"update","data":[{"symbol":"XBTUSDT","id":32402462668,"side":"Sell","size":360000,"price":66801.9,"timestamp":"2024-05-18T15:46:08.974Z"}]}
{"table":"orderBookL2_25","action":"insert","data":[{"symbol":"XBTUSDT","id":32402489893,"side":"Sell","size":1000,"price":66815.9,"timestamp":"2024-05-18T15:46:08.974Z"}]}
{"table":"orderBookL2_25","action":"delete","data":[{"symbol":"ETHUSDT","id":32402489604,"side":"Sell","price":3110.90,"timestamp":"2024-05-18T15:46:08.984Z"},{"symbol":"ETHUSDT","id":32402489607,"side":"Buy","price":3109.60,"timestamp":"2024-05-18T15:46:08.984Z"},{"symbol":"ETHUSDT","id":32402489408,"side":"Buy","price":3109.61,"timestamp":"2024-05-18T15:46:08.984Z"}]}
{"table":"orderBookL2_25","action":"update","data":[{"symbol":"ETHUSDT","id":32402489313,"side":"Sell","size":66000,"price":3110.88,"timestamp":"2024-05-18T15:46:08.984Z"}]}
{"table":"orderBookL2_25","action":"insert","data":[{"symbol":"ETHUSDT","id":32402489900,"side":"Sell","size":32000,"price":3110.90,"timestamp":"2024-05-18T15:46:08.984Z"},{"symbol":"ETHUSDT","id":32402489852,"side":"Buy","size":32000,"price":3109.59,"timestamp":"2024-05-18T15:46:08.984Z"},{"symbol":"ETHUSDT","id":32402489897,"side":"Buy","size":32000,"price":3109.60,"timestamp":"2024-05-18T15:46:08.984Z"}]}
{"table":"orderBookL2_25","action":"delete","data":[{"symbol":"XBTUSDT","id":32402489609,"side":"Sell","price":66807.8,"timestamp":"2024-05-18T15:46:09.027Z"}]}
{"table":"orderBookL2_25","action":"insert","data":[{"symbol":"XBTUSDT","id":32402489941,"side":"Sell","size":356000,"price":66809.6,"timestamp":"2024-05-18T15:46:09.027Z"}]}
{"table":"orderBookL2_25","action":"delete","data":[{"symbol":"XBTUSDT","id":32402489216,"side":"Sell","price":66807.4,"timestamp":"2024-05-18T15:46:09.076Z"},{"symbol":"XBTUSDT","id":32402489941,"side":"Sell","price":66809.6,"timestamp":"2024-05-18T15:46:09.076Z"},{"symbol":"XBTUSDT","id":32402489616,"side":"Sell","price":66809.7,"timestamp":"2024-05-18T15:46:09.076Z"},{"symbol":"XBTUSDT","id":32402363228,"side":"Buy","price":66766.1,"timestamp":"2024-05-18T15:46:09.076Z"},{"symbol":"XBTUSDT","id":32402489611,"side":"Buy","price":66772.7,"timestamp":"2024-05-18T15:46:09.076Z"}]}
{"table":"orderBookL2_25","action":"update","data":[{"symbol":"XBTUSDT","id":32402476497,"side":"Sell","size":50000,"price":66821.6,"timestamp":"2024-05-18T15:46:09.076Z"}]}
{"table":"orderBookL2_25","action":"insert","data":[{"symbol":"XBTUSDT","id":32402489956,"side":"Sell","size":219000,"price":66808.5,"timestamp":"2024-05-18T15:46:09.076Z"},{"symbol":"XBTUSDT","id":32402471671,"side":"Sell","size":74000,"price":66821.7,"timestamp":"2024-05-18T15:46:09.076Z"},{"symbol":"XBTUSDT","id":32402489947,"side":"Sell","size":351000,"price":66808.6,"timestamp":"2024-05-18T15:46:09.076Z"},{"symbol":"XBTUSDT","id":32402489986,"side":"Buy","size":22000,"price":66786.8,"timestamp":"2024-05-18T15:46:09.076Z"},{"symbol":"XBTUSDT","id":32402489954,"side":"Buy","size":368000,"price":66772.7,"timestamp":"2024-05-18T15:46:09.076Z"}]}
{"table":"orderBookL2_25","action":"delete","data":[{"symbol":"ETHUSDT","id":32402489852,"side":"Buy","price":3109.59,"timestamp":"2024-05-18T15:46:09.077Z"}]}
{"table":"orderBookL2_25","action":"insert","data":[{"symbol":"ETHUSDT","id":32402489997,"side":"Buy","size":32000,"price":3109.61,"timestamp":"2024-05-18T15:46:09.077Z"}]}
{"table":"orderBookL2_25","action":"delete","data":[{"symbol":"ETHUSDT","id":32402489900,"side":"Sell","price":3110.90,"timestamp":"2024-05-18T15:46:09.127Z"},{"symbol":"ETHUSDT","id":32402489997,"side":"Buy","price":3109.61,"timestamp":"2024-05-18T15:46:09.127Z"}]}
{"table":"orderBookL2_25","action":"update","data":[{"symbol":"ETHUSDT","id":32402489313,"side":"Sell","size":66000,"price":3110.88,"timestamp":"2024-05-18T15:46:09.127Z"}]}
{"table":"orderBookL2_25","action":"insert","data":[{"symbol":"ETHUSDT","id":32402490013,"side":"Sell","size":32000,"price":3110.90,"timestamp":"2024-05-18T15:46:09.127Z"},{"symbol":"ETHUSDT","id":32402490011,"side":"Buy","size":32000,"price":3109.59,"timestamp":"2024-05-18T15:46:09.127Z"}]}
{"table":"orderBookL2_25","action":"delete","data":[{"symbol":"ETHUSDT","id":32402489698,"side":"Buy","price":3109.34,"timestamp":"2024-05-18T15:46:09.252Z"}]}
{"table":"orderBookL2_25","action":"insert","data":[{"symbol":"ETHUSDT","id":32402490171,"side":"Buy","size":1000,"price":3109.38,"timestamp":"2024-05-18T15:46:09.252Z"}]}
{"table":"orderBookL2_25","action":"delete","data":[{"symbol":"XBTUSDT","id":32402489362,"side":"Sell","price":66816.0,"timestamp":"2024-05-18T15:46:09.254Z"}]}
{"table":"orderBookL2_25","action":"insert","data":[{"symbol":"XBTUSDT","id":32402490173,"side":"Sell","size":1000,"price":66815.8,"timestamp":"2024-05-18T15:46:09.254Z"}]}
{"table":"orderBookL2_25","action":"delete","data":[{"symbol":"ETHUSDT","id":32402489848,"side":"Sell","price":3110.89,"timestamp":"2024-05-18T15:46:09.302Z"},{"symbol":"ETHUSDT","id":32402490013,"side":"Sell","price":3110.90,"timestamp":"2024-05-18T15:46:09.302Z"},{"symbol":"ETHUSDT","id":32402490171,"side":"Buy","price":3109.38,"timestamp":"2024-05-18T15:46:09.302Z"},{"symbol":"ETHUSDT","id":32402489653,"side":"Buy","price":3109.35,"timestamp":"2024-05-18T15:46:09.302Z"},{"symbol":"ETHUSDT","id":32402490011,"side":"Buy","price":3109.59,"timestamp":"2024-05-18T15:46:09.302Z"},{"symbol":"ETHUSDT","id":32402489897,"side":"Buy","price":3109.60,"timestamp":"2024-05-18T15:46:09.302Z"}]}
{"table":"orderBookL2_25","action":"update","data":[{"symbol":"ETHUSDT","id":32402489313,"side":"Sell","size":98000,"price":3110.88,"timestamp":"2024-05-18T15:46:09.302Z"},{"symbol":"ETHUSDT","id":32402489700,"side":"Buy","size":81000,"price":3109.62,"timestamp":"2024-05-18T15:46:09.302Z"}]}
{"table":"orderBookL2_25","action":"insert","data":[{"symbol":"ETHUSDT","id":32402490185,"side":"Sell","size":32000,"price":3110.87,"timestamp":"2024-05-18T15:46:09.302Z"},{"symbol":"ETHUSDT","id":32402461791,"side":"Sell","size":989000,"price":3112.06,"timestamp":"2024-05-18T15:46:09.302Z"},{"symbol":"ETHUSDT","id":32402490178,"side":"Buy","size":1000,"price":3109.36,"timestamp":"2024-05-18T15:46:09.302Z"},{"symbol":"ETHUSDT","id":32402458908,"side":"Buy","size":1114000,"price":3107.30,"timestamp":"2024-05-18T15:46:09.302Z"},{"symbol":"ETHUSDT","id":32402490175,"side":"Buy","size":1000,"price":3109.37,"timestamp":"2024-05-18T15:46:09.302Z"},{"symbol":"ETHUSDT","id":32402490190,"side":"Buy","size":32000,"price":3109.61,"timestamp":"2024-05-18T15:46:09.302Z"}]}
{"table":"orderBookL2_25","action":"delete","data":[{"symbol":"XBTUSDT","id":32402489947,"side":"Sell","price":66808.6,"timestamp":"2024-05-18T15:46:09.303Z"},{"symbol":"XBTUSDT","id":32402489445,"side":"Sell","price":66809.9,"timestamp":"2024-05-18T15:46:09.303Z"},{"symbol":"XBTUSDT","id":32402489449,"side":"Sell","price":66809.8,"timestamp":"2024-05-18T15:46:09.303Z"},{"symbol":"XBTUSDT","id":32402489758,"side":"Buy","price":66786.6,"timestamp":"2024-05-18T15:46:09.303Z"},{"symbol":"XBTUSDT","id":32402489954,"side":"Buy","price":66772.7,"timestamp":"2024-05-18T15:46:09.303Z"}]}
{"table":"orderBookL2_25","action":"update","data":[{"symbol":"XBTUSDT","id":32402489956,"side":"Sell","size":216000,"price":66808.5,"timestamp":"2024-05-18T15:46:09.303Z"}]}
