{"channel":"book","type":"snapshot","data":[{"symbol":"AUD/USD","bids":[{"price":0.66446,"qty":5600.28887913},{"price":0.66445,"qty":3063.26424008},{"price":0.66433,"qty":1029.94271647},{"price":0.66432,"qty":5184.58590000},{"price":0.66378,"qty":23129.70653033},{"price":0.66377,"qty":458.79562936},{"price":0.66375,"qty":53001.00000000},{"price":0.66361,"qty":47002.00000000},{"price":0.66358,"qty":3003.00000000},{"price":0.66352,"qty":2804.00000000}],"asks":[{"price":0.66473,"qty":4887.54731976},{"price":0.66474,"qty":12212.66745688},{"price":0.66502,"qty":4258.83710000},{"price":0.66503,"qty":342.43142964},{"price":0.66528,"qty":466.07172610},{"price":0.66586,"qty":206.02937419},{"price":0.66587,"qty":26468.72040764},{"price":0.66588,"qty":10240.00000000},{"price":0.66597,"qty":2955.00000000},{"price":0.66622,"qty":262.66395977}],"checksum":2818164055}]}
{"channel":"book","type":"update","data":[{"symbol":"AUD/USD","bids":[{"price":0.66445,"qty":3006.20781915}],"asks":[],"checksum":4098523734,"timestamp":"2024-06-01T17:52:13.666235Z"}]}
{"channel":"book","type":"update","data":[{"symbol":"AUD/USD","bids":[{"price":0.66377,"qty":0.00000000},{"price":0.66346,"qty":2506.00000000}],"asks":[],"checksum":736842621,"timestamp":"2024-06-01T17:52:13.666270Z"}]}
{"channel":"book","type":"update","data":[{"symbol":"AUD/USD","bids":[{"price":0.66379,"qty":512.89680471}],"asks":[],"checksum":3847003572,"timestamp":"2024-06-01T17:52:13.670944Z"}]}
{"channel":"book","type":"update","data":[{"symbol":"AUD/USD","bids":[{"price":0.66447,"qty":30.06185226}],"asks":[],"checksum":254880272,"timestamp":"2024-06-01T17:52:13.671115Z"}]}
{"channel":"book","type":"update","data":[{"symbol":"AUD/USD","bids":[],"asks":[{"price":0.66559,"qty":5032.00000000}],"checksum":3118367863,"timestamp":"2024-06-01T17:52:13.983111Z"}]}
{"channel":"book","type":"update","data":[{"symbol":"AUD/USD","bids":[{"price":0.66445,"qty":0.00000000},{"price":0.66352,"qty":2804.00000000}],"asks":[],"checksum":589025524,"timestamp":"2024-06-01T17:52:14.184284Z"}]}
{"channel":"book","type":"update","data":[{"symbol":"AUD/USD","bids":[{"price":0.66447,"qty":2899.40750270}],"asks":[],"checksum":2931101790,"timestamp":"2024-06-01T17:52:14.186460Z"}]}
{"channel":"book","type":"update","data":[{"symbol":"AUD/USD","bids":[{"price":0.66446,"qty":0.00000000},{"price":0.66346,"qty":2506.00000000},{"price":0.66434,"qty":5601.30046155}],"asks":[],"checksum":3802454297,"timestamp":"2024-06-01T17:52:14.187571Z"}]}
{"channel":"book","type":"update","data":[{"symbol":"AUD/USD","bids":[{"price":0.66433,"qty":0.00000000},{"price":0.66346,"qty":2506.00000000}],"asks":[],"checksum":2067060011,"timestamp":"2024-06-01T17:52:14.194388Z"}]}
{"channel":"book","type":"update","data":[{"symbol":"AUD/USD","bids":[{"price":0.66435,"qty":1029.91169156}],"asks":[],"checksum":1677676559,"timestamp":"2024-06-01T17:52:14.194426Z"}]}
{"channel":"book","type":"update","data":[{"symbol":"AUD/USD","bids":[{"price":0.66434,"qty":0.00000000},{"price":0.66346,"qty":2506.00000000},{"price":0.66448,"qty":5600.12031758}],"asks":[],"checksum":2055816506,"timestamp":"2024-06-01T17:52:14.600745Z"}]}
{"channel":"book","type":"update","data":[{"symbol":"AUD/USD","bids":[{"price":0.66433,"qty":1029.94271647}],"asks":[],"checksum":447306030,"timestamp":"2024-06-01T17:52:14.610001Z"}]}
{"channel":"book","type":"update","data":[{"symbol":"AUD/USD","bids":[{"price":0.66435,"qty":0.00000000},{"price":0.66352,"qty":2804.00000000}],"asks":[],"checksum":383089030,"timestamp":"2024-06-01T17:52:14.610181Z"}]}
{"channel":"book","type":"update","data":[{"symbol":"AUD/USD","bids":[],"asks":[{"price":0.66587,"qty":0.00000000},{"price":0.66622,"qty":262.66395977}],"checksum":3375241816,"timestamp":"2024-06-01T17:52:15.229163Z"}]}
{"channel":"book","type":"update","data":[{"symbol":"AUD/USD","bids":[],"asks":[{"price":0.66558,"qty":23535.90633408}],"checksum":3727606954,"timestamp":"2024-06-01T17:52:15.230426Z"}]}
{"channel":"book","type":"update","data":[{"symbol":"AUD/USD","bids":[],"asks":[{"price":0.66546,"qty":72701.00000000}],"checksum":1110639011,"timestamp":"2024-06-01T17:52:15.405199Z"}]}
{"channel":"book","type":"update","data":[{"symbol":"AUD/USD","bids":[],"asks":[{"price":0.66553,"qty":3013.00000000}],"checksum":3867046194,"timestamp":"2024-06-01T17:52:15.453131Z"}]}
{"channel":"book","type":"update","data":[{"symbol":"AUD/USD","bids":[],"asks":[{"price":0.66474,"qty":0.00000000},{"price":0.66588,"qty":10240.00000000},{"price":0.66472,"qty":12212.66745688}],"checksum":2551836248,"timestamp":"2024-06-01T17:52:15.462187Z"}]}
{"channel":"book","type":"update","data":[{"symbol":"AUD/USD","bids":[],"asks":[{"price":0.66473,"qty":0.00000000},{"price":0.66588,"qty":10240.00000000},{"price":0.66471,"qty":4884.87143965}],"checksum":1694040273,"timestamp":"2024-06-01T17:52:15.472578Z"}]}
{"channel":"book","type":"update","data":[{"symbol":"AUD/USD","bids":[],"asks":[{"price":0.66586,"qty":0.00000000},{"price":0.66588,"qty":10240.00000000}],"checksum":4152522777,"timestamp":"2024-06-01T17:52:15.605546Z"}]}
{"channel":"book","type":"update","data":[{"symbol":"AUD/USD","bids":[],"asks":[{"price":0.66557,"qty":176.70145387}],"checksum":1098311047,"timestamp":"2024-06-01T17:52:15.607118Z"}]}
{"channel":"book","type":"update","data":[{"symbol":"AUD/USD","bids":[{"price":0.66447,"qty":2869.34565044}],"asks":[],"checksum":103183870,"timestamp":"2024-06-01T17:52:16.465218Z"}]}
{"channel":"book","type":"update","data":[{"symbol":"AUD/USD","bids":[{"price":0.66449,"qty":30.06185226}],"asks":[],"checksum":2922010765,"timestamp":"2024-06-01T17:52:16.469811Z"}]}
{"channel":"book","type":"update","data":[{"symbol":"AUD/USD","bids":[{"price":0.66447,"qty":0.00000000},{"price":0.66352,"qty":2804.00000000}],"asks":[],"checksum":1628673431,"timestamp":"2024-06-01T17:52:17.715230Z"}]}
{"channel":"book","type":"update","data":[{"symbol":"AUD/USD","bids":[{"price":0.66378,"qty":0.00000000},{"price":0.66346,"qty":2506.00000000}],"asks":[],"checksum":548679562,"timestamp":"2024-06-01T17:52:17.715384Z"}]}
{"channel":"book","type":"update","data":[{"symbol":"AUD/USD","bids":[{"price":0.66448,"qty":0.00000000},{"price":0.66345,"qty":505.00000000},{"price":0.66434,"qty":5601.30046155}],"asks":[],"checksum":703166285,"timestamp":"2024-06-01T17:52:17.718286Z"}]}
{"channel":"book","type":"update","data":[{"symbol":"AUD/USD","bids":[{"price":0.66380,"qty":11765.38662357}],"asks":[],"checksum":1830209627,"timestamp":"2024-06-01T17:52:17.720424Z"}]}
{"channel":"book","type":"update","data":[{"symbol":"AUD/USD","bids":[{"price":0.66376,"qty":13125.93737831}],"asks":[],"checksum":2826945715,"timestamp":"2024-06-01T17:52:17.720518Z"}]}
{"channel":"book","type":"update","data":[{"symbol":"AUD/USD","bids":[{"price":0.66433,"qty":0.00000000},{"price":0.66352,"qty":2804.00000000}],"asks":[],"checksum":2911938584,"timestamp":"2024-06-01T17:52:17.732165Z"}]}
{"channel":"book","type":"update","data":[{"symbol":"AUD/USD","bids":[{"price":0.66435,"qty":1029.91169156}],"asks":[],"checksum":1546267243,"timestamp":"2024-06-01T17:52:17.732375Z"}]}
{"channel":"book","type":"update","data":[{"symbol":"AUD/USD","bids":[],"asks":[{"price":0.66472,"qty":0.00000000},{"price":0.66588,"qty":10240.00000000},{"price":0.66470,"qty":12212.66745688}],"checksum":458356244,"timestamp":"2024-06-01T17:52:17.732961Z"}]}
{"channel":"book","type":"update","data":[{"symbol":"AUD/USD","bids":[{"price":0.66434,"qty":0.00000000},{"price":0.66352,"qty":2804.00000000},{"price":0.66433,"qty":5601.38477658}],"asks":[],"checksum":2352064669,"timestamp":"2024-06-01T17:52:17.737407Z"}]}
{"channel":"book","type":"update","data":[{"symbol":"AUD/USD","bids":[],"asks":[{"price":0.66470,"qty":12555.09888652}],"checksum":392944009,"timestamp":"2024-06-01T17:52:17.887482Z"}]}
{"channel":"book","type":"update","data":[{"symbol":"AUD/USD","bids":[{"price":0.66433,"qty":0.00000000},{"price":0.66352,"qty":2804.00000000},{"price":0.66436,"qty":5601.13183910}],"asks":[],"checksum":589571567,"timestamp":"2024-06-01T17:52:17.924947Z"}]}
{"channel":"book","type":"update","data":[{"symbol":"AUD/USD","bids":[],"asks":[{"price":0.66471,"qty":0.00000000},{"price":0.66588,"qty":10240.00000000},{"price":0.66469,"qty":4884.70711870}],"checksum":2251121749,"timestamp":"2024-06-01T17:52:17.924985Z"}]}
{"channel":"book","type":"update","data":[{"symbol":"AUD/USD","bids":[{"price":0.66435,"qty":0.00000000},{"price":0.66352,"qty":2804.00000000}],"asks":[],"checksum":1098492773,"timestamp":"2024-06-01T17:52:17.941816Z"}]}
{"channel":"book","type":"update","data":[{"symbol":"AUD/USD","bids":[{"price":0.66437,"qty":1029.88066852}],"asks":[],"checksum":3739447153,"timestamp":"2024-06-01T17:52:17.941963Z"}]}
{"channel":"book","type":"update","data":[{"symbol":"AUD/USD","bids":[{"price":0.66436,"qty":0.00000000},{"price":0.66352,"qty":2804.00000000},{"price":0.66433,"qty":5601.38477658}],"asks":[],"checksum":4147506785,"timestamp":"2024-06-01T17:52:17.944730Z"}]}
{"channel":"book","type":"update","data":[{"symbol":"AUD/USD","bids":[],"asks":[{"price":0.66470,"qty":342.43142964},{"price":0.66468,"qty":12212.66745688}],"checksum":1918956646,"timestamp":"2024-06-01T17:52:17.948862Z"}]}
{"channel":"book","type":"update","data":[{"symbol":"AUD/USD","bids":[{"price":0.66437,"qty":0.00000000},{"price":0.66352,"qty":2804.00000000}],"asks":[],"checksum":2688422809,"timestamp":"2024-06-01T17:52:17.963429Z"}]}
{"channel":"book","type":"update","data":[{"symbol":"AUD/USD","bids":[{"price":0.66434,"qty":1029.92727904}],"asks":[],"checksum":1418932244,"timestamp":"2024-06-01T17:52:17.963647Z"}]}
{"channel":"book","type":"update","data":[{"symbol":"AUD/USD","bids":[],"asks":[{"price":0.66503,"qty":0.00000000},{"price":0.66559,"qty":5032.00000000}],"checksum":1289544234,"timestamp":"2024-06-01T17:52:18.064330Z"}]}
{"channel":"book","type":"update","data":[{"symbol":"AUD/USD","bids":[],"asks":[{"price":0.66502,"qty":0.00000000},{"price":0.66588,"qty":10240.00000000}],"checksum":3902080902,"timestamp":"2024-06-01T17:52:18.088988Z"}]}
{"channel":"book","type":"update","data":[{"symbol":"AUD/USD","bids":[],"asks":[{"price":0.66527,"qty":4258.83710000}],"checksum":3497762081,"timestamp":"2024-06-01T17:52:18.089000Z"}]}
{"channel":"book","type":"update","data":[{"symbol":"AUD/USD","bids":[],"asks":[{"price":0.66558,"qty":0.00000000},{"price":0.66588,"qty":10240.00000000}],"checksum":3343849614,"timestamp":"2024-06-01T17:52:18.223028Z"}]}
{"channel":"book","type":"update","data":[{"symbol":"AUD/USD","bids":[],"asks":[{"price":0.66545,"qty":20603.09226052}],"checksum":1195062676,"timestamp":"2024-06-01T17:52:18.224519Z"}]}
{"channel":"book","type":"update","data":[{"symbol":"AUD/USD","bids":[{"price":0.66433,"qty":0.00000000},{"price":0.66352,"qty":2804.00000000},{"price":0.66435,"qty":5601.21614905}],"asks":[],"checksum":1686381767,"timestamp":"2024-06-01T17:52:18.232690Z"}]}
{"channel":"book","type":"update","data":[{"symbol":"AUD/USD","bids":[],"asks":[{"price":0.66469,"qty":0.00000000},{"price":0.66588,"qty":10240.00000000},{"price":0.66467,"qty":4884.70578704}],"checksum":2246318600,"timestamp":"2024-06-01T17:52:18.232718Z"}]}
{"channel":"book","type":"update","data":[{"symbol":"AUD/USD","bids":[],"asks":[{"price":0.66468,"qty":0.00000000},{"price":0.66588,"qty":10240.00000000},{"price":0.66466,"qty":12212.66745688}],"checksum":3814502345,"timestamp":"2024-06-01T17:52:18.254838Z"}]}
{"channel":"book","type":"update","data":[{"symbol":"AUD/USD","bids":[{"price":0.66434,"qty":0.00000000},{"price":0.66352,"qty":2804.00000000}],"asks":[],"checksum":3959749614,"timestamp":"2024-06-01T17:52:18.255223Z"}]}
{"channel":"book","type":"update","data":[{"symbol":"AUD/USD","bids":[{"price":0.66436,"qty":1029.89625506}],"asks":[],"checksum":510454651,"timestamp":"2024-06-01T17:52:18.255280Z"}]}
{"channel":"book","type":"update","data":[{"symbol":"AUD/USD","bids":[],"asks":[{"price":0.66557,"qty":0.00000000},{"price":0.66588,"qty":10240.00000000}],"checksum":2241116041,"timestamp":"2024-06-01T17:52:18.606850Z"}]}
{"channel":"book","type":"update","data":[{"symbol":"AUD/USD","bids":[],"asks":[{"price":0.66526,"qty":147.37353355}],"checksum":403766709,"timestamp":"2024-06-01T17:52:18.607444Z"}]}
{"channel":"book","type":"update","data":[{"symbol":"AUD/USD","bids":[{"price":0.66435,"qty":0.00000000},{"price":0.66352,"qty":2804.00000000},{"price":0.66437,"qty":5601.04753168}],"asks":[],"checksum":1407554861,"timestamp":"2024-06-01T17:52:18.641682Z"}]}
{"channel":"book","type":"update","data":[{"symbol":"AUD/USD","bids":[],"asks":[{"price":0.66467,"qty":0.00000000},{"price":0.66588,"qty":10240.00000000},{"price":0.66465,"qty":4884.70488004}],"checksum":989428763,"timestamp":"2024-06-01T17:52:18.641733Z"}]}
{"channel":"book","type":"update","data":[{"symbol":"AUD/USD","bids":[{"price":0.66436,"qty":0.00000000},{"price":0.66352,"qty":2804.00000000}],"asks":[],"checksum":1228287005,"timestamp":"2024-06-01T17:52:18.658335Z"}]}
{"channel":"book","type":"update","data":[{"symbol":"AUD/USD","bids":[{"price":0.66438,"qty":1029.86523295}],"asks":[],"checksum":2794280755,"timestamp":"2024-06-01T17:52:18.658346Z"}]}
{"channel":"book","type":"update","data":[{"symbol":"AUD/USD","bids":[{"price":0.66437,"qty":0.00000000},{"price":0.66352,"qty":2804.00000000},{"price":0.66433,"qty":5601.38477658}],"asks":[],"checksum":2775675412,"timestamp":"2024-06-01T17:52:18.661295Z"}]}
{"channel":"book","type":"update","data":[{"symbol":"AUD/USD","bids":[{"price":0.66438,"qty":0.00000000},{"price":0.66352,"qty":2804.00000000}],"asks":[],"checksum":1529766639,"timestamp":"2024-06-01T17:52:18.673808Z"}]}
{"channel":"book","type":"update","data":[{"symbol":"AUD/USD","bids":[{"price":0.66434,"qty":1029.92727904}],"asks":[],"checksum":2944614754,"timestamp":"2024-06-01T17:52:18.673819Z"}]}
{"channel":"book","type":"update","data":[{"symbol":"AUD/USD","bids":[{"price":0.66433,"qty":0.00000000},{"price":0.66352,"qty":2804.00000000},{"price":0.66435,"qty":5601.21614905}],"asks":[],"checksum":2352762929,"timestamp":"2024-06-01T17:52:19.040275Z"}]}
{"channel":"book","type":"update","data":[{"symbol":"AUD/USD","bids":[{"price":0.66436,"qty":1029.89625506}],"asks":[],"checksum":2789752462,"timestamp":"2024-06-01T17:52:19.071358Z"}]}
{"channel":"book","type":"update","data":[{"symbol":"AUD/USD","bids":[{"price":0.66434,"qty":0.00000000},{"price":0.66358,"qty":3003.00000000}],"asks":[],"checksum":1896617091,"timestamp":"2024-06-01T17:52:19.071382Z"}]}
{"channel":"book","type":"update","data":[{"symbol":"AUD/USD","bids":[{"price":0.66379,"qty":0.00000000},{"price":0.66352,"qty":2804.00000000}],"asks":[],"checksum":1405039571,"timestamp":"2024-06-01T17:52:19.442867Z"}]}
{"channel":"book","type":"update","data":[{"symbol":"AUD/USD","bids":[{"price":0.66449,"qty":0.00000000},{"price":0.66346,"qty":2506.00000000}],"asks":[],"checksum":528302134,"timestamp":"2024-06-01T17:52:19.442971Z"}]}
{"channel":"book","type":"update","data":[{"symbol":"AUD/USD","bids":[],"asks":[{"price":0.66466,"qty":0.00000000},{"price":0.66588,"qty":10240.00000000},{"price":0.66464,"qty":12212.66745688}],"checksum":3813754989,"timestamp":"2024-06-01T17:52:19.471587Z"}]}
{"channel":"book","type":"update","data":[{"symbol":"AUD/USD","bids":[{"price":0.66435,"qty":0.00000000},{"price":0.66345,"qty":505.00000000},{"price":0.66437,"qty":5601.04753168}],"asks":[],"checksum":217061904,"timestamp":"2024-06-01T17:52:19.506876Z"}]}
{"channel":"book","type":"update","data":[{"symbol":"AUD/USD","bids":[],"asks":[{"price":0.66465,"qty":0.00000000},{"price":0.66588,"qty":10240.00000000},{"price":0.66463,"qty":4884.75718918}],"checksum":4194683316,"timestamp":"2024-06-01T17:52:19.507158Z"}]}
{"channel":"book","type":"update","data":[{"symbol":"AUD/USD","bids":[{"price":0.66436,"qty":0.00000000},{"price":0.66345,"qty":505.00000000}],"asks":[],"checksum":1394727517,"timestamp":"2024-06-01T17:52:19.511978Z"}]}
{"channel":"book","type":"update","data":[{"symbol":"AUD/USD","bids":[{"price":0.66438,"qty":1029.86523295}],"asks":[],"checksum":1870446822,"timestamp":"2024-06-01T17:52:19.512070Z"}]}
{"channel":"book","type":"update","data":[{"symbol":"AUD/USD","bids":[{"price":0.66437,"qty":0.00000000},{"price":0.66345,"qty":505.00000000},{"price":0.66433,"qty":5601.38477658}],"asks":[],"checksum":1021135768,"timestamp":"2024-06-01T17:52:19.514856Z"}]}
{"channel":"book","type":"update","data":[{"symbol":"AUD/USD","bids":[{"price":0.66438,"qty":0.00000000},{"price":0.66345,"qty":505.00000000}],"asks":[],"checksum":1542382681,"timestamp":"2024-06-01T17:52:19.542473Z"}]}
{"channel":"book","type":"update","data":[{"symbol":"AUD/USD","bids":[{"price":0.66434,"qty":1029.92727904}],"asks":[],"checksum":4069889486,"timestamp":"2024-06-01T17:52:19.542490Z"}]}
{"channel":"book","type":"update","data":[{"symbol":"AUD/USD","bids":[{"price":0.66438,"qty":84.05098960}],"asks":[],"checksum":2205564478,"timestamp":"2024-06-01T17:52:19.792250Z"}]}
{"channel":"book","type":"update","data":[{"symbol":"AUD/USD","bids":[{"price":0.66381,"qty":485.66497909}],"asks":[],"checksum":1574220020,"timestamp":"2024-06-01T17:52:19.792356Z"}]}
{"channel":"book","type":"update","data":[{"symbol":"AUD/USD","bids":[{"price":0.66434,"qty":0.00000000},{"price":0.66352,"qty":2804.00000000}],"asks":[],"checksum":1257099573,"timestamp":"2024-06-01T17:52:19.810259Z"}]}
{"channel":"book","type":"update","data":[{"symbol":"AUD/USD","bids":[{"price":0.66439,"qty":1029.84964734}],"asks":[],"checksum":4054142346,"timestamp":"2024-06-01T17:52:19.810356Z"}]}
{"channel":"book","type":"update","data":[{"symbol":"AUD/USD","bids":[],"asks":[{"price":0.66463,"qty":0.00000000},{"price":0.66588,"qty":10240.00000000},{"price":0.66462,"qty":4884.75718918}],"checksum":1912664011,"timestamp":"2024-06-01T17:52:19.963290Z"}]}
{"channel":"book","type":"update","data":[{"symbol":"AUD/USD","bids":[{"price":0.66433,"qty":0.00000000},{"price":0.66352,"qty":2804.00000000},{"price":0.66440,"qty":5600.79462466}],"asks":[],"checksum":223940992,"timestamp":"2024-06-01T17:52:19.963318Z"}]}
{"channel":"book","type":"update","data":[{"symbol":"AUD/USD","bids":[],"asks":[{"price":0.66462,"qty":0.00000000},{"price":0.66588,"qty":10240.00000000},{"price":0.66461,"qty":4884.75882457}],"checksum":2049735066,"timestamp":"2024-06-01T17:52:20.521199Z"}]}
{"channel":"book","type":"update","data":[{"symbol":"AUD/USD","bids":[],"asks":[{"price":0.66461,"qty":0.00000000},{"price":0.66588,"qty":10240.00000000},{"price":0.66460,"qty":4884.75408790}],"checksum":3323646562,"timestamp":"2024-06-01T17:52:21.112121Z"}]}
{"channel":"book","type":"update","data":[{"symbol":"AUD/USD","bids":[],"asks":[{"price":0.66460,"qty":0.00000000},{"price":0.66588,"qty":10240.00000000},{"price":0.66463,"qty":4884.73923300}],"checksum":3400234842,"timestamp":"2024-06-01T17:52:21.115350Z"}]}
{"channel":"book","type":"update","data":[{"symbol":"AUD/USD","bids":[],"asks":[{"price":0.66545,"qty":0.00000000},{"price":0.66588,"qty":10240.00000000}],"checksum":3537716018,"timestamp":"2024-06-01T17:52:21.222440Z"}]}
{"channel":"book","type":"update","data":[{"symbol":"AUD/USD","bids":[],"asks":[{"price":0.66526,"qty":21300.36843286}],"checksum":1601553737,"timestamp":"2024-06-01T17:52:21.224333Z"}]}
{"channel":"book","type":"update","data":[{"symbol":"AUD/USD","bids":[],"asks":[{"price":0.66527,"qty":0.00000000},{"price":0.66597,"qty":2955.00000000}],"checksum":2686672512,"timestamp":"2024-06-01T17:52:21.246807Z"}]}
{"channel":"book","type":"update","data":[{"symbol":"AUD/USD","bids":[],"asks":[{"price":0.66525,"qty":4258.83710000}],"checksum":2735738158,"timestamp":"2024-06-01T17:52:21.246828Z"}]}
{"channel":"book","type":"update","data":[{"symbol":"AUD/USD","bids":[{"price":0.66380,"qty":0.00000000},{"price":0.66352,"qty":2804.00000000}],"asks":[],"checksum":3020215903,"timestamp":"2024-06-01T17:52:21.319778Z"}]}
{"channel":"book","type":"update","data":[{"symbol":"AUD/USD","bids":[{"price":0.66376,"qty":0.00000000},{"price":0.66346,"qty":2506.00000000}],"asks":[],"checksum":1105163374,"timestamp":"2024-06-01T17:52:21.319927Z"}]}
{"channel":"book","type":"update","data":[{"symbol":"AUD/USD","bids":[{"price":0.66441,"qty":7306.02007570}],"asks":[],"checksum":3176780810,"timestamp":"2024-06-01T17:52:21.324505Z"}]}
{"channel":"book","type":"update","data":[{"symbol":"AUD/USD","bids":[{"price":0.66376,"qty":17190.85095542}],"asks":[],"checksum":1595715782,"timestamp":"2024-06-01T17:52:21.324578Z"}]}
{"channel":"book","type":"update","data":[{"symbol":"AUD/USD","bids":[],"asks":[{"price":0.66464,"qty":0.00000000},{"price":0.66597,"qty":2955.00000000},{"price":0.66469,"qty":12212.66745688}],"checksum":2800043397,"timestamp":"2024-06-01T17:52:21.353505Z"}]}
{"channel":"book","type":"update","data":[{"symbol":"AUD/USD","bids":[],"asks":[{"price":0.66463,"qty":0.00000000},{"price":0.66597,"qty":2955.00000000},{"price":0.66468,"qty":4884.73551886}],"checksum":2720338969,"timestamp":"2024-06-01T17:52:21.356753Z"}]}
{"channel":"book","type":"update","data":[{"symbol":"AUD/USD","bids":[],"asks":[{"price":0.66526,"qty":21152.99489931}],"checksum":936172189,"timestamp":"2024-06-01T17:52:21.557521Z"}]}
{"channel":"book","type":"update","data":[{"symbol":"AUD/USD","bids":[],"asks":[{"price":0.66524,"qty":147.37353355}],"checksum":2432259232,"timestamp":"2024-06-01T17:52:21.558367Z"}]}
{"channel":"book","type":"update","data":[{"symbol":"AUD/USD","bids":[{"price":0.66440,"qty":0.00000000},{"price":0.66352,"qty":2804.00000000},{"price":0.66442,"qty":5600.62603267}],"asks":[],"checksum":3068419380,"timestamp":"2024-06-01T17:52:21.660684Z"}]}
{"channel":"book","type":"update","data":[{"symbol":"AUD/USD","bids":[{"price":0.66438,"qty":0.00000000},{"price":0.66352,"qty":2804.00000000}],"asks":[],"checksum":1106395310,"timestamp":"2024-06-01T17:52:21.902971Z"}]}
{"channel":"book","type":"update","data":[{"symbol":"AUD/USD","bids":[{"price":0.66381,"qty":0.00000000},{"price":0.66346,"qty":2506.00000000}],"asks":[],"checksum":2369031544,"timestamp":"2024-06-01T17:52:21.903080Z"}]}
{"channel":"book","type":"update","data":[{"symbol":"AUD/USD","bids":[{"price":0.66441,"qty":7363.07649663}],"asks":[],"checksum":3762237210,"timestamp":"2024-06-01T17:52:21.907262Z"}]}
{"channel":"book","type":"update","data":[{"symbol":"AUD/USD","bids":[{"price":0.66381,"qty":512.77158576}],"asks":[],"checksum":3588406388,"timestamp":"2024-06-01T17:52:21.907315Z"}]}
{"channel":"book","type":"update","data":[{"symbol":"AUD/USD","bids":[{"price":0.66439,"qty":0.00000000},{"price":0.66346,"qty":2506.00000000}],"asks":[],"checksum":1971956856,"timestamp":"2024-06-01T17:52:21.914685Z"}]}
{"channel":"book","type":"update","data":[{"symbol":"AUD/USD","bids":[{"price":0.66433,"qty":1029.94271647}],"asks":[],"checksum":3018610148,"timestamp":"2024-06-01T17:52:21.914952Z"}]}
{"channel":"book","type":"update","data":[{"symbol":"AUD/USD","bids":[],"asks":[{"price":0.66526,"qty":0.00000000},{"price":0.66588,"qty":10240.00000000}],"checksum":1555615082,"timestamp":"2024-06-01T17:52:24.210141Z"}]}
{"channel":"book","type":"update","data":[{"symbol":"AUD/USD","bids":[],"asks":[{"price":0.66524,"qty":6086.39542626}],"checksum":742412987,"timestamp":"2024-06-01T17:52:24.210805Z"}]}
{"channel":"book","type":"update","data":[{"symbol":"AUD/USD","bids":[],"asks":[{"price":0.66545,"qty":14649.74998659}],"checksum":3235790170,"timestamp":"2024-06-01T17:52:24.211024Z"}]}
{"channel":"book","type":"update","data":[{"symbol":"AUD/USD","bids":[],"asks":[{"price":0.66525,"qty":0.00000000},{"price":0.66588,"qty":10240.00000000}],"checksum":1391243967,"timestamp":"2024-06-01T17:52:24.223159Z"}]}
{"channel":"book","type":"update","data":[{"symbol":"AUD/USD","bids":[],"asks":[{"price":0.66523,"qty":4258.83710000}],"checksum":310677553,"timestamp":"2024-06-01T17:52:24.223220Z"}]}
{"channel":"book","type":"update","data":[{"symbol":"AUD/USD","bids":[],"asks":[{"price":0.66469,"qty":0.00000000},{"price":0.66588,"qty":10240.00000000},{"price":0.66467,"qty":12212.66745688}],"checksum":2554537320,"timestamp":"2024-06-01T17:52:24.229294Z"}]}
{"channel":"book","type":"update","data":[{"symbol":"AUD/USD","bids":[],"asks":[{"price":0.66468,"qty":0.00000000},{"price":0.66588,"qty":10240.00000000},{"price":0.66466,"qty":4885.19759286}],"checksum":1483947404,"timestamp":"2024-06-01T17:52:24.232366Z"}]}
{"channel":"book","type":"update","data":[{"symbol":"AUD/USD","bids":[{"price":0.66441,"qty":7306.02007570}],"asks":[],"checksum":2385884313,"timestamp":"2024-06-01T17:52:24.453845Z"}]}
{"channel":"book","type":"update","data":[{"symbol":"AUD/USD","bids":[{"price":0.66381,"qty":0.00000000},{"price":0.66346,"qty":2506.00000000}],"asks":[],"checksum":1054828247,"timestamp":"2024-06-01T17:52:24.454052Z"}]}
{"channel":"book","type":"update","data":[{"symbol":"AUD/USD","bids":[{"price":0.66443,"qty":90.77700769}],"asks":[],"checksum":772519891,"timestamp":"2024-06-01T17:52:24.458180Z"}]}
{"channel":"book","type":"update","data":[{"symbol":"AUD/USD","bids":[{"price":0.66377,"qty":404.47124215}],"asks":[],"checksum":2047392107,"timestamp":"2024-06-01T17:52:24.458224Z"}]}
{"channel":"book","type":"update","data":[{"symbol":"AUD/USD","bids":[],"asks":[{"price":0.66524,"qty":5939.02189271}],"checksum":3308019719,"timestamp":"2024-06-01T17:52:24.515757Z"}]}
{"channel":"book","type":"update","data":[{"symbol":"AUD/USD","bids":[],"asks":[{"price":0.66522,"qty":147.37353355}],"checksum":1993980622,"timestamp":"2024-06-01T17:52:24.516996Z"}]}
{"channel":"book","type":"update","data":[{"symbol":"AUD/USD","bids":[{"price":0.66442,"qty":0.00000000},{"price":0.66352,"qty":2804.00000000},{"price":0.66444,"qty":5600.45745082}],"asks":[],"checksum":101372522,"timestamp":"2024-06-01T17:52:24.684413Z"}]}
{"channel":"book","type":"update","data":[{"symbol":"AUD/USD","bids":[{"price":0.66441,"qty":0.00000000},{"price":0.66352,"qty":2804.00000000}],"asks":[],"checksum":4038104,"timestamp":"2024-06-01T17:52:25.096464Z"}]}
{"channel":"book","type":"update","data":[{"symbol":"AUD/USD","bids":[{"price":0.66376,"qty":0.00000000},{"price":0.66346,"qty":2506.00000000}],"asks":[],"checksum":2077992552,"timestamp":"2024-06-01T17:52:25.096592Z"}]}
{"channel":"book","type":"update","data":[{"symbol":"AUD/USD","bids":[{"price":0.66444,"qty":0.00000000},{"price":0.66345,"qty":505.00000000},{"price":0.66434,"qty":5601.30046155}],"asks":[],"checksum":2993873210,"timestamp":"2024-06-01T17:52:25.099437Z"}]}
{"channel":"book","type":"update","data":[{"symbol":"AUD/USD","bids":[{"price":0.66443,"qty":5286.77952794}],"asks":[],"checksum":109092975,"timestamp":"2024-06-01T17:52:25.103224Z"}]}
{"channel":"book","type":"update","data":[{"symbol":"AUD/USD","bids":[{"price":0.66378,"qty":11765.38662357}],"asks":[],"checksum":2454919226,"timestamp":"2024-06-01T17:52:25.103286Z"}]}
{"channel":"book","type":"update","data":[{"symbol":"AUD/USD","bids":[{"price":0.66376,"qty":7929.93485806}],"asks":[],"checksum":1238423349,"timestamp":"2024-06-01T17:52:25.103511Z"}]}
{"channel":"book","type":"update","data":[{"symbol":"AUD/USD","bids":[{"price":0.66435,"qty":1029.91169156}],"asks":[],"checksum":3972219505,"timestamp":"2024-06-01T17:52:25.110290Z"}]}
{"channel":"book","type":"update","data":[{"symbol":"AUD/USD","bids":[{"price":0.66433,"qty":0.00000000},{"price":0.66358,"qty":3003.00000000}],"asks":[],"checksum":3364576803,"timestamp":"2024-06-01T17:52:25.110323Z"}]}
{"channel":"book","type":"update","data":[{"symbol":"AUD/USD","bids":[],"asks":[{"price":0.66467,"qty":0.00000000},{"price":0.66559,"qty":5032.00000000},{"price":0.66465,"qty":12212.66745688}],"checksum":3671354178,"timestamp":"2024-06-01T17:52:25.110821Z"}]}
{"channel":"book","type":"update","data":[{"symbol":"AUD/USD","bids":[],"asks":[{"price":0.66466,"qty":0.00000000},{"price":0.66559,"qty":5032.00000000},{"price":0.66464,"qty":4885.14330527}],"checksum":3438492999,"timestamp":"2024-06-01T17:52:25.170445Z"}]}
{"channel":"book","type":"update","data":[{"symbol":"AUD/USD","bids":[{"price":0.66434,"qty":0.00000000},{"price":0.66352,"qty":2804.00000000},{"price":0.66444,"qty":5600.45745082}],"asks":[],"checksum":4057781223,"timestamp":"2024-06-01T17:52:25.170483Z"}]}
{"channel":"book","type":"update","data":[{"symbol":"AUD/USD","bids":[{"price":0.66433,"qty":1029.94271647}],"asks":[],"checksum":3583299509,"timestamp":"2024-06-01T17:52:25.182973Z"}]}
{"channel":"book","type":"update","data":[{"symbol":"AUD/USD","bids":[{"price":0.66435,"qty":0.00000000},{"price":0.66358,"qty":3003.00000000}],"asks":[],"checksum":2642472795,"timestamp":"2024-06-01T17:52:25.183040Z"}]}
{"channel":"book","type":"update","data":[{"symbol":"AUD/USD","bids":[{"price":0.66443,"qty":5196.00252025}],"asks":[],"checksum":14487403,"timestamp":"2024-06-01T17:52:26.934623Z"}]}
{"channel":"book","type":"update","data":[{"symbol":"AUD/USD","bids":[{"price":0.66377,"qty":0.00000000},{"price":0.66352,"qty":2804.00000000}],"asks":[],"checksum":1073826339,"timestamp":"2024-06-01T17:52:26.934739Z"}]}
{"channel":"book","type":"update","data":[{"symbol":"AUD/USD","bids":[{"price":0.66445,"qty":57.05642093}],"asks":[],"checksum":1512678886,"timestamp":"2024-06-01T17:52:26.938857Z"}]}
{"channel":"book","type":"update","data":[{"symbol":"AUD/USD","bids":[{"price":0.66379,"qty":458.79562936}],"asks":[],"checksum":2827670297,"timestamp":"2024-06-01T17:52:26.938869Z"}]}
{"channel":"book","type":"update","data":[{"symbol":"AUD/USD","bids":[],"asks":[{"price":0.66524,"qty":0.00000000},{"price":0.66559,"qty":5032.00000000}],"checksum":402694249,"timestamp":"2024-06-01T17:52:27.225057Z"}]}
{"channel":"book","type":"update","data":[{"symbol":"AUD/USD","bids":[],"asks":[{"price":0.66545,"qty":0.00000000},{"price":0.66588,"qty":5806.00000000}],"checksum":1726770866,"timestamp":"2024-06-01T17:52:27.225136Z"}]}
{"channel":"book","type":"update","data":[{"symbol":"AUD/USD","bids":[],"asks":[{"price":0.66522,"qty":3153.58135270}],"checksum":3482536592,"timestamp":"2024-06-01T17:52:27.227467Z"}]}
{"channel":"book","type":"update","data":[{"symbol":"AUD/USD","bids":[],"asks":[{"price":0.66545,"qty":17596.88444137}],"checksum":1890037846,"timestamp":"2024-06-01T17:52:27.227493Z"}]}
{"channel":"book","type":"update","data":[{"symbol":"AUD/USD","bids":[],"asks":[{"price":0.66522,"qty":3006.20781915}],"checksum":3056790718,"timestamp":"2024-06-01T17:52:27.491786Z"}]}
{"channel":"book","type":"update","data":[{"symbol":"AUD/USD","bids":[],"asks":[{"price":0.66521,"qty":145.54053853}],"checksum":3680919202,"timestamp":"2024-06-01T17:52:27.492575Z"}]}
{"channel":"book","type":"update","data":[{"symbol":"AUD/USD","bids":[{"price":0.66376,"qty":0.00000000},{"price":0.66358,"qty":3003.00000000}],"asks":[],"checksum":1782079601,"timestamp":"2024-06-01T17:52:28.641825Z"}]}
{"channel":"book","type":"update","data":[{"symbol":"AUD/USD","bids":[{"price":0.66443,"qty":0.00000000},{"price":0.66352,"qty":2804.00000000}],"asks":[],"checksum":3008870007,"timestamp":"2024-06-01T17:52:28.641837Z"}]}
{"channel":"book","type":"update","data":[{"symbol":"AUD/USD","bids":[{"price":0.66378,"qty":0.00000000},{"price":0.66346,"qty":2506.00000000}],"asks":[],"checksum":1966516760,"timestamp":"2024-06-01T17:52:28.641848Z"}]}
{"channel":"book","type":"update","data":[{"symbol":"AUD/USD","bids":[{"price":0.66444,"qty":0.00000000},{"price":0.66345,"qty":505.00000000},{"price":0.66434,"qty":5601.30046155}],"asks":[],"checksum":335669988,"timestamp":"2024-06-01T17:52:28.645126Z"}]}
{"channel":"book","type":"update","data":[{"symbol":"AUD/USD","bids":[{"price":0.66445,"qty":3063.26424008}],"asks":[],"checksum":4222726455,"timestamp":"2024-06-01T17:52:28.647175Z"}]}
{"channel":"book","type":"update","data":[{"symbol":"AUD/USD","bids":[{"price":0.66376,"qty":10119.72955917}],"asks":[],"checksum":1868392128,"timestamp":"2024-06-01T17:52:28.647297Z"}]}
{"channel":"book","type":"update","data":[{"symbol":"AUD/USD","bids":[{"price":0.66380,"qty":11765.38662357}],"asks":[],"checksum":1105695507,"timestamp":"2024-06-01T17:52:28.647314Z"}]}
{"channel":"book","type":"update","data":[{"symbol":"AUD/USD","bids":[{"price":0.66433,"qty":0.00000000},{"price":0.66352,"qty":2804.00000000}],"asks":[],"checksum":3544167281,"timestamp":"2024-06-01T17:52:28.655323Z"}]}
{"channel":"book","type":"update","data":[{"symbol":"AUD/USD","bids":[{"price":0.66435,"qty":1029.91169156}],"asks":[],"checksum":3048373707,"timestamp":"2024-06-01T17:52:28.655418Z"}]}
{"channel":"book","type":"update","data":[{"symbol":"AUD/USD","bids":[{"price":0.66434,"qty":0.00000000},{"price":0.66352,"qty":2804.00000000},{"price":0.66446,"qty":5600.28887913}],"asks":[],"checksum":2317464806,"timestamp":"2024-06-01T17:52:28.957520Z"}]}
{"channel":"book","type":"update","data":[{"symbol":"AUD/USD","bids":[{"price":0.66433,"qty":1029.94271647}],"asks":[],"checksum":2822117133,"timestamp":"2024-06-01T17:52:28.988266Z"}]}
{"channel":"book","type":"update","data":[{"symbol":"AUD/USD","bids":[{"price":0.66435,"qty":0.00000000},{"price":0.66358,"qty":3003.00000000}],"asks":[],"checksum":1218058109,"timestamp":"2024-06-01T17:52:28.988303Z"}]}
{"channel":"book","type":"update","data":[{"symbol":"AUD/USD","bids":[{"price":0.66379,"qty":0.00000000},{"price":0.66352,"qty":2804.00000000}],"asks":[],"checksum":3610993455,"timestamp":"2024-06-01T17:52:29.560021Z"}]}
{"channel":"book","type":"update","data":[{"symbol":"AUD/USD","bids":[{"price":0.66445,"qty":3006.20781915}],"asks":[],"checksum":647550446,"timestamp":"2024-06-01T17:52:29.560123Z"}]}
{"channel":"book","type":"update","data":[{"symbol":"AUD/USD","bids":[{"price":0.66446,"qty":5630.35073139}],"asks":[],"checksum":2931520006,"timestamp":"2024-06-01T17:52:29.566606Z"}]}
{"channel":"book","type":"update","data":[{"symbol":"AUD/USD","bids":[{"price":0.66436,"qty":84.05098960}],"asks":[],"checksum":2681901769,"timestamp":"2024-06-01T17:52:29.566675Z"}]}
{"channel":"book","type":"update","data":[{"symbol":"AUD/USD","bids":[{"price":0.66381,"qty":428.62173910}],"asks":[],"checksum":2092895773,"timestamp":"2024-06-01T17:52:29.566741Z"}]}
{"channel":"book","type":"update","data":[{"symbol":"AUD/USD","bids":[{"price":0.66436,"qty":0.00000000},{"price":0.66358,"qty":3003.00000000}],"asks":[],"checksum":1153865549,"timestamp":"2024-06-01T17:52:31.812799Z"}]}
{"channel":"book","type":"update","data":[{"symbol":"AUD/USD","bids":[{"price":0.66446,"qty":5600.28887913}],"asks":[],"checksum":1866176917,"timestamp":"2024-06-01T17:52:31.812861Z"}]}
{"channel":"book","type":"update","data":[{"symbol":"AUD/USD","bids":[{"price":0.66381,"qty":0.00000000},{"price":0.66352,"qty":2804.00000000}],"asks":[],"checksum":647550446,"timestamp":"2024-06-01T17:52:31.812987Z"}]}
{"channel":"book","type":"update","data":[{"symbol":"AUD/USD","bids":[{"price":0.66381,"qty":528.63649772}],"asks":[],"checksum":3497680278,"timestamp":"2024-06-01T17:52:31.818077Z"}]}
{"channel":"book","type":"update","data":[{"symbol":"AUD/USD","bids":[{"price":0.66445,"qty":0.00000000},{"price":0.66352,"qty":2804.00000000}],"asks":[],"checksum":3000452359,"timestamp":"2024-06-01T17:52:32.326994Z"}]}
{"channel":"book","type":"update","data":[{"symbol":"AUD/USD","bids":[{"price":0.66380,"qty":0.00000000},{"price":0.66346,"qty":2506.00000000}],"asks":[],"checksum":86190184,"timestamp":"2024-06-01T17:52:32.327024Z"}]}
{"channel":"book","type":"update","data":[{"symbol":"AUD/USD","bids":[{"price":0.66376,"qty":0.00000000},{"price":0.66345,"qty":505.00000000}],"asks":[],"checksum":1567136106,"timestamp":"2024-06-01T17:52:32.327193Z"}]}
{"channel":"book","type":"update","data":[{"symbol":"AUD/USD","bids":[{"price":0.66446,"qty":0.00000000},{"price":0.66336,"qty":353.60339055},{"price":0.66434,"qty":5601.30046155}],"asks":[],"checksum":1022791536,"timestamp":"2024-06-01T17:52:32.330091Z"}]}
{"channel":"book","type":"update","data":[{"symbol":"AUD/USD","bids":[{"price":0.66447,"qty":3006.20781915}],"asks":[],"checksum":3287373366,"timestamp":"2024-06-01T17:52:32.334290Z"}]}
{"channel":"book","type":"update","data":[{"symbol":"AUD/USD","bids":[{"price":0.66376,"qty":16639.93763276}],"asks":[],"checksum":1111013711,"timestamp":"2024-06-01T17:52:32.334453Z"}]}
{"channel":"book","type":"update","data":[{"symbol":"AUD/USD","bids":[],"asks":[{"price":0.66465,"qty":0.00000000},{"price":0.66559,"qty":5032.00000000},{"price":0.66463,"qty":12212.66745688}],"checksum":1138323997,"timestamp":"2024-06-01T17:52:32.340273Z"}]}
{"channel":"book","type":"update","data":[{"symbol":"AUD/USD","bids":[{"price":0.66435,"qty":1029.91169156}],"asks":[],"checksum":2473727205,"timestamp":"2024-06-01T17:52:32.342596Z"}]}
{"channel":"book","type":"update","data":[{"symbol":"AUD/USD","bids":[{"price":0.66433,"qty":0.00000000},{"price":0.66352,"qty":2804.00000000}],"asks":[],"checksum":3263363851,"timestamp":"2024-06-01T17:52:32.342716Z"}]}
{"channel":"book","type":"update","data":[{"symbol":"AUD/USD","bids":[],"asks":[{"price":0.66463,"qty":0.00000000},{"price":0.66559,"qty":5032.00000000},{"price":0.66469,"qty":12212.66745688}],"checksum":2823213140,"timestamp":"2024-06-01T17:52:32.372172Z"}]}
{"channel":"book","type":"update","data":[{"symbol":"AUD/USD","bids":[],"asks":[{"price":0.66464,"qty":0.00000000},{"price":0.66559,"qty":5032.00000000},{"price":0.66468,"qty":4887.14968918}],"checksum":1011133727,"timestamp":"2024-06-01T17:52:32.375558Z"}]}
{"channel":"book","type":"update","data":[{"symbol":"AUD/USD","bids":[],"asks":[{"price":0.66468,"qty":0.00000000},{"price":0.66559,"qty":5032.00000000},{"price":0.66467,"qty":4887.14968918}],"checksum":805840707,"timestamp":"2024-06-01T17:52:32.403602Z"}]}
{"channel":"book","type":"update","data":[{"symbol":"AUD/USD","bids":[{"price":0.66434,"qty":0.00000000},{"price":0.66346,"qty":2506.00000000},{"price":0.66448,"qty":5600.12031758}],"asks":[],"checksum":3810204409,"timestamp":"2024-06-01T17:52:32.403702Z"}]}
{"channel":"book","type":"update","data":[{"symbol":"AUD/USD","bids":[],"asks":[{"price":0.66469,"qty":0.00000000},{"price":0.66559,"qty":5032.00000000},{"price":0.66467,"qty":17099.81714606}],"checksum":238669663,"timestamp":"2024-06-01T17:52:32.404083Z"}]}
{"channel":"book","type":"update","data":[{"symbol":"AUD/USD","bids":[{"price":0.66435,"qty":0.00000000},{"price":0.66346,"qty":2506.00000000}],"asks":[],"checksum":1265991239,"timestamp":"2024-06-01T17:52:32.407542Z"}]}
{"channel":"book","type":"update","data":[{"symbol":"AUD/USD","bids":[],"asks":[{"price":0.66467,"qty":12212.66745688},{"price":0.66468,"qty":4887.14968918}],"checksum":1471242347,"timestamp":"2024-06-01T17:52:32.407646Z"}]}
{"channel":"book","type":"update","data":[{"symbol":"AUD/USD","bids":[{"price":0.66433,"qty":1029.94271647}],"asks":[],"checksum":2124541391,"timestamp":"2024-06-01T17:52:32.407686Z"}]}
{"channel":"book","type":"update","data":[{"symbol":"AUD/USD","bids":[],"asks":[{"price":0.66468,"qty":0.00000000},{"price":0.66559,"qty":5032.00000000},{"price":0.66466,"qty":4887.14968918}],"checksum":468926001,"timestamp":"2024-06-01T17:52:32.576730Z"}]}
{"channel":"book","type":"update","data":[{"symbol":"AUD/USD","bids":[],"asks":[{"price":0.66466,"qty":0.00000000},{"price":0.66559,"qty":5032.00000000},{"price":0.66465,"qty":4887.11932989}],"checksum":2535877156,"timestamp":"2024-06-01T17:52:32.817595Z"}]}
{"channel":"book","type":"update","data":[{"symbol":"AUD/USD","bids":[],"asks":[{"price":0.66465,"qty":0.00000000},{"price":0.66559,"qty":5032.00000000},{"price":0.66464,"qty":4887.09919964}],"checksum":4167910992,"timestamp":"2024-06-01T17:52:33.091856Z"}]}
{"channel":"book","type":"update","data":[{"symbol":"AUD/USD","bids":[],"asks":[{"price":0.66464,"qty":0.00000000},{"price":0.66559,"qty":5032.00000000},{"price":0.66463,"qty":4887.07668611}],"checksum":2308545216,"timestamp":"2024-06-01T17:52:33.400189Z"}]}
{"channel":"book","type":"update","data":[{"symbol":"AUD/USD","bids":[],"asks":[{"price":0.66463,"qty":0.00000000},{"price":0.66559,"qty":5032.00000000},{"price":0.66466,"qty":4887.07056782}],"checksum":31671081,"timestamp":"2024-06-01T17:52:33.403588Z"}]}
{"channel":"book","type":"update","data":[{"symbol":"AUD/USD","bids":[],"asks":[{"price":0.66466,"qty":0.00000000},{"price":0.66559,"qty":5032.00000000},{"price":0.66465,"qty":4887.07056782}],"checksum":34225861,"timestamp":"2024-06-01T17:52:33.664038Z"}]}
{"channel":"book","type":"update","data":[{"symbol":"AUD/USD","bids":[],"asks":[{"price":0.66465,"qty":0.00000000},{"price":0.66559,"qty":5032.00000000},{"price":0.66464,"qty":4887.06642169}],"checksum":2681336051,"timestamp":"2024-06-01T17:52:33.995249Z"}]}
{"channel":"book","type":"update","data":[{"symbol":"AUD/USD","bids":[],"asks":[{"price":0.66464,"qty":0.00000000},{"price":0.66559,"qty":5032.00000000},{"price":0.66463,"qty":4887.06169354}],"checksum":1940426521,"timestamp":"2024-06-01T17:52:34.360491Z"}]}
{"channel":"book","type":"update","data":[{"symbol":"AUD/USD","bids":[],"asks":[{"price":0.66463,"qty":0.00000000},{"price":0.66559,"qty":5032.00000000},{"price":0.66466,"qty":4887.14417330}],"checksum":3729100458,"timestamp":"2024-06-01T17:52:34.363894Z"}]}
{"channel":"book","type":"update","data":[{"symbol":"AUD/USD","bids":[],"asks":[{"price":0.66466,"qty":0.00000000},{"price":0.66559,"qty":5032.00000000},{"price":0.66465,"qty":4887.14417330}],"checksum":3719099206,"timestamp":"2024-06-01T17:52:34.683494Z"}]}
{"channel":"book","type":"update","data":[{"symbol":"AUD/USD","bids":[],"asks":[{"price":0.66465,"qty":0.00000000},{"price":0.66559,"qty":5032.00000000},{"price":0.66464,"qty":4887.11907533}],"checksum":4278631531,"timestamp":"2024-06-01T17:52:35.072089Z"}]}
{"channel":"book","type":"update","data":[{"symbol":"AUD/USD","bids":[],"asks":[{"price":0.66464,"qty":0.00000000},{"price":0.66559,"qty":5032.00000000},{"price":0.66466,"qty":4887.10686242}],"checksum":265457689,"timestamp":"2024-06-01T17:52:35.075721Z"}]}
{"channel":"book","type":"update","data":[{"symbol":"AUD/USD","bids":[{"price":0.66381,"qty":0.00000000},{"price":0.66346,"qty":2506.00000000}],"asks":[],"checksum":2381461259,"timestamp":"2024-06-01T17:52:35.281912Z"}]}
{"channel":"book","type":"update","data":[{"symbol":"AUD/USD","bids":[],"asks":[{"price":0.66466,"qty":0.00000000},{"price":0.66559,"qty":5032.00000000},{"price":0.66465,"qty":4887.10686242}],"checksum":609054757,"timestamp":"2024-06-01T17:52:35.495663Z"}]}
{"channel":"book","type":"update","data":[{"symbol":"AUD/USD","bids":[],"asks":[{"price":0.66465,"qty":0.00000000},{"price":0.66559,"qty":5032.00000000},{"price":0.66466,"qty":4887.10112569}],"checksum":2822373048,"timestamp":"2024-06-01T17:52:35.499327Z"}]}
{"channel":"book","type":"update","data":[{"symbol":"AUD/USD","bids":[{"price":0.66449,"qty":30.06185226}],"asks":[],"checksum":152835094,"timestamp":"2024-06-01T17:52:35.548664Z"}]}
{"channel":"book","type":"update","data":[{"symbol":"AUD/USD","bids":[{"price":0.66377,"qty":512.89680471}],"asks":[],"checksum":3588654866,"timestamp":"2024-06-01T17:52:35.548858Z"}]}
{"channel":"book","type":"update","data":[{"symbol":"AUD/USD","bids":[{"price":0.66376,"qty":0.00000000},{"price":0.66352,"qty":2804.00000000}],"asks":[],"checksum":2715119907,"timestamp":"2024-06-01T17:52:35.840060Z"}]}
{"channel":"book","type":"update","data":[{"symbol":"AUD/USD","bids":[{"price":0.66447,"qty":0.00000000},{"price":0.66346,"qty":2506.00000000}],"asks":[],"checksum":3428294104,"timestamp":"2024-06-01T17:52:35.840103Z"}]}
{"channel":"book","type":"update","data":[{"symbol":"AUD/USD","bids":[{"price":0.66448,"qty":0.00000000},{"price":0.66345,"qty":505.00000000},{"price":0.66434,"qty":5601.30046155}],"asks":[],"checksum":3305817375,"timestamp":"2024-06-01T17:52:35.844516Z"}]}
{"channel":"book","type":"update","data":[{"symbol":"AUD/USD","bids":[{"price":0.66376,"qty":27093.94953132}],"asks":[],"checksum":218913542,"timestamp":"2024-06-01T17:52:35.846466Z"}]}
{"channel":"book","type":"update","data":[{"symbol":"AUD/USD","bids":[{"price":0.66433,"qty":0.00000000},{"price":0.66346,"qty":2506.00000000}],"asks":[],"checksum":1097379879,"timestamp":"2024-06-01T17:52:35.859409Z"}]}
{"channel":"book","type":"update","data":[{"symbol":"AUD/USD","bids":[{"price":0.66435,"qty":1029.91171270}],"asks":[],"checksum":778076234,"timestamp":"2024-06-01T17:52:35.859869Z"}]}
{"channel":"book","type":"update","data":[{"symbol":"AUD/USD","bids":[],"asks":[{"price":0.66467,"qty":0.00000000},{"price":0.66559,"qty":5032.00000000},{"price":0.66465,"qty":12212.66745688}],"checksum":4097942201,"timestamp":"2024-06-01T17:52:35.861148Z"}]}
{"channel":"book","type":"update","data":[{"symbol":"AUD/USD","bids":[{"price":0.66434,"qty":0.00000000},{"price":0.66346,"qty":2506.00000000},{"price":0.66433,"qty":5601.38477658}],"asks":[],"checksum":1187423154,"timestamp":"2024-06-01T17:52:35.862795Z"}]}
{"channel":"book","type":"update","data":[{"symbol":"AUD/USD","bids":[{"price":0.66433,"qty":0.00000000},{"price":0.66346,"qty":2506.00000000},{"price":0.66436,"qty":5601.13183910}],"asks":[],"checksum":2936466858,"timestamp":"2024-06-01T17:52:35.908765Z"}]}
{"channel":"book","type":"update","data":[{"symbol":"AUD/USD","bids":[],"asks":[{"price":0.66466,"qty":0.00000000},{"price":0.66559,"qty":5032.00000000},{"price":0.66464,"qty":4887.09845675}],"checksum":936881014,"timestamp":"2024-06-01T17:52:35.908952Z"}]}
{"channel":"book","type":"update","data":[{"symbol":"AUD/USD","bids":[{"price":0.66435,"qty":0.00000000},{"price":0.66346,"qty":2506.00000000}],"asks":[],"checksum":2101213888,"timestamp":"2024-06-01T17:52:35.921846Z"}]}
{"channel":"book","type":"update","data":[{"symbol":"AUD/USD","bids":[{"price":0.66437,"qty":1029.88074595}],"asks":[],"checksum":3038345976,"timestamp":"2024-06-01T17:52:35.922043Z"}]}
{"channel":"book","type":"update","data":[{"symbol":"AUD/USD","bids":[{"price":0.66436,"qty":0.00000000},{"price":0.66346,"qty":2506.00000000},{"price":0.66433,"qty":5601.38477658}],"asks":[],"checksum":3125932673,"timestamp":"2024-06-01T17:52:35.924785Z"}]}
{"channel":"book","type":"update","data":[{"symbol":"AUD/USD","bids":[{"price":0.66437,"qty":0.00000000},{"price":0.66346,"qty":2506.00000000}],"asks":[],"checksum":70762969,"timestamp":"2024-06-01T17:52:35.941641Z"}]}
{"channel":"book","type":"update","data":[{"symbol":"AUD/USD","bids":[{"price":0.66434,"qty":1029.92727204}],"asks":[],"checksum":2465797200,"timestamp":"2024-06-01T17:52:35.941952Z"}]}
{"channel":"book","type":"update","data":[{"symbol":"AUD/USD","bids":[],"asks":[{"price":0.66545,"qty":0.00000000},{"price":0.66559,"qty":5032.00000000}],"checksum":2805431997,"timestamp":"2024-06-01T17:52:36.233789Z"}]}
{"channel":"book","type":"update","data":[{"symbol":"AUD/USD","bids":[],"asks":[{"price":0.66545,"qty":20529.69851493}],"checksum":3390864024,"timestamp":"2024-06-01T17:52:36.235217Z"}]}
{"channel":"book","type":"update","data":[{"symbol":"AUD/USD","bids":[],"asks":[{"price":0.66521,"qty":0.00000000},{"price":0.66559,"qty":5032.00000000}],"checksum":353731374,"timestamp":"2024-06-01T17:52:36.352289Z"}]}
{"channel":"book","type":"update","data":[{"symbol":"AUD/USD","bids":[],"asks":[{"price":0.66521,"qty":162.03749371}],"checksum":3683975010,"timestamp":"2024-06-01T17:52:36.352799Z"}]}
{"channel":"book","type":"update","data":[{"symbol":"AUD/USD","bids":[{"price":0.66433,"qty":0.00000000},{"price":0.66346,"qty":2506.00000000},{"price":0.66435,"qty":5601.21614905}],"asks":[],"checksum":2067504761,"timestamp":"2024-06-01T17:52:36.490070Z"}]}
{"channel":"book","type":"update","data":[{"symbol":"AUD/USD","bids":[{"price":0.66436,"qty":1029.89615383}],"asks":[],"checksum":3347127086,"timestamp":"2024-06-01T17:52:36.495519Z"}]}
{"channel":"book","type":"update","data":[{"symbol":"AUD/USD","bids":[{"price":0.66434,"qty":0.00000000},{"price":0.66352,"qty":2804.00000000}],"asks":[],"checksum":3045279062,"timestamp":"2024-06-01T17:52:36.496302Z"}]}
{"channel":"book","type":"update","data":[{"symbol":"AUD/USD","bids":[{"price":0.66435,"qty":0.00000000},{"price":0.66346,"qty":2506.00000000},{"price":0.66437,"qty":5601.04753168}],"asks":[],"checksum":1459112091,"timestamp":"2024-06-01T17:52:37.061309Z"}]}
{"channel":"book","type":"update","data":[{"symbol":"AUD/USD","bids":[{"price":0.66436,"qty":0.00000000},{"price":0.66346,"qty":2506.00000000}],"asks":[],"checksum":3808266418,"timestamp":"2024-06-01T17:52:37.065290Z"}]}
{"channel":"book","type":"update","data":[{"symbol":"AUD/USD","bids":[{"price":0.66438,"qty":1029.86518801}],"asks":[],"checksum":2768677967,"timestamp":"2024-06-01T17:52:37.065458Z"}]}
{"channel":"book","type":"update","data":[{"symbol":"AUD/USD","bids":[{"price":0.66437,"qty":0.00000000},{"price":0.66346,"qty":2506.00000000},{"price":0.66433,"qty":5601.38477658}],"asks":[],"checksum":4022437837,"timestamp":"2024-06-01T17:52:37.069053Z"}]}
{"channel":"book","type":"update","data":[{"symbol":"AUD/USD","bids":[{"price":0.66438,"qty":0.00000000},{"price":0.66346,"qty":2506.00000000}],"asks":[],"checksum":1297754859,"timestamp":"2024-06-01T17:52:37.078665Z"}]}
{"channel":"book","type":"update","data":[{"symbol":"AUD/USD","bids":[{"price":0.66434,"qty":1029.92727204}],"asks":[],"checksum":3683975010,"timestamp":"2024-06-01T17:52:37.078769Z"}]}
{"channel":"book","type":"update","data":[{"symbol":"AUD/USD","bids":[{"price":0.66377,"qty":0.00000000},{"price":0.66346,"qty":2506.00000000}],"asks":[],"checksum":1364890384,"timestamp":"2024-06-01T17:52:37.645125Z"}]}
{"channel":"book","type":"update","data":[{"symbol":"AUD/USD","bids":[{"price":0.66449,"qty":0.00000000},{"price":0.66345,"qty":505.00000000}],"asks":[],"checksum":3852106974,"timestamp":"2024-06-01T17:52:37.645217Z"}]}
{"channel":"book","type":"update","data":[{"symbol":"AUD/USD","bids":[{"price":0.66377,"qty":485.66497909}],"asks":[],"checksum":2131613593,"timestamp":"2024-06-01T17:52:37.653566Z"}]}
{"channel":"book","type":"update","data":[{"symbol":"AUD/USD","bids":[{"price":0.66437,"qty":84.05098960}],"asks":[],"checksum":27037573,"timestamp":"2024-06-01T17:52:37.653586Z"}]}
{"channel":"book","type":"update","data":[{"symbol":"AUD/USD","bids":[{"price":0.66438,"qty":1029.86518801}],"asks":[],"checksum":3799950127,"timestamp":"2024-06-01T17:52:37.664272Z"}]}
{"channel":"book","type":"update","data":[{"symbol":"AUD/USD","bids":[{"price":0.66434,"qty":0.00000000},{"price":0.66352,"qty":2804.00000000}],"asks":[],"checksum":1037474894,"timestamp":"2024-06-01T17:52:37.664343Z"}]}
{"channel":"book","type":"update","data":[{"symbol":"AUD/USD","bids":[{"price":0.66433,"qty":0.00000000},{"price":0.66346,"qty":2506.00000000},{"price":0.66435,"qty":5601.21614905}],"asks":[],"checksum":2591329053,"timestamp":"2024-06-01T17:52:37.666954Z"}]}
{"channel":"book","type":"update","data":[{"symbol":"AUD/USD","bids":[],"asks":[{"price":0.66465,"qty":0.00000000},{"price":0.66557,"qty":4434.00000000},{"price":0.66463,"qty":12212.66745688}],"checksum":1812919663,"timestamp":"2024-06-01T17:52:37.682446Z"}]}
{"channel":"book","type":"update","data":[{"symbol":"AUD/USD","bids":[{"price":0.66435,"qty":0.00000000},{"price":0.66346,"qty":2506.00000000},{"price":0.66439,"qty":5600.87892446}],"asks":[],"checksum":875365918,"timestamp":"2024-06-01T17:52:38.262431Z"}]}
{"channel":"book","type":"update","data":[{"symbol":"AUD/USD","bids":[],"asks":[{"price":0.66464,"qty":0.00000000},{"price":0.66557,"qty":4434.00000000},{"price":0.66462,"qty":4887.10496420}],"checksum":1572075813,"timestamp":"2024-06-01T17:52:38.262521Z"}]}
{"channel":"book","type":"update","data":[{"symbol":"AUD/USD","bids":[{"price":0.66438,"qty":0.00000000},{"price":0.66346,"qty":2506.00000000}],"asks":[],"checksum":2653949495,"timestamp":"2024-06-01T17:52:38.267269Z"}]}
{"channel":"book","type":"update","data":[{"symbol":"AUD/USD","bids":[{"price":0.66440,"qty":1029.83422405}],"asks":[],"checksum":1212191619,"timestamp":"2024-06-01T17:52:38.267617Z"}]}
{"channel":"book","type":"update","data":[{"symbol":"AUD/USD","bids":[{"price":0.66439,"qty":0.00000000},{"price":0.66346,"qty":2506.00000000},{"price":0.66433,"qty":5601.38477658}],"asks":[],"checksum":2201692849,"timestamp":"2024-06-01T17:52:38.269964Z"}]}
{"channel":"book","type":"update","data":[{"symbol":"AUD/USD","bids":[{"price":0.66438,"qty":1029.86518801}],"asks":[],"checksum":2964349615,"timestamp":"2024-06-01T17:52:38.297530Z"}]}
{"channel":"book","type":"update","data":[{"symbol":"AUD/USD","bids":[{"price":0.66440,"qty":0.00000000},{"price":0.66352,"qty":2804.00000000}],"asks":[],"checksum":2721193223,"timestamp":"2024-06-01T17:52:38.297846Z"}]}
{"channel":"book","type":"update","data":[{"symbol":"AUD/USD","bids":[{"price":0.66433,"qty":0.00000000},{"price":0.66346,"qty":2506.00000000},{"price":0.66439,"qty":5600.87892446}],"asks":[],"checksum":1572075813,"timestamp":"2024-06-01T17:52:38.925859Z"}]}
{"channel":"book","type":"update","data":[{"symbol":"AUD/USD","bids":[{"price":0.66438,"qty":0.00000000},{"price":0.66346,"qty":2506.00000000}],"asks":[],"checksum":2653949495,"timestamp":"2024-06-01T17:52:38.955033Z"}]}
{"channel":"book","type":"update","data":[{"symbol":"AUD/USD","bids":[{"price":0.66440,"qty":1029.83422405}],"asks":[],"checksum":1212191619,"timestamp":"2024-06-01T17:52:38.955179Z"}]}
{"channel":"book","type":"update","data":[{"symbol":"AUD/USD","bids":[{"price":0.66439,"qty":0.00000000},{"price":0.66346,"qty":2506.00000000},{"price":0.66433,"qty":5601.38477658}],"asks":[],"checksum":2201692849,"timestamp":"2024-06-01T17:52:38.958062Z"}]}
{"channel":"book","type":"update","data":[{"symbol":"AUD/USD","bids":[{"price":0.66440,"qty":0.00000000},{"price":0.66346,"qty":2506.00000000}],"asks":[],"checksum":1446693906,"timestamp":"2024-06-01T17:52:38.982124Z"}]}
{"channel":"book","type":"update","data":[{"symbol":"AUD/USD","bids":[{"price":0.66438,"qty":1029.86518801}],"asks":[],"checksum":2721193223,"timestamp":"2024-06-01T17:52:38.982250Z"}]}
{"channel":"book","type":"update","data":[{"symbol":"AUD/USD","bids":[],"asks":[{"price":0.66545,"qty":0.00000000},{"price":0.66557,"qty":4434.00000000}],"checksum":2424993109,"timestamp":"2024-06-01T17:52:39.244514Z"}]}
{"channel":"book","type":"update","data":[{"symbol":"AUD/USD","bids":[],"asks":[{"price":0.66545,"qty":17596.88444137}],"checksum":4208423887,"timestamp":"2024-06-01T17:52:39.246015Z"}]}
{"channel":"book","type":"update","data":[{"symbol":"AUD/USD","bids":[],"asks":[{"price":0.66521,"qty":0.00000000},{"price":0.66557,"qty":4434.00000000}],"checksum":3433667384,"timestamp":"2024-06-01T17:52:39.312229Z"}]}
{"channel":"book","type":"update","data":[{"symbol":"AUD/USD","bids":[],"asks":[{"price":0.66521,"qty":140.04155347}],"checksum":2645126644,"timestamp":"2024-06-01T17:52:39.313166Z"}]}
{"channel":"book","type":"update","data":[{"symbol":"AUD/USD","bids":[{"price":0.66376,"qty":0.00000000},{"price":0.66346,"qty":2506.00000000}],"asks":[],"checksum":3743524368,"timestamp":"2024-06-01T17:52:39.388836Z"}]}
{"channel":"book","type":"update","data":[{"symbol":"AUD/USD","bids":[{"price":0.66439,"qty":3006.20781915}],"asks":[],"checksum":2346283820,"timestamp":"2024-06-01T17:52:39.396338Z"}]}
{"channel":"book","type":"update","data":[{"symbol":"AUD/USD","bids":[{"price":0.66434,"qty":9575.59192247}],"asks":[],"checksum":3841245633,"timestamp":"2024-06-01T17:52:39.396490Z"}]}
{"channel":"book","type":"update","data":[{"symbol":"AUD/USD","bids":[{"price":0.66378,"qty":12311.12811381}],"asks":[],"checksum":3431363792,"timestamp":"2024-06-01T17:52:39.396550Z"}]}
{"channel":"book","type":"update","data":[{"symbol":"AUD/USD","bids":[{"price":0.66440,"qty":1029.83422405}],"asks":[],"checksum":2738192393,"timestamp":"2024-06-01T17:52:39.409493Z"}]}
{"channel":"book","type":"update","data":[{"symbol":"AUD/USD","bids":[{"price":0.66438,"qty":0.00000000},{"price":0.66361,"qty":47002.00000000}],"asks":[],"checksum":1378997005,"timestamp":"2024-06-01T17:52:39.409572Z"}]}
{"channel":"book","type":"update","data":[{"symbol":"AUD/USD","bids":[],"asks":[{"price":0.66461,"qty":342.43142964}],"checksum":2354300983,"timestamp":"2024-06-01T17:52:39.551848Z"}]}
{"channel":"book","type":"update","data":[{"symbol":"AUD/USD","bids":[{"price":0.66433,"qty":0.00000000},{"price":0.66358,"qty":3003.00000000},{"price":0.66441,"qty":5600.71032739}],"asks":[],"checksum":907911282,"timestamp":"2024-06-01T17:52:39.579276Z"}]}
{"channel":"book","type":"update","data":[{"symbol":"AUD/USD","bids":[],"asks":[{"price":0.66462,"qty":0.00000000},{"price":0.66553,"qty":3013.00000000},{"price":0.66460,"qty":4887.54049515}],"checksum":3114224097,"timestamp":"2024-06-01T17:52:39.579463Z"}]}
{"channel":"book","type":"update","data":[{"symbol":"AUD/USD","bids":[],"asks":[{"price":0.66470,"qty":0.00000000},{"price":0.66553,"qty":3013.00000000}],"checksum":3690816371,"timestamp":"2024-06-01T17:52:39.719774Z"}]}
{"channel":"book","type":"update","data":[{"symbol":"AUD/USD","bids":[],"asks":[{"price":0.66463,"qty":0.00000000},{"price":0.66557,"qty":4434.00000000},{"price":0.66520,"qty":12212.66745688}],"checksum":2252407299,"timestamp":"2024-06-01T17:52:39.750480Z"}]}
{"channel":"book","type":"update","data":[{"symbol":"AUD/USD","bids":[],"asks":[{"price":0.66460,"qty":0.00000000},{"price":0.66557,"qty":4434.00000000},{"price":0.66519,"qty":4887.54224123}],"checksum":363331188,"timestamp":"2024-06-01T17:52:39.753471Z"}]}
{"channel":"book","type":"update","data":[{"symbol":"AUD/USD","bids":[],"asks":[{"price":0.66523,"qty":0.00000000},{"price":0.66557,"qty":4434.00000000}],"checksum":1040702890,"timestamp":"2024-06-01T17:52:39.774066Z"}]}
{"channel":"book","type":"update","data":[{"symbol":"AUD/USD","bids":[],"asks":[{"price":0.66518,"qty":4258.83710000}],"checksum":1768332741,"timestamp":"2024-06-01T17:52:39.774169Z"}]}
{"channel":"book","type":"update","data":[{"symbol":"AUD/USD","bids":[],"asks":[{"price":0.66520,"qty":0.00000000},{"price":0.66557,"qty":4434.00000000},{"price":0.66517,"qty":12212.66745688}],"checksum":833482403,"timestamp":"2024-06-01T17:52:39.782246Z"}]}
{"channel":"book","type":"update","data":[{"symbol":"AUD/USD","bids":[],"asks":[{"price":0.66516,"qty":4258.83710000}],"checksum":2863096640,"timestamp":"2024-06-01T17:52:39.812997Z"}]}
{"channel":"book","type":"update","data":[{"symbol":"AUD/USD","bids":[],"asks":[{"price":0.66518,"qty":0.00000000},{"price":0.66553,"qty":3013.00000000}],"checksum":1923614347,"timestamp":"2024-06-01T17:52:39.813031Z"}]}
{"channel":"book","type":"update","data":[{"symbol":"AUD/USD","bids":[],"asks":[{"price":0.66517,"qty":0.00000000},{"price":0.66557,"qty":4434.00000000},{"price":0.66515,"qty":12212.66745688}],"checksum":1773145281,"timestamp":"2024-06-01T17:52:39.845627Z"}]}
{"channel":"book","type":"update","data":[{"symbol":"AUD/USD","bids":[],"asks":[{"price":0.66516,"qty":0.00000000},{"price":0.66557,"qty":4434.00000000}],"checksum":3873587519,"timestamp":"2024-06-01T17:52:39.849698Z"}]}
{"channel":"book","type":"update","data":[{"symbol":"AUD/USD","bids":[],"asks":[{"price":0.66514,"qty":4258.83710000}],"checksum":3214938955,"timestamp":"2024-06-01T17:52:39.849834Z"}]}
{"channel":"book","type":"update","data":[{"symbol":"AUD/USD","bids":[],"asks":[{"price":0.66515,"qty":0.00000000},{"price":0.66557,"qty":4434.00000000},{"price":0.66513,"qty":12212.66745688}],"checksum":289431436,"timestamp":"2024-06-01T17:52:39.877427Z"}]}
{"channel":"book","type":"update","data":[{"symbol":"AUD/USD","bids":[],"asks":[{"price":0.66512,"qty":4258.83710000}],"checksum":2466429446,"timestamp":"2024-06-01T17:52:39.890450Z"}]}
{"channel":"book","type":"update","data":[{"symbol":"AUD/USD","bids":[],"asks":[{"price":0.66514,"qty":0.00000000},{"price":0.66553,"qty":3013.00000000}],"checksum":868821834,"timestamp":"2024-06-01T17:52:39.890474Z"}]}
{"channel":"book","type":"update","data":[{"symbol":"AUD/USD","bids":[],"asks":[{"price":0.66513,"qty":0.00000000},{"price":0.66557,"qty":4434.00000000},{"price":0.66511,"qty":12212.66745688}],"checksum":3968730171,"timestamp":"2024-06-01T17:52:39.908901Z"}]}
{"channel":"book","type":"update","data":[{"symbol":"AUD/USD","bids":[],"asks":[{"price":0.66512,"qty":0.00000000},{"price":0.66557,"qty":4434.00000000}],"checksum":3700233743,"timestamp":"2024-06-01T17:52:39.922605Z"}]}
{"channel":"book","type":"update","data":[{"symbol":"AUD/USD","bids":[],"asks":[{"price":0.66510,"qty":4258.83710000}],"checksum":4274077322,"timestamp":"2024-06-01T17:52:39.923622Z"}]}
{"channel":"book","type":"update","data":[{"symbol":"AUD/USD","bids":[],"asks":[{"price":0.66511,"qty":0.00000000},{"price":0.66557,"qty":4434.00000000},{"price":0.66509,"qty":12212.66745688}],"checksum":1428426992,"timestamp":"2024-06-01T17:52:39.941022Z"}]}
{"channel":"book","type":"update","data":[{"symbol":"AUD/USD","bids":[],"asks":[{"price":0.66510,"qty":0.00000000},{"price":0.66557,"qty":4434.00000000}],"checksum":982494497,"timestamp":"2024-06-01T17:52:39.964407Z"}]}
{"channel":"book","type":"update","data":[{"symbol":"AUD/USD","bids":[],"asks":[{"price":0.66508,"qty":4258.83710000}],"checksum":3698262906,"timestamp":"2024-06-01T17:52:39.964433Z"}]}
{"channel":"book","type":"update","data":[{"symbol":"AUD/USD","bids":[],"asks":[{"price":0.66509,"qty":0.00000000},{"price":0.66557,"qty":4434.00000000},{"price":0.66507,"qty":12212.66745688}],"checksum":3412993217,"timestamp":"2024-06-01T17:52:39.972606Z"}]}
{"channel":"book","type":"update","data":[{"symbol":"AUD/USD","bids":[],"asks":[{"price":0.66506,"qty":4258.83710000}],"checksum":2008045353,"timestamp":"2024-06-01T17:52:39.993037Z"}]}
{"channel":"book","type":"update","data":[{"symbol":"AUD/USD","bids":[],"asks":[{"price":0.66508,"qty":0.00000000},{"price":0.66553,"qty":3013.00000000}],"checksum":3536085241,"timestamp":"2024-06-01T17:52:39.993066Z"}]}
{"channel":"book","type":"update","data":[{"symbol":"AUD/USD","bids":[],"asks":[{"price":0.66507,"qty":0.00000000},{"price":0.66557,"qty":4434.00000000},{"price":0.66505,"qty":12212.66745688}],"checksum":2473838243,"timestamp":"2024-06-01T17:52:40.004050Z"}]}
{"channel":"book","type":"update","data":[{"symbol":"AUD/USD","bids":[],"asks":[{"price":0.66506,"qty":0.00000000},{"price":0.66557,"qty":4434.00000000}],"checksum":1950241905,"timestamp":"2024-06-01T17:52:40.023703Z"}]}
{"channel":"book","type":"update","data":[{"symbol":"AUD/USD","bids":[],"asks":[{"price":0.66504,"qty":4258.83710000}],"checksum":533493049,"timestamp":"2024-06-01T17:52:40.023730Z"}]}
{"channel":"book","type":"update","data":[{"symbol":"AUD/USD","bids":[],"asks":[{"price":0.66505,"qty":0.00000000},{"price":0.66557,"qty":4434.00000000},{"price":0.66503,"qty":12212.66745688}],"checksum":3951269358,"timestamp":"2024-06-01T17:52:40.036192Z"}]}
{"channel":"book","type":"update","data":[{"symbol":"AUD/USD","bids":[],"asks":[{"price":0.66504,"qty":0.00000000},{"price":0.66557,"qty":4434.00000000}],"checksum":1399236825,"timestamp":"2024-06-01T17:52:40.053044Z"}]}
{"channel":"book","type":"update","data":[{"symbol":"AUD/USD","bids":[],"asks":[{"price":0.66502,"qty":4258.83710000}],"checksum":2477083960,"timestamp":"2024-06-01T17:52:40.053164Z"}]}
{"channel":"book","type":"update","data":[{"symbol":"AUD/USD","bids":[],"asks":[{"price":0.66503,"qty":0.00000000},{"price":0.66557,"qty":4434.00000000},{"price":0.66501,"qty":12212.66745688}],"checksum":374197849,"timestamp":"2024-06-01T17:52:40.067678Z"}]}
{"channel":"book","type":"update","data":[{"symbol":"AUD/USD","bids":[],"asks":[{"price":0.66519,"qty":0.00000000},{"price":0.66557,"qty":4434.00000000},{"price":0.66500,"qty":4887.54423278}],"checksum":1612775721,"timestamp":"2024-06-01T17:52:40.256767Z"}]}
{"channel":"book","type":"update","data":[{"symbol":"AUD/USD","bids":[],"asks":[{"price":0.66501,"qty":0.00000000},{"price":0.66557,"qty":4434.00000000},{"price":0.66499,"qty":12212.66745688}],"checksum":1600835127,"timestamp":"2024-06-01T17:52:40.281760Z"}]}
{"channel":"book","type":"update","data":[{"symbol":"AUD/USD","bids":[],"asks":[{"price":0.66498,"qty":4258.83710000}],"checksum":1513003063,"timestamp":"2024-06-01T17:52:40.442541Z"}]}
{"channel":"book","type":"update","data":[{"symbol":"AUD/USD","bids":[],"asks":[{"price":0.66502,"qty":0.00000000},{"price":0.66553,"qty":3013.00000000}],"checksum":3913414561,"timestamp":"2024-06-01T17:52:40.442602Z"}]}
{"channel":"book","type":"update","data":[{"symbol":"AUD/USD","bids":[],"asks":[{"price":0.66499,"qty":0.00000000},{"price":0.66557,"qty":4434.00000000},{"price":0.66497,"qty":12212.66745688}],"checksum":32287105,"timestamp":"2024-06-01T17:52:40.465525Z"}]}
{"channel":"book","type":"update","data":[{"symbol":"AUD/USD","bids":[],"asks":[{"price":0.66498,"qty":0.00000000},{"price":0.66557,"qty":4434.00000000}],"checksum":3948252267,"timestamp":"2024-06-01T17:52:40.475237Z"}]}
{"channel":"book","type":"update","data":[{"symbol":"AUD/USD","bids":[],"asks":[{"price":0.66496,"qty":4258.83710000}],"checksum":3890910242,"timestamp":"2024-06-01T17:52:40.475444Z"}]}
{"channel":"book","type":"update","data":[{"symbol":"AUD/USD","bids":[],"asks":[{"price":0.66497,"qty":0.00000000},{"price":0.66557,"qty":4434.00000000},{"price":0.66495,"qty":12212.66745688}],"checksum":1508985827,"timestamp":"2024-06-01T17:52:40.497097Z"}]}
{"channel":"book","type":"update","data":[{"symbol":"AUD/USD","bids":[],"asks":[{"price":0.66500,"qty":0.00000000},{"price":0.66557,"qty":4434.00000000},{"price":0.66494,"qty":4887.68473025}],"checksum":2341483452,"timestamp":"2024-06-01T17:52:41.000575Z"}]}
{"channel":"book","type":"update","data":[{"symbol":"AUD/USD","bids":[],"asks":[{"price":0.66495,"qty":0.00000000},{"price":0.66557,"qty":4434.00000000},{"price":0.66493,"qty":12212.66745688}],"checksum":1201145499,"timestamp":"2024-06-01T17:52:41.012979Z"}]}
{"channel":"book","type":"update","data":[{"symbol":"AUD/USD","bids":[],"asks":[{"price":0.66494,"qty":0.00000000},{"price":0.66557,"qty":4434.00000000},{"price":0.66492,"qty":4887.68947300}],"checksum":3196970220,"timestamp":"2024-06-01T17:52:41.702034Z"}]}
{"channel":"book","type":"update","data":[{"symbol":"AUD/USD","bids":[],"asks":[{"price":0.66493,"qty":0.00000000},{"price":0.66557,"qty":4434.00000000},{"price":0.66491,"qty":12212.66745688}],"checksum":686884861,"timestamp":"2024-06-01T17:52:41.711640Z"}]}
{"channel":"book","type":"update","data":[{"symbol":"AUD/USD","bids":[],"asks":[{"price":0.66496,"qty":0.00000000},{"price":0.66557,"qty":4434.00000000}],"checksum":1297139691,"timestamp":"2024-06-01T17:52:41.847850Z"}]}
{"channel":"book","type":"update","data":[{"symbol":"AUD/USD","bids":[],"asks":[{"price":0.66490,"qty":4258.83710000}],"checksum":685453225,"timestamp":"2024-06-01T17:52:41.848204Z"}]}
{"channel":"book","type":"update","data":[{"symbol":"AUD/USD","bids":[],"asks":[{"price":0.66491,"qty":0.00000000},{"price":0.66557,"qty":4434.00000000},{"price":0.66489,"qty":12212.66745688}],"checksum":641586264,"timestamp":"2024-06-01T17:52:41.865063Z"}]}
{"channel":"book","type":"update","data":[{"symbol":"AUD/USD","bids":[],"asks":[{"price":0.66490,"qty":0.00000000},{"price":0.66557,"qty":4434.00000000}],"checksum":2874309829,"timestamp":"2024-06-01T17:52:41.875314Z"}]}
{"channel":"book","type":"update","data":[{"symbol":"AUD/USD","bids":[],"asks":[{"price":0.66488,"qty":4258.83710000}],"checksum":175444569,"timestamp":"2024-06-01T17:52:41.875778Z"}]}
{"channel":"book","type":"update","data":[{"symbol":"AUD/USD","bids":[],"asks":[{"price":0.66489,"qty":0.00000000},{"price":0.66557,"qty":4434.00000000},{"price":0.66487,"qty":12212.66745688}],"checksum":3094863977,"timestamp":"2024-06-01T17:52:41.896717Z"}]}
{"channel":"book","type":"update","data":[{"symbol":"AUD/USD","bids":[],"asks":[{"price":0.66522,"qty":0.00000000},{"price":0.66557,"qty":4434.00000000}],"checksum":196670260,"timestamp":"2024-06-01T17:52:42.251222Z"}]}
{"channel":"book","type":"update","data":[{"symbol":"AUD/USD","bids":[],"asks":[{"price":0.66545,"qty":0.00000000},{"price":0.66559,"qty":5032.00000000}],"checksum":4212351431,"timestamp":"2024-06-01T17:52:42.251541Z"}]}
{"channel":"book","type":"update","data":[{"symbol":"AUD/USD","bids":[],"asks":[{"price":0.66545,"qty":5842.71553717}],"checksum":2587645911,"timestamp":"2024-06-01T17:52:42.253268Z"}]}
{"channel":"book","type":"update","data":[{"symbol":"AUD/USD","bids":[],"asks":[{"price":0.66486,"qty":14737.46411339}],"checksum":3778874971,"timestamp":"2024-06-01T17:52:42.253408Z"}]}
{"channel":"book","type":"update","data":[{"symbol":"AUD/USD","bids":[],"asks":[{"price":0.66487,"qty":0.00000000},{"price":0.66557,"qty":4434.00000000},{"price":0.66485,"qty":12212.66745688}],"checksum":2085644464,"timestamp":"2024-06-01T17:52:42.262039Z"}]}
{"channel":"book","type":"update","data":[{"symbol":"AUD/USD","bids":[],"asks":[{"price":0.66521,"qty":0.00000000},{"price":0.66557,"qty":4434.00000000}],"checksum":1563842259,"timestamp":"2024-06-01T17:52:42.288217Z"}]}
{"channel":"book","type":"update","data":[{"symbol":"AUD/USD","bids":[],"asks":[{"price":0.66486,"qty":14884.75172529}],"checksum":3927202688,"timestamp":"2024-06-01T17:52:42.289351Z"}]}
{"channel":"book","type":"update","data":[{"symbol":"AUD/USD","bids":[],"asks":[{"price":0.66492,"qty":0.00000000},{"price":0.66559,"qty":5032.00000000},{"price":0.66484,"qty":4887.69271714}],"checksum":3157832520,"timestamp":"2024-06-01T17:52:42.360075Z"}]}
{"channel":"book","type":"update","data":[{"symbol":"AUD/USD","bids":[],"asks":[{"price":0.66485,"qty":0.00000000},{"price":0.66559,"qty":5032.00000000},{"price":0.66483,"qty":12212.66745688}],"checksum":1603173556,"timestamp":"2024-06-01T17:52:42.386720Z"}]}
{"channel":"book","type":"update","data":[{"symbol":"AUD/USD","bids":[],"asks":[{"price":0.66488,"qty":0.00000000},{"price":0.66559,"qty":5032.00000000}],"checksum":1699500386,"timestamp":"2024-06-01T17:52:42.849525Z"}]}
{"channel":"book","type":"update","data":[{"symbol":"AUD/USD","bids":[],"asks":[{"price":0.66482,"qty":4258.83710000}],"checksum":338080743,"timestamp":"2024-06-01T17:52:42.849804Z"}]}
{"channel":"book","type":"update","data":[{"symbol":"AUD/USD","bids":[{"price":0.66377,"qty":0.00000000},{"price":0.66358,"qty":3003.00000000}],"asks":[],"checksum":2808587145,"timestamp":"2024-06-01T17:52:42.869165Z"}]}
{"channel":"book","type":"update","data":[{"symbol":"AUD/USD","bids":[{"price":0.66437,"qty":0.00000000},{"price":0.66352,"qty":2804.00000000}],"asks":[],"checksum":394863148,"timestamp":"2024-06-01T17:52:42.869294Z"}]}
{"channel":"book","type":"update","data":[{"symbol":"AUD/USD","bids":[],"asks":[{"price":0.66483,"qty":0.00000000},{"price":0.66559,"qty":5032.00000000},{"price":0.66481,"qty":12212.66745688}],"checksum":1084152733,"timestamp":"2024-06-01T17:52:42.873032Z"}]}
{"channel":"book","type":"update","data":[{"symbol":"AUD/USD","bids":[{"price":0.66442,"qty":111.04555827}],"asks":[],"checksum":1656113281,"timestamp":"2024-06-01T17:52:42.877238Z"}]}
{"channel":"book","type":"update","data":[{"symbol":"AUD/USD","bids":[{"price":0.66379,"qty":323.69756707}],"asks":[],"checksum":2115430078,"timestamp":"2024-06-01T17:52:42.877346Z"}]}
{"channel":"book","type":"update","data":[{"symbol":"AUD/USD","bids":[{"price":0.66441,"qty":0.00000000},{"price":0.66358,"qty":3003.00000000},{"price":0.66443,"qty":5600.54174048}],"asks":[],"checksum":4179342567,"timestamp":"2024-06-01T17:52:43.053352Z"}]}
{"channel":"book","type":"update","data":[{"symbol":"AUD/USD","bids":[],"asks":[{"price":0.66484,"qty":0.00000000},{"price":0.66559,"qty":5032.00000000},{"price":0.66480,"qty":4887.67032717}],"checksum":2611162000,"timestamp":"2024-06-01T17:52:43.053483Z"}]}
{"channel":"book","type":"update","data":[{"symbol":"AUD/USD","bids":[],"asks":[{"price":0.66481,"qty":0.00000000},{"price":0.66559,"qty":5032.00000000},{"price":0.66479,"qty":12212.66745688}],"checksum":3789272448,"timestamp":"2024-06-01T17:52:43.085692Z"}]}
{"channel":"book","type":"update","data":[{"symbol":"AUD/USD","bids":[{"price":0.66439,"qty":0.00000000},{"price":0.66358,"qty":3003.00000000}],"asks":[],"checksum":1254650527,"timestamp":"2024-06-01T17:52:43.114373Z"}]}
{"channel":"book","type":"update","data":[{"symbol":"AUD/USD","bids":[{"price":0.66378,"qty":0.00000000},{"price":0.66352,"qty":2804.00000000}],"asks":[],"checksum":1864406629,"timestamp":"2024-06-01T17:52:43.114386Z"}]}
{"channel":"book","type":"update","data":[{"symbol":"AUD/USD","bids":[{"price":0.66434,"qty":0.00000000},{"price":0.66346,"qty":2506.00000000}],"asks":[],"checksum":2177591913,"timestamp":"2024-06-01T17:52:43.114398Z"}]}
{"channel":"book","type":"update","data":[{"symbol":"AUD/USD","bids":[{"price":0.66442,"qty":5307.04807852}],"asks":[],"checksum":3445962340,"timestamp":"2024-06-01T17:52:43.118320Z"}]}
{"channel":"book","type":"update","data":[{"symbol":"AUD/USD","bids":[{"price":0.66378,"qty":19708.15230996}],"asks":[],"checksum":1497361932,"timestamp":"2024-06-01T17:52:43.118395Z"}]}
{"channel":"book","type":"update","data":[{"symbol":"AUD/USD","bids":[],"asks":[{"price":0.66480,"qty":0.00000000},{"price":0.66559,"qty":5032.00000000},{"price":0.66478,"qty":4887.67081519}],"checksum":269548467,"timestamp":"2024-06-01T17:52:43.735219Z"}]}
{"channel":"book","type":"update","data":[{"symbol":"AUD/USD","bids":[],"asks":[{"price":0.66479,"qty":0.00000000},{"price":0.66559,"qty":5032.00000000},{"price":0.66477,"qty":12212.66745688}],"checksum":3720665478,"timestamp":"2024-06-01T17:52:43.753582Z"}]}
{"channel":"book","type":"update","data":[{"symbol":"AUD/USD","bids":[],"asks":[{"price":0.66482,"qty":0.00000000},{"price":0.66559,"qty":5032.00000000}],"checksum":3962723556,"timestamp":"2024-06-01T17:52:44.244230Z"}]}
{"channel":"book","type":"update","data":[{"symbol":"AUD/USD","bids":[],"asks":[{"price":0.66485,"qty":4258.83710000}],"checksum":410929961,"timestamp":"2024-06-01T17:52:44.244457Z"}]}
{"channel":"book","type":"update","data":[{"symbol":"AUD/USD","bids":[{"price":0.66433,"qty":1029.94268132}],"asks":[],"checksum":4125463417,"timestamp":"2024-06-01T17:52:44.244518Z"}]}
{"channel":"book","type":"update","data":[{"symbol":"AUD/USD","bids":[{"price":0.66440,"qty":0.00000000},{"price":0.66352,"qty":2804.00000000}],"asks":[],"checksum":2421505160,"timestamp":"2024-06-01T17:52:44.244769Z"}]}
{"channel":"book","type":"update","data":[{"symbol":"AUD/USD","bids":[],"asks":[{"price":0.66478,"qty":0.00000000},{"price":0.66559,"qty":5032.00000000},{"price":0.66476,"qty":4887.67169946}],"checksum":1786087524,"timestamp":"2024-06-01T17:52:44.373856Z"}]}
{"channel":"book","type":"update","data":[{"symbol":"AUD/USD","bids":[],"asks":[{"price":0.66477,"qty":0.00000000},{"price":0.66559,"qty":5032.00000000},{"price":0.66475,"qty":12212.66745688}],"checksum":1264734820,"timestamp":"2024-06-01T17:52:44.391647Z"}]}
{"channel":"book","type":"update","data":[{"symbol":"AUD/USD","bids":[],"asks":[{"price":0.66476,"qty":0.00000000},{"price":0.66559,"qty":5032.00000000},{"price":0.66474,"qty":4887.70438887}],"checksum":1529592387,"timestamp":"2024-06-01T17:52:45.046940Z"}]}
{"channel":"book","type":"update","data":[{"symbol":"AUD/USD","bids":[],"asks":[{"price":0.66475,"qty":0.00000000},{"price":0.66559,"qty":5032.00000000},{"price":0.66473,"qty":12212.66745688}],"checksum":3297794712,"timestamp":"2024-06-01T17:52:45.058760Z"}]}
{"channel":"book","type":"update","data":[{"symbol":"AUD/USD","bids":[],"asks":[{"price":0.66545,"qty":0.00000000},{"price":0.66559,"qty":5032.00000000}],"checksum":1105771647,"timestamp":"2024-06-01T17:52:45.198485Z"}]}
{"channel":"book","type":"update","data":[{"symbol":"AUD/USD","bids":[],"asks":[{"price":0.66486,"qty":147.28761190}],"checksum":2030579493,"timestamp":"2024-06-01T17:52:45.198690Z"}]}
{"channel":"book","type":"update","data":[{"symbol":"AUD/USD","bids":[],"asks":[{"price":0.66474,"qty":7893.91220802}],"checksum":4289298235,"timestamp":"2024-06-01T17:52:45.199658Z"}]}
{"channel":"book","type":"update","data":[{"symbol":"AUD/USD","bids":[],"asks":[{"price":0.66545,"qty":17596.88444137}],"checksum":1866560336,"timestamp":"2024-06-01T17:52:45.199928Z"}]}
{"channel":"book","type":"update","data":[{"symbol":"AUD/USD","bids":[],"asks":[{"price":0.66486,"qty":0.00000000},{"price":0.66559,"qty":5032.00000000}],"checksum":1586742220,"timestamp":"2024-06-01T17:52:45.256457Z"}]}
{"channel":"book","type":"update","data":[{"symbol":"AUD/USD","bids":[],"asks":[{"price":0.66544,"qty":59.38977258}],"checksum":2731248480,"timestamp":"2024-06-01T17:52:45.257401Z"}]}
{"channel":"book","type":"update","data":[{"symbol":"AUD/USD","bids":[],"asks":[{"price":0.66485,"qty":0.00000000},{"price":0.66559,"qty":5032.00000000}],"checksum":1109972705,"timestamp":"2024-06-01T17:52:45.281300Z"}]}
{"channel":"book","type":"update","data":[{"symbol":"AUD/USD","bids":[],"asks":[{"price":0.66527,"qty":4258.83710000}],"checksum":818760228,"timestamp":"2024-06-01T17:52:45.281455Z"}]}
{"channel":"book","type":"update","data":[{"symbol":"AUD/USD","bids":[{"price":0.66379,"qty":0.00000000},{"price":0.66346,"qty":2506.00000000}],"asks":[],"checksum":1396268971,"timestamp":"2024-06-01T17:52:45.510799Z"}]}
{"channel":"book","type":"update","data":[{"symbol":"AUD/USD","bids":[{"price":0.66442,"qty":5196.00252025}],"asks":[],"checksum":2413445282,"timestamp":"2024-06-01T17:52:45.510821Z"}]}
{"channel":"book","type":"update","data":[{"symbol":"AUD/USD","bids":[{"price":0.66444,"qty":57.05642093}],"asks":[],"checksum":1641334415,"timestamp":"2024-06-01T17:52:45.518707Z"}]}
{"channel":"book","type":"update","data":[{"symbol":"AUD/USD","bids":[{"price":0.66379,"qty":458.79562936}],"asks":[],"checksum":3425387443,"timestamp":"2024-06-01T17:52:45.518730Z"}]}
{"channel":"book","type":"update","data":[{"symbol":"AUD/USD","bids":[],"asks":[{"price":0.66474,"qty":3006.20781915},{"price":0.66472,"qty":4887.71197199}],"checksum":1775660333,"timestamp":"2024-06-01T17:52:45.675788Z"}]}
{"channel":"book","type":"update","data":[{"symbol":"AUD/USD","bids":[],"asks":[{"price":0.66473,"qty":0.00000000},{"price":0.66557,"qty":4434.00000000},{"price":0.66471,"qty":12212.66745688}],"checksum":48493618,"timestamp":"2024-06-01T17:52:45.702946Z"}]}
{"channel":"book","type":"update","data":[{"symbol":"AUD/USD","bids":[],"asks":[{"price":0.66472,"qty":0.00000000},{"price":0.66557,"qty":4434.00000000},{"price":0.66470,"qty":4887.71336129}],"checksum":3860688630,"timestamp":"2024-06-01T17:52:46.338563Z"}]}
{"channel":"book","type":"update","data":[{"symbol":"AUD/USD","bids":[],"asks":[{"price":0.66471,"qty":0.00000000},{"price":0.66557,"qty":4434.00000000},{"price":0.66469,"qty":12212.66745688}],"checksum":1514535141,"timestamp":"2024-06-01T17:52:46.370887Z"}]}
{"channel":"book","type":"update","data":[{"symbol":"AUD/USD","bids":[{"price":0.66442,"qty":0.00000000},{"price":0.66352,"qty":2804.00000000}],"asks":[],"checksum":646242869,"timestamp":"2024-06-01T17:52:46.692028Z"}]}
{"channel":"book","type":"update","data":[{"symbol":"AUD/USD","bids":[{"price":0.66378,"qty":0.00000000},{"price":0.66346,"qty":2506.00000000}],"asks":[],"checksum":476361768,"timestamp":"2024-06-01T17:52:46.692041Z"}]}
{"channel":"book","type":"update","data":[{"symbol":"AUD/USD","bids":[{"price":0.66443,"qty":0.00000000},{"price":0.66345,"qty":505.00000000},{"price":0.66434,"qty":5601.30046155}],"asks":[],"checksum":3717977117,"timestamp":"2024-06-01T17:52:46.695701Z"}]}
{"channel":"book","type":"update","data":[{"symbol":"AUD/USD","bids":[{"price":0.66376,"qty":12307.38578889}],"asks":[],"checksum":1881134405,"timestamp":"2024-06-01T17:52:46.697655Z"}]}
{"channel":"book","type":"update","data":[{"symbol":"AUD/USD","bids":[{"price":0.66444,"qty":3063.26424008}],"asks":[],"checksum":2721654176,"timestamp":"2024-06-01T17:52:46.697705Z"}]}
{"channel":"book","type":"update","data":[{"symbol":"AUD/USD","bids":[{"price":0.66380,"qty":11765.38662357}],"asks":[],"checksum":3899847870,"timestamp":"2024-06-01T17:52:46.697716Z"}]}
{"channel":"book","type":"update","data":[{"symbol":"AUD/USD","bids":[{"price":0.66433,"qty":0.00000000},{"price":0.66352,"qty":2804.00000000}],"asks":[],"checksum":2027558987,"timestamp":"2024-06-01T17:52:46.698977Z"}]}
{"channel":"book","type":"update","data":[{"symbol":"AUD/USD","bids":[{"price":0.66435,"qty":1029.91171270}],"asks":[],"checksum":2046828800,"timestamp":"2024-06-01T17:52:46.699187Z"}]}
{"channel":"book","type":"update","data":[{"symbol":"AUD/USD","bids":[],"asks":[{"price":0.66470,"qty":0.00000000},{"price":0.66557,"qty":4434.00000000},{"price":0.66468,"qty":4887.72041567}],"checksum":565676216,"timestamp":"2024-06-01T17:52:46.958277Z"}]}
{"channel":"book","type":"update","data":[{"symbol":"AUD/USD","bids":[{"price":0.66434,"qty":0.00000000},{"price":0.66352,"qty":2804.00000000},{"price":0.66445,"qty":5600.37316371}],"asks":[],"checksum":1276164766,"timestamp":"2024-06-01T17:52:46.958473Z"}]}
{"channel":"book","type":"update","data":[{"symbol":"AUD/USD","bids":[{"price":0.66435,"qty":0.00000000},{"price":0.66352,"qty":2804.00000000}],"asks":[],"checksum":1609460456,"timestamp":"2024-06-01T17:52:46.966603Z"}]}
{"channel":"book","type":"update","data":[{"symbol":"AUD/USD","bids":[{"price":0.66433,"qty":1029.94268132}],"asks":[],"checksum":3477505565,"timestamp":"2024-06-01T17:52:46.966788Z"}]}
{"channel":"book","type":"update","data":[{"symbol":"AUD/USD","bids":[],"asks":[{"price":0.66469,"qty":0.00000000},{"price":0.66557,"qty":4434.00000000},{"price":0.66467,"qty":12212.66745688}],"checksum":3773916370,"timestamp":"2024-06-01T17:52:46.981702Z"}]}
{"channel":"book","type":"update","data":[{"symbol":"AUD/USD","bids":[],"asks":[{"price":0.66468,"qty":0.00000000},{"price":0.66557,"qty":4434.00000000},{"price":0.66466,"qty":4887.73406511}],"checksum":1074133673,"timestamp":"2024-06-01T17:52:47.602213Z"}]}
{"channel":"book","type":"update","data":[{"symbol":"AUD/USD","bids":[],"asks":[{"price":0.66467,"qty":0.00000000},{"price":0.66557,"qty":4434.00000000},{"price":0.66465,"qty":12212.66745688}],"checksum":1508278789,"timestamp":"2024-06-01T17:52:47.618342Z"}]}
{"channel":"book","type":"update","data":[{"symbol":"AUD/USD","bids":[],"asks":[{"price":0.66544,"qty":0.00000000},{"price":0.66557,"qty":4434.00000000}],"checksum":1516343518,"timestamp":"2024-06-01T17:52:48.204877Z"}]}
{"channel":"book","type":"update","data":[{"symbol":"AUD/USD","bids":[],"asks":[{"price":0.66526,"qty":140.04155347}],"checksum":1625762271,"timestamp":"2024-06-01T17:52:48.205378Z"}]}
{"channel":"book","type":"update","data":[{"symbol":"AUD/USD","bids":[],"asks":[{"price":0.66474,"qty":0.00000000},{"price":0.66557,"qty":4434.00000000}],"checksum":250354360,"timestamp":"2024-06-01T17:52:48.229542Z"}]}
{"channel":"book","type":"update","data":[{"symbol":"AUD/USD","bids":[],"asks":[{"price":0.66545,"qty":0.00000000},{"price":0.66559,"qty":5032.00000000}],"checksum":2439297936,"timestamp":"2024-06-01T17:52:48.229639Z"}]}
{"channel":"book","type":"update","data":[{"symbol":"AUD/USD","bids":[],"asks":[{"price":0.66526,"qty":23675.94788755}],"checksum":1684758286,"timestamp":"2024-06-01T17:52:48.230128Z"}]}
{"channel":"book","type":"update","data":[{"symbol":"AUD/USD","bids":[],"asks":[{"price":0.66527,"qty":0.00000000},{"price":0.66588,"qty":5806.00000000}],"checksum":3730592220,"timestamp":"2024-06-01T17:52:48.261797Z"}]}
{"channel":"book","type":"update","data":[{"symbol":"AUD/USD","bids":[],"asks":[{"price":0.66525,"qty":4258.83710000}],"checksum":530670947,"timestamp":"2024-06-01T17:52:48.262115Z"}]}
{"channel":"book","type":"update","data":[{"symbol":"AUD/USD","bids":[],"asks":[{"price":0.66466,"qty":0.00000000},{"price":0.66588,"qty":5806.00000000},{"price":0.66464,"qty":4887.73862261}],"checksum":1263081737,"timestamp":"2024-06-01T17:52:48.280034Z"}]}
{"channel":"book","type":"update","data":[{"symbol":"AUD/USD","bids":[],"asks":[{"price":0.66465,"qty":0.00000000},{"price":0.66588,"qty":5806.00000000},{"price":0.66463,"qty":12212.66745688}],"checksum":682792500,"timestamp":"2024-06-01T17:52:48.287041Z"}]}
{"channel":"book","type":"update","data":[{"symbol":"AUD/USD","bids":[{"price":0.66379,"qty":0.00000000},{"price":0.66352,"qty":2804.00000000}],"asks":[],"checksum":3692370473,"timestamp":"2024-06-01T17:52:48.433744Z"}]}
{"channel":"book","type":"update","data":[{"symbol":"AUD/USD","bids":[{"price":0.66444,"qty":3006.20781915}],"asks":[],"checksum":766946536,"timestamp":"2024-06-01T17:52:48.433755Z"}]}
{"channel":"book","type":"update","data":[{"symbol":"AUD/USD","bids":[{"price":0.66381,"qty":512.89680471}],"asks":[],"checksum":929405195,"timestamp":"2024-06-01T17:52:48.439310Z"}]}
{"channel":"book","type":"update","data":[{"symbol":"AUD/USD","bids":[{"price":0.66446,"qty":30.06185226}],"asks":[],"checksum":2355425749,"timestamp":"2024-06-01T17:52:48.439337Z"}]}
{"channel":"book","type":"update","data":[{"symbol":"AUD/USD","bids":[],"asks":[{"price":0.66463,"qty":0.00000000},{"price":0.66588,"qty":5806.00000000},{"price":0.66524,"qty":12212.66745688}],"checksum":1179155107,"timestamp":"2024-06-01T17:52:48.470479Z"}]}
{"channel":"book","type":"update","data":[{"symbol":"AUD/USD","bids":[],"asks":[{"price":0.66464,"qty":0.00000000},{"price":0.66588,"qty":5806.00000000},{"price":0.66523,"qty":4887.81446800}],"checksum":647162016,"timestamp":"2024-06-01T17:52:48.473482Z"}]}
{"channel":"book","type":"update","data":[{"symbol":"AUD/USD","bids":[],"asks":[{"price":0.66525,"qty":0.00000000},{"price":0.66588,"qty":5806.00000000}],"checksum":109084516,"timestamp":"2024-06-01T17:52:48.482029Z"}]}
{"channel":"book","type":"update","data":[{"symbol":"AUD/USD","bids":[],"asks":[{"price":0.66522,"qty":4258.83710000}],"checksum":3792965652,"timestamp":"2024-06-01T17:52:48.482132Z"}]}
{"channel":"book","type":"update","data":[{"symbol":"AUD/USD","bids":[],"asks":[{"price":0.66524,"qty":0.00000000},{"price":0.66588,"qty":5806.00000000},{"price":0.66521,"qty":12212.66745688}],"checksum":1923368539,"timestamp":"2024-06-01T17:52:48.502432Z"}]}
{"channel":"book","type":"update","data":[{"symbol":"AUD/USD","bids":[],"asks":[{"price":0.66523,"qty":0.00000000},{"price":0.66588,"qty":5806.00000000},{"price":0.66520,"qty":4887.81446800}],"checksum":3715879419,"timestamp":"2024-06-01T17:52:48.913997Z"}]}
{"channel":"book","type":"update","data":[{"symbol":"AUD/USD","bids":[],"asks":[{"price":0.66521,"qty":0.00000000},{"price":0.66588,"qty":5806.00000000},{"price":0.66519,"qty":12212.66745688}],"checksum":2968280622,"timestamp":"2024-06-01T17:52:48.927971Z"}]}
{"channel":"book","type":"update","data":[{"symbol":"AUD/USD","bids":[],"asks":[{"price":0.66522,"qty":0.00000000},{"price":0.66588,"qty":5806.00000000}],"checksum":2421676114,"timestamp":"2024-06-01T17:52:49.045305Z"}]}
{"channel":"book","type":"update","data":[{"symbol":"AUD/USD","bids":[],"asks":[{"price":0.66518,"qty":4258.83710000}],"checksum":2376948595,"timestamp":"2024-06-01T17:52:49.045721Z"}]}
{"channel":"book","type":"update","data":[{"symbol":"AUD/USD","bids":[],"asks":[{"price":0.66519,"qty":0.00000000},{"price":0.66588,"qty":5806.00000000},{"price":0.66517,"qty":12212.66745688}],"checksum":3123980631,"timestamp":"2024-06-01T17:52:49.081735Z"}]}
{"channel":"book","type":"update","data":[{"symbol":"AUD/USD","bids":[],"asks":[{"price":0.66516,"qty":4258.83710000}],"checksum":3190016123,"timestamp":"2024-06-01T17:52:49.085872Z"}]}
{"channel":"book","type":"update","data":[{"symbol":"AUD/USD","bids":[],"asks":[{"price":0.66518,"qty":0.00000000},{"price":0.66559,"qty":5032.00000000}],"checksum":1236840114,"timestamp":"2024-06-01T17:52:49.085905Z"}]}
{"channel":"book","type":"update","data":[{"symbol":"AUD/USD","bids":[],"asks":[{"price":0.66517,"qty":0.00000000},{"price":0.66588,"qty":5806.00000000},{"price":0.66515,"qty":12212.66745688}],"checksum":2751200059,"timestamp":"2024-06-01T17:52:49.113859Z"}]}
{"channel":"book","type":"update","data":[{"symbol":"AUD/USD","bids":[],"asks":[{"price":0.66520,"qty":0.00000000},{"price":0.66588,"qty":5806.00000000},{"price":0.66514,"qty":4887.82232650}],"checksum":3341704545,"timestamp":"2024-06-01T17:52:49.538758Z"}]}
{"channel":"book","type":"update","data":[{"symbol":"AUD/USD","bids":[],"asks":[{"price":0.66515,"qty":0.00000000},{"price":0.66588,"qty":5806.00000000},{"price":0.66513,"qty":12212.66745688}],"checksum":650572634,"timestamp":"2024-06-01T17:52:49.570287Z"}]}
{"channel":"book","type":"update","data":[{"symbol":"AUD/USD","bids":[],"asks":[{"price":0.66516,"qty":0.00000000},{"price":0.66588,"qty":5806.00000000}],"checksum":930627414,"timestamp":"2024-06-01T17:52:50.038641Z"}]}
{"channel":"book","type":"update","data":[{"symbol":"AUD/USD","bids":[],"asks":[{"price":0.66512,"qty":4258.83710000}],"checksum":2354030245,"timestamp":"2024-06-01T17:52:50.038684Z"}]}
{"channel":"book","type":"update","data":[{"symbol":"AUD/USD","bids":[],"asks":[{"price":0.66513,"qty":0.00000000},{"price":0.66588,"qty":5806.00000000},{"price":0.66511,"qty":12212.66745688}],"checksum":297405452,"timestamp":"2024-06-01T17:52:50.055768Z"}]}
{"channel":"book","type":"update","data":[{"symbol":"AUD/USD","bids":[],"asks":[{"price":0.66512,"qty":0.00000000},{"price":0.66588,"qty":5806.00000000}],"checksum":3487848467,"timestamp":"2024-06-01T17:52:50.064868Z"}]}
{"channel":"book","type":"update","data":[{"symbol":"AUD/USD","bids":[],"asks":[{"price":0.66510,"qty":4258.83710000}],"checksum":711481352,"timestamp":"2024-06-01T17:52:50.064908Z"}]}
{"channel":"book","type":"update","data":[{"symbol":"AUD/USD","bids":[],"asks":[{"price":0.66511,"qty":0.00000000},{"price":0.66588,"qty":5806.00000000},{"price":0.66509,"qty":12212.66745688}],"checksum":594440030,"timestamp":"2024-06-01T17:52:50.087650Z"}]}
{"channel":"book","type":"update","data":[{"symbol":"AUD/USD","bids":[],"asks":[{"price":0.66514,"qty":0.00000000},{"price":0.66588,"qty":5806.00000000},{"price":0.66508,"qty":4887.82511321}],"checksum":2446446380,"timestamp":"2024-06-01T17:52:50.196352Z"}]}
{"channel":"book","type":"update","data":[{"symbol":"AUD/USD","bids":[],"asks":[{"price":0.66509,"qty":0.00000000},{"price":0.66588,"qty":5806.00000000},{"price":0.66507,"qty":12212.66745688}],"checksum":4279174609,"timestamp":"2024-06-01T17:52:50.211007Z"}]}
{"channel":"book","type":"update","data":[{"symbol":"AUD/USD","bids":[{"price":0.66444,"qty":0.00000000},{"price":0.66358,"qty":3003.00000000}],"asks":[],"checksum":3746728153,"timestamp":"2024-06-01T17:52:50.344194Z"}]}
{"channel":"book","type":"update","data":[{"symbol":"AUD/USD","bids":[{"price":0.66376,"qty":0.00000000},{"price":0.66352,"qty":2804.00000000}],"asks":[],"checksum":3368961816,"timestamp":"2024-06-01T17:52:50.344206Z"}]}
{"channel":"book","type":"update","data":[{"symbol":"AUD/USD","bids":[{"price":0.66380,"qty":0.00000000},{"price":0.66346,"qty":2506.00000000}],"asks":[],"checksum":2397545653,"timestamp":"2024-06-01T17:52:50.344315Z"}]}
{"channel":"book","type":"update","data":[{"symbol":"AUD/USD","bids":[{"price":0.66445,"qty":0.00000000},{"price":0.66345,"qty":505.00000000},{"price":0.66434,"qty":5601.30046155}],"asks":[],"checksum":565034324,"timestamp":"2024-06-01T17:52:50.347950Z"}]}
{"channel":"book","type":"update","data":[{"symbol":"AUD/USD","bids":[{"price":0.66376,"qty":32846.92051660}],"asks":[],"checksum":1068976307,"timestamp":"2024-06-01T17:52:50.350273Z"}]}
{"channel":"book","type":"update","data":[{"symbol":"AUD/USD","bids":[{"price":0.66446,"qty":3036.26967141}],"asks":[],"checksum":396469070,"timestamp":"2024-06-01T17:52:50.350344Z"}]}
{"channel":"book","type":"update","data":[{"symbol":"AUD/USD","bids":[{"price":0.66434,"qty":0.00000000},{"price":0.66346,"qty":2506.00000000},{"price":0.66447,"qty":5600.20459708}],"asks":[],"checksum":4214789195,"timestamp":"2024-06-01T17:52:50.812128Z"}]}
{"channel":"book","type":"update","data":[{"symbol":"AUD/USD","bids":[],"asks":[{"price":0.66508,"qty":0.00000000},{"price":0.66588,"qty":5806.00000000},{"price":0.66506,"qty":4887.63745336}],"checksum":3690779371,"timestamp":"2024-06-01T17:52:50.812311Z"}]}
{"channel":"book","type":"update","data":[{"symbol":"AUD/USD","bids":[],"asks":[{"price":0.66507,"qty":0.00000000},{"price":0.66588,"qty":5806.00000000},{"price":0.66505,"qty":12212.66745688}],"checksum":29744050,"timestamp":"2024-06-01T17:52:50.850090Z"}]}
{"channel":"book","type":"update","data":[{"symbol":"AUD/USD","bids":[],"asks":[{"price":0.66526,"qty":23535.90633408}],"checksum":3616540027,"timestamp":"2024-06-01T17:52:51.152204Z"}]}
{"channel":"book","type":"update","data":[{"symbol":"AUD/USD","bids":[],"asks":[{"price":0.66504,"qty":206.02937419}],"checksum":1276754383,"timestamp":"2024-06-01T17:52:51.153225Z"}]}
{"channel":"book","type":"update","data":[{"symbol":"AUD/USD","bids":[],"asks":[{"price":0.66505,"qty":0.00000000},{"price":0.66559,"qty":5032.00000000},{"price":0.66503,"qty":12212.66745688}],"checksum":3745989341,"timestamp":"2024-06-01T17:52:51.183996Z"}]}
{"channel":"book","type":"update","data":[{"symbol":"AUD/USD","bids":[],"asks":[{"price":0.66526,"qty":0.00000000},{"price":0.66559,"qty":5032.00000000}],"checksum":2118875454,"timestamp":"2024-06-01T17:52:51.206151Z"}]}
{"channel":"book","type":"update","data":[{"symbol":"AUD/USD","bids":[],"asks":[{"price":0.66504,"qty":29607.56385539}],"checksum":2571579629,"timestamp":"2024-06-01T17:52:51.207256Z"}]}
{"channel":"book","type":"update","data":[{"symbol":"AUD/USD","bids":[],"asks":[{"price":0.66510,"qty":0.00000000},{"price":0.66588,"qty":5806.00000000}],"checksum":2998191367,"timestamp":"2024-06-01T17:52:51.455520Z"}]}
{"channel":"book","type":"update","data":[{"symbol":"AUD/USD","bids":[],"asks":[{"price":0.66502,"qty":4258.83710000}],"checksum":1934548727,"timestamp":"2024-06-01T17:52:51.455746Z"}]}
{"channel":"book","type":"update","data":[{"symbol":"AUD/USD","bids":[],"asks":[{"price":0.66503,"qty":0.00000000},{"price":0.66588,"qty":5806.00000000},{"price":0.66501,"qty":12212.66745688}],"checksum":2217008807,"timestamp":"2024-06-01T17:52:51.487420Z"}]}
{"channel":"book","type":"update","data":[{"symbol":"AUD/USD","bids":[],"asks":[{"price":0.66500,"qty":4258.83710000}],"checksum":2762478006,"timestamp":"2024-06-01T17:52:51.509000Z"}]}
{"channel":"book","type":"update","data":[{"symbol":"AUD/USD","bids":[],"asks":[{"price":0.66502,"qty":0.00000000},{"price":0.66559,"qty":5032.00000000}],"checksum":3683591772,"timestamp":"2024-06-01T17:52:51.509097Z"}]}
{"channel":"book","type":"update","data":[{"symbol":"AUD/USD","bids":[],"asks":[{"price":0.66501,"qty":0.00000000},{"price":0.66588,"qty":5806.00000000},{"price":0.66499,"qty":12212.66745688}],"checksum":4090156591,"timestamp":"2024-06-01T17:52:51.518945Z"}]}
{"channel":"book","type":"update","data":[{"symbol":"AUD/USD","bids":[{"price":0.66447,"qty":0.00000000},{"price":0.66346,"qty":2506.00000000},{"price":0.66448,"qty":5600.12031758}],"asks":[],"checksum":2162054065,"timestamp":"2024-06-01T17:52:51.527290Z"}]}
{"channel":"book","type":"update","data":[{"symbol":"AUD/USD","bids":[],"asks":[{"price":0.66506,"qty":0.00000000},{"price":0.66588,"qty":5806.00000000},{"price":0.66498,"qty":4887.59700105}],"checksum":2337493333,"timestamp":"2024-06-01T17:52:51.527452Z"}]}
{"channel":"book","type":"update","data":[{"symbol":"AUD/USD","bids":[{"price":0.66448,"qty":0.00000000},{"price":0.66346,"qty":2506.00000000},{"price":0.66447,"qty":5600.20459708}],"asks":[],"checksum":4165457099,"timestamp":"2024-06-01T17:52:51.531096Z"}]}
{"channel":"book","type":"update","data":[{"symbol":"AUD/USD","bids":[],"asks":[{"price":0.66499,"qty":0.00000000},{"price":0.66588,"qty":5806.00000000},{"price":0.66497,"qty":12212.66745688}],"checksum":180301191,"timestamp":"2024-06-01T17:52:51.550389Z"}]}
{"channel":"book","type":"update","data":[{"symbol":"AUD/USD","bids":[{"price":0.66447,"qty":0.00000000},{"price":0.66346,"qty":2506.00000000},{"price":0.66448,"qty":5600.12031758}],"asks":[],"checksum":2041292825,"timestamp":"2024-06-01T17:52:52.233134Z"}]}
{"channel":"book","type":"update","data":[{"symbol":"AUD/USD","bids":[],"asks":[{"price":0.66498,"qty":0.00000000},{"price":0.66588,"qty":5806.00000000},{"price":0.66496,"qty":4887.59700105}],"checksum":1744090758,"timestamp":"2024-06-01T17:52:52.233187Z"}]}
{"channel":"book","type":"update","data":[{"symbol":"AUD/USD","bids":[{"price":0.66448,"qty":0.00000000},{"price":0.66346,"qty":2506.00000000},{"price":0.66447,"qty":5600.20459708}],"asks":[],"checksum":350237464,"timestamp":"2024-06-01T17:52:52.238507Z"}]}
{"channel":"book","type":"update","data":[{"symbol":"AUD/USD","bids":[],"asks":[{"price":0.66497,"qty":0.00000000},{"price":0.66588,"qty":5806.00000000},{"price":0.66495,"qty":12212.66745688}],"checksum":1319292710,"timestamp":"2024-06-01T17:52:52.248287Z"}]}
{"channel":"book","type":"update","data":[{"symbol":"AUD/USD","bids":[],"asks":[{"price":0.66500,"qty":0.00000000},{"price":0.66588,"qty":5806.00000000}],"checksum":2874189320,"timestamp":"2024-06-01T17:52:52.457965Z"}]}
{"channel":"book","type":"update","data":[{"symbol":"AUD/USD","bids":[],"asks":[{"price":0.66494,"qty":4258.83710000}],"checksum":4204663519,"timestamp":"2024-06-01T17:52:52.457986Z"}]}
{"channel":"book","type":"update","data":[{"symbol":"AUD/USD","bids":[],"asks":[{"price":0.66495,"qty":0.00000000},{"price":0.66588,"qty":5806.00000000},{"price":0.66493,"qty":12212.66745688}],"checksum":446620897,"timestamp":"2024-06-01T17:52:52.492082Z"}]}
{"channel":"book","type":"update","data":[{"symbol":"AUD/USD","bids":[],"asks":[{"price":0.66494,"qty":0.00000000},{"price":0.66588,"qty":5806.00000000}],"checksum":2709708160,"timestamp":"2024-06-01T17:52:52.520097Z"}]}
{"channel":"book","type":"update","data":[{"symbol":"AUD/USD","bids":[],"asks":[{"price":0.66492,"qty":4258.83710000}],"checksum":3635223907,"timestamp":"2024-06-01T17:52:52.520265Z"}]}
{"channel":"book","type":"update","data":[{"symbol":"AUD/USD","bids":[],"asks":[{"price":0.66493,"qty":0.00000000},{"price":0.66588,"qty":5806.00000000},{"price":0.66491,"qty":12212.66745688}],"checksum":4280051617,"timestamp":"2024-06-01T17:52:52.555210Z"}]}
{"channel":"book","type":"update","data":[{"symbol":"AUD/USD","bids":[{"price":0.66447,"qty":0.00000000},{"price":0.66346,"qty":2506.00000000},{"price":0.66448,"qty":5600.12031758}],"asks":[],"checksum":2349392447,"timestamp":"2024-06-01T17:52:52.964079Z"}]}
{"channel":"book","type":"update","data":[{"symbol":"AUD/USD","bids":[],"asks":[{"price":0.66496,"qty":0.00000000},{"price":0.66588,"qty":5806.00000000},{"price":0.66490,"qty":4887.43623565}],"checksum":3761734891,"timestamp":"2024-06-01T17:52:52.964126Z"}]}
{"channel":"book","type":"update","data":[{"symbol":"AUD/USD","bids":[],"asks":[{"price":0.66491,"qty":0.00000000},{"price":0.66588,"qty":5806.00000000},{"price":0.66489,"qty":12212.66745688}],"checksum":3834230683,"timestamp":"2024-06-01T17:52:52.980647Z"}]}
{"channel":"book","type":"update","data":[{"symbol":"AUD/USD","bids":[{"price":0.66446,"qty":3006.20781915}],"asks":[],"checksum":2453014721,"timestamp":"2024-06-01T17:52:53.477118Z"}]}
{"channel":"book","type":"update","data":[{"symbol":"AUD/USD","bids":[{"price":0.66381,"qty":0.00000000},{"price":0.66346,"qty":2506.00000000}],"asks":[],"checksum":583289642,"timestamp":"2024-06-01T17:52:53.477148Z"}]}
{"channel":"book","type":"update","data":[{"symbol":"AUD/USD","bids":[{"price":0.66448,"qty":0.00000000},{"price":0.66345,"qty":505.00000000},{"price":0.66447,"qty":5600.20459708}],"asks":[],"checksum":889250284,"timestamp":"2024-06-01T17:52:53.480786Z"}]}
{"channel":"book","type":"update","data":[{"symbol":"AUD/USD","bids":[{"price":0.66448,"qty":30.06185226}],"asks":[],"checksum":1988575583,"timestamp":"2024-06-01T17:52:53.486333Z"}]}
{"channel":"book","type":"update","data":[{"symbol":"AUD/USD","bids":[{"price":0.66377,"qty":512.89680471}],"asks":[],"checksum":1495782232,"timestamp":"2024-06-01T17:52:53.486476Z"}]}
{"channel":"book","type":"update","data":[{"symbol":"AUD/USD","bids":[],"asks":[{"price":0.66490,"qty":0.00000000},{"price":0.66588,"qty":5806.00000000},{"price":0.66488,"qty":4887.42891119}],"checksum":651463033,"timestamp":"2024-06-01T17:52:53.795123Z"}]}
{"channel":"book","type":"update","data":[{"symbol":"AUD/USD","bids":[],"asks":[{"price":0.66489,"qty":0.00000000},{"price":0.66588,"qty":5806.00000000},{"price":0.66487,"qty":12212.66745688}],"checksum":1826761784,"timestamp":"2024-06-01T17:52:53.830049Z"}]}
{"channel":"book","type":"update","data":[{"symbol":"AUD/USD","bids":[],"asks":[{"price":0.66492,"qty":0.00000000},{"price":0.66588,"qty":5806.00000000}],"checksum":1860066190,"timestamp":"2024-06-01T17:52:53.870716Z"}]}
{"channel":"book","type":"update","data":[{"symbol":"AUD/USD","bids":[],"asks":[{"price":0.66486,"qty":4258.83710000}],"checksum":3715573422,"timestamp":"2024-06-01T17:52:53.870852Z"}]}
{"channel":"book","type":"update","data":[{"symbol":"AUD/USD","bids":[],"asks":[{"price":0.66487,"qty":0.00000000},{"price":0.66588,"qty":5806.00000000},{"price":0.66485,"qty":12212.66745688}],"checksum":742879391,"timestamp":"2024-06-01T17:52:53.893260Z"}]}
{"channel":"book","type":"update","data":[{"symbol":"AUD/USD","bids":[],"asks":[{"price":0.66504,"qty":29401.53448120}],"checksum":1103862221,"timestamp":"2024-06-01T17:52:54.055389Z"}]}
{"channel":"book","type":"update","data":[{"symbol":"AUD/USD","bids":[],"asks":[{"price":0.66486,"qty":4398.87865347}],"checksum":2957402666,"timestamp":"2024-06-01T17:52:54.056469Z"}]}
{"channel":"book","type":"update","data":[{"symbol":"AUD/USD","bids":[{"price":0.66376,"qty":0.00000000},{"price":0.66352,"qty":2804.00000000}],"asks":[],"checksum":2891392997,"timestamp":"2024-06-01T17:52:54.071158Z"}]}
{"channel":"book","type":"update","data":[{"symbol":"AUD/USD","bids":[{"price":0.66446,"qty":0.00000000},{"price":0.66346,"qty":2506.00000000}],"asks":[],"checksum":667127051,"timestamp":"2024-06-01T17:52:54.071227Z"}]}
{"channel":"book","type":"update","data":[{"symbol":"AUD/USD","bids":[{"price":0.66447,"qty":0.00000000},{"price":0.66345,"qty":505.00000000},{"price":0.66434,"qty":5601.30046155}],"asks":[],"checksum":3505369937,"timestamp":"2024-06-01T17:52:54.074160Z"}]}
{"channel":"book","type":"update","data":[{"symbol":"AUD/USD","bids":[{"price":0.66376,"qty":29283.74423243}],"asks":[],"checksum":2451339171,"timestamp":"2024-06-01T17:52:54.076377Z"}]}
{"channel":"book","type":"update","data":[{"symbol":"AUD/USD","bids":[],"asks":[{"price":0.66504,"qty":0.00000000},{"price":0.66588,"qty":5806.00000000}],"checksum":518872535,"timestamp":"2024-06-01T17:52:54.168238Z"}]}
{"channel":"book","type":"update","data":[{"symbol":"AUD/USD","bids":[],"asks":[{"price":0.66545,"qty":5842.71553717}],"checksum":4256437683,"timestamp":"2024-06-01T17:52:54.169523Z"}]}
{"channel":"book","type":"update","data":[{"symbol":"AUD/USD","bids":[],"asks":[{"price":0.66484,"qty":14737.46411339}],"checksum":4014304291,"timestamp":"2024-06-01T17:52:54.169705Z"}]}
{"channel":"book","type":"update","data":[{"symbol":"AUD/USD","bids":[],"asks":[{"price":0.66485,"qty":0.00000000},{"price":0.66559,"qty":5032.00000000},{"price":0.66483,"qty":12212.66745688}],"checksum":4276315470,"timestamp":"2024-06-01T17:52:54.200380Z"}]}
{"channel":"book","type":"update","data":[{"symbol":"AUD/USD","bids":[],"asks":[{"price":0.66488,"qty":0.00000000},{"price":0.66559,"qty":5032.00000000},{"price":0.66482,"qty":4893.95056195}],"checksum":169556719,"timestamp":"2024-06-01T17:52:54.616631Z"}]}
{"channel":"book","type":"update","data":[{"symbol":"AUD/USD","bids":[],"asks":[{"price":0.66483,"qty":0.00000000},{"price":0.66559,"qty":5032.00000000},{"price":0.66481,"qty":12212.66745688}],"checksum":1666012680,"timestamp":"2024-06-01T17:52:54.625803Z"}]}
{"channel":"book","type":"update","data":[{"symbol":"AUD/USD","bids":[{"price":0.66433,"qty":0.00000000},{"price":0.66346,"qty":2506.00000000}],"asks":[],"checksum":2381587650,"timestamp":"2024-06-01T17:52:54.864320Z"}]}
{"channel":"book","type":"update","data":[{"symbol":"AUD/USD","bids":[],"asks":[{"price":0.66483,"qty":4258.83710000}],"checksum":1754711387,"timestamp":"2024-06-01T17:52:54.864533Z"}]}
{"channel":"book","type":"update","data":[{"symbol":"AUD/USD","bids":[{"price":0.66435,"qty":1029.91171270}],"asks":[],"checksum":645173853,"timestamp":"2024-06-01T17:52:54.864549Z"}]}
{"channel":"book","type":"update","data":[{"symbol":"AUD/USD","bids":[],"asks":[{"price":0.66486,"qty":140.04155347}],"checksum":3493508103,"timestamp":"2024-06-01T17:52:54.864658Z"}]}
{"channel":"book","type":"update","data":[{"symbol":"AUD/USD","bids":[{"price":0.66434,"qty":0.00000000},{"price":0.66346,"qty":2506.00000000},{"price":0.66433,"qty":5601.38477658}],"asks":[],"checksum":1656599820,"timestamp":"2024-06-01T17:52:54.869695Z"}]}
{"channel":"book","type":"update","data":[{"symbol":"AUD/USD","bids":[{"price":0.66433,"qty":0.00000000},{"price":0.66346,"qty":2506.00000000},{"price":0.66436,"qty":5601.13183910}],"asks":[],"checksum":2340289300,"timestamp":"2024-06-01T17:52:55.428088Z"}]}
{"channel":"book","type":"update","data":[{"symbol":"AUD/USD","bids":[],"asks":[{"price":0.66482,"qty":0.00000000},{"price":0.66557,"qty":4434.00000000},{"price":0.66480,"qty":4894.18707130}],"checksum":2483762123,"timestamp":"2024-06-01T17:52:55.428225Z"}]}
{"channel":"book","type":"update","data":[{"symbol":"AUD/USD","bids":[],"asks":[{"price":0.66481,"qty":0.00000000},{"price":0.66557,"qty":4434.00000000},{"price":0.66479,"qty":12212.66745688}],"checksum":2493273084,"timestamp":"2024-06-01T17:52:55.443857Z"}]}
{"channel":"book","type":"update","data":[{"symbol":"AUD/USD","bids":[{"price":0.66377,"qty":0.00000000},{"price":0.66346,"qty":2506.00000000}],"asks":[],"checksum":412484604,"timestamp":"2024-06-01T17:52:56.102697Z"}]}
{"channel":"book","type":"update","data":[{"symbol":"AUD/USD","bids":[{"price":0.66448,"qty":0.00000000},{"price":0.66345,"qty":505.00000000}],"asks":[],"checksum":1186920970,"timestamp":"2024-06-01T17:52:56.102890Z"}]}
{"channel":"book","type":"update","data":[{"symbol":"AUD/USD","bids":[{"price":0.66435,"qty":0.00000000},{"price":0.66336,"qty":353.60339055}],"asks":[],"checksum":4197017532,"timestamp":"2024-06-01T17:52:56.245296Z"}]}
{"channel":"book","type":"update","data":[{"symbol":"AUD/USD","bids":[{"price":0.66437,"qty":1029.88074595}],"asks":[],"checksum":2361968009,"timestamp":"2024-06-01T17:52:56.245525Z"}]}
{"channel":"book","type":"update","data":[{"symbol":"AUD/USD","bids":[{"price":0.66436,"qty":0.00000000},{"price":0.66336,"qty":353.60339055},{"price":0.66433,"qty":5601.38477658}],"asks":[],"checksum":4123197072,"timestamp":"2024-06-01T17:52:56.248506Z"}]}
{"channel":"book","type":"update","data":[{"symbol":"AUD/USD","bids":[{"price":0.66437,"qty":0.00000000},{"price":0.66336,"qty":353.60339055}],"asks":[],"checksum":1014037540,"timestamp":"2024-06-01T17:52:56.258043Z"}]}
{"channel":"book","type":"update","data":[{"symbol":"AUD/USD","bids":[{"price":0.66434,"qty":1029.92727204}],"asks":[],"checksum":1126461289,"timestamp":"2024-06-01T17:52:56.258087Z"}]}
{"channel":"book","type":"update","data":[{"symbol":"AUD/USD","bids":[{"price":0.66433,"qty":0.00000000},{"price":0.66336,"qty":353.60339055},{"price":0.66435,"qty":5601.21614905}],"asks":[],"checksum":2852873370,"timestamp":"2024-06-01T17:52:56.263449Z"}]}
{"channel":"book","type":"update","data":[{"symbol":"AUD/USD","bids":[{"price":0.66377,"qty":485.66497909}],"asks":[],"checksum":4068303149,"timestamp":"2024-06-01T17:52:56.345492Z"}]}
{"channel":"book","type":"update","data":[{"symbol":"AUD/USD","bids":[{"price":0.66436,"qty":84.05098960}],"asks":[],"checksum":1259732262,"timestamp":"2024-06-01T17:52:56.345506Z"}]}
{"channel":"book","type":"update","data":[{"symbol":"AUD/USD","bids":[],"asks":[{"price":0.66486,"qty":0.00000000},{"price":0.66557,"qty":4434.00000000}],"checksum":669359698,"timestamp":"2024-06-01T17:52:57.014710Z"}]}
{"channel":"book","type":"update","data":[{"symbol":"AUD/USD","bids":[],"asks":[{"price":0.66478,"qty":59.38977258}],"checksum":2926651096,"timestamp":"2024-06-01T17:52:57.015553Z"}]}
{"channel":"book","type":"update","data":[{"symbol":"AUD/USD","bids":[],"asks":[{"price":0.66479,"qty":0.00000000},{"price":0.66557,"qty":4434.00000000},{"price":0.66477,"qty":12212.66745688}],"checksum":1145176831,"timestamp":"2024-06-01T17:52:57.051884Z"}]}
{"channel":"book","type":"update","data":[{"symbol":"AUD/USD","bids":[{"price":0.66435,"qty":0.00000000},{"price":0.66346,"qty":2506.00000000},{"price":0.66437,"qty":5601.04753168}],"asks":[],"checksum":263908649,"timestamp":"2024-06-01T17:52:57.089334Z"}]}
{"channel":"book","type":"update","data":[{"symbol":"AUD/USD","bids":[],"asks":[{"price":0.66480,"qty":0.00000000},{"price":0.66557,"qty":4434.00000000},{"price":0.66476,"qty":4894.17960176}],"checksum":3588293392,"timestamp":"2024-06-01T17:52:57.089405Z"}]}
{"channel":"book","type":"update","data":[{"symbol":"AUD/USD","bids":[],"asks":[{"price":0.66477,"qty":0.00000000},{"price":0.66557,"qty":4434.00000000},{"price":0.66475,"qty":12212.66745688}],"checksum":1550504489,"timestamp":"2024-06-01T17:52:57.114972Z"}]}
{"channel":"book","type":"update","data":[{"symbol":"AUD/USD","bids":[],"asks":[{"price":0.66545,"qty":0.00000000},{"price":0.66557,"qty":4434.00000000}],"checksum":2796916598,"timestamp":"2024-06-01T17:52:57.183228Z"}]}
{"channel":"book","type":"update","data":[{"symbol":"AUD/USD","bids":[],"asks":[{"price":0.66484,"qty":0.00000000},{"price":0.66559,"qty":5032.00000000}],"checksum":1417011500,"timestamp":"2024-06-01T17:52:57.183432Z"}]}
{"channel":"book","type":"update","data":[{"symbol":"AUD/USD","bids":[],"asks":[{"price":0.66478,"qty":5998.41166529}],"checksum":1265582944,"timestamp":"2024-06-01T17:52:57.184829Z"}]}
{"channel":"book","type":"update","data":[{"symbol":"AUD/USD","bids":[],"asks":[{"price":0.66545,"qty":14649.74998659}],"checksum":1139654164,"timestamp":"2024-06-01T17:52:57.184897Z"}]}
{"channel":"book","type":"update","data":[{"symbol":"AUD/USD","bids":[{"price":0.66434,"qty":0.00000000},{"price":0.66346,"qty":2506.00000000}],"asks":[],"checksum":1302812946,"timestamp":"2024-06-01T17:52:57.239803Z"}]}
{"channel":"book","type":"update","data":[{"symbol":"AUD/USD","bids":[],"asks":[{"price":0.66527,"qty":4258.83710000}],"checksum":3224391067,"timestamp":"2024-06-01T17:52:57.239944Z"}]}
{"channel":"book","type":"update","data":[{"symbol":"AUD/USD","bids":[],"asks":[{"price":0.66483,"qty":0.00000000},{"price":0.66557,"qty":4434.00000000}],"checksum":3537116553,"timestamp":"2024-06-01T17:52:57.239960Z"}]}
{"channel":"book","type":"update","data":[{"symbol":"AUD/USD","bids":[{"price":0.66438,"qty":1029.86518801}],"asks":[],"checksum":4131222389,"timestamp":"2024-06-01T17:52:57.240019Z"}]}
{"channel":"book","type":"update","data":[{"symbol":"AUD/USD","bids":[{"price":0.66437,"qty":0.00000000},{"price":0.66346,"qty":2506.00000000},{"price":0.66433,"qty":5601.38477658}],"asks":[],"checksum":878029742,"timestamp":"2024-06-01T17:52:57.243421Z"}]}
{"channel":"book","type":"update","data":[{"symbol":"AUD/USD","bids":[{"price":0.66376,"qty":0.00000000},{"price":0.66346,"qty":2506.00000000}],"asks":[],"checksum":627366388,"timestamp":"2024-06-01T17:52:57.526566Z"}]}
{"channel":"book","type":"update","data":[{"symbol":"AUD/USD","bids":[{"price":0.66436,"qty":9659.64291207}],"asks":[],"checksum":3659332438,"timestamp":"2024-06-01T17:52:57.531825Z"}]}
{"channel":"book","type":"update","data":[{"symbol":"AUD/USD","bids":[{"price":0.66378,"qty":19708.15230996}],"asks":[],"checksum":4129449496,"timestamp":"2024-06-01T17:52:57.531970Z"}]}
{"channel":"book","type":"update","data":[{"symbol":"AUD/USD","bids":[{"price":0.66433,"qty":0.00000000},{"price":0.66346,"qty":2506.00000000},{"price":0.66439,"qty":5600.87892446}],"asks":[],"checksum":2099425937,"timestamp":"2024-06-01T17:52:57.983313Z"}]}
{"channel":"book","type":"update","data":[{"symbol":"AUD/USD","bids":[],"asks":[{"price":0.66476,"qty":0.00000000},{"price":0.66559,"qty":5032.00000000},{"price":0.66474,"qty":4894.17960176}],"checksum":2560153618,"timestamp":"2024-06-01T17:52:57.983445Z"}]}
{"channel":"book","type":"update","data":[{"symbol":"AUD/USD","bids":[],"asks":[{"price":0.66475,"qty":0.00000000},{"price":0.66559,"qty":5032.00000000},{"price":0.66473,"qty":12212.66745688}],"checksum":692801777,"timestamp":"2024-06-01T17:52:57.996056Z"}]}
{"channel":"book","type":"update","data":[{"symbol":"AUD/USD","bids":[{"price":0.66438,"qty":0.00000000},{"price":0.66346,"qty":2506.00000000}],"asks":[],"checksum":4272985347,"timestamp":"2024-06-01T17:52:58.645327Z"}]}
{"channel":"book","type":"update","data":[{"symbol":"AUD/USD","bids":[{"price":0.66440,"qty":1029.83422405}],"asks":[],"checksum":2087835179,"timestamp":"2024-06-01T17:52:58.645380Z"}]}
{"channel":"book","type":"update","data":[{"symbol":"AUD/USD","bids":[{"price":0.66439,"qty":0.00000000},{"price":0.66346,"qty":2506.00000000},{"price":0.66437,"qty":5601.04753168}],"asks":[],"checksum":2862747978,"timestamp":"2024-06-01T17:52:58.650148Z"}]}
{"channel":"book","type":"update","data":[{"symbol":"AUD/USD","bids":[{"price":0.66377,"qty":0.00000000},{"price":0.66346,"qty":2506.00000000}],"asks":[],"checksum":3162202508,"timestamp":"2024-06-01T17:52:58.692968Z"}]}
{"channel":"book","type":"update","data":[{"symbol":"AUD/USD","bids":[{"price":0.66436,"qty":9575.59192247}],"asks":[],"checksum":2771562803,"timestamp":"2024-06-01T17:52:58.693128Z"}]}
{"channel":"book","type":"update","data":[{"symbol":"AUD/USD","bids":[{"price":0.66437,"qty":0.00000000},{"price":0.66345,"qty":505.00000000},{"price":0.66441,"qty":5600.71032739}],"asks":[],"checksum":4093027023,"timestamp":"2024-06-01T17:52:58.900586Z"}]}
{"channel":"book","type":"update","data":[{"symbol":"AUD/USD","bids":[],"asks":[{"price":0.66474,"qty":0.00000000},{"price":0.66559,"qty":5032.00000000},{"price":0.66472,"qty":4894.17868374}],"checksum":2455484623,"timestamp":"2024-06-01T17:52:58.900671Z"}]}
{"channel":"book","type":"update","data":[{"symbol":"AUD/USD","bids":[],"asks":[{"price":0.66473,"qty":0.00000000},{"price":0.66559,"qty":5032.00000000},{"price":0.66471,"qty":12212.66745688}],"checksum":3592374281,"timestamp":"2024-06-01T17:52:58.908301Z"}]}
{"channel":"book","type":"update","data":[{"symbol":"AUD/USD","bids":[{"price":0.66439,"qty":111.04555827}],"asks":[],"checksum":1750253577,"timestamp":"2024-06-01T17:52:58.993661Z"}]}
{"channel":"book","type":"update","data":[{"symbol":"AUD/USD","bids":[{"price":0.66379,"qty":239.54112994}],"asks":[],"checksum":3957276595,"timestamp":"2024-06-01T17:52:58.993754Z"}]}
{"channel":"book","type":"update","data":[{"symbol":"AUD/USD","bids":[{"price":0.66437,"qty":138.04012694}],"asks":[],"checksum":2906059550,"timestamp":"2024-06-01T17:52:58.993768Z"}]}
{"channel":"book","type":"update","data":[{"symbol":"AUD/USD","bids":[],"asks":[{"price":0.66472,"qty":0.00000000},{"price":0.66559,"qty":5032.00000000},{"price":0.66470,"qty":4894.02023566}],"checksum":151998884,"timestamp":"2024-06-01T17:52:59.842256Z"}]}
{"channel":"book","type":"update","data":[{"symbol":"AUD/USD","bids":[],"asks":[{"price":0.66471,"qty":0.00000000},{"price":0.66559,"qty":5032.00000000},{"price":0.66469,"qty":12212.66745688}],"checksum":2538196837,"timestamp":"2024-06-01T17:52:59.879213Z"}]}
{"channel":"book","type":"update","data":[{"symbol":"AUD/USD","bids":[],"asks":[{"price":0.66478,"qty":5939.02189271}],"checksum":3952197889,"timestamp":"2024-06-01T17:52:59.920463Z"}]}
{"channel":"book","type":"update","data":[{"symbol":"AUD/USD","bids":[],"asks":[{"price":0.66526,"qty":140.04155347}],"checksum":348386455,"timestamp":"2024-06-01T17:52:59.920995Z"}]}
{"channel":"book","type":"update","data":[{"symbol":"AUD/USD","bids":[],"asks":[{"price":0.66478,"qty":0.00000000},{"price":0.66557,"qty":4434.00000000}],"checksum":3251628875,"timestamp":"2024-06-01T17:53:00.203961Z"}]}
{"channel":"book","type":"update","data":[{"symbol":"AUD/USD","bids":[],"asks":[{"price":0.66545,"qty":0.00000000},{"price":0.66559,"qty":5032.00000000}],"checksum":1132887521,"timestamp":"2024-06-01T17:53:00.203976Z"}]}
{"channel":"book","type":"update","data":[{"symbol":"AUD/USD","bids":[],"asks":[{"price":0.66526,"qty":23675.94788755}],"checksum":943326828,"timestamp":"2024-06-01T17:53:00.204700Z"}]}
{"channel":"book","type":"update","data":[{"symbol":"AUD/USD","bids":[],"asks":[{"price":0.66527,"qty":0.00000000},{"price":0.66588,"qty":5806.00000000}],"checksum":2813248505,"timestamp":"2024-06-01T17:53:00.208031Z"}]}
{"channel":"book","type":"update","data":[{"symbol":"AUD/USD","bids":[],"asks":[{"price":0.66525,"qty":4258.83710000}],"checksum":3669800076,"timestamp":"2024-06-01T17:53:00.208310Z"}]}
{"channel":"book","type":"update","data":[{"symbol":"AUD/USD","bids":[],"asks":[{"price":0.66470,"qty":0.00000000},{"price":0.66588,"qty":5806.00000000},{"price":0.66468,"qty":4894.00550938}],"checksum":4004945093,"timestamp":"2024-06-01T17:53:00.740964Z"}]}
{"channel":"book","type":"update","data":[{"symbol":"AUD/USD","bids":[],"asks":[{"price":0.66469,"qty":0.00000000},{"price":0.66588,"qty":5806.00000000},{"price":0.66467,"qty":12212.66745688}],"checksum":2628892569,"timestamp":"2024-06-01T17:53:00.759326Z"}]}
{"channel":"book","type":"update","data":[{"symbol":"AUD/USD","bids":[{"price":0.66379,"qty":0.00000000},{"price":0.66358,"qty":3003.00000000}],"asks":[],"checksum":3898765631,"timestamp":"2024-06-01T17:53:00.986419Z"}]}
{"channel":"book","type":"update","data":[{"symbol":"AUD/USD","bids":[{"price":0.66439,"qty":0.00000000},{"price":0.66352,"qty":2804.00000000}],"asks":[],"checksum":2838701487,"timestamp":"2024-06-01T17:53:00.986538Z"}]}
{"channel":"book","type":"update","data":[{"symbol":"AUD/USD","bids":[{"price":0.66437,"qty":0.00000000},{"price":0.66346,"qty":2506.00000000}],"asks":[],"checksum":3584874943,"timestamp":"2024-06-01T17:53:00.986575Z"}]}
{"channel":"book","type":"update","data":[{"symbol":"AUD/USD","bids":[{"price":0.66379,"qty":377.64716159}],"asks":[],"checksum":2113416716,"timestamp":"2024-06-01T17:53:00.990796Z"}]}
{"channel":"book","type":"update","data":[{"symbol":"AUD/USD","bids":[{"price":0.66442,"qty":111.04555827}],"asks":[],"checksum":2005372600,"timestamp":"2024-06-01T17:53:00.990823Z"}]}
{"channel":"book","type":"update","data":[{"symbol":"AUD/USD","bids":[{"price":0.66440,"qty":0.00000000},{"price":0.66352,"qty":2804.00000000}],"asks":[],"checksum":2536108316,"timestamp":"2024-06-01T17:53:00.992075Z"}]}
{"channel":"book","type":"update","data":[{"symbol":"AUD/USD","bids":[{"price":0.66437,"qty":1029.88074595}],"asks":[],"checksum":186014345,"timestamp":"2024-06-01T17:53:00.992245Z"}]}
{"channel":"book","type":"update","data":[{"symbol":"AUD/USD","bids":[{"price":0.66441,"qty":0.00000000},{"price":0.66352,"qty":2804.00000000},{"price":0.66437,"qty":6630.92827763}],"asks":[],"checksum":2681023382,"timestamp":"2024-06-01T17:53:00.995704Z"}]}
{"channel":"book","type":"update","data":[{"symbol":"AUD/USD","bids":[{"price":0.66378,"qty":0.00000000},{"price":0.66346,"qty":2506.00000000}],"asks":[],"checksum":863575646,"timestamp":"2024-06-01T17:53:01.247955Z"}]}
{"channel":"book","type":"update","data":[{"symbol":"AUD/USD","bids":[{"price":0.66436,"qty":0.00000000},{"price":0.66345,"qty":505.00000000}],"asks":[],"checksum":3703772368,"timestamp":"2024-06-01T17:53:01.248002Z"}]}
{"channel":"book","type":"update","data":[{"symbol":"AUD/USD","bids":[{"price":0.66442,"qty":5307.04807852}],"asks":[],"checksum":3134964362,"timestamp":"2024-06-01T17:53:01.253539Z"}]}
{"channel":"book","type":"update","data":[{"symbol":"AUD/USD","bids":[{"price":0.66376,"qty":41595.94158193}],"asks":[],"checksum":196719818,"timestamp":"2024-06-01T17:53:01.253592Z"}]}
{"channel":"book","type":"update","data":[{"symbol":"AUD/USD","bids":[],"asks":[{"price":0.66466,"qty":342.43142964}],"checksum":3146017217,"timestamp":"2024-06-01T17:53:01.415706Z"}]}
{"channel":"book","type":"update","data":[{"symbol":"AUD/USD","bids":[],"asks":[{"price":0.66467,"qty":0.00000000},{"price":0.66559,"qty":5032.00000000},{"price":0.66465,"qty":12212.66745688}],"checksum":2480988961,"timestamp":"2024-06-01T17:53:01.426747Z"}]}
{"channel":"book","type":"update","data":[{"symbol":"AUD/USD","bids":[{"price":0.66437,"qty":1029.88074595},{"price":0.66443,"qty":5600.54174048}],"asks":[],"checksum":1825597887,"timestamp":"2024-06-01T17:53:01.596246Z"}]}
{"channel":"book","type":"update","data":[{"symbol":"AUD/USD","bids":[],"asks":[{"price":0.66468,"qty":0.00000000},{"price":0.66559,"qty":5032.00000000},{"price":0.66464,"qty":4893.95269252}],"checksum":783775589,"timestamp":"2024-06-01T17:53:01.596647Z"}]}
{"channel":"book","type":"update","data":[{"symbol":"AUD/USD","bids":[{"price":0.66437,"qty":0.00000000},{"price":0.66346,"qty":2506.00000000}],"asks":[],"checksum":2790802282,"timestamp":"2024-06-01T17:53:01.605224Z"}]}
{"channel":"book","type":"update","data":[{"symbol":"AUD/USD","bids":[{"price":0.66433,"qty":1029.94268132}],"asks":[],"checksum":3658339573,"timestamp":"2024-06-01T17:53:01.605255Z"}]}
{"channel":"book","type":"update","data":[{"symbol":"AUD/USD","bids":[],"asks":[{"price":0.66461,"qty":0.00000000},{"price":0.66559,"qty":5032.00000000}],"checksum":1931804164,"timestamp":"2024-06-01T17:53:01.605871Z"}]}
{"channel":"book","type":"update","data":[{"symbol":"AUD/USD","bids":[],"asks":[{"price":0.66465,"qty":0.00000000},{"price":0.66588,"qty":5806.00000000},{"price":0.66463,"qty":12212.66745688}],"checksum":3945840456,"timestamp":"2024-06-01T17:53:01.610236Z"}]}
{"channel":"book","type":"update","data":[{"symbol":"AUD/USD","bids":[],"asks":[{"price":0.66463,"qty":0.00000000},{"price":0.66588,"qty":5806.00000000},{"price":0.66524,"qty":12212.66745688}],"checksum":2978003368,"timestamp":"2024-06-01T17:53:01.642314Z"}]}
{"channel":"book","type":"update","data":[{"symbol":"AUD/USD","bids":[],"asks":[{"price":0.66464,"qty":0.00000000},{"price":0.66588,"qty":5806.00000000},{"price":0.66523,"qty":4893.95239215}],"checksum":787851019,"timestamp":"2024-06-01T17:53:01.645483Z"}]}
{"channel":"book","type":"update","data":[{"symbol":"AUD/USD","bids":[],"asks":[{"price":0.66525,"qty":0.00000000},{"price":0.66588,"qty":5806.00000000}],"checksum":3000808245,"timestamp":"2024-06-01T17:53:01.670733Z"}]}
{"channel":"book","type":"update","data":[{"symbol":"AUD/USD","bids":[],"asks":[{"price":0.66522,"qty":4258.83710000}],"checksum":1428216826,"timestamp":"2024-06-01T17:53:01.670822Z"}]}
{"channel":"book","type":"update","data":[{"symbol":"AUD/USD","bids":[],"asks":[{"price":0.66524,"qty":0.00000000},{"price":0.66588,"qty":5806.00000000},{"price":0.66522,"qty":16471.50455688}],"checksum":2241959506,"timestamp":"2024-06-01T17:53:01.673982Z"}]}
{"channel":"book","type":"update","data":[{"symbol":"AUD/USD","bids":[],"asks":[{"price":0.66522,"qty":4258.83710000},{"price":0.66521,"qty":12212.66745688}],"checksum":921277198,"timestamp":"2024-06-01T17:53:01.705903Z"}]}
{"channel":"book","type":"update","data":[{"symbol":"AUD/USD","bids":[],"asks":[{"price":0.66520,"qty":4258.83710000}],"checksum":2381690901,"timestamp":"2024-06-01T17:53:02.062620Z"}]}
{"channel":"book","type":"update","data":[{"symbol":"AUD/USD","bids":[],"asks":[{"price":0.66522,"qty":0.00000000},{"price":0.66559,"qty":5032.00000000}],"checksum":3636049561,"timestamp":"2024-06-01T17:53:02.062750Z"}]}
{"channel":"book","type":"update","data":[{"symbol":"AUD/USD","bids":[],"asks":[{"price":0.66521,"qty":0.00000000},{"price":0.66588,"qty":5806.00000000},{"price":0.66519,"qty":12212.66745688}],"checksum":3982934162,"timestamp":"2024-06-01T17:53:02.101546Z"}]}
{"channel":"book","type":"update","data":[{"symbol":"AUD/USD","bids":[],"asks":[{"price":0.66520,"qty":0.00000000},{"price":0.66588,"qty":5806.00000000}],"checksum":4163404231,"timestamp":"2024-06-01T17:53:02.114430Z"}]}
{"channel":"book","type":"update","data":[{"symbol":"AUD/USD","bids":[],"asks":[{"price":0.66518,"qty":4258.83710000}],"checksum":2002237602,"timestamp":"2024-06-01T17:53:02.114736Z"}]}
{"channel":"book","type":"update","data":[{"symbol":"AUD/USD","bids":[],"asks":[{"price":0.66519,"qty":0.00000000},{"price":0.66588,"qty":5806.00000000},{"price":0.66517,"qty":12212.66745688}],"checksum":1264829697,"timestamp":"2024-06-01T17:53:02.133565Z"}]}
{"channel":"book","type":"update","data":[{"symbol":"AUD/USD","bids":[],"asks":[{"price":0.66523,"qty":0.00000000},{"price":0.66588,"qty":5806.00000000},{"price":0.66516,"qty":4893.95204694}],"checksum":2856849580,"timestamp":"2024-06-01T17:53:02.475441Z"}]}
{"channel":"book","type":"update","data":[{"symbol":"AUD/USD","bids":[],"asks":[{"price":0.66517,"qty":0.00000000},{"price":0.66588,"qty":5806.00000000},{"price":0.66515,"qty":12212.66745688}],"checksum":600585238,"timestamp":"2024-06-01T17:53:02.499323Z"}]}
{"channel":"book","type":"update","data":[{"symbol":"AUD/USD","bids":[],"asks":[{"price":0.66526,"qty":23535.90633408}],"checksum":4120505055,"timestamp":"2024-06-01T17:53:02.904352Z"}]}
{"channel":"book","type":"update","data":[{"symbol":"AUD/USD","bids":[],"asks":[{"price":0.66514,"qty":264.68521483}],"checksum":2641298534,"timestamp":"2024-06-01T17:53:02.905250Z"}]}
{"channel":"book","type":"update","data":[{"symbol":"AUD/USD","bids":[],"asks":[{"price":0.66515,"qty":0.00000000},{"price":0.66559,"qty":5032.00000000},{"price":0.66513,"qty":12212.66745688}],"checksum":320911167,"timestamp":"2024-06-01T17:53:02.925793Z"}]}
{"channel":"book","type":"update","data":[{"symbol":"AUD/USD","bids":[],"asks":[{"price":0.66526,"qty":0.00000000},{"price":0.66559,"qty":5032.00000000}],"checksum":2564862516,"timestamp":"2024-06-01T17:53:03.218287Z"}]}
{"channel":"book","type":"update","data":[{"symbol":"AUD/USD","bids":[],"asks":[{"price":0.66512,"qty":32334.34855477}],"checksum":4241466075,"timestamp":"2024-06-01T17:53:03.220337Z"}]}
{"channel":"book","type":"update","data":[{"symbol":"AUD/USD","bids":[],"asks":[{"price":0.66513,"qty":0.00000000},{"price":0.66559,"qty":5032.00000000},{"price":0.66511,"qty":12212.66745688}],"checksum":1478646663,"timestamp":"2024-06-01T17:53:03.229632Z"}]}
{"channel":"book","type":"update","data":[{"symbol":"AUD/USD","bids":[],"asks":[{"price":0.66516,"qty":0.00000000},{"price":0.66559,"qty":5032.00000000},{"price":0.66510,"qty":4894.06339051}],"checksum":270605774,"timestamp":"2024-06-01T17:53:03.421558Z"}]}
{"channel":"book","type":"update","data":[{"symbol":"AUD/USD","bids":[],"asks":[{"price":0.66511,"qty":0.00000000},{"price":0.66559,"qty":5032.00000000},{"price":0.66509,"qty":12212.66745688}],"checksum":4019738060,"timestamp":"2024-06-01T17:53:03.444051Z"}]}
{"channel":"book","type":"update","data":[{"symbol":"AUD/USD","bids":[],"asks":[{"price":0.66508,"qty":4258.83710000}],"checksum":1410568031,"timestamp":"2024-06-01T17:53:03.446898Z"}]}
{"channel":"book","type":"update","data":[{"symbol":"AUD/USD","bids":[],"asks":[{"price":0.66518,"qty":0.00000000},{"price":0.66557,"qty":4434.00000000}],"checksum":2699724561,"timestamp":"2024-06-01T17:53:03.447013Z"}]}
{"channel":"book","type":"update","data":[{"symbol":"AUD/USD","bids":[],"asks":[{"price":0.66509,"qty":0.00000000},{"price":0.66559,"qty":5032.00000000},{"price":0.66507,"qty":12212.66745688}],"checksum":47272456,"timestamp":"2024-06-01T17:53:03.475669Z"}]}
{"channel":"book","type":"update","data":[{"symbol":"AUD/USD","bids":[],"asks":[{"price":0.66508,"qty":0.00000000},{"price":0.66559,"qty":5032.00000000}],"checksum":4138673104,"timestamp":"2024-06-01T17:53:03.492355Z"}]}
{"channel":"book","type":"update","data":[{"symbol":"AUD/USD","bids":[],"asks":[{"price":0.66506,"qty":4258.83710000}],"checksum":1694462672,"timestamp":"2024-06-01T17:53:03.492539Z"}]}
{"channel":"book","type":"update","data":[{"symbol":"AUD/USD","bids":[],"asks":[{"price":0.66507,"qty":0.00000000},{"price":0.66559,"qty":5032.00000000},{"price":0.66505,"qty":12212.66745688}],"checksum":454983780,"timestamp":"2024-06-01T17:53:03.506997Z"}]}
{"channel":"book","type":"update","data":[{"symbol":"AUD/USD","bids":[{"price":0.66442,"qty":5196.00252025}],"asks":[],"checksum":772556362,"timestamp":"2024-06-01T17:53:03.957992Z"}]}
{"channel":"book","type":"update","data":[{"symbol":"AUD/USD","bids":[{"price":0.66379,"qty":0.00000000},{"price":0.66346,"qty":2506.00000000}],"asks":[],"checksum":3767243727,"timestamp":"2024-06-01T17:53:03.958038Z"}]}
{"channel":"book","type":"update","data":[{"symbol":"AUD/USD","bids":[{"price":0.66444,"qty":56.40893678}],"asks":[],"checksum":2848131042,"timestamp":"2024-06-01T17:53:03.968771Z"}]}
{"channel":"book","type":"update","data":[{"symbol":"AUD/USD","bids":[{"price":0.66377,"qty":474.13173823}],"asks":[],"checksum":2887131708,"timestamp":"2024-06-01T17:53:03.968845Z"}]}
{"channel":"book","type":"update","data":[{"symbol":"AUD/USD","bids":[],"asks":[{"price":0.66510,"qty":0.00000000},{"price":0.66559,"qty":5032.00000000},{"price":0.66504,"qty":4894.06552902}],"checksum":1114517600,"timestamp":"2024-06-01T17:53:04.324305Z"}]}
{"channel":"book","type":"update","data":[{"symbol":"AUD/USD","bids":[],"asks":[{"price":0.66505,"qty":0.00000000},{"price":0.66559,"qty":5032.00000000},{"price":0.66503,"qty":12212.66745688}],"checksum":4281444113,"timestamp":"2024-06-01T17:53:04.357560Z"}]}
{"channel":"book","type":"update","data":[{"symbol":"AUD/USD","bids":[],"asks":[{"price":0.66506,"qty":0.00000000},{"price":0.66559,"qty":5032.00000000}],"checksum":1003360263,"timestamp":"2024-06-01T17:53:04.453338Z"}]}
{"channel":"book","type":"update","data":[{"symbol":"AUD/USD","bids":[],"asks":[{"price":0.66502,"qty":4258.83710000}],"checksum":2960139239,"timestamp":"2024-06-01T17:53:04.453587Z"}]}
{"channel":"book","type":"update","data":[{"symbol":"AUD/USD","bids":[],"asks":[{"price":0.66503,"qty":0.00000000},{"price":0.66559,"qty":5032.00000000},{"price":0.66501,"qty":12212.66745688}],"checksum":899195014,"timestamp":"2024-06-01T17:53:04.480743Z"}]}
{"channel":"book","type":"update","data":[{"symbol":"AUD/USD","bids":[{"price":0.66376,"qty":0.00000000},{"price":0.66352,"qty":2804.00000000}],"asks":[],"checksum":248833112,"timestamp":"2024-06-01T17:53:04.881838Z"}]}
{"channel":"book","type":"update","data":[{"symbol":"AUD/USD","bids":[{"price":0.66442,"qty":0.00000000},{"price":0.66346,"qty":2506.00000000}],"asks":[],"checksum":3667435222,"timestamp":"2024-06-01T17:53:04.882092Z"}]}
{"channel":"book","type":"update","data":[{"symbol":"AUD/USD","bids":[{"price":0.66443,"qty":0.00000000},{"price":0.66345,"qty":505.00000000},{"price":0.66434,"qty":5601.30046155}],"asks":[],"checksum":459800291,"timestamp":"2024-06-01T17:53:04.885787Z"}]}
{"channel":"book","type":"update","data":[{"symbol":"AUD/USD","bids":[{"price":0.66444,"qty":3062.61675593}],"asks":[],"checksum":2257172285,"timestamp":"2024-06-01T17:53:04.887383Z"}]}
{"channel":"book","type":"update","data":[{"symbol":"AUD/USD","bids":[{"price":0.66378,"qty":23266.56869926}],"asks":[],"checksum":2617452252,"timestamp":"2024-06-01T17:53:04.887535Z"}]}
{"channel":"book","type":"update","data":[{"symbol":"AUD/USD","bids":[{"price":0.66434,"qty":0.00000000},{"price":0.66346,"qty":2506.00000000},{"price":0.66445,"qty":5600.37316371}],"asks":[],"checksum":2174664222,"timestamp":"2024-06-01T17:53:05.184425Z"}]}
{"channel":"book","type":"update","data":[{"symbol":"AUD/USD","bids":[],"asks":[{"price":0.66504,"qty":0.00000000},{"price":0.66559,"qty":5032.00000000},{"price":0.66500,"qty":4894.10672623}],"checksum":1051418020,"timestamp":"2024-06-01T17:53:05.184611Z"}]}
{"channel":"book","type":"update","data":[{"symbol":"AUD/USD","bids":[],"asks":[{"price":0.66501,"qty":0.00000000},{"price":0.66559,"qty":5032.00000000},{"price":0.66499,"qty":12212.66745688}],"checksum":3311149095,"timestamp":"2024-06-01T17:53:05.209017Z"}]}
{"channel":"book","type":"update","data":[{"symbol":"AUD/USD","bids":[],"asks":[{"price":0.66514,"qty":0.00000000},{"price":0.66559,"qty":5032.00000000}],"checksum":3677037728,"timestamp":"2024-06-01T17:53:05.841846Z"}]}
{"channel":"book","type":"update","data":[{"symbol":"AUD/USD","bids":[],"asks":[{"price":0.66498,"qty":191.36541403}],"checksum":2313262978,"timestamp":"2024-06-01T17:53:05.842410Z"}]}
{"channel":"book","type":"update","data":[{"symbol":"AUD/USD","bids":[],"asks":[{"price":0.66502,"qty":0.00000000},{"price":0.66559,"qty":5032.00000000}],"checksum":1783869681,"timestamp":"2024-06-01T17:53:05.846927Z"}]}
{"channel":"book","type":"update","data":[{"symbol":"AUD/USD","bids":[],"asks":[{"price":0.66498,"qty":4450.20251403}],"checksum":342653224,"timestamp":"2024-06-01T17:53:05.847022Z"}]}
{"channel":"book","type":"update","data":[{"symbol":"AUD/USD","bids":[],"asks":[{"price":0.66499,"qty":0.00000000},{"price":0.66588,"qty":5806.00000000},{"price":0.66497,"qty":12212.66745688}],"checksum":4182901578,"timestamp":"2024-06-01T17:53:05.876673Z"}]}
{"channel":"book","type":"update","data":[{"symbol":"AUD/USD","bids":[],"asks":[{"price":0.66498,"qty":191.36541403}],"checksum":2930891015,"timestamp":"2024-06-01T17:53:05.889436Z"}]}
{"channel":"book","type":"update","data":[{"symbol":"AUD/USD","bids":[],"asks":[{"price":0.66496,"qty":4258.83710000}],"checksum":1217292345,"timestamp":"2024-06-01T17:53:05.889601Z"}]}
{"channel":"book","type":"update","data":[{"symbol":"AUD/USD","bids":[],"asks":[{"price":0.66497,"qty":0.00000000},{"price":0.66559,"qty":5032.00000000},{"price":0.66495,"qty":12212.66745688}],"checksum":2349072232,"timestamp":"2024-06-01T17:53:05.908332Z"}]}
{"channel":"book","type":"update","data":[{"symbol":"AUD/USD","bids":[],"asks":[{"price":0.66500,"qty":0.00000000},{"price":0.66559,"qty":5032.00000000},{"price":0.66494,"qty":4894.10428027}],"checksum":1563437594,"timestamp":"2024-06-01T17:53:06.067943Z"}]}
{"channel":"book","type":"update","data":[{"symbol":"AUD/USD","bids":[],"asks":[{"price":0.66495,"qty":0.00000000},{"price":0.66559,"qty":5032.00000000},{"price":0.66493,"qty":12212.66745688}],"checksum":322714204,"timestamp":"2024-06-01T17:53:06.092137Z"}]}
{"channel":"book","type":"update","data":[{"symbol":"AUD/USD","bids":[],"asks":[{"price":0.66512,"qty":0.00000000},{"price":0.66559,"qty":5032.00000000}],"checksum":2562949434,"timestamp":"2024-06-01T17:53:06.225584Z"}]}
{"channel":"book","type":"update","data":[{"symbol":"AUD/USD","bids":[],"asks":[{"price":0.66494,"qty":29896.41765113}],"checksum":2989519428,"timestamp":"2024-06-01T17:53:06.226595Z"}]}
{"channel":"book","type":"update","data":[{"symbol":"AUD/USD","bids":[{"price":0.66444,"qty":3006.20781915}],"asks":[],"checksum":126337062,"timestamp":"2024-06-01T17:53:06.603765Z"}]}
{"channel":"book","type":"update","data":[{"symbol":"AUD/USD","bids":[{"price":0.66377,"qty":0.00000000},{"price":0.66346,"qty":2506.00000000}],"asks":[],"checksum":1522848386,"timestamp":"2024-06-01T17:53:06.603887Z"}]}
{"channel":"book","type":"update","data":[{"symbol":"AUD/USD","bids":[],"asks":[{"price":0.66496,"qty":0.00000000},{"price":0.66588,"qty":5806.00000000}],"checksum":3140341557,"timestamp":"2024-06-01T17:53:06.855603Z"}]}
{"channel":"book","type":"update","data":[{"symbol":"AUD/USD","bids":[],"asks":[{"price":0.66492,"qty":4258.83710000}],"checksum":1557749729,"timestamp":"2024-06-01T17:53:06.856863Z"}]}
{"channel":"book","type":"update","data":[{"symbol":"AUD/USD","bids":[],"asks":[{"price":0.66493,"qty":0.00000000},{"price":0.66588,"qty":5806.00000000},{"price":0.66491,"qty":12212.66745688}],"checksum":2070422819,"timestamp":"2024-06-01T17:53:06.880697Z"}]}
{"channel":"book","type":"update","data":[{"symbol":"AUD/USD","bids":[{"price":0.66446,"qty":30.06185226}],"asks":[],"checksum":1347623063,"timestamp":"2024-06-01T17:53:06.886891Z"}]}
{"channel":"book","type":"update","data":[{"symbol":"AUD/USD","bids":[{"price":0.66379,"qty":512.89680471}],"asks":[],"checksum":192906113,"timestamp":"2024-06-01T17:53:06.887022Z"}]}
{"channel":"book","type":"update","data":[{"symbol":"AUD/USD","bids":[],"asks":[{"price":0.66492,"qty":0.00000000},{"price":0.66588,"qty":5806.00000000}],"checksum":342626688,"timestamp":"2024-06-01T17:53:06.897425Z"}]}
{"channel":"book","type":"update","data":[{"symbol":"AUD/USD","bids":[],"asks":[{"price":0.66490,"qty":4258.83710000}],"checksum":3157486779,"timestamp":"2024-06-01T17:53:06.897536Z"}]}
{"channel":"book","type":"update","data":[{"symbol":"AUD/USD","bids":[],"asks":[{"price":0.66494,"qty":25002.31337086},{"price":0.66489,"qty":4893.93217164}],"checksum":2673372679,"timestamp":"2024-06-01T17:53:06.908477Z"}]}
{"channel":"book","type":"update","data":[{"symbol":"AUD/USD","bids":[],"asks":[{"price":0.66491,"qty":0.00000000},{"price":0.66559,"qty":5032.00000000},{"price":0.66489,"qty":17106.59962852}],"checksum":626326763,"timestamp":"2024-06-01T17:53:06.912434Z"}]}
{"channel":"book","type":"update","data":[{"symbol":"AUD/USD","bids":[],"asks":[{"price":0.66489,"qty":4893.93217164},{"price":0.66488,"qty":12212.66745688}],"checksum":4256945126,"timestamp":"2024-06-01T17:53:06.944644Z"}]}
{"channel":"book","type":"update","data":[{"symbol":"AUD/USD","bids":[],"asks":[{"price":0.66489,"qty":0.00000000},{"price":0.66559,"qty":5032.00000000},{"price":0.66487,"qty":4893.93217164}],"checksum":2367020250,"timestamp":"2024-06-01T17:53:07.706033Z"}]}
{"channel":"book","type":"update","data":[{"symbol":"AUD/USD","bids":[],"asks":[{"price":0.66488,"qty":0.00000000},{"price":0.66559,"qty":5032.00000000},{"price":0.66486,"qty":12212.66745688}],"checksum":3944204500,"timestamp":"2024-06-01T17:53:07.732896Z"}]}
{"channel":"book","type":"update","data":[{"symbol":"AUD/USD","bids":[],"asks":[{"price":0.66485,"qty":4258.83710000}],"checksum":2042416226,"timestamp":"2024-06-01T17:53:08.245099Z"}]}
{"channel":"book","type":"update","data":[{"symbol":"AUD/USD","bids":[],"asks":[{"price":0.66490,"qty":0.00000000},{"price":0.66557,"qty":4434.00000000}],"checksum":3238562091,"timestamp":"2024-06-01T17:53:08.245251Z"}]}
{"channel":"book","type":"update","data":[{"symbol":"AUD/USD","bids":[],"asks":[{"price":0.66486,"qty":0.00000000},{"price":0.66559,"qty":5032.00000000},{"price":0.66484,"qty":12212.66745688}],"checksum":3444635001,"timestamp":"2024-06-01T17:53:08.279047Z"}]}
{"channel":"book","type":"update","data":[{"symbol":"AUD/USD","bids":[],"asks":[{"price":0.66485,"qty":0.00000000},{"price":0.66559,"qty":5032.00000000}],"checksum":2386758329,"timestamp":"2024-06-01T17:53:08.297804Z"}]}
{"channel":"book","type":"update","data":[{"symbol":"AUD/USD","bids":[],"asks":[{"price":0.66483,"qty":4258.83710000}],"checksum":913296347,"timestamp":"2024-06-01T17:53:08.297967Z"}]}
{"channel":"book","type":"update","data":[{"symbol":"AUD/USD","bids":[],"asks":[{"price":0.66484,"qty":0.00000000},{"price":0.66559,"qty":5032.00000000},{"price":0.66482,"qty":12212.66745688}],"checksum":183630334,"timestamp":"2024-06-01T17:53:08.310627Z"}]}
{"channel":"book","type":"update","data":[{"symbol":"AUD/USD","bids":[],"asks":[{"price":0.66487,"qty":0.00000000},{"price":0.66559,"qty":5032.00000000},{"price":0.66481,"qty":4893.96063248}],"checksum":177498806,"timestamp":"2024-06-01T17:53:08.536603Z"}]}
{"channel":"book","type":"update","data":[{"symbol":"AUD/USD","bids":[],"asks":[{"price":0.66482,"qty":0.00000000},{"price":0.66559,"qty":5032.00000000},{"price":0.66480,"qty":12212.66745688}],"checksum":2262411686,"timestamp":"2024-06-01T17:53:08.554476Z"}]}
{"channel":"book","type":"update","data":[{"symbol":"AUD/USD","bids":[{"price":0.66444,"qty":0.00000000},{"price":0.66352,"qty":2804.00000000}],"asks":[],"checksum":494416413,"timestamp":"2024-06-01T17:53:08.618984Z"}]}
{"channel":"book","type":"update","data":[{"symbol":"AUD/USD","bids":[{"price":0.66378,"qty":0.00000000},{"price":0.66346,"qty":2506.00000000}],"asks":[],"checksum":2363339360,"timestamp":"2024-06-01T17:53:08.619111Z"}]}
{"channel":"book","type":"update","data":[{"symbol":"AUD/USD","bids":[{"price":0.66445,"qty":0.00000000},{"price":0.66345,"qty":505.00000000},{"price":0.66434,"qty":5601.30046155}],"asks":[],"checksum":597142401,"timestamp":"2024-06-01T17:53:08.623372Z"}]}
{"channel":"book","type":"update","data":[{"symbol":"AUD/USD","bids":[{"price":0.66380,"qty":11765.38662357}],"asks":[],"checksum":4291704860,"timestamp":"2024-06-01T17:53:08.627204Z"}]}
{"channel":"book","type":"update","data":[{"symbol":"AUD/USD","bids":[{"price":0.66446,"qty":3036.26967141}],"asks":[],"checksum":311100093,"timestamp":"2024-06-01T17:53:08.627292Z"}]}
{"channel":"book","type":"update","data":[{"symbol":"AUD/USD","bids":[{"price":0.66376,"qty":16682.69824832}],"asks":[],"checksum":3988433460,"timestamp":"2024-06-01T17:53:08.627333Z"}]}
{"channel":"book","type":"update","data":[{"symbol":"AUD/USD","bids":[],"asks":[{"price":0.66498,"qty":0.00000000},{"price":0.66559,"qty":5032.00000000}],"checksum":3610176347,"timestamp":"2024-06-01T17:53:08.777664Z"}]}
{"channel":"book","type":"update","data":[{"symbol":"AUD/USD","bids":[],"asks":[{"price":0.66480,"qty":12272.05722946}],"checksum":1466846644,"timestamp":"2024-06-01T17:53:08.779433Z"}]}
{"channel":"book","type":"update","data":[{"symbol":"AUD/USD","bids":[],"asks":[{"price":0.66480,"qty":59.38977258},{"price":0.66479,"qty":12212.66745688}],"checksum":3189670167,"timestamp":"2024-06-01T17:53:08.799452Z"}]}
{"channel":"book","type":"update","data":[{"symbol":"AUD/USD","bids":[],"asks":[{"price":0.66494,"qty":0.00000000},{"price":0.66559,"qty":5032.00000000}],"checksum":610611244,"timestamp":"2024-06-01T17:53:09.228046Z"}]}
{"channel":"book","type":"update","data":[{"symbol":"AUD/USD","bids":[],"asks":[{"price":0.66478,"qty":3006.20781915}],"checksum":327146276,"timestamp":"2024-06-01T17:53:09.229113Z"}]}
{"channel":"book","type":"update","data":[{"symbol":"AUD/USD","bids":[],"asks":[{"price":0.66545,"qty":20529.69851493}],"checksum":268318190,"timestamp":"2024-06-01T17:53:09.229186Z"}]}
{"channel":"book","type":"update","data":[{"symbol":"AUD/USD","bids":[],"asks":[{"price":0.66483,"qty":0.00000000},{"price":0.66557,"qty":4434.00000000}],"checksum":3842733192,"timestamp":"2024-06-01T17:53:09.242995Z"}]}
{"channel":"book","type":"update","data":[{"symbol":"AUD/USD","bids":[],"asks":[{"price":0.66527,"qty":4258.83710000}],"checksum":312164080,"timestamp":"2024-06-01T17:53:09.243190Z"}]}
{"channel":"book","type":"update","data":[{"symbol":"AUD/USD","bids":[{"price":0.66435,"qty":1029.91171270}],"asks":[],"checksum":3484643076,"timestamp":"2024-06-01T17:53:09.243223Z"}]}
{"channel":"book","type":"update","data":[{"symbol":"AUD/USD","bids":[{"price":0.66433,"qty":0.00000000},{"price":0.66358,"qty":3003.00000000}],"asks":[],"checksum":2162813774,"timestamp":"2024-06-01T17:53:09.243460Z"}]}
{"channel":"book","type":"update","data":[{"symbol":"AUD/USD","bids":[],"asks":[{"price":0.66479,"qty":0.00000000},{"price":0.66557,"qty":4434.00000000},{"price":0.66477,"qty":12212.66745688}],"checksum":3534182108,"timestamp":"2024-06-01T17:53:09.255076Z"}]}
{"channel":"book","type":"update","data":[{"symbol":"AUD/USD","bids":[{"price":0.66434,"qty":0.00000000},{"price":0.66352,"qty":2804.00000000},{"price":0.66447,"qty":5600.20459708}],"asks":[],"checksum":3003503193,"timestamp":"2024-06-01T17:53:09.325102Z"}]}
{"channel":"book","type":"update","data":[{"symbol":"AUD/USD","bids":[],"asks":[{"price":0.66481,"qty":0.00000000},{"price":0.66557,"qty":4434.00000000},{"price":0.66476,"qty":4893.97019238}],"checksum":1899635549,"timestamp":"2024-06-01T17:53:09.325220Z"}]}
{"channel":"book","type":"update","data":[{"symbol":"AUD/USD","bids":[],"asks":[{"price":0.66477,"qty":0.00000000},{"price":0.66557,"qty":4434.00000000},{"price":0.66475,"qty":12212.66745688}],"checksum":2794783272,"timestamp":"2024-06-01T17:53:09.348205Z"}]}
{"channel":"book","type":"update","data":[{"symbol":"AUD/USD","bids":[{"price":0.66381,"qty":82.64425534}],"asks":[],"checksum":1142099401,"timestamp":"2024-06-01T17:53:09.393096Z"}]}
{"channel":"book","type":"update","data":[{"symbol":"AUD/USD","bids":[{"price":0.66381,"qty":0.00000000},{"price":0.66358,"qty":3003.00000000}],"asks":[],"checksum":2794783272,"timestamp":"2024-06-01T17:53:09.565907Z"}]}
{"channel":"book","type":"update","data":[{"symbol":"AUD/USD","bids":[],"asks":[{"price":0.66476,"qty":0.00000000},{"price":0.66557,"qty":4434.00000000},{"price":0.66474,"qty":4893.97019238}],"checksum":3609058800,"timestamp":"2024-06-01T17:53:10.136250Z"}]}
{"channel":"book","type":"update","data":[{"symbol":"AUD/USD","bids":[],"asks":[{"price":0.66475,"qty":0.00000000},{"price":0.66557,"qty":4434.00000000},{"price":0.66473,"qty":12212.66745688}],"checksum":287329246,"timestamp":"2024-06-01T17:53:10.166999Z"}]}
{"channel":"book","type":"update","data":[{"symbol":"AUD/USD","bids":[{"price":0.66435,"qty":0.00000000},{"price":0.66352,"qty":2804.00000000}],"asks":[],"checksum":4096987237,"timestamp":"2024-06-01T17:53:10.644892Z"}]}
{"channel":"book","type":"update","data":[{"symbol":"AUD/USD","bids":[{"price":0.66433,"qty":1029.94268132}],"asks":[],"checksum":2457237341,"timestamp":"2024-06-01T17:53:10.644904Z"}]}
{"channel":"book","type":"update","data":[{"symbol":"AUD/USD","bids":[],"asks":[{"price":0.66474,"qty":0.00000000},{"price":0.66557,"qty":4434.00000000},{"price":0.66472,"qty":4880.28366320}],"checksum":689840996,"timestamp":"2024-06-01T17:53:10.905061Z"}]}
{"channel":"book","type":"update","data":[{"symbol":"AUD/USD","bids":[],"asks":[{"price":0.66473,"qty":0.00000000},{"price":0.66557,"qty":4434.00000000},{"price":0.66471,"qty":12212.66745688}],"checksum":2328563722,"timestamp":"2024-06-01T17:53:10.925306Z"}]}
{"channel":"book","type":"update","data":[{"symbol":"AUD/USD","bids":[{"price":0.66446,"qty":3006.20781915}],"asks":[],"checksum":16979807,"timestamp":"2024-06-01T17:53:11.655852Z"}]}
{"channel":"book","type":"update","data":[{"symbol":"AUD/USD","bids":[{"price":0.66379,"qty":0.00000000},{"price":0.66352,"qty":2804.00000000}],"asks":[],"checksum":1592031958,"timestamp":"2024-06-01T17:53:11.656242Z"}]}
{"channel":"book","type":"update","data":[{"symbol":"AUD/USD","bids":[{"price":0.66448,"qty":30.06185226}],"asks":[],"checksum":2012265857,"timestamp":"2024-06-01T17:53:11.664305Z"}]}
{"channel":"book","type":"update","data":[{"symbol":"AUD/USD","bids":[{"price":0.66381,"qty":512.89680471}],"asks":[],"checksum":804575436,"timestamp":"2024-06-01T17:53:11.664347Z"}]}
{"channel":"book","type":"update","data":[{"symbol":"AUD/USD","bids":[],"asks":[{"price":0.66480,"qty":0.00000000},{"price":0.66557,"qty":4434.00000000}],"checksum":3623258067,"timestamp":"2024-06-01T17:53:11.717141Z"}]}
{"channel":"book","type":"update","data":[{"symbol":"AUD/USD","bids":[],"asks":[{"price":0.66526,"qty":176.58689168}],"checksum":3510628277,"timestamp":"2024-06-01T17:53:11.718158Z"}]}
{"channel":"book","type":"update","data":[{"symbol":"AUD/USD","bids":[],"asks":[{"price":0.66472,"qty":0.00000000},{"price":0.66557,"qty":4434.00000000},{"price":0.66470,"qty":4880.28315964}],"checksum":3839183911,"timestamp":"2024-06-01T17:53:11.723792Z"}]}
{"channel":"book","type":"update","data":[{"symbol":"AUD/USD","bids":[],"asks":[{"price":0.66471,"qty":0.00000000},{"price":0.66557,"qty":4434.00000000},{"price":0.66469,"qty":12212.66745688}],"checksum":3844786773,"timestamp":"2024-06-01T17:53:11.745053Z"}]}
{"channel":"book","type":"update","data":[{"symbol":"AUD/USD","bids":[{"price":0.66446,"qty":0.00000000},{"price":0.66358,"qty":3003.00000000}],"asks":[],"checksum":659950753,"timestamp":"2024-06-01T17:53:12.105551Z"}]}
{"channel":"book","type":"update","data":[{"symbol":"AUD/USD","bids":[{"price":0.66376,"qty":0.00000000},{"price":0.66352,"qty":2804.00000000}],"asks":[],"checksum":1156521292,"timestamp":"2024-06-01T17:53:12.105638Z"}]}
{"channel":"book","type":"update","data":[{"symbol":"AUD/USD","bids":[{"price":0.66447,"qty":0.00000000},{"price":0.66346,"qty":2506.00000000},{"price":0.66434,"qty":5601.30046155}],"asks":[],"checksum":3483797912,"timestamp":"2024-06-01T17:53:12.108916Z"}]}
{"channel":"book","type":"update","data":[{"symbol":"AUD/USD","bids":[{"price":0.66376,"qty":19688.90606747}],"asks":[],"checksum":808952748,"timestamp":"2024-06-01T17:53:12.110748Z"}]}
{"channel":"book","type":"update","data":[{"symbol":"AUD/USD","bids":[{"price":0.66433,"qty":0.00000000},{"price":0.66352,"qty":2804.00000000}],"asks":[],"checksum":1971429902,"timestamp":"2024-06-01T17:53:12.120165Z"}]}
{"channel":"book","type":"update","data":[{"symbol":"AUD/USD","bids":[{"price":0.66435,"qty":1029.91171270}],"asks":[],"checksum":2722461202,"timestamp":"2024-06-01T17:53:12.120298Z"}]}
{"channel":"book","type":"update","data":[{"symbol":"AUD/USD","bids":[{"price":0.66434,"qty":0.00000000},{"price":0.66352,"qty":2804.00000000},{"price":0.66433,"qty":5601.38477658}],"asks":[],"checksum":891627675,"timestamp":"2024-06-01T17:53:12.123361Z"}]}
{"channel":"book","type":"update","data":[{"symbol":"AUD/USD","bids":[],"asks":[{"price":0.66478,"qty":0.00000000},{"price":0.66557,"qty":4434.00000000}],"checksum":2483047367,"timestamp":"2024-06-01T17:53:12.255756Z"}]}
{"channel":"book","type":"update","data":[{"symbol":"AUD/USD","bids":[],"asks":[{"price":0.66545,"qty":0.00000000},{"price":0.66559,"qty":5032.00000000}],"checksum":3700654515,"timestamp":"2024-06-01T17:53:12.255964Z"}]}
{"channel":"book","type":"update","data":[{"symbol":"AUD/USD","bids":[],"asks":[{"price":0.66525,"qty":3006.20781915}],"checksum":3329584582,"timestamp":"2024-06-01T17:53:12.257167Z"}]}
{"channel":"book","type":"update","data":[{"symbol":"AUD/USD","bids":[],"asks":[{"price":0.66526,"qty":20339.68364742}],"checksum":702766319,"timestamp":"2024-06-01T17:53:12.257351Z"}]}
{"channel":"book","type":"update","data":[{"symbol":"AUD/USD","bids":[],"asks":[{"price":0.66527,"qty":0.00000000},{"price":0.66559,"qty":5032.00000000}],"checksum":1440058103,"timestamp":"2024-06-01T17:53:12.260946Z"}]}
{"channel":"book","type":"update","data":[{"symbol":"AUD/USD","bids":[],"asks":[{"price":0.66524,"qty":4258.83710000}],"checksum":2588095985,"timestamp":"2024-06-01T17:53:12.261050Z"}]}
{"channel":"book","type":"update","data":[{"symbol":"AUD/USD","bids":[{"price":0.66433,"qty":0.00000000},{"price":0.66352,"qty":2804.00000000},{"price":0.66436,"qty":5601.13183910}],"asks":[],"checksum":2311482857,"timestamp":"2024-06-01T17:53:12.482497Z"}]}
{"channel":"book","type":"update","data":[{"symbol":"AUD/USD","bids":[],"asks":[{"price":0.66470,"qty":0.00000000},{"price":0.66559,"qty":5032.00000000},{"price":0.66465,"qty":4880.28228217}],"checksum":1086368812,"timestamp":"2024-06-01T17:53:12.482548Z"}]}
{"channel":"book","type":"update","data":[{"symbol":"AUD/USD","bids":[{"price":0.66435,"qty":0.00000000},{"price":0.66352,"qty":2804.00000000}],"asks":[],"checksum":2250281229,"timestamp":"2024-06-01T17:53:13.056419Z"}]}
{"channel":"book","type":"update","data":[{"symbol":"AUD/USD","bids":[{"price":0.66437,"qty":1029.88074595}],"asks":[],"checksum":1245891802,"timestamp":"2024-06-01T17:53:13.056461Z"}]}
{"channel":"book","type":"update","data":[{"symbol":"AUD/USD","bids":[{"price":0.66436,"qty":0.00000000},{"price":0.66352,"qty":2804.00000000},{"price":0.66433,"qty":5601.38477658}],"asks":[],"checksum":1670663626,"timestamp":"2024-06-01T17:53:13.060902Z"}]}
{"channel":"book","type":"update","data":[{"symbol":"AUD/USD","bids":[{"price":0.66437,"qty":0.00000000},{"price":0.66352,"qty":2804.00000000}],"asks":[],"checksum":3794940918,"timestamp":"2024-06-01T17:53:13.073723Z"}]}
{"channel":"book","type":"update","data":[{"symbol":"AUD/USD","bids":[{"price":0.66434,"qty":1029.92727204}],"asks":[],"checksum":2456291182,"timestamp":"2024-06-01T17:53:13.073770Z"}]}
{"channel":"book","type":"update","data":[{"symbol":"AUD/USD","bids":[],"asks":[{"price":0.66469,"qty":0.00000000},{"price":0.66559,"qty":5032.00000000},{"price":0.66464,"qty":12212.66745688}],"checksum":3344941552,"timestamp":"2024-06-01T17:53:13.078127Z"}]}
{"channel":"book","type":"update","data":[{"symbol":"AUD/USD","bids":[{"price":0.66433,"qty":0.00000000},{"price":0.66352,"qty":2804.00000000},{"price":0.66435,"qty":5601.21614905}],"asks":[],"checksum":1301981053,"timestamp":"2024-06-01T17:53:13.299050Z"}]}
{"channel":"book","type":"update","data":[{"symbol":"AUD/USD","bids":[],"asks":[{"price":0.66465,"qty":0.00000000},{"price":0.66559,"qty":5032.00000000},{"price":0.66463,"qty":4880.21975539}],"checksum":114207534,"timestamp":"2024-06-01T17:53:13.299170Z"}]}
{"channel":"book","type":"update","data":[{"symbol":"AUD/USD","bids":[{"price":0.66434,"qty":0.00000000},{"price":0.66352,"qty":2804.00000000}],"asks":[],"checksum":605790146,"timestamp":"2024-06-01T17:53:14.059986Z"}]}
{"channel":"book","type":"update","data":[{"symbol":"AUD/USD","bids":[{"price":0.66436,"qty":1029.89615383}],"asks":[],"checksum":2916167340,"timestamp":"2024-06-01T17:53:14.061562Z"}]}
{"channel":"book","type":"update","data":[{"symbol":"AUD/USD","bids":[],"asks":[{"price":0.66463,"qty":0.00000000},{"price":0.66559,"qty":5032.00000000},{"price":0.66462,"qty":4880.21859208}],"checksum":4242694625,"timestamp":"2024-06-01T17:53:14.139812Z"}]}
{"channel":"book","type":"update","data":[{"symbol":"AUD/USD","bids":[{"price":0.66448,"qty":0.00000000},{"price":0.66352,"qty":2804.00000000}],"asks":[],"checksum":2650329527,"timestamp":"2024-06-01T17:53:14.195940Z"}]}
{"channel":"book","type":"update","data":[{"symbol":"AUD/USD","bids":[{"price":0.66381,"qty":0.00000000},{"price":0.66346,"qty":2506.00000000}],"asks":[],"checksum":832847653,"timestamp":"2024-06-01T17:53:14.195971Z"}]}
{"channel":"book","type":"update","data":[{"symbol":"AUD/USD","bids":[{"price":0.66381,"qty":485.66497909}],"asks":[],"checksum":1840294565,"timestamp":"2024-06-01T17:53:14.200618Z"}]}
{"channel":"book","type":"update","data":[{"symbol":"AUD/USD","bids":[{"price":0.66436,"qty":1113.94714343}],"asks":[],"checksum":4108373919,"timestamp":"2024-06-01T17:53:14.200655Z"}]}
{"channel":"book","type":"update","data":[{"symbol":"AUD/USD","bids":[],"asks":[{"price":0.66464,"qty":0.00000000},{"price":0.66559,"qty":5032.00000000},{"price":0.66461,"qty":12212.66745688}],"checksum":1815402701,"timestamp":"2024-06-01T17:53:14.232167Z"}]}
{"channel":"book","type":"update","data":[{"symbol":"AUD/USD","bids":[],"asks":[{"price":0.66526,"qty":20163.09675574}],"checksum":237281918,"timestamp":"2024-06-01T17:53:14.668646Z"}]}
{"channel":"book","type":"update","data":[{"symbol":"AUD/USD","bids":[],"asks":[{"price":0.66523,"qty":176.70145387}],"checksum":1744653567,"timestamp":"2024-06-01T17:53:14.669716Z"}]}
{"channel":"book","type":"update","data":[{"symbol":"AUD/USD","bids":[],"asks":[{"price":0.66462,"qty":0.00000000},{"price":0.66557,"qty":4434.00000000},{"price":0.66460,"qty":4880.21663521}],"checksum":409561584,"timestamp":"2024-06-01T17:53:14.937238Z"}]}
{"channel":"book","type":"update","data":[{"symbol":"AUD/USD","bids":[{"price":0.66435,"qty":0.00000000},{"price":0.66346,"qty":2506.00000000},{"price":0.66437,"qty":5601.04753168}],"asks":[],"checksum":2120390164,"timestamp":"2024-06-01T17:53:14.937338Z"}]}
{"channel":"book","type":"update","data":[{"symbol":"AUD/USD","bids":[{"price":0.66436,"qty":84.05098960}],"asks":[],"checksum":1345884398,"timestamp":"2024-06-01T17:53:14.943655Z"}]}
{"channel":"book","type":"update","data":[{"symbol":"AUD/USD","bids":[{"price":0.66438,"qty":1029.86518801}],"asks":[],"checksum":3674100937,"timestamp":"2024-06-01T17:53:14.943771Z"}]}
{"channel":"book","type":"update","data":[{"symbol":"AUD/USD","bids":[{"price":0.66437,"qty":0.00000000},{"price":0.66352,"qty":2804.00000000},{"price":0.66433,"qty":5601.38477658}],"asks":[],"checksum":3409786701,"timestamp":"2024-06-01T17:53:14.946847Z"}]}
{"channel":"book","type":"update","data":[{"symbol":"AUD/USD","bids":[{"price":0.66433,"qty":0.00000000},{"price":0.66352,"qty":2804.00000000},{"price":0.66439,"qty":5600.87892446}],"asks":[],"checksum":3256432464,"timestamp":"2024-06-01T17:53:15.801966Z"}]}
{"channel":"book","type":"update","data":[{"symbol":"AUD/USD","bids":[],"asks":[{"price":0.66460,"qty":0.00000000},{"price":0.66557,"qty":4434.00000000},{"price":0.66459,"qty":4880.22965957}],"checksum":3427607794,"timestamp":"2024-06-01T17:53:15.802218Z"}]}
{"channel":"book","type":"update","data":[{"symbol":"AUD/USD","bids":[{"price":0.66438,"qty":0.00000000},{"price":0.66352,"qty":2804.00000000}],"asks":[],"checksum":119855001,"timestamp":"2024-06-01T17:53:15.829118Z"}]}
{"channel":"book","type":"update","data":[{"symbol":"AUD/USD","bids":[{"price":0.66440,"qty":1029.83422405}],"asks":[],"checksum":4092449093,"timestamp":"2024-06-01T17:53:15.829349Z"}]}
{"channel":"book","type":"update","data":[{"symbol":"AUD/USD","bids":[{"price":0.66439,"qty":0.00000000},{"price":0.66352,"qty":2804.00000000},{"price":0.66433,"qty":5601.38477658}],"asks":[],"checksum":3880401761,"timestamp":"2024-06-01T17:53:15.832004Z"}]}
{"channel":"book","type":"update","data":[{"symbol":"AUD/USD","bids":[{"price":0.66440,"qty":0.00000000},{"price":0.66352,"qty":2804.00000000}],"asks":[],"checksum":3923602107,"timestamp":"2024-06-01T17:53:16.458900Z"}]}
{"channel":"book","type":"update","data":[{"symbol":"AUD/USD","bids":[{"price":0.66437,"qty":1029.88074595}],"asks":[],"checksum":759178497,"timestamp":"2024-06-01T17:53:16.458916Z"}]}
{"channel":"book","type":"update","data":[{"symbol":"AUD/USD","bids":[{"price":0.66433,"qty":0.00000000},{"price":0.66352,"qty":2804.00000000},{"price":0.66438,"qty":5600.96322680}],"asks":[],"checksum":2880608569,"timestamp":"2024-06-01T17:53:16.690236Z"}]}
{"channel":"book","type":"update","data":[{"symbol":"AUD/USD","bids":[],"asks":[{"price":0.66459,"qty":0.00000000},{"price":0.66557,"qty":4434.00000000},{"price":0.66458,"qty":4880.23130529}],"checksum":364186144,"timestamp":"2024-06-01T17:53:16.690261Z"}]}
{"channel":"book","type":"update","data":[{"symbol":"AUD/USD","bids":[{"price":0.66439,"qty":1029.84978106}],"asks":[],"checksum":1082249038,"timestamp":"2024-06-01T17:53:16.699460Z"}]}
{"channel":"book","type":"update","data":[{"symbol":"AUD/USD","bids":[{"price":0.66437,"qty":0.00000000},{"price":0.66358,"qty":3003.00000000}],"asks":[],"checksum":4032421989,"timestamp":"2024-06-01T17:53:16.699514Z"}]}
{"channel":"book","type":"update","data":[{"symbol":"AUD/USD","bids":[],"asks":[{"price":0.66458,"qty":0.00000000},{"price":0.66557,"qty":4434.00000000},{"price":0.66460,"qty":4880.28086522}],"checksum":3038018619,"timestamp":"2024-06-01T17:53:16.700220Z"}]}
{"channel":"book","type":"update","data":[{"symbol":"AUD/USD","bids":[{"price":0.66436,"qty":0.00000000},{"price":0.66352,"qty":2804.00000000}],"asks":[],"checksum":2394930054,"timestamp":"2024-06-01T17:53:16.856436Z"}]}
{"channel":"book","type":"update","data":[{"symbol":"AUD/USD","bids":[{"price":0.66381,"qty":0.00000000},{"price":0.66346,"qty":2506.00000000}],"asks":[],"checksum":2468364614,"timestamp":"2024-06-01T17:53:16.856624Z"}]}
{"channel":"book","type":"update","data":[{"symbol":"AUD/USD","bids":[{"price":0.66434,"qty":57.05642093}],"asks":[],"checksum":146450115,"timestamp":"2024-06-01T17:53:16.860516Z"}]}
{"channel":"book","type":"update","data":[{"symbol":"AUD/USD","bids":[{"price":0.66381,"qty":512.77158576}],"asks":[],"checksum":713642138,"timestamp":"2024-06-01T17:53:16.860560Z"}]}
{"channel":"book","type":"update","data":[{"symbol":"AUD/USD","bids":[],"asks":[{"price":0.66460,"qty":0.00000000},{"price":0.66557,"qty":4434.00000000},{"price":0.66459,"qty":4880.28086522}],"checksum":1825474745,"timestamp":"2024-06-01T17:53:17.602703Z"}]}
{"channel":"book","type":"update","data":[{"symbol":"AUD/USD","bids":[{"price":0.66438,"qty":0.00000000},{"price":0.66352,"qty":2804.00000000},{"price":0.66440,"qty":5600.79462466}],"asks":[],"checksum":674113496,"timestamp":"2024-06-01T17:53:17.602885Z"}]}
{"channel":"book","type":"update","data":[{"symbol":"AUD/USD","bids":[{"price":0.66439,"qty":0.00000000},{"price":0.66352,"qty":2804.00000000}],"asks":[],"checksum":3778654650,"timestamp":"2024-06-01T17:53:17.850994Z"}]}
{"channel":"book","type":"update","data":[{"symbol":"AUD/USD","bids":[{"price":0.66435,"qty":1029.91171270}],"asks":[],"checksum":4020747612,"timestamp":"2024-06-01T17:53:17.851541Z"}]}
{"channel":"book","type":"update","data":[{"symbol":"AUD/USD","bids":[{"price":0.66440,"qty":0.00000000},{"price":0.66352,"qty":2804.00000000},{"price":0.66436,"qty":5601.13183910}],"asks":[],"checksum":2849250321,"timestamp":"2024-06-01T17:53:17.859193Z"}]}
{"channel":"book","type":"update","data":[{"symbol":"AUD/USD","bids":[{"price":0.66435,"qty":0.00000000},{"price":0.66352,"qty":2804.00000000}],"asks":[],"checksum":2806649079,"timestamp":"2024-06-01T17:53:17.865338Z"}]}
{"channel":"book","type":"update","data":[{"symbol":"AUD/USD","bids":[{"price":0.66437,"qty":1029.88074595}],"asks":[],"checksum":1697191392,"timestamp":"2024-06-01T17:53:17.865374Z"}]}
{"channel":"book","type":"update","data":[{"symbol":"AUD/USD","bids":[{"price":0.66436,"qty":0.00000000},{"price":0.66352,"qty":2804.00000000},{"price":0.66435,"qty":5601.21614905}],"asks":[],"checksum":1279688455,"timestamp":"2024-06-01T17:53:17.868306Z"}]}
{"channel":"book","type":"update","data":[{"symbol":"AUD/USD","bids":[],"asks":[{"price":0.66525,"qty":0.00000000},{"price":0.66557,"qty":4434.00000000}],"checksum":959511481,"timestamp":"2024-06-01T17:53:18.301614Z"}]}
{"channel":"book","type":"update","data":[{"symbol":"AUD/USD","bids":[],"asks":[{"price":0.66526,"qty":0.00000000},{"price":0.66559,"qty":5032.00000000}],"checksum":937248273,"timestamp":"2024-06-01T17:53:18.301648Z"}]}
{"channel":"book","type":"update","data":[{"symbol":"AUD/USD","bids":[],"asks":[{"price":0.66522,"qty":3006.20781915}],"checksum":3952572348,"timestamp":"2024-06-01T17:53:18.302715Z"}]}
{"channel":"book","type":"update","data":[{"symbol":"AUD/USD","bids":[],"asks":[{"price":0.66545,"qty":20529.69851493}],"checksum":3227636282,"timestamp":"2024-06-01T17:53:18.302842Z"}]}
{"channel":"book","type":"update","data":[{"symbol":"AUD/USD","bids":[],"asks":[{"price":0.66459,"qty":0.00000000},{"price":0.66557,"qty":4434.00000000},{"price":0.66460,"qty":4880.26468559}],"checksum":1227634354,"timestamp":"2024-06-01T17:53:18.304530Z"}]}
{"channel":"book","type":"update","data":[{"symbol":"AUD/USD","bids":[],"asks":[{"price":0.66460,"qty":0.00000000},{"price":0.66557,"qty":4434.00000000},{"price":0.66459,"qty":4880.26468559}],"checksum":258731665,"timestamp":"2024-06-01T17:53:18.539235Z"}]}
{"channel":"book","type":"update","data":[{"symbol":"AUD/USD","bids":[{"price":0.66435,"qty":0.00000000},{"price":0.66352,"qty":2804.00000000},{"price":0.66438,"qty":5600.96322680}],"asks":[],"checksum":3390042986,"timestamp":"2024-06-01T17:53:18.539396Z"}]}
{"channel":"book","type":"update","data":[{"symbol":"AUD/USD","bids":[{"price":0.66437,"qty":0.00000000},{"price":0.66352,"qty":2804.00000000}],"asks":[],"checksum":3912159381,"timestamp":"2024-06-01T17:53:18.838949Z"}]}
{"channel":"book","type":"update","data":[{"symbol":"AUD/USD","bids":[{"price":0.66439,"qty":1029.84978106}],"asks":[],"checksum":803412271,"timestamp":"2024-06-01T17:53:18.839254Z"}]}
