{"channel":"book","type":"snapshot","data":[{"symbol":"BCH/AUD","bids":[{"price":692.34,"qty":6.00000000},{"price":692.23,"qty":6.15234407},{"price":692.22,"qty":0.23161520},{"price":691.72,"qty":1.00000000},{"price":691.70,"qty":1.00000000},{"price":691.69,"qty":1.00000000},{"price":691.63,"qty":1.00000000},{"price":691.61,"qty":0.26329050},{"price":690.96,"qty":2.74650750},{"price":690.91,"qty":10.93257000}],"asks":[{"price":693.44,"qty":1.00000000},{"price":693.45,"qty":1.00000000},{"price":693.46,"qty":1.00000000},{"price":693.47,"qty":1.00000000},{"price":693.48,"qty":1.00000000},{"price":693.72,"qty":0.02500000},{"price":694.14,"qty":0.26329050},{"price":695.42,"qty":2.58370377},{"price":695.43,"qty":2.74650750},{"price":695.57,"qty":10.93257000}],"checksum":1474878277}]}
{"channel":"book","type":"update","data":[{"symbol":"BCH/AUD","bids":[{"price":692.34,"qty":0.00000000},{"price":690.28,"qty":0.03288107}],"asks":[],"checksum":2483785570,"timestamp":"2024-06-01T17:51:16.643570Z"}]}
{"channel":"book","type":"update","data":[{"symbol":"BCH/AUD","bids":[{"price":692.24,"qty":6.00000000}],"asks":[],"checksum":1755968319,"timestamp":"2024-06-01T17:51:16.643745Z"}]}
{"channel":"book","type":"update","data":[{"symbol":"BCH/AUD","bids":[{"price":692.25,"qty":6.15216636}],"asks":[],"checksum":1010884914,"timestamp":"2024-06-01T17:51:16.664981Z"}]}
{"channel":"book","type":"update","data":[{"symbol":"BCH/AUD","bids":[{"price":692.23,"qty":0.00000000},{"price":690.91,"qty":10.93257000}],"asks":[],"checksum":3445482563,"timestamp":"2024-06-01T17:51:16.665182Z"}]}
{"channel":"book","type":"update","data":[{"symbol":"BCH/AUD","bids":[],"asks":[{"price":695.43,"qty":0.00000000},{"price":695.65,"qty":0.26329050}],"checksum":4020704678,"timestamp":"2024-06-01T17:51:16.835029Z"}]}
{"channel":"book","type":"update","data":[{"symbol":"BCH/AUD","bids":[],"asks":[{"price":695.41,"qty":2.74650750}],"checksum":2524613529,"timestamp":"2024-06-01T17:51:16.838950Z"}]}
{"channel":"book","type":"update","data":[{"symbol":"BCH/AUD","bids":[],"asks":[{"price":695.42,"qty":0.00000000},{"price":695.65,"qty":0.26329050}],"checksum":2480561052,"timestamp":"2024-06-01T17:51:16.853374Z"}]}
{"channel":"book","type":"update","data":[{"symbol":"BCH/AUD","bids":[],"asks":[{"price":695.40,"qty":2.58370377}],"checksum":2918168232,"timestamp":"2024-06-01T17:51:16.853433Z"}]}
{"channel":"book","type":"update","data":[{"symbol":"BCH/AUD","bids":[{"price":692.26,"qty":6.00000000}],"asks":[],"checksum":2585547857,"timestamp":"2024-06-01T17:51:17.142931Z"}]}
{"channel":"book","type":"update","data":[{"symbol":"BCH/AUD","bids":[{"price":692.24,"qty":0.00000000},{"price":690.91,"qty":10.93257000}],"asks":[],"checksum":1978328641,"timestamp":"2024-06-01T17:51:17.147796Z"}]}
{"channel":"book","type":"update","data":[{"symbol":"BCH/AUD","bids":[{"price":692.27,"qty":6.15198853}],"asks":[],"checksum":2749647276,"timestamp":"2024-06-01T17:51:17.150722Z"}]}
{"channel":"book","type":"update","data":[{"symbol":"BCH/AUD","bids":[{"price":692.25,"qty":0.00000000},{"price":690.91,"qty":10.93257000}],"asks":[],"checksum":2687628539,"timestamp":"2024-06-01T17:51:17.150809Z"}]}
{"channel":"book","type":"update","data":[{"symbol":"BCH/AUD","bids":[{"price":692.28,"qty":6.00000000}],"asks":[],"checksum":347576731,"timestamp":"2024-06-01T17:51:17.643412Z"}]}
{"channel":"book","type":"update","data":[{"symbol":"BCH/AUD","bids":[{"price":692.26,"qty":0.00000000},{"price":690.91,"qty":10.93257000}],"asks":[],"checksum":2196206166,"timestamp":"2024-06-01T17:51:17.648750Z"}]}
{"channel":"book","type":"update","data":[{"symbol":"BCH/AUD","bids":[{"price":692.27,"qty":0.00000000},{"price":690.28,"qty":0.03288107}],"asks":[],"checksum":3969731763,"timestamp":"2024-06-01T17:51:17.855191Z"}]}
{"channel":"book","type":"update","data":[{"symbol":"BCH/AUD","bids":[{"price":692.29,"qty":6.15181080}],"asks":[],"checksum":3377032076,"timestamp":"2024-06-01T17:51:17.855730Z"}]}
{"channel":"book","type":"update","data":[{"symbol":"BCH/AUD","bids":[{"price":692.30,"qty":6.00000000}],"asks":[],"checksum":518988247,"timestamp":"2024-06-01T17:51:18.142228Z"}]}
{"channel":"book","type":"update","data":[{"symbol":"BCH/AUD","bids":[{"price":692.28,"qty":0.00000000},{"price":690.91,"qty":10.93257000}],"asks":[],"checksum":4026222235,"timestamp":"2024-06-01T17:51:18.149224Z"}]}
{"channel":"book","type":"update","data":[{"symbol":"BCH/AUD","bids":[{"price":692.29,"qty":0.00000000},{"price":690.28,"qty":0.03288107}],"asks":[],"checksum":4175172437,"timestamp":"2024-06-01T17:51:18.169081Z"}]}
{"channel":"book","type":"update","data":[{"symbol":"BCH/AUD","bids":[{"price":692.23,"qty":6.15234401}],"asks":[],"checksum":4111645494,"timestamp":"2024-06-01T17:51:18.169242Z"}]}
{"channel":"book","type":"update","data":[{"symbol":"BCH/AUD","bids":[{"price":692.30,"qty":0.00000000},{"price":690.28,"qty":0.03288107}],"asks":[],"checksum":3334538142,"timestamp":"2024-06-01T17:51:19.644590Z"}]}
{"channel":"book","type":"update","data":[{"symbol":"BCH/AUD","bids":[{"price":692.24,"qty":6.00000000}],"asks":[],"checksum":2886402390,"timestamp":"2024-06-01T17:51:19.644766Z"}]}
{"channel":"book","type":"update","data":[{"symbol":"BCH/AUD","bids":[{"price":692.22,"qty":0.00000000},{"price":690.28,"qty":0.03288107},{"price":692.23,"qty":6.38395586}],"asks":[],"checksum":1866803931,"timestamp":"2024-06-01T17:51:19.651096Z"}]}
{"channel":"book","type":"update","data":[{"symbol":"BCH/AUD","bids":[{"price":692.23,"qty":0.23161185}],"asks":[],"checksum":1027557264,"timestamp":"2024-06-01T17:51:19.670600Z"}]}
{"channel":"book","type":"update","data":[{"symbol":"BCH/AUD","bids":[{"price":692.25,"qty":6.15216626}],"asks":[],"checksum":646979544,"timestamp":"2024-06-01T17:51:19.671112Z"}]}
{"channel":"book","type":"update","data":[{"symbol":"BCH/AUD","bids":[{"price":692.26,"qty":6.00000000}],"asks":[],"checksum":516750476,"timestamp":"2024-06-01T17:51:20.143891Z"}]}
{"channel":"book","type":"update","data":[{"symbol":"BCH/AUD","bids":[{"price":692.24,"qty":0.00000000},{"price":690.91,"qty":10.93257000}],"asks":[],"checksum":3022670929,"timestamp":"2024-06-01T17:51:20.148604Z"}]}
{"channel":"book","type":"update","data":[{"symbol":"BCH/AUD","bids":[{"price":692.25,"qty":0.00000000},{"price":690.28,"qty":0.03288107}],"asks":[],"checksum":111914412,"timestamp":"2024-06-01T17:51:20.156669Z"}]}
{"channel":"book","type":"update","data":[{"symbol":"BCH/AUD","bids":[{"price":692.27,"qty":6.15198853}],"asks":[],"checksum":3618016230,"timestamp":"2024-06-01T17:51:20.157023Z"}]}
{"channel":"book","type":"update","data":[{"symbol":"BCH/AUD","bids":[{"price":692.28,"qty":6.00000000}],"asks":[],"checksum":2711552377,"timestamp":"2024-06-01T17:51:20.643662Z"}]}
{"channel":"book","type":"update","data":[{"symbol":"BCH/AUD","bids":[{"price":692.27,"qty":0.00000000},{"price":690.91,"qty":10.93257000}],"asks":[],"checksum":1212398766,"timestamp":"2024-06-01T17:51:20.648368Z"}]}
{"channel":"book","type":"update","data":[{"symbol":"BCH/AUD","bids":[{"price":692.29,"qty":6.15181080}],"asks":[],"checksum":189963356,"timestamp":"2024-06-01T17:51:20.648383Z"}]}
{"channel":"book","type":"update","data":[{"symbol":"BCH/AUD","bids":[{"price":692.26,"qty":0.00000000},{"price":690.91,"qty":10.93257000}],"asks":[],"checksum":3202225297,"timestamp":"2024-06-01T17:51:20.649763Z"}]}
{"channel":"book","type":"update","data":[{"symbol":"BCH/AUD","bids":[{"price":692.30,"qty":6.00000000}],"asks":[],"checksum":2881993013,"timestamp":"2024-06-01T17:51:21.144192Z"}]}
{"channel":"book","type":"update","data":[{"symbol":"BCH/AUD","bids":[{"price":692.28,"qty":0.00000000},{"price":690.91,"qty":10.93257000}],"asks":[],"checksum":2557229446,"timestamp":"2024-06-01T17:51:21.151842Z"}]}
{"channel":"book","type":"update","data":[{"symbol":"BCH/AUD","bids":[{"price":692.29,"qty":0.00000000},{"price":690.28,"qty":0.03288107}],"asks":[],"checksum":2953078014,"timestamp":"2024-06-01T17:51:21.160074Z"}]}
{"channel":"book","type":"update","data":[{"symbol":"BCH/AUD","bids":[{"price":692.24,"qty":6.15225514}],"asks":[],"checksum":353222303,"timestamp":"2024-06-01T17:51:21.160152Z"}]}
{"channel":"book","type":"update","data":[{"symbol":"BCH/AUD","bids":[{"price":692.30,"qty":0.00000000},{"price":690.28,"qty":0.03288107}],"asks":[],"checksum":3193600731,"timestamp":"2024-06-01T17:51:22.644598Z"}]}
{"channel":"book","type":"update","data":[{"symbol":"BCH/AUD","bids":[{"price":692.25,"qty":6.00000000}],"asks":[],"checksum":3090850649,"timestamp":"2024-06-01T17:51:22.644735Z"}]}
{"channel":"book","type":"update","data":[{"symbol":"BCH/AUD","bids":[{"price":692.24,"qty":0.00000000},{"price":690.28,"qty":0.03288107}],"asks":[],"checksum":552940174,"timestamp":"2024-06-01T17:51:22.648611Z"}]}
{"channel":"book","type":"update","data":[{"symbol":"BCH/AUD","bids":[{"price":692.26,"qty":6.15207739}],"asks":[],"checksum":3466596481,"timestamp":"2024-06-01T17:51:22.648629Z"}]}
{"channel":"book","type":"update","data":[{"symbol":"BCH/AUD","bids":[{"price":692.27,"qty":6.00000000}],"asks":[],"checksum":2143154706,"timestamp":"2024-06-01T17:51:23.143833Z"}]}
{"channel":"book","type":"update","data":[{"symbol":"BCH/AUD","bids":[{"price":692.25,"qty":0.00000000},{"price":690.91,"qty":10.93257000}],"asks":[],"checksum":3857025318,"timestamp":"2024-06-01T17:51:23.151771Z"}]}
{"channel":"book","type":"update","data":[{"symbol":"BCH/AUD","bids":[{"price":692.26,"qty":0.00000000},{"price":690.28,"qty":0.03288107}],"asks":[],"checksum":459397298,"timestamp":"2024-06-01T17:51:23.168978Z"}]}
{"channel":"book","type":"update","data":[{"symbol":"BCH/AUD","bids":[{"price":692.28,"qty":6.15189966}],"asks":[],"checksum":4060101287,"timestamp":"2024-06-01T17:51:23.169059Z"}]}
{"channel":"book","type":"update","data":[{"symbol":"BCH/AUD","bids":[{"price":692.29,"qty":6.00000000}],"asks":[],"checksum":1094421051,"timestamp":"2024-06-01T17:51:23.644130Z"}]}
{"channel":"book","type":"update","data":[{"symbol":"BCH/AUD","bids":[{"price":692.27,"qty":0.00000000},{"price":690.91,"qty":10.93257000}],"asks":[],"checksum":727417670,"timestamp":"2024-06-01T17:51:23.649768Z"}]}
{"channel":"book","type":"update","data":[{"symbol":"BCH/AUD","bids":[{"price":692.28,"qty":0.00000000},{"price":690.28,"qty":0.03288107}],"asks":[],"checksum":3113176582,"timestamp":"2024-06-01T17:51:23.658231Z"}]}
{"channel":"book","type":"update","data":[{"symbol":"BCH/AUD","bids":[{"price":692.24,"qty":6.15225514}],"asks":[],"checksum":315823479,"timestamp":"2024-06-01T17:51:23.658251Z"}]}
{"channel":"book","type":"update","data":[{"symbol":"BCH/AUD","bids":[{"price":692.24,"qty":0.00000000},{"price":690.28,"qty":0.03288107}],"asks":[],"checksum":3113176582,"timestamp":"2024-06-01T17:51:24.105691Z"}]}
{"channel":"book","type":"update","data":[{"symbol":"BCH/AUD","bids":[{"price":692.30,"qty":6.15172205}],"asks":[],"checksum":3593191836,"timestamp":"2024-06-01T17:51:24.105778Z"}]}
{"channel":"book","type":"update","data":[{"symbol":"BCH/AUD","bids":[{"price":692.31,"qty":6.00000000}],"asks":[],"checksum":2823243721,"timestamp":"2024-06-01T17:51:24.112041Z"}]}
{"channel":"book","type":"update","data":[{"symbol":"BCH/AUD","bids":[{"price":692.29,"qty":0.00000000},{"price":690.91,"qty":10.93257000}],"asks":[],"checksum":1786580341,"timestamp":"2024-06-01T17:51:24.143971Z"}]}
{"channel":"book","type":"update","data":[{"symbol":"BCH/AUD","bids":[{"price":692.30,"qty":0.00000000},{"price":690.28,"qty":0.03288107}],"asks":[],"checksum":2915963360,"timestamp":"2024-06-01T17:51:24.152236Z"}]}
{"channel":"book","type":"update","data":[{"symbol":"BCH/AUD","bids":[{"price":692.24,"qty":6.15225521}],"asks":[],"checksum":380801196,"timestamp":"2024-06-01T17:51:24.152396Z"}]}
{"channel":"book","type":"update","data":[{"symbol":"BCH/AUD","bids":[{"price":692.24,"qty":0.00000000},{"price":690.28,"qty":0.03288107}],"asks":[],"checksum":2915963360,"timestamp":"2024-06-01T17:51:25.045347Z"}]}
{"channel":"book","type":"update","data":[{"symbol":"BCH/AUD","bids":[{"price":692.32,"qty":6.15154422}],"asks":[],"checksum":3634348330,"timestamp":"2024-06-01T17:51:25.045367Z"}]}
{"channel":"book","type":"update","data":[{"symbol":"BCH/AUD","bids":[{"price":692.32,"qty":0.00000000},{"price":690.28,"qty":0.03288107}],"asks":[],"checksum":2915963360,"timestamp":"2024-06-01T17:51:25.101828Z"}]}
{"channel":"book","type":"update","data":[{"symbol":"BCH/AUD","bids":[{"price":692.24,"qty":6.15225521}],"asks":[],"checksum":380801196,"timestamp":"2024-06-01T17:51:25.101894Z"}]}
{"channel":"book","type":"update","data":[{"symbol":"BCH/AUD","bids":[{"price":692.31,"qty":0.00000000},{"price":690.28,"qty":0.03288107}],"asks":[],"checksum":2591344969,"timestamp":"2024-06-01T17:51:25.142499Z"}]}
{"channel":"book","type":"update","data":[{"symbol":"BCH/AUD","bids":[{"price":692.25,"qty":6.00000000}],"asks":[],"checksum":1336617676,"timestamp":"2024-06-01T17:51:25.142650Z"}]}
{"channel":"book","type":"update","data":[{"symbol":"BCH/AUD","bids":[{"price":692.23,"qty":0.00000000},{"price":690.28,"qty":0.03288107},{"price":692.26,"qty":0.23160181}],"asks":[],"checksum":3081484009,"timestamp":"2024-06-01T17:51:25.152308Z"}]}
{"channel":"book","type":"update","data":[{"symbol":"BCH/AUD","bids":[{"price":692.27,"qty":6.15198853}],"asks":[],"checksum":1341056383,"timestamp":"2024-06-01T17:51:26.047014Z"}]}
{"channel":"book","type":"update","data":[{"symbol":"BCH/AUD","bids":[{"price":692.24,"qty":0.00000000},{"price":690.91,"qty":10.93257000}],"asks":[],"checksum":3706805469,"timestamp":"2024-06-01T17:51:26.047236Z"}]}
{"channel":"book","type":"update","data":[{"symbol":"BCH/AUD","bids":[{"price":692.28,"qty":6.00000000}],"asks":[],"checksum":138375293,"timestamp":"2024-06-01T17:51:26.052291Z"}]}
{"channel":"book","type":"update","data":[{"symbol":"BCH/AUD","bids":[{"price":692.25,"qty":0.00000000},{"price":690.91,"qty":10.93257000}],"asks":[],"checksum":2783101983,"timestamp":"2024-06-01T17:51:26.143135Z"}]}
{"channel":"book","type":"update","data":[{"symbol":"BCH/AUD","bids":[{"price":692.26,"qty":0.00000000},{"price":690.28,"qty":0.03288107},{"price":692.29,"qty":0.23159178}],"asks":[],"checksum":2623978485,"timestamp":"2024-06-01T17:51:30.835207Z"}]}
{"channel":"book","type":"update","data":[{"symbol":"BCH/AUD","bids":[{"price":691.73,"qty":6.15679108}],"asks":[],"checksum":908595624,"timestamp":"2024-06-01T17:51:30.856723Z"}]}
{"channel":"book","type":"update","data":[{"symbol":"BCH/AUD","bids":[{"price":692.27,"qty":0.00000000},{"price":690.91,"qty":10.93257000}],"asks":[],"checksum":3959075034,"timestamp":"2024-06-01T17:51:30.856841Z"}]}
{"channel":"book","type":"update","data":[{"symbol":"BCH/AUD","bids":[{"price":692.28,"qty":0.00000000},{"price":690.28,"qty":0.03288107}],"asks":[],"checksum":2116917750,"timestamp":"2024-06-01T17:51:31.143639Z"}]}
{"channel":"book","type":"update","data":[{"symbol":"BCH/AUD","bids":[{"price":691.74,"qty":6.00000000}],"asks":[],"checksum":948746596,"timestamp":"2024-06-01T17:51:31.143812Z"}]}
{"channel":"book","type":"update","data":[{"symbol":"BCH/AUD","bids":[{"price":691.73,"qty":0.00000000},{"price":690.28,"qty":0.03288107}],"asks":[],"checksum":2190308314,"timestamp":"2024-06-01T17:51:31.164561Z"}]}
{"channel":"book","type":"update","data":[{"symbol":"BCH/AUD","bids":[{"price":691.75,"qty":6.15661308}],"asks":[],"checksum":2824146021,"timestamp":"2024-06-01T17:51:31.164641Z"}]}
{"channel":"book","type":"update","data":[{"symbol":"BCH/AUD","bids":[{"price":691.76,"qty":6.00000000}],"asks":[],"checksum":3722870243,"timestamp":"2024-06-01T17:51:31.643213Z"}]}
{"channel":"book","type":"update","data":[{"symbol":"BCH/AUD","bids":[{"price":691.74,"qty":0.00000000},{"price":690.91,"qty":10.93257000}],"asks":[],"checksum":1213945041,"timestamp":"2024-06-01T17:51:31.648829Z"}]}
{"channel":"book","type":"update","data":[{"symbol":"BCH/AUD","bids":[{"price":691.75,"qty":0.00000000},{"price":690.28,"qty":0.03288107}],"asks":[],"checksum":2078386201,"timestamp":"2024-06-01T17:51:31.651055Z"}]}
{"channel":"book","type":"update","data":[{"symbol":"BCH/AUD","bids":[{"price":691.77,"qty":6.15643508}],"asks":[],"checksum":3666260455,"timestamp":"2024-06-01T17:51:31.651375Z"}]}
{"channel":"book","type":"update","data":[{"symbol":"BCH/AUD","bids":[{"price":691.77,"qty":0.00000000},{"price":690.28,"qty":0.03288107}],"asks":[],"checksum":2078386201,"timestamp":"2024-06-01T17:51:31.675762Z"}]}
{"channel":"book","type":"update","data":[{"symbol":"BCH/AUD","bids":[{"price":692.30,"qty":6.15172194}],"asks":[],"checksum":2636796702,"timestamp":"2024-06-01T17:51:31.675968Z"}]}
{"channel":"book","type":"update","data":[{"symbol":"BCH/AUD","bids":[{"price":692.31,"qty":6.00000000}],"asks":[],"checksum":1283398844,"timestamp":"2024-06-01T17:51:32.143821Z"}]}
{"channel":"book","type":"update","data":[{"symbol":"BCH/AUD","bids":[{"price":691.76,"qty":0.00000000},{"price":690.91,"qty":10.93257000}],"asks":[],"checksum":2070563937,"timestamp":"2024-06-01T17:51:32.149006Z"}]}
{"channel":"book","type":"update","data":[{"symbol":"BCH/AUD","bids":[{"price":692.29,"qty":0.00000000},{"price":690.28,"qty":0.03288107},{"price":692.32,"qty":0.23158174}],"asks":[],"checksum":277534989,"timestamp":"2024-06-01T17:51:36.368982Z"}]}
{"channel":"book","type":"update","data":[{"symbol":"BCH/AUD","bids":[{"price":691.73,"qty":6.15679108}],"asks":[],"checksum":154540790,"timestamp":"2024-06-01T17:51:36.401890Z"}]}
{"channel":"book","type":"update","data":[{"symbol":"BCH/AUD","bids":[{"price":692.30,"qty":0.00000000},{"price":690.91,"qty":10.93257000}],"asks":[],"checksum":2058853554,"timestamp":"2024-06-01T17:51:36.401976Z"}]}
{"channel":"book","type":"update","data":[{"symbol":"BCH/AUD","bids":[{"price":692.31,"qty":0.00000000},{"price":690.28,"qty":0.03288107}],"asks":[],"checksum":3384163848,"timestamp":"2024-06-01T17:51:36.642802Z"}]}
{"channel":"book","type":"update","data":[{"symbol":"BCH/AUD","bids":[{"price":691.74,"qty":6.00000000}],"asks":[],"checksum":4194432135,"timestamp":"2024-06-01T17:51:36.642923Z"}]}
{"channel":"book","type":"update","data":[{"symbol":"BCH/AUD","bids":[{"price":691.73,"qty":0.00000000},{"price":690.28,"qty":0.03288107}],"asks":[],"checksum":890688548,"timestamp":"2024-06-01T17:51:36.655606Z"}]}
{"channel":"book","type":"update","data":[{"symbol":"BCH/AUD","bids":[{"price":691.75,"qty":6.15661308}],"asks":[],"checksum":1792557446,"timestamp":"2024-06-01T17:51:36.655626Z"}]}
{"channel":"book","type":"update","data":[{"symbol":"BCH/AUD","bids":[{"price":691.76,"qty":6.00000000}],"asks":[],"checksum":2270443871,"timestamp":"2024-06-01T17:51:37.142786Z"}]}
{"channel":"book","type":"update","data":[{"symbol":"BCH/AUD","bids":[{"price":691.74,"qty":0.00000000},{"price":690.91,"qty":10.93257000}],"asks":[],"checksum":2329286962,"timestamp":"2024-06-01T17:51:37.149358Z"}]}
{"channel":"book","type":"update","data":[{"symbol":"BCH/AUD","bids":[{"price":691.77,"qty":6.15643508}],"asks":[],"checksum":211402311,"timestamp":"2024-06-01T17:51:37.175137Z"}]}
{"channel":"book","type":"update","data":[{"symbol":"BCH/AUD","bids":[{"price":691.75,"qty":0.00000000},{"price":690.91,"qty":10.93257000}],"asks":[],"checksum":403438596,"timestamp":"2024-06-01T17:51:37.175157Z"}]}
{"channel":"book","type":"update","data":[{"symbol":"BCH/AUD","bids":[{"price":691.78,"qty":6.00000000}],"asks":[],"checksum":862084037,"timestamp":"2024-06-01T17:51:37.181797Z"}]}
{"channel":"book","type":"update","data":[{"symbol":"BCH/AUD","bids":[{"price":691.77,"qty":0.00000000},{"price":690.91,"qty":10.93257000}],"asks":[],"checksum":3766739962,"timestamp":"2024-06-01T17:51:37.213865Z"}]}
{"channel":"book","type":"update","data":[{"symbol":"BCH/AUD","bids":[{"price":691.79,"qty":6.15625710}],"asks":[],"checksum":2122846091,"timestamp":"2024-06-01T17:51:37.213996Z"}]}
{"channel":"book","type":"update","data":[{"symbol":"BCH/AUD","bids":[{"price":691.78,"qty":0.00000000},{"price":690.91,"qty":10.93257000}],"asks":[],"checksum":3207302571,"timestamp":"2024-06-01T17:51:37.218925Z"}]}
{"channel":"book","type":"update","data":[{"symbol":"BCH/AUD","bids":[{"price":691.80,"qty":6.00000000}],"asks":[],"checksum":1760782639,"timestamp":"2024-06-01T17:51:37.643401Z"}]}
{"channel":"book","type":"update","data":[{"symbol":"BCH/AUD","bids":[{"price":691.76,"qty":0.00000000},{"price":690.91,"qty":10.93257000}],"asks":[],"checksum":306709226,"timestamp":"2024-06-01T17:51:37.648569Z"}]}
{"channel":"book","type":"update","data":[{"symbol":"BCH/AUD","bids":[{"price":691.81,"qty":6.15607912}],"asks":[],"checksum":1987032140,"timestamp":"2024-06-01T17:51:37.674027Z"}]}
{"channel":"book","type":"update","data":[{"symbol":"BCH/AUD","bids":[{"price":691.79,"qty":0.00000000},{"price":690.91,"qty":10.93257000}],"asks":[],"checksum":2150879176,"timestamp":"2024-06-01T17:51:37.674172Z"}]}
{"channel":"book","type":"update","data":[{"symbol":"BCH/AUD","bids":[{"price":691.82,"qty":6.00000000}],"asks":[],"checksum":2607507374,"timestamp":"2024-06-01T17:51:37.679259Z"}]}
{"channel":"book","type":"update","data":[{"symbol":"BCH/AUD","bids":[{"price":691.81,"qty":0.00000000},{"price":690.91,"qty":10.93257000}],"asks":[],"checksum":945704890,"timestamp":"2024-06-01T17:51:37.706560Z"}]}
{"channel":"book","type":"update","data":[{"symbol":"BCH/AUD","bids":[{"price":691.83,"qty":6.15590116}],"asks":[],"checksum":3058841185,"timestamp":"2024-06-01T17:51:37.706862Z"}]}
{"channel":"book","type":"update","data":[{"symbol":"BCH/AUD","bids":[{"price":691.82,"qty":0.00000000},{"price":690.91,"qty":10.93257000}],"asks":[],"checksum":978787177,"timestamp":"2024-06-01T17:51:37.711162Z"}]}
{"channel":"book","type":"update","data":[{"symbol":"BCH/AUD","bids":[{"price":691.84,"qty":6.00000000}],"asks":[],"checksum":2090466654,"timestamp":"2024-06-01T17:51:38.144236Z"}]}
{"channel":"book","type":"update","data":[{"symbol":"BCH/AUD","bids":[{"price":691.80,"qty":0.00000000},{"price":690.91,"qty":10.93257000}],"asks":[],"checksum":3676273326,"timestamp":"2024-06-01T17:51:38.149658Z"}]}
{"channel":"book","type":"update","data":[{"symbol":"BCH/AUD","bids":[{"price":691.85,"qty":6.15572320}],"asks":[],"checksum":4271728698,"timestamp":"2024-06-01T17:51:38.156174Z"}]}
{"channel":"book","type":"update","data":[{"symbol":"BCH/AUD","bids":[{"price":691.83,"qty":0.00000000},{"price":690.91,"qty":10.93257000}],"asks":[],"checksum":2118235142,"timestamp":"2024-06-01T17:51:38.156303Z"}]}
{"channel":"book","type":"update","data":[{"symbol":"BCH/AUD","bids":[{"price":691.86,"qty":6.00000000}],"asks":[],"checksum":1443444805,"timestamp":"2024-06-01T17:51:38.643516Z"}]}
{"channel":"book","type":"update","data":[{"symbol":"BCH/AUD","bids":[{"price":691.84,"qty":0.00000000},{"price":690.91,"qty":10.93257000}],"asks":[],"checksum":449363630,"timestamp":"2024-06-01T17:51:38.648363Z"}]}
{"channel":"book","type":"update","data":[{"symbol":"BCH/AUD","bids":[{"price":691.87,"qty":6.15554526}],"asks":[],"checksum":3952307052,"timestamp":"2024-06-01T17:51:38.665839Z"}]}
{"channel":"book","type":"update","data":[{"symbol":"BCH/AUD","bids":[{"price":691.85,"qty":0.00000000},{"price":690.91,"qty":10.93257000}],"asks":[],"checksum":165765256,"timestamp":"2024-06-01T17:51:38.665874Z"}]}
{"channel":"book","type":"update","data":[{"symbol":"BCH/AUD","bids":[{"price":691.88,"qty":6.00000000}],"asks":[],"checksum":292415827,"timestamp":"2024-06-01T17:51:39.143191Z"}]}
{"channel":"book","type":"update","data":[{"symbol":"BCH/AUD","bids":[{"price":691.86,"qty":0.00000000},{"price":690.91,"qty":10.93257000}],"asks":[],"checksum":640656026,"timestamp":"2024-06-01T17:51:39.148465Z"}]}
{"channel":"book","type":"update","data":[{"symbol":"BCH/AUD","bids":[{"price":691.87,"qty":0.00000000},{"price":690.28,"qty":0.03288107}],"asks":[],"checksum":2935162258,"timestamp":"2024-06-01T17:51:39.165425Z"}]}
{"channel":"book","type":"update","data":[{"symbol":"BCH/AUD","bids":[{"price":691.89,"qty":6.15536732}],"asks":[],"checksum":3528195081,"timestamp":"2024-06-01T17:51:39.165678Z"}]}
{"channel":"book","type":"update","data":[{"symbol":"BCH/AUD","bids":[{"price":691.90,"qty":6.00000000}],"asks":[],"checksum":3899469645,"timestamp":"2024-06-01T17:51:39.643926Z"}]}
{"channel":"book","type":"update","data":[{"symbol":"BCH/AUD","bids":[{"price":691.88,"qty":0.00000000},{"price":690.91,"qty":10.93257000}],"asks":[],"checksum":3355768304,"timestamp":"2024-06-01T17:51:39.650734Z"}]}
{"channel":"book","type":"update","data":[{"symbol":"BCH/AUD","bids":[{"price":691.91,"qty":6.15518940}],"asks":[],"checksum":262925387,"timestamp":"2024-06-01T17:51:39.665803Z"}]}
{"channel":"book","type":"update","data":[{"symbol":"BCH/AUD","bids":[{"price":691.89,"qty":0.00000000},{"price":690.91,"qty":10.93257000}],"asks":[],"checksum":3901926432,"timestamp":"2024-06-01T17:51:39.665935Z"}]}
{"channel":"book","type":"update","data":[{"symbol":"BCH/AUD","bids":[{"price":691.92,"qty":6.00000000}],"asks":[],"checksum":4089121029,"timestamp":"2024-06-01T17:51:40.143703Z"}]}
{"channel":"book","type":"update","data":[{"symbol":"BCH/AUD","bids":[{"price":691.90,"qty":0.00000000},{"price":690.91,"qty":10.93257000}],"asks":[],"checksum":1095487882,"timestamp":"2024-06-01T17:51:40.149564Z"}]}
{"channel":"book","type":"update","data":[{"symbol":"BCH/AUD","bids":[{"price":691.91,"qty":0.00000000},{"price":690.28,"qty":0.03288107}],"asks":[],"checksum":3896262935,"timestamp":"2024-06-01T17:51:40.153361Z"}]}
{"channel":"book","type":"update","data":[{"symbol":"BCH/AUD","bids":[{"price":691.93,"qty":6.15501148}],"asks":[],"checksum":720256332,"timestamp":"2024-06-01T17:51:40.153575Z"}]}
{"channel":"book","type":"update","data":[{"symbol":"BCH/AUD","bids":[],"asks":[{"price":695.41,"qty":0.00000000},{"price":695.65,"qty":0.26329050}],"checksum":1135014832,"timestamp":"2024-06-01T17:51:40.373944Z"}]}
{"channel":"book","type":"update","data":[{"symbol":"BCH/AUD","bids":[],"asks":[{"price":695.39,"qty":2.74650750}],"checksum":2199686781,"timestamp":"2024-06-01T17:51:40.377129Z"}]}
{"channel":"book","type":"update","data":[{"symbol":"BCH/AUD","bids":[],"asks":[{"price":695.40,"qty":0.00000000},{"price":695.65,"qty":0.26329050}],"checksum":2282166489,"timestamp":"2024-06-01T17:51:40.386219Z"}]}
{"channel":"book","type":"update","data":[{"symbol":"BCH/AUD","bids":[],"asks":[{"price":695.38,"qty":2.58370377}],"checksum":809741974,"timestamp":"2024-06-01T17:51:40.386484Z"}]}
{"channel":"book","type":"update","data":[{"symbol":"BCH/AUD","bids":[{"price":691.94,"qty":6.00000000}],"asks":[],"checksum":3278049912,"timestamp":"2024-06-01T17:51:40.644576Z"}]}
{"channel":"book","type":"update","data":[{"symbol":"BCH/AUD","bids":[{"price":691.95,"qty":6.15483358}],"asks":[],"checksum":1595008985,"timestamp":"2024-06-01T17:51:40.647988Z"}]}
{"channel":"book","type":"update","data":[{"symbol":"BCH/AUD","bids":[{"price":691.93,"qty":0.00000000},{"price":690.96,"qty":2.74650750}],"asks":[],"checksum":3475114222,"timestamp":"2024-06-01T17:51:40.648049Z"}]}
{"channel":"book","type":"update","data":[{"symbol":"BCH/AUD","bids":[{"price":691.92,"qty":0.00000000},{"price":690.91,"qty":10.93257000}],"asks":[],"checksum":3202072271,"timestamp":"2024-06-01T17:51:40.649174Z"}]}
{"channel":"book","type":"update","data":[{"symbol":"BCH/AUD","bids":[{"price":691.96,"qty":6.00000000}],"asks":[],"checksum":3597865920,"timestamp":"2024-06-01T17:51:41.142743Z"}]}
{"channel":"book","type":"update","data":[{"symbol":"BCH/AUD","bids":[{"price":691.94,"qty":0.00000000},{"price":690.91,"qty":10.93257000}],"asks":[],"checksum":3791172230,"timestamp":"2024-06-01T17:51:41.148078Z"}]}
{"channel":"book","type":"update","data":[{"symbol":"BCH/AUD","bids":[{"price":691.95,"qty":0.00000000},{"price":690.28,"qty":0.03288107}],"asks":[],"checksum":2164486865,"timestamp":"2024-06-01T17:51:41.151854Z"}]}
{"channel":"book","type":"update","data":[{"symbol":"BCH/AUD","bids":[{"price":691.97,"qty":6.15465569}],"asks":[],"checksum":1580691596,"timestamp":"2024-06-01T17:51:41.152009Z"}]}
{"channel":"book","type":"update","data":[{"symbol":"BCH/AUD","bids":[{"price":691.98,"qty":6.00000000}],"asks":[],"checksum":2613090413,"timestamp":"2024-06-01T17:51:41.644839Z"}]}
{"channel":"book","type":"update","data":[{"symbol":"BCH/AUD","bids":[{"price":691.96,"qty":0.00000000},{"price":690.91,"qty":10.93257000}],"asks":[],"checksum":2175144940,"timestamp":"2024-06-01T17:51:41.650509Z"}]}
{"channel":"book","type":"update","data":[{"symbol":"BCH/AUD","bids":[{"price":691.99,"qty":6.15447781}],"asks":[],"checksum":4116770016,"timestamp":"2024-06-01T17:51:41.675524Z"}]}
{"channel":"book","type":"update","data":[{"symbol":"BCH/AUD","bids":[{"price":691.97,"qty":0.00000000},{"price":690.91,"qty":10.93257000}],"asks":[],"checksum":3000453821,"timestamp":"2024-06-01T17:51:41.675588Z"}]}
{"channel":"book","type":"update","data":[{"symbol":"BCH/AUD","bids":[{"price":692.00,"qty":6.00000000}],"asks":[],"checksum":1454366856,"timestamp":"2024-06-01T17:51:41.680845Z"}]}
{"channel":"book","type":"update","data":[{"symbol":"BCH/AUD","bids":[{"price":691.99,"qty":0.00000000},{"price":690.91,"qty":10.93257000}],"asks":[],"checksum":3081150790,"timestamp":"2024-06-01T17:51:41.692562Z"}]}
{"channel":"book","type":"update","data":[{"symbol":"BCH/AUD","bids":[{"price":692.01,"qty":6.15429993}],"asks":[],"checksum":1063546245,"timestamp":"2024-06-01T17:51:41.692585Z"}]}
{"channel":"book","type":"update","data":[{"symbol":"BCH/AUD","bids":[{"price":692.00,"qty":0.00000000},{"price":690.91,"qty":10.93257000}],"asks":[],"checksum":3846057549,"timestamp":"2024-06-01T17:51:42.142005Z"}]}
{"channel":"book","type":"update","data":[{"symbol":"BCH/AUD","bids":[{"price":692.02,"qty":6.00000000}],"asks":[],"checksum":1045129455,"timestamp":"2024-06-01T17:51:42.142162Z"}]}
{"channel":"book","type":"update","data":[{"symbol":"BCH/AUD","bids":[{"price":691.98,"qty":0.00000000},{"price":690.91,"qty":10.93257000}],"asks":[],"checksum":2523402463,"timestamp":"2024-06-01T17:51:42.148361Z"}]}
{"channel":"book","type":"update","data":[{"symbol":"BCH/AUD","bids":[{"price":692.01,"qty":0.00000000},{"price":690.28,"qty":0.03288107}],"asks":[],"checksum":714018393,"timestamp":"2024-06-01T17:51:42.152220Z"}]}
{"channel":"book","type":"update","data":[{"symbol":"BCH/AUD","bids":[{"price":692.03,"qty":6.15412207}],"asks":[],"checksum":2270405128,"timestamp":"2024-06-01T17:51:42.152364Z"}]}
{"channel":"book","type":"update","data":[{"symbol":"BCH/AUD","bids":[{"price":692.04,"qty":6.00000000}],"asks":[],"checksum":2388513859,"timestamp":"2024-06-01T17:51:42.644808Z"}]}
{"channel":"book","type":"update","data":[{"symbol":"BCH/AUD","bids":[{"price":692.02,"qty":0.00000000},{"price":690.91,"qty":10.93257000}],"asks":[],"checksum":1326943759,"timestamp":"2024-06-01T17:51:42.649992Z"}]}
{"channel":"book","type":"update","data":[{"symbol":"BCH/AUD","bids":[{"price":692.03,"qty":0.00000000},{"price":690.28,"qty":0.03288107}],"asks":[],"checksum":4199244893,"timestamp":"2024-06-01T17:51:42.671255Z"}]}
{"channel":"book","type":"update","data":[{"symbol":"BCH/AUD","bids":[{"price":692.05,"qty":6.15394422}],"asks":[],"checksum":4112640144,"timestamp":"2024-06-01T17:51:42.671407Z"}]}
{"channel":"book","type":"update","data":[{"symbol":"BCH/AUD","bids":[{"price":692.06,"qty":6.00000000}],"asks":[],"checksum":744045830,"timestamp":"2024-06-01T17:51:43.143606Z"}]}
{"channel":"book","type":"update","data":[{"symbol":"BCH/AUD","bids":[{"price":692.04,"qty":0.00000000},{"price":690.91,"qty":10.93257000}],"asks":[],"checksum":3404689252,"timestamp":"2024-06-01T17:51:43.149242Z"}]}
{"channel":"book","type":"update","data":[{"symbol":"BCH/AUD","bids":[{"price":692.07,"qty":6.15376638}],"asks":[],"checksum":900515137,"timestamp":"2024-06-01T17:51:43.165184Z"}]}
{"channel":"book","type":"update","data":[{"symbol":"BCH/AUD","bids":[{"price":692.05,"qty":0.00000000},{"price":690.91,"qty":10.93257000}],"asks":[],"checksum":2347537951,"timestamp":"2024-06-01T17:51:43.165219Z"}]}
{"channel":"book","type":"update","data":[{"symbol":"BCH/AUD","bids":[{"price":692.08,"qty":6.00000000}],"asks":[],"checksum":1415675047,"timestamp":"2024-06-01T17:51:43.644417Z"}]}
{"channel":"book","type":"update","data":[{"symbol":"BCH/AUD","bids":[{"price":692.06,"qty":0.00000000},{"price":690.91,"qty":10.93257000}],"asks":[],"checksum":2737965551,"timestamp":"2024-06-01T17:51:43.651739Z"}]}
{"channel":"book","type":"update","data":[{"symbol":"BCH/AUD","bids":[{"price":692.07,"qty":0.00000000},{"price":690.28,"qty":0.03288107}],"asks":[],"checksum":2159195668,"timestamp":"2024-06-01T17:51:43.670921Z"}]}
{"channel":"book","type":"update","data":[{"symbol":"BCH/AUD","bids":[{"price":692.09,"qty":6.15358855}],"asks":[],"checksum":2347506552,"timestamp":"2024-06-01T17:51:43.671008Z"}]}
{"channel":"book","type":"update","data":[{"symbol":"BCH/AUD","bids":[{"price":692.09,"qty":0.00000000},{"price":690.28,"qty":0.03288107}],"asks":[],"checksum":2159195668,"timestamp":"2024-06-01T17:51:43.914242Z"}]}
{"channel":"book","type":"update","data":[{"symbol":"BCH/AUD","bids":[{"price":692.33,"qty":6.15145543}],"asks":[],"checksum":758966776,"timestamp":"2024-06-01T17:51:43.914258Z"}]}
{"channel":"book","type":"update","data":[{"symbol":"BCH/AUD","bids":[{"price":692.34,"qty":6.00000000}],"asks":[],"checksum":3114448191,"timestamp":"2024-06-01T17:51:44.143069Z"}]}
{"channel":"book","type":"update","data":[{"symbol":"BCH/AUD","bids":[{"price":692.08,"qty":0.00000000},{"price":690.91,"qty":10.93257000}],"asks":[],"checksum":1238809503,"timestamp":"2024-06-01T17:51:44.148165Z"}]}
{"channel":"book","type":"update","data":[{"symbol":"BCH/AUD","bids":[{"price":692.33,"qty":0.00000000},{"price":690.28,"qty":0.03288107}],"asks":[],"checksum":3593733067,"timestamp":"2024-06-01T17:51:44.255062Z"}]}
{"channel":"book","type":"update","data":[{"symbol":"BCH/AUD","bids":[{"price":692.35,"qty":6.15127767}],"asks":[],"checksum":131415241,"timestamp":"2024-06-01T17:51:44.255366Z"}]}
{"channel":"book","type":"update","data":[{"symbol":"BCH/AUD","bids":[{"price":692.36,"qty":6.00000000}],"asks":[],"checksum":645923664,"timestamp":"2024-06-01T17:51:44.644014Z"}]}
{"channel":"book","type":"update","data":[{"symbol":"BCH/AUD","bids":[{"price":692.34,"qty":0.00000000},{"price":690.91,"qty":10.93257000}],"asks":[],"checksum":1913209444,"timestamp":"2024-06-01T17:51:44.649647Z"}]}
{"channel":"book","type":"update","data":[{"symbol":"BCH/AUD","bids":[{"price":692.35,"qty":0.00000000},{"price":690.28,"qty":0.03288107}],"asks":[],"checksum":3986745847,"timestamp":"2024-06-01T17:51:44.666466Z"}]}
{"channel":"book","type":"update","data":[{"symbol":"BCH/AUD","bids":[{"price":692.37,"qty":6.15109998}],"asks":[],"checksum":4218971838,"timestamp":"2024-06-01T17:51:44.666532Z"}]}
{"channel":"book","type":"update","data":[{"symbol":"BCH/AUD","bids":[{"price":692.38,"qty":6.00000000}],"asks":[],"checksum":2752790918,"timestamp":"2024-06-01T17:51:45.144701Z"}]}
{"channel":"book","type":"update","data":[{"symbol":"BCH/AUD","bids":[{"price":692.36,"qty":0.00000000},{"price":690.91,"qty":10.93257000}],"asks":[],"checksum":2433332659,"timestamp":"2024-06-01T17:51:45.150348Z"}]}
{"channel":"book","type":"update","data":[{"symbol":"BCH/AUD","bids":[{"price":692.39,"qty":6.15092231}],"asks":[],"checksum":636986708,"timestamp":"2024-06-01T17:51:45.260858Z"}]}
{"channel":"book","type":"update","data":[{"symbol":"BCH/AUD","bids":[{"price":692.37,"qty":0.00000000},{"price":690.91,"qty":10.93257000}],"asks":[],"checksum":3356980056,"timestamp":"2024-06-01T17:51:45.260926Z"}]}
{"channel":"book","type":"update","data":[{"symbol":"BCH/AUD","bids":[{"price":692.40,"qty":6.00000000}],"asks":[],"checksum":2134881326,"timestamp":"2024-06-01T17:51:45.271377Z"}]}
{"channel":"book","type":"update","data":[{"symbol":"BCH/AUD","bids":[{"price":692.38,"qty":0.00000000},{"price":690.91,"qty":10.93257000}],"asks":[],"checksum":1537463378,"timestamp":"2024-06-01T17:51:45.643321Z"}]}
{"channel":"book","type":"update","data":[{"symbol":"BCH/AUD","bids":[{"price":692.33,"qty":6.15145537}],"asks":[],"checksum":3628735858,"timestamp":"2024-06-01T17:51:45.669875Z"}]}
{"channel":"book","type":"update","data":[{"symbol":"BCH/AUD","bids":[{"price":692.39,"qty":0.00000000},{"price":690.91,"qty":10.93257000}],"asks":[],"checksum":3790346174,"timestamp":"2024-06-01T17:51:45.669942Z"}]}
{"channel":"book","type":"update","data":[{"symbol":"BCH/AUD","bids":[{"price":692.40,"qty":0.00000000},{"price":690.28,"qty":0.03288107}],"asks":[],"checksum":4029359496,"timestamp":"2024-06-01T17:51:46.643378Z"}]}
{"channel":"book","type":"update","data":[{"symbol":"BCH/AUD","bids":[{"price":692.34,"qty":6.00000000}],"asks":[],"checksum":997416130,"timestamp":"2024-06-01T17:51:46.643454Z"}]}
{"channel":"book","type":"update","data":[{"symbol":"BCH/AUD","bids":[{"price":692.33,"qty":0.00000000},{"price":690.28,"qty":0.03288107}],"asks":[],"checksum":3593733067,"timestamp":"2024-06-01T17:51:46.659682Z"}]}
{"channel":"book","type":"update","data":[{"symbol":"BCH/AUD","bids":[{"price":692.35,"qty":6.15127767}],"asks":[],"checksum":131415241,"timestamp":"2024-06-01T17:51:46.659871Z"}]}
{"channel":"book","type":"update","data":[{"symbol":"BCH/AUD","bids":[{"price":692.36,"qty":6.00000000}],"asks":[],"checksum":645923664,"timestamp":"2024-06-01T17:51:47.142529Z"}]}
{"channel":"book","type":"update","data":[{"symbol":"BCH/AUD","bids":[{"price":692.34,"qty":0.00000000},{"price":690.91,"qty":10.93257000}],"asks":[],"checksum":1913209444,"timestamp":"2024-06-01T17:51:47.147860Z"}]}
{"channel":"book","type":"update","data":[{"symbol":"BCH/AUD","bids":[{"price":692.35,"qty":0.00000000},{"price":690.28,"qty":0.03288107}],"asks":[],"checksum":3986745847,"timestamp":"2024-06-01T17:51:47.160102Z"}]}
{"channel":"book","type":"update","data":[{"symbol":"BCH/AUD","bids":[{"price":692.37,"qty":6.15109998}],"asks":[],"checksum":4218971838,"timestamp":"2024-06-01T17:51:47.160288Z"}]}
{"channel":"book","type":"update","data":[{"symbol":"BCH/AUD","bids":[{"price":692.38,"qty":6.00000000}],"asks":[],"checksum":2752790918,"timestamp":"2024-06-01T17:51:47.643649Z"}]}
{"channel":"book","type":"update","data":[{"symbol":"BCH/AUD","bids":[{"price":692.36,"qty":0.00000000},{"price":690.91,"qty":10.93257000}],"asks":[],"checksum":2433332659,"timestamp":"2024-06-01T17:51:47.648725Z"}]}
{"channel":"book","type":"update","data":[{"symbol":"BCH/AUD","bids":[{"price":692.39,"qty":6.15092231}],"asks":[],"checksum":636986708,"timestamp":"2024-06-01T17:51:47.659357Z"}]}
{"channel":"book","type":"update","data":[{"symbol":"BCH/AUD","bids":[{"price":692.37,"qty":0.00000000},{"price":690.91,"qty":10.93257000}],"asks":[],"checksum":3356980056,"timestamp":"2024-06-01T17:51:47.659522Z"}]}
{"channel":"book","type":"update","data":[{"symbol":"BCH/AUD","bids":[{"price":692.40,"qty":6.00000000}],"asks":[],"checksum":2134881326,"timestamp":"2024-06-01T17:51:48.143698Z"}]}
{"channel":"book","type":"update","data":[{"symbol":"BCH/AUD","bids":[{"price":692.38,"qty":0.00000000},{"price":690.91,"qty":10.93257000}],"asks":[],"checksum":1537463378,"timestamp":"2024-06-01T17:51:48.148798Z"}]}
{"channel":"book","type":"update","data":[{"symbol":"BCH/AUD","bids":[{"price":692.39,"qty":0.00000000},{"price":690.28,"qty":0.03288107}],"asks":[],"checksum":720508946,"timestamp":"2024-06-01T17:51:48.171855Z"}]}
{"channel":"book","type":"update","data":[{"symbol":"BCH/AUD","bids":[{"price":692.33,"qty":6.15145537}],"asks":[],"checksum":3790346174,"timestamp":"2024-06-01T17:51:48.171931Z"}]}
{"channel":"book","type":"update","data":[{"symbol":"BCH/AUD","bids":[{"price":692.34,"qty":6.00000000}],"asks":[],"checksum":3231072602,"timestamp":"2024-06-01T17:51:49.642788Z"}]}
{"channel":"book","type":"update","data":[{"symbol":"BCH/AUD","bids":[{"price":692.40,"qty":0.00000000},{"price":690.91,"qty":10.93257000}],"asks":[],"checksum":997416130,"timestamp":"2024-06-01T17:51:49.642809Z"}]}
{"channel":"book","type":"update","data":[{"symbol":"BCH/AUD","bids":[{"price":692.33,"qty":0.00000000},{"price":690.28,"qty":0.03288107}],"asks":[],"checksum":3593733067,"timestamp":"2024-06-01T17:51:49.685860Z"}]}
{"channel":"book","type":"update","data":[{"symbol":"BCH/AUD","bids":[{"price":692.35,"qty":6.15127767}],"asks":[],"checksum":131415241,"timestamp":"2024-06-01T17:51:49.685908Z"}]}
{"channel":"book","type":"update","data":[{"symbol":"BCH/AUD","bids":[{"price":692.36,"qty":6.00000000}],"asks":[],"checksum":645923664,"timestamp":"2024-06-01T17:51:49.693872Z"}]}
{"channel":"book","type":"update","data":[{"symbol":"BCH/AUD","bids":[{"price":692.32,"qty":0.00000000},{"price":690.91,"qty":10.93257000},{"price":692.37,"qty":0.23156502}],"asks":[],"checksum":2039725222,"timestamp":"2024-06-01T17:51:49.809033Z"}]}
{"channel":"book","type":"update","data":[{"symbol":"BCH/AUD","bids":[{"price":692.34,"qty":0.00000000},{"price":690.91,"qty":10.93257000}],"asks":[],"checksum":3066692857,"timestamp":"2024-06-01T17:51:49.816245Z"}]}
{"channel":"book","type":"update","data":[{"symbol":"BCH/AUD","bids":[{"price":692.35,"qty":0.00000000},{"price":690.28,"qty":0.03288107}],"asks":[],"checksum":4110672704,"timestamp":"2024-06-01T17:51:50.054158Z"}]}
{"channel":"book","type":"update","data":[{"symbol":"BCH/AUD","bids":[{"price":692.38,"qty":6.15101128}],"asks":[],"checksum":2480305200,"timestamp":"2024-06-01T17:51:50.054372Z"}]}
{"channel":"book","type":"update","data":[{"symbol":"BCH/AUD","bids":[{"price":692.39,"qty":6.00000000}],"asks":[],"checksum":1518787082,"timestamp":"2024-06-01T17:51:50.061172Z"}]}
{"channel":"book","type":"update","data":[{"symbol":"BCH/AUD","bids":[{"price":692.40,"qty":6.15083361}],"asks":[],"checksum":1243026638,"timestamp":"2024-06-01T17:51:50.066061Z"}]}
{"channel":"book","type":"update","data":[{"symbol":"BCH/AUD","bids":[{"price":692.38,"qty":0.00000000},{"price":690.96,"qty":2.74650750}],"asks":[],"checksum":633874087,"timestamp":"2024-06-01T17:51:50.066130Z"}]}
{"channel":"book","type":"update","data":[{"symbol":"BCH/AUD","bids":[{"price":692.39,"qty":0.00000000},{"price":690.91,"qty":10.93257000}],"asks":[],"checksum":2816653787,"timestamp":"2024-06-01T17:51:50.143429Z"}]}
{"channel":"book","type":"update","data":[{"symbol":"BCH/AUD","bids":[{"price":692.41,"qty":6.00000000}],"asks":[],"checksum":4269538358,"timestamp":"2024-06-01T17:51:50.143526Z"}]}
{"channel":"book","type":"update","data":[{"symbol":"BCH/AUD","bids":[{"price":692.36,"qty":0.00000000},{"price":690.91,"qty":10.93257000}],"asks":[],"checksum":2385949257,"timestamp":"2024-06-01T17:51:50.148044Z"}]}
{"channel":"book","type":"update","data":[{"symbol":"BCH/AUD","bids":[{"price":692.40,"qty":0.00000000},{"price":690.28,"qty":0.03288107}],"asks":[],"checksum":1429925860,"timestamp":"2024-06-01T17:51:51.442853Z"}]}
{"channel":"book","type":"update","data":[{"symbol":"BCH/AUD","bids":[{"price":692.42,"qty":6.15065583}],"asks":[],"checksum":1051481996,"timestamp":"2024-06-01T17:51:51.443061Z"}]}
{"channel":"book","type":"update","data":[{"symbol":"BCH/AUD","bids":[{"price":691.73,"qty":6.00000000}],"asks":[],"checksum":2562715821,"timestamp":"2024-06-01T17:51:51.449500Z"}]}
{"channel":"book","type":"update","data":[{"symbol":"BCH/AUD","bids":[{"price":692.41,"qty":0.00000000},{"price":690.91,"qty":10.93257000}],"asks":[],"checksum":248117141,"timestamp":"2024-06-01T17:51:51.449526Z"}]}
{"channel":"book","type":"update","data":[{"symbol":"BCH/AUD","bids":[{"price":692.42,"qty":0.00000000},{"price":690.28,"qty":0.03288107}],"asks":[],"checksum":738823463,"timestamp":"2024-06-01T17:51:51.455389Z"}]}
{"channel":"book","type":"update","data":[{"symbol":"BCH/AUD","bids":[{"price":692.38,"qty":6.15101124}],"asks":[],"checksum":584439353,"timestamp":"2024-06-01T17:51:51.455731Z"}]}
{"channel":"book","type":"update","data":[{"symbol":"BCH/AUD","bids":[{"price":692.39,"qty":6.00000000}],"asks":[],"checksum":797436262,"timestamp":"2024-06-01T17:51:51.643397Z"}]}
{"channel":"book","type":"update","data":[{"symbol":"BCH/AUD","bids":[{"price":691.73,"qty":0.00000000},{"price":690.91,"qty":10.93257000}],"asks":[],"checksum":850228397,"timestamp":"2024-06-01T17:51:51.648264Z"}]}
{"channel":"book","type":"update","data":[{"symbol":"BCH/AUD","bids":[{"price":692.40,"qty":6.15083355}],"asks":[],"checksum":172991684,"timestamp":"2024-06-01T17:51:52.446429Z"}]}
{"channel":"book","type":"update","data":[{"symbol":"BCH/AUD","bids":[{"price":692.38,"qty":0.00000000},{"price":690.91,"qty":10.93257000}],"asks":[],"checksum":1235525018,"timestamp":"2024-06-01T17:51:52.446495Z"}]}
{"channel":"book","type":"update","data":[{"symbol":"BCH/AUD","bids":[{"price":692.41,"qty":6.00000000}],"asks":[],"checksum":2468889497,"timestamp":"2024-06-01T17:51:52.451837Z"}]}
{"channel":"book","type":"update","data":[{"symbol":"BCH/AUD","bids":[{"price":692.42,"qty":6.15065594}],"asks":[],"checksum":4163271463,"timestamp":"2024-06-01T17:51:52.458706Z"}]}
{"channel":"book","type":"update","data":[{"symbol":"BCH/AUD","bids":[{"price":692.40,"qty":0.00000000},{"price":690.96,"qty":2.74650750}],"asks":[],"checksum":3690956439,"timestamp":"2024-06-01T17:51:52.458776Z"}]}
{"channel":"book","type":"update","data":[{"symbol":"BCH/AUD","bids":[{"price":692.43,"qty":6.00000000}],"asks":[],"checksum":1500915160,"timestamp":"2024-06-01T17:51:52.643308Z"}]}
{"channel":"book","type":"update","data":[{"symbol":"BCH/AUD","bids":[{"price":692.41,"qty":0.00000000},{"price":690.96,"qty":2.74650750}],"asks":[],"checksum":3097686861,"timestamp":"2024-06-01T17:51:52.643326Z"}]}
{"channel":"book","type":"update","data":[{"symbol":"BCH/AUD","bids":[{"price":692.39,"qty":0.00000000},{"price":690.91,"qty":10.93257000}],"asks":[],"checksum":3385497502,"timestamp":"2024-06-01T17:51:52.648033Z"}]}
{"channel":"book","type":"update","data":[{"symbol":"BCH/AUD","bids":[{"price":692.42,"qty":0.00000000},{"price":690.28,"qty":0.03288107}],"asks":[],"checksum":1856898520,"timestamp":"2024-06-01T17:51:53.855619Z"}]}
{"channel":"book","type":"update","data":[{"symbol":"BCH/AUD","bids":[{"price":692.44,"qty":6.15047824}],"asks":[],"checksum":3284473444,"timestamp":"2024-06-01T17:51:53.855831Z"}]}
{"channel":"book","type":"update","data":[{"symbol":"BCH/AUD","bids":[{"price":692.45,"qty":6.00000000}],"asks":[],"checksum":241592898,"timestamp":"2024-06-01T17:51:53.861679Z"}]}
{"channel":"book","type":"update","data":[{"symbol":"BCH/AUD","bids":[{"price":692.43,"qty":0.00000000},{"price":690.91,"qty":10.93257000}],"asks":[],"checksum":3066906650,"timestamp":"2024-06-01T17:51:54.143102Z"}]}
{"channel":"book","type":"update","data":[{"symbol":"BCH/AUD","bids":[{"price":692.38,"qty":6.15101114}],"asks":[],"checksum":3552504804,"timestamp":"2024-06-01T17:51:54.611224Z"}]}
{"channel":"book","type":"update","data":[{"symbol":"BCH/AUD","bids":[{"price":692.44,"qty":0.00000000},{"price":690.91,"qty":10.93257000}],"asks":[],"checksum":621437619,"timestamp":"2024-06-01T17:51:54.611244Z"}]}
{"channel":"book","type":"update","data":[{"symbol":"BCH/AUD","bids":[{"price":692.45,"qty":0.00000000},{"price":690.28,"qty":0.03288107}],"asks":[],"checksum":164338169,"timestamp":"2024-06-01T17:51:55.142440Z"}]}
{"channel":"book","type":"update","data":[{"symbol":"BCH/AUD","bids":[{"price":692.39,"qty":6.00000000}],"asks":[],"checksum":858000891,"timestamp":"2024-06-01T17:51:55.142664Z"}]}
{"channel":"book","type":"update","data":[{"symbol":"BCH/AUD","bids":[{"price":692.40,"qty":6.15083347}],"asks":[],"checksum":1057803845,"timestamp":"2024-06-01T17:51:55.167004Z"}]}
{"channel":"book","type":"update","data":[{"symbol":"BCH/AUD","bids":[{"price":692.38,"qty":0.00000000},{"price":690.91,"qty":10.93257000}],"asks":[],"checksum":401631553,"timestamp":"2024-06-01T17:51:55.167050Z"}]}
{"channel":"book","type":"update","data":[{"symbol":"BCH/AUD","bids":[{"price":692.41,"qty":6.00000000}],"asks":[],"checksum":1423758523,"timestamp":"2024-06-01T17:51:55.644449Z"}]}
{"channel":"book","type":"update","data":[{"symbol":"BCH/AUD","bids":[{"price":692.39,"qty":0.00000000},{"price":690.91,"qty":10.93257000}],"asks":[],"checksum":2650324624,"timestamp":"2024-06-01T17:51:55.649073Z"}]}
{"channel":"book","type":"update","data":[{"symbol":"BCH/AUD","bids":[{"price":692.40,"qty":0.00000000},{"price":690.28,"qty":0.03288107}],"asks":[],"checksum":1429925860,"timestamp":"2024-06-01T17:51:56.246759Z"}]}
{"channel":"book","type":"update","data":[{"symbol":"BCH/AUD","bids":[{"price":692.42,"qty":6.15065581}],"asks":[],"checksum":2618324282,"timestamp":"2024-06-01T17:51:56.246791Z"}]}
{"channel":"book","type":"update","data":[{"symbol":"BCH/AUD","bids":[{"price":692.43,"qty":6.00000000}],"asks":[],"checksum":317881018,"timestamp":"2024-06-01T17:51:56.252919Z"}]}
{"channel":"book","type":"update","data":[{"symbol":"BCH/AUD","bids":[{"price":692.42,"qty":0.00000000},{"price":690.91,"qty":10.93257000}],"asks":[],"checksum":3118376767,"timestamp":"2024-06-01T17:51:56.264209Z"}]}
{"channel":"book","type":"update","data":[{"symbol":"BCH/AUD","bids":[{"price":692.44,"qty":6.15047816}],"asks":[],"checksum":2772629520,"timestamp":"2024-06-01T17:51:56.264280Z"}]}
{"channel":"book","type":"update","data":[{"symbol":"BCH/AUD","bids":[{"price":692.43,"qty":0.00000000},{"price":690.91,"qty":10.93257000}],"asks":[],"checksum":3181754357,"timestamp":"2024-06-01T17:51:56.642352Z"}]}
{"channel":"book","type":"update","data":[{"symbol":"BCH/AUD","bids":[{"price":692.45,"qty":6.00000000}],"asks":[],"checksum":1258953280,"timestamp":"2024-06-01T17:51:56.642585Z"}]}
{"channel":"book","type":"update","data":[{"symbol":"BCH/AUD","bids":[{"price":692.41,"qty":0.00000000},{"price":690.91,"qty":10.93257000}],"asks":[],"checksum":3568587058,"timestamp":"2024-06-01T17:51:56.647079Z"}]}
{"channel":"book","type":"update","data":[{"symbol":"BCH/AUD","bids":[{"price":692.44,"qty":0.00000000},{"price":690.28,"qty":0.03288107}],"asks":[],"checksum":571685788,"timestamp":"2024-06-01T17:51:57.240780Z"}]}
{"channel":"book","type":"update","data":[{"symbol":"BCH/AUD","bids":[{"price":692.38,"qty":6.15101114}],"asks":[],"checksum":621437619,"timestamp":"2024-06-01T17:51:57.241160Z"}]}
{"channel":"book","type":"update","data":[{"symbol":"BCH/AUD","bids":[{"price":692.45,"qty":0.00000000},{"price":690.28,"qty":0.03288107}],"asks":[],"checksum":164338169,"timestamp":"2024-06-01T17:51:58.142762Z"}]}
{"channel":"book","type":"update","data":[{"symbol":"BCH/AUD","bids":[{"price":692.39,"qty":6.00000000}],"asks":[],"checksum":858000891,"timestamp":"2024-06-01T17:51:58.142981Z"}]}
{"channel":"book","type":"update","data":[{"symbol":"BCH/AUD","bids":[{"price":692.37,"qty":0.00000000},{"price":690.28,"qty":0.03288107},{"price":692.38,"qty":6.38257281}],"asks":[],"checksum":2668554634,"timestamp":"2024-06-01T17:51:58.149981Z"}]}
{"channel":"book","type":"update","data":[{"symbol":"BCH/AUD","bids":[{"price":692.38,"qty":0.23156167}],"asks":[],"checksum":2911040844,"timestamp":"2024-06-01T17:51:58.163251Z"}]}
{"channel":"book","type":"update","data":[{"symbol":"BCH/AUD","bids":[{"price":692.40,"qty":6.15083347}],"asks":[],"checksum":1695110093,"timestamp":"2024-06-01T17:51:58.163313Z"}]}
{"channel":"book","type":"update","data":[{"symbol":"BCH/AUD","bids":[{"price":692.41,"qty":6.00000000}],"asks":[],"checksum":1936722299,"timestamp":"2024-06-01T17:51:58.643250Z"}]}
{"channel":"book","type":"update","data":[{"symbol":"BCH/AUD","bids":[{"price":692.40,"qty":0.00000000},{"price":690.91,"qty":10.93257000}],"asks":[],"checksum":2919239170,"timestamp":"2024-06-01T17:51:58.647362Z"}]}
{"channel":"book","type":"update","data":[{"symbol":"BCH/AUD","bids":[{"price":692.42,"qty":6.15065581}],"asks":[],"checksum":1087022394,"timestamp":"2024-06-01T17:51:58.647588Z"}]}
{"channel":"book","type":"update","data":[{"symbol":"BCH/AUD","bids":[{"price":692.39,"qty":0.00000000},{"price":690.91,"qty":10.93257000}],"asks":[],"checksum":4008267702,"timestamp":"2024-06-01T17:51:58.648693Z"}]}
{"channel":"book","type":"update","data":[{"symbol":"BCH/AUD","bids":[{"price":692.43,"qty":6.00000000}],"asks":[],"checksum":895395706,"timestamp":"2024-06-01T17:51:59.142792Z"}]}
{"channel":"book","type":"update","data":[{"symbol":"BCH/AUD","bids":[{"price":692.41,"qty":0.00000000},{"price":690.91,"qty":10.93257000}],"asks":[],"checksum":4219242716,"timestamp":"2024-06-01T17:51:59.147369Z"}]}
{"channel":"book","type":"update","data":[{"symbol":"BCH/AUD","bids":[{"price":692.42,"qty":0.00000000},{"price":690.28,"qty":0.03288107}],"asks":[],"checksum":4088035361,"timestamp":"2024-06-01T17:51:59.157745Z"}]}
{"channel":"book","type":"update","data":[{"symbol":"BCH/AUD","bids":[{"price":692.39,"qty":6.15092231}],"asks":[],"checksum":1258934151,"timestamp":"2024-06-01T17:51:59.158221Z"}]}
{"channel":"book","type":"update","data":[{"symbol":"BCH/AUD","bids":[{"price":692.44,"qty":6.15047816}],"asks":[],"checksum":2891133073,"timestamp":"2024-06-01T17:51:59.777946Z"}]}
{"channel":"book","type":"update","data":[{"symbol":"BCH/AUD","bids":[{"price":692.39,"qty":0.00000000},{"price":690.91,"qty":10.93257000}],"asks":[],"checksum":3452465832,"timestamp":"2024-06-01T17:51:59.777973Z"}]}
{"channel":"book","type":"update","data":[{"symbol":"BCH/AUD","bids":[{"price":692.45,"qty":6.00000000}],"asks":[],"checksum":2379104478,"timestamp":"2024-06-01T17:51:59.783607Z"}]}
{"channel":"book","type":"update","data":[{"symbol":"BCH/AUD","bids":[{"price":692.43,"qty":0.00000000},{"price":690.91,"qty":10.93257000}],"asks":[],"checksum":2790091710,"timestamp":"2024-06-01T17:52:00.143437Z"}]}
{"channel":"book","type":"update","data":[{"symbol":"BCH/AUD","bids":[{"price":692.44,"qty":0.00000000},{"price":690.28,"qty":0.03288107}],"asks":[],"checksum":3205973605,"timestamp":"2024-06-01T17:52:01.042983Z"}]}
{"channel":"book","type":"update","data":[{"symbol":"BCH/AUD","bids":[{"price":692.46,"qty":6.15030052}],"asks":[],"checksum":1138943915,"timestamp":"2024-06-01T17:52:01.043101Z"}]}
{"channel":"book","type":"update","data":[{"symbol":"BCH/AUD","bids":[{"price":692.47,"qty":6.00000000}],"asks":[],"checksum":1378718756,"timestamp":"2024-06-01T17:52:01.048892Z"}]}
{"channel":"book","type":"update","data":[{"symbol":"BCH/AUD","bids":[{"price":692.48,"qty":6.15012289}],"asks":[],"checksum":2957209936,"timestamp":"2024-06-01T17:52:01.056990Z"}]}
{"channel":"book","type":"update","data":[{"symbol":"BCH/AUD","bids":[{"price":692.46,"qty":0.00000000},{"price":690.96,"qty":2.74650750}],"asks":[],"checksum":1942259067,"timestamp":"2024-06-01T17:52:01.057086Z"}]}
{"channel":"book","type":"update","data":[{"symbol":"BCH/AUD","bids":[{"price":692.47,"qty":0.00000000},{"price":690.91,"qty":10.93257000}],"asks":[],"checksum":1304228624,"timestamp":"2024-06-01T17:52:01.142679Z"}]}
{"channel":"book","type":"update","data":[{"symbol":"BCH/AUD","bids":[{"price":692.49,"qty":6.00000000}],"asks":[],"checksum":2082714267,"timestamp":"2024-06-01T17:52:01.142827Z"}]}
{"channel":"book","type":"update","data":[{"symbol":"BCH/AUD","bids":[{"price":692.45,"qty":0.00000000},{"price":690.91,"qty":10.93257000}],"asks":[],"checksum":4012706190,"timestamp":"2024-06-01T17:52:01.149253Z"}]}
{"channel":"book","type":"update","data":[{"symbol":"BCH/AUD","bids":[{"price":692.48,"qty":0.00000000},{"price":690.28,"qty":0.03288107}],"asks":[],"checksum":644692717,"timestamp":"2024-06-01T17:52:02.038638Z"}]}
{"channel":"book","type":"update","data":[{"symbol":"BCH/AUD","bids":[{"price":692.39,"qty":6.15092231}],"asks":[],"checksum":3029639870,"timestamp":"2024-06-01T17:52:02.052472Z"}]}
{"channel":"book","type":"update","data":[{"symbol":"BCH/AUD","bids":[{"price":692.39,"qty":0.00000000},{"price":690.28,"qty":0.03288107}],"asks":[],"checksum":644692717,"timestamp":"2024-06-01T17:52:02.457802Z"}]}
{"channel":"book","type":"update","data":[{"symbol":"BCH/AUD","bids":[{"price":692.50,"qty":6.14994535}],"asks":[],"checksum":2568434817,"timestamp":"2024-06-01T17:52:02.458056Z"}]}
{"channel":"book","type":"update","data":[{"symbol":"BCH/AUD","bids":[{"price":692.51,"qty":6.00000000}],"asks":[],"checksum":1134312546,"timestamp":"2024-06-01T17:52:02.464920Z"}]}
{"channel":"book","type":"update","data":[{"symbol":"BCH/AUD","bids":[{"price":692.49,"qty":0.00000000},{"price":690.91,"qty":10.93257000}],"asks":[],"checksum":3040708866,"timestamp":"2024-06-01T17:52:02.644373Z"}]}
{"channel":"book","type":"update","data":[{"symbol":"BCH/AUD","bids":[{"price":692.50,"qty":0.00000000},{"price":690.28,"qty":0.03288107}],"asks":[],"checksum":841770251,"timestamp":"2024-06-01T17:52:03.450094Z"}]}
{"channel":"book","type":"update","data":[{"symbol":"BCH/AUD","bids":[{"price":692.52,"qty":6.14976766}],"asks":[],"checksum":1059274376,"timestamp":"2024-06-01T17:52:03.450223Z"}]}
{"channel":"book","type":"update","data":[{"symbol":"BCH/AUD","bids":[{"price":692.53,"qty":6.00000000}],"asks":[],"checksum":430600955,"timestamp":"2024-06-01T17:52:03.458563Z"}]}
{"channel":"book","type":"update","data":[{"symbol":"BCH/AUD","bids":[{"price":692.52,"qty":0.00000000},{"price":690.91,"qty":10.93257000}],"asks":[],"checksum":1630866871,"timestamp":"2024-06-01T17:52:03.462899Z"}]}
{"channel":"book","type":"update","data":[{"symbol":"BCH/AUD","bids":[{"price":692.54,"qty":6.14959018}],"asks":[],"checksum":623374880,"timestamp":"2024-06-01T17:52:03.463039Z"}]}
{"channel":"book","type":"update","data":[{"symbol":"BCH/AUD","bids":[{"price":690.96,"qty":0.00000000},{"price":690.91,"qty":10.93257000}],"asks":[],"checksum":1945000967,"timestamp":"2024-06-01T17:52:03.466503Z"}]}
{"channel":"book","type":"update","data":[{"symbol":"BCH/AUD","bids":[{"price":691.62,"qty":2.74650750}],"asks":[],"checksum":3899290467,"timestamp":"2024-06-01T17:52:03.469540Z"}]}
{"channel":"book","type":"update","data":[{"symbol":"BCH/AUD","bids":[{"price":692.53,"qty":0.00000000},{"price":690.91,"qty":10.93257000}],"asks":[],"checksum":1163674033,"timestamp":"2024-06-01T17:52:03.643950Z"}]}
{"channel":"book","type":"update","data":[{"symbol":"BCH/AUD","bids":[{"price":692.55,"qty":6.00000000}],"asks":[],"checksum":2606183582,"timestamp":"2024-06-01T17:52:03.644082Z"}]}
{"channel":"book","type":"update","data":[{"symbol":"BCH/AUD","bids":[{"price":692.51,"qty":0.00000000},{"price":690.91,"qty":10.93257000}],"asks":[],"checksum":2226589062,"timestamp":"2024-06-01T17:52:03.648958Z"}]}
{"channel":"book","type":"update","data":[{"symbol":"BCH/AUD","bids":[{"price":692.38,"qty":0.00000000},{"price":690.28,"qty":0.03288107},{"price":692.55,"qty":6.23150483}],"asks":[],"checksum":2708729771,"timestamp":"2024-06-01T17:52:03.655323Z"}]}
{"channel":"book","type":"update","data":[{"symbol":"BCH/AUD","bids":[{"price":692.54,"qty":0.00000000},{"price":690.01,"qty":0.26329050}],"asks":[],"checksum":3029634719,"timestamp":"2024-06-01T17:52:04.442532Z"}]}
{"channel":"book","type":"update","data":[{"symbol":"BCH/AUD","bids":[{"price":692.56,"qty":6.14941246}],"asks":[],"checksum":3207306682,"timestamp":"2024-06-01T17:52:04.442582Z"}]}
{"channel":"book","type":"update","data":[{"symbol":"BCH/AUD","bids":[{"price":692.57,"qty":6.00000000}],"asks":[],"checksum":19292582,"timestamp":"2024-06-01T17:52:04.448096Z"}]}
{"channel":"book","type":"update","data":[{"symbol":"BCH/AUD","bids":[{"price":692.55,"qty":0.23150483}],"asks":[],"checksum":2823481464,"timestamp":"2024-06-01T17:52:04.642700Z"}]}
{"channel":"book","type":"update","data":[{"symbol":"BCH/AUD","bids":[{"price":692.56,"qty":0.00000000},{"price":690.28,"qty":0.03288107}],"asks":[],"checksum":1910205921,"timestamp":"2024-06-01T17:52:05.853964Z"}]}
{"channel":"book","type":"update","data":[{"symbol":"BCH/AUD","bids":[{"price":692.58,"qty":6.14923488}],"asks":[],"checksum":3247539965,"timestamp":"2024-06-01T17:52:05.854244Z"}]}
{"channel":"book","type":"update","data":[{"symbol":"BCH/AUD","bids":[{"price":692.57,"qty":0.00000000},{"price":690.28,"qty":0.03288107}],"asks":[],"checksum":3766748433,"timestamp":"2024-06-01T17:52:05.859710Z"}]}
{"channel":"book","type":"update","data":[{"symbol":"BCH/AUD","bids":[{"price":691.73,"qty":6.00000000}],"asks":[],"checksum":192039900,"timestamp":"2024-06-01T17:52:05.859787Z"}]}
{"channel":"book","type":"update","data":[{"symbol":"BCH/AUD","bids":[{"price":692.56,"qty":6.14941246}],"asks":[],"checksum":2199674625,"timestamp":"2024-06-01T17:52:05.866302Z"}]}
{"channel":"book","type":"update","data":[{"symbol":"BCH/AUD","bids":[{"price":692.58,"qty":0.00000000},{"price":690.91,"qty":10.93257000}],"asks":[],"checksum":530403008,"timestamp":"2024-06-01T17:52:05.866316Z"}]}
{"channel":"book","type":"update","data":[{"symbol":"BCH/AUD","bids":[{"price":692.57,"qty":6.00000000}],"asks":[],"checksum":1043395189,"timestamp":"2024-06-01T17:52:06.141505Z"}]}
{"channel":"book","type":"update","data":[{"symbol":"BCH/AUD","bids":[{"price":691.73,"qty":0.00000000},{"price":690.91,"qty":10.93257000}],"asks":[],"checksum":2823481464,"timestamp":"2024-06-01T17:52:06.148469Z"}]}
{"channel":"book","type":"update","data":[{"symbol":"BCH/AUD","bids":[{"price":691.62,"qty":0.00000000},{"price":690.28,"qty":0.03288107}],"asks":[],"checksum":1441202159,"timestamp":"2024-06-01T17:52:06.852965Z"}]}
{"channel":"book","type":"update","data":[{"symbol":"BCH/AUD","bids":[{"price":691.64,"qty":2.74650750}],"asks":[],"checksum":2240531229,"timestamp":"2024-06-01T17:52:06.855824Z"}]}
{"channel":"book","type":"update","data":[{"symbol":"BCH/AUD","bids":[{"price":692.56,"qty":0.00000000},{"price":690.28,"qty":0.03288107}],"asks":[],"checksum":983015236,"timestamp":"2024-06-01T17:52:06.860321Z"}]}
{"channel":"book","type":"update","data":[{"symbol":"BCH/AUD","bids":[{"price":692.58,"qty":6.14923488}],"asks":[],"checksum":3964708248,"timestamp":"2024-06-01T17:52:06.860351Z"}]}
{"channel":"book","type":"update","data":[{"symbol":"BCH/AUD","bids":[{"price":692.59,"qty":6.00000000}],"asks":[],"checksum":960241127,"timestamp":"2024-06-01T17:52:06.867001Z"}]}
{"channel":"book","type":"update","data":[{"symbol":"BCH/AUD","bids":[{"price":692.57,"qty":0.00000000},{"price":690.91,"qty":10.93257000}],"asks":[],"checksum":3141041833,"timestamp":"2024-06-01T17:52:07.142131Z"}]}
{"channel":"book","type":"update","data":[{"symbol":"BCH/AUD","bids":[{"price":692.56,"qty":6.14941246}],"asks":[],"checksum":3817901110,"timestamp":"2024-06-01T17:52:07.145232Z"}]}
{"channel":"book","type":"update","data":[{"symbol":"BCH/AUD","bids":[{"price":692.58,"qty":0.00000000},{"price":690.91,"qty":10.93257000}],"asks":[],"checksum":474887230,"timestamp":"2024-06-01T17:52:07.145280Z"}]}
{"channel":"book","type":"update","data":[{"symbol":"BCH/AUD","bids":[{"price":692.59,"qty":0.00000000},{"price":690.28,"qty":0.03288107}],"asks":[],"checksum":4244293558,"timestamp":"2024-06-01T17:52:08.143998Z"}]}
{"channel":"book","type":"update","data":[{"symbol":"BCH/AUD","bids":[{"price":692.57,"qty":6.00000000}],"asks":[],"checksum":2240531229,"timestamp":"2024-06-01T17:52:08.144245Z"}]}
{"channel":"book","type":"update","data":[{"symbol":"BCH/AUD","bids":[{"price":692.56,"qty":0.00000000},{"price":690.28,"qty":0.03288107}],"asks":[],"checksum":983015236,"timestamp":"2024-06-01T17:52:08.259623Z"}]}
{"channel":"book","type":"update","data":[{"symbol":"BCH/AUD","bids":[{"price":692.58,"qty":6.14923488}],"asks":[],"checksum":3964708248,"timestamp":"2024-06-01T17:52:08.259745Z"}]}
{"channel":"book","type":"update","data":[{"symbol":"BCH/AUD","bids":[{"price":692.59,"qty":6.00000000}],"asks":[],"checksum":960241127,"timestamp":"2024-06-01T17:52:08.265534Z"}]}
{"channel":"book","type":"update","data":[{"symbol":"BCH/AUD","bids":[{"price":692.57,"qty":0.00000000},{"price":690.91,"qty":10.93257000}],"asks":[],"checksum":3141041833,"timestamp":"2024-06-01T17:52:08.642604Z"}]}
{"channel":"book","type":"update","data":[{"symbol":"BCH/AUD","bids":[{"price":692.58,"qty":0.00000000},{"price":690.28,"qty":0.03288107}],"asks":[],"checksum":2558069232,"timestamp":"2024-06-01T17:52:08.659044Z"}]}
{"channel":"book","type":"update","data":[{"symbol":"BCH/AUD","bids":[{"price":692.56,"qty":6.14941246}],"asks":[],"checksum":474887230,"timestamp":"2024-06-01T17:52:08.659403Z"}]}
{"channel":"book","type":"update","data":[{"symbol":"BCH/AUD","bids":[{"price":692.59,"qty":0.00000000},{"price":690.28,"qty":0.03288107}],"asks":[],"checksum":4244293558,"timestamp":"2024-06-01T17:52:09.644280Z"}]}
{"channel":"book","type":"update","data":[{"symbol":"BCH/AUD","bids":[{"price":692.57,"qty":6.00000000}],"asks":[],"checksum":2240531229,"timestamp":"2024-06-01T17:52:09.644424Z"}]}
{"channel":"book","type":"update","data":[{"symbol":"BCH/AUD","bids":[{"price":692.55,"qty":0.00000000},{"price":690.28,"qty":0.03288107},{"price":692.58,"qty":0.23149480}],"asks":[],"checksum":954924318,"timestamp":"2024-06-01T17:52:09.651380Z"}]}
{"channel":"book","type":"update","data":[{"symbol":"BCH/AUD","bids":[{"price":692.56,"qty":0.00000000},{"price":690.28,"qty":0.03288107}],"asks":[],"checksum":2061221464,"timestamp":"2024-06-01T17:52:09.666328Z"}]}
{"channel":"book","type":"update","data":[{"symbol":"BCH/AUD","bids":[{"price":692.58,"qty":6.38072968}],"asks":[],"checksum":1760388276,"timestamp":"2024-06-01T17:52:09.666403Z"}]}
{"channel":"book","type":"update","data":[{"symbol":"BCH/AUD","bids":[{"price":692.59,"qty":6.00000000}],"asks":[],"checksum":1357177217,"timestamp":"2024-06-01T17:52:10.143300Z"}]}
{"channel":"book","type":"update","data":[{"symbol":"BCH/AUD","bids":[{"price":692.57,"qty":0.00000000},{"price":690.28,"qty":0.03288107}],"asks":[],"checksum":3655599854,"timestamp":"2024-06-01T17:52:10.148587Z"}]}
{"channel":"book","type":"update","data":[{"symbol":"BCH/AUD","bids":[{"price":691.73,"qty":6.15679108}],"asks":[],"checksum":2520418603,"timestamp":"2024-06-01T17:52:10.176670Z"}]}
{"channel":"book","type":"update","data":[{"symbol":"BCH/AUD","bids":[{"price":692.58,"qty":0.23149480}],"asks":[],"checksum":2471414788,"timestamp":"2024-06-01T17:52:10.176824Z"}]}
{"channel":"book","type":"update","data":[{"symbol":"BCH/AUD","bids":[{"price":692.59,"qty":0.00000000},{"price":690.28,"qty":0.03288107}],"asks":[],"checksum":2282246244,"timestamp":"2024-06-01T17:52:11.642728Z"}]}
{"channel":"book","type":"update","data":[{"symbol":"BCH/AUD","bids":[{"price":691.74,"qty":6.00000000}],"asks":[],"checksum":2897264815,"timestamp":"2024-06-01T17:52:11.642896Z"}]}
{"channel":"book","type":"update","data":[{"symbol":"BCH/AUD","bids":[{"price":691.75,"qty":6.15661308}],"asks":[],"checksum":4256166047,"timestamp":"2024-06-01T17:52:11.647634Z"}]}
{"channel":"book","type":"update","data":[{"symbol":"BCH/AUD","bids":[{"price":691.73,"qty":0.00000000},{"price":690.91,"qty":10.93257000}],"asks":[],"checksum":1013544366,"timestamp":"2024-06-01T17:52:11.647682Z"}]}
{"channel":"book","type":"update","data":[{"symbol":"BCH/AUD","bids":[{"price":691.76,"qty":6.00000000}],"asks":[],"checksum":1259335869,"timestamp":"2024-06-01T17:52:12.143760Z"}]}
{"channel":"book","type":"update","data":[{"symbol":"BCH/AUD","bids":[{"price":691.74,"qty":0.00000000},{"price":690.91,"qty":10.93257000}],"asks":[],"checksum":3697749274,"timestamp":"2024-06-01T17:52:12.148704Z"}]}
{"channel":"book","type":"update","data":[{"symbol":"BCH/AUD","bids":[{"price":691.77,"qty":6.15643508}],"asks":[],"checksum":3233970085,"timestamp":"2024-06-01T17:52:12.152321Z"}]}
{"channel":"book","type":"update","data":[{"symbol":"BCH/AUD","bids":[{"price":691.75,"qty":0.00000000},{"price":690.91,"qty":10.93257000}],"asks":[],"checksum":1320863788,"timestamp":"2024-06-01T17:52:12.152433Z"}]}
{"channel":"book","type":"update","data":[{"symbol":"BCH/AUD","bids":[{"price":691.78,"qty":6.00000000}],"asks":[],"checksum":4281963047,"timestamp":"2024-06-01T17:52:12.644136Z"}]}
{"channel":"book","type":"update","data":[{"symbol":"BCH/AUD","bids":[{"price":691.76,"qty":0.00000000},{"price":690.91,"qty":10.93257000}],"asks":[],"checksum":75345046,"timestamp":"2024-06-01T17:52:12.648930Z"}]}
{"channel":"book","type":"update","data":[{"symbol":"BCH/AUD","bids":[{"price":691.77,"qty":0.00000000},{"price":690.28,"qty":0.03288107}],"asks":[],"checksum":240216065,"timestamp":"2024-06-01T17:52:12.655319Z"}]}
{"channel":"book","type":"update","data":[{"symbol":"BCH/AUD","bids":[{"price":691.79,"qty":6.15625710}],"asks":[],"checksum":2505321045,"timestamp":"2024-06-01T17:52:12.655477Z"}]}
{"channel":"book","type":"update","data":[{"symbol":"BCH/AUD","bids":[{"price":691.64,"qty":0.00000000},{"price":690.28,"qty":0.03288107}],"asks":[],"checksum":3466819112,"timestamp":"2024-06-01T17:52:12.736995Z"}]}
{"channel":"book","type":"update","data":[{"symbol":"BCH/AUD","bids":[{"price":691.65,"qty":2.74650750}],"asks":[],"checksum":4237874776,"timestamp":"2024-06-01T17:52:12.739738Z"}]}
{"channel":"book","type":"update","data":[{"symbol":"BCH/AUD","bids":[{"price":691.80,"qty":6.00000000}],"asks":[],"checksum":4167972814,"timestamp":"2024-06-01T17:52:13.143803Z"}]}
{"channel":"book","type":"update","data":[{"symbol":"BCH/AUD","bids":[{"price":691.78,"qty":0.00000000},{"price":690.91,"qty":10.93257000}],"asks":[],"checksum":758500047,"timestamp":"2024-06-01T17:52:13.148976Z"}]}
{"channel":"book","type":"update","data":[{"symbol":"BCH/AUD","bids":[{"price":691.79,"qty":0.00000000},{"price":690.28,"qty":0.03288107}],"asks":[],"checksum":858334693,"timestamp":"2024-06-01T17:52:13.175541Z"}]}
{"channel":"book","type":"update","data":[{"symbol":"BCH/AUD","bids":[{"price":691.81,"qty":6.15607912}],"asks":[],"checksum":3209562093,"timestamp":"2024-06-01T17:52:13.175623Z"}]}
{"channel":"book","type":"update","data":[{"symbol":"BCH/AUD","bids":[{"price":691.82,"qty":6.00000000}],"asks":[],"checksum":3619731795,"timestamp":"2024-06-01T17:52:13.642549Z"}]}
{"channel":"book","type":"update","data":[{"symbol":"BCH/AUD","bids":[{"price":691.80,"qty":0.00000000},{"price":690.91,"qty":10.93257000}],"asks":[],"checksum":1496887821,"timestamp":"2024-06-01T17:52:13.647457Z"}]}
{"channel":"book","type":"update","data":[{"symbol":"BCH/AUD","bids":[{"price":691.81,"qty":0.00000000},{"price":690.28,"qty":0.03288107}],"asks":[],"checksum":3393584678,"timestamp":"2024-06-01T17:52:13.654916Z"}]}
{"channel":"book","type":"update","data":[{"symbol":"BCH/AUD","bids":[{"price":691.83,"qty":6.15590116}],"asks":[],"checksum":1389253757,"timestamp":"2024-06-01T17:52:13.655480Z"}]}
{"channel":"book","type":"update","data":[{"symbol":"BCH/AUD","bids":[{"price":691.84,"qty":6.00000000}],"asks":[],"checksum":2477660049,"timestamp":"2024-06-01T17:52:14.143099Z"}]}
{"channel":"book","type":"update","data":[{"symbol":"BCH/AUD","bids":[{"price":691.82,"qty":0.00000000},{"price":690.91,"qty":10.93257000}],"asks":[],"checksum":3831673483,"timestamp":"2024-06-01T17:52:14.147888Z"}]}
{"channel":"book","type":"update","data":[{"symbol":"BCH/AUD","bids":[{"price":691.83,"qty":0.00000000},{"price":690.28,"qty":0.03288107}],"asks":[],"checksum":444699682,"timestamp":"2024-06-01T17:52:14.152257Z"}]}
{"channel":"book","type":"update","data":[{"symbol":"BCH/AUD","bids":[{"price":691.85,"qty":6.15572320}],"asks":[],"checksum":1094482979,"timestamp":"2024-06-01T17:52:14.152465Z"}]}
{"channel":"book","type":"update","data":[{"symbol":"BCH/AUD","bids":[{"price":691.86,"qty":6.00000000}],"asks":[],"checksum":446883512,"timestamp":"2024-06-01T17:52:14.643465Z"}]}
{"channel":"book","type":"update","data":[{"symbol":"BCH/AUD","bids":[{"price":691.85,"qty":0.00000000},{"price":690.91,"qty":10.93257000}],"asks":[],"checksum":2419548870,"timestamp":"2024-06-01T17:52:14.647579Z"}]}
{"channel":"book","type":"update","data":[{"symbol":"BCH/AUD","bids":[{"price":691.87,"qty":6.15554526}],"asks":[],"checksum":1608816288,"timestamp":"2024-06-01T17:52:14.647644Z"}]}
{"channel":"book","type":"update","data":[{"symbol":"BCH/AUD","bids":[{"price":691.84,"qty":0.00000000},{"price":690.91,"qty":10.93257000}],"asks":[],"checksum":916236461,"timestamp":"2024-06-01T17:52:14.648724Z"}]}
{"channel":"book","type":"update","data":[{"symbol":"BCH/AUD","bids":[{"price":691.88,"qty":6.00000000}],"asks":[],"checksum":1573271470,"timestamp":"2024-06-01T17:52:15.142506Z"}]}
{"channel":"book","type":"update","data":[{"symbol":"BCH/AUD","bids":[{"price":691.86,"qty":0.00000000},{"price":690.91,"qty":10.93257000}],"asks":[],"checksum":424831679,"timestamp":"2024-06-01T17:52:15.147545Z"}]}
{"channel":"book","type":"update","data":[{"symbol":"BCH/AUD","bids":[{"price":691.87,"qty":0.00000000},{"price":690.28,"qty":0.03288107}],"asks":[],"checksum":1618495083,"timestamp":"2024-06-01T17:52:15.457804Z"}]}
{"channel":"book","type":"update","data":[{"symbol":"BCH/AUD","bids":[{"price":692.59,"qty":6.14914620}],"asks":[],"checksum":2920599211,"timestamp":"2024-06-01T17:52:15.457823Z"}]}
{"channel":"book","type":"update","data":[{"symbol":"BCH/AUD","bids":[{"price":692.60,"qty":6.00000000}],"asks":[],"checksum":2914037351,"timestamp":"2024-06-01T17:52:15.464501Z"}]}
{"channel":"book","type":"update","data":[{"symbol":"BCH/AUD","bids":[{"price":691.88,"qty":0.00000000},{"price":690.91,"qty":10.93257000}],"asks":[],"checksum":4022799613,"timestamp":"2024-06-01T17:52:15.643217Z"}]}
{"channel":"book","type":"update","data":[{"symbol":"BCH/AUD","bids":[{"price":692.59,"qty":0.00000000},{"price":690.28,"qty":0.03288107}],"asks":[],"checksum":3554718829,"timestamp":"2024-06-01T17:52:16.471546Z"}]}
{"channel":"book","type":"update","data":[{"symbol":"BCH/AUD","bids":[{"price":692.61,"qty":6.14896863}],"asks":[],"checksum":125722139,"timestamp":"2024-06-01T17:52:16.472247Z"}]}
{"channel":"book","type":"update","data":[{"symbol":"BCH/AUD","bids":[{"price":692.60,"qty":0.00000000},{"price":690.28,"qty":0.03288107}],"asks":[],"checksum":1745462676,"timestamp":"2024-06-01T17:52:16.478930Z"}]}
{"channel":"book","type":"update","data":[{"symbol":"BCH/AUD","bids":[{"price":691.73,"qty":6.00000000}],"asks":[],"checksum":376958480,"timestamp":"2024-06-01T17:52:16.478989Z"}]}
{"channel":"book","type":"update","data":[{"symbol":"BCH/AUD","bids":[{"price":692.59,"qty":6.14914623}],"asks":[],"checksum":1754169928,"timestamp":"2024-06-01T17:52:16.485718Z"}]}
{"channel":"book","type":"update","data":[{"symbol":"BCH/AUD","bids":[{"price":692.61,"qty":0.00000000},{"price":690.91,"qty":10.93257000}],"asks":[],"checksum":3792398406,"timestamp":"2024-06-01T17:52:16.485739Z"}]}
{"channel":"book","type":"update","data":[{"symbol":"BCH/AUD","bids":[{"price":692.60,"qty":6.00000000}],"asks":[],"checksum":2891194849,"timestamp":"2024-06-01T17:52:16.644676Z"}]}
{"channel":"book","type":"update","data":[{"symbol":"BCH/AUD","bids":[{"price":691.73,"qty":0.00000000},{"price":690.91,"qty":10.93257000}],"asks":[],"checksum":3184483516,"timestamp":"2024-06-01T17:52:16.651935Z"}]}
{"channel":"book","type":"update","data":[{"symbol":"BCH/AUD","bids":[{"price":692.59,"qty":0.00000000},{"price":690.28,"qty":0.03288107}],"asks":[],"checksum":3554718829,"timestamp":"2024-06-01T17:52:17.863971Z"}]}
{"channel":"book","type":"update","data":[{"symbol":"BCH/AUD","bids":[{"price":692.61,"qty":6.14896868}],"asks":[],"checksum":335539693,"timestamp":"2024-06-01T17:52:17.864011Z"}]}
{"channel":"book","type":"update","data":[{"symbol":"BCH/AUD","bids":[{"price":692.62,"qty":6.00000000}],"asks":[],"checksum":3388455844,"timestamp":"2024-06-01T17:52:17.869261Z"}]}
{"channel":"book","type":"update","data":[{"symbol":"BCH/AUD","bids":[{"price":692.61,"qty":0.00000000},{"price":690.91,"qty":10.93257000}],"asks":[],"checksum":2610747129,"timestamp":"2024-06-01T17:52:17.878511Z"}]}
{"channel":"book","type":"update","data":[{"symbol":"BCH/AUD","bids":[{"price":692.63,"qty":6.14879102}],"asks":[],"checksum":3221500593,"timestamp":"2024-06-01T17:52:17.878634Z"}]}
{"channel":"book","type":"update","data":[{"symbol":"BCH/AUD","bids":[{"price":692.62,"qty":0.00000000},{"price":690.91,"qty":10.93257000}],"asks":[],"checksum":2156263063,"timestamp":"2024-06-01T17:52:18.144567Z"}]}
{"channel":"book","type":"update","data":[{"symbol":"BCH/AUD","bids":[{"price":692.64,"qty":6.00000000}],"asks":[],"checksum":3129359244,"timestamp":"2024-06-01T17:52:18.144598Z"}]}
{"channel":"book","type":"update","data":[{"symbol":"BCH/AUD","bids":[{"price":692.60,"qty":0.00000000},{"price":690.91,"qty":10.93257000}],"asks":[],"checksum":3657680734,"timestamp":"2024-06-01T17:52:18.150458Z"}]}
{"channel":"book","type":"update","data":[{"symbol":"BCH/AUD","bids":[{"price":691.65,"qty":0.00000000},{"price":690.28,"qty":0.03288107}],"asks":[],"checksum":1569794561,"timestamp":"2024-06-01T17:52:18.621363Z"}]}
{"channel":"book","type":"update","data":[{"symbol":"BCH/AUD","bids":[{"price":691.66,"qty":2.74650750}],"asks":[],"checksum":1616298825,"timestamp":"2024-06-01T17:52:18.624175Z"}]}
{"channel":"book","type":"update","data":[{"symbol":"BCH/AUD","bids":[{"price":692.63,"qty":0.00000000},{"price":690.28,"qty":0.03288107}],"asks":[],"checksum":4008120555,"timestamp":"2024-06-01T17:52:18.872593Z"}]}
{"channel":"book","type":"update","data":[{"symbol":"BCH/AUD","bids":[{"price":692.65,"qty":6.14861344}],"asks":[],"checksum":2993798269,"timestamp":"2024-06-01T17:52:18.872633Z"}]}
{"channel":"book","type":"update","data":[{"symbol":"BCH/AUD","bids":[{"price":692.66,"qty":6.00000000}],"asks":[],"checksum":2990650426,"timestamp":"2024-06-01T17:52:18.878267Z"}]}
{"channel":"book","type":"update","data":[{"symbol":"BCH/AUD","bids":[{"price":692.67,"qty":6.14843590}],"asks":[],"checksum":2593253365,"timestamp":"2024-06-01T17:52:18.885624Z"}]}
{"channel":"book","type":"update","data":[{"symbol":"BCH/AUD","bids":[{"price":692.65,"qty":0.00000000},{"price":691.61,"qty":0.26329050}],"asks":[],"checksum":3838805183,"timestamp":"2024-06-01T17:52:18.885988Z"}]}
{"channel":"book","type":"update","data":[{"symbol":"BCH/AUD","bids":[{"price":692.66,"qty":0.00000000},{"price":690.91,"qty":10.93257000}],"asks":[],"checksum":1404123903,"timestamp":"2024-06-01T17:52:19.144144Z"}]}
{"channel":"book","type":"update","data":[{"symbol":"BCH/AUD","bids":[{"price":692.68,"qty":6.00000000}],"asks":[],"checksum":1802547461,"timestamp":"2024-06-01T17:52:19.144166Z"}]}
{"channel":"book","type":"update","data":[{"symbol":"BCH/AUD","bids":[{"price":692.64,"qty":0.00000000},{"price":690.91,"qty":10.93257000}],"asks":[],"checksum":2048794761,"timestamp":"2024-06-01T17:52:19.149962Z"}]}
{"channel":"book","type":"update","data":[{"symbol":"BCH/AUD","bids":[{"price":692.69,"qty":6.14825838}],"asks":[],"checksum":1159544290,"timestamp":"2024-06-01T17:52:20.256416Z"}]}
{"channel":"book","type":"update","data":[{"symbol":"BCH/AUD","bids":[{"price":692.67,"qty":0.00000000},{"price":690.91,"qty":10.93257000}],"asks":[],"checksum":2447597808,"timestamp":"2024-06-01T17:52:20.256483Z"}]}
{"channel":"book","type":"update","data":[{"symbol":"BCH/AUD","bids":[{"price":692.70,"qty":6.00000000}],"asks":[],"checksum":3975708168,"timestamp":"2024-06-01T17:52:20.262980Z"}]}
{"channel":"book","type":"update","data":[{"symbol":"BCH/AUD","bids":[{"price":692.69,"qty":0.00000000},{"price":690.91,"qty":10.93257000}],"asks":[],"checksum":670518493,"timestamp":"2024-06-01T17:52:20.269203Z"}]}
{"channel":"book","type":"update","data":[{"symbol":"BCH/AUD","bids":[{"price":692.71,"qty":6.14808087}],"asks":[],"checksum":725281971,"timestamp":"2024-06-01T17:52:20.269293Z"}]}
{"channel":"book","type":"update","data":[{"symbol":"BCH/AUD","bids":[{"price":692.70,"qty":0.00000000},{"price":690.91,"qty":10.93257000}],"asks":[],"checksum":1494372077,"timestamp":"2024-06-01T17:52:20.643735Z"}]}
{"channel":"book","type":"update","data":[{"symbol":"BCH/AUD","bids":[{"price":692.72,"qty":6.00000000}],"asks":[],"checksum":1825227139,"timestamp":"2024-06-01T17:52:20.648622Z"}]}
{"channel":"book","type":"update","data":[{"symbol":"BCH/AUD","bids":[{"price":692.68,"qty":0.00000000},{"price":690.91,"qty":10.93257000}],"asks":[],"checksum":3767322966,"timestamp":"2024-06-01T17:52:21.143275Z"}]}
{"channel":"book","type":"update","data":[{"symbol":"BCH/AUD","bids":[{"price":692.71,"qty":0.00000000},{"price":690.28,"qty":0.03288107}],"asks":[],"checksum":1481169337,"timestamp":"2024-06-01T17:52:21.250991Z"}]}
{"channel":"book","type":"update","data":[{"symbol":"BCH/AUD","bids":[{"price":692.59,"qty":6.14914610}],"asks":[],"checksum":1484132555,"timestamp":"2024-06-01T17:52:21.251023Z"}]}
{"channel":"book","type":"update","data":[{"symbol":"BCH/AUD","bids":[{"price":692.72,"qty":0.00000000},{"price":690.28,"qty":0.03288107}],"asks":[],"checksum":2981510250,"timestamp":"2024-06-01T17:52:22.142542Z"}]}
{"channel":"book","type":"update","data":[{"symbol":"BCH/AUD","bids":[{"price":692.60,"qty":6.00000000}],"asks":[],"checksum":1411084732,"timestamp":"2024-06-01T17:52:22.142696Z"}]}
{"channel":"book","type":"update","data":[{"symbol":"BCH/AUD","bids":[{"price":692.58,"qty":0.00000000},{"price":690.28,"qty":0.03288107},{"price":692.61,"qty":0.23148478}],"asks":[],"checksum":1295772095,"timestamp":"2024-06-01T17:52:22.149322Z"}]}
{"channel":"book","type":"update","data":[{"symbol":"BCH/AUD","bids":[],"asks":[{"price":694.14,"qty":0.00000000},{"price":695.65,"qty":0.26329050}],"checksum":2557603088,"timestamp":"2024-06-01T17:52:22.409934Z"}]}
{"channel":"book","type":"update","data":[{"symbol":"BCH/AUD","bids":[{"price":691.66,"qty":0.00000000},{"price":690.28,"qty":0.03288107}],"asks":[],"checksum":50168364,"timestamp":"2024-06-01T17:52:22.410026Z"}]}
{"channel":"book","type":"update","data":[{"symbol":"BCH/AUD","bids":[{"price":691.73,"qty":2.74650750}],"asks":[],"checksum":1893491839,"timestamp":"2024-06-01T17:52:22.412844Z"}]}
{"channel":"book","type":"update","data":[{"symbol":"BCH/AUD","bids":[{"price":691.12,"qty":0.26329050}],"asks":[],"checksum":3937588982,"timestamp":"2024-06-01T17:52:22.412955Z"}]}
{"channel":"book","type":"update","data":[{"symbol":"BCH/AUD","bids":[],"asks":[{"price":694.65,"qty":0.26329050}],"checksum":2240024431,"timestamp":"2024-06-01T17:52:22.413036Z"}]}
{"channel":"book","type":"update","data":[{"symbol":"BCH/AUD","bids":[{"price":692.62,"qty":6.14887984}],"asks":[],"checksum":445420825,"timestamp":"2024-06-01T17:52:22.651837Z"}]}
{"channel":"book","type":"update","data":[{"symbol":"BCH/AUD","bids":[{"price":692.59,"qty":0.00000000},{"price":691.12,"qty":0.26329050}],"asks":[],"checksum":2620450608,"timestamp":"2024-06-01T17:52:22.651889Z"}]}
{"channel":"book","type":"update","data":[{"symbol":"BCH/AUD","bids":[{"price":692.63,"qty":6.00000000}],"asks":[],"checksum":3015977957,"timestamp":"2024-06-01T17:52:22.657600Z"}]}
{"channel":"book","type":"update","data":[{"symbol":"BCH/AUD","bids":[{"price":692.62,"qty":0.00000000},{"price":691.12,"qty":0.26329050}],"asks":[],"checksum":1138323788,"timestamp":"2024-06-01T17:52:22.665057Z"}]}
{"channel":"book","type":"update","data":[{"symbol":"BCH/AUD","bids":[{"price":692.64,"qty":6.14870234}],"asks":[],"checksum":4238864835,"timestamp":"2024-06-01T17:52:22.665144Z"}]}
{"channel":"book","type":"update","data":[{"symbol":"BCH/AUD","bids":[{"price":692.63,"qty":0.00000000},{"price":691.12,"qty":0.26329050}],"asks":[],"checksum":10198558,"timestamp":"2024-06-01T17:52:23.143798Z"}]}
{"channel":"book","type":"update","data":[{"symbol":"BCH/AUD","bids":[{"price":692.65,"qty":6.00000000}],"asks":[],"checksum":1635471171,"timestamp":"2024-06-01T17:52:23.143856Z"}]}
{"channel":"book","type":"update","data":[{"symbol":"BCH/AUD","bids":[{"price":692.60,"qty":0.00000000},{"price":691.12,"qty":0.26329050}],"asks":[],"checksum":1561990834,"timestamp":"2024-06-01T17:52:23.149089Z"}]}
{"channel":"book","type":"update","data":[{"symbol":"BCH/AUD","bids":[{"price":692.66,"qty":6.14852469}],"asks":[],"checksum":3811646875,"timestamp":"2024-06-01T17:52:23.663134Z"}]}
{"channel":"book","type":"update","data":[{"symbol":"BCH/AUD","bids":[{"price":692.64,"qty":0.00000000},{"price":691.12,"qty":0.26329050}],"asks":[],"checksum":833560596,"timestamp":"2024-06-01T17:52:23.663275Z"}]}
{"channel":"book","type":"update","data":[{"symbol":"BCH/AUD","bids":[{"price":692.67,"qty":6.00000000}],"asks":[],"checksum":1061723143,"timestamp":"2024-06-01T17:52:23.676277Z"}]}
{"channel":"book","type":"update","data":[{"symbol":"BCH/AUD","bids":[{"price":692.68,"qty":6.14834721}],"asks":[],"checksum":347505264,"timestamp":"2024-06-01T17:52:23.687666Z"}]}
{"channel":"book","type":"update","data":[{"symbol":"BCH/AUD","bids":[{"price":692.66,"qty":0.00000000},{"price":691.61,"qty":0.26329050}],"asks":[],"checksum":2785118507,"timestamp":"2024-06-01T17:52:23.687789Z"}]}
{"channel":"book","type":"update","data":[{"symbol":"BCH/AUD","bids":[{"price":692.67,"qty":0.00000000},{"price":691.12,"qty":0.26329050}],"asks":[],"checksum":3561034343,"timestamp":"2024-06-01T17:52:24.141869Z"}]}
{"channel":"book","type":"update","data":[{"symbol":"BCH/AUD","bids":[{"price":692.69,"qty":6.00000000}],"asks":[],"checksum":1453898532,"timestamp":"2024-06-01T17:52:24.147436Z"}]}
{"channel":"book","type":"update","data":[{"symbol":"BCH/AUD","bids":[{"price":692.65,"qty":0.00000000},{"price":691.12,"qty":0.26329050}],"asks":[],"checksum":2816800107,"timestamp":"2024-06-01T17:52:24.644642Z"}]}
{"channel":"book","type":"update","data":[{"symbol":"BCH/AUD","bids":[{"price":692.68,"qty":0.00000000},{"price":690.91,"qty":10.93257000}],"asks":[],"checksum":2671633698,"timestamp":"2024-06-01T17:52:25.046865Z"}]}
{"channel":"book","type":"update","data":[{"symbol":"BCH/AUD","bids":[{"price":692.70,"qty":6.14816962}],"asks":[],"checksum":1021086927,"timestamp":"2024-06-01T17:52:25.047072Z"}]}
{"channel":"book","type":"update","data":[{"symbol":"BCH/AUD","bids":[{"price":692.71,"qty":6.00000000}],"asks":[],"checksum":3860746089,"timestamp":"2024-06-01T17:52:25.143204Z"}]}
{"channel":"book","type":"update","data":[{"symbol":"BCH/AUD","bids":[{"price":692.69,"qty":0.00000000},{"price":691.12,"qty":0.26329050}],"asks":[],"checksum":1320815082,"timestamp":"2024-06-01T17:52:25.147963Z"}]}
{"channel":"book","type":"update","data":[{"symbol":"BCH/AUD","bids":[{"price":692.70,"qty":0.00000000},{"price":690.91,"qty":10.93257000}],"asks":[],"checksum":3594576688,"timestamp":"2024-06-01T17:52:25.163221Z"}]}
{"channel":"book","type":"update","data":[{"symbol":"BCH/AUD","bids":[{"price":692.72,"qty":6.14799211}],"asks":[],"checksum":3920543005,"timestamp":"2024-06-01T17:52:25.163448Z"}]}
{"channel":"book","type":"update","data":[{"symbol":"BCH/AUD","bids":[{"price":692.73,"qty":6.00000000}],"asks":[],"checksum":2581380216,"timestamp":"2024-06-01T17:52:25.644048Z"}]}
{"channel":"book","type":"update","data":[{"symbol":"BCH/AUD","bids":[{"price":692.71,"qty":0.00000000},{"price":691.12,"qty":0.26329050}],"asks":[],"checksum":3590127460,"timestamp":"2024-06-01T17:52:25.648926Z"}]}
{"channel":"book","type":"update","data":[{"symbol":"BCH/AUD","bids":[{"price":692.72,"qty":0.00000000},{"price":690.91,"qty":10.93257000}],"asks":[],"checksum":4178840413,"timestamp":"2024-06-01T17:52:26.050222Z"}]}
{"channel":"book","type":"update","data":[{"symbol":"BCH/AUD","bids":[{"price":692.74,"qty":6.14781462}],"asks":[],"checksum":1598043563,"timestamp":"2024-06-01T17:52:26.050638Z"}]}
{"channel":"book","type":"update","data":[{"symbol":"BCH/AUD","bids":[{"price":692.75,"qty":6.00000000}],"asks":[],"checksum":705283508,"timestamp":"2024-06-01T17:52:26.057330Z"}]}
{"channel":"book","type":"update","data":[{"symbol":"BCH/AUD","bids":[{"price":692.73,"qty":0.00000000},{"price":691.12,"qty":0.26329050}],"asks":[],"checksum":14703575,"timestamp":"2024-06-01T17:52:26.142151Z"}]}
{"channel":"book","type":"update","data":[{"symbol":"BCH/AUD","bids":[{"price":691.73,"qty":0.00000000},{"price":690.91,"qty":10.93257000}],"asks":[],"checksum":2587926883,"timestamp":"2024-06-01T17:52:27.449090Z"}]}
{"channel":"book","type":"update","data":[{"symbol":"BCH/AUD","bids":[{"price":691.74,"qty":2.74650750}],"asks":[],"checksum":1889972800,"timestamp":"2024-06-01T17:52:27.451835Z"}]}
{"channel":"book","type":"update","data":[{"symbol":"BCH/AUD","bids":[{"price":692.74,"qty":0.00000000},{"price":690.91,"qty":10.93257000}],"asks":[],"checksum":2178351885,"timestamp":"2024-06-01T17:52:27.467172Z"}]}
{"channel":"book","type":"update","data":[{"symbol":"BCH/AUD","bids":[{"price":692.76,"qty":6.14763713}],"asks":[],"checksum":3484425312,"timestamp":"2024-06-01T17:52:27.467193Z"}]}
{"channel":"book","type":"update","data":[{"symbol":"BCH/AUD","bids":[{"price":692.77,"qty":6.00000000}],"asks":[],"checksum":4137308118,"timestamp":"2024-06-01T17:52:27.643632Z"}]}
{"channel":"book","type":"update","data":[{"symbol":"BCH/AUD","bids":[{"price":692.76,"qty":0.00000000},{"price":691.12,"qty":0.26329050}],"asks":[],"checksum":3634233784,"timestamp":"2024-06-01T17:52:27.648825Z"}]}
{"channel":"book","type":"update","data":[{"symbol":"BCH/AUD","bids":[{"price":692.78,"qty":6.14745965}],"asks":[],"checksum":3472234063,"timestamp":"2024-06-01T17:52:27.649093Z"}]}
{"channel":"book","type":"update","data":[{"symbol":"BCH/AUD","bids":[{"price":692.75,"qty":0.00000000},{"price":691.12,"qty":0.26329050}],"asks":[],"checksum":3059867689,"timestamp":"2024-06-01T17:52:27.650083Z"}]}
{"channel":"book","type":"update","data":[{"symbol":"BCH/AUD","bids":[{"price":692.61,"qty":0.00000000},{"price":690.91,"qty":10.93257000},{"price":692.78,"qty":6.37888762}],"asks":[],"checksum":688580627,"timestamp":"2024-06-01T17:52:27.653663Z"}]}
{"channel":"book","type":"update","data":[{"symbol":"BCH/AUD","bids":[{"price":692.79,"qty":6.00000000}],"asks":[],"checksum":3356904782,"timestamp":"2024-06-01T17:52:28.143629Z"}]}
{"channel":"book","type":"update","data":[{"symbol":"BCH/AUD","bids":[{"price":692.77,"qty":0.00000000},{"price":690.91,"qty":10.93257000}],"asks":[],"checksum":1273922141,"timestamp":"2024-06-01T17:52:28.149036Z"}]}
{"channel":"book","type":"update","data":[{"symbol":"BCH/AUD","bids":[{"price":692.78,"qty":0.23142797}],"asks":[],"checksum":1294566418,"timestamp":"2024-06-01T17:52:28.470955Z"}]}
{"channel":"book","type":"update","data":[{"symbol":"BCH/AUD","bids":[{"price":692.80,"qty":6.14728218}],"asks":[],"checksum":3982713130,"timestamp":"2024-06-01T17:52:28.471234Z"}]}
{"channel":"book","type":"update","data":[{"symbol":"BCH/AUD","bids":[{"price":692.81,"qty":6.00000000}],"asks":[],"checksum":835919760,"timestamp":"2024-06-01T17:52:28.642791Z"}]}
