{"channel":"book","type":"snapshot","data":[{"symbol":"BCH/JPY","bids":[{"price":72332,"qty":0.32607652},{"price":72300,"qty":0.38039880},{"price":72223,"qty":1.72271007},{"price":72222,"qty":3.94789140},{"price":72215,"qty":0.02500000},{"price":72077,"qty":15.44858940},{"price":72076,"qty":0.38039880},{"price":71978,"qty":11.81242440},{"price":71825,"qty":19.75345998},{"price":71732,"qty":21.75179434}],"asks":[{"price":72536,"qty":0.38039880},{"price":72559,"qty":0.02500000},{"price":72613,"qty":3.94789140},{"price":72680,"qty":15.44858940},{"price":72681,"qty":0.38039880},{"price":72876,"qty":2.58370377},{"price":72877,"qty":0.02511046},{"price":72878,"qty":11.81242440},{"price":73321,"qty":7.62842340},{"price":73322,"qty":7.62842340}],"checksum":674798246}]}
{"channel":"book","type":"update","data":[{"symbol":"BCH/JPY","bids":[],"asks":[{"price":73321,"qty":0.00000000},{"price":73333,"qty":0.02500000}],"checksum":2904045643,"timestamp":"2024-06-01T17:51:11.505509Z"}]}
{"channel":"book","type":"update","data":[{"symbol":"BCH/JPY","bids":[],"asks":[{"price":73320,"qty":7.62842340}],"checksum":3513659440,"timestamp":"2024-06-01T17:51:11.508279Z"}]}
{"channel":"book","type":"update","data":[{"symbol":"BCH/JPY","bids":[{"price":71732,"qty":0.00000000},{"price":71612,"qty":7.62842340}],"asks":[],"checksum":3701514009,"timestamp":"2024-06-01T17:51:12.214011Z"}]}
{"channel":"book","type":"update","data":[{"symbol":"BCH/JPY","bids":[{"price":71737,"qty":21.75085314}],"asks":[],"checksum":2493125561,"timestamp":"2024-06-01T17:51:12.254328Z"}]}
{"channel":"book","type":"update","data":[{"symbol":"BCH/JPY","bids":[{"price":72077,"qty":0.00000000},{"price":71612,"qty":7.62842340}],"asks":[],"checksum":342003901,"timestamp":"2024-06-01T17:51:17.388982Z"}]}
{"channel":"book","type":"update","data":[{"symbol":"BCH/JPY","bids":[],"asks":[{"price":73320,"qty":0.00000000},{"price":73333,"qty":0.02500000}],"checksum":3196410995,"timestamp":"2024-06-01T17:51:17.388999Z"}]}
{"channel":"book","type":"update","data":[{"symbol":"BCH/JPY","bids":[{"price":72078,"qty":15.44858940}],"asks":[],"checksum":2969278672,"timestamp":"2024-06-01T17:51:17.391800Z"}]}
{"channel":"book","type":"update","data":[{"symbol":"BCH/JPY","bids":[],"asks":[{"price":73321,"qty":7.62842340}],"checksum":903559741,"timestamp":"2024-06-01T17:51:17.391992Z"}]}
{"channel":"book","type":"update","data":[{"symbol":"BCH/JPY","bids":[{"price":72078,"qty":0.00000000},{"price":71612,"qty":7.62842340}],"asks":[],"checksum":4212615457,"timestamp":"2024-06-01T17:51:23.273261Z"}]}
{"channel":"book","type":"update","data":[{"symbol":"BCH/JPY","bids":[{"price":72077,"qty":15.44858940}],"asks":[],"checksum":1842133295,"timestamp":"2024-06-01T17:51:23.275966Z"}]}
{"channel":"book","type":"update","data":[{"symbol":"BCH/JPY","bids":[{"price":72223,"qty":0.00000000},{"price":71612,"qty":7.62842340}],"asks":[],"checksum":4186662759,"timestamp":"2024-06-01T17:51:24.262321Z"}]}
{"channel":"book","type":"update","data":[{"symbol":"BCH/JPY","bids":[{"price":72301,"qty":1.72085157}],"asks":[],"checksum":1018129240,"timestamp":"2024-06-01T17:51:24.262543Z"}]}
{"channel":"book","type":"update","data":[{"symbol":"BCH/JPY","bids":[],"asks":[{"price":72877,"qty":0.00000000},{"price":73333,"qty":0.02500000},{"price":72875,"qty":0.02511046}],"checksum":887354120,"timestamp":"2024-06-01T17:51:24.264581Z"}]}
{"channel":"book","type":"update","data":[{"symbol":"BCH/JPY","bids":[{"price":72301,"qty":0.00000000},{"price":71612,"qty":7.62842340}],"asks":[],"checksum":4056416055,"timestamp":"2024-06-01T17:51:25.248792Z"}]}
{"channel":"book","type":"update","data":[{"symbol":"BCH/JPY","bids":[{"price":72223,"qty":1.72271007}],"asks":[],"checksum":1702895999,"timestamp":"2024-06-01T17:51:25.248926Z"}]}
{"channel":"book","type":"update","data":[{"symbol":"BCH/JPY","bids":[{"price":72223,"qty":0.00000000},{"price":71612,"qty":7.62842340}],"asks":[],"checksum":4056416055,"timestamp":"2024-06-01T17:51:27.576073Z"}]}
{"channel":"book","type":"update","data":[{"symbol":"BCH/JPY","bids":[{"price":72301,"qty":1.72085157}],"asks":[],"checksum":887354120,"timestamp":"2024-06-01T17:51:27.576201Z"}]}
{"channel":"book","type":"update","data":[{"symbol":"BCH/JPY","bids":[{"price":71737,"qty":0.00000000},{"price":71612,"qty":7.62842340}],"asks":[],"checksum":2946651897,"timestamp":"2024-06-01T17:51:27.577102Z"}]}
{"channel":"book","type":"update","data":[{"symbol":"BCH/JPY","bids":[{"price":71744,"qty":21.74652576}],"asks":[],"checksum":1881788991,"timestamp":"2024-06-01T17:51:27.617301Z"}]}
{"channel":"book","type":"update","data":[{"symbol":"BCH/JPY","bids":[{"price":72301,"qty":0.00000000},{"price":71612,"qty":7.62842340}],"asks":[],"checksum":2369181999,"timestamp":"2024-06-01T17:51:28.328000Z"}]}
{"channel":"book","type":"update","data":[{"symbol":"BCH/JPY","bids":[{"price":72223,"qty":1.72271007}],"asks":[],"checksum":558497864,"timestamp":"2024-06-01T17:51:28.328331Z"}]}
{"channel":"book","type":"update","data":[{"symbol":"BCH/JPY","bids":[],"asks":[{"price":73321,"qty":0.00000000},{"price":73333,"qty":0.02500000}],"checksum":3182412481,"timestamp":"2024-06-01T17:51:29.157945Z"}]}
{"channel":"book","type":"update","data":[{"symbol":"BCH/JPY","bids":[{"price":72077,"qty":0.00000000},{"price":71612,"qty":7.62842340}],"asks":[],"checksum":1250366128,"timestamp":"2024-06-01T17:51:29.158181Z"}]}
{"channel":"book","type":"update","data":[{"symbol":"BCH/JPY","bids":[],"asks":[{"price":73320,"qty":7.62842340}],"checksum":1228327912,"timestamp":"2024-06-01T17:51:29.160504Z"}]}
{"channel":"book","type":"update","data":[{"symbol":"BCH/JPY","bids":[{"price":72223,"qty":17.17129947}],"asks":[],"checksum":1617478553,"timestamp":"2024-06-01T17:51:29.160802Z"}]}
{"channel":"book","type":"update","data":[{"symbol":"BCH/JPY","bids":[],"asks":[{"price":73320,"qty":0.00000000},{"price":73333,"qty":0.02500000}],"checksum":98282374,"timestamp":"2024-06-01T17:51:35.042628Z"}]}
{"channel":"book","type":"update","data":[{"symbol":"BCH/JPY","bids":[],"asks":[{"price":73321,"qty":7.62842340}],"checksum":2571004175,"timestamp":"2024-06-01T17:51:35.045402Z"}]}
{"channel":"book","type":"update","data":[{"symbol":"BCH/JPY","bids":[{"price":71744,"qty":0.00000000},{"price":71398,"qty":3.78585540}],"asks":[],"checksum":2807070227,"timestamp":"2024-06-01T17:51:42.278785Z"}]}
{"channel":"book","type":"update","data":[{"symbol":"BCH/JPY","bids":[{"price":71751,"qty":21.73834334}],"asks":[],"checksum":405349850,"timestamp":"2024-06-01T17:51:42.319115Z"}]}
{"channel":"book","type":"update","data":[{"symbol":"BCH/JPY","bids":[{"price":72223,"qty":15.44858940}],"asks":[],"checksum":128719750,"timestamp":"2024-06-01T17:51:43.859104Z"}]}
{"channel":"book","type":"update","data":[{"symbol":"BCH/JPY","bids":[{"price":72301,"qty":1.72085157}],"asks":[],"checksum":3482939103,"timestamp":"2024-06-01T17:51:43.859189Z"}]}
{"channel":"book","type":"update","data":[{"symbol":"BCH/JPY","bids":[],"asks":[{"price":73321,"qty":0.00000000},{"price":73333,"qty":0.02500000}],"checksum":1400679510,"timestamp":"2024-06-01T17:51:46.811942Z"}]}
{"channel":"book","type":"update","data":[{"symbol":"BCH/JPY","bids":[],"asks":[{"price":73320,"qty":7.62842340}],"checksum":919585865,"timestamp":"2024-06-01T17:51:46.814716Z"}]}
{"channel":"book","type":"update","data":[{"symbol":"BCH/JPY","bids":[],"asks":[{"price":73320,"qty":0.00000000},{"price":73333,"qty":0.02500000}],"checksum":1400679510,"timestamp":"2024-06-01T17:51:52.696298Z"}]}
{"channel":"book","type":"update","data":[{"symbol":"BCH/JPY","bids":[],"asks":[{"price":73321,"qty":7.62842340}],"checksum":3482939103,"timestamp":"2024-06-01T17:51:52.699250Z"}]}
{"channel":"book","type":"update","data":[{"symbol":"BCH/JPY","bids":[{"price":71751,"qty":0.00000000},{"price":71612,"qty":7.62842340}],"asks":[],"checksum":977042020,"timestamp":"2024-06-01T17:51:56.876777Z"}]}
{"channel":"book","type":"update","data":[{"symbol":"BCH/JPY","bids":[{"price":71759,"qty":21.72862708}],"asks":[],"checksum":456450998,"timestamp":"2024-06-01T17:51:56.917036Z"}]}
{"channel":"book","type":"update","data":[{"symbol":"BCH/JPY","bids":[{"price":71978,"qty":0.00000000},{"price":71612,"qty":7.62842340}],"asks":[],"checksum":1147073702,"timestamp":"2024-06-01T17:51:58.580735Z"}]}
{"channel":"book","type":"update","data":[{"symbol":"BCH/JPY","bids":[{"price":72077,"qty":11.81242440}],"asks":[],"checksum":2329403757,"timestamp":"2024-06-01T17:51:58.583528Z"}]}
{"channel":"book","type":"update","data":[{"symbol":"BCH/JPY","bids":[{"price":72301,"qty":0.00000000},{"price":71612,"qty":7.62842340}],"asks":[],"checksum":925914396,"timestamp":"2024-06-01T17:52:03.560486Z"}]}
{"channel":"book","type":"update","data":[{"symbol":"BCH/JPY","bids":[{"price":72333,"qty":1.72009027}],"asks":[],"checksum":1444300599,"timestamp":"2024-06-01T17:52:03.560720Z"}]}
{"channel":"book","type":"update","data":[{"symbol":"BCH/JPY","bids":[{"price":72332,"qty":0.00000000},{"price":71612,"qty":7.62842340},{"price":72343,"qty":0.32613383}],"asks":[],"checksum":1114488467,"timestamp":"2024-06-01T17:52:03.568762Z"}]}
{"channel":"book","type":"update","data":[{"symbol":"BCH/JPY","bids":[{"price":72222,"qty":0.00000000},{"price":71612,"qty":7.62842340}],"asks":[],"checksum":2994254697,"timestamp":"2024-06-01T17:52:03.572164Z"}]}
{"channel":"book","type":"update","data":[{"symbol":"BCH/JPY","bids":[],"asks":[{"price":73321,"qty":0.00000000},{"price":73333,"qty":0.02500000}],"checksum":782070240,"timestamp":"2024-06-01T17:52:03.572332Z"}]}
{"channel":"book","type":"update","data":[{"symbol":"BCH/JPY","bids":[],"asks":[{"price":72536,"qty":0.00000000},{"price":73663,"qty":17.78878527}],"checksum":569022544,"timestamp":"2024-06-01T17:52:03.573011Z"}]}
{"channel":"book","type":"update","data":[{"symbol":"BCH/JPY","bids":[{"price":72224,"qty":3.94789140}],"asks":[],"checksum":710515495,"timestamp":"2024-06-01T17:52:03.574890Z"}]}
{"channel":"book","type":"update","data":[{"symbol":"BCH/JPY","bids":[],"asks":[{"price":73320,"qty":7.62842340}],"checksum":2599353559,"timestamp":"2024-06-01T17:52:03.575248Z"}]}
{"channel":"book","type":"update","data":[{"symbol":"BCH/JPY","bids":[],"asks":[{"price":72577,"qty":0.38039880}],"checksum":3206139406,"timestamp":"2024-06-01T17:52:03.575607Z"}]}
{"channel":"book","type":"update","data":[{"symbol":"BCH/JPY","bids":[{"price":72333,"qty":0.00000000},{"price":71612,"qty":7.62842340}],"asks":[],"checksum":1740660749,"timestamp":"2024-06-01T17:52:03.580255Z"}]}
{"channel":"book","type":"update","data":[{"symbol":"BCH/JPY","bids":[{"price":72344,"qty":1.71982873}],"asks":[],"checksum":1108669555,"timestamp":"2024-06-01T17:52:03.580399Z"}]}
{"channel":"book","type":"update","data":[{"symbol":"BCH/JPY","bids":[],"asks":[{"price":72875,"qty":0.00000000},{"price":73333,"qty":0.02500000},{"price":73319,"qty":0.02511050}],"checksum":349125694,"timestamp":"2024-06-01T17:52:03.582285Z"}]}
{"channel":"book","type":"update","data":[{"symbol":"BCH/JPY","bids":[{"price":72344,"qty":0.00000000},{"price":71612,"qty":7.62842340}],"asks":[],"checksum":823896128,"timestamp":"2024-06-01T17:52:04.556989Z"}]}
{"channel":"book","type":"update","data":[{"symbol":"BCH/JPY","bids":[{"price":72301,"qty":1.72085157}],"asks":[],"checksum":2216456293,"timestamp":"2024-06-01T17:52:04.557081Z"}]}
{"channel":"book","type":"update","data":[{"symbol":"BCH/JPY","bids":[{"price":72301,"qty":0.00000000},{"price":71612,"qty":7.62842340}],"asks":[],"checksum":823896128,"timestamp":"2024-06-01T17:52:04.652885Z"}]}
{"channel":"book","type":"update","data":[{"symbol":"BCH/JPY","bids":[{"price":72344,"qty":1.71982873}],"asks":[],"checksum":349125694,"timestamp":"2024-06-01T17:52:04.653002Z"}]}
{"channel":"book","type":"update","data":[{"symbol":"BCH/JPY","bids":[{"price":72344,"qty":0.00000000},{"price":71612,"qty":7.62842340}],"asks":[],"checksum":823896128,"timestamp":"2024-06-01T17:52:05.210853Z"}]}
{"channel":"book","type":"update","data":[{"symbol":"BCH/JPY","bids":[{"price":72301,"qty":1.72085157}],"asks":[],"checksum":2216456293,"timestamp":"2024-06-01T17:52:05.210868Z"}]}
{"channel":"book","type":"update","data":[{"symbol":"BCH/JPY","bids":[{"price":72076,"qty":0.00000000},{"price":71612,"qty":7.62842340}],"asks":[],"checksum":2011299439,"timestamp":"2024-06-01T17:52:07.407339Z"}]}
{"channel":"book","type":"update","data":[{"symbol":"BCH/JPY","bids":[{"price":72224,"qty":0.00000000},{"price":71398,"qty":3.78585540}],"asks":[],"checksum":3329216273,"timestamp":"2024-06-01T17:52:07.407355Z"}]}
{"channel":"book","type":"update","data":[{"symbol":"BCH/JPY","bids":[],"asks":[{"price":73320,"qty":0.00000000},{"price":73333,"qty":0.02500000}],"checksum":2762976580,"timestamp":"2024-06-01T17:52:07.407578Z"}]}
{"channel":"book","type":"update","data":[{"symbol":"BCH/JPY","bids":[{"price":72199,"qty":0.38039880}],"asks":[],"checksum":2989932131,"timestamp":"2024-06-01T17:52:07.409963Z"}]}
{"channel":"book","type":"update","data":[{"symbol":"BCH/JPY","bids":[{"price":72225,"qty":3.94789140}],"asks":[],"checksum":3383601508,"timestamp":"2024-06-01T17:52:07.410054Z"}]}
{"channel":"book","type":"update","data":[{"symbol":"BCH/JPY","bids":[],"asks":[{"price":73318,"qty":7.62842340}],"checksum":2908676292,"timestamp":"2024-06-01T17:52:07.410988Z"}]}
{"channel":"book","type":"update","data":[{"symbol":"BCH/JPY","bids":[{"price":72343,"qty":0.00000000},{"price":71612,"qty":7.62842340},{"price":72353,"qty":0.32591981}],"asks":[],"checksum":3193082639,"timestamp":"2024-06-01T17:52:09.455785Z"}]}
{"channel":"book","type":"update","data":[{"symbol":"BCH/JPY","bids":[],"asks":[{"price":73319,"qty":0.00000000},{"price":73333,"qty":0.02500000},{"price":73317,"qty":0.02510012}],"checksum":3959363234,"timestamp":"2024-06-01T17:52:09.457914Z"}]}
{"channel":"book","type":"update","data":[{"symbol":"BCH/JPY","bids":[],"asks":[{"price":73318,"qty":0.00000000},{"price":73333,"qty":0.02500000}],"checksum":2367725640,"timestamp":"2024-06-01T17:52:13.291789Z"}]}
{"channel":"book","type":"update","data":[{"symbol":"BCH/JPY","bids":[{"price":72225,"qty":0.00000000},{"price":71612,"qty":7.62842340}],"asks":[],"checksum":4139497295,"timestamp":"2024-06-01T17:52:13.291933Z"}]}
{"channel":"book","type":"update","data":[{"symbol":"BCH/JPY","bids":[{"price":72226,"qty":3.94789140}],"asks":[],"checksum":663134908,"timestamp":"2024-06-01T17:52:13.294491Z"}]}
{"channel":"book","type":"update","data":[{"symbol":"BCH/JPY","bids":[],"asks":[{"price":73317,"qty":7.65352352}],"checksum":250260732,"timestamp":"2024-06-01T17:52:13.294536Z"}]}
{"channel":"book","type":"update","data":[{"symbol":"BCH/JPY","bids":[{"price":71759,"qty":0.00000000},{"price":71612,"qty":7.62842340}],"asks":[],"checksum":1046378809,"timestamp":"2024-06-01T17:52:13.889348Z"}]}
{"channel":"book","type":"update","data":[{"symbol":"BCH/JPY","bids":[{"price":71765,"qty":21.72554946}],"asks":[],"checksum":611393296,"timestamp":"2024-06-01T17:52:13.929797Z"}]}
{"channel":"book","type":"update","data":[{"symbol":"BCH/JPY","bids":[],"asks":[{"price":73317,"qty":0.02510012}],"checksum":220008784,"timestamp":"2024-06-01T17:52:19.176023Z"}]}
{"channel":"book","type":"update","data":[{"symbol":"BCH/JPY","bids":[{"price":72226,"qty":0.00000000},{"price":71612,"qty":7.62842340}],"asks":[],"checksum":2957447966,"timestamp":"2024-06-01T17:52:19.176392Z"}]}
{"channel":"book","type":"update","data":[{"symbol":"BCH/JPY","bids":[],"asks":[{"price":73318,"qty":7.62842340}],"checksum":3600328180,"timestamp":"2024-06-01T17:52:19.178835Z"}]}
{"channel":"book","type":"update","data":[{"symbol":"BCH/JPY","bids":[{"price":72224,"qty":3.94789140}],"asks":[],"checksum":2802230498,"timestamp":"2024-06-01T17:52:19.179143Z"}]}
{"channel":"book","type":"update","data":[{"symbol":"BCH/JPY","bids":[],"asks":[{"price":72613,"qty":0.00000000},{"price":73333,"qty":0.02500000}],"checksum":3736475290,"timestamp":"2024-06-01T17:52:22.409960Z"}]}
{"channel":"book","type":"update","data":[{"symbol":"BCH/JPY","bids":[{"price":72223,"qty":0.00000000},{"price":71612,"qty":7.62842340}],"asks":[],"checksum":3649996563,"timestamp":"2024-06-01T17:52:22.409981Z"}]}
{"channel":"book","type":"update","data":[{"symbol":"BCH/JPY","bids":[],"asks":[{"price":72577,"qty":0.00000000},{"price":73663,"qty":17.78878527}],"checksum":715257456,"timestamp":"2024-06-01T17:52:22.410136Z"}]}
{"channel":"book","type":"update","data":[{"symbol":"BCH/JPY","bids":[],"asks":[{"price":72681,"qty":0.00000000},{"price":73715,"qty":3.78585540}],"checksum":3491132749,"timestamp":"2024-06-01T17:52:22.410157Z"}]}
{"channel":"book","type":"update","data":[{"symbol":"BCH/JPY","bids":[{"price":72300,"qty":0.00000000},{"price":71398,"qty":3.78585540}],"asks":[],"checksum":931084860,"timestamp":"2024-06-01T17:52:22.410210Z"}]}
{"channel":"book","type":"update","data":[{"symbol":"BCH/JPY","bids":[],"asks":[{"price":72680,"qty":0.00000000},{"price":74162,"qty":0.33513317}],"checksum":1003774187,"timestamp":"2024-06-01T17:52:22.410273Z"}]}
{"channel":"book","type":"update","data":[{"symbol":"BCH/JPY","bids":[{"price":72199,"qty":0.00000000},{"price":71343,"qty":25.75977859}],"asks":[],"checksum":880528688,"timestamp":"2024-06-01T17:52:22.410285Z"}]}
{"channel":"book","type":"update","data":[{"symbol":"BCH/JPY","bids":[],"asks":[{"price":72878,"qty":0.00000000},{"price":74498,"qty":0.07053545}],"checksum":2552503037,"timestamp":"2024-06-01T17:52:22.410307Z"}]}
{"channel":"book","type":"update","data":[{"symbol":"BCH/JPY","bids":[{"price":72224,"qty":0.00000000},{"price":70532,"qty":0.04847214}],"asks":[],"checksum":348972014,"timestamp":"2024-06-01T17:52:22.410773Z"}]}
{"channel":"book","type":"update","data":[{"symbol":"BCH/JPY","bids":[],"asks":[{"price":72875,"qty":3.94789140}],"checksum":2170528265,"timestamp":"2024-06-01T17:52:22.412734Z"}]}
{"channel":"book","type":"update","data":[{"symbol":"BCH/JPY","bids":[],"asks":[{"price":72875,"qty":19.39648080}],"checksum":2717980534,"timestamp":"2024-06-01T17:52:22.412771Z"}]}
{"channel":"book","type":"update","data":[{"symbol":"BCH/JPY","bids":[],"asks":[{"price":72897,"qty":0.38039880}],"checksum":1426639193,"timestamp":"2024-06-01T17:52:22.412796Z"}]}
{"channel":"book","type":"update","data":[{"symbol":"BCH/JPY","bids":[{"price":72227,"qty":0.38039880}],"asks":[],"checksum":839313919,"timestamp":"2024-06-01T17:52:22.412815Z"}]}
{"channel":"book","type":"update","data":[{"symbol":"BCH/JPY","bids":[],"asks":[{"price":72752,"qty":0.38039880}],"checksum":1150102769,"timestamp":"2024-06-01T17:52:22.412967Z"}]}
{"channel":"book","type":"update","data":[{"symbol":"BCH/JPY","bids":[{"price":72082,"qty":0.38039880}],"asks":[],"checksum":109676797,"timestamp":"2024-06-01T17:52:22.413219Z"}]}
{"channel":"book","type":"update","data":[{"symbol":"BCH/JPY","bids":[{"price":72078,"qty":15.44858940}],"asks":[],"checksum":3378675456,"timestamp":"2024-06-01T17:52:22.413346Z"}]}
{"channel":"book","type":"update","data":[{"symbol":"BCH/JPY","bids":[],"asks":[{"price":73316,"qty":11.81242440}],"checksum":3646674493,"timestamp":"2024-06-01T17:52:22.413390Z"}]}
{"channel":"book","type":"update","data":[{"symbol":"BCH/JPY","bids":[{"price":72078,"qty":19.39648080}],"asks":[],"checksum":529816432,"timestamp":"2024-06-01T17:52:22.413654Z"}]}
{"channel":"book","type":"update","data":[{"symbol":"BCH/JPY","bids":[{"price":72301,"qty":0.00000000},{"price":71398,"qty":3.78585540}],"asks":[],"checksum":1348908856,"timestamp":"2024-06-01T17:52:22.416245Z"}]}
{"channel":"book","type":"update","data":[{"symbol":"BCH/JPY","bids":[{"price":72228,"qty":1.72259082}],"asks":[],"checksum":16319072,"timestamp":"2024-06-01T17:52:22.416320Z"}]}
{"channel":"book","type":"update","data":[{"symbol":"BCH/JPY","bids":[],"asks":[{"price":72874,"qty":2.58370377}],"checksum":4061002669,"timestamp":"2024-06-01T17:52:22.416341Z"}]}
{"channel":"book","type":"update","data":[{"symbol":"BCH/JPY","bids":[],"asks":[{"price":72876,"qty":0.00000000},{"price":73333,"qty":0.02500000}],"checksum":3912816310,"timestamp":"2024-06-01T17:52:22.416352Z"}]}
{"channel":"book","type":"update","data":[{"symbol":"BCH/JPY","bids":[],"asks":[{"price":73317,"qty":0.00000000},{"price":73663,"qty":17.78878527},{"price":73315,"qty":0.02510012}],"checksum":2995037690,"timestamp":"2024-06-01T17:52:22.417385Z"}]}
{"channel":"book","type":"update","data":[{"symbol":"BCH/JPY","bids":[],"asks":[{"price":72874,"qty":0.00000000},{"price":73663,"qty":17.78878527}],"checksum":3951665148,"timestamp":"2024-06-01T17:52:22.438214Z"}]}
{"channel":"book","type":"update","data":[{"symbol":"BCH/JPY","bids":[],"asks":[{"price":72751,"qty":2.58370377}],"checksum":2693785141,"timestamp":"2024-06-01T17:52:22.438318Z"}]}
{"channel":"book","type":"update","data":[{"symbol":"BCH/JPY","bids":[{"price":72228,"qty":0.00000000},{"price":71398,"qty":3.78585540}],"asks":[],"checksum":4027601773,"timestamp":"2024-06-01T17:52:22.547516Z"}]}
{"channel":"book","type":"update","data":[{"symbol":"BCH/JPY","bids":[{"price":72354,"qty":1.71959103}],"asks":[],"checksum":808531195,"timestamp":"2024-06-01T17:52:22.547670Z"}]}
{"channel":"book","type":"update","data":[{"symbol":"BCH/JPY","bids":[{"price":72353,"qty":0.00000000},{"price":71398,"qty":3.78585540},{"price":72364,"qty":0.32603919}],"asks":[],"checksum":369740804,"timestamp":"2024-06-01T17:52:22.557817Z"}]}
{"channel":"book","type":"update","data":[{"symbol":"BCH/JPY","bids":[{"price":72354,"qty":0.00000000},{"price":71398,"qty":3.78585540}],"asks":[],"checksum":3666749481,"timestamp":"2024-06-01T17:52:22.568109Z"}]}
{"channel":"book","type":"update","data":[{"symbol":"BCH/JPY","bids":[{"price":72365,"qty":1.71932964}],"asks":[],"checksum":849078017,"timestamp":"2024-06-01T17:52:22.568348Z"}]}
