{"channel":"book","type":"snapshot","data":[{"symbol":"BCH/GBP","bids":[{"price":361.10,"qty":1.42815290},{"price":361.07,"qty":0.27796855},{"price":360.57,"qty":1.16379371},{"price":360.56,"qty":0.51840801},{"price":360.10,"qty":1.08651483},{"price":359.97,"qty":0.02751466},{"price":358.01,"qty":1.08651483},{"price":357.97,"qty":0.72258459},{"price":357.89,"qty":15.43302236},{"price":357.74,"qty":0.35770469}],"asks":[{"price":361.81,"qty":0.27796855},{"price":361.89,"qty":15.69622891},{"price":361.94,"qty":0.10173481},{"price":361.95,"qty":4.30941607},{"price":362.15,"qty":0.02500000},{"price":362.26,"qty":0.51840801},{"price":362.55,"qty":1.08651483},{"price":362.56,"qty":3.00000000},{"price":364.04,"qty":1.08651483},{"price":364.10,"qty":0.72258459}],"checksum":1183826977}]}
{"channel":"book","type":"update","data":[{"symbol":"BCH/GBP","bids":[],"asks":[{"price":364.04,"qty":0.00000000},{"price":364.73,"qty":0.35735297}],"checksum":3585122108,"timestamp":"2024-06-01T17:51:16.882605Z"}]}
{"channel":"book","type":"update","data":[{"symbol":"BCH/GBP","bids":[{"price":358.01,"qty":0.00000000},{"price":357.39,"qty":36.68804364}],"asks":[],"checksum":3451113729,"timestamp":"2024-06-01T17:51:16.882767Z"}]}
{"channel":"book","type":"update","data":[{"symbol":"BCH/GBP","bids":[],"asks":[{"price":364.03,"qty":1.08651483}],"checksum":733241147,"timestamp":"2024-06-01T17:51:16.885463Z"}]}
{"channel":"book","type":"update","data":[{"symbol":"BCH/GBP","bids":[{"price":358.02,"qty":1.08651483}],"asks":[],"checksum":877704839,"timestamp":"2024-06-01T17:51:16.885558Z"}]}
{"channel":"book","type":"update","data":[{"symbol":"BCH/GBP","bids":[],"asks":[{"price":361.95,"qty":0.00000000},{"price":364.73,"qty":0.35735297}],"checksum":2431295206,"timestamp":"2024-06-01T17:51:23.841137Z"}]}
{"channel":"book","type":"update","data":[{"symbol":"BCH/GBP","bids":[],"asks":[{"price":362.14,"qty":2.58370377}],"checksum":1888846090,"timestamp":"2024-06-01T17:51:23.861873Z"}]}
{"channel":"book","type":"update","data":[{"symbol":"BCH/GBP","bids":[],"asks":[{"price":361.94,"qty":0.00000000},{"price":364.73,"qty":0.35735297}],"checksum":760221318,"timestamp":"2024-06-01T17:51:23.861926Z"}]}
{"channel":"book","type":"update","data":[{"symbol":"BCH/GBP","bids":[],"asks":[{"price":361.98,"qty":4.30941607}],"checksum":2813112482,"timestamp":"2024-06-01T17:51:25.062860Z"}]}
{"channel":"book","type":"update","data":[{"symbol":"BCH/GBP","bids":[],"asks":[{"price":361.97,"qty":0.10172638}],"checksum":4063614037,"timestamp":"2024-06-01T17:51:25.069263Z"}]}
{"channel":"book","type":"update","data":[{"symbol":"BCH/GBP","bids":[],"asks":[{"price":362.14,"qty":0.00000000},{"price":364.10,"qty":0.72258459}],"checksum":1644446468,"timestamp":"2024-06-01T17:51:25.069331Z"}]}
{"channel":"book","type":"update","data":[{"symbol":"BCH/GBP","bids":[{"price":361.10,"qty":0.00000000},{"price":357.42,"qty":36.68140487}],"asks":[],"checksum":3477188797,"timestamp":"2024-06-01T17:51:27.953765Z"}]}
{"channel":"book","type":"update","data":[{"symbol":"BCH/GBP","bids":[],"asks":[{"price":361.89,"qty":0.00000000},{"price":364.73,"qty":0.35735297}],"checksum":2509206350,"timestamp":"2024-06-01T17:51:27.953970Z"}]}
{"channel":"book","type":"update","data":[{"symbol":"BCH/GBP","bids":[{"price":360.58,"qty":8.31992900}],"asks":[],"checksum":2738079873,"timestamp":"2024-06-01T17:51:27.955911Z"}]}
{"channel":"book","type":"update","data":[{"symbol":"BCH/GBP","bids":[{"price":361.17,"qty":1.42784250}],"asks":[],"checksum":2959176526,"timestamp":"2024-06-01T17:51:27.957527Z"}]}
{"channel":"book","type":"update","data":[{"symbol":"BCH/GBP","bids":[],"asks":[{"price":361.89,"qty":7.70922891}],"checksum":3575961104,"timestamp":"2024-06-01T17:51:27.957673Z"}]}
{"channel":"book","type":"update","data":[{"symbol":"BCH/GBP","bids":[{"price":360.58,"qty":0.00000000},{"price":357.74,"qty":0.35770469}],"asks":[],"checksum":2217310595,"timestamp":"2024-06-01T17:51:27.959982Z"}]}
{"channel":"book","type":"update","data":[{"symbol":"BCH/GBP","bids":[],"asks":[{"price":364.03,"qty":0.00000000},{"price":364.73,"qty":0.35735297}],"checksum":1643715131,"timestamp":"2024-06-01T17:51:27.961184Z"}]}
{"channel":"book","type":"update","data":[{"symbol":"BCH/GBP","bids":[{"price":358.02,"qty":0.00000000},{"price":357.42,"qty":36.68140487}],"asks":[],"checksum":3785846037,"timestamp":"2024-06-01T17:51:27.961268Z"}]}
{"channel":"book","type":"update","data":[{"symbol":"BCH/GBP","bids":[],"asks":[{"price":364.02,"qty":1.08651483}],"checksum":331904064,"timestamp":"2024-06-01T17:51:27.964639Z"}]}
{"channel":"book","type":"update","data":[{"symbol":"BCH/GBP","bids":[{"price":358.03,"qty":1.08651483}],"asks":[],"checksum":2799629051,"timestamp":"2024-06-01T17:51:27.970009Z"}]}
{"channel":"book","type":"update","data":[{"symbol":"BCH/GBP","bids":[{"price":357.97,"qty":0.00000000},{"price":357.42,"qty":36.68140487}],"asks":[],"checksum":3704328330,"timestamp":"2024-06-01T17:51:31.593777Z"}]}
{"channel":"book","type":"update","data":[{"symbol":"BCH/GBP","bids":[{"price":358.03,"qty":0.00000000},{"price":356.32,"qty":0.34687155}],"asks":[],"checksum":4081030826,"timestamp":"2024-06-01T17:51:31.593906Z"}]}
{"channel":"book","type":"update","data":[{"symbol":"BCH/GBP","bids":[],"asks":[{"price":364.02,"qty":0.00000000},{"price":364.73,"qty":0.35735297}],"checksum":22056959,"timestamp":"2024-06-01T17:51:31.594153Z"}]}
{"channel":"book","type":"update","data":[{"symbol":"BCH/GBP","bids":[{"price":357.98,"qty":1.08651483}],"asks":[],"checksum":764962582,"timestamp":"2024-06-01T17:51:31.596514Z"}]}
{"channel":"book","type":"update","data":[{"symbol":"BCH/GBP","bids":[{"price":357.98,"qty":1.80909942}],"asks":[],"checksum":2073066388,"timestamp":"2024-06-01T17:51:31.596667Z"}]}
{"channel":"book","type":"update","data":[{"symbol":"BCH/GBP","bids":[],"asks":[{"price":364.09,"qty":1.08651483}],"checksum":3918216595,"timestamp":"2024-06-01T17:51:31.596962Z"}]}
{"channel":"book","type":"update","data":[{"symbol":"BCH/GBP","bids":[{"price":357.42,"qty":0.00000000},{"price":356.32,"qty":0.34687155}],"asks":[],"checksum":3633114212,"timestamp":"2024-06-01T17:51:39.886659Z"}]}
{"channel":"book","type":"update","data":[{"symbol":"BCH/GBP","bids":[{"price":357.46,"qty":36.67179476}],"asks":[],"checksum":1697458171,"timestamp":"2024-06-01T17:51:39.926911Z"}]}
{"channel":"book","type":"update","data":[{"symbol":"BCH/GBP","bids":[{"price":361.17,"qty":0.00000000},{"price":356.32,"qty":0.34687155}],"asks":[],"checksum":2126715276,"timestamp":"2024-06-01T17:51:43.020173Z"}]}
{"channel":"book","type":"update","data":[{"symbol":"BCH/GBP","bids":[],"asks":[{"price":361.89,"qty":0.00000000},{"price":364.73,"qty":0.35735297}],"checksum":3292715198,"timestamp":"2024-06-01T17:51:43.020268Z"}]}
{"channel":"book","type":"update","data":[{"symbol":"BCH/GBP","bids":[{"price":360.58,"qty":8.31992900}],"asks":[],"checksum":2946893934,"timestamp":"2024-06-01T17:51:43.022544Z"}]}
{"channel":"book","type":"update","data":[{"symbol":"BCH/GBP","bids":[{"price":361.17,"qty":1.42784250}],"asks":[],"checksum":278073341,"timestamp":"2024-06-01T17:51:43.025272Z"}]}
{"channel":"book","type":"update","data":[{"symbol":"BCH/GBP","bids":[{"price":360.58,"qty":0.00000000},{"price":357.46,"qty":36.67179476}],"asks":[],"checksum":2906716090,"timestamp":"2024-06-01T17:51:43.027350Z"}]}
{"channel":"book","type":"update","data":[{"symbol":"BCH/GBP","bids":[],"asks":[{"price":361.89,"qty":5.53722891}],"checksum":2876539034,"timestamp":"2024-06-01T17:51:43.027381Z"}]}
{"channel":"book","type":"update","data":[{"symbol":"BCH/GBP","bids":[],"asks":[{"price":364.09,"qty":0.00000000},{"price":364.73,"qty":0.35735297}],"checksum":3480592267,"timestamp":"2024-06-01T17:51:43.364315Z"}]}
{"channel":"book","type":"update","data":[{"symbol":"BCH/GBP","bids":[{"price":357.98,"qty":0.72258459}],"asks":[],"checksum":3366967895,"timestamp":"2024-06-01T17:51:43.364436Z"}]}
{"channel":"book","type":"update","data":[{"symbol":"BCH/GBP","bids":[],"asks":[{"price":364.08,"qty":1.08651483}],"checksum":2502490566,"timestamp":"2024-06-01T17:51:43.367106Z"}]}
{"channel":"book","type":"update","data":[{"symbol":"BCH/GBP","bids":[{"price":357.99,"qty":1.08651483}],"asks":[],"checksum":775964514,"timestamp":"2024-06-01T17:51:43.367352Z"}]}
{"channel":"book","type":"update","data":[{"symbol":"BCH/GBP","bids":[],"asks":[{"price":361.98,"qty":0.00000000},{"price":364.73,"qty":0.35735297}],"checksum":2484930452,"timestamp":"2024-06-01T17:51:43.816585Z"}]}
{"channel":"book","type":"update","data":[{"symbol":"BCH/GBP","bids":[],"asks":[{"price":361.97,"qty":0.00000000},{"price":364.82,"qty":0.02511149}],"checksum":930007092,"timestamp":"2024-06-01T17:51:43.830213Z"}]}
{"channel":"book","type":"update","data":[{"symbol":"BCH/GBP","bids":[],"asks":[{"price":362.14,"qty":2.58370377}],"checksum":3096524087,"timestamp":"2024-06-01T17:51:43.830303Z"}]}
{"channel":"book","type":"update","data":[{"symbol":"BCH/GBP","bids":[],"asks":[{"price":362.14,"qty":0.00000000},{"price":364.82,"qty":0.02511149}],"checksum":930007092,"timestamp":"2024-06-01T17:51:43.929366Z"}]}
{"channel":"book","type":"update","data":[{"symbol":"BCH/GBP","bids":[],"asks":[{"price":362.14,"qty":2.52312141}],"checksum":3752824222,"timestamp":"2024-06-01T17:51:43.929560Z"}]}
{"channel":"book","type":"update","data":[{"symbol":"BCH/GBP","bids":[],"asks":[{"price":364.08,"qty":0.00000000},{"price":364.82,"qty":0.02511149}],"checksum":2719235217,"timestamp":"2024-06-01T17:51:49.247517Z"}]}
{"channel":"book","type":"update","data":[{"symbol":"BCH/GBP","bids":[],"asks":[{"price":364.09,"qty":1.08651483}],"checksum":1248355598,"timestamp":"2024-06-01T17:51:49.250343Z"}]}
{"channel":"book","type":"update","data":[{"symbol":"BCH/GBP","bids":[{"price":360.56,"qty":0.00000000},{"price":357.46,"qty":36.67179476}],"asks":[],"checksum":2682437227,"timestamp":"2024-06-01T17:51:55.131874Z"}]}
{"channel":"book","type":"update","data":[{"symbol":"BCH/GBP","bids":[{"price":357.99,"qty":0.00000000},{"price":356.32,"qty":0.34687155}],"asks":[],"checksum":1755460921,"timestamp":"2024-06-01T17:51:55.132041Z"}]}
{"channel":"book","type":"update","data":[{"symbol":"BCH/GBP","bids":[{"price":360.10,"qty":0.00000000},{"price":356.01,"qty":0.55086523}],"asks":[],"checksum":1862430299,"timestamp":"2024-06-01T17:51:55.132163Z"}]}
{"channel":"book","type":"update","data":[{"symbol":"BCH/GBP","bids":[{"price":357.98,"qty":0.00000000},{"price":352.09,"qty":0.07640141}],"asks":[],"checksum":2920129009,"timestamp":"2024-06-01T17:51:55.132428Z"}]}
{"channel":"book","type":"update","data":[{"symbol":"BCH/GBP","bids":[{"price":360.58,"qty":0.51840801}],"asks":[],"checksum":4053609934,"timestamp":"2024-06-01T17:51:55.134584Z"}]}
{"channel":"book","type":"update","data":[{"symbol":"BCH/GBP","bids":[{"price":358.00,"qty":1.08651483}],"asks":[],"checksum":3008025333,"timestamp":"2024-06-01T17:51:55.134996Z"}]}
{"channel":"book","type":"update","data":[{"symbol":"BCH/GBP","bids":[{"price":360.11,"qty":1.08651483}],"asks":[],"checksum":692359435,"timestamp":"2024-06-01T17:51:55.135006Z"}]}
{"channel":"book","type":"update","data":[{"symbol":"BCH/GBP","bids":[{"price":358.00,"qty":1.80909942}],"asks":[],"checksum":2135723401,"timestamp":"2024-06-01T17:51:55.135449Z"}]}
{"channel":"book","type":"update","data":[{"symbol":"BCH/GBP","bids":[{"price":360.57,"qty":0.00000000},{"price":356.32,"qty":0.34687155}],"asks":[],"checksum":4235079038,"timestamp":"2024-06-01T17:51:55.166836Z"}]}
{"channel":"book","type":"update","data":[{"symbol":"BCH/GBP","bids":[{"price":361.08,"qty":1.16215015}],"asks":[],"checksum":1653788975,"timestamp":"2024-06-01T17:51:55.166892Z"}]}
{"channel":"book","type":"update","data":[{"symbol":"BCH/GBP","bids":[{"price":360.59,"qty":1.16372916}],"asks":[],"checksum":2949253340,"timestamp":"2024-06-01T17:51:56.264335Z"}]}
{"channel":"book","type":"update","data":[{"symbol":"BCH/GBP","bids":[{"price":361.08,"qty":0.00000000},{"price":357.46,"qty":36.67179476}],"asks":[],"checksum":407046303,"timestamp":"2024-06-01T17:51:56.265414Z"}]}
{"channel":"book","type":"update","data":[{"symbol":"BCH/GBP","bids":[{"price":361.17,"qty":0.00000000},{"price":356.32,"qty":0.34687155}],"asks":[],"checksum":484195968,"timestamp":"2024-06-01T17:51:58.153370Z"}]}
{"channel":"book","type":"update","data":[{"symbol":"BCH/GBP","bids":[{"price":360.60,"qty":8.31946755}],"asks":[],"checksum":2212443367,"timestamp":"2024-06-01T17:51:58.155526Z"}]}
{"channel":"book","type":"update","data":[{"symbol":"BCH/GBP","bids":[],"asks":[{"price":361.89,"qty":0.00000000},{"price":364.82,"qty":0.02511149}],"checksum":185563342,"timestamp":"2024-06-01T17:51:58.155741Z"}]}
{"channel":"book","type":"update","data":[{"symbol":"BCH/GBP","bids":[{"price":361.17,"qty":1.42784250}],"asks":[],"checksum":1779177603,"timestamp":"2024-06-01T17:51:58.158225Z"}]}
{"channel":"book","type":"update","data":[{"symbol":"BCH/GBP","bids":[{"price":360.60,"qty":0.00000000},{"price":357.46,"qty":36.67179476}],"asks":[],"checksum":2425570486,"timestamp":"2024-06-01T17:51:58.160383Z"}]}
{"channel":"book","type":"update","data":[{"symbol":"BCH/GBP","bids":[],"asks":[{"price":361.89,"qty":0.44972891}],"checksum":542294123,"timestamp":"2024-06-01T17:51:58.160813Z"}]}
{"channel":"book","type":"update","data":[{"symbol":"BCH/GBP","bids":[{"price":360.59,"qty":0.00000000},{"price":356.32,"qty":0.34687155}],"asks":[],"checksum":895753692,"timestamp":"2024-06-01T17:51:58.163181Z"}]}
{"channel":"book","type":"update","data":[{"symbol":"BCH/GBP","bids":[{"price":360.61,"qty":1.16366474}],"asks":[],"checksum":1149537560,"timestamp":"2024-06-01T17:51:58.163264Z"}]}
{"channel":"book","type":"update","data":[{"symbol":"BCH/GBP","bids":[{"price":357.46,"qty":0.00000000},{"price":356.32,"qty":0.34687155}],"asks":[],"checksum":835370100,"timestamp":"2024-06-01T17:51:59.156174Z"}]}
{"channel":"book","type":"update","data":[{"symbol":"BCH/GBP","bids":[{"price":357.51,"qty":36.65844848}],"asks":[],"checksum":919581112,"timestamp":"2024-06-01T17:51:59.196462Z"}]}
{"channel":"book","type":"update","data":[{"symbol":"BCH/GBP","bids":[],"asks":[{"price":362.14,"qty":0.00000000},{"price":364.82,"qty":0.02511149}],"checksum":405254710,"timestamp":"2024-06-01T17:52:00.151550Z"}]}
{"channel":"book","type":"update","data":[{"symbol":"BCH/GBP","bids":[],"asks":[{"price":362.14,"qty":2.58370377}],"checksum":2360404632,"timestamp":"2024-06-01T17:52:00.151731Z"}]}
{"channel":"book","type":"update","data":[{"symbol":"BCH/GBP","bids":[{"price":358.00,"qty":1.08651483}],"asks":[],"checksum":3669554714,"timestamp":"2024-06-01T17:52:01.016386Z"}]}
{"channel":"book","type":"update","data":[{"symbol":"BCH/GBP","bids":[{"price":360.11,"qty":0.00000000},{"price":356.32,"qty":0.34687155}],"asks":[],"checksum":3219484744,"timestamp":"2024-06-01T17:52:01.016445Z"}]}
{"channel":"book","type":"update","data":[{"symbol":"BCH/GBP","bids":[],"asks":[{"price":364.09,"qty":0.00000000},{"price":364.82,"qty":0.02511149}],"checksum":4240023116,"timestamp":"2024-06-01T17:52:01.016591Z"}]}
{"channel":"book","type":"update","data":[{"symbol":"BCH/GBP","bids":[{"price":360.58,"qty":0.00000000},{"price":356.01,"qty":0.55086523}],"asks":[],"checksum":1495781193,"timestamp":"2024-06-01T17:52:01.016645Z"}]}
{"channel":"book","type":"update","data":[{"symbol":"BCH/GBP","bids":[{"price":358.00,"qty":0.00000000},{"price":352.09,"qty":0.07640141}],"asks":[],"checksum":2642006254,"timestamp":"2024-06-01T17:52:01.016790Z"}]}
{"channel":"book","type":"update","data":[{"symbol":"BCH/GBP","bids":[{"price":360.61,"qty":1.68207275}],"asks":[],"checksum":2437199937,"timestamp":"2024-06-01T17:52:01.019232Z"}]}
{"channel":"book","type":"update","data":[{"symbol":"BCH/GBP","bids":[{"price":360.12,"qty":1.08651483}],"asks":[],"checksum":3146289211,"timestamp":"2024-06-01T17:52:01.019285Z"}]}
{"channel":"book","type":"update","data":[{"symbol":"BCH/GBP","bids":[{"price":358.01,"qty":0.72258459}],"asks":[],"checksum":504928186,"timestamp":"2024-06-01T17:52:01.019392Z"}]}
{"channel":"book","type":"update","data":[{"symbol":"BCH/GBP","bids":[],"asks":[{"price":364.08,"qty":1.08651483}],"checksum":2917018898,"timestamp":"2024-06-01T17:52:01.019475Z"}]}
{"channel":"book","type":"update","data":[{"symbol":"BCH/GBP","bids":[{"price":358.01,"qty":1.80909942}],"asks":[],"checksum":2314938156,"timestamp":"2024-06-01T17:52:01.019513Z"}]}
{"channel":"book","type":"update","data":[{"symbol":"BCH/GBP","bids":[{"price":361.08,"qty":1.16215000}],"asks":[],"checksum":705152063,"timestamp":"2024-06-01T17:52:01.027067Z"}]}
{"channel":"book","type":"update","data":[{"symbol":"BCH/GBP","bids":[{"price":360.61,"qty":0.51840801}],"asks":[],"checksum":483937763,"timestamp":"2024-06-01T17:52:01.027160Z"}]}
{"channel":"book","type":"update","data":[{"symbol":"BCH/GBP","bids":[],"asks":[{"price":361.89,"qty":0.00000000},{"price":364.82,"qty":0.02511149}],"checksum":3447152932,"timestamp":"2024-06-01T17:52:03.199226Z"}]}
{"channel":"book","type":"update","data":[{"symbol":"BCH/GBP","bids":[],"asks":[{"price":364.08,"qty":0.00000000},{"price":365.99,"qty":0.35735297}],"checksum":1476160927,"timestamp":"2024-06-01T17:52:03.199918Z"}]}
{"channel":"book","type":"update","data":[{"symbol":"BCH/GBP","bids":[{"price":358.01,"qty":0.72258459}],"asks":[],"checksum":2909629299,"timestamp":"2024-06-01T17:52:03.200041Z"}]}
{"channel":"book","type":"update","data":[{"symbol":"BCH/GBP","bids":[{"price":360.12,"qty":0.00000000},{"price":356.32,"qty":0.34687155}],"asks":[],"checksum":1969115469,"timestamp":"2024-06-01T17:52:03.200054Z"}]}
{"channel":"book","type":"update","data":[{"symbol":"BCH/GBP","bids":[{"price":358.01,"qty":0.00000000},{"price":356.01,"qty":0.55086523}],"asks":[],"checksum":3503183564,"timestamp":"2024-06-01T17:52:03.200080Z"}]}
{"channel":"book","type":"update","data":[{"symbol":"BCH/GBP","bids":[],"asks":[{"price":361.81,"qty":0.00000000},{"price":366.00,"qty":0.02500000}],"checksum":2115668136,"timestamp":"2024-06-01T17:52:03.200166Z"}]}
{"channel":"book","type":"update","data":[{"symbol":"BCH/GBP","bids":[{"price":359.98,"qty":1.08651483}],"asks":[],"checksum":3931216863,"timestamp":"2024-06-01T17:52:03.202762Z"}]}
{"channel":"book","type":"update","data":[{"symbol":"BCH/GBP","bids":[],"asks":[{"price":364.09,"qty":1.08651483}],"checksum":2863752410,"timestamp":"2024-06-01T17:52:03.202808Z"}]}
{"channel":"book","type":"update","data":[{"symbol":"BCH/GBP","bids":[{"price":357.90,"qty":1.08651483}],"asks":[],"checksum":930752153,"timestamp":"2024-06-01T17:52:03.202857Z"}]}
{"channel":"book","type":"update","data":[{"symbol":"BCH/GBP","bids":[{"price":357.90,"qty":1.80909942}],"asks":[],"checksum":1634875931,"timestamp":"2024-06-01T17:52:03.203082Z"}]}
{"channel":"book","type":"update","data":[{"symbol":"BCH/GBP","bids":[],"asks":[{"price":361.99,"qty":0.27796855}],"checksum":2871239003,"timestamp":"2024-06-01T17:52:03.203198Z"}]}
{"channel":"book","type":"update","data":[{"symbol":"BCH/GBP","bids":[{"price":360.61,"qty":0.00000000},{"price":356.32,"qty":0.34687155}],"asks":[],"checksum":2690746694,"timestamp":"2024-06-01T17:52:03.203573Z"}]}
{"channel":"book","type":"update","data":[{"symbol":"BCH/GBP","bids":[{"price":361.07,"qty":0.00000000},{"price":356.01,"qty":0.55086523}],"asks":[],"checksum":3264980755,"timestamp":"2024-06-01T17:52:03.203845Z"}]}
{"channel":"book","type":"update","data":[{"symbol":"BCH/GBP","bids":[],"asks":[{"price":361.97,"qty":2.88347891}],"checksum":3526352557,"timestamp":"2024-06-01T17:52:03.204694Z"}]}
{"channel":"book","type":"update","data":[{"symbol":"BCH/GBP","bids":[{"price":360.62,"qty":0.51840801}],"asks":[],"checksum":2352550459,"timestamp":"2024-06-01T17:52:03.206465Z"}]}
{"channel":"book","type":"update","data":[{"symbol":"BCH/GBP","bids":[{"price":361.24,"qty":0.27796855}],"asks":[],"checksum":1058069116,"timestamp":"2024-06-01T17:52:03.206544Z"}]}
{"channel":"book","type":"update","data":[{"symbol":"BCH/GBP","bids":[{"price":360.63,"qty":1.16360014}],"asks":[],"checksum":612359648,"timestamp":"2024-06-01T17:52:03.214086Z"}]}
{"channel":"book","type":"update","data":[{"symbol":"BCH/GBP","bids":[],"asks":[{"price":362.14,"qty":0.00000000},{"price":364.98,"qty":0.02511146}],"checksum":495330588,"timestamp":"2024-06-01T17:52:03.214102Z"}]}
{"channel":"book","type":"update","data":[{"symbol":"BCH/GBP","bids":[{"price":361.08,"qty":0.00000000},{"price":357.51,"qty":36.65844848}],"asks":[],"checksum":391828821,"timestamp":"2024-06-01T17:52:03.214247Z"}]}
{"channel":"book","type":"update","data":[{"symbol":"BCH/GBP","bids":[],"asks":[{"price":361.96,"qty":0.10172918}],"checksum":2476521433,"timestamp":"2024-06-01T17:52:03.214476Z"}]}
{"channel":"book","type":"update","data":[{"symbol":"BCH/GBP","bids":[],"asks":[{"price":362.14,"qty":4.30941607}],"checksum":769532979,"timestamp":"2024-06-01T17:52:03.560161Z"}]}
{"channel":"book","type":"update","data":[{"symbol":"BCH/GBP","bids":[{"price":360.63,"qty":0.00000000},{"price":356.32,"qty":0.34687155}],"asks":[],"checksum":3009792068,"timestamp":"2024-06-01T17:52:03.560322Z"}]}
{"channel":"book","type":"update","data":[{"symbol":"BCH/GBP","bids":[{"price":361.25,"qty":1.16160311}],"asks":[],"checksum":3787800733,"timestamp":"2024-06-01T17:52:03.560507Z"}]}
{"channel":"book","type":"update","data":[{"symbol":"BCH/GBP","bids":[{"price":361.25,"qty":0.00000000},{"price":356.32,"qty":0.34687155}],"asks":[],"checksum":3009792068,"timestamp":"2024-06-01T17:52:04.556942Z"}]}
{"channel":"book","type":"update","data":[{"symbol":"BCH/GBP","bids":[{"price":360.63,"qty":1.16360033}],"asks":[],"checksum":1798075307,"timestamp":"2024-06-01T17:52:04.557042Z"}]}
{"channel":"book","type":"update","data":[{"symbol":"BCH/GBP","bids":[{"price":361.25,"qty":0.76000000}],"asks":[],"checksum":1191277190,"timestamp":"2024-06-01T17:52:04.652778Z"}]}
{"channel":"book","type":"update","data":[{"symbol":"BCH/GBP","bids":[{"price":360.63,"qty":0.00000000},{"price":357.51,"qty":36.65844848}],"asks":[],"checksum":1020923866,"timestamp":"2024-06-01T17:52:04.652871Z"}]}
{"channel":"book","type":"update","data":[{"symbol":"BCH/GBP","bids":[{"price":361.25,"qty":0.00000000},{"price":356.32,"qty":0.34687155}],"asks":[],"checksum":3009792068,"timestamp":"2024-06-01T17:52:05.210882Z"}]}
{"channel":"book","type":"update","data":[{"symbol":"BCH/GBP","bids":[{"price":360.63,"qty":1.16360022}],"asks":[],"checksum":1952203757,"timestamp":"2024-06-01T17:52:05.210952Z"}]}
{"channel":"book","type":"update","data":[{"symbol":"BCH/GBP","bids":[{"price":359.98,"qty":0.00000000},{"price":356.32,"qty":0.34687155}],"asks":[],"checksum":2256316366,"timestamp":"2024-06-01T17:52:06.901131Z"}]}
{"channel":"book","type":"update","data":[{"symbol":"BCH/GBP","bids":[{"price":359.99,"qty":1.08651483}],"asks":[],"checksum":1067791548,"timestamp":"2024-06-01T17:52:06.903836Z"}]}
{"channel":"book","type":"update","data":[{"symbol":"BCH/GBP","bids":[{"price":357.90,"qty":0.72258459}],"asks":[],"checksum":696758433,"timestamp":"2024-06-01T17:52:12.785254Z"}]}
{"channel":"book","type":"update","data":[{"symbol":"BCH/GBP","bids":[{"price":357.90,"qty":0.00000000},{"price":356.32,"qty":0.34687155}],"asks":[],"checksum":2739326370,"timestamp":"2024-06-01T17:52:12.785279Z"}]}
{"channel":"book","type":"update","data":[{"symbol":"BCH/GBP","bids":[],"asks":[{"price":364.09,"qty":0.00000000},{"price":364.73,"qty":0.35735297}],"checksum":4074727416,"timestamp":"2024-06-01T17:52:12.785292Z"}]}
{"channel":"book","type":"update","data":[{"symbol":"BCH/GBP","bids":[{"price":359.99,"qty":0.00000000},{"price":356.01,"qty":0.55086523}],"asks":[],"checksum":2253293413,"timestamp":"2024-06-01T17:52:12.785435Z"}]}
{"channel":"book","type":"update","data":[{"symbol":"BCH/GBP","bids":[{"price":360.62,"qty":0.00000000},{"price":352.09,"qty":0.07640141}],"asks":[],"checksum":801505197,"timestamp":"2024-06-01T17:52:12.785605Z"}]}
{"channel":"book","type":"update","data":[{"symbol":"BCH/GBP","bids":[{"price":357.91,"qty":0.72258459}],"asks":[],"checksum":4075207380,"timestamp":"2024-06-01T17:52:12.788062Z"}]}
{"channel":"book","type":"update","data":[{"symbol":"BCH/GBP","bids":[],"asks":[{"price":364.08,"qty":1.08651483}],"checksum":1569038862,"timestamp":"2024-06-01T17:52:12.788230Z"}]}
{"channel":"book","type":"update","data":[{"symbol":"BCH/GBP","bids":[{"price":357.91,"qty":1.80909942}],"asks":[],"checksum":140566180,"timestamp":"2024-06-01T17:52:12.788246Z"}]}
{"channel":"book","type":"update","data":[{"symbol":"BCH/GBP","bids":[{"price":359.98,"qty":1.08651483}],"asks":[],"checksum":3851262044,"timestamp":"2024-06-01T17:52:12.788291Z"}]}
{"channel":"book","type":"update","data":[{"symbol":"BCH/GBP","bids":[{"price":360.63,"qty":1.68200823}],"asks":[],"checksum":593227893,"timestamp":"2024-06-01T17:52:12.788522Z"}]}
{"channel":"book","type":"update","data":[{"symbol":"BCH/GBP","bids":[{"price":360.63,"qty":0.51840801}],"asks":[],"checksum":319535062,"timestamp":"2024-06-01T17:52:15.623877Z"}]}
{"channel":"book","type":"update","data":[{"symbol":"BCH/GBP","bids":[{"price":361.25,"qty":1.16160311}],"asks":[],"checksum":1817438221,"timestamp":"2024-06-01T17:52:15.624078Z"}]}
{"channel":"book","type":"update","data":[{"symbol":"BCH/GBP","bids":[{"price":361.17,"qty":0.00000000},{"price":356.32,"qty":0.34687155}],"asks":[],"checksum":1089879075,"timestamp":"2024-06-01T17:52:15.626788Z"}]}
{"channel":"book","type":"update","data":[{"symbol":"BCH/GBP","bids":[{"price":361.25,"qty":3.37621070}],"asks":[],"checksum":3377036604,"timestamp":"2024-06-01T17:52:15.629646Z"}]}
{"channel":"book","type":"update","data":[{"symbol":"BCH/GBP","bids":[{"price":361.25,"qty":2.21460759}],"asks":[],"checksum":134010447,"timestamp":"2024-06-01T17:52:17.361333Z"}]}
{"channel":"book","type":"update","data":[{"symbol":"BCH/GBP","bids":[{"price":360.64,"qty":1.16356806}],"asks":[],"checksum":1219253056,"timestamp":"2024-06-01T17:52:17.361614Z"}]}
{"channel":"book","type":"update","data":[{"symbol":"BCH/GBP","bids":[],"asks":[{"price":364.08,"qty":0.00000000},{"price":364.73,"qty":0.35735297}],"checksum":538397152,"timestamp":"2024-06-01T17:52:18.669490Z"}]}
{"channel":"book","type":"update","data":[{"symbol":"BCH/GBP","bids":[{"price":359.98,"qty":0.00000000},{"price":356.32,"qty":0.34687155}],"asks":[],"checksum":855953962,"timestamp":"2024-06-01T17:52:18.669695Z"}]}
{"channel":"book","type":"update","data":[{"symbol":"BCH/GBP","bids":[{"price":360.63,"qty":0.00000000},{"price":356.01,"qty":0.55086523}],"asks":[],"checksum":60333901,"timestamp":"2024-06-01T17:52:18.669828Z"}]}
{"channel":"book","type":"update","data":[{"symbol":"BCH/GBP","bids":[{"price":357.91,"qty":1.08651483}],"asks":[],"checksum":4039717823,"timestamp":"2024-06-01T17:52:18.669838Z"}]}
{"channel":"book","type":"update","data":[{"symbol":"BCH/GBP","bids":[{"price":357.91,"qty":0.00000000},{"price":352.09,"qty":0.07640141}],"asks":[],"checksum":23665139,"timestamp":"2024-06-01T17:52:18.669847Z"}]}
{"channel":"book","type":"update","data":[{"symbol":"BCH/GBP","bids":[],"asks":[{"price":364.07,"qty":1.08651483}],"checksum":3705228916,"timestamp":"2024-06-01T17:52:18.672347Z"}]}
{"channel":"book","type":"update","data":[{"symbol":"BCH/GBP","bids":[{"price":359.99,"qty":1.08651483}],"asks":[],"checksum":4231119799,"timestamp":"2024-06-01T17:52:18.672424Z"}]}
{"channel":"book","type":"update","data":[{"symbol":"BCH/GBP","bids":[{"price":357.92,"qty":0.72258459}],"asks":[],"checksum":3453451317,"timestamp":"2024-06-01T17:52:18.672662Z"}]}
{"channel":"book","type":"update","data":[{"symbol":"BCH/GBP","bids":[{"price":357.92,"qty":1.80909942}],"asks":[],"checksum":747739926,"timestamp":"2024-06-01T17:52:18.672784Z"}]}
{"channel":"book","type":"update","data":[{"symbol":"BCH/GBP","bids":[{"price":360.64,"qty":1.68197607}],"asks":[],"checksum":2798085434,"timestamp":"2024-06-01T17:52:18.672807Z"}]}
{"channel":"book","type":"update","data":[{"symbol":"BCH/GBP","bids":[{"price":360.64,"qty":0.51840801}],"asks":[],"checksum":1580115774,"timestamp":"2024-06-01T17:52:18.675889Z"}]}
{"channel":"book","type":"update","data":[{"symbol":"BCH/GBP","bids":[{"price":360.00,"qty":1.16563663}],"asks":[],"checksum":1811487526,"timestamp":"2024-06-01T17:52:18.676002Z"}]}
{"channel":"book","type":"update","data":[{"symbol":"BCH/GBP","bids":[{"price":360.65,"qty":1.16353562}],"asks":[],"checksum":4005190188,"timestamp":"2024-06-01T17:52:18.697168Z"}]}
{"channel":"book","type":"update","data":[{"symbol":"BCH/GBP","bids":[{"price":360.00,"qty":0.00000000},{"price":357.51,"qty":36.65844848}],"asks":[],"checksum":2997951951,"timestamp":"2024-06-01T17:52:18.697201Z"}]}
{"channel":"book","type":"update","data":[{"symbol":"BCH/GBP","bids":[],"asks":[{"price":362.14,"qty":0.00000000},{"price":364.73,"qty":0.35735297}],"checksum":3141099246,"timestamp":"2024-06-01T17:52:18.964391Z"}]}
{"channel":"book","type":"update","data":[{"symbol":"BCH/GBP","bids":[],"asks":[{"price":361.97,"qty":0.00000000},{"price":364.97,"qty":0.02511077}],"checksum":1630839048,"timestamp":"2024-06-01T17:52:18.965666Z"}]}
