{"channel":"book","type":"snapshot","data":[{"symbol":"BCH/USD","bids":[{"price":460.74,"qty":0.60000000},{"price":460.71,"qty":0.46843387},{"price":460.69,"qty":6.30780540},{"price":460.67,"qty":10.85068578},{"price":460.65,"qty":0.45000000},{"price":460.64,"qty":10.85070170},{"price":460.62,"qty":7.83392088},{"price":460.61,"qty":0.88120000},{"price":460.60,"qty":0.13918988},{"price":460.57,"qty":1.55700000}],"asks":[{"price":460.75,"qty":0.04659451},{"price":460.83,"qty":0.05516446},{"price":460.93,"qty":0.60000000},{"price":460.94,"qty":1.87946956},{"price":460.95,"qty":0.88120000},{"price":460.97,"qty":5.42336381},{"price":460.98,"qty":2.53908177},{"price":461.00,"qty":0.88120000},{"price":461.07,"qty":0.14726888},{"price":461.08,"qty":0.88120000}],"checksum":1022616518}]}
{"channel":"book","type":"update","data":[{"symbol":"BCH/USD","bids":[{"price":460.74,"qty":1.48120000}],"asks":[],"checksum":2485550316,"timestamp":"2024-06-01T17:51:21.105219Z"}]}
{"channel":"book","type":"update","data":[{"symbol":"BCH/USD","bids":[{"price":460.74,"qty":2.36240000}],"asks":[],"checksum":1404172874,"timestamp":"2024-06-01T17:51:21.363638Z"}]}
{"channel":"book","type":"update","data":[{"symbol":"BCH/USD","bids":[{"price":460.68,"qty":10.85068578}],"asks":[],"checksum":1132054434,"timestamp":"2024-06-01T17:51:23.778123Z"}]}
{"channel":"book","type":"update","data":[{"symbol":"BCH/USD","bids":[{"price":460.71,"qty":11.31911965}],"asks":[],"checksum":2225224876,"timestamp":"2024-06-01T17:51:23.780137Z"}]}
{"channel":"book","type":"update","data":[{"symbol":"BCH/USD","bids":[{"price":460.64,"qty":0.00000000},{"price":460.57,"qty":1.55700000}],"asks":[],"checksum":456121055,"timestamp":"2024-06-01T17:51:23.796231Z"}]}
{"channel":"book","type":"update","data":[{"symbol":"BCH/USD","bids":[{"price":460.68,"qty":0.00000000},{"price":460.54,"qty":1.74911741}],"asks":[],"checksum":2292729251,"timestamp":"2024-06-01T17:51:23.807928Z"}]}
{"channel":"book","type":"update","data":[{"symbol":"BCH/USD","bids":[],"asks":[{"price":460.95,"qty":0.00000000},{"price":461.12,"qty":7.07000000}],"checksum":3961442095,"timestamp":"2024-06-01T17:51:23.809744Z"}]}
{"channel":"book","type":"update","data":[{"symbol":"BCH/USD","bids":[],"asks":[{"price":460.97,"qty":0.00000000},{"price":461.15,"qty":10.84257314}],"checksum":3853680825,"timestamp":"2024-06-01T17:51:23.822452Z"}]}
{"channel":"book","type":"update","data":[{"symbol":"BCH/USD","bids":[],"asks":[{"price":461.01,"qty":5.42291621}],"checksum":907298385,"timestamp":"2024-06-01T17:51:23.827130Z"}]}
{"channel":"book","type":"update","data":[{"symbol":"BCH/USD","bids":[],"asks":[{"price":461.12,"qty":0.00000000},{"price":461.15,"qty":10.84257314}],"checksum":1642132826,"timestamp":"2024-06-01T17:51:23.841885Z"}]}
{"channel":"book","type":"update","data":[{"symbol":"BCH/USD","bids":[],"asks":[{"price":461.07,"qty":0.00000000},{"price":461.17,"qty":0.88120000}],"checksum":4264919808,"timestamp":"2024-06-01T17:51:23.859404Z"}]}
{"channel":"book","type":"update","data":[{"symbol":"BCH/USD","bids":[{"price":460.69,"qty":0.88120000}],"asks":[],"checksum":2645691310,"timestamp":"2024-06-01T17:51:23.860051Z"}]}
{"channel":"book","type":"update","data":[{"symbol":"BCH/USD","bids":[{"price":460.68,"qty":7.83392088}],"asks":[],"checksum":520187073,"timestamp":"2024-06-01T17:51:23.864199Z"}]}
{"channel":"book","type":"update","data":[{"symbol":"BCH/USD","bids":[{"price":460.74,"qty":7.78845373}],"asks":[],"checksum":518081789,"timestamp":"2024-06-01T17:51:23.864545Z"}]}
{"channel":"book","type":"update","data":[{"symbol":"BCH/USD","bids":[{"price":460.71,"qty":10.85068578}],"asks":[],"checksum":1588918898,"timestamp":"2024-06-01T17:51:23.865634Z"}]}
{"channel":"book","type":"update","data":[{"symbol":"BCH/USD","bids":[{"price":460.72,"qty":0.43395133}],"asks":[],"checksum":3718397865,"timestamp":"2024-06-01T17:51:23.866033Z"}]}
{"channel":"book","type":"update","data":[{"symbol":"BCH/USD","bids":[],"asks":[{"price":460.93,"qty":0.00000000},{"price":461.20,"qty":25.67747891}],"checksum":2651985287,"timestamp":"2024-06-01T17:51:23.867872Z"}]}
{"channel":"book","type":"update","data":[{"symbol":"BCH/USD","bids":[],"asks":[{"price":461.20,"qty":21.72000000}],"checksum":4224610025,"timestamp":"2024-06-01T17:51:23.868736Z"}]}
{"channel":"book","type":"update","data":[{"symbol":"BCH/USD","bids":[],"asks":[{"price":461.20,"qty":10.85000000}],"checksum":815561546,"timestamp":"2024-06-01T17:51:23.878311Z"}]}
{"channel":"book","type":"update","data":[{"symbol":"BCH/USD","bids":[],"asks":[{"price":461.15,"qty":0.00000000},{"price":461.22,"qty":14.62155400}],"checksum":3381273618,"timestamp":"2024-06-01T17:51:23.878507Z"}]}
{"channel":"book","type":"update","data":[{"symbol":"BCH/USD","bids":[],"asks":[{"price":461.01,"qty":0.00000000},{"price":461.25,"qty":1.53100000}],"checksum":2635474835,"timestamp":"2024-06-01T17:51:23.878565Z"}]}
{"channel":"book","type":"update","data":[{"symbol":"BCH/USD","bids":[],"asks":[{"price":461.20,"qty":0.00000000},{"price":461.27,"qty":1.12500000},{"price":461.21,"qty":10.85000000}],"checksum":2291536234,"timestamp":"2024-06-01T17:51:23.882472Z"}]}
{"channel":"book","type":"update","data":[{"symbol":"BCH/USD","bids":[],"asks":[{"price":461.23,"qty":10.84072215}],"checksum":164717046,"timestamp":"2024-06-01T17:51:23.884194Z"}]}
{"channel":"book","type":"update","data":[{"symbol":"BCH/USD","bids":[{"price":460.60,"qty":10.99457552}],"asks":[],"checksum":3146203952,"timestamp":"2024-06-01T17:51:23.884285Z"}]}
{"channel":"book","type":"update","data":[{"symbol":"BCH/USD","bids":[],"asks":[{"price":461.20,"qty":0.67572891}],"checksum":2419662889,"timestamp":"2024-06-01T17:51:23.902393Z"}]}
{"channel":"book","type":"update","data":[{"symbol":"BCH/USD","bids":[],"asks":[{"price":460.98,"qty":0.05961221}],"checksum":3363162570,"timestamp":"2024-06-01T17:51:23.948529Z"}]}
{"channel":"book","type":"update","data":[{"symbol":"BCH/USD","bids":[{"price":460.62,"qty":0.00000000},{"price":460.57,"qty":1.55700000}],"asks":[],"checksum":2475986103,"timestamp":"2024-06-01T17:51:23.952902Z"}]}
{"channel":"book","type":"update","data":[{"symbol":"BCH/USD","bids":[],"asks":[{"price":461.20,"qty":0.00000000},{"price":461.23,"qty":10.84072215}],"checksum":1289987314,"timestamp":"2024-06-01T17:51:24.051899Z"}]}
{"channel":"book","type":"update","data":[{"symbol":"BCH/USD","bids":[],"asks":[{"price":461.22,"qty":21.69155400}],"checksum":4058215560,"timestamp":"2024-06-01T17:51:24.060655Z"}]}
{"channel":"book","type":"update","data":[{"symbol":"BCH/USD","bids":[],"asks":[{"price":461.00,"qty":0.00000000},{"price":461.25,"qty":1.53100000}],"checksum":2831131466,"timestamp":"2024-06-01T17:51:24.062054Z"}]}
{"channel":"book","type":"update","data":[{"symbol":"BCH/USD","bids":[{"price":460.72,"qty":0.00000000},{"price":460.54,"qty":1.74911741}],"asks":[],"checksum":2882256540,"timestamp":"2024-06-01T17:51:24.065839Z"}]}
{"channel":"book","type":"update","data":[{"symbol":"BCH/USD","bids":[],"asks":[{"price":461.09,"qty":0.14726888}],"checksum":1322063598,"timestamp":"2024-06-01T17:51:24.407773Z"}]}
{"channel":"book","type":"update","data":[{"symbol":"BCH/USD","bids":[{"price":460.57,"qty":0.00000000},{"price":460.50,"qty":13.74035400}],"asks":[],"checksum":563341828,"timestamp":"2024-06-01T17:51:24.501907Z"}]}
{"channel":"book","type":"update","data":[{"symbol":"BCH/USD","bids":[{"price":460.63,"qty":1.49800000}],"asks":[],"checksum":2760112413,"timestamp":"2024-06-01T17:51:24.504351Z"}]}
{"channel":"book","type":"update","data":[{"symbol":"BCH/USD","bids":[{"price":460.70,"qty":0.46844404}],"asks":[],"checksum":3999094625,"timestamp":"2024-06-01T17:51:24.602627Z"}]}
{"channel":"book","type":"update","data":[{"symbol":"BCH/USD","bids":[{"price":460.60,"qty":10.85538564}],"asks":[],"checksum":996605230,"timestamp":"2024-06-01T17:51:24.801938Z"}]}
{"channel":"book","type":"update","data":[{"symbol":"BCH/USD","bids":[{"price":460.60,"qty":11.25950868}],"asks":[],"checksum":2172991465,"timestamp":"2024-06-01T17:51:24.804817Z"}]}
{"channel":"book","type":"update","data":[{"symbol":"BCH/USD","bids":[{"price":460.70,"qty":0.00000000},{"price":460.54,"qty":1.74911741}],"asks":[],"checksum":2210853755,"timestamp":"2024-06-01T17:51:24.825246Z"}]}
{"channel":"book","type":"update","data":[{"symbol":"BCH/USD","bids":[],"asks":[{"price":461.09,"qty":0.00000000},{"price":461.25,"qty":1.53100000}],"checksum":1723882249,"timestamp":"2024-06-01T17:51:24.827066Z"}]}
{"channel":"book","type":"update","data":[{"symbol":"BCH/USD","bids":[],"asks":[{"price":461.12,"qty":7.07000000}],"checksum":3758887695,"timestamp":"2024-06-01T17:51:24.830588Z"}]}
{"channel":"book","type":"update","data":[{"symbol":"BCH/USD","bids":[],"asks":[{"price":461.18,"qty":1.08600000}],"checksum":2077164750,"timestamp":"2024-06-01T17:51:24.851641Z"}]}
{"channel":"book","type":"update","data":[{"symbol":"BCH/USD","bids":[],"asks":[{"price":461.20,"qty":10.87000000}],"checksum":3746900070,"timestamp":"2024-06-01T17:51:25.087285Z"}]}
{"channel":"book","type":"update","data":[{"symbol":"BCH/USD","bids":[],"asks":[{"price":461.03,"qty":0.14726888}],"checksum":4089475693,"timestamp":"2024-06-01T17:51:25.207834Z"}]}
{"channel":"book","type":"update","data":[{"symbol":"BCH/USD","bids":[{"price":460.73,"qty":0.46841354}],"asks":[],"checksum":3072704832,"timestamp":"2024-06-01T17:51:25.213621Z"}]}
{"channel":"book","type":"update","data":[{"symbol":"BCH/USD","bids":[],"asks":[{"price":460.98,"qty":1.93908177}],"checksum":840583144,"timestamp":"2024-06-01T17:51:25.411070Z"}]}
{"channel":"book","type":"update","data":[{"symbol":"BCH/USD","bids":[],"asks":[{"price":460.95,"qty":0.88120000}],"checksum":3866870338,"timestamp":"2024-06-01T17:51:25.415366Z"}]}
{"channel":"book","type":"update","data":[{"symbol":"BCH/USD","bids":[],"asks":[{"price":461.02,"qty":5.42278407}],"checksum":239724890,"timestamp":"2024-06-01T17:51:25.435517Z"}]}
{"channel":"book","type":"update","data":[{"symbol":"BCH/USD","bids":[],"asks":[{"price":461.00,"qty":0.88120000}],"checksum":3189034015,"timestamp":"2024-06-01T17:51:25.442586Z"}]}
{"channel":"book","type":"update","data":[{"symbol":"BCH/USD","bids":[{"price":460.60,"qty":0.40412304}],"asks":[],"checksum":1947971871,"timestamp":"2024-06-01T17:51:26.745256Z"}]}
{"channel":"book","type":"update","data":[{"symbol":"BCH/USD","bids":[{"price":460.74,"qty":2.36240000}],"asks":[],"checksum":1330285406,"timestamp":"2024-06-01T17:51:26.745349Z"}]}
{"channel":"book","type":"update","data":[{"symbol":"BCH/USD","bids":[{"price":460.69,"qty":6.30772721}],"asks":[],"checksum":4016492093,"timestamp":"2024-06-01T17:51:26.750327Z"}]}
{"channel":"book","type":"update","data":[{"symbol":"BCH/USD","bids":[{"price":460.74,"qty":13.21245149}],"asks":[],"checksum":3451701972,"timestamp":"2024-06-01T17:51:27.537550Z"}]}
{"channel":"book","type":"update","data":[{"symbol":"BCH/USD","bids":[{"price":460.71,"qty":0.00000000},{"price":460.54,"qty":1.74911741}],"asks":[],"checksum":2903844349,"timestamp":"2024-06-01T17:51:27.540848Z"}]}
{"channel":"book","type":"update","data":[{"symbol":"BCH/USD","bids":[],"asks":[{"price":460.95,"qty":0.00000000},{"price":461.17,"qty":11.72335562}],"checksum":38208742,"timestamp":"2024-06-01T17:51:27.989639Z"}]}
{"channel":"book","type":"update","data":[{"symbol":"BCH/USD","bids":[],"asks":[{"price":460.95,"qty":0.88120000}],"checksum":2903844349,"timestamp":"2024-06-01T17:51:28.068333Z"}]}
{"channel":"book","type":"update","data":[{"symbol":"BCH/USD","bids":[{"price":460.69,"qty":0.88120000}],"asks":[],"checksum":3710715709,"timestamp":"2024-06-01T17:51:28.356423Z"}]}
{"channel":"book","type":"update","data":[{"symbol":"BCH/USD","bids":[{"price":460.73,"qty":5.89454259}],"asks":[],"checksum":4182397695,"timestamp":"2024-06-01T17:51:28.360384Z"}]}
{"channel":"book","type":"update","data":[{"symbol":"BCH/USD","bids":[{"price":460.74,"qty":2.36240000}],"asks":[],"checksum":559415881,"timestamp":"2024-06-01T17:51:34.333822Z"}]}
{"channel":"book","type":"update","data":[{"symbol":"BCH/USD","bids":[{"price":460.74,"qty":13.21156237}],"asks":[],"checksum":1064085427,"timestamp":"2024-06-01T17:51:34.400617Z"}]}
{"channel":"book","type":"update","data":[{"symbol":"BCH/USD","bids":[],"asks":[{"price":460.94,"qty":0.00000000},{"price":461.17,"qty":11.72335562}],"checksum":1692415270,"timestamp":"2024-06-01T17:51:35.022250Z"}]}
{"channel":"book","type":"update","data":[{"symbol":"BCH/USD","bids":[{"price":460.60,"qty":0.00000000},{"price":460.53,"qty":10.85702190}],"asks":[],"checksum":2846229609,"timestamp":"2024-06-01T17:51:40.004437Z"}]}
{"channel":"book","type":"update","data":[{"symbol":"BCH/USD","bids":[{"price":460.60,"qty":0.63945085}],"asks":[],"checksum":3240747029,"timestamp":"2024-06-01T17:51:40.009532Z"}]}
{"channel":"book","type":"update","data":[{"symbol":"BCH/USD","bids":[{"price":460.73,"qty":0.46841354}],"asks":[],"checksum":16032907,"timestamp":"2024-06-01T17:51:40.090989Z"}]}
{"channel":"book","type":"update","data":[{"symbol":"BCH/USD","bids":[{"price":460.69,"qty":6.30781516}],"asks":[],"checksum":2780156923,"timestamp":"2024-06-01T17:51:40.096592Z"}]}
{"channel":"book","type":"update","data":[{"symbol":"BCH/USD","bids":[{"price":460.74,"qty":2.36240000}],"asks":[],"checksum":2989583403,"timestamp":"2024-06-01T17:51:40.099845Z"}]}
{"channel":"book","type":"update","data":[{"symbol":"BCH/USD","bids":[{"price":460.74,"qty":1.48120000}],"asks":[],"checksum":4062150224,"timestamp":"2024-06-01T17:51:40.108549Z"}]}
{"channel":"book","type":"update","data":[{"symbol":"BCH/USD","bids":[],"asks":[{"price":460.98,"qty":2.53908177}],"checksum":1356967005,"timestamp":"2024-06-01T17:51:40.111883Z"}]}
{"channel":"book","type":"update","data":[{"symbol":"BCH/USD","bids":[{"price":460.74,"qty":2.36240000}],"asks":[],"checksum":282050086,"timestamp":"2024-06-01T17:51:40.115663Z"}]}
{"channel":"book","type":"update","data":[{"symbol":"BCH/USD","bids":[{"price":460.74,"qty":1.48120000}],"asks":[],"checksum":1356967005,"timestamp":"2024-06-01T17:51:40.118319Z"}]}
{"channel":"book","type":"update","data":[{"symbol":"BCH/USD","bids":[{"price":460.74,"qty":2.36240000}],"asks":[],"checksum":282050086,"timestamp":"2024-06-01T17:51:40.124359Z"}]}
{"channel":"book","type":"update","data":[{"symbol":"BCH/USD","bids":[],"asks":[{"price":461.02,"qty":0.00000000},{"price":461.20,"qty":13.17522891}],"checksum":378653899,"timestamp":"2024-06-01T17:51:40.127609Z"}]}
{"channel":"book","type":"update","data":[{"symbol":"BCH/USD","bids":[],"asks":[{"price":460.97,"qty":5.42337843}],"checksum":2552700675,"timestamp":"2024-06-01T17:51:40.132023Z"}]}
{"channel":"book","type":"update","data":[{"symbol":"BCH/USD","bids":[{"price":460.74,"qty":13.21155735}],"asks":[],"checksum":1765324504,"timestamp":"2024-06-01T17:51:40.139679Z"}]}
{"channel":"book","type":"update","data":[{"symbol":"BCH/USD","bids":[],"asks":[{"price":460.98,"qty":1.93908177}],"checksum":4140481308,"timestamp":"2024-06-01T17:51:40.187205Z"}]}
{"channel":"book","type":"update","data":[{"symbol":"BCH/USD","bids":[],"asks":[{"price":460.97,"qty":6.02337843}],"checksum":677628245,"timestamp":"2024-06-01T17:51:40.187229Z"}]}
{"channel":"book","type":"update","data":[{"symbol":"BCH/USD","bids":[],"asks":[{"price":461.16,"qty":1.08600000}],"checksum":840520049,"timestamp":"2024-06-01T17:51:40.613275Z"}]}
{"channel":"book","type":"update","data":[{"symbol":"BCH/USD","bids":[],"asks":[{"price":461.16,"qty":11.95600000}],"checksum":2181586670,"timestamp":"2024-06-01T17:51:40.613328Z"}]}
{"channel":"book","type":"update","data":[{"symbol":"BCH/USD","bids":[{"price":460.68,"qty":0.00000000},{"price":460.53,"qty":10.85702190}],"asks":[],"checksum":385218649,"timestamp":"2024-06-01T17:51:40.830112Z"}]}
{"channel":"book","type":"update","data":[{"symbol":"BCH/USD","bids":[],"asks":[{"price":461.16,"qty":22.80600000}],"checksum":1345199768,"timestamp":"2024-06-01T17:51:40.831581Z"}]}
{"channel":"book","type":"update","data":[{"symbol":"BCH/USD","bids":[{"price":460.63,"qty":9.33192088}],"asks":[],"checksum":1776248968,"timestamp":"2024-06-01T17:51:41.016671Z"}]}
{"channel":"book","type":"update","data":[{"symbol":"BCH/USD","bids":[],"asks":[{"price":461.16,"qty":11.95600000}],"checksum":788827721,"timestamp":"2024-06-01T17:51:43.696548Z"}]}
{"channel":"book","type":"update","data":[{"symbol":"BCH/USD","bids":[],"asks":[{"price":461.16,"qty":1.08600000}],"checksum":1325666707,"timestamp":"2024-06-01T17:51:43.696716Z"}]}
{"channel":"book","type":"update","data":[{"symbol":"BCH/USD","bids":[],"asks":[{"price":461.16,"qty":0.00000000},{"price":461.17,"qty":11.72335562}],"checksum":1931317210,"timestamp":"2024-06-01T17:51:43.696772Z"}]}
{"channel":"book","type":"update","data":[{"symbol":"BCH/USD","bids":[{"price":460.74,"qty":2.36240000}],"asks":[],"checksum":2969452608,"timestamp":"2024-06-01T17:51:43.697221Z"}]}
{"channel":"book","type":"update","data":[{"symbol":"BCH/USD","bids":[],"asks":[{"price":460.97,"qty":5.42337843}],"checksum":1851208201,"timestamp":"2024-06-01T17:51:43.700127Z"}]}
{"channel":"book","type":"update","data":[{"symbol":"BCH/USD","bids":[],"asks":[{"price":460.96,"qty":0.60000000}],"checksum":1403384316,"timestamp":"2024-06-01T17:51:43.700667Z"}]}
{"channel":"book","type":"update","data":[{"symbol":"BCH/USD","bids":[{"price":460.70,"qty":0.43397584}],"asks":[],"checksum":4277943288,"timestamp":"2024-06-01T17:51:43.705130Z"}]}
{"channel":"book","type":"update","data":[{"symbol":"BCH/USD","bids":[],"asks":[{"price":460.97,"qty":0.00000000},{"price":461.17,"qty":11.72335562}],"checksum":2834773078,"timestamp":"2024-06-01T17:51:43.707614Z"}]}
{"channel":"book","type":"update","data":[{"symbol":"BCH/USD","bids":[],"asks":[{"price":461.02,"qty":5.42285665}],"checksum":1243756553,"timestamp":"2024-06-01T17:51:43.712781Z"}]}
{"channel":"book","type":"update","data":[{"symbol":"BCH/USD","bids":[],"asks":[{"price":460.95,"qty":0.00000000},{"price":461.17,"qty":11.72335562}],"checksum":2933625936,"timestamp":"2024-06-01T17:51:43.715576Z"}]}
{"channel":"book","type":"update","data":[{"symbol":"BCH/USD","bids":[{"price":460.69,"qty":0.88120000}],"asks":[],"checksum":1384628841,"timestamp":"2024-06-01T17:51:43.725911Z"}]}
{"channel":"book","type":"update","data":[{"symbol":"BCH/USD","bids":[{"price":460.73,"qty":5.89451046}],"asks":[],"checksum":4224963537,"timestamp":"2024-06-01T17:51:43.730157Z"}]}
{"channel":"book","type":"update","data":[{"symbol":"BCH/USD","bids":[{"price":460.68,"qty":7.83392088}],"asks":[],"checksum":671609092,"timestamp":"2024-06-01T17:51:43.737163Z"}]}
{"channel":"book","type":"update","data":[{"symbol":"BCH/USD","bids":[{"price":460.74,"qty":2.79635251}],"asks":[],"checksum":809759450,"timestamp":"2024-06-01T17:51:43.741253Z"}]}
{"channel":"book","type":"update","data":[{"symbol":"BCH/USD","bids":[],"asks":[{"price":461.02,"qty":0.00000000},{"price":461.20,"qty":1.21922891}],"checksum":203266563,"timestamp":"2024-06-01T17:51:43.771339Z"}]}
{"channel":"book","type":"update","data":[{"symbol":"BCH/USD","bids":[],"asks":[{"price":461.12,"qty":0.00000000},{"price":461.22,"qty":14.62155400}],"checksum":490826519,"timestamp":"2024-06-01T17:51:43.816620Z"}]}
{"channel":"book","type":"update","data":[{"symbol":"BCH/USD","bids":[],"asks":[{"price":461.20,"qty":0.00000000},{"price":461.27,"qty":1.12500000}],"checksum":2396936477,"timestamp":"2024-06-01T17:51:43.820064Z"}]}
{"channel":"book","type":"update","data":[{"symbol":"BCH/USD","bids":[],"asks":[{"price":461.03,"qty":0.00000000},{"price":461.28,"qty":1.49800000}],"checksum":1786304269,"timestamp":"2024-06-01T17:51:43.842816Z"}]}
{"channel":"book","type":"update","data":[{"symbol":"BCH/USD","bids":[{"price":460.73,"qty":5.42609692}],"asks":[],"checksum":2751592284,"timestamp":"2024-06-01T17:51:43.844228Z"}]}
{"channel":"book","type":"update","data":[{"symbol":"BCH/USD","bids":[{"price":460.63,"qty":1.49800000}],"asks":[],"checksum":1278289457,"timestamp":"2024-06-01T17:51:43.847864Z"}]}
{"channel":"book","type":"update","data":[{"symbol":"BCH/USD","bids":[{"price":460.74,"qty":9.86635251}],"asks":[],"checksum":2256454043,"timestamp":"2024-06-01T17:51:43.849719Z"}]}
{"channel":"book","type":"update","data":[{"symbol":"BCH/USD","bids":[],"asks":[{"price":460.96,"qty":0.00000000},{"price":461.30,"qty":4.33867891}],"checksum":983886043,"timestamp":"2024-06-01T17:51:43.852368Z"}]}
{"channel":"book","type":"update","data":[{"symbol":"BCH/USD","bids":[],"asks":[{"price":461.17,"qty":0.88120000}],"checksum":302164497,"timestamp":"2024-06-01T17:51:43.859208Z"}]}
{"channel":"book","type":"update","data":[{"symbol":"BCH/USD","bids":[],"asks":[{"price":461.24,"qty":10.84043152}],"checksum":491821892,"timestamp":"2024-06-01T17:51:43.863404Z"}]}
{"channel":"book","type":"update","data":[{"symbol":"BCH/USD","bids":[{"price":460.74,"qty":20.71551711}],"asks":[],"checksum":2983469128,"timestamp":"2024-06-01T17:51:43.897842Z"}]}
{"channel":"book","type":"update","data":[{"symbol":"BCH/USD","bids":[],"asks":[{"price":460.98,"qty":0.05961221}],"checksum":2694594771,"timestamp":"2024-06-01T17:51:43.917047Z"}]}
{"channel":"book","type":"update","data":[{"symbol":"BCH/USD","bids":[],"asks":[{"price":461.07,"qty":0.60000000}],"checksum":1401102795,"timestamp":"2024-06-01T17:51:43.920015Z"}]}
{"channel":"book","type":"update","data":[{"symbol":"BCH/USD","bids":[],"asks":[{"price":461.09,"qty":0.14726888}],"checksum":3080859275,"timestamp":"2024-06-01T17:51:44.019412Z"}]}
{"channel":"book","type":"update","data":[{"symbol":"BCH/USD","bids":[],"asks":[{"price":461.22,"qty":21.69155400}],"checksum":674677371,"timestamp":"2024-06-01T17:51:44.111493Z"}]}
{"channel":"book","type":"update","data":[{"symbol":"BCH/USD","bids":[{"price":460.74,"qty":21.18392048}],"asks":[],"checksum":1276467156,"timestamp":"2024-06-01T17:51:44.121274Z"}]}
{"channel":"book","type":"update","data":[{"symbol":"BCH/USD","bids":[{"price":460.70,"qty":0.00000000},{"price":460.59,"qty":10.85547104}],"asks":[],"checksum":2706457341,"timestamp":"2024-06-01T17:51:44.212619Z"}]}
{"channel":"book","type":"update","data":[{"symbol":"BCH/USD","bids":[],"asks":[{"price":461.06,"qty":5.42231414}],"checksum":1299133948,"timestamp":"2024-06-01T17:51:44.228070Z"}]}
{"channel":"book","type":"update","data":[{"symbol":"BCH/USD","bids":[],"asks":[{"price":461.07,"qty":0.00000000},{"price":461.24,"qty":10.84043152}],"checksum":2212495496,"timestamp":"2024-06-01T17:51:44.238162Z"}]}
{"channel":"book","type":"update","data":[{"symbol":"BCH/USD","bids":[],"asks":[{"price":461.05,"qty":0.60000000}],"checksum":3683741271,"timestamp":"2024-06-01T17:51:44.238387Z"}]}
{"channel":"book","type":"update","data":[{"symbol":"BCH/USD","bids":[],"asks":[{"price":461.01,"qty":0.86771656}],"checksum":296639841,"timestamp":"2024-06-01T17:51:44.249719Z"}]}
{"channel":"book","type":"update","data":[{"symbol":"BCH/USD","bids":[{"price":460.74,"qty":20.74996797}],"asks":[],"checksum":3716058810,"timestamp":"2024-06-01T17:51:46.029421Z"}]}
{"channel":"book","type":"update","data":[{"symbol":"BCH/USD","bids":[{"price":460.74,"qty":28.58388885}],"asks":[],"checksum":2512596912,"timestamp":"2024-06-01T17:51:47.016093Z"}]}
{"channel":"book","type":"update","data":[{"symbol":"BCH/USD","bids":[{"price":460.68,"qty":0.00000000},{"price":460.54,"qty":1.74911741}],"asks":[],"checksum":3561270637,"timestamp":"2024-06-01T17:51:47.020132Z"}]}
{"channel":"book","type":"update","data":[{"symbol":"BCH/USD","bids":[{"price":460.74,"qty":28.11548548}],"asks":[],"checksum":3178729336,"timestamp":"2024-06-01T17:51:47.253570Z"}]}
{"channel":"book","type":"update","data":[{"symbol":"BCH/USD","bids":[{"price":460.74,"qty":28.58388885}],"asks":[],"checksum":3561270637,"timestamp":"2024-06-01T17:51:47.374008Z"}]}
{"channel":"book","type":"update","data":[{"symbol":"BCH/USD","bids":[],"asks":[{"price":461.00,"qty":0.00000000},{"price":461.22,"qty":33.64755400}],"checksum":4123188395,"timestamp":"2024-06-01T17:51:49.598501Z"}]}
{"channel":"book","type":"update","data":[{"symbol":"BCH/USD","bids":[],"asks":[{"price":461.00,"qty":0.88120000}],"checksum":3561270637,"timestamp":"2024-06-01T17:51:49.604676Z"}]}
{"channel":"book","type":"update","data":[{"symbol":"BCH/USD","bids":[],"asks":[{"price":461.00,"qty":0.00000000},{"price":461.22,"qty":33.64755400}],"checksum":4123188395,"timestamp":"2024-06-01T17:51:49.608054Z"}]}
{"channel":"book","type":"update","data":[{"symbol":"BCH/USD","bids":[],"asks":[{"price":461.06,"qty":0.00000000},{"price":461.24,"qty":10.84043152}],"checksum":1861330631,"timestamp":"2024-06-01T17:51:49.624453Z"}]}
{"channel":"book","type":"update","data":[{"symbol":"BCH/USD","bids":[],"asks":[{"price":461.22,"qty":22.77755400}],"checksum":1527531922,"timestamp":"2024-06-01T17:51:49.627036Z"}]}
{"channel":"book","type":"update","data":[{"symbol":"BCH/USD","bids":[],"asks":[{"price":461.11,"qty":5.42173940}],"checksum":754650392,"timestamp":"2024-06-01T17:51:49.630974Z"}]}
{"channel":"book","type":"update","data":[{"symbol":"BCH/USD","bids":[],"asks":[{"price":461.22,"qty":21.69155400}],"checksum":1493136480,"timestamp":"2024-06-01T17:51:49.631257Z"}]}
{"channel":"book","type":"update","data":[{"symbol":"BCH/USD","bids":[],"asks":[{"price":461.09,"qty":0.00000000},{"price":461.24,"qty":10.84043152}],"checksum":1097016666,"timestamp":"2024-06-01T17:51:49.636399Z"}]}
{"channel":"book","type":"update","data":[{"symbol":"BCH/USD","bids":[{"price":460.74,"qty":17.73472425}],"asks":[],"checksum":2759481064,"timestamp":"2024-06-01T17:51:49.670976Z"}]}
{"channel":"book","type":"update","data":[{"symbol":"BCH/USD","bids":[],"asks":[{"price":461.01,"qty":0.00000000},{"price":461.28,"qty":23.21800000}],"checksum":389105669,"timestamp":"2024-06-01T17:51:49.700531Z"}]}
{"channel":"book","type":"update","data":[{"symbol":"BCH/USD","bids":[{"price":460.59,"qty":0.00000000},{"price":460.51,"qty":0.50682788}],"asks":[],"checksum":2579265592,"timestamp":"2024-06-01T17:51:49.746209Z"}]}
{"channel":"book","type":"update","data":[{"symbol":"BCH/USD","bids":[{"price":460.55,"qty":1.08600000}],"asks":[],"checksum":1495690407,"timestamp":"2024-06-01T17:51:49.749713Z"}]}
{"channel":"book","type":"update","data":[{"symbol":"BCH/USD","bids":[{"price":460.55,"qty":11.95600000}],"asks":[],"checksum":3874093873,"timestamp":"2024-06-01T17:51:49.749955Z"}]}
{"channel":"book","type":"update","data":[{"symbol":"BCH/USD","bids":[{"price":460.65,"qty":11.30416515}],"asks":[],"checksum":3696313885,"timestamp":"2024-06-01T17:51:49.750664Z"}]}
{"channel":"book","type":"update","data":[{"symbol":"BCH/USD","bids":[],"asks":[{"price":461.28,"qty":12.34800000}],"checksum":508284355,"timestamp":"2024-06-01T17:51:49.790430Z"}]}
{"channel":"book","type":"update","data":[{"symbol":"BCH/USD","bids":[],"asks":[{"price":461.28,"qty":1.49800000}],"checksum":1622890739,"timestamp":"2024-06-01T17:51:49.791242Z"}]}
{"channel":"book","type":"update","data":[{"symbol":"BCH/USD","bids":[],"asks":[{"price":461.14,"qty":0.14726888}],"checksum":791230478,"timestamp":"2024-06-01T17:51:49.819017Z"}]}
{"channel":"book","type":"update","data":[{"symbol":"BCH/USD","bids":[{"price":460.74,"qty":28.58245983}],"asks":[],"checksum":2907389951,"timestamp":"2024-06-01T17:51:49.826504Z"}]}
{"channel":"book","type":"update","data":[{"symbol":"BCH/USD","bids":[{"price":460.74,"qty":29.08245983}],"asks":[],"checksum":4259233685,"timestamp":"2024-06-01T17:51:49.954281Z"}]}
{"channel":"book","type":"update","data":[{"symbol":"BCH/USD","bids":[],"asks":[{"price":461.02,"qty":0.86768104}],"checksum":507339354,"timestamp":"2024-06-01T17:51:50.069179Z"}]}
{"channel":"book","type":"update","data":[{"symbol":"BCH/USD","bids":[],"asks":[{"price":461.22,"qty":7.95120000}],"checksum":777181041,"timestamp":"2024-06-01T17:51:51.406738Z"}]}
{"channel":"book","type":"update","data":[{"symbol":"BCH/USD","bids":[{"price":460.55,"qty":10.87000000}],"asks":[],"checksum":3270428109,"timestamp":"2024-06-01T17:51:51.439335Z"}]}
{"channel":"book","type":"update","data":[{"symbol":"BCH/USD","bids":[{"price":460.55,"qty":11.95600000}],"asks":[],"checksum":777181041,"timestamp":"2024-06-01T17:51:51.691597Z"}]}
{"channel":"book","type":"update","data":[{"symbol":"BCH/USD","bids":[{"price":460.74,"qty":18.23472425}],"asks":[],"checksum":905260963,"timestamp":"2024-06-01T17:51:53.992059Z"}]}
{"channel":"book","type":"update","data":[{"symbol":"BCH/USD","bids":[],"asks":[{"price":461.11,"qty":0.00000000},{"price":461.24,"qty":10.84043152}],"checksum":2142905877,"timestamp":"2024-06-01T17:51:54.008419Z"}]}
{"channel":"book","type":"update","data":[{"symbol":"BCH/USD","bids":[],"asks":[{"price":461.07,"qty":5.42220199}],"checksum":1121734047,"timestamp":"2024-06-01T17:51:54.012755Z"}]}
{"channel":"book","type":"update","data":[{"symbol":"BCH/USD","bids":[{"price":460.55,"qty":10.87000000}],"asks":[],"checksum":2925551395,"timestamp":"2024-06-01T17:51:54.028479Z"}]}
{"channel":"book","type":"update","data":[{"symbol":"BCH/USD","bids":[],"asks":[{"price":461.02,"qty":0.00000000},{"price":461.24,"qty":22.79643152}],"checksum":2280269814,"timestamp":"2024-06-01T17:51:54.394587Z"}]}
{"channel":"book","type":"update","data":[{"symbol":"BCH/USD","bids":[],"asks":[{"price":461.03,"qty":0.86767552}],"checksum":2378530587,"timestamp":"2024-06-01T17:51:54.696380Z"}]}
{"channel":"book","type":"update","data":[{"symbol":"BCH/USD","bids":[{"price":460.60,"qty":0.00000000},{"price":460.51,"qty":0.50682788}],"asks":[],"checksum":3807618744,"timestamp":"2024-06-01T17:51:55.145001Z"}]}
{"channel":"book","type":"update","data":[{"symbol":"BCH/USD","bids":[{"price":460.70,"qty":0.97786851}],"asks":[],"checksum":569002982,"timestamp":"2024-06-01T17:51:55.149485Z"}]}
{"channel":"book","type":"update","data":[{"symbol":"BCH/USD","bids":[{"price":460.74,"qty":29.08296957}],"asks":[],"checksum":512145864,"timestamp":"2024-06-01T17:51:55.818568Z"}]}
{"channel":"book","type":"update","data":[{"symbol":"BCH/USD","bids":[{"price":460.74,"qty":28.61456620}],"asks":[],"checksum":993243964,"timestamp":"2024-06-01T17:51:56.360645Z"}]}
{"channel":"book","type":"update","data":[{"symbol":"BCH/USD","bids":[{"price":460.74,"qty":29.08296957}],"asks":[],"checksum":512145864,"timestamp":"2024-06-01T17:51:56.480520Z"}]}
{"channel":"book","type":"update","data":[{"symbol":"BCH/USD","bids":[],"asks":[{"price":461.14,"qty":0.00000000},{"price":461.24,"qty":10.84043152}],"checksum":3517361816,"timestamp":"2024-06-01T17:52:00.113920Z"}]}
{"channel":"book","type":"update","data":[{"symbol":"BCH/USD","bids":[],"asks":[{"price":461.07,"qty":0.00000000},{"price":461.26,"qty":1.08600000}],"checksum":4056693195,"timestamp":"2024-06-01T17:52:00.147632Z"}]}
{"channel":"book","type":"update","data":[{"symbol":"BCH/USD","bids":[],"asks":[{"price":461.11,"qty":5.42172776}],"checksum":2498577520,"timestamp":"2024-06-01T17:52:00.152364Z"}]}
{"channel":"book","type":"update","data":[{"symbol":"BCH/USD","bids":[],"asks":[{"price":461.03,"qty":0.00000000},{"price":461.26,"qty":1.08600000}],"checksum":1609956251,"timestamp":"2024-06-01T17:52:00.187165Z"}]}
{"channel":"book","type":"update","data":[{"symbol":"BCH/USD","bids":[],"asks":[{"price":461.04,"qty":0.86764816}],"checksum":3315824908,"timestamp":"2024-06-01T17:52:00.448532Z"}]}
{"channel":"book","type":"update","data":[{"symbol":"BCH/USD","bids":[],"asks":[{"price":461.15,"qty":0.14726888}],"checksum":1543210679,"timestamp":"2024-06-01T17:52:01.300785Z"}]}
{"channel":"book","type":"update","data":[{"symbol":"BCH/USD","bids":[{"price":460.63,"qty":0.00000000},{"price":460.51,"qty":0.50682788}],"asks":[],"checksum":178832041,"timestamp":"2024-06-01T17:52:02.336550Z"}]}
{"channel":"book","type":"update","data":[{"symbol":"BCH/USD","bids":[{"price":460.73,"qty":6.90609692}],"asks":[],"checksum":4281153612,"timestamp":"2024-06-01T17:52:02.339349Z"}]}
{"channel":"book","type":"update","data":[{"symbol":"BCH/USD","bids":[],"asks":[{"price":461.22,"qty":0.88120000}],"checksum":2066254756,"timestamp":"2024-06-01T17:52:03.199534Z"}]}
{"channel":"book","type":"update","data":[{"symbol":"BCH/USD","bids":[{"price":460.74,"qty":39.93296957}],"asks":[],"checksum":2801378270,"timestamp":"2024-06-01T17:52:03.203244Z"}]}
{"channel":"book","type":"update","data":[{"symbol":"BCH/USD","bids":[{"price":460.55,"qty":0.00000000},{"price":460.50,"qty":13.74035400},{"price":460.67,"qty":21.72068578}],"asks":[],"checksum":3573904386,"timestamp":"2024-06-01T17:52:03.204373Z"}]}
{"channel":"book","type":"update","data":[{"symbol":"BCH/USD","bids":[{"price":460.65,"qty":0.45000000}],"asks":[],"checksum":2881485857,"timestamp":"2024-06-01T17:52:03.205084Z"}]}
{"channel":"book","type":"update","data":[{"symbol":"BCH/USD","bids":[],"asks":[{"price":461.11,"qty":0.00000000},{"price":461.30,"qty":0.88120000}],"checksum":1219069332,"timestamp":"2024-06-01T17:52:03.205095Z"}]}
{"channel":"book","type":"update","data":[{"symbol":"BCH/USD","bids":[{"price":460.71,"qty":10.85265733}],"asks":[],"checksum":4176491433,"timestamp":"2024-06-01T17:52:03.210701Z"}]}
{"channel":"book","type":"update","data":[{"symbol":"BCH/USD","bids":[],"asks":[{"price":461.16,"qty":5.42121834}],"checksum":901051317,"timestamp":"2024-06-01T17:52:03.211627Z"}]}
{"channel":"book","type":"update","data":[{"symbol":"BCH/USD","bids":[],"asks":[{"price":461.08,"qty":0.00000000},{"price":461.30,"qty":0.88120000}],"checksum":866236315,"timestamp":"2024-06-01T17:52:03.213071Z"}]}
{"channel":"book","type":"update","data":[{"symbol":"BCH/USD","bids":[],"asks":[{"price":461.05,"qty":0.00000000},{"price":461.31,"qty":1.08600000}],"checksum":2893791134,"timestamp":"2024-06-01T17:52:03.213518Z"}]}
{"channel":"book","type":"update","data":[{"symbol":"BCH/USD","bids":[],"asks":[{"price":461.10,"qty":0.88120000}],"checksum":488674552,"timestamp":"2024-06-01T17:52:03.217700Z"}]}
{"channel":"book","type":"update","data":[{"symbol":"BCH/USD","bids":[],"asks":[{"price":461.16,"qty":0.00000000},{"price":461.31,"qty":1.08600000}],"checksum":4272965254,"timestamp":"2024-06-01T17:52:03.220625Z"}]}
{"channel":"book","type":"update","data":[{"symbol":"BCH/USD","bids":[],"asks":[{"price":461.31,"qty":0.00000000},{"price":461.32,"qty":10.83849881}],"checksum":1463092094,"timestamp":"2024-06-01T17:52:03.220687Z"}]}
{"channel":"book","type":"update","data":[{"symbol":"BCH/USD","bids":[],"asks":[{"price":461.10,"qty":1.48120000}],"checksum":3365791507,"timestamp":"2024-06-01T17:52:03.223649Z"}]}
{"channel":"book","type":"update","data":[{"symbol":"BCH/USD","bids":[],"asks":[{"price":461.15,"qty":0.00000000},{"price":461.33,"qty":24.59035400}],"checksum":3022205301,"timestamp":"2024-06-01T17:52:03.224638Z"}]}
{"channel":"book","type":"update","data":[{"symbol":"BCH/USD","bids":[{"price":460.74,"qty":29.08296957}],"asks":[],"checksum":916296027,"timestamp":"2024-06-01T17:52:03.229950Z"}]}
{"channel":"book","type":"update","data":[{"symbol":"BCH/USD","bids":[],"asks":[{"price":461.33,"qty":13.74035400}],"checksum":1814949411,"timestamp":"2024-06-01T17:52:03.274015Z"}]}
{"channel":"book","type":"update","data":[{"symbol":"BCH/USD","bids":[],"asks":[{"price":461.04,"qty":0.00000000},{"price":461.35,"qty":0.92994237}],"checksum":898682613,"timestamp":"2024-06-01T17:52:03.285547Z"}]}
{"channel":"book","type":"update","data":[{"symbol":"BCH/USD","bids":[],"asks":[{"price":461.21,"qty":0.14726888}],"checksum":4258426836,"timestamp":"2024-06-01T17:52:03.345545Z"}]}
{"channel":"book","type":"update","data":[{"symbol":"BCH/USD","bids":[],"asks":[{"price":461.21,"qty":0.00000000},{"price":461.35,"qty":0.92994237}],"checksum":898682613,"timestamp":"2024-06-01T17:52:03.393533Z"}]}
{"channel":"book","type":"update","data":[{"symbol":"BCH/USD","bids":[{"price":460.53,"qty":1.12500000}],"asks":[],"checksum":3313913719,"timestamp":"2024-06-01T17:52:03.405810Z"}]}
{"channel":"book","type":"update","data":[{"symbol":"BCH/USD","bids":[],"asks":[{"price":461.23,"qty":0.14726888}],"checksum":1455485855,"timestamp":"2024-06-01T17:52:03.513466Z"}]}
{"channel":"book","type":"update","data":[{"symbol":"BCH/USD","bids":[],"asks":[{"price":461.23,"qty":0.00000000},{"price":461.35,"qty":0.92994237}],"checksum":3313913719,"timestamp":"2024-06-01T17:52:03.552854Z"}]}
{"channel":"book","type":"update","data":[{"symbol":"BCH/USD","bids":[],"asks":[{"price":461.13,"qty":0.86749147}],"checksum":2754727647,"timestamp":"2024-06-01T17:52:03.560073Z"}]}
{"channel":"book","type":"update","data":[{"symbol":"BCH/USD","bids":[],"asks":[{"price":461.32,"qty":17.90849881}],"checksum":4064130278,"timestamp":"2024-06-01T17:52:03.564623Z"}]}
{"channel":"book","type":"update","data":[{"symbol":"BCH/USD","bids":[],"asks":[{"price":461.24,"qty":0.14726888}],"checksum":1806040523,"timestamp":"2024-06-01T17:52:03.682575Z"}]}
{"channel":"book","type":"update","data":[{"symbol":"BCH/USD","bids":[{"price":460.73,"qty":17.75609692}],"asks":[],"checksum":2708938351,"timestamp":"2024-06-01T17:52:04.322288Z"}]}
{"channel":"book","type":"update","data":[{"symbol":"BCH/USD","bids":[],"asks":[{"price":461.21,"qty":5.42061481}],"checksum":562142350,"timestamp":"2024-06-01T17:52:04.434625Z"}]}
{"channel":"book","type":"update","data":[{"symbol":"BCH/USD","bids":[],"asks":[{"price":461.13,"qty":0.00000000},{"price":461.32,"qty":17.90849881}],"checksum":1993717138,"timestamp":"2024-06-01T17:52:04.682790Z"}]}
{"channel":"book","type":"update","data":[{"symbol":"BCH/USD","bids":[],"asks":[{"price":461.14,"qty":0.86747302}],"checksum":2458705647,"timestamp":"2024-06-01T17:52:04.947693Z"}]}
{"channel":"book","type":"update","data":[{"symbol":"BCH/USD","bids":[{"price":460.74,"qty":28.61456620}],"asks":[],"checksum":1213499997,"timestamp":"2024-06-01T17:52:05.431831Z"}]}
{"channel":"book","type":"update","data":[{"symbol":"BCH/USD","bids":[{"price":460.74,"qty":29.08296957}],"asks":[],"checksum":2458705647,"timestamp":"2024-06-01T17:52:05.553494Z"}]}
{"channel":"book","type":"update","data":[{"symbol":"BCH/USD","bids":[],"asks":[{"price":461.24,"qty":0.00000000},{"price":461.32,"qty":17.90849881}],"checksum":1787582662,"timestamp":"2024-06-01T17:52:05.563129Z"}]}
{"channel":"book","type":"update","data":[{"symbol":"BCH/USD","bids":[],"asks":[{"price":461.24,"qty":0.14726888}],"checksum":2458705647,"timestamp":"2024-06-01T17:52:07.326037Z"}]}
{"channel":"book","type":"update","data":[{"symbol":"BCH/USD","bids":[{"price":460.73,"qty":6.90609692},{"price":460.74,"qty":39.93296957}],"asks":[],"checksum":1328294857,"timestamp":"2024-06-01T17:52:08.831840Z"}]}
{"channel":"book","type":"update","data":[{"symbol":"BCH/USD","bids":[{"price":460.74,"qty":29.08296957}],"asks":[],"checksum":2474154150,"timestamp":"2024-06-01T17:52:08.965246Z"}]}
{"channel":"book","type":"update","data":[{"symbol":"BCH/USD","bids":[{"price":460.70,"qty":11.82786851}],"asks":[],"checksum":140916766,"timestamp":"2024-06-01T17:52:09.982192Z"}]}
{"channel":"book","type":"update","data":[{"symbol":"BCH/USD","bids":[{"price":460.54,"qty":0.88120000}],"asks":[],"checksum":3312257570,"timestamp":"2024-06-01T17:52:11.851766Z"}]}
{"channel":"book","type":"update","data":[{"symbol":"BCH/USD","bids":[{"price":460.74,"qty":32.97629252}],"asks":[],"checksum":4213396640,"timestamp":"2024-06-01T17:52:12.058493Z"}]}
{"channel":"book","type":"update","data":[{"symbol":"BCH/USD","bids":[{"price":460.74,"qty":33.84376513}],"asks":[],"checksum":2415777606,"timestamp":"2024-06-01T17:52:12.149711Z"}]}
{"channel":"book","type":"update","data":[{"symbol":"BCH/USD","bids":[{"price":460.61,"qty":0.00000000},{"price":460.52,"qty":0.07403157}],"asks":[],"checksum":2205439424,"timestamp":"2024-06-01T17:52:12.456082Z"}]}
{"channel":"book","type":"update","data":[{"symbol":"BCH/USD","bids":[{"price":460.64,"qty":0.88120000}],"asks":[],"checksum":584932164,"timestamp":"2024-06-01T17:52:12.458625Z"}]}
{"channel":"book","type":"update","data":[{"symbol":"BCH/USD","bids":[{"price":460.70,"qty":0.97786851},{"price":460.74,"qty":44.69376513}],"asks":[],"checksum":2969027900,"timestamp":"2024-06-01T17:52:12.577509Z"}]}
{"channel":"book","type":"update","data":[{"symbol":"BCH/USD","bids":[{"price":460.74,"qty":45.69376513}],"asks":[],"checksum":3448946476,"timestamp":"2024-06-01T17:52:13.702065Z"}]}
{"channel":"book","type":"update","data":[{"symbol":"BCH/USD","bids":[{"price":460.74,"qty":45.19376513}],"asks":[],"checksum":979164608,"timestamp":"2024-06-01T17:52:13.781407Z"}]}
{"channel":"book","type":"update","data":[{"symbol":"BCH/USD","bids":[],"asks":[{"price":461.24,"qty":0.00000000},{"price":461.32,"qty":17.90849881}],"checksum":3473006492,"timestamp":"2024-06-01T17:52:15.207849Z"}]}
{"channel":"book","type":"update","data":[{"symbol":"BCH/USD","bids":[],"asks":[{"price":461.10,"qty":0.60000000}],"checksum":6585239,"timestamp":"2024-06-01T17:52:15.326761Z"}]}
{"channel":"book","type":"update","data":[{"symbol":"BCH/USD","bids":[],"asks":[{"price":461.10,"qty":1.48120000}],"checksum":3473006492,"timestamp":"2024-06-01T17:52:15.330029Z"}]}
{"channel":"book","type":"update","data":[{"symbol":"BCH/USD","bids":[],"asks":[{"price":461.26,"qty":0.14726888}],"checksum":663071809,"timestamp":"2024-06-01T17:52:15.331670Z"}]}
{"channel":"book","type":"update","data":[{"symbol":"BCH/USD","bids":[],"asks":[{"price":461.10,"qty":0.60000000}],"checksum":1995987437,"timestamp":"2024-06-01T17:52:15.377223Z"}]}
{"channel":"book","type":"update","data":[{"symbol":"BCH/USD","bids":[],"asks":[{"price":461.10,"qty":0.00000000},{"price":461.32,"qty":7.07000000}],"checksum":3768848716,"timestamp":"2024-06-01T17:52:15.399498Z"}]}
{"channel":"book","type":"update","data":[{"symbol":"BCH/USD","bids":[],"asks":[{"price":461.16,"qty":0.60000000}],"checksum":3291736100,"timestamp":"2024-06-01T17:52:15.400168Z"}]}
{"channel":"book","type":"update","data":[{"symbol":"BCH/USD","bids":[{"price":460.67,"qty":10.85068578},{"price":460.74,"qty":56.06376513}],"asks":[],"checksum":719911756,"timestamp":"2024-06-01T17:52:15.426410Z"}]}
{"channel":"book","type":"update","data":[{"symbol":"BCH/USD","bids":[{"price":460.74,"qty":45.19376513}],"asks":[],"checksum":1758434520,"timestamp":"2024-06-01T17:52:15.660938Z"}]}
{"channel":"book","type":"update","data":[{"symbol":"BCH/USD","bids":[{"price":460.64,"qty":0.00000000},{"price":460.52,"qty":0.07403157}],"asks":[],"checksum":1310623908,"timestamp":"2024-06-01T17:52:16.142944Z"}]}
{"channel":"book","type":"update","data":[{"symbol":"BCH/USD","bids":[{"price":460.71,"qty":21.70265733}],"asks":[],"checksum":719585885,"timestamp":"2024-06-01T17:52:16.471037Z"}]}
{"channel":"book","type":"update","data":[{"symbol":"BCH/USD","bids":[{"price":460.71,"qty":10.85265733},{"price":460.74,"qty":56.04376513}],"asks":[],"checksum":2136951562,"timestamp":"2024-06-01T17:52:17.346188Z"}]}
{"channel":"book","type":"update","data":[{"symbol":"BCH/USD","bids":[],"asks":[{"price":461.21,"qty":0.00000000},{"price":461.35,"qty":0.92994237}],"checksum":1625300929,"timestamp":"2024-06-01T17:52:18.969897Z"}]}
{"channel":"book","type":"update","data":[{"symbol":"BCH/USD","bids":[],"asks":[{"price":461.25,"qty":5.42008573}],"checksum":1586801456,"timestamp":"2024-06-01T17:52:18.974916Z"}]}
{"channel":"book","type":"update","data":[{"symbol":"BCH/USD","bids":[],"asks":[{"price":461.14,"qty":0.00000000},{"price":461.35,"qty":0.92994237}],"checksum":1440473138,"timestamp":"2024-06-01T17:52:18.983991Z"}]}
{"channel":"book","type":"update","data":[{"symbol":"BCH/USD","bids":[{"price":460.74,"qty":55.57536176}],"asks":[],"checksum":1392865539,"timestamp":"2024-06-01T17:52:18.993353Z"}]}
{"channel":"book","type":"update","data":[{"symbol":"BCH/USD","bids":[],"asks":[{"price":461.26,"qty":0.00000000},{"price":461.36,"qty":0.04209654}],"checksum":1854293212,"timestamp":"2024-06-01T17:52:18.994203Z"}]}
{"channel":"book","type":"update","data":[{"symbol":"BCH/USD","bids":[{"price":460.74,"qty":56.04376513}],"asks":[],"checksum":1750652397,"timestamp":"2024-06-01T17:52:19.111451Z"}]}
