{"channel":"book","type":"snapshot","data":[{"symbol":"BCH/EUR","bids":[{"price":424.98,"qty":0.45000000},{"price":424.96,"qty":2.00000000},{"price":424.95,"qty":0.09892917},{"price":424.94,"qty":2.00000000},{"price":424.93,"qty":7.83392088},{"price":424.92,"qty":16.27506963},{"price":424.91,"qty":3.88726919},{"price":424.88,"qty":8.00000000},{"price":424.85,"qty":0.37035124},{"price":424.80,"qty":10.85070170}],"asks":[{"price":425.24,"qty":5.87054263},{"price":425.26,"qty":7.83392088},{"price":425.27,"qty":15.96804300},{"price":425.34,"qty":3.88726919},{"price":425.35,"qty":2.00000000},{"price":425.37,"qty":0.03152465},{"price":425.41,"qty":2.67422891},{"price":425.49,"qty":8.00000000},{"price":425.50,"qty":25.18732600},{"price":425.52,"qty":5.42125266}],"checksum":3961822466}]}
{"channel":"book","type":"update","data":[{"symbol":"BCH/EUR","bids":[{"price":424.96,"qty":0.00000000},{"price":424.71,"qty":5.42125266}],"asks":[],"checksum":1588843213,"timestamp":"2024-06-01T17:51:20.129798Z"}]}
{"channel":"book","type":"update","data":[{"symbol":"BCH/EUR","bids":[{"price":424.95,"qty":7.93285005}],"asks":[],"checksum":4193118966,"timestamp":"2024-06-01T17:51:20.133645Z"}]}
{"channel":"book","type":"update","data":[{"symbol":"BCH/EUR","bids":[{"price":424.88,"qty":0.00000000},{"price":424.69,"qty":0.48000000}],"asks":[],"checksum":2445833221,"timestamp":"2024-06-01T17:51:20.134927Z"}]}
{"channel":"book","type":"update","data":[{"symbol":"BCH/EUR","bids":[{"price":424.93,"qty":0.00000000},{"price":424.65,"qty":5.42774177}],"asks":[],"checksum":3601462626,"timestamp":"2024-06-01T17:51:20.509746Z"}]}
{"channel":"book","type":"update","data":[{"symbol":"BCH/EUR","bids":[{"price":424.88,"qty":8.00000000}],"asks":[],"checksum":1552227248,"timestamp":"2024-06-01T17:51:20.515309Z"}]}
{"channel":"book","type":"update","data":[{"symbol":"BCH/EUR","bids":[{"price":424.96,"qty":2.00000000}],"asks":[],"checksum":2797573129,"timestamp":"2024-06-01T17:51:20.519096Z"}]}
{"channel":"book","type":"update","data":[{"symbol":"BCH/EUR","bids":[{"price":424.94,"qty":0.00000000},{"price":424.69,"qty":0.48000000}],"asks":[],"checksum":3392122355,"timestamp":"2024-06-01T17:51:20.630421Z"}]}
{"channel":"book","type":"update","data":[{"symbol":"BCH/EUR","bids":[{"price":424.92,"qty":5.42438385}],"asks":[],"checksum":566725743,"timestamp":"2024-06-01T17:51:23.777226Z"}]}
{"channel":"book","type":"update","data":[{"symbol":"BCH/EUR","bids":[{"price":424.92,"qty":0.00000000},{"price":424.65,"qty":5.42774177}],"asks":[],"checksum":649816665,"timestamp":"2024-06-01T17:51:23.781965Z"}]}
{"channel":"book","type":"update","data":[{"symbol":"BCH/EUR","bids":[{"price":424.96,"qty":7.42395904}],"asks":[],"checksum":3319185099,"timestamp":"2024-06-01T17:51:23.789792Z"}]}
{"channel":"book","type":"update","data":[{"symbol":"BCH/EUR","bids":[],"asks":[{"price":425.26,"qty":0.00000000},{"price":425.54,"qty":5.41654689}],"checksum":4031925658,"timestamp":"2024-06-01T17:51:23.803286Z"}]}
{"channel":"book","type":"update","data":[{"symbol":"BCH/EUR","bids":[{"price":424.97,"qty":7.83392088}],"asks":[],"checksum":1798697747,"timestamp":"2024-06-01T17:51:23.820250Z"}]}
{"channel":"book","type":"update","data":[{"symbol":"BCH/EUR","bids":[],"asks":[{"price":425.35,"qty":0.00000000},{"price":425.56,"qty":0.10173817}],"checksum":431697214,"timestamp":"2024-06-01T17:51:23.850121Z"}]}
{"channel":"book","type":"update","data":[{"symbol":"BCH/EUR","bids":[],"asks":[{"price":425.49,"qty":0.00000000},{"price":425.57,"qty":1.08600000}],"checksum":3657971653,"timestamp":"2024-06-01T17:51:23.850288Z"}]}
{"channel":"book","type":"update","data":[{"symbol":"BCH/EUR","bids":[],"asks":[{"price":425.34,"qty":0.00000000},{"price":425.62,"qty":10.86000000}],"checksum":3007714025,"timestamp":"2024-06-01T17:51:23.855526Z"}]}
{"channel":"book","type":"update","data":[{"symbol":"BCH/EUR","bids":[{"price":424.95,"qty":0.09892917}],"asks":[],"checksum":2606345300,"timestamp":"2024-06-01T17:51:23.855990Z"}]}
{"channel":"book","type":"update","data":[{"symbol":"BCH/EUR","bids":[],"asks":[{"price":425.37,"qty":0.00000000},{"price":425.63,"qty":12.24000000}],"checksum":3462413754,"timestamp":"2024-06-01T17:51:23.856811Z"}]}
{"channel":"book","type":"update","data":[{"symbol":"BCH/EUR","bids":[],"asks":[{"price":425.50,"qty":24.84732600}],"checksum":1505342763,"timestamp":"2024-06-01T17:51:23.862556Z"}]}
{"channel":"book","type":"update","data":[{"symbol":"BCH/EUR","bids":[{"price":424.95,"qty":0.00000000},{"price":424.65,"qty":5.42774177}],"asks":[],"checksum":2398567062,"timestamp":"2024-06-01T17:51:23.865542Z"}]}
{"channel":"book","type":"update","data":[{"symbol":"BCH/EUR","bids":[{"price":424.85,"qty":0.00000000},{"price":424.57,"qty":26.82804300}],"asks":[],"checksum":695110607,"timestamp":"2024-06-01T17:51:23.868646Z"}]}
{"channel":"book","type":"update","data":[{"symbol":"BCH/EUR","bids":[],"asks":[{"price":425.41,"qty":0.00000000},{"price":425.69,"qty":0.35000000}],"checksum":1123032750,"timestamp":"2024-06-01T17:51:23.868749Z"}]}
{"channel":"book","type":"update","data":[{"symbol":"BCH/EUR","bids":[{"price":424.93,"qty":10.85068578}],"asks":[],"checksum":2988131357,"timestamp":"2024-06-01T17:51:23.869615Z"}]}
{"channel":"book","type":"update","data":[{"symbol":"BCH/EUR","bids":[{"price":424.92,"qty":10.85068578}],"asks":[],"checksum":2601536416,"timestamp":"2024-06-01T17:51:23.875225Z"}]}
{"channel":"book","type":"update","data":[{"symbol":"BCH/EUR","bids":[{"price":424.96,"qty":2.00000000}],"asks":[],"checksum":4095566046,"timestamp":"2024-06-01T17:51:23.878076Z"}]}
{"channel":"book","type":"update","data":[{"symbol":"BCH/EUR","bids":[],"asks":[{"price":425.24,"qty":0.45000000}],"checksum":4204777886,"timestamp":"2024-06-01T17:51:23.878189Z"}]}
{"channel":"book","type":"update","data":[{"symbol":"BCH/EUR","bids":[],"asks":[{"price":425.62,"qty":0.00000000},{"price":425.71,"qty":10.92514000}],"checksum":14190486,"timestamp":"2024-06-01T17:51:23.878213Z"}]}
{"channel":"book","type":"update","data":[{"symbol":"BCH/EUR","bids":[],"asks":[{"price":425.30,"qty":5.41973211}],"checksum":3332938013,"timestamp":"2024-06-01T17:51:23.882827Z"}]}
{"channel":"book","type":"update","data":[{"symbol":"BCH/EUR","bids":[{"price":424.98,"qty":2.45000000}],"asks":[],"checksum":534460024,"timestamp":"2024-06-01T17:51:23.890200Z"}]}
{"channel":"book","type":"update","data":[{"symbol":"BCH/EUR","bids":[],"asks":[{"price":425.41,"qty":0.67572891}],"checksum":4150940442,"timestamp":"2024-06-01T17:51:23.902081Z"}]}
{"channel":"book","type":"update","data":[{"symbol":"BCH/EUR","bids":[{"price":424.85,"qty":0.72569042}],"asks":[],"checksum":2529605573,"timestamp":"2024-06-01T17:51:23.902545Z"}]}
{"channel":"book","type":"update","data":[{"symbol":"BCH/EUR","bids":[{"price":424.96,"qty":0.00000000},{"price":424.69,"qty":0.48000000}],"asks":[],"checksum":2956597404,"timestamp":"2024-06-01T17:51:23.930966Z"}]}
{"channel":"book","type":"update","data":[{"symbol":"BCH/EUR","bids":[{"price":424.99,"qty":7.83392088}],"asks":[],"checksum":1886120884,"timestamp":"2024-06-01T17:51:23.936860Z"}]}
{"channel":"book","type":"update","data":[{"symbol":"BCH/EUR","bids":[],"asks":[{"price":425.49,"qty":8.00000000}],"checksum":96959771,"timestamp":"2024-06-01T17:51:23.969563Z"}]}
{"channel":"book","type":"update","data":[{"symbol":"BCH/EUR","bids":[],"asks":[{"price":425.33,"qty":3.88726919}],"checksum":3502362315,"timestamp":"2024-06-01T17:51:23.972866Z"}]}
{"channel":"book","type":"update","data":[{"symbol":"BCH/EUR","bids":[{"price":424.97,"qty":0.00000000},{"price":424.69,"qty":0.48000000}],"asks":[],"checksum":3384011068,"timestamp":"2024-06-01T17:51:23.973175Z"}]}
{"channel":"book","type":"update","data":[{"symbol":"BCH/EUR","bids":[{"price":424.92,"qty":0.00000000},{"price":424.65,"qty":5.42774177}],"asks":[],"checksum":3962161284,"timestamp":"2024-06-01T17:51:24.032741Z"}]}
{"channel":"book","type":"update","data":[{"symbol":"BCH/EUR","bids":[{"price":425.00,"qty":2.00000000}],"asks":[],"checksum":931666654,"timestamp":"2024-06-01T17:51:24.036635Z"}]}
{"channel":"book","type":"update","data":[{"symbol":"BCH/EUR","bids":[],"asks":[{"price":425.41,"qty":0.00000000},{"price":425.57,"qty":1.08600000}],"checksum":4230538789,"timestamp":"2024-06-01T17:51:24.049435Z"}]}
{"channel":"book","type":"update","data":[{"symbol":"BCH/EUR","bids":[],"asks":[{"price":425.33,"qty":0.00000000},{"price":425.63,"qty":12.24000000}],"checksum":414745579,"timestamp":"2024-06-01T17:51:24.050428Z"}]}
{"channel":"book","type":"update","data":[{"symbol":"BCH/EUR","bids":[],"asks":[{"price":425.49,"qty":0.00000000},{"price":425.65,"qty":10.86000000}],"checksum":752944663,"timestamp":"2024-06-01T17:51:24.050501Z"}]}
{"channel":"book","type":"update","data":[{"symbol":"BCH/EUR","bids":[],"asks":[{"price":425.30,"qty":0.00000000},{"price":425.69,"qty":0.35000000}],"checksum":221995870,"timestamp":"2024-06-01T17:51:24.052376Z"}]}
{"channel":"book","type":"update","data":[{"symbol":"BCH/EUR","bids":[],"asks":[{"price":425.51,"qty":6.25147891}],"checksum":3485344008,"timestamp":"2024-06-01T17:51:24.054120Z"}]}
{"channel":"book","type":"update","data":[{"symbol":"BCH/EUR","bids":[{"price":425.00,"qty":2.45000000}],"asks":[],"checksum":4227092660,"timestamp":"2024-06-01T17:51:24.055277Z"}]}
{"channel":"book","type":"update","data":[{"symbol":"BCH/EUR","bids":[{"price":424.98,"qty":2.00000000}],"asks":[],"checksum":4041077978,"timestamp":"2024-06-01T17:51:24.055299Z"}]}
{"channel":"book","type":"update","data":[{"symbol":"BCH/EUR","bids":[{"price":425.00,"qty":6.33726919}],"asks":[],"checksum":2917246668,"timestamp":"2024-06-01T17:51:24.076602Z"}]}
{"channel":"book","type":"update","data":[{"symbol":"BCH/EUR","bids":[{"price":425.00,"qty":5.88726919}],"asks":[],"checksum":3405496698,"timestamp":"2024-06-01T17:51:24.079707Z"}]}
{"channel":"book","type":"update","data":[{"symbol":"BCH/EUR","bids":[{"price":425.01,"qty":0.45000000}],"asks":[],"checksum":628187133,"timestamp":"2024-06-01T17:51:24.079879Z"}]}
{"channel":"book","type":"update","data":[{"symbol":"BCH/EUR","bids":[{"price":425.01,"qty":8.28392088}],"asks":[],"checksum":1792620467,"timestamp":"2024-06-01T17:51:24.080333Z"}]}
{"channel":"book","type":"update","data":[{"symbol":"BCH/EUR","bids":[{"price":424.88,"qty":0.00000000},{"price":424.69,"qty":0.48000000}],"asks":[],"checksum":146247785,"timestamp":"2024-06-01T17:51:24.085673Z"}]}
{"channel":"book","type":"update","data":[{"symbol":"BCH/EUR","bids":[{"price":424.98,"qty":0.00000000},{"price":424.65,"qty":5.42774177}],"asks":[],"checksum":1264215702,"timestamp":"2024-06-01T17:51:24.088476Z"}]}
{"channel":"book","type":"update","data":[{"symbol":"BCH/EUR","bids":[{"price":424.91,"qty":0.00000000},{"price":424.57,"qty":26.82804300}],"asks":[],"checksum":131900861,"timestamp":"2024-06-01T17:51:24.107111Z"}]}
{"channel":"book","type":"update","data":[{"symbol":"BCH/EUR","bids":[{"price":424.99,"qty":0.00000000},{"price":424.52,"qty":0.37000000}],"asks":[],"checksum":1862265860,"timestamp":"2024-06-01T17:51:24.110686Z"}]}
{"channel":"book","type":"update","data":[{"symbol":"BCH/EUR","bids":[{"price":425.02,"qty":2.00000000}],"asks":[],"checksum":3290166224,"timestamp":"2024-06-01T17:51:24.122072Z"}]}
{"channel":"book","type":"update","data":[{"symbol":"BCH/EUR","bids":[],"asks":[{"price":425.52,"qty":0.00000000},{"price":425.69,"qty":0.35000000}],"checksum":2181785317,"timestamp":"2024-06-01T17:51:24.128847Z"}]}
{"channel":"book","type":"update","data":[{"symbol":"BCH/EUR","bids":[{"price":425.00,"qty":3.88726919}],"asks":[],"checksum":2049372086,"timestamp":"2024-06-01T17:51:24.130172Z"}]}
{"channel":"book","type":"update","data":[{"symbol":"BCH/EUR","bids":[{"price":425.02,"qty":5.88726919}],"asks":[],"checksum":1848238013,"timestamp":"2024-06-01T17:51:24.142742Z"}]}
{"channel":"book","type":"update","data":[{"symbol":"BCH/EUR","bids":[],"asks":[{"price":425.42,"qty":3.88726919}],"checksum":1480780011,"timestamp":"2024-06-01T17:51:24.230880Z"}]}
{"channel":"book","type":"update","data":[{"symbol":"BCH/EUR","bids":[{"price":425.00,"qty":0.00000000},{"price":424.52,"qty":0.37000000}],"asks":[],"checksum":39428409,"timestamp":"2024-06-01T17:51:24.230892Z"}]}
{"channel":"book","type":"update","data":[{"symbol":"BCH/EUR","bids":[],"asks":[{"price":425.58,"qty":8.00000000}],"checksum":302288755,"timestamp":"2024-06-01T17:51:24.238723Z"}]}
{"channel":"book","type":"update","data":[{"symbol":"BCH/EUR","bids":[{"price":425.10,"qty":1.10000000}],"asks":[],"checksum":3606354924,"timestamp":"2024-06-01T17:51:24.257676Z"}]}
{"channel":"book","type":"update","data":[{"symbol":"BCH/EUR","bids":[],"asks":[{"price":425.40,"qty":0.03152465}],"checksum":1425008382,"timestamp":"2024-06-01T17:51:24.407558Z"}]}
{"channel":"book","type":"update","data":[{"symbol":"BCH/EUR","bids":[{"price":425.11,"qty":2.00000000}],"asks":[],"checksum":3096774783,"timestamp":"2024-06-01T17:51:24.412619Z"}]}
{"channel":"book","type":"update","data":[{"symbol":"BCH/EUR","bids":[],"asks":[{"price":425.40,"qty":0.00000000},{"price":425.63,"qty":12.24000000}],"checksum":2870795049,"timestamp":"2024-06-01T17:51:24.418531Z"}]}
{"channel":"book","type":"update","data":[{"symbol":"BCH/EUR","bids":[],"asks":[{"price":425.32,"qty":7.83392088}],"checksum":3804852631,"timestamp":"2024-06-01T17:51:24.508967Z"}]}
{"channel":"book","type":"update","data":[{"symbol":"BCH/EUR","bids":[{"price":424.97,"qty":8.00000000}],"asks":[],"checksum":2796680867,"timestamp":"2024-06-01T17:51:24.515432Z"}]}
{"channel":"book","type":"update","data":[{"symbol":"BCH/EUR","bids":[{"price":425.02,"qty":3.88726919}],"asks":[],"checksum":3918974078,"timestamp":"2024-06-01T17:51:24.515692Z"}]}
{"channel":"book","type":"update","data":[{"symbol":"BCH/EUR","bids":[],"asks":[{"price":425.40,"qty":0.03152465}],"checksum":2497594091,"timestamp":"2024-06-01T17:51:24.603866Z"}]}
{"channel":"book","type":"update","data":[{"symbol":"BCH/EUR","bids":[{"price":424.95,"qty":0.09892917}],"asks":[],"checksum":3042787876,"timestamp":"2024-06-01T17:51:24.604230Z"}]}
{"channel":"book","type":"update","data":[{"symbol":"BCH/EUR","bids":[{"price":425.11,"qty":0.00000000},{"price":424.69,"qty":0.48000000}],"asks":[],"checksum":403139596,"timestamp":"2024-06-01T17:51:24.802750Z"}]}
{"channel":"book","type":"update","data":[{"symbol":"BCH/EUR","bids":[{"price":424.97,"qty":0.00000000},{"price":424.65,"qty":5.42774177}],"asks":[],"checksum":2861962531,"timestamp":"2024-06-01T17:51:24.802812Z"}]}
{"channel":"book","type":"update","data":[{"symbol":"BCH/EUR","bids":[{"price":425.02,"qty":0.00000000},{"price":424.57,"qty":26.82804300}],"asks":[],"checksum":398991231,"timestamp":"2024-06-01T17:51:24.803227Z"}]}
{"channel":"book","type":"update","data":[{"symbol":"BCH/EUR","bids":[],"asks":[{"price":425.49,"qty":8.00000000}],"checksum":423767508,"timestamp":"2024-06-01T17:51:24.807570Z"}]}
{"channel":"book","type":"update","data":[{"symbol":"BCH/EUR","bids":[],"asks":[{"price":425.33,"qty":3.88726919}],"checksum":2265396819,"timestamp":"2024-06-01T17:51:24.808381Z"}]}
{"channel":"book","type":"update","data":[{"symbol":"BCH/EUR","bids":[{"price":424.95,"qty":0.00000000},{"price":424.52,"qty":0.37000000}],"asks":[],"checksum":3921730765,"timestamp":"2024-06-01T17:51:24.825538Z"}]}
{"channel":"book","type":"update","data":[{"symbol":"BCH/EUR","bids":[],"asks":[{"price":425.40,"qty":0.00000000},{"price":425.56,"qty":0.10173817}],"checksum":1769558172,"timestamp":"2024-06-01T17:51:24.826317Z"}]}
{"channel":"book","type":"update","data":[{"symbol":"BCH/EUR","bids":[],"asks":[{"price":425.27,"qty":0.00000000},{"price":425.57,"qty":1.08600000}],"checksum":1434888124,"timestamp":"2024-06-01T17:51:24.877365Z"}]}
{"channel":"book","type":"update","data":[{"symbol":"BCH/EUR","bids":[],"asks":[{"price":425.24,"qty":0.00000000},{"price":425.58,"qty":8.00000000}],"checksum":3069026762,"timestamp":"2024-06-01T17:51:24.880232Z"}]}
{"channel":"book","type":"update","data":[{"symbol":"BCH/EUR","bids":[],"asks":[{"price":425.39,"qty":15.96804300}],"checksum":3003754548,"timestamp":"2024-06-01T17:51:24.880274Z"}]}
{"channel":"book","type":"update","data":[{"symbol":"BCH/EUR","bids":[],"asks":[{"price":425.30,"qty":0.45000000}],"checksum":1419472684,"timestamp":"2024-06-01T17:51:24.880354Z"}]}
{"channel":"book","type":"update","data":[{"symbol":"BCH/EUR","bids":[],"asks":[{"price":425.42,"qty":0.00000000},{"price":425.57,"qty":1.08600000}],"checksum":2393867198,"timestamp":"2024-06-01T17:51:24.884637Z"}]}
{"channel":"book","type":"update","data":[{"symbol":"BCH/EUR","bids":[{"price":425.01,"qty":0.45000000}],"asks":[],"checksum":1868733647,"timestamp":"2024-06-01T17:51:25.092869Z"}]}
{"channel":"book","type":"update","data":[{"symbol":"BCH/EUR","bids":[{"price":425.01,"qty":0.00000000},{"price":424.50,"qty":12.24000000}],"asks":[],"checksum":2642994219,"timestamp":"2024-06-01T17:51:25.095980Z"}]}
{"channel":"book","type":"update","data":[{"symbol":"BCH/EUR","bids":[{"price":424.95,"qty":0.45000000}],"asks":[],"checksum":965411558,"timestamp":"2024-06-01T17:51:25.096239Z"}]}
{"channel":"book","type":"update","data":[{"symbol":"BCH/EUR","bids":[{"price":424.81,"qty":8.00000000}],"asks":[],"checksum":3401430632,"timestamp":"2024-06-01T17:51:25.098396Z"}]}
{"channel":"book","type":"update","data":[{"symbol":"BCH/EUR","bids":[],"asks":[{"price":425.29,"qty":3.88726919}],"checksum":3387608824,"timestamp":"2024-06-01T17:51:25.099196Z"}]}
{"channel":"book","type":"update","data":[{"symbol":"BCH/EUR","bids":[{"price":424.89,"qty":3.88726919}],"asks":[],"checksum":911716980,"timestamp":"2024-06-01T17:51:25.099450Z"}]}
{"channel":"book","type":"update","data":[{"symbol":"BCH/EUR","bids":[],"asks":[{"price":425.30,"qty":0.00000000},{"price":425.57,"qty":1.08600000}],"checksum":3618292641,"timestamp":"2024-06-01T17:51:25.102251Z"}]}
{"channel":"book","type":"update","data":[{"symbol":"BCH/EUR","bids":[],"asks":[{"price":425.27,"qty":0.45000000}],"checksum":733818965,"timestamp":"2024-06-01T17:51:25.102415Z"}]}
{"channel":"book","type":"update","data":[{"symbol":"BCH/EUR","bids":[{"price":424.90,"qty":8.00000000}],"asks":[],"checksum":1026008766,"timestamp":"2024-06-01T17:51:25.135226Z"}]}
{"channel":"book","type":"update","data":[{"symbol":"BCH/EUR","bids":[{"price":424.81,"qty":0.00000000},{"price":424.65,"qty":5.42774177}],"asks":[],"checksum":706446152,"timestamp":"2024-06-01T17:51:25.139351Z"}]}
{"channel":"book","type":"update","data":[{"symbol":"BCH/EUR","bids":[],"asks":[{"price":425.29,"qty":0.00000000},{"price":425.57,"qty":1.08600000}],"checksum":3689963463,"timestamp":"2024-06-01T17:51:25.140038Z"}]}
{"channel":"book","type":"update","data":[{"symbol":"BCH/EUR","bids":[],"asks":[{"price":425.34,"qty":0.03152465}],"checksum":3551583463,"timestamp":"2024-06-01T17:51:25.206216Z"}]}
{"channel":"book","type":"update","data":[{"symbol":"BCH/EUR","bids":[{"price":424.96,"qty":0.09892684}],"asks":[],"checksum":2363474866,"timestamp":"2024-06-01T17:51:25.207109Z"}]}
{"channel":"book","type":"update","data":[{"symbol":"BCH/EUR","bids":[{"price":424.97,"qty":7.83392088}],"asks":[],"checksum":2966576348,"timestamp":"2024-06-01T17:51:25.210160Z"}]}
{"channel":"book","type":"update","data":[{"symbol":"BCH/EUR","bids":[{"price":424.95,"qty":0.00000000},{"price":424.69,"qty":0.48000000}],"asks":[],"checksum":1507365494,"timestamp":"2024-06-01T17:51:25.212622Z"}]}
{"channel":"book","type":"update","data":[{"symbol":"BCH/EUR","bids":[{"price":424.99,"qty":0.45000000}],"asks":[],"checksum":1671180850,"timestamp":"2024-06-01T17:51:25.212877Z"}]}
{"channel":"book","type":"update","data":[{"symbol":"BCH/EUR","bids":[{"price":425.10,"qty":0.00000000},{"price":424.69,"qty":0.48000000}],"asks":[],"checksum":4024704567,"timestamp":"2024-06-01T17:51:25.226900Z"}]}
{"channel":"book","type":"update","data":[{"symbol":"BCH/EUR","bids":[],"asks":[{"price":425.26,"qty":5.42019119}],"checksum":3632725680,"timestamp":"2024-06-01T17:51:25.427994Z"}]}
{"channel":"book","type":"update","data":[{"symbol":"BCH/EUR","bids":[{"price":424.99,"qty":5.87361725}],"asks":[],"checksum":2771060512,"timestamp":"2024-06-01T17:51:25.428069Z"}]}
{"channel":"book","type":"update","data":[{"symbol":"BCH/EUR","bids":[],"asks":[{"price":425.27,"qty":0.00000000},{"price":425.56,"qty":0.10173817}],"checksum":767407533,"timestamp":"2024-06-01T17:51:25.430708Z"}]}
{"channel":"book","type":"update","data":[{"symbol":"BCH/EUR","bids":[],"asks":[{"price":425.24,"qty":0.45000000}],"checksum":2935041099,"timestamp":"2024-06-01T17:51:25.431019Z"}]}
{"channel":"book","type":"update","data":[{"symbol":"BCH/EUR","bids":[{"price":424.97,"qty":0.00000000},{"price":424.65,"qty":5.42774177}],"asks":[],"checksum":3601338006,"timestamp":"2024-06-01T17:51:25.432290Z"}]}
{"channel":"book","type":"update","data":[{"symbol":"BCH/EUR","bids":[{"price":424.94,"qty":7.83392088}],"asks":[],"checksum":1526104779,"timestamp":"2024-06-01T17:51:25.432350Z"}]}
{"channel":"book","type":"update","data":[{"symbol":"BCH/EUR","bids":[{"price":425.00,"qty":7.83392088}],"asks":[],"checksum":755767398,"timestamp":"2024-06-01T17:51:25.510889Z"}]}
{"channel":"book","type":"update","data":[{"symbol":"BCH/EUR","bids":[{"price":424.99,"qty":0.45000000}],"asks":[],"checksum":3929781729,"timestamp":"2024-06-01T17:51:25.871064Z"}]}
{"channel":"book","type":"update","data":[{"symbol":"BCH/EUR","bids":[{"price":425.00,"qty":0.00000000},{"price":424.69,"qty":0.48000000}],"asks":[],"checksum":762649343,"timestamp":"2024-06-01T17:51:25.874803Z"}]}
{"channel":"book","type":"update","data":[{"symbol":"BCH/EUR","bids":[{"price":424.95,"qty":2.00000000}],"asks":[],"checksum":767525627,"timestamp":"2024-06-01T17:51:26.130491Z"}]}
{"channel":"book","type":"update","data":[{"symbol":"BCH/EUR","bids":[{"price":424.96,"qty":7.93284772}],"asks":[],"checksum":1650604455,"timestamp":"2024-06-01T17:51:26.134282Z"}]}
{"channel":"book","type":"update","data":[{"symbol":"BCH/EUR","bids":[{"price":424.94,"qty":0.00000000},{"price":424.69,"qty":0.48000000}],"asks":[],"checksum":3590609090,"timestamp":"2024-06-01T17:51:26.511867Z"}]}
{"channel":"book","type":"update","data":[{"symbol":"BCH/EUR","bids":[{"price":424.97,"qty":2.00000000}],"asks":[],"checksum":2102477159,"timestamp":"2024-06-01T17:51:26.517019Z"}]}
{"channel":"book","type":"update","data":[{"symbol":"BCH/EUR","bids":[{"price":424.95,"qty":0.00000000},{"price":424.69,"qty":0.48000000}],"asks":[],"checksum":2102388726,"timestamp":"2024-06-01T17:51:26.630540Z"}]}
{"channel":"book","type":"update","data":[{"symbol":"BCH/EUR","bids":[{"price":424.98,"qty":7.83392088}],"asks":[],"checksum":2323124294,"timestamp":"2024-06-01T17:51:26.634810Z"}]}
{"channel":"book","type":"update","data":[{"symbol":"BCH/EUR","bids":[{"price":424.96,"qty":0.09892684}],"asks":[],"checksum":1861386546,"timestamp":"2024-06-01T17:51:27.008088Z"}]}
{"channel":"book","type":"update","data":[{"symbol":"BCH/EUR","bids":[{"price":424.99,"qty":2.45000000}],"asks":[],"checksum":1545674712,"timestamp":"2024-06-01T17:51:27.013183Z"}]}
{"channel":"book","type":"update","data":[{"symbol":"BCH/EUR","bids":[{"price":424.97,"qty":0.00000000},{"price":424.69,"qty":0.48000000}],"asks":[],"checksum":3223018008,"timestamp":"2024-06-01T17:51:27.130133Z"}]}
{"channel":"book","type":"update","data":[{"symbol":"BCH/EUR","bids":[{"price":425.00,"qty":7.83392088}],"asks":[],"checksum":3741037866,"timestamp":"2024-06-01T17:51:27.134180Z"}]}
{"channel":"book","type":"update","data":[{"symbol":"BCH/EUR","bids":[{"price":424.95,"qty":5.42409159}],"asks":[],"checksum":1654137804,"timestamp":"2024-06-01T17:51:27.427341Z"}]}
{"channel":"book","type":"update","data":[{"symbol":"BCH/EUR","bids":[{"price":424.98,"qty":0.00000000},{"price":424.71,"qty":5.42125266}],"asks":[],"checksum":2148952679,"timestamp":"2024-06-01T17:51:27.430987Z"}]}
{"channel":"book","type":"update","data":[{"symbol":"BCH/EUR","bids":[{"price":425.01,"qty":2.00000000}],"asks":[],"checksum":521791820,"timestamp":"2024-06-01T17:51:27.432460Z"}]}
{"channel":"book","type":"update","data":[{"symbol":"BCH/EUR","bids":[{"price":425.02,"qty":7.83392088}],"asks":[],"checksum":2170347120,"timestamp":"2024-06-01T17:51:27.513731Z"}]}
{"channel":"book","type":"update","data":[{"symbol":"BCH/EUR","bids":[{"price":425.01,"qty":0.00000000},{"price":424.80,"qty":10.85070170}],"asks":[],"checksum":1409884535,"timestamp":"2024-06-01T17:51:27.518644Z"}]}
{"channel":"book","type":"update","data":[{"symbol":"BCH/EUR","bids":[{"price":425.10,"qty":1.05000000}],"asks":[],"checksum":1854208721,"timestamp":"2024-06-01T17:51:27.559194Z"}]}
{"channel":"book","type":"update","data":[{"symbol":"BCH/EUR","bids":[{"price":425.02,"qty":0.00000000},{"price":424.80,"qty":10.85070170}],"asks":[],"checksum":1387392506,"timestamp":"2024-06-01T17:51:27.562895Z"}]}
{"channel":"book","type":"update","data":[{"symbol":"BCH/EUR","bids":[{"price":425.01,"qty":0.45000000}],"asks":[],"checksum":425337570,"timestamp":"2024-06-01T17:51:28.031365Z"}]}
{"channel":"book","type":"update","data":[{"symbol":"BCH/EUR","bids":[{"price":424.99,"qty":2.00000000}],"asks":[],"checksum":202911349,"timestamp":"2024-06-01T17:51:28.031543Z"}]}
{"channel":"book","type":"update","data":[{"symbol":"BCH/EUR","bids":[{"price":424.90,"qty":0.00000000},{"price":424.80,"qty":10.85070170}],"asks":[],"checksum":1154254204,"timestamp":"2024-06-01T17:51:28.065115Z"}]}
{"channel":"book","type":"update","data":[{"symbol":"BCH/EUR","bids":[{"price":425.10,"qty":0.00000000},{"price":424.71,"qty":5.42125266}],"asks":[],"checksum":2673820399,"timestamp":"2024-06-01T17:51:28.324098Z"}]}
{"channel":"book","type":"update","data":[{"symbol":"BCH/EUR","bids":[{"price":424.99,"qty":0.00000000},{"price":424.69,"qty":0.48000000}],"asks":[],"checksum":3747200249,"timestamp":"2024-06-01T17:51:28.329054Z"}]}
{"channel":"book","type":"update","data":[{"symbol":"BCH/EUR","bids":[{"price":424.96,"qty":7.93284772}],"asks":[],"checksum":754166116,"timestamp":"2024-06-01T17:51:28.511751Z"}]}
{"channel":"book","type":"update","data":[{"symbol":"BCH/EUR","bids":[{"price":425.00,"qty":0.00000000},{"price":424.65,"qty":16.28774177}],"asks":[],"checksum":3517546500,"timestamp":"2024-06-01T17:51:28.511808Z"}]}
{"channel":"book","type":"update","data":[{"symbol":"BCH/EUR","bids":[{"price":424.97,"qty":2.00000000}],"asks":[],"checksum":1980176742,"timestamp":"2024-06-01T17:51:29.129113Z"}]}
{"channel":"book","type":"update","data":[{"symbol":"BCH/EUR","bids":[{"price":424.98,"qty":7.83392088}],"asks":[],"checksum":2087479053,"timestamp":"2024-06-01T17:51:29.132937Z"}]}
{"channel":"book","type":"update","data":[{"symbol":"BCH/EUR","bids":[{"price":424.88,"qty":8.00000000}],"asks":[],"checksum":3403688755,"timestamp":"2024-06-01T17:51:29.136479Z"}]}
{"channel":"book","type":"update","data":[{"symbol":"BCH/EUR","bids":[{"price":424.96,"qty":0.09892684}],"asks":[],"checksum":1648161232,"timestamp":"2024-06-01T17:51:29.509287Z"}]}
{"channel":"book","type":"update","data":[{"symbol":"BCH/EUR","bids":[{"price":424.99,"qty":2.00000000}],"asks":[],"checksum":3663096895,"timestamp":"2024-06-01T17:51:29.514674Z"}]}
{"channel":"book","type":"update","data":[{"symbol":"BCH/EUR","bids":[{"price":424.97,"qty":0.00000000},{"price":424.80,"qty":10.85070170}],"asks":[],"checksum":1421941124,"timestamp":"2024-06-01T17:51:29.628101Z"}]}
{"channel":"book","type":"update","data":[{"symbol":"BCH/EUR","bids":[{"price":425.00,"qty":7.83392088}],"asks":[],"checksum":3410655325,"timestamp":"2024-06-01T17:51:29.632003Z"}]}
{"channel":"book","type":"update","data":[{"symbol":"BCH/EUR","bids":[{"price":424.88,"qty":0.00000000},{"price":424.80,"qty":10.85070170}],"asks":[],"checksum":592580410,"timestamp":"2024-06-01T17:51:29.633758Z"}]}
{"channel":"book","type":"update","data":[{"symbol":"BCH/EUR","bids":[{"price":424.98,"qty":0.00000000},{"price":424.71,"qty":5.42125266}],"asks":[],"checksum":2673820399,"timestamp":"2024-06-01T17:51:30.010541Z"}]}
{"channel":"book","type":"update","data":[{"symbol":"BCH/EUR","bids":[{"price":424.88,"qty":8.00000000}],"asks":[],"checksum":701697745,"timestamp":"2024-06-01T17:51:30.018883Z"}]}
{"channel":"book","type":"update","data":[{"symbol":"BCH/EUR","bids":[{"price":425.01,"qty":2.45000000}],"asks":[],"checksum":3286895282,"timestamp":"2024-06-01T17:51:30.022342Z"}]}
{"channel":"book","type":"update","data":[{"symbol":"BCH/EUR","bids":[{"price":424.99,"qty":0.00000000},{"price":424.71,"qty":5.42125266}],"asks":[],"checksum":1882738360,"timestamp":"2024-06-01T17:51:30.131525Z"}]}
{"channel":"book","type":"update","data":[{"symbol":"BCH/EUR","bids":[{"price":425.02,"qty":7.83392088}],"asks":[],"checksum":3632916486,"timestamp":"2024-06-01T17:51:30.136448Z"}]}
{"channel":"book","type":"update","data":[{"symbol":"BCH/EUR","bids":[{"price":425.00,"qty":0.00000000},{"price":424.71,"qty":5.42125266}],"asks":[],"checksum":809938368,"timestamp":"2024-06-01T17:51:30.509229Z"}]}
{"channel":"book","type":"update","data":[{"symbol":"BCH/EUR","bids":[{"price":425.03,"qty":2.00000000}],"asks":[],"checksum":4262413208,"timestamp":"2024-06-01T17:51:30.515162Z"}]}
{"channel":"book","type":"update","data":[{"symbol":"BCH/EUR","bids":[{"price":425.01,"qty":0.45000000}],"asks":[],"checksum":257320793,"timestamp":"2024-06-01T17:51:30.630374Z"}]}
{"channel":"book","type":"update","data":[{"symbol":"BCH/EUR","bids":[{"price":424.94,"qty":10.84916237}],"asks":[],"checksum":2688342203,"timestamp":"2024-06-01T17:51:34.333024Z"}]}
{"channel":"book","type":"update","data":[{"symbol":"BCH/EUR","bids":[{"price":424.98,"qty":10.84916237}],"asks":[],"checksum":330986124,"timestamp":"2024-06-01T17:51:34.334499Z"}]}
{"channel":"book","type":"update","data":[{"symbol":"BCH/EUR","bids":[{"price":424.93,"qty":0.00000000},{"price":424.85,"qty":0.72569042}],"asks":[],"checksum":416469978,"timestamp":"2024-06-01T17:51:34.337733Z"}]}
{"channel":"book","type":"update","data":[{"symbol":"BCH/EUR","bids":[{"price":424.94,"qty":0.00000000},{"price":424.80,"qty":10.85070170}],"asks":[],"checksum":3065943814,"timestamp":"2024-06-01T17:51:34.338050Z"}]}
{"channel":"book","type":"update","data":[{"symbol":"BCH/EUR","bids":[{"price":424.98,"qty":0.00000000},{"price":424.71,"qty":5.42125266}],"asks":[],"checksum":1491420394,"timestamp":"2024-06-01T17:51:34.714421Z"}]}
{"channel":"book","type":"update","data":[{"symbol":"BCH/EUR","bids":[{"price":424.97,"qty":10.84916237}],"asks":[],"checksum":994446595,"timestamp":"2024-06-01T17:51:34.963840Z"}]}
{"channel":"book","type":"update","data":[{"symbol":"BCH/EUR","bids":[],"asks":[{"price":425.26,"qty":0.00000000},{"price":425.59,"qty":7.83392088}],"checksum":1700683100,"timestamp":"2024-06-01T17:51:40.090920Z"}]}
{"channel":"book","type":"update","data":[{"symbol":"BCH/EUR","bids":[{"price":424.98,"qty":10.84915735}],"asks":[],"checksum":15518980,"timestamp":"2024-06-01T17:51:40.092835Z"}]}
{"channel":"book","type":"update","data":[{"symbol":"BCH/EUR","bids":[],"asks":[{"price":425.24,"qty":0.00000000},{"price":425.62,"qty":0.10172711}],"checksum":1173427574,"timestamp":"2024-06-01T17:51:40.094976Z"}]}
{"channel":"book","type":"update","data":[{"symbol":"BCH/EUR","bids":[],"asks":[{"price":425.30,"qty":0.45000000}],"checksum":3538303311,"timestamp":"2024-06-01T17:51:40.095400Z"}]}
{"channel":"book","type":"update","data":[{"symbol":"BCH/EUR","bids":[],"asks":[{"price":425.23,"qty":5.42055616}],"checksum":2140707769,"timestamp":"2024-06-01T17:51:40.096135Z"}]}
{"channel":"book","type":"update","data":[{"symbol":"BCH/EUR","bids":[],"asks":[{"price":425.23,"qty":0.00000000},{"price":425.59,"qty":7.83392088}],"checksum":3538303311,"timestamp":"2024-06-01T17:51:40.102051Z"}]}
{"channel":"book","type":"update","data":[{"symbol":"BCH/EUR","bids":[],"asks":[{"price":425.51,"qty":0.00000000},{"price":425.62,"qty":0.10172711}],"checksum":3934581099,"timestamp":"2024-06-01T17:51:40.103332Z"}]}
{"channel":"book","type":"update","data":[{"symbol":"BCH/EUR","bids":[{"price":424.85,"qty":0.00000000},{"price":424.80,"qty":10.85070170}],"asks":[],"checksum":1542276892,"timestamp":"2024-06-01T17:51:40.103426Z"}]}
{"channel":"book","type":"update","data":[{"symbol":"BCH/EUR","bids":[{"price":424.85,"qty":0.72730007}],"asks":[],"checksum":111321361,"timestamp":"2024-06-01T17:51:40.108794Z"}]}
{"channel":"book","type":"update","data":[{"symbol":"BCH/EUR","bids":[],"asks":[{"price":425.41,"qty":1.31922891}],"checksum":1906990631,"timestamp":"2024-06-01T17:51:40.108808Z"}]}
{"channel":"book","type":"update","data":[{"symbol":"BCH/EUR","bids":[{"price":424.97,"qty":0.00000000},{"price":424.80,"qty":10.85070170}],"asks":[],"checksum":810477024,"timestamp":"2024-06-01T17:51:40.119809Z"}]}
{"channel":"book","type":"update","data":[{"symbol":"BCH/EUR","bids":[{"price":424.98,"qty":0.00000000},{"price":424.71,"qty":5.42125266}],"asks":[],"checksum":1918173806,"timestamp":"2024-06-01T17:51:40.138759Z"}]}
{"channel":"book","type":"update","data":[{"symbol":"BCH/EUR","bids":[],"asks":[{"price":425.58,"qty":0.10173527}],"checksum":2703034072,"timestamp":"2024-06-01T17:51:40.205679Z"}]}
{"channel":"book","type":"update","data":[{"symbol":"BCH/EUR","bids":[{"price":424.98,"qty":10.84916460}],"asks":[],"checksum":2353802389,"timestamp":"2024-06-01T17:51:40.235692Z"}]}
{"channel":"book","type":"update","data":[{"symbol":"BCH/EUR","bids":[{"price":424.98,"qty":0.00000000},{"price":424.71,"qty":5.42125266}],"asks":[],"checksum":2703034072,"timestamp":"2024-06-01T17:51:40.295167Z"}]}
{"channel":"book","type":"update","data":[{"symbol":"BCH/EUR","bids":[],"asks":[{"price":425.29,"qty":0.43356802}],"checksum":585238935,"timestamp":"2024-06-01T17:51:40.330964Z"}]}
{"channel":"book","type":"update","data":[{"symbol":"BCH/EUR","bids":[],"asks":[{"price":425.49,"qty":0.00000000},{"price":425.58,"qty":0.10173527}],"checksum":931800007,"timestamp":"2024-06-01T17:51:40.336777Z"}]}
{"channel":"book","type":"update","data":[{"symbol":"BCH/EUR","bids":[{"price":425.02,"qty":0.00000000},{"price":424.69,"qty":0.48000000}],"asks":[],"checksum":887155321,"timestamp":"2024-06-01T17:51:40.563946Z"}]}
{"channel":"book","type":"update","data":[{"symbol":"BCH/EUR","bids":[{"price":424.88,"qty":0.00000000},{"price":424.65,"qty":5.42774177}],"asks":[],"checksum":1742914781,"timestamp":"2024-06-01T17:51:40.568103Z"}]}
{"channel":"book","type":"update","data":[{"symbol":"BCH/EUR","bids":[{"price":425.03,"qty":0.00000000},{"price":424.57,"qty":15.96804300}],"asks":[],"checksum":620197803,"timestamp":"2024-06-01T17:51:40.568736Z"}]}
{"channel":"book","type":"update","data":[{"symbol":"BCH/EUR","bids":[{"price":424.86,"qty":0.43368500}],"asks":[],"checksum":1606802022,"timestamp":"2024-06-01T17:51:40.572388Z"}]}
{"channel":"book","type":"update","data":[{"symbol":"BCH/EUR","bids":[],"asks":[{"price":425.50,"qty":25.93332600}],"checksum":2363276122,"timestamp":"2024-06-01T17:51:40.704405Z"}]}
{"channel":"book","type":"update","data":[{"symbol":"BCH/EUR","bids":[{"price":424.95,"qty":0.00000000},{"price":424.57,"qty":15.96804300}],"asks":[],"checksum":695095793,"timestamp":"2024-06-01T17:51:40.863188Z"}]}
{"channel":"book","type":"update","data":[{"symbol":"BCH/EUR","bids":[{"price":424.90,"qty":5.42466746}],"asks":[],"checksum":1276998100,"timestamp":"2024-06-01T17:51:40.867740Z"}]}
{"channel":"book","type":"update","data":[{"symbol":"BCH/EUR","bids":[],"asks":[{"price":425.21,"qty":5.42089075}],"checksum":487658871,"timestamp":"2024-06-01T17:51:40.867766Z"}]}
{"channel":"book","type":"update","data":[{"symbol":"BCH/EUR","bids":[],"asks":[{"price":425.20,"qty":0.45000000}],"checksum":575916329,"timestamp":"2024-06-01T17:51:40.870495Z"}]}
{"channel":"book","type":"update","data":[{"symbol":"BCH/EUR","bids":[],"asks":[{"price":425.30,"qty":0.00000000},{"price":425.54,"qty":5.41654689}],"checksum":1832485049,"timestamp":"2024-06-01T17:51:40.870519Z"}]}
{"channel":"book","type":"update","data":[{"symbol":"BCH/EUR","bids":[],"asks":[{"price":425.29,"qty":0.00000000},{"price":425.58,"qty":0.10173527}],"checksum":3026726118,"timestamp":"2024-06-01T17:51:40.871735Z"}]}
{"channel":"book","type":"update","data":[{"symbol":"BCH/EUR","bids":[],"asks":[{"price":425.19,"qty":0.40764252}],"checksum":1984324928,"timestamp":"2024-06-01T17:51:40.875924Z"}]}
{"channel":"book","type":"update","data":[{"symbol":"BCH/EUR","bids":[{"price":424.91,"qty":7.83392088}],"asks":[],"checksum":56276471,"timestamp":"2024-06-01T17:51:41.013981Z"}]}
{"channel":"book","type":"update","data":[{"symbol":"BCH/EUR","bids":[{"price":424.86,"qty":0.00000000},{"price":424.65,"qty":5.42774177}],"asks":[],"checksum":2043462587,"timestamp":"2024-06-01T17:51:41.018565Z"}]}
{"channel":"book","type":"update","data":[{"symbol":"BCH/EUR","bids":[{"price":424.90,"qty":13.42466746}],"asks":[],"checksum":3225706544,"timestamp":"2024-06-01T17:51:41.019556Z"}]}
{"channel":"book","type":"update","data":[{"symbol":"BCH/EUR","bids":[],"asks":[{"price":425.49,"qty":8.00000000}],"checksum":1337481591,"timestamp":"2024-06-01T17:51:41.019712Z"}]}
{"channel":"book","type":"update","data":[{"symbol":"BCH/EUR","bids":[{"price":424.92,"qty":2.00000000}],"asks":[],"checksum":703320031,"timestamp":"2024-06-01T17:51:41.128976Z"}]}
{"channel":"book","type":"update","data":[{"symbol":"BCH/EUR","bids":[{"price":424.93,"qty":7.83392088}],"asks":[],"checksum":43304610,"timestamp":"2024-06-01T17:51:41.133028Z"}]}
{"channel":"book","type":"update","data":[{"symbol":"BCH/EUR","bids":[{"price":424.91,"qty":0.00000000},{"price":424.69,"qty":0.48000000}],"asks":[],"checksum":1511481106,"timestamp":"2024-06-01T17:51:41.509849Z"}]}
{"channel":"book","type":"update","data":[{"symbol":"BCH/EUR","bids":[{"price":424.91,"qty":8.00000000}],"asks":[],"checksum":1724151627,"timestamp":"2024-06-01T17:51:41.514121Z"}]}
{"channel":"book","type":"update","data":[{"symbol":"BCH/EUR","bids":[{"price":424.94,"qty":2.00000000}],"asks":[],"checksum":1809601631,"timestamp":"2024-06-01T17:51:41.522211Z"}]}
{"channel":"book","type":"update","data":[{"symbol":"BCH/EUR","bids":[{"price":424.92,"qty":0.00000000},{"price":424.71,"qty":5.42125266}],"asks":[],"checksum":3174832969,"timestamp":"2024-06-01T17:51:41.628416Z"}]}
{"channel":"book","type":"update","data":[{"symbol":"BCH/EUR","bids":[{"price":424.95,"qty":7.83392088}],"asks":[],"checksum":476156971,"timestamp":"2024-06-01T17:51:41.632424Z"}]}
{"channel":"book","type":"update","data":[{"symbol":"BCH/EUR","bids":[{"price":424.91,"qty":0.00000000},{"price":424.71,"qty":5.42125266}],"asks":[],"checksum":2779803178,"timestamp":"2024-06-01T17:51:41.634621Z"}]}
{"channel":"book","type":"update","data":[{"symbol":"BCH/EUR","bids":[{"price":424.93,"qty":0.00000000},{"price":424.69,"qty":0.48000000}],"asks":[],"checksum":567707356,"timestamp":"2024-06-01T17:51:42.010480Z"}]}
{"channel":"book","type":"update","data":[{"symbol":"BCH/EUR","bids":[{"price":424.91,"qty":8.00000000}],"asks":[],"checksum":442718501,"timestamp":"2024-06-01T17:51:42.015049Z"}]}
{"channel":"book","type":"update","data":[{"symbol":"BCH/EUR","bids":[{"price":424.96,"qty":2.09892684}],"asks":[],"checksum":3506460685,"timestamp":"2024-06-01T17:51:42.015429Z"}]}
{"channel":"book","type":"update","data":[{"symbol":"BCH/EUR","bids":[{"price":424.94,"qty":0.00000000},{"price":424.69,"qty":0.48000000}],"asks":[],"checksum":1287206822,"timestamp":"2024-06-01T17:51:42.130788Z"}]}
{"channel":"book","type":"update","data":[{"symbol":"BCH/EUR","bids":[{"price":424.91,"qty":0.00000000},{"price":424.65,"qty":5.42774177}],"asks":[],"checksum":3804492709,"timestamp":"2024-06-01T17:51:42.133826Z"}]}
{"channel":"book","type":"update","data":[{"symbol":"BCH/EUR","bids":[{"price":424.97,"qty":7.83392088}],"asks":[],"checksum":2005205021,"timestamp":"2024-06-01T17:51:42.134899Z"}]}
{"channel":"book","type":"update","data":[{"symbol":"BCH/EUR","bids":[{"price":424.95,"qty":0.00000000},{"price":424.65,"qty":5.42774177}],"asks":[],"checksum":4103258163,"timestamp":"2024-06-01T17:51:42.511938Z"}]}
{"channel":"book","type":"update","data":[{"symbol":"BCH/EUR","bids":[{"price":424.91,"qty":8.00000000}],"asks":[],"checksum":1525154864,"timestamp":"2024-06-01T17:51:42.517024Z"}]}
{"channel":"book","type":"update","data":[{"symbol":"BCH/EUR","bids":[{"price":424.98,"qty":2.00000000}],"asks":[],"checksum":1202798909,"timestamp":"2024-06-01T17:51:42.517285Z"}]}
{"channel":"book","type":"update","data":[{"symbol":"BCH/EUR","bids":[{"price":424.96,"qty":0.09892684}],"asks":[],"checksum":1563956371,"timestamp":"2024-06-01T17:51:42.627972Z"}]}
{"channel":"book","type":"update","data":[{"symbol":"BCH/EUR","bids":[{"price":424.91,"qty":0.00000000},{"price":424.69,"qty":0.48000000}],"asks":[],"checksum":3360968498,"timestamp":"2024-06-01T17:51:42.635624Z"}]}
{"channel":"book","type":"update","data":[{"symbol":"BCH/EUR","bids":[{"price":424.91,"qty":8.00000000}],"asks":[],"checksum":1563956371,"timestamp":"2024-06-01T17:51:43.135428Z"}]}
{"channel":"book","type":"update","data":[{"symbol":"BCH/EUR","bids":[{"price":424.91,"qty":0.00000000},{"price":424.69,"qty":0.48000000}],"asks":[],"checksum":3360968498,"timestamp":"2024-06-01T17:51:43.139819Z"}]}
{"channel":"book","type":"update","data":[{"symbol":"BCH/EUR","bids":[{"price":424.91,"qty":8.00000000}],"asks":[],"checksum":1563956371,"timestamp":"2024-06-01T17:51:43.632508Z"}]}
{"channel":"book","type":"update","data":[{"symbol":"BCH/EUR","bids":[{"price":424.91,"qty":0.00000000},{"price":424.69,"qty":0.48000000}],"asks":[],"checksum":3360968498,"timestamp":"2024-06-01T17:51:43.636448Z"}]}
{"channel":"book","type":"update","data":[{"symbol":"BCH/EUR","bids":[{"price":424.93,"qty":10.84916460}],"asks":[],"checksum":189320862,"timestamp":"2024-06-01T17:51:43.692890Z"}]}
{"channel":"book","type":"update","data":[{"symbol":"BCH/EUR","bids":[],"asks":[{"price":425.50,"qty":24.84732600}],"checksum":3845699416,"timestamp":"2024-06-01T17:51:43.696674Z"}]}
{"channel":"book","type":"update","data":[{"symbol":"BCH/EUR","bids":[{"price":424.97,"qty":18.68308548}],"asks":[],"checksum":1110851177,"timestamp":"2024-06-01T17:51:43.698163Z"}]}
{"channel":"book","type":"update","data":[{"symbol":"BCH/EUR","bids":[{"price":424.90,"qty":8.00000000}],"asks":[],"checksum":2740971230,"timestamp":"2024-06-01T17:51:43.698307Z"}]}
{"channel":"book","type":"update","data":[{"symbol":"BCH/EUR","bids":[{"price":424.93,"qty":16.27342236}],"asks":[],"checksum":2428963756,"timestamp":"2024-06-01T17:51:43.703998Z"}]}
{"channel":"book","type":"update","data":[{"symbol":"BCH/EUR","bids":[],"asks":[{"price":425.21,"qty":0.00000000},{"price":425.54,"qty":5.41654689}],"checksum":3493026323,"timestamp":"2024-06-01T17:51:43.705886Z"}]}
{"channel":"book","type":"update","data":[{"symbol":"BCH/EUR","bids":[],"asks":[{"price":425.20,"qty":0.00000000},{"price":425.58,"qty":0.10173527}],"checksum":808962108,"timestamp":"2024-06-01T17:51:43.709293Z"}]}
{"channel":"book","type":"update","data":[{"symbol":"BCH/EUR","bids":[],"asks":[{"price":425.30,"qty":0.45000000}],"checksum":3995198761,"timestamp":"2024-06-01T17:51:43.709960Z"}]}
{"channel":"book","type":"update","data":[{"symbol":"BCH/EUR","bids":[],"asks":[{"price":425.26,"qty":5.42025802}],"checksum":1000271190,"timestamp":"2024-06-01T17:51:43.710311Z"}]}
{"channel":"book","type":"update","data":[{"symbol":"BCH/EUR","bids":[],"asks":[{"price":425.19,"qty":0.00000000},{"price":425.54,"qty":5.41654689}],"checksum":2499200786,"timestamp":"2024-06-01T17:51:43.713105Z"}]}
{"channel":"book","type":"update","data":[{"symbol":"BCH/EUR","bids":[],"asks":[{"price":425.30,"qty":0.00000000},{"price":425.58,"qty":0.10173527}],"checksum":1256253959,"timestamp":"2024-06-01T17:51:43.714586Z"}]}
{"channel":"book","type":"update","data":[{"symbol":"BCH/EUR","bids":[],"asks":[{"price":425.24,"qty":0.45000000}],"checksum":1261764902,"timestamp":"2024-06-01T17:51:43.714737Z"}]}
{"channel":"book","type":"update","data":[{"symbol":"BCH/EUR","bids":[],"asks":[{"price":425.25,"qty":0.43356802}],"checksum":2174816570,"timestamp":"2024-06-01T17:51:43.721749Z"}]}
{"channel":"book","type":"update","data":[{"symbol":"BCH/EUR","bids":[{"price":424.93,"qty":10.84916460}],"asks":[],"checksum":2990144584,"timestamp":"2024-06-01T17:51:43.724106Z"}]}
{"channel":"book","type":"update","data":[{"symbol":"BCH/EUR","bids":[],"asks":[{"price":425.25,"qty":0.00000000},{"price":425.54,"qty":5.41654689}],"checksum":2024664148,"timestamp":"2024-06-01T17:51:43.727519Z"}]}
{"channel":"book","type":"update","data":[{"symbol":"BCH/EUR","bids":[{"price":424.99,"qty":7.83392088}],"asks":[],"checksum":2518791081,"timestamp":"2024-06-01T17:51:43.737147Z"}]}
{"channel":"book","type":"update","data":[{"symbol":"BCH/EUR","bids":[{"price":424.99,"qty":18.68308548}],"asks":[],"checksum":2765971090,"timestamp":"2024-06-01T17:51:43.737642Z"}]}
{"channel":"book","type":"update","data":[{"symbol":"BCH/EUR","bids":[{"price":424.93,"qty":0.00000000},{"price":424.71,"qty":5.42125266}],"asks":[],"checksum":695818489,"timestamp":"2024-06-01T17:51:43.753063Z"}]}
{"channel":"book","type":"update","data":[{"symbol":"BCH/EUR","bids":[{"price":424.97,"qty":7.83392088}],"asks":[],"checksum":4125925684,"timestamp":"2024-06-01T17:51:43.759740Z"}]}
{"channel":"book","type":"update","data":[{"symbol":"BCH/EUR","bids":[{"price":424.97,"qty":0.00000000},{"price":424.69,"qty":0.48000000}],"asks":[],"checksum":3614422358,"timestamp":"2024-06-01T17:51:43.763441Z"}]}
{"channel":"book","type":"update","data":[{"symbol":"BCH/EUR","bids":[{"price":424.98,"qty":0.00000000},{"price":424.65,"qty":5.42774177}],"asks":[],"checksum":530642888,"timestamp":"2024-06-01T17:51:43.770509Z"}]}
{"channel":"book","type":"update","data":[{"symbol":"BCH/EUR","bids":[{"price":424.99,"qty":7.83392088}],"asks":[],"checksum":3515023072,"timestamp":"2024-06-01T17:51:43.785072Z"}]}
{"channel":"book","type":"update","data":[{"symbol":"BCH/EUR","bids":[{"price":424.66,"qty":10.86000000}],"asks":[],"checksum":3026538227,"timestamp":"2024-06-01T17:51:43.787933Z"}]}
{"channel":"book","type":"update","data":[{"symbol":"BCH/EUR","bids":[{"price":424.91,"qty":0.43363486}],"asks":[],"checksum":1436855288,"timestamp":"2024-06-01T17:51:43.789258Z"}]}
{"channel":"book","type":"update","data":[{"symbol":"BCH/EUR","bids":[],"asks":[{"price":425.49,"qty":0.00000000},{"price":425.58,"qty":0.10173527}],"checksum":2219479967,"timestamp":"2024-06-01T17:51:43.816560Z"}]}
{"channel":"book","type":"update","data":[{"symbol":"BCH/EUR","bids":[],"asks":[{"price":425.33,"qty":0.00000000},{"price":425.59,"qty":8.91992088}],"checksum":3350114542,"timestamp":"2024-06-01T17:51:43.817537Z"}]}
{"channel":"book","type":"update","data":[{"symbol":"BCH/EUR","bids":[],"asks":[{"price":425.41,"qty":0.00000000},{"price":425.63,"qty":12.24000000}],"checksum":3291476360,"timestamp":"2024-06-01T17:51:43.817788Z"}]}
{"channel":"book","type":"update","data":[{"symbol":"BCH/EUR","bids":[],"asks":[{"price":425.51,"qty":3.45747891}],"checksum":3504173157,"timestamp":"2024-06-01T17:51:43.822456Z"}]}
{"channel":"book","type":"update","data":[{"symbol":"BCH/EUR","bids":[],"asks":[{"price":425.26,"qty":0.00000000},{"price":425.63,"qty":12.24000000}],"checksum":3777766200,"timestamp":"2024-06-01T17:51:43.822734Z"}]}
{"channel":"book","type":"update","data":[{"symbol":"BCH/EUR","bids":[{"price":424.97,"qty":8.00000000}],"asks":[],"checksum":3613736127,"timestamp":"2024-06-01T17:51:43.822869Z"}]}
{"channel":"book","type":"update","data":[{"symbol":"BCH/EUR","bids":[],"asks":[{"price":425.24,"qty":0.00000000},{"price":425.69,"qty":0.35000000}],"checksum":906792867,"timestamp":"2024-06-01T17:51:43.825554Z"}]}
{"channel":"book","type":"update","data":[{"symbol":"BCH/EUR","bids":[],"asks":[{"price":425.30,"qty":0.45000000}],"checksum":3407283131,"timestamp":"2024-06-01T17:51:43.825808Z"}]}
{"channel":"book","type":"update","data":[{"symbol":"BCH/EUR","bids":[{"price":424.91,"qty":0.00000000},{"price":424.69,"qty":0.48000000}],"asks":[],"checksum":3590240837,"timestamp":"2024-06-01T17:51:43.826986Z"}]}
{"channel":"book","type":"update","data":[{"symbol":"BCH/EUR","bids":[],"asks":[{"price":425.34,"qty":0.00000000},{"price":425.69,"qty":0.35000000}],"checksum":1743471440,"timestamp":"2024-06-01T17:51:43.840545Z"}]}
{"channel":"book","type":"update","data":[{"symbol":"BCH/EUR","bids":[{"price":424.96,"qty":0.00000000},{"price":424.65,"qty":5.42774177}],"asks":[],"checksum":1837288341,"timestamp":"2024-06-01T17:51:43.844000Z"}]}
{"channel":"book","type":"update","data":[{"symbol":"BCH/EUR","bids":[{"price":425.02,"qty":3.88726919}],"asks":[],"checksum":3455646502,"timestamp":"2024-06-01T17:51:43.849318Z"}]}
{"channel":"book","type":"update","data":[{"symbol":"BCH/EUR","bids":[{"price":425.03,"qty":0.45000000}],"asks":[],"checksum":3625597726,"timestamp":"2024-06-01T17:51:43.852238Z"}]}
{"channel":"book","type":"update","data":[{"symbol":"BCH/EUR","bids":[{"price":425.01,"qty":0.00000000},{"price":424.69,"qty":0.48000000}],"asks":[],"checksum":421937244,"timestamp":"2024-06-01T17:51:43.852298Z"}]}
{"channel":"book","type":"update","data":[{"symbol":"BCH/EUR","bids":[],"asks":[{"price":425.32,"qty":0.00000000},{"price":425.71,"qty":10.86000000}],"checksum":3108689375,"timestamp":"2024-06-01T17:51:43.853327Z"}]}
{"channel":"book","type":"update","data":[{"symbol":"BCH/EUR","bids":[{"price":425.03,"qty":8.28392088}],"asks":[],"checksum":1070795943,"timestamp":"2024-06-01T17:51:43.853472Z"}]}
{"channel":"book","type":"update","data":[{"symbol":"BCH/EUR","bids":[{"price":424.90,"qty":0.00000000},{"price":424.65,"qty":5.42774177}],"asks":[],"checksum":2414603859,"timestamp":"2024-06-01T17:51:43.854488Z"}]}
{"channel":"book","type":"update","data":[{"symbol":"BCH/EUR","bids":[],"asks":[{"price":425.30,"qty":0.00000000},{"price":425.72,"qty":5.41425969}],"checksum":695468657,"timestamp":"2024-06-01T17:51:43.856243Z"}]}
{"channel":"book","type":"update","data":[{"symbol":"BCH/EUR","bids":[],"asks":[{"price":425.37,"qty":0.45000000}],"checksum":343829780,"timestamp":"2024-06-01T17:51:43.856524Z"}]}
{"channel":"book","type":"update","data":[{"symbol":"BCH/EUR","bids":[],"asks":[{"price":425.63,"qty":0.00000000},{"price":425.72,"qty":5.41425969}],"checksum":1226153823,"timestamp":"2024-06-01T17:51:43.909055Z"}]}
{"channel":"book","type":"update","data":[{"symbol":"BCH/EUR","bids":[],"asks":[{"price":425.59,"qty":1.08600000}],"checksum":1495463784,"timestamp":"2024-06-01T17:51:43.926047Z"}]}
{"channel":"book","type":"update","data":[{"symbol":"BCH/EUR","bids":[],"asks":[{"price":425.67,"qty":12.24000000}],"checksum":199416265,"timestamp":"2024-06-01T17:51:43.963403Z"}]}
{"channel":"book","type":"update","data":[{"symbol":"BCH/EUR","bids":[],"asks":[{"price":425.39,"qty":15.99956765}],"checksum":1937979761,"timestamp":"2024-06-01T17:51:44.019674Z"}]}
{"channel":"book","type":"update","data":[{"symbol":"BCH/EUR","bids":[{"price":424.99,"qty":0.00000000},{"price":424.57,"qty":15.96804300}],"asks":[],"checksum":308667648,"timestamp":"2024-06-01T17:51:44.023877Z"}]}
{"channel":"book","type":"update","data":[{"symbol":"BCH/EUR","bids":[{"price":425.00,"qty":8.00000000}],"asks":[],"checksum":4206276121,"timestamp":"2024-06-01T17:51:44.024653Z"}]}
{"channel":"book","type":"update","data":[{"symbol":"BCH/EUR","bids":[],"asks":[{"price":425.58,"qty":8.10173527}],"checksum":3349200139,"timestamp":"2024-06-01T17:51:44.024683Z"}]}
{"channel":"book","type":"update","data":[{"symbol":"BCH/EUR","bids":[{"price":424.89,"qty":0.00000000},{"price":424.57,"qty":15.96804300}],"asks":[],"checksum":1327361574,"timestamp":"2024-06-01T17:51:44.025021Z"}]}
{"channel":"book","type":"update","data":[{"symbol":"BCH/EUR","bids":[],"asks":[{"price":425.43,"qty":3.88726919}],"checksum":1592214942,"timestamp":"2024-06-01T17:51:44.025064Z"}]}
{"channel":"book","type":"update","data":[{"symbol":"BCH/EUR","bids":[{"price":425.02,"qty":3.98618207}],"asks":[],"checksum":2749713960,"timestamp":"2024-06-01T17:51:44.119089Z"}]}
{"channel":"book","type":"update","data":[{"symbol":"BCH/EUR","bids":[{"price":425.00,"qty":0.00000000},{"price":424.52,"qty":0.37000000}],"asks":[],"checksum":527108117,"timestamp":"2024-06-01T17:51:44.123344Z"}]}
{"channel":"book","type":"update","data":[{"symbol":"BCH/EUR","bids":[{"price":425.04,"qty":2.00000000}],"asks":[],"checksum":3802927565,"timestamp":"2024-06-01T17:51:44.124895Z"}]}
{"channel":"book","type":"update","data":[{"symbol":"BCH/EUR","bids":[{"price":425.03,"qty":7.83392088}],"asks":[],"checksum":4110151263,"timestamp":"2024-06-01T17:51:44.127703Z"}]}
{"channel":"book","type":"update","data":[{"symbol":"BCH/EUR","bids":[{"price":425.05,"qty":0.45000000}],"asks":[],"checksum":4098116437,"timestamp":"2024-06-01T17:51:44.127723Z"}]}
{"channel":"book","type":"update","data":[{"symbol":"BCH/EUR","bids":[],"asks":[{"price":425.65,"qty":8.28392088}],"checksum":2854247070,"timestamp":"2024-06-01T17:51:44.256717Z"}]}
{"channel":"book","type":"update","data":[{"symbol":"BCH/EUR","bids":[{"price":424.97,"qty":0.00000000},{"price":424.63,"qty":10.86000000}],"asks":[],"checksum":3414649911,"timestamp":"2024-06-01T17:51:45.136202Z"}]}
{"channel":"book","type":"update","data":[{"symbol":"BCH/EUR","bids":[{"price":424.63,"qty":0.00000000},{"price":424.57,"qty":15.96804300},{"price":424.65,"qty":16.28774177}],"asks":[],"checksum":2093018817,"timestamp":"2024-06-01T17:51:45.139204Z"}]}
{"channel":"book","type":"update","data":[{"symbol":"BCH/EUR","bids":[],"asks":[{"price":425.30,"qty":5.41974797}],"checksum":3562408855,"timestamp":"2024-06-01T17:51:45.139817Z"}]}
{"channel":"book","type":"update","data":[{"symbol":"BCH/EUR","bids":[{"price":425.00,"qty":5.42340177}],"asks":[],"checksum":4202687366,"timestamp":"2024-06-01T17:51:45.139967Z"}]}
{"channel":"book","type":"update","data":[{"symbol":"BCH/EUR","bids":[{"price":424.97,"qty":8.00000000}],"asks":[],"checksum":569182741,"timestamp":"2024-06-01T17:51:45.140821Z"}]}
{"channel":"book","type":"update","data":[{"symbol":"BCH/EUR","bids":[],"asks":[{"price":425.37,"qty":0.00000000},{"price":425.67,"qty":12.24000000}],"checksum":1950237109,"timestamp":"2024-06-01T17:51:45.142418Z"}]}
{"channel":"book","type":"update","data":[{"symbol":"BCH/EUR","bids":[],"asks":[{"price":425.28,"qty":0.45000000}],"checksum":1367191973,"timestamp":"2024-06-01T17:51:45.142611Z"}]}
{"channel":"book","type":"update","data":[{"symbol":"BCH/EUR","bids":[{"price":425.20,"qty":1.83000000}],"asks":[],"checksum":162546570,"timestamp":"2024-06-01T17:51:45.330156Z"}]}
{"channel":"book","type":"update","data":[{"symbol":"BCH/EUR","bids":[],"asks":[{"price":425.34,"qty":7.83392088}],"checksum":3027425961,"timestamp":"2024-06-01T17:51:45.333994Z"}]}
{"channel":"book","type":"update","data":[{"symbol":"BCH/EUR","bids":[{"price":425.03,"qty":18.68165646}],"asks":[],"checksum":1076228200,"timestamp":"2024-06-01T17:51:45.440017Z"}]}
{"channel":"book","type":"update","data":[{"symbol":"BCH/EUR","bids":[{"price":425.00,"qty":16.27113735}],"asks":[],"checksum":1741609009,"timestamp":"2024-06-01T17:51:45.440489Z"}]}
{"channel":"book","type":"update","data":[{"symbol":"BCH/EUR","bids":[{"price":424.80,"qty":0.00000000},{"price":424.69,"qty":0.48000000}],"asks":[],"checksum":2829198426,"timestamp":"2024-06-01T17:51:45.463337Z"}]}
{"channel":"book","type":"update","data":[{"symbol":"BCH/EUR","bids":[{"price":425.03,"qty":7.83392088}],"asks":[],"checksum":725464140,"timestamp":"2024-06-01T17:51:45.914061Z"}]}
{"channel":"book","type":"update","data":[{"symbol":"BCH/EUR","bids":[{"price":425.01,"qty":10.84773558}],"asks":[],"checksum":474717348,"timestamp":"2024-06-01T17:51:45.982103Z"}]}
{"channel":"book","type":"update","data":[{"symbol":"BCH/EUR","bids":[{"price":425.01,"qty":0.00000000},{"price":424.69,"qty":0.48000000}],"asks":[],"checksum":725464140,"timestamp":"2024-06-01T17:51:45.989696Z"}]}
{"channel":"book","type":"update","data":[{"symbol":"BCH/EUR","bids":[{"price":425.00,"qty":5.42340177}],"asks":[],"checksum":4007768395,"timestamp":"2024-06-01T17:51:45.989995Z"}]}
{"channel":"book","type":"update","data":[{"symbol":"BCH/EUR","bids":[{"price":425.02,"qty":3.88726919}],"asks":[],"checksum":1613308825,"timestamp":"2024-06-01T17:51:47.252390Z"}]}
{"channel":"book","type":"update","data":[{"symbol":"BCH/EUR","bids":[{"price":425.01,"qty":0.09891520}],"asks":[],"checksum":2476670811,"timestamp":"2024-06-01T17:51:47.375076Z"}]}
{"channel":"book","type":"update","data":[{"symbol":"BCH/EUR","bids":[{"price":425.20,"qty":0.00000000},{"price":424.69,"qty":0.48000000}],"asks":[],"checksum":3935704381,"timestamp":"2024-06-01T17:51:47.461660Z"}]}
{"channel":"book","type":"update","data":[{"symbol":"BCH/EUR","bids":[{"price":424.97,"qty":0.00000000},{"price":424.65,"qty":5.42774177}],"asks":[],"checksum":3750899786,"timestamp":"2024-06-01T17:51:47.467041Z"}]}
{"channel":"book","type":"update","data":[{"symbol":"BCH/EUR","bids":[{"price":424.97,"qty":8.00000000}],"asks":[],"checksum":3935704381,"timestamp":"2024-06-01T17:51:47.635382Z"}]}
{"channel":"book","type":"update","data":[{"symbol":"BCH/EUR","bids":[],"asks":[{"price":425.58,"qty":8.00000000}],"checksum":565385157,"timestamp":"2024-06-01T17:51:48.261891Z"}]}
{"channel":"book","type":"update","data":[{"symbol":"BCH/EUR","bids":[],"asks":[{"price":425.57,"qty":0.10173578}],"checksum":319786596,"timestamp":"2024-06-01T17:51:48.262248Z"}]}
{"channel":"book","type":"update","data":[{"symbol":"BCH/EUR","bids":[],"asks":[{"price":425.57,"qty":0.00000000},{"price":425.59,"qty":1.08600000}],"checksum":565385157,"timestamp":"2024-06-01T17:51:48.560571Z"}]}
{"channel":"book","type":"update","data":[{"symbol":"BCH/EUR","bids":[],"asks":[{"price":425.57,"qty":0.10173507}],"checksum":4268414044,"timestamp":"2024-06-01T17:51:48.560779Z"}]}
{"channel":"book","type":"update","data":[{"symbol":"BCH/EUR","bids":[{"price":424.97,"qty":0.00000000},{"price":424.65,"qty":5.42774177}],"asks":[],"checksum":3413045547,"timestamp":"2024-06-01T17:51:48.632479Z"}]}
{"channel":"book","type":"update","data":[{"symbol":"BCH/EUR","bids":[{"price":424.97,"qty":8.00000000}],"asks":[],"checksum":4268414044,"timestamp":"2024-06-01T17:51:49.135697Z"}]}
{"channel":"book","type":"update","data":[{"symbol":"BCH/EUR","bids":[{"price":424.99,"qty":10.84773558}],"asks":[],"checksum":1618096771,"timestamp":"2024-06-01T17:51:49.585739Z"}]}
{"channel":"book","type":"update","data":[{"symbol":"BCH/EUR","bids":[{"price":424.96,"qty":10.84773558}],"asks":[],"checksum":3439106052,"timestamp":"2024-06-01T17:51:49.590671Z"}]}
{"channel":"book","type":"update","data":[{"symbol":"BCH/EUR","bids":[],"asks":[{"price":425.30,"qty":0.00000000},{"price":425.59,"qty":1.08600000}],"checksum":3293890831,"timestamp":"2024-06-01T17:51:49.622291Z"}]}
{"channel":"book","type":"update","data":[{"symbol":"BCH/EUR","bids":[{"price":425.00,"qty":0.00000000},{"price":424.71,"qty":5.42125266}],"asks":[],"checksum":1974754547,"timestamp":"2024-06-01T17:51:49.622369Z"}]}
{"channel":"book","type":"update","data":[{"symbol":"BCH/EUR","bids":[{"price":424.99,"qty":0.00000000},{"price":424.69,"qty":0.48000000}],"asks":[],"checksum":4199683220,"timestamp":"2024-06-01T17:51:49.625196Z"}]}
{"channel":"book","type":"update","data":[{"symbol":"BCH/EUR","bids":[{"price":425.04,"qty":7.42296353}],"asks":[],"checksum":2564336621,"timestamp":"2024-06-01T17:51:49.628658Z"}]}
{"channel":"book","type":"update","data":[{"symbol":"BCH/EUR","bids":[],"asks":[{"price":425.35,"qty":5.41913774}],"checksum":4239786440,"timestamp":"2024-06-01T17:51:49.628673Z"}]}
{"channel":"book","type":"update","data":[{"symbol":"BCH/EUR","bids":[],"asks":[{"price":425.28,"qty":0.00000000},{"price":425.59,"qty":1.08600000}],"checksum":2158770759,"timestamp":"2024-06-01T17:51:49.629299Z"}]}
{"channel":"book","type":"update","data":[{"symbol":"BCH/EUR","bids":[],"asks":[{"price":425.32,"qty":0.45000000}],"checksum":2760482675,"timestamp":"2024-06-01T17:51:49.629355Z"}]}
{"channel":"book","type":"update","data":[{"symbol":"BCH/EUR","bids":[],"asks":[{"price":425.39,"qty":15.96804300}],"checksum":94527259,"timestamp":"2024-06-01T17:51:49.636310Z"}]}
{"channel":"book","type":"update","data":[{"symbol":"BCH/EUR","bids":[],"asks":[{"price":425.34,"qty":0.00000000},{"price":425.65,"qty":8.28392088}],"checksum":1403523052,"timestamp":"2024-06-01T17:51:49.651064Z"}]}
{"channel":"book","type":"update","data":[{"symbol":"BCH/EUR","bids":[{"price":425.05,"qty":8.28392088}],"asks":[],"checksum":3402831751,"timestamp":"2024-06-01T17:51:49.651299Z"}]}
{"channel":"book","type":"update","data":[{"symbol":"BCH/EUR","bids":[{"price":425.06,"qty":0.43360020}],"asks":[],"checksum":3976167004,"timestamp":"2024-06-01T17:51:49.679470Z"}]}
{"channel":"book","type":"update","data":[{"symbol":"BCH/EUR","bids":[],"asks":[{"price":425.65,"qty":0.00000000},{"price":425.67,"qty":12.24000000}],"checksum":1018905453,"timestamp":"2024-06-01T17:51:49.694051Z"}]}
{"channel":"book","type":"update","data":[{"symbol":"BCH/EUR","bids":[{"price":425.03,"qty":0.00000000},{"price":424.69,"qty":0.48000000}],"asks":[],"checksum":1584921387,"timestamp":"2024-06-01T17:51:49.702138Z"}]}
{"channel":"book","type":"update","data":[{"symbol":"BCH/EUR","bids":[{"price":425.06,"qty":2.43360020}],"asks":[],"checksum":3935954555,"timestamp":"2024-06-01T17:51:49.712075Z"}]}
{"channel":"book","type":"update","data":[{"symbol":"BCH/EUR","bids":[{"price":425.05,"qty":7.83392088}],"asks":[],"checksum":3279407107,"timestamp":"2024-06-01T17:51:49.717129Z"}]}
{"channel":"book","type":"update","data":[{"symbol":"BCH/EUR","bids":[{"price":425.08,"qty":0.45000000}],"asks":[],"checksum":3996076557,"timestamp":"2024-06-01T17:51:49.717575Z"}]}
{"channel":"book","type":"update","data":[{"symbol":"BCH/EUR","bids":[{"price":425.04,"qty":5.42296353}],"asks":[],"checksum":3052182392,"timestamp":"2024-06-01T17:51:49.745871Z"}]}
{"channel":"book","type":"update","data":[{"symbol":"BCH/EUR","bids":[{"price":425.00,"qty":10.84773558}],"asks":[],"checksum":3915749409,"timestamp":"2024-06-01T17:51:49.747022Z"}]}
{"channel":"book","type":"update","data":[{"symbol":"BCH/EUR","bids":[],"asks":[{"price":425.67,"qty":0.00000000},{"price":425.68,"qty":1.08600000}],"checksum":3133113095,"timestamp":"2024-06-01T17:51:49.791564Z"}]}
{"channel":"book","type":"update","data":[{"symbol":"BCH/EUR","bids":[],"asks":[{"price":425.44,"qty":0.03152465}],"checksum":3268130413,"timestamp":"2024-06-01T17:51:49.816012Z"}]}
{"channel":"book","type":"update","data":[{"symbol":"BCH/EUR","bids":[{"price":424.86,"qty":0.34000000}],"asks":[],"checksum":3625807523,"timestamp":"2024-06-01T17:51:49.952375Z"}]}
{"channel":"book","type":"update","data":[{"symbol":"BCH/EUR","bids":[{"price":425.20,"qty":0.89000000}],"asks":[],"checksum":965286338,"timestamp":"2024-06-01T17:51:49.956321Z"}]}
{"channel":"book","type":"update","data":[{"symbol":"BCH/EUR","bids":[{"price":425.09,"qty":2.00000000}],"asks":[],"checksum":3602538141,"timestamp":"2024-06-01T17:51:49.961871Z"}]}
{"channel":"book","type":"update","data":[{"symbol":"BCH/EUR","bids":[{"price":425.06,"qty":0.43360020}],"asks":[],"checksum":2300045173,"timestamp":"2024-06-01T17:51:50.129733Z"}]}
{"channel":"book","type":"update","data":[{"symbol":"BCH/EUR","bids":[{"price":424.97,"qty":0.00000000},{"price":424.96,"qty":10.84773558}],"asks":[],"checksum":117144323,"timestamp":"2024-06-01T17:51:50.134242Z"}]}
{"channel":"book","type":"update","data":[{"symbol":"BCH/EUR","bids":[{"price":425.20,"qty":0.00000000},{"price":424.86,"qty":0.34000000}],"asks":[],"checksum":3517323633,"timestamp":"2024-06-01T17:51:50.251986Z"}]}
{"channel":"book","type":"update","data":[{"symbol":"BCH/EUR","bids":[{"price":424.97,"qty":8.00000000}],"asks":[],"checksum":542633667,"timestamp":"2024-06-01T17:51:50.256931Z"}]}
{"channel":"book","type":"update","data":[{"symbol":"BCH/EUR","bids":[{"price":425.06,"qty":2.43360020}],"asks":[],"checksum":1428043429,"timestamp":"2024-06-01T17:51:50.630878Z"}]}
{"channel":"book","type":"update","data":[{"symbol":"BCH/EUR","bids":[{"price":425.09,"qty":0.00000000},{"price":424.86,"qty":0.34000000}],"asks":[],"checksum":3625807523,"timestamp":"2024-06-01T17:51:50.630935Z"}]}
{"channel":"book","type":"update","data":[{"symbol":"BCH/EUR","bids":[],"asks":[{"price":425.34,"qty":7.83392088}],"checksum":2443746027,"timestamp":"2024-06-01T17:51:51.509945Z"}]}
{"channel":"book","type":"update","data":[{"symbol":"BCH/EUR","bids":[{"price":425.06,"qty":2.00000000}],"asks":[],"checksum":751102911,"timestamp":"2024-06-01T17:51:53.135740Z"}]}
{"channel":"book","type":"update","data":[{"symbol":"BCH/EUR","bids":[{"price":425.02,"qty":0.00000000},{"price":424.85,"qty":0.72730007}],"asks":[],"checksum":3924783441,"timestamp":"2024-06-01T17:51:53.141751Z"}]}
{"channel":"book","type":"update","data":[{"symbol":"BCH/EUR","bids":[{"price":424.97,"qty":11.88726919}],"asks":[],"checksum":3533022546,"timestamp":"2024-06-01T17:51:53.141785Z"}]}
{"channel":"book","type":"update","data":[{"symbol":"BCH/EUR","bids":[],"asks":[{"price":425.35,"qty":0.00000000},{"price":425.58,"qty":8.00000000}],"checksum":2659818018,"timestamp":"2024-06-01T17:51:53.917298Z"}]}
{"channel":"book","type":"update","data":[{"symbol":"BCH/EUR","bids":[],"asks":[{"price":425.34,"qty":0.00000000},{"price":425.66,"qty":8.28392088}],"checksum":2477129675,"timestamp":"2024-06-01T17:51:53.921149Z"}]}
{"channel":"book","type":"update","data":[{"symbol":"BCH/EUR","bids":[],"asks":[{"price":425.32,"qty":5.86948620}],"checksum":3292180225,"timestamp":"2024-06-01T17:51:53.921791Z"}]}
{"channel":"book","type":"update","data":[{"symbol":"BCH/EUR","bids":[],"asks":[{"price":425.37,"qty":0.45000000}],"checksum":4258286637,"timestamp":"2024-06-01T17:51:53.923977Z"}]}
{"channel":"book","type":"update","data":[{"symbol":"BCH/EUR","bids":[],"asks":[{"price":425.32,"qty":5.41948620}],"checksum":3829193921,"timestamp":"2024-06-01T17:51:53.924130Z"}]}
{"channel":"book","type":"update","data":[{"symbol":"BCH/EUR","bids":[],"asks":[{"price":425.37,"qty":0.00000000},{"price":425.66,"qty":8.28392088}],"checksum":1839197634,"timestamp":"2024-06-01T17:51:53.953744Z"}]}
{"channel":"book","type":"update","data":[{"symbol":"BCH/EUR","bids":[],"asks":[{"price":425.30,"qty":0.45000000}],"checksum":1640043704,"timestamp":"2024-06-01T17:51:53.953818Z"}]}
{"channel":"book","type":"update","data":[{"symbol":"BCH/EUR","bids":[{"price":425.20,"qty":1.86000000}],"asks":[],"checksum":1894712614,"timestamp":"2024-06-01T17:51:54.079847Z"}]}
{"channel":"book","type":"update","data":[{"symbol":"BCH/EUR","bids":[],"asks":[{"price":425.38,"qty":7.83392088}],"checksum":2789303615,"timestamp":"2024-06-01T17:51:54.510501Z"}]}
{"channel":"book","type":"update","data":[{"symbol":"BCH/EUR","bids":[],"asks":[{"price":425.49,"qty":2.00000000}],"checksum":2809576813,"timestamp":"2024-06-01T17:51:54.650193Z"}]}
{"channel":"book","type":"update","data":[{"symbol":"BCH/EUR","bids":[],"asks":[{"price":425.49,"qty":0.00000000},{"price":425.57,"qty":0.10173507}],"checksum":2789303615,"timestamp":"2024-06-01T17:51:56.120652Z"}]}
{"channel":"book","type":"update","data":[{"symbol":"BCH/EUR","bids":[{"price":425.20,"qty":0.00000000},{"price":424.85,"qty":0.72730007}],"asks":[],"checksum":419620120,"timestamp":"2024-06-01T17:51:56.251353Z"}]}
{"channel":"book","type":"update","data":[{"symbol":"BCH/EUR","bids":[{"price":424.85,"qty":0.00000000},{"price":424.71,"qty":5.42125266}],"asks":[],"checksum":875978187,"timestamp":"2024-06-01T17:51:56.257091Z"}]}
{"channel":"book","type":"update","data":[{"symbol":"BCH/EUR","bids":[{"price":424.94,"qty":0.99612274}],"asks":[],"checksum":1647286387,"timestamp":"2024-06-01T17:51:56.259815Z"}]}
{"channel":"book","type":"update","data":[{"symbol":"BCH/EUR","bids":[{"price":425.01,"qty":0.00000000},{"price":424.71,"qty":5.42125266}],"asks":[],"checksum":3446568096,"timestamp":"2024-06-01T17:51:56.360560Z"}]}
{"channel":"book","type":"update","data":[{"symbol":"BCH/EUR","bids":[],"asks":[{"price":425.49,"qty":2.00000000}],"checksum":1208644512,"timestamp":"2024-06-01T17:51:56.392926Z"}]}
{"channel":"book","type":"update","data":[{"symbol":"BCH/EUR","bids":[{"price":425.04,"qty":5.52187175}],"asks":[],"checksum":3275671236,"timestamp":"2024-06-01T17:51:56.481223Z"}]}
{"channel":"book","type":"update","data":[{"symbol":"BCH/EUR","bids":[{"price":425.07,"qty":7.83392088}],"asks":[],"checksum":1877943641,"timestamp":"2024-06-01T17:51:59.017352Z"}]}
{"channel":"book","type":"update","data":[{"symbol":"BCH/EUR","bids":[{"price":425.08,"qty":2.45000000}],"asks":[],"checksum":1675483433,"timestamp":"2024-06-01T17:51:59.023209Z"}]}
{"channel":"book","type":"update","data":[{"symbol":"BCH/EUR","bids":[{"price":425.06,"qty":0.00000000},{"price":424.71,"qty":5.42125266}],"asks":[],"checksum":3347628334,"timestamp":"2024-06-01T17:51:59.128674Z"}]}
{"channel":"book","type":"update","data":[{"symbol":"BCH/EUR","bids":[{"price":425.07,"qty":0.00000000},{"price":424.69,"qty":0.48000000}],"asks":[],"checksum":1071119633,"timestamp":"2024-06-01T17:51:59.132330Z"}]}
{"channel":"book","type":"update","data":[{"symbol":"BCH/EUR","bids":[{"price":425.20,"qty":0.88000000}],"asks":[],"checksum":3949192613,"timestamp":"2024-06-01T17:51:59.154790Z"}]}
{"channel":"book","type":"update","data":[{"symbol":"BCH/EUR","bids":[],"asks":[{"price":425.51,"qty":0.00000000},{"price":425.57,"qty":0.10173507}],"checksum":1863984084,"timestamp":"2024-06-01T17:51:59.157696Z"}]}
{"channel":"book","type":"update","data":[{"symbol":"BCH/EUR","bids":[],"asks":[{"price":425.51,"qty":0.44972891}],"checksum":2872124428,"timestamp":"2024-06-01T17:51:59.160755Z"}]}
{"channel":"book","type":"update","data":[{"symbol":"BCH/EUR","bids":[],"asks":[{"price":425.49,"qty":0.00000000},{"price":425.57,"qty":0.10173507}],"checksum":956251145,"timestamp":"2024-06-01T17:51:59.288616Z"}]}
{"channel":"book","type":"update","data":[{"symbol":"BCH/EUR","bids":[{"price":425.09,"qty":2.00000000}],"asks":[],"checksum":1405114272,"timestamp":"2024-06-01T17:51:59.628422Z"}]}
{"channel":"book","type":"update","data":[{"symbol":"BCH/EUR","bids":[{"price":425.08,"qty":0.45000000}],"asks":[],"checksum":1366834288,"timestamp":"2024-06-01T17:51:59.635835Z"}]}
{"channel":"book","type":"update","data":[{"symbol":"BCH/EUR","bids":[],"asks":[{"price":425.44,"qty":0.00000000},{"price":425.58,"qty":8.00000000}],"checksum":1033589228,"timestamp":"2024-06-01T17:52:00.113599Z"}]}
{"channel":"book","type":"update","data":[{"symbol":"BCH/EUR","bids":[],"asks":[{"price":425.44,"qty":0.03152465}],"checksum":1366834288,"timestamp":"2024-06-01T17:52:00.264698Z"}]}
{"channel":"book","type":"update","data":[{"symbol":"BCH/EUR","bids":[{"price":425.20,"qty":0.00000000},{"price":424.71,"qty":5.42125266}],"asks":[],"checksum":3620794134,"timestamp":"2024-06-01T17:52:00.287053Z"}]}
{"channel":"book","type":"update","data":[{"symbol":"BCH/EUR","bids":[{"price":425.09,"qty":0.00000000},{"price":424.69,"qty":0.48000000}],"asks":[],"checksum":4045267645,"timestamp":"2024-06-01T17:52:00.293178Z"}]}
{"channel":"book","type":"update","data":[{"symbol":"BCH/EUR","bids":[{"price":425.06,"qty":2.00000000}],"asks":[],"checksum":279060328,"timestamp":"2024-06-01T17:52:00.293365Z"}]}
{"channel":"book","type":"update","data":[{"symbol":"BCH/EUR","bids":[{"price":424.71,"qty":0.00000000},{"price":424.69,"qty":0.48000000}],"asks":[],"checksum":790668330,"timestamp":"2024-06-01T17:52:00.304203Z"}]}
{"channel":"book","type":"update","data":[{"symbol":"BCH/EUR","bids":[{"price":425.07,"qty":0.43358274}],"asks":[],"checksum":2555260618,"timestamp":"2024-06-01T17:52:00.337207Z"}]}
{"channel":"book","type":"update","data":[{"symbol":"BCH/EUR","bids":[{"price":425.07,"qty":8.26750362}],"asks":[],"checksum":3407301155,"timestamp":"2024-06-01T17:52:00.341547Z"}]}
{"channel":"book","type":"update","data":[{"symbol":"BCH/EUR","bids":[],"asks":[{"price":425.51,"qty":2.44972891}],"checksum":705727914,"timestamp":"2024-06-01T17:52:00.450650Z"}]}
{"channel":"book","type":"update","data":[{"symbol":"BCH/EUR","bids":[{"price":425.05,"qty":0.00000000},{"price":424.69,"qty":0.48000000}],"asks":[],"checksum":48433538,"timestamp":"2024-06-01T17:52:00.507471Z"}]}
{"channel":"book","type":"update","data":[{"symbol":"BCH/EUR","bids":[{"price":425.08,"qty":2.45000000}],"asks":[],"checksum":4159543616,"timestamp":"2024-06-01T17:52:00.531753Z"}]}
{"channel":"book","type":"update","data":[{"symbol":"BCH/EUR","bids":[{"price":424.78,"qty":7.83392088}],"asks":[],"checksum":1129724896,"timestamp":"2024-06-01T17:52:00.577486Z"}]}
{"channel":"book","type":"update","data":[{"symbol":"BCH/EUR","bids":[{"price":425.06,"qty":0.00000000},{"price":424.69,"qty":0.48000000}],"asks":[],"checksum":1884545587,"timestamp":"2024-06-01T17:52:00.629365Z"}]}
{"channel":"book","type":"update","data":[{"symbol":"BCH/EUR","bids":[{"price":425.09,"qty":7.83392088}],"asks":[],"checksum":3187714118,"timestamp":"2024-06-01T17:52:00.633052Z"}]}
{"channel":"book","type":"update","data":[{"symbol":"BCH/EUR","bids":[{"price":425.07,"qty":7.83392088}],"asks":[],"checksum":4197645689,"timestamp":"2024-06-01T17:52:00.637122Z"}]}
{"channel":"book","type":"update","data":[{"symbol":"BCH/EUR","bids":[{"price":425.20,"qty":0.67000000}],"asks":[],"checksum":1859581534,"timestamp":"2024-06-01T17:52:00.814269Z"}]}
{"channel":"book","type":"update","data":[{"symbol":"BCH/EUR","bids":[{"price":425.07,"qty":0.00000000},{"price":424.78,"qty":7.83392088}],"asks":[],"checksum":3201035840,"timestamp":"2024-06-01T17:52:00.818668Z"}]}
{"channel":"book","type":"update","data":[{"symbol":"BCH/EUR","bids":[{"price":425.10,"qty":2.00000000}],"asks":[],"checksum":4023680811,"timestamp":"2024-06-01T17:52:00.821036Z"}]}
{"channel":"book","type":"update","data":[{"symbol":"BCH/EUR","bids":[{"price":425.08,"qty":0.45000000}],"asks":[],"checksum":147899202,"timestamp":"2024-06-01T17:52:01.130588Z"}]}
{"channel":"book","type":"update","data":[{"symbol":"BCH/EUR","bids":[{"price":425.20,"qty":0.00000000},{"price":424.78,"qty":7.83392088}],"asks":[],"checksum":3183593619,"timestamp":"2024-06-01T17:52:01.237283Z"}]}
{"channel":"book","type":"update","data":[{"symbol":"BCH/EUR","bids":[{"price":424.78,"qty":0.00000000},{"price":424.69,"qty":0.48000000}],"asks":[],"checksum":3020266712,"timestamp":"2024-06-01T17:52:02.366379Z"}]}
{"channel":"book","type":"update","data":[{"symbol":"BCH/EUR","bids":[{"price":424.78,"qty":7.83392088}],"asks":[],"checksum":3183593619,"timestamp":"2024-06-01T17:52:02.643206Z"}]}
{"channel":"book","type":"update","data":[{"symbol":"BCH/EUR","bids":[{"price":425.05,"qty":0.43357932}],"asks":[],"checksum":1395386818,"timestamp":"2024-06-01T17:52:03.165358Z"}]}
{"channel":"book","type":"update","data":[{"symbol":"BCH/EUR","bids":[],"asks":[{"price":425.51,"qty":2.00000000}],"checksum":3993864006,"timestamp":"2024-06-01T17:52:03.199197Z"}]}
{"channel":"book","type":"update","data":[{"symbol":"BCH/EUR","bids":[],"asks":[{"price":425.43,"qty":0.00000000},{"price":425.68,"qty":1.08600000}],"checksum":2393996016,"timestamp":"2024-06-01T17:52:03.199719Z"}]}
{"channel":"book","type":"update","data":[{"symbol":"BCH/EUR","bids":[],"asks":[{"price":425.50,"qty":0.00000000},{"price":425.69,"qty":0.35000000}],"checksum":2866419251,"timestamp":"2024-06-01T17:52:03.199885Z"}]}
{"channel":"book","type":"update","data":[{"symbol":"BCH/EUR","bids":[],"asks":[{"price":425.38,"qty":0.00000000},{"price":425.71,"qty":10.86000000}],"checksum":338458806,"timestamp":"2024-06-01T17:52:03.200594Z"}]}
{"channel":"book","type":"update","data":[{"symbol":"BCH/EUR","bids":[],"asks":[{"price":425.60,"qty":4.23722891}],"checksum":2664453434,"timestamp":"2024-06-01T17:52:03.202286Z"}]}
{"channel":"book","type":"update","data":[{"symbol":"BCH/EUR","bids":[],"asks":[{"price":425.32,"qty":0.00000000},{"price":425.71,"qty":35.70732600}],"checksum":2887168693,"timestamp":"2024-06-01T17:52:03.202903Z"}]}
{"channel":"book","type":"update","data":[{"symbol":"BCH/EUR","bids":[{"price":425.04,"qty":0.09890822}],"asks":[],"checksum":506569018,"timestamp":"2024-06-01T17:52:03.203030Z"}]}
{"channel":"book","type":"update","data":[{"symbol":"BCH/EUR","bids":[{"price":425.05,"qty":0.00000000},{"price":424.78,"qty":7.83392088}],"asks":[],"checksum":896294851,"timestamp":"2024-06-01T17:52:03.203048Z"}]}
{"channel":"book","type":"update","data":[{"symbol":"BCH/EUR","bids":[],"asks":[{"price":425.68,"qty":0.00000000},{"price":425.72,"qty":17.65425969},{"price":425.70,"qty":1.08600000}],"checksum":4263852203,"timestamp":"2024-06-01T17:52:03.203338Z"}]}
{"channel":"book","type":"update","data":[{"symbol":"BCH/EUR","bids":[{"price":425.11,"qty":7.83392088}],"asks":[],"checksum":4200275806,"timestamp":"2024-06-01T17:52:03.204471Z"}]}
{"channel":"book","type":"update","data":[{"symbol":"BCH/EUR","bids":[{"price":425.05,"qty":8.00000000}],"asks":[],"checksum":272129002,"timestamp":"2024-06-01T17:52:03.204733Z"}]}
{"channel":"book","type":"update","data":[{"symbol":"BCH/EUR","bids":[{"price":425.06,"qty":3.88726919}],"asks":[],"checksum":2871117180,"timestamp":"2024-06-01T17:52:03.205409Z"}]}
{"channel":"book","type":"update","data":[{"symbol":"BCH/EUR","bids":[],"asks":[{"price":425.30,"qty":0.00000000},{"price":425.72,"qty":17.65425969}],"checksum":1785275669,"timestamp":"2024-06-01T17:52:03.205627Z"}]}
{"channel":"book","type":"update","data":[{"symbol":"BCH/EUR","bids":[],"asks":[{"price":425.37,"qty":0.45000000}],"checksum":32085684,"timestamp":"2024-06-01T17:52:03.205690Z"}]}
{"channel":"book","type":"update","data":[{"symbol":"BCH/EUR","bids":[{"price":425.04,"qty":0.53243045}],"asks":[],"checksum":3237321159,"timestamp":"2024-06-01T17:52:03.206920Z"}]}
{"channel":"book","type":"update","data":[{"symbol":"BCH/EUR","bids":[{"price":425.11,"qty":13.25600716}],"asks":[],"checksum":909769346,"timestamp":"2024-06-01T17:52:03.208439Z"}]}
{"channel":"book","type":"update","data":[{"symbol":"BCH/EUR","bids":[],"asks":[{"price":425.41,"qty":5.41833915}],"checksum":1995769959,"timestamp":"2024-06-01T17:52:03.208516Z"}]}
{"channel":"book","type":"update","data":[{"symbol":"BCH/EUR","bids":[{"price":425.04,"qty":0.09890822}],"asks":[],"checksum":1733626763,"timestamp":"2024-06-01T17:52:03.210757Z"}]}
{"channel":"book","type":"update","data":[{"symbol":"BCH/EUR","bids":[],"asks":[{"price":425.57,"qty":0.00000000},{"price":425.71,"qty":35.70732600}],"checksum":542359611,"timestamp":"2024-06-01T17:52:03.214072Z"}]}
{"channel":"book","type":"update","data":[{"symbol":"BCH/EUR","bids":[],"asks":[{"price":425.59,"qty":0.10173288}],"checksum":3981176440,"timestamp":"2024-06-01T17:52:03.214355Z"}]}
{"channel":"book","type":"update","data":[{"symbol":"BCH/EUR","bids":[],"asks":[{"price":425.54,"qty":0.00000000},{"price":425.71,"qty":35.70732600}],"checksum":3574217185,"timestamp":"2024-06-01T17:52:03.219775Z"}]}
{"channel":"book","type":"update","data":[{"symbol":"BCH/EUR","bids":[],"asks":[{"price":425.44,"qty":0.00000000},{"price":425.72,"qty":17.65425969}],"checksum":1231304717,"timestamp":"2024-06-01T17:52:03.223752Z"}]}
{"channel":"book","type":"update","data":[{"symbol":"BCH/EUR","bids":[{"price":425.08,"qty":0.00000000},{"price":424.94,"qty":0.99612274}],"asks":[],"checksum":4102976143,"timestamp":"2024-06-01T17:52:03.229126Z"}]}
{"channel":"book","type":"update","data":[{"symbol":"BCH/EUR","bids":[{"price":425.11,"qty":13.70600716}],"asks":[],"checksum":987165733,"timestamp":"2024-06-01T17:52:03.229232Z"}]}
{"channel":"book","type":"update","data":[{"symbol":"BCH/EUR","bids":[{"price":424.97,"qty":8.00000000}],"asks":[],"checksum":1706027672,"timestamp":"2024-06-01T17:52:03.232130Z"}]}
{"channel":"book","type":"update","data":[{"symbol":"BCH/EUR","bids":[],"asks":[{"price":425.59,"qty":0.00000000},{"price":425.76,"qty":49.88613000}],"checksum":2234340152,"timestamp":"2024-06-01T17:52:03.243912Z"}]}
{"channel":"book","type":"update","data":[{"symbol":"BCH/EUR","bids":[],"asks":[{"price":425.59,"qty":0.10173194}],"checksum":3528059398,"timestamp":"2024-06-01T17:52:03.244325Z"}]}
{"channel":"book","type":"update","data":[{"symbol":"BCH/EUR","bids":[{"price":425.09,"qty":0.00000000},{"price":424.86,"qty":0.34000000}],"asks":[],"checksum":3383676951,"timestamp":"2024-06-01T17:52:03.247292Z"}]}
{"channel":"book","type":"update","data":[{"symbol":"BCH/EUR","bids":[{"price":424.97,"qty":0.00000000},{"price":424.80,"qty":5.42595971}],"asks":[],"checksum":3896858035,"timestamp":"2024-06-01T17:52:03.248024Z"}]}
{"channel":"book","type":"update","data":[{"symbol":"BCH/EUR","bids":[{"price":425.12,"qty":2.00000000}],"asks":[],"checksum":1451897273,"timestamp":"2024-06-01T17:52:03.248995Z"}]}
{"channel":"book","type":"update","data":[{"symbol":"BCH/EUR","bids":[{"price":425.11,"qty":8.28392088}],"asks":[],"checksum":180696330,"timestamp":"2024-06-01T17:52:03.253057Z"}]}
{"channel":"book","type":"update","data":[{"symbol":"BCH/EUR","bids":[],"asks":[{"price":425.71,"qty":24.84732600}],"checksum":4096797590,"timestamp":"2024-06-01T17:52:03.273356Z"}]}
{"channel":"book","type":"update","data":[{"symbol":"BCH/EUR","bids":[{"price":425.11,"qty":7.83392088}],"asks":[],"checksum":2865183926,"timestamp":"2024-06-01T17:52:03.275892Z"}]}
{"channel":"book","type":"update","data":[{"symbol":"BCH/EUR","bids":[{"price":425.12,"qty":2.45000000}],"asks":[],"checksum":3055874885,"timestamp":"2024-06-01T17:52:03.276107Z"}]}
{"channel":"book","type":"update","data":[{"symbol":"BCH/EUR","bids":[{"price":425.13,"qty":7.83392088}],"asks":[],"checksum":3578180499,"timestamp":"2024-06-01T17:52:03.280194Z"}]}
{"channel":"book","type":"update","data":[{"symbol":"BCH/EUR","bids":[{"price":425.07,"qty":8.00000000}],"asks":[],"checksum":1938155335,"timestamp":"2024-06-01T17:52:03.281296Z"}]}
{"channel":"book","type":"update","data":[{"symbol":"BCH/EUR","bids":[{"price":425.10,"qty":0.00000000},{"price":424.94,"qty":0.99612274}],"asks":[],"checksum":2139277997,"timestamp":"2024-06-01T17:52:03.281603Z"}]}
{"channel":"book","type":"update","data":[{"symbol":"BCH/EUR","bids":[],"asks":[{"price":425.51,"qty":0.00000000},{"price":425.76,"qty":49.88613000}],"checksum":4076384907,"timestamp":"2024-06-01T17:52:03.284787Z"}]}
{"channel":"book","type":"update","data":[{"symbol":"BCH/EUR","bids":[{"price":425.11,"qty":18.68076345}],"asks":[],"checksum":1898252283,"timestamp":"2024-06-01T17:52:03.287141Z"}]}
{"channel":"book","type":"update","data":[{"symbol":"BCH/EUR","bids":[{"price":425.12,"qty":2.00000000}],"asks":[],"checksum":1131921163,"timestamp":"2024-06-01T17:52:03.289803Z"}]}
{"channel":"book","type":"update","data":[{"symbol":"BCH/EUR","bids":[{"price":425.13,"qty":8.28392088}],"asks":[],"checksum":1956026757,"timestamp":"2024-06-01T17:52:03.289970Z"}]}
{"channel":"book","type":"update","data":[{"symbol":"BCH/EUR","bids":[{"price":424.96,"qty":0.00000000},{"price":424.86,"qty":0.34000000}],"asks":[],"checksum":2073755722,"timestamp":"2024-06-01T17:52:03.290787Z"}]}
{"channel":"book","type":"update","data":[{"symbol":"BCH/EUR","bids":[{"price":425.13,"qty":7.83392088}],"asks":[],"checksum":1700145577,"timestamp":"2024-06-01T17:52:03.318552Z"}]}
{"channel":"book","type":"update","data":[{"symbol":"BCH/EUR","bids":[{"price":425.14,"qty":0.45000000}],"asks":[],"checksum":3103681733,"timestamp":"2024-06-01T17:52:03.318584Z"}]}
{"channel":"book","type":"update","data":[{"symbol":"BCH/EUR","bids":[{"price":425.11,"qty":10.84684257}],"asks":[],"checksum":2186849367,"timestamp":"2024-06-01T17:52:03.322196Z"}]}
{"channel":"book","type":"update","data":[{"symbol":"BCH/EUR","bids":[{"price":425.05,"qty":0.00000000},{"price":424.86,"qty":0.34000000}],"asks":[],"checksum":1658757743,"timestamp":"2024-06-01T17:52:03.323221Z"}]}
{"channel":"book","type":"update","data":[{"symbol":"BCH/EUR","bids":[],"asks":[{"price":425.68,"qty":8.00000000}],"checksum":2223587922,"timestamp":"2024-06-01T17:52:03.323356Z"}]}
{"channel":"book","type":"update","data":[{"symbol":"BCH/EUR","bids":[],"asks":[{"price":425.51,"qty":3.88726919}],"checksum":2901847843,"timestamp":"2024-06-01T17:52:03.324027Z"}]}
{"channel":"book","type":"update","data":[{"symbol":"BCH/EUR","bids":[{"price":425.14,"qty":2.45000000}],"asks":[],"checksum":233032951,"timestamp":"2024-06-01T17:52:03.325174Z"}]}
{"channel":"book","type":"update","data":[{"symbol":"BCH/EUR","bids":[{"price":425.15,"qty":10.84684257}],"asks":[],"checksum":4174567903,"timestamp":"2024-06-01T17:52:03.325815Z"}]}
{"channel":"book","type":"update","data":[{"symbol":"BCH/EUR","bids":[{"price":425.11,"qty":0.00000000},{"price":424.86,"qty":0.34000000}],"asks":[],"checksum":3893981453,"timestamp":"2024-06-01T17:52:03.329103Z"}]}
{"channel":"book","type":"update","data":[{"symbol":"BCH/EUR","bids":[],"asks":[{"price":425.49,"qty":0.03152465}],"checksum":688633729,"timestamp":"2024-06-01T17:52:03.345831Z"}]}
{"channel":"book","type":"update","data":[{"symbol":"BCH/EUR","bids":[],"asks":[{"price":425.49,"qty":0.00000000},{"price":425.71,"qty":24.84732600}],"checksum":3893981453,"timestamp":"2024-06-01T17:52:03.397563Z"}]}
{"channel":"book","type":"update","data":[{"symbol":"BCH/EUR","bids":[{"price":425.16,"qty":7.83392088}],"asks":[],"checksum":3357683365,"timestamp":"2024-06-01T17:52:03.401504Z"}]}
{"channel":"book","type":"update","data":[{"symbol":"BCH/EUR","bids":[{"price":425.14,"qty":0.45000000}],"asks":[],"checksum":1685160385,"timestamp":"2024-06-01T17:52:03.402273Z"}]}
{"channel":"book","type":"update","data":[{"symbol":"BCH/EUR","bids":[{"price":425.04,"qty":0.00000000},{"price":424.86,"qty":0.34000000}],"asks":[],"checksum":819968579,"timestamp":"2024-06-01T17:52:03.406112Z"}]}
{"channel":"book","type":"update","data":[{"symbol":"BCH/EUR","bids":[],"asks":[{"price":425.70,"qty":0.00000000},{"price":425.72,"qty":17.65425969}],"checksum":1581542421,"timestamp":"2024-06-01T17:52:03.424786Z"}]}
{"channel":"book","type":"update","data":[{"symbol":"BCH/EUR","bids":[{"price":425.13,"qty":0.00000000},{"price":424.80,"qty":5.42595971}],"asks":[],"checksum":1963270024,"timestamp":"2024-06-01T17:52:03.510883Z"}]}
{"channel":"book","type":"update","data":[{"symbol":"BCH/EUR","bids":[],"asks":[{"price":425.49,"qty":7.83392088}],"checksum":2949966008,"timestamp":"2024-06-01T17:52:03.511015Z"}]}
{"channel":"book","type":"update","data":[{"symbol":"BCH/EUR","bids":[],"asks":[{"price":425.51,"qty":3.91879384}],"checksum":1789568909,"timestamp":"2024-06-01T17:52:03.518676Z"}]}
{"channel":"book","type":"update","data":[{"symbol":"BCH/EUR","bids":[{"price":425.17,"qty":2.00000000}],"asks":[],"checksum":2128865114,"timestamp":"2024-06-01T17:52:03.524826Z"}]}
{"channel":"book","type":"update","data":[{"symbol":"BCH/EUR","bids":[{"price":425.15,"qty":10.94572520}],"asks":[],"checksum":3694382128,"timestamp":"2024-06-01T17:52:03.536104Z"}]}
{"channel":"book","type":"update","data":[{"symbol":"BCH/EUR","bids":[{"price":425.30,"qty":2.34000000}],"asks":[],"checksum":22063853,"timestamp":"2024-06-01T17:52:03.536702Z"}]}
{"channel":"book","type":"update","data":[{"symbol":"BCH/EUR","bids":[],"asks":[{"price":425.51,"qty":3.88726919}],"checksum":1462112385,"timestamp":"2024-06-01T17:52:03.556880Z"}]}
{"channel":"book","type":"update","data":[{"symbol":"BCH/EUR","bids":[{"price":425.17,"qty":0.00000000},{"price":424.86,"qty":0.34000000}],"asks":[],"checksum":3459243619,"timestamp":"2024-06-01T17:52:03.561511Z"}]}
{"channel":"book","type":"update","data":[{"symbol":"BCH/EUR","bids":[],"asks":[{"price":425.51,"qty":3.91879384}],"checksum":189894998,"timestamp":"2024-06-01T17:52:03.678723Z"}]}
{"channel":"book","type":"update","data":[{"symbol":"BCH/EUR","bids":[{"price":425.15,"qty":0.09888263}],"asks":[],"checksum":3333960855,"timestamp":"2024-06-01T17:52:03.788959Z"}]}
{"channel":"book","type":"update","data":[{"symbol":"BCH/EUR","bids":[{"price":425.11,"qty":10.84684257}],"asks":[],"checksum":323354579,"timestamp":"2024-06-01T17:52:03.857682Z"}]}
{"channel":"book","type":"update","data":[{"symbol":"BCH/EUR","bids":[{"price":425.13,"qty":5.42183120}],"asks":[],"checksum":585795499,"timestamp":"2024-06-01T17:52:04.427148Z"}]}
{"channel":"book","type":"update","data":[{"symbol":"BCH/EUR","bids":[{"price":425.30,"qty":0.00000000},{"price":424.94,"qty":0.99612274}],"asks":[],"checksum":2766543144,"timestamp":"2024-06-01T17:52:04.539887Z"}]}
{"channel":"book","type":"update","data":[{"symbol":"BCH/EUR","bids":[{"price":425.14,"qty":8.28392088}],"asks":[],"checksum":4157413677,"timestamp":"2024-06-01T17:52:04.544006Z"}]}
{"channel":"book","type":"update","data":[{"symbol":"BCH/EUR","bids":[{"price":425.16,"qty":0.00000000},{"price":424.86,"qty":0.34000000}],"asks":[],"checksum":772030205,"timestamp":"2024-06-01T17:52:04.544021Z"}]}
{"channel":"book","type":"update","data":[{"symbol":"BCH/EUR","bids":[{"price":425.17,"qty":2.00000000}],"asks":[],"checksum":2414975003,"timestamp":"2024-06-01T17:52:04.545581Z"}]}
{"channel":"book","type":"update","data":[{"symbol":"BCH/EUR","bids":[],"asks":[{"price":425.59,"qty":0.00000000},{"price":425.72,"qty":5.41425969}],"checksum":3960632070,"timestamp":"2024-06-01T17:52:04.556776Z"}]}
{"channel":"book","type":"update","data":[{"symbol":"BCH/EUR","bids":[],"asks":[{"price":425.59,"qty":0.10173100}],"checksum":3120685872,"timestamp":"2024-06-01T17:52:04.557001Z"}]}
{"channel":"book","type":"update","data":[{"symbol":"BCH/EUR","bids":[{"price":425.12,"qty":0.00000000},{"price":424.86,"qty":0.34000000}],"asks":[],"checksum":923772891,"timestamp":"2024-06-01T17:52:04.629376Z"}]}
{"channel":"book","type":"update","data":[{"symbol":"BCH/EUR","bids":[{"price":425.18,"qty":7.83392088}],"asks":[],"checksum":1357116880,"timestamp":"2024-06-01T17:52:04.633023Z"}]}
{"channel":"book","type":"update","data":[{"symbol":"BCH/EUR","bids":[{"price":425.30,"qty":0.76000000}],"asks":[],"checksum":2704746889,"timestamp":"2024-06-01T17:52:04.633589Z"}]}
{"channel":"book","type":"update","data":[{"symbol":"BCH/EUR","bids":[{"price":425.14,"qty":0.45000000}],"asks":[],"checksum":4133407627,"timestamp":"2024-06-01T17:52:05.009492Z"}]}
{"channel":"book","type":"update","data":[{"symbol":"BCH/EUR","bids":[{"price":425.19,"qty":2.00000000}],"asks":[],"checksum":3108760341,"timestamp":"2024-06-01T17:52:05.014849Z"}]}
{"channel":"book","type":"update","data":[{"symbol":"BCH/EUR","bids":[{"price":425.07,"qty":0.00000000},{"price":425.00,"qty":10.84773558}],"asks":[],"checksum":1391567702,"timestamp":"2024-06-01T17:52:05.015361Z"}]}
{"channel":"book","type":"update","data":[{"symbol":"BCH/EUR","bids":[{"price":425.17,"qty":0.00000000},{"price":424.94,"qty":0.99612274}],"asks":[],"checksum":1039560821,"timestamp":"2024-06-01T17:52:05.132886Z"}]}
{"channel":"book","type":"update","data":[{"symbol":"BCH/EUR","bids":[{"price":425.07,"qty":8.00000000}],"asks":[],"checksum":3231917023,"timestamp":"2024-06-01T17:52:05.133168Z"}]}
{"channel":"book","type":"update","data":[{"symbol":"BCH/EUR","bids":[{"price":425.30,"qty":0.00000000},{"price":424.94,"qty":0.99612274}],"asks":[],"checksum":4284358153,"timestamp":"2024-06-01T17:52:05.203961Z"}]}
{"channel":"book","type":"update","data":[{"symbol":"BCH/EUR","bids":[{"price":425.15,"qty":0.00000000},{"price":424.86,"qty":0.34000000}],"asks":[],"checksum":4082086910,"timestamp":"2024-06-01T17:52:05.431466Z"}]}
{"channel":"book","type":"update","data":[{"symbol":"BCH/EUR","bids":[{"price":425.15,"qty":0.09888263}],"asks":[],"checksum":4284358153,"timestamp":"2024-06-01T17:52:05.552169Z"}]}
{"channel":"book","type":"update","data":[{"symbol":"BCH/EUR","bids":[],"asks":[{"price":425.51,"qty":3.88726919}],"checksum":992646577,"timestamp":"2024-06-01T17:52:05.560709Z"}]}
{"channel":"book","type":"update","data":[{"symbol":"BCH/EUR","bids":[],"asks":[{"price":425.51,"qty":3.91879384}],"checksum":4284358153,"timestamp":"2024-06-01T17:52:07.325687Z"}]}
{"channel":"book","type":"update","data":[{"symbol":"BCH/EUR","bids":[],"asks":[{"price":425.39,"qty":0.00000000},{"price":425.72,"qty":5.41425969}],"checksum":282716297,"timestamp":"2024-06-01T17:52:09.011026Z"}]}
{"channel":"book","type":"update","data":[{"symbol":"BCH/EUR","bids":[],"asks":[{"price":425.50,"qty":15.96804300}],"checksum":4216447490,"timestamp":"2024-06-01T17:52:09.013886Z"}]}
{"channel":"book","type":"update","data":[{"symbol":"BCH/EUR","bids":[],"asks":[{"price":425.59,"qty":0.00000000},{"price":425.72,"qty":5.41425969}],"checksum":3369917768,"timestamp":"2024-06-01T17:52:10.880413Z"}]}
{"channel":"book","type":"update","data":[{"symbol":"BCH/EUR","bids":[],"asks":[{"price":425.59,"qty":0.10173029}],"checksum":719683953,"timestamp":"2024-06-01T17:52:10.880603Z"}]}
{"channel":"book","type":"update","data":[{"symbol":"BCH/EUR","bids":[],"asks":[{"price":425.59,"qty":0.20345941}],"checksum":936531039,"timestamp":"2024-06-01T17:52:10.961685Z"}]}
{"channel":"book","type":"update","data":[{"symbol":"BCH/EUR","bids":[],"asks":[{"price":425.59,"qty":0.10172912}],"checksum":2403525303,"timestamp":"2024-06-01T17:52:10.961716Z"}]}
{"channel":"book","type":"update","data":[{"symbol":"BCH/EUR","bids":[],"asks":[{"price":425.59,"qty":0.20345730}],"checksum":419548964,"timestamp":"2024-06-01T17:52:10.973900Z"}]}
{"channel":"book","type":"update","data":[{"symbol":"BCH/EUR","bids":[],"asks":[{"price":425.59,"qty":0.10172818}],"checksum":4000999045,"timestamp":"2024-06-01T17:52:10.973938Z"}]}
{"channel":"book","type":"update","data":[{"symbol":"BCH/EUR","bids":[],"asks":[{"price":425.59,"qty":0.00000000},{"price":425.72,"qty":5.41425969}],"checksum":3369917768,"timestamp":"2024-06-01T17:52:12.750578Z"}]}
{"channel":"book","type":"update","data":[{"symbol":"BCH/EUR","bids":[],"asks":[{"price":425.59,"qty":0.10172724}],"checksum":824642452,"timestamp":"2024-06-01T17:52:12.750754Z"}]}
{"channel":"book","type":"update","data":[{"symbol":"BCH/EUR","bids":[],"asks":[{"price":425.71,"qty":25.93332600}],"checksum":1329586582,"timestamp":"2024-06-01T17:52:13.526021Z"}]}
{"channel":"book","type":"update","data":[{"symbol":"BCH/EUR","bids":[],"asks":[{"price":425.51,"qty":3.88726919}],"checksum":2336975406,"timestamp":"2024-06-01T17:52:15.207716Z"}]}
{"channel":"book","type":"update","data":[{"symbol":"BCH/EUR","bids":[],"asks":[{"price":425.53,"qty":0.03152465}],"checksum":291610255,"timestamp":"2024-06-01T17:52:15.359655Z"}]}
{"channel":"book","type":"update","data":[{"symbol":"BCH/EUR","bids":[],"asks":[{"price":425.41,"qty":0.00000000},{"price":425.71,"qty":25.93332600}],"checksum":3765793079,"timestamp":"2024-06-01T17:52:15.393175Z"}]}
{"channel":"book","type":"update","data":[{"symbol":"BCH/EUR","bids":[{"price":425.13,"qty":0.00000000},{"price":424.86,"qty":0.34000000}],"asks":[],"checksum":3913400764,"timestamp":"2024-06-01T17:52:15.393293Z"}]}
{"channel":"book","type":"update","data":[{"symbol":"BCH/EUR","bids":[],"asks":[{"price":425.37,"qty":0.00000000},{"price":425.72,"qty":5.41425969}],"checksum":2537754390,"timestamp":"2024-06-01T17:52:15.396476Z"}]}
{"channel":"book","type":"update","data":[{"symbol":"BCH/EUR","bids":[],"asks":[{"price":425.47,"qty":0.45000000}],"checksum":556337152,"timestamp":"2024-06-01T17:52:15.396508Z"}]}
{"channel":"book","type":"update","data":[{"symbol":"BCH/EUR","bids":[],"asks":[{"price":425.45,"qty":5.41775788}],"checksum":595753445,"timestamp":"2024-06-01T17:52:15.399793Z"}]}
{"channel":"book","type":"update","data":[{"symbol":"BCH/EUR","bids":[{"price":425.16,"qty":5.42136192}],"asks":[],"checksum":3550080349,"timestamp":"2024-06-01T17:52:15.399898Z"}]}
{"channel":"book","type":"update","data":[{"symbol":"BCH/EUR","bids":[{"price":424.94,"qty":0.00000000},{"price":424.86,"qty":0.34000000}],"asks":[],"checksum":3894564731,"timestamp":"2024-06-01T17:52:15.402089Z"}]}
{"channel":"book","type":"update","data":[{"symbol":"BCH/EUR","bids":[],"asks":[{"price":425.47,"qty":0.00000000},{"price":425.71,"qty":25.93332600}],"checksum":2953610219,"timestamp":"2024-06-01T17:52:15.403595Z"}]}
{"channel":"book","type":"update","data":[{"symbol":"BCH/EUR","bids":[],"asks":[{"price":425.43,"qty":0.45000000}],"checksum":2449380609,"timestamp":"2024-06-01T17:52:15.404114Z"}]}
{"channel":"book","type":"update","data":[{"symbol":"BCH/EUR","bids":[{"price":425.04,"qty":0.99590690}],"asks":[],"checksum":1436105604,"timestamp":"2024-06-01T17:52:15.407208Z"}]}
{"channel":"book","type":"update","data":[{"symbol":"BCH/EUR","bids":[{"price":425.17,"qty":0.43348006}],"asks":[],"checksum":1442888188,"timestamp":"2024-06-01T17:52:15.448635Z"}]}
{"channel":"book","type":"update","data":[{"symbol":"BCH/EUR","bids":[{"price":425.14,"qty":0.00000000},{"price":425.00,"qty":10.84773558}],"asks":[],"checksum":1820780800,"timestamp":"2024-06-01T17:52:15.488970Z"}]}
{"channel":"book","type":"update","data":[{"symbol":"BCH/EUR","bids":[{"price":425.19,"qty":2.45000000}],"asks":[],"checksum":1885677299,"timestamp":"2024-06-01T17:52:15.489022Z"}]}
{"channel":"book","type":"update","data":[{"symbol":"BCH/EUR","bids":[{"price":425.30,"qty":1.20000000}],"asks":[],"checksum":65192542,"timestamp":"2024-06-01T17:52:15.605362Z"}]}
{"channel":"book","type":"update","data":[{"symbol":"BCH/EUR","bids":[{"price":425.17,"qty":0.00000000},{"price":425.00,"qty":10.84773558}],"asks":[],"checksum":83727213,"timestamp":"2024-06-01T17:52:17.257048Z"}]}
{"channel":"book","type":"update","data":[{"symbol":"BCH/EUR","bids":[{"price":425.30,"qty":0.00000000},{"price":424.86,"qty":0.34000000}],"asks":[],"checksum":3748690111,"timestamp":"2024-06-01T17:52:17.346128Z"}]}
{"channel":"book","type":"update","data":[{"symbol":"BCH/EUR","bids":[{"price":425.17,"qty":0.43347261}],"asks":[],"checksum":3042017571,"timestamp":"2024-06-01T17:52:18.484141Z"}]}
{"channel":"book","type":"update","data":[{"symbol":"BCH/EUR","bids":[],"asks":[{"price":425.60,"qty":0.00000000},{"price":425.71,"qty":24.84732600}],"checksum":2497383784,"timestamp":"2024-06-01T17:52:18.963213Z"}]}
{"channel":"book","type":"update","data":[{"symbol":"BCH/EUR","bids":[],"asks":[{"price":425.68,"qty":0.00000000},{"price":425.72,"qty":5.41425969}],"checksum":1335988756,"timestamp":"2024-06-01T17:52:18.964336Z"}]}
{"channel":"book","type":"update","data":[{"symbol":"BCH/EUR","bids":[],"asks":[{"price":425.51,"qty":0.00000000},{"price":425.75,"qty":1.08600000}],"checksum":2998978866,"timestamp":"2024-06-01T17:52:18.965030Z"}]}
{"channel":"book","type":"update","data":[{"symbol":"BCH/EUR","bids":[],"asks":[{"price":425.69,"qty":3.15872891}],"checksum":3614165829,"timestamp":"2024-06-01T17:52:18.967808Z"}]}
{"channel":"book","type":"update","data":[{"symbol":"BCH/EUR","bids":[{"price":425.20,"qty":7.83392088}],"asks":[],"checksum":433255005,"timestamp":"2024-06-01T17:52:18.969194Z"}]}
{"channel":"book","type":"update","data":[{"symbol":"BCH/EUR","bids":[{"price":425.17,"qty":8.43347261}],"asks":[],"checksum":906945767,"timestamp":"2024-06-01T17:52:18.969752Z"}]}
{"channel":"book","type":"update","data":[{"symbol":"BCH/EUR","bids":[{"price":425.20,"qty":11.72119007}],"asks":[],"checksum":2041578617,"timestamp":"2024-06-01T17:52:18.970972Z"}]}
{"channel":"book","type":"update","data":[{"symbol":"BCH/EUR","bids":[{"price":425.17,"qty":8.00000000}],"asks":[],"checksum":2831710764,"timestamp":"2024-06-01T17:52:18.973461Z"}]}
{"channel":"book","type":"update","data":[{"symbol":"BCH/EUR","bids":[],"asks":[{"price":425.59,"qty":0.00000000},{"price":425.76,"qty":57.72005088}],"checksum":4253188639,"timestamp":"2024-06-01T17:52:18.978916Z"}]}
{"channel":"book","type":"update","data":[{"symbol":"BCH/EUR","bids":[],"asks":[{"price":425.68,"qty":0.16132093}],"checksum":3966637227,"timestamp":"2024-06-01T17:52:18.979070Z"}]}
{"channel":"book","type":"update","data":[{"symbol":"BCH/EUR","bids":[],"asks":[{"price":425.53,"qty":0.00000000},{"price":425.76,"qty":57.72005088}],"checksum":2214387531,"timestamp":"2024-06-01T17:52:18.990065Z"}]}
{"channel":"book","type":"update","data":[{"symbol":"BCH/EUR","bids":[{"price":425.19,"qty":2.00000000}],"asks":[],"checksum":841359184,"timestamp":"2024-06-01T17:52:18.990649Z"}]}
{"channel":"book","type":"update","data":[{"symbol":"BCH/EUR","bids":[{"price":425.20,"qty":12.17119007}],"asks":[],"checksum":4065442721,"timestamp":"2024-06-01T17:52:18.990938Z"}]}
{"channel":"book","type":"update","data":[{"symbol":"BCH/EUR","bids":[{"price":425.15,"qty":0.00000000},{"price":425.00,"qty":10.84773558}],"asks":[],"checksum":369959869,"timestamp":"2024-06-01T17:52:18.995661Z"}]}
{"channel":"book","type":"update","data":[{"symbol":"BCH/EUR","bids":[{"price":425.18,"qty":0.00000000},{"price":424.86,"qty":0.34000000}],"asks":[],"checksum":929793227,"timestamp":"2024-06-01T17:52:19.021495Z"}]}
{"channel":"book","type":"update","data":[{"symbol":"BCH/EUR","bids":[{"price":425.07,"qty":0.00000000},{"price":424.80,"qty":16.28595971}],"asks":[],"checksum":2386176107,"timestamp":"2024-06-01T17:52:19.025886Z"}]}
{"channel":"book","type":"update","data":[{"symbol":"BCH/EUR","bids":[{"price":425.06,"qty":0.00000000},{"price":424.78,"qty":7.83392088}],"asks":[],"checksum":1014272817,"timestamp":"2024-06-01T17:52:19.026383Z"}]}
{"channel":"book","type":"update","data":[{"symbol":"BCH/EUR","bids":[{"price":425.21,"qty":2.00000000}],"asks":[],"checksum":585548772,"timestamp":"2024-06-01T17:52:19.026712Z"}]}
{"channel":"book","type":"update","data":[{"symbol":"BCH/EUR","bids":[],"asks":[{"price":425.76,"qty":49.88613000}],"checksum":4009427693,"timestamp":"2024-06-01T17:52:19.086062Z"}]}
{"channel":"book","type":"update","data":[{"symbol":"BCH/EUR","bids":[],"asks":[{"price":425.56,"qty":0.03152465}],"checksum":2235232122,"timestamp":"2024-06-01T17:52:19.109222Z"}]}
{"channel":"book","type":"update","data":[{"symbol":"BCH/EUR","bids":[{"price":425.20,"qty":20.17119007}],"asks":[],"checksum":1994755843,"timestamp":"2024-06-01T17:52:19.113831Z"}]}
{"channel":"book","type":"update","data":[{"symbol":"BCH/EUR","bids":[{"price":425.19,"qty":0.00000000},{"price":424.78,"qty":7.83392088}],"asks":[],"checksum":163264545,"timestamp":"2024-06-01T17:52:19.114110Z"}]}
{"channel":"book","type":"update","data":[{"symbol":"BCH/EUR","bids":[{"price":425.19,"qty":0.09887333}],"asks":[],"checksum":494354583,"timestamp":"2024-06-01T17:52:19.114211Z"}]}
{"channel":"book","type":"update","data":[{"symbol":"BCH/EUR","bids":[],"asks":[{"price":425.60,"qty":3.88726919}],"checksum":1578080918,"timestamp":"2024-06-01T17:52:19.114822Z"}]}
{"channel":"book","type":"update","data":[{"symbol":"BCH/EUR","bids":[{"price":425.30,"qty":1.05000000}],"asks":[],"checksum":1415599844,"timestamp":"2024-06-01T17:52:19.121491Z"}]}
{"channel":"book","type":"update","data":[{"symbol":"BCH/EUR","bids":[{"price":425.31,"qty":2.00000000}],"asks":[],"checksum":1170450395,"timestamp":"2024-06-01T17:52:19.129702Z"}]}
{"channel":"book","type":"update","data":[{"symbol":"BCH/EUR","bids":[{"price":425.20,"qty":12.17119007}],"asks":[],"checksum":2544226194,"timestamp":"2024-06-01T17:52:19.133813Z"}]}
{"channel":"book","type":"update","data":[{"symbol":"BCH/EUR","bids":[],"asks":[{"price":425.55,"qty":0.10174221}],"checksum":2212070873,"timestamp":"2024-06-01T17:52:19.187308Z"}]}
{"channel":"book","type":"update","data":[{"symbol":"BCH/EUR","bids":[],"asks":[{"price":425.68,"qty":0.00000000},{"price":425.72,"qty":5.41425969}],"checksum":3882444880,"timestamp":"2024-06-01T17:52:19.187403Z"}]}
{"channel":"book","type":"update","data":[{"symbol":"BCH/EUR","bids":[{"price":425.21,"qty":0.00000000},{"price":424.86,"qty":0.34000000}],"asks":[],"checksum":2641791094,"timestamp":"2024-06-01T17:52:19.191988Z"}]}
{"channel":"book","type":"update","data":[{"symbol":"BCH/EUR","bids":[],"asks":[{"price":425.55,"qty":0.00000000},{"price":425.75,"qty":1.08600000}],"checksum":1995644007,"timestamp":"2024-06-01T17:52:19.215951Z"}]}
{"channel":"book","type":"update","data":[{"symbol":"BCH/EUR","bids":[],"asks":[{"price":425.55,"qty":0.10174150}],"checksum":2622587992,"timestamp":"2024-06-01T17:52:19.216186Z"}]}
{"channel":"book","type":"update","data":[{"symbol":"BCH/EUR","bids":[{"price":425.30,"qty":0.00000000},{"price":424.80,"qty":16.28595971}],"asks":[],"checksum":1441863239,"timestamp":"2024-06-01T17:52:19.234252Z"}]}
{"channel":"book","type":"update","data":[{"symbol":"BCH/EUR","bids":[{"price":425.16,"qty":0.00000000},{"price":424.78,"qty":7.83392088}],"asks":[],"checksum":850318429,"timestamp":"2024-06-01T17:52:19.402707Z"}]}
{"channel":"book","type":"update","data":[{"symbol":"BCH/EUR","bids":[{"price":425.19,"qty":5.51984077}],"asks":[],"checksum":2404089367,"timestamp":"2024-06-01T17:52:19.406987Z"}]}
{"channel":"book","type":"update","data":[{"symbol":"BCH/EUR","bids":[],"asks":[{"price":425.45,"qty":0.00000000},{"price":425.75,"qty":1.08600000}],"checksum":2695621036,"timestamp":"2024-06-01T17:52:19.452264Z"}]}
{"channel":"book","type":"update","data":[{"symbol":"BCH/EUR","bids":[],"asks":[{"price":425.43,"qty":0.00000000},{"price":425.76,"qty":49.88613000}],"checksum":43525021,"timestamp":"2024-06-01T17:52:19.454941Z"}]}
{"channel":"book","type":"update","data":[{"symbol":"BCH/EUR","bids":[],"asks":[{"price":425.47,"qty":0.45000000}],"checksum":3844158110,"timestamp":"2024-06-01T17:52:19.455177Z"}]}
{"channel":"book","type":"update","data":[{"symbol":"BCH/EUR","bids":[],"asks":[{"price":425.49,"qty":13.25121177}],"checksum":2561336401,"timestamp":"2024-06-01T17:52:19.456364Z"}]}
{"channel":"book","type":"update","data":[{"symbol":"BCH/EUR","bids":[{"price":425.20,"qty":20.17119007}],"asks":[],"checksum":1802863656,"timestamp":"2024-06-01T17:52:19.457053Z"}]}
{"channel":"book","type":"update","data":[{"symbol":"BCH/EUR","bids":[{"price":425.17,"qty":0.00000000},{"price":424.73,"qty":15.96804300}],"asks":[],"checksum":262610801,"timestamp":"2024-06-01T17:52:19.632271Z"}]}
{"channel":"book","type":"update","data":[{"symbol":"BCH/EUR","bids":[{"price":425.31,"qty":0.00000000},{"price":424.69,"qty":0.48000000}],"asks":[],"checksum":3453007915,"timestamp":"2024-06-01T17:52:19.637408Z"}]}
{"channel":"book","type":"update","data":[{"symbol":"BCH/EUR","bids":[{"price":425.21,"qty":2.00000000}],"asks":[],"checksum":1652497320,"timestamp":"2024-06-01T17:52:19.637523Z"}]}
{"channel":"book","type":"update","data":[{"symbol":"BCH/EUR","bids":[],"asks":[{"price":425.69,"qty":2.80872891}],"checksum":3909184451,"timestamp":"2024-06-01T17:52:21.111988Z"}]}
{"channel":"book","type":"update","data":[{"symbol":"BCH/EUR","bids":[],"asks":[{"price":425.70,"qty":0.37000000}],"checksum":2662094495,"timestamp":"2024-06-01T17:52:21.195902Z"}]}
{"channel":"book","type":"update","data":[{"symbol":"BCH/EUR","bids":[],"asks":[{"price":425.55,"qty":0.00000000},{"price":425.75,"qty":1.08600000}],"checksum":1813398635,"timestamp":"2024-06-01T17:52:21.335442Z"}]}
{"channel":"book","type":"update","data":[{"symbol":"BCH/EUR","bids":[],"asks":[{"price":425.55,"qty":0.10173986}],"checksum":1988089994,"timestamp":"2024-06-01T17:52:21.335606Z"}]}
{"channel":"book","type":"update","data":[{"symbol":"BCH/EUR","bids":[{"price":425.22,"qty":0.43345681}],"asks":[],"checksum":3363370677,"timestamp":"2024-06-01T17:52:21.336366Z"}]}
{"channel":"book","type":"update","data":[{"symbol":"BCH/EUR","bids":[{"price":425.20,"qty":19.72119007}],"asks":[],"checksum":941082820,"timestamp":"2024-06-01T17:52:21.338651Z"}]}
{"channel":"book","type":"update","data":[{"symbol":"BCH/EUR","bids":[{"price":425.21,"qty":2.45000000}],"asks":[],"checksum":3910213781,"timestamp":"2024-06-01T17:52:21.338666Z"}]}
{"channel":"book","type":"update","data":[{"symbol":"BCH/EUR","bids":[{"price":425.20,"qty":15.83392088}],"asks":[],"checksum":2659088009,"timestamp":"2024-06-01T17:52:21.341752Z"}]}
{"channel":"book","type":"update","data":[{"symbol":"BCH/EUR","bids":[{"price":425.15,"qty":3.88726919}],"asks":[],"checksum":3680216706,"timestamp":"2024-06-01T17:52:21.341798Z"}]}
{"channel":"book","type":"update","data":[{"symbol":"BCH/EUR","bids":[],"asks":[{"price":425.56,"qty":0.00000000},{"price":425.75,"qty":1.08600000}],"checksum":496064546,"timestamp":"2024-06-01T17:52:21.414927Z"}]}
{"channel":"book","type":"update","data":[{"symbol":"BCH/EUR","bids":[],"asks":[{"price":425.55,"qty":0.00000000},{"price":425.76,"qty":49.88613000}],"checksum":340669205,"timestamp":"2024-06-01T17:52:21.427246Z"}]}
{"channel":"book","type":"update","data":[{"symbol":"BCH/EUR","bids":[],"asks":[{"price":425.59,"qty":0.10173029}],"checksum":2502661074,"timestamp":"2024-06-01T17:52:21.427506Z"}]}
{"channel":"book","type":"update","data":[{"symbol":"BCH/EUR","bids":[{"price":425.21,"qty":2.00000000}],"asks":[],"checksum":1143831427,"timestamp":"2024-06-01T17:52:21.454855Z"}]}
{"channel":"book","type":"update","data":[{"symbol":"BCH/EUR","bids":[{"price":425.22,"qty":0.88345681}],"asks":[],"checksum":2481083749,"timestamp":"2024-06-01T17:52:21.454916Z"}]}
{"channel":"book","type":"update","data":[{"symbol":"BCH/EUR","bids":[{"price":425.21,"qty":12.84432147}],"asks":[],"checksum":985901013,"timestamp":"2024-06-01T17:52:21.587364Z"}]}
{"channel":"book","type":"update","data":[{"symbol":"BCH/EUR","bids":[{"price":425.11,"qty":0.00000000},{"price":424.78,"qty":7.83392088}],"asks":[],"checksum":216746173,"timestamp":"2024-06-01T17:52:21.591190Z"}]}
{"channel":"book","type":"update","data":[{"symbol":"BCH/EUR","bids":[{"price":425.30,"qty":2.25000000}],"asks":[],"checksum":512871497,"timestamp":"2024-06-01T17:52:21.595299Z"}]}
{"channel":"book","type":"update","data":[{"symbol":"BCH/EUR","bids":[{"price":425.31,"qty":2.00000000}],"asks":[],"checksum":2353124244,"timestamp":"2024-06-01T17:52:21.628682Z"}]}
{"channel":"book","type":"update","data":[{"symbol":"BCH/EUR","bids":[],"asks":[{"price":425.58,"qty":0.03152465}],"checksum":785796876,"timestamp":"2024-06-01T17:52:21.633162Z"}]}
{"channel":"book","type":"update","data":[{"symbol":"BCH/EUR","bids":[{"price":425.21,"qty":10.84432147}],"asks":[],"checksum":2370468670,"timestamp":"2024-06-01T17:52:21.634965Z"}]}
{"channel":"book","type":"update","data":[{"symbol":"BCH/EUR","bids":[],"asks":[{"price":425.70,"qty":0.00000000},{"price":425.76,"qty":49.88613000}],"checksum":3455402670,"timestamp":"2024-06-01T17:52:21.757490Z"}]}
{"channel":"book","type":"update","data":[{"symbol":"BCH/EUR","bids":[{"price":425.30,"qty":0.00000000},{"price":424.80,"qty":16.28595971}],"asks":[],"checksum":1614044196,"timestamp":"2024-06-01T17:52:21.812864Z"}]}
{"channel":"book","type":"update","data":[{"symbol":"BCH/EUR","bids":[],"asks":[{"price":425.71,"qty":25.25732600}],"checksum":3120261208,"timestamp":"2024-06-01T17:52:21.862906Z"}]}
{"channel":"book","type":"update","data":[{"symbol":"BCH/EUR","bids":[{"price":425.22,"qty":0.45000000}],"asks":[],"checksum":4000806526,"timestamp":"2024-06-01T17:52:22.033588Z"}]}
{"channel":"book","type":"update","data":[{"symbol":"BCH/EUR","bids":[],"asks":[{"price":425.49,"qty":5.41729089}],"checksum":1566589825,"timestamp":"2024-06-01T17:52:22.037849Z"}]}
{"channel":"book","type":"update","data":[{"symbol":"BCH/EUR","bids":[{"price":425.19,"qty":0.09887333}],"asks":[],"checksum":866814231,"timestamp":"2024-06-01T17:52:22.070541Z"}]}
{"channel":"book","type":"update","data":[{"symbol":"BCH/EUR","bids":[{"price":424.81,"qty":1.08600000}],"asks":[],"checksum":3987534342,"timestamp":"2024-06-01T17:52:22.073657Z"}]}
{"channel":"book","type":"update","data":[{"symbol":"BCH/EUR","bids":[{"price":425.22,"qty":5.87056191}],"asks":[],"checksum":2163676953,"timestamp":"2024-06-01T17:52:22.074330Z"}]}
{"channel":"book","type":"update","data":[{"symbol":"BCH/EUR","bids":[],"asks":[{"price":425.71,"qty":24.84732600}],"checksum":2187431823,"timestamp":"2024-06-01T17:52:22.082000Z"}]}
{"channel":"book","type":"update","data":[{"symbol":"BCH/EUR","bids":[{"price":425.03,"qty":0.44000000}],"asks":[],"checksum":1494868479,"timestamp":"2024-06-01T17:52:22.109138Z"}]}
{"channel":"book","type":"update","data":[{"symbol":"BCH/EUR","bids":[],"asks":[{"price":425.76,"qty":50.29613000}],"checksum":3531921693,"timestamp":"2024-06-01T17:52:22.208865Z"}]}
{"channel":"book","type":"update","data":[{"symbol":"BCH/EUR","bids":[{"price":425.23,"qty":0.43343132}],"asks":[],"checksum":2780849195,"timestamp":"2024-06-01T17:52:22.333461Z"}]}
{"channel":"book","type":"update","data":[{"symbol":"BCH/EUR","bids":[{"price":425.23,"qty":2.43343132}],"asks":[],"checksum":587089904,"timestamp":"2024-06-01T17:52:22.339758Z"}]}
{"channel":"book","type":"update","data":[{"symbol":"BCH/EUR","bids":[{"price":425.31,"qty":0.00000000},{"price":424.86,"qty":0.34000000}],"asks":[],"checksum":3635881243,"timestamp":"2024-06-01T17:52:22.339809Z"}]}
{"channel":"book","type":"update","data":[{"symbol":"BCH/EUR","bids":[],"asks":[{"price":425.58,"qty":0.00000000},{"price":425.77,"qty":8.00000000}],"checksum":1217191201,"timestamp":"2024-06-01T17:52:22.365843Z"}]}
{"channel":"book","type":"update","data":[{"symbol":"BCH/EUR","bids":[{"price":425.24,"qty":7.83392088}],"asks":[],"checksum":3309805292,"timestamp":"2024-06-01T17:52:22.369513Z"}]}
{"channel":"book","type":"update","data":[{"symbol":"BCH/EUR","bids":[{"price":425.23,"qty":2.00000000}],"asks":[],"checksum":360943280,"timestamp":"2024-06-01T17:52:22.385623Z"}]}
{"channel":"book","type":"update","data":[{"symbol":"BCH/EUR","bids":[{"price":425.25,"qty":0.43340552}],"asks":[],"checksum":2185984791,"timestamp":"2024-06-01T17:52:22.385721Z"}]}
{"channel":"book","type":"update","data":[{"symbol":"BCH/EUR","bids":[],"asks":[{"price":425.69,"qty":0.00000000},{"price":425.82,"qty":5.41315493}],"checksum":883599752,"timestamp":"2024-06-01T17:52:22.388803Z"}]}
{"channel":"book","type":"update","data":[{"symbol":"BCH/EUR","bids":[],"asks":[{"price":425.77,"qty":0.00000000},{"price":425.83,"qty":12.24000000}],"checksum":3260711101,"timestamp":"2024-06-01T17:52:22.389646Z"}]}
{"channel":"book","type":"update","data":[{"symbol":"BCH/EUR","bids":[],"asks":[{"price":425.60,"qty":0.00000000},{"price":425.99,"qty":0.10000000}],"checksum":2356033786,"timestamp":"2024-06-01T17:52:22.390536Z"}]}
{"channel":"book","type":"update","data":[{"symbol":"BCH/EUR","bids":[],"asks":[{"price":425.76,"qty":49.88613000}],"checksum":275388201,"timestamp":"2024-06-01T17:52:22.391815Z"}]}
{"channel":"book","type":"update","data":[{"symbol":"BCH/EUR","bids":[],"asks":[{"price":425.78,"qty":9.53947891}],"checksum":1665784085,"timestamp":"2024-06-01T17:52:22.393487Z"}]}
{"channel":"book","type":"update","data":[{"symbol":"BCH/EUR","bids":[],"asks":[{"price":425.49,"qty":0.00000000},{"price":425.99,"qty":0.10000000}],"checksum":3379293943,"timestamp":"2024-06-01T17:52:22.398232Z"}]}
{"channel":"book","type":"update","data":[{"symbol":"BCH/EUR","bids":[{"price":425.22,"qty":0.45000000}],"asks":[],"checksum":3908458896,"timestamp":"2024-06-01T17:52:22.398472Z"}]}
{"channel":"book","type":"update","data":[{"symbol":"BCH/EUR","bids":[],"asks":[{"price":425.59,"qty":0.00000000},{"price":426.14,"qty":5.90000000}],"checksum":2571784226,"timestamp":"2024-06-01T17:52:22.400722Z"}]}
{"channel":"book","type":"update","data":[{"symbol":"BCH/EUR","bids":[],"asks":[{"price":425.70,"qty":0.16130819}],"checksum":167362049,"timestamp":"2024-06-01T17:52:22.400935Z"}]}
{"channel":"book","type":"update","data":[{"symbol":"BCH/EUR","bids":[{"price":425.20,"qty":8.00000000}],"asks":[],"checksum":1970965059,"timestamp":"2024-06-01T17:52:22.402150Z"}]}
{"channel":"book","type":"update","data":[{"symbol":"BCH/EUR","bids":[{"price":425.23,"qty":10.00000000}],"asks":[],"checksum":3277801667,"timestamp":"2024-06-01T17:52:22.402777Z"}]}
{"channel":"book","type":"update","data":[{"symbol":"BCH/EUR","bids":[],"asks":[{"price":425.58,"qty":5.41617424}],"checksum":767919127,"timestamp":"2024-06-01T17:52:22.402923Z"}]}
{"channel":"book","type":"update","data":[{"symbol":"BCH/EUR","bids":[{"price":425.25,"qty":2.43340552}],"asks":[],"checksum":3864092690,"timestamp":"2024-06-01T17:52:22.403818Z"}]}
{"channel":"book","type":"update","data":[{"symbol":"BCH/EUR","bids":[{"price":425.26,"qty":3.88726919}],"asks":[],"checksum":3759414474,"timestamp":"2024-06-01T17:52:22.403944Z"}]}
{"channel":"book","type":"update","data":[{"symbol":"BCH/EUR","bids":[{"price":425.22,"qty":0.00000000},{"price":425.03,"qty":0.44000000}],"asks":[],"checksum":2169547933,"timestamp":"2024-06-01T17:52:22.405399Z"}]}
{"channel":"book","type":"update","data":[{"symbol":"BCH/EUR","bids":[{"price":425.24,"qty":8.28392088}],"asks":[],"checksum":2515734431,"timestamp":"2024-06-01T17:52:22.405934Z"}]}
{"channel":"book","type":"update","data":[{"symbol":"BCH/EUR","bids":[{"price":425.25,"qty":2.00000000}],"asks":[],"checksum":2736793527,"timestamp":"2024-06-01T17:52:22.407984Z"}]}
{"channel":"book","type":"update","data":[{"symbol":"BCH/EUR","bids":[],"asks":[{"price":425.76,"qty":0.00000000},{"price":425.99,"qty":0.10000000}],"checksum":845890493,"timestamp":"2024-06-01T17:52:22.409853Z"}]}
{"channel":"book","type":"update","data":[{"symbol":"BCH/EUR","bids":[],"asks":[{"price":425.70,"qty":0.00000000},{"price":426.13,"qty":49.88613000}],"checksum":2435087292,"timestamp":"2024-06-01T17:52:22.416283Z"}]}
{"channel":"book","type":"update","data":[{"symbol":"BCH/EUR","bids":[],"asks":[{"price":425.57,"qty":0.10173507}],"checksum":2392900433,"timestamp":"2024-06-01T17:52:22.416418Z"}]}
{"channel":"book","type":"update","data":[{"symbol":"BCH/EUR","bids":[{"price":425.19,"qty":0.00000000},{"price":425.00,"qty":10.84773558}],"asks":[],"checksum":1352206658,"timestamp":"2024-06-01T17:52:22.416727Z"}]}
{"channel":"book","type":"update","data":[{"symbol":"BCH/EUR","bids":[],"asks":[{"price":425.57,"qty":0.00000000},{"price":426.13,"qty":49.88613000}],"checksum":929704231,"timestamp":"2024-06-01T17:52:22.455200Z"}]}
{"channel":"book","type":"update","data":[{"symbol":"BCH/EUR","bids":[],"asks":[{"price":425.70,"qty":0.11474324}],"checksum":457432689,"timestamp":"2024-06-01T17:52:22.455632Z"}]}
{"channel":"book","type":"update","data":[{"symbol":"BCH/EUR","bids":[{"price":425.20,"qty":0.00000000},{"price":424.98,"qty":5.42368062}],"asks":[],"checksum":642304588,"timestamp":"2024-06-01T17:52:22.459620Z"}]}
{"channel":"book","type":"update","data":[{"symbol":"BCH/EUR","bids":[{"price":425.27,"qty":7.83392088}],"asks":[],"checksum":2810666293,"timestamp":"2024-06-01T17:52:22.459709Z"}]}
{"channel":"book","type":"update","data":[{"symbol":"BCH/EUR","bids":[{"price":425.15,"qty":0.00000000},{"price":424.98,"qty":5.42368062}],"asks":[],"checksum":3466603047,"timestamp":"2024-06-01T17:52:22.460336Z"}]}
{"channel":"book","type":"update","data":[{"symbol":"BCH/EUR","bids":[{"price":425.25,"qty":0.00000000},{"price":424.87,"qty":15.96804300}],"asks":[],"checksum":328850904,"timestamp":"2024-06-01T17:52:22.468085Z"}]}
{"channel":"book","type":"update","data":[{"symbol":"BCH/EUR","bids":[],"asks":[{"price":425.83,"qty":0.00000000},{"price":426.13,"qty":49.88613000}],"checksum":199744605,"timestamp":"2024-06-01T17:52:22.494052Z"}]}
{"channel":"book","type":"update","data":[{"symbol":"BCH/EUR","bids":[{"price":425.21,"qty":21.68864294}],"asks":[],"checksum":2308675336,"timestamp":"2024-06-01T17:52:22.505635Z"}]}
{"channel":"book","type":"update","data":[{"symbol":"BCH/EUR","bids":[{"price":425.24,"qty":0.45000000}],"asks":[],"checksum":328421356,"timestamp":"2024-06-01T17:52:22.508021Z"}]}
{"channel":"book","type":"update","data":[{"symbol":"BCH/EUR","bids":[{"price":425.00,"qty":0.00000000},{"price":424.86,"qty":0.34000000}],"asks":[],"checksum":3853226169,"timestamp":"2024-06-01T17:52:22.509023Z"}]}
{"channel":"book","type":"update","data":[{"symbol":"BCH/EUR","bids":[{"price":425.25,"qty":8.00000000}],"asks":[],"checksum":1671817912,"timestamp":"2024-06-01T17:52:22.510296Z"}]}
{"channel":"book","type":"update","data":[{"symbol":"BCH/EUR","bids":[],"asks":[{"price":425.86,"qty":8.00000000}],"checksum":2817144955,"timestamp":"2024-06-01T17:52:22.510443Z"}]}
{"channel":"book","type":"update","data":[{"symbol":"BCH/EUR","bids":[{"price":425.28,"qty":3.88726919}],"asks":[],"checksum":4031736867,"timestamp":"2024-06-01T17:52:22.510837Z"}]}
{"channel":"book","type":"update","data":[{"symbol":"BCH/EUR","bids":[{"price":425.28,"qty":5.88726919}],"asks":[],"checksum":2175947924,"timestamp":"2024-06-01T17:52:22.510871Z"}]}
{"channel":"book","type":"update","data":[{"symbol":"BCH/EUR","bids":[],"asks":[{"price":425.91,"qty":8.67226566}],"checksum":2621841903,"timestamp":"2024-06-01T17:52:22.529604Z"}]}
{"channel":"book","type":"update","data":[{"symbol":"BCH/EUR","bids":[{"price":425.40,"qty":0.86000000}],"asks":[],"checksum":3244975060,"timestamp":"2024-06-01T17:52:22.533772Z"}]}
{"channel":"book","type":"update","data":[{"symbol":"BCH/EUR","bids":[],"asks":[{"price":425.50,"qty":0.00000000},{"price":425.99,"qty":0.10000000}],"checksum":2744453481,"timestamp":"2024-06-01T17:52:22.537118Z"}]}
{"channel":"book","type":"update","data":[{"symbol":"BCH/EUR","bids":[],"asks":[{"price":425.47,"qty":0.00000000},{"price":426.13,"qty":49.88613000}],"checksum":2970551952,"timestamp":"2024-06-01T17:52:22.539913Z"}]}
{"channel":"book","type":"update","data":[{"symbol":"BCH/EUR","bids":[],"asks":[{"price":425.65,"qty":15.96804300}],"checksum":3389344268,"timestamp":"2024-06-01T17:52:22.539935Z"}]}
{"channel":"book","type":"update","data":[{"symbol":"BCH/EUR","bids":[{"price":425.24,"qty":0.00000000},{"price":424.98,"qty":5.42368062}],"asks":[],"checksum":1800156654,"timestamp":"2024-06-01T17:52:22.539966Z"}]}
{"channel":"book","type":"update","data":[{"symbol":"BCH/EUR","bids":[{"price":425.29,"qty":0.45000000}],"asks":[],"checksum":3215937447,"timestamp":"2024-06-01T17:52:22.540194Z"}]}
{"channel":"book","type":"update","data":[{"symbol":"BCH/EUR","bids":[],"asks":[{"price":425.56,"qty":0.45000000}],"checksum":2868491623,"timestamp":"2024-06-01T17:52:22.540232Z"}]}
{"channel":"book","type":"update","data":[{"symbol":"BCH/EUR","bids":[{"price":425.23,"qty":8.00000000}],"asks":[],"checksum":1185151940,"timestamp":"2024-06-01T17:52:22.540982Z"}]}
{"channel":"book","type":"update","data":[{"symbol":"BCH/EUR","bids":[{"price":425.23,"qty":0.00000000},{"price":424.98,"qty":5.42368062}],"asks":[],"checksum":1258264215,"timestamp":"2024-06-01T17:52:22.541535Z"}]}
{"channel":"book","type":"update","data":[{"symbol":"BCH/EUR","bids":[{"price":425.28,"qty":2.00000000}],"asks":[],"checksum":3899539820,"timestamp":"2024-06-01T17:52:22.541928Z"}]}
{"channel":"book","type":"update","data":[{"symbol":"BCH/EUR","bids":[{"price":425.30,"qty":7.83392088}],"asks":[],"checksum":3378158181,"timestamp":"2024-06-01T17:52:22.544558Z"}]}
{"channel":"book","type":"update","data":[{"symbol":"BCH/EUR","bids":[],"asks":[{"price":425.64,"qty":0.05514683}],"checksum":1642026425,"timestamp":"2024-06-01T17:52:22.547487Z"}]}
{"channel":"book","type":"update","data":[{"symbol":"BCH/EUR","bids":[],"asks":[{"price":425.70,"qty":0.00000000},{"price":425.91,"qty":8.67226566}],"checksum":4020590585,"timestamp":"2024-06-01T17:52:22.548084Z"}]}
{"channel":"book","type":"update","data":[{"symbol":"BCH/EUR","bids":[{"price":425.31,"qty":2.00000000}],"asks":[],"checksum":2350870850,"timestamp":"2024-06-01T17:52:22.629841Z"}]}
{"channel":"book","type":"update","data":[{"symbol":"BCH/EUR","bids":[{"price":425.30,"qty":0.00000000},{"price":425.03,"qty":0.44000000}],"asks":[],"checksum":4150803166,"timestamp":"2024-06-01T17:52:22.633719Z"}]}
{"channel":"book","type":"update","data":[{"symbol":"BCH/EUR","bids":[{"price":425.28,"qty":10.00000000}],"asks":[],"checksum":305576335,"timestamp":"2024-06-01T17:52:22.634701Z"}]}
{"channel":"book","type":"update","data":[{"symbol":"BCH/EUR","bids":[{"price":425.28,"qty":8.00000000}],"asks":[],"checksum":1468884276,"timestamp":"2024-06-01T17:52:22.635496Z"}]}
{"channel":"book","type":"update","data":[{"symbol":"BCH/EUR","bids":[],"asks":[{"price":425.66,"qty":0.03152465}],"checksum":1030145665,"timestamp":"2024-06-01T17:52:22.636358Z"}]}
{"channel":"book","type":"update","data":[{"symbol":"BCH/EUR","bids":[],"asks":[{"price":425.69,"qty":3.88726919}],"checksum":468367756,"timestamp":"2024-06-01T17:52:22.637544Z"}]}
{"channel":"book","type":"update","data":[{"symbol":"BCH/EUR","bids":[],"asks":[{"price":425.80,"qty":0.47000000}],"checksum":3501346635,"timestamp":"2024-06-01T17:52:22.650902Z"}]}
{"channel":"book","type":"update","data":[{"symbol":"BCH/EUR","bids":[{"price":425.31,"qty":2.09884543}],"asks":[],"checksum":4160349983,"timestamp":"2024-06-01T17:52:22.733335Z"}]}
{"channel":"book","type":"update","data":[{"symbol":"BCH/EUR","bids":[{"price":425.28,"qty":0.00000000},{"price":424.98,"qty":5.42368062}],"asks":[],"checksum":872639385,"timestamp":"2024-06-01T17:52:22.737728Z"}]}
{"channel":"book","type":"update","data":[{"symbol":"BCH/EUR","bids":[],"asks":[{"price":425.63,"qty":7.83392088}],"checksum":4236658716,"timestamp":"2024-06-01T17:52:23.010089Z"}]}
{"channel":"book","type":"update","data":[{"symbol":"BCH/EUR","bids":[{"price":425.27,"qty":15.83392088}],"asks":[],"checksum":3174073277,"timestamp":"2024-06-01T17:52:23.016728Z"}]}
{"channel":"book","type":"update","data":[{"symbol":"BCH/EUR","bids":[],"asks":[{"price":425.64,"qty":0.00000000},{"price":425.80,"qty":0.47000000}],"checksum":1567084738,"timestamp":"2024-06-01T17:52:23.026672Z"}]}
{"channel":"book","type":"update","data":[{"symbol":"BCH/EUR","bids":[],"asks":[{"price":425.62,"qty":0.05514942}],"checksum":2052410638,"timestamp":"2024-06-01T17:52:23.026699Z"}]}
{"channel":"book","type":"update","data":[{"symbol":"BCH/EUR","bids":[],"asks":[{"price":425.73,"qty":2.09884543}],"checksum":3621754479,"timestamp":"2024-06-01T17:52:23.077757Z"}]}
{"channel":"book","type":"update","data":[{"symbol":"BCH/EUR","bids":[{"price":425.40,"qty":0.00000000},{"price":424.87,"qty":15.96804300}],"asks":[],"checksum":4245430270,"timestamp":"2024-06-01T17:52:23.122245Z"}]}
{"channel":"book","type":"update","data":[{"symbol":"BCH/EUR","bids":[{"price":425.27,"qty":7.83392088}],"asks":[],"checksum":2234763928,"timestamp":"2024-06-01T17:52:23.126727Z"}]}
{"channel":"book","type":"update","data":[{"symbol":"BCH/EUR","bids":[{"price":425.29,"qty":5.86970566}],"asks":[],"checksum":1973679030,"timestamp":"2024-06-01T17:52:23.427579Z"}]}
