{"channel":"book","type":"snapshot","data":[{"symbol":"BCH/BTC","bids":[{"price":0.00681,"qty":30.15189589},{"price":0.00680,"qty":97.83280370},{"price":0.00679,"qty":126.29121132},{"price":0.00678,"qty":74.27718240},{"price":0.00676,"qty":33.70243070},{"price":0.00674,"qty":22.35608820},{"price":0.00673,"qty":177.59915711},{"price":0.00672,"qty":2.45511125},{"price":0.00671,"qty":15.34558460},{"price":0.00670,"qty":0.19953496}],"asks":[{"price":0.00682,"qty":0.29637523},{"price":0.00683,"qty":91.65323609},{"price":0.00684,"qty":128.56591462},{"price":0.00685,"qty":30.73599327},{"price":0.00686,"qty":1.62522282},{"price":0.00687,"qty":33.07805630},{"price":0.00688,"qty":15.26565390},{"price":0.00689,"qty":7.20000000},{"price":0.00690,"qty":31.01848460},{"price":0.00692,"qty":7.83790116}],"checksum":720184045}]}
{"channel":"book","type":"update","data":[{"symbol":"BCH/BTC","bids":[{"price":0.00680,"qty":77.58982370}],"asks":[],"checksum":1760428487,"timestamp":"2024-06-01T17:51:20.493431Z"}]}
{"channel":"book","type":"update","data":[{"symbol":"BCH/BTC","bids":[],"asks":[{"price":0.00690,"qty":9.08913460}],"checksum":1864032750,"timestamp":"2024-06-01T17:51:20.494085Z"}]}
{"channel":"book","type":"update","data":[{"symbol":"BCH/BTC","bids":[{"price":0.00680,"qty":75.86430370}],"asks":[],"checksum":533606611,"timestamp":"2024-06-01T17:51:20.540188Z"}]}
{"channel":"book","type":"update","data":[{"symbol":"BCH/BTC","bids":[],"asks":[{"price":0.00690,"qty":7.64558460}],"checksum":4136090770,"timestamp":"2024-06-01T17:51:20.549587Z"}]}
{"channel":"book","type":"update","data":[{"symbol":"BCH/BTC","bids":[{"price":0.00680,"qty":99.37073370}],"asks":[],"checksum":2881989773,"timestamp":"2024-06-01T17:51:20.574147Z"}]}
{"channel":"book","type":"update","data":[{"symbol":"BCH/BTC","bids":[],"asks":[{"price":0.00690,"qty":29.92464460}],"checksum":1279327586,"timestamp":"2024-06-01T17:51:20.575071Z"}]}
{"channel":"book","type":"update","data":[{"symbol":"BCH/BTC","bids":[],"asks":[{"price":0.00690,"qty":31.40164460}],"checksum":1840678510,"timestamp":"2024-06-01T17:51:20.604461Z"}]}
{"channel":"book","type":"update","data":[{"symbol":"BCH/BTC","bids":[{"price":0.00680,"qty":101.12748370}],"asks":[],"checksum":2052164634,"timestamp":"2024-06-01T17:51:20.607117Z"}]}
{"channel":"book","type":"update","data":[{"symbol":"BCH/BTC","bids":[],"asks":[{"price":0.00682,"qty":10.39637523}],"checksum":280836023,"timestamp":"2024-06-01T17:51:23.804906Z"}]}
{"channel":"book","type":"update","data":[{"symbol":"BCH/BTC","bids":[],"asks":[{"price":0.00683,"qty":81.55323609}],"checksum":406236038,"timestamp":"2024-06-01T17:51:23.865141Z"}]}
{"channel":"book","type":"update","data":[{"symbol":"BCH/BTC","bids":[],"asks":[{"price":0.00682,"qty":15.39637523}],"checksum":2780553339,"timestamp":"2024-06-01T17:51:23.890372Z"}]}
{"channel":"book","type":"update","data":[{"symbol":"BCH/BTC","bids":[],"asks":[{"price":0.00683,"qty":76.55323609}],"checksum":2134577947,"timestamp":"2024-06-01T17:51:23.945993Z"}]}
{"channel":"book","type":"update","data":[{"symbol":"BCH/BTC","bids":[],"asks":[{"price":0.00682,"qty":10.39637523}],"checksum":3266730214,"timestamp":"2024-06-01T17:51:24.052503Z"}]}
{"channel":"book","type":"update","data":[{"symbol":"BCH/BTC","bids":[],"asks":[{"price":0.00682,"qty":0.29637523}],"checksum":2824528715,"timestamp":"2024-06-01T17:51:24.057816Z"}]}
{"channel":"book","type":"update","data":[{"symbol":"BCH/BTC","bids":[],"asks":[{"price":0.00683,"qty":86.65323609}],"checksum":3492034206,"timestamp":"2024-06-01T17:51:24.057937Z"}]}
{"channel":"book","type":"update","data":[{"symbol":"BCH/BTC","bids":[],"asks":[{"price":0.00692,"qty":0.13790116}],"checksum":2364386951,"timestamp":"2024-06-01T17:51:24.531851Z"}]}
{"channel":"book","type":"update","data":[{"symbol":"BCH/BTC","bids":[],"asks":[{"price":0.00692,"qty":7.83790116}],"checksum":3492034206,"timestamp":"2024-06-01T17:51:24.567018Z"}]}
{"channel":"book","type":"update","data":[{"symbol":"BCH/BTC","bids":[{"price":0.00671,"qty":7.64558460}],"asks":[],"checksum":263943661,"timestamp":"2024-06-01T17:51:24.614113Z"}]}
{"channel":"book","type":"update","data":[{"symbol":"BCH/BTC","bids":[{"price":0.00671,"qty":15.34558460}],"asks":[],"checksum":3492034206,"timestamp":"2024-06-01T17:51:24.645003Z"}]}
{"channel":"book","type":"update","data":[{"symbol":"BCH/BTC","bids":[],"asks":[{"price":0.00682,"qty":5.29637523}],"checksum":528357732,"timestamp":"2024-06-01T17:51:25.054509Z"}]}
{"channel":"book","type":"update","data":[{"symbol":"BCH/BTC","bids":[],"asks":[{"price":0.00682,"qty":15.39637523}],"checksum":122013390,"timestamp":"2024-06-01T17:51:25.063106Z"}]}
{"channel":"book","type":"update","data":[{"symbol":"BCH/BTC","bids":[],"asks":[{"price":0.00683,"qty":76.55323609}],"checksum":2134577947,"timestamp":"2024-06-01T17:51:25.300499Z"}]}
{"channel":"book","type":"update","data":[{"symbol":"BCH/BTC","bids":[],"asks":[{"price":0.00686,"qty":0.82522282}],"checksum":3303160976,"timestamp":"2024-06-01T17:51:30.469638Z"}]}
{"channel":"book","type":"update","data":[{"symbol":"BCH/BTC","bids":[],"asks":[{"price":0.00685,"qty":31.53599327}],"checksum":3040620276,"timestamp":"2024-06-01T17:51:30.501911Z"}]}
{"channel":"book","type":"update","data":[{"symbol":"BCH/BTC","bids":[],"asks":[{"price":0.00685,"qty":0.87238694}],"checksum":2456038772,"timestamp":"2024-06-01T17:51:31.263338Z"}]}
{"channel":"book","type":"update","data":[{"symbol":"BCH/BTC","bids":[],"asks":[{"price":0.00684,"qty":159.20712668}],"checksum":2334629633,"timestamp":"2024-06-01T17:51:31.303630Z"}]}
{"channel":"book","type":"update","data":[{"symbol":"BCH/BTC","bids":[{"price":0.00679,"qty":82.02216582}],"asks":[],"checksum":3336739460,"timestamp":"2024-06-01T17:51:39.602264Z"}]}
{"channel":"book","type":"update","data":[{"symbol":"BCH/BTC","bids":[{"price":0.00677,"qty":44.26904550}],"asks":[],"checksum":1732086233,"timestamp":"2024-06-01T17:51:39.605045Z"}]}
{"channel":"book","type":"update","data":[{"symbol":"BCH/BTC","bids":[],"asks":[{"price":0.00683,"qty":76.52823609}],"checksum":622281971,"timestamp":"2024-06-01T17:51:40.191396Z"}]}
{"channel":"book","type":"update","data":[{"symbol":"BCH/BTC","bids":[],"asks":[{"price":0.00683,"qty":76.55323609}],"checksum":1732086233,"timestamp":"2024-06-01T17:51:40.324054Z"}]}
{"channel":"book","type":"update","data":[{"symbol":"BCH/BTC","bids":[{"price":0.00679,"qty":81.99716582}],"asks":[],"checksum":3985046143,"timestamp":"2024-06-01T17:51:44.166849Z"}]}
{"channel":"book","type":"update","data":[{"symbol":"BCH/BTC","bids":[{"price":0.00679,"qty":82.02216582}],"asks":[],"checksum":1732086233,"timestamp":"2024-06-01T17:51:44.241368Z"}]}
{"channel":"book","type":"update","data":[{"symbol":"BCH/BTC","bids":[],"asks":[{"price":0.00687,"qty":29.27805630}],"checksum":3307549523,"timestamp":"2024-06-01T17:51:50.003797Z"}]}
{"channel":"book","type":"update","data":[{"symbol":"BCH/BTC","bids":[],"asks":[{"price":0.00687,"qty":33.07805630}],"checksum":1732086233,"timestamp":"2024-06-01T17:51:50.031662Z"}]}
{"channel":"book","type":"update","data":[{"symbol":"BCH/BTC","bids":[{"price":0.00676,"qty":29.90243070}],"asks":[],"checksum":1097322609,"timestamp":"2024-06-01T17:51:54.327394Z"}]}
{"channel":"book","type":"update","data":[{"symbol":"BCH/BTC","bids":[{"price":0.00676,"qty":33.70243070}],"asks":[],"checksum":1732086233,"timestamp":"2024-06-01T17:51:54.356840Z"}]}
{"channel":"book","type":"update","data":[{"symbol":"BCH/BTC","bids":[{"price":0.00680,"qty":77.62105370}],"asks":[],"checksum":1285425492,"timestamp":"2024-06-01T17:51:58.724298Z"}]}
{"channel":"book","type":"update","data":[{"symbol":"BCH/BTC","bids":[],"asks":[{"price":0.00690,"qty":9.12258460}],"checksum":512987361,"timestamp":"2024-06-01T17:51:58.725281Z"}]}
{"channel":"book","type":"update","data":[{"symbol":"BCH/BTC","bids":[{"price":0.00680,"qty":75.86430370}],"asks":[],"checksum":2499322690,"timestamp":"2024-06-01T17:51:58.772763Z"}]}
{"channel":"book","type":"update","data":[{"symbol":"BCH/BTC","bids":[],"asks":[{"price":0.00690,"qty":7.64558460}],"checksum":2897720021,"timestamp":"2024-06-01T17:51:58.784320Z"}]}
{"channel":"book","type":"update","data":[{"symbol":"BCH/BTC","bids":[{"price":0.00680,"qty":96.99829370}],"asks":[],"checksum":2957299534,"timestamp":"2024-06-01T17:51:58.791646Z"}]}
{"channel":"book","type":"update","data":[{"symbol":"BCH/BTC","bids":[],"asks":[{"price":0.00690,"qty":28.20363460}],"checksum":980824702,"timestamp":"2024-06-01T17:51:58.791853Z"}]}
{"channel":"book","type":"update","data":[{"symbol":"BCH/BTC","bids":[{"price":0.00680,"qty":98.66690370}],"asks":[],"checksum":2259797157,"timestamp":"2024-06-01T17:51:58.827601Z"}]}
{"channel":"book","type":"update","data":[{"symbol":"BCH/BTC","bids":[],"asks":[{"price":0.00690,"qty":29.83914460}],"checksum":3129908138,"timestamp":"2024-06-01T17:51:58.829153Z"}]}
{"channel":"book","type":"update","data":[{"symbol":"BCH/BTC","bids":[{"price":0.00677,"qty":0.00000000},{"price":0.00670,"qty":0.19953496}],"asks":[],"checksum":2739463670,"timestamp":"2024-06-01T17:52:03.199773Z"}]}
{"channel":"book","type":"update","data":[{"symbol":"BCH/BTC","bids":[],"asks":[{"price":0.00682,"qty":5.29637523}],"checksum":3908072,"timestamp":"2024-06-01T17:52:03.199899Z"}]}
{"channel":"book","type":"update","data":[{"symbol":"BCH/BTC","bids":[{"price":0.00679,"qty":126.29121132}],"asks":[],"checksum":3487918921,"timestamp":"2024-06-01T17:52:03.202788Z"}]}
{"channel":"book","type":"update","data":[{"symbol":"BCH/BTC","bids":[],"asks":[{"price":0.00683,"qty":76.04568566}],"checksum":901204796,"timestamp":"2024-06-01T17:52:03.290634Z"}]}
{"channel":"book","type":"update","data":[{"symbol":"BCH/BTC","bids":[],"asks":[{"price":0.00682,"qty":15.39637523}],"checksum":3474654491,"timestamp":"2024-06-01T17:52:03.301959Z"}]}
{"channel":"book","type":"update","data":[{"symbol":"BCH/BTC","bids":[],"asks":[{"price":0.00685,"qty":1.37921482}],"checksum":1626200456,"timestamp":"2024-06-01T17:52:03.438642Z"}]}
{"channel":"book","type":"update","data":[{"symbol":"BCH/BTC","bids":[],"asks":[{"price":0.00685,"qty":0.87238694}],"checksum":3474654491,"timestamp":"2024-06-01T17:52:04.028556Z"}]}
{"channel":"book","type":"update","data":[{"symbol":"BCH/BTC","bids":[],"asks":[{"price":0.00683,"qty":76.55251354}],"checksum":1877890479,"timestamp":"2024-06-01T17:52:04.029585Z"}]}
{"channel":"book","type":"update","data":[{"symbol":"BCH/BTC","bids":[],"asks":[{"price":0.00684,"qty":128.56591462}],"checksum":1080709433,"timestamp":"2024-06-01T17:52:06.814492Z"}]}
{"channel":"book","type":"update","data":[{"symbol":"BCH/BTC","bids":[],"asks":[{"price":0.00685,"qty":31.50113779}],"checksum":444041463,"timestamp":"2024-06-01T17:52:06.854674Z"}]}
{"channel":"book","type":"update","data":[{"symbol":"BCH/BTC","bids":[{"price":0.00680,"qty":77.53291370}],"asks":[],"checksum":3899115938,"timestamp":"2024-06-01T17:52:11.617676Z"}]}
{"channel":"book","type":"update","data":[{"symbol":"BCH/BTC","bids":[],"asks":[{"price":0.00690,"qty":9.28109460}],"checksum":1469399875,"timestamp":"2024-06-01T17:52:11.618743Z"}]}
{"channel":"book","type":"update","data":[{"symbol":"BCH/BTC","bids":[{"price":0.00680,"qty":75.86430370}],"asks":[],"checksum":2615950070,"timestamp":"2024-06-01T17:52:11.657706Z"}]}
{"channel":"book","type":"update","data":[{"symbol":"BCH/BTC","bids":[],"asks":[{"price":0.00690,"qty":7.64558460}],"checksum":830341517,"timestamp":"2024-06-01T17:52:11.700737Z"}]}
