{"channel":"book","type":"snapshot","data":[{"symbol":"BCH/USDT","bids":[{"price":461.07,"qty":0.90000000},{"price":461.06,"qty":7.83392088},{"price":461.05,"qty":3.00000000},{"price":461.04,"qty":3.80879832},{"price":461.00,"qty":0.32333877},{"price":460.45,"qty":6.50186806},{"price":460.43,"qty":0.76032560},{"price":460.40,"qty":1.22648000},{"price":460.23,"qty":1.16000000},{"price":460.03,"qty":2.50000000}],"asks":[{"price":461.44,"qty":8.73392088},{"price":461.45,"qty":3.80879832},{"price":461.47,"qty":3.00000000},{"price":461.50,"qty":2.10522891},{"price":461.57,"qty":0.76032560},{"price":461.67,"qty":0.04648253},{"price":461.83,"qty":1.36603240},{"price":461.84,"qty":2.58370377},{"price":461.85,"qty":0.29976596},{"price":462.16,"qty":0.04431792}],"checksum":780099003}]}
{"channel":"book","type":"update","data":[{"symbol":"BCH/USDT","bids":[{"price":460.40,"qty":0.00000000},{"price":459.94,"qty":1.36603240}],"asks":[],"checksum":3668081919,"timestamp":"2024-06-01T17:51:20.549306Z"}]}
{"channel":"book","type":"update","data":[{"symbol":"BCH/USDT","bids":[{"price":460.50,"qty":1.42666000}],"asks":[],"checksum":401010592,"timestamp":"2024-06-01T17:51:20.610539Z"}]}
{"channel":"book","type":"update","data":[{"symbol":"BCH/USDT","bids":[],"asks":[{"price":461.47,"qty":0.00000000},{"price":462.17,"qty":0.08972479}],"checksum":688334415,"timestamp":"2024-06-01T17:51:23.841308Z"}]}
{"channel":"book","type":"update","data":[{"symbol":"BCH/USDT","bids":[],"asks":[{"price":461.45,"qty":0.00000000},{"price":462.18,"qty":0.06585657}],"checksum":136686335,"timestamp":"2024-06-01T17:51:23.866683Z"}]}
{"channel":"book","type":"update","data":[{"symbol":"BCH/USDT","bids":[],"asks":[{"price":461.44,"qty":7.83392088}],"checksum":563106821,"timestamp":"2024-06-01T17:51:23.867195Z"}]}
{"channel":"book","type":"update","data":[{"symbol":"BCH/USDT","bids":[],"asks":[{"price":461.50,"qty":0.00000000},{"price":462.20,"qty":1.17906000}],"checksum":560937858,"timestamp":"2024-06-01T17:51:23.868761Z"}]}
{"channel":"book","type":"update","data":[{"symbol":"BCH/USDT","bids":[],"asks":[{"price":461.44,"qty":0.00000000},{"price":462.45,"qty":4.78432880}],"checksum":773029737,"timestamp":"2024-06-01T17:51:23.872069Z"}]}
{"channel":"book","type":"update","data":[{"symbol":"BCH/USDT","bids":[],"asks":[{"price":461.84,"qty":0.00000000},{"price":462.46,"qty":1.24000000}],"checksum":2326023911,"timestamp":"2024-06-01T17:51:23.886331Z"}]}
{"channel":"book","type":"update","data":[{"symbol":"BCH/USDT","bids":[],"asks":[{"price":461.82,"qty":2.58370377}],"checksum":2784647364,"timestamp":"2024-06-01T17:51:23.886359Z"}]}
{"channel":"book","type":"update","data":[{"symbol":"BCH/USDT","bids":[],"asks":[{"price":461.50,"qty":0.67572891}],"checksum":1359044363,"timestamp":"2024-06-01T17:51:23.902505Z"}]}
{"channel":"book","type":"update","data":[{"symbol":"BCH/USDT","bids":[],"asks":[{"price":461.49,"qty":3.80879832}],"checksum":893914400,"timestamp":"2024-06-01T17:51:23.950843Z"}]}
{"channel":"book","type":"update","data":[{"symbol":"BCH/USDT","bids":[],"asks":[{"price":461.48,"qty":3.00000000}],"checksum":3447212499,"timestamp":"2024-06-01T17:51:23.955914Z"}]}
{"channel":"book","type":"update","data":[{"symbol":"BCH/USDT","bids":[],"asks":[{"price":461.48,"qty":3.90000000}],"checksum":2355742195,"timestamp":"2024-06-01T17:51:23.957313Z"}]}
{"channel":"book","type":"update","data":[{"symbol":"BCH/USDT","bids":[],"asks":[{"price":461.49,"qty":0.00000000},{"price":462.18,"qty":0.06585657}],"checksum":2368860057,"timestamp":"2024-06-01T17:51:24.050049Z"}]}
{"channel":"book","type":"update","data":[{"symbol":"BCH/USDT","bids":[],"asks":[{"price":461.48,"qty":0.90000000}],"checksum":2356757543,"timestamp":"2024-06-01T17:51:24.050140Z"}]}
{"channel":"book","type":"update","data":[{"symbol":"BCH/USDT","bids":[],"asks":[{"price":461.50,"qty":0.00000000},{"price":462.20,"qty":1.17906000}],"checksum":1947459073,"timestamp":"2024-06-01T17:51:24.051757Z"}]}
{"channel":"book","type":"update","data":[{"symbol":"BCH/USDT","bids":[],"asks":[{"price":461.60,"qty":6.52222891}],"checksum":642160238,"timestamp":"2024-06-01T17:51:24.056515Z"}]}
{"channel":"book","type":"update","data":[{"symbol":"BCH/USDT","bids":[],"asks":[{"price":461.48,"qty":0.00000000},{"price":462.20,"qty":1.17906000}],"checksum":1883306785,"timestamp":"2024-06-01T17:51:24.091140Z"}]}
{"channel":"book","type":"update","data":[{"symbol":"BCH/USDT","bids":[],"asks":[{"price":461.56,"qty":0.90000000}],"checksum":640626648,"timestamp":"2024-06-01T17:51:24.091280Z"}]}
{"channel":"book","type":"update","data":[{"symbol":"BCH/USDT","bids":[{"price":461.07,"qty":3.90000000}],"asks":[],"checksum":4168639524,"timestamp":"2024-06-01T17:51:24.096683Z"}]}
{"channel":"book","type":"update","data":[{"symbol":"BCH/USDT","bids":[{"price":461.08,"qty":3.80879832}],"asks":[],"checksum":3933837320,"timestamp":"2024-06-01T17:51:24.097780Z"}]}
{"channel":"book","type":"update","data":[{"symbol":"BCH/USDT","bids":[{"price":461.09,"qty":3.00000000}],"asks":[],"checksum":1764267588,"timestamp":"2024-06-01T17:51:24.211166Z"}]}
{"channel":"book","type":"update","data":[{"symbol":"BCH/USDT","bids":[{"price":461.05,"qty":0.00000000},{"price":460.23,"qty":1.16000000}],"asks":[],"checksum":2304740724,"timestamp":"2024-06-01T17:51:24.211277Z"}]}
{"channel":"book","type":"update","data":[{"symbol":"BCH/USDT","bids":[],"asks":[{"price":461.56,"qty":3.90000000}],"checksum":2419918869,"timestamp":"2024-06-01T17:51:24.211329Z"}]}
{"channel":"book","type":"update","data":[{"symbol":"BCH/USDT","bids":[{"price":461.10,"qty":7.83392088}],"asks":[],"checksum":1418747210,"timestamp":"2024-06-01T17:51:24.215150Z"}]}
{"channel":"book","type":"update","data":[{"symbol":"BCH/USDT","bids":[{"price":461.07,"qty":0.90000000}],"asks":[],"checksum":2883003602,"timestamp":"2024-06-01T17:51:24.215885Z"}]}
{"channel":"book","type":"update","data":[{"symbol":"BCH/USDT","bids":[],"asks":[{"price":461.56,"qty":0.90000000}],"checksum":2774807620,"timestamp":"2024-06-01T17:51:24.215897Z"}]}
{"channel":"book","type":"update","data":[{"symbol":"BCH/USDT","bids":[],"asks":[{"price":461.59,"qty":3.00000000}],"checksum":1138290154,"timestamp":"2024-06-01T17:51:24.215931Z"}]}
{"channel":"book","type":"update","data":[{"symbol":"BCH/USDT","bids":[{"price":461.10,"qty":8.73392088}],"asks":[],"checksum":3780326351,"timestamp":"2024-06-01T17:51:24.216771Z"}]}
{"channel":"book","type":"update","data":[{"symbol":"BCH/USDT","bids":[{"price":461.04,"qty":0.00000000},{"price":460.23,"qty":1.16000000}],"asks":[],"checksum":2337647979,"timestamp":"2024-06-01T17:51:24.217470Z"}]}
{"channel":"book","type":"update","data":[{"symbol":"BCH/USDT","bids":[{"price":461.10,"qty":12.54271920}],"asks":[],"checksum":2395606001,"timestamp":"2024-06-01T17:51:24.217649Z"}]}
{"channel":"book","type":"update","data":[{"symbol":"BCH/USDT","bids":[],"asks":[{"price":461.55,"qty":3.80879832}],"checksum":257705969,"timestamp":"2024-06-01T17:51:24.217662Z"}]}
{"channel":"book","type":"update","data":[{"symbol":"BCH/USDT","bids":[{"price":461.08,"qty":0.00000000},{"price":460.03,"qty":2.50000000}],"asks":[],"checksum":3397244150,"timestamp":"2024-06-01T17:51:24.451192Z"}]}
{"channel":"book","type":"update","data":[{"symbol":"BCH/USDT","bids":[{"price":461.06,"qty":0.00000000},{"price":459.94,"qty":1.36603240}],"asks":[],"checksum":3018130273,"timestamp":"2024-06-01T17:51:24.455254Z"}]}
{"channel":"book","type":"update","data":[{"symbol":"BCH/USDT","bids":[],"asks":[{"price":461.54,"qty":7.83392088}],"checksum":462573959,"timestamp":"2024-06-01T17:51:24.455363Z"}]}
{"channel":"book","type":"update","data":[{"symbol":"BCH/USDT","bids":[{"price":461.11,"qty":3.00000000}],"asks":[],"checksum":1026235226,"timestamp":"2024-06-01T17:51:24.456012Z"}]}
{"channel":"book","type":"update","data":[{"symbol":"BCH/USDT","bids":[{"price":461.07,"qty":0.00000000},{"price":459.94,"qty":1.36603240}],"asks":[],"checksum":1105126278,"timestamp":"2024-06-01T17:51:24.456891Z"}]}
{"channel":"book","type":"update","data":[{"symbol":"BCH/USDT","bids":[],"asks":[{"price":461.54,"qty":8.73392088}],"checksum":2874513832,"timestamp":"2024-06-01T17:51:24.456969Z"}]}
{"channel":"book","type":"update","data":[{"symbol":"BCH/USDT","bids":[{"price":461.12,"qty":7.83392088}],"asks":[],"checksum":1022824874,"timestamp":"2024-06-01T17:51:24.515404Z"}]}
{"channel":"book","type":"update","data":[{"symbol":"BCH/USDT","bids":[{"price":461.09,"qty":0.00000000},{"price":459.94,"qty":1.36603240}],"asks":[],"checksum":2174967114,"timestamp":"2024-06-01T17:51:24.520365Z"}]}
{"channel":"book","type":"update","data":[{"symbol":"BCH/USDT","bids":[{"price":461.13,"qty":3.00000000}],"asks":[],"checksum":476641009,"timestamp":"2024-06-01T17:51:24.520577Z"}]}
{"channel":"book","type":"update","data":[{"symbol":"BCH/USDT","bids":[{"price":461.13,"qty":6.80879832}],"asks":[],"checksum":597705478,"timestamp":"2024-06-01T17:51:24.520733Z"}]}
{"channel":"book","type":"update","data":[{"symbol":"BCH/USDT","bids":[{"price":461.10,"qty":4.70879832}],"asks":[],"checksum":1603750378,"timestamp":"2024-06-01T17:51:24.521178Z"}]}
{"channel":"book","type":"update","data":[{"symbol":"BCH/USDT","bids":[],"asks":[{"price":461.56,"qty":0.00000000},{"price":462.16,"qty":0.04431792}],"checksum":4168720725,"timestamp":"2024-06-01T17:51:24.522664Z"}]}
{"channel":"book","type":"update","data":[{"symbol":"BCH/USDT","bids":[{"price":461.13,"qty":7.70879832}],"asks":[],"checksum":288450680,"timestamp":"2024-06-01T17:51:24.522743Z"}]}
{"channel":"book","type":"update","data":[{"symbol":"BCH/USDT","bids":[{"price":461.10,"qty":3.80879832}],"asks":[],"checksum":2354535487,"timestamp":"2024-06-01T17:51:24.587216Z"}]}
{"channel":"book","type":"update","data":[{"symbol":"BCH/USDT","bids":[{"price":461.11,"qty":0.00000000},{"price":459.94,"qty":1.36603240}],"asks":[],"checksum":3391052848,"timestamp":"2024-06-01T17:51:24.591782Z"}]}
{"channel":"book","type":"update","data":[{"symbol":"BCH/USDT","bids":[{"price":461.10,"qty":0.00000000},{"price":459.93,"qty":1.22000000}],"asks":[],"checksum":67771038,"timestamp":"2024-06-01T17:51:24.591881Z"}]}
{"channel":"book","type":"update","data":[{"symbol":"BCH/USDT","bids":[{"price":461.13,"qty":4.70879832}],"asks":[],"checksum":575964604,"timestamp":"2024-06-01T17:51:24.802914Z"}]}
{"channel":"book","type":"update","data":[{"symbol":"BCH/USDT","bids":[{"price":461.13,"qty":0.90000000}],"asks":[],"checksum":474439753,"timestamp":"2024-06-01T17:51:24.803011Z"}]}
{"channel":"book","type":"update","data":[{"symbol":"BCH/USDT","bids":[{"price":460.51,"qty":1.68306690}],"asks":[],"checksum":1007848466,"timestamp":"2024-06-01T17:51:24.807472Z"}]}
{"channel":"book","type":"update","data":[{"symbol":"BCH/USDT","bids":[{"price":460.45,"qty":0.00000000},{"price":459.93,"qty":1.22000000}],"asks":[],"checksum":1901063736,"timestamp":"2024-06-01T17:51:24.823793Z"}]}
{"channel":"book","type":"update","data":[{"symbol":"BCH/USDT","bids":[{"price":460.52,"qty":6.50087976}],"asks":[],"checksum":1052013248,"timestamp":"2024-06-01T17:51:24.823941Z"}]}
{"channel":"book","type":"update","data":[{"symbol":"BCH/USDT","bids":[{"price":460.51,"qty":0.00000000},{"price":459.93,"qty":1.22000000}],"asks":[],"checksum":3492220895,"timestamp":"2024-06-01T17:51:24.828553Z"}]}
{"channel":"book","type":"update","data":[{"symbol":"BCH/USDT","bids":[{"price":460.53,"qty":1.68306690}],"asks":[],"checksum":1688315511,"timestamp":"2024-06-01T17:51:24.828767Z"}]}
{"channel":"book","type":"update","data":[{"symbol":"BCH/USDT","bids":[],"asks":[{"price":461.53,"qty":3.00000000}],"checksum":2589141239,"timestamp":"2024-06-01T17:51:24.835818Z"}]}
{"channel":"book","type":"update","data":[{"symbol":"BCH/USDT","bids":[{"price":461.12,"qty":0.00000000},{"price":459.93,"qty":1.22000000}],"asks":[],"checksum":1094644297,"timestamp":"2024-06-01T17:51:24.840300Z"}]}
{"channel":"book","type":"update","data":[{"symbol":"BCH/USDT","bids":[{"price":461.01,"qty":7.83392088}],"asks":[],"checksum":516153661,"timestamp":"2024-06-01T17:51:24.840406Z"}]}
{"channel":"book","type":"update","data":[{"symbol":"BCH/USDT","bids":[],"asks":[{"price":461.52,"qty":0.90000000}],"checksum":265598710,"timestamp":"2024-06-01T17:51:24.840804Z"}]}
{"channel":"book","type":"update","data":[{"symbol":"BCH/USDT","bids":[],"asks":[{"price":461.52,"qty":4.70879832}],"checksum":2850684453,"timestamp":"2024-06-01T17:51:24.840851Z"}]}
{"channel":"book","type":"update","data":[{"symbol":"BCH/USDT","bids":[{"price":460.53,"qty":0.00000000},{"price":459.93,"qty":1.22000000}],"asks":[],"checksum":493836173,"timestamp":"2024-06-01T17:51:24.844374Z"}]}
{"channel":"book","type":"update","data":[{"symbol":"BCH/USDT","bids":[{"price":461.02,"qty":1.62711187}],"asks":[],"checksum":2573648717,"timestamp":"2024-06-01T17:51:24.844554Z"}]}
{"channel":"book","type":"update","data":[{"symbol":"BCH/USDT","bids":[],"asks":[{"price":461.55,"qty":0.00000000},{"price":461.85,"qty":0.29976596}],"checksum":3006231948,"timestamp":"2024-06-01T17:51:24.953011Z"}]}
{"channel":"book","type":"update","data":[{"symbol":"BCH/USDT","bids":[{"price":461.01,"qty":11.64271920}],"asks":[],"checksum":1509423860,"timestamp":"2024-06-01T17:51:24.953049Z"}]}
{"channel":"book","type":"update","data":[{"symbol":"BCH/USDT","bids":[],"asks":[{"price":461.54,"qty":7.83392088}],"checksum":3120810743,"timestamp":"2024-06-01T17:51:24.957491Z"}]}
{"channel":"book","type":"update","data":[{"symbol":"BCH/USDT","bids":[{"price":461.03,"qty":7.83392088}],"asks":[],"checksum":1322258062,"timestamp":"2024-06-01T17:51:24.957537Z"}]}
{"channel":"book","type":"update","data":[{"symbol":"BCH/USDT","bids":[],"asks":[{"price":461.59,"qty":0.00000000},{"price":462.16,"qty":0.04431792}],"checksum":1151991279,"timestamp":"2024-06-01T17:51:24.957997Z"}]}
{"channel":"book","type":"update","data":[{"symbol":"BCH/USDT","bids":[],"asks":[{"price":461.51,"qty":3.00000000}],"checksum":1203679327,"timestamp":"2024-06-01T17:51:24.958183Z"}]}
{"channel":"book","type":"update","data":[{"symbol":"BCH/USDT","bids":[{"price":461.03,"qty":10.83392088}],"asks":[],"checksum":2871681796,"timestamp":"2024-06-01T17:51:24.958194Z"}]}
{"channel":"book","type":"update","data":[{"symbol":"BCH/USDT","bids":[{"price":461.02,"qty":0.00000000},{"price":459.94,"qty":1.36603240}],"asks":[],"checksum":3074505515,"timestamp":"2024-06-01T17:51:24.962610Z"}]}
{"channel":"book","type":"update","data":[{"symbol":"BCH/USDT","bids":[{"price":461.03,"qty":3.00000000}],"asks":[],"checksum":2201715327,"timestamp":"2024-06-01T17:51:25.012821Z"}]}
{"channel":"book","type":"update","data":[{"symbol":"BCH/USDT","bids":[{"price":461.03,"qty":4.67085000}],"asks":[],"checksum":1630971756,"timestamp":"2024-06-01T17:51:25.017899Z"}]}
{"channel":"book","type":"update","data":[{"symbol":"BCH/USDT","bids":[],"asks":[{"price":461.53,"qty":0.00000000},{"price":462.16,"qty":0.04431792}],"checksum":808071043,"timestamp":"2024-06-01T17:51:25.018124Z"}]}
{"channel":"book","type":"update","data":[{"symbol":"BCH/USDT","bids":[],"asks":[{"price":461.50,"qty":3.80879832}],"checksum":1174231471,"timestamp":"2024-06-01T17:51:25.018245Z"}]}
{"channel":"book","type":"update","data":[{"symbol":"BCH/USDT","bids":[],"asks":[{"price":461.50,"qty":4.70879832}],"checksum":3853425247,"timestamp":"2024-06-01T17:51:25.018851Z"}]}
{"channel":"book","type":"update","data":[{"symbol":"BCH/USDT","bids":[{"price":461.13,"qty":0.00000000},{"price":459.93,"qty":1.22000000}],"asks":[],"checksum":373280649,"timestamp":"2024-06-01T17:51:25.089216Z"}]}
{"channel":"book","type":"update","data":[{"symbol":"BCH/USDT","bids":[],"asks":[{"price":461.52,"qty":3.80879832}],"checksum":3477670707,"timestamp":"2024-06-01T17:51:25.089278Z"}]}
{"channel":"book","type":"update","data":[{"symbol":"BCH/USDT","bids":[{"price":461.04,"qty":0.90000000}],"asks":[],"checksum":988910769,"timestamp":"2024-06-01T17:51:25.089366Z"}]}
{"channel":"book","type":"update","data":[{"symbol":"BCH/USDT","bids":[{"price":461.03,"qty":3.00000000}],"asks":[],"checksum":3640439202,"timestamp":"2024-06-01T17:51:25.093976Z"}]}
{"channel":"book","type":"update","data":[{"symbol":"BCH/USDT","bids":[{"price":461.02,"qty":1.66926000}],"asks":[],"checksum":3773494559,"timestamp":"2024-06-01T17:51:25.093986Z"}]}
{"channel":"book","type":"update","data":[{"symbol":"BCH/USDT","bids":[],"asks":[{"price":461.49,"qty":3.00000000}],"checksum":2707436025,"timestamp":"2024-06-01T17:51:25.094892Z"}]}
{"channel":"book","type":"update","data":[{"symbol":"BCH/USDT","bids":[],"asks":[{"price":461.52,"qty":0.00000000},{"price":461.85,"qty":0.29976596}],"checksum":3694363088,"timestamp":"2024-06-01T17:51:25.095249Z"}]}
{"channel":"book","type":"update","data":[{"symbol":"BCH/USDT","bids":[{"price":461.04,"qty":4.70879832}],"asks":[],"checksum":3675280271,"timestamp":"2024-06-01T17:51:25.095427Z"}]}
{"channel":"book","type":"update","data":[{"symbol":"BCH/USDT","bids":[],"asks":[{"price":461.51,"qty":0.00000000},{"price":462.16,"qty":0.04431792}],"checksum":322699111,"timestamp":"2024-06-01T17:51:25.209918Z"}]}
{"channel":"book","type":"update","data":[{"symbol":"BCH/USDT","bids":[{"price":461.05,"qty":3.00000000}],"asks":[],"checksum":3118793514,"timestamp":"2024-06-01T17:51:25.209960Z"}]}
{"channel":"book","type":"update","data":[{"symbol":"BCH/USDT","bids":[{"price":461.05,"qty":10.83392088}],"asks":[],"checksum":1084196821,"timestamp":"2024-06-01T17:51:25.213921Z"}]}
{"channel":"book","type":"update","data":[{"symbol":"BCH/USDT","bids":[{"price":461.03,"qty":0.00000000},{"price":460.03,"qty":2.50000000}],"asks":[],"checksum":3039614340,"timestamp":"2024-06-01T17:51:25.214806Z"}]}
{"channel":"book","type":"update","data":[{"symbol":"BCH/USDT","bids":[],"asks":[{"price":461.48,"qty":3.80879832}],"checksum":3549737257,"timestamp":"2024-06-01T17:51:25.215219Z"}]}
{"channel":"book","type":"update","data":[{"symbol":"BCH/USDT","bids":[{"price":461.06,"qty":0.90000000}],"asks":[],"checksum":686074105,"timestamp":"2024-06-01T17:51:25.215353Z"}]}
{"channel":"book","type":"update","data":[{"symbol":"BCH/USDT","bids":[{"price":461.04,"qty":0.90000000}],"asks":[],"checksum":1847572296,"timestamp":"2024-06-01T17:51:25.215393Z"}]}
{"channel":"book","type":"update","data":[{"symbol":"BCH/USDT","bids":[{"price":461.05,"qty":14.64271920}],"asks":[],"checksum":4275457303,"timestamp":"2024-06-01T17:51:25.215495Z"}]}
{"channel":"book","type":"update","data":[{"symbol":"BCH/USDT","bids":[],"asks":[{"price":461.48,"qty":4.70879832}],"checksum":1585811175,"timestamp":"2024-06-01T17:51:25.215538Z"}]}
{"channel":"book","type":"update","data":[{"symbol":"BCH/USDT","bids":[{"price":461.02,"qty":0.00000000},{"price":460.03,"qty":2.50000000}],"asks":[],"checksum":3843851305,"timestamp":"2024-06-01T17:51:25.218164Z"}]}
{"channel":"book","type":"update","data":[{"symbol":"BCH/USDT","bids":[],"asks":[{"price":461.50,"qty":0.90000000}],"checksum":2740687215,"timestamp":"2024-06-01T17:51:25.451638Z"}]}
{"channel":"book","type":"update","data":[{"symbol":"BCH/USDT","bids":[{"price":461.05,"qty":10.83392088}],"asks":[],"checksum":865233712,"timestamp":"2024-06-01T17:51:25.451654Z"}]}
{"channel":"book","type":"update","data":[{"symbol":"BCH/USDT","bids":[{"price":461.01,"qty":3.80879832}],"asks":[],"checksum":3395178689,"timestamp":"2024-06-01T17:51:25.456154Z"}]}
{"channel":"book","type":"update","data":[{"symbol":"BCH/USDT","bids":[],"asks":[{"price":461.47,"qty":3.00000000}],"checksum":2510774584,"timestamp":"2024-06-01T17:51:25.456458Z"}]}
{"channel":"book","type":"update","data":[{"symbol":"BCH/USDT","bids":[],"asks":[{"price":461.50,"qty":0.00000000},{"price":461.85,"qty":0.29976596}],"checksum":3160455225,"timestamp":"2024-06-01T17:51:25.457079Z"}]}
{"channel":"book","type":"update","data":[{"symbol":"BCH/USDT","bids":[{"price":461.04,"qty":0.00000000},{"price":459.94,"qty":1.36603240}],"asks":[],"checksum":187452684,"timestamp":"2024-06-01T17:51:25.457159Z"}]}
{"channel":"book","type":"update","data":[{"symbol":"BCH/USDT","bids":[{"price":461.06,"qty":8.73392088}],"asks":[],"checksum":2617070230,"timestamp":"2024-06-01T17:51:25.513007Z"}]}
{"channel":"book","type":"update","data":[{"symbol":"BCH/USDT","bids":[],"asks":[{"price":461.49,"qty":0.00000000},{"price":462.16,"qty":0.04431792}],"checksum":3527594036,"timestamp":"2024-06-01T17:51:25.517901Z"}]}
{"channel":"book","type":"update","data":[{"symbol":"BCH/USDT","bids":[],"asks":[{"price":461.46,"qty":3.80879832}],"checksum":3415599374,"timestamp":"2024-06-01T17:51:25.517940Z"}]}
{"channel":"book","type":"update","data":[{"symbol":"BCH/USDT","bids":[],"asks":[{"price":461.46,"qty":4.70879832}],"checksum":1988643025,"timestamp":"2024-06-01T17:51:25.517952Z"}]}
{"channel":"book","type":"update","data":[{"symbol":"BCH/USDT","bids":[],"asks":[{"price":461.48,"qty":3.80879832}],"checksum":2952694891,"timestamp":"2024-06-01T17:51:25.586692Z"}]}
{"channel":"book","type":"update","data":[{"symbol":"BCH/USDT","bids":[{"price":461.05,"qty":3.00000000}],"asks":[],"checksum":1789158534,"timestamp":"2024-06-01T17:51:25.591802Z"}]}
{"channel":"book","type":"update","data":[{"symbol":"BCH/USDT","bids":[],"asks":[{"price":461.48,"qty":0.00000000},{"price":462.16,"qty":0.04431792}],"checksum":1660613498,"timestamp":"2024-06-01T17:51:25.592005Z"}]}
{"channel":"book","type":"update","data":[{"symbol":"BCH/USDT","bids":[],"asks":[{"price":461.45,"qty":3.00000000}],"checksum":2360367509,"timestamp":"2024-06-01T17:51:25.593357Z"}]}
{"channel":"book","type":"update","data":[{"symbol":"BCH/USDT","bids":[],"asks":[{"price":461.47,"qty":0.00000000},{"price":462.16,"qty":0.04431792}],"checksum":821114405,"timestamp":"2024-06-01T17:51:25.708547Z"}]}
{"channel":"book","type":"update","data":[{"symbol":"BCH/USDT","bids":[],"asks":[{"price":461.44,"qty":0.90000000}],"checksum":3844150299,"timestamp":"2024-06-01T17:51:25.714956Z"}]}
{"channel":"book","type":"update","data":[{"symbol":"BCH/USDT","bids":[],"asks":[{"price":461.54,"qty":0.00000000},{"price":462.16,"qty":0.04431792}],"checksum":1504051510,"timestamp":"2024-06-01T17:51:26.014977Z"}]}
{"channel":"book","type":"update","data":[{"symbol":"BCH/USDT","bids":[],"asks":[{"price":461.46,"qty":3.80879832}],"checksum":3104597439,"timestamp":"2024-06-01T17:51:26.019513Z"}]}
{"channel":"book","type":"update","data":[{"symbol":"BCH/USDT","bids":[],"asks":[{"price":461.44,"qty":8.73392088}],"checksum":3361636950,"timestamp":"2024-06-01T17:51:27.514016Z"}]}
{"channel":"book","type":"update","data":[{"symbol":"BCH/USDT","bids":[],"asks":[{"price":461.44,"qty":0.90000000}],"checksum":3104597439,"timestamp":"2024-06-01T17:51:28.014005Z"}]}
{"channel":"book","type":"update","data":[{"symbol":"BCH/USDT","bids":[],"asks":[{"price":461.49,"qty":7.83392088}],"checksum":4138230394,"timestamp":"2024-06-01T17:51:28.056496Z"}]}
{"channel":"book","type":"update","data":[{"symbol":"BCH/USDT","bids":[],"asks":[{"price":461.60,"qty":0.00000000},{"price":462.16,"qty":0.04431792}],"checksum":444512696,"timestamp":"2024-06-01T17:51:40.909777Z"}]}
{"channel":"book","type":"update","data":[{"symbol":"BCH/USDT","bids":[{"price":461.00,"qty":0.00000000},{"price":459.93,"qty":1.22000000}],"asks":[],"checksum":2010659867,"timestamp":"2024-06-01T17:51:40.909837Z"}]}
{"channel":"book","type":"update","data":[{"symbol":"BCH/USDT","bids":[],"asks":[{"price":461.49,"qty":0.00000000},{"price":462.17,"qty":0.08972479}],"checksum":1023971175,"timestamp":"2024-06-01T17:51:40.913294Z"}]}
{"channel":"book","type":"update","data":[{"symbol":"BCH/USDT","bids":[],"asks":[{"price":461.50,"qty":1.52197891}],"checksum":3129465874,"timestamp":"2024-06-01T17:51:40.914484Z"}]}
{"channel":"book","type":"update","data":[{"symbol":"BCH/USDT","bids":[{"price":461.00,"qty":1.90533877}],"asks":[],"checksum":2341224597,"timestamp":"2024-06-01T17:51:40.914526Z"}]}
{"channel":"book","type":"update","data":[{"symbol":"BCH/USDT","bids":[{"price":461.07,"qty":1.11880872}],"asks":[],"checksum":2568517307,"timestamp":"2024-06-01T17:51:42.388194Z"}]}
{"channel":"book","type":"update","data":[{"symbol":"BCH/USDT","bids":[],"asks":[{"price":461.44,"qty":8.73392088}],"checksum":1086291584,"timestamp":"2024-06-01T17:51:42.392275Z"}]}
{"channel":"book","type":"update","data":[{"symbol":"BCH/USDT","bids":[{"price":461.08,"qty":7.83392088}],"asks":[],"checksum":2918470680,"timestamp":"2024-06-01T17:51:42.392384Z"}]}
{"channel":"book","type":"update","data":[{"symbol":"BCH/USDT","bids":[{"price":461.08,"qty":8.73392088}],"asks":[],"checksum":611113383,"timestamp":"2024-06-01T17:51:42.393756Z"}]}
{"channel":"book","type":"update","data":[{"symbol":"BCH/USDT","bids":[{"price":461.06,"qty":0.90000000}],"asks":[],"checksum":562517069,"timestamp":"2024-06-01T17:51:42.513780Z"}]}
{"channel":"book","type":"update","data":[{"symbol":"BCH/USDT","bids":[{"price":461.06,"qty":0.00000000},{"price":460.03,"qty":2.50000000}],"asks":[],"checksum":372523800,"timestamp":"2024-06-01T17:51:42.521220Z"}]}
{"channel":"book","type":"update","data":[{"symbol":"BCH/USDT","bids":[{"price":461.07,"qty":0.00000000},{"price":459.94,"qty":1.36603240}],"asks":[],"checksum":3421419405,"timestamp":"2024-06-01T17:51:42.593949Z"}]}
{"channel":"book","type":"update","data":[{"symbol":"BCH/USDT","bids":[{"price":461.08,"qty":0.90000000}],"asks":[],"checksum":198680261,"timestamp":"2024-06-01T17:51:43.014045Z"}]}
{"channel":"book","type":"update","data":[{"symbol":"BCH/USDT","bids":[{"price":461.06,"qty":7.83392088}],"asks":[],"checksum":2851367153,"timestamp":"2024-06-01T17:51:43.014076Z"}]}
{"channel":"book","type":"update","data":[{"symbol":"BCH/USDT","bids":[{"price":461.08,"qty":0.00000000},{"price":459.94,"qty":1.36603240}],"asks":[],"checksum":3685991697,"timestamp":"2024-06-01T17:51:43.019355Z"}]}
{"channel":"book","type":"update","data":[{"symbol":"BCH/USDT","bids":[{"price":461.07,"qty":0.90000000}],"asks":[],"checksum":2672297700,"timestamp":"2024-06-01T17:51:43.019411Z"}]}
{"channel":"book","type":"update","data":[{"symbol":"BCH/USDT","bids":[{"price":461.07,"qty":2.06450106}],"asks":[],"checksum":1432792523,"timestamp":"2024-06-01T17:51:43.165131Z"}]}
{"channel":"book","type":"update","data":[{"symbol":"BCH/USDT","bids":[{"price":461.08,"qty":7.83392088}],"asks":[],"checksum":1571830347,"timestamp":"2024-06-01T17:51:43.168757Z"}]}
{"channel":"book","type":"update","data":[{"symbol":"BCH/USDT","bids":[{"price":461.06,"qty":0.00000000},{"price":460.03,"qty":2.50000000}],"asks":[],"checksum":3813574839,"timestamp":"2024-06-01T17:51:43.511239Z"}]}
{"channel":"book","type":"update","data":[{"symbol":"BCH/USDT","bids":[{"price":461.09,"qty":0.90000000}],"asks":[],"checksum":3106356326,"timestamp":"2024-06-01T17:51:43.516139Z"}]}
{"channel":"book","type":"update","data":[{"symbol":"BCH/USDT","bids":[{"price":461.07,"qty":0.90000000}],"asks":[],"checksum":3743847493,"timestamp":"2024-06-01T17:51:43.520356Z"}]}
{"channel":"book","type":"update","data":[{"symbol":"BCH/USDT","bids":[{"price":461.07,"qty":0.00000000},{"price":460.03,"qty":2.50000000}],"asks":[],"checksum":1577607376,"timestamp":"2024-06-01T17:51:43.588760Z"}]}
{"channel":"book","type":"update","data":[{"symbol":"BCH/USDT","bids":[{"price":461.06,"qty":7.83392088}],"asks":[],"checksum":3774272044,"timestamp":"2024-06-01T17:51:43.593207Z"}]}
{"channel":"book","type":"update","data":[{"symbol":"BCH/USDT","bids":[{"price":461.08,"qty":0.00000000},{"price":460.03,"qty":2.50000000}],"asks":[],"checksum":1407623143,"timestamp":"2024-06-01T17:51:43.593248Z"}]}
{"channel":"book","type":"update","data":[{"symbol":"BCH/USDT","bids":[{"price":460.51,"qty":6.50102093}],"asks":[],"checksum":3637873836,"timestamp":"2024-06-01T17:51:43.701779Z"}]}
{"channel":"book","type":"update","data":[{"symbol":"BCH/USDT","bids":[{"price":460.52,"qty":0.00000000},{"price":460.03,"qty":2.50000000}],"asks":[],"checksum":256182209,"timestamp":"2024-06-01T17:51:43.702028Z"}]}
{"channel":"book","type":"update","data":[{"symbol":"BCH/USDT","bids":[],"asks":[{"price":461.46,"qty":0.00000000},{"price":462.17,"qty":0.08972479}],"checksum":1882759463,"timestamp":"2024-06-01T17:51:43.816684Z"}]}
{"channel":"book","type":"update","data":[{"symbol":"BCH/USDT","bids":[],"asks":[{"price":461.45,"qty":0.00000000},{"price":462.18,"qty":0.06585657}],"checksum":219537198,"timestamp":"2024-06-01T17:51:43.816753Z"}]}
{"channel":"book","type":"update","data":[{"symbol":"BCH/USDT","bids":[],"asks":[{"price":461.44,"qty":7.83392088}],"checksum":1347711442,"timestamp":"2024-06-01T17:51:43.816777Z"}]}
{"channel":"book","type":"update","data":[{"symbol":"BCH/USDT","bids":[],"asks":[{"price":461.50,"qty":0.00000000},{"price":462.20,"qty":1.17906000}],"checksum":628574029,"timestamp":"2024-06-01T17:51:43.820075Z"}]}
{"channel":"book","type":"update","data":[{"symbol":"BCH/USDT","bids":[],"asks":[{"price":461.60,"qty":3.45747891}],"checksum":3904948569,"timestamp":"2024-06-01T17:51:43.824951Z"}]}
{"channel":"book","type":"update","data":[{"symbol":"BCH/USDT","bids":[{"price":461.06,"qty":8.98316807}],"asks":[],"checksum":1610688970,"timestamp":"2024-06-01T17:51:43.898765Z"}]}
{"channel":"book","type":"update","data":[{"symbol":"BCH/USDT","bids":[{"price":461.07,"qty":3.00000000}],"asks":[],"checksum":696248074,"timestamp":"2024-06-01T17:51:43.903493Z"}]}
{"channel":"book","type":"update","data":[{"symbol":"BCH/USDT","bids":[{"price":461.10,"qty":3.80879832}],"asks":[],"checksum":1140164964,"timestamp":"2024-06-01T17:51:43.904964Z"}]}
{"channel":"book","type":"update","data":[{"symbol":"BCH/USDT","bids":[{"price":461.06,"qty":7.83392088}],"asks":[],"checksum":1125930124,"timestamp":"2024-06-01T17:51:43.907153Z"}]}
{"channel":"book","type":"update","data":[{"symbol":"BCH/USDT","bids":[],"asks":[{"price":461.44,"qty":0.00000000},{"price":462.20,"qty":1.17906000}],"checksum":2533900508,"timestamp":"2024-06-01T17:51:43.912432Z"}]}
{"channel":"book","type":"update","data":[{"symbol":"BCH/USDT","bids":[{"price":461.11,"qty":7.83392088}],"asks":[],"checksum":735388334,"timestamp":"2024-06-01T17:51:43.912575Z"}]}
{"channel":"book","type":"update","data":[{"symbol":"BCH/USDT","bids":[],"asks":[{"price":461.56,"qty":3.80879832}],"checksum":1491728579,"timestamp":"2024-06-01T17:51:43.952798Z"}]}
{"channel":"book","type":"update","data":[{"symbol":"BCH/USDT","bids":[{"price":461.01,"qty":0.00000000},{"price":460.43,"qty":0.76032560}],"asks":[],"checksum":2382196465,"timestamp":"2024-06-01T17:51:43.952872Z"}]}
{"channel":"book","type":"update","data":[{"symbol":"BCH/USDT","bids":[{"price":461.12,"qty":3.80879832}],"asks":[],"checksum":4275658863,"timestamp":"2024-06-01T17:51:43.952984Z"}]}
{"channel":"book","type":"update","data":[{"symbol":"BCH/USDT","bids":[{"price":461.06,"qty":0.00000000},{"price":460.43,"qty":0.76032560}],"asks":[],"checksum":3070964283,"timestamp":"2024-06-01T17:51:43.956727Z"}]}
{"channel":"book","type":"update","data":[{"symbol":"BCH/USDT","bids":[{"price":461.10,"qty":0.00000000},{"price":460.23,"qty":1.16000000}],"asks":[],"checksum":1786702527,"timestamp":"2024-06-01T17:51:43.958498Z"}]}
{"channel":"book","type":"update","data":[{"symbol":"BCH/USDT","bids":[],"asks":[{"price":461.55,"qty":0.90000000}],"checksum":3032860621,"timestamp":"2024-06-01T17:51:43.958682Z"}]}
{"channel":"book","type":"update","data":[{"symbol":"BCH/USDT","bids":[{"price":461.12,"qty":4.70879832}],"asks":[],"checksum":288370852,"timestamp":"2024-06-01T17:51:43.958721Z"}]}
{"channel":"book","type":"update","data":[{"symbol":"BCH/USDT","bids":[{"price":461.05,"qty":0.00000000},{"price":460.03,"qty":2.50000000}],"asks":[],"checksum":1901612227,"timestamp":"2024-06-01T17:51:43.958836Z"}]}
{"channel":"book","type":"update","data":[{"symbol":"BCH/USDT","bids":[{"price":461.12,"qty":7.70879832}],"asks":[],"checksum":1460065249,"timestamp":"2024-06-01T17:51:43.958973Z"}]}
{"channel":"book","type":"update","data":[{"symbol":"BCH/USDT","bids":[],"asks":[{"price":461.55,"qty":3.90000000}],"checksum":2669151714,"timestamp":"2024-06-01T17:51:43.959032Z"}]}
{"channel":"book","type":"update","data":[{"symbol":"BCH/USDT","bids":[{"price":461.13,"qty":7.83392088}],"asks":[],"checksum":46938285,"timestamp":"2024-06-01T17:51:44.023707Z"}]}
{"channel":"book","type":"update","data":[{"symbol":"BCH/USDT","bids":[{"price":461.07,"qty":0.00000000},{"price":460.03,"qty":2.50000000}],"asks":[],"checksum":4116097640,"timestamp":"2024-06-01T17:51:44.029243Z"}]}
{"channel":"book","type":"update","data":[{"symbol":"BCH/USDT","bids":[{"price":461.14,"qty":3.00000000}],"asks":[],"checksum":941924863,"timestamp":"2024-06-01T17:51:44.029260Z"}]}
{"channel":"book","type":"update","data":[{"symbol":"BCH/USDT","bids":[{"price":461.12,"qty":6.80879832}],"asks":[],"checksum":2757608465,"timestamp":"2024-06-01T17:51:44.029408Z"}]}
{"channel":"book","type":"update","data":[{"symbol":"BCH/USDT","bids":[{"price":461.14,"qty":3.90000000}],"asks":[],"checksum":2230411779,"timestamp":"2024-06-01T17:51:44.029444Z"}]}
{"channel":"book","type":"update","data":[{"symbol":"BCH/USDT","bids":[{"price":461.14,"qty":7.70879832}],"asks":[],"checksum":816195482,"timestamp":"2024-06-01T17:51:44.029845Z"}]}
{"channel":"book","type":"update","data":[{"symbol":"BCH/USDT","bids":[{"price":461.11,"qty":0.00000000},{"price":460.03,"qty":2.50000000}],"asks":[],"checksum":2882500134,"timestamp":"2024-06-01T17:51:44.030564Z"}]}
{"channel":"book","type":"update","data":[{"symbol":"BCH/USDT","bids":[{"price":461.09,"qty":0.00000000},{"price":459.94,"qty":1.36603240}],"asks":[],"checksum":871709868,"timestamp":"2024-06-01T17:51:44.088222Z"}]}
{"channel":"book","type":"update","data":[{"symbol":"BCH/USDT","bids":[{"price":461.12,"qty":3.80879832}],"asks":[],"checksum":1524725758,"timestamp":"2024-06-01T17:51:44.092964Z"}]}
{"channel":"book","type":"update","data":[{"symbol":"BCH/USDT","bids":[{"price":461.12,"qty":0.00000000},{"price":459.93,"qty":1.22000000}],"asks":[],"checksum":4216693293,"timestamp":"2024-06-01T17:51:44.093098Z"}]}
{"channel":"book","type":"update","data":[{"symbol":"BCH/USDT","bids":[],"asks":[{"price":461.54,"qty":7.83392088}],"checksum":2879009490,"timestamp":"2024-06-01T17:51:45.511948Z"}]}
{"channel":"book","type":"update","data":[{"symbol":"BCH/USDT","bids":[],"asks":[{"price":461.53,"qty":0.90000000}],"checksum":430975905,"timestamp":"2024-06-01T17:51:45.517090Z"}]}
{"channel":"book","type":"update","data":[{"symbol":"BCH/USDT","bids":[],"asks":[{"price":461.55,"qty":3.00000000}],"checksum":611022342,"timestamp":"2024-06-01T17:51:45.586647Z"}]}
{"channel":"book","type":"update","data":[{"symbol":"BCH/USDT","bids":[{"price":461.15,"qty":1.21058645}],"asks":[],"checksum":3200235266,"timestamp":"2024-06-01T17:51:49.672783Z"}]}
{"channel":"book","type":"update","data":[{"symbol":"BCH/USDT","bids":[{"price":461.16,"qty":7.83392088}],"asks":[],"checksum":3701335778,"timestamp":"2024-06-01T17:51:49.697908Z"}]}
{"channel":"book","type":"update","data":[{"symbol":"BCH/USDT","bids":[{"price":461.15,"qty":0.00000000},{"price":459.94,"qty":1.36603240}],"asks":[],"checksum":1678261367,"timestamp":"2024-06-01T17:51:49.704083Z"}]}
{"channel":"book","type":"update","data":[{"symbol":"BCH/USDT","bids":[{"price":461.17,"qty":1.25515114}],"asks":[],"checksum":2841480237,"timestamp":"2024-06-01T17:51:49.704097Z"}]}
{"channel":"book","type":"update","data":[{"symbol":"BCH/USDT","bids":[{"price":461.16,"qty":8.73392088}],"asks":[],"checksum":2546495551,"timestamp":"2024-06-01T17:51:49.704914Z"}]}
{"channel":"book","type":"update","data":[{"symbol":"BCH/USDT","bids":[{"price":461.16,"qty":7.83392088}],"asks":[],"checksum":2841480237,"timestamp":"2024-06-01T17:51:49.733478Z"}]}
{"channel":"book","type":"update","data":[{"symbol":"BCH/USDT","bids":[{"price":461.18,"qty":0.90000000}],"asks":[],"checksum":4053887936,"timestamp":"2024-06-01T17:51:49.733617Z"}]}
{"channel":"book","type":"update","data":[{"symbol":"BCH/USDT","bids":[{"price":461.17,"qty":0.00000000},{"price":460.03,"qty":2.50000000}],"asks":[],"checksum":2235257065,"timestamp":"2024-06-01T17:51:49.738322Z"}]}
{"channel":"book","type":"update","data":[{"symbol":"BCH/USDT","bids":[{"price":461.19,"qty":1.21504711}],"asks":[],"checksum":2431785094,"timestamp":"2024-06-01T17:51:49.738403Z"}]}
{"channel":"book","type":"update","data":[{"symbol":"BCH/USDT","bids":[{"price":461.16,"qty":0.00000000},{"price":460.03,"qty":2.50000000}],"asks":[],"checksum":3852580680,"timestamp":"2024-06-01T17:51:49.742565Z"}]}
{"channel":"book","type":"update","data":[{"symbol":"BCH/USDT","bids":[{"price":461.18,"qty":0.00000000},{"price":459.94,"qty":1.36603240}],"asks":[],"checksum":2148897063,"timestamp":"2024-06-01T17:51:49.768447Z"}]}
{"channel":"book","type":"update","data":[{"symbol":"BCH/USDT","bids":[{"price":461.20,"qty":0.90000000}],"asks":[],"checksum":1365442873,"timestamp":"2024-06-01T17:51:49.768753Z"}]}
{"channel":"book","type":"update","data":[{"symbol":"BCH/USDT","bids":[{"price":461.19,"qty":0.00000000},{"price":459.94,"qty":1.36603240}],"asks":[],"checksum":2148250045,"timestamp":"2024-06-01T17:51:49.773287Z"}]}
{"channel":"book","type":"update","data":[{"symbol":"BCH/USDT","bids":[{"price":461.21,"qty":1.16120928}],"asks":[],"checksum":2586034484,"timestamp":"2024-06-01T17:51:49.773478Z"}]}
{"channel":"book","type":"update","data":[{"symbol":"BCH/USDT","bids":[{"price":461.15,"qty":7.83392088}],"asks":[],"checksum":626749620,"timestamp":"2024-06-01T17:51:49.777515Z"}]}
{"channel":"book","type":"update","data":[{"symbol":"BCH/USDT","bids":[{"price":461.20,"qty":0.00000000},{"price":460.03,"qty":2.50000000}],"asks":[],"checksum":638104211,"timestamp":"2024-06-01T17:51:49.798465Z"}]}
{"channel":"book","type":"update","data":[{"symbol":"BCH/USDT","bids":[{"price":461.22,"qty":0.90000000}],"asks":[],"checksum":1894347571,"timestamp":"2024-06-01T17:51:49.798587Z"}]}
{"channel":"book","type":"update","data":[{"symbol":"BCH/USDT","bids":[{"price":461.21,"qty":0.00000000},{"price":460.03,"qty":2.50000000}],"asks":[],"checksum":1046017154,"timestamp":"2024-06-01T17:51:49.921385Z"}]}
{"channel":"book","type":"update","data":[{"symbol":"BCH/USDT","bids":[{"price":461.16,"qty":1.39191831}],"asks":[],"checksum":499516595,"timestamp":"2024-06-01T17:51:49.921515Z"}]}
{"channel":"book","type":"update","data":[{"symbol":"BCH/USDT","bids":[{"price":461.13,"qty":0.00000000},{"price":460.03,"qty":2.50000000}],"asks":[],"checksum":682528836,"timestamp":"2024-06-01T17:51:49.925113Z"}]}
{"channel":"book","type":"update","data":[{"symbol":"BCH/USDT","bids":[{"price":461.14,"qty":6.80879832}],"asks":[],"checksum":2698504421,"timestamp":"2024-06-01T17:51:49.926374Z"}]}
{"channel":"book","type":"update","data":[{"symbol":"BCH/USDT","bids":[{"price":461.17,"qty":7.83392088}],"asks":[],"checksum":256453006,"timestamp":"2024-06-01T17:51:50.013257Z"}]}
{"channel":"book","type":"update","data":[{"symbol":"BCH/USDT","bids":[{"price":461.16,"qty":0.00000000},{"price":460.03,"qty":2.50000000}],"asks":[],"checksum":1051022981,"timestamp":"2024-06-01T17:51:50.017404Z"}]}
{"channel":"book","type":"update","data":[{"symbol":"BCH/USDT","bids":[{"price":461.18,"qty":1.45518269}],"asks":[],"checksum":564390557,"timestamp":"2024-06-01T17:51:50.017669Z"}]}
{"channel":"book","type":"update","data":[{"symbol":"BCH/USDT","bids":[{"price":461.17,"qty":0.00000000},{"price":460.03,"qty":2.50000000}],"asks":[],"checksum":3792685596,"timestamp":"2024-06-01T17:51:50.512650Z"}]}
{"channel":"book","type":"update","data":[{"symbol":"BCH/USDT","bids":[{"price":461.22,"qty":0.00000000},{"price":459.94,"qty":1.36603240}],"asks":[],"checksum":1030323378,"timestamp":"2024-06-01T17:51:50.517784Z"}]}
{"channel":"book","type":"update","data":[{"symbol":"BCH/USDT","bids":[{"price":461.19,"qty":0.90000000}],"asks":[],"checksum":1293458040,"timestamp":"2024-06-01T17:51:50.517874Z"}]}
{"channel":"book","type":"update","data":[{"symbol":"BCH/USDT","bids":[{"price":461.18,"qty":0.00000000},{"price":459.94,"qty":1.36603240}],"asks":[],"checksum":4291026474,"timestamp":"2024-06-01T17:51:51.098413Z"}]}
{"channel":"book","type":"update","data":[{"symbol":"BCH/USDT","bids":[{"price":461.16,"qty":1.53125345}],"asks":[],"checksum":3903273877,"timestamp":"2024-06-01T17:51:51.098674Z"}]}
{"channel":"book","type":"update","data":[{"symbol":"BCH/USDT","bids":[{"price":461.17,"qty":0.90000000}],"asks":[],"checksum":2558496383,"timestamp":"2024-06-01T17:51:51.104036Z"}]}
{"channel":"book","type":"update","data":[{"symbol":"BCH/USDT","bids":[{"price":461.19,"qty":0.00000000},{"price":460.03,"qty":2.50000000}],"asks":[],"checksum":604611222,"timestamp":"2024-06-01T17:51:51.104086Z"}]}
{"channel":"book","type":"update","data":[{"symbol":"BCH/USDT","bids":[{"price":461.16,"qty":0.00000000},{"price":459.94,"qty":1.36603240}],"asks":[],"checksum":862799657,"timestamp":"2024-06-01T17:51:51.108217Z"}]}
{"channel":"book","type":"update","data":[{"symbol":"BCH/USDT","bids":[{"price":461.18,"qty":1.53125345}],"asks":[],"checksum":4122730351,"timestamp":"2024-06-01T17:51:51.108413Z"}]}
{"channel":"book","type":"update","data":[{"symbol":"BCH/USDT","bids":[{"price":461.19,"qty":0.90000000}],"asks":[],"checksum":1504218322,"timestamp":"2024-06-01T17:51:51.589986Z"}]}
{"channel":"book","type":"update","data":[{"symbol":"BCH/USDT","bids":[{"price":461.17,"qty":0.00000000},{"price":460.03,"qty":2.50000000}],"asks":[],"checksum":3846816930,"timestamp":"2024-06-01T17:51:51.594501Z"}]}
{"channel":"book","type":"update","data":[{"symbol":"BCH/USDT","bids":[{"price":461.18,"qty":0.00000000},{"price":459.94,"qty":1.36603240}],"asks":[],"checksum":4291026474,"timestamp":"2024-06-01T17:51:52.288002Z"}]}
{"channel":"book","type":"update","data":[{"symbol":"BCH/USDT","bids":[{"price":461.16,"qty":1.54880382}],"asks":[],"checksum":2816581912,"timestamp":"2024-06-01T17:51:52.288163Z"}]}
{"channel":"book","type":"update","data":[{"symbol":"BCH/USDT","bids":[{"price":461.17,"qty":0.90000000}],"asks":[],"checksum":1110709857,"timestamp":"2024-06-01T17:51:52.293478Z"}]}
{"channel":"book","type":"update","data":[{"symbol":"BCH/USDT","bids":[{"price":461.19,"qty":0.00000000},{"price":460.03,"qty":2.50000000}],"asks":[],"checksum":1800353819,"timestamp":"2024-06-01T17:51:52.293497Z"}]}
{"channel":"book","type":"update","data":[{"symbol":"BCH/USDT","bids":[{"price":461.16,"qty":0.00000000},{"price":459.94,"qty":1.36603240}],"asks":[],"checksum":862799657,"timestamp":"2024-06-01T17:51:52.298485Z"}]}
{"channel":"book","type":"update","data":[{"symbol":"BCH/USDT","bids":[{"price":461.18,"qty":1.54665620}],"asks":[],"checksum":1418096814,"timestamp":"2024-06-01T17:51:52.298570Z"}]}
{"channel":"book","type":"update","data":[{"symbol":"BCH/USDT","bids":[{"price":461.19,"qty":0.90000000}],"asks":[],"checksum":1942119140,"timestamp":"2024-06-01T17:51:52.587893Z"}]}
{"channel":"book","type":"update","data":[{"symbol":"BCH/USDT","bids":[{"price":461.17,"qty":0.00000000},{"price":460.03,"qty":2.50000000}],"asks":[],"checksum":718879701,"timestamp":"2024-06-01T17:51:52.592717Z"}]}
{"channel":"book","type":"update","data":[{"symbol":"BCH/USDT","bids":[{"price":461.18,"qty":0.00000000},{"price":459.94,"qty":1.36603240}],"asks":[],"checksum":4291026474,"timestamp":"2024-06-01T17:51:53.301768Z"}]}
{"channel":"book","type":"update","data":[{"symbol":"BCH/USDT","bids":[{"price":461.16,"qty":1.53615251}],"asks":[],"checksum":460291186,"timestamp":"2024-06-01T17:51:53.301862Z"}]}
{"channel":"book","type":"update","data":[{"symbol":"BCH/USDT","bids":[{"price":461.19,"qty":0.00000000},{"price":459.94,"qty":1.36603240}],"asks":[],"checksum":570161569,"timestamp":"2024-06-01T17:51:53.306916Z"}]}
{"channel":"book","type":"update","data":[{"symbol":"BCH/USDT","bids":[{"price":461.17,"qty":0.90000000}],"asks":[],"checksum":3619808625,"timestamp":"2024-06-01T17:51:53.307041Z"}]}
{"channel":"book","type":"update","data":[{"symbol":"BCH/USDT","bids":[{"price":461.16,"qty":0.00000000},{"price":459.94,"qty":1.36603240}],"asks":[],"checksum":862799657,"timestamp":"2024-06-01T17:51:53.311236Z"}]}
{"channel":"book","type":"update","data":[{"symbol":"BCH/USDT","bids":[{"price":461.18,"qty":1.53661076}],"asks":[],"checksum":1921261937,"timestamp":"2024-06-01T17:51:53.311473Z"}]}
{"channel":"book","type":"update","data":[{"symbol":"BCH/USDT","bids":[{"price":461.19,"qty":0.90000000}],"asks":[],"checksum":2584868426,"timestamp":"2024-06-01T17:51:53.589074Z"}]}
{"channel":"book","type":"update","data":[{"symbol":"BCH/USDT","bids":[{"price":461.17,"qty":0.00000000},{"price":460.03,"qty":2.50000000}],"asks":[],"checksum":459171502,"timestamp":"2024-06-01T17:51:53.593765Z"}]}
{"channel":"book","type":"update","data":[{"symbol":"BCH/USDT","bids":[{"price":461.18,"qty":0.00000000},{"price":459.94,"qty":1.36603240}],"asks":[],"checksum":4291026474,"timestamp":"2024-06-01T17:51:54.042281Z"}]}
{"channel":"book","type":"update","data":[{"symbol":"BCH/USDT","bids":[{"price":461.19,"qty":0.00000000},{"price":459.93,"qty":1.22000000}],"asks":[],"checksum":3586964594,"timestamp":"2024-06-01T17:51:54.589067Z"}]}
{"channel":"book","type":"update","data":[{"symbol":"BCH/USDT","bids":[{"price":461.16,"qty":0.90000000}],"asks":[],"checksum":3380588607,"timestamp":"2024-06-01T17:51:54.589187Z"}]}
{"channel":"book","type":"update","data":[{"symbol":"BCH/USDT","bids":[{"price":461.16,"qty":2.38273932}],"asks":[],"checksum":355130653,"timestamp":"2024-06-01T17:51:56.252647Z"}]}
{"channel":"book","type":"update","data":[{"symbol":"BCH/USDT","bids":[{"price":461.17,"qty":7.83392088}],"asks":[],"checksum":1309177177,"timestamp":"2024-06-01T17:51:56.260710Z"}]}
{"channel":"book","type":"update","data":[{"symbol":"BCH/USDT","bids":[{"price":461.00,"qty":0.00000000},{"price":459.94,"qty":1.36603240}],"asks":[],"checksum":2104532848,"timestamp":"2024-06-01T17:51:56.265015Z"}]}
{"channel":"book","type":"update","data":[{"symbol":"BCH/USDT","bids":[{"price":461.10,"qty":1.72334959}],"asks":[],"checksum":1623791034,"timestamp":"2024-06-01T17:51:56.269898Z"}]}
{"channel":"book","type":"update","data":[{"symbol":"BCH/USDT","bids":[{"price":461.15,"qty":0.00000000},{"price":459.94,"qty":1.36603240}],"asks":[],"checksum":1077607843,"timestamp":"2024-06-01T17:51:56.509509Z"}]}
{"channel":"book","type":"update","data":[{"symbol":"BCH/USDT","bids":[{"price":461.16,"qty":0.90000000}],"asks":[],"checksum":2199897972,"timestamp":"2024-06-01T17:51:56.513905Z"}]}
{"channel":"book","type":"update","data":[{"symbol":"BCH/USDT","bids":[{"price":461.18,"qty":0.90000000}],"asks":[],"checksum":530135030,"timestamp":"2024-06-01T17:51:56.514636Z"}]}
{"channel":"book","type":"update","data":[{"symbol":"BCH/USDT","bids":[{"price":461.16,"qty":0.00000000},{"price":459.94,"qty":1.36603240}],"asks":[],"checksum":1704098061,"timestamp":"2024-06-01T17:51:56.587595Z"}]}
{"channel":"book","type":"update","data":[{"symbol":"BCH/USDT","bids":[{"price":461.17,"qty":0.00000000},{"price":459.93,"qty":1.22000000}],"asks":[],"checksum":2546645130,"timestamp":"2024-06-01T17:51:56.591767Z"}]}
{"channel":"book","type":"update","data":[{"symbol":"BCH/USDT","bids":[{"price":461.15,"qty":7.83392088}],"asks":[],"checksum":1728480988,"timestamp":"2024-06-01T17:51:56.591798Z"}]}
{"channel":"book","type":"update","data":[{"symbol":"BCH/USDT","bids":[{"price":460.52,"qty":1.34526726}],"asks":[],"checksum":3755491833,"timestamp":"2024-06-01T17:51:56.596761Z"}]}
{"channel":"book","type":"update","data":[{"symbol":"BCH/USDT","bids":[{"price":460.52,"qty":0.00000000},{"price":459.94,"qty":1.36603240}],"asks":[],"checksum":1728480988,"timestamp":"2024-06-01T17:51:56.601677Z"}]}
{"channel":"book","type":"update","data":[{"symbol":"BCH/USDT","bids":[{"price":461.16,"qty":0.90000000}],"asks":[],"checksum":1873391228,"timestamp":"2024-06-01T17:51:57.088720Z"}]}
{"channel":"book","type":"update","data":[{"symbol":"BCH/USDT","bids":[{"price":461.18,"qty":0.00000000},{"price":459.94,"qty":1.36603240}],"asks":[],"checksum":2879922143,"timestamp":"2024-06-01T17:51:57.088826Z"}]}
{"channel":"book","type":"update","data":[{"symbol":"BCH/USDT","bids":[{"price":461.17,"qty":7.83392088}],"asks":[],"checksum":2750164845,"timestamp":"2024-06-01T17:51:57.092775Z"}]}
{"channel":"book","type":"update","data":[{"symbol":"BCH/USDT","bids":[{"price":461.17,"qty":0.00000000},{"price":459.94,"qty":1.36603240}],"asks":[],"checksum":2879922143,"timestamp":"2024-06-01T17:51:57.509695Z"}]}
{"channel":"book","type":"update","data":[{"symbol":"BCH/USDT","bids":[{"price":460.60,"qty":1.34034000}],"asks":[],"checksum":1467518670,"timestamp":"2024-06-01T17:51:58.822954Z"}]}
{"channel":"book","type":"update","data":[{"symbol":"BCH/USDT","bids":[{"price":460.50,"qty":0.00000000},{"price":459.94,"qty":1.36603240}],"asks":[],"checksum":1637510908,"timestamp":"2024-06-01T17:51:58.891051Z"}]}
{"channel":"book","type":"update","data":[{"symbol":"BCH/USDT","bids":[{"price":461.17,"qty":1.25828645}],"asks":[],"checksum":3475582535,"timestamp":"2024-06-01T17:51:59.767891Z"}]}
{"channel":"book","type":"update","data":[{"symbol":"BCH/USDT","bids":[],"asks":[{"price":461.60,"qty":0.00000000},{"price":462.16,"qty":0.04431792}],"checksum":2577122702,"timestamp":"2024-06-01T17:51:59.770499Z"}]}
{"channel":"book","type":"update","data":[{"symbol":"BCH/USDT","bids":[{"price":461.18,"qty":7.83392088}],"asks":[],"checksum":1441548352,"timestamp":"2024-06-01T17:51:59.772049Z"}]}
{"channel":"book","type":"update","data":[{"symbol":"BCH/USDT","bids":[],"asks":[{"price":461.60,"qty":0.44972891}],"checksum":1728108255,"timestamp":"2024-06-01T17:51:59.773202Z"}]}
{"channel":"book","type":"update","data":[{"symbol":"BCH/USDT","bids":[{"price":461.18,"qty":8.73392088}],"asks":[],"checksum":749111622,"timestamp":"2024-06-01T17:51:59.773796Z"}]}
{"channel":"book","type":"update","data":[{"symbol":"BCH/USDT","bids":[{"price":461.15,"qty":0.00000000},{"price":460.03,"qty":2.50000000}],"asks":[],"checksum":3903569468,"timestamp":"2024-06-01T17:52:00.010142Z"}]}
{"channel":"book","type":"update","data":[{"symbol":"BCH/USDT","bids":[{"price":461.16,"qty":0.00000000},{"price":459.94,"qty":1.36603240}],"asks":[],"checksum":831661935,"timestamp":"2024-06-01T17:52:00.017054Z"}]}
{"channel":"book","type":"update","data":[{"symbol":"BCH/USDT","bids":[{"price":461.17,"qty":0.00000000},{"price":459.93,"qty":1.22000000}],"asks":[],"checksum":4141516314,"timestamp":"2024-06-01T17:52:00.090341Z"}]}
{"channel":"book","type":"update","data":[{"symbol":"BCH/USDT","bids":[{"price":461.19,"qty":1.42825813}],"asks":[],"checksum":1636752163,"timestamp":"2024-06-01T17:52:00.337559Z"}]}
{"channel":"book","type":"update","data":[{"symbol":"BCH/USDT","bids":[{"price":461.20,"qty":7.83392088}],"asks":[],"checksum":3258303423,"timestamp":"2024-06-01T17:52:00.342631Z"}]}
{"channel":"book","type":"update","data":[{"symbol":"BCH/USDT","bids":[{"price":461.20,"qty":8.73392088}],"asks":[],"checksum":1269648896,"timestamp":"2024-06-01T17:52:00.344598Z"}]}
{"channel":"book","type":"update","data":[{"symbol":"BCH/USDT","bids":[{"price":461.18,"qty":0.90000000}],"asks":[],"checksum":339131709,"timestamp":"2024-06-01T17:52:00.511165Z"}]}
{"channel":"book","type":"update","data":[{"symbol":"BCH/USDT","bids":[{"price":461.18,"qty":0.00000000},{"price":459.94,"qty":1.36603240}],"asks":[],"checksum":1410722612,"timestamp":"2024-06-01T17:52:00.516130Z"}]}
{"channel":"book","type":"update","data":[{"symbol":"BCH/USDT","bids":[{"price":461.19,"qty":0.00000000},{"price":459.93,"qty":1.22000000}],"asks":[],"checksum":2074663584,"timestamp":"2024-06-01T17:52:01.676013Z"}]}
{"channel":"book","type":"update","data":[{"symbol":"BCH/USDT","bids":[{"price":461.15,"qty":1.58441131}],"asks":[],"checksum":2202614297,"timestamp":"2024-06-01T17:52:01.676265Z"}]}
{"channel":"book","type":"update","data":[{"symbol":"BCH/USDT","bids":[{"price":461.20,"qty":0.90000000}],"asks":[],"checksum":475481623,"timestamp":"2024-06-01T17:52:01.680101Z"}]}
{"channel":"book","type":"update","data":[{"symbol":"BCH/USDT","bids":[{"price":461.15,"qty":9.41833219}],"asks":[],"checksum":481809307,"timestamp":"2024-06-01T17:52:01.680300Z"}]}
{"channel":"book","type":"update","data":[{"symbol":"BCH/USDT","bids":[{"price":461.16,"qty":7.83392088}],"asks":[],"checksum":694810069,"timestamp":"2024-06-01T17:52:02.014025Z"}]}
{"channel":"book","type":"update","data":[{"symbol":"BCH/USDT","bids":[{"price":461.15,"qty":7.83392088}],"asks":[],"checksum":370424920,"timestamp":"2024-06-01T17:52:02.018742Z"}]}
{"channel":"book","type":"update","data":[{"symbol":"BCH/USDT","bids":[{"price":461.17,"qty":0.90000000}],"asks":[],"checksum":1606493142,"timestamp":"2024-06-01T17:52:02.019306Z"}]}
{"channel":"book","type":"update","data":[{"symbol":"BCH/USDT","bids":[{"price":461.20,"qty":0.00000000},{"price":460.03,"qty":2.50000000}],"asks":[],"checksum":1526275410,"timestamp":"2024-06-01T17:52:02.019339Z"}]}
{"channel":"book","type":"update","data":[{"symbol":"BCH/USDT","bids":[{"price":461.15,"qty":0.00000000},{"price":459.94,"qty":1.36603240}],"asks":[],"checksum":296808357,"timestamp":"2024-06-01T17:52:02.020801Z"}]}
{"channel":"book","type":"update","data":[{"symbol":"BCH/USDT","bids":[{"price":461.18,"qty":1.56589120}],"asks":[],"checksum":590307232,"timestamp":"2024-06-01T17:52:02.382557Z"}]}
{"channel":"book","type":"update","data":[{"symbol":"BCH/USDT","bids":[{"price":461.19,"qty":7.83392088}],"asks":[],"checksum":2358498715,"timestamp":"2024-06-01T17:52:02.386554Z"}]}
{"channel":"book","type":"update","data":[{"symbol":"BCH/USDT","bids":[{"price":461.19,"qty":8.73392088}],"asks":[],"checksum":3342174722,"timestamp":"2024-06-01T17:52:02.387229Z"}]}
{"channel":"book","type":"update","data":[{"symbol":"BCH/USDT","bids":[{"price":461.18,"qty":0.00000000},{"price":460.03,"qty":2.50000000}],"asks":[],"checksum":3122071523,"timestamp":"2024-06-01T17:52:02.436319Z"}]}
{"channel":"book","type":"update","data":[{"symbol":"BCH/USDT","bids":[{"price":461.20,"qty":1.64707026}],"asks":[],"checksum":606627674,"timestamp":"2024-06-01T17:52:02.436387Z"}]}
{"channel":"book","type":"update","data":[{"symbol":"BCH/USDT","bids":[{"price":461.19,"qty":0.90000000}],"asks":[],"checksum":1854242305,"timestamp":"2024-06-01T17:52:02.440125Z"}]}
{"channel":"book","type":"update","data":[{"symbol":"BCH/USDT","bids":[{"price":461.21,"qty":0.90000000}],"asks":[],"checksum":453920655,"timestamp":"2024-06-01T17:52:02.441963Z"}]}
{"channel":"book","type":"update","data":[{"symbol":"BCH/USDT","bids":[{"price":461.19,"qty":0.00000000},{"price":460.23,"qty":1.16000000}],"asks":[],"checksum":248483693,"timestamp":"2024-06-01T17:52:02.441989Z"}]}
{"channel":"book","type":"update","data":[{"symbol":"BCH/USDT","bids":[{"price":461.17,"qty":0.00000000},{"price":460.03,"qty":2.50000000}],"asks":[],"checksum":4130994884,"timestamp":"2024-06-01T17:52:02.588487Z"}]}
{"channel":"book","type":"update","data":[{"symbol":"BCH/USDT","bids":[],"asks":[{"price":461.60,"qty":0.00000000},{"price":462.16,"qty":0.04431792}],"checksum":3302319195,"timestamp":"2024-06-01T17:52:03.199343Z"}]}
{"channel":"book","type":"update","data":[{"symbol":"BCH/USDT","bids":[],"asks":[{"price":461.55,"qty":0.00000000},{"price":462.17,"qty":0.08972479}],"checksum":1908294115,"timestamp":"2024-06-01T17:52:03.199373Z"}]}
{"channel":"book","type":"update","data":[{"symbol":"BCH/USDT","bids":[],"asks":[{"price":461.56,"qty":0.00000000},{"price":462.18,"qty":0.06585657}],"checksum":3627571518,"timestamp":"2024-06-01T17:52:03.199501Z"}]}
{"channel":"book","type":"update","data":[{"symbol":"BCH/USDT","bids":[],"asks":[{"price":461.53,"qty":0.00000000},{"price":462.30,"qty":1.27971000}],"checksum":3532471089,"timestamp":"2024-06-01T17:52:03.199597Z"}]}
{"channel":"book","type":"update","data":[{"symbol":"BCH/USDT","bids":[],"asks":[{"price":461.57,"qty":0.00000000},{"price":462.45,"qty":4.78432880}],"checksum":102000938,"timestamp":"2024-06-01T17:52:03.200272Z"}]}
{"channel":"book","type":"update","data":[{"symbol":"BCH/USDT","bids":[],"asks":[{"price":461.54,"qty":0.00000000},{"price":462.46,"qty":1.24000000}],"checksum":2757277304,"timestamp":"2024-06-01T17:52:03.200747Z"}]}
{"channel":"book","type":"update","data":[{"symbol":"BCH/USDT","bids":[{"price":460.43,"qty":0.00000000},{"price":459.94,"qty":1.36603240}],"asks":[],"checksum":502237071,"timestamp":"2024-06-01T17:52:03.203817Z"}]}
{"channel":"book","type":"update","data":[{"symbol":"BCH/USDT","bids":[],"asks":[{"price":461.72,"qty":0.76032560}],"checksum":3489369557,"timestamp":"2024-06-01T17:52:03.203963Z"}]}
{"channel":"book","type":"update","data":[{"symbol":"BCH/USDT","bids":[],"asks":[{"price":461.70,"qty":2.88347891}],"checksum":1389991471,"timestamp":"2024-06-01T17:52:03.204838Z"}]}
{"channel":"book","type":"update","data":[{"symbol":"BCH/USDT","bids":[{"price":460.64,"qty":0.76032560}],"asks":[],"checksum":1034325583,"timestamp":"2024-06-01T17:52:03.206391Z"}]}
{"channel":"book","type":"update","data":[{"symbol":"BCH/USDT","bids":[{"price":461.21,"qty":3.90000000}],"asks":[],"checksum":2528383602,"timestamp":"2024-06-01T17:52:03.211589Z"}]}
{"channel":"book","type":"update","data":[{"symbol":"BCH/USDT","bids":[],"asks":[{"price":461.71,"qty":0.10174043}],"checksum":1833934571,"timestamp":"2024-06-01T17:52:03.214206Z"}]}
{"channel":"book","type":"update","data":[{"symbol":"BCH/USDT","bids":[],"asks":[{"price":461.82,"qty":0.00000000},{"price":462.30,"qty":1.27971000}],"checksum":3978161534,"timestamp":"2024-06-01T17:52:03.214379Z"}]}
{"channel":"book","type":"update","data":[{"symbol":"BCH/USDT","bids":[{"price":461.17,"qty":1.39959750}],"asks":[],"checksum":2370534797,"timestamp":"2024-06-01T17:52:03.217425Z"}]}
{"channel":"book","type":"update","data":[{"symbol":"BCH/USDT","bids":[{"price":461.20,"qty":0.00000000},{"price":460.03,"qty":2.50000000}],"asks":[],"checksum":2138073438,"timestamp":"2024-06-01T17:52:03.217852Z"}]}
{"channel":"book","type":"update","data":[{"symbol":"BCH/USDT","bids":[{"price":461.22,"qty":3.80879832}],"asks":[],"checksum":769737724,"timestamp":"2024-06-01T17:52:03.230846Z"}]}
{"channel":"book","type":"update","data":[{"symbol":"BCH/USDT","bids":[{"price":461.23,"qty":7.83392088}],"asks":[],"checksum":118186206,"timestamp":"2024-06-01T17:52:03.234775Z"}]}
{"channel":"book","type":"update","data":[{"symbol":"BCH/USDT","bids":[{"price":461.14,"qty":3.80879832}],"asks":[],"checksum":3648647644,"timestamp":"2024-06-01T17:52:03.235782Z"}]}
{"channel":"book","type":"update","data":[{"symbol":"BCH/USDT","bids":[{"price":461.23,"qty":10.83392088}],"asks":[],"checksum":112405212,"timestamp":"2024-06-01T17:52:03.236006Z"}]}
{"channel":"book","type":"update","data":[{"symbol":"BCH/USDT","bids":[{"price":461.23,"qty":11.73392088}],"asks":[],"checksum":1132805728,"timestamp":"2024-06-01T17:52:03.236238Z"}]}
{"channel":"book","type":"update","data":[{"symbol":"BCH/USDT","bids":[{"price":461.17,"qty":0.00000000},{"price":460.23,"qty":1.16000000}],"asks":[],"checksum":3968190075,"timestamp":"2024-06-01T17:52:03.238980Z"}]}
{"channel":"book","type":"update","data":[{"symbol":"BCH/USDT","bids":[],"asks":[{"price":461.66,"qty":3.80879832}],"checksum":151238863,"timestamp":"2024-06-01T17:52:03.453761Z"}]}
{"channel":"book","type":"update","data":[{"symbol":"BCH/USDT","bids":[{"price":461.14,"qty":0.00000000},{"price":460.06,"qty":2.42000000}],"asks":[],"checksum":1264257455,"timestamp":"2024-06-01T17:52:03.453786Z"}]}
{"channel":"book","type":"update","data":[{"symbol":"BCH/USDT","bids":[{"price":461.24,"qty":3.80879832}],"asks":[],"checksum":1878849437,"timestamp":"2024-06-01T17:52:03.453909Z"}]}
{"channel":"book","type":"update","data":[{"symbol":"BCH/USDT","bids":[{"price":461.16,"qty":0.00000000},{"price":460.06,"qty":2.42000000}],"asks":[],"checksum":738639092,"timestamp":"2024-06-01T17:52:03.457901Z"}]}
{"channel":"book","type":"update","data":[{"symbol":"BCH/USDT","bids":[],"asks":[{"price":461.65,"qty":7.83392088}],"checksum":672782032,"timestamp":"2024-06-01T17:52:03.457997Z"}]}
{"channel":"book","type":"update","data":[{"symbol":"BCH/USDT","bids":[{"price":461.21,"qty":0.90000000}],"asks":[],"checksum":3603217010,"timestamp":"2024-06-01T17:52:03.458698Z"}]}
{"channel":"book","type":"update","data":[{"symbol":"BCH/USDT","bids":[],"asks":[{"price":461.65,"qty":10.83392088}],"checksum":2473901992,"timestamp":"2024-06-01T17:52:03.458841Z"}]}
{"channel":"book","type":"update","data":[{"symbol":"BCH/USDT","bids":[],"asks":[{"price":461.65,"qty":11.73392088}],"checksum":709762704,"timestamp":"2024-06-01T17:52:03.459392Z"}]}
{"channel":"book","type":"update","data":[{"symbol":"BCH/USDT","bids":[{"price":461.21,"qty":0.00000000},{"price":460.03,"qty":2.50000000}],"asks":[],"checksum":3071103815,"timestamp":"2024-06-01T17:52:03.459415Z"}]}
{"channel":"book","type":"update","data":[{"symbol":"BCH/USDT","bids":[{"price":461.22,"qty":0.00000000},{"price":459.94,"qty":1.36603240}],"asks":[],"checksum":2911002850,"timestamp":"2024-06-01T17:52:03.465445Z"}]}
{"channel":"book","type":"update","data":[{"symbol":"BCH/USDT","bids":[{"price":461.25,"qty":7.83392088}],"asks":[],"checksum":2144691166,"timestamp":"2024-06-01T17:52:03.513293Z"}]}
{"channel":"book","type":"update","data":[{"symbol":"BCH/USDT","bids":[{"price":461.26,"qty":0.90000000}],"asks":[],"checksum":738424790,"timestamp":"2024-06-01T17:52:03.518044Z"}]}
{"channel":"book","type":"update","data":[{"symbol":"BCH/USDT","bids":[{"price":461.23,"qty":3.90000000}],"asks":[],"checksum":3370733216,"timestamp":"2024-06-01T17:52:03.518322Z"}]}
{"channel":"book","type":"update","data":[{"symbol":"BCH/USDT","bids":[{"price":461.23,"qty":3.00000000}],"asks":[],"checksum":3167643311,"timestamp":"2024-06-01T17:52:03.589794Z"}]}
{"channel":"book","type":"update","data":[{"symbol":"BCH/USDT","bids":[{"price":460.60,"qty":0.00000000},{"price":460.03,"qty":2.50000000}],"asks":[],"checksum":3802904928,"timestamp":"2024-06-01T17:52:11.670300Z"}]}
{"channel":"book","type":"update","data":[{"symbol":"BCH/USDT","bids":[{"price":460.70,"qty":1.30818000}],"asks":[],"checksum":3705120705,"timestamp":"2024-06-01T17:52:12.731632Z"}]}
{"channel":"book","type":"update","data":[{"symbol":"BCH/USDT","bids":[{"price":461.27,"qty":1.29109440}],"asks":[],"checksum":1337224546,"timestamp":"2024-06-01T17:52:15.448599Z"}]}
{"channel":"book","type":"update","data":[{"symbol":"BCH/USDT","bids":[{"price":461.10,"qty":0.00000000},{"price":460.06,"qty":2.42000000}],"asks":[],"checksum":1547092248,"timestamp":"2024-06-01T17:52:15.452873Z"}]}
{"channel":"book","type":"update","data":[{"symbol":"BCH/USDT","bids":[{"price":461.20,"qty":2.97411041}],"asks":[],"checksum":2050194087,"timestamp":"2024-06-01T17:52:15.455921Z"}]}
{"channel":"book","type":"update","data":[{"symbol":"BCH/USDT","bids":[{"price":461.28,"qty":7.83392088}],"asks":[],"checksum":100726138,"timestamp":"2024-06-01T17:52:15.456857Z"}]}
{"channel":"book","type":"update","data":[{"symbol":"BCH/USDT","bids":[{"price":461.29,"qty":1.34050381}],"asks":[],"checksum":1382768224,"timestamp":"2024-06-01T17:52:15.461626Z"}]}
{"channel":"book","type":"update","data":[{"symbol":"BCH/USDT","bids":[{"price":461.27,"qty":0.00000000},{"price":460.51,"qty":6.50102093}],"asks":[],"checksum":2328203442,"timestamp":"2024-06-01T17:52:15.461673Z"}]}
{"channel":"book","type":"update","data":[{"symbol":"BCH/USDT","bids":[{"price":461.28,"qty":8.73392088}],"asks":[],"checksum":1900960085,"timestamp":"2024-06-01T17:52:15.469321Z"}]}
{"channel":"book","type":"update","data":[{"symbol":"BCH/USDT","bids":[{"price":461.25,"qty":0.00000000},{"price":460.23,"qty":1.16000000}],"asks":[],"checksum":2614900864,"timestamp":"2024-06-01T17:52:15.511775Z"}]}
{"channel":"book","type":"update","data":[{"symbol":"BCH/USDT","bids":[{"price":461.30,"qty":7.83392088}],"asks":[],"checksum":3496614150,"timestamp":"2024-06-01T17:52:15.516358Z"}]}
{"channel":"book","type":"update","data":[{"symbol":"BCH/USDT","bids":[{"price":461.29,"qty":0.00000000},{"price":460.23,"qty":1.16000000}],"asks":[],"checksum":2352957893,"timestamp":"2024-06-01T17:52:15.520593Z"}]}
{"channel":"book","type":"update","data":[{"symbol":"BCH/USDT","bids":[{"price":461.31,"qty":1.53856321}],"asks":[],"checksum":2571468684,"timestamp":"2024-06-01T17:52:15.520674Z"}]}
{"channel":"book","type":"update","data":[{"symbol":"BCH/USDT","bids":[{"price":461.28,"qty":7.83392088}],"asks":[],"checksum":3960590290,"timestamp":"2024-06-01T17:52:15.543515Z"}]}
{"channel":"book","type":"update","data":[{"symbol":"BCH/USDT","bids":[{"price":461.30,"qty":8.73392088}],"asks":[],"checksum":395970101,"timestamp":"2024-06-01T17:52:15.543551Z"}]}
{"channel":"book","type":"update","data":[{"symbol":"BCH/USDT","bids":[{"price":461.30,"qty":0.90000000}],"asks":[],"checksum":2766276468,"timestamp":"2024-06-01T17:52:15.548277Z"}]}
{"channel":"book","type":"update","data":[{"symbol":"BCH/USDT","bids":[{"price":461.32,"qty":0.90000000}],"asks":[],"checksum":133170878,"timestamp":"2024-06-01T17:52:15.588224Z"}]}
{"channel":"book","type":"update","data":[{"symbol":"BCH/USDT","bids":[{"price":461.30,"qty":0.00000000},{"price":460.51,"qty":6.50102093}],"asks":[],"checksum":4135736361,"timestamp":"2024-06-01T17:52:15.588281Z"}]}
{"channel":"book","type":"update","data":[{"symbol":"BCH/USDT","bids":[{"price":461.26,"qty":0.00000000},{"price":460.23,"qty":1.16000000}],"asks":[],"checksum":960566350,"timestamp":"2024-06-01T17:52:15.593274Z"}]}
{"channel":"book","type":"update","data":[{"symbol":"BCH/USDT","bids":[{"price":461.31,"qty":0.00000000},{"price":460.06,"qty":2.42000000}],"asks":[],"checksum":1470602078,"timestamp":"2024-06-01T17:52:17.364117Z"}]}
{"channel":"book","type":"update","data":[{"symbol":"BCH/USDT","bids":[{"price":461.29,"qty":1.50852814}],"asks":[],"checksum":347573229,"timestamp":"2024-06-01T17:52:17.364262Z"}]}
{"channel":"book","type":"update","data":[{"symbol":"BCH/USDT","bids":[{"price":461.30,"qty":7.83392088}],"asks":[],"checksum":1150838990,"timestamp":"2024-06-01T17:52:17.511707Z"}]}
{"channel":"book","type":"update","data":[{"symbol":"BCH/USDT","bids":[{"price":461.28,"qty":0.00000000},{"price":460.23,"qty":1.16000000}],"asks":[],"checksum":2154735404,"timestamp":"2024-06-01T17:52:17.515138Z"}]}
{"channel":"book","type":"update","data":[{"symbol":"BCH/USDT","bids":[{"price":461.29,"qty":0.00000000},{"price":460.06,"qty":2.42000000}],"asks":[],"checksum":3366444132,"timestamp":"2024-06-01T17:52:17.516333Z"}]}
{"channel":"book","type":"update","data":[{"symbol":"BCH/USDT","bids":[{"price":461.31,"qty":1.61161346}],"asks":[],"checksum":662649137,"timestamp":"2024-06-01T17:52:17.516477Z"}]}
{"channel":"book","type":"update","data":[{"symbol":"BCH/USDT","bids":[{"price":461.32,"qty":0.00000000},{"price":460.06,"qty":2.42000000}],"asks":[],"checksum":2432006218,"timestamp":"2024-06-01T17:52:17.517040Z"}]}
{"channel":"book","type":"update","data":[{"symbol":"BCH/USDT","bids":[{"price":461.31,"qty":2.51161346}],"asks":[],"checksum":1676539923,"timestamp":"2024-06-01T17:52:17.517101Z"}]}
{"channel":"book","type":"update","data":[{"symbol":"BCH/USDT","bids":[{"price":461.32,"qty":7.83392088}],"asks":[],"checksum":1648178311,"timestamp":"2024-06-01T17:52:18.010209Z"}]}
{"channel":"book","type":"update","data":[{"symbol":"BCH/USDT","bids":[{"price":461.33,"qty":0.90000000}],"asks":[],"checksum":4243706177,"timestamp":"2024-06-01T17:52:18.016307Z"}]}
{"channel":"book","type":"update","data":[{"symbol":"BCH/USDT","bids":[{"price":461.31,"qty":1.61161346}],"asks":[],"checksum":3582292990,"timestamp":"2024-06-01T17:52:18.087437Z"}]}
{"channel":"book","type":"update","data":[{"symbol":"BCH/USDT","bids":[{"price":461.30,"qty":0.00000000},{"price":460.23,"qty":1.16000000}],"asks":[],"checksum":2527723725,"timestamp":"2024-06-01T17:52:18.091021Z"}]}
{"channel":"book","type":"update","data":[{"symbol":"BCH/USDT","bids":[{"price":461.31,"qty":0.00000000},{"price":460.06,"qty":2.42000000}],"asks":[],"checksum":807523491,"timestamp":"2024-06-01T17:52:18.645583Z"}]}
{"channel":"book","type":"update","data":[{"symbol":"BCH/USDT","bids":[{"price":461.25,"qty":1.47760980}],"asks":[],"checksum":2469033473,"timestamp":"2024-06-01T17:52:18.645790Z"}]}
{"channel":"book","type":"update","data":[{"symbol":"BCH/USDT","bids":[{"price":461.25,"qty":9.31153068}],"asks":[],"checksum":2661943543,"timestamp":"2024-06-01T17:52:18.649684Z"}]}
{"channel":"book","type":"update","data":[{"symbol":"BCH/USDT","bids":[{"price":461.32,"qty":0.00000000},{"price":460.06,"qty":2.42000000}],"asks":[],"checksum":2326613077,"timestamp":"2024-06-01T17:52:18.649826Z"}]}
{"channel":"book","type":"update","data":[{"symbol":"BCH/USDT","bids":[],"asks":[{"price":461.65,"qty":8.73392088}],"checksum":232205719,"timestamp":"2024-06-01T17:52:18.964519Z"}]}
{"channel":"book","type":"update","data":[{"symbol":"BCH/USDT","bids":[],"asks":[{"price":461.66,"qty":0.00000000},{"price":462.18,"qty":0.06585657}],"checksum":3422803029,"timestamp":"2024-06-01T17:52:18.964771Z"}]}
{"channel":"book","type":"update","data":[{"symbol":"BCH/USDT","bids":[],"asks":[{"price":461.70,"qty":0.00000000},{"price":462.40,"qty":1.13708000}],"checksum":1203001653,"timestamp":"2024-06-01T17:52:18.965622Z"}]}
{"channel":"book","type":"update","data":[{"symbol":"BCH/USDT","bids":[{"price":460.32,"qty":2.61000000}],"asks":[],"checksum":581323022,"timestamp":"2024-06-01T17:52:18.968914Z"}]}
{"channel":"book","type":"update","data":[{"symbol":"BCH/USDT","bids":[],"asks":[{"price":461.80,"qty":3.35022891}],"checksum":4275078644,"timestamp":"2024-06-01T17:52:18.970262Z"}]}
{"channel":"book","type":"update","data":[{"symbol":"BCH/USDT","bids":[{"price":461.34,"qty":3.80879832}],"asks":[],"checksum":1699166604,"timestamp":"2024-06-01T17:52:18.995962Z"}]}
{"channel":"book","type":"update","data":[{"symbol":"BCH/USDT","bids":[{"price":461.35,"qty":3.00000000}],"asks":[],"checksum":1396783449,"timestamp":"2024-06-01T17:52:19.000440Z"}]}
{"channel":"book","type":"update","data":[{"symbol":"BCH/USDT","bids":[],"asks":[{"price":461.65,"qty":7.83392088}],"checksum":2062862243,"timestamp":"2024-06-01T17:52:19.001227Z"}]}
{"channel":"book","type":"update","data":[{"symbol":"BCH/USDT","bids":[{"price":461.35,"qty":3.90000000}],"asks":[],"checksum":1515741617,"timestamp":"2024-06-01T17:52:19.001420Z"}]}
{"channel":"book","type":"update","data":[{"symbol":"BCH/USDT","bids":[],"asks":[{"price":462.16,"qty":0.94431792}],"checksum":1329792510,"timestamp":"2024-06-01T17:52:19.001519Z"}]}
{"channel":"book","type":"update","data":[{"symbol":"BCH/USDT","bids":[],"asks":[{"price":461.65,"qty":0.00000000},{"price":462.40,"qty":1.13708000}],"checksum":1806546904,"timestamp":"2024-06-01T17:52:19.016577Z"}]}
{"channel":"book","type":"update","data":[{"symbol":"BCH/USDT","bids":[],"asks":[{"price":461.66,"qty":0.90000000}],"checksum":47196285,"timestamp":"2024-06-01T17:52:19.088521Z"}]}
{"channel":"book","type":"update","data":[{"symbol":"BCH/USDT","bids":[{"price":461.33,"qty":0.00000000},{"price":460.32,"qty":2.61000000}],"asks":[],"checksum":2287858062,"timestamp":"2024-06-01T17:52:19.088535Z"}]}
{"channel":"book","type":"update","data":[{"symbol":"BCH/USDT","bids":[],"asks":[{"price":462.16,"qty":0.04431792}],"checksum":1464130271,"timestamp":"2024-06-01T17:52:19.094229Z"}]}
{"channel":"book","type":"update","data":[{"symbol":"BCH/USDT","bids":[{"price":461.23,"qty":0.00000000},{"price":460.23,"qty":1.16000000}],"asks":[],"checksum":1479410300,"timestamp":"2024-06-01T17:52:19.094438Z"}]}
{"channel":"book","type":"update","data":[{"symbol":"BCH/USDT","bids":[{"price":461.24,"qty":0.00000000},{"price":460.06,"qty":2.42000000}],"asks":[],"checksum":2790233729,"timestamp":"2024-06-01T17:52:19.094457Z"}]}
{"channel":"book","type":"update","data":[{"symbol":"BCH/USDT","bids":[],"asks":[{"price":461.79,"qty":3.00000000}],"checksum":2753683533,"timestamp":"2024-06-01T17:52:19.094465Z"}]}
{"channel":"book","type":"update","data":[{"symbol":"BCH/USDT","bids":[],"asks":[{"price":461.79,"qty":6.80879832}],"checksum":1446169699,"timestamp":"2024-06-01T17:52:19.094535Z"}]}
{"channel":"book","type":"update","data":[{"symbol":"BCH/USDT","bids":[],"asks":[{"price":461.70,"qty":7.83392088}],"checksum":3034682416,"timestamp":"2024-06-01T17:52:20.011736Z"}]}
{"channel":"book","type":"update","data":[{"symbol":"BCH/USDT","bids":[{"price":460.24,"qty":1.36603240}],"asks":[],"checksum":4268134919,"timestamp":"2024-06-01T17:52:20.421094Z"}]}
{"channel":"book","type":"update","data":[{"symbol":"BCH/USDT","bids":[{"price":461.25,"qty":7.83392088}],"asks":[],"checksum":3712648205,"timestamp":"2024-06-01T17:52:21.336385Z"}]}
{"channel":"book","type":"update","data":[{"symbol":"BCH/USDT","bids":[{"price":461.36,"qty":1.11548004}],"asks":[],"checksum":3351974161,"timestamp":"2024-06-01T17:52:21.336476Z"}]}
{"channel":"book","type":"update","data":[{"symbol":"BCH/USDT","bids":[{"price":461.37,"qty":0.90000000}],"asks":[],"checksum":1255246509,"timestamp":"2024-06-01T17:52:21.342105Z"}]}
{"channel":"book","type":"update","data":[{"symbol":"BCH/USDT","bids":[{"price":461.36,"qty":0.00000000},{"price":460.24,"qty":1.36603240}],"asks":[],"checksum":151723552,"timestamp":"2024-06-01T17:52:21.433024Z"}]}
{"channel":"book","type":"update","data":[{"symbol":"BCH/USDT","bids":[{"price":461.38,"qty":1.15107348}],"asks":[],"checksum":116455524,"timestamp":"2024-06-01T17:52:21.433229Z"}]}
{"channel":"book","type":"update","data":[{"symbol":"BCH/USDT","bids":[{"price":461.37,"qty":0.00000000},{"price":460.24,"qty":1.36603240}],"asks":[],"checksum":3637541023,"timestamp":"2024-06-01T17:52:21.437741Z"}]}
{"channel":"book","type":"update","data":[{"symbol":"BCH/USDT","bids":[{"price":461.39,"qty":0.90000000}],"asks":[],"checksum":1347802185,"timestamp":"2024-06-01T17:52:21.587303Z"}]}
{"channel":"book","type":"update","data":[{"symbol":"BCH/USDT","bids":[{"price":461.35,"qty":3.00000000}],"asks":[],"checksum":3454987041,"timestamp":"2024-06-01T17:52:21.591864Z"}]}
{"channel":"book","type":"update","data":[{"symbol":"BCH/USDT","bids":[{"price":461.38,"qty":0.00000000},{"price":460.24,"qty":1.36603240}],"asks":[],"checksum":1305964447,"timestamp":"2024-06-01T17:52:21.592038Z"}]}
{"channel":"book","type":"update","data":[{"symbol":"BCH/USDT","bids":[{"price":461.40,"qty":1.05042498}],"asks":[],"checksum":2637075154,"timestamp":"2024-06-01T17:52:21.592213Z"}]}
{"channel":"book","type":"update","data":[{"symbol":"BCH/USDT","bids":[{"price":461.41,"qty":0.90000000}],"asks":[],"checksum":91016297,"timestamp":"2024-06-01T17:52:22.087559Z"}]}
{"channel":"book","type":"update","data":[{"symbol":"BCH/USDT","bids":[{"price":461.31,"qty":7.83392088}],"asks":[],"checksum":2321976543,"timestamp":"2024-06-01T17:52:22.091293Z"}]}
{"channel":"book","type":"update","data":[{"symbol":"BCH/USDT","bids":[{"price":461.40,"qty":0.00000000},{"price":460.51,"qty":6.50102093}],"asks":[],"checksum":2202137714,"timestamp":"2024-06-01T17:52:22.092480Z"}]}
{"channel":"book","type":"update","data":[{"symbol":"BCH/USDT","bids":[{"price":461.42,"qty":0.91327841}],"asks":[],"checksum":2571621507,"timestamp":"2024-06-01T17:52:22.092497Z"}]}
{"channel":"book","type":"update","data":[{"symbol":"BCH/USDT","bids":[{"price":461.39,"qty":0.00000000},{"price":460.51,"qty":6.50102093}],"asks":[],"checksum":2666716512,"timestamp":"2024-06-01T17:52:22.092923Z"}]}
{"channel":"book","type":"update","data":[{"symbol":"BCH/USDT","bids":[],"asks":[{"price":461.65,"qty":0.60407019}],"checksum":1438550846,"timestamp":"2024-06-01T17:52:22.121524Z"}]}
{"channel":"book","type":"update","data":[{"symbol":"BCH/USDT","bids":[{"price":461.25,"qty":0.00000000},{"price":460.32,"qty":2.61000000}],"asks":[],"checksum":2176929179,"timestamp":"2024-06-01T17:52:22.125428Z"}]}
{"channel":"book","type":"update","data":[{"symbol":"BCH/USDT","bids":[{"price":461.43,"qty":0.90000000}],"asks":[],"checksum":2899194171,"timestamp":"2024-06-01T17:52:22.130761Z"}]}
{"channel":"book","type":"update","data":[{"symbol":"BCH/USDT","bids":[{"price":461.42,"qty":0.00000000},{"price":460.32,"qty":2.61000000}],"asks":[],"checksum":536351104,"timestamp":"2024-06-01T17:52:22.134454Z"}]}
{"channel":"book","type":"update","data":[{"symbol":"BCH/USDT","bids":[{"price":461.44,"qty":0.77474216}],"asks":[],"checksum":305281059,"timestamp":"2024-06-01T17:52:22.134681Z"}]}
{"channel":"book","type":"update","data":[{"symbol":"BCH/USDT","bids":[],"asks":[{"price":461.65,"qty":0.00000000},{"price":462.16,"qty":0.04431792}],"checksum":1071114899,"timestamp":"2024-06-01T17:52:22.281354Z"}]}
{"channel":"book","type":"update","data":[{"symbol":"BCH/USDT","bids":[{"price":461.43,"qty":0.00000000},{"price":460.32,"qty":2.61000000}],"asks":[],"checksum":2664896568,"timestamp":"2024-06-01T17:52:22.286046Z"}]}
{"channel":"book","type":"update","data":[{"symbol":"BCH/USDT","bids":[{"price":461.44,"qty":0.00000000},{"price":460.24,"qty":1.36603240}],"asks":[],"checksum":2846734949,"timestamp":"2024-06-01T17:52:22.333444Z"}]}
{"channel":"book","type":"update","data":[{"symbol":"BCH/USDT","bids":[{"price":461.42,"qty":1.12838748}],"asks":[],"checksum":581567944,"timestamp":"2024-06-01T17:52:22.333615Z"}]}
{"channel":"book","type":"update","data":[{"symbol":"BCH/USDT","bids":[],"asks":[{"price":461.79,"qty":3.80879832}],"checksum":4015708817,"timestamp":"2024-06-01T17:52:22.389885Z"}]}
{"channel":"book","type":"update","data":[{"symbol":"BCH/USDT","bids":[{"price":460.57,"qty":1.19000000}],"asks":[],"checksum":1022025763,"timestamp":"2024-06-01T17:52:22.389920Z"}]}
{"channel":"book","type":"update","data":[{"symbol":"BCH/USDT","bids":[],"asks":[{"price":461.79,"qty":0.00000000},{"price":462.17,"qty":0.08972479}],"checksum":3800849681,"timestamp":"2024-06-01T17:52:22.390005Z"}]}
{"channel":"book","type":"update","data":[{"symbol":"BCH/USDT","bids":[],"asks":[{"price":461.66,"qty":0.00000000},{"price":462.18,"qty":0.06585657}],"checksum":342734734,"timestamp":"2024-06-01T17:52:22.390031Z"}]}
{"channel":"book","type":"update","data":[{"symbol":"BCH/USDT","bids":[],"asks":[{"price":461.80,"qty":0.00000000},{"price":462.40,"qty":1.13708000}],"checksum":3357244276,"timestamp":"2024-06-01T17:52:22.391339Z"}]}
{"channel":"book","type":"update","data":[{"symbol":"BCH/USDT","bids":[],"asks":[{"price":461.70,"qty":0.00000000},{"price":462.45,"qty":4.78432880}],"checksum":3391826866,"timestamp":"2024-06-01T17:52:22.393074Z"}]}
{"channel":"book","type":"update","data":[{"symbol":"BCH/USDT","bids":[],"asks":[{"price":461.90,"qty":8.99797891}],"checksum":2664813527,"timestamp":"2024-06-01T17:52:22.395959Z"}]}
{"channel":"book","type":"update","data":[{"symbol":"BCH/USDT","bids":[{"price":461.42,"qty":0.00000000},{"price":460.32,"qty":2.61000000}],"asks":[],"checksum":193108821,"timestamp":"2024-06-01T17:52:22.438363Z"}]}
{"channel":"book","type":"update","data":[{"symbol":"BCH/USDT","bids":[],"asks":[{"price":461.71,"qty":0.70581062}],"checksum":3874252366,"timestamp":"2024-06-01T17:52:22.438482Z"}]}
{"channel":"book","type":"update","data":[{"symbol":"BCH/USDT","bids":[{"price":461.42,"qty":0.96408023}],"asks":[],"checksum":2105595210,"timestamp":"2024-06-01T17:52:22.442523Z"}]}
{"channel":"book","type":"update","data":[{"symbol":"BCH/USDT","bids":[],"asks":[{"price":461.71,"qty":0.10174043}],"checksum":2885611210,"timestamp":"2024-06-01T17:52:22.442628Z"}]}
{"channel":"book","type":"update","data":[{"symbol":"BCH/USDT","bids":[{"price":461.36,"qty":7.83392088}],"asks":[],"checksum":3827494595,"timestamp":"2024-06-01T17:52:22.442736Z"}]}
{"channel":"book","type":"update","data":[{"symbol":"BCH/USDT","bids":[{"price":461.43,"qty":3.80879832}],"asks":[],"checksum":157009892,"timestamp":"2024-06-01T17:52:22.451843Z"}]}
{"channel":"book","type":"update","data":[{"symbol":"BCH/USDT","bids":[],"asks":[{"price":461.71,"qty":0.00000000},{"price":462.45,"qty":4.78432880}],"checksum":1708211933,"timestamp":"2024-06-01T17:52:22.455212Z"}]}
{"channel":"book","type":"update","data":[{"symbol":"BCH/USDT","bids":[],"asks":[{"price":461.82,"qty":2.58370377}],"checksum":1623264278,"timestamp":"2024-06-01T17:52:22.455418Z"}]}
{"channel":"book","type":"update","data":[{"symbol":"BCH/USDT","bids":[{"price":461.42,"qty":0.00000000},{"price":460.57,"qty":1.19000000}],"asks":[],"checksum":2068614462,"timestamp":"2024-06-01T17:52:22.456240Z"}]}
{"channel":"book","type":"update","data":[{"symbol":"BCH/USDT","bids":[{"price":461.44,"qty":0.98889260}],"asks":[],"checksum":1628557726,"timestamp":"2024-06-01T17:52:22.456357Z"}]}
{"channel":"book","type":"update","data":[{"symbol":"BCH/USDT","bids":[{"price":461.31,"qty":0.00000000},{"price":460.57,"qty":1.19000000}],"asks":[],"checksum":1865344213,"timestamp":"2024-06-01T17:52:22.513438Z"}]}
{"channel":"book","type":"update","data":[{"symbol":"BCH/USDT","bids":[],"asks":[{"price":461.71,"qty":0.60407019}],"checksum":3173761143,"timestamp":"2024-06-01T17:52:22.540607Z"}]}
{"channel":"book","type":"update","data":[{"symbol":"BCH/USDT","bids":[],"asks":[{"price":461.89,"qty":3.00000000}],"checksum":1813250809,"timestamp":"2024-06-01T17:52:22.545729Z"}]}
{"channel":"book","type":"update","data":[{"symbol":"BCH/USDT","bids":[{"price":461.44,"qty":3.98889260}],"asks":[],"checksum":2500095110,"timestamp":"2024-06-01T17:52:22.545742Z"}]}
{"channel":"book","type":"update","data":[{"symbol":"BCH/USDT","bids":[{"price":461.45,"qty":0.90000000}],"asks":[],"checksum":1281647286,"timestamp":"2024-06-01T17:52:22.546039Z"}]}
{"channel":"book","type":"update","data":[{"symbol":"BCH/USDT","bids":[],"asks":[{"price":461.89,"qty":6.80879832}],"checksum":1830967928,"timestamp":"2024-06-01T17:52:22.546458Z"}]}
{"channel":"book","type":"update","data":[{"symbol":"BCH/USDT","bids":[{"price":461.34,"qty":0.00000000},{"price":460.57,"qty":1.19000000}],"asks":[],"checksum":2093528166,"timestamp":"2024-06-01T17:52:22.546520Z"}]}
{"channel":"book","type":"update","data":[{"symbol":"BCH/USDT","bids":[{"price":461.45,"qty":4.70879832}],"asks":[],"checksum":2914128875,"timestamp":"2024-06-01T17:52:22.546531Z"}]}
{"channel":"book","type":"update","data":[{"symbol":"BCH/USDT","bids":[{"price":461.44,"qty":11.82281348}],"asks":[],"checksum":2683045173,"timestamp":"2024-06-01T17:52:22.546712Z"}]}
{"channel":"book","type":"update","data":[{"symbol":"BCH/USDT","bids":[{"price":461.44,"qty":10.83392088}],"asks":[],"checksum":165767765,"timestamp":"2024-06-01T17:52:22.550902Z"}]}
{"channel":"book","type":"update","data":[{"symbol":"BCH/USDT","bids":[],"asks":[{"price":461.71,"qty":0.00000000},{"price":462.18,"qty":0.06585657}],"checksum":840795835,"timestamp":"2024-06-01T17:52:22.551144Z"}]}
{"channel":"book","type":"update","data":[{"symbol":"BCH/USDT","bids":[{"price":461.46,"qty":0.84162298}],"asks":[],"checksum":3363268098,"timestamp":"2024-06-01T17:52:22.551222Z"}]}
{"channel":"book","type":"update","data":[{"symbol":"BCH/USDT","bids":[{"price":461.45,"qty":3.80879832}],"asks":[],"checksum":2780035486,"timestamp":"2024-06-01T17:52:22.588527Z"}]}
{"channel":"book","type":"update","data":[{"symbol":"BCH/USDT","bids":[{"price":461.47,"qty":0.90000000}],"asks":[],"checksum":1261900346,"timestamp":"2024-06-01T17:52:22.588624Z"}]}
{"channel":"book","type":"update","data":[{"symbol":"BCH/USDT","bids":[{"price":461.36,"qty":0.00000000},{"price":460.64,"qty":0.76032560}],"asks":[],"checksum":3469292851,"timestamp":"2024-06-01T17:52:22.592839Z"}]}
{"channel":"book","type":"update","data":[{"symbol":"BCH/USDT","bids":[{"price":461.48,"qty":0.93677248}],"asks":[],"checksum":1630333747,"timestamp":"2024-06-01T17:52:22.592914Z"}]}
{"channel":"book","type":"update","data":[{"symbol":"BCH/USDT","bids":[{"price":461.46,"qty":0.00000000},{"price":460.64,"qty":0.76032560}],"asks":[],"checksum":2231545876,"timestamp":"2024-06-01T17:52:22.592981Z"}]}
{"channel":"book","type":"update","data":[{"symbol":"BCH/USDT","bids":[{"price":461.35,"qty":0.00000000},{"price":460.57,"qty":1.19000000}],"asks":[],"checksum":3277913023,"timestamp":"2024-06-01T17:52:22.593468Z"}]}
{"channel":"book","type":"update","data":[{"symbol":"BCH/USDT","bids":[{"price":461.41,"qty":0.00000000},{"price":460.51,"qty":6.50102093}],"asks":[],"checksum":169736867,"timestamp":"2024-06-01T17:52:22.593793Z"}]}
{"channel":"book","type":"update","data":[{"symbol":"BCH/USDT","bids":[{"price":461.45,"qty":0.00000000},{"price":460.32,"qty":2.61000000}],"asks":[],"checksum":55622826,"timestamp":"2024-06-01T17:52:22.594019Z"}]}
{"channel":"book","type":"update","data":[{"symbol":"BCH/USDT","bids":[{"price":461.48,"qty":0.00000000},{"price":460.24,"qty":1.36603240}],"asks":[],"checksum":1340547331,"timestamp":"2024-06-01T17:52:22.849522Z"}]}
{"channel":"book","type":"update","data":[{"symbol":"BCH/USDT","bids":[],"asks":[{"price":461.81,"qty":7.83392088}],"checksum":449833999,"timestamp":"2024-06-01T17:52:22.853724Z"}]}
{"channel":"book","type":"update","data":[{"symbol":"BCH/USDT","bids":[{"price":461.45,"qty":7.83392088}],"asks":[],"checksum":2678880233,"timestamp":"2024-06-01T17:52:22.853839Z"}]}
{"channel":"book","type":"update","data":[{"symbol":"BCH/USDT","bids":[{"price":461.45,"qty":10.83392088}],"asks":[],"checksum":662154893,"timestamp":"2024-06-01T17:52:22.854306Z"}]}
{"channel":"book","type":"update","data":[{"symbol":"BCH/USDT","bids":[],"asks":[{"price":461.82,"qty":0.00000000},{"price":462.18,"qty":0.06585657}],"checksum":2452260715,"timestamp":"2024-06-01T17:52:22.881747Z"}]}
{"channel":"book","type":"update","data":[{"symbol":"BCH/USDT","bids":[],"asks":[{"price":461.80,"qty":2.58370377}],"checksum":3121663070,"timestamp":"2024-06-01T17:52:22.881947Z"}]}
{"channel":"book","type":"update","data":[{"symbol":"BCH/USDT","bids":[{"price":461.44,"qty":3.00000000}],"asks":[],"checksum":374062729,"timestamp":"2024-06-01T17:52:22.886034Z"}]}
{"channel":"book","type":"update","data":[{"symbol":"BCH/USDT","bids":[{"price":461.44,"qty":0.00000000},{"price":460.24,"qty":1.36603240}],"asks":[],"checksum":982067444,"timestamp":"2024-06-01T17:52:22.886291Z"}]}
{"channel":"book","type":"update","data":[{"symbol":"BCH/USDT","bids":[],"asks":[{"price":461.81,"qty":0.00000000},{"price":462.18,"qty":0.06585657}],"checksum":3663427943,"timestamp":"2024-06-01T17:52:22.886770Z"}]}
{"channel":"book","type":"update","data":[{"symbol":"BCH/USDT","bids":[],"asks":[{"price":461.82,"qty":7.83392088}],"checksum":1886161769,"timestamp":"2024-06-01T17:52:22.886903Z"}]}
{"channel":"book","type":"update","data":[{"symbol":"BCH/USDT","bids":[],"asks":[{"price":461.80,"qty":0.00000000},{"price":462.18,"qty":0.06585657}],"checksum":48403419,"timestamp":"2024-06-01T17:52:22.907282Z"}]}
{"channel":"book","type":"update","data":[{"symbol":"BCH/USDT","bids":[],"asks":[{"price":461.81,"qty":2.58370377}],"checksum":2021590863,"timestamp":"2024-06-01T17:52:22.907330Z"}]}
{"channel":"book","type":"update","data":[{"symbol":"BCH/USDT","bids":[{"price":461.46,"qty":0.98677145}],"asks":[],"checksum":2527175515,"timestamp":"2024-06-01T17:52:23.584995Z"}]}
{"channel":"book","type":"update","data":[{"symbol":"BCH/USDT","bids":[{"price":461.47,"qty":0.00000000},{"price":460.24,"qty":1.36603240}],"asks":[],"checksum":610404404,"timestamp":"2024-06-01T17:52:23.587286Z"}]}
{"channel":"book","type":"update","data":[{"symbol":"BCH/USDT","bids":[{"price":461.46,"qty":1.88677145}],"asks":[],"checksum":3674088668,"timestamp":"2024-06-01T17:52:23.587382Z"}]}
{"channel":"book","type":"update","data":[{"symbol":"BCH/USDT","bids":[{"price":461.46,"qty":0.90000000}],"asks":[],"checksum":2354159849,"timestamp":"2024-06-01T17:52:24.346653Z"}]}
{"channel":"book","type":"update","data":[{"symbol":"BCH/USDT","bids":[{"price":461.45,"qty":3.00000000}],"asks":[],"checksum":1243136459,"timestamp":"2024-06-01T17:52:24.350628Z"}]}
{"channel":"book","type":"update","data":[{"symbol":"BCH/USDT","bids":[],"asks":[{"price":461.82,"qty":0.00000000},{"price":462.18,"qty":0.06585657}],"checksum":2129106664,"timestamp":"2024-06-01T17:52:24.350726Z"}]}
{"channel":"book","type":"update","data":[{"symbol":"BCH/USDT","bids":[{"price":461.40,"qty":7.83392088}],"asks":[],"checksum":1247077135,"timestamp":"2024-06-01T17:52:24.350954Z"}]}
{"channel":"book","type":"update","data":[{"symbol":"BCH/USDT","bids":[],"asks":[{"price":461.81,"qty":0.00000000},{"price":462.26,"qty":0.90000000}],"checksum":1692991113,"timestamp":"2024-06-01T17:52:24.367990Z"}]}
{"channel":"book","type":"update","data":[{"symbol":"BCH/USDT","bids":[],"asks":[{"price":461.82,"qty":2.58370377}],"checksum":3527734287,"timestamp":"2024-06-01T17:52:24.368932Z"}]}
{"channel":"book","type":"update","data":[{"symbol":"BCH/USDT","bids":[{"price":461.45,"qty":0.00000000},{"price":460.24,"qty":1.36603240}],"asks":[],"checksum":2239369127,"timestamp":"2024-06-01T17:52:24.710487Z"}]}
{"channel":"book","type":"update","data":[{"symbol":"BCH/USDT","bids":[{"price":461.44,"qty":3.00000000}],"asks":[],"checksum":1052117191,"timestamp":"2024-06-01T17:52:24.710556Z"}]}
{"channel":"book","type":"update","data":[{"symbol":"BCH/USDT","bids":[{"price":461.44,"qty":10.83392088}],"asks":[],"checksum":2407199554,"timestamp":"2024-06-01T17:52:24.714589Z"}]}
{"channel":"book","type":"update","data":[{"symbol":"BCH/USDT","bids":[{"price":461.46,"qty":0.00000000},{"price":460.24,"qty":1.36603240}],"asks":[],"checksum":4013137586,"timestamp":"2024-06-01T17:52:24.715401Z"}]}
{"channel":"book","type":"update","data":[{"symbol":"BCH/USDT","bids":[{"price":461.45,"qty":0.90000000}],"asks":[],"checksum":1215831529,"timestamp":"2024-06-01T17:52:24.715618Z"}]}
{"channel":"book","type":"update","data":[{"symbol":"BCH/USDT","bids":[{"price":461.44,"qty":3.00000000}],"asks":[],"checksum":3958380476,"timestamp":"2024-06-01T17:52:25.012725Z"}]}
{"channel":"book","type":"update","data":[{"symbol":"BCH/USDT","bids":[],"asks":[{"price":461.81,"qty":7.83392088}],"checksum":3323671563,"timestamp":"2024-06-01T17:52:26.010642Z"}]}
{"channel":"book","type":"update","data":[{"symbol":"BCH/USDT","bids":[],"asks":[{"price":461.82,"qty":0.00000000},{"price":462.18,"qty":0.06585657}],"checksum":683768852,"timestamp":"2024-06-01T17:52:26.022388Z"}]}
{"channel":"book","type":"update","data":[{"symbol":"BCH/USDT","bids":[],"asks":[{"price":461.80,"qty":2.58370377}],"checksum":61374646,"timestamp":"2024-06-01T17:52:26.022429Z"}]}
{"channel":"book","type":"update","data":[{"symbol":"BCH/USDT","bids":[],"asks":[{"price":461.83,"qty":0.00000000},{"price":462.18,"qty":0.06585657}],"checksum":3094859219,"timestamp":"2024-06-01T17:52:26.302643Z"}]}
{"channel":"book","type":"update","data":[{"symbol":"BCH/USDT","bids":[],"asks":[{"price":461.72,"qty":0.00000000},{"price":462.26,"qty":0.90000000}],"checksum":2172237235,"timestamp":"2024-06-01T17:52:26.303439Z"}]}
{"channel":"book","type":"update","data":[{"symbol":"BCH/USDT","bids":[],"asks":[{"price":462.25,"qty":1.36603240}],"checksum":2993514496,"timestamp":"2024-06-01T17:52:26.305372Z"}]}
{"channel":"book","type":"update","data":[{"symbol":"BCH/USDT","bids":[],"asks":[{"price":461.91,"qty":0.76032560}],"checksum":3716267225,"timestamp":"2024-06-01T17:52:26.306228Z"}]}
{"channel":"book","type":"update","data":[{"symbol":"BCH/USDT","bids":[],"asks":[{"price":461.81,"qty":0.00000000},{"price":462.25,"qty":1.36603240}],"checksum":1229899982,"timestamp":"2024-06-01T17:52:27.514833Z"}]}
{"channel":"book","type":"update","data":[{"symbol":"BCH/USDT","bids":[],"asks":[{"price":461.84,"qty":2.58370377}],"checksum":3212495841,"timestamp":"2024-06-01T17:52:27.542162Z"}]}
{"channel":"book","type":"update","data":[{"symbol":"BCH/USDT","bids":[],"asks":[{"price":461.80,"qty":0.00000000},{"price":462.25,"qty":1.36603240}],"checksum":1185491266,"timestamp":"2024-06-01T17:52:27.542306Z"}]}
{"channel":"book","type":"update","data":[{"symbol":"BCH/USDT","bids":[],"asks":[{"price":461.83,"qty":7.83392088}],"checksum":3586236182,"timestamp":"2024-06-01T17:52:29.020259Z"}]}
{"channel":"book","type":"update","data":[{"symbol":"BCH/USDT","bids":[],"asks":[{"price":461.82,"qty":2.58370377}],"checksum":3734486336,"timestamp":"2024-06-01T17:52:29.037276Z"}]}
{"channel":"book","type":"update","data":[{"symbol":"BCH/USDT","bids":[],"asks":[{"price":461.84,"qty":0.00000000},{"price":462.18,"qty":0.06585657}],"checksum":4017645148,"timestamp":"2024-06-01T17:52:29.037359Z"}]}
{"channel":"book","type":"update","data":[{"symbol":"BCH/USDT","bids":[],"asks":[{"price":461.83,"qty":0.00000000},{"price":462.25,"qty":1.36603240}],"checksum":1321023496,"timestamp":"2024-06-01T17:52:30.511696Z"}]}
{"channel":"book","type":"update","data":[{"symbol":"BCH/USDT","bids":[],"asks":[{"price":461.82,"qty":0.00000000},{"price":462.26,"qty":0.90000000}],"checksum":4160499413,"timestamp":"2024-06-01T17:52:30.524412Z"}]}
{"channel":"book","type":"update","data":[{"symbol":"BCH/USDT","bids":[],"asks":[{"price":461.84,"qty":2.58370377}],"checksum":1185491266,"timestamp":"2024-06-01T17:52:30.524615Z"}]}
{"channel":"book","type":"update","data":[{"symbol":"BCH/USDT","bids":[{"price":461.45,"qty":2.11378067}],"asks":[],"checksum":1089249522,"timestamp":"2024-06-01T17:52:30.894477Z"}]}
{"channel":"book","type":"update","data":[{"symbol":"BCH/USDT","bids":[{"price":461.44,"qty":0.00000000},{"price":460.24,"qty":1.36603240}],"asks":[],"checksum":4213221266,"timestamp":"2024-06-01T17:52:31.037276Z"}]}
{"channel":"book","type":"update","data":[{"symbol":"BCH/USDT","bids":[{"price":461.43,"qty":0.00000000},{"price":460.06,"qty":2.42000000}],"asks":[],"checksum":557418901,"timestamp":"2024-06-01T17:52:31.038335Z"}]}
{"channel":"book","type":"update","data":[{"symbol":"BCH/USDT","bids":[{"price":461.40,"qty":0.00000000},{"price":459.93,"qty":1.22000000}],"asks":[],"checksum":431569032,"timestamp":"2024-06-01T17:52:31.045710Z"}]}
{"channel":"book","type":"update","data":[{"symbol":"BCH/USDT","bids":[{"price":461.45,"qty":0.90000000}],"asks":[],"checksum":536654136,"timestamp":"2024-06-01T17:52:31.056440Z"}]}
{"channel":"book","type":"update","data":[{"symbol":"BCH/USDT","bids":[{"price":461.21,"qty":1.12656640}],"asks":[],"checksum":1077928936,"timestamp":"2024-06-01T17:52:31.056636Z"}]}
{"channel":"book","type":"update","data":[{"symbol":"BCH/USDT","bids":[{"price":460.71,"qty":6.49819876}],"asks":[],"checksum":2365487662,"timestamp":"2024-06-01T17:52:31.058404Z"}]}
{"channel":"book","type":"update","data":[{"symbol":"BCH/USDT","bids":[{"price":460.51,"qty":0.00000000},{"price":460.06,"qty":2.42000000}],"asks":[],"checksum":3526002327,"timestamp":"2024-06-01T17:52:31.058992Z"}]}
{"channel":"book","type":"update","data":[{"symbol":"BCH/USDT","bids":[{"price":461.21,"qty":0.00000000},{"price":459.93,"qty":1.22000000}],"asks":[],"checksum":2770013631,"timestamp":"2024-06-01T17:52:31.073926Z"}]}
{"channel":"book","type":"update","data":[{"symbol":"BCH/USDT","bids":[{"price":461.22,"qty":1.10992878}],"asks":[],"checksum":3249335028,"timestamp":"2024-06-01T17:52:31.074049Z"}]}
{"channel":"book","type":"update","data":[{"symbol":"BCH/USDT","bids":[{"price":461.45,"qty":0.00000000},{"price":459.93,"qty":1.22000000}],"asks":[],"checksum":2812681331,"timestamp":"2024-06-01T17:52:31.092120Z"}]}
{"channel":"book","type":"update","data":[{"symbol":"BCH/USDT","bids":[{"price":461.22,"qty":2.00992878}],"asks":[],"checksum":1865053718,"timestamp":"2024-06-01T17:52:31.092201Z"}]}
{"channel":"book","type":"update","data":[{"symbol":"BCH/USDT","bids":[],"asks":[{"price":461.83,"qty":3.00000000}],"checksum":287513207,"timestamp":"2024-06-01T17:52:31.155368Z"}]}
{"channel":"book","type":"update","data":[{"symbol":"BCH/USDT","bids":[{"price":461.21,"qty":3.00000000}],"asks":[],"checksum":4232477139,"timestamp":"2024-06-01T17:52:31.155521Z"}]}
{"channel":"book","type":"update","data":[{"symbol":"BCH/USDT","bids":[{"price":461.20,"qty":0.00000000},{"price":459.93,"qty":1.22000000}],"asks":[],"checksum":1787293863,"timestamp":"2024-06-01T17:52:31.165902Z"}]}
{"channel":"book","type":"update","data":[{"symbol":"BCH/USDT","bids":[],"asks":[{"price":461.79,"qty":3.80879832}],"checksum":1478079586,"timestamp":"2024-06-01T17:52:31.171114Z"}]}
{"channel":"book","type":"update","data":[{"symbol":"BCH/USDT","bids":[{"price":461.31,"qty":3.80879832}],"asks":[],"checksum":843537081,"timestamp":"2024-06-01T17:52:31.171369Z"}]}
{"channel":"book","type":"update","data":[{"symbol":"BCH/USDT","bids":[{"price":461.30,"qty":0.15537122}],"asks":[],"checksum":1319271615,"timestamp":"2024-06-01T17:52:31.171401Z"}]}
{"channel":"book","type":"update","data":[{"symbol":"BCH/USDT","bids":[{"price":461.23,"qty":7.83392088}],"asks":[],"checksum":1964165931,"timestamp":"2024-06-01T17:52:31.178753Z"}]}
{"channel":"book","type":"update","data":[{"symbol":"BCH/USDT","bids":[],"asks":[{"price":461.84,"qty":0.00000000},{"price":462.18,"qty":0.06585657}],"checksum":1997710356,"timestamp":"2024-06-01T17:52:31.187220Z"}]}
{"channel":"book","type":"update","data":[{"symbol":"BCH/USDT","bids":[],"asks":[{"price":461.82,"qty":2.58370377}],"checksum":2150556990,"timestamp":"2024-06-01T17:52:31.187309Z"}]}
{"channel":"book","type":"update","data":[{"symbol":"BCH/USDT","bids":[],"asks":[{"price":461.89,"qty":3.80879832}],"checksum":1537587791,"timestamp":"2024-06-01T17:52:31.198313Z"}]}
{"channel":"book","type":"update","data":[{"symbol":"BCH/USDT","bids":[{"price":461.23,"qty":10.83392088}],"asks":[],"checksum":1766629830,"timestamp":"2024-06-01T17:52:31.198356Z"}]}
{"channel":"book","type":"update","data":[{"symbol":"BCH/USDT","bids":[{"price":461.21,"qty":0.00000000},{"price":460.24,"qty":1.36603240}],"asks":[],"checksum":2466368860,"timestamp":"2024-06-01T17:52:31.213395Z"}]}
{"channel":"book","type":"update","data":[{"symbol":"BCH/USDT","bids":[{"price":461.32,"qty":7.83392088}],"asks":[],"checksum":2717067171,"timestamp":"2024-06-01T17:52:31.214901Z"}]}
{"channel":"book","type":"update","data":[{"symbol":"BCH/USDT","bids":[{"price":461.23,"qty":14.64271920}],"asks":[],"checksum":2928288663,"timestamp":"2024-06-01T17:52:31.218683Z"}]}
{"channel":"book","type":"update","data":[{"symbol":"BCH/USDT","bids":[],"asks":[{"price":461.89,"qty":0.00000000},{"price":462.18,"qty":0.06585657}],"checksum":3153080514,"timestamp":"2024-06-01T17:52:31.218822Z"}]}
{"channel":"book","type":"update","data":[{"symbol":"BCH/USDT","bids":[{"price":461.31,"qty":0.00000000},{"price":460.24,"qty":1.36603240}],"asks":[],"checksum":4107443589,"timestamp":"2024-06-01T17:52:31.218890Z"}]}
{"channel":"book","type":"update","data":[{"symbol":"BCH/USDT","bids":[{"price":460.65,"qty":6.49904515}],"asks":[],"checksum":3158376282,"timestamp":"2024-06-01T17:52:31.231538Z"}]}
{"channel":"book","type":"update","data":[{"symbol":"BCH/USDT","bids":[{"price":460.71,"qty":0.00000000},{"price":460.24,"qty":1.36603240}],"asks":[],"checksum":3822302927,"timestamp":"2024-06-01T17:52:31.232436Z"}]}
{"channel":"book","type":"update","data":[{"symbol":"BCH/USDT","bids":[{"price":461.30,"qty":0.00000000},{"price":460.06,"qty":2.42000000}],"asks":[],"checksum":3384527015,"timestamp":"2024-06-01T17:52:31.234624Z"}]}
{"channel":"book","type":"update","data":[{"symbol":"BCH/USDT","bids":[{"price":461.32,"qty":0.00000000},{"price":459.93,"qty":1.22000000}],"asks":[],"checksum":3750321,"timestamp":"2024-06-01T17:52:31.245746Z"}]}
{"channel":"book","type":"update","data":[{"symbol":"BCH/USDT","bids":[{"price":461.20,"qty":1.42836041}],"asks":[],"checksum":2703796792,"timestamp":"2024-06-01T17:52:31.252910Z"}]}
{"channel":"book","type":"update","data":[{"symbol":"BCH/USDT","bids":[{"price":461.32,"qty":0.90000000}],"asks":[],"checksum":2991991327,"timestamp":"2024-06-01T17:52:31.255457Z"}]}
{"channel":"book","type":"update","data":[{"symbol":"BCH/USDT","bids":[],"asks":[{"price":461.66,"qty":0.90000000}],"checksum":697449002,"timestamp":"2024-06-01T17:52:31.255471Z"}]}
{"channel":"book","type":"update","data":[{"symbol":"BCH/USDT","bids":[{"price":461.22,"qty":0.90000000}],"asks":[],"checksum":97784757,"timestamp":"2024-06-01T17:52:31.274537Z"}]}
{"channel":"book","type":"update","data":[{"symbol":"BCH/USDT","bids":[{"price":461.22,"qty":0.00000000},{"price":460.06,"qty":2.42000000}],"asks":[],"checksum":3797077096,"timestamp":"2024-06-01T17:52:31.286004Z"}]}
{"channel":"book","type":"update","data":[{"symbol":"BCH/USDT","bids":[],"asks":[{"price":461.66,"qty":4.70879832}],"checksum":3475085885,"timestamp":"2024-06-01T17:52:31.302170Z"}]}
{"channel":"book","type":"update","data":[{"symbol":"BCH/USDT","bids":[],"asks":[{"price":461.79,"qty":0.00000000},{"price":462.18,"qty":0.06585657}],"checksum":3156633812,"timestamp":"2024-06-01T17:52:31.334222Z"}]}
{"channel":"book","type":"update","data":[{"symbol":"BCH/USDT","bids":[],"asks":[{"price":461.78,"qty":3.00000000}],"checksum":3699090647,"timestamp":"2024-06-01T17:52:31.336518Z"}]}
{"channel":"book","type":"update","data":[{"symbol":"BCH/USDT","bids":[{"price":461.23,"qty":6.80879832}],"asks":[],"checksum":624640147,"timestamp":"2024-06-01T17:52:31.363594Z"}]}
{"channel":"book","type":"update","data":[{"symbol":"BCH/USDT","bids":[{"price":460.71,"qty":1.26702651}],"asks":[],"checksum":1405676099,"timestamp":"2024-06-01T17:52:31.368277Z"}]}
{"channel":"book","type":"update","data":[{"symbol":"BCH/USDT","bids":[],"asks":[{"price":461.83,"qty":0.00000000},{"price":462.18,"qty":0.06585657}],"checksum":3012252663,"timestamp":"2024-06-01T17:52:31.370045Z"}]}
{"channel":"book","type":"update","data":[{"symbol":"BCH/USDT","bids":[{"price":460.65,"qty":0.00000000},{"price":460.06,"qty":2.42000000}],"asks":[],"checksum":4215107048,"timestamp":"2024-06-01T17:52:31.375987Z"}]}
{"channel":"book","type":"update","data":[{"symbol":"BCH/USDT","bids":[],"asks":[{"price":461.84,"qty":2.58370377}],"checksum":2218906927,"timestamp":"2024-06-01T17:52:31.376166Z"}]}
{"channel":"book","type":"update","data":[{"symbol":"BCH/USDT","bids":[],"asks":[{"price":461.82,"qty":0.00000000},{"price":462.18,"qty":0.06585657}],"checksum":2629821475,"timestamp":"2024-06-01T17:52:31.376180Z"}]}
{"channel":"book","type":"update","data":[{"symbol":"BCH/USDT","bids":[{"price":460.72,"qty":6.49805771}],"asks":[],"checksum":775350207,"timestamp":"2024-06-01T17:52:31.376208Z"}]}
{"channel":"book","type":"update","data":[{"symbol":"BCH/USDT","bids":[{"price":460.71,"qty":0.00000000},{"price":460.06,"qty":2.42000000}],"asks":[],"checksum":1240934623,"timestamp":"2024-06-01T17:52:31.381201Z"}]}
{"channel":"book","type":"update","data":[{"symbol":"BCH/USDT","bids":[{"price":460.73,"qty":1.26702651}],"asks":[],"checksum":943304315,"timestamp":"2024-06-01T17:52:31.381361Z"}]}
{"channel":"book","type":"update","data":[{"symbol":"BCH/USDT","bids":[],"asks":[{"price":461.65,"qty":3.00000000}],"checksum":2713082620,"timestamp":"2024-06-01T17:52:31.466620Z"}]}
{"channel":"book","type":"update","data":[{"symbol":"BCH/USDT","bids":[],"asks":[{"price":461.64,"qty":0.90000000}],"checksum":4201469531,"timestamp":"2024-06-01T17:52:31.481527Z"}]}
{"channel":"book","type":"update","data":[{"symbol":"BCH/USDT","bids":[{"price":460.72,"qty":0.00000000},{"price":460.06,"qty":2.42000000}],"asks":[],"checksum":4252444721,"timestamp":"2024-06-01T17:52:31.538687Z"}]}
{"channel":"book","type":"update","data":[{"symbol":"BCH/USDT","bids":[{"price":460.74,"qty":3.63000000}],"asks":[],"checksum":3699743888,"timestamp":"2024-06-01T17:52:31.538743Z"}]}
{"channel":"book","type":"update","data":[{"symbol":"BCH/USDT","bids":[{"price":460.73,"qty":0.00000000},{"price":460.06,"qty":2.42000000}],"asks":[],"checksum":750173522,"timestamp":"2024-06-01T17:52:31.543292Z"}]}
{"channel":"book","type":"update","data":[{"symbol":"BCH/USDT","bids":[{"price":460.75,"qty":1.19245650}],"asks":[],"checksum":3740784256,"timestamp":"2024-06-01T17:52:31.543586Z"}]}
{"channel":"book","type":"update","data":[{"symbol":"BCH/USDT","bids":[],"asks":[{"price":461.66,"qty":3.80879832}],"checksum":1046327817,"timestamp":"2024-06-01T17:52:31.544329Z"}]}
{"channel":"book","type":"update","data":[{"symbol":"BCH/USDT","bids":[],"asks":[{"price":461.78,"qty":0.00000000},{"price":462.17,"qty":0.08972479}],"checksum":1364437989,"timestamp":"2024-06-01T17:52:31.547732Z"}]}
{"channel":"book","type":"update","data":[{"symbol":"BCH/USDT","bids":[{"price":460.75,"qty":0.00000000},{"price":460.06,"qty":2.42000000}],"asks":[],"checksum":2735915063,"timestamp":"2024-06-01T17:52:31.548112Z"}]}
{"channel":"book","type":"update","data":[{"symbol":"BCH/USDT","bids":[{"price":461.20,"qty":2.62168803}],"asks":[],"checksum":2345266580,"timestamp":"2024-06-01T17:52:31.548235Z"}]}
{"channel":"book","type":"update","data":[{"symbol":"BCH/USDT","bids":[{"price":460.76,"qty":1.19332762}],"asks":[],"checksum":1458410578,"timestamp":"2024-06-01T17:52:31.548781Z"}]}
{"channel":"book","type":"update","data":[{"symbol":"BCH/USDT","bids":[{"price":460.74,"qty":0.00000000},{"price":460.06,"qty":2.42000000}],"asks":[],"checksum":1720927380,"timestamp":"2024-06-01T17:52:31.551389Z"}]}
{"channel":"book","type":"update","data":[{"symbol":"BCH/USDT","bids":[{"price":460.71,"qty":6.49819876}],"asks":[],"checksum":958681537,"timestamp":"2024-06-01T17:52:31.551545Z"}]}
{"channel":"book","type":"update","data":[{"symbol":"BCH/USDT","bids":[{"price":461.20,"qty":1.42836041}],"asks":[],"checksum":301956194,"timestamp":"2024-06-01T17:52:31.552248Z"}]}
{"channel":"book","type":"update","data":[{"symbol":"BCH/USDT","bids":[{"price":460.76,"qty":0.00000000},{"price":460.06,"qty":2.42000000}],"asks":[],"checksum":878424498,"timestamp":"2024-06-01T17:52:31.760333Z"}]}
{"channel":"book","type":"update","data":[{"symbol":"BCH/USDT","bids":[{"price":461.21,"qty":1.22030661}],"asks":[],"checksum":491772061,"timestamp":"2024-06-01T17:52:31.760446Z"}]}
{"channel":"book","type":"update","data":[{"symbol":"BCH/USDT","bids":[{"price":461.23,"qty":8.21464594}],"asks":[],"checksum":1631785126,"timestamp":"2024-06-01T17:52:31.762801Z"}]}
{"channel":"book","type":"update","data":[{"symbol":"BCH/USDT","bids":[],"asks":[{"price":461.64,"qty":8.73392088}],"checksum":1187035710,"timestamp":"2024-06-01T17:52:31.764243Z"}]}
{"channel":"book","type":"update","data":[{"symbol":"BCH/USDT","bids":[{"price":461.32,"qty":0.00000000},{"price":460.06,"qty":2.42000000}],"asks":[],"checksum":2334280820,"timestamp":"2024-06-01T17:52:31.765672Z"}]}
{"channel":"book","type":"update","data":[{"symbol":"BCH/USDT","bids":[{"price":461.24,"qty":0.90000000}],"asks":[],"checksum":3272811823,"timestamp":"2024-06-01T17:52:31.765695Z"}]}
{"channel":"book","type":"update","data":[{"symbol":"BCH/USDT","bids":[{"price":461.23,"qty":6.80879832}],"asks":[],"checksum":3206540564,"timestamp":"2024-06-01T17:52:31.774320Z"}]}
{"channel":"book","type":"update","data":[{"symbol":"BCH/USDT","bids":[],"asks":[{"price":461.66,"qty":0.00000000},{"price":462.18,"qty":0.06585657}],"checksum":2313517927,"timestamp":"2024-06-01T17:52:31.776680Z"}]}
{"channel":"book","type":"update","data":[{"symbol":"BCH/USDT","bids":[],"asks":[{"price":461.65,"qty":0.00000000},{"price":462.25,"qty":1.36603240}],"checksum":48803529,"timestamp":"2024-06-01T17:52:31.776729Z"}]}
{"channel":"book","type":"update","data":[{"symbol":"BCH/USDT","bids":[],"asks":[{"price":461.64,"qty":7.83392088}],"checksum":1604911157,"timestamp":"2024-06-01T17:52:31.776806Z"}]}
{"channel":"book","type":"update","data":[{"symbol":"BCH/USDT","bids":[{"price":461.23,"qty":8.11488229}],"asks":[],"checksum":2267019192,"timestamp":"2024-06-01T17:52:31.778102Z"}]}
{"channel":"book","type":"update","data":[{"symbol":"BCH/USDT","bids":[],"asks":[{"price":461.64,"qty":0.00000000},{"price":462.40,"qty":1.13708000}],"checksum":1352536862,"timestamp":"2024-06-01T17:52:31.778186Z"}]}
{"channel":"book","type":"update","data":[{"symbol":"BCH/USDT","bids":[{"price":461.21,"qty":0.00000000},{"price":460.06,"qty":2.42000000}],"asks":[],"checksum":2039118385,"timestamp":"2024-06-01T17:52:31.782170Z"}]}
{"channel":"book","type":"update","data":[{"symbol":"BCH/USDT","bids":[{"price":461.25,"qty":1.42927660}],"asks":[],"checksum":2766094070,"timestamp":"2024-06-01T17:52:31.782181Z"}]}
{"channel":"book","type":"update","data":[{"symbol":"BCH/USDT","bids":[{"price":461.25,"qty":0.00000000},{"price":460.06,"qty":2.42000000}],"asks":[],"checksum":2039118385,"timestamp":"2024-06-01T17:52:31.786504Z"}]}
{"channel":"book","type":"update","data":[{"symbol":"BCH/USDT","bids":[{"price":461.25,"qty":1.40834891}],"asks":[],"checksum":1421043753,"timestamp":"2024-06-01T17:52:31.814254Z"}]}
{"channel":"book","type":"update","data":[{"symbol":"BCH/USDT","bids":[{"price":461.26,"qty":3.80879832}],"asks":[],"checksum":2179186120,"timestamp":"2024-06-01T17:52:31.820905Z"}]}
{"channel":"book","type":"update","data":[{"symbol":"BCH/USDT","bids":[{"price":461.23,"qty":6.80879832}],"asks":[],"checksum":2419457132,"timestamp":"2024-06-01T17:52:31.825396Z"}]}
{"channel":"book","type":"update","data":[{"symbol":"BCH/USDT","bids":[{"price":461.27,"qty":1.41066903}],"asks":[],"checksum":2727335119,"timestamp":"2024-06-01T17:52:31.825596Z"}]}
{"channel":"book","type":"update","data":[{"symbol":"BCH/USDT","bids":[{"price":461.27,"qty":2.31066903}],"asks":[],"checksum":765078492,"timestamp":"2024-06-01T17:52:31.826538Z"}]}
{"channel":"book","type":"update","data":[{"symbol":"BCH/USDT","bids":[{"price":461.27,"qty":5.31066903}],"asks":[],"checksum":2095931526,"timestamp":"2024-06-01T17:52:31.829808Z"}]}
{"channel":"book","type":"update","data":[{"symbol":"BCH/USDT","bids":[{"price":461.23,"qty":3.00000000}],"asks":[],"checksum":2100392764,"timestamp":"2024-06-01T17:52:31.951596Z"}]}
{"channel":"book","type":"update","data":[{"symbol":"BCH/USDT","bids":[{"price":461.28,"qty":3.80879832}],"asks":[],"checksum":1630376458,"timestamp":"2024-06-01T17:52:31.951758Z"}]}
{"channel":"book","type":"update","data":[{"symbol":"BCH/USDT","bids":[],"asks":[{"price":461.79,"qty":3.80879832}],"checksum":2028185245,"timestamp":"2024-06-01T17:52:31.951848Z"}]}
{"channel":"book","type":"update","data":[{"symbol":"BCH/USDT","bids":[],"asks":[{"price":461.78,"qty":7.83392088}],"checksum":1194171422,"timestamp":"2024-06-01T17:52:31.955852Z"}]}
{"channel":"book","type":"update","data":[{"symbol":"BCH/USDT","bids":[{"price":461.26,"qty":0.00000000},{"price":460.57,"qty":1.19000000}],"asks":[],"checksum":1071637757,"timestamp":"2024-06-01T17:52:31.956270Z"}]}
{"channel":"book","type":"update","data":[{"symbol":"BCH/USDT","bids":[{"price":461.23,"qty":0.00000000},{"price":460.32,"qty":2.61000000}],"asks":[],"checksum":1524123714,"timestamp":"2024-06-01T17:52:31.956381Z"}]}
{"channel":"book","type":"update","data":[{"symbol":"BCH/USDT","bids":[],"asks":[{"price":461.83,"qty":3.00000000}],"checksum":3113046346,"timestamp":"2024-06-01T17:52:31.956604Z"}]}
{"channel":"book","type":"update","data":[{"symbol":"BCH/USDT","bids":[{"price":461.27,"qty":4.41066903}],"asks":[],"checksum":1280193395,"timestamp":"2024-06-01T17:52:31.957015Z"}]}
{"channel":"book","type":"update","data":[{"symbol":"BCH/USDT","bids":[{"price":461.29,"qty":0.90000000}],"asks":[],"checksum":3528151534,"timestamp":"2024-06-01T17:52:31.957140Z"}]}
{"channel":"book","type":"update","data":[{"symbol":"BCH/USDT","bids":[],"asks":[{"price":461.66,"qty":0.90000000}],"checksum":3083836398,"timestamp":"2024-06-01T17:52:31.957205Z"}]}
{"channel":"book","type":"update","data":[{"symbol":"BCH/USDT","bids":[],"asks":[{"price":461.84,"qty":0.00000000},{"price":462.17,"qty":0.08972479}],"checksum":3596033472,"timestamp":"2024-06-01T17:52:31.968535Z"}]}
{"channel":"book","type":"update","data":[{"symbol":"BCH/USDT","bids":[],"asks":[{"price":461.82,"qty":2.58370377}],"checksum":2109746885,"timestamp":"2024-06-01T17:52:31.968721Z"}]}
{"channel":"book","type":"update","data":[{"symbol":"BCH/USDT","bids":[{"price":461.25,"qty":0.00000000},{"price":460.32,"qty":2.61000000}],"asks":[],"checksum":3256857197,"timestamp":"2024-06-01T17:52:31.973595Z"}]}
{"channel":"book","type":"update","data":[{"symbol":"BCH/USDT","bids":[{"price":461.27,"qty":3.00000000}],"asks":[],"checksum":1469499936,"timestamp":"2024-06-01T17:52:31.973704Z"}]}
{"channel":"book","type":"update","data":[{"symbol":"BCH/USDT","bids":[{"price":461.28,"qty":4.74950702}],"asks":[],"checksum":1928492489,"timestamp":"2024-06-01T17:52:31.977904Z"}]}
{"channel":"book","type":"update","data":[{"symbol":"BCH/USDT","bids":[{"price":461.24,"qty":0.00000000},{"price":460.24,"qty":1.36603240}],"asks":[],"checksum":1924843107,"timestamp":"2024-06-01T17:52:32.088437Z"}]}
{"channel":"book","type":"update","data":[{"symbol":"BCH/USDT","bids":[{"price":461.30,"qty":3.80879832}],"asks":[],"checksum":1462920701,"timestamp":"2024-06-01T17:52:32.093148Z"}]}
{"channel":"book","type":"update","data":[{"symbol":"BCH/USDT","bids":[{"price":461.29,"qty":3.90000000}],"asks":[],"checksum":550838707,"timestamp":"2024-06-01T17:52:32.093170Z"}]}
{"channel":"book","type":"update","data":[{"symbol":"BCH/USDT","bids":[],"asks":[{"price":461.77,"qty":3.00000000}],"checksum":872077663,"timestamp":"2024-06-01T17:52:32.093247Z"}]}
{"channel":"book","type":"update","data":[{"symbol":"BCH/USDT","bids":[],"asks":[{"price":461.83,"qty":0.00000000},{"price":462.16,"qty":0.04431792}],"checksum":3139106564,"timestamp":"2024-06-01T17:52:32.209774Z"}]}
{"channel":"book","type":"update","data":[{"symbol":"BCH/USDT","bids":[{"price":461.27,"qty":0.00000000},{"price":460.24,"qty":1.36603240}],"asks":[],"checksum":1586068572,"timestamp":"2024-06-01T17:52:32.209861Z"}]}
{"channel":"book","type":"update","data":[{"symbol":"BCH/USDT","bids":[{"price":461.31,"qty":3.00000000}],"asks":[],"checksum":3168021960,"timestamp":"2024-06-01T17:52:32.209958Z"}]}
{"channel":"book","type":"update","data":[{"symbol":"BCH/USDT","bids":[{"price":461.29,"qty":0.90000000}],"asks":[],"checksum":8896385,"timestamp":"2024-06-01T17:52:32.214242Z"}]}
{"channel":"book","type":"update","data":[{"symbol":"BCH/USDT","bids":[{"price":461.28,"qty":0.94070870}],"asks":[],"checksum":715637092,"timestamp":"2024-06-01T17:52:32.214716Z"}]}
{"channel":"book","type":"update","data":[{"symbol":"BCH/USDT","bids":[{"price":461.32,"qty":0.90000000}],"asks":[],"checksum":1969620394,"timestamp":"2024-06-01T17:52:32.215658Z"}]}
{"channel":"book","type":"update","data":[{"symbol":"BCH/USDT","bids":[{"price":461.28,"qty":0.00000000},{"price":460.32,"qty":2.61000000}],"asks":[],"checksum":3653671057,"timestamp":"2024-06-01T17:52:32.219112Z"}]}
{"channel":"book","type":"update","data":[{"symbol":"BCH/USDT","bids":[{"price":461.21,"qty":1.20422420}],"asks":[],"checksum":2408177580,"timestamp":"2024-06-01T17:52:32.219155Z"}]}
{"channel":"book","type":"update","data":[{"symbol":"BCH/USDT","bids":[],"asks":[{"price":461.84,"qty":2.58370377}],"checksum":3175867529,"timestamp":"2024-06-01T17:52:32.227530Z"}]}
{"channel":"book","type":"update","data":[{"symbol":"BCH/USDT","bids":[],"asks":[{"price":461.82,"qty":0.00000000},{"price":462.16,"qty":0.04431792}],"checksum":63459637,"timestamp":"2024-06-01T17:52:32.227577Z"}]}
{"channel":"book","type":"update","data":[{"symbol":"BCH/USDT","bids":[{"price":461.33,"qty":3.80879832}],"asks":[],"checksum":528707210,"timestamp":"2024-06-01T17:52:32.452796Z"}]}
{"channel":"book","type":"update","data":[{"symbol":"BCH/USDT","bids":[{"price":461.30,"qty":0.00000000},{"price":460.57,"qty":1.19000000}],"asks":[],"checksum":375739094,"timestamp":"2024-06-01T17:52:32.457186Z"}]}
{"channel":"book","type":"update","data":[{"symbol":"BCH/USDT","bids":[{"price":461.34,"qty":3.00000000}],"asks":[],"checksum":2793317029,"timestamp":"2024-06-01T17:52:32.457342Z"}]}
{"channel":"book","type":"update","data":[{"symbol":"BCH/USDT","bids":[{"price":461.32,"qty":0.00000000},{"price":460.57,"qty":1.19000000}],"asks":[],"checksum":2057563165,"timestamp":"2024-06-01T17:52:32.457773Z"}]}
{"channel":"book","type":"update","data":[{"symbol":"BCH/USDT","bids":[{"price":461.34,"qty":3.90000000}],"asks":[],"checksum":1510951439,"timestamp":"2024-06-01T17:52:32.457799Z"}]}
{"channel":"book","type":"update","data":[{"symbol":"BCH/USDT","bids":[{"price":461.29,"qty":0.00000000},{"price":460.32,"qty":2.61000000}],"asks":[],"checksum":2747241331,"timestamp":"2024-06-01T17:52:32.587976Z"}]}
{"channel":"book","type":"update","data":[{"symbol":"BCH/USDT","bids":[{"price":461.35,"qty":7.83392088}],"asks":[],"checksum":425820886,"timestamp":"2024-06-01T17:52:32.591863Z"}]}
{"channel":"book","type":"update","data":[{"symbol":"BCH/USDT","bids":[{"price":461.31,"qty":0.00000000},{"price":460.32,"qty":2.61000000}],"asks":[],"checksum":606212277,"timestamp":"2024-06-01T17:52:32.592093Z"}]}
{"channel":"book","type":"update","data":[{"symbol":"BCH/USDT","bids":[{"price":461.35,"qty":11.64271920}],"asks":[],"checksum":1850215694,"timestamp":"2024-06-01T17:52:32.592728Z"}]}
{"channel":"book","type":"update","data":[{"symbol":"BCH/USDT","bids":[{"price":461.33,"qty":0.00000000},{"price":460.24,"qty":1.36603240}],"asks":[],"checksum":2197808370,"timestamp":"2024-06-01T17:52:32.952128Z"}]}
{"channel":"book","type":"update","data":[{"symbol":"BCH/USDT","bids":[{"price":461.36,"qty":0.90000000}],"asks":[],"checksum":495561464,"timestamp":"2024-06-01T17:52:32.957329Z"}]}
{"channel":"book","type":"update","data":[{"symbol":"BCH/USDT","bids":[{"price":461.21,"qty":0.00000000},{"price":460.24,"qty":1.36603240}],"asks":[],"checksum":3371812915,"timestamp":"2024-06-01T17:52:32.961519Z"}]}
{"channel":"book","type":"update","data":[{"symbol":"BCH/USDT","bids":[{"price":461.34,"qty":3.00000000}],"asks":[],"checksum":1430452059,"timestamp":"2024-06-01T17:52:33.088353Z"}]}
{"channel":"book","type":"update","data":[{"symbol":"BCH/USDT","bids":[],"asks":[{"price":461.78,"qty":0.00000000},{"price":462.17,"qty":0.08972479}],"checksum":380535897,"timestamp":"2024-06-01T17:52:33.513694Z"}]}
{"channel":"book","type":"update","data":[{"symbol":"BCH/USDT","bids":[],"asks":[{"price":461.78,"qty":3.00000000}],"checksum":2313167692,"timestamp":"2024-06-01T17:52:33.518622Z"}]}
{"channel":"book","type":"update","data":[{"symbol":"BCH/USDT","bids":[],"asks":[{"price":461.77,"qty":0.00000000},{"price":462.17,"qty":0.08972479}],"checksum":4154647569,"timestamp":"2024-06-01T17:52:33.518722Z"}]}
{"channel":"book","type":"update","data":[{"symbol":"BCH/USDT","bids":[],"asks":[{"price":461.77,"qty":7.83392088}],"checksum":1917754859,"timestamp":"2024-06-01T17:52:35.014594Z"}]}
{"channel":"book","type":"update","data":[{"symbol":"BCH/USDT","bids":[],"asks":[{"price":461.76,"qty":3.00000000}],"checksum":3868466274,"timestamp":"2024-06-01T17:52:35.019540Z"}]}
{"channel":"book","type":"update","data":[{"symbol":"BCH/USDT","bids":[],"asks":[{"price":461.78,"qty":0.00000000},{"price":462.16,"qty":0.04431792}],"checksum":1609582811,"timestamp":"2024-06-01T17:52:35.208718Z"}]}
{"channel":"book","type":"update","data":[{"symbol":"BCH/USDT","bids":[],"asks":[{"price":461.77,"qty":0.00000000},{"price":462.17,"qty":0.08972479}],"checksum":1746898708,"timestamp":"2024-06-01T17:52:36.511370Z"}]}
{"channel":"book","type":"update","data":[{"symbol":"BCH/USDT","bids":[],"asks":[{"price":461.76,"qty":0.00000000},{"price":462.18,"qty":0.06585657}],"checksum":3762840044,"timestamp":"2024-06-01T17:52:36.516355Z"}]}
{"channel":"book","type":"update","data":[{"symbol":"BCH/USDT","bids":[],"asks":[{"price":461.78,"qty":3.00000000}],"checksum":4154647569,"timestamp":"2024-06-01T17:52:36.516500Z"}]}
{"channel":"book","type":"update","data":[{"symbol":"BCH/USDT","bids":[{"price":461.35,"qty":3.80879832}],"asks":[],"checksum":3058237080,"timestamp":"2024-06-01T17:52:37.136018Z"}]}
{"channel":"book","type":"update","data":[{"symbol":"BCH/USDT","bids":[{"price":461.21,"qty":1.48782210}],"asks":[],"checksum":3744392684,"timestamp":"2024-06-01T17:52:37.141191Z"}]}
{"channel":"book","type":"update","data":[{"symbol":"BCH/USDT","bids":[{"price":461.35,"qty":0.00000000},{"price":460.24,"qty":1.36603240}],"asks":[],"checksum":2256690287,"timestamp":"2024-06-01T17:52:37.230178Z"}]}
{"channel":"book","type":"update","data":[{"symbol":"BCH/USDT","bids":[{"price":461.34,"qty":0.00000000},{"price":460.06,"qty":2.42000000}],"asks":[],"checksum":1893621385,"timestamp":"2024-06-01T17:52:37.230294Z"}]}
{"channel":"book","type":"update","data":[{"symbol":"BCH/USDT","bids":[{"price":461.36,"qty":0.00000000},{"price":459.93,"qty":1.22000000}],"asks":[],"checksum":3997370789,"timestamp":"2024-06-01T17:52:37.230482Z"}]}
{"channel":"book","type":"update","data":[{"symbol":"BCH/USDT","bids":[{"price":461.22,"qty":3.80879832}],"asks":[],"checksum":2463619771,"timestamp":"2024-06-01T17:52:37.452993Z"}]}
{"channel":"book","type":"update","data":[{"symbol":"BCH/USDT","bids":[],"asks":[{"price":461.65,"qty":3.80879832}],"checksum":2090766505,"timestamp":"2024-06-01T17:52:37.453143Z"}]}
{"channel":"book","type":"update","data":[{"symbol":"BCH/USDT","bids":[],"asks":[{"price":461.90,"qty":0.00000000},{"price":462.17,"qty":0.08972479}],"checksum":1171175110,"timestamp":"2024-06-01T17:52:37.455776Z"}]}
{"channel":"book","type":"update","data":[{"symbol":"BCH/USDT","bids":[{"price":461.23,"qty":7.83392088}],"asks":[],"checksum":3125886107,"timestamp":"2024-06-01T17:52:37.456689Z"}]}
{"channel":"book","type":"update","data":[{"symbol":"BCH/USDT","bids":[{"price":461.23,"qty":10.83392088}],"asks":[],"checksum":1467638539,"timestamp":"2024-06-01T17:52:37.457634Z"}]}
{"channel":"book","type":"update","data":[{"symbol":"BCH/USDT","bids":[{"price":461.23,"qty":11.73392088}],"asks":[],"checksum":307001271,"timestamp":"2024-06-01T17:52:37.457752Z"}]}
{"channel":"book","type":"update","data":[{"symbol":"BCH/USDT","bids":[],"asks":[{"price":461.79,"qty":0.00000000},{"price":462.18,"qty":0.06585657}],"checksum":656563357,"timestamp":"2024-06-01T17:52:37.457933Z"}]}
{"channel":"book","type":"update","data":[{"symbol":"BCH/USDT","bids":[],"asks":[{"price":461.70,"qty":0.23847891}],"checksum":617342504,"timestamp":"2024-06-01T17:52:37.458751Z"}]}
{"channel":"book","type":"update","data":[{"symbol":"BCH/USDT","bids":[{"price":461.21,"qty":0.00000000},{"price":460.06,"qty":2.42000000}],"asks":[],"checksum":1353353200,"timestamp":"2024-06-01T17:52:37.461266Z"}]}
{"channel":"book","type":"update","data":[{"symbol":"BCH/USDT","bids":[],"asks":[{"price":461.64,"qty":0.90000000}],"checksum":744553835,"timestamp":"2024-06-01T17:52:37.588592Z"}]}
{"channel":"book","type":"update","data":[{"symbol":"BCH/USDT","bids":[],"asks":[{"price":461.66,"qty":0.00000000},{"price":462.17,"qty":0.08972479}],"checksum":3166594354,"timestamp":"2024-06-01T17:52:37.593602Z"}]}
{"channel":"book","type":"update","data":[{"symbol":"BCH/USDT","bids":[{"price":461.24,"qty":3.80879832}],"asks":[],"checksum":3659043086,"timestamp":"2024-06-01T17:52:37.594318Z"}]}
{"channel":"book","type":"update","data":[{"symbol":"BCH/USDT","bids":[],"asks":[{"price":461.69,"qty":3.00000000}],"checksum":3125699668,"timestamp":"2024-06-01T17:52:37.594398Z"}]}
{"channel":"book","type":"update","data":[{"symbol":"BCH/USDT","bids":[],"asks":[{"price":461.78,"qty":0.00000000},{"price":462.17,"qty":0.08972479}],"checksum":1698068407,"timestamp":"2024-06-01T17:52:37.709143Z"}]}
{"channel":"book","type":"update","data":[{"symbol":"BCH/USDT","bids":[{"price":461.25,"qty":3.00000000}],"asks":[],"checksum":3124899087,"timestamp":"2024-06-01T17:52:37.709426Z"}]}
{"channel":"book","type":"update","data":[{"symbol":"BCH/USDT","bids":[{"price":461.26,"qty":7.83392088}],"asks":[],"checksum":864878512,"timestamp":"2024-06-01T17:52:37.713540Z"}]}
{"channel":"book","type":"update","data":[{"symbol":"BCH/USDT","bids":[{"price":461.24,"qty":0.00000000},{"price":460.32,"qty":2.61000000}],"asks":[],"checksum":3264898234,"timestamp":"2024-06-01T17:52:37.713917Z"}]}
{"channel":"book","type":"update","data":[{"symbol":"BCH/USDT","bids":[{"price":461.23,"qty":8.73392088}],"asks":[],"checksum":4126254347,"timestamp":"2024-06-01T17:52:37.714030Z"}]}
{"channel":"book","type":"update","data":[{"symbol":"BCH/USDT","bids":[{"price":461.26,"qty":8.73392088}],"asks":[],"checksum":2087266484,"timestamp":"2024-06-01T17:52:37.715153Z"}]}
{"channel":"book","type":"update","data":[{"symbol":"BCH/USDT","bids":[],"asks":[{"price":461.69,"qty":0.00000000},{"price":462.18,"qty":0.06585657}],"checksum":1505617771,"timestamp":"2024-06-01T17:52:37.997348Z"}]}
{"channel":"book","type":"update","data":[{"symbol":"BCH/USDT","bids":[],"asks":[{"price":461.65,"qty":0.00000000},{"price":462.25,"qty":1.36603240}],"checksum":968167270,"timestamp":"2024-06-01T17:52:38.002142Z"}]}
{"channel":"book","type":"update","data":[{"symbol":"BCH/USDT","bids":[],"asks":[{"price":461.64,"qty":0.00000000},{"price":462.40,"qty":1.13708000}],"checksum":3711957538,"timestamp":"2024-06-01T17:52:38.002302Z"}]}
{"channel":"book","type":"update","data":[{"symbol":"BCH/USDT","bids":[],"asks":[{"price":461.70,"qty":0.00000000},{"price":462.45,"qty":4.78432880}],"checksum":2629072951,"timestamp":"2024-06-01T17:52:38.012282Z"}]}
{"channel":"book","type":"update","data":[{"symbol":"BCH/USDT","bids":[{"price":461.23,"qty":0.90000000}],"asks":[],"checksum":3756274023,"timestamp":"2024-06-01T17:52:38.016986Z"}]}
{"channel":"book","type":"update","data":[{"symbol":"BCH/USDT","bids":[],"asks":[{"price":461.64,"qty":7.83392088}],"checksum":1507572523,"timestamp":"2024-06-01T17:52:38.017135Z"}]}
{"channel":"book","type":"update","data":[{"symbol":"BCH/USDT","bids":[],"asks":[{"price":461.80,"qty":1.99322891}],"checksum":450893760,"timestamp":"2024-06-01T17:52:38.019487Z"}]}
{"channel":"book","type":"update","data":[{"symbol":"BCH/USDT","bids":[],"asks":[{"price":461.79,"qty":2.58370377}],"checksum":1512270813,"timestamp":"2024-06-01T17:52:38.023297Z"}]}
{"channel":"book","type":"update","data":[{"symbol":"BCH/USDT","bids":[],"asks":[{"price":461.84,"qty":0.00000000},{"price":462.25,"qty":1.36603240}],"checksum":2967254039,"timestamp":"2024-06-01T17:52:38.023563Z"}]}
{"channel":"book","type":"update","data":[{"symbol":"BCH/USDT","bids":[],"asks":[{"price":461.64,"qty":0.00000000},{"price":462.40,"qty":1.13708000}],"checksum":985649828,"timestamp":"2024-06-01T17:52:38.029704Z"}]}
{"channel":"book","type":"update","data":[{"symbol":"BCH/USDT","bids":[],"asks":[{"price":461.78,"qty":7.83392088}],"checksum":4077107959,"timestamp":"2024-06-01T17:52:38.029959Z"}]}
{"channel":"book","type":"update","data":[{"symbol":"BCH/USDT","bids":[{"price":461.27,"qty":3.80879832}],"asks":[],"checksum":3574810482,"timestamp":"2024-06-01T17:52:38.030244Z"}]}
{"channel":"book","type":"update","data":[{"symbol":"BCH/USDT","bids":[{"price":461.23,"qty":0.00000000},{"price":460.32,"qty":2.61000000}],"asks":[],"checksum":2163235535,"timestamp":"2024-06-01T17:52:38.031331Z"}]}
{"channel":"book","type":"update","data":[{"symbol":"BCH/USDT","bids":[{"price":461.27,"qty":6.80879832}],"asks":[],"checksum":608926979,"timestamp":"2024-06-01T17:52:38.037979Z"}]}
{"channel":"book","type":"update","data":[{"symbol":"BCH/USDT","bids":[{"price":461.28,"qty":1.47168491}],"asks":[],"checksum":1639892937,"timestamp":"2024-06-01T17:52:38.047284Z"}]}
{"channel":"book","type":"update","data":[{"symbol":"BCH/USDT","bids":[{"price":461.29,"qty":0.90000000}],"asks":[],"checksum":562096415,"timestamp":"2024-06-01T17:52:38.088634Z"}]}
{"channel":"book","type":"update","data":[{"symbol":"BCH/USDT","bids":[{"price":461.29,"qty":8.73392088}],"asks":[],"checksum":3040881051,"timestamp":"2024-06-01T17:52:38.092685Z"}]}
{"channel":"book","type":"update","data":[{"symbol":"BCH/USDT","bids":[{"price":461.28,"qty":0.00000000},{"price":460.57,"qty":1.19000000}],"asks":[],"checksum":2077457788,"timestamp":"2024-06-01T17:52:38.093222Z"}]}
{"channel":"book","type":"update","data":[{"symbol":"BCH/USDT","bids":[{"price":461.30,"qty":1.18843991}],"asks":[],"checksum":4214079382,"timestamp":"2024-06-01T17:52:38.093326Z"}]}
{"channel":"book","type":"update","data":[{"symbol":"BCH/USDT","bids":[{"price":461.25,"qty":0.00000000},{"price":460.57,"qty":1.19000000}],"asks":[],"checksum":1738334290,"timestamp":"2024-06-01T17:52:38.093790Z"}]}
{"channel":"book","type":"update","data":[{"symbol":"BCH/USDT","bids":[{"price":461.29,"qty":11.73392088}],"asks":[],"checksum":753657621,"timestamp":"2024-06-01T17:52:38.093814Z"}]}
{"channel":"book","type":"update","data":[{"symbol":"BCH/USDT","bids":[{"price":461.26,"qty":7.83392088}],"asks":[],"checksum":1142901914,"timestamp":"2024-06-01T17:52:38.094350Z"}]}
{"channel":"book","type":"update","data":[{"symbol":"BCH/USDT","bids":[{"price":461.22,"qty":0.00000000},{"price":460.32,"qty":2.61000000}],"asks":[],"checksum":3606103805,"timestamp":"2024-06-01T17:52:38.094743Z"}]}
{"channel":"book","type":"update","data":[{"symbol":"BCH/USDT","bids":[{"price":461.30,"qty":4.99723823}],"asks":[],"checksum":142269519,"timestamp":"2024-06-01T17:52:38.094928Z"}]}
{"channel":"book","type":"update","data":[{"symbol":"BCH/USDT","bids":[{"price":461.31,"qty":3.00000000}],"asks":[],"checksum":602561964,"timestamp":"2024-06-01T17:52:38.210339Z"}]}
{"channel":"book","type":"update","data":[{"symbol":"BCH/USDT","bids":[{"price":461.27,"qty":3.80879832}],"asks":[],"checksum":1939403353,"timestamp":"2024-06-01T17:52:38.210355Z"}]}
{"channel":"book","type":"update","data":[{"symbol":"BCH/USDT","bids":[],"asks":[{"price":461.77,"qty":3.00000000}],"checksum":2961550491,"timestamp":"2024-06-01T17:52:38.210376Z"}]}
{"channel":"book","type":"update","data":[{"symbol":"BCH/USDT","bids":[{"price":461.26,"qty":0.00000000},{"price":460.32,"qty":2.61000000}],"asks":[],"checksum":1085204818,"timestamp":"2024-06-01T17:52:38.214131Z"}]}
{"channel":"book","type":"update","data":[{"symbol":"BCH/USDT","bids":[{"price":461.29,"qty":8.73392088}],"asks":[],"checksum":1417500564,"timestamp":"2024-06-01T17:52:38.214904Z"}]}
{"channel":"book","type":"update","data":[{"symbol":"BCH/USDT","bids":[{"price":461.30,"qty":3.80879832}],"asks":[],"checksum":4275188501,"timestamp":"2024-06-01T17:52:38.215197Z"}]}
{"channel":"book","type":"update","data":[{"symbol":"BCH/USDT","bids":[{"price":461.32,"qty":1.12169103}],"asks":[],"checksum":1947439360,"timestamp":"2024-06-01T17:52:38.215364Z"}]}
{"channel":"book","type":"update","data":[{"symbol":"BCH/USDT","bids":[{"price":461.32,"qty":2.02169103}],"asks":[],"checksum":3164601189,"timestamp":"2024-06-01T17:52:38.215571Z"}]}
{"channel":"book","type":"update","data":[{"symbol":"BCH/USDT","bids":[{"price":461.27,"qty":0.00000000},{"price":460.32,"qty":2.61000000}],"asks":[],"checksum":2434653526,"timestamp":"2024-06-01T17:52:38.215681Z"}]}
{"channel":"book","type":"update","data":[{"symbol":"BCH/USDT","bids":[{"price":461.32,"qty":5.83048935}],"asks":[],"checksum":2177428855,"timestamp":"2024-06-01T17:52:38.215870Z"}]}
{"channel":"book","type":"update","data":[{"symbol":"BCH/USDT","bids":[],"asks":[{"price":461.66,"qty":0.90000000}],"checksum":241182321,"timestamp":"2024-06-01T17:52:38.215897Z"}]}
{"channel":"book","type":"update","data":[{"symbol":"BCH/USDT","bids":[],"asks":[{"price":461.79,"qty":6.39250209}],"checksum":4206655437,"timestamp":"2024-06-01T17:52:38.215961Z"}]}
{"channel":"book","type":"update","data":[{"symbol":"BCH/USDT","bids":[{"price":461.30,"qty":0.00000000},{"price":460.24,"qty":1.36603240}],"asks":[],"checksum":2507511818,"timestamp":"2024-06-01T17:52:38.450808Z"}]}
{"channel":"book","type":"update","data":[{"symbol":"BCH/USDT","bids":[{"price":461.32,"qty":4.70879832}],"asks":[],"checksum":1561913736,"timestamp":"2024-06-01T17:52:38.451452Z"}]}
{"channel":"book","type":"update","data":[{"symbol":"BCH/USDT","bids":[{"price":461.33,"qty":7.83392088}],"asks":[],"checksum":3285807259,"timestamp":"2024-06-01T17:52:38.455125Z"}]}
{"channel":"book","type":"update","data":[{"symbol":"BCH/USDT","bids":[{"price":461.29,"qty":7.83392088}],"asks":[],"checksum":2871909140,"timestamp":"2024-06-01T17:52:38.455493Z"}]}
{"channel":"book","type":"update","data":[{"symbol":"BCH/USDT","bids":[{"price":461.31,"qty":0.00000000},{"price":460.24,"qty":1.36603240}],"asks":[],"checksum":4261036531,"timestamp":"2024-06-01T17:52:38.456453Z"}]}
{"channel":"book","type":"update","data":[{"symbol":"BCH/USDT","bids":[{"price":461.29,"qty":0.00000000},{"price":460.06,"qty":2.42000000}],"asks":[],"checksum":2129702280,"timestamp":"2024-06-01T17:52:38.510292Z"}]}
{"channel":"book","type":"update","data":[{"symbol":"BCH/USDT","bids":[{"price":461.34,"qty":0.90000000}],"asks":[],"checksum":2866413942,"timestamp":"2024-06-01T17:52:38.515441Z"}]}
{"channel":"book","type":"update","data":[{"symbol":"BCH/USDT","bids":[{"price":461.34,"qty":4.70879832}],"asks":[],"checksum":2617735041,"timestamp":"2024-06-01T17:52:38.519464Z"}]}
{"channel":"book","type":"update","data":[{"symbol":"BCH/USDT","bids":[{"price":461.32,"qty":3.80879832}],"asks":[],"checksum":601968184,"timestamp":"2024-06-01T17:52:38.589614Z"}]}
{"channel":"book","type":"update","data":[{"symbol":"BCH/USDT","bids":[{"price":461.32,"qty":0.00000000},{"price":460.06,"qty":2.42000000}],"asks":[],"checksum":3719979897,"timestamp":"2024-06-01T17:52:38.594448Z"}]}
{"channel":"book","type":"update","data":[{"symbol":"BCH/USDT","bids":[{"price":461.35,"qty":7.83392088}],"asks":[],"checksum":3088061768,"timestamp":"2024-06-01T17:52:38.594741Z"}]}
{"channel":"book","type":"update","data":[{"symbol":"BCH/USDT","bids":[{"price":461.33,"qty":0.00000000},{"price":460.06,"qty":2.42000000}],"asks":[],"checksum":741963500,"timestamp":"2024-06-01T17:52:39.021312Z"}]}
{"channel":"book","type":"update","data":[{"symbol":"BCH/USDT","bids":[{"price":461.31,"qty":3.00000000}],"asks":[],"checksum":2199697717,"timestamp":"2024-06-01T17:52:39.026145Z"}]}
{"channel":"book","type":"update","data":[{"symbol":"BCH/USDT","bids":[{"price":461.36,"qty":0.90000000}],"asks":[],"checksum":1936221216,"timestamp":"2024-06-01T17:52:39.027588Z"}]}
{"channel":"book","type":"update","data":[{"symbol":"BCH/USDT","bids":[{"price":461.34,"qty":3.80879832}],"asks":[],"checksum":3431882137,"timestamp":"2024-06-01T17:52:39.088537Z"}]}
{"channel":"book","type":"update","data":[{"symbol":"BCH/USDT","bids":[],"asks":[{"price":461.78,"qty":0.00000000},{"price":462.18,"qty":0.06585657}],"checksum":2287020085,"timestamp":"2024-06-01T17:52:39.510239Z"}]}
{"channel":"book","type":"update","data":[{"symbol":"BCH/USDT","bids":[],"asks":[{"price":461.77,"qty":0.00000000},{"price":462.25,"qty":1.36603240}],"checksum":3533139821,"timestamp":"2024-06-01T17:52:39.515028Z"}]}
{"channel":"book","type":"update","data":[{"symbol":"BCH/USDT","bids":[],"asks":[{"price":461.78,"qty":3.00000000}],"checksum":4099566077,"timestamp":"2024-06-01T17:52:39.515136Z"}]}
{"channel":"book","type":"update","data":[{"symbol":"BCH/USDT","bids":[],"asks":[{"price":461.77,"qty":7.83392088}],"checksum":1365119241,"timestamp":"2024-06-01T17:52:41.013190Z"}]}
{"channel":"book","type":"update","data":[{"symbol":"BCH/USDT","bids":[],"asks":[{"price":461.76,"qty":3.00000000}],"checksum":1765525989,"timestamp":"2024-06-01T17:52:41.018670Z"}]}
{"channel":"book","type":"update","data":[{"symbol":"BCH/USDT","bids":[],"asks":[{"price":461.78,"qty":0.00000000},{"price":462.17,"qty":0.08972479}],"checksum":3704726706,"timestamp":"2024-06-01T17:52:41.208667Z"}]}
{"channel":"book","type":"update","data":[{"symbol":"BCH/USDT","bids":[],"asks":[{"price":461.77,"qty":0.00000000},{"price":462.18,"qty":0.06585657}],"checksum":2137833012,"timestamp":"2024-06-01T17:52:42.513218Z"}]}
{"channel":"book","type":"update","data":[{"symbol":"BCH/USDT","bids":[],"asks":[{"price":461.76,"qty":0.00000000},{"price":462.25,"qty":1.36603240}],"checksum":3533139821,"timestamp":"2024-06-01T17:52:42.520021Z"}]}
{"channel":"book","type":"update","data":[{"symbol":"BCH/USDT","bids":[],"asks":[{"price":461.78,"qty":3.00000000}],"checksum":4099566077,"timestamp":"2024-06-01T17:52:42.520262Z"}]}
{"channel":"book","type":"update","data":[{"symbol":"BCH/USDT","bids":[],"asks":[{"price":461.77,"qty":7.83392088}],"checksum":1365119241,"timestamp":"2024-06-01T17:52:44.021613Z"}]}
{"channel":"book","type":"update","data":[{"symbol":"BCH/USDT","bids":[],"asks":[{"price":461.76,"qty":3.00000000}],"checksum":1765525989,"timestamp":"2024-06-01T17:52:44.026983Z"}]}
{"channel":"book","type":"update","data":[{"symbol":"BCH/USDT","bids":[],"asks":[{"price":461.78,"qty":0.00000000},{"price":462.17,"qty":0.08972479}],"checksum":3704726706,"timestamp":"2024-06-01T17:52:44.209654Z"}]}
{"channel":"book","type":"update","data":[{"symbol":"BCH/USDT","bids":[],"asks":[{"price":461.77,"qty":0.00000000},{"price":462.18,"qty":0.06585657}],"checksum":2137833012,"timestamp":"2024-06-01T17:52:45.509603Z"}]}
{"channel":"book","type":"update","data":[{"symbol":"BCH/USDT","bids":[],"asks":[{"price":461.76,"qty":0.00000000},{"price":462.25,"qty":1.36603240}],"checksum":3533139821,"timestamp":"2024-06-01T17:52:45.514312Z"}]}
{"channel":"book","type":"update","data":[{"symbol":"BCH/USDT","bids":[],"asks":[{"price":461.78,"qty":3.00000000}],"checksum":4099566077,"timestamp":"2024-06-01T17:52:45.514370Z"}]}
{"channel":"book","type":"update","data":[{"symbol":"BCH/USDT","bids":[],"asks":[{"price":461.77,"qty":7.83392088}],"checksum":1365119241,"timestamp":"2024-06-01T17:52:47.016277Z"}]}
{"channel":"book","type":"update","data":[{"symbol":"BCH/USDT","bids":[],"asks":[{"price":461.76,"qty":3.00000000}],"checksum":1765525989,"timestamp":"2024-06-01T17:52:47.021628Z"}]}
{"channel":"book","type":"update","data":[{"symbol":"BCH/USDT","bids":[],"asks":[{"price":461.78,"qty":0.00000000},{"price":462.17,"qty":0.08972479}],"checksum":3704726706,"timestamp":"2024-06-01T17:52:47.211520Z"}]}
{"channel":"book","type":"update","data":[{"symbol":"BCH/USDT","bids":[{"price":461.37,"qty":1.85037566}],"asks":[],"checksum":1324310960,"timestamp":"2024-06-01T17:52:47.750263Z"}]}
{"channel":"book","type":"update","data":[{"symbol":"BCH/USDT","bids":[{"price":461.20,"qty":0.00000000},{"price":460.32,"qty":2.61000000}],"asks":[],"checksum":112584654,"timestamp":"2024-06-01T17:52:47.753113Z"}]}
{"channel":"book","type":"update","data":[{"symbol":"BCH/USDT","bids":[{"price":461.38,"qty":0.90000000}],"asks":[],"checksum":3042524161,"timestamp":"2024-06-01T17:52:47.755433Z"}]}
{"channel":"book","type":"update","data":[{"symbol":"BCH/USDT","bids":[{"price":461.30,"qty":1.60656937}],"asks":[],"checksum":357805034,"timestamp":"2024-06-01T17:52:47.755868Z"}]}
{"channel":"book","type":"update","data":[{"symbol":"BCH/USDT","bids":[{"price":461.38,"qty":8.73392088}],"asks":[],"checksum":27269735,"timestamp":"2024-06-01T17:52:47.756167Z"}]}
{"channel":"book","type":"update","data":[{"symbol":"BCH/USDT","bids":[{"price":461.37,"qty":0.00000000},{"price":460.57,"qty":1.19000000}],"asks":[],"checksum":2091902961,"timestamp":"2024-06-01T17:52:47.855155Z"}]}
{"channel":"book","type":"update","data":[{"symbol":"BCH/USDT","bids":[],"asks":[{"price":461.77,"qty":0.00000000},{"price":462.18,"qty":0.06585657}],"checksum":3742563703,"timestamp":"2024-06-01T17:52:47.858976Z"}]}
{"channel":"book","type":"update","data":[{"symbol":"BCH/USDT","bids":[{"price":461.38,"qty":0.90000000}],"asks":[],"checksum":1766237214,"timestamp":"2024-06-01T17:52:47.859064Z"}]}
{"channel":"book","type":"update","data":[{"symbol":"BCH/USDT","bids":[{"price":461.38,"qty":0.00000000},{"price":460.32,"qty":2.61000000}],"asks":[],"checksum":2421772418,"timestamp":"2024-06-01T17:52:47.859658Z"}]}
{"channel":"book","type":"update","data":[{"symbol":"BCH/USDT","bids":[{"price":461.37,"qty":1.33867091}],"asks":[],"checksum":3898976679,"timestamp":"2024-06-01T17:52:47.863739Z"}]}
{"channel":"book","type":"update","data":[{"symbol":"BCH/USDT","bids":[{"price":461.38,"qty":7.83392088}],"asks":[],"checksum":2869401754,"timestamp":"2024-06-01T17:52:48.013821Z"}]}
{"channel":"book","type":"update","data":[{"symbol":"BCH/USDT","bids":[],"asks":[{"price":461.75,"qty":7.83392088}],"checksum":4218832708,"timestamp":"2024-06-01T17:52:48.014025Z"}]}
{"channel":"book","type":"update","data":[{"symbol":"BCH/USDT","bids":[{"price":461.35,"qty":0.00000000},{"price":460.57,"qty":1.19000000}],"asks":[],"checksum":682442555,"timestamp":"2024-06-01T17:52:48.018084Z"}]}
{"channel":"book","type":"update","data":[{"symbol":"BCH/USDT","bids":[{"price":461.39,"qty":0.90000000}],"asks":[],"checksum":250029823,"timestamp":"2024-06-01T17:52:48.019085Z"}]}
{"channel":"book","type":"update","data":[{"symbol":"BCH/USDT","bids":[{"price":461.36,"qty":0.00000000},{"price":460.57,"qty":1.19000000}],"asks":[],"checksum":2317874249,"timestamp":"2024-06-01T17:52:48.087766Z"}]}
{"channel":"book","type":"update","data":[{"symbol":"BCH/USDT","bids":[{"price":461.37,"qty":0.00000000},{"price":460.32,"qty":2.61000000}],"asks":[],"checksum":354164071,"timestamp":"2024-06-01T17:52:48.667531Z"}]}
{"channel":"book","type":"update","data":[{"symbol":"BCH/USDT","bids":[{"price":461.38,"qty":0.00000000},{"price":460.24,"qty":1.36603240}],"asks":[],"checksum":3015124777,"timestamp":"2024-06-01T17:52:48.671670Z"}]}
{"channel":"book","type":"update","data":[{"symbol":"BCH/USDT","bids":[{"price":461.35,"qty":7.83392088}],"asks":[],"checksum":4136952137,"timestamp":"2024-06-01T17:52:48.671746Z"}]}
{"channel":"book","type":"update","data":[{"symbol":"BCH/USDT","bids":[{"price":461.32,"qty":1.42251047}],"asks":[],"checksum":1041668291,"timestamp":"2024-06-01T17:52:48.676081Z"}]}
{"channel":"book","type":"update","data":[{"symbol":"BCH/USDT","bids":[{"price":461.32,"qty":0.00000000},{"price":460.32,"qty":2.61000000}],"asks":[],"checksum":4136952137,"timestamp":"2024-06-01T17:52:48.680233Z"}]}
{"channel":"book","type":"update","data":[{"symbol":"BCH/USDT","bids":[{"price":461.36,"qty":1.68202218}],"asks":[],"checksum":578466289,"timestamp":"2024-06-01T17:52:49.070502Z"}]}
{"channel":"book","type":"update","data":[{"symbol":"BCH/USDT","bids":[{"price":461.37,"qty":7.83392088}],"asks":[],"checksum":3021021342,"timestamp":"2024-06-01T17:52:49.075760Z"}]}
{"channel":"book","type":"update","data":[{"symbol":"BCH/USDT","bids":[{"price":461.39,"qty":0.00000000},{"price":460.57,"qty":1.19000000}],"asks":[],"checksum":965300138,"timestamp":"2024-06-01T17:52:49.075913Z"}]}
{"channel":"book","type":"update","data":[{"symbol":"BCH/USDT","bids":[{"price":461.37,"qty":8.73392088}],"asks":[],"checksum":2953953813,"timestamp":"2024-06-01T17:52:49.076099Z"}]}
{"channel":"book","type":"update","data":[{"symbol":"BCH/USDT","bids":[{"price":461.36,"qty":0.00000000},{"price":460.32,"qty":2.61000000}],"asks":[],"checksum":1694470829,"timestamp":"2024-06-01T17:52:49.080292Z"}]}
{"channel":"book","type":"update","data":[{"symbol":"BCH/USDT","bids":[{"price":461.38,"qty":1.75840291}],"asks":[],"checksum":158771708,"timestamp":"2024-06-01T17:52:49.080472Z"}]}
{"channel":"book","type":"update","data":[{"symbol":"BCH/USDT","bids":[{"price":461.39,"qty":0.90000000}],"asks":[],"checksum":2195643881,"timestamp":"2024-06-01T17:52:49.090329Z"}]}
{"channel":"book","type":"update","data":[{"symbol":"BCH/USDT","bids":[{"price":461.35,"qty":0.00000000},{"price":460.57,"qty":1.19000000}],"asks":[],"checksum":1359324566,"timestamp":"2024-06-01T17:52:49.510396Z"}]}
{"channel":"book","type":"update","data":[{"symbol":"BCH/USDT","bids":[{"price":461.37,"qty":7.83392088}],"asks":[],"checksum":3718483413,"timestamp":"2024-06-01T17:52:49.515173Z"}]}
{"channel":"book","type":"update","data":[{"symbol":"BCH/USDT","bids":[{"price":461.39,"qty":8.73392088}],"asks":[],"checksum":3591176466,"timestamp":"2024-06-01T17:52:50.012696Z"}]}
{"channel":"book","type":"update","data":[{"symbol":"BCH/USDT","bids":[{"price":461.37,"qty":0.00000000},{"price":460.32,"qty":2.61000000}],"asks":[],"checksum":3013335256,"timestamp":"2024-06-01T17:52:50.016434Z"}]}
{"channel":"book","type":"update","data":[{"symbol":"BCH/USDT","bids":[{"price":461.38,"qty":0.00000000},{"price":460.24,"qty":1.36603240}],"asks":[],"checksum":3088690158,"timestamp":"2024-06-01T17:52:50.324209Z"}]}
{"channel":"book","type":"update","data":[{"symbol":"BCH/USDT","bids":[{"price":461.39,"qty":0.90000000}],"asks":[],"checksum":3015124777,"timestamp":"2024-06-01T17:52:50.328142Z"}]}
