{"channel":"book","type":"snapshot","data":[{"symbol":"BTC/JPY","bids":[{"price":10608535,"qty":0.02979585},{"price":10601924,"qty":0.01173553},{"price":10601923,"qty":0.00031910},{"price":10598802,"qty":0.50757127},{"price":10598800,"qty":0.00011000},{"price":10594031,"qty":1.21219667},{"price":10591924,"qty":0.26132317},{"price":10586622,"qty":0.48668914},{"price":10576939,"qty":0.48668914},{"price":10576323,"qty":2.42596995}],"asks":[{"price":10650696,"qty":0.00039296},{"price":10654499,"qty":0.03545983},{"price":10664636,"qty":0.01129070},{"price":10664637,"qty":0.14777643},{"price":10664638,"qty":0.26132317},{"price":10671930,"qty":0.48668914},{"price":10676635,"qty":1.21286958},{"price":10676729,"qty":0.48668914},{"price":10680108,"qty":1.31226123},{"price":10691000,"qty":0.00010000}],"checksum":1711124827}]}
{"channel":"book","type":"update","data":[{"symbol":"BTC/JPY","bids":[{"price":10601923,"qty":0.00000000},{"price":10564392,"qty":1.31226123}],"asks":[],"checksum":4158371563,"timestamp":"2024-06-01T17:51:32.396259Z"}]}
{"channel":"book","type":"update","data":[{"symbol":"BTC/JPY","bids":[{"price":10598803,"qty":0.01173899}],"asks":[],"checksum":545973258,"timestamp":"2024-06-01T17:51:32.401915Z"}]}
{"channel":"book","type":"update","data":[{"symbol":"BTC/JPY","bids":[{"price":10601924,"qty":0.00000000},{"price":10564392,"qty":1.31226123}],"asks":[],"checksum":1816509037,"timestamp":"2024-06-01T17:51:32.402092Z"}]}
{"channel":"book","type":"update","data":[{"symbol":"BTC/JPY","bids":[],"asks":[{"price":10664635,"qty":0.00529390}],"checksum":3887607444,"timestamp":"2024-06-01T17:51:32.434417Z"}]}
{"channel":"book","type":"update","data":[{"symbol":"BTC/JPY","bids":[{"price":10601923,"qty":0.00031913}],"asks":[],"checksum":4008362046,"timestamp":"2024-06-01T17:51:32.491601Z"}]}
{"channel":"book","type":"update","data":[{"symbol":"BTC/JPY","bids":[],"asks":[{"price":10664637,"qty":0.00000000},{"price":10691000,"qty":0.00010000},{"price":10664637,"qty":0.13373062}],"checksum":493520784,"timestamp":"2024-06-01T17:51:32.538272Z"}]}
{"channel":"book","type":"update","data":[{"symbol":"BTC/JPY","bids":[],"asks":[{"price":10654499,"qty":0.00000000},{"price":10691000,"qty":0.00010000},{"price":10649880,"qty":0.03545983}],"checksum":4016138368,"timestamp":"2024-06-01T17:51:32.788373Z"}]}
{"channel":"book","type":"update","data":[{"symbol":"BTC/JPY","bids":[{"price":10576939,"qty":0.00000000},{"price":10556415,"qty":0.00012369}],"asks":[],"checksum":2022125953,"timestamp":"2024-06-01T17:51:33.438158Z"}]}
{"channel":"book","type":"update","data":[{"symbol":"BTC/JPY","bids":[{"price":10576940,"qty":0.48668914}],"asks":[],"checksum":2407572781,"timestamp":"2024-06-01T17:51:33.440981Z"}]}
{"channel":"book","type":"update","data":[{"symbol":"BTC/JPY","bids":[],"asks":[{"price":10664635,"qty":0.00000000},{"price":10691000,"qty":0.00010000}],"checksum":3317227610,"timestamp":"2024-06-01T17:51:34.480672Z"}]}
{"channel":"book","type":"update","data":[{"symbol":"BTC/JPY","bids":[],"asks":[{"price":10664635,"qty":0.00529399}],"checksum":1707551365,"timestamp":"2024-06-01T17:51:36.204432Z"}]}
{"channel":"book","type":"update","data":[{"symbol":"BTC/JPY","bids":[{"price":10594031,"qty":0.00000000},{"price":10564393,"qty":1.31226123}],"asks":[],"checksum":55871661,"timestamp":"2024-06-01T17:51:39.472811Z"}]}
{"channel":"book","type":"update","data":[{"symbol":"BTC/JPY","bids":[{"price":10576323,"qty":0.00000000},{"price":10556415,"qty":0.00012369}],"asks":[],"checksum":359089186,"timestamp":"2024-06-01T17:51:39.472833Z"}]}
{"channel":"book","type":"update","data":[{"symbol":"BTC/JPY","bids":[{"price":10596949,"qty":1.21059373}],"asks":[],"checksum":2542379760,"timestamp":"2024-06-01T17:51:39.513081Z"}]}
{"channel":"book","type":"update","data":[{"symbol":"BTC/JPY","bids":[{"price":10584185,"qty":2.42118746}],"asks":[],"checksum":4092199775,"timestamp":"2024-06-01T17:51:39.513111Z"}]}
{"channel":"book","type":"update","data":[{"symbol":"BTC/JPY","bids":[],"asks":[{"price":10664637,"qty":0.00000000},{"price":10691000,"qty":0.00010000},{"price":10664637,"qty":0.12551596}],"checksum":1194672610,"timestamp":"2024-06-01T17:51:40.671490Z"}]}
{"channel":"book","type":"update","data":[{"symbol":"BTC/JPY","bids":[{"price":10598803,"qty":0.00000000},{"price":10564393,"qty":1.31226123}],"asks":[],"checksum":1256652938,"timestamp":"2024-06-01T17:51:42.145992Z"}]}
{"channel":"book","type":"update","data":[{"symbol":"BTC/JPY","bids":[{"price":10608536,"qty":0.01172822}],"asks":[],"checksum":2615723750,"timestamp":"2024-06-01T17:51:42.146150Z"}]}
{"channel":"book","type":"update","data":[{"symbol":"BTC/JPY","bids":[{"price":10608535,"qty":0.02749960},{"price":10610603,"qty":0.00243353}],"asks":[],"checksum":587339438,"timestamp":"2024-06-01T17:51:42.161305Z"}]}
{"channel":"book","type":"update","data":[{"symbol":"BTC/JPY","bids":[],"asks":[{"price":10664635,"qty":0.00000000},{"price":10691000,"qty":0.00010000}],"checksum":2985215651,"timestamp":"2024-06-01T17:51:43.807825Z"}]}
{"channel":"book","type":"update","data":[{"symbol":"BTC/JPY","bids":[],"asks":[{"price":10676635,"qty":0.00000000},{"price":10693107,"qty":2.42581227}],"checksum":3287708440,"timestamp":"2024-06-01T17:51:47.293839Z"}]}
{"channel":"book","type":"update","data":[{"symbol":"BTC/JPY","bids":[{"price":10608535,"qty":0.00000000},{"price":10576940,"qty":0.48668914}],"asks":[],"checksum":2156939650,"timestamp":"2024-06-01T17:51:47.293851Z"}]}
{"channel":"book","type":"update","data":[{"symbol":"BTC/JPY","bids":[{"price":10608536,"qty":0.00000000},{"price":10564394,"qty":1.31226123}],"asks":[],"checksum":2277034168,"timestamp":"2024-06-01T17:51:47.299680Z"}]}
{"channel":"book","type":"update","data":[{"symbol":"BTC/JPY","bids":[{"price":10601924,"qty":0.01173553}],"asks":[],"checksum":1373370293,"timestamp":"2024-06-01T17:51:47.299746Z"}]}
{"channel":"book","type":"update","data":[{"symbol":"BTC/JPY","bids":[],"asks":[{"price":10680973,"qty":1.21244217}],"checksum":1287626233,"timestamp":"2024-06-01T17:51:47.333960Z"}]}
{"channel":"book","type":"update","data":[{"symbol":"BTC/JPY","bids":[{"price":10610603,"qty":0.02991031}],"asks":[],"checksum":1893825186,"timestamp":"2024-06-01T17:51:47.334098Z"}]}
{"channel":"book","type":"update","data":[{"symbol":"BTC/JPY","bids":[],"asks":[{"price":10664635,"qty":0.00529394}],"checksum":3975846265,"timestamp":"2024-06-01T17:51:48.114665Z"}]}
{"channel":"book","type":"update","data":[{"symbol":"BTC/JPY","bids":[],"asks":[{"price":10664637,"qty":0.00000000},{"price":10691000,"qty":0.00010000},{"price":10671929,"qty":0.16194996}],"checksum":1773600817,"timestamp":"2024-06-01T17:51:48.720180Z"}]}
{"channel":"book","type":"update","data":[{"symbol":"BTC/JPY","bids":[],"asks":[{"price":10664635,"qty":0.00000000},{"price":10691000,"qty":0.00010000}],"checksum":2078873156,"timestamp":"2024-06-01T17:51:49.710199Z"}]}
{"channel":"book","type":"update","data":[{"symbol":"BTC/JPY","bids":[],"asks":[{"price":10664636,"qty":0.00000000},{"price":10693737,"qty":2.42488434}],"checksum":1079984227,"timestamp":"2024-06-01T17:51:50.136031Z"}]}
{"channel":"book","type":"update","data":[{"symbol":"BTC/JPY","bids":[],"asks":[{"price":10671928,"qty":0.01129070}],"checksum":4216934261,"timestamp":"2024-06-01T17:51:50.136170Z"}]}
{"channel":"book","type":"update","data":[{"symbol":"BTC/JPY","bids":[],"asks":[{"price":10671929,"qty":0.00000000},{"price":10693737,"qty":2.42488434},{"price":10671927,"qty":0.15980898}],"checksum":39500470,"timestamp":"2024-06-01T17:51:50.241776Z"}]}
{"channel":"book","type":"update","data":[{"symbol":"BTC/JPY","bids":[],"asks":[{"price":10671928,"qty":0.00000000},{"price":10693737,"qty":2.42488434}],"checksum":3788786636,"timestamp":"2024-06-01T17:51:50.263770Z"}]}
{"channel":"book","type":"update","data":[{"symbol":"BTC/JPY","bids":[],"asks":[{"price":10671926,"qty":0.01129070}],"checksum":2026523061,"timestamp":"2024-06-01T17:51:50.263943Z"}]}
{"channel":"book","type":"update","data":[{"symbol":"BTC/JPY","bids":[],"asks":[{"price":10671927,"qty":0.00000000},{"price":10693737,"qty":2.42488434},{"price":10671925,"qty":0.15978717}],"checksum":1636253633,"timestamp":"2024-06-01T17:51:50.362438Z"}]}
{"channel":"book","type":"update","data":[{"symbol":"BTC/JPY","bids":[],"asks":[{"price":10671926,"qty":0.00000000},{"price":10693737,"qty":2.42488434}],"checksum":3144639399,"timestamp":"2024-06-01T17:51:50.389950Z"}]}
{"channel":"book","type":"update","data":[{"symbol":"BTC/JPY","bids":[],"asks":[{"price":10671924,"qty":0.01129070}],"checksum":3009391861,"timestamp":"2024-06-01T17:51:50.390336Z"}]}
{"channel":"book","type":"update","data":[{"symbol":"BTC/JPY","bids":[],"asks":[{"price":10671925,"qty":0.00000000},{"price":10693737,"qty":2.42488434},{"price":10671923,"qty":0.16101741}],"checksum":700558635,"timestamp":"2024-06-01T17:51:50.463933Z"}]}
{"channel":"book","type":"update","data":[{"symbol":"BTC/JPY","bids":[],"asks":[{"price":10671922,"qty":0.01129070}],"checksum":1894950473,"timestamp":"2024-06-01T17:51:50.474259Z"}]}
{"channel":"book","type":"update","data":[{"symbol":"BTC/JPY","bids":[],"asks":[{"price":10671924,"qty":0.00000000},{"price":10691000,"qty":0.00010000}],"checksum":3709756513,"timestamp":"2024-06-01T17:51:50.474385Z"}]}
{"channel":"book","type":"update","data":[{"symbol":"BTC/JPY","bids":[],"asks":[{"price":10671923,"qty":0.00000000},{"price":10693737,"qty":2.42488434},{"price":10671921,"qty":0.16107785}],"checksum":1083208623,"timestamp":"2024-06-01T17:51:50.522770Z"}]}
{"channel":"book","type":"update","data":[{"symbol":"BTC/JPY","bids":[],"asks":[{"price":10671920,"qty":0.01129070}],"checksum":4220061378,"timestamp":"2024-06-01T17:51:50.539450Z"}]}
{"channel":"book","type":"update","data":[{"symbol":"BTC/JPY","bids":[],"asks":[{"price":10671922,"qty":0.00000000},{"price":10691000,"qty":0.00010000}],"checksum":3274625626,"timestamp":"2024-06-01T17:51:50.539473Z"}]}
{"channel":"book","type":"update","data":[{"symbol":"BTC/JPY","bids":[],"asks":[{"price":10671921,"qty":0.00000000},{"price":10693737,"qty":2.42488434},{"price":10671919,"qty":0.16090626}],"checksum":327214684,"timestamp":"2024-06-01T17:51:50.604992Z"}]}
{"channel":"book","type":"update","data":[{"symbol":"BTC/JPY","bids":[],"asks":[{"price":10671920,"qty":0.00000000},{"price":10693737,"qty":2.42488434}],"checksum":16904290,"timestamp":"2024-06-01T17:51:50.623154Z"}]}
{"channel":"book","type":"update","data":[{"symbol":"BTC/JPY","bids":[],"asks":[{"price":10671918,"qty":0.01129070}],"checksum":2633216310,"timestamp":"2024-06-01T17:51:50.623475Z"}]}
{"channel":"book","type":"update","data":[{"symbol":"BTC/JPY","bids":[],"asks":[{"price":10671919,"qty":0.00000000},{"price":10693737,"qty":2.42488434},{"price":10671917,"qty":0.16092322}],"checksum":844285647,"timestamp":"2024-06-01T17:51:50.677352Z"}]}
{"channel":"book","type":"update","data":[{"symbol":"BTC/JPY","bids":[],"asks":[{"price":10671918,"qty":0.00000000},{"price":10693737,"qty":2.42488434}],"checksum":787105832,"timestamp":"2024-06-01T17:51:50.704637Z"}]}
{"channel":"book","type":"update","data":[{"symbol":"BTC/JPY","bids":[],"asks":[{"price":10671916,"qty":0.01129070}],"checksum":1628057775,"timestamp":"2024-06-01T17:51:50.704899Z"}]}
{"channel":"book","type":"update","data":[{"symbol":"BTC/JPY","bids":[],"asks":[{"price":10671917,"qty":0.00000000},{"price":10693737,"qty":2.42488434},{"price":10671915,"qty":0.16200063}],"checksum":57341190,"timestamp":"2024-06-01T17:51:50.758679Z"}]}
{"channel":"book","type":"update","data":[{"symbol":"BTC/JPY","bids":[],"asks":[{"price":10671914,"qty":0.01129070}],"checksum":3599647090,"timestamp":"2024-06-01T17:51:50.771436Z"}]}
{"channel":"book","type":"update","data":[{"symbol":"BTC/JPY","bids":[],"asks":[{"price":10671916,"qty":0.00000000},{"price":10691000,"qty":0.00010000}],"checksum":807502788,"timestamp":"2024-06-01T17:51:50.771457Z"}]}
{"channel":"book","type":"update","data":[{"symbol":"BTC/JPY","bids":[],"asks":[{"price":10671914,"qty":0.01658467}],"checksum":1781373092,"timestamp":"2024-06-01T17:51:50.794223Z"}]}
{"channel":"book","type":"update","data":[{"symbol":"BTC/JPY","bids":[],"asks":[{"price":10671915,"qty":0.00000000},{"price":10693737,"qty":2.42488434},{"price":10671913,"qty":0.16098075}],"checksum":1378566164,"timestamp":"2024-06-01T17:51:50.850802Z"}]}
{"channel":"book","type":"update","data":[{"symbol":"BTC/JPY","bids":[],"asks":[{"price":10671914,"qty":0.00529397}],"checksum":4219801946,"timestamp":"2024-06-01T17:51:50.876958Z"}]}
{"channel":"book","type":"update","data":[{"symbol":"BTC/JPY","bids":[],"asks":[{"price":10671912,"qty":0.01129070}],"checksum":1099064813,"timestamp":"2024-06-01T17:51:50.877128Z"}]}
{"channel":"book","type":"update","data":[{"symbol":"BTC/JPY","bids":[],"asks":[{"price":10671913,"qty":0.00000000},{"price":10691000,"qty":0.00010000},{"price":10671911,"qty":0.16176891}],"checksum":2135679140,"timestamp":"2024-06-01T17:51:50.932786Z"}]}
{"channel":"book","type":"update","data":[{"symbol":"BTC/JPY","bids":[],"asks":[{"price":10671910,"qty":0.01129070}],"checksum":3944896099,"timestamp":"2024-06-01T17:51:50.955983Z"}]}
{"channel":"book","type":"update","data":[{"symbol":"BTC/JPY","bids":[],"asks":[{"price":10671912,"qty":0.00000000},{"price":10680973,"qty":1.21244217}],"checksum":129661421,"timestamp":"2024-06-01T17:51:50.956040Z"}]}
{"channel":"book","type":"update","data":[{"symbol":"BTC/JPY","bids":[],"asks":[{"price":10671911,"qty":0.00000000},{"price":10691000,"qty":0.00010000},{"price":10671909,"qty":0.16211651}],"checksum":866499195,"timestamp":"2024-06-01T17:51:51.020792Z"}]}
{"channel":"book","type":"update","data":[{"symbol":"BTC/JPY","bids":[],"asks":[{"price":10671910,"qty":0.00000000},{"price":10691000,"qty":0.00010000}],"checksum":3972699354,"timestamp":"2024-06-01T17:51:51.045069Z"}]}
{"channel":"book","type":"update","data":[{"symbol":"BTC/JPY","bids":[],"asks":[{"price":10671908,"qty":0.01129070}],"checksum":2495461393,"timestamp":"2024-06-01T17:51:51.045295Z"}]}
{"channel":"book","type":"update","data":[{"symbol":"BTC/JPY","bids":[],"asks":[{"price":10671909,"qty":0.00000000},{"price":10691000,"qty":0.00010000},{"price":10671907,"qty":0.16207157}],"checksum":1811332766,"timestamp":"2024-06-01T17:51:51.107867Z"}]}
{"channel":"book","type":"update","data":[{"symbol":"BTC/JPY","bids":[],"asks":[{"price":10671906,"qty":0.01129070}],"checksum":2405588727,"timestamp":"2024-06-01T17:51:51.113850Z"}]}
{"channel":"book","type":"update","data":[{"symbol":"BTC/JPY","bids":[],"asks":[{"price":10671908,"qty":0.00000000},{"price":10680973,"qty":1.21244217}],"checksum":254381933,"timestamp":"2024-06-01T17:51:51.113907Z"}]}
{"channel":"book","type":"update","data":[{"symbol":"BTC/JPY","bids":[],"asks":[{"price":10671907,"qty":0.00000000},{"price":10691000,"qty":0.00010000},{"price":10671905,"qty":0.16185414}],"checksum":2114084656,"timestamp":"2024-06-01T17:51:51.178568Z"}]}
{"channel":"book","type":"update","data":[{"symbol":"BTC/JPY","bids":[],"asks":[{"price":10671904,"qty":0.01129070}],"checksum":3999189761,"timestamp":"2024-06-01T17:51:51.187838Z"}]}
{"channel":"book","type":"update","data":[{"symbol":"BTC/JPY","bids":[],"asks":[{"price":10671906,"qty":0.00000000},{"price":10680973,"qty":1.21244217}],"checksum":162867593,"timestamp":"2024-06-01T17:51:51.187987Z"}]}
{"channel":"book","type":"update","data":[{"symbol":"BTC/JPY","bids":[],"asks":[{"price":10671905,"qty":0.00000000},{"price":10691000,"qty":0.00010000},{"price":10671903,"qty":0.15897993}],"checksum":3538118764,"timestamp":"2024-06-01T17:51:51.246230Z"}]}
{"channel":"book","type":"update","data":[{"symbol":"BTC/JPY","bids":[],"asks":[{"price":10671904,"qty":0.00000000},{"price":10691000,"qty":0.00010000}],"checksum":1805475588,"timestamp":"2024-06-01T17:51:51.258965Z"}]}
{"channel":"book","type":"update","data":[{"symbol":"BTC/JPY","bids":[],"asks":[{"price":10671902,"qty":0.01129070}],"checksum":789556179,"timestamp":"2024-06-01T17:51:51.259117Z"}]}
{"channel":"book","type":"update","data":[{"symbol":"BTC/JPY","bids":[],"asks":[{"price":10671903,"qty":0.00000000},{"price":10691000,"qty":0.00010000},{"price":10671901,"qty":0.15912535}],"checksum":1967817169,"timestamp":"2024-06-01T17:51:51.318341Z"}]}
{"channel":"book","type":"update","data":[{"symbol":"BTC/JPY","bids":[],"asks":[{"price":10671900,"qty":0.01129070}],"checksum":3148916053,"timestamp":"2024-06-01T17:51:51.327194Z"}]}
{"channel":"book","type":"update","data":[{"symbol":"BTC/JPY","bids":[],"asks":[{"price":10671902,"qty":0.00000000},{"price":10680973,"qty":1.21244217}],"checksum":627148568,"timestamp":"2024-06-01T17:51:51.327209Z"}]}
{"channel":"book","type":"update","data":[{"symbol":"BTC/JPY","bids":[],"asks":[{"price":10671901,"qty":0.00000000},{"price":10691000,"qty":0.00010000},{"price":10671899,"qty":0.15956254}],"checksum":3336297031,"timestamp":"2024-06-01T17:51:51.390414Z"}]}
{"channel":"book","type":"update","data":[{"symbol":"BTC/JPY","bids":[],"asks":[{"price":10671900,"qty":0.00000000},{"price":10691000,"qty":0.00010000}],"checksum":2274705875,"timestamp":"2024-06-01T17:51:51.400981Z"}]}
{"channel":"book","type":"update","data":[{"symbol":"BTC/JPY","bids":[],"asks":[{"price":10671898,"qty":0.01129070}],"checksum":913305588,"timestamp":"2024-06-01T17:51:51.401154Z"}]}
{"channel":"book","type":"update","data":[{"symbol":"BTC/JPY","bids":[],"asks":[{"price":10671899,"qty":0.00000000},{"price":10691000,"qty":0.00010000},{"price":10671897,"qty":0.16002049}],"checksum":3287964396,"timestamp":"2024-06-01T17:51:51.494530Z"}]}
{"channel":"book","type":"update","data":[{"symbol":"BTC/JPY","bids":[],"asks":[{"price":10671898,"qty":0.00000000},{"price":10691000,"qty":0.00010000}],"checksum":3534643726,"timestamp":"2024-06-01T17:51:51.511696Z"}]}
{"channel":"book","type":"update","data":[{"symbol":"BTC/JPY","bids":[],"asks":[{"price":10671896,"qty":0.01129070}],"checksum":2295562689,"timestamp":"2024-06-01T17:51:51.511982Z"}]}
{"channel":"book","type":"update","data":[{"symbol":"BTC/JPY","bids":[],"asks":[{"price":10671897,"qty":0.00000000},{"price":10691000,"qty":0.00010000},{"price":10671895,"qty":0.16071279}],"checksum":1088668357,"timestamp":"2024-06-01T17:51:51.569081Z"}]}
{"channel":"book","type":"update","data":[{"symbol":"BTC/JPY","bids":[],"asks":[{"price":10671896,"qty":0.00000000},{"price":10691000,"qty":0.00010000}],"checksum":1997365177,"timestamp":"2024-06-01T17:51:51.579120Z"}]}
{"channel":"book","type":"update","data":[{"symbol":"BTC/JPY","bids":[],"asks":[{"price":10671894,"qty":0.01129070}],"checksum":2661821307,"timestamp":"2024-06-01T17:51:51.579471Z"}]}
{"channel":"book","type":"update","data":[{"symbol":"BTC/JPY","bids":[],"asks":[{"price":10671895,"qty":0.00000000},{"price":10691000,"qty":0.00010000},{"price":10671893,"qty":0.16115500}],"checksum":3326116909,"timestamp":"2024-06-01T17:51:51.629562Z"}]}
{"channel":"book","type":"update","data":[{"symbol":"BTC/JPY","bids":[],"asks":[{"price":10671894,"qty":0.00000000},{"price":10691000,"qty":0.00010000}],"checksum":2301288614,"timestamp":"2024-06-01T17:51:51.640665Z"}]}
{"channel":"book","type":"update","data":[{"symbol":"BTC/JPY","bids":[],"asks":[{"price":10671892,"qty":0.01129070}],"checksum":3498118187,"timestamp":"2024-06-01T17:51:51.641698Z"}]}
{"channel":"book","type":"update","data":[{"symbol":"BTC/JPY","bids":[],"asks":[{"price":10671893,"qty":0.00000000},{"price":10691000,"qty":0.00010000},{"price":10671891,"qty":0.16176513}],"checksum":4100154593,"timestamp":"2024-06-01T17:51:51.702576Z"}]}
{"channel":"book","type":"update","data":[{"symbol":"BTC/JPY","bids":[],"asks":[{"price":10671892,"qty":0.00000000},{"price":10691000,"qty":0.00010000}],"checksum":3497626071,"timestamp":"2024-06-01T17:51:51.712720Z"}]}
{"channel":"book","type":"update","data":[{"symbol":"BTC/JPY","bids":[],"asks":[{"price":10671890,"qty":0.01129070}],"checksum":1499113664,"timestamp":"2024-06-01T17:51:51.713103Z"}]}
{"channel":"book","type":"update","data":[{"symbol":"BTC/JPY","bids":[],"asks":[{"price":10671891,"qty":0.00000000},{"price":10691000,"qty":0.00010000},{"price":10671889,"qty":0.16210056}],"checksum":129553639,"timestamp":"2024-06-01T17:51:51.764592Z"}]}
{"channel":"book","type":"update","data":[{"symbol":"BTC/JPY","bids":[],"asks":[{"price":10671890,"qty":0.00000000},{"price":10691000,"qty":0.00010000}],"checksum":3435504785,"timestamp":"2024-06-01T17:51:51.779401Z"}]}
{"channel":"book","type":"update","data":[{"symbol":"BTC/JPY","bids":[],"asks":[{"price":10671888,"qty":0.01129070}],"checksum":3518269105,"timestamp":"2024-06-01T17:51:51.779539Z"}]}
{"channel":"book","type":"update","data":[{"symbol":"BTC/JPY","bids":[],"asks":[{"price":10671889,"qty":0.00000000},{"price":10691000,"qty":0.00010000},{"price":10671887,"qty":0.16260786}],"checksum":3830557669,"timestamp":"2024-06-01T17:51:51.836389Z"}]}
{"channel":"book","type":"update","data":[{"symbol":"BTC/JPY","bids":[],"asks":[{"price":10671886,"qty":0.01129070}],"checksum":1389622625,"timestamp":"2024-06-01T17:51:51.858327Z"}]}
{"channel":"book","type":"update","data":[{"symbol":"BTC/JPY","bids":[],"asks":[{"price":10671888,"qty":0.00000000},{"price":10680973,"qty":1.21244217}],"checksum":84930831,"timestamp":"2024-06-01T17:51:51.858409Z"}]}
{"channel":"book","type":"update","data":[{"symbol":"BTC/JPY","bids":[],"asks":[{"price":10671887,"qty":0.00000000},{"price":10691000,"qty":0.00010000},{"price":10671885,"qty":0.16320125}],"checksum":2393141561,"timestamp":"2024-06-01T17:51:51.927754Z"}]}
{"channel":"book","type":"update","data":[{"symbol":"BTC/JPY","bids":[],"asks":[{"price":10671886,"qty":0.00000000},{"price":10691000,"qty":0.00010000}],"checksum":2280624068,"timestamp":"2024-06-01T17:51:51.956298Z"}]}
{"channel":"book","type":"update","data":[{"symbol":"BTC/JPY","bids":[],"asks":[{"price":10671884,"qty":0.01129070}],"checksum":3164574229,"timestamp":"2024-06-01T17:51:51.956354Z"}]}
{"channel":"book","type":"update","data":[{"symbol":"BTC/JPY","bids":[],"asks":[{"price":10671885,"qty":0.00000000},{"price":10691000,"qty":0.00010000},{"price":10671883,"qty":0.16381817}],"checksum":1428757350,"timestamp":"2024-06-01T17:51:52.023547Z"}]}
{"channel":"book","type":"update","data":[{"symbol":"BTC/JPY","bids":[],"asks":[{"price":10671884,"qty":0.00000000},{"price":10691000,"qty":0.00010000}],"checksum":667136884,"timestamp":"2024-06-01T17:51:52.035513Z"}]}
{"channel":"book","type":"update","data":[{"symbol":"BTC/JPY","bids":[],"asks":[{"price":10671882,"qty":0.01129070}],"checksum":3826062965,"timestamp":"2024-06-01T17:51:52.035623Z"}]}
{"channel":"book","type":"update","data":[{"symbol":"BTC/JPY","bids":[],"asks":[{"price":10671883,"qty":0.00000000},{"price":10691000,"qty":0.00010000},{"price":10664637,"qty":0.12373273}],"checksum":2057111141,"timestamp":"2024-06-01T17:51:52.095598Z"}]}
{"channel":"book","type":"update","data":[{"symbol":"BTC/JPY","bids":[],"asks":[{"price":10664637,"qty":0.00000000},{"price":10691000,"qty":0.00010000},{"price":10671881,"qty":0.16442859}],"checksum":4138406446,"timestamp":"2024-06-01T17:51:52.143326Z"}]}
{"channel":"book","type":"update","data":[{"symbol":"BTC/JPY","bids":[],"asks":[{"price":10671880,"qty":0.01129070}],"checksum":4142129421,"timestamp":"2024-06-01T17:51:52.157964Z"}]}
{"channel":"book","type":"update","data":[{"symbol":"BTC/JPY","bids":[],"asks":[{"price":10671882,"qty":0.00000000},{"price":10680973,"qty":1.21244217}],"checksum":1250651313,"timestamp":"2024-06-01T17:51:52.158038Z"}]}
{"channel":"book","type":"update","data":[{"symbol":"BTC/JPY","bids":[],"asks":[{"price":10671881,"qty":0.00000000},{"price":10691000,"qty":0.00010000},{"price":10664637,"qty":0.12421574}],"checksum":1199768534,"timestamp":"2024-06-01T17:51:52.214955Z"}]}
{"channel":"book","type":"update","data":[{"symbol":"BTC/JPY","bids":[],"asks":[{"price":10671914,"qty":0.00000000},{"price":10691000,"qty":0.00010000}],"checksum":1637320698,"timestamp":"2024-06-01T17:51:53.839791Z"}]}
{"channel":"book","type":"update","data":[{"symbol":"BTC/JPY","bids":[],"asks":[{"price":10671879,"qty":0.00529386}],"checksum":2164883912,"timestamp":"2024-06-01T17:51:54.013466Z"}]}
{"channel":"book","type":"update","data":[{"symbol":"BTC/JPY","bids":[{"price":10591924,"qty":0.00000000},{"price":10556415,"qty":0.00012369}],"asks":[],"checksum":3558589662,"timestamp":"2024-06-01T17:51:54.034564Z"}]}
{"channel":"book","type":"update","data":[{"symbol":"BTC/JPY","bids":[{"price":10576940,"qty":0.00000000},{"price":10553000,"qty":0.00010000}],"asks":[],"checksum":1247977252,"timestamp":"2024-06-01T17:51:54.034779Z"}]}
{"channel":"book","type":"update","data":[{"symbol":"BTC/JPY","bids":[{"price":10564396,"qty":1.31226123}],"asks":[],"checksum":799568939,"timestamp":"2024-06-01T17:51:54.037509Z"}]}
{"channel":"book","type":"update","data":[{"symbol":"BTC/JPY","bids":[{"price":10597283,"qty":0.26132317}],"asks":[],"checksum":4239248563,"timestamp":"2024-06-01T17:51:54.037556Z"}]}
{"channel":"book","type":"update","data":[{"symbol":"BTC/JPY","bids":[{"price":10586623,"qty":0.48668914}],"asks":[],"checksum":1666521124,"timestamp":"2024-06-01T17:51:54.037784Z"}]}
{"channel":"book","type":"update","data":[{"symbol":"BTC/JPY","bids":[],"asks":[{"price":10671930,"qty":0.00000000},{"price":10691000,"qty":0.00010000}],"checksum":2443261836,"timestamp":"2024-06-01T17:51:59.916654Z"}]}
{"channel":"book","type":"update","data":[{"symbol":"BTC/JPY","bids":[{"price":10586622,"qty":0.00000000},{"price":10564396,"qty":1.31226123}],"asks":[],"checksum":1665263037,"timestamp":"2024-06-01T17:51:59.916766Z"}]}
{"channel":"book","type":"update","data":[{"symbol":"BTC/JPY","bids":[{"price":10597283,"qty":0.00000000},{"price":10556415,"qty":0.00012369}],"asks":[],"checksum":343128758,"timestamp":"2024-06-01T17:51:59.916795Z"}]}
{"channel":"book","type":"update","data":[{"symbol":"BTC/JPY","bids":[{"price":10564396,"qty":0.00000000},{"price":10553000,"qty":0.00010000}],"asks":[],"checksum":4172359986,"timestamp":"2024-06-01T17:51:59.916827Z"}]}
{"channel":"book","type":"update","data":[{"symbol":"BTC/JPY","bids":[],"asks":[{"price":10680108,"qty":0.00000000},{"price":10693737,"qty":2.42488434}],"checksum":220185982,"timestamp":"2024-06-01T17:51:59.916836Z"}]}
{"channel":"book","type":"update","data":[{"symbol":"BTC/JPY","bids":[],"asks":[{"price":10664638,"qty":0.00000000},{"price":10697794,"qty":0.00030785}],"checksum":4246075738,"timestamp":"2024-06-01T17:51:59.916857Z"}]}
{"channel":"book","type":"update","data":[{"symbol":"BTC/JPY","bids":[{"price":10586623,"qty":0.00000000},{"price":10539254,"qty":0.00028195}],"asks":[],"checksum":2257058878,"timestamp":"2024-06-01T17:51:59.916880Z"}]}
{"channel":"book","type":"update","data":[{"symbol":"BTC/JPY","bids":[],"asks":[{"price":10676729,"qty":0.00000000},{"price":10707724,"qty":0.07707449}],"checksum":3893941149,"timestamp":"2024-06-01T17:51:59.916916Z"}]}
{"channel":"book","type":"update","data":[{"symbol":"BTC/JPY","bids":[{"price":10601925,"qty":0.48668914}],"asks":[],"checksum":3314287056,"timestamp":"2024-06-01T17:51:59.919460Z"}]}
{"channel":"book","type":"update","data":[{"symbol":"BTC/JPY","bids":[],"asks":[{"price":10647381,"qty":0.48668914}],"checksum":1641051381,"timestamp":"2024-06-01T17:51:59.919506Z"}]}
{"channel":"book","type":"update","data":[{"symbol":"BTC/JPY","bids":[{"price":10556416,"qty":0.98399545}],"asks":[],"checksum":3894877932,"timestamp":"2024-06-01T17:51:59.919569Z"}]}
{"channel":"book","type":"update","data":[{"symbol":"BTC/JPY","bids":[],"asks":[{"price":10642065,"qty":0.26132317}],"checksum":2418413885,"timestamp":"2024-06-01T17:51:59.919654Z"}]}
{"channel":"book","type":"update","data":[{"symbol":"BTC/JPY","bids":[{"price":10614133,"qty":0.26132317}],"asks":[],"checksum":3234955106,"timestamp":"2024-06-01T17:51:59.919680Z"}]}
{"channel":"book","type":"update","data":[{"symbol":"BTC/JPY","bids":[{"price":10586623,"qty":1.31226123}],"asks":[],"checksum":441898490,"timestamp":"2024-06-01T17:51:59.919693Z"}]}
{"channel":"book","type":"update","data":[{"symbol":"BTC/JPY","bids":[],"asks":[{"price":10664636,"qty":1.31226123}],"checksum":1622965903,"timestamp":"2024-06-01T17:51:59.919731Z"}]}
{"channel":"book","type":"update","data":[{"symbol":"BTC/JPY","bids":[],"asks":[{"price":10664636,"qty":1.79895037}],"checksum":4059006976,"timestamp":"2024-06-01T17:51:59.919757Z"}]}
{"channel":"book","type":"update","data":[{"symbol":"BTC/JPY","bids":[],"asks":[{"price":10690999,"qty":0.98399545}],"checksum":2961735886,"timestamp":"2024-06-01T17:51:59.919770Z"}]}
{"channel":"book","type":"update","data":[{"symbol":"BTC/JPY","bids":[{"price":10608820,"qty":0.48668914}],"asks":[],"checksum":135320861,"timestamp":"2024-06-01T17:51:59.919789Z"}]}
{"channel":"book","type":"update","data":[{"symbol":"BTC/JPY","bids":[],"asks":[{"price":10642065,"qty":0.00000000},{"price":10691000,"qty":0.00010000}],"checksum":1062576397,"timestamp":"2024-06-01T17:51:59.922988Z"}]}
{"channel":"book","type":"update","data":[{"symbol":"BTC/JPY","bids":[],"asks":[{"price":10664636,"qty":0.48668914}],"checksum":2673534261,"timestamp":"2024-06-01T17:51:59.923085Z"}]}
{"channel":"book","type":"update","data":[{"symbol":"BTC/JPY","bids":[{"price":10601925,"qty":0.00000000},{"price":10584185,"qty":2.42118746}],"asks":[],"checksum":1433897306,"timestamp":"2024-06-01T17:51:59.923165Z"}]}
{"channel":"book","type":"update","data":[{"symbol":"BTC/JPY","bids":[],"asks":[{"price":10647381,"qty":0.00000000},{"price":10693737,"qty":2.42488434}],"checksum":1179311240,"timestamp":"2024-06-01T17:51:59.923188Z"}]}
{"channel":"book","type":"update","data":[{"symbol":"BTC/JPY","bids":[{"price":10608820,"qty":0.00000000},{"price":10556416,"qty":0.98399545}],"asks":[],"checksum":2802823085,"timestamp":"2024-06-01T17:51:59.923213Z"}]}
{"channel":"book","type":"update","data":[{"symbol":"BTC/JPY","bids":[{"price":10586623,"qty":0.00000000},{"price":10556415,"qty":0.00012369}],"asks":[],"checksum":4084384245,"timestamp":"2024-06-01T17:51:59.923221Z"}]}
{"channel":"book","type":"update","data":[{"symbol":"BTC/JPY","bids":[{"price":10614133,"qty":0.00000000},{"price":10553000,"qty":0.00010000}],"asks":[],"checksum":578113773,"timestamp":"2024-06-01T17:51:59.923260Z"}]}
{"channel":"book","type":"update","data":[{"symbol":"BTC/JPY","bids":[],"asks":[{"price":10664636,"qty":0.00000000},{"price":10697794,"qty":0.00030785}],"checksum":2422251089,"timestamp":"2024-06-01T17:51:59.923341Z"}]}
{"channel":"book","type":"update","data":[{"symbol":"BTC/JPY","bids":[],"asks":[{"price":10690999,"qty":0.00000000},{"price":10707724,"qty":0.07707449}],"checksum":1687826300,"timestamp":"2024-06-01T17:51:59.923452Z"}]}
{"channel":"book","type":"update","data":[{"symbol":"BTC/JPY","bids":[],"asks":[{"price":10664697,"qty":0.26132317}],"checksum":743973236,"timestamp":"2024-06-01T17:51:59.925554Z"}]}
{"channel":"book","type":"update","data":[{"symbol":"BTC/JPY","bids":[{"price":10592896,"qty":0.48668914}],"asks":[],"checksum":2923057582,"timestamp":"2024-06-01T17:51:59.925854Z"}]}
{"channel":"book","type":"update","data":[{"symbol":"BTC/JPY","bids":[{"price":10584186,"qty":0.48668914}],"asks":[],"checksum":222918071,"timestamp":"2024-06-01T17:51:59.925868Z"}]}
{"channel":"book","type":"update","data":[{"symbol":"BTC/JPY","bids":[{"price":10556417,"qty":1.31226123}],"asks":[],"checksum":3760005000,"timestamp":"2024-06-01T17:51:59.925919Z"}]}
{"channel":"book","type":"update","data":[{"symbol":"BTC/JPY","bids":[],"asks":[{"price":10670024,"qty":0.48668914}],"checksum":1039933588,"timestamp":"2024-06-01T17:51:59.926010Z"}]}
{"channel":"book","type":"update","data":[{"symbol":"BTC/JPY","bids":[],"asks":[{"price":10690999,"qty":1.31226123}],"checksum":2971768545,"timestamp":"2024-06-01T17:51:59.926024Z"}]}
{"channel":"book","type":"update","data":[{"symbol":"BTC/JPY","bids":[{"price":10598201,"qty":0.26132317}],"asks":[],"checksum":2742028181,"timestamp":"2024-06-01T17:51:59.926263Z"}]}
{"channel":"book","type":"update","data":[{"symbol":"BTC/JPY","bids":[],"asks":[{"price":10680972,"qty":0.48668914}],"checksum":1247475644,"timestamp":"2024-06-01T17:51:59.926280Z"}]}
{"channel":"book","type":"update","data":[{"symbol":"BTC/JPY","bids":[{"price":10610603,"qty":0.02747678},{"price":10615529,"qty":0.00243227}],"asks":[],"checksum":3719664979,"timestamp":"2024-06-01T17:51:59.926552Z"}]}
{"channel":"book","type":"update","data":[{"symbol":"BTC/JPY","bids":[],"asks":[{"price":10671880,"qty":0.00000000},{"price":10691000,"qty":0.00010000}],"checksum":2844671689,"timestamp":"2024-06-01T17:51:59.933947Z"}]}
{"channel":"book","type":"update","data":[{"symbol":"BTC/JPY","bids":[],"asks":[{"price":10670023,"qty":0.01129070}],"checksum":4228908993,"timestamp":"2024-06-01T17:51:59.934020Z"}]}
{"channel":"book","type":"update","data":[{"symbol":"BTC/JPY","bids":[],"asks":[{"price":10671879,"qty":0.00000000},{"price":10691000,"qty":0.00010000}],"checksum":1259310226,"timestamp":"2024-06-01T17:51:59.975708Z"}]}
{"channel":"book","type":"update","data":[{"symbol":"BTC/JPY","bids":[],"asks":[{"price":10670022,"qty":0.00529385}],"checksum":3601931181,"timestamp":"2024-06-01T17:52:00.028775Z"}]}
{"channel":"book","type":"update","data":[{"symbol":"BTC/JPY","bids":[{"price":10610603,"qty":0.00000000},{"price":10584185,"qty":2.42118746}],"asks":[],"checksum":1465700017,"timestamp":"2024-06-01T17:52:01.816317Z"}]}
{"channel":"book","type":"update","data":[{"symbol":"BTC/JPY","bids":[{"price":10615529,"qty":0.02990265}],"asks":[],"checksum":2276917487,"timestamp":"2024-06-01T17:52:01.856605Z"}]}
{"channel":"book","type":"update","data":[{"symbol":"BTC/JPY","bids":[],"asks":[{"price":10664637,"qty":0.00000000},{"price":10691000,"qty":0.00010000},{"price":10670021,"qty":0.13719450}],"checksum":3415505644,"timestamp":"2024-06-01T17:52:06.961897Z"}]}
{"channel":"book","type":"update","data":[{"symbol":"BTC/JPY","bids":[],"asks":[{"price":10670023,"qty":0.00000000},{"price":10691000,"qty":0.00010000}],"checksum":3860405786,"timestamp":"2024-06-01T17:52:06.980512Z"}]}
{"channel":"book","type":"update","data":[{"symbol":"BTC/JPY","bids":[],"asks":[{"price":10670020,"qty":0.01129070}],"checksum":1232424150,"timestamp":"2024-06-01T17:52:06.980718Z"}]}
{"channel":"book","type":"update","data":[{"symbol":"BTC/JPY","bids":[],"asks":[{"price":10670022,"qty":0.00000000},{"price":10691000,"qty":0.00010000}],"checksum":2029738906,"timestamp":"2024-06-01T17:52:07.019751Z"}]}
{"channel":"book","type":"update","data":[{"symbol":"BTC/JPY","bids":[],"asks":[{"price":10670021,"qty":0.00000000},{"price":10693737,"qty":2.42488434},{"price":10670019,"qty":0.13763613}],"checksum":221073546,"timestamp":"2024-06-01T17:52:07.038534Z"}]}
{"channel":"book","type":"update","data":[{"symbol":"BTC/JPY","bids":[],"asks":[{"price":10670019,"qty":0.14293007}],"checksum":2766951277,"timestamp":"2024-06-01T17:52:07.050651Z"}]}
{"channel":"book","type":"update","data":[{"symbol":"BTC/JPY","bids":[],"asks":[{"price":10670018,"qty":0.01129070}],"checksum":756794421,"timestamp":"2024-06-01T17:52:07.062736Z"}]}
{"channel":"book","type":"update","data":[{"symbol":"BTC/JPY","bids":[],"asks":[{"price":10670020,"qty":0.00000000},{"price":10691000,"qty":0.00010000}],"checksum":3569278394,"timestamp":"2024-06-01T17:52:07.062755Z"}]}
{"channel":"book","type":"update","data":[{"symbol":"BTC/JPY","bids":[],"asks":[{"price":10670019,"qty":0.00529394},{"price":10670017,"qty":0.13799888}],"checksum":1480868521,"timestamp":"2024-06-01T17:52:07.132413Z"}]}
{"channel":"book","type":"update","data":[{"symbol":"BTC/JPY","bids":[],"asks":[{"price":10670016,"qty":0.01129070}],"checksum":734987527,"timestamp":"2024-06-01T17:52:07.140660Z"}]}
{"channel":"book","type":"update","data":[{"symbol":"BTC/JPY","bids":[],"asks":[{"price":10670018,"qty":0.00000000},{"price":10690999,"qty":1.31226123}],"checksum":1517080646,"timestamp":"2024-06-01T17:52:07.140685Z"}]}
{"channel":"book","type":"update","data":[{"symbol":"BTC/JPY","bids":[],"asks":[{"price":10670017,"qty":0.00000000},{"price":10691000,"qty":0.00010000},{"price":10670015,"qty":0.13926353}],"checksum":1585654329,"timestamp":"2024-06-01T17:52:07.210993Z"}]}
{"channel":"book","type":"update","data":[{"symbol":"BTC/JPY","bids":[],"asks":[{"price":10670016,"qty":0.00000000},{"price":10691000,"qty":0.00010000}],"checksum":940309832,"timestamp":"2024-06-01T17:52:07.240589Z"}]}
{"channel":"book","type":"update","data":[{"symbol":"BTC/JPY","bids":[],"asks":[{"price":10670014,"qty":0.01129070}],"checksum":4257212313,"timestamp":"2024-06-01T17:52:07.240759Z"}]}
{"channel":"book","type":"update","data":[{"symbol":"BTC/JPY","bids":[],"asks":[{"price":10670015,"qty":0.00000000},{"price":10691000,"qty":0.00010000},{"price":10670013,"qty":0.13904360}],"checksum":2053890637,"timestamp":"2024-06-01T17:52:07.289669Z"}]}
{"channel":"book","type":"update","data":[{"symbol":"BTC/JPY","bids":[],"asks":[{"price":10670012,"qty":0.01129070}],"checksum":167626845,"timestamp":"2024-06-01T17:52:07.309886Z"}]}
{"channel":"book","type":"update","data":[{"symbol":"BTC/JPY","bids":[],"asks":[{"price":10670014,"qty":0.00000000},{"price":10690999,"qty":1.31226123}],"checksum":402032695,"timestamp":"2024-06-01T17:52:07.309937Z"}]}
{"channel":"book","type":"update","data":[{"symbol":"BTC/JPY","bids":[],"asks":[{"price":10670013,"qty":0.00000000},{"price":10691000,"qty":0.00010000},{"price":10670011,"qty":0.13851565}],"checksum":3869686076,"timestamp":"2024-06-01T17:52:07.360935Z"}]}
{"channel":"book","type":"update","data":[{"symbol":"BTC/JPY","bids":[],"asks":[{"price":10670012,"qty":0.00000000},{"price":10691000,"qty":0.00010000}],"checksum":3724457534,"timestamp":"2024-06-01T17:52:07.391854Z"}]}
{"channel":"book","type":"update","data":[{"symbol":"BTC/JPY","bids":[],"asks":[{"price":10670010,"qty":0.01129070}],"checksum":2355358848,"timestamp":"2024-06-01T17:52:07.391942Z"}]}
{"channel":"book","type":"update","data":[{"symbol":"BTC/JPY","bids":[],"asks":[{"price":10670011,"qty":0.00000000},{"price":10691000,"qty":0.00010000},{"price":10670009,"qty":0.13857280}],"checksum":241378267,"timestamp":"2024-06-01T17:52:07.435181Z"}]}
{"channel":"book","type":"update","data":[{"symbol":"BTC/JPY","bids":[],"asks":[{"price":10670010,"qty":0.00000000},{"price":10691000,"qty":0.00010000}],"checksum":2489032875,"timestamp":"2024-06-01T17:52:07.471547Z"}]}
{"channel":"book","type":"update","data":[{"symbol":"BTC/JPY","bids":[],"asks":[{"price":10670008,"qty":0.01129070}],"checksum":2450490161,"timestamp":"2024-06-01T17:52:07.471694Z"}]}
{"channel":"book","type":"update","data":[{"symbol":"BTC/JPY","bids":[],"asks":[{"price":10670009,"qty":0.00000000},{"price":10691000,"qty":0.00010000},{"price":10670007,"qty":0.13874439}],"checksum":3551305627,"timestamp":"2024-06-01T17:52:07.524161Z"}]}
{"channel":"book","type":"update","data":[{"symbol":"BTC/JPY","bids":[],"asks":[{"price":10670006,"qty":0.01129070}],"checksum":2428758965,"timestamp":"2024-06-01T17:52:07.539395Z"}]}
{"channel":"book","type":"update","data":[{"symbol":"BTC/JPY","bids":[],"asks":[{"price":10670008,"qty":0.00000000},{"price":10690999,"qty":1.31226123}],"checksum":1147073723,"timestamp":"2024-06-01T17:52:07.539423Z"}]}
{"channel":"book","type":"update","data":[{"symbol":"BTC/JPY","bids":[],"asks":[{"price":10670007,"qty":0.00000000},{"price":10691000,"qty":0.00010000},{"price":10670005,"qty":0.13880747}],"checksum":471815637,"timestamp":"2024-06-01T17:52:07.600006Z"}]}
{"channel":"book","type":"update","data":[{"symbol":"BTC/JPY","bids":[],"asks":[{"price":10670006,"qty":0.00000000},{"price":10691000,"qty":0.00010000}],"checksum":355950200,"timestamp":"2024-06-01T17:52:07.624700Z"}]}
{"channel":"book","type":"update","data":[{"symbol":"BTC/JPY","bids":[],"asks":[{"price":10670004,"qty":0.01129070}],"checksum":2917393966,"timestamp":"2024-06-01T17:52:07.624728Z"}]}
{"channel":"book","type":"update","data":[{"symbol":"BTC/JPY","bids":[],"asks":[{"price":10670005,"qty":0.00000000},{"price":10691000,"qty":0.00010000},{"price":10670003,"qty":0.13885060}],"checksum":3190924710,"timestamp":"2024-06-01T17:52:07.680567Z"}]}
{"channel":"book","type":"update","data":[{"symbol":"BTC/JPY","bids":[],"asks":[{"price":10670004,"qty":0.00000000},{"price":10691000,"qty":0.00010000}],"checksum":4255043716,"timestamp":"2024-06-01T17:52:07.706424Z"}]}
{"channel":"book","type":"update","data":[{"symbol":"BTC/JPY","bids":[],"asks":[{"price":10670002,"qty":0.01129070}],"checksum":977501175,"timestamp":"2024-06-01T17:52:07.706464Z"}]}
{"channel":"book","type":"update","data":[{"symbol":"BTC/JPY","bids":[],"asks":[{"price":10670003,"qty":0.00000000},{"price":10691000,"qty":0.00010000},{"price":10670001,"qty":0.13879532}],"checksum":2390967120,"timestamp":"2024-06-01T17:52:07.758026Z"}]}
{"channel":"book","type":"update","data":[{"symbol":"BTC/JPY","bids":[],"asks":[{"price":10670002,"qty":0.00000000},{"price":10691000,"qty":0.00010000}],"checksum":2289370798,"timestamp":"2024-06-01T17:52:07.767279Z"}]}
{"channel":"book","type":"update","data":[{"symbol":"BTC/JPY","bids":[],"asks":[{"price":10670000,"qty":0.01129070}],"checksum":1523720780,"timestamp":"2024-06-01T17:52:07.767473Z"}]}
{"channel":"book","type":"update","data":[{"symbol":"BTC/JPY","bids":[],"asks":[{"price":10670001,"qty":0.00000000},{"price":10691000,"qty":0.00010000},{"price":10669999,"qty":0.13885197}],"checksum":2786762614,"timestamp":"2024-06-01T17:52:07.818553Z"}]}
{"channel":"book","type":"update","data":[{"symbol":"BTC/JPY","bids":[],"asks":[{"price":10669998,"qty":0.01129070}],"checksum":1634818546,"timestamp":"2024-06-01T17:52:07.836528Z"}]}
{"channel":"book","type":"update","data":[{"symbol":"BTC/JPY","bids":[],"asks":[{"price":10670000,"qty":0.00000000},{"price":10690999,"qty":1.31226123}],"checksum":1847283851,"timestamp":"2024-06-01T17:52:07.836578Z"}]}
{"channel":"book","type":"update","data":[{"symbol":"BTC/JPY","bids":[],"asks":[{"price":10669999,"qty":0.00000000},{"price":10691000,"qty":0.00010000},{"price":10669997,"qty":0.13872900}],"checksum":700510931,"timestamp":"2024-06-01T17:52:07.881427Z"}]}
{"channel":"book","type":"update","data":[{"symbol":"BTC/JPY","bids":[],"asks":[{"price":10669998,"qty":0.00000000},{"price":10691000,"qty":0.00010000}],"checksum":243067422,"timestamp":"2024-06-01T17:52:07.887997Z"}]}
{"channel":"book","type":"update","data":[{"symbol":"BTC/JPY","bids":[],"asks":[{"price":10669996,"qty":0.01129070}],"checksum":3594265014,"timestamp":"2024-06-01T17:52:07.888101Z"}]}
{"channel":"book","type":"update","data":[{"symbol":"BTC/JPY","bids":[],"asks":[{"price":10669997,"qty":0.00000000},{"price":10691000,"qty":0.00010000},{"price":10669995,"qty":0.13774742}],"checksum":3993422579,"timestamp":"2024-06-01T17:52:07.936847Z"}]}
{"channel":"book","type":"update","data":[{"symbol":"BTC/JPY","bids":[],"asks":[{"price":10669996,"qty":0.00000000},{"price":10691000,"qty":0.00010000}],"checksum":2641128835,"timestamp":"2024-06-01T17:52:07.944894Z"}]}
{"channel":"book","type":"update","data":[{"symbol":"BTC/JPY","bids":[],"asks":[{"price":10669994,"qty":0.01129070}],"checksum":2008710444,"timestamp":"2024-06-01T17:52:07.945052Z"}]}
{"channel":"book","type":"update","data":[{"symbol":"BTC/JPY","bids":[],"asks":[{"price":10669995,"qty":0.00000000},{"price":10691000,"qty":0.00010000},{"price":10669993,"qty":0.13790959}],"checksum":2400597953,"timestamp":"2024-06-01T17:52:08.000350Z"}]}
{"channel":"book","type":"update","data":[{"symbol":"BTC/JPY","bids":[],"asks":[{"price":10669994,"qty":0.00000000},{"price":10691000,"qty":0.00010000}],"checksum":776600915,"timestamp":"2024-06-01T17:52:08.023348Z"}]}
{"channel":"book","type":"update","data":[{"symbol":"BTC/JPY","bids":[],"asks":[{"price":10669992,"qty":0.01129070}],"checksum":3144301538,"timestamp":"2024-06-01T17:52:08.023436Z"}]}
{"channel":"book","type":"update","data":[{"symbol":"BTC/JPY","bids":[],"asks":[{"price":10669993,"qty":0.00000000},{"price":10691000,"qty":0.00010000},{"price":10669991,"qty":0.13820668}],"checksum":1669891406,"timestamp":"2024-06-01T17:52:08.074467Z"}]}
{"channel":"book","type":"update","data":[{"symbol":"BTC/JPY","bids":[],"asks":[{"price":10669992,"qty":0.00000000},{"price":10691000,"qty":0.00010000}],"checksum":220816999,"timestamp":"2024-06-01T17:52:08.100986Z"}]}
{"channel":"book","type":"update","data":[{"symbol":"BTC/JPY","bids":[],"asks":[{"price":10669990,"qty":0.01129070}],"checksum":3187109005,"timestamp":"2024-06-01T17:52:08.101078Z"}]}
{"channel":"book","type":"update","data":[{"symbol":"BTC/JPY","bids":[],"asks":[{"price":10669991,"qty":0.00000000},{"price":10691000,"qty":0.00010000},{"price":10669989,"qty":0.13844825}],"checksum":2490502212,"timestamp":"2024-06-01T17:52:08.162921Z"}]}
{"channel":"book","type":"update","data":[{"symbol":"BTC/JPY","bids":[],"asks":[{"price":10669990,"qty":0.00000000},{"price":10691000,"qty":0.00010000}],"checksum":28421695,"timestamp":"2024-06-01T17:52:08.188644Z"}]}
{"channel":"book","type":"update","data":[{"symbol":"BTC/JPY","bids":[],"asks":[{"price":10669988,"qty":0.01129070}],"checksum":3719458680,"timestamp":"2024-06-01T17:52:08.188720Z"}]}
{"channel":"book","type":"update","data":[{"symbol":"BTC/JPY","bids":[],"asks":[{"price":10669989,"qty":0.00000000},{"price":10691000,"qty":0.00010000},{"price":10669987,"qty":0.13827574}],"checksum":3832871476,"timestamp":"2024-06-01T17:52:08.242879Z"}]}
{"channel":"book","type":"update","data":[{"symbol":"BTC/JPY","bids":[],"asks":[{"price":10669986,"qty":0.01129070}],"checksum":1379744042,"timestamp":"2024-06-01T17:52:08.255140Z"}]}
{"channel":"book","type":"update","data":[{"symbol":"BTC/JPY","bids":[],"asks":[{"price":10669988,"qty":0.00000000},{"price":10690999,"qty":1.31226123}],"checksum":3037888955,"timestamp":"2024-06-01T17:52:08.255173Z"}]}
{"channel":"book","type":"update","data":[{"symbol":"BTC/JPY","bids":[],"asks":[{"price":10669987,"qty":0.00000000},{"price":10691000,"qty":0.00010000},{"price":10669985,"qty":0.13765562}],"checksum":2563025703,"timestamp":"2024-06-01T17:52:08.319702Z"}]}
{"channel":"book","type":"update","data":[{"symbol":"BTC/JPY","bids":[],"asks":[{"price":10669986,"qty":0.00000000},{"price":10691000,"qty":0.00010000}],"checksum":3261812316,"timestamp":"2024-06-01T17:52:08.343246Z"}]}
{"channel":"book","type":"update","data":[{"symbol":"BTC/JPY","bids":[],"asks":[{"price":10669984,"qty":0.01129070}],"checksum":703821252,"timestamp":"2024-06-01T17:52:08.343415Z"}]}
{"channel":"book","type":"update","data":[{"symbol":"BTC/JPY","bids":[],"asks":[{"price":10669985,"qty":0.00000000},{"price":10691000,"qty":0.00010000},{"price":10669983,"qty":0.13780172}],"checksum":987513128,"timestamp":"2024-06-01T17:52:08.397213Z"}]}
{"channel":"book","type":"update","data":[{"symbol":"BTC/JPY","bids":[],"asks":[{"price":10669982,"qty":0.01129070}],"checksum":1107290118,"timestamp":"2024-06-01T17:52:08.400434Z"}]}
{"channel":"book","type":"update","data":[{"symbol":"BTC/JPY","bids":[],"asks":[{"price":10669984,"qty":0.00000000},{"price":10690999,"qty":1.31226123}],"checksum":2515298821,"timestamp":"2024-06-01T17:52:08.400480Z"}]}
{"channel":"book","type":"update","data":[{"symbol":"BTC/JPY","bids":[],"asks":[{"price":10669983,"qty":0.00000000},{"price":10691000,"qty":0.00010000},{"price":10669981,"qty":0.13796874}],"checksum":2482128026,"timestamp":"2024-06-01T17:52:08.459436Z"}]}
{"channel":"book","type":"update","data":[{"symbol":"BTC/JPY","bids":[],"asks":[{"price":10669982,"qty":0.00000000},{"price":10691000,"qty":0.00010000}],"checksum":1269522920,"timestamp":"2024-06-01T17:52:08.478357Z"}]}
{"channel":"book","type":"update","data":[{"symbol":"BTC/JPY","bids":[],"asks":[{"price":10669980,"qty":0.01129070}],"checksum":439126840,"timestamp":"2024-06-01T17:52:08.478488Z"}]}
{"channel":"book","type":"update","data":[{"symbol":"BTC/JPY","bids":[],"asks":[{"price":10669981,"qty":0.00000000},{"price":10691000,"qty":0.00010000},{"price":10669979,"qty":0.13707494}],"checksum":3805597459,"timestamp":"2024-06-01T17:52:08.524369Z"}]}
{"channel":"book","type":"update","data":[{"symbol":"BTC/JPY","bids":[],"asks":[{"price":10669980,"qty":0.00000000},{"price":10691000,"qty":0.00010000}],"checksum":2543668729,"timestamp":"2024-06-01T17:52:08.527961Z"}]}
{"channel":"book","type":"update","data":[{"symbol":"BTC/JPY","bids":[],"asks":[{"price":10669978,"qty":0.01129070}],"checksum":1131493683,"timestamp":"2024-06-01T17:52:08.528003Z"}]}
{"channel":"book","type":"update","data":[{"symbol":"BTC/JPY","bids":[],"asks":[{"price":10669979,"qty":0.00000000},{"price":10691000,"qty":0.00010000},{"price":10669977,"qty":0.13738344}],"checksum":3084602215,"timestamp":"2024-06-01T17:52:08.582206Z"}]}
{"channel":"book","type":"update","data":[{"symbol":"BTC/JPY","bids":[],"asks":[{"price":10669978,"qty":0.00000000},{"price":10691000,"qty":0.00010000}],"checksum":3621469527,"timestamp":"2024-06-01T17:52:08.600065Z"}]}
{"channel":"book","type":"update","data":[{"symbol":"BTC/JPY","bids":[],"asks":[{"price":10669976,"qty":0.01129070}],"checksum":4017110276,"timestamp":"2024-06-01T17:52:08.600161Z"}]}
{"channel":"book","type":"update","data":[{"symbol":"BTC/JPY","bids":[],"asks":[{"price":10669977,"qty":0.00000000},{"price":10691000,"qty":0.00010000},{"price":10669975,"qty":0.13785385}],"checksum":2430957807,"timestamp":"2024-06-01T17:52:08.665421Z"}]}
{"channel":"book","type":"update","data":[{"symbol":"BTC/JPY","bids":[],"asks":[{"price":10669976,"qty":0.00000000},{"price":10691000,"qty":0.00010000}],"checksum":2761047349,"timestamp":"2024-06-01T17:52:08.679207Z"}]}
{"channel":"book","type":"update","data":[{"symbol":"BTC/JPY","bids":[],"asks":[{"price":10669974,"qty":0.01129070}],"checksum":3591835268,"timestamp":"2024-06-01T17:52:08.679438Z"}]}
{"channel":"book","type":"update","data":[{"symbol":"BTC/JPY","bids":[],"asks":[{"price":10669975,"qty":0.00000000},{"price":10691000,"qty":0.00010000},{"price":10669973,"qty":0.13808494}],"checksum":530419813,"timestamp":"2024-06-01T17:52:08.741562Z"}]}
{"channel":"book","type":"update","data":[{"symbol":"BTC/JPY","bids":[],"asks":[{"price":10669974,"qty":0.00000000},{"price":10691000,"qty":0.00010000}],"checksum":1696097599,"timestamp":"2024-06-01T17:52:08.751027Z"}]}
{"channel":"book","type":"update","data":[{"symbol":"BTC/JPY","bids":[],"asks":[{"price":10669972,"qty":0.01129070}],"checksum":35431430,"timestamp":"2024-06-01T17:52:08.751113Z"}]}
{"channel":"book","type":"update","data":[{"symbol":"BTC/JPY","bids":[],"asks":[{"price":10669973,"qty":0.00000000},{"price":10691000,"qty":0.00010000},{"price":10669971,"qty":0.13806463}],"checksum":2729121333,"timestamp":"2024-06-01T17:52:08.797352Z"}]}
{"channel":"book","type":"update","data":[{"symbol":"BTC/JPY","bids":[],"asks":[{"price":10669972,"qty":0.00000000},{"price":10691000,"qty":0.00010000}],"checksum":2933677899,"timestamp":"2024-06-01T17:52:08.807421Z"}]}
{"channel":"book","type":"update","data":[{"symbol":"BTC/JPY","bids":[],"asks":[{"price":10669970,"qty":0.01129070}],"checksum":4096258776,"timestamp":"2024-06-01T17:52:08.807437Z"}]}
{"channel":"book","type":"update","data":[{"symbol":"BTC/JPY","bids":[],"asks":[{"price":10669971,"qty":0.00000000},{"price":10691000,"qty":0.00010000},{"price":10669969,"qty":0.13754962}],"checksum":1485144564,"timestamp":"2024-06-01T17:52:08.846538Z"}]}
{"channel":"book","type":"update","data":[{"symbol":"BTC/JPY","bids":[],"asks":[{"price":10669970,"qty":0.00000000},{"price":10691000,"qty":0.00010000}],"checksum":2959414373,"timestamp":"2024-06-01T17:52:08.860686Z"}]}
{"channel":"book","type":"update","data":[{"symbol":"BTC/JPY","bids":[],"asks":[{"price":10669968,"qty":0.01129070}],"checksum":5062737,"timestamp":"2024-06-01T17:52:08.860814Z"}]}
{"channel":"book","type":"update","data":[{"symbol":"BTC/JPY","bids":[],"asks":[{"price":10669969,"qty":0.00000000},{"price":10691000,"qty":0.00010000},{"price":10669967,"qty":0.13790119}],"checksum":2456446987,"timestamp":"2024-06-01T17:52:08.928616Z"}]}
{"channel":"book","type":"update","data":[{"symbol":"BTC/JPY","bids":[],"asks":[{"price":10669968,"qty":0.00000000},{"price":10691000,"qty":0.00010000}],"checksum":3812114935,"timestamp":"2024-06-01T17:52:09.255477Z"}]}
{"channel":"book","type":"update","data":[{"symbol":"BTC/JPY","bids":[],"asks":[{"price":10669966,"qty":0.01129070}],"checksum":2434676702,"timestamp":"2024-06-01T17:52:09.255707Z"}]}
{"channel":"book","type":"update","data":[{"symbol":"BTC/JPY","bids":[],"asks":[{"price":10669967,"qty":0.00000000},{"price":10691000,"qty":0.00010000},{"price":10669965,"qty":0.13790355}],"checksum":648265483,"timestamp":"2024-06-01T17:52:09.320955Z"}]}
{"channel":"book","type":"update","data":[{"symbol":"BTC/JPY","bids":[],"asks":[{"price":10670019,"qty":0.00000000},{"price":10691000,"qty":0.00010000}],"checksum":3161176350,"timestamp":"2024-06-01T17:52:09.854312Z"}]}
{"channel":"book","type":"update","data":[{"symbol":"BTC/JPY","bids":[],"asks":[{"price":10669964,"qty":0.01129070}],"checksum":1157607855,"timestamp":"2024-06-01T17:52:10.653558Z"}]}
{"channel":"book","type":"update","data":[{"symbol":"BTC/JPY","bids":[],"asks":[{"price":10669966,"qty":0.00000000},{"price":10691000,"qty":0.00010000}],"checksum":1999915958,"timestamp":"2024-06-01T17:52:10.653936Z"}]}
{"channel":"book","type":"update","data":[{"symbol":"BTC/JPY","bids":[],"asks":[{"price":10669965,"qty":0.00000000},{"price":10693737,"qty":2.42488434},{"price":10669963,"qty":0.13752515}],"checksum":1092745416,"timestamp":"2024-06-01T17:52:10.710076Z"}]}
{"channel":"book","type":"update","data":[{"symbol":"BTC/JPY","bids":[],"asks":[{"price":10669962,"qty":0.01129070}],"checksum":1061659682,"timestamp":"2024-06-01T17:52:10.716341Z"}]}
{"channel":"book","type":"update","data":[{"symbol":"BTC/JPY","bids":[],"asks":[{"price":10669964,"qty":0.00000000},{"price":10691000,"qty":0.00010000}],"checksum":575838468,"timestamp":"2024-06-01T17:52:10.716392Z"}]}
{"channel":"book","type":"update","data":[{"symbol":"BTC/JPY","bids":[{"price":10596949,"qty":0.00000000},{"price":10556418,"qty":1.31226123}],"asks":[],"checksum":1483792398,"timestamp":"2024-06-01T17:52:10.739744Z"}]}
{"channel":"book","type":"update","data":[{"symbol":"BTC/JPY","bids":[{"price":10597650,"qty":1.20999450}],"asks":[],"checksum":414694335,"timestamp":"2024-06-01T17:52:10.779944Z"}]}
{"channel":"book","type":"update","data":[{"symbol":"BTC/JPY","bids":[],"asks":[{"price":10669963,"qty":0.00000000},{"price":10693737,"qty":2.42488434},{"price":10669961,"qty":0.13656560}],"checksum":3233236419,"timestamp":"2024-06-01T17:52:10.788206Z"}]}
{"channel":"book","type":"update","data":[{"symbol":"BTC/JPY","bids":[],"asks":[{"price":10669960,"qty":0.00529392}],"checksum":3226291031,"timestamp":"2024-06-01T17:52:11.297229Z"}]}
{"channel":"book","type":"update","data":[{"symbol":"BTC/JPY","bids":[],"asks":[{"price":10669961,"qty":0.00000000},{"price":10691000,"qty":0.00010000},{"price":10669959,"qty":0.13564921}],"checksum":3953890908,"timestamp":"2024-06-01T17:52:11.352448Z"}]}
{"channel":"book","type":"update","data":[{"symbol":"BTC/JPY","bids":[],"asks":[{"price":10669962,"qty":0.00000000},{"price":10691000,"qty":0.00010000}],"checksum":3102798392,"timestamp":"2024-06-01T17:52:11.656787Z"}]}
{"channel":"book","type":"update","data":[{"symbol":"BTC/JPY","bids":[],"asks":[{"price":10669958,"qty":0.01129070}],"checksum":2795468727,"timestamp":"2024-06-01T17:52:11.657137Z"}]}
{"channel":"book","type":"update","data":[{"symbol":"BTC/JPY","bids":[],"asks":[{"price":10669959,"qty":0.00000000},{"price":10691000,"qty":0.00010000},{"price":10669957,"qty":0.13599952}],"checksum":1548255364,"timestamp":"2024-06-01T17:52:11.711429Z"}]}
{"channel":"book","type":"update","data":[{"symbol":"BTC/JPY","bids":[],"asks":[{"price":10669956,"qty":0.01129070}],"checksum":1620038307,"timestamp":"2024-06-01T17:52:11.720097Z"}]}
{"channel":"book","type":"update","data":[{"symbol":"BTC/JPY","bids":[],"asks":[{"price":10669958,"qty":0.00000000},{"price":10690999,"qty":1.31226123}],"checksum":2981354073,"timestamp":"2024-06-01T17:52:11.720255Z"}]}
{"channel":"book","type":"update","data":[{"symbol":"BTC/JPY","bids":[],"asks":[{"price":10669957,"qty":0.00000000},{"price":10691000,"qty":0.00010000},{"price":10669955,"qty":0.13605809}],"checksum":3957252032,"timestamp":"2024-06-01T17:52:11.788633Z"}]}
{"channel":"book","type":"update","data":[{"symbol":"BTC/JPY","bids":[],"asks":[{"price":10669954,"qty":0.01129070}],"checksum":732260783,"timestamp":"2024-06-01T17:52:13.063359Z"}]}
{"channel":"book","type":"update","data":[{"symbol":"BTC/JPY","bids":[],"asks":[{"price":10669956,"qty":0.00000000},{"price":10690999,"qty":1.31226123}],"checksum":2242531923,"timestamp":"2024-06-01T17:52:13.063497Z"}]}
{"channel":"book","type":"update","data":[{"symbol":"BTC/JPY","bids":[],"asks":[{"price":10669955,"qty":0.00000000},{"price":10691000,"qty":0.00010000},{"price":10669953,"qty":0.13569667}],"checksum":3175746304,"timestamp":"2024-06-01T17:52:13.132628Z"}]}
{"channel":"book","type":"update","data":[{"symbol":"BTC/JPY","bids":[],"asks":[{"price":10669954,"qty":0.00000000},{"price":10691000,"qty":0.00010000}],"checksum":2942670104,"timestamp":"2024-06-01T17:52:13.136037Z"}]}
{"channel":"book","type":"update","data":[{"symbol":"BTC/JPY","bids":[],"asks":[{"price":10669952,"qty":0.01129070}],"checksum":2819333046,"timestamp":"2024-06-01T17:52:13.136140Z"}]}
{"channel":"book","type":"update","data":[{"symbol":"BTC/JPY","bids":[],"asks":[{"price":10669953,"qty":0.00000000},{"price":10691000,"qty":0.00010000},{"price":10669951,"qty":0.13575476}],"checksum":344608967,"timestamp":"2024-06-01T17:52:13.212172Z"}]}
{"channel":"book","type":"update","data":[{"symbol":"BTC/JPY","bids":[],"asks":[{"price":10669952,"qty":0.00000000},{"price":10691000,"qty":0.00010000}],"checksum":2267999992,"timestamp":"2024-06-01T17:52:14.051714Z"}]}
{"channel":"book","type":"update","data":[{"symbol":"BTC/JPY","bids":[],"asks":[{"price":10669950,"qty":0.01129070}],"checksum":3458525007,"timestamp":"2024-06-01T17:52:14.051909Z"}]}
{"channel":"book","type":"update","data":[{"symbol":"BTC/JPY","bids":[],"asks":[{"price":10669951,"qty":0.00000000},{"price":10691000,"qty":0.00010000},{"price":10669949,"qty":0.13610672}],"checksum":1753300077,"timestamp":"2024-06-01T17:52:14.105257Z"}]}
{"channel":"book","type":"update","data":[{"symbol":"BTC/JPY","bids":[],"asks":[{"price":10669950,"qty":0.00000000},{"price":10691000,"qty":0.00010000}],"checksum":151924227,"timestamp":"2024-06-01T17:52:14.119204Z"}]}
{"channel":"book","type":"update","data":[{"symbol":"BTC/JPY","bids":[],"asks":[{"price":10669948,"qty":0.01129070}],"checksum":3500939598,"timestamp":"2024-06-01T17:52:14.120601Z"}]}
{"channel":"book","type":"update","data":[{"symbol":"BTC/JPY","bids":[],"asks":[{"price":10669949,"qty":0.00000000},{"price":10691000,"qty":0.00010000},{"price":10669947,"qty":0.13595641}],"checksum":2749238099,"timestamp":"2024-06-01T17:52:14.180759Z"}]}
{"channel":"book","type":"update","data":[{"symbol":"BTC/JPY","bids":[],"asks":[{"price":10669960,"qty":0.00000000},{"price":10691000,"qty":0.00010000}],"checksum":3519895302,"timestamp":"2024-06-01T17:52:14.444121Z"}]}
{"channel":"book","type":"update","data":[{"symbol":"BTC/JPY","bids":[],"asks":[{"price":10669946,"qty":0.01129070}],"checksum":551244377,"timestamp":"2024-06-01T17:52:15.467332Z"}]}
{"channel":"book","type":"update","data":[{"symbol":"BTC/JPY","bids":[],"asks":[{"price":10669948,"qty":0.00000000},{"price":10691000,"qty":0.00010000}],"checksum":4256790687,"timestamp":"2024-06-01T17:52:15.467350Z"}]}
{"channel":"book","type":"update","data":[{"symbol":"BTC/JPY","bids":[],"asks":[{"price":10669945,"qty":0.00529384}],"checksum":2972263330,"timestamp":"2024-06-01T17:52:15.507053Z"}]}
{"channel":"book","type":"update","data":[{"symbol":"BTC/JPY","bids":[],"asks":[{"price":10669947,"qty":0.00000000},{"price":10691000,"qty":0.00010000},{"price":10669945,"qty":0.14185071}],"checksum":1214452776,"timestamp":"2024-06-01T17:52:15.519024Z"}]}
{"channel":"book","type":"update","data":[{"symbol":"BTC/JPY","bids":[],"asks":[{"price":10669945,"qty":0.00529384},{"price":10669944,"qty":0.13651042}],"checksum":3007006701,"timestamp":"2024-06-01T17:52:15.571852Z"}]}
{"channel":"book","type":"update","data":[{"symbol":"BTC/JPY","bids":[],"asks":[{"price":10669946,"qty":0.00000000},{"price":10691000,"qty":0.00010000}],"checksum":177819744,"timestamp":"2024-06-01T17:52:16.467627Z"}]}
{"channel":"book","type":"update","data":[{"symbol":"BTC/JPY","bids":[],"asks":[{"price":10669943,"qty":0.01129070}],"checksum":3208765224,"timestamp":"2024-06-01T17:52:16.467640Z"}]}
{"channel":"book","type":"update","data":[{"symbol":"BTC/JPY","bids":[],"asks":[{"price":10669944,"qty":0.00000000},{"price":10691000,"qty":0.00010000},{"price":10669942,"qty":0.13527021}],"checksum":3828326452,"timestamp":"2024-06-01T17:52:16.525181Z"}]}
{"channel":"book","type":"update","data":[{"symbol":"BTC/JPY","bids":[],"asks":[{"price":10669943,"qty":0.00000000},{"price":10691000,"qty":0.00010000}],"checksum":657969232,"timestamp":"2024-06-01T17:52:16.529591Z"}]}
{"channel":"book","type":"update","data":[{"symbol":"BTC/JPY","bids":[],"asks":[{"price":10669941,"qty":0.01129070}],"checksum":294858617,"timestamp":"2024-06-01T17:52:16.529752Z"}]}
{"channel":"book","type":"update","data":[{"symbol":"BTC/JPY","bids":[],"asks":[{"price":10669942,"qty":0.00000000},{"price":10691000,"qty":0.00010000},{"price":10669940,"qty":0.13528244}],"checksum":2685178230,"timestamp":"2024-06-01T17:52:16.587488Z"}]}
{"channel":"book","type":"update","data":[{"symbol":"BTC/JPY","bids":[],"asks":[{"price":10669939,"qty":0.01129070}],"checksum":3201137301,"timestamp":"2024-06-01T17:52:17.875329Z"}]}
{"channel":"book","type":"update","data":[{"symbol":"BTC/JPY","bids":[],"asks":[{"price":10669941,"qty":0.00000000},{"price":10690999,"qty":1.31226123}],"checksum":1096321339,"timestamp":"2024-06-01T17:52:17.875394Z"}]}
{"channel":"book","type":"update","data":[{"symbol":"BTC/JPY","bids":[],"asks":[{"price":10669940,"qty":0.00000000},{"price":10691000,"qty":0.00010000},{"price":10669938,"qty":0.13469089}],"checksum":1807355607,"timestamp":"2024-06-01T17:52:17.928597Z"}]}
{"channel":"book","type":"update","data":[{"symbol":"BTC/JPY","bids":[],"asks":[{"price":10669937,"qty":0.01129070}],"checksum":89395568,"timestamp":"2024-06-01T17:52:17.940015Z"}]}
{"channel":"book","type":"update","data":[{"symbol":"BTC/JPY","bids":[],"asks":[{"price":10669939,"qty":0.00000000},{"price":10690999,"qty":1.31226123}],"checksum":312150197,"timestamp":"2024-06-01T17:52:17.940041Z"}]}
{"channel":"book","type":"update","data":[{"symbol":"BTC/JPY","bids":[],"asks":[{"price":10669938,"qty":0.00000000},{"price":10691000,"qty":0.00010000},{"price":10669936,"qty":0.13478652}],"checksum":3537149081,"timestamp":"2024-06-01T17:52:17.992450Z"}]}
{"channel":"book","type":"update","data":[{"symbol":"BTC/JPY","bids":[],"asks":[{"price":10669937,"qty":0.00000000},{"price":10691000,"qty":0.00010000}],"checksum":2424038683,"timestamp":"2024-06-01T17:52:18.868951Z"}]}
{"channel":"book","type":"update","data":[{"symbol":"BTC/JPY","bids":[],"asks":[{"price":10669935,"qty":0.01129070}],"checksum":1781664010,"timestamp":"2024-06-01T17:52:18.869164Z"}]}
{"channel":"book","type":"update","data":[{"symbol":"BTC/JPY","bids":[],"asks":[{"price":10669945,"qty":0.00000000},{"price":10691000,"qty":0.00010000}],"checksum":3026265779,"timestamp":"2024-06-01T17:52:18.902349Z"}]}
{"channel":"book","type":"update","data":[{"symbol":"BTC/JPY","bids":[],"asks":[{"price":10669936,"qty":0.00000000},{"price":10693737,"qty":2.42488434},{"price":10669934,"qty":0.13516375}],"checksum":2037838614,"timestamp":"2024-06-01T17:52:18.931883Z"}]}
{"channel":"book","type":"update","data":[{"symbol":"BTC/JPY","bids":[],"asks":[{"price":10669934,"qty":0.14045763}],"checksum":1680662464,"timestamp":"2024-06-01T17:52:18.934254Z"}]}
{"channel":"book","type":"update","data":[{"symbol":"BTC/JPY","bids":[],"asks":[{"price":10669933,"qty":0.01129070}],"checksum":1743540138,"timestamp":"2024-06-01T17:52:18.957317Z"}]}
{"channel":"book","type":"update","data":[{"symbol":"BTC/JPY","bids":[],"asks":[{"price":10669935,"qty":0.00000000},{"price":10691000,"qty":0.00010000}],"checksum":3844835137,"timestamp":"2024-06-01T17:52:18.957333Z"}]}
{"channel":"book","type":"update","data":[{"symbol":"BTC/JPY","bids":[],"asks":[{"price":10669934,"qty":0.00529388},{"price":10669933,"qty":0.14641383}],"checksum":952220051,"timestamp":"2024-06-01T17:52:18.991526Z"}]}
{"channel":"book","type":"update","data":[{"symbol":"BTC/JPY","bids":[],"asks":[{"price":10669933,"qty":0.01129070},{"price":10669932,"qty":0.13457753}],"checksum":2823137249,"timestamp":"2024-06-01T17:52:19.037127Z"}]}
{"channel":"book","type":"update","data":[{"symbol":"BTC/JPY","bids":[],"asks":[{"price":10680973,"qty":0.00000000},{"price":10691000,"qty":0.00010000}],"checksum":4237801674,"timestamp":"2024-06-01T17:52:19.554541Z"}]}
{"channel":"book","type":"update","data":[{"symbol":"BTC/JPY","bids":[],"asks":[{"price":10682733,"qty":1.21228296}],"checksum":1325211044,"timestamp":"2024-06-01T17:52:19.594847Z"}]}
{"channel":"book","type":"update","data":[{"symbol":"BTC/JPY","bids":[],"asks":[{"price":10669933,"qty":0.00000000},{"price":10691000,"qty":0.00010000}],"checksum":2122560195,"timestamp":"2024-06-01T17:52:20.252402Z"}]}
{"channel":"book","type":"update","data":[{"symbol":"BTC/JPY","bids":[],"asks":[{"price":10669931,"qty":0.01129070}],"checksum":3874415803,"timestamp":"2024-06-01T17:52:20.252580Z"}]}
{"channel":"book","type":"update","data":[{"symbol":"BTC/JPY","bids":[],"asks":[{"price":10669932,"qty":0.00000000},{"price":10691000,"qty":0.00010000},{"price":10669930,"qty":0.13442307}],"checksum":2327633882,"timestamp":"2024-06-01T17:52:20.295760Z"}]}
{"channel":"book","type":"update","data":[{"symbol":"BTC/JPY","bids":[],"asks":[{"price":10669931,"qty":0.00000000},{"price":10691000,"qty":0.00010000}],"checksum":2570000556,"timestamp":"2024-06-01T17:52:21.260952Z"}]}
{"channel":"book","type":"update","data":[{"symbol":"BTC/JPY","bids":[],"asks":[{"price":10669929,"qty":0.01129070}],"checksum":1627308248,"timestamp":"2024-06-01T17:52:21.261191Z"}]}
{"channel":"book","type":"update","data":[{"symbol":"BTC/JPY","bids":[],"asks":[{"price":10669930,"qty":0.00000000},{"price":10691000,"qty":0.00010000},{"price":10669928,"qty":0.13510707}],"checksum":3870300870,"timestamp":"2024-06-01T17:52:21.326082Z"}]}
{"channel":"book","type":"update","data":[{"symbol":"BTC/JPY","bids":[],"asks":[{"price":10669929,"qty":0.00000000},{"price":10691000,"qty":0.00010000}],"checksum":3028213767,"timestamp":"2024-06-01T17:52:21.331959Z"}]}
{"channel":"book","type":"update","data":[{"symbol":"BTC/JPY","bids":[],"asks":[{"price":10669927,"qty":0.01129070}],"checksum":3652237215,"timestamp":"2024-06-01T17:52:21.332087Z"}]}
{"channel":"book","type":"update","data":[{"symbol":"BTC/JPY","bids":[],"asks":[{"price":10669928,"qty":0.00000000},{"price":10691000,"qty":0.00010000},{"price":10669926,"qty":0.13503223}],"checksum":2780547507,"timestamp":"2024-06-01T17:52:21.383996Z"}]}
{"channel":"book","type":"update","data":[{"symbol":"BTC/JPY","bids":[],"asks":[{"price":10669925,"qty":0.01129070}],"checksum":3937881894,"timestamp":"2024-06-01T17:52:22.661614Z"}]}
{"channel":"book","type":"update","data":[{"symbol":"BTC/JPY","bids":[],"asks":[{"price":10669927,"qty":0.00000000},{"price":10690999,"qty":1.31226123}],"checksum":3336424540,"timestamp":"2024-06-01T17:52:22.661778Z"}]}
{"channel":"book","type":"update","data":[{"symbol":"BTC/JPY","bids":[],"asks":[{"price":10669934,"qty":0.00000000},{"price":10691000,"qty":0.00010000}],"checksum":949195710,"timestamp":"2024-06-01T17:52:22.693127Z"}]}
{"channel":"book","type":"update","data":[{"symbol":"BTC/JPY","bids":[],"asks":[{"price":10669926,"qty":0.00000000},{"price":10693737,"qty":2.42488434},{"price":10669924,"qty":0.13223057}],"checksum":1713514826,"timestamp":"2024-06-01T17:52:22.711131Z"}]}
{"channel":"book","type":"update","data":[{"symbol":"BTC/JPY","bids":[],"asks":[{"price":10669925,"qty":0.00000000},{"price":10693737,"qty":2.42488434}],"checksum":804434848,"timestamp":"2024-06-01T17:52:22.718369Z"}]}
{"channel":"book","type":"update","data":[{"symbol":"BTC/JPY","bids":[],"asks":[{"price":10669923,"qty":0.01129070}],"checksum":1546641644,"timestamp":"2024-06-01T17:52:22.718451Z"}]}
{"channel":"book","type":"update","data":[{"symbol":"BTC/JPY","bids":[],"asks":[{"price":10669924,"qty":0.13752440}],"checksum":3674402129,"timestamp":"2024-06-01T17:52:22.725445Z"}]}
{"channel":"book","type":"update","data":[{"symbol":"BTC/JPY","bids":[],"asks":[{"price":10669924,"qty":0.00529383},{"price":10669922,"qty":0.13257906}],"checksum":2291631212,"timestamp":"2024-06-01T17:52:22.773223Z"}]}
{"channel":"book","type":"update","data":[{"symbol":"BTC/JPY","bids":[],"asks":[{"price":10669923,"qty":0.00000000},{"price":10691000,"qty":0.00010000}],"checksum":2330164812,"timestamp":"2024-06-01T17:52:23.658946Z"}]}
{"channel":"book","type":"update","data":[{"symbol":"BTC/JPY","bids":[],"asks":[{"price":10669921,"qty":0.01129070}],"checksum":3702170764,"timestamp":"2024-06-01T17:52:23.659074Z"}]}
{"channel":"book","type":"update","data":[{"symbol":"BTC/JPY","bids":[],"asks":[{"price":10669922,"qty":0.00000000},{"price":10691000,"qty":0.00010000},{"price":10669920,"qty":0.12965093}],"checksum":3402847831,"timestamp":"2024-06-01T17:52:23.712601Z"}]}
{"channel":"book","type":"update","data":[{"symbol":"BTC/JPY","bids":[],"asks":[{"price":10669919,"qty":0.01129070}],"checksum":599896642,"timestamp":"2024-06-01T17:52:23.725877Z"}]}
{"channel":"book","type":"update","data":[{"symbol":"BTC/JPY","bids":[],"asks":[{"price":10669921,"qty":0.00000000},{"price":10690999,"qty":1.31226123}],"checksum":2695400817,"timestamp":"2024-06-01T17:52:23.725989Z"}]}
{"channel":"book","type":"update","data":[{"symbol":"BTC/JPY","bids":[],"asks":[{"price":10669920,"qty":0.00000000},{"price":10691000,"qty":0.00010000},{"price":10669918,"qty":0.12986480}],"checksum":4035202359,"timestamp":"2024-06-01T17:52:23.775846Z"}]}
{"channel":"book","type":"update","data":[{"symbol":"BTC/JPY","bids":[],"asks":[{"price":10669917,"qty":0.01129070}],"checksum":2771000383,"timestamp":"2024-06-01T17:52:25.042356Z"}]}
{"channel":"book","type":"update","data":[{"symbol":"BTC/JPY","bids":[],"asks":[{"price":10669919,"qty":0.00000000},{"price":10690999,"qty":1.31226123}],"checksum":4053827507,"timestamp":"2024-06-01T17:52:25.042714Z"}]}
{"channel":"book","type":"update","data":[{"symbol":"BTC/JPY","bids":[],"asks":[{"price":10669918,"qty":0.00000000},{"price":10691000,"qty":0.00010000},{"price":10669916,"qty":0.13216792}],"checksum":2081536861,"timestamp":"2024-06-01T17:52:25.104695Z"}]}
{"channel":"book","type":"update","data":[{"symbol":"BTC/JPY","bids":[],"asks":[{"price":10669917,"qty":0.00000000},{"price":10691000,"qty":0.00010000}],"checksum":3933045532,"timestamp":"2024-06-01T17:52:25.108213Z"}]}
{"channel":"book","type":"update","data":[{"symbol":"BTC/JPY","bids":[],"asks":[{"price":10669915,"qty":0.01129070}],"checksum":3756072997,"timestamp":"2024-06-01T17:52:25.108360Z"}]}
{"channel":"book","type":"update","data":[{"symbol":"BTC/JPY","bids":[],"asks":[{"price":10669916,"qty":0.00000000},{"price":10691000,"qty":0.00010000},{"price":10669914,"qty":0.13213939}],"checksum":3518355109,"timestamp":"2024-06-01T17:52:25.165233Z"}]}
{"channel":"book","type":"update","data":[{"symbol":"BTC/JPY","bids":[],"asks":[{"price":10669913,"qty":0.01129070}],"checksum":1403516445,"timestamp":"2024-06-01T17:52:26.046548Z"}]}
{"channel":"book","type":"update","data":[{"symbol":"BTC/JPY","bids":[],"asks":[{"price":10669915,"qty":0.00000000},{"price":10690999,"qty":1.31226123}],"checksum":4275484136,"timestamp":"2024-06-01T17:52:26.046733Z"}]}
{"channel":"book","type":"update","data":[{"symbol":"BTC/JPY","bids":[],"asks":[{"price":10669924,"qty":0.00000000},{"price":10691000,"qty":0.00010000}],"checksum":1534263070,"timestamp":"2024-06-01T17:52:26.087648Z"}]}
{"channel":"book","type":"update","data":[{"symbol":"BTC/JPY","bids":[],"asks":[{"price":10669914,"qty":0.00000000},{"price":10693737,"qty":2.42488434},{"price":10669912,"qty":0.13197994}],"checksum":4125767285,"timestamp":"2024-06-01T17:52:26.104415Z"}]}
{"channel":"book","type":"update","data":[{"symbol":"BTC/JPY","bids":[],"asks":[{"price":10669913,"qty":0.00000000},{"price":10693737,"qty":2.42488434}],"checksum":333100032,"timestamp":"2024-06-01T17:52:27.464026Z"}]}
{"channel":"book","type":"update","data":[{"symbol":"BTC/JPY","bids":[],"asks":[{"price":10669911,"qty":0.01129070}],"checksum":2828794712,"timestamp":"2024-06-01T17:52:27.464190Z"}]}
{"channel":"book","type":"update","data":[{"symbol":"BTC/JPY","bids":[],"asks":[{"price":10669911,"qty":0.01658454}],"checksum":3060672282,"timestamp":"2024-06-01T17:52:27.497485Z"}]}
{"channel":"book","type":"update","data":[{"symbol":"BTC/JPY","bids":[],"asks":[{"price":10669912,"qty":0.00000000},{"price":10693737,"qty":2.42488434},{"price":10669910,"qty":0.13146250}],"checksum":911446189,"timestamp":"2024-06-01T17:52:27.526051Z"}]}
{"channel":"book","type":"update","data":[{"symbol":"BTC/JPY","bids":[],"asks":[{"price":10669909,"qty":0.01129070}],"checksum":1913168317,"timestamp":"2024-06-01T17:52:27.533347Z"}]}
{"channel":"book","type":"update","data":[{"symbol":"BTC/JPY","bids":[],"asks":[{"price":10669911,"qty":0.00529384}],"checksum":3152147349,"timestamp":"2024-06-01T17:52:27.533430Z"}]}
{"channel":"book","type":"update","data":[{"symbol":"BTC/JPY","bids":[],"asks":[{"price":10669910,"qty":0.00000000},{"price":10691000,"qty":0.00010000},{"price":10669908,"qty":0.13146305}],"checksum":44710973,"timestamp":"2024-06-01T17:52:27.581568Z"}]}
{"channel":"book","type":"update","data":[{"symbol":"BTC/JPY","bids":[],"asks":[{"price":10669907,"qty":0.01129070}],"checksum":1068850713,"timestamp":"2024-06-01T17:52:28.467716Z"}]}
{"channel":"book","type":"update","data":[{"symbol":"BTC/JPY","bids":[],"asks":[{"price":10669909,"qty":0.00000000},{"price":10690999,"qty":1.31226123}],"checksum":3512542681,"timestamp":"2024-06-01T17:52:28.467743Z"}]}
{"channel":"book","type":"update","data":[{"symbol":"BTC/JPY","bids":[],"asks":[{"price":10669908,"qty":0.00000000},{"price":10691000,"qty":0.00010000},{"price":10669906,"qty":0.13105600}],"checksum":2810555154,"timestamp":"2024-06-01T17:52:28.524713Z"}]}
{"channel":"book","type":"update","data":[{"symbol":"BTC/JPY","bids":[],"asks":[{"price":10669907,"qty":0.00000000},{"price":10691000,"qty":0.00010000}],"checksum":209710139,"timestamp":"2024-06-01T17:52:28.547954Z"}]}
{"channel":"book","type":"update","data":[{"symbol":"BTC/JPY","bids":[],"asks":[{"price":10669905,"qty":0.01129070}],"checksum":1518329489,"timestamp":"2024-06-01T17:52:28.548020Z"}]}
{"channel":"book","type":"update","data":[{"symbol":"BTC/JPY","bids":[],"asks":[{"price":10669906,"qty":0.00000000},{"price":10691000,"qty":0.00010000},{"price":10669904,"qty":0.13103310}],"checksum":2092858260,"timestamp":"2024-06-01T17:52:28.608041Z"}]}
{"channel":"book","type":"update","data":[{"symbol":"BTC/JPY","bids":[],"asks":[{"price":10669905,"qty":0.00000000},{"price":10691000,"qty":0.00010000}],"checksum":1890053556,"timestamp":"2024-06-01T17:52:29.851464Z"}]}
{"channel":"book","type":"update","data":[{"symbol":"BTC/JPY","bids":[],"asks":[{"price":10669903,"qty":0.01129070}],"checksum":1733376003,"timestamp":"2024-06-01T17:52:29.851513Z"}]}
{"channel":"book","type":"update","data":[{"symbol":"BTC/JPY","bids":[],"asks":[{"price":10669904,"qty":0.00000000},{"price":10691000,"qty":0.00010000},{"price":10669902,"qty":0.12842780}],"checksum":3395150406,"timestamp":"2024-06-01T17:52:29.952950Z"}]}
{"channel":"book","type":"update","data":[{"symbol":"BTC/JPY","bids":[],"asks":[{"price":10669903,"qty":0.00000000},{"price":10691000,"qty":0.00010000}],"checksum":2689084104,"timestamp":"2024-06-01T17:52:29.978158Z"}]}
{"channel":"book","type":"update","data":[{"symbol":"BTC/JPY","bids":[],"asks":[{"price":10669901,"qty":0.01129070}],"checksum":2256702483,"timestamp":"2024-06-01T17:52:29.978206Z"}]}
{"channel":"book","type":"update","data":[{"symbol":"BTC/JPY","bids":[],"asks":[{"price":10669902,"qty":0.00000000},{"price":10691000,"qty":0.00010000},{"price":10669900,"qty":0.12840730}],"checksum":1913498130,"timestamp":"2024-06-01T17:52:30.024192Z"}]}
{"channel":"book","type":"update","data":[{"symbol":"BTC/JPY","bids":[],"asks":[{"price":10669899,"qty":0.01129070}],"checksum":3216999005,"timestamp":"2024-06-01T17:52:30.859681Z"}]}
{"channel":"book","type":"update","data":[{"symbol":"BTC/JPY","bids":[],"asks":[{"price":10669901,"qty":0.00000000},{"price":10690999,"qty":1.31226123}],"checksum":2051010509,"timestamp":"2024-06-01T17:52:30.860312Z"}]}
{"channel":"book","type":"update","data":[{"symbol":"BTC/JPY","bids":[],"asks":[{"price":10669911,"qty":0.00000000},{"price":10691000,"qty":0.00010000}],"checksum":1992067898,"timestamp":"2024-06-01T17:52:30.896909Z"}]}
{"channel":"book","type":"update","data":[{"symbol":"BTC/JPY","bids":[],"asks":[{"price":10669900,"qty":0.00000000},{"price":10693737,"qty":2.42488434},{"price":10669898,"qty":0.12664092}],"checksum":3737464681,"timestamp":"2024-06-01T17:52:30.927303Z"}]}
{"channel":"book","type":"update","data":[{"symbol":"BTC/JPY","bids":[],"asks":[{"price":10669899,"qty":0.00000000},{"price":10693737,"qty":2.42488434}],"checksum":43935678,"timestamp":"2024-06-01T17:52:32.264161Z"}]}
{"channel":"book","type":"update","data":[{"symbol":"BTC/JPY","bids":[],"asks":[{"price":10669897,"qty":0.01129070}],"checksum":4260258639,"timestamp":"2024-06-01T17:52:32.264359Z"}]}
{"channel":"book","type":"update","data":[{"symbol":"BTC/JPY","bids":[],"asks":[{"price":10669898,"qty":0.00000000},{"price":10693737,"qty":2.42488434},{"price":10669896,"qty":0.12247152}],"checksum":1212996317,"timestamp":"2024-06-01T17:52:32.317297Z"}]}
{"channel":"book","type":"update","data":[{"symbol":"BTC/JPY","bids":[],"asks":[{"price":10669895,"qty":0.01129070}],"checksum":2838369501,"timestamp":"2024-06-01T17:52:32.325266Z"}]}
{"channel":"book","type":"update","data":[{"symbol":"BTC/JPY","bids":[],"asks":[{"price":10669897,"qty":0.00000000},{"price":10691000,"qty":0.00010000}],"checksum":2498562710,"timestamp":"2024-06-01T17:52:32.325563Z"}]}
{"channel":"book","type":"update","data":[{"symbol":"BTC/JPY","bids":[],"asks":[{"price":10669896,"qty":0.00000000},{"price":10693737,"qty":2.42488434},{"price":10669894,"qty":0.12287548}],"checksum":3554040753,"timestamp":"2024-06-01T17:52:32.384907Z"}]}
{"channel":"book","type":"update","data":[{"symbol":"BTC/JPY","bids":[],"asks":[{"price":10669895,"qty":0.00000000},{"price":10693737,"qty":2.42488434}],"checksum":3296356628,"timestamp":"2024-06-01T17:52:33.266537Z"}]}
{"channel":"book","type":"update","data":[{"symbol":"BTC/JPY","bids":[],"asks":[{"price":10669893,"qty":0.01129070}],"checksum":1030436843,"timestamp":"2024-06-01T17:52:33.266608Z"}]}
{"channel":"book","type":"update","data":[{"symbol":"BTC/JPY","bids":[],"asks":[{"price":10669893,"qty":0.01658457}],"checksum":3058277389,"timestamp":"2024-06-01T17:52:33.298172Z"}]}
{"channel":"book","type":"update","data":[{"symbol":"BTC/JPY","bids":[],"asks":[{"price":10669894,"qty":0.00000000},{"price":10693737,"qty":2.42488434},{"price":10669892,"qty":0.12894771}],"checksum":4079880834,"timestamp":"2024-06-01T17:52:33.321500Z"}]}
{"channel":"book","type":"update","data":[{"symbol":"BTC/JPY","bids":[],"asks":[{"price":10669893,"qty":0.00529387}],"checksum":295810726,"timestamp":"2024-06-01T17:52:33.350931Z"}]}
{"channel":"book","type":"update","data":[{"symbol":"BTC/JPY","bids":[],"asks":[{"price":10669891,"qty":0.01129070}],"checksum":2441336320,"timestamp":"2024-06-01T17:52:33.351167Z"}]}
{"channel":"book","type":"update","data":[{"symbol":"BTC/JPY","bids":[],"asks":[{"price":10669892,"qty":0.00000000},{"price":10691000,"qty":0.00010000},{"price":10669890,"qty":0.12941139}],"checksum":3113354008,"timestamp":"2024-06-01T17:52:33.421175Z"}]}
