{"channel":"book","type":"snapshot","data":[{"symbol":"BTC/GBP","bids":[{"price":53041.3,"qty":0.36978059},{"price":53041.2,"qty":0.00097400},{"price":53039.3,"qty":0.36979435},{"price":53037.3,"qty":0.36980810},{"price":53036.1,"qty":0.17686451},{"price":53033.6,"qty":0.36983401},{"price":53023.1,"qty":0.30186774},{"price":53019.0,"qty":0.36993562},{"price":53011.2,"qty":0.36999006},{"price":52992.4,"qty":0.37012042}],"asks":[{"price":53047.6,"qty":0.36973667},{"price":53047.8,"qty":0.36973528},{"price":53048.1,"qty":0.00931900},{"price":53048.9,"qty":0.01522000},{"price":53049.2,"qty":0.02900000},{"price":53050.6,"qty":0.00097400},{"price":53051.3,"qty":0.36971095},{"price":53055.9,"qty":0.00135200},{"price":53056.7,"qty":0.36967383},{"price":53066.5,"qty":0.01129070}],"checksum":3448331951}]}
{"channel":"book","type":"update","data":[{"symbol":"BTC/GBP","bids":[],"asks":[{"price":53047.8,"qty":0.00000000},{"price":53066.6,"qty":0.16769151}],"checksum":560385157,"timestamp":"2024-06-01T17:51:30.455422Z"}]}
{"channel":"book","type":"update","data":[{"symbol":"BTC/GBP","bids":[],"asks":[{"price":53046.5,"qty":0.36974458}],"checksum":2901955397,"timestamp":"2024-06-01T17:51:30.459193Z"}]}
{"channel":"book","type":"update","data":[{"symbol":"BTC/GBP","bids":[{"price":53037.3,"qty":0.00000000},{"price":52986.6,"qty":0.00135300}],"asks":[],"checksum":1258998654,"timestamp":"2024-06-01T17:51:30.869992Z"}]}
{"channel":"book","type":"update","data":[{"symbol":"BTC/GBP","bids":[{"price":53042.3,"qty":0.36977351}],"asks":[],"checksum":1182800048,"timestamp":"2024-06-01T17:51:30.873565Z"}]}
{"channel":"book","type":"update","data":[{"symbol":"BTC/GBP","bids":[{"price":53042.3,"qty":0.00000000},{"price":52986.6,"qty":0.00135300}],"asks":[],"checksum":1258998654,"timestamp":"2024-06-01T17:51:31.501968Z"}]}
{"channel":"book","type":"update","data":[{"symbol":"BTC/GBP","bids":[{"price":53037.3,"qty":0.36980805}],"asks":[],"checksum":332058538,"timestamp":"2024-06-01T17:51:31.506535Z"}]}
{"channel":"book","type":"update","data":[{"symbol":"BTC/GBP","bids":[{"price":53041.4,"qty":0.00813712}],"asks":[],"checksum":1770762114,"timestamp":"2024-06-01T17:51:33.364649Z"}]}
{"channel":"book","type":"update","data":[{"symbol":"BTC/GBP","bids":[{"price":53037.3,"qty":0.00000000},{"price":52992.4,"qty":0.37012042}],"asks":[],"checksum":3923427801,"timestamp":"2024-06-01T17:51:33.373232Z"}]}
{"channel":"book","type":"update","data":[{"symbol":"BTC/GBP","bids":[{"price":53041.3,"qty":0.00000000},{"price":52986.6,"qty":0.00135300}],"asks":[],"checksum":737825357,"timestamp":"2024-06-01T17:51:33.373331Z"}]}
{"channel":"book","type":"update","data":[{"symbol":"BTC/GBP","bids":[{"price":53042.6,"qty":0.36977101}],"asks":[],"checksum":3687232855,"timestamp":"2024-06-01T17:51:33.377799Z"}]}
{"channel":"book","type":"update","data":[{"symbol":"BTC/GBP","bids":[{"price":53041.5,"qty":0.36977920}],"asks":[],"checksum":3951701814,"timestamp":"2024-06-01T17:51:33.377812Z"}]}
{"channel":"book","type":"update","data":[{"symbol":"BTC/GBP","bids":[{"price":53041.4,"qty":0.00000000},{"price":52992.4,"qty":0.37012042}],"asks":[],"checksum":3466456282,"timestamp":"2024-06-01T17:51:33.381429Z"}]}
{"channel":"book","type":"update","data":[{"symbol":"BTC/GBP","bids":[],"asks":[{"price":53046.5,"qty":0.00000000},{"price":53066.6,"qty":0.16769151}],"checksum":1124299546,"timestamp":"2024-06-01T17:51:33.388278Z"}]}
{"channel":"book","type":"update","data":[{"symbol":"BTC/GBP","bids":[{"price":53042.6,"qty":0.00000000},{"price":52986.6,"qty":0.00135300}],"asks":[],"checksum":2636571227,"timestamp":"2024-06-01T17:51:33.394666Z"}]}
{"channel":"book","type":"update","data":[{"symbol":"BTC/GBP","bids":[{"price":53041.5,"qty":0.00000000},{"price":52986.5,"qty":0.01360000}],"asks":[],"checksum":937792282,"timestamp":"2024-06-01T17:51:33.394768Z"}]}
{"channel":"book","type":"update","data":[{"symbol":"BTC/GBP","bids":[{"price":53041.6,"qty":0.00813669}],"asks":[],"checksum":1948440476,"timestamp":"2024-06-01T17:51:33.398702Z"}]}
{"channel":"book","type":"update","data":[{"symbol":"BTC/GBP","bids":[],"asks":[{"price":53051.7,"qty":0.36970813}],"checksum":2908697537,"timestamp":"2024-06-01T17:51:33.399939Z"}]}
{"channel":"book","type":"update","data":[{"symbol":"BTC/GBP","bids":[],"asks":[{"price":53066.5,"qty":0.00000000},{"price":53071.1,"qty":0.36957222}],"checksum":1420440421,"timestamp":"2024-06-01T17:51:33.467416Z"}]}
{"channel":"book","type":"update","data":[{"symbol":"BTC/GBP","bids":[],"asks":[{"price":53071.0,"qty":0.01129070}],"checksum":184546675,"timestamp":"2024-06-01T17:51:33.467449Z"}]}
{"channel":"book","type":"update","data":[{"symbol":"BTC/GBP","bids":[],"asks":[{"price":53055.9,"qty":0.00000000},{"price":53071.1,"qty":0.36957222},{"price":53053.1,"qty":0.00135200}],"checksum":392858816,"timestamp":"2024-06-01T17:51:33.523684Z"}]}
{"channel":"book","type":"update","data":[{"symbol":"BTC/GBP","bids":[{"price":53043.7,"qty":0.36976345}],"asks":[],"checksum":3426472546,"timestamp":"2024-06-01T17:51:33.571225Z"}]}
{"channel":"book","type":"update","data":[{"symbol":"BTC/GBP","bids":[{"price":53041.7,"qty":0.36977780}],"asks":[],"checksum":3932577717,"timestamp":"2024-06-01T17:51:33.571440Z"}]}
{"channel":"book","type":"update","data":[{"symbol":"BTC/GBP","bids":[{"price":53041.6,"qty":0.00000000},{"price":52992.4,"qty":0.37012042}],"asks":[],"checksum":452724363,"timestamp":"2024-06-01T17:51:33.575980Z"}]}
{"channel":"book","type":"update","data":[{"symbol":"BTC/GBP","bids":[],"asks":[{"price":53047.6,"qty":0.00000000},{"price":53071.1,"qty":0.36957222}],"checksum":845459273,"timestamp":"2024-06-01T17:51:34.336996Z"}]}
{"channel":"book","type":"update","data":[{"symbol":"BTC/GBP","bids":[{"price":53041.7,"qty":0.00000000},{"price":52986.6,"qty":0.00135300}],"asks":[],"checksum":3097117932,"timestamp":"2024-06-01T17:51:34.337033Z"}]}
{"channel":"book","type":"update","data":[{"symbol":"BTC/GBP","bids":[],"asks":[{"price":53051.3,"qty":0.00000000},{"price":53077.7,"qty":0.00032928}],"checksum":1837234568,"timestamp":"2024-06-01T17:51:34.337087Z"}]}
{"channel":"book","type":"update","data":[{"symbol":"BTC/GBP","bids":[{"price":53033.6,"qty":0.00000000},{"price":52986.5,"qty":0.01360000}],"asks":[],"checksum":428818550,"timestamp":"2024-06-01T17:51:34.337136Z"}]}
{"channel":"book","type":"update","data":[{"symbol":"BTC/GBP","bids":[],"asks":[{"price":53057.2,"qty":0.36967036}],"checksum":3384251936,"timestamp":"2024-06-01T17:51:34.351531Z"}]}
{"channel":"book","type":"update","data":[{"symbol":"BTC/GBP","bids":[{"price":53047.3,"qty":0.36973825}],"asks":[],"checksum":986975921,"timestamp":"2024-06-01T17:51:34.351592Z"}]}
{"channel":"book","type":"update","data":[{"symbol":"BTC/GBP","bids":[],"asks":[{"price":53061.2,"qty":0.36964233}],"checksum":715769315,"timestamp":"2024-06-01T17:51:34.351607Z"}]}
{"channel":"book","type":"update","data":[{"symbol":"BTC/GBP","bids":[{"price":53043.8,"qty":0.36976316}],"asks":[],"checksum":2716768056,"timestamp":"2024-06-01T17:51:34.351694Z"}]}
{"channel":"book","type":"update","data":[{"symbol":"BTC/GBP","bids":[],"asks":[{"price":53071.0,"qty":0.00000000},{"price":53071.1,"qty":0.36957222}],"checksum":2233460098,"timestamp":"2024-06-01T17:51:34.352657Z"}]}
{"channel":"book","type":"update","data":[{"symbol":"BTC/GBP","bids":[{"price":53048.0,"qty":0.14781329}],"asks":[],"checksum":2904838723,"timestamp":"2024-06-01T17:51:34.353397Z"}]}
{"channel":"book","type":"update","data":[{"symbol":"BTC/GBP","bids":[{"price":53036.1,"qty":0.02900000}],"asks":[],"checksum":2702595995,"timestamp":"2024-06-01T17:51:34.356453Z"}]}
{"channel":"book","type":"update","data":[{"symbol":"BTC/GBP","bids":[],"asks":[{"price":53051.1,"qty":0.02900000}],"checksum":3531179797,"timestamp":"2024-06-01T17:51:34.357984Z"}]}
{"channel":"book","type":"update","data":[{"symbol":"BTC/GBP","bids":[],"asks":[{"price":53049.2,"qty":0.00000000},{"price":53071.1,"qty":0.36957222}],"checksum":2267726107,"timestamp":"2024-06-01T17:51:34.358027Z"}]}
{"channel":"book","type":"update","data":[{"symbol":"BTC/GBP","bids":[{"price":53043.7,"qty":0.00000000},{"price":52992.4,"qty":0.37012042}],"asks":[],"checksum":3106649279,"timestamp":"2024-06-01T17:51:34.360077Z"}]}
{"channel":"book","type":"update","data":[{"symbol":"BTC/GBP","bids":[{"price":53043.8,"qty":0.73952632}],"asks":[],"checksum":3374703024,"timestamp":"2024-06-01T17:51:34.364018Z"}]}
{"channel":"book","type":"update","data":[{"symbol":"BTC/GBP","bids":[{"price":53048.0,"qty":0.00000000},{"price":52986.6,"qty":0.00135300}],"asks":[],"checksum":1718656422,"timestamp":"2024-06-01T17:51:34.386095Z"}]}
{"channel":"book","type":"update","data":[{"symbol":"BTC/GBP","bids":[{"price":53019.0,"qty":0.00000000},{"price":52986.5,"qty":0.01360000}],"asks":[],"checksum":186217585,"timestamp":"2024-06-01T17:51:34.392213Z"}]}
{"channel":"book","type":"update","data":[{"symbol":"BTC/GBP","bids":[{"price":53043.8,"qty":0.36976316}],"asks":[],"checksum":2739832761,"timestamp":"2024-06-01T17:51:34.392228Z"}]}
{"channel":"book","type":"update","data":[{"symbol":"BTC/GBP","bids":[],"asks":[{"price":53051.7,"qty":0.00000000},{"price":53077.7,"qty":0.00032928}],"checksum":2201106810,"timestamp":"2024-06-01T17:51:34.392309Z"}]}
{"channel":"book","type":"update","data":[{"symbol":"BTC/GBP","bids":[],"asks":[{"price":53056.6,"qty":0.00471418}],"checksum":3818652594,"timestamp":"2024-06-01T17:51:34.396310Z"}]}
{"channel":"book","type":"update","data":[{"symbol":"BTC/GBP","bids":[],"asks":[{"price":53054.2,"qty":0.36969117}],"checksum":2206292758,"timestamp":"2024-06-01T17:51:34.397252Z"}]}
{"channel":"book","type":"update","data":[{"symbol":"BTC/GBP","bids":[{"price":53027.0,"qty":0.36987991}],"asks":[],"checksum":2154156738,"timestamp":"2024-06-01T17:51:34.397360Z"}]}
{"channel":"book","type":"update","data":[{"symbol":"BTC/GBP","bids":[],"asks":[{"price":53056.6,"qty":0.00000000},{"price":53071.1,"qty":0.36957222}],"checksum":2455587989,"timestamp":"2024-06-01T17:51:34.401407Z"}]}
{"channel":"book","type":"update","data":[{"symbol":"BTC/GBP","bids":[{"price":53047.3,"qty":0.00000000},{"price":52986.5,"qty":0.01360000}],"asks":[],"checksum":102997787,"timestamp":"2024-06-01T17:51:34.426558Z"}]}
{"channel":"book","type":"update","data":[{"symbol":"BTC/GBP","bids":[{"price":53036.1,"qty":0.00000000},{"price":52981.1,"qty":0.04239626}],"asks":[],"checksum":1897250482,"timestamp":"2024-06-01T17:51:34.429475Z"}]}
{"channel":"book","type":"update","data":[{"symbol":"BTC/GBP","bids":[{"price":53043.9,"qty":0.02900000}],"asks":[],"checksum":1148866671,"timestamp":"2024-06-01T17:51:34.429640Z"}]}
{"channel":"book","type":"update","data":[{"symbol":"BTC/GBP","bids":[{"price":53043.8,"qty":0.00000000},{"price":52981.1,"qty":0.04239626}],"asks":[],"checksum":1197346768,"timestamp":"2024-06-01T17:51:34.430968Z"}]}
{"channel":"book","type":"update","data":[{"symbol":"BTC/GBP","bids":[{"price":53043.9,"qty":0.03713641}],"asks":[],"checksum":1342908437,"timestamp":"2024-06-01T17:51:34.431211Z"}]}
{"channel":"book","type":"update","data":[{"symbol":"BTC/GBP","bids":[{"price":53043.9,"qty":0.00813641}],"asks":[],"checksum":3318903422,"timestamp":"2024-06-01T17:51:34.433624Z"}]}
{"channel":"book","type":"update","data":[{"symbol":"BTC/GBP","bids":[{"price":53041.8,"qty":0.02900000}],"asks":[],"checksum":3029549400,"timestamp":"2024-06-01T17:51:34.433667Z"}]}
{"channel":"book","type":"update","data":[{"symbol":"BTC/GBP","bids":[],"asks":[{"price":53057.2,"qty":0.00000000},{"price":53077.7,"qty":0.00032928}],"checksum":3307736628,"timestamp":"2024-06-01T17:51:34.435942Z"}]}
{"channel":"book","type":"update","data":[{"symbol":"BTC/GBP","bids":[],"asks":[{"price":53071.1,"qty":0.00000000},{"price":53081.7,"qty":0.19906855}],"checksum":2986096972,"timestamp":"2024-06-01T17:51:34.436026Z"}]}
{"channel":"book","type":"update","data":[{"symbol":"BTC/GBP","bids":[{"price":53043.9,"qty":0.00000000},{"price":52981.1,"qty":0.04239626}],"asks":[],"checksum":3331754206,"timestamp":"2024-06-01T17:51:34.437751Z"}]}
{"channel":"book","type":"update","data":[{"symbol":"BTC/GBP","bids":[{"price":53041.9,"qty":0.00813639}],"asks":[],"checksum":725748962,"timestamp":"2024-06-01T17:51:34.437911Z"}]}
{"channel":"book","type":"update","data":[{"symbol":"BTC/GBP","bids":[],"asks":[{"price":53054.2,"qty":0.00000000},{"price":53081.8,"qty":0.07402000}],"checksum":792457923,"timestamp":"2024-06-01T17:51:34.437970Z"}]}
{"channel":"book","type":"update","data":[{"symbol":"BTC/GBP","bids":[{"price":53042.3,"qty":0.14784671}],"asks":[],"checksum":2086675512,"timestamp":"2024-06-01T17:51:34.440772Z"}]}
{"channel":"book","type":"update","data":[{"symbol":"BTC/GBP","bids":[{"price":53041.9,"qty":0.00000000},{"price":52986.5,"qty":0.01360000}],"asks":[],"checksum":998993277,"timestamp":"2024-06-01T17:51:34.441717Z"}]}
{"channel":"book","type":"update","data":[{"symbol":"BTC/GBP","bids":[],"asks":[{"price":53056.6,"qty":0.00471418}],"checksum":3835704762,"timestamp":"2024-06-01T17:51:34.441872Z"}]}
{"channel":"book","type":"update","data":[{"symbol":"BTC/GBP","bids":[{"price":52996.2,"qty":0.01464000}],"asks":[],"checksum":3727241146,"timestamp":"2024-06-01T17:51:34.443062Z"}]}
{"channel":"book","type":"update","data":[{"symbol":"BTC/GBP","bids":[],"asks":[{"price":53057.0,"qty":0.36967179}],"checksum":2065488126,"timestamp":"2024-06-01T17:51:34.443082Z"}]}
{"channel":"book","type":"update","data":[{"symbol":"BTC/GBP","bids":[{"price":53039.3,"qty":0.00000000},{"price":52986.5,"qty":0.01360000}],"asks":[],"checksum":2301665481,"timestamp":"2024-06-01T17:51:34.443163Z"}]}
{"channel":"book","type":"update","data":[{"symbol":"BTC/GBP","bids":[],"asks":[{"price":53051.1,"qty":0.00000000},{"price":53081.7,"qty":0.19906855}],"checksum":4019362557,"timestamp":"2024-06-01T17:51:34.443778Z"}]}
{"channel":"book","type":"update","data":[{"symbol":"BTC/GBP","bids":[{"price":53042.9,"qty":0.02900000}],"asks":[],"checksum":1091189232,"timestamp":"2024-06-01T17:51:34.443853Z"}]}
{"channel":"book","type":"update","data":[{"symbol":"BTC/GBP","bids":[{"price":53041.8,"qty":0.00000000},{"price":52986.5,"qty":0.01360000}],"asks":[],"checksum":469582844,"timestamp":"2024-06-01T17:51:34.443897Z"}]}
{"channel":"book","type":"update","data":[{"symbol":"BTC/GBP","bids":[],"asks":[{"price":53056.1,"qty":0.02900000}],"checksum":461027128,"timestamp":"2024-06-01T17:51:34.444226Z"}]}
{"channel":"book","type":"update","data":[{"symbol":"BTC/GBP","bids":[{"price":53042.0,"qty":0.36977571}],"asks":[],"checksum":183586719,"timestamp":"2024-06-01T17:51:34.446869Z"}]}
{"channel":"book","type":"update","data":[{"symbol":"BTC/GBP","bids":[{"price":53043.2,"qty":0.14784486}],"asks":[],"checksum":368475768,"timestamp":"2024-06-01T17:51:34.446957Z"}]}
{"channel":"book","type":"update","data":[{"symbol":"BTC/GBP","bids":[{"price":53042.3,"qty":0.00000000},{"price":52986.6,"qty":0.00135300}],"asks":[],"checksum":455185196,"timestamp":"2024-06-01T17:51:34.447070Z"}]}
{"channel":"book","type":"update","data":[{"symbol":"BTC/GBP","bids":[],"asks":[{"price":53056.6,"qty":0.00000000},{"price":53081.7,"qty":0.19906855}],"checksum":2272035034,"timestamp":"2024-06-01T17:51:34.448265Z"}]}
{"channel":"book","type":"update","data":[{"symbol":"BTC/GBP","bids":[{"price":53042.9,"qty":0.00000000},{"price":52986.5,"qty":0.01360000}],"asks":[],"checksum":305345802,"timestamp":"2024-06-01T17:51:34.449768Z"}]}
{"channel":"book","type":"update","data":[{"symbol":"BTC/GBP","bids":[{"price":53043.8,"qty":0.02900000}],"asks":[],"checksum":3122411556,"timestamp":"2024-06-01T17:51:34.450419Z"}]}
{"channel":"book","type":"update","data":[{"symbol":"BTC/GBP","bids":[{"price":53048.0,"qty":0.36973389}],"asks":[],"checksum":412285908,"timestamp":"2024-06-01T17:51:34.451155Z"}]}
{"channel":"book","type":"update","data":[{"symbol":"BTC/GBP","bids":[],"asks":[{"price":53056.0,"qty":0.00471418}],"checksum":2288092762,"timestamp":"2024-06-01T17:51:34.452596Z"}]}
{"channel":"book","type":"update","data":[{"symbol":"BTC/GBP","bids":[],"asks":[{"price":53057.0,"qty":0.00000000},{"price":53081.7,"qty":0.19906855}],"checksum":1068355281,"timestamp":"2024-06-01T17:51:34.453569Z"}]}
{"channel":"book","type":"update","data":[{"symbol":"BTC/GBP","bids":[],"asks":[{"price":53055.4,"qty":0.36968247}],"checksum":4265729828,"timestamp":"2024-06-01T17:51:34.456800Z"}]}
{"channel":"book","type":"update","data":[{"symbol":"BTC/GBP","bids":[],"asks":[{"price":53056.1,"qty":0.00000000},{"price":53081.7,"qty":0.19906855}],"checksum":3079818331,"timestamp":"2024-06-01T17:51:34.457155Z"}]}
{"channel":"book","type":"update","data":[{"symbol":"BTC/GBP","bids":[],"asks":[{"price":53055.4,"qty":0.39868247}],"checksum":271085543,"timestamp":"2024-06-01T17:51:34.457218Z"}]}
{"channel":"book","type":"update","data":[{"symbol":"BTC/GBP","bids":[],"asks":[{"price":53055.4,"qty":0.36968247}],"checksum":3079818331,"timestamp":"2024-06-01T17:51:34.459899Z"}]}
{"channel":"book","type":"update","data":[{"symbol":"BTC/GBP","bids":[],"asks":[{"price":53054.8,"qty":0.02900000}],"checksum":2657358860,"timestamp":"2024-06-01T17:51:34.459989Z"}]}
{"channel":"book","type":"update","data":[{"symbol":"BTC/GBP","bids":[],"asks":[{"price":53056.0,"qty":0.00000000},{"price":53081.7,"qty":0.19906855}],"checksum":4046737162,"timestamp":"2024-06-01T17:51:34.460691Z"}]}
{"channel":"book","type":"update","data":[{"symbol":"BTC/GBP","bids":[],"asks":[{"price":53055.3,"qty":0.00471418}],"checksum":1866811740,"timestamp":"2024-06-01T17:51:34.464595Z"}]}
{"channel":"book","type":"update","data":[{"symbol":"BTC/GBP","bids":[],"asks":[{"price":53048.1,"qty":0.00000000},{"price":53081.7,"qty":0.19906855},{"price":53058.3,"qty":0.00931900}],"checksum":2037241802,"timestamp":"2024-06-01T17:51:34.468591Z"}]}
{"channel":"book","type":"update","data":[{"symbol":"BTC/GBP","bids":[],"asks":[{"price":53050.6,"qty":0.00000000},{"price":53081.7,"qty":0.19906855},{"price":53057.6,"qty":0.00097400}],"checksum":1058122563,"timestamp":"2024-06-01T17:51:34.501382Z"}]}
{"channel":"book","type":"update","data":[{"symbol":"BTC/GBP","bids":[{"price":52999.5,"qty":0.04239626}],"asks":[],"checksum":1803736185,"timestamp":"2024-06-01T17:51:34.528818Z"}]}
{"channel":"book","type":"update","data":[{"symbol":"BTC/GBP","bids":[],"asks":[{"price":53055.3,"qty":0.00000000},{"price":53081.7,"qty":0.19906855}],"checksum":2716503084,"timestamp":"2024-06-01T17:51:34.537583Z"}]}
{"channel":"book","type":"update","data":[{"symbol":"BTC/GBP","bids":[{"price":53048.8,"qty":0.36972831}],"asks":[],"checksum":2569853263,"timestamp":"2024-06-01T17:51:34.560371Z"}]}
{"channel":"book","type":"update","data":[{"symbol":"BTC/GBP","bids":[{"price":53003.9,"qty":0.00135300}],"asks":[],"checksum":280958301,"timestamp":"2024-06-01T17:51:34.570153Z"}]}
{"channel":"book","type":"update","data":[{"symbol":"BTC/GBP","bids":[],"asks":[{"price":53053.1,"qty":0.00000000},{"price":53081.8,"qty":0.07402000},{"price":53056.1,"qty":0.00135200}],"checksum":3968816887,"timestamp":"2024-06-01T17:51:34.570181Z"}]}
{"channel":"book","type":"update","data":[{"symbol":"BTC/GBP","bids":[{"price":53048.0,"qty":0.00000000},{"price":52999.5,"qty":0.04239626}],"asks":[],"checksum":3089617896,"timestamp":"2024-06-01T17:51:34.700968Z"}]}
{"channel":"book","type":"update","data":[{"symbol":"BTC/GBP","bids":[{"price":53042.0,"qty":0.00000000},{"price":52996.2,"qty":0.01464000}],"asks":[],"checksum":3178012581,"timestamp":"2024-06-01T17:51:34.703723Z"}]}
{"channel":"book","type":"update","data":[{"symbol":"BTC/GBP","bids":[{"price":53048.1,"qty":0.36973319}],"asks":[],"checksum":1194985528,"timestamp":"2024-06-01T17:51:34.707448Z"}]}
{"channel":"book","type":"update","data":[{"symbol":"BTC/GBP","bids":[{"price":53045.6,"qty":0.36975061}],"asks":[],"checksum":1920409703,"timestamp":"2024-06-01T17:51:34.707549Z"}]}
{"channel":"book","type":"update","data":[{"symbol":"BTC/GBP","bids":[{"price":53048.1,"qty":0.00000000},{"price":52999.5,"qty":0.04239626}],"asks":[],"checksum":1577172221,"timestamp":"2024-06-01T17:51:34.714462Z"}]}
{"channel":"book","type":"update","data":[{"symbol":"BTC/GBP","bids":[],"asks":[{"price":53053.6,"qty":0.36969550}],"checksum":1300401344,"timestamp":"2024-06-01T17:51:34.726090Z"}]}
{"channel":"book","type":"update","data":[{"symbol":"BTC/GBP","bids":[],"asks":[{"price":53053.6,"qty":0.00000000},{"price":53081.6,"qty":0.07402000}],"checksum":2499007023,"timestamp":"2024-06-01T17:51:34.749759Z"}]}
{"channel":"book","type":"update","data":[{"symbol":"BTC/GBP","bids":[],"asks":[{"price":53081.5,"qty":0.01129070}],"checksum":3698140562,"timestamp":"2024-06-01T17:51:34.764242Z"}]}
{"channel":"book","type":"update","data":[{"symbol":"BTC/GBP","bids":[],"asks":[{"price":53056.1,"qty":0.00000000},{"price":53081.6,"qty":0.07402000},{"price":53063.0,"qty":0.00135200}],"checksum":2692081415,"timestamp":"2024-06-01T17:51:34.767091Z"}]}
{"channel":"book","type":"update","data":[{"symbol":"BTC/GBP","bids":[],"asks":[{"price":53048.9,"qty":0.00000000},{"price":53081.6,"qty":0.07402000}],"checksum":343205068,"timestamp":"2024-06-01T17:51:34.768039Z"}]}
{"channel":"book","type":"update","data":[{"symbol":"BTC/GBP","bids":[],"asks":[{"price":53061.2,"qty":0.00000000},{"price":53081.7,"qty":0.18777785}],"checksum":3612528081,"timestamp":"2024-06-01T17:51:34.776090Z"}]}
{"channel":"book","type":"update","data":[{"symbol":"BTC/GBP","bids":[],"asks":[{"price":53054.7,"qty":0.36968719}],"checksum":2467241144,"timestamp":"2024-06-01T17:51:34.780721Z"}]}
{"channel":"book","type":"update","data":[{"symbol":"BTC/GBP","bids":[],"asks":[{"price":53054.7,"qty":0.00000000},{"price":53081.7,"qty":0.18777785}],"checksum":3612528081,"timestamp":"2024-06-01T17:51:34.822942Z"}]}
{"channel":"book","type":"update","data":[{"symbol":"BTC/GBP","bids":[],"asks":[{"price":53059.1,"qty":0.36965683}],"checksum":3241322370,"timestamp":"2024-06-01T17:51:34.826266Z"}]}
{"channel":"book","type":"update","data":[{"symbol":"BTC/GBP","bids":[],"asks":[{"price":53049.0,"qty":0.01802000}],"checksum":595594986,"timestamp":"2024-06-01T17:51:34.828237Z"}]}
{"channel":"book","type":"update","data":[{"symbol":"BTC/GBP","bids":[{"price":53041.2,"qty":0.00000000},{"price":52996.2,"qty":0.01464000},{"price":53046.0,"qty":0.00097400}],"asks":[],"checksum":3731859455,"timestamp":"2024-06-01T17:51:34.885028Z"}]}
{"channel":"book","type":"update","data":[{"symbol":"BTC/GBP","bids":[],"asks":[{"price":53056.7,"qty":0.00000000},{"price":53081.6,"qty":0.07402000}],"checksum":2048999768,"timestamp":"2024-06-01T17:51:34.894624Z"}]}
{"channel":"book","type":"update","data":[{"symbol":"BTC/GBP","bids":[],"asks":[{"price":53054.2,"qty":0.36969075}],"checksum":1625063860,"timestamp":"2024-06-01T17:51:34.898066Z"}]}
{"channel":"book","type":"update","data":[{"symbol":"BTC/GBP","bids":[{"price":53044.9,"qty":0.36975518}],"asks":[],"checksum":2101924562,"timestamp":"2024-06-01T17:51:34.964156Z"}]}
{"channel":"book","type":"update","data":[{"symbol":"BTC/GBP","bids":[],"asks":[{"price":53052.9,"qty":0.36969999}],"checksum":2028694928,"timestamp":"2024-06-01T17:51:34.964189Z"}]}
{"channel":"book","type":"update","data":[{"symbol":"BTC/GBP","bids":[{"price":53044.9,"qty":0.00000000},{"price":52999.5,"qty":0.04239626}],"asks":[],"checksum":3275018355,"timestamp":"2024-06-01T17:51:34.972992Z"}]}
{"channel":"book","type":"update","data":[{"symbol":"BTC/GBP","bids":[{"price":53048.8,"qty":0.00000000},{"price":52996.2,"qty":0.01464000}],"asks":[],"checksum":1903117423,"timestamp":"2024-06-01T17:51:34.973062Z"}]}
{"channel":"book","type":"update","data":[{"symbol":"BTC/GBP","bids":[],"asks":[{"price":53054.2,"qty":0.00000000},{"price":53081.5,"qty":0.01129070}],"checksum":272003534,"timestamp":"2024-06-01T17:51:34.973080Z"}]}
{"channel":"book","type":"update","data":[{"symbol":"BTC/GBP","bids":[],"asks":[{"price":53052.9,"qty":0.00000000},{"price":53081.6,"qty":0.07402000}],"checksum":36333081,"timestamp":"2024-06-01T17:51:34.976604Z"}]}
{"channel":"book","type":"update","data":[{"symbol":"BTC/GBP","bids":[{"price":53043.2,"qty":0.00000000},{"price":52992.4,"qty":0.37012042}],"asks":[],"checksum":2046841807,"timestamp":"2024-06-01T17:51:34.981405Z"}]}
{"channel":"book","type":"update","data":[{"symbol":"BTC/GBP","bids":[{"price":53045.3,"qty":0.36975262}],"asks":[],"checksum":2512132547,"timestamp":"2024-06-01T17:51:34.981433Z"}]}
{"channel":"book","type":"update","data":[{"symbol":"BTC/GBP","bids":[],"asks":[{"price":53074.2,"qty":0.36955178}],"checksum":2272939253,"timestamp":"2024-06-01T17:51:34.981645Z"}]}
{"channel":"book","type":"update","data":[{"symbol":"BTC/GBP","bids":[{"price":53043.8,"qty":0.00000000},{"price":52992.4,"qty":0.37012042}],"asks":[],"checksum":2296303859,"timestamp":"2024-06-01T17:51:34.984276Z"}]}
{"channel":"book","type":"update","data":[{"symbol":"BTC/GBP","bids":[{"price":53045.6,"qty":0.00000000},{"price":52986.5,"qty":0.01360000}],"asks":[],"checksum":935580194,"timestamp":"2024-06-01T17:51:35.020970Z"}]}
{"channel":"book","type":"update","data":[{"symbol":"BTC/GBP","bids":[],"asks":[{"price":53049.0,"qty":0.00000000},{"price":53081.6,"qty":0.07402000}],"checksum":589449523,"timestamp":"2024-06-01T17:51:35.022734Z"}]}
{"channel":"book","type":"update","data":[{"symbol":"BTC/GBP","bids":[{"price":53046.1,"qty":0.36974713}],"asks":[],"checksum":766247424,"timestamp":"2024-06-01T17:51:35.027336Z"}]}
{"channel":"book","type":"update","data":[{"symbol":"BTC/GBP","bids":[],"asks":[{"price":53050.8,"qty":0.36971457}],"checksum":518548001,"timestamp":"2024-06-01T17:51:35.027350Z"}]}
{"channel":"book","type":"update","data":[{"symbol":"BTC/GBP","bids":[],"asks":[{"price":53050.8,"qty":0.00000000},{"price":53081.6,"qty":0.07402000}],"checksum":766247424,"timestamp":"2024-06-01T17:51:35.032411Z"}]}
{"channel":"book","type":"update","data":[{"symbol":"BTC/GBP","bids":[],"asks":[{"price":53054.7,"qty":0.36968719}],"checksum":2173307061,"timestamp":"2024-06-01T17:51:35.036789Z"}]}
{"channel":"book","type":"update","data":[{"symbol":"BTC/GBP","bids":[],"asks":[{"price":53054.7,"qty":0.00000000},{"price":53081.6,"qty":0.07402000}],"checksum":766247424,"timestamp":"2024-06-01T17:51:35.041045Z"}]}
{"channel":"book","type":"update","data":[{"symbol":"BTC/GBP","bids":[],"asks":[{"price":53049.1,"qty":0.01672000}],"checksum":2600637757,"timestamp":"2024-06-01T17:51:35.173877Z"}]}
{"channel":"book","type":"update","data":[{"symbol":"BTC/GBP","bids":[],"asks":[{"price":53049.1,"qty":0.00000000},{"price":53081.6,"qty":0.07402000}],"checksum":766247424,"timestamp":"2024-06-01T17:51:35.282947Z"}]}
{"channel":"book","type":"update","data":[{"symbol":"BTC/GBP","bids":[],"asks":[{"price":53055.3,"qty":0.02957363}],"checksum":3786550436,"timestamp":"2024-06-01T17:51:35.327211Z"}]}
{"channel":"book","type":"update","data":[{"symbol":"BTC/GBP","bids":[],"asks":[{"price":53054.9,"qty":0.01764000}],"checksum":3646846326,"timestamp":"2024-06-01T17:51:35.386098Z"}]}
{"channel":"book","type":"update","data":[{"symbol":"BTC/GBP","bids":[{"price":53041.3,"qty":0.36977998}],"asks":[],"checksum":442680632,"timestamp":"2024-06-01T17:51:35.846991Z"}]}
{"channel":"book","type":"update","data":[{"symbol":"BTC/GBP","bids":[],"asks":[{"price":53054.6,"qty":0.36968789}],"checksum":3282991728,"timestamp":"2024-06-01T17:51:35.847073Z"}]}
{"channel":"book","type":"update","data":[{"symbol":"BTC/GBP","bids":[],"asks":[{"price":53054.6,"qty":0.00000000},{"price":53077.7,"qty":0.00032928}],"checksum":442680632,"timestamp":"2024-06-01T17:51:35.853883Z"}]}
{"channel":"book","type":"update","data":[{"symbol":"BTC/GBP","bids":[],"asks":[{"price":53052.2,"qty":0.36970526}],"checksum":1256353892,"timestamp":"2024-06-01T17:51:35.858329Z"}]}
{"channel":"book","type":"update","data":[{"symbol":"BTC/GBP","bids":[],"asks":[{"price":53051.3,"qty":0.36971155}],"checksum":2438699533,"timestamp":"2024-06-01T17:51:35.994776Z"}]}
{"channel":"book","type":"update","data":[{"symbol":"BTC/GBP","bids":[],"asks":[{"price":53058.3,"qty":0.00000000},{"price":53074.2,"qty":0.36955178},{"price":53052.1,"qty":0.00931900}],"checksum":1149547334,"timestamp":"2024-06-01T17:51:36.011037Z"}]}
{"channel":"book","type":"update","data":[{"symbol":"BTC/GBP","bids":[{"price":53041.3,"qty":0.00000000},{"price":52992.4,"qty":0.37012042}],"asks":[],"checksum":2276983560,"timestamp":"2024-06-01T17:51:36.388728Z"}]}
{"channel":"book","type":"update","data":[{"symbol":"BTC/GBP","bids":[{"price":53047.2,"qty":0.36973900}],"asks":[],"checksum":1430574085,"timestamp":"2024-06-01T17:51:36.392482Z"}]}
{"channel":"book","type":"update","data":[{"symbol":"BTC/GBP","bids":[{"price":53047.2,"qty":0.00000000},{"price":52992.4,"qty":0.37012042}],"asks":[],"checksum":2276983560,"timestamp":"2024-06-01T17:51:36.463605Z"}]}
{"channel":"book","type":"update","data":[{"symbol":"BTC/GBP","bids":[{"price":53042.5,"qty":0.36977214}],"asks":[],"checksum":1230656767,"timestamp":"2024-06-01T17:51:36.468742Z"}]}
{"channel":"book","type":"update","data":[{"symbol":"BTC/GBP","bids":[],"asks":[{"price":53052.1,"qty":0.00000000},{"price":53074.2,"qty":0.36955178},{"price":53058.3,"qty":0.00931900}],"checksum":2625994164,"timestamp":"2024-06-01T17:51:36.469968Z"}]}
{"channel":"book","type":"update","data":[{"symbol":"BTC/GBP","bids":[],"asks":[{"price":53057.6,"qty":0.00000000},{"price":53074.2,"qty":0.36955178},{"price":53052.4,"qty":0.00097400}],"checksum":968701459,"timestamp":"2024-06-01T17:51:36.558573Z"}]}
{"channel":"book","type":"update","data":[{"symbol":"BTC/GBP","bids":[],"asks":[{"price":53051.3,"qty":0.35299686}],"checksum":1849951256,"timestamp":"2024-06-01T17:51:37.472785Z"}]}
{"channel":"book","type":"update","data":[{"symbol":"BTC/GBP","bids":[],"asks":[{"price":53058.3,"qty":0.00000000},{"price":53074.2,"qty":0.36955178},{"price":53053.1,"qty":0.00931900}],"checksum":773132556,"timestamp":"2024-06-01T17:51:37.625619Z"}]}
{"channel":"book","type":"update","data":[{"symbol":"BTC/GBP","bids":[{"price":53038.9,"qty":0.36979671}],"asks":[],"checksum":3099259446,"timestamp":"2024-06-01T17:51:37.988890Z"}]}
{"channel":"book","type":"update","data":[{"symbol":"BTC/GBP","bids":[],"asks":[{"price":53055.3,"qty":0.00000000},{"price":53074.2,"qty":0.36955178}],"checksum":2387607846,"timestamp":"2024-06-01T17:51:38.059723Z"}]}
{"channel":"book","type":"update","data":[{"symbol":"BTC/GBP","bids":[{"price":53046.1,"qty":0.00000000},{"price":52996.2,"qty":0.01464000}],"asks":[],"checksum":3424700136,"timestamp":"2024-06-01T17:51:38.156613Z"}]}
{"channel":"book","type":"update","data":[{"symbol":"BTC/GBP","bids":[],"asks":[{"price":53055.4,"qty":0.00000000},{"price":53077.7,"qty":0.00032928}],"checksum":3505891171,"timestamp":"2024-06-01T17:51:38.156866Z"}]}
{"channel":"book","type":"update","data":[{"symbol":"BTC/GBP","bids":[{"price":53046.0,"qty":0.00911015}],"asks":[],"checksum":2169538207,"timestamp":"2024-06-01T17:51:38.160859Z"}]}
{"channel":"book","type":"update","data":[{"symbol":"BTC/GBP","bids":[],"asks":[{"price":53051.3,"qty":0.00000000},{"price":53084.2,"qty":0.07402000}],"checksum":2100095771,"timestamp":"2024-06-01T17:51:38.161931Z"}]}
{"channel":"book","type":"update","data":[{"symbol":"BTC/GBP","bids":[],"asks":[{"price":53084.1,"qty":0.01129070}],"checksum":3367287517,"timestamp":"2024-06-01T17:51:38.166270Z"}]}
{"channel":"book","type":"update","data":[{"symbol":"BTC/GBP","bids":[],"asks":[{"price":53049.8,"qty":0.36972142}],"checksum":1039286904,"timestamp":"2024-06-01T17:51:38.166419Z"}]}
{"channel":"book","type":"update","data":[{"symbol":"BTC/GBP","bids":[],"asks":[{"price":53051.2,"qty":0.36971158}],"checksum":708127079,"timestamp":"2024-06-01T17:51:38.166513Z"}]}
{"channel":"book","type":"update","data":[{"symbol":"BTC/GBP","bids":[{"price":53046.0,"qty":0.00097400}],"asks":[],"checksum":1684342348,"timestamp":"2024-06-01T17:51:38.170096Z"}]}
{"channel":"book","type":"update","data":[{"symbol":"BTC/GBP","bids":[],"asks":[{"price":53049.8,"qty":0.00000000},{"price":53077.7,"qty":0.00032928}],"checksum":544008285,"timestamp":"2024-06-01T17:51:38.206780Z"}]}
{"channel":"book","type":"update","data":[{"symbol":"BTC/GBP","bids":[{"price":53046.1,"qty":0.36974713}],"asks":[],"checksum":901188107,"timestamp":"2024-06-01T17:51:38.211288Z"}]}
{"channel":"book","type":"update","data":[{"symbol":"BTC/GBP","bids":[],"asks":[{"price":53055.1,"qty":0.36968489}],"checksum":4289407729,"timestamp":"2024-06-01T17:51:38.211356Z"}]}
{"channel":"book","type":"update","data":[{"symbol":"BTC/GBP","bids":[{"price":53046.0,"qty":0.00911016}],"asks":[],"checksum":619436152,"timestamp":"2024-06-01T17:51:38.211490Z"}]}
{"channel":"book","type":"update","data":[{"symbol":"BTC/GBP","bids":[{"price":53046.0,"qty":0.00097400}],"asks":[],"checksum":4289407729,"timestamp":"2024-06-01T17:51:38.215265Z"}]}
{"channel":"book","type":"update","data":[{"symbol":"BTC/GBP","bids":[{"price":53041.4,"qty":0.00942660}],"asks":[],"checksum":312132588,"timestamp":"2024-06-01T17:51:38.698422Z"}]}
{"channel":"book","type":"update","data":[{"symbol":"BTC/GBP","bids":[],"asks":[{"price":53063.0,"qty":0.00000000},{"price":53077.7,"qty":0.00032928},{"price":53058.4,"qty":0.00135200}],"checksum":2795349681,"timestamp":"2024-06-01T17:51:39.846600Z"}]}
{"channel":"book","type":"update","data":[{"symbol":"BTC/GBP","bids":[],"asks":[{"price":53051.2,"qty":0.00000000},{"price":53077.7,"qty":0.00032928}],"checksum":1412241885,"timestamp":"2024-06-01T17:51:40.077001Z"}]}
{"channel":"book","type":"update","data":[{"symbol":"BTC/GBP","bids":[{"price":53046.1,"qty":0.00000000},{"price":52999.5,"qty":0.04239626}],"asks":[],"checksum":1145394057,"timestamp":"2024-06-01T17:51:40.077024Z"}]}
{"channel":"book","type":"update","data":[{"symbol":"BTC/GBP","bids":[],"asks":[{"price":53055.1,"qty":0.00000000},{"price":53084.0,"qty":0.18777785}],"checksum":4245516386,"timestamp":"2024-06-01T17:51:40.077072Z"}]}
{"channel":"book","type":"update","data":[{"symbol":"BTC/GBP","bids":[{"price":53023.1,"qty":0.00000000},{"price":52996.2,"qty":0.01464000}],"asks":[],"checksum":3086742657,"timestamp":"2024-06-01T17:51:40.077580Z"}]}
{"channel":"book","type":"update","data":[{"symbol":"BTC/GBP","bids":[{"price":53045.3,"qty":0.00000000},{"price":52992.4,"qty":0.37012042}],"asks":[],"checksum":1032727937,"timestamp":"2024-06-01T17:51:40.078399Z"}]}
{"channel":"book","type":"update","data":[{"symbol":"BTC/GBP","bids":[],"asks":[{"price":53083.9,"qty":0.07402000}],"checksum":1748376958,"timestamp":"2024-06-01T17:51:40.080074Z"}]}
{"channel":"book","type":"update","data":[{"symbol":"BTC/GBP","bids":[],"asks":[{"price":53052.1,"qty":0.00471418}],"checksum":2860806939,"timestamp":"2024-06-01T17:51:40.081309Z"}]}
{"channel":"book","type":"update","data":[{"symbol":"BTC/GBP","bids":[],"asks":[{"price":53052.2,"qty":0.00000000},{"price":53083.9,"qty":0.07402000}],"checksum":4213281885,"timestamp":"2024-06-01T17:51:40.081700Z"}]}
{"channel":"book","type":"update","data":[{"symbol":"BTC/GBP","bids":[{"price":53043.1,"qty":0.02900000}],"asks":[],"checksum":1995652755,"timestamp":"2024-06-01T17:51:40.082772Z"}]}
{"channel":"book","type":"update","data":[{"symbol":"BTC/GBP","bids":[{"price":53027.0,"qty":0.00000000},{"price":52992.4,"qty":0.37012042}],"asks":[],"checksum":2227433548,"timestamp":"2024-06-01T17:51:40.089821Z"}]}
{"channel":"book","type":"update","data":[{"symbol":"BTC/GBP","bids":[],"asks":[{"price":53059.1,"qty":0.00000000},{"price":53084.0,"qty":0.18777785}],"checksum":625638231,"timestamp":"2024-06-01T17:51:40.089852Z"}]}
{"channel":"book","type":"update","data":[{"symbol":"BTC/GBP","bids":[],"asks":[{"price":53083.8,"qty":0.01129070}],"checksum":844304474,"timestamp":"2024-06-01T17:51:40.091225Z"}]}
{"channel":"book","type":"update","data":[{"symbol":"BTC/GBP","bids":[{"price":53039.2,"qty":0.30177610}],"asks":[],"checksum":3792781227,"timestamp":"2024-06-01T17:51:40.097999Z"}]}
{"channel":"book","type":"update","data":[{"symbol":"BTC/GBP","bids":[{"price":53043.2,"qty":0.00813650}],"asks":[],"checksum":1988480901,"timestamp":"2024-06-01T17:51:40.098450Z"}]}
{"channel":"book","type":"update","data":[{"symbol":"BTC/GBP","bids":[{"price":53042.6,"qty":0.00813647}],"asks":[],"checksum":1901524226,"timestamp":"2024-06-01T17:51:40.098532Z"}]}
{"channel":"book","type":"update","data":[{"symbol":"BTC/GBP","bids":[],"asks":[{"price":53047.2,"qty":0.36973977}],"checksum":3426393144,"timestamp":"2024-06-01T17:51:40.102358Z"}]}
{"channel":"book","type":"update","data":[{"symbol":"BTC/GBP","bids":[],"asks":[{"price":53051.0,"qty":0.36971318}],"checksum":4005344208,"timestamp":"2024-06-01T17:51:40.102388Z"}]}
{"channel":"book","type":"update","data":[{"symbol":"BTC/GBP","bids":[],"asks":[{"price":53051.1,"qty":0.36971228}],"checksum":3565206363,"timestamp":"2024-06-01T17:51:40.102460Z"}]}
{"channel":"book","type":"update","data":[{"symbol":"BTC/GBP","bids":[{"price":53019.9,"qty":0.36992970}],"asks":[],"checksum":2762160309,"timestamp":"2024-06-01T17:51:40.102474Z"}]}
{"channel":"book","type":"update","data":[{"symbol":"BTC/GBP","bids":[{"price":53037.1,"qty":0.36980953}],"asks":[],"checksum":4258776756,"timestamp":"2024-06-01T17:51:40.102508Z"}]}
{"channel":"book","type":"update","data":[{"symbol":"BTC/GBP","bids":[],"asks":[{"price":53053.5,"qty":0.36969614}],"checksum":1640754041,"timestamp":"2024-06-01T17:51:40.102544Z"}]}
{"channel":"book","type":"update","data":[{"symbol":"BTC/GBP","bids":[{"price":53043.2,"qty":0.00000000},{"price":53011.2,"qty":0.36999006}],"asks":[],"checksum":862613490,"timestamp":"2024-06-01T17:51:40.104599Z"}]}
{"channel":"book","type":"update","data":[{"symbol":"BTC/GBP","bids":[{"price":53042.6,"qty":0.00000000},{"price":53003.9,"qty":0.00135300}],"asks":[],"checksum":3863269411,"timestamp":"2024-06-01T17:51:40.104613Z"}]}
{"channel":"book","type":"update","data":[{"symbol":"BTC/GBP","bids":[],"asks":[{"price":53052.1,"qty":0.00000000},{"price":53074.2,"qty":0.36955178}],"checksum":1751068154,"timestamp":"2024-06-01T17:51:40.106593Z"}]}
{"channel":"book","type":"update","data":[{"symbol":"BTC/GBP","bids":[{"price":53043.1,"qty":0.00000000},{"price":52999.5,"qty":0.04239626}],"asks":[],"checksum":3173138539,"timestamp":"2024-06-01T17:51:40.108167Z"}]}
{"channel":"book","type":"update","data":[{"symbol":"BTC/GBP","bids":[],"asks":[{"price":53051.0,"qty":0.00000000},{"price":53077.7,"qty":0.00032928}],"checksum":3149727687,"timestamp":"2024-06-01T17:51:40.110476Z"}]}
{"channel":"book","type":"update","data":[{"symbol":"BTC/GBP","bids":[{"price":53042.5,"qty":0.00000000},{"price":52996.2,"qty":0.01464000}],"asks":[],"checksum":374957087,"timestamp":"2024-06-01T17:51:40.120538Z"}]}
{"channel":"book","type":"update","data":[{"symbol":"BTC/GBP","bids":[],"asks":[{"price":53051.1,"qty":0.00000000},{"price":53082.6,"qty":0.01129070}],"checksum":1859516967,"timestamp":"2024-06-01T17:51:40.120604Z"}]}
{"channel":"book","type":"update","data":[{"symbol":"BTC/GBP","bids":[],"asks":[{"price":53082.6,"qty":0.19906855}],"checksum":537961152,"timestamp":"2024-06-01T17:51:40.125671Z"}]}
{"channel":"book","type":"update","data":[{"symbol":"BTC/GBP","bids":[{"price":53039.8,"qty":0.02900000}],"asks":[],"checksum":1600864279,"timestamp":"2024-06-01T17:51:40.125694Z"}]}
{"channel":"book","type":"update","data":[{"symbol":"BTC/GBP","bids":[{"price":53039.9,"qty":0.36978969}],"asks":[],"checksum":2238293864,"timestamp":"2024-06-01T17:51:40.127684Z"}]}
{"channel":"book","type":"update","data":[{"symbol":"BTC/GBP","bids":[],"asks":[{"price":53074.2,"qty":0.00000000},{"price":53082.7,"qty":0.36949239}],"checksum":3328480788,"timestamp":"2024-06-01T17:51:40.131880Z"}]}
{"channel":"book","type":"update","data":[{"symbol":"BTC/GBP","bids":[{"price":53039.8,"qty":0.00000000},{"price":52999.5,"qty":0.04239626}],"asks":[],"checksum":3341320680,"timestamp":"2024-06-01T17:51:40.132163Z"}]}
{"channel":"book","type":"update","data":[{"symbol":"BTC/GBP","bids":[{"price":53041.5,"qty":0.02900000}],"asks":[],"checksum":2358605645,"timestamp":"2024-06-01T17:51:40.132211Z"}]}
{"channel":"book","type":"update","data":[{"symbol":"BTC/GBP","bids":[{"price":53039.9,"qty":0.00000000},{"price":52999.5,"qty":0.04239626}],"asks":[],"checksum":3456231525,"timestamp":"2024-06-01T17:51:40.134141Z"}]}
{"channel":"book","type":"update","data":[{"symbol":"BTC/GBP","bids":[],"asks":[{"price":53066.4,"qty":0.36960586}],"checksum":3508653362,"timestamp":"2024-06-01T17:51:40.138563Z"}]}
{"channel":"book","type":"update","data":[{"symbol":"BTC/GBP","bids":[{"price":53039.2,"qty":0.00000000},{"price":52992.4,"qty":0.37012042}],"asks":[],"checksum":2633034912,"timestamp":"2024-06-01T17:51:40.155402Z"}]}
{"channel":"book","type":"update","data":[{"symbol":"BTC/GBP","bids":[{"price":53041.5,"qty":0.00000000},{"price":52986.5,"qty":0.01360000}],"asks":[],"checksum":2126007885,"timestamp":"2024-06-01T17:51:40.156206Z"}]}
{"channel":"book","type":"update","data":[{"symbol":"BTC/GBP","bids":[{"price":53039.8,"qty":0.02900000}],"asks":[],"checksum":1765954234,"timestamp":"2024-06-01T17:51:40.156616Z"}]}
{"channel":"book","type":"update","data":[{"symbol":"BTC/GBP","bids":[{"price":53038.9,"qty":0.67157452}],"asks":[],"checksum":3451762522,"timestamp":"2024-06-01T17:51:40.160057Z"}]}
{"channel":"book","type":"update","data":[{"symbol":"BTC/GBP","bids":[],"asks":[{"price":53054.8,"qty":0.00000000},{"price":53082.7,"qty":0.36949239}],"checksum":2259164520,"timestamp":"2024-06-01T17:51:40.161211Z"}]}
{"channel":"book","type":"update","data":[{"symbol":"BTC/GBP","bids":[],"asks":[{"price":53046.9,"qty":0.02900000}],"checksum":3814813382,"timestamp":"2024-06-01T17:51:40.161428Z"}]}
{"channel":"book","type":"update","data":[{"symbol":"BTC/GBP","bids":[{"price":53046.0,"qty":0.00000000},{"price":52979.8,"qty":0.00792054},{"price":53038.6,"qty":0.00097400}],"asks":[],"checksum":417479745,"timestamp":"2024-06-01T17:51:40.229601Z"}]}
{"channel":"book","type":"update","data":[{"symbol":"BTC/GBP","bids":[{"price":53038.9,"qty":0.36979671}],"asks":[],"checksum":2304031982,"timestamp":"2024-06-01T17:51:40.233605Z"}]}
{"channel":"book","type":"update","data":[{"symbol":"BTC/GBP","bids":[],"asks":[{"price":53044.5,"qty":0.36975846}],"checksum":956636551,"timestamp":"2024-06-01T17:51:40.234365Z"}]}
{"channel":"book","type":"update","data":[{"symbol":"BTC/GBP","bids":[{"price":53039.8,"qty":0.00000000},{"price":52979.8,"qty":0.00792054}],"asks":[],"checksum":510772378,"timestamp":"2024-06-01T17:51:40.236726Z"}]}
{"channel":"book","type":"update","data":[{"symbol":"BTC/GBP","bids":[{"price":53029.3,"qty":0.30183244}],"asks":[],"checksum":1643029798,"timestamp":"2024-06-01T17:51:40.238256Z"}]}
{"channel":"book","type":"update","data":[{"symbol":"BTC/GBP","bids":[{"price":53038.9,"qty":0.00000000},{"price":52979.8,"qty":0.00792054}],"asks":[],"checksum":3595423156,"timestamp":"2024-06-01T17:51:40.254600Z"}]}
{"channel":"book","type":"update","data":[{"symbol":"BTC/GBP","bids":[{"price":53011.2,"qty":0.00000000},{"price":52979.7,"qty":0.37021046}],"asks":[],"checksum":3574564462,"timestamp":"2024-06-01T17:51:40.254610Z"}]}
{"channel":"book","type":"update","data":[{"symbol":"BTC/GBP","bids":[],"asks":[{"price":53046.9,"qty":0.00000000},{"price":53082.6,"qty":0.19906855}],"checksum":1494402757,"timestamp":"2024-06-01T17:51:40.257744Z"}]}
{"channel":"book","type":"update","data":[{"symbol":"BTC/GBP","bids":[],"asks":[{"price":53044.3,"qty":0.02900000}],"checksum":2771786256,"timestamp":"2024-06-01T17:51:40.257853Z"}]}
{"channel":"book","type":"update","data":[{"symbol":"BTC/GBP","bids":[{"price":53003.4,"qty":0.37004494}],"asks":[],"checksum":1204995855,"timestamp":"2024-06-01T17:51:40.259212Z"}]}
{"channel":"book","type":"update","data":[{"symbol":"BTC/GBP","bids":[],"asks":[{"price":53053.1,"qty":0.00000000},{"price":53082.6,"qty":0.19906855},{"price":53047.1,"qty":0.00931900}],"checksum":4018812273,"timestamp":"2024-06-01T17:51:40.276370Z"}]}
{"channel":"book","type":"update","data":[{"symbol":"BTC/GBP","bids":[],"asks":[{"price":53044.5,"qty":0.00000000},{"price":53082.6,"qty":0.19906855}],"checksum":3712166702,"timestamp":"2024-06-01T17:51:40.281029Z"}]}
{"channel":"book","type":"update","data":[{"symbol":"BTC/GBP","bids":[{"price":53037.2,"qty":0.02900000}],"asks":[],"checksum":549886029,"timestamp":"2024-06-01T17:51:40.283908Z"}]}
{"channel":"book","type":"update","data":[{"symbol":"BTC/GBP","bids":[],"asks":[{"price":53046.5,"qty":0.02900000}],"checksum":583497179,"timestamp":"2024-06-01T17:51:40.284066Z"}]}
{"channel":"book","type":"update","data":[{"symbol":"BTC/GBP","bids":[],"asks":[{"price":53044.3,"qty":0.00000000},{"price":53082.6,"qty":0.19906855}],"checksum":3855269834,"timestamp":"2024-06-01T17:51:40.284088Z"}]}
{"channel":"book","type":"update","data":[{"symbol":"BTC/GBP","bids":[],"asks":[{"price":53043.2,"qty":0.36976760}],"checksum":1534645531,"timestamp":"2024-06-01T17:51:40.284831Z"}]}
{"channel":"book","type":"update","data":[{"symbol":"BTC/GBP","bids":[],"asks":[{"price":53044.2,"qty":0.36976037}],"checksum":3236214048,"timestamp":"2024-06-01T17:51:40.284846Z"}]}
{"channel":"book","type":"update","data":[{"symbol":"BTC/GBP","bids":[{"price":53037.2,"qty":0.00000000},{"price":52979.8,"qty":0.00792054}],"asks":[],"checksum":713512996,"timestamp":"2024-06-01T17:51:40.287803Z"}]}
{"channel":"book","type":"update","data":[{"symbol":"BTC/GBP","bids":[{"price":53036.7,"qty":0.36981259}],"asks":[],"checksum":740696175,"timestamp":"2024-06-01T17:51:40.315052Z"}]}
{"channel":"book","type":"update","data":[{"symbol":"BTC/GBP","bids":[],"asks":[{"price":53052.4,"qty":0.00000000},{"price":53077.7,"qty":0.00032928},{"price":53047.1,"qty":0.01029300}],"checksum":2808311782,"timestamp":"2024-06-01T17:51:40.325288Z"}]}
{"channel":"book","type":"update","data":[{"symbol":"BTC/GBP","bids":[{"price":53037.1,"qty":0.39880953}],"asks":[],"checksum":683704599,"timestamp":"2024-06-01T17:51:40.497958Z"}]}
{"channel":"book","type":"update","data":[{"symbol":"BTC/GBP","bids":[],"asks":[{"price":53044.6,"qty":0.01504000}],"checksum":609901161,"timestamp":"2024-06-01T17:51:40.498556Z"}]}
{"channel":"book","type":"update","data":[{"symbol":"BTC/GBP","bids":[{"price":53037.1,"qty":0.36980953}],"asks":[],"checksum":2885268632,"timestamp":"2024-06-01T17:51:40.634062Z"}]}
{"channel":"book","type":"update","data":[{"symbol":"BTC/GBP","bids":[{"price":53037.2,"qty":0.02900000}],"asks":[],"checksum":3828045892,"timestamp":"2024-06-01T17:51:40.634142Z"}]}
{"channel":"book","type":"update","data":[{"symbol":"BTC/GBP","bids":[],"asks":[{"price":53044.6,"qty":0.00000000},{"price":53077.7,"qty":0.00032928}],"checksum":3370851983,"timestamp":"2024-06-01T17:51:40.771030Z"}]}
{"channel":"book","type":"update","data":[{"symbol":"BTC/GBP","bids":[{"price":53036.7,"qty":0.00000000},{"price":52992.4,"qty":0.37012042}],"asks":[],"checksum":991155834,"timestamp":"2024-06-01T17:51:41.241849Z"}]}
{"channel":"book","type":"update","data":[{"symbol":"BTC/GBP","bids":[{"price":53038.2,"qty":0.36980194}],"asks":[],"checksum":1934381292,"timestamp":"2024-06-01T17:51:41.246152Z"}]}
{"channel":"book","type":"update","data":[{"symbol":"BTC/GBP","bids":[{"price":53033.6,"qty":0.36983416}],"asks":[],"checksum":3040702698,"timestamp":"2024-06-01T17:51:41.246172Z"}]}
{"channel":"book","type":"update","data":[{"symbol":"BTC/GBP","bids":[{"price":53038.7,"qty":0.00813711}],"asks":[],"checksum":1742303139,"timestamp":"2024-06-01T17:51:41.325028Z"}]}
{"channel":"book","type":"update","data":[{"symbol":"BTC/GBP","bids":[],"asks":[{"price":53043.3,"qty":0.01559000}],"checksum":3199624219,"timestamp":"2024-06-01T17:51:41.380359Z"}]}
{"channel":"book","type":"update","data":[{"symbol":"BTC/GBP","bids":[{"price":53038.7,"qty":0.00000000},{"price":53003.4,"qty":0.37004494}],"asks":[],"checksum":250827965,"timestamp":"2024-06-01T17:51:41.790637Z"}]}
{"channel":"book","type":"update","data":[{"symbol":"BTC/GBP","bids":[{"price":53038.7,"qty":0.00813711}],"asks":[],"checksum":3199624219,"timestamp":"2024-06-01T17:51:41.898432Z"}]}
{"channel":"book","type":"update","data":[{"symbol":"BTC/GBP","bids":[{"price":53038.7,"qty":0.00000000},{"price":53003.4,"qty":0.37004494}],"asks":[],"checksum":250827965,"timestamp":"2024-06-01T17:51:42.653249Z"}]}
{"channel":"book","type":"update","data":[{"symbol":"BTC/GBP","bids":[{"price":53038.7,"qty":0.00813711}],"asks":[],"checksum":3199624219,"timestamp":"2024-06-01T17:51:42.893810Z"}]}
{"channel":"book","type":"update","data":[{"symbol":"BTC/GBP","bids":[{"price":53029.7,"qty":0.36986101}],"asks":[],"checksum":3693783750,"timestamp":"2024-06-01T17:51:42.988632Z"}]}
{"channel":"book","type":"update","data":[{"symbol":"BTC/GBP","bids":[],"asks":[{"price":53044.2,"qty":0.00000000},{"price":53077.7,"qty":0.00032928}],"checksum":1079139414,"timestamp":"2024-06-01T17:51:43.259817Z"}]}
{"channel":"book","type":"update","data":[{"symbol":"BTC/GBP","bids":[],"asks":[{"price":53042.0,"qty":0.36977624}],"checksum":1174215139,"timestamp":"2024-06-01T17:51:43.263603Z"}]}
{"channel":"book","type":"update","data":[{"symbol":"BTC/GBP","bids":[{"price":53038.2,"qty":0.00000000},{"price":53003.9,"qty":0.00135300}],"asks":[],"checksum":1665168354,"timestamp":"2024-06-01T17:51:43.279548Z"}]}
{"channel":"book","type":"update","data":[{"symbol":"BTC/GBP","bids":[{"price":53033.2,"qty":0.36983699}],"asks":[],"checksum":3924712255,"timestamp":"2024-06-01T17:51:43.283523Z"}]}
{"channel":"book","type":"update","data":[{"symbol":"BTC/GBP","bids":[{"price":53033.2,"qty":0.00000000},{"price":53003.9,"qty":0.00135300}],"asks":[],"checksum":1665168354,"timestamp":"2024-06-01T17:51:43.380576Z"}]}
{"channel":"book","type":"update","data":[{"symbol":"BTC/GBP","bids":[{"price":53036.8,"qty":0.36981131}],"asks":[],"checksum":1615339953,"timestamp":"2024-06-01T17:51:43.384337Z"}]}
{"channel":"book","type":"update","data":[{"symbol":"BTC/GBP","bids":[{"price":53033.6,"qty":0.00000000},{"price":53003.9,"qty":0.00135300}],"asks":[],"checksum":1464826950,"timestamp":"2024-06-01T17:51:43.689700Z"}]}
{"channel":"book","type":"update","data":[{"symbol":"BTC/GBP","bids":[],"asks":[{"price":53042.0,"qty":0.00000000},{"price":53077.7,"qty":0.00032928}],"checksum":1341323247,"timestamp":"2024-06-01T17:51:43.689784Z"}]}
{"channel":"book","type":"update","data":[{"symbol":"BTC/GBP","bids":[{"price":53036.8,"qty":0.00000000},{"price":53003.4,"qty":0.37004494}],"asks":[],"checksum":3074478383,"timestamp":"2024-06-01T17:51:43.689837Z"}]}
{"channel":"book","type":"update","data":[{"symbol":"BTC/GBP","bids":[{"price":53043.1,"qty":0.14782446}],"asks":[],"checksum":2060598221,"timestamp":"2024-06-01T17:51:43.704352Z"}]}
{"channel":"book","type":"update","data":[{"symbol":"BTC/GBP","bids":[{"price":53029.7,"qty":0.00000000},{"price":53003.4,"qty":0.37004494}],"asks":[],"checksum":848734235,"timestamp":"2024-06-01T17:51:43.704774Z"}]}
{"channel":"book","type":"update","data":[{"symbol":"BTC/GBP","bids":[],"asks":[{"price":53047.2,"qty":0.00000000},{"price":53082.3,"qty":0.07402000}],"checksum":2678936076,"timestamp":"2024-06-01T17:51:43.704851Z"}]}
{"channel":"book","type":"update","data":[{"symbol":"BTC/GBP","bids":[],"asks":[{"price":53043.2,"qty":0.00000000},{"price":53082.4,"qty":0.18777785}],"checksum":3417948858,"timestamp":"2024-06-01T17:51:43.704876Z"}]}
{"channel":"book","type":"update","data":[{"symbol":"BTC/GBP","bids":[],"asks":[{"price":53066.4,"qty":0.00000000},{"price":53082.6,"qty":0.01129070}],"checksum":1869836064,"timestamp":"2024-06-01T17:51:43.706064Z"}]}
{"channel":"book","type":"update","data":[{"symbol":"BTC/GBP","bids":[{"price":53037.1,"qty":0.00000000},{"price":52999.5,"qty":0.04239626}],"asks":[],"checksum":1365065173,"timestamp":"2024-06-01T17:51:43.706073Z"}]}
{"channel":"book","type":"update","data":[{"symbol":"BTC/GBP","bids":[{"price":53038.7,"qty":0.00000000},{"price":52982.9,"qty":0.01594000}],"asks":[],"checksum":724212768,"timestamp":"2024-06-01T17:51:43.709588Z"}]}
{"channel":"book","type":"update","data":[{"symbol":"BTC/GBP","bids":[],"asks":[{"price":53046.5,"qty":0.00000000},{"price":53082.7,"qty":0.36949239}],"checksum":650115206,"timestamp":"2024-06-01T17:51:43.709888Z"}]}
{"channel":"book","type":"update","data":[{"symbol":"BTC/GBP","bids":[{"price":53037.2,"qty":0.00000000},{"price":52979.7,"qty":0.37021046}],"asks":[],"checksum":744084097,"timestamp":"2024-06-01T17:51:43.710916Z"}]}
{"channel":"book","type":"update","data":[{"symbol":"BTC/GBP","bids":[{"price":53043.2,"qty":0.00813659}],"asks":[],"checksum":4048890540,"timestamp":"2024-06-01T17:51:43.711190Z"}]}
{"channel":"book","type":"update","data":[{"symbol":"BTC/GBP","bids":[{"price":53043.1,"qty":0.00000000},{"price":52979.7,"qty":0.37021046}],"asks":[],"checksum":3546695947,"timestamp":"2024-06-01T17:51:43.714124Z"}]}
{"channel":"book","type":"update","data":[{"symbol":"BTC/GBP","bids":[{"price":53043.2,"qty":0.15594987}],"asks":[],"checksum":3330005921,"timestamp":"2024-06-01T17:51:43.714251Z"}]}
{"channel":"book","type":"update","data":[{"symbol":"BTC/GBP","bids":[{"price":52979.8,"qty":0.00792054}],"asks":[],"checksum":2024106300,"timestamp":"2024-06-01T17:51:43.714345Z"}]}
{"channel":"book","type":"update","data":[{"symbol":"BTC/GBP","bids":[],"asks":[{"price":53082.6,"qty":0.00000000},{"price":53084.6,"qty":0.16769151}],"checksum":2404854699,"timestamp":"2024-06-01T17:51:43.715690Z"}]}
{"channel":"book","type":"update","data":[{"symbol":"BTC/GBP","bids":[],"asks":[{"price":53082.2,"qty":0.01129070}],"checksum":2461186361,"timestamp":"2024-06-01T17:51:43.715775Z"}]}
{"channel":"book","type":"update","data":[{"symbol":"BTC/GBP","bids":[],"asks":[{"price":53052.0,"qty":0.36970620}],"checksum":3128256125,"timestamp":"2024-06-01T17:51:43.717572Z"}]}
{"channel":"book","type":"update","data":[{"symbol":"BTC/GBP","bids":[],"asks":[{"price":53055.5,"qty":0.36968216}],"checksum":3732750153,"timestamp":"2024-06-01T17:51:43.717652Z"}]}
{"channel":"book","type":"update","data":[{"symbol":"BTC/GBP","bids":[],"asks":[{"price":53059.8,"qty":0.36965179}],"checksum":339507113,"timestamp":"2024-06-01T17:51:43.717714Z"}]}
{"channel":"book","type":"update","data":[{"symbol":"BTC/GBP","bids":[{"price":53043.1,"qty":0.36976804}],"asks":[],"checksum":3087181461,"timestamp":"2024-06-01T17:51:43.717727Z"}]}
{"channel":"book","type":"update","data":[{"symbol":"BTC/GBP","bids":[{"price":53043.1,"qty":0.73953608}],"asks":[],"checksum":3322707048,"timestamp":"2024-06-01T17:51:43.717771Z"}]}
{"channel":"book","type":"update","data":[{"symbol":"BTC/GBP","bids":[{"price":53011.4,"qty":0.36998902}],"asks":[],"checksum":3641111381,"timestamp":"2024-06-01T17:51:43.717848Z"}]}
{"channel":"book","type":"update","data":[{"symbol":"BTC/GBP","bids":[],"asks":[{"price":53073.1,"qty":0.36955922}],"checksum":3713747728,"timestamp":"2024-06-01T17:51:43.718034Z"}]}
{"channel":"book","type":"update","data":[{"symbol":"BTC/GBP","bids":[],"asks":[{"price":53051.9,"qty":0.00471418}],"checksum":2684218796,"timestamp":"2024-06-01T17:51:43.724947Z"}]}
{"channel":"book","type":"update","data":[{"symbol":"BTC/GBP","bids":[],"asks":[{"price":53051.9,"qty":0.00000000},{"price":53077.7,"qty":0.00032928}],"checksum":3713747728,"timestamp":"2024-06-01T17:51:43.730175Z"}]}
{"channel":"book","type":"update","data":[{"symbol":"BTC/GBP","bids":[],"asks":[{"price":53047.1,"qty":0.00097400},{"price":53052.6,"qty":0.00931900}],"checksum":3399902207,"timestamp":"2024-06-01T17:51:43.802506Z"}]}
{"channel":"book","type":"update","data":[{"symbol":"BTC/GBP","bids":[],"asks":[{"price":53047.1,"qty":0.00000000},{"price":53077.7,"qty":0.00032928},{"price":53051.9,"qty":0.00097400}],"checksum":1504419444,"timestamp":"2024-06-01T17:51:43.837403Z"}]}
{"channel":"book","type":"update","data":[{"symbol":"BTC/GBP","bids":[],"asks":[{"price":53043.3,"qty":0.00000000},{"price":53077.7,"qty":0.00032928}],"checksum":2384129180,"timestamp":"2024-06-01T17:51:43.892517Z"}]}
{"channel":"book","type":"update","data":[{"symbol":"BTC/GBP","bids":[{"price":53043.2,"qty":0.14781328}],"asks":[],"checksum":1918142400,"timestamp":"2024-06-01T17:51:43.896788Z"}]}
{"channel":"book","type":"update","data":[{"symbol":"BTC/GBP","bids":[{"price":53043.1,"qty":0.36976804}],"asks":[],"checksum":2972059579,"timestamp":"2024-06-01T17:51:43.898066Z"}]}
{"channel":"book","type":"update","data":[{"symbol":"BTC/GBP","bids":[{"price":53043.1,"qty":0.00000000},{"price":52992.5,"qty":0.01526000}],"asks":[],"checksum":213925306,"timestamp":"2024-06-01T17:51:43.898236Z"}]}
{"channel":"book","type":"update","data":[{"symbol":"BTC/GBP","bids":[{"price":53043.3,"qty":0.36976665}],"asks":[],"checksum":3916638609,"timestamp":"2024-06-01T17:51:43.902074Z"}]}
{"channel":"book","type":"update","data":[{"symbol":"BTC/GBP","bids":[{"price":53043.3,"qty":0.73953330}],"asks":[],"checksum":3365247699,"timestamp":"2024-06-01T17:51:43.902102Z"}]}
{"channel":"book","type":"update","data":[{"symbol":"BTC/GBP","bids":[{"price":53043.3,"qty":1.10929995}],"asks":[],"checksum":2778757270,"timestamp":"2024-06-01T17:51:43.902121Z"}]}
{"channel":"book","type":"update","data":[{"symbol":"BTC/GBP","bids":[{"price":53043.8,"qty":0.14783744}],"asks":[],"checksum":2149081324,"timestamp":"2024-06-01T17:51:43.904924Z"}]}
{"channel":"book","type":"update","data":[{"symbol":"BTC/GBP","bids":[{"price":53043.3,"qty":0.73953330}],"asks":[],"checksum":3168454148,"timestamp":"2024-06-01T17:51:43.907829Z"}]}
{"channel":"book","type":"update","data":[{"symbol":"BTC/GBP","bids":[{"price":53043.2,"qty":0.00000000},{"price":52999.5,"qty":0.04239626}],"asks":[],"checksum":2378684147,"timestamp":"2024-06-01T17:51:43.907895Z"}]}
{"channel":"book","type":"update","data":[{"symbol":"BTC/GBP","bids":[{"price":53043.3,"qty":0.36976665}],"asks":[],"checksum":761948143,"timestamp":"2024-06-01T17:51:43.909801Z"}]}
{"channel":"book","type":"update","data":[{"symbol":"BTC/GBP","bids":[],"asks":[{"price":53052.0,"qty":0.00000000},{"price":53082.1,"qty":0.18777785}],"checksum":847324027,"timestamp":"2024-06-01T17:51:43.954527Z"}]}
{"channel":"book","type":"update","data":[{"symbol":"BTC/GBP","bids":[{"price":53047.1,"qty":0.36973967}],"asks":[],"checksum":929259524,"timestamp":"2024-06-01T17:51:43.958531Z"}]}
{"channel":"book","type":"update","data":[{"symbol":"BTC/GBP","bids":[],"asks":[{"price":53082.1,"qty":0.00000000},{"price":53082.2,"qty":0.01129070}],"checksum":3563147480,"timestamp":"2024-06-01T17:51:43.961764Z"}]}
{"channel":"book","type":"update","data":[{"symbol":"BTC/GBP","bids":[],"asks":[{"price":53052.6,"qty":0.00000000},{"price":53082.3,"qty":0.07402000},{"price":53058.3,"qty":0.00931900}],"checksum":3667723071,"timestamp":"2024-06-01T17:51:43.978164Z"}]}
{"channel":"book","type":"update","data":[{"symbol":"BTC/GBP","bids":[{"price":53038.6,"qty":0.00000000},{"price":52999.5,"qty":0.04239626},{"price":53043.9,"qty":0.00097400}],"asks":[],"checksum":3635143690,"timestamp":"2024-06-01T17:51:44.097059Z"}]}
{"channel":"book","type":"update","data":[{"symbol":"BTC/GBP","bids":[],"asks":[{"price":53051.9,"qty":0.00000000},{"price":53082.3,"qty":0.07402000},{"price":53057.6,"qty":0.00097400}],"checksum":1299272961,"timestamp":"2024-06-01T17:51:44.112446Z"}]}
{"channel":"book","type":"update","data":[{"symbol":"BTC/GBP","bids":[],"asks":[{"price":53058.4,"qty":0.00000000},{"price":53082.3,"qty":0.07402000},{"price":53061.7,"qty":0.00135200}],"checksum":725409593,"timestamp":"2024-06-01T17:51:44.123561Z"}]}
{"channel":"book","type":"update","data":[{"symbol":"BTC/GBP","bids":[{"price":53043.9,"qty":0.37073646}],"asks":[],"checksum":1461706443,"timestamp":"2024-06-01T17:51:44.745118Z"}]}
{"channel":"book","type":"update","data":[{"symbol":"BTC/GBP","bids":[],"asks":[{"price":53052.4,"qty":0.36970336}],"checksum":4058774531,"timestamp":"2024-06-01T17:51:44.745207Z"}]}
{"channel":"book","type":"update","data":[{"symbol":"BTC/GBP","bids":[{"price":53038.4,"qty":0.36980061}],"asks":[],"checksum":523806256,"timestamp":"2024-06-01T17:51:44.745225Z"}]}
{"channel":"book","type":"update","data":[{"symbol":"BTC/GBP","bids":[{"price":53043.8,"qty":0.00000000},{"price":53003.4,"qty":0.37004494}],"asks":[],"checksum":733836784,"timestamp":"2024-06-01T17:51:45.934302Z"}]}
{"channel":"book","type":"update","data":[{"symbol":"BTC/GBP","bids":[],"asks":[{"price":53053.5,"qty":0.00000000},{"price":53082.2,"qty":0.01129070}],"checksum":1671702907,"timestamp":"2024-06-01T17:51:45.960760Z"}]}
{"channel":"book","type":"update","data":[{"symbol":"BTC/GBP","bids":[],"asks":[{"price":53051.4,"qty":0.36971085}],"checksum":2215274585,"timestamp":"2024-06-01T17:51:45.965036Z"}]}
{"channel":"book","type":"update","data":[{"symbol":"BTC/GBP","bids":[{"price":53047.1,"qty":0.00000000},{"price":52999.5,"qty":0.04239626}],"asks":[],"checksum":4142825307,"timestamp":"2024-06-01T17:51:46.001395Z"}]}
{"channel":"book","type":"update","data":[{"symbol":"BTC/GBP","bids":[],"asks":[{"price":53052.4,"qty":0.00000000},{"price":53084.3,"qty":0.01129070}],"checksum":3826606839,"timestamp":"2024-06-01T17:51:46.001512Z"}]}
{"channel":"book","type":"update","data":[{"symbol":"BTC/GBP","bids":[{"price":53043.9,"qty":0.00097400}],"asks":[],"checksum":3626678317,"timestamp":"2024-06-01T17:51:46.001584Z"}]}
{"channel":"book","type":"update","data":[{"symbol":"BTC/GBP","bids":[],"asks":[{"price":53051.4,"qty":0.39871085}],"checksum":2316919390,"timestamp":"2024-06-01T17:51:46.004418Z"}]}
{"channel":"book","type":"update","data":[{"symbol":"BTC/GBP","bids":[],"asks":[{"price":53051.4,"qty":0.36971085}],"checksum":3626678317,"timestamp":"2024-06-01T17:51:46.004588Z"}]}
{"channel":"book","type":"update","data":[{"symbol":"BTC/GBP","bids":[],"asks":[{"price":53051.2,"qty":0.02900000}],"checksum":857883024,"timestamp":"2024-06-01T17:51:46.004618Z"}]}
{"channel":"book","type":"update","data":[{"symbol":"BTC/GBP","bids":[{"price":53044.0,"qty":0.02900000}],"asks":[],"checksum":3722172053,"timestamp":"2024-06-01T17:51:46.004651Z"}]}
{"channel":"book","type":"update","data":[{"symbol":"BTC/GBP","bids":[{"price":53044.0,"qty":0.03713613}],"asks":[],"checksum":3661179385,"timestamp":"2024-06-01T17:51:46.005429Z"}]}
{"channel":"book","type":"update","data":[{"symbol":"BTC/GBP","bids":[{"price":53046.1,"qty":0.36974692}],"asks":[],"checksum":1124464250,"timestamp":"2024-06-01T17:51:46.009393Z"}]}
{"channel":"book","type":"update","data":[{"symbol":"BTC/GBP","bids":[{"price":53038.4,"qty":0.00000000},{"price":53003.4,"qty":0.37004494}],"asks":[],"checksum":2916527177,"timestamp":"2024-06-01T17:51:46.012675Z"}]}
{"channel":"book","type":"update","data":[{"symbol":"BTC/GBP","bids":[{"price":53046.1,"qty":0.00000000},{"price":52999.5,"qty":0.04239626}],"asks":[],"checksum":2856910515,"timestamp":"2024-06-01T17:51:46.013696Z"}]}
{"channel":"book","type":"update","data":[{"symbol":"BTC/GBP","bids":[{"price":53044.0,"qty":0.02900000}],"asks":[],"checksum":628329399,"timestamp":"2024-06-01T17:51:46.014011Z"}]}
{"channel":"book","type":"update","data":[{"symbol":"BTC/GBP","bids":[{"price":53046.2,"qty":0.00813613}],"asks":[],"checksum":1856361665,"timestamp":"2024-06-01T17:51:46.014154Z"}]}
{"channel":"book","type":"update","data":[{"symbol":"BTC/GBP","bids":[{"price":53044.1,"qty":0.36976107}],"asks":[],"checksum":266578378,"timestamp":"2024-06-01T17:51:46.017889Z"}]}
{"channel":"book","type":"update","data":[{"symbol":"BTC/GBP","bids":[],"asks":[{"price":53050.4,"qty":0.36971780}],"checksum":1760662013,"timestamp":"2024-06-01T17:51:46.017923Z"}]}
{"channel":"book","type":"update","data":[{"symbol":"BTC/GBP","bids":[{"price":53037.3,"qty":0.36980779}],"asks":[],"checksum":452034142,"timestamp":"2024-06-01T17:51:46.017946Z"}]}
{"channel":"book","type":"update","data":[{"symbol":"BTC/GBP","bids":[{"price":53044.1,"qty":0.37789720}],"asks":[],"checksum":3226486180,"timestamp":"2024-06-01T17:51:46.018401Z"}]}
{"channel":"book","type":"update","data":[{"symbol":"BTC/GBP","bids":[{"price":53046.2,"qty":0.00000000},{"price":53003.9,"qty":0.00135300}],"asks":[],"checksum":3817514297,"timestamp":"2024-06-01T17:51:46.018651Z"}]}
{"channel":"book","type":"update","data":[{"symbol":"BTC/GBP","bids":[{"price":53044.1,"qty":0.00813613}],"asks":[],"checksum":1387799641,"timestamp":"2024-06-01T17:51:46.023573Z"}]}
{"channel":"book","type":"update","data":[{"symbol":"BTC/GBP","bids":[],"asks":[{"price":53058.3,"qty":0.00000000},{"price":53077.7,"qty":0.00032928},{"price":53052.3,"qty":0.00931900}],"checksum":1319543720,"timestamp":"2024-06-01T17:51:46.058689Z"}]}
{"channel":"book","type":"update","data":[{"symbol":"BTC/GBP","bids":[],"asks":[{"price":53057.6,"qty":0.00000000},{"price":53077.7,"qty":0.00032928},{"price":53052.3,"qty":0.01029300}],"checksum":455622021,"timestamp":"2024-06-01T17:51:46.109850Z"}]}
{"channel":"book","type":"update","data":[{"symbol":"BTC/GBP","bids":[{"price":53044.1,"qty":0.00000000},{"price":53003.4,"qty":0.37004494}],"asks":[],"checksum":902251370,"timestamp":"2024-06-01T17:51:46.139484Z"}]}
{"channel":"book","type":"update","data":[{"symbol":"BTC/GBP","bids":[{"price":53044.0,"qty":0.00000000},{"price":52999.5,"qty":0.04239626}],"asks":[],"checksum":949626362,"timestamp":"2024-06-01T17:51:46.142178Z"}]}
{"channel":"book","type":"update","data":[{"symbol":"BTC/GBP","bids":[],"asks":[{"price":53050.3,"qty":0.02900000}],"checksum":3603163478,"timestamp":"2024-06-01T17:51:46.142257Z"}]}
{"channel":"book","type":"update","data":[{"symbol":"BTC/GBP","bids":[],"asks":[{"price":53051.2,"qty":0.00000000},{"price":53077.7,"qty":0.00032928}],"checksum":750270711,"timestamp":"2024-06-01T17:51:46.142335Z"}]}
{"channel":"book","type":"update","data":[{"symbol":"BTC/GBP","bids":[{"price":53043.3,"qty":0.39876665}],"asks":[],"checksum":2102422625,"timestamp":"2024-06-01T17:51:46.186967Z"}]}
{"channel":"book","type":"update","data":[{"symbol":"BTC/GBP","bids":[{"price":52999.5,"qty":0.00000000},{"price":52992.5,"qty":0.01526000},{"price":53024.4,"qty":0.04239626}],"asks":[],"checksum":2373384344,"timestamp":"2024-06-01T17:51:46.314899Z"}]}
{"channel":"book","type":"update","data":[{"symbol":"BTC/GBP","bids":[{"price":53043.3,"qty":0.36976665}],"asks":[],"checksum":3701386254,"timestamp":"2024-06-01T17:51:46.344226Z"}]}
{"channel":"book","type":"update","data":[{"symbol":"BTC/GBP","bids":[{"price":53043.4,"qty":0.02900000}],"asks":[],"checksum":1349954745,"timestamp":"2024-06-01T17:51:46.344369Z"}]}
{"channel":"book","type":"update","data":[{"symbol":"BTC/GBP","bids":[{"price":53003.9,"qty":0.00000000},{"price":53003.4,"qty":0.37004494},{"price":53034.5,"qty":0.00135300}],"asks":[],"checksum":725565224,"timestamp":"2024-06-01T17:51:46.376753Z"}]}
{"channel":"book","type":"update","data":[{"symbol":"BTC/GBP","bids":[{"price":53046.3,"qty":0.36974517}],"asks":[],"checksum":954526519,"timestamp":"2024-06-01T17:51:46.788413Z"}]}
{"channel":"book","type":"update","data":[{"symbol":"BTC/GBP","bids":[],"asks":[{"price":53050.3,"qty":0.00000000},{"price":53084.4,"qty":0.18777785}],"checksum":4034417553,"timestamp":"2024-06-01T17:51:46.793125Z"}]}
{"channel":"book","type":"update","data":[{"symbol":"BTC/GBP","bids":[],"asks":[{"price":53084.3,"qty":0.07402000}],"checksum":544819892,"timestamp":"2024-06-01T17:51:46.795907Z"}]}
{"channel":"book","type":"update","data":[{"symbol":"BTC/GBP","bids":[],"asks":[{"price":53059.8,"qty":0.00000000},{"price":53084.4,"qty":0.18777785}],"checksum":3330678612,"timestamp":"2024-06-01T17:51:47.942939Z"}]}
{"channel":"book","type":"update","data":[{"symbol":"BTC/GBP","bids":[],"asks":[{"price":53050.4,"qty":0.00000000},{"price":53084.6,"qty":0.16769151}],"checksum":4009379755,"timestamp":"2024-06-01T17:51:47.942953Z"}]}
{"channel":"book","type":"update","data":[{"symbol":"BTC/GBP","bids":[{"price":53046.3,"qty":0.00000000},{"price":53011.4,"qty":0.36998902}],"asks":[],"checksum":4246836148,"timestamp":"2024-06-01T17:51:47.943007Z"}]}
{"channel":"book","type":"update","data":[{"symbol":"BTC/GBP","bids":[],"asks":[{"price":53049.1,"qty":0.36972656}],"checksum":3322647651,"timestamp":"2024-06-01T17:51:47.948642Z"}]}
{"channel":"book","type":"update","data":[{"symbol":"BTC/GBP","bids":[{"price":53045.0,"qty":0.36975411}],"asks":[],"checksum":682726664,"timestamp":"2024-06-01T17:51:47.948821Z"}]}
{"channel":"book","type":"update","data":[{"symbol":"BTC/GBP","bids":[],"asks":[{"price":53050.3,"qty":0.36971786}],"checksum":1231750283,"timestamp":"2024-06-01T17:51:47.948843Z"}]}
{"channel":"book","type":"update","data":[{"symbol":"BTC/GBP","bids":[{"price":53036.5,"qty":0.36981346}],"asks":[],"checksum":2709696589,"timestamp":"2024-06-01T17:51:47.948861Z"}]}
{"channel":"book","type":"update","data":[{"symbol":"BTC/GBP","bids":[{"price":53045.0,"qty":0.00000000},{"price":53019.9,"qty":0.36992970}],"asks":[],"checksum":2664644444,"timestamp":"2024-06-01T17:51:47.983394Z"}]}
{"channel":"book","type":"update","data":[{"symbol":"BTC/GBP","bids":[],"asks":[{"price":53050.3,"qty":0.00000000},{"price":53084.4,"qty":0.18777785}],"checksum":4278824671,"timestamp":"2024-06-01T17:51:47.983472Z"}]}
{"channel":"book","type":"update","data":[{"symbol":"BTC/GBP","bids":[],"asks":[{"price":53084.4,"qty":0.00000000},{"price":53084.6,"qty":0.16769151}],"checksum":464886905,"timestamp":"2024-06-01T17:51:47.986863Z"}]}
{"channel":"book","type":"update","data":[{"symbol":"BTC/GBP","bids":[{"price":53036.5,"qty":0.00000000},{"price":53011.4,"qty":0.36998902}],"asks":[],"checksum":582461125,"timestamp":"2024-06-01T17:51:47.989487Z"}]}
{"channel":"book","type":"update","data":[{"symbol":"BTC/GBP","bids":[],"asks":[{"price":53084.3,"qty":0.00000000},{"price":53090.0,"qty":0.01129070},{"price":53084.5,"qty":0.07402000}],"checksum":509769445,"timestamp":"2024-06-01T17:51:47.989619Z"}]}
{"channel":"book","type":"update","data":[{"symbol":"BTC/GBP","bids":[{"price":53043.3,"qty":0.00000000},{"price":53003.4,"qty":0.37004494}],"asks":[],"checksum":3179981050,"timestamp":"2024-06-01T17:51:47.989659Z"}]}
{"channel":"book","type":"update","data":[{"symbol":"BTC/GBP","bids":[],"asks":[{"price":53049.1,"qty":0.00000000},{"price":53090.0,"qty":0.01129070}],"checksum":3912512760,"timestamp":"2024-06-01T17:51:47.989708Z"}]}
{"channel":"book","type":"update","data":[{"symbol":"BTC/GBP","bids":[],"asks":[{"price":53090.0,"qty":0.00000000},{"price":53093.7,"qty":0.01542515}],"checksum":3680665353,"timestamp":"2024-06-01T17:51:47.993356Z"}]}
{"channel":"book","type":"update","data":[{"symbol":"BTC/GBP","bids":[],"asks":[{"price":53093.6,"qty":0.01129070}],"checksum":1125946861,"timestamp":"2024-06-01T17:51:47.993562Z"}]}
{"channel":"book","type":"update","data":[{"symbol":"BTC/GBP","bids":[],"asks":[{"price":53058.7,"qty":0.36965965}],"checksum":1518752476,"timestamp":"2024-06-01T17:51:47.994564Z"}]}
{"channel":"book","type":"update","data":[{"symbol":"BTC/GBP","bids":[],"asks":[{"price":53082.9,"qty":0.36949122}],"checksum":4219453584,"timestamp":"2024-06-01T17:51:47.994698Z"}]}
{"channel":"book","type":"update","data":[{"symbol":"BTC/GBP","bids":[{"price":53044.0,"qty":0.36976177}],"asks":[],"checksum":4106229373,"timestamp":"2024-06-01T17:51:47.994731Z"}]}
{"channel":"book","type":"update","data":[{"symbol":"BTC/GBP","bids":[{"price":53044.0,"qty":0.00000000},{"price":53003.4,"qty":0.37004494}],"asks":[],"checksum":4219453584,"timestamp":"2024-06-01T17:51:47.999405Z"}]}
{"channel":"book","type":"update","data":[{"symbol":"BTC/GBP","bids":[],"asks":[{"price":53051.1,"qty":0.02900000}],"checksum":2304971237,"timestamp":"2024-06-01T17:51:48.002337Z"}]}
{"channel":"book","type":"update","data":[{"symbol":"BTC/GBP","bids":[{"price":53046.0,"qty":0.36974761}],"asks":[],"checksum":2979604078,"timestamp":"2024-06-01T17:51:48.003241Z"}]}
{"channel":"book","type":"update","data":[{"symbol":"BTC/GBP","bids":[],"asks":[{"price":53051.4,"qty":0.00000000},{"price":53084.5,"qty":0.07402000}],"checksum":792456974,"timestamp":"2024-06-01T17:51:48.008011Z"}]}
{"channel":"book","type":"update","data":[{"symbol":"BTC/GBP","bids":[],"asks":[{"price":53051.0,"qty":0.36971298}],"checksum":1686803500,"timestamp":"2024-06-01T17:51:48.011991Z"}]}
{"channel":"book","type":"update","data":[{"symbol":"BTC/GBP","bids":[],"asks":[{"price":53082.8,"qty":0.18777785}],"checksum":107961212,"timestamp":"2024-06-01T17:51:48.015169Z"}]}
{"channel":"book","type":"update","data":[{"symbol":"BTC/GBP","bids":[{"price":53046.0,"qty":0.00000000},{"price":53003.4,"qty":0.37004494}],"asks":[],"checksum":1049980151,"timestamp":"2024-06-01T17:51:48.233476Z"}]}
{"channel":"book","type":"update","data":[{"symbol":"BTC/GBP","bids":[],"asks":[{"price":53051.1,"qty":0.00000000},{"price":53082.9,"qty":0.36949122}],"checksum":706264240,"timestamp":"2024-06-01T17:51:48.236397Z"}]}
{"channel":"book","type":"update","data":[{"symbol":"BTC/GBP","bids":[],"asks":[{"price":53050.8,"qty":0.02900000}],"checksum":1161035372,"timestamp":"2024-06-01T17:51:48.236678Z"}]}
{"channel":"book","type":"update","data":[{"symbol":"BTC/GBP","bids":[{"price":53045.7,"qty":0.36974984}],"asks":[],"checksum":4041198873,"timestamp":"2024-06-01T17:51:48.241455Z"}]}
{"channel":"book","type":"update","data":[{"symbol":"BTC/GBP","bids":[{"price":53044.1,"qty":0.36976107}],"asks":[],"checksum":403274583,"timestamp":"2024-06-01T17:51:48.241482Z"}]}
{"channel":"book","type":"update","data":[{"symbol":"BTC/GBP","bids":[],"asks":[{"price":53050.0,"qty":0.36972031}],"checksum":3501906809,"timestamp":"2024-06-01T17:51:48.241500Z"}]}
{"channel":"book","type":"update","data":[{"symbol":"BTC/GBP","bids":[],"asks":[{"price":53055.5,"qty":0.00000000},{"price":53082.8,"qty":0.18777785}],"checksum":2472264247,"timestamp":"2024-06-01T17:51:48.250072Z"}]}
{"channel":"book","type":"update","data":[{"symbol":"BTC/GBP","bids":[{"price":53045.7,"qty":0.00000000},{"price":53011.4,"qty":0.36998902}],"asks":[],"checksum":1585325329,"timestamp":"2024-06-01T17:51:48.250350Z"}]}
{"channel":"book","type":"update","data":[{"symbol":"BTC/GBP","bids":[{"price":53041.2,"qty":0.36978102}],"asks":[],"checksum":1607609476,"timestamp":"2024-06-01T17:51:48.254496Z"}]}
{"channel":"book","type":"update","data":[{"symbol":"BTC/GBP","bids":[],"asks":[{"price":53050.7,"qty":0.36971507}],"checksum":4201070040,"timestamp":"2024-06-01T17:51:48.254547Z"}]}
{"channel":"book","type":"update","data":[{"symbol":"BTC/GBP","bids":[],"asks":[{"price":53050.7,"qty":0.00000000},{"price":53082.8,"qty":0.18777785}],"checksum":1607609476,"timestamp":"2024-06-01T17:51:48.288948Z"}]}
{"channel":"book","type":"update","data":[{"symbol":"BTC/GBP","bids":[],"asks":[{"price":53053.9,"qty":0.36969300}],"checksum":2437148083,"timestamp":"2024-06-01T17:51:48.292787Z"}]}
{"channel":"book","type":"update","data":[{"symbol":"BTC/GBP","bids":[{"price":53044.1,"qty":0.00000000},{"price":53011.4,"qty":0.36998902}],"asks":[],"checksum":1774785038,"timestamp":"2024-06-01T17:51:48.454270Z"}]}
{"channel":"book","type":"update","data":[{"symbol":"BTC/GBP","bids":[{"price":53045.2,"qty":0.36975334}],"asks":[],"checksum":1616834056,"timestamp":"2024-06-01T17:51:48.454354Z"}]}
{"channel":"book","type":"update","data":[{"symbol":"BTC/GBP","bids":[{"price":53044.2,"qty":0.36976037}],"asks":[],"checksum":3699548255,"timestamp":"2024-06-01T17:51:48.459360Z"}]}
{"channel":"book","type":"update","data":[{"symbol":"BTC/GBP","bids":[],"asks":[{"price":53050.0,"qty":0.00000000},{"price":53082.8,"qty":0.18777785}],"checksum":3064245354,"timestamp":"2024-06-01T17:51:48.587891Z"}]}
{"channel":"book","type":"update","data":[{"symbol":"BTC/GBP","bids":[{"price":53044.2,"qty":0.00000000},{"price":53019.9,"qty":0.36992970}],"asks":[],"checksum":175694397,"timestamp":"2024-06-01T17:51:48.587962Z"}]}
{"channel":"book","type":"update","data":[{"symbol":"BTC/GBP","bids":[],"asks":[{"price":53050.8,"qty":0.00000000},{"price":53082.9,"qty":0.36949122}],"checksum":2551875324,"timestamp":"2024-06-01T17:51:48.590743Z"}]}
{"channel":"book","type":"update","data":[{"symbol":"BTC/GBP","bids":[],"asks":[{"price":53082.7,"qty":0.07402000}],"checksum":3085579768,"timestamp":"2024-06-01T17:51:48.590853Z"}]}
{"channel":"book","type":"update","data":[{"symbol":"BTC/GBP","bids":[],"asks":[{"price":53054.9,"qty":0.38732592}],"checksum":3100466695,"timestamp":"2024-06-01T17:51:48.592363Z"}]}
{"channel":"book","type":"update","data":[{"symbol":"BTC/GBP","bids":[{"price":53046.2,"qty":0.36974585}],"asks":[],"checksum":1896631518,"timestamp":"2024-06-01T17:51:48.592467Z"}]}
{"channel":"book","type":"update","data":[{"symbol":"BTC/GBP","bids":[],"asks":[{"price":53054.9,"qty":0.01764000}],"checksum":2116757281,"timestamp":"2024-06-01T17:51:49.541594Z"}]}
{"channel":"book","type":"update","data":[{"symbol":"BTC/GBP","bids":[{"price":53046.2,"qty":0.00000000},{"price":53019.9,"qty":0.36992970}],"asks":[],"checksum":3085579768,"timestamp":"2024-06-01T17:51:49.541625Z"}]}
{"channel":"book","type":"update","data":[{"symbol":"BTC/GBP","bids":[],"asks":[{"price":53051.0,"qty":0.00000000},{"price":53082.9,"qty":0.36949122}],"checksum":2074609108,"timestamp":"2024-06-01T17:51:49.547261Z"}]}
{"channel":"book","type":"update","data":[{"symbol":"BTC/GBP","bids":[],"asks":[{"price":53049.7,"qty":0.36972273}],"checksum":2200925235,"timestamp":"2024-06-01T17:51:49.547273Z"}]}
{"channel":"book","type":"update","data":[{"symbol":"BTC/GBP","bids":[{"price":53040.8,"qty":0.36978348}],"asks":[],"checksum":2795682071,"timestamp":"2024-06-01T17:51:49.547285Z"}]}
{"channel":"book","type":"update","data":[{"symbol":"BTC/GBP","bids":[],"asks":[{"price":53050.9,"qty":0.36971367}],"checksum":1434670471,"timestamp":"2024-06-01T17:51:49.551865Z"}]}
{"channel":"book","type":"update","data":[{"symbol":"BTC/GBP","bids":[],"asks":[{"price":53049.7,"qty":0.00000000},{"price":53082.8,"qty":0.18777785}],"checksum":2123826278,"timestamp":"2024-06-01T17:51:49.578557Z"}]}
{"channel":"book","type":"update","data":[{"symbol":"BTC/GBP","bids":[{"price":53040.8,"qty":0.00000000},{"price":53019.9,"qty":0.36992970}],"asks":[],"checksum":1528482114,"timestamp":"2024-06-01T17:51:49.578568Z"}]}
{"channel":"book","type":"update","data":[{"symbol":"BTC/GBP","bids":[{"price":53045.2,"qty":0.00000000},{"price":53011.4,"qty":0.36998902}],"asks":[],"checksum":1384985924,"timestamp":"2024-06-01T17:51:49.592117Z"}]}
{"channel":"book","type":"update","data":[{"symbol":"BTC/GBP","bids":[],"asks":[{"price":53050.9,"qty":0.00000000},{"price":53082.9,"qty":0.36949122}],"checksum":1916795346,"timestamp":"2024-06-01T17:51:49.593645Z"}]}
{"channel":"book","type":"update","data":[{"symbol":"BTC/GBP","bids":[{"price":53037.3,"qty":0.00000000},{"price":53003.4,"qty":0.37004494}],"asks":[],"checksum":738913056,"timestamp":"2024-06-01T17:51:49.593745Z"}]}
{"channel":"book","type":"update","data":[{"symbol":"BTC/GBP","bids":[{"price":53019.9,"qty":0.00000000},{"price":52992.5,"qty":0.01526000}],"asks":[],"checksum":601584933,"timestamp":"2024-06-01T17:51:49.593985Z"}]}
{"channel":"book","type":"update","data":[{"symbol":"BTC/GBP","bids":[{"price":53050.8,"qty":0.14781530}],"asks":[],"checksum":1557646728,"timestamp":"2024-06-01T17:51:49.598692Z"}]}
{"channel":"book","type":"update","data":[{"symbol":"BTC/GBP","bids":[],"asks":[{"price":53053.9,"qty":0.00000000},{"price":53084.6,"qty":0.16769151}],"checksum":3189777686,"timestamp":"2024-06-01T17:51:49.606192Z"}]}
{"channel":"book","type":"update","data":[{"symbol":"BTC/GBP","bids":[],"asks":[{"price":53082.9,"qty":0.00000000},{"price":53093.6,"qty":0.01129070}],"checksum":1377116368,"timestamp":"2024-06-01T17:51:49.617249Z"}]}
{"channel":"book","type":"update","data":[{"symbol":"BTC/GBP","bids":[{"price":53052.2,"qty":0.14781025}],"asks":[],"checksum":3489992966,"timestamp":"2024-06-01T17:51:49.618593Z"}]}
{"channel":"book","type":"update","data":[{"symbol":"BTC/GBP","bids":[{"price":53050.8,"qty":0.00000000},{"price":53003.4,"qty":0.37004494}],"asks":[],"checksum":484601339,"timestamp":"2024-06-01T17:51:49.620763Z"}]}
{"channel":"book","type":"update","data":[{"symbol":"BTC/GBP","bids":[],"asks":[{"price":53082.8,"qty":0.00000000},{"price":53093.7,"qty":0.01542515}],"checksum":39347216,"timestamp":"2024-06-01T17:51:49.632830Z"}]}
{"channel":"book","type":"update","data":[{"symbol":"BTC/GBP","bids":[],"asks":[{"price":53082.7,"qty":0.00000000},{"price":53095.5,"qty":0.18777785},{"price":53084.5,"qty":0.07402000}],"checksum":3185903435,"timestamp":"2024-06-01T17:51:49.638118Z"}]}
{"channel":"book","type":"update","data":[{"symbol":"BTC/GBP","bids":[],"asks":[{"price":53056.3,"qty":0.36967639}],"checksum":2540023793,"timestamp":"2024-06-01T17:51:49.645307Z"}]}
{"channel":"book","type":"update","data":[{"symbol":"BTC/GBP","bids":[{"price":53050.7,"qty":0.36971444}],"asks":[],"checksum":986080543,"timestamp":"2024-06-01T17:51:49.645348Z"}]}
{"channel":"book","type":"update","data":[{"symbol":"BTC/GBP","bids":[{"price":53045.3,"qty":0.36975271}],"asks":[],"checksum":2990341188,"timestamp":"2024-06-01T17:51:49.645413Z"}]}
{"channel":"book","type":"update","data":[{"symbol":"BTC/GBP","bids":[{"price":53027.9,"qty":0.36987340}],"asks":[],"checksum":1989767692,"timestamp":"2024-06-01T17:51:49.645437Z"}]}
{"channel":"book","type":"update","data":[{"symbol":"BTC/GBP","bids":[],"asks":[{"price":53059.2,"qty":0.36965645}],"checksum":3502764045,"timestamp":"2024-06-01T17:51:49.645496Z"}]}
{"channel":"book","type":"update","data":[{"symbol":"BTC/GBP","bids":[],"asks":[{"price":53062.7,"qty":0.36963169}],"checksum":551972382,"timestamp":"2024-06-01T17:51:49.645536Z"}]}
{"channel":"book","type":"update","data":[{"symbol":"BTC/GBP","bids":[{"price":53050.7,"qty":0.00000000},{"price":53024.4,"qty":0.04239626}],"asks":[],"checksum":42959457,"timestamp":"2024-06-01T17:51:49.678165Z"}]}
{"channel":"book","type":"update","data":[{"symbol":"BTC/GBP","bids":[],"asks":[{"price":53059.2,"qty":0.00000000},{"price":53084.6,"qty":0.16769151}],"checksum":98487538,"timestamp":"2024-06-01T17:51:49.678320Z"}]}
{"channel":"book","type":"update","data":[{"symbol":"BTC/GBP","bids":[],"asks":[{"price":53062.7,"qty":0.00000000},{"price":53093.6,"qty":0.01129070}],"checksum":3461854036,"timestamp":"2024-06-01T17:51:49.693841Z"}]}
{"channel":"book","type":"update","data":[{"symbol":"BTC/GBP","bids":[],"asks":[{"price":53061.7,"qty":0.00000000},{"price":53093.7,"qty":0.01542515},{"price":53057.1,"qty":0.00135200}],"checksum":455517867,"timestamp":"2024-06-01T17:51:49.708136Z"}]}
{"channel":"book","type":"update","data":[{"symbol":"BTC/GBP","bids":[{"price":53049.4,"qty":0.36972365}],"asks":[],"checksum":2252592924,"timestamp":"2024-06-01T17:51:49.709106Z"}]}
{"channel":"book","type":"update","data":[{"symbol":"BTC/GBP","bids":[{"price":53052.2,"qty":0.00000000},{"price":53024.4,"qty":0.04239626}],"asks":[],"checksum":341970219,"timestamp":"2024-06-01T17:51:49.726823Z"}]}
{"channel":"book","type":"update","data":[{"symbol":"BTC/GBP","bids":[{"price":53049.4,"qty":0.00000000},{"price":53011.4,"qty":0.36998902}],"asks":[],"checksum":1235346013,"timestamp":"2024-06-01T17:51:49.734898Z"}]}
{"channel":"book","type":"update","data":[{"symbol":"BTC/GBP","bids":[{"price":53045.8,"qty":0.14783543}],"asks":[],"checksum":1165362081,"timestamp":"2024-06-01T17:51:49.739300Z"}]}
{"channel":"book","type":"update","data":[{"symbol":"BTC/GBP","bids":[],"asks":[{"price":53053.9,"qty":0.36969317}],"checksum":3607598315,"timestamp":"2024-06-01T17:51:49.739640Z"}]}
{"channel":"book","type":"update","data":[{"symbol":"BTC/GBP","bids":[{"price":53040.4,"qty":0.36978672}],"asks":[],"checksum":2887592463,"timestamp":"2024-06-01T17:51:49.739720Z"}]}
{"channel":"book","type":"update","data":[{"symbol":"BTC/GBP","bids":[{"price":53041.2,"qty":0.00000000},{"price":53024.4,"qty":0.04239626}],"asks":[],"checksum":1005572544,"timestamp":"2024-06-01T17:51:49.744995Z"}]}
{"channel":"book","type":"update","data":[{"symbol":"BTC/GBP","bids":[{"price":53045.9,"qty":0.36974852}],"asks":[],"checksum":542094388,"timestamp":"2024-06-01T17:51:49.749583Z"}]}
{"channel":"book","type":"update","data":[{"symbol":"BTC/GBP","bids":[{"price":53046.4,"qty":0.14783398}],"asks":[],"checksum":4147359330,"timestamp":"2024-06-01T17:51:49.752627Z"}]}
{"channel":"book","type":"update","data":[{"symbol":"BTC/GBP","bids":[{"price":53045.9,"qty":0.00000000},{"price":53027.9,"qty":0.36987340}],"asks":[],"checksum":880079232,"timestamp":"2024-06-01T17:51:49.754444Z"}]}
{"channel":"book","type":"update","data":[{"symbol":"BTC/GBP","bids":[{"price":53045.8,"qty":0.00000000},{"price":53024.4,"qty":0.04239626}],"asks":[],"checksum":2874970427,"timestamp":"2024-06-01T17:51:49.755541Z"}]}
{"channel":"book","type":"update","data":[{"symbol":"BTC/GBP","bids":[],"asks":[{"price":53053.9,"qty":0.00000000},{"price":53093.6,"qty":0.01129070}],"checksum":959252081,"timestamp":"2024-06-01T17:51:49.760271Z"}]}
{"channel":"book","type":"update","data":[{"symbol":"BTC/GBP","bids":[{"price":53045.3,"qty":0.00000000},{"price":53011.4,"qty":0.36998902}],"asks":[],"checksum":2994713149,"timestamp":"2024-06-01T17:51:49.760332Z"}]}
{"channel":"book","type":"update","data":[{"symbol":"BTC/GBP","bids":[{"price":53049.8,"qty":0.36972102}],"asks":[],"checksum":4276297247,"timestamp":"2024-06-01T17:51:49.764410Z"}]}
{"channel":"book","type":"update","data":[{"symbol":"BTC/GBP","bids":[],"asks":[{"price":53058.7,"qty":0.00000000},{"price":53093.7,"qty":0.01542515}],"checksum":2071977319,"timestamp":"2024-06-01T17:51:49.785123Z"}]}
{"channel":"book","type":"update","data":[{"symbol":"BTC/GBP","bids":[{"price":53049.8,"qty":0.00000000},{"price":53011.4,"qty":0.36998902}],"asks":[],"checksum":937652549,"timestamp":"2024-06-01T17:51:49.809565Z"}]}
{"channel":"book","type":"update","data":[{"symbol":"BTC/GBP","bids":[],"asks":[{"price":53055.4,"qty":0.36968289}],"checksum":1966571401,"timestamp":"2024-06-01T17:51:49.814868Z"}]}
{"channel":"book","type":"update","data":[{"symbol":"BTC/GBP","bids":[{"price":53045.3,"qty":0.36975266}],"asks":[],"checksum":132819267,"timestamp":"2024-06-01T17:51:49.814971Z"}]}
{"channel":"book","type":"update","data":[{"symbol":"BTC/GBP","bids":[{"price":53048.7,"qty":0.36972875}],"asks":[],"checksum":2274873598,"timestamp":"2024-06-01T17:51:49.818997Z"}]}
{"channel":"book","type":"update","data":[{"symbol":"BTC/GBP","bids":[],"asks":[{"price":53056.3,"qty":0.00000000},{"price":53093.7,"qty":0.01542515}],"checksum":2195140112,"timestamp":"2024-06-01T17:51:49.835290Z"}]}
{"channel":"book","type":"update","data":[{"symbol":"BTC/GBP","bids":[],"asks":[{"price":53057.1,"qty":0.00000000},{"price":53095.5,"qty":0.18777785},{"price":53065.3,"qty":0.00135200}],"checksum":731670695,"timestamp":"2024-06-01T17:51:49.894652Z"}]}
{"channel":"book","type":"update","data":[{"symbol":"BTC/GBP","bids":[{"price":53034.3,"qty":0.04239626}],"asks":[],"checksum":4041082402,"timestamp":"2024-06-01T17:51:49.932427Z"}]}
{"channel":"book","type":"update","data":[{"symbol":"BTC/GBP","bids":[{"price":53043.4,"qty":0.00000000},{"price":53027.9,"qty":0.36987340}],"asks":[],"checksum":2902757672,"timestamp":"2024-06-01T17:51:50.245107Z"}]}
{"channel":"book","type":"update","data":[{"symbol":"BTC/GBP","bids":[{"price":53049.3,"qty":0.02900000}],"asks":[],"checksum":634828834,"timestamp":"2024-06-01T17:51:50.245380Z"}]}
{"channel":"book","type":"update","data":[{"symbol":"BTC/GBP","bids":[],"asks":[{"price":53059.3,"qty":0.36965518}],"checksum":3765768605,"timestamp":"2024-06-01T17:51:50.989227Z"}]}
{"channel":"book","type":"update","data":[{"symbol":"BTC/GBP","bids":[{"price":53046.5,"qty":0.36974434}],"asks":[],"checksum":3235778814,"timestamp":"2024-06-01T17:51:50.989261Z"}]}
{"channel":"book","type":"update","data":[{"symbol":"BTC/GBP","bids":[],"asks":[{"price":53063.4,"qty":0.36962712}],"checksum":308932187,"timestamp":"2024-06-01T17:51:50.989321Z"}]}
{"channel":"book","type":"update","data":[{"symbol":"BTC/GBP","bids":[],"asks":[{"price":53054.3,"qty":0.36969056}],"checksum":3708922945,"timestamp":"2024-06-01T17:51:50.989333Z"}]}
{"channel":"book","type":"update","data":[{"symbol":"BTC/GBP","bids":[{"price":53034.5,"qty":0.00000000},{"price":53029.3,"qty":0.30183244},{"price":53038.5,"qty":0.00135300}],"asks":[],"checksum":3927613836,"timestamp":"2024-06-01T17:51:51.156083Z"}]}
{"channel":"book","type":"update","data":[{"symbol":"BTC/GBP","bids":[{"price":53049.8,"qty":0.14782448}],"asks":[],"checksum":1289931577,"timestamp":"2024-06-01T17:51:51.360099Z"}]}
{"channel":"book","type":"update","data":[{"symbol":"BTC/GBP","bids":[{"price":53046.4,"qty":0.00000000},{"price":53034.3,"qty":0.04239626}],"asks":[],"checksum":3590134365,"timestamp":"2024-06-01T17:51:51.360277Z"}]}
{"channel":"book","type":"update","data":[{"symbol":"BTC/GBP","bids":[{"price":53049.3,"qty":0.00000000},{"price":53029.3,"qty":0.30183244}],"asks":[],"checksum":411067923,"timestamp":"2024-06-01T17:51:51.362741Z"}]}
{"channel":"book","type":"update","data":[{"symbol":"BTC/GBP","bids":[{"price":53050.0,"qty":0.02900000}],"asks":[],"checksum":164001823,"timestamp":"2024-06-01T17:51:51.362887Z"}]}
{"channel":"book","type":"update","data":[{"symbol":"BTC/GBP","bids":[{"price":53050.0,"qty":0.02824593}],"asks":[],"checksum":1681785857,"timestamp":"2024-06-01T17:51:51.526856Z"}]}
{"channel":"book","type":"update","data":[{"symbol":"BTC/GBP","bids":[{"price":53046.5,"qty":0.00000000},{"price":53029.3,"qty":0.30183244}],"asks":[],"checksum":509848947,"timestamp":"2024-06-01T17:51:51.572855Z"}]}
{"channel":"book","type":"update","data":[{"symbol":"BTC/GBP","bids":[{"price":53049.6,"qty":0.36972205}],"asks":[],"checksum":733965030,"timestamp":"2024-06-01T17:51:51.577472Z"}]}
{"channel":"book","type":"update","data":[{"symbol":"BTC/GBP","bids":[{"price":53038.5,"qty":0.00000000},{"price":53029.3,"qty":0.30183244},{"price":53035.1,"qty":0.00135300}],"asks":[],"checksum":3447918572,"timestamp":"2024-06-01T17:51:52.178125Z"}]}
{"channel":"book","type":"update","data":[{"symbol":"BTC/GBP","bids":[],"asks":[{"price":53052.3,"qty":0.00097400},{"price":53055.8,"qty":0.00931900}],"checksum":2932996638,"timestamp":"2024-06-01T17:51:52.232260Z"}]}
{"channel":"book","type":"update","data":[{"symbol":"BTC/GBP","bids":[{"price":53043.9,"qty":0.00000000},{"price":53029.3,"qty":0.30183244},{"price":53048.0,"qty":0.00097400}],"asks":[],"checksum":532889537,"timestamp":"2024-06-01T17:51:52.252674Z"}]}
{"channel":"book","type":"update","data":[{"symbol":"BTC/GBP","bids":[],"asks":[{"price":53052.3,"qty":0.00000000},{"price":53084.5,"qty":0.07402000},{"price":53055.1,"qty":0.00097400}],"checksum":2834656234,"timestamp":"2024-06-01T17:51:52.252875Z"}]}
{"channel":"book","type":"update","data":[{"symbol":"BTC/GBP","bids":[{"price":53049.8,"qty":0.00000000},{"price":53029.3,"qty":0.30183244}],"asks":[],"checksum":1855779584,"timestamp":"2024-06-01T17:51:53.888730Z"}]}
{"channel":"book","type":"update","data":[{"symbol":"BTC/GBP","bids":[],"asks":[{"price":53054.2,"qty":0.00471418}],"checksum":324956736,"timestamp":"2024-06-01T17:51:53.893072Z"}]}
{"channel":"book","type":"update","data":[{"symbol":"BTC/GBP","bids":[],"asks":[{"price":53054.3,"qty":0.00000000},{"price":53077.7,"qty":0.00032928}],"checksum":1123991370,"timestamp":"2024-06-01T17:51:53.898034Z"}]}
{"channel":"book","type":"update","data":[{"symbol":"BTC/GBP","bids":[],"asks":[{"price":53054.1,"qty":0.36969138}],"checksum":639262987,"timestamp":"2024-06-01T17:51:53.901807Z"}]}
{"channel":"book","type":"update","data":[{"symbol":"BTC/GBP","bids":[],"asks":[{"price":53054.2,"qty":0.00000000},{"price":53077.7,"qty":0.00032928}],"checksum":1367252950,"timestamp":"2024-06-01T17:51:53.905441Z"}]}
{"channel":"book","type":"update","data":[{"symbol":"BTC/GBP","bids":[],"asks":[{"price":53054.0,"qty":0.00471418}],"checksum":2421946383,"timestamp":"2024-06-01T17:51:53.909449Z"}]}
{"channel":"book","type":"update","data":[{"symbol":"BTC/GBP","bids":[],"asks":[{"price":53054.0,"qty":0.00000000},{"price":53077.7,"qty":0.00032928}],"checksum":1367252950,"timestamp":"2024-06-01T17:51:53.948540Z"}]}
{"channel":"book","type":"update","data":[{"symbol":"BTC/GBP","bids":[{"price":53050.0,"qty":0.00000000},{"price":53027.9,"qty":0.36987340}],"asks":[],"checksum":3649283556,"timestamp":"2024-06-01T17:51:53.956246Z"}]}
{"channel":"book","type":"update","data":[{"symbol":"BTC/GBP","bids":[{"price":53049.6,"qty":0.00000000},{"price":53011.4,"qty":0.36998902}],"asks":[],"checksum":1944419871,"timestamp":"2024-06-01T17:51:54.007405Z"}]}
{"channel":"book","type":"update","data":[{"symbol":"BTC/GBP","bids":[{"price":53044.5,"qty":0.36975803}],"asks":[],"checksum":2270283004,"timestamp":"2024-06-01T17:51:54.012413Z"}]}
{"channel":"book","type":"update","data":[{"symbol":"BTC/GBP","bids":[],"asks":[{"price":53063.4,"qty":0.00000000},{"price":53084.3,"qty":0.07402000}],"checksum":531707070,"timestamp":"2024-06-01T17:51:54.196590Z"}]}
{"channel":"book","type":"update","data":[{"symbol":"BTC/GBP","bids":[],"asks":[{"price":53053.1,"qty":0.36969872}],"checksum":3452753495,"timestamp":"2024-06-01T17:51:54.200326Z"}]}
{"channel":"book","type":"update","data":[{"symbol":"BTC/GBP","bids":[],"asks":[{"price":53065.3,"qty":0.00000000},{"price":53084.3,"qty":0.07402000},{"price":53059.5,"qty":0.00135200}],"checksum":630698422,"timestamp":"2024-06-01T17:51:54.864955Z"}]}
{"channel":"book","type":"update","data":[{"symbol":"BTC/GBP","bids":[],"asks":[{"price":53053.1,"qty":0.00000000},{"price":53084.3,"qty":0.07402000}],"checksum":1339981840,"timestamp":"2024-06-01T17:51:55.000141Z"}]}
{"channel":"book","type":"update","data":[{"symbol":"BTC/GBP","bids":[],"asks":[{"price":53054.0,"qty":0.00471418}],"checksum":936322576,"timestamp":"2024-06-01T17:51:55.004786Z"}]}
{"channel":"book","type":"update","data":[{"symbol":"BTC/GBP","bids":[],"asks":[{"price":53061.5,"qty":0.36963998}],"checksum":3964582518,"timestamp":"2024-06-01T17:51:55.005315Z"}]}
{"channel":"book","type":"update","data":[{"symbol":"BTC/GBP","bids":[],"asks":[{"price":53054.1,"qty":0.00000000},{"price":53077.7,"qty":0.00032928}],"checksum":1675797680,"timestamp":"2024-06-01T17:51:55.009376Z"}]}
