{"channel":"book","type":"snapshot","data":[{"symbol":"BTC/USD","bids":[{"price":67577.1,"qty":10.03414098},{"price":67573.9,"qty":0.33750000},{"price":67570.6,"qty":1.56667252},{"price":67570.5,"qty":0.38827528},{"price":67558.4,"qty":0.44350000},{"price":67555.0,"qty":9.35601624},{"price":67549.6,"qty":0.48001934},{"price":67549.5,"qty":0.05751040},{"price":67549.4,"qty":0.01542984},{"price":67548.2,"qty":0.33750000}],"asks":[{"price":67577.2,"qty":0.00173834},{"price":67581.5,"qty":0.00043562},{"price":67594.4,"qty":0.07615541},{"price":67594.5,"qty":0.00100000},{"price":67599.9,"qty":0.00100000},{"price":67601.3,"qty":0.00010000},{"price":67602.6,"qty":0.00016909},{"price":67603.0,"qty":0.00010000},{"price":67607.9,"qty":0.00034728},{"price":67608.0,"qty":0.01477199}],"checksum":675837035}]}
{"channel":"book","type":"update","data":[{"symbol":"BTC/USD","bids":[{"price":67577.1,"qty":10.03444990}],"asks":[],"checksum":3496314313,"timestamp":"2024-06-01T17:51:34.355544Z"}]}
{"channel":"book","type":"update","data":[{"symbol":"BTC/USD","bids":[{"price":67577.1,"qty":10.17264990}],"asks":[],"checksum":1287258008,"timestamp":"2024-06-01T17:51:34.357584Z"}]}
{"channel":"book","type":"update","data":[{"symbol":"BTC/USD","bids":[],"asks":[{"price":67608.0,"qty":0.00000000},{"price":67608.1,"qty":0.01465202}],"checksum":3415818744,"timestamp":"2024-06-01T17:51:34.359552Z"}]}
{"channel":"book","type":"update","data":[{"symbol":"BTC/USD","bids":[],"asks":[{"price":67608.1,"qty":0.00000000},{"price":67608.2,"qty":0.01457708}],"checksum":3368635577,"timestamp":"2024-06-01T17:51:34.359600Z"}]}
{"channel":"book","type":"update","data":[{"symbol":"BTC/USD","bids":[],"asks":[{"price":67608.2,"qty":0.00000000},{"price":67612.3,"qty":0.02961607}],"checksum":1832205377,"timestamp":"2024-06-01T17:51:34.359723Z"}]}
{"channel":"book","type":"update","data":[{"symbol":"BTC/USD","bids":[{"price":67555.0,"qty":8.92432706}],"asks":[],"checksum":3717723028,"timestamp":"2024-06-01T17:51:34.359795Z"}]}
{"channel":"book","type":"update","data":[{"symbol":"BTC/USD","bids":[{"price":67555.0,"qty":8.90620706},{"price":67577.1,"qty":10.19076990}],"asks":[],"checksum":3718319041,"timestamp":"2024-06-01T17:51:34.360552Z"}]}
{"channel":"book","type":"update","data":[{"symbol":"BTC/USD","bids":[{"price":67555.0,"qty":8.90223706},{"price":67577.1,"qty":10.19473990}],"asks":[],"checksum":1861079783,"timestamp":"2024-06-01T17:51:34.360643Z"}]}
{"channel":"book","type":"update","data":[{"symbol":"BTC/USD","bids":[{"price":67555.0,"qty":6.84323706}],"asks":[],"checksum":4004751887,"timestamp":"2024-06-01T17:51:34.376428Z"}]}
{"channel":"book","type":"update","data":[{"symbol":"BTC/USD","bids":[{"price":67572.0,"qty":1.02300000}],"asks":[],"checksum":3388171848,"timestamp":"2024-06-01T17:51:34.385231Z"}]}
{"channel":"book","type":"update","data":[{"symbol":"BTC/USD","bids":[{"price":67570.6,"qty":4.29567252}],"asks":[],"checksum":2829273954,"timestamp":"2024-06-01T17:51:34.386184Z"}]}
{"channel":"book","type":"update","data":[{"symbol":"BTC/USD","bids":[{"price":67555.0,"qty":6.80376208}],"asks":[],"checksum":2757027005,"timestamp":"2024-06-01T17:51:34.389428Z"}]}
{"channel":"book","type":"update","data":[{"symbol":"BTC/USD","bids":[{"price":67570.5,"qty":0.61664390}],"asks":[],"checksum":3593573060,"timestamp":"2024-06-01T17:51:34.392549Z"}]}
{"channel":"book","type":"update","data":[{"symbol":"BTC/USD","bids":[],"asks":[{"price":67607.9,"qty":0.00000000},{"price":67613.6,"qty":0.11091373},{"price":67608.0,"qty":0.00034730}],"checksum":3626048120,"timestamp":"2024-06-01T17:51:34.394568Z"}]}
{"channel":"book","type":"update","data":[{"symbol":"BTC/USD","bids":[{"price":67555.0,"qty":6.80261623},{"price":67577.1,"qty":10.19588112}],"asks":[],"checksum":590239817,"timestamp":"2024-06-01T17:51:34.394649Z"}]}
{"channel":"book","type":"update","data":[{"symbol":"BTC/USD","bids":[{"price":67577.1,"qty":12.82188112}],"asks":[],"checksum":2047861144,"timestamp":"2024-06-01T17:51:34.416908Z"}]}
{"channel":"book","type":"update","data":[{"symbol":"BTC/USD","bids":[{"price":67570.6,"qty":1.56667252}],"asks":[],"checksum":459263154,"timestamp":"2024-06-01T17:51:34.421288Z"}]}
{"channel":"book","type":"update","data":[{"symbol":"BTC/USD","bids":[{"price":67577.1,"qty":12.86135610}],"asks":[],"checksum":3348772000,"timestamp":"2024-06-01T17:51:34.421318Z"}]}
{"channel":"book","type":"update","data":[{"symbol":"BTC/USD","bids":[],"asks":[{"price":67594.5,"qty":0.00000000},{"price":67613.6,"qty":0.11091373}],"checksum":3804633192,"timestamp":"2024-06-01T17:51:34.433233Z"}]}
{"channel":"book","type":"update","data":[{"symbol":"BTC/USD","bids":[{"price":67555.0,"qty":6.79800756}],"asks":[],"checksum":2047556146,"timestamp":"2024-06-01T17:51:34.441677Z"}]}
{"channel":"book","type":"update","data":[{"symbol":"BTC/USD","bids":[{"price":67571.2,"qty":0.00460867}],"asks":[],"checksum":3713134699,"timestamp":"2024-06-01T17:51:34.442640Z"}]}
{"channel":"book","type":"update","data":[{"symbol":"BTC/USD","bids":[],"asks":[{"price":67608.0,"qty":0.00000000},{"price":67616.3,"qty":0.00120000},{"price":67616.2,"qty":0.00034730}],"checksum":246939943,"timestamp":"2024-06-01T17:51:34.471203Z"}]}
{"channel":"book","type":"update","data":[{"symbol":"BTC/USD","bids":[{"price":67555.0,"qty":6.76642704}],"asks":[],"checksum":2413383904,"timestamp":"2024-06-01T17:51:34.476533Z"}]}
{"channel":"book","type":"update","data":[{"symbol":"BTC/USD","bids":[{"price":67571.2,"qty":0.03618919}],"asks":[],"checksum":4147962860,"timestamp":"2024-06-01T17:51:34.476578Z"}]}
{"channel":"book","type":"update","data":[{"symbol":"BTC/USD","bids":[{"price":67570.6,"qty":1.52719754}],"asks":[],"checksum":381340906,"timestamp":"2024-06-01T17:51:34.480785Z"}]}
{"channel":"book","type":"update","data":[{"symbol":"BTC/USD","bids":[{"price":67577.0,"qty":0.43154864}],"asks":[],"checksum":3551636624,"timestamp":"2024-06-01T17:51:34.481923Z"}]}
{"channel":"book","type":"update","data":[{"symbol":"BTC/USD","bids":[{"price":67570.5,"qty":0.38827528}],"asks":[],"checksum":4064921171,"timestamp":"2024-06-01T17:51:34.493109Z"}]}
{"channel":"book","type":"update","data":[{"symbol":"BTC/USD","bids":[],"asks":[{"price":67599.9,"qty":0.00000000},{"price":67616.3,"qty":0.00120000}],"checksum":322775702,"timestamp":"2024-06-01T17:51:34.498185Z"}]}
{"channel":"book","type":"update","data":[{"symbol":"BTC/USD","bids":[{"price":67555.0,"qty":6.76632704},{"price":67573.0,"qty":0.00010000}],"asks":[],"checksum":3931925556,"timestamp":"2024-06-01T17:51:34.502906Z"}]}
{"channel":"book","type":"update","data":[{"symbol":"BTC/USD","bids":[],"asks":[{"price":67603.0,"qty":0.00000000},{"price":67617.9,"qty":0.01437809},{"price":67609.0,"qty":0.00010000}],"checksum":2252067991,"timestamp":"2024-06-01T17:51:34.505067Z"}]}
{"channel":"book","type":"update","data":[{"symbol":"BTC/USD","bids":[{"price":67555.0,"qty":5.84598787}],"asks":[],"checksum":54573582,"timestamp":"2024-06-01T17:51:34.509846Z"}]}
{"channel":"book","type":"update","data":[{"symbol":"BTC/USD","bids":[{"price":67577.1,"qty":13.78133668}],"asks":[],"checksum":2236648322,"timestamp":"2024-06-01T17:51:34.510064Z"}]}
{"channel":"book","type":"update","data":[{"symbol":"BTC/USD","bids":[{"price":67555.0,"qty":5.83598787}],"asks":[],"checksum":1089975564,"timestamp":"2024-06-01T17:51:34.510104Z"}]}
{"channel":"book","type":"update","data":[{"symbol":"BTC/USD","bids":[{"price":67555.0,"qty":5.82598787}],"asks":[],"checksum":3867197112,"timestamp":"2024-06-01T17:51:34.511403Z"}]}
{"channel":"book","type":"update","data":[{"symbol":"BTC/USD","bids":[{"price":67555.0,"qty":5.81598787}],"asks":[],"checksum":3613959205,"timestamp":"2024-06-01T17:51:34.511416Z"}]}
{"channel":"book","type":"update","data":[{"symbol":"BTC/USD","bids":[],"asks":[{"price":67615.0,"qty":0.00100000}],"checksum":3611976593,"timestamp":"2024-06-01T17:51:34.523797Z"}]}
{"channel":"book","type":"update","data":[{"symbol":"BTC/USD","bids":[],"asks":[{"price":67616.2,"qty":0.00000000},{"price":67616.3,"qty":0.00120000}],"checksum":1415219122,"timestamp":"2024-06-01T17:51:34.528040Z"}]}
{"channel":"book","type":"update","data":[{"symbol":"BTC/USD","bids":[{"price":67577.1,"qty":14.00970530}],"asks":[],"checksum":2241996720,"timestamp":"2024-06-01T17:51:34.543831Z"}]}
{"channel":"book","type":"update","data":[{"symbol":"BTC/USD","bids":[{"price":67577.0,"qty":0.00000000},{"price":67549.6,"qty":0.48001934}],"asks":[],"checksum":3494879293,"timestamp":"2024-06-01T17:51:34.562618Z"}]}
{"channel":"book","type":"update","data":[{"symbol":"BTC/USD","bids":[],"asks":[{"price":67616.3,"qty":0.00220000}],"checksum":1950058038,"timestamp":"2024-06-01T17:51:34.576983Z"}]}
{"channel":"book","type":"update","data":[{"symbol":"BTC/USD","bids":[{"price":67571.2,"qty":0.00460867}],"asks":[],"checksum":3398753641,"timestamp":"2024-06-01T17:51:34.580143Z"}]}
{"channel":"book","type":"update","data":[{"symbol":"BTC/USD","bids":[{"price":67577.1,"qty":14.04128582}],"asks":[],"checksum":709291541,"timestamp":"2024-06-01T17:51:34.583676Z"}]}
{"channel":"book","type":"update","data":[{"symbol":"BTC/USD","bids":[{"price":67570.5,"qty":0.44314528}],"asks":[],"checksum":2696133511,"timestamp":"2024-06-01T17:51:34.608923Z"}]}
{"channel":"book","type":"update","data":[{"symbol":"BTC/USD","bids":[{"price":67555.0,"qty":5.46288787}],"asks":[],"checksum":437300756,"timestamp":"2024-06-01T17:51:34.616106Z"}]}
{"channel":"book","type":"update","data":[{"symbol":"BTC/USD","bids":[{"price":67555.0,"qty":4.70176368}],"asks":[],"checksum":3158259506,"timestamp":"2024-06-01T17:51:34.651483Z"}]}
{"channel":"book","type":"update","data":[{"symbol":"BTC/USD","bids":[],"asks":[{"price":67609.0,"qty":0.00000000},{"price":67617.9,"qty":0.00034730}],"checksum":620756060,"timestamp":"2024-06-01T17:51:34.663011Z"}]}
{"channel":"book","type":"update","data":[{"symbol":"BTC/USD","bids":[{"price":67577.0,"qty":0.43154864}],"asks":[],"checksum":2172983223,"timestamp":"2024-06-01T17:51:34.694461Z"}]}
{"channel":"book","type":"update","data":[{"symbol":"BTC/USD","bids":[],"asks":[{"price":67617.9,"qty":0.01506652}],"checksum":3115953762,"timestamp":"2024-06-01T17:51:34.697984Z"}]}
{"channel":"book","type":"update","data":[{"symbol":"BTC/USD","bids":[],"asks":[{"price":67617.9,"qty":0.01471922}],"checksum":304946070,"timestamp":"2024-06-01T17:51:34.721273Z"}]}
{"channel":"book","type":"update","data":[{"symbol":"BTC/USD","bids":[{"price":67570.6,"qty":1.96320650}],"asks":[],"checksum":1127912125,"timestamp":"2024-06-01T17:51:34.735667Z"}]}
{"channel":"book","type":"update","data":[{"symbol":"BTC/USD","bids":[],"asks":[{"price":67617.9,"qty":0.00000000},{"price":67618.0,"qty":0.29580000}],"checksum":1099882850,"timestamp":"2024-06-01T17:51:34.737746Z"}]}
{"channel":"book","type":"update","data":[{"symbol":"BTC/USD","bids":[{"price":67577.1,"qty":14.05128582}],"asks":[],"checksum":594165997,"timestamp":"2024-06-01T17:51:34.746637Z"}]}
{"channel":"book","type":"update","data":[{"symbol":"BTC/USD","bids":[{"price":67577.1,"qty":14.06128582}],"asks":[],"checksum":2219287164,"timestamp":"2024-06-01T17:51:34.753525Z"}]}
{"channel":"book","type":"update","data":[{"symbol":"BTC/USD","bids":[{"price":67577.0,"qty":0.00000000},{"price":67549.6,"qty":0.48001934}],"asks":[],"checksum":339323617,"timestamp":"2024-06-01T17:51:34.761493Z"}]}
{"channel":"book","type":"update","data":[{"symbol":"BTC/USD","bids":[],"asks":[{"price":67617.9,"qty":0.00034730}],"checksum":2233849119,"timestamp":"2024-06-01T17:51:34.789983Z"}]}
{"channel":"book","type":"update","data":[{"symbol":"BTC/USD","bids":[{"price":67554.6,"qty":0.00739895}],"asks":[],"checksum":2422339722,"timestamp":"2024-06-01T17:51:34.841379Z"}]}
{"channel":"book","type":"update","data":[{"symbol":"BTC/USD","bids":[{"price":67560.4,"qty":0.01542984}],"asks":[],"checksum":4186855762,"timestamp":"2024-06-01T17:51:34.848501Z"}]}
{"channel":"book","type":"update","data":[{"symbol":"BTC/USD","bids":[{"price":67555.0,"qty":4.66117188}],"asks":[],"checksum":4228843475,"timestamp":"2024-06-01T17:51:34.853057Z"}]}
{"channel":"book","type":"update","data":[{"symbol":"BTC/USD","bids":[{"price":67565.3,"qty":0.04059180}],"asks":[],"checksum":1745420114,"timestamp":"2024-06-01T17:51:34.870085Z"}]}
{"channel":"book","type":"update","data":[{"symbol":"BTC/USD","bids":[],"asks":[{"price":67617.9,"qty":0.00000000},{"price":67618.0,"qty":0.29580000}],"checksum":3384342606,"timestamp":"2024-06-01T17:51:34.872212Z"}]}
{"channel":"book","type":"update","data":[{"symbol":"BTC/USD","bids":[],"asks":[{"price":67617.9,"qty":0.01409020}],"checksum":15427768,"timestamp":"2024-06-01T17:51:34.875198Z"}]}
{"channel":"book","type":"update","data":[{"symbol":"BTC/USD","bids":[{"price":67577.0,"qty":0.43154864}],"asks":[],"checksum":4196237424,"timestamp":"2024-06-01T17:51:34.887207Z"}]}
{"channel":"book","type":"update","data":[{"symbol":"BTC/USD","bids":[],"asks":[{"price":67617.8,"qty":0.01443837}],"checksum":2238892468,"timestamp":"2024-06-01T17:51:34.917100Z"}]}
{"channel":"book","type":"update","data":[{"symbol":"BTC/USD","bids":[{"price":67577.0,"qty":0.00000000},{"price":67558.4,"qty":0.44350000}],"asks":[],"checksum":2139365756,"timestamp":"2024-06-01T17:51:34.923498Z"}]}
{"channel":"book","type":"update","data":[{"symbol":"BTC/USD","bids":[],"asks":[{"price":67617.7,"qty":0.01447986}],"checksum":1695356318,"timestamp":"2024-06-01T17:51:34.923747Z"}]}
{"channel":"book","type":"update","data":[{"symbol":"BTC/USD","bids":[{"price":67570.6,"qty":1.84079250}],"asks":[],"checksum":2823020140,"timestamp":"2024-06-01T17:51:34.953925Z"}]}
{"channel":"book","type":"update","data":[{"symbol":"BTC/USD","bids":[],"asks":[{"price":67617.7,"qty":0.01482716}],"checksum":220779340,"timestamp":"2024-06-01T17:51:34.992903Z"}]}
{"channel":"book","type":"update","data":[{"symbol":"BTC/USD","bids":[{"price":67577.1,"qty":13.99218582}],"asks":[],"checksum":325989311,"timestamp":"2024-06-01T17:51:35.054144Z"}]}
{"channel":"book","type":"update","data":[{"symbol":"BTC/USD","bids":[{"price":67577.1,"qty":13.92308582}],"asks":[],"checksum":2924889093,"timestamp":"2024-06-01T17:51:35.057020Z"}]}
{"channel":"book","type":"update","data":[{"symbol":"BTC/USD","bids":[{"price":67577.1,"qty":13.78488582}],"asks":[],"checksum":950863478,"timestamp":"2024-06-01T17:51:35.057065Z"}]}
{"channel":"book","type":"update","data":[{"symbol":"BTC/USD","bids":[{"price":67577.1,"qty":13.90729982}],"asks":[],"checksum":3019541741,"timestamp":"2024-06-01T17:51:35.058971Z"}]}
{"channel":"book","type":"update","data":[{"symbol":"BTC/USD","bids":[{"price":67577.0,"qty":0.43154864}],"asks":[],"checksum":3424672341,"timestamp":"2024-06-01T17:51:35.070877Z"}]}
{"channel":"book","type":"update","data":[{"symbol":"BTC/USD","bids":[{"price":67577.1,"qty":13.91729982}],"asks":[],"checksum":4292849510,"timestamp":"2024-06-01T17:51:35.079318Z"}]}
{"channel":"book","type":"update","data":[{"symbol":"BTC/USD","bids":[{"price":67565.3,"qty":0.00000000},{"price":67558.4,"qty":0.44350000}],"asks":[],"checksum":2449681326,"timestamp":"2024-06-01T17:51:35.107755Z"}]}
{"channel":"book","type":"update","data":[{"symbol":"BTC/USD","bids":[{"price":67577.1,"qty":13.98639982},{"price":67577.1,"qty":14.05549982},{"price":67577.1,"qty":14.19369982}],"asks":[],"checksum":111913158,"timestamp":"2024-06-01T17:51:35.126917Z"}]}
{"channel":"book","type":"update","data":[{"symbol":"BTC/USD","bids":[{"price":67577.0,"qty":0.00000000},{"price":67555.0,"qty":4.66017188}],"asks":[],"checksum":3879963840,"timestamp":"2024-06-01T17:51:35.136337Z"}]}
{"channel":"book","type":"update","data":[{"symbol":"BTC/USD","bids":[{"price":67558.8,"qty":0.04059180}],"asks":[],"checksum":1337914340,"timestamp":"2024-06-01T17:51:35.206107Z"}]}
{"channel":"book","type":"update","data":[{"symbol":"BTC/USD","bids":[{"price":67577.0,"qty":0.43154864}],"asks":[],"checksum":3536081965,"timestamp":"2024-06-01T17:51:35.258402Z"}]}
{"channel":"book","type":"update","data":[{"symbol":"BTC/USD","bids":[],"asks":[{"price":67617.1,"qty":0.06910000}],"checksum":3019181933,"timestamp":"2024-06-01T17:51:35.280646Z"}]}
{"channel":"book","type":"update","data":[{"symbol":"BTC/USD","bids":[],"asks":[{"price":67617.1,"qty":0.13820000}],"checksum":532422409,"timestamp":"2024-06-01T17:51:35.284568Z"}]}
{"channel":"book","type":"update","data":[{"symbol":"BTC/USD","bids":[],"asks":[{"price":67617.1,"qty":0.06910000}],"checksum":3019181933,"timestamp":"2024-06-01T17:51:35.388660Z"}]}
{"channel":"book","type":"update","data":[{"symbol":"BTC/USD","bids":[{"price":67577.1,"qty":15.67349105}],"asks":[],"checksum":3198790354,"timestamp":"2024-06-01T17:51:35.438089Z"}]}
{"channel":"book","type":"update","data":[{"symbol":"BTC/USD","bids":[{"price":67577.0,"qty":0.00000000},{"price":67558.4,"qty":0.44350000}],"asks":[],"checksum":601034011,"timestamp":"2024-06-01T17:51:35.458878Z"}]}
{"channel":"book","type":"update","data":[{"symbol":"BTC/USD","bids":[{"price":67577.0,"qty":0.43154864}],"asks":[],"checksum":3198790354,"timestamp":"2024-06-01T17:51:35.577858Z"}]}
{"channel":"book","type":"update","data":[{"symbol":"BTC/USD","bids":[{"price":67577.1,"qty":16.87349105}],"asks":[],"checksum":1032713249,"timestamp":"2024-06-01T17:51:35.591870Z"}]}
{"channel":"book","type":"update","data":[{"symbol":"BTC/USD","bids":[{"price":67577.1,"qty":16.84191053}],"asks":[],"checksum":61002707,"timestamp":"2024-06-01T17:51:35.750100Z"}]}
{"channel":"book","type":"update","data":[{"symbol":"BTC/USD","bids":[],"asks":[{"price":67617.1,"qty":0.00000000},{"price":67617.6,"qty":0.00034730}],"checksum":3694992300,"timestamp":"2024-06-01T17:51:35.768174Z"}]}
{"channel":"book","type":"update","data":[{"symbol":"BTC/USD","bids":[],"asks":[{"price":67617.6,"qty":0.00000000},{"price":67617.7,"qty":0.01447986},{"price":67617.7,"qty":0.01482716}],"checksum":1653835923,"timestamp":"2024-06-01T17:51:35.804568Z"}]}
{"channel":"book","type":"update","data":[{"symbol":"BTC/USD","bids":[{"price":67569.7,"qty":0.03158052}],"asks":[],"checksum":1982063698,"timestamp":"2024-06-01T17:51:35.853293Z"}]}
{"channel":"book","type":"update","data":[{"symbol":"BTC/USD","bids":[{"price":67577.0,"qty":0.00000000},{"price":67558.8,"qty":0.04059180}],"asks":[],"checksum":3044783120,"timestamp":"2024-06-01T17:51:35.855497Z"}]}
{"channel":"book","type":"update","data":[{"symbol":"BTC/USD","bids":[{"price":67577.1,"qty":17.32192987}],"asks":[],"checksum":920613024,"timestamp":"2024-06-01T17:51:35.856594Z"}]}
{"channel":"book","type":"update","data":[{"symbol":"BTC/USD","bids":[{"price":67558.8,"qty":0.00000000},{"price":67558.4,"qty":0.44350000}],"asks":[],"checksum":2504412287,"timestamp":"2024-06-01T17:51:35.899034Z"}]}
{"channel":"book","type":"update","data":[{"symbol":"BTC/USD","bids":[{"price":67577.0,"qty":0.43154864}],"asks":[],"checksum":3183604506,"timestamp":"2024-06-01T17:51:35.980171Z"}]}
{"channel":"book","type":"update","data":[{"symbol":"BTC/USD","bids":[{"price":67577.1,"qty":17.32292987}],"asks":[],"checksum":1669959660,"timestamp":"2024-06-01T17:51:36.019112Z"}]}
{"channel":"book","type":"update","data":[{"symbol":"BTC/USD","bids":[{"price":67577.1,"qty":18.43201341}],"asks":[],"checksum":2970633221,"timestamp":"2024-06-01T17:51:36.192706Z"}]}
{"channel":"book","type":"update","data":[{"symbol":"BTC/USD","bids":[{"price":67577.0,"qty":0.00000000},{"price":67558.4,"qty":0.44350000}],"asks":[],"checksum":2576874336,"timestamp":"2024-06-01T17:51:36.197283Z"}]}
{"channel":"book","type":"update","data":[{"symbol":"BTC/USD","bids":[{"price":67577.0,"qty":0.43154864}],"asks":[],"checksum":2970633221,"timestamp":"2024-06-01T17:51:36.316078Z"}]}
{"channel":"book","type":"update","data":[{"symbol":"BTC/USD","bids":[{"price":67570.7,"qty":1.47993139}],"asks":[],"checksum":3521440384,"timestamp":"2024-06-01T17:51:36.469589Z"}]}
{"channel":"book","type":"update","data":[{"symbol":"BTC/USD","bids":[{"price":67577.1,"qty":18.68201341}],"asks":[],"checksum":1216011739,"timestamp":"2024-06-01T17:51:36.616420Z"}]}
{"channel":"book","type":"update","data":[{"symbol":"BTC/USD","bids":[{"price":67577.0,"qty":0.00000000},{"price":67560.4,"qty":0.01542984}],"asks":[],"checksum":139570644,"timestamp":"2024-06-01T17:51:36.697267Z"}]}
{"channel":"book","type":"update","data":[{"symbol":"BTC/USD","bids":[{"price":67577.0,"qty":0.43154864}],"asks":[],"checksum":1216011739,"timestamp":"2024-06-01T17:51:36.818836Z"}]}
{"channel":"book","type":"update","data":[{"symbol":"BTC/USD","bids":[{"price":67577.0,"qty":0.00000000},{"price":67567.0,"qty":0.01542984}],"asks":[],"checksum":3900362471,"timestamp":"2024-06-01T17:51:38.182241Z"}]}
{"channel":"book","type":"update","data":[{"symbol":"BTC/USD","bids":[{"price":67577.1,"qty":18.20199407},{"price":67574.0,"qty":0.48001934}],"asks":[],"checksum":919814255,"timestamp":"2024-06-01T17:51:38.185401Z"}]}
{"channel":"book","type":"update","data":[{"symbol":"BTC/USD","bids":[{"price":67572.1,"qty":7.72036537}],"asks":[],"checksum":1190664744,"timestamp":"2024-06-01T17:51:38.188423Z"}]}
{"channel":"book","type":"update","data":[{"symbol":"BTC/USD","bids":[{"price":67577.0,"qty":0.43154864}],"asks":[],"checksum":1150802271,"timestamp":"2024-06-01T17:51:38.303109Z"}]}
{"channel":"book","type":"update","data":[{"symbol":"BTC/USD","bids":[{"price":67577.0,"qty":0.49068110}],"asks":[],"checksum":750600921,"timestamp":"2024-06-01T17:51:38.398498Z"}]}
{"channel":"book","type":"update","data":[{"symbol":"BTC/USD","bids":[{"price":67574.1,"qty":0.03669989}],"asks":[],"checksum":571594112,"timestamp":"2024-06-01T17:51:39.113682Z"}]}
{"channel":"book","type":"update","data":[{"symbol":"BTC/USD","bids":[{"price":67572.2,"qty":0.07759223}],"asks":[],"checksum":1655244025,"timestamp":"2024-06-01T17:51:39.113855Z"}]}
{"channel":"book","type":"update","data":[{"symbol":"BTC/USD","bids":[],"asks":[{"price":67577.2,"qty":0.00163832}],"checksum":2064358271,"timestamp":"2024-06-01T17:51:39.909250Z"}]}
{"channel":"book","type":"update","data":[{"symbol":"BTC/USD","bids":[{"price":67574.0,"qty":0.00000000},{"price":67570.7,"qty":1.47993139},{"price":67577.1,"qty":18.68201341}],"asks":[],"checksum":3779619064,"timestamp":"2024-06-01T17:51:39.912950Z"}]}
{"channel":"book","type":"update","data":[{"symbol":"BTC/USD","bids":[{"price":67577.1,"qty":18.55959941}],"asks":[],"checksum":931395726,"timestamp":"2024-06-01T17:51:40.049804Z"}]}
{"channel":"book","type":"update","data":[{"symbol":"BTC/USD","bids":[],"asks":[{"price":67617.3,"qty":0.06910000}],"checksum":2273496065,"timestamp":"2024-06-01T17:51:40.064673Z"}]}
{"channel":"book","type":"update","data":[{"symbol":"BTC/USD","bids":[],"asks":[{"price":67617.3,"qty":0.13820000}],"checksum":1938911721,"timestamp":"2024-06-01T17:51:40.073714Z"}]}
{"channel":"book","type":"update","data":[{"symbol":"BTC/USD","bids":[],"asks":[{"price":67617.3,"qty":0.06910000}],"checksum":2273496065,"timestamp":"2024-06-01T17:51:40.073851Z"}]}
{"channel":"book","type":"update","data":[{"symbol":"BTC/USD","bids":[],"asks":[{"price":67617.3,"qty":0.00000000},{"price":67617.7,"qty":0.01482716}],"checksum":931395726,"timestamp":"2024-06-01T17:51:40.073961Z"}]}
{"channel":"book","type":"update","data":[{"symbol":"BTC/USD","bids":[],"asks":[{"price":67617.2,"qty":0.29580000}],"checksum":1440010330,"timestamp":"2024-06-01T17:51:40.075210Z"}]}
{"channel":"book","type":"update","data":[{"symbol":"BTC/USD","bids":[{"price":67577.1,"qty":18.30959941}],"asks":[],"checksum":3986939454,"timestamp":"2024-06-01T17:51:40.079687Z"}]}
{"channel":"book","type":"update","data":[{"symbol":"BTC/USD","bids":[],"asks":[{"price":67616.5,"qty":0.06910000}],"checksum":2051217198,"timestamp":"2024-06-01T17:51:40.080385Z"}]}
{"channel":"book","type":"update","data":[{"symbol":"BTC/USD","bids":[],"asks":[{"price":67616.5,"qty":0.13820000}],"checksum":716001600,"timestamp":"2024-06-01T17:51:40.083311Z"}]}
{"channel":"book","type":"update","data":[{"symbol":"BTC/USD","bids":[{"price":67577.1,"qty":18.24049941}],"asks":[],"checksum":177601748,"timestamp":"2024-06-01T17:51:40.083495Z"}]}
{"channel":"book","type":"update","data":[{"symbol":"BTC/USD","bids":[{"price":67577.1,"qty":18.17139941}],"asks":[],"checksum":4092753319,"timestamp":"2024-06-01T17:51:40.083723Z"}]}
{"channel":"book","type":"update","data":[{"symbol":"BTC/USD","bids":[{"price":67577.1,"qty":18.03319941}],"asks":[],"checksum":487330889,"timestamp":"2024-06-01T17:51:40.083731Z"}]}
{"channel":"book","type":"update","data":[{"symbol":"BTC/USD","bids":[],"asks":[{"price":67616.5,"qty":0.06910000}],"checksum":1306677799,"timestamp":"2024-06-01T17:51:40.083790Z"}]}
{"channel":"book","type":"update","data":[{"symbol":"BTC/USD","bids":[],"asks":[{"price":67616.5,"qty":0.00000000},{"price":67617.2,"qty":0.29580000},{"price":67615.6,"qty":0.06910000}],"checksum":1363525536,"timestamp":"2024-06-01T17:51:40.083936Z"}]}
{"channel":"book","type":"update","data":[{"symbol":"BTC/USD","bids":[{"price":67577.0,"qty":0.05913246}],"asks":[],"checksum":3149145802,"timestamp":"2024-06-01T17:51:40.101505Z"}]}
{"channel":"book","type":"update","data":[{"symbol":"BTC/USD","bids":[],"asks":[{"price":67615.6,"qty":0.00000000},{"price":67617.1,"qty":0.25409234},{"price":67613.7,"qty":0.06910000}],"checksum":196599943,"timestamp":"2024-06-01T17:51:40.110385Z"}]}
{"channel":"book","type":"update","data":[{"symbol":"BTC/USD","bids":[],"asks":[{"price":67615.3,"qty":1.47895702}],"checksum":3545509506,"timestamp":"2024-06-01T17:51:40.110449Z"}]}
{"channel":"book","type":"update","data":[{"symbol":"BTC/USD","bids":[],"asks":[{"price":67613.7,"qty":0.00000000},{"price":67616.3,"qty":0.00220000}],"checksum":4042129161,"timestamp":"2024-06-01T17:51:40.113325Z"}]}
{"channel":"book","type":"update","data":[{"symbol":"BTC/USD","bids":[],"asks":[{"price":67613.7,"qty":0.06910000}],"checksum":3545509506,"timestamp":"2024-06-01T17:51:40.113591Z"}]}
{"channel":"book","type":"update","data":[{"symbol":"BTC/USD","bids":[{"price":67577.1,"qty":17.99372443}],"asks":[],"checksum":773735588,"timestamp":"2024-06-01T17:51:40.115251Z"}]}
{"channel":"book","type":"update","data":[{"symbol":"BTC/USD","bids":[],"asks":[{"price":67613.5,"qty":0.01435566}],"checksum":206269123,"timestamp":"2024-06-01T17:51:40.115929Z"}]}
{"channel":"book","type":"update","data":[{"symbol":"BTC/USD","bids":[],"asks":[{"price":67613.7,"qty":0.00000000},{"price":67615.2,"qty":0.24000000}],"checksum":1483856054,"timestamp":"2024-06-01T17:51:40.118570Z"}]}
{"channel":"book","type":"update","data":[{"symbol":"BTC/USD","bids":[],"asks":[{"price":67612.0,"qty":0.06910000}],"checksum":1056762948,"timestamp":"2024-06-01T17:51:40.120613Z"}]}
{"channel":"book","type":"update","data":[{"symbol":"BTC/USD","bids":[],"asks":[{"price":67612.2,"qty":0.01448629}],"checksum":4066189062,"timestamp":"2024-06-01T17:51:40.125129Z"}]}
{"channel":"book","type":"update","data":[{"symbol":"BTC/USD","bids":[],"asks":[{"price":67613.4,"qty":0.01406452}],"checksum":550320177,"timestamp":"2024-06-01T17:51:40.130580Z"}]}
{"channel":"book","type":"update","data":[{"symbol":"BTC/USD","bids":[],"asks":[{"price":67611.9,"qty":0.01423340}],"checksum":4168877854,"timestamp":"2024-06-01T17:51:40.135536Z"}]}
{"channel":"book","type":"update","data":[{"symbol":"BTC/USD","bids":[],"asks":[{"price":67612.0,"qty":0.00000000},{"price":67613.5,"qty":0.01435566},{"price":67610.9,"qty":0.06910000}],"checksum":4025853653,"timestamp":"2024-06-01T17:51:40.140965Z"}]}
{"channel":"book","type":"update","data":[{"symbol":"BTC/USD","bids":[{"price":67572.9,"qty":0.03158052}],"asks":[],"checksum":3314475567,"timestamp":"2024-06-01T17:51:40.142243Z"}]}
{"channel":"book","type":"update","data":[{"symbol":"BTC/USD","bids":[],"asks":[{"price":67610.9,"qty":0.13820000}],"checksum":3740897946,"timestamp":"2024-06-01T17:51:40.143958Z"}]}
{"channel":"book","type":"update","data":[{"symbol":"BTC/USD","bids":[],"asks":[{"price":67612.2,"qty":0.00000000},{"price":67613.5,"qty":0.01435566}],"checksum":1462327082,"timestamp":"2024-06-01T17:51:40.144360Z"}]}
{"channel":"book","type":"update","data":[{"symbol":"BTC/USD","bids":[],"asks":[{"price":67611.8,"qty":0.01463165}],"checksum":2110733929,"timestamp":"2024-06-01T17:51:40.144501Z"}]}
{"channel":"book","type":"update","data":[{"symbol":"BTC/USD","bids":[{"price":67571.2,"qty":0.00000000},{"price":67570.7,"qty":1.47993139}],"asks":[],"checksum":1346515992,"timestamp":"2024-06-01T17:51:40.146092Z"}]}
{"channel":"book","type":"update","data":[{"symbol":"BTC/USD","bids":[{"price":67570.7,"qty":0.00000000},{"price":67570.6,"qty":1.84079250}],"asks":[],"checksum":59113026,"timestamp":"2024-06-01T17:51:40.148333Z"}]}
{"channel":"book","type":"update","data":[{"symbol":"BTC/USD","bids":[{"price":67577.1,"qty":18.11612643}],"asks":[],"checksum":4242990683,"timestamp":"2024-06-01T17:51:40.148538Z"}]}
{"channel":"book","type":"update","data":[{"symbol":"BTC/USD","bids":[],"asks":[{"price":67610.9,"qty":0.06910000}],"checksum":3727509458,"timestamp":"2024-06-01T17:51:40.149351Z"}]}
{"channel":"book","type":"update","data":[{"symbol":"BTC/USD","bids":[],"asks":[{"price":67611.2,"qty":0.33750000}],"checksum":2856203630,"timestamp":"2024-06-01T17:51:40.150064Z"}]}
{"channel":"book","type":"update","data":[{"symbol":"BTC/USD","bids":[],"asks":[{"price":67611.8,"qty":0.00000000},{"price":67613.4,"qty":0.01406452}],"checksum":3380454347,"timestamp":"2024-06-01T17:51:40.151198Z"}]}
{"channel":"book","type":"update","data":[{"symbol":"BTC/USD","bids":[],"asks":[{"price":67610.8,"qty":0.01460832}],"checksum":3682295104,"timestamp":"2024-06-01T17:51:40.151308Z"}]}
{"channel":"book","type":"update","data":[{"symbol":"BTC/USD","bids":[],"asks":[{"price":67610.5,"qty":0.03947498}],"checksum":3073640582,"timestamp":"2024-06-01T17:51:40.153251Z"}]}
{"channel":"book","type":"update","data":[{"symbol":"BTC/USD","bids":[{"price":67577.1,"qty":17.99372443}],"asks":[],"checksum":1213665439,"timestamp":"2024-06-01T17:51:40.153883Z"}]}
{"channel":"book","type":"update","data":[{"symbol":"BTC/USD","bids":[],"asks":[{"price":67610.9,"qty":0.00000000},{"price":67612.3,"qty":0.02961607},{"price":67609.8,"qty":0.06910000}],"checksum":717747121,"timestamp":"2024-06-01T17:51:40.155866Z"}]}
{"channel":"book","type":"update","data":[{"symbol":"BTC/USD","bids":[],"asks":[{"price":67611.9,"qty":0.00000000},{"price":67612.3,"qty":0.02961607}],"checksum":1400556524,"timestamp":"2024-06-01T17:51:40.157985Z"}]}
{"channel":"book","type":"update","data":[{"symbol":"BTC/USD","bids":[],"asks":[{"price":67611.1,"qty":0.01406735}],"checksum":1417159783,"timestamp":"2024-06-01T17:51:40.158188Z"}]}
{"channel":"book","type":"update","data":[{"symbol":"BTC/USD","bids":[],"asks":[{"price":67609.8,"qty":0.13820000}],"checksum":1941100533,"timestamp":"2024-06-01T17:51:40.158771Z"}]}
{"channel":"book","type":"update","data":[{"symbol":"BTC/USD","bids":[],"asks":[{"price":67609.8,"qty":0.06910000}],"checksum":1417159783,"timestamp":"2024-06-01T17:51:40.158913Z"}]}
{"channel":"book","type":"update","data":[{"symbol":"BTC/USD","bids":[],"asks":[{"price":67610.7,"qty":0.01432553}],"checksum":3717140695,"timestamp":"2024-06-01T17:51:40.163955Z"}]}
{"channel":"book","type":"update","data":[{"symbol":"BTC/USD","bids":[],"asks":[{"price":67609.7,"qty":0.01466261}],"checksum":1673866314,"timestamp":"2024-06-01T17:51:40.171473Z"}]}
{"channel":"book","type":"update","data":[{"symbol":"BTC/USD","bids":[],"asks":[{"price":67610.7,"qty":0.00000000},{"price":67611.1,"qty":0.01406735}],"checksum":2718802439,"timestamp":"2024-06-01T17:51:40.182835Z"}]}
{"channel":"book","type":"update","data":[{"symbol":"BTC/USD","bids":[],"asks":[{"price":67609.6,"qty":0.01475175}],"checksum":3021056665,"timestamp":"2024-06-01T17:51:40.182967Z"}]}
{"channel":"book","type":"update","data":[{"symbol":"BTC/USD","bids":[],"asks":[{"price":67608.2,"qty":0.06694000}],"checksum":3552357787,"timestamp":"2024-06-01T17:51:40.188065Z"}]}
{"channel":"book","type":"update","data":[{"symbol":"BTC/USD","bids":[{"price":67577.0,"qty":0.49068110}],"asks":[],"checksum":2988230052,"timestamp":"2024-06-01T17:51:40.224643Z"}]}
{"channel":"book","type":"update","data":[{"symbol":"BTC/USD","bids":[],"asks":[{"price":67609.8,"qty":0.00000000},{"price":67610.8,"qty":0.01460832}],"checksum":4034120611,"timestamp":"2024-06-01T17:51:40.226617Z"}]}
{"channel":"book","type":"update","data":[{"symbol":"BTC/USD","bids":[],"asks":[{"price":67599.1,"qty":0.06339000}],"checksum":4128258848,"timestamp":"2024-06-01T17:51:40.236712Z"}]}
{"channel":"book","type":"update","data":[{"symbol":"BTC/USD","bids":[{"price":67570.6,"qty":0.73170896}],"asks":[],"checksum":1713029602,"timestamp":"2024-06-01T17:51:40.243062Z"}]}
{"channel":"book","type":"update","data":[{"symbol":"BTC/USD","bids":[{"price":67577.1,"qty":16.88464089}],"asks":[],"checksum":2774277661,"timestamp":"2024-06-01T17:51:40.243290Z"}]}
{"channel":"book","type":"update","data":[{"symbol":"BTC/USD","bids":[{"price":67572.9,"qty":0.00000000},{"price":67570.5,"qty":0.38827528}],"asks":[],"checksum":1780398738,"timestamp":"2024-06-01T17:51:40.244410Z"}]}
{"channel":"book","type":"update","data":[{"symbol":"BTC/USD","bids":[{"price":67577.0,"qty":0.05913246}],"asks":[],"checksum":2850467304,"timestamp":"2024-06-01T17:51:40.254339Z"}]}
{"channel":"book","type":"update","data":[{"symbol":"BTC/USD","bids":[{"price":67577.1,"qty":15.40484966}],"asks":[],"checksum":1218628168,"timestamp":"2024-06-01T17:51:40.254518Z"}]}
{"channel":"book","type":"update","data":[{"symbol":"BTC/USD","bids":[{"price":67577.0,"qty":1.53892561}],"asks":[],"checksum":14669489,"timestamp":"2024-06-01T17:51:40.258325Z"}]}
{"channel":"book","type":"update","data":[{"symbol":"BTC/USD","bids":[],"asks":[{"price":67596.5,"qty":0.00120000}],"checksum":1455665867,"timestamp":"2024-06-01T17:51:40.264241Z"}]}
{"channel":"book","type":"update","data":[{"symbol":"BTC/USD","bids":[],"asks":[{"price":67609.6,"qty":0.00000000},{"price":67610.3,"qty":0.06910000}],"checksum":2079933649,"timestamp":"2024-06-01T17:51:40.302769Z"}]}
{"channel":"book","type":"update","data":[{"symbol":"BTC/USD","bids":[],"asks":[{"price":67609.7,"qty":0.00000000},{"price":67610.5,"qty":0.03947498}],"checksum":1356560135,"timestamp":"2024-06-01T17:51:40.308778Z"}]}
{"channel":"book","type":"update","data":[{"symbol":"BTC/USD","bids":[{"price":67577.1,"qty":15.39484966}],"asks":[],"checksum":984856131,"timestamp":"2024-06-01T17:51:40.311543Z"}]}
{"channel":"book","type":"update","data":[{"symbol":"BTC/USD","bids":[{"price":67577.1,"qty":15.51725166}],"asks":[],"checksum":3877559419,"timestamp":"2024-06-01T17:51:40.325066Z"}]}
{"channel":"book","type":"update","data":[{"symbol":"BTC/USD","bids":[{"price":67577.1,"qty":15.50725166}],"asks":[],"checksum":2247785972,"timestamp":"2024-06-01T17:51:40.327944Z"}]}
{"channel":"book","type":"update","data":[{"symbol":"BTC/USD","bids":[{"price":67577.1,"qty":15.49725166}],"asks":[],"checksum":1002219153,"timestamp":"2024-06-01T17:51:40.336296Z"}]}
{"channel":"book","type":"update","data":[{"symbol":"BTC/USD","bids":[],"asks":[{"price":67599.1,"qty":0.00000000},{"price":67610.8,"qty":0.01495735}],"checksum":861363854,"timestamp":"2024-06-01T17:51:40.342998Z"}]}
{"channel":"book","type":"update","data":[{"symbol":"BTC/USD","bids":[],"asks":[{"price":67610.8,"qty":0.01460832},{"price":67610.2,"qty":0.00034903}],"checksum":1079118768,"timestamp":"2024-06-01T17:51:40.343042Z"}]}
{"channel":"book","type":"update","data":[{"symbol":"BTC/USD","bids":[],"asks":[{"price":67610.2,"qty":0.01484597}],"checksum":2951703119,"timestamp":"2024-06-01T17:51:40.353310Z"}]}
{"channel":"book","type":"update","data":[{"symbol":"BTC/USD","bids":[],"asks":[{"price":67610.1,"qty":0.01467164}],"checksum":91569709,"timestamp":"2024-06-01T17:51:40.358761Z"}]}
{"channel":"book","type":"update","data":[{"symbol":"BTC/USD","bids":[{"price":67577.0,"qty":1.97047425}],"asks":[],"checksum":2045850252,"timestamp":"2024-06-01T17:51:40.380394Z"}]}
{"channel":"book","type":"update","data":[{"symbol":"BTC/USD","bids":[],"asks":[{"price":67577.2,"qty":0.00016642}],"checksum":3394471983,"timestamp":"2024-06-01T17:51:40.395522Z"}]}
{"channel":"book","type":"update","data":[{"symbol":"BTC/USD","bids":[],"asks":[{"price":67610.2,"qty":0.00034903}],"checksum":1232515371,"timestamp":"2024-06-01T17:51:40.407721Z"}]}
{"channel":"book","type":"update","data":[{"symbol":"BTC/USD","bids":[],"asks":[{"price":67610.1,"qty":0.00000000},{"price":67610.5,"qty":0.03947498}],"checksum":2635155432,"timestamp":"2024-06-01T17:51:40.407910Z"}]}
{"channel":"book","type":"update","data":[{"symbol":"BTC/USD","bids":[],"asks":[{"price":67610.2,"qty":0.00000000},{"price":67611.1,"qty":0.24000000},{"price":67610.0,"qty":0.00034903}],"checksum":2807359729,"timestamp":"2024-06-01T17:51:40.415157Z"}]}
{"channel":"book","type":"update","data":[{"symbol":"BTC/USD","bids":[],"asks":[{"price":67610.0,"qty":0.00000000},{"price":67611.0,"qty":0.24000000},{"price":67610.2,"qty":0.00034903}],"checksum":2635155432,"timestamp":"2024-06-01T17:51:40.487513Z"}]}
{"channel":"book","type":"update","data":[{"symbol":"BTC/USD","bids":[],"asks":[{"price":67610.2,"qty":0.01465646}],"checksum":3998559000,"timestamp":"2024-06-01T17:51:40.489837Z"}]}
{"channel":"book","type":"update","data":[{"symbol":"BTC/USD","bids":[],"asks":[{"price":67610.2,"qty":0.01430743},{"price":67610.1,"qty":0.00034903}],"checksum":1103417026,"timestamp":"2024-06-01T17:51:40.545699Z"}]}
{"channel":"book","type":"update","data":[{"symbol":"BTC/USD","bids":[],"asks":[{"price":67610.1,"qty":0.00000000},{"price":67610.5,"qty":0.03947498}],"checksum":2344146079,"timestamp":"2024-06-01T17:51:40.602457Z"}]}
{"channel":"book","type":"update","data":[{"symbol":"BTC/USD","bids":[],"asks":[{"price":67610.3,"qty":0.00000000},{"price":67610.8,"qty":0.00034903}],"checksum":135704505,"timestamp":"2024-06-01T17:51:40.617200Z"}]}
{"channel":"book","type":"update","data":[{"symbol":"BTC/USD","bids":[],"asks":[{"price":67608.2,"qty":0.00000000},{"price":67610.9,"qty":0.01465917}],"checksum":1514410280,"timestamp":"2024-06-01T17:51:40.639042Z"}]}
{"channel":"book","type":"update","data":[{"symbol":"BTC/USD","bids":[],"asks":[{"price":67610.8,"qty":0.00000000},{"price":67611.0,"qty":0.24000000},{"price":67610.9,"qty":0.01500820}],"checksum":1074398317,"timestamp":"2024-06-01T17:51:40.671658Z"}]}
{"channel":"book","type":"update","data":[{"symbol":"BTC/USD","bids":[],"asks":[{"price":67610.4,"qty":0.01449916}],"checksum":1551305260,"timestamp":"2024-06-01T17:51:40.710475Z"}]}
{"channel":"book","type":"update","data":[{"symbol":"BTC/USD","bids":[],"asks":[{"price":67610.3,"qty":0.01427309}],"checksum":567362792,"timestamp":"2024-06-01T17:51:40.720529Z"}]}
{"channel":"book","type":"update","data":[{"symbol":"BTC/USD","bids":[],"asks":[{"price":67610.4,"qty":0.00000000},{"price":67610.8,"qty":0.00034903}],"checksum":1956260705,"timestamp":"2024-06-01T17:51:41.226981Z"}]}
{"channel":"book","type":"update","data":[{"symbol":"BTC/USD","bids":[],"asks":[{"price":67610.2,"qty":0.00000000},{"price":67610.9,"qty":0.01465917}],"checksum":3086681635,"timestamp":"2024-06-01T17:51:41.227030Z"}]}
{"channel":"book","type":"update","data":[{"symbol":"BTC/USD","bids":[],"asks":[{"price":67610.3,"qty":0.00000000},{"price":67611.0,"qty":0.24000000}],"checksum":2433244897,"timestamp":"2024-06-01T17:51:41.227073Z"}]}
{"channel":"book","type":"update","data":[{"symbol":"BTC/USD","bids":[],"asks":[{"price":67610.9,"qty":0.00000000},{"price":67611.2,"qty":0.33750000}],"checksum":2896902678,"timestamp":"2024-06-01T17:51:41.234496Z"}]}
{"channel":"book","type":"update","data":[{"symbol":"BTC/USD","bids":[],"asks":[{"price":67610.8,"qty":0.00000000},{"price":67612.3,"qty":0.02961607},{"price":67612.2,"qty":0.00034903}],"checksum":304808269,"timestamp":"2024-06-01T17:51:41.299182Z"}]}
{"channel":"book","type":"update","data":[{"symbol":"BTC/USD","bids":[],"asks":[{"price":67612.2,"qty":0.00000000},{"price":67612.3,"qty":0.02961607}],"checksum":874672197,"timestamp":"2024-06-01T17:51:41.375753Z"}]}
{"channel":"book","type":"update","data":[{"symbol":"BTC/USD","bids":[],"asks":[{"price":67612.2,"qty":1.47902347}],"checksum":1494103139,"timestamp":"2024-06-01T17:51:41.409635Z"}]}
{"channel":"book","type":"update","data":[{"symbol":"BTC/USD","bids":[{"price":67577.1,"qty":15.01723232},{"price":67573.1,"qty":0.48001934}],"asks":[],"checksum":3412659404,"timestamp":"2024-06-01T17:51:41.412990Z"}]}
{"channel":"book","type":"update","data":[{"symbol":"BTC/USD","bids":[{"price":67571.0,"qty":0.01542984}],"asks":[],"checksum":3977691955,"timestamp":"2024-06-01T17:51:41.420096Z"}]}
{"channel":"book","type":"update","data":[{"symbol":"BTC/USD","bids":[],"asks":[{"price":67612.2,"qty":1.47937250}],"checksum":4194072936,"timestamp":"2024-06-01T17:51:41.521018Z"}]}
{"channel":"book","type":"update","data":[{"symbol":"BTC/USD","bids":[{"price":67577.1,"qty":15.26723232}],"asks":[],"checksum":2415954914,"timestamp":"2024-06-01T17:51:41.616040Z"}]}
{"channel":"book","type":"update","data":[{"symbol":"BTC/USD","bids":[{"price":67572.1,"qty":0.00000000},{"price":67570.6,"qty":0.73170896}],"asks":[],"checksum":2121312218,"timestamp":"2024-06-01T17:51:41.678569Z"}]}
{"channel":"book","type":"update","data":[{"symbol":"BTC/USD","bids":[],"asks":[{"price":67612.2,"qty":0.00034903}],"checksum":3221955570,"timestamp":"2024-06-01T17:51:41.901844Z"}]}
{"channel":"book","type":"update","data":[{"symbol":"BTC/USD","bids":[],"asks":[{"price":67611.9,"qty":1.47903082}],"checksum":947522588,"timestamp":"2024-06-01T17:51:41.905736Z"}]}
{"channel":"book","type":"update","data":[{"symbol":"BTC/USD","bids":[{"price":67572.2,"qty":0.00000000},{"price":67570.5,"qty":0.38827528}],"asks":[],"checksum":1362313153,"timestamp":"2024-06-01T17:51:41.931484Z"}]}
{"channel":"book","type":"update","data":[{"symbol":"BTC/USD","bids":[{"price":67574.1,"qty":0.00000000},{"price":67569.8,"qty":0.03947498}],"asks":[],"checksum":1112185282,"timestamp":"2024-06-01T17:51:41.931505Z"}]}
{"channel":"book","type":"update","data":[{"symbol":"BTC/USD","bids":[{"price":67577.1,"qty":15.27416802}],"asks":[],"checksum":2476209995,"timestamp":"2024-06-01T17:51:41.938021Z"}]}
{"channel":"book","type":"update","data":[{"symbol":"BTC/USD","bids":[{"price":67572.2,"qty":0.04518167}],"asks":[],"checksum":659361529,"timestamp":"2024-06-01T17:51:41.938069Z"}]}
{"channel":"book","type":"update","data":[{"symbol":"BTC/USD","bids":[],"asks":[{"price":67610.5,"qty":1.51853524}],"checksum":418068478,"timestamp":"2024-06-01T17:51:42.002626Z"}]}
{"channel":"book","type":"update","data":[{"symbol":"BTC/USD","bids":[],"asks":[{"price":67611.0,"qty":0.00000000},{"price":67612.3,"qty":0.02961607},{"price":67610.4,"qty":0.24000000}],"checksum":2477439094,"timestamp":"2024-06-01T17:51:42.005776Z"}]}
{"channel":"book","type":"update","data":[{"symbol":"BTC/USD","bids":[],"asks":[{"price":67610.5,"qty":0.03947498}],"checksum":3604399111,"timestamp":"2024-06-01T17:51:42.009756Z"}]}
{"channel":"book","type":"update","data":[{"symbol":"BTC/USD","bids":[],"asks":[{"price":67611.3,"qty":1.47904415}],"checksum":2514509017,"timestamp":"2024-06-01T17:51:42.140280Z"}]}
{"channel":"book","type":"update","data":[{"symbol":"BTC/USD","bids":[],"asks":[{"price":67610.3,"qty":0.01466604}],"checksum":1212565721,"timestamp":"2024-06-01T17:51:42.165866Z"}]}
{"channel":"book","type":"update","data":[{"symbol":"BTC/USD","bids":[],"asks":[{"price":67610.2,"qty":0.01416301}],"checksum":782974937,"timestamp":"2024-06-01T17:51:42.174853Z"}]}
{"channel":"book","type":"update","data":[{"symbol":"BTC/USD","bids":[],"asks":[{"price":67610.1,"qty":0.01449340}],"checksum":2636128998,"timestamp":"2024-06-01T17:51:42.184813Z"}]}
{"channel":"book","type":"update","data":[{"symbol":"BTC/USD","bids":[],"asks":[{"price":67610.0,"qty":0.01440182}],"checksum":3443779749,"timestamp":"2024-06-01T17:51:42.194422Z"}]}
{"channel":"book","type":"update","data":[{"symbol":"BTC/USD","bids":[],"asks":[{"price":67610.3,"qty":0.01501507}],"checksum":3718889269,"timestamp":"2024-06-01T17:51:42.308270Z"}]}
{"channel":"book","type":"update","data":[{"symbol":"BTC/USD","bids":[{"price":67572.0,"qty":0.00000000},{"price":67569.8,"qty":0.03947498}],"asks":[],"checksum":22863275,"timestamp":"2024-06-01T17:51:42.620090Z"}]}
{"channel":"book","type":"update","data":[{"symbol":"BTC/USD","bids":[{"price":67574.8,"qty":1.11500000}],"asks":[],"checksum":3688989939,"timestamp":"2024-06-01T17:51:42.621108Z"}]}
{"channel":"book","type":"update","data":[{"symbol":"BTC/USD","bids":[{"price":67577.1,"qty":12.64816802}],"asks":[],"checksum":98238923,"timestamp":"2024-06-01T17:51:42.629736Z"}]}
{"channel":"book","type":"update","data":[{"symbol":"BTC/USD","bids":[{"price":67577.1,"qty":14.55616802}],"asks":[],"checksum":2256799536,"timestamp":"2024-06-01T17:51:42.633005Z"}]}
{"channel":"book","type":"update","data":[{"symbol":"BTC/USD","bids":[],"asks":[{"price":67610.0,"qty":1.49347372}],"checksum":4020097316,"timestamp":"2024-06-01T17:51:43.260794Z"}]}
{"channel":"book","type":"update","data":[{"symbol":"BTC/USD","bids":[],"asks":[{"price":67609.9,"qty":0.24000000}],"checksum":688131832,"timestamp":"2024-06-01T17:51:43.264247Z"}]}
{"channel":"book","type":"update","data":[{"symbol":"BTC/USD","bids":[],"asks":[{"price":67610.2,"qty":0.00000000},{"price":67610.3,"qty":0.00034903}],"checksum":3137389033,"timestamp":"2024-06-01T17:51:43.267468Z"}]}
{"channel":"book","type":"update","data":[{"symbol":"BTC/USD","bids":[],"asks":[{"price":67610.1,"qty":0.00000000},{"price":67610.5,"qty":0.03947498}],"checksum":3338943001,"timestamp":"2024-06-01T17:51:43.267597Z"}]}
{"channel":"book","type":"update","data":[{"symbol":"BTC/USD","bids":[],"asks":[{"price":67609.9,"qty":0.25425473}],"checksum":2176246533,"timestamp":"2024-06-01T17:51:43.267704Z"}]}
{"channel":"book","type":"update","data":[{"symbol":"BTC/USD","bids":[],"asks":[{"price":67610.0,"qty":1.47907190}],"checksum":4134387346,"timestamp":"2024-06-01T17:51:43.267715Z"}]}
{"channel":"book","type":"update","data":[{"symbol":"BTC/USD","bids":[],"asks":[{"price":67610.0,"qty":0.00000000},{"price":67611.2,"qty":0.33750000}],"checksum":1060597497,"timestamp":"2024-06-01T17:51:43.279638Z"}]}
{"channel":"book","type":"update","data":[{"symbol":"BTC/USD","bids":[],"asks":[{"price":67609.9,"qty":0.24000000}],"checksum":3830451030,"timestamp":"2024-06-01T17:51:43.285315Z"}]}
{"channel":"book","type":"update","data":[{"symbol":"BTC/USD","bids":[],"asks":[{"price":67610.3,"qty":0.00000000},{"price":67611.9,"qty":1.47903082},{"price":67611.8,"qty":0.00034902}],"checksum":2869040254,"timestamp":"2024-06-01T17:51:43.327382Z"}]}
{"channel":"book","type":"update","data":[{"symbol":"BTC/USD","bids":[],"asks":[{"price":67610.3,"qty":1.47906495}],"checksum":816360053,"timestamp":"2024-06-01T17:51:43.360357Z"}]}
{"channel":"book","type":"update","data":[{"symbol":"BTC/USD","bids":[],"asks":[{"price":67610.3,"qty":0.00000000},{"price":67611.8,"qty":0.00034902}],"checksum":2869040254,"timestamp":"2024-06-01T17:51:43.380805Z"}]}
{"channel":"book","type":"update","data":[{"symbol":"BTC/USD","bids":[],"asks":[{"price":67611.8,"qty":0.00000000},{"price":67611.9,"qty":1.47903082}],"checksum":1377002721,"timestamp":"2024-06-01T17:51:43.384575Z"}]}
{"channel":"book","type":"update","data":[{"symbol":"BTC/USD","bids":[],"asks":[{"price":67611.7,"qty":0.00034902}],"checksum":1451172167,"timestamp":"2024-06-01T17:51:43.440641Z"}]}
{"channel":"book","type":"update","data":[{"symbol":"BTC/USD","bids":[],"asks":[{"price":67610.7,"qty":1.47905745}],"checksum":65266065,"timestamp":"2024-06-01T17:51:43.440807Z"}]}
{"channel":"book","type":"update","data":[{"symbol":"BTC/USD","bids":[],"asks":[{"price":67610.7,"qty":0.00000000},{"price":67611.7,"qty":0.00034902}],"checksum":1451172167,"timestamp":"2024-06-01T17:51:43.479755Z"}]}
{"channel":"book","type":"update","data":[{"symbol":"BTC/USD","bids":[],"asks":[{"price":67611.7,"qty":0.00000000},{"price":67611.9,"qty":1.47903082}],"checksum":1377002721,"timestamp":"2024-06-01T17:51:43.485507Z"}]}
{"channel":"book","type":"update","data":[{"symbol":"BTC/USD","bids":[],"asks":[{"price":67610.6,"qty":1.47905878}],"checksum":3676043070,"timestamp":"2024-06-01T17:51:43.598003Z"}]}
{"channel":"book","type":"update","data":[{"symbol":"BTC/USD","bids":[],"asks":[{"price":67610.6,"qty":0.00000000},{"price":67611.8,"qty":0.00034902}],"checksum":2869040254,"timestamp":"2024-06-01T17:51:43.679399Z"}]}
{"channel":"book","type":"update","data":[{"symbol":"BTC/USD","bids":[],"asks":[{"price":67610.4,"qty":1.47906426}],"checksum":1342874398,"timestamp":"2024-06-01T17:51:43.683164Z"}]}
{"channel":"book","type":"update","data":[{"symbol":"BTC/USD","bids":[],"asks":[{"price":67611.2,"qty":0.00000000},{"price":67611.8,"qty":0.00034902}],"checksum":869514933,"timestamp":"2024-06-01T17:51:43.683705Z"}]}
{"channel":"book","type":"update","data":[{"symbol":"BTC/USD","bids":[],"asks":[{"price":67610.4,"qty":0.00000000},{"price":67612.3,"qty":0.02961607}],"checksum":3962217852,"timestamp":"2024-06-01T17:51:43.694582Z"}]}
{"channel":"book","type":"update","data":[{"symbol":"BTC/USD","bids":[],"asks":[{"price":67609.9,"qty":0.00000000},{"price":67613.6,"qty":0.11091373}],"checksum":3962527208,"timestamp":"2024-06-01T17:51:43.699299Z"}]}
{"channel":"book","type":"update","data":[{"symbol":"BTC/USD","bids":[{"price":67573.1,"qty":0.00000000},{"price":67569.8,"qty":0.03947498},{"price":67574.9,"qty":0.48001934}],"asks":[],"checksum":1087980307,"timestamp":"2024-06-01T17:51:43.717671Z"}]}
{"channel":"book","type":"update","data":[{"symbol":"BTC/USD","bids":[{"price":67577.1,"qty":14.59564300}],"asks":[],"checksum":3996976248,"timestamp":"2024-06-01T17:51:43.726084Z"}]}
{"channel":"book","type":"update","data":[{"symbol":"BTC/USD","bids":[{"price":67577.0,"qty":1.53892561}],"asks":[],"checksum":3068007094,"timestamp":"2024-06-01T17:51:43.736437Z"}]}
{"channel":"book","type":"update","data":[{"symbol":"BTC/USD","bids":[{"price":67577.1,"qty":14.60564300}],"asks":[],"checksum":1054614746,"timestamp":"2024-06-01T17:51:43.746858Z"}]}
{"channel":"book","type":"update","data":[{"symbol":"BTC/USD","bids":[{"price":67577.1,"qty":14.61564300}],"asks":[],"checksum":123761798,"timestamp":"2024-06-01T17:51:43.747462Z"}]}
{"channel":"book","type":"update","data":[{"symbol":"BTC/USD","bids":[],"asks":[{"price":67596.5,"qty":0.00000000},{"price":67615.0,"qty":0.00100000}],"checksum":873381793,"timestamp":"2024-06-01T17:51:43.749809Z"}]}
{"channel":"book","type":"update","data":[{"symbol":"BTC/USD","bids":[{"price":67577.1,"qty":14.62564300}],"asks":[],"checksum":2127187781,"timestamp":"2024-06-01T17:51:43.753749Z"}]}
{"channel":"book","type":"update","data":[{"symbol":"BTC/USD","bids":[],"asks":[{"price":67611.8,"qty":0.00000000},{"price":67616.0,"qty":0.00010000},{"price":67612.2,"qty":0.00034902}],"checksum":4035681798,"timestamp":"2024-06-01T17:51:43.756038Z"}]}
{"channel":"book","type":"update","data":[{"symbol":"BTC/USD","bids":[{"price":67572.0,"qty":0.07064000}],"asks":[],"checksum":2728305907,"timestamp":"2024-06-01T17:51:43.757140Z"}]}
{"channel":"book","type":"update","data":[{"symbol":"BTC/USD","bids":[],"asks":[{"price":67613.5,"qty":0.00120000}],"checksum":2820148650,"timestamp":"2024-06-01T17:51:43.764925Z"}]}
{"channel":"book","type":"update","data":[{"symbol":"BTC/USD","bids":[{"price":67577.1,"qty":14.63025167}],"asks":[],"checksum":1961494988,"timestamp":"2024-06-01T17:51:43.815991Z"}]}
{"channel":"book","type":"update","data":[{"symbol":"BTC/USD","bids":[{"price":67577.0,"qty":1.97047425}],"asks":[],"checksum":4289779441,"timestamp":"2024-06-01T17:51:43.857793Z"}]}
{"channel":"book","type":"update","data":[{"symbol":"BTC/USD","bids":[],"asks":[{"price":67612.2,"qty":0.00000000},{"price":67615.0,"qty":0.00100000},{"price":67614.9,"qty":0.00034902}],"checksum":1518421949,"timestamp":"2024-06-01T17:51:43.859722Z"}]}
{"channel":"book","type":"update","data":[{"symbol":"BTC/USD","bids":[],"asks":[{"price":67614.9,"qty":0.00000000},{"price":67615.0,"qty":0.00100000}],"checksum":2307812056,"timestamp":"2024-06-01T17:51:43.951827Z"}]}
{"channel":"book","type":"update","data":[{"symbol":"BTC/USD","bids":[{"price":67577.0,"qty":1.53892561}],"asks":[],"checksum":47494629,"timestamp":"2024-06-01T17:51:44.022837Z"}]}
{"channel":"book","type":"update","data":[{"symbol":"BTC/USD","bids":[{"price":67577.0,"qty":1.97047425}],"asks":[],"checksum":2307812056,"timestamp":"2024-06-01T17:51:44.149334Z"}]}
{"channel":"book","type":"update","data":[{"symbol":"BTC/USD","bids":[{"price":67577.0,"qty":1.53892561}],"asks":[],"checksum":47494629,"timestamp":"2024-06-01T17:51:44.209439Z"}]}
{"channel":"book","type":"update","data":[{"symbol":"BTC/USD","bids":[{"price":67577.0,"qty":1.97047425}],"asks":[],"checksum":2307812056,"timestamp":"2024-06-01T17:51:44.327656Z"}]}
{"channel":"book","type":"update","data":[{"symbol":"BTC/USD","bids":[],"asks":[{"price":67577.2,"qty":0.00027664}],"checksum":2902402371,"timestamp":"2024-06-01T17:51:44.538087Z"}]}
{"channel":"book","type":"update","data":[{"symbol":"BTC/USD","bids":[{"price":67577.1,"qty":14.50784967}],"asks":[],"checksum":1145091832,"timestamp":"2024-06-01T17:51:44.738317Z"}]}
{"channel":"book","type":"update","data":[{"symbol":"BTC/USD","bids":[{"price":67577.0,"qty":1.53892561}],"asks":[],"checksum":3474614725,"timestamp":"2024-06-01T17:51:44.762442Z"}]}
{"channel":"book","type":"update","data":[{"symbol":"BTC/USD","bids":[{"price":67577.1,"qty":14.63024667}],"asks":[],"checksum":1081065520,"timestamp":"2024-06-01T17:51:44.856512Z"}]}
{"channel":"book","type":"update","data":[{"symbol":"BTC/USD","bids":[{"price":67577.0,"qty":1.97047425}],"asks":[],"checksum":3409256205,"timestamp":"2024-06-01T17:51:44.882514Z"}]}
{"channel":"book","type":"update","data":[{"symbol":"BTC/USD","bids":[{"price":67577.1,"qty":26.20050726}],"asks":[],"checksum":1302650493,"timestamp":"2024-06-01T17:51:45.220141Z"}]}
{"channel":"book","type":"update","data":[{"symbol":"BTC/USD","bids":[{"price":67574.9,"qty":0.00000000},{"price":67570.5,"qty":0.38827528},{"price":67577.1,"qty":26.68052660}],"asks":[],"checksum":2918331662,"timestamp":"2024-06-01T17:51:45.223511Z"}]}
{"channel":"book","type":"update","data":[{"symbol":"BTC/USD","bids":[{"price":67577.1,"qty":26.55812960}],"asks":[],"checksum":3648324461,"timestamp":"2024-06-01T17:51:45.835203Z"}]}
{"channel":"book","type":"update","data":[{"symbol":"BTC/USD","bids":[{"price":67577.0,"qty":1.53892561}],"asks":[],"checksum":1378868304,"timestamp":"2024-06-01T17:51:45.858430Z"}]}
{"channel":"book","type":"update","data":[{"symbol":"BTC/USD","bids":[{"price":67577.1,"qty":26.68052760}],"asks":[],"checksum":2797177602,"timestamp":"2024-06-01T17:51:45.933816Z"}]}
{"channel":"book","type":"update","data":[{"symbol":"BTC/USD","bids":[{"price":67577.0,"qty":1.97047425}],"asks":[],"checksum":769872959,"timestamp":"2024-06-01T17:51:45.999093Z"}]}
{"channel":"book","type":"update","data":[{"symbol":"BTC/USD","bids":[{"price":67577.0,"qty":1.53892561}],"asks":[],"checksum":2797177602,"timestamp":"2024-06-01T17:51:46.005988Z"}]}
{"channel":"book","type":"update","data":[{"symbol":"BTC/USD","bids":[{"price":67577.0,"qty":1.97047425}],"asks":[],"checksum":769872959,"timestamp":"2024-06-01T17:51:46.128917Z"}]}
{"channel":"book","type":"update","data":[{"symbol":"BTC/USD","bids":[],"asks":[{"price":67577.2,"qty":0.00011022},{"price":67577.2,"qty":0.00000000},{"price":67616.2,"qty":0.00034904},{"price":67581.5,"qty":0.00000000},{"price":67616.3,"qty":0.00100000},{"price":67594.4,"qty":0.00000000},{"price":67618.6,"qty":0.06910000},{"price":67601.3,"qty":0.00000000},{"price":67619.0,"qty":0.01421912},{"price":67602.6,"qty":0.00000000},{"price":67619.1,"qty":0.01416878},{"price":67610.5,"qty":0.00000000},{"price":67619.2,"qty":0.01452399},{"price":67612.3,"qty":0.00000000},{"price":67619.3,"qty":0.01443433},{"price":67613.5,"qty":0.00000000},{"price":67619.4,"qty":0.24000000},{"price":67613.6,"qty":0.00000000},{"price":67619.5,"qty":0.29580000},{"price":67615.0,"qty":0.00000000},{"price":67620.2,"qty":0.33750000},{"price":67616.2,"qty":0.00000000},{"price":67621.3,"qty":0.00010000},{"price":67616.3,"qty":0.00000000},{"price":67622.4,"qty":0.00126365},{"price":67618.6,"qty":0.00000000},{"price":67627.1,"qty":1.47869734},{"price":67619.0,"qty":0.00000000},{"price":67627.7,"qty":0.05977000},{"price":67619.1,"qty":0.00000000},{"price":67630.2,"qty":0.22190000},{"price":67619.2,"qty":0.00000000},{"price":67630.3,"qty":0.33750000},{"price":67619.3,"qty":0.00000000},{"price":67630.9,"qty":1.44286861},{"price":67619.4,"qty":0.00000000},{"price":67631.7,"qty":0.92002822},{"price":67619.5,"qty":0.12611268},{"price":67619.5,"qty":0.00000000},{"price":67631.8,"qty":0.69011052},{"price":67620.2,"qty":0.16492191}],"checksum":3780858139,"timestamp":"2024-06-01T17:51:46.142840Z"}]}
{"channel":"book","type":"update","data":[{"symbol":"BTC/USD","bids":[{"price":67577.1,"qty":26.25052760}],"asks":[],"checksum":3575585560,"timestamp":"2024-06-01T17:51:46.146997Z"}]}
{"channel":"book","type":"update","data":[{"symbol":"BTC/USD","bids":[],"asks":[{"price":67618.9,"qty":0.43000000}],"checksum":3306467894,"timestamp":"2024-06-01T17:51:46.147157Z"}]}
{"channel":"book","type":"update","data":[{"symbol":"BTC/USD","bids":[{"price":67578.4,"qty":0.43000000}],"asks":[],"checksum":1302021216,"timestamp":"2024-06-01T17:51:46.147425Z"}]}
{"channel":"book","type":"update","data":[{"symbol":"BTC/USD","bids":[{"price":67580.4,"qty":0.33750000}],"asks":[],"checksum":324969353,"timestamp":"2024-06-01T17:51:46.148038Z"}]}
{"channel":"book","type":"update","data":[{"symbol":"BTC/USD","bids":[],"asks":[{"price":67630.9,"qty":0.71203176}],"checksum":2412984401,"timestamp":"2024-06-01T17:51:46.148475Z"}]}
{"channel":"book","type":"update","data":[{"symbol":"BTC/USD","bids":[{"price":67583.8,"qty":0.33750000}],"asks":[],"checksum":3325382008,"timestamp":"2024-06-01T17:51:46.148699Z"}]}
{"channel":"book","type":"update","data":[{"symbol":"BTC/USD","bids":[],"asks":[{"price":67630.9,"qty":0.00000000},{"price":67631.8,"qty":0.69011052}],"checksum":3130603162,"timestamp":"2024-06-01T17:51:46.148828Z"}]}
{"channel":"book","type":"update","data":[{"symbol":"BTC/USD","bids":[],"asks":[{"price":67620.2,"qty":0.00000000},{"price":67632.9,"qty":1.47857181}],"checksum":3437649784,"timestamp":"2024-06-01T17:51:46.149017Z"}]}
{"channel":"book","type":"update","data":[{"symbol":"BTC/USD","bids":[{"price":67573.9,"qty":0.00000000},{"price":67571.0,"qty":0.01542984}],"asks":[],"checksum":2143471130,"timestamp":"2024-06-01T17:51:46.149157Z"}]}
{"channel":"book","type":"update","data":[{"symbol":"BTC/USD","bids":[{"price":67577.2,"qty":0.00295808}],"asks":[],"checksum":2575211255,"timestamp":"2024-06-01T17:51:46.149371Z"}]}
{"channel":"book","type":"update","data":[{"symbol":"BTC/USD","bids":[{"price":67577.1,"qty":24.77073637}],"asks":[],"checksum":598271773,"timestamp":"2024-06-01T17:51:46.150151Z"}]}
{"channel":"book","type":"update","data":[{"symbol":"BTC/USD","bids":[{"price":67577.1,"qty":23.29094514}],"asks":[],"checksum":2427785519,"timestamp":"2024-06-01T17:51:46.150217Z"}]}
{"channel":"book","type":"update","data":[{"symbol":"BTC/USD","bids":[{"price":67577.0,"qty":0.49068110}],"asks":[],"checksum":2063413392,"timestamp":"2024-06-01T17:51:46.150288Z"}]}
{"channel":"book","type":"update","data":[{"symbol":"BTC/USD","bids":[{"price":67577.1,"qty":21.81115391}],"asks":[],"checksum":2172888556,"timestamp":"2024-06-01T17:51:46.150314Z"}]}
{"channel":"book","type":"update","data":[{"symbol":"BTC/USD","bids":[{"price":67577.1,"qty":20.33136268}],"asks":[],"checksum":4263818543,"timestamp":"2024-06-01T17:51:46.150413Z"}]}
{"channel":"book","type":"update","data":[{"symbol":"BTC/USD","bids":[{"price":67618.8,"qty":1.33071452}],"asks":[],"checksum":4231825639,"timestamp":"2024-06-01T17:51:46.150487Z"}]}
{"channel":"book","type":"update","data":[{"symbol":"BTC/USD","bids":[{"price":67612.2,"qty":0.06910000}],"asks":[],"checksum":2198699681,"timestamp":"2024-06-01T17:51:46.150547Z"}]}
{"channel":"book","type":"update","data":[{"symbol":"BTC/USD","bids":[{"price":67577.1,"qty":19.00060987}],"asks":[],"checksum":4193538234,"timestamp":"2024-06-01T17:51:46.150801Z"}]}
{"channel":"book","type":"update","data":[{"symbol":"BTC/USD","bids":[{"price":67578.4,"qty":0.00000000},{"price":67572.2,"qty":0.04518167}],"asks":[],"checksum":1572331754,"timestamp":"2024-06-01T17:51:46.150876Z"}]}
{"channel":"book","type":"update","data":[{"symbol":"BTC/USD","bids":[],"asks":[{"price":67630.3,"qty":0.00000000},{"price":67634.5,"qty":0.05912874}],"checksum":2263058792,"timestamp":"2024-06-01T17:51:46.151239Z"}]}
{"channel":"book","type":"update","data":[{"symbol":"BTC/USD","bids":[{"price":67577.1,"qty":18.97101405},{"price":67577.2,"qty":0.03255386}],"asks":[],"checksum":2370322736,"timestamp":"2024-06-01T17:51:46.151281Z"}]}
{"channel":"book","type":"update","data":[{"symbol":"BTC/USD","bids":[{"price":67581.7,"qty":0.43000000}],"asks":[],"checksum":3360267644,"timestamp":"2024-06-01T17:51:46.151329Z"}]}
{"channel":"book","type":"update","data":[{"symbol":"BTC/USD","bids":[{"price":67578.5,"qty":0.00295808}],"asks":[],"checksum":3129520530,"timestamp":"2024-06-01T17:51:46.151876Z"}]}
{"channel":"book","type":"update","data":[{"symbol":"BTC/USD","bids":[{"price":67581.7,"qty":0.00000000},{"price":67573.0,"qty":0.00010000}],"asks":[],"checksum":2705000459,"timestamp":"2024-06-01T17:51:46.152092Z"}]}
{"channel":"book","type":"update","data":[{"symbol":"BTC/USD","bids":[{"price":67577.1,"qty":18.38977637}],"asks":[],"checksum":26084724,"timestamp":"2024-06-01T17:51:46.152133Z"}]}
{"channel":"book","type":"update","data":[{"symbol":"BTC/USD","bids":[{"price":67578.5,"qty":0.58418372}],"asks":[],"checksum":3042385602,"timestamp":"2024-06-01T17:51:46.152241Z"}]}
{"channel":"book","type":"update","data":[{"symbol":"BTC/USD","bids":[{"price":67585.1,"qty":0.43000000}],"asks":[],"checksum":239423726,"timestamp":"2024-06-01T17:51:46.152483Z"}]}
{"channel":"book","type":"update","data":[{"symbol":"BTC/USD","bids":[{"price":67580.5,"qty":0.00295808}],"asks":[],"checksum":2476977752,"timestamp":"2024-06-01T17:51:46.152558Z"}]}
{"channel":"book","type":"update","data":[{"symbol":"BTC/USD","bids":[{"price":67583.8,"qty":0.67500000}],"asks":[],"checksum":3311010682,"timestamp":"2024-06-01T17:51:46.152615Z"}]}
{"channel":"book","type":"update","data":[{"symbol":"BTC/USD","bids":[{"price":67577.1,"qty":18.16140775}],"asks":[],"checksum":477604448,"timestamp":"2024-06-01T17:51:46.152853Z"}]}
{"channel":"book","type":"update","data":[{"symbol":"BTC/USD","bids":[{"price":67577.2,"qty":0.02959578}],"asks":[],"checksum":1500302339,"timestamp":"2024-06-01T17:51:46.152964Z"}]}
{"channel":"book","type":"update","data":[{"symbol":"BTC/USD","bids":[{"price":67577.1,"qty":17.82390775}],"asks":[],"checksum":1847310147,"timestamp":"2024-06-01T17:51:46.152971Z"}]}
{"channel":"book","type":"update","data":[{"symbol":"BTC/USD","bids":[],"asks":[{"price":67620.1,"qty":0.02957700}],"checksum":959014771,"timestamp":"2024-06-01T17:51:46.153357Z"}]}
{"channel":"book","type":"update","data":[{"symbol":"BTC/USD","bids":[{"price":67577.1,"qty":17.70150975}],"asks":[],"checksum":1783947315,"timestamp":"2024-06-01T17:51:46.153637Z"}]}
{"channel":"book","type":"update","data":[{"symbol":"BTC/USD","bids":[{"price":67612.2,"qty":0.00000000},{"price":67574.8,"qty":1.11500000},{"price":67581.0,"qty":0.06910000}],"asks":[],"checksum":3016729529,"timestamp":"2024-06-01T17:51:46.153744Z"}]}
{"channel":"book","type":"update","data":[{"symbol":"BTC/USD","bids":[{"price":67580.4,"qty":0.00000000},{"price":67574.8,"qty":1.11500000}],"asks":[],"checksum":760950844,"timestamp":"2024-06-01T17:51:46.153795Z"}]}
{"channel":"book","type":"update","data":[{"symbol":"BTC/USD","bids":[{"price":67598.8,"qty":0.17739500}],"asks":[],"checksum":300325984,"timestamp":"2024-06-01T17:51:46.154010Z"}]}
{"channel":"book","type":"update","data":[{"symbol":"BTC/USD","bids":[],"asks":[{"price":67630.2,"qty":0.00000000},{"price":67634.5,"qty":0.05912874},{"price":67631.6,"qty":0.22190000}],"checksum":120781005,"timestamp":"2024-06-01T17:51:46.154974Z"}]}
{"channel":"book","type":"update","data":[{"symbol":"BTC/USD","bids":[{"price":67618.8,"qty":1.66821452}],"asks":[],"checksum":1574512163,"timestamp":"2024-06-01T17:51:46.155063Z"}]}
{"channel":"book","type":"update","data":[{"symbol":"BTC/USD","bids":[{"price":67578.5,"qty":0.58122564}],"asks":[],"checksum":1876569488,"timestamp":"2024-06-01T17:51:46.155408Z"}]}
{"channel":"book","type":"update","data":[{"symbol":"BTC/USD","bids":[{"price":67580.5,"qty":0.00000000},{"price":67574.8,"qty":1.11500000}],"asks":[],"checksum":3636073722,"timestamp":"2024-06-01T17:51:46.155625Z"}]}
{"channel":"book","type":"update","data":[{"symbol":"BTC/USD","bids":[{"price":67577.2,"qty":0.00000000},{"price":67573.0,"qty":0.00010000},{"price":67618.8,"qty":1.69779209}],"asks":[],"checksum":1632333253,"timestamp":"2024-06-01T17:51:46.156214Z"}]}
{"channel":"book","type":"update","data":[{"symbol":"BTC/USD","bids":[],"asks":[{"price":67621.2,"qty":1.47882750}],"checksum":4130075008,"timestamp":"2024-06-01T17:51:46.156232Z"}]}
{"channel":"book","type":"update","data":[{"symbol":"BTC/USD","bids":[{"price":67614.4,"qty":1.47897368}],"asks":[],"checksum":761818742,"timestamp":"2024-06-01T17:51:46.156318Z"}]}
{"channel":"book","type":"update","data":[{"symbol":"BTC/USD","bids":[{"price":67584.1,"qty":1.47963684}],"asks":[],"checksum":4168420372,"timestamp":"2024-06-01T17:51:46.156368Z"}]}
{"channel":"book","type":"update","data":[{"symbol":"BTC/USD","bids":[{"price":67584.1,"qty":2.95927368}],"asks":[],"checksum":2242041376,"timestamp":"2024-06-01T17:51:46.156403Z"}]}
{"channel":"book","type":"update","data":[{"symbol":"BTC/USD","bids":[{"price":67584.1,"qty":4.43891052}],"asks":[],"checksum":2748219471,"timestamp":"2024-06-01T17:51:46.156493Z"}]}
{"channel":"book","type":"update","data":[{"symbol":"BTC/USD","bids":[{"price":67584.1,"qty":5.91854736}],"asks":[],"checksum":92177246,"timestamp":"2024-06-01T17:51:46.156650Z"}]}
{"channel":"book","type":"update","data":[{"symbol":"BTC/USD","bids":[{"price":67618.8,"qty":2.03529209}],"asks":[],"checksum":575614796,"timestamp":"2024-06-01T17:51:46.156945Z"}]}
{"channel":"book","type":"update","data":[{"symbol":"BTC/USD","bids":[{"price":67583.9,"qty":0.01409170}],"asks":[],"checksum":3955693049,"timestamp":"2024-06-01T17:51:46.157061Z"}]}
{"channel":"book","type":"update","data":[{"symbol":"BTC/USD","bids":[],"asks":[{"price":67620.1,"qty":0.00000000},{"price":67632.9,"qty":1.47857181}],"checksum":3083338982,"timestamp":"2024-06-01T17:51:46.157986Z"}]}
{"channel":"book","type":"update","data":[{"symbol":"BTC/USD","bids":[],"asks":[{"price":67632.5,"qty":0.33750000}],"checksum":3285741911,"timestamp":"2024-06-01T17:51:46.158427Z"}]}
{"channel":"book","type":"update","data":[{"symbol":"BTC/USD","bids":[],"asks":[{"price":67618.9,"qty":0.00000000},{"price":67632.9,"qty":1.47857181}],"checksum":839504725,"timestamp":"2024-06-01T17:51:46.159373Z"}]}
{"channel":"book","type":"update","data":[{"symbol":"BTC/USD","bids":[{"price":67618.8,"qty":1.69779209}],"asks":[],"checksum":31746852,"timestamp":"2024-06-01T17:51:46.159981Z"}]}
{"channel":"book","type":"update","data":[{"symbol":"BTC/USD","bids":[{"price":67578.5,"qty":0.00000000},{"price":67577.0,"qty":0.49068110}],"asks":[],"checksum":1954239643,"timestamp":"2024-06-01T17:51:46.160200Z"}]}
{"channel":"book","type":"update","data":[{"symbol":"BTC/USD","bids":[{"price":67618.8,"qty":1.66821452},{"price":67583.6,"qty":0.02957757}],"asks":[],"checksum":1829834083,"timestamp":"2024-06-01T17:51:46.160970Z"}]}
{"channel":"book","type":"update","data":[{"symbol":"BTC/USD","bids":[{"price":67581.8,"qty":0.01444740}],"asks":[],"checksum":1754545173,"timestamp":"2024-06-01T17:51:46.160985Z"}]}
{"channel":"book","type":"update","data":[{"symbol":"BTC/USD","bids":[{"price":67584.1,"qty":4.43891052}],"asks":[],"checksum":4263169156,"timestamp":"2024-06-01T17:51:46.161861Z"}]}
{"channel":"book","type":"update","data":[{"symbol":"BTC/USD","bids":[{"price":67584.1,"qty":2.95927368}],"asks":[],"checksum":1473344576,"timestamp":"2024-06-01T17:51:46.161877Z"}]}
{"channel":"book","type":"update","data":[{"symbol":"BTC/USD","bids":[{"price":67584.1,"qty":1.47963684}],"asks":[],"checksum":2211633577,"timestamp":"2024-06-01T17:51:46.161934Z"}]}
{"channel":"book","type":"update","data":[{"symbol":"BTC/USD","bids":[],"asks":[{"price":67632.5,"qty":0.00000000},{"price":67634.5,"qty":0.05912874}],"checksum":3060324598,"timestamp":"2024-06-01T17:51:46.163239Z"}]}
{"channel":"book","type":"update","data":[{"symbol":"BTC/USD","bids":[{"price":67620.4,"qty":0.33750000}],"asks":[],"checksum":2247117552,"timestamp":"2024-06-01T17:51:46.163430Z"}]}
{"channel":"book","type":"update","data":[{"symbol":"BTC/USD","bids":[{"price":67583.8,"qty":0.33750000}],"asks":[],"checksum":3842792018,"timestamp":"2024-06-01T17:51:46.163643Z"}]}
{"channel":"book","type":"update","data":[{"symbol":"BTC/USD","bids":[{"price":67618.8,"qty":1.96821452}],"asks":[],"checksum":3372368139,"timestamp":"2024-06-01T17:51:46.164882Z"}]}
{"channel":"book","type":"update","data":[{"symbol":"BTC/USD","bids":[{"price":67598.9,"qty":0.00028778}],"asks":[],"checksum":4100463677,"timestamp":"2024-06-01T17:51:46.164910Z"}]}
{"channel":"book","type":"update","data":[{"symbol":"BTC/USD","bids":[{"price":67583.6,"qty":0.00000000},{"price":67581.8,"qty":0.01444740},{"price":67618.9,"qty":0.02957752}],"asks":[],"checksum":2778349105,"timestamp":"2024-06-01T17:51:46.165076Z"}]}
{"channel":"book","type":"update","data":[{"symbol":"BTC/USD","bids":[{"price":67612.0,"qty":0.33750000}],"asks":[],"checksum":3134862585,"timestamp":"2024-06-01T17:51:46.165218Z"}]}
{"channel":"book","type":"update","data":[{"symbol":"BTC/USD","bids":[{"price":67618.8,"qty":2.13514499}],"asks":[],"checksum":3732795803,"timestamp":"2024-06-01T17:51:46.166980Z"}]}
{"channel":"book","type":"update","data":[{"symbol":"BTC/USD","bids":[{"price":67618.8,"qty":2.43514499}],"asks":[],"checksum":3761779394,"timestamp":"2024-06-01T17:51:46.167202Z"}]}
{"channel":"book","type":"update","data":[{"symbol":"BTC/USD","bids":[{"price":67618.8,"qty":2.13514499}],"asks":[],"checksum":3732795803,"timestamp":"2024-06-01T17:51:46.169518Z"}]}
{"channel":"book","type":"update","data":[{"symbol":"BTC/USD","bids":[{"price":67618.8,"qty":1.83514499}],"asks":[],"checksum":261967952,"timestamp":"2024-06-01T17:51:46.171252Z"}]}
{"channel":"book","type":"update","data":[{"symbol":"BTC/USD","bids":[{"price":67618.8,"qty":1.66821452}],"asks":[],"checksum":4162089234,"timestamp":"2024-06-01T17:51:46.172755Z"}]}
{"channel":"book","type":"update","data":[{"symbol":"BTC/USD","bids":[{"price":67618.8,"qty":1.85797380}],"asks":[],"checksum":464495145,"timestamp":"2024-06-01T17:51:46.173081Z"}]}
{"channel":"book","type":"update","data":[{"symbol":"BTC/USD","bids":[{"price":67616.3,"qty":0.12239800}],"asks":[],"checksum":999321725,"timestamp":"2024-06-01T17:51:46.173911Z"}]}
{"channel":"book","type":"update","data":[{"symbol":"BTC/USD","bids":[{"price":67585.2,"qty":0.24000000}],"asks":[],"checksum":2448812027,"timestamp":"2024-06-01T17:51:46.174669Z"}]}
{"channel":"book","type":"update","data":[{"symbol":"BTC/USD","bids":[{"price":67618.8,"qty":1.66821452}],"asks":[],"checksum":1917727936,"timestamp":"2024-06-01T17:51:46.178760Z"}]}
{"channel":"book","type":"update","data":[{"symbol":"BTC/USD","bids":[{"price":67621.1,"qty":0.30000000}],"asks":[],"checksum":1336626212,"timestamp":"2024-06-01T17:51:46.182167Z"}]}
{"channel":"book","type":"update","data":[{"symbol":"BTC/USD","bids":[{"price":67621.1,"qty":0.46693000}],"asks":[],"checksum":4075514839,"timestamp":"2024-06-01T17:51:46.184003Z"}]}
{"channel":"book","type":"update","data":[{"symbol":"BTC/USD","bids":[{"price":67618.8,"qty":1.33071452}],"asks":[],"checksum":2693651795,"timestamp":"2024-06-01T17:51:46.186285Z"}]}
{"channel":"book","type":"update","data":[{"symbol":"BTC/USD","bids":[{"price":67621.1,"qty":0.80443000}],"asks":[],"checksum":3880224760,"timestamp":"2024-06-01T17:51:46.186489Z"}]}
{"channel":"book","type":"update","data":[{"symbol":"BTC/USD","bids":[{"price":67620.4,"qty":0.00000000},{"price":67585.1,"qty":0.43000000}],"asks":[],"checksum":1145534800,"timestamp":"2024-06-01T17:51:46.187592Z"}]}
{"channel":"book","type":"update","data":[{"symbol":"BTC/USD","bids":[{"price":67621.1,"qty":1.10443000}],"asks":[],"checksum":3790663619,"timestamp":"2024-06-01T17:51:46.190181Z"}]}
{"channel":"book","type":"update","data":[{"symbol":"BTC/USD","bids":[{"price":67621.1,"qty":1.29418000}],"asks":[],"checksum":2550964134,"timestamp":"2024-06-01T17:51:46.191313Z"}]}
{"channel":"book","type":"update","data":[{"symbol":"BTC/USD","bids":[{"price":67621.1,"qty":1.29815000}],"asks":[],"checksum":3504395345,"timestamp":"2024-06-01T17:51:46.210890Z"}]}
{"channel":"book","type":"update","data":[{"symbol":"BTC/USD","bids":[{"price":67621.1,"qty":1.31627000}],"asks":[],"checksum":4092757200,"timestamp":"2024-06-01T17:51:46.211324Z"}]}
{"channel":"book","type":"update","data":[{"symbol":"BTC/USD","bids":[{"price":67621.1,"qty":1.65377000}],"asks":[],"checksum":35876412,"timestamp":"2024-06-01T17:51:46.228410Z"}]}
{"channel":"book","type":"update","data":[{"symbol":"BTC/USD","bids":[{"price":67621.1,"qty":1.63565000}],"asks":[],"checksum":3667671058,"timestamp":"2024-06-01T17:51:46.242295Z"}]}
{"channel":"book","type":"update","data":[{"symbol":"BTC/USD","bids":[{"price":67621.1,"qty":1.63168000}],"asks":[],"checksum":2229532484,"timestamp":"2024-06-01T17:51:46.243995Z"}]}
{"channel":"book","type":"update","data":[{"symbol":"BTC/USD","bids":[],"asks":[{"price":67630.5,"qty":0.00460867}],"checksum":4234222564,"timestamp":"2024-06-01T17:51:46.249798Z"}]}
{"channel":"book","type":"update","data":[{"symbol":"BTC/USD","bids":[{"price":67612.2,"qty":0.06910000}],"asks":[],"checksum":2483893966,"timestamp":"2024-06-01T17:51:46.252510Z"}]}
{"channel":"book","type":"update","data":[{"symbol":"BTC/USD","bids":[{"price":67621.1,"qty":1.64980000}],"asks":[],"checksum":2709477530,"timestamp":"2024-06-01T17:51:46.255193Z"}]}
{"channel":"book","type":"update","data":[{"symbol":"BTC/USD","bids":[{"price":67621.1,"qty":1.65377000}],"asks":[],"checksum":2269551134,"timestamp":"2024-06-01T17:51:46.255830Z"}]}
{"channel":"book","type":"update","data":[{"symbol":"BTC/USD","bids":[],"asks":[{"price":67621.2,"qty":1.47917654}],"checksum":54599588,"timestamp":"2024-06-01T17:51:46.266133Z"}]}
{"channel":"book","type":"update","data":[{"symbol":"BTC/USD","bids":[{"price":67585.3,"qty":0.00113943}],"asks":[],"checksum":4062083966,"timestamp":"2024-06-01T17:51:46.266184Z"}]}
{"channel":"book","type":"update","data":[{"symbol":"BTC/USD","bids":[{"price":67621.1,"qty":1.96477000}],"asks":[],"checksum":1259633951,"timestamp":"2024-06-01T17:51:46.291990Z"}]}
{"channel":"book","type":"update","data":[{"symbol":"BTC/USD","bids":[{"price":67621.1,"qty":1.94665000}],"asks":[],"checksum":2219239578,"timestamp":"2024-06-01T17:51:46.293451Z"}]}
{"channel":"book","type":"update","data":[{"symbol":"BTC/USD","bids":[{"price":67621.1,"qty":1.94268000}],"asks":[],"checksum":4151135892,"timestamp":"2024-06-01T17:51:46.298537Z"}]}
{"channel":"book","type":"update","data":[{"symbol":"BTC/USD","bids":[{"price":67614.4,"qty":0.00000000},{"price":67585.2,"qty":0.24000000}],"asks":[],"checksum":3017527645,"timestamp":"2024-06-01T17:51:46.303908Z"}]}
{"channel":"book","type":"update","data":[{"symbol":"BTC/USD","bids":[{"price":67591.4,"qty":0.00010000}],"asks":[],"checksum":4144246472,"timestamp":"2024-06-01T17:51:46.306131Z"}]}
{"channel":"book","type":"update","data":[{"symbol":"BTC/USD","bids":[{"price":67614.7,"qty":1.47896640}],"asks":[],"checksum":3400976466,"timestamp":"2024-06-01T17:51:46.307786Z"}]}
{"channel":"book","type":"update","data":[{"symbol":"BTC/USD","bids":[],"asks":[{"price":67622.4,"qty":1.48006462}],"checksum":939446007,"timestamp":"2024-06-01T17:51:46.307901Z"}]}
{"channel":"book","type":"update","data":[{"symbol":"BTC/USD","bids":[{"price":67621.1,"qty":1.96080000}],"asks":[],"checksum":3424635098,"timestamp":"2024-06-01T17:51:46.308915Z"}]}
{"channel":"book","type":"update","data":[{"symbol":"BTC/USD","bids":[{"price":67621.1,"qty":1.96477000}],"asks":[],"checksum":676224838,"timestamp":"2024-06-01T17:51:46.311405Z"}]}
{"channel":"book","type":"update","data":[{"symbol":"BTC/USD","bids":[],"asks":[{"price":67621.3,"qty":0.00000000},{"price":67634.5,"qty":0.05912874}],"checksum":3813374274,"timestamp":"2024-06-01T17:51:46.312806Z"}]}
{"channel":"book","type":"update","data":[{"symbol":"BTC/USD","bids":[{"price":67621.1,"qty":1.62727000}],"asks":[],"checksum":1734251759,"timestamp":"2024-06-01T17:51:46.313408Z"}]}
{"channel":"book","type":"update","data":[{"symbol":"BTC/USD","bids":[{"price":67621.1,"qty":1.96477000}],"asks":[],"checksum":3813374274,"timestamp":"2024-06-01T17:51:46.325456Z"}]}
{"channel":"book","type":"update","data":[{"symbol":"BTC/USD","bids":[{"price":67591.8,"qty":0.02214349}],"asks":[],"checksum":3584802867,"timestamp":"2024-06-01T17:51:46.329293Z"}]}
{"channel":"book","type":"update","data":[{"symbol":"BTC/USD","bids":[{"price":67621.1,"qty":1.65377000}],"asks":[],"checksum":4020739067,"timestamp":"2024-06-01T17:51:46.344939Z"}]}
{"channel":"book","type":"update","data":[{"symbol":"BTC/USD","bids":[{"price":67614.7,"qty":0.00000000},{"price":67591.6,"qty":0.33750000}],"asks":[],"checksum":2950319422,"timestamp":"2024-06-01T17:51:46.354184Z"}]}
{"channel":"book","type":"update","data":[{"symbol":"BTC/USD","bids":[{"price":67613.0,"qty":1.47900456}],"asks":[],"checksum":4107062303,"timestamp":"2024-06-01T17:51:46.357911Z"}]}
{"channel":"book","type":"update","data":[{"symbol":"BTC/USD","bids":[{"price":67614.4,"qty":1.47897424}],"asks":[],"checksum":336875572,"timestamp":"2024-06-01T17:51:46.357978Z"}]}
{"channel":"book","type":"update","data":[{"symbol":"BTC/USD","bids":[{"price":67621.1,"qty":1.96477000}],"asks":[],"checksum":3952000770,"timestamp":"2024-06-01T17:51:46.361293Z"}]}
{"channel":"book","type":"update","data":[{"symbol":"BTC/USD","bids":[{"price":67621.1,"qty":1.62727000}],"asks":[],"checksum":685087748,"timestamp":"2024-06-01T17:51:46.365141Z"}]}
{"channel":"book","type":"update","data":[{"symbol":"BTC/USD","bids":[{"price":67621.1,"qty":1.31627000}],"asks":[],"checksum":3854940888,"timestamp":"2024-06-01T17:51:46.414502Z"}]}
{"channel":"book","type":"update","data":[{"symbol":"BTC/USD","bids":[],"asks":[{"price":67621.2,"qty":1.77497654}],"checksum":3070225753,"timestamp":"2024-06-01T17:51:46.417420Z"}]}
{"channel":"book","type":"update","data":[{"symbol":"BTC/USD","bids":[{"price":67621.1,"qty":1.65377000}],"asks":[],"checksum":1194198965,"timestamp":"2024-06-01T17:51:46.423317Z"}]}
{"channel":"book","type":"update","data":[{"symbol":"BTC/USD","bids":[{"price":67621.1,"qty":1.96477000}],"asks":[],"checksum":3098863747,"timestamp":"2024-06-01T17:51:46.431201Z"}]}
{"channel":"book","type":"update","data":[{"symbol":"BTC/USD","bids":[{"price":67621.1,"qty":1.62727000}],"asks":[],"checksum":2079312773,"timestamp":"2024-06-01T17:51:46.452425Z"}]}
{"channel":"book","type":"update","data":[{"symbol":"BTC/USD","bids":[{"price":67611.3,"qty":0.00010000}],"asks":[],"checksum":3010606069,"timestamp":"2024-06-01T17:51:46.462381Z"}]}
{"channel":"book","type":"update","data":[{"symbol":"BTC/USD","bids":[{"price":67612.2,"qty":0.00000000},{"price":67598.8,"qty":0.17739500},{"price":67613.4,"qty":0.06910000}],"asks":[],"checksum":2382476459,"timestamp":"2024-06-01T17:51:46.467432Z"}]}
{"channel":"book","type":"update","data":[{"symbol":"BTC/USD","bids":[],"asks":[{"price":67621.2,"qty":1.84407654}],"checksum":2047279519,"timestamp":"2024-06-01T17:51:46.471278Z"}]}
{"channel":"book","type":"update","data":[{"symbol":"BTC/USD","bids":[{"price":67613.4,"qty":0.00000000},{"price":67598.8,"qty":0.17739500},{"price":67612.5,"qty":0.06910000}],"asks":[],"checksum":2443980783,"timestamp":"2024-06-01T17:51:46.597376Z"}]}
{"channel":"book","type":"update","data":[{"symbol":"BTC/USD","bids":[],"asks":[{"price":67621.2,"qty":1.97538167}],"checksum":2492427524,"timestamp":"2024-06-01T17:51:46.648639Z"}]}
{"channel":"book","type":"update","data":[{"symbol":"BTC/USD","bids":[],"asks":[{"price":67630.4,"qty":0.44359340}],"checksum":1480049075,"timestamp":"2024-06-01T17:51:46.679912Z"}]}
{"channel":"book","type":"update","data":[{"symbol":"BTC/USD","bids":[{"price":67618.9,"qty":0.00000000},{"price":67598.8,"qty":0.17739500},{"price":67621.1,"qty":1.65684656}],"asks":[],"checksum":3656647395,"timestamp":"2024-06-01T17:51:46.730675Z"}]}
{"channel":"book","type":"update","data":[{"symbol":"BTC/USD","bids":[],"asks":[{"price":67631.8,"qty":0.11091373},{"price":67632.8,"qty":0.57919679}],"checksum":3418127457,"timestamp":"2024-06-01T17:51:46.734057Z"}]}
{"channel":"book","type":"update","data":[{"symbol":"BTC/USD","bids":[],"asks":[{"price":67621.2,"qty":1.90628167}],"checksum":2364441543,"timestamp":"2024-06-01T17:51:46.754395Z"}]}
{"channel":"book","type":"update","data":[{"symbol":"BTC/USD","bids":[{"price":67614.4,"qty":0.00000000},{"price":67591.7,"qty":0.02214290}],"asks":[],"checksum":2837200746,"timestamp":"2024-06-01T17:51:46.755783Z"}]}
{"channel":"book","type":"update","data":[{"symbol":"BTC/USD","bids":[{"price":67604.5,"qty":1.47919138}],"asks":[],"checksum":1820409612,"timestamp":"2024-06-01T17:51:46.760086Z"}]}
{"channel":"book","type":"update","data":[{"symbol":"BTC/USD","bids":[{"price":67609.5,"qty":1.47908029}],"asks":[],"checksum":3641852839,"timestamp":"2024-06-01T17:51:46.760173Z"}]}
{"channel":"book","type":"update","data":[{"symbol":"BTC/USD","bids":[{"price":67614.7,"qty":1.47896753}],"asks":[],"checksum":2492492082,"timestamp":"2024-06-01T17:51:46.760437Z"}]}
{"channel":"book","type":"update","data":[{"symbol":"BTC/USD","bids":[],"asks":[{"price":67621.2,"qty":0.42745417}],"checksum":3323269265,"timestamp":"2024-06-01T17:51:46.761603Z"}]}
{"channel":"book","type":"update","data":[{"symbol":"BTC/USD","bids":[{"price":67614.7,"qty":0.00000000},{"price":67598.9,"qty":0.00028778}],"asks":[],"checksum":2545429905,"timestamp":"2024-06-01T17:51:46.765843Z"}]}
{"channel":"book","type":"update","data":[{"symbol":"BTC/USD","bids":[{"price":67605.2,"qty":0.33750000}],"asks":[],"checksum":3700363719,"timestamp":"2024-06-01T17:51:46.767209Z"}]}
{"channel":"book","type":"update","data":[{"symbol":"BTC/USD","bids":[],"asks":[{"price":67621.7,"qty":1.47881730}],"checksum":3997676008,"timestamp":"2024-06-01T17:51:46.769940Z"}]}
{"channel":"book","type":"update","data":[{"symbol":"BTC/USD","bids":[{"price":67613.0,"qty":0.00000000},{"price":67598.9,"qty":0.00028778}],"asks":[],"checksum":751540922,"timestamp":"2024-06-01T17:51:46.788402Z"}]}
{"channel":"book","type":"update","data":[{"symbol":"BTC/USD","bids":[{"price":67612.5,"qty":0.00000000},{"price":67598.8,"qty":0.17739500},{"price":67613.9,"qty":0.06910000}],"asks":[],"checksum":522885916,"timestamp":"2024-06-01T17:51:46.817452Z"}]}
{"channel":"book","type":"update","data":[{"symbol":"BTC/USD","bids":[{"price":67613.9,"qty":0.00000000},{"price":67598.8,"qty":0.17739500},{"price":67612.7,"qty":0.06910000}],"asks":[],"checksum":2202077832,"timestamp":"2024-06-01T17:51:46.847181Z"}]}
{"channel":"book","type":"update","data":[{"symbol":"BTC/USD","bids":[{"price":67609.6,"qty":0.00113913}],"asks":[],"checksum":2523139803,"timestamp":"2024-06-01T17:51:46.847216Z"}]}
{"channel":"book","type":"update","data":[{"symbol":"BTC/USD","bids":[],"asks":[{"price":67621.7,"qty":0.00000000},{"price":67632.8,"qty":0.57919679}],"checksum":1289605380,"timestamp":"2024-06-01T17:51:46.899670Z"}]}
{"channel":"book","type":"update","data":[{"symbol":"BTC/USD","bids":[],"asks":[{"price":67621.4,"qty":1.47882368}],"checksum":829427452,"timestamp":"2024-06-01T17:51:46.903833Z"}]}
{"channel":"book","type":"update","data":[{"symbol":"BTC/USD","bids":[{"price":67613.5,"qty":1.47899371}],"asks":[],"checksum":2737906677,"timestamp":"2024-06-01T17:51:46.903964Z"}]}
{"channel":"book","type":"update","data":[{"symbol":"BTC/USD","bids":[{"price":67615.4,"qty":1.47895231}],"asks":[],"checksum":911142473,"timestamp":"2024-06-01T17:51:46.904010Z"}]}
{"channel":"book","type":"update","data":[{"symbol":"BTC/USD","bids":[{"price":67615.4,"qty":0.00000000},{"price":67605.2,"qty":0.33750000}],"asks":[],"checksum":2737906677,"timestamp":"2024-06-01T17:51:46.928109Z"}]}
{"channel":"book","type":"update","data":[{"symbol":"BTC/USD","bids":[],"asks":[{"price":67621.4,"qty":0.00000000},{"price":67632.8,"qty":0.57919679}],"checksum":3734830093,"timestamp":"2024-06-01T17:51:46.928239Z"}]}
{"channel":"book","type":"update","data":[{"symbol":"BTC/USD","bids":[{"price":67605.3,"qty":0.92000789}],"asks":[],"checksum":2684314835,"timestamp":"2024-06-01T17:51:46.930627Z"}]}
{"channel":"book","type":"update","data":[{"symbol":"BTC/USD","bids":[{"price":67621.1,"qty":1.31934656}],"asks":[],"checksum":763659305,"timestamp":"2024-06-01T17:51:46.937740Z"}]}
{"channel":"book","type":"update","data":[{"symbol":"BTC/USD","bids":[{"price":67621.1,"qty":1.65684656}],"asks":[],"checksum":2684314835,"timestamp":"2024-06-01T17:51:46.946589Z"}]}
{"channel":"book","type":"update","data":[{"symbol":"BTC/USD","bids":[],"asks":[{"price":67621.2,"qty":0.49655417}],"checksum":246557049,"timestamp":"2024-06-01T17:51:46.969124Z"}]}
{"channel":"book","type":"update","data":[{"symbol":"BTC/USD","bids":[{"price":67612.7,"qty":0.00000000},{"price":67605.2,"qty":0.33750000},{"price":67613.7,"qty":0.06910000}],"asks":[],"checksum":26959273,"timestamp":"2024-06-01T17:51:46.969249Z"}]}
{"channel":"book","type":"update","data":[{"symbol":"BTC/USD","bids":[],"asks":[{"price":67621.8,"qty":1.47881404}],"checksum":3306490448,"timestamp":"2024-06-01T17:51:46.982210Z"}]}
{"channel":"book","type":"update","data":[{"symbol":"BTC/USD","bids":[{"price":67615.5,"qty":1.47894964}],"asks":[],"checksum":3068522828,"timestamp":"2024-06-01T17:51:46.982345Z"}]}
{"channel":"book","type":"update","data":[{"symbol":"BTC/USD","bids":[{"price":67621.1,"qty":1.31934656}],"asks":[],"checksum":3946811822,"timestamp":"2024-06-01T17:51:46.990225Z"}]}
{"channel":"book","type":"update","data":[{"symbol":"BTC/USD","bids":[{"price":67621.1,"qty":1.65684656}],"asks":[],"checksum":3068522828,"timestamp":"2024-06-01T17:51:47.031927Z"}]}
{"channel":"book","type":"update","data":[{"symbol":"BTC/USD","bids":[{"price":67615.5,"qty":0.00000000},{"price":67605.3,"qty":0.92000789}],"asks":[],"checksum":3306490448,"timestamp":"2024-06-01T17:51:47.034975Z"}]}
{"channel":"book","type":"update","data":[{"symbol":"BTC/USD","bids":[{"price":67615.7,"qty":1.47894490}],"asks":[],"checksum":94243837,"timestamp":"2024-06-01T17:51:47.039680Z"}]}
{"channel":"book","type":"update","data":[{"symbol":"BTC/USD","bids":[{"price":67621.1,"qty":1.31934656}],"asks":[],"checksum":1480878879,"timestamp":"2024-06-01T17:51:47.073188Z"}]}
{"channel":"book","type":"update","data":[{"symbol":"BTC/USD","bids":[],"asks":[{"price":67621.2,"qty":0.42745417}],"checksum":79794972,"timestamp":"2024-06-01T17:51:47.108628Z"}]}
{"channel":"book","type":"update","data":[{"symbol":"BTC/USD","bids":[{"price":67621.1,"qty":1.65684656}],"asks":[],"checksum":1495004158,"timestamp":"2024-06-01T17:51:47.153527Z"}]}
{"channel":"book","type":"update","data":[{"symbol":"BTC/USD","bids":[{"price":67609.6,"qty":0.00000000},{"price":67605.2,"qty":0.33750000},{"price":67615.8,"qty":0.00113902}],"asks":[],"checksum":2045646399,"timestamp":"2024-06-01T17:51:47.184556Z"}]}
{"channel":"book","type":"update","data":[{"symbol":"BTC/USD","bids":[],"asks":[{"price":67621.8,"qty":0.00000000},{"price":67632.8,"qty":0.57919679}],"checksum":3613142376,"timestamp":"2024-06-01T17:51:47.244229Z"}]}
{"channel":"book","type":"update","data":[{"symbol":"BTC/USD","bids":[{"price":67613.5,"qty":0.00000000},{"price":67605.2,"qty":0.33750000}],"asks":[],"checksum":1783925559,"timestamp":"2024-06-01T17:51:47.244256Z"}]}
{"channel":"book","type":"update","data":[{"symbol":"BTC/USD","bids":[],"asks":[{"price":67622.1,"qty":1.47880722}],"checksum":2256115194,"timestamp":"2024-06-01T17:51:47.248738Z"}]}
{"channel":"book","type":"update","data":[{"symbol":"BTC/USD","bids":[{"price":67616.1,"qty":1.47893662}],"asks":[],"checksum":3428493715,"timestamp":"2024-06-01T17:51:47.248772Z"}]}
{"channel":"book","type":"update","data":[{"symbol":"BTC/USD","bids":[{"price":67613.7,"qty":0.00000000},{"price":67605.2,"qty":0.33750000}],"asks":[],"checksum":2156353282,"timestamp":"2024-06-01T17:51:47.254928Z"}]}
{"channel":"book","type":"update","data":[{"symbol":"BTC/USD","bids":[{"price":67615.8,"qty":0.00000000},{"price":67604.5,"qty":1.47919138},{"price":67609.6,"qty":0.00113913}],"asks":[],"checksum":504979574,"timestamp":"2024-06-01T17:51:47.286355Z"}]}
{"channel":"book","type":"update","data":[{"symbol":"BTC/USD","bids":[{"price":67621.1,"qty":1.31934656}],"asks":[],"checksum":1346386242,"timestamp":"2024-06-01T17:51:47.301206Z"}]}
{"channel":"book","type":"update","data":[{"symbol":"BTC/USD","bids":[{"price":67609.6,"qty":0.00000000},{"price":67604.5,"qty":1.47919138}],"asks":[],"checksum":36977045,"timestamp":"2024-06-01T17:51:47.352972Z"}]}
{"channel":"book","type":"update","data":[{"symbol":"BTC/USD","bids":[{"price":67614.1,"qty":0.06910000}],"asks":[],"checksum":938027685,"timestamp":"2024-06-01T17:51:47.356988Z"}]}
{"channel":"book","type":"update","data":[{"symbol":"BTC/USD","bids":[],"asks":[{"price":67622.1,"qty":0.00000000},{"price":67632.8,"qty":0.57919679}],"checksum":1056984304,"timestamp":"2024-06-01T17:51:47.399658Z"}]}
{"channel":"book","type":"update","data":[{"symbol":"BTC/USD","bids":[],"asks":[{"price":67621.9,"qty":1.47881237}],"checksum":4074663280,"timestamp":"2024-06-01T17:51:47.403427Z"}]}
{"channel":"book","type":"update","data":[{"symbol":"BTC/USD","bids":[],"asks":[{"price":67621.2,"qty":0.29614904}],"checksum":1945702856,"timestamp":"2024-06-01T17:51:47.403879Z"}]}
{"channel":"book","type":"update","data":[{"symbol":"BTC/USD","bids":[{"price":67621.1,"qty":1.90020603}],"asks":[],"checksum":488950086,"timestamp":"2024-06-01T17:51:47.404145Z"}]}
{"channel":"book","type":"update","data":[{"symbol":"BTC/USD","bids":[],"asks":[{"price":67621.2,"qty":0.00034904},{"price":67621.8,"qty":0.29580000}],"checksum":1237269657,"timestamp":"2024-06-01T17:51:47.406969Z"}]}
{"channel":"book","type":"update","data":[{"symbol":"BTC/USD","bids":[{"price":67621.1,"qty":2.23770603}],"asks":[],"checksum":1538961948,"timestamp":"2024-06-01T17:51:47.464975Z"}]}
{"channel":"book","type":"update","data":[{"symbol":"BTC/USD","bids":[{"price":67621.1,"qty":1.90020603}],"asks":[],"checksum":1237269657,"timestamp":"2024-06-01T17:51:47.510746Z"}]}
{"channel":"book","type":"update","data":[{"symbol":"BTC/USD","bids":[{"price":67621.1,"qty":2.23770603}],"asks":[],"checksum":1538961948,"timestamp":"2024-06-01T17:51:47.514789Z"}]}
{"channel":"book","type":"update","data":[{"symbol":"BTC/USD","bids":[{"price":67621.1,"qty":1.90020603}],"asks":[],"checksum":1237269657,"timestamp":"2024-06-01T17:51:47.559413Z"}]}
{"channel":"book","type":"update","data":[{"symbol":"BTC/USD","bids":[{"price":67621.1,"qty":2.23770603}],"asks":[],"checksum":1538961948,"timestamp":"2024-06-01T17:51:47.596101Z"}]}
{"channel":"book","type":"update","data":[{"symbol":"BTC/USD","bids":[{"price":67621.1,"qty":1.90020603}],"asks":[],"checksum":1237269657,"timestamp":"2024-06-01T17:51:47.666684Z"}]}
{"channel":"book","type":"update","data":[{"symbol":"BTC/USD","bids":[],"asks":[{"price":67621.9,"qty":0.00000000},{"price":67631.8,"qty":0.11091373}],"checksum":225469365,"timestamp":"2024-06-01T17:51:47.681234Z"}]}
{"channel":"book","type":"update","data":[{"symbol":"BTC/USD","bids":[],"asks":[{"price":67621.7,"qty":1.47881681}],"checksum":92550835,"timestamp":"2024-06-01T17:51:47.685787Z"}]}
{"channel":"book","type":"update","data":[{"symbol":"BTC/USD","bids":[],"asks":[{"price":67621.2,"qty":0.00154904}],"checksum":2987817904,"timestamp":"2024-06-01T17:51:47.816533Z"}]}
{"channel":"book","type":"update","data":[{"symbol":"BTC/USD","bids":[],"asks":[{"price":67621.2,"qty":0.07064904}],"checksum":2636305598,"timestamp":"2024-06-01T17:51:47.904935Z"}]}
{"channel":"book","type":"update","data":[{"symbol":"BTC/USD","bids":[],"asks":[{"price":67621.8,"qty":0.00000000},{"price":67631.8,"qty":0.11091373},{"price":67621.2,"qty":0.36644904}],"checksum":1193563182,"timestamp":"2024-06-01T17:51:47.907840Z"}]}
{"channel":"book","type":"update","data":[{"symbol":"BTC/USD","bids":[{"price":67621.1,"qty":2.23770603}],"asks":[],"checksum":1428282027,"timestamp":"2024-06-01T17:51:47.908801Z"}]}
{"channel":"book","type":"update","data":[{"symbol":"BTC/USD","bids":[{"price":67621.1,"qty":1.90020603}],"asks":[],"checksum":1193563182,"timestamp":"2024-06-01T17:51:47.933035Z"}]}
{"channel":"book","type":"update","data":[{"symbol":"BTC/USD","bids":[],"asks":[{"price":67621.7,"qty":0.00000000},{"price":67632.8,"qty":0.57919679}],"checksum":2677735079,"timestamp":"2024-06-01T17:51:47.941531Z"}]}
{"channel":"book","type":"update","data":[{"symbol":"BTC/USD","bids":[{"price":67615.7,"qty":0.00000000},{"price":67604.5,"qty":1.47919138}],"asks":[],"checksum":1353156824,"timestamp":"2024-06-01T17:51:47.941569Z"}]}
{"channel":"book","type":"update","data":[{"symbol":"BTC/USD","bids":[{"price":67616.1,"qty":0.00000000},{"price":67599.0,"qty":1.20113931}],"asks":[],"checksum":2456141914,"timestamp":"2024-06-01T17:51:47.941615Z"}]}
{"channel":"book","type":"update","data":[{"symbol":"BTC/USD","bids":[{"price":67614.1,"qty":0.00000000},{"price":67598.9,"qty":0.92029524}],"asks":[],"checksum":2886541138,"timestamp":"2024-06-01T17:51:47.943476Z"}]}
{"channel":"book","type":"update","data":[{"symbol":"BTC/USD","bids":[{"price":67613.4,"qty":1.47899624}],"asks":[],"checksum":3230861830,"timestamp":"2024-06-01T17:51:47.946634Z"}]}
{"channel":"book","type":"update","data":[{"symbol":"BTC/USD","bids":[],"asks":[{"price":67624.0,"qty":1.47876657}],"checksum":4097446167,"timestamp":"2024-06-01T17:51:47.946650Z"}]}
{"channel":"book","type":"update","data":[{"symbol":"BTC/USD","bids":[{"price":67613.1,"qty":1.47900308}],"asks":[],"checksum":631550755,"timestamp":"2024-06-01T17:51:47.946681Z"}]}
{"channel":"book","type":"update","data":[{"symbol":"BTC/USD","bids":[],"asks":[{"price":67621.2,"qty":1.84527520}],"checksum":3113909655,"timestamp":"2024-06-01T17:51:47.946697Z"}]}
{"channel":"book","type":"update","data":[{"symbol":"BTC/USD","bids":[],"asks":[{"price":67621.2,"qty":2.14527520}],"checksum":1836462956,"timestamp":"2024-06-01T17:51:47.975399Z"}]}
{"channel":"book","type":"update","data":[{"symbol":"BTC/USD","bids":[],"asks":[{"price":67621.2,"qty":2.34527520}],"checksum":3834109409,"timestamp":"2024-06-01T17:51:47.975943Z"}]}
{"channel":"book","type":"update","data":[{"symbol":"BTC/USD","bids":[],"asks":[{"price":67621.2,"qty":2.64527520}],"checksum":2236969692,"timestamp":"2024-06-01T17:51:47.976569Z"}]}
{"channel":"book","type":"update","data":[{"symbol":"BTC/USD","bids":[{"price":67613.4,"qty":0.00000000},{"price":67599.0,"qty":1.20113931}],"asks":[],"checksum":77930690,"timestamp":"2024-06-01T17:51:47.979852Z"}]}
{"channel":"book","type":"update","data":[{"symbol":"BTC/USD","bids":[{"price":67613.1,"qty":0.00000000},{"price":67598.9,"qty":0.92029524}],"asks":[],"checksum":2431415771,"timestamp":"2024-06-01T17:51:47.980012Z"}]}
{"channel":"book","type":"update","data":[{"symbol":"BTC/USD","bids":[],"asks":[{"price":67621.2,"qty":2.94527520}],"checksum":2154578168,"timestamp":"2024-06-01T17:51:47.982018Z"}]}
{"channel":"book","type":"update","data":[{"symbol":"BTC/USD","bids":[{"price":67609.5,"qty":0.00000000},{"price":67598.8,"qty":0.17739500}],"asks":[],"checksum":505596280,"timestamp":"2024-06-01T17:51:47.984348Z"}]}
{"channel":"book","type":"update","data":[{"symbol":"BTC/USD","bids":[{"price":67621.1,"qty":1.31934656}],"asks":[],"checksum":1895764470,"timestamp":"2024-06-01T17:51:47.987127Z"}]}
{"channel":"book","type":"update","data":[{"symbol":"BTC/USD","bids":[],"asks":[{"price":67624.0,"qty":0.00000000},{"price":67632.8,"qty":0.57919679}],"checksum":726315810,"timestamp":"2024-06-01T17:51:47.990163Z"}]}
{"channel":"book","type":"update","data":[{"symbol":"BTC/USD","bids":[{"price":67621.1,"qty":1.28977000},{"price":67603.6,"qty":0.02957656}],"asks":[],"checksum":2826650311,"timestamp":"2024-06-01T17:51:47.991289Z"}]}
{"channel":"book","type":"update","data":[{"symbol":"BTC/USD","bids":[],"asks":[{"price":67631.3,"qty":1.47860552}],"checksum":1886927333,"timestamp":"2024-06-01T17:51:47.993938Z"}]}
{"channel":"book","type":"update","data":[{"symbol":"BTC/USD","bids":[{"price":67615.2,"qty":1.47895739}],"asks":[],"checksum":2710947674,"timestamp":"2024-06-01T17:51:47.997921Z"}]}
{"channel":"book","type":"update","data":[{"symbol":"BTC/USD","bids":[{"price":67614.4,"qty":0.24204335}],"asks":[],"checksum":2564441896,"timestamp":"2024-06-01T17:51:48.008640Z"}]}
{"channel":"book","type":"update","data":[{"symbol":"BTC/USD","bids":[{"price":67621.1,"qty":1.28580000}],"asks":[],"checksum":1511007921,"timestamp":"2024-06-01T17:51:48.012797Z"}]}
{"channel":"book","type":"update","data":[{"symbol":"BTC/USD","bids":[],"asks":[{"price":67621.2,"qty":3.27927520}],"checksum":4177063881,"timestamp":"2024-06-01T17:51:48.034128Z"}]}
{"channel":"book","type":"update","data":[{"symbol":"BTC/USD","bids":[{"price":67605.3,"qty":0.00113920}],"asks":[],"checksum":3460737437,"timestamp":"2024-06-01T17:51:48.089836Z"}]}
{"channel":"book","type":"update","data":[{"symbol":"BTC/USD","bids":[],"asks":[{"price":67622.3,"qty":0.07643008}],"checksum":2977360865,"timestamp":"2024-06-01T17:51:48.154297Z"}]}
{"channel":"book","type":"update","data":[{"symbol":"BTC/USD","bids":[],"asks":[{"price":67621.2,"qty":3.31875018}],"checksum":5794482,"timestamp":"2024-06-01T17:51:48.158540Z"}]}
{"channel":"book","type":"update","data":[{"symbol":"BTC/USD","bids":[{"price":67613.5,"qty":0.06910000}],"asks":[],"checksum":133106643,"timestamp":"2024-06-01T17:51:48.183101Z"}]}
{"channel":"book","type":"update","data":[{"symbol":"BTC/USD","bids":[{"price":67615.2,"qty":0.00000000},{"price":67604.5,"qty":1.47919138}],"asks":[],"checksum":2129422609,"timestamp":"2024-06-01T17:51:48.232230Z"}]}
{"channel":"book","type":"update","data":[{"symbol":"BTC/USD","bids":[{"price":67614.4,"qty":0.00000000},{"price":67603.6,"qty":0.02957656}],"asks":[],"checksum":3423353867,"timestamp":"2024-06-01T17:51:48.234383Z"}]}
{"channel":"book","type":"update","data":[{"symbol":"BTC/USD","bids":[{"price":67614.7,"qty":1.47896627}],"asks":[],"checksum":3327384144,"timestamp":"2024-06-01T17:51:48.237121Z"}]}
{"channel":"book","type":"update","data":[{"symbol":"BTC/USD","bids":[{"price":67608.6,"qty":1.47910019}],"asks":[],"checksum":2322570302,"timestamp":"2024-06-01T17:51:48.237158Z"}]}
{"channel":"book","type":"update","data":[{"symbol":"BTC/USD","bids":[{"price":67614.0,"qty":0.36658577}],"asks":[],"checksum":1892015932,"timestamp":"2024-06-01T17:51:48.237430Z"}]}
{"channel":"book","type":"update","data":[{"symbol":"BTC/USD","bids":[],"asks":[{"price":67627.1,"qty":0.00000000},{"price":67631.8,"qty":0.69011052}],"checksum":3056445097,"timestamp":"2024-06-01T17:51:48.244929Z"}]}
{"channel":"book","type":"update","data":[{"symbol":"BTC/USD","bids":[{"price":67614.7,"qty":0.00000000},{"price":67605.2,"qty":0.33750000}],"asks":[],"checksum":1919198661,"timestamp":"2024-06-01T17:51:48.244942Z"}]}
{"channel":"book","type":"update","data":[{"symbol":"BTC/USD","bids":[],"asks":[{"price":67624.4,"qty":1.47875624}],"checksum":3842073050,"timestamp":"2024-06-01T17:51:48.249150Z"}]}
{"channel":"book","type":"update","data":[{"symbol":"BTC/USD","bids":[{"price":67611.5,"qty":1.47903790}],"asks":[],"checksum":229581791,"timestamp":"2024-06-01T17:51:48.249180Z"}]}
{"channel":"book","type":"update","data":[{"symbol":"BTC/USD","bids":[{"price":67611.5,"qty":0.00000000},{"price":67605.2,"qty":0.33750000}],"asks":[],"checksum":3842073050,"timestamp":"2024-06-01T17:51:48.288851Z"}]}
{"channel":"book","type":"update","data":[{"symbol":"BTC/USD","bids":[{"price":67613.7,"qty":1.47898971}],"asks":[],"checksum":2148699114,"timestamp":"2024-06-01T17:51:48.293176Z"}]}
{"channel":"book","type":"update","data":[{"symbol":"BTC/USD","bids":[{"price":67613.7,"qty":0.00000000},{"price":67605.2,"qty":0.33750000}],"asks":[],"checksum":3842073050,"timestamp":"2024-06-01T17:51:48.297977Z"}]}
{"channel":"book","type":"update","data":[{"symbol":"BTC/USD","bids":[{"price":67613.5,"qty":0.00000000},{"price":67604.5,"qty":1.47919138},{"price":67614.5,"qty":0.06910000}],"asks":[],"checksum":3658483144,"timestamp":"2024-06-01T17:51:48.417831Z"}]}
{"channel":"book","type":"update","data":[{"symbol":"BTC/USD","bids":[{"price":67614.1,"qty":1.47898030}],"asks":[],"checksum":2825723534,"timestamp":"2024-06-01T17:51:48.454036Z"}]}
{"channel":"book","type":"update","data":[{"symbol":"BTC/USD","bids":[{"price":67614.1,"qty":0.00000000},{"price":67605.2,"qty":0.33750000}],"asks":[],"checksum":3658483144,"timestamp":"2024-06-01T17:51:48.457379Z"}]}
{"channel":"book","type":"update","data":[{"symbol":"BTC/USD","bids":[{"price":67605.3,"qty":0.00000000},{"price":67604.5,"qty":1.47919138},{"price":67608.7,"qty":0.00113908}],"asks":[],"checksum":2588683237,"timestamp":"2024-06-01T17:51:48.551832Z"}]}
{"channel":"book","type":"update","data":[{"symbol":"BTC/USD","bids":[],"asks":[{"price":67621.2,"qty":1.83992402}],"checksum":3345178812,"timestamp":"2024-06-01T17:51:48.588080Z"}]}
{"channel":"book","type":"update","data":[{"symbol":"BTC/USD","bids":[],"asks":[{"price":67621.2,"qty":1.97122915}],"checksum":3681962269,"timestamp":"2024-06-01T17:51:48.591258Z"}]}
{"channel":"book","type":"update","data":[{"symbol":"BTC/USD","bids":[],"asks":[{"price":67621.7,"qty":1.47881721}],"checksum":1472409547,"timestamp":"2024-06-01T17:51:48.592037Z"}]}
{"channel":"book","type":"update","data":[{"symbol":"BTC/USD","bids":[{"price":67615.5,"qty":1.47895034}],"asks":[],"checksum":3832816520,"timestamp":"2024-06-01T17:51:48.592105Z"}]}
{"channel":"book","type":"update","data":[{"symbol":"BTC/USD","bids":[{"price":67615.5,"qty":0.00000000},{"price":67605.2,"qty":0.33750000}],"asks":[],"checksum":1472409547,"timestamp":"2024-06-01T17:51:48.618353Z"}]}
{"channel":"book","type":"update","data":[{"symbol":"BTC/USD","bids":[],"asks":[{"price":67621.7,"qty":0.00000000},{"price":67631.7,"qty":0.92002822}],"checksum":3681962269,"timestamp":"2024-06-01T17:51:48.618943Z"}]}
{"channel":"book","type":"update","data":[{"symbol":"BTC/USD","bids":[{"price":67613.1,"qty":1.47900318}],"asks":[],"checksum":2917409416,"timestamp":"2024-06-01T17:51:48.622796Z"}]}
{"channel":"book","type":"update","data":[{"symbol":"BTC/USD","bids":[],"asks":[{"price":67621.2,"qty":3.45005531}],"checksum":3163691079,"timestamp":"2024-06-01T17:51:48.657436Z"}]}
{"channel":"book","type":"update","data":[{"symbol":"BTC/USD","bids":[{"price":67614.2,"qty":1.47897822}],"asks":[],"checksum":2779302334,"timestamp":"2024-06-01T17:51:48.657478Z"}]}
{"channel":"book","type":"update","data":[{"symbol":"BTC/USD","bids":[{"price":67608.7,"qty":0.00000000},{"price":67608.6,"qty":1.47910019},{"price":67614.3,"qty":0.00113899}],"asks":[],"checksum":3282050968,"timestamp":"2024-06-01T17:51:49.051614Z"}]}
{"channel":"book","type":"update","data":[{"symbol":"BTC/USD","bids":[],"asks":[{"price":67621.2,"qty":3.11605531}],"checksum":3165085665,"timestamp":"2024-06-01T17:51:49.243980Z"}]}
{"channel":"book","type":"update","data":[{"symbol":"BTC/USD","bids":[{"price":67621.1,"qty":1.28977000}],"asks":[],"checksum":2508818417,"timestamp":"2024-06-01T17:51:49.255199Z"}]}
{"channel":"book","type":"update","data":[{"symbol":"BTC/USD","bids":[{"price":67614.2,"qty":0.00000000},{"price":67608.6,"qty":1.47910019}],"asks":[],"checksum":903288010,"timestamp":"2024-06-01T17:51:49.541775Z"}]}
{"channel":"book","type":"update","data":[{"symbol":"BTC/USD","bids":[{"price":67613.5,"qty":1.47899433}],"asks":[],"checksum":3354405968,"timestamp":"2024-06-01T17:51:49.545647Z"}]}
{"channel":"book","type":"update","data":[{"symbol":"BTC/USD","bids":[{"price":67614.5,"qty":0.00000000},{"price":67608.6,"qty":1.47910019},{"price":67617.4,"qty":0.06910000}],"asks":[],"checksum":3279835659,"timestamp":"2024-06-01T17:51:49.573559Z"}]}
{"channel":"book","type":"update","data":[{"symbol":"BTC/USD","bids":[],"asks":[{"price":67621.2,"qty":3.04695531}],"checksum":1302322831,"timestamp":"2024-06-01T17:51:49.576595Z"}]}
{"channel":"book","type":"update","data":[{"symbol":"BTC/USD","bids":[{"price":67617.4,"qty":0.00000000},{"price":67608.6,"qty":1.47910019}],"asks":[],"checksum":2736538029,"timestamp":"2024-06-01T17:51:49.576723Z"}]}
{"channel":"book","type":"update","data":[{"symbol":"BTC/USD","bids":[{"price":67618.6,"qty":0.06910000}],"asks":[],"checksum":518402290,"timestamp":"2024-06-01T17:51:49.576891Z"}]}
{"channel":"book","type":"update","data":[{"symbol":"BTC/USD","bids":[],"asks":[{"price":67630.4,"qty":0.00000000},{"price":67631.8,"qty":0.69011052}],"checksum":3734912103,"timestamp":"2024-06-01T17:51:49.577630Z"}]}
{"channel":"book","type":"update","data":[{"symbol":"BTC/USD","bids":[{"price":67621.1,"qty":1.62727000}],"asks":[],"checksum":3732281323,"timestamp":"2024-06-01T17:51:49.578037Z"}]}
{"channel":"book","type":"update","data":[{"symbol":"BTC/USD","bids":[{"price":67621.1,"qty":1.96477000}],"asks":[],"checksum":2312876054,"timestamp":"2024-06-01T17:51:49.579819Z"}]}
{"channel":"book","type":"update","data":[{"symbol":"BTC/USD","bids":[],"asks":[{"price":67621.2,"qty":1.56812915}],"checksum":838141672,"timestamp":"2024-06-01T17:51:49.581176Z"}]}
{"channel":"book","type":"update","data":[{"symbol":"BTC/USD","bids":[{"price":67613.5,"qty":0.00000000},{"price":67608.6,"qty":1.47910019}],"asks":[],"checksum":3285335666,"timestamp":"2024-06-01T17:51:49.581247Z"}]}
{"channel":"book","type":"update","data":[{"symbol":"BTC/USD","bids":[{"price":67613.1,"qty":0.00000000},{"price":67605.3,"qty":0.35269783}],"asks":[],"checksum":3422181181,"timestamp":"2024-06-01T17:51:49.581261Z"}]}
{"channel":"book","type":"update","data":[{"symbol":"BTC/USD","bids":[{"price":67608.6,"qty":0.00000000},{"price":67605.2,"qty":0.33750000}],"asks":[],"checksum":4006934301,"timestamp":"2024-06-01T17:51:49.581296Z"}]}
{"channel":"book","type":"update","data":[{"symbol":"BTC/USD","bids":[],"asks":[{"price":67622.4,"qty":0.00126365}],"checksum":868965467,"timestamp":"2024-06-01T17:51:49.581329Z"}]}
{"channel":"book","type":"update","data":[{"symbol":"BTC/USD","bids":[],"asks":[{"price":67631.7,"qty":0.00000000},{"price":67634.5,"qty":0.05912874}],"checksum":835621248,"timestamp":"2024-06-01T17:51:49.582240Z"}]}
{"channel":"book","type":"update","data":[{"symbol":"BTC/USD","bids":[],"asks":[{"price":67624.4,"qty":0.00000000},{"price":67636.0,"qty":0.22170000}],"checksum":759737643,"timestamp":"2024-06-01T17:51:49.593511Z"}]}
{"channel":"book","type":"update","data":[{"symbol":"BTC/USD","bids":[{"price":67621.1,"qty":3.29510771}],"asks":[],"checksum":580832596,"timestamp":"2024-06-01T17:51:49.598614Z"}]}
{"channel":"book","type":"update","data":[{"symbol":"BTC/USD","bids":[{"price":67618.8,"qty":0.00000000},{"price":67603.6,"qty":0.02957656}],"asks":[],"checksum":2527369481,"timestamp":"2024-06-01T17:51:49.600127Z"}]}
{"channel":"book","type":"update","data":[{"symbol":"BTC/USD","bids":[],"asks":[{"price":67634.8,"qty":0.33750000}],"checksum":139991343,"timestamp":"2024-06-01T17:51:49.602401Z"}]}
{"channel":"book","type":"update","data":[{"symbol":"BTC/USD","bids":[{"price":67621.1,"qty":2.95760771}],"asks":[],"checksum":1513479737,"timestamp":"2024-06-01T17:51:49.603867Z"}]}
{"channel":"book","type":"update","data":[{"symbol":"BTC/USD","bids":[],"asks":[{"price":67621.2,"qty":1.26812915}],"checksum":1698342361,"timestamp":"2024-06-01T17:51:49.604067Z"}]}
{"channel":"book","type":"update","data":[{"symbol":"BTC/USD","bids":[],"asks":[{"price":67621.2,"qty":1.06812915}],"checksum":841889154,"timestamp":"2024-06-01T17:51:49.605351Z"}]}
{"channel":"book","type":"update","data":[{"symbol":"BTC/USD","bids":[{"price":67612.1,"qty":0.00030320}],"asks":[],"checksum":692517243,"timestamp":"2024-06-01T17:51:49.606672Z"}]}
{"channel":"book","type":"update","data":[{"symbol":"BTC/USD","bids":[{"price":67614.3,"qty":0.00000000},{"price":67603.6,"qty":0.02957656},{"price":67614.1,"qty":0.00113899}],"asks":[],"checksum":1044725881,"timestamp":"2024-06-01T17:51:49.608514Z"}]}
{"channel":"book","type":"update","data":[{"symbol":"BTC/USD","bids":[],"asks":[{"price":67621.2,"qty":0.76812915}],"checksum":3983494531,"timestamp":"2024-06-01T17:51:49.609661Z"}]}
{"channel":"book","type":"update","data":[{"symbol":"BTC/USD","bids":[],"asks":[{"price":67631.6,"qty":0.00000000},{"price":67636.0,"qty":0.22170000},{"price":67631.7,"qty":0.22190000}],"checksum":2878022982,"timestamp":"2024-06-01T17:51:49.610071Z"}]}
{"channel":"book","type":"update","data":[{"symbol":"BTC/USD","bids":[{"price":67618.6,"qty":0.00000000},{"price":67603.6,"qty":0.02957656}],"asks":[],"checksum":2525060362,"timestamp":"2024-06-01T17:51:49.611504Z"}]}
{"channel":"book","type":"update","data":[{"symbol":"BTC/USD","bids":[{"price":67620.2,"qty":1.47884706}],"asks":[],"checksum":1086759550,"timestamp":"2024-06-01T17:51:49.612081Z"}]}
{"channel":"book","type":"update","data":[{"symbol":"BTC/USD","bids":[],"asks":[{"price":67627.0,"qty":1.47870006}],"checksum":2909988572,"timestamp":"2024-06-01T17:51:49.612097Z"}]}
{"channel":"book","type":"update","data":[{"symbol":"BTC/USD","bids":[],"asks":[{"price":67627.4,"qty":1.47869129}],"checksum":2270443563,"timestamp":"2024-06-01T17:51:49.612205Z"}]}
{"channel":"book","type":"update","data":[{"symbol":"BTC/USD","bids":[{"price":67611.0,"qty":1.47904845}],"asks":[],"checksum":3749697831,"timestamp":"2024-06-01T17:51:49.612310Z"}]}
{"channel":"book","type":"update","data":[{"symbol":"BTC/USD","bids":[{"price":67621.1,"qty":3.29510771}],"asks":[],"checksum":737739185,"timestamp":"2024-06-01T17:51:49.613166Z"}]}
{"channel":"book","type":"update","data":[{"symbol":"BTC/USD","bids":[],"asks":[{"price":67627.2,"qty":0.43000000}],"checksum":1392471454,"timestamp":"2024-06-01T17:51:49.613786Z"}]}
{"channel":"book","type":"update","data":[{"symbol":"BTC/USD","bids":[{"price":67621.1,"qty":3.36420771}],"asks":[],"checksum":2056761160,"timestamp":"2024-06-01T17:51:49.614722Z"}]}
{"channel":"book","type":"update","data":[{"symbol":"BTC/USD","bids":[{"price":67621.1,"qty":3.39378427}],"asks":[],"checksum":1440689866,"timestamp":"2024-06-01T17:51:49.616319Z"}]}
{"channel":"book","type":"update","data":[{"symbol":"BTC/USD","bids":[{"price":67621.1,"qty":3.05628427}],"asks":[],"checksum":3968627589,"timestamp":"2024-06-01T17:51:49.620061Z"}]}
{"channel":"book","type":"update","data":[{"symbol":"BTC/USD","bids":[],"asks":[{"price":67621.2,"qty":0.46812915}],"checksum":651543132,"timestamp":"2024-06-01T17:51:49.620463Z"}]}
{"channel":"book","type":"update","data":[{"symbol":"BTC/USD","bids":[{"price":67621.1,"qty":3.39378427}],"asks":[],"checksum":2676399891,"timestamp":"2024-06-01T17:51:49.627019Z"}]}
{"channel":"book","type":"update","data":[{"symbol":"BTC/USD","bids":[],"asks":[{"price":67630.5,"qty":0.00000000},{"price":67631.8,"qty":0.69011052}],"checksum":2808393909,"timestamp":"2024-06-01T17:51:49.636916Z"}]}
{"channel":"book","type":"update","data":[{"symbol":"BTC/USD","bids":[],"asks":[{"price":67627.0,"qty":0.00000000},{"price":67634.5,"qty":0.05912874}],"checksum":3261262251,"timestamp":"2024-06-01T17:51:49.641841Z"}]}
{"channel":"book","type":"update","data":[{"symbol":"BTC/USD","bids":[],"asks":[{"price":67631.3,"qty":0.00000000},{"price":67635.6,"qty":1.47851218}],"checksum":3865065768,"timestamp":"2024-06-01T17:51:49.641900Z"}]}
{"channel":"book","type":"update","data":[{"symbol":"BTC/USD","bids":[],"asks":[{"price":67627.4,"qty":0.00000000},{"price":67636.0,"qty":0.22170000}],"checksum":2457955691,"timestamp":"2024-06-01T17:51:49.642008Z"}]}
{"channel":"book","type":"update","data":[{"symbol":"BTC/USD","bids":[],"asks":[{"price":67630.4,"qty":0.43000000}],"checksum":970161002,"timestamp":"2024-06-01T17:51:49.645278Z"}]}
{"channel":"book","type":"update","data":[{"symbol":"BTC/USD","bids":[],"asks":[{"price":67627.2,"qty":0.00000000},{"price":67636.0,"qty":0.22170000}],"checksum":3231776622,"timestamp":"2024-06-01T17:51:49.645799Z"}]}
{"channel":"book","type":"update","data":[{"symbol":"BTC/USD","bids":[],"asks":[{"price":67627.7,"qty":0.00000000},{"price":67637.2,"qty":0.00010000}],"checksum":2270709246,"timestamp":"2024-06-01T17:51:49.650814Z"}]}
{"channel":"book","type":"update","data":[{"symbol":"BTC/USD","bids":[{"price":67620.2,"qty":0.00000000},{"price":67605.2,"qty":0.33750000}],"asks":[],"checksum":870405182,"timestamp":"2024-06-01T17:51:49.668578Z"}]}
{"channel":"book","type":"update","data":[{"symbol":"BTC/USD","bids":[{"price":67614.1,"qty":0.00000000},{"price":67599.0,"qty":1.20000000},{"price":67599.1,"qty":0.00113924}],"asks":[],"checksum":2832638243,"timestamp":"2024-06-01T17:51:49.676279Z"}]}
{"channel":"book","type":"update","data":[{"symbol":"BTC/USD","bids":[],"asks":[{"price":67621.2,"qty":0.46778011},{"price":67626.9,"qty":0.00034800}],"checksum":2293514904,"timestamp":"2024-06-01T17:51:49.676301Z"}]}
{"channel":"book","type":"update","data":[{"symbol":"BTC/USD","bids":[{"price":67621.1,"qty":3.39478427}],"asks":[],"checksum":3189795213,"timestamp":"2024-06-01T17:51:49.689365Z"}]}
{"channel":"book","type":"update","data":[{"symbol":"BTC/USD","bids":[{"price":67620.1,"qty":1.47884955}],"asks":[],"checksum":15009273,"timestamp":"2024-06-01T17:51:49.691675Z"}]}
{"channel":"book","type":"update","data":[{"symbol":"BTC/USD","bids":[],"asks":[{"price":67627.4,"qty":1.47869242}],"checksum":988379113,"timestamp":"2024-06-01T17:51:49.691813Z"}]}
{"channel":"book","type":"update","data":[{"symbol":"BTC/USD","bids":[{"price":67618.7,"qty":1.47887883}],"asks":[],"checksum":2683713660,"timestamp":"2024-06-01T17:51:49.691826Z"}]}
{"channel":"book","type":"update","data":[{"symbol":"BTC/USD","bids":[],"asks":[{"price":67630.4,"qty":0.00000000},{"price":67636.0,"qty":0.22170000}],"checksum":130668527,"timestamp":"2024-06-01T17:51:49.698159Z"}]}
{"channel":"book","type":"update","data":[{"symbol":"BTC/USD","bids":[],"asks":[{"price":67621.2,"qty":0.33647498}],"checksum":4054716117,"timestamp":"2024-06-01T17:51:49.703537Z"}]}
{"channel":"book","type":"update","data":[{"symbol":"BTC/USD","bids":[],"asks":[{"price":67627.4,"qty":0.00000000},{"price":67637.2,"qty":0.00010000}],"checksum":2402429396,"timestamp":"2024-06-01T17:51:49.708808Z"}]}
{"channel":"book","type":"update","data":[{"symbol":"BTC/USD","bids":[],"asks":[{"price":67634.8,"qty":0.33750000}],"checksum":1820488810,"timestamp":"2024-06-01T17:51:49.718741Z"}]}
{"channel":"book","type":"update","data":[{"symbol":"BTC/USD","bids":[],"asks":[{"price":67634.8,"qty":0.00000000},{"price":67637.2,"qty":0.00010000}],"checksum":2402429396,"timestamp":"2024-06-01T17:51:49.724095Z"}]}
{"channel":"book","type":"update","data":[{"symbol":"BTC/USD","bids":[],"asks":[{"price":67636.0,"qty":0.00000000},{"price":67639.9,"qty":0.91997364},{"price":67639.8,"qty":0.22170000}],"checksum":3640007747,"timestamp":"2024-06-01T17:51:49.725196Z"}]}
{"channel":"book","type":"update","data":[{"symbol":"BTC/USD","bids":[],"asks":[{"price":67626.9,"qty":0.00000000},{"price":67639.9,"qty":0.91997364},{"price":67630.3,"qty":0.00034800}],"checksum":1743564751,"timestamp":"2024-06-01T17:51:49.730881Z"}]}
{"channel":"book","type":"update","data":[{"symbol":"BTC/USD","bids":[{"price":67620.1,"qty":0.00000000},{"price":67605.2,"qty":0.33750000}],"asks":[],"checksum":827089758,"timestamp":"2024-06-01T17:51:49.734998Z"}]}
{"channel":"book","type":"update","data":[{"symbol":"BTC/USD","bids":[{"price":67618.7,"qty":0.00000000},{"price":67599.1,"qty":0.00113924}],"asks":[],"checksum":1679375407,"timestamp":"2024-06-01T17:51:49.735007Z"}]}
{"channel":"book","type":"update","data":[{"symbol":"BTC/USD","bids":[],"asks":[{"price":67631.8,"qty":0.11091373},{"price":67634.4,"qty":0.57919679}],"checksum":3860125137,"timestamp":"2024-06-01T17:51:49.736885Z"}]}
{"channel":"book","type":"update","data":[{"symbol":"BTC/USD","bids":[],"asks":[{"price":67625.2,"qty":1.47873960}],"checksum":514818786,"timestamp":"2024-06-01T17:51:49.739805Z"}]}
{"channel":"book","type":"update","data":[{"symbol":"BTC/USD","bids":[],"asks":[{"price":67634.5,"qty":0.00000000},{"price":67637.2,"qty":0.00010000}],"checksum":947700320,"timestamp":"2024-06-01T17:51:49.739864Z"}]}
{"channel":"book","type":"update","data":[{"symbol":"BTC/USD","bids":[{"price":67617.9,"qty":1.47889674}],"asks":[],"checksum":2302649014,"timestamp":"2024-06-01T17:51:49.739881Z"}]}
{"channel":"book","type":"update","data":[{"symbol":"BTC/USD","bids":[{"price":67608.0,"qty":1.47911381}],"asks":[],"checksum":2493430628,"timestamp":"2024-06-01T17:51:49.739919Z"}]}
{"channel":"book","type":"update","data":[{"symbol":"BTC/USD","bids":[{"price":67611.0,"qty":0.00000000},{"price":67605.2,"qty":0.33750000}],"asks":[],"checksum":1023896747,"timestamp":"2024-06-01T17:51:49.742772Z"}]}
{"channel":"book","type":"update","data":[{"symbol":"BTC/USD","bids":[],"asks":[{"price":67625.2,"qty":0.00000000},{"price":67639.8,"qty":0.22170000}],"checksum":2863100708,"timestamp":"2024-06-01T17:51:49.744592Z"}]}
{"channel":"book","type":"update","data":[{"symbol":"BTC/USD","bids":[{"price":67617.9,"qty":0.00000000},{"price":67599.6,"qty":0.22836862}],"asks":[],"checksum":3564399200,"timestamp":"2024-06-01T17:51:49.759903Z"}]}
{"channel":"book","type":"update","data":[{"symbol":"BTC/USD","bids":[],"asks":[{"price":67631.7,"qty":0.65190000}],"checksum":99497307,"timestamp":"2024-06-01T17:51:49.763102Z"}]}
{"channel":"book","type":"update","data":[{"symbol":"BTC/USD","bids":[],"asks":[{"price":67628.7,"qty":1.47866314}],"checksum":369349131,"timestamp":"2024-06-01T17:51:49.764810Z"}]}
{"channel":"book","type":"update","data":[{"symbol":"BTC/USD","bids":[],"asks":[{"price":67634.8,"qty":0.33750000}],"checksum":2596002565,"timestamp":"2024-06-01T17:51:49.772487Z"}]}
{"channel":"book","type":"update","data":[{"symbol":"BTC/USD","bids":[{"price":67611.3,"qty":0.00000000},{"price":67599.1,"qty":0.00113924},{"price":67616.3,"qty":0.12249800}],"asks":[],"checksum":3350260161,"timestamp":"2024-06-01T17:51:49.779059Z"}]}
{"channel":"book","type":"update","data":[{"symbol":"BTC/USD","bids":[],"asks":[{"price":67630.3,"qty":0.00000000},{"price":67637.2,"qty":0.00010000},{"price":67631.6,"qty":0.00034800}],"checksum":3131924148,"timestamp":"2024-06-01T17:51:49.783886Z"}]}
{"channel":"book","type":"update","data":[{"symbol":"BTC/USD","bids":[{"price":67621.1,"qty":3.05728427}],"asks":[],"checksum":1888921550,"timestamp":"2024-06-01T17:51:49.789459Z"}]}
{"channel":"book","type":"update","data":[{"symbol":"BTC/USD","bids":[],"asks":[{"price":67628.7,"qty":0.00000000},{"price":67637.2,"qty":0.00010000}],"checksum":1094899754,"timestamp":"2024-06-01T17:51:49.809731Z"}]}
{"channel":"book","type":"update","data":[{"symbol":"BTC/USD","bids":[],"asks":[{"price":67626.2,"qty":1.47871764}],"checksum":3883277950,"timestamp":"2024-06-01T17:51:49.813712Z"}]}
{"channel":"book","type":"update","data":[{"symbol":"BTC/USD","bids":[{"price":67619.1,"qty":1.47887130}],"asks":[],"checksum":4021843905,"timestamp":"2024-06-01T17:51:49.813764Z"}]}
{"channel":"book","type":"update","data":[{"symbol":"BTC/USD","bids":[],"asks":[{"price":67626.8,"qty":0.06910000}],"checksum":1087536145,"timestamp":"2024-06-01T17:51:49.818450Z"}]}
{"channel":"book","type":"update","data":[{"symbol":"BTC/USD","bids":[],"asks":[{"price":67626.2,"qty":0.00000000},{"price":67635.6,"qty":1.47851218}],"checksum":2518311509,"timestamp":"2024-06-01T17:51:49.835763Z"}]}
{"channel":"book","type":"update","data":[{"symbol":"BTC/USD","bids":[],"asks":[{"price":67631.7,"qty":0.22190000}],"checksum":4012276495,"timestamp":"2024-06-01T17:51:49.856898Z"}]}
{"channel":"book","type":"update","data":[{"symbol":"BTC/USD","bids":[],"asks":[{"price":67631.6,"qty":0.43034800}],"checksum":448276834,"timestamp":"2024-06-01T17:51:49.856969Z"}]}
{"channel":"book","type":"update","data":[{"symbol":"BTC/USD","bids":[{"price":67621.1,"qty":3.39478427}],"asks":[],"checksum":933984254,"timestamp":"2024-06-01T17:51:49.875517Z"}]}
{"channel":"book","type":"update","data":[{"symbol":"BTC/USD","bids":[{"price":67621.1,"qty":4.98778427}],"asks":[],"checksum":3016450578,"timestamp":"2024-06-01T17:51:49.887123Z"}]}
{"channel":"book","type":"update","data":[{"symbol":"BTC/USD","bids":[{"price":67621.1,"qty":4.65028427}],"asks":[],"checksum":707050091,"timestamp":"2024-06-01T17:51:49.893441Z"}]}
{"channel":"book","type":"update","data":[{"symbol":"BTC/USD","bids":[{"price":67619.1,"qty":0.00000000},{"price":67599.1,"qty":0.00113924}],"asks":[],"checksum":2887690562,"timestamp":"2024-06-01T17:51:50.054324Z"}]}
{"channel":"book","type":"update","data":[{"symbol":"BTC/USD","bids":[{"price":67618.5,"qty":1.47888387}],"asks":[],"checksum":4001182356,"timestamp":"2024-06-01T17:51:50.061690Z"}]}
{"channel":"book","type":"update","data":[{"symbol":"BTC/USD","bids":[],"asks":[{"price":67631.0,"qty":1.47861266}],"checksum":3371280218,"timestamp":"2024-06-01T17:51:50.061850Z"}]}
{"channel":"book","type":"update","data":[{"symbol":"BTC/USD","bids":[{"price":67613.3,"qty":1.47899752}],"asks":[],"checksum":1815786080,"timestamp":"2024-06-01T17:51:50.061879Z"}]}
{"channel":"book","type":"update","data":[{"symbol":"BTC/USD","bids":[],"asks":[{"price":67625.6,"qty":1.47873021}],"checksum":411427698,"timestamp":"2024-06-01T17:51:50.063283Z"}]}
{"channel":"book","type":"update","data":[{"symbol":"BTC/USD","bids":[],"asks":[{"price":67631.6,"qty":0.43000000},{"price":67631.5,"qty":0.00034800}],"checksum":262393377,"timestamp":"2024-06-01T17:51:50.101596Z"}]}
{"channel":"book","type":"update","data":[{"symbol":"BTC/USD","bids":[{"price":67608.1,"qty":0.00113909}],"asks":[],"checksum":1389228274,"timestamp":"2024-06-01T17:51:50.101717Z"}]}
{"channel":"book","type":"update","data":[{"symbol":"BTC/USD","bids":[],"asks":[{"price":67625.6,"qty":0.00000000},{"price":67634.4,"qty":0.57919679}],"checksum":1154931548,"timestamp":"2024-06-01T17:51:50.106397Z"}]}
{"channel":"book","type":"update","data":[{"symbol":"BTC/USD","bids":[{"price":67618.5,"qty":0.00000000},{"price":67605.2,"qty":0.33750000}],"asks":[],"checksum":506893586,"timestamp":"2024-06-01T17:51:50.106579Z"}]}
{"channel":"book","type":"update","data":[{"symbol":"BTC/USD","bids":[{"price":67619.0,"qty":1.47887263}],"asks":[],"checksum":3887162592,"timestamp":"2024-06-01T17:51:50.110607Z"}]}
{"channel":"book","type":"update","data":[{"symbol":"BTC/USD","bids":[],"asks":[{"price":67626.2,"qty":1.47871897}],"checksum":1186006205,"timestamp":"2024-06-01T17:51:50.110764Z"}]}
{"channel":"book","type":"update","data":[{"symbol":"BTC/USD","bids":[],"asks":[{"price":67626.2,"qty":0.00000000},{"price":67634.4,"qty":0.57919679}],"checksum":3887162592,"timestamp":"2024-06-01T17:51:50.157364Z"}]}
{"channel":"book","type":"update","data":[{"symbol":"BTC/USD","bids":[{"price":67619.0,"qty":0.00000000},{"price":67605.2,"qty":0.33750000}],"asks":[],"checksum":506893586,"timestamp":"2024-06-01T17:51:50.157431Z"}]}
{"channel":"book","type":"update","data":[{"symbol":"BTC/USD","bids":[],"asks":[{"price":67625.8,"qty":1.47872681}],"checksum":316627303,"timestamp":"2024-06-01T17:51:50.162518Z"}]}
{"channel":"book","type":"update","data":[{"symbol":"BTC/USD","bids":[{"price":67618.7,"qty":1.47888047}],"asks":[],"checksum":3120665459,"timestamp":"2024-06-01T17:51:50.162659Z"}]}
{"channel":"book","type":"update","data":[{"symbol":"BTC/USD","bids":[{"price":67621.1,"qty":4.58118427}],"asks":[],"checksum":2357709171,"timestamp":"2024-06-01T17:51:50.170152Z"}]}
{"channel":"book","type":"update","data":[{"symbol":"BTC/USD","bids":[],"asks":[{"price":67625.8,"qty":0.00000000},{"price":67634.4,"qty":0.57919679}],"checksum":2900665612,"timestamp":"2024-06-01T17:51:50.206312Z"}]}
{"channel":"book","type":"update","data":[{"symbol":"BTC/USD","bids":[],"asks":[{"price":67626.8,"qty":0.00000000},{"price":67634.8,"qty":0.33750000},{"price":67625.2,"qty":0.06910000}],"checksum":3071203506,"timestamp":"2024-06-01T17:51:50.222645Z"}]}
{"channel":"book","type":"update","data":[{"symbol":"BTC/USD","bids":[{"price":67620.5,"qty":0.06910000}],"asks":[],"checksum":2260189471,"timestamp":"2024-06-01T17:51:50.277989Z"}]}
{"channel":"book","type":"update","data":[{"symbol":"BTC/USD","bids":[],"asks":[{"price":67625.2,"qty":0.00000000},{"price":67634.8,"qty":0.33750000},{"price":67626.1,"qty":0.06910000}],"checksum":1118202072,"timestamp":"2024-06-01T17:51:50.278105Z"}]}
{"channel":"book","type":"update","data":[{"symbol":"BTC/USD","bids":[{"price":67620.5,"qty":0.00000000},{"price":67605.3,"qty":0.35269783},{"price":67619.5,"qty":0.06910000}],"asks":[],"checksum":2729882982,"timestamp":"2024-06-01T17:51:50.281489Z"}]}
{"channel":"book","type":"update","data":[{"symbol":"BTC/USD","bids":[{"price":67618.7,"qty":0.00000000},{"price":67605.3,"qty":0.35269783}],"asks":[],"checksum":1433577499,"timestamp":"2024-06-01T17:51:50.471788Z"}]}
{"channel":"book","type":"update","data":[{"symbol":"BTC/USD","bids":[],"asks":[{"price":67625.5,"qty":1.47873259}],"checksum":2420648316,"timestamp":"2024-06-01T17:51:50.475708Z"}]}
{"channel":"book","type":"update","data":[{"symbol":"BTC/USD","bids":[{"price":67619.0,"qty":1.47887317}],"asks":[],"checksum":3550429727,"timestamp":"2024-06-01T17:51:50.475807Z"}]}
{"channel":"book","type":"update","data":[{"symbol":"BTC/USD","bids":[{"price":67621.1,"qty":4.24368427}],"asks":[],"checksum":3950646588,"timestamp":"2024-06-01T17:51:50.561612Z"}]}
{"channel":"book","type":"update","data":[{"symbol":"BTC/USD","bids":[{"price":67608.1,"qty":0.00000000},{"price":67605.3,"qty":0.35269783},{"price":67614.1,"qty":0.00113899}],"asks":[],"checksum":3334982303,"timestamp":"2024-06-01T17:51:50.720381Z"}]}
{"channel":"book","type":"update","data":[{"symbol":"BTC/USD","bids":[],"asks":[{"price":67631.5,"qty":0.00000000},{"price":67634.4,"qty":0.57919679},{"price":67625.4,"qty":0.00034801}],"checksum":2525168153,"timestamp":"2024-06-01T17:51:50.720418Z"}]}
{"channel":"book","type":"update","data":[{"symbol":"BTC/USD","bids":[{"price":67619.5,"qty":0.00000000},{"price":67605.3,"qty":0.35269783},{"price":67620.4,"qty":0.06910000}],"asks":[],"checksum":1155883958,"timestamp":"2024-06-01T17:51:50.772619Z"}]}
{"channel":"book","type":"update","data":[{"symbol":"BTC/USD","bids":[{"price":67621.1,"qty":4.82454374}],"asks":[],"checksum":3150865911,"timestamp":"2024-06-01T17:51:50.942293Z"}]}
{"channel":"book","type":"update","data":[{"symbol":"BTC/USD","bids":[{"price":67621.1,"qty":5.16204374}],"asks":[],"checksum":701666517,"timestamp":"2024-06-01T17:51:51.089943Z"}]}
{"channel":"book","type":"update","data":[{"symbol":"BTC/USD","bids":[{"price":67621.1,"qty":4.82454374}],"asks":[],"checksum":3150865911,"timestamp":"2024-06-01T17:51:51.098178Z"}]}
{"channel":"book","type":"update","data":[{"symbol":"BTC/USD","bids":[{"price":67621.1,"qty":5.16204374}],"asks":[],"checksum":701666517,"timestamp":"2024-06-01T17:51:51.178592Z"}]}
{"channel":"book","type":"update","data":[{"symbol":"BTC/USD","bids":[{"price":67621.1,"qty":4.82454374}],"asks":[],"checksum":3150865911,"timestamp":"2024-06-01T17:51:51.220707Z"}]}
{"channel":"book","type":"update","data":[{"symbol":"BTC/USD","bids":[{"price":67621.1,"qty":5.16204374}],"asks":[],"checksum":701666517,"timestamp":"2024-06-01T17:51:51.223923Z"}]}
{"channel":"book","type":"update","data":[{"symbol":"BTC/USD","bids":[{"price":67621.1,"qty":5.49954374}],"asks":[],"checksum":3110985814,"timestamp":"2024-06-01T17:51:51.334858Z"}]}
{"channel":"book","type":"update","data":[{"symbol":"BTC/USD","bids":[{"price":67621.1,"qty":5.16204374}],"asks":[],"checksum":701666517,"timestamp":"2024-06-01T17:51:51.337708Z"}]}
{"channel":"book","type":"update","data":[{"symbol":"BTC/USD","bids":[],"asks":[{"price":67631.8,"qty":0.69011052}],"checksum":3059597353,"timestamp":"2024-06-01T17:51:51.338888Z"}]}
{"channel":"book","type":"update","data":[{"symbol":"BTC/USD","bids":[{"price":67621.1,"qty":4.82454374}],"asks":[],"checksum":608252171,"timestamp":"2024-06-01T17:51:51.425406Z"}]}
{"channel":"book","type":"update","data":[{"symbol":"BTC/USD","bids":[{"price":67614.1,"qty":0.00000000},{"price":67605.3,"qty":0.35269783},{"price":67621.1,"qty":4.82568262}],"asks":[],"checksum":1399358889,"timestamp":"2024-06-01T17:51:51.442570Z"}]}
{"channel":"book","type":"update","data":[{"symbol":"BTC/USD","bids":[{"price":67621.1,"qty":5.16318262}],"asks":[],"checksum":1293431719,"timestamp":"2024-06-01T17:51:51.482764Z"}]}
{"channel":"book","type":"update","data":[{"symbol":"BTC/USD","bids":[{"price":67621.1,"qty":4.82568262}],"asks":[],"checksum":1399358889,"timestamp":"2024-06-01T17:51:51.486253Z"}]}
{"channel":"book","type":"update","data":[{"symbol":"BTC/USD","bids":[{"price":67621.1,"qty":5.16318262}],"asks":[],"checksum":1293431719,"timestamp":"2024-06-01T17:51:51.539818Z"}]}
{"channel":"book","type":"update","data":[{"symbol":"BTC/USD","bids":[],"asks":[{"price":67626.1,"qty":0.00000000},{"price":67634.8,"qty":0.33750000}],"checksum":2818654757,"timestamp":"2024-06-01T17:51:51.564201Z"}]}
{"channel":"book","type":"update","data":[{"symbol":"BTC/USD","bids":[{"price":67621.1,"qty":4.82568262}],"asks":[],"checksum":3060921387,"timestamp":"2024-06-01T17:51:51.572265Z"}]}
{"channel":"book","type":"update","data":[{"symbol":"BTC/USD","bids":[],"asks":[{"price":67625.5,"qty":0.00000000},{"price":67635.3,"qty":0.44356848}],"checksum":3691240970,"timestamp":"2024-06-01T17:51:51.572424Z"}]}
{"channel":"book","type":"update","data":[{"symbol":"BTC/USD","bids":[{"price":67619.0,"qty":0.00000000},{"price":67605.2,"qty":0.33750000}],"asks":[],"checksum":3156068721,"timestamp":"2024-06-01T17:51:51.572776Z"}]}
{"channel":"book","type":"update","data":[{"symbol":"BTC/USD","bids":[],"asks":[{"price":67626.5,"qty":1.47871111}],"checksum":2672272854,"timestamp":"2024-06-01T17:51:51.576702Z"}]}
{"channel":"book","type":"update","data":[{"symbol":"BTC/USD","bids":[{"price":67619.8,"qty":1.47885512}],"asks":[],"checksum":4089272388,"timestamp":"2024-06-01T17:51:51.576832Z"}]}
{"channel":"book","type":"update","data":[{"symbol":"BTC/USD","bids":[{"price":67621.1,"qty":5.16318262}],"asks":[],"checksum":3989696074,"timestamp":"2024-06-01T17:51:51.577873Z"}]}
{"channel":"book","type":"update","data":[{"symbol":"BTC/USD","bids":[{"price":67621.1,"qty":4.82568262}],"asks":[],"checksum":4089272388,"timestamp":"2024-06-01T17:51:51.581539Z"}]}
{"channel":"book","type":"update","data":[{"symbol":"BTC/USD","bids":[{"price":67619.8,"qty":0.00000000},{"price":67605.2,"qty":0.33750000}],"asks":[],"checksum":2672272854,"timestamp":"2024-06-01T17:51:51.599652Z"}]}
{"channel":"book","type":"update","data":[{"symbol":"BTC/USD","bids":[{"price":67621.1,"qty":5.16318262}],"asks":[],"checksum":3993224004,"timestamp":"2024-06-01T17:51:51.604510Z"}]}
{"channel":"book","type":"update","data":[{"symbol":"BTC/USD","bids":[],"asks":[{"price":67625.4,"qty":0.00000000},{"price":67635.3,"qty":0.44356848},{"price":67626.4,"qty":0.00034800}],"checksum":2710777852,"timestamp":"2024-06-01T17:51:51.630906Z"}]}
{"channel":"book","type":"update","data":[{"symbol":"BTC/USD","bids":[],"asks":[{"price":67626.7,"qty":0.06910000}],"checksum":3847947022,"timestamp":"2024-06-01T17:51:51.730870Z"}]}
{"channel":"book","type":"update","data":[{"symbol":"BTC/USD","bids":[],"asks":[{"price":67626.5,"qty":0.00000000},{"price":67634.8,"qty":0.33750000}],"checksum":1725310650,"timestamp":"2024-06-01T17:51:51.848436Z"}]}
{"channel":"book","type":"update","data":[{"symbol":"BTC/USD","bids":[{"price":67619.5,"qty":1.47886156}],"asks":[],"checksum":958679446,"timestamp":"2024-06-01T17:51:51.852352Z"}]}
{"channel":"book","type":"update","data":[{"symbol":"BTC/USD","bids":[],"asks":[{"price":67626.2,"qty":1.47871843}],"checksum":130698093,"timestamp":"2024-06-01T17:51:51.852377Z"}]}
{"channel":"book","type":"update","data":[{"symbol":"BTC/USD","bids":[],"asks":[{"price":67626.4,"qty":0.00000000},{"price":67634.8,"qty":0.33750000},{"price":67630.9,"qty":0.00034800}],"checksum":2817439599,"timestamp":"2024-06-01T17:51:51.894074Z"}]}
{"channel":"book","type":"update","data":[{"symbol":"BTC/USD","bids":[{"price":67621.1,"qty":4.82568262}],"asks":[],"checksum":3114140001,"timestamp":"2024-06-01T17:51:51.906077Z"}]}
{"channel":"book","type":"update","data":[{"symbol":"BTC/USD","bids":[{"price":67619.5,"qty":0.00000000},{"price":67605.2,"qty":0.33750000}],"asks":[],"checksum":3120110127,"timestamp":"2024-06-01T17:51:52.008741Z"}]}
{"channel":"book","type":"update","data":[{"symbol":"BTC/USD","bids":[],"asks":[{"price":67626.2,"qty":0.00000000},{"price":67634.8,"qty":0.33750000}],"checksum":2840895602,"timestamp":"2024-06-01T17:51:52.008874Z"}]}
{"channel":"book","type":"update","data":[{"symbol":"BTC/USD","bids":[{"price":67619.1,"qty":1.47887147}],"asks":[],"checksum":2116701073,"timestamp":"2024-06-01T17:51:52.012694Z"}]}
{"channel":"book","type":"update","data":[{"symbol":"BTC/USD","bids":[],"asks":[{"price":67625.7,"qty":1.47872834}],"checksum":2413178546,"timestamp":"2024-06-01T17:51:52.012807Z"}]}
{"channel":"book","type":"update","data":[{"symbol":"BTC/USD","bids":[{"price":67621.1,"qty":4.82668262}],"asks":[],"checksum":687590435,"timestamp":"2024-06-01T17:51:52.027749Z"}]}
{"channel":"book","type":"update","data":[{"symbol":"BTC/USD","bids":[],"asks":[{"price":67630.9,"qty":0.00000000},{"price":67634.8,"qty":0.33750000},{"price":67625.6,"qty":0.00034800}],"checksum":713920922,"timestamp":"2024-06-01T17:51:52.070805Z"}]}
{"channel":"book","type":"update","data":[{"symbol":"BTC/USD","bids":[],"asks":[{"price":67626.7,"qty":0.00000000},{"price":67634.8,"qty":0.33750000},{"price":67625.5,"qty":0.06910000}],"checksum":957607578,"timestamp":"2024-06-01T17:51:52.268193Z"}]}
{"channel":"book","type":"update","data":[{"symbol":"BTC/USD","bids":[{"price":67605.3,"qty":0.00000000},{"price":67605.2,"qty":0.33750000}],"asks":[],"checksum":1933747773,"timestamp":"2024-06-01T17:51:52.396417Z"}]}
{"channel":"book","type":"update","data":[{"symbol":"BTC/USD","bids":[],"asks":[{"price":67625.6,"qty":0.00000000},{"price":67634.8,"qty":0.33750000},{"price":67625.4,"qty":0.00029555}],"checksum":148227496,"timestamp":"2024-06-01T17:51:52.724819Z"}]}
{"channel":"book","type":"update","data":[{"symbol":"BTC/USD","bids":[{"price":67621.1,"qty":5.16418262}],"asks":[],"checksum":1179055067,"timestamp":"2024-06-01T17:51:52.961655Z"}]}
{"channel":"book","type":"update","data":[{"symbol":"BTC/USD","bids":[{"price":67621.1,"qty":5.14418262}],"asks":[],"checksum":3163293691,"timestamp":"2024-06-01T17:51:53.032845Z"}]}
{"channel":"book","type":"update","data":[{"symbol":"BTC/USD","bids":[{"price":67621.1,"qty":4.80668262}],"asks":[],"checksum":4062130568,"timestamp":"2024-06-01T17:51:53.036512Z"}]}
{"channel":"book","type":"update","data":[{"symbol":"BTC/USD","bids":[{"price":67621.1,"qty":4.80554374}],"asks":[],"checksum":2164454568,"timestamp":"2024-06-01T17:51:53.070754Z"}]}
{"channel":"book","type":"update","data":[{"symbol":"BTC/USD","bids":[{"price":67618.2,"qty":1.47889127}],"asks":[],"checksum":1131372110,"timestamp":"2024-06-01T17:51:53.128332Z"}]}
{"channel":"book","type":"update","data":[{"symbol":"BTC/USD","bids":[],"asks":[{"price":67627.1,"qty":1.47869790}],"checksum":2502309303,"timestamp":"2024-06-01T17:51:53.128404Z"}]}
{"channel":"book","type":"update","data":[{"symbol":"BTC/USD","bids":[{"price":67619.1,"qty":0.00000000},{"price":67605.2,"qty":0.33750000}],"asks":[],"checksum":2101513679,"timestamp":"2024-06-01T17:51:53.137833Z"}]}
{"channel":"book","type":"update","data":[{"symbol":"BTC/USD","bids":[],"asks":[{"price":67625.7,"qty":0.00000000},{"price":67631.8,"qty":0.69011052}],"checksum":2832304949,"timestamp":"2024-06-01T17:51:53.137868Z"}]}
{"channel":"book","type":"update","data":[{"symbol":"BTC/USD","bids":[],"asks":[{"price":67625.4,"qty":0.00000000},{"price":67634.8,"qty":0.33750000},{"price":67627.0,"qty":0.00029555}],"checksum":334612454,"timestamp":"2024-06-01T17:51:53.187219Z"}]}
{"channel":"book","type":"update","data":[{"symbol":"BTC/USD","bids":[],"asks":[{"price":67625.9,"qty":1.47872555}],"checksum":2575303076,"timestamp":"2024-06-01T17:51:53.188410Z"}]}
{"channel":"book","type":"update","data":[{"symbol":"BTC/USD","bids":[{"price":67619.2,"qty":1.47886907}],"asks":[],"checksum":3365365348,"timestamp":"2024-06-01T17:51:53.188452Z"}]}
{"channel":"book","type":"update","data":[{"symbol":"BTC/USD","bids":[{"price":67621.1,"qty":5.14304374}],"asks":[],"checksum":3942152395,"timestamp":"2024-06-01T17:51:53.201305Z"}]}
{"channel":"book","type":"update","data":[{"symbol":"BTC/USD","bids":[],"asks":[{"price":67625.5,"qty":0.00000000},{"price":67631.8,"qty":0.11091373},{"price":67626.4,"qty":0.06910000}],"checksum":3204833708,"timestamp":"2024-06-01T17:51:53.255467Z"}]}
{"channel":"book","type":"update","data":[{"symbol":"BTC/USD","bids":[{"price":67608.1,"qty":0.00113871}],"asks":[],"checksum":3300066149,"timestamp":"2024-06-01T17:51:53.426996Z"}]}
{"channel":"book","type":"update","data":[{"symbol":"BTC/USD","bids":[],"asks":[{"price":67627.0,"qty":0.00000000},{"price":67631.8,"qty":0.11091373},{"price":67625.8,"qty":0.00029555}],"checksum":3093386670,"timestamp":"2024-06-01T17:51:53.427022Z"}]}
{"channel":"book","type":"update","data":[{"symbol":"BTC/USD","bids":[{"price":67608.1,"qty":0.00000000},{"price":67608.0,"qty":1.47911381}],"asks":[],"checksum":2797850971,"timestamp":"2024-06-01T17:51:53.470192Z"}]}
{"channel":"book","type":"update","data":[{"symbol":"BTC/USD","bids":[],"asks":[{"price":67625.9,"qty":0.00000000},{"price":67631.8,"qty":0.11091373}],"checksum":1191355890,"timestamp":"2024-06-01T17:51:53.706172Z"}]}
{"channel":"book","type":"update","data":[{"symbol":"BTC/USD","bids":[],"asks":[{"price":67625.7,"qty":1.47872884}],"checksum":17566473,"timestamp":"2024-06-01T17:51:53.709399Z"}]}
{"channel":"book","type":"update","data":[{"symbol":"BTC/USD","bids":[{"price":67621.1,"qty":4.80554374}],"asks":[],"checksum":593696166,"timestamp":"2024-06-01T17:51:53.712826Z"}]}
{"channel":"book","type":"update","data":[{"symbol":"BTC/USD","bids":[{"price":67620.4,"qty":0.00000000},{"price":67605.3,"qty":1.20000000}],"asks":[],"checksum":1407190829,"timestamp":"2024-06-01T17:51:53.867297Z"}]}
{"channel":"book","type":"update","data":[{"symbol":"BTC/USD","bids":[{"price":67619.2,"qty":0.00000000},{"price":67605.2,"qty":0.33750000}],"asks":[],"checksum":829219235,"timestamp":"2024-06-01T17:51:53.885600Z"}]}
{"channel":"book","type":"update","data":[{"symbol":"BTC/USD","bids":[],"asks":[{"price":67625.7,"qty":0.00000000},{"price":67631.8,"qty":0.11091373}],"checksum":457557145,"timestamp":"2024-06-01T17:51:53.885614Z"}]}
{"channel":"book","type":"update","data":[{"symbol":"BTC/USD","bids":[{"price":67618.8,"qty":1.47887860}],"asks":[],"checksum":3000720109,"timestamp":"2024-06-01T17:51:53.890558Z"}]}
{"channel":"book","type":"update","data":[{"symbol":"BTC/USD","bids":[],"asks":[{"price":67625.4,"qty":1.47873565}],"checksum":1752908111,"timestamp":"2024-06-01T17:51:53.890583Z"}]}
{"channel":"book","type":"update","data":[{"symbol":"BTC/USD","bids":[],"asks":[{"price":67626.4,"qty":0.00000000},{"price":67631.8,"qty":0.11091373},{"price":67624.6,"qty":0.06910000}],"checksum":1097492476,"timestamp":"2024-06-01T17:51:53.905257Z"}]}
{"channel":"book","type":"update","data":[{"symbol":"BTC/USD","bids":[],"asks":[{"price":67628.0,"qty":0.33750000}],"checksum":803567267,"timestamp":"2024-06-01T17:51:53.905361Z"}]}
{"channel":"book","type":"update","data":[{"symbol":"BTC/USD","bids":[],"asks":[{"price":67628.0,"qty":0.00000000},{"price":67631.7,"qty":0.22190000}],"checksum":1097492476,"timestamp":"2024-06-01T17:51:53.910032Z"}]}
{"channel":"book","type":"update","data":[{"symbol":"BTC/USD","bids":[],"asks":[{"price":67625.4,"qty":0.00000000},{"price":67631.8,"qty":0.11091373}],"checksum":861739596,"timestamp":"2024-06-01T17:51:53.938939Z"}]}
{"channel":"book","type":"update","data":[{"symbol":"BTC/USD","bids":[{"price":67618.8,"qty":0.00000000},{"price":67605.2,"qty":0.33750000}],"asks":[],"checksum":588490829,"timestamp":"2024-06-01T17:51:53.939077Z"}]}
{"channel":"book","type":"update","data":[{"symbol":"BTC/USD","bids":[],"asks":[{"price":67625.2,"qty":1.47874080}],"checksum":181630219,"timestamp":"2024-06-01T17:51:53.942733Z"}]}
{"channel":"book","type":"update","data":[{"symbol":"BTC/USD","bids":[{"price":67618.5,"qty":1.47888407}],"asks":[],"checksum":1627398968,"timestamp":"2024-06-01T17:51:53.942971Z"}]}
{"channel":"book","type":"update","data":[{"symbol":"BTC/USD","bids":[],"asks":[{"price":67625.2,"qty":0.00000000},{"price":67631.8,"qty":0.11091373}],"checksum":4271245120,"timestamp":"2024-06-01T17:51:53.960098Z"}]}
{"channel":"book","type":"update","data":[{"symbol":"BTC/USD","bids":[{"price":67618.5,"qty":0.00000000},{"price":67605.2,"qty":0.33750000}],"asks":[],"checksum":588490829,"timestamp":"2024-06-01T17:51:53.960265Z"}]}
{"channel":"book","type":"update","data":[{"symbol":"BTC/USD","bids":[],"asks":[{"price":67625.8,"qty":0.00000000},{"price":67634.7,"qty":0.57919679},{"price":67627.0,"qty":0.00029555}],"checksum":1521646382,"timestamp":"2024-06-01T17:51:53.979885Z"}]}
{"channel":"book","type":"update","data":[{"symbol":"BTC/USD","bids":[{"price":67621.1,"qty":4.52554374}],"asks":[],"checksum":723616459,"timestamp":"2024-06-01T17:51:53.980803Z"}]}
{"channel":"book","type":"update","data":[{"symbol":"BTC/USD","bids":[],"asks":[{"price":67627.1,"qty":0.00000000},{"price":67634.7,"qty":0.57919679}],"checksum":3340318439,"timestamp":"2024-06-01T17:51:54.006912Z"}]}
{"channel":"book","type":"update","data":[{"symbol":"BTC/USD","bids":[],"asks":[{"price":67624.5,"qty":1.47875408}],"checksum":39769940,"timestamp":"2024-06-01T17:51:54.011252Z"}]}
{"channel":"book","type":"update","data":[{"symbol":"BTC/USD","bids":[{"price":67618.4,"qty":1.47888540}],"asks":[],"checksum":1512497800,"timestamp":"2024-06-01T17:51:54.011454Z"}]}
{"channel":"book","type":"update","data":[{"symbol":"BTC/USD","bids":[{"price":67612.1,"qty":0.00000000},{"price":67605.2,"qty":0.33750000}],"asks":[],"checksum":4103173766,"timestamp":"2024-06-01T17:51:54.024128Z"}]}
{"channel":"book","type":"update","data":[{"symbol":"BTC/USD","bids":[{"price":67608.1,"qty":0.00029668}],"asks":[],"checksum":1690276501,"timestamp":"2024-06-01T17:51:54.031211Z"}]}
{"channel":"book","type":"update","data":[{"symbol":"BTC/USD","bids":[],"asks":[{"price":67627.0,"qty":0.00000000},{"price":67634.7,"qty":0.57919679},{"price":67630.9,"qty":0.00029555}],"checksum":2141624863,"timestamp":"2024-06-01T17:51:54.052328Z"}]}
{"channel":"book","type":"update","data":[{"symbol":"BTC/USD","bids":[],"asks":[{"price":67629.1,"qty":0.07224000}],"checksum":4199621739,"timestamp":"2024-06-01T17:51:54.131653Z"}]}
{"channel":"book","type":"update","data":[{"symbol":"BTC/USD","bids":[{"price":67617.4,"qty":0.06910000}],"asks":[],"checksum":1155259751,"timestamp":"2024-06-01T17:51:54.140608Z"}]}
{"channel":"book","type":"update","data":[{"symbol":"BTC/USD","bids":[],"asks":[{"price":67624.6,"qty":0.00000000},{"price":67631.8,"qty":0.11091373},{"price":67623.3,"qty":0.06910000}],"checksum":2740293750,"timestamp":"2024-06-01T17:51:54.143455Z"}]}
{"channel":"book","type":"update","data":[{"symbol":"BTC/USD","bids":[{"price":67608.1,"qty":0.00143539}],"asks":[],"checksum":3234658273,"timestamp":"2024-06-01T17:51:54.187389Z"}]}
{"channel":"book","type":"update","data":[{"symbol":"BTC/USD","bids":[],"asks":[{"price":67630.9,"qty":0.00000000},{"price":67631.8,"qty":0.11091373},{"price":67621.2,"qty":0.33677053}],"checksum":2936209100,"timestamp":"2024-06-01T17:51:54.187457Z"}]}
{"channel":"book","type":"update","data":[{"symbol":"BTC/USD","bids":[],"asks":[{"price":67624.5,"qty":0.00000000},{"price":67634.7,"qty":0.57919679}],"checksum":280879972,"timestamp":"2024-06-01T17:51:54.197085Z"}]}
{"channel":"book","type":"update","data":[{"symbol":"BTC/USD","bids":[{"price":67618.2,"qty":0.00000000},{"price":67605.3,"qty":1.20000000}],"asks":[],"checksum":2057733452,"timestamp":"2024-06-01T17:51:54.197155Z"}]}
{"channel":"book","type":"update","data":[{"symbol":"BTC/USD","bids":[{"price":67618.4,"qty":0.00000000},{"price":67605.2,"qty":0.33750000}],"asks":[],"checksum":2342449214,"timestamp":"2024-06-01T17:51:54.197166Z"}]}
{"channel":"book","type":"update","data":[{"symbol":"BTC/USD","bids":[{"price":67616.2,"qty":1.47893444}],"asks":[],"checksum":1814814279,"timestamp":"2024-06-01T17:51:54.201726Z"}]}
{"channel":"book","type":"update","data":[{"symbol":"BTC/USD","bids":[{"price":67617.6,"qty":1.47890365}],"asks":[],"checksum":1837953292,"timestamp":"2024-06-01T17:51:54.201796Z"}]}
{"channel":"book","type":"update","data":[{"symbol":"BTC/USD","bids":[],"asks":[{"price":67624.2,"qty":1.47876257}],"checksum":2348324537,"timestamp":"2024-06-01T17:51:54.201819Z"}]}
{"channel":"book","type":"update","data":[{"symbol":"BTC/USD","bids":[],"asks":[{"price":67624.2,"qty":0.00000000},{"price":67634.7,"qty":0.57919679}],"checksum":1837953292,"timestamp":"2024-06-01T17:51:54.208139Z"}]}
{"channel":"book","type":"update","data":[{"symbol":"BTC/USD","bids":[],"asks":[{"price":67631.0,"qty":0.00000000},{"price":67634.8,"qty":0.33750000}],"checksum":438605321,"timestamp":"2024-06-01T17:51:54.208230Z"}]}
{"channel":"book","type":"update","data":[{"symbol":"BTC/USD","bids":[{"price":67617.6,"qty":0.00000000},{"price":67605.3,"qty":1.20000000}],"asks":[],"checksum":461617474,"timestamp":"2024-06-01T17:51:54.208362Z"}]}
{"channel":"book","type":"update","data":[{"symbol":"BTC/USD","bids":[],"asks":[{"price":67628.7,"qty":1.47866350}],"checksum":2100105136,"timestamp":"2024-06-01T17:51:54.213002Z"}]}
{"channel":"book","type":"update","data":[{"symbol":"BTC/USD","bids":[],"asks":[{"price":67621.2,"qty":0.33647498},{"price":67628.6,"qty":0.00029555}],"checksum":2147974056,"timestamp":"2024-06-01T17:51:54.269396Z"}]}
{"channel":"book","type":"update","data":[{"symbol":"BTC/USD","bids":[{"price":67617.4,"qty":0.00000000},{"price":67605.2,"qty":0.33750000},{"price":67616.4,"qty":0.06910000}],"asks":[],"checksum":925856811,"timestamp":"2024-06-01T17:51:54.270751Z"}]}
{"channel":"book","type":"update","data":[{"symbol":"BTC/USD","bids":[],"asks":[{"price":67623.3,"qty":0.00000000},{"price":67634.7,"qty":0.57919679},{"price":67622.3,"qty":0.14553008}],"checksum":1450121879,"timestamp":"2024-06-01T17:51:54.273728Z"}]}
{"channel":"book","type":"update","data":[{"symbol":"BTC/USD","bids":[],"asks":[{"price":67631.5,"qty":0.91998199}],"checksum":368591650,"timestamp":"2024-06-01T17:51:54.355733Z"}]}
{"channel":"book","type":"update","data":[{"symbol":"BTC/USD","bids":[],"asks":[{"price":67631.5,"qty":0.00000000},{"price":67634.7,"qty":0.57919679}],"checksum":1450121879,"timestamp":"2024-06-01T17:51:54.363322Z"}]}
{"channel":"book","type":"update","data":[{"symbol":"BTC/USD","bids":[],"asks":[{"price":67634.6,"qty":0.91998268}],"checksum":762974624,"timestamp":"2024-06-01T17:51:54.363605Z"}]}
{"channel":"book","type":"update","data":[{"symbol":"BTC/USD","bids":[{"price":67616.4,"qty":0.00000000},{"price":67605.2,"qty":0.33750000},{"price":67618.1,"qty":0.06910000}],"asks":[],"checksum":1039204530,"timestamp":"2024-06-01T17:51:54.593263Z"}]}
{"channel":"book","type":"update","data":[{"symbol":"BTC/USD","bids":[],"asks":[{"price":67622.3,"qty":0.07643008},{"price":67624.1,"qty":0.06910000}],"checksum":212779725,"timestamp":"2024-06-01T17:51:54.596178Z"}]}
{"channel":"book","type":"update","data":[{"symbol":"BTC/USD","bids":[{"price":67617.8,"qty":1.47889950}],"asks":[],"checksum":1021419997,"timestamp":"2024-06-01T17:51:54.697286Z"}]}
{"channel":"book","type":"update","data":[{"symbol":"BTC/USD","bids":[],"asks":[{"price":67624.2,"qty":1.47876257}],"checksum":841888908,"timestamp":"2024-06-01T17:51:54.697330Z"}]}
{"channel":"book","type":"update","data":[{"symbol":"BTC/USD","bids":[{"price":67617.8,"qty":0.00000000},{"price":67605.3,"qty":1.20000000}],"asks":[],"checksum":39933852,"timestamp":"2024-06-01T17:51:54.741268Z"}]}
{"channel":"book","type":"update","data":[{"symbol":"BTC/USD","bids":[],"asks":[{"price":67624.2,"qty":0.00000000},{"price":67631.8,"qty":0.69011052}],"checksum":1996548079,"timestamp":"2024-06-01T17:51:54.741354Z"}]}
{"channel":"book","type":"update","data":[{"symbol":"BTC/USD","bids":[],"asks":[{"price":67624.6,"qty":1.47875298}],"checksum":2422694679,"timestamp":"2024-06-01T17:51:54.819344Z"}]}
{"channel":"book","type":"update","data":[{"symbol":"BTC/USD","bids":[{"price":67618.4,"qty":1.47888621}],"asks":[],"checksum":1402699559,"timestamp":"2024-06-01T17:51:54.819542Z"}]}
{"channel":"book","type":"update","data":[{"symbol":"BTC/USD","bids":[],"asks":[{"price":67624.1,"qty":0.00000000},{"price":67631.8,"qty":0.69011052}],"checksum":2575944017,"timestamp":"2024-06-01T17:51:54.965478Z"}]}
{"channel":"book","type":"update","data":[{"symbol":"BTC/USD","bids":[{"price":67616.2,"qty":0.00000000},{"price":67605.3,"qty":1.20000000}],"asks":[],"checksum":2027945465,"timestamp":"2024-06-01T17:51:54.999849Z"}]}
{"channel":"book","type":"update","data":[{"symbol":"BTC/USD","bids":[{"price":67618.7,"qty":1.47887895}],"asks":[],"checksum":1070865285,"timestamp":"2024-06-01T17:51:55.003625Z"}]}
{"channel":"book","type":"update","data":[{"symbol":"BTC/USD","bids":[],"asks":[{"price":67625.0,"qty":1.47874438}],"checksum":639974201,"timestamp":"2024-06-01T17:51:55.003771Z"}]}
{"channel":"book","type":"update","data":[{"symbol":"BTC/USD","bids":[],"asks":[{"price":67628.6,"qty":0.00000000},{"price":67631.8,"qty":0.69011052},{"price":67621.2,"qty":0.33677054}],"checksum":2825331709,"timestamp":"2024-06-01T17:51:55.009102Z"}]}
{"channel":"book","type":"update","data":[{"symbol":"BTC/USD","bids":[],"asks":[{"price":67621.2,"qty":0.33647498},{"price":67624.5,"qty":0.00029556}],"checksum":1333341241,"timestamp":"2024-06-01T17:51:55.100069Z"}]}
{"channel":"book","type":"update","data":[{"symbol":"BTC/USD","bids":[],"asks":[{"price":67624.1,"qty":0.06910000}],"checksum":3577953760,"timestamp":"2024-06-01T17:51:55.185822Z"}]}
{"channel":"book","type":"update","data":[{"symbol":"BTC/USD","bids":[{"price":67618.7,"qty":0.00000000},{"price":67605.3,"qty":1.20000000}],"asks":[],"checksum":2454248348,"timestamp":"2024-06-01T17:51:55.186221Z"}]}
{"channel":"book","type":"update","data":[{"symbol":"BTC/USD","bids":[],"asks":[{"price":67624.6,"qty":0.00000000},{"price":67631.7,"qty":0.22190000}],"checksum":2039155072,"timestamp":"2024-06-01T17:51:55.186319Z"}]}
{"channel":"book","type":"update","data":[{"symbol":"BTC/USD","bids":[],"asks":[{"price":67624.4,"qty":1.47875731}],"checksum":3244298044,"timestamp":"2024-06-01T17:51:55.190497Z"}]}
{"channel":"book","type":"update","data":[{"symbol":"BTC/USD","bids":[{"price":67618.1,"qty":1.54799363}],"asks":[],"checksum":265035269,"timestamp":"2024-06-01T17:51:55.190549Z"}]}
{"channel":"book","type":"update","data":[{"symbol":"BTC/USD","bids":[{"price":67618.1,"qty":1.47889363}],"asks":[],"checksum":3811435926,"timestamp":"2024-06-01T17:51:55.220512Z"}]}
{"channel":"book","type":"update","data":[{"symbol":"BTC/USD","bids":[{"price":67618.1,"qty":1.54799363}],"asks":[],"checksum":265035269,"timestamp":"2024-06-01T17:51:55.360079Z"}]}
{"channel":"book","type":"update","data":[{"symbol":"BTC/USD","bids":[],"asks":[{"price":67621.2,"qty":0.04067498}],"checksum":951744027,"timestamp":"2024-06-01T17:51:55.362904Z"}]}
{"channel":"book","type":"update","data":[{"symbol":"BTC/USD","bids":[],"asks":[{"price":67626.3,"qty":0.29580000}],"checksum":2278847116,"timestamp":"2024-06-01T17:51:55.478724Z"}]}
{"channel":"book","type":"update","data":[{"symbol":"BTC/USD","bids":[],"asks":[{"price":67621.2,"qty":0.00120000}],"checksum":874719165,"timestamp":"2024-06-01T17:51:55.593814Z"}]}
{"channel":"book","type":"update","data":[{"symbol":"BTC/USD","bids":[],"asks":[{"price":67622.2,"qty":0.03947498}],"checksum":2659917877,"timestamp":"2024-06-01T17:51:55.594058Z"}]}
{"channel":"book","type":"update","data":[{"symbol":"BTC/USD","bids":[{"price":67618.4,"qty":0.00000000},{"price":67605.2,"qty":0.33750000}],"asks":[],"checksum":2925440231,"timestamp":"2024-06-01T17:51:55.712942Z"}]}
{"channel":"book","type":"update","data":[{"symbol":"BTC/USD","bids":[{"price":67618.6,"qty":1.47888180}],"asks":[],"checksum":3300004744,"timestamp":"2024-06-01T17:51:55.717094Z"}]}
{"channel":"book","type":"update","data":[{"symbol":"BTC/USD","bids":[],"asks":[{"price":67621.2,"qty":0.00000000},{"price":67629.1,"qty":0.07224000}],"checksum":2126430278,"timestamp":"2024-06-01T17:51:55.801745Z"}]}
{"channel":"book","type":"update","data":[{"symbol":"BTC/USD","bids":[],"asks":[{"price":67624.1,"qty":0.07030000}],"checksum":280819752,"timestamp":"2024-06-01T17:51:55.803862Z"}]}
{"channel":"book","type":"update","data":[{"symbol":"BTC/USD","bids":[{"price":67622.1,"qty":1.33061122}],"asks":[],"checksum":2205036382,"timestamp":"2024-06-01T17:51:55.804602Z"}]}
{"channel":"book","type":"update","data":[{"symbol":"BTC/USD","bids":[{"price":67621.1,"qty":3.94468427}],"asks":[],"checksum":3976736568,"timestamp":"2024-06-01T17:51:55.804740Z"}]}
{"channel":"book","type":"update","data":[{"symbol":"BTC/USD","bids":[{"price":67622.1,"qty":1.91146211}],"asks":[],"checksum":1313245402,"timestamp":"2024-06-01T17:51:55.804926Z"}]}
{"channel":"book","type":"update","data":[{"symbol":"BTC/USD","bids":[{"price":67621.1,"qty":3.91510771},{"price":67621.2,"qty":0.02957652}],"asks":[],"checksum":357899587,"timestamp":"2024-06-01T17:51:55.805816Z"}]}
{"channel":"book","type":"update","data":[{"symbol":"BTC/USD","bids":[{"price":67621.1,"qty":2.58477000}],"asks":[],"checksum":484594893,"timestamp":"2024-06-01T17:51:55.807256Z"}]}
{"channel":"book","type":"update","data":[{"symbol":"BTC/USD","bids":[{"price":67621.1,"qty":2.27377000},{"price":67622.1,"qty":2.22246211}],"asks":[],"checksum":1662935372,"timestamp":"2024-06-01T17:51:55.808303Z"}]}
{"channel":"book","type":"update","data":[{"symbol":"BTC/USD","bids":[{"price":67621.1,"qty":1.97377000},{"price":67622.1,"qty":2.52246211}],"asks":[],"checksum":3298434857,"timestamp":"2024-06-01T17:51:55.808367Z"}]}
{"channel":"book","type":"update","data":[{"symbol":"BTC/USD","bids":[{"price":67621.1,"qty":1.96980000},{"price":67622.1,"qty":2.52643211}],"asks":[],"checksum":2900270256,"timestamp":"2024-06-01T17:51:55.808862Z"}]}
{"channel":"book","type":"update","data":[{"symbol":"BTC/USD","bids":[{"price":67621.1,"qty":1.95168000},{"price":67622.1,"qty":2.54455211}],"asks":[],"checksum":3565553546,"timestamp":"2024-06-01T17:51:55.808919Z"}]}
{"channel":"book","type":"update","data":[{"symbol":"BTC/USD","bids":[{"price":67621.2,"qty":0.00000000},{"price":67608.0,"qty":1.47911381},{"price":67622.1,"qty":2.57412823}],"asks":[],"checksum":187323677,"timestamp":"2024-06-01T17:51:55.809832Z"}]}
{"channel":"book","type":"update","data":[{"symbol":"BTC/USD","bids":[{"price":67621.1,"qty":1.76193000},{"price":67622.1,"qty":2.76388751}],"asks":[],"checksum":2846535360,"timestamp":"2024-06-01T17:51:55.811240Z"}]}
{"channel":"book","type":"update","data":[{"symbol":"BTC/USD","bids":[{"price":67621.1,"qty":1.59500000},{"price":67622.1,"qty":2.93081798}],"asks":[],"checksum":4116687182,"timestamp":"2024-06-01T17:51:55.814520Z"}]}
{"channel":"book","type":"update","data":[{"symbol":"BTC/USD","bids":[{"price":67622.1,"qty":3.09774798}],"asks":[],"checksum":2147683251,"timestamp":"2024-06-01T17:51:55.825780Z"}]}
{"channel":"book","type":"update","data":[{"symbol":"BTC/USD","bids":[{"price":67621.1,"qty":0.00200000}],"asks":[],"checksum":3939126854,"timestamp":"2024-06-01T17:51:55.839088Z"}]}
{"channel":"book","type":"update","data":[{"symbol":"BTC/USD","bids":[],"asks":[{"price":67624.5,"qty":0.00000000},{"price":67631.6,"qty":0.43000000},{"price":67622.2,"qty":0.03977054}],"checksum":1210045171,"timestamp":"2024-06-01T17:51:55.917881Z"}]}
{"channel":"book","type":"update","data":[{"symbol":"BTC/USD","bids":[],"asks":[{"price":67624.4,"qty":0.00000000},{"price":67631.7,"qty":0.22190000}],"checksum":3424489337,"timestamp":"2024-06-01T17:51:55.934351Z"}]}
{"channel":"book","type":"update","data":[{"symbol":"BTC/USD","bids":[],"asks":[{"price":67625.0,"qty":0.00000000},{"price":67631.8,"qty":0.69011052}],"checksum":168947759,"timestamp":"2024-06-01T17:51:55.934386Z"}]}
{"channel":"book","type":"update","data":[{"symbol":"BTC/USD","bids":[{"price":67618.1,"qty":0.06910000}],"asks":[],"checksum":1804275859,"timestamp":"2024-06-01T17:51:55.934491Z"}]}
{"channel":"book","type":"update","data":[{"symbol":"BTC/USD","bids":[],"asks":[{"price":67626.1,"qty":1.47872108}],"checksum":3698740120,"timestamp":"2024-06-01T17:51:55.939044Z"}]}
{"channel":"book","type":"update","data":[{"symbol":"BTC/USD","bids":[],"asks":[{"price":67630.9,"qty":1.47861476}],"checksum":3699765034,"timestamp":"2024-06-01T17:51:55.939096Z"}]}
{"channel":"book","type":"update","data":[{"symbol":"BTC/USD","bids":[{"price":67619.7,"qty":1.47885740}],"asks":[],"checksum":2875479061,"timestamp":"2024-06-01T17:51:55.939191Z"}]}
{"channel":"book","type":"update","data":[{"symbol":"BTC/USD","bids":[{"price":67618.1,"qty":0.00000000},{"price":67608.0,"qty":1.47911381},{"price":67621.2,"qty":0.06910000}],"asks":[],"checksum":4114067428,"timestamp":"2024-06-01T17:51:55.946886Z"}]}
{"channel":"book","type":"update","data":[{"symbol":"BTC/USD","bids":[{"price":67622.1,"qty":3.43524798}],"asks":[],"checksum":3780857109,"timestamp":"2024-06-01T17:51:55.949608Z"}]}
{"channel":"book","type":"update","data":[{"symbol":"BTC/USD","bids":[],"asks":[{"price":67624.1,"qty":0.00120000},{"price":67627.1,"qty":0.06910000}],"checksum":1627906071,"timestamp":"2024-06-01T17:51:55.950158Z"}]}
{"channel":"book","type":"update","data":[{"symbol":"BTC/USD","bids":[],"asks":[{"price":67627.1,"qty":0.00000000},{"price":67631.6,"qty":0.43000000}],"checksum":2602383550,"timestamp":"2024-06-01T17:51:55.950183Z"}]}
{"channel":"book","type":"update","data":[{"symbol":"BTC/USD","bids":[{"price":67618.6,"qty":0.00000000},{"price":67608.0,"qty":1.47911381}],"asks":[],"checksum":3663018520,"timestamp":"2024-06-01T17:51:55.950241Z"}]}
{"channel":"book","type":"update","data":[{"symbol":"BTC/USD","bids":[],"asks":[{"price":67626.1,"qty":0.00000000},{"price":67631.7,"qty":0.22190000}],"checksum":1553104784,"timestamp":"2024-06-01T17:51:55.950299Z"}]}
{"channel":"book","type":"update","data":[{"symbol":"BTC/USD","bids":[{"price":67608.0,"qty":0.00000000},{"price":67605.3,"qty":1.20000000}],"asks":[],"checksum":1622320455,"timestamp":"2024-06-01T17:51:55.950320Z"}]}
{"channel":"book","type":"update","data":[{"symbol":"BTC/USD","bids":[{"price":67622.1,"qty":3.09774798}],"asks":[],"checksum":1960724406,"timestamp":"2024-06-01T17:51:55.953173Z"}]}
{"channel":"book","type":"update","data":[{"symbol":"BTC/USD","bids":[{"price":67622.1,"qty":3.43524798}],"asks":[],"checksum":1622320455,"timestamp":"2024-06-01T17:51:55.956903Z"}]}
{"channel":"book","type":"update","data":[{"symbol":"BTC/USD","bids":[],"asks":[{"price":67630.9,"qty":0.00000000},{"price":67631.8,"qty":0.69011052}],"checksum":3718277731,"timestamp":"2024-06-01T17:51:55.957863Z"}]}
{"channel":"book","type":"update","data":[{"symbol":"BTC/USD","bids":[{"price":67619.7,"qty":0.00000000},{"price":67605.2,"qty":0.33750000}],"asks":[],"checksum":2908264240,"timestamp":"2024-06-01T17:51:55.957932Z"}]}
{"channel":"book","type":"update","data":[{"symbol":"BTC/USD","bids":[{"price":67615.9,"qty":1.47894147}],"asks":[],"checksum":2574165236,"timestamp":"2024-06-01T17:51:55.962718Z"}]}
{"channel":"book","type":"update","data":[{"symbol":"BTC/USD","bids":[{"price":67608.1,"qty":0.00113871}],"asks":[],"checksum":1096024960,"timestamp":"2024-06-01T17:51:55.971547Z"}]}
{"channel":"book","type":"update","data":[{"symbol":"BTC/USD","bids":[{"price":67614.1,"qty":0.00028394}],"asks":[],"checksum":2765434880,"timestamp":"2024-06-01T17:51:55.977155Z"}]}
{"channel":"book","type":"update","data":[{"symbol":"BTC/USD","bids":[{"price":67621.2,"qty":0.00000000},{"price":67605.3,"qty":1.20000000},{"price":67622.1,"qty":3.50434798}],"asks":[],"checksum":3829154759,"timestamp":"2024-06-01T17:51:55.981190Z"}]}
{"channel":"book","type":"update","data":[{"symbol":"BTC/USD","bids":[],"asks":[{"price":67627.5,"qty":1.47868840}],"checksum":4090994834,"timestamp":"2024-06-01T17:51:55.990215Z"}]}
{"channel":"book","type":"update","data":[{"symbol":"BTC/USD","bids":[{"price":67621.0,"qty":1.47882985}],"asks":[],"checksum":2766693037,"timestamp":"2024-06-01T17:51:55.990256Z"}]}
{"channel":"book","type":"update","data":[{"symbol":"BTC/USD","bids":[],"asks":[{"price":67627.5,"qty":0.00000000},{"price":67631.8,"qty":0.69011052}],"checksum":3003351544,"timestamp":"2024-06-01T17:51:56.012052Z"}]}
{"channel":"book","type":"update","data":[{"symbol":"BTC/USD","bids":[],"asks":[{"price":67622.2,"qty":0.03947498},{"price":67626.2,"qty":0.00029556}],"checksum":2472159707,"timestamp":"2024-06-01T17:51:56.035752Z"}]}
{"channel":"book","type":"update","data":[{"symbol":"BTC/USD","bids":[{"price":67621.0,"qty":0.00000000},{"price":67605.3,"qty":1.20000000}],"asks":[],"checksum":3295013860,"timestamp":"2024-06-01T17:51:56.053128Z"}]}
{"channel":"book","type":"update","data":[{"symbol":"BTC/USD","bids":[],"asks":[{"price":67626.9,"qty":1.47870305}],"checksum":1139526498,"timestamp":"2024-06-01T17:51:56.056625Z"}]}
{"channel":"book","type":"update","data":[{"symbol":"BTC/USD","bids":[{"price":67620.7,"qty":1.47883514}],"asks":[],"checksum":3301333014,"timestamp":"2024-06-01T17:51:56.056791Z"}]}
{"channel":"book","type":"update","data":[{"symbol":"BTC/USD","bids":[],"asks":[{"price":67622.2,"qty":0.43947498}],"checksum":2876650219,"timestamp":"2024-06-01T17:51:56.059081Z"}]}
{"channel":"book","type":"update","data":[{"symbol":"BTC/USD","bids":[],"asks":[{"price":67629.1,"qty":0.00000000},{"price":67631.7,"qty":0.22190000}],"checksum":2034770054,"timestamp":"2024-06-01T17:51:56.061072Z"}]}
{"channel":"book","type":"update","data":[{"symbol":"BTC/USD","bids":[{"price":67608.1,"qty":0.00000000},{"price":67605.3,"qty":1.20000000},{"price":67605.4,"qty":0.00113858}],"asks":[],"checksum":4221550806,"timestamp":"2024-06-01T17:51:56.101043Z"}]}
{"channel":"book","type":"update","data":[{"symbol":"BTC/USD","bids":[],"asks":[{"price":67626.2,"qty":0.00000000},{"price":67631.8,"qty":0.69011052},{"price":67628.6,"qty":0.00029556}],"checksum":1567539077,"timestamp":"2024-06-01T17:51:56.101155Z"}]}
{"channel":"book","type":"update","data":[{"symbol":"BTC/USD","bids":[],"asks":[{"price":67626.9,"qty":0.00000000},{"price":67631.8,"qty":0.69011052}],"checksum":549611371,"timestamp":"2024-06-01T17:51:56.122198Z"}]}
{"channel":"book","type":"update","data":[{"symbol":"BTC/USD","bids":[],"asks":[{"price":67628.7,"qty":0.00000000},{"price":67636.0,"qty":0.05912750}],"checksum":2382653320,"timestamp":"2024-06-01T17:51:56.122300Z"}]}
{"channel":"book","type":"update","data":[{"symbol":"BTC/USD","bids":[{"price":67620.7,"qty":0.00000000},{"price":67605.3,"qty":1.20000000}],"asks":[],"checksum":1386640660,"timestamp":"2024-06-01T17:51:56.122361Z"}]}
{"channel":"book","type":"update","data":[{"symbol":"BTC/USD","bids":[],"asks":[{"price":67628.8,"qty":0.06910000}],"checksum":4086115944,"timestamp":"2024-06-01T17:51:56.125006Z"}]}
{"channel":"book","type":"update","data":[{"symbol":"BTC/USD","bids":[],"asks":[{"price":67628.5,"qty":1.47866813}],"checksum":3101183294,"timestamp":"2024-06-01T17:51:56.127610Z"}]}
{"channel":"book","type":"update","data":[{"symbol":"BTC/USD","bids":[{"price":67622.1,"qty":4.98315446}],"asks":[],"checksum":666916714,"timestamp":"2024-06-01T17:51:56.127766Z"}]}
{"channel":"book","type":"update","data":[{"symbol":"BTC/USD","bids":[{"price":67622.1,"qty":3.50434798}],"asks":[],"checksum":3101183294,"timestamp":"2024-06-01T17:51:56.151919Z"}]}
{"channel":"book","type":"update","data":[{"symbol":"BTC/USD","bids":[],"asks":[{"price":67628.5,"qty":0.00000000},{"price":67631.8,"qty":0.69011052}],"checksum":4086115944,"timestamp":"2024-06-01T17:51:56.151931Z"}]}
{"channel":"book","type":"update","data":[{"symbol":"BTC/USD","bids":[],"asks":[{"price":67630.5,"qty":1.47862467}],"checksum":2109461553,"timestamp":"2024-06-01T17:51:56.156072Z"}]}
{"channel":"book","type":"update","data":[{"symbol":"BTC/USD","bids":[{"price":67620.1,"qty":1.47885006}],"asks":[],"checksum":1402895521,"timestamp":"2024-06-01T17:51:56.156126Z"}]}
{"channel":"book","type":"update","data":[{"symbol":"BTC/USD","bids":[{"price":67622.1,"qty":6.59934798}],"asks":[],"checksum":2579474761,"timestamp":"2024-06-01T17:51:56.161236Z"}]}
{"channel":"book","type":"update","data":[{"symbol":"BTC/USD","bids":[],"asks":[{"price":67628.6,"qty":0.00000000},{"price":67631.8,"qty":0.69011052},{"price":67631.5,"qty":0.00029556}],"checksum":3580463587,"timestamp":"2024-06-01T17:51:56.168555Z"}]}
{"channel":"book","type":"update","data":[{"symbol":"BTC/USD","bids":[{"price":67622.1,"qty":6.26184798}],"asks":[],"checksum":521892288,"timestamp":"2024-06-01T17:51:56.180744Z"}]}
{"channel":"book","type":"update","data":[{"symbol":"BTC/USD","bids":[{"price":67622.1,"qty":6.59934798}],"asks":[],"checksum":3580463587,"timestamp":"2024-06-01T17:51:56.242525Z"}]}
{"channel":"book","type":"update","data":[{"symbol":"BTC/USD","bids":[{"price":67622.1,"qty":6.53024798}],"asks":[],"checksum":84793916,"timestamp":"2024-06-01T17:51:56.275571Z"}]}
{"channel":"book","type":"update","data":[{"symbol":"BTC/USD","bids":[{"price":67622.1,"qty":6.19274798}],"asks":[],"checksum":1716989225,"timestamp":"2024-06-01T17:51:56.276297Z"}]}
{"channel":"book","type":"update","data":[{"symbol":"BTC/USD","bids":[],"asks":[{"price":67630.5,"qty":0.00000000},{"price":67631.8,"qty":0.69011052}],"checksum":2568326682,"timestamp":"2024-06-01T17:51:56.280582Z"}]}
{"channel":"book","type":"update","data":[{"symbol":"BTC/USD","bids":[],"asks":[{"price":67628.3,"qty":1.47867113}],"checksum":2472580096,"timestamp":"2024-06-01T17:51:56.296636Z"}]}
{"channel":"book","type":"update","data":[{"symbol":"BTC/USD","bids":[{"price":67621.6,"qty":1.47881691}],"asks":[],"checksum":904680908,"timestamp":"2024-06-01T17:51:56.296714Z"}]}
{"channel":"book","type":"update","data":[{"symbol":"BTC/USD","bids":[],"asks":[{"price":67622.2,"qty":0.03947498}],"checksum":966340042,"timestamp":"2024-06-01T17:51:56.317424Z"}]}
{"channel":"book","type":"update","data":[{"symbol":"BTC/USD","bids":[],"asks":[{"price":67628.8,"qty":0.00000000},{"price":67631.8,"qty":0.69011052},{"price":67627.2,"qty":0.06910000}],"checksum":3626222802,"timestamp":"2024-06-01T17:51:56.320668Z"}]}
{"channel":"book","type":"update","data":[{"symbol":"BTC/USD","bids":[{"price":67621.6,"qty":0.00000000},{"price":67608.0,"qty":0.20730000}],"asks":[],"checksum":1834019451,"timestamp":"2024-06-01T17:51:56.366914Z"}]}
{"channel":"book","type":"update","data":[{"symbol":"BTC/USD","bids":[],"asks":[{"price":67629.0,"qty":1.47865661}],"checksum":1720689843,"timestamp":"2024-06-01T17:51:56.371220Z"}]}
{"channel":"book","type":"update","data":[{"symbol":"BTC/USD","bids":[{"price":67621.8,"qty":1.47881188}],"asks":[],"checksum":3000045394,"timestamp":"2024-06-01T17:51:56.371369Z"}]}
{"channel":"book","type":"update","data":[{"symbol":"BTC/USD","bids":[],"asks":[{"price":67628.3,"qty":0.00000000},{"price":67631.7,"qty":0.22190000}],"checksum":2853961304,"timestamp":"2024-06-01T17:51:56.384885Z"}]}
{"channel":"book","type":"update","data":[{"symbol":"BTC/USD","bids":[{"price":67621.3,"qty":0.06910000}],"asks":[],"checksum":4220613778,"timestamp":"2024-06-01T17:51:56.392423Z"}]}
{"channel":"book","type":"update","data":[{"symbol":"BTC/USD","bids":[],"asks":[{"price":67628.4,"qty":1.47866981}],"checksum":634907244,"timestamp":"2024-06-01T17:51:56.438416Z"}]}
{"channel":"book","type":"update","data":[{"symbol":"BTC/USD","bids":[],"asks":[{"price":67627.2,"qty":0.00000000},{"price":67631.7,"qty":0.22190000},{"price":67628.7,"qty":0.06910000}],"checksum":3888328072,"timestamp":"2024-06-01T17:51:56.595665Z"}]}
{"channel":"book","type":"update","data":[{"symbol":"BTC/USD","bids":[{"price":67621.8,"qty":0.00000000},{"price":67612.0,"qty":0.33750000}],"asks":[],"checksum":3887741587,"timestamp":"2024-06-01T17:51:56.722576Z"}]}
{"channel":"book","type":"update","data":[{"symbol":"BTC/USD","bids":[{"price":67622.0,"qty":1.47880715}],"asks":[],"checksum":1004874137,"timestamp":"2024-06-01T17:51:56.726486Z"}]}
{"channel":"book","type":"update","data":[{"symbol":"BTC/USD","bids":[{"price":67616.0,"qty":0.00113873}],"asks":[],"checksum":2906206663,"timestamp":"2024-06-01T17:51:56.819924Z"}]}
{"channel":"book","type":"update","data":[{"symbol":"BTC/USD","bids":[],"asks":[{"price":67628.7,"qty":0.00000000},{"price":67631.7,"qty":0.22190000}],"checksum":1195249460,"timestamp":"2024-06-01T17:51:56.924933Z"}]}
{"channel":"book","type":"update","data":[{"symbol":"BTC/USD","bids":[],"asks":[{"price":67626.3,"qty":0.00000000},{"price":67631.8,"qty":0.69011052},{"price":67628.3,"qty":0.29580000}],"checksum":2878924326,"timestamp":"2024-06-01T17:51:56.943092Z"}]}
{"channel":"book","type":"update","data":[{"symbol":"BTC/USD","bids":[{"price":67622.1,"qty":6.53024798}],"asks":[],"checksum":4144179771,"timestamp":"2024-06-01T17:51:56.968240Z"}]}
{"channel":"book","type":"update","data":[{"symbol":"BTC/USD","bids":[],"asks":[{"price":67628.4,"qty":0.00000000},{"price":67631.8,"qty":0.69011052}],"checksum":3236726288,"timestamp":"2024-06-01T17:51:57.002795Z"}]}
{"channel":"book","type":"update","data":[{"symbol":"BTC/USD","bids":[{"price":67615.9,"qty":0.00000000},{"price":67613.3,"qty":1.47899752}],"asks":[],"checksum":1560862742,"timestamp":"2024-06-01T17:51:57.002845Z"}]}
{"channel":"book","type":"update","data":[{"symbol":"BTC/USD","bids":[],"asks":[{"price":67629.4,"qty":1.47864769}],"checksum":4067130522,"timestamp":"2024-06-01T17:51:57.007890Z"}]}
{"channel":"book","type":"update","data":[{"symbol":"BTC/USD","bids":[{"price":67618.1,"qty":1.47889305}],"asks":[],"checksum":822505800,"timestamp":"2024-06-01T17:51:57.007966Z"}]}
{"channel":"book","type":"update","data":[{"symbol":"BTC/USD","bids":[{"price":67621.1,"qty":0.00100000}],"asks":[],"checksum":477115285,"timestamp":"2024-06-01T17:51:57.023776Z"}]}
{"channel":"book","type":"update","data":[{"symbol":"BTC/USD","bids":[{"price":67616.0,"qty":0.00000000},{"price":67613.3,"qty":1.47899752}],"asks":[],"checksum":493006999,"timestamp":"2024-06-01T17:51:57.044022Z"}]}
{"channel":"book","type":"update","data":[{"symbol":"BTC/USD","bids":[],"asks":[{"price":67622.3,"qty":0.00000000},{"price":67631.8,"qty":0.69011052}],"checksum":2424931292,"timestamp":"2024-06-01T17:51:57.073928Z"}]}
{"channel":"book","type":"update","data":[{"symbol":"BTC/USD","bids":[],"asks":[{"price":67622.2,"qty":0.00000000},{"price":67633.3,"qty":1.47856339}],"checksum":3600359245,"timestamp":"2024-06-01T17:51:57.078418Z"}]}
{"channel":"book","type":"update","data":[{"symbol":"BTC/USD","bids":[],"asks":[{"price":67628.2,"qty":0.03947498}],"checksum":691447698,"timestamp":"2024-06-01T17:51:57.078478Z"}]}
{"channel":"book","type":"update","data":[{"symbol":"BTC/USD","bids":[{"price":67622.3,"qty":1.33049763}],"asks":[],"checksum":1958151399,"timestamp":"2024-06-01T17:51:57.081154Z"}]}
{"channel":"book","type":"update","data":[{"symbol":"BTC/USD","bids":[{"price":67622.1,"qty":5.19963676}],"asks":[],"checksum":2067034619,"timestamp":"2024-06-01T17:51:57.081308Z"}]}
{"channel":"book","type":"update","data":[{"symbol":"BTC/USD","bids":[{"price":67622.1,"qty":4.61878587}],"asks":[],"checksum":3915116553,"timestamp":"2024-06-01T17:51:57.081561Z"}]}
{"channel":"book","type":"update","data":[{"symbol":"BTC/USD","bids":[{"price":67622.3,"qty":1.91134680}],"asks":[],"checksum":4288086939,"timestamp":"2024-06-01T17:51:57.081648Z"}]}
{"channel":"book","type":"update","data":[{"symbol":"BTC/USD","bids":[],"asks":[{"price":67631.8,"qty":0.11091373}],"checksum":1258500856,"timestamp":"2024-06-01T17:51:57.081693Z"}]}
{"channel":"book","type":"update","data":[{"symbol":"BTC/USD","bids":[],"asks":[{"price":67628.2,"qty":0.11739314}],"checksum":1769073936,"timestamp":"2024-06-01T17:51:57.081762Z"}]}
{"channel":"book","type":"update","data":[{"symbol":"BTC/USD","bids":[{"price":67622.1,"qty":4.58920975},{"price":67622.3,"qty":1.94092284}],"asks":[],"checksum":800365609,"timestamp":"2024-06-01T17:51:57.082632Z"}]}
{"channel":"book","type":"update","data":[{"symbol":"BTC/USD","bids":[{"price":67620.1,"qty":0.00000000},{"price":67613.3,"qty":1.47899752}],"asks":[],"checksum":1143701924,"timestamp":"2024-06-01T17:51:57.083111Z"}]}
{"channel":"book","type":"update","data":[{"symbol":"BTC/USD","bids":[{"price":67621.3,"qty":0.00000000},{"price":67612.0,"qty":0.33750000},{"price":67622.3,"qty":2.01002284}],"asks":[],"checksum":2098877022,"timestamp":"2024-06-01T17:51:57.083461Z"}]}
{"channel":"book","type":"update","data":[{"symbol":"BTC/USD","bids":[{"price":67622.1,"qty":4.28920975},{"price":67622.3,"qty":2.31002284}],"asks":[],"checksum":3288725771,"timestamp":"2024-06-01T17:51:57.084668Z"}]}
{"channel":"book","type":"update","data":[{"symbol":"BTC/USD","bids":[{"price":67622.1,"qty":4.27108975},{"price":67622.3,"qty":2.32814284}],"asks":[],"checksum":2840428980,"timestamp":"2024-06-01T17:51:57.085333Z"}]}
{"channel":"book","type":"update","data":[{"symbol":"BTC/USD","bids":[{"price":67622.1,"qty":3.96008975},{"price":67622.3,"qty":2.63914284}],"asks":[],"checksum":2747721944,"timestamp":"2024-06-01T17:51:57.085839Z"}]}
{"channel":"book","type":"update","data":[{"symbol":"BTC/USD","bids":[],"asks":[{"price":67628.9,"qty":0.06910000}],"checksum":2439870005,"timestamp":"2024-06-01T17:51:57.086474Z"}]}
{"channel":"book","type":"update","data":[{"symbol":"BTC/USD","bids":[{"price":67622.1,"qty":3.95611975},{"price":67622.3,"qty":2.64311284}],"asks":[],"checksum":659320546,"timestamp":"2024-06-01T17:51:57.086712Z"}]}
{"channel":"book","type":"update","data":[{"symbol":"BTC/USD","bids":[{"price":67622.2,"qty":1.47880429}],"asks":[],"checksum":4069576273,"timestamp":"2024-06-01T17:51:57.086743Z"}]}
{"channel":"book","type":"update","data":[{"symbol":"BTC/USD","bids":[{"price":67622.1,"qty":3.61861975}],"asks":[],"checksum":975435818,"timestamp":"2024-06-01T17:51:57.088307Z"}]}
{"channel":"book","type":"update","data":[{"symbol":"BTC/USD","bids":[{"price":67622.1,"qty":3.42886047},{"price":67622.3,"qty":2.83287212}],"asks":[],"checksum":1435649791,"timestamp":"2024-06-01T17:51:57.088448Z"}]}
{"channel":"book","type":"update","data":[{"symbol":"BTC/USD","bids":[{"price":67622.3,"qty":2.76377212}],"asks":[],"checksum":581013898,"timestamp":"2024-06-01T17:51:57.091684Z"}]}
{"channel":"book","type":"update","data":[{"symbol":"BTC/USD","bids":[{"price":67622.1,"qty":3.26193047},{"price":67622.3,"qty":2.93070259}],"asks":[],"checksum":3406310442,"timestamp":"2024-06-01T17:51:57.092105Z"}]}
{"channel":"book","type":"update","data":[{"symbol":"BTC/USD","bids":[{"price":67622.3,"qty":2.99980259}],"asks":[],"checksum":1751821026,"timestamp":"2024-06-01T17:51:57.097189Z"}]}
{"channel":"book","type":"update","data":[{"symbol":"BTC/USD","bids":[{"price":67622.1,"qty":0.16693047}],"asks":[],"checksum":3349984993,"timestamp":"2024-06-01T17:51:57.111454Z"}]}
{"channel":"book","type":"update","data":[{"symbol":"BTC/USD","bids":[],"asks":[{"price":67629.0,"qty":0.00000000},{"price":67631.8,"qty":0.11091373}],"checksum":2116468432,"timestamp":"2024-06-01T17:51:57.119232Z"}]}
{"channel":"book","type":"update","data":[{"symbol":"BTC/USD","bids":[],"asks":[{"price":67628.3,"qty":1.77447283}],"checksum":1945937977,"timestamp":"2024-06-01T17:51:57.122734Z"}]}
{"channel":"book","type":"update","data":[{"symbol":"BTC/USD","bids":[],"asks":[{"price":67631.5,"qty":0.00000000},{"price":67633.2,"qty":0.57919679},{"price":67633.1,"qty":0.00029538}],"checksum":765401549,"timestamp":"2024-06-01T17:51:57.125021Z"}]}
{"channel":"book","type":"update","data":[{"symbol":"BTC/USD","bids":[{"price":67622.3,"qty":4.64580259}],"asks":[],"checksum":472517188,"timestamp":"2024-06-01T17:51:57.174881Z"}]}
{"channel":"book","type":"update","data":[{"symbol":"BTC/USD","bids":[{"price":67622.2,"qty":0.00000000},{"price":67612.0,"qty":0.33750000}],"asks":[],"checksum":803510813,"timestamp":"2024-06-01T17:51:57.192494Z"}]}
{"channel":"book","type":"update","data":[{"symbol":"BTC/USD","bids":[{"price":67622.0,"qty":0.00000000},{"price":67605.4,"qty":0.00113904}],"asks":[],"checksum":4059092674,"timestamp":"2024-06-01T17:51:57.192544Z"}]}
{"channel":"book","type":"update","data":[{"symbol":"BTC/USD","bids":[],"asks":[{"price":67628.3,"qty":0.29580000}],"checksum":2288177478,"timestamp":"2024-06-01T17:51:57.192670Z"}]}
{"channel":"book","type":"update","data":[{"symbol":"BTC/USD","bids":[{"price":67621.4,"qty":1.47882131}],"asks":[],"checksum":1891502126,"timestamp":"2024-06-01T17:51:57.196979Z"}]}
{"channel":"book","type":"update","data":[{"symbol":"BTC/USD","bids":[],"asks":[{"price":67627.8,"qty":1.47868185}],"checksum":79688483,"timestamp":"2024-06-01T17:51:57.197098Z"}]}
{"channel":"book","type":"update","data":[{"symbol":"BTC/USD","bids":[],"asks":[{"price":67627.8,"qty":0.00000000},{"price":67633.1,"qty":0.00029538}],"checksum":1891502126,"timestamp":"2024-06-01T17:51:57.237755Z"}]}
{"channel":"book","type":"update","data":[{"symbol":"BTC/USD","bids":[{"price":67618.1,"qty":0.00000000},{"price":67605.4,"qty":0.00113904}],"asks":[],"checksum":1544609544,"timestamp":"2024-06-01T17:51:57.237907Z"}]}
{"channel":"book","type":"update","data":[{"symbol":"BTC/USD","bids":[],"asks":[{"price":67622.4,"qty":0.40126365}],"checksum":373403138,"timestamp":"2024-06-01T17:51:57.317062Z"}]}
{"channel":"book","type":"update","data":[{"symbol":"BTC/USD","bids":[],"asks":[{"price":67622.4,"qty":0.44073863}],"checksum":3092506649,"timestamp":"2024-06-01T17:51:57.321588Z"}]}
{"channel":"book","type":"update","data":[{"symbol":"BTC/USD","bids":[{"price":67621.8,"qty":1.47881214}],"asks":[],"checksum":3305862236,"timestamp":"2024-06-01T17:51:57.413298Z"}]}
{"channel":"book","type":"update","data":[{"symbol":"BTC/USD","bids":[],"asks":[{"price":67628.1,"qty":1.47867608}],"checksum":550731896,"timestamp":"2024-06-01T17:51:57.413322Z"}]}
{"channel":"book","type":"update","data":[{"symbol":"BTC/USD","bids":[{"price":67616.5,"qty":1.47892764}],"asks":[],"checksum":1629145709,"timestamp":"2024-06-01T17:51:57.413391Z"}]}
{"channel":"book","type":"update","data":[{"symbol":"BTC/USD","bids":[],"asks":[{"price":67628.2,"qty":0.07791816}],"checksum":63428175,"timestamp":"2024-06-01T17:51:57.417077Z"}]}
{"channel":"book","type":"update","data":[{"symbol":"BTC/USD","bids":[],"asks":[{"price":67628.3,"qty":0.00000000},{"price":67633.1,"qty":0.00029538},{"price":67628.0,"qty":0.29580000}],"checksum":2920900417,"timestamp":"2024-06-01T17:51:57.482836Z"}]}
{"channel":"book","type":"update","data":[{"symbol":"BTC/USD","bids":[],"asks":[{"price":67628.1,"qty":0.00000000},{"price":67633.1,"qty":0.00029538}],"checksum":3015537814,"timestamp":"2024-06-01T17:51:57.575126Z"}]}
{"channel":"book","type":"update","data":[{"symbol":"BTC/USD","bids":[{"price":67621.8,"qty":0.00000000},{"price":67612.0,"qty":0.33750000}],"asks":[],"checksum":3853774746,"timestamp":"2024-06-01T17:51:57.575165Z"}]}
{"channel":"book","type":"update","data":[{"symbol":"BTC/USD","bids":[{"price":67621.1,"qty":1.47982825}],"asks":[],"checksum":963517277,"timestamp":"2024-06-01T17:51:57.578630Z"}]}
{"channel":"book","type":"update","data":[{"symbol":"BTC/USD","bids":[],"asks":[{"price":67628.0,"qty":1.77447801}],"checksum":2453532602,"timestamp":"2024-06-01T17:51:57.578847Z"}]}
{"channel":"book","type":"update","data":[{"symbol":"BTC/USD","bids":[],"asks":[{"price":67633.1,"qty":0.00000000},{"price":67633.2,"qty":0.57919679},{"price":67627.9,"qty":0.00029514}],"checksum":882221526,"timestamp":"2024-06-01T17:51:57.814828Z"}]}
{"channel":"book","type":"update","data":[{"symbol":"BTC/USD","bids":[{"price":67616.6,"qty":0.00113918}],"asks":[],"checksum":1900038082,"timestamp":"2024-06-01T17:51:57.814863Z"}]}
{"channel":"book","type":"update","data":[{"symbol":"BTC/USD","bids":[{"price":67621.4,"qty":0.00000000},{"price":67612.0,"qty":0.33750000}],"asks":[],"checksum":131306883,"timestamp":"2024-06-01T17:51:57.862362Z"}]}
{"channel":"book","type":"update","data":[{"symbol":"BTC/USD","bids":[{"price":67621.7,"qty":1.47881387}],"asks":[],"checksum":4140502197,"timestamp":"2024-06-01T17:51:57.866002Z"}]}
{"channel":"book","type":"update","data":[{"symbol":"BTC/USD","bids":[{"price":67616.6,"qty":0.00000000},{"price":67612.0,"qty":0.33750000}],"asks":[],"checksum":3051704692,"timestamp":"2024-06-01T17:51:57.880045Z"}]}
{"channel":"book","type":"update","data":[{"symbol":"BTC/USD","bids":[],"asks":[{"price":67628.0,"qty":0.29580000}],"checksum":1955817019,"timestamp":"2024-06-01T17:51:57.944370Z"}]}
{"channel":"book","type":"update","data":[{"symbol":"BTC/USD","bids":[{"price":67621.7,"qty":0.00000000},{"price":67605.4,"qty":0.00113937}],"asks":[],"checksum":1584653134,"timestamp":"2024-06-01T17:51:57.944496Z"}]}
{"channel":"book","type":"update","data":[{"symbol":"BTC/USD","bids":[],"asks":[{"price":67628.1,"qty":1.47867589}],"checksum":3782277594,"timestamp":"2024-06-01T17:51:57.949171Z"}]}
{"channel":"book","type":"update","data":[{"symbol":"BTC/USD","bids":[{"price":67621.7,"qty":1.47881431}],"asks":[],"checksum":1867447412,"timestamp":"2024-06-01T17:51:57.949269Z"}]}
{"channel":"book","type":"update","data":[{"symbol":"BTC/USD","bids":[],"asks":[{"price":67628.1,"qty":0.00000000},{"price":67631.8,"qty":0.11091373}],"checksum":3161474950,"timestamp":"2024-06-01T17:51:57.953635Z"}]}
{"channel":"book","type":"update","data":[{"symbol":"BTC/USD","bids":[],"asks":[{"price":67627.9,"qty":0.00000000},{"price":67633.2,"qty":0.57919679},{"price":67631.5,"qty":0.00029514}],"checksum":3138339522,"timestamp":"2024-06-01T17:51:58.002688Z"}]}
{"channel":"book","type":"update","data":[{"symbol":"BTC/USD","bids":[{"price":67622.3,"qty":4.64680259}],"asks":[],"checksum":2639388128,"timestamp":"2024-06-01T17:51:58.033568Z"}]}
{"channel":"book","type":"update","data":[{"symbol":"BTC/USD","bids":[],"asks":[{"price":67628.9,"qty":0.00000000},{"price":67633.2,"qty":0.57919679},{"price":67627.6,"qty":0.06910000}],"checksum":3138753512,"timestamp":"2024-06-01T17:51:58.278208Z"}]}
{"channel":"book","type":"update","data":[{"symbol":"BTC/USD","bids":[],"asks":[{"price":67628.0,"qty":0.00000000},{"price":67633.2,"qty":0.57919679},{"price":67627.5,"qty":0.29580000}],"checksum":3260388482,"timestamp":"2024-06-01T17:51:58.281374Z"}]}
{"channel":"book","type":"update","data":[{"symbol":"BTC/USD","bids":[{"price":67621.7,"qty":0.00000000},{"price":67605.4,"qty":0.00113937}],"asks":[],"checksum":3175737086,"timestamp":"2024-06-01T17:51:58.510064Z"}]}
{"channel":"book","type":"update","data":[{"symbol":"BTC/USD","bids":[{"price":67621.9,"qty":1.47880878}],"asks":[],"checksum":3442980283,"timestamp":"2024-06-01T17:51:58.513594Z"}]}
{"channel":"book","type":"update","data":[{"symbol":"BTC/USD","bids":[],"asks":[{"price":67628.5,"qty":1.47866731}],"checksum":3149786135,"timestamp":"2024-06-01T17:51:58.513610Z"}]}
{"channel":"book","type":"update","data":[{"symbol":"BTC/USD","bids":[],"asks":[{"price":67631.5,"qty":0.00000000},{"price":67631.8,"qty":0.11091373}],"checksum":4285123827,"timestamp":"2024-06-01T17:51:58.571953Z"}]}
{"channel":"book","type":"update","data":[{"symbol":"BTC/USD","bids":[{"price":67621.1,"qty":1.48003765}],"asks":[],"checksum":2416311490,"timestamp":"2024-06-01T17:51:58.612255Z"}]}
{"channel":"book","type":"update","data":[{"symbol":"BTC/USD","bids":[],"asks":[{"price":67631.8,"qty":0.69011052}],"checksum":3953908192,"timestamp":"2024-06-01T17:51:58.615598Z"}]}
{"channel":"book","type":"update","data":[{"symbol":"BTC/USD","bids":[{"price":67621.9,"qty":0.00000000},{"price":67605.4,"qty":0.00113937}],"asks":[],"checksum":2468032091,"timestamp":"2024-06-01T17:51:58.864220Z"}]}
{"channel":"book","type":"update","data":[{"symbol":"BTC/USD","bids":[{"price":67622.1,"qty":1.64573550}],"asks":[],"checksum":3919141979,"timestamp":"2024-06-01T17:51:58.868155Z"}]}
{"channel":"book","type":"update","data":[{"symbol":"BTC/USD","bids":[{"price":67605.4,"qty":0.00000000},{"price":67605.3,"qty":1.20000000},{"price":67616.6,"qty":0.00113918}],"asks":[],"checksum":942873363,"timestamp":"2024-06-01T17:51:58.872757Z"}]}
{"channel":"book","type":"update","data":[{"symbol":"BTC/USD","bids":[{"price":67614.6,"qty":0.05912737}],"asks":[],"checksum":3739870974,"timestamp":"2024-06-01T17:51:59.107755Z"}]}
{"channel":"book","type":"update","data":[{"symbol":"BTC/USD","bids":[],"asks":[{"price":67627.6,"qty":0.00000000},{"price":67633.1,"qty":0.00029514}],"checksum":3013227060,"timestamp":"2024-06-01T17:51:59.171262Z"}]}
{"channel":"book","type":"update","data":[{"symbol":"BTC/USD","bids":[{"price":67621.1,"qty":0.00120940}],"asks":[],"checksum":1423783551,"timestamp":"2024-06-01T17:51:59.180115Z"}]}
{"channel":"book","type":"update","data":[{"symbol":"BTC/USD","bids":[],"asks":[{"price":67628.5,"qty":0.00000000},{"price":67633.3,"qty":1.47856339}],"checksum":263222311,"timestamp":"2024-06-01T17:51:59.180146Z"}]}
{"channel":"book","type":"update","data":[{"symbol":"BTC/USD","bids":[{"price":67622.1,"qty":0.16693047}],"asks":[],"checksum":318903131,"timestamp":"2024-06-01T17:51:59.180199Z"}]}
{"channel":"book","type":"update","data":[{"symbol":"BTC/USD","bids":[{"price":67622.3,"qty":6.12560470}],"asks":[],"checksum":3322225046,"timestamp":"2024-06-01T17:51:59.184432Z"}]}
{"channel":"book","type":"update","data":[{"symbol":"BTC/USD","bids":[],"asks":[{"price":67630.8,"qty":1.47861687}],"checksum":673374811,"timestamp":"2024-06-01T17:51:59.184473Z"}]}
{"channel":"book","type":"update","data":[{"symbol":"BTC/USD","bids":[],"asks":[{"price":67627.5,"qty":0.00000000},{"price":67633.3,"qty":1.47856339}],"checksum":2531507556,"timestamp":"2024-06-01T17:51:59.184692Z"}]}
{"channel":"book","type":"update","data":[{"symbol":"BTC/USD","bids":[],"asks":[{"price":67630.8,"qty":0.00000000},{"price":67636.1,"qty":0.05912733}],"checksum":138187524,"timestamp":"2024-06-01T17:51:59.188388Z"}]}
{"channel":"book","type":"update","data":[{"symbol":"BTC/USD","bids":[],"asks":[{"price":67628.3,"qty":1.47867278}],"checksum":1049880135,"timestamp":"2024-06-01T17:51:59.191579Z"}]}
{"channel":"book","type":"update","data":[{"symbol":"BTC/USD","bids":[],"asks":[{"price":67629.7,"qty":0.29580000}],"checksum":1406614608,"timestamp":"2024-06-01T17:51:59.195261Z"}]}
{"channel":"book","type":"update","data":[{"symbol":"BTC/USD","bids":[],"asks":[{"price":67628.3,"qty":0.00000000},{"price":67633.3,"qty":1.47856339}],"checksum":3677283596,"timestamp":"2024-06-01T17:51:59.195287Z"}]}
{"channel":"book","type":"update","data":[{"symbol":"BTC/USD","bids":[],"asks":[{"price":67631.7,"qty":0.00000000},{"price":67636.1,"qty":0.05912733}],"checksum":2093206991,"timestamp":"2024-06-01T17:51:59.226636Z"}]}
{"channel":"book","type":"update","data":[{"symbol":"BTC/USD","bids":[],"asks":[{"price":67629.4,"qty":0.00000000},{"price":67637.2,"qty":0.00010000}],"checksum":634057016,"timestamp":"2024-06-01T17:51:59.231031Z"}]}
{"channel":"book","type":"update","data":[{"symbol":"BTC/USD","bids":[{"price":67616.5,"qty":0.00000000},{"price":67612.0,"qty":0.33750000}],"asks":[],"checksum":255422834,"timestamp":"2024-06-01T17:51:59.231123Z"}]}
{"channel":"book","type":"update","data":[{"symbol":"BTC/USD","bids":[],"asks":[{"price":67629.7,"qty":0.00000000},{"price":67638.2,"qty":0.07066000}],"checksum":2032381527,"timestamp":"2024-06-01T17:51:59.231911Z"}]}
{"channel":"book","type":"update","data":[{"symbol":"BTC/USD","bids":[],"asks":[{"price":67635.1,"qty":1.47852273}],"checksum":764768711,"timestamp":"2024-06-01T17:51:59.237827Z"}]}
{"channel":"book","type":"update","data":[{"symbol":"BTC/USD","bids":[{"price":67621.7,"qty":1.47881450}],"asks":[],"checksum":2101688068,"timestamp":"2024-06-01T17:51:59.237840Z"}]}
{"channel":"book","type":"update","data":[{"symbol":"BTC/USD","bids":[{"price":67619.1,"qty":1.47887110}],"asks":[],"checksum":541198976,"timestamp":"2024-06-01T17:51:59.238068Z"}]}
{"channel":"book","type":"update","data":[{"symbol":"BTC/USD","bids":[{"price":67622.3,"qty":6.46310470}],"asks":[],"checksum":2468492487,"timestamp":"2024-06-01T17:51:59.243424Z"}]}
{"channel":"book","type":"update","data":[{"symbol":"BTC/USD","bids":[],"asks":[{"price":67633.3,"qty":0.00000000},{"price":67638.2,"qty":0.07066000}],"checksum":438609079,"timestamp":"2024-06-01T17:51:59.250123Z"}]}
{"channel":"book","type":"update","data":[{"symbol":"BTC/USD","bids":[],"asks":[{"price":67630.8,"qty":1.47861791}],"checksum":4272135381,"timestamp":"2024-06-01T17:51:59.250274Z"}]}
{"channel":"book","type":"update","data":[{"symbol":"BTC/USD","bids":[],"asks":[{"price":67630.8,"qty":0.00000000},{"price":67638.2,"qty":0.07066000}],"checksum":438609079,"timestamp":"2024-06-01T17:51:59.256657Z"}]}
{"channel":"book","type":"update","data":[{"symbol":"BTC/USD","bids":[],"asks":[{"price":67636.1,"qty":0.00000000},{"price":67638.9,"qty":1.47843946}],"checksum":2057582668,"timestamp":"2024-06-01T17:51:59.273448Z"}]}
{"channel":"book","type":"update","data":[{"symbol":"BTC/USD","bids":[],"asks":[{"price":67630.4,"qty":0.06910000}],"checksum":1865273678,"timestamp":"2024-06-01T17:51:59.279069Z"}]}
{"channel":"book","type":"update","data":[{"symbol":"BTC/USD","bids":[],"asks":[{"price":67631.6,"qty":0.00000000},{"price":67638.9,"qty":1.47843946}],"checksum":156297920,"timestamp":"2024-06-01T17:51:59.281937Z"}]}
{"channel":"book","type":"update","data":[{"symbol":"BTC/USD","bids":[],"asks":[{"price":67629.8,"qty":1.47863968}],"checksum":2422960374,"timestamp":"2024-06-01T17:51:59.329144Z"}]}
{"channel":"book","type":"update","data":[{"symbol":"BTC/USD","bids":[{"price":67614.1,"qty":0.92017687}],"asks":[],"checksum":2701244392,"timestamp":"2024-06-01T17:51:59.389718Z"}]}
{"channel":"book","type":"update","data":[{"symbol":"BTC/USD","bids":[{"price":67616.3,"qty":0.12239800},{"price":67621.9,"qty":0.00010000}],"asks":[],"checksum":157475815,"timestamp":"2024-06-01T17:51:59.391109Z"}]}
{"channel":"book","type":"update","data":[{"symbol":"BTC/USD","bids":[],"asks":[{"price":67629.8,"qty":0.00000000},{"price":67638.9,"qty":1.47843946}],"checksum":2421782993,"timestamp":"2024-06-01T17:51:59.432980Z"}]}
{"channel":"book","type":"update","data":[{"symbol":"BTC/USD","bids":[],"asks":[{"price":67630.4,"qty":1.54772711}],"checksum":2625414717,"timestamp":"2024-06-01T17:51:59.436590Z"}]}
{"channel":"book","type":"update","data":[{"symbol":"BTC/USD","bids":[{"price":67616.6,"qty":0.00000000},{"price":67614.0,"qty":0.36658577},{"price":67614.2,"qty":0.00113905}],"asks":[],"checksum":1216190638,"timestamp":"2024-06-01T17:51:59.439541Z"}]}
{"channel":"book","type":"update","data":[{"symbol":"BTC/USD","bids":[],"asks":[{"price":67630.4,"qty":0.06910000}],"checksum":1146636098,"timestamp":"2024-06-01T17:51:59.458202Z"}]}
{"channel":"book","type":"update","data":[{"symbol":"BTC/USD","bids":[],"asks":[{"price":67632.4,"qty":1.47858214}],"checksum":3455389359,"timestamp":"2024-06-01T17:51:59.462049Z"}]}
{"channel":"book","type":"update","data":[{"symbol":"BTC/USD","bids":[],"asks":[{"price":67633.1,"qty":0.00000000},{"price":67638.9,"qty":1.47843946},{"price":67635.0,"qty":0.00029514}],"checksum":2303841232,"timestamp":"2024-06-01T17:51:59.516096Z"}]}
{"channel":"book","type":"update","data":[{"symbol":"BTC/USD","bids":[],"asks":[{"price":67637.5,"qty":0.05912611}],"checksum":4015901662,"timestamp":"2024-06-01T17:51:59.554759Z"}]}
{"channel":"book","type":"update","data":[{"symbol":"BTC/USD","bids":[{"price":67614.1,"qty":0.00028394}],"asks":[],"checksum":1867282097,"timestamp":"2024-06-01T17:51:59.614719Z"}]}
{"channel":"book","type":"update","data":[{"symbol":"BTC/USD","bids":[],"asks":[{"price":67630.4,"qty":1.54772550}],"checksum":1971283177,"timestamp":"2024-06-01T17:52:00.008137Z"}]}
{"channel":"book","type":"update","data":[{"symbol":"BTC/USD","bids":[],"asks":[{"price":67632.4,"qty":0.00000000},{"price":67638.2,"qty":0.07066000}],"checksum":2086218319,"timestamp":"2024-06-01T17:52:00.113398Z"}]}
{"channel":"book","type":"update","data":[{"symbol":"BTC/USD","bids":[],"asks":[{"price":67631.8,"qty":0.11091373},{"price":67637.1,"qty":0.57919679}],"checksum":282997951,"timestamp":"2024-06-01T17:52:00.116659Z"}]}
{"channel":"book","type":"update","data":[{"symbol":"BTC/USD","bids":[],"asks":[{"price":67630.0,"qty":1.47863509}],"checksum":1554217929,"timestamp":"2024-06-01T17:52:00.117452Z"}]}
{"channel":"book","type":"update","data":[{"symbol":"BTC/USD","bids":[],"asks":[{"price":67630.0,"qty":0.00000000},{"price":67637.5,"qty":0.05912611}],"checksum":282997951,"timestamp":"2024-06-01T17:52:00.152013Z"}]}
{"channel":"book","type":"update","data":[{"symbol":"BTC/USD","bids":[],"asks":[{"price":67632.0,"qty":0.29580000}],"checksum":1756155326,"timestamp":"2024-06-01T17:52:00.200036Z"}]}
{"channel":"book","type":"update","data":[{"symbol":"BTC/USD","bids":[],"asks":[{"price":67630.4,"qty":1.47862550},{"price":67632.0,"qty":0.36490000}],"checksum":1687319535,"timestamp":"2024-06-01T17:52:00.340735Z"}]}
{"channel":"book","type":"update","data":[{"symbol":"BTC/USD","bids":[],"asks":[{"price":67632.0,"qty":0.29580000},{"price":67630.8,"qty":0.06910000}],"checksum":3102421772,"timestamp":"2024-06-01T17:52:00.360715Z"}]}
{"channel":"book","type":"update","data":[{"symbol":"BTC/USD","bids":[{"price":67622.3,"qty":6.12560470}],"asks":[],"checksum":101464159,"timestamp":"2024-06-01T17:52:00.394337Z"}]}
{"channel":"book","type":"update","data":[{"symbol":"BTC/USD","bids":[{"price":67622.3,"qty":6.46310470}],"asks":[],"checksum":3102421772,"timestamp":"2024-06-01T17:52:00.398892Z"}]}
{"channel":"book","type":"update","data":[{"symbol":"BTC/USD","bids":[],"asks":[{"price":67630.1,"qty":1.47863174}],"checksum":1267079848,"timestamp":"2024-06-01T17:52:00.444784Z"}]}
{"channel":"book","type":"update","data":[{"symbol":"BTC/USD","bids":[],"asks":[{"price":67630.1,"qty":0.00000000},{"price":67637.1,"qty":0.57919679}],"checksum":3102421772,"timestamp":"2024-06-01T17:52:00.448213Z"}]}
{"channel":"book","type":"update","data":[{"symbol":"BTC/USD","bids":[{"price":67614.2,"qty":0.00000000},{"price":67614.0,"qty":0.36658577},{"price":67619.2,"qty":0.00113880}],"asks":[],"checksum":1555738767,"timestamp":"2024-06-01T17:52:00.520331Z"}]}
{"channel":"book","type":"update","data":[{"symbol":"BTC/USD","bids":[],"asks":[{"price":67630.4,"qty":0.00000000},{"price":67637.2,"qty":0.00010000}],"checksum":2576811619,"timestamp":"2024-06-01T17:52:00.632833Z"}]}
{"channel":"book","type":"update","data":[{"symbol":"BTC/USD","bids":[],"asks":[{"price":67630.0,"qty":1.47863381}],"checksum":1193274838,"timestamp":"2024-06-01T17:52:00.636408Z"}]}
{"channel":"book","type":"update","data":[{"symbol":"BTC/USD","bids":[],"asks":[{"price":67632.0,"qty":0.00000000},{"price":67637.2,"qty":0.00010000},{"price":67631.7,"qty":0.29580000}],"checksum":3124079203,"timestamp":"2024-06-01T17:52:00.754104Z"}]}
{"channel":"book","type":"update","data":[{"symbol":"BTC/USD","bids":[],"asks":[{"price":67630.0,"qty":0.00000000},{"price":67637.2,"qty":0.00010000}],"checksum":3097280989,"timestamp":"2024-06-01T17:52:00.784858Z"}]}
{"channel":"book","type":"update","data":[{"symbol":"BTC/USD","bids":[],"asks":[{"price":67629.7,"qty":1.47864046}],"checksum":621135619,"timestamp":"2024-06-01T17:52:00.788360Z"}]}
{"channel":"book","type":"update","data":[{"symbol":"BTC/USD","bids":[{"price":67622.1,"qty":0.00000000},{"price":67614.0,"qty":0.36658577},{"price":67622.3,"qty":6.29617423}],"asks":[],"checksum":1899878470,"timestamp":"2024-06-01T17:52:00.926664Z"}]}
{"channel":"book","type":"update","data":[{"symbol":"BTC/USD","bids":[{"price":67622.3,"qty":6.46310423}],"asks":[],"checksum":2874699285,"timestamp":"2024-06-01T17:52:00.926760Z"}]}
{"channel":"book","type":"update","data":[{"symbol":"BTC/USD","bids":[],"asks":[{"price":67631.9,"qty":0.00010000}],"checksum":4239626519,"timestamp":"2024-06-01T17:52:01.065102Z"}]}
{"channel":"book","type":"update","data":[{"symbol":"BTC/USD","bids":[],"asks":[{"price":67629.7,"qty":0.00000000},{"price":67637.1,"qty":0.57919679}],"checksum":255812498,"timestamp":"2024-06-01T17:52:01.176967Z"}]}
{"channel":"book","type":"update","data":[{"symbol":"BTC/USD","bids":[],"asks":[{"price":67629.4,"qty":1.47864851}],"checksum":2391671287,"timestamp":"2024-06-01T17:52:01.180293Z"}]}
{"channel":"book","type":"update","data":[{"symbol":"BTC/USD","bids":[{"price":67622.3,"qty":6.12560423}],"asks":[],"checksum":812190372,"timestamp":"2024-06-01T17:52:01.185036Z"}]}
{"channel":"book","type":"update","data":[{"symbol":"BTC/USD","bids":[{"price":67619.2,"qty":0.00000000},{"price":67613.3,"qty":1.47899752},{"price":67614.1,"qty":0.00142283}],"asks":[],"checksum":59854673,"timestamp":"2024-06-01T17:52:01.188465Z"}]}
{"channel":"book","type":"update","data":[{"symbol":"BTC/USD","bids":[],"asks":[{"price":67629.4,"qty":0.00000000},{"price":67637.1,"qty":0.57919679}],"checksum":593197921,"timestamp":"2024-06-01T17:52:01.190466Z"}]}
{"channel":"book","type":"update","data":[{"symbol":"BTC/USD","bids":[{"price":67622.3,"qty":6.46310423}],"asks":[],"checksum":3411070828,"timestamp":"2024-06-01T17:52:01.282013Z"}]}
{"channel":"book","type":"update","data":[{"symbol":"BTC/USD","bids":[],"asks":[{"price":67630.1,"qty":1.47863349}],"checksum":144819925,"timestamp":"2024-06-01T17:52:01.297792Z"}]}
{"channel":"book","type":"update","data":[{"symbol":"BTC/USD","bids":[],"asks":[{"price":67630.1,"qty":0.00000000},{"price":67637.1,"qty":0.57919679}],"checksum":3411070828,"timestamp":"2024-06-01T17:52:01.397801Z"}]}
{"channel":"book","type":"update","data":[{"symbol":"BTC/USD","bids":[],"asks":[{"price":67629.7,"qty":1.47864222}],"checksum":1163458947,"timestamp":"2024-06-01T17:52:01.402026Z"}]}
{"channel":"book","type":"update","data":[{"symbol":"BTC/USD","bids":[],"asks":[{"price":67630.8,"qty":0.00000000},{"price":67637.1,"qty":0.57919679},{"price":67632.3,"qty":0.06910000}],"checksum":574649884,"timestamp":"2024-06-01T17:52:01.470524Z"}]}
{"channel":"book","type":"update","data":[{"symbol":"BTC/USD","bids":[],"asks":[{"price":67629.7,"qty":0.00000000},{"price":67637.1,"qty":0.57919679}],"checksum":2363768975,"timestamp":"2024-06-01T17:52:01.471406Z"}]}
{"channel":"book","type":"update","data":[{"symbol":"BTC/USD","bids":[],"asks":[{"price":67630.8,"qty":1.47861813}],"checksum":2522806753,"timestamp":"2024-06-01T17:52:01.475354Z"}]}
{"channel":"book","type":"update","data":[{"symbol":"BTC/USD","bids":[],"asks":[{"price":67632.1,"qty":1.47858848}],"checksum":1840146363,"timestamp":"2024-06-01T17:52:01.475395Z"}]}
