{"channel":"book","type":"snapshot","data":[{"symbol":"BTC/EUR","bids":[{"price":62360.0,"qty":5.03002750},{"price":62356.9,"qty":0.00853700},{"price":62356.4,"qty":1.47858474},{"price":62353.8,"qty":0.03158383},{"price":62351.9,"qty":0.12651341},{"price":62350.3,"qty":0.06121200},{"price":62346.8,"qty":0.05914552},{"price":62341.0,"qty":0.41750723},{"price":62337.4,"qty":6.68689519},{"price":62337.2,"qty":1.10922789}],"asks":[{"price":62360.1,"qty":0.02433539},{"price":62363.2,"qty":0.04000000},{"price":62368.9,"qty":0.00853600},{"price":62369.7,"qty":0.52796633},{"price":62372.8,"qty":0.03947498},{"price":62373.5,"qty":1.47818136},{"price":62374.0,"qty":1.47817052},{"price":62375.1,"qty":0.00050835},{"price":62376.3,"qty":0.00045401},{"price":62380.2,"qty":0.29575561}],"checksum":3542774460}]}
{"channel":"book","type":"update","data":[{"symbol":"BTC/EUR","bids":[],"asks":[{"price":62374.2,"qty":0.29575561}],"checksum":3801761967,"timestamp":"2024-06-01T17:51:34.071045Z"}]}
{"channel":"book","type":"update","data":[{"symbol":"BTC/EUR","bids":[{"price":62341.1,"qty":1.10908354}],"asks":[],"checksum":2509025762,"timestamp":"2024-06-01T17:51:34.072341Z"}]}
{"channel":"book","type":"update","data":[{"symbol":"BTC/EUR","bids":[{"price":62353.8,"qty":0.00000000},{"price":62337.2,"qty":1.10922789}],"asks":[],"checksum":3534681436,"timestamp":"2024-06-01T17:51:34.172311Z"}]}
{"channel":"book","type":"update","data":[{"symbol":"BTC/EUR","bids":[],"asks":[{"price":62376.3,"qty":0.00000000},{"price":62381.5,"qty":0.29575561},{"price":62373.4,"qty":0.00045401}],"checksum":1724889693,"timestamp":"2024-06-01T17:51:34.203901Z"}]}
{"channel":"book","type":"update","data":[{"symbol":"BTC/EUR","bids":[{"price":62347.7,"qty":0.03158383}],"asks":[],"checksum":451896671,"timestamp":"2024-06-01T17:51:34.275129Z"}]}
{"channel":"book","type":"update","data":[{"symbol":"BTC/EUR","bids":[{"price":62341.0,"qty":0.00000000},{"price":62337.2,"qty":1.10922789}],"asks":[],"checksum":2053655489,"timestamp":"2024-06-01T17:51:34.330978Z"}]}
{"channel":"book","type":"update","data":[{"symbol":"BTC/EUR","bids":[{"price":62360.0,"qty":5.44833332}],"asks":[],"checksum":4199061666,"timestamp":"2024-06-01T17:51:34.335872Z"}]}
{"channel":"book","type":"update","data":[{"symbol":"BTC/EUR","bids":[],"asks":[{"price":62374.2,"qty":0.00000000},{"price":62381.5,"qty":0.29575561}],"checksum":597874684,"timestamp":"2024-06-01T17:51:34.336711Z"}]}
{"channel":"book","type":"update","data":[{"symbol":"BTC/EUR","bids":[{"price":62356.4,"qty":0.00000000},{"price":62331.2,"qty":0.03947498}],"asks":[],"checksum":854957777,"timestamp":"2024-06-01T17:51:34.336761Z"}]}
{"channel":"book","type":"update","data":[{"symbol":"BTC/EUR","bids":[],"asks":[{"price":62373.5,"qty":0.00000000},{"price":62382.5,"qty":1.47796824}],"checksum":2544712723,"timestamp":"2024-06-01T17:51:34.336780Z"}]}
{"channel":"book","type":"update","data":[{"symbol":"BTC/EUR","bids":[],"asks":[{"price":62374.0,"qty":0.00000000},{"price":62383.0,"qty":0.54621000}],"checksum":1762734958,"timestamp":"2024-06-01T17:51:34.336821Z"}]}
{"channel":"book","type":"update","data":[{"symbol":"BTC/EUR","bids":[],"asks":[{"price":62377.0,"qty":1.47809827}],"checksum":2332282955,"timestamp":"2024-06-01T17:51:34.346968Z"}]}
{"channel":"book","type":"update","data":[{"symbol":"BTC/EUR","bids":[],"asks":[{"price":62379.2,"qty":1.47804814}],"checksum":4063256234,"timestamp":"2024-06-01T17:51:34.347026Z"}]}
{"channel":"book","type":"update","data":[{"symbol":"BTC/EUR","bids":[],"asks":[{"price":62381.5,"qty":0.00000000},{"price":62382.5,"qty":1.47796824}],"checksum":2674678717,"timestamp":"2024-06-01T17:51:34.353735Z"}]}
{"channel":"book","type":"update","data":[{"symbol":"BTC/EUR","bids":[{"price":62360.0,"qty":5.32350573}],"asks":[],"checksum":1243139703,"timestamp":"2024-06-01T17:51:34.353844Z"}]}
{"channel":"book","type":"update","data":[{"symbol":"BTC/EUR","bids":[],"asks":[{"price":62377.0,"qty":0.00000000},{"price":62383.0,"qty":0.54621000}],"checksum":98165273,"timestamp":"2024-06-01T17:51:34.393049Z"}]}
{"channel":"book","type":"update","data":[{"symbol":"BTC/EUR","bids":[{"price":62347.7,"qty":0.00000000},{"price":62328.3,"qty":2.21887673}],"asks":[],"checksum":1243281565,"timestamp":"2024-06-01T17:51:34.404572Z"}]}
{"channel":"book","type":"update","data":[{"symbol":"BTC/EUR","bids":[],"asks":[{"price":62373.4,"qty":0.00000000},{"price":62386.4,"qty":0.22190000},{"price":62376.9,"qty":0.00045402}],"checksum":4097627167,"timestamp":"2024-06-01T17:51:34.412682Z"}]}
{"channel":"book","type":"update","data":[{"symbol":"BTC/EUR","bids":[{"price":62347.9,"qty":0.03158383}],"asks":[],"checksum":1788516362,"timestamp":"2024-06-01T17:51:34.445602Z"}]}
{"channel":"book","type":"update","data":[{"symbol":"BTC/EUR","bids":[],"asks":[{"price":62379.2,"qty":0.00000000},{"price":62386.4,"qty":0.22190000}],"checksum":1943329284,"timestamp":"2024-06-01T17:51:34.453293Z"}]}
{"channel":"book","type":"update","data":[{"symbol":"BTC/EUR","bids":[],"asks":[{"price":62360.1,"qty":0.00000000},{"price":62387.1,"qty":1.47785945}],"checksum":2099758536,"timestamp":"2024-06-01T17:51:34.454407Z"}]}
{"channel":"book","type":"update","data":[{"symbol":"BTC/EUR","bids":[{"price":62363.1,"qty":0.88709098}],"asks":[],"checksum":2500044793,"timestamp":"2024-06-01T17:51:34.457881Z"}]}
{"channel":"book","type":"update","data":[{"symbol":"BTC/EUR","bids":[{"price":62360.0,"qty":4.43639156}],"asks":[],"checksum":3604902805,"timestamp":"2024-06-01T17:51:34.460830Z"}]}
{"channel":"book","type":"update","data":[{"symbol":"BTC/EUR","bids":[{"price":62360.0,"qty":2.95789054}],"asks":[],"checksum":1612534902,"timestamp":"2024-06-01T17:51:34.462927Z"}]}
{"channel":"book","type":"update","data":[{"symbol":"BTC/EUR","bids":[{"price":62360.0,"qty":1.47938952}],"asks":[],"checksum":3900204981,"timestamp":"2024-06-01T17:51:34.463007Z"}]}
{"channel":"book","type":"update","data":[{"symbol":"BTC/EUR","bids":[],"asks":[{"price":62376.9,"qty":0.00000000},{"price":62388.0,"qty":0.12038502},{"price":62379.1,"qty":0.00045402}],"checksum":2969978896,"timestamp":"2024-06-01T17:51:34.486481Z"}]}
{"channel":"book","type":"update","data":[{"symbol":"BTC/EUR","bids":[],"asks":[{"price":62368.9,"qty":0.00000000},{"price":62388.0,"qty":0.12038502},{"price":62381.0,"qty":0.00853500}],"checksum":1244199700,"timestamp":"2024-06-01T17:51:34.489712Z"}]}
{"channel":"book","type":"update","data":[{"symbol":"BTC/EUR","bids":[{"price":62363.1,"qty":0.93152172}],"asks":[],"checksum":3099479443,"timestamp":"2024-06-01T17:51:34.494919Z"}]}
{"channel":"book","type":"update","data":[{"symbol":"BTC/EUR","bids":[{"price":62360.0,"qty":1.07938952}],"asks":[],"checksum":1902427607,"timestamp":"2024-06-01T17:51:34.509527Z"}]}
{"channel":"book","type":"update","data":[{"symbol":"BTC/EUR","bids":[],"asks":[{"price":62379.1,"qty":0.00000000},{"price":62388.0,"qty":0.12038502},{"price":62382.4,"qty":0.00045402}],"checksum":4176886216,"timestamp":"2024-06-01T17:51:34.540734Z"}]}
{"channel":"book","type":"update","data":[{"symbol":"BTC/EUR","bids":[{"price":62360.0,"qty":1.03495878}],"asks":[],"checksum":2161492009,"timestamp":"2024-06-01T17:51:34.545726Z"}]}
{"channel":"book","type":"update","data":[{"symbol":"BTC/EUR","bids":[],"asks":[{"price":62363.8,"qty":0.06282000}],"checksum":920098182,"timestamp":"2024-06-01T17:51:34.582887Z"}]}
{"channel":"book","type":"update","data":[{"symbol":"BTC/EUR","bids":[{"price":62360.0,"qty":1.02497722}],"asks":[],"checksum":224488028,"timestamp":"2024-06-01T17:51:34.627155Z"}]}
{"channel":"book","type":"update","data":[{"symbol":"BTC/EUR","bids":[],"asks":[{"price":62363.8,"qty":0.00000000},{"price":62387.1,"qty":1.47785945}],"checksum":3143843827,"timestamp":"2024-06-01T17:51:34.632202Z"}]}
{"channel":"book","type":"update","data":[{"symbol":"BTC/EUR","bids":[{"price":62360.0,"qty":1.01497722}],"asks":[],"checksum":2472751046,"timestamp":"2024-06-01T17:51:34.632843Z"}]}
{"channel":"book","type":"update","data":[{"symbol":"BTC/EUR","bids":[{"price":62360.1,"qty":0.22000000}],"asks":[],"checksum":3640973328,"timestamp":"2024-06-01T17:51:34.661943Z"}]}
{"channel":"book","type":"update","data":[{"symbol":"BTC/EUR","bids":[{"price":62360.0,"qty":0.84497722}],"asks":[],"checksum":1437360889,"timestamp":"2024-06-01T17:51:34.664665Z"}]}
{"channel":"book","type":"update","data":[{"symbol":"BTC/EUR","bids":[{"price":62363.1,"qty":1.10152172}],"asks":[],"checksum":9141625,"timestamp":"2024-06-01T17:51:34.664918Z"}]}
{"channel":"book","type":"update","data":[{"symbol":"BTC/EUR","bids":[{"price":62360.0,"qty":0.78497722}],"asks":[],"checksum":2104903688,"timestamp":"2024-06-01T17:51:34.667229Z"}]}
{"channel":"book","type":"update","data":[{"symbol":"BTC/EUR","bids":[{"price":62360.0,"qty":0.68497722}],"asks":[],"checksum":1974312387,"timestamp":"2024-06-01T17:51:34.708963Z"}]}
{"channel":"book","type":"update","data":[{"symbol":"BTC/EUR","bids":[{"price":62360.0,"qty":0.67039248}],"asks":[],"checksum":2431260612,"timestamp":"2024-06-01T17:51:34.712303Z"}]}
{"channel":"book","type":"update","data":[{"symbol":"BTC/EUR","bids":[{"price":62338.3,"qty":0.03947498}],"asks":[],"checksum":375730158,"timestamp":"2024-06-01T17:51:34.713422Z"}]}
{"channel":"book","type":"update","data":[{"symbol":"BTC/EUR","bids":[],"asks":[{"price":62387.1,"qty":0.00000000},{"price":62388.0,"qty":0.12038502}],"checksum":3003959627,"timestamp":"2024-06-01T17:51:34.715557Z"}]}
{"channel":"book","type":"update","data":[{"symbol":"BTC/EUR","bids":[],"asks":[{"price":62379.5,"qty":1.47803914}],"checksum":3424428733,"timestamp":"2024-06-01T17:51:34.720298Z"}]}
{"channel":"book","type":"update","data":[{"symbol":"BTC/EUR","bids":[],"asks":[{"price":62382.3,"qty":1.47797385}],"checksum":1572833911,"timestamp":"2024-06-01T17:51:34.720321Z"}]}
{"channel":"book","type":"update","data":[{"symbol":"BTC/EUR","bids":[],"asks":[{"price":62382.3,"qty":0.00000000},{"price":62386.4,"qty":0.22190000}],"checksum":3424428733,"timestamp":"2024-06-01T17:51:34.729212Z"}]}
{"channel":"book","type":"update","data":[{"symbol":"BTC/EUR","bids":[],"asks":[{"price":62364.6,"qty":0.06473000}],"checksum":4131400004,"timestamp":"2024-06-01T17:51:34.739194Z"}]}
{"channel":"book","type":"update","data":[{"symbol":"BTC/EUR","bids":[{"price":62363.1,"qty":1.11152172}],"asks":[],"checksum":3317685367,"timestamp":"2024-06-01T17:51:34.796920Z"}]}
{"channel":"book","type":"update","data":[{"symbol":"BTC/EUR","bids":[{"price":62347.9,"qty":0.00000000},{"price":62337.4,"qty":6.68689519}],"asks":[],"checksum":3270342848,"timestamp":"2024-06-01T17:51:34.798673Z"}]}
{"channel":"book","type":"update","data":[{"symbol":"BTC/EUR","bids":[{"price":62363.1,"qty":2.58994925}],"asks":[],"checksum":3029356176,"timestamp":"2024-06-01T17:51:34.801357Z"}]}
{"channel":"book","type":"update","data":[{"symbol":"BTC/EUR","bids":[{"price":62357.3,"qty":0.03158383}],"asks":[],"checksum":533571635,"timestamp":"2024-06-01T17:51:34.816252Z"}]}
{"channel":"book","type":"update","data":[{"symbol":"BTC/EUR","bids":[{"price":62356.9,"qty":0.00000000},{"price":62337.4,"qty":6.68689519},{"price":62363.1,"qty":2.59848625}],"asks":[],"checksum":3045345275,"timestamp":"2024-06-01T17:51:34.824823Z"}]}
{"channel":"book","type":"update","data":[{"symbol":"BTC/EUR","bids":[{"price":62363.1,"qty":2.69848625}],"asks":[],"checksum":841730507,"timestamp":"2024-06-01T17:51:34.869885Z"}]}
{"channel":"book","type":"update","data":[{"symbol":"BTC/EUR","bids":[{"price":62363.1,"qty":2.71307099}],"asks":[],"checksum":984157241,"timestamp":"2024-06-01T17:51:34.879600Z"}]}
{"channel":"book","type":"update","data":[{"symbol":"BTC/EUR","bids":[{"price":62363.1,"qty":2.72305255}],"asks":[],"checksum":399179626,"timestamp":"2024-06-01T17:51:34.918382Z"}]}
{"channel":"book","type":"update","data":[{"symbol":"BTC/EUR","bids":[{"price":62350.3,"qty":0.00000000},{"price":62337.2,"qty":1.10922789}],"asks":[],"checksum":693323963,"timestamp":"2024-06-01T17:51:34.953838Z"}]}
{"channel":"book","type":"update","data":[{"symbol":"BTC/EUR","bids":[{"price":62363.1,"qty":4.20148008}],"asks":[],"checksum":3949104323,"timestamp":"2024-06-01T17:51:34.961303Z"}]}
{"channel":"book","type":"update","data":[{"symbol":"BTC/EUR","bids":[],"asks":[{"price":62379.2,"qty":1.47804647}],"checksum":1014144301,"timestamp":"2024-06-01T17:51:34.961364Z"}]}
{"channel":"book","type":"update","data":[{"symbol":"BTC/EUR","bids":[{"price":62363.1,"qty":5.67990761}],"asks":[],"checksum":1211780640,"timestamp":"2024-06-01T17:51:34.961467Z"}]}
{"channel":"book","type":"update","data":[{"symbol":"BTC/EUR","bids":[],"asks":[{"price":62379.5,"qty":0.00000000},{"price":62383.0,"qty":0.54621000}],"checksum":2556780621,"timestamp":"2024-06-01T17:51:34.968264Z"}]}
{"channel":"book","type":"update","data":[{"symbol":"BTC/EUR","bids":[],"asks":[{"price":62376.9,"qty":1.47810122}],"checksum":929804516,"timestamp":"2024-06-01T17:51:34.972565Z"}]}
{"channel":"book","type":"update","data":[{"symbol":"BTC/EUR","bids":[],"asks":[{"price":62382.5,"qty":0.00000000},{"price":62383.0,"qty":0.54621000}],"checksum":416783262,"timestamp":"2024-06-01T17:51:34.978070Z"}]}
{"channel":"book","type":"update","data":[{"symbol":"BTC/EUR","bids":[],"asks":[{"price":62382.4,"qty":0.00000000},{"price":62384.3,"qty":1.47792673},{"price":62376.8,"qty":0.00045402}],"checksum":435801944,"timestamp":"2024-06-01T17:51:35.040525Z"}]}
{"channel":"book","type":"update","data":[{"symbol":"BTC/EUR","bids":[{"price":62360.0,"qty":0.67028012},{"price":62363.1,"qty":5.68001994}],"asks":[],"checksum":616836869,"timestamp":"2024-06-01T17:51:35.040626Z"}]}
{"channel":"book","type":"update","data":[{"symbol":"BTC/EUR","bids":[{"price":62360.0,"qty":0.42028012}],"asks":[],"checksum":3609527496,"timestamp":"2024-06-01T17:51:35.046037Z"}]}
{"channel":"book","type":"update","data":[{"symbol":"BTC/EUR","bids":[{"price":62360.0,"qty":0.41830582}],"asks":[],"checksum":38196605,"timestamp":"2024-06-01T17:51:35.046269Z"}]}
{"channel":"book","type":"update","data":[{"symbol":"BTC/EUR","bids":[{"price":62363.1,"qty":6.08001994}],"asks":[],"checksum":3032023905,"timestamp":"2024-06-01T17:51:35.051295Z"}]}
{"channel":"book","type":"update","data":[{"symbol":"BTC/EUR","bids":[{"price":62355.3,"qty":0.06120700}],"asks":[],"checksum":3486200516,"timestamp":"2024-06-01T17:51:35.058941Z"}]}
{"channel":"book","type":"update","data":[{"symbol":"BTC/EUR","bids":[{"price":62363.1,"qty":6.07148294},{"price":62357.7,"qty":0.00853700}],"asks":[],"checksum":1698505561,"timestamp":"2024-06-01T17:51:35.108393Z"}]}
{"channel":"book","type":"update","data":[{"symbol":"BTC/EUR","bids":[{"price":62357.3,"qty":0.00000000},{"price":62337.4,"qty":6.68689519}],"asks":[],"checksum":1502545761,"timestamp":"2024-06-01T17:51:35.112597Z"}]}
{"channel":"book","type":"update","data":[{"symbol":"BTC/EUR","bids":[{"price":62363.1,"qty":6.07345724}],"asks":[],"checksum":2175467195,"timestamp":"2024-06-01T17:51:35.130525Z"}]}
{"channel":"book","type":"update","data":[{"symbol":"BTC/EUR","bids":[{"price":62347.4,"qty":0.03158383}],"asks":[],"checksum":1626325384,"timestamp":"2024-06-01T17:51:35.215414Z"}]}
{"channel":"book","type":"update","data":[{"symbol":"BTC/EUR","bids":[{"price":62341.2,"qty":0.04736432}],"asks":[],"checksum":3258439029,"timestamp":"2024-06-01T17:51:35.728712Z"}]}
{"channel":"book","type":"update","data":[{"symbol":"BTC/EUR","bids":[],"asks":[{"price":62382.3,"qty":0.29575561}],"checksum":3706170832,"timestamp":"2024-06-01T17:51:35.831401Z"}]}
{"channel":"book","type":"update","data":[{"symbol":"BTC/EUR","bids":[],"asks":[{"price":62382.3,"qty":0.00000000},{"price":62383.0,"qty":0.54621000}],"checksum":3258439029,"timestamp":"2024-06-01T17:51:35.836886Z"}]}
{"channel":"book","type":"update","data":[{"symbol":"BTC/EUR","bids":[],"asks":[{"price":62380.7,"qty":1.47801129}],"checksum":3660483383,"timestamp":"2024-06-01T17:51:35.876529Z"}]}
{"channel":"book","type":"update","data":[{"symbol":"BTC/EUR","bids":[{"price":62347.4,"qty":0.00000000},{"price":62338.3,"qty":0.03947498}],"asks":[],"checksum":2730030715,"timestamp":"2024-06-01T17:51:35.891757Z"}]}
{"channel":"book","type":"update","data":[{"symbol":"BTC/EUR","bids":[{"price":62344.7,"qty":0.03158383}],"asks":[],"checksum":2964626784,"timestamp":"2024-06-01T17:51:35.994746Z"}]}
{"channel":"book","type":"update","data":[{"symbol":"BTC/EUR","bids":[],"asks":[{"price":62381.0,"qty":0.00000000},{"price":62383.0,"qty":0.54621000},{"price":62375.6,"qty":0.00853600}],"checksum":155889657,"timestamp":"2024-06-01T17:51:36.095158Z"}]}
{"channel":"book","type":"update","data":[{"symbol":"BTC/EUR","bids":[{"price":62341.2,"qty":7.08036238}],"asks":[],"checksum":1254380559,"timestamp":"2024-06-01T17:51:36.111917Z"}]}
{"channel":"book","type":"update","data":[{"symbol":"BTC/EUR","bids":[{"price":62344.3,"qty":1.10908354}],"asks":[],"checksum":1732589720,"timestamp":"2024-06-01T17:51:36.191697Z"}]}
{"channel":"book","type":"update","data":[{"symbol":"BTC/EUR","bids":[{"price":62357.7,"qty":0.00000000},{"price":62341.1,"qty":1.10908354},{"price":62363.1,"qty":6.08199424}],"asks":[],"checksum":2727811919,"timestamp":"2024-06-01T17:51:36.457191Z"}]}
{"channel":"book","type":"update","data":[{"symbol":"BTC/EUR","bids":[],"asks":[{"price":62375.6,"qty":0.00000000},{"price":62382.2,"qty":0.29575561},{"price":62381.0,"qty":0.00853500}],"checksum":2935891247,"timestamp":"2024-06-01T17:51:36.491900Z"}]}
{"channel":"book","type":"update","data":[{"symbol":"BTC/EUR","bids":[{"price":62363.1,"qty":6.33199424}],"asks":[],"checksum":3014987142,"timestamp":"2024-06-01T17:51:36.632151Z"}]}
{"channel":"book","type":"update","data":[{"symbol":"BTC/EUR","bids":[],"asks":[{"price":62380.7,"qty":0.00000000},{"price":62382.2,"qty":0.29575561}],"checksum":2773309921,"timestamp":"2024-06-01T17:51:36.651136Z"}]}
{"channel":"book","type":"update","data":[{"symbol":"BTC/EUR","bids":[],"asks":[{"price":62376.4,"qty":1.47811263}],"checksum":2266072717,"timestamp":"2024-06-01T17:51:36.656325Z"}]}
{"channel":"book","type":"update","data":[{"symbol":"BTC/EUR","bids":[],"asks":[{"price":62376.8,"qty":0.00000000},{"price":62382.2,"qty":0.29575561},{"price":62376.3,"qty":0.00045408}],"checksum":2949803359,"timestamp":"2024-06-01T17:51:36.709383Z"}]}
{"channel":"book","type":"update","data":[{"symbol":"BTC/EUR","bids":[{"price":62363.1,"qty":6.55199424}],"asks":[],"checksum":2459069356,"timestamp":"2024-06-01T17:51:37.140345Z"}]}
{"channel":"book","type":"update","data":[{"symbol":"BTC/EUR","bids":[{"price":62360.1,"qty":0.00000000},{"price":62338.3,"qty":0.03947498}],"asks":[],"checksum":20789890,"timestamp":"2024-06-01T17:51:37.193866Z"}]}
{"channel":"book","type":"update","data":[{"symbol":"BTC/EUR","bids":[],"asks":[{"price":62377.4,"qty":0.29572893}],"checksum":2260457000,"timestamp":"2024-06-01T17:51:37.344030Z"}]}
{"channel":"book","type":"update","data":[{"symbol":"BTC/EUR","bids":[{"price":62341.2,"qty":7.03299806}],"asks":[],"checksum":3309619887,"timestamp":"2024-06-01T17:51:37.978679Z"}]}
{"channel":"book","type":"update","data":[{"symbol":"BTC/EUR","bids":[{"price":62344.4,"qty":0.04427136}],"asks":[],"checksum":555845328,"timestamp":"2024-06-01T17:51:37.984315Z"}]}
{"channel":"book","type":"update","data":[{"symbol":"BTC/EUR","bids":[],"asks":[{"price":62363.2,"qty":0.03919000}],"checksum":1775717487,"timestamp":"2024-06-01T17:51:38.037995Z"}]}
{"channel":"book","type":"update","data":[{"symbol":"BTC/EUR","bids":[],"asks":[{"price":62376.9,"qty":0.00000000},{"price":62381.0,"qty":0.00853500}],"checksum":2100561808,"timestamp":"2024-06-01T17:51:38.157217Z"}]}
{"channel":"book","type":"update","data":[{"symbol":"BTC/EUR","bids":[],"asks":[{"price":62373.8,"qty":1.47817602}],"checksum":3592931366,"timestamp":"2024-06-01T17:51:38.161782Z"}]}
{"channel":"book","type":"update","data":[{"symbol":"BTC/EUR","bids":[],"asks":[{"price":62373.8,"qty":0.00000000},{"price":62381.0,"qty":0.00853500}],"checksum":2100561808,"timestamp":"2024-06-01T17:51:38.207161Z"}]}
{"channel":"book","type":"update","data":[{"symbol":"BTC/EUR","bids":[],"asks":[{"price":62379.9,"qty":1.47802999}],"checksum":1174116351,"timestamp":"2024-06-01T17:51:38.211404Z"}]}
{"channel":"book","type":"update","data":[{"symbol":"BTC/EUR","bids":[],"asks":[{"price":62374.8,"qty":0.00853600}],"checksum":4040062660,"timestamp":"2024-06-01T17:51:38.213204Z"}]}
{"channel":"book","type":"update","data":[{"symbol":"BTC/EUR","bids":[],"asks":[{"price":62379.2,"qty":0.00000000},{"price":62379.9,"qty":1.47802999}],"checksum":4026421294,"timestamp":"2024-06-01T17:51:38.231704Z"}]}
{"channel":"book","type":"update","data":[{"symbol":"BTC/EUR","bids":[],"asks":[{"price":62376.5,"qty":1.47811076}],"checksum":1755143783,"timestamp":"2024-06-01T17:51:38.236073Z"}]}
{"channel":"book","type":"update","data":[{"symbol":"BTC/EUR","bids":[{"price":62344.7,"qty":0.00000000},{"price":62338.3,"qty":0.03947498}],"asks":[],"checksum":1480465196,"timestamp":"2024-06-01T17:51:38.292367Z"}]}
{"channel":"book","type":"update","data":[{"symbol":"BTC/EUR","bids":[{"price":62363.1,"qty":6.67681563}],"asks":[],"checksum":2932242052,"timestamp":"2024-06-01T17:51:38.333566Z"}]}
{"channel":"book","type":"update","data":[{"symbol":"BTC/EUR","bids":[{"price":62341.2,"qty":0.00000000},{"price":62328.3,"qty":2.21887673}],"asks":[],"checksum":1967572091,"timestamp":"2024-06-01T17:51:38.507073Z"}]}
{"channel":"book","type":"update","data":[{"symbol":"BTC/EUR","bids":[{"price":62344.5,"qty":6.56248392}],"asks":[],"checksum":358597892,"timestamp":"2024-06-01T17:51:38.512099Z"}]}
{"channel":"book","type":"update","data":[{"symbol":"BTC/EUR","bids":[{"price":62346.8,"qty":0.00000000},{"price":62328.3,"qty":2.21887673}],"asks":[],"checksum":184804844,"timestamp":"2024-06-01T17:51:38.569993Z"}]}
{"channel":"book","type":"update","data":[{"symbol":"BTC/EUR","bids":[{"price":62363.1,"qty":6.73594809}],"asks":[],"checksum":347917482,"timestamp":"2024-06-01T17:51:38.820244Z"}]}
{"channel":"book","type":"update","data":[{"symbol":"BTC/EUR","bids":[],"asks":[{"price":62363.2,"qty":0.03880000}],"checksum":1343899022,"timestamp":"2024-06-01T17:51:39.129711Z"}]}
{"channel":"book","type":"update","data":[{"symbol":"BTC/EUR","bids":[{"price":62363.1,"qty":6.67681563}],"asks":[],"checksum":1336241352,"timestamp":"2024-06-01T17:51:39.883751Z"}]}
{"channel":"book","type":"update","data":[{"symbol":"BTC/EUR","bids":[{"price":62355.3,"qty":0.00000000},{"price":62314.4,"qty":0.00200000}],"asks":[],"checksum":2999591171,"timestamp":"2024-06-01T17:51:40.049738Z"}]}
{"channel":"book","type":"update","data":[{"symbol":"BTC/EUR","bids":[{"price":62351.9,"qty":0.00000000},{"price":62313.4,"qty":0.04517000}],"asks":[],"checksum":1763304065,"timestamp":"2024-06-01T17:51:40.069524Z"}]}
{"channel":"book","type":"update","data":[{"symbol":"BTC/EUR","bids":[],"asks":[{"price":62376.5,"qty":0.00000000},{"price":62379.9,"qty":1.47802999}],"checksum":4001033416,"timestamp":"2024-06-01T17:51:40.078377Z"}]}
{"channel":"book","type":"update","data":[{"symbol":"BTC/EUR","bids":[],"asks":[{"price":62374.2,"qty":0.29572893}],"checksum":415354893,"timestamp":"2024-06-01T17:51:40.081176Z"}]}
{"channel":"book","type":"update","data":[{"symbol":"BTC/EUR","bids":[{"price":62363.1,"qty":5.19838810}],"asks":[],"checksum":3982498788,"timestamp":"2024-06-01T17:51:40.085694Z"}]}
{"channel":"book","type":"update","data":[{"symbol":"BTC/EUR","bids":[],"asks":[{"price":62376.4,"qty":0.00000000},{"price":62379.9,"qty":1.47802999}],"checksum":2060887918,"timestamp":"2024-06-01T17:51:40.085763Z"}]}
{"channel":"book","type":"update","data":[{"symbol":"BTC/EUR","bids":[],"asks":[{"price":62377.4,"qty":0.00000000},{"price":62383.0,"qty":0.54621000}],"checksum":3595053810,"timestamp":"2024-06-01T17:51:40.086350Z"}]}
{"channel":"book","type":"update","data":[{"symbol":"BTC/EUR","bids":[],"asks":[{"price":62373.7,"qty":1.47817683}],"checksum":2382155571,"timestamp":"2024-06-01T17:51:40.093568Z"}]}
{"channel":"book","type":"update","data":[{"symbol":"BTC/EUR","bids":[],"asks":[{"price":62370.4,"qty":1.47825571}],"checksum":3798611792,"timestamp":"2024-06-01T17:51:40.093599Z"}]}
{"channel":"book","type":"update","data":[{"symbol":"BTC/EUR","bids":[],"asks":[{"price":62375.1,"qty":1.47865217}],"checksum":3729949389,"timestamp":"2024-06-01T17:51:40.093638Z"}]}
{"channel":"book","type":"update","data":[{"symbol":"BTC/EUR","bids":[{"price":62363.1,"qty":5.07356671}],"asks":[],"checksum":3402490817,"timestamp":"2024-06-01T17:51:40.095764Z"}]}
{"channel":"book","type":"update","data":[{"symbol":"BTC/EUR","bids":[],"asks":[{"price":62375.1,"qty":0.00050835}],"checksum":4143273564,"timestamp":"2024-06-01T17:51:40.102153Z"}]}
{"channel":"book","type":"update","data":[{"symbol":"BTC/EUR","bids":[{"price":62363.1,"qty":4.18647573}],"asks":[],"checksum":2806758089,"timestamp":"2024-06-01T17:51:40.103958Z"}]}
{"channel":"book","type":"update","data":[{"symbol":"BTC/EUR","bids":[{"price":62363.1,"qty":2.70804820}],"asks":[],"checksum":4233001253,"timestamp":"2024-06-01T17:51:40.107098Z"}]}
{"channel":"book","type":"update","data":[{"symbol":"BTC/EUR","bids":[{"price":62363.1,"qty":2.53804820}],"asks":[],"checksum":1081417001,"timestamp":"2024-06-01T17:51:40.112559Z"}]}
{"channel":"book","type":"update","data":[{"symbol":"BTC/EUR","bids":[{"price":62363.1,"qty":1.05962067}],"asks":[],"checksum":2249996725,"timestamp":"2024-06-01T17:51:40.131940Z"}]}
{"channel":"book","type":"update","data":[{"symbol":"BTC/EUR","bids":[{"price":62363.1,"qty":0.65962067}],"asks":[],"checksum":2891069010,"timestamp":"2024-06-01T17:51:40.132588Z"}]}
{"channel":"book","type":"update","data":[{"symbol":"BTC/EUR","bids":[{"price":62313.4,"qty":0.00000000},{"price":62313.2,"qty":0.03850000}],"asks":[],"checksum":2069073148,"timestamp":"2024-06-01T17:51:40.135681Z"}]}
{"channel":"book","type":"update","data":[{"symbol":"BTC/EUR","bids":[{"price":62347.4,"qty":0.03158383}],"asks":[],"checksum":905586228,"timestamp":"2024-06-01T17:51:40.142458Z"}]}
{"channel":"book","type":"update","data":[{"symbol":"BTC/EUR","bids":[{"price":62350.5,"qty":0.06120100}],"asks":[],"checksum":2497160946,"timestamp":"2024-06-01T17:51:40.148420Z"}]}
{"channel":"book","type":"update","data":[{"symbol":"BTC/EUR","bids":[{"price":62358.9,"qty":0.05913254}],"asks":[],"checksum":2410871674,"timestamp":"2024-06-01T17:51:40.149750Z"}]}
{"channel":"book","type":"update","data":[{"symbol":"BTC/EUR","bids":[{"price":62350.5,"qty":0.00000000},{"price":62328.3,"qty":2.21887673}],"asks":[],"checksum":2234951576,"timestamp":"2024-06-01T17:51:40.153898Z"}]}
{"channel":"book","type":"update","data":[{"symbol":"BTC/EUR","bids":[{"price":62363.1,"qty":0.40962067}],"asks":[],"checksum":3229740691,"timestamp":"2024-06-01T17:51:40.155195Z"}]}
{"channel":"book","type":"update","data":[{"symbol":"BTC/EUR","bids":[{"price":62347.5,"qty":0.13025529}],"asks":[],"checksum":3315221337,"timestamp":"2024-06-01T17:51:40.157673Z"}]}
{"channel":"book","type":"update","data":[{"symbol":"BTC/EUR","bids":[],"asks":[{"price":62369.6,"qty":0.17000000}],"checksum":4196267080,"timestamp":"2024-06-01T17:51:40.165590Z"}]}
{"channel":"book","type":"update","data":[{"symbol":"BTC/EUR","bids":[],"asks":[{"price":62369.7,"qty":0.69796633}],"checksum":2974826551,"timestamp":"2024-06-01T17:51:40.165825Z"}]}
{"channel":"book","type":"update","data":[{"symbol":"BTC/EUR","bids":[],"asks":[{"price":62369.7,"qty":0.52796633}],"checksum":4196267080,"timestamp":"2024-06-01T17:51:40.168518Z"}]}
{"channel":"book","type":"update","data":[{"symbol":"BTC/EUR","bids":[{"price":62344.4,"qty":0.00000000},{"price":62328.3,"qty":2.21887673}],"asks":[],"checksum":3731256165,"timestamp":"2024-06-01T17:51:40.181632Z"}]}
{"channel":"book","type":"update","data":[{"symbol":"BTC/EUR","bids":[{"price":62344.6,"qty":0.04105506}],"asks":[],"checksum":1496233247,"timestamp":"2024-06-01T17:51:40.186971Z"}]}
{"channel":"book","type":"update","data":[{"symbol":"BTC/EUR","bids":[{"price":62363.1,"qty":0.40108367},{"price":62354.9,"qty":0.00853700}],"asks":[],"checksum":2178260223,"timestamp":"2024-06-01T17:51:40.219615Z"}]}
{"channel":"book","type":"update","data":[{"symbol":"BTC/EUR","bids":[{"price":62360.0,"qty":0.00000000},{"price":62338.3,"qty":0.03947498}],"asks":[],"checksum":3719091329,"timestamp":"2024-06-01T17:51:40.231137Z"}]}
{"channel":"book","type":"update","data":[{"symbol":"BTC/EUR","bids":[{"price":62355.8,"qty":0.17000000}],"asks":[],"checksum":3481407716,"timestamp":"2024-06-01T17:51:40.233983Z"}]}
{"channel":"book","type":"update","data":[{"symbol":"BTC/EUR","bids":[{"price":62357.4,"qty":0.41832326}],"asks":[],"checksum":2417818372,"timestamp":"2024-06-01T17:51:40.235805Z"}]}
{"channel":"book","type":"update","data":[{"symbol":"BTC/EUR","bids":[],"asks":[{"price":62374.8,"qty":0.00000000},{"price":62379.8,"qty":0.00045408},{"price":62369.2,"qty":0.00853600}],"checksum":3400425985,"timestamp":"2024-06-01T17:51:40.236462Z"}]}
{"channel":"book","type":"update","data":[{"symbol":"BTC/EUR","bids":[{"price":62344.3,"qty":0.00000000},{"price":62341.1,"qty":1.10908354}],"asks":[],"checksum":3205242494,"timestamp":"2024-06-01T17:51:40.240105Z"}]}
{"channel":"book","type":"update","data":[{"symbol":"BTC/EUR","bids":[{"price":62357.4,"qty":0.00000000},{"price":62338.3,"qty":0.03947498}],"asks":[],"checksum":1638283882,"timestamp":"2024-06-01T17:51:40.240405Z"}]}
{"channel":"book","type":"update","data":[{"symbol":"BTC/EUR","bids":[{"price":62341.1,"qty":0.00000000},{"price":62328.3,"qty":2.21887673}],"asks":[],"checksum":192730638,"timestamp":"2024-06-01T17:51:40.240829Z"}]}
{"channel":"book","type":"update","data":[{"symbol":"BTC/EUR","bids":[{"price":62356.9,"qty":0.41832661}],"asks":[],"checksum":485417024,"timestamp":"2024-06-01T17:51:40.243094Z"}]}
{"channel":"book","type":"update","data":[{"symbol":"BTC/EUR","bids":[{"price":62347.4,"qty":0.00000000},{"price":62328.3,"qty":2.21887673}],"asks":[],"checksum":3978672023,"timestamp":"2024-06-01T17:51:40.245607Z"}]}
{"channel":"book","type":"update","data":[{"symbol":"BTC/EUR","bids":[],"asks":[{"price":62369.1,"qty":0.12094534}],"checksum":1593058974,"timestamp":"2024-06-01T17:51:40.258866Z"}]}
{"channel":"book","type":"update","data":[{"symbol":"BTC/EUR","bids":[],"asks":[{"price":62368.0,"qty":1.47831370}],"checksum":144258498,"timestamp":"2024-06-01T17:51:40.259308Z"}]}
{"channel":"book","type":"update","data":[{"symbol":"BTC/EUR","bids":[],"asks":[{"price":62369.6,"qty":0.00000000},{"price":62374.2,"qty":0.29572893}],"checksum":1527688227,"timestamp":"2024-06-01T17:51:40.261859Z"}]}
{"channel":"book","type":"update","data":[{"symbol":"BTC/EUR","bids":[],"asks":[{"price":62368.3,"qty":0.17000000}],"checksum":3902219183,"timestamp":"2024-06-01T17:51:40.262001Z"}]}
{"channel":"book","type":"update","data":[{"symbol":"BTC/EUR","bids":[],"asks":[{"price":62368.3,"qty":0.00000000},{"price":62374.2,"qty":0.29572893}],"checksum":1527688227,"timestamp":"2024-06-01T17:51:40.262058Z"}]}
{"channel":"book","type":"update","data":[{"symbol":"BTC/EUR","bids":[],"asks":[{"price":62367.7,"qty":0.17000000}],"checksum":2550453493,"timestamp":"2024-06-01T17:51:40.262411Z"}]}
{"channel":"book","type":"update","data":[{"symbol":"BTC/EUR","bids":[],"asks":[{"price":62367.2,"qty":1.47833061}],"checksum":3763302634,"timestamp":"2024-06-01T17:51:40.315446Z"}]}
{"channel":"book","type":"update","data":[{"symbol":"BTC/EUR","bids":[{"price":62350.2,"qty":0.06120100}],"asks":[],"checksum":2038982167,"timestamp":"2024-06-01T17:51:40.325009Z"}]}
{"channel":"book","type":"update","data":[{"symbol":"BTC/EUR","bids":[{"price":62358.9,"qty":0.00000000},{"price":62328.3,"qty":2.21887673}],"asks":[],"checksum":2802653064,"timestamp":"2024-06-01T17:51:40.410599Z"}]}
{"channel":"book","type":"update","data":[{"symbol":"BTC/EUR","bids":[{"price":62363.1,"qty":0.52590506}],"asks":[],"checksum":659113564,"timestamp":"2024-06-01T17:51:40.468329Z"}]}
{"channel":"book","type":"update","data":[{"symbol":"BTC/EUR","bids":[{"price":62354.6,"qty":0.05913934}],"asks":[],"checksum":3043836476,"timestamp":"2024-06-01T17:51:40.685891Z"}]}
{"channel":"book","type":"update","data":[{"symbol":"BTC/EUR","bids":[{"price":62354.6,"qty":0.00000000},{"price":62328.3,"qty":2.21887673}],"asks":[],"checksum":659113564,"timestamp":"2024-06-01T17:51:40.941911Z"}]}
{"channel":"book","type":"update","data":[{"symbol":"BTC/EUR","bids":[{"price":62354.0,"qty":1.47864164}],"asks":[],"checksum":4105236923,"timestamp":"2024-06-01T17:51:41.153043Z"}]}
{"channel":"book","type":"update","data":[{"symbol":"BTC/EUR","bids":[{"price":62359.6,"qty":1.47851046}],"asks":[],"checksum":4045209044,"timestamp":"2024-06-01T17:51:41.153076Z"}]}
{"channel":"book","type":"update","data":[{"symbol":"BTC/EUR","bids":[{"price":62354.3,"qty":0.05913964}],"asks":[],"checksum":3634375604,"timestamp":"2024-06-01T17:51:41.207838Z"}]}
{"channel":"book","type":"update","data":[{"symbol":"BTC/EUR","bids":[],"asks":[{"price":62367.7,"qty":0.00000000},{"price":62373.6,"qty":0.00045408}],"checksum":518485954,"timestamp":"2024-06-01T17:51:41.221939Z"}]}
{"channel":"book","type":"update","data":[{"symbol":"BTC/EUR","bids":[{"price":62363.1,"qty":0.30590506}],"asks":[],"checksum":4172616729,"timestamp":"2024-06-01T17:51:41.266269Z"}]}
{"channel":"book","type":"update","data":[{"symbol":"BTC/EUR","bids":[],"asks":[{"price":62369.1,"qty":0.00000000},{"price":62373.7,"qty":1.47817683}],"checksum":144195230,"timestamp":"2024-06-01T17:51:41.268023Z"}]}
{"channel":"book","type":"update","data":[{"symbol":"BTC/EUR","bids":[{"price":62355.8,"qty":0.00000000},{"price":62344.5,"qty":6.56248392}],"asks":[],"checksum":4138288290,"timestamp":"2024-06-01T17:51:41.269113Z"}]}
{"channel":"book","type":"update","data":[{"symbol":"BTC/EUR","bids":[{"price":62359.6,"qty":1.64851046}],"asks":[],"checksum":1926303107,"timestamp":"2024-06-01T17:51:41.269175Z"}]}
{"channel":"book","type":"update","data":[{"symbol":"BTC/EUR","bids":[{"price":62359.6,"qty":1.47851046}],"asks":[],"checksum":4138288290,"timestamp":"2024-06-01T17:51:41.296574Z"}]}
{"channel":"book","type":"update","data":[{"symbol":"BTC/EUR","bids":[{"price":62359.7,"qty":0.17000000}],"asks":[],"checksum":910631163,"timestamp":"2024-06-01T17:51:41.296714Z"}]}
{"channel":"book","type":"update","data":[{"symbol":"BTC/EUR","bids":[{"price":62363.1,"qty":0.55590506}],"asks":[],"checksum":2082534068,"timestamp":"2024-06-01T17:51:41.632390Z"}]}
{"channel":"book","type":"update","data":[{"symbol":"BTC/EUR","bids":[{"price":62357.0,"qty":0.40000000}],"asks":[],"checksum":2378320574,"timestamp":"2024-06-01T17:51:41.635513Z"}]}
{"channel":"book","type":"update","data":[{"symbol":"BTC/EUR","bids":[],"asks":[{"price":62372.7,"qty":0.13266390}],"checksum":1444283915,"timestamp":"2024-06-01T17:51:41.635917Z"}]}
{"channel":"book","type":"update","data":[{"symbol":"BTC/EUR","bids":[],"asks":[{"price":62368.0,"qty":0.00000000},{"price":62373.7,"qty":1.47817683}],"checksum":4003952135,"timestamp":"2024-06-01T17:51:42.002674Z"}]}
{"channel":"book","type":"update","data":[{"symbol":"BTC/EUR","bids":[],"asks":[{"price":62365.0,"qty":1.47838432}],"checksum":2058067791,"timestamp":"2024-06-01T17:51:42.006993Z"}]}
{"channel":"book","type":"update","data":[{"symbol":"BTC/EUR","bids":[],"asks":[{"price":62370.1,"qty":0.29576348}],"checksum":2062167112,"timestamp":"2024-06-01T17:51:42.204478Z"}]}
{"channel":"book","type":"update","data":[{"symbol":"BTC/EUR","bids":[{"price":62357.0,"qty":0.00000000},{"price":62344.6,"qty":0.03898672}],"asks":[],"checksum":1638490189,"timestamp":"2024-06-01T17:51:42.633458Z"}]}
{"channel":"book","type":"update","data":[{"symbol":"BTC/EUR","bids":[{"price":62357.2,"qty":1.47856579}],"asks":[],"checksum":590195326,"timestamp":"2024-06-01T17:51:43.152675Z"}]}
{"channel":"book","type":"update","data":[{"symbol":"BTC/EUR","bids":[],"asks":[{"price":62372.7,"qty":0.00000000},{"price":62373.6,"qty":0.00045408}],"checksum":823370,"timestamp":"2024-06-01T17:51:43.681277Z"}]}
{"channel":"book","type":"update","data":[{"symbol":"BTC/EUR","bids":[],"asks":[{"price":62370.1,"qty":0.00000000},{"price":62373.7,"qty":1.47817683}],"checksum":1791121517,"timestamp":"2024-06-01T17:51:43.681618Z"}]}
{"channel":"book","type":"update","data":[{"symbol":"BTC/EUR","bids":[],"asks":[{"price":62365.0,"qty":0.00000000},{"price":62375.1,"qty":0.00050835}],"checksum":219221200,"timestamp":"2024-06-01T17:51:43.689300Z"}]}
{"channel":"book","type":"update","data":[{"symbol":"BTC/EUR","bids":[{"price":62359.6,"qty":0.00000000},{"price":62344.6,"qty":0.03898672}],"asks":[],"checksum":2045142401,"timestamp":"2024-06-01T17:51:43.697645Z"}]}
{"channel":"book","type":"update","data":[{"symbol":"BTC/EUR","bids":[],"asks":[{"price":62370.4,"qty":0.00000000},{"price":62383.0,"qty":0.54621000}],"checksum":353799,"timestamp":"2024-06-01T17:51:43.697702Z"}]}
{"channel":"book","type":"update","data":[{"symbol":"BTC/EUR","bids":[{"price":62354.0,"qty":0.00000000},{"price":62338.3,"qty":0.03947498}],"asks":[],"checksum":2794105731,"timestamp":"2024-06-01T17:51:43.697770Z"}]}
{"channel":"book","type":"update","data":[{"symbol":"BTC/EUR","bids":[],"asks":[{"price":62367.2,"qty":0.00000000},{"price":62386.4,"qty":0.22190000}],"checksum":1456082340,"timestamp":"2024-06-01T17:51:43.697812Z"}]}
{"channel":"book","type":"update","data":[{"symbol":"BTC/EUR","bids":[{"price":62357.2,"qty":0.00000000},{"price":62328.4,"qty":9.62096033}],"asks":[],"checksum":1254514931,"timestamp":"2024-06-01T17:51:43.701640Z"}]}
{"channel":"book","type":"update","data":[{"symbol":"BTC/EUR","bids":[],"asks":[{"price":62373.7,"qty":0.00000000},{"price":62388.1,"qty":0.27459385}],"checksum":1511760850,"timestamp":"2024-06-01T17:51:43.701821Z"}]}
{"channel":"book","type":"update","data":[{"symbol":"BTC/EUR","bids":[{"price":62328.5,"qty":0.22180000}],"asks":[],"checksum":4179676672,"timestamp":"2024-06-01T17:51:43.702226Z"}]}
{"channel":"book","type":"update","data":[{"symbol":"BTC/EUR","bids":[{"price":62328.5,"qty":0.25137000}],"asks":[],"checksum":3598776614,"timestamp":"2024-06-01T17:51:43.702583Z"}]}
{"channel":"book","type":"update","data":[{"symbol":"BTC/EUR","bids":[{"price":62363.1,"qty":1.44308708}],"asks":[],"checksum":2414973571,"timestamp":"2024-06-01T17:51:43.704161Z"}]}
{"channel":"book","type":"update","data":[{"symbol":"BTC/EUR","bids":[{"price":62363.1,"qty":1.31826569}],"asks":[],"checksum":119477384,"timestamp":"2024-06-01T17:51:43.704418Z"}]}
{"channel":"book","type":"update","data":[{"symbol":"BTC/EUR","bids":[],"asks":[{"price":62386.4,"qty":0.00000000},{"price":62391.9,"qty":0.79104677},{"price":62388.0,"qty":0.22190000}],"checksum":3263973015,"timestamp":"2024-06-01T17:51:43.704535Z"}]}
{"channel":"book","type":"update","data":[{"symbol":"BTC/EUR","bids":[{"price":62359.7,"qty":0.00000000},{"price":62328.4,"qty":9.62096033}],"asks":[],"checksum":1468346770,"timestamp":"2024-06-01T17:51:43.705742Z"}]}
{"channel":"book","type":"update","data":[{"symbol":"BTC/EUR","bids":[{"price":62328.5,"qty":0.47307000}],"asks":[],"checksum":3748841183,"timestamp":"2024-06-01T17:51:43.706007Z"}]}
{"channel":"book","type":"update","data":[{"symbol":"BTC/EUR","bids":[{"price":62363.1,"qty":2.79669322}],"asks":[],"checksum":2585590815,"timestamp":"2024-06-01T17:51:43.716348Z"}]}
{"channel":"book","type":"update","data":[{"symbol":"BTC/EUR","bids":[],"asks":[{"price":62378.0,"qty":1.47807593}],"checksum":3584348979,"timestamp":"2024-06-01T17:51:43.716448Z"}]}
{"channel":"book","type":"update","data":[{"symbol":"BTC/EUR","bids":[],"asks":[{"price":62374.8,"qty":1.47815106}],"checksum":3069068951,"timestamp":"2024-06-01T17:51:43.716463Z"}]}
{"channel":"book","type":"update","data":[{"symbol":"BTC/EUR","bids":[],"asks":[{"price":62382.6,"qty":1.47796557}],"checksum":1184674450,"timestamp":"2024-06-01T17:51:43.716565Z"}]}
{"channel":"book","type":"update","data":[{"symbol":"BTC/EUR","bids":[{"price":62363.1,"qty":2.96669322}],"asks":[],"checksum":1343060165,"timestamp":"2024-06-01T17:51:43.716710Z"}]}
{"channel":"book","type":"update","data":[{"symbol":"BTC/EUR","bids":[],"asks":[{"price":62374.8,"qty":0.00000000},{"price":62383.0,"qty":0.54621000}],"checksum":3735213217,"timestamp":"2024-06-01T17:51:43.728254Z"}]}
{"channel":"book","type":"update","data":[{"symbol":"BTC/EUR","bids":[],"asks":[{"price":62373.6,"qty":0.00000000},{"price":62388.0,"qty":0.22190000},{"price":62382.9,"qty":0.00045408}],"checksum":895755652,"timestamp":"2024-06-01T17:51:43.756424Z"}]}
{"channel":"book","type":"update","data":[{"symbol":"BTC/EUR","bids":[],"asks":[{"price":62369.2,"qty":0.00000000},{"price":62388.0,"qty":0.22190000},{"price":62380.2,"qty":0.00853500}],"checksum":983310295,"timestamp":"2024-06-01T17:51:43.827861Z"}]}
{"channel":"book","type":"update","data":[{"symbol":"BTC/EUR","bids":[{"price":62354.9,"qty":0.00000000},{"price":62328.3,"qty":2.21887673},{"price":62363.1,"qty":2.97523022}],"asks":[],"checksum":2687390809,"timestamp":"2024-06-01T17:51:43.837177Z"}]}
{"channel":"book","type":"update","data":[{"symbol":"BTC/EUR","bids":[],"asks":[{"price":62364.6,"qty":0.00000000},{"price":62388.0,"qty":0.22190000}],"checksum":1343257982,"timestamp":"2024-06-01T17:51:43.895262Z"}]}
{"channel":"book","type":"update","data":[{"symbol":"BTC/EUR","bids":[],"asks":[{"price":62382.5,"qty":0.13266390}],"checksum":1135956382,"timestamp":"2024-06-01T17:51:43.921460Z"}]}
{"channel":"book","type":"update","data":[{"symbol":"BTC/EUR","bids":[],"asks":[{"price":62364.8,"qty":0.05923000}],"checksum":2597544332,"timestamp":"2024-06-01T17:51:44.004653Z"}]}
{"channel":"book","type":"update","data":[{"symbol":"BTC/EUR","bids":[{"price":62363.1,"qty":3.10005161}],"asks":[],"checksum":3343289903,"timestamp":"2024-06-01T17:51:44.007806Z"}]}
{"channel":"book","type":"update","data":[{"symbol":"BTC/EUR","bids":[{"price":62363.1,"qty":3.50005161}],"asks":[],"checksum":3919732782,"timestamp":"2024-06-01T17:51:44.133979Z"}]}
{"channel":"book","type":"update","data":[{"symbol":"BTC/EUR","bids":[],"asks":[{"price":62382.9,"qty":0.00000000},{"price":62383.0,"qty":0.54621000},{"price":62377.9,"qty":0.00045408}],"checksum":3203965722,"timestamp":"2024-06-01T17:51:44.147134Z"}]}
{"channel":"book","type":"update","data":[{"symbol":"BTC/EUR","bids":[{"price":62363.1,"qty":3.37523022}],"asks":[],"checksum":2000748420,"timestamp":"2024-06-01T17:51:44.205151Z"}]}
{"channel":"book","type":"update","data":[{"symbol":"BTC/EUR","bids":[{"price":62363.1,"qty":3.50005161}],"asks":[],"checksum":3203965722,"timestamp":"2024-06-01T17:51:44.326049Z"}]}
{"channel":"book","type":"update","data":[{"symbol":"BTC/EUR","bids":[{"price":62350.2,"qty":0.00000000},{"price":62314.4,"qty":0.00200000}],"asks":[],"checksum":1238511919,"timestamp":"2024-06-01T17:51:44.738157Z"}]}
{"channel":"book","type":"update","data":[{"symbol":"BTC/EUR","bids":[{"price":62363.1,"qty":3.37523022}],"asks":[],"checksum":4256049500,"timestamp":"2024-06-01T17:51:44.741021Z"}]}
{"channel":"book","type":"update","data":[{"symbol":"BTC/EUR","bids":[{"price":62357.7,"qty":0.06119800}],"asks":[],"checksum":372686237,"timestamp":"2024-06-01T17:51:44.856609Z"}]}
{"channel":"book","type":"update","data":[{"symbol":"BTC/EUR","bids":[{"price":62363.1,"qty":3.50005161}],"asks":[],"checksum":3750682883,"timestamp":"2024-06-01T17:51:44.868633Z"}]}
{"channel":"book","type":"update","data":[{"symbol":"BTC/EUR","bids":[],"asks":[{"price":62377.8,"qty":1.47808058}],"checksum":2790211213,"timestamp":"2024-06-01T17:51:45.154635Z"}]}
{"channel":"book","type":"update","data":[{"symbol":"BTC/EUR","bids":[{"price":62363.1,"qty":4.97847914}],"asks":[],"checksum":2583957290,"timestamp":"2024-06-01T17:51:45.154699Z"}]}
{"channel":"book","type":"update","data":[{"symbol":"BTC/EUR","bids":[{"price":62341.3,"qty":2.21841387}],"asks":[],"checksum":4101921651,"timestamp":"2024-06-01T17:51:45.154829Z"}]}
{"channel":"book","type":"update","data":[{"symbol":"BTC/EUR","bids":[{"price":62363.1,"qty":6.45690667}],"asks":[],"checksum":3910748607,"timestamp":"2024-06-01T17:51:45.154853Z"}]}
{"channel":"book","type":"update","data":[{"symbol":"BTC/EUR","bids":[],"asks":[{"price":62377.9,"qty":0.00000000},{"price":62382.6,"qty":1.47796557},{"price":62377.7,"qty":0.00045408}],"checksum":3928627630,"timestamp":"2024-06-01T17:51:45.212847Z"}]}
{"channel":"book","type":"update","data":[{"symbol":"BTC/EUR","bids":[{"price":62357.7,"qty":0.00000000},{"price":62328.3,"qty":2.21887673}],"asks":[],"checksum":2133528725,"timestamp":"2024-06-01T17:51:45.835254Z"}]}
{"channel":"book","type":"update","data":[{"symbol":"BTC/EUR","bids":[{"price":62363.1,"qty":6.33208528}],"asks":[],"checksum":2248988833,"timestamp":"2024-06-01T17:51:45.848366Z"}]}
{"channel":"book","type":"update","data":[{"symbol":"BTC/EUR","bids":[],"asks":[{"price":62382.4,"qty":0.29576348}],"checksum":2365711357,"timestamp":"2024-06-01T17:51:45.911477Z"}]}
{"channel":"book","type":"update","data":[{"symbol":"BTC/EUR","bids":[{"price":62357.2,"qty":0.06119900}],"asks":[],"checksum":3469157206,"timestamp":"2024-06-01T17:51:45.933864Z"}]}
{"channel":"book","type":"update","data":[{"symbol":"BTC/EUR","bids":[],"asks":[{"price":62375.6,"qty":1.47813337}],"checksum":730004849,"timestamp":"2024-06-01T17:51:45.966660Z"}]}
{"channel":"book","type":"update","data":[{"symbol":"BTC/EUR","bids":[{"price":62328.4,"qty":0.00000000},{"price":62328.3,"qty":2.21887673}],"asks":[],"checksum":4157020604,"timestamp":"2024-06-01T17:51:46.016164Z"}]}
{"channel":"book","type":"update","data":[{"symbol":"BTC/EUR","bids":[{"price":62341.4,"qty":7.18912348}],"asks":[],"checksum":1968454346,"timestamp":"2024-06-01T17:51:46.021298Z"}]}
{"channel":"book","type":"update","data":[{"symbol":"BTC/EUR","bids":[],"asks":[{"price":62377.7,"qty":0.00000000},{"price":62382.4,"qty":0.29576348},{"price":62375.5,"qty":0.00045408}],"checksum":2510991258,"timestamp":"2024-06-01T17:51:46.027499Z"}]}
{"channel":"book","type":"update","data":[{"symbol":"BTC/EUR","bids":[{"price":62363.1,"qty":6.32354828},{"price":62357.0,"qty":0.00853700}],"asks":[],"checksum":660609233,"timestamp":"2024-06-01T17:51:46.080411Z"}]}
{"channel":"book","type":"update","data":[{"symbol":"BTC/EUR","bids":[],"asks":[{"price":62380.2,"qty":0.00000000},{"price":62382.4,"qty":0.29576348},{"price":62373.5,"qty":0.00853600}],"checksum":4195095115,"timestamp":"2024-06-01T17:51:46.081178Z"}]}
{"channel":"book","type":"update","data":[{"symbol":"BTC/EUR","bids":[{"price":62363.1,"qty":6.44836967}],"asks":[],"checksum":873940080,"timestamp":"2024-06-01T17:51:46.220159Z"}]}
{"channel":"book","type":"update","data":[{"symbol":"BTC/EUR","bids":[],"asks":[{"price":62376.9,"qty":0.29576348}],"checksum":2863574924,"timestamp":"2024-06-01T17:51:46.344597Z"}]}
{"channel":"book","type":"update","data":[{"symbol":"BTC/EUR","bids":[{"price":62344.6,"qty":0.00000000},{"price":62328.5,"qty":0.47307000}],"asks":[],"checksum":2035445494,"timestamp":"2024-06-01T17:51:46.664782Z"}]}
{"channel":"book","type":"update","data":[{"symbol":"BTC/EUR","bids":[{"price":62341.5,"qty":0.03990584}],"asks":[],"checksum":4096554625,"timestamp":"2024-06-01T17:51:46.671124Z"}]}
{"channel":"book","type":"update","data":[{"symbol":"BTC/EUR","bids":[{"price":62360.1,"qty":1.47849741}],"asks":[],"checksum":4022492426,"timestamp":"2024-06-01T17:51:47.947620Z"}]}
{"channel":"book","type":"update","data":[{"symbol":"BTC/EUR","bids":[],"asks":[{"price":62372.9,"qty":1.47819616}],"checksum":1390762279,"timestamp":"2024-06-01T17:51:47.947639Z"}]}
{"channel":"book","type":"update","data":[{"symbol":"BTC/EUR","bids":[{"price":62363.1,"qty":6.32354828}],"asks":[],"checksum":3965684933,"timestamp":"2024-06-01T17:51:47.962607Z"}]}
{"channel":"book","type":"update","data":[{"symbol":"BTC/EUR","bids":[{"price":62363.1,"qty":4.84512075}],"asks":[],"checksum":1152144039,"timestamp":"2024-06-01T17:51:47.983641Z"}]}
{"channel":"book","type":"update","data":[{"symbol":"BTC/EUR","bids":[{"price":62356.9,"qty":1.89690100}],"asks":[],"checksum":2104479914,"timestamp":"2024-06-01T17:51:47.990054Z"}]}
{"channel":"book","type":"update","data":[{"symbol":"BTC/EUR","bids":[],"asks":[{"price":62372.9,"qty":0.00000000},{"price":62377.8,"qty":1.47808058}],"checksum":940420059,"timestamp":"2024-06-01T17:51:47.990232Z"}]}
{"channel":"book","type":"update","data":[{"symbol":"BTC/EUR","bids":[{"price":62356.9,"qty":0.41832661}],"asks":[],"checksum":4186658442,"timestamp":"2024-06-01T17:51:47.994592Z"}]}
{"channel":"book","type":"update","data":[{"symbol":"BTC/EUR","bids":[{"price":62363.1,"qty":6.32354828}],"asks":[],"checksum":1366853864,"timestamp":"2024-06-01T17:51:47.999139Z"}]}
{"channel":"book","type":"update","data":[{"symbol":"BTC/EUR","bids":[],"asks":[{"price":62375.5,"qty":0.00000000},{"price":62379.5,"qty":1.47803967},{"price":62372.7,"qty":0.00045355}],"checksum":161610669,"timestamp":"2024-06-01T17:51:48.005325Z"}]}
{"channel":"book","type":"update","data":[{"symbol":"BTC/EUR","bids":[],"asks":[{"price":62372.7,"qty":0.00000000},{"price":62379.5,"qty":1.47803967},{"price":62375.5,"qty":0.00045355}],"checksum":1495482014,"timestamp":"2024-06-01T17:51:48.066689Z"}]}
{"channel":"book","type":"update","data":[{"symbol":"BTC/EUR","bids":[{"price":62363.1,"qty":6.44836967}],"asks":[],"checksum":3885624188,"timestamp":"2024-06-01T17:51:48.084526Z"}]}
{"channel":"book","type":"update","data":[{"symbol":"BTC/EUR","bids":[{"price":62357.0,"qty":0.00000000},{"price":62338.3,"qty":0.03947498},{"price":62363.1,"qty":6.45690667}],"asks":[],"checksum":3163750535,"timestamp":"2024-06-01T17:51:48.125968Z"}]}
{"channel":"book","type":"update","data":[{"symbol":"BTC/EUR","bids":[{"price":62363.1,"qty":6.33208528}],"asks":[],"checksum":579099419,"timestamp":"2024-06-01T17:51:48.175233Z"}]}
{"channel":"book","type":"update","data":[{"symbol":"BTC/EUR","bids":[],"asks":[{"price":62373.3,"qty":1.47818586}],"checksum":565184748,"timestamp":"2024-06-01T17:51:48.249166Z"}]}
{"channel":"book","type":"update","data":[{"symbol":"BTC/EUR","bids":[],"asks":[{"price":62375.5,"qty":0.00000000},{"price":62377.8,"qty":1.47808058},{"price":62373.2,"qty":0.00045366}],"checksum":1602200160,"timestamp":"2024-06-01T17:51:48.299462Z"}]}
{"channel":"book","type":"update","data":[{"symbol":"BTC/EUR","bids":[{"price":62363.1,"qty":6.45690667}],"asks":[],"checksum":3244882428,"timestamp":"2024-06-01T17:51:48.317952Z"}]}
{"channel":"book","type":"update","data":[{"symbol":"BTC/EUR","bids":[{"price":62341.4,"qty":0.00000000},{"price":62328.5,"qty":0.47307000}],"asks":[],"checksum":2567912179,"timestamp":"2024-06-01T17:51:48.521526Z"}]}
{"channel":"book","type":"update","data":[{"symbol":"BTC/EUR","bids":[{"price":62341.6,"qty":6.87571488}],"asks":[],"checksum":3947804741,"timestamp":"2024-06-01T17:51:48.526696Z"}]}
{"channel":"book","type":"update","data":[{"symbol":"BTC/EUR","bids":[],"asks":[{"price":62373.3,"qty":0.00000000},{"price":62377.8,"qty":1.47808058}],"checksum":34484200,"timestamp":"2024-06-01T17:51:48.588188Z"}]}
{"channel":"book","type":"update","data":[{"symbol":"BTC/EUR","bids":[],"asks":[{"price":62373.2,"qty":0.00000000},{"price":62379.8,"qty":1.47803372},{"price":62375.5,"qty":0.00045366}],"checksum":3604156280,"timestamp":"2024-06-01T17:51:48.641361Z"}]}
{"channel":"book","type":"update","data":[{"symbol":"BTC/EUR","bids":[{"price":62341.5,"qty":0.00000000},{"price":62328.5,"qty":0.47307000}],"asks":[],"checksum":3248955657,"timestamp":"2024-06-01T17:51:48.905026Z"}]}
{"channel":"book","type":"update","data":[{"symbol":"BTC/EUR","bids":[{"price":62341.5,"qty":0.03916080}],"asks":[],"checksum":2440016090,"timestamp":"2024-06-01T17:51:48.908242Z"}]}
{"channel":"book","type":"update","data":[{"symbol":"BTC/EUR","bids":[],"asks":[{"price":62374.9,"qty":1.47815006}],"checksum":1495394796,"timestamp":"2024-06-01T17:51:49.545856Z"}]}
{"channel":"book","type":"update","data":[{"symbol":"BTC/EUR","bids":[],"asks":[{"price":62376.9,"qty":0.00000000},{"price":62377.8,"qty":1.47808058}],"checksum":846711762,"timestamp":"2024-06-01T17:51:49.577227Z"}]}
{"channel":"book","type":"update","data":[{"symbol":"BTC/EUR","bids":[],"asks":[{"price":62374.9,"qty":0.00000000},{"price":62383.0,"qty":0.54621000}],"checksum":1858033234,"timestamp":"2024-06-01T17:51:49.580822Z"}]}
{"channel":"book","type":"update","data":[{"symbol":"BTC/EUR","bids":[],"asks":[{"price":62375.6,"qty":0.00000000},{"price":62385.0,"qty":1.47791052}],"checksum":3066863854,"timestamp":"2024-06-01T17:51:49.587234Z"}]}
{"channel":"book","type":"update","data":[{"symbol":"BTC/EUR","bids":[],"asks":[{"price":62377.8,"qty":0.00000000},{"price":62388.0,"qty":0.22190000}],"checksum":801787003,"timestamp":"2024-06-01T17:51:49.593349Z"}]}
{"channel":"book","type":"update","data":[{"symbol":"BTC/EUR","bids":[{"price":62360.1,"qty":0.00000000},{"price":62328.5,"qty":0.47307000}],"asks":[],"checksum":4141704705,"timestamp":"2024-06-01T17:51:49.593384Z"}]}
{"channel":"book","type":"update","data":[{"symbol":"BTC/EUR","bids":[],"asks":[{"price":62375.5,"qty":0.00000000},{"price":62388.1,"qty":0.27459385},{"price":62374.8,"qty":0.00045366}],"checksum":895896412,"timestamp":"2024-06-01T17:51:49.608466Z"}]}
{"channel":"book","type":"update","data":[{"symbol":"BTC/EUR","bids":[],"asks":[{"price":62386.5,"qty":1.47787372}],"checksum":2950979538,"timestamp":"2024-06-01T17:51:49.610762Z"}]}
{"channel":"book","type":"update","data":[{"symbol":"BTC/EUR","bids":[{"price":62363.1,"qty":7.93533420}],"asks":[],"checksum":3863499766,"timestamp":"2024-06-01T17:51:49.610903Z"}]}
{"channel":"book","type":"update","data":[{"symbol":"BTC/EUR","bids":[],"asks":[{"price":62380.2,"qty":1.47802316}],"checksum":2879135186,"timestamp":"2024-06-01T17:51:49.610929Z"}]}
{"channel":"book","type":"update","data":[{"symbol":"BTC/EUR","bids":[],"asks":[{"price":62380.2,"qty":0.00000000},{"price":62386.5,"qty":1.47787372}],"checksum":3863499766,"timestamp":"2024-06-01T17:51:49.640530Z"}]}
{"channel":"book","type":"update","data":[{"symbol":"BTC/EUR","bids":[],"asks":[{"price":62386.5,"qty":0.00000000},{"price":62388.0,"qty":0.22190000}],"checksum":2093631352,"timestamp":"2024-06-01T17:51:49.640626Z"}]}
{"channel":"book","type":"update","data":[{"symbol":"BTC/EUR","bids":[],"asks":[{"price":62364.8,"qty":0.00000000},{"price":62388.1,"qty":0.27459385}],"checksum":1572782524,"timestamp":"2024-06-01T17:51:49.646448Z"}]}
{"channel":"book","type":"update","data":[{"symbol":"BTC/EUR","bids":[],"asks":[{"price":62374.8,"qty":0.00000000},{"price":62391.7,"qty":0.12247789},{"price":62380.1,"qty":0.00045366}],"checksum":2535526581,"timestamp":"2024-06-01T17:51:49.676327Z"}]}
{"channel":"book","type":"update","data":[{"symbol":"BTC/EUR","bids":[],"asks":[{"price":62380.1,"qty":0.00000000},{"price":62391.7,"qty":0.12247789},{"price":62382.9,"qty":0.00045366}],"checksum":1116144556,"timestamp":"2024-06-01T17:51:49.730990Z"}]}
{"channel":"book","type":"update","data":[{"symbol":"BTC/EUR","bids":[],"asks":[{"price":62388.0,"qty":0.00000000},{"price":62391.7,"qty":0.12247789},{"price":62382.9,"qty":0.22235366}],"checksum":746972699,"timestamp":"2024-06-01T17:51:49.732056Z"}]}
{"channel":"book","type":"update","data":[{"symbol":"BTC/EUR","bids":[],"asks":[{"price":62378.5,"qty":1.47806270}],"checksum":3780588091,"timestamp":"2024-06-01T17:51:49.735703Z"}]}
{"channel":"book","type":"update","data":[{"symbol":"BTC/EUR","bids":[],"asks":[{"price":62378.5,"qty":0.00000000},{"price":62391.7,"qty":0.12247789}],"checksum":746972699,"timestamp":"2024-06-01T17:51:49.760112Z"}]}
{"channel":"book","type":"update","data":[{"symbol":"BTC/EUR","bids":[],"asks":[{"price":62382.9,"qty":0.00045366}],"checksum":2232279226,"timestamp":"2024-06-01T17:51:49.762114Z"}]}
{"channel":"book","type":"update","data":[{"symbol":"BTC/EUR","bids":[],"asks":[{"price":62381.1,"qty":1.47800310}],"checksum":3226612650,"timestamp":"2024-06-01T17:51:49.764543Z"}]}
{"channel":"book","type":"update","data":[{"symbol":"BTC/EUR","bids":[],"asks":[{"price":62371.3,"qty":0.06649000}],"checksum":900357567,"timestamp":"2024-06-01T17:51:49.812088Z"}]}
{"channel":"book","type":"update","data":[{"symbol":"BTC/EUR","bids":[],"asks":[{"price":62382.9,"qty":0.00000000},{"price":62388.1,"qty":0.27459385},{"price":62381.0,"qty":0.00045366}],"checksum":708390615,"timestamp":"2024-06-01T17:51:49.922902Z"}]}
{"channel":"book","type":"update","data":[{"symbol":"BTC/EUR","bids":[],"asks":[{"price":62385.0,"qty":0.00000000},{"price":62388.1,"qty":0.27459385}],"checksum":8797574,"timestamp":"2024-06-01T17:51:50.053112Z"}]}
{"channel":"book","type":"update","data":[{"symbol":"BTC/EUR","bids":[],"asks":[{"price":62378.6,"qty":1.47806070}],"checksum":2018785824,"timestamp":"2024-06-01T17:51:50.057832Z"}]}
{"channel":"book","type":"update","data":[{"symbol":"BTC/EUR","bids":[],"asks":[{"price":62382.4,"qty":1.47797216}],"checksum":4042927070,"timestamp":"2024-06-01T17:51:50.057917Z"}]}
{"channel":"book","type":"update","data":[{"symbol":"BTC/EUR","bids":[],"asks":[{"price":62381.0,"qty":0.00000000},{"price":62383.0,"qty":0.54621000},{"price":62378.5,"qty":0.00045366}],"checksum":2527085947,"timestamp":"2024-06-01T17:51:50.261224Z"}]}
{"channel":"book","type":"update","data":[{"symbol":"BTC/EUR","bids":[{"price":62349.8,"qty":1.10898351}],"asks":[],"checksum":164578996,"timestamp":"2024-06-01T17:51:50.660407Z"}]}
{"channel":"book","type":"update","data":[{"symbol":"BTC/EUR","bids":[{"price":62341.6,"qty":0.00000000},{"price":62328.5,"qty":0.47307000}],"asks":[],"checksum":259413063,"timestamp":"2024-06-01T17:51:51.058870Z"}]}
{"channel":"book","type":"update","data":[{"symbol":"BTC/EUR","bids":[{"price":62341.6,"qty":6.11793567}],"asks":[],"checksum":2583278286,"timestamp":"2024-06-01T17:51:51.061828Z"}]}
{"channel":"book","type":"update","data":[{"symbol":"BTC/EUR","bids":[{"price":62341.5,"qty":0.00000000},{"price":62328.5,"qty":0.47307000}],"asks":[],"checksum":3681903478,"timestamp":"2024-06-01T17:51:51.161724Z"}]}
{"channel":"book","type":"update","data":[{"symbol":"BTC/EUR","bids":[{"price":62341.7,"qty":0.04059207}],"asks":[],"checksum":1130086847,"timestamp":"2024-06-01T17:51:51.170097Z"}]}
{"channel":"book","type":"update","data":[{"symbol":"BTC/EUR","bids":[{"price":62363.1,"qty":7.81051281}],"asks":[],"checksum":4129264698,"timestamp":"2024-06-01T17:51:51.365918Z"}]}
{"channel":"book","type":"update","data":[{"symbol":"BTC/EUR","bids":[{"price":62363.1,"qty":7.93533420}],"asks":[],"checksum":1130086847,"timestamp":"2024-06-01T17:51:51.487284Z"}]}
{"channel":"book","type":"update","data":[{"symbol":"BTC/EUR","bids":[],"asks":[{"price":62378.6,"qty":0.00000000},{"price":62383.0,"qty":0.54621000}],"checksum":1089078852,"timestamp":"2024-06-01T17:51:51.599396Z"}]}
{"channel":"book","type":"update","data":[{"symbol":"BTC/EUR","bids":[],"asks":[{"price":62378.5,"qty":0.00000000},{"price":62383.8,"qty":0.29572893},{"price":62381.0,"qty":0.00045366}],"checksum":9941262,"timestamp":"2024-06-01T17:51:51.643068Z"}]}
{"channel":"book","type":"update","data":[{"symbol":"BTC/EUR","bids":[],"asks":[{"price":62382.4,"qty":1.77370109}],"checksum":3144144432,"timestamp":"2024-06-01T17:51:51.682690Z"}]}
{"channel":"book","type":"update","data":[{"symbol":"BTC/EUR","bids":[],"asks":[{"price":62373.5,"qty":0.00000000},{"price":62383.8,"qty":0.29572893},{"price":62378.0,"qty":0.00853600}],"checksum":1394307584,"timestamp":"2024-06-01T17:51:52.252927Z"}]}
{"channel":"book","type":"update","data":[{"symbol":"BTC/EUR","bids":[{"price":62363.1,"qty":7.90354960}],"asks":[],"checksum":2693845408,"timestamp":"2024-06-01T17:51:52.284460Z"}]}
{"channel":"book","type":"update","data":[{"symbol":"BTC/EUR","bids":[{"price":62363.1,"qty":7.77872821}],"asks":[],"checksum":3488390752,"timestamp":"2024-06-01T17:51:52.315601Z"}]}
{"channel":"book","type":"update","data":[{"symbol":"BTC/EUR","bids":[],"asks":[{"price":62378.8,"qty":1.47805623}],"checksum":3653644691,"timestamp":"2024-06-01T17:51:52.335549Z"}]}
{"channel":"book","type":"update","data":[{"symbol":"BTC/EUR","bids":[],"asks":[{"price":62381.0,"qty":0.00000000},{"price":62383.0,"qty":0.54621000},{"price":62378.7,"qty":0.00045367}],"checksum":1603243975,"timestamp":"2024-06-01T17:51:52.390470Z"}]}
{"channel":"book","type":"update","data":[{"symbol":"BTC/EUR","bids":[{"price":62363.1,"qty":7.90354960}],"asks":[],"checksum":821280775,"timestamp":"2024-06-01T17:51:52.431996Z"}]}
{"channel":"book","type":"update","data":[{"symbol":"BTC/EUR","bids":[],"asks":[{"price":62378.7,"qty":0.12765981}],"checksum":407463127,"timestamp":"2024-06-01T17:51:52.851942Z"}]}
{"channel":"book","type":"update","data":[{"symbol":"BTC/EUR","bids":[],"asks":[{"price":62378.7,"qty":0.12720614},{"price":62378.6,"qty":0.00042897}],"checksum":257544331,"timestamp":"2024-06-01T17:51:52.901167Z"}]}
{"channel":"book","type":"update","data":[{"symbol":"BTC/EUR","bids":[],"asks":[{"price":62378.7,"qty":0.00000000},{"price":62382.4,"qty":1.77370109}],"checksum":3927006880,"timestamp":"2024-06-01T17:51:53.207352Z"}]}
{"channel":"book","type":"update","data":[{"symbol":"BTC/EUR","bids":[],"asks":[{"price":62378.6,"qty":0.00000000},{"price":62383.0,"qty":0.54621000},{"price":62378.7,"qty":0.00042897}],"checksum":899795164,"timestamp":"2024-06-01T17:51:53.262565Z"}]}
{"channel":"book","type":"update","data":[{"symbol":"BTC/EUR","bids":[{"price":62341.7,"qty":0.00000000},{"price":62328.5,"qty":0.47307000}],"asks":[],"checksum":263760285,"timestamp":"2024-06-01T17:51:53.400737Z"}]}
{"channel":"book","type":"update","data":[{"symbol":"BTC/EUR","bids":[{"price":62341.7,"qty":0.04473683}],"asks":[],"checksum":2717400745,"timestamp":"2024-06-01T17:51:53.442665Z"}]}
{"channel":"book","type":"update","data":[{"symbol":"BTC/EUR","bids":[{"price":62341.6,"qty":0.00000000},{"price":62328.5,"qty":0.47307000}],"asks":[],"checksum":1553220852,"timestamp":"2024-06-01T17:51:53.568599Z"}]}
{"channel":"book","type":"update","data":[{"symbol":"BTC/EUR","bids":[{"price":62341.4,"qty":6.01253356}],"asks":[],"checksum":4105850520,"timestamp":"2024-06-01T17:51:53.571243Z"}]}
{"channel":"book","type":"update","data":[{"symbol":"BTC/EUR","bids":[{"price":62363.1,"qty":7.77872821}],"asks":[],"checksum":2613444952,"timestamp":"2024-06-01T17:51:53.897248Z"}]}
{"channel":"book","type":"update","data":[{"symbol":"BTC/EUR","bids":[{"price":62363.1,"qty":7.90354960}],"asks":[],"checksum":4105850520,"timestamp":"2024-06-01T17:51:54.021004Z"}]}
{"channel":"book","type":"update","data":[{"symbol":"BTC/EUR","bids":[{"price":62363.1,"qty":7.77872821}],"asks":[],"checksum":2613444952,"timestamp":"2024-06-01T17:51:54.031748Z"}]}
{"channel":"book","type":"update","data":[{"symbol":"BTC/EUR","bids":[{"price":62363.1,"qty":7.90354960}],"asks":[],"checksum":4105850520,"timestamp":"2024-06-01T17:51:54.150583Z"}]}
{"channel":"book","type":"update","data":[{"symbol":"BTC/EUR","bids":[{"price":62349.8,"qty":0.00000000},{"price":62328.5,"qty":0.47307000}],"asks":[],"checksum":1019244275,"timestamp":"2024-06-01T17:51:54.688817Z"}]}
{"channel":"book","type":"update","data":[{"symbol":"BTC/EUR","bids":[{"price":62356.9,"qty":0.00000000},{"price":62328.3,"qty":2.21887673}],"asks":[],"checksum":898872076,"timestamp":"2024-06-01T17:51:55.444376Z"}]}
{"channel":"book","type":"update","data":[{"symbol":"BTC/EUR","bids":[{"price":62363.1,"qty":8.31205951}],"asks":[],"checksum":651273768,"timestamp":"2024-06-01T17:51:55.449284Z"}]}
{"channel":"book","type":"update","data":[{"symbol":"BTC/EUR","bids":[],"asks":[{"price":62382.4,"qty":1.47797216}],"checksum":1361417268,"timestamp":"2024-06-01T17:51:55.532455Z"}]}
{"channel":"book","type":"update","data":[{"symbol":"BTC/EUR","bids":[{"price":62341.7,"qty":0.00000000},{"price":62314.4,"qty":0.00200000}],"asks":[],"checksum":2427888108,"timestamp":"2024-06-01T17:51:55.568356Z"}]}
{"channel":"book","type":"update","data":[{"symbol":"BTC/EUR","bids":[{"price":62341.5,"qty":0.05049347}],"asks":[],"checksum":990423966,"timestamp":"2024-06-01T17:51:55.573184Z"}]}
{"channel":"book","type":"update","data":[{"symbol":"BTC/EUR","bids":[{"price":62341.4,"qty":0.00000000},{"price":62314.4,"qty":0.00200000}],"asks":[],"checksum":936583104,"timestamp":"2024-06-01T17:51:55.907035Z"}]}
{"channel":"book","type":"update","data":[{"symbol":"BTC/EUR","bids":[{"price":62341.4,"qty":6.37830604}],"asks":[],"checksum":3982760722,"timestamp":"2024-06-01T17:51:55.909329Z"}]}
{"channel":"book","type":"update","data":[{"symbol":"BTC/EUR","bids":[],"asks":[{"price":62378.8,"qty":0.00000000},{"price":62383.0,"qty":0.54621000}],"checksum":1087816443,"timestamp":"2024-06-01T17:51:55.951752Z"}]}
{"channel":"book","type":"update","data":[{"symbol":"BTC/EUR","bids":[],"asks":[{"price":62378.7,"qty":0.00000000},{"price":62385.0,"qty":1.47790988},{"price":62381.0,"qty":0.00042898}],"checksum":740783453,"timestamp":"2024-06-01T17:51:56.022583Z"}]}
{"channel":"book","type":"update","data":[{"symbol":"BTC/EUR","bids":[{"price":62363.1,"qty":8.31194718},{"price":62341.6,"qty":0.00012522}],"asks":[],"checksum":1200723651,"timestamp":"2024-06-01T17:51:56.101083Z"}]}
{"channel":"book","type":"update","data":[{"symbol":"BTC/EUR","bids":[],"asks":[{"price":62381.1,"qty":0.00000000},{"price":62384.9,"qty":0.12921474}],"checksum":1681693009,"timestamp":"2024-06-01T17:51:56.121779Z"}]}
{"channel":"book","type":"update","data":[{"symbol":"BTC/EUR","bids":[],"asks":[{"price":62382.3,"qty":1.47797287}],"checksum":2522476210,"timestamp":"2024-06-01T17:51:56.150674Z"}]}
{"channel":"book","type":"update","data":[{"symbol":"BTC/EUR","bids":[{"price":62352.3,"qty":1.10892120}],"asks":[],"checksum":3735652546,"timestamp":"2024-06-01T17:51:56.155242Z"}]}
{"channel":"book","type":"update","data":[{"symbol":"BTC/EUR","bids":[{"price":62341.6,"qty":0.00000000},{"price":62328.5,"qty":0.47307000},{"price":62363.1,"qty":8.31207236}],"asks":[],"checksum":2123700622,"timestamp":"2024-06-01T17:51:56.168398Z"}]}
{"channel":"book","type":"update","data":[{"symbol":"BTC/EUR","bids":[],"asks":[{"price":62381.0,"qty":0.00000000},{"price":62384.9,"qty":0.12921474},{"price":62382.3,"qty":1.47840185}],"checksum":3862574874,"timestamp":"2024-06-01T17:51:56.168435Z"}]}
{"channel":"book","type":"update","data":[{"symbol":"BTC/EUR","bids":[],"asks":[{"price":62382.3,"qty":1.47797287},{"price":62382.2,"qty":0.00042898}],"checksum":3199720530,"timestamp":"2024-06-01T17:51:56.429118Z"}]}
{"channel":"book","type":"update","data":[{"symbol":"BTC/EUR","bids":[],"asks":[{"price":62375.1,"qty":0.00000000},{"price":62384.9,"qty":0.12921474}],"checksum":2479058407,"timestamp":"2024-06-01T17:51:56.510679Z"}]}
{"channel":"book","type":"update","data":[{"symbol":"BTC/EUR","bids":[],"asks":[{"price":62363.2,"qty":0.03142443}],"checksum":2944814068,"timestamp":"2024-06-01T17:51:56.819398Z"}]}
{"channel":"book","type":"update","data":[{"symbol":"BTC/EUR","bids":[{"price":62350.6,"qty":2.21808371}],"asks":[],"checksum":4201670134,"timestamp":"2024-06-01T17:51:57.153277Z"}]}
{"channel":"book","type":"update","data":[{"symbol":"BTC/EUR","bids":[],"asks":[{"price":62382.2,"qty":0.22232898}],"checksum":124142183,"timestamp":"2024-06-01T17:51:57.482601Z"}]}
{"channel":"book","type":"update","data":[{"symbol":"BTC/EUR","bids":[],"asks":[{"price":62382.2,"qty":0.22190000},{"price":62382.1,"qty":0.00042898}],"checksum":1446906763,"timestamp":"2024-06-01T17:51:57.531772Z"}]}
{"channel":"book","type":"update","data":[{"symbol":"BTC/EUR","bids":[{"price":62341.3,"qty":0.00000000},{"price":62328.5,"qty":0.47307000}],"asks":[],"checksum":2174405171,"timestamp":"2024-06-01T17:51:57.575619Z"}]}
{"channel":"book","type":"update","data":[{"symbol":"BTC/EUR","bids":[{"price":62341.5,"qty":0.00000000},{"price":62328.3,"qty":2.21887673}],"asks":[],"checksum":749018901,"timestamp":"2024-06-01T17:51:57.712426Z"}]}
{"channel":"book","type":"update","data":[{"symbol":"BTC/EUR","bids":[{"price":62350.7,"qty":0.02953811}],"asks":[],"checksum":3704551997,"timestamp":"2024-06-01T17:51:57.717842Z"}]}
{"channel":"book","type":"update","data":[{"symbol":"BTC/EUR","bids":[{"price":62341.4,"qty":0.00000000},{"price":62328.3,"qty":2.21887673}],"asks":[],"checksum":2835602509,"timestamp":"2024-06-01T17:51:58.461163Z"}]}
{"channel":"book","type":"update","data":[{"symbol":"BTC/EUR","bids":[{"price":62352.4,"qty":4.75826312}],"asks":[],"checksum":1084557539,"timestamp":"2024-06-01T17:51:58.463342Z"}]}
{"channel":"book","type":"update","data":[{"symbol":"BTC/EUR","bids":[],"asks":[{"price":62372.8,"qty":0.00000000},{"price":62384.9,"qty":0.12921474}],"checksum":64424642,"timestamp":"2024-06-01T17:51:59.172441Z"}]}
{"channel":"book","type":"update","data":[{"symbol":"BTC/EUR","bids":[],"asks":[{"price":62382.2,"qty":0.00000000},{"price":62385.0,"qty":1.47790988}],"checksum":2832966458,"timestamp":"2024-06-01T17:51:59.184705Z"}]}
{"channel":"book","type":"update","data":[{"symbol":"BTC/EUR","bids":[],"asks":[{"price":62384.2,"qty":0.22190000}],"checksum":55901957,"timestamp":"2024-06-01T17:51:59.226815Z"}]}
{"channel":"book","type":"update","data":[{"symbol":"BTC/EUR","bids":[],"asks":[{"price":62384.2,"qty":0.00000000},{"price":62385.0,"qty":1.47790988}],"checksum":2832966458,"timestamp":"2024-06-01T17:51:59.231821Z"}]}
{"channel":"book","type":"update","data":[{"symbol":"BTC/EUR","bids":[],"asks":[{"price":62382.3,"qty":0.00000000},{"price":62388.1,"qty":0.27459385}],"checksum":1291183924,"timestamp":"2024-06-01T17:51:59.232277Z"}]}
{"channel":"book","type":"update","data":[{"symbol":"BTC/EUR","bids":[],"asks":[{"price":62387.6,"qty":1.47784764}],"checksum":870291483,"timestamp":"2024-06-01T17:51:59.236411Z"}]}
{"channel":"book","type":"update","data":[{"symbol":"BTC/EUR","bids":[],"asks":[{"price":62382.1,"qty":0.00000000},{"price":62388.1,"qty":0.27459385},{"price":62382.2,"qty":0.00042898}],"checksum":3719384506,"timestamp":"2024-06-01T17:51:59.243452Z"}]}
{"channel":"book","type":"update","data":[{"symbol":"BTC/EUR","bids":[{"price":62345.0,"qty":0.03947498}],"asks":[],"checksum":1755225144,"timestamp":"2024-06-01T17:51:59.248045Z"}]}
{"channel":"book","type":"update","data":[{"symbol":"BTC/EUR","bids":[],"asks":[{"price":62382.4,"qty":0.00000000},{"price":62388.1,"qty":0.27459385}],"checksum":4026851281,"timestamp":"2024-06-01T17:51:59.251976Z"}]}
{"channel":"book","type":"update","data":[{"symbol":"BTC/EUR","bids":[],"asks":[{"price":62384.9,"qty":1.60712649}],"checksum":2352505779,"timestamp":"2024-06-01T17:51:59.256934Z"}]}
{"channel":"book","type":"update","data":[{"symbol":"BTC/EUR","bids":[],"asks":[{"price":62382.2,"qty":0.00000000},{"price":62391.5,"qty":0.29571232},{"price":62382.9,"qty":0.00042898}],"checksum":2186202431,"timestamp":"2024-06-01T17:51:59.313582Z"}]}
{"channel":"book","type":"update","data":[{"symbol":"BTC/EUR","bids":[{"price":62338.3,"qty":0.00000000},{"price":62328.5,"qty":0.47307000}],"asks":[],"checksum":3502873118,"timestamp":"2024-06-01T17:51:59.317895Z"}]}
{"channel":"book","type":"update","data":[{"symbol":"BTC/EUR","bids":[],"asks":[{"price":62382.6,"qty":0.03947498}],"checksum":1675719926,"timestamp":"2024-06-01T17:51:59.318234Z"}]}
{"channel":"book","type":"update","data":[{"symbol":"BTC/EUR","bids":[],"asks":[{"price":62385.0,"qty":0.00000000},{"price":62388.1,"qty":0.27459385}],"checksum":148395788,"timestamp":"2024-06-01T17:51:59.328875Z"}]}
{"channel":"book","type":"update","data":[{"symbol":"BTC/EUR","bids":[],"asks":[{"price":62382.7,"qty":1.47796452}],"checksum":1241403376,"timestamp":"2024-06-01T17:51:59.333046Z"}]}
{"channel":"book","type":"update","data":[{"symbol":"BTC/EUR","bids":[],"asks":[{"price":62382.9,"qty":0.00000000},{"price":62388.1,"qty":0.27459385},{"price":62384.8,"qty":0.00042898}],"checksum":1848745086,"timestamp":"2024-06-01T17:51:59.360938Z"}]}
{"channel":"book","type":"update","data":[{"symbol":"BTC/EUR","bids":[],"asks":[{"price":62384.8,"qty":0.00000000},{"price":62388.1,"qty":0.27459385}],"checksum":2080454997,"timestamp":"2024-06-01T17:51:59.482431Z"}]}
{"channel":"book","type":"update","data":[{"symbol":"BTC/EUR","bids":[],"asks":[{"price":62378.0,"qty":0.00000000},{"price":62391.4,"qty":0.00042898},{"price":62380.9,"qty":0.00853500}],"checksum":2281130732,"timestamp":"2024-06-01T17:51:59.505147Z"}]}
{"channel":"book","type":"update","data":[{"symbol":"BTC/EUR","bids":[],"asks":[{"price":62382.5,"qty":0.00042898}],"checksum":3026375814,"timestamp":"2024-06-01T17:51:59.538346Z"}]}
{"channel":"book","type":"update","data":[{"symbol":"BTC/EUR","bids":[{"price":62350.7,"qty":0.00000000},{"price":62328.3,"qty":2.21887673}],"asks":[],"checksum":2807070156,"timestamp":"2024-06-01T17:51:59.962264Z"}]}
{"channel":"book","type":"update","data":[{"symbol":"BTC/EUR","bids":[{"price":62352.5,"qty":0.03385268}],"asks":[],"checksum":1221082459,"timestamp":"2024-06-01T17:51:59.967104Z"}]}
{"channel":"book","type":"update","data":[{"symbol":"BTC/EUR","bids":[],"asks":[{"price":62382.5,"qty":0.00000000},{"price":62391.5,"qty":0.29571232},{"price":62382.6,"qty":0.03990396}],"checksum":2573761467,"timestamp":"2024-06-01T17:52:00.171181Z"}]}
{"channel":"book","type":"update","data":[{"symbol":"BTC/EUR","bids":[],"asks":[{"price":62382.6,"qty":0.03947498},{"price":62391.4,"qty":0.00042898}],"checksum":380866058,"timestamp":"2024-06-01T17:52:00.241611Z"}]}
{"channel":"book","type":"update","data":[{"symbol":"BTC/EUR","bids":[],"asks":[{"price":62386.3,"qty":0.22190000}],"checksum":3873206052,"timestamp":"2024-06-01T17:52:00.244538Z"}]}
{"channel":"book","type":"update","data":[{"symbol":"BTC/EUR","bids":[],"asks":[{"price":62384.8,"qty":0.00042898}],"checksum":3766794057,"timestamp":"2024-06-01T17:52:00.388688Z"}]}
{"channel":"book","type":"update","data":[{"symbol":"BTC/EUR","bids":[],"asks":[{"price":62386.3,"qty":0.00000000},{"price":62387.6,"qty":1.47784764}],"checksum":2162693318,"timestamp":"2024-06-01T17:52:00.602528Z"}]}
{"channel":"book","type":"update","data":[{"symbol":"BTC/EUR","bids":[{"price":62352.4,"qty":0.00000000},{"price":62328.3,"qty":2.21887673}],"asks":[],"checksum":3168288855,"timestamp":"2024-06-01T17:52:00.841255Z"}]}
{"channel":"book","type":"update","data":[{"symbol":"BTC/EUR","bids":[{"price":62352.4,"qty":4.68022020}],"asks":[],"checksum":3199539837,"timestamp":"2024-06-01T17:52:00.843551Z"}]}
{"channel":"book","type":"update","data":[{"symbol":"BTC/EUR","bids":[],"asks":[{"price":62384.8,"qty":0.00000000},{"price":62391.5,"qty":0.29571232},{"price":62382.5,"qty":0.00042898}],"checksum":1989489632,"timestamp":"2024-06-01T17:52:00.924496Z"}]}
{"channel":"book","type":"update","data":[{"symbol":"BTC/EUR","bids":[],"asks":[{"price":62382.5,"qty":0.00000000},{"price":62391.5,"qty":0.29571232},{"price":62384.8,"qty":0.00042898}],"checksum":3199539837,"timestamp":"2024-06-01T17:52:00.987402Z"}]}
{"channel":"book","type":"update","data":[{"symbol":"BTC/EUR","bids":[],"asks":[{"price":62384.8,"qty":0.00000000},{"price":62391.5,"qty":0.29571232},{"price":62382.5,"qty":0.00042898}],"checksum":1989489632,"timestamp":"2024-06-01T17:52:01.177121Z"}]}
{"channel":"book","type":"update","data":[{"symbol":"BTC/EUR","bids":[],"asks":[{"price":62382.5,"qty":0.00000000},{"price":62391.5,"qty":0.29571232},{"price":62391.4,"qty":0.00042898}],"checksum":686719153,"timestamp":"2024-06-01T17:52:01.233406Z"}]}
{"channel":"book","type":"update","data":[{"symbol":"BTC/EUR","bids":[],"asks":[{"price":62386.7,"qty":0.22190000}],"checksum":3201622771,"timestamp":"2024-06-01T17:52:01.468983Z"}]}
{"channel":"book","type":"update","data":[{"symbol":"BTC/EUR","bids":[],"asks":[{"price":62384.8,"qty":0.00042898}],"checksum":2625313034,"timestamp":"2024-06-01T17:52:01.488453Z"}]}
{"channel":"book","type":"update","data":[{"symbol":"BTC/EUR","bids":[],"asks":[{"price":62384.8,"qty":0.00000000},{"price":62387.6,"qty":1.47784764},{"price":62382.5,"qty":0.00042898}],"checksum":1795359800,"timestamp":"2024-06-01T17:52:01.863363Z"}]}
{"channel":"book","type":"update","data":[{"symbol":"BTC/EUR","bids":[{"price":62352.5,"qty":0.00000000},{"price":62328.3,"qty":2.21887673}],"asks":[],"checksum":1929222723,"timestamp":"2024-06-01T17:52:02.022994Z"}]}
{"channel":"book","type":"update","data":[{"symbol":"BTC/EUR","bids":[{"price":62352.5,"qty":0.03022872}],"asks":[],"checksum":2543779888,"timestamp":"2024-06-01T17:52:02.028358Z"}]}
{"channel":"book","type":"update","data":[{"symbol":"BTC/EUR","bids":[],"asks":[{"price":62382.5,"qty":0.00000000},{"price":62387.6,"qty":1.47784764},{"price":62384.8,"qty":0.00042898}],"checksum":1625758978,"timestamp":"2024-06-01T17:52:02.078795Z"}]}
{"channel":"book","type":"update","data":[{"symbol":"BTC/EUR","bids":[],"asks":[{"price":62382.7,"qty":0.00000000},{"price":62387.6,"qty":1.47784764}],"checksum":3636123581,"timestamp":"2024-06-01T17:52:02.225178Z"}]}
{"channel":"book","type":"update","data":[{"symbol":"BTC/EUR","bids":[],"asks":[{"price":62386.7,"qty":0.00000000},{"price":62391.5,"qty":0.29571232},{"price":62387.5,"qty":0.22190000}],"checksum":4203251767,"timestamp":"2024-06-01T17:52:02.228170Z"}]}
{"channel":"book","type":"update","data":[{"symbol":"BTC/EUR","bids":[],"asks":[{"price":62384.9,"qty":1.47791175}],"checksum":1700437800,"timestamp":"2024-06-01T17:52:02.322585Z"}]}
{"channel":"book","type":"update","data":[{"symbol":"BTC/EUR","bids":[],"asks":[{"price":62384.8,"qty":0.00000000},{"price":62388.6,"qty":1.47782518},{"price":62387.4,"qty":0.00042898}],"checksum":771242234,"timestamp":"2024-06-01T17:52:02.443403Z"}]}
{"channel":"book","type":"update","data":[{"symbol":"BTC/EUR","bids":[],"asks":[{"price":62380.8,"qty":0.12264150}],"checksum":1699272602,"timestamp":"2024-06-01T17:52:02.447065Z"}]}
{"channel":"book","type":"update","data":[{"symbol":"BTC/EUR","bids":[],"asks":[{"price":62387.5,"qty":0.00000000},{"price":62387.6,"qty":1.47784764}],"checksum":2091050625,"timestamp":"2024-06-01T17:52:02.604037Z"}]}
{"channel":"book","type":"update","data":[{"symbol":"BTC/EUR","bids":[],"asks":[{"price":62387.4,"qty":0.00000000},{"price":62388.3,"qty":0.22190000},{"price":62384.8,"qty":0.00042898}],"checksum":1382220164,"timestamp":"2024-06-01T17:52:02.845613Z"}]}
{"channel":"book","type":"update","data":[{"symbol":"BTC/EUR","bids":[],"asks":[{"price":62384.8,"qty":0.00000000},{"price":62388.3,"qty":0.22190000},{"price":62387.5,"qty":0.00042898}],"checksum":3695923394,"timestamp":"2024-06-01T17:52:03.083869Z"}]}
{"channel":"book","type":"update","data":[{"symbol":"BTC/EUR","bids":[],"asks":[{"price":62384.9,"qty":0.00000000},{"price":62388.6,"qty":1.47782518}],"checksum":147829676,"timestamp":"2024-06-01T17:52:03.161784Z"}]}
{"channel":"book","type":"update","data":[{"symbol":"BTC/EUR","bids":[],"asks":[{"price":62385.2,"qty":1.47790518}],"checksum":726039578,"timestamp":"2024-06-01T17:52:03.184008Z"}]}
{"channel":"book","type":"update","data":[{"symbol":"BTC/EUR","bids":[],"asks":[{"price":62371.3,"qty":0.00000000},{"price":62388.6,"qty":1.47782518}],"checksum":1668839494,"timestamp":"2024-06-01T17:52:03.233400Z"}]}
{"channel":"book","type":"update","data":[{"symbol":"BTC/EUR","bids":[],"asks":[{"price":62380.9,"qty":0.00000000},{"price":62391.9,"qty":0.79104677},{"price":62390.2,"qty":0.00853500}],"checksum":4075501029,"timestamp":"2024-06-01T17:52:03.298867Z"}]}
{"channel":"book","type":"update","data":[{"symbol":"BTC/EUR","bids":[],"asks":[{"price":62387.5,"qty":0.00000000},{"price":62391.9,"qty":0.79104677},{"price":62385.1,"qty":0.00042898}],"checksum":303908306,"timestamp":"2024-06-01T17:52:03.320946Z"}]}
{"channel":"book","type":"update","data":[{"symbol":"BTC/EUR","bids":[{"price":62352.4,"qty":0.00000000},{"price":62328.3,"qty":2.21887673}],"asks":[],"checksum":275783672,"timestamp":"2024-06-01T17:52:03.340571Z"}]}
{"channel":"book","type":"update","data":[{"symbol":"BTC/EUR","bids":[],"asks":[{"price":62380.8,"qty":0.00000000},{"price":62391.9,"qty":0.79104677}],"checksum":3267309005,"timestamp":"2024-06-01T17:52:03.341768Z"}]}
{"channel":"book","type":"update","data":[{"symbol":"BTC/EUR","bids":[{"price":62352.4,"qty":4.83698368}],"asks":[],"checksum":2186321157,"timestamp":"2024-06-01T17:52:03.342773Z"}]}
{"channel":"book","type":"update","data":[{"symbol":"BTC/EUR","bids":[],"asks":[{"price":62385.2,"qty":0.00000000},{"price":62392.7,"qty":0.29570489}],"checksum":2002303158,"timestamp":"2024-06-01T17:52:03.354752Z"}]}
{"channel":"book","type":"update","data":[{"symbol":"BTC/EUR","bids":[],"asks":[{"price":62372.1,"qty":0.05456000}],"checksum":434296849,"timestamp":"2024-06-01T17:52:03.380095Z"}]}
{"channel":"book","type":"update","data":[{"symbol":"BTC/EUR","bids":[],"asks":[{"price":62385.1,"qty":0.00000000},{"price":62392.7,"qty":0.29570489},{"price":62387.5,"qty":0.00042898}],"checksum":1618363752,"timestamp":"2024-06-01T17:52:03.380598Z"}]}
{"channel":"book","type":"update","data":[{"symbol":"BTC/EUR","bids":[],"asks":[{"price":62387.4,"qty":0.12264150}],"checksum":3943673068,"timestamp":"2024-06-01T17:52:03.522410Z"}]}
{"channel":"book","type":"update","data":[{"symbol":"BTC/EUR","bids":[],"asks":[{"price":62387.5,"qty":0.00000000},{"price":62391.9,"qty":0.79104677},{"price":62387.3,"qty":0.00042898}],"checksum":1655230312,"timestamp":"2024-06-01T17:52:03.745946Z"}]}
{"channel":"book","type":"update","data":[{"symbol":"BTC/EUR","bids":[{"price":62355.8,"qty":1.10889332}],"asks":[],"checksum":303426619,"timestamp":"2024-06-01T17:52:03.856377Z"}]}
{"channel":"book","type":"update","data":[{"symbol":"BTC/EUR","bids":[{"price":62352.5,"qty":0.00000000},{"price":62328.5,"qty":0.47307000}],"asks":[],"checksum":153944001,"timestamp":"2024-06-01T17:52:04.281908Z"}]}
{"channel":"book","type":"update","data":[{"symbol":"BTC/EUR","bids":[{"price":62352.5,"qty":0.03322149}],"asks":[],"checksum":1590627567,"timestamp":"2024-06-01T17:52:04.288600Z"}]}
{"channel":"book","type":"update","data":[{"symbol":"BTC/EUR","bids":[],"asks":[{"price":62385.3,"qty":1.47790309}],"checksum":1212585464,"timestamp":"2024-06-01T17:52:05.078539Z"}]}
{"channel":"book","type":"update","data":[{"symbol":"BTC/EUR","bids":[],"asks":[{"price":62387.3,"qty":0.00000000},{"price":62390.2,"qty":0.00853500},{"price":62387.5,"qty":0.00042881}],"checksum":1420423718,"timestamp":"2024-06-01T17:52:05.144187Z"}]}
{"channel":"book","type":"update","data":[{"symbol":"BTC/EUR","bids":[],"asks":[{"price":62386.4,"qty":0.00853500}],"checksum":978990775,"timestamp":"2024-06-01T17:52:05.254539Z"}]}
{"channel":"book","type":"update","data":[{"symbol":"BTC/EUR","bids":[{"price":62352.4,"qty":0.00000000},{"price":62328.5,"qty":0.47307000}],"asks":[],"checksum":2001743755,"timestamp":"2024-06-01T17:52:05.700464Z"}]}
{"channel":"book","type":"update","data":[{"symbol":"BTC/EUR","bids":[{"price":62355.9,"qty":4.91501512}],"asks":[],"checksum":1967073592,"timestamp":"2024-06-01T17:52:05.702625Z"}]}
{"channel":"book","type":"update","data":[{"symbol":"BTC/EUR","bids":[],"asks":[{"price":62387.5,"qty":0.00000000},{"price":62388.6,"qty":1.47782518},{"price":62385.2,"qty":0.00042881}],"checksum":3656114643,"timestamp":"2024-06-01T17:52:05.876458Z"}]}
{"channel":"book","type":"update","data":[{"symbol":"BTC/EUR","bids":[{"price":62363.1,"qty":8.31662150}],"asks":[],"checksum":1776073214,"timestamp":"2024-06-01T17:52:05.929572Z"}]}
{"channel":"book","type":"update","data":[{"symbol":"BTC/EUR","bids":[{"price":62352.5,"qty":0.00000000},{"price":62328.5,"qty":0.47307000}],"asks":[],"checksum":3744739420,"timestamp":"2024-06-01T17:52:06.438449Z"}]}
{"channel":"book","type":"update","data":[{"symbol":"BTC/EUR","bids":[{"price":62356.0,"qty":0.02308972}],"asks":[],"checksum":2786039599,"timestamp":"2024-06-01T17:52:06.443569Z"}]}
{"channel":"book","type":"update","data":[{"symbol":"BTC/EUR","bids":[],"asks":[{"price":62385.2,"qty":0.00000000},{"price":62388.6,"qty":1.47782518},{"price":62387.5,"qty":0.00042883}],"checksum":3917672266,"timestamp":"2024-06-01T17:52:07.361213Z"}]}
{"channel":"book","type":"update","data":[{"symbol":"BTC/EUR","bids":[],"asks":[{"price":62387.5,"qty":0.00000000},{"price":62388.6,"qty":1.47782518},{"price":62387.3,"qty":0.00042883}],"checksum":320237677,"timestamp":"2024-06-01T17:52:07.655201Z"}]}
