{"channel":"book","type":"snapshot","data":[{"symbol":"BTC/USDT","bids":[{"price":67658.0,"qty":0.65264157},{"price":67657.9,"qty":0.19949267},{"price":67653.8,"qty":0.14793168},{"price":67651.7,"qty":0.03157632},{"price":67651.6,"qty":0.09959460},{"price":67651.4,"qty":0.02214869},{"price":67645.3,"qty":0.00460867},{"price":67644.9,"qty":0.09000000},{"price":67641.6,"qty":0.01822460},{"price":67641.4,"qty":0.00029869}],"asks":[{"price":67658.1,"qty":0.06624000},{"price":67665.4,"qty":0.03947498},{"price":67670.7,"qty":0.05333424},{"price":67670.8,"qty":0.19976708},{"price":67671.7,"qty":0.09000000},{"price":67678.4,"qty":0.22170000},{"price":67678.5,"qty":0.09000000},{"price":67680.5,"qty":0.07396000},{"price":67680.7,"qty":0.14787311},{"price":67686.1,"qty":0.09000000}],"checksum":1912587165}]}
{"channel":"book","type":"update","data":[{"symbol":"BTC/USDT","bids":[{"price":67651.4,"qty":0.00000000},{"price":67641.3,"qty":1.64024234}],"asks":[],"checksum":275349810,"timestamp":"2024-06-01T17:51:33.247357Z"}]}
{"channel":"book","type":"update","data":[{"symbol":"BTC/USDT","bids":[{"price":67658.0,"qty":0.74264157}],"asks":[],"checksum":3240554840,"timestamp":"2024-06-01T17:51:33.276115Z"}]}
{"channel":"book","type":"update","data":[{"symbol":"BTC/USDT","bids":[{"price":67658.0,"qty":0.65264157}],"asks":[],"checksum":275349810,"timestamp":"2024-06-01T17:51:33.278755Z"}]}
{"channel":"book","type":"update","data":[{"symbol":"BTC/USDT","bids":[{"price":67658.0,"qty":0.74264157}],"asks":[],"checksum":3240554840,"timestamp":"2024-06-01T17:51:33.282915Z"}]}
{"channel":"book","type":"update","data":[{"symbol":"BTC/USDT","bids":[],"asks":[{"price":67671.7,"qty":0.00000000},{"price":67686.4,"qty":0.12243000}],"checksum":2112741953,"timestamp":"2024-06-01T17:51:33.286492Z"}]}
{"channel":"book","type":"update","data":[{"symbol":"BTC/USDT","bids":[{"price":67650.7,"qty":0.02214885}],"asks":[],"checksum":2546773923,"timestamp":"2024-06-01T17:51:33.287840Z"}]}
{"channel":"book","type":"update","data":[{"symbol":"BTC/USDT","bids":[],"asks":[{"price":67671.7,"qty":0.09000000}],"checksum":1615288521,"timestamp":"2024-06-01T17:51:33.293271Z"}]}
{"channel":"book","type":"update","data":[{"symbol":"BTC/USDT","bids":[{"price":67643.7,"qty":0.17742700}],"asks":[],"checksum":399426339,"timestamp":"2024-06-01T17:51:33.334931Z"}]}
{"channel":"book","type":"update","data":[{"symbol":"BTC/USDT","bids":[{"price":67643.8,"qty":0.00029401}],"asks":[],"checksum":2836749698,"timestamp":"2024-06-01T17:51:33.340745Z"}]}
{"channel":"book","type":"update","data":[{"symbol":"BTC/USDT","bids":[],"asks":[{"price":67671.7,"qty":0.00000000},{"price":67686.4,"qty":0.12243000}],"checksum":75849267,"timestamp":"2024-06-01T17:51:33.351709Z"}]}
{"channel":"book","type":"update","data":[{"symbol":"BTC/USDT","bids":[],"asks":[{"price":67686.4,"qty":0.00000000},{"price":67690.7,"qty":0.00057699}],"checksum":1943701546,"timestamp":"2024-06-01T17:51:33.352910Z"}]}
{"channel":"book","type":"update","data":[{"symbol":"BTC/USDT","bids":[],"asks":[{"price":67680.5,"qty":0.00000000},{"price":67690.8,"qty":0.00028854}],"checksum":24814776,"timestamp":"2024-06-01T17:51:33.353429Z"}]}
{"channel":"book","type":"update","data":[{"symbol":"BTC/USDT","bids":[{"price":67658.0,"qty":0.83264157}],"asks":[],"checksum":2065854473,"timestamp":"2024-06-01T17:51:33.354874Z"}]}
{"channel":"book","type":"update","data":[{"symbol":"BTC/USDT","bids":[],"asks":[{"price":67665.4,"qty":0.00000000},{"price":67691.9,"qty":0.00460867}],"checksum":2508928413,"timestamp":"2024-06-01T17:51:33.355113Z"}]}
{"channel":"book","type":"update","data":[{"symbol":"BTC/USDT","bids":[],"asks":[{"price":67684.2,"qty":0.07396000}],"checksum":3738874218,"timestamp":"2024-06-01T17:51:33.358480Z"}]}
{"channel":"book","type":"update","data":[{"symbol":"BTC/USDT","bids":[{"price":67658.0,"qty":0.74264157}],"asks":[],"checksum":2760009179,"timestamp":"2024-06-01T17:51:33.386818Z"}]}
{"channel":"book","type":"update","data":[{"symbol":"BTC/USDT","bids":[{"price":67658.0,"qty":0.83264157}],"asks":[],"checksum":3738874218,"timestamp":"2024-06-01T17:51:33.442402Z"}]}
{"channel":"book","type":"update","data":[{"symbol":"BTC/USDT","bids":[],"asks":[{"price":67687.4,"qty":0.12242100}],"checksum":2756604701,"timestamp":"2024-06-01T17:51:33.451481Z"}]}
{"channel":"book","type":"update","data":[{"symbol":"BTC/USDT","bids":[{"price":67658.0,"qty":0.74264157}],"asks":[],"checksum":3726026668,"timestamp":"2024-06-01T17:51:33.470395Z"}]}
{"channel":"book","type":"update","data":[{"symbol":"BTC/USDT","bids":[{"price":67651.7,"qty":0.00000000},{"price":67641.6,"qty":0.01822460}],"asks":[],"checksum":454802700,"timestamp":"2024-06-01T17:51:33.517528Z"}]}
{"channel":"book","type":"update","data":[{"symbol":"BTC/USDT","bids":[{"price":67658.0,"qty":0.77421789}],"asks":[],"checksum":2654585860,"timestamp":"2024-06-01T17:51:33.519270Z"}]}
{"channel":"book","type":"update","data":[{"symbol":"BTC/USDT","bids":[],"asks":[{"price":67672.4,"qty":0.03947498}],"checksum":4151411900,"timestamp":"2024-06-01T17:51:33.521476Z"}]}
{"channel":"book","type":"update","data":[{"symbol":"BTC/USDT","bids":[],"asks":[{"price":67670.7,"qty":0.00000000},{"price":67690.7,"qty":0.00057699},{"price":67678.3,"qty":0.05333334}],"checksum":1082918306,"timestamp":"2024-06-01T17:51:33.540734Z"}]}
{"channel":"book","type":"update","data":[{"symbol":"BTC/USDT","bids":[{"price":67650.7,"qty":0.00000000},{"price":67641.3,"qty":1.64024234}],"asks":[],"checksum":3014955629,"timestamp":"2024-06-01T17:51:33.894366Z"}]}
{"channel":"book","type":"update","data":[{"symbol":"BTC/USDT","bids":[{"price":67652.7,"qty":0.02214893}],"asks":[],"checksum":561129604,"timestamp":"2024-06-01T17:51:33.934582Z"}]}
{"channel":"book","type":"update","data":[{"symbol":"BTC/USDT","bids":[],"asks":[{"price":67658.1,"qty":0.05224000}],"checksum":559078822,"timestamp":"2024-06-01T17:51:33.937195Z"}]}
{"channel":"book","type":"update","data":[{"symbol":"BTC/USDT","bids":[],"asks":[{"price":67671.7,"qty":0.09000000}],"checksum":3329128536,"timestamp":"2024-06-01T17:51:34.224147Z"}]}
{"channel":"book","type":"update","data":[{"symbol":"BTC/USDT","bids":[],"asks":[{"price":67671.7,"qty":0.00000000},{"price":67687.4,"qty":0.12242100}],"checksum":559078822,"timestamp":"2024-06-01T17:51:34.330724Z"}]}
{"channel":"book","type":"update","data":[{"symbol":"BTC/USDT","bids":[],"asks":[{"price":67687.4,"qty":0.00000000},{"price":67690.7,"qty":0.00057699}],"checksum":3170661811,"timestamp":"2024-06-01T17:51:34.331067Z"}]}
{"channel":"book","type":"update","data":[{"symbol":"BTC/USDT","bids":[],"asks":[{"price":67678.4,"qty":0.00000000},{"price":67690.8,"qty":0.00028854}],"checksum":68295201,"timestamp":"2024-06-01T17:51:34.333352Z"}]}
{"channel":"book","type":"update","data":[{"symbol":"BTC/USDT","bids":[{"price":67658.0,"qty":0.86421789}],"asks":[],"checksum":2637027247,"timestamp":"2024-06-01T17:51:34.334033Z"}]}
{"channel":"book","type":"update","data":[{"symbol":"BTC/USDT","bids":[],"asks":[{"price":67680.7,"qty":0.00000000},{"price":67691.9,"qty":0.00460867}],"checksum":274459770,"timestamp":"2024-06-01T17:51:34.336914Z"}]}
{"channel":"book","type":"update","data":[{"symbol":"BTC/USDT","bids":[],"asks":[{"price":67682.7,"qty":0.22170000}],"checksum":2396862861,"timestamp":"2024-06-01T17:51:34.339496Z"}]}
{"channel":"book","type":"update","data":[{"symbol":"BTC/USDT","bids":[],"asks":[{"price":67684.2,"qty":0.00000000},{"price":67691.9,"qty":0.00460867}],"checksum":879538144,"timestamp":"2024-06-01T17:51:34.342934Z"}]}
{"channel":"book","type":"update","data":[{"symbol":"BTC/USDT","bids":[],"asks":[{"price":67687.5,"qty":0.14785801}],"checksum":1835391886,"timestamp":"2024-06-01T17:51:34.346617Z"}]}
{"channel":"book","type":"update","data":[{"symbol":"BTC/USDT","bids":[],"asks":[{"price":67678.5,"qty":0.00000000},{"price":67691.9,"qty":0.00460867}],"checksum":2319970227,"timestamp":"2024-06-01T17:51:34.353871Z"}]}
{"channel":"book","type":"update","data":[{"symbol":"BTC/USDT","bids":[{"price":67643.8,"qty":0.00000000},{"price":67641.3,"qty":1.64024234}],"asks":[],"checksum":3137867666,"timestamp":"2024-06-01T17:51:34.355361Z"}]}
{"channel":"book","type":"update","data":[{"symbol":"BTC/USDT","bids":[{"price":67658.0,"qty":0.86451039}],"asks":[],"checksum":4204586467,"timestamp":"2024-06-01T17:51:34.356245Z"}]}
{"channel":"book","type":"update","data":[{"symbol":"BTC/USDT","bids":[],"asks":[{"price":67687.0,"qty":0.07396000}],"checksum":2585502716,"timestamp":"2024-06-01T17:51:34.361694Z"}]}
{"channel":"book","type":"update","data":[{"symbol":"BTC/USDT","bids":[],"asks":[{"price":67678.5,"qty":0.09000000}],"checksum":3863969779,"timestamp":"2024-06-01T17:51:34.366395Z"}]}
{"channel":"book","type":"update","data":[{"symbol":"BTC/USDT","bids":[{"price":67641.6,"qty":0.00000000},{"price":67641.2,"qty":0.14795925}],"asks":[],"checksum":4160540847,"timestamp":"2024-06-01T17:51:34.367400Z"}]}
{"channel":"book","type":"update","data":[{"symbol":"BTC/USDT","bids":[{"price":67645.0,"qty":0.00734483}],"asks":[],"checksum":3918349572,"timestamp":"2024-06-01T17:51:34.372823Z"}]}
{"channel":"book","type":"update","data":[{"symbol":"BTC/USDT","bids":[{"price":67643.8,"qty":0.01056288}],"asks":[],"checksum":1027362438,"timestamp":"2024-06-01T17:51:34.372894Z"}]}
{"channel":"book","type":"update","data":[{"symbol":"BTC/USDT","bids":[],"asks":[{"price":67678.3,"qty":0.00000000},{"price":67690.8,"qty":0.00028854},{"price":67670.7,"qty":0.05333334}],"checksum":1235585871,"timestamp":"2024-06-01T17:51:34.373302Z"}]}
{"channel":"book","type":"update","data":[{"symbol":"BTC/USDT","bids":[{"price":67658.0,"qty":0.83293407}],"asks":[],"checksum":2503006044,"timestamp":"2024-06-01T17:51:34.378972Z"}]}
{"channel":"book","type":"update","data":[{"symbol":"BTC/USDT","bids":[],"asks":[{"price":67670.7,"qty":0.00000000},{"price":67690.8,"qty":0.00028854},{"price":67682.6,"qty":0.05333321}],"checksum":3076196385,"timestamp":"2024-06-01T17:51:34.442754Z"}]}
{"channel":"book","type":"update","data":[{"symbol":"BTC/USDT","bids":[{"price":67645.3,"qty":0.00000000},{"price":67641.4,"qty":0.03134255}],"asks":[],"checksum":611143692,"timestamp":"2024-06-01T17:51:34.448196Z"}]}
{"channel":"book","type":"update","data":[{"symbol":"BTC/USDT","bids":[],"asks":[{"price":67658.1,"qty":0.00000000},{"price":67690.8,"qty":0.00028854}],"checksum":4069005966,"timestamp":"2024-06-01T17:51:34.455256Z"}]}
{"channel":"book","type":"update","data":[{"symbol":"BTC/USDT","bids":[{"price":67652.7,"qty":0.00000000},{"price":67641.3,"qty":1.64024234}],"asks":[],"checksum":3148660741,"timestamp":"2024-06-01T17:51:34.457200Z"}]}
{"channel":"book","type":"update","data":[{"symbol":"BTC/USDT","bids":[{"price":67657.9,"qty":0.15659267}],"asks":[],"checksum":3897462807,"timestamp":"2024-06-01T17:51:34.458298Z"}]}
{"channel":"book","type":"update","data":[{"symbol":"BTC/USDT","bids":[{"price":67658.9,"qty":0.04290000}],"asks":[],"checksum":1952705184,"timestamp":"2024-06-01T17:51:34.458595Z"}]}
{"channel":"book","type":"update","data":[{"symbol":"BTC/USDT","bids":[{"price":67658.1,"qty":0.01774610}],"asks":[],"checksum":1896785698,"timestamp":"2024-06-01T17:51:34.459081Z"}]}
{"channel":"book","type":"update","data":[{"symbol":"BTC/USDT","bids":[{"price":67661.3,"qty":0.09000000}],"asks":[],"checksum":1891865458,"timestamp":"2024-06-01T17:51:34.459204Z"}]}
{"channel":"book","type":"update","data":[{"symbol":"BTC/USDT","bids":[],"asks":[{"price":67678.5,"qty":0.00000000},{"price":67692.6,"qty":0.00141499}],"checksum":3579888940,"timestamp":"2024-06-01T17:51:34.459346Z"}]}
{"channel":"book","type":"update","data":[{"symbol":"BTC/USDT","bids":[],"asks":[{"price":67690.0,"qty":0.12241400}],"checksum":3151378232,"timestamp":"2024-06-01T17:51:34.459611Z"}]}
{"channel":"book","type":"update","data":[{"symbol":"BTC/USDT","bids":[{"price":67653.8,"qty":0.00000000},{"price":67643.7,"qty":0.17742700}],"asks":[],"checksum":3906454655,"timestamp":"2024-06-01T17:51:34.460129Z"}]}
{"channel":"book","type":"update","data":[{"symbol":"BTC/USDT","bids":[{"price":67659.6,"qty":0.29569514}],"asks":[],"checksum":3001189019,"timestamp":"2024-06-01T17:51:34.461492Z"}]}
{"channel":"book","type":"update","data":[{"symbol":"BTC/USDT","bids":[{"price":67658.0,"qty":0.53719555}],"asks":[],"checksum":287016177,"timestamp":"2024-06-01T17:51:34.461906Z"}]}
{"channel":"book","type":"update","data":[{"symbol":"BTC/USDT","bids":[{"price":67658.9,"qty":0.00000000},{"price":67643.7,"qty":0.17742700}],"asks":[],"checksum":3057712504,"timestamp":"2024-06-01T17:51:34.461968Z"}]}
{"channel":"book","type":"update","data":[{"symbol":"BTC/USDT","bids":[{"price":67662.2,"qty":0.04290000}],"asks":[],"checksum":3475969612,"timestamp":"2024-06-01T17:51:34.462142Z"}]}
{"channel":"book","type":"update","data":[{"symbol":"BTC/USDT","bids":[{"price":67658.0,"qty":0.48719555},{"price":67670.7,"qty":0.05000000}],"asks":[],"checksum":3031186678,"timestamp":"2024-06-01T17:51:34.462418Z"}]}
{"channel":"book","type":"update","data":[{"symbol":"BTC/USDT","bids":[{"price":67659.0,"qty":0.01774609}],"asks":[],"checksum":3561629742,"timestamp":"2024-06-01T17:51:34.462969Z"}]}
{"channel":"book","type":"update","data":[{"symbol":"BTC/USDT","bids":[{"price":67658.1,"qty":0.00000000},{"price":67644.9,"qty":0.09000000}],"asks":[],"checksum":4142420236,"timestamp":"2024-06-01T17:51:34.463105Z"}]}
{"channel":"book","type":"update","data":[{"symbol":"BTC/USDT","bids":[{"price":67661.4,"qty":0.01774609}],"asks":[],"checksum":3270230972,"timestamp":"2024-06-01T17:51:34.463307Z"}]}
{"channel":"book","type":"update","data":[{"symbol":"BTC/USDT","bids":[{"price":67658.0,"qty":0.51877187}],"asks":[],"checksum":61366914,"timestamp":"2024-06-01T17:51:34.463373Z"}]}
{"channel":"book","type":"update","data":[{"symbol":"BTC/USDT","bids":[{"price":67662.0,"qty":0.29569335}],"asks":[],"checksum":2933719140,"timestamp":"2024-06-01T17:51:34.464367Z"}]}
{"channel":"book","type":"update","data":[{"symbol":"BTC/USDT","bids":[{"price":67661.4,"qty":0.16566113}],"asks":[],"checksum":1986583553,"timestamp":"2024-06-01T17:51:34.464710Z"}]}
{"channel":"book","type":"update","data":[{"symbol":"BTC/USDT","bids":[{"price":67659.6,"qty":0.00000000},{"price":67645.0,"qty":0.00734483}],"asks":[],"checksum":3396975263,"timestamp":"2024-06-01T17:51:34.464953Z"}]}
{"channel":"book","type":"update","data":[{"symbol":"BTC/USDT","bids":[{"price":67665.2,"qty":0.09000000}],"asks":[],"checksum":3367828912,"timestamp":"2024-06-01T17:51:34.465518Z"}]}
{"channel":"book","type":"update","data":[{"symbol":"BTC/USDT","bids":[{"price":67658.0,"qty":0.42877187}],"asks":[],"checksum":1789139234,"timestamp":"2024-06-01T17:51:34.465606Z"}]}
{"channel":"book","type":"update","data":[{"symbol":"BTC/USDT","bids":[{"price":67659.0,"qty":0.00000000},{"price":67645.0,"qty":0.00734483}],"asks":[],"checksum":3008489624,"timestamp":"2024-06-01T17:51:34.466493Z"}]}
{"channel":"book","type":"update","data":[{"symbol":"BTC/USDT","bids":[{"price":67662.3,"qty":0.01774610}],"asks":[],"checksum":2067271372,"timestamp":"2024-06-01T17:51:34.466541Z"}]}
{"channel":"book","type":"update","data":[{"symbol":"BTC/USDT","bids":[{"price":67661.4,"qty":0.14791504}],"asks":[],"checksum":1232328958,"timestamp":"2024-06-01T17:51:34.466772Z"}]}
{"channel":"book","type":"update","data":[{"symbol":"BTC/USDT","bids":[{"price":67658.0,"qty":0.42784291},{"price":67661.4,"qty":0.14884400}],"asks":[],"checksum":1966776870,"timestamp":"2024-06-01T17:51:34.467640Z"}]}
{"channel":"book","type":"update","data":[{"symbol":"BTC/USDT","bids":[{"price":67662.2,"qty":0.00000000},{"price":67645.0,"qty":0.00734483}],"asks":[],"checksum":3978541431,"timestamp":"2024-06-01T17:51:34.468313Z"}]}
{"channel":"book","type":"update","data":[{"symbol":"BTC/USDT","bids":[{"price":67661.4,"qty":0.00092896}],"asks":[],"checksum":2595535539,"timestamp":"2024-06-01T17:51:34.468494Z"}]}
{"channel":"book","type":"update","data":[{"symbol":"BTC/USDT","bids":[{"price":67670.7,"qty":0.09290000}],"asks":[],"checksum":3603102147,"timestamp":"2024-06-01T17:51:34.468509Z"}]}
{"channel":"book","type":"update","data":[{"symbol":"BTC/USDT","bids":[{"price":67662.3,"qty":0.00000000},{"price":67644.9,"qty":0.09000000}],"asks":[],"checksum":1982850681,"timestamp":"2024-06-01T17:51:34.470265Z"}]}
{"channel":"book","type":"update","data":[{"symbol":"BTC/USDT","bids":[{"price":67665.3,"qty":0.01774610}],"asks":[],"checksum":1777988467,"timestamp":"2024-06-01T17:51:34.470427Z"}]}
{"channel":"book","type":"update","data":[{"symbol":"BTC/USDT","bids":[{"price":67665.3,"qty":0.00000000},{"price":67644.9,"qty":0.09000000}],"asks":[],"checksum":1982850681,"timestamp":"2024-06-01T17:51:34.474472Z"}]}
{"channel":"book","type":"update","data":[{"symbol":"BTC/USDT","bids":[{"price":67665.4,"qty":0.01774610}],"asks":[],"checksum":4228998094,"timestamp":"2024-06-01T17:51:34.474667Z"}]}
{"channel":"book","type":"update","data":[{"symbol":"BTC/USDT","bids":[{"price":67658.0,"qty":0.43245158}],"asks":[],"checksum":1892606721,"timestamp":"2024-06-01T17:51:34.476085Z"}]}
{"channel":"book","type":"update","data":[{"symbol":"BTC/USDT","bids":[{"price":67670.7,"qty":0.38858838}],"asks":[],"checksum":398734211,"timestamp":"2024-06-01T17:51:34.477359Z"}]}
{"channel":"book","type":"update","data":[{"symbol":"BTC/USDT","bids":[{"price":67662.0,"qty":0.00000000},{"price":67644.9,"qty":0.09000000}],"asks":[],"checksum":2463389550,"timestamp":"2024-06-01T17:51:34.477656Z"}]}
{"channel":"book","type":"update","data":[{"symbol":"BTC/USDT","bids":[],"asks":[{"price":67670.8,"qty":0.23924206}],"checksum":3380344299,"timestamp":"2024-06-01T17:51:34.478842Z"}]}
{"channel":"book","type":"update","data":[{"symbol":"BTC/USDT","bids":[{"price":67665.3,"qty":0.15000000}],"asks":[],"checksum":4274992597,"timestamp":"2024-06-01T17:51:34.479593Z"}]}
{"channel":"book","type":"update","data":[{"symbol":"BTC/USDT","bids":[{"price":67665.4,"qty":0.00000000},{"price":67644.9,"qty":0.09000000}],"asks":[],"checksum":1032049393,"timestamp":"2024-06-01T17:51:34.481511Z"}]}
{"channel":"book","type":"update","data":[{"symbol":"BTC/USDT","bids":[{"price":67670.7,"qty":0.43858838}],"asks":[],"checksum":2177445489,"timestamp":"2024-06-01T17:51:34.482223Z"}]}
{"channel":"book","type":"update","data":[{"symbol":"BTC/USDT","bids":[{"price":67670.7,"qty":0.48264792}],"asks":[],"checksum":1704471191,"timestamp":"2024-06-01T17:51:34.482740Z"}]}
{"channel":"book","type":"update","data":[{"symbol":"BTC/USDT","bids":[{"price":67665.2,"qty":0.00000000},{"price":67643.8,"qty":0.01056288}],"asks":[],"checksum":1784853067,"timestamp":"2024-06-01T17:51:34.484757Z"}]}
{"channel":"book","type":"update","data":[{"symbol":"BTC/USDT","bids":[{"price":67654.5,"qty":0.02214398}],"asks":[],"checksum":2002430594,"timestamp":"2024-06-01T17:51:34.497410Z"}]}
{"channel":"book","type":"update","data":[{"symbol":"BTC/USDT","bids":[{"price":67648.1,"qty":0.04059151}],"asks":[],"checksum":2447649432,"timestamp":"2024-06-01T17:51:34.499888Z"}]}
{"channel":"book","type":"update","data":[{"symbol":"BTC/USDT","bids":[{"price":67658.0,"qty":0.41545158}],"asks":[],"checksum":2109577642,"timestamp":"2024-06-01T17:51:34.505681Z"}]}
{"channel":"book","type":"update","data":[{"symbol":"BTC/USDT","bids":[],"asks":[{"price":67672.4,"qty":0.00000000},{"price":67692.6,"qty":0.00141499}],"checksum":3707944652,"timestamp":"2024-06-01T17:51:34.509157Z"}]}
{"channel":"book","type":"update","data":[{"symbol":"BTC/USDT","bids":[{"price":67658.0,"qty":0.26545158}],"asks":[],"checksum":2095761989,"timestamp":"2024-06-01T17:51:34.510250Z"}]}
{"channel":"book","type":"update","data":[{"symbol":"BTC/USDT","bids":[{"price":67670.7,"qty":0.63264792}],"asks":[],"checksum":761780723,"timestamp":"2024-06-01T17:51:34.510336Z"}]}
{"channel":"book","type":"update","data":[{"symbol":"BTC/USDT","bids":[{"price":67658.0,"qty":0.21545158}],"asks":[],"checksum":3518328733,"timestamp":"2024-06-01T17:51:34.513760Z"}]}
{"channel":"book","type":"update","data":[{"symbol":"BTC/USDT","bids":[{"price":67658.0,"qty":0.17139204}],"asks":[],"checksum":2482812426,"timestamp":"2024-06-01T17:51:34.514523Z"}]}
{"channel":"book","type":"update","data":[{"symbol":"BTC/USDT","bids":[{"price":67665.4,"qty":0.00028179}],"asks":[],"checksum":1646298109,"timestamp":"2024-06-01T17:51:34.515567Z"}]}
{"channel":"book","type":"update","data":[{"symbol":"BTC/USDT","bids":[{"price":67658.0,"qty":0.17109954}],"asks":[],"checksum":3715319513,"timestamp":"2024-06-01T17:51:34.515628Z"}]}
{"channel":"book","type":"update","data":[{"symbol":"BTC/USDT","bids":[],"asks":[{"price":67692.1,"qty":0.00460867}],"checksum":728789446,"timestamp":"2024-06-01T17:51:34.564262Z"}]}
{"channel":"book","type":"update","data":[{"symbol":"BTC/USDT","bids":[],"asks":[{"price":67690.0,"qty":0.00000000},{"price":67692.6,"qty":0.00141499}],"checksum":3488981002,"timestamp":"2024-06-01T17:51:34.663355Z"}]}
{"channel":"book","type":"update","data":[{"symbol":"BTC/USDT","bids":[{"price":67665.3,"qty":0.00000000},{"price":67645.0,"qty":0.00734483}],"asks":[],"checksum":634220595,"timestamp":"2024-06-01T17:51:34.709664Z"}]}
{"channel":"book","type":"update","data":[{"symbol":"BTC/USDT","bids":[{"price":67658.1,"qty":0.00030432}],"asks":[],"checksum":3253045143,"timestamp":"2024-06-01T17:51:34.725027Z"}]}
{"channel":"book","type":"update","data":[{"symbol":"BTC/USDT","bids":[{"price":67665.4,"qty":0.00000000},{"price":67645.0,"qty":0.00734483}],"asks":[],"checksum":907537133,"timestamp":"2024-06-01T17:51:34.725070Z"}]}
{"channel":"book","type":"update","data":[{"symbol":"BTC/USDT","bids":[],"asks":[{"price":67692.6,"qty":0.12382899}],"checksum":2756551610,"timestamp":"2024-06-01T17:51:34.761882Z"}]}
{"channel":"book","type":"update","data":[{"symbol":"BTC/USDT","bids":[],"asks":[{"price":67670.8,"qty":0.29999206}],"checksum":1313625809,"timestamp":"2024-06-01T17:51:34.823112Z"}]}
{"channel":"book","type":"update","data":[{"symbol":"BTC/USDT","bids":[],"asks":[{"price":67692.6,"qty":0.00141499}],"checksum":1064668302,"timestamp":"2024-06-01T17:51:34.897093Z"}]}
{"channel":"book","type":"update","data":[{"symbol":"BTC/USDT","bids":[{"price":67657.9,"qty":0.03416867}],"asks":[],"checksum":3553492036,"timestamp":"2024-06-01T17:51:34.954010Z"}]}
{"channel":"book","type":"update","data":[{"symbol":"BTC/USDT","bids":[{"price":67654.5,"qty":0.00000000},{"price":67644.9,"qty":0.09000000}],"asks":[],"checksum":1123862256,"timestamp":"2024-06-01T17:51:34.954055Z"}]}
{"channel":"book","type":"update","data":[{"symbol":"BTC/USDT","bids":[],"asks":[{"price":67677.6,"qty":0.09000000}],"checksum":1156918618,"timestamp":"2024-06-01T17:51:34.954379Z"}]}
{"channel":"book","type":"update","data":[{"symbol":"BTC/USDT","bids":[{"price":67661.3,"qty":0.00000000},{"price":67643.8,"qty":0.01056288}],"asks":[],"checksum":55636128,"timestamp":"2024-06-01T17:51:34.958863Z"}]}
{"channel":"book","type":"update","data":[{"symbol":"BTC/USDT","bids":[{"price":67658.0,"qty":0.08109954}],"asks":[],"checksum":1346453742,"timestamp":"2024-06-01T17:51:34.962859Z"}]}
{"channel":"book","type":"update","data":[{"symbol":"BTC/USDT","bids":[{"price":67658.1,"qty":0.00000000},{"price":67643.7,"qty":0.17742700}],"asks":[],"checksum":2830807706,"timestamp":"2024-06-01T17:51:34.969702Z"}]}
{"channel":"book","type":"update","data":[{"symbol":"BTC/USDT","bids":[{"price":67657.1,"qty":0.09000000}],"asks":[],"checksum":2669948380,"timestamp":"2024-06-01T17:51:34.970623Z"}]}
{"channel":"book","type":"update","data":[{"symbol":"BTC/USDT","bids":[{"price":67670.7,"qty":0.33695954}],"asks":[],"checksum":2013857276,"timestamp":"2024-06-01T17:51:34.981478Z"}]}
{"channel":"book","type":"update","data":[{"symbol":"BTC/USDT","bids":[{"price":67670.7,"qty":0.29405954}],"asks":[],"checksum":2491649640,"timestamp":"2024-06-01T17:51:34.985835Z"}]}
{"channel":"book","type":"update","data":[{"symbol":"BTC/USDT","bids":[{"price":67662.3,"qty":0.04290000}],"asks":[],"checksum":3796233109,"timestamp":"2024-06-01T17:51:34.986033Z"}]}
{"channel":"book","type":"update","data":[{"symbol":"BTC/USDT","bids":[{"price":67653.3,"qty":0.02214280}],"asks":[],"checksum":858189085,"timestamp":"2024-06-01T17:51:34.994256Z"}]}
{"channel":"book","type":"update","data":[{"symbol":"BTC/USDT","bids":[{"price":67657.1,"qty":0.00000000},{"price":67644.9,"qty":0.09000000}],"asks":[],"checksum":2922452638,"timestamp":"2024-06-01T17:51:34.994942Z"}]}
{"channel":"book","type":"update","data":[{"symbol":"BTC/USDT","bids":[{"price":67657.1,"qty":0.09000000}],"asks":[],"checksum":858189085,"timestamp":"2024-06-01T17:51:35.005202Z"}]}
{"channel":"book","type":"update","data":[{"symbol":"BTC/USDT","bids":[{"price":67658.0,"qty":0.04952322}],"asks":[],"checksum":2872456478,"timestamp":"2024-06-01T17:51:35.027163Z"}]}
{"channel":"book","type":"update","data":[{"symbol":"BTC/USDT","bids":[{"price":67667.3,"qty":0.12241400}],"asks":[],"checksum":683925251,"timestamp":"2024-06-01T17:51:35.059032Z"}]}
{"channel":"book","type":"update","data":[{"symbol":"BTC/USDT","bids":[{"price":67669.1,"qty":0.03157632}],"asks":[],"checksum":4237991546,"timestamp":"2024-06-01T17:51:35.069819Z"}]}
{"channel":"book","type":"update","data":[{"symbol":"BTC/USDT","bids":[{"price":67669.1,"qty":0.00000000},{"price":67645.0,"qty":0.00734483}],"asks":[],"checksum":3129872766,"timestamp":"2024-06-01T17:51:35.164921Z"}]}
{"channel":"book","type":"update","data":[{"symbol":"BTC/USDT","bids":[{"price":67658.0,"qty":0.00460867},{"price":67658.1,"qty":0.04527781}],"asks":[],"checksum":1525465408,"timestamp":"2024-06-01T17:51:35.197461Z"}]}
{"channel":"book","type":"update","data":[{"symbol":"BTC/USDT","bids":[{"price":67670.7,"qty":0.31905954}],"asks":[],"checksum":2146952347,"timestamp":"2024-06-01T17:51:35.220165Z"}]}
{"channel":"book","type":"update","data":[{"symbol":"BTC/USDT","bids":[{"price":67661.4,"qty":0.00000000},{"price":67645.0,"qty":0.00734483},{"price":67667.4,"qty":0.00092896}],"asks":[],"checksum":406729632,"timestamp":"2024-06-01T17:51:35.223577Z"}]}
{"channel":"book","type":"update","data":[{"symbol":"BTC/USDT","bids":[{"price":67654.8,"qty":0.03157632}],"asks":[],"checksum":3314627638,"timestamp":"2024-06-01T17:51:35.258462Z"}]}
{"channel":"book","type":"update","data":[{"symbol":"BTC/USDT","bids":[{"price":67653.3,"qty":0.00000000},{"price":67651.6,"qty":0.09959460}],"asks":[],"checksum":1453562316,"timestamp":"2024-06-01T17:51:35.518307Z"}]}
{"channel":"book","type":"update","data":[{"symbol":"BTC/USDT","bids":[],"asks":[{"price":67682.7,"qty":0.00000000},{"price":67692.5,"qty":0.02957363},{"price":67686.0,"qty":0.22170000}],"checksum":3883526839,"timestamp":"2024-06-01T17:51:35.521524Z"}]}
{"channel":"book","type":"update","data":[{"symbol":"BTC/USDT","bids":[],"asks":[{"price":67682.6,"qty":0.00000000},{"price":67692.5,"qty":0.02957363},{"price":67685.9,"qty":0.05333322}],"checksum":2807091315,"timestamp":"2024-06-01T17:51:35.568184Z"}]}
{"channel":"book","type":"update","data":[{"symbol":"BTC/USDT","bids":[],"asks":[{"price":67677.6,"qty":0.00000000},{"price":67692.5,"qty":0.02957363}],"checksum":2101596651,"timestamp":"2024-06-01T17:51:35.826861Z"}]}
{"channel":"book","type":"update","data":[{"symbol":"BTC/USDT","bids":[{"price":67663.9,"qty":0.09000000}],"asks":[],"checksum":3933964084,"timestamp":"2024-06-01T17:51:35.843491Z"}]}
{"channel":"book","type":"update","data":[{"symbol":"BTC/USDT","bids":[{"price":67662.3,"qty":0.00000000},{"price":67651.6,"qty":0.09959460}],"asks":[],"checksum":3224160854,"timestamp":"2024-06-01T17:51:35.867331Z"}]}
{"channel":"book","type":"update","data":[{"symbol":"BTC/USDT","bids":[{"price":67670.7,"qty":0.36195954}],"asks":[],"checksum":1417190821,"timestamp":"2024-06-01T17:51:35.867791Z"}]}
{"channel":"book","type":"update","data":[{"symbol":"BTC/USDT","bids":[{"price":67662.3,"qty":0.14791307}],"asks":[],"checksum":2900215050,"timestamp":"2024-06-01T17:51:35.874973Z"}]}
{"channel":"book","type":"update","data":[{"symbol":"BTC/USDT","bids":[{"price":67663.9,"qty":0.00000000},{"price":67651.6,"qty":0.09959460}],"asks":[],"checksum":1503252737,"timestamp":"2024-06-01T17:51:35.876446Z"}]}
{"channel":"book","type":"update","data":[{"symbol":"BTC/USDT","bids":[{"price":67654.8,"qty":0.00000000},{"price":67645.1,"qty":2.15669765}],"asks":[],"checksum":1829049217,"timestamp":"2024-06-01T17:51:35.882687Z"}]}
{"channel":"book","type":"update","data":[{"symbol":"BTC/USDT","bids":[],"asks":[{"price":67692.1,"qty":0.00000000},{"price":67692.6,"qty":0.00141499}],"checksum":222864647,"timestamp":"2024-06-01T17:51:35.912025Z"}]}
{"channel":"book","type":"update","data":[{"symbol":"BTC/USDT","bids":[],"asks":[{"price":67692.1,"qty":0.00460867}],"checksum":1829049217,"timestamp":"2024-06-01T17:51:35.953744Z"}]}
{"channel":"book","type":"update","data":[{"symbol":"BTC/USDT","bids":[],"asks":[{"price":67677.6,"qty":0.09000000}],"checksum":60852876,"timestamp":"2024-06-01T17:51:35.967150Z"}]}
{"channel":"book","type":"update","data":[{"symbol":"BTC/USDT","bids":[{"price":67658.1,"qty":0.00000000},{"price":67645.0,"qty":0.00734483},{"price":67670.7,"qty":0.40722891}],"asks":[],"checksum":3269545942,"timestamp":"2024-06-01T17:51:35.976863Z"}]}
{"channel":"book","type":"update","data":[{"symbol":"BTC/USDT","bids":[{"price":67651.4,"qty":0.03157632}],"asks":[],"checksum":1291677905,"timestamp":"2024-06-01T17:51:35.983290Z"}]}
{"channel":"book","type":"update","data":[{"symbol":"BTC/USDT","bids":[],"asks":[{"price":67677.6,"qty":0.00000000},{"price":67692.5,"qty":0.02957363}],"checksum":576252380,"timestamp":"2024-06-01T17:51:36.009421Z"}]}
{"channel":"book","type":"update","data":[{"symbol":"BTC/USDT","bids":[],"asks":[{"price":67686.0,"qty":0.00000000},{"price":67692.6,"qty":0.00141499},{"price":67685.8,"qty":0.22170000}],"checksum":3057376668,"timestamp":"2024-06-01T17:51:36.093137Z"}]}
{"channel":"book","type":"update","data":[{"symbol":"BTC/USDT","bids":[{"price":67667.4,"qty":0.00000000},{"price":67645.0,"qty":0.00734483}],"asks":[],"checksum":881577423,"timestamp":"2024-06-01T17:51:36.125100Z"}]}
{"channel":"book","type":"update","data":[{"symbol":"BTC/USDT","bids":[{"price":67653.3,"qty":0.02214505}],"asks":[],"checksum":2101848370,"timestamp":"2024-06-01T17:51:36.129736Z"}]}
{"channel":"book","type":"update","data":[{"symbol":"BTC/USDT","bids":[],"asks":[{"price":67677.6,"qty":0.09000000}],"checksum":4055772531,"timestamp":"2024-06-01T17:51:36.145562Z"}]}
{"channel":"book","type":"update","data":[{"symbol":"BTC/USDT","bids":[{"price":67667.4,"qty":0.00092896}],"asks":[],"checksum":1646279690,"timestamp":"2024-06-01T17:51:36.371696Z"}]}
{"channel":"book","type":"update","data":[{"symbol":"BTC/USDT","bids":[],"asks":[{"price":67677.6,"qty":0.00000000},{"price":67692.5,"qty":0.02957363}],"checksum":1971810351,"timestamp":"2024-06-01T17:51:36.476962Z"}]}
{"channel":"book","type":"update","data":[{"symbol":"BTC/USDT","bids":[{"price":67653.3,"qty":0.00000000},{"price":67645.1,"qty":2.15669765}],"asks":[],"checksum":3057376668,"timestamp":"2024-06-01T17:51:36.595569Z"}]}
{"channel":"book","type":"update","data":[{"symbol":"BTC/USDT","bids":[{"price":67652.3,"qty":0.02214505}],"asks":[],"checksum":3122227175,"timestamp":"2024-06-01T17:51:36.635794Z"}]}
{"channel":"book","type":"update","data":[{"symbol":"BTC/USDT","bids":[],"asks":[{"price":67677.6,"qty":0.09000000}],"checksum":2914921410,"timestamp":"2024-06-01T17:51:36.698751Z"}]}
{"channel":"book","type":"update","data":[{"symbol":"BTC/USDT","bids":[{"price":67670.7,"qty":0.36195954},{"price":67662.4,"qty":0.04524742}],"asks":[],"checksum":990403014,"timestamp":"2024-06-01T17:51:36.720344Z"}]}
{"channel":"book","type":"update","data":[{"symbol":"BTC/USDT","bids":[],"asks":[{"price":67677.6,"qty":0.00000000},{"price":67692.5,"qty":0.02957363}],"checksum":749671907,"timestamp":"2024-06-01T17:51:37.030493Z"}]}
{"channel":"book","type":"update","data":[{"symbol":"BTC/USDT","bids":[{"price":67652.3,"qty":0.00000000},{"price":67651.4,"qty":0.03157632}],"asks":[],"checksum":1802669218,"timestamp":"2024-06-01T17:51:37.172785Z"}]}
{"channel":"book","type":"update","data":[{"symbol":"BTC/USDT","bids":[],"asks":[{"price":67685.9,"qty":0.00000000},{"price":67692.8,"qty":0.24047267},{"price":67685.7,"qty":0.05333322}],"checksum":327241339,"timestamp":"2024-06-01T17:51:37.525686Z"}]}
{"channel":"book","type":"update","data":[{"symbol":"BTC/USDT","bids":[],"asks":[{"price":67685.8,"qty":0.00000000},{"price":67692.8,"qty":0.24047267},{"price":67686.0,"qty":0.22170000}],"checksum":3946926181,"timestamp":"2024-06-01T17:51:37.529043Z"}]}
{"channel":"book","type":"update","data":[{"symbol":"BTC/USDT","bids":[{"price":67658.1,"qty":0.05913246}],"asks":[],"checksum":3352455266,"timestamp":"2024-06-01T17:51:37.964147Z"}]}
{"channel":"book","type":"update","data":[{"symbol":"BTC/USDT","bids":[],"asks":[{"price":67692.5,"qty":0.00000000},{"price":67692.8,"qty":0.24047267}],"checksum":248291989,"timestamp":"2024-06-01T17:51:38.059476Z"}]}
{"channel":"book","type":"update","data":[{"symbol":"BTC/USDT","bids":[],"asks":[{"price":67692.7,"qty":0.16738140}],"checksum":2036782887,"timestamp":"2024-06-01T17:51:38.061843Z"}]}
{"channel":"book","type":"update","data":[{"symbol":"BTC/USDT","bids":[],"asks":[{"price":67670.8,"qty":0.10022498}],"checksum":110463396,"timestamp":"2024-06-01T17:51:38.094939Z"}]}
{"channel":"book","type":"update","data":[{"symbol":"BTC/USDT","bids":[],"asks":[{"price":67682.0,"qty":0.19976708}],"checksum":78703010,"timestamp":"2024-06-01T17:51:38.097906Z"}]}
{"channel":"book","type":"update","data":[{"symbol":"BTC/USDT","bids":[],"asks":[{"price":67685.7,"qty":0.00000000},{"price":67692.7,"qty":0.16738140},{"price":67685.9,"qty":0.05331966}],"checksum":992276836,"timestamp":"2024-06-01T17:51:38.113144Z"}]}
{"channel":"book","type":"update","data":[{"symbol":"BTC/USDT","bids":[],"asks":[{"price":67686.0,"qty":0.00000000},{"price":67692.7,"qty":0.16738140},{"price":67685.8,"qty":0.22170000}],"checksum":1017386867,"timestamp":"2024-06-01T17:51:38.116382Z"}]}
{"channel":"book","type":"update","data":[{"symbol":"BTC/USDT","bids":[],"asks":[{"price":67677.6,"qty":0.09000000}],"checksum":2603788627,"timestamp":"2024-06-01T17:51:38.168699Z"}]}
{"channel":"book","type":"update","data":[{"symbol":"BTC/USDT","bids":[{"price":67662.4,"qty":0.00000000},{"price":67651.4,"qty":0.03157632},{"price":67670.7,"qty":0.40720153}],"asks":[],"checksum":1125697173,"timestamp":"2024-06-01T17:51:38.270857Z"}]}
{"channel":"book","type":"update","data":[{"symbol":"BTC/USDT","bids":[],"asks":[{"price":67677.6,"qty":0.00000000},{"price":67692.1,"qty":0.00460867}],"checksum":3834542261,"timestamp":"2024-06-01T17:51:38.274644Z"}]}
{"channel":"book","type":"update","data":[{"symbol":"BTC/USDT","bids":[{"price":67651.4,"qty":0.00000000},{"price":67651.3,"qty":0.02214505}],"asks":[],"checksum":2660399521,"timestamp":"2024-06-01T17:51:38.306407Z"}]}
{"channel":"book","type":"update","data":[{"symbol":"BTC/USDT","bids":[{"price":67670.7,"qty":0.36195954},{"price":67662.4,"qty":0.04524743}],"asks":[],"checksum":2002608162,"timestamp":"2024-06-01T17:51:38.319412Z"}]}
{"channel":"book","type":"update","data":[{"symbol":"BTC/USDT","bids":[],"asks":[{"price":67687.0,"qty":0.00000000},{"price":67692.7,"qty":0.16738140}],"checksum":1436693853,"timestamp":"2024-06-01T17:51:38.937180Z"}]}
{"channel":"book","type":"update","data":[{"symbol":"BTC/USDT","bids":[],"asks":[{"price":67689.2,"qty":0.07396000}],"checksum":2284042796,"timestamp":"2024-06-01T17:51:38.961165Z"}]}
{"channel":"book","type":"update","data":[{"symbol":"BTC/USDT","bids":[{"price":67662.4,"qty":0.00000000},{"price":67645.9,"qty":0.02214505},{"price":67670.7,"qty":0.40720142}],"asks":[],"checksum":3735341928,"timestamp":"2024-06-01T17:51:39.015221Z"}]}
{"channel":"book","type":"update","data":[{"symbol":"BTC/USDT","bids":[],"asks":[{"price":67685.9,"qty":0.00000000},{"price":67692.7,"qty":0.16738140},{"price":67681.9,"qty":0.05331963}],"checksum":1695201286,"timestamp":"2024-06-01T17:51:39.015266Z"}]}
{"channel":"book","type":"update","data":[{"symbol":"BTC/USDT","bids":[],"asks":[{"price":67685.8,"qty":0.00000000},{"price":67692.7,"qty":0.16738140},{"price":67686.0,"qty":0.22170000}],"checksum":469191243,"timestamp":"2024-06-01T17:51:39.117425Z"}]}
{"channel":"book","type":"update","data":[{"symbol":"BTC/USDT","bids":[],"asks":[{"price":67677.6,"qty":0.09000000}],"checksum":1509882663,"timestamp":"2024-06-01T17:51:39.188730Z"}]}
{"channel":"book","type":"update","data":[{"symbol":"BTC/USDT","bids":[{"price":67670.7,"qty":0.36195954},{"price":67662.4,"qty":0.04524744}],"asks":[],"checksum":669436053,"timestamp":"2024-06-01T17:51:39.301859Z"}]}
{"channel":"book","type":"update","data":[{"symbol":"BTC/USDT","bids":[{"price":67658.1,"qty":0.00000000},{"price":67645.9,"qty":0.02214505}],"asks":[],"checksum":1384634236,"timestamp":"2024-06-01T17:51:39.444551Z"}]}
{"channel":"book","type":"update","data":[{"symbol":"BTC/USDT","bids":[{"price":67645.9,"qty":0.00000000},{"price":67645.7,"qty":1.15389371}],"asks":[],"checksum":3668539724,"timestamp":"2024-06-01T17:51:39.508967Z"}]}
{"channel":"book","type":"update","data":[{"symbol":"BTC/USDT","bids":[{"price":67658.0,"qty":0.06374121}],"asks":[],"checksum":3652392117,"timestamp":"2024-06-01T17:51:39.707556Z"}]}
{"channel":"book","type":"update","data":[{"symbol":"BTC/USDT","bids":[],"asks":[{"price":67681.9,"qty":0.00000000},{"price":67692.1,"qty":0.00460867},{"price":67677.5,"qty":0.05331963}],"checksum":4188889189,"timestamp":"2024-06-01T17:51:39.786948Z"}]}
{"channel":"book","type":"update","data":[{"symbol":"BTC/USDT","bids":[{"price":67646.0,"qty":0.02159485}],"asks":[],"checksum":1338647153,"timestamp":"2024-06-01T17:51:39.929148Z"}]}
{"channel":"book","type":"update","data":[{"symbol":"BTC/USDT","bids":[{"price":67667.3,"qty":0.00000000},{"price":67645.7,"qty":1.15389371}],"asks":[],"checksum":1128432455,"timestamp":"2024-06-01T17:51:40.049565Z"}]}
{"channel":"book","type":"update","data":[{"symbol":"BTC/USDT","bids":[{"price":67657.1,"qty":0.00000000},{"price":67645.3,"qty":1.85279566}],"asks":[],"checksum":1563047810,"timestamp":"2024-06-01T17:51:40.067480Z"}]}
{"channel":"book","type":"update","data":[{"symbol":"BTC/USDT","bids":[],"asks":[{"price":67670.8,"qty":0.19022498}],"checksum":848518531,"timestamp":"2024-06-01T17:51:40.067865Z"}]}
{"channel":"book","type":"update","data":[{"symbol":"BTC/USDT","bids":[],"asks":[{"price":67670.8,"qty":0.28022498}],"checksum":805238510,"timestamp":"2024-06-01T17:51:40.068700Z"}]}
{"channel":"book","type":"update","data":[{"symbol":"BTC/USDT","bids":[{"price":67670.7,"qty":0.31905954}],"asks":[],"checksum":136847882,"timestamp":"2024-06-01T17:51:40.072448Z"}]}
{"channel":"book","type":"update","data":[{"symbol":"BTC/USDT","bids":[],"asks":[{"price":67687.5,"qty":0.00000000},{"price":67692.1,"qty":0.00460867}],"checksum":761621659,"timestamp":"2024-06-01T17:51:40.077889Z"}]}
{"channel":"book","type":"update","data":[{"symbol":"BTC/USDT","bids":[{"price":67662.3,"qty":0.00000000},{"price":67645.1,"qty":0.02214505}],"asks":[],"checksum":324004100,"timestamp":"2024-06-01T17:51:40.077993Z"}]}
{"channel":"book","type":"update","data":[{"symbol":"BTC/USDT","bids":[],"asks":[{"price":67670.8,"qty":0.19022498}],"checksum":424039470,"timestamp":"2024-06-01T17:51:40.083922Z"}]}
{"channel":"book","type":"update","data":[{"symbol":"BTC/USDT","bids":[{"price":67645.1,"qty":0.00000000},{"price":67644.9,"qty":0.09000000}],"asks":[],"checksum":1454646954,"timestamp":"2024-06-01T17:51:40.085213Z"}]}
{"channel":"book","type":"update","data":[{"symbol":"BTC/USDT","bids":[],"asks":[{"price":67681.3,"qty":0.14787158}],"checksum":418417861,"timestamp":"2024-06-01T17:51:40.085284Z"}]}
{"channel":"book","type":"update","data":[{"symbol":"BTC/USDT","bids":[{"price":67655.2,"qty":0.14792855}],"asks":[],"checksum":462394325,"timestamp":"2024-06-01T17:51:40.085397Z"}]}
{"channel":"book","type":"update","data":[{"symbol":"BTC/USDT","bids":[],"asks":[{"price":67670.8,"qty":0.10022498}],"checksum":1949759956,"timestamp":"2024-06-01T17:51:40.089523Z"}]}
{"channel":"book","type":"update","data":[{"symbol":"BTC/USDT","bids":[],"asks":[{"price":67670.8,"qty":0.19022498}],"checksum":462394325,"timestamp":"2024-06-01T17:51:40.093200Z"}]}
{"channel":"book","type":"update","data":[{"symbol":"BTC/USDT","bids":[],"asks":[{"price":67670.8,"qty":0.10022498}],"checksum":1949759956,"timestamp":"2024-06-01T17:51:40.096574Z"}]}
{"channel":"book","type":"update","data":[{"symbol":"BTC/USDT","bids":[{"price":67661.6,"qty":1.28770743}],"asks":[],"checksum":1590080247,"timestamp":"2024-06-01T17:51:40.097953Z"}]}
{"channel":"book","type":"update","data":[{"symbol":"BTC/USDT","bids":[{"price":67670.7,"qty":0.26905954}],"asks":[],"checksum":4130369028,"timestamp":"2024-06-01T17:51:40.097973Z"}]}
{"channel":"book","type":"update","data":[{"symbol":"BTC/USDT","bids":[],"asks":[{"price":67670.8,"qty":0.19022498}],"checksum":2575893509,"timestamp":"2024-06-01T17:51:40.104462Z"}]}
{"channel":"book","type":"update","data":[{"symbol":"BTC/USDT","bids":[],"asks":[{"price":67670.8,"qty":0.28022498}],"checksum":2229579624,"timestamp":"2024-06-01T17:51:40.104889Z"}]}
{"channel":"book","type":"update","data":[{"symbol":"BTC/USDT","bids":[],"asks":[{"price":67670.8,"qty":0.19022498}],"checksum":2575893509,"timestamp":"2024-06-01T17:51:40.117413Z"}]}
{"channel":"book","type":"update","data":[{"symbol":"BTC/USDT","bids":[],"asks":[{"price":67670.8,"qty":0.10022498}],"checksum":4130369028,"timestamp":"2024-06-01T17:51:40.120015Z"}]}
{"channel":"book","type":"update","data":[{"symbol":"BTC/USDT","bids":[{"price":67658.0,"qty":0.05913254}],"asks":[],"checksum":496355431,"timestamp":"2024-06-01T17:51:40.126229Z"}]}
{"channel":"book","type":"update","data":[{"symbol":"BTC/USDT","bids":[],"asks":[{"price":67686.0,"qty":0.00000000},{"price":67692.1,"qty":0.00460867},{"price":67681.9,"qty":0.22170000}],"checksum":1133260646,"timestamp":"2024-06-01T17:51:40.143152Z"}]}
{"channel":"book","type":"update","data":[{"symbol":"BTC/USDT","bids":[],"asks":[{"price":67670.8,"qty":0.19022498}],"checksum":741688679,"timestamp":"2024-06-01T17:51:40.143410Z"}]}
{"channel":"book","type":"update","data":[{"symbol":"BTC/USDT","bids":[{"price":67658.0,"qty":0.00000000},{"price":67645.3,"qty":1.85279566}],"asks":[],"checksum":4028002853,"timestamp":"2024-06-01T17:51:40.143975Z"}]}
{"channel":"book","type":"update","data":[{"symbol":"BTC/USDT","bids":[],"asks":[{"price":67670.8,"qty":0.28022498}],"checksum":1631649986,"timestamp":"2024-06-01T17:51:40.144062Z"}]}
{"channel":"book","type":"update","data":[{"symbol":"BTC/USDT","bids":[{"price":67661.9,"qty":0.12240200}],"asks":[],"checksum":2814963254,"timestamp":"2024-06-01T17:51:40.148280Z"}]}
{"channel":"book","type":"update","data":[{"symbol":"BTC/USDT","bids":[{"price":67661.9,"qty":0.00000000},{"price":67645.3,"qty":1.85279566}],"asks":[],"checksum":1631649986,"timestamp":"2024-06-01T17:51:40.153436Z"}]}
{"channel":"book","type":"update","data":[{"symbol":"BTC/USDT","bids":[{"price":67670.7,"qty":0.11905954}],"asks":[],"checksum":2731353101,"timestamp":"2024-06-01T17:51:40.155146Z"}]}
{"channel":"book","type":"update","data":[{"symbol":"BTC/USDT","bids":[{"price":67650.7,"qty":0.03157632}],"asks":[],"checksum":2144345136,"timestamp":"2024-06-01T17:51:40.156553Z"}]}
{"channel":"book","type":"update","data":[{"symbol":"BTC/USDT","bids":[],"asks":[{"price":67670.8,"qty":0.19022498}],"checksum":1656600413,"timestamp":"2024-06-01T17:51:40.157513Z"}]}
{"channel":"book","type":"update","data":[{"symbol":"BTC/USDT","bids":[{"price":67661.6,"qty":0.00000000},{"price":67645.3,"qty":1.85279566}],"asks":[],"checksum":1072779806,"timestamp":"2024-06-01T17:51:40.157756Z"}]}
{"channel":"book","type":"update","data":[{"symbol":"BTC/USDT","bids":[{"price":67662.4,"qty":0.00000000},{"price":67644.9,"qty":0.11214505},{"price":67658.1,"qty":0.04525031}],"asks":[],"checksum":3497467504,"timestamp":"2024-06-01T17:51:40.159413Z"}]}
{"channel":"book","type":"update","data":[{"symbol":"BTC/USDT","bids":[],"asks":[{"price":67677.5,"qty":0.00000000},{"price":67692.1,"qty":0.00460867},{"price":67681.9,"qty":0.27501963}],"checksum":879811265,"timestamp":"2024-06-01T17:51:40.159611Z"}]}
{"channel":"book","type":"update","data":[{"symbol":"BTC/USDT","bids":[],"asks":[{"price":67670.8,"qty":0.10022498}],"checksum":1030568471,"timestamp":"2024-06-01T17:51:40.160342Z"}]}
{"channel":"book","type":"update","data":[{"symbol":"BTC/USDT","bids":[{"price":67661.1,"qty":1.07780993}],"asks":[],"checksum":2185894656,"timestamp":"2024-06-01T17:51:40.162575Z"}]}
{"channel":"book","type":"update","data":[{"symbol":"BTC/USDT","bids":[],"asks":[{"price":67670.8,"qty":0.15022498}],"checksum":3260457317,"timestamp":"2024-06-01T17:51:40.178188Z"}]}
{"channel":"book","type":"update","data":[{"symbol":"BTC/USDT","bids":[{"price":67657.1,"qty":0.09000000}],"asks":[],"checksum":3247789499,"timestamp":"2024-06-01T17:51:40.185529Z"}]}
{"channel":"book","type":"update","data":[{"symbol":"BTC/USDT","bids":[{"price":67657.1,"qty":0.00000000},{"price":67645.7,"qty":1.15389371}],"asks":[],"checksum":3260457317,"timestamp":"2024-06-01T17:51:40.193783Z"}]}
{"channel":"book","type":"update","data":[{"symbol":"BTC/USDT","bids":[{"price":67667.4,"qty":0.00000000},{"price":67645.3,"qty":1.85279566}],"asks":[],"checksum":733585600,"timestamp":"2024-06-01T17:51:40.209401Z"}]}
{"channel":"book","type":"update","data":[{"symbol":"BTC/USDT","bids":[],"asks":[{"price":67670.8,"qty":0.24022498}],"checksum":356941929,"timestamp":"2024-06-01T17:51:40.217411Z"}]}
{"channel":"book","type":"update","data":[{"symbol":"BTC/USDT","bids":[],"asks":[{"price":67670.8,"qty":0.33022498}],"checksum":2254412967,"timestamp":"2024-06-01T17:51:40.220353Z"}]}
{"channel":"book","type":"update","data":[{"symbol":"BTC/USDT","bids":[{"price":67670.7,"qty":0.07500000}],"asks":[],"checksum":3858774319,"timestamp":"2024-06-01T17:51:40.232286Z"}]}
{"channel":"book","type":"update","data":[{"symbol":"BTC/USDT","bids":[{"price":67661.1,"qty":0.00000000},{"price":67644.9,"qty":0.11214505}],"asks":[],"checksum":3947036639,"timestamp":"2024-06-01T17:51:40.233478Z"}]}
{"channel":"book","type":"update","data":[{"symbol":"BTC/USDT","bids":[{"price":67655.2,"qty":0.00000000},{"price":67643.7,"qty":0.17742700}],"asks":[],"checksum":2932842876,"timestamp":"2024-06-01T17:51:40.233592Z"}]}
{"channel":"book","type":"update","data":[{"symbol":"BTC/USDT","bids":[{"price":67662.0,"qty":0.04290000}],"asks":[],"checksum":2918332834,"timestamp":"2024-06-01T17:51:40.235279Z"}]}
{"channel":"book","type":"update","data":[{"symbol":"BTC/USDT","bids":[{"price":67659.0,"qty":0.04290000}],"asks":[],"checksum":3364654668,"timestamp":"2024-06-01T17:51:40.236565Z"}]}
{"channel":"book","type":"update","data":[{"symbol":"BTC/USDT","bids":[{"price":67662.0,"qty":0.00000000},{"price":67644.9,"qty":0.11214505}],"asks":[],"checksum":204202378,"timestamp":"2024-06-01T17:51:40.236615Z"}]}
{"channel":"book","type":"update","data":[{"symbol":"BTC/USDT","bids":[{"price":67656.7,"qty":1.65206491}],"asks":[],"checksum":1959468072,"timestamp":"2024-06-01T17:51:40.238185Z"}]}
{"channel":"book","type":"update","data":[{"symbol":"BTC/USDT","bids":[{"price":67650.7,"qty":0.00000000},{"price":67644.9,"qty":0.11214505}],"asks":[],"checksum":948521418,"timestamp":"2024-06-01T17:51:40.249272Z"}]}
{"channel":"book","type":"update","data":[{"symbol":"BTC/USDT","bids":[],"asks":[{"price":67681.3,"qty":0.00000000},{"price":67692.7,"qty":0.16738140}],"checksum":1032660211,"timestamp":"2024-06-01T17:51:40.255093Z"}]}
{"channel":"book","type":"update","data":[{"symbol":"BTC/USDT","bids":[{"price":67658.1,"qty":0.00000000},{"price":67643.7,"qty":0.17742700},{"price":67646.1,"qty":0.04525801}],"asks":[],"checksum":4086253083,"timestamp":"2024-06-01T17:51:40.258304Z"}]}
{"channel":"book","type":"update","data":[{"symbol":"BTC/USDT","bids":[],"asks":[{"price":67670.8,"qty":0.24022498}],"checksum":3815511446,"timestamp":"2024-06-01T17:51:40.284530Z"}]}
{"channel":"book","type":"update","data":[{"symbol":"BTC/USDT","bids":[],"asks":[{"price":67670.8,"qty":0.15022498}],"checksum":1916495729,"timestamp":"2024-06-01T17:51:40.286136Z"}]}
{"channel":"book","type":"update","data":[{"symbol":"BTC/USDT","bids":[{"price":67661.5,"qty":0.12240200}],"asks":[],"checksum":352529569,"timestamp":"2024-06-01T17:51:40.325125Z"}]}
{"channel":"book","type":"update","data":[{"symbol":"BTC/USDT","bids":[{"price":67659.0,"qty":0.00000000},{"price":67644.9,"qty":0.11214505}],"asks":[],"checksum":3720421807,"timestamp":"2024-06-01T17:51:40.327893Z"}]}
{"channel":"book","type":"update","data":[{"symbol":"BTC/USDT","bids":[{"price":67662.4,"qty":0.04290000}],"asks":[],"checksum":1904705126,"timestamp":"2024-06-01T17:51:40.328046Z"}]}
{"channel":"book","type":"update","data":[{"symbol":"BTC/USDT","bids":[{"price":67648.9,"qty":0.05913902}],"asks":[],"checksum":395220742,"timestamp":"2024-06-01T17:51:40.412629Z"}]}
{"channel":"book","type":"update","data":[{"symbol":"BTC/USDT","bids":[{"price":67660.1,"qty":0.04405954}],"asks":[],"checksum":2156491458,"timestamp":"2024-06-01T17:51:40.448461Z"}]}
{"channel":"book","type":"update","data":[{"symbol":"BTC/USDT","bids":[{"price":67646.1,"qty":0.00000000},{"price":67645.7,"qty":1.15389371},{"price":67660.2,"qty":0.04524856}],"asks":[],"checksum":3336549347,"timestamp":"2024-06-01T17:51:40.602540Z"}]}
{"channel":"book","type":"update","data":[{"symbol":"BTC/USDT","bids":[{"price":67648.9,"qty":0.00000000},{"price":67645.7,"qty":1.15389371}],"asks":[],"checksum":1606015549,"timestamp":"2024-06-01T17:51:40.689477Z"}]}
{"channel":"book","type":"update","data":[{"symbol":"BTC/USDT","bids":[],"asks":[{"price":67682.0,"qty":0.21376708}],"checksum":2754152573,"timestamp":"2024-06-01T17:51:40.937761Z"}]}
{"channel":"book","type":"update","data":[{"symbol":"BTC/USDT","bids":[{"price":67648.4,"qty":0.05913951}],"asks":[],"checksum":3152054924,"timestamp":"2024-06-01T17:51:40.996508Z"}]}
{"channel":"book","type":"update","data":[{"symbol":"BTC/USDT","bids":[{"price":67657.1,"qty":0.09000000}],"asks":[],"checksum":1392487185,"timestamp":"2024-06-01T17:51:41.194814Z"}]}
{"channel":"book","type":"update","data":[{"symbol":"BTC/USDT","bids":[],"asks":[{"price":67670.8,"qty":0.10022498}],"checksum":2437851387,"timestamp":"2024-06-01T17:51:41.225283Z"}]}
{"channel":"book","type":"update","data":[{"symbol":"BTC/USDT","bids":[{"price":67648.4,"qty":0.00000000},{"price":67646.0,"qty":0.02159485}],"asks":[],"checksum":3558125267,"timestamp":"2024-06-01T17:51:41.256336Z"}]}
{"channel":"book","type":"update","data":[{"symbol":"BTC/USDT","bids":[{"price":67660.2,"qty":0.00000000},{"price":67645.7,"qty":1.15389371},{"price":67658.0,"qty":0.04525002}],"asks":[],"checksum":3613354199,"timestamp":"2024-06-01T17:51:41.272215Z"}]}
{"channel":"book","type":"update","data":[{"symbol":"BTC/USDT","bids":[{"price":67658.0,"qty":0.00000000},{"price":67645.7,"qty":1.15389371},{"price":67662.5,"qty":0.04524701}],"asks":[],"checksum":2806709135,"timestamp":"2024-06-01T17:51:41.497558Z"}]}
{"channel":"book","type":"update","data":[{"symbol":"BTC/USDT","bids":[],"asks":[{"price":67681.9,"qty":0.22170000},{"price":67670.8,"qty":0.15354457}],"checksum":3340705639,"timestamp":"2024-06-01T17:51:41.497646Z"}]}
{"channel":"book","type":"update","data":[{"symbol":"BTC/USDT","bids":[{"price":67662.4,"qty":0.00000000},{"price":67645.7,"qty":1.15389371}],"asks":[],"checksum":3787160380,"timestamp":"2024-06-01T17:51:41.500591Z"}]}
{"channel":"book","type":"update","data":[{"symbol":"BTC/USDT","bids":[{"price":67663.4,"qty":0.04290000}],"asks":[],"checksum":3620573035,"timestamp":"2024-06-01T17:51:41.500683Z"}]}
{"channel":"book","type":"update","data":[{"symbol":"BTC/USDT","bids":[{"price":67662.6,"qty":0.15000000}],"asks":[],"checksum":2174794572,"timestamp":"2024-06-01T17:51:41.502735Z"}]}
{"channel":"book","type":"update","data":[{"symbol":"BTC/USDT","bids":[{"price":67663.5,"qty":0.15000000}],"asks":[],"checksum":2951026771,"timestamp":"2024-06-01T17:51:41.711679Z"}]}
{"channel":"book","type":"update","data":[{"symbol":"BTC/USDT","bids":[{"price":67663.4,"qty":0.00000000},{"price":67651.6,"qty":0.09959460}],"asks":[],"checksum":3717970981,"timestamp":"2024-06-01T17:51:41.714456Z"}]}
{"channel":"book","type":"update","data":[{"symbol":"BTC/USDT","bids":[{"price":67664.4,"qty":0.04290000}],"asks":[],"checksum":3434702774,"timestamp":"2024-06-01T17:51:41.714785Z"}]}
{"channel":"book","type":"update","data":[{"symbol":"BTC/USDT","bids":[{"price":67662.6,"qty":0.00000000},{"price":67651.6,"qty":0.09959460}],"asks":[],"checksum":1789056954,"timestamp":"2024-06-01T17:51:41.717182Z"}]}
{"channel":"book","type":"update","data":[{"symbol":"BTC/USDT","bids":[],"asks":[{"price":67670.8,"qty":0.20354457}],"checksum":1043731716,"timestamp":"2024-06-01T17:51:41.805370Z"}]}
{"channel":"book","type":"update","data":[{"symbol":"BTC/USDT","bids":[{"price":67664.5,"qty":0.15000000}],"asks":[],"checksum":87052468,"timestamp":"2024-06-01T17:51:41.810543Z"}]}
{"channel":"book","type":"update","data":[{"symbol":"BTC/USDT","bids":[{"price":67664.4,"qty":0.00000000},{"price":67651.6,"qty":0.09959460}],"asks":[],"checksum":2072329387,"timestamp":"2024-06-01T17:51:41.813346Z"}]}
{"channel":"book","type":"update","data":[{"symbol":"BTC/USDT","bids":[{"price":67664.8,"qty":0.04290000}],"asks":[],"checksum":176419753,"timestamp":"2024-06-01T17:51:41.813437Z"}]}
{"channel":"book","type":"update","data":[{"symbol":"BTC/USDT","bids":[],"asks":[{"price":67674.5,"qty":0.14788644}],"checksum":1664940124,"timestamp":"2024-06-01T17:51:41.876145Z"}]}
{"channel":"book","type":"update","data":[{"symbol":"BTC/USDT","bids":[{"price":67664.5,"qty":0.00000000},{"price":67651.6,"qty":0.09959460}],"asks":[],"checksum":2371727991,"timestamp":"2024-06-01T17:51:41.880646Z"}]}
{"channel":"book","type":"update","data":[{"symbol":"BTC/USDT","bids":[{"price":67664.9,"qty":0.15000000}],"asks":[],"checksum":2839470817,"timestamp":"2024-06-01T17:51:41.880698Z"}]}
{"channel":"book","type":"update","data":[{"symbol":"BTC/USDT","bids":[{"price":67657.1,"qty":0.00000000},{"price":67651.6,"qty":0.09959460}],"asks":[],"checksum":795546714,"timestamp":"2024-06-01T17:51:42.007622Z"}]}
{"channel":"book","type":"update","data":[{"symbol":"BTC/USDT","bids":[{"price":67662.5,"qty":0.00000000},{"price":67648.9,"qty":0.14794227},{"price":67656.8,"qty":0.04525082}],"asks":[],"checksum":4090317965,"timestamp":"2024-06-01T17:51:42.069515Z"}]}
{"channel":"book","type":"update","data":[{"symbol":"BTC/USDT","bids":[{"price":67663.5,"qty":0.00000000},{"price":67648.9,"qty":0.14794227}],"asks":[],"checksum":3573083171,"timestamp":"2024-06-01T17:51:42.074272Z"}]}
{"channel":"book","type":"update","data":[{"symbol":"BTC/USDT","bids":[{"price":67664.8,"qty":0.00000000},{"price":67648.7,"qty":0.05913931}],"asks":[],"checksum":3169184723,"timestamp":"2024-06-01T17:51:42.076983Z"}]}
{"channel":"book","type":"update","data":[{"symbol":"BTC/USDT","bids":[{"price":67670.7,"qty":0.05000000}],"asks":[],"checksum":3830706603,"timestamp":"2024-06-01T17:51:42.386075Z"}]}
{"channel":"book","type":"update","data":[{"symbol":"BTC/USDT","bids":[{"price":67664.9,"qty":0.00000000},{"price":67646.0,"qty":0.02159485}],"asks":[],"checksum":152017930,"timestamp":"2024-06-01T17:51:42.390806Z"}]}
{"channel":"book","type":"update","data":[{"symbol":"BTC/USDT","bids":[{"price":67661.6,"qty":0.15000000}],"asks":[],"checksum":2550131999,"timestamp":"2024-06-01T17:51:42.390919Z"}]}
{"channel":"book","type":"update","data":[{"symbol":"BTC/USDT","bids":[{"price":67670.7,"qty":0.00000000},{"price":67646.0,"qty":0.02159485}],"asks":[],"checksum":2426286863,"timestamp":"2024-06-01T17:51:42.390999Z"}]}
{"channel":"book","type":"update","data":[{"symbol":"BTC/USDT","bids":[{"price":67665.0,"qty":0.05000000}],"asks":[],"checksum":1957169001,"timestamp":"2024-06-01T17:51:42.391045Z"}]}
{"channel":"book","type":"update","data":[{"symbol":"BTC/USDT","bids":[{"price":67662.4,"qty":0.04290000}],"asks":[],"checksum":2942706566,"timestamp":"2024-06-01T17:51:42.393709Z"}]}
{"channel":"book","type":"update","data":[{"symbol":"BTC/USDT","bids":[{"price":67661.6,"qty":0.20000000}],"asks":[],"checksum":3067226209,"timestamp":"2024-06-01T17:51:42.402561Z"}]}
{"channel":"book","type":"update","data":[{"symbol":"BTC/USDT","bids":[{"price":67661.6,"qty":0.15000000},{"price":67665.0,"qty":0.10000000}],"asks":[],"checksum":2868014622,"timestamp":"2024-06-01T17:51:42.406597Z"}]}
{"channel":"book","type":"update","data":[{"symbol":"BTC/USDT","bids":[{"price":67665.0,"qty":0.15000000}],"asks":[],"checksum":2265743794,"timestamp":"2024-06-01T17:51:42.412542Z"}]}
{"channel":"book","type":"update","data":[{"symbol":"BTC/USDT","bids":[{"price":67665.0,"qty":0.10000000},{"price":67665.0,"qty":0.05000000}],"asks":[{"price":67670.8,"qty":0.15354457}],"checksum":2213226959,"timestamp":"2024-06-01T17:51:42.412558Z"}]}
{"channel":"book","type":"update","data":[{"symbol":"BTC/USDT","bids":[{"price":67656.8,"qty":0.00000000},{"price":67648.7,"qty":0.05913931},{"price":67658.0,"qty":0.04525002}],"asks":[],"checksum":3482406498,"timestamp":"2024-06-01T17:51:42.415939Z"}]}
{"channel":"book","type":"update","data":[{"symbol":"BTC/USDT","bids":[{"price":67665.0,"qty":0.10000000}],"asks":[],"checksum":3919871373,"timestamp":"2024-06-01T17:51:42.417104Z"}]}
{"channel":"book","type":"update","data":[{"symbol":"BTC/USDT","bids":[],"asks":[{"price":67670.7,"qty":0.03947498}],"checksum":1813766715,"timestamp":"2024-06-01T17:51:42.421158Z"}]}
{"channel":"book","type":"update","data":[{"symbol":"BTC/USDT","bids":[{"price":67662.5,"qty":0.15000000}],"asks":[],"checksum":1615668983,"timestamp":"2024-06-01T17:51:42.421620Z"}]}
{"channel":"book","type":"update","data":[{"symbol":"BTC/USDT","bids":[{"price":67665.1,"qty":0.04405954}],"asks":[],"checksum":483081899,"timestamp":"2024-06-01T17:51:42.422728Z"}]}
{"channel":"book","type":"update","data":[{"symbol":"BTC/USDT","bids":[{"price":67665.0,"qty":0.05000000}],"asks":[],"checksum":549972956,"timestamp":"2024-06-01T17:51:42.425554Z"}]}
{"channel":"book","type":"update","data":[{"symbol":"BTC/USDT","bids":[{"price":67665.0,"qty":0.10000000}],"asks":[],"checksum":483081899,"timestamp":"2024-06-01T17:51:42.425745Z"}]}
{"channel":"book","type":"update","data":[{"symbol":"BTC/USDT","bids":[{"price":67665.0,"qty":0.05000000},{"price":67665.1,"qty":0.09405954}],"asks":[],"checksum":4067614895,"timestamp":"2024-06-01T17:51:42.431759Z"}]}
{"channel":"book","type":"update","data":[{"symbol":"BTC/USDT","bids":[{"price":67665.1,"qty":0.14405954}],"asks":[],"checksum":792999848,"timestamp":"2024-06-01T17:51:42.437462Z"}]}
{"channel":"book","type":"update","data":[{"symbol":"BTC/USDT","bids":[{"price":67665.1,"qty":0.09405954},{"price":67665.1,"qty":0.04405954}],"asks":[],"checksum":549972956,"timestamp":"2024-06-01T17:51:42.437522Z"}]}
{"channel":"book","type":"update","data":[{"symbol":"BTC/USDT","bids":[{"price":67665.1,"qty":0.09405954}],"asks":[],"checksum":4067614895,"timestamp":"2024-06-01T17:51:42.442011Z"}]}
{"channel":"book","type":"update","data":[{"symbol":"BTC/USDT","bids":[{"price":67665.1,"qty":0.04405954}],"asks":[],"checksum":549972956,"timestamp":"2024-06-01T17:51:42.448712Z"}]}
{"channel":"book","type":"update","data":[{"symbol":"BTC/USDT","bids":[{"price":67660.1,"qty":0.00000000},{"price":67651.6,"qty":0.09959460}],"asks":[],"checksum":3524914183,"timestamp":"2024-06-01T17:51:42.448732Z"}]}
{"channel":"book","type":"update","data":[{"symbol":"BTC/USDT","bids":[{"price":67665.1,"qty":0.09405954}],"asks":[],"checksum":11331444,"timestamp":"2024-06-01T17:51:42.448827Z"}]}
{"channel":"book","type":"update","data":[{"symbol":"BTC/USDT","bids":[],"asks":[{"price":67670.8,"qty":0.11406959}],"checksum":2285136294,"timestamp":"2024-06-01T17:51:42.452587Z"}]}
{"channel":"book","type":"update","data":[{"symbol":"BTC/USDT","bids":[{"price":67665.1,"qty":0.04405954}],"asks":[],"checksum":1518428885,"timestamp":"2024-06-01T17:51:42.452691Z"}]}
{"channel":"book","type":"update","data":[{"symbol":"BTC/USDT","bids":[{"price":67665.1,"qty":0.09405954}],"asks":[],"checksum":2285136294,"timestamp":"2024-06-01T17:51:42.452841Z"}]}
{"channel":"book","type":"update","data":[{"symbol":"BTC/USDT","bids":[{"price":67661.6,"qty":0.00000000},{"price":67648.9,"qty":0.14794227}],"asks":[],"checksum":2021164605,"timestamp":"2024-06-01T17:51:42.453218Z"}]}
{"channel":"book","type":"update","data":[{"symbol":"BTC/USDT","bids":[{"price":67665.2,"qty":0.05000000}],"asks":[],"checksum":3914830956,"timestamp":"2024-06-01T17:51:42.453792Z"}]}
{"channel":"book","type":"update","data":[{"symbol":"BTC/USDT","bids":[{"price":67665.1,"qty":0.04405954}],"asks":[],"checksum":138591651,"timestamp":"2024-06-01T17:51:42.459355Z"}]}
{"channel":"book","type":"update","data":[{"symbol":"BTC/USDT","bids":[{"price":67665.1,"qty":0.09405954}],"asks":[],"checksum":3914830956,"timestamp":"2024-06-01T17:51:42.459549Z"}]}
{"channel":"book","type":"update","data":[{"symbol":"BTC/USDT","bids":[{"price":67665.2,"qty":0.10000000}],"asks":[],"checksum":3752794704,"timestamp":"2024-06-01T17:51:42.464164Z"}]}
{"channel":"book","type":"update","data":[{"symbol":"BTC/USDT","bids":[{"price":67665.1,"qty":0.04405954},{"price":67665.2,"qty":0.05000000}],"asks":[],"checksum":138591651,"timestamp":"2024-06-01T17:51:42.464223Z"}]}
{"channel":"book","type":"update","data":[{"symbol":"BTC/USDT","bids":[{"price":67665.2,"qty":0.10000000}],"asks":[],"checksum":1052390303,"timestamp":"2024-06-01T17:51:42.470495Z"}]}
{"channel":"book","type":"update","data":[{"symbol":"BTC/USDT","bids":[{"price":67658.0,"qty":0.00000000},{"price":67648.9,"qty":0.14794227},{"price":67656.8,"qty":0.04525191}],"asks":[],"checksum":3907539539,"timestamp":"2024-06-01T17:51:42.488763Z"}]}
{"channel":"book","type":"update","data":[{"symbol":"BTC/USDT","bids":[{"price":67665.0,"qty":0.00000000},{"price":67648.9,"qty":0.14794227}],"asks":[],"checksum":3877164743,"timestamp":"2024-06-01T17:51:42.588540Z"}]}
{"channel":"book","type":"update","data":[{"symbol":"BTC/USDT","bids":[{"price":67665.2,"qty":0.25000000}],"asks":[],"checksum":2149763471,"timestamp":"2024-06-01T17:51:42.593170Z"}]}
{"channel":"book","type":"update","data":[{"symbol":"BTC/USDT","bids":[{"price":67665.3,"qty":0.04405954}],"asks":[],"checksum":4221459785,"timestamp":"2024-06-01T17:51:42.593933Z"}]}
{"channel":"book","type":"update","data":[{"symbol":"BTC/USDT","bids":[{"price":67651.7,"qty":0.09000000}],"asks":[],"checksum":4102079423,"timestamp":"2024-06-01T17:51:42.600373Z"}]}
{"channel":"book","type":"update","data":[{"symbol":"BTC/USDT","bids":[{"price":67665.2,"qty":0.20000000},{"price":67665.3,"qty":0.09405954}],"asks":[],"checksum":2987170248,"timestamp":"2024-06-01T17:51:42.602413Z"}]}
{"channel":"book","type":"update","data":[{"symbol":"BTC/USDT","bids":[{"price":67665.3,"qty":0.10805954}],"asks":[],"checksum":539624087,"timestamp":"2024-06-01T17:51:42.627409Z"}]}
{"channel":"book","type":"update","data":[{"symbol":"BTC/USDT","bids":[{"price":67665.2,"qty":0.05000000}],"asks":[],"checksum":1809439665,"timestamp":"2024-06-01T17:51:42.632508Z"}]}
{"channel":"book","type":"update","data":[{"symbol":"BTC/USDT","bids":[{"price":67665.4,"qty":0.15000000}],"asks":[],"checksum":270305256,"timestamp":"2024-06-01T17:51:42.632582Z"}]}
{"channel":"book","type":"update","data":[{"symbol":"BTC/USDT","bids":[{"price":67665.1,"qty":0.00000000},{"price":67651.7,"qty":0.09000000}],"asks":[],"checksum":4079326730,"timestamp":"2024-06-01T17:51:42.633659Z"}]}
{"channel":"book","type":"update","data":[{"symbol":"BTC/USDT","bids":[{"price":67661.7,"qty":0.01800000}],"asks":[],"checksum":2714293827,"timestamp":"2024-06-01T17:51:42.638355Z"}]}
{"channel":"book","type":"update","data":[{"symbol":"BTC/USDT","bids":[{"price":67665.3,"qty":0.05805954},{"price":67665.4,"qty":0.20000000}],"asks":[],"checksum":266452068,"timestamp":"2024-06-01T17:51:42.642183Z"}]}
{"channel":"book","type":"update","data":[{"symbol":"BTC/USDT","bids":[{"price":67665.3,"qty":0.04405954}],"asks":[],"checksum":692104710,"timestamp":"2024-06-01T17:51:42.665273Z"}]}
{"channel":"book","type":"update","data":[{"symbol":"BTC/USDT","bids":[{"price":67661.7,"qty":0.00000000},{"price":67651.7,"qty":0.09000000}],"asks":[],"checksum":2074996303,"timestamp":"2024-06-01T17:51:42.666906Z"}]}
{"channel":"book","type":"update","data":[{"symbol":"BTC/USDT","bids":[{"price":67665.4,"qty":0.05000000}],"asks":[],"checksum":4112674327,"timestamp":"2024-06-01T17:51:42.669706Z"}]}
{"channel":"book","type":"update","data":[{"symbol":"BTC/USDT","bids":[{"price":67665.5,"qty":0.04405954}],"asks":[],"checksum":3270351928,"timestamp":"2024-06-01T17:51:42.670290Z"}]}
{"channel":"book","type":"update","data":[{"symbol":"BTC/USDT","bids":[{"price":67665.4,"qty":0.00000000},{"price":67651.7,"qty":0.09000000},{"price":67665.5,"qty":0.09405954}],"asks":[],"checksum":891536169,"timestamp":"2024-06-01T17:51:42.676837Z"}]}
{"channel":"book","type":"update","data":[{"symbol":"BTC/USDT","bids":[{"price":67665.6,"qty":0.05000000}],"asks":[],"checksum":877485152,"timestamp":"2024-06-01T17:51:42.695734Z"}]}
{"channel":"book","type":"update","data":[{"symbol":"BTC/USDT","bids":[{"price":67665.5,"qty":0.11905954}],"asks":[],"checksum":1859447984,"timestamp":"2024-06-01T17:51:42.697555Z"}]}
{"channel":"book","type":"update","data":[{"symbol":"BTC/USDT","bids":[{"price":67665.7,"qty":0.04405954}],"asks":[],"checksum":3666164960,"timestamp":"2024-06-01T17:51:42.700907Z"}]}
{"channel":"book","type":"update","data":[{"symbol":"BTC/USDT","bids":[{"price":67665.5,"qty":0.07500000}],"asks":[],"checksum":3406818162,"timestamp":"2024-06-01T17:51:42.700962Z"}]}
{"channel":"book","type":"update","data":[{"symbol":"BTC/USDT","bids":[{"price":67665.5,"qty":0.02500000},{"price":67665.6,"qty":0.10000000}],"asks":[],"checksum":3937565402,"timestamp":"2024-06-01T17:51:42.703152Z"}]}
{"channel":"book","type":"update","data":[{"symbol":"BTC/USDT","bids":[{"price":67665.6,"qty":0.25000000}],"asks":[],"checksum":1780518040,"timestamp":"2024-06-01T17:51:42.705042Z"}]}
{"channel":"book","type":"update","data":[{"symbol":"BTC/USDT","bids":[{"price":67665.6,"qty":0.20000000},{"price":67665.7,"qty":0.09405954}],"asks":[],"checksum":1536175701,"timestamp":"2024-06-01T17:51:42.709421Z"}]}
{"channel":"book","type":"update","data":[{"symbol":"BTC/USDT","bids":[{"price":67665.5,"qty":0.00000000},{"price":67656.7,"qty":1.65206491}],"asks":[],"checksum":1417153296,"timestamp":"2024-06-01T17:51:42.733044Z"}]}
{"channel":"book","type":"update","data":[{"symbol":"BTC/USDT","bids":[{"price":67665.7,"qty":0.24405954}],"asks":[],"checksum":602188796,"timestamp":"2024-06-01T17:51:42.737994Z"}]}
{"channel":"book","type":"update","data":[{"symbol":"BTC/USDT","bids":[{"price":67665.6,"qty":0.05000000}],"asks":[],"checksum":1182113352,"timestamp":"2024-06-01T17:51:42.738040Z"}]}
{"channel":"book","type":"update","data":[{"symbol":"BTC/USDT","bids":[{"price":67665.3,"qty":0.00000000},{"price":67651.7,"qty":0.09000000}],"asks":[],"checksum":3353929735,"timestamp":"2024-06-01T17:51:42.738396Z"}]}
{"channel":"book","type":"update","data":[{"symbol":"BTC/USDT","bids":[{"price":67665.2,"qty":0.00000000},{"price":67651.6,"qty":0.09959460}],"asks":[],"checksum":1236547871,"timestamp":"2024-06-01T17:51:42.738573Z"}]}
{"channel":"book","type":"update","data":[{"symbol":"BTC/USDT","bids":[{"price":67665.8,"qty":0.05000000}],"asks":[],"checksum":1154246612,"timestamp":"2024-06-01T17:51:42.738606Z"}]}
{"channel":"book","type":"update","data":[{"symbol":"BTC/USDT","bids":[{"price":67665.7,"qty":0.19405954},{"price":67665.8,"qty":0.10000000}],"asks":[],"checksum":2311915223,"timestamp":"2024-06-01T17:51:42.746242Z"}]}
{"channel":"book","type":"update","data":[{"symbol":"BTC/USDT","bids":[{"price":67665.9,"qty":0.04405954}],"asks":[],"checksum":1037191573,"timestamp":"2024-06-01T17:51:42.948636Z"}]}
{"channel":"book","type":"update","data":[{"symbol":"BTC/USDT","bids":[{"price":67665.7,"qty":0.04405954}],"asks":[],"checksum":943647405,"timestamp":"2024-06-01T17:51:42.953659Z"}]}
{"channel":"book","type":"update","data":[{"symbol":"BTC/USDT","bids":[{"price":67665.7,"qty":0.00000000},{"price":67651.7,"qty":0.09000000}],"asks":[],"checksum":2203930012,"timestamp":"2024-06-01T17:51:42.953720Z"}]}
{"channel":"book","type":"update","data":[{"symbol":"BTC/USDT","bids":[{"price":67665.9,"qty":0.19405954}],"asks":[],"checksum":166902628,"timestamp":"2024-06-01T17:51:42.953815Z"}]}
{"channel":"book","type":"update","data":[{"symbol":"BTC/USDT","bids":[{"price":67665.6,"qty":0.00000000},{"price":67651.6,"qty":0.09959460}],"asks":[],"checksum":2764127568,"timestamp":"2024-06-01T17:51:42.953871Z"}]}
{"channel":"book","type":"update","data":[{"symbol":"BTC/USDT","bids":[{"price":67666.0,"qty":0.05000000}],"asks":[],"checksum":3822403067,"timestamp":"2024-06-01T17:51:42.954316Z"}]}
{"channel":"book","type":"update","data":[{"symbol":"BTC/USDT","bids":[{"price":67665.8,"qty":0.05000000},{"price":67665.9,"qty":0.24405954}],"asks":[],"checksum":2812604875,"timestamp":"2024-06-01T17:51:42.957039Z"}]}
{"channel":"book","type":"update","data":[{"symbol":"BTC/USDT","bids":[{"price":67665.9,"qty":0.19405954},{"price":67666.0,"qty":0.10000000}],"asks":[],"checksum":4252203058,"timestamp":"2024-06-01T17:51:42.967019Z"}]}
{"channel":"book","type":"update","data":[{"symbol":"BTC/USDT","bids":[{"price":67666.0,"qty":0.05000000}],"asks":[],"checksum":1142518588,"timestamp":"2024-06-01T17:51:42.971001Z"}]}
{"channel":"book","type":"update","data":[{"symbol":"BTC/USDT","bids":[{"price":67666.0,"qty":0.10000000}],"asks":[],"checksum":4252203058,"timestamp":"2024-06-01T17:51:42.971232Z"}]}
{"channel":"book","type":"update","data":[{"symbol":"BTC/USDT","bids":[{"price":67666.0,"qty":0.15000000}],"asks":[],"checksum":3498940318,"timestamp":"2024-06-01T17:51:42.982497Z"}]}
{"channel":"book","type":"update","data":[{"symbol":"BTC/USDT","bids":[{"price":67666.0,"qty":0.10000000},{"price":67666.0,"qty":0.05000000}],"asks":[],"checksum":1142518588,"timestamp":"2024-06-01T17:51:42.982624Z"}]}
{"channel":"book","type":"update","data":[{"symbol":"BTC/USDT","bids":[{"price":67665.8,"qty":0.00000000},{"price":67651.6,"qty":0.09959460}],"asks":[],"checksum":2636949482,"timestamp":"2024-06-01T17:51:42.987202Z"}]}
{"channel":"book","type":"update","data":[{"symbol":"BTC/USDT","bids":[{"price":67666.1,"qty":0.04405954}],"asks":[],"checksum":1254758370,"timestamp":"2024-06-01T17:51:42.987459Z"}]}
{"channel":"book","type":"update","data":[{"symbol":"BTC/USDT","bids":[{"price":67666.0,"qty":0.10000000}],"asks":[],"checksum":1603548529,"timestamp":"2024-06-01T17:51:42.987821Z"}]}
{"channel":"book","type":"update","data":[{"symbol":"BTC/USDT","bids":[{"price":67666.1,"qty":0.19405954}],"asks":[],"checksum":2978426179,"timestamp":"2024-06-01T17:51:42.988047Z"}]}
{"channel":"book","type":"update","data":[{"symbol":"BTC/USDT","bids":[{"price":67665.9,"qty":0.04405954}],"asks":[],"checksum":1034481114,"timestamp":"2024-06-01T17:51:42.988134Z"}]}
{"channel":"book","type":"update","data":[{"symbol":"BTC/USDT","bids":[{"price":67666.0,"qty":0.05000000}],"asks":[],"checksum":1792036757,"timestamp":"2024-06-01T17:51:42.993524Z"}]}
{"channel":"book","type":"update","data":[{"symbol":"BTC/USDT","bids":[{"price":67666.0,"qty":0.10000000}],"asks":[],"checksum":1034481114,"timestamp":"2024-06-01T17:51:42.993761Z"}]}
{"channel":"book","type":"update","data":[{"symbol":"BTC/USDT","bids":[{"price":67666.0,"qty":0.05000000}],"asks":[],"checksum":1792036757,"timestamp":"2024-06-01T17:51:43.001293Z"}]}
{"channel":"book","type":"update","data":[{"symbol":"BTC/USDT","bids":[{"price":67666.1,"qty":0.24405954}],"asks":[],"checksum":3372967127,"timestamp":"2024-06-01T17:51:43.001483Z"}]}
{"channel":"book","type":"update","data":[{"symbol":"BTC/USDT","bids":[{"price":67666.1,"qty":0.19405954}],"asks":[],"checksum":1792036757,"timestamp":"2024-06-01T17:51:43.010339Z"}]}
{"channel":"book","type":"update","data":[{"symbol":"BTC/USDT","bids":[{"price":67666.1,"qty":0.24405954}],"asks":[],"checksum":3372967127,"timestamp":"2024-06-01T17:51:43.010401Z"}]}
{"channel":"book","type":"update","data":[{"symbol":"BTC/USDT","bids":[{"price":67666.1,"qty":0.19405954}],"asks":[],"checksum":1792036757,"timestamp":"2024-06-01T17:51:43.017728Z"}]}
{"channel":"book","type":"update","data":[{"symbol":"BTC/USDT","bids":[{"price":67666.1,"qty":0.24405954}],"asks":[],"checksum":3372967127,"timestamp":"2024-06-01T17:51:43.017892Z"}]}
{"channel":"book","type":"update","data":[{"symbol":"BTC/USDT","bids":[{"price":67666.1,"qty":0.09405954}],"asks":[],"checksum":475047843,"timestamp":"2024-06-01T17:51:43.022300Z"}]}
{"channel":"book","type":"update","data":[{"symbol":"BTC/USDT","bids":[{"price":67665.9,"qty":0.00000000},{"price":67651.6,"qty":0.09959460}],"asks":[],"checksum":2199568247,"timestamp":"2024-06-01T17:51:43.022497Z"}]}
{"channel":"book","type":"update","data":[{"symbol":"BTC/USDT","bids":[{"price":67666.2,"qty":0.05000000}],"asks":[],"checksum":1193069232,"timestamp":"2024-06-01T17:51:43.023717Z"}]}
{"channel":"book","type":"update","data":[{"symbol":"BTC/USDT","bids":[{"price":67666.1,"qty":0.04405954}],"asks":[],"checksum":2785665919,"timestamp":"2024-06-01T17:51:43.024432Z"}]}
{"channel":"book","type":"update","data":[{"symbol":"BTC/USDT","bids":[{"price":67666.1,"qty":0.09405954}],"asks":[],"checksum":1193069232,"timestamp":"2024-06-01T17:51:43.024584Z"}]}
{"channel":"book","type":"update","data":[{"symbol":"BTC/USDT","bids":[{"price":67666.1,"qty":0.04405954}],"asks":[],"checksum":2785665919,"timestamp":"2024-06-01T17:51:43.032173Z"}]}
{"channel":"book","type":"update","data":[{"symbol":"BTC/USDT","bids":[{"price":67666.2,"qty":0.10000000}],"asks":[],"checksum":2098757430,"timestamp":"2024-06-01T17:51:43.032365Z"}]}
{"channel":"book","type":"update","data":[{"symbol":"BTC/USDT","bids":[{"price":67666.0,"qty":0.00000000},{"price":67651.6,"qty":0.09959460}],"asks":[],"checksum":4147135631,"timestamp":"2024-06-01T17:51:43.086538Z"}]}
{"channel":"book","type":"update","data":[{"symbol":"BTC/USDT","bids":[{"price":67666.2,"qty":0.25000000}],"asks":[],"checksum":275103764,"timestamp":"2024-06-01T17:51:43.091446Z"}]}
{"channel":"book","type":"update","data":[{"symbol":"BTC/USDT","bids":[{"price":67666.3,"qty":0.04405954}],"asks":[],"checksum":284533802,"timestamp":"2024-06-01T17:51:43.092394Z"}]}
{"channel":"book","type":"update","data":[{"symbol":"BTC/USDT","bids":[{"price":67666.2,"qty":0.10000000}],"asks":[],"checksum":2254724630,"timestamp":"2024-06-01T17:51:43.210815Z"}]}
{"channel":"book","type":"update","data":[{"symbol":"BTC/USDT","bids":[{"price":67666.3,"qty":0.19405954}],"asks":[],"checksum":766288818,"timestamp":"2024-06-01T17:51:43.211052Z"}]}
{"channel":"book","type":"update","data":[{"symbol":"BTC/USDT","bids":[{"price":67662.5,"qty":0.00000000},{"price":67651.6,"qty":0.09959460}],"asks":[],"checksum":393323937,"timestamp":"2024-06-01T17:51:43.215576Z"}]}
{"channel":"book","type":"update","data":[{"symbol":"BTC/USDT","bids":[{"price":67666.4,"qty":0.05000000}],"asks":[],"checksum":3247668452,"timestamp":"2024-06-01T17:51:43.215946Z"}]}
{"channel":"book","type":"update","data":[{"symbol":"BTC/USDT","bids":[{"price":67666.1,"qty":0.00000000},{"price":67651.6,"qty":0.09959460}],"asks":[],"checksum":231461586,"timestamp":"2024-06-01T17:51:43.216239Z"}]}
{"channel":"book","type":"update","data":[{"symbol":"BTC/USDT","bids":[{"price":67656.8,"qty":0.00000000},{"price":67648.9,"qty":0.14794227},{"price":67662.5,"qty":0.04524814}],"asks":[],"checksum":1430640038,"timestamp":"2024-06-01T17:51:43.327168Z"}]}
{"channel":"book","type":"update","data":[{"symbol":"BTC/USDT","bids":[],"asks":[{"price":67670.8,"qty":0.06075000},{"price":67670.6,"qty":0.05331977}],"checksum":3365415283,"timestamp":"2024-06-01T17:51:43.328100Z"}]}
{"channel":"book","type":"update","data":[{"symbol":"BTC/USDT","bids":[{"price":67666.5,"qty":0.04405954}],"asks":[],"checksum":2529227140,"timestamp":"2024-06-01T17:51:43.332961Z"}]}
{"channel":"book","type":"update","data":[{"symbol":"BTC/USDT","bids":[{"price":67666.2,"qty":0.05000000}],"asks":[],"checksum":3287773512,"timestamp":"2024-06-01T17:51:43.333000Z"}]}
{"channel":"book","type":"update","data":[{"symbol":"BTC/USDT","bids":[{"price":67666.3,"qty":0.15000000}],"asks":[],"checksum":375767764,"timestamp":"2024-06-01T17:51:43.450844Z"}]}
{"channel":"book","type":"update","data":[{"symbol":"BTC/USDT","bids":[],"asks":[{"price":67670.5,"qty":0.03947498}],"checksum":1192853643,"timestamp":"2024-06-01T17:51:43.454983Z"}]}
{"channel":"book","type":"update","data":[{"symbol":"BTC/USDT","bids":[{"price":67666.4,"qty":0.20000000}],"asks":[],"checksum":1565289514,"timestamp":"2024-06-01T17:51:43.455352Z"}]}
{"channel":"book","type":"update","data":[{"symbol":"BTC/USDT","bids":[{"price":67666.6,"qty":0.05000000}],"asks":[],"checksum":3594713013,"timestamp":"2024-06-01T17:51:43.455486Z"}]}
{"channel":"book","type":"update","data":[{"symbol":"BTC/USDT","bids":[{"price":67662.5,"qty":0.00000000},{"price":67651.7,"qty":0.09000000},{"price":67656.8,"qty":0.04525195}],"asks":[],"checksum":3117079071,"timestamp":"2024-06-01T17:51:43.519551Z"}]}
{"channel":"book","type":"update","data":[{"symbol":"BTC/USDT","bids":[{"price":67666.4,"qty":0.15000000}],"asks":[],"checksum":2692665848,"timestamp":"2024-06-01T17:51:43.584431Z"}]}
{"channel":"book","type":"update","data":[{"symbol":"BTC/USDT","bids":[{"price":67666.7,"qty":0.04405954}],"asks":[],"checksum":3311050717,"timestamp":"2024-06-01T17:51:43.589596Z"}]}
{"channel":"book","type":"update","data":[{"symbol":"BTC/USDT","bids":[{"price":67666.4,"qty":0.00000000},{"price":67656.7,"qty":1.65206491}],"asks":[],"checksum":1902600418,"timestamp":"2024-06-01T17:51:43.590061Z"}]}
{"channel":"book","type":"update","data":[{"symbol":"BTC/USDT","bids":[{"price":67666.5,"qty":0.19405954}],"asks":[],"checksum":3464015206,"timestamp":"2024-06-01T17:51:43.590094Z"}]}
{"channel":"book","type":"update","data":[{"symbol":"BTC/USDT","bids":[],"asks":[{"price":67670.7,"qty":0.00000000},{"price":67690.7,"qty":0.00057699}],"checksum":2219085994,"timestamp":"2024-06-01T17:51:43.590139Z"}]}
{"channel":"book","type":"update","data":[{"symbol":"BTC/USDT","bids":[],"asks":[{"price":67677.6,"qty":0.00000000},{"price":67690.8,"qty":0.00028854}],"checksum":1671976822,"timestamp":"2024-06-01T17:51:43.684071Z"}]}
{"channel":"book","type":"update","data":[{"symbol":"BTC/USDT","bids":[{"price":67659.9,"qty":0.09000000}],"asks":[],"checksum":3151882665,"timestamp":"2024-06-01T17:51:43.688941Z"}]}
{"channel":"book","type":"update","data":[{"symbol":"BTC/USDT","bids":[],"asks":[{"price":67674.5,"qty":0.00000000},{"price":67692.1,"qty":0.00460867}],"checksum":3829124564,"timestamp":"2024-06-01T17:51:43.693310Z"}]}
{"channel":"book","type":"update","data":[{"symbol":"BTC/USDT","bids":[{"price":67666.7,"qty":0.13405954}],"asks":[],"checksum":3279098456,"timestamp":"2024-06-01T17:51:43.694660Z"}]}
{"channel":"book","type":"update","data":[{"symbol":"BTC/USDT","bids":[{"price":67666.7,"qty":0.04405954}],"asks":[],"checksum":3829124564,"timestamp":"2024-06-01T17:51:43.697659Z"}]}
{"channel":"book","type":"update","data":[{"symbol":"BTC/USDT","bids":[],"asks":[{"price":67683.0,"qty":0.14786805}],"checksum":4975643,"timestamp":"2024-06-01T17:51:43.701364Z"}]}
{"channel":"book","type":"update","data":[{"symbol":"BTC/USDT","bids":[{"price":67662.4,"qty":0.00000000},{"price":67656.7,"qty":1.65206491}],"asks":[],"checksum":785980972,"timestamp":"2024-06-01T17:51:43.703634Z"}]}
{"channel":"book","type":"update","data":[{"symbol":"BTC/USDT","bids":[{"price":67667.2,"qty":0.04290000}],"asks":[],"checksum":2920936275,"timestamp":"2024-06-01T17:51:43.703664Z"}]}
{"channel":"book","type":"update","data":[{"symbol":"BTC/USDT","bids":[{"price":67670.4,"qty":0.29564891}],"asks":[],"checksum":2111107950,"timestamp":"2024-06-01T17:51:43.704445Z"}]}
{"channel":"book","type":"update","data":[{"symbol":"BTC/USDT","bids":[{"price":67666.7,"qty":0.13405954}],"asks":[],"checksum":1241105225,"timestamp":"2024-06-01T17:51:43.706053Z"}]}
{"channel":"book","type":"update","data":[{"symbol":"BTC/USDT","bids":[{"price":67666.7,"qty":0.04405954}],"asks":[],"checksum":2111107950,"timestamp":"2024-06-01T17:51:43.710776Z"}]}
{"channel":"book","type":"update","data":[{"symbol":"BTC/USDT","bids":[{"price":67666.3,"qty":0.00000000},{"price":67656.8,"qty":0.04525195}],"asks":[],"checksum":1596882988,"timestamp":"2024-06-01T17:51:43.712046Z"}]}
{"channel":"book","type":"update","data":[{"symbol":"BTC/USDT","bids":[{"price":67666.7,"qty":0.19405954}],"asks":[],"checksum":3991203349,"timestamp":"2024-06-01T17:51:43.712181Z"}]}
{"channel":"book","type":"update","data":[{"symbol":"BTC/USDT","bids":[{"price":67666.2,"qty":0.00000000},{"price":67656.7,"qty":1.65206491}],"asks":[],"checksum":1353901187,"timestamp":"2024-06-01T17:51:43.715164Z"}]}
{"channel":"book","type":"update","data":[{"symbol":"BTC/USDT","bids":[{"price":67666.5,"qty":0.15000000}],"asks":[],"checksum":1883986281,"timestamp":"2024-06-01T17:51:43.717257Z"}]}
{"channel":"book","type":"update","data":[{"symbol":"BTC/USDT","bids":[{"price":67670.4,"qty":0.34564891}],"asks":[],"checksum":2604794438,"timestamp":"2024-06-01T17:51:43.719050Z"}]}
{"channel":"book","type":"update","data":[{"symbol":"BTC/USDT","bids":[{"price":67666.5,"qty":0.00000000},{"price":67655.6,"qty":0.14792768}],"asks":[],"checksum":771113850,"timestamp":"2024-06-01T17:51:43.721139Z"}]}
{"channel":"book","type":"update","data":[{"symbol":"BTC/USDT","bids":[{"price":67670.4,"qty":0.49564891}],"asks":[],"checksum":1400306077,"timestamp":"2024-06-01T17:51:43.721452Z"}]}
{"channel":"book","type":"update","data":[{"symbol":"BTC/USDT","bids":[{"price":67670.4,"qty":0.53970845}],"asks":[],"checksum":2974377,"timestamp":"2024-06-01T17:51:43.754227Z"}]}
{"channel":"book","type":"update","data":[{"symbol":"BTC/USDT","bids":[{"price":67666.6,"qty":0.00000000},{"price":67651.7,"qty":0.09000000}],"asks":[],"checksum":3237497815,"timestamp":"2024-06-01T17:51:43.759185Z"}]}
{"channel":"book","type":"update","data":[{"symbol":"BTC/USDT","bids":[{"price":67666.7,"qty":0.04405954}],"asks":[],"checksum":2080836670,"timestamp":"2024-06-01T17:51:43.759853Z"}]}
{"channel":"book","type":"update","data":[{"symbol":"BTC/USDT","bids":[],"asks":[{"price":67670.6,"qty":0.00000000},{"price":67692.6,"qty":0.00483630},{"price":67681.8,"qty":0.05331975}],"checksum":1806996815,"timestamp":"2024-06-01T17:51:43.804889Z"}]}
{"channel":"book","type":"update","data":[{"symbol":"BTC/USDT","bids":[],"asks":[{"price":67670.5,"qty":0.00000000},{"price":67692.6,"qty":0.00483630}],"checksum":368959358,"timestamp":"2024-06-01T17:51:43.809371Z"}]}
{"channel":"book","type":"update","data":[{"symbol":"BTC/USDT","bids":[],"asks":[{"price":67670.7,"qty":0.03947498}],"checksum":1135097043,"timestamp":"2024-06-01T17:51:43.809468Z"}]}
{"channel":"book","type":"update","data":[{"symbol":"BTC/USDT","bids":[{"price":67666.7,"qty":0.00000000},{"price":67651.6,"qty":0.09959460}],"asks":[],"checksum":3388259618,"timestamp":"2024-06-01T17:51:43.809765Z"}]}
{"channel":"book","type":"update","data":[{"symbol":"BTC/USDT","bids":[{"price":67667.2,"qty":0.00000000},{"price":67648.7,"qty":0.05913926}],"asks":[],"checksum":4278907536,"timestamp":"2024-06-01T17:51:43.812622Z"}]}
{"channel":"book","type":"update","data":[{"symbol":"BTC/USDT","bids":[{"price":67670.6,"qty":0.04290000}],"asks":[],"checksum":3513484742,"timestamp":"2024-06-01T17:51:43.812820Z"}]}
{"channel":"book","type":"update","data":[{"symbol":"BTC/USDT","bids":[{"price":67670.4,"qty":0.24405954}],"asks":[],"checksum":2078456171,"timestamp":"2024-06-01T17:51:43.812854Z"}]}
{"channel":"book","type":"update","data":[{"symbol":"BTC/USDT","bids":[{"price":67670.6,"qty":0.33857911}],"asks":[],"checksum":1303494899,"timestamp":"2024-06-01T17:51:43.813035Z"}]}
{"channel":"book","type":"update","data":[{"symbol":"BTC/USDT","bids":[{"price":67670.4,"qty":0.24866821}],"asks":[],"checksum":994450403,"timestamp":"2024-06-01T17:51:43.818938Z"}]}
{"channel":"book","type":"update","data":[{"symbol":"BTC/USDT","bids":[{"price":67670.5,"qty":0.00092896}],"asks":[],"checksum":2185945255,"timestamp":"2024-06-01T17:51:43.836989Z"}]}
{"channel":"book","type":"update","data":[{"symbol":"BTC/USDT","bids":[{"price":67670.6,"qty":0.38857911}],"asks":[],"checksum":3598726717,"timestamp":"2024-06-01T17:51:43.841891Z"}]}
{"channel":"book","type":"update","data":[{"symbol":"BTC/USDT","bids":[{"price":67670.6,"qty":0.53857911}],"asks":[],"checksum":709549581,"timestamp":"2024-06-01T17:51:43.842037Z"}]}
{"channel":"book","type":"update","data":[{"symbol":"BTC/USDT","bids":[{"price":67670.6,"qty":0.58263865}],"asks":[],"checksum":2234398436,"timestamp":"2024-06-01T17:51:43.843435Z"}]}
{"channel":"book","type":"update","data":[{"symbol":"BTC/USDT","bids":[{"price":67670.4,"qty":0.20460867}],"asks":[],"checksum":942883159,"timestamp":"2024-06-01T17:51:43.947872Z"}]}
{"channel":"book","type":"update","data":[{"symbol":"BTC/USDT","bids":[{"price":67670.4,"qty":0.05460867}],"asks":[],"checksum":1408255418,"timestamp":"2024-06-01T17:51:43.953140Z"}]}
{"channel":"book","type":"update","data":[{"symbol":"BTC/USDT","bids":[{"price":67670.4,"qty":0.00460867}],"asks":[],"checksum":2510838155,"timestamp":"2024-06-01T17:51:43.953649Z"}]}
{"channel":"book","type":"update","data":[{"symbol":"BTC/USDT","bids":[],"asks":[{"price":67681.9,"qty":0.00000000},{"price":67692.5,"qty":0.12239700}],"checksum":3299840830,"timestamp":"2024-06-01T17:51:43.962207Z"}]}
{"channel":"book","type":"update","data":[{"symbol":"BTC/USDT","bids":[],"asks":[{"price":67692.5,"qty":0.00000000},{"price":67692.6,"qty":0.00483630}],"checksum":3487335507,"timestamp":"2024-06-01T17:51:43.963254Z"}]}
{"channel":"book","type":"update","data":[{"symbol":"BTC/USDT","bids":[],"asks":[{"price":67685.8,"qty":0.22170000}],"checksum":2708851163,"timestamp":"2024-06-01T17:51:43.966907Z"}]}
{"channel":"book","type":"update","data":[{"symbol":"BTC/USDT","bids":[{"price":67670.4,"qty":0.00000000},{"price":67651.6,"qty":0.12173890}],"asks":[],"checksum":398505684,"timestamp":"2024-06-01T17:51:43.978561Z"}]}
{"channel":"book","type":"update","data":[{"symbol":"BTC/USDT","bids":[],"asks":[{"price":67681.8,"qty":0.00000000},{"price":67692.6,"qty":0.00483630},{"price":67681.9,"qty":0.05331975}],"checksum":147626505,"timestamp":"2024-06-01T17:51:44.002538Z"}]}
{"channel":"book","type":"update","data":[{"symbol":"BTC/USDT","bids":[{"price":67651.6,"qty":0.09959460}],"asks":[],"checksum":11188387,"timestamp":"2024-06-01T17:51:44.048553Z"}]}
{"channel":"book","type":"update","data":[{"symbol":"BTC/USDT","bids":[{"price":67663.2,"qty":0.00460867}],"asks":[],"checksum":3441890791,"timestamp":"2024-06-01T17:51:44.080657Z"}]}
{"channel":"book","type":"update","data":[{"symbol":"BTC/USDT","bids":[{"price":67656.8,"qty":0.00000000},{"price":67651.6,"qty":0.09959460},{"price":67670.6,"qty":0.62788138}],"asks":[],"checksum":3510060242,"timestamp":"2024-06-01T17:51:44.270670Z"}]}
{"channel":"book","type":"update","data":[{"symbol":"BTC/USDT","bids":[{"price":67652.5,"qty":0.02214279}],"asks":[],"checksum":1811853191,"timestamp":"2024-06-01T17:51:44.593970Z"}]}
{"channel":"book","type":"update","data":[{"symbol":"BTC/USDT","bids":[{"price":67661.5,"qty":0.00000000},{"price":67651.6,"qty":0.09959460}],"asks":[],"checksum":3764824301,"timestamp":"2024-06-01T17:51:44.737978Z"}]}
{"channel":"book","type":"update","data":[{"symbol":"BTC/USDT","bids":[{"price":67669.6,"qty":0.12239700}],"asks":[],"checksum":1643621549,"timestamp":"2024-06-01T17:51:44.856559Z"}]}
{"channel":"book","type":"update","data":[{"symbol":"BTC/USDT","bids":[],"asks":[{"price":67685.8,"qty":0.00000000},{"price":67692.6,"qty":0.00483630},{"price":67686.0,"qty":0.22170000}],"checksum":122074416,"timestamp":"2024-06-01T17:51:45.091466Z"}]}
{"channel":"book","type":"update","data":[{"symbol":"BTC/USDT","bids":[{"price":67652.5,"qty":0.00000000},{"price":67651.6,"qty":0.09959460}],"asks":[],"checksum":3180289637,"timestamp":"2024-06-01T17:51:45.121274Z"}]}
{"channel":"book","type":"update","data":[{"symbol":"BTC/USDT","bids":[{"price":67656.8,"qty":0.01163388}],"asks":[],"checksum":3450922329,"timestamp":"2024-06-01T17:51:45.282131Z"}]}
{"channel":"book","type":"update","data":[{"symbol":"BTC/USDT","bids":[{"price":67670.6,"qty":0.58263865},{"price":67660.0,"qty":0.04567306}],"asks":[],"checksum":1382011465,"timestamp":"2024-06-01T17:51:45.318719Z"}]}
{"channel":"book","type":"update","data":[{"symbol":"BTC/USDT","bids":[{"price":67669.6,"qty":0.00000000},{"price":67651.7,"qty":0.09000000}],"asks":[],"checksum":3383561111,"timestamp":"2024-06-01T17:51:45.834993Z"}]}
{"channel":"book","type":"update","data":[{"symbol":"BTC/USDT","bids":[],"asks":[{"price":67677.5,"qty":0.09000000}],"checksum":1418399905,"timestamp":"2024-06-01T17:51:45.913467Z"}]}
{"channel":"book","type":"update","data":[{"symbol":"BTC/USDT","bids":[{"price":67659.9,"qty":0.00000000},{"price":67651.6,"qty":0.09959460}],"asks":[],"checksum":2190388456,"timestamp":"2024-06-01T17:51:45.920731Z"}]}
{"channel":"book","type":"update","data":[{"symbol":"BTC/USDT","bids":[{"price":67669.1,"qty":0.12239800}],"asks":[],"checksum":4099365999,"timestamp":"2024-06-01T17:51:45.933851Z"}]}
{"channel":"book","type":"update","data":[{"symbol":"BTC/USDT","bids":[{"price":67670.6,"qty":0.28695954}],"asks":[],"checksum":3219296108,"timestamp":"2024-06-01T17:51:45.948402Z"}]}
{"channel":"book","type":"update","data":[{"symbol":"BTC/USDT","bids":[{"price":67660.0,"qty":0.00000000},{"price":67651.6,"qty":0.09959460},{"price":67658.0,"qty":0.04567441}],"asks":[],"checksum":1223155414,"timestamp":"2024-06-01T17:51:45.993352Z"}]}
{"channel":"book","type":"update","data":[{"symbol":"BTC/USDT","bids":[{"price":67670.6,"qty":0.24405954}],"asks":[],"checksum":414112169,"timestamp":"2024-06-01T17:51:46.021929Z"}]}
{"channel":"book","type":"update","data":[{"symbol":"BTC/USDT","bids":[{"price":67669.1,"qty":0.16529800}],"asks":[],"checksum":3637337926,"timestamp":"2024-06-01T17:51:46.022206Z"}]}
{"channel":"book","type":"update","data":[{"symbol":"BTC/USDT","bids":[{"price":67663.2,"qty":0.00000000},{"price":67651.6,"qty":0.09959460}],"asks":[],"checksum":3033882214,"timestamp":"2024-06-01T17:51:46.032241Z"}]}
{"channel":"book","type":"update","data":[{"symbol":"BTC/USDT","bids":[{"price":67670.5,"qty":0.00000000},{"price":67648.7,"qty":0.05913926}],"asks":[],"checksum":69741899,"timestamp":"2024-06-01T17:51:46.032612Z"}]}
{"channel":"book","type":"update","data":[{"symbol":"BTC/USDT","bids":[{"price":67670.6,"qty":0.09405954}],"asks":[],"checksum":2248208513,"timestamp":"2024-06-01T17:51:46.038437Z"}]}
{"channel":"book","type":"update","data":[{"symbol":"BTC/USDT","bids":[{"price":67669.2,"qty":0.15000000}],"asks":[],"checksum":2188345228,"timestamp":"2024-06-01T17:51:46.038468Z"}]}
{"channel":"book","type":"update","data":[{"symbol":"BTC/USDT","bids":[{"price":67655.8,"qty":0.00460867}],"asks":[],"checksum":3642440136,"timestamp":"2024-06-01T17:51:46.134999Z"}]}
{"channel":"book","type":"update","data":[{"symbol":"BTC/USDT","bids":[{"price":67656.9,"qty":1.32092692}],"asks":[],"checksum":3941661453,"timestamp":"2024-06-01T17:51:46.135177Z"}]}
{"channel":"book","type":"update","data":[{"symbol":"BTC/USDT","bids":[{"price":67660.1,"qty":0.02957106}],"asks":[],"checksum":7098537,"timestamp":"2024-06-01T17:51:46.135216Z"}]}
{"channel":"book","type":"update","data":[{"symbol":"BTC/USDT","bids":[],"asks":[{"price":67677.5,"qty":0.00000000},{"price":67690.8,"qty":0.00028854}],"checksum":2285885336,"timestamp":"2024-06-01T17:51:46.298091Z"}]}
{"channel":"book","type":"update","data":[{"symbol":"BTC/USDT","bids":[{"price":67658.0,"qty":0.00000000},{"price":67655.6,"qty":0.14792768},{"price":67670.6,"qty":0.13972526}],"asks":[],"checksum":4079781877,"timestamp":"2024-06-01T17:51:46.347636Z"}]}
{"channel":"book","type":"update","data":[{"symbol":"BTC/USDT","bids":[{"price":67669.1,"qty":0.12239800}],"asks":[],"checksum":772902560,"timestamp":"2024-06-01T17:51:46.350307Z"}]}
{"channel":"book","type":"update","data":[{"symbol":"BTC/USDT","bids":[{"price":67670.6,"qty":0.18262526}],"asks":[],"checksum":2779205229,"timestamp":"2024-06-01T17:51:46.350645Z"}]}
{"channel":"book","type":"update","data":[{"symbol":"BTC/USDT","bids":[{"price":67670.6,"qty":0.33262526}],"asks":[],"checksum":1010399542,"timestamp":"2024-06-01T17:51:46.352575Z"}]}
{"channel":"book","type":"update","data":[{"symbol":"BTC/USDT","bids":[],"asks":[{"price":67677.5,"qty":0.09000000}],"checksum":2310594644,"timestamp":"2024-06-01T17:51:46.565395Z"}]}
{"channel":"book","type":"update","data":[{"symbol":"BTC/USDT","bids":[{"price":67669.2,"qty":0.00000000},{"price":67651.7,"qty":0.09000000}],"asks":[],"checksum":3991833953,"timestamp":"2024-06-01T17:51:46.569926Z"}]}
{"channel":"book","type":"update","data":[{"symbol":"BTC/USDT","bids":[],"asks":[{"price":67677.5,"qty":0.00000000},{"price":67690.8,"qty":0.00028854}],"checksum":3166232284,"timestamp":"2024-06-01T17:51:46.773958Z"}]}
{"channel":"book","type":"update","data":[{"symbol":"BTC/USDT","bids":[{"price":67670.6,"qty":0.28695954},{"price":67658.0,"qty":0.04575402}],"asks":[],"checksum":49736295,"timestamp":"2024-06-01T17:51:47.506416Z"}]}
{"channel":"book","type":"update","data":[{"symbol":"BTC/USDT","bids":[{"price":67656.8,"qty":0.00000000},{"price":67651.7,"qty":0.09000000}],"asks":[],"checksum":2224556288,"timestamp":"2024-06-01T17:51:47.861532Z"}]}
{"channel":"book","type":"update","data":[{"symbol":"BTC/USDT","bids":[{"price":67657.0,"qty":0.01125861}],"asks":[],"checksum":4225328861,"timestamp":"2024-06-01T17:51:47.866377Z"}]}
{"channel":"book","type":"update","data":[{"symbol":"BTC/USDT","bids":[],"asks":[{"price":67677.5,"qty":0.09000000}],"checksum":2861512032,"timestamp":"2024-06-01T17:51:47.936920Z"}]}
{"channel":"book","type":"update","data":[{"symbol":"BTC/USDT","bids":[{"price":67670.6,"qty":0.33695954}],"asks":[],"checksum":1999447175,"timestamp":"2024-06-01T17:51:48.007894Z"}]}
{"channel":"book","type":"update","data":[{"symbol":"BTC/USDT","bids":[{"price":67658.0,"qty":0.00000000},{"price":67651.7,"qty":0.09000000},{"price":67670.6,"qty":0.38270504}],"asks":[],"checksum":187991121,"timestamp":"2024-06-01T17:51:48.476829Z"}]}
{"channel":"book","type":"update","data":[{"symbol":"BTC/USDT","bids":[],"asks":[{"price":67681.9,"qty":0.00000000},{"price":67690.8,"qty":0.00028854},{"price":67677.4,"qty":0.05329469}],"checksum":2782908160,"timestamp":"2024-06-01T17:51:48.476865Z"}]}
{"channel":"book","type":"update","data":[{"symbol":"BTC/USDT","bids":[{"price":67670.6,"qty":0.42070504}],"asks":[],"checksum":904416170,"timestamp":"2024-06-01T17:51:48.506649Z"}]}
{"channel":"book","type":"update","data":[{"symbol":"BTC/USDT","bids":[],"asks":[{"price":67677.5,"qty":0.00000000},{"price":67690.8,"qty":0.00028854}],"checksum":462060613,"timestamp":"2024-06-01T17:51:48.579126Z"}]}
{"channel":"book","type":"update","data":[{"symbol":"BTC/USDT","bids":[],"asks":[{"price":67677.5,"qty":0.09000000}],"checksum":904416170,"timestamp":"2024-06-01T17:51:48.605866Z"}]}
{"channel":"book","type":"update","data":[{"symbol":"BTC/USDT","bids":[],"asks":[{"price":67677.4,"qty":0.00000000},{"price":67690.8,"qty":0.00028854},{"price":67681.9,"qty":0.05329456}],"checksum":3784612994,"timestamp":"2024-06-01T17:51:48.628960Z"}]}
{"channel":"book","type":"update","data":[{"symbol":"BTC/USDT","bids":[],"asks":[{"price":67677.5,"qty":0.00000000},{"price":67690.8,"qty":0.00028854}],"checksum":130676216,"timestamp":"2024-06-01T17:51:49.397715Z"}]}
{"channel":"book","type":"update","data":[{"symbol":"BTC/USDT","bids":[],"asks":[{"price":67681.9,"qty":0.00000000},{"price":67692.8,"qty":0.24047267},{"price":67677.4,"qty":0.05329456}],"checksum":2205315628,"timestamp":"2024-06-01T17:51:49.437712Z"}]}
{"channel":"book","type":"update","data":[{"symbol":"BTC/USDT","bids":[],"asks":[{"price":67677.4,"qty":0.00000000},{"price":67692.8,"qty":0.24047267},{"price":67681.9,"qty":0.05329447}],"checksum":2662867600,"timestamp":"2024-06-01T17:51:49.490674Z"}]}
{"channel":"book","type":"update","data":[{"symbol":"BTC/USDT","bids":[{"price":67669.2,"qty":0.00092896}],"asks":[],"checksum":3885089729,"timestamp":"2024-06-01T17:51:49.561150Z"}]}
{"channel":"book","type":"update","data":[{"symbol":"BTC/USDT","bids":[],"asks":[{"price":67677.5,"qty":0.09000000}],"checksum":3615132672,"timestamp":"2024-06-01T17:51:49.563890Z"}]}
{"channel":"book","type":"update","data":[{"symbol":"BTC/USDT","bids":[],"asks":[{"price":67677.5,"qty":0.00000000},{"price":67690.8,"qty":0.00028854}],"checksum":3885089729,"timestamp":"2024-06-01T17:51:49.575264Z"}]}
{"channel":"book","type":"update","data":[{"symbol":"BTC/USDT","bids":[{"price":67663.8,"qty":0.09000000}],"asks":[],"checksum":879869449,"timestamp":"2024-06-01T17:51:49.579369Z"}]}
{"channel":"book","type":"update","data":[{"symbol":"BTC/USDT","bids":[{"price":67670.6,"qty":0.51070504}],"asks":[],"checksum":997940105,"timestamp":"2024-06-01T17:51:49.585464Z"}]}
{"channel":"book","type":"update","data":[{"symbol":"BTC/USDT","bids":[],"asks":[{"price":67686.1,"qty":0.00000000},{"price":67692.8,"qty":0.24047267}],"checksum":254595835,"timestamp":"2024-06-01T17:51:49.587645Z"}]}
{"channel":"book","type":"update","data":[{"symbol":"BTC/USDT","bids":[],"asks":[{"price":67683.0,"qty":0.00000000},{"price":67692.9,"qty":0.09000000}],"checksum":778766729,"timestamp":"2024-06-01T17:51:49.594681Z"}]}
{"channel":"book","type":"update","data":[{"symbol":"BTC/USDT","bids":[{"price":67670.6,"qty":0.80633564}],"asks":[],"checksum":4098195811,"timestamp":"2024-06-01T17:51:49.598770Z"}]}
{"channel":"book","type":"update","data":[{"symbol":"BTC/USDT","bids":[],"asks":[{"price":67686.0,"qty":0.00000000},{"price":67697.1,"qty":0.16738190},{"price":67689.1,"qty":0.22170000}],"checksum":4242844684,"timestamp":"2024-06-01T17:51:49.598785Z"}]}
{"channel":"book","type":"update","data":[{"symbol":"BTC/USDT","bids":[{"price":67661.8,"qty":0.14791415}],"asks":[],"checksum":4289781444,"timestamp":"2024-06-01T17:51:49.602471Z"}]}
{"channel":"book","type":"update","data":[{"symbol":"BTC/USDT","bids":[],"asks":[{"price":67689.5,"qty":0.14785380}],"checksum":381189164,"timestamp":"2024-06-01T17:51:49.602523Z"}]}
{"channel":"book","type":"update","data":[{"symbol":"BTC/USDT","bids":[{"price":67670.6,"qty":0.76059014},{"price":67658.0,"qty":0.04570642}],"asks":[],"checksum":1462611138,"timestamp":"2024-06-01T17:51:49.641954Z"}]}
{"channel":"book","type":"update","data":[{"symbol":"BTC/USDT","bids":[],"asks":[{"price":67684.3,"qty":0.09000000}],"checksum":589965452,"timestamp":"2024-06-01T17:51:49.646010Z"}]}
{"channel":"book","type":"update","data":[{"symbol":"BTC/USDT","bids":[{"price":67660.1,"qty":0.00000000},{"price":67656.7,"qty":1.65206491}],"asks":[],"checksum":3671965059,"timestamp":"2024-06-01T17:51:49.730691Z"}]}
{"channel":"book","type":"update","data":[{"symbol":"BTC/USDT","bids":[{"price":67656.9,"qty":0.00000000},{"price":67655.8,"qty":0.00460867}],"asks":[],"checksum":2083865186,"timestamp":"2024-06-01T17:51:49.730842Z"}]}
{"channel":"book","type":"update","data":[{"symbol":"BTC/USDT","bids":[{"price":67656.8,"qty":0.78926253}],"asks":[],"checksum":1461502810,"timestamp":"2024-06-01T17:51:49.735852Z"}]}
{"channel":"book","type":"update","data":[{"symbol":"BTC/USDT","bids":[],"asks":[{"price":67676.2,"qty":0.05026000}],"checksum":1054975491,"timestamp":"2024-06-01T17:51:49.813968Z"}]}
{"channel":"book","type":"update","data":[{"symbol":"BTC/USDT","bids":[],"asks":[{"price":67681.9,"qty":0.00000000},{"price":67690.8,"qty":0.00028854},{"price":67689.0,"qty":0.05329446}],"checksum":2368006910,"timestamp":"2024-06-01T17:51:49.843817Z"}]}
{"channel":"book","type":"update","data":[{"symbol":"BTC/USDT","bids":[{"price":67670.6,"qty":0.67059014}],"asks":[],"checksum":1110690208,"timestamp":"2024-06-01T17:51:49.870975Z"}]}
{"channel":"book","type":"update","data":[{"symbol":"BTC/USDT","bids":[],"asks":[{"price":67670.8,"qty":0.00000000},{"price":67690.8,"qty":0.00028854}],"checksum":3307616036,"timestamp":"2024-06-01T17:51:50.128814Z"}]}
{"channel":"book","type":"update","data":[{"symbol":"BTC/USDT","bids":[],"asks":[{"price":67689.1,"qty":0.00000000},{"price":67692.8,"qty":0.24047267},{"price":67688.9,"qty":0.22170000}],"checksum":3080071597,"timestamp":"2024-06-01T17:51:50.131983Z"}]}
{"channel":"book","type":"update","data":[{"symbol":"BTC/USDT","bids":[],"asks":[{"price":67670.7,"qty":0.00000000},{"price":67692.8,"qty":0.24047267}],"checksum":2769531997,"timestamp":"2024-06-01T17:51:50.133035Z"}]}
{"channel":"book","type":"update","data":[{"symbol":"BTC/USDT","bids":[],"asks":[{"price":67676.1,"qty":0.03947498}],"checksum":3986214209,"timestamp":"2024-06-01T17:51:50.133148Z"}]}
{"channel":"book","type":"update","data":[{"symbol":"BTC/USDT","bids":[{"price":67670.6,"qty":0.62769014}],"asks":[],"checksum":1654168520,"timestamp":"2024-06-01T17:51:50.135838Z"}]}
{"channel":"book","type":"update","data":[{"symbol":"BTC/USDT","bids":[{"price":67671.5,"qty":0.04290000}],"asks":[],"checksum":3710948613,"timestamp":"2024-06-01T17:51:50.136018Z"}]}
{"channel":"book","type":"update","data":[{"symbol":"BTC/USDT","bids":[],"asks":[{"price":67684.3,"qty":0.00000000},{"price":67692.8,"qty":0.24047267}],"checksum":817933614,"timestamp":"2024-06-01T17:51:50.137170Z"}]}
{"channel":"book","type":"update","data":[{"symbol":"BTC/USDT","bids":[{"price":67670.7,"qty":0.01774487}],"asks":[],"checksum":959971644,"timestamp":"2024-06-01T17:51:50.137613Z"}]}
{"channel":"book","type":"update","data":[{"symbol":"BTC/USDT","bids":[{"price":67672.2,"qty":0.29567168}],"asks":[],"checksum":920606557,"timestamp":"2024-06-01T17:51:50.138808Z"}]}
{"channel":"book","type":"update","data":[{"symbol":"BTC/USDT","bids":[{"price":67670.6,"qty":0.33205954}],"asks":[],"checksum":4156132781,"timestamp":"2024-06-01T17:51:50.140120Z"}]}
{"channel":"book","type":"update","data":[{"symbol":"BTC/USDT","bids":[{"price":67671.5,"qty":0.00000000},{"price":67657.0,"qty":0.01125861}],"asks":[],"checksum":2770118307,"timestamp":"2024-06-01T17:51:50.141491Z"}]}
{"channel":"book","type":"update","data":[{"symbol":"BTC/USDT","bids":[{"price":67673.1,"qty":0.04290000}],"asks":[],"checksum":3606387652,"timestamp":"2024-06-01T17:51:50.141591Z"}]}
{"channel":"book","type":"update","data":[{"symbol":"BTC/USDT","bids":[{"price":67673.8,"qty":0.29567173}],"asks":[],"checksum":1213425296,"timestamp":"2024-06-01T17:51:50.144711Z"}]}
{"channel":"book","type":"update","data":[{"symbol":"BTC/USDT","bids":[{"price":67670.7,"qty":0.00000000},{"price":67657.9,"qty":0.03416867}],"asks":[],"checksum":1783133167,"timestamp":"2024-06-01T17:51:50.145723Z"}]}
{"channel":"book","type":"update","data":[{"symbol":"BTC/USDT","bids":[{"price":67673.1,"qty":0.00000000},{"price":67657.0,"qty":0.01125861}],"asks":[],"checksum":703866308,"timestamp":"2024-06-01T17:51:50.147569Z"}]}
{"channel":"book","type":"update","data":[{"symbol":"BTC/USDT","bids":[{"price":67672.2,"qty":0.00000000},{"price":67656.8,"qty":0.78926253}],"asks":[],"checksum":1860838286,"timestamp":"2024-06-01T17:51:50.147740Z"}]}
{"channel":"book","type":"update","data":[{"symbol":"BTC/USDT","bids":[{"price":67674.7,"qty":0.04290000}],"asks":[],"checksum":2626115351,"timestamp":"2024-06-01T17:51:50.147892Z"}]}
{"channel":"book","type":"update","data":[{"symbol":"BTC/USDT","bids":[{"price":67670.6,"qty":0.28205954}],"asks":[],"checksum":912412438,"timestamp":"2024-06-01T17:51:50.157669Z"}]}
{"channel":"book","type":"update","data":[{"symbol":"BTC/USDT","bids":[{"price":67669.2,"qty":0.00000000},{"price":67656.8,"qty":0.78926253},{"price":67674.8,"qty":0.00092896}],"asks":[],"checksum":2830643981,"timestamp":"2024-06-01T17:51:50.159644Z"}]}
{"channel":"book","type":"update","data":[{"symbol":"BTC/USDT","bids":[{"price":67674.8,"qty":0.05092896}],"asks":[],"checksum":4114878629,"timestamp":"2024-06-01T17:51:50.164900Z"}]}
{"channel":"book","type":"update","data":[{"symbol":"BTC/USDT","bids":[{"price":67673.9,"qty":0.15000000}],"asks":[],"checksum":4218694467,"timestamp":"2024-06-01T17:51:50.164946Z"}]}
{"channel":"book","type":"update","data":[{"symbol":"BTC/USDT","bids":[{"price":67676.0,"qty":0.05000000}],"asks":[],"checksum":2640312407,"timestamp":"2024-06-01T17:51:50.165730Z"}]}
{"channel":"book","type":"update","data":[{"symbol":"BTC/USDT","bids":[{"price":67670.6,"qty":0.24405954}],"asks":[],"checksum":988381809,"timestamp":"2024-06-01T17:51:50.166766Z"}]}
{"channel":"book","type":"update","data":[{"symbol":"BTC/USDT","bids":[{"price":67674.8,"qty":0.09498850}],"asks":[],"checksum":3189281683,"timestamp":"2024-06-01T17:51:50.166988Z"}]}
{"channel":"book","type":"update","data":[{"symbol":"BTC/USDT","bids":[{"price":67674.7,"qty":0.00000000},{"price":67657.9,"qty":0.03416867}],"asks":[],"checksum":4118586442,"timestamp":"2024-06-01T17:51:50.167599Z"}]}
{"channel":"book","type":"update","data":[{"symbol":"BTC/USDT","bids":[{"price":67675.7,"qty":0.04290000}],"asks":[],"checksum":4038896419,"timestamp":"2024-06-01T17:51:50.167744Z"}]}
{"channel":"book","type":"update","data":[{"symbol":"BTC/USDT","bids":[{"price":67670.6,"qty":0.09405954}],"asks":[],"checksum":3266254835,"timestamp":"2024-06-01T17:51:50.209555Z"}]}
{"channel":"book","type":"update","data":[{"symbol":"BTC/USDT","bids":[{"price":67674.9,"qty":0.15000000}],"asks":[],"checksum":3279594304,"timestamp":"2024-06-01T17:51:50.209610Z"}]}
{"channel":"book","type":"update","data":[{"symbol":"BTC/USDT","bids":[{"price":67673.9,"qty":0.00000000},{"price":67658.0,"qty":0.04570642}],"asks":[],"checksum":1727533143,"timestamp":"2024-06-01T17:51:50.214231Z"}]}
{"channel":"book","type":"update","data":[{"symbol":"BTC/USDT","bids":[{"price":67670.6,"qty":0.04405954}],"asks":[],"checksum":1878592175,"timestamp":"2024-06-01T17:51:50.214766Z"}]}
{"channel":"book","type":"update","data":[{"symbol":"BTC/USDT","bids":[{"price":67676.0,"qty":0.10000000}],"asks":[],"checksum":254157552,"timestamp":"2024-06-01T17:51:50.214916Z"}]}
{"channel":"book","type":"update","data":[{"symbol":"BTC/USDT","bids":[{"price":67670.6,"qty":0.00000000},{"price":67657.9,"qty":0.03416867}],"asks":[],"checksum":3471641862,"timestamp":"2024-06-01T17:51:50.217538Z"}]}
{"channel":"book","type":"update","data":[{"symbol":"BTC/USDT","bids":[{"price":67676.0,"qty":0.14405954}],"asks":[],"checksum":4118909186,"timestamp":"2024-06-01T17:51:50.217599Z"}]}
{"channel":"book","type":"update","data":[{"symbol":"BTC/USDT","bids":[{"price":67674.8,"qty":0.09405954},{"price":67674.9,"qty":0.15092896}],"asks":[],"checksum":866885926,"timestamp":"2024-06-01T17:51:50.346994Z"}]}
{"channel":"book","type":"update","data":[{"symbol":"BTC/USDT","bids":[{"price":67676.0,"qty":0.29405954}],"asks":[],"checksum":2423294564,"timestamp":"2024-06-01T17:51:50.351414Z"}]}
{"channel":"book","type":"update","data":[{"symbol":"BTC/USDT","bids":[{"price":67674.8,"qty":0.04405954}],"asks":[],"checksum":2422779475,"timestamp":"2024-06-01T17:51:50.351575Z"}]}
{"channel":"book","type":"update","data":[{"symbol":"BTC/USDT","bids":[{"price":67674.8,"qty":0.00000000},{"price":67657.0,"qty":0.01125861}],"asks":[],"checksum":4140966900,"timestamp":"2024-06-01T17:51:50.351625Z"}]}
{"channel":"book","type":"update","data":[{"symbol":"BTC/USDT","bids":[],"asks":[{"price":67689.0,"qty":0.00000000},{"price":67692.9,"qty":0.09000000},{"price":67681.9,"qty":0.05329446}],"checksum":1340542876,"timestamp":"2024-06-01T17:51:50.391118Z"}]}
{"channel":"book","type":"update","data":[{"symbol":"BTC/USDT","bids":[{"price":67658.0,"qty":0.00000000},{"price":67656.8,"qty":0.78926253},{"price":67673.9,"qty":0.04569570}],"asks":[],"checksum":3216162340,"timestamp":"2024-06-01T17:51:50.391143Z"}]}
{"channel":"book","type":"update","data":[{"symbol":"BTC/USDT","bids":[{"price":67674.9,"qty":0.00092896}],"asks":[],"checksum":2758725473,"timestamp":"2024-06-01T17:51:50.395846Z"}]}
{"channel":"book","type":"update","data":[{"symbol":"BTC/USDT","bids":[{"price":67674.9,"qty":0.00000000},{"price":67656.8,"qty":0.78926253},{"price":67675.8,"qty":0.00092896}],"asks":[],"checksum":2648728092,"timestamp":"2024-06-01T17:51:50.411094Z"}]}
{"channel":"book","type":"update","data":[{"symbol":"BTC/USDT","bids":[],"asks":[{"price":67682.9,"qty":0.09000000}],"checksum":412977197,"timestamp":"2024-06-01T17:51:50.557294Z"}]}
{"channel":"book","type":"update","data":[{"symbol":"BTC/USDT","bids":[{"price":67657.0,"qty":0.00000000},{"price":67656.8,"qty":0.78926253}],"asks":[],"checksum":1957035052,"timestamp":"2024-06-01T17:51:50.636059Z"}]}
{"channel":"book","type":"update","data":[{"symbol":"BTC/USDT","bids":[{"price":67656.9,"qty":0.00433468}],"asks":[],"checksum":2531238021,"timestamp":"2024-06-01T17:51:50.639212Z"}]}
{"channel":"book","type":"update","data":[{"symbol":"BTC/USDT","bids":[],"asks":[{"price":67682.9,"qty":0.00000000},{"price":67692.8,"qty":0.24047267}],"checksum":2382711255,"timestamp":"2024-06-01T17:51:50.645044Z"}]}
{"channel":"book","type":"update","data":[{"symbol":"BTC/USDT","bids":[],"asks":[{"price":67682.9,"qty":0.09000000}],"checksum":2531238021,"timestamp":"2024-06-01T17:51:51.075414Z"}]}
{"channel":"book","type":"update","data":[{"symbol":"BTC/USDT","bids":[],"asks":[{"price":67688.9,"qty":0.00000000},{"price":67692.8,"qty":0.24047267},{"price":67689.1,"qty":0.22170000}],"checksum":2347548673,"timestamp":"2024-06-01T17:51:51.179783Z"}]}
{"channel":"book","type":"update","data":[{"symbol":"BTC/USDT","bids":[],"asks":[{"price":67682.9,"qty":0.00000000},{"price":67692.8,"qty":0.24047267}],"checksum":486317640,"timestamp":"2024-06-01T17:51:51.211694Z"}]}
{"channel":"book","type":"update","data":[{"symbol":"BTC/USDT","bids":[{"price":67676.0,"qty":0.58970850}],"asks":[],"checksum":204809036,"timestamp":"2024-06-01T17:51:51.359935Z"}]}
{"channel":"book","type":"update","data":[{"symbol":"BTC/USDT","bids":[{"price":67673.8,"qty":0.00000000},{"price":67656.8,"qty":0.78926253}],"asks":[],"checksum":1534810653,"timestamp":"2024-06-01T17:51:51.360325Z"}]}
{"channel":"book","type":"update","data":[{"symbol":"BTC/USDT","bids":[{"price":67673.9,"qty":0.00000000},{"price":67656.7,"qty":1.65206491},{"price":67663.9,"qty":0.04570005}],"asks":[],"checksum":2798249970,"timestamp":"2024-06-01T17:51:51.397243Z"}]}
{"channel":"book","type":"update","data":[{"symbol":"BTC/USDT","bids":[{"price":67675.7,"qty":0.00000000},{"price":67656.7,"qty":1.65206491}],"asks":[],"checksum":1485938737,"timestamp":"2024-06-01T17:51:51.400154Z"}]}
{"channel":"book","type":"update","data":[{"symbol":"BTC/USDT","bids":[{"price":67663.9,"qty":0.00000000},{"price":67655.8,"qty":0.00460867},{"price":67676.0,"qty":0.63540038}],"asks":[],"checksum":2481894966,"timestamp":"2024-06-01T17:51:51.442400Z"}]}
{"channel":"book","type":"update","data":[{"symbol":"BTC/USDT","bids":[{"price":67676.0,"qty":0.67830038}],"asks":[],"checksum":616289424,"timestamp":"2024-06-01T17:51:51.445213Z"}]}
{"channel":"book","type":"update","data":[{"symbol":"BTC/USDT","bids":[],"asks":[{"price":67682.9,"qty":0.09000000}],"checksum":724319738,"timestamp":"2024-06-01T17:51:51.985348Z"}]}
{"channel":"book","type":"update","data":[{"symbol":"BTC/USDT","bids":[],"asks":[{"price":67682.9,"qty":0.00000000},{"price":67692.8,"qty":0.24047267}],"checksum":616289424,"timestamp":"2024-06-01T17:51:52.920769Z"}]}
{"channel":"book","type":"update","data":[{"symbol":"BTC/USDT","bids":[{"price":67676.0,"qty":0.63260850},{"price":67663.9,"qty":0.04957258}],"asks":[],"checksum":63826424,"timestamp":"2024-06-01T17:51:53.070697Z"}]}
{"channel":"book","type":"update","data":[{"symbol":"BTC/USDT","bids":[{"price":67656.8,"qty":0.00000000},{"price":67655.8,"qty":0.00460867}],"asks":[],"checksum":21463083,"timestamp":"2024-06-01T17:51:53.262189Z"}]}
{"channel":"book","type":"update","data":[{"symbol":"BTC/USDT","bids":[{"price":67656.8,"qty":0.73320648}],"asks":[],"checksum":164189784,"timestamp":"2024-06-01T17:51:53.266636Z"}]}
{"channel":"book","type":"update","data":[{"symbol":"BTC/USDT","bids":[{"price":67656.9,"qty":0.00000000},{"price":67655.8,"qty":0.00460867}],"asks":[],"checksum":3427011289,"timestamp":"2024-06-01T17:51:53.285578Z"}]}
{"channel":"book","type":"update","data":[{"symbol":"BTC/USDT","bids":[{"price":67656.9,"qty":0.00734392}],"asks":[],"checksum":2775420067,"timestamp":"2024-06-01T17:51:53.290354Z"}]}
{"channel":"book","type":"update","data":[{"symbol":"BTC/USDT","bids":[],"asks":[{"price":67682.9,"qty":0.09000000}],"checksum":134583052,"timestamp":"2024-06-01T17:51:53.727858Z"}]}
{"channel":"book","type":"update","data":[{"symbol":"BTC/USDT","bids":[{"price":67663.8,"qty":0.00000000},{"price":67655.8,"qty":0.00460867}],"asks":[],"checksum":4192890101,"timestamp":"2024-06-01T17:51:53.860842Z"}]}
{"channel":"book","type":"update","data":[{"symbol":"BTC/USDT","bids":[{"price":67662.4,"qty":0.09000000}],"asks":[],"checksum":876650075,"timestamp":"2024-06-01T17:51:53.868604Z"}]}
{"channel":"book","type":"update","data":[{"symbol":"BTC/USDT","bids":[{"price":67662.4,"qty":0.00000000},{"price":67655.8,"qty":0.00460867}],"asks":[],"checksum":4192890101,"timestamp":"2024-06-01T17:51:53.876333Z"}]}
{"channel":"book","type":"update","data":[{"symbol":"BTC/USDT","bids":[{"price":67676.0,"qty":0.33695954}],"asks":[],"checksum":134115254,"timestamp":"2024-06-01T17:51:53.896080Z"}]}
{"channel":"book","type":"update","data":[{"symbol":"BTC/USDT","bids":[{"price":67662.4,"qty":0.09000000}],"asks":[],"checksum":3681262194,"timestamp":"2024-06-01T17:51:53.930838Z"}]}
{"channel":"book","type":"update","data":[{"symbol":"BTC/USDT","bids":[{"price":67663.9,"qty":0.00000000},{"price":67655.8,"qty":0.00460867},{"price":67661.9,"qty":0.04957404}],"asks":[],"checksum":2337527783,"timestamp":"2024-06-01T17:51:53.967331Z"}]}
{"channel":"book","type":"update","data":[{"symbol":"BTC/USDT","bids":[{"price":67676.0,"qty":0.29405954}],"asks":[],"checksum":2346993083,"timestamp":"2024-06-01T17:51:53.981692Z"}]}
{"channel":"book","type":"update","data":[{"symbol":"BTC/USDT","bids":[{"price":67675.8,"qty":0.00000000},{"price":67655.8,"qty":0.00460867}],"asks":[],"checksum":2951068970,"timestamp":"2024-06-01T17:51:54.013084Z"}]}
{"channel":"book","type":"update","data":[{"symbol":"BTC/USDT","bids":[{"price":67669.2,"qty":0.00092896}],"asks":[],"checksum":2460739023,"timestamp":"2024-06-01T17:51:54.167086Z"}]}
{"channel":"book","type":"update","data":[{"symbol":"BTC/USDT","bids":[{"price":67676.0,"qty":0.32505954}],"asks":[],"checksum":4208189797,"timestamp":"2024-06-01T17:51:54.620809Z"}]}
{"channel":"book","type":"update","data":[{"symbol":"BTC/USDT","bids":[{"price":67661.9,"qty":0.00000000},{"price":67655.8,"qty":0.00460867},{"price":67662.5,"qty":0.04957361}],"asks":[],"checksum":4046807753,"timestamp":"2024-06-01T17:51:54.915819Z"}]}
{"channel":"book","type":"update","data":[{"symbol":"BTC/USDT","bids":[{"price":67661.5,"qty":0.04699206}],"asks":[],"checksum":669985484,"timestamp":"2024-06-01T17:51:55.847915Z"}]}
{"channel":"book","type":"update","data":[{"symbol":"BTC/USDT","bids":[{"price":67661.5,"qty":0.00000000},{"price":67656.7,"qty":1.65206491}],"asks":[],"checksum":4046807753,"timestamp":"2024-06-01T17:51:55.856018Z"}]}
{"channel":"book","type":"update","data":[{"symbol":"BTC/USDT","bids":[{"price":67656.9,"qty":0.00000000},{"price":67655.8,"qty":0.00460867}],"asks":[],"checksum":2552030387,"timestamp":"2024-06-01T17:51:55.900521Z"}]}
{"channel":"book","type":"update","data":[{"symbol":"BTC/USDT","bids":[{"price":67656.9,"qty":0.01025514}],"asks":[],"checksum":3980688494,"timestamp":"2024-06-01T17:51:55.905560Z"}]}
{"channel":"book","type":"update","data":[{"symbol":"BTC/USDT","bids":[],"asks":[{"price":67682.9,"qty":0.00000000},{"price":67692.8,"qty":0.24047267}],"checksum":2877336072,"timestamp":"2024-06-01T17:51:55.929018Z"}]}
{"channel":"book","type":"update","data":[{"symbol":"BTC/USDT","bids":[{"price":67656.7,"qty":0.00000000},{"price":67655.8,"qty":0.00460867}],"asks":[],"checksum":1470929121,"timestamp":"2024-06-01T17:51:55.948134Z"}]}
{"channel":"book","type":"update","data":[{"symbol":"BTC/USDT","bids":[{"price":67676.0,"qty":1.92647131}],"asks":[],"checksum":809470296,"timestamp":"2024-06-01T17:51:55.952991Z"}]}
{"channel":"book","type":"update","data":[{"symbol":"BTC/USDT","bids":[{"price":67676.0,"qty":1.96937131}],"asks":[],"checksum":1830817121,"timestamp":"2024-06-01T17:51:55.956114Z"}]}
{"channel":"book","type":"update","data":[{"symbol":"BTC/USDT","bids":[{"price":67669.2,"qty":0.09092896}],"asks":[],"checksum":446149476,"timestamp":"2024-06-01T17:51:55.960610Z"}]}
{"channel":"book","type":"update","data":[{"symbol":"BTC/USDT","bids":[{"price":67676.0,"qty":2.26501938}],"asks":[],"checksum":2279313836,"timestamp":"2024-06-01T17:51:55.970745Z"}]}
{"channel":"book","type":"update","data":[{"symbol":"BTC/USDT","bids":[{"price":67661.5,"qty":0.04961738}],"asks":[],"checksum":1331510971,"timestamp":"2024-06-01T17:51:55.999604Z"}]}
{"channel":"book","type":"update","data":[{"symbol":"BTC/USDT","bids":[{"price":67661.5,"qty":0.00000000},{"price":67655.8,"qty":0.00460867}],"asks":[],"checksum":2279313836,"timestamp":"2024-06-01T17:51:56.006261Z"}]}
{"channel":"book","type":"update","data":[{"symbol":"BTC/USDT","bids":[{"price":67662.5,"qty":0.00000000},{"price":67651.7,"qty":0.09000000},{"price":67657.0,"qty":0.04957769}],"asks":[],"checksum":719771594,"timestamp":"2024-06-01T17:51:56.022562Z"}]}
{"channel":"book","type":"update","data":[{"symbol":"BTC/USDT","bids":[],"asks":[{"price":67681.9,"qty":0.00000000},{"price":67692.9,"qty":0.09000000},{"price":67689.0,"qty":0.05329390}],"checksum":2289371337,"timestamp":"2024-06-01T17:51:56.035818Z"}]}
{"channel":"book","type":"update","data":[{"symbol":"BTC/USDT","bids":[],"asks":[{"price":67689.1,"qty":0.00000000},{"price":67692.9,"qty":0.09000000},{"price":67688.9,"qty":0.22170000}],"checksum":133896969,"timestamp":"2024-06-01T17:51:56.039074Z"}]}
{"channel":"book","type":"update","data":[{"symbol":"BTC/USDT","bids":[{"price":67663.5,"qty":0.04647162}],"asks":[],"checksum":1909453769,"timestamp":"2024-06-01T17:51:56.147244Z"}]}
{"channel":"book","type":"update","data":[{"symbol":"BTC/USDT","bids":[{"price":67663.5,"qty":0.00000000},{"price":67655.8,"qty":0.00460867}],"asks":[],"checksum":133896969,"timestamp":"2024-06-01T17:51:56.155220Z"}]}
{"channel":"book","type":"update","data":[{"symbol":"BTC/USDT","bids":[{"price":67655.8,"qty":0.00000000},{"price":67651.7,"qty":0.09000000}],"asks":[],"checksum":809148281,"timestamp":"2024-06-01T17:51:56.167546Z"}]}
{"channel":"book","type":"update","data":[{"symbol":"BTC/USDT","bids":[{"price":67676.0,"qty":2.26962805}],"asks":[],"checksum":1408967866,"timestamp":"2024-06-01T17:51:56.168946Z"}]}
{"channel":"book","type":"update","data":[{"symbol":"BTC/USDT","bids":[],"asks":[{"price":67692.8,"qty":0.00000000},{"price":67692.9,"qty":0.09000000}],"checksum":2292527828,"timestamp":"2024-06-01T17:51:56.197678Z"}]}
{"channel":"book","type":"update","data":[{"symbol":"BTC/USDT","bids":[{"price":67669.2,"qty":0.00092896}],"asks":[],"checksum":1552413666,"timestamp":"2024-06-01T17:51:56.294131Z"}]}
{"channel":"book","type":"update","data":[{"symbol":"BTC/USDT","bids":[{"price":67664.3,"qty":0.05410255}],"asks":[],"checksum":3123096928,"timestamp":"2024-06-01T17:51:56.298779Z"}]}
{"channel":"book","type":"update","data":[{"symbol":"BTC/USDT","bids":[{"price":67664.3,"qty":0.00000000},{"price":67651.7,"qty":0.09000000}],"asks":[],"checksum":1552413666,"timestamp":"2024-06-01T17:51:56.304583Z"}]}
{"channel":"book","type":"update","data":[{"symbol":"BTC/USDT","bids":[{"price":67669.2,"qty":0.09092896}],"asks":[],"checksum":2292527828,"timestamp":"2024-06-01T17:51:56.309256Z"}]}
{"channel":"book","type":"update","data":[{"symbol":"BTC/USDT","bids":[{"price":67669.2,"qty":0.00092896}],"asks":[],"checksum":1552413666,"timestamp":"2024-06-01T17:51:56.345717Z"}]}
{"channel":"book","type":"update","data":[{"symbol":"BTC/USDT","bids":[{"price":67669.2,"qty":0.09092896}],"asks":[],"checksum":2292527828,"timestamp":"2024-06-01T17:51:56.392061Z"}]}
{"channel":"book","type":"update","data":[{"symbol":"BTC/USDT","bids":[{"price":67669.2,"qty":0.00092896}],"asks":[],"checksum":1552413666,"timestamp":"2024-06-01T17:51:56.398768Z"}]}
{"channel":"book","type":"update","data":[{"symbol":"BTC/USDT","bids":[{"price":67664.5,"qty":0.04647405}],"asks":[],"checksum":3855949288,"timestamp":"2024-06-01T17:51:56.447208Z"}]}
{"channel":"book","type":"update","data":[{"symbol":"BTC/USDT","bids":[{"price":67664.5,"qty":0.00000000},{"price":67651.7,"qty":0.09000000}],"asks":[],"checksum":1552413666,"timestamp":"2024-06-01T17:51:56.453787Z"}]}
{"channel":"book","type":"update","data":[{"symbol":"BTC/USDT","bids":[{"price":67669.2,"qty":0.09092896}],"asks":[],"checksum":2292527828,"timestamp":"2024-06-01T17:51:56.472203Z"}]}
{"channel":"book","type":"update","data":[{"symbol":"BTC/USDT","bids":[{"price":67665.0,"qty":0.05330213}],"asks":[],"checksum":2987063198,"timestamp":"2024-06-01T17:51:56.597637Z"}]}
{"channel":"book","type":"update","data":[{"symbol":"BTC/USDT","bids":[],"asks":[{"price":67689.0,"qty":0.00000000},{"price":67698.3,"qty":0.12089700},{"price":67688.8,"qty":0.05329390}],"checksum":495401155,"timestamp":"2024-06-01T17:51:56.874812Z"}]}
{"channel":"book","type":"update","data":[{"symbol":"BTC/USDT","bids":[],"asks":[{"price":67688.9,"qty":0.00000000},{"price":67698.3,"qty":0.12089700},{"price":67688.7,"qty":0.22170000}],"checksum":1369863618,"timestamp":"2024-06-01T17:51:56.877713Z"}]}
{"channel":"book","type":"update","data":[{"symbol":"BTC/USDT","bids":[{"price":67656.8,"qty":0.00000000},{"price":67651.7,"qty":0.09000000}],"asks":[],"checksum":2691379069,"timestamp":"2024-06-01T17:51:56.982853Z"}]}
{"channel":"book","type":"update","data":[{"symbol":"BTC/USDT","bids":[{"price":67657.0,"qty":0.00000000},{"price":67651.6,"qty":0.09959460},{"price":67651.8,"qty":0.04958134}],"asks":[],"checksum":2486180733,"timestamp":"2024-06-01T17:51:57.043890Z"}]}
{"channel":"book","type":"update","data":[{"symbol":"BTC/USDT","bids":[{"price":67669.2,"qty":0.00092896}],"asks":[],"checksum":440685307,"timestamp":"2024-06-01T17:51:57.195172Z"}]}
{"channel":"book","type":"update","data":[{"symbol":"BTC/USDT","bids":[],"asks":[{"price":67688.8,"qty":0.00000000},{"price":67699.0,"qty":0.12089700},{"price":67688.6,"qty":0.05329326}],"checksum":1715963325,"timestamp":"2024-06-01T17:51:57.729508Z"}]}
{"channel":"book","type":"update","data":[{"symbol":"BTC/USDT","bids":[],"asks":[{"price":67688.7,"qty":0.00000000},{"price":67699.0,"qty":0.12089700},{"price":67688.5,"qty":0.22170000}],"checksum":3411975805,"timestamp":"2024-06-01T17:51:57.732849Z"}]}
{"channel":"book","type":"update","data":[{"symbol":"BTC/USDT","bids":[],"asks":[{"price":67682.9,"qty":0.09000000}],"checksum":2338382947,"timestamp":"2024-06-01T17:51:57.903277Z"}]}
{"channel":"book","type":"update","data":[{"symbol":"BTC/USDT","bids":[{"price":67656.9,"qty":0.00000000},{"price":67651.6,"qty":0.09959460}],"asks":[],"checksum":1429248504,"timestamp":"2024-06-01T17:51:58.415132Z"}]}
{"channel":"book","type":"update","data":[{"symbol":"BTC/USDT","bids":[],"asks":[{"price":67688.6,"qty":0.00000000},{"price":67692.9,"qty":0.09000000},{"price":67688.4,"qty":0.05329326}],"checksum":549436292,"timestamp":"2024-06-01T17:51:58.572047Z"}]}
{"channel":"book","type":"update","data":[{"symbol":"BTC/USDT","bids":[],"asks":[{"price":67688.5,"qty":0.00000000},{"price":67692.9,"qty":0.09000000},{"price":67688.3,"qty":0.22170000}],"checksum":1089275865,"timestamp":"2024-06-01T17:51:58.575231Z"}]}
{"channel":"book","type":"update","data":[{"symbol":"BTC/USDT","bids":[{"price":67651.8,"qty":0.00000000},{"price":67649.7,"qty":0.02213919}],"asks":[],"checksum":3096594809,"timestamp":"2024-06-01T17:51:58.662843Z"}]}
{"channel":"book","type":"update","data":[{"symbol":"BTC/USDT","bids":[],"asks":[{"price":67682.9,"qty":0.00000000},{"price":67692.9,"qty":0.09000000}],"checksum":54231332,"timestamp":"2024-06-01T17:51:58.826595Z"}]}
{"channel":"book","type":"update","data":[{"symbol":"BTC/USDT","bids":[{"price":67661.9,"qty":0.00028678}],"asks":[],"checksum":3784297591,"timestamp":"2024-06-01T17:51:59.102759Z"}]}
{"channel":"book","type":"update","data":[{"symbol":"BTC/USDT","bids":[],"asks":[{"price":67689.2,"qty":0.00000000},{"price":67700.5,"qty":0.30401005}],"checksum":3013094269,"timestamp":"2024-06-01T17:51:59.172806Z"}]}
{"channel":"book","type":"update","data":[{"symbol":"BTC/USDT","bids":[],"asks":[{"price":67692.5,"qty":0.07396000}],"checksum":845843243,"timestamp":"2024-06-01T17:51:59.183512Z"}]}
{"channel":"book","type":"update","data":[{"symbol":"BTC/USDT","bids":[{"price":67669.2,"qty":0.09092896}],"asks":[],"checksum":257131809,"timestamp":"2024-06-01T17:51:59.190308Z"}]}
{"channel":"book","type":"update","data":[{"symbol":"BTC/USDT","bids":[],"asks":[{"price":67692.5,"qty":0.00000000},{"price":67700.5,"qty":0.30401005}],"checksum":895770089,"timestamp":"2024-06-01T17:51:59.226706Z"}]}
{"channel":"book","type":"update","data":[{"symbol":"BTC/USDT","bids":[],"asks":[{"price":67688.3,"qty":0.00000000},{"price":67701.6,"qty":0.09000000}],"checksum":2167648596,"timestamp":"2024-06-01T17:51:59.246453Z"}]}
{"channel":"book","type":"update","data":[{"symbol":"BTC/USDT","bids":[],"asks":[{"price":67692.0,"qty":0.22170000}],"checksum":995609058,"timestamp":"2024-06-01T17:51:59.260789Z"}]}
{"channel":"book","type":"update","data":[{"symbol":"BTC/USDT","bids":[],"asks":[{"price":67700.1,"qty":0.12089400}],"checksum":1037294540,"timestamp":"2024-06-01T17:51:59.269180Z"}]}
{"channel":"book","type":"update","data":[{"symbol":"BTC/USDT","bids":[],"asks":[{"price":67688.4,"qty":0.00000000},{"price":67700.5,"qty":0.30401005},{"price":67689.4,"qty":0.05329316}],"checksum":1412154053,"timestamp":"2024-06-01T17:51:59.299517Z"}]}
{"channel":"book","type":"update","data":[{"symbol":"BTC/USDT","bids":[{"price":67651.8,"qty":0.04958154}],"asks":[],"checksum":4187735573,"timestamp":"2024-06-01T17:51:59.372355Z"}]}
{"channel":"book","type":"update","data":[{"symbol":"BTC/USDT","bids":[],"asks":[{"price":67700.1,"qty":0.00000000},{"price":67700.5,"qty":0.30401005}],"checksum":4280276027,"timestamp":"2024-06-01T17:52:00.168592Z"}]}
{"channel":"book","type":"update","data":[{"symbol":"BTC/USDT","bids":[],"asks":[{"price":67694.7,"qty":0.07396000}],"checksum":1387815411,"timestamp":"2024-06-01T17:52:00.195902Z"}]}
{"channel":"book","type":"update","data":[{"symbol":"BTC/USDT","bids":[{"price":67676.0,"qty":2.35962805}],"asks":[],"checksum":1319243645,"timestamp":"2024-06-01T17:52:00.247468Z"}]}
{"channel":"book","type":"update","data":[{"symbol":"BTC/USDT","bids":[{"price":67676.0,"qty":2.26962805}],"asks":[],"checksum":1387815411,"timestamp":"2024-06-01T17:52:00.393896Z"}]}
{"channel":"book","type":"update","data":[{"symbol":"BTC/USDT","bids":[],"asks":[{"price":67692.0,"qty":0.00000000},{"price":67700.5,"qty":0.30401005},{"price":67692.8,"qty":0.22170000}],"checksum":3330070609,"timestamp":"2024-06-01T17:52:00.730224Z"}]}
{"channel":"book","type":"update","data":[{"symbol":"BTC/USDT","bids":[],"asks":[{"price":67689.4,"qty":0.00000000},{"price":67700.5,"qty":0.30401005},{"price":67692.7,"qty":0.05329304}],"checksum":793467785,"timestamp":"2024-06-01T17:52:00.808589Z"}]}
{"channel":"book","type":"update","data":[{"symbol":"BTC/USDT","bids":[],"asks":[{"price":67692.8,"qty":0.00000000},{"price":67700.5,"qty":0.30401005},{"price":67692.6,"qty":0.22170000}],"checksum":2205045558,"timestamp":"2024-06-01T17:52:01.419154Z"}]}
{"channel":"book","type":"update","data":[{"symbol":"BTC/USDT","bids":[{"price":67676.0,"qty":2.35962805}],"asks":[],"checksum":2675195320,"timestamp":"2024-06-01T17:52:01.488476Z"}]}
{"channel":"book","type":"update","data":[{"symbol":"BTC/USDT","bids":[],"asks":[{"price":67692.7,"qty":0.00000000},{"price":67700.5,"qty":0.30401005},{"price":67689.4,"qty":0.05329304}],"checksum":1420657301,"timestamp":"2024-06-01T17:52:01.586669Z"}]}
{"channel":"book","type":"update","data":[{"symbol":"BTC/USDT","bids":[{"price":67676.0,"qty":2.26962805}],"asks":[],"checksum":1220013083,"timestamp":"2024-06-01T17:52:01.678112Z"}]}
{"channel":"book","type":"update","data":[{"symbol":"BTC/USDT","bids":[],"asks":[{"price":67689.4,"qty":0.00000000},{"price":67700.5,"qty":0.30401005},{"price":67692.5,"qty":0.05329304}],"checksum":1601675725,"timestamp":"2024-06-01T17:52:02.078827Z"}]}
{"channel":"book","type":"update","data":[{"symbol":"BTC/USDT","bids":[],"asks":[{"price":67692.6,"qty":0.00000000},{"price":67700.5,"qty":0.30401005},{"price":67692.4,"qty":0.22170000}],"checksum":3145804155,"timestamp":"2024-06-01T17:52:02.082058Z"}]}
{"channel":"book","type":"update","data":[{"symbol":"BTC/USDT","bids":[{"price":67669.2,"qty":0.00092896}],"asks":[],"checksum":3668519923,"timestamp":"2024-06-01T17:52:02.103873Z"}]}
{"channel":"book","type":"update","data":[{"symbol":"BTC/USDT","bids":[{"price":67669.2,"qty":0.09092896}],"asks":[],"checksum":3145804155,"timestamp":"2024-06-01T17:52:02.108744Z"}]}
{"channel":"book","type":"update","data":[{"symbol":"BTC/USDT","bids":[{"price":67669.2,"qty":0.00092896}],"asks":[],"checksum":3668519923,"timestamp":"2024-06-01T17:52:02.135550Z"}]}
{"channel":"book","type":"update","data":[{"symbol":"BTC/USDT","bids":[],"asks":[{"price":67676.1,"qty":0.00000000},{"price":67700.5,"qty":0.30401005}],"checksum":1792501713,"timestamp":"2024-06-01T17:52:02.224143Z"}]}
{"channel":"book","type":"update","data":[{"symbol":"BTC/USDT","bids":[{"price":67661.8,"qty":0.00000000},{"price":67651.6,"qty":0.09959460}],"asks":[],"checksum":3430698472,"timestamp":"2024-06-01T17:52:02.224246Z"}]}
{"channel":"book","type":"update","data":[{"symbol":"BTC/USDT","bids":[{"price":67669.2,"qty":0.09092896}],"asks":[],"checksum":4102367716,"timestamp":"2024-06-01T17:52:02.226829Z"}]}
{"channel":"book","type":"update","data":[{"symbol":"BTC/USDT","bids":[{"price":67676.0,"qty":2.22672805}],"asks":[],"checksum":2225541741,"timestamp":"2024-06-01T17:52:02.227086Z"}]}
{"channel":"book","type":"update","data":[{"symbol":"BTC/USDT","bids":[{"price":67676.1,"qty":0.04290000}],"asks":[],"checksum":2187144153,"timestamp":"2024-06-01T17:52:02.227260Z"}]}
{"channel":"book","type":"update","data":[{"symbol":"BTC/USDT","bids":[{"price":67676.1,"qty":0.33856293}],"asks":[],"checksum":2576220246,"timestamp":"2024-06-01T17:52:02.227442Z"}]}
{"channel":"book","type":"update","data":[{"symbol":"BTC/USDT","bids":[{"price":67661.9,"qty":0.00000000},{"price":67651.6,"qty":0.09959460}],"asks":[],"checksum":3703464622,"timestamp":"2024-06-01T17:52:02.228416Z"}]}
{"channel":"book","type":"update","data":[{"symbol":"BTC/USDT","bids":[{"price":67669.2,"qty":0.00092896}],"asks":[],"checksum":3747254081,"timestamp":"2024-06-01T17:52:02.230453Z"}]}
{"channel":"book","type":"update","data":[{"symbol":"BTC/USDT","bids":[{"price":67676.0,"qty":1.93107998}],"asks":[],"checksum":242848056,"timestamp":"2024-06-01T17:52:02.230634Z"}]}
{"channel":"book","type":"update","data":[{"symbol":"BTC/USDT","bids":[{"price":67676.0,"qty":1.88107998},{"price":67676.1,"qty":0.38856293}],"asks":[],"checksum":2705821570,"timestamp":"2024-06-01T17:52:02.231831Z"}]}
{"channel":"book","type":"update","data":[{"symbol":"BTC/USDT","bids":[{"price":67669.3,"qty":0.09000000}],"asks":[],"checksum":1019130796,"timestamp":"2024-06-01T17:52:02.233262Z"}]}
{"channel":"book","type":"update","data":[{"symbol":"BTC/USDT","bids":[{"price":67668.0,"qty":0.14790060}],"asks":[],"checksum":1401108347,"timestamp":"2024-06-01T17:52:02.234422Z"}]}
{"channel":"book","type":"update","data":[{"symbol":"BTC/USDT","bids":[{"price":67669.2,"qty":0.00000000},{"price":67651.7,"qty":0.09000000},{"price":67676.1,"qty":0.38949189}],"asks":[],"checksum":2735821965,"timestamp":"2024-06-01T17:52:02.242064Z"}]}
{"channel":"book","type":"update","data":[{"symbol":"BTC/USDT","bids":[{"price":67676.0,"qty":1.85007998}],"asks":[],"checksum":580605159,"timestamp":"2024-06-01T17:52:02.268170Z"}]}
{"channel":"book","type":"update","data":[{"symbol":"BTC/USDT","bids":[{"price":67676.1,"qty":0.43355143}],"asks":[],"checksum":2081638462,"timestamp":"2024-06-01T17:52:02.273120Z"}]}
{"channel":"book","type":"update","data":[{"symbol":"BTC/USDT","bids":[{"price":67676.1,"qty":0.48355143}],"asks":[],"checksum":1822292146,"timestamp":"2024-06-01T17:52:02.273145Z"}]}
{"channel":"book","type":"update","data":[{"symbol":"BTC/USDT","bids":[{"price":67676.1,"qty":0.63355143}],"asks":[],"checksum":3634721721,"timestamp":"2024-06-01T17:52:02.273319Z"}]}
{"channel":"book","type":"update","data":[{"symbol":"BTC/USDT","bids":[{"price":67676.1,"qty":0.64555143}],"asks":[],"checksum":616253325,"timestamp":"2024-06-01T17:52:02.283036Z"}]}
{"channel":"book","type":"update","data":[{"symbol":"BTC/USDT","bids":[{"price":67676.1,"qty":0.73555143}],"asks":[],"checksum":10949367,"timestamp":"2024-06-01T17:52:02.292535Z"}]}
{"channel":"book","type":"update","data":[{"symbol":"BTC/USDT","bids":[],"asks":[{"price":67692.5,"qty":0.00000000},{"price":67701.6,"qty":0.09000000},{"price":67689.4,"qty":0.05329304}],"checksum":2952827125,"timestamp":"2024-06-01T17:52:02.327598Z"}]}
{"channel":"book","type":"update","data":[{"symbol":"BTC/USDT","bids":[],"asks":[{"price":67676.2,"qty":0.08973498}],"checksum":2705255072,"timestamp":"2024-06-01T17:52:02.331657Z"}]}
{"channel":"book","type":"update","data":[{"symbol":"BTC/USDT","bids":[{"price":67676.0,"qty":1.70007998}],"asks":[],"checksum":1142612161,"timestamp":"2024-06-01T17:52:02.332198Z"}]}
{"channel":"book","type":"update","data":[{"symbol":"BTC/USDT","bids":[{"price":67676.0,"qty":1.65007998}],"asks":[],"checksum":948322387,"timestamp":"2024-06-01T17:52:02.332311Z"}]}
{"channel":"book","type":"update","data":[{"symbol":"BTC/USDT","bids":[{"price":67676.0,"qty":1.60602044}],"asks":[],"checksum":2986509476,"timestamp":"2024-06-01T17:52:02.332390Z"}]}
{"channel":"book","type":"update","data":[{"symbol":"BTC/USDT","bids":[],"asks":[{"price":67694.7,"qty":0.00000000},{"price":67701.6,"qty":0.09000000}],"checksum":2676986146,"timestamp":"2024-06-01T17:52:02.337776Z"}]}
{"channel":"book","type":"update","data":[{"symbol":"BTC/USDT","bids":[],"asks":[{"price":67676.2,"qty":0.05026000}],"checksum":2394024823,"timestamp":"2024-06-01T17:52:02.365352Z"}]}
{"channel":"book","type":"update","data":[{"symbol":"BTC/USDT","bids":[],"asks":[{"price":67698.1,"qty":0.07396000}],"checksum":1676613712,"timestamp":"2024-06-01T17:52:02.367567Z"}]}
{"channel":"book","type":"update","data":[{"symbol":"BTC/USDT","bids":[],"asks":[{"price":67689.5,"qty":0.00000000},{"price":67701.6,"qty":0.09000000}],"checksum":4040707178,"timestamp":"2024-06-01T17:52:02.381283Z"}]}
{"channel":"book","type":"update","data":[{"symbol":"BTC/USDT","bids":[],"asks":[{"price":67696.0,"qty":0.14783968}],"checksum":1188007532,"timestamp":"2024-06-01T17:52:02.385930Z"}]}
{"channel":"book","type":"update","data":[{"symbol":"BTC/USDT","bids":[],"asks":[{"price":67689.4,"qty":0.00000000},{"price":67701.6,"qty":0.09000000},{"price":67692.3,"qty":0.05329292}],"checksum":1512389212,"timestamp":"2024-06-01T17:52:02.408474Z"}]}
{"channel":"book","type":"update","data":[{"symbol":"BTC/USDT","bids":[{"price":67651.8,"qty":0.07172019}],"asks":[],"checksum":1480284768,"timestamp":"2024-06-01T17:52:02.422659Z"}]}
{"channel":"book","type":"update","data":[{"symbol":"BTC/USDT","bids":[{"price":67668.1,"qty":0.00028593}],"asks":[],"checksum":209318797,"timestamp":"2024-06-01T17:52:02.439148Z"}]}
{"channel":"book","type":"update","data":[{"symbol":"BTC/USDT","bids":[],"asks":[{"price":67684.2,"qty":0.03947498}],"checksum":4022142579,"timestamp":"2024-06-01T17:52:02.590106Z"}]}
{"channel":"book","type":"update","data":[{"symbol":"BTC/USDT","bids":[{"price":67676.1,"qty":0.64555143}],"asks":[],"checksum":2126422238,"timestamp":"2024-06-01T17:52:02.614001Z"}]}
{"channel":"book","type":"update","data":[{"symbol":"BTC/USDT","bids":[{"price":67676.1,"qty":0.73555143}],"asks":[],"checksum":4022142579,"timestamp":"2024-06-01T17:52:02.968463Z"}]}
{"channel":"book","type":"update","data":[{"symbol":"BTC/USDT","bids":[{"price":67651.8,"qty":0.04958154}],"asks":[],"checksum":1013251593,"timestamp":"2024-06-01T17:52:02.984456Z"}]}
{"channel":"book","type":"update","data":[{"symbol":"BTC/USDT","bids":[{"price":67651.9,"qty":0.02213854}],"asks":[],"checksum":3565756704,"timestamp":"2024-06-01T17:52:03.024652Z"}]}
{"channel":"book","type":"update","data":[{"symbol":"BTC/USDT","bids":[],"asks":[{"price":67692.4,"qty":0.00000000},{"price":67700.5,"qty":0.30401005},{"price":67692.8,"qty":0.22170000}],"checksum":1322895518,"timestamp":"2024-06-01T17:52:03.099766Z"}]}
{"channel":"book","type":"update","data":[{"symbol":"BTC/USDT","bids":[{"price":67652.0,"qty":0.05331101}],"asks":[],"checksum":3034948341,"timestamp":"2024-06-01T17:52:03.130364Z"}]}
{"channel":"book","type":"update","data":[{"symbol":"BTC/USDT","bids":[],"asks":[{"price":67698.1,"qty":0.00000000},{"price":67700.5,"qty":0.30401005}],"checksum":3397019346,"timestamp":"2024-06-01T17:52:03.145392Z"}]}
{"channel":"book","type":"update","data":[{"symbol":"BTC/USDT","bids":[],"asks":[{"price":67692.8,"qty":0.00000000},{"price":67701.6,"qty":0.09000000}],"checksum":2566464610,"timestamp":"2024-06-01T17:52:03.145998Z"}]}
{"channel":"book","type":"update","data":[{"symbol":"BTC/USDT","bids":[],"asks":[{"price":67692.9,"qty":0.00000000},{"price":67702.1,"qty":0.19890820}],"checksum":1586895769,"timestamp":"2024-06-01T17:52:03.147500Z"}]}
{"channel":"book","type":"update","data":[{"symbol":"BTC/USDT","bids":[{"price":67676.1,"qty":0.82555143}],"asks":[],"checksum":507742574,"timestamp":"2024-06-01T17:52:03.149025Z"}]}
{"channel":"book","type":"update","data":[{"symbol":"BTC/USDT","bids":[],"asks":[{"price":67692.3,"qty":0.00000000},{"price":67706.1,"qty":0.12089100},{"price":67692.7,"qty":0.05329287}],"checksum":4120466730,"timestamp":"2024-06-01T17:52:03.152138Z"}]}
{"channel":"book","type":"update","data":[{"symbol":"BTC/USDT","bids":[{"price":67676.1,"qty":0.73555143}],"asks":[],"checksum":3041707997,"timestamp":"2024-06-01T17:52:03.215598Z"}]}
{"channel":"book","type":"update","data":[{"symbol":"BTC/USDT","bids":[],"asks":[{"price":67692.7,"qty":0.00000000},{"price":67706.3,"qty":0.00460867},{"price":67695.9,"qty":0.05329287}],"checksum":783806923,"timestamp":"2024-06-01T17:52:03.225042Z"}]}
{"channel":"book","type":"update","data":[{"symbol":"BTC/USDT","bids":[{"price":67676.1,"qty":0.82555143}],"asks":[],"checksum":1851941692,"timestamp":"2024-06-01T17:52:03.332552Z"}]}
{"channel":"book","type":"update","data":[{"symbol":"BTC/USDT","bids":[],"asks":[{"price":67701.4,"qty":0.07396000}],"checksum":1505633393,"timestamp":"2024-06-01T17:52:03.370767Z"}]}
{"channel":"book","type":"update","data":[{"symbol":"BTC/USDT","bids":[{"price":67676.1,"qty":0.73555143}],"asks":[],"checksum":426489478,"timestamp":"2024-06-01T17:52:03.407668Z"}]}
{"channel":"book","type":"update","data":[{"symbol":"BTC/USDT","bids":[],"asks":[{"price":67700.4,"qty":0.05253833}],"checksum":1107999528,"timestamp":"2024-06-01T17:52:03.521119Z"}]}
{"channel":"book","type":"update","data":[{"symbol":"BTC/USDT","bids":[],"asks":[{"price":67698.2,"qty":0.22170000}],"checksum":1077456703,"timestamp":"2024-06-01T17:52:03.671633Z"}]}
{"channel":"book","type":"update","data":[{"symbol":"BTC/USDT","bids":[{"price":67652.7,"qty":0.02213793}],"asks":[],"checksum":2945349169,"timestamp":"2024-06-01T17:52:03.708638Z"}]}
{"channel":"book","type":"update","data":[{"symbol":"BTC/USDT","bids":[{"price":67652.7,"qty":0.00000000},{"price":67651.8,"qty":0.05331114}],"asks":[],"checksum":3273739649,"timestamp":"2024-06-01T17:52:04.350127Z"}]}
{"channel":"book","type":"update","data":[{"symbol":"BTC/USDT","bids":[{"price":67656.9,"qty":0.02213460}],"asks":[],"checksum":4215260707,"timestamp":"2024-06-01T17:52:04.466531Z"}]}
{"channel":"book","type":"update","data":[{"symbol":"BTC/USDT","bids":[{"price":67676.1,"qty":0.78884338}],"asks":[],"checksum":653237070,"timestamp":"2024-06-01T17:52:04.476168Z"}]}
{"channel":"book","type":"update","data":[{"symbol":"BTC/USDT","bids":[],"asks":[{"price":67689.8,"qty":0.09000000}],"checksum":3663568587,"timestamp":"2024-06-01T17:52:04.862115Z"}]}
{"channel":"book","type":"update","data":[{"symbol":"BTC/USDT","bids":[{"price":67676.1,"qty":0.69884338}],"asks":[],"checksum":2011912701,"timestamp":"2024-06-01T17:52:04.863412Z"}]}
{"channel":"book","type":"update","data":[{"symbol":"BTC/USDT","bids":[{"price":67676.1,"qty":0.78884338}],"asks":[],"checksum":3663568587,"timestamp":"2024-06-01T17:52:04.954454Z"}]}
{"channel":"book","type":"update","data":[{"symbol":"BTC/USDT","bids":[{"price":67656.9,"qty":0.00000000},{"price":67651.7,"qty":0.09000000}],"asks":[],"checksum":2600443333,"timestamp":"2024-06-01T17:52:05.029288Z"}]}
{"channel":"book","type":"update","data":[{"symbol":"BTC/USDT","bids":[{"price":67656.7,"qty":0.02213459}],"asks":[],"checksum":2636539806,"timestamp":"2024-06-01T17:52:05.069226Z"}]}
{"channel":"book","type":"update","data":[{"symbol":"BTC/USDT","bids":[{"price":67676.1,"qty":0.73555143}],"asks":[],"checksum":1089878771,"timestamp":"2024-06-01T17:52:05.144040Z"}]}
{"channel":"book","type":"update","data":[{"symbol":"BTC/USDT","bids":[],"asks":[{"price":67698.2,"qty":0.00000000},{"price":67700.5,"qty":0.30401005},{"price":67700.3,"qty":0.22170000}],"checksum":3794208469,"timestamp":"2024-06-01T17:52:05.146983Z"}]}
{"channel":"book","type":"update","data":[{"symbol":"BTC/USDT","bids":[{"price":67676.1,"qty":0.64555143}],"asks":[],"checksum":1931780216,"timestamp":"2024-06-01T17:52:05.148416Z"}]}
{"channel":"book","type":"update","data":[{"symbol":"BTC/USDT","bids":[{"price":67676.1,"qty":0.69884337}],"asks":[],"checksum":2161802181,"timestamp":"2024-06-01T17:52:05.331528Z"}]}
{"channel":"book","type":"update","data":[{"symbol":"BTC/USDT","bids":[{"price":67676.1,"qty":0.78884337}],"asks":[],"checksum":762100979,"timestamp":"2024-06-01T17:52:05.390957Z"}]}
{"channel":"book","type":"update","data":[{"symbol":"BTC/USDT","bids":[{"price":67676.1,"qty":0.69884337}],"asks":[],"checksum":2161802181,"timestamp":"2024-06-01T17:52:05.405838Z"}]}
{"channel":"book","type":"update","data":[{"symbol":"BTC/USDT","bids":[{"price":67669.3,"qty":0.00000000},{"price":67651.7,"qty":0.09000000}],"asks":[],"checksum":2484151995,"timestamp":"2024-06-01T17:52:05.424699Z"}]}
{"channel":"book","type":"update","data":[{"symbol":"BTC/USDT","bids":[{"price":67669.3,"qty":0.09000000}],"asks":[],"checksum":2161802181,"timestamp":"2024-06-01T17:52:05.434431Z"}]}
{"channel":"book","type":"update","data":[{"symbol":"BTC/USDT","bids":[{"price":67656.7,"qty":0.00000000},{"price":67651.7,"qty":0.09000000}],"asks":[],"checksum":2265153950,"timestamp":"2024-06-01T17:52:05.716755Z"}]}
{"channel":"book","type":"update","data":[{"symbol":"BTC/USDT","bids":[{"price":67657.0,"qty":0.02213475}],"asks":[],"checksum":2799978550,"timestamp":"2024-06-01T17:52:05.809455Z"}]}
{"channel":"book","type":"update","data":[{"symbol":"BTC/USDT","bids":[{"price":67668.1,"qty":0.00000000},{"price":67651.7,"qty":0.09000000}],"asks":[],"checksum":3347429544,"timestamp":"2024-06-01T17:52:05.988916Z"}]}
{"channel":"book","type":"update","data":[{"symbol":"BTC/USDT","bids":[],"asks":[{"price":67700.4,"qty":0.00000000},{"price":67700.5,"qty":0.30401005}],"checksum":1157035249,"timestamp":"2024-06-01T17:52:06.232301Z"}]}
{"channel":"book","type":"update","data":[{"symbol":"BTC/USDT","bids":[],"asks":[{"price":67700.3,"qty":0.00000000},{"price":67701.4,"qty":0.07396000},{"price":67700.4,"qty":0.22170000}],"checksum":3004929187,"timestamp":"2024-06-01T17:52:06.235545Z"}]}
{"channel":"book","type":"update","data":[{"symbol":"BTC/USDT","bids":[{"price":67657.0,"qty":0.00000000},{"price":67651.6,"qty":0.09959460}],"asks":[],"checksum":2525924241,"timestamp":"2024-06-01T17:52:06.460024Z"}]}
{"channel":"book","type":"update","data":[{"symbol":"BTC/USDT","bids":[{"price":67657.5,"qty":0.02213454}],"asks":[],"checksum":196166497,"timestamp":"2024-06-01T17:52:06.500122Z"}]}
{"channel":"book","type":"update","data":[{"symbol":"BTC/USDT","bids":[{"price":67669.3,"qty":0.00000000},{"price":67651.6,"qty":0.09959460}],"asks":[],"checksum":2532566851,"timestamp":"2024-06-01T17:52:06.519905Z"}]}
{"channel":"book","type":"update","data":[{"symbol":"BTC/USDT","bids":[{"price":67669.3,"qty":0.09000000}],"asks":[],"checksum":196166497,"timestamp":"2024-06-01T17:52:06.585370Z"}]}
{"channel":"book","type":"update","data":[{"symbol":"BTC/USDT","bids":[{"price":67676.1,"qty":0.69791441}],"asks":[],"checksum":1274241671,"timestamp":"2024-06-01T17:52:06.618317Z"}]}
{"channel":"book","type":"update","data":[{"symbol":"BTC/USDT","bids":[{"price":67657.5,"qty":0.00000000},{"price":67651.6,"qty":0.09959460}],"asks":[],"checksum":3603737207,"timestamp":"2024-06-01T17:52:07.058844Z"}]}
{"channel":"book","type":"update","data":[{"symbol":"BTC/USDT","bids":[{"price":67657.2,"qty":0.02213475}],"asks":[],"checksum":396211256,"timestamp":"2024-06-01T17:52:07.098931Z"}]}
{"channel":"book","type":"update","data":[{"symbol":"BTC/USDT","bids":[{"price":67657.2,"qty":0.00000000},{"price":67651.6,"qty":0.09959460}],"asks":[],"checksum":3603737207,"timestamp":"2024-06-01T17:52:07.186413Z"}]}
{"channel":"book","type":"update","data":[{"symbol":"BTC/USDT","bids":[],"asks":[{"price":67700.5,"qty":0.00000000},{"price":67701.4,"qty":0.07396000}],"checksum":3634521932,"timestamp":"2024-06-01T17:52:07.639942Z"}]}
{"channel":"book","type":"update","data":[{"symbol":"BTC/USDT","bids":[],"asks":[{"price":67682.0,"qty":0.01400000}],"checksum":2287603519,"timestamp":"2024-06-01T17:52:07.640381Z"}]}
{"channel":"book","type":"update","data":[{"symbol":"BTC/USDT","bids":[],"asks":[{"price":67700.4,"qty":0.00000000},{"price":67701.6,"qty":0.09000000},{"price":67701.3,"qty":0.22170000}],"checksum":4020533312,"timestamp":"2024-06-01T17:52:07.643150Z"}]}
{"channel":"book","type":"update","data":[{"symbol":"BTC/USDT","bids":[],"asks":[{"price":67693.5,"qty":0.19976708}],"checksum":7814907,"timestamp":"2024-06-01T17:52:07.643226Z"}]}
{"channel":"book","type":"update","data":[{"symbol":"BTC/USDT","bids":[],"asks":[{"price":67695.9,"qty":0.00000000},{"price":67701.4,"qty":0.07396000},{"price":67693.4,"qty":0.05328938}],"checksum":2674858105,"timestamp":"2024-06-01T17:52:07.714737Z"}]}
{"channel":"book","type":"update","data":[{"symbol":"BTC/USDT","bids":[{"price":67651.8,"qty":0.10552189}],"asks":[],"checksum":1815071136,"timestamp":"2024-06-01T17:52:07.807177Z"}]}
{"channel":"book","type":"update","data":[{"symbol":"BTC/USDT","bids":[{"price":67669.3,"qty":0.00000000},{"price":67651.6,"qty":0.09959460}],"asks":[],"checksum":2786254668,"timestamp":"2024-06-01T17:52:07.828388Z"}]}
{"channel":"book","type":"update","data":[{"symbol":"BTC/USDT","bids":[{"price":67669.3,"qty":0.09000000}],"asks":[],"checksum":1815071136,"timestamp":"2024-06-01T17:52:07.836743Z"}]}
{"channel":"book","type":"update","data":[{"symbol":"BTC/USDT","bids":[{"price":67657.9,"qty":0.00000000},{"price":67651.6,"qty":0.09959460}],"asks":[],"checksum":1172727196,"timestamp":"2024-06-01T17:52:08.132189Z"}]}
{"channel":"book","type":"update","data":[{"symbol":"BTC/USDT","bids":[{"price":67658.1,"qty":0.02213475}],"asks":[],"checksum":2218144596,"timestamp":"2024-06-01T17:52:08.435698Z"}]}
{"channel":"book","type":"update","data":[{"symbol":"BTC/USDT","bids":[],"asks":[{"price":67689.8,"qty":0.00000000},{"price":67701.4,"qty":0.07396000}],"checksum":1643824837,"timestamp":"2024-06-01T17:52:08.634598Z"}]}
{"channel":"book","type":"update","data":[{"symbol":"BTC/USDT","bids":[{"price":67676.1,"qty":0.78791441}],"asks":[],"checksum":3886352506,"timestamp":"2024-06-01T17:52:08.635201Z"}]}
{"channel":"book","type":"update","data":[{"symbol":"BTC/USDT","bids":[],"asks":[{"price":67689.8,"qty":0.09000000}],"checksum":40500715,"timestamp":"2024-06-01T17:52:08.661241Z"}]}
{"channel":"book","type":"update","data":[{"symbol":"BTC/USDT","bids":[],"asks":[{"price":67682.0,"qty":0.00000000},{"price":67701.4,"qty":0.07396000}],"checksum":3642373584,"timestamp":"2024-06-01T17:52:08.853927Z"}]}
{"channel":"book","type":"update","data":[{"symbol":"BTC/USDT","bids":[{"price":67658.1,"qty":0.00000000},{"price":67651.6,"qty":0.09959460}],"asks":[],"checksum":415916824,"timestamp":"2024-06-01T17:52:09.077309Z"}]}
{"channel":"book","type":"update","data":[{"symbol":"BTC/USDT","bids":[{"price":67676.1,"qty":0.69791441}],"asks":[],"checksum":2660609447,"timestamp":"2024-06-01T17:52:09.098599Z"}]}
{"channel":"book","type":"update","data":[{"symbol":"BTC/USDT","bids":[{"price":67658.0,"qty":0.02213474}],"asks":[],"checksum":2439909818,"timestamp":"2024-06-01T17:52:09.117495Z"}]}
{"channel":"book","type":"update","data":[{"symbol":"BTC/USDT","bids":[],"asks":[{"price":67693.4,"qty":0.00000000},{"price":67701.6,"qty":0.09000000},{"price":67689.7,"qty":0.05328927}],"checksum":2202688401,"timestamp":"2024-06-01T17:52:09.581552Z"}]}
{"channel":"book","type":"update","data":[{"symbol":"BTC/USDT","bids":[],"asks":[{"price":67689.7,"qty":0.00000000},{"price":67701.6,"qty":0.09000000},{"price":67693.4,"qty":0.05328927}],"checksum":4161343116,"timestamp":"2024-06-01T17:52:09.630654Z"}]}
{"channel":"book","type":"update","data":[{"symbol":"BTC/USDT","bids":[{"price":67658.0,"qty":0.00000000},{"price":67651.6,"qty":0.09959460}],"asks":[],"checksum":4159877777,"timestamp":"2024-06-01T17:52:09.720640Z"}]}
{"channel":"book","type":"update","data":[{"symbol":"BTC/USDT","bids":[{"price":67658.7,"qty":0.02213365}],"asks":[],"checksum":751889974,"timestamp":"2024-06-01T17:52:09.760964Z"}]}
{"channel":"book","type":"update","data":[{"symbol":"BTC/USDT","bids":[{"price":67664.6,"qty":0.17735600}],"asks":[],"checksum":374943238,"timestamp":"2024-06-01T17:52:10.005928Z"}]}
{"channel":"book","type":"update","data":[{"symbol":"BTC/USDT","bids":[],"asks":[{"price":67693.4,"qty":0.00000000},{"price":67701.6,"qty":0.09000000},{"price":67689.7,"qty":0.05328927}],"checksum":1965293962,"timestamp":"2024-06-01T17:52:10.184531Z"}]}
{"channel":"book","type":"update","data":[{"symbol":"BTC/USDT","bids":[],"asks":[{"price":67689.7,"qty":0.00000000},{"price":67701.6,"qty":0.09000000},{"price":67693.4,"qty":0.05328837}],"checksum":2367069030,"timestamp":"2024-06-01T17:52:10.246668Z"}]}
{"channel":"book","type":"update","data":[{"symbol":"BTC/USDT","bids":[{"price":67658.7,"qty":0.00000000},{"price":67651.7,"qty":0.09000000}],"asks":[],"checksum":3888823645,"timestamp":"2024-06-01T17:52:10.402375Z"}]}
{"channel":"book","type":"update","data":[{"symbol":"BTC/USDT","bids":[{"price":67659.3,"qty":0.02213362}],"asks":[],"checksum":3519409576,"timestamp":"2024-06-01T17:52:10.442582Z"}]}
{"channel":"book","type":"update","data":[{"symbol":"BTC/USDT","bids":[],"asks":[{"price":67693.4,"qty":0.00000000},{"price":67701.6,"qty":0.09000000},{"price":67689.7,"qty":0.05328821}],"checksum":3307998174,"timestamp":"2024-06-01T17:52:10.849140Z"}]}
{"channel":"book","type":"update","data":[{"symbol":"BTC/USDT","bids":[],"asks":[{"price":67689.7,"qty":0.00000000},{"price":67701.6,"qty":0.09000000},{"price":67693.4,"qty":0.05328821}],"checksum":2296392779,"timestamp":"2024-06-01T17:52:11.018707Z"}]}
{"channel":"book","type":"update","data":[{"symbol":"BTC/USDT","bids":[{"price":67659.3,"qty":0.00000000},{"price":67651.7,"qty":0.09000000}],"asks":[],"checksum":3203366078,"timestamp":"2024-06-01T17:52:11.084742Z"}]}
{"channel":"book","type":"update","data":[{"symbol":"BTC/USDT","bids":[{"price":67659.2,"qty":0.02213362}],"asks":[],"checksum":2680703115,"timestamp":"2024-06-01T17:52:11.124993Z"}]}
{"channel":"book","type":"update","data":[{"symbol":"BTC/USDT","bids":[{"price":67651.8,"qty":0.00000000},{"price":67651.7,"qty":0.09000000}],"asks":[],"checksum":2037584077,"timestamp":"2024-06-01T17:52:11.417170Z"}]}
{"channel":"book","type":"update","data":[{"symbol":"BTC/USDT","bids":[{"price":67659.2,"qty":0.00000000},{"price":67651.6,"qty":0.09959460}],"asks":[],"checksum":1382021983,"timestamp":"2024-06-01T17:52:11.686351Z"}]}
{"channel":"book","type":"update","data":[{"symbol":"BTC/USDT","bids":[{"price":67660.0,"qty":0.02213363}],"asks":[],"checksum":3627453243,"timestamp":"2024-06-01T17:52:11.726673Z"}]}
{"channel":"book","type":"update","data":[{"symbol":"BTC/USDT","bids":[],"asks":[{"price":67693.4,"qty":0.00000000},{"price":67701.6,"qty":0.09000000},{"price":67689.7,"qty":0.05328816}],"checksum":2392463058,"timestamp":"2024-06-01T17:52:11.986676Z"}]}
{"channel":"book","type":"update","data":[{"symbol":"BTC/USDT","bids":[],"asks":[{"price":67689.7,"qty":0.00000000},{"price":67701.6,"qty":0.09000000},{"price":67693.4,"qty":0.05328816}],"checksum":4179249905,"timestamp":"2024-06-01T17:52:12.042828Z"}]}
{"channel":"book","type":"update","data":[{"symbol":"BTC/USDT","bids":[],"asks":[{"price":67689.8,"qty":0.00000000},{"price":67701.6,"qty":0.09000000}],"checksum":884233835,"timestamp":"2024-06-01T17:52:12.149827Z"}]}
{"channel":"book","type":"update","data":[{"symbol":"BTC/USDT","bids":[{"price":67676.1,"qty":0.78791441}],"asks":[],"checksum":3001784532,"timestamp":"2024-06-01T17:52:12.149971Z"}]}
{"channel":"book","type":"update","data":[{"symbol":"BTC/USDT","bids":[],"asks":[{"price":67689.8,"qty":0.09000000}],"checksum":2135262286,"timestamp":"2024-06-01T17:52:12.161771Z"}]}
{"channel":"book","type":"update","data":[{"symbol":"BTC/USDT","bids":[{"price":67676.1,"qty":0.69791441}],"asks":[],"checksum":4179249905,"timestamp":"2024-06-01T17:52:12.182247Z"}]}
{"channel":"book","type":"update","data":[{"symbol":"BTC/USDT","bids":[{"price":67660.0,"qty":0.00000000},{"price":67651.6,"qty":0.09959460}],"asks":[],"checksum":1936931477,"timestamp":"2024-06-01T17:52:12.369789Z"}]}
{"channel":"book","type":"update","data":[{"symbol":"BTC/USDT","bids":[],"asks":[{"price":67693.4,"qty":0.00000000},{"price":67701.6,"qty":0.09000000},{"price":67689.7,"qty":0.05328815}],"checksum":1056291538,"timestamp":"2024-06-01T17:52:12.883539Z"}]}
{"channel":"book","type":"update","data":[{"symbol":"BTC/USDT","bids":[],"asks":[{"price":67689.7,"qty":0.00000000},{"price":67701.6,"qty":0.09000000},{"price":67693.4,"qty":0.05328815}],"checksum":2563157014,"timestamp":"2024-06-01T17:52:12.941674Z"}]}
{"channel":"book","type":"update","data":[{"symbol":"BTC/USDT","bids":[{"price":67660.8,"qty":0.02213308}],"asks":[],"checksum":1520384539,"timestamp":"2024-06-01T17:52:13.053387Z"}]}
{"channel":"book","type":"update","data":[{"symbol":"BTC/USDT","bids":[{"price":67676.1,"qty":0.64462247},{"price":67651.8,"qty":0.05330950}],"asks":[],"checksum":566642364,"timestamp":"2024-06-01T17:52:13.055716Z"}]}
{"channel":"book","type":"update","data":[{"symbol":"BTC/USDT","bids":[{"price":67651.8,"qty":0.00000000},{"price":67651.7,"qty":0.09000000},{"price":67676.1,"qty":0.69791283}],"asks":[],"checksum":1149525319,"timestamp":"2024-06-01T17:52:13.530141Z"}]}
{"channel":"book","type":"update","data":[{"symbol":"BTC/USDT","bids":[{"price":67676.1,"qty":0.78791283}],"asks":[],"checksum":3269170168,"timestamp":"2024-06-01T17:52:13.553642Z"}]}
{"channel":"book","type":"update","data":[{"symbol":"BTC/USDT","bids":[{"price":67676.1,"qty":0.73462247},{"price":67651.8,"qty":0.05330950}],"asks":[],"checksum":2436022987,"timestamp":"2024-06-01T17:52:13.588824Z"}]}
{"channel":"book","type":"update","data":[{"symbol":"BTC/USDT","bids":[{"price":67660.8,"qty":0.00000000},{"price":67651.7,"qty":0.09000000}],"asks":[],"checksum":3379047431,"timestamp":"2024-06-01T17:52:13.617143Z"}]}
{"channel":"book","type":"update","data":[{"symbol":"BTC/USDT","bids":[{"price":67661.8,"qty":0.02213308}],"asks":[],"checksum":2249893387,"timestamp":"2024-06-01T17:52:13.657228Z"}]}
{"channel":"book","type":"update","data":[{"symbol":"BTC/USDT","bids":[{"price":67676.1,"qty":0.76462247}],"asks":[],"checksum":2883864999,"timestamp":"2024-06-01T17:52:13.728488Z"}]}
{"channel":"book","type":"update","data":[{"symbol":"BTC/USDT","bids":[{"price":67676.1,"qty":0.75262247}],"asks":[],"checksum":414306921,"timestamp":"2024-06-01T17:52:13.804681Z"}]}
{"channel":"book","type":"update","data":[{"symbol":"BTC/USDT","bids":[{"price":67667.5,"qty":0.05912288}],"asks":[],"checksum":49366225,"timestamp":"2024-06-01T17:52:13.814862Z"}]}
{"channel":"book","type":"update","data":[{"symbol":"BTC/USDT","bids":[{"price":67676.1,"qty":0.66262247}],"asks":[],"checksum":538489321,"timestamp":"2024-06-01T17:52:13.840095Z"}]}
{"channel":"book","type":"update","data":[{"symbol":"BTC/USDT","bids":[{"price":67676.1,"qty":0.75262247}],"asks":[],"checksum":49366225,"timestamp":"2024-06-01T17:52:13.944913Z"}]}
{"channel":"book","type":"update","data":[{"symbol":"BTC/USDT","bids":[],"asks":[{"price":67689.8,"qty":0.00000000},{"price":67701.6,"qty":0.09000000}],"checksum":1534493866,"timestamp":"2024-06-01T17:52:14.018232Z"}]}
{"channel":"book","type":"update","data":[{"symbol":"BTC/USDT","bids":[{"price":67661.8,"qty":0.00000000},{"price":67651.8,"qty":0.05330950}],"asks":[],"checksum":2834618285,"timestamp":"2024-06-01T17:52:14.298595Z"}]}
{"channel":"book","type":"update","data":[{"symbol":"BTC/USDT","bids":[{"price":67663.0,"qty":0.02213184}],"asks":[],"checksum":3728812670,"timestamp":"2024-06-01T17:52:14.338788Z"}]}
{"channel":"book","type":"update","data":[{"symbol":"BTC/USDT","bids":[],"asks":[{"price":67689.8,"qty":0.09000000}],"checksum":2277960197,"timestamp":"2024-06-01T17:52:14.393692Z"}]}
{"channel":"book","type":"update","data":[{"symbol":"BTC/USDT","bids":[],"asks":[{"price":67676.2,"qty":0.04955465}],"checksum":2304198608,"timestamp":"2024-06-01T17:52:14.471525Z"}]}
{"channel":"book","type":"update","data":[{"symbol":"BTC/USDT","bids":[{"price":67676.1,"qty":0.66262247}],"asks":[],"checksum":2881401576,"timestamp":"2024-06-01T17:52:14.474471Z"}]}
{"channel":"book","type":"update","data":[{"symbol":"BTC/USDT","bids":[{"price":67669.3,"qty":0.00000000},{"price":67651.8,"qty":0.05330950}],"asks":[],"checksum":2278622585,"timestamp":"2024-06-01T17:52:14.475195Z"}]}
{"channel":"book","type":"update","data":[{"symbol":"BTC/USDT","bids":[{"price":67669.3,"qty":0.09000000}],"asks":[],"checksum":2881401576,"timestamp":"2024-06-01T17:52:14.514655Z"}]}
{"channel":"book","type":"update","data":[{"symbol":"BTC/USDT","bids":[{"price":67667.5,"qty":0.00000000},{"price":67651.8,"qty":0.05330950}],"asks":[],"checksum":3442084264,"timestamp":"2024-06-01T17:52:14.538611Z"}]}
{"channel":"book","type":"update","data":[{"symbol":"BTC/USDT","bids":[],"asks":[{"price":67689.8,"qty":0.00000000},{"price":67701.6,"qty":0.09000000}],"checksum":2494417363,"timestamp":"2024-06-01T17:52:14.611634Z"}]}
{"channel":"book","type":"update","data":[{"symbol":"BTC/USDT","bids":[{"price":67676.1,"qty":0.75262247}],"asks":[],"checksum":3057925355,"timestamp":"2024-06-01T17:52:14.612130Z"}]}
{"channel":"book","type":"update","data":[{"symbol":"BTC/USDT","bids":[{"price":67651.8,"qty":0.00000000},{"price":67651.7,"qty":0.09000000},{"price":67676.1,"qty":0.80591275}],"asks":[],"checksum":3702666302,"timestamp":"2024-06-01T17:52:14.669563Z"}]}
{"channel":"book","type":"update","data":[{"symbol":"BTC/USDT","bids":[{"price":67676.1,"qty":0.89591275}],"asks":[],"checksum":2618969602,"timestamp":"2024-06-01T17:52:14.689608Z"}]}
{"channel":"book","type":"update","data":[{"symbol":"BTC/USDT","bids":[{"price":67676.1,"qty":0.80591275}],"asks":[],"checksum":3702666302,"timestamp":"2024-06-01T17:52:14.692072Z"}]}
{"channel":"book","type":"update","data":[{"symbol":"BTC/USDT","bids":[{"price":67676.1,"qty":0.75262247},{"price":67651.8,"qty":0.05330942}],"asks":[],"checksum":1095855238,"timestamp":"2024-06-01T17:52:14.730374Z"}]}
{"channel":"book","type":"update","data":[{"symbol":"BTC/USDT","bids":[{"price":67676.1,"qty":0.78157457}],"asks":[],"checksum":343467665,"timestamp":"2024-06-01T17:52:14.749754Z"}]}
{"channel":"book","type":"update","data":[{"symbol":"BTC/USDT","bids":[{"price":67667.5,"qty":0.05912289}],"asks":[],"checksum":2220663818,"timestamp":"2024-06-01T17:52:14.797871Z"}]}
{"channel":"book","type":"update","data":[{"symbol":"BTC/USDT","bids":[{"price":67676.1,"qty":0.88134676}],"asks":[],"checksum":781149173,"timestamp":"2024-06-01T17:52:15.003219Z"}]}
{"channel":"book","type":"update","data":[{"symbol":"BTC/USDT","bids":[{"price":67663.0,"qty":0.00000000},{"price":67651.8,"qty":0.05330942}],"asks":[],"checksum":2939145803,"timestamp":"2024-06-01T17:52:15.014292Z"}]}
{"channel":"book","type":"update","data":[{"symbol":"BTC/USDT","bids":[{"price":67662.9,"qty":0.02213184}],"asks":[],"checksum":2207223261,"timestamp":"2024-06-01T17:52:15.054391Z"}]}
{"channel":"book","type":"update","data":[{"symbol":"BTC/USDT","bids":[{"price":67676.1,"qty":0.97134676}],"asks":[],"checksum":3425758581,"timestamp":"2024-06-01T17:52:15.327273Z"}]}
{"channel":"book","type":"update","data":[{"symbol":"BTC/USDT","bids":[],"asks":[{"price":67676.2,"qty":0.00000000},{"price":67702.1,"qty":0.19890820}],"checksum":3909960201,"timestamp":"2024-06-01T17:52:15.427150Z"}]}
{"channel":"book","type":"update","data":[{"symbol":"BTC/USDT","bids":[{"price":67676.0,"qty":0.00460867}],"asks":[],"checksum":4216601078,"timestamp":"2024-06-01T17:52:15.430333Z"}]}
{"channel":"book","type":"update","data":[{"symbol":"BTC/USDT","bids":[{"price":67676.2,"qty":0.01774222}],"asks":[],"checksum":4105488251,"timestamp":"2024-06-01T17:52:15.431327Z"}]}
{"channel":"book","type":"update","data":[{"symbol":"BTC/USDT","bids":[],"asks":[{"price":67684.2,"qty":0.00000000},{"price":67706.3,"qty":0.00460867}],"checksum":3457426844,"timestamp":"2024-06-01T17:52:15.431389Z"}]}
{"channel":"book","type":"update","data":[{"symbol":"BTC/USDT","bids":[],"asks":[{"price":67693.3,"qty":0.03947498}],"checksum":2759894579,"timestamp":"2024-06-01T17:52:15.431495Z"}]}
{"channel":"book","type":"update","data":[{"symbol":"BTC/USDT","bids":[{"price":67679.4,"qty":0.09000000}],"asks":[],"checksum":3958598096,"timestamp":"2024-06-01T17:52:15.431756Z"}]}
{"channel":"book","type":"update","data":[{"symbol":"BTC/USDT","bids":[{"price":67676.1,"qty":0.67568383}],"asks":[],"checksum":1624347650,"timestamp":"2024-06-01T17:52:15.434474Z"}]}
{"channel":"book","type":"update","data":[{"symbol":"BTC/USDT","bids":[{"price":67676.9,"qty":0.29564681}],"asks":[],"checksum":3134936456,"timestamp":"2024-06-01T17:52:15.434501Z"}]}
{"channel":"book","type":"update","data":[{"symbol":"BTC/USDT","bids":[{"price":67676.1,"qty":0.63278383}],"asks":[],"checksum":3575521707,"timestamp":"2024-06-01T17:52:15.434575Z"}]}
{"channel":"book","type":"update","data":[{"symbol":"BTC/USDT","bids":[{"price":67680.3,"qty":0.04290000}],"asks":[],"checksum":2280647026,"timestamp":"2024-06-01T17:52:15.434659Z"}]}
{"channel":"book","type":"update","data":[{"symbol":"BTC/USDT","bids":[{"price":67676.2,"qty":1.61914926}],"asks":[],"checksum":1447205456,"timestamp":"2024-06-01T17:52:15.435161Z"}]}
{"channel":"book","type":"update","data":[{"symbol":"BTC/USDT","bids":[{"price":67676.2,"qty":1.60140704}],"asks":[],"checksum":3608024275,"timestamp":"2024-06-01T17:52:15.435987Z"}]}
{"channel":"book","type":"update","data":[{"symbol":"BTC/USDT","bids":[{"price":67679.5,"qty":0.01774197}],"asks":[],"checksum":3433413823,"timestamp":"2024-06-01T17:52:15.436404Z"}]}
{"channel":"book","type":"update","data":[{"symbol":"BTC/USDT","bids":[{"price":67680.1,"qty":0.29564685}],"asks":[],"checksum":844137139,"timestamp":"2024-06-01T17:52:15.436983Z"}]}
{"channel":"book","type":"update","data":[{"symbol":"BTC/USDT","bids":[{"price":67676.9,"qty":0.00000000},{"price":67668.0,"qty":0.14790060}],"asks":[],"checksum":3217195298,"timestamp":"2024-06-01T17:52:15.438018Z"}]}
{"channel":"book","type":"update","data":[{"symbol":"BTC/USDT","bids":[{"price":67682.3,"qty":0.09000000}],"asks":[],"checksum":2911939286,"timestamp":"2024-06-01T17:52:15.438186Z"}]}
{"channel":"book","type":"update","data":[{"symbol":"BTC/USDT","bids":[{"price":67676.1,"qty":0.54278383}],"asks":[],"checksum":2987815873,"timestamp":"2024-06-01T17:52:15.438706Z"}]}
{"channel":"book","type":"update","data":[{"symbol":"BTC/USDT","bids":[{"price":67679.5,"qty":0.00000000},{"price":67668.0,"qty":0.14790060}],"asks":[],"checksum":3778262272,"timestamp":"2024-06-01T17:52:15.440042Z"}]}
{"channel":"book","type":"update","data":[{"symbol":"BTC/USDT","bids":[{"price":67680.4,"qty":0.01774197}],"asks":[],"checksum":3614041490,"timestamp":"2024-06-01T17:52:15.440066Z"}]}
{"channel":"book","type":"update","data":[{"symbol":"BTC/USDT","bids":[{"price":67680.3,"qty":0.33854690}],"asks":[],"checksum":2026994313,"timestamp":"2024-06-01T17:52:15.440443Z"}]}
{"channel":"book","type":"update","data":[{"symbol":"BTC/USDT","bids":[{"price":67669.1,"qty":0.00000000},{"price":67668.0,"qty":0.14790060}],"asks":[],"checksum":3699638376,"timestamp":"2024-06-01T17:52:15.440803Z"}]}
{"channel":"book","type":"update","data":[{"symbol":"BTC/USDT","bids":[{"price":67680.3,"qty":0.29564690}],"asks":[],"checksum":1044863758,"timestamp":"2024-06-01T17:52:15.441042Z"}]}
{"channel":"book","type":"update","data":[{"symbol":"BTC/USDT","bids":[{"price":67683.2,"qty":0.04290000}],"asks":[],"checksum":933879351,"timestamp":"2024-06-01T17:52:15.441116Z"}]}
{"channel":"book","type":"update","data":[{"symbol":"BTC/USDT","bids":[{"price":67680.1,"qty":0.00000000},{"price":67668.0,"qty":0.14790060}],"asks":[],"checksum":410971586,"timestamp":"2024-06-01T17:52:15.441141Z"}]}
{"channel":"book","type":"update","data":[{"symbol":"BTC/USDT","bids":[{"price":67676.2,"qty":1.75140704}],"asks":[],"checksum":852236492,"timestamp":"2024-06-01T17:52:15.442886Z"}]}
{"channel":"book","type":"update","data":[{"symbol":"BTC/USDT","bids":[{"price":67682.4,"qty":0.12088300}],"asks":[],"checksum":3806643569,"timestamp":"2024-06-01T17:52:15.443153Z"}]}
{"channel":"book","type":"update","data":[{"symbol":"BTC/USDT","bids":[{"price":67682.4,"qty":0.13862497}],"asks":[],"checksum":2461074482,"timestamp":"2024-06-01T17:52:15.443588Z"}]}
{"channel":"book","type":"update","data":[{"symbol":"BTC/USDT","bids":[{"price":67680.4,"qty":0.00000000},{"price":67668.0,"qty":0.14790060}],"asks":[],"checksum":1386975226,"timestamp":"2024-06-01T17:52:15.443693Z"}]}
{"channel":"book","type":"update","data":[{"symbol":"BTC/USDT","bids":[{"price":67676.2,"qty":1.79546658}],"asks":[],"checksum":3199379787,"timestamp":"2024-06-01T17:52:15.444697Z"}]}
{"channel":"book","type":"update","data":[{"symbol":"BTC/USDT","bids":[{"price":67680.4,"qty":0.00092896}],"asks":[],"checksum":2879397660,"timestamp":"2024-06-01T17:52:15.446049Z"}]}
{"channel":"book","type":"update","data":[{"symbol":"BTC/USDT","bids":[{"price":67682.4,"qty":0.12088300}],"asks":[],"checksum":728418234,"timestamp":"2024-06-01T17:52:15.447155Z"}]}
{"channel":"book","type":"update","data":[{"symbol":"BTC/USDT","bids":[{"price":67683.3,"qty":0.01774197}],"asks":[],"checksum":3180549738,"timestamp":"2024-06-01T17:52:15.447169Z"}]}
{"channel":"book","type":"update","data":[{"symbol":"BTC/USDT","bids":[{"price":67679.5,"qty":0.04405954}],"asks":[],"checksum":4187287597,"timestamp":"2024-06-01T17:52:15.448568Z"}]}
{"channel":"book","type":"update","data":[{"symbol":"BTC/USDT","bids":[{"price":67676.2,"qty":1.84546658}],"asks":[],"checksum":2380228158,"timestamp":"2024-06-01T17:52:15.450752Z"}]}
{"channel":"book","type":"update","data":[{"symbol":"BTC/USDT","bids":[{"price":67683.3,"qty":0.00000000},{"price":67676.0,"qty":0.00460867}],"asks":[],"checksum":3310681329,"timestamp":"2024-06-01T17:52:15.451410Z"}]}
{"channel":"book","type":"update","data":[{"symbol":"BTC/USDT","bids":[{"price":67683.4,"qty":0.01774197}],"asks":[],"checksum":371240359,"timestamp":"2024-06-01T17:52:15.451430Z"}]}
{"channel":"book","type":"update","data":[{"symbol":"BTC/USDT","bids":[{"price":67676.1,"qty":0.59607410}],"asks":[],"checksum":1268891201,"timestamp":"2024-06-01T17:52:15.458076Z"}]}
{"channel":"book","type":"update","data":[{"symbol":"BTC/USDT","bids":[{"price":67676.3,"qty":0.03700000}],"asks":[],"checksum":3920229064,"timestamp":"2024-06-01T17:52:15.461439Z"}]}
{"channel":"book","type":"update","data":[{"symbol":"BTC/USDT","bids":[{"price":67682.3,"qty":0.00000000},{"price":67676.1,"qty":0.56607410}],"asks":[],"checksum":2851207680,"timestamp":"2024-06-01T17:52:15.464943Z"}]}
{"channel":"book","type":"update","data":[{"symbol":"BTC/USDT","bids":[{"price":67680.4,"qty":0.00000000},{"price":67676.0,"qty":0.00460867},{"price":67683.5,"qty":0.00092896}],"asks":[],"checksum":2690654655,"timestamp":"2024-06-01T17:52:15.479457Z"}]}
{"channel":"book","type":"update","data":[{"symbol":"BTC/USDT","bids":[{"price":67676.1,"qty":0.41607410}],"asks":[],"checksum":2842501039,"timestamp":"2024-06-01T17:52:15.480731Z"}]}
{"channel":"book","type":"update","data":[{"symbol":"BTC/USDT","bids":[{"price":67682.5,"qty":0.15000000}],"asks":[],"checksum":4147393814,"timestamp":"2024-06-01T17:52:15.480805Z"}]}
{"channel":"book","type":"update","data":[{"symbol":"BTC/USDT","bids":[{"price":67676.2,"qty":1.80140704}],"asks":[],"checksum":3364019862,"timestamp":"2024-06-01T17:52:15.482340Z"}]}
{"channel":"book","type":"update","data":[{"symbol":"BTC/USDT","bids":[{"price":67683.5,"qty":0.05092896}],"asks":[],"checksum":2763810714,"timestamp":"2024-06-01T17:52:15.491121Z"}]}
{"channel":"book","type":"update","data":[{"symbol":"BTC/USDT","bids":[{"price":67683.2,"qty":0.00000000},{"price":67676.1,"qty":0.32201456}],"asks":[],"checksum":3417094129,"timestamp":"2024-06-01T17:52:15.494031Z"}]}
{"channel":"book","type":"update","data":[{"symbol":"BTC/USDT","bids":[{"price":67684.4,"qty":0.04290000}],"asks":[],"checksum":2213061976,"timestamp":"2024-06-01T17:52:15.494087Z"}]}
{"channel":"book","type":"update","data":[{"symbol":"BTC/USDT","bids":[{"price":67683.5,"qty":0.07992896}],"asks":[],"checksum":3068395010,"timestamp":"2024-06-01T17:52:15.494112Z"}]}
{"channel":"book","type":"update","data":[{"symbol":"BTC/USDT","bids":[{"price":67676.3,"qty":0.00000000},{"price":67676.1,"qty":0.32201456}],"asks":[],"checksum":3224839800,"timestamp":"2024-06-01T17:52:15.497630Z"}]}
{"channel":"book","type":"update","data":[{"symbol":"BTC/USDT","bids":[{"price":67683.3,"qty":0.15000000}],"asks":[],"checksum":1679461246,"timestamp":"2024-06-01T17:52:15.512757Z"}]}
{"channel":"book","type":"update","data":[{"symbol":"BTC/USDT","bids":[{"price":67676.2,"qty":1.65140704}],"asks":[],"checksum":598259435,"timestamp":"2024-06-01T17:52:15.512833Z"}]}
{"channel":"book","type":"update","data":[{"symbol":"BTC/USDT","bids":[{"price":67683.6,"qty":0.04405954}],"asks":[],"checksum":3508101093,"timestamp":"2024-06-01T17:52:15.514421Z"}]}
{"channel":"book","type":"update","data":[{"symbol":"BTC/USDT","bids":[{"price":67683.5,"qty":0.05092896}],"asks":[],"checksum":1141862783,"timestamp":"2024-06-01T17:52:15.526052Z"}]}
{"channel":"book","type":"update","data":[{"symbol":"BTC/USDT","bids":[{"price":67683.5,"qty":0.05000000},{"price":67684.5,"qty":0.00092896}],"asks":[],"checksum":1573872478,"timestamp":"2024-06-01T17:52:15.544245Z"}]}
{"channel":"book","type":"update","data":[{"symbol":"BTC/USDT","bids":[{"price":67683.3,"qty":0.00000000},{"price":67679.4,"qty":0.09000000}],"asks":[],"checksum":1336401939,"timestamp":"2024-06-01T17:52:15.548998Z"}]}
{"channel":"book","type":"update","data":[{"symbol":"BTC/USDT","bids":[{"price":67683.6,"qty":0.19405954}],"asks":[],"checksum":449780057,"timestamp":"2024-06-01T17:52:15.549162Z"}]}
{"channel":"book","type":"update","data":[{"symbol":"BTC/USDT","bids":[{"price":67683.6,"qty":0.15000000}],"asks":[],"checksum":3479022277,"timestamp":"2024-06-01T17:52:15.549547Z"}]}
{"channel":"book","type":"update","data":[{"symbol":"BTC/USDT","bids":[{"price":67684.6,"qty":0.04405954}],"asks":[],"checksum":1752731032,"timestamp":"2024-06-01T17:52:15.549764Z"}]}
{"channel":"book","type":"update","data":[{"symbol":"BTC/USDT","bids":[{"price":67684.4,"qty":0.00000000},{"price":67679.4,"qty":0.09000000}],"asks":[],"checksum":863350361,"timestamp":"2024-06-01T17:52:15.552506Z"}]}
{"channel":"book","type":"update","data":[{"symbol":"BTC/USDT","bids":[{"price":67685.5,"qty":0.04290000}],"asks":[],"checksum":884811918,"timestamp":"2024-06-01T17:52:15.552593Z"}]}
{"channel":"book","type":"update","data":[{"symbol":"BTC/USDT","bids":[{"price":67683.4,"qty":0.00000000},{"price":67679.4,"qty":0.09000000}],"asks":[],"checksum":3266622249,"timestamp":"2024-06-01T17:52:15.557018Z"}]}
{"channel":"book","type":"update","data":[{"symbol":"BTC/USDT","bids":[{"price":67684.5,"qty":0.05092896}],"asks":[],"checksum":1437743820,"timestamp":"2024-06-01T17:52:15.558978Z"}]}
{"channel":"book","type":"update","data":[{"symbol":"BTC/USDT","bids":[{"price":67683.5,"qty":0.00000000},{"price":67676.2,"qty":1.60140704}],"asks":[],"checksum":3183794922,"timestamp":"2024-06-01T17:52:15.588297Z"}]}
{"channel":"book","type":"update","data":[{"symbol":"BTC/USDT","bids":[{"price":67685.6,"qty":0.05000000}],"asks":[],"checksum":1476245303,"timestamp":"2024-06-01T17:52:15.588327Z"}]}
{"channel":"book","type":"update","data":[{"symbol":"BTC/USDT","bids":[{"price":67685.5,"qty":0.00000000},{"price":67676.2,"qty":1.60140704}],"asks":[],"checksum":4036102474,"timestamp":"2024-06-01T17:52:15.591408Z"}]}
{"channel":"book","type":"update","data":[{"symbol":"BTC/USDT","bids":[{"price":67686.5,"qty":0.04290000}],"asks":[],"checksum":402739540,"timestamp":"2024-06-01T17:52:15.591612Z"}]}
{"channel":"book","type":"update","data":[{"symbol":"BTC/USDT","bids":[{"price":67684.5,"qty":0.00092896}],"asks":[],"checksum":473752948,"timestamp":"2024-06-01T17:52:15.593854Z"}]}
{"channel":"book","type":"update","data":[{"symbol":"BTC/USDT","bids":[{"price":67684.6,"qty":0.00000000},{"price":67676.2,"qty":1.60140704}],"asks":[],"checksum":615113961,"timestamp":"2024-06-01T17:52:15.594639Z"}]}
{"channel":"book","type":"update","data":[{"symbol":"BTC/USDT","bids":[{"price":67683.6,"qty":0.00000000},{"price":67676.1,"qty":0.32201456}],"asks":[],"checksum":248416424,"timestamp":"2024-06-01T17:52:15.594653Z"}]}
{"channel":"book","type":"update","data":[{"symbol":"BTC/USDT","bids":[{"price":67684.7,"qty":0.15000000}],"asks":[],"checksum":1645860247,"timestamp":"2024-06-01T17:52:15.594746Z"}]}
{"channel":"book","type":"update","data":[{"symbol":"BTC/USDT","bids":[{"price":67685.7,"qty":0.04405954}],"asks":[],"checksum":991188588,"timestamp":"2024-06-01T17:52:15.594865Z"}]}
{"channel":"book","type":"update","data":[{"symbol":"BTC/USDT","bids":[{"price":67682.6,"qty":0.01774197}],"asks":[],"checksum":3813553638,"timestamp":"2024-06-01T17:52:15.599037Z"}]}
{"channel":"book","type":"update","data":[{"symbol":"BTC/USDT","bids":[{"price":67682.6,"qty":0.00000000},{"price":67679.4,"qty":0.09000000}],"asks":[],"checksum":991188588,"timestamp":"2024-06-01T17:52:15.603204Z"}]}
{"channel":"book","type":"update","data":[{"symbol":"BTC/USDT","bids":[],"asks":[{"price":67690.8,"qty":0.01428854}],"checksum":1854427566,"timestamp":"2024-06-01T17:52:15.605241Z"}]}
{"channel":"book","type":"update","data":[{"symbol":"BTC/USDT","bids":[{"price":67684.5,"qty":0.00000000},{"price":67676.2,"qty":1.60140704},{"price":67686.6,"qty":0.00092896}],"asks":[],"checksum":3873317378,"timestamp":"2024-06-01T17:52:15.607877Z"}]}
{"channel":"book","type":"update","data":[{"symbol":"BTC/USDT","bids":[{"price":67685.7,"qty":0.19405954}],"asks":[],"checksum":3516349188,"timestamp":"2024-06-01T17:52:15.711162Z"}]}
{"channel":"book","type":"update","data":[{"symbol":"BTC/USDT","bids":[{"price":67684.7,"qty":0.00000000},{"price":67676.2,"qty":1.60140704}],"asks":[],"checksum":2250907480,"timestamp":"2024-06-01T17:52:15.711247Z"}]}
{"channel":"book","type":"update","data":[{"symbol":"BTC/USDT","bids":[],"asks":[{"price":67690.7,"qty":0.04005197}],"checksum":4204972354,"timestamp":"2024-06-01T17:52:15.715270Z"}]}
{"channel":"book","type":"update","data":[{"symbol":"BTC/USDT","bids":[{"price":67682.5,"qty":0.00000000},{"price":67676.1,"qty":0.32201456}],"asks":[],"checksum":2972047945,"timestamp":"2024-06-01T17:52:15.715396Z"}]}
{"channel":"book","type":"update","data":[{"symbol":"BTC/USDT","bids":[{"price":67686.6,"qty":0.05092896}],"asks":[],"checksum":1393059885,"timestamp":"2024-06-01T17:52:15.716044Z"}]}
{"channel":"book","type":"update","data":[{"symbol":"BTC/USDT","bids":[{"price":67685.7,"qty":0.15000000}],"asks":[],"checksum":3700726431,"timestamp":"2024-06-01T17:52:15.716643Z"}]}
{"channel":"book","type":"update","data":[{"symbol":"BTC/USDT","bids":[{"price":67686.5,"qty":0.00000000},{"price":67676.0,"qty":0.00460867}],"asks":[],"checksum":3088660752,"timestamp":"2024-06-01T17:52:15.718804Z"}]}
{"channel":"book","type":"update","data":[{"symbol":"BTC/USDT","bids":[{"price":67686.9,"qty":0.04290000}],"asks":[],"checksum":2067764098,"timestamp":"2024-06-01T17:52:15.718860Z"}]}
{"channel":"book","type":"update","data":[{"symbol":"BTC/USDT","bids":[{"price":67686.6,"qty":0.05000000},{"price":67687.0,"qty":0.00092896}],"asks":[],"checksum":2594643980,"timestamp":"2024-06-01T17:52:15.733169Z"}]}
{"channel":"book","type":"update","data":[{"symbol":"BTC/USDT","bids":[],"asks":[{"price":67690.7,"qty":0.09389197}],"checksum":375796870,"timestamp":"2024-06-01T17:52:15.793965Z"}]}
{"channel":"book","type":"update","data":[{"symbol":"BTC/USDT","bids":[],"asks":[{"price":67693.3,"qty":0.00000000},{"price":67707.9,"qty":0.37408842}],"checksum":1429730689,"timestamp":"2024-06-01T17:52:15.797709Z"}]}
{"channel":"book","type":"update","data":[{"symbol":"BTC/USDT","bids":[{"price":67685.8,"qty":0.15000000}],"asks":[],"checksum":1825033737,"timestamp":"2024-06-01T17:52:15.798627Z"}]}
{"channel":"book","type":"update","data":[{"symbol":"BTC/USDT","bids":[{"price":67685.6,"qty":0.00000000},{"price":67676.2,"qty":1.60140704}],"asks":[],"checksum":2949802802,"timestamp":"2024-06-01T17:52:15.798834Z"}]}
{"channel":"book","type":"update","data":[{"symbol":"BTC/USDT","bids":[{"price":67687.0,"qty":0.05092896}],"asks":[],"checksum":3704373243,"timestamp":"2024-06-01T17:52:15.798917Z"}]}
{"channel":"book","type":"update","data":[{"symbol":"BTC/USDT","bids":[{"price":67679.4,"qty":0.00000000},{"price":67676.1,"qty":0.32201456}],"asks":[],"checksum":1559827188,"timestamp":"2024-06-01T17:52:15.981290Z"}]}
{"channel":"book","type":"update","data":[{"symbol":"BTC/USDT","bids":[{"price":67686.6,"qty":0.00000000},{"price":67676.0,"qty":0.00460867}],"asks":[],"checksum":916598856,"timestamp":"2024-06-01T17:52:16.086060Z"}]}
{"channel":"book","type":"update","data":[{"symbol":"BTC/USDT","bids":[{"price":67685.7,"qty":0.00000000},{"price":67669.3,"qty":0.09000000}],"asks":[],"checksum":1007678412,"timestamp":"2024-06-01T17:52:16.090834Z"}]}
{"channel":"book","type":"update","data":[{"symbol":"BTC/USDT","bids":[{"price":67676.1,"qty":0.23201456}],"asks":[],"checksum":4213663381,"timestamp":"2024-06-01T17:52:16.097485Z"}]}
{"channel":"book","type":"update","data":[{"symbol":"BTC/USDT","bids":[{"price":67676.1,"qty":0.17872429},{"price":67685.9,"qty":0.05328255}],"asks":[],"checksum":2379900814,"timestamp":"2024-06-01T17:52:16.171409Z"}]}
{"channel":"book","type":"update","data":[{"symbol":"BTC/USDT","bids":[],"asks":[{"price":67693.4,"qty":0.00000000},{"price":67708.1,"qty":0.00460867},{"price":67690.6,"qty":0.05328804}],"checksum":768758611,"timestamp":"2024-06-01T17:52:16.171438Z"}]}
{"channel":"book","type":"update","data":[{"symbol":"BTC/USDT","bids":[{"price":67686.0,"qty":0.15000000}],"asks":[],"checksum":1488451101,"timestamp":"2024-06-01T17:52:16.176156Z"}]}
{"channel":"book","type":"update","data":[{"symbol":"BTC/USDT","bids":[{"price":67685.8,"qty":0.00000000},{"price":67676.0,"qty":0.00460867}],"asks":[],"checksum":3499471605,"timestamp":"2024-06-01T17:52:16.211101Z"}]}
{"channel":"book","type":"update","data":[{"symbol":"BTC/USDT","bids":[],"asks":[{"price":67690.5,"qty":0.03947498}],"checksum":1205294242,"timestamp":"2024-06-01T17:52:16.215353Z"}]}
{"channel":"book","type":"update","data":[{"symbol":"BTC/USDT","bids":[{"price":67685.9,"qty":0.00000000},{"price":67669.3,"qty":0.09000000},{"price":67676.3,"qty":0.05329011}],"asks":[],"checksum":3004475901,"timestamp":"2024-06-01T17:52:16.238210Z"}]}
{"channel":"book","type":"update","data":[{"symbol":"BTC/USDT","bids":[],"asks":[{"price":67690.7,"qty":0.05441699}],"checksum":2353070031,"timestamp":"2024-06-01T17:52:16.590824Z"}]}
{"channel":"book","type":"update","data":[{"symbol":"BTC/USDT","bids":[{"price":67686.0,"qty":0.00000000},{"price":67669.3,"qty":0.09000000}],"asks":[],"checksum":3518508084,"timestamp":"2024-06-01T17:52:16.711212Z"}]}
{"channel":"book","type":"update","data":[{"symbol":"BTC/USDT","bids":[{"price":67682.5,"qty":0.15000000}],"asks":[],"checksum":2117840896,"timestamp":"2024-06-01T17:52:16.711426Z"}]}
{"channel":"book","type":"update","data":[{"symbol":"BTC/USDT","bids":[{"price":67686.9,"qty":0.00000000},{"price":67669.3,"qty":0.09000000}],"asks":[],"checksum":1169022207,"timestamp":"2024-06-01T17:52:16.713939Z"}]}
{"channel":"book","type":"update","data":[{"symbol":"BTC/USDT","bids":[{"price":67683.3,"qty":0.04290000}],"asks":[],"checksum":1972870379,"timestamp":"2024-06-01T17:52:16.714559Z"}]}
{"channel":"book","type":"update","data":[{"symbol":"BTC/USDT","bids":[{"price":67682.5,"qty":0.16774197}],"asks":[],"checksum":4012380059,"timestamp":"2024-06-01T17:52:16.715781Z"}]}
{"channel":"book","type":"update","data":[{"symbol":"BTC/USDT","bids":[{"price":67683.4,"qty":0.01764254}],"asks":[],"checksum":4042668106,"timestamp":"2024-06-01T17:52:16.718694Z"}]}
{"channel":"book","type":"update","data":[{"symbol":"BTC/USDT","bids":[{"price":67682.5,"qty":0.15000000}],"asks":[],"checksum":3745909409,"timestamp":"2024-06-01T17:52:16.720084Z"}]}
{"channel":"book","type":"update","data":[{"symbol":"BTC/USDT","bids":[],"asks":[{"price":67690.6,"qty":0.00000000},{"price":67707.9,"qty":0.37408842},{"price":67690.4,"qty":0.05328804}],"checksum":688114684,"timestamp":"2024-06-01T17:52:16.881386Z"}]}
{"channel":"book","type":"update","data":[{"symbol":"BTC/USDT","bids":[],"asks":[{"price":67690.3,"qty":0.03947498}],"checksum":3316381898,"timestamp":"2024-06-01T17:52:16.885704Z"}]}
{"channel":"book","type":"update","data":[{"symbol":"BTC/USDT","bids":[{"price":67683.4,"qty":0.16764254}],"asks":[],"checksum":2795132699,"timestamp":"2024-06-01T17:52:16.886296Z"}]}
{"channel":"book","type":"update","data":[{"symbol":"BTC/USDT","bids":[{"price":67687.0,"qty":0.00092896}],"asks":[],"checksum":1742380866,"timestamp":"2024-06-01T17:52:16.886501Z"}]}
{"channel":"book","type":"update","data":[{"symbol":"BTC/USDT","bids":[{"price":67683.5,"qty":0.05000000}],"asks":[],"checksum":1045769737,"timestamp":"2024-06-01T17:52:16.886529Z"}]}
{"channel":"book","type":"update","data":[{"symbol":"BTC/USDT","bids":[{"price":67683.3,"qty":0.00000000},{"price":67676.1,"qty":0.17872429}],"asks":[],"checksum":1247843394,"timestamp":"2024-06-01T17:52:16.888991Z"}]}
{"channel":"book","type":"update","data":[{"symbol":"BTC/USDT","bids":[{"price":67684.3,"qty":0.04290000}],"asks":[],"checksum":1540745742,"timestamp":"2024-06-01T17:52:16.889149Z"}]}
{"channel":"book","type":"update","data":[{"symbol":"BTC/USDT","bids":[{"price":67683.4,"qty":0.15000000}],"asks":[],"checksum":3405821790,"timestamp":"2024-06-01T17:52:16.890453Z"}]}
{"channel":"book","type":"update","data":[{"symbol":"BTC/USDT","bids":[{"price":67683.5,"qty":0.06774170}],"asks":[],"checksum":3593560918,"timestamp":"2024-06-01T17:52:16.893043Z"}]}
{"channel":"book","type":"update","data":[{"symbol":"BTC/USDT","bids":[],"asks":[{"price":67690.4,"qty":0.00000000},{"price":67702.1,"qty":0.19890820},{"price":67693.4,"qty":0.05328737}],"checksum":1622045549,"timestamp":"2024-06-01T17:52:17.041943Z"}]}
{"channel":"book","type":"update","data":[{"symbol":"BTC/USDT","bids":[],"asks":[{"price":67690.3,"qty":0.00000000},{"price":67702.1,"qty":0.19890820}],"checksum":2400083656,"timestamp":"2024-06-01T17:52:17.046023Z"}]}
{"channel":"book","type":"update","data":[{"symbol":"BTC/USDT","bids":[{"price":67683.4,"qty":0.00000000},{"price":67676.1,"qty":0.17872429}],"asks":[],"checksum":169841570,"timestamp":"2024-06-01T17:52:17.047181Z"}]}
{"channel":"book","type":"update","data":[{"symbol":"BTC/USDT","bids":[{"price":67683.6,"qty":0.15000000}],"asks":[],"checksum":3105658319,"timestamp":"2024-06-01T17:52:17.047208Z"}]}
{"channel":"book","type":"update","data":[{"symbol":"BTC/USDT","bids":[{"price":67684.4,"qty":0.05000000}],"asks":[],"checksum":999437886,"timestamp":"2024-06-01T17:52:17.047391Z"}]}
{"channel":"book","type":"update","data":[{"symbol":"BTC/USDT","bids":[{"price":67684.3,"qty":0.00000000},{"price":67676.2,"qty":1.60140704}],"asks":[],"checksum":3179677902,"timestamp":"2024-06-01T17:52:17.050133Z"}]}
{"channel":"book","type":"update","data":[{"symbol":"BTC/USDT","bids":[{"price":67685.3,"qty":0.04290000}],"asks":[],"checksum":262403405,"timestamp":"2024-06-01T17:52:17.050314Z"}]}
{"channel":"book","type":"update","data":[{"symbol":"BTC/USDT","bids":[{"price":67683.5,"qty":0.05000000}],"asks":[],"checksum":4185898027,"timestamp":"2024-06-01T17:52:17.051574Z"}]}
{"channel":"book","type":"update","data":[{"symbol":"BTC/USDT","bids":[{"price":67683.5,"qty":0.00000000},{"price":67676.2,"qty":1.60140704}],"asks":[],"checksum":2386720485,"timestamp":"2024-06-01T17:52:17.085657Z"}]}
{"channel":"book","type":"update","data":[{"symbol":"BTC/USDT","bids":[{"price":67685.4,"qty":0.05000000}],"asks":[],"checksum":1158481248,"timestamp":"2024-06-01T17:52:17.085668Z"}]}
{"channel":"book","type":"update","data":[{"symbol":"BTC/USDT","bids":[{"price":67685.3,"qty":0.00000000},{"price":67676.2,"qty":1.60140704}],"asks":[],"checksum":2329471972,"timestamp":"2024-06-01T17:52:17.088558Z"}]}
{"channel":"book","type":"update","data":[{"symbol":"BTC/USDT","bids":[{"price":67686.3,"qty":0.04290000}],"asks":[],"checksum":4159448074,"timestamp":"2024-06-01T17:52:17.088678Z"}]}
{"channel":"book","type":"update","data":[{"symbol":"BTC/USDT","bids":[{"price":67684.4,"qty":0.00000000},{"price":67676.2,"qty":1.60140704}],"asks":[],"checksum":1097912216,"timestamp":"2024-06-01T17:52:17.090182Z"}]}
{"channel":"book","type":"update","data":[{"symbol":"BTC/USDT","bids":[{"price":67683.6,"qty":0.00000000},{"price":67676.1,"qty":0.17872429}],"asks":[],"checksum":3830793360,"timestamp":"2024-06-01T17:52:17.090396Z"}]}
{"channel":"book","type":"update","data":[{"symbol":"BTC/USDT","bids":[{"price":67682.6,"qty":0.01774196}],"asks":[],"checksum":2736631367,"timestamp":"2024-06-01T17:52:17.094787Z"}]}
{"channel":"book","type":"update","data":[{"symbol":"BTC/USDT","bids":[{"price":67676.4,"qty":0.00198081}],"asks":[],"checksum":819444798,"timestamp":"2024-06-01T17:52:17.145556Z"}]}
{"channel":"book","type":"update","data":[{"symbol":"BTC/USDT","bids":[{"price":67682.7,"qty":0.15000000}],"asks":[],"checksum":492823289,"timestamp":"2024-06-01T17:52:17.212940Z"}]}
{"channel":"book","type":"update","data":[{"symbol":"BTC/USDT","bids":[],"asks":[{"price":67690.5,"qty":0.00000000},{"price":67707.9,"qty":0.37408842}],"checksum":2560811287,"timestamp":"2024-06-01T17:52:17.217419Z"}]}
{"channel":"book","type":"update","data":[{"symbol":"BTC/USDT","bids":[{"price":67682.5,"qty":0.00000000},{"price":67676.3,"qty":0.05329011}],"asks":[],"checksum":1645333058,"timestamp":"2024-06-01T17:52:17.217476Z"}]}
{"channel":"book","type":"update","data":[{"symbol":"BTC/USDT","bids":[],"asks":[{"price":67690.6,"qty":0.03947498}],"checksum":3325037890,"timestamp":"2024-06-01T17:52:17.217487Z"}]}
{"channel":"book","type":"update","data":[{"symbol":"BTC/USDT","bids":[{"price":67682.8,"qty":0.01320950}],"asks":[],"checksum":919814580,"timestamp":"2024-06-01T17:52:17.218006Z"}]}
{"channel":"book","type":"update","data":[{"symbol":"BTC/USDT","bids":[{"price":67682.6,"qty":0.00000000},{"price":67676.3,"qty":0.05329011}],"asks":[],"checksum":2888853240,"timestamp":"2024-06-01T17:52:17.218136Z"}]}
{"channel":"book","type":"update","data":[{"symbol":"BTC/USDT","bids":[{"price":67686.4,"qty":0.05000000}],"asks":[],"checksum":1798397421,"timestamp":"2024-06-01T17:52:17.220780Z"}]}
{"channel":"book","type":"update","data":[{"symbol":"BTC/USDT","bids":[{"price":67686.3,"qty":0.00000000},{"price":67676.3,"qty":0.05329011}],"asks":[],"checksum":547177866,"timestamp":"2024-06-01T17:52:17.223230Z"}]}
{"channel":"book","type":"update","data":[{"symbol":"BTC/USDT","bids":[{"price":67686.5,"qty":0.04290000}],"asks":[],"checksum":3896651684,"timestamp":"2024-06-01T17:52:17.223761Z"}]}
{"channel":"book","type":"update","data":[{"symbol":"BTC/USDT","bids":[{"price":67682.8,"qty":0.00000000},{"price":67676.3,"qty":0.05329011}],"asks":[],"checksum":357487803,"timestamp":"2024-06-01T17:52:17.225183Z"}]}
{"channel":"book","type":"update","data":[{"symbol":"BTC/USDT","bids":[{"price":67685.4,"qty":0.00000000},{"price":67676.2,"qty":1.60140704}],"asks":[],"checksum":1776857994,"timestamp":"2024-06-01T17:52:17.585947Z"}]}
{"channel":"book","type":"update","data":[{"symbol":"BTC/USDT","bids":[{"price":67686.6,"qty":0.05000000}],"asks":[],"checksum":1445882554,"timestamp":"2024-06-01T17:52:17.586187Z"}]}
{"channel":"book","type":"update","data":[{"symbol":"BTC/USDT","bids":[],"asks":[{"price":67693.4,"qty":0.00000000},{"price":67708.1,"qty":0.00460867},{"price":67690.5,"qty":0.05328738}],"checksum":1515578632,"timestamp":"2024-06-01T17:52:17.588031Z"}]}
{"channel":"book","type":"update","data":[{"symbol":"BTC/USDT","bids":[{"price":67686.4,"qty":0.00000000},{"price":67676.2,"qty":1.60140704}],"asks":[],"checksum":1816443711,"timestamp":"2024-06-01T17:52:17.591068Z"}]}
{"channel":"book","type":"update","data":[{"symbol":"BTC/USDT","bids":[{"price":67686.5,"qty":0.00000000},{"price":67676.1,"qty":0.17872429}],"asks":[],"checksum":2446190118,"timestamp":"2024-06-01T17:52:17.593718Z"}]}
{"channel":"book","type":"update","data":[{"symbol":"BTC/USDT","bids":[{"price":67683.6,"qty":0.04290000}],"asks":[],"checksum":1265436219,"timestamp":"2024-06-01T17:52:17.593941Z"}]}
{"channel":"book","type":"update","data":[{"symbol":"BTC/USDT","bids":[{"price":67682.8,"qty":0.01774196}],"asks":[],"checksum":2749271357,"timestamp":"2024-06-01T17:52:17.595393Z"}]}
{"channel":"book","type":"update","data":[{"symbol":"BTC/USDT","bids":[{"price":67683.6,"qty":0.05709017}],"asks":[],"checksum":622314613,"timestamp":"2024-06-01T17:52:17.598714Z"}]}
{"channel":"book","type":"update","data":[{"symbol":"BTC/USDT","bids":[{"price":67682.8,"qty":0.00000000},{"price":67676.2,"qty":1.60140704}],"asks":[],"checksum":2093857995,"timestamp":"2024-06-01T17:52:17.599296Z"}]}
{"channel":"book","type":"update","data":[{"symbol":"BTC/USDT","bids":[{"price":67683.7,"qty":0.15000000}],"asks":[],"checksum":1763083354,"timestamp":"2024-06-01T17:52:17.711512Z"}]}
{"channel":"book","type":"update","data":[{"symbol":"BTC/USDT","bids":[{"price":67683.6,"qty":0.01419017}],"asks":[],"checksum":3428709175,"timestamp":"2024-06-01T17:52:17.714157Z"}]}
{"channel":"book","type":"update","data":[{"symbol":"BTC/USDT","bids":[{"price":67686.6,"qty":0.09290000}],"asks":[],"checksum":2071794889,"timestamp":"2024-06-01T17:52:17.714267Z"}]}
{"channel":"book","type":"update","data":[{"symbol":"BTC/USDT","bids":[{"price":67682.7,"qty":0.00000000},{"price":67676.2,"qty":1.60140704}],"asks":[],"checksum":2281684334,"timestamp":"2024-06-01T17:52:17.715916Z"}]}
{"channel":"book","type":"update","data":[{"symbol":"BTC/USDT","bids":[],"asks":[{"price":67690.4,"qty":0.03947498}],"checksum":3706948594,"timestamp":"2024-06-01T17:52:17.715931Z"}]}
{"channel":"book","type":"update","data":[{"symbol":"BTC/USDT","bids":[{"price":67683.6,"qty":0.00000000},{"price":67676.1,"qty":0.17872429}],"asks":[],"checksum":46733746,"timestamp":"2024-06-01T17:52:17.716137Z"}]}
{"channel":"book","type":"update","data":[{"symbol":"BTC/USDT","bids":[],"asks":[{"price":67690.6,"qty":0.00000000},{"price":67702.1,"qty":0.19890820}],"checksum":3548674225,"timestamp":"2024-06-01T17:52:18.091941Z"}]}
{"channel":"book","type":"update","data":[{"symbol":"BTC/USDT","bids":[],"asks":[{"price":67690.4,"qty":0.12947498}],"checksum":4231262601,"timestamp":"2024-06-01T17:52:18.264671Z"}]}
{"channel":"book","type":"update","data":[{"symbol":"BTC/USDT","bids":[{"price":67683.7,"qty":0.00000000},{"price":67676.0,"qty":0.00460867}],"asks":[],"checksum":673981888,"timestamp":"2024-06-01T17:52:18.270135Z"}]}
{"channel":"book","type":"update","data":[{"symbol":"BTC/USDT","bids":[{"price":67682.5,"qty":0.15000000}],"asks":[],"checksum":1006194774,"timestamp":"2024-06-01T17:52:18.270168Z"}]}
{"channel":"book","type":"update","data":[{"symbol":"BTC/USDT","bids":[{"price":67682.6,"qty":0.01774196}],"asks":[],"checksum":2578216391,"timestamp":"2024-06-01T17:52:18.275108Z"}]}
{"channel":"book","type":"update","data":[{"symbol":"BTC/USDT","bids":[],"asks":[{"price":67690.4,"qty":0.21947498}],"checksum":1589810848,"timestamp":"2024-06-01T17:52:18.282281Z"}]}
{"channel":"book","type":"update","data":[{"symbol":"BTC/USDT","bids":[],"asks":[{"price":67690.3,"qty":0.09000000}],"checksum":3593038149,"timestamp":"2024-06-01T17:52:18.286258Z"}]}
{"channel":"book","type":"update","data":[{"symbol":"BTC/USDT","bids":[{"price":67686.6,"qty":0.05000000}],"asks":[],"checksum":2359006905,"timestamp":"2024-06-01T17:52:18.287178Z"}]}
{"channel":"book","type":"update","data":[{"symbol":"BTC/USDT","bids":[{"price":67683.5,"qty":0.04290000}],"asks":[],"checksum":3165951596,"timestamp":"2024-06-01T17:52:18.287433Z"}]}
{"channel":"book","type":"update","data":[{"symbol":"BTC/USDT","bids":[],"asks":[{"price":67690.4,"qty":0.12947498}],"checksum":2770186093,"timestamp":"2024-06-01T17:52:18.290113Z"}]}
{"channel":"book","type":"update","data":[{"symbol":"BTC/USDT","bids":[{"price":67682.6,"qty":0.00000000},{"price":67676.2,"qty":1.60140704}],"asks":[],"checksum":857397183,"timestamp":"2024-06-01T17:52:18.291529Z"}]}
{"channel":"book","type":"update","data":[{"symbol":"BTC/USDT","bids":[{"price":67683.5,"qty":0.05709028}],"asks":[],"checksum":2758236324,"timestamp":"2024-06-01T17:52:18.291666Z"}]}
{"channel":"book","type":"update","data":[{"symbol":"BTC/USDT","bids":[],"asks":[{"price":67690.3,"qty":0.18000000}],"checksum":4192248286,"timestamp":"2024-06-01T17:52:18.293556Z"}]}
{"channel":"book","type":"update","data":[{"symbol":"BTC/USDT","bids":[],"asks":[{"price":67690.5,"qty":0.00000000},{"price":67702.1,"qty":0.19890820},{"price":67690.2,"qty":0.05328717}],"checksum":2410359400,"timestamp":"2024-06-01T17:52:18.367051Z"}]}
{"channel":"book","type":"update","data":[{"symbol":"BTC/USDT","bids":[{"price":67676.3,"qty":0.00000000},{"price":67676.1,"qty":0.17872429},{"price":67680.4,"qty":0.05328833}],"asks":[],"checksum":2069546817,"timestamp":"2024-06-01T17:52:18.367074Z"}]}
{"channel":"book","type":"update","data":[{"symbol":"BTC/USDT","bids":[],"asks":[{"price":67689.1,"qty":0.09000000}],"checksum":4195418170,"timestamp":"2024-06-01T17:52:18.370370Z"}]}
{"channel":"book","type":"update","data":[{"symbol":"BTC/USDT","bids":[],"asks":[{"price":67690.4,"qty":0.03947498}],"checksum":132264050,"timestamp":"2024-06-01T17:52:18.370473Z"}]}
{"channel":"book","type":"update","data":[{"symbol":"BTC/USDT","bids":[{"price":67686.6,"qty":0.00000000},{"price":67676.1,"qty":0.17872429}],"asks":[],"checksum":3848534954,"timestamp":"2024-06-01T17:52:18.371948Z"}]}
{"channel":"book","type":"update","data":[{"symbol":"BTC/USDT","bids":[],"asks":[{"price":67690.1,"qty":0.03947498}],"checksum":1535570751,"timestamp":"2024-06-01T17:52:18.372046Z"}]}
{"channel":"book","type":"update","data":[{"symbol":"BTC/USDT","bids":[{"price":67683.6,"qty":0.15000000}],"asks":[],"checksum":2036241989,"timestamp":"2024-06-01T17:52:18.372062Z"}]}
{"channel":"book","type":"update","data":[{"symbol":"BTC/USDT","bids":[{"price":67683.6,"qty":0.20000000}],"asks":[],"checksum":4023348345,"timestamp":"2024-06-01T17:52:18.372075Z"}]}
{"channel":"book","type":"update","data":[{"symbol":"BTC/USDT","bids":[{"price":67683.5,"qty":0.01419028}],"asks":[],"checksum":1682747155,"timestamp":"2024-06-01T17:52:18.374580Z"}]}
{"channel":"book","type":"update","data":[{"symbol":"BTC/USDT","bids":[{"price":67683.5,"qty":0.00000000},{"price":67676.1,"qty":0.17872429}],"asks":[],"checksum":4207347376,"timestamp":"2024-06-01T17:52:18.374589Z"}]}
{"channel":"book","type":"update","data":[{"symbol":"BTC/USDT","bids":[{"price":67684.5,"qty":0.04290000}],"asks":[],"checksum":765874256,"timestamp":"2024-06-01T17:52:18.374918Z"}]}
{"channel":"book","type":"update","data":[{"symbol":"BTC/USDT","bids":[{"price":67682.6,"qty":0.01330878}],"asks":[],"checksum":711914010,"timestamp":"2024-06-01T17:52:18.375189Z"}]}
{"channel":"book","type":"update","data":[{"symbol":"BTC/USDT","bids":[{"price":67682.6,"qty":0.00000000},{"price":67676.2,"qty":1.60140704}],"asks":[],"checksum":765874256,"timestamp":"2024-06-01T17:52:18.379061Z"}]}
{"channel":"book","type":"update","data":[{"symbol":"BTC/USDT","bids":[{"price":67680.4,"qty":0.00000000},{"price":67676.1,"qty":0.17872429},{"price":67676.3,"qty":0.05329134}],"asks":[],"checksum":2556446281,"timestamp":"2024-06-01T17:52:18.440452Z"}]}
{"channel":"book","type":"update","data":[{"symbol":"BTC/USDT","bids":[{"price":67687.0,"qty":0.00000000},{"price":67676.1,"qty":0.17872429}],"asks":[],"checksum":195582667,"timestamp":"2024-06-01T17:52:18.447707Z"}]}
{"channel":"book","type":"update","data":[{"symbol":"BTC/USDT","bids":[],"asks":[{"price":67690.4,"qty":0.00000000},{"price":67701.4,"qty":0.07396000}],"checksum":260174963,"timestamp":"2024-06-01T17:52:18.451740Z"}]}
{"channel":"book","type":"update","data":[{"symbol":"BTC/USDT","bids":[{"price":67683.6,"qty":0.05000000}],"asks":[],"checksum":3719656841,"timestamp":"2024-06-01T17:52:18.452288Z"}]}
{"channel":"book","type":"update","data":[{"symbol":"BTC/USDT","bids":[{"price":67684.6,"qty":0.05000000}],"asks":[],"checksum":2973393011,"timestamp":"2024-06-01T17:52:18.453133Z"}]}
{"channel":"book","type":"update","data":[{"symbol":"BTC/USDT","bids":[{"price":67684.6,"qty":0.09405954}],"asks":[],"checksum":3470283694,"timestamp":"2024-06-01T17:52:18.453858Z"}]}
{"channel":"book","type":"update","data":[{"symbol":"BTC/USDT","bids":[{"price":67684.5,"qty":0.00000000},{"price":67676.1,"qty":0.17872429}],"asks":[],"checksum":3239756211,"timestamp":"2024-06-01T17:52:18.455796Z"}]}
{"channel":"book","type":"update","data":[{"symbol":"BTC/USDT","bids":[{"price":67685.0,"qty":0.04290000}],"asks":[],"checksum":2336323371,"timestamp":"2024-06-01T17:52:18.455904Z"}]}
{"channel":"book","type":"update","data":[{"symbol":"BTC/USDT","bids":[{"price":67682.6,"qty":0.01774208}],"asks":[],"checksum":1397438510,"timestamp":"2024-06-01T17:52:18.457026Z"}]}
{"channel":"book","type":"update","data":[{"symbol":"BTC/USDT","bids":[{"price":67682.6,"qty":0.00000000},{"price":67676.2,"qty":1.60140704}],"asks":[],"checksum":2336323371,"timestamp":"2024-06-01T17:52:18.460983Z"}]}
{"channel":"book","type":"update","data":[{"symbol":"BTC/USDT","bids":[],"asks":[{"price":67689.1,"qty":0.00000000},{"price":67701.6,"qty":0.09000000}],"checksum":1913040581,"timestamp":"2024-06-01T17:52:18.557962Z"}]}
