{"channel":"book","type":"snapshot","data":[{"symbol":"BTC/AUD","bids":[{"price":101646.8,"qty":0.00308000},{"price":101646.7,"qty":0.15000000},{"price":101646.6,"qty":0.05390421},{"price":101646.4,"qty":0.19717373},{"price":101646.3,"qty":0.00269415},{"price":101645.9,"qty":0.37580253},{"price":101643.3,"qty":0.00551300},{"price":101642.3,"qty":0.02937000},{"price":101642.2,"qty":0.23811098},{"price":101629.7,"qty":0.00135300}],"asks":[{"price":101770.9,"qty":0.05388402},{"price":101771.0,"qty":0.04717373},{"price":101771.2,"qty":0.00475100},{"price":101771.3,"qty":0.00135200},{"price":101773.0,"qty":0.00639000},{"price":101775.1,"qty":0.00075700},{"price":101780.3,"qty":0.00045608},{"price":101820.0,"qty":0.01129070},{"price":101820.1,"qty":0.02937000},{"price":101820.9,"qty":0.33176118}],"checksum":3043906944}]}
{"channel":"book","type":"update","data":[{"symbol":"BTC/AUD","bids":[],"asks":[{"price":101820.9,"qty":0.32815861}],"checksum":1932620280,"timestamp":"2024-06-01T17:51:31.943422Z"}]}
{"channel":"book","type":"update","data":[{"symbol":"BTC/AUD","bids":[],"asks":[{"price":101820.1,"qty":0.03287084}],"checksum":1712230128,"timestamp":"2024-06-01T17:51:31.948617Z"}]}
{"channel":"book","type":"update","data":[{"symbol":"BTC/AUD","bids":[{"price":101646.4,"qty":0.04717373}],"asks":[],"checksum":3123233808,"timestamp":"2024-06-01T17:51:32.143900Z"}]}
{"channel":"book","type":"update","data":[{"symbol":"BTC/AUD","bids":[],"asks":[{"price":101770.8,"qty":0.04717373}],"checksum":1959134022,"timestamp":"2024-06-01T17:51:32.149429Z"}]}
{"channel":"book","type":"update","data":[{"symbol":"BTC/AUD","bids":[],"asks":[{"price":101771.0,"qty":0.00000000},{"price":101820.9,"qty":0.32815861}],"checksum":256313235,"timestamp":"2024-06-01T17:51:32.178661Z"}]}
{"channel":"book","type":"update","data":[{"symbol":"BTC/AUD","bids":[],"asks":[{"price":101820.1,"qty":0.00350084},{"price":101819.9,"qty":0.02937000}],"checksum":265925270,"timestamp":"2024-06-01T17:51:32.181313Z"}]}
{"channel":"book","type":"update","data":[{"symbol":"BTC/AUD","bids":[{"price":101642.3,"qty":0.00000000},{"price":101595.2,"qty":0.00569000},{"price":101643.4,"qty":0.02937000}],"asks":[],"checksum":3573265415,"timestamp":"2024-06-01T17:51:32.181630Z"}]}
{"channel":"book","type":"update","data":[{"symbol":"BTC/AUD","bids":[],"asks":[{"price":101820.0,"qty":0.00000000},{"price":101820.9,"qty":0.32815861}],"checksum":343220870,"timestamp":"2024-06-01T17:51:32.198407Z"}]}
{"channel":"book","type":"update","data":[{"symbol":"BTC/AUD","bids":[],"asks":[{"price":101819.8,"qty":0.01129070}],"checksum":3520463782,"timestamp":"2024-06-01T17:51:32.198592Z"}]}
{"channel":"book","type":"update","data":[{"symbol":"BTC/AUD","bids":[{"price":101646.6,"qty":0.00000000},{"price":101595.2,"qty":0.00569000},{"price":101646.9,"qty":0.05390405}],"asks":[],"checksum":1836733285,"timestamp":"2024-06-01T17:51:32.532413Z"}]}
{"channel":"book","type":"update","data":[{"symbol":"BTC/AUD","bids":[{"price":101646.8,"qty":0.00000000},{"price":101595.2,"qty":0.00569000},{"price":101647.0,"qty":0.00308000}],"asks":[],"checksum":556815785,"timestamp":"2024-06-01T17:51:32.565557Z"}]}
{"channel":"book","type":"update","data":[{"symbol":"BTC/AUD","bids":[],"asks":[{"price":101819.9,"qty":0.38049848}],"checksum":2236347845,"timestamp":"2024-06-01T17:51:32.596527Z"}]}
{"channel":"book","type":"update","data":[{"symbol":"BTC/AUD","bids":[],"asks":[{"price":101819.9,"qty":0.35112848},{"price":101819.7,"qty":0.02937000}],"checksum":1120570223,"timestamp":"2024-06-01T17:51:32.767690Z"}]}
{"channel":"book","type":"update","data":[{"symbol":"BTC/AUD","bids":[],"asks":[{"price":101819.6,"qty":0.01129070}],"checksum":2488717225,"timestamp":"2024-06-01T17:51:32.786811Z"}]}
{"channel":"book","type":"update","data":[{"symbol":"BTC/AUD","bids":[],"asks":[{"price":101819.8,"qty":0.00000000},{"price":101819.9,"qty":0.35112848}],"checksum":3672407041,"timestamp":"2024-06-01T17:51:32.786831Z"}]}
{"channel":"book","type":"update","data":[{"symbol":"BTC/AUD","bids":[{"price":101645.9,"qty":0.00000000},{"price":101595.2,"qty":0.00569000}],"asks":[],"checksum":4209891834,"timestamp":"2024-06-01T17:51:33.116148Z"}]}
{"channel":"book","type":"update","data":[{"symbol":"BTC/AUD","bids":[{"price":101647.1,"qty":0.37582045}],"asks":[],"checksum":2639561608,"timestamp":"2024-06-01T17:51:33.116206Z"}]}
{"channel":"book","type":"update","data":[{"symbol":"BTC/AUD","bids":[{"price":101647.2,"qty":0.04717373}],"asks":[],"checksum":4230947477,"timestamp":"2024-06-01T17:51:33.122075Z"}]}
{"channel":"book","type":"update","data":[{"symbol":"BTC/AUD","bids":[{"price":101647.2,"qty":0.19717373}],"asks":[],"checksum":4264808857,"timestamp":"2024-06-01T17:51:33.122895Z"}]}
{"channel":"book","type":"update","data":[{"symbol":"BTC/AUD","bids":[{"price":101646.7,"qty":0.00000000},{"price":101629.7,"qty":0.00135300}],"asks":[],"checksum":2543129872,"timestamp":"2024-06-01T17:51:33.142866Z"}]}
{"channel":"book","type":"update","data":[{"symbol":"BTC/AUD","bids":[{"price":101647.0,"qty":0.00000000},{"price":101595.2,"qty":0.00569000},{"price":101647.3,"qty":0.00308000}],"asks":[],"checksum":3385650752,"timestamp":"2024-06-01T17:51:33.144914Z"}]}
{"channel":"book","type":"update","data":[{"symbol":"BTC/AUD","bids":[{"price":101646.4,"qty":0.00000000},{"price":101595.2,"qty":0.00569000}],"asks":[],"checksum":2094280510,"timestamp":"2024-06-01T17:51:33.177739Z"}]}
{"channel":"book","type":"update","data":[{"symbol":"BTC/AUD","bids":[],"asks":[{"price":101770.9,"qty":0.00000000},{"price":101820.1,"qty":0.00350084},{"price":101770.7,"qty":0.05388402}],"checksum":2912255798,"timestamp":"2024-06-01T17:51:33.287074Z"}]}
{"channel":"book","type":"update","data":[{"symbol":"BTC/AUD","bids":[{"price":101646.9,"qty":0.00000000},{"price":101585.0,"qty":0.09768924},{"price":101647.4,"qty":0.05390354}],"asks":[],"checksum":629706584,"timestamp":"2024-06-01T17:51:33.287123Z"}]}
{"channel":"book","type":"update","data":[{"symbol":"BTC/AUD","bids":[],"asks":[{"price":101819.7,"qty":0.00000000},{"price":101820.1,"qty":0.00350084},{"price":101819.5,"qty":0.02937000}],"checksum":2517420081,"timestamp":"2024-06-01T17:51:33.289961Z"}]}
{"channel":"book","type":"update","data":[{"symbol":"BTC/AUD","bids":[],"asks":[{"price":101819.6,"qty":0.00000000},{"price":101820.1,"qty":0.00350084}],"checksum":1549687858,"timestamp":"2024-06-01T17:51:33.301827Z"}]}
{"channel":"book","type":"update","data":[{"symbol":"BTC/AUD","bids":[],"asks":[{"price":101819.4,"qty":0.01129070}],"checksum":2213832803,"timestamp":"2024-06-01T17:51:33.301854Z"}]}
{"channel":"book","type":"update","data":[{"symbol":"BTC/AUD","bids":[{"price":101643.4,"qty":0.00000000},{"price":101585.0,"qty":0.09768924},{"price":101647.5,"qty":0.02937000}],"asks":[],"checksum":912514506,"timestamp":"2024-06-01T17:51:33.364057Z"}]}
{"channel":"book","type":"update","data":[{"symbol":"BTC/AUD","bids":[{"price":101647.3,"qty":0.00000000},{"price":101585.0,"qty":0.09768924},{"price":101647.6,"qty":0.00308000}],"asks":[],"checksum":1255986384,"timestamp":"2024-06-01T17:51:33.999095Z"}]}
{"channel":"book","type":"update","data":[{"symbol":"BTC/AUD","bids":[],"asks":[{"price":101819.5,"qty":0.00000000},{"price":101820.1,"qty":0.00350084},{"price":101819.3,"qty":0.02937000}],"checksum":2162526273,"timestamp":"2024-06-01T17:51:34.001882Z"}]}
{"channel":"book","type":"update","data":[{"symbol":"BTC/AUD","bids":[{"price":101647.6,"qty":0.15308000}],"asks":[],"checksum":4123708986,"timestamp":"2024-06-01T17:51:34.004318Z"}]}
{"channel":"book","type":"update","data":[{"symbol":"BTC/AUD","bids":[],"asks":[{"price":101770.6,"qty":0.04717373}],"checksum":2157826314,"timestamp":"2024-06-01T17:51:34.004467Z"}]}
{"channel":"book","type":"update","data":[{"symbol":"BTC/AUD","bids":[{"price":101647.7,"qty":0.04717373}],"asks":[],"checksum":3650674465,"timestamp":"2024-06-01T17:51:34.004579Z"}]}
{"channel":"book","type":"update","data":[{"symbol":"BTC/AUD","bids":[],"asks":[{"price":101819.2,"qty":0.01129070}],"checksum":2619824254,"timestamp":"2024-06-01T17:51:34.005948Z"}]}
{"channel":"book","type":"update","data":[{"symbol":"BTC/AUD","bids":[{"price":101647.5,"qty":0.00000000},{"price":101595.2,"qty":0.00569000},{"price":101647.7,"qty":0.07654373}],"asks":[],"checksum":3763515094,"timestamp":"2024-06-01T17:51:34.006945Z"}]}
{"channel":"book","type":"update","data":[{"symbol":"BTC/AUD","bids":[{"price":101646.3,"qty":0.00000000},{"price":101585.0,"qty":0.09768924}],"asks":[],"checksum":23873081,"timestamp":"2024-06-01T17:51:34.057929Z"}]}
{"channel":"book","type":"update","data":[{"symbol":"BTC/AUD","bids":[{"price":101647.6,"qty":0.15590042}],"asks":[],"checksum":3962277422,"timestamp":"2024-06-01T17:51:34.059190Z"}]}
{"channel":"book","type":"update","data":[{"symbol":"BTC/AUD","bids":[],"asks":[{"price":101770.8,"qty":0.00000000},{"price":101819.9,"qty":0.35112848}],"checksum":1942663927,"timestamp":"2024-06-01T17:51:34.064812Z"}]}
{"channel":"book","type":"update","data":[{"symbol":"BTC/AUD","bids":[{"price":101647.2,"qty":0.15000000}],"asks":[],"checksum":3556085874,"timestamp":"2024-06-01T17:51:34.064869Z"}]}
{"channel":"book","type":"update","data":[{"symbol":"BTC/AUD","bids":[{"price":101647.6,"qty":0.00590042}],"asks":[],"checksum":1046112357,"timestamp":"2024-06-01T17:51:34.065549Z"}]}
{"channel":"book","type":"update","data":[{"symbol":"BTC/AUD","bids":[{"price":101647.6,"qty":0.00282042},{"price":101647.8,"qty":0.00308000}],"asks":[],"checksum":3670346939,"timestamp":"2024-06-01T17:51:34.091628Z"}]}
{"channel":"book","type":"update","data":[{"symbol":"BTC/AUD","bids":[{"price":101647.4,"qty":0.00000000},{"price":101585.0,"qty":0.09768924},{"price":101647.8,"qty":0.05698331}],"asks":[],"checksum":3907669953,"timestamp":"2024-06-01T17:51:34.102395Z"}]}
{"channel":"book","type":"update","data":[{"symbol":"BTC/AUD","bids":[],"asks":[{"price":101770.7,"qty":0.00000000},{"price":101820.1,"qty":0.00350084},{"price":101770.5,"qty":0.05388398}],"checksum":752598554,"timestamp":"2024-06-01T17:51:34.102417Z"}]}
{"channel":"book","type":"update","data":[{"symbol":"BTC/AUD","bids":[{"price":101585.1,"qty":0.02950711}],"asks":[],"checksum":196170615,"timestamp":"2024-06-01T17:51:34.143831Z"}]}
{"channel":"book","type":"update","data":[{"symbol":"BTC/AUD","bids":[],"asks":[{"price":101819.3,"qty":0.03290899}],"checksum":3289789784,"timestamp":"2024-06-01T17:51:34.191699Z"}]}
{"channel":"book","type":"update","data":[{"symbol":"BTC/AUD","bids":[],"asks":[{"price":101770.6,"qty":0.00000000},{"price":101822.9,"qty":0.05056249}],"checksum":2434609591,"timestamp":"2024-06-01T17:51:34.329801Z"}]}
{"channel":"book","type":"update","data":[{"symbol":"BTC/AUD","bids":[],"asks":[{"price":101819.2,"qty":0.00000000},{"price":101826.0,"qty":0.09768924}],"checksum":2305036337,"timestamp":"2024-06-01T17:51:34.352511Z"}]}
{"channel":"book","type":"update","data":[{"symbol":"BTC/AUD","bids":[],"asks":[{"price":101770.5,"qty":0.00000000},{"price":101829.4,"qty":0.05000000},{"price":101771.1,"qty":0.05388385}],"checksum":1723818693,"timestamp":"2024-06-01T17:51:34.394620Z"}]}
{"channel":"book","type":"update","data":[{"symbol":"BTC/AUD","bids":[{"price":101627.0,"qty":0.00503000}],"asks":[],"checksum":2581686723,"timestamp":"2024-06-01T17:51:34.466041Z"}]}
{"channel":"book","type":"update","data":[{"symbol":"BTC/AUD","bids":[],"asks":[{"price":101771.2,"qty":0.00000000},{"price":101829.4,"qty":0.05000000},{"price":101789.4,"qty":0.00475100}],"checksum":3304528549,"timestamp":"2024-06-01T17:51:34.479415Z"}]}
{"channel":"book","type":"update","data":[{"symbol":"BTC/AUD","bids":[],"asks":[{"price":101775.1,"qty":0.00000000},{"price":101854.6,"qty":0.01129070},{"price":101788.6,"qty":0.00075700}],"checksum":3948929216,"timestamp":"2024-06-01T17:51:34.500499Z"}]}
{"channel":"book","type":"update","data":[{"symbol":"BTC/AUD","bids":[{"price":101606.3,"qty":0.05056249}],"asks":[],"checksum":3614624751,"timestamp":"2024-06-01T17:51:34.521234Z"}]}
{"channel":"book","type":"update","data":[{"symbol":"BTC/AUD","bids":[{"price":101647.7,"qty":0.04717373},{"price":101647.9,"qty":0.02937000}],"asks":[],"checksum":208152461,"timestamp":"2024-06-01T17:51:34.524087Z"}]}
{"channel":"book","type":"update","data":[{"symbol":"BTC/AUD","bids":[],"asks":[{"price":101771.1,"qty":0.00000000},{"price":101854.6,"qty":0.01129070},{"price":101771.2,"qty":0.05388385}],"checksum":4088206412,"timestamp":"2024-06-01T17:51:34.528076Z"}]}
{"channel":"book","type":"update","data":[{"symbol":"BTC/AUD","bids":[{"price":101629.7,"qty":0.00000000},{"price":101606.4,"qty":0.04191504},{"price":101647.9,"qty":0.03072300}],"asks":[],"checksum":965903165,"timestamp":"2024-06-01T17:51:34.572142Z"}]}
{"channel":"book","type":"update","data":[{"symbol":"BTC/AUD","bids":[{"price":101647.8,"qty":0.05390331},{"price":101648.0,"qty":0.00308000}],"asks":[],"checksum":704023722,"timestamp":"2024-06-01T17:51:34.888844Z"}]}
{"channel":"book","type":"update","data":[{"symbol":"BTC/AUD","bids":[{"price":101648.0,"qty":0.15308000}],"asks":[],"checksum":3116630141,"timestamp":"2024-06-01T17:51:34.893906Z"}]}
{"channel":"book","type":"update","data":[{"symbol":"BTC/AUD","bids":[{"price":101647.8,"qty":0.00000000},{"price":101606.4,"qty":0.04191504},{"price":101648.0,"qty":0.20698362}],"asks":[],"checksum":2648850242,"timestamp":"2024-06-01T17:51:34.906127Z"}]}
{"channel":"book","type":"update","data":[{"symbol":"BTC/AUD","bids":[{"price":101647.9,"qty":0.00135300},{"price":101648.1,"qty":0.02937000}],"asks":[],"checksum":1338941087,"timestamp":"2024-06-01T17:51:35.067108Z"}]}
{"channel":"book","type":"update","data":[{"symbol":"BTC/AUD","bids":[{"price":101648.0,"qty":0.05698362}],"asks":[],"checksum":3671473220,"timestamp":"2024-06-01T17:51:35.072212Z"}]}
{"channel":"book","type":"update","data":[{"symbol":"BTC/AUD","bids":[{"price":101648.2,"qty":0.04717373}],"asks":[],"checksum":1548768051,"timestamp":"2024-06-01T17:51:35.072439Z"}]}
{"channel":"book","type":"update","data":[{"symbol":"BTC/AUD","bids":[{"price":101648.3,"qty":0.15000000}],"asks":[],"checksum":3484174567,"timestamp":"2024-06-01T17:51:35.143672Z"}]}
{"channel":"book","type":"update","data":[{"symbol":"BTC/AUD","bids":[{"price":101647.2,"qty":0.00000000},{"price":101642.2,"qty":0.23811098}],"asks":[],"checksum":3732509390,"timestamp":"2024-06-01T17:51:35.148429Z"}]}
{"channel":"book","type":"update","data":[{"symbol":"BTC/AUD","bids":[{"price":101647.7,"qty":0.00000000},{"price":101627.0,"qty":0.00503000}],"asks":[],"checksum":957977528,"timestamp":"2024-06-01T17:51:35.148873Z"}]}
{"channel":"book","type":"update","data":[{"symbol":"BTC/AUD","bids":[],"asks":[{"price":101819.9,"qty":0.00000000},{"price":101851.5,"qty":0.05000000}],"checksum":361017067,"timestamp":"2024-06-01T17:51:35.322718Z"}]}
{"channel":"book","type":"update","data":[{"symbol":"BTC/AUD","bids":[],"asks":[{"price":101851.4,"qty":0.01129070}],"checksum":3140148542,"timestamp":"2024-06-01T17:51:35.326970Z"}]}
{"channel":"book","type":"update","data":[{"symbol":"BTC/AUD","bids":[],"asks":[{"price":101819.2,"qty":0.25925397}],"checksum":485065348,"timestamp":"2024-06-01T17:51:35.327524Z"}]}
{"channel":"book","type":"update","data":[{"symbol":"BTC/AUD","bids":[],"asks":[{"price":101819.3,"qty":0.00353899},{"price":101819.1,"qty":0.02937000}],"checksum":2919044446,"timestamp":"2024-06-01T17:51:35.330625Z"}]}
{"channel":"book","type":"update","data":[{"symbol":"BTC/AUD","bids":[{"price":101648.0,"qty":0.00308000},{"price":101648.4,"qty":0.05390343}],"asks":[],"checksum":2443710246,"timestamp":"2024-06-01T17:51:35.739869Z"}]}
{"channel":"book","type":"update","data":[{"symbol":"BTC/AUD","bids":[{"price":101648.1,"qty":0.00000000},{"price":101627.0,"qty":0.00503000},{"price":101648.5,"qty":0.02937000}],"asks":[],"checksum":2604136986,"timestamp":"2024-06-01T17:51:35.742910Z"}]}
{"channel":"book","type":"update","data":[{"symbol":"BTC/AUD","bids":[{"price":101648.5,"qty":0.17937000}],"asks":[],"checksum":3416173336,"timestamp":"2024-06-01T17:51:35.745300Z"}]}
{"channel":"book","type":"update","data":[{"symbol":"BTC/AUD","bids":[{"price":101648.0,"qty":0.00000000},{"price":101627.0,"qty":0.00503000},{"price":101648.6,"qty":0.00308000}],"asks":[],"checksum":1929805399,"timestamp":"2024-06-01T17:51:35.776620Z"}]}
{"channel":"book","type":"update","data":[{"symbol":"BTC/AUD","bids":[{"price":101648.3,"qty":0.00000000},{"price":101627.0,"qty":0.00503000}],"asks":[],"checksum":3201565158,"timestamp":"2024-06-01T17:51:35.781875Z"}]}
{"channel":"book","type":"update","data":[{"symbol":"BTC/AUD","bids":[],"asks":[{"price":101789.4,"qty":0.00000000},{"price":101826.0,"qty":0.09768924},{"price":101777.3,"qty":0.00475100}],"checksum":1890833749,"timestamp":"2024-06-01T17:51:35.904988Z"}]}
{"channel":"book","type":"update","data":[{"symbol":"BTC/AUD","bids":[],"asks":[{"price":101788.6,"qty":0.00000000},{"price":101826.0,"qty":0.09768924},{"price":101776.5,"qty":0.00075700}],"checksum":3809042325,"timestamp":"2024-06-01T17:51:35.919699Z"}]}
{"channel":"book","type":"update","data":[{"symbol":"BTC/AUD","bids":[],"asks":[{"price":101777.3,"qty":0.00000000},{"price":101826.0,"qty":0.09768924},{"price":101786.6,"qty":0.00475100}],"checksum":587299726,"timestamp":"2024-06-01T17:51:36.082040Z"}]}
{"channel":"book","type":"update","data":[{"symbol":"BTC/AUD","bids":[{"price":101648.7,"qty":0.04717373}],"asks":[],"checksum":777106064,"timestamp":"2024-06-01T17:51:36.086893Z"}]}
{"channel":"book","type":"update","data":[{"symbol":"BTC/AUD","bids":[{"price":101642.2,"qty":0.00000000},{"price":101627.0,"qty":0.00503000}],"asks":[],"checksum":911530563,"timestamp":"2024-06-01T17:51:36.089882Z"}]}
{"channel":"book","type":"update","data":[{"symbol":"BTC/AUD","bids":[{"price":101648.8,"qty":0.23809552}],"asks":[],"checksum":3493191277,"timestamp":"2024-06-01T17:51:36.092955Z"}]}
{"channel":"book","type":"update","data":[{"symbol":"BTC/AUD","bids":[{"price":101647.1,"qty":0.00000000},{"price":101627.0,"qty":0.00503000}],"asks":[],"checksum":3531931553,"timestamp":"2024-06-01T17:51:36.104543Z"}]}
{"channel":"book","type":"update","data":[{"symbol":"BTC/AUD","bids":[{"price":101648.7,"qty":0.42296895}],"asks":[],"checksum":420013032,"timestamp":"2024-06-01T17:51:36.105214Z"}]}
{"channel":"book","type":"update","data":[{"symbol":"BTC/AUD","bids":[{"price":101648.6,"qty":0.00000000},{"price":101606.4,"qty":0.04191504},{"price":101648.9,"qty":0.00308000}],"asks":[],"checksum":70733748,"timestamp":"2024-06-01T17:51:36.115872Z"}]}
{"channel":"book","type":"update","data":[{"symbol":"BTC/AUD","bids":[{"price":101648.2,"qty":0.00000000},{"price":101606.4,"qty":0.04191504}],"asks":[],"checksum":2137265294,"timestamp":"2024-06-01T17:51:36.120932Z"}]}
{"channel":"book","type":"update","data":[{"symbol":"BTC/AUD","bids":[{"price":101648.5,"qty":0.15000000},{"price":101648.9,"qty":0.03245000}],"asks":[],"checksum":740218857,"timestamp":"2024-06-01T17:51:36.244256Z"}]}
{"channel":"book","type":"update","data":[{"symbol":"BTC/AUD","bids":[],"asks":[{"price":101819.3,"qty":0.00000000},{"price":101826.0,"qty":0.09768924}],"checksum":2295541517,"timestamp":"2024-06-01T17:51:36.487076Z"}]}
{"channel":"book","type":"update","data":[{"symbol":"BTC/AUD","bids":[],"asks":[{"price":101776.5,"qty":0.00000000},{"price":101851.4,"qty":0.01129070},{"price":101788.6,"qty":0.00075700}],"checksum":647598824,"timestamp":"2024-06-01T17:51:36.489067Z"}]}
{"channel":"book","type":"update","data":[{"symbol":"BTC/AUD","bids":[],"asks":[{"price":101819.0,"qty":0.00294119}],"checksum":2770307083,"timestamp":"2024-06-01T17:51:36.490784Z"}]}
{"channel":"book","type":"update","data":[{"symbol":"BTC/AUD","bids":[{"price":101648.9,"qty":0.02937000},{"price":101649.0,"qty":0.00308000}],"asks":[],"checksum":843944538,"timestamp":"2024-06-01T17:51:36.513187Z"}]}
{"channel":"book","type":"update","data":[{"symbol":"BTC/AUD","bids":[{"price":101648.4,"qty":0.00000000},{"price":101606.4,"qty":0.04191504},{"price":101649.0,"qty":0.05698089}],"asks":[],"checksum":1588353150,"timestamp":"2024-06-01T17:51:36.522744Z"}]}
{"channel":"book","type":"update","data":[{"symbol":"BTC/AUD","bids":[{"price":101649.0,"qty":0.00308000},{"price":101648.9,"qty":0.08327073}],"asks":[],"checksum":2934580479,"timestamp":"2024-06-01T17:51:36.567421Z"}]}
{"channel":"book","type":"update","data":[{"symbol":"BTC/AUD","bids":[{"price":101647.6,"qty":0.00000000},{"price":101606.3,"qty":0.05056249}],"asks":[],"checksum":1078564104,"timestamp":"2024-06-01T17:51:37.018042Z"}]}
{"channel":"book","type":"update","data":[{"symbol":"BTC/AUD","bids":[{"price":101649.1,"qty":0.00275710}],"asks":[],"checksum":3994065640,"timestamp":"2024-06-01T17:51:37.019065Z"}]}
{"channel":"book","type":"update","data":[{"symbol":"BTC/AUD","bids":[{"price":101649.0,"qty":0.15308000}],"asks":[],"checksum":2133830503,"timestamp":"2024-06-01T17:51:37.024529Z"}]}
{"channel":"book","type":"update","data":[{"symbol":"BTC/AUD","bids":[],"asks":[{"price":101784.7,"qty":0.04717373}],"checksum":2664366790,"timestamp":"2024-06-01T17:51:37.024554Z"}]}
{"channel":"book","type":"update","data":[{"symbol":"BTC/AUD","bids":[{"price":101649.2,"qty":0.04717373}],"asks":[],"checksum":2606415962,"timestamp":"2024-06-01T17:51:37.024749Z"}]}
{"channel":"book","type":"update","data":[{"symbol":"BTC/AUD","bids":[{"price":101648.9,"qty":0.05390073},{"price":101649.1,"qty":0.03212710}],"asks":[],"checksum":1323019494,"timestamp":"2024-06-01T17:51:37.027196Z"}]}
{"channel":"book","type":"update","data":[{"symbol":"BTC/AUD","bids":[{"price":101649.0,"qty":0.15000000},{"price":101649.3,"qty":0.00308000}],"asks":[],"checksum":368362008,"timestamp":"2024-06-01T17:51:37.062028Z"}]}
{"channel":"book","type":"update","data":[{"symbol":"BTC/AUD","bids":[{"price":101648.7,"qty":0.37579522}],"asks":[],"checksum":397691232,"timestamp":"2024-06-01T17:51:37.067873Z"}]}
{"channel":"book","type":"update","data":[{"symbol":"BTC/AUD","bids":[{"price":101649.0,"qty":0.00000000},{"price":101627.0,"qty":0.00503000}],"asks":[],"checksum":1592924146,"timestamp":"2024-06-01T17:51:37.075171Z"}]}
{"channel":"book","type":"update","data":[{"symbol":"BTC/AUD","bids":[{"price":101648.9,"qty":0.00000000},{"price":101606.4,"qty":0.04191504},{"price":101649.4,"qty":0.05390037}],"asks":[],"checksum":1177861249,"timestamp":"2024-06-01T17:51:37.343565Z"}]}
{"channel":"book","type":"update","data":[{"symbol":"BTC/AUD","bids":[],"asks":[{"price":101786.6,"qty":0.00000000},{"price":101822.9,"qty":0.05056249},{"price":101779.4,"qty":0.00475100}],"checksum":541296572,"timestamp":"2024-06-01T17:51:37.513773Z"}]}
{"channel":"book","type":"update","data":[{"symbol":"BTC/AUD","bids":[{"price":101649.3,"qty":0.00000000},{"price":101606.4,"qty":0.04191504},{"price":101649.5,"qty":0.00308000}],"asks":[],"checksum":1824302752,"timestamp":"2024-06-01T17:51:37.585942Z"}]}
{"channel":"book","type":"update","data":[{"symbol":"BTC/AUD","bids":[{"price":101649.1,"qty":0.00275710},{"price":101649.5,"qty":0.03245000}],"asks":[],"checksum":3906859453,"timestamp":"2024-06-01T17:51:37.588739Z"}]}
{"channel":"book","type":"update","data":[{"symbol":"BTC/AUD","bids":[],"asks":[{"price":101788.6,"qty":0.00000000},{"price":101822.9,"qty":0.05056249},{"price":101778.6,"qty":0.00075700}],"checksum":303348239,"timestamp":"2024-06-01T17:51:37.694944Z"}]}
{"channel":"book","type":"update","data":[{"symbol":"BTC/AUD","bids":[{"price":101649.6,"qty":0.15000000}],"asks":[],"checksum":2498977377,"timestamp":"2024-06-01T17:51:37.701980Z"}]}
{"channel":"book","type":"update","data":[{"symbol":"BTC/AUD","bids":[],"asks":[{"price":101819.2,"qty":0.00000000},{"price":101822.9,"qty":0.05056249}],"checksum":4242401603,"timestamp":"2024-06-01T17:51:38.059819Z"}]}
{"channel":"book","type":"update","data":[{"symbol":"BTC/AUD","bids":[],"asks":[{"price":101818.9,"qty":0.28222158}],"checksum":2539776977,"timestamp":"2024-06-01T17:51:38.063502Z"}]}
{"channel":"book","type":"update","data":[{"symbol":"BTC/AUD","bids":[],"asks":[{"price":101819.1,"qty":0.00000000},{"price":101822.9,"qty":0.05056249},{"price":101822.8,"qty":0.02937000}],"checksum":1451100758,"timestamp":"2024-06-01T17:51:38.063835Z"}]}
{"channel":"book","type":"update","data":[{"symbol":"BTC/AUD","bids":[{"price":101648.5,"qty":0.00000000},{"price":101627.0,"qty":0.00503000}],"asks":[],"checksum":1825655765,"timestamp":"2024-06-01T17:51:38.144303Z"}]}
{"channel":"book","type":"update","data":[{"symbol":"BTC/AUD","bids":[{"price":101649.5,"qty":0.00308000},{"price":101649.7,"qty":0.02937000}],"asks":[],"checksum":3078463038,"timestamp":"2024-06-01T17:51:38.147291Z"}]}
{"channel":"book","type":"update","data":[{"symbol":"BTC/AUD","bids":[{"price":101649.8,"qty":0.04717373}],"asks":[],"checksum":3584888384,"timestamp":"2024-06-01T17:51:38.153113Z"}]}
{"channel":"book","type":"update","data":[{"symbol":"BTC/AUD","bids":[{"price":101649.4,"qty":0.00000000},{"price":101643.3,"qty":0.00551300},{"price":101649.7,"qty":0.08327016}],"asks":[],"checksum":1132782825,"timestamp":"2024-06-01T17:51:38.160369Z"}]}
{"channel":"book","type":"update","data":[{"symbol":"BTC/AUD","bids":[{"price":101649.2,"qty":0.00000000},{"price":101627.0,"qty":0.00503000}],"asks":[],"checksum":2201429833,"timestamp":"2024-06-01T17:51:38.178579Z"}]}
{"channel":"book","type":"update","data":[{"symbol":"BTC/AUD","bids":[{"price":101649.5,"qty":0.00000000},{"price":101606.4,"qty":0.04191504},{"price":101649.9,"qty":0.00308000}],"asks":[],"checksum":641336143,"timestamp":"2024-06-01T17:51:38.503815Z"}]}
{"channel":"book","type":"update","data":[{"symbol":"BTC/AUD","bids":[],"asks":[{"price":101819.0,"qty":0.00000000},{"price":101822.9,"qty":0.05056249}],"checksum":1581310790,"timestamp":"2024-06-01T17:51:38.630728Z"}]}
{"channel":"book","type":"update","data":[{"symbol":"BTC/AUD","bids":[],"asks":[{"price":101822.8,"qty":0.00000000},{"price":101826.0,"qty":0.09768924},{"price":101818.8,"qty":0.02937000}],"checksum":1109413161,"timestamp":"2024-06-01T17:51:38.634007Z"}]}
{"channel":"book","type":"update","data":[{"symbol":"BTC/AUD","bids":[],"asks":[{"price":101818.8,"qty":0.03259101}],"checksum":2243632798,"timestamp":"2024-06-01T17:51:38.636690Z"}]}
{"channel":"book","type":"update","data":[{"symbol":"BTC/AUD","bids":[],"asks":[{"price":101779.4,"qty":0.00000000},{"price":101826.0,"qty":0.09768924},{"price":101787.1,"qty":0.00475100}],"checksum":2515690607,"timestamp":"2024-06-01T17:51:38.839331Z"}]}
{"channel":"book","type":"update","data":[{"symbol":"BTC/AUD","bids":[{"price":101649.7,"qty":0.05390016},{"price":101649.9,"qty":0.03245000}],"asks":[],"checksum":2678796909,"timestamp":"2024-06-01T17:51:38.842253Z"}]}
{"channel":"book","type":"update","data":[{"symbol":"BTC/AUD","bids":[{"price":101649.9,"qty":0.18245000}],"asks":[],"checksum":3427402083,"timestamp":"2024-06-01T17:51:38.844894Z"}]}
{"channel":"book","type":"update","data":[{"symbol":"BTC/AUD","bids":[],"asks":[{"price":101778.6,"qty":0.00000000},{"price":101826.0,"qty":0.09768924},{"price":101786.2,"qty":0.00075700}],"checksum":3176560521,"timestamp":"2024-06-01T17:51:38.847782Z"}]}
{"channel":"book","type":"update","data":[{"symbol":"BTC/AUD","bids":[{"price":101649.9,"qty":0.17937000},{"price":101650.0,"qty":0.00308000}],"asks":[],"checksum":4046588312,"timestamp":"2024-06-01T17:51:38.868697Z"}]}
{"channel":"book","type":"update","data":[{"symbol":"BTC/AUD","bids":[{"price":101649.7,"qty":0.00000000},{"price":101627.0,"qty":0.00503000},{"price":101650.1,"qty":0.05389997}],"asks":[],"checksum":2268403413,"timestamp":"2024-06-01T17:51:38.923014Z"}]}
{"channel":"book","type":"update","data":[{"symbol":"BTC/AUD","bids":[{"price":101649.9,"qty":0.02937000}],"asks":[],"checksum":531485624,"timestamp":"2024-06-01T17:51:38.928393Z"}]}
{"channel":"book","type":"update","data":[{"symbol":"BTC/AUD","bids":[{"price":101650.2,"qty":0.04717373}],"asks":[],"checksum":667129626,"timestamp":"2024-06-01T17:51:38.932223Z"}]}
{"channel":"book","type":"update","data":[{"symbol":"BTC/AUD","bids":[{"price":101648.7,"qty":0.00000000},{"price":101643.3,"qty":0.00551300}],"asks":[],"checksum":690402844,"timestamp":"2024-06-01T17:51:39.100750Z"}]}
{"channel":"book","type":"update","data":[{"symbol":"BTC/AUD","bids":[{"price":101650.1,"qty":0.42968527}],"asks":[],"checksum":2275267131,"timestamp":"2024-06-01T17:51:39.102034Z"}]}
{"channel":"book","type":"update","data":[{"symbol":"BTC/AUD","bids":[{"price":101649.8,"qty":0.00000000},{"price":101627.0,"qty":0.00503000}],"asks":[],"checksum":1909590309,"timestamp":"2024-06-01T17:51:39.107792Z"}]}
{"channel":"book","type":"update","data":[{"symbol":"BTC/AUD","bids":[{"price":101650.0,"qty":0.00000000},{"price":101606.4,"qty":0.04191504},{"price":101650.3,"qty":0.00308000}],"asks":[],"checksum":1276421455,"timestamp":"2024-06-01T17:51:39.601955Z"}]}
{"channel":"book","type":"update","data":[{"symbol":"BTC/AUD","bids":[{"price":101649.9,"qty":0.00000000},{"price":101606.4,"qty":0.04191504},{"price":101650.3,"qty":0.03245000}],"asks":[],"checksum":2168491986,"timestamp":"2024-06-01T17:51:39.604748Z"}]}
{"channel":"book","type":"update","data":[{"symbol":"BTC/AUD","bids":[{"price":101650.3,"qty":0.02937000},{"price":101650.4,"qty":0.00308000}],"asks":[],"checksum":2373516344,"timestamp":"2024-06-01T17:51:39.695321Z"}]}
{"channel":"book","type":"update","data":[{"symbol":"BTC/AUD","bids":[{"price":101650.1,"qty":0.37578530},{"price":101650.4,"qty":0.05697981}],"asks":[],"checksum":1630706921,"timestamp":"2024-06-01T17:51:39.695600Z"}]}
{"channel":"book","type":"update","data":[{"symbol":"BTC/AUD","bids":[{"price":101650.4,"qty":0.20697981}],"asks":[],"checksum":1751922250,"timestamp":"2024-06-01T17:51:39.700481Z"}]}
{"channel":"book","type":"update","data":[{"symbol":"BTC/AUD","bids":[{"price":101643.3,"qty":0.00075800},{"price":101650.5,"qty":0.00475500}],"asks":[],"checksum":716052684,"timestamp":"2024-06-01T17:51:39.860353Z"}]}
{"channel":"book","type":"update","data":[{"symbol":"BTC/AUD","bids":[{"price":101649.6,"qty":0.00000000},{"price":101627.0,"qty":0.00503000}],"asks":[],"checksum":3115183214,"timestamp":"2024-06-01T17:51:39.865451Z"}]}
{"channel":"book","type":"update","data":[{"symbol":"BTC/AUD","bids":[{"price":101643.3,"qty":0.00000000},{"price":101606.4,"qty":0.04191504},{"price":101650.5,"qty":0.00551300}],"asks":[],"checksum":743833989,"timestamp":"2024-06-01T17:51:39.871105Z"}]}
{"channel":"book","type":"update","data":[{"symbol":"BTC/AUD","bids":[{"price":101649.1,"qty":0.00000000},{"price":101606.3,"qty":0.05056249}],"asks":[],"checksum":3195289914,"timestamp":"2024-06-01T17:51:39.966733Z"}]}
{"channel":"book","type":"update","data":[{"symbol":"BTC/AUD","bids":[{"price":101650.5,"qty":0.00811684}],"asks":[],"checksum":4225337234,"timestamp":"2024-06-01T17:51:39.967299Z"}]}
{"channel":"book","type":"update","data":[{"symbol":"BTC/AUD","bids":[{"price":101650.6,"qty":0.04717373}],"asks":[],"checksum":1119744896,"timestamp":"2024-06-01T17:51:39.972988Z"}]}
{"channel":"book","type":"update","data":[{"symbol":"BTC/AUD","bids":[{"price":101650.3,"qty":0.00000000},{"price":101606.3,"qty":0.05056249}],"asks":[],"checksum":2914479002,"timestamp":"2024-06-01T17:51:40.107825Z"}]}
{"channel":"book","type":"update","data":[{"symbol":"BTC/AUD","bids":[{"price":101650.2,"qty":0.00000000},{"price":101595.2,"qty":0.00569000}],"asks":[],"checksum":901367468,"timestamp":"2024-06-01T17:51:40.124876Z"}]}
{"channel":"book","type":"update","data":[{"symbol":"BTC/AUD","bids":[{"price":101644.5,"qty":0.02937000}],"asks":[],"checksum":4224514723,"timestamp":"2024-06-01T17:51:40.135263Z"}]}
{"channel":"book","type":"update","data":[{"symbol":"BTC/AUD","bids":[{"price":101627.0,"qty":0.00000000},{"price":101595.2,"qty":0.00569000}],"asks":[],"checksum":352202030,"timestamp":"2024-06-01T17:51:40.176173Z"}]}
{"channel":"book","type":"update","data":[{"symbol":"BTC/AUD","bids":[],"asks":[{"price":101771.1,"qty":0.04717373}],"checksum":159746527,"timestamp":"2024-06-01T17:51:40.178376Z"}]}
{"channel":"book","type":"update","data":[{"symbol":"BTC/AUD","bids":[],"asks":[{"price":101784.7,"qty":0.00000000},{"price":101822.9,"qty":0.05056249}],"checksum":1495099568,"timestamp":"2024-06-01T17:51:40.189095Z"}]}
{"channel":"book","type":"update","data":[{"symbol":"BTC/AUD","bids":[],"asks":[{"price":101787.1,"qty":0.00000000},{"price":101826.0,"qty":0.09768924},{"price":101774.2,"qty":0.00475100}],"checksum":1856701895,"timestamp":"2024-06-01T17:51:40.201363Z"}]}
{"channel":"book","type":"update","data":[{"symbol":"BTC/AUD","bids":[],"asks":[{"price":101786.2,"qty":0.00000000},{"price":101826.0,"qty":0.09768924},{"price":101773.4,"qty":0.00075700}],"checksum":2219748974,"timestamp":"2024-06-01T17:51:40.211113Z"}]}
{"channel":"book","type":"update","data":[{"symbol":"BTC/AUD","bids":[{"price":101644.5,"qty":0.00000000},{"price":101585.0,"qty":0.09768924}],"asks":[],"checksum":3415116193,"timestamp":"2024-06-01T17:51:40.239126Z"}]}
{"channel":"book","type":"update","data":[{"symbol":"BTC/AUD","bids":[{"price":101650.4,"qty":0.15308000},{"price":101650.7,"qty":0.05389965}],"asks":[],"checksum":501196979,"timestamp":"2024-06-01T17:51:40.461368Z"}]}
{"channel":"book","type":"update","data":[{"symbol":"BTC/AUD","bids":[],"asks":[{"price":101771.2,"qty":0.00000000},{"price":101826.0,"qty":0.09768924},{"price":101771.0,"qty":0.05387009}],"checksum":4023433854,"timestamp":"2024-06-01T17:51:40.461540Z"}]}
{"channel":"book","type":"update","data":[{"symbol":"BTC/AUD","bids":[{"price":101650.4,"qty":0.15000000},{"price":101650.8,"qty":0.00308000}],"asks":[],"checksum":1809010850,"timestamp":"2024-06-01T17:51:40.796558Z"}]}
{"channel":"book","type":"update","data":[{"symbol":"BTC/AUD","bids":[{"price":101650.8,"qty":0.15308000}],"asks":[],"checksum":1099289737,"timestamp":"2024-06-01T17:51:40.801966Z"}]}
{"channel":"book","type":"update","data":[{"symbol":"BTC/AUD","bids":[{"price":101650.8,"qty":0.15000000},{"price":101650.9,"qty":0.00308000}],"asks":[],"checksum":1533992016,"timestamp":"2024-06-01T17:51:41.100715Z"}]}
{"channel":"book","type":"update","data":[{"symbol":"BTC/AUD","bids":[{"price":101650.4,"qty":0.00000000},{"price":101606.3,"qty":0.05056249}],"asks":[],"checksum":2158852053,"timestamp":"2024-06-01T17:51:41.106211Z"}]}
{"channel":"book","type":"update","data":[{"symbol":"BTC/AUD","bids":[{"price":101651.0,"qty":0.04717373}],"asks":[],"checksum":1618047533,"timestamp":"2024-06-01T17:51:41.106257Z"}]}
{"channel":"book","type":"update","data":[{"symbol":"BTC/AUD","bids":[{"price":101651.1,"qty":0.15000000}],"asks":[],"checksum":1745331208,"timestamp":"2024-06-01T17:51:41.143447Z"}]}
{"channel":"book","type":"update","data":[{"symbol":"BTC/AUD","bids":[{"price":101650.8,"qty":0.00000000},{"price":101629.8,"qty":0.02937000}],"asks":[],"checksum":3658941650,"timestamp":"2024-06-01T17:51:41.148538Z"}]}
{"channel":"book","type":"update","data":[{"symbol":"BTC/AUD","bids":[{"price":101650.6,"qty":0.00000000},{"price":101606.4,"qty":0.04191504}],"asks":[],"checksum":3894158330,"timestamp":"2024-06-01T17:51:41.149025Z"}]}
{"channel":"book","type":"update","data":[{"symbol":"BTC/AUD","bids":[{"price":101650.7,"qty":0.00000000},{"price":101606.3,"qty":0.05056249},{"price":101651.2,"qty":0.05389950}],"asks":[],"checksum":2519779605,"timestamp":"2024-06-01T17:51:41.197168Z"}]}
{"channel":"book","type":"update","data":[{"symbol":"BTC/AUD","bids":[{"price":101650.9,"qty":0.00000000},{"price":101606.3,"qty":0.05056249},{"price":101651.3,"qty":0.00308000}],"asks":[],"checksum":3844620296,"timestamp":"2024-06-01T17:51:41.407379Z"}]}
{"channel":"book","type":"update","data":[{"symbol":"BTC/AUD","bids":[{"price":101651.2,"qty":0.00000000},{"price":101606.3,"qty":0.05056249},{"price":101651.4,"qty":0.05389939}],"asks":[],"checksum":704526158,"timestamp":"2024-06-01T17:51:41.900748Z"}]}
{"channel":"book","type":"update","data":[{"symbol":"BTC/AUD","bids":[{"price":101651.5,"qty":0.15000000}],"asks":[],"checksum":3416101471,"timestamp":"2024-06-01T17:51:41.906010Z"}]}
{"channel":"book","type":"update","data":[{"symbol":"BTC/AUD","bids":[{"price":101651.1,"qty":0.00000000},{"price":101606.4,"qty":0.04191504}],"asks":[],"checksum":4196660650,"timestamp":"2024-06-01T17:51:42.143081Z"}]}
{"channel":"book","type":"update","data":[{"symbol":"BTC/AUD","bids":[{"price":101651.6,"qty":0.04717373}],"asks":[],"checksum":3997399027,"timestamp":"2024-06-01T17:51:42.148449Z"}]}
{"channel":"book","type":"update","data":[{"symbol":"BTC/AUD","bids":[{"price":101650.1,"qty":0.00000000},{"price":101606.4,"qty":0.04191504}],"asks":[],"checksum":3124427521,"timestamp":"2024-06-01T17:51:42.167433Z"}]}
{"channel":"book","type":"update","data":[{"symbol":"BTC/AUD","bids":[{"price":101651.6,"qty":0.39414895}],"asks":[],"checksum":2491984557,"timestamp":"2024-06-01T17:51:42.168650Z"}]}
{"channel":"book","type":"update","data":[{"symbol":"BTC/AUD","bids":[{"price":101629.8,"qty":0.00000000},{"price":101606.3,"qty":0.05056249},{"price":101606.5,"qty":0.02937000}],"asks":[],"checksum":3380178154,"timestamp":"2024-06-01T17:51:42.170158Z"}]}
{"channel":"book","type":"update","data":[{"symbol":"BTC/AUD","bids":[{"price":101651.0,"qty":0.00000000},{"price":101606.3,"qty":0.05056249}],"asks":[],"checksum":2948192963,"timestamp":"2024-06-01T17:51:42.178299Z"}]}
{"channel":"book","type":"update","data":[{"symbol":"BTC/AUD","bids":[{"price":101651.5,"qty":0.00000000},{"price":101595.2,"qty":0.00569000}],"asks":[],"checksum":485718303,"timestamp":"2024-06-01T17:51:42.183176Z"}]}
{"channel":"book","type":"update","data":[{"symbol":"BTC/AUD","bids":[{"price":101606.4,"qty":0.00000000},{"price":101585.0,"qty":0.09768924}],"asks":[],"checksum":1119445323,"timestamp":"2024-06-01T17:51:42.395511Z"}]}
{"channel":"book","type":"update","data":[{"symbol":"BTC/AUD","bids":[{"price":101595.3,"qty":0.04191962}],"asks":[],"checksum":2521168196,"timestamp":"2024-06-01T17:51:42.395547Z"}]}
{"channel":"book","type":"update","data":[{"symbol":"BTC/AUD","bids":[{"price":101651.4,"qty":0.00000000},{"price":101585.0,"qty":0.09768924},{"price":101651.7,"qty":0.05389924}],"asks":[],"checksum":4205444589,"timestamp":"2024-06-01T17:51:42.648028Z"}]}
{"channel":"book","type":"update","data":[{"symbol":"BTC/AUD","bids":[{"price":101651.3,"qty":0.00000000},{"price":101585.0,"qty":0.09768924},{"price":101651.8,"qty":0.00308000}],"asks":[],"checksum":882453327,"timestamp":"2024-06-01T17:51:42.682806Z"}]}
{"channel":"book","type":"update","data":[{"symbol":"BTC/AUD","bids":[{"price":101650.5,"qty":0.00551300}],"asks":[],"checksum":2059804725,"timestamp":"2024-06-01T17:51:42.947146Z"}]}
{"channel":"book","type":"update","data":[{"symbol":"BTC/AUD","bids":[{"price":101651.9,"qty":0.00231560}],"asks":[],"checksum":4208175312,"timestamp":"2024-06-01T17:51:42.948198Z"}]}
{"channel":"book","type":"update","data":[{"symbol":"BTC/AUD","bids":[{"price":101651.9,"qty":0.04948933}],"asks":[],"checksum":2175986658,"timestamp":"2024-06-01T17:51:42.953831Z"}]}
{"channel":"book","type":"update","data":[{"symbol":"BTC/AUD","bids":[],"asks":[{"price":101770.9,"qty":0.04717373}],"checksum":456253004,"timestamp":"2024-06-01T17:51:42.953949Z"}]}
{"channel":"book","type":"update","data":[{"symbol":"BTC/AUD","bids":[{"price":101651.8,"qty":0.00000000},{"price":101595.2,"qty":0.00569000},{"price":101652.0,"qty":0.00308000}],"asks":[],"checksum":4197465102,"timestamp":"2024-06-01T17:51:42.988291Z"}]}
{"channel":"book","type":"update","data":[{"symbol":"BTC/AUD","bids":[],"asks":[{"price":101771.1,"qty":0.00000000},{"price":101822.9,"qty":0.05056249}],"checksum":760901100,"timestamp":"2024-06-01T17:51:42.994827Z"}]}
{"channel":"book","type":"update","data":[{"symbol":"BTC/AUD","bids":[{"price":101651.6,"qty":0.34697522}],"asks":[],"checksum":963537063,"timestamp":"2024-06-01T17:51:42.995462Z"}]}
{"channel":"book","type":"update","data":[{"symbol":"BTC/AUD","bids":[{"price":101647.9,"qty":0.00000000},{"price":101595.2,"qty":0.00569000},{"price":101651.9,"qty":0.05084233}],"asks":[],"checksum":1773265269,"timestamp":"2024-06-01T17:51:43.114882Z"}]}
{"channel":"book","type":"update","data":[{"symbol":"BTC/AUD","bids":[],"asks":[{"price":101818.8,"qty":0.02937000}],"checksum":1014193161,"timestamp":"2024-06-01T17:51:43.185177Z"}]}
{"channel":"book","type":"update","data":[{"symbol":"BTC/AUD","bids":[{"price":101606.5,"qty":0.00000000},{"price":101585.0,"qty":0.09768924},{"price":101606.4,"qty":0.02937000}],"asks":[],"checksum":3005969178,"timestamp":"2024-06-01T17:51:43.188434Z"}]}
{"channel":"book","type":"update","data":[{"symbol":"BTC/AUD","bids":[],"asks":[{"price":101818.7,"qty":0.00395872}],"checksum":189814640,"timestamp":"2024-06-01T17:51:43.190165Z"}]}
{"channel":"book","type":"update","data":[{"symbol":"BTC/AUD","bids":[{"price":101651.7,"qty":0.00000000},{"price":101585.0,"qty":0.09768924},{"price":101652.1,"qty":0.05389654}],"asks":[],"checksum":2351229469,"timestamp":"2024-06-01T17:51:43.338221Z"}]}
{"channel":"book","type":"update","data":[{"symbol":"BTC/AUD","bids":[],"asks":[{"price":101771.0,"qty":0.00000000},{"price":101822.9,"qty":0.05056249},{"price":101770.8,"qty":0.05387025}],"checksum":484938557,"timestamp":"2024-06-01T17:51:43.338452Z"}]}
{"channel":"book","type":"update","data":[{"symbol":"BTC/AUD","bids":[{"price":101652.0,"qty":0.00000000},{"price":101585.0,"qty":0.09768924},{"price":101652.2,"qty":0.00308000}],"asks":[],"checksum":2742849280,"timestamp":"2024-06-01T17:51:43.354803Z"}]}
{"channel":"book","type":"update","data":[{"symbol":"BTC/AUD","bids":[],"asks":[{"price":101770.9,"qty":0.00000000},{"price":101822.9,"qty":0.05056249}],"checksum":3889493533,"timestamp":"2024-06-01T17:51:43.682844Z"}]}
{"channel":"book","type":"update","data":[{"symbol":"BTC/AUD","bids":[{"price":101652.2,"qty":0.15308000}],"asks":[],"checksum":947659799,"timestamp":"2024-06-01T17:51:43.690163Z"}]}
{"channel":"book","type":"update","data":[{"symbol":"BTC/AUD","bids":[],"asks":[{"price":101822.8,"qty":0.05000000}],"checksum":3204646874,"timestamp":"2024-06-01T17:51:43.753716Z"}]}
{"channel":"book","type":"update","data":[{"symbol":"BTC/AUD","bids":[],"asks":[{"price":101770.8,"qty":0.00000000},{"price":101822.9,"qty":0.05056249},{"price":101771.2,"qty":0.05387025}],"checksum":736586476,"timestamp":"2024-06-01T17:51:43.756163Z"}]}
{"channel":"book","type":"update","data":[{"symbol":"BTC/AUD","bids":[{"price":101652.2,"qty":0.15000000},{"price":101652.3,"qty":0.00308000}],"asks":[],"checksum":410616857,"timestamp":"2024-06-01T17:51:43.783814Z"}]}
{"channel":"book","type":"update","data":[{"symbol":"BTC/AUD","bids":[],"asks":[{"price":101822.8,"qty":0.00000000},{"price":101822.9,"qty":0.05056249}],"checksum":2668013524,"timestamp":"2024-06-01T17:51:43.807697Z"}]}
{"channel":"book","type":"update","data":[{"symbol":"BTC/AUD","bids":[],"asks":[{"price":101774.2,"qty":0.00000000},{"price":101826.0,"qty":0.09768924},{"price":101788.1,"qty":0.00475100}],"checksum":700550244,"timestamp":"2024-06-01T17:51:43.816540Z"}]}
{"channel":"book","type":"update","data":[{"symbol":"BTC/AUD","bids":[{"price":101627.6,"qty":0.00639000}],"asks":[],"checksum":3638714411,"timestamp":"2024-06-01T17:51:43.826608Z"}]}
{"channel":"book","type":"update","data":[{"symbol":"BTC/AUD","bids":[{"price":101606.4,"qty":0.00000000},{"price":101595.3,"qty":0.04191962},{"price":101627.7,"qty":0.02937000}],"asks":[],"checksum":3476403329,"timestamp":"2024-06-01T17:51:43.829383Z"}]}
{"channel":"book","type":"update","data":[{"symbol":"BTC/AUD","bids":[],"asks":[{"price":101773.4,"qty":0.00000000},{"price":101826.0,"qty":0.09768924},{"price":101787.3,"qty":0.00075700}],"checksum":4198884767,"timestamp":"2024-06-01T17:51:43.855407Z"}]}
{"channel":"book","type":"update","data":[{"symbol":"BTC/AUD","bids":[],"asks":[{"price":101818.9,"qty":0.00000000},{"price":101826.0,"qty":0.09768924}],"checksum":2283069139,"timestamp":"2024-06-01T17:51:43.891784Z"}]}
{"channel":"book","type":"update","data":[{"symbol":"BTC/AUD","bids":[],"asks":[{"price":101818.6,"qty":0.35112897}],"checksum":3024288000,"timestamp":"2024-06-01T17:51:43.893779Z"}]}
{"channel":"book","type":"update","data":[{"symbol":"BTC/AUD","bids":[],"asks":[{"price":101818.8,"qty":0.00000000},{"price":101826.0,"qty":0.09768924},{"price":101822.8,"qty":0.02937000}],"checksum":273696436,"timestamp":"2024-06-01T17:51:43.895421Z"}]}
{"channel":"book","type":"update","data":[{"symbol":"BTC/AUD","bids":[{"price":101652.1,"qty":0.00000000},{"price":101595.3,"qty":0.04191962},{"price":101652.4,"qty":0.05389637}],"asks":[],"checksum":2569379006,"timestamp":"2024-06-01T17:51:44.027708Z"}]}
{"channel":"book","type":"update","data":[{"symbol":"BTC/AUD","bids":[{"price":101652.5,"qty":0.15000000}],"asks":[],"checksum":3982463920,"timestamp":"2024-06-01T17:51:44.033475Z"}]}
{"channel":"book","type":"update","data":[{"symbol":"BTC/AUD","bids":[{"price":101652.5,"qty":0.19717373}],"asks":[],"checksum":1297976601,"timestamp":"2024-06-01T17:51:44.033655Z"}]}
{"channel":"book","type":"update","data":[{"symbol":"BTC/AUD","bids":[{"price":101652.2,"qty":0.00000000},{"price":101606.3,"qty":0.05056249}],"asks":[],"checksum":2183587586,"timestamp":"2024-06-01T17:51:44.143030Z"}]}
{"channel":"book","type":"update","data":[{"symbol":"BTC/AUD","bids":[{"price":101651.9,"qty":0.00366860}],"asks":[],"checksum":2205092980,"timestamp":"2024-06-01T17:51:44.147728Z"}]}
{"channel":"book","type":"update","data":[{"symbol":"BTC/AUD","bids":[{"price":101652.3,"qty":0.00000000},{"price":101595.3,"qty":0.04191962},{"price":101652.6,"qty":0.00308000}],"asks":[],"checksum":4201069763,"timestamp":"2024-06-01T17:51:44.307419Z"}]}
{"channel":"book","type":"update","data":[{"symbol":"BTC/AUD","bids":[{"price":101652.4,"qty":0.00000000},{"price":101595.3,"qty":0.04191962},{"price":101652.7,"qty":0.05389641}],"asks":[],"checksum":3504846191,"timestamp":"2024-06-01T17:51:44.787021Z"}]}
{"channel":"book","type":"update","data":[{"symbol":"BTC/AUD","bids":[],"asks":[{"price":101822.8,"qty":0.00000000},{"price":101826.0,"qty":0.09768924},{"price":101818.5,"qty":0.02937000}],"checksum":2762123186,"timestamp":"2024-06-01T17:51:44.789726Z"}]}
{"channel":"book","type":"update","data":[{"symbol":"BTC/AUD","bids":[{"price":101652.8,"qty":0.15000000}],"asks":[],"checksum":1470253405,"timestamp":"2024-06-01T17:51:44.792269Z"}]}
{"channel":"book","type":"update","data":[{"symbol":"BTC/AUD","bids":[{"price":101652.6,"qty":0.00000000},{"price":101606.3,"qty":0.05056249},{"price":101652.8,"qty":0.15308000}],"asks":[],"checksum":1792621021,"timestamp":"2024-06-01T17:51:44.795803Z"}]}
{"channel":"book","type":"update","data":[{"symbol":"BTC/AUD","bids":[{"price":101652.5,"qty":0.04717373}],"asks":[],"checksum":65715535,"timestamp":"2024-06-01T17:51:45.144681Z"}]}
{"channel":"book","type":"update","data":[{"symbol":"BTC/AUD","bids":[{"price":101652.9,"qty":0.04717373}],"asks":[],"checksum":2382437893,"timestamp":"2024-06-01T17:51:45.150572Z"}]}
{"channel":"book","type":"update","data":[{"symbol":"BTC/AUD","bids":[{"price":101652.8,"qty":0.15000000},{"price":101653.0,"qty":0.00308000}],"asks":[],"checksum":2046816805,"timestamp":"2024-06-01T17:51:45.161986Z"}]}
{"channel":"book","type":"update","data":[{"symbol":"BTC/AUD","bids":[{"price":101651.6,"qty":0.00000000},{"price":101627.6,"qty":0.00639000}],"asks":[],"checksum":1867011460,"timestamp":"2024-06-01T17:51:45.165718Z"}]}
{"channel":"book","type":"update","data":[{"symbol":"BTC/AUD","bids":[{"price":101652.9,"qty":0.45178316}],"asks":[],"checksum":4136765728,"timestamp":"2024-06-01T17:51:45.166614Z"}]}
{"channel":"book","type":"update","data":[{"symbol":"BTC/AUD","bids":[{"price":101652.5,"qty":0.00000000},{"price":101606.3,"qty":0.05056249}],"asks":[],"checksum":230062209,"timestamp":"2024-06-01T17:51:45.178997Z"}]}
{"channel":"book","type":"update","data":[{"symbol":"BTC/AUD","bids":[{"price":101627.7,"qty":0.00000000},{"price":101595.3,"qty":0.04191962},{"price":101648.9,"qty":0.02937000}],"asks":[],"checksum":191307090,"timestamp":"2024-06-01T17:51:45.234748Z"}]}
{"channel":"book","type":"update","data":[{"symbol":"BTC/AUD","bids":[],"asks":[{"price":101818.7,"qty":0.00000000},{"price":101826.0,"qty":0.09768924}],"checksum":1025057698,"timestamp":"2024-06-01T17:51:45.276981Z"}]}
{"channel":"book","type":"update","data":[{"symbol":"BTC/AUD","bids":[],"asks":[{"price":101818.4,"qty":0.00253418}],"checksum":645590177,"timestamp":"2024-06-01T17:51:45.280296Z"}]}
{"channel":"book","type":"update","data":[{"symbol":"BTC/AUD","bids":[{"price":101652.7,"qty":0.00000000},{"price":101595.3,"qty":0.04191962},{"price":101653.1,"qty":0.05389618}],"asks":[],"checksum":2941523780,"timestamp":"2024-06-01T17:51:45.491102Z"}]}
{"channel":"book","type":"update","data":[{"symbol":"BTC/AUD","bids":[{"price":101653.0,"qty":0.00000000},{"price":101595.3,"qty":0.04191962},{"price":101653.2,"qty":0.00308000}],"asks":[],"checksum":1951449545,"timestamp":"2024-06-01T17:51:45.650191Z"}]}
{"channel":"book","type":"update","data":[{"symbol":"BTC/AUD","bids":[{"price":101648.9,"qty":0.00000000},{"price":101595.3,"qty":0.04191962},{"price":101653.2,"qty":0.03245000}],"asks":[],"checksum":3828733707,"timestamp":"2024-06-01T17:51:45.793934Z"}]}
{"channel":"book","type":"update","data":[{"symbol":"BTC/AUD","bids":[{"price":101653.3,"qty":0.15000000}],"asks":[],"checksum":1171106506,"timestamp":"2024-06-01T17:51:45.799194Z"}]}
{"channel":"book","type":"update","data":[{"symbol":"BTC/AUD","bids":[{"price":101651.9,"qty":0.00135300}],"asks":[],"checksum":3856665888,"timestamp":"2024-06-01T17:51:45.942237Z"}]}
{"channel":"book","type":"update","data":[{"symbol":"BTC/AUD","bids":[{"price":101653.3,"qty":0.15275690}],"asks":[],"checksum":1987287778,"timestamp":"2024-06-01T17:51:45.943491Z"}]}
{"channel":"book","type":"update","data":[{"symbol":"BTC/AUD","bids":[],"asks":[{"price":101786.5,"qty":0.04717373}],"checksum":3155537062,"timestamp":"2024-06-01T17:51:45.948518Z"}]}
{"channel":"book","type":"update","data":[{"symbol":"BTC/AUD","bids":[{"price":101653.4,"qty":0.04717373}],"asks":[],"checksum":1767641854,"timestamp":"2024-06-01T17:51:45.948667Z"}]}
{"channel":"book","type":"update","data":[{"symbol":"BTC/AUD","bids":[{"price":101652.8,"qty":0.00000000},{"price":101606.3,"qty":0.05056249}],"asks":[],"checksum":1555516441,"timestamp":"2024-06-01T17:51:45.949149Z"}]}
{"channel":"book","type":"update","data":[{"symbol":"BTC/AUD","bids":[],"asks":[{"price":101788.1,"qty":0.00000000},{"price":101822.9,"qty":0.05056249},{"price":101777.2,"qty":0.00475100}],"checksum":29567923,"timestamp":"2024-06-01T17:51:46.069997Z"}]}
{"channel":"book","type":"update","data":[{"symbol":"BTC/AUD","bids":[{"price":101652.9,"qty":0.40460943}],"asks":[],"checksum":693323800,"timestamp":"2024-06-01T17:51:46.074845Z"}]}
{"channel":"book","type":"update","data":[{"symbol":"BTC/AUD","bids":[],"asks":[{"price":101787.3,"qty":0.00000000},{"price":101822.9,"qty":0.05056249},{"price":101776.3,"qty":0.00075700}],"checksum":815069201,"timestamp":"2024-06-01T17:51:46.093139Z"}]}
{"channel":"book","type":"update","data":[{"symbol":"BTC/AUD","bids":[{"price":101653.1,"qty":0.00000000},{"price":101595.3,"qty":0.04191962},{"price":101653.5,"qty":0.05389597}],"asks":[],"checksum":3235951190,"timestamp":"2024-06-01T17:51:46.161169Z"}]}
{"channel":"book","type":"update","data":[{"symbol":"BTC/AUD","bids":[{"price":101653.2,"qty":0.02937000},{"price":101653.6,"qty":0.00308000}],"asks":[],"checksum":3269898615,"timestamp":"2024-06-01T17:51:46.171185Z"}]}
{"channel":"book","type":"update","data":[{"symbol":"BTC/AUD","bids":[{"price":101656.6,"qty":0.05056249}],"asks":[],"checksum":886046386,"timestamp":"2024-06-01T17:51:46.311471Z"}]}
{"channel":"book","type":"update","data":[{"symbol":"BTC/AUD","bids":[{"price":101653.2,"qty":0.00000000},{"price":101627.6,"qty":0.00639000},{"price":101653.6,"qty":0.03245000}],"asks":[],"checksum":1885963201,"timestamp":"2024-06-01T17:51:46.314681Z"}]}
{"channel":"book","type":"update","data":[{"symbol":"BTC/AUD","bids":[{"price":101653.6,"qty":0.02937000},{"price":101656.7,"qty":0.00308000}],"asks":[],"checksum":4154348318,"timestamp":"2024-06-01T17:51:46.324917Z"}]}
{"channel":"book","type":"update","data":[{"symbol":"BTC/AUD","bids":[],"asks":[{"price":101818.6,"qty":0.00000000},{"price":101822.9,"qty":0.05056249}],"checksum":2281927177,"timestamp":"2024-06-01T17:51:46.654070Z"}]}
{"channel":"book","type":"update","data":[{"symbol":"BTC/AUD","bids":[],"asks":[{"price":101818.3,"qty":0.28222312}],"checksum":2939194530,"timestamp":"2024-06-01T17:51:46.656894Z"}]}
{"channel":"book","type":"update","data":[{"symbol":"BTC/AUD","bids":[],"asks":[{"price":101818.5,"qty":0.00000000},{"price":101822.8,"qty":0.30519116},{"price":101822.8,"qty":0.33456116}],"checksum":3129846543,"timestamp":"2024-06-01T17:51:46.659723Z"}]}
{"channel":"book","type":"update","data":[{"symbol":"BTC/AUD","bids":[{"price":101653.5,"qty":0.00000000},{"price":101627.6,"qty":0.00639000},{"price":101656.8,"qty":0.05389435}],"asks":[],"checksum":4244313774,"timestamp":"2024-06-01T17:51:46.858736Z"}]}
{"channel":"book","type":"update","data":[{"symbol":"BTC/AUD","bids":[{"price":101656.9,"qty":0.15000000}],"asks":[],"checksum":3566780899,"timestamp":"2024-06-01T17:51:46.865371Z"}]}
{"channel":"book","type":"update","data":[{"symbol":"BTC/AUD","bids":[{"price":101656.7,"qty":0.00000000},{"price":101648.8,"qty":0.23809552},{"price":101657.0,"qty":0.00308000}],"asks":[],"checksum":4118448103,"timestamp":"2024-06-01T17:51:46.873808Z"}]}
{"channel":"book","type":"update","data":[{"symbol":"BTC/AUD","bids":[],"asks":[{"price":101777.2,"qty":0.00000000},{"price":101822.9,"qty":0.05056249},{"price":101784.4,"qty":0.00475100}],"checksum":2735159700,"timestamp":"2024-06-01T17:51:47.013511Z"}]}
{"channel":"book","type":"update","data":[{"symbol":"BTC/AUD","bids":[{"price":101657.1,"qty":0.04717373}],"asks":[],"checksum":1483606363,"timestamp":"2024-06-01T17:51:47.018599Z"}]}
{"channel":"book","type":"update","data":[{"symbol":"BTC/AUD","bids":[{"price":101653.3,"qty":0.00275690}],"asks":[],"checksum":3784029870,"timestamp":"2024-06-01T17:51:47.018891Z"}]}
{"channel":"book","type":"update","data":[{"symbol":"BTC/AUD","bids":[],"asks":[{"price":101776.3,"qty":0.00000000},{"price":101822.9,"qty":0.05056249},{"price":101783.5,"qty":0.00075700}],"checksum":118140260,"timestamp":"2024-06-01T17:51:47.025719Z"}]}
{"channel":"book","type":"update","data":[{"symbol":"BTC/AUD","bids":[{"price":101657.2,"qty":0.15000000}],"asks":[],"checksum":3978946930,"timestamp":"2024-06-01T17:51:47.143736Z"}]}
{"channel":"book","type":"update","data":[{"symbol":"BTC/AUD","bids":[{"price":101656.9,"qty":0.00000000},{"price":101651.9,"qty":0.00135300}],"asks":[],"checksum":926505499,"timestamp":"2024-06-01T17:51:47.148433Z"}]}
{"channel":"book","type":"update","data":[{"symbol":"BTC/AUD","bids":[{"price":101653.4,"qty":0.00000000},{"price":101650.5,"qty":0.00551300}],"asks":[],"checksum":3574519784,"timestamp":"2024-06-01T17:51:47.152993Z"}]}
{"channel":"book","type":"update","data":[{"symbol":"BTC/AUD","bids":[{"price":101653.6,"qty":0.00000000},{"price":101648.8,"qty":0.23809552}],"asks":[],"checksum":1732813799,"timestamp":"2024-06-01T17:51:47.210605Z"}]}
{"channel":"book","type":"update","data":[{"symbol":"BTC/AUD","bids":[],"asks":[{"price":101822.8,"qty":0.30519116},{"price":101818.2,"qty":0.02937000}],"checksum":2128803558,"timestamp":"2024-06-01T17:51:47.210619Z"}]}
{"channel":"book","type":"update","data":[{"symbol":"BTC/AUD","bids":[],"asks":[{"price":101818.4,"qty":0.00000000},{"price":101822.8,"qty":0.30519116}],"checksum":864808782,"timestamp":"2024-06-01T17:51:47.415418Z"}]}
{"channel":"book","type":"update","data":[{"symbol":"BTC/AUD","bids":[],"asks":[{"price":101818.2,"qty":0.03230999}],"checksum":960182419,"timestamp":"2024-06-01T17:51:47.418049Z"}]}
{"channel":"book","type":"update","data":[{"symbol":"BTC/AUD","bids":[{"price":101657.0,"qty":0.00000000},{"price":101627.6,"qty":0.00639000},{"price":101657.3,"qty":0.00308000}],"asks":[],"checksum":1517551338,"timestamp":"2024-06-01T17:51:47.425865Z"}]}
{"channel":"book","type":"update","data":[{"symbol":"BTC/AUD","bids":[{"price":101656.8,"qty":0.00000000},{"price":101627.6,"qty":0.00639000},{"price":101657.4,"qty":0.05389404}],"asks":[],"checksum":3115943915,"timestamp":"2024-06-01T17:51:47.518147Z"}]}
{"channel":"book","type":"update","data":[{"symbol":"BTC/AUD","bids":[{"price":101657.3,"qty":0.00000000},{"price":101627.6,"qty":0.00639000},{"price":101657.5,"qty":0.00308000}],"asks":[],"checksum":1861795172,"timestamp":"2024-06-01T17:51:47.551948Z"}]}
{"channel":"book","type":"update","data":[{"symbol":"BTC/AUD","bids":[{"price":101657.5,"qty":0.15308000}],"asks":[],"checksum":717894194,"timestamp":"2024-06-01T17:51:48.144566Z"}]}
{"channel":"book","type":"update","data":[{"symbol":"BTC/AUD","bids":[{"price":101657.6,"qty":0.04717373}],"asks":[],"checksum":1891380402,"timestamp":"2024-06-01T17:51:48.149713Z"}]}
{"channel":"book","type":"update","data":[{"symbol":"BTC/AUD","bids":[{"price":101657.2,"qty":0.00000000},{"price":101648.8,"qty":0.23809552}],"asks":[],"checksum":2708832034,"timestamp":"2024-06-01T17:51:48.150059Z"}]}
{"channel":"book","type":"update","data":[{"symbol":"BTC/AUD","bids":[{"price":101657.5,"qty":0.15000000},{"price":101657.7,"qty":0.00308000}],"asks":[],"checksum":3313042253,"timestamp":"2024-06-01T17:51:48.157763Z"}]}
{"channel":"book","type":"update","data":[{"symbol":"BTC/AUD","bids":[{"price":101657.1,"qty":0.00000000},{"price":101648.8,"qty":0.23809552}],"asks":[],"checksum":585519814,"timestamp":"2024-06-01T17:51:48.179055Z"}]}
{"channel":"book","type":"update","data":[{"symbol":"BTC/AUD","bids":[{"price":101657.4,"qty":0.00000000},{"price":101627.7,"qty":0.02937000},{"price":101657.7,"qty":0.05697388}],"asks":[],"checksum":4170668461,"timestamp":"2024-06-01T17:51:48.191171Z"}]}
{"channel":"book","type":"update","data":[{"symbol":"BTC/AUD","bids":[{"price":101657.7,"qty":0.05389388},{"price":101657.8,"qty":0.00308000}],"asks":[],"checksum":1755133088,"timestamp":"2024-06-01T17:51:48.220806Z"}]}
{"channel":"book","type":"update","data":[{"symbol":"BTC/AUD","bids":[{"price":101652.9,"qty":0.00000000},{"price":101627.7,"qty":0.02937000}],"asks":[],"checksum":1647461338,"timestamp":"2024-06-01T17:51:48.228601Z"}]}
{"channel":"book","type":"update","data":[{"symbol":"BTC/AUD","bids":[{"price":101657.6,"qty":0.39409244}],"asks":[],"checksum":4275813920,"timestamp":"2024-06-01T17:51:48.230259Z"}]}
{"channel":"book","type":"update","data":[{"symbol":"BTC/AUD","bids":[{"price":101650.5,"qty":0.00075800},{"price":101657.7,"qty":0.05864888}],"asks":[],"checksum":2823761743,"timestamp":"2024-06-01T17:51:48.315162Z"}]}
{"channel":"book","type":"update","data":[{"symbol":"BTC/AUD","bids":[],"asks":[{"price":101784.4,"qty":0.00000000},{"price":101822.9,"qty":0.05056249},{"price":101775.2,"qty":0.00475100}],"checksum":2699912905,"timestamp":"2024-06-01T17:51:48.321816Z"}]}
{"channel":"book","type":"update","data":[{"symbol":"BTC/AUD","bids":[{"price":101650.5,"qty":0.00000000},{"price":101627.6,"qty":0.00639000},{"price":101657.7,"qty":0.05940588}],"asks":[],"checksum":1940724593,"timestamp":"2024-06-01T17:51:48.328096Z"}]}
{"channel":"book","type":"update","data":[{"symbol":"BTC/AUD","bids":[],"asks":[{"price":101783.5,"qty":0.00000000},{"price":101822.9,"qty":0.05056249},{"price":101774.3,"qty":0.00075700}],"checksum":2836274541,"timestamp":"2024-06-01T17:51:48.336244Z"}]}
{"channel":"book","type":"update","data":[{"symbol":"BTC/AUD","bids":[],"asks":[{"price":101775.2,"qty":0.00000000},{"price":101822.9,"qty":0.05056249},{"price":101784.5,"qty":0.00475100}],"checksum":476279567,"timestamp":"2024-06-01T17:51:48.673600Z"}]}
{"channel":"book","type":"update","data":[{"symbol":"BTC/AUD","bids":[],"asks":[{"price":101774.3,"qty":0.00000000},{"price":101822.9,"qty":0.05056249},{"price":101783.6,"qty":0.00075700}],"checksum":4256324975,"timestamp":"2024-06-01T17:51:48.683782Z"}]}
{"channel":"book","type":"update","data":[{"symbol":"BTC/AUD","bids":[{"price":101657.7,"qty":0.00551200},{"price":101657.9,"qty":0.05388878}],"asks":[],"checksum":1252304863,"timestamp":"2024-06-01T17:51:48.832111Z"}]}
{"channel":"book","type":"update","data":[{"symbol":"BTC/AUD","bids":[{"price":101658.0,"qty":0.15000000}],"asks":[],"checksum":2496741726,"timestamp":"2024-06-01T17:51:48.837254Z"}]}
{"channel":"book","type":"update","data":[{"symbol":"BTC/AUD","bids":[{"price":101653.3,"qty":0.00000000},{"price":101627.7,"qty":0.02937000}],"asks":[],"checksum":372158131,"timestamp":"2024-06-01T17:51:48.840665Z"}]}
{"channel":"book","type":"update","data":[{"symbol":"BTC/AUD","bids":[{"price":101657.9,"qty":0.05595173}],"asks":[],"checksum":2611497602,"timestamp":"2024-06-01T17:51:48.842210Z"}]}
{"channel":"book","type":"update","data":[{"symbol":"BTC/AUD","bids":[{"price":101657.8,"qty":0.00000000},{"price":101627.6,"qty":0.00639000},{"price":101658.1,"qty":0.00308000}],"asks":[],"checksum":4161355942,"timestamp":"2024-06-01T17:51:48.859181Z"}]}
{"channel":"book","type":"update","data":[{"symbol":"BTC/AUD","bids":[{"price":101651.9,"qty":0.00000000},{"price":101627.6,"qty":0.00639000},{"price":101658.1,"qty":0.00443300}],"asks":[],"checksum":1611607805,"timestamp":"2024-06-01T17:51:49.009445Z"}]}
{"channel":"book","type":"update","data":[{"symbol":"BTC/AUD","bids":[{"price":101658.2,"qty":0.04717373}],"asks":[],"checksum":616055465,"timestamp":"2024-06-01T17:51:49.014768Z"}]}
{"channel":"book","type":"update","data":[{"symbol":"BTC/AUD","bids":[{"price":101657.5,"qty":0.00000000},{"price":101627.6,"qty":0.00639000}],"asks":[],"checksum":3268209874,"timestamp":"2024-06-01T17:51:49.015350Z"}]}
{"channel":"book","type":"update","data":[{"symbol":"BTC/AUD","bids":[{"price":101658.1,"qty":0.00135300},{"price":101658.3,"qty":0.00308000}],"asks":[],"checksum":2929258319,"timestamp":"2024-06-01T17:51:49.043360Z"}]}
{"channel":"book","type":"update","data":[{"symbol":"BTC/AUD","bids":[{"price":101657.6,"qty":0.34691871}],"asks":[],"checksum":2492105284,"timestamp":"2024-06-01T17:51:49.048288Z"}]}
{"channel":"book","type":"update","data":[{"symbol":"BTC/AUD","bids":[{"price":101658.4,"qty":0.04717373}],"asks":[],"checksum":3674104506,"timestamp":"2024-06-01T17:51:49.178074Z"}]}
{"channel":"book","type":"update","data":[{"symbol":"BTC/AUD","bids":[{"price":101658.2,"qty":0.00000000},{"price":101627.7,"qty":0.02937000}],"asks":[],"checksum":2732842721,"timestamp":"2024-06-01T17:51:49.182729Z"}]}
{"channel":"book","type":"update","data":[{"symbol":"BTC/AUD","bids":[],"asks":[{"price":101822.8,"qty":0.00000000},{"price":101822.9,"qty":0.05056249}],"checksum":1090732242,"timestamp":"2024-06-01T17:51:49.412751Z"}]}
{"channel":"book","type":"update","data":[{"symbol":"BTC/AUD","bids":[],"asks":[{"price":101818.3,"qty":0.00000000},{"price":101826.0,"qty":0.09768924}],"checksum":2060617433,"timestamp":"2024-06-01T17:51:49.412911Z"}]}
{"channel":"book","type":"update","data":[{"symbol":"BTC/AUD","bids":[],"asks":[{"price":101818.1,"qty":0.16738190}],"checksum":2765802158,"timestamp":"2024-06-01T17:51:49.416432Z"}]}
{"channel":"book","type":"update","data":[{"symbol":"BTC/AUD","bids":[],"asks":[{"price":101822.8,"qty":0.28222207}],"checksum":324206406,"timestamp":"2024-06-01T17:51:49.416471Z"}]}
{"channel":"book","type":"update","data":[{"symbol":"BTC/AUD","bids":[],"asks":[{"price":101818.2,"qty":0.00293999},{"price":101822.8,"qty":0.31159207}],"checksum":1998023396,"timestamp":"2024-06-01T17:51:49.416981Z"}]}
{"channel":"book","type":"update","data":[{"symbol":"BTC/AUD","bids":[{"price":101657.9,"qty":0.00206295},{"price":101658.5,"qty":0.05388795}],"asks":[],"checksum":3114443048,"timestamp":"2024-06-01T17:51:49.437755Z"}]}
{"channel":"book","type":"update","data":[{"symbol":"BTC/AUD","bids":[],"asks":[{"price":101773.0,"qty":0.00000000},{"price":101822.9,"qty":0.05056249}],"checksum":2976579446,"timestamp":"2024-06-01T17:51:49.649958Z"}]}
{"channel":"book","type":"update","data":[{"symbol":"BTC/AUD","bids":[],"asks":[{"price":101786.5,"qty":0.00000000},{"price":101826.0,"qty":0.09768924}],"checksum":1647462608,"timestamp":"2024-06-01T17:51:49.680032Z"}]}
{"channel":"book","type":"update","data":[{"symbol":"BTC/AUD","bids":[],"asks":[{"price":101818.2,"qty":0.00000000},{"price":101843.9,"qty":0.01129070}],"checksum":3772668418,"timestamp":"2024-06-01T17:51:49.684991Z"}]}
{"channel":"book","type":"update","data":[{"symbol":"BTC/AUD","bids":[],"asks":[{"price":101818.1,"qty":0.17053932}],"checksum":3715670119,"timestamp":"2024-06-01T17:51:49.686516Z"}]}
{"channel":"book","type":"update","data":[{"symbol":"BTC/AUD","bids":[],"asks":[{"price":101771.2,"qty":0.00000000},{"price":101856.6,"qty":0.55017308},{"price":101783.5,"qty":0.05384470}],"checksum":45566491,"timestamp":"2024-06-01T17:51:49.717349Z"}]}
{"channel":"book","type":"update","data":[{"symbol":"BTC/AUD","bids":[],"asks":[{"price":101843.9,"qty":0.00000000},{"price":101856.6,"qty":0.55017308}],"checksum":1624340482,"timestamp":"2024-06-01T17:51:49.724848Z"}]}
{"channel":"book","type":"update","data":[{"symbol":"BTC/AUD","bids":[{"price":101658.6,"qty":0.15000000}],"asks":[],"checksum":4097376759,"timestamp":"2024-06-01T17:51:49.725056Z"}]}
{"channel":"book","type":"update","data":[{"symbol":"BTC/AUD","bids":[],"asks":[{"price":101856.5,"qty":0.01129070}],"checksum":408877452,"timestamp":"2024-06-01T17:51:49.725132Z"}]}
{"channel":"book","type":"update","data":[{"symbol":"BTC/AUD","bids":[],"asks":[{"price":101783.5,"qty":0.00000000},{"price":101856.6,"qty":0.55017308},{"price":101818.0,"qty":0.05384470}],"checksum":1431498305,"timestamp":"2024-06-01T17:51:49.770866Z"}]}
{"channel":"book","type":"update","data":[{"symbol":"BTC/AUD","bids":[{"price":101658.0,"qty":0.00000000},{"price":101648.8,"qty":0.23809552}],"asks":[],"checksum":3391411143,"timestamp":"2024-06-01T17:51:49.776524Z"}]}
{"channel":"book","type":"update","data":[{"symbol":"BTC/AUD","bids":[],"asks":[{"price":101779.7,"qty":0.00562000}],"checksum":2769670387,"timestamp":"2024-06-01T17:51:49.803198Z"}]}
{"channel":"book","type":"update","data":[{"symbol":"BTC/AUD","bids":[],"asks":[{"price":101771.3,"qty":0.00000000},{"price":101856.5,"qty":0.01129070},{"price":101780.2,"qty":0.00135200}],"checksum":1694352595,"timestamp":"2024-06-01T17:51:49.913432Z"}]}
{"channel":"book","type":"update","data":[{"symbol":"BTC/AUD","bids":[{"price":101658.7,"qty":0.04717373}],"asks":[],"checksum":3679954044,"timestamp":"2024-06-01T17:51:49.918887Z"}]}
{"channel":"book","type":"update","data":[{"symbol":"BTC/AUD","bids":[],"asks":[{"price":101822.8,"qty":0.28222207},{"price":101817.9,"qty":0.02937000}],"checksum":522097444,"timestamp":"2024-06-01T17:51:49.921642Z"}]}
{"channel":"book","type":"update","data":[{"symbol":"BTC/AUD","bids":[],"asks":[{"price":101818.0,"qty":0.00000000},{"price":101826.0,"qty":0.09768924},{"price":101779.6,"qty":0.05384469}],"checksum":267164503,"timestamp":"2024-06-01T17:51:50.078094Z"}]}
{"channel":"book","type":"update","data":[{"symbol":"BTC/AUD","bids":[{"price":101658.5,"qty":0.00000000},{"price":101648.8,"qty":0.23809552},{"price":101658.8,"qty":0.05388773}],"asks":[],"checksum":3401715080,"timestamp":"2024-06-01T17:51:50.078124Z"}]}
{"channel":"book","type":"update","data":[{"symbol":"BTC/AUD","bids":[{"price":101658.4,"qty":0.00000000},{"price":101648.8,"qty":0.23809552}],"asks":[],"checksum":3561814771,"timestamp":"2024-06-01T17:51:50.083204Z"}]}
{"channel":"book","type":"update","data":[{"symbol":"BTC/AUD","bids":[{"price":101658.3,"qty":0.00000000},{"price":101627.7,"qty":0.02937000},{"price":101658.9,"qty":0.00308000}],"asks":[],"checksum":3975695635,"timestamp":"2024-06-01T17:51:50.115878Z"}]}
{"channel":"book","type":"update","data":[{"symbol":"BTC/AUD","bids":[],"asks":[{"price":101779.7,"qty":0.00000000},{"price":101826.0,"qty":0.09768924}],"checksum":2860016682,"timestamp":"2024-06-01T17:51:50.172275Z"}]}
{"channel":"book","type":"update","data":[{"symbol":"BTC/AUD","bids":[],"asks":[{"price":101779.6,"qty":0.00000000},{"price":101851.5,"qty":0.05000000},{"price":101817.8,"qty":0.05384469}],"checksum":3284839793,"timestamp":"2024-06-01T17:51:50.227912Z"}]}
{"channel":"book","type":"update","data":[{"symbol":"BTC/AUD","bids":[],"asks":[{"price":101779.8,"qty":0.00665000}],"checksum":208341387,"timestamp":"2024-06-01T17:51:50.351493Z"}]}
{"channel":"book","type":"update","data":[{"symbol":"BTC/AUD","bids":[],"asks":[{"price":101779.8,"qty":0.00000000},{"price":101826.0,"qty":0.09768924}],"checksum":3284839793,"timestamp":"2024-06-01T17:51:50.475245Z"}]}
{"channel":"book","type":"update","data":[{"symbol":"BTC/AUD","bids":[],"asks":[{"price":101817.9,"qty":0.00000000},{"price":101851.5,"qty":0.05000000},{"price":101817.7,"qty":0.02937000}],"checksum":4221025738,"timestamp":"2024-06-01T17:51:50.478381Z"}]}
{"channel":"book","type":"update","data":[{"symbol":"BTC/AUD","bids":[],"asks":[{"price":101780.3,"qty":0.00519608}],"checksum":3567255865,"timestamp":"2024-06-01T17:51:50.587347Z"}]}
{"channel":"book","type":"update","data":[{"symbol":"BTC/AUD","bids":[],"asks":[{"price":101817.8,"qty":0.00000000},{"price":101851.5,"qty":0.05000000},{"price":101780.1,"qty":0.05384455}],"checksum":2593714626,"timestamp":"2024-06-01T17:51:50.763719Z"}]}
{"channel":"book","type":"update","data":[{"symbol":"BTC/AUD","bids":[{"price":101658.8,"qty":0.00000000},{"price":101627.7,"qty":0.02937000},{"price":101659.0,"qty":0.05388761}],"asks":[],"checksum":1959147910,"timestamp":"2024-06-01T17:51:50.763807Z"}]}
{"channel":"book","type":"update","data":[{"symbol":"BTC/AUD","bids":[{"price":101658.9,"qty":0.15308000}],"asks":[],"checksum":419914833,"timestamp":"2024-06-01T17:51:50.769376Z"}]}
{"channel":"book","type":"update","data":[{"symbol":"BTC/AUD","bids":[{"price":101658.9,"qty":0.15000000},{"price":101659.1,"qty":0.00308000}],"asks":[],"checksum":1507795635,"timestamp":"2024-06-01T17:51:50.789525Z"}]}
{"channel":"book","type":"update","data":[{"symbol":"BTC/AUD","bids":[{"price":101658.9,"qty":0.00000000},{"price":101648.8,"qty":0.23809552}],"asks":[],"checksum":4171478609,"timestamp":"2024-06-01T17:51:51.143120Z"}]}
{"channel":"book","type":"update","data":[{"symbol":"BTC/AUD","bids":[{"price":101659.2,"qty":0.04717373}],"asks":[],"checksum":2656847817,"timestamp":"2024-06-01T17:51:51.148544Z"}]}
{"channel":"book","type":"update","data":[{"symbol":"BTC/AUD","bids":[{"price":101659.3,"qty":0.23807093}],"asks":[],"checksum":2552646825,"timestamp":"2024-06-01T17:51:51.154662Z"}]}
{"channel":"book","type":"update","data":[{"symbol":"BTC/AUD","bids":[{"price":101659.1,"qty":0.00000000},{"price":101656.6,"qty":0.05056249},{"price":101659.3,"qty":0.24115093}],"asks":[],"checksum":4092664790,"timestamp":"2024-06-01T17:51:51.157051Z"}]}
{"channel":"book","type":"update","data":[{"symbol":"BTC/AUD","bids":[{"price":101658.7,"qty":0.00000000},{"price":101627.7,"qty":0.02937000}],"asks":[],"checksum":4025724959,"timestamp":"2024-06-01T17:51:51.179315Z"}]}
{"channel":"book","type":"update","data":[{"symbol":"BTC/AUD","bids":[{"price":101657.6,"qty":0.00000000},{"price":101627.6,"qty":0.00639000}],"asks":[],"checksum":4027558453,"timestamp":"2024-06-01T17:51:51.282372Z"}]}
{"channel":"book","type":"update","data":[{"symbol":"BTC/AUD","bids":[{"price":101659.2,"qty":0.39409244}],"asks":[],"checksum":2941436872,"timestamp":"2024-06-01T17:51:51.283427Z"}]}
{"channel":"book","type":"update","data":[{"symbol":"BTC/AUD","bids":[{"price":101659.3,"qty":0.23807093},{"price":101659.4,"qty":0.00308000}],"asks":[],"checksum":206104999,"timestamp":"2024-06-01T17:51:51.310264Z"}]}
{"channel":"book","type":"update","data":[{"symbol":"BTC/AUD","bids":[{"price":101656.6,"qty":0.00000000},{"price":101627.6,"qty":0.00639000},{"price":101665.7,"qty":0.05056249}],"asks":[],"checksum":1754380714,"timestamp":"2024-06-01T17:51:51.491356Z"}]}
{"channel":"book","type":"update","data":[{"symbol":"BTC/AUD","bids":[],"asks":[{"price":101817.7,"qty":0.00000000},{"price":101851.5,"qty":0.05000000},{"price":101818.0,"qty":0.02937000}],"checksum":1252847754,"timestamp":"2024-06-01T17:51:51.494162Z"}]}
{"channel":"book","type":"update","data":[{"symbol":"BTC/AUD","bids":[{"price":101659.0,"qty":0.00000000},{"price":101627.6,"qty":0.00639000},{"price":101665.8,"qty":0.05388601}],"asks":[],"checksum":1341660701,"timestamp":"2024-06-01T17:51:51.548338Z"}]}
{"channel":"book","type":"update","data":[{"symbol":"BTC/AUD","bids":[{"price":101657.7,"qty":0.00075700},{"price":101665.8,"qty":0.05864001}],"asks":[],"checksum":1285044216,"timestamp":"2024-06-01T17:51:51.655835Z"}]}
{"channel":"book","type":"update","data":[{"symbol":"BTC/AUD","bids":[{"price":101657.7,"qty":0.00000000},{"price":101627.6,"qty":0.00639000},{"price":101665.8,"qty":0.05939701}],"asks":[],"checksum":693014246,"timestamp":"2024-06-01T17:51:51.666591Z"}]}
{"channel":"book","type":"update","data":[{"symbol":"BTC/AUD","bids":[{"price":101657.9,"qty":0.00000000},{"price":101595.3,"qty":0.04191962}],"asks":[],"checksum":1092090262,"timestamp":"2024-06-01T17:51:51.852400Z"}]}
{"channel":"book","type":"update","data":[{"symbol":"BTC/AUD","bids":[{"price":101665.9,"qty":0.00231520}],"asks":[],"checksum":1454022329,"timestamp":"2024-06-01T17:51:51.853231Z"}]}
{"channel":"book","type":"update","data":[{"symbol":"BTC/AUD","bids":[{"price":101665.9,"qty":0.15231520}],"asks":[],"checksum":100658861,"timestamp":"2024-06-01T17:51:51.859436Z"}]}
{"channel":"book","type":"update","data":[{"symbol":"BTC/AUD","bids":[],"asks":[{"price":101818.1,"qty":0.16738190}],"checksum":3115049416,"timestamp":"2024-06-01T17:51:51.862564Z"}]}
{"channel":"book","type":"update","data":[{"symbol":"BTC/AUD","bids":[],"asks":[{"price":101817.6,"qty":0.00355167}],"checksum":3418080253,"timestamp":"2024-06-01T17:51:51.865110Z"}]}
{"channel":"book","type":"update","data":[{"symbol":"BTC/AUD","bids":[{"price":101659.4,"qty":0.00000000},{"price":101595.3,"qty":0.04191962},{"price":101666.0,"qty":0.00308000}],"asks":[],"checksum":897930317,"timestamp":"2024-06-01T17:51:51.890047Z"}]}
{"channel":"book","type":"update","data":[{"symbol":"BTC/AUD","bids":[{"price":101658.6,"qty":0.00000000},{"price":101595.3,"qty":0.04191962}],"asks":[],"checksum":1080677569,"timestamp":"2024-06-01T17:51:51.895924Z"}]}
{"channel":"book","type":"update","data":[{"symbol":"BTC/AUD","bids":[{"price":101666.1,"qty":0.04717373}],"asks":[],"checksum":814800200,"timestamp":"2024-06-01T17:51:52.179532Z"}]}
{"channel":"book","type":"update","data":[{"symbol":"BTC/AUD","bids":[],"asks":[{"price":101796.7,"qty":0.04717373}],"checksum":2976528380,"timestamp":"2024-06-01T17:51:52.179658Z"}]}
{"channel":"book","type":"update","data":[{"symbol":"BTC/AUD","bids":[],"asks":[{"price":101818.0,"qty":0.00000000},{"price":101822.9,"qty":0.05056249},{"price":101796.6,"qty":0.02937000}],"checksum":1916079390,"timestamp":"2024-06-01T17:51:52.183289Z"}]}
{"channel":"book","type":"update","data":[{"symbol":"BTC/AUD","bids":[{"price":101659.2,"qty":0.34691871}],"asks":[],"checksum":1335620769,"timestamp":"2024-06-01T17:51:52.184378Z"}]}
{"channel":"book","type":"update","data":[{"symbol":"BTC/AUD","bids":[{"price":101666.0,"qty":0.00000000},{"price":101595.3,"qty":0.04191962},{"price":101666.2,"qty":0.00308000}],"asks":[],"checksum":1921851909,"timestamp":"2024-06-01T17:51:52.194770Z"}]}
{"channel":"book","type":"update","data":[{"symbol":"BTC/AUD","bids":[{"price":101665.8,"qty":0.00551100},{"price":101666.3,"qty":0.05388576}],"asks":[],"checksum":3371968571,"timestamp":"2024-06-01T17:51:52.293265Z"}]}
{"channel":"book","type":"update","data":[{"symbol":"BTC/AUD","bids":[],"asks":[{"price":101822.8,"qty":0.00000000},{"price":101822.9,"qty":0.05056249}],"checksum":613212023,"timestamp":"2024-06-01T17:51:52.300015Z"}]}
{"channel":"book","type":"update","data":[{"symbol":"BTC/AUD","bids":[],"asks":[{"price":101818.1,"qty":0.00000000},{"price":101826.0,"qty":0.09768924}],"checksum":1923403387,"timestamp":"2024-06-01T17:51:52.300085Z"}]}
{"channel":"book","type":"update","data":[{"symbol":"BTC/AUD","bids":[],"asks":[{"price":101817.9,"qty":0.16737991}],"checksum":243590846,"timestamp":"2024-06-01T17:51:52.304684Z"}]}
{"channel":"book","type":"update","data":[{"symbol":"BTC/AUD","bids":[],"asks":[{"price":101822.8,"qty":0.30518812}],"checksum":107758193,"timestamp":"2024-06-01T17:51:52.304858Z"}]}
{"channel":"book","type":"update","data":[{"symbol":"BTC/AUD","bids":[],"asks":[{"price":101796.6,"qty":0.00000000},{"price":101822.9,"qty":0.05056249}],"checksum":1625639642,"timestamp":"2024-06-01T17:51:52.402317Z"}]}
{"channel":"book","type":"update","data":[{"symbol":"BTC/AUD","bids":[{"price":101658.1,"qty":0.00000000},{"price":101627.6,"qty":0.00639000},{"price":101666.4,"qty":0.00135300}],"asks":[],"checksum":3151824949,"timestamp":"2024-06-01T17:51:52.743250Z"}]}
{"channel":"book","type":"update","data":[{"symbol":"BTC/AUD","bids":[],"asks":[{"price":101792.5,"qty":0.02937000}],"checksum":1248616746,"timestamp":"2024-06-01T17:51:52.746052Z"}]}
{"channel":"book","type":"update","data":[{"symbol":"BTC/AUD","bids":[{"price":101666.4,"qty":0.15135300}],"asks":[],"checksum":1171066398,"timestamp":"2024-06-01T17:51:52.749508Z"}]}
{"channel":"book","type":"update","data":[{"symbol":"BTC/AUD","bids":[{"price":101666.3,"qty":0.00000000},{"price":101627.6,"qty":0.00639000},{"price":101666.5,"qty":0.05388532}],"asks":[],"checksum":3058741943,"timestamp":"2024-06-01T17:51:52.994995Z"}]}
{"channel":"book","type":"update","data":[{"symbol":"BTC/AUD","bids":[{"price":101666.4,"qty":0.00135300}],"asks":[],"checksum":2619539252,"timestamp":"2024-06-01T17:51:53.000802Z"}]}
{"channel":"book","type":"update","data":[{"symbol":"BTC/AUD","bids":[{"price":101666.6,"qty":0.04717373}],"asks":[],"checksum":1774832272,"timestamp":"2024-06-01T17:51:53.001011Z"}]}
{"channel":"book","type":"update","data":[{"symbol":"BTC/AUD","bids":[{"price":101666.1,"qty":0.00000000},{"price":101627.7,"qty":0.02937000}],"asks":[],"checksum":1204472057,"timestamp":"2024-06-01T17:51:53.180363Z"}]}
{"channel":"book","type":"update","data":[{"symbol":"BTC/AUD","bids":[{"price":101666.2,"qty":0.00000000},{"price":101627.6,"qty":0.00639000},{"price":101666.7,"qty":0.00308000}],"asks":[],"checksum":475490999,"timestamp":"2024-06-01T17:51:53.207534Z"}]}
{"channel":"book","type":"update","data":[{"symbol":"BTC/AUD","bids":[{"price":101666.5,"qty":0.00000000},{"price":101627.6,"qty":0.00639000},{"price":101666.8,"qty":0.05388517}],"asks":[],"checksum":3120193373,"timestamp":"2024-06-01T17:51:53.659768Z"}]}
{"channel":"book","type":"update","data":[{"symbol":"BTC/AUD","bids":[{"price":101666.7,"qty":0.00000000},{"price":101627.6,"qty":0.00639000},{"price":101666.9,"qty":0.00308000}],"asks":[],"checksum":4167822593,"timestamp":"2024-06-01T17:51:53.695293Z"}]}
{"channel":"book","type":"update","data":[{"symbol":"BTC/AUD","bids":[{"price":101666.9,"qty":0.15308000}],"asks":[],"checksum":220186702,"timestamp":"2024-06-01T17:51:53.700616Z"}]}
{"channel":"book","type":"update","data":[{"symbol":"BTC/AUD","bids":[{"price":101666.9,"qty":0.15000000},{"price":101667.0,"qty":0.00308000}],"asks":[],"checksum":3183343419,"timestamp":"2024-06-01T17:51:54.028801Z"}]}
{"channel":"book","type":"update","data":[{"symbol":"BTC/AUD","bids":[{"price":101667.1,"qty":0.04717373}],"asks":[],"checksum":53690069,"timestamp":"2024-06-01T17:51:54.034413Z"}]}
{"channel":"book","type":"update","data":[{"symbol":"BTC/AUD","bids":[{"price":101665.9,"qty":0.00231520}],"asks":[],"checksum":967234258,"timestamp":"2024-06-01T17:51:54.034580Z"}]}
{"channel":"book","type":"update","data":[{"symbol":"BTC/AUD","bids":[],"asks":[{"price":101817.6,"qty":0.00000000},{"price":101822.9,"qty":0.05056249}],"checksum":1781476621,"timestamp":"2024-06-01T17:51:54.127355Z"}]}
{"channel":"book","type":"update","data":[{"symbol":"BTC/AUD","bids":[],"asks":[{"price":101817.8,"qty":0.00314468}],"checksum":4188268474,"timestamp":"2024-06-01T17:51:54.132485Z"}]}
{"channel":"book","type":"update","data":[{"symbol":"BTC/AUD","bids":[{"price":101666.6,"qty":0.00000000},{"price":101659.2,"qty":0.34691871}],"asks":[],"checksum":1243112491,"timestamp":"2024-06-01T17:51:54.178460Z"}]}
{"channel":"book","type":"update","data":[{"symbol":"BTC/AUD","bids":[{"price":101659.2,"qty":0.00000000},{"price":101627.7,"qty":0.02937000}],"asks":[],"checksum":3489415497,"timestamp":"2024-06-01T17:51:54.227155Z"}]}
{"channel":"book","type":"update","data":[{"symbol":"BTC/AUD","bids":[{"price":101667.0,"qty":0.32114893}],"asks":[],"checksum":2290278255,"timestamp":"2024-06-01T17:51:54.228280Z"}]}
{"channel":"book","type":"update","data":[{"symbol":"BTC/AUD","bids":[],"asks":[{"price":101792.5,"qty":0.00000000},{"price":101822.9,"qty":0.05056249},{"price":101796.6,"qty":0.02937000}],"checksum":532332251,"timestamp":"2024-06-01T17:51:54.231329Z"}]}
{"channel":"book","type":"update","data":[{"symbol":"BTC/AUD","bids":[{"price":101666.8,"qty":0.00000000},{"price":101627.6,"qty":0.00639000},{"price":101667.2,"qty":0.05388496}],"asks":[],"checksum":1938474731,"timestamp":"2024-06-01T17:51:54.348128Z"}]}
{"channel":"book","type":"update","data":[{"symbol":"BTC/AUD","bids":[{"price":101667.0,"qty":0.31806893},{"price":101667.3,"qty":0.00308000}],"asks":[],"checksum":813610926,"timestamp":"2024-06-01T17:51:54.368699Z"}]}
{"channel":"book","type":"update","data":[{"symbol":"BTC/AUD","bids":[{"price":101665.9,"qty":0.00000000},{"price":101627.7,"qty":0.02937000}],"asks":[],"checksum":1428864731,"timestamp":"2024-06-01T17:51:54.781087Z"}]}
{"channel":"book","type":"update","data":[{"symbol":"BTC/AUD","bids":[{"price":101667.4,"qty":0.00217101}],"asks":[],"checksum":905602370,"timestamp":"2024-06-01T17:51:54.782255Z"}]}
{"channel":"book","type":"update","data":[{"symbol":"BTC/AUD","bids":[{"price":101667.3,"qty":0.15308000}],"asks":[],"checksum":3739081537,"timestamp":"2024-06-01T17:51:54.787771Z"}]}
{"channel":"book","type":"update","data":[{"symbol":"BTC/AUD","bids":[{"price":101667.2,"qty":0.00000000},{"price":101627.7,"qty":0.02937000},{"price":101667.5,"qty":0.05388485}],"asks":[],"checksum":2981516216,"timestamp":"2024-06-01T17:51:55.009129Z"}]}
{"channel":"book","type":"update","data":[{"symbol":"BTC/AUD","bids":[{"price":101667.6,"qty":0.04717373}],"asks":[],"checksum":2085692756,"timestamp":"2024-06-01T17:51:55.015310Z"}]}
{"channel":"book","type":"update","data":[{"symbol":"BTC/AUD","bids":[{"price":101667.3,"qty":0.00308000}],"asks":[],"checksum":1546084641,"timestamp":"2024-06-01T17:51:55.016391Z"}]}
{"channel":"book","type":"update","data":[{"symbol":"BTC/AUD","bids":[{"price":101667.3,"qty":0.00000000},{"price":101659.3,"qty":0.23807093},{"price":101667.7,"qty":0.00308000}],"asks":[],"checksum":162266303,"timestamp":"2024-06-01T17:51:55.038196Z"}]}
{"channel":"book","type":"update","data":[{"symbol":"BTC/AUD","bids":[],"asks":[{"price":101817.9,"qty":0.00000000},{"price":101822.9,"qty":0.05056249}],"checksum":1328890200,"timestamp":"2024-06-01T17:51:55.174896Z"}]}
{"channel":"book","type":"update","data":[{"symbol":"BTC/AUD","bids":[{"price":101667.1,"qty":0.00000000},{"price":101659.3,"qty":0.23807093}],"asks":[],"checksum":3210612144,"timestamp":"2024-06-01T17:51:55.179069Z"}]}
{"channel":"book","type":"update","data":[{"symbol":"BTC/AUD","bids":[{"price":101667.8,"qty":0.04717373}],"asks":[],"checksum":3346656798,"timestamp":"2024-06-01T17:51:55.187686Z"}]}
{"channel":"book","type":"update","data":[{"symbol":"BTC/AUD","bids":[{"price":101667.7,"qty":0.00000000},{"price":101659.3,"qty":0.23807093},{"price":101667.9,"qty":0.00308000}],"asks":[],"checksum":4087055373,"timestamp":"2024-06-01T17:51:55.223467Z"}]}
{"channel":"book","type":"update","data":[{"symbol":"BTC/AUD","bids":[{"price":101667.6,"qty":0.00000000},{"price":101659.3,"qty":0.23807093}],"asks":[],"checksum":2653262478,"timestamp":"2024-06-01T17:51:55.228948Z"}]}
{"channel":"book","type":"update","data":[{"symbol":"BTC/AUD","bids":[{"price":101667.5,"qty":0.00000000},{"price":101627.6,"qty":0.00639000},{"price":101668.0,"qty":0.05388456}],"asks":[],"checksum":3136697876,"timestamp":"2024-06-01T17:51:55.700674Z"}]}
{"channel":"book","type":"update","data":[{"symbol":"BTC/AUD","bids":[{"price":101668.1,"qty":0.15000000}],"asks":[],"checksum":3503020383,"timestamp":"2024-06-01T17:51:55.706668Z"}]}
{"channel":"book","type":"update","data":[{"symbol":"BTC/AUD","bids":[{"price":101667.9,"qty":0.00000000},{"price":101659.3,"qty":0.23807093},{"price":101668.1,"qty":0.15308000}],"asks":[],"checksum":1171382092,"timestamp":"2024-06-01T17:51:55.711003Z"}]}
{"channel":"book","type":"update","data":[{"symbol":"BTC/AUD","bids":[],"asks":[{"price":101822.9,"qty":0.00000000},{"price":101826.0,"qty":0.09768924}],"checksum":744785242,"timestamp":"2024-06-01T17:51:56.071536Z"}]}
{"channel":"book","type":"update","data":[{"symbol":"BTC/AUD","bids":[{"price":101666.9,"qty":0.00000000},{"price":101627.7,"qty":0.02937000}],"asks":[],"checksum":1889599142,"timestamp":"2024-06-01T17:51:56.143162Z"}]}
{"channel":"book","type":"update","data":[{"symbol":"BTC/AUD","bids":[{"price":101668.2,"qty":0.04717373}],"asks":[],"checksum":1641466181,"timestamp":"2024-06-01T17:51:56.179827Z"}]}
{"channel":"book","type":"update","data":[{"symbol":"BTC/AUD","bids":[{"price":101667.8,"qty":0.00000000},{"price":101627.7,"qty":0.02937000}],"asks":[],"checksum":448677178,"timestamp":"2024-06-01T17:51:56.184329Z"}]}
{"channel":"book","type":"update","data":[{"symbol":"BTC/AUD","bids":[{"price":101668.3,"qty":0.15000000}],"asks":[],"checksum":257692976,"timestamp":"2024-06-01T17:51:56.184969Z"}]}
{"channel":"book","type":"update","data":[{"symbol":"BTC/AUD","bids":[],"asks":[{"price":101817.8,"qty":0.00000000},{"price":101851.1,"qty":0.01129070}],"checksum":3860720779,"timestamp":"2024-06-01T17:51:56.283937Z"}]}
{"channel":"book","type":"update","data":[{"symbol":"BTC/AUD","bids":[],"asks":[{"price":101822.7,"qty":0.00403498}],"checksum":1907691108,"timestamp":"2024-06-01T17:51:56.286906Z"}]}
{"channel":"book","type":"update","data":[{"symbol":"BTC/AUD","bids":[{"price":101668.0,"qty":0.00000000},{"price":101627.7,"qty":0.02937000},{"price":101668.4,"qty":0.05388433}],"asks":[],"checksum":4264583341,"timestamp":"2024-06-01T17:51:56.354560Z"}]}
{"channel":"book","type":"update","data":[{"symbol":"BTC/AUD","bids":[{"price":101668.3,"qty":0.00000000},{"price":101627.7,"qty":0.02937000}],"asks":[],"checksum":2611685684,"timestamp":"2024-06-01T17:51:56.361714Z"}]}
{"channel":"book","type":"update","data":[{"symbol":"BTC/AUD","bids":[{"price":101665.7,"qty":0.00000000},{"price":101627.6,"qty":0.00639000},{"price":101671.6,"qty":0.05056249}],"asks":[],"checksum":3457141057,"timestamp":"2024-06-01T17:51:56.574289Z"}]}
{"channel":"book","type":"update","data":[{"symbol":"BTC/AUD","bids":[{"price":101668.4,"qty":0.00000000},{"price":101627.6,"qty":0.00639000},{"price":101671.7,"qty":0.05388208}],"asks":[],"checksum":3194626823,"timestamp":"2024-06-01T17:51:56.950540Z"}]}
{"channel":"book","type":"update","data":[{"symbol":"BTC/AUD","bids":[{"price":101671.8,"qty":0.04717373}],"asks":[],"checksum":2678269474,"timestamp":"2024-06-01T17:51:56.955292Z"}]}
{"channel":"book","type":"update","data":[{"symbol":"BTC/AUD","bids":[{"price":101671.8,"qty":0.19717373}],"asks":[],"checksum":2661697775,"timestamp":"2024-06-01T17:51:56.955411Z"}]}
{"channel":"book","type":"update","data":[{"symbol":"BTC/AUD","bids":[{"price":101668.1,"qty":0.15000000},{"price":101671.9,"qty":0.00308000}],"asks":[],"checksum":924695992,"timestamp":"2024-06-01T17:51:56.966566Z"}]}
{"channel":"book","type":"update","data":[{"symbol":"BTC/AUD","bids":[{"price":101668.1,"qty":0.00000000},{"price":101659.3,"qty":0.23807093}],"asks":[],"checksum":2671715736,"timestamp":"2024-06-01T17:51:57.143839Z"}]}
{"channel":"book","type":"update","data":[{"symbol":"BTC/AUD","bids":[{"price":101668.2,"qty":0.00000000},{"price":101627.7,"qty":0.02937000}],"asks":[],"checksum":1865026015,"timestamp":"2024-06-01T17:51:57.179024Z"}]}
{"channel":"book","type":"update","data":[{"symbol":"BTC/AUD","bids":[{"price":101672.0,"qty":0.04717373}],"asks":[],"checksum":302349073,"timestamp":"2024-06-01T17:51:57.183656Z"}]}
{"channel":"book","type":"update","data":[{"symbol":"BTC/AUD","bids":[{"price":101666.4,"qty":0.00000000},{"price":101627.7,"qty":0.02937000},{"price":101672.0,"qty":0.04852673}],"asks":[],"checksum":1932663549,"timestamp":"2024-06-01T17:51:57.213259Z"}]}
{"channel":"book","type":"update","data":[{"symbol":"BTC/AUD","bids":[{"price":101671.8,"qty":0.15000000}],"asks":[],"checksum":2059887802,"timestamp":"2024-06-01T17:51:57.217893Z"}]}
{"channel":"book","type":"update","data":[{"symbol":"BTC/AUD","bids":[{"price":101667.0,"qty":0.00000000},{"price":101627.6,"qty":0.00639000}],"asks":[],"checksum":3251789391,"timestamp":"2024-06-01T17:51:57.218400Z"}]}
{"channel":"book","type":"update","data":[{"symbol":"BTC/AUD","bids":[{"price":101672.0,"qty":0.36658231}],"asks":[],"checksum":699812561,"timestamp":"2024-06-01T17:51:57.219528Z"}]}
{"channel":"book","type":"update","data":[{"symbol":"BTC/AUD","bids":[{"price":101671.9,"qty":0.00000000},{"price":101595.3,"qty":0.04191962},{"price":101672.1,"qty":0.00308000}],"asks":[],"checksum":1942771529,"timestamp":"2024-06-01T17:51:57.251475Z"}]}
{"channel":"book","type":"update","data":[{"symbol":"BTC/AUD","bids":[{"price":101671.7,"qty":0.00000000},{"price":101595.3,"qty":0.04191962},{"price":101672.2,"qty":0.05388179}],"asks":[],"checksum":1436832217,"timestamp":"2024-06-01T17:51:57.587131Z"}]}
{"channel":"book","type":"update","data":[{"symbol":"BTC/AUD","bids":[{"price":101672.1,"qty":0.00000000},{"price":101595.3,"qty":0.04191962},{"price":101672.3,"qty":0.00308000}],"asks":[],"checksum":1366551967,"timestamp":"2024-06-01T17:51:57.606811Z"}]}
{"channel":"book","type":"update","data":[{"symbol":"BTC/AUD","bids":[{"price":101667.4,"qty":0.00000000},{"price":101595.3,"qty":0.04191962}],"asks":[],"checksum":1696718994,"timestamp":"2024-06-01T17:51:57.769930Z"}]}
{"channel":"book","type":"update","data":[{"symbol":"BTC/AUD","bids":[{"price":101672.2,"qty":0.05607068}],"asks":[],"checksum":2190998604,"timestamp":"2024-06-01T17:51:57.773470Z"}]}
{"channel":"book","type":"update","data":[{"symbol":"BTC/AUD","bids":[{"price":101672.3,"qty":0.15308000}],"asks":[],"checksum":1616541426,"timestamp":"2024-06-01T17:51:57.779071Z"}]}
{"channel":"book","type":"update","data":[{"symbol":"BTC/AUD","bids":[{"price":101595.4,"qty":0.02950412}],"asks":[],"checksum":3754510156,"timestamp":"2024-06-01T17:51:57.833941Z"}]}
{"channel":"book","type":"update","data":[{"symbol":"BTC/AUD","bids":[],"asks":[{"price":101822.8,"qty":0.00000000},{"price":101851.1,"qty":0.01129070}],"checksum":2840600495,"timestamp":"2024-06-01T17:51:57.902060Z"}]}
{"channel":"book","type":"update","data":[{"symbol":"BTC/AUD","bids":[],"asks":[{"price":101825.9,"qty":0.09847456}],"checksum":678293724,"timestamp":"2024-06-01T17:51:57.904493Z"}]}
{"channel":"book","type":"update","data":[{"symbol":"BTC/AUD","bids":[{"price":101671.8,"qty":0.00000000},{"price":101595.3,"qty":0.04191962}],"asks":[],"checksum":4110840715,"timestamp":"2024-06-01T17:51:58.143479Z"}]}
{"channel":"book","type":"update","data":[{"symbol":"BTC/AUD","bids":[{"price":101672.4,"qty":0.04717373}],"asks":[],"checksum":817758312,"timestamp":"2024-06-01T17:51:58.148378Z"}]}
{"channel":"book","type":"update","data":[{"symbol":"BTC/AUD","bids":[{"price":101672.3,"qty":0.15000000},{"price":101672.5,"qty":0.00308000}],"asks":[],"checksum":1889311701,"timestamp":"2024-06-01T17:51:58.157585Z"}]}
{"channel":"book","type":"update","data":[{"symbol":"BTC/AUD","bids":[{"price":101672.0,"qty":0.31940858}],"asks":[],"checksum":4157272691,"timestamp":"2024-06-01T17:51:58.179109Z"}]}
{"channel":"book","type":"update","data":[{"symbol":"BTC/AUD","bids":[{"price":101672.2,"qty":0.00218889},{"price":101672.4,"qty":0.10105540}],"asks":[],"checksum":3624768907,"timestamp":"2024-06-01T17:51:58.179590Z"}]}
{"channel":"book","type":"update","data":[{"symbol":"BTC/AUD","bids":[{"price":101672.5,"qty":0.15308000}],"asks":[],"checksum":3540731700,"timestamp":"2024-06-01T17:51:58.183820Z"}]}
{"channel":"book","type":"update","data":[{"symbol":"BTC/AUD","bids":[],"asks":[{"price":101822.7,"qty":0.00000000},{"price":101850.9,"qty":0.01129070}],"checksum":2903348281,"timestamp":"2024-06-01T17:51:58.561056Z"}]}
{"channel":"book","type":"update","data":[{"symbol":"BTC/AUD","bids":[],"asks":[{"price":101825.8,"qty":0.00294117}],"checksum":3416124189,"timestamp":"2024-06-01T17:51:58.563559Z"}]}
{"channel":"book","type":"update","data":[{"symbol":"BTC/AUD","bids":[{"price":101672.3,"qty":0.00000000},{"price":101595.4,"qty":0.02950412}],"asks":[],"checksum":3343795156,"timestamp":"2024-06-01T17:51:58.644126Z"}]}
{"channel":"book","type":"update","data":[{"symbol":"BTC/AUD","bids":[{"price":101672.4,"qty":0.04717373},{"price":101672.6,"qty":0.05388189}],"asks":[],"checksum":3706310628,"timestamp":"2024-06-01T17:51:58.807332Z"}]}
{"channel":"book","type":"update","data":[{"symbol":"BTC/AUD","bids":[{"price":101672.7,"qty":0.15000000}],"asks":[],"checksum":1259735589,"timestamp":"2024-06-01T17:51:58.816119Z"}]}
{"channel":"book","type":"update","data":[{"symbol":"BTC/AUD","bids":[{"price":101672.5,"qty":0.00308000}],"asks":[],"checksum":263384724,"timestamp":"2024-06-01T17:51:59.143479Z"}]}
{"channel":"book","type":"update","data":[{"symbol":"BTC/AUD","bids":[{"price":101672.8,"qty":0.04717373}],"asks":[],"checksum":1452458840,"timestamp":"2024-06-01T17:51:59.149347Z"}]}
{"channel":"book","type":"update","data":[{"symbol":"BTC/AUD","bids":[{"price":101672.4,"qty":0.00000000},{"price":101627.7,"qty":0.02937000}],"asks":[],"checksum":1365383904,"timestamp":"2024-06-01T17:51:59.178288Z"}]}
{"channel":"book","type":"update","data":[{"symbol":"BTC/AUD","bids":[{"price":101672.5,"qty":0.00000000},{"price":101627.6,"qty":0.00639000},{"price":101672.9,"qty":0.00308000}],"asks":[],"checksum":3255489080,"timestamp":"2024-06-01T17:51:59.194432Z"}]}
{"channel":"book","type":"update","data":[{"symbol":"BTC/AUD","bids":[{"price":101665.8,"qty":0.00075700},{"price":101673.0,"qty":0.00475400}],"asks":[],"checksum":2808340475,"timestamp":"2024-06-01T17:51:59.359607Z"}]}
{"channel":"book","type":"update","data":[{"symbol":"BTC/AUD","bids":[{"price":101665.8,"qty":0.00000000},{"price":101627.7,"qty":0.02937000},{"price":101673.0,"qty":0.00551100}],"asks":[],"checksum":2565965141,"timestamp":"2024-06-01T17:51:59.383369Z"}]}
{"channel":"book","type":"update","data":[{"symbol":"BTC/AUD","bids":[{"price":101672.6,"qty":0.00000000},{"price":101627.6,"qty":0.00639000},{"price":101673.0,"qty":0.05939267}],"asks":[],"checksum":3073259257,"timestamp":"2024-06-01T17:51:59.395507Z"}]}
{"channel":"book","type":"update","data":[{"symbol":"BTC/AUD","bids":[{"price":101672.9,"qty":0.00000000},{"price":101595.4,"qty":0.02950412},{"price":101673.1,"qty":0.00308000}],"asks":[],"checksum":4007891824,"timestamp":"2024-06-01T17:51:59.409878Z"}]}
{"channel":"book","type":"update","data":[{"symbol":"BTC/AUD","bids":[],"asks":[{"price":101796.6,"qty":0.00000000},{"price":101850.8,"qty":0.00146264}],"checksum":1998819218,"timestamp":"2024-06-01T17:51:59.627055Z"}]}
{"channel":"book","type":"update","data":[{"symbol":"BTC/AUD","bids":[],"asks":[{"price":101813.1,"qty":0.02937000}],"checksum":3354582680,"timestamp":"2024-06-01T17:51:59.689449Z"}]}
{"channel":"book","type":"update","data":[{"symbol":"BTC/AUD","bids":[{"price":101673.0,"qty":0.00551100},{"price":101673.2,"qty":0.05388157}],"asks":[],"checksum":2343447763,"timestamp":"2024-06-01T17:52:00.006190Z"}]}
{"channel":"book","type":"update","data":[{"symbol":"BTC/AUD","bids":[{"price":101673.3,"qty":0.04717373}],"asks":[],"checksum":465041564,"timestamp":"2024-06-01T17:52:00.011195Z"}]}
{"channel":"book","type":"update","data":[{"symbol":"BTC/AUD","bids":[{"price":101673.3,"qty":0.19717373}],"asks":[],"checksum":3890616922,"timestamp":"2024-06-01T17:52:00.011611Z"}]}
{"channel":"book","type":"update","data":[{"symbol":"BTC/AUD","bids":[{"price":101673.1,"qty":0.00000000},{"price":101627.7,"qty":0.02937000},{"price":101673.3,"qty":0.20025373}],"asks":[],"checksum":243638728,"timestamp":"2024-06-01T17:52:00.018597Z"}]}
{"channel":"book","type":"update","data":[{"symbol":"BTC/AUD","bids":[{"price":101672.7,"qty":0.00000000},{"price":101627.6,"qty":0.00639000}],"asks":[],"checksum":3581155868,"timestamp":"2024-06-01T17:52:00.143513Z"}]}
{"channel":"book","type":"update","data":[{"symbol":"BTC/AUD","bids":[{"price":101672.8,"qty":0.00000000},{"price":101595.4,"qty":0.02950412}],"asks":[],"checksum":1765418445,"timestamp":"2024-06-01T17:52:00.148703Z"}]}
{"channel":"book","type":"update","data":[{"symbol":"BTC/AUD","bids":[{"price":101672.0,"qty":0.00135300}],"asks":[],"checksum":3754834270,"timestamp":"2024-06-01T17:52:00.208097Z"}]}
{"channel":"book","type":"update","data":[{"symbol":"BTC/AUD","bids":[{"price":101673.2,"qty":0.37193550}],"asks":[],"checksum":394980100,"timestamp":"2024-06-01T17:52:00.209538Z"}]}
{"channel":"book","type":"update","data":[{"symbol":"BTC/AUD","bids":[{"price":101673.3,"qty":0.19717373},{"price":101673.4,"qty":0.00308000}],"asks":[],"checksum":3342181582,"timestamp":"2024-06-01T17:52:00.537664Z"}]}
{"channel":"book","type":"update","data":[{"symbol":"BTC/AUD","bids":[{"price":101673.5,"qty":0.04717373}],"asks":[],"checksum":543324701,"timestamp":"2024-06-01T17:52:00.542933Z"}]}
{"channel":"book","type":"update","data":[{"symbol":"BTC/AUD","bids":[{"price":101673.2,"qty":0.31805393},{"price":101673.5,"qty":0.10105556}],"asks":[],"checksum":2312844564,"timestamp":"2024-06-01T17:52:00.584844Z"}]}
{"channel":"book","type":"update","data":[{"symbol":"BTC/AUD","bids":[{"price":101673.3,"qty":0.15000000}],"asks":[],"checksum":3404290328,"timestamp":"2024-06-01T17:52:00.589650Z"}]}
{"channel":"book","type":"update","data":[{"symbol":"BTC/AUD","bids":[{"price":101673.3,"qty":0.00000000},{"price":101627.6,"qty":0.00639000}],"asks":[],"checksum":3945238261,"timestamp":"2024-06-01T17:52:00.590025Z"}]}
{"channel":"book","type":"update","data":[{"symbol":"BTC/AUD","bids":[],"asks":[{"price":101825.9,"qty":0.00000000},{"price":101850.8,"qty":0.00146264}],"checksum":2568629518,"timestamp":"2024-06-01T17:52:00.727337Z"}]}
{"channel":"book","type":"update","data":[{"symbol":"BTC/AUD","bids":[],"asks":[{"price":101825.7,"qty":0.09847440}],"checksum":1882872230,"timestamp":"2024-06-01T17:52:00.732266Z"}]}
{"channel":"book","type":"update","data":[{"symbol":"BTC/AUD","bids":[],"asks":[{"price":101813.1,"qty":0.00000000},{"price":101850.7,"qty":0.76454743},{"price":101825.9,"qty":0.02937000}],"checksum":2087121234,"timestamp":"2024-06-01T17:52:00.753022Z"}]}
{"channel":"book","type":"update","data":[{"symbol":"BTC/AUD","bids":[{"price":101672.2,"qty":0.00000000},{"price":101595.4,"qty":0.02950412}],"asks":[],"checksum":2519293847,"timestamp":"2024-06-01T17:52:00.762558Z"}]}
{"channel":"book","type":"update","data":[{"symbol":"BTC/AUD","bids":[{"price":101673.6,"qty":0.00202660}],"asks":[],"checksum":4214114189,"timestamp":"2024-06-01T17:52:00.763317Z"}]}
{"channel":"book","type":"update","data":[{"symbol":"BTC/AUD","bids":[],"asks":[{"price":101825.8,"qty":0.00000000},{"price":101850.6,"qty":0.01129070}],"checksum":4150814083,"timestamp":"2024-06-01T17:52:00.810668Z"}]}
{"channel":"book","type":"update","data":[{"symbol":"BTC/AUD","bids":[],"asks":[{"price":101825.8,"qty":0.00280126}],"checksum":2588170224,"timestamp":"2024-06-01T17:52:00.816475Z"}]}
{"channel":"book","type":"update","data":[{"symbol":"BTC/AUD","bids":[{"price":101673.5,"qty":0.04717373},{"price":101673.7,"qty":0.05388172}],"asks":[],"checksum":2907947156,"timestamp":"2024-06-01T17:52:01.111875Z"}]}
{"channel":"book","type":"update","data":[{"symbol":"BTC/AUD","bids":[{"price":101673.8,"qty":0.04717373}],"asks":[],"checksum":3558341346,"timestamp":"2024-06-01T17:52:01.116894Z"}]}
{"channel":"book","type":"update","data":[{"symbol":"BTC/AUD","bids":[{"price":101673.4,"qty":0.00000000},{"price":101627.7,"qty":0.02937000},{"price":101673.9,"qty":0.00308000}],"asks":[],"checksum":461711605,"timestamp":"2024-06-01T17:52:01.147371Z"}]}
{"channel":"book","type":"update","data":[{"symbol":"BTC/AUD","bids":[{"price":101673.5,"qty":0.00000000},{"price":101627.7,"qty":0.02937000}],"asks":[],"checksum":1339352304,"timestamp":"2024-06-01T17:52:01.152504Z"}]}
{"channel":"book","type":"update","data":[{"symbol":"BTC/AUD","bids":[],"asks":[{"price":101825.9,"qty":0.00000000},{"price":101850.6,"qty":0.01129070},{"price":101825.6,"qty":0.02937000}],"checksum":347942430,"timestamp":"2024-06-01T17:52:01.468906Z"}]}
{"channel":"book","type":"update","data":[{"symbol":"BTC/AUD","bids":[{"price":101673.9,"qty":0.15308000}],"asks":[],"checksum":403027461,"timestamp":"2024-06-01T17:52:01.643566Z"}]}
{"channel":"book","type":"update","data":[{"symbol":"BTC/AUD","bids":[{"price":101671.6,"qty":0.00000000},{"price":101627.6,"qty":0.00639000},{"price":101673.9,"qty":0.20364249}],"asks":[],"checksum":1969375067,"timestamp":"2024-06-01T17:52:01.666857Z"}]}
{"channel":"book","type":"update","data":[{"symbol":"BTC/AUD","bids":[{"price":101673.9,"qty":0.20056249},{"price":101674.0,"qty":0.00308000}],"asks":[],"checksum":750225872,"timestamp":"2024-06-01T17:52:01.667371Z"}]}
{"channel":"book","type":"update","data":[{"symbol":"BTC/AUD","bids":[{"price":101673.7,"qty":0.00000000},{"price":101627.6,"qty":0.00639000},{"price":101674.0,"qty":0.05696156}],"asks":[],"checksum":518719847,"timestamp":"2024-06-01T17:52:01.672020Z"}]}
{"channel":"book","type":"update","data":[{"symbol":"BTC/AUD","bids":[{"price":101673.9,"qty":0.15000000},{"price":101673.5,"qty":0.05056249}],"asks":[],"checksum":510742307,"timestamp":"2024-06-01T17:52:01.825360Z"}]}
{"channel":"book","type":"update","data":[{"symbol":"BTC/AUD","bids":[{"price":101674.1,"qty":0.15000000}],"asks":[],"checksum":2743227550,"timestamp":"2024-06-01T17:52:01.831180Z"}]}
{"channel":"book","type":"update","data":[{"symbol":"BTC/AUD","bids":[],"asks":[{"price":101784.5,"qty":0.00000000},{"price":101850.6,"qty":0.01129070},{"price":101789.3,"qty":0.00475100}],"checksum":1687834408,"timestamp":"2024-06-01T17:52:01.875791Z"}]}
{"channel":"book","type":"update","data":[{"symbol":"BTC/AUD","bids":[{"price":101673.9,"qty":0.00000000},{"price":101627.7,"qty":0.02937000}],"asks":[],"checksum":2052356081,"timestamp":"2024-06-01T17:52:01.880569Z"}]}
{"channel":"book","type":"update","data":[{"symbol":"BTC/AUD","bids":[],"asks":[{"price":101783.6,"qty":0.00000000},{"price":101850.6,"qty":0.01129070},{"price":101788.4,"qty":0.00075700}],"checksum":3818618255,"timestamp":"2024-06-01T17:52:01.884833Z"}]}
{"channel":"book","type":"update","data":[{"symbol":"BTC/AUD","bids":[{"price":101674.2,"qty":0.04717373}],"asks":[],"checksum":1039594223,"timestamp":"2024-06-01T17:52:02.178726Z"}]}
{"channel":"book","type":"update","data":[{"symbol":"BTC/AUD","bids":[{"price":101673.8,"qty":0.00000000},{"price":101627.7,"qty":0.02937000}],"asks":[],"checksum":1805378574,"timestamp":"2024-06-01T17:52:02.184226Z"}]}
{"channel":"book","type":"update","data":[{"symbol":"BTC/AUD","bids":[{"price":101674.3,"qty":0.15000000}],"asks":[],"checksum":1504123101,"timestamp":"2024-06-01T17:52:02.184390Z"}]}
{"channel":"book","type":"update","data":[{"symbol":"BTC/AUD","bids":[{"price":101674.0,"qty":0.00308000},{"price":101674.2,"qty":0.10105519}],"asks":[],"checksum":4293879273,"timestamp":"2024-06-01T17:52:02.190354Z"}]}
{"channel":"book","type":"update","data":[{"symbol":"BTC/AUD","bids":[{"price":101674.0,"qty":0.00000000},{"price":101627.7,"qty":0.02937000},{"price":101674.4,"qty":0.00308000}],"asks":[],"checksum":2203548064,"timestamp":"2024-06-01T17:52:02.215514Z"}]}
{"channel":"book","type":"update","data":[{"symbol":"BTC/AUD","bids":[{"price":101674.1,"qty":0.00000000},{"price":101627.7,"qty":0.02937000}],"asks":[],"checksum":3667236315,"timestamp":"2024-06-01T17:52:02.220559Z"}]}
{"channel":"book","type":"update","data":[{"symbol":"BTC/AUD","bids":[{"price":101627.7,"qty":0.00000000},{"price":101627.6,"qty":0.00639000},{"price":101659.4,"qty":0.02937000}],"asks":[],"checksum":2747988918,"timestamp":"2024-06-01T17:52:02.374651Z"}]}
{"channel":"book","type":"update","data":[{"symbol":"BTC/AUD","bids":[{"price":101674.2,"qty":0.04717373},{"price":101674.5,"qty":0.05388140}],"asks":[],"checksum":1371024986,"timestamp":"2024-06-01T17:52:02.740730Z"}]}
{"channel":"book","type":"update","data":[{"symbol":"BTC/AUD","bids":[{"price":101674.6,"qty":0.15000000}],"asks":[],"checksum":32557503,"timestamp":"2024-06-01T17:52:02.746282Z"}]}
{"channel":"book","type":"update","data":[{"symbol":"BTC/AUD","bids":[{"price":101674.4,"qty":0.00000000},{"price":101659.4,"qty":0.02937000},{"price":101674.7,"qty":0.00308000}],"asks":[],"checksum":2420375509,"timestamp":"2024-06-01T17:52:02.761329Z"}]}
{"channel":"book","type":"update","data":[{"symbol":"BTC/AUD","bids":[],"asks":[{"price":101825.8,"qty":0.00000000},{"price":101850.6,"qty":0.01129070}],"checksum":2224440088,"timestamp":"2024-06-01T17:52:02.969878Z"}]}
{"channel":"book","type":"update","data":[{"symbol":"BTC/AUD","bids":[],"asks":[{"price":101850.5,"qty":0.00167885}],"checksum":3395805094,"timestamp":"2024-06-01T17:52:02.974844Z"}]}
{"channel":"book","type":"update","data":[{"symbol":"BTC/AUD","bids":[],"asks":[{"price":101825.5,"qty":0.00314467}],"checksum":529426391,"timestamp":"2024-06-01T17:52:02.974927Z"}]}
{"channel":"book","type":"update","data":[{"symbol":"BTC/AUD","bids":[{"price":101674.3,"qty":0.00000000},{"price":101659.4,"qty":0.02937000}],"asks":[],"checksum":332976974,"timestamp":"2024-06-01T17:52:03.142940Z"}]}
{"channel":"book","type":"update","data":[{"symbol":"BTC/AUD","bids":[{"price":101674.8,"qty":0.04717373}],"asks":[],"checksum":51346337,"timestamp":"2024-06-01T17:52:03.148028Z"}]}
{"channel":"book","type":"update","data":[{"symbol":"BTC/AUD","bids":[{"price":101674.2,"qty":0.00000000},{"price":101659.4,"qty":0.02937000}],"asks":[],"checksum":1247480001,"timestamp":"2024-06-01T17:52:03.180145Z"}]}
{"channel":"book","type":"update","data":[{"symbol":"BTC/AUD","bids":[{"price":101674.7,"qty":0.00000000},{"price":101659.3,"qty":0.23807093},{"price":101674.9,"qty":0.00308000}],"asks":[],"checksum":3567369995,"timestamp":"2024-06-01T17:52:03.187288Z"}]}
{"channel":"book","type":"update","data":[{"symbol":"BTC/AUD","bids":[{"price":101673.2,"qty":0.00000000},{"price":101659.3,"qty":0.23807093}],"asks":[],"checksum":1944516811,"timestamp":"2024-06-01T17:52:03.233686Z"}]}
{"channel":"book","type":"update","data":[{"symbol":"BTC/AUD","bids":[{"price":101674.8,"qty":0.36522766}],"asks":[],"checksum":1636023925,"timestamp":"2024-06-01T17:52:03.234172Z"}]}
{"channel":"book","type":"update","data":[{"symbol":"BTC/AUD","bids":[{"price":101675.0,"qty":0.04717373}],"asks":[],"checksum":3845800514,"timestamp":"2024-06-01T17:52:03.240297Z"}]}
{"channel":"book","type":"update","data":[{"symbol":"BTC/AUD","bids":[{"price":101674.5,"qty":0.00000000},{"price":101659.3,"qty":0.23807093},{"price":101675.0,"qty":0.10105475}],"asks":[],"checksum":3730860157,"timestamp":"2024-06-01T17:52:03.250195Z"}]}
{"channel":"book","type":"update","data":[{"symbol":"BTC/AUD","bids":[],"asks":[{"price":101789.3,"qty":0.00000000},{"price":101850.5,"qty":0.00167885},{"price":101804.5,"qty":0.00475000}],"checksum":1586674128,"timestamp":"2024-06-01T17:52:03.287924Z"}]}
{"channel":"book","type":"update","data":[{"symbol":"BTC/AUD","bids":[{"price":101674.8,"qty":0.31805393}],"asks":[],"checksum":3390735342,"timestamp":"2024-06-01T17:52:03.293344Z"}]}
{"channel":"book","type":"update","data":[{"symbol":"BTC/AUD","bids":[],"asks":[{"price":101788.4,"qty":0.00000000},{"price":101850.5,"qty":0.00167885},{"price":101803.5,"qty":0.00075700}],"checksum":4284556520,"timestamp":"2024-06-01T17:52:03.319389Z"}]}
{"channel":"book","type":"update","data":[{"symbol":"BTC/AUD","bids":[],"asks":[{"price":101780.1,"qty":0.00000000},{"price":101850.5,"qty":0.00167885},{"price":101796.6,"qty":0.05384309}],"checksum":2271680543,"timestamp":"2024-06-01T17:52:03.380518Z"}]}
{"channel":"book","type":"update","data":[{"symbol":"BTC/AUD","bids":[],"asks":[{"price":101825.7,"qty":0.00000000},{"price":101850.5,"qty":0.00167885}],"checksum":1813671492,"timestamp":"2024-06-01T17:52:03.519678Z"}]}
{"channel":"book","type":"update","data":[{"symbol":"BTC/AUD","bids":[],"asks":[{"price":101825.4,"qty":0.32815476}],"checksum":4029341225,"timestamp":"2024-06-01T17:52:03.521681Z"}]}
{"channel":"book","type":"update","data":[{"symbol":"BTC/AUD","bids":[],"asks":[{"price":101825.6,"qty":0.00000000},{"price":101850.4,"qty":0.68676445},{"price":101825.9,"qty":0.02937000}],"checksum":127659482,"timestamp":"2024-06-01T17:52:03.522551Z"}]}
{"channel":"book","type":"update","data":[{"symbol":"BTC/AUD","bids":[{"price":101674.9,"qty":0.00000000},{"price":101627.6,"qty":0.00639000},{"price":101675.1,"qty":0.00308000}],"asks":[],"checksum":216278663,"timestamp":"2024-06-01T17:52:03.527954Z"}]}
{"channel":"book","type":"update","data":[{"symbol":"BTC/AUD","bids":[{"price":101673.6,"qty":0.00000000},{"price":101627.6,"qty":0.00639000}],"asks":[],"checksum":960254568,"timestamp":"2024-06-01T17:52:03.739064Z"}]}
{"channel":"book","type":"update","data":[{"symbol":"BTC/AUD","bids":[{"price":101675.1,"qty":0.00536801}],"asks":[],"checksum":3819917335,"timestamp":"2024-06-01T17:52:03.740358Z"}]}
{"channel":"book","type":"update","data":[{"symbol":"BTC/AUD","bids":[{"price":101675.1,"qty":0.15536801}],"asks":[],"checksum":1260838959,"timestamp":"2024-06-01T17:52:03.744691Z"}]}
{"channel":"book","type":"update","data":[{"symbol":"BTC/AUD","bids":[],"asks":[{"price":101796.6,"qty":0.00000000},{"price":101850.3,"qty":0.01129070},{"price":101780.1,"qty":0.05384309}],"checksum":1637864129,"timestamp":"2024-06-01T17:52:03.790485Z"}]}
{"channel":"book","type":"update","data":[{"symbol":"BTC/AUD","bids":[{"price":101675.0,"qty":0.04717373},{"price":101675.2,"qty":0.05388090}],"asks":[],"checksum":1943730029,"timestamp":"2024-06-01T17:52:03.790506Z"}]}
{"channel":"book","type":"update","data":[{"symbol":"BTC/AUD","bids":[{"price":101675.1,"qty":0.00536801}],"asks":[],"checksum":2370935204,"timestamp":"2024-06-01T17:52:03.796600Z"}]}
{"channel":"book","type":"update","data":[{"symbol":"BTC/AUD","bids":[],"asks":[{"price":101780.1,"qty":0.00000000},{"price":101850.3,"qty":0.01129070},{"price":101796.6,"qty":0.05384308}],"checksum":2254181949,"timestamp":"2024-06-01T17:52:03.845580Z"}]}
{"channel":"book","type":"update","data":[{"symbol":"BTC/AUD","bids":[{"price":101675.3,"qty":0.15000000}],"asks":[],"checksum":493216942,"timestamp":"2024-06-01T17:52:03.850756Z"}]}
{"channel":"book","type":"update","data":[{"symbol":"BTC/AUD","bids":[{"price":101674.6,"qty":0.00000000},{"price":101659.3,"qty":0.23807093}],"asks":[],"checksum":1330973351,"timestamp":"2024-06-01T17:52:04.143779Z"}]}
{"channel":"book","type":"update","data":[{"symbol":"BTC/AUD","bids":[],"asks":[{"price":101825.9,"qty":0.00000000},{"price":101850.3,"qty":0.01129070},{"price":101825.3,"qty":0.02937000}],"checksum":397154770,"timestamp":"2024-06-01T17:52:04.146579Z"}]}
{"channel":"book","type":"update","data":[{"symbol":"BTC/AUD","bids":[{"price":101675.4,"qty":0.04717373}],"asks":[],"checksum":2733142239,"timestamp":"2024-06-01T17:52:04.180042Z"}]}
{"channel":"book","type":"update","data":[{"symbol":"BTC/AUD","bids":[{"price":101675.0,"qty":0.00000000},{"price":101659.3,"qty":0.23807093}],"asks":[],"checksum":2197696027,"timestamp":"2024-06-01T17:52:04.184225Z"}]}
{"channel":"book","type":"update","data":[{"symbol":"BTC/AUD","bids":[{"price":101675.2,"qty":0.00000000},{"price":101627.6,"qty":0.00639000},{"price":101675.5,"qty":0.05388073}],"asks":[],"checksum":3310069127,"timestamp":"2024-06-01T17:52:04.355302Z"}]}
{"channel":"book","type":"update","data":[{"symbol":"BTC/AUD","bids":[],"asks":[{"price":101804.5,"qty":0.00000000},{"price":101850.3,"qty":0.01129070},{"price":101790.9,"qty":0.00475100}],"checksum":1875989884,"timestamp":"2024-06-01T17:52:04.520089Z"}]}
{"channel":"book","type":"update","data":[{"symbol":"BTC/AUD","bids":[],"asks":[{"price":101803.5,"qty":0.00000000},{"price":101850.3,"qty":0.01129070},{"price":101790.0,"qty":0.00075700}],"checksum":1444471361,"timestamp":"2024-06-01T17:52:04.531065Z"}]}
{"channel":"book","type":"update","data":[{"symbol":"BTC/AUD","bids":[{"price":101675.1,"qty":0.00228801},{"price":101675.6,"qty":0.00308000}],"asks":[],"checksum":2330403817,"timestamp":"2024-06-01T17:52:04.537463Z"}]}
{"channel":"book","type":"update","data":[{"symbol":"BTC/AUD","bids":[{"price":101675.5,"qty":0.00000000},{"price":101659.3,"qty":0.23807093},{"price":101675.7,"qty":0.05388061}],"asks":[],"checksum":1739249482,"timestamp":"2024-06-01T17:52:04.994414Z"}]}
{"channel":"book","type":"update","data":[{"symbol":"BTC/AUD","bids":[],"asks":[{"price":101796.6,"qty":0.00000000},{"price":101850.3,"qty":0.01129070},{"price":101780.1,"qty":0.05384287}],"checksum":3912328171,"timestamp":"2024-06-01T17:52:04.994464Z"}]}
{"channel":"book","type":"update","data":[{"symbol":"BTC/AUD","bids":[{"price":101675.8,"qty":0.04717373}],"asks":[],"checksum":3072311856,"timestamp":"2024-06-01T17:52:04.999307Z"}]}
{"channel":"book","type":"update","data":[{"symbol":"BTC/AUD","bids":[{"price":101675.8,"qty":0.19717373}],"asks":[],"checksum":4152412652,"timestamp":"2024-06-01T17:52:05.000041Z"}]}
{"channel":"book","type":"update","data":[{"symbol":"BTC/AUD","bids":[{"price":101675.6,"qty":0.00000000},{"price":101659.4,"qty":0.02937000},{"price":101675.9,"qty":0.00308000}],"asks":[],"checksum":592075761,"timestamp":"2024-06-01T17:52:05.023016Z"}]}
{"channel":"book","type":"update","data":[{"symbol":"BTC/AUD","bids":[],"asks":[{"price":101825.5,"qty":0.00000000},{"price":101850.3,"qty":0.01129070}],"checksum":1606884750,"timestamp":"2024-06-01T17:52:05.140802Z"}]}
{"channel":"book","type":"update","data":[{"symbol":"BTC/AUD","bids":[{"price":101675.3,"qty":0.00000000},{"price":101659.4,"qty":0.02937000}],"asks":[],"checksum":3780275743,"timestamp":"2024-06-01T17:52:05.142907Z"}]}
{"channel":"book","type":"update","data":[{"symbol":"BTC/AUD","bids":[],"asks":[{"price":101796.5,"qty":0.00029570}],"checksum":2681234579,"timestamp":"2024-06-01T17:52:05.147662Z"}]}
{"channel":"book","type":"update","data":[{"symbol":"BTC/AUD","bids":[],"asks":[{"price":101825.2,"qty":0.00345946}],"checksum":2239238001,"timestamp":"2024-06-01T17:52:05.147777Z"}]}
{"channel":"book","type":"update","data":[{"symbol":"BTC/AUD","bids":[{"price":101675.4,"qty":0.00000000},{"price":101659.3,"qty":0.23807093}],"asks":[],"checksum":1920398461,"timestamp":"2024-06-01T17:52:05.148499Z"}]}
{"channel":"book","type":"update","data":[{"symbol":"BTC/AUD","bids":[],"asks":[{"price":101790.9,"qty":0.00000000},{"price":101826.0,"qty":0.09768924},{"price":101800.5,"qty":0.00475100}],"checksum":2072669263,"timestamp":"2024-06-01T17:52:05.163788Z"}]}
{"channel":"book","type":"update","data":[{"symbol":"BTC/AUD","bids":[],"asks":[{"price":101790.0,"qty":0.00000000},{"price":101826.0,"qty":0.09768924},{"price":101799.6,"qty":0.00075700}],"checksum":1673133683,"timestamp":"2024-06-01T17:52:05.180327Z"}]}
{"channel":"book","type":"update","data":[{"symbol":"BTC/AUD","bids":[],"asks":[{"price":101780.1,"qty":0.00000000},{"price":101826.0,"qty":0.09768924},{"price":101796.4,"qty":0.05384287}],"checksum":2955483336,"timestamp":"2024-06-01T17:52:05.241376Z"}]}
{"channel":"book","type":"update","data":[{"symbol":"BTC/AUD","bids":[{"price":101675.7,"qty":0.00000000},{"price":101627.6,"qty":0.00639000},{"price":101676.0,"qty":0.05388045}],"asks":[],"checksum":1426445003,"timestamp":"2024-06-01T17:52:05.621415Z"}]}
{"channel":"book","type":"update","data":[{"symbol":"BTC/AUD","bids":[{"price":101675.9,"qty":0.00000000},{"price":101627.6,"qty":0.00639000},{"price":101676.1,"qty":0.00308000}],"asks":[],"checksum":1565215881,"timestamp":"2024-06-01T17:52:05.633457Z"}]}
{"channel":"book","type":"update","data":[{"symbol":"BTC/AUD","bids":[{"price":101676.1,"qty":0.15308000}],"asks":[],"checksum":1021149287,"timestamp":"2024-06-01T17:52:06.143221Z"}]}
{"channel":"book","type":"update","data":[{"symbol":"BTC/AUD","bids":[{"price":101675.8,"qty":0.04717373}],"asks":[],"checksum":4276103999,"timestamp":"2024-06-01T17:52:06.148584Z"}]}
{"channel":"book","type":"update","data":[{"symbol":"BTC/AUD","bids":[{"price":101676.2,"qty":0.04717373}],"asks":[],"checksum":1686048326,"timestamp":"2024-06-01T17:52:06.148817Z"}]}
{"channel":"book","type":"update","data":[{"symbol":"BTC/AUD","bids":[{"price":101676.1,"qty":0.15000000},{"price":101676.3,"qty":0.00308000}],"asks":[],"checksum":4171841974,"timestamp":"2024-06-01T17:52:06.179380Z"}]}
{"channel":"book","type":"update","data":[{"symbol":"BTC/AUD","bids":[{"price":101675.8,"qty":0.00000000},{"price":101659.4,"qty":0.02937000}],"asks":[],"checksum":525811792,"timestamp":"2024-06-01T17:52:06.179445Z"}]}
{"channel":"book","type":"update","data":[{"symbol":"BTC/AUD","bids":[{"price":101676.4,"qty":0.04717373}],"asks":[],"checksum":3410302101,"timestamp":"2024-06-01T17:52:06.183959Z"}]}
{"channel":"book","type":"update","data":[{"symbol":"BTC/AUD","bids":[{"price":101676.4,"qty":0.28520462}],"asks":[],"checksum":1734745635,"timestamp":"2024-06-01T17:52:06.185309Z"}]}
{"channel":"book","type":"update","data":[{"symbol":"BTC/AUD","bids":[{"price":101674.8,"qty":0.00000000},{"price":101634.1,"qty":0.02937000}],"asks":[],"checksum":4200483512,"timestamp":"2024-06-01T17:52:06.229753Z"}]}
{"channel":"book","type":"update","data":[{"symbol":"BTC/AUD","bids":[{"price":101676.2,"qty":0.36520824}],"asks":[],"checksum":1749923832,"timestamp":"2024-06-01T17:52:06.230982Z"}]}
{"channel":"book","type":"update","data":[{"symbol":"BTC/AUD","bids":[],"asks":[{"price":101825.4,"qty":0.00000000},{"price":101826.0,"qty":0.09768924}],"checksum":2037390178,"timestamp":"2024-06-01T17:52:06.233125Z"}]}
{"channel":"book","type":"update","data":[{"symbol":"BTC/AUD","bids":[{"price":101676.2,"qty":0.31803451}],"asks":[],"checksum":3193769200,"timestamp":"2024-06-01T17:52:06.235753Z"}]}
{"channel":"book","type":"update","data":[{"symbol":"BTC/AUD","bids":[],"asks":[{"price":101825.3,"qty":0.00000000},{"price":101850.3,"qty":0.01129070},{"price":101825.9,"qty":0.02937000}],"checksum":602261480,"timestamp":"2024-06-01T17:52:06.236919Z"}]}
{"channel":"book","type":"update","data":[{"symbol":"BTC/AUD","bids":[],"asks":[{"price":101825.1,"qty":0.16737670}],"checksum":2186094720,"timestamp":"2024-06-01T17:52:06.237244Z"}]}
{"channel":"book","type":"update","data":[{"symbol":"BTC/AUD","bids":[{"price":101634.1,"qty":0.00000000},{"price":101634.0,"qty":0.09768924}],"asks":[],"checksum":3705872294,"timestamp":"2024-06-01T17:52:06.270976Z"}]}
{"channel":"book","type":"update","data":[{"symbol":"BTC/AUD","bids":[{"price":101676.0,"qty":0.00000000},{"price":101627.6,"qty":0.00639000},{"price":101676.5,"qty":0.05387984}],"asks":[],"checksum":521285671,"timestamp":"2024-06-01T17:52:06.312547Z"}]}
{"channel":"book","type":"update","data":[{"symbol":"BTC/AUD","bids":[],"asks":[{"price":101796.4,"qty":0.00000000},{"price":101826.0,"qty":0.09768924},{"price":101780.1,"qty":0.05384286}],"checksum":3633088082,"timestamp":"2024-06-01T17:52:06.312640Z"}]}
{"channel":"book","type":"update","data":[{"symbol":"BTC/AUD","bids":[{"price":101672.0,"qty":0.00000000},{"price":101627.6,"qty":0.00639000},{"price":101676.4,"qty":0.28655762}],"asks":[],"checksum":3147926745,"timestamp":"2024-06-01T17:52:06.346984Z"}]}
{"channel":"book","type":"update","data":[{"symbol":"BTC/AUD","bids":[{"price":101676.3,"qty":0.00000000},{"price":101595.4,"qty":0.02950412},{"price":101676.6,"qty":0.00308000}],"asks":[],"checksum":3969943539,"timestamp":"2024-06-01T17:52:06.368801Z"}]}
{"channel":"book","type":"update","data":[{"symbol":"BTC/AUD","bids":[{"price":101675.1,"qty":0.00000000},{"price":101595.4,"qty":0.02950412}],"asks":[],"checksum":4287806851,"timestamp":"2024-06-01T17:52:06.660407Z"}]}
{"channel":"book","type":"update","data":[{"symbol":"BTC/AUD","bids":[{"price":101676.7,"qty":0.00231494}],"asks":[],"checksum":2334267293,"timestamp":"2024-06-01T17:52:06.661038Z"}]}
{"channel":"book","type":"update","data":[{"symbol":"BTC/AUD","bids":[],"asks":[{"price":101825.9,"qty":0.00000000},{"price":101826.0,"qty":0.09768924},{"price":101825.0,"qty":0.02937000}],"checksum":709657626,"timestamp":"2024-06-01T17:52:06.785605Z"}]}
{"channel":"book","type":"update","data":[{"symbol":"BTC/AUD","bids":[{"price":101639.1,"qty":0.02937000}],"asks":[],"checksum":1714513194,"timestamp":"2024-06-01T17:52:06.785736Z"}]}
{"channel":"book","type":"update","data":[{"symbol":"BTC/AUD","bids":[{"price":101676.5,"qty":0.00000000},{"price":101627.6,"qty":0.00639000},{"price":101676.8,"qty":0.05387959}],"asks":[],"checksum":599470644,"timestamp":"2024-06-01T17:52:06.992923Z"}]}
{"channel":"book","type":"update","data":[{"symbol":"BTC/AUD","bids":[{"price":101676.9,"qty":0.04717373}],"asks":[],"checksum":473189819,"timestamp":"2024-06-01T17:52:06.997827Z"}]}
{"channel":"book","type":"update","data":[{"symbol":"BTC/AUD","bids":[{"price":101676.9,"qty":0.19717373}],"asks":[],"checksum":1326179671,"timestamp":"2024-06-01T17:52:06.999303Z"}]}
{"channel":"book","type":"update","data":[{"symbol":"BTC/AUD","bids":[{"price":101676.6,"qty":0.00000000},{"price":101634.0,"qty":0.09768924},{"price":101677.0,"qty":0.00308000}],"asks":[],"checksum":746000177,"timestamp":"2024-06-01T17:52:07.006510Z"}]}
{"channel":"book","type":"update","data":[{"symbol":"BTC/AUD","bids":[{"price":101676.1,"qty":0.00000000},{"price":101634.0,"qty":0.09768924}],"asks":[],"checksum":4061362934,"timestamp":"2024-06-01T17:52:07.143166Z"}]}
{"channel":"book","type":"update","data":[{"symbol":"BTC/AUD","bids":[{"price":101676.4,"qty":0.23938389}],"asks":[],"checksum":12289789,"timestamp":"2024-06-01T17:52:07.178741Z"}]}
{"channel":"book","type":"update","data":[{"symbol":"BTC/AUD","bids":[{"price":101639.1,"qty":0.00000000},{"price":101627.6,"qty":0.00639000},{"price":101634.1,"qty":0.02937000}],"asks":[],"checksum":2603454108,"timestamp":"2024-06-01T17:52:07.334495Z"}]}
{"channel":"book","type":"update","data":[{"symbol":"BTC/AUD","bids":[],"asks":[{"price":101796.5,"qty":0.00000000},{"price":101826.0,"qty":0.09768924}],"checksum":3260578377,"timestamp":"2024-06-01T17:52:07.343766Z"}]}
{"channel":"book","type":"update","data":[{"symbol":"BTC/AUD","bids":[],"asks":[{"price":101825.2,"qty":0.00000000},{"price":101850.1,"qty":0.01129070}],"checksum":263943103,"timestamp":"2024-06-01T17:52:07.343912Z"}]}
{"channel":"book","type":"update","data":[{"symbol":"BTC/AUD","bids":[],"asks":[{"price":101824.9,"qty":0.00273765}],"checksum":1917560188,"timestamp":"2024-06-01T17:52:07.348748Z"}]}
{"channel":"book","type":"update","data":[{"symbol":"BTC/AUD","bids":[],"asks":[{"price":101780.1,"qty":0.00000000},{"price":101850.0,"qty":0.00101749},{"price":101796.6,"qty":0.05383957}],"checksum":414278711,"timestamp":"2024-06-01T17:52:07.482592Z"}]}
{"channel":"book","type":"update","data":[{"symbol":"BTC/AUD","bids":[{"price":101676.8,"qty":0.00000000},{"price":101627.6,"qty":0.00639000},{"price":101677.1,"qty":0.05387938}],"asks":[],"checksum":1029182301,"timestamp":"2024-06-01T17:52:07.642861Z"}]}
{"channel":"book","type":"update","data":[{"symbol":"BTC/AUD","bids":[],"asks":[{"price":101796.6,"qty":0.00000000},{"price":101850.0,"qty":0.00101749},{"price":101780.1,"qty":0.05383957}],"checksum":2773454978,"timestamp":"2024-06-01T17:52:07.642882Z"}]}
{"channel":"book","type":"update","data":[{"symbol":"BTC/AUD","bids":[{"price":101677.2,"qty":0.15000000}],"asks":[],"checksum":2675586587,"timestamp":"2024-06-01T17:52:07.648482Z"}]}
{"channel":"book","type":"update","data":[{"symbol":"BTC/AUD","bids":[{"price":101677.0,"qty":0.00000000},{"price":101634.0,"qty":0.09768924},{"price":101677.3,"qty":0.00308000}],"asks":[],"checksum":303059352,"timestamp":"2024-06-01T17:52:07.676426Z"}]}
{"channel":"book","type":"update","data":[{"symbol":"BTC/AUD","bids":[{"price":101676.9,"qty":0.04717373}],"asks":[],"checksum":693282409,"timestamp":"2024-06-01T17:52:07.681660Z"}]}
{"channel":"book","type":"update","data":[{"symbol":"BTC/AUD","bids":[],"asks":[{"price":101780.1,"qty":0.00000000},{"price":101850.0,"qty":0.00101749},{"price":101796.6,"qty":0.05383957}],"checksum":2974098870,"timestamp":"2024-06-01T17:52:07.774855Z"}]}
{"channel":"book","type":"update","data":[{"symbol":"BTC/AUD","bids":[{"price":101677.4,"qty":0.04717373}],"asks":[],"checksum":455561394,"timestamp":"2024-06-01T17:52:08.180008Z"}]}
{"channel":"book","type":"update","data":[{"symbol":"BTC/AUD","bids":[{"price":101676.9,"qty":0.00000000},{"price":101634.1,"qty":0.02937000}],"asks":[],"checksum":832323003,"timestamp":"2024-06-01T17:52:08.184640Z"}]}
{"channel":"book","type":"update","data":[{"symbol":"BTC/AUD","bids":[{"price":101677.5,"qty":0.15000000}],"asks":[],"checksum":372541406,"timestamp":"2024-06-01T17:52:08.185941Z"}]}
{"channel":"book","type":"update","data":[{"symbol":"BTC/AUD","bids":[{"price":101677.3,"qty":0.00000000},{"price":101634.1,"qty":0.02937000},{"price":101677.6,"qty":0.00308000}],"asks":[],"checksum":1182429734,"timestamp":"2024-06-01T17:52:08.196952Z"}]}
{"channel":"book","type":"update","data":[{"symbol":"BTC/AUD","bids":[{"price":101677.1,"qty":0.00000000},{"price":101634.1,"qty":0.02937000},{"price":101677.7,"qty":0.05387904}],"asks":[],"checksum":2107265202,"timestamp":"2024-06-01T17:52:08.388725Z"}]}
{"channel":"book","type":"update","data":[{"symbol":"BTC/AUD","bids":[],"asks":[{"price":101796.6,"qty":0.00000000},{"price":101850.0,"qty":0.00101749},{"price":101780.1,"qty":0.05383957}],"checksum":1802406004,"timestamp":"2024-06-01T17:52:08.388758Z"}]}
{"channel":"book","type":"update","data":[{"symbol":"BTC/AUD","bids":[{"price":101677.5,"qty":0.00000000},{"price":101634.1,"qty":0.02937000}],"asks":[],"checksum":1464224341,"timestamp":"2024-06-01T17:52:08.395726Z"}]}
{"channel":"book","type":"update","data":[{"symbol":"BTC/AUD","bids":[{"price":101677.6,"qty":0.00000000},{"price":101634.0,"qty":0.09768924},{"price":101677.8,"qty":0.00308000}],"asks":[],"checksum":2286565863,"timestamp":"2024-06-01T17:52:08.414126Z"}]}
{"channel":"book","type":"update","data":[{"symbol":"BTC/AUD","bids":[],"asks":[{"price":101780.1,"qty":0.00000000},{"price":101850.0,"qty":0.00101749},{"price":101796.6,"qty":0.05383946}],"checksum":2336782997,"timestamp":"2024-06-01T17:52:08.489640Z"}]}
{"channel":"book","type":"update","data":[{"symbol":"BTC/AUD","bids":[],"asks":[{"price":101825.1,"qty":0.00000000},{"price":101850.0,"qty":0.00101749}],"checksum":1619574263,"timestamp":"2024-06-01T17:52:09.015590Z"}]}
{"channel":"book","type":"update","data":[{"symbol":"BTC/AUD","bids":[],"asks":[{"price":101825.0,"qty":0.00000000},{"price":101850.1,"qty":0.01129070},{"price":101825.9,"qty":0.02937000}],"checksum":2375929081,"timestamp":"2024-06-01T17:52:09.019232Z"}]}
{"channel":"book","type":"update","data":[{"symbol":"BTC/AUD","bids":[],"asks":[{"price":101824.8,"qty":0.16737657}],"checksum":939456462,"timestamp":"2024-06-01T17:52:09.022758Z"}]}
{"channel":"book","type":"update","data":[{"symbol":"BTC/AUD","bids":[{"price":101677.8,"qty":0.15308000}],"asks":[],"checksum":1825908253,"timestamp":"2024-06-01T17:52:09.142892Z"}]}
{"channel":"book","type":"update","data":[{"symbol":"BTC/AUD","bids":[{"price":101677.2,"qty":0.00000000},{"price":101634.0,"qty":0.09768924}],"asks":[],"checksum":3292496604,"timestamp":"2024-06-01T17:52:09.147801Z"}]}
{"channel":"book","type":"update","data":[{"symbol":"BTC/AUD","bids":[{"price":101677.9,"qty":0.04717373}],"asks":[],"checksum":3593661884,"timestamp":"2024-06-01T17:52:09.147858Z"}]}
{"channel":"book","type":"update","data":[{"symbol":"BTC/AUD","bids":[{"price":101677.7,"qty":0.00000000},{"price":101634.0,"qty":0.09768924},{"price":101677.9,"qty":0.10105241}],"asks":[],"checksum":1642078740,"timestamp":"2024-06-01T17:52:09.155817Z"}]}
{"channel":"book","type":"update","data":[{"symbol":"BTC/AUD","bids":[{"price":101677.8,"qty":0.15000000},{"price":101678.0,"qty":0.00308000}],"asks":[],"checksum":1819737042,"timestamp":"2024-06-01T17:52:09.173209Z"}]}
{"channel":"book","type":"update","data":[{"symbol":"BTC/AUD","bids":[{"price":101677.4,"qty":0.00000000},{"price":101634.0,"qty":0.09768924}],"asks":[],"checksum":896733001,"timestamp":"2024-06-01T17:52:09.178090Z"}]}
{"channel":"book","type":"update","data":[{"symbol":"BTC/AUD","bids":[{"price":101678.0,"qty":0.15308000}],"asks":[],"checksum":1586622728,"timestamp":"2024-06-01T17:52:09.178562Z"}]}
{"channel":"book","type":"update","data":[{"symbol":"BTC/AUD","bids":[{"price":101676.2,"qty":0.00000000},{"price":101627.6,"qty":0.00639000}],"asks":[],"checksum":35473693,"timestamp":"2024-06-01T17:52:09.210891Z"}]}
{"channel":"book","type":"update","data":[{"symbol":"BTC/AUD","bids":[{"price":101677.9,"qty":0.41908151}],"asks":[],"checksum":2282422246,"timestamp":"2024-06-01T17:52:09.211996Z"}]}
{"channel":"book","type":"update","data":[{"symbol":"BTC/AUD","bids":[{"price":101677.8,"qty":0.00000000},{"price":101595.4,"qty":0.02950412}],"asks":[],"checksum":4043430742,"timestamp":"2024-06-01T17:52:09.216999Z"}]}
{"channel":"book","type":"update","data":[{"symbol":"BTC/AUD","bids":[{"price":101678.1,"qty":0.04717373}],"asks":[],"checksum":3954258360,"timestamp":"2024-06-01T17:52:09.217041Z"}]}
{"channel":"book","type":"update","data":[{"symbol":"BTC/AUD","bids":[],"asks":[{"price":101824.9,"qty":0.00000000},{"price":101849.8,"qty":0.01129070}],"checksum":4116242362,"timestamp":"2024-06-01T17:52:09.597074Z"}]}
{"channel":"book","type":"update","data":[{"symbol":"BTC/AUD","bids":[],"asks":[{"price":101824.7,"qty":0.00273765}],"checksum":3154705820,"timestamp":"2024-06-01T17:52:09.599312Z"}]}
{"channel":"book","type":"update","data":[{"symbol":"BTC/AUD","bids":[],"asks":[{"price":101825.9,"qty":0.00000000},{"price":101849.7,"qty":0.00096661},{"price":101824.7,"qty":0.03210765}],"checksum":2582530645,"timestamp":"2024-06-01T17:52:09.600066Z"}]}
{"channel":"book","type":"update","data":[{"symbol":"BTC/AUD","bids":[{"price":101678.0,"qty":0.15000000},{"price":101678.2,"qty":0.00308000}],"asks":[],"checksum":3253745642,"timestamp":"2024-06-01T17:52:09.631985Z"}]}
{"channel":"book","type":"update","data":[{"symbol":"BTC/AUD","bids":[{"price":101677.9,"qty":0.37190778}],"asks":[],"checksum":2944118801,"timestamp":"2024-06-01T17:52:09.637090Z"}]}
{"channel":"book","type":"update","data":[{"symbol":"BTC/AUD","bids":[{"price":101676.7,"qty":0.00000000},{"price":101627.6,"qty":0.00639000}],"asks":[],"checksum":224343150,"timestamp":"2024-06-01T17:52:09.640009Z"}]}
{"channel":"book","type":"update","data":[{"symbol":"BTC/AUD","bids":[{"price":101678.2,"qty":0.00548504}],"asks":[],"checksum":2142511563,"timestamp":"2024-06-01T17:52:09.641297Z"}]}
{"channel":"book","type":"update","data":[{"symbol":"BTC/AUD","bids":[{"price":101677.9,"qty":0.31802910},{"price":101678.3,"qty":0.05387844}],"asks":[],"checksum":3686027482,"timestamp":"2024-06-01T17:52:09.907050Z"}]}
{"channel":"book","type":"update","data":[{"symbol":"BTC/AUD","bids":[],"asks":[{"price":101796.6,"qty":0.00000000},{"price":101849.8,"qty":0.01129070},{"price":101780.1,"qty":0.05383945}],"checksum":4057320837,"timestamp":"2024-06-01T17:52:09.907182Z"}]}
{"channel":"book","type":"update","data":[{"symbol":"BTC/AUD","bids":[{"price":101678.4,"qty":0.15000000}],"asks":[],"checksum":3048964091,"timestamp":"2024-06-01T17:52:09.912368Z"}]}
{"channel":"book","type":"update","data":[{"symbol":"BTC/AUD","bids":[{"price":101678.0,"qty":0.00000000},{"price":101634.0,"qty":0.09768924}],"asks":[],"checksum":2693279049,"timestamp":"2024-06-01T17:52:10.143341Z"}]}
{"channel":"book","type":"update","data":[{"symbol":"BTC/AUD","bids":[{"price":101678.5,"qty":0.04717373}],"asks":[],"checksum":2872763572,"timestamp":"2024-06-01T17:52:10.152303Z"}]}
{"channel":"book","type":"update","data":[{"symbol":"BTC/AUD","bids":[{"price":101678.1,"qty":0.00000000},{"price":101634.0,"qty":0.09768924}],"asks":[],"checksum":3926980904,"timestamp":"2024-06-01T17:52:10.178866Z"}]}
{"channel":"book","type":"update","data":[{"symbol":"BTC/AUD","bids":[{"price":101678.2,"qty":0.00240504},{"price":101678.6,"qty":0.00308000}],"asks":[],"checksum":850206301,"timestamp":"2024-06-01T17:52:10.666910Z"}]}
{"channel":"book","type":"update","data":[{"symbol":"BTC/AUD","bids":[{"price":101678.3,"qty":0.00000000},{"price":101634.0,"qty":0.09768924},{"price":101678.7,"qty":0.05387638}],"asks":[],"checksum":1527796177,"timestamp":"2024-06-01T17:52:10.724609Z"}]}
{"channel":"book","type":"update","data":[{"symbol":"BTC/AUD","bids":[{"price":101678.8,"qty":0.15000000}],"asks":[],"checksum":2942260811,"timestamp":"2024-06-01T17:52:10.730844Z"}]}
{"channel":"book","type":"update","data":[{"symbol":"BTC/AUD","bids":[{"price":101678.6,"qty":0.00000000},{"price":101634.1,"qty":0.02937000},{"price":101678.9,"qty":0.00308000}],"asks":[],"checksum":2800833355,"timestamp":"2024-06-01T17:52:10.759679Z"}]}
{"channel":"book","type":"update","data":[{"symbol":"BTC/AUD","bids":[{"price":101678.4,"qty":0.00000000},{"price":101634.1,"qty":0.02937000}],"asks":[],"checksum":781836859,"timestamp":"2024-06-01T17:52:10.764778Z"}]}
{"channel":"book","type":"update","data":[{"symbol":"BTC/AUD","bids":[{"price":101679.0,"qty":0.04717373}],"asks":[],"checksum":232312486,"timestamp":"2024-06-01T17:52:11.179845Z"}]}
{"channel":"book","type":"update","data":[{"symbol":"BTC/AUD","bids":[{"price":101678.9,"qty":0.00000000},{"price":101634.1,"qty":0.02937000},{"price":101679.1,"qty":0.00308000}],"asks":[],"checksum":859912876,"timestamp":"2024-06-01T17:52:11.216171Z"}]}
{"channel":"book","type":"update","data":[{"symbol":"BTC/AUD","bids":[{"price":101678.5,"qty":0.00000000},{"price":101634.1,"qty":0.02937000}],"asks":[],"checksum":3682026613,"timestamp":"2024-06-01T17:52:11.221830Z"}]}
{"channel":"book","type":"update","data":[{"symbol":"BTC/AUD","bids":[{"price":101678.7,"qty":0.00000000},{"price":101634.0,"qty":0.09768924},{"price":101679.2,"qty":0.05387598}],"asks":[],"checksum":2725583208,"timestamp":"2024-06-01T17:52:11.502559Z"}]}
{"channel":"book","type":"update","data":[{"symbol":"BTC/AUD","bids":[],"asks":[{"price":101824.7,"qty":0.02937000}],"checksum":13398499,"timestamp":"2024-06-01T17:52:11.810819Z"}]}
{"channel":"book","type":"update","data":[{"symbol":"BTC/AUD","bids":[],"asks":[{"price":101824.6,"qty":0.00273765}],"checksum":163107963,"timestamp":"2024-06-01T17:52:11.815561Z"}]}
{"channel":"book","type":"update","data":[{"symbol":"BTC/AUD","bids":[{"price":101679.1,"qty":0.00000000},{"price":101634.0,"qty":0.09768924},{"price":101679.3,"qty":0.00308000}],"asks":[],"checksum":2342452171,"timestamp":"2024-06-01T17:52:11.827322Z"}]}
{"channel":"book","type":"update","data":[{"symbol":"BTC/AUD","bids":[{"price":101679.3,"qty":0.15308000}],"asks":[],"checksum":1452409895,"timestamp":"2024-06-01T17:52:11.832942Z"}]}
{"channel":"book","type":"update","data":[{"symbol":"BTC/AUD","bids":[],"asks":[{"price":101824.8,"qty":0.00000000},{"price":101849.7,"qty":0.00096661}],"checksum":2382169,"timestamp":"2024-06-01T17:52:11.838512Z"}]}
{"channel":"book","type":"update","data":[{"symbol":"BTC/AUD","bids":[],"asks":[{"price":101824.7,"qty":0.00000000},{"price":101849.8,"qty":0.01129070},{"price":101825.9,"qty":0.02937000}],"checksum":2948743172,"timestamp":"2024-06-01T17:52:11.841710Z"}]}
{"channel":"book","type":"update","data":[{"symbol":"BTC/AUD","bids":[],"asks":[{"price":101824.6,"qty":0.12417819}],"checksum":2857938829,"timestamp":"2024-06-01T17:52:11.843323Z"}]}
{"channel":"book","type":"update","data":[{"symbol":"BTC/AUD","bids":[{"price":101679.3,"qty":0.15000000},{"price":101679.4,"qty":0.00308000}],"asks":[],"checksum":3585270931,"timestamp":"2024-06-01T17:52:11.921104Z"}]}
{"channel":"book","type":"update","data":[{"symbol":"BTC/AUD","bids":[{"price":101678.8,"qty":0.00000000},{"price":101634.1,"qty":0.02937000}],"asks":[],"checksum":1904887174,"timestamp":"2024-06-01T17:52:11.926289Z"}]}
{"channel":"book","type":"update","data":[{"symbol":"BTC/AUD","bids":[{"price":101679.5,"qty":0.04717373}],"asks":[],"checksum":2435948363,"timestamp":"2024-06-01T17:52:11.926559Z"}]}
{"channel":"book","type":"update","data":[{"symbol":"BTC/AUD","bids":[{"price":101679.6,"qty":0.15000000}],"asks":[],"checksum":376092337,"timestamp":"2024-06-01T17:52:12.142929Z"}]}
{"channel":"book","type":"update","data":[{"symbol":"BTC/AUD","bids":[{"price":101679.3,"qty":0.00000000},{"price":101673.0,"qty":0.00551100}],"asks":[],"checksum":3316821873,"timestamp":"2024-06-01T17:52:12.147974Z"}]}
{"channel":"book","type":"update","data":[{"symbol":"BTC/AUD","bids":[{"price":101679.0,"qty":0.00000000},{"price":101634.1,"qty":0.02937000}],"asks":[],"checksum":3685803210,"timestamp":"2024-06-01T17:52:12.148164Z"}]}
{"channel":"book","type":"update","data":[{"symbol":"BTC/AUD","bids":[{"price":101679.7,"qty":0.04717373}],"asks":[],"checksum":1047498089,"timestamp":"2024-06-01T17:52:12.178646Z"}]}
{"channel":"book","type":"update","data":[{"symbol":"BTC/AUD","bids":[{"price":101679.5,"qty":0.00000000},{"price":101634.1,"qty":0.02937000}],"asks":[],"checksum":1996069988,"timestamp":"2024-06-01T17:52:12.183003Z"}]}
{"channel":"book","type":"update","data":[{"symbol":"BTC/AUD","bids":[{"price":101677.9,"qty":0.00000000},{"price":101634.0,"qty":0.09768924}],"asks":[],"checksum":2237278435,"timestamp":"2024-06-01T17:52:12.224148Z"}]}
{"channel":"book","type":"update","data":[{"symbol":"BTC/AUD","bids":[{"price":101679.6,"qty":0.46802680}],"asks":[],"checksum":4053360646,"timestamp":"2024-06-01T17:52:12.224676Z"}]}
{"channel":"book","type":"update","data":[{"symbol":"BTC/AUD","bids":[{"price":101679.2,"qty":0.00000000},{"price":101627.6,"qty":0.00639000},{"price":101679.8,"qty":0.05387567}],"asks":[],"checksum":4051055170,"timestamp":"2024-06-01T17:52:12.240331Z"}]}
{"channel":"book","type":"update","data":[{"symbol":"BTC/AUD","bids":[{"price":101679.4,"qty":0.00000000},{"price":101627.6,"qty":0.00639000},{"price":101679.9,"qty":0.00308000}],"asks":[],"checksum":3268945186,"timestamp":"2024-06-01T17:52:12.560763Z"}]}
{"channel":"book","type":"update","data":[{"symbol":"BTC/AUD","bids":[],"asks":[{"price":101825.9,"qty":0.00000000},{"price":101849.8,"qty":0.01129070},{"price":101824.5,"qty":0.02937000}],"checksum":3115001748,"timestamp":"2024-06-01T17:52:12.563298Z"}]}
{"channel":"book","type":"update","data":[{"symbol":"BTC/AUD","bids":[{"price":101678.2,"qty":0.00000000},{"price":101627.6,"qty":0.00639000}],"asks":[],"checksum":3711199132,"timestamp":"2024-06-01T17:52:12.669908Z"}]}
{"channel":"book","type":"update","data":[{"symbol":"BTC/AUD","bids":[{"price":101679.9,"qty":0.00548502}],"asks":[],"checksum":1453832439,"timestamp":"2024-06-01T17:52:12.670731Z"}]}
{"channel":"book","type":"update","data":[{"symbol":"BTC/AUD","bids":[{"price":101679.8,"qty":0.00000000},{"price":101606.8,"qty":0.02950081},{"price":101680.0,"qty":0.05387555}],"asks":[],"checksum":541012298,"timestamp":"2024-06-01T17:52:13.009749Z"}]}
{"channel":"book","type":"update","data":[{"symbol":"BTC/AUD","bids":[{"price":101680.1,"qty":0.04717373}],"asks":[],"checksum":188042015,"timestamp":"2024-06-01T17:52:13.015267Z"}]}
{"channel":"book","type":"update","data":[{"symbol":"BTC/AUD","bids":[{"price":101680.1,"qty":0.19717373}],"asks":[],"checksum":2771544302,"timestamp":"2024-06-01T17:52:13.015397Z"}]}
{"channel":"book","type":"update","data":[{"symbol":"BTC/AUD","bids":[{"price":101679.9,"qty":0.00240502},{"price":101680.2,"qty":0.00308000}],"asks":[],"checksum":1951744383,"timestamp":"2024-06-01T17:52:13.046901Z"}]}
{"channel":"book","type":"update","data":[{"symbol":"BTC/AUD","bids":[{"price":101679.6,"qty":0.31802680}],"asks":[],"checksum":123051843,"timestamp":"2024-06-01T17:52:13.051958Z"}]}
{"channel":"book","type":"update","data":[{"symbol":"BTC/AUD","bids":[{"price":101679.7,"qty":0.00000000},{"price":101634.0,"qty":0.09768924}],"asks":[],"checksum":3236039554,"timestamp":"2024-06-01T17:52:13.052019Z"}]}
{"channel":"book","type":"update","data":[{"symbol":"BTC/AUD","bids":[{"price":101673.0,"qty":0.00075700},{"price":101680.2,"qty":0.00783400}],"asks":[],"checksum":1625825474,"timestamp":"2024-06-01T17:52:13.181412Z"}]}
{"channel":"book","type":"update","data":[{"symbol":"BTC/AUD","bids":[{"price":101673.0,"qty":0.00000000},{"price":101627.6,"qty":0.00639000},{"price":101680.2,"qty":0.00859100}],"asks":[],"checksum":1251332268,"timestamp":"2024-06-01T17:52:13.191512Z"}]}
{"channel":"book","type":"update","data":[{"symbol":"BTC/AUD","bids":[{"price":101676.4,"qty":0.23803089},{"price":101680.3,"qty":0.00135300}],"asks":[],"checksum":4176445109,"timestamp":"2024-06-01T17:52:13.491237Z"}]}
{"channel":"book","type":"update","data":[{"symbol":"BTC/AUD","bids":[{"price":101680.0,"qty":0.00000000},{"price":101627.6,"qty":0.00639000},{"price":101680.4,"qty":0.05387532}],"asks":[],"checksum":668001118,"timestamp":"2024-06-01T17:52:13.739916Z"}]}
{"channel":"book","type":"update","data":[{"symbol":"BTC/AUD","bids":[{"price":101680.5,"qty":0.15000000}],"asks":[],"checksum":1360131533,"timestamp":"2024-06-01T17:52:13.745654Z"}]}
{"channel":"book","type":"update","data":[{"symbol":"BTC/AUD","bids":[{"price":101680.2,"qty":0.00551100},{"price":101680.6,"qty":0.00308000}],"asks":[],"checksum":1129888822,"timestamp":"2024-06-01T17:52:13.776476Z"}]}
{"channel":"book","type":"update","data":[{"symbol":"BTC/AUD","bids":[{"price":101680.1,"qty":0.04717373}],"asks":[],"checksum":1745367020,"timestamp":"2024-06-01T17:52:13.781274Z"}]}
{"channel":"book","type":"update","data":[{"symbol":"BTC/AUD","bids":[],"asks":[{"price":101849.7,"qty":0.00000000},{"price":101849.8,"qty":0.01129070}],"checksum":3545503499,"timestamp":"2024-06-01T17:52:14.052761Z"}]}
{"channel":"book","type":"update","data":[{"symbol":"BTC/AUD","bids":[],"asks":[{"price":101824.6,"qty":0.12144054}],"checksum":3025015112,"timestamp":"2024-06-01T17:52:14.052850Z"}]}
{"channel":"book","type":"update","data":[{"symbol":"BTC/AUD","bids":[],"asks":[{"price":101824.4,"qty":0.00253416}],"checksum":3082282452,"timestamp":"2024-06-01T17:52:14.054624Z"}]}
{"channel":"book","type":"update","data":[{"symbol":"BTC/AUD","bids":[{"price":101680.7,"qty":0.04717373}],"asks":[],"checksum":3440273445,"timestamp":"2024-06-01T17:52:14.179040Z"}]}
{"channel":"book","type":"update","data":[{"symbol":"BTC/AUD","bids":[{"price":101680.6,"qty":0.00000000},{"price":101673.5,"qty":0.05056249},{"price":101680.8,"qty":0.00308000}],"asks":[],"checksum":2359828633,"timestamp":"2024-06-01T17:52:14.202164Z"}]}
{"channel":"book","type":"update","data":[{"symbol":"BTC/AUD","bids":[{"price":101680.4,"qty":0.00000000},{"price":101673.5,"qty":0.05056249},{"price":101680.9,"qty":0.05387506}],"asks":[],"checksum":3655148707,"timestamp":"2024-06-01T17:52:14.425988Z"}]}
{"channel":"book","type":"update","data":[{"symbol":"BTC/AUD","bids":[{"price":101680.1,"qty":0.00000000},{"price":101673.5,"qty":0.05056249}],"asks":[],"checksum":3918214628,"timestamp":"2024-06-01T17:52:14.431163Z"}]}
{"channel":"book","type":"update","data":[{"symbol":"BTC/AUD","bids":[{"price":101680.8,"qty":0.00000000},{"price":101634.1,"qty":0.02937000},{"price":101681.0,"qty":0.00308000}],"asks":[],"checksum":2898949118,"timestamp":"2024-06-01T17:52:14.446366Z"}]}
{"channel":"book","type":"update","data":[{"symbol":"BTC/AUD","bids":[],"asks":[{"price":101824.6,"qty":0.00000000},{"price":101849.8,"qty":0.01129070}],"checksum":3806990299,"timestamp":"2024-06-01T17:52:14.663827Z"}]}
{"channel":"book","type":"update","data":[{"symbol":"BTC/AUD","bids":[],"asks":[{"price":101824.5,"qty":0.00000000},{"price":101853.1,"qty":0.00182164},{"price":101825.9,"qty":0.02937000}],"checksum":842437518,"timestamp":"2024-06-01T17:52:14.667056Z"}]}
{"channel":"book","type":"update","data":[{"symbol":"BTC/AUD","bids":[],"asks":[{"price":101824.3,"qty":0.14440806}],"checksum":3171230460,"timestamp":"2024-06-01T17:52:14.668276Z"}]}
{"channel":"book","type":"update","data":[{"symbol":"BTC/AUD","bids":[{"price":101681.0,"qty":0.15308000}],"asks":[],"checksum":2552881971,"timestamp":"2024-06-01T17:52:15.143713Z"}]}
{"channel":"book","type":"update","data":[{"symbol":"BTC/AUD","bids":[{"price":101680.5,"qty":0.00000000},{"price":101634.1,"qty":0.02937000}],"asks":[],"checksum":1868085619,"timestamp":"2024-06-01T17:52:15.148317Z"}]}
{"channel":"book","type":"update","data":[{"symbol":"BTC/AUD","bids":[{"price":101681.1,"qty":0.04717373}],"asks":[],"checksum":2477047980,"timestamp":"2024-06-01T17:52:15.150084Z"}]}
{"channel":"book","type":"update","data":[{"symbol":"BTC/AUD","bids":[{"price":101680.9,"qty":0.00000000},{"price":101634.1,"qty":0.02937000},{"price":101681.1,"qty":0.10104867}],"asks":[],"checksum":2312014810,"timestamp":"2024-06-01T17:52:15.151036Z"}]}
{"channel":"book","type":"update","data":[{"symbol":"BTC/AUD","bids":[{"price":101681.0,"qty":0.15000000},{"price":101681.2,"qty":0.00308000}],"asks":[],"checksum":1960535884,"timestamp":"2024-06-01T17:52:15.175286Z"}]}
{"channel":"book","type":"update","data":[{"symbol":"BTC/AUD","bids":[],"asks":[{"price":101825.9,"qty":0.00000000},{"price":101849.8,"qty":0.01129070},{"price":101824.2,"qty":0.02937000}],"checksum":2383593867,"timestamp":"2024-06-01T17:52:15.177915Z"}]}
{"channel":"book","type":"update","data":[{"symbol":"BTC/AUD","bids":[{"price":101680.7,"qty":0.00000000},{"price":101634.1,"qty":0.02937000}],"asks":[],"checksum":1957592957,"timestamp":"2024-06-01T17:52:15.179594Z"}]}
{"channel":"book","type":"update","data":[{"symbol":"BTC/AUD","bids":[{"price":101681.2,"qty":0.15308000}],"asks":[],"checksum":1866542942,"timestamp":"2024-06-01T17:52:15.180526Z"}]}
{"channel":"book","type":"update","data":[{"symbol":"BTC/AUD","bids":[{"price":101679.6,"qty":0.00000000},{"price":101634.0,"qty":0.09768924}],"asks":[],"checksum":2186796615,"timestamp":"2024-06-01T17:52:15.229430Z"}]}
{"channel":"book","type":"update","data":[{"symbol":"BTC/AUD","bids":[{"price":101681.1,"qty":0.41907394}],"asks":[],"checksum":2303016240,"timestamp":"2024-06-01T17:52:15.230716Z"}]}
{"channel":"book","type":"update","data":[{"symbol":"BTC/AUD","bids":[{"price":101681.3,"qty":0.04717373}],"asks":[],"checksum":1147426682,"timestamp":"2024-06-01T17:52:15.235877Z"}]}
{"channel":"book","type":"update","data":[{"symbol":"BTC/AUD","bids":[{"price":101681.0,"qty":0.00000000},{"price":101634.0,"qty":0.09768924}],"asks":[],"checksum":810959734,"timestamp":"2024-06-01T17:52:15.235933Z"}]}
{"channel":"book","type":"update","data":[{"symbol":"BTC/AUD","bids":[],"asks":[{"price":101780.3,"qty":0.00045608}],"checksum":821904003,"timestamp":"2024-06-01T17:52:15.446648Z"}]}
{"channel":"book","type":"update","data":[{"symbol":"BTC/AUD","bids":[{"price":101681.1,"qty":0.37190021}],"asks":[],"checksum":3243852822,"timestamp":"2024-06-01T17:52:15.451369Z"}]}
{"channel":"book","type":"update","data":[{"symbol":"BTC/AUD","bids":[{"price":101681.2,"qty":0.15000000},{"price":101681.4,"qty":0.00308000}],"asks":[],"checksum":815166361,"timestamp":"2024-06-01T17:52:15.452670Z"}]}
{"channel":"book","type":"update","data":[{"symbol":"BTC/AUD","bids":[],"asks":[{"price":101780.1,"qty":0.00000000},{"price":101849.8,"qty":0.01129070},{"price":101796.6,"qty":0.05383821}],"checksum":712243187,"timestamp":"2024-06-01T17:52:15.504953Z"}]}
{"channel":"book","type":"update","data":[{"symbol":"BTC/AUD","bids":[],"asks":[{"price":101783.2,"qty":0.00547000}],"checksum":1157792687,"timestamp":"2024-06-01T17:52:15.573966Z"}]}
{"channel":"book","type":"update","data":[{"symbol":"BTC/AUD","bids":[{"price":101679.9,"qty":0.00000000},{"price":101634.0,"qty":0.09768924}],"asks":[],"checksum":2097018230,"timestamp":"2024-06-01T17:52:15.605658Z"}]}
{"channel":"book","type":"update","data":[{"symbol":"BTC/AUD","bids":[{"price":101681.4,"qty":0.00548501}],"asks":[],"checksum":4061577516,"timestamp":"2024-06-01T17:52:15.607283Z"}]}
{"channel":"book","type":"update","data":[{"symbol":"BTC/AUD","bids":[{"price":101681.1,"qty":0.31802527},{"price":101681.5,"qty":0.05387471}],"asks":[],"checksum":1289054971,"timestamp":"2024-06-01T17:52:15.827498Z"}]}
{"channel":"book","type":"update","data":[{"symbol":"BTC/AUD","bids":[],"asks":[{"price":101796.6,"qty":0.00000000},{"price":101826.0,"qty":0.09768924},{"price":101780.1,"qty":0.05383821}],"checksum":3897584843,"timestamp":"2024-06-01T17:52:15.827527Z"}]}
{"channel":"book","type":"update","data":[{"symbol":"BTC/AUD","bids":[{"price":101681.6,"qty":0.15000000}],"asks":[],"checksum":490231044,"timestamp":"2024-06-01T17:52:15.832944Z"}]}
{"channel":"book","type":"update","data":[{"symbol":"BTC/AUD","bids":[],"asks":[{"price":101783.2,"qty":0.00000000},{"price":101826.0,"qty":0.09768924}],"checksum":3331839703,"timestamp":"2024-06-01T17:52:15.875419Z"}]}
{"channel":"book","type":"update","data":[{"symbol":"BTC/AUD","bids":[{"price":101681.2,"qty":0.00000000},{"price":101634.1,"qty":0.02937000}],"asks":[],"checksum":1645497009,"timestamp":"2024-06-01T17:52:15.880512Z"}]}
{"channel":"book","type":"update","data":[{"symbol":"BTC/AUD","bids":[],"asks":[{"price":101780.1,"qty":0.00000000},{"price":101849.8,"qty":0.01129070},{"price":101796.6,"qty":0.05383821}],"checksum":2959680768,"timestamp":"2024-06-01T17:52:15.924800Z"}]}
{"channel":"book","type":"update","data":[{"symbol":"BTC/AUD","bids":[{"price":101681.7,"qty":0.04717373}],"asks":[],"checksum":4263524140,"timestamp":"2024-06-01T17:52:15.930070Z"}]}
{"channel":"book","type":"update","data":[{"symbol":"BTC/AUD","bids":[{"price":101681.4,"qty":0.00240501},{"price":101681.8,"qty":0.00308000}],"asks":[],"checksum":712508945,"timestamp":"2024-06-01T17:52:16.035955Z"}]}
{"channel":"book","type":"update","data":[{"symbol":"BTC/AUD","bids":[{"price":101681.3,"qty":0.00000000},{"price":101673.5,"qty":0.05056249}],"asks":[],"checksum":533207553,"timestamp":"2024-06-01T17:52:16.040901Z"}]}
{"channel":"book","type":"update","data":[{"symbol":"BTC/AUD","bids":[],"asks":[{"price":101783.8,"qty":0.00483000}],"checksum":2835471461,"timestamp":"2024-06-01T17:52:16.166090Z"}]}
{"channel":"book","type":"update","data":[{"symbol":"BTC/AUD","bids":[],"asks":[{"price":101824.4,"qty":0.00000000},{"price":101826.0,"qty":0.09768924}],"checksum":1300453084,"timestamp":"2024-06-01T17:52:16.204847Z"}]}
{"channel":"book","type":"update","data":[{"symbol":"BTC/AUD","bids":[],"asks":[{"price":101824.1,"qty":0.00212714}],"checksum":2690313715,"timestamp":"2024-06-01T17:52:16.209532Z"}]}
{"channel":"book","type":"update","data":[{"symbol":"BTC/AUD","bids":[{"price":101681.5,"qty":0.00000000},{"price":101634.1,"qty":0.02937000},{"price":101681.9,"qty":0.05387449}],"asks":[],"checksum":237893937,"timestamp":"2024-06-01T17:52:16.530984Z"}]}
{"channel":"book","type":"update","data":[{"symbol":"BTC/AUD","bids":[],"asks":[{"price":101796.6,"qty":0.00000000},{"price":101826.0,"qty":0.09768924},{"price":101780.1,"qty":0.05383821}],"checksum":2612364999,"timestamp":"2024-06-01T17:52:16.531078Z"}]}
{"channel":"book","type":"update","data":[{"symbol":"BTC/AUD","bids":[{"price":101681.8,"qty":0.00000000},{"price":101634.1,"qty":0.02937000},{"price":101682.0,"qty":0.00308000}],"asks":[],"checksum":398242761,"timestamp":"2024-06-01T17:52:16.555716Z"}]}
{"channel":"book","type":"update","data":[{"symbol":"BTC/AUD","bids":[{"price":101682.0,"qty":0.15308000}],"asks":[],"checksum":3246735689,"timestamp":"2024-06-01T17:52:17.143042Z"}]}
{"channel":"book","type":"update","data":[{"symbol":"BTC/AUD","bids":[{"price":101681.6,"qty":0.00000000},{"price":101634.1,"qty":0.02937000}],"asks":[],"checksum":2629967457,"timestamp":"2024-06-01T17:52:17.147750Z"}]}
{"channel":"book","type":"update","data":[{"symbol":"BTC/AUD","bids":[{"price":101682.1,"qty":0.04717373}],"asks":[],"checksum":1030704384,"timestamp":"2024-06-01T17:52:17.150487Z"}]}
{"channel":"book","type":"update","data":[{"symbol":"BTC/AUD","bids":[{"price":101681.7,"qty":0.00000000},{"price":101634.1,"qty":0.02937000}],"asks":[],"checksum":3614953922,"timestamp":"2024-06-01T17:52:17.179338Z"}]}
{"channel":"book","type":"update","data":[{"symbol":"BTC/AUD","bids":[{"price":101682.0,"qty":0.15000000},{"price":101682.2,"qty":0.00308000}],"asks":[],"checksum":2616704773,"timestamp":"2024-06-01T17:52:17.192022Z"}]}
{"channel":"book","type":"update","data":[{"symbol":"BTC/AUD","bids":[],"asks":[{"price":101780.2,"qty":0.00000000},{"price":101826.0,"qty":0.09768924},{"price":101784.4,"qty":0.00135200}],"checksum":507985952,"timestamp":"2024-06-01T17:52:17.308027Z"}]}
{"channel":"book","type":"update","data":[{"symbol":"BTC/AUD","bids":[{"price":101681.9,"qty":0.00000000},{"price":101634.1,"qty":0.02937000},{"price":101682.3,"qty":0.05387481}],"asks":[],"checksum":3378448664,"timestamp":"2024-06-01T17:52:17.325660Z"}]}
{"channel":"book","type":"update","data":[{"symbol":"BTC/AUD","bids":[{"price":101682.2,"qty":0.00000000},{"price":101634.1,"qty":0.02937000},{"price":101682.4,"qty":0.00308000}],"asks":[],"checksum":3603697964,"timestamp":"2024-06-01T17:52:17.345259Z"}]}
{"channel":"book","type":"update","data":[{"symbol":"BTC/AUD","bids":[],"asks":[{"price":101780.1,"qty":0.00000000},{"price":101826.0,"qty":0.09768924},{"price":101783.7,"qty":0.05383754}],"checksum":672383612,"timestamp":"2024-06-01T17:52:17.370442Z"}]}
{"channel":"book","type":"update","data":[{"symbol":"BTC/AUD","bids":[],"asks":[{"price":101824.3,"qty":0.00000000},{"price":101826.0,"qty":0.09768924}],"checksum":1729825362,"timestamp":"2024-06-01T17:52:17.383097Z"}]}
{"channel":"book","type":"update","data":[{"symbol":"BTC/AUD","bids":[],"asks":[{"price":101824.2,"qty":0.00000000},{"price":101849.8,"qty":0.01129070},{"price":101825.9,"qty":0.02937000}],"checksum":3040841365,"timestamp":"2024-06-01T17:52:17.386456Z"}]}
{"channel":"book","type":"update","data":[{"symbol":"BTC/AUD","bids":[],"asks":[{"price":101824.0,"qty":0.09847056}],"checksum":85637343,"timestamp":"2024-06-01T17:52:17.389009Z"}]}
{"channel":"book","type":"update","data":[{"symbol":"BTC/AUD","bids":[],"asks":[{"price":101783.8,"qty":0.00000000},{"price":101826.0,"qty":0.09768924}],"checksum":611715404,"timestamp":"2024-06-01T17:52:17.470140Z"}]}
{"channel":"book","type":"update","data":[{"symbol":"BTC/AUD","bids":[],"asks":[{"price":101783.7,"qty":0.00000000},{"price":101849.8,"qty":0.01129070},{"price":101796.6,"qty":0.05383755}],"checksum":2344008581,"timestamp":"2024-06-01T17:52:17.521766Z"}]}
{"channel":"book","type":"update","data":[{"symbol":"BTC/AUD","bids":[],"asks":[{"price":101784.0,"qty":0.00631000}],"checksum":2889916775,"timestamp":"2024-06-01T17:52:17.608153Z"}]}
{"channel":"book","type":"update","data":[{"symbol":"BTC/AUD","bids":[],"asks":[{"price":101825.9,"qty":0.00000000},{"price":101826.0,"qty":0.09768924},{"price":101823.9,"qty":0.02937000}],"checksum":287633814,"timestamp":"2024-06-01T17:52:17.928106Z"}]}
{"channel":"book","type":"update","data":[{"symbol":"BTC/AUD","bids":[{"price":101682.3,"qty":0.00000000},{"price":101634.1,"qty":0.02937000},{"price":101682.5,"qty":0.05387471}],"asks":[],"checksum":4160595887,"timestamp":"2024-06-01T17:52:18.081818Z"}]}
{"channel":"book","type":"update","data":[{"symbol":"BTC/AUD","bids":[],"asks":[{"price":101796.6,"qty":0.00000000},{"price":101826.0,"qty":0.09768924},{"price":101783.9,"qty":0.05383755}],"checksum":3317310901,"timestamp":"2024-06-01T17:52:18.082173Z"}]}
{"channel":"book","type":"update","data":[{"symbol":"BTC/AUD","bids":[{"price":101682.6,"qty":0.15000000}],"asks":[],"checksum":1478456302,"timestamp":"2024-06-01T17:52:18.087164Z"}]}
{"channel":"book","type":"update","data":[{"symbol":"BTC/AUD","bids":[{"price":101682.6,"qty":0.19717373}],"asks":[],"checksum":1357095438,"timestamp":"2024-06-01T17:52:18.088312Z"}]}
{"channel":"book","type":"update","data":[{"symbol":"BTC/AUD","bids":[{"price":101682.4,"qty":0.00000000},{"price":101673.5,"qty":0.05056249},{"price":101682.7,"qty":0.00308000}],"asks":[],"checksum":635806801,"timestamp":"2024-06-01T17:52:18.108521Z"}]}
{"channel":"book","type":"update","data":[{"symbol":"BTC/AUD","bids":[{"price":101682.0,"qty":0.00000000},{"price":101673.5,"qty":0.05056249}],"asks":[],"checksum":1626659442,"timestamp":"2024-06-01T17:52:18.144578Z"}]}
{"channel":"book","type":"update","data":[{"symbol":"BTC/AUD","bids":[{"price":101682.1,"qty":0.00000000},{"price":101634.1,"qty":0.02937000}],"asks":[],"checksum":1451643004,"timestamp":"2024-06-01T17:52:18.150172Z"}]}
{"channel":"book","type":"update","data":[{"symbol":"BTC/AUD","bids":[{"price":101682.8,"qty":0.04717373}],"asks":[],"checksum":2821905849,"timestamp":"2024-06-01T17:52:18.178705Z"}]}
{"channel":"book","type":"update","data":[{"symbol":"BTC/AUD","bids":[{"price":101682.6,"qty":0.04717373}],"asks":[],"checksum":1722781457,"timestamp":"2024-06-01T17:52:18.183566Z"}]}
{"channel":"book","type":"update","data":[{"symbol":"BTC/AUD","bids":[{"price":101682.6,"qty":0.00000000},{"price":101634.1,"qty":0.02937000}],"asks":[],"checksum":3706502050,"timestamp":"2024-06-01T17:52:18.183788Z"}]}
{"channel":"book","type":"update","data":[{"symbol":"BTC/AUD","bids":[{"price":101681.1,"qty":0.00000000},{"price":101634.0,"qty":0.09768924}],"asks":[],"checksum":4213303036,"timestamp":"2024-06-01T17:52:18.223144Z"}]}
{"channel":"book","type":"update","data":[{"symbol":"BTC/AUD","bids":[{"price":101682.5,"qty":0.40072943}],"asks":[],"checksum":495668491,"timestamp":"2024-06-01T17:52:18.224553Z"}]}
{"channel":"book","type":"update","data":[{"symbol":"BTC/AUD","bids":[{"price":101634.1,"qty":0.00000000},{"price":101627.6,"qty":0.00639000},{"price":101673.6,"qty":0.02937000}],"asks":[],"checksum":286600077,"timestamp":"2024-06-01T17:52:18.258491Z"}]}
{"channel":"book","type":"update","data":[{"symbol":"BTC/AUD","bids":[],"asks":[{"price":101824.1,"qty":0.00000000},{"price":101826.0,"qty":0.09768924}],"checksum":739439873,"timestamp":"2024-06-01T17:52:18.305061Z"}]}
{"channel":"book","type":"update","data":[{"symbol":"BTC/AUD","bids":[],"asks":[{"price":101823.9,"qty":0.03129364}],"checksum":3258122760,"timestamp":"2024-06-01T17:52:18.307643Z"}]}
{"channel":"book","type":"update","data":[{"symbol":"BTC/AUD","bids":[{"price":101681.4,"qty":0.00000000},{"price":101627.6,"qty":0.00639000}],"asks":[],"checksum":886378717,"timestamp":"2024-06-01T17:52:18.607088Z"}]}
{"channel":"book","type":"update","data":[{"symbol":"BTC/AUD","bids":[{"price":101682.9,"qty":0.00240496}],"asks":[],"checksum":3462617838,"timestamp":"2024-06-01T17:52:18.607550Z"}]}
{"channel":"book","type":"update","data":[{"symbol":"BTC/AUD","bids":[{"price":101682.7,"qty":0.00000000},{"price":101627.6,"qty":0.00639000},{"price":101683.0,"qty":0.00308000}],"asks":[],"checksum":3155126241,"timestamp":"2024-06-01T17:52:18.628827Z"}]}
{"channel":"book","type":"update","data":[{"symbol":"BTC/AUD","bids":[],"asks":[{"price":101784.0,"qty":0.00000000},{"price":101849.8,"qty":0.01129070}],"checksum":3112200126,"timestamp":"2024-06-01T17:52:18.638702Z"}]}
{"channel":"book","type":"update","data":[{"symbol":"BTC/AUD","bids":[],"asks":[{"price":101783.9,"qty":0.00000000},{"price":101852.7,"qty":0.00228935},{"price":101796.6,"qty":0.05383732}],"checksum":3495590179,"timestamp":"2024-06-01T17:52:18.693027Z"}]}
{"channel":"book","type":"update","data":[{"symbol":"BTC/AUD","bids":[],"asks":[{"price":101785.1,"qty":0.00464000}],"checksum":3740390872,"timestamp":"2024-06-01T17:52:18.743871Z"}]}
{"channel":"book","type":"update","data":[{"symbol":"BTC/AUD","bids":[{"price":101682.5,"qty":0.34685472},{"price":101683.1,"qty":0.05387437}],"asks":[],"checksum":1385381550,"timestamp":"2024-06-01T17:52:18.893116Z"}]}
{"channel":"book","type":"update","data":[{"symbol":"BTC/AUD","bids":[],"asks":[{"price":101796.6,"qty":0.00000000},{"price":101849.8,"qty":0.01129070},{"price":101784.3,"qty":0.05383732}],"checksum":3215123118,"timestamp":"2024-06-01T17:52:18.893173Z"}]}
{"channel":"book","type":"update","data":[{"symbol":"BTC/AUD","bids":[{"price":101683.2,"qty":0.04717373}],"asks":[],"checksum":2009938373,"timestamp":"2024-06-01T17:52:19.178357Z"}]}
{"channel":"book","type":"update","data":[{"symbol":"BTC/AUD","bids":[{"price":101683.0,"qty":0.00000000},{"price":101673.5,"qty":0.05056249},{"price":101683.3,"qty":0.00308000}],"asks":[],"checksum":2113165622,"timestamp":"2024-06-01T17:52:19.209130Z"}]}
{"channel":"book","type":"update","data":[{"symbol":"BTC/AUD","bids":[{"price":101682.8,"qty":0.00000000},{"price":101673.5,"qty":0.05056249}],"asks":[],"checksum":2490948018,"timestamp":"2024-06-01T17:52:19.214093Z"}]}
{"channel":"book","type":"update","data":[{"symbol":"BTC/AUD","bids":[{"price":101673.6,"qty":0.00000000},{"price":101634.0,"qty":0.09768924},{"price":101676.5,"qty":0.02937000}],"asks":[],"checksum":962795965,"timestamp":"2024-06-01T17:52:19.377520Z"}]}
{"channel":"book","type":"update","data":[{"symbol":"BTC/AUD","bids":[{"price":101683.3,"qty":0.15308000}],"asks":[],"checksum":2044034571,"timestamp":"2024-06-01T17:52:19.644222Z"}]}
{"channel":"book","type":"update","data":[{"symbol":"BTC/AUD","bids":[{"price":101683.3,"qty":0.15000000},{"price":101683.4,"qty":0.00308000}],"asks":[],"checksum":3981933522,"timestamp":"2024-06-01T17:52:19.665773Z"}]}
{"channel":"book","type":"update","data":[{"symbol":"BTC/AUD","bids":[{"price":101683.1,"qty":0.00000000},{"price":101673.5,"qty":0.05056249},{"price":101683.5,"qty":0.05387413}],"asks":[],"checksum":258172359,"timestamp":"2024-06-01T17:52:19.723534Z"}]}
{"channel":"book","type":"update","data":[{"symbol":"BTC/AUD","bids":[{"price":101683.6,"qty":0.15000000}],"asks":[],"checksum":4280930425,"timestamp":"2024-06-01T17:52:19.729060Z"}]}
{"channel":"book","type":"update","data":[{"symbol":"BTC/AUD","bids":[],"asks":[{"price":101785.1,"qty":0.00000000},{"price":101849.8,"qty":0.01129070}],"checksum":588722777,"timestamp":"2024-06-01T17:52:19.806227Z"}]}
{"channel":"book","type":"update","data":[{"symbol":"BTC/AUD","bids":[{"price":101683.3,"qty":0.00000000},{"price":101676.4,"qty":0.23803089}],"asks":[],"checksum":1692279006,"timestamp":"2024-06-01T17:52:19.811385Z"}]}
{"channel":"book","type":"update","data":[{"symbol":"BTC/AUD","bids":[],"asks":[{"price":101784.3,"qty":0.00000000},{"price":101852.7,"qty":0.00228935},{"price":101796.6,"qty":0.05383731}],"checksum":2540107600,"timestamp":"2024-06-01T17:52:19.860766Z"}]}
{"channel":"book","type":"update","data":[{"symbol":"BTC/AUD","bids":[],"asks":[{"price":101785.3,"qty":0.00563000}],"checksum":2896083180,"timestamp":"2024-06-01T17:52:19.904300Z"}]}
{"channel":"book","type":"update","data":[{"symbol":"BTC/AUD","bids":[{"price":101676.5,"qty":0.00000000},{"price":101673.5,"qty":0.05056249},{"price":101680.3,"qty":0.03072300}],"asks":[],"checksum":917225375,"timestamp":"2024-06-01T17:52:19.966468Z"}]}
{"channel":"book","type":"update","data":[{"symbol":"BTC/AUD","bids":[],"asks":[{"price":101824.0,"qty":0.00000000},{"price":101849.8,"qty":0.01129070}],"checksum":395179264,"timestamp":"2024-06-01T17:52:20.144752Z"}]}
{"channel":"book","type":"update","data":[{"symbol":"BTC/AUD","bids":[],"asks":[{"price":101823.9,"qty":0.00192364},{"price":101825.9,"qty":0.02937000}],"checksum":2947888390,"timestamp":"2024-06-01T17:52:20.148008Z"}]}
{"channel":"book","type":"update","data":[{"symbol":"BTC/AUD","bids":[],"asks":[{"price":101823.8,"qty":0.12143894}],"checksum":1816795530,"timestamp":"2024-06-01T17:52:20.149269Z"}]}
{"channel":"book","type":"update","data":[{"symbol":"BTC/AUD","bids":[{"price":101683.7,"qty":0.04717373}],"asks":[],"checksum":832448287,"timestamp":"2024-06-01T17:52:20.179608Z"}]}
{"channel":"book","type":"update","data":[{"symbol":"BTC/AUD","bids":[{"price":101683.8,"qty":0.15000000}],"asks":[],"checksum":3154333338,"timestamp":"2024-06-01T17:52:20.184991Z"}]}
{"channel":"book","type":"update","data":[{"symbol":"BTC/AUD","bids":[{"price":101683.2,"qty":0.00000000},{"price":101676.4,"qty":0.23803089}],"asks":[],"checksum":4122465224,"timestamp":"2024-06-01T17:52:20.185245Z"}]}
{"channel":"book","type":"update","data":[{"symbol":"BTC/AUD","bids":[],"asks":[{"price":101785.3,"qty":0.00000000},{"price":101826.0,"qty":0.09768924}],"checksum":1593373967,"timestamp":"2024-06-01T17:52:20.374095Z"}]}
{"channel":"book","type":"update","data":[{"symbol":"BTC/AUD","bids":[{"price":101683.6,"qty":0.00000000},{"price":101673.5,"qty":0.05056249}],"asks":[],"checksum":2609849700,"timestamp":"2024-06-01T17:52:20.379411Z"}]}
{"channel":"book","type":"update","data":[{"symbol":"BTC/AUD","bids":[],"asks":[{"price":101823.9,"qty":0.00000000},{"price":101849.6,"qty":0.01129070}],"checksum":1797763247,"timestamp":"2024-06-01T17:52:20.488316Z"}]}
{"channel":"book","type":"update","data":[{"symbol":"BTC/AUD","bids":[{"price":101680.3,"qty":0.00135300},{"price":101682.6,"qty":0.02937000}],"asks":[],"checksum":129081695,"timestamp":"2024-06-01T17:52:20.491684Z"}]}
{"channel":"book","type":"update","data":[{"symbol":"BTC/AUD","bids":[],"asks":[{"price":101823.8,"qty":0.12376958}],"checksum":2285663545,"timestamp":"2024-06-01T17:52:20.493143Z"}]}
{"channel":"book","type":"update","data":[{"symbol":"BTC/AUD","bids":[],"asks":[{"price":101785.6,"qty":0.00549000}],"checksum":4013419052,"timestamp":"2024-06-01T17:52:20.518148Z"}]}
{"channel":"book","type":"update","data":[{"symbol":"BTC/AUD","bids":[],"asks":[{"price":101796.6,"qty":0.00000000},{"price":101849.6,"qty":0.01129070},{"price":101784.3,"qty":0.05383744}],"checksum":418339052,"timestamp":"2024-06-01T17:52:20.573911Z"}]}
{"channel":"book","type":"update","data":[{"symbol":"BTC/AUD","bids":[],"asks":[{"price":101785.6,"qty":0.00000000},{"price":101849.6,"qty":0.01129070}],"checksum":1744246771,"timestamp":"2024-06-01T17:52:20.575578Z"}]}
{"channel":"book","type":"update","data":[{"symbol":"BTC/AUD","bids":[],"asks":[{"price":101786.4,"qty":0.00569000}],"checksum":2391039521,"timestamp":"2024-06-01T17:52:20.748210Z"}]}
{"channel":"book","type":"update","data":[{"symbol":"BTC/AUD","bids":[],"asks":[{"price":101825.9,"qty":0.00000000},{"price":101849.6,"qty":0.01129070},{"price":101823.7,"qty":0.02937000}],"checksum":1500895557,"timestamp":"2024-06-01T17:52:20.750867Z"}]}
{"channel":"book","type":"update","data":[{"symbol":"BTC/AUD","bids":[{"price":101683.4,"qty":0.00000000},{"price":101673.5,"qty":0.05056249},{"price":101683.9,"qty":0.00308000}],"asks":[],"checksum":1783837414,"timestamp":"2024-06-01T17:52:20.771667Z"}]}
{"channel":"book","type":"update","data":[{"symbol":"BTC/AUD","bids":[{"price":101682.6,"qty":0.00000000},{"price":101673.5,"qty":0.05056249},{"price":101683.9,"qty":0.03245000}],"asks":[],"checksum":2063452388,"timestamp":"2024-06-01T17:52:21.115455Z"}]}
{"channel":"book","type":"update","data":[{"symbol":"BTC/AUD","bids":[{"price":101684.0,"qty":0.04717373}],"asks":[],"checksum":903711401,"timestamp":"2024-06-01T17:52:21.120582Z"}]}
{"channel":"book","type":"update","data":[{"symbol":"BTC/AUD","bids":[{"price":101684.0,"qty":0.19717373}],"asks":[],"checksum":1772219559,"timestamp":"2024-06-01T17:52:21.121416Z"}]}
{"channel":"book","type":"update","data":[{"symbol":"BTC/AUD","bids":[{"price":101683.9,"qty":0.02937000},{"price":101684.1,"qty":0.00308000}],"asks":[],"checksum":1306284151,"timestamp":"2024-06-01T17:52:21.136731Z"}]}
{"channel":"book","type":"update","data":[{"symbol":"BTC/AUD","bids":[{"price":101683.8,"qty":0.00000000},{"price":101676.4,"qty":0.23803089}],"asks":[],"checksum":3399306790,"timestamp":"2024-06-01T17:52:21.143410Z"}]}
{"channel":"book","type":"update","data":[{"symbol":"BTC/AUD","bids":[{"price":101683.7,"qty":0.00000000},{"price":101673.5,"qty":0.05056249}],"asks":[],"checksum":2834685537,"timestamp":"2024-06-01T17:52:21.179027Z"}]}
{"channel":"book","type":"update","data":[{"symbol":"BTC/AUD","bids":[{"price":101684.2,"qty":0.04717373}],"asks":[],"checksum":1200762573,"timestamp":"2024-06-01T17:52:21.185289Z"}]}
{"channel":"book","type":"update","data":[{"symbol":"BTC/AUD","bids":[{"price":101676.4,"qty":0.00000000},{"price":101673.5,"qty":0.05056249}],"asks":[],"checksum":634900424,"timestamp":"2024-06-01T17:52:21.188081Z"}]}
{"channel":"book","type":"update","data":[{"symbol":"BTC/AUD","bids":[{"price":101684.3,"qty":0.23801240}],"asks":[],"checksum":4128276946,"timestamp":"2024-06-01T17:52:21.190898Z"}]}
{"channel":"book","type":"update","data":[{"symbol":"BTC/AUD","bids":[{"price":101682.5,"qty":0.00000000},{"price":101673.5,"qty":0.05056249}],"asks":[],"checksum":726651661,"timestamp":"2024-06-01T17:52:21.222837Z"}]}
{"channel":"book","type":"update","data":[{"symbol":"BTC/AUD","bids":[{"price":101684.0,"qty":0.54402825}],"asks":[],"checksum":1682882264,"timestamp":"2024-06-01T17:52:21.224615Z"}]}
{"channel":"book","type":"update","data":[{"symbol":"BTC/AUD","bids":[{"price":101684.0,"qty":0.49685452}],"asks":[],"checksum":3000701883,"timestamp":"2024-06-01T17:52:21.229744Z"}]}
{"channel":"book","type":"update","data":[{"symbol":"BTC/AUD","bids":[{"price":101684.4,"qty":0.15000000}],"asks":[],"checksum":64071643,"timestamp":"2024-06-01T17:52:21.229856Z"}]}
{"channel":"book","type":"update","data":[{"symbol":"BTC/AUD","bids":[{"price":101680.3,"qty":0.00000000},{"price":101673.5,"qty":0.05056249},{"price":101684.0,"qty":0.49820752}],"asks":[],"checksum":3523379720,"timestamp":"2024-06-01T17:52:21.238719Z"}]}
{"channel":"book","type":"update","data":[{"symbol":"BTC/AUD","bids":[{"price":101683.9,"qty":0.00000000},{"price":101634.0,"qty":0.09768924}],"asks":[],"checksum":2945377298,"timestamp":"2024-06-01T17:52:21.359694Z"}]}
{"channel":"book","type":"update","data":[{"symbol":"BTC/AUD","bids":[{"price":101683.5,"qty":0.00000000},{"price":101627.6,"qty":0.00639000},{"price":101684.5,"qty":0.05387433}],"asks":[],"checksum":3928269639,"timestamp":"2024-06-01T17:52:21.437084Z"}]}
{"channel":"book","type":"update","data":[{"symbol":"BTC/AUD","bids":[{"price":101684.4,"qty":0.00000000},{"price":101627.6,"qty":0.00639000}],"asks":[],"checksum":2190863099,"timestamp":"2024-06-01T17:52:21.442572Z"}]}
{"channel":"book","type":"update","data":[{"symbol":"BTC/AUD","bids":[{"price":101684.1,"qty":0.00000000},{"price":101606.8,"qty":0.02950081},{"price":101684.6,"qty":0.00308000}],"asks":[],"checksum":853750521,"timestamp":"2024-06-01T17:52:21.445532Z"}]}
{"channel":"book","type":"update","data":[{"symbol":"BTC/AUD","bids":[{"price":101682.9,"qty":0.00000000},{"price":101606.8,"qty":0.02950081}],"asks":[],"checksum":1384743280,"timestamp":"2024-06-01T17:52:21.557584Z"}]}
{"channel":"book","type":"update","data":[{"symbol":"BTC/AUD","bids":[{"price":101684.5,"qty":0.05618910}],"asks":[],"checksum":1706933311,"timestamp":"2024-06-01T17:52:21.558512Z"}]}
{"channel":"book","type":"update","data":[{"symbol":"BTC/AUD","bids":[{"price":101673.4,"qty":0.02937000}],"asks":[],"checksum":39345568,"timestamp":"2024-06-01T17:52:21.664041Z"}]}
{"channel":"book","type":"update","data":[{"symbol":"BTC/AUD","bids":[],"asks":[{"price":101786.4,"qty":0.00000000},{"price":101849.6,"qty":0.01129070}],"checksum":2382294824,"timestamp":"2024-06-01T17:52:21.963553Z"}]}
{"channel":"book","type":"update","data":[{"symbol":"BTC/AUD","bids":[{"price":101684.7,"qty":0.04717373}],"asks":[],"checksum":2802155673,"timestamp":"2024-06-01T17:52:21.968766Z"}]}
{"channel":"book","type":"update","data":[{"symbol":"BTC/AUD","bids":[{"price":101684.6,"qty":0.15308000}],"asks":[],"checksum":838246980,"timestamp":"2024-06-01T17:52:21.969200Z"}]}
{"channel":"book","type":"update","data":[{"symbol":"BTC/AUD","bids":[{"price":101684.6,"qty":0.15000000},{"price":101684.8,"qty":0.00308000}],"asks":[],"checksum":670098426,"timestamp":"2024-06-01T17:52:21.992429Z"}]}
{"channel":"book","type":"update","data":[{"symbol":"BTC/AUD","bids":[],"asks":[{"price":101784.3,"qty":0.00000000},{"price":101849.7,"qty":0.16737502},{"price":101796.6,"qty":0.05383747}],"checksum":1994811397,"timestamp":"2024-06-01T17:52:22.029401Z"}]}
{"channel":"book","type":"update","data":[{"symbol":"BTC/AUD","bids":[{"price":101684.2,"qty":0.00000000},{"price":101634.0,"qty":0.09768924}],"asks":[],"checksum":3924155897,"timestamp":"2024-06-01T17:52:22.034857Z"}]}
{"channel":"book","type":"update","data":[{"symbol":"BTC/AUD","bids":[{"price":101684.6,"qty":0.00000000},{"price":101627.6,"qty":0.00639000}],"asks":[],"checksum":236645856,"timestamp":"2024-06-01T17:52:22.038704Z"}]}
{"channel":"book","type":"update","data":[{"symbol":"BTC/AUD","bids":[],"asks":[{"price":101792.1,"qty":0.00544000}],"checksum":3838680584,"timestamp":"2024-06-01T17:52:22.241360Z"}]}
{"channel":"book","type":"update","data":[{"symbol":"BTC/AUD","bids":[{"price":101673.4,"qty":0.00000000},{"price":101606.8,"qty":0.02950081},{"price":101673.6,"qty":0.02937000}],"asks":[],"checksum":3348604490,"timestamp":"2024-06-01T17:52:22.244058Z"}]}
{"channel":"book","type":"update","data":[{"symbol":"BTC/AUD","bids":[{"price":101684.5,"qty":0.00231477},{"price":101684.9,"qty":0.05387413}],"asks":[],"checksum":593719381,"timestamp":"2024-06-01T17:52:22.268515Z"}]}
{"channel":"book","type":"update","data":[{"symbol":"BTC/AUD","bids":[{"price":101684.8,"qty":0.00000000},{"price":101627.6,"qty":0.00639000},{"price":101685.0,"qty":0.00308000}],"asks":[],"checksum":1969768401,"timestamp":"2024-06-01T17:52:22.299378Z"}]}
{"channel":"book","type":"update","data":[{"symbol":"BTC/AUD","bids":[],"asks":[{"price":101792.1,"qty":0.00000000},{"price":101849.6,"qty":0.01129070}],"checksum":2680108089,"timestamp":"2024-06-01T17:52:22.306220Z"}]}
{"channel":"book","type":"update","data":[{"symbol":"BTC/AUD","bids":[],"asks":[{"price":101800.5,"qty":0.00000000},{"price":101849.7,"qty":0.16737502},{"price":101808.4,"qty":0.00475000}],"checksum":1357166157,"timestamp":"2024-06-01T17:52:22.442579Z"}]}
{"channel":"book","type":"update","data":[{"symbol":"BTC/AUD","bids":[],"asks":[{"price":101799.6,"qty":0.00000000},{"price":101849.7,"qty":0.16737502},{"price":101807.3,"qty":0.00075700}],"checksum":1480530883,"timestamp":"2024-06-01T17:52:22.452515Z"}]}
{"channel":"book","type":"update","data":[{"symbol":"BTC/AUD","bids":[],"asks":[{"price":101795.7,"qty":0.00582000}],"checksum":2013901241,"timestamp":"2024-06-01T17:52:22.464030Z"}]}
{"channel":"book","type":"update","data":[{"symbol":"BTC/AUD","bids":[],"asks":[{"price":101795.7,"qty":0.00000000},{"price":101849.6,"qty":0.01129070}],"checksum":1480530883,"timestamp":"2024-06-01T17:52:22.533579Z"}]}
{"channel":"book","type":"update","data":[{"symbol":"BTC/AUD","bids":[],"asks":[{"price":101823.8,"qty":0.12143894}],"checksum":1022901189,"timestamp":"2024-06-01T17:52:22.623479Z"}]}
{"channel":"book","type":"update","data":[{"symbol":"BTC/AUD","bids":[],"asks":[{"price":101823.6,"qty":0.00222710}],"checksum":2075649208,"timestamp":"2024-06-01T17:52:22.626158Z"}]}
{"channel":"book","type":"update","data":[{"symbol":"BTC/AUD","bids":[],"asks":[{"price":101796.1,"qty":0.00521000}],"checksum":2505212913,"timestamp":"2024-06-01T17:52:22.668559Z"}]}
{"channel":"book","type":"update","data":[{"symbol":"BTC/AUD","bids":[],"asks":[{"price":101823.8,"qty":0.00000000},{"price":101826.0,"qty":0.09768924}],"checksum":2638115385,"timestamp":"2024-06-01T17:52:22.911782Z"}]}
{"channel":"book","type":"update","data":[{"symbol":"BTC/AUD","bids":[],"asks":[{"price":101823.7,"qty":0.00000000},{"price":101849.5,"qty":0.00184694},{"price":101825.9,"qty":0.02937000}],"checksum":3759961445,"timestamp":"2024-06-01T17:52:22.914925Z"}]}
{"channel":"book","type":"update","data":[{"symbol":"BTC/AUD","bids":[],"asks":[{"price":101823.6,"qty":0.10069682}],"checksum":1569846188,"timestamp":"2024-06-01T17:52:22.916550Z"}]}
{"channel":"book","type":"update","data":[{"symbol":"BTC/AUD","bids":[{"price":101684.9,"qty":0.00000000},{"price":101627.6,"qty":0.00639000},{"price":101685.1,"qty":0.05387266}],"asks":[],"checksum":2424016609,"timestamp":"2024-06-01T17:52:23.080302Z"}]}
{"channel":"book","type":"update","data":[{"symbol":"BTC/AUD","bids":[],"asks":[{"price":101796.6,"qty":0.00000000},{"price":101849.5,"qty":0.00184694},{"price":101796.0,"qty":0.05383672}],"checksum":572242739,"timestamp":"2024-06-01T17:52:23.080426Z"}]}
{"channel":"book","type":"update","data":[{"symbol":"BTC/AUD","bids":[{"price":101685.2,"qty":0.04717373}],"asks":[],"checksum":1214980574,"timestamp":"2024-06-01T17:52:23.085218Z"}]}
{"channel":"book","type":"update","data":[{"symbol":"BTC/AUD","bids":[{"price":101685.2,"qty":0.19717373}],"asks":[],"checksum":4249385513,"timestamp":"2024-06-01T17:52:23.086232Z"}]}
{"channel":"book","type":"update","data":[{"symbol":"BTC/AUD","bids":[{"price":101685.0,"qty":0.00000000},{"price":101634.0,"qty":0.09768924},{"price":101685.3,"qty":0.00308000}],"asks":[],"checksum":199448705,"timestamp":"2024-06-01T17:52:23.101406Z"}]}
{"channel":"book","type":"update","data":[{"symbol":"BTC/AUD","bids":[{"price":101684.0,"qty":0.34820752}],"asks":[],"checksum":3959531127,"timestamp":"2024-06-01T17:52:23.143884Z"}]}
{"channel":"book","type":"update","data":[{"symbol":"BTC/AUD","bids":[{"price":101684.7,"qty":0.00000000},{"price":101634.0,"qty":0.09768924}],"asks":[],"checksum":4103589904,"timestamp":"2024-06-01T17:52:23.178122Z"}]}
{"channel":"book","type":"update","data":[{"symbol":"BTC/AUD","bids":[],"asks":[{"price":101825.9,"qty":0.00000000},{"price":101849.5,"qty":0.00184694},{"price":101823.5,"qty":0.02937000}],"checksum":3035032849,"timestamp":"2024-06-01T17:52:23.475194Z"}]}
{"channel":"book","type":"update","data":[{"symbol":"BTC/AUD","bids":[{"price":101673.5,"qty":0.00000000},{"price":101627.6,"qty":0.00639000},{"price":101688.4,"qty":0.05056249}],"asks":[],"checksum":381207386,"timestamp":"2024-06-01T17:52:23.563495Z"}]}
{"channel":"book","type":"update","data":[{"symbol":"BTC/AUD","bids":[{"price":101673.6,"qty":0.00000000},{"price":101627.6,"qty":0.00639000},{"price":101634.1,"qty":0.02937000}],"asks":[],"checksum":1826552811,"timestamp":"2024-06-01T17:52:23.566822Z"}]}
{"channel":"book","type":"update","data":[{"symbol":"BTC/AUD","bids":[{"price":101659.8,"qty":0.00566000}],"asks":[],"checksum":3343704130,"timestamp":"2024-06-01T17:52:23.575948Z"}]}
{"channel":"book","type":"update","data":[{"symbol":"BTC/AUD","bids":[{"price":101685.3,"qty":0.00000000},{"price":101634.0,"qty":0.09768924},{"price":101688.5,"qty":0.00308000}],"asks":[],"checksum":2014973077,"timestamp":"2024-06-01T17:52:23.590450Z"}]}
{"channel":"book","type":"update","data":[{"symbol":"BTC/AUD","bids":[],"asks":[{"price":101797.8,"qty":0.00639000}],"checksum":3416393375,"timestamp":"2024-06-01T17:52:23.733056Z"}]}
{"channel":"book","type":"update","data":[{"symbol":"BTC/AUD","bids":[{"price":101680.2,"qty":0.00075700},{"price":101688.5,"qty":0.00783400}],"asks":[],"checksum":1933571287,"timestamp":"2024-06-01T17:52:23.733658Z"}]}
{"channel":"book","type":"update","data":[{"symbol":"BTC/AUD","bids":[{"price":101688.5,"qty":0.15783400}],"asks":[],"checksum":3881677068,"timestamp":"2024-06-01T17:52:23.738888Z"}]}
{"channel":"book","type":"update","data":[{"symbol":"BTC/AUD","bids":[{"price":101680.2,"qty":0.00000000},{"price":101634.0,"qty":0.09768924},{"price":101688.5,"qty":0.15859100}],"asks":[],"checksum":2225511997,"timestamp":"2024-06-01T17:52:23.744335Z"}]}
{"channel":"book","type":"update","data":[{"symbol":"BTC/AUD","bids":[],"asks":[{"price":101797.8,"qty":0.00000000},{"price":101826.0,"qty":0.09768924}],"checksum":3060058220,"timestamp":"2024-06-01T17:52:23.755190Z"}]}
{"channel":"book","type":"update","data":[{"symbol":"BTC/AUD","bids":[],"asks":[{"price":101798.4,"qty":0.00648000}],"checksum":409205092,"timestamp":"2024-06-01T17:52:23.865096Z"}]}
{"channel":"book","type":"update","data":[{"symbol":"BTC/AUD","bids":[{"price":101688.5,"qty":0.15551100},{"price":101688.6,"qty":0.00308000}],"asks":[],"checksum":3304268421,"timestamp":"2024-06-01T17:52:23.868140Z"}]}
{"channel":"book","type":"update","data":[{"symbol":"BTC/AUD","bids":[{"price":101685.2,"qty":0.04717373}],"asks":[],"checksum":2475598120,"timestamp":"2024-06-01T17:52:23.873688Z"}]}
{"channel":"book","type":"update","data":[{"symbol":"BTC/AUD","bids":[{"price":101685.1,"qty":0.00000000},{"price":101634.0,"qty":0.09768924},{"price":101688.7,"qty":0.05387034}],"asks":[],"checksum":2298278844,"timestamp":"2024-06-01T17:52:23.952039Z"}]}
{"channel":"book","type":"update","data":[{"symbol":"BTC/AUD","bids":[{"price":101688.8,"qty":0.04717373}],"asks":[],"checksum":3077573170,"timestamp":"2024-06-01T17:52:23.957010Z"}]}
{"channel":"book","type":"update","data":[{"symbol":"BTC/AUD","bids":[{"price":101688.8,"qty":0.19717373}],"asks":[],"checksum":686852447,"timestamp":"2024-06-01T17:52:23.957479Z"}]}
{"channel":"book","type":"update","data":[{"symbol":"BTC/AUD","bids":[],"asks":[{"price":101796.1,"qty":0.00000000},{"price":101826.0,"qty":0.09768924}],"checksum":2922455223,"timestamp":"2024-06-01T17:52:24.088011Z"}]}
{"channel":"book","type":"update","data":[{"symbol":"BTC/AUD","bids":[{"price":101659.9,"qty":0.02937000}],"asks":[],"checksum":203223842,"timestamp":"2024-06-01T17:52:24.090656Z"}]}
{"channel":"book","type":"update","data":[{"symbol":"BTC/AUD","bids":[{"price":101685.2,"qty":0.00000000},{"price":101659.8,"qty":0.00566000}],"asks":[],"checksum":4004057609,"timestamp":"2024-06-01T17:52:24.092811Z"}]}
{"channel":"book","type":"update","data":[{"symbol":"BTC/AUD","bids":[{"price":101688.5,"qty":0.00551100}],"asks":[],"checksum":4287332887,"timestamp":"2024-06-01T17:52:24.092838Z"}]}
{"channel":"book","type":"update","data":[{"symbol":"BTC/AUD","bids":[],"asks":[{"price":101796.0,"qty":0.00000000},{"price":101849.5,"qty":0.00184694},{"price":101796.6,"qty":0.05383664}],"checksum":19086958,"timestamp":"2024-06-01T17:52:24.136553Z"}]}
{"channel":"book","type":"update","data":[{"symbol":"BTC/AUD","bids":[{"price":101684.0,"qty":0.00135300}],"asks":[],"checksum":1531870550,"timestamp":"2024-06-01T17:52:24.210506Z"}]}
{"channel":"book","type":"update","data":[{"symbol":"BTC/AUD","bids":[{"price":101688.9,"qty":0.34684722}],"asks":[],"checksum":643032776,"timestamp":"2024-06-01T17:52:24.211089Z"}]}
{"channel":"book","type":"update","data":[{"symbol":"BTC/AUD","bids":[{"price":101689.0,"qty":0.04717373}],"asks":[],"checksum":2122187882,"timestamp":"2024-06-01T17:52:24.215951Z"}]}
{"channel":"book","type":"update","data":[{"symbol":"BTC/AUD","bids":[],"asks":[{"price":101784.4,"qty":0.00000000},{"price":101849.5,"qty":0.00184694},{"price":101790.0,"qty":0.00135200}],"checksum":1829613584,"timestamp":"2024-06-01T17:52:24.379376Z"}]}
{"channel":"book","type":"update","data":[{"symbol":"BTC/AUD","bids":[{"price":101688.8,"qty":0.15000000}],"asks":[],"checksum":918930863,"timestamp":"2024-06-01T17:52:24.384873Z"}]}
{"channel":"book","type":"update","data":[{"symbol":"BTC/AUD","bids":[{"price":101688.6,"qty":0.00000000},{"price":101659.9,"qty":0.02937000},{"price":101689.1,"qty":0.00308000}],"asks":[],"checksum":2872987794,"timestamp":"2024-06-01T17:52:24.388821Z"}]}
{"channel":"book","type":"update","data":[{"symbol":"BTC/AUD","bids":[{"price":101684.5,"qty":0.00000000},{"price":101659.9,"qty":0.02937000}],"asks":[],"checksum":1331359486,"timestamp":"2024-06-01T17:52:24.515666Z"}]}
{"channel":"book","type":"update","data":[{"symbol":"BTC/AUD","bids":[{"price":101689.1,"qty":0.00560204}],"asks":[],"checksum":3398024725,"timestamp":"2024-06-01T17:52:24.517014Z"}]}
{"channel":"book","type":"update","data":[{"symbol":"BTC/AUD","bids":[{"price":101688.7,"qty":0.00000000},{"price":101659.8,"qty":0.00566000},{"price":101689.2,"qty":0.05387024}],"asks":[],"checksum":2475742989,"timestamp":"2024-06-01T17:52:24.788360Z"}]}
{"channel":"book","type":"update","data":[{"symbol":"BTC/AUD","bids":[{"price":101689.3,"qty":0.15000000}],"asks":[],"checksum":4214438084,"timestamp":"2024-06-01T17:52:24.793696Z"}]}
{"channel":"book","type":"update","data":[{"symbol":"BTC/AUD","bids":[{"price":101689.1,"qty":0.00252204},{"price":101689.4,"qty":0.00308000}],"asks":[],"checksum":644294209,"timestamp":"2024-06-01T17:52:24.817359Z"}]}
{"channel":"book","type":"update","data":[{"symbol":"BTC/AUD","bids":[],"asks":[{"price":101823.6,"qty":0.09846972}],"checksum":2388595365,"timestamp":"2024-06-01T17:52:24.865085Z"}]}
{"channel":"book","type":"update","data":[{"symbol":"BTC/AUD","bids":[],"asks":[{"price":101823.4,"qty":0.00192364}],"checksum":4257052304,"timestamp":"2024-06-01T17:52:24.867783Z"}]}
{"channel":"book","type":"update","data":[{"symbol":"BTC/AUD","bids":[],"asks":[{"price":101823.5,"qty":0.00000000},{"price":101826.0,"qty":0.09768924}],"checksum":4164880742,"timestamp":"2024-06-01T17:52:25.102967Z"}]}
{"channel":"book","type":"update","data":[{"symbol":"BTC/AUD","bids":[],"asks":[{"price":101817.1,"qty":0.02937000}],"checksum":418415746,"timestamp":"2024-06-01T17:52:25.114024Z"}]}
{"channel":"book","type":"update","data":[{"symbol":"BTC/AUD","bids":[{"price":101688.8,"qty":0.00000000},{"price":101684.0,"qty":0.00135300}],"asks":[],"checksum":1670756489,"timestamp":"2024-06-01T17:52:25.143189Z"}]}
{"channel":"book","type":"update","data":[{"symbol":"BTC/AUD","bids":[{"price":101689.5,"qty":0.04717373}],"asks":[],"checksum":2646530472,"timestamp":"2024-06-01T17:52:25.178873Z"}]}
{"channel":"book","type":"update","data":[{"symbol":"BTC/AUD","bids":[{"price":101689.0,"qty":0.00000000},{"price":101684.0,"qty":0.00135300}],"asks":[],"checksum":2732402543,"timestamp":"2024-06-01T17:52:25.191437Z"}]}
{"channel":"book","type":"update","data":[{"symbol":"BTC/AUD","bids":[{"price":101689.4,"qty":0.00000000},{"price":101659.9,"qty":0.02937000},{"price":101689.6,"qty":0.00308000}],"asks":[],"checksum":1922558663,"timestamp":"2024-06-01T17:52:25.214820Z"}]}
{"channel":"book","type":"update","data":[{"symbol":"BTC/AUD","bids":[{"price":101689.2,"qty":0.00000000},{"price":101659.9,"qty":0.02937000},{"price":101689.7,"qty":0.05386997}],"asks":[],"checksum":2299190346,"timestamp":"2024-06-01T17:52:25.616192Z"}]}
{"channel":"book","type":"update","data":[{"symbol":"BTC/AUD","bids":[],"asks":[{"price":101823.6,"qty":0.00000000},{"price":101826.0,"qty":0.09768924}],"checksum":3007169983,"timestamp":"2024-06-01T17:52:25.786972Z"}]}
{"channel":"book","type":"update","data":[{"symbol":"BTC/AUD","bids":[],"asks":[{"price":101825.9,"qty":0.05253354}],"checksum":115161630,"timestamp":"2024-06-01T17:52:25.789352Z"}]}
{"channel":"book","type":"update","data":[{"symbol":"BTC/AUD","bids":[{"price":101684.0,"qty":0.00000000},{"price":101659.9,"qty":0.02937000},{"price":101689.8,"qty":0.00135200}],"asks":[],"checksum":2732392636,"timestamp":"2024-06-01T17:52:26.132806Z"}]}
{"channel":"book","type":"update","data":[{"symbol":"BTC/AUD","bids":[{"price":101689.8,"qty":0.15135200}],"asks":[],"checksum":4072180319,"timestamp":"2024-06-01T17:52:26.138039Z"}]}
{"channel":"book","type":"update","data":[{"symbol":"BTC/AUD","bids":[{"price":101689.9,"qty":0.04717373}],"asks":[],"checksum":1615498787,"timestamp":"2024-06-01T17:52:26.138088Z"}]}
{"channel":"book","type":"update","data":[{"symbol":"BTC/AUD","bids":[{"price":101689.5,"qty":0.00000000},{"price":101684.3,"qty":0.23801240}],"asks":[],"checksum":1602372276,"timestamp":"2024-06-01T17:52:26.178741Z"}]}
{"channel":"book","type":"update","data":[{"symbol":"BTC/AUD","bids":[],"asks":[{"price":101817.1,"qty":0.00000000},{"price":101826.0,"qty":0.09768924},{"price":101825.8,"qty":0.02937000}],"checksum":3794776964,"timestamp":"2024-06-01T17:52:26.181681Z"}]}
{"channel":"book","type":"update","data":[{"symbol":"BTC/AUD","bids":[{"price":101689.8,"qty":0.00135200}],"asks":[],"checksum":2120276938,"timestamp":"2024-06-01T17:52:26.183984Z"}]}
{"channel":"book","type":"update","data":[{"symbol":"BTC/AUD","bids":[{"price":101689.7,"qty":0.00000000},{"price":101659.9,"qty":0.02937000},{"price":101690.0,"qty":0.05386981}],"asks":[],"checksum":1334254854,"timestamp":"2024-06-01T17:52:26.399881Z"}]}
{"channel":"book","type":"update","data":[{"symbol":"BTC/AUD","bids":[{"price":101689.6,"qty":0.00000000},{"price":101659.9,"qty":0.02937000},{"price":101690.1,"qty":0.00308000}],"asks":[],"checksum":3961983660,"timestamp":"2024-06-01T17:52:26.434404Z"}]}
{"channel":"book","type":"update","data":[{"symbol":"BTC/AUD","bids":[],"asks":[{"price":101823.4,"qty":0.00000000},{"price":101826.0,"qty":0.09768924}],"checksum":1463732118,"timestamp":"2024-06-01T17:52:27.099098Z"}]}
{"channel":"book","type":"update","data":[{"symbol":"BTC/AUD","bids":[],"asks":[{"price":101825.7,"qty":0.00172014}],"checksum":4215627379,"timestamp":"2024-06-01T17:52:27.102168Z"}]}
{"channel":"book","type":"update","data":[{"symbol":"BTC/AUD","bids":[{"price":101690.0,"qty":0.00000000},{"price":101659.9,"qty":0.02937000},{"price":101690.2,"qty":0.05386995}],"asks":[],"checksum":1128527849,"timestamp":"2024-06-01T17:52:27.130953Z"}]}
{"channel":"book","type":"update","data":[{"symbol":"BTC/AUD","bids":[{"price":101690.3,"qty":0.04717373}],"asks":[],"checksum":625897137,"timestamp":"2024-06-01T17:52:27.136306Z"}]}
{"channel":"book","type":"update","data":[{"symbol":"BTC/AUD","bids":[{"price":101690.3,"qty":0.19717373}],"asks":[],"checksum":686171679,"timestamp":"2024-06-01T17:52:27.136402Z"}]}
{"channel":"book","type":"update","data":[{"symbol":"BTC/AUD","bids":[{"price":101689.3,"qty":0.00000000},{"price":101684.3,"qty":0.23801240}],"asks":[],"checksum":2026607299,"timestamp":"2024-06-01T17:52:27.143370Z"}]}
{"channel":"book","type":"update","data":[{"symbol":"BTC/AUD","bids":[{"price":101690.1,"qty":0.00000000},{"price":101659.9,"qty":0.02937000},{"price":101690.4,"qty":0.00308000}],"asks":[],"checksum":1447889921,"timestamp":"2024-06-01T17:52:27.163850Z"}]}
{"channel":"book","type":"update","data":[{"symbol":"BTC/AUD","bids":[{"price":101689.9,"qty":0.00000000},{"price":101659.9,"qty":0.02937000}],"asks":[],"checksum":1685993982,"timestamp":"2024-06-01T17:52:27.168835Z"}]}
{"channel":"book","type":"update","data":[{"symbol":"BTC/AUD","bids":[{"price":101690.5,"qty":0.04717373}],"asks":[],"checksum":4027179639,"timestamp":"2024-06-01T17:52:27.178392Z"}]}
{"channel":"book","type":"update","data":[{"symbol":"BTC/AUD","bids":[{"price":101688.9,"qty":0.00000000},{"price":101659.9,"qty":0.02937000}],"asks":[],"checksum":276773731,"timestamp":"2024-06-01T17:52:27.225752Z"}]}
{"channel":"book","type":"update","data":[{"symbol":"BTC/AUD","bids":[{"price":101690.2,"qty":0.37187240}],"asks":[],"checksum":2237685712,"timestamp":"2024-06-01T17:52:27.227772Z"}]}
{"channel":"book","type":"update","data":[{"symbol":"BTC/AUD","bids":[{"price":101690.3,"qty":0.15000000}],"asks":[],"checksum":3327275996,"timestamp":"2024-06-01T17:52:27.232565Z"}]}
{"channel":"book","type":"update","data":[{"symbol":"BTC/AUD","bids":[{"price":101690.6,"qty":0.15000000}],"asks":[],"checksum":1522072470,"timestamp":"2024-06-01T17:52:27.232960Z"}]}
{"channel":"book","type":"update","data":[{"symbol":"BTC/AUD","bids":[{"price":101690.4,"qty":0.00000000},{"price":101659.9,"qty":0.02937000},{"price":101690.7,"qty":0.00308000}],"asks":[],"checksum":4230428933,"timestamp":"2024-06-01T17:52:27.257189Z"}]}
{"channel":"book","type":"update","data":[{"symbol":"BTC/AUD","bids":[{"price":101690.3,"qty":0.00000000},{"price":101659.9,"qty":0.02937000}],"asks":[],"checksum":1296638991,"timestamp":"2024-06-01T17:52:27.263434Z"}]}
{"channel":"book","type":"update","data":[{"symbol":"BTC/AUD","bids":[{"price":101689.1,"qty":0.00000000},{"price":101659.8,"qty":0.00566000}],"asks":[],"checksum":1789305095,"timestamp":"2024-06-01T17:52:27.491963Z"}]}
{"channel":"book","type":"update","data":[{"symbol":"BTC/AUD","bids":[{"price":101690.8,"qty":0.00231471}],"asks":[],"checksum":289491627,"timestamp":"2024-06-01T17:52:27.492645Z"}]}
{"channel":"book","type":"update","data":[{"symbol":"BTC/AUD","bids":[{"price":101690.2,"qty":0.31800245},{"price":101690.9,"qty":0.05386959}],"asks":[],"checksum":4262413005,"timestamp":"2024-06-01T17:52:27.899352Z"}]}
{"channel":"book","type":"update","data":[{"symbol":"BTC/AUD","bids":[{"price":101691.0,"qty":0.15000000}],"asks":[],"checksum":3544129772,"timestamp":"2024-06-01T17:52:27.904790Z"}]}
{"channel":"book","type":"update","data":[{"symbol":"BTC/AUD","bids":[{"price":101690.7,"qty":0.00000000},{"price":101684.3,"qty":0.23801240},{"price":101691.1,"qty":0.00308000}],"asks":[],"checksum":3288775853,"timestamp":"2024-06-01T17:52:27.924554Z"}]}
{"channel":"book","type":"update","data":[{"symbol":"BTC/AUD","bids":[{"price":101690.6,"qty":0.00000000},{"price":101684.3,"qty":0.23801240}],"asks":[],"checksum":1080680622,"timestamp":"2024-06-01T17:52:28.143613Z"}]}
{"channel":"book","type":"update","data":[{"symbol":"BTC/AUD","bids":[{"price":101691.2,"qty":0.04717373}],"asks":[],"checksum":2352184110,"timestamp":"2024-06-01T17:52:28.149918Z"}]}
{"channel":"book","type":"update","data":[{"symbol":"BTC/AUD","bids":[{"price":101691.1,"qty":0.00000000},{"price":101684.3,"qty":0.23801240},{"price":101691.3,"qty":0.00308000}],"asks":[],"checksum":2771252832,"timestamp":"2024-06-01T17:52:28.169045Z"}]}
{"channel":"book","type":"update","data":[{"symbol":"BTC/AUD","bids":[{"price":101690.5,"qty":0.00000000},{"price":101684.3,"qty":0.23801240}],"asks":[],"checksum":3864002383,"timestamp":"2024-06-01T17:52:28.179535Z"}]}
{"channel":"book","type":"update","data":[{"symbol":"BTC/AUD","bids":[],"asks":[{"price":101825.9,"qty":0.00000000},{"price":101826.0,"qty":0.09768924}],"checksum":1403977966,"timestamp":"2024-06-01T17:52:28.578200Z"}]}
{"channel":"book","type":"update","data":[{"symbol":"BTC/AUD","bids":[],"asks":[{"price":101825.8,"qty":0.00000000},{"price":101849.6,"qty":0.01129070},{"price":101825.9,"qty":0.02937000}],"checksum":4081497773,"timestamp":"2024-06-01T17:52:28.581306Z"}]}
{"channel":"book","type":"update","data":[{"symbol":"BTC/AUD","bids":[],"asks":[{"price":101825.6,"qty":0.12143766}],"checksum":898905475,"timestamp":"2024-06-01T17:52:28.583269Z"}]}
{"channel":"book","type":"update","data":[{"symbol":"BTC/AUD","bids":[{"price":101684.4,"qty":0.02937000}],"asks":[],"checksum":1530390085,"timestamp":"2024-06-01T17:52:28.583653Z"}]}
{"channel":"book","type":"update","data":[{"symbol":"BTC/AUD","bids":[{"price":101690.9,"qty":0.00000000},{"price":101684.3,"qty":0.23801240},{"price":101691.4,"qty":0.05386933}],"asks":[],"checksum":3260584905,"timestamp":"2024-06-01T17:52:28.639390Z"}]}
{"channel":"book","type":"update","data":[{"symbol":"BTC/AUD","bids":[],"asks":[{"price":101825.9,"qty":0.00000000},{"price":101826.0,"qty":0.09768924}],"checksum":3551176193,"timestamp":"2024-06-01T17:52:28.648140Z"}]}
{"channel":"book","type":"update","data":[{"symbol":"BTC/AUD","bids":[{"price":101691.3,"qty":0.00000000},{"price":101684.3,"qty":0.23801240},{"price":101691.5,"qty":0.00308000}],"asks":[],"checksum":1606357708,"timestamp":"2024-06-01T17:52:28.659085Z"}]}
{"channel":"book","type":"update","data":[{"symbol":"BTC/AUD","bids":[{"price":101688.4,"qty":0.00000000},{"price":101684.3,"qty":0.23801240},{"price":101692.2,"qty":0.05056249}],"asks":[],"checksum":2902478167,"timestamp":"2024-06-01T17:52:28.816842Z"}]}
{"channel":"book","type":"update","data":[{"symbol":"BTC/AUD","bids":[{"price":101692.3,"qty":0.15000000}],"asks":[],"checksum":4127246888,"timestamp":"2024-06-01T17:52:28.822466Z"}]}
{"channel":"book","type":"update","data":[{"symbol":"BTC/AUD","bids":[{"price":101691.0,"qty":0.00000000},{"price":101684.4,"qty":0.02937000}],"asks":[],"checksum":3370802490,"timestamp":"2024-06-01T17:52:29.142431Z"}]}
{"channel":"book","type":"update","data":[{"symbol":"BTC/AUD","bids":[],"asks":[{"price":101818.7,"qty":0.02937000}],"checksum":3375142183,"timestamp":"2024-06-01T17:52:29.145161Z"}]}
{"channel":"book","type":"update","data":[{"symbol":"BTC/AUD","bids":[{"price":101692.4,"qty":0.04717373}],"asks":[],"checksum":2151220699,"timestamp":"2024-06-01T17:52:29.178464Z"}]}
{"channel":"book","type":"update","data":[{"symbol":"BTC/AUD","bids":[],"asks":[{"price":101825.7,"qty":0.00000000},{"price":101826.0,"qty":0.09768924}],"checksum":1168087340,"timestamp":"2024-06-01T17:52:29.285076Z"}]}
{"channel":"book","type":"update","data":[{"symbol":"BTC/AUD","bids":[],"asks":[{"price":101825.5,"qty":0.00233063}],"checksum":3902886391,"timestamp":"2024-06-01T17:52:29.287248Z"}]}
{"channel":"book","type":"update","data":[{"symbol":"BTC/AUD","bids":[{"price":101691.4,"qty":0.00000000},{"price":101684.4,"qty":0.02937000},{"price":101692.5,"qty":0.05386886}],"asks":[],"checksum":3302273937,"timestamp":"2024-06-01T17:52:29.324705Z"}]}
{"channel":"book","type":"update","data":[{"symbol":"BTC/AUD","bids":[{"price":101691.2,"qty":0.00000000},{"price":101684.4,"qty":0.02937000}],"asks":[],"checksum":2083936436,"timestamp":"2024-06-01T17:52:29.329926Z"}]}
{"channel":"book","type":"update","data":[{"symbol":"BTC/AUD","bids":[{"price":101691.5,"qty":0.00000000},{"price":101684.3,"qty":0.23801240},{"price":101692.6,"qty":0.00308000}],"asks":[],"checksum":3476334748,"timestamp":"2024-06-01T17:52:29.970787Z"}]}
{"channel":"book","type":"update","data":[{"symbol":"BTC/AUD","bids":[],"asks":[{"price":101818.7,"qty":0.00000000},{"price":101826.0,"qty":0.09768924},{"price":101825.5,"qty":0.03170063}],"checksum":4169906118,"timestamp":"2024-06-01T17:52:29.973502Z"}]}
{"channel":"book","type":"update","data":[{"symbol":"BTC/AUD","bids":[{"price":101692.7,"qty":0.04717373}],"asks":[],"checksum":1003179329,"timestamp":"2024-06-01T17:52:29.975887Z"}]}
{"channel":"book","type":"update","data":[{"symbol":"BTC/AUD","bids":[{"price":101692.6,"qty":0.15308000}],"asks":[],"checksum":1374948833,"timestamp":"2024-06-01T17:52:29.976026Z"}]}
{"channel":"book","type":"update","data":[{"symbol":"BTC/AUD","bids":[{"price":101692.5,"qty":0.00000000},{"price":101684.4,"qty":0.02937000},{"price":101692.7,"qty":0.10104248}],"asks":[],"checksum":3956753588,"timestamp":"2024-06-01T17:52:30.030641Z"}]}
{"channel":"book","type":"update","data":[{"symbol":"BTC/AUD","bids":[{"price":101692.4,"qty":0.00000000},{"price":101684.3,"qty":0.23801240}],"asks":[],"checksum":4004111795,"timestamp":"2024-06-01T17:52:30.035275Z"}]}
{"channel":"book","type":"update","data":[{"symbol":"BTC/AUD","bids":[{"price":101692.6,"qty":0.00308000}],"asks":[],"checksum":614260185,"timestamp":"2024-06-01T17:52:30.036246Z"}]}
{"channel":"book","type":"update","data":[{"symbol":"BTC/AUD","bids":[{"price":101692.6,"qty":0.00000000},{"price":101659.8,"qty":0.00566000},{"price":101692.8,"qty":0.00308000}],"asks":[],"checksum":2600918249,"timestamp":"2024-06-01T17:52:30.064612Z"}]}
