{"channel":"book","type":"update","data":[{"symbol":"BTC/USD","bids":[{"price":67614.1,"qty":0.00028394},{"price":67619.2,"qty":0.00113880}],"asks":[],"checksum":419280147,"timestamp":"2024-06-01T17:52:01.575689Z"}]}
{"channel":"book","type":"update","data":[{"symbol":"BTC/USD","bids":[],"asks":[{"price":67630.8,"qty":0.00000000},{"price":67635.1,"qty":1.47852273}],"checksum":3688493928,"timestamp":"2024-06-01T17:52:01.792570Z"}]}
{"channel":"book","type":"update","data":[{"symbol":"BTC/USD","bids":[],"asks":[{"price":67630.4,"qty":1.47862659}],"checksum":835470977,"timestamp":"2024-06-01T17:52:01.796744Z"}]}
{"channel":"book","type":"update","data":[{"symbol":"BTC/USD","bids":[],"asks":[{"price":67632.1,"qty":0.00000000},{"price":67635.1,"qty":1.47852273}],"checksum":1279666688,"timestamp":"2024-06-01T17:52:02.017870Z"}]}
{"channel":"book","type":"update","data":[{"symbol":"BTC/USD","bids":[{"price":67622.3,"qty":6.12560423}],"asks":[],"checksum":4070646099,"timestamp":"2024-06-01T17:52:02.021333Z"}]}
{"channel":"book","type":"update","data":[{"symbol":"BTC/USD","bids":[],"asks":[{"price":67629.9,"qty":1.47863774}],"checksum":461355984,"timestamp":"2024-06-01T17:52:02.021832Z"}]}
{"channel":"book","type":"update","data":[{"symbol":"BTC/USD","bids":[],"asks":[{"price":67635.0,"qty":0.00000000},{"price":67635.1,"qty":1.47852273}],"checksum":1811994189,"timestamp":"2024-06-01T17:52:02.090486Z"}]}
{"channel":"book","type":"update","data":[{"symbol":"BTC/USD","bids":[],"asks":[{"price":67629.9,"qty":0.00000000},{"price":67637.2,"qty":0.00029461}],"checksum":1694176184,"timestamp":"2024-06-01T17:52:02.109132Z"}]}
{"channel":"book","type":"update","data":[{"symbol":"BTC/USD","bids":[],"asks":[{"price":67629.6,"qty":1.47864440}],"checksum":2091510755,"timestamp":"2024-06-01T17:52:02.113220Z"}]}
{"channel":"book","type":"update","data":[{"symbol":"BTC/USD","bids":[],"asks":[{"price":67629.6,"qty":0.00000000},{"price":67637.2,"qty":0.00029461}],"checksum":1694176184,"timestamp":"2024-06-01T17:52:02.130381Z"}]}
{"channel":"book","type":"update","data":[{"symbol":"BTC/USD","bids":[],"asks":[{"price":67630.4,"qty":0.00000000},{"price":67637.3,"qty":0.57919679}],"checksum":1009960031,"timestamp":"2024-06-01T17:52:02.223694Z"}]}
{"channel":"book","type":"update","data":[{"symbol":"BTC/USD","bids":[],"asks":[{"price":67622.4,"qty":0.44059223}],"checksum":2188904719,"timestamp":"2024-06-01T17:52:02.224853Z"}]}
{"channel":"book","type":"update","data":[{"symbol":"BTC/USD","bids":[],"asks":[{"price":67632.7,"qty":1.47857505}],"checksum":2759163969,"timestamp":"2024-06-01T17:52:02.229143Z"}]}
{"channel":"book","type":"update","data":[{"symbol":"BTC/USD","bids":[],"asks":[{"price":67631.6,"qty":1.47859899}],"checksum":500405396,"timestamp":"2024-06-01T17:52:02.229271Z"}]}
{"channel":"book","type":"update","data":[{"symbol":"BTC/USD","bids":[],"asks":[{"price":67631.6,"qty":0.00000000},{"price":67637.2,"qty":0.00029461}],"checksum":2759163969,"timestamp":"2024-06-01T17:52:02.261491Z"}]}
{"channel":"book","type":"update","data":[{"symbol":"BTC/USD","bids":[{"price":67622.3,"qty":6.46310423}],"asks":[],"checksum":445811474,"timestamp":"2024-06-01T17:52:02.280742Z"}]}
{"channel":"book","type":"update","data":[{"symbol":"BTC/USD","bids":[],"asks":[{"price":67631.5,"qty":1.47860177}],"checksum":1755656322,"timestamp":"2024-06-01T17:52:02.287663Z"}]}
{"channel":"book","type":"update","data":[{"symbol":"BTC/USD","bids":[{"price":67622.3,"qty":6.80060423}],"asks":[],"checksum":1676183688,"timestamp":"2024-06-01T17:52:02.295221Z"}]}
{"channel":"book","type":"update","data":[{"symbol":"BTC/USD","bids":[],"asks":[{"price":67632.3,"qty":0.00000000},{"price":67637.2,"qty":0.00029461}],"checksum":2174108753,"timestamp":"2024-06-01T17:52:02.316483Z"}]}
{"channel":"book","type":"update","data":[{"symbol":"BTC/USD","bids":[],"asks":[{"price":67631.5,"qty":0.00000000},{"price":67637.3,"qty":0.57919679}],"checksum":3472970476,"timestamp":"2024-06-01T17:52:02.319776Z"}]}
{"channel":"book","type":"update","data":[{"symbol":"BTC/USD","bids":[],"asks":[{"price":67635.1,"qty":0.00000000},{"price":67638.2,"qty":0.07066000}],"checksum":411933656,"timestamp":"2024-06-01T17:52:02.319885Z"}]}
{"channel":"book","type":"update","data":[{"symbol":"BTC/USD","bids":[{"price":67621.3,"qty":1.47882281}],"asks":[],"checksum":1325453037,"timestamp":"2024-06-01T17:52:02.324393Z"}]}
{"channel":"book","type":"update","data":[{"symbol":"BTC/USD","bids":[{"price":67622.3,"qty":6.80160423}],"asks":[],"checksum":990262392,"timestamp":"2024-06-01T17:52:02.335265Z"}]}
{"channel":"book","type":"update","data":[{"symbol":"BTC/USD","bids":[],"asks":[{"price":67631.7,"qty":0.00000000},{"price":67638.9,"qty":1.47843946}],"checksum":757095078,"timestamp":"2024-06-01T17:52:02.337944Z"}]}
{"channel":"book","type":"update","data":[{"symbol":"BTC/USD","bids":[{"price":67619.2,"qty":0.00000000},{"price":67614.0,"qty":0.36658577}],"asks":[],"checksum":317544409,"timestamp":"2024-06-01T17:52:02.363075Z"}]}
{"channel":"book","type":"update","data":[{"symbol":"BTC/USD","bids":[],"asks":[{"price":67635.7,"qty":0.29580000}],"checksum":2898390738,"timestamp":"2024-06-01T17:52:02.365951Z"}]}
{"channel":"book","type":"update","data":[{"symbol":"BTC/USD","bids":[],"asks":[{"price":67632.1,"qty":1.47858801}],"checksum":773652301,"timestamp":"2024-06-01T17:52:02.366293Z"}]}
{"channel":"book","type":"update","data":[{"symbol":"BTC/USD","bids":[{"price":67619.1,"qty":0.00000000},{"price":67612.0,"qty":0.33750000}],"asks":[],"checksum":495559353,"timestamp":"2024-06-01T17:52:02.369517Z"}]}
{"channel":"book","type":"update","data":[{"symbol":"BTC/USD","bids":[],"asks":[{"price":67632.1,"qty":0.00000000},{"price":67638.2,"qty":0.07066000}],"checksum":3362585839,"timestamp":"2024-06-01T17:52:02.371325Z"}]}
{"channel":"book","type":"update","data":[{"symbol":"BTC/USD","bids":[],"asks":[{"price":67636.5,"qty":1.47849319}],"checksum":34273720,"timestamp":"2024-06-01T17:52:02.375275Z"}]}
{"channel":"book","type":"update","data":[{"symbol":"BTC/USD","bids":[{"price":67615.5,"qty":1.47894955}],"asks":[],"checksum":1046385744,"timestamp":"2024-06-01T17:52:02.375321Z"}]}
{"channel":"book","type":"update","data":[{"symbol":"BTC/USD","bids":[],"asks":[{"price":67632.7,"qty":0.00000000},{"price":67638.2,"qty":0.07066000}],"checksum":380565088,"timestamp":"2024-06-01T17:52:02.380855Z"}]}
{"channel":"book","type":"update","data":[{"symbol":"BTC/USD","bids":[],"asks":[{"price":67633.2,"qty":0.06910000}],"checksum":1870271880,"timestamp":"2024-06-01T17:52:02.418019Z"}]}
{"channel":"book","type":"update","data":[{"symbol":"BTC/USD","bids":[],"asks":[{"price":67631.8,"qty":1.58950988}],"checksum":3171770274,"timestamp":"2024-06-01T17:52:02.420878Z"}]}
{"channel":"book","type":"update","data":[{"symbol":"BTC/USD","bids":[{"price":67622.3,"qty":6.46410423}],"asks":[],"checksum":2824774265,"timestamp":"2024-06-01T17:52:02.425034Z"}]}
{"channel":"book","type":"update","data":[{"symbol":"BTC/USD","bids":[],"asks":[{"price":67631.8,"qty":0.11091373}],"checksum":2049566803,"timestamp":"2024-06-01T17:52:02.572479Z"}]}
{"channel":"book","type":"update","data":[{"symbol":"BTC/USD","bids":[],"asks":[{"price":67632.4,"qty":1.47858151}],"checksum":1012440545,"timestamp":"2024-06-01T17:52:02.576232Z"}]}
{"channel":"book","type":"update","data":[{"symbol":"BTC/USD","bids":[{"price":67615.6,"qty":0.00113966}],"asks":[],"checksum":1275695010,"timestamp":"2024-06-01T17:52:02.698895Z"}]}
{"channel":"book","type":"update","data":[{"symbol":"BTC/USD","bids":[],"asks":[{"price":67632.4,"qty":0.00000000},{"price":67637.3,"qty":0.57919679}],"checksum":1292169002,"timestamp":"2024-06-01T17:52:02.919505Z"}]}
{"channel":"book","type":"update","data":[{"symbol":"BTC/USD","bids":[],"asks":[{"price":67632.2,"qty":1.47858668}],"checksum":3283335850,"timestamp":"2024-06-01T17:52:02.923840Z"}]}
{"channel":"book","type":"update","data":[{"symbol":"BTC/USD","bids":[],"asks":[{"price":67632.2,"qty":0.00000000},{"price":67637.3,"qty":0.57919679}],"checksum":1292169002,"timestamp":"2024-06-01T17:52:02.955560Z"}]}
{"channel":"book","type":"update","data":[{"symbol":"BTC/USD","bids":[],"asks":[{"price":67633.2,"qty":0.00000000},{"price":67638.2,"qty":0.07066000},{"price":67634.2,"qty":0.06910000}],"checksum":2712863785,"timestamp":"2024-06-01T17:52:02.995807Z"}]}
{"channel":"book","type":"update","data":[{"symbol":"BTC/USD","bids":[{"price":67622.3,"qty":6.80160423}],"asks":[],"checksum":2718611888,"timestamp":"2024-06-01T17:52:02.999946Z"}]}
{"channel":"book","type":"update","data":[{"symbol":"BTC/USD","bids":[],"asks":[{"price":67634.2,"qty":0.00000000},{"price":67638.2,"qty":0.07066000}],"checksum":180438951,"timestamp":"2024-06-01T17:52:03.003297Z"}]}
{"channel":"book","type":"update","data":[{"symbol":"BTC/USD","bids":[],"asks":[{"price":67636.1,"qty":0.06910000}],"checksum":727935100,"timestamp":"2024-06-01T17:52:03.006979Z"}]}
{"channel":"book","type":"update","data":[{"symbol":"BTC/USD","bids":[],"asks":[{"price":67631.7,"qty":1.47859664}],"checksum":2167825227,"timestamp":"2024-06-01T17:52:03.011053Z"}]}
{"channel":"book","type":"update","data":[{"symbol":"BTC/USD","bids":[],"asks":[{"price":67636.1,"qty":0.00000000},{"price":67637.3,"qty":0.57919679}],"checksum":3924528328,"timestamp":"2024-06-01T17:52:03.013266Z"}]}
{"channel":"book","type":"update","data":[{"symbol":"BTC/USD","bids":[],"asks":[{"price":67622.4,"qty":0.40111725}],"checksum":362856864,"timestamp":"2024-06-01T17:52:03.013406Z"}]}
{"channel":"book","type":"update","data":[{"symbol":"BTC/USD","bids":[],"asks":[{"price":67631.7,"qty":0.00000000},{"price":67638.2,"qty":0.07066000}],"checksum":2916438772,"timestamp":"2024-06-01T17:52:03.018112Z"}]}
{"channel":"book","type":"update","data":[{"symbol":"BTC/USD","bids":[],"asks":[{"price":67631.6,"qty":1.47859890}],"checksum":3418359578,"timestamp":"2024-06-01T17:52:03.060292Z"}]}
{"channel":"book","type":"update","data":[{"symbol":"BTC/USD","bids":[],"asks":[{"price":67631.6,"qty":0.00000000},{"price":67638.2,"qty":0.07066000}],"checksum":2916438772,"timestamp":"2024-06-01T17:52:03.110915Z"}]}
{"channel":"book","type":"update","data":[{"symbol":"BTC/USD","bids":[],"asks":[{"price":67629.4,"qty":0.03947498}],"checksum":700469861,"timestamp":"2024-06-01T17:52:03.115231Z"}]}
{"channel":"book","type":"update","data":[{"symbol":"BTC/USD","bids":[],"asks":[{"price":67632.5,"qty":1.47857997}],"checksum":2540291823,"timestamp":"2024-06-01T17:52:03.115322Z"}]}
{"channel":"book","type":"update","data":[{"symbol":"BTC/USD","bids":[],"asks":[{"price":67632.5,"qty":0.00000000},{"price":67637.3,"qty":0.57919679}],"checksum":700469861,"timestamp":"2024-06-01T17:52:03.133148Z"}]}
{"channel":"book","type":"update","data":[{"symbol":"BTC/USD","bids":[],"asks":[{"price":67635.7,"qty":0.00000000},{"price":67638.2,"qty":0.07066000}],"checksum":3262717198,"timestamp":"2024-06-01T17:52:03.145554Z"}]}
{"channel":"book","type":"update","data":[{"symbol":"BTC/USD","bids":[],"asks":[{"price":67636.5,"qty":1.54759319}],"checksum":3263873343,"timestamp":"2024-06-01T17:52:03.149819Z"}]}
{"channel":"book","type":"update","data":[{"symbol":"BTC/USD","bids":[],"asks":[{"price":67636.5,"qty":1.47849319},{"price":67637.6,"qty":0.06910000}],"checksum":3132696783,"timestamp":"2024-06-01T17:52:03.153947Z"}]}
{"channel":"book","type":"update","data":[{"symbol":"BTC/USD","bids":[],"asks":[{"price":67636.5,"qty":0.00000000},{"price":67638.2,"qty":0.07066000}],"checksum":2302925312,"timestamp":"2024-06-01T17:52:03.157392Z"}]}
{"channel":"book","type":"update","data":[{"symbol":"BTC/USD","bids":[],"asks":[{"price":67637.6,"qty":0.00000000},{"price":67638.4,"qty":1.47845082},{"price":67636.1,"qty":0.06910000}],"checksum":3767606900,"timestamp":"2024-06-01T17:52:03.172319Z"}]}
{"channel":"book","type":"update","data":[{"symbol":"BTC/USD","bids":[],"asks":[{"price":67634.0,"qty":1.47854846}],"checksum":3049573658,"timestamp":"2024-06-01T17:52:03.173000Z"}]}
{"channel":"book","type":"update","data":[{"symbol":"BTC/USD","bids":[],"asks":[{"price":67635.6,"qty":1.47851304}],"checksum":973714371,"timestamp":"2024-06-01T17:52:03.173113Z"}]}
{"channel":"book","type":"update","data":[{"symbol":"BTC/USD","bids":[],"asks":[{"price":67635.6,"qty":0.00000000},{"price":67637.3,"qty":0.57919679}],"checksum":3049573658,"timestamp":"2024-06-01T17:52:03.179354Z"}]}
{"channel":"book","type":"update","data":[{"symbol":"BTC/USD","bids":[],"asks":[{"price":67634.0,"qty":0.00000000},{"price":67638.2,"qty":0.07066000}],"checksum":3767606900,"timestamp":"2024-06-01T17:52:03.179413Z"}]}
{"channel":"book","type":"update","data":[{"symbol":"BTC/USD","bids":[],"asks":[{"price":67622.4,"qty":0.00111725}],"checksum":743685586,"timestamp":"2024-06-01T17:52:03.231763Z"}]}
{"channel":"book","type":"update","data":[{"symbol":"BTC/USD","bids":[],"asks":[{"price":67628.1,"qty":0.03947498}],"checksum":2325877159,"timestamp":"2024-06-01T17:52:03.236547Z"}]}
{"channel":"book","type":"update","data":[{"symbol":"BTC/USD","bids":[{"price":67614.5,"qty":0.22836862}],"asks":[],"checksum":1344678367,"timestamp":"2024-06-01T17:52:03.257147Z"}]}
{"channel":"book","type":"update","data":[{"symbol":"BTC/USD","bids":[],"asks":[{"price":67637.3,"qty":0.00000000},{"price":67638.2,"qty":0.07066000}],"checksum":1187562456,"timestamp":"2024-06-01T17:52:03.330299Z"}]}
{"channel":"book","type":"update","data":[{"symbol":"BTC/USD","bids":[],"asks":[{"price":67633.7,"qty":1.47855487}],"checksum":1460727184,"timestamp":"2024-06-01T17:52:03.334387Z"}]}
{"channel":"book","type":"update","data":[{"symbol":"BTC/USD","bids":[],"asks":[{"price":67633.7,"qty":0.00000000},{"price":67638.2,"qty":0.07066000}],"checksum":1187562456,"timestamp":"2024-06-01T17:52:03.352530Z"}]}
{"channel":"book","type":"update","data":[{"symbol":"BTC/USD","bids":[],"asks":[{"price":67635.2,"qty":1.47852171}],"checksum":3105581421,"timestamp":"2024-06-01T17:52:03.375491Z"}]}
{"channel":"book","type":"update","data":[{"symbol":"BTC/USD","bids":[{"price":67615.5,"qty":0.00000000},{"price":67614.1,"qty":0.00028394}],"asks":[],"checksum":4259537434,"timestamp":"2024-06-01T17:52:03.388944Z"}]}
{"channel":"book","type":"update","data":[{"symbol":"BTC/USD","bids":[{"price":67618.7,"qty":1.47888071}],"asks":[],"checksum":1384565855,"timestamp":"2024-06-01T17:52:03.392507Z"}]}
{"channel":"book","type":"update","data":[{"symbol":"BTC/USD","bids":[],"asks":[{"price":67634.7,"qty":1.47853152}],"checksum":3942352363,"timestamp":"2024-06-01T17:52:03.392522Z"}]}
{"channel":"book","type":"update","data":[{"symbol":"BTC/USD","bids":[],"asks":[{"price":67634.7,"qty":0.00000000},{"price":67636.4,"qty":0.00029379}],"checksum":1384565855,"timestamp":"2024-06-01T17:52:03.406482Z"}]}
{"channel":"book","type":"update","data":[{"symbol":"BTC/USD","bids":[],"asks":[{"price":67634.4,"qty":1.47853965}],"checksum":3408654688,"timestamp":"2024-06-01T17:52:03.461169Z"}]}
{"channel":"book","type":"update","data":[{"symbol":"BTC/USD","bids":[],"asks":[{"price":67636.1,"qty":0.00000000},{"price":67636.4,"qty":0.00029379}],"checksum":2444391825,"timestamp":"2024-06-01T17:52:03.474187Z"}]}
{"channel":"book","type":"update","data":[{"symbol":"BTC/USD","bids":[],"asks":[{"price":67634.4,"qty":0.00000000},{"price":67637.7,"qty":0.06910000}],"checksum":2640412903,"timestamp":"2024-06-01T17:52:03.591298Z"}]}
{"channel":"book","type":"update","data":[{"symbol":"BTC/USD","bids":[],"asks":[{"price":67629.4,"qty":0.00000000},{"price":67638.2,"qty":0.07066000}],"checksum":1409316452,"timestamp":"2024-06-01T17:52:03.592418Z"}]}
{"channel":"book","type":"update","data":[{"symbol":"BTC/USD","bids":[],"asks":[{"price":67634.8,"qty":1.47853048}],"checksum":2488406068,"timestamp":"2024-06-01T17:52:03.595078Z"}]}
{"channel":"book","type":"update","data":[{"symbol":"BTC/USD","bids":[],"asks":[{"price":67634.8,"qty":0.00000000},{"price":67638.2,"qty":0.07066000}],"checksum":1409316452,"timestamp":"2024-06-01T17:52:03.602668Z"}]}
{"channel":"book","type":"update","data":[{"symbol":"BTC/USD","bids":[],"asks":[{"price":67634.2,"qty":1.47854350}],"checksum":1275748143,"timestamp":"2024-06-01T17:52:03.727000Z"}]}
{"channel":"book","type":"update","data":[{"symbol":"BTC/USD","bids":[],"asks":[{"price":67634.2,"qty":0.00000000},{"price":67638.2,"qty":0.07066000}],"checksum":1409316452,"timestamp":"2024-06-01T17:52:03.730529Z"}]}
{"channel":"book","type":"update","data":[{"symbol":"BTC/USD","bids":[],"asks":[{"price":67637.7,"qty":0.00000000},{"price":67638.4,"qty":1.47845082},{"price":67636.4,"qty":0.06939379}],"checksum":1346564529,"timestamp":"2024-06-01T17:52:03.734994Z"}]}
{"channel":"book","type":"update","data":[{"symbol":"BTC/USD","bids":[],"asks":[{"price":67636.4,"qty":0.06910000},{"price":67638.3,"qty":0.00029379}],"checksum":3414312626,"timestamp":"2024-06-01T17:52:03.801861Z"}]}
{"channel":"book","type":"update","data":[{"symbol":"BTC/USD","bids":[{"price":67615.6,"qty":0.00000000},{"price":67614.1,"qty":0.00028394},{"price":67618.8,"qty":0.00114074}],"asks":[],"checksum":2747309567,"timestamp":"2024-06-01T17:52:03.801939Z"}]}
{"channel":"book","type":"update","data":[{"symbol":"BTC/USD","bids":[],"asks":[{"price":67633.9,"qty":1.47854986}],"checksum":72657181,"timestamp":"2024-06-01T17:52:03.928121Z"}]}
{"channel":"book","type":"update","data":[{"symbol":"BTC/USD","bids":[],"asks":[{"price":67633.9,"qty":0.00000000},{"price":67638.3,"qty":0.00029379}],"checksum":2747309567,"timestamp":"2024-06-01T17:52:04.025511Z"}]}
{"channel":"book","type":"update","data":[{"symbol":"BTC/USD","bids":[],"asks":[{"price":67633.6,"qty":1.47855700}],"checksum":2182407535,"timestamp":"2024-06-01T17:52:04.028870Z"}]}
{"channel":"book","type":"update","data":[{"symbol":"BTC/USD","bids":[],"asks":[{"price":67633.6,"qty":0.00000000},{"price":67638.3,"qty":0.00029379}],"checksum":2747309567,"timestamp":"2024-06-01T17:52:04.142709Z"}]}
{"channel":"book","type":"update","data":[{"symbol":"BTC/USD","bids":[],"asks":[{"price":67633.1,"qty":1.47856602}],"checksum":166280822,"timestamp":"2024-06-01T17:52:04.146862Z"}]}
{"channel":"book","type":"update","data":[{"symbol":"BTC/USD","bids":[{"price":67618.8,"qty":0.00000000},{"price":67614.1,"qty":0.00028394}],"asks":[],"checksum":4281923904,"timestamp":"2024-06-01T17:52:04.270890Z"}]}
{"channel":"book","type":"update","data":[{"symbol":"BTC/USD","bids":[],"asks":[{"price":67622.4,"qty":0.00000000},{"price":67638.3,"qty":0.00029379},{"price":67624.1,"qty":0.00000000},{"price":67638.4,"qty":1.47845082},{"price":67628.1,"qty":0.03049155}],"checksum":7232472,"timestamp":"2024-06-01T17:52:04.407412Z"}]}
{"channel":"book","type":"update","data":[{"symbol":"BTC/USD","bids":[{"price":67625.6,"qty":0.33750000}],"asks":[],"checksum":2389864644,"timestamp":"2024-06-01T17:52:04.410626Z"}]}
{"channel":"book","type":"update","data":[{"symbol":"BTC/USD","bids":[{"price":67628.0,"qty":1.33039193}],"asks":[],"checksum":4116944796,"timestamp":"2024-06-01T17:52:04.410786Z"}]}
{"channel":"book","type":"update","data":[{"symbol":"BTC/USD","bids":[{"price":67628.0,"qty":1.91119214}],"asks":[],"checksum":85737603,"timestamp":"2024-06-01T17:52:04.411175Z"}]}
{"channel":"book","type":"update","data":[{"symbol":"BTC/USD","bids":[{"price":67622.3,"qty":6.22075506}],"asks":[],"checksum":499276353,"timestamp":"2024-06-01T17:52:04.411194Z"}]}
{"channel":"book","type":"update","data":[{"symbol":"BTC/USD","bids":[{"price":67622.3,"qty":6.15165506},{"price":67628.0,"qty":1.98029214}],"asks":[],"checksum":2823322002,"timestamp":"2024-06-01T17:52:04.412026Z"}]}
{"channel":"book","type":"update","data":[{"symbol":"BTC/USD","bids":[{"price":67621.7,"qty":0.00000000},{"price":67614.5,"qty":0.22836862}],"asks":[],"checksum":190823815,"timestamp":"2024-06-01T17:52:04.412977Z"}]}
{"channel":"book","type":"update","data":[{"symbol":"BTC/USD","bids":[{"price":67621.3,"qty":0.00000000},{"price":67614.1,"qty":0.00028394}],"asks":[],"checksum":1381797297,"timestamp":"2024-06-01T17:52:04.413070Z"}]}
{"channel":"book","type":"update","data":[{"symbol":"BTC/USD","bids":[{"price":67616.3,"qty":0.00000000},{"price":67612.0,"qty":0.33750000}],"asks":[],"checksum":1689001197,"timestamp":"2024-06-01T17:52:04.413415Z"}]}
{"channel":"book","type":"update","data":[{"symbol":"BTC/USD","bids":[{"price":67622.3,"qty":4.82115743}],"asks":[],"checksum":806364400,"timestamp":"2024-06-01T17:52:04.413529Z"}]}
{"channel":"book","type":"update","data":[{"symbol":"BTC/USD","bids":[{"price":67622.3,"qty":4.79158139},{"price":67628.0,"qty":2.00986568}],"asks":[],"checksum":1737273481,"timestamp":"2024-06-01T17:52:04.414170Z"}]}
{"channel":"book","type":"update","data":[{"symbol":"BTC/USD","bids":[{"price":67622.4,"qty":0.36654024}],"asks":[],"checksum":1509730686,"timestamp":"2024-06-01T17:52:04.414222Z"}]}
{"channel":"book","type":"update","data":[{"symbol":"BTC/USD","bids":[{"price":67628.0,"qty":2.07896568}],"asks":[],"checksum":3221242394,"timestamp":"2024-06-01T17:52:04.415105Z"}]}
{"channel":"book","type":"update","data":[{"symbol":"BTC/USD","bids":[{"price":67628.0,"qty":2.00986568}],"asks":[],"checksum":1509730686,"timestamp":"2024-06-01T17:52:04.415153Z"}]}
{"channel":"book","type":"update","data":[{"symbol":"BTC/USD","bids":[{"price":67622.3,"qty":4.49158139},{"price":67628.0,"qty":2.30986568}],"asks":[],"checksum":1773155545,"timestamp":"2024-06-01T17:52:04.415814Z"}]}
{"channel":"book","type":"update","data":[{"symbol":"BTC/USD","bids":[{"price":67628.0,"qty":2.43079868}],"asks":[],"checksum":223060140,"timestamp":"2024-06-01T17:52:04.416351Z"}]}
{"channel":"book","type":"update","data":[{"symbol":"BTC/USD","bids":[{"price":67628.0,"qty":2.76829868}],"asks":[],"checksum":3096806562,"timestamp":"2024-06-01T17:52:04.417136Z"}]}
{"channel":"book","type":"update","data":[{"symbol":"BTC/USD","bids":[{"price":67627.0,"qty":1.47869832}],"asks":[],"checksum":2438239496,"timestamp":"2024-06-01T17:52:04.417207Z"}]}
{"channel":"book","type":"update","data":[{"symbol":"BTC/USD","bids":[{"price":67622.3,"qty":4.15408139}],"asks":[],"checksum":1229654020,"timestamp":"2024-06-01T17:52:04.417310Z"}]}
{"channel":"book","type":"update","data":[{"symbol":"BTC/USD","bids":[{"price":67625.6,"qty":1.81622897}],"asks":[],"checksum":1100891872,"timestamp":"2024-06-01T17:52:04.417372Z"}]}
{"channel":"book","type":"update","data":[{"symbol":"BTC/USD","bids":[{"price":67622.3,"qty":3.98715139},{"price":67628.0,"qty":2.93522915}],"asks":[],"checksum":1075067978,"timestamp":"2024-06-01T17:52:04.417946Z"}]}
{"channel":"book","type":"update","data":[{"symbol":"BTC/USD","bids":[{"price":67622.3,"qty":3.79739211},{"price":67628.0,"qty":3.12498843}],"asks":[],"checksum":994226964,"timestamp":"2024-06-01T17:52:04.421201Z"}]}
{"channel":"book","type":"update","data":[{"symbol":"BTC/USD","bids":[{"price":67622.3,"qty":3.77927211},{"price":67628.0,"qty":3.14310843}],"asks":[],"checksum":2571371467,"timestamp":"2024-06-01T17:52:04.422461Z"}]}
{"channel":"book","type":"update","data":[{"symbol":"BTC/USD","bids":[{"price":67622.3,"qty":3.46430211},{"price":67628.0,"qty":3.45807843}],"asks":[],"checksum":3253510334,"timestamp":"2024-06-01T17:52:04.424007Z"}]}
{"channel":"book","type":"update","data":[{"symbol":"BTC/USD","bids":[],"asks":[{"price":67636.4,"qty":0.00000000},{"price":67639.1,"qty":0.29580000}],"checksum":1698895998,"timestamp":"2024-06-01T17:52:04.430820Z"}]}
{"channel":"book","type":"update","data":[{"symbol":"BTC/USD","bids":[{"price":67625.7,"qty":3.67700000}],"asks":[],"checksum":2572171901,"timestamp":"2024-06-01T17:52:04.441734Z"}]}
{"channel":"book","type":"update","data":[{"symbol":"BTC/USD","bids":[{"price":67625.7,"qty":0.00000000},{"price":67614.5,"qty":0.22836862}],"asks":[],"checksum":1698895998,"timestamp":"2024-06-01T17:52:04.504251Z"}]}
{"channel":"book","type":"update","data":[{"symbol":"BTC/USD","bids":[{"price":67622.3,"qty":1.81830211}],"asks":[],"checksum":2406772750,"timestamp":"2024-06-01T17:52:04.513196Z"}]}
{"channel":"book","type":"update","data":[{"symbol":"BTC/USD","bids":[{"price":67621.9,"qty":0.00000000},{"price":67614.1,"qty":0.00028394},{"price":67626.9,"qty":0.00010000}],"asks":[],"checksum":3717332204,"timestamp":"2024-06-01T17:52:04.569421Z"}]}
{"channel":"book","type":"update","data":[{"symbol":"BTC/USD","bids":[],"asks":[{"price":67636.7,"qty":0.00120000}],"checksum":1969669522,"timestamp":"2024-06-01T17:52:04.577669Z"}]}
{"channel":"book","type":"update","data":[{"symbol":"BTC/USD","bids":[],"asks":[{"price":67636.1,"qty":0.06910000}],"checksum":1799375711,"timestamp":"2024-06-01T17:52:04.597135Z"}]}
{"channel":"book","type":"update","data":[{"symbol":"BTC/USD","bids":[{"price":67627.0,"qty":0.00000000},{"price":67614.1,"qty":0.00028394}],"asks":[],"checksum":1089557284,"timestamp":"2024-06-01T17:52:04.698138Z"}]}
{"channel":"book","type":"update","data":[{"symbol":"BTC/USD","bids":[],"asks":[{"price":67635.2,"qty":0.00000000},{"price":67638.4,"qty":1.47845082}],"checksum":2826127471,"timestamp":"2024-06-01T17:52:04.698219Z"}]}
{"channel":"book","type":"update","data":[{"symbol":"BTC/USD","bids":[{"price":67626.6,"qty":1.47870736}],"asks":[],"checksum":2480427195,"timestamp":"2024-06-01T17:52:04.702755Z"}]}
{"channel":"book","type":"update","data":[{"symbol":"BTC/USD","bids":[],"asks":[{"price":67632.8,"qty":1.47857372}],"checksum":4085850655,"timestamp":"2024-06-01T17:52:04.702773Z"}]}
{"channel":"book","type":"update","data":[{"symbol":"BTC/USD","bids":[{"price":67628.0,"qty":3.12057843}],"asks":[],"checksum":1823195119,"timestamp":"2024-06-01T17:52:04.851863Z"}]}
{"channel":"book","type":"update","data":[{"symbol":"BTC/USD","bids":[{"price":67628.0,"qty":3.45807843}],"asks":[],"checksum":4085850655,"timestamp":"2024-06-01T17:52:04.855832Z"}]}
{"channel":"book","type":"update","data":[{"symbol":"BTC/USD","bids":[{"price":67628.0,"qty":3.12057843}],"asks":[],"checksum":1823195119,"timestamp":"2024-06-01T17:52:04.859727Z"}]}
{"channel":"book","type":"update","data":[{"symbol":"BTC/USD","bids":[{"price":67622.5,"qty":0.00114034}],"asks":[],"checksum":3735798094,"timestamp":"2024-06-01T17:52:04.894038Z"}]}
{"channel":"book","type":"update","data":[{"symbol":"BTC/USD","bids":[{"price":67626.6,"qty":0.00000000},{"price":67614.5,"qty":0.22836862}],"asks":[],"checksum":2878998556,"timestamp":"2024-06-01T17:52:05.078055Z"}]}
{"channel":"book","type":"update","data":[{"symbol":"BTC/USD","bids":[],"asks":[{"price":67632.8,"qty":0.00000000},{"price":67638.4,"qty":1.47845082}],"checksum":538774863,"timestamp":"2024-06-01T17:52:05.078080Z"}]}
{"channel":"book","type":"update","data":[{"symbol":"BTC/USD","bids":[],"asks":[{"price":67634.7,"qty":1.47853204}],"checksum":2778260894,"timestamp":"2024-06-01T17:52:05.082021Z"}]}
{"channel":"book","type":"update","data":[{"symbol":"BTC/USD","bids":[{"price":67627.2,"qty":1.47869321}],"asks":[],"checksum":2502331383,"timestamp":"2024-06-01T17:52:05.082165Z"}]}
{"channel":"book","type":"update","data":[{"symbol":"BTC/USD","bids":[{"price":67622.5,"qty":0.00000000},{"price":67614.5,"qty":0.22836862}],"asks":[],"checksum":3483715869,"timestamp":"2024-06-01T17:52:05.144087Z"}]}
{"channel":"book","type":"update","data":[{"symbol":"BTC/USD","bids":[{"price":67627.2,"qty":0.00000000},{"price":67614.1,"qty":0.00028394}],"asks":[],"checksum":621159983,"timestamp":"2024-06-01T17:52:05.248870Z"}]}
{"channel":"book","type":"update","data":[{"symbol":"BTC/USD","bids":[{"price":67627.4,"qty":1.47868911}],"asks":[],"checksum":2323447681,"timestamp":"2024-06-01T17:52:05.252437Z"}]}
{"channel":"book","type":"update","data":[{"symbol":"BTC/USD","bids":[],"asks":[{"price":67636.1,"qty":0.00000000},{"price":67638.4,"qty":1.47845082},{"price":67635.1,"qty":0.06910000}],"checksum":1327524943,"timestamp":"2024-06-01T17:52:05.378062Z"}]}
{"channel":"book","type":"update","data":[{"symbol":"BTC/USD","bids":[{"price":67628.0,"qty":3.05147843}],"asks":[],"checksum":1138014732,"timestamp":"2024-06-01T17:52:05.404847Z"}]}
{"channel":"book","type":"update","data":[{"symbol":"BTC/USD","bids":[{"price":67625.6,"qty":1.47872897}],"asks":[],"checksum":2700379965,"timestamp":"2024-06-01T17:52:05.407321Z"}]}
{"channel":"book","type":"update","data":[{"symbol":"BTC/USD","bids":[{"price":67622.3,"qty":1.48080211}],"asks":[],"checksum":666530328,"timestamp":"2024-06-01T17:52:05.408530Z"}]}
{"channel":"book","type":"update","data":[{"symbol":"BTC/USD","bids":[],"asks":[{"price":67633.1,"qty":0.00000000},{"price":67638.4,"qty":1.47845082}],"checksum":3225374602,"timestamp":"2024-06-01T17:52:05.411770Z"}]}
{"channel":"book","type":"update","data":[{"symbol":"BTC/USD","bids":[{"price":67627.4,"qty":0.00000000},{"price":67614.1,"qty":0.00028394}],"asks":[],"checksum":3563959132,"timestamp":"2024-06-01T17:52:05.411785Z"}]}
{"channel":"book","type":"update","data":[{"symbol":"BTC/USD","bids":[{"price":67621.2,"qty":0.33750000}],"asks":[],"checksum":451108311,"timestamp":"2024-06-01T17:52:05.414309Z"}]}
{"channel":"book","type":"update","data":[{"symbol":"BTC/USD","bids":[],"asks":[{"price":67634.7,"qty":0.00000000},{"price":67639.1,"qty":0.29580000}],"checksum":4246594382,"timestamp":"2024-06-01T17:52:05.414846Z"}]}
{"channel":"book","type":"update","data":[{"symbol":"BTC/USD","bids":[],"asks":[{"price":67639.1,"qty":0.00000000},{"price":67642.2,"qty":0.33750000},{"price":67642.2,"qty":0.63330000}],"checksum":1991552007,"timestamp":"2024-06-01T17:52:05.419169Z"}]}
{"channel":"book","type":"update","data":[{"symbol":"BTC/USD","bids":[{"price":67626.2,"qty":1.47871609}],"asks":[],"checksum":3897181761,"timestamp":"2024-06-01T17:52:05.419529Z"}]}
{"channel":"book","type":"update","data":[{"symbol":"BTC/USD","bids":[],"asks":[{"price":67632.2,"qty":1.47858779}],"checksum":2232175448,"timestamp":"2024-06-01T17:52:05.419638Z"}]}
{"channel":"book","type":"update","data":[{"symbol":"BTC/USD","bids":[],"asks":[{"price":67632.2,"qty":0.00000000},{"price":67642.2,"qty":0.63330000}],"checksum":3897181761,"timestamp":"2024-06-01T17:52:05.430997Z"}]}
{"channel":"book","type":"update","data":[{"symbol":"BTC/USD","bids":[],"asks":[{"price":67635.1,"qty":0.00000000},{"price":67642.3,"qty":1.50794401},{"price":67634.1,"qty":0.06910000}],"checksum":2146148403,"timestamp":"2024-06-01T17:52:05.451307Z"}]}
{"channel":"book","type":"update","data":[{"symbol":"BTC/USD","bids":[],"asks":[{"price":67632.3,"qty":1.47858481}],"checksum":1896031352,"timestamp":"2024-06-01T17:52:05.519697Z"}]}
{"channel":"book","type":"update","data":[{"symbol":"BTC/USD","bids":[],"asks":[{"price":67632.3,"qty":0.00000000},{"price":67642.2,"qty":0.63330000}],"checksum":2146148403,"timestamp":"2024-06-01T17:52:05.531116Z"}]}
{"channel":"book","type":"update","data":[{"symbol":"BTC/USD","bids":[],"asks":[{"price":67631.9,"qty":0.00000000},{"price":67642.3,"qty":1.50794401},{"price":67638.1,"qty":0.00010000}],"checksum":4124221950,"timestamp":"2024-06-01T17:52:05.575039Z"}]}
{"channel":"book","type":"update","data":[{"symbol":"BTC/USD","bids":[],"asks":[{"price":67641.0,"qty":0.05912298}],"checksum":1770566119,"timestamp":"2024-06-01T17:52:05.578470Z"}]}
{"channel":"book","type":"update","data":[{"symbol":"BTC/USD","bids":[],"asks":[{"price":67634.1,"qty":0.00000000},{"price":67642.2,"qty":0.63330000}],"checksum":2856411537,"timestamp":"2024-06-01T17:52:05.588145Z"}]}
{"channel":"book","type":"update","data":[{"symbol":"BTC/USD","bids":[{"price":67628.0,"qty":3.12057843}],"asks":[],"checksum":2796926930,"timestamp":"2024-06-01T17:52:05.591136Z"}]}
{"channel":"book","type":"update","data":[{"symbol":"BTC/USD","bids":[],"asks":[{"price":67637.4,"qty":0.43000000}],"checksum":3635113327,"timestamp":"2024-06-01T17:52:05.591485Z"}]}
{"channel":"book","type":"update","data":[{"symbol":"BTC/USD","bids":[{"price":67628.0,"qty":3.45807843}],"asks":[],"checksum":1200222367,"timestamp":"2024-06-01T17:52:05.620802Z"}]}
{"channel":"book","type":"update","data":[{"symbol":"BTC/USD","bids":[{"price":67628.0,"qty":3.12057843}],"asks":[],"checksum":3635113327,"timestamp":"2024-06-01T17:52:05.623379Z"}]}
{"channel":"book","type":"update","data":[{"symbol":"BTC/USD","bids":[{"price":67626.2,"qty":0.00000000},{"price":67614.5,"qty":0.22836862}],"asks":[],"checksum":576744424,"timestamp":"2024-06-01T17:52:05.632756Z"}]}
{"channel":"book","type":"update","data":[{"symbol":"BTC/USD","bids":[{"price":67625.8,"qty":1.47872382}],"asks":[],"checksum":1598740727,"timestamp":"2024-06-01T17:52:05.636374Z"}]}
{"channel":"book","type":"update","data":[{"symbol":"BTC/USD","bids":[],"asks":[{"price":67632.1,"qty":1.47858984}],"checksum":199157015,"timestamp":"2024-06-01T17:52:05.636403Z"}]}
{"channel":"book","type":"update","data":[{"symbol":"BTC/USD","bids":[{"price":67625.8,"qty":0.00000000},{"price":67614.5,"qty":0.22836862}],"asks":[],"checksum":1745527326,"timestamp":"2024-06-01T17:52:05.708276Z"}]}
{"channel":"book","type":"update","data":[{"symbol":"BTC/USD","bids":[],"asks":[{"price":67632.1,"qty":0.00000000},{"price":67641.0,"qty":0.05912298}],"checksum":576744424,"timestamp":"2024-06-01T17:52:05.711553Z"}]}
{"channel":"book","type":"update","data":[{"symbol":"BTC/USD","bids":[],"asks":[{"price":67632.6,"qty":1.47857892}],"checksum":355115579,"timestamp":"2024-06-01T17:52:05.715308Z"}]}
{"channel":"book","type":"update","data":[{"symbol":"BTC/USD","bids":[],"asks":[{"price":67634.1,"qty":1.47854575}],"checksum":3121475253,"timestamp":"2024-06-01T17:52:05.715346Z"}]}
{"channel":"book","type":"update","data":[{"symbol":"BTC/USD","bids":[{"price":67626.6,"qty":1.47870665}],"asks":[],"checksum":2539866141,"timestamp":"2024-06-01T17:52:05.715450Z"}]}
{"channel":"book","type":"update","data":[{"symbol":"BTC/USD","bids":[{"price":67626.6,"qty":0.00000000},{"price":67614.5,"qty":0.22836862}],"asks":[],"checksum":3121475253,"timestamp":"2024-06-01T17:52:05.724393Z"}]}
{"channel":"book","type":"update","data":[{"symbol":"BTC/USD","bids":[],"asks":[{"price":67635.5,"qty":0.06910000}],"checksum":4020278302,"timestamp":"2024-06-01T17:52:05.736143Z"}]}
{"channel":"book","type":"update","data":[{"symbol":"BTC/USD","bids":[{"price":67622.5,"qty":0.00113926}],"asks":[],"checksum":1849482100,"timestamp":"2024-06-01T17:52:05.983430Z"}]}
{"channel":"book","type":"update","data":[{"symbol":"BTC/USD","bids":[{"price":67618.8,"qty":0.91981426}],"asks":[],"checksum":3888814811,"timestamp":"2024-06-01T17:52:06.008214Z"}]}
{"channel":"book","type":"update","data":[{"symbol":"BTC/USD","bids":[],"asks":[{"price":67632.6,"qty":0.00000000},{"price":67638.3,"qty":0.00029379}],"checksum":4287215539,"timestamp":"2024-06-01T17:52:06.045478Z"}]}
{"channel":"book","type":"update","data":[{"symbol":"BTC/USD","bids":[],"asks":[{"price":67632.3,"qty":1.47858397}],"checksum":1575613554,"timestamp":"2024-06-01T17:52:06.049789Z"}]}
{"channel":"book","type":"update","data":[{"symbol":"BTC/USD","bids":[{"price":67626.4,"qty":1.47871241}],"asks":[],"checksum":620254662,"timestamp":"2024-06-01T17:52:06.049811Z"}]}
{"channel":"book","type":"update","data":[{"symbol":"BTC/USD","bids":[],"asks":[{"price":67628.1,"qty":0.43049155}],"checksum":1945798005,"timestamp":"2024-06-01T17:52:06.105590Z"}]}
{"channel":"book","type":"update","data":[{"symbol":"BTC/USD","bids":[{"price":67618.8,"qty":0.00000000},{"price":67618.7,"qty":1.47888071}],"asks":[],"checksum":2895455435,"timestamp":"2024-06-01T17:52:06.210889Z"}]}
{"channel":"book","type":"update","data":[{"symbol":"BTC/USD","bids":[],"asks":[{"price":67635.5,"qty":0.00000000},{"price":67638.3,"qty":0.00029379},{"price":67636.4,"qty":0.06910000}],"checksum":3675312731,"timestamp":"2024-06-01T17:52:06.261005Z"}]}
{"channel":"book","type":"update","data":[{"symbol":"BTC/USD","bids":[{"price":67628.0,"qty":4.44757843}],"asks":[],"checksum":1553835643,"timestamp":"2024-06-01T17:52:06.269461Z"}]}
{"channel":"book","type":"update","data":[{"symbol":"BTC/USD","bids":[],"asks":[{"price":67636.4,"qty":0.00000000},{"price":67638.3,"qty":0.00029379},{"price":67635.3,"qty":0.06910000}],"checksum":2690133918,"timestamp":"2024-06-01T17:52:06.279620Z"}]}
{"channel":"book","type":"update","data":[{"symbol":"BTC/USD","bids":[],"asks":[{"price":67635.3,"qty":0.00000000},{"price":67638.3,"qty":0.00029379},{"price":67634.3,"qty":0.06910000}],"checksum":425266179,"timestamp":"2024-06-01T17:52:06.650134Z"}]}
{"channel":"book","type":"update","data":[{"symbol":"BTC/USD","bids":[{"price":67626.4,"qty":0.00000000},{"price":67614.7,"qty":0.91981488}],"asks":[],"checksum":782506363,"timestamp":"2024-06-01T17:52:06.858802Z"}]}
{"channel":"book","type":"update","data":[{"symbol":"BTC/USD","bids":[],"asks":[{"price":67632.3,"qty":0.00000000},{"price":67638.3,"qty":0.00029379}],"checksum":960021098,"timestamp":"2024-06-01T17:52:06.858816Z"}]}
{"channel":"book","type":"update","data":[{"symbol":"BTC/USD","bids":[],"asks":[{"price":67632.0,"qty":1.47859067}],"checksum":1564024002,"timestamp":"2024-06-01T17:52:06.863577Z"}]}
{"channel":"book","type":"update","data":[{"symbol":"BTC/USD","bids":[{"price":67626.0,"qty":1.47871947}],"asks":[],"checksum":1238548217,"timestamp":"2024-06-01T17:52:06.863673Z"}]}
{"channel":"book","type":"update","data":[{"symbol":"BTC/USD","bids":[],"asks":[{"price":67637.3,"qty":0.00029495}],"checksum":2429071277,"timestamp":"2024-06-01T17:52:07.063444Z"}]}
{"channel":"book","type":"update","data":[{"symbol":"BTC/USD","bids":[],"asks":[{"price":67632.0,"qty":0.00000000},{"price":67638.2,"qty":0.07066000}],"checksum":2603014823,"timestamp":"2024-06-01T17:52:07.279114Z"}]}
{"channel":"book","type":"update","data":[{"symbol":"BTC/USD","bids":[{"price":67626.0,"qty":0.00000000},{"price":67614.7,"qty":0.91981488}],"asks":[],"checksum":2765668324,"timestamp":"2024-06-01T17:52:07.279143Z"}]}
{"channel":"book","type":"update","data":[{"symbol":"BTC/USD","bids":[],"asks":[{"price":67632.5,"qty":1.47857944}],"checksum":2056825294,"timestamp":"2024-06-01T17:52:07.283797Z"}]}
{"channel":"book","type":"update","data":[{"symbol":"BTC/USD","bids":[{"price":67626.5,"qty":1.47870824}],"asks":[],"checksum":3549982944,"timestamp":"2024-06-01T17:52:07.283873Z"}]}
{"channel":"book","type":"update","data":[{"symbol":"BTC/USD","bids":[{"price":67626.5,"qty":0.00000000},{"price":67614.7,"qty":0.91981488}],"asks":[],"checksum":2056825294,"timestamp":"2024-06-01T17:52:07.328897Z"}]}
{"channel":"book","type":"update","data":[{"symbol":"BTC/USD","bids":[],"asks":[{"price":67632.5,"qty":0.00000000},{"price":67638.2,"qty":0.07066000}],"checksum":2765668324,"timestamp":"2024-06-01T17:52:07.329001Z"}]}
{"channel":"book","type":"update","data":[{"symbol":"BTC/USD","bids":[],"asks":[{"price":67637.3,"qty":0.00000000},{"price":67638.4,"qty":1.47845082},{"price":67638.3,"qty":0.00029495}],"checksum":2308628048,"timestamp":"2024-06-01T17:52:07.361145Z"}]}
{"channel":"book","type":"update","data":[{"symbol":"BTC/USD","bids":[],"asks":[{"price":67632.5,"qty":1.47857988}],"checksum":3816014966,"timestamp":"2024-06-01T17:52:07.793928Z"}]}
{"channel":"book","type":"update","data":[{"symbol":"BTC/USD","bids":[{"price":67626.5,"qty":1.47870986}],"asks":[],"checksum":1106796241,"timestamp":"2024-06-01T17:52:07.793966Z"}]}
{"channel":"book","type":"update","data":[{"symbol":"BTC/USD","bids":[],"asks":[{"price":67632.5,"qty":0.00000000},{"price":67638.4,"qty":1.47845082}],"checksum":1465895374,"timestamp":"2024-06-01T17:52:07.825733Z"}]}
{"channel":"book","type":"update","data":[{"symbol":"BTC/USD","bids":[{"price":67626.5,"qty":0.00000000},{"price":67614.7,"qty":0.91981488}],"asks":[],"checksum":673947305,"timestamp":"2024-06-01T17:52:07.825885Z"}]}
{"channel":"book","type":"update","data":[{"symbol":"BTC/USD","bids":[{"price":67626.0,"qty":1.47872081}],"asks":[],"checksum":3021871473,"timestamp":"2024-06-01T17:52:07.843789Z"}]}
{"channel":"book","type":"update","data":[{"symbol":"BTC/USD","bids":[],"asks":[{"price":67632.0,"qty":1.47859083}],"checksum":2022358338,"timestamp":"2024-06-01T17:52:07.843985Z"}]}
{"channel":"book","type":"update","data":[{"symbol":"BTC/USD","bids":[],"asks":[{"price":67632.0,"qty":0.00000000},{"price":67638.4,"qty":1.47845082}],"checksum":3021871473,"timestamp":"2024-06-01T17:52:07.858334Z"}]}
{"channel":"book","type":"update","data":[{"symbol":"BTC/USD","bids":[{"price":67622.3,"qty":1.47980211}],"asks":[],"checksum":2795938571,"timestamp":"2024-06-01T17:52:08.026481Z"}]}
{"channel":"book","type":"update","data":[{"symbol":"BTC/USD","bids":[],"asks":[{"price":67638.3,"qty":0.00029495}],"checksum":1650874611,"timestamp":"2024-06-01T17:52:08.100551Z"}]}
{"channel":"book","type":"update","data":[{"symbol":"BTC/USD","bids":[],"asks":[{"price":67638.3,"qty":0.00000000},{"price":67638.4,"qty":1.47845082}],"checksum":2795938571,"timestamp":"2024-06-01T17:52:08.189746Z"}]}
{"channel":"book","type":"update","data":[{"symbol":"BTC/USD","bids":[{"price":67626.0,"qty":0.00000000},{"price":67614.7,"qty":0.91981488}],"asks":[],"checksum":155650937,"timestamp":"2024-06-01T17:52:08.294508Z"}]}
{"channel":"book","type":"update","data":[{"symbol":"BTC/USD","bids":[{"price":67626.4,"qty":1.47871197}],"asks":[],"checksum":143238478,"timestamp":"2024-06-01T17:52:08.298339Z"}]}
{"channel":"book","type":"update","data":[{"symbol":"BTC/USD","bids":[],"asks":[{"price":67632.2,"qty":1.47858668}],"checksum":3390000868,"timestamp":"2024-06-01T17:52:08.298390Z"}]}
{"channel":"book","type":"update","data":[{"symbol":"BTC/USD","bids":[{"price":67626.4,"qty":0.00000000},{"price":67614.7,"qty":0.91981488}],"asks":[],"checksum":1481836229,"timestamp":"2024-06-01T17:52:08.310096Z"}]}
{"channel":"book","type":"update","data":[{"symbol":"BTC/USD","bids":[],"asks":[{"price":67634.1,"qty":0.00000000},{"price":67638.4,"qty":1.47845082}],"checksum":2946159467,"timestamp":"2024-06-01T17:52:08.310178Z"}]}
{"channel":"book","type":"update","data":[{"symbol":"BTC/USD","bids":[],"asks":[{"price":67632.2,"qty":0.00000000},{"price":67641.1,"qty":0.00029495}],"checksum":361863269,"timestamp":"2024-06-01T17:52:08.360798Z"}]}
{"channel":"book","type":"update","data":[{"symbol":"BTC/USD","bids":[],"asks":[{"price":67641.1,"qty":0.29609495}],"checksum":1943521301,"timestamp":"2024-06-01T17:52:08.363821Z"}]}
{"channel":"book","type":"update","data":[{"symbol":"BTC/USD","bids":[],"asks":[{"price":67631.9,"qty":1.47859245}],"checksum":2816963035,"timestamp":"2024-06-01T17:52:08.366521Z"}]}
{"channel":"book","type":"update","data":[{"symbol":"BTC/USD","bids":[{"price":67626.1,"qty":1.47871773}],"asks":[],"checksum":3078895658,"timestamp":"2024-06-01T17:52:08.366657Z"}]}
{"channel":"book","type":"update","data":[{"symbol":"BTC/USD","bids":[],"asks":[{"price":67631.9,"qty":0.00000000},{"price":67641.1,"qty":0.29609495}],"checksum":3415009060,"timestamp":"2024-06-01T17:52:08.370663Z"}]}
{"channel":"book","type":"update","data":[{"symbol":"BTC/USD","bids":[],"asks":[{"price":67632.1,"qty":1.47858904}],"checksum":4281440186,"timestamp":"2024-06-01T17:52:08.563105Z"}]}
{"channel":"book","type":"update","data":[{"symbol":"BTC/USD","bids":[],"asks":[{"price":67632.1,"qty":0.00000000},{"price":67641.1,"qty":0.29609495}],"checksum":3415009060,"timestamp":"2024-06-01T17:52:08.612658Z"}]}
{"channel":"book","type":"update","data":[{"symbol":"BTC/USD","bids":[],"asks":[{"price":67631.7,"qty":1.47859747}],"checksum":24395659,"timestamp":"2024-06-01T17:52:08.616312Z"}]}
{"channel":"book","type":"update","data":[{"symbol":"BTC/USD","bids":[{"price":67628.0,"qty":4.44857843}],"asks":[],"checksum":2004291455,"timestamp":"2024-06-01T17:52:09.036450Z"}]}
{"channel":"book","type":"update","data":[{"symbol":"BTC/USD","bids":[{"price":67626.1,"qty":0.00000000},{"price":67614.7,"qty":0.91981488}],"asks":[],"checksum":4005333412,"timestamp":"2024-06-01T17:52:10.076380Z"}]}
{"channel":"book","type":"update","data":[{"symbol":"BTC/USD","bids":[],"asks":[{"price":67632.6,"qty":1.47857884}],"checksum":2477731737,"timestamp":"2024-06-01T17:52:10.079624Z"}]}
{"channel":"book","type":"update","data":[{"symbol":"BTC/USD","bids":[{"price":67625.8,"qty":1.47872468}],"asks":[],"checksum":3655828430,"timestamp":"2024-06-01T17:52:10.079668Z"}]}
{"channel":"book","type":"update","data":[{"symbol":"BTC/USD","bids":[{"price":67622.5,"qty":0.00000000},{"price":67614.7,"qty":0.91981488},{"price":67628.0,"qty":4.44971744}],"asks":[],"checksum":1789081907,"timestamp":"2024-06-01T17:52:10.184442Z"}]}
{"channel":"book","type":"update","data":[{"symbol":"BTC/USD","bids":[{"price":67628.0,"qty":4.44857843},{"price":67625.9,"qty":0.00113891}],"asks":[],"checksum":2414629234,"timestamp":"2024-06-01T17:52:10.246558Z"}]}
{"channel":"book","type":"update","data":[{"symbol":"BTC/USD","bids":[],"asks":[{"price":67638.1,"qty":0.00000000},{"price":67638.4,"qty":1.47845082},{"price":67633.0,"qty":0.00010000}],"checksum":1625575954,"timestamp":"2024-06-01T17:52:10.612804Z"}]}
{"channel":"book","type":"update","data":[{"symbol":"BTC/USD","bids":[{"price":67625.9,"qty":0.00000000},{"price":67614.7,"qty":0.91981488},{"price":67628.0,"qty":4.44971731}],"asks":[],"checksum":3255408528,"timestamp":"2024-06-01T17:52:11.262528Z"}]}
{"channel":"book","type":"update","data":[{"symbol":"BTC/USD","bids":[{"price":67628.0,"qty":4.44857843},{"price":67625.9,"qty":0.00113891}],"asks":[],"checksum":1625575954,"timestamp":"2024-06-01T17:52:11.319206Z"}]}
{"channel":"book","type":"update","data":[{"symbol":"BTC/USD","bids":[],"asks":[{"price":67631.7,"qty":0.00000000},{"price":67638.3,"qty":0.00029496}],"checksum":245206972,"timestamp":"2024-06-01T17:52:12.121590Z"}]}
{"channel":"book","type":"update","data":[{"symbol":"BTC/USD","bids":[],"asks":[{"price":67636.2,"qty":1.47849828}],"checksum":839852570,"timestamp":"2024-06-01T17:52:12.125702Z"}]}
{"channel":"book","type":"update","data":[{"symbol":"BTC/USD","bids":[],"asks":[{"price":67631.5,"qty":1.47860261}],"checksum":3178343031,"timestamp":"2024-06-01T17:52:12.126007Z"}]}
{"channel":"book","type":"update","data":[{"symbol":"BTC/USD","bids":[],"asks":[{"price":67631.5,"qty":0.00000000},{"price":67638.2,"qty":0.07066000}],"checksum":839852570,"timestamp":"2024-06-01T17:52:12.137610Z"}]}
{"channel":"book","type":"update","data":[{"symbol":"BTC/USD","bids":[{"price":67625.8,"qty":0.00000000},{"price":67614.7,"qty":0.91981488}],"asks":[],"checksum":1030361069,"timestamp":"2024-06-01T17:52:12.137764Z"}]}
{"channel":"book","type":"update","data":[{"symbol":"BTC/USD","bids":[{"price":67626.1,"qty":1.47871718}],"asks":[],"checksum":431652048,"timestamp":"2024-06-01T17:52:12.141609Z"}]}
{"channel":"book","type":"update","data":[{"symbol":"BTC/USD","bids":[{"price":67626.1,"qty":0.00000000},{"price":67614.7,"qty":0.91981488}],"asks":[],"checksum":1030361069,"timestamp":"2024-06-01T17:52:12.145486Z"}]}
{"channel":"book","type":"update","data":[{"symbol":"BTC/USD","bids":[{"price":67628.0,"qty":4.78607843}],"asks":[],"checksum":1340045489,"timestamp":"2024-06-01T17:52:12.149776Z"}]}
{"channel":"book","type":"update","data":[{"symbol":"BTC/USD","bids":[{"price":67628.0,"qty":4.44857843}],"asks":[],"checksum":1030361069,"timestamp":"2024-06-01T17:52:12.162021Z"}]}
{"channel":"book","type":"update","data":[{"symbol":"BTC/USD","bids":[],"asks":[{"price":67631.9,"qty":1.47859241}],"checksum":3069609125,"timestamp":"2024-06-01T17:52:12.187908Z"}]}
{"channel":"book","type":"update","data":[{"symbol":"BTC/USD","bids":[{"price":67626.0,"qty":1.47872014}],"asks":[],"checksum":1812207478,"timestamp":"2024-06-01T17:52:12.191787Z"}]}
{"channel":"book","type":"update","data":[{"symbol":"BTC/USD","bids":[{"price":67625.9,"qty":0.00000000},{"price":67614.7,"qty":0.91981488},{"price":67625.7,"qty":0.00113918}],"asks":[],"checksum":549570714,"timestamp":"2024-06-01T17:52:12.203861Z"}]}
{"channel":"book","type":"update","data":[{"symbol":"BTC/USD","bids":[],"asks":[{"price":67631.9,"qty":0.00000000},{"price":67638.2,"qty":0.07066000}],"checksum":1481481651,"timestamp":"2024-06-01T17:52:12.252496Z"}]}
{"channel":"book","type":"update","data":[{"symbol":"BTC/USD","bids":[],"asks":[{"price":67631.5,"qty":1.47860261}],"checksum":3610449374,"timestamp":"2024-06-01T17:52:12.256197Z"}]}
{"channel":"book","type":"update","data":[{"symbol":"BTC/USD","bids":[{"price":67621.3,"qty":0.91978771}],"asks":[],"checksum":1030764690,"timestamp":"2024-06-01T17:52:12.298005Z"}]}
{"channel":"book","type":"update","data":[{"symbol":"BTC/USD","bids":[],"asks":[{"price":67631.5,"qty":0.00000000},{"price":67638.2,"qty":0.07066000}],"checksum":644262478,"timestamp":"2024-06-01T17:52:12.347815Z"}]}
{"channel":"book","type":"update","data":[{"symbol":"BTC/USD","bids":[],"asks":[{"price":67631.3,"qty":1.47860648}],"checksum":880488311,"timestamp":"2024-06-01T17:52:12.351696Z"}]}
{"channel":"book","type":"update","data":[{"symbol":"BTC/USD","bids":[{"price":67621.3,"qty":0.00000000},{"price":67618.7,"qty":1.47888071}],"asks":[],"checksum":123340862,"timestamp":"2024-06-01T17:52:12.353791Z"}]}
{"channel":"book","type":"update","data":[{"symbol":"BTC/USD","bids":[{"price":67618.8,"qty":0.91978825}],"asks":[],"checksum":44063199,"timestamp":"2024-06-01T17:52:12.354084Z"}]}
{"channel":"book","type":"update","data":[{"symbol":"BTC/USD","bids":[{"price":67625.7,"qty":0.00000000},{"price":67618.7,"qty":1.47888071},{"price":67626.1,"qty":0.00113917}],"asks":[],"checksum":317139051,"timestamp":"2024-06-01T17:52:12.375638Z"}]}
{"channel":"book","type":"update","data":[{"symbol":"BTC/USD","bids":[],"asks":[{"price":67631.3,"qty":0.00000000},{"price":67638.1,"qty":0.00029501}],"checksum":3634429088,"timestamp":"2024-06-01T17:52:12.716099Z"}]}
{"channel":"book","type":"update","data":[{"symbol":"BTC/USD","bids":[{"price":67626.0,"qty":0.00000000},{"price":67618.7,"qty":1.47888071}],"asks":[],"checksum":1320834708,"timestamp":"2024-06-01T17:52:12.716113Z"}]}
{"channel":"book","type":"update","data":[{"symbol":"BTC/USD","bids":[],"asks":[{"price":67632.2,"qty":1.47858696}],"checksum":3097251781,"timestamp":"2024-06-01T17:52:12.720532Z"}]}
{"channel":"book","type":"update","data":[{"symbol":"BTC/USD","bids":[{"price":67626.4,"qty":1.47871088}],"asks":[],"checksum":2546186046,"timestamp":"2024-06-01T17:52:12.720680Z"}]}
{"channel":"book","type":"update","data":[{"symbol":"BTC/USD","bids":[{"price":67626.4,"qty":0.00000000},{"price":67618.7,"qty":1.47888071}],"asks":[],"checksum":3097251781,"timestamp":"2024-06-01T17:52:12.728007Z"}]}
{"channel":"book","type":"update","data":[{"symbol":"BTC/USD","bids":[],"asks":[{"price":67632.2,"qty":0.00000000},{"price":67638.1,"qty":0.00029501}],"checksum":1320834708,"timestamp":"2024-06-01T17:52:12.728168Z"}]}
{"channel":"book","type":"update","data":[{"symbol":"BTC/USD","bids":[{"price":67624.4,"qty":1.47875608}],"asks":[],"checksum":3238358814,"timestamp":"2024-06-01T17:52:12.732399Z"}]}
{"channel":"book","type":"update","data":[{"symbol":"BTC/USD","bids":[{"price":67625.6,"qty":0.00000000},{"price":67618.7,"qty":1.47888071}],"asks":[],"checksum":1399674476,"timestamp":"2024-06-01T17:52:12.768728Z"}]}
{"channel":"book","type":"update","data":[{"symbol":"BTC/USD","bids":[{"price":67626.0,"qty":1.47872094}],"asks":[],"checksum":2608048275,"timestamp":"2024-06-01T17:52:12.772415Z"}]}
{"channel":"book","type":"update","data":[{"symbol":"BTC/USD","bids":[],"asks":[{"price":67631.5,"qty":1.47860204}],"checksum":1201484617,"timestamp":"2024-06-01T17:52:12.772432Z"}]}
{"channel":"book","type":"update","data":[{"symbol":"BTC/USD","bids":[],"asks":[{"price":67631.5,"qty":0.00000000},{"price":67638.1,"qty":0.00029501}],"checksum":2608048275,"timestamp":"2024-06-01T17:52:13.060111Z"}]}
{"channel":"book","type":"update","data":[{"symbol":"BTC/USD","bids":[{"price":67626.0,"qty":0.00000000},{"price":67618.7,"qty":1.47888071}],"asks":[],"checksum":1399674476,"timestamp":"2024-06-01T17:52:13.060138Z"}]}
{"channel":"book","type":"update","data":[{"symbol":"BTC/USD","bids":[],"asks":[{"price":67631.3,"qty":1.47860648}],"checksum":2569700007,"timestamp":"2024-06-01T17:52:13.066229Z"}]}
{"channel":"book","type":"update","data":[{"symbol":"BTC/USD","bids":[{"price":67625.5,"qty":1.47873040}],"asks":[],"checksum":1048758421,"timestamp":"2024-06-01T17:52:13.066366Z"}]}
{"channel":"book","type":"update","data":[{"symbol":"BTC/USD","bids":[{"price":67626.1,"qty":0.00000000},{"price":67618.7,"qty":1.47888071},{"price":67624.5,"qty":0.00113920}],"asks":[],"checksum":3979020871,"timestamp":"2024-06-01T17:52:13.496096Z"}]}
{"channel":"book","type":"update","data":[{"symbol":"BTC/USD","bids":[{"price":67624.5,"qty":0.00000000},{"price":67618.7,"qty":1.47888071},{"price":67618.9,"qty":0.00113956}],"asks":[],"checksum":1448334194,"timestamp":"2024-06-01T17:52:13.553441Z"}]}
{"channel":"book","type":"update","data":[{"symbol":"BTC/USD","bids":[{"price":67628.0,"qty":3.12157843}],"asks":[],"checksum":1057665168,"timestamp":"2024-06-01T17:52:13.725175Z"}]}
{"channel":"book","type":"update","data":[{"symbol":"BTC/USD","bids":[{"price":67628.0,"qty":4.31757843}],"asks":[],"checksum":149547274,"timestamp":"2024-06-01T17:52:13.727820Z"}]}
{"channel":"book","type":"update","data":[{"symbol":"BTC/USD","bids":[{"price":67625.5,"qty":0.00000000},{"price":67618.7,"qty":1.47888071}],"asks":[],"checksum":2567304098,"timestamp":"2024-06-01T17:52:14.016743Z"}]}
{"channel":"book","type":"update","data":[{"symbol":"BTC/USD","bids":[],"asks":[{"price":67631.3,"qty":0.00000000},{"price":67638.1,"qty":0.00029501}],"checksum":1396844393,"timestamp":"2024-06-01T17:52:14.016840Z"}]}
{"channel":"book","type":"update","data":[{"symbol":"BTC/USD","bids":[{"price":67626.0,"qty":1.47871981}],"asks":[],"checksum":1547412231,"timestamp":"2024-06-01T17:52:14.021291Z"}]}
{"channel":"book","type":"update","data":[{"symbol":"BTC/USD","bids":[],"asks":[{"price":67631.8,"qty":1.58950896}],"checksum":1659766071,"timestamp":"2024-06-01T17:52:14.021423Z"}]}
{"channel":"book","type":"update","data":[{"symbol":"BTC/USD","bids":[],"asks":[{"price":67631.8,"qty":0.11091373}],"checksum":1547412231,"timestamp":"2024-06-01T17:52:14.147931Z"}]}
{"channel":"book","type":"update","data":[{"symbol":"BTC/USD","bids":[],"asks":[{"price":67631.5,"qty":1.47860115}],"checksum":1836576642,"timestamp":"2024-06-01T17:52:14.151816Z"}]}
{"channel":"book","type":"update","data":[{"symbol":"BTC/USD","bids":[],"asks":[{"price":67631.5,"qty":0.00000000},{"price":67638.1,"qty":0.00029501}],"checksum":1547412231,"timestamp":"2024-06-01T17:52:14.185219Z"}]}
{"channel":"book","type":"update","data":[{"symbol":"BTC/USD","bids":[{"price":67626.0,"qty":0.00000000},{"price":67618.7,"qty":1.47888071}],"asks":[],"checksum":1396844393,"timestamp":"2024-06-01T17:52:14.187714Z"}]}
{"channel":"book","type":"update","data":[{"symbol":"BTC/USD","bids":[{"price":67625.7,"qty":1.47872647}],"asks":[],"checksum":2548895611,"timestamp":"2024-06-01T17:52:14.191825Z"}]}
{"channel":"book","type":"update","data":[{"symbol":"BTC/USD","bids":[{"price":67625.7,"qty":0.00000000},{"price":67618.7,"qty":1.47888071}],"asks":[],"checksum":1396844393,"timestamp":"2024-06-01T17:52:14.206414Z"}]}
{"channel":"book","type":"update","data":[{"symbol":"BTC/USD","bids":[],"asks":[{"price":67631.9,"qty":1.47859316}],"checksum":1755926290,"timestamp":"2024-06-01T17:52:14.210441Z"}]}
{"channel":"book","type":"update","data":[{"symbol":"BTC/USD","bids":[{"price":67618.7,"qty":0.00000000},{"price":67614.6,"qty":0.05912737}],"asks":[],"checksum":3701850381,"timestamp":"2024-06-01T17:52:14.418811Z"}]}
{"channel":"book","type":"update","data":[{"symbol":"BTC/USD","bids":[],"asks":[{"price":67631.9,"qty":0.00000000},{"price":67638.1,"qty":0.00029501}],"checksum":4045814111,"timestamp":"2024-06-01T17:52:14.418823Z"}]}
{"channel":"book","type":"update","data":[{"symbol":"BTC/USD","bids":[{"price":67625.4,"qty":1.47873386}],"asks":[],"checksum":10573673,"timestamp":"2024-06-01T17:52:14.422736Z"}]}
{"channel":"book","type":"update","data":[{"symbol":"BTC/USD","bids":[],"asks":[{"price":67631.1,"qty":1.47861065}],"checksum":656612549,"timestamp":"2024-06-01T17:52:14.422840Z"}]}
{"channel":"book","type":"update","data":[{"symbol":"BTC/USD","bids":[{"price":67625.4,"qty":0.00000000},{"price":67615.6,"qty":1.47894753}],"asks":[],"checksum":4267166175,"timestamp":"2024-06-01T17:52:14.427875Z"}]}
{"channel":"book","type":"update","data":[{"symbol":"BTC/USD","bids":[],"asks":[{"price":67631.1,"qty":0.00000000},{"price":67638.1,"qty":0.00029501}],"checksum":3654648435,"timestamp":"2024-06-01T17:52:14.427919Z"}]}
{"channel":"book","type":"update","data":[{"symbol":"BTC/USD","bids":[],"asks":[{"price":67631.1,"qty":1.47861076}],"checksum":658382589,"timestamp":"2024-06-01T17:52:14.495706Z"}]}
{"channel":"book","type":"update","data":[{"symbol":"BTC/USD","bids":[{"price":67625.4,"qty":1.47873386}],"asks":[],"checksum":4266314727,"timestamp":"2024-06-01T17:52:14.495743Z"}]}
{"channel":"book","type":"update","data":[{"symbol":"BTC/USD","bids":[],"asks":[{"price":67631.1,"qty":0.00000000},{"price":67638.1,"qty":0.00029501}],"checksum":10573673,"timestamp":"2024-06-01T17:52:14.514729Z"}]}
{"channel":"book","type":"update","data":[{"symbol":"BTC/USD","bids":[{"price":67625.4,"qty":0.00000000},{"price":67615.6,"qty":1.47894753}],"asks":[],"checksum":3654648435,"timestamp":"2024-06-01T17:52:14.514754Z"}]}
{"channel":"book","type":"update","data":[{"symbol":"BTC/USD","bids":[],"asks":[{"price":67631.1,"qty":1.47861076}],"checksum":658382589,"timestamp":"2024-06-01T17:52:14.565519Z"}]}
{"channel":"book","type":"update","data":[{"symbol":"BTC/USD","bids":[{"price":67625.4,"qty":1.47873386}],"asks":[],"checksum":4266314727,"timestamp":"2024-06-01T17:52:14.565559Z"}]}
{"channel":"book","type":"update","data":[{"symbol":"BTC/USD","bids":[{"price":67625.4,"qty":0.00000000},{"price":67615.6,"qty":1.47894753}],"asks":[],"checksum":658382589,"timestamp":"2024-06-01T17:52:14.615982Z"}]}
{"channel":"book","type":"update","data":[{"symbol":"BTC/USD","bids":[{"price":67625.6,"qty":1.47872838}],"asks":[],"checksum":3398204633,"timestamp":"2024-06-01T17:52:14.619685Z"}]}
{"channel":"book","type":"update","data":[{"symbol":"BTC/USD","bids":[{"price":67625.6,"qty":0.00000000},{"price":67615.6,"qty":1.47894753}],"asks":[],"checksum":658382589,"timestamp":"2024-06-01T17:52:14.653622Z"}]}
{"channel":"book","type":"update","data":[{"symbol":"BTC/USD","bids":[],"asks":[{"price":67631.1,"qty":0.00000000},{"price":67638.2,"qty":0.07066000}],"checksum":26203009,"timestamp":"2024-06-01T17:52:14.653634Z"}]}
{"channel":"book","type":"update","data":[{"symbol":"BTC/USD","bids":[{"price":67618.8,"qty":0.00000000},{"price":67614.6,"qty":0.05912737}],"asks":[],"checksum":3938092224,"timestamp":"2024-06-01T17:52:14.656915Z"}]}
{"channel":"book","type":"update","data":[{"symbol":"BTC/USD","bids":[{"price":67615.7,"qty":0.91978950}],"asks":[],"checksum":624854710,"timestamp":"2024-06-01T17:52:14.657183Z"}]}
{"channel":"book","type":"update","data":[{"symbol":"BTC/USD","bids":[],"asks":[{"price":67631.7,"qty":1.47859789}],"checksum":2077261276,"timestamp":"2024-06-01T17:52:14.657476Z"}]}
{"channel":"book","type":"update","data":[{"symbol":"BTC/USD","bids":[],"asks":[{"price":67634.3,"qty":0.00000000},{"price":67638.2,"qty":0.07066000},{"price":67636.5,"qty":0.06910000}],"checksum":3996896580,"timestamp":"2024-06-01T17:52:14.700486Z"}]}
{"channel":"book","type":"update","data":[{"symbol":"BTC/USD","bids":[],"asks":[{"price":67636.5,"qty":0.13820000}],"checksum":3112286611,"timestamp":"2024-06-01T17:52:14.703475Z"}]}
{"channel":"book","type":"update","data":[{"symbol":"BTC/USD","bids":[{"price":67618.9,"qty":0.00000000},{"price":67614.6,"qty":0.05912737},{"price":67615.8,"qty":0.00113937}],"asks":[],"checksum":79958070,"timestamp":"2024-06-01T17:52:14.717702Z"}]}
{"channel":"book","type":"update","data":[{"symbol":"BTC/USD","bids":[],"asks":[{"price":67636.5,"qty":0.06910000}],"checksum":1400792289,"timestamp":"2024-06-01T17:52:14.735797Z"}]}
{"channel":"book","type":"update","data":[{"symbol":"BTC/USD","bids":[],"asks":[{"price":67636.5,"qty":0.00000000},{"price":67638.2,"qty":0.07066000},{"price":67635.2,"qty":0.06910000}],"checksum":3015748128,"timestamp":"2024-06-01T17:52:14.735967Z"}]}
{"channel":"book","type":"update","data":[{"symbol":"BTC/USD","bids":[],"asks":[{"price":67635.2,"qty":0.13820000}],"checksum":1545462185,"timestamp":"2024-06-01T17:52:14.744542Z"}]}
{"channel":"book","type":"update","data":[{"symbol":"BTC/USD","bids":[],"asks":[{"price":67635.2,"qty":0.06910000}],"checksum":3015748128,"timestamp":"2024-06-01T17:52:14.747476Z"}]}
{"channel":"book","type":"update","data":[{"symbol":"BTC/USD","bids":[],"asks":[{"price":67631.7,"qty":0.00000000},{"price":67638.2,"qty":0.07066000}],"checksum":3264643034,"timestamp":"2024-06-01T17:52:14.797753Z"}]}
{"channel":"book","type":"update","data":[{"symbol":"BTC/USD","bids":[],"asks":[{"price":67631.3,"qty":1.47860617}],"checksum":4112470875,"timestamp":"2024-06-01T17:52:14.801977Z"}]}
{"channel":"book","type":"update","data":[{"symbol":"BTC/USD","bids":[{"price":67625.6,"qty":1.47872869}],"asks":[],"checksum":2107245306,"timestamp":"2024-06-01T17:52:14.802068Z"}]}
{"channel":"book","type":"update","data":[{"symbol":"BTC/USD","bids":[{"price":67625.6,"qty":0.00000000},{"price":67615.6,"qty":1.47894753}],"asks":[],"checksum":4112470875,"timestamp":"2024-06-01T17:52:14.814481Z"}]}
{"channel":"book","type":"update","data":[{"symbol":"BTC/USD","bids":[],"asks":[{"price":67631.3,"qty":0.00000000},{"price":67638.2,"qty":0.07066000}],"checksum":3264643034,"timestamp":"2024-06-01T17:52:14.903570Z"}]}
{"channel":"book","type":"update","data":[{"symbol":"BTC/USD","bids":[],"asks":[{"price":67631.8,"qty":1.58950868}],"checksum":513471022,"timestamp":"2024-06-01T17:52:14.907712Z"}]}
{"channel":"book","type":"update","data":[{"symbol":"BTC/USD","bids":[{"price":67626.1,"qty":1.47871683}],"asks":[],"checksum":1808765584,"timestamp":"2024-06-01T17:52:14.907866Z"}]}
{"channel":"book","type":"update","data":[{"symbol":"BTC/USD","bids":[],"asks":[{"price":67628.1,"qty":0.40468737}],"checksum":1176596556,"timestamp":"2024-06-01T17:52:14.979773Z"}]}
{"channel":"book","type":"update","data":[{"symbol":"BTC/USD","bids":[{"price":67628.0,"qty":4.65507843}],"asks":[],"checksum":3576133906,"timestamp":"2024-06-01T17:52:14.983387Z"}]}
{"channel":"book","type":"update","data":[{"symbol":"BTC/USD","bids":[],"asks":[{"price":67628.1,"qty":0.40000000}],"checksum":1454946160,"timestamp":"2024-06-01T17:52:14.985473Z"}]}
{"channel":"book","type":"update","data":[{"symbol":"BTC/USD","bids":[{"price":67615.7,"qty":0.00000000},{"price":67615.6,"qty":1.47894753}],"asks":[],"checksum":837523612,"timestamp":"2024-06-01T17:52:15.012606Z"}]}
{"channel":"book","type":"update","data":[{"symbol":"BTC/USD","bids":[{"price":67622.5,"qty":0.91978336}],"asks":[],"checksum":1271699499,"timestamp":"2024-06-01T17:52:15.012710Z"}]}
{"channel":"book","type":"update","data":[{"symbol":"BTC/USD","bids":[],"asks":[{"price":67631.8,"qty":0.11091373}],"checksum":2583154057,"timestamp":"2024-06-01T17:52:15.072480Z"}]}
{"channel":"book","type":"update","data":[{"symbol":"BTC/USD","bids":[{"price":67624.4,"qty":0.00000000},{"price":67615.6,"qty":1.47894753}],"asks":[],"checksum":1606867102,"timestamp":"2024-06-01T17:52:15.072533Z"}]}
{"channel":"book","type":"update","data":[{"symbol":"BTC/USD","bids":[],"asks":[{"price":67632.3,"qty":1.47858386}],"checksum":284532770,"timestamp":"2024-06-01T17:52:15.076890Z"}]}
{"channel":"book","type":"update","data":[{"symbol":"BTC/USD","bids":[{"price":67626.7,"qty":1.47870574}],"asks":[],"checksum":346662369,"timestamp":"2024-06-01T17:52:15.076992Z"}]}
{"channel":"book","type":"update","data":[{"symbol":"BTC/USD","bids":[{"price":67628.0,"qty":4.31757843}],"asks":[],"checksum":2276437183,"timestamp":"2024-06-01T17:52:15.088158Z"}]}
{"channel":"book","type":"update","data":[{"symbol":"BTC/USD","bids":[],"asks":[{"price":67632.3,"qty":0.00000000},{"price":67638.2,"qty":0.07066000}],"checksum":3365721091,"timestamp":"2024-06-01T17:52:15.122943Z"}]}
{"channel":"book","type":"update","data":[{"symbol":"BTC/USD","bids":[{"price":67626.7,"qty":0.00000000},{"price":67615.6,"qty":1.47894753}],"asks":[],"checksum":3435188672,"timestamp":"2024-06-01T17:52:15.122999Z"}]}
{"channel":"book","type":"update","data":[{"symbol":"BTC/USD","bids":[],"asks":[{"price":67631.6,"qty":1.47859895}],"checksum":312761658,"timestamp":"2024-06-01T17:52:15.127234Z"}]}
{"channel":"book","type":"update","data":[{"symbol":"BTC/USD","bids":[{"price":67624.6,"qty":1.47875081}],"asks":[],"checksum":2399866467,"timestamp":"2024-06-01T17:52:15.127361Z"}]}
{"channel":"book","type":"update","data":[{"symbol":"BTC/USD","bids":[],"asks":[{"price":67631.6,"qty":0.00000000},{"price":67638.2,"qty":0.07066000}],"checksum":1366262425,"timestamp":"2024-06-01T17:52:15.142405Z"}]}
{"channel":"book","type":"update","data":[{"symbol":"BTC/USD","bids":[{"price":67626.1,"qty":0.00000000},{"price":67615.6,"qty":1.47894753}],"asks":[],"checksum":2082886112,"timestamp":"2024-06-01T17:52:15.146008Z"}]}
{"channel":"book","type":"update","data":[{"symbol":"BTC/USD","bids":[{"price":67626.5,"qty":1.47871018}],"asks":[],"checksum":362314879,"timestamp":"2024-06-01T17:52:15.149237Z"}]}
{"channel":"book","type":"update","data":[{"symbol":"BTC/USD","bids":[{"price":67622.5,"qty":0.00000000},{"price":67615.6,"qty":1.47894753}],"asks":[],"checksum":1572034965,"timestamp":"2024-06-01T17:52:15.275662Z"}]}
{"channel":"book","type":"update","data":[{"symbol":"BTC/USD","bids":[{"price":67615.7,"qty":0.91978875}],"asks":[],"checksum":1265807134,"timestamp":"2024-06-01T17:52:15.275921Z"}]}
{"channel":"book","type":"update","data":[{"symbol":"BTC/USD","bids":[],"asks":[{"price":67635.2,"qty":0.00000000},{"price":67641.0,"qty":0.00029482}],"checksum":297732760,"timestamp":"2024-06-01T17:52:15.315503Z"}]}
{"channel":"book","type":"update","data":[{"symbol":"BTC/USD","bids":[{"price":67628.0,"qty":4.65507843}],"asks":[],"checksum":2193163206,"timestamp":"2024-06-01T17:52:15.327259Z"}]}
{"channel":"book","type":"update","data":[{"symbol":"BTC/USD","bids":[{"price":67626.5,"qty":0.00000000},{"price":67615.6,"qty":1.47894753}],"asks":[],"checksum":3619517162,"timestamp":"2024-06-01T17:52:15.349112Z"}]}
{"channel":"book","type":"update","data":[{"symbol":"BTC/USD","bids":[{"price":67626.7,"qty":1.47870397}],"asks":[],"checksum":3127425284,"timestamp":"2024-06-01T17:52:15.352856Z"}]}
{"channel":"book","type":"update","data":[{"symbol":"BTC/USD","bids":[],"asks":[{"price":67632.4,"qty":1.47858209}],"checksum":3155347339,"timestamp":"2024-06-01T17:52:15.352911Z"}]}
{"channel":"book","type":"update","data":[{"symbol":"BTC/USD","bids":[{"price":67628.0,"qty":4.99257843}],"asks":[],"checksum":1236545516,"timestamp":"2024-06-01T17:52:15.355509Z"}]}
{"channel":"book","type":"update","data":[{"symbol":"BTC/USD","bids":[],"asks":[{"price":67632.4,"qty":0.00000000},{"price":67641.0,"qty":0.00029482}],"checksum":1338921315,"timestamp":"2024-06-01T17:52:15.358185Z"}]}
{"channel":"book","type":"update","data":[{"symbol":"BTC/USD","bids":[{"price":67624.6,"qty":0.00000000},{"price":67615.6,"qty":1.47894753}],"asks":[],"checksum":4007353993,"timestamp":"2024-06-01T17:52:15.362164Z"}]}
{"channel":"book","type":"update","data":[{"symbol":"BTC/USD","bids":[],"asks":[{"price":67628.2,"qty":0.00000000},{"price":67641.1,"qty":0.29580000}],"checksum":3177826501,"timestamp":"2024-06-01T17:52:15.389120Z"}]}
{"channel":"book","type":"update","data":[{"symbol":"BTC/USD","bids":[],"asks":[{"price":67636.1,"qty":0.08002518}],"checksum":663458805,"timestamp":"2024-06-01T17:52:15.393372Z"}]}
{"channel":"book","type":"update","data":[{"symbol":"BTC/USD","bids":[{"price":67628.0,"qty":4.65507843}],"asks":[],"checksum":3526196114,"timestamp":"2024-06-01T17:52:15.398332Z"}]}
{"channel":"book","type":"update","data":[{"symbol":"BTC/USD","bids":[],"asks":[{"price":67637.4,"qty":0.00000000},{"price":67641.1,"qty":0.29580000}],"checksum":2768272417,"timestamp":"2024-06-01T17:52:15.398495Z"}]}
{"channel":"book","type":"update","data":[{"symbol":"BTC/USD","bids":[{"price":67628.0,"qty":4.99257843}],"asks":[],"checksum":1353094214,"timestamp":"2024-06-01T17:52:15.402768Z"}]}
{"channel":"book","type":"update","data":[{"symbol":"BTC/USD","bids":[],"asks":[{"price":67638.2,"qty":0.00000000},{"price":67641.7,"qty":0.33750000}],"checksum":1551814212,"timestamp":"2024-06-01T17:52:15.408962Z"}]}
{"channel":"book","type":"update","data":[{"symbol":"BTC/USD","bids":[],"asks":[{"price":67641.7,"qty":0.00000000},{"price":67642.3,"qty":1.50794401}],"checksum":3540670176,"timestamp":"2024-06-01T17:52:15.427007Z"}]}
{"channel":"book","type":"update","data":[{"symbol":"BTC/USD","bids":[],"asks":[{"price":67641.3,"qty":0.05912262}],"checksum":360556764,"timestamp":"2024-06-01T17:52:15.458732Z"}]}
{"channel":"book","type":"update","data":[{"symbol":"BTC/USD","bids":[{"price":67628.0,"qty":4.65507843}],"asks":[],"checksum":3772465339,"timestamp":"2024-06-01T17:52:15.489979Z"}]}
{"channel":"book","type":"update","data":[{"symbol":"BTC/USD","bids":[],"asks":[{"price":67641.0,"qty":0.07936482}],"checksum":3202151416,"timestamp":"2024-06-01T17:52:15.577484Z"}]}
{"channel":"book","type":"update","data":[{"symbol":"BTC/USD","bids":[],"asks":[{"price":67638.2,"qty":0.06910000}],"checksum":222975562,"timestamp":"2024-06-01T17:52:15.601051Z"}]}
{"channel":"book","type":"update","data":[{"symbol":"BTC/USD","bids":[],"asks":[{"price":67641.0,"qty":0.07907000}],"checksum":4046459418,"timestamp":"2024-06-01T17:52:15.626323Z"}]}
{"channel":"book","type":"update","data":[{"symbol":"BTC/USD","bids":[{"price":67615.8,"qty":0.00000000},{"price":67614.6,"qty":0.05912737},{"price":67628.0,"qty":4.65621759}],"asks":[],"checksum":2311025244,"timestamp":"2024-06-01T17:52:15.639955Z"}]}
{"channel":"book","type":"update","data":[{"symbol":"BTC/USD","bids":[],"asks":[{"price":67633.0,"qty":1.47866907}],"checksum":2802621508,"timestamp":"2024-06-01T17:52:15.655553Z"}]}
{"channel":"book","type":"update","data":[{"symbol":"BTC/USD","bids":[{"price":67626.9,"qty":1.47879982}],"asks":[],"checksum":3094693998,"timestamp":"2024-06-01T17:52:15.655653Z"}]}
{"channel":"book","type":"update","data":[{"symbol":"BTC/USD","bids":[],"asks":[{"price":67641.0,"qty":0.00000000},{"price":67641.3,"qty":0.05912262}],"checksum":3335841828,"timestamp":"2024-06-01T17:52:15.669812Z"}]}
{"channel":"book","type":"update","data":[{"symbol":"BTC/USD","bids":[{"price":67628.0,"qty":4.65507843},{"price":67626.8,"qty":0.00113918}],"asks":[],"checksum":1186680115,"timestamp":"2024-06-01T17:52:15.715835Z"}]}
{"channel":"book","type":"update","data":[{"symbol":"BTC/USD","bids":[],"asks":[{"price":67641.3,"qty":0.00000000},{"price":67641.7,"qty":0.33750000}],"checksum":183669171,"timestamp":"2024-06-01T17:52:15.731591Z"}]}
{"channel":"book","type":"update","data":[{"symbol":"BTC/USD","bids":[],"asks":[{"price":67638.2,"qty":0.00000000},{"price":67642.2,"qty":0.00029482},{"price":67636.7,"qty":0.07030000}],"checksum":3602989821,"timestamp":"2024-06-01T17:52:15.740370Z"}]}
{"channel":"book","type":"update","data":[{"symbol":"BTC/USD","bids":[],"asks":[{"price":67641.5,"qty":0.07817000}],"checksum":487115831,"timestamp":"2024-06-01T17:52:15.740622Z"}]}
{"channel":"book","type":"update","data":[{"symbol":"BTC/USD","bids":[],"asks":[{"price":67636.7,"qty":0.13940000}],"checksum":1721277965,"timestamp":"2024-06-01T17:52:15.743875Z"}]}
{"channel":"book","type":"update","data":[{"symbol":"BTC/USD","bids":[],"asks":[{"price":67632.6,"qty":0.00000000},{"price":67642.2,"qty":0.00029482}],"checksum":1813048059,"timestamp":"2024-06-01T17:52:15.898000Z"}]}
{"channel":"book","type":"update","data":[{"symbol":"BTC/USD","bids":[],"asks":[{"price":67632.2,"qty":1.47858628}],"checksum":1086055548,"timestamp":"2024-06-01T17:52:15.902451Z"}]}
{"channel":"book","type":"update","data":[{"symbol":"BTC/USD","bids":[{"price":67628.0,"qty":4.31757843}],"asks":[],"checksum":1541718554,"timestamp":"2024-06-01T17:52:15.969372Z"}]}
{"channel":"book","type":"update","data":[{"symbol":"BTC/USD","bids":[],"asks":[{"price":67632.2,"qty":0.00000000},{"price":67642.2,"qty":0.00029482}],"checksum":2001718429,"timestamp":"2024-06-01T17:52:15.996552Z"}]}
{"channel":"book","type":"update","data":[{"symbol":"BTC/USD","bids":[],"asks":[{"price":67632.0,"qty":1.47859116}],"checksum":2131850872,"timestamp":"2024-06-01T17:52:16.000272Z"}]}
{"channel":"book","type":"update","data":[{"symbol":"BTC/USD","bids":[{"price":67628.0,"qty":4.65507843}],"asks":[],"checksum":1682853918,"timestamp":"2024-06-01T17:52:16.095318Z"}]}
{"channel":"book","type":"update","data":[{"symbol":"BTC/USD","bids":[{"price":67628.0,"qty":4.31757843}],"asks":[],"checksum":2131850872,"timestamp":"2024-06-01T17:52:16.099607Z"}]}
{"channel":"book","type":"update","data":[{"symbol":"BTC/USD","bids":[],"asks":[{"price":67636.7,"qty":0.07030000}],"checksum":3171611538,"timestamp":"2024-06-01T17:52:16.193032Z"}]}
{"channel":"book","type":"update","data":[{"symbol":"BTC/USD","bids":[{"price":67626.9,"qty":0.00010000}],"asks":[],"checksum":1841548943,"timestamp":"2024-06-01T17:52:16.223978Z"}]}
{"channel":"book","type":"update","data":[{"symbol":"BTC/USD","bids":[],"asks":[{"price":67632.0,"qty":0.00000000},{"price":67642.0,"qty":0.05912217}],"checksum":132839702,"timestamp":"2024-06-01T17:52:16.224037Z"}]}
{"channel":"book","type":"update","data":[{"symbol":"BTC/USD","bids":[],"asks":[{"price":67631.8,"qty":1.58950947}],"checksum":3875900303,"timestamp":"2024-06-01T17:52:16.227856Z"}]}
{"channel":"book","type":"update","data":[{"symbol":"BTC/USD","bids":[{"price":67626.3,"qty":1.47871397}],"asks":[],"checksum":2626568315,"timestamp":"2024-06-01T17:52:16.227922Z"}]}
{"channel":"book","type":"update","data":[{"symbol":"BTC/USD","bids":[{"price":67628.0,"qty":4.65507843}],"asks":[],"checksum":260589861,"timestamp":"2024-06-01T17:52:16.390145Z"}]}
{"channel":"book","type":"update","data":[{"symbol":"BTC/USD","bids":[{"price":67628.0,"qty":4.31757843}],"asks":[],"checksum":2626568315,"timestamp":"2024-06-01T17:52:16.411225Z"}]}
{"channel":"book","type":"update","data":[{"symbol":"BTC/USD","bids":[{"price":67628.0,"qty":4.65507843}],"asks":[],"checksum":260589861,"timestamp":"2024-06-01T17:52:16.416322Z"}]}
{"channel":"book","type":"update","data":[{"symbol":"BTC/USD","bids":[{"price":67628.0,"qty":4.31757843}],"asks":[],"checksum":2626568315,"timestamp":"2024-06-01T17:52:16.517039Z"}]}
{"channel":"book","type":"update","data":[{"symbol":"BTC/USD","bids":[],"asks":[{"price":67636.7,"qty":0.00120000}],"checksum":3333149293,"timestamp":"2024-06-01T17:52:16.547651Z"}]}
{"channel":"book","type":"update","data":[{"symbol":"BTC/USD","bids":[],"asks":[{"price":67637.5,"qty":0.06910000}],"checksum":155676306,"timestamp":"2024-06-01T17:52:16.622125Z"}]}
{"channel":"book","type":"update","data":[{"symbol":"BTC/USD","bids":[{"price":67628.0,"qty":4.65507843}],"asks":[],"checksum":2587977676,"timestamp":"2024-06-01T17:52:16.714788Z"}]}
{"channel":"book","type":"update","data":[{"symbol":"BTC/USD","bids":[],"asks":[{"price":67641.0,"qty":0.00029482}],"checksum":3058956771,"timestamp":"2024-06-01T17:52:16.728556Z"}]}
{"channel":"book","type":"update","data":[{"symbol":"BTC/USD","bids":[{"price":67626.8,"qty":0.00000000},{"price":67615.6,"qty":1.47894753},{"price":67626.4,"qty":0.00113938}],"asks":[],"checksum":2271019798,"timestamp":"2024-06-01T17:52:16.728589Z"}]}
{"channel":"book","type":"update","data":[{"symbol":"BTC/USD","bids":[],"asks":[{"price":67631.8,"qty":0.11091373}],"checksum":2476777802,"timestamp":"2024-06-01T17:52:16.870201Z"}]}
{"channel":"book","type":"update","data":[{"symbol":"BTC/USD","bids":[],"asks":[{"price":67632.1,"qty":1.47858859}],"checksum":3140364783,"timestamp":"2024-06-01T17:52:16.873967Z"}]}
{"channel":"book","type":"update","data":[{"symbol":"BTC/USD","bids":[{"price":67628.0,"qty":4.31757843}],"asks":[],"checksum":673718449,"timestamp":"2024-06-01T17:52:16.977095Z"}]}
{"channel":"book","type":"update","data":[{"symbol":"BTC/USD","bids":[],"asks":[{"price":67632.1,"qty":0.00000000},{"price":67641.5,"qty":0.07817000}],"checksum":10922004,"timestamp":"2024-06-01T17:52:16.982179Z"}]}
{"channel":"book","type":"update","data":[{"symbol":"BTC/USD","bids":[{"price":67628.0,"qty":4.65507843}],"asks":[],"checksum":2476777802,"timestamp":"2024-06-01T17:52:16.986099Z"}]}
{"channel":"book","type":"update","data":[{"symbol":"BTC/USD","bids":[],"asks":[{"price":67631.8,"qty":1.58950824}],"checksum":249364094,"timestamp":"2024-06-01T17:52:16.986295Z"}]}
{"channel":"book","type":"update","data":[{"symbol":"BTC/USD","bids":[{"price":67628.0,"qty":4.31757843}],"asks":[],"checksum":2648373024,"timestamp":"2024-06-01T17:52:16.990140Z"}]}
{"channel":"book","type":"update","data":[{"symbol":"BTC/USD","bids":[],"asks":[{"price":67635.8,"qty":0.03947498}],"checksum":1085058816,"timestamp":"2024-06-01T17:52:17.094336Z"}]}
{"channel":"book","type":"update","data":[{"symbol":"BTC/USD","bids":[{"price":67628.0,"qty":4.65507843}],"asks":[],"checksum":3551176286,"timestamp":"2024-06-01T17:52:17.098943Z"}]}
{"channel":"book","type":"update","data":[{"symbol":"BTC/USD","bids":[{"price":67628.0,"qty":4.31757843}],"asks":[],"checksum":1085058816,"timestamp":"2024-06-01T17:52:17.290392Z"}]}
{"channel":"book","type":"update","data":[{"symbol":"BTC/USD","bids":[{"price":67628.0,"qty":4.65507843}],"asks":[],"checksum":3551176286,"timestamp":"2024-06-01T17:52:17.396102Z"}]}
{"channel":"book","type":"update","data":[{"symbol":"BTC/USD","bids":[{"price":67628.0,"qty":4.31757843}],"asks":[],"checksum":1085058816,"timestamp":"2024-06-01T17:52:17.463988Z"}]}
{"channel":"book","type":"update","data":[{"symbol":"BTC/USD","bids":[{"price":67628.0,"qty":4.65507843}],"asks":[],"checksum":3551176286,"timestamp":"2024-06-01T17:52:17.499700Z"}]}
{"channel":"book","type":"update","data":[{"symbol":"BTC/USD","bids":[],"asks":[{"price":67628.1,"qty":0.38660697}],"checksum":2074057327,"timestamp":"2024-06-01T17:52:17.501537Z"}]}
{"channel":"book","type":"update","data":[{"symbol":"BTC/USD","bids":[{"price":67628.0,"qty":4.65463483}],"asks":[],"checksum":441218538,"timestamp":"2024-06-01T17:52:17.581644Z"}]}
{"channel":"book","type":"update","data":[{"symbol":"BTC/USD","bids":[{"price":67615.8,"qty":1.20000000}],"asks":[],"checksum":1965265601,"timestamp":"2024-06-01T17:52:17.592096Z"}]}
{"channel":"book","type":"update","data":[{"symbol":"BTC/USD","bids":[],"asks":[{"price":67637.5,"qty":0.00000000},{"price":67641.7,"qty":0.33750000}],"checksum":698649243,"timestamp":"2024-06-01T17:52:17.679563Z"}]}
{"channel":"book","type":"update","data":[{"symbol":"BTC/USD","bids":[],"asks":[{"price":67636.8,"qty":0.06910000}],"checksum":1609291640,"timestamp":"2024-06-01T17:52:17.828206Z"}]}
{"channel":"book","type":"update","data":[{"symbol":"BTC/USD","bids":[{"price":67626.4,"qty":0.00000000},{"price":67615.7,"qty":0.91978875},{"price":67622.5,"qty":0.00113944}],"asks":[],"checksum":1152186407,"timestamp":"2024-06-01T17:52:17.839994Z"}]}
{"channel":"book","type":"update","data":[{"symbol":"BTC/USD","bids":[],"asks":[{"price":67641.0,"qty":0.00000000},{"price":67641.7,"qty":0.33750000},{"price":67641.6,"qty":0.00029485}],"checksum":2031076231,"timestamp":"2024-06-01T17:52:17.840015Z"}]}
{"channel":"book","type":"update","data":[{"symbol":"BTC/USD","bids":[],"asks":[{"price":67631.8,"qty":0.11091373}],"checksum":2707767898,"timestamp":"2024-06-01T17:52:17.932437Z"}]}
{"channel":"book","type":"update","data":[{"symbol":"BTC/USD","bids":[{"price":67626.7,"qty":0.00000000},{"price":67615.7,"qty":0.91978875}],"asks":[],"checksum":3668890134,"timestamp":"2024-06-01T17:52:17.932479Z"}]}
{"channel":"book","type":"update","data":[{"symbol":"BTC/USD","bids":[{"price":67626.0,"qty":1.47871992}],"asks":[],"checksum":2283316115,"timestamp":"2024-06-01T17:52:17.936159Z"}]}
{"channel":"book","type":"update","data":[{"symbol":"BTC/USD","bids":[],"asks":[{"price":67631.5,"qty":1.47860116}],"checksum":3830579984,"timestamp":"2024-06-01T17:52:17.936200Z"}]}
{"channel":"book","type":"update","data":[{"symbol":"BTC/USD","bids":[{"price":67628.0,"qty":4.31713483}],"asks":[],"checksum":2953710959,"timestamp":"2024-06-01T17:52:17.947156Z"}]}
{"channel":"book","type":"update","data":[{"symbol":"BTC/USD","bids":[{"price":67628.0,"qty":4.24803483}],"asks":[],"checksum":1213954059,"timestamp":"2024-06-01T17:52:18.250161Z"}]}
{"channel":"book","type":"update","data":[{"symbol":"BTC/USD","bids":[{"price":67628.0,"qty":4.31713483}],"asks":[],"checksum":2953710959,"timestamp":"2024-06-01T17:52:18.367496Z"}]}
{"channel":"book","type":"update","data":[{"symbol":"BTC/USD","bids":[{"price":67628.0,"qty":4.24803483}],"asks":[],"checksum":1213954059,"timestamp":"2024-06-01T17:52:18.435468Z"}]}
{"channel":"book","type":"update","data":[{"symbol":"BTC/USD","bids":[],"asks":[{"price":67631.5,"qty":0.00000000},{"price":67641.6,"qty":0.00029485}],"checksum":605149320,"timestamp":"2024-06-01T17:52:18.483082Z"}]}
{"channel":"book","type":"update","data":[{"symbol":"BTC/USD","bids":[],"asks":[{"price":67631.9,"qty":1.47859435}],"checksum":2438488742,"timestamp":"2024-06-01T17:52:18.489574Z"}]}
{"channel":"book","type":"update","data":[{"symbol":"BTC/USD","bids":[{"price":67626.3,"qty":0.00000000},{"price":67615.7,"qty":0.91978875}],"asks":[],"checksum":3904927668,"timestamp":"2024-06-01T17:52:18.552930Z"}]}
{"channel":"book","type":"update","data":[{"symbol":"BTC/USD","bids":[{"price":67626.6,"qty":1.47870615}],"asks":[],"checksum":4050243864,"timestamp":"2024-06-01T17:52:18.557240Z"}]}
{"channel":"book","type":"update","data":[{"symbol":"BTC/USD","bids":[{"price":67628.0,"qty":4.31713483}],"asks":[],"checksum":154969212,"timestamp":"2024-06-01T17:52:18.621389Z"}]}
{"channel":"book","type":"update","data":[{"symbol":"BTC/USD","bids":[{"price":67626.6,"qty":0.00000000},{"price":67615.7,"qty":0.91978875}],"asks":[],"checksum":3743119977,"timestamp":"2024-06-01T17:52:18.665810Z"}]}
{"channel":"book","type":"update","data":[{"symbol":"BTC/USD","bids":[{"price":67626.3,"qty":1.47871422}],"asks":[],"checksum":3795031305,"timestamp":"2024-06-01T17:52:18.669726Z"}]}
{"channel":"book","type":"update","data":[{"symbol":"BTC/USD","bids":[{"price":67622.5,"qty":0.00000000},{"price":67615.7,"qty":0.91978875},{"price":67626.4,"qty":0.00113906}],"asks":[],"checksum":3248057508,"timestamp":"2024-06-01T17:52:18.955988Z"}]}
{"channel":"book","type":"update","data":[{"symbol":"BTC/USD","bids":[{"price":67626.4,"qty":0.00000000},{"price":67615.7,"qty":0.91978875},{"price":67622.5,"qty":0.00113913}],"asks":[],"checksum":4072181845,"timestamp":"2024-06-01T17:52:19.024184Z"}]}
{"channel":"book","type":"update","data":[{"symbol":"BTC/USD","bids":[{"price":67626.3,"qty":0.00000000},{"price":67615.7,"qty":0.91978875}],"asks":[],"checksum":1885969647,"timestamp":"2024-06-01T17:52:19.382606Z"}]}
{"channel":"book","type":"update","data":[{"symbol":"BTC/USD","bids":[],"asks":[{"price":67631.9,"qty":0.00000000},{"price":67641.6,"qty":0.00029485}],"checksum":3910959954,"timestamp":"2024-06-01T17:52:19.382805Z"}]}
{"channel":"book","type":"update","data":[{"symbol":"BTC/USD","bids":[{"price":67628.0,"qty":4.65463483}],"asks":[],"checksum":1799738788,"timestamp":"2024-06-01T17:52:19.383203Z"}]}
{"channel":"book","type":"update","data":[{"symbol":"BTC/USD","bids":[],"asks":[{"price":67634.3,"qty":1.47854011}],"checksum":717807387,"timestamp":"2024-06-01T17:52:19.387923Z"}]}
{"channel":"book","type":"update","data":[{"symbol":"BTC/USD","bids":[{"price":67627.3,"qty":1.47869149}],"asks":[],"checksum":1634853932,"timestamp":"2024-06-01T17:52:19.388093Z"}]}
{"channel":"book","type":"update","data":[{"symbol":"BTC/USD","bids":[{"price":67627.3,"qty":0.00000000},{"price":67615.7,"qty":0.91978875}],"asks":[],"checksum":717807387,"timestamp":"2024-06-01T17:52:19.392026Z"}]}
{"channel":"book","type":"update","data":[{"symbol":"BTC/USD","bids":[],"asks":[{"price":67633.0,"qty":0.00010000}],"checksum":3090167414,"timestamp":"2024-06-01T17:52:19.429684Z"}]}
{"channel":"book","type":"update","data":[{"symbol":"BTC/USD","bids":[],"asks":[{"price":67632.8,"qty":1.47857392}],"checksum":2623943769,"timestamp":"2024-06-01T17:52:19.433584Z"}]}
{"channel":"book","type":"update","data":[{"symbol":"BTC/USD","bids":[{"price":67627.1,"qty":1.47869504}],"asks":[],"checksum":3789225336,"timestamp":"2024-06-01T17:52:19.437391Z"}]}
{"channel":"book","type":"update","data":[{"symbol":"BTC/USD","bids":[{"price":67622.4,"qty":0.00000000},{"price":67615.7,"qty":0.91978875}],"asks":[],"checksum":3352969411,"timestamp":"2024-06-01T17:52:19.570606Z"}]}
{"channel":"book","type":"update","data":[{"symbol":"BTC/USD","bids":[{"price":67622.5,"qty":0.36767882}],"asks":[],"checksum":2330209718,"timestamp":"2024-06-01T17:52:19.573716Z"}]}
{"channel":"book","type":"update","data":[{"symbol":"BTC/USD","bids":[{"price":67615.7,"qty":0.00000000},{"price":67615.6,"qty":1.47894753}],"asks":[],"checksum":2239751373,"timestamp":"2024-06-01T17:52:19.578289Z"}]}
{"channel":"book","type":"update","data":[{"symbol":"BTC/USD","bids":[{"price":67622.5,"qty":1.28745807}],"asks":[],"checksum":1453601266,"timestamp":"2024-06-01T17:52:19.578319Z"}]}
{"channel":"book","type":"update","data":[{"symbol":"BTC/USD","bids":[],"asks":[{"price":67636.8,"qty":0.00000000},{"price":67641.1,"qty":0.29580000},{"price":67637.7,"qty":0.06910000}],"checksum":1502848874,"timestamp":"2024-06-01T17:52:19.601938Z"}]}
{"channel":"book","type":"update","data":[{"symbol":"BTC/USD","bids":[],"asks":[{"price":67637.7,"qty":0.13820000}],"checksum":1094257987,"timestamp":"2024-06-01T17:52:19.605552Z"}]}
{"channel":"book","type":"update","data":[{"symbol":"BTC/USD","bids":[],"asks":[{"price":67632.8,"qty":0.00000000},{"price":67641.1,"qty":0.29580000}],"checksum":3451758945,"timestamp":"2024-06-01T17:52:19.763741Z"}]}
{"channel":"book","type":"update","data":[{"symbol":"BTC/USD","bids":[],"asks":[{"price":67632.5,"qty":1.47858078}],"checksum":1865772208,"timestamp":"2024-06-01T17:52:19.767991Z"}]}
{"channel":"book","type":"update","data":[{"symbol":"BTC/USD","bids":[{"price":67628.0,"qty":4.31713483}],"asks":[],"checksum":754939589,"timestamp":"2024-06-01T17:52:19.904993Z"}]}
{"channel":"book","type":"update","data":[{"symbol":"BTC/USD","bids":[{"price":67622.5,"qty":1.28631894},{"price":67626.1,"qty":0.00113907}],"asks":[],"checksum":301386172,"timestamp":"2024-06-01T17:52:20.013531Z"}]}
{"channel":"book","type":"update","data":[{"symbol":"BTC/USD","bids":[{"price":67627.1,"qty":0.00000000},{"price":67615.6,"qty":1.47894753}],"asks":[],"checksum":637577153,"timestamp":"2024-06-01T17:52:20.127052Z"}]}
{"channel":"book","type":"update","data":[{"symbol":"BTC/USD","bids":[],"asks":[{"price":67632.5,"qty":0.00000000},{"price":67641.1,"qty":0.29580000}],"checksum":4277548831,"timestamp":"2024-06-01T17:52:20.127236Z"}]}
{"channel":"book","type":"update","data":[{"symbol":"BTC/USD","bids":[],"asks":[{"price":67632.2,"qty":1.47858581}],"checksum":1722751071,"timestamp":"2024-06-01T17:52:20.132276Z"}]}
{"channel":"book","type":"update","data":[{"symbol":"BTC/USD","bids":[{"price":67626.6,"qty":1.47870690}],"asks":[],"checksum":3532406385,"timestamp":"2024-06-01T17:52:20.132294Z"}]}
{"channel":"book","type":"update","data":[{"symbol":"BTC/USD","bids":[{"price":67628.0,"qty":4.65463483}],"asks":[],"checksum":308416210,"timestamp":"2024-06-01T17:52:20.172757Z"}]}
{"channel":"book","type":"update","data":[{"symbol":"BTC/USD","bids":[],"asks":[{"price":67637.7,"qty":0.06910000}],"checksum":374590888,"timestamp":"2024-06-01T17:52:20.176742Z"}]}
{"channel":"book","type":"update","data":[{"symbol":"BTC/USD","bids":[{"price":67628.0,"qty":4.31713483}],"asks":[],"checksum":3602775307,"timestamp":"2024-06-01T17:52:20.176810Z"}]}
{"channel":"book","type":"update","data":[{"symbol":"BTC/USD","bids":[{"price":67626.6,"qty":0.00000000},{"price":67615.6,"qty":1.47894753}],"asks":[],"checksum":1654577957,"timestamp":"2024-06-01T17:52:20.178281Z"}]}
{"channel":"book","type":"update","data":[{"symbol":"BTC/USD","bids":[],"asks":[{"price":67632.2,"qty":0.00000000},{"price":67641.1,"qty":0.29580000}],"checksum":3953103098,"timestamp":"2024-06-01T17:52:20.178403Z"}]}
{"channel":"book","type":"update","data":[{"symbol":"BTC/USD","bids":[{"price":67628.0,"qty":4.65463483}],"asks":[],"checksum":728866905,"timestamp":"2024-06-01T17:52:20.181103Z"}]}
{"channel":"book","type":"update","data":[{"symbol":"BTC/USD","bids":[{"price":67627.6,"qty":1.47868434}],"asks":[],"checksum":895809806,"timestamp":"2024-06-01T17:52:20.182770Z"}]}
{"channel":"book","type":"update","data":[{"symbol":"BTC/USD","bids":[],"asks":[{"price":67633.2,"qty":1.47856461}],"checksum":1500684879,"timestamp":"2024-06-01T17:52:20.182854Z"}]}
{"channel":"book","type":"update","data":[{"symbol":"BTC/USD","bids":[{"price":67627.6,"qty":0.00000000},{"price":67615.6,"qty":1.47894753}],"asks":[],"checksum":1197996824,"timestamp":"2024-06-01T17:52:20.196630Z"}]}
{"channel":"book","type":"update","data":[{"symbol":"BTC/USD","bids":[{"price":67626.1,"qty":0.00000000},{"price":67614.6,"qty":0.05912737},{"price":67622.6,"qty":0.00113939}],"asks":[],"checksum":3007838035,"timestamp":"2024-06-01T17:52:20.198529Z"}]}
{"channel":"book","type":"update","data":[{"symbol":"BTC/USD","bids":[],"asks":[{"price":67636.2,"qty":0.00000000},{"price":67641.1,"qty":0.29580000}],"checksum":4111835364,"timestamp":"2024-06-01T17:52:20.215008Z"}]}
{"channel":"book","type":"update","data":[{"symbol":"BTC/USD","bids":[],"asks":[{"price":67633.2,"qty":0.00000000},{"price":67641.6,"qty":0.00029485}],"checksum":3715923419,"timestamp":"2024-06-01T17:52:20.215115Z"}]}
{"channel":"book","type":"update","data":[{"symbol":"BTC/USD","bids":[],"asks":[{"price":67641.1,"qty":0.00000000},{"price":67641.7,"qty":0.33750000},{"price":67641.6,"qty":0.29609485}],"checksum":3856236012,"timestamp":"2024-06-01T17:52:20.218310Z"}]}
{"channel":"book","type":"update","data":[{"symbol":"BTC/USD","bids":[],"asks":[{"price":67638.4,"qty":1.47845079}],"checksum":74281668,"timestamp":"2024-06-01T17:52:20.218826Z"}]}
{"channel":"book","type":"update","data":[{"symbol":"BTC/USD","bids":[{"price":67618.4,"qty":0.00460867}],"asks":[],"checksum":1331600908,"timestamp":"2024-06-01T17:52:20.228173Z"}]}
{"channel":"book","type":"update","data":[{"symbol":"BTC/USD","bids":[{"price":67618.4,"qty":0.00000000},{"price":67615.6,"qty":1.47894753}],"asks":[],"checksum":74281668,"timestamp":"2024-06-01T17:52:20.327450Z"}]}
{"channel":"book","type":"update","data":[{"symbol":"BTC/USD","bids":[],"asks":[{"price":67628.1,"qty":0.38650697}],"checksum":339054924,"timestamp":"2024-06-01T17:52:20.448568Z"}]}
{"channel":"book","type":"update","data":[{"symbol":"BTC/USD","bids":[],"asks":[{"price":67637.7,"qty":0.00000000},{"price":67641.7,"qty":0.33750000}],"checksum":446233566,"timestamp":"2024-06-01T17:52:20.658244Z"}]}
{"channel":"book","type":"update","data":[{"symbol":"BTC/USD","bids":[{"price":67615.6,"qty":0.00000000},{"price":67615.3,"qty":0.00460867}],"asks":[],"checksum":1319039604,"timestamp":"2024-06-01T17:52:20.661950Z"}]}
{"channel":"book","type":"update","data":[{"symbol":"BTC/USD","bids":[],"asks":[{"price":67634.0,"qty":1.47854634}],"checksum":3910281158,"timestamp":"2024-06-01T17:52:20.666160Z"}]}
{"channel":"book","type":"update","data":[{"symbol":"BTC/USD","bids":[{"price":67618.7,"qty":1.47887910}],"asks":[],"checksum":692606252,"timestamp":"2024-06-01T17:52:20.666269Z"}]}
{"channel":"book","type":"update","data":[{"symbol":"BTC/USD","bids":[{"price":67627.9,"qty":1.47867885}],"asks":[],"checksum":534190399,"timestamp":"2024-06-01T17:52:20.666309Z"}]}
{"channel":"book","type":"update","data":[{"symbol":"BTC/USD","bids":[],"asks":[{"price":67634.0,"qty":0.00000000},{"price":67641.7,"qty":0.33750000}],"checksum":3243036087,"timestamp":"2024-06-01T17:52:20.777539Z"}]}
{"channel":"book","type":"update","data":[{"symbol":"BTC/USD","bids":[],"asks":[{"price":67633.7,"qty":1.47855344}],"checksum":4036083120,"timestamp":"2024-06-01T17:52:20.781277Z"}]}
{"channel":"book","type":"update","data":[{"symbol":"BTC/USD","bids":[],"asks":[{"price":67637.3,"qty":0.06910000}],"checksum":765574532,"timestamp":"2024-06-01T17:52:20.829479Z"}]}
{"channel":"book","type":"update","data":[{"symbol":"BTC/USD","bids":[],"asks":[{"price":67633.7,"qty":0.00000000},{"price":67641.6,"qty":0.29609485}],"checksum":2097045520,"timestamp":"2024-06-01T17:52:20.872796Z"}]}
{"channel":"book","type":"update","data":[{"symbol":"BTC/USD","bids":[],"asks":[{"price":67633.5,"qty":1.47855891}],"checksum":638064397,"timestamp":"2024-06-01T17:52:20.875987Z"}]}
{"channel":"book","type":"update","data":[{"symbol":"BTC/USD","bids":[{"price":67622.6,"qty":0.00000000},{"price":67615.8,"qty":1.20000000},{"price":67626.1,"qty":0.00113933}],"asks":[],"checksum":1514179077,"timestamp":"2024-06-01T17:52:21.063842Z"}]}
{"channel":"book","type":"update","data":[{"symbol":"BTC/USD","bids":[],"asks":[{"price":67633.5,"qty":0.00000000},{"price":67641.5,"qty":0.00029486}],"checksum":3493704756,"timestamp":"2024-06-01T17:52:21.148750Z"}]}
{"channel":"book","type":"update","data":[{"symbol":"BTC/USD","bids":[],"asks":[{"price":67633.3,"qty":1.47856335}],"checksum":857250222,"timestamp":"2024-06-01T17:52:21.152327Z"}]}
{"channel":"book","type":"update","data":[{"symbol":"BTC/USD","bids":[{"price":67627.9,"qty":0.00000000},{"price":67615.8,"qty":1.20000000}],"asks":[],"checksum":582199636,"timestamp":"2024-06-01T17:52:21.196502Z"}]}
{"channel":"book","type":"update","data":[{"symbol":"BTC/USD","bids":[],"asks":[{"price":67633.3,"qty":0.00000000},{"price":67641.5,"qty":0.00029486}],"checksum":3247867086,"timestamp":"2024-06-01T17:52:21.196512Z"}]}
{"channel":"book","type":"update","data":[{"symbol":"BTC/USD","bids":[{"price":67627.5,"qty":1.47868688}],"asks":[],"checksum":136598716,"timestamp":"2024-06-01T17:52:21.200604Z"}]}
{"channel":"book","type":"update","data":[{"symbol":"BTC/USD","bids":[],"asks":[{"price":67633.1,"qty":1.47856793}],"checksum":1611150148,"timestamp":"2024-06-01T17:52:21.204342Z"}]}
{"channel":"book","type":"update","data":[{"symbol":"BTC/USD","bids":[],"asks":[{"price":67633.1,"qty":0.00000000},{"price":67641.5,"qty":0.00029486}],"checksum":136598716,"timestamp":"2024-06-01T17:52:21.266064Z"}]}
{"channel":"book","type":"update","data":[{"symbol":"BTC/USD","bids":[],"asks":[{"price":67632.8,"qty":1.47857414}],"checksum":4130297633,"timestamp":"2024-06-01T17:52:21.270107Z"}]}
{"channel":"book","type":"update","data":[{"symbol":"BTC/USD","bids":[],"asks":[{"price":67637.3,"qty":0.00000000},{"price":67641.5,"qty":0.00029486}],"checksum":1167666298,"timestamp":"2024-06-01T17:52:21.776571Z"}]}
{"channel":"book","type":"update","data":[{"symbol":"BTC/USD","bids":[{"price":67628.0,"qty":4.99213483}],"asks":[],"checksum":1560159533,"timestamp":"2024-06-01T17:52:21.877034Z"}]}
{"channel":"book","type":"update","data":[{"symbol":"BTC/USD","bids":[{"price":67627.5,"qty":0.00000000},{"price":67615.8,"qty":1.20000000}],"asks":[],"checksum":2504848735,"timestamp":"2024-06-01T17:52:21.893545Z"}]}
{"channel":"book","type":"update","data":[{"symbol":"BTC/USD","bids":[],"asks":[{"price":67632.8,"qty":0.00000000},{"price":67641.6,"qty":0.29580000}],"checksum":2629802428,"timestamp":"2024-06-01T17:52:21.893668Z"}]}
{"channel":"book","type":"update","data":[{"symbol":"BTC/USD","bids":[],"asks":[{"price":67633.5,"qty":1.47855735}],"checksum":1153868022,"timestamp":"2024-06-01T17:52:21.899479Z"}]}
{"channel":"book","type":"update","data":[{"symbol":"BTC/USD","bids":[{"price":67627.9,"qty":1.47867795}],"asks":[],"checksum":42686374,"timestamp":"2024-06-01T17:52:21.899498Z"}]}
{"channel":"book","type":"update","data":[{"symbol":"BTC/USD","bids":[],"asks":[{"price":67640.4,"qty":0.06910000}],"checksum":133016318,"timestamp":"2024-06-01T17:52:21.913008Z"}]}
{"channel":"book","type":"update","data":[{"symbol":"BTC/USD","bids":[],"asks":[{"price":67638.8,"qty":0.06910000}],"checksum":2827241721,"timestamp":"2024-06-01T17:52:21.926847Z"}]}
{"channel":"book","type":"update","data":[{"symbol":"BTC/USD","bids":[],"asks":[{"price":67638.4,"qty":1.54755079}],"checksum":3209626312,"timestamp":"2024-06-01T17:52:21.994174Z"}]}
{"channel":"book","type":"update","data":[{"symbol":"BTC/USD","bids":[],"asks":[{"price":67638.4,"qty":1.47845079}],"checksum":2827241721,"timestamp":"2024-06-01T17:52:22.014313Z"}]}
{"channel":"book","type":"update","data":[{"symbol":"BTC/USD","bids":[],"asks":[{"price":67638.8,"qty":0.00000000},{"price":67639.9,"qty":0.06910000}],"checksum":257242021,"timestamp":"2024-06-01T17:52:22.021434Z"}]}
{"channel":"book","type":"update","data":[{"symbol":"BTC/USD","bids":[],"asks":[{"price":67633.5,"qty":0.00000000},{"price":67641.6,"qty":0.29580000}],"checksum":3925280701,"timestamp":"2024-06-01T17:52:22.027392Z"}]}
{"channel":"book","type":"update","data":[{"symbol":"BTC/USD","bids":[],"asks":[{"price":67634.3,"qty":0.00000000},{"price":67642.2,"qty":0.00029486}],"checksum":1257396000,"timestamp":"2024-06-01T17:52:22.034177Z"}]}
{"channel":"book","type":"update","data":[{"symbol":"BTC/USD","bids":[{"price":67622.3,"qty":0.00100000}],"asks":[],"checksum":3766573178,"timestamp":"2024-06-01T17:52:22.034187Z"}]}
{"channel":"book","type":"update","data":[{"symbol":"BTC/USD","bids":[],"asks":[{"price":67641.6,"qty":0.00000000},{"price":67642.3,"qty":1.57235401},{"price":67642.2,"qty":0.29609486}],"checksum":514441485,"timestamp":"2024-06-01T17:52:22.039889Z"}]}
{"channel":"book","type":"update","data":[{"symbol":"BTC/USD","bids":[],"asks":[{"price":67634.5,"qty":1.47853714}],"checksum":1668732907,"timestamp":"2024-06-01T17:52:22.040295Z"}]}
{"channel":"book","type":"update","data":[{"symbol":"BTC/USD","bids":[{"price":67627.9,"qty":2.95735643}],"asks":[],"checksum":3088435392,"timestamp":"2024-06-01T17:52:22.040386Z"}]}
{"channel":"book","type":"update","data":[{"symbol":"BTC/USD","bids":[],"asks":[{"price":67635.8,"qty":1.51798334}],"checksum":2317259469,"timestamp":"2024-06-01T17:52:22.040416Z"}]}
{"channel":"book","type":"update","data":[{"symbol":"BTC/USD","bids":[],"asks":[{"price":67634.5,"qty":0.00000000},{"price":67642.3,"qty":1.57235401}],"checksum":3080876862,"timestamp":"2024-06-01T17:52:22.047966Z"}]}
{"channel":"book","type":"update","data":[{"symbol":"BTC/USD","bids":[],"asks":[{"price":67642.2,"qty":0.29580000}],"checksum":35142344,"timestamp":"2024-06-01T17:52:22.097563Z"}]}
{"channel":"book","type":"update","data":[{"symbol":"BTC/USD","bids":[{"price":67626.1,"qty":0.00000000},{"price":67615.8,"qty":1.20000000},{"price":67628.0,"qty":4.99327412}],"asks":[],"checksum":1747989596,"timestamp":"2024-06-01T17:52:22.151186Z"}]}
{"channel":"book","type":"update","data":[{"symbol":"BTC/USD","bids":[{"price":67626.0,"qty":0.00000000},{"price":67615.3,"qty":0.00460867}],"asks":[],"checksum":3121198876,"timestamp":"2024-06-01T17:52:22.192170Z"}]}
{"channel":"book","type":"update","data":[{"symbol":"BTC/USD","bids":[{"price":67623.7,"qty":1.47877124}],"asks":[],"checksum":974571941,"timestamp":"2024-06-01T17:52:22.196058Z"}]}
{"channel":"book","type":"update","data":[{"symbol":"BTC/USD","bids":[],"asks":[{"price":67633.9,"qty":1.47855010}],"checksum":435216808,"timestamp":"2024-06-01T17:52:22.196191Z"}]}
{"channel":"book","type":"update","data":[{"symbol":"BTC/USD","bids":[],"asks":[{"price":67639.9,"qty":0.00000000},{"price":67642.3,"qty":1.50794401}],"checksum":2029366905,"timestamp":"2024-06-01T17:52:22.707344Z"}]}
{"channel":"book","type":"update","data":[{"symbol":"BTC/USD","bids":[],"asks":[{"price":67639.8,"qty":0.06910000}],"checksum":3105445867,"timestamp":"2024-06-01T17:52:22.825710Z"}]}
{"channel":"book","type":"update","data":[{"symbol":"BTC/USD","bids":[],"asks":[{"price":67633.9,"qty":0.00000000},{"price":67642.3,"qty":1.50794401}],"checksum":3162074780,"timestamp":"2024-06-01T17:52:23.042473Z"}]}
{"channel":"book","type":"update","data":[{"symbol":"BTC/USD","bids":[],"asks":[{"price":67633.6,"qty":1.47855515}],"checksum":126308423,"timestamp":"2024-06-01T17:52:23.047714Z"}]}
{"channel":"book","type":"update","data":[{"symbol":"BTC/USD","bids":[{"price":67628.0,"qty":4.99213483},{"price":67623.8,"qty":0.00113938}],"asks":[],"checksum":3153518839,"timestamp":"2024-06-01T17:52:23.206154Z"}]}
{"channel":"book","type":"update","data":[{"symbol":"BTC/USD","bids":[],"asks":[{"price":67639.8,"qty":0.00000000},{"price":67642.3,"qty":1.50794401}],"checksum":3908565225,"timestamp":"2024-06-01T17:52:23.241633Z"}]}
{"channel":"book","type":"update","data":[{"symbol":"BTC/USD","bids":[],"asks":[{"price":67642.1,"qty":0.00029486}],"checksum":481604391,"timestamp":"2024-06-01T17:52:23.253573Z"}]}
{"channel":"book","type":"update","data":[{"symbol":"BTC/USD","bids":[],"asks":[{"price":67633.6,"qty":0.00000000},{"price":67642.3,"qty":1.50794401}],"checksum":3793496802,"timestamp":"2024-06-01T17:52:23.276076Z"}]}
{"channel":"book","type":"update","data":[{"symbol":"BTC/USD","bids":[],"asks":[{"price":67634.8,"qty":1.47852899}],"checksum":3527545391,"timestamp":"2024-06-01T17:52:23.279739Z"}]}
{"channel":"book","type":"update","data":[{"symbol":"BTC/USD","bids":[],"asks":[{"price":67642.1,"qty":0.00000000},{"price":67642.3,"qty":1.50794401}],"checksum":3418574557,"timestamp":"2024-06-01T17:52:23.298395Z"}]}
{"channel":"book","type":"update","data":[{"symbol":"BTC/USD","bids":[],"asks":[{"price":67640.4,"qty":0.06910000}],"checksum":2085605359,"timestamp":"2024-06-01T17:52:23.421215Z"}]}
{"channel":"book","type":"update","data":[{"symbol":"BTC/USD","bids":[],"asks":[{"price":67634.8,"qty":0.00000000},{"price":67642.3,"qty":1.50794401}],"checksum":255766766,"timestamp":"2024-06-01T17:52:23.437510Z"}]}
{"channel":"book","type":"update","data":[{"symbol":"BTC/USD","bids":[],"asks":[{"price":67635.1,"qty":1.47852229}],"checksum":1744006053,"timestamp":"2024-06-01T17:52:23.441210Z"}]}
{"channel":"book","type":"update","data":[{"symbol":"BTC/USD","bids":[],"asks":[{"price":67640.4,"qty":0.00000000},{"price":67642.3,"qty":1.50794401}],"checksum":284071199,"timestamp":"2024-06-01T17:52:23.450419Z"}]}
{"channel":"book","type":"update","data":[{"symbol":"BTC/USD","bids":[{"price":67622.5,"qty":0.36653969}],"asks":[],"checksum":2221042228,"timestamp":"2024-06-01T17:52:23.462601Z"}]}
{"channel":"book","type":"update","data":[{"symbol":"BTC/USD","bids":[{"price":67628.0,"qty":5.91186031}],"asks":[],"checksum":3232290114,"timestamp":"2024-06-01T17:52:23.462828Z"}]}
{"channel":"book","type":"update","data":[{"symbol":"BTC/USD","bids":[],"asks":[{"price":67635.1,"qty":0.00000000},{"price":67643.2,"qty":0.00029489}],"checksum":958377292,"timestamp":"2024-06-01T17:52:23.529206Z"}]}
{"channel":"book","type":"update","data":[{"symbol":"BTC/USD","bids":[],"asks":[{"price":67642.3,"qty":0.02957700}],"checksum":2125103274,"timestamp":"2024-06-01T17:52:23.535094Z"}]}
{"channel":"book","type":"update","data":[{"symbol":"BTC/USD","bids":[],"asks":[{"price":67635.3,"qty":1.47851886}],"checksum":596417655,"timestamp":"2024-06-01T17:52:23.544233Z"}]}
{"channel":"book","type":"update","data":[{"symbol":"BTC/USD","bids":[],"asks":[{"price":67635.3,"qty":0.00000000},{"price":67643.2,"qty":0.00029489}],"checksum":2125103274,"timestamp":"2024-06-01T17:52:23.588546Z"}]}
{"channel":"book","type":"update","data":[{"symbol":"BTC/USD","bids":[{"price":67618.8,"qty":1.20000000}],"asks":[],"checksum":3679918069,"timestamp":"2024-06-01T17:52:23.592747Z"}]}
{"channel":"book","type":"update","data":[{"symbol":"BTC/USD","bids":[],"asks":[{"price":67640.5,"qty":1.47840576}],"checksum":4163078672,"timestamp":"2024-06-01T17:52:23.593060Z"}]}
{"channel":"book","type":"update","data":[{"symbol":"BTC/USD","bids":[{"price":67623.2,"qty":0.22836862}],"asks":[],"checksum":2283819231,"timestamp":"2024-06-01T17:52:23.618818Z"}]}
{"channel":"book","type":"update","data":[{"symbol":"BTC/USD","bids":[],"asks":[{"price":67641.3,"qty":0.06910000}],"checksum":10625126,"timestamp":"2024-06-01T17:52:23.676568Z"}]}
{"channel":"book","type":"update","data":[{"symbol":"BTC/USD","bids":[],"asks":[{"price":67638.4,"qty":0.00000000},{"price":67642.3,"qty":0.02957700}],"checksum":439639772,"timestamp":"2024-06-01T17:52:23.729097Z"}]}
{"channel":"book","type":"update","data":[{"symbol":"BTC/USD","bids":[],"asks":[{"price":67635.5,"qty":1.47851561}],"checksum":2091064042,"timestamp":"2024-06-01T17:52:23.733483Z"}]}
{"channel":"book","type":"update","data":[{"symbol":"BTC/USD","bids":[],"asks":[{"price":67635.5,"qty":0.00000000},{"price":67642.3,"qty":0.02957700}],"checksum":439639772,"timestamp":"2024-06-01T17:52:23.756716Z"}]}
{"channel":"book","type":"update","data":[{"symbol":"BTC/USD","bids":[],"asks":[{"price":67641.3,"qty":0.00000000},{"price":67643.2,"qty":0.00029489},{"price":67642.4,"qty":0.06910000}],"checksum":2367483091,"timestamp":"2024-06-01T17:52:23.830301Z"}]}
{"channel":"book","type":"update","data":[{"symbol":"BTC/USD","bids":[],"asks":[{"price":67642.4,"qty":0.13820000}],"checksum":149489730,"timestamp":"2024-06-01T17:52:23.833389Z"}]}
{"channel":"book","type":"update","data":[{"symbol":"BTC/USD","bids":[],"asks":[{"price":67635.3,"qty":1.47851812}],"checksum":4163987244,"timestamp":"2024-06-01T17:52:23.849937Z"}]}
{"channel":"book","type":"update","data":[{"symbol":"BTC/USD","bids":[],"asks":[{"price":67635.3,"qty":0.00000000},{"price":67642.4,"qty":0.13820000}],"checksum":149489730,"timestamp":"2024-06-01T17:52:24.001050Z"}]}
{"channel":"book","type":"update","data":[{"symbol":"BTC/USD","bids":[],"asks":[{"price":67635.1,"qty":1.47852345}],"checksum":2096326638,"timestamp":"2024-06-01T17:52:24.005215Z"}]}
{"channel":"book","type":"update","data":[{"symbol":"BTC/USD","bids":[],"asks":[{"price":67635.1,"qty":0.00000000},{"price":67642.4,"qty":0.06910000}],"checksum":2367483091,"timestamp":"2024-06-01T17:52:24.215743Z"}]}
{"channel":"book","type":"update","data":[{"symbol":"BTC/USD","bids":[],"asks":[{"price":67634.8,"qty":1.47853033}],"checksum":2704656235,"timestamp":"2024-06-01T17:52:24.219219Z"}]}
{"channel":"book","type":"update","data":[{"symbol":"BTC/USD","bids":[{"price":67628.0,"qty":4.99213483}],"asks":[],"checksum":1873265159,"timestamp":"2024-06-01T17:52:24.249697Z"}]}
{"channel":"book","type":"update","data":[{"symbol":"BTC/USD","bids":[{"price":67623.8,"qty":0.92086537}],"asks":[],"checksum":615869781,"timestamp":"2024-06-01T17:52:24.249889Z"}]}
{"channel":"book","type":"update","data":[{"symbol":"BTC/USD","bids":[{"price":67623.8,"qty":0.91972599},{"price":67628.0,"qty":4.99327414}],"asks":[],"checksum":1694524980,"timestamp":"2024-06-01T17:52:24.345600Z"}]}
{"channel":"book","type":"update","data":[{"symbol":"BTC/USD","bids":[],"asks":[{"price":67642.3,"qty":0.02987190}],"checksum":3574734387,"timestamp":"2024-06-01T17:52:24.345647Z"}]}
{"channel":"book","type":"update","data":[{"symbol":"BTC/USD","bids":[],"asks":[{"price":67634.8,"qty":0.00000000},{"price":67642.4,"qty":0.06910000}],"checksum":3271135372,"timestamp":"2024-06-01T17:52:24.363644Z"}]}
{"channel":"book","type":"update","data":[{"symbol":"BTC/USD","bids":[],"asks":[{"price":67634.9,"qty":1.47852811}],"checksum":1975675142,"timestamp":"2024-06-01T17:52:24.367529Z"}]}
{"channel":"book","type":"update","data":[{"symbol":"BTC/USD","bids":[],"asks":[{"price":67641.5,"qty":0.06910000}],"checksum":3220628983,"timestamp":"2024-06-01T17:52:24.370668Z"}]}
{"channel":"book","type":"update","data":[{"symbol":"BTC/USD","bids":[],"asks":[{"price":67641.5,"qty":0.13820000}],"checksum":3120107803,"timestamp":"2024-06-01T17:52:24.373570Z"}]}
{"channel":"book","type":"update","data":[{"symbol":"BTC/USD","bids":[],"asks":[{"price":67641.5,"qty":0.06910000}],"checksum":3220628983,"timestamp":"2024-06-01T17:52:24.399971Z"}]}
{"channel":"book","type":"update","data":[{"symbol":"BTC/USD","bids":[],"asks":[{"price":67634.9,"qty":0.00000000},{"price":67642.3,"qty":0.02987190}],"checksum":1027066191,"timestamp":"2024-06-01T17:52:24.400904Z"}]}
{"channel":"book","type":"update","data":[{"symbol":"BTC/USD","bids":[],"asks":[{"price":67641.5,"qty":0.00000000},{"price":67644.5,"qty":0.05912006}],"checksum":2481905890,"timestamp":"2024-06-01T17:52:24.403559Z"}]}
{"channel":"book","type":"update","data":[{"symbol":"BTC/USD","bids":[{"price":67623.7,"qty":0.00000000},{"price":67618.8,"qty":1.20000000}],"asks":[],"checksum":3390558359,"timestamp":"2024-06-01T17:52:24.412370Z"}]}
{"channel":"book","type":"update","data":[{"symbol":"BTC/USD","bids":[],"asks":[{"price":67635.8,"qty":0.03947498}],"checksum":2969433921,"timestamp":"2024-06-01T17:52:24.412396Z"}]}
{"channel":"book","type":"update","data":[{"symbol":"BTC/USD","bids":[{"price":67626.0,"qty":1.47871950}],"asks":[],"checksum":1611781396,"timestamp":"2024-06-01T17:52:24.416632Z"}]}
{"channel":"book","type":"update","data":[{"symbol":"BTC/USD","bids":[],"asks":[{"price":67637.2,"qty":1.47847674}],"checksum":3547068602,"timestamp":"2024-06-01T17:52:24.416771Z"}]}
{"channel":"book","type":"update","data":[{"symbol":"BTC/USD","bids":[{"price":67623.8,"qty":0.00000000},{"price":67618.8,"qty":1.20000000}],"asks":[],"checksum":3697507782,"timestamp":"2024-06-01T17:52:24.418754Z"}]}
{"channel":"book","type":"update","data":[{"symbol":"BTC/USD","bids":[{"price":67628.0,"qty":5.91299878}],"asks":[],"checksum":2685872793,"timestamp":"2024-06-01T17:52:24.418972Z"}]}
{"channel":"book","type":"update","data":[{"symbol":"BTC/USD","bids":[],"asks":[{"price":67636.1,"qty":1.55852682}],"checksum":709583417,"timestamp":"2024-06-01T17:52:24.421047Z"}]}
{"channel":"book","type":"update","data":[{"symbol":"BTC/USD","bids":[{"price":67628.0,"qty":4.99327414}],"asks":[],"checksum":1446983014,"timestamp":"2024-06-01T17:52:24.460362Z"}]}
{"channel":"book","type":"update","data":[{"symbol":"BTC/USD","bids":[{"price":67623.8,"qty":0.91972979}],"asks":[],"checksum":208744041,"timestamp":"2024-06-01T17:52:24.460594Z"}]}
{"channel":"book","type":"update","data":[{"symbol":"BTC/USD","bids":[{"price":67623.8,"qty":0.00000000},{"price":67618.8,"qty":1.20000000}],"asks":[],"checksum":1446983014,"timestamp":"2024-06-01T17:52:24.492798Z"}]}
{"channel":"book","type":"update","data":[{"symbol":"BTC/USD","bids":[{"price":67628.0,"qty":5.91299633}],"asks":[],"checksum":4145520925,"timestamp":"2024-06-01T17:52:24.493104Z"}]}
{"channel":"book","type":"update","data":[{"symbol":"BTC/USD","bids":[],"asks":[{"price":67641.0,"qty":0.06910000}],"checksum":3600052147,"timestamp":"2024-06-01T17:52:24.603619Z"}]}
{"channel":"book","type":"update","data":[{"symbol":"BTC/USD","bids":[{"price":67628.0,"qty":4.99327414}],"asks":[],"checksum":2008873928,"timestamp":"2024-06-01T17:52:24.610678Z"}]}
{"channel":"book","type":"update","data":[{"symbol":"BTC/USD","bids":[{"price":67623.3,"qty":0.91972598}],"asks":[],"checksum":3219655,"timestamp":"2024-06-01T17:52:24.611015Z"}]}
{"channel":"book","type":"update","data":[{"symbol":"BTC/USD","bids":[{"price":67623.3,"qty":0.00000000},{"price":67618.8,"qty":1.20000000}],"asks":[],"checksum":2008873928,"timestamp":"2024-06-01T17:52:24.635755Z"}]}
{"channel":"book","type":"update","data":[{"symbol":"BTC/USD","bids":[],"asks":[{"price":67636.1,"qty":0.08002518}],"checksum":4259361640,"timestamp":"2024-06-01T17:52:24.638892Z"}]}
{"channel":"book","type":"update","data":[{"symbol":"BTC/USD","bids":[],"asks":[{"price":67635.8,"qty":1.51798360}],"checksum":3256539950,"timestamp":"2024-06-01T17:52:24.643506Z"}]}
{"channel":"book","type":"update","data":[{"symbol":"BTC/USD","bids":[],"asks":[{"price":67635.8,"qty":0.03947498}],"checksum":4259361640,"timestamp":"2024-06-01T17:52:24.835805Z"}]}
{"channel":"book","type":"update","data":[{"symbol":"BTC/USD","bids":[],"asks":[{"price":67635.5,"qty":1.47851395}],"checksum":1902046371,"timestamp":"2024-06-01T17:52:24.839904Z"}]}
{"channel":"book","type":"update","data":[{"symbol":"BTC/USD","bids":[{"price":67620.7,"qty":0.17734900}],"asks":[],"checksum":1033992801,"timestamp":"2024-06-01T17:52:25.038446Z"}]}
{"channel":"book","type":"update","data":[{"symbol":"BTC/USD","bids":[],"asks":[{"price":67635.5,"qty":0.00000000},{"price":67642.2,"qty":0.29580000}],"checksum":1350713919,"timestamp":"2024-06-01T17:52:25.126890Z"}]}
{"channel":"book","type":"update","data":[{"symbol":"BTC/USD","bids":[],"asks":[{"price":67635.2,"qty":1.47852149}],"checksum":3540074762,"timestamp":"2024-06-01T17:52:25.130933Z"}]}
{"channel":"book","type":"update","data":[{"symbol":"BTC/USD","bids":[{"price":67628.0,"qty":4.65577414}],"asks":[],"checksum":2261100336,"timestamp":"2024-06-01T17:52:25.193881Z"}]}
{"channel":"book","type":"update","data":[{"symbol":"BTC/USD","bids":[{"price":67628.0,"qty":4.99327414}],"asks":[],"checksum":3540074762,"timestamp":"2024-06-01T17:52:25.217511Z"}]}
{"channel":"book","type":"update","data":[{"symbol":"BTC/USD","bids":[],"asks":[{"price":67641.0,"qty":0.00000000},{"price":67642.2,"qty":0.29580000}],"checksum":2065595738,"timestamp":"2024-06-01T17:52:25.284133Z"}]}
{"channel":"book","type":"update","data":[{"symbol":"BTC/USD","bids":[],"asks":[{"price":67636.1,"qty":0.00000000},{"price":67642.3,"qty":0.02987190}],"checksum":291636297,"timestamp":"2024-06-01T17:52:25.347178Z"}]}
{"channel":"book","type":"update","data":[{"symbol":"BTC/USD","bids":[],"asks":[{"price":67635.2,"qty":0.00000000},{"price":67644.1,"qty":0.06910000}],"checksum":4193386867,"timestamp":"2024-06-01T17:52:25.373187Z"}]}
{"channel":"book","type":"update","data":[{"symbol":"BTC/USD","bids":[],"asks":[{"price":67635.6,"qty":1.47851217}],"checksum":3147215552,"timestamp":"2024-06-01T17:52:25.376723Z"}]}
{"channel":"book","type":"update","data":[{"symbol":"BTC/USD","bids":[],"asks":[{"price":67642.3,"qty":0.02957700}],"checksum":193252039,"timestamp":"2024-06-01T17:52:25.393887Z"}]}
{"channel":"book","type":"update","data":[{"symbol":"BTC/USD","bids":[],"asks":[{"price":67642.1,"qty":0.08181051}],"checksum":3970896999,"timestamp":"2024-06-01T17:52:25.397331Z"}]}
{"channel":"book","type":"update","data":[{"symbol":"BTC/USD","bids":[],"asks":[{"price":67635.6,"qty":0.00000000},{"price":67642.3,"qty":0.02957700}],"checksum":2755302682,"timestamp":"2024-06-01T17:52:25.408687Z"}]}
{"channel":"book","type":"update","data":[{"symbol":"BTC/USD","bids":[{"price":67628.0,"qty":5.91299510}],"asks":[],"checksum":278022272,"timestamp":"2024-06-01T17:52:25.520761Z"}]}
{"channel":"book","type":"update","data":[{"symbol":"BTC/USD","bids":[],"asks":[{"price":67635.7,"qty":1.47851007}],"checksum":2139650809,"timestamp":"2024-06-01T17:52:25.638866Z"}]}
{"channel":"book","type":"update","data":[{"symbol":"BTC/USD","bids":[],"asks":[{"price":67635.7,"qty":0.00000000},{"price":67642.3,"qty":0.02957700}],"checksum":278022272,"timestamp":"2024-06-01T17:52:25.730781Z"}]}
{"channel":"book","type":"update","data":[{"symbol":"BTC/USD","bids":[],"asks":[{"price":67635.4,"qty":1.47851582}],"checksum":422036756,"timestamp":"2024-06-01T17:52:25.733994Z"}]}
{"channel":"book","type":"update","data":[{"symbol":"BTC/USD","bids":[],"asks":[{"price":67635.4,"qty":0.00000000},{"price":67642.3,"qty":0.02957700}],"checksum":278022272,"timestamp":"2024-06-01T17:52:25.803919Z"}]}
{"channel":"book","type":"update","data":[{"symbol":"BTC/USD","bids":[],"asks":[{"price":67635.9,"qty":1.47850606}],"checksum":4217423223,"timestamp":"2024-06-01T17:52:25.807866Z"}]}
{"channel":"book","type":"update","data":[{"symbol":"BTC/USD","bids":[],"asks":[{"price":67635.9,"qty":0.00000000},{"price":67642.3,"qty":0.02957700}],"checksum":278022272,"timestamp":"2024-06-01T17:52:25.889758Z"}]}
{"channel":"book","type":"update","data":[{"symbol":"BTC/USD","bids":[],"asks":[{"price":67635.6,"qty":1.47851153}],"checksum":4070501496,"timestamp":"2024-06-01T17:52:25.893226Z"}]}
{"channel":"book","type":"update","data":[{"symbol":"BTC/USD","bids":[],"asks":[{"price":67641.3,"qty":0.06910000}],"checksum":2996075387,"timestamp":"2024-06-01T17:52:26.284185Z"}]}
{"channel":"book","type":"update","data":[{"symbol":"BTC/USD","bids":[],"asks":[{"price":67641.3,"qty":0.13820000}],"checksum":185716730,"timestamp":"2024-06-01T17:52:26.286994Z"}]}
{"channel":"book","type":"update","data":[{"symbol":"BTC/USD","bids":[],"asks":[{"price":67641.3,"qty":0.06910000}],"checksum":2996075387,"timestamp":"2024-06-01T17:52:26.371487Z"}]}
{"channel":"book","type":"update","data":[{"symbol":"BTC/USD","bids":[],"asks":[{"price":67642.1,"qty":0.08210542}],"checksum":3053694482,"timestamp":"2024-06-01T17:52:26.521672Z"}]}
{"channel":"book","type":"update","data":[{"symbol":"BTC/USD","bids":[],"asks":[{"price":67635.6,"qty":0.00000000},{"price":67642.2,"qty":0.29580000}],"checksum":2813965732,"timestamp":"2024-06-01T17:52:26.538510Z"}]}
{"channel":"book","type":"update","data":[{"symbol":"BTC/USD","bids":[],"asks":[{"price":67635.3,"qty":1.47851788}],"checksum":2363264387,"timestamp":"2024-06-01T17:52:26.542592Z"}]}
{"channel":"book","type":"update","data":[{"symbol":"BTC/USD","bids":[],"asks":[{"price":67642.1,"qty":0.08181051}],"checksum":2286639338,"timestamp":"2024-06-01T17:52:26.566471Z"}]}
{"channel":"book","type":"update","data":[{"symbol":"BTC/USD","bids":[],"asks":[{"price":67635.3,"qty":0.00000000},{"price":67642.2,"qty":0.29609491}],"checksum":1796642946,"timestamp":"2024-06-01T17:52:26.711028Z"}]}
{"channel":"book","type":"update","data":[{"symbol":"BTC/USD","bids":[],"asks":[{"price":67636.1,"qty":1.47850137}],"checksum":1675638154,"timestamp":"2024-06-01T17:52:26.714384Z"}]}
{"channel":"book","type":"update","data":[{"symbol":"BTC/USD","bids":[{"price":67628.0,"qty":4.99327414}],"asks":[],"checksum":3611879440,"timestamp":"2024-06-01T17:52:27.008498Z"}]}
{"channel":"book","type":"update","data":[{"symbol":"BTC/USD","bids":[{"price":67623.3,"qty":0.91972861}],"asks":[],"checksum":3568397179,"timestamp":"2024-06-01T17:52:27.008845Z"}]}
{"channel":"book","type":"update","data":[{"symbol":"BTC/USD","bids":[{"price":67623.3,"qty":0.00000000},{"price":67620.7,"qty":0.17734900}],"asks":[],"checksum":3611879440,"timestamp":"2024-06-01T17:52:27.387760Z"}]}
{"channel":"book","type":"update","data":[{"symbol":"BTC/USD","bids":[],"asks":[{"price":67642.1,"qty":0.08210542}],"checksum":3554622841,"timestamp":"2024-06-01T17:52:27.602297Z"}]}
{"channel":"book","type":"update","data":[{"symbol":"BTC/USD","bids":[],"asks":[{"price":67636.1,"qty":0.00000000},{"price":67642.2,"qty":0.29580000}],"checksum":319907902,"timestamp":"2024-06-01T17:52:27.935336Z"}]}
{"channel":"book","type":"update","data":[{"symbol":"BTC/USD","bids":[],"asks":[{"price":67636.4,"qty":1.47849433}],"checksum":116886690,"timestamp":"2024-06-01T17:52:27.938796Z"}]}
{"channel":"book","type":"update","data":[{"symbol":"BTC/USD","bids":[],"asks":[{"price":67636.4,"qty":0.00000000},{"price":67642.2,"qty":0.29580000}],"checksum":319907902,"timestamp":"2024-06-01T17:52:27.955703Z"}]}
{"channel":"book","type":"update","data":[{"symbol":"BTC/USD","bids":[],"asks":[{"price":67642.1,"qty":0.08181051},{"price":67642.2,"qty":0.29609491}],"checksum":3753788696,"timestamp":"2024-06-01T17:52:28.009411Z"}]}
{"channel":"book","type":"update","data":[{"symbol":"BTC/USD","bids":[],"asks":[{"price":67636.0,"qty":1.47850462}],"checksum":1332953435,"timestamp":"2024-06-01T17:52:28.033906Z"}]}
{"channel":"book","type":"update","data":[{"symbol":"BTC/USD","bids":[{"price":67628.0,"qty":5.91299872}],"asks":[],"checksum":1738934622,"timestamp":"2024-06-01T17:52:28.526790Z"}]}
{"channel":"book","type":"update","data":[{"symbol":"BTC/USD","bids":[],"asks":[{"price":67636.0,"qty":0.00000000},{"price":67642.2,"qty":0.00029491}],"checksum":1226322327,"timestamp":"2024-06-01T17:52:28.576300Z"}]}
{"channel":"book","type":"update","data":[{"symbol":"BTC/USD","bids":[],"asks":[{"price":67641.3,"qty":0.00000000},{"price":67642.3,"qty":0.02957700}],"checksum":1453869930,"timestamp":"2024-06-01T17:52:28.581238Z"}]}
{"channel":"book","type":"update","data":[{"symbol":"BTC/USD","bids":[],"asks":[{"price":67637.2,"qty":0.00000000},{"price":67643.1,"qty":0.13820000}],"checksum":2320855231,"timestamp":"2024-06-01T17:52:28.585019Z"}]}
{"channel":"book","type":"update","data":[{"symbol":"BTC/USD","bids":[],"asks":[{"price":67640.5,"qty":0.00000000},{"price":67644.6,"qty":0.05911989}],"checksum":281991718,"timestamp":"2024-06-01T17:52:28.587756Z"}]}
{"channel":"book","type":"update","data":[{"symbol":"BTC/USD","bids":[],"asks":[{"price":67643.1,"qty":0.06910000}],"checksum":165190683,"timestamp":"2024-06-01T17:52:28.590801Z"}]}
{"channel":"book","type":"update","data":[{"symbol":"BTC/USD","bids":[],"asks":[{"price":67642.5,"qty":1.47836201}],"checksum":4179950116,"timestamp":"2024-06-01T17:52:28.591393Z"}]}
{"channel":"book","type":"update","data":[{"symbol":"BTC/USD","bids":[{"price":67622.0,"qty":1.47880837}],"asks":[],"checksum":437572360,"timestamp":"2024-06-01T17:52:28.591510Z"}]}
{"channel":"book","type":"update","data":[{"symbol":"BTC/USD","bids":[],"asks":[{"price":67637.2,"qty":1.47847760}],"checksum":2847175131,"timestamp":"2024-06-01T17:52:28.591532Z"}]}
{"channel":"book","type":"update","data":[{"symbol":"BTC/USD","bids":[],"asks":[{"price":67637.2,"qty":0.00000000},{"price":67644.6,"qty":0.05911989}],"checksum":1001385286,"timestamp":"2024-06-01T17:52:28.600510Z"}]}
{"channel":"book","type":"update","data":[{"symbol":"BTC/USD","bids":[],"asks":[{"price":67639.3,"qty":1.47843239}],"checksum":1829704660,"timestamp":"2024-06-01T17:52:28.630481Z"}]}
{"channel":"book","type":"update","data":[{"symbol":"BTC/USD","bids":[{"price":67628.0,"qty":6.61018746}],"asks":[],"checksum":212244810,"timestamp":"2024-06-01T17:52:28.647776Z"}]}
{"channel":"book","type":"update","data":[{"symbol":"BTC/USD","bids":[],"asks":[{"price":67628.1,"qty":0.00000000},{"price":67644.6,"qty":0.05911989}],"checksum":4168990023,"timestamp":"2024-06-01T17:52:28.649346Z"}]}
{"channel":"book","type":"update","data":[{"symbol":"BTC/USD","bids":[{"price":67631.7,"qty":1.33032956}],"asks":[],"checksum":1689749683,"timestamp":"2024-06-01T17:52:28.652361Z"}]}
{"channel":"book","type":"update","data":[{"symbol":"BTC/USD","bids":[{"price":67631.7,"qty":1.91109800}],"asks":[],"checksum":828848508,"timestamp":"2024-06-01T17:52:28.652413Z"}]}
{"channel":"book","type":"update","data":[{"symbol":"BTC/USD","bids":[{"price":67628.0,"qty":6.02938725}],"asks":[],"checksum":4219927348,"timestamp":"2024-06-01T17:52:28.652483Z"}]}
{"channel":"book","type":"update","data":[{"symbol":"BTC/USD","bids":[{"price":67628.0,"qty":5.96028725},{"price":67631.7,"qty":1.98019800}],"asks":[],"checksum":3722080613,"timestamp":"2024-06-01T17:52:28.653104Z"}]}
{"channel":"book","type":"update","data":[{"symbol":"BTC/USD","bids":[{"price":67631.3,"qty":0.33750000}],"asks":[],"checksum":2592898688,"timestamp":"2024-06-01T17:52:28.653417Z"}]}
{"channel":"book","type":"update","data":[{"symbol":"BTC/USD","bids":[{"price":67628.0,"qty":5.93071371},{"price":67631.7,"qty":2.00976993}],"asks":[],"checksum":2675258196,"timestamp":"2024-06-01T17:52:28.653582Z"}]}
{"channel":"book","type":"update","data":[{"symbol":"BTC/USD","bids":[{"price":67627.9,"qty":1.47867795}],"asks":[],"checksum":3368783171,"timestamp":"2024-06-01T17:52:28.653731Z"}]}
{"channel":"book","type":"update","data":[{"symbol":"BTC/USD","bids":[{"price":67626.0,"qty":0.00000000},{"price":67621.2,"qty":0.33750000}],"asks":[],"checksum":809570324,"timestamp":"2024-06-01T17:52:28.653813Z"}]}
{"channel":"book","type":"update","data":[{"symbol":"BTC/USD","bids":[{"price":67628.0,"qty":5.92957440}],"asks":[],"checksum":2451316600,"timestamp":"2024-06-01T17:52:28.655140Z"}]}
{"channel":"book","type":"update","data":[{"symbol":"BTC/USD","bids":[{"price":67628.0,"qty":4.59962607}],"asks":[],"checksum":3965090065,"timestamp":"2024-06-01T17:52:28.655178Z"}]}
{"channel":"book","type":"update","data":[{"symbol":"BTC/USD","bids":[],"asks":[{"price":67642.2,"qty":0.00000000},{"price":67644.9,"qty":0.29580000},{"price":67644.8,"qty":0.00029491}],"checksum":869000626,"timestamp":"2024-06-01T17:52:28.655244Z"}]}
{"channel":"book","type":"update","data":[{"symbol":"BTC/USD","bids":[{"price":67628.0,"qty":4.29962607},{"price":67631.7,"qty":2.30976993}],"asks":[],"checksum":2389132019,"timestamp":"2024-06-01T17:52:28.655838Z"}]}
{"channel":"book","type":"update","data":[{"symbol":"BTC/USD","bids":[{"price":67628.0,"qty":3.96212607}],"asks":[],"checksum":2172263255,"timestamp":"2024-06-01T17:52:28.655878Z"}]}
{"channel":"book","type":"update","data":[{"symbol":"BTC/USD","bids":[{"price":67628.0,"qty":3.79519560},{"price":67631.7,"qty":2.47670040}],"asks":[],"checksum":2290832952,"timestamp":"2024-06-01T17:52:28.655945Z"}]}
{"channel":"book","type":"update","data":[{"symbol":"BTC/USD","bids":[{"price":67631.7,"qty":2.54580040}],"asks":[],"checksum":1845759657,"timestamp":"2024-06-01T17:52:28.656247Z"}]}
{"channel":"book","type":"update","data":[{"symbol":"BTC/USD","bids":[{"price":67631.7,"qty":2.88330040}],"asks":[],"checksum":3774834254,"timestamp":"2024-06-01T17:52:28.656667Z"}]}
{"channel":"book","type":"update","data":[{"symbol":"BTC/USD","bids":[{"price":67628.0,"qty":3.60543632},{"price":67631.7,"qty":3.07179158}],"asks":[],"checksum":843035161,"timestamp":"2024-06-01T17:52:28.656991Z"}]}
{"channel":"book","type":"update","data":[{"symbol":"BTC/USD","bids":[{"price":67628.0,"qty":3.60146632},{"price":67631.7,"qty":3.07576158}],"asks":[],"checksum":3406976862,"timestamp":"2024-06-01T17:52:28.657080Z"}]}
{"channel":"book","type":"update","data":[{"symbol":"BTC/USD","bids":[],"asks":[{"price":67644.6,"qty":0.00000000},{"price":67644.9,"qty":0.29580000}],"checksum":681697160,"timestamp":"2024-06-01T17:52:28.657910Z"}]}
{"channel":"book","type":"update","data":[{"symbol":"BTC/USD","bids":[{"price":67631.7,"qty":4.55435815}],"asks":[],"checksum":3459690895,"timestamp":"2024-06-01T17:52:28.657928Z"}]}
{"channel":"book","type":"update","data":[{"symbol":"BTC/USD","bids":[{"price":67631.2,"qty":1.47860659}],"asks":[],"checksum":1967279378,"timestamp":"2024-06-01T17:52:28.658128Z"}]}
{"channel":"book","type":"update","data":[{"symbol":"BTC/USD","bids":[],"asks":[{"price":67638.0,"qty":1.47845930}],"checksum":4274189552,"timestamp":"2024-06-01T17:52:28.658144Z"}]}
{"channel":"book","type":"update","data":[{"symbol":"BTC/USD","bids":[{"price":67628.0,"qty":3.29046632},{"price":67631.7,"qty":4.86535815}],"asks":[],"checksum":4248329438,"timestamp":"2024-06-01T17:52:28.659538Z"}]}
{"channel":"book","type":"update","data":[{"symbol":"BTC/USD","bids":[{"price":67628.0,"qty":3.27234632},{"price":67631.7,"qty":4.88347815}],"asks":[],"checksum":4115102638,"timestamp":"2024-06-01T17:52:28.659726Z"}]}
{"channel":"book","type":"update","data":[{"symbol":"BTC/USD","bids":[{"price":67628.0,"qty":2.07634632}],"asks":[],"checksum":73362642,"timestamp":"2024-06-01T17:52:28.681711Z"}]}
{"channel":"book","type":"update","data":[{"symbol":"BTC/USD","bids":[{"price":67631.7,"qty":7.00347815}],"asks":[],"checksum":1652754267,"timestamp":"2024-06-01T17:52:28.690834Z"}]}
{"channel":"book","type":"update","data":[{"symbol":"BTC/USD","bids":[],"asks":[{"price":67638.0,"qty":0.00000000},{"price":67644.9,"qty":0.29580000}],"checksum":3909336761,"timestamp":"2024-06-01T17:52:28.727968Z"}]}
{"channel":"book","type":"update","data":[{"symbol":"BTC/USD","bids":[],"asks":[{"price":67637.6,"qty":1.47846764}],"checksum":790403009,"timestamp":"2024-06-01T17:52:28.731352Z"}]}
{"channel":"book","type":"update","data":[{"symbol":"BTC/USD","bids":[],"asks":[{"price":67644.8,"qty":0.00000000},{"price":67644.9,"qty":0.29580000}],"checksum":4077138955,"timestamp":"2024-06-01T17:52:28.739088Z"}]}
{"channel":"book","type":"update","data":[{"symbol":"BTC/USD","bids":[],"asks":[{"price":67641.8,"qty":0.06910000}],"checksum":4255895250,"timestamp":"2024-06-01T17:52:28.743885Z"}]}
{"channel":"book","type":"update","data":[{"symbol":"BTC/USD","bids":[],"asks":[{"price":67633.0,"qty":0.00000000},{"price":67644.9,"qty":0.29580000},{"price":67638.0,"qty":0.00010000}],"checksum":3365374954,"timestamp":"2024-06-01T17:52:28.811048Z"}]}
{"channel":"book","type":"update","data":[{"symbol":"BTC/USD","bids":[{"price":67631.7,"qty":6.93437815}],"asks":[],"checksum":491322458,"timestamp":"2024-06-01T17:52:28.832988Z"}]}
{"channel":"book","type":"update","data":[{"symbol":"BTC/USD","bids":[{"price":67628.0,"qty":2.07534632}],"asks":[],"checksum":809418375,"timestamp":"2024-06-01T17:52:29.030695Z"}]}
{"channel":"book","type":"update","data":[{"symbol":"BTC/USD","bids":[],"asks":[{"price":67637.6,"qty":0.00000000},{"price":67644.9,"qty":0.29580000}],"checksum":868344688,"timestamp":"2024-06-01T17:52:29.047949Z"}]}
{"channel":"book","type":"update","data":[{"symbol":"BTC/USD","bids":[],"asks":[{"price":67637.9,"qty":1.47846141}],"checksum":2480566576,"timestamp":"2024-06-01T17:52:29.051682Z"}]}
{"channel":"book","type":"update","data":[{"symbol":"BTC/USD","bids":[],"asks":[{"price":67637.9,"qty":0.00000000},{"price":67644.9,"qty":0.29580000}],"checksum":868344688,"timestamp":"2024-06-01T17:52:29.199070Z"}]}
{"channel":"book","type":"update","data":[{"symbol":"BTC/USD","bids":[],"asks":[{"price":67637.7,"qty":1.47846688}],"checksum":3239494765,"timestamp":"2024-06-01T17:52:29.202894Z"}]}
{"channel":"book","type":"update","data":[{"symbol":"BTC/USD","bids":[],"asks":[{"price":67637.7,"qty":0.00000000},{"price":67644.9,"qty":0.29580000}],"checksum":868344688,"timestamp":"2024-06-01T17:52:29.364079Z"}]}
{"channel":"book","type":"update","data":[{"symbol":"BTC/USD","bids":[],"asks":[{"price":67637.5,"qty":1.47847146}],"checksum":612975233,"timestamp":"2024-06-01T17:52:29.367966Z"}]}
{"channel":"book","type":"update","data":[{"symbol":"BTC/USD","bids":[],"asks":[{"price":67641.8,"qty":0.00000000},{"price":67644.9,"qty":0.29580000}],"checksum":3404568436,"timestamp":"2024-06-01T17:52:29.401659Z"}]}
{"channel":"book","type":"update","data":[{"symbol":"BTC/USD","bids":[],"asks":[{"price":67643.5,"qty":0.06910000}],"checksum":1782889452,"timestamp":"2024-06-01T17:52:29.660724Z"}]}
{"channel":"book","type":"update","data":[{"symbol":"BTC/USD","bids":[],"asks":[{"price":67643.5,"qty":0.00000000},{"price":67644.9,"qty":0.29580000}],"checksum":3404568436,"timestamp":"2024-06-01T17:52:29.673301Z"}]}
{"channel":"book","type":"update","data":[{"symbol":"BTC/USD","bids":[],"asks":[{"price":67637.5,"qty":0.00000000},{"price":67645.5,"qty":0.05941410}],"checksum":3864246493,"timestamp":"2024-06-01T17:52:29.705566Z"}]}
{"channel":"book","type":"update","data":[{"symbol":"BTC/USD","bids":[],"asks":[{"price":67638.0,"qty":1.47856039}],"checksum":191462962,"timestamp":"2024-06-01T17:52:29.709559Z"}]}
{"channel":"book","type":"update","data":[{"symbol":"BTC/USD","bids":[],"asks":[{"price":67645.5,"qty":0.05911919},{"price":67645.4,"qty":0.00029491}],"checksum":1413538533,"timestamp":"2024-06-01T17:52:29.730948Z"}]}
{"channel":"book","type":"update","data":[{"symbol":"BTC/USD","bids":[{"price":67628.1,"qty":0.00113940}],"asks":[],"checksum":2370164190,"timestamp":"2024-06-01T17:52:29.731150Z"}]}
{"channel":"book","type":"update","data":[{"symbol":"BTC/USD","bids":[],"asks":[{"price":67638.0,"qty":0.00010000}],"checksum":297010380,"timestamp":"2024-06-01T17:52:29.760009Z"}]}
{"channel":"book","type":"update","data":[{"symbol":"BTC/USD","bids":[],"asks":[{"price":67637.7,"qty":1.47846542}],"checksum":3142468236,"timestamp":"2024-06-01T17:52:29.763625Z"}]}
{"channel":"book","type":"update","data":[{"symbol":"BTC/USD","bids":[],"asks":[{"price":67637.7,"qty":0.00000000},{"price":67645.4,"qty":0.00029491}],"checksum":297010380,"timestamp":"2024-06-01T17:52:29.812546Z"}]}
{"channel":"book","type":"update","data":[{"symbol":"BTC/USD","bids":[],"asks":[{"price":67638.0,"qty":1.47855965}],"checksum":735648586,"timestamp":"2024-06-01T17:52:29.816021Z"}]}
{"channel":"book","type":"update","data":[{"symbol":"BTC/USD","bids":[],"asks":[{"price":67642.6,"qty":0.06910000}],"checksum":2217110402,"timestamp":"2024-06-01T17:52:29.859696Z"}]}
{"channel":"book","type":"update","data":[{"symbol":"BTC/USD","bids":[],"asks":[{"price":67638.0,"qty":0.00010000}],"checksum":1693934551,"timestamp":"2024-06-01T17:52:29.865595Z"}]}
{"channel":"book","type":"update","data":[{"symbol":"BTC/USD","bids":[],"asks":[{"price":67637.8,"qty":1.47846438}],"checksum":770806926,"timestamp":"2024-06-01T17:52:29.870500Z"}]}
{"channel":"book","type":"update","data":[{"symbol":"BTC/USD","bids":[{"price":67631.7,"qty":6.93537815}],"asks":[],"checksum":504259005,"timestamp":"2024-06-01T17:52:30.027069Z"}]}
{"channel":"book","type":"update","data":[{"symbol":"BTC/USD","bids":[{"price":67628.0,"qty":1.15562174}],"asks":[],"checksum":2320171648,"timestamp":"2024-06-01T17:52:30.153735Z"}]}
{"channel":"book","type":"update","data":[{"symbol":"BTC/USD","bids":[{"price":67623.3,"qty":0.91972970}],"asks":[],"checksum":3180808228,"timestamp":"2024-06-01T17:52:30.153912Z"}]}
{"channel":"book","type":"update","data":[{"symbol":"BTC/USD","bids":[],"asks":[{"price":67631.8,"qty":0.51091373}],"checksum":2235233958,"timestamp":"2024-06-01T17:52:30.154174Z"}]}
{"channel":"book","type":"update","data":[{"symbol":"BTC/USD","bids":[],"asks":[{"price":67637.8,"qty":0.00000000},{"price":67644.9,"qty":0.29580000}],"checksum":2152449570,"timestamp":"2024-06-01T17:52:30.218120Z"}]}
{"channel":"book","type":"update","data":[{"symbol":"BTC/USD","bids":[{"price":67631.2,"qty":0.00000000},{"price":67622.3,"qty":0.00100000}],"asks":[],"checksum":3696075084,"timestamp":"2024-06-01T17:52:30.223227Z"}]}
{"channel":"book","type":"update","data":[{"symbol":"BTC/USD","bids":[{"price":67631.7,"qty":8.41397472}],"asks":[],"checksum":2379629695,"timestamp":"2024-06-01T17:52:30.226717Z"}]}
{"channel":"book","type":"update","data":[{"symbol":"BTC/USD","bids":[],"asks":[{"price":67638.4,"qty":1.47845143}],"checksum":3336899775,"timestamp":"2024-06-01T17:52:30.226763Z"}]}
{"channel":"book","type":"update","data":[{"symbol":"BTC/USD","bids":[],"asks":[{"price":67638.4,"qty":0.00000000},{"price":67644.9,"qty":0.29580000}],"checksum":2379629695,"timestamp":"2024-06-01T17:52:30.568405Z"}]}
{"channel":"book","type":"update","data":[{"symbol":"BTC/USD","bids":[],"asks":[{"price":67638.1,"qty":1.47845735}],"checksum":2173834533,"timestamp":"2024-06-01T17:52:30.572100Z"}]}
{"channel":"book","type":"update","data":[{"symbol":"BTC/USD","bids":[],"asks":[{"price":67638.1,"qty":0.00000000},{"price":67644.9,"qty":0.29580000}],"checksum":2379629695,"timestamp":"2024-06-01T17:52:30.687760Z"}]}
{"channel":"book","type":"update","data":[{"symbol":"BTC/USD","bids":[],"asks":[{"price":67637.8,"qty":1.47846532}],"checksum":3183892285,"timestamp":"2024-06-01T17:52:30.691140Z"}]}
{"channel":"book","type":"update","data":[{"symbol":"BTC/USD","bids":[],"asks":[{"price":67642.6,"qty":0.00000000},{"price":67644.9,"qty":0.29580000}],"checksum":1494586335,"timestamp":"2024-06-01T17:52:30.765166Z"}]}
{"channel":"book","type":"update","data":[{"symbol":"BTC/USD","bids":[],"asks":[{"price":67637.8,"qty":0.00000000},{"price":67645.4,"qty":0.00029491}],"checksum":2129920204,"timestamp":"2024-06-01T17:52:30.772302Z"}]}
{"channel":"book","type":"update","data":[{"symbol":"BTC/USD","bids":[],"asks":[{"price":67638.4,"qty":1.47845142}],"checksum":2897667418,"timestamp":"2024-06-01T17:52:30.776149Z"}]}
{"channel":"book","type":"update","data":[{"symbol":"BTC/USD","bids":[],"asks":[{"price":67638.4,"qty":0.00000000},{"price":67645.4,"qty":0.00029491}],"checksum":2129920204,"timestamp":"2024-06-01T17:52:30.790503Z"}]}
{"channel":"book","type":"update","data":[{"symbol":"BTC/USD","bids":[],"asks":[{"price":67631.8,"qty":0.40000000}],"checksum":1965687848,"timestamp":"2024-06-01T17:52:30.832786Z"}]}
{"channel":"book","type":"update","data":[{"symbol":"BTC/USD","bids":[],"asks":[{"price":67644.1,"qty":1.47832669}],"checksum":3726489393,"timestamp":"2024-06-01T17:52:30.836598Z"}]}
{"channel":"book","type":"update","data":[{"symbol":"BTC/USD","bids":[],"asks":[{"price":67642.5,"qty":0.00000000},{"price":67645.4,"qty":0.00029491}],"checksum":1330677327,"timestamp":"2024-06-01T17:52:30.852721Z"}]}
{"channel":"book","type":"update","data":[{"symbol":"BTC/USD","bids":[],"asks":[{"price":67645.4,"qty":0.00000000},{"price":67648.8,"qty":1.47822498},{"price":67645.5,"qty":0.00029493}],"checksum":2724849037,"timestamp":"2024-06-01T17:52:30.855415Z"}]}
{"channel":"book","type":"update","data":[{"symbol":"BTC/USD","bids":[],"asks":[{"price":67639.1,"qty":1.47843693}],"checksum":407517745,"timestamp":"2024-06-01T17:52:30.858059Z"}]}
{"channel":"book","type":"update","data":[{"symbol":"BTC/USD","bids":[],"asks":[{"price":67639.1,"qty":0.00000000},{"price":67645.5,"qty":0.00029493}],"checksum":2724849037,"timestamp":"2024-06-01T17:52:30.895428Z"}]}
{"channel":"book","type":"update","data":[{"symbol":"BTC/USD","bids":[],"asks":[{"price":67645.5,"qty":0.00000000},{"price":67648.8,"qty":1.47822498},{"price":67648.7,"qty":0.00029493}],"checksum":3355384848,"timestamp":"2024-06-01T17:52:30.912963Z"}]}
{"channel":"book","type":"update","data":[{"symbol":"BTC/USD","bids":[{"price":67631.7,"qty":8.34487472}],"asks":[],"checksum":2027999583,"timestamp":"2024-06-01T17:52:30.967636Z"}]}
{"channel":"book","type":"update","data":[{"symbol":"BTC/USD","bids":[],"asks":[{"price":67643.3,"qty":0.06910000}],"checksum":3762903385,"timestamp":"2024-06-01T17:52:30.975661Z"}]}
{"channel":"book","type":"update","data":[{"symbol":"BTC/USD","bids":[],"asks":[{"price":67643.3,"qty":0.00000000},{"price":67648.7,"qty":0.00029493},{"price":67642.4,"qty":0.06910000}],"checksum":4255092205,"timestamp":"2024-06-01T17:52:30.976470Z"}]}
{"channel":"book","type":"update","data":[{"symbol":"BTC/USD","bids":[],"asks":[{"price":67642.4,"qty":0.00000000},{"price":67648.7,"qty":0.00029493},{"price":67641.4,"qty":0.06910000}],"checksum":3441833316,"timestamp":"2024-06-01T17:52:30.977892Z"}]}
{"channel":"book","type":"update","data":[{"symbol":"BTC/USD","bids":[],"asks":[{"price":67641.4,"qty":0.00000000},{"price":67648.7,"qty":0.00029493},{"price":67640.1,"qty":0.06910000}],"checksum":3600454524,"timestamp":"2024-06-01T17:52:30.980158Z"}]}
{"channel":"book","type":"update","data":[{"symbol":"BTC/USD","bids":[{"price":67628.0,"qty":1.03468874}],"asks":[],"checksum":2098156190,"timestamp":"2024-06-01T17:52:30.981993Z"}]}
{"channel":"book","type":"update","data":[{"symbol":"BTC/USD","bids":[],"asks":[{"price":67640.1,"qty":0.00000000},{"price":67648.7,"qty":0.00029493}],"checksum":3547664573,"timestamp":"2024-06-01T17:52:30.982251Z"}]}
{"channel":"book","type":"update","data":[{"symbol":"BTC/USD","bids":[{"price":67631.7,"qty":8.00737472}],"asks":[],"checksum":3440815637,"timestamp":"2024-06-01T17:52:30.984381Z"}]}
{"channel":"book","type":"update","data":[{"symbol":"BTC/USD","bids":[{"price":67631.3,"qty":0.00000000},{"price":67622.0,"qty":1.47880837}],"asks":[],"checksum":310778087,"timestamp":"2024-06-01T17:52:30.984720Z"}]}
{"channel":"book","type":"update","data":[{"symbol":"BTC/USD","bids":[{"price":67628.0,"qty":0.69718874}],"asks":[],"checksum":1687764143,"timestamp":"2024-06-01T17:52:30.985254Z"}]}
{"channel":"book","type":"update","data":[{"symbol":"BTC/USD","bids":[],"asks":[{"price":67638.6,"qty":0.33750000}],"checksum":4019619776,"timestamp":"2024-06-01T17:52:30.987256Z"}]}
{"channel":"book","type":"update","data":[{"symbol":"BTC/USD","bids":[],"asks":[{"price":67636.0,"qty":0.06910000}],"checksum":1835259815,"timestamp":"2024-06-01T17:52:30.988718Z"}]}
{"channel":"book","type":"update","data":[{"symbol":"BTC/USD","bids":[],"asks":[{"price":67638.5,"qty":1.47844965}],"checksum":1175197269,"timestamp":"2024-06-01T17:52:30.989147Z"}]}
{"channel":"book","type":"update","data":[{"symbol":"BTC/USD","bids":[],"asks":[{"price":67636.0,"qty":0.00000000},{"price":67644.1,"qty":1.47832669},{"price":67634.4,"qty":0.06910000}],"checksum":1623818555,"timestamp":"2024-06-01T17:52:30.989858Z"}]}
{"channel":"book","type":"update","data":[{"symbol":"BTC/USD","bids":[],"asks":[{"price":67638.5,"qty":0.00000000},{"price":67644.3,"qty":0.06910000}],"checksum":333757321,"timestamp":"2024-06-01T17:52:30.995436Z"}]}
{"channel":"book","type":"update","data":[{"symbol":"BTC/USD","bids":[{"price":67623.3,"qty":0.00000000},{"price":67621.1,"qty":0.00120940}],"asks":[],"checksum":3643379371,"timestamp":"2024-06-01T17:52:30.999227Z"}]}
{"channel":"book","type":"update","data":[{"symbol":"BTC/USD","bids":[],"asks":[{"price":67634.4,"qty":0.00000000},{"price":67644.9,"qty":0.29580000}],"checksum":1272597005,"timestamp":"2024-06-01T17:52:30.999424Z"}]}
{"channel":"book","type":"update","data":[{"symbol":"BTC/USD","bids":[],"asks":[{"price":67631.8,"qty":0.73750000}],"checksum":3794704207,"timestamp":"2024-06-01T17:52:31.001665Z"}]}
{"channel":"book","type":"update","data":[{"symbol":"BTC/USD","bids":[{"price":67631.7,"qty":6.52877815}],"asks":[],"checksum":4244096292,"timestamp":"2024-06-01T17:52:31.003555Z"}]}
{"channel":"book","type":"update","data":[{"symbol":"BTC/USD","bids":[],"asks":[{"price":67639.3,"qty":0.00000000},{"price":67648.7,"qty":0.00029493}],"checksum":4245977145,"timestamp":"2024-06-01T17:52:31.003593Z"}]}
{"channel":"book","type":"update","data":[{"symbol":"BTC/USD","bids":[],"asks":[{"price":67631.8,"qty":1.07500000}],"checksum":2867276653,"timestamp":"2024-06-01T17:52:31.003658Z"}]}
{"channel":"book","type":"update","data":[{"symbol":"BTC/USD","bids":[{"price":67631.7,"qty":5.05018158}],"asks":[],"checksum":309600868,"timestamp":"2024-06-01T17:52:31.003675Z"}]}
{"channel":"book","type":"update","data":[{"symbol":"BTC/USD","bids":[],"asks":[{"price":67644.9,"qty":0.00000000},{"price":67648.8,"qty":1.47822498},{"price":67648.7,"qty":0.29609493}],"checksum":3622226128,"timestamp":"2024-06-01T17:52:31.005814Z"}]}
{"channel":"book","type":"update","data":[{"symbol":"BTC/USD","bids":[],"asks":[{"price":67631.8,"qty":0.73750000}],"checksum":938325733,"timestamp":"2024-06-01T17:52:31.006821Z"}]}
{"channel":"book","type":"update","data":[{"symbol":"BTC/USD","bids":[],"asks":[{"price":67631.8,"qty":0.40000000}],"checksum":2652466087,"timestamp":"2024-06-01T17:52:31.009569Z"}]}
{"channel":"book","type":"update","data":[{"symbol":"BTC/USD","bids":[{"price":67630.9,"qty":1.47861303}],"asks":[],"checksum":1798804479,"timestamp":"2024-06-01T17:52:31.009958Z"}]}
{"channel":"book","type":"update","data":[{"symbol":"BTC/USD","bids":[{"price":67626.1,"qty":1.47871752}],"asks":[],"checksum":1762979247,"timestamp":"2024-06-01T17:52:31.010068Z"}]}
{"channel":"book","type":"update","data":[{"symbol":"BTC/USD","bids":[],"asks":[{"price":67631.8,"qty":0.73750000}],"checksum":2488023551,"timestamp":"2024-06-01T17:52:31.011733Z"}]}
{"channel":"book","type":"update","data":[{"symbol":"BTC/USD","bids":[],"asks":[{"price":67631.8,"qty":1.07500000}],"checksum":2424476564,"timestamp":"2024-06-01T17:52:31.014132Z"}]}
{"channel":"book","type":"update","data":[{"symbol":"BTC/USD","bids":[],"asks":[{"price":67648.8,"qty":0.00000000},{"price":67649.1,"qty":0.73083685}],"checksum":3329556707,"timestamp":"2024-06-01T17:52:31.018022Z"}]}
{"channel":"book","type":"update","data":[{"symbol":"BTC/USD","bids":[{"price":67630.9,"qty":0.00000000},{"price":67622.0,"qty":1.47880837}],"asks":[],"checksum":1048424031,"timestamp":"2024-06-01T17:52:31.018069Z"}]}
{"channel":"book","type":"update","data":[{"symbol":"BTC/USD","bids":[],"asks":[{"price":67631.8,"qty":1.14410000}],"checksum":3535672629,"timestamp":"2024-06-01T17:52:31.029396Z"}]}
{"channel":"book","type":"update","data":[{"symbol":"BTC/USD","bids":[],"asks":[{"price":67648.7,"qty":0.29580000},{"price":67649.0,"qty":0.00029510}],"checksum":1648116937,"timestamp":"2024-06-01T17:52:31.029606Z"}]}
{"channel":"book","type":"update","data":[{"symbol":"BTC/USD","bids":[{"price":67631.7,"qty":4.86169040}],"asks":[],"checksum":3115777360,"timestamp":"2024-06-01T17:52:31.037772Z"}]}
{"channel":"book","type":"update","data":[{"symbol":"BTC/USD","bids":[{"price":67627.9,"qty":0.00000000},{"price":67621.1,"qty":0.00120940}],"asks":[],"checksum":4209516965,"timestamp":"2024-06-01T17:52:31.038789Z"}]}
{"channel":"book","type":"update","data":[{"symbol":"BTC/USD","bids":[],"asks":[{"price":67632.1,"qty":1.47858967}],"checksum":382312493,"timestamp":"2024-06-01T17:52:31.044417Z"}]}
{"channel":"book","type":"update","data":[{"symbol":"BTC/USD","bids":[],"asks":[{"price":67631.8,"qty":1.07500000}],"checksum":1432820173,"timestamp":"2024-06-01T17:52:31.049435Z"}]}
{"channel":"book","type":"update","data":[{"symbol":"BTC/USD","bids":[],"asks":[{"price":67631.8,"qty":1.37500000}],"checksum":3493739492,"timestamp":"2024-06-01T17:52:31.049649Z"}]}
{"channel":"book","type":"update","data":[{"symbol":"BTC/USD","bids":[],"asks":[{"price":67631.8,"qty":1.57500000}],"checksum":33389047,"timestamp":"2024-06-01T17:52:31.050436Z"}]}
{"channel":"book","type":"update","data":[{"symbol":"BTC/USD","bids":[{"price":67631.7,"qty":4.56169040}],"asks":[],"checksum":852906176,"timestamp":"2024-06-01T17:52:31.050528Z"}]}
{"channel":"book","type":"update","data":[{"symbol":"BTC/USD","bids":[{"price":67631.7,"qty":4.53211847}],"asks":[],"checksum":3099883874,"timestamp":"2024-06-01T17:52:31.051432Z"}]}
{"channel":"book","type":"update","data":[{"symbol":"BTC/USD","bids":[],"asks":[{"price":67642.3,"qty":0.00000000},{"price":67649.0,"qty":0.00029510},{"price":67631.8,"qty":1.60457188}],"checksum":3550129186,"timestamp":"2024-06-01T17:52:31.051682Z"}]}
{"channel":"book","type":"update","data":[{"symbol":"BTC/USD","bids":[{"price":67631.7,"qty":4.36518800}],"asks":[],"checksum":124006871,"timestamp":"2024-06-01T17:52:31.051830Z"}]}
{"channel":"book","type":"update","data":[{"symbol":"BTC/USD","bids":[{"price":67626.1,"qty":0.00000000},{"price":67620.7,"qty":0.17734900}],"asks":[],"checksum":2775821036,"timestamp":"2024-06-01T17:52:31.052614Z"}]}
{"channel":"book","type":"update","data":[{"symbol":"BTC/USD","bids":[{"price":67620.7,"qty":0.00000000},{"price":67617.8,"qty":1.47889992}],"asks":[],"checksum":3821626861,"timestamp":"2024-06-01T17:52:31.054714Z"}]}
{"channel":"book","type":"update","data":[{"symbol":"BTC/USD","bids":[],"asks":[{"price":67631.8,"qty":1.90457188}],"checksum":3062557273,"timestamp":"2024-06-01T17:52:31.055552Z"}]}
{"channel":"book","type":"update","data":[{"symbol":"BTC/USD","bids":[],"asks":[{"price":67632.1,"qty":0.00000000},{"price":67649.1,"qty":0.73083685}],"checksum":3507722411,"timestamp":"2024-06-01T17:52:31.056001Z"}]}
{"channel":"book","type":"update","data":[{"symbol":"BTC/USD","bids":[{"price":67622.0,"qty":0.00000000},{"price":67616.5,"qty":1.20000000}],"asks":[],"checksum":1224410085,"timestamp":"2024-06-01T17:52:31.056525Z"}]}
{"channel":"book","type":"update","data":[{"symbol":"BTC/USD","bids":[],"asks":[{"price":67647.0,"qty":0.18040000}],"checksum":3428370289,"timestamp":"2024-06-01T17:52:31.057024Z"}]}
{"channel":"book","type":"update","data":[{"symbol":"BTC/USD","bids":[{"price":67617.8,"qty":0.00000000},{"price":67616.4,"qty":0.02530277}],"asks":[],"checksum":1191013523,"timestamp":"2024-06-01T17:52:31.060839Z"}]}
{"channel":"book","type":"update","data":[{"symbol":"BTC/USD","bids":[],"asks":[{"price":67631.8,"qty":1.97367188}],"checksum":2648629097,"timestamp":"2024-06-01T17:52:31.062146Z"}]}
{"channel":"book","type":"update","data":[{"symbol":"BTC/USD","bids":[{"price":67631.7,"qty":4.55367800}],"asks":[],"checksum":235311485,"timestamp":"2024-06-01T17:52:31.063359Z"}]}
{"channel":"book","type":"update","data":[{"symbol":"BTC/USD","bids":[{"price":67631.7,"qty":4.72060800}],"asks":[],"checksum":2876398731,"timestamp":"2024-06-01T17:52:31.064200Z"}]}
{"channel":"book","type":"update","data":[{"symbol":"BTC/USD","bids":[{"price":67631.7,"qty":5.02060800}],"asks":[],"checksum":3434636997,"timestamp":"2024-06-01T17:52:31.064653Z"}]}
{"channel":"book","type":"update","data":[{"symbol":"BTC/USD","bids":[{"price":67631.7,"qty":4.83211800}],"asks":[],"checksum":935743858,"timestamp":"2024-06-01T17:52:31.068455Z"}]}
{"channel":"book","type":"update","data":[{"symbol":"BTC/USD","bids":[{"price":67631.7,"qty":4.53211800}],"asks":[],"checksum":28090954,"timestamp":"2024-06-01T17:52:31.070838Z"}]}
{"channel":"book","type":"update","data":[{"symbol":"BTC/USD","bids":[],"asks":[{"price":67642.5,"qty":0.06246000}],"checksum":1936754906,"timestamp":"2024-06-01T17:52:31.071739Z"}]}
{"channel":"book","type":"update","data":[{"symbol":"BTC/USD","bids":[{"price":67631.7,"qty":4.51399800}],"asks":[],"checksum":1472027457,"timestamp":"2024-06-01T17:52:31.071814Z"}]}
{"channel":"book","type":"update","data":[{"symbol":"BTC/USD","bids":[{"price":67631.7,"qty":4.34706800}],"asks":[],"checksum":714301149,"timestamp":"2024-06-01T17:52:31.071851Z"}]}
{"channel":"book","type":"update","data":[{"symbol":"BTC/USD","bids":[{"price":67631.7,"qty":3.01673844}],"asks":[],"checksum":3646888867,"timestamp":"2024-06-01T17:52:31.074747Z"}]}
{"channel":"book","type":"update","data":[{"symbol":"BTC/USD","bids":[],"asks":[{"price":67631.8,"qty":2.01314686}],"checksum":881513783,"timestamp":"2024-06-01T17:52:31.077015Z"}]}
{"channel":"book","type":"update","data":[{"symbol":"BTC/USD","bids":[{"price":67631.7,"qty":2.70573844}],"asks":[],"checksum":625935144,"timestamp":"2024-06-01T17:52:31.079178Z"}]}
{"channel":"book","type":"update","data":[{"symbol":"BTC/USD","bids":[{"price":67622.0,"qty":1.47880738}],"asks":[],"checksum":2918226944,"timestamp":"2024-06-01T17:52:31.080479Z"}]}
{"channel":"book","type":"update","data":[{"symbol":"BTC/USD","bids":[],"asks":[{"price":67631.8,"qty":3.49174124}],"checksum":3552425256,"timestamp":"2024-06-01T17:52:31.080546Z"}]}
{"channel":"book","type":"update","data":[{"symbol":"BTC/USD","bids":[],"asks":[{"price":67631.8,"qty":3.19174124}],"checksum":2542446302,"timestamp":"2024-06-01T17:52:31.083124Z"}]}
{"channel":"book","type":"update","data":[{"symbol":"BTC/USD","bids":[],"asks":[{"price":67631.8,"qty":2.99174124}],"checksum":1261486409,"timestamp":"2024-06-01T17:52:31.083474Z"}]}
{"channel":"book","type":"update","data":[{"symbol":"BTC/USD","bids":[],"asks":[{"price":67644.3,"qty":0.00000000},{"price":67649.0,"qty":0.00029510}],"checksum":3195339864,"timestamp":"2024-06-01T17:52:31.086504Z"}]}
{"channel":"book","type":"update","data":[{"symbol":"BTC/USD","bids":[{"price":67622.0,"qty":0.00000000},{"price":67616.4,"qty":0.02530277}],"asks":[],"checksum":1189359150,"timestamp":"2024-06-01T17:52:31.087387Z"}]}
{"channel":"book","type":"update","data":[{"symbol":"BTC/USD","bids":[],"asks":[{"price":67631.8,"qty":3.29174124}],"checksum":2253457927,"timestamp":"2024-06-01T17:52:31.088285Z"}]}
{"channel":"book","type":"update","data":[{"symbol":"BTC/USD","bids":[],"asks":[{"price":67631.8,"qty":3.37004124}],"checksum":3955353014,"timestamp":"2024-06-01T17:52:31.088440Z"}]}
{"channel":"book","type":"update","data":[{"symbol":"BTC/USD","bids":[],"asks":[{"price":67631.8,"qty":3.68204124}],"checksum":1201055855,"timestamp":"2024-06-01T17:52:31.090927Z"}]}
{"channel":"book","type":"update","data":[{"symbol":"BTC/USD","bids":[],"asks":[{"price":67631.8,"qty":3.88204124}],"checksum":2325872231,"timestamp":"2024-06-01T17:52:31.092182Z"}]}
{"channel":"book","type":"update","data":[{"symbol":"BTC/USD","bids":[{"price":67617.9,"qty":1.47889712}],"asks":[],"checksum":4164882661,"timestamp":"2024-06-01T17:52:31.095014Z"}]}
{"channel":"book","type":"update","data":[{"symbol":"BTC/USD","bids":[],"asks":[{"price":67635.8,"qty":0.00000000},{"price":67649.1,"qty":0.73083685}],"checksum":154184479,"timestamp":"2024-06-01T17:52:31.101118Z"}]}
{"channel":"book","type":"update","data":[{"symbol":"BTC/USD","bids":[{"price":67631.7,"qty":2.70176844}],"asks":[],"checksum":1660755540,"timestamp":"2024-06-01T17:52:31.102138Z"}]}
{"channel":"book","type":"update","data":[{"symbol":"BTC/USD","bids":[],"asks":[{"price":67637.1,"qty":1.47847937}],"checksum":644078322,"timestamp":"2024-06-01T17:52:31.102252Z"}]}
{"channel":"book","type":"update","data":[{"symbol":"BTC/USD","bids":[{"price":67617.9,"qty":0.00000000},{"price":67614.6,"qty":0.05912737}],"asks":[],"checksum":176576867,"timestamp":"2024-06-01T17:52:31.107328Z"}]}
{"channel":"book","type":"update","data":[{"symbol":"BTC/USD","bids":[],"asks":[{"price":67631.8,"qty":4.19304124}],"checksum":3569258890,"timestamp":"2024-06-01T17:52:31.108253Z"}]}
{"channel":"book","type":"update","data":[{"symbol":"BTC/USD","bids":[],"asks":[{"price":67631.8,"qty":3.85554124}],"checksum":1453495010,"timestamp":"2024-06-01T17:52:31.108666Z"}]}
{"channel":"book","type":"update","data":[{"symbol":"BTC/USD","bids":[],"asks":[{"price":67631.8,"qty":3.51804124}],"checksum":30503685,"timestamp":"2024-06-01T17:52:31.114613Z"}]}
{"channel":"book","type":"update","data":[{"symbol":"BTC/USD","bids":[],"asks":[{"price":67631.8,"qty":3.85554124}],"checksum":1453495010,"timestamp":"2024-06-01T17:52:31.123776Z"}]}
{"channel":"book","type":"update","data":[{"symbol":"BTC/USD","bids":[],"asks":[{"price":67631.8,"qty":4.18954124}],"checksum":4212369961,"timestamp":"2024-06-01T17:52:31.124580Z"}]}
{"channel":"book","type":"update","data":[{"symbol":"BTC/USD","bids":[],"asks":[{"price":67631.8,"qty":3.88954124}],"checksum":3113043836,"timestamp":"2024-06-01T17:52:31.125304Z"}]}
{"channel":"book","type":"update","data":[{"symbol":"BTC/USD","bids":[],"asks":[{"price":67631.8,"qty":4.22704124}],"checksum":521714637,"timestamp":"2024-06-01T17:52:31.125835Z"}]}
{"channel":"book","type":"update","data":[{"symbol":"BTC/USD","bids":[],"asks":[{"price":67634.3,"qty":0.00460867}],"checksum":1586390150,"timestamp":"2024-06-01T17:52:31.128591Z"}]}
{"channel":"book","type":"update","data":[{"symbol":"BTC/USD","bids":[{"price":67623.2,"qty":0.00000000},{"price":67612.8,"qty":0.06107546}],"asks":[],"checksum":758129286,"timestamp":"2024-06-01T17:52:31.130748Z"}]}
{"channel":"book","type":"update","data":[{"symbol":"BTC/USD","bids":[{"price":67622.6,"qty":1.47879453}],"asks":[],"checksum":1393299533,"timestamp":"2024-06-01T17:52:31.131753Z"}]}
{"channel":"book","type":"update","data":[{"symbol":"BTC/USD","bids":[{"price":67622.6,"qty":0.00000000},{"price":67612.8,"qty":0.06107546}],"asks":[],"checksum":758129286,"timestamp":"2024-06-01T17:52:31.137584Z"}]}
{"channel":"book","type":"update","data":[{"symbol":"BTC/USD","bids":[],"asks":[{"price":67634.5,"qty":1.47853752}],"checksum":1510750023,"timestamp":"2024-06-01T17:52:31.143887Z"}]}
{"channel":"book","type":"update","data":[{"symbol":"BTC/USD","bids":[],"asks":[{"price":67631.8,"qty":4.65704124}],"checksum":1129769672,"timestamp":"2024-06-01T17:52:31.151785Z"}]}
{"channel":"book","type":"update","data":[{"symbol":"BTC/USD","bids":[],"asks":[{"price":67631.8,"qty":4.95704124}],"checksum":370500988,"timestamp":"2024-06-01T17:52:31.153581Z"}]}
{"channel":"book","type":"update","data":[{"symbol":"BTC/USD","bids":[],"asks":[{"price":67631.8,"qty":4.61954124}],"checksum":3205625698,"timestamp":"2024-06-01T17:52:31.159162Z"}]}
{"channel":"book","type":"update","data":[{"symbol":"BTC/USD","bids":[],"asks":[{"price":67631.8,"qty":4.28204124}],"checksum":1629593592,"timestamp":"2024-06-01T17:52:31.159285Z"}]}
{"channel":"book","type":"update","data":[{"symbol":"BTC/USD","bids":[],"asks":[{"price":67635.0,"qty":0.06910000}],"checksum":2886149231,"timestamp":"2024-06-01T17:52:31.161813Z"}]}
{"channel":"book","type":"update","data":[{"symbol":"BTC/USD","bids":[],"asks":[{"price":67635.0,"qty":0.20730000}],"checksum":3246587681,"timestamp":"2024-06-01T17:52:31.163488Z"}]}
{"channel":"book","type":"update","data":[{"symbol":"BTC/USD","bids":[{"price":67625.9,"qty":0.12011500}],"asks":[],"checksum":9599681,"timestamp":"2024-06-01T17:52:31.166338Z"}]}
{"channel":"book","type":"update","data":[{"symbol":"BTC/USD","bids":[],"asks":[{"price":67635.0,"qty":0.06910000}],"checksum":2442892173,"timestamp":"2024-06-01T17:52:31.168724Z"}]}
{"channel":"book","type":"update","data":[{"symbol":"BTC/USD","bids":[],"asks":[{"price":67631.8,"qty":4.61954124}],"checksum":1336670999,"timestamp":"2024-06-01T17:52:31.171047Z"}]}
{"channel":"book","type":"update","data":[{"symbol":"BTC/USD","bids":[],"asks":[{"price":67635.0,"qty":0.00000000},{"price":67647.0,"qty":0.18040000}],"checksum":4013554147,"timestamp":"2024-06-01T17:52:31.171841Z"}]}
{"channel":"book","type":"update","data":[{"symbol":"BTC/USD","bids":[],"asks":[{"price":67631.8,"qty":4.95704124}],"checksum":362790930,"timestamp":"2024-06-01T17:52:31.173270Z"}]}
{"channel":"book","type":"update","data":[{"symbol":"BTC/USD","bids":[],"asks":[{"price":67631.8,"qty":4.61954124}],"checksum":4013554147,"timestamp":"2024-06-01T17:52:31.177804Z"}]}
{"channel":"book","type":"update","data":[{"symbol":"BTC/USD","bids":[],"asks":[{"price":67631.8,"qty":4.28204124}],"checksum":4282233809,"timestamp":"2024-06-01T17:52:31.178371Z"}]}
{"channel":"book","type":"update","data":[{"symbol":"BTC/USD","bids":[{"price":67622.1,"qty":1.47880515}],"asks":[],"checksum":1704891571,"timestamp":"2024-06-01T17:52:31.181154Z"}]}
{"channel":"book","type":"update","data":[{"symbol":"BTC/USD","bids":[{"price":67622.1,"qty":0.00000000},{"price":67614.6,"qty":0.05912737}],"asks":[],"checksum":4282233809,"timestamp":"2024-06-01T17:52:31.200365Z"}]}
{"channel":"book","type":"update","data":[{"symbol":"BTC/USD","bids":[],"asks":[{"price":67634.5,"qty":0.00000000},{"price":67648.7,"qty":0.29580000}],"checksum":1944147688,"timestamp":"2024-06-01T17:52:31.204902Z"}]}
{"channel":"book","type":"update","data":[{"symbol":"BTC/USD","bids":[],"asks":[{"price":67635.0,"qty":0.06910000},{"price":67635.0,"qty":0.20730000}],"checksum":4024661016,"timestamp":"2024-06-01T17:52:31.206050Z"}]}
{"channel":"book","type":"update","data":[{"symbol":"BTC/USD","bids":[],"asks":[{"price":67631.8,"qty":4.61954124}],"checksum":835918978,"timestamp":"2024-06-01T17:52:31.212676Z"}]}
{"channel":"book","type":"update","data":[{"symbol":"BTC/USD","bids":[],"asks":[{"price":67631.8,"qty":4.95704124}],"checksum":2564263580,"timestamp":"2024-06-01T17:52:31.212690Z"}]}
{"channel":"book","type":"update","data":[{"symbol":"BTC/USD","bids":[],"asks":[{"price":67631.8,"qty":4.61954124}],"checksum":835918978,"timestamp":"2024-06-01T17:52:31.216906Z"}]}
{"channel":"book","type":"update","data":[{"symbol":"BTC/USD","bids":[],"asks":[{"price":67631.8,"qty":4.28204124}],"checksum":4024661016,"timestamp":"2024-06-01T17:52:31.216963Z"}]}
{"channel":"book","type":"update","data":[{"symbol":"BTC/USD","bids":[{"price":67616.0,"qty":1.47893889}],"asks":[],"checksum":965510856,"timestamp":"2024-06-01T17:52:31.232917Z"}]}
{"channel":"book","type":"update","data":[{"symbol":"BTC/USD","bids":[],"asks":[{"price":67631.8,"qty":4.61954124}],"checksum":4048278274,"timestamp":"2024-06-01T17:52:31.238050Z"}]}
{"channel":"book","type":"update","data":[{"symbol":"BTC/USD","bids":[],"asks":[{"price":67631.8,"qty":4.95704124}],"checksum":990623665,"timestamp":"2024-06-01T17:52:31.238695Z"}]}
{"channel":"book","type":"update","data":[{"symbol":"BTC/USD","bids":[],"asks":[{"price":67631.8,"qty":5.25704124}],"checksum":3504679192,"timestamp":"2024-06-01T17:52:31.245007Z"}]}
{"channel":"book","type":"update","data":[{"symbol":"BTC/USD","bids":[{"price":67631.7,"qty":0.58176844}],"asks":[],"checksum":3684749371,"timestamp":"2024-06-01T17:52:31.252059Z"}]}
{"channel":"book","type":"update","data":[{"symbol":"BTC/USD","bids":[{"price":67616.0,"qty":0.00000000},{"price":67614.6,"qty":0.05912737}],"asks":[],"checksum":2805938577,"timestamp":"2024-06-01T17:52:31.254116Z"}]}
{"channel":"book","type":"update","data":[{"symbol":"BTC/USD","bids":[],"asks":[{"price":67639.0,"qty":0.18040000}],"checksum":2826449450,"timestamp":"2024-06-01T17:52:31.258859Z"}]}
{"channel":"book","type":"update","data":[{"symbol":"BTC/USD","bids":[],"asks":[{"price":67631.8,"qty":4.91954124}],"checksum":782786558,"timestamp":"2024-06-01T17:52:31.262897Z"}]}
{"channel":"book","type":"update","data":[{"symbol":"BTC/USD","bids":[],"asks":[{"price":67631.8,"qty":5.25704124}],"checksum":2826449450,"timestamp":"2024-06-01T17:52:31.269458Z"}]}
{"channel":"book","type":"update","data":[{"symbol":"BTC/USD","bids":[{"price":67631.7,"qty":0.00100000}],"asks":[],"checksum":3035125517,"timestamp":"2024-06-01T17:52:31.274461Z"}]}
{"channel":"book","type":"update","data":[{"symbol":"BTC/USD","bids":[{"price":67624.4,"qty":0.43124616}],"asks":[],"checksum":876166304,"timestamp":"2024-06-01T17:52:31.279293Z"}]}
{"channel":"book","type":"update","data":[{"symbol":"BTC/USD","bids":[{"price":67616.8,"qty":1.47892100}],"asks":[],"checksum":2290598585,"timestamp":"2024-06-01T17:52:31.283027Z"}]}
{"channel":"book","type":"update","data":[{"symbol":"BTC/USD","bids":[],"asks":[{"price":67631.8,"qty":6.73563562}],"checksum":3256587314,"timestamp":"2024-06-01T17:52:31.283142Z"}]}
{"channel":"book","type":"update","data":[{"symbol":"BTC/USD","bids":[],"asks":[{"price":67639.5,"qty":0.05912278}],"checksum":2388435359,"timestamp":"2024-06-01T17:52:31.289398Z"}]}
{"channel":"book","type":"update","data":[{"symbol":"BTC/USD","bids":[{"price":67624.4,"qty":0.00000000},{"price":67616.5,"qty":1.20000000}],"asks":[],"checksum":1808962938,"timestamp":"2024-06-01T17:52:31.301395Z"}]}
{"channel":"book","type":"update","data":[{"symbol":"BTC/USD","bids":[],"asks":[{"price":67631.8,"qty":6.39813562}],"checksum":2098406623,"timestamp":"2024-06-01T17:52:31.317067Z"}]}
{"channel":"book","type":"update","data":[{"symbol":"BTC/USD","bids":[],"asks":[{"price":67631.8,"qty":6.06063562}],"checksum":3440899338,"timestamp":"2024-06-01T17:52:31.319420Z"}]}
{"channel":"book","type":"update","data":[{"symbol":"BTC/USD","bids":[],"asks":[{"price":67631.8,"qty":5.99153562}],"checksum":4238361187,"timestamp":"2024-06-01T17:52:31.328522Z"}]}
{"channel":"book","type":"update","data":[{"symbol":"BTC/USD","bids":[],"asks":[{"price":67635.0,"qty":0.13820000}],"checksum":2161469938,"timestamp":"2024-06-01T17:52:31.331631Z"}]}
{"channel":"book","type":"update","data":[{"symbol":"BTC/USD","bids":[],"asks":[{"price":67635.0,"qty":0.00000000},{"price":67642.5,"qty":0.06246000}],"checksum":2603205242,"timestamp":"2024-06-01T17:52:31.331818Z"}]}
{"channel":"book","type":"update","data":[{"symbol":"BTC/USD","bids":[{"price":67616.8,"qty":0.00000000},{"price":67614.6,"qty":0.05912737}],"asks":[],"checksum":3385831262,"timestamp":"2024-06-01T17:52:31.335412Z"}]}
{"channel":"book","type":"update","data":[{"symbol":"BTC/USD","bids":[{"price":67617.5,"qty":1.47890699}],"asks":[],"checksum":660515641,"timestamp":"2024-06-01T17:52:31.340060Z"}]}
{"channel":"book","type":"update","data":[{"symbol":"BTC/USD","bids":[{"price":67625.9,"qty":0.00000000},{"price":67614.6,"qty":0.05912737}],"asks":[],"checksum":2296487948,"timestamp":"2024-06-01T17:52:31.353606Z"}]}
{"channel":"book","type":"update","data":[{"symbol":"BTC/USD","bids":[{"price":67617.5,"qty":0.00000000},{"price":67612.8,"qty":0.02957193}],"asks":[],"checksum":2185686338,"timestamp":"2024-06-01T17:52:31.378022Z"}]}
{"channel":"book","type":"update","data":[{"symbol":"BTC/USD","bids":[{"price":67616.5,"qty":0.00000000},{"price":67612.0,"qty":0.33750000}],"asks":[],"checksum":604314347,"timestamp":"2024-06-01T17:52:31.382473Z"}]}
{"channel":"book","type":"update","data":[{"symbol":"BTC/USD","bids":[{"price":67617.6,"qty":1.47890439}],"asks":[],"checksum":1593092094,"timestamp":"2024-06-01T17:52:31.395426Z"}]}
{"channel":"book","type":"update","data":[{"symbol":"BTC/USD","bids":[{"price":67614.0,"qty":0.06910000}],"asks":[],"checksum":723189615,"timestamp":"2024-06-01T17:52:31.404250Z"}]}
{"channel":"book","type":"update","data":[{"symbol":"BTC/USD","bids":[],"asks":[{"price":67634.3,"qty":0.00000000},{"price":67647.6,"qty":0.02634244}],"checksum":3077885197,"timestamp":"2024-06-01T17:52:31.413430Z"}]}
{"channel":"book","type":"update","data":[{"symbol":"BTC/USD","bids":[{"price":67622.9,"qty":0.43125572}],"asks":[],"checksum":2994019420,"timestamp":"2024-06-01T17:52:31.422334Z"}]}
{"channel":"book","type":"update","data":[{"symbol":"BTC/USD","bids":[{"price":67617.6,"qty":0.00000000},{"price":67612.8,"qty":0.02957193}],"asks":[],"checksum":3117799422,"timestamp":"2024-06-01T17:52:31.448663Z"}]}
{"channel":"book","type":"update","data":[{"symbol":"BTC/USD","bids":[{"price":67623.2,"qty":0.12011500}],"asks":[],"checksum":1834404583,"timestamp":"2024-06-01T17:52:31.452217Z"}]}
{"channel":"book","type":"update","data":[{"symbol":"BTC/USD","bids":[{"price":67618.0,"qty":1.47889579}],"asks":[],"checksum":161090250,"timestamp":"2024-06-01T17:52:31.452287Z"}]}
{"channel":"book","type":"update","data":[{"symbol":"BTC/USD","bids":[],"asks":[{"price":67632.0,"qty":1.47859154}],"checksum":537947134,"timestamp":"2024-06-01T17:52:31.452398Z"}]}
{"channel":"book","type":"update","data":[{"symbol":"BTC/USD","bids":[],"asks":[{"price":67631.8,"qty":6.06063562},{"price":67635.0,"qty":0.06910000},{"price":67635.0,"qty":0.20730000}],"checksum":247637444,"timestamp":"2024-06-01T17:52:31.466964Z"}]}
{"channel":"book","type":"update","data":[{"symbol":"BTC/USD","bids":[],"asks":[{"price":67638.0,"qty":0.00000000},{"price":67642.5,"qty":0.06246000},{"price":67631.8,"qty":6.06073562}],"checksum":3124645662,"timestamp":"2024-06-01T17:52:31.468145Z"}]}
