{"channel":"book","type":"update","data":[{"symbol":"BTC/USDT","bids":[],"asks":[{"price":67690.3,"qty":0.09000000}],"checksum":737114599,"timestamp":"2024-06-01T17:52:18.561114Z"}]}
{"channel":"book","type":"update","data":[{"symbol":"BTC/USDT","bids":[{"price":67684.7,"qty":0.15000000}],"asks":[],"checksum":3670835022,"timestamp":"2024-06-01T17:52:18.562833Z"}]}
{"channel":"book","type":"update","data":[{"symbol":"BTC/USDT","bids":[{"price":67684.6,"qty":0.05000000}],"asks":[],"checksum":675153772,"timestamp":"2024-06-01T17:52:18.563355Z"}]}
{"channel":"book","type":"update","data":[{"symbol":"BTC/USDT","bids":[{"price":67685.1,"qty":0.04405954}],"asks":[],"checksum":3770311135,"timestamp":"2024-06-01T17:52:18.563568Z"}]}
{"channel":"book","type":"update","data":[{"symbol":"BTC/USDT","bids":[{"price":67683.6,"qty":0.00000000},{"price":67676.3,"qty":0.05329134}],"asks":[],"checksum":137272405,"timestamp":"2024-06-01T17:52:18.563680Z"}]}
{"channel":"book","type":"update","data":[{"symbol":"BTC/USDT","bids":[{"price":67685.1,"qty":0.09405954}],"asks":[],"checksum":990229858,"timestamp":"2024-06-01T17:52:18.563708Z"}]}
{"channel":"book","type":"update","data":[{"symbol":"BTC/USDT","bids":[{"price":67685.0,"qty":0.00000000},{"price":67676.2,"qty":1.60140704}],"asks":[],"checksum":3017955780,"timestamp":"2024-06-01T17:52:18.566159Z"}]}
{"channel":"book","type":"update","data":[{"symbol":"BTC/USDT","bids":[{"price":67685.9,"qty":0.04290000}],"asks":[],"checksum":2822739549,"timestamp":"2024-06-01T17:52:18.566257Z"}]}
{"channel":"book","type":"update","data":[{"symbol":"BTC/USDT","bids":[{"price":67684.6,"qty":0.00000000},{"price":67676.2,"qty":1.60140704}],"asks":[],"checksum":2977788194,"timestamp":"2024-06-01T17:52:18.584918Z"}]}
{"channel":"book","type":"update","data":[{"symbol":"BTC/USDT","bids":[{"price":67686.0,"qty":0.05000000}],"asks":[],"checksum":1530026164,"timestamp":"2024-06-01T17:52:18.585035Z"}]}
{"channel":"book","type":"update","data":[{"symbol":"BTC/USDT","bids":[{"price":67685.9,"qty":0.00000000},{"price":67676.2,"qty":1.60140704}],"asks":[],"checksum":2533969866,"timestamp":"2024-06-01T17:52:18.587898Z"}]}
{"channel":"book","type":"update","data":[{"symbol":"BTC/USDT","bids":[{"price":67686.2,"qty":0.04290000}],"asks":[],"checksum":2703701553,"timestamp":"2024-06-01T17:52:18.588031Z"}]}
{"channel":"book","type":"update","data":[{"symbol":"BTC/USDT","bids":[{"price":67685.1,"qty":0.05000000}],"asks":[],"checksum":1958053293,"timestamp":"2024-06-01T17:52:18.594073Z"}]}
{"channel":"book","type":"update","data":[{"symbol":"BTC/USDT","bids":[{"price":67686.3,"qty":0.04405954}],"asks":[],"checksum":3283366826,"timestamp":"2024-06-01T17:52:18.594198Z"}]}
{"channel":"book","type":"update","data":[{"symbol":"BTC/USDT","bids":[{"price":67685.2,"qty":0.15000000}],"asks":[],"checksum":4103392768,"timestamp":"2024-06-01T17:52:18.594246Z"}]}
{"channel":"book","type":"update","data":[{"symbol":"BTC/USDT","bids":[{"price":67685.1,"qty":0.00000000},{"price":67676.4,"qty":0.00198081}],"asks":[],"checksum":596164137,"timestamp":"2024-06-01T17:52:18.594279Z"}]}
{"channel":"book","type":"update","data":[{"symbol":"BTC/USDT","bids":[{"price":67684.7,"qty":0.00000000},{"price":67676.3,"qty":0.05329134}],"asks":[],"checksum":2956339376,"timestamp":"2024-06-01T17:52:18.594294Z"}]}
{"channel":"book","type":"update","data":[{"symbol":"BTC/USDT","bids":[{"price":67686.3,"qty":0.09405954}],"asks":[],"checksum":2199716231,"timestamp":"2024-06-01T17:52:18.594366Z"}]}
{"channel":"book","type":"update","data":[{"symbol":"BTC/USDT","bids":[],"asks":[{"price":67690.3,"qty":0.00000000},{"price":67702.1,"qty":0.19890820}],"checksum":3638168188,"timestamp":"2024-06-01T17:52:18.631962Z"}]}
{"channel":"book","type":"update","data":[{"symbol":"BTC/USDT","bids":[{"price":67686.0,"qty":0.00000000},{"price":67676.2,"qty":1.60140704}],"asks":[],"checksum":3484582960,"timestamp":"2024-06-01T17:52:18.636477Z"}]}
{"channel":"book","type":"update","data":[{"symbol":"BTC/USDT","bids":[{"price":67685.2,"qty":0.00000000},{"price":67676.1,"qty":0.17872429}],"asks":[],"checksum":3143713227,"timestamp":"2024-06-01T17:52:18.636565Z"}]}
{"channel":"book","type":"update","data":[{"symbol":"BTC/USDT","bids":[{"price":67679.5,"qty":0.00000000},{"price":67676.0,"qty":0.00460867}],"asks":[],"checksum":1432911061,"timestamp":"2024-06-01T17:52:18.638359Z"}]}
{"channel":"book","type":"update","data":[{"symbol":"BTC/USDT","bids":[{"price":67686.2,"qty":0.00000000},{"price":67671.4,"qty":0.09000000}],"asks":[],"checksum":4183391920,"timestamp":"2024-06-01T17:52:18.639341Z"}]}
{"channel":"book","type":"update","data":[{"symbol":"BTC/USDT","bids":[{"price":67676.4,"qty":0.45686747}],"asks":[],"checksum":1336902581,"timestamp":"2024-06-01T17:52:18.671174Z"}]}
{"channel":"book","type":"update","data":[{"symbol":"BTC/USDT","bids":[{"price":67686.4,"qty":0.00092896}],"asks":[],"checksum":1430732940,"timestamp":"2024-06-01T17:52:18.760964Z"}]}
{"channel":"book","type":"update","data":[{"symbol":"BTC/USDT","bids":[],"asks":[{"price":67690.2,"qty":0.00000000},{"price":67708.1,"qty":0.00460867},{"price":67690.0,"qty":0.05328716}],"checksum":4068832515,"timestamp":"2024-06-01T17:52:19.128670Z"}]}
{"channel":"book","type":"update","data":[{"symbol":"BTC/USDT","bids":[{"price":67676.3,"qty":0.00000000},{"price":67671.4,"qty":0.09000000},{"price":67676.5,"qty":0.05329116}],"asks":[],"checksum":3990898846,"timestamp":"2024-06-01T17:52:19.128695Z"}]}
{"channel":"book","type":"update","data":[{"symbol":"BTC/USDT","bids":[],"asks":[{"price":67689.9,"qty":0.03947498}],"checksum":1772751944,"timestamp":"2024-06-01T17:52:19.133410Z"}]}
{"channel":"book","type":"update","data":[{"symbol":"BTC/USDT","bids":[{"price":67686.4,"qty":0.02792896}],"asks":[],"checksum":4145612790,"timestamp":"2024-06-01T17:52:19.368636Z"}]}
{"channel":"book","type":"update","data":[{"symbol":"BTC/USDT","bids":[],"asks":[{"price":67690.1,"qty":0.00000000},{"price":67702.1,"qty":0.19890820}],"checksum":1201623300,"timestamp":"2024-06-01T17:52:19.372628Z"}]}
{"channel":"book","type":"update","data":[{"symbol":"BTC/USDT","bids":[{"price":67686.5,"qty":0.05000000}],"asks":[],"checksum":2325992480,"timestamp":"2024-06-01T17:52:19.373761Z"}]}
{"channel":"book","type":"update","data":[{"symbol":"BTC/USDT","bids":[{"price":67686.4,"qty":0.02700000},{"price":67686.6,"qty":0.00092896}],"asks":[],"checksum":516533779,"timestamp":"2024-06-01T17:52:19.401856Z"}]}
{"channel":"book","type":"update","data":[{"symbol":"BTC/USDT","bids":[{"price":67686.4,"qty":0.00000000},{"price":67676.1,"qty":0.17872429}],"asks":[],"checksum":1034973321,"timestamp":"2024-06-01T17:52:19.403666Z"}]}
{"channel":"book","type":"update","data":[{"symbol":"BTC/USDT","bids":[{"price":67686.3,"qty":0.04405954}],"asks":[],"checksum":1815462775,"timestamp":"2024-06-01T17:52:19.406736Z"}]}
{"channel":"book","type":"update","data":[{"symbol":"BTC/USDT","bids":[],"asks":[{"price":67690.0,"qty":0.00000000},{"price":67708.1,"qty":0.00460867},{"price":67690.6,"qty":0.05328715}],"checksum":2104060030,"timestamp":"2024-06-01T17:52:19.434109Z"}]}
{"channel":"book","type":"update","data":[{"symbol":"BTC/USDT","bids":[],"asks":[{"price":67689.9,"qty":0.00000000},{"price":67708.1,"qty":0.00460867}],"checksum":743437163,"timestamp":"2024-06-01T17:52:19.437928Z"}]}
{"channel":"book","type":"update","data":[{"symbol":"BTC/USDT","bids":[],"asks":[{"price":67708.1,"qty":0.00000000},{"price":67708.8,"qty":0.09847056}],"checksum":4241554820,"timestamp":"2024-06-01T17:52:19.438533Z"}]}
{"channel":"book","type":"update","data":[{"symbol":"BTC/USDT","bids":[{"price":67682.6,"qty":0.01774184}],"asks":[],"checksum":2582041472,"timestamp":"2024-06-01T17:52:19.478535Z"}]}
{"channel":"book","type":"update","data":[{"symbol":"BTC/USDT","bids":[],"asks":[{"price":67690.5,"qty":0.03947498}],"checksum":1612366551,"timestamp":"2024-06-01T17:52:19.482604Z"}]}
{"channel":"book","type":"update","data":[{"symbol":"BTC/USDT","bids":[{"price":67682.7,"qty":0.15000000}],"asks":[],"checksum":35131797,"timestamp":"2024-06-01T17:52:19.483207Z"}]}
{"channel":"book","type":"update","data":[{"symbol":"BTC/USDT","bids":[{"price":67682.6,"qty":0.00000000},{"price":67676.2,"qty":1.60140704}],"asks":[],"checksum":449415233,"timestamp":"2024-06-01T17:52:19.488187Z"}]}
{"channel":"book","type":"update","data":[{"symbol":"BTC/USDT","bids":[{"price":67682.8,"qty":0.01774185}],"asks":[],"checksum":4162370252,"timestamp":"2024-06-01T17:52:19.488355Z"}]}
{"channel":"book","type":"update","data":[{"symbol":"BTC/USDT","bids":[{"price":67682.7,"qty":0.00000000},{"price":67676.2,"qty":1.60140704}],"asks":[],"checksum":2333527416,"timestamp":"2024-06-01T17:52:19.711443Z"}]}
{"channel":"book","type":"update","data":[{"symbol":"BTC/USDT","bids":[{"price":67682.9,"qty":0.15000000}],"asks":[],"checksum":1400583934,"timestamp":"2024-06-01T17:52:19.711637Z"}]}
{"channel":"book","type":"update","data":[{"symbol":"BTC/USDT","bids":[{"price":67682.5,"qty":0.00000000},{"price":67676.2,"qty":1.60140704}],"asks":[],"checksum":3566735830,"timestamp":"2024-06-01T17:52:19.715868Z"}]}
{"channel":"book","type":"update","data":[{"symbol":"BTC/USDT","bids":[{"price":67682.8,"qty":0.00000000},{"price":67676.1,"qty":0.17872429}],"asks":[],"checksum":1988915692,"timestamp":"2024-06-01T17:52:19.716255Z"}]}
{"channel":"book","type":"update","data":[{"symbol":"BTC/USDT","bids":[{"price":67683.0,"qty":0.01774185}],"asks":[],"checksum":2630198695,"timestamp":"2024-06-01T17:52:19.716502Z"}]}
{"channel":"book","type":"update","data":[{"symbol":"BTC/USDT","bids":[{"price":67676.4,"qty":0.45488666}],"asks":[],"checksum":2038040059,"timestamp":"2024-06-01T17:52:19.794930Z"}]}
{"channel":"book","type":"update","data":[{"symbol":"BTC/USDT","bids":[{"price":67676.6,"qty":0.00167443}],"asks":[],"checksum":3283970901,"timestamp":"2024-06-01T17:52:19.799441Z"}]}
{"channel":"book","type":"update","data":[{"symbol":"BTC/USDT","bids":[],"asks":[{"price":67690.6,"qty":0.00000000},{"price":67708.8,"qty":0.09847056},{"price":67690.4,"qty":0.05328715}],"checksum":1381204150,"timestamp":"2024-06-01T17:52:19.920740Z"}]}
{"channel":"book","type":"update","data":[{"symbol":"BTC/USDT","bids":[],"asks":[{"price":67690.3,"qty":0.03947498}],"checksum":2019503421,"timestamp":"2024-06-01T17:52:19.925083Z"}]}
{"channel":"book","type":"update","data":[{"symbol":"BTC/USDT","bids":[{"price":67683.1,"qty":0.15000000}],"asks":[],"checksum":454118835,"timestamp":"2024-06-01T17:52:19.925695Z"}]}
{"channel":"book","type":"update","data":[{"symbol":"BTC/USDT","bids":[{"price":67686.5,"qty":0.00000000},{"price":67676.4,"qty":0.45488666}],"asks":[],"checksum":674902486,"timestamp":"2024-06-01T17:52:19.926232Z"}]}
{"channel":"book","type":"update","data":[{"symbol":"BTC/USDT","bids":[{"price":67686.4,"qty":0.05000000}],"asks":[],"checksum":1476830194,"timestamp":"2024-06-01T17:52:19.926402Z"}]}
{"channel":"book","type":"update","data":[{"symbol":"BTC/USDT","bids":[{"price":67683.0,"qty":0.00000000},{"price":67676.4,"qty":0.45488666}],"asks":[],"checksum":4185034689,"timestamp":"2024-06-01T17:52:19.930808Z"}]}
{"channel":"book","type":"update","data":[{"symbol":"BTC/USDT","bids":[{"price":67683.2,"qty":0.01774188}],"asks":[],"checksum":1750229803,"timestamp":"2024-06-01T17:52:19.931046Z"}]}
{"channel":"book","type":"update","data":[{"symbol":"BTC/USDT","bids":[],"asks":[{"price":67690.5,"qty":0.00000000},{"price":67702.1,"qty":0.19890820}],"checksum":2099113820,"timestamp":"2024-06-01T17:52:20.094217Z"}]}
{"channel":"book","type":"update","data":[{"symbol":"BTC/USDT","bids":[{"price":67683.3,"qty":0.15000000}],"asks":[],"checksum":1129110350,"timestamp":"2024-06-01T17:52:20.099342Z"}]}
{"channel":"book","type":"update","data":[{"symbol":"BTC/USDT","bids":[{"price":67683.1,"qty":0.00000000},{"price":67676.5,"qty":0.05329116}],"asks":[],"checksum":323571351,"timestamp":"2024-06-01T17:52:20.099489Z"}]}
{"channel":"book","type":"update","data":[{"symbol":"BTC/USDT","bids":[{"price":67683.2,"qty":0.00000000},{"price":67676.4,"qty":0.45488666}],"asks":[],"checksum":712592493,"timestamp":"2024-06-01T17:52:20.104033Z"}]}
{"channel":"book","type":"update","data":[{"symbol":"BTC/USDT","bids":[{"price":67683.4,"qty":0.01774186}],"asks":[],"checksum":511490080,"timestamp":"2024-06-01T17:52:20.104113Z"}]}
{"channel":"book","type":"update","data":[{"symbol":"BTC/USDT","bids":[],"asks":[{"price":67701.4,"qty":0.00000000},{"price":67708.8,"qty":0.14440698}],"checksum":268868433,"timestamp":"2024-06-01T17:52:20.177098Z"}]}
{"channel":"book","type":"update","data":[{"symbol":"BTC/USDT","bids":[],"asks":[{"price":67701.3,"qty":0.00000000},{"price":67708.9,"qty":0.14781151},{"price":67701.5,"qty":0.22170000}],"checksum":2316508209,"timestamp":"2024-06-01T17:52:20.180709Z"}]}
{"channel":"book","type":"update","data":[{"symbol":"BTC/USDT","bids":[],"asks":[{"price":67703.5,"qty":0.07396000}],"checksum":1634579938,"timestamp":"2024-06-01T17:52:20.205719Z"}]}
{"channel":"book","type":"update","data":[{"symbol":"BTC/USDT","bids":[{"price":67683.3,"qty":0.00000000},{"price":67676.4,"qty":0.45488666}],"asks":[],"checksum":2588268326,"timestamp":"2024-06-01T17:52:20.211943Z"}]}
{"channel":"book","type":"update","data":[{"symbol":"BTC/USDT","bids":[{"price":67683.5,"qty":0.15000000}],"asks":[],"checksum":2433165494,"timestamp":"2024-06-01T17:52:20.212148Z"}]}
{"channel":"book","type":"update","data":[{"symbol":"BTC/USDT","bids":[{"price":67682.9,"qty":0.00000000},{"price":67676.4,"qty":0.45488666}],"asks":[],"checksum":3305631011,"timestamp":"2024-06-01T17:52:20.216941Z"}]}
{"channel":"book","type":"update","data":[{"symbol":"BTC/USDT","bids":[{"price":67683.4,"qty":0.00000000},{"price":67676.2,"qty":1.60140704}],"asks":[],"checksum":1184187456,"timestamp":"2024-06-01T17:52:20.217018Z"}]}
{"channel":"book","type":"update","data":[{"symbol":"BTC/USDT","bids":[{"price":67683.6,"qty":0.01658424}],"asks":[],"checksum":3227133689,"timestamp":"2024-06-01T17:52:20.217204Z"}]}
{"channel":"book","type":"update","data":[{"symbol":"BTC/USDT","bids":[],"asks":[{"price":67690.4,"qty":0.00000000},{"price":67708.8,"qty":0.14440698},{"price":67693.4,"qty":0.05328727}],"checksum":3846576935,"timestamp":"2024-06-01T17:52:20.259215Z"}]}
{"channel":"book","type":"update","data":[{"symbol":"BTC/USDT","bids":[],"asks":[{"price":67690.3,"qty":0.00000000},{"price":67708.8,"qty":0.14440698}],"checksum":2355424340,"timestamp":"2024-06-01T17:52:20.264370Z"}]}
{"channel":"book","type":"update","data":[{"symbol":"BTC/USDT","bids":[],"asks":[{"price":67690.6,"qty":0.03947498}],"checksum":2984016669,"timestamp":"2024-06-01T17:52:20.264528Z"}]}
{"channel":"book","type":"update","data":[{"symbol":"BTC/USDT","bids":[{"price":67683.7,"qty":0.15000000}],"asks":[],"checksum":3577108799,"timestamp":"2024-06-01T17:52:20.265176Z"}]}
{"channel":"book","type":"update","data":[{"symbol":"BTC/USDT","bids":[{"price":67683.6,"qty":0.00000000},{"price":67676.4,"qty":0.45488666}],"asks":[],"checksum":4274094825,"timestamp":"2024-06-01T17:52:20.270016Z"}]}
{"channel":"book","type":"update","data":[{"symbol":"BTC/USDT","bids":[{"price":67683.8,"qty":0.01774162}],"asks":[],"checksum":2024788836,"timestamp":"2024-06-01T17:52:20.270043Z"}]}
{"channel":"book","type":"update","data":[{"symbol":"BTC/USDT","bids":[{"price":67683.9,"qty":0.15000000}],"asks":[],"checksum":529997246,"timestamp":"2024-06-01T17:52:20.711159Z"}]}
{"channel":"book","type":"update","data":[{"symbol":"BTC/USDT","bids":[{"price":67683.7,"qty":0.00000000},{"price":67676.5,"qty":0.05329116}],"asks":[],"checksum":1677327060,"timestamp":"2024-06-01T17:52:20.711199Z"}]}
{"channel":"book","type":"update","data":[{"symbol":"BTC/USDT","bids":[{"price":67683.5,"qty":0.00000000},{"price":67676.4,"qty":0.45488666}],"asks":[],"checksum":1648283353,"timestamp":"2024-06-01T17:52:20.715846Z"}]}
{"channel":"book","type":"update","data":[{"symbol":"BTC/USDT","bids":[{"price":67683.8,"qty":0.00000000},{"price":67676.2,"qty":1.60140704}],"asks":[],"checksum":1789185816,"timestamp":"2024-06-01T17:52:20.716437Z"}]}
{"channel":"book","type":"update","data":[{"symbol":"BTC/USDT","bids":[{"price":67684.0,"qty":0.01658428}],"asks":[],"checksum":1708609636,"timestamp":"2024-06-01T17:52:20.716635Z"}]}
{"channel":"book","type":"update","data":[{"symbol":"BTC/USDT","bids":[{"price":67684.1,"qty":0.15000000}],"asks":[],"checksum":1053756506,"timestamp":"2024-06-01T17:52:21.209717Z"}]}
{"channel":"book","type":"update","data":[{"symbol":"BTC/USDT","bids":[{"price":67683.9,"qty":0.00000000},{"price":67676.4,"qty":0.45488666}],"asks":[],"checksum":981246739,"timestamp":"2024-06-01T17:52:21.214058Z"}]}
{"channel":"book","type":"update","data":[{"symbol":"BTC/USDT","bids":[{"price":67684.0,"qty":0.00000000},{"price":67676.2,"qty":1.60140704}],"asks":[],"checksum":2929485082,"timestamp":"2024-06-01T17:52:21.214531Z"}]}
{"channel":"book","type":"update","data":[{"symbol":"BTC/USDT","bids":[{"price":67684.2,"qty":0.01774162}],"asks":[],"checksum":1508241286,"timestamp":"2024-06-01T17:52:21.214761Z"}]}
{"channel":"book","type":"update","data":[{"symbol":"BTC/USDT","bids":[],"asks":[{"price":67693.4,"qty":0.00000000},{"price":67708.8,"qty":0.14440698},{"price":67690.5,"qty":0.05328731}],"checksum":4012708798,"timestamp":"2024-06-01T17:52:21.620584Z"}]}
{"channel":"book","type":"update","data":[{"symbol":"BTC/USDT","bids":[],"asks":[{"price":67690.4,"qty":0.03947498}],"checksum":492787076,"timestamp":"2024-06-01T17:52:21.624738Z"}]}
{"channel":"book","type":"update","data":[{"symbol":"BTC/USDT","bids":[{"price":67684.3,"qty":0.15000000}],"asks":[],"checksum":3505937219,"timestamp":"2024-06-01T17:52:21.626125Z"}]}
{"channel":"book","type":"update","data":[{"symbol":"BTC/USDT","bids":[{"price":67684.2,"qty":0.00000000},{"price":67676.4,"qty":0.45488666}],"asks":[],"checksum":2062469562,"timestamp":"2024-06-01T17:52:21.630537Z"}]}
{"channel":"book","type":"update","data":[{"symbol":"BTC/USDT","bids":[{"price":67684.4,"qty":0.01774173}],"asks":[],"checksum":1243595304,"timestamp":"2024-06-01T17:52:21.631105Z"}]}
{"channel":"book","type":"update","data":[{"symbol":"BTC/USDT","bids":[],"asks":[{"price":67690.5,"qty":0.00000000},{"price":67703.5,"qty":0.07396000},{"price":67693.4,"qty":0.05328731}],"checksum":3949312102,"timestamp":"2024-06-01T17:52:21.688607Z"}]}
{"channel":"book","type":"update","data":[{"symbol":"BTC/USDT","bids":[],"asks":[{"price":67690.4,"qty":0.00000000},{"price":67703.5,"qty":0.07396000}],"checksum":1802246916,"timestamp":"2024-06-01T17:52:21.692985Z"}]}
{"channel":"book","type":"update","data":[{"symbol":"BTC/USDT","bids":[{"price":67684.3,"qty":0.00000000},{"price":67676.4,"qty":0.45488666}],"asks":[],"checksum":1892340322,"timestamp":"2024-06-01T17:52:21.693519Z"}]}
{"channel":"book","type":"update","data":[{"symbol":"BTC/USDT","bids":[{"price":67684.5,"qty":0.15000000}],"asks":[],"checksum":2787022541,"timestamp":"2024-06-01T17:52:21.693644Z"}]}
{"channel":"book","type":"update","data":[{"symbol":"BTC/USDT","bids":[{"price":67684.4,"qty":0.00000000},{"price":67676.4,"qty":0.45488666}],"asks":[],"checksum":1872129857,"timestamp":"2024-06-01T17:52:21.697726Z"}]}
{"channel":"book","type":"update","data":[{"symbol":"BTC/USDT","bids":[{"price":67684.6,"qty":0.01774164}],"asks":[],"checksum":632296180,"timestamp":"2024-06-01T17:52:21.697932Z"}]}
{"channel":"book","type":"update","data":[{"symbol":"BTC/USDT","bids":[{"price":67684.5,"qty":0.00000000},{"price":67676.4,"qty":0.45488666}],"asks":[],"checksum":2910548372,"timestamp":"2024-06-01T17:52:21.711562Z"}]}
{"channel":"book","type":"update","data":[{"symbol":"BTC/USDT","bids":[{"price":67684.7,"qty":0.15000000}],"asks":[],"checksum":2020505205,"timestamp":"2024-06-01T17:52:21.711784Z"}]}
{"channel":"book","type":"update","data":[{"symbol":"BTC/USDT","bids":[{"price":67684.6,"qty":0.00000000},{"price":67676.4,"qty":0.45488666}],"asks":[],"checksum":1927874558,"timestamp":"2024-06-01T17:52:21.716523Z"}]}
{"channel":"book","type":"update","data":[{"symbol":"BTC/USDT","bids":[{"price":67684.8,"qty":0.01774164}],"asks":[],"checksum":4139613562,"timestamp":"2024-06-01T17:52:21.716778Z"}]}
{"channel":"book","type":"update","data":[{"symbol":"BTC/USDT","bids":[{"price":67679.8,"qty":0.09000000}],"asks":[],"checksum":1214444783,"timestamp":"2024-06-01T17:52:21.886723Z"}]}
{"channel":"book","type":"update","data":[{"symbol":"BTC/USDT","bids":[{"price":67679.8,"qty":0.00000000},{"price":67676.5,"qty":0.05329116}],"asks":[],"checksum":4139613562,"timestamp":"2024-06-01T17:52:21.896152Z"}]}
{"channel":"book","type":"update","data":[{"symbol":"BTC/USDT","bids":[{"price":67679.8,"qty":0.09000000}],"asks":[],"checksum":1214444783,"timestamp":"2024-06-01T17:52:21.945985Z"}]}
{"channel":"book","type":"update","data":[{"symbol":"BTC/USDT","bids":[],"asks":[{"price":67693.4,"qty":0.00000000},{"price":67708.8,"qty":0.14440698},{"price":67701.4,"qty":0.05328731}],"checksum":1409503953,"timestamp":"2024-06-01T17:52:22.097681Z"}]}
{"channel":"book","type":"update","data":[{"symbol":"BTC/USDT","bids":[],"asks":[{"price":67701.5,"qty":0.00000000},{"price":67708.8,"qty":0.14440698},{"price":67701.3,"qty":0.22170000}],"checksum":1365748775,"timestamp":"2024-06-01T17:52:22.101276Z"}]}
{"channel":"book","type":"update","data":[{"symbol":"BTC/USDT","bids":[{"price":67684.9,"qty":0.15000000}],"asks":[],"checksum":3963735149,"timestamp":"2024-06-01T17:52:22.102776Z"}]}
{"channel":"book","type":"update","data":[{"symbol":"BTC/USDT","bids":[{"price":67684.7,"qty":0.00000000},{"price":67676.6,"qty":0.00167443}],"asks":[],"checksum":539628282,"timestamp":"2024-06-01T17:52:22.102836Z"}]}
{"channel":"book","type":"update","data":[{"symbol":"BTC/USDT","bids":[{"price":67684.8,"qty":0.00000000},{"price":67676.5,"qty":0.05329116}],"asks":[],"checksum":3752480079,"timestamp":"2024-06-01T17:52:22.106600Z"}]}
{"channel":"book","type":"update","data":[{"symbol":"BTC/USDT","bids":[{"price":67685.0,"qty":0.01774143}],"asks":[],"checksum":7784462,"timestamp":"2024-06-01T17:52:22.106823Z"}]}
{"channel":"book","type":"update","data":[{"symbol":"BTC/USDT","bids":[{"price":67676.6,"qty":0.00000000},{"price":67676.5,"qty":0.05329116}],"asks":[],"checksum":3732563036,"timestamp":"2024-06-01T17:52:22.168381Z"}]}
{"channel":"book","type":"update","data":[{"symbol":"BTC/USDT","bids":[{"price":67676.6,"qty":0.00469089}],"asks":[],"checksum":4211941440,"timestamp":"2024-06-01T17:52:22.173312Z"}]}
{"channel":"book","type":"update","data":[{"symbol":"BTC/USDT","bids":[{"price":67684.9,"qty":0.00000000},{"price":67676.5,"qty":0.05329116}],"asks":[],"checksum":2846365078,"timestamp":"2024-06-01T17:52:22.212884Z"}]}
{"channel":"book","type":"update","data":[{"symbol":"BTC/USDT","bids":[{"price":67685.1,"qty":0.15000000}],"asks":[],"checksum":1067256269,"timestamp":"2024-06-01T17:52:22.212960Z"}]}
{"channel":"book","type":"update","data":[{"symbol":"BTC/USDT","bids":[{"price":67685.0,"qty":0.00000000},{"price":67676.5,"qty":0.05329116}],"asks":[],"checksum":2549174310,"timestamp":"2024-06-01T17:52:22.217525Z"}]}
{"channel":"book","type":"update","data":[{"symbol":"BTC/USDT","bids":[{"price":67685.2,"qty":0.01774143}],"asks":[],"checksum":1537816636,"timestamp":"2024-06-01T17:52:22.217650Z"}]}
{"channel":"book","type":"update","data":[{"symbol":"BTC/USDT","bids":[{"price":67684.1,"qty":0.00000000},{"price":67676.5,"qty":0.05329116}],"asks":[],"checksum":2288006298,"timestamp":"2024-06-01T17:52:22.217936Z"}]}
{"channel":"book","type":"update","data":[{"symbol":"BTC/USDT","bids":[{"price":67676.6,"qty":0.74816514}],"asks":[],"checksum":1918034421,"timestamp":"2024-06-01T17:52:22.301311Z"}]}
{"channel":"book","type":"update","data":[{"symbol":"BTC/USDT","bids":[{"price":67679.8,"qty":0.00000000},{"price":67676.2,"qty":1.60140704}],"asks":[],"checksum":2730632718,"timestamp":"2024-06-01T17:52:22.342357Z"}]}
{"channel":"book","type":"update","data":[{"symbol":"BTC/USDT","bids":[{"price":67676.5,"qty":0.00000000},{"price":67676.1,"qty":0.17872429},{"price":67680.4,"qty":0.05328850}],"asks":[],"checksum":2700372239,"timestamp":"2024-06-01T17:52:22.409467Z"}]}
{"channel":"book","type":"update","data":[{"symbol":"BTC/USDT","bids":[],"asks":[{"price":67701.4,"qty":0.00000000},{"price":67708.8,"qty":0.14440698},{"price":67693.4,"qty":0.05328731}],"checksum":727804428,"timestamp":"2024-06-01T17:52:22.409513Z"}]}
{"channel":"book","type":"update","data":[{"symbol":"BTC/USDT","bids":[{"price":67685.3,"qty":0.15000000}],"asks":[],"checksum":1321639988,"timestamp":"2024-06-01T17:52:22.414945Z"}]}
{"channel":"book","type":"update","data":[{"symbol":"BTC/USDT","bids":[{"price":67685.2,"qty":0.00000000},{"price":67676.2,"qty":1.60140704}],"asks":[],"checksum":2078615009,"timestamp":"2024-06-01T17:52:22.419377Z"}]}
{"channel":"book","type":"update","data":[{"symbol":"BTC/USDT","bids":[{"price":67685.4,"qty":0.01774143}],"asks":[],"checksum":3718259794,"timestamp":"2024-06-01T17:52:22.419435Z"}]}
{"channel":"book","type":"update","data":[{"symbol":"BTC/USDT","bids":[{"price":67685.3,"qty":0.00000000},{"price":67676.2,"qty":1.60140704}],"asks":[],"checksum":1262330026,"timestamp":"2024-06-01T17:52:22.711391Z"}]}
{"channel":"book","type":"update","data":[{"symbol":"BTC/USDT","bids":[{"price":67685.5,"qty":0.15000000}],"asks":[],"checksum":1265769268,"timestamp":"2024-06-01T17:52:22.711478Z"}]}
{"channel":"book","type":"update","data":[{"symbol":"BTC/USDT","bids":[{"price":67685.1,"qty":0.00000000},{"price":67676.2,"qty":1.60140704}],"asks":[],"checksum":2022201434,"timestamp":"2024-06-01T17:52:22.716476Z"}]}
{"channel":"book","type":"update","data":[{"symbol":"BTC/USDT","bids":[{"price":67685.4,"qty":0.00000000},{"price":67676.1,"qty":0.17872429}],"asks":[],"checksum":2228111617,"timestamp":"2024-06-01T17:52:22.716925Z"}]}
{"channel":"book","type":"update","data":[{"symbol":"BTC/USDT","bids":[{"price":67685.6,"qty":0.01774143}],"asks":[],"checksum":2677882317,"timestamp":"2024-06-01T17:52:22.717024Z"}]}
{"channel":"book","type":"update","data":[{"symbol":"BTC/USDT","bids":[],"asks":[{"price":67693.4,"qty":0.00000000},{"price":67708.9,"qty":0.14781151},{"price":67701.2,"qty":0.05328652}],"checksum":2165125607,"timestamp":"2024-06-01T17:52:23.103368Z"}]}
{"channel":"book","type":"update","data":[{"symbol":"BTC/USDT","bids":[{"price":67680.4,"qty":0.00000000},{"price":67676.1,"qty":0.17872429},{"price":67676.7,"qty":0.05329031}],"asks":[],"checksum":1799558628,"timestamp":"2024-06-01T17:52:23.103545Z"}]}
{"channel":"book","type":"update","data":[{"symbol":"BTC/USDT","bids":[],"asks":[{"price":67701.3,"qty":0.00000000},{"price":67708.9,"qty":0.14781151},{"price":67701.1,"qty":0.22170000}],"checksum":1285037194,"timestamp":"2024-06-01T17:52:23.106760Z"}]}
{"channel":"book","type":"update","data":[{"symbol":"BTC/USDT","bids":[{"price":67685.7,"qty":0.15000000}],"asks":[],"checksum":1056531787,"timestamp":"2024-06-01T17:52:23.108394Z"}]}
{"channel":"book","type":"update","data":[{"symbol":"BTC/USDT","bids":[{"price":67685.6,"qty":0.00000000},{"price":67676.2,"qty":1.60140704}],"asks":[],"checksum":2298378830,"timestamp":"2024-06-01T17:52:23.112600Z"}]}
{"channel":"book","type":"update","data":[{"symbol":"BTC/USDT","bids":[],"asks":[{"price":67701.2,"qty":0.00000000},{"price":67708.9,"qty":0.14781151},{"price":67701.0,"qty":0.05328652}],"checksum":3138958120,"timestamp":"2024-06-01T17:52:23.206337Z"}]}
{"channel":"book","type":"update","data":[{"symbol":"BTC/USDT","bids":[{"price":67685.7,"qty":0.00000000},{"price":67676.1,"qty":0.17872429}],"asks":[],"checksum":3587102110,"timestamp":"2024-06-01T17:52:23.211552Z"}]}
{"channel":"book","type":"update","data":[{"symbol":"BTC/USDT","bids":[{"price":67685.6,"qty":0.01774143}],"asks":[],"checksum":2840371175,"timestamp":"2024-06-01T17:52:23.216572Z"}]}
{"channel":"book","type":"update","data":[{"symbol":"BTC/USDT","bids":[{"price":67679.8,"qty":0.09000000}],"asks":[],"checksum":1776875842,"timestamp":"2024-06-01T17:52:23.268896Z"}]}
{"channel":"book","type":"update","data":[{"symbol":"BTC/USDT","bids":[{"price":67687.3,"qty":0.29561616}],"asks":[],"checksum":4083163551,"timestamp":"2024-06-01T17:52:23.294089Z"}]}
{"channel":"book","type":"update","data":[{"symbol":"BTC/USDT","bids":[{"price":67680.3,"qty":0.00000000},{"price":67676.6,"qty":0.74816514}],"asks":[],"checksum":1988771521,"timestamp":"2024-06-01T17:52:23.297528Z"}]}
{"channel":"book","type":"update","data":[{"symbol":"BTC/USDT","bids":[{"price":67685.6,"qty":0.00000000},{"price":67676.2,"qty":1.60140704}],"asks":[],"checksum":3433582862,"timestamp":"2024-06-01T17:52:23.298690Z"}]}
{"channel":"book","type":"update","data":[{"symbol":"BTC/USDT","bids":[{"price":67687.4,"qty":0.05000000}],"asks":[],"checksum":3902329843,"timestamp":"2024-06-01T17:52:23.306151Z"}]}
{"channel":"book","type":"update","data":[{"symbol":"BTC/USDT","bids":[{"price":67686.6,"qty":0.00000000},{"price":67676.2,"qty":1.60140704},{"price":67687.5,"qty":0.00092896}],"asks":[],"checksum":696884941,"timestamp":"2024-06-01T17:52:23.337246Z"}]}
{"channel":"book","type":"update","data":[{"symbol":"BTC/USDT","bids":[{"price":67686.4,"qty":0.00000000},{"price":67676.2,"qty":1.60140704}],"asks":[],"checksum":1981153554,"timestamp":"2024-06-01T17:52:23.342197Z"}]}
{"channel":"book","type":"update","data":[{"symbol":"BTC/USDT","bids":[],"asks":[{"price":67701.6,"qty":0.00000000},{"price":67708.9,"qty":0.14781151}],"checksum":1719389527,"timestamp":"2024-06-01T17:52:23.477914Z"}]}
{"channel":"book","type":"update","data":[{"symbol":"BTC/USDT","bids":[{"price":67687.6,"qty":0.09000000}],"asks":[],"checksum":936828950,"timestamp":"2024-06-01T17:52:23.478249Z"}]}
{"channel":"book","type":"update","data":[{"symbol":"BTC/USDT","bids":[],"asks":[{"price":67704.2,"qty":0.09000000}],"checksum":2701974812,"timestamp":"2024-06-01T17:52:23.481217Z"}]}
{"channel":"book","type":"update","data":[{"symbol":"BTC/USDT","bids":[{"price":67687.6,"qty":0.00000000},{"price":67676.2,"qty":1.60140704}],"asks":[],"checksum":3304914710,"timestamp":"2024-06-01T17:52:23.481716Z"}]}
{"channel":"book","type":"update","data":[{"symbol":"BTC/USDT","bids":[{"price":67676.7,"qty":0.00000000},{"price":67676.1,"qty":0.17872429},{"price":67679.9,"qty":0.05328777}],"asks":[],"checksum":3746564524,"timestamp":"2024-06-01T17:52:24.056427Z"}]}
{"channel":"book","type":"update","data":[{"symbol":"BTC/USDT","bids":[],"asks":[{"price":67703.5,"qty":0.00000000},{"price":67708.9,"qty":0.14781151}],"checksum":412786522,"timestamp":"2024-06-01T17:52:24.406718Z"}]}
{"channel":"book","type":"update","data":[{"symbol":"BTC/USDT","bids":[],"asks":[{"price":67705.7,"qty":0.07396000}],"checksum":3605133462,"timestamp":"2024-06-01T17:52:24.421244Z"}]}
{"channel":"book","type":"update","data":[{"symbol":"BTC/USDT","bids":[],"asks":[{"price":67701.1,"qty":0.00000000},{"price":67708.9,"qty":0.14781151},{"price":67702.0,"qty":0.22170000}],"checksum":4176853263,"timestamp":"2024-06-01T17:52:24.424564Z"}]}
{"channel":"book","type":"update","data":[{"symbol":"BTC/USDT","bids":[{"price":67687.5,"qty":0.00000000},{"price":67676.1,"qty":0.17872429}],"asks":[],"checksum":3952307805,"timestamp":"2024-06-01T17:52:24.442500Z"}]}
{"channel":"book","type":"update","data":[{"symbol":"BTC/USDT","bids":[],"asks":[{"price":67701.0,"qty":0.00000000},{"price":67708.9,"qty":0.14781151},{"price":67701.9,"qty":0.05328627}],"checksum":2588218172,"timestamp":"2024-06-01T17:52:24.481754Z"}]}
{"channel":"book","type":"update","data":[{"symbol":"BTC/USDT","bids":[{"price":67687.4,"qty":0.05092896}],"asks":[],"checksum":925430382,"timestamp":"2024-06-01T17:52:24.631326Z"}]}
{"channel":"book","type":"update","data":[{"symbol":"BTC/USDT","bids":[{"price":67676.6,"qty":0.74347425}],"asks":[],"checksum":676673470,"timestamp":"2024-06-01T17:52:24.733747Z"}]}
{"channel":"book","type":"update","data":[{"symbol":"BTC/USDT","bids":[{"price":67676.7,"qty":0.00721816}],"asks":[],"checksum":2248523912,"timestamp":"2024-06-01T17:52:24.739182Z"}]}
{"channel":"book","type":"update","data":[{"symbol":"BTC/USDT","bids":[],"asks":[{"price":67697.4,"qty":0.09000000}],"checksum":806407754,"timestamp":"2024-06-01T17:52:24.885442Z"}]}
{"channel":"book","type":"update","data":[{"symbol":"BTC/USDT","bids":[],"asks":[{"price":67702.0,"qty":0.00000000},{"price":67705.7,"qty":0.07396000},{"price":67701.8,"qty":0.22170000}],"checksum":3510253297,"timestamp":"2024-06-01T17:52:25.232013Z"}]}
{"channel":"book","type":"update","data":[{"symbol":"BTC/USDT","bids":[],"asks":[{"price":67701.9,"qty":0.00000000},{"price":67705.7,"qty":0.07396000},{"price":67701.7,"qty":0.05328626}],"checksum":159256305,"timestamp":"2024-06-01T17:52:25.290713Z"}]}
{"channel":"book","type":"update","data":[{"symbol":"BTC/USDT","bids":[],"asks":[{"price":67697.4,"qty":0.00000000},{"price":67705.7,"qty":0.07396000}],"checksum":4160463,"timestamp":"2024-06-01T17:52:25.326643Z"}]}
{"channel":"book","type":"update","data":[{"symbol":"BTC/USDT","bids":[{"price":67687.5,"qty":0.02000000}],"asks":[],"checksum":291790480,"timestamp":"2024-06-01T17:52:25.369961Z"}]}
{"channel":"book","type":"update","data":[{"symbol":"BTC/USDT","bids":[{"price":67687.4,"qty":0.05000000},{"price":67687.6,"qty":0.00092896}],"asks":[],"checksum":4279413283,"timestamp":"2024-06-01T17:52:25.434617Z"}]}
{"channel":"book","type":"update","data":[{"symbol":"BTC/USDT","bids":[{"price":67687.6,"qty":0.05092896}],"asks":[],"checksum":3094047583,"timestamp":"2024-06-01T17:52:25.440056Z"}]}
{"channel":"book","type":"update","data":[{"symbol":"BTC/USDT","bids":[{"price":67687.5,"qty":0.00000000},{"price":67676.6,"qty":0.74347425}],"asks":[],"checksum":3209399328,"timestamp":"2024-06-01T17:52:25.463866Z"}]}
{"channel":"book","type":"update","data":[{"symbol":"BTC/USDT","bids":[{"price":67679.9,"qty":0.00000000},{"price":67676.2,"qty":1.60140704}],"asks":[],"checksum":3367156210,"timestamp":"2024-06-01T17:52:25.476836Z"}]}
{"channel":"book","type":"update","data":[{"symbol":"BTC/USDT","bids":[{"price":67687.6,"qty":0.05000000},{"price":67687.7,"qty":0.00092896}],"asks":[],"checksum":2829322327,"timestamp":"2024-06-01T17:52:25.499179Z"}]}
{"channel":"book","type":"update","data":[{"symbol":"BTC/USDT","bids":[{"price":67688.6,"qty":0.04290000}],"asks":[],"checksum":2519201143,"timestamp":"2024-06-01T17:52:25.502023Z"}]}
{"channel":"book","type":"update","data":[{"symbol":"BTC/USDT","bids":[{"price":67687.6,"qty":0.00000000},{"price":67676.6,"qty":0.74347425}],"asks":[],"checksum":4168611375,"timestamp":"2024-06-01T17:52:25.505399Z"}]}
{"channel":"book","type":"update","data":[{"symbol":"BTC/USDT","bids":[{"price":67687.7,"qty":0.05092896}],"asks":[],"checksum":4057263790,"timestamp":"2024-06-01T17:52:25.505717Z"}]}
{"channel":"book","type":"update","data":[{"symbol":"BTC/USDT","bids":[{"price":67687.7,"qty":0.00092896}],"asks":[],"checksum":4168611375,"timestamp":"2024-06-01T17:52:25.586453Z"}]}
{"channel":"book","type":"update","data":[{"symbol":"BTC/USDT","bids":[{"price":67688.7,"qty":0.05000000}],"asks":[],"checksum":2048674319,"timestamp":"2024-06-01T17:52:25.586628Z"}]}
{"channel":"book","type":"update","data":[{"symbol":"BTC/USDT","bids":[{"price":67688.6,"qty":0.00000000},{"price":67676.6,"qty":0.74347425}],"asks":[],"checksum":3473543987,"timestamp":"2024-06-01T17:52:25.589419Z"}]}
{"channel":"book","type":"update","data":[{"symbol":"BTC/USDT","bids":[{"price":67689.6,"qty":0.04290000}],"asks":[],"checksum":3295802416,"timestamp":"2024-06-01T17:52:25.589500Z"}]}
{"channel":"book","type":"update","data":[{"symbol":"BTC/USDT","bids":[{"price":67687.4,"qty":0.00000000},{"price":67676.6,"qty":0.74347425}],"asks":[],"checksum":2789064390,"timestamp":"2024-06-01T17:52:25.590925Z"}]}
{"channel":"book","type":"update","data":[{"symbol":"BTC/USDT","bids":[{"price":67687.7,"qty":0.00000000},{"price":67676.2,"qty":1.60140704},{"price":67688.7,"qty":0.05092896}],"asks":[],"checksum":3795331012,"timestamp":"2024-06-01T17:52:25.592875Z"}]}
{"channel":"book","type":"update","data":[{"symbol":"BTC/USDT","bids":[{"price":67688.7,"qty":0.05000000},{"price":67688.8,"qty":0.00092896}],"asks":[],"checksum":2551813736,"timestamp":"2024-06-01T17:52:25.808159Z"}]}
{"channel":"book","type":"update","data":[{"symbol":"BTC/USDT","bids":[{"price":67689.7,"qty":0.05000000}],"asks":[],"checksum":4251535144,"timestamp":"2024-06-01T17:52:25.814436Z"}]}
{"channel":"book","type":"update","data":[{"symbol":"BTC/USDT","bids":[{"price":67689.6,"qty":0.00000000},{"price":67676.6,"qty":0.74347425}],"asks":[],"checksum":2942595956,"timestamp":"2024-06-01T17:52:25.817112Z"}]}
{"channel":"book","type":"update","data":[{"symbol":"BTC/USDT","bids":[{"price":67690.3,"qty":0.04290000}],"asks":[],"checksum":3041411159,"timestamp":"2024-06-01T17:52:25.817262Z"}]}
{"channel":"book","type":"update","data":[{"symbol":"BTC/USDT","bids":[{"price":67679.8,"qty":0.00000000},{"price":67676.6,"qty":0.74347425}],"asks":[],"checksum":2436233742,"timestamp":"2024-06-01T17:52:25.818325Z"}]}
{"channel":"book","type":"update","data":[{"symbol":"BTC/USDT","bids":[],"asks":[{"price":67693.5,"qty":0.00000000},{"price":67708.9,"qty":0.14781151}],"checksum":1128059867,"timestamp":"2024-06-01T17:52:25.820549Z"}]}
{"channel":"book","type":"update","data":[{"symbol":"BTC/USDT","bids":[],"asks":[{"price":67701.7,"qty":0.25305334}],"checksum":621209606,"timestamp":"2024-06-01T17:52:25.823391Z"}]}
{"channel":"book","type":"update","data":[{"symbol":"BTC/USDT","bids":[{"price":67676.6,"qty":0.00000000},{"price":67676.2,"qty":1.60140704}],"asks":[],"checksum":4034868847,"timestamp":"2024-06-01T17:52:25.966119Z"}]}
{"channel":"book","type":"update","data":[{"symbol":"BTC/USDT","bids":[{"price":67676.3,"qty":1.06243957}],"asks":[],"checksum":3234018393,"timestamp":"2024-06-01T17:52:25.972808Z"}]}
{"channel":"book","type":"update","data":[{"symbol":"BTC/USDT","bids":[{"price":67689.7,"qty":0.00000000},{"price":67676.2,"qty":1.60140704}],"asks":[],"checksum":1851086540,"timestamp":"2024-06-01T17:52:26.085019Z"}]}
{"channel":"book","type":"update","data":[{"symbol":"BTC/USDT","bids":[{"price":67690.4,"qty":0.05000000}],"asks":[],"checksum":2316518646,"timestamp":"2024-06-01T17:52:26.085222Z"}]}
{"channel":"book","type":"update","data":[{"symbol":"BTC/USDT","bids":[{"price":67690.3,"qty":0.00000000},{"price":67676.2,"qty":1.60140704}],"asks":[],"checksum":1082084367,"timestamp":"2024-06-01T17:52:26.087987Z"}]}
{"channel":"book","type":"update","data":[{"symbol":"BTC/USDT","bids":[{"price":67690.5,"qty":0.04290000}],"asks":[],"checksum":310920750,"timestamp":"2024-06-01T17:52:26.088263Z"}]}
{"channel":"book","type":"update","data":[{"symbol":"BTC/USDT","bids":[{"price":67688.7,"qty":0.00000000},{"price":67676.2,"qty":1.60140704}],"asks":[],"checksum":2455466343,"timestamp":"2024-06-01T17:52:26.089570Z"}]}
{"channel":"book","type":"update","data":[{"symbol":"BTC/USDT","bids":[{"price":67676.8,"qty":0.05329015}],"asks":[],"checksum":952000526,"timestamp":"2024-06-01T17:52:26.141049Z"}]}
{"channel":"book","type":"update","data":[{"symbol":"BTC/USDT","bids":[{"price":67676.8,"qty":0.00000000},{"price":67676.2,"qty":1.60140704},{"price":67676.4,"qty":0.05329047}],"asks":[],"checksum":3176270698,"timestamp":"2024-06-01T17:52:26.236323Z"}]}
{"channel":"book","type":"update","data":[{"symbol":"BTC/USDT","bids":[],"asks":[{"price":67701.8,"qty":0.00000000},{"price":67710.1,"qty":0.05000000},{"price":67702.0,"qty":0.22170000}],"checksum":2563663209,"timestamp":"2024-06-01T17:52:26.239397Z"}]}
{"channel":"book","type":"update","data":[{"symbol":"BTC/USDT","bids":[{"price":67690.5,"qty":0.09290000}],"asks":[],"checksum":2969220868,"timestamp":"2024-06-01T17:52:26.586158Z"}]}
{"channel":"book","type":"update","data":[{"symbol":"BTC/USDT","bids":[{"price":67690.4,"qty":0.00000000},{"price":67676.2,"qty":1.60140704}],"asks":[],"checksum":1313763007,"timestamp":"2024-06-01T17:52:26.591213Z"}]}
{"channel":"book","type":"update","data":[{"symbol":"BTC/USDT","bids":[],"asks":[{"price":67701.7,"qty":0.19976708},{"price":67701.6,"qty":0.05328626}],"checksum":1712983795,"timestamp":"2024-06-01T17:52:27.004143Z"}]}
{"channel":"book","type":"update","data":[{"symbol":"BTC/USDT","bids":[{"price":67676.7,"qty":0.00000000},{"price":67676.1,"qty":0.12872429}],"asks":[],"checksum":2241449972,"timestamp":"2024-06-01T17:52:27.395116Z"}]}
{"channel":"book","type":"update","data":[{"symbol":"BTC/USDT","bids":[{"price":67676.5,"qty":0.01040618}],"asks":[],"checksum":3904865950,"timestamp":"2024-06-01T17:52:27.400602Z"}]}
{"channel":"book","type":"update","data":[{"symbol":"BTC/USDT","bids":[],"asks":[{"price":67697.4,"qty":0.09000000}],"checksum":3264496184,"timestamp":"2024-06-01T17:52:27.456448Z"}]}
{"channel":"book","type":"update","data":[{"symbol":"BTC/USDT","bids":[],"asks":[{"price":67697.4,"qty":0.00000000},{"price":67705.7,"qty":0.07396000}],"checksum":3904865950,"timestamp":"2024-06-01T17:52:27.849012Z"}]}
{"channel":"book","type":"update","data":[{"symbol":"BTC/USDT","bids":[{"price":67676.4,"qty":0.00000000},{"price":67676.1,"qty":0.12872429},{"price":67676.6,"qty":0.05329071}],"asks":[],"checksum":3187946030,"timestamp":"2024-06-01T17:52:27.854016Z"}]}
{"channel":"book","type":"update","data":[{"symbol":"BTC/USDT","bids":[],"asks":[{"price":67701.6,"qty":0.00000000},{"price":67708.9,"qty":0.14781151},{"price":67695.9,"qty":0.05328625}],"checksum":4025527859,"timestamp":"2024-06-01T17:52:27.854072Z"}]}
{"channel":"book","type":"update","data":[{"symbol":"BTC/USDT","bids":[],"asks":[{"price":67695.9,"qty":0.00000000},{"price":67708.9,"qty":0.14781151},{"price":67701.6,"qty":0.05328625}],"checksum":1212410722,"timestamp":"2024-06-01T17:52:27.910718Z"}]}
{"channel":"book","type":"update","data":[{"symbol":"BTC/USDT","bids":[{"price":67687.4,"qty":0.01774136}],"asks":[],"checksum":2421873380,"timestamp":"2024-06-01T17:52:28.576591Z"}]}
{"channel":"book","type":"update","data":[{"symbol":"BTC/USDT","bids":[],"asks":[{"price":67705.7,"qty":0.00000000},{"price":67710.1,"qty":0.05000000}],"checksum":228118381,"timestamp":"2024-06-01T17:52:28.579897Z"}]}
{"channel":"book","type":"update","data":[{"symbol":"BTC/USDT","bids":[],"asks":[{"price":67707.2,"qty":0.07396000}],"checksum":2340356844,"timestamp":"2024-06-01T17:52:28.583630Z"}]}
{"channel":"book","type":"update","data":[{"symbol":"BTC/USDT","bids":[{"price":67687.4,"qty":0.00000000},{"price":67676.2,"qty":1.60140704}],"asks":[],"checksum":143794345,"timestamp":"2024-06-01T17:52:28.591701Z"}]}
{"channel":"book","type":"update","data":[{"symbol":"BTC/USDT","bids":[{"price":67688.8,"qty":0.01866965}],"asks":[],"checksum":1474902079,"timestamp":"2024-06-01T17:52:28.591934Z"}]}
{"channel":"book","type":"update","data":[{"symbol":"BTC/USDT","bids":[{"price":67688.9,"qty":0.01774069}],"asks":[],"checksum":2191034246,"timestamp":"2024-06-01T17:52:28.595448Z"}]}
{"channel":"book","type":"update","data":[{"symbol":"BTC/USDT","bids":[{"price":67688.8,"qty":0.00092896}],"asks":[],"checksum":1534647835,"timestamp":"2024-06-01T17:52:28.595551Z"}]}
{"channel":"book","type":"update","data":[{"symbol":"BTC/USDT","bids":[{"price":67683.7,"qty":0.09000000}],"asks":[],"checksum":3420905144,"timestamp":"2024-06-01T17:52:28.609155Z"}]}
{"channel":"book","type":"update","data":[{"symbol":"BTC/USDT","bids":[{"price":67688.8,"qty":0.00000000},{"price":67676.3,"qty":1.06243957},{"price":67689.0,"qty":0.00092896}],"asks":[],"checksum":3601966182,"timestamp":"2024-06-01T17:52:28.633688Z"}]}
{"channel":"book","type":"update","data":[{"symbol":"BTC/USDT","bids":[{"price":67688.9,"qty":0.00000000},{"price":67676.3,"qty":1.06243957}],"asks":[],"checksum":1320260998,"timestamp":"2024-06-01T17:52:28.637779Z"}]}
{"channel":"book","type":"update","data":[{"symbol":"BTC/USDT","bids":[{"price":67689.1,"qty":0.01774051}],"asks":[],"checksum":1790183838,"timestamp":"2024-06-01T17:52:28.637958Z"}]}
{"channel":"book","type":"update","data":[{"symbol":"BTC/USDT","bids":[{"price":67676.6,"qty":0.00000000},{"price":67676.3,"qty":1.06243957}],"asks":[],"checksum":3019906302,"timestamp":"2024-06-01T17:52:28.654946Z"}]}
{"channel":"book","type":"update","data":[{"symbol":"BTC/USDT","bids":[{"price":67689.1,"qty":0.00000000},{"price":67676.2,"qty":1.60140704}],"asks":[],"checksum":2677375482,"timestamp":"2024-06-01T17:52:28.678439Z"}]}
{"channel":"book","type":"update","data":[{"symbol":"BTC/USDT","bids":[{"price":67687.4,"qty":0.01774071}],"asks":[],"checksum":3718354114,"timestamp":"2024-06-01T17:52:28.682875Z"}]}
{"channel":"book","type":"update","data":[{"symbol":"BTC/USDT","bids":[{"price":67676.7,"qty":0.05329065}],"asks":[],"checksum":2027760663,"timestamp":"2024-06-01T17:52:28.724942Z"}]}
{"channel":"book","type":"update","data":[{"symbol":"BTC/USDT","bids":[{"price":67676.7,"qty":0.00000000},{"price":67676.3,"qty":1.06243957},{"price":67676.6,"qty":0.05329073}],"asks":[],"checksum":2789097431,"timestamp":"2024-06-01T17:52:28.788953Z"}]}
{"channel":"book","type":"update","data":[{"symbol":"BTC/USDT","bids":[{"price":67683.7,"qty":0.00000000},{"price":67676.3,"qty":1.06243957}],"asks":[],"checksum":801079662,"timestamp":"2024-06-01T17:52:29.411464Z"}]}
{"channel":"book","type":"update","data":[{"symbol":"BTC/USDT","bids":[{"price":67683.7,"qty":0.09000000}],"asks":[],"checksum":2789097431,"timestamp":"2024-06-01T17:52:29.491903Z"}]}
{"channel":"book","type":"update","data":[{"symbol":"BTC/USDT","bids":[{"price":67676.7,"qty":1.01687723}],"asks":[],"checksum":2925801784,"timestamp":"2024-06-01T17:52:29.580165Z"}]}
{"channel":"book","type":"update","data":[{"symbol":"BTC/USDT","bids":[{"price":67676.6,"qty":0.00000000},{"price":67676.5,"qty":0.01040618},{"price":67676.8,"qty":0.05329057}],"asks":[],"checksum":2542512216,"timestamp":"2024-06-01T17:52:29.653037Z"}]}
{"channel":"book","type":"update","data":[{"symbol":"BTC/USDT","bids":[{"price":67676.7,"qty":1.02656818}],"asks":[],"checksum":1374477415,"timestamp":"2024-06-01T17:52:29.954602Z"}]}
{"channel":"book","type":"update","data":[{"symbol":"BTC/USDT","bids":[{"price":67682.4,"qty":0.00000000},{"price":67676.2,"qty":1.60140704}],"asks":[],"checksum":1542392384,"timestamp":"2024-06-01T17:52:30.299379Z"}]}
{"channel":"book","type":"update","data":[{"symbol":"BTC/USDT","bids":[{"price":67690.5,"qty":0.21301700}],"asks":[],"checksum":1869104510,"timestamp":"2024-06-01T17:52:30.301630Z"}]}
{"channel":"book","type":"update","data":[{"symbol":"BTC/USDT","bids":[{"price":67687.4,"qty":0.00000000},{"price":67676.1,"qty":0.12872429}],"asks":[],"checksum":2062546551,"timestamp":"2024-06-01T17:52:30.306246Z"}]}
{"channel":"book","type":"update","data":[{"symbol":"BTC/USDT","bids":[],"asks":[{"price":67707.2,"qty":0.00000000},{"price":67710.1,"qty":0.05000000}],"checksum":3659684254,"timestamp":"2024-06-01T17:52:30.820852Z"}]}
{"channel":"book","type":"update","data":[{"symbol":"BTC/USDT","bids":[],"asks":[{"price":67696.0,"qty":0.00000000},{"price":67711.3,"qty":0.09846962}],"checksum":2929879447,"timestamp":"2024-06-01T17:52:30.834471Z"}]}
{"channel":"book","type":"update","data":[{"symbol":"BTC/USDT","bids":[],"asks":[{"price":67708.6,"qty":0.07396000}],"checksum":2949268553,"timestamp":"2024-06-01T17:52:30.838623Z"}]}
{"channel":"book","type":"update","data":[{"symbol":"BTC/USDT","bids":[],"asks":[{"price":67702.2,"qty":0.14782616}],"checksum":3515833250,"timestamp":"2024-06-01T17:52:30.839301Z"}]}
{"channel":"book","type":"update","data":[{"symbol":"BTC/USDT","bids":[{"price":67676.8,"qty":0.00000000},{"price":67676.0,"qty":0.00460867},{"price":67690.5,"qty":0.26629650}],"asks":[],"checksum":2046433280,"timestamp":"2024-06-01T17:52:30.937731Z"}]}
{"channel":"book","type":"update","data":[{"symbol":"BTC/USDT","bids":[{"price":67690.5,"qty":0.14617950}],"asks":[],"checksum":439224645,"timestamp":"2024-06-01T17:52:30.982006Z"}]}
{"channel":"book","type":"update","data":[{"symbol":"BTC/USDT","bids":[{"price":67683.7,"qty":0.00000000},{"price":67674.3,"qty":0.14788674}],"asks":[],"checksum":1433272167,"timestamp":"2024-06-01T17:52:30.984299Z"}]}
{"channel":"book","type":"update","data":[{"symbol":"BTC/USDT","bids":[],"asks":[{"price":67697.4,"qty":0.09000000}],"checksum":1444880321,"timestamp":"2024-06-01T17:52:30.988439Z"}]}
{"channel":"book","type":"update","data":[{"symbol":"BTC/USDT","bids":[],"asks":[{"price":67690.6,"qty":0.12947498}],"checksum":4075754203,"timestamp":"2024-06-01T17:52:31.001155Z"}]}
{"channel":"book","type":"update","data":[{"symbol":"BTC/USDT","bids":[],"asks":[{"price":67690.6,"qty":0.21947498}],"checksum":29663906,"timestamp":"2024-06-01T17:52:31.002261Z"}]}
{"channel":"book","type":"update","data":[{"symbol":"BTC/USDT","bids":[{"price":67687.3,"qty":0.00000000},{"price":67672.2,"qty":0.05489469}],"asks":[],"checksum":902307534,"timestamp":"2024-06-01T17:52:31.021284Z"}]}
{"channel":"book","type":"update","data":[{"symbol":"BTC/USDT","bids":[{"price":67689.2,"qty":0.04290000}],"asks":[],"checksum":1158533378,"timestamp":"2024-06-01T17:52:31.029545Z"}]}
{"channel":"book","type":"update","data":[{"symbol":"BTC/USDT","bids":[{"price":67690.5,"qty":0.10327950}],"asks":[],"checksum":3233396088,"timestamp":"2024-06-01T17:52:31.029922Z"}]}
{"channel":"book","type":"update","data":[{"symbol":"BTC/USDT","bids":[{"price":67689.2,"qty":0.00000000},{"price":67672.2,"qty":0.05489469}],"asks":[],"checksum":2960947892,"timestamp":"2024-06-01T17:52:31.035192Z"}]}
{"channel":"book","type":"update","data":[{"symbol":"BTC/USDT","bids":[],"asks":[{"price":67702.2,"qty":0.00000000},{"price":67708.6,"qty":0.07396000}],"checksum":1128886817,"timestamp":"2024-06-01T17:52:31.036599Z"}]}
{"channel":"book","type":"update","data":[{"symbol":"BTC/USDT","bids":[{"price":67674.3,"qty":0.00000000},{"price":67671.1,"qty":0.03149933}],"asks":[],"checksum":50765679,"timestamp":"2024-06-01T17:52:31.061135Z"}]}
{"channel":"book","type":"update","data":[{"symbol":"BTC/USDT","bids":[{"price":67676.0,"qty":0.00000000},{"price":67669.0,"qty":0.02212585}],"asks":[],"checksum":2103619948,"timestamp":"2024-06-01T17:52:31.063727Z"}]}
{"channel":"book","type":"update","data":[{"symbol":"BTC/USDT","bids":[{"price":67689.0,"qty":0.00000000},{"price":67667.5,"qty":0.05912289},{"price":67689.3,"qty":0.00092896}],"asks":[],"checksum":2143951444,"timestamp":"2024-06-01T17:52:31.072652Z"}]}
{"channel":"book","type":"update","data":[{"symbol":"BTC/USDT","bids":[],"asks":[{"price":67702.0,"qty":0.00000000},{"price":67710.1,"qty":0.05000000},{"price":67701.5,"qty":0.22170000}],"checksum":872740794,"timestamp":"2024-06-01T17:52:31.085970Z"}]}
{"channel":"book","type":"update","data":[{"symbol":"BTC/USDT","bids":[],"asks":[{"price":67695.7,"qty":0.14784031}],"checksum":1853642296,"timestamp":"2024-06-01T17:52:31.093181Z"}]}
{"channel":"book","type":"update","data":[{"symbol":"BTC/USDT","bids":[{"price":67690.5,"qty":0.05000000},{"price":67676.8,"qty":0.05329027}],"asks":[],"checksum":1655465071,"timestamp":"2024-06-01T17:52:31.100421Z"}]}
{"channel":"book","type":"update","data":[{"symbol":"BTC/USDT","bids":[{"price":67672.2,"qty":0.00000000},{"price":67669.0,"qty":0.02212585}],"asks":[],"checksum":3395238313,"timestamp":"2024-06-01T17:52:31.105555Z"}]}
{"channel":"book","type":"update","data":[{"symbol":"BTC/USDT","bids":[{"price":67672.6,"qty":0.04383510}],"asks":[],"checksum":4129254987,"timestamp":"2024-06-01T17:52:31.112924Z"}]}
{"channel":"book","type":"update","data":[{"symbol":"BTC/USDT","bids":[],"asks":[{"price":67690.6,"qty":0.22408365}],"checksum":2184317698,"timestamp":"2024-06-01T17:52:31.137008Z"}]}
{"channel":"book","type":"update","data":[{"symbol":"BTC/USDT","bids":[{"price":67689.3,"qty":0.00000000},{"price":67669.0,"qty":0.02212585}],"asks":[],"checksum":3130877571,"timestamp":"2024-06-01T17:52:31.137702Z"}]}
{"channel":"book","type":"update","data":[{"symbol":"BTC/USDT","bids":[{"price":67671.1,"qty":0.00000000},{"price":67667.6,"qty":0.14790154}],"asks":[],"checksum":370463690,"timestamp":"2024-06-01T17:52:31.156848Z"}]}
{"channel":"book","type":"update","data":[{"symbol":"BTC/USDT","bids":[{"price":67677.3,"qty":0.12011500}],"asks":[],"checksum":3644110590,"timestamp":"2024-06-01T17:52:31.173608Z"}]}
{"channel":"book","type":"update","data":[{"symbol":"BTC/USDT","bids":[{"price":67685.5,"qty":0.00000000},{"price":67667.6,"qty":0.14790154}],"asks":[],"checksum":3219133738,"timestamp":"2024-06-01T17:52:31.213109Z"}]}
{"channel":"book","type":"update","data":[{"symbol":"BTC/USDT","bids":[{"price":67676.9,"qty":0.15000000}],"asks":[],"checksum":581058111,"timestamp":"2024-06-01T17:52:31.213347Z"}]}
{"channel":"book","type":"update","data":[{"symbol":"BTC/USDT","bids":[{"price":67672.6,"qty":0.00000000},{"price":67667.5,"qty":0.05912289}],"asks":[],"checksum":853126233,"timestamp":"2024-06-01T17:52:31.225000Z"}]}
{"channel":"book","type":"update","data":[{"symbol":"BTC/USDT","bids":[{"price":67667.5,"qty":0.00000000},{"price":67664.6,"qty":0.09000000}],"asks":[],"checksum":1084009274,"timestamp":"2024-06-01T17:52:31.231498Z"}]}
{"channel":"book","type":"update","data":[{"symbol":"BTC/USDT","bids":[],"asks":[{"price":67690.6,"qty":0.26698365}],"checksum":3289834611,"timestamp":"2024-06-01T17:52:31.235280Z"}]}
{"channel":"book","type":"update","data":[{"symbol":"BTC/USDT","bids":[],"asks":[{"price":67695.6,"qty":0.07396000}],"checksum":2106432231,"timestamp":"2024-06-01T17:52:31.239749Z"}]}
{"channel":"book","type":"update","data":[{"symbol":"BTC/USDT","bids":[{"price":67690.5,"qty":0.00000000},{"price":67661.7,"qty":0.17734000}],"asks":[],"checksum":2573971394,"timestamp":"2024-06-01T17:52:31.250983Z"}]}
{"channel":"book","type":"update","data":[{"symbol":"BTC/USDT","bids":[{"price":67686.4,"qty":0.05000000}],"asks":[],"checksum":3058117029,"timestamp":"2024-06-01T17:52:31.251081Z"}]}
{"channel":"book","type":"update","data":[{"symbol":"BTC/USDT","bids":[{"price":67685.6,"qty":0.15000000}],"asks":[],"checksum":258982330,"timestamp":"2024-06-01T17:52:31.254517Z"}]}
{"channel":"book","type":"update","data":[{"symbol":"BTC/USDT","bids":[],"asks":[{"price":67687.3,"qty":0.09000000}],"checksum":472238620,"timestamp":"2024-06-01T17:52:31.261687Z"}]}
{"channel":"book","type":"update","data":[{"symbol":"BTC/USDT","bids":[],"asks":[{"price":67695.7,"qty":0.00000000},{"price":67702.1,"qty":0.19890820}],"checksum":484569726,"timestamp":"2024-06-01T17:52:31.274899Z"}]}
{"channel":"book","type":"update","data":[{"symbol":"BTC/USDT","bids":[{"price":67676.2,"qty":0.00000000},{"price":67664.6,"qty":0.09000000}],"asks":[],"checksum":3231321814,"timestamp":"2024-06-01T17:52:31.283505Z"}]}
{"channel":"book","type":"update","data":[{"symbol":"BTC/USDT","bids":[{"price":67676.3,"qty":1.63543501}],"asks":[],"checksum":1188471805,"timestamp":"2024-06-01T17:52:31.288384Z"}]}
{"channel":"book","type":"update","data":[{"symbol":"BTC/USDT","bids":[{"price":67676.9,"qty":0.00000000},{"price":67664.6,"qty":0.09000000}],"asks":[],"checksum":733995049,"timestamp":"2024-06-01T17:52:31.300263Z"}]}
{"channel":"book","type":"update","data":[{"symbol":"BTC/USDT","bids":[],"asks":[{"price":67687.2,"qty":0.03947498}],"checksum":1607249400,"timestamp":"2024-06-01T17:52:31.306326Z"}]}
{"channel":"book","type":"update","data":[{"symbol":"BTC/USDT","bids":[],"asks":[{"price":67686.5,"qty":0.09000000}],"checksum":3431757788,"timestamp":"2024-06-01T17:52:31.312746Z"}]}
{"channel":"book","type":"update","data":[{"symbol":"BTC/USDT","bids":[],"asks":[{"price":67690.6,"qty":0.17698365}],"checksum":3857560189,"timestamp":"2024-06-01T17:52:31.313287Z"}]}
{"channel":"book","type":"update","data":[{"symbol":"BTC/USDT","bids":[{"price":67677.3,"qty":0.00000000},{"price":67664.1,"qty":0.05311591}],"asks":[],"checksum":769763463,"timestamp":"2024-06-01T17:52:31.353844Z"}]}
{"channel":"book","type":"update","data":[{"symbol":"BTC/USDT","bids":[],"asks":[{"price":67690.6,"qty":0.13750867}],"checksum":3953310657,"timestamp":"2024-06-01T17:52:31.359172Z"}]}
{"channel":"book","type":"update","data":[{"symbol":"BTC/USDT","bids":[{"price":67669.0,"qty":0.00000000},{"price":67661.7,"qty":0.17734000}],"asks":[],"checksum":3429947120,"timestamp":"2024-06-01T17:52:31.401324Z"}]}
{"channel":"book","type":"update","data":[{"symbol":"BTC/USDT","bids":[],"asks":[{"price":67686.5,"qty":0.00000000},{"price":67701.7,"qty":0.19976708}],"checksum":970111160,"timestamp":"2024-06-01T17:52:31.404399Z"}]}
{"channel":"book","type":"update","data":[{"symbol":"BTC/USDT","bids":[],"asks":[{"price":67687.0,"qty":0.09000000}],"checksum":345521912,"timestamp":"2024-06-01T17:52:31.409477Z"}]}
{"channel":"book","type":"update","data":[{"symbol":"BTC/USDT","bids":[{"price":67665.6,"qty":0.02213992}],"asks":[],"checksum":2164359834,"timestamp":"2024-06-01T17:52:31.441604Z"}]}
{"channel":"book","type":"update","data":[{"symbol":"BTC/USDT","bids":[{"price":67674.6,"qty":0.12011500}],"asks":[],"checksum":2442775262,"timestamp":"2024-06-01T17:52:31.452262Z"}]}
{"channel":"book","type":"update","data":[{"symbol":"BTC/USDT","bids":[{"price":67686.4,"qty":0.09405954}],"asks":[],"checksum":2930215590,"timestamp":"2024-06-01T17:52:31.506185Z"}]}
{"channel":"book","type":"update","data":[{"symbol":"BTC/USDT","bids":[],"asks":[{"price":67686.9,"qty":0.03947498}],"checksum":2742780058,"timestamp":"2024-06-01T17:52:31.511173Z"}]}
{"channel":"book","type":"update","data":[{"symbol":"BTC/USDT","bids":[],"asks":[{"price":67686.6,"qty":0.09000000}],"checksum":2314599849,"timestamp":"2024-06-01T17:52:31.515238Z"}]}
{"channel":"book","type":"update","data":[{"symbol":"BTC/USDT","bids":[],"asks":[{"price":67687.3,"qty":0.00000000},{"price":67701.5,"qty":0.22170000}],"checksum":1581968950,"timestamp":"2024-06-01T17:52:31.515350Z"}]}
{"channel":"book","type":"update","data":[{"symbol":"BTC/USDT","bids":[{"price":67674.6,"qty":0.00000000},{"price":67664.1,"qty":0.05311591}],"asks":[],"checksum":3903910828,"timestamp":"2024-06-01T17:52:31.535067Z"}]}
{"channel":"book","type":"update","data":[{"symbol":"BTC/USDT","bids":[{"price":67664.2,"qty":0.05000000}],"asks":[],"checksum":3313074432,"timestamp":"2024-06-01T17:52:31.538937Z"}]}
{"channel":"book","type":"update","data":[{"symbol":"BTC/USDT","bids":[{"price":67686.4,"qty":0.05000000}],"asks":[],"checksum":1312760998,"timestamp":"2024-06-01T17:52:31.539446Z"}]}
{"channel":"book","type":"update","data":[{"symbol":"BTC/USDT","bids":[],"asks":[{"price":67687.2,"qty":0.00000000},{"price":67701.6,"qty":0.05328625}],"checksum":1799854019,"timestamp":"2024-06-01T17:52:31.543997Z"}]}
{"channel":"book","type":"update","data":[{"symbol":"BTC/USDT","bids":[],"asks":[{"price":67690.6,"qty":0.13290000}],"checksum":2987606347,"timestamp":"2024-06-01T17:52:31.565071Z"}]}
{"channel":"book","type":"update","data":[{"symbol":"BTC/USDT","bids":[],"asks":[{"price":67686.5,"qty":0.03947498}],"checksum":1077875172,"timestamp":"2024-06-01T17:52:31.593322Z"}]}
{"channel":"book","type":"update","data":[{"symbol":"BTC/USDT","bids":[],"asks":[{"price":67701.5,"qty":0.00000000},{"price":67701.6,"qty":0.05328625},{"price":67695.5,"qty":0.22170000}],"checksum":1574617907,"timestamp":"2024-06-01T17:52:31.596466Z"}]}
{"channel":"book","type":"update","data":[{"symbol":"BTC/USDT","bids":[],"asks":[{"price":67686.5,"qty":0.12947498}],"checksum":2539133374,"timestamp":"2024-06-01T17:52:31.601904Z"}]}
{"channel":"book","type":"update","data":[{"symbol":"BTC/USDT","bids":[],"asks":[{"price":67687.0,"qty":0.00000000},{"price":67701.6,"qty":0.05328625}],"checksum":3310437325,"timestamp":"2024-06-01T17:52:31.602153Z"}]}
{"channel":"book","type":"update","data":[{"symbol":"BTC/USDT","bids":[],"asks":[{"price":67686.6,"qty":0.00000000},{"price":67701.7,"qty":0.19976708}],"checksum":2662320717,"timestamp":"2024-06-01T17:52:31.602951Z"}]}
{"channel":"book","type":"update","data":[{"symbol":"BTC/USDT","bids":[{"price":67675.8,"qty":0.12011500}],"asks":[],"checksum":3315468979,"timestamp":"2024-06-01T17:52:31.633781Z"}]}
{"channel":"book","type":"update","data":[{"symbol":"BTC/USDT","bids":[],"asks":[{"price":67686.5,"qty":0.03947498}],"checksum":766844413,"timestamp":"2024-06-01T17:52:31.640370Z"}]}
{"channel":"book","type":"update","data":[{"symbol":"BTC/USDT","bids":[],"asks":[{"price":67695.6,"qty":0.00000000},{"price":67702.1,"qty":0.19890820},{"price":67695.4,"qty":0.07396000}],"checksum":2885390538,"timestamp":"2024-06-01T17:52:31.643716Z"}]}
{"channel":"book","type":"update","data":[{"symbol":"BTC/USDT","bids":[],"asks":[{"price":67686.5,"qty":0.00000000},{"price":67702.1,"qty":0.19890820}],"checksum":908920732,"timestamp":"2024-06-01T17:52:31.644780Z"}]}
{"channel":"book","type":"update","data":[{"symbol":"BTC/USDT","bids":[],"asks":[{"price":67695.0,"qty":0.00460867}],"checksum":2751308652,"timestamp":"2024-06-01T17:52:31.667453Z"}]}
{"channel":"book","type":"update","data":[{"symbol":"BTC/USDT","bids":[{"price":67676.8,"qty":0.00000000},{"price":67664.2,"qty":0.05000000}],"asks":[],"checksum":12994349,"timestamp":"2024-06-01T17:52:31.682474Z"}]}
{"channel":"book","type":"update","data":[{"symbol":"BTC/USDT","bids":[{"price":67671.0,"qty":0.04972930}],"asks":[],"checksum":2000838767,"timestamp":"2024-06-01T17:52:31.723637Z"}]}
{"channel":"book","type":"update","data":[{"symbol":"BTC/USDT","bids":[{"price":67671.0,"qty":0.00000000},{"price":67664.2,"qty":0.05000000}],"asks":[],"checksum":12994349,"timestamp":"2024-06-01T17:52:31.732007Z"}]}
{"channel":"book","type":"update","data":[{"symbol":"BTC/USDT","bids":[],"asks":[{"price":67701.6,"qty":0.00000000},{"price":67702.1,"qty":0.19890820},{"price":67686.5,"qty":0.05328396}],"checksum":3817982164,"timestamp":"2024-06-01T17:52:31.750096Z"}]}
{"channel":"book","type":"update","data":[{"symbol":"BTC/USDT","bids":[{"price":67676.8,"qty":0.00092896}],"asks":[],"checksum":3724412813,"timestamp":"2024-06-01T17:52:31.751494Z"}]}
{"channel":"book","type":"update","data":[{"symbol":"BTC/USDT","bids":[],"asks":[{"price":67690.6,"qty":0.04290000}],"checksum":3861246628,"timestamp":"2024-06-01T17:52:31.753648Z"}]}
{"channel":"book","type":"update","data":[{"symbol":"BTC/USDT","bids":[],"asks":[{"price":67686.5,"qty":0.09275894}],"checksum":2309811810,"timestamp":"2024-06-01T17:52:31.754388Z"}]}
{"channel":"book","type":"update","data":[{"symbol":"BTC/USDT","bids":[{"price":67686.4,"qty":0.09405954}],"asks":[],"checksum":1907466808,"timestamp":"2024-06-01T17:52:31.755935Z"}]}
{"channel":"book","type":"update","data":[{"symbol":"BTC/USDT","bids":[],"asks":[{"price":67695.0,"qty":0.00000000},{"price":67702.1,"qty":0.19890820}],"checksum":507607436,"timestamp":"2024-06-01T17:52:31.771410Z"}]}
{"channel":"book","type":"update","data":[{"symbol":"BTC/USDT","bids":[],"asks":[{"price":67690.6,"qty":0.00000000},{"price":67704.2,"qty":0.09000000}],"checksum":3852954668,"timestamp":"2024-06-01T17:52:31.861087Z"}]}
{"channel":"book","type":"update","data":[{"symbol":"BTC/USDT","bids":[],"asks":[{"price":67686.9,"qty":0.00000000},{"price":67710.1,"qty":0.05000000}],"checksum":904514201,"timestamp":"2024-06-01T17:52:31.865592Z"}]}
{"channel":"book","type":"update","data":[{"symbol":"BTC/USDT","bids":[{"price":67686.3,"qty":0.00000000},{"price":67661.7,"qty":0.17734000}],"asks":[],"checksum":568290202,"timestamp":"2024-06-01T17:52:31.866497Z"}]}
{"channel":"book","type":"update","data":[{"symbol":"BTC/USDT","bids":[{"price":67671.3,"qty":0.05264216}],"asks":[],"checksum":502007890,"timestamp":"2024-06-01T17:52:31.873890Z"}]}
{"channel":"book","type":"update","data":[{"symbol":"BTC/USDT","bids":[],"asks":[{"price":67700.8,"qty":0.00460867}],"checksum":937080723,"timestamp":"2024-06-01T17:52:31.874188Z"}]}
{"channel":"book","type":"update","data":[{"symbol":"BTC/USDT","bids":[{"price":67672.8,"qty":0.09000000}],"asks":[],"checksum":2898073119,"timestamp":"2024-06-01T17:52:31.879189Z"}]}
{"channel":"book","type":"update","data":[{"symbol":"BTC/USDT","bids":[{"price":67671.3,"qty":0.00000000},{"price":67664.6,"qty":0.09000000}],"asks":[],"checksum":221697653,"timestamp":"2024-06-01T17:52:31.880483Z"}]}
{"channel":"book","type":"update","data":[{"symbol":"BTC/USDT","bids":[{"price":67672.8,"qty":0.00000000},{"price":67661.7,"qty":0.17734000}],"asks":[],"checksum":3449204483,"timestamp":"2024-06-01T17:52:31.929581Z"}]}
{"channel":"book","type":"update","data":[{"symbol":"BTC/USDT","bids":[{"price":67665.6,"qty":0.00000000},{"price":67654.6,"qty":0.01106952}],"asks":[],"checksum":1416196435,"timestamp":"2024-06-01T17:52:31.976228Z"}]}
{"channel":"book","type":"update","data":[{"symbol":"BTC/USDT","bids":[{"price":67666.5,"qty":0.02213830}],"asks":[],"checksum":1971160124,"timestamp":"2024-06-01T17:52:32.016314Z"}]}
{"channel":"book","type":"update","data":[{"symbol":"BTC/USDT","bids":[{"price":67671.4,"qty":0.04560991}],"asks":[],"checksum":158337406,"timestamp":"2024-06-01T17:52:32.023706Z"}]}
{"channel":"book","type":"update","data":[{"symbol":"BTC/USDT","bids":[{"price":67671.4,"qty":0.00000000},{"price":67661.7,"qty":0.17734000}],"asks":[],"checksum":1971160124,"timestamp":"2024-06-01T17:52:32.029633Z"}]}
{"channel":"book","type":"update","data":[{"symbol":"BTC/USDT","bids":[],"asks":[{"price":67695.5,"qty":0.00000000},{"price":67710.1,"qty":0.05000000},{"price":67695.3,"qty":0.22170000}],"checksum":1389540403,"timestamp":"2024-06-01T17:52:32.125072Z"}]}
{"channel":"book","type":"update","data":[{"symbol":"BTC/USDT","bids":[{"price":67676.8,"qty":0.15092896}],"asks":[],"checksum":671475353,"timestamp":"2024-06-01T17:52:32.129936Z"}]}
{"channel":"book","type":"update","data":[{"symbol":"BTC/USDT","bids":[{"price":67685.6,"qty":0.00000000},{"price":67654.6,"qty":0.01106952}],"asks":[],"checksum":3557123519,"timestamp":"2024-06-01T17:52:32.129958Z"}]}
{"channel":"book","type":"update","data":[{"symbol":"BTC/USDT","bids":[{"price":67676.8,"qty":0.15000000},{"price":67676.9,"qty":0.00092896}],"asks":[],"checksum":3200485009,"timestamp":"2024-06-01T17:52:32.162004Z"}]}
{"channel":"book","type":"update","data":[{"symbol":"BTC/USDT","bids":[{"price":67671.4,"qty":0.05043724}],"asks":[],"checksum":101505527,"timestamp":"2024-06-01T17:52:32.173794Z"}]}
{"channel":"book","type":"update","data":[{"symbol":"BTC/USDT","bids":[{"price":67671.4,"qty":0.00000000},{"price":67661.7,"qty":0.17734000}],"asks":[],"checksum":3200485009,"timestamp":"2024-06-01T17:52:32.180384Z"}]}
{"channel":"book","type":"update","data":[{"symbol":"BTC/USDT","bids":[{"price":67677.0,"qty":0.01774328}],"asks":[],"checksum":646013037,"timestamp":"2024-06-01T17:52:32.186847Z"}]}
{"channel":"book","type":"update","data":[{"symbol":"BTC/USDT","bids":[{"price":67677.1,"qty":0.15000000}],"asks":[],"checksum":671448443,"timestamp":"2024-06-01T17:52:32.209976Z"}]}
{"channel":"book","type":"update","data":[{"symbol":"BTC/USDT","bids":[{"price":67677.0,"qty":0.00000000},{"price":67664.6,"qty":0.09000000}],"asks":[],"checksum":2621631010,"timestamp":"2024-06-01T17:52:32.213798Z"}]}
{"channel":"book","type":"update","data":[{"symbol":"BTC/USDT","bids":[{"price":67677.2,"qty":0.01774327}],"asks":[],"checksum":329624073,"timestamp":"2024-06-01T17:52:32.214077Z"}]}
{"channel":"book","type":"update","data":[{"symbol":"BTC/USDT","bids":[{"price":67676.8,"qty":0.00000000},{"price":67664.6,"qty":0.09000000}],"asks":[],"checksum":3336838858,"timestamp":"2024-06-01T17:52:32.214983Z"}]}
{"channel":"book","type":"update","data":[{"symbol":"BTC/USDT","bids":[{"price":67671.5,"qty":0.04992725}],"asks":[],"checksum":3498190310,"timestamp":"2024-06-01T17:52:32.324435Z"}]}
{"channel":"book","type":"update","data":[{"symbol":"BTC/USDT","bids":[{"price":67671.5,"qty":0.00000000},{"price":67664.6,"qty":0.09000000}],"asks":[],"checksum":3336838858,"timestamp":"2024-06-01T17:52:32.331117Z"}]}
{"channel":"book","type":"update","data":[{"symbol":"BTC/USDT","bids":[{"price":67676.9,"qty":0.00000000},{"price":67663.4,"qty":0.05912545}],"asks":[],"checksum":181816025,"timestamp":"2024-06-01T17:52:32.473937Z"}]}
{"channel":"book","type":"update","data":[{"symbol":"BTC/USDT","bids":[{"price":67671.5,"qty":0.04608311}],"asks":[],"checksum":3240663648,"timestamp":"2024-06-01T17:52:32.477411Z"}]}
{"channel":"book","type":"update","data":[{"symbol":"BTC/USDT","bids":[{"price":67677.3,"qty":0.15000000}],"asks":[],"checksum":3087510677,"timestamp":"2024-06-01T17:52:32.480163Z"}]}
{"channel":"book","type":"update","data":[{"symbol":"BTC/USDT","bids":[{"price":67671.5,"qty":0.00000000},{"price":67664.6,"qty":0.09000000}],"asks":[],"checksum":4214320934,"timestamp":"2024-06-01T17:52:32.483121Z"}]}
{"channel":"book","type":"update","data":[{"symbol":"BTC/USDT","bids":[{"price":67677.2,"qty":0.00000000},{"price":67663.4,"qty":0.05912545}],"asks":[],"checksum":2641013173,"timestamp":"2024-06-01T17:52:32.484229Z"}]}
{"channel":"book","type":"update","data":[{"symbol":"BTC/USDT","bids":[{"price":67666.5,"qty":0.00000000},{"price":67661.7,"qty":0.17734000}],"asks":[],"checksum":587488066,"timestamp":"2024-06-01T17:52:32.542387Z"}]}
{"channel":"book","type":"update","data":[{"symbol":"BTC/USDT","bids":[{"price":67667.4,"qty":0.02213739}],"asks":[],"checksum":2260922015,"timestamp":"2024-06-01T17:52:32.582856Z"}]}
{"channel":"book","type":"update","data":[{"symbol":"BTC/USDT","bids":[{"price":67671.5,"qty":0.04737452}],"asks":[],"checksum":3596180930,"timestamp":"2024-06-01T17:52:32.624822Z"}]}
{"channel":"book","type":"update","data":[{"symbol":"BTC/USDT","bids":[{"price":67671.5,"qty":0.00000000},{"price":67663.4,"qty":0.05912545}],"asks":[],"checksum":2260922015,"timestamp":"2024-06-01T17:52:32.633828Z"}]}
{"channel":"book","type":"update","data":[{"symbol":"BTC/USDT","bids":[{"price":67677.4,"qty":0.05328905}],"asks":[],"checksum":27533461,"timestamp":"2024-06-01T17:52:32.662747Z"}]}
{"channel":"book","type":"update","data":[{"symbol":"BTC/USDT","bids":[{"price":67677.1,"qty":0.00000000},{"price":67663.4,"qty":0.05912545}],"asks":[],"checksum":2153823374,"timestamp":"2024-06-01T17:52:32.667495Z"}]}
{"channel":"book","type":"update","data":[{"symbol":"BTC/USDT","bids":[{"price":67677.5,"qty":0.15000000}],"asks":[],"checksum":3181413556,"timestamp":"2024-06-01T17:52:32.667656Z"}]}
{"channel":"book","type":"update","data":[{"symbol":"BTC/USDT","bids":[{"price":67677.3,"qty":0.00000000},{"price":67663.4,"qty":0.05912545}],"asks":[],"checksum":3262366045,"timestamp":"2024-06-01T17:52:32.709666Z"}]}
{"channel":"book","type":"update","data":[{"symbol":"BTC/USDT","bids":[{"price":67671.5,"qty":0.04668402}],"asks":[],"checksum":3699147375,"timestamp":"2024-06-01T17:52:32.774711Z"}]}
{"channel":"book","type":"update","data":[{"symbol":"BTC/USDT","bids":[],"asks":[{"price":67690.5,"qty":0.14785153}],"checksum":1024472906,"timestamp":"2024-06-01T17:52:32.876841Z"}]}
{"channel":"book","type":"update","data":[{"symbol":"BTC/USDT","bids":[{"price":67676.7,"qty":1.01687723}],"asks":[],"checksum":2855619732,"timestamp":"2024-06-01T17:52:33.004710Z"}]}
{"channel":"book","type":"update","data":[{"symbol":"BTC/USDT","bids":[],"asks":[{"price":67686.5,"qty":0.18275894}],"checksum":1109285850,"timestamp":"2024-06-01T17:52:33.159503Z"}]}
{"channel":"book","type":"update","data":[{"symbol":"BTC/USDT","bids":[],"asks":[{"price":67686.5,"qty":0.27275894}],"checksum":4032193923,"timestamp":"2024-06-01T17:52:33.160068Z"}]}
{"channel":"book","type":"update","data":[{"symbol":"BTC/USDT","bids":[{"price":67676.7,"qty":0.00000000},{"price":67663.4,"qty":0.05912545}],"asks":[],"checksum":4213165454,"timestamp":"2024-06-01T17:52:33.178176Z"}]}
{"channel":"book","type":"update","data":[{"symbol":"BTC/USDT","bids":[{"price":67667.4,"qty":0.00000000},{"price":67661.7,"qty":0.17734000}],"asks":[],"checksum":1237952147,"timestamp":"2024-06-01T17:52:33.183282Z"}]}
{"channel":"book","type":"update","data":[{"symbol":"BTC/USDT","bids":[{"price":67668.9,"qty":0.02213677}],"asks":[],"checksum":1626357042,"timestamp":"2024-06-01T17:52:33.223589Z"}]}
{"channel":"book","type":"update","data":[{"symbol":"BTC/USDT","bids":[],"asks":[{"price":67686.5,"qty":0.18275894}],"checksum":1514525541,"timestamp":"2024-06-01T17:52:33.292970Z"}]}
{"channel":"book","type":"update","data":[{"symbol":"BTC/USDT","bids":[],"asks":[{"price":67686.5,"qty":0.09275894}],"checksum":2428963304,"timestamp":"2024-06-01T17:52:33.299065Z"}]}
{"channel":"book","type":"update","data":[{"symbol":"BTC/USDT","bids":[{"price":67677.4,"qty":0.00000000},{"price":67661.7,"qty":0.17734000},{"price":67677.6,"qty":0.05328899}],"asks":[],"checksum":3419329573,"timestamp":"2024-06-01T17:52:33.533899Z"}]}
{"channel":"book","type":"update","data":[{"symbol":"BTC/USDT","bids":[],"asks":[{"price":67686.5,"qty":0.14275894}],"checksum":675703091,"timestamp":"2024-06-01T17:52:33.537916Z"}]}
{"channel":"book","type":"update","data":[{"symbol":"BTC/USDT","bids":[{"price":67677.7,"qty":0.15000000}],"asks":[],"checksum":4049156002,"timestamp":"2024-06-01T17:52:33.538854Z"}]}
{"channel":"book","type":"update","data":[{"symbol":"BTC/USDT","bids":[],"asks":[{"price":67686.5,"qty":0.23275894}],"checksum":1093941545,"timestamp":"2024-06-01T17:52:33.540290Z"}]}
{"channel":"book","type":"update","data":[{"symbol":"BTC/USDT","bids":[],"asks":[{"price":67686.5,"qty":0.32275894}],"checksum":2254165016,"timestamp":"2024-06-01T17:52:33.540668Z"}]}
{"channel":"book","type":"update","data":[{"symbol":"BTC/USDT","bids":[],"asks":[{"price":67686.5,"qty":0.23275894}],"checksum":1093941545,"timestamp":"2024-06-01T17:52:33.598846Z"}]}
{"channel":"book","type":"update","data":[{"symbol":"BTC/USDT","bids":[{"price":67677.5,"qty":0.00000000},{"price":67663.4,"qty":0.05912545}],"asks":[],"checksum":3656911512,"timestamp":"2024-06-01T17:52:33.603198Z"}]}
{"channel":"book","type":"update","data":[{"symbol":"BTC/USDT","bids":[],"asks":[{"price":67686.5,"qty":0.14275894}],"checksum":1684972514,"timestamp":"2024-06-01T17:52:33.606272Z"}]}
{"channel":"book","type":"update","data":[{"symbol":"BTC/USDT","bids":[{"price":67668.9,"qty":0.00000000},{"price":67661.7,"qty":0.17734000}],"asks":[],"checksum":3474909913,"timestamp":"2024-06-01T17:52:33.825929Z"}]}
{"channel":"book","type":"update","data":[{"symbol":"BTC/USDT","bids":[{"price":67677.6,"qty":0.00000000},{"price":67660.9,"qty":0.02213712},{"price":67677.8,"qty":0.05328889}],"asks":[],"checksum":2358392970,"timestamp":"2024-06-01T17:52:34.364195Z"}]}
{"channel":"book","type":"update","data":[{"symbol":"BTC/USDT","bids":[{"price":67677.9,"qty":0.15000000}],"asks":[],"checksum":3593952646,"timestamp":"2024-06-01T17:52:34.369415Z"}]}
{"channel":"book","type":"update","data":[{"symbol":"BTC/USDT","bids":[],"asks":[{"price":67686.5,"qty":0.23275894}],"checksum":1717195533,"timestamp":"2024-06-01T17:52:34.372403Z"}]}
{"channel":"book","type":"update","data":[{"symbol":"BTC/USDT","bids":[],"asks":[{"price":67686.5,"qty":0.32275894}],"checksum":2704653884,"timestamp":"2024-06-01T17:52:34.372676Z"}]}
{"channel":"book","type":"update","data":[{"symbol":"BTC/USDT","bids":[],"asks":[{"price":67686.5,"qty":0.23275894}],"checksum":1717195533,"timestamp":"2024-06-01T17:52:34.590330Z"}]}
{"channel":"book","type":"update","data":[{"symbol":"BTC/USDT","bids":[],"asks":[{"price":67686.5,"qty":0.14275894}],"checksum":3593952646,"timestamp":"2024-06-01T17:52:34.590753Z"}]}
{"channel":"book","type":"update","data":[{"symbol":"BTC/USDT","bids":[],"asks":[{"price":67686.5,"qty":0.23275894}],"checksum":1717195533,"timestamp":"2024-06-01T17:52:34.593358Z"}]}
{"channel":"book","type":"update","data":[{"symbol":"BTC/USDT","bids":[],"asks":[{"price":67686.5,"qty":0.32275894}],"checksum":2704653884,"timestamp":"2024-06-01T17:52:34.594009Z"}]}
{"channel":"book","type":"update","data":[{"symbol":"BTC/USDT","bids":[{"price":67677.7,"qty":0.00000000},{"price":67661.7,"qty":0.19947712}],"asks":[],"checksum":1101027494,"timestamp":"2024-06-01T17:52:34.595149Z"}]}
{"channel":"book","type":"update","data":[{"symbol":"BTC/USDT","bids":[],"asks":[{"price":67686.5,"qty":0.23275894}],"checksum":2261759383,"timestamp":"2024-06-01T17:52:34.790984Z"}]}
{"channel":"book","type":"update","data":[{"symbol":"BTC/USDT","bids":[{"price":67661.7,"qty":0.17734000}],"asks":[],"checksum":3191184044,"timestamp":"2024-06-01T17:52:35.136092Z"}]}
{"channel":"book","type":"update","data":[{"symbol":"BTC/USDT","bids":[{"price":67677.8,"qty":0.00000000},{"price":67659.7,"qty":0.14791883},{"price":67678.0,"qty":0.05328931}],"asks":[],"checksum":1864862754,"timestamp":"2024-06-01T17:52:35.147883Z"}]}
{"channel":"book","type":"update","data":[{"symbol":"BTC/USDT","bids":[{"price":67678.1,"qty":0.15000000}],"asks":[],"checksum":3110883393,"timestamp":"2024-06-01T17:52:35.152751Z"}]}
{"channel":"book","type":"update","data":[{"symbol":"BTC/USDT","bids":[{"price":67677.9,"qty":0.00000000},{"price":67661.7,"qty":0.17734000}],"asks":[],"checksum":960080362,"timestamp":"2024-06-01T17:52:35.209494Z"}]}
{"channel":"book","type":"update","data":[{"symbol":"BTC/USDT","bids":[],"asks":[{"price":67686.5,"qty":0.32275894}],"checksum":4267066587,"timestamp":"2024-06-01T17:52:35.253751Z"}]}
{"channel":"book","type":"update","data":[{"symbol":"BTC/USDT","bids":[],"asks":[{"price":67686.5,"qty":0.23275894}],"checksum":960080362,"timestamp":"2024-06-01T17:52:35.810722Z"}]}
{"channel":"book","type":"update","data":[{"symbol":"BTC/USDT","bids":[],"asks":[{"price":67686.5,"qty":0.14275894}],"checksum":2304026465,"timestamp":"2024-06-01T17:52:35.811392Z"}]}
{"channel":"book","type":"update","data":[{"symbol":"BTC/USDT","bids":[{"price":67661.9,"qty":0.02213788}],"asks":[],"checksum":3075285328,"timestamp":"2024-06-01T17:52:35.816534Z"}]}
{"channel":"book","type":"update","data":[{"symbol":"BTC/USDT","bids":[{"price":67678.0,"qty":0.00000000},{"price":67661.7,"qty":0.17734000},{"price":67678.2,"qty":0.05328921}],"asks":[],"checksum":1487800847,"timestamp":"2024-06-01T17:52:35.895683Z"}]}
{"channel":"book","type":"update","data":[{"symbol":"BTC/USDT","bids":[{"price":67678.3,"qty":0.15000000}],"asks":[],"checksum":1522369007,"timestamp":"2024-06-01T17:52:35.901278Z"}]}
{"channel":"book","type":"update","data":[{"symbol":"BTC/USDT","bids":[],"asks":[{"price":67686.5,"qty":0.23275894}],"checksum":3939536740,"timestamp":"2024-06-01T17:52:35.902995Z"}]}
{"channel":"book","type":"update","data":[{"symbol":"BTC/USDT","bids":[],"asks":[{"price":67686.5,"qty":0.32275894}],"checksum":767517269,"timestamp":"2024-06-01T17:52:35.906813Z"}]}
{"channel":"book","type":"update","data":[{"symbol":"BTC/USDT","bids":[],"asks":[{"price":67686.5,"qty":0.23275894}],"checksum":3939536740,"timestamp":"2024-06-01T17:52:36.155807Z"}]}
{"channel":"book","type":"update","data":[{"symbol":"BTC/USDT","bids":[],"asks":[{"price":67686.5,"qty":0.14275894}],"checksum":1522369007,"timestamp":"2024-06-01T17:52:36.157066Z"}]}
{"channel":"book","type":"update","data":[{"symbol":"BTC/USDT","bids":[{"price":67678.1,"qty":0.00000000},{"price":67661.9,"qty":0.02213788}],"asks":[],"checksum":1436536270,"timestamp":"2024-06-01T17:52:36.160325Z"}]}
{"channel":"book","type":"update","data":[{"symbol":"BTC/USDT","bids":[{"price":67678.4,"qty":0.01774327}],"asks":[],"checksum":1342535044,"timestamp":"2024-06-01T17:52:36.160759Z"}]}
{"channel":"book","type":"update","data":[{"symbol":"BTC/USDT","bids":[],"asks":[{"price":67686.5,"qty":0.09275894}],"checksum":3012413586,"timestamp":"2024-06-01T17:52:36.188468Z"}]}
{"channel":"book","type":"update","data":[{"symbol":"BTC/USDT","bids":[{"price":67678.5,"qty":0.15000000}],"asks":[],"checksum":1369893199,"timestamp":"2024-06-01T17:52:36.193498Z"}]}
{"channel":"book","type":"update","data":[{"symbol":"BTC/USDT","bids":[{"price":67678.4,"qty":0.00000000},{"price":67663.4,"qty":0.05912545}],"asks":[],"checksum":1994321145,"timestamp":"2024-06-01T17:52:36.197889Z"}]}
{"channel":"book","type":"update","data":[{"symbol":"BTC/USDT","bids":[],"asks":[{"price":67700.8,"qty":0.00000000},{"price":67704.2,"qty":0.09000000}],"checksum":1596476618,"timestamp":"2024-06-01T17:52:36.207242Z"}]}
{"channel":"book","type":"update","data":[{"symbol":"BTC/USDT","bids":[{"price":67678.5,"qty":0.00000000},{"price":67661.9,"qty":0.02213788}],"asks":[],"checksum":2575227809,"timestamp":"2024-06-01T17:52:36.211180Z"}]}
{"channel":"book","type":"update","data":[{"symbol":"BTC/USDT","bids":[{"price":67661.9,"qty":0.00000000},{"price":67661.7,"qty":0.17734000}],"asks":[],"checksum":1136678417,"timestamp":"2024-06-01T17:52:36.314147Z"}]}
{"channel":"book","type":"update","data":[{"symbol":"BTC/USDT","bids":[{"price":67667.4,"qty":0.02214011}],"asks":[],"checksum":1961681973,"timestamp":"2024-06-01T17:52:36.354424Z"}]}
{"channel":"book","type":"update","data":[{"symbol":"BTC/USDT","bids":[],"asks":[{"price":67686.5,"qty":0.18275894}],"checksum":3878656370,"timestamp":"2024-06-01T17:52:36.374933Z"}]}
{"channel":"book","type":"update","data":[{"symbol":"BTC/USDT","bids":[],"asks":[{"price":67686.5,"qty":0.27275894}],"checksum":303753419,"timestamp":"2024-06-01T17:52:36.375653Z"}]}
{"channel":"book","type":"update","data":[{"symbol":"BTC/USDT","bids":[{"price":67663.4,"qty":0.00000000},{"price":67661.7,"qty":0.17734000}],"asks":[],"checksum":948549375,"timestamp":"2024-06-01T17:52:36.481262Z"}]}
{"channel":"book","type":"update","data":[{"symbol":"BTC/USDT","bids":[],"asks":[{"price":67686.5,"qty":0.32275894}],"checksum":3764477687,"timestamp":"2024-06-01T17:52:36.616973Z"}]}
{"channel":"book","type":"update","data":[{"symbol":"BTC/USDT","bids":[{"price":67678.2,"qty":0.00000000},{"price":67661.6,"qty":0.00460867},{"price":67678.4,"qty":0.05328870}],"asks":[],"checksum":299279963,"timestamp":"2024-06-01T17:52:36.676288Z"}]}
{"channel":"book","type":"update","data":[{"symbol":"BTC/USDT","bids":[{"price":67678.5,"qty":0.15000000}],"asks":[],"checksum":577551772,"timestamp":"2024-06-01T17:52:36.685400Z"}]}
{"channel":"book","type":"update","data":[{"symbol":"BTC/USDT","bids":[{"price":67678.3,"qty":0.00000000},{"price":67661.7,"qty":0.17734000}],"asks":[],"checksum":4238489190,"timestamp":"2024-06-01T17:52:36.710886Z"}]}
{"channel":"book","type":"update","data":[{"symbol":"BTC/USDT","bids":[{"price":67663.2,"qty":0.05912540}],"asks":[],"checksum":4006949946,"timestamp":"2024-06-01T17:52:36.746906Z"}]}
{"channel":"book","type":"update","data":[{"symbol":"BTC/USDT","bids":[{"price":67667.4,"qty":0.00000000},{"price":67661.7,"qty":0.17734000}],"asks":[],"checksum":2633898900,"timestamp":"2024-06-01T17:52:36.924602Z"}]}
{"channel":"book","type":"update","data":[{"symbol":"BTC/USDT","bids":[{"price":67668.2,"qty":0.02213970}],"asks":[],"checksum":4011703937,"timestamp":"2024-06-01T17:52:36.964966Z"}]}
{"channel":"book","type":"update","data":[{"symbol":"BTC/USDT","bids":[{"price":67663.2,"qty":0.00000000},{"price":67661.7,"qty":0.17734000}],"asks":[],"checksum":2685441256,"timestamp":"2024-06-01T17:52:37.022753Z"}]}
{"channel":"book","type":"update","data":[{"symbol":"BTC/USDT","bids":[],"asks":[{"price":67699.1,"qty":0.00460867}],"checksum":2316839476,"timestamp":"2024-06-01T17:52:37.230236Z"}]}
{"channel":"book","type":"update","data":[{"symbol":"BTC/USDT","bids":[{"price":67663.2,"qty":0.05912536}],"asks":[],"checksum":782943624,"timestamp":"2024-06-01T17:52:37.294741Z"}]}
{"channel":"book","type":"update","data":[{"symbol":"BTC/USDT","bids":[{"price":67678.4,"qty":0.00000000},{"price":67661.7,"qty":0.17734000},{"price":67678.6,"qty":0.05328852}],"asks":[],"checksum":207772087,"timestamp":"2024-06-01T17:52:37.405218Z"}]}
{"channel":"book","type":"update","data":[{"symbol":"BTC/USDT","bids":[{"price":67678.7,"qty":0.15000000}],"asks":[],"checksum":3488330556,"timestamp":"2024-06-01T17:52:37.410628Z"}]}
{"channel":"book","type":"update","data":[{"symbol":"BTC/USDT","bids":[{"price":67668.2,"qty":0.00000000},{"price":67663.2,"qty":0.05912536}],"asks":[],"checksum":3622632966,"timestamp":"2024-06-01T17:52:37.536363Z"}]}
{"channel":"book","type":"update","data":[{"symbol":"BTC/USDT","bids":[{"price":67668.4,"qty":0.02213908}],"asks":[],"checksum":2442045398,"timestamp":"2024-06-01T17:52:37.576531Z"}]}
{"channel":"book","type":"update","data":[{"symbol":"BTC/USDT","bids":[{"price":67678.5,"qty":0.00000000},{"price":67663.2,"qty":0.05912536}],"asks":[],"checksum":710678669,"timestamp":"2024-06-01T17:52:37.712610Z"}]}
{"channel":"book","type":"update","data":[{"symbol":"BTC/USDT","bids":[{"price":67663.2,"qty":0.00000000},{"price":67661.7,"qty":0.17734000}],"asks":[],"checksum":4202047590,"timestamp":"2024-06-01T17:52:37.897050Z"}]}
{"channel":"book","type":"update","data":[{"symbol":"BTC/USDT","bids":[],"asks":[{"price":67686.5,"qty":0.23275894}],"checksum":1025099095,"timestamp":"2024-06-01T17:52:37.970666Z"}]}
{"channel":"book","type":"update","data":[{"symbol":"BTC/USDT","bids":[],"asks":[{"price":67686.5,"qty":0.14275894}],"checksum":2373241820,"timestamp":"2024-06-01T17:52:37.970754Z"}]}
{"channel":"book","type":"update","data":[{"symbol":"BTC/USDT","bids":[{"price":67672.8,"qty":0.09000000}],"asks":[],"checksum":3471676016,"timestamp":"2024-06-01T17:52:37.987570Z"}]}
{"channel":"book","type":"update","data":[{"symbol":"BTC/USDT","bids":[],"asks":[{"price":67686.5,"qty":0.09275894}],"checksum":761605990,"timestamp":"2024-06-01T17:52:38.000790Z"}]}
{"channel":"book","type":"update","data":[{"symbol":"BTC/USDT","bids":[{"price":67686.4,"qty":0.14405954}],"asks":[],"checksum":2978965758,"timestamp":"2024-06-01T17:52:38.010273Z"}]}
{"channel":"book","type":"update","data":[{"symbol":"BTC/USDT","bids":[],"asks":[{"price":67695.4,"qty":0.00000000},{"price":67703.3,"qty":0.12011500}],"checksum":3258012300,"timestamp":"2024-06-01T17:52:38.041023Z"}]}
{"channel":"book","type":"update","data":[{"symbol":"BTC/USDT","bids":[],"asks":[{"price":67695.3,"qty":0.00000000},{"price":67704.2,"qty":0.09000000},{"price":67697.3,"qty":0.22170000}],"checksum":906205225,"timestamp":"2024-06-01T17:52:38.044500Z"}]}
{"channel":"book","type":"update","data":[{"symbol":"BTC/USDT","bids":[{"price":67668.4,"qty":0.00000000},{"price":67661.7,"qty":0.17734000}],"asks":[],"checksum":2906955930,"timestamp":"2024-06-01T17:52:38.076989Z"}]}
{"channel":"book","type":"update","data":[{"symbol":"BTC/USDT","bids":[],"asks":[{"price":67697.9,"qty":0.07396000}],"checksum":1037778406,"timestamp":"2024-06-01T17:52:38.080628Z"}]}
{"channel":"book","type":"update","data":[{"symbol":"BTC/USDT","bids":[],"asks":[{"price":67699.1,"qty":0.00000000},{"price":67703.3,"qty":0.12011500}],"checksum":1599913088,"timestamp":"2024-06-01T17:52:38.100842Z"}]}
{"channel":"book","type":"update","data":[{"symbol":"BTC/USDT","bids":[{"price":67678.6,"qty":0.00000000},{"price":67661.6,"qty":0.00460867},{"price":67678.8,"qty":0.05328835}],"asks":[],"checksum":3662575611,"timestamp":"2024-06-01T17:52:38.109762Z"}]}
{"channel":"book","type":"update","data":[{"symbol":"BTC/USDT","bids":[{"price":67668.5,"qty":0.02213908}],"asks":[],"checksum":2755587254,"timestamp":"2024-06-01T17:52:38.117278Z"}]}
{"channel":"book","type":"update","data":[{"symbol":"BTC/USDT","bids":[],"asks":[{"price":67703.2,"qty":0.00460867}],"checksum":903710790,"timestamp":"2024-06-01T17:52:38.203332Z"}]}
{"channel":"book","type":"update","data":[{"symbol":"BTC/USDT","bids":[{"price":67672.8,"qty":0.00000000},{"price":67663.5,"qty":0.05912512}],"asks":[],"checksum":1350128528,"timestamp":"2024-06-01T17:52:38.228399Z"}]}
{"channel":"book","type":"update","data":[{"symbol":"BTC/USDT","bids":[{"price":67686.4,"qty":0.09405954}],"asks":[],"checksum":3585428776,"timestamp":"2024-06-01T17:52:38.435162Z"}]}
{"channel":"book","type":"update","data":[{"symbol":"BTC/USDT","bids":[{"price":67678.9,"qty":0.15000000}],"asks":[],"checksum":667354163,"timestamp":"2024-06-01T17:52:38.439674Z"}]}
{"channel":"book","type":"update","data":[{"symbol":"BTC/USDT","bids":[{"price":67668.5,"qty":0.00000000},{"price":67663.5,"qty":0.05912512}],"asks":[],"checksum":3252777471,"timestamp":"2024-06-01T17:52:38.687888Z"}]}
{"channel":"book","type":"update","data":[{"symbol":"BTC/USDT","bids":[{"price":67672.8,"qty":0.09000000}],"asks":[],"checksum":1857315783,"timestamp":"2024-06-01T17:52:38.708207Z"}]}
{"channel":"book","type":"update","data":[{"symbol":"BTC/USDT","bids":[{"price":67678.7,"qty":0.00000000},{"price":67663.5,"qty":0.05912512}],"asks":[],"checksum":3847537637,"timestamp":"2024-06-01T17:52:38.711086Z"}]}
{"channel":"book","type":"update","data":[{"symbol":"BTC/USDT","bids":[{"price":67678.8,"qty":0.00000000},{"price":67661.7,"qty":0.17734000},{"price":67679.0,"qty":0.05328800}],"asks":[],"checksum":995656848,"timestamp":"2024-06-01T17:52:38.830447Z"}]}
{"channel":"book","type":"update","data":[{"symbol":"BTC/USDT","bids":[{"price":67679.1,"qty":0.15000000}],"asks":[],"checksum":1758809290,"timestamp":"2024-06-01T17:52:38.835522Z"}]}
{"channel":"book","type":"update","data":[{"symbol":"BTC/USDT","bids":[{"price":67672.8,"qty":0.00000000},{"price":67663.5,"qty":0.05912512}],"asks":[],"checksum":3347078898,"timestamp":"2024-06-01T17:52:38.964179Z"}]}
{"channel":"book","type":"update","data":[{"symbol":"BTC/USDT","bids":[{"price":67672.8,"qty":0.09000000}],"asks":[],"checksum":1758809290,"timestamp":"2024-06-01T17:52:39.028859Z"}]}
{"channel":"book","type":"update","data":[{"symbol":"BTC/USDT","bids":[{"price":67678.9,"qty":0.00000000},{"price":67663.5,"qty":0.05912512}],"asks":[],"checksum":1622330013,"timestamp":"2024-06-01T17:52:39.209917Z"}]}
{"channel":"book","type":"update","data":[{"symbol":"BTC/USDT","bids":[{"price":67668.5,"qty":0.02213948}],"asks":[],"checksum":216586802,"timestamp":"2024-06-01T17:52:39.371354Z"}]}
{"channel":"book","type":"update","data":[{"symbol":"BTC/USDT","bids":[{"price":67679.0,"qty":0.00000000},{"price":67663.5,"qty":0.05912512},{"price":67679.2,"qty":0.05328780}],"asks":[],"checksum":3306935993,"timestamp":"2024-06-01T17:52:39.512464Z"}]}
{"channel":"book","type":"update","data":[{"symbol":"BTC/USDT","bids":[{"price":67679.3,"qty":0.15000000}],"asks":[],"checksum":1567398612,"timestamp":"2024-06-01T17:52:39.517115Z"}]}
{"channel":"book","type":"update","data":[{"symbol":"BTC/USDT","bids":[],"asks":[{"price":67686.5,"qty":0.14275894}],"checksum":2841356088,"timestamp":"2024-06-01T17:52:39.558461Z"}]}
{"channel":"book","type":"update","data":[{"symbol":"BTC/USDT","bids":[],"asks":[{"price":67686.5,"qty":0.09275894}],"checksum":1567398612,"timestamp":"2024-06-01T17:52:39.562350Z"}]}
{"channel":"book","type":"update","data":[{"symbol":"BTC/USDT","bids":[{"price":67679.1,"qty":0.00000000},{"price":67664.6,"qty":0.09000000}],"asks":[],"checksum":2938633577,"timestamp":"2024-06-01T17:52:39.563059Z"}]}
{"channel":"book","type":"update","data":[{"symbol":"BTC/USDT","bids":[{"price":67686.4,"qty":0.14405954}],"asks":[],"checksum":720102353,"timestamp":"2024-06-01T17:52:39.799555Z"}]}
{"channel":"book","type":"update","data":[{"symbol":"BTC/USDT","bids":[{"price":67668.5,"qty":0.00000000},{"price":67663.5,"qty":0.05912512}],"asks":[],"checksum":1186067326,"timestamp":"2024-06-01T17:52:39.872686Z"}]}
{"channel":"book","type":"update","data":[{"symbol":"BTC/USDT","bids":[{"price":67669.1,"qty":0.02213905}],"asks":[],"checksum":314349202,"timestamp":"2024-06-01T17:52:39.912930Z"}]}
{"channel":"book","type":"update","data":[{"symbol":"BTC/USDT","bids":[{"price":67669.1,"qty":0.00000000},{"price":67663.5,"qty":0.05912512}],"asks":[],"checksum":1186067326,"timestamp":"2024-06-01T17:52:39.989857Z"}]}
{"channel":"book","type":"update","data":[{"symbol":"BTC/USDT","bids":[{"price":67679.2,"qty":0.00000000},{"price":67661.7,"qty":0.17734000},{"price":67679.4,"qty":0.05328762}],"asks":[],"checksum":2143633499,"timestamp":"2024-06-01T17:52:40.147818Z"}]}
{"channel":"book","type":"update","data":[{"symbol":"BTC/USDT","bids":[{"price":67670.2,"qty":0.02215727}],"asks":[],"checksum":2878356447,"timestamp":"2024-06-01T17:52:40.527332Z"}]}
{"channel":"book","type":"update","data":[{"symbol":"BTC/USDT","bids":[{"price":67672.8,"qty":0.00000000},{"price":67663.5,"qty":0.05912512}],"asks":[],"checksum":4181596526,"timestamp":"2024-06-01T17:52:40.782617Z"}]}
{"channel":"book","type":"update","data":[{"symbol":"BTC/USDT","bids":[{"price":67686.4,"qty":0.09405954}],"asks":[],"checksum":2096236502,"timestamp":"2024-06-01T17:52:40.913430Z"}]}
{"channel":"book","type":"update","data":[{"symbol":"BTC/USDT","bids":[{"price":67679.5,"qty":0.15000000}],"asks":[],"checksum":948980831,"timestamp":"2024-06-01T17:52:40.919001Z"}]}
{"channel":"book","type":"update","data":[{"symbol":"BTC/USDT","bids":[{"price":67679.4,"qty":0.00000000},{"price":67663.5,"qty":0.05912512},{"price":67679.6,"qty":0.05328786}],"asks":[],"checksum":1381084855,"timestamp":"2024-06-01T17:52:40.970027Z"}]}
{"channel":"book","type":"update","data":[{"symbol":"BTC/USDT","bids":[{"price":67679.5,"qty":0.00000000},{"price":67663.5,"qty":0.05912512}],"asks":[],"checksum":3856994740,"timestamp":"2024-06-01T17:52:40.975127Z"}]}
{"channel":"book","type":"update","data":[{"symbol":"BTC/USDT","bids":[{"price":67679.7,"qty":0.15000000}],"asks":[],"checksum":226883627,"timestamp":"2024-06-01T17:52:40.975233Z"}]}
{"channel":"book","type":"update","data":[{"symbol":"BTC/USDT","bids":[{"price":67670.2,"qty":0.00000000},{"price":67663.5,"qty":0.05912512}],"asks":[],"checksum":3654321071,"timestamp":"2024-06-01T17:52:41.065751Z"}]}
{"channel":"book","type":"update","data":[{"symbol":"BTC/USDT","bids":[{"price":67672.8,"qty":0.09000000}],"asks":[],"checksum":1988465047,"timestamp":"2024-06-01T17:52:41.091770Z"}]}
{"channel":"book","type":"update","data":[{"symbol":"BTC/USDT","bids":[{"price":67670.9,"qty":0.02215712}],"asks":[],"checksum":2862666642,"timestamp":"2024-06-01T17:52:41.105791Z"}]}
{"channel":"book","type":"update","data":[{"symbol":"BTC/USDT","bids":[{"price":67672.8,"qty":0.00000000},{"price":67664.6,"qty":0.09000000}],"asks":[],"checksum":3333912490,"timestamp":"2024-06-01T17:52:41.110412Z"}]}
{"channel":"book","type":"update","data":[{"symbol":"BTC/USDT","bids":[{"price":67686.4,"qty":0.14405954}],"asks":[],"checksum":59277322,"timestamp":"2024-06-01T17:52:41.134529Z"}]}
{"channel":"book","type":"update","data":[{"symbol":"BTC/USDT","bids":[{"price":67679.7,"qty":0.00000000},{"price":67663.5,"qty":0.05912512}],"asks":[],"checksum":4292805764,"timestamp":"2024-06-01T17:52:41.139074Z"}]}
{"channel":"book","type":"update","data":[{"symbol":"BTC/USDT","bids":[{"price":67679.6,"qty":0.00000000},{"price":67661.7,"qty":0.17734000},{"price":67679.4,"qty":0.05328802}],"asks":[],"checksum":1727326852,"timestamp":"2024-06-01T17:52:41.212939Z"}]}
{"channel":"book","type":"update","data":[{"symbol":"BTC/USDT","bids":[{"price":67670.9,"qty":0.00000000},{"price":67661.7,"qty":0.17734000}],"asks":[],"checksum":3207572593,"timestamp":"2024-06-01T17:52:41.633925Z"}]}
{"channel":"book","type":"update","data":[{"symbol":"BTC/USDT","bids":[{"price":67671.0,"qty":0.02215752}],"asks":[],"checksum":1952241663,"timestamp":"2024-06-01T17:52:42.136224Z"}]}
{"channel":"book","type":"update","data":[{"symbol":"BTC/USDT","bids":[{"price":67672.8,"qty":0.09000000}],"asks":[],"checksum":1206044535,"timestamp":"2024-06-01T17:52:42.303791Z"}]}
{"channel":"book","type":"update","data":[{"symbol":"BTC/USDT","bids":[],"asks":[{"price":67697.2,"qty":0.05253703}],"checksum":386449801,"timestamp":"2024-06-01T17:52:42.403314Z"}]}
{"channel":"book","type":"update","data":[{"symbol":"BTC/USDT","bids":[],"asks":[{"price":67697.3,"qty":0.00000000},{"price":67703.2,"qty":0.00460867},{"price":67697.1,"qty":0.22170000}],"checksum":1868628063,"timestamp":"2024-06-01T17:52:42.406599Z"}]}
{"channel":"book","type":"update","data":[{"symbol":"BTC/USDT","bids":[],"asks":[{"price":67686.5,"qty":0.03947498},{"price":67690.4,"qty":0.05328459}],"checksum":1593933315,"timestamp":"2024-06-01T17:52:42.460018Z"}]}
{"channel":"book","type":"update","data":[{"symbol":"BTC/USDT","bids":[],"asks":[{"price":67686.5,"qty":0.00000000},{"price":67702.1,"qty":0.19890820}],"checksum":1382291633,"timestamp":"2024-06-01T17:52:42.464381Z"}]}
{"channel":"book","type":"update","data":[{"symbol":"BTC/USDT","bids":[],"asks":[{"price":67690.3,"qty":0.03947498}],"checksum":2462091832,"timestamp":"2024-06-01T17:52:42.464469Z"}]}
{"channel":"book","type":"update","data":[{"symbol":"BTC/USDT","bids":[],"asks":[{"price":67690.8,"qty":0.00028854}],"checksum":3008066852,"timestamp":"2024-06-01T17:52:42.626838Z"}]}
{"channel":"book","type":"update","data":[{"symbol":"BTC/USDT","bids":[],"asks":[{"price":67697.9,"qty":0.00000000},{"price":67702.1,"qty":0.19890820}],"checksum":2088149190,"timestamp":"2024-06-01T17:52:42.651383Z"}]}
{"channel":"book","type":"update","data":[{"symbol":"BTC/USDT","bids":[],"asks":[{"price":67690.4,"qty":0.00000000},{"price":67703.3,"qty":0.12011500},{"price":67690.2,"qty":0.05328459}],"checksum":3531473269,"timestamp":"2024-06-01T17:52:43.064805Z"}]}
{"channel":"book","type":"update","data":[{"symbol":"BTC/USDT","bids":[],"asks":[{"price":67700.4,"qty":0.07396000}],"checksum":223040330,"timestamp":"2024-06-01T17:52:43.067692Z"}]}
{"channel":"book","type":"update","data":[{"symbol":"BTC/USDT","bids":[{"price":67672.8,"qty":0.00000000},{"price":67663.5,"qty":0.05912512}],"asks":[],"checksum":1056261058,"timestamp":"2024-06-01T17:52:43.068258Z"}]}
{"channel":"book","type":"update","data":[{"symbol":"BTC/USDT","bids":[],"asks":[{"price":67690.1,"qty":0.03947498}],"checksum":1221455378,"timestamp":"2024-06-01T17:52:43.069275Z"}]}
{"channel":"book","type":"update","data":[{"symbol":"BTC/USDT","bids":[{"price":67672.8,"qty":0.09000000}],"asks":[],"checksum":2071199386,"timestamp":"2024-06-01T17:52:43.075311Z"}]}
{"channel":"book","type":"update","data":[{"symbol":"BTC/USDT","bids":[{"price":67666.3,"qty":0.14790422}],"asks":[],"checksum":1184269802,"timestamp":"2024-06-01T17:52:43.082640Z"}]}
{"channel":"book","type":"update","data":[{"symbol":"BTC/USDT","bids":[],"asks":[{"price":67690.3,"qty":0.00000000},{"price":67701.7,"qty":0.19976708}],"checksum":1644870597,"timestamp":"2024-06-01T17:52:43.090771Z"}]}
{"channel":"book","type":"update","data":[{"symbol":"BTC/USDT","bids":[{"price":67679.5,"qty":0.00092896}],"asks":[],"checksum":636174069,"timestamp":"2024-06-01T17:52:43.143329Z"}]}
{"channel":"book","type":"update","data":[{"symbol":"BTC/USDT","bids":[{"price":67671.0,"qty":0.00000000},{"price":67666.3,"qty":0.14790422}],"asks":[],"checksum":2937832855,"timestamp":"2024-06-01T17:52:43.237206Z"}]}
{"channel":"book","type":"update","data":[{"symbol":"BTC/USDT","bids":[{"price":67671.5,"qty":0.06884119}],"asks":[],"checksum":1586576370,"timestamp":"2024-06-01T17:52:43.281144Z"}]}
{"channel":"book","type":"update","data":[{"symbol":"BTC/USDT","bids":[],"asks":[{"price":67690.2,"qty":0.00000000},{"price":67702.1,"qty":0.19890820},{"price":67690.0,"qty":0.05328458}],"checksum":2903903214,"timestamp":"2024-06-01T17:52:43.636622Z"}]}
{"channel":"book","type":"update","data":[{"symbol":"BTC/USDT","bids":[],"asks":[{"price":67689.9,"qty":0.03947498}],"checksum":826619821,"timestamp":"2024-06-01T17:52:43.641078Z"}]}
{"channel":"book","type":"update","data":[{"symbol":"BTC/USDT","bids":[{"price":67671.5,"qty":0.04668402}],"asks":[],"checksum":3234843080,"timestamp":"2024-06-01T17:52:43.938571Z"}]}
{"channel":"book","type":"update","data":[{"symbol":"BTC/USDT","bids":[{"price":67671.2,"qty":0.02215883}],"asks":[],"checksum":3393228472,"timestamp":"2024-06-01T17:52:43.978744Z"}]}
{"channel":"book","type":"update","data":[{"symbol":"BTC/USDT","bids":[],"asks":[{"price":67690.1,"qty":0.00000000},{"price":67701.7,"qty":0.19976708}],"checksum":1380171891,"timestamp":"2024-06-01T17:52:44.091875Z"}]}
{"channel":"book","type":"update","data":[{"symbol":"BTC/USDT","bids":[],"asks":[{"price":67690.0,"qty":0.00000000},{"price":67702.1,"qty":0.19890820},{"price":67689.8,"qty":0.05328458}],"checksum":3695398740,"timestamp":"2024-06-01T17:52:44.246755Z"}]}
{"channel":"book","type":"update","data":[{"symbol":"BTC/USDT","bids":[],"asks":[{"price":67689.7,"qty":0.03947498}],"checksum":3756409050,"timestamp":"2024-06-01T17:52:44.251299Z"}]}
{"channel":"book","type":"update","data":[{"symbol":"BTC/USDT","bids":[{"price":67672.8,"qty":0.00000000},{"price":67666.3,"qty":0.14790422}],"asks":[],"checksum":2197067506,"timestamp":"2024-06-01T17:52:44.252051Z"}]}
{"channel":"book","type":"update","data":[{"symbol":"BTC/USDT","bids":[{"price":67672.8,"qty":0.09000000}],"asks":[],"checksum":3756409050,"timestamp":"2024-06-01T17:52:44.257436Z"}]}
{"channel":"book","type":"update","data":[{"symbol":"BTC/USDT","bids":[{"price":67671.2,"qty":0.00000000},{"price":67666.3,"qty":0.14790422}],"asks":[],"checksum":1667657586,"timestamp":"2024-06-01T17:52:44.508928Z"}]}
{"channel":"book","type":"update","data":[{"symbol":"BTC/USDT","bids":[{"price":67672.5,"qty":0.02216012}],"asks":[],"checksum":1109336370,"timestamp":"2024-06-01T17:52:44.549167Z"}]}
{"channel":"book","type":"update","data":[{"symbol":"BTC/USDT","bids":[],"asks":[{"price":67689.9,"qty":0.00000000},{"price":67701.7,"qty":0.19976708}],"checksum":2172928774,"timestamp":"2024-06-01T17:52:44.589771Z"}]}
{"channel":"book","type":"update","data":[{"symbol":"BTC/USDT","bids":[],"asks":[{"price":67689.8,"qty":0.00000000},{"price":67702.1,"qty":0.19890820},{"price":67689.6,"qty":0.05328437}],"checksum":1447590921,"timestamp":"2024-06-01T17:52:44.807047Z"}]}
{"channel":"book","type":"update","data":[{"symbol":"BTC/USDT","bids":[{"price":67672.8,"qty":0.00000000},{"price":67666.3,"qty":0.14790422}],"asks":[],"checksum":400440699,"timestamp":"2024-06-01T17:52:44.811283Z"}]}
{"channel":"book","type":"update","data":[{"symbol":"BTC/USDT","bids":[],"asks":[{"price":67689.5,"qty":0.03947498}],"checksum":30893419,"timestamp":"2024-06-01T17:52:44.811529Z"}]}
{"channel":"book","type":"update","data":[{"symbol":"BTC/USDT","bids":[{"price":67672.8,"qty":0.09000000}],"asks":[],"checksum":870263254,"timestamp":"2024-06-01T17:52:44.815651Z"}]}
{"channel":"book","type":"update","data":[{"symbol":"BTC/USDT","bids":[{"price":67679.5,"qty":0.00000000},{"price":67666.3,"qty":0.14790422}],"asks":[],"checksum":4127226950,"timestamp":"2024-06-01T17:52:44.829541Z"}]}
{"channel":"book","type":"update","data":[{"symbol":"BTC/USDT","bids":[{"price":67672.5,"qty":0.00000000},{"price":67664.6,"qty":0.09000000}],"asks":[],"checksum":798506036,"timestamp":"2024-06-01T17:52:45.080912Z"}]}
{"channel":"book","type":"update","data":[{"symbol":"BTC/USDT","bids":[],"asks":[{"price":67689.7,"qty":0.00000000},{"price":67701.7,"qty":0.19976708}],"checksum":4062392462,"timestamp":"2024-06-01T17:52:45.092900Z"}]}
{"channel":"book","type":"update","data":[{"symbol":"BTC/USDT","bids":[{"price":67672.7,"qty":0.02216027}],"asks":[],"checksum":3449568040,"timestamp":"2024-06-01T17:52:45.121326Z"}]}
{"channel":"book","type":"update","data":[{"symbol":"BTC/USDT","bids":[],"asks":[{"price":67697.2,"qty":0.00000000},{"price":67702.1,"qty":0.19890820}],"checksum":3174614251,"timestamp":"2024-06-01T17:52:45.212138Z"}]}
{"channel":"book","type":"update","data":[{"symbol":"BTC/USDT","bids":[],"asks":[{"price":67697.1,"qty":0.00000000},{"price":67703.3,"qty":0.12011500},{"price":67697.3,"qty":0.22170000}],"checksum":3320978737,"timestamp":"2024-06-01T17:52:45.215466Z"}]}
{"channel":"book","type":"update","data":[{"symbol":"BTC/USDT","bids":[],"asks":[{"price":67697.0,"qty":0.09847303}],"checksum":909406545,"timestamp":"2024-06-01T17:52:45.216533Z"}]}
{"channel":"book","type":"update","data":[{"symbol":"BTC/USDT","bids":[],"asks":[{"price":67689.6,"qty":0.00000000},{"price":67702.1,"qty":0.19890820},{"price":67689.4,"qty":0.05328437}],"checksum":1750703006,"timestamp":"2024-06-01T17:52:45.331224Z"}]}
{"channel":"book","type":"update","data":[{"symbol":"BTC/USDT","bids":[{"price":67672.8,"qty":0.00000000},{"price":67664.6,"qty":0.09000000}],"asks":[],"checksum":1538147479,"timestamp":"2024-06-01T17:52:45.334650Z"}]}
{"channel":"book","type":"update","data":[{"symbol":"BTC/USDT","bids":[],"asks":[{"price":67689.3,"qty":0.03947498}],"checksum":3281441923,"timestamp":"2024-06-01T17:52:45.335279Z"}]}
{"channel":"book","type":"update","data":[{"symbol":"BTC/USDT","bids":[{"price":67672.8,"qty":0.09000000}],"asks":[],"checksum":4032891786,"timestamp":"2024-06-01T17:52:45.337872Z"}]}
{"channel":"book","type":"update","data":[{"symbol":"BTC/USDT","bids":[{"price":67672.7,"qty":0.00000000},{"price":67664.6,"qty":0.09000000}],"asks":[],"checksum":3487432748,"timestamp":"2024-06-01T17:52:45.585597Z"}]}
{"channel":"book","type":"update","data":[{"symbol":"BTC/USDT","bids":[],"asks":[{"price":67689.5,"qty":0.00000000},{"price":67701.7,"qty":0.19976708}],"checksum":2273541765,"timestamp":"2024-06-01T17:52:45.592845Z"}]}
{"channel":"book","type":"update","data":[{"symbol":"BTC/USDT","bids":[{"price":67672.8,"qty":0.11216027}],"asks":[],"checksum":1034136305,"timestamp":"2024-06-01T17:52:45.626162Z"}]}
{"channel":"book","type":"update","data":[{"symbol":"BTC/USDT","bids":[],"asks":[{"price":67697.3,"qty":0.00000000},{"price":67702.1,"qty":0.19890820},{"price":67696.9,"qty":0.22170000}],"checksum":3304578539,"timestamp":"2024-06-01T17:52:45.867073Z"}]}
{"channel":"book","type":"update","data":[{"symbol":"BTC/USDT","bids":[],"asks":[{"price":67689.4,"qty":0.00000000},{"price":67702.1,"qty":0.19890820},{"price":67686.5,"qty":0.05328436}],"checksum":1709673408,"timestamp":"2024-06-01T17:52:45.891397Z"}]}
{"channel":"book","type":"update","data":[{"symbol":"BTC/USDT","bids":[{"price":67672.8,"qty":0.02216027}],"asks":[],"checksum":558722210,"timestamp":"2024-06-01T17:52:45.895403Z"}]}
{"channel":"book","type":"update","data":[{"symbol":"BTC/USDT","bids":[],"asks":[{"price":67686.5,"qty":0.09275934}],"checksum":2328308196,"timestamp":"2024-06-01T17:52:45.895696Z"}]}
{"channel":"book","type":"update","data":[{"symbol":"BTC/USDT","bids":[{"price":67672.8,"qty":0.11216027}],"asks":[],"checksum":4210287904,"timestamp":"2024-06-01T17:52:45.904288Z"}]}
{"channel":"book","type":"update","data":[{"symbol":"BTC/USDT","bids":[],"asks":[{"price":67689.3,"qty":0.00000000},{"price":67702.1,"qty":0.19890820}],"checksum":4018196701,"timestamp":"2024-06-01T17:52:46.093180Z"}]}
{"channel":"book","type":"update","data":[{"symbol":"BTC/USDT","bids":[{"price":67672.8,"qty":0.09000000}],"asks":[],"checksum":2843520931,"timestamp":"2024-06-01T17:52:46.141424Z"}]}
{"channel":"book","type":"update","data":[{"symbol":"BTC/USDT","bids":[{"price":67672.8,"qty":0.00000000},{"price":67663.5,"qty":0.05912512}],"asks":[],"checksum":1579818982,"timestamp":"2024-06-01T17:52:46.236518Z"}]}
{"channel":"book","type":"update","data":[{"symbol":"BTC/USDT","bids":[{"price":67673.0,"qty":0.02216043}],"asks":[],"checksum":4239559403,"timestamp":"2024-06-01T17:52:46.696016Z"}]}
{"channel":"book","type":"update","data":[{"symbol":"BTC/USDT","bids":[{"price":67673.0,"qty":0.00000000},{"price":67663.5,"qty":0.05912512}],"asks":[],"checksum":1579818982,"timestamp":"2024-06-01T17:52:47.144319Z"}]}
{"channel":"book","type":"update","data":[{"symbol":"BTC/USDT","bids":[{"price":67673.4,"qty":0.02216098}],"asks":[],"checksum":2241051415,"timestamp":"2024-06-01T17:52:47.184549Z"}]}
{"channel":"book","type":"update","data":[{"symbol":"BTC/USDT","bids":[{"price":67675.8,"qty":0.00000000},{"price":67663.5,"qty":0.05912512}],"asks":[],"checksum":3514055929,"timestamp":"2024-06-01T17:52:47.245606Z"}]}
{"channel":"book","type":"update","data":[{"symbol":"BTC/USDT","bids":[{"price":67679.0,"qty":0.12012000}],"asks":[],"checksum":1532089722,"timestamp":"2024-06-01T17:52:47.247705Z"}]}
{"channel":"book","type":"update","data":[{"symbol":"BTC/USDT","bids":[{"price":67672.8,"qty":0.09000000}],"asks":[],"checksum":1198422392,"timestamp":"2024-06-01T17:52:47.672383Z"}]}
{"channel":"book","type":"update","data":[{"symbol":"BTC/USDT","bids":[],"asks":[{"price":67697.0,"qty":0.00000000},{"price":67703.3,"qty":0.12011500}],"checksum":1821222328,"timestamp":"2024-06-01T17:52:47.980102Z"}]}
{"channel":"book","type":"update","data":[{"symbol":"BTC/USDT","bids":[],"asks":[{"price":67696.8,"qty":0.12144125}],"checksum":1878270430,"timestamp":"2024-06-01T17:52:47.982286Z"}]}
{"channel":"book","type":"update","data":[{"symbol":"BTC/USDT","bids":[],"asks":[{"price":67696.9,"qty":0.00000000},{"price":67703.3,"qty":0.12011500},{"price":67697.3,"qty":0.22170000}],"checksum":4058210948,"timestamp":"2024-06-01T17:52:47.983954Z"}]}
{"channel":"book","type":"update","data":[{"symbol":"BTC/USDT","bids":[{"price":67672.8,"qty":0.00000000},{"price":67664.6,"qty":0.09000000}],"asks":[],"checksum":3990670982,"timestamp":"2024-06-01T17:52:48.283842Z"}]}
{"channel":"book","type":"update","data":[{"symbol":"BTC/USDT","bids":[{"price":67673.4,"qty":0.00000000},{"price":67663.5,"qty":0.05912512}],"asks":[],"checksum":912616055,"timestamp":"2024-06-01T17:52:48.292935Z"}]}
{"channel":"book","type":"update","data":[{"symbol":"BTC/USDT","bids":[{"price":67672.8,"qty":0.09000000}],"asks":[],"checksum":3241400882,"timestamp":"2024-06-01T17:52:48.304517Z"}]}
{"channel":"book","type":"update","data":[{"symbol":"BTC/USDT","bids":[{"price":67674.1,"qty":0.02216021}],"asks":[],"checksum":3559935930,"timestamp":"2024-06-01T17:52:48.333359Z"}]}
{"channel":"book","type":"update","data":[{"symbol":"BTC/USDT","bids":[],"asks":[{"price":67697.3,"qty":0.00000000},{"price":67703.3,"qty":0.12011500},{"price":67696.7,"qty":0.22170000}],"checksum":2074520829,"timestamp":"2024-06-01T17:52:48.709329Z"}]}
{"channel":"book","type":"update","data":[{"symbol":"BTC/USDT","bids":[{"price":67672.8,"qty":0.00000000},{"price":67664.6,"qty":0.09000000}],"asks":[],"checksum":1738080511,"timestamp":"2024-06-01T17:52:49.016892Z"}]}
{"channel":"book","type":"update","data":[{"symbol":"BTC/USDT","bids":[],"asks":[{"price":67686.5,"qty":0.18275934}],"checksum":2410813361,"timestamp":"2024-06-01T17:52:49.036903Z"}]}
{"channel":"book","type":"update","data":[{"symbol":"BTC/USDT","bids":[],"asks":[{"price":67686.5,"qty":0.27275934}],"checksum":1039804904,"timestamp":"2024-06-01T17:52:49.037641Z"}]}
{"channel":"book","type":"update","data":[{"symbol":"BTC/USDT","bids":[{"price":67686.4,"qty":0.09405954}],"asks":[],"checksum":4178480598,"timestamp":"2024-06-01T17:52:49.046698Z"}]}
{"channel":"book","type":"update","data":[{"symbol":"BTC/USDT","bids":[{"price":67679.5,"qty":0.01774291}],"asks":[],"checksum":3345656998,"timestamp":"2024-06-01T17:52:49.053562Z"}]}
{"channel":"book","type":"update","data":[{"symbol":"BTC/USDT","bids":[],"asks":[{"price":67686.5,"qty":0.18275934}],"checksum":845143327,"timestamp":"2024-06-01T17:52:49.079952Z"}]}
{"channel":"book","type":"update","data":[{"symbol":"BTC/USDT","bids":[],"asks":[{"price":67686.5,"qty":0.09275934}],"checksum":2711396440,"timestamp":"2024-06-01T17:52:49.080044Z"}]}
{"channel":"book","type":"update","data":[{"symbol":"BTC/USDT","bids":[{"price":67679.4,"qty":0.00000000},{"price":67664.6,"qty":0.09000000},{"price":67679.6,"qty":0.05328754}],"asks":[],"checksum":2952300524,"timestamp":"2024-06-01T17:52:49.108587Z"}]}
{"channel":"book","type":"update","data":[{"symbol":"BTC/USDT","bids":[{"price":67679.5,"qty":0.00000000},{"price":67664.6,"qty":0.09000000}],"asks":[],"checksum":3418716833,"timestamp":"2024-06-01T17:52:49.112930Z"}]}
{"channel":"book","type":"update","data":[{"symbol":"BTC/USDT","bids":[{"price":67679.7,"qty":0.01774287}],"asks":[],"checksum":3921632619,"timestamp":"2024-06-01T17:52:49.113193Z"}]}
{"channel":"book","type":"update","data":[{"symbol":"BTC/USDT","bids":[{"price":67679.7,"qty":0.16774287}],"asks":[],"checksum":1489400073,"timestamp":"2024-06-01T17:52:49.114631Z"}]}
{"channel":"book","type":"update","data":[{"symbol":"BTC/USDT","bids":[],"asks":[{"price":67690.5,"qty":0.16185153}],"checksum":3640040350,"timestamp":"2024-06-01T17:52:49.147413Z"}]}
{"channel":"book","type":"update","data":[{"symbol":"BTC/USDT","bids":[{"price":67679.3,"qty":0.00000000},{"price":67664.6,"qty":0.09000000}],"asks":[],"checksum":2493707180,"timestamp":"2024-06-01T17:52:49.152421Z"}]}
{"channel":"book","type":"update","data":[{"symbol":"BTC/USDT","bids":[{"price":67674.1,"qty":0.00000000},{"price":67663.5,"qty":0.05912512}],"asks":[],"checksum":1791523427,"timestamp":"2024-06-01T17:52:49.309770Z"}]}
{"channel":"book","type":"update","data":[{"symbol":"BTC/USDT","bids":[{"price":67663.6,"qty":0.01108026}],"asks":[],"checksum":2215462683,"timestamp":"2024-06-01T17:52:49.314098Z"}]}
{"channel":"book","type":"update","data":[{"symbol":"BTC/USDT","bids":[{"price":67674.3,"qty":0.02216052}],"asks":[],"checksum":3720744894,"timestamp":"2024-06-01T17:52:49.349900Z"}]}
{"channel":"book","type":"update","data":[{"symbol":"BTC/USDT","bids":[{"price":67672.8,"qty":0.09000000}],"asks":[],"checksum":3254363068,"timestamp":"2024-06-01T17:52:49.378910Z"}]}
{"channel":"book","type":"update","data":[{"symbol":"BTC/USDT","bids":[{"price":67679.6,"qty":0.00000000},{"price":67664.6,"qty":0.09000000},{"price":67679.8,"qty":0.05328738}],"asks":[],"checksum":3790779373,"timestamp":"2024-06-01T17:52:49.415130Z"}]}
{"channel":"book","type":"update","data":[{"symbol":"BTC/USDT","bids":[{"price":67679.7,"qty":0.15000000}],"asks":[],"checksum":527887378,"timestamp":"2024-06-01T17:52:49.419720Z"}]}
{"channel":"book","type":"update","data":[{"symbol":"BTC/USDT","bids":[{"price":67679.9,"qty":0.15000000}],"asks":[],"checksum":3429730846,"timestamp":"2024-06-01T17:52:49.419861Z"}]}
{"channel":"book","type":"update","data":[{"symbol":"BTC/USDT","bids":[{"price":67679.9,"qty":0.16774287}],"asks":[],"checksum":1993423346,"timestamp":"2024-06-01T17:52:49.419918Z"}]}
{"channel":"book","type":"update","data":[{"symbol":"BTC/USDT","bids":[{"price":67672.8,"qty":0.00000000},{"price":67666.3,"qty":0.14790422}],"asks":[],"checksum":1101943774,"timestamp":"2024-06-01T17:52:49.690491Z"}]}
{"channel":"book","type":"update","data":[{"symbol":"BTC/USDT","bids":[{"price":67679.7,"qty":0.00000000},{"price":67664.6,"qty":0.09000000}],"asks":[],"checksum":3309382571,"timestamp":"2024-06-01T17:52:49.709492Z"}]}
{"channel":"book","type":"update","data":[{"symbol":"BTC/USDT","bids":[{"price":67679.8,"qty":0.00000000},{"price":67663.6,"qty":0.01108026},{"price":67680.0,"qty":0.05328722}],"asks":[],"checksum":1877550261,"timestamp":"2024-06-01T17:52:49.766389Z"}]}
{"channel":"book","type":"update","data":[{"symbol":"BTC/USDT","bids":[{"price":67679.9,"qty":0.15000000}],"asks":[],"checksum":2439871306,"timestamp":"2024-06-01T17:52:49.770934Z"}]}
{"channel":"book","type":"update","data":[{"symbol":"BTC/USDT","bids":[{"price":67680.1,"qty":0.01774287}],"asks":[],"checksum":537426828,"timestamp":"2024-06-01T17:52:49.771033Z"}]}
{"channel":"book","type":"update","data":[{"symbol":"BTC/USDT","bids":[{"price":67680.1,"qty":0.16774287}],"asks":[],"checksum":4096596776,"timestamp":"2024-06-01T17:52:49.771048Z"}]}
{"channel":"book","type":"update","data":[{"symbol":"BTC/USDT","bids":[{"price":67680.0,"qty":0.00000000},{"price":67664.6,"qty":0.09000000},{"price":67680.2,"qty":0.05328706}],"asks":[],"checksum":1815791130,"timestamp":"2024-06-01T17:52:50.150793Z"}]}
{"channel":"book","type":"update","data":[{"symbol":"BTC/USDT","bids":[{"price":67680.1,"qty":0.15000000}],"asks":[],"checksum":1103539656,"timestamp":"2024-06-01T17:52:50.155503Z"}]}
{"channel":"book","type":"update","data":[{"symbol":"BTC/USDT","bids":[{"price":67680.3,"qty":0.15000000}],"asks":[],"checksum":2534149584,"timestamp":"2024-06-01T17:52:50.155736Z"}]}
{"channel":"book","type":"update","data":[{"symbol":"BTC/USDT","bids":[{"price":67680.1,"qty":0.00000000},{"price":67666.3,"qty":0.14790422}],"asks":[],"checksum":2951525831,"timestamp":"2024-06-01T17:52:50.155780Z"}]}
{"channel":"book","type":"update","data":[{"symbol":"BTC/USDT","bids":[{"price":67679.9,"qty":0.00000000},{"price":67664.6,"qty":0.09000000}],"asks":[],"checksum":3522965155,"timestamp":"2024-06-01T17:52:50.209063Z"}]}
{"channel":"book","type":"update","data":[{"symbol":"BTC/USDT","bids":[{"price":67674.3,"qty":0.00000000},{"price":67663.5,"qty":0.05912512}],"asks":[],"checksum":1727159166,"timestamp":"2024-06-01T17:52:50.378135Z"}]}
