{"channel":"book","type":"snapshot","data":[{"symbol":"ETH/BTC","bids":[{"price":0.05613,"qty":4.08970671},{"price":0.05612,"qty":11.17247563},{"price":0.05611,"qty":13.99046902},{"price":0.05610,"qty":15.59800078},{"price":0.05609,"qty":21.94703067},{"price":0.05608,"qty":16.94575145},{"price":0.05607,"qty":23.49168207},{"price":0.05606,"qty":25.31506906},{"price":0.05605,"qty":24.02470675},{"price":0.05604,"qty":20.00163369}],"asks":[{"price":0.05614,"qty":2.64095257},{"price":0.05615,"qty":10.60768130},{"price":0.05616,"qty":23.10807826},{"price":0.05617,"qty":14.53281506},{"price":0.05618,"qty":1.05332071},{"price":0.05619,"qty":7.24281142},{"price":0.05620,"qty":15.52928643},{"price":0.05621,"qty":19.96670871},{"price":0.05622,"qty":16.15624527},{"price":0.05623,"qty":0.01263578}],"checksum":2170531242}]}
{"channel":"book","type":"update","data":[{"symbol":"ETH/BTC","bids":[{"price":0.05613,"qty":4.90530671}],"asks":[],"checksum":193192326,"timestamp":"2024-06-01T17:51:46.093372Z"}]}
{"channel":"book","type":"update","data":[{"symbol":"ETH/BTC","bids":[{"price":0.05610,"qty":15.84324937}],"asks":[],"checksum":1955733984,"timestamp":"2024-06-01T17:51:46.123939Z"}]}
{"channel":"book","type":"update","data":[{"symbol":"ETH/BTC","bids":[],"asks":[{"price":0.05623,"qty":0.00000000},{"price":0.05624,"qty":12.47897749}],"checksum":4219183397,"timestamp":"2024-06-01T17:51:46.165530Z"}]}
{"channel":"book","type":"update","data":[{"symbol":"ETH/BTC","bids":[],"asks":[{"price":0.05623,"qty":0.20717085}],"checksum":3869547146,"timestamp":"2024-06-01T17:51:46.165774Z"}]}
{"channel":"book","type":"update","data":[{"symbol":"ETH/BTC","bids":[{"price":0.05613,"qty":0.90530671}],"asks":[],"checksum":634980281,"timestamp":"2024-06-01T17:51:46.303216Z"}]}
{"channel":"book","type":"update","data":[{"symbol":"ETH/BTC","bids":[{"price":0.05613,"qty":1.72090671}],"asks":[],"checksum":3026652156,"timestamp":"2024-06-01T17:51:46.306748Z"}]}
{"channel":"book","type":"update","data":[{"symbol":"ETH/BTC","bids":[{"price":0.05613,"qty":0.90530671}],"asks":[],"checksum":634980281,"timestamp":"2024-06-01T17:51:46.412782Z"}]}
{"channel":"book","type":"update","data":[{"symbol":"ETH/BTC","bids":[{"price":0.05613,"qty":0.08970671}],"asks":[],"checksum":2160003506,"timestamp":"2024-06-01T17:51:46.447082Z"}]}
{"channel":"book","type":"update","data":[{"symbol":"ETH/BTC","bids":[{"price":0.05606,"qty":24.43047671},{"price":0.05606,"qty":25.30153545}],"asks":[],"checksum":2825622685,"timestamp":"2024-06-01T17:51:46.682988Z"}]}
{"channel":"book","type":"update","data":[{"symbol":"ETH/BTC","bids":[{"price":0.05613,"qty":0.90530671}],"asks":[],"checksum":218995350,"timestamp":"2024-06-01T17:51:46.726257Z"}]}
{"channel":"book","type":"update","data":[{"symbol":"ETH/BTC","bids":[{"price":0.05613,"qty":1.72090671}],"asks":[],"checksum":2629015251,"timestamp":"2024-06-01T17:51:46.752750Z"}]}
{"channel":"book","type":"update","data":[{"symbol":"ETH/BTC","bids":[{"price":0.05612,"qty":8.53792467}],"asks":[],"checksum":761062784,"timestamp":"2024-06-01T17:51:46.758415Z"}]}
{"channel":"book","type":"update","data":[{"symbol":"ETH/BTC","bids":[{"price":0.05613,"qty":4.35522897}],"asks":[],"checksum":2688269596,"timestamp":"2024-06-01T17:51:46.762361Z"}]}
{"channel":"book","type":"update","data":[{"symbol":"ETH/BTC","bids":[{"price":0.05610,"qty":2.66545000}],"asks":[],"checksum":2931095240,"timestamp":"2024-06-01T17:51:46.767388Z"}]}
{"channel":"book","type":"update","data":[{"symbol":"ETH/BTC","bids":[{"price":0.05612,"qty":21.71182243}],"asks":[],"checksum":4010827577,"timestamp":"2024-06-01T17:51:46.771247Z"}]}
{"channel":"book","type":"update","data":[{"symbol":"ETH/BTC","bids":[{"price":0.05604,"qty":20.15088145}],"asks":[],"checksum":3941294082,"timestamp":"2024-06-01T17:51:47.028474Z"}]}
{"channel":"book","type":"update","data":[{"symbol":"ETH/BTC","bids":[{"price":0.05612,"qty":19.07745776}],"asks":[],"checksum":3596232008,"timestamp":"2024-06-01T17:51:47.113966Z"}]}
{"channel":"book","type":"update","data":[{"symbol":"ETH/BTC","bids":[{"price":0.05604,"qty":20.00163369}],"asks":[],"checksum":3550550643,"timestamp":"2024-06-01T17:51:47.201812Z"}]}
{"channel":"book","type":"update","data":[{"symbol":"ETH/BTC","bids":[],"asks":[{"price":0.05614,"qty":0.00604074}],"checksum":3246293977,"timestamp":"2024-06-01T17:51:47.223132Z"}]}
{"channel":"book","type":"update","data":[{"symbol":"ETH/BTC","bids":[],"asks":[{"price":0.05615,"qty":7.97393532}],"checksum":3334888764,"timestamp":"2024-06-01T17:51:47.238625Z"}]}
{"channel":"book","type":"update","data":[{"symbol":"ETH/BTC","bids":[],"asks":[{"price":0.05616,"qty":25.74124951}],"checksum":936823105,"timestamp":"2024-06-01T17:51:47.242333Z"}]}
{"channel":"book","type":"update","data":[{"symbol":"ETH/BTC","bids":[{"price":0.05613,"qty":6.98955123}],"asks":[],"checksum":2867200406,"timestamp":"2024-06-01T17:51:47.351299Z"}]}
{"channel":"book","type":"update","data":[{"symbol":"ETH/BTC","bids":[],"asks":[{"price":0.05620,"qty":14.70789018}],"checksum":750042643,"timestamp":"2024-06-01T17:51:47.398935Z"}]}
{"channel":"book","type":"update","data":[{"symbol":"ETH/BTC","bids":[],"asks":[{"price":0.05620,"qty":15.52928643}],"checksum":2867200406,"timestamp":"2024-06-01T17:51:47.417946Z"}]}
{"channel":"book","type":"update","data":[{"symbol":"ETH/BTC","bids":[{"price":0.05613,"qty":10.98955123}],"asks":[],"checksum":2790548687,"timestamp":"2024-06-01T17:51:47.777507Z"}]}
{"channel":"book","type":"update","data":[{"symbol":"ETH/BTC","bids":[],"asks":[{"price":0.05619,"qty":2.39689315}],"checksum":2503829304,"timestamp":"2024-06-01T17:51:48.655212Z"}]}
{"channel":"book","type":"update","data":[{"symbol":"ETH/BTC","bids":[{"price":0.05604,"qty":19.44555480}],"asks":[],"checksum":3118900284,"timestamp":"2024-06-01T17:51:48.688181Z"}]}
{"channel":"book","type":"update","data":[{"symbol":"ETH/BTC","bids":[{"price":0.05606,"qty":24.43047671},{"price":0.05607,"qty":24.36031051}],"asks":[],"checksum":1296895489,"timestamp":"2024-06-01T17:51:49.068849Z"}]}
{"channel":"book","type":"update","data":[{"symbol":"ETH/BTC","bids":[{"price":0.05605,"qty":24.58068643}],"asks":[],"checksum":1117672647,"timestamp":"2024-06-01T17:51:49.164780Z"}]}
{"channel":"book","type":"update","data":[{"symbol":"ETH/BTC","bids":[],"asks":[{"price":0.05620,"qty":20.15553268}],"checksum":2578911737,"timestamp":"2024-06-01T17:51:49.257530Z"}]}
{"channel":"book","type":"update","data":[{"symbol":"ETH/BTC","bids":[],"asks":[{"price":0.05616,"qty":23.10807826}],"checksum":3086093548,"timestamp":"2024-06-01T17:51:49.578613Z"}]}
{"channel":"book","type":"update","data":[{"symbol":"ETH/BTC","bids":[],"asks":[{"price":0.05615,"qty":10.60733620}],"checksum":3175897453,"timestamp":"2024-06-01T17:51:49.583187Z"}]}
{"channel":"book","type":"update","data":[{"symbol":"ETH/BTC","bids":[],"asks":[{"price":0.05615,"qty":7.97382667}],"checksum":743428294,"timestamp":"2024-06-01T17:51:49.584352Z"}]}
{"channel":"book","type":"update","data":[{"symbol":"ETH/BTC","bids":[],"asks":[{"price":0.05616,"qty":25.74118016}],"checksum":171245379,"timestamp":"2024-06-01T17:51:49.588736Z"}]}
{"channel":"book","type":"update","data":[{"symbol":"ETH/BTC","bids":[],"asks":[{"price":0.05614,"qty":2.64031213}],"checksum":3787579277,"timestamp":"2024-06-01T17:51:49.598726Z"}]}
{"channel":"book","type":"update","data":[{"symbol":"ETH/BTC","bids":[{"price":0.05613,"qty":18.89075174}],"asks":[],"checksum":1478787937,"timestamp":"2024-06-01T17:51:49.776428Z"}]}
{"channel":"book","type":"update","data":[{"symbol":"ETH/BTC","bids":[],"asks":[{"price":0.05616,"qty":24.24416697}],"checksum":2883102083,"timestamp":"2024-06-01T17:51:49.971454Z"}]}
{"channel":"book","type":"update","data":[{"symbol":"ETH/BTC","bids":[{"price":0.05610,"qty":1.67909960}],"asks":[],"checksum":3784581650,"timestamp":"2024-06-01T17:51:49.971561Z"}]}
{"channel":"book","type":"update","data":[{"symbol":"ETH/BTC","bids":[],"asks":[{"price":0.05617,"qty":16.02982825}],"checksum":3489394683,"timestamp":"2024-06-01T17:51:49.974130Z"}]}
{"channel":"book","type":"update","data":[{"symbol":"ETH/BTC","bids":[{"price":0.05611,"qty":14.97681942}],"asks":[],"checksum":1206632358,"timestamp":"2024-06-01T17:51:49.974243Z"}]}
{"channel":"book","type":"update","data":[{"symbol":"ETH/BTC","bids":[],"asks":[{"price":0.05620,"qty":19.33413643}],"checksum":1048740157,"timestamp":"2024-06-01T17:51:50.804126Z"}]}
{"channel":"book","type":"update","data":[{"symbol":"ETH/BTC","bids":[],"asks":[{"price":0.05620,"qty":20.15553268}],"checksum":1206632358,"timestamp":"2024-06-01T17:51:50.809920Z"}]}
{"channel":"book","type":"update","data":[{"symbol":"ETH/BTC","bids":[],"asks":[{"price":0.05620,"qty":19.33413643}],"checksum":1048740157,"timestamp":"2024-06-01T17:51:50.908394Z"}]}
{"channel":"book","type":"update","data":[{"symbol":"ETH/BTC","bids":[],"asks":[{"price":0.05620,"qty":20.15553268}],"checksum":1206632358,"timestamp":"2024-06-01T17:51:50.953141Z"}]}
{"channel":"book","type":"update","data":[{"symbol":"ETH/BTC","bids":[],"asks":[{"price":0.05615,"qty":5.34042579}],"checksum":3096930302,"timestamp":"2024-06-01T17:51:51.572216Z"}]}
{"channel":"book","type":"update","data":[{"symbol":"ETH/BTC","bids":[],"asks":[{"price":0.05616,"qty":26.87728485}],"checksum":805013885,"timestamp":"2024-06-01T17:51:51.578631Z"}]}
{"channel":"book","type":"update","data":[{"symbol":"ETH/BTC","bids":[],"asks":[{"price":0.05620,"qty":19.33413643}],"checksum":1452455910,"timestamp":"2024-06-01T17:51:51.631106Z"}]}
{"channel":"book","type":"update","data":[{"symbol":"ETH/BTC","bids":[],"asks":[{"price":0.05620,"qty":20.15553268}],"checksum":805013885,"timestamp":"2024-06-01T17:51:51.640292Z"}]}
{"channel":"book","type":"update","data":[{"symbol":"ETH/BTC","bids":[],"asks":[{"price":0.05620,"qty":19.33413643}],"checksum":1452455910,"timestamp":"2024-06-01T17:51:51.739042Z"}]}
{"channel":"book","type":"update","data":[{"symbol":"ETH/BTC","bids":[],"asks":[{"price":0.05614,"qty":2.63427139},{"price":0.05615,"qty":5.34646731}],"checksum":933358366,"timestamp":"2024-06-01T17:51:52.203992Z"}]}
{"channel":"book","type":"update","data":[{"symbol":"ETH/BTC","bids":[],"asks":[{"price":0.05615,"qty":5.34042579},{"price":0.05615,"qty":5.34714960}],"checksum":1252847250,"timestamp":"2024-06-01T17:51:52.718623Z"}]}
{"channel":"book","type":"update","data":[{"symbol":"ETH/BTC","bids":[],"asks":[{"price":0.05615,"qty":4.44386639}],"checksum":1562486938,"timestamp":"2024-06-01T17:51:54.107502Z"}]}
{"channel":"book","type":"update","data":[{"symbol":"ETH/BTC","bids":[],"asks":[{"price":0.05616,"qty":27.78056806}],"checksum":2612673859,"timestamp":"2024-06-01T17:51:54.107622Z"}]}
{"channel":"book","type":"update","data":[{"symbol":"ETH/BTC","bids":[],"asks":[{"price":0.05620,"qty":20.15553268}],"checksum":3805479896,"timestamp":"2024-06-01T17:51:54.266936Z"}]}
{"channel":"book","type":"update","data":[{"symbol":"ETH/BTC","bids":[],"asks":[{"price":0.05620,"qty":19.33413643}],"checksum":2612673859,"timestamp":"2024-06-01T17:51:54.366535Z"}]}
{"channel":"book","type":"update","data":[{"symbol":"ETH/BTC","bids":[],"asks":[{"price":0.05620,"qty":20.15553268}],"checksum":3805479896,"timestamp":"2024-06-01T17:51:54.409574Z"}]}
{"channel":"book","type":"update","data":[{"symbol":"ETH/BTC","bids":[],"asks":[{"price":0.05620,"qty":19.33413643}],"checksum":2612673859,"timestamp":"2024-06-01T17:51:54.526766Z"}]}
{"channel":"book","type":"update","data":[{"symbol":"ETH/BTC","bids":[],"asks":[{"price":0.05620,"qty":20.15553268}],"checksum":3805479896,"timestamp":"2024-06-01T17:51:54.557108Z"}]}
{"channel":"book","type":"update","data":[{"symbol":"ETH/BTC","bids":[],"asks":[{"price":0.05620,"qty":19.33413643}],"checksum":2612673859,"timestamp":"2024-06-01T17:51:54.746415Z"}]}
{"channel":"book","type":"update","data":[{"symbol":"ETH/BTC","bids":[],"asks":[{"price":0.05620,"qty":20.15553268}],"checksum":3805479896,"timestamp":"2024-06-01T17:51:54.906281Z"}]}
{"channel":"book","type":"update","data":[{"symbol":"ETH/BTC","bids":[],"asks":[{"price":0.05620,"qty":19.33413643}],"checksum":2612673859,"timestamp":"2024-06-01T17:51:55.066827Z"}]}
{"channel":"book","type":"update","data":[{"symbol":"ETH/BTC","bids":[],"asks":[{"price":0.05616,"qty":25.14745018}],"checksum":3705833298,"timestamp":"2024-06-01T17:51:55.984850Z"}]}
{"channel":"book","type":"update","data":[{"symbol":"ETH/BTC","bids":[],"asks":[{"price":0.05615,"qty":7.07706459}],"checksum":1656193314,"timestamp":"2024-06-01T17:51:55.988837Z"}]}
{"channel":"book","type":"update","data":[{"symbol":"ETH/BTC","bids":[],"asks":[{"price":0.05615,"qty":7.98034780}],"checksum":196832204,"timestamp":"2024-06-01T17:51:56.000275Z"}]}
{"channel":"book","type":"update","data":[{"symbol":"ETH/BTC","bids":[],"asks":[{"price":0.05615,"qty":7.97362399},{"price":0.05614,"qty":2.64099524}],"checksum":293419680,"timestamp":"2024-06-01T17:51:56.038603Z"}]}
{"channel":"book","type":"update","data":[{"symbol":"ETH/BTC","bids":[],"asks":[{"price":0.05620,"qty":20.15553268}],"checksum":1746142267,"timestamp":"2024-06-01T17:51:56.041456Z"}]}
{"channel":"book","type":"update","data":[{"symbol":"ETH/BTC","bids":[],"asks":[{"price":0.05616,"qty":24.24416697}],"checksum":2126234992,"timestamp":"2024-06-01T17:51:56.044207Z"}]}
{"channel":"book","type":"update","data":[{"symbol":"ETH/BTC","bids":[],"asks":[{"price":0.05616,"qty":21.61106507}],"checksum":2143220798,"timestamp":"2024-06-01T17:51:56.280228Z"}]}
{"channel":"book","type":"update","data":[{"symbol":"ETH/BTC","bids":[],"asks":[{"price":0.05620,"qty":19.33413643}],"checksum":114805413,"timestamp":"2024-06-01T17:51:56.329521Z"}]}
{"channel":"book","type":"update","data":[{"symbol":"ETH/BTC","bids":[{"price":0.05613,"qty":18.07515174}],"asks":[],"checksum":3337446476,"timestamp":"2024-06-01T17:51:56.344452Z"}]}
{"channel":"book","type":"update","data":[{"symbol":"ETH/BTC","bids":[{"price":0.05613,"qty":15.44082948}],"asks":[],"checksum":1481607489,"timestamp":"2024-06-01T17:51:56.350416Z"}]}
{"channel":"book","type":"update","data":[{"symbol":"ETH/BTC","bids":[{"price":0.05612,"qty":21.71172661}],"asks":[],"checksum":2612505623,"timestamp":"2024-06-01T17:51:56.354506Z"}]}
{"channel":"book","type":"update","data":[{"symbol":"ETH/BTC","bids":[{"price":0.05613,"qty":14.62522948}],"asks":[],"checksum":3656625911,"timestamp":"2024-06-01T17:51:56.354910Z"}]}
{"channel":"book","type":"update","data":[{"symbol":"ETH/BTC","bids":[],"asks":[{"price":0.05620,"qty":18.71019426}],"checksum":1281439895,"timestamp":"2024-06-01T17:51:56.371400Z"}]}
{"channel":"book","type":"update","data":[{"symbol":"ETH/BTC","bids":[],"asks":[{"price":0.05619,"qty":3.02083532}],"checksum":3057488745,"timestamp":"2024-06-01T17:51:56.393268Z"}]}
{"channel":"book","type":"update","data":[{"symbol":"ETH/BTC","bids":[],"asks":[{"price":0.05615,"qty":10.60708285}],"checksum":1642021833,"timestamp":"2024-06-01T17:51:56.722442Z"}]}
{"channel":"book","type":"update","data":[{"symbol":"ETH/BTC","bids":[],"asks":[{"price":0.05619,"qty":3.84223157}],"checksum":2874399062,"timestamp":"2024-06-01T17:51:57.708504Z"}]}
{"channel":"book","type":"update","data":[{"symbol":"ETH/BTC","bids":[{"price":0.05613,"qty":6.72402897}],"asks":[],"checksum":2305227834,"timestamp":"2024-06-01T17:51:57.719201Z"}]}
{"channel":"book","type":"update","data":[{"symbol":"ETH/BTC","bids":[{"price":0.05609,"qty":11.41048172}],"asks":[],"checksum":1123551236,"timestamp":"2024-06-01T17:51:57.719264Z"}]}
{"channel":"book","type":"update","data":[{"symbol":"ETH/BTC","bids":[{"price":0.05605,"qty":1.46542196}],"asks":[],"checksum":4020428517,"timestamp":"2024-06-01T17:51:57.719297Z"}]}
{"channel":"book","type":"update","data":[{"symbol":"ETH/BTC","bids":[{"price":0.05606,"qty":47.54343022}],"asks":[],"checksum":3505168162,"timestamp":"2024-06-01T17:51:57.759401Z"}]}
{"channel":"book","type":"update","data":[{"symbol":"ETH/BTC","bids":[{"price":0.05611,"qty":25.51200574}],"asks":[],"checksum":1754806756,"timestamp":"2024-06-01T17:51:57.759495Z"}]}
{"channel":"book","type":"update","data":[{"symbol":"ETH/BTC","bids":[{"price":0.05611,"qty":14.97681942}],"asks":[],"checksum":3505168162,"timestamp":"2024-06-01T17:51:58.328840Z"}]}
{"channel":"book","type":"update","data":[{"symbol":"ETH/BTC","bids":[{"price":0.05612,"qty":29.61313928}],"asks":[],"checksum":343802900,"timestamp":"2024-06-01T17:51:58.369147Z"}]}
{"channel":"book","type":"update","data":[{"symbol":"ETH/BTC","bids":[{"price":0.05609,"qty":21.94569862}],"asks":[],"checksum":2248893710,"timestamp":"2024-06-01T17:51:58.369221Z"}]}
{"channel":"book","type":"update","data":[{"symbol":"ETH/BTC","bids":[],"asks":[{"price":0.05622,"qty":16.01274527}],"checksum":3115419407,"timestamp":"2024-06-01T17:51:58.725953Z"}]}
{"channel":"book","type":"update","data":[{"symbol":"ETH/BTC","bids":[{"price":0.05604,"qty":19.30525480}],"asks":[],"checksum":4112217621,"timestamp":"2024-06-01T17:51:58.728029Z"}]}
{"channel":"book","type":"update","data":[{"symbol":"ETH/BTC","bids":[{"price":0.05604,"qty":19.16905480}],"asks":[],"checksum":3656177481,"timestamp":"2024-06-01T17:51:58.754042Z"}]}
{"channel":"book","type":"update","data":[{"symbol":"ETH/BTC","bids":[],"asks":[{"price":0.05622,"qty":15.87224527}],"checksum":1769323651,"timestamp":"2024-06-01T17:51:58.768148Z"}]}
{"channel":"book","type":"update","data":[{"symbol":"ETH/BTC","bids":[],"asks":[{"price":0.05621,"qty":20.11030871}],"checksum":2509837984,"timestamp":"2024-06-01T17:51:58.791657Z"}]}
{"channel":"book","type":"update","data":[{"symbol":"ETH/BTC","bids":[],"asks":[{"price":0.05623,"qty":0.78897085}],"checksum":1589224073,"timestamp":"2024-06-01T17:51:58.792482Z"}]}
{"channel":"book","type":"update","data":[{"symbol":"ETH/BTC","bids":[],"asks":[{"price":0.05620,"qty":18.63339426}],"checksum":2554761171,"timestamp":"2024-06-01T17:51:58.795250Z"}]}
{"channel":"book","type":"update","data":[{"symbol":"ETH/BTC","bids":[],"asks":[{"price":0.05623,"qty":1.51597085}],"checksum":3227113152,"timestamp":"2024-06-01T17:51:58.815006Z"}]}
{"channel":"book","type":"update","data":[{"symbol":"ETH/BTC","bids":[{"price":0.05604,"qty":19.24295480}],"asks":[],"checksum":3198046904,"timestamp":"2024-06-01T17:51:58.823723Z"}]}
{"channel":"book","type":"update","data":[{"symbol":"ETH/BTC","bids":[],"asks":[{"price":0.05622,"qty":16.10384527}],"checksum":2199616930,"timestamp":"2024-06-01T17:51:58.827121Z"}]}
{"channel":"book","type":"update","data":[{"symbol":"ETH/BTC","bids":[],"asks":[{"price":0.05620,"qty":18.78679426}],"checksum":3770147636,"timestamp":"2024-06-01T17:51:58.853348Z"}]}
{"channel":"book","type":"update","data":[{"symbol":"ETH/BTC","bids":[],"asks":[{"price":0.05619,"qty":3.92213157}],"checksum":1088512934,"timestamp":"2024-06-01T17:51:58.864104Z"}]}
{"channel":"book","type":"update","data":[{"symbol":"ETH/BTC","bids":[{"price":0.05612,"qty":21.71172661}],"asks":[],"checksum":2222192784,"timestamp":"2024-06-01T17:51:58.872982Z"}]}
{"channel":"book","type":"update","data":[{"symbol":"ETH/BTC","bids":[{"price":0.05609,"qty":11.41048172}],"asks":[],"checksum":369531274,"timestamp":"2024-06-01T17:51:58.873020Z"}]}
{"channel":"book","type":"update","data":[{"symbol":"ETH/BTC","bids":[{"price":0.05611,"qty":25.51204373}],"asks":[],"checksum":1657294848,"timestamp":"2024-06-01T17:51:58.913301Z"}]}
{"channel":"book","type":"update","data":[{"symbol":"ETH/BTC","bids":[{"price":0.05607,"qty":23.49168207},{"price":0.05607,"qty":24.35841837}],"asks":[],"checksum":3462600090,"timestamp":"2024-06-01T17:51:59.023013Z"}]}
{"channel":"book","type":"update","data":[{"symbol":"ETH/BTC","bids":[{"price":0.05613,"qty":4.08970671}],"asks":[],"checksum":2683013590,"timestamp":"2024-06-01T17:51:59.248481Z"}]}
{"channel":"book","type":"update","data":[{"symbol":"ETH/BTC","bids":[{"price":0.05612,"qty":24.34599866}],"asks":[],"checksum":896834791,"timestamp":"2024-06-01T17:51:59.252690Z"}]}
{"channel":"book","type":"update","data":[{"symbol":"ETH/BTC","bids":[{"price":0.05607,"qty":23.49168207},{"price":0.05606,"qty":48.44957381}],"asks":[],"checksum":13739401,"timestamp":"2024-06-01T17:51:59.297479Z"}]}
{"channel":"book","type":"update","data":[{"symbol":"ETH/BTC","bids":[{"price":0.05611,"qty":14.97681942}],"asks":[],"checksum":1948216323,"timestamp":"2024-06-01T17:51:59.485790Z"}]}
{"channel":"book","type":"update","data":[{"symbol":"ETH/BTC","bids":[{"price":0.05609,"qty":21.94570694}],"asks":[],"checksum":133910208,"timestamp":"2024-06-01T17:51:59.526066Z"}]}
{"channel":"book","type":"update","data":[{"symbol":"ETH/BTC","bids":[{"price":0.05606,"qty":47.54343022},{"price":0.05607,"qty":24.35979858}],"asks":[],"checksum":1448548157,"timestamp":"2024-06-01T17:51:59.946586Z"}]}
{"channel":"book","type":"update","data":[{"symbol":"ETH/BTC","bids":[{"price":0.05613,"qty":11.99105170}],"asks":[],"checksum":316014893,"timestamp":"2024-06-01T17:52:00.687818Z"}]}
{"channel":"book","type":"update","data":[{"symbol":"ETH/BTC","bids":[{"price":0.05607,"qty":11.18902285}],"asks":[],"checksum":2608685365,"timestamp":"2024-06-01T17:52:01.333342Z"}]}
{"channel":"book","type":"update","data":[{"symbol":"ETH/BTC","bids":[{"price":0.05608,"qty":30.11465377}],"asks":[],"checksum":237934976,"timestamp":"2024-06-01T17:52:01.373731Z"}]}
{"channel":"book","type":"update","data":[{"symbol":"ETH/BTC","bids":[{"price":0.05607,"qty":10.32090634},{"price":0.05606,"qty":48.43914814}],"asks":[],"checksum":2242875206,"timestamp":"2024-06-01T17:52:02.383457Z"}]}
{"channel":"book","type":"update","data":[{"symbol":"ETH/BTC","bids":[],"asks":[{"price":0.05620,"qty":14.16054801}],"checksum":1772139064,"timestamp":"2024-06-01T17:52:02.665364Z"}]}
{"channel":"book","type":"update","data":[{"symbol":"ETH/BTC","bids":[{"price":0.05613,"qty":4.08970671}],"asks":[],"checksum":2917253527,"timestamp":"2024-06-01T17:52:03.953472Z"}]}
{"channel":"book","type":"update","data":[{"symbol":"ETH/BTC","bids":[{"price":0.05609,"qty":11.41048172}],"asks":[],"checksum":3724927828,"timestamp":"2024-06-01T17:52:03.953534Z"}]}
{"channel":"book","type":"update","data":[{"symbol":"ETH/BTC","bids":[{"price":0.05611,"qty":25.51201612}],"asks":[],"checksum":2484086428,"timestamp":"2024-06-01T17:52:03.994376Z"}]}
{"channel":"book","type":"update","data":[{"symbol":"ETH/BTC","bids":[{"price":0.05613,"qty":0.08970671}],"asks":[],"checksum":2876536835,"timestamp":"2024-06-01T17:52:04.319748Z"}]}
{"channel":"book","type":"update","data":[{"symbol":"ETH/BTC","bids":[{"price":0.05611,"qty":14.97681942}],"asks":[],"checksum":3781279179,"timestamp":"2024-06-01T17:52:04.714382Z"}]}
{"channel":"book","type":"update","data":[{"symbol":"ETH/BTC","bids":[{"price":0.05612,"qty":32.24694866}],"asks":[],"checksum":4286341261,"timestamp":"2024-06-01T17:52:04.754507Z"}]}
{"channel":"book","type":"update","data":[{"symbol":"ETH/BTC","bids":[{"price":0.05609,"qty":21.94508172}],"asks":[],"checksum":2697532059,"timestamp":"2024-06-01T17:52:04.754574Z"}]}
{"channel":"book","type":"update","data":[{"symbol":"ETH/BTC","bids":[{"price":0.05609,"qty":11.41048172}],"asks":[],"checksum":4286341261,"timestamp":"2024-06-01T17:52:05.320349Z"}]}
{"channel":"book","type":"update","data":[{"symbol":"ETH/BTC","bids":[{"price":0.05612,"qty":24.34599866}],"asks":[],"checksum":3781279179,"timestamp":"2024-06-01T17:52:05.320441Z"}]}
{"channel":"book","type":"update","data":[{"symbol":"ETH/BTC","bids":[{"price":0.05611,"qty":25.51149194}],"asks":[],"checksum":1177868112,"timestamp":"2024-06-01T17:52:05.360674Z"}]}
{"channel":"book","type":"update","data":[{"symbol":"ETH/BTC","bids":[],"asks":[{"price":0.05619,"qty":8.54350661}],"checksum":1105656210,"timestamp":"2024-06-01T17:52:05.361141Z"}]}
{"channel":"book","type":"update","data":[{"symbol":"ETH/BTC","bids":[],"asks":[{"price":0.05614,"qty":3.45659524}],"checksum":932150632,"timestamp":"2024-06-01T17:52:05.408429Z"}]}
{"channel":"book","type":"update","data":[{"symbol":"ETH/BTC","bids":[{"price":0.05612,"qty":11.17210090}],"asks":[],"checksum":4078329470,"timestamp":"2024-06-01T17:52:05.408904Z"}]}
{"channel":"book","type":"update","data":[{"symbol":"ETH/BTC","bids":[],"asks":[{"price":0.05621,"qty":6.95637232}],"checksum":1991979917,"timestamp":"2024-06-01T17:52:05.408958Z"}]}
{"channel":"book","type":"update","data":[{"symbol":"ETH/BTC","bids":[],"asks":[{"price":0.05615,"qty":7.97362399}],"checksum":2095446402,"timestamp":"2024-06-01T17:52:05.409187Z"}]}
{"channel":"book","type":"update","data":[{"symbol":"ETH/BTC","bids":[],"asks":[{"price":0.05615,"qty":21.13825170}],"checksum":1582439609,"timestamp":"2024-06-01T17:52:05.414828Z"}]}
{"channel":"book","type":"update","data":[{"symbol":"ETH/BTC","bids":[],"asks":[{"price":0.05614,"qty":6.08997497}],"checksum":2802206320,"timestamp":"2024-06-01T17:52:05.414921Z"}]}
{"channel":"book","type":"update","data":[{"symbol":"ETH/BTC","bids":[{"price":0.05610,"qty":14.85533953}],"asks":[],"checksum":3158161224,"timestamp":"2024-06-01T17:52:05.415059Z"}]}
{"channel":"book","type":"update","data":[{"symbol":"ETH/BTC","bids":[{"price":0.05610,"qty":14.78844638}],"asks":[],"checksum":2889507168,"timestamp":"2024-06-01T17:52:05.459541Z"}]}
{"channel":"book","type":"update","data":[{"symbol":"ETH/BTC","bids":[],"asks":[{"price":0.05619,"qty":7.91956444}],"checksum":345211093,"timestamp":"2024-06-01T17:52:05.490134Z"}]}
{"channel":"book","type":"update","data":[{"symbol":"ETH/BTC","bids":[{"price":0.05610,"qty":14.54319779}],"asks":[],"checksum":505630181,"timestamp":"2024-06-01T17:52:05.490292Z"}]}
{"channel":"book","type":"update","data":[{"symbol":"ETH/BTC","bids":[],"asks":[{"price":0.05619,"qty":7.09816819}],"checksum":2398681410,"timestamp":"2024-06-01T17:52:05.505702Z"}]}
{"channel":"book","type":"update","data":[{"symbol":"ETH/BTC","bids":[],"asks":[{"price":0.05619,"qty":7.72211036}],"checksum":687671036,"timestamp":"2024-06-01T17:52:05.516478Z"}]}
{"channel":"book","type":"update","data":[{"symbol":"ETH/BTC","bids":[{"price":0.05609,"qty":11.47741530}],"asks":[],"checksum":3196458743,"timestamp":"2024-06-01T17:52:05.563622Z"}]}
{"channel":"book","type":"update","data":[{"symbol":"ETH/BTC","bids":[],"asks":[{"price":0.05619,"qty":8.54350661}],"checksum":821148763,"timestamp":"2024-06-01T17:52:05.666946Z"}]}
{"channel":"book","type":"update","data":[{"symbol":"ETH/BTC","bids":[],"asks":[{"price":0.05619,"qty":7.72211036}],"checksum":3196458743,"timestamp":"2024-06-01T17:52:05.766229Z"}]}
{"channel":"book","type":"update","data":[{"symbol":"ETH/BTC","bids":[],"asks":[{"price":0.05619,"qty":8.54350661}],"checksum":821148763,"timestamp":"2024-06-01T17:52:05.807030Z"}]}
{"channel":"book","type":"update","data":[{"symbol":"ETH/BTC","bids":[{"price":0.05611,"qty":14.97681942}],"asks":[],"checksum":1468769277,"timestamp":"2024-06-01T17:52:06.127844Z"}]}
{"channel":"book","type":"update","data":[{"symbol":"ETH/BTC","bids":[],"asks":[{"price":0.05619,"qty":7.72211036}],"checksum":3657173329,"timestamp":"2024-06-01T17:52:06.146569Z"}]}
{"channel":"book","type":"update","data":[{"symbol":"ETH/BTC","bids":[{"price":0.05609,"qty":22.01266245}],"asks":[],"checksum":2397930150,"timestamp":"2024-06-01T17:52:06.167934Z"}]}
{"channel":"book","type":"update","data":[{"symbol":"ETH/BTC","bids":[],"asks":[{"price":0.05619,"qty":8.54350661}],"checksum":10102794,"timestamp":"2024-06-01T17:52:06.188574Z"}]}
{"channel":"book","type":"update","data":[{"symbol":"ETH/BTC","bids":[{"price":0.05605,"qty":1.37157968},{"price":0.05604,"qty":19.33681382}],"asks":[],"checksum":3376028331,"timestamp":"2024-06-01T17:52:06.489096Z"}]}
{"channel":"book","type":"update","data":[{"symbol":"ETH/BTC","bids":[],"asks":[{"price":0.05614,"qty":7.68997497}],"checksum":1701549016,"timestamp":"2024-06-01T17:52:07.407721Z"}]}
{"channel":"book","type":"update","data":[{"symbol":"ETH/BTC","bids":[{"price":0.05610,"qty":14.22770999}],"asks":[],"checksum":1309536351,"timestamp":"2024-06-01T17:52:07.684049Z"}]}
{"channel":"book","type":"update","data":[{"symbol":"ETH/BTC","bids":[],"asks":[{"price":0.05623,"qty":1.30880000}],"checksum":2703442679,"timestamp":"2024-06-01T17:52:09.121928Z"}]}
{"channel":"book","type":"update","data":[{"symbol":"ETH/BTC","bids":[{"price":0.05605,"qty":0.81560000}],"asks":[],"checksum":129547215,"timestamp":"2024-06-01T17:52:09.854386Z"}]}
{"channel":"book","type":"update","data":[{"symbol":"ETH/BTC","bids":[{"price":0.05612,"qty":10.45110090}],"asks":[],"checksum":317647093,"timestamp":"2024-06-01T17:52:10.642002Z"}]}
{"channel":"book","type":"update","data":[{"symbol":"ETH/BTC","bids":[{"price":0.05611,"qty":13.99046902}],"asks":[],"checksum":182735661,"timestamp":"2024-06-01T17:52:10.651419Z"}]}
{"channel":"book","type":"update","data":[{"symbol":"ETH/BTC","bids":[{"price":0.05610,"qty":15.21406039}],"asks":[],"checksum":3741006744,"timestamp":"2024-06-01T17:52:10.653995Z"}]}
{"channel":"book","type":"update","data":[{"symbol":"ETH/BTC","bids":[{"price":0.05605,"qty":1.37157968}],"asks":[],"checksum":1425392928,"timestamp":"2024-06-01T17:52:10.674118Z"}]}
{"channel":"book","type":"update","data":[{"symbol":"ETH/BTC","bids":[{"price":0.05611,"qty":14.72446902}],"asks":[],"checksum":1727974895,"timestamp":"2024-06-01T17:52:10.751349Z"}]}
{"channel":"book","type":"update","data":[{"symbol":"ETH/BTC","bids":[],"asks":[{"price":0.05621,"qty":6.81277232}],"checksum":3248507875,"timestamp":"2024-06-01T17:52:11.618615Z"}]}
{"channel":"book","type":"update","data":[{"symbol":"ETH/BTC","bids":[],"asks":[{"price":0.05623,"qty":0.72700000}],"checksum":1089468597,"timestamp":"2024-06-01T17:52:11.620896Z"}]}
{"channel":"book","type":"update","data":[{"symbol":"ETH/BTC","bids":[{"price":0.05604,"qty":19.26291382}],"asks":[],"checksum":2022489130,"timestamp":"2024-06-01T17:52:11.640236Z"}]}
{"channel":"book","type":"update","data":[{"symbol":"ETH/BTC","bids":[],"asks":[{"price":0.05619,"qty":8.46360661}],"checksum":127967511,"timestamp":"2024-06-01T17:52:11.649354Z"}]}
{"channel":"book","type":"update","data":[{"symbol":"ETH/BTC","bids":[],"asks":[{"price":0.05622,"qty":15.87224527}],"checksum":3581331181,"timestamp":"2024-06-01T17:52:11.649509Z"}]}
{"channel":"book","type":"update","data":[{"symbol":"ETH/BTC","bids":[],"asks":[{"price":0.05623,"qty":0.00000000},{"price":0.05624,"qty":11.59207749}],"checksum":1816172866,"timestamp":"2024-06-01T17:52:11.667781Z"}]}
{"channel":"book","type":"update","data":[{"symbol":"ETH/BTC","bids":[],"asks":[{"price":0.05620,"qty":14.00714801}],"checksum":2636561295,"timestamp":"2024-06-01T17:52:11.677469Z"}]}
{"channel":"book","type":"update","data":[{"symbol":"ETH/BTC","bids":[],"asks":[{"price":0.05621,"qty":6.95537232}],"checksum":500276858,"timestamp":"2024-06-01T17:52:12.699309Z"}]}
{"channel":"book","type":"update","data":[{"symbol":"ETH/BTC","bids":[],"asks":[{"price":0.05623,"qty":0.58870000}],"checksum":1398148560,"timestamp":"2024-06-01T17:52:12.699538Z"}]}
{"channel":"book","type":"update","data":[{"symbol":"ETH/BTC","bids":[{"price":0.05604,"qty":19.33631382}],"asks":[],"checksum":484800606,"timestamp":"2024-06-01T17:52:12.720382Z"}]}
{"channel":"book","type":"update","data":[{"symbol":"ETH/BTC","bids":[],"asks":[{"price":0.05619,"qty":8.53760661}],"checksum":767980096,"timestamp":"2024-06-01T17:52:12.728915Z"}]}
{"channel":"book","type":"update","data":[{"symbol":"ETH/BTC","bids":[],"asks":[{"price":0.05622,"qty":16.09564527}],"checksum":3552836333,"timestamp":"2024-06-01T17:52:12.741142Z"}]}
{"channel":"book","type":"update","data":[{"symbol":"ETH/BTC","bids":[],"asks":[{"price":0.05620,"qty":14.17004801}],"checksum":4197799280,"timestamp":"2024-06-01T17:52:12.743477Z"}]}
{"channel":"book","type":"update","data":[{"symbol":"ETH/BTC","bids":[],"asks":[{"price":0.05623,"qty":1.36850000}],"checksum":3528336990,"timestamp":"2024-06-01T17:52:12.743570Z"}]}
{"channel":"book","type":"update","data":[{"symbol":"ETH/BTC","bids":[{"price":0.05607,"qty":1.32090634}],"asks":[],"checksum":3492445073,"timestamp":"2024-06-01T17:52:13.482705Z"}]}
{"channel":"book","type":"update","data":[{"symbol":"ETH/BTC","bids":[{"price":0.05606,"qty":57.46914814}],"asks":[],"checksum":3393317671,"timestamp":"2024-06-01T17:52:13.724636Z"}]}
{"channel":"book","type":"update","data":[{"symbol":"ETH/BTC","bids":[],"asks":[{"price":0.05614,"qty":6.87437497}],"checksum":2457080203,"timestamp":"2024-06-01T17:52:14.083344Z"}]}
{"channel":"book","type":"update","data":[{"symbol":"ETH/BTC","bids":[],"asks":[{"price":0.05622,"qty":1.98740000}],"checksum":2750879245,"timestamp":"2024-06-01T17:52:14.227457Z"}]}
{"channel":"book","type":"update","data":[{"symbol":"ETH/BTC","bids":[],"asks":[{"price":0.05621,"qty":21.06262888}],"checksum":2918628309,"timestamp":"2024-06-01T17:52:14.267618Z"}]}
{"channel":"book","type":"update","data":[{"symbol":"ETH/BTC","bids":[],"asks":[{"price":0.05614,"qty":5.27437497}],"checksum":1092085993,"timestamp":"2024-06-01T17:52:15.356241Z"}]}
{"channel":"book","type":"update","data":[{"symbol":"ETH/BTC","bids":[],"asks":[{"price":0.05616,"qty":8.44490087}],"checksum":1037015037,"timestamp":"2024-06-01T17:52:15.363600Z"}]}
{"channel":"book","type":"update","data":[{"symbol":"ETH/BTC","bids":[{"price":0.05613,"qty":0.90530671}],"asks":[],"checksum":1197029988,"timestamp":"2024-06-01T17:52:15.368001Z"}]}
{"channel":"book","type":"update","data":[{"symbol":"ETH/BTC","bids":[],"asks":[{"price":0.05621,"qty":34.21484439}],"checksum":2310095998,"timestamp":"2024-06-01T17:52:15.368875Z"}]}
{"channel":"book","type":"update","data":[{"symbol":"ETH/BTC","bids":[{"price":0.05613,"qty":0.08970671}],"asks":[],"checksum":3025474186,"timestamp":"2024-06-01T17:52:15.372111Z"}]}
{"channel":"book","type":"update","data":[{"symbol":"ETH/BTC","bids":[],"asks":[{"price":0.05614,"qty":2.64099524}],"checksum":1540516311,"timestamp":"2024-06-01T17:52:15.372927Z"}]}
{"channel":"book","type":"update","data":[{"symbol":"ETH/BTC","bids":[{"price":0.05610,"qty":2.03782046}],"asks":[],"checksum":3738562411,"timestamp":"2024-06-01T17:52:15.375548Z"}]}
{"channel":"book","type":"update","data":[{"symbol":"ETH/BTC","bids":[{"price":0.05612,"qty":7.81682885}],"asks":[],"checksum":1486912383,"timestamp":"2024-06-01T17:52:15.375655Z"}]}
{"channel":"book","type":"update","data":[{"symbol":"ETH/BTC","bids":[],"asks":[{"price":0.05617,"qty":15.47982825}],"checksum":333628243,"timestamp":"2024-06-01T17:52:15.376459Z"}]}
{"channel":"book","type":"update","data":[{"symbol":"ETH/BTC","bids":[],"asks":[{"price":0.05615,"qty":21.68825170}],"checksum":2264358076,"timestamp":"2024-06-01T17:52:15.376666Z"}]}
{"channel":"book","type":"update","data":[{"symbol":"ETH/BTC","bids":[{"price":0.05613,"qty":0.90530671}],"asks":[],"checksum":3408529798,"timestamp":"2024-06-01T17:52:15.380698Z"}]}
{"channel":"book","type":"update","data":[{"symbol":"ETH/BTC","bids":[{"price":0.05611,"qty":27.89633656}],"asks":[],"checksum":4086520138,"timestamp":"2024-06-01T17:52:15.385396Z"}]}
{"channel":"book","type":"update","data":[{"symbol":"ETH/BTC","bids":[{"price":0.05613,"qty":3.53919601}],"asks":[],"checksum":2254182501,"timestamp":"2024-06-01T17:52:15.385431Z"}]}
{"channel":"book","type":"update","data":[{"symbol":"ETH/BTC","bids":[],"asks":[{"price":0.05615,"qty":24.32147174}],"checksum":1427333905,"timestamp":"2024-06-01T17:52:15.385526Z"}]}
{"channel":"book","type":"update","data":[{"symbol":"ETH/BTC","bids":[],"asks":[{"price":0.05615,"qty":11.15684403}],"checksum":1170624168,"timestamp":"2024-06-01T17:52:15.386843Z"}]}
{"channel":"book","type":"update","data":[{"symbol":"ETH/BTC","bids":[{"price":0.05611,"qty":14.72146754}],"asks":[],"checksum":935226038,"timestamp":"2024-06-01T17:52:15.386944Z"}]}
{"channel":"book","type":"update","data":[{"symbol":"ETH/BTC","bids":[{"price":0.05613,"qty":4.35479601}],"asks":[],"checksum":3158168273,"timestamp":"2024-06-01T17:52:15.388849Z"}]}
{"channel":"book","type":"update","data":[{"symbol":"ETH/BTC","bids":[],"asks":[{"price":0.05616,"qty":21.60801476}],"checksum":3992223161,"timestamp":"2024-06-01T17:52:15.395454Z"}]}
{"channel":"book","type":"update","data":[{"symbol":"ETH/BTC","bids":[{"price":0.05609,"qty":22.32815025}],"asks":[],"checksum":3644355017,"timestamp":"2024-06-01T17:52:15.420538Z"}]}
{"channel":"book","type":"update","data":[{"symbol":"ETH/BTC","bids":[],"asks":[{"price":0.05615,"qty":10.25356082}],"checksum":2663599422,"timestamp":"2024-06-01T17:52:15.427734Z"}]}
{"channel":"book","type":"update","data":[{"symbol":"ETH/BTC","bids":[],"asks":[{"price":0.05616,"qty":22.51129797}],"checksum":6087274,"timestamp":"2024-06-01T17:52:15.428113Z"}]}
{"channel":"book","type":"update","data":[{"symbol":"ETH/BTC","bids":[{"price":0.05611,"qty":15.62475075}],"asks":[],"checksum":2104895976,"timestamp":"2024-06-01T17:52:15.428201Z"}]}
{"channel":"book","type":"update","data":[{"symbol":"ETH/BTC","bids":[{"price":0.05610,"qty":8.03782046}],"asks":[],"checksum":2462825224,"timestamp":"2024-06-01T17:52:15.438421Z"}]}
{"channel":"book","type":"update","data":[{"symbol":"ETH/BTC","bids":[{"price":0.05610,"qty":8.28306905}],"asks":[],"checksum":3055079474,"timestamp":"2024-06-01T17:52:15.478258Z"}]}
{"channel":"book","type":"update","data":[{"symbol":"ETH/BTC","bids":[{"price":0.05609,"qty":16.32815025}],"asks":[],"checksum":3671301366,"timestamp":"2024-06-01T17:52:15.487651Z"}]}
{"channel":"book","type":"update","data":[{"symbol":"ETH/BTC","bids":[],"asks":[{"price":0.05615,"qty":11.85356082}],"checksum":1381944642,"timestamp":"2024-06-01T17:52:15.599371Z"}]}
{"channel":"book","type":"update","data":[{"symbol":"ETH/BTC","bids":[{"price":0.05609,"qty":16.01266245}],"asks":[],"checksum":1720893746,"timestamp":"2024-06-01T17:52:15.641036Z"}]}
{"channel":"book","type":"update","data":[{"symbol":"ETH/BTC","bids":[{"price":0.05610,"qty":8.59855685}],"asks":[],"checksum":1038932104,"timestamp":"2024-06-01T17:52:15.654772Z"}]}
{"channel":"book","type":"update","data":[{"symbol":"ETH/BTC","bids":[],"asks":[{"price":0.05614,"qty":2.63427139},{"price":0.05614,"qty":2.64089089}],"checksum":1819335135,"timestamp":"2024-06-01T17:52:15.664085Z"}]}
{"channel":"book","type":"update","data":[{"symbol":"ETH/BTC","bids":[{"price":0.05612,"qty":20.98836972}],"asks":[],"checksum":1965733844,"timestamp":"2024-06-01T17:52:15.920993Z"}]}
{"channel":"book","type":"update","data":[{"symbol":"ETH/BTC","bids":[],"asks":[{"price":0.05621,"qty":20.10758783}],"checksum":3323522001,"timestamp":"2024-06-01T17:52:16.091505Z"}]}
{"channel":"book","type":"update","data":[{"symbol":"ETH/BTC","bids":[],"asks":[{"price":0.05622,"qty":16.09362331}],"checksum":318573332,"timestamp":"2024-06-01T17:52:16.130241Z"}]}
{"channel":"book","type":"update","data":[{"symbol":"ETH/BTC","bids":[{"price":0.05613,"qty":12.25531361}],"asks":[],"checksum":1548046305,"timestamp":"2024-06-01T17:52:16.130430Z"}]}
{"channel":"book","type":"update","data":[{"symbol":"ETH/BTC","bids":[{"price":0.05608,"qty":16.94575145}],"asks":[],"checksum":2969008169,"timestamp":"2024-06-01T17:52:16.693097Z"}]}
{"channel":"book","type":"update","data":[{"symbol":"ETH/BTC","bids":[{"price":0.05607,"qty":14.48851326}],"asks":[],"checksum":1805377508,"timestamp":"2024-06-01T17:52:16.733114Z"}]}
{"channel":"book","type":"update","data":[{"symbol":"ETH/BTC","bids":[{"price":0.05613,"qty":16.25531361}],"asks":[],"checksum":481430428,"timestamp":"2024-06-01T17:52:17.054518Z"}]}
{"channel":"book","type":"update","data":[{"symbol":"ETH/BTC","bids":[{"price":0.05604,"qty":19.24245480},{"price":0.05605,"qty":1.46542196}],"asks":[],"checksum":1515375773,"timestamp":"2024-06-01T17:52:17.911105Z"}]}
{"channel":"book","type":"update","data":[{"symbol":"ETH/BTC","bids":[{"price":0.05613,"qty":15.43971361}],"asks":[],"checksum":1601650275,"timestamp":"2024-06-01T17:52:18.257971Z"}]}
{"channel":"book","type":"update","data":[{"symbol":"ETH/BTC","bids":[{"price":0.05613,"qty":16.25531361}],"asks":[],"checksum":1515375773,"timestamp":"2024-06-01T17:52:18.266092Z"}]}
{"channel":"book","type":"update","data":[{"symbol":"ETH/BTC","bids":[],"asks":[{"price":0.05619,"qty":7.71621036}],"checksum":3777784671,"timestamp":"2024-06-01T17:52:18.310806Z"}]}
{"channel":"book","type":"update","data":[{"symbol":"ETH/BTC","bids":[{"price":0.05613,"qty":15.43971361}],"asks":[],"checksum":3825834401,"timestamp":"2024-06-01T17:52:18.321161Z"}]}
{"channel":"book","type":"update","data":[{"symbol":"ETH/BTC","bids":[],"asks":[{"price":0.05619,"qty":8.53760661}],"checksum":1601650275,"timestamp":"2024-06-01T17:52:18.367239Z"}]}
{"channel":"book","type":"update","data":[{"symbol":"ETH/BTC","bids":[{"price":0.05613,"qty":14.62411361}],"asks":[],"checksum":635879831,"timestamp":"2024-06-01T17:52:18.891680Z"}]}
{"channel":"book","type":"update","data":[{"symbol":"ETH/BTC","bids":[],"asks":[{"price":0.05619,"qty":3.91623157}],"checksum":629312222,"timestamp":"2024-06-01T17:52:20.019942Z"}]}
{"channel":"book","type":"update","data":[{"symbol":"ETH/BTC","bids":[{"price":0.05613,"qty":15.43971361}],"asks":[],"checksum":1595110698,"timestamp":"2024-06-01T17:52:20.303485Z"}]}
{"channel":"book","type":"update","data":[{"symbol":"ETH/BTC","bids":[{"price":0.05609,"qty":5.47741530}],"asks":[],"checksum":1067564375,"timestamp":"2024-06-01T17:52:20.630034Z"}]}
{"channel":"book","type":"update","data":[{"symbol":"ETH/BTC","bids":[{"price":0.05612,"qty":18.35410087}],"asks":[],"checksum":898554641,"timestamp":"2024-06-01T17:52:20.667866Z"}]}
{"channel":"book","type":"update","data":[{"symbol":"ETH/BTC","bids":[{"price":0.05611,"qty":26.15883355}],"asks":[],"checksum":1611112533,"timestamp":"2024-06-01T17:52:20.671659Z"}]}
{"channel":"book","type":"update","data":[{"symbol":"ETH/BTC","bids":[{"price":0.05613,"qty":18.07360291}],"asks":[],"checksum":4040225549,"timestamp":"2024-06-01T17:52:20.672229Z"}]}
{"channel":"book","type":"update","data":[{"symbol":"ETH/BTC","bids":[{"price":0.05606,"qty":56.57343022},{"price":0.05607,"qty":15.35825467}],"asks":[],"checksum":726878188,"timestamp":"2024-06-01T17:52:21.862224Z"}]}
{"channel":"book","type":"update","data":[{"symbol":"ETH/BTC","bids":[{"price":0.05611,"qty":15.62475075}],"asks":[],"checksum":2128231592,"timestamp":"2024-06-01T17:52:23.626000Z"}]}
{"channel":"book","type":"update","data":[{"symbol":"ETH/BTC","bids":[{"price":0.05613,"qty":10.17308531}],"asks":[],"checksum":241204494,"timestamp":"2024-06-01T17:52:23.626036Z"}]}
{"channel":"book","type":"update","data":[{"symbol":"ETH/BTC","bids":[],"asks":[{"price":0.05619,"qty":8.49381758}],"checksum":1993784709,"timestamp":"2024-06-01T17:52:23.666267Z"}]}
{"channel":"book","type":"update","data":[{"symbol":"ETH/BTC","bids":[],"asks":[{"price":0.05619,"qty":8.42692443}],"checksum":600284985,"timestamp":"2024-06-01T17:52:23.835881Z"}]}
{"channel":"book","type":"update","data":[{"symbol":"ETH/BTC","bids":[],"asks":[{"price":0.05619,"qty":8.49385801}],"checksum":3881047285,"timestamp":"2024-06-01T17:52:23.939962Z"}]}
{"channel":"book","type":"update","data":[{"symbol":"ETH/BTC","bids":[{"price":0.05609,"qty":16.01136371}],"asks":[],"checksum":3718205615,"timestamp":"2024-06-01T17:52:24.287672Z"}]}
{"channel":"book","type":"update","data":[{"symbol":"ETH/BTC","bids":[],"asks":[{"price":0.05616,"qty":16.51129797}],"checksum":1353637093,"timestamp":"2024-06-01T17:52:24.400314Z"}]}
{"channel":"book","type":"update","data":[{"symbol":"ETH/BTC","bids":[],"asks":[{"price":0.05619,"qty":6.16385801},{"price":0.05621,"qty":22.56758783}],"checksum":3160020318,"timestamp":"2024-06-01T17:52:24.402895Z"}]}
{"channel":"book","type":"update","data":[{"symbol":"ETH/BTC","bids":[],"asks":[{"price":0.05617,"qty":21.47982825}],"checksum":1660118807,"timestamp":"2024-06-01T17:52:24.801473Z"}]}
{"channel":"book","type":"update","data":[{"symbol":"ETH/BTC","bids":[{"price":0.05613,"qty":6.17308531}],"asks":[],"checksum":479928862,"timestamp":"2024-06-01T17:52:25.430236Z"}]}
{"channel":"book","type":"update","data":[{"symbol":"ETH/BTC","bids":[{"price":0.05613,"qty":6.98868531}],"asks":[],"checksum":2108138119,"timestamp":"2024-06-01T17:52:25.433736Z"}]}
{"channel":"book","type":"update","data":[{"symbol":"ETH/BTC","bids":[{"price":0.05607,"qty":14.85294833}],"asks":[],"checksum":496673387,"timestamp":"2024-06-01T17:52:26.648660Z"}]}
{"channel":"book","type":"update","data":[{"symbol":"ETH/BTC","bids":[{"price":0.05607,"qty":15.35825467}],"asks":[],"checksum":2108138119,"timestamp":"2024-06-01T17:52:26.744168Z"}]}
{"channel":"book","type":"update","data":[{"symbol":"ETH/BTC","bids":[{"price":0.05613,"qty":4.35479601}],"asks":[],"checksum":589602955,"timestamp":"2024-06-01T17:52:28.594326Z"}]}
{"channel":"book","type":"update","data":[{"symbol":"ETH/BTC","bids":[{"price":0.05612,"qty":20.98798920}],"asks":[],"checksum":3727963636,"timestamp":"2024-06-01T17:52:28.598423Z"}]}
{"channel":"book","type":"update","data":[{"symbol":"ETH/BTC","bids":[{"price":0.05613,"qty":12.25475569}],"asks":[],"checksum":1863872667,"timestamp":"2024-06-01T17:52:30.054457Z"}]}
{"channel":"book","type":"update","data":[{"symbol":"ETH/BTC","bids":[{"price":0.05613,"qty":4.35479601}],"asks":[],"checksum":3727963636,"timestamp":"2024-06-01T17:52:30.644884Z"}]}
{"channel":"book","type":"update","data":[{"symbol":"ETH/BTC","bids":[],"asks":[{"price":0.05615,"qty":9.22036262}],"checksum":3175183758,"timestamp":"2024-06-01T17:52:30.776109Z"}]}
{"channel":"book","type":"update","data":[{"symbol":"ETH/BTC","bids":[],"asks":[{"price":0.05615,"qty":6.58714258}],"checksum":2728621390,"timestamp":"2024-06-01T17:52:30.776257Z"}]}
{"channel":"book","type":"update","data":[{"symbol":"ETH/BTC","bids":[{"price":0.05612,"qty":18.35410087}],"asks":[],"checksum":1605623857,"timestamp":"2024-06-01T17:52:30.776304Z"}]}
{"channel":"book","type":"update","data":[{"symbol":"ETH/BTC","bids":[],"asks":[{"price":0.05616,"qty":19.14382244}],"checksum":583441778,"timestamp":"2024-06-01T17:52:30.783660Z"}]}
{"channel":"book","type":"update","data":[{"symbol":"ETH/BTC","bids":[],"asks":[{"price":0.05616,"qty":21.77654174}],"checksum":3977048933,"timestamp":"2024-06-01T17:52:30.783785Z"}]}
{"channel":"book","type":"update","data":[{"symbol":"ETH/BTC","bids":[{"price":0.05613,"qty":6.98863641}],"asks":[],"checksum":279072211,"timestamp":"2024-06-01T17:52:30.783842Z"}]}
{"channel":"book","type":"update","data":[{"symbol":"ETH/BTC","bids":[],"asks":[{"price":0.05614,"qty":0.00661950}],"checksum":4110220449,"timestamp":"2024-06-01T17:52:30.792359Z"}]}
{"channel":"book","type":"update","data":[{"symbol":"ETH/BTC","bids":[],"asks":[{"price":0.05615,"qty":6.03714258}],"checksum":4240096678,"timestamp":"2024-06-01T17:52:30.797782Z"}]}
{"channel":"book","type":"update","data":[{"symbol":"ETH/BTC","bids":[],"asks":[{"price":0.05615,"qty":5.22154258}],"checksum":279749633,"timestamp":"2024-06-01T17:52:30.812475Z"}]}
{"channel":"book","type":"update","data":[{"symbol":"ETH/BTC","bids":[],"asks":[{"price":0.05618,"qty":1.86892071}],"checksum":225303145,"timestamp":"2024-06-01T17:52:30.816865Z"}]}
{"channel":"book","type":"update","data":[{"symbol":"ETH/BTC","bids":[],"asks":[{"price":0.05616,"qty":20.87325853}],"checksum":4289013736,"timestamp":"2024-06-01T17:52:30.823296Z"}]}
{"channel":"book","type":"update","data":[{"symbol":"ETH/BTC","bids":[{"price":0.05605,"qty":0.90944228}],"asks":[],"checksum":2329826945,"timestamp":"2024-06-01T17:52:30.923706Z"}]}
{"channel":"book","type":"update","data":[{"symbol":"ETH/BTC","bids":[],"asks":[{"price":0.05619,"qty":5.34246176}],"checksum":3588653201,"timestamp":"2024-06-01T17:52:30.931554Z"}]}
{"channel":"book","type":"update","data":[{"symbol":"ETH/BTC","bids":[],"asks":[{"price":0.05620,"qty":14.99144426}],"checksum":4113581580,"timestamp":"2024-06-01T17:52:30.931814Z"}]}
{"channel":"book","type":"update","data":[{"symbol":"ETH/BTC","bids":[],"asks":[{"price":0.05615,"qty":6.03714258}],"checksum":2161887181,"timestamp":"2024-06-01T17:52:30.944271Z"}]}
{"channel":"book","type":"update","data":[{"symbol":"ETH/BTC","bids":[{"price":0.05613,"qty":10.98863641}],"asks":[],"checksum":2523247431,"timestamp":"2024-06-01T17:52:30.946063Z"}]}
{"channel":"book","type":"update","data":[{"symbol":"ETH/BTC","bids":[],"asks":[{"price":0.05615,"qty":4.43714258}],"checksum":1936986599,"timestamp":"2024-06-01T17:52:30.953319Z"}]}
{"channel":"book","type":"update","data":[{"symbol":"ETH/BTC","bids":[{"price":0.05612,"qty":17.80410087}],"asks":[],"checksum":4258835587,"timestamp":"2024-06-01T17:52:30.955929Z"}]}
{"channel":"book","type":"update","data":[{"symbol":"ETH/BTC","bids":[{"price":0.05613,"qty":11.53863641}],"asks":[],"checksum":768483921,"timestamp":"2024-06-01T17:52:30.956088Z"}]}
{"channel":"book","type":"update","data":[{"symbol":"ETH/BTC","bids":[],"asks":[{"price":0.05616,"qty":18.24053923}],"checksum":981861075,"timestamp":"2024-06-01T17:52:30.987402Z"}]}
{"channel":"book","type":"update","data":[{"symbol":"ETH/BTC","bids":[{"price":0.05613,"qty":10.72303641}],"asks":[],"checksum":4152890512,"timestamp":"2024-06-01T17:52:30.987535Z"}]}
{"channel":"book","type":"update","data":[{"symbol":"ETH/BTC","bids":[],"asks":[{"price":0.05616,"qty":15.60801476}],"checksum":2184016582,"timestamp":"2024-06-01T17:52:30.987552Z"}]}
{"channel":"book","type":"update","data":[{"symbol":"ETH/BTC","bids":[{"price":0.05613,"qty":9.90743641}],"asks":[],"checksum":165494328,"timestamp":"2024-06-01T17:52:30.988064Z"}]}
{"channel":"book","type":"update","data":[{"symbol":"ETH/BTC","bids":[],"asks":[{"price":0.05614,"qty":0.82221950}],"checksum":2566640640,"timestamp":"2024-06-01T17:52:30.989136Z"}]}
{"channel":"book","type":"update","data":[{"symbol":"ETH/BTC","bids":[],"asks":[{"price":0.05618,"qty":1.05332071}],"checksum":4002797584,"timestamp":"2024-06-01T17:52:30.989972Z"}]}
{"channel":"book","type":"update","data":[{"symbol":"ETH/BTC","bids":[{"price":0.05610,"qty":7.61220645}],"asks":[],"checksum":128690098,"timestamp":"2024-06-01T17:52:30.990100Z"}]}
{"channel":"book","type":"update","data":[{"symbol":"ETH/BTC","bids":[{"price":0.05608,"qty":15.44873826}],"asks":[],"checksum":1629645635,"timestamp":"2024-06-01T17:52:30.990226Z"}]}
{"channel":"book","type":"update","data":[{"symbol":"ETH/BTC","bids":[{"price":0.05608,"qty":16.43508866}],"asks":[],"checksum":3666990323,"timestamp":"2024-06-01T17:52:30.992712Z"}]}
{"channel":"book","type":"update","data":[{"symbol":"ETH/BTC","bids":[{"price":0.05607,"qty":16.85526786}],"asks":[],"checksum":3584242845,"timestamp":"2024-06-01T17:52:30.992857Z"}]}
{"channel":"book","type":"update","data":[{"symbol":"ETH/BTC","bids":[{"price":0.05613,"qty":7.27354711}],"asks":[],"checksum":1894380176,"timestamp":"2024-06-01T17:52:31.000422Z"}]}
{"channel":"book","type":"update","data":[{"symbol":"ETH/BTC","bids":[{"price":0.05613,"qty":4.63970671}],"asks":[],"checksum":3754723034,"timestamp":"2024-06-01T17:52:31.000623Z"}]}
{"channel":"book","type":"update","data":[{"symbol":"ETH/BTC","bids":[],"asks":[{"price":0.05614,"qty":3.45614009}],"checksum":2344308567,"timestamp":"2024-06-01T17:52:31.005680Z"}]}
{"channel":"book","type":"update","data":[{"symbol":"ETH/BTC","bids":[{"price":0.05612,"qty":20.43796476}],"asks":[],"checksum":3233264187,"timestamp":"2024-06-01T17:52:31.007025Z"}]}
{"channel":"book","type":"update","data":[{"symbol":"ETH/BTC","bids":[{"price":0.05611,"qty":14.72146754}],"asks":[],"checksum":3181214137,"timestamp":"2024-06-01T17:52:31.009404Z"}]}
{"channel":"book","type":"update","data":[{"symbol":"ETH/BTC","bids":[{"price":0.05612,"qty":7.26642389}],"asks":[],"checksum":2587455999,"timestamp":"2024-06-01T17:52:31.011554Z"}]}
{"channel":"book","type":"update","data":[{"symbol":"ETH/BTC","bids":[{"price":0.05612,"qty":6.63386389}],"asks":[],"checksum":1009058053,"timestamp":"2024-06-01T17:52:31.014058Z"}]}
{"channel":"book","type":"update","data":[{"symbol":"ETH/BTC","bids":[{"price":0.05607,"qty":15.35825467}],"asks":[],"checksum":857203051,"timestamp":"2024-06-01T17:52:31.014438Z"}]}
{"channel":"book","type":"update","data":[{"symbol":"ETH/BTC","bids":[{"price":0.05608,"qty":15.44873826}],"asks":[],"checksum":2292473563,"timestamp":"2024-06-01T17:52:31.014735Z"}]}
{"channel":"book","type":"update","data":[{"symbol":"ETH/BTC","bids":[{"price":0.05606,"qty":54.12365790}],"asks":[],"checksum":123382671,"timestamp":"2024-06-01T17:52:31.014810Z"}]}
{"channel":"book","type":"update","data":[{"symbol":"ETH/BTC","bids":[{"price":0.05610,"qty":1.61220645}],"asks":[],"checksum":3944667152,"timestamp":"2024-06-01T17:52:31.015961Z"}]}
{"channel":"book","type":"update","data":[{"symbol":"ETH/BTC","bids":[{"price":0.05604,"qty":20.73946799}],"asks":[],"checksum":993955123,"timestamp":"2024-06-01T17:52:31.017385Z"}]}
{"channel":"book","type":"update","data":[{"symbol":"ETH/BTC","bids":[{"price":0.05606,"qty":55.11000830}],"asks":[],"checksum":3747995730,"timestamp":"2024-06-01T17:52:31.017531Z"}]}
{"channel":"book","type":"update","data":[{"symbol":"ETH/BTC","bids":[{"price":0.05613,"qty":4.08970671}],"asks":[],"checksum":2935111713,"timestamp":"2024-06-01T17:52:31.019200Z"}]}
{"channel":"book","type":"update","data":[{"symbol":"ETH/BTC","bids":[],"asks":[{"price":0.05621,"qty":9.41537232}],"checksum":2211238203,"timestamp":"2024-06-01T17:52:31.023264Z"}]}
{"channel":"book","type":"update","data":[{"symbol":"ETH/BTC","bids":[],"asks":[{"price":0.05616,"qty":16.51129797}],"checksum":492011119,"timestamp":"2024-06-01T17:52:31.025168Z"}]}
{"channel":"book","type":"update","data":[{"symbol":"ETH/BTC","bids":[{"price":0.05610,"qty":1.37633639}],"asks":[],"checksum":1830562197,"timestamp":"2024-06-01T17:52:31.026298Z"}]}
{"channel":"book","type":"update","data":[{"symbol":"ETH/BTC","bids":[],"asks":[{"price":0.05616,"qty":3.34818408}],"checksum":1834219950,"timestamp":"2024-06-01T17:52:31.027081Z"}]}
{"channel":"book","type":"update","data":[{"symbol":"ETH/BTC","bids":[{"price":0.05611,"qty":1.54960000}],"asks":[],"checksum":561662523,"timestamp":"2024-06-01T17:52:31.027157Z"}]}
{"channel":"book","type":"update","data":[{"symbol":"ETH/BTC","bids":[{"price":0.05612,"qty":4.00000000}],"asks":[],"checksum":1883056619,"timestamp":"2024-06-01T17:52:31.027198Z"}]}
{"channel":"book","type":"update","data":[{"symbol":"ETH/BTC","bids":[{"price":0.05610,"qty":1.06084859}],"asks":[],"checksum":2462279543,"timestamp":"2024-06-01T17:52:31.029747Z"}]}
{"channel":"book","type":"update","data":[{"symbol":"ETH/BTC","bids":[{"price":0.05608,"qty":14.62734201}],"asks":[],"checksum":724474769,"timestamp":"2024-06-01T17:52:31.030580Z"}]}
{"channel":"book","type":"update","data":[{"symbol":"ETH/BTC","bids":[],"asks":[{"price":0.05621,"qty":6.95537232},{"price":0.05619,"qty":7.74246176}],"checksum":2234017210,"timestamp":"2024-06-01T17:52:31.033510Z"}]}
{"channel":"book","type":"update","data":[{"symbol":"ETH/BTC","bids":[{"price":0.05610,"qty":0.81560000}],"asks":[],"checksum":3443704083,"timestamp":"2024-06-01T17:52:31.037004Z"}]}
{"channel":"book","type":"update","data":[{"symbol":"ETH/BTC","bids":[{"price":0.05609,"qty":15.94443013}],"asks":[],"checksum":486552575,"timestamp":"2024-06-01T17:52:31.040029Z"}]}
{"channel":"book","type":"update","data":[{"symbol":"ETH/BTC","bids":[{"price":0.05608,"qty":14.00339984}],"asks":[],"checksum":1384224572,"timestamp":"2024-06-01T17:52:31.040055Z"}]}
{"channel":"book","type":"update","data":[{"symbol":"ETH/BTC","bids":[{"price":0.05605,"qty":14.09665180}],"asks":[],"checksum":37359689,"timestamp":"2024-06-01T17:52:31.042692Z"}]}
{"channel":"book","type":"update","data":[{"symbol":"ETH/BTC","bids":[],"asks":[{"price":0.05614,"qty":16.62237071}],"checksum":3068966132,"timestamp":"2024-06-01T17:52:31.042753Z"}]}
{"channel":"book","type":"update","data":[{"symbol":"ETH/BTC","bids":[{"price":0.05610,"qty":13.99107741}],"asks":[],"checksum":701399434,"timestamp":"2024-06-01T17:52:31.042769Z"}]}
{"channel":"book","type":"update","data":[{"symbol":"ETH/BTC","bids":[{"price":0.05607,"qty":14.85294833}],"asks":[],"checksum":2148668121,"timestamp":"2024-06-01T17:52:31.045128Z"}]}
{"channel":"book","type":"update","data":[{"symbol":"ETH/BTC","bids":[],"asks":[{"price":0.05619,"qty":8.24776810}],"checksum":1808081549,"timestamp":"2024-06-01T17:52:31.045251Z"}]}
{"channel":"book","type":"update","data":[{"symbol":"ETH/BTC","bids":[],"asks":[{"price":0.05617,"qty":22.79626506}],"checksum":621239347,"timestamp":"2024-06-01T17:52:31.048324Z"}]}
{"channel":"book","type":"update","data":[{"symbol":"ETH/BTC","bids":[],"asks":[{"price":0.05617,"qty":23.67848721}],"checksum":845795079,"timestamp":"2024-06-01T17:52:31.053840Z"}]}
{"channel":"book","type":"update","data":[{"symbol":"ETH/BTC","bids":[{"price":0.05611,"qty":0.81560000}],"asks":[],"checksum":115156194,"timestamp":"2024-06-01T17:52:31.054845Z"}]}
{"channel":"book","type":"update","data":[{"symbol":"ETH/BTC","bids":[],"asks":[{"price":0.05622,"qty":15.36962331}],"checksum":4219831630,"timestamp":"2024-06-01T17:52:31.055270Z"}]}
{"channel":"book","type":"update","data":[{"symbol":"ETH/BTC","bids":[],"asks":[{"price":0.05620,"qty":14.17004801}],"checksum":1120316219,"timestamp":"2024-06-01T17:52:31.055314Z"}]}
{"channel":"book","type":"update","data":[{"symbol":"ETH/BTC","bids":[],"asks":[{"price":0.05618,"qty":1.87471696}],"checksum":2925373345,"timestamp":"2024-06-01T17:52:31.055323Z"}]}
{"channel":"book","type":"update","data":[{"symbol":"ETH/BTC","bids":[],"asks":[{"price":0.05619,"qty":9.10276810}],"checksum":727968242,"timestamp":"2024-06-01T17:52:31.058111Z"}]}
{"channel":"book","type":"update","data":[{"symbol":"ETH/BTC","bids":[],"asks":[{"price":0.05615,"qty":5.34042579}],"checksum":3515850807,"timestamp":"2024-06-01T17:52:31.058620Z"}]}
{"channel":"book","type":"update","data":[{"symbol":"ETH/BTC","bids":[],"asks":[{"price":0.05619,"qty":9.03583452}],"checksum":811436553,"timestamp":"2024-06-01T17:52:31.062054Z"}]}
{"channel":"book","type":"update","data":[{"symbol":"ETH/BTC","bids":[],"asks":[{"price":0.05616,"qty":3.41511766}],"checksum":2934173819,"timestamp":"2024-06-01T17:52:31.062166Z"}]}
{"channel":"book","type":"update","data":[{"symbol":"ETH/BTC","bids":[],"asks":[{"price":0.05615,"qty":6.01436311}],"checksum":2272776550,"timestamp":"2024-06-01T17:52:31.072989Z"}]}
{"channel":"book","type":"update","data":[{"symbol":"ETH/BTC","bids":[],"asks":[{"price":0.05618,"qty":2.78371696}],"checksum":3329368890,"timestamp":"2024-06-01T17:52:31.073173Z"}]}
{"channel":"book","type":"update","data":[{"symbol":"ETH/BTC","bids":[],"asks":[{"price":0.05616,"qty":9.41511766}],"checksum":552623544,"timestamp":"2024-06-01T17:52:31.077454Z"}]}
{"channel":"book","type":"update","data":[{"symbol":"ETH/BTC","bids":[],"asks":[{"price":0.05618,"qty":3.44743479}],"checksum":3525114823,"timestamp":"2024-06-01T17:52:31.085406Z"}]}
{"channel":"book","type":"update","data":[{"symbol":"ETH/BTC","bids":[],"asks":[{"price":0.05616,"qty":9.94514972}],"checksum":1580888546,"timestamp":"2024-06-01T17:52:31.088816Z"}]}
{"channel":"book","type":"update","data":[{"symbol":"ETH/BTC","bids":[],"asks":[{"price":0.05616,"qty":9.04186651}],"checksum":2070207423,"timestamp":"2024-06-01T17:52:31.098119Z"}]}
{"channel":"book","type":"update","data":[{"symbol":"ETH/BTC","bids":[],"asks":[{"price":0.05619,"qty":8.41189235}],"checksum":102644114,"timestamp":"2024-06-01T17:52:31.105879Z"}]}
{"channel":"book","type":"update","data":[{"symbol":"ETH/BTC","bids":[],"asks":[{"price":0.05614,"qty":16.61575121},{"price":0.05616,"qty":9.04848728}],"checksum":2321721806,"timestamp":"2024-06-01T17:52:31.114976Z"}]}
{"channel":"book","type":"update","data":[{"symbol":"ETH/BTC","bids":[{"price":0.05613,"qty":4.00000000},{"price":0.05611,"qty":0.90036487}],"asks":[],"checksum":1776921137,"timestamp":"2024-06-01T17:52:31.115090Z"}]}
{"channel":"book","type":"update","data":[{"symbol":"ETH/BTC","bids":[],"asks":[{"price":0.05615,"qty":12.01436311}],"checksum":2189410012,"timestamp":"2024-06-01T17:52:31.128710Z"}]}
{"channel":"book","type":"update","data":[{"symbol":"ETH/BTC","bids":[],"asks":[{"price":0.05617,"qty":17.67848721}],"checksum":963443299,"timestamp":"2024-06-01T17:52:31.128855Z"}]}
{"channel":"book","type":"update","data":[{"symbol":"ETH/BTC","bids":[],"asks":[{"price":0.05614,"qty":18.72783714}],"checksum":2051877212,"timestamp":"2024-06-01T17:52:31.135253Z"}]}
{"channel":"book","type":"update","data":[{"symbol":"ETH/BTC","bids":[],"asks":[{"price":0.05619,"qty":9.03583452}],"checksum":121097073,"timestamp":"2024-06-01T17:52:31.139795Z"}]}
{"channel":"book","type":"update","data":[{"symbol":"ETH/BTC","bids":[],"asks":[{"price":0.05619,"qty":8.53052818}],"checksum":3207055990,"timestamp":"2024-06-01T17:52:31.144744Z"}]}
{"channel":"book","type":"update","data":[{"symbol":"ETH/BTC","bids":[],"asks":[{"price":0.05614,"qty":17.91223714}],"checksum":1175660927,"timestamp":"2024-06-01T17:52:31.147786Z"}]}
{"channel":"book","type":"update","data":[{"symbol":"ETH/BTC","bids":[{"price":0.05604,"qty":21.29554688}],"asks":[],"checksum":848111286,"timestamp":"2024-06-01T17:52:31.149827Z"}]}
{"channel":"book","type":"update","data":[{"symbol":"ETH/BTC","bids":[],"asks":[{"price":0.05617,"qty":16.36205040}],"checksum":1590955849,"timestamp":"2024-06-01T17:52:31.153415Z"}]}
{"channel":"book","type":"update","data":[{"symbol":"ETH/BTC","bids":[],"asks":[{"price":0.05617,"qty":15.47982825}],"checksum":761117642,"timestamp":"2024-06-01T17:52:31.154258Z"}]}
{"channel":"book","type":"update","data":[{"symbol":"ETH/BTC","bids":[],"asks":[{"price":0.05615,"qty":13.67595534}],"checksum":84304110,"timestamp":"2024-06-01T17:52:31.155506Z"}]}
{"channel":"book","type":"update","data":[{"symbol":"ETH/BTC","bids":[],"asks":[{"price":0.05616,"qty":3.04848728}],"checksum":3817086572,"timestamp":"2024-06-01T17:52:31.159674Z"}]}
{"channel":"book","type":"update","data":[{"symbol":"ETH/BTC","bids":[],"asks":[{"price":0.05615,"qty":13.00201802}],"checksum":3501825413,"timestamp":"2024-06-01T17:52:31.172287Z"}]}
{"channel":"book","type":"update","data":[{"symbol":"ETH/BTC","bids":[],"asks":[{"price":0.05614,"qty":18.81552035}],"checksum":1180074375,"timestamp":"2024-06-01T17:52:31.174680Z"}]}
{"channel":"book","type":"update","data":[{"symbol":"ETH/BTC","bids":[],"asks":[{"price":0.05618,"qty":2.78371696}],"checksum":3032098808,"timestamp":"2024-06-01T17:52:31.183711Z"}]}
{"channel":"book","type":"update","data":[{"symbol":"ETH/BTC","bids":[],"asks":[{"price":0.05614,"qty":21.12942743}],"checksum":3326002457,"timestamp":"2024-06-01T17:52:31.183943Z"}]}
{"channel":"book","type":"update","data":[{"symbol":"ETH/BTC","bids":[],"asks":[{"price":0.05616,"qty":2.51845522}],"checksum":2755473227,"timestamp":"2024-06-01T17:52:31.186861Z"}]}
{"channel":"book","type":"update","data":[{"symbol":"ETH/BTC","bids":[{"price":0.05610,"qty":14.84407741}],"asks":[],"checksum":3227852944,"timestamp":"2024-06-01T17:52:31.187034Z"}]}
{"channel":"book","type":"update","data":[{"symbol":"ETH/BTC","bids":[],"asks":[{"price":0.05616,"qty":2.51183445},{"price":0.05615,"qty":13.00863879}],"checksum":3960875847,"timestamp":"2024-06-01T17:52:31.201633Z"}]}
{"channel":"book","type":"update","data":[{"symbol":"ETH/BTC","bids":[],"asks":[{"price":0.05616,"qty":2.44490087}],"checksum":2610207823,"timestamp":"2024-06-01T17:52:31.203822Z"}]}
{"channel":"book","type":"update","data":[{"symbol":"ETH/BTC","bids":[{"price":0.05613,"qty":0.00000000},{"price":0.05603,"qty":7.04084464}],"asks":[],"checksum":1159645113,"timestamp":"2024-06-01T17:52:31.207005Z"}]}
{"channel":"book","type":"update","data":[{"symbol":"ETH/BTC","bids":[{"price":0.05610,"qty":1.66860000}],"asks":[],"checksum":1677751844,"timestamp":"2024-06-01T17:52:31.212257Z"}]}
{"channel":"book","type":"update","data":[{"symbol":"ETH/BTC","bids":[],"asks":[{"price":0.05615,"qty":12.10535558}],"checksum":1366489323,"timestamp":"2024-06-01T17:52:31.212991Z"}]}
{"channel":"book","type":"update","data":[{"symbol":"ETH/BTC","bids":[{"price":0.05606,"qty":53.90000830},{"price":0.05603,"qty":8.23084464}],"asks":[],"checksum":995874735,"timestamp":"2024-06-01T17:52:31.213207Z"}]}
{"channel":"book","type":"update","data":[{"symbol":"ETH/BTC","bids":[],"asks":[{"price":0.05621,"qty":4.31537232},{"price":0.05619,"qty":11.02052818}],"checksum":2710383955,"timestamp":"2024-06-01T17:52:31.214321Z"}]}
{"channel":"book","type":"update","data":[{"symbol":"ETH/BTC","bids":[],"asks":[{"price":0.05621,"qty":3.25537232},{"price":0.05618,"qty":3.81371696}],"checksum":2471899429,"timestamp":"2024-06-01T17:52:31.214340Z"}]}
{"channel":"book","type":"update","data":[{"symbol":"ETH/BTC","bids":[{"price":0.05609,"qty":5.41048172}],"asks":[],"checksum":1975963781,"timestamp":"2024-06-01T17:52:31.216410Z"}]}
{"channel":"book","type":"update","data":[{"symbol":"ETH/BTC","bids":[{"price":0.05606,"qty":30.78705479}],"asks":[],"checksum":966115521,"timestamp":"2024-06-01T17:52:31.216471Z"}]}
{"channel":"book","type":"update","data":[{"symbol":"ETH/BTC","bids":[{"price":0.05607,"qty":1.68534141}],"asks":[],"checksum":1992657275,"timestamp":"2024-06-01T17:52:31.216485Z"}]}
{"channel":"book","type":"update","data":[{"symbol":"ETH/BTC","bids":[{"price":0.05609,"qty":18.58914263}],"asks":[],"checksum":2605624346,"timestamp":"2024-06-01T17:52:31.218153Z"}]}
{"channel":"book","type":"update","data":[{"symbol":"ETH/BTC","bids":[{"price":0.05604,"qty":18.76554688}],"asks":[],"checksum":2994479331,"timestamp":"2024-06-01T17:52:31.220093Z"}]}
{"channel":"book","type":"update","data":[{"symbol":"ETH/BTC","bids":[],"asks":[{"price":0.05614,"qty":21.94502743}],"checksum":1978405146,"timestamp":"2024-06-01T17:52:31.222164Z"}]}
{"channel":"book","type":"update","data":[{"symbol":"ETH/BTC","bids":[],"asks":[{"price":0.05618,"qty":2.90471696}],"checksum":1009413989,"timestamp":"2024-06-01T17:52:31.226455Z"}]}
{"channel":"book","type":"update","data":[{"symbol":"ETH/BTC","bids":[{"price":0.05603,"qty":5.78107232}],"asks":[],"checksum":4269983972,"timestamp":"2024-06-01T17:52:31.227641Z"}]}
{"channel":"book","type":"update","data":[{"symbol":"ETH/BTC","bids":[],"asks":[{"price":0.05614,"qty":27.94502743}],"checksum":3809831239,"timestamp":"2024-06-01T17:52:31.231411Z"}]}
{"channel":"book","type":"update","data":[{"symbol":"ETH/BTC","bids":[],"asks":[{"price":0.05614,"qty":25.83294150}],"checksum":1775360601,"timestamp":"2024-06-01T17:52:31.234710Z"}]}
{"channel":"book","type":"update","data":[{"symbol":"ETH/BTC","bids":[],"asks":[{"price":0.05614,"qty":26.83294150}],"checksum":2325907880,"timestamp":"2024-06-01T17:52:31.235524Z"}]}
{"channel":"book","type":"update","data":[{"symbol":"ETH/BTC","bids":[],"asks":[{"price":0.05617,"qty":16.62229599}],"checksum":1800971810,"timestamp":"2024-06-01T17:52:31.239847Z"}]}
{"channel":"book","type":"update","data":[{"symbol":"ETH/BTC","bids":[{"price":0.05607,"qty":0.81560000},{"price":0.05604,"qty":19.66259103}],"asks":[],"checksum":1206226855,"timestamp":"2024-06-01T17:52:31.244967Z"}]}
{"channel":"book","type":"update","data":[{"symbol":"ETH/BTC","bids":[],"asks":[{"price":0.05614,"qty":27.38294150}],"checksum":792304947,"timestamp":"2024-06-01T17:52:31.249791Z"}]}
{"channel":"book","type":"update","data":[{"symbol":"ETH/BTC","bids":[],"asks":[{"price":0.05613,"qty":0.81560000}],"checksum":2943333616,"timestamp":"2024-06-01T17:52:31.254702Z"}]}
{"channel":"book","type":"update","data":[{"symbol":"ETH/BTC","bids":[],"asks":[{"price":0.05615,"qty":10.44376335}],"checksum":1699068373,"timestamp":"2024-06-01T17:52:31.254774Z"}]}
{"channel":"book","type":"update","data":[{"symbol":"ETH/BTC","bids":[],"asks":[{"price":0.05617,"qty":15.80669599}],"checksum":489479777,"timestamp":"2024-06-01T17:52:31.255290Z"}]}
{"channel":"book","type":"update","data":[{"symbol":"ETH/BTC","bids":[{"price":0.05605,"qty":37.21530428}],"asks":[],"checksum":1590902506,"timestamp":"2024-06-01T17:52:31.257736Z"}]}
{"channel":"book","type":"update","data":[{"symbol":"ETH/BTC","bids":[{"price":0.05608,"qty":24.53943354}],"asks":[],"checksum":2685620087,"timestamp":"2024-06-01T17:52:31.258101Z"}]}
{"channel":"book","type":"update","data":[{"symbol":"ETH/BTC","bids":[{"price":0.05612,"qty":11.90202527}],"asks":[],"checksum":2119905637,"timestamp":"2024-06-01T17:52:31.261424Z"}]}
{"channel":"book","type":"update","data":[{"symbol":"ETH/BTC","bids":[],"asks":[{"price":0.05618,"qty":2.08332071}],"checksum":975833513,"timestamp":"2024-06-01T17:52:31.262740Z"}]}
{"channel":"book","type":"update","data":[{"symbol":"ETH/BTC","bids":[{"price":0.05605,"qty":50.38534640}],"asks":[],"checksum":431472682,"timestamp":"2024-06-01T17:52:31.262984Z"}]}
{"channel":"book","type":"update","data":[{"symbol":"ETH/BTC","bids":[],"asks":[{"price":0.05615,"qty":4.44376335}],"checksum":689751640,"timestamp":"2024-06-01T17:52:31.266905Z"}]}
{"channel":"book","type":"update","data":[{"symbol":"ETH/BTC","bids":[],"asks":[{"price":0.05613,"qty":0.00000000},{"price":0.05623,"qty":1.36850000}],"checksum":372043040,"timestamp":"2024-06-01T17:52:31.269017Z"}]}
{"channel":"book","type":"update","data":[{"symbol":"ETH/BTC","bids":[],"asks":[{"price":0.05615,"qty":1.80857117}],"checksum":3483011825,"timestamp":"2024-06-01T17:52:31.275025Z"}]}
{"channel":"book","type":"update","data":[{"symbol":"ETH/BTC","bids":[],"asks":[{"price":0.05613,"qty":2.63534806}],"checksum":2168703328,"timestamp":"2024-06-01T17:52:31.275071Z"}]}
{"channel":"book","type":"update","data":[{"symbol":"ETH/BTC","bids":[],"asks":[{"price":0.05613,"qty":3.53863127}],"checksum":1533826567,"timestamp":"2024-06-01T17:52:31.277873Z"}]}
{"channel":"book","type":"update","data":[{"symbol":"ETH/BTC","bids":[],"asks":[{"price":0.05613,"qty":4.35423127}],"checksum":2169095202,"timestamp":"2024-06-01T17:52:31.279580Z"}]}
{"channel":"book","type":"update","data":[{"symbol":"ETH/BTC","bids":[{"price":0.05609,"qty":17.53582091}],"asks":[],"checksum":3726508753,"timestamp":"2024-06-01T17:52:31.280298Z"}]}
{"channel":"book","type":"update","data":[{"symbol":"ETH/BTC","bids":[],"asks":[{"price":0.05613,"qty":3.53863127}],"checksum":71012596,"timestamp":"2024-06-01T17:52:31.283256Z"}]}
{"channel":"book","type":"update","data":[{"symbol":"ETH/BTC","bids":[],"asks":[{"price":0.05615,"qty":1.80195040},{"price":0.05614,"qty":27.38956227}],"checksum":1081486122,"timestamp":"2024-06-01T17:52:31.283960Z"}]}
{"channel":"book","type":"update","data":[{"symbol":"ETH/BTC","bids":[],"asks":[{"price":0.05613,"qty":6.17261192}],"checksum":1753249583,"timestamp":"2024-06-01T17:52:31.285049Z"}]}
{"channel":"book","type":"update","data":[{"symbol":"ETH/BTC","bids":[],"asks":[{"price":0.05613,"qty":8.80659257}],"checksum":1879407198,"timestamp":"2024-06-01T17:52:31.285140Z"}]}
{"channel":"book","type":"update","data":[{"symbol":"ETH/BTC","bids":[],"asks":[{"price":0.05619,"qty":10.39658601}],"checksum":3087033928,"timestamp":"2024-06-01T17:52:31.298038Z"}]}
{"channel":"book","type":"update","data":[{"symbol":"ETH/BTC","bids":[],"asks":[{"price":0.05614,"qty":26.48627906}],"checksum":3883221977,"timestamp":"2024-06-01T17:52:31.308473Z"}]}
{"channel":"book","type":"update","data":[{"symbol":"ETH/BTC","bids":[],"asks":[{"price":0.05617,"qty":14.66422825}],"checksum":3849211895,"timestamp":"2024-06-01T17:52:31.338771Z"}]}
{"channel":"book","type":"update","data":[{"symbol":"ETH/BTC","bids":[{"price":0.05611,"qty":0.81560000},{"price":0.05610,"qty":1.75337998}],"asks":[],"checksum":2140374239,"timestamp":"2024-06-01T17:52:31.341539Z"}]}
{"channel":"book","type":"update","data":[{"symbol":"ETH/BTC","bids":[],"asks":[{"price":0.05614,"qty":26.47965829},{"price":0.05613,"qty":8.81321335}],"checksum":2244713245,"timestamp":"2024-06-01T17:52:31.356166Z"}]}
{"channel":"book","type":"update","data":[{"symbol":"ETH/BTC","bids":[],"asks":[{"price":0.05621,"qty":5.25537232}],"checksum":2068860110,"timestamp":"2024-06-01T17:52:31.365861Z"}]}
{"channel":"book","type":"update","data":[{"symbol":"ETH/BTC","bids":[{"price":0.05606,"qty":31.41099696}],"asks":[],"checksum":594768554,"timestamp":"2024-06-01T17:52:31.380789Z"}]}
{"channel":"book","type":"update","data":[{"symbol":"ETH/BTC","bids":[{"price":0.05609,"qty":20.17146391}],"asks":[],"checksum":2687237444,"timestamp":"2024-06-01T17:52:31.421015Z"}]}
{"channel":"book","type":"update","data":[{"symbol":"ETH/BTC","bids":[],"asks":[{"price":0.05620,"qty":14.23698159}],"checksum":3433250929,"timestamp":"2024-06-01T17:52:31.449723Z"}]}
{"channel":"book","type":"update","data":[{"symbol":"ETH/BTC","bids":[{"price":0.05606,"qty":30.78705479}],"asks":[],"checksum":2491448853,"timestamp":"2024-06-01T17:52:31.482409Z"}]}
{"channel":"book","type":"update","data":[{"symbol":"ETH/BTC","bids":[{"price":0.05607,"qty":1.43954217}],"asks":[],"checksum":3526650051,"timestamp":"2024-06-01T17:52:31.495979Z"}]}
{"channel":"book","type":"update","data":[{"symbol":"ETH/BTC","bids":[{"price":0.05612,"qty":7.90202527}],"asks":[],"checksum":3118811373,"timestamp":"2024-06-01T17:52:31.507410Z"}]}
{"channel":"book","type":"update","data":[{"symbol":"ETH/BTC","bids":[{"price":0.05610,"qty":4.38877921}],"asks":[],"checksum":610374827,"timestamp":"2024-06-01T17:52:31.512213Z"}]}
{"channel":"book","type":"update","data":[{"symbol":"ETH/BTC","bids":[{"price":0.05604,"qty":19.10651214}],"asks":[],"checksum":857933952,"timestamp":"2024-06-01T17:52:31.516733Z"}]}
{"channel":"book","type":"update","data":[{"symbol":"ETH/BTC","bids":[],"asks":[{"price":0.05616,"qty":2.95020721}],"checksum":1768589172,"timestamp":"2024-06-01T17:52:31.523375Z"}]}
{"channel":"book","type":"update","data":[{"symbol":"ETH/BTC","bids":[],"asks":[{"price":0.05613,"qty":9.62881335}],"checksum":2853554703,"timestamp":"2024-06-01T17:52:31.524176Z"}]}
{"channel":"book","type":"update","data":[{"symbol":"ETH/BTC","bids":[],"asks":[{"price":0.05620,"qty":17.77854159}],"checksum":1253753636,"timestamp":"2024-06-01T17:52:31.525293Z"}]}
{"channel":"book","type":"update","data":[{"symbol":"ETH/BTC","bids":[{"price":0.05610,"qty":4.30399923},{"price":0.05611,"qty":0.90036488}],"asks":[],"checksum":3874606340,"timestamp":"2024-06-01T17:52:31.554533Z"}]}
{"channel":"book","type":"update","data":[{"symbol":"ETH/BTC","bids":[{"price":0.05604,"qty":3.28305734}],"asks":[],"checksum":1468713761,"timestamp":"2024-06-01T17:52:31.566726Z"}]}
{"channel":"book","type":"update","data":[{"symbol":"ETH/BTC","bids":[{"price":0.05609,"qty":20.94046391}],"asks":[],"checksum":2503561148,"timestamp":"2024-06-01T17:52:31.594241Z"}]}
{"channel":"book","type":"update","data":[{"symbol":"ETH/BTC","bids":[],"asks":[{"price":0.05614,"qty":24.16575121}],"checksum":3431169776,"timestamp":"2024-06-01T17:52:31.594745Z"}]}
{"channel":"book","type":"update","data":[{"symbol":"ETH/BTC","bids":[{"price":0.05611,"qty":0.81560000},{"price":0.05610,"qty":4.38877922}],"asks":[],"checksum":2165214940,"timestamp":"2024-06-01T17:52:31.622732Z"}]}
{"channel":"book","type":"update","data":[{"symbol":"ETH/BTC","bids":[],"asks":[{"price":0.05616,"qty":2.44490087}],"checksum":3445514530,"timestamp":"2024-06-01T17:52:31.631842Z"}]}
{"channel":"book","type":"update","data":[{"symbol":"ETH/BTC","bids":[{"price":0.05608,"qty":25.59294933}],"asks":[],"checksum":376431106,"timestamp":"2024-06-01T17:52:31.633887Z"}]}
{"channel":"book","type":"update","data":[{"symbol":"ETH/BTC","bids":[],"asks":[{"price":0.05620,"qty":17.71160801}],"checksum":4084802992,"timestamp":"2024-06-01T17:52:31.634675Z"}]}
{"channel":"book","type":"update","data":[{"symbol":"ETH/BTC","bids":[{"price":0.05606,"qty":31.60845104}],"asks":[],"checksum":828568945,"timestamp":"2024-06-01T17:52:31.635833Z"}]}
{"channel":"book","type":"update","data":[{"symbol":"ETH/BTC","bids":[{"price":0.05610,"qty":3.53577922}],"asks":[],"checksum":3872548879,"timestamp":"2024-06-01T17:52:31.639931Z"}]}
{"channel":"book","type":"update","data":[{"symbol":"ETH/BTC","bids":[],"asks":[{"price":0.05615,"qty":1.86888398}],"checksum":4054931728,"timestamp":"2024-06-01T17:52:31.645771Z"}]}
{"channel":"book","type":"update","data":[{"symbol":"ETH/BTC","bids":[],"asks":[{"price":0.05613,"qty":8.81321335}],"checksum":2188542957,"timestamp":"2024-06-01T17:52:31.647233Z"}]}
{"channel":"book","type":"update","data":[{"symbol":"ETH/BTC","bids":[],"asks":[{"price":0.05615,"qty":15.03497370}],"checksum":4192996180,"timestamp":"2024-06-01T17:52:31.648689Z"}]}
{"channel":"book","type":"update","data":[{"symbol":"ETH/BTC","bids":[{"price":0.05609,"qty":18.30482091}],"asks":[],"checksum":3744899915,"timestamp":"2024-06-01T17:52:31.656272Z"}]}
{"channel":"book","type":"update","data":[{"symbol":"ETH/BTC","bids":[],"asks":[{"price":0.05613,"qty":7.90993014}],"checksum":2919477129,"timestamp":"2024-06-01T17:52:31.667481Z"}]}
{"channel":"book","type":"update","data":[{"symbol":"ETH/BTC","bids":[],"asks":[{"price":0.05614,"qty":25.06903442}],"checksum":1280106801,"timestamp":"2024-06-01T17:52:31.667558Z"}]}
{"channel":"book","type":"update","data":[{"symbol":"ETH/BTC","bids":[{"price":0.05612,"qty":8.71762527}],"asks":[],"checksum":1408994953,"timestamp":"2024-06-01T17:52:31.690090Z"}]}
{"channel":"book","type":"update","data":[{"symbol":"ETH/BTC","bids":[{"price":0.05603,"qty":6.28637866}],"asks":[],"checksum":264127434,"timestamp":"2024-06-01T17:52:31.699091Z"}]}
{"channel":"book","type":"update","data":[{"symbol":"ETH/BTC","bids":[{"price":0.05607,"qty":0.81560000}],"asks":[],"checksum":2898528441,"timestamp":"2024-06-01T17:52:31.708001Z"}]}
{"channel":"book","type":"update","data":[{"symbol":"ETH/BTC","bids":[{"price":0.05612,"qty":9.53322527}],"asks":[],"checksum":2040207285,"timestamp":"2024-06-01T17:52:31.708168Z"}]}
{"channel":"book","type":"update","data":[{"symbol":"ETH/BTC","bids":[{"price":0.05610,"qty":5.04262233}],"asks":[],"checksum":362091975,"timestamp":"2024-06-01T17:52:31.726781Z"}]}
{"channel":"book","type":"update","data":[{"symbol":"ETH/BTC","bids":[{"price":0.05610,"qty":4.95784234},{"price":0.05611,"qty":0.90036488}],"asks":[],"checksum":2454690617,"timestamp":"2024-06-01T17:52:31.741842Z"}]}
{"channel":"book","type":"update","data":[{"symbol":"ETH/BTC","bids":[],"asks":[{"price":0.05614,"qty":24.06903442}],"checksum":1473399706,"timestamp":"2024-06-01T17:52:31.767774Z"}]}
{"channel":"book","type":"update","data":[{"symbol":"ETH/BTC","bids":[],"asks":[{"price":0.05613,"qty":5.27594949}],"checksum":1947944935,"timestamp":"2024-06-01T17:52:31.771365Z"}]}
{"channel":"book","type":"update","data":[{"symbol":"ETH/BTC","bids":[],"asks":[{"price":0.05614,"qty":26.70281879}],"checksum":1819002681,"timestamp":"2024-06-01T17:52:31.785879Z"}]}
{"channel":"book","type":"update","data":[{"symbol":"ETH/BTC","bids":[],"asks":[{"price":0.05613,"qty":2.64196884}],"checksum":1275188189,"timestamp":"2024-06-01T17:52:31.790429Z"}]}
{"channel":"book","type":"update","data":[{"symbol":"ETH/BTC","bids":[],"asks":[{"price":0.05615,"qty":21.03497370}],"checksum":166873607,"timestamp":"2024-06-01T17:52:31.794279Z"}]}
{"channel":"book","type":"update","data":[{"symbol":"ETH/BTC","bids":[],"asks":[{"price":0.05614,"qty":29.33679825}],"checksum":3619852894,"timestamp":"2024-06-01T17:52:31.794465Z"}]}
{"channel":"book","type":"update","data":[{"symbol":"ETH/BTC","bids":[],"asks":[{"price":0.05614,"qty":23.33679825}],"checksum":500412164,"timestamp":"2024-06-01T17:52:31.794525Z"}]}
{"channel":"book","type":"update","data":[{"symbol":"ETH/BTC","bids":[{"price":0.05608,"qty":26.53044364}],"asks":[],"checksum":2421558160,"timestamp":"2024-06-01T17:52:31.832663Z"}]}
{"channel":"book","type":"update","data":[{"symbol":"ETH/BTC","bids":[],"asks":[{"price":0.05614,"qty":10.17056763}],"checksum":3159178571,"timestamp":"2024-06-01T17:52:31.838928Z"}]}
{"channel":"book","type":"update","data":[{"symbol":"ETH/BTC","bids":[],"asks":[{"price":0.05620,"qty":30.87002602}],"checksum":1855505888,"timestamp":"2024-06-01T17:52:31.843884Z"}]}
{"channel":"book","type":"update","data":[{"symbol":"ETH/BTC","bids":[{"price":0.05610,"qty":2.32244311}],"asks":[],"checksum":2856055214,"timestamp":"2024-06-01T17:52:31.846281Z"}]}
{"channel":"book","type":"update","data":[{"symbol":"ETH/BTC","bids":[{"price":0.05612,"qty":1.63120000}],"asks":[],"checksum":2959071156,"timestamp":"2024-06-01T17:52:31.863871Z"}]}
{"channel":"book","type":"update","data":[{"symbol":"ETH/BTC","bids":[{"price":0.05605,"qty":27.26669392}],"asks":[],"checksum":4221597014,"timestamp":"2024-06-01T17:52:31.864037Z"}]}
{"channel":"book","type":"update","data":[{"symbol":"ETH/BTC","bids":[{"price":0.05610,"qty":2.87244311}],"asks":[],"checksum":2492318319,"timestamp":"2024-06-01T17:52:31.867100Z"}]}
{"channel":"book","type":"update","data":[{"symbol":"ETH/BTC","bids":[],"asks":[{"price":0.05615,"qty":20.96804012}],"checksum":1660378734,"timestamp":"2024-06-01T17:52:31.892020Z"}]}
{"channel":"book","type":"update","data":[{"symbol":"ETH/BTC","bids":[{"price":0.05611,"qty":0.81560000},{"price":0.05610,"qty":2.95722310}],"asks":[],"checksum":1511761481,"timestamp":"2024-06-01T17:52:31.896713Z"}]}
{"channel":"book","type":"update","data":[{"symbol":"ETH/BTC","bids":[{"price":0.05612,"qty":0.81560000}],"asks":[],"checksum":444774188,"timestamp":"2024-06-01T17:52:31.902301Z"}]}
{"channel":"book","type":"update","data":[{"symbol":"ETH/BTC","bids":[{"price":0.05604,"qty":26.40606492}],"asks":[],"checksum":2888791104,"timestamp":"2024-06-01T17:52:31.904158Z"}]}
{"channel":"book","type":"update","data":[{"symbol":"ETH/BTC","bids":[],"asks":[{"price":0.05616,"qty":4.31919986}],"checksum":150247702,"timestamp":"2024-06-01T17:52:31.904181Z"}]}
{"channel":"book","type":"update","data":[{"symbol":"ETH/BTC","bids":[{"price":0.05607,"qty":1.43954217}],"asks":[],"checksum":717759090,"timestamp":"2024-06-01T17:52:31.922561Z"}]}
{"channel":"book","type":"update","data":[{"symbol":"ETH/BTC","bids":[{"price":0.05610,"qty":1.45037999}],"asks":[],"checksum":4036141067,"timestamp":"2024-06-01T17:52:31.936394Z"}]}
{"channel":"book","type":"update","data":[{"symbol":"ETH/BTC","bids":[{"price":0.05603,"qty":5.78107232}],"asks":[],"checksum":2899799368,"timestamp":"2024-06-01T17:52:31.936405Z"}]}
{"channel":"book","type":"update","data":[{"symbol":"ETH/BTC","bids":[{"price":0.05606,"qty":32.11375738}],"asks":[],"checksum":3489606912,"timestamp":"2024-06-01T17:52:31.936567Z"}]}
{"channel":"book","type":"update","data":[{"symbol":"ETH/BTC","bids":[{"price":0.05612,"qty":2.65757644}],"asks":[],"checksum":3118502292,"timestamp":"2024-06-01T17:52:31.936581Z"}]}
{"channel":"book","type":"update","data":[{"symbol":"ETH/BTC","bids":[{"price":0.05610,"qty":1.36560000},{"price":0.05612,"qty":2.74232622}],"asks":[],"checksum":839993322,"timestamp":"2024-06-01T17:52:31.955710Z"}]}
{"channel":"book","type":"update","data":[{"symbol":"ETH/BTC","bids":[{"price":0.05608,"qty":25.59294933}],"asks":[],"checksum":4136100480,"timestamp":"2024-06-01T17:52:31.971973Z"}]}
{"channel":"book","type":"update","data":[{"symbol":"ETH/BTC","bids":[{"price":0.05609,"qty":19.24231522}],"asks":[],"checksum":4284376123,"timestamp":"2024-06-01T17:52:31.972176Z"}]}
{"channel":"book","type":"update","data":[{"symbol":"ETH/BTC","bids":[],"asks":[{"price":0.05618,"qty":2.72932071}],"checksum":4164133403,"timestamp":"2024-06-01T17:52:31.987923Z"}]}
{"channel":"book","type":"update","data":[{"symbol":"ETH/BTC","bids":[],"asks":[{"price":0.05616,"qty":4.38613344}],"checksum":2460458037,"timestamp":"2024-06-01T17:52:31.996085Z"}]}
{"channel":"book","type":"update","data":[{"symbol":"ETH/BTC","bids":[{"price":0.05608,"qty":12.40514949}],"asks":[],"checksum":2860424363,"timestamp":"2024-06-01T17:52:32.005686Z"}]}
{"channel":"book","type":"update","data":[{"symbol":"ETH/BTC","bids":[{"price":0.05610,"qty":14.54285432}],"asks":[],"checksum":2210263873,"timestamp":"2024-06-01T17:52:32.009779Z"}]}
{"channel":"book","type":"update","data":[{"symbol":"ETH/BTC","bids":[{"price":0.05612,"qty":2.65757644},{"price":0.05611,"qty":0.90036488}],"asks":[],"checksum":3901281173,"timestamp":"2024-06-01T17:52:32.013880Z"}]}
{"channel":"book","type":"update","data":[{"symbol":"ETH/BTC","bids":[{"price":0.05611,"qty":3.53522882}],"asks":[],"checksum":3668530424,"timestamp":"2024-06-01T17:52:32.014652Z"}]}
{"channel":"book","type":"update","data":[{"symbol":"ETH/BTC","bids":[{"price":0.05612,"qty":0.81560000}],"asks":[],"checksum":3345186040,"timestamp":"2024-06-01T17:52:32.039136Z"}]}
{"channel":"book","type":"update","data":[{"symbol":"ETH/BTC","bids":[{"price":0.05612,"qty":1.63120000}],"asks":[],"checksum":2765852696,"timestamp":"2024-06-01T17:52:32.055599Z"}]}
{"channel":"book","type":"update","data":[{"symbol":"ETH/BTC","bids":[{"price":0.05611,"qty":4.69748999}],"asks":[],"checksum":2912369740,"timestamp":"2024-06-01T17:52:32.132697Z"}]}
{"channel":"book","type":"update","data":[{"symbol":"ETH/BTC","bids":[{"price":0.05611,"qty":4.61272511},{"price":0.05612,"qty":1.71594978}],"asks":[],"checksum":3743708632,"timestamp":"2024-06-01T17:52:32.178327Z"}]}
{"channel":"book","type":"update","data":[{"symbol":"ETH/BTC","bids":[],"asks":[{"price":0.05614,"qty":11.77056763}],"checksum":3029567732,"timestamp":"2024-06-01T17:52:32.409869Z"}]}
{"channel":"book","type":"update","data":[{"symbol":"ETH/BTC","bids":[],"asks":[{"price":0.05616,"qty":2.51183445}],"checksum":3711713869,"timestamp":"2024-06-01T17:52:32.509798Z"}]}
{"channel":"book","type":"update","data":[{"symbol":"ETH/BTC","bids":[{"price":0.05608,"qty":1.86911579}],"asks":[],"checksum":1920583866,"timestamp":"2024-06-01T17:52:32.509819Z"}]}
{"channel":"book","type":"update","data":[{"symbol":"ETH/BTC","bids":[{"price":0.05609,"qty":18.30482091}],"asks":[],"checksum":498292918,"timestamp":"2024-06-01T17:52:32.530510Z"}]}
{"channel":"book","type":"update","data":[{"symbol":"ETH/BTC","bids":[{"price":0.05610,"qty":15.48034863}],"asks":[],"checksum":2557813769,"timestamp":"2024-06-01T17:52:32.531517Z"}]}
{"channel":"book","type":"update","data":[{"symbol":"ETH/BTC","bids":[{"price":0.05610,"qty":23.38302667}],"asks":[],"checksum":985915059,"timestamp":"2024-06-01T17:52:32.549933Z"}]}
{"channel":"book","type":"update","data":[{"symbol":"ETH/BTC","bids":[{"price":0.05607,"qty":11.97644622}],"asks":[],"checksum":2769036869,"timestamp":"2024-06-01T17:52:32.550115Z"}]}
{"channel":"book","type":"update","data":[{"symbol":"ETH/BTC","bids":[{"price":0.05608,"qty":7.86911579}],"asks":[],"checksum":3310704728,"timestamp":"2024-06-01T17:52:32.554802Z"}]}
{"channel":"book","type":"update","data":[{"symbol":"ETH/BTC","bids":[],"asks":[{"price":0.05621,"qty":4.59237232}],"checksum":1902053561,"timestamp":"2024-06-01T17:52:32.593352Z"}]}
{"channel":"book","type":"update","data":[{"symbol":"ETH/BTC","bids":[{"price":0.05605,"qty":27.17285164},{"price":0.05604,"qty":26.49992394}],"asks":[],"checksum":4159377767,"timestamp":"2024-06-01T17:52:32.657007Z"}]}
{"channel":"book","type":"update","data":[{"symbol":"ETH/BTC","bids":[],"asks":[{"price":0.05622,"qty":1.26340000}],"checksum":490871166,"timestamp":"2024-06-01T17:52:33.078472Z"}]}
{"channel":"book","type":"update","data":[{"symbol":"ETH/BTC","bids":[{"price":0.05607,"qty":1.43954217}],"asks":[],"checksum":673642890,"timestamp":"2024-06-01T17:52:33.078538Z"}]}
{"channel":"book","type":"update","data":[{"symbol":"ETH/BTC","bids":[{"price":0.05610,"qty":15.48034863}],"asks":[],"checksum":2324693808,"timestamp":"2024-06-01T17:52:33.078566Z"}]}
{"channel":"book","type":"update","data":[{"symbol":"ETH/BTC","bids":[{"price":0.05605,"qty":14.00280952}],"asks":[],"checksum":700110674,"timestamp":"2024-06-01T17:52:33.078588Z"}]}
{"channel":"book","type":"update","data":[{"symbol":"ETH/BTC","bids":[{"price":0.05609,"qty":28.84168153}],"asks":[],"checksum":4026249355,"timestamp":"2024-06-01T17:52:33.118646Z"}]}
{"channel":"book","type":"update","data":[{"symbol":"ETH/BTC","bids":[{"price":0.05606,"qty":45.28483315}],"asks":[],"checksum":2919800899,"timestamp":"2024-06-01T17:52:33.118667Z"}]}
{"channel":"book","type":"update","data":[{"symbol":"ETH/BTC","bids":[],"asks":[{"price":0.05620,"qty":44.96789254}],"checksum":2207576452,"timestamp":"2024-06-01T17:52:33.118688Z"}]}
{"channel":"book","type":"update","data":[{"symbol":"ETH/BTC","bids":[{"price":0.05611,"qty":8.61272511}],"asks":[],"checksum":42657545,"timestamp":"2024-06-01T17:52:33.129908Z"}]}
{"channel":"book","type":"update","data":[{"symbol":"ETH/BTC","bids":[{"price":0.05604,"qty":27.05600283}],"asks":[],"checksum":3381871812,"timestamp":"2024-06-01T17:52:33.160329Z"}]}
{"channel":"book","type":"update","data":[{"symbol":"ETH/BTC","bids":[{"price":0.05609,"qty":29.11579126}],"asks":[],"checksum":136397596,"timestamp":"2024-06-01T17:52:33.181118Z"}]}
{"channel":"book","type":"update","data":[{"symbol":"ETH/BTC","bids":[{"price":0.05611,"qty":11.24757008}],"asks":[],"checksum":2115294618,"timestamp":"2024-06-01T17:52:33.192633Z"}]}
{"channel":"book","type":"update","data":[{"symbol":"ETH/BTC","bids":[{"price":0.05610,"qty":16.21134863}],"asks":[],"checksum":3594313674,"timestamp":"2024-06-01T17:52:33.217878Z"}]}
{"channel":"book","type":"update","data":[{"symbol":"ETH/BTC","bids":[{"price":0.05611,"qty":10.08530891}],"asks":[],"checksum":604101900,"timestamp":"2024-06-01T17:52:33.633673Z"}]}
{"channel":"book","type":"update","data":[{"symbol":"ETH/BTC","bids":[{"price":0.05609,"qty":18.57893064}],"asks":[],"checksum":2185767988,"timestamp":"2024-06-01T17:52:33.721370Z"}]}
{"channel":"book","type":"update","data":[{"symbol":"ETH/BTC","bids":[{"price":0.05609,"qty":19.48154854}],"asks":[],"checksum":3840748886,"timestamp":"2024-06-01T17:52:33.729190Z"}]}
{"channel":"book","type":"update","data":[{"symbol":"ETH/BTC","bids":[],"asks":[{"price":0.05620,"qty":31.80947453}],"checksum":775220561,"timestamp":"2024-06-01T17:52:34.240551Z"}]}
{"channel":"book","type":"update","data":[{"symbol":"ETH/BTC","bids":[],"asks":[{"price":0.05614,"qty":9.13658817}],"checksum":3636824788,"timestamp":"2024-06-01T17:52:34.240677Z"}]}
{"channel":"book","type":"update","data":[{"symbol":"ETH/BTC","bids":[],"asks":[{"price":0.05615,"qty":34.13537873}],"checksum":932993151,"timestamp":"2024-06-01T17:52:34.247008Z"}]}
{"channel":"book","type":"update","data":[{"symbol":"ETH/BTC","bids":[],"asks":[{"price":0.05613,"qty":5.27600307}],"checksum":2413081910,"timestamp":"2024-06-01T17:52:34.247129Z"}]}
{"channel":"book","type":"update","data":[{"symbol":"ETH/BTC","bids":[],"asks":[{"price":0.05616,"qty":0.91183445}],"checksum":1142742340,"timestamp":"2024-06-01T17:52:34.387475Z"}]}
{"channel":"book","type":"update","data":[{"symbol":"ETH/BTC","bids":[{"price":0.05606,"qty":54.65729130}],"asks":[],"checksum":3109962734,"timestamp":"2024-06-01T17:52:34.525449Z"}]}
{"channel":"book","type":"update","data":[{"symbol":"ETH/BTC","bids":[{"price":0.05609,"qty":19.20743881}],"asks":[],"checksum":1840810726,"timestamp":"2024-06-01T17:52:34.609690Z"}]}
{"channel":"book","type":"update","data":[{"symbol":"ETH/BTC","bids":[{"price":0.05606,"qty":45.28483315}],"asks":[],"checksum":2432308300,"timestamp":"2024-06-01T17:52:35.140396Z"}]}
{"channel":"book","type":"update","data":[{"symbol":"ETH/BTC","bids":[{"price":0.05610,"qty":15.27385432}],"asks":[],"checksum":86693782,"timestamp":"2024-06-01T17:52:35.232533Z"}]}
{"channel":"book","type":"update","data":[{"symbol":"ETH/BTC","bids":[{"price":0.05609,"qty":19.60322377}],"asks":[],"checksum":3754608678,"timestamp":"2024-06-01T17:52:35.331656Z"}]}
{"channel":"book","type":"update","data":[{"symbol":"ETH/BTC","bids":[],"asks":[{"price":0.05615,"qty":20.96804012}],"checksum":1393052005,"timestamp":"2024-06-01T17:52:35.534452Z"}]}
{"channel":"book","type":"update","data":[{"symbol":"ETH/BTC","bids":[],"asks":[{"price":0.05614,"qty":22.30440804}],"checksum":3636133150,"timestamp":"2024-06-01T17:52:35.538594Z"}]}
{"channel":"book","type":"update","data":[{"symbol":"ETH/BTC","bids":[{"price":0.05604,"qty":26.96214381},{"price":0.05603,"qty":5.87494810}],"asks":[],"checksum":1367879453,"timestamp":"2024-06-01T17:52:36.616660Z"}]}
{"channel":"book","type":"update","data":[{"symbol":"ETH/BTC","bids":[],"asks":[{"price":0.05614,"qty":19.67062367}],"checksum":128720117,"timestamp":"2024-06-01T17:52:36.847758Z"}]}
{"channel":"book","type":"update","data":[{"symbol":"ETH/BTC","bids":[],"asks":[{"price":0.05613,"qty":7.91003730}],"checksum":1980252961,"timestamp":"2024-06-01T17:52:36.851617Z"}]}
{"channel":"book","type":"update","data":[{"symbol":"ETH/BTC","bids":[{"price":0.05611,"qty":7.45044497}],"asks":[],"checksum":471152260,"timestamp":"2024-06-01T17:52:36.882433Z"}]}
{"channel":"book","type":"update","data":[{"symbol":"ETH/BTC","bids":[{"price":0.05610,"qty":17.90897873}],"asks":[],"checksum":266335228,"timestamp":"2024-06-01T17:52:36.886255Z"}]}
{"channel":"book","type":"update","data":[{"symbol":"ETH/BTC","bids":[],"asks":[{"price":0.05619,"qty":5.81900000}],"checksum":2505146555,"timestamp":"2024-06-01T17:52:37.436661Z"}]}
{"channel":"book","type":"update","data":[{"symbol":"ETH/BTC","bids":[{"price":0.05612,"qty":0.90034978}],"asks":[],"checksum":1469993652,"timestamp":"2024-06-01T17:52:37.785782Z"}]}
{"channel":"book","type":"update","data":[{"symbol":"ETH/BTC","bids":[{"price":0.05612,"qty":1.71594978}],"asks":[],"checksum":2505146555,"timestamp":"2024-06-01T17:52:37.792766Z"}]}
{"channel":"book","type":"update","data":[{"symbol":"ETH/BTC","bids":[{"price":0.05609,"qty":19.20743881}],"asks":[],"checksum":1337040651,"timestamp":"2024-06-01T17:52:37.891150Z"}]}
{"channel":"book","type":"update","data":[{"symbol":"ETH/BTC","bids":[],"asks":[{"price":0.05617,"qty":13.16721506}],"checksum":2344469819,"timestamp":"2024-06-01T17:52:37.971670Z"}]}
{"channel":"book","type":"update","data":[{"symbol":"ETH/BTC","bids":[{"price":0.05606,"qty":44.29848275}],"asks":[],"checksum":2640827253,"timestamp":"2024-06-01T17:52:37.971716Z"}]}
{"channel":"book","type":"update","data":[{"symbol":"ETH/BTC","bids":[{"price":0.05604,"qty":25.46513062}],"asks":[],"checksum":3736636986,"timestamp":"2024-06-01T17:52:37.971795Z"}]}
{"channel":"book","type":"update","data":[{"symbol":"ETH/BTC","bids":[],"asks":[{"price":0.05615,"qty":19.98168972}],"checksum":2011956791,"timestamp":"2024-06-01T17:52:37.971803Z"}]}
{"channel":"book","type":"update","data":[{"symbol":"ETH/BTC","bids":[{"price":0.05610,"qty":15.27385432}],"asks":[],"checksum":1680261967,"timestamp":"2024-06-01T17:52:37.973986Z"}]}
{"channel":"book","type":"update","data":[{"symbol":"ETH/BTC","bids":[],"asks":[{"price":0.05615,"qty":21.47870291}],"checksum":1963221274,"timestamp":"2024-06-01T17:52:37.974150Z"}]}
{"channel":"book","type":"update","data":[{"symbol":"ETH/BTC","bids":[{"price":0.05608,"qty":8.85546619}],"asks":[],"checksum":2633212230,"timestamp":"2024-06-01T17:52:37.974352Z"}]}
{"channel":"book","type":"update","data":[{"symbol":"ETH/BTC","bids":[{"price":0.05607,"qty":2.93655536}],"asks":[],"checksum":1877561510,"timestamp":"2024-06-01T17:52:37.974462Z"}]}
{"channel":"book","type":"update","data":[{"symbol":"ETH/BTC","bids":[],"asks":[{"price":0.05614,"qty":20.65697407}],"checksum":2423550901,"timestamp":"2024-06-01T17:52:37.974582Z"}]}
{"channel":"book","type":"update","data":[{"symbol":"ETH/BTC","bids":[],"asks":[{"price":0.05614,"qty":19.05697407}],"checksum":3471230045,"timestamp":"2024-06-01T17:52:37.974825Z"}]}
{"channel":"book","type":"update","data":[{"symbol":"ETH/BTC","bids":[],"asks":[{"price":0.05614,"qty":18.24137407}],"checksum":90606481,"timestamp":"2024-06-01T17:52:37.975073Z"}]}
{"channel":"book","type":"update","data":[{"symbol":"ETH/BTC","bids":[{"price":0.05603,"qty":8.16494810}],"asks":[],"checksum":1292991577,"timestamp":"2024-06-01T17:52:37.975530Z"}]}
{"channel":"book","type":"update","data":[{"symbol":"ETH/BTC","bids":[],"asks":[{"price":0.05618,"qty":1.69932071},{"price":0.05620,"qty":32.90947453}],"checksum":3830369005,"timestamp":"2024-06-01T17:52:37.975803Z"}]}
{"channel":"book","type":"update","data":[{"symbol":"ETH/BTC","bids":[],"asks":[{"price":0.05619,"qty":3.32900000},{"price":0.05621,"qty":7.02237232}],"checksum":2323204371,"timestamp":"2024-06-01T17:52:37.975905Z"}]}
{"channel":"book","type":"update","data":[{"symbol":"ETH/BTC","bids":[{"price":0.05603,"qty":6.97494810},{"price":0.05605,"qty":15.17280952}],"asks":[],"checksum":2454255199,"timestamp":"2024-06-01T17:52:37.976050Z"}]}
{"channel":"book","type":"update","data":[{"symbol":"ETH/BTC","bids":[],"asks":[{"price":0.05614,"qty":17.33809086}],"checksum":88771025,"timestamp":"2024-06-01T17:52:37.976175Z"}]}
{"channel":"book","type":"update","data":[{"symbol":"ETH/BTC","bids":[],"asks":[{"price":0.05615,"qty":15.47870291}],"checksum":1085870091,"timestamp":"2024-06-01T17:52:37.977947Z"}]}
{"channel":"book","type":"update","data":[{"symbol":"ETH/BTC","bids":[],"asks":[{"price":0.05613,"qty":5.27600307}],"checksum":1086922070,"timestamp":"2024-06-01T17:52:37.978053Z"}]}
{"channel":"book","type":"update","data":[{"symbol":"ETH/BTC","bids":[],"asks":[{"price":0.05616,"qty":6.91183445}],"checksum":871023587,"timestamp":"2024-06-01T17:52:37.978200Z"}]}
{"channel":"book","type":"update","data":[{"symbol":"ETH/BTC","bids":[],"asks":[{"price":0.05617,"qty":13.98281506}],"checksum":3575474944,"timestamp":"2024-06-01T17:52:37.980207Z"}]}
{"channel":"book","type":"update","data":[{"symbol":"ETH/BTC","bids":[],"asks":[{"price":0.05620,"qty":29.36791453}],"checksum":3484263178,"timestamp":"2024-06-01T17:52:37.981058Z"}]}
{"channel":"book","type":"update","data":[{"symbol":"ETH/BTC","bids":[],"asks":[{"price":0.05614,"qty":4.17027099}],"checksum":2662160500,"timestamp":"2024-06-01T17:52:37.982017Z"}]}
{"channel":"book","type":"update","data":[{"symbol":"ETH/BTC","bids":[],"asks":[{"price":0.05613,"qty":2.64196884}],"checksum":3643750435,"timestamp":"2024-06-01T17:52:37.982098Z"}]}
{"channel":"book","type":"update","data":[{"symbol":"ETH/BTC","bids":[],"asks":[{"price":0.05616,"qty":0.91183445}],"checksum":1390023008,"timestamp":"2024-06-01T17:52:37.986458Z"}]}
{"channel":"book","type":"update","data":[{"symbol":"ETH/BTC","bids":[{"price":0.05605,"qty":1.98560000}],"asks":[],"checksum":4246485405,"timestamp":"2024-06-01T17:52:37.988074Z"}]}
{"channel":"book","type":"update","data":[{"symbol":"ETH/BTC","bids":[],"asks":[{"price":0.05613,"qty":0.00662078}],"checksum":2284467678,"timestamp":"2024-06-01T17:52:37.994511Z"}]}
{"channel":"book","type":"update","data":[{"symbol":"ETH/BTC","bids":[{"price":0.05610,"qty":28.44919071}],"asks":[],"checksum":2277862048,"timestamp":"2024-06-01T17:52:37.994643Z"}]}
{"channel":"book","type":"update","data":[{"symbol":"ETH/BTC","bids":[],"asks":[{"price":0.05620,"qty":42.52633254}],"checksum":2405496132,"timestamp":"2024-06-01T17:52:37.994696Z"}]}
{"channel":"book","type":"update","data":[{"symbol":"ETH/BTC","bids":[],"asks":[{"price":0.05614,"qty":6.80395410}],"checksum":2868089476,"timestamp":"2024-06-01T17:52:37.994711Z"}]}
{"channel":"book","type":"update","data":[{"symbol":"ETH/BTC","bids":[{"price":0.05612,"qty":4.35044860}],"asks":[],"checksum":190076029,"timestamp":"2024-06-01T17:52:37.994865Z"}]}
{"channel":"book","type":"update","data":[{"symbol":"ETH/BTC","bids":[{"price":0.05610,"qty":15.27193639}],"asks":[],"checksum":2066921340,"timestamp":"2024-06-01T17:52:37.997368Z"}]}
{"channel":"book","type":"update","data":[{"symbol":"ETH/BTC","bids":[],"asks":[{"price":0.05614,"qty":6.25395410}],"checksum":2494909261,"timestamp":"2024-06-01T17:52:37.998047Z"}]}
{"channel":"book","type":"update","data":[{"symbol":"ETH/BTC","bids":[{"price":0.05610,"qty":2.09660000}],"asks":[],"checksum":4027240148,"timestamp":"2024-06-01T17:52:38.000731Z"}]}
{"channel":"book","type":"update","data":[{"symbol":"ETH/BTC","bids":[],"asks":[{"price":0.05614,"qty":3.62003351}],"checksum":3491306814,"timestamp":"2024-06-01T17:52:38.003235Z"}]}
{"channel":"book","type":"update","data":[{"symbol":"ETH/BTC","bids":[{"price":0.05605,"qty":15.17321069}],"asks":[],"checksum":1350819551,"timestamp":"2024-06-01T17:52:38.004633Z"}]}
{"channel":"book","type":"update","data":[{"symbol":"ETH/BTC","bids":[{"price":0.05612,"qty":6.98358695}],"asks":[],"checksum":2884898617,"timestamp":"2024-06-01T17:52:38.007137Z"}]}
{"channel":"book","type":"update","data":[{"symbol":"ETH/BTC","bids":[{"price":0.05610,"qty":8.09660000}],"asks":[],"checksum":3615459723,"timestamp":"2024-06-01T17:52:38.011672Z"}]}
{"channel":"book","type":"update","data":[{"symbol":"ETH/BTC","bids":[{"price":0.05611,"qty":8.35372818}],"asks":[],"checksum":884493448,"timestamp":"2024-06-01T17:52:38.011749Z"}]}
{"channel":"book","type":"update","data":[{"symbol":"ETH/BTC","bids":[{"price":0.05611,"qty":5.71888321}],"asks":[],"checksum":1269362487,"timestamp":"2024-06-01T17:52:38.012486Z"}]}
{"channel":"book","type":"update","data":[{"symbol":"ETH/BTC","bids":[{"price":0.05612,"qty":4.35044860}],"asks":[],"checksum":2967420625,"timestamp":"2024-06-01T17:52:38.018035Z"}]}
{"channel":"book","type":"update","data":[{"symbol":"ETH/BTC","bids":[],"asks":[{"price":0.05615,"qty":18.11204336}],"checksum":217939311,"timestamp":"2024-06-01T17:52:38.020863Z"}]}
{"channel":"book","type":"update","data":[{"symbol":"ETH/BTC","bids":[{"price":0.05612,"qty":6.98494742}],"asks":[],"checksum":885022600,"timestamp":"2024-06-01T17:52:38.020887Z"}]}
{"channel":"book","type":"update","data":[{"symbol":"ETH/BTC","bids":[{"price":0.05610,"qty":7.54660000}],"asks":[],"checksum":3933392017,"timestamp":"2024-06-01T17:52:38.026288Z"}]}
{"channel":"book","type":"update","data":[{"symbol":"ETH/BTC","bids":[{"price":0.05612,"qty":7.53494742}],"asks":[],"checksum":2920724945,"timestamp":"2024-06-01T17:52:38.026581Z"}]}
{"channel":"book","type":"update","data":[{"symbol":"ETH/BTC","bids":[{"price":0.05607,"qty":2.31261319}],"asks":[],"checksum":1858807421,"timestamp":"2024-06-01T17:52:38.038004Z"}]}
{"channel":"book","type":"update","data":[{"symbol":"ETH/BTC","bids":[{"price":0.05608,"qty":2.85546619}],"asks":[],"checksum":2410379677,"timestamp":"2024-06-01T17:52:38.038154Z"}]}
{"channel":"book","type":"update","data":[{"symbol":"ETH/BTC","bids":[{"price":0.05611,"qty":6.59088321}],"asks":[],"checksum":2540473201,"timestamp":"2024-06-01T17:52:38.042982Z"}]}
{"channel":"book","type":"update","data":[{"symbol":"ETH/BTC","bids":[{"price":0.05608,"qty":3.20776900}],"asks":[],"checksum":3421543683,"timestamp":"2024-06-01T17:52:38.048849Z"}]}
{"channel":"book","type":"update","data":[{"symbol":"ETH/BTC","bids":[],"asks":[{"price":0.05613,"qty":0.00000000},{"price":0.05623,"qty":4.91006000},{"price":0.05614,"qty":3.62664956}],"checksum":3345167632,"timestamp":"2024-06-01T17:52:38.058251Z"}]}
{"channel":"book","type":"update","data":[{"symbol":"ETH/BTC","bids":[{"price":0.05609,"qty":18.30482091}],"asks":[],"checksum":3566890051,"timestamp":"2024-06-01T17:52:38.061058Z"}]}
{"channel":"book","type":"update","data":[{"symbol":"ETH/BTC","bids":[{"price":0.05610,"qty":8.25148890}],"asks":[],"checksum":2815035300,"timestamp":"2024-06-01T17:52:38.061936Z"}]}
{"channel":"book","type":"update","data":[{"symbol":"ETH/BTC","bids":[],"asks":[{"price":0.05614,"qty":6.26072071}],"checksum":1884784070,"timestamp":"2024-06-01T17:52:38.062666Z"}]}
{"channel":"book","type":"update","data":[{"symbol":"ETH/BTC","bids":[{"price":0.05613,"qty":0.81560000}],"asks":[],"checksum":2306850263,"timestamp":"2024-06-01T17:52:38.063738Z"}]}
{"channel":"book","type":"update","data":[{"symbol":"ETH/BTC","bids":[{"price":0.05613,"qty":1.63120000}],"asks":[],"checksum":1703450608,"timestamp":"2024-06-01T17:52:38.063761Z"}]}
{"channel":"book","type":"update","data":[{"symbol":"ETH/BTC","bids":[{"price":0.05607,"qty":2.37954677}],"asks":[],"checksum":3225115999,"timestamp":"2024-06-01T17:52:38.070922Z"}]}
{"channel":"book","type":"update","data":[{"symbol":"ETH/BTC","bids":[],"asks":[{"price":0.05616,"qty":0.84490087}],"checksum":3600292758,"timestamp":"2024-06-01T17:52:38.070993Z"}]}
{"channel":"book","type":"update","data":[{"symbol":"ETH/BTC","bids":[],"asks":[{"price":0.05618,"qty":1.05332071}],"checksum":2996036141,"timestamp":"2024-06-01T17:52:38.072651Z"}]}
{"channel":"book","type":"update","data":[{"symbol":"ETH/BTC","bids":[{"price":0.05608,"qty":3.83171117}],"asks":[],"checksum":2600543528,"timestamp":"2024-06-01T17:52:38.072984Z"}]}
{"channel":"book","type":"update","data":[{"symbol":"ETH/BTC","bids":[],"asks":[{"price":0.05617,"qty":21.18676387}],"checksum":369633649,"timestamp":"2024-06-01T17:52:38.092944Z"}]}
{"channel":"book","type":"update","data":[{"symbol":"ETH/BTC","bids":[{"price":0.05612,"qty":7.45019764},{"price":0.05613,"qty":1.71593374}],"asks":[],"checksum":4157919648,"timestamp":"2024-06-01T17:52:38.117342Z"}]}
{"channel":"book","type":"update","data":[{"symbol":"ETH/BTC","bids":[{"price":0.05609,"qty":18.57893064}],"asks":[],"checksum":486561243,"timestamp":"2024-06-01T17:52:38.117604Z"}]}
{"channel":"book","type":"update","data":[{"symbol":"ETH/BTC","bids":[],"asks":[{"price":0.05614,"qty":3.62703760}],"checksum":1080005716,"timestamp":"2024-06-01T17:52:38.136931Z"}]}
{"channel":"book","type":"update","data":[{"symbol":"ETH/BTC","bids":[{"price":0.05608,"qty":3.47940836}],"asks":[],"checksum":1819989449,"timestamp":"2024-06-01T17:52:38.147623Z"}]}
{"channel":"book","type":"update","data":[{"symbol":"ETH/BTC","bids":[{"price":0.05610,"qty":8.60379171}],"asks":[],"checksum":2322996724,"timestamp":"2024-06-01T17:52:38.153585Z"}]}
{"channel":"book","type":"update","data":[{"symbol":"ETH/BTC","bids":[{"price":0.05604,"qty":24.90905173}],"asks":[],"checksum":1708127403,"timestamp":"2024-06-01T17:52:38.163581Z"}]}
{"channel":"book","type":"update","data":[{"symbol":"ETH/BTC","bids":[{"price":0.05610,"qty":7.89890281}],"asks":[],"checksum":705554201,"timestamp":"2024-06-01T17:52:38.309650Z"}]}
{"channel":"book","type":"update","data":[{"symbol":"ETH/BTC","bids":[{"price":0.05611,"qty":7.29577211}],"asks":[],"checksum":3626547584,"timestamp":"2024-06-01T17:52:38.309785Z"}]}
{"channel":"book","type":"update","data":[{"symbol":"ETH/BTC","bids":[],"asks":[{"price":0.05614,"qty":3.62042155},{"price":0.05614,"qty":3.62694725}],"checksum":2995758381,"timestamp":"2024-06-01T17:52:38.490533Z"}]}
{"channel":"book","type":"update","data":[{"symbol":"ETH/BTC","bids":[{"price":0.05608,"qty":2.49305796}],"asks":[],"checksum":1186423192,"timestamp":"2024-06-01T17:52:38.593289Z"}]}
{"channel":"book","type":"update","data":[{"symbol":"ETH/BTC","bids":[],"asks":[{"price":0.05615,"qty":16.61503017}],"checksum":3214773699,"timestamp":"2024-06-01T17:52:38.593304Z"}]}
{"channel":"book","type":"update","data":[{"symbol":"ETH/BTC","bids":[{"price":0.05609,"qty":19.56528104}],"asks":[],"checksum":2264613187,"timestamp":"2024-06-01T17:52:38.595917Z"}]}
{"channel":"book","type":"update","data":[{"symbol":"ETH/BTC","bids":[],"asks":[{"price":0.05616,"qty":2.34191406}],"checksum":769709313,"timestamp":"2024-06-01T17:52:38.595943Z"}]}
{"channel":"book","type":"update","data":[{"symbol":"ETH/BTC","bids":[{"price":0.05612,"qty":4.81569882}],"asks":[],"checksum":1169633257,"timestamp":"2024-06-01T17:52:38.599228Z"}]}
{"channel":"book","type":"update","data":[{"symbol":"ETH/BTC","bids":[{"price":0.05605,"qty":1.98560000}],"asks":[],"checksum":2678203986,"timestamp":"2024-06-01T17:52:38.599286Z"}]}
{"channel":"book","type":"update","data":[{"symbol":"ETH/BTC","bids":[],"asks":[{"price":0.05615,"qty":3.44894045}],"checksum":3842444006,"timestamp":"2024-06-01T17:52:38.599438Z"}]}
{"channel":"book","type":"update","data":[{"symbol":"ETH/BTC","bids":[],"asks":[{"price":0.05616,"qty":15.50550020}],"checksum":4239616875,"timestamp":"2024-06-01T17:52:38.604637Z"}]}
{"channel":"book","type":"update","data":[{"symbol":"ETH/BTC","bids":[],"asks":[{"price":0.05615,"qty":6.08232886}],"checksum":1933531269,"timestamp":"2024-06-01T17:52:38.604660Z"}]}
{"channel":"book","type":"update","data":[{"symbol":"ETH/BTC","bids":[{"price":0.05611,"qty":20.46868006}],"asks":[],"checksum":1767845178,"timestamp":"2024-06-01T17:52:38.604672Z"}]}
{"channel":"book","type":"update","data":[{"symbol":"ETH/BTC","bids":[{"price":0.05613,"qty":4.34996146}],"asks":[],"checksum":3789154713,"timestamp":"2024-06-01T17:52:38.604797Z"}]}
{"channel":"book","type":"update","data":[{"symbol":"ETH/BTC","bids":[],"asks":[{"price":0.05617,"qty":13.98281506}],"checksum":1825629632,"timestamp":"2024-06-01T17:52:38.667770Z"}]}
{"channel":"book","type":"update","data":[{"symbol":"ETH/BTC","bids":[],"asks":[{"price":0.05620,"qty":28.42846602}],"checksum":1404654419,"timestamp":"2024-06-01T17:52:38.667906Z"}]}
{"channel":"book","type":"update","data":[{"symbol":"ETH/BTC","bids":[{"price":0.05609,"qty":30.09979254}],"asks":[],"checksum":3737528585,"timestamp":"2024-06-01T17:52:38.707874Z"}]}
{"channel":"book","type":"update","data":[{"symbol":"ETH/BTC","bids":[],"asks":[{"price":0.05621,"qty":21.12247969}],"checksum":2127545498,"timestamp":"2024-06-01T17:52:38.707923Z"}]}
{"channel":"book","type":"update","data":[{"symbol":"ETH/BTC","bids":[],"asks":[{"price":0.05615,"qty":7.68232886}],"checksum":3238674961,"timestamp":"2024-06-01T17:52:39.014230Z"}]}
{"channel":"book","type":"update","data":[{"symbol":"ETH/BTC","bids":[{"price":0.05611,"qty":33.64143728}],"asks":[],"checksum":1491947532,"timestamp":"2024-06-01T17:52:39.130074Z"}]}
{"channel":"book","type":"update","data":[{"symbol":"ETH/BTC","bids":[],"asks":[{"price":0.05616,"qty":21.50550020}],"checksum":1051629663,"timestamp":"2024-06-01T17:52:39.300690Z"}]}
{"channel":"book","type":"update","data":[{"symbol":"ETH/BTC","bids":[],"asks":[{"price":0.05615,"qty":8.58561207}],"checksum":1962300552,"timestamp":"2024-06-01T17:52:39.306166Z"}]}
{"channel":"book","type":"update","data":[{"symbol":"ETH/BTC","bids":[],"asks":[{"price":0.05619,"qty":10.53673519}],"checksum":860517589,"timestamp":"2024-06-01T17:52:39.321661Z"}]}
{"channel":"book","type":"update","data":[{"symbol":"ETH/BTC","bids":[],"asks":[{"price":0.05618,"qty":8.26105590}],"checksum":3546748276,"timestamp":"2024-06-01T17:52:39.321685Z"}]}
{"channel":"book","type":"update","data":[{"symbol":"ETH/BTC","bids":[{"price":0.05611,"qty":20.46852933}],"asks":[],"checksum":1258332091,"timestamp":"2024-06-01T17:52:39.438777Z"}]}
{"channel":"book","type":"update","data":[{"symbol":"ETH/BTC","bids":[{"price":0.05612,"qty":17.98801785}],"asks":[],"checksum":333477153,"timestamp":"2024-06-01T17:52:39.878324Z"}]}
{"channel":"book","type":"update","data":[{"symbol":"ETH/BTC","bids":[{"price":0.05604,"qty":24.01200758},{"price":0.05606,"qty":45.19009315}],"asks":[],"checksum":4135717064,"timestamp":"2024-06-01T17:52:39.890965Z"}]}
{"channel":"book","type":"update","data":[{"symbol":"ETH/BTC","bids":[],"asks":[{"price":0.05618,"qty":1.05332071}],"checksum":1471395543,"timestamp":"2024-06-01T17:52:39.893114Z"}]}
{"channel":"book","type":"update","data":[{"symbol":"ETH/BTC","bids":[],"asks":[{"price":0.05620,"qty":28.49539960}],"checksum":3735505624,"timestamp":"2024-06-01T17:52:39.983157Z"}]}
{"channel":"book","type":"update","data":[{"symbol":"ETH/BTC","bids":[{"price":0.05613,"qty":8.34996146}],"asks":[],"checksum":797166175,"timestamp":"2024-06-01T17:52:40.309787Z"}]}
{"channel":"book","type":"update","data":[{"symbol":"ETH/BTC","bids":[{"price":0.05605,"qty":2.54157968}],"asks":[],"checksum":2058620293,"timestamp":"2024-06-01T17:52:40.345938Z"}]}
{"channel":"book","type":"update","data":[{"symbol":"ETH/BTC","bids":[{"price":0.05604,"qty":24.10586660}],"asks":[],"checksum":1011061708,"timestamp":"2024-06-01T17:52:40.575597Z"}]}
{"channel":"book","type":"update","data":[{"symbol":"ETH/BTC","bids":[],"asks":[{"price":0.05620,"qty":28.42846602}],"checksum":3042406339,"timestamp":"2024-06-01T17:52:40.834291Z"}]}
{"channel":"book","type":"update","data":[{"symbol":"ETH/BTC","bids":[],"asks":[{"price":0.05617,"qty":14.04974864}],"checksum":1112397238,"timestamp":"2024-06-01T17:52:40.835005Z"}]}
{"channel":"book","type":"update","data":[{"symbol":"ETH/BTC","bids":[{"price":0.05611,"qty":19.76364043}],"asks":[],"checksum":3795183467,"timestamp":"2024-06-01T17:52:40.856780Z"}]}
{"channel":"book","type":"update","data":[{"symbol":"ETH/BTC","bids":[{"price":0.05613,"qty":7.53436146}],"asks":[],"checksum":3092332111,"timestamp":"2024-06-01T17:52:40.857386Z"}]}
{"channel":"book","type":"update","data":[{"symbol":"ETH/BTC","bids":[{"price":0.05613,"qty":6.71876146}],"asks":[],"checksum":3276483292,"timestamp":"2024-06-01T17:52:40.858252Z"}]}
{"channel":"book","type":"update","data":[{"symbol":"ETH/BTC","bids":[{"price":0.05610,"qty":8.14713996}],"asks":[],"checksum":1308364819,"timestamp":"2024-06-01T17:52:40.950143Z"}]}
{"channel":"book","type":"update","data":[{"symbol":"ETH/BTC","bids":[{"price":0.05613,"qty":7.53436146}],"asks":[],"checksum":921044096,"timestamp":"2024-06-01T17:52:41.048443Z"}]}
{"channel":"book","type":"update","data":[{"symbol":"ETH/BTC","bids":[{"price":0.05608,"qty":1.43954217}],"asks":[],"checksum":599693625,"timestamp":"2024-06-01T17:52:41.447618Z"}]}
{"channel":"book","type":"update","data":[{"symbol":"ETH/BTC","bids":[{"price":0.05610,"qty":9.20020772}],"asks":[],"checksum":2026548851,"timestamp":"2024-06-01T17:52:41.700160Z"}]}
