{"channel":"book","type":"snapshot","data":[{"symbol":"ETH/AUD","bids":[{"price":5708.66,"qty":1.03808156},{"price":5708.65,"qty":0.90387105},{"price":5708.64,"qty":0.07347674},{"price":5708.63,"qty":0.02406309},{"price":5708.28,"qty":0.06658500},{"price":5708.07,"qty":3.33204140},{"price":5705.26,"qty":0.52360000},{"price":5705.25,"qty":1.60677000},{"price":5703.24,"qty":0.03096920},{"price":5703.23,"qty":0.74674126}],"asks":[{"price":5711.31,"qty":0.01292326},{"price":5711.88,"qty":0.20900281},{"price":5711.89,"qty":0.90387105},{"price":5711.97,"qty":0.00417834},{"price":5713.50,"qty":0.06654900},{"price":5715.00,"qty":0.53664977},{"price":5715.01,"qty":11.10915821},{"price":5715.05,"qty":0.07535243},{"price":5715.52,"qty":9.59019515},{"price":5717.86,"qty":1.60677000}],"checksum":851632831}]}
{"channel":"book","type":"update","data":[{"symbol":"ETH/AUD","bids":[{"price":5708.64,"qty":0.00000000},{"price":5703.22,"qty":0.11200000},{"price":5708.67,"qty":0.07347674}],"asks":[],"checksum":1321735546,"timestamp":"2024-06-01T17:51:44.838499Z"}]}
{"channel":"book","type":"update","data":[{"symbol":"ETH/AUD","bids":[{"price":5708.66,"qty":0.00000000},{"price":5703.22,"qty":0.11200000},{"price":5708.68,"qty":1.03808159}],"asks":[],"checksum":2128505335,"timestamp":"2024-06-01T17:51:45.074725Z"}]}
{"channel":"book","type":"update","data":[{"symbol":"ETH/AUD","bids":[{"price":5708.69,"qty":0.90387105}],"asks":[],"checksum":2926908862,"timestamp":"2024-06-01T17:51:45.081401Z"}]}
{"channel":"book","type":"update","data":[{"symbol":"ETH/AUD","bids":[],"asks":[{"price":5715.51,"qty":0.83372964}],"checksum":2961710989,"timestamp":"2024-06-01T17:51:45.112836Z"}]}
{"channel":"book","type":"update","data":[{"symbol":"ETH/AUD","bids":[{"price":5703.25,"qty":4.12493832}],"asks":[],"checksum":3223959665,"timestamp":"2024-06-01T17:51:45.166723Z"}]}
{"channel":"book","type":"update","data":[{"symbol":"ETH/AUD","bids":[{"price":5708.65,"qty":0.00000000},{"price":5703.24,"qty":0.03096920}],"asks":[],"checksum":1427012493,"timestamp":"2024-06-01T17:51:45.176360Z"}]}
{"channel":"book","type":"update","data":[{"symbol":"ETH/AUD","bids":[{"price":5703.26,"qty":0.74673733}],"asks":[],"checksum":1665124011,"timestamp":"2024-06-01T17:51:45.178117Z"}]}
{"channel":"book","type":"update","data":[{"symbol":"ETH/AUD","bids":[],"asks":[{"price":5715.01,"qty":0.00000000},{"price":5717.86,"qty":1.60677000}],"checksum":3941567157,"timestamp":"2024-06-01T17:51:45.468722Z"}]}
{"channel":"book","type":"update","data":[{"symbol":"ETH/AUD","bids":[],"asks":[{"price":5715.00,"qty":0.01304977},{"price":5715.50,"qty":0.52360000}],"checksum":4197061296,"timestamp":"2024-06-01T17:51:45.474335Z"}]}
{"channel":"book","type":"update","data":[{"symbol":"ETH/AUD","bids":[],"asks":[{"price":5715.50,"qty":8.82606149}],"checksum":171901238,"timestamp":"2024-06-01T17:51:45.474909Z"}]}
{"channel":"book","type":"update","data":[{"symbol":"ETH/AUD","bids":[],"asks":[{"price":5714.99,"qty":3.12774149}],"checksum":3664972689,"timestamp":"2024-06-01T17:51:45.475060Z"}]}
{"channel":"book","type":"update","data":[{"symbol":"ETH/AUD","bids":[{"price":5708.67,"qty":0.00000000},{"price":5703.24,"qty":0.03096920},{"price":5708.70,"qty":0.07347674}],"asks":[],"checksum":2409997005,"timestamp":"2024-06-01T17:51:45.482416Z"}]}
{"channel":"book","type":"update","data":[{"symbol":"ETH/AUD","bids":[],"asks":[{"price":5714.98,"qty":0.01304982}],"checksum":4219549268,"timestamp":"2024-06-01T17:51:45.504051Z"}]}
{"channel":"book","type":"update","data":[{"symbol":"ETH/AUD","bids":[],"asks":[{"price":5715.00,"qty":0.00000000},{"price":5715.51,"qty":0.83372964}],"checksum":4165240738,"timestamp":"2024-06-01T17:51:45.504206Z"}]}
{"channel":"book","type":"update","data":[{"symbol":"ETH/AUD","bids":[],"asks":[{"price":5715.05,"qty":0.00000000},{"price":5715.52,"qty":9.59019515}],"checksum":896611989,"timestamp":"2024-06-01T17:51:45.569215Z"}]}
{"channel":"book","type":"update","data":[{"symbol":"ETH/AUD","bids":[],"asks":[{"price":5714.99,"qty":3.19842167}],"checksum":2782630942,"timestamp":"2024-06-01T17:51:45.571415Z"}]}
{"channel":"book","type":"update","data":[{"symbol":"ETH/AUD","bids":[{"price":5708.68,"qty":0.00000000},{"price":5703.24,"qty":0.03096920},{"price":5708.71,"qty":1.03807601}],"asks":[],"checksum":3931504761,"timestamp":"2024-06-01T17:51:45.666808Z"}]}
{"channel":"book","type":"update","data":[{"symbol":"ETH/AUD","bids":[{"price":5703.27,"qty":0.04638948}],"asks":[],"checksum":178935980,"timestamp":"2024-06-01T17:51:45.943505Z"}]}
{"channel":"book","type":"update","data":[{"symbol":"ETH/AUD","bids":[{"price":5708.70,"qty":0.00000000},{"price":5703.25,"qty":4.12493832},{"price":5708.72,"qty":0.07347674}],"asks":[],"checksum":4177879371,"timestamp":"2024-06-01T17:51:45.970000Z"}]}
{"channel":"book","type":"update","data":[{"symbol":"ETH/AUD","bids":[{"price":5708.73,"qty":0.90387105}],"asks":[],"checksum":1488445193,"timestamp":"2024-06-01T17:51:45.974691Z"}]}
{"channel":"book","type":"update","data":[{"symbol":"ETH/AUD","bids":[],"asks":[{"price":5715.50,"qty":8.30246149},{"price":5714.98,"qty":0.53664982}],"checksum":436434176,"timestamp":"2024-06-01T17:51:45.977544Z"}]}
{"channel":"book","type":"update","data":[{"symbol":"ETH/AUD","bids":[],"asks":[{"price":5711.97,"qty":0.00000000},{"price":5717.86,"qty":1.60677000}],"checksum":3013044269,"timestamp":"2024-06-01T17:51:46.085224Z"}]}
{"channel":"book","type":"update","data":[{"symbol":"ETH/AUD","bids":[{"price":5708.69,"qty":0.00000000},{"price":5703.26,"qty":0.74673733}],"asks":[],"checksum":2610412770,"timestamp":"2024-06-01T17:51:46.089587Z"}]}
{"channel":"book","type":"update","data":[{"symbol":"ETH/AUD","bids":[{"price":5708.28,"qty":0.00000000},{"price":5703.25,"qty":4.12493832},{"price":5708.74,"qty":0.06658200}],"asks":[],"checksum":3546198008,"timestamp":"2024-06-01T17:51:46.148442Z"}]}
{"channel":"book","type":"update","data":[{"symbol":"ETH/AUD","bids":[],"asks":[{"price":5714.71,"qty":0.00417304}],"checksum":3726690480,"timestamp":"2024-06-01T17:51:46.180666Z"}]}
{"channel":"book","type":"update","data":[{"symbol":"ETH/AUD","bids":[],"asks":[{"price":5714.70,"qty":0.01263345}],"checksum":1549239537,"timestamp":"2024-06-01T17:51:46.190850Z"}]}
{"channel":"book","type":"update","data":[{"symbol":"ETH/AUD","bids":[],"asks":[{"price":5714.98,"qty":0.52360000}],"checksum":2896281781,"timestamp":"2024-06-01T17:51:46.190922Z"}]}
{"channel":"book","type":"update","data":[{"symbol":"ETH/AUD","bids":[{"price":5708.71,"qty":0.00000000},{"price":5703.25,"qty":4.12493832},{"price":5708.75,"qty":1.03807131}],"asks":[],"checksum":4107450211,"timestamp":"2024-06-01T17:51:46.205595Z"}]}
{"channel":"book","type":"update","data":[{"symbol":"ETH/AUD","bids":[{"price":5708.72,"qty":0.00000000},{"price":5703.25,"qty":4.12493832},{"price":5708.76,"qty":0.07347674}],"asks":[],"checksum":4039914241,"timestamp":"2024-06-01T17:51:46.522055Z"}]}
{"channel":"book","type":"update","data":[{"symbol":"ETH/AUD","bids":[],"asks":[{"price":5715.51,"qty":0.00000000},{"price":5715.52,"qty":9.59019515}],"checksum":375528378,"timestamp":"2024-06-01T17:51:46.624998Z"}]}
{"channel":"book","type":"update","data":[{"symbol":"ETH/AUD","bids":[],"asks":[{"price":5715.52,"qty":0.00000000},{"price":5717.86,"qty":1.60677000}],"checksum":2978999108,"timestamp":"2024-06-01T17:51:46.762715Z"}]}
{"channel":"book","type":"update","data":[{"symbol":"ETH/AUD","bids":[],"asks":[{"price":5715.55,"qty":11.18435577}],"checksum":3008747788,"timestamp":"2024-06-01T17:51:46.766616Z"}]}
{"channel":"book","type":"update","data":[{"symbol":"ETH/AUD","bids":[{"price":5708.75,"qty":0.00000000},{"price":5703.25,"qty":4.12493832},{"price":5708.77,"qty":1.03806770}],"asks":[],"checksum":1291557217,"timestamp":"2024-06-01T17:51:46.784404Z"}]}
{"channel":"book","type":"update","data":[{"symbol":"ETH/AUD","bids":[{"price":5708.76,"qty":0.00000000},{"price":5703.25,"qty":4.12493832},{"price":5708.78,"qty":0.07347674}],"asks":[],"checksum":1680851558,"timestamp":"2024-06-01T17:51:47.100146Z"}]}
{"channel":"book","type":"update","data":[{"symbol":"ETH/AUD","bids":[{"price":5708.07,"qty":0.00000000},{"price":5703.25,"qty":4.12493832}],"asks":[],"checksum":3930513212,"timestamp":"2024-06-01T17:51:47.103136Z"}]}
{"channel":"book","type":"update","data":[{"symbol":"ETH/AUD","bids":[{"price":5708.79,"qty":0.90387105}],"asks":[],"checksum":932470950,"timestamp":"2024-06-01T17:51:47.105598Z"}]}
{"channel":"book","type":"update","data":[{"symbol":"ETH/AUD","bids":[{"price":5708.78,"qty":3.40510594}],"asks":[],"checksum":2428369747,"timestamp":"2024-06-01T17:51:47.106353Z"}]}
{"channel":"book","type":"update","data":[{"symbol":"ETH/AUD","bids":[{"price":5708.73,"qty":0.00000000},{"price":5703.25,"qty":4.12493832}],"asks":[],"checksum":1419773203,"timestamp":"2024-06-01T17:51:47.176970Z"}]}
{"channel":"book","type":"update","data":[{"symbol":"ETH/AUD","bids":[],"asks":[{"price":5715.55,"qty":0.00000000},{"price":5717.86,"qty":1.60677000}],"checksum":2765591364,"timestamp":"2024-06-01T17:51:47.185191Z"}]}
{"channel":"book","type":"update","data":[{"symbol":"ETH/AUD","bids":[],"asks":[{"price":5715.72,"qty":6.12554515}],"checksum":657921440,"timestamp":"2024-06-01T17:51:47.188948Z"}]}
{"channel":"book","type":"update","data":[{"symbol":"ETH/AUD","bids":[{"price":5705.26,"qty":0.00000000},{"price":5703.22,"qty":0.11200000}],"asks":[],"checksum":2386642733,"timestamp":"2024-06-01T17:51:47.210235Z"}]}
{"channel":"book","type":"update","data":[{"symbol":"ETH/AUD","bids":[],"asks":[{"price":5715.49,"qty":0.83372964}],"checksum":804030529,"timestamp":"2024-06-01T17:51:47.214766Z"}]}
{"channel":"book","type":"update","data":[{"symbol":"ETH/AUD","bids":[{"price":5703.82,"qty":0.52360000}],"asks":[],"checksum":195044336,"timestamp":"2024-06-01T17:51:47.221688Z"}]}
{"channel":"book","type":"update","data":[{"symbol":"ETH/AUD","bids":[],"asks":[{"price":5714.98,"qty":0.00000000},{"price":5715.72,"qty":6.12554515}],"checksum":1698639077,"timestamp":"2024-06-01T17:51:47.224707Z"}]}
{"channel":"book","type":"update","data":[{"symbol":"ETH/AUD","bids":[],"asks":[{"price":5715.52,"qty":0.52360000}],"checksum":3098106163,"timestamp":"2024-06-01T17:51:47.237035Z"}]}
{"channel":"book","type":"update","data":[{"symbol":"ETH/AUD","bids":[],"asks":[{"price":5713.50,"qty":0.00000000},{"price":5715.72,"qty":6.12554515},{"price":5714.14,"qty":0.06654500}],"checksum":1753113970,"timestamp":"2024-06-01T17:51:47.239314Z"}]}
{"channel":"book","type":"update","data":[{"symbol":"ETH/AUD","bids":[{"price":5708.77,"qty":0.00000000},{"price":5703.22,"qty":0.11200000},{"price":5708.80,"qty":1.03806226}],"asks":[],"checksum":1698834114,"timestamp":"2024-06-01T17:51:47.323964Z"}]}
{"channel":"book","type":"update","data":[{"symbol":"ETH/AUD","bids":[{"price":5708.81,"qty":0.90387105}],"asks":[],"checksum":2181584524,"timestamp":"2024-06-01T17:51:47.329147Z"}]}
{"channel":"book","type":"update","data":[{"symbol":"ETH/AUD","bids":[{"price":5708.78,"qty":3.33162920},{"price":5708.82,"qty":0.07347674}],"asks":[],"checksum":4141600420,"timestamp":"2024-06-01T17:51:47.653492Z"}]}
{"channel":"book","type":"update","data":[{"symbol":"ETH/AUD","bids":[{"price":5708.79,"qty":0.00000000},{"price":5703.26,"qty":0.74673733}],"asks":[],"checksum":3774607180,"timestamp":"2024-06-01T17:51:47.659272Z"}]}
{"channel":"book","type":"update","data":[{"symbol":"ETH/AUD","bids":[],"asks":[{"price":5715.52,"qty":0.00000000},{"price":5715.72,"qty":6.12554515},{"price":5715.48,"qty":0.52360000}],"checksum":3930524462,"timestamp":"2024-06-01T17:51:47.860677Z"}]}
{"channel":"book","type":"update","data":[{"symbol":"ETH/AUD","bids":[{"price":5703.82,"qty":0.00000000},{"price":5703.25,"qty":4.12493832},{"price":5705.26,"qty":0.52360000}],"asks":[],"checksum":1192375920,"timestamp":"2024-06-01T17:51:47.860716Z"}]}
{"channel":"book","type":"update","data":[{"symbol":"ETH/AUD","bids":[{"price":5708.80,"qty":0.00000000},{"price":5703.25,"qty":4.12493832},{"price":5708.83,"qty":1.03805681}],"asks":[],"checksum":2538027174,"timestamp":"2024-06-01T17:51:47.899060Z"}]}
{"channel":"book","type":"update","data":[{"symbol":"ETH/AUD","bids":[{"price":5708.84,"qty":0.90387105}],"asks":[],"checksum":2003290271,"timestamp":"2024-06-01T17:51:47.904779Z"}]}
{"channel":"book","type":"update","data":[{"symbol":"ETH/AUD","bids":[],"asks":[{"price":5714.99,"qty":3.12774149}],"checksum":4042806215,"timestamp":"2024-06-01T17:51:47.933836Z"}]}
{"channel":"book","type":"update","data":[{"symbol":"ETH/AUD","bids":[],"asks":[{"price":5714.98,"qty":0.04427137}],"checksum":4021857962,"timestamp":"2024-06-01T17:51:47.936274Z"}]}
{"channel":"book","type":"update","data":[{"symbol":"ETH/AUD","bids":[],"asks":[{"price":5715.48,"qty":0.54594553}],"checksum":941026112,"timestamp":"2024-06-01T17:51:47.936468Z"}]}
{"channel":"book","type":"update","data":[{"symbol":"ETH/AUD","bids":[{"price":5708.81,"qty":0.00000000},{"price":5703.26,"qty":0.74673733}],"asks":[],"checksum":2795230871,"timestamp":"2024-06-01T17:51:48.176516Z"}]}
{"channel":"book","type":"update","data":[{"symbol":"ETH/AUD","bids":[{"price":5708.82,"qty":0.00000000},{"price":5703.25,"qty":4.12493832},{"price":5708.85,"qty":0.07347674}],"asks":[],"checksum":3709907754,"timestamp":"2024-06-01T17:51:48.204231Z"}]}
{"channel":"book","type":"update","data":[{"symbol":"ETH/AUD","bids":[{"price":5703.28,"qty":5.15250955}],"asks":[],"checksum":3530191792,"timestamp":"2024-06-01T17:51:48.230329Z"}]}
{"channel":"book","type":"update","data":[{"symbol":"ETH/AUD","bids":[{"price":5708.85,"qty":0.60030348}],"asks":[],"checksum":3884019201,"timestamp":"2024-06-01T17:51:48.230388Z"}]}
{"channel":"book","type":"update","data":[{"symbol":"ETH/AUD","bids":[{"price":5703.29,"qty":0.74673340}],"asks":[],"checksum":35780386,"timestamp":"2024-06-01T17:51:48.244528Z"}]}
{"channel":"book","type":"update","data":[{"symbol":"ETH/AUD","bids":[{"price":5708.83,"qty":0.00000000},{"price":5703.27,"qty":0.04638948},{"price":5708.86,"qty":1.03795515}],"asks":[],"checksum":2153998411,"timestamp":"2024-06-01T17:51:48.428631Z"}]}
{"channel":"book","type":"update","data":[{"symbol":"ETH/AUD","bids":[],"asks":[{"price":5715.48,"qty":0.02234553}],"checksum":2969791299,"timestamp":"2024-06-01T17:51:48.761780Z"}]}
{"channel":"book","type":"update","data":[{"symbol":"ETH/AUD","bids":[{"price":5708.85,"qty":0.52682674},{"price":5708.87,"qty":0.07347674}],"asks":[],"checksum":2928480371,"timestamp":"2024-06-01T17:51:48.789033Z"}]}
{"channel":"book","type":"update","data":[{"symbol":"ETH/AUD","bids":[],"asks":[{"price":5715.35,"qty":0.52360000}],"checksum":3114684276,"timestamp":"2024-06-01T17:51:48.805408Z"}]}
{"channel":"book","type":"update","data":[{"symbol":"ETH/AUD","bids":[{"price":5703.30,"qty":0.03083789}],"asks":[],"checksum":33898641,"timestamp":"2024-06-01T17:51:48.842305Z"}]}
{"channel":"book","type":"update","data":[{"symbol":"ETH/AUD","bids":[{"price":5708.87,"qty":0.07874501}],"asks":[],"checksum":210365808,"timestamp":"2024-06-01T17:51:48.842468Z"}]}
{"channel":"book","type":"update","data":[{"symbol":"ETH/AUD","bids":[{"price":5708.86,"qty":0.00000000},{"price":5703.29,"qty":0.74673340},{"price":5708.88,"qty":1.03794362}],"asks":[],"checksum":3491186290,"timestamp":"2024-06-01T17:51:48.986126Z"}]}
{"channel":"book","type":"update","data":[{"symbol":"ETH/AUD","bids":[{"price":5708.89,"qty":0.90387105}],"asks":[],"checksum":2810655820,"timestamp":"2024-06-01T17:51:48.991188Z"}]}
{"channel":"book","type":"update","data":[{"symbol":"ETH/AUD","bids":[{"price":5708.84,"qty":0.00000000},{"price":5703.30,"qty":0.03083789}],"asks":[],"checksum":3424874024,"timestamp":"2024-06-01T17:51:49.175733Z"}]}
{"channel":"book","type":"update","data":[{"symbol":"ETH/AUD","bids":[{"price":5708.88,"qty":0.00000000},{"price":5703.29,"qty":0.74673340},{"price":5708.90,"qty":1.03793881}],"asks":[],"checksum":1399029406,"timestamp":"2024-06-01T17:51:49.508343Z"}]}
{"channel":"book","type":"update","data":[{"symbol":"ETH/AUD","bids":[{"price":5708.91,"qty":0.90387105}],"asks":[],"checksum":2167271015,"timestamp":"2024-06-01T17:51:49.513641Z"}]}
{"channel":"book","type":"update","data":[{"symbol":"ETH/AUD","bids":[{"price":5708.87,"qty":0.00526827},{"price":5708.92,"qty":0.07347674}],"asks":[],"checksum":2205342495,"timestamp":"2024-06-01T17:51:49.522503Z"}]}
{"channel":"book","type":"update","data":[{"symbol":"ETH/AUD","bids":[],"asks":[{"price":5711.89,"qty":0.00000000},{"price":5715.49,"qty":0.83372964}],"checksum":1247029760,"timestamp":"2024-06-01T17:51:49.584291Z"}]}
{"channel":"book","type":"update","data":[{"symbol":"ETH/AUD","bids":[{"price":5708.89,"qty":0.00000000},{"price":5705.25,"qty":1.60677000}],"asks":[],"checksum":4005047243,"timestamp":"2024-06-01T17:51:49.597534Z"}]}
{"channel":"book","type":"update","data":[{"symbol":"ETH/AUD","bids":[],"asks":[{"price":5711.88,"qty":0.00000000},{"price":5715.50,"qty":8.30246149},{"price":5714.13,"qty":0.20895352}],"checksum":4168416890,"timestamp":"2024-06-01T17:51:49.632171Z"}]}
{"channel":"book","type":"update","data":[{"symbol":"ETH/AUD","bids":[],"asks":[{"price":5714.70,"qty":0.00000000},{"price":5715.50,"qty":8.30246149}],"checksum":4149212127,"timestamp":"2024-06-01T17:51:49.642048Z"}]}
{"channel":"book","type":"update","data":[{"symbol":"ETH/AUD","bids":[],"asks":[{"price":5711.31,"qty":0.00000000},{"price":5716.14,"qty":4.52264515},{"price":5714.12,"qty":0.01292326}],"checksum":4202390413,"timestamp":"2024-06-01T17:51:49.679252Z"}]}
{"channel":"book","type":"update","data":[{"symbol":"ETH/AUD","bids":[],"asks":[{"price":5715.49,"qty":0.00000000},{"price":5716.46,"qty":0.02091896}],"checksum":2809203273,"timestamp":"2024-06-01T17:51:49.740907Z"}]}
{"channel":"book","type":"update","data":[{"symbol":"ETH/AUD","bids":[],"asks":[{"price":5714.14,"qty":0.00000000},{"price":5716.47,"qty":7.25344515},{"price":5714.61,"qty":0.06654100}],"checksum":1707078373,"timestamp":"2024-06-01T17:51:49.750010Z"}]}
{"channel":"book","type":"update","data":[{"symbol":"ETH/AUD","bids":[],"asks":[{"price":5714.13,"qty":0.00000000},{"price":5716.47,"qty":7.25344515},{"price":5714.60,"qty":0.20895345}],"checksum":3260260269,"timestamp":"2024-06-01T17:51:49.802345Z"}]}
{"channel":"book","type":"update","data":[{"symbol":"ETH/AUD","bids":[],"asks":[{"price":5714.98,"qty":0.00000000},{"price":5716.47,"qty":7.25344515}],"checksum":623215,"timestamp":"2024-06-01T17:51:49.901812Z"}]}
{"channel":"book","type":"update","data":[{"symbol":"ETH/AUD","bids":[],"asks":[{"price":5714.11,"qty":0.90387105}],"checksum":2135936947,"timestamp":"2024-06-01T17:51:49.907243Z"}]}
{"channel":"book","type":"update","data":[{"symbol":"ETH/AUD","bids":[],"asks":[{"price":5715.35,"qty":0.00000000},{"price":5716.47,"qty":7.25344515},{"price":5715.49,"qty":0.52360000}],"checksum":2596630274,"timestamp":"2024-06-01T17:51:50.037789Z"}]}
{"channel":"book","type":"update","data":[{"symbol":"ETH/AUD","bids":[{"price":5708.90,"qty":0.00000000},{"price":5703.30,"qty":0.03083789},{"price":5708.93,"qty":1.03793202}],"asks":[],"checksum":2870487951,"timestamp":"2024-06-01T17:51:50.063725Z"}]}
{"channel":"book","type":"update","data":[{"symbol":"ETH/AUD","bids":[],"asks":[{"price":5714.60,"qty":0.00000000},{"price":5716.47,"qty":7.25344515},{"price":5714.10,"qty":0.20895345}],"checksum":792220233,"timestamp":"2024-06-01T17:51:50.063771Z"}]}
{"channel":"book","type":"update","data":[{"symbol":"ETH/AUD","bids":[],"asks":[{"price":5716.46,"qty":0.00000000},{"price":5716.47,"qty":7.25344515}],"checksum":3167354468,"timestamp":"2024-06-01T17:51:50.264214Z"}]}
{"channel":"book","type":"update","data":[{"symbol":"ETH/AUD","bids":[],"asks":[{"price":5715.47,"qty":0.01301250}],"checksum":2803219834,"timestamp":"2024-06-01T17:51:50.264441Z"}]}
{"channel":"book","type":"update","data":[{"symbol":"ETH/AUD","bids":[{"price":5708.92,"qty":0.00000000},{"price":5703.30,"qty":0.03083789},{"price":5708.94,"qty":0.07347674}],"asks":[],"checksum":2676275100,"timestamp":"2024-06-01T17:51:50.601224Z"}]}
{"channel":"book","type":"update","data":[{"symbol":"ETH/AUD","bids":[{"price":5708.93,"qty":0.00000000},{"price":5703.30,"qty":0.03083789},{"price":5708.95,"qty":1.03796464}],"asks":[],"checksum":2522987139,"timestamp":"2024-06-01T17:51:50.668572Z"}]}
{"channel":"book","type":"update","data":[{"symbol":"ETH/AUD","bids":[{"price":5708.94,"qty":0.00000000},{"price":5703.30,"qty":0.03083789},{"price":5708.96,"qty":0.07347674}],"asks":[],"checksum":1339558501,"timestamp":"2024-06-01T17:51:51.088616Z"}]}
{"channel":"book","type":"update","data":[{"symbol":"ETH/AUD","bids":[],"asks":[{"price":5714.09,"qty":0.90387105}],"checksum":2559047733,"timestamp":"2024-06-01T17:51:51.094304Z"}]}
{"channel":"book","type":"update","data":[{"symbol":"ETH/AUD","bids":[],"asks":[{"price":5714.11,"qty":0.00000000},{"price":5715.50,"qty":8.30246149}],"checksum":1660509909,"timestamp":"2024-06-01T17:51:51.175178Z"}]}
{"channel":"book","type":"update","data":[{"symbol":"ETH/AUD","bids":[{"price":5708.85,"qty":0.00000000},{"price":5703.30,"qty":0.03083789}],"asks":[],"checksum":3521627510,"timestamp":"2024-06-01T17:51:51.282687Z"}]}
{"channel":"book","type":"update","data":[{"symbol":"ETH/AUD","bids":[{"price":5708.96,"qty":1.62798341}],"asks":[],"checksum":2283825029,"timestamp":"2024-06-01T17:51:51.283467Z"}]}
{"channel":"book","type":"update","data":[{"symbol":"ETH/AUD","bids":[{"price":5703.31,"qty":6.26293994}],"asks":[],"checksum":4025074609,"timestamp":"2024-06-01T17:51:51.283503Z"}]}
{"channel":"book","type":"update","data":[{"symbol":"ETH/AUD","bids":[{"price":5703.32,"qty":0.74672948}],"asks":[],"checksum":1972445516,"timestamp":"2024-06-01T17:51:51.306472Z"}]}
{"channel":"book","type":"update","data":[{"symbol":"ETH/AUD","bids":[],"asks":[{"price":5714.10,"qty":0.00000000},{"price":5716.47,"qty":7.25344515},{"price":5714.08,"qty":0.20896871}],"checksum":2915366436,"timestamp":"2024-06-01T17:51:51.320791Z"}]}
{"channel":"book","type":"update","data":[{"symbol":"ETH/AUD","bids":[{"price":5708.95,"qty":0.00000000},{"price":5703.31,"qty":6.26293994},{"price":5708.97,"qty":1.03796228}],"asks":[],"checksum":3333364398,"timestamp":"2024-06-01T17:51:51.320825Z"}]}
{"channel":"book","type":"update","data":[{"symbol":"ETH/AUD","bids":[],"asks":[{"price":5715.49,"qty":0.00000000},{"price":5716.47,"qty":7.25344515}],"checksum":888057803,"timestamp":"2024-06-01T17:51:51.565493Z"}]}
{"channel":"book","type":"update","data":[{"symbol":"ETH/AUD","bids":[],"asks":[{"price":5715.85,"qty":0.52360000}],"checksum":1867942660,"timestamp":"2024-06-01T17:51:51.572360Z"}]}
{"channel":"book","type":"update","data":[{"symbol":"ETH/AUD","bids":[{"price":5708.87,"qty":0.00000000},{"price":5703.31,"qty":6.26293994}],"asks":[],"checksum":2846335319,"timestamp":"2024-06-01T17:51:51.852496Z"}]}
{"channel":"book","type":"update","data":[{"symbol":"ETH/AUD","bids":[{"price":5703.33,"qty":0.02051514}],"asks":[],"checksum":2750389011,"timestamp":"2024-06-01T17:51:51.853301Z"}]}
{"channel":"book","type":"update","data":[{"symbol":"ETH/AUD","bids":[{"price":5708.98,"qty":0.01554507}],"asks":[],"checksum":1522758902,"timestamp":"2024-06-01T17:51:51.853422Z"}]}
{"channel":"book","type":"update","data":[{"symbol":"ETH/AUD","bids":[{"price":5708.96,"qty":1.55450667},{"price":5708.99,"qty":0.07347674}],"asks":[],"checksum":2607424168,"timestamp":"2024-06-01T17:51:51.881506Z"}]}
{"channel":"book","type":"update","data":[{"symbol":"ETH/AUD","bids":[{"price":5708.97,"qty":0.00000000},{"price":5703.33,"qty":0.02051514},{"price":5709.00,"qty":1.03795728}],"asks":[],"checksum":1818535871,"timestamp":"2024-06-01T17:51:51.920997Z"}]}
{"channel":"book","type":"update","data":[{"symbol":"ETH/AUD","bids":[{"price":5709.01,"qty":0.90387105}],"asks":[],"checksum":1023930632,"timestamp":"2024-06-01T17:51:51.928919Z"}]}
{"channel":"book","type":"update","data":[{"symbol":"ETH/AUD","bids":[],"asks":[{"price":5714.07,"qty":0.90387105}],"checksum":1608124952,"timestamp":"2024-06-01T17:51:51.928970Z"}]}
{"channel":"book","type":"update","data":[{"symbol":"ETH/AUD","bids":[],"asks":[{"price":5714.09,"qty":0.00000000},{"price":5715.85,"qty":0.52360000}],"checksum":2950806048,"timestamp":"2024-06-01T17:51:52.175458Z"}]}
{"channel":"book","type":"update","data":[{"symbol":"ETH/AUD","bids":[{"price":5708.91,"qty":0.00000000},{"price":5705.25,"qty":1.60677000}],"asks":[],"checksum":3165562157,"timestamp":"2024-06-01T17:51:52.177363Z"}]}
{"channel":"book","type":"update","data":[{"symbol":"ETH/AUD","bids":[],"asks":[{"price":5715.85,"qty":0.00000000},{"price":5716.16,"qty":0.83372964}],"checksum":3403430770,"timestamp":"2024-06-01T17:51:52.402540Z"}]}
{"channel":"book","type":"update","data":[{"symbol":"ETH/AUD","bids":[{"price":5708.99,"qty":0.00000000},{"price":5703.33,"qty":0.02051514},{"price":5709.02,"qty":0.07347674}],"asks":[],"checksum":2159890717,"timestamp":"2024-06-01T17:51:52.430882Z"}]}
{"channel":"book","type":"update","data":[{"symbol":"ETH/AUD","bids":[],"asks":[{"price":5714.08,"qty":0.00000000},{"price":5716.47,"qty":7.25344515},{"price":5714.06,"qty":0.20896884}],"checksum":3104515372,"timestamp":"2024-06-01T17:51:52.525866Z"}]}
{"channel":"book","type":"update","data":[{"symbol":"ETH/AUD","bids":[{"price":5709.00,"qty":0.00000000},{"price":5703.33,"qty":0.02051514},{"price":5709.03,"qty":1.03794531}],"asks":[],"checksum":1762876101,"timestamp":"2024-06-01T17:51:52.525890Z"}]}
{"channel":"book","type":"update","data":[{"symbol":"ETH/AUD","bids":[],"asks":[{"price":5715.48,"qty":0.00000000},{"price":5716.47,"qty":7.25344515}],"checksum":2173616011,"timestamp":"2024-06-01T17:51:52.731761Z"}]}
{"channel":"book","type":"update","data":[{"symbol":"ETH/AUD","bids":[],"asks":[{"price":5714.98,"qty":0.03126950}],"checksum":4103647598,"timestamp":"2024-06-01T17:51:52.733992Z"}]}
{"channel":"book","type":"update","data":[{"symbol":"ETH/AUD","bids":[],"asks":[{"price":5715.49,"qty":0.03890154}],"checksum":3916619733,"timestamp":"2024-06-01T17:51:52.734004Z"}]}
{"channel":"book","type":"update","data":[{"symbol":"ETH/AUD","bids":[{"price":5709.02,"qty":0.00000000},{"price":5703.33,"qty":0.02051514},{"price":5709.04,"qty":0.07347674}],"asks":[],"checksum":2718601810,"timestamp":"2024-06-01T17:51:52.859421Z"}]}
{"channel":"book","type":"update","data":[{"symbol":"ETH/AUD","bids":[],"asks":[{"price":5715.50,"qty":0.00000000},{"price":5715.67,"qty":0.52360000}],"checksum":1082752748,"timestamp":"2024-06-01T17:51:53.038010Z"}]}
{"channel":"book","type":"update","data":[{"symbol":"ETH/AUD","bids":[],"asks":[{"price":5714.99,"qty":0.00000000},{"price":5716.47,"qty":7.25344515}],"checksum":1707183755,"timestamp":"2024-06-01T17:51:53.038081Z"}]}
{"channel":"book","type":"update","data":[{"symbol":"ETH/AUD","bids":[],"asks":[{"price":5716.15,"qty":7.80917624}],"checksum":201187362,"timestamp":"2024-06-01T17:51:53.042648Z"}]}
{"channel":"book","type":"update","data":[{"symbol":"ETH/AUD","bids":[{"price":5709.05,"qty":0.90387105}],"asks":[],"checksum":3882688948,"timestamp":"2024-06-01T17:51:53.176695Z"}]}
{"channel":"book","type":"update","data":[{"symbol":"ETH/AUD","bids":[{"price":5709.01,"qty":0.00000000},{"price":5705.25,"qty":1.60677000}],"asks":[],"checksum":1698297917,"timestamp":"2024-06-01T17:51:53.182288Z"}]}
{"channel":"book","type":"update","data":[{"symbol":"ETH/AUD","bids":[{"price":5709.03,"qty":0.00000000},{"price":5703.33,"qty":0.02051514},{"price":5709.05,"qty":1.94181296}],"asks":[],"checksum":696930543,"timestamp":"2024-06-01T17:51:53.190742Z"}]}
{"channel":"book","type":"update","data":[{"symbol":"ETH/AUD","bids":[{"price":5709.04,"qty":0.00000000},{"price":5703.32,"qty":0.74672948},{"price":5709.06,"qty":0.07347674}],"asks":[],"checksum":2719486857,"timestamp":"2024-06-01T17:51:53.530032Z"}]}
{"channel":"book","type":"update","data":[{"symbol":"ETH/AUD","bids":[],"asks":[{"price":5715.67,"qty":0.00000000},{"price":5716.47,"qty":7.25344515},{"price":5716.14,"qty":0.52360000}],"checksum":223439415,"timestamp":"2024-06-01T17:51:53.755656Z"}]}
{"channel":"book","type":"update","data":[{"symbol":"ETH/AUD","bids":[{"price":5709.05,"qty":0.90387105},{"price":5709.07,"qty":1.03793840}],"asks":[],"checksum":461837749,"timestamp":"2024-06-01T17:51:53.805755Z"}]}
{"channel":"book","type":"update","data":[{"symbol":"ETH/AUD","bids":[{"price":5709.06,"qty":0.00000000},{"price":5703.33,"qty":0.02051514},{"price":5709.08,"qty":0.07347674}],"asks":[],"checksum":2219138671,"timestamp":"2024-06-01T17:51:54.050939Z"}]}
{"channel":"book","type":"update","data":[{"symbol":"ETH/AUD","bids":[{"price":5709.09,"qty":0.90387105}],"asks":[],"checksum":3811081575,"timestamp":"2024-06-01T17:51:54.056232Z"}]}
{"channel":"book","type":"update","data":[{"symbol":"ETH/AUD","bids":[{"price":5709.05,"qty":0.00000000},{"price":5705.25,"qty":1.60677000}],"asks":[],"checksum":3870183466,"timestamp":"2024-06-01T17:51:54.178628Z"}]}
{"channel":"book","type":"update","data":[{"symbol":"ETH/AUD","bids":[{"price":5708.96,"qty":0.00000000},{"price":5703.33,"qty":0.02051514}],"asks":[],"checksum":475454332,"timestamp":"2024-06-01T17:51:54.226956Z"}]}
{"channel":"book","type":"update","data":[{"symbol":"ETH/AUD","bids":[{"price":5709.08,"qty":1.11410665}],"asks":[],"checksum":1042565876,"timestamp":"2024-06-01T17:51:54.228342Z"}]}
{"channel":"book","type":"update","data":[{"symbol":"ETH/AUD","bids":[{"price":5703.33,"qty":5.13446060}],"asks":[],"checksum":883781950,"timestamp":"2024-06-01T17:51:54.228402Z"}]}
{"channel":"book","type":"update","data":[{"symbol":"ETH/AUD","bids":[{"price":5705.27,"qty":1.55451487}],"asks":[],"checksum":3612031525,"timestamp":"2024-06-01T17:51:54.228496Z"}]}
{"channel":"book","type":"update","data":[{"symbol":"ETH/AUD","bids":[{"price":5705.26,"qty":0.00000000},{"price":5703.33,"qty":5.13446060},{"price":5705.28,"qty":0.52360000}],"asks":[],"checksum":4266573434,"timestamp":"2024-06-01T17:51:54.232237Z"}]}
{"channel":"book","type":"update","data":[{"symbol":"ETH/AUD","bids":[{"price":5709.07,"qty":0.00000000},{"price":5703.34,"qty":0.74672684},{"price":5709.10,"qty":1.03793298}],"asks":[],"checksum":3637304266,"timestamp":"2024-06-01T17:51:54.451732Z"}]}
{"channel":"book","type":"update","data":[{"symbol":"ETH/AUD","bids":[{"price":5708.98,"qty":0.00000000},{"price":5703.34,"qty":0.74672684}],"asks":[],"checksum":3808001607,"timestamp":"2024-06-01T17:51:54.781051Z"}]}
{"channel":"book","type":"update","data":[{"symbol":"ETH/AUD","bids":[{"price":5709.08,"qty":1.04062991},{"price":5709.11,"qty":0.07347674}],"asks":[],"checksum":2738929614,"timestamp":"2024-06-01T17:51:54.782278Z"}]}
{"channel":"book","type":"update","data":[{"symbol":"ETH/AUD","bids":[{"price":5709.11,"qty":0.08902185}],"asks":[],"checksum":869690823,"timestamp":"2024-06-01T17:51:54.782396Z"}]}
{"channel":"book","type":"update","data":[{"symbol":"ETH/AUD","bids":[{"price":5705.29,"qty":0.02890595}],"asks":[],"checksum":2997362617,"timestamp":"2024-06-01T17:51:54.782417Z"}]}
{"channel":"book","type":"update","data":[{"symbol":"ETH/AUD","bids":[{"price":5709.10,"qty":0.00000000},{"price":5705.25,"qty":1.60677000},{"price":5709.12,"qty":1.03793032}],"asks":[],"checksum":1644832985,"timestamp":"2024-06-01T17:51:55.067044Z"}]}
{"channel":"book","type":"update","data":[{"symbol":"ETH/AUD","bids":[],"asks":[{"price":5714.05,"qty":0.90387105}],"checksum":2041679489,"timestamp":"2024-06-01T17:51:55.072957Z"}]}
{"channel":"book","type":"update","data":[{"symbol":"ETH/AUD","bids":[{"price":5709.13,"qty":0.90387105}],"asks":[],"checksum":3511274327,"timestamp":"2024-06-01T17:51:55.073160Z"}]}
{"channel":"book","type":"update","data":[{"symbol":"ETH/AUD","bids":[],"asks":[{"price":5714.98,"qty":0.00000000},{"price":5716.15,"qty":7.80917624}],"checksum":4043744949,"timestamp":"2024-06-01T17:51:55.078646Z"}]}
{"channel":"book","type":"update","data":[{"symbol":"ETH/AUD","bids":[],"asks":[{"price":5715.49,"qty":0.00000000},{"price":5716.47,"qty":7.25344515}],"checksum":1641578297,"timestamp":"2024-06-01T17:51:55.078692Z"}]}
{"channel":"book","type":"update","data":[{"symbol":"ETH/AUD","bids":[],"asks":[{"price":5716.13,"qty":0.07636686}],"checksum":3075475292,"timestamp":"2024-06-01T17:51:55.080560Z"}]}
{"channel":"book","type":"update","data":[{"symbol":"ETH/AUD","bids":[],"asks":[{"price":5716.12,"qty":0.02091743}],"checksum":1891057293,"timestamp":"2024-06-01T17:51:55.102272Z"}]}
{"channel":"book","type":"update","data":[{"symbol":"ETH/AUD","bids":[],"asks":[{"price":5715.47,"qty":0.00000000},{"price":5716.15,"qty":7.80917624}],"checksum":1648962849,"timestamp":"2024-06-01T17:51:55.102310Z"}]}
{"channel":"book","type":"update","data":[{"symbol":"ETH/AUD","bids":[],"asks":[{"price":5714.07,"qty":0.00000000},{"price":5716.47,"qty":7.25344515}],"checksum":3131434463,"timestamp":"2024-06-01T17:51:55.176527Z"}]}
{"channel":"book","type":"update","data":[{"symbol":"ETH/AUD","bids":[{"price":5709.09,"qty":0.00000000},{"price":5705.27,"qty":1.55451487}],"asks":[],"checksum":1314163927,"timestamp":"2024-06-01T17:51:55.176658Z"}]}
{"channel":"book","type":"update","data":[{"symbol":"ETH/AUD","bids":[{"price":5709.11,"qty":0.01554511},{"price":5709.14,"qty":0.07347674}],"asks":[],"checksum":4118348006,"timestamp":"2024-06-01T17:51:55.212110Z"}]}
{"channel":"book","type":"update","data":[{"symbol":"ETH/AUD","bids":[],"asks":[{"price":5716.15,"qty":0.00000000},{"price":5716.57,"qty":0.83372964}],"checksum":997514389,"timestamp":"2024-06-01T17:51:55.471673Z"}]}
{"channel":"book","type":"update","data":[{"symbol":"ETH/AUD","bids":[],"asks":[{"price":5716.46,"qty":8.30652636}],"checksum":4061018263,"timestamp":"2024-06-01T17:51:55.476288Z"}]}
{"channel":"book","type":"update","data":[{"symbol":"ETH/AUD","bids":[],"asks":[{"price":5716.12,"qty":2.62835505}],"checksum":866616457,"timestamp":"2024-06-01T17:51:55.476424Z"}]}
{"channel":"book","type":"update","data":[{"symbol":"ETH/AUD","bids":[],"asks":[{"price":5716.14,"qty":0.00000000},{"price":5716.57,"qty":0.83372964},{"price":5716.45,"qty":0.52360000}],"checksum":1164074564,"timestamp":"2024-06-01T17:51:55.480536Z"}]}
{"channel":"book","type":"update","data":[{"symbol":"ETH/AUD","bids":[{"price":5705.28,"qty":0.00000000},{"price":5705.27,"qty":1.55451487}],"asks":[],"checksum":754839613,"timestamp":"2024-06-01T17:51:55.508320Z"}]}
{"channel":"book","type":"update","data":[{"symbol":"ETH/AUD","bids":[{"price":5709.15,"qty":0.02406309}],"asks":[],"checksum":1508052573,"timestamp":"2024-06-01T17:51:55.633940Z"}]}
{"channel":"book","type":"update","data":[{"symbol":"ETH/AUD","bids":[{"price":5709.12,"qty":0.00000000},{"price":5705.27,"qty":1.55451487},{"price":5709.15,"qty":1.06198743}],"asks":[],"checksum":1612234344,"timestamp":"2024-06-01T17:51:55.635500Z"}]}
{"channel":"book","type":"update","data":[{"symbol":"ETH/AUD","bids":[],"asks":[{"price":5714.06,"qty":0.00000000},{"price":5716.57,"qty":0.83372964},{"price":5714.04,"qty":0.20887640}],"checksum":721106021,"timestamp":"2024-06-01T17:51:55.635537Z"}]}
{"channel":"book","type":"update","data":[{"symbol":"ETH/AUD","bids":[{"price":5709.14,"qty":0.00000000},{"price":5705.25,"qty":1.60677000},{"price":5709.16,"qty":0.07347674}],"asks":[],"checksum":883269210,"timestamp":"2024-06-01T17:51:55.962883Z"}]}
{"channel":"book","type":"update","data":[{"symbol":"ETH/AUD","bids":[],"asks":[{"price":5714.03,"qty":0.90387105}],"checksum":3503462282,"timestamp":"2024-06-01T17:51:55.968866Z"}]}
{"channel":"book","type":"update","data":[{"symbol":"ETH/AUD","bids":[],"asks":[{"price":5716.45,"qty":0.00000000},{"price":5716.47,"qty":7.25344515},{"price":5716.11,"qty":0.52360000}],"checksum":1166012805,"timestamp":"2024-06-01T17:51:55.999648Z"}]}
{"channel":"book","type":"update","data":[{"symbol":"ETH/AUD","bids":[],"asks":[{"price":5716.10,"qty":0.02091751}],"checksum":1427492686,"timestamp":"2024-06-01T17:51:56.005067Z"}]}
{"channel":"book","type":"update","data":[{"symbol":"ETH/AUD","bids":[],"asks":[{"price":5716.12,"qty":2.60743762}],"checksum":2454845642,"timestamp":"2024-06-01T17:51:56.005207Z"}]}
{"channel":"book","type":"update","data":[{"symbol":"ETH/AUD","bids":[{"price":5708.63,"qty":0.00000000},{"price":5705.25,"qty":1.60677000}],"asks":[],"checksum":3718927961,"timestamp":"2024-06-01T17:51:56.107843Z"}]}
{"channel":"book","type":"update","data":[{"symbol":"ETH/AUD","bids":[{"price":5705.28,"qty":0.52360000}],"asks":[],"checksum":3844464066,"timestamp":"2024-06-01T17:51:56.111008Z"}]}
{"channel":"book","type":"update","data":[{"symbol":"ETH/AUD","bids":[],"asks":[{"price":5714.05,"qty":0.00000000},{"price":5716.46,"qty":8.30652636}],"checksum":2847266999,"timestamp":"2024-06-01T17:51:56.178052Z"}]}
{"channel":"book","type":"update","data":[{"symbol":"ETH/AUD","bids":[{"price":5709.15,"qty":0.02406309},{"price":5709.17,"qty":1.03792038}],"asks":[],"checksum":3025082063,"timestamp":"2024-06-01T17:51:56.265771Z"}]}
{"channel":"book","type":"update","data":[{"symbol":"ETH/AUD","bids":[],"asks":[{"price":5714.04,"qty":0.00000000},{"price":5716.47,"qty":7.25344515},{"price":5714.02,"qty":0.20887630}],"checksum":535843822,"timestamp":"2024-06-01T17:51:56.265988Z"}]}
{"channel":"book","type":"update","data":[{"symbol":"ETH/AUD","bids":[],"asks":[{"price":5714.61,"qty":0.00000000},{"price":5716.47,"qty":7.25344515},{"price":5714.15,"qty":0.06655000}],"checksum":4169630246,"timestamp":"2024-06-01T17:51:56.476750Z"}]}
{"channel":"book","type":"update","data":[{"symbol":"ETH/AUD","bids":[{"price":5709.16,"qty":0.00000000},{"price":5705.27,"qty":1.55451487},{"price":5709.18,"qty":0.07347674}],"asks":[],"checksum":3658148586,"timestamp":"2024-06-01T17:51:56.484605Z"}]}
{"channel":"book","type":"update","data":[{"symbol":"ETH/AUD","bids":[{"price":5709.17,"qty":0.00000000},{"price":5705.27,"qty":1.55451487},{"price":5709.19,"qty":1.03790703}],"asks":[],"checksum":558748385,"timestamp":"2024-06-01T17:51:56.882995Z"}]}
{"channel":"book","type":"update","data":[{"symbol":"ETH/AUD","bids":[{"price":5709.18,"qty":0.00000000},{"price":5705.27,"qty":1.55451487},{"price":5709.20,"qty":0.07347674}],"asks":[],"checksum":2007732894,"timestamp":"2024-06-01T17:51:56.943250Z"}]}
{"channel":"book","type":"update","data":[{"symbol":"ETH/AUD","bids":[],"asks":[{"price":5714.01,"qty":0.90387105}],"checksum":2068004031,"timestamp":"2024-06-01T17:51:56.948990Z"}]}
{"channel":"book","type":"update","data":[{"symbol":"ETH/AUD","bids":[{"price":5708.74,"qty":0.00000000},{"price":5705.27,"qty":1.55451487},{"price":5709.20,"qty":0.14005974}],"asks":[],"checksum":3333928951,"timestamp":"2024-06-01T17:51:57.057989Z"}]}
{"channel":"book","type":"update","data":[{"symbol":"ETH/AUD","bids":[],"asks":[{"price":5714.03,"qty":0.00000000},{"price":5716.46,"qty":8.30652636}],"checksum":265126094,"timestamp":"2024-06-01T17:51:57.063066Z"}]}
{"channel":"book","type":"update","data":[{"symbol":"ETH/AUD","bids":[{"price":5709.08,"qty":0.00000000},{"price":5705.25,"qty":1.60677000}],"asks":[],"checksum":1412178378,"timestamp":"2024-06-01T17:51:57.218097Z"}]}
{"channel":"book","type":"update","data":[{"symbol":"ETH/AUD","bids":[{"price":5705.27,"qty":0.00000000},{"price":5703.34,"qty":0.74672684}],"asks":[],"checksum":3893214657,"timestamp":"2024-06-01T17:51:57.218505Z"}]}
{"channel":"book","type":"update","data":[{"symbol":"ETH/AUD","bids":[{"price":5709.21,"qty":0.52678653}],"asks":[],"checksum":2785558240,"timestamp":"2024-06-01T17:51:57.219684Z"}]}
{"channel":"book","type":"update","data":[{"symbol":"ETH/AUD","bids":[{"price":5705.30,"qty":1.04071206}],"asks":[],"checksum":3807803542,"timestamp":"2024-06-01T17:51:57.219860Z"}]}
{"channel":"book","type":"update","data":[{"symbol":"ETH/AUD","bids":[{"price":5705.28,"qty":0.00000000},{"price":5705.25,"qty":1.60677000},{"price":5705.31,"qty":0.52360000}],"asks":[],"checksum":1078158048,"timestamp":"2024-06-01T17:51:57.222733Z"}]}
{"channel":"book","type":"update","data":[{"symbol":"ETH/AUD","bids":[],"asks":[{"price":5716.45,"qty":0.83372964}],"checksum":2036131492,"timestamp":"2024-06-01T17:51:57.249867Z"}]}
{"channel":"book","type":"update","data":[{"symbol":"ETH/AUD","bids":[],"asks":[{"price":5716.13,"qty":0.00000000},{"price":5716.46,"qty":8.30652636}],"checksum":1023798996,"timestamp":"2024-06-01T17:51:57.437818Z"}]}
{"channel":"book","type":"update","data":[{"symbol":"ETH/AUD","bids":[],"asks":[{"price":5716.09,"qty":0.03777046}],"checksum":2240176036,"timestamp":"2024-06-01T17:51:57.440025Z"}]}
{"channel":"book","type":"update","data":[{"symbol":"ETH/AUD","bids":[],"asks":[{"price":5716.10,"qty":0.06926511}],"checksum":1663636850,"timestamp":"2024-06-01T17:51:57.440057Z"}]}
{"channel":"book","type":"update","data":[{"symbol":"ETH/AUD","bids":[{"price":5709.19,"qty":0.00000000},{"price":5705.25,"qty":1.60677000},{"price":5709.22,"qty":1.03790106}],"asks":[],"checksum":2841430112,"timestamp":"2024-06-01T17:51:57.536339Z"}]}
{"channel":"book","type":"update","data":[{"symbol":"ETH/AUD","bids":[],"asks":[{"price":5714.02,"qty":0.00000000},{"price":5716.46,"qty":8.30652636},{"price":5714.00,"qty":0.20887124}],"checksum":3587700330,"timestamp":"2024-06-01T17:51:57.536458Z"}]}
{"channel":"book","type":"update","data":[{"symbol":"ETH/AUD","bids":[{"price":5709.20,"qty":0.06658300},{"price":5709.23,"qty":0.07347674}],"asks":[],"checksum":1672390093,"timestamp":"2024-06-01T17:51:57.555668Z"}]}
{"channel":"book","type":"update","data":[{"symbol":"ETH/AUD","bids":[{"price":5709.11,"qty":0.00000000},{"price":5705.25,"qty":1.60677000}],"asks":[],"checksum":4058906230,"timestamp":"2024-06-01T17:51:57.769988Z"}]}
{"channel":"book","type":"update","data":[{"symbol":"ETH/AUD","bids":[{"price":5705.32,"qty":0.03179914}],"asks":[],"checksum":3285811444,"timestamp":"2024-06-01T17:51:57.773602Z"}]}
{"channel":"book","type":"update","data":[{"symbol":"ETH/AUD","bids":[{"price":5709.24,"qty":0.00526787}],"asks":[],"checksum":4171566000,"timestamp":"2024-06-01T17:51:57.773655Z"}]}
{"channel":"book","type":"update","data":[{"symbol":"ETH/AUD","bids":[],"asks":[{"price":5716.12,"qty":0.00000000},{"price":5716.46,"qty":8.30652636}],"checksum":2929386262,"timestamp":"2024-06-01T17:51:57.801458Z"}]}
{"channel":"book","type":"update","data":[{"symbol":"ETH/AUD","bids":[],"asks":[{"price":5716.46,"qty":0.00000000},{"price":5716.47,"qty":7.25344515}],"checksum":2651929159,"timestamp":"2024-06-01T17:51:57.801718Z"}]}
{"channel":"book","type":"update","data":[{"symbol":"ETH/AUD","bids":[],"asks":[{"price":5716.11,"qty":0.00000000},{"price":5719.72,"qty":0.08600000},{"price":5716.44,"qty":0.52360000}],"checksum":4141133274,"timestamp":"2024-06-01T17:51:57.804661Z"}]}
{"channel":"book","type":"update","data":[{"symbol":"ETH/AUD","bids":[],"asks":[{"price":5716.08,"qty":5.20835109}],"checksum":3982951950,"timestamp":"2024-06-01T17:51:57.806079Z"}]}
{"channel":"book","type":"update","data":[{"symbol":"ETH/AUD","bids":[],"asks":[{"price":5716.44,"qty":7.25614296}],"checksum":3895548445,"timestamp":"2024-06-01T17:51:57.806341Z"}]}
{"channel":"book","type":"update","data":[{"symbol":"ETH/AUD","bids":[],"asks":[{"price":5716.10,"qty":0.04834760}],"checksum":516480678,"timestamp":"2024-06-01T17:51:57.828621Z"}]}
{"channel":"book","type":"update","data":[{"symbol":"ETH/AUD","bids":[],"asks":[{"price":5716.07,"qty":0.02091761}],"checksum":4189145794,"timestamp":"2024-06-01T17:51:57.828793Z"}]}
{"channel":"book","type":"update","data":[{"symbol":"ETH/AUD","bids":[{"price":5709.23,"qty":0.00000000},{"price":5705.30,"qty":1.04071206},{"price":5709.25,"qty":0.07347674}],"asks":[],"checksum":2868289755,"timestamp":"2024-06-01T17:51:58.165363Z"}]}
{"channel":"book","type":"update","data":[{"symbol":"ETH/AUD","bids":[{"price":5709.26,"qty":0.90387105}],"asks":[],"checksum":2093857222,"timestamp":"2024-06-01T17:51:58.170607Z"}]}
{"channel":"book","type":"update","data":[{"symbol":"ETH/AUD","bids":[],"asks":[{"price":5713.99,"qty":0.90387105}],"checksum":1702440193,"timestamp":"2024-06-01T17:51:58.170692Z"}]}
{"channel":"book","type":"update","data":[{"symbol":"ETH/AUD","bids":[{"price":5709.22,"qty":0.00000000},{"price":5705.31,"qty":0.52360000},{"price":5709.25,"qty":1.11137218}],"asks":[],"checksum":1253654266,"timestamp":"2024-06-01T17:51:58.186832Z"}]}
{"channel":"book","type":"update","data":[{"symbol":"ETH/AUD","bids":[],"asks":[{"price":5716.07,"qty":0.54451761}],"checksum":1734506505,"timestamp":"2024-06-01T17:51:58.329874Z"}]}
{"channel":"book","type":"update","data":[{"symbol":"ETH/AUD","bids":[],"asks":[{"price":5714.01,"qty":0.00000000},{"price":5716.44,"qty":6.73254296}],"checksum":3461558969,"timestamp":"2024-06-01T17:51:58.677331Z"}]}
{"channel":"book","type":"update","data":[{"symbol":"ETH/AUD","bids":[{"price":5709.13,"qty":0.00000000},{"price":5705.30,"qty":1.04071206}],"asks":[],"checksum":1993246679,"timestamp":"2024-06-01T17:51:58.677523Z"}]}
{"channel":"book","type":"update","data":[{"symbol":"ETH/AUD","bids":[{"price":5709.25,"qty":1.03789544},{"price":5709.27,"qty":0.07347674}],"asks":[],"checksum":3873714409,"timestamp":"2024-06-01T17:51:58.684656Z"}]}
{"channel":"book","type":"update","data":[{"symbol":"ETH/AUD","bids":[],"asks":[{"price":5716.07,"qty":0.52360000}],"checksum":1554913798,"timestamp":"2024-06-01T17:51:58.785242Z"}]}
{"channel":"book","type":"update","data":[{"symbol":"ETH/AUD","bids":[],"asks":[{"price":5714.00,"qty":0.00000000},{"price":5716.45,"qty":0.83372964},{"price":5713.98,"qty":0.20887299}],"checksum":978557784,"timestamp":"2024-06-01T17:51:58.868528Z"}]}
{"channel":"book","type":"update","data":[{"symbol":"ETH/AUD","bids":[{"price":5709.25,"qty":0.00000000},{"price":5705.30,"qty":1.04071206},{"price":5709.28,"qty":1.03789615}],"asks":[],"checksum":154270024,"timestamp":"2024-06-01T17:51:58.868594Z"}]}
{"channel":"book","type":"update","data":[{"symbol":"ETH/AUD","bids":[{"price":5709.29,"qty":0.90387105}],"asks":[],"checksum":170616096,"timestamp":"2024-06-01T17:51:59.175436Z"}]}
{"channel":"book","type":"update","data":[{"symbol":"ETH/AUD","bids":[{"price":5709.26,"qty":0.00000000},{"price":5705.31,"qty":0.52360000}],"asks":[],"checksum":922408065,"timestamp":"2024-06-01T17:51:59.180500Z"}]}
{"channel":"book","type":"update","data":[{"symbol":"ETH/AUD","bids":[{"price":5709.27,"qty":0.00000000},{"price":5705.30,"qty":1.04071206},{"price":5709.30,"qty":0.07347674}],"asks":[],"checksum":3515665916,"timestamp":"2024-06-01T17:51:59.506535Z"}]}
{"channel":"book","type":"update","data":[{"symbol":"ETH/AUD","bids":[{"price":5709.28,"qty":0.00000000},{"price":5705.30,"qty":1.04071206},{"price":5709.30,"qty":1.11136925}],"asks":[],"checksum":1532400968,"timestamp":"2024-06-01T17:51:59.539775Z"}]}
{"channel":"book","type":"update","data":[{"symbol":"ETH/AUD","bids":[],"asks":[{"price":5716.09,"qty":0.00000000},{"price":5716.45,"qty":0.83372964}],"checksum":4013489782,"timestamp":"2024-06-01T17:51:59.746043Z"}]}
{"channel":"book","type":"update","data":[{"symbol":"ETH/AUD","bids":[],"asks":[{"price":5716.10,"qty":0.00000000},{"price":5716.47,"qty":7.25344515}],"checksum":2483410109,"timestamp":"2024-06-01T17:51:59.746286Z"}]}
{"channel":"book","type":"update","data":[{"symbol":"ETH/AUD","bids":[],"asks":[{"price":5716.06,"qty":0.08479773}],"checksum":1702097864,"timestamp":"2024-06-01T17:51:59.747979Z"}]}
{"channel":"book","type":"update","data":[{"symbol":"ETH/AUD","bids":[],"asks":[{"price":5716.07,"qty":0.00000000},{"price":5716.47,"qty":7.25344515},{"price":5716.05,"qty":0.52360000}],"checksum":903081339,"timestamp":"2024-06-01T17:51:59.751175Z"}]}
{"channel":"book","type":"update","data":[{"symbol":"ETH/AUD","bids":[],"asks":[{"price":5714.12,"qty":0.00000000},{"price":5716.47,"qty":7.25344515},{"price":5713.97,"qty":0.01292326}],"checksum":3355180406,"timestamp":"2024-06-01T17:51:59.783583Z"}]}
{"channel":"book","type":"update","data":[{"symbol":"ETH/AUD","bids":[{"price":5709.30,"qty":0.07347674},{"price":5709.31,"qty":1.03789069}],"asks":[],"checksum":3353069743,"timestamp":"2024-06-01T17:52:00.171023Z"}]}
{"channel":"book","type":"update","data":[{"symbol":"ETH/AUD","bids":[],"asks":[{"price":5713.98,"qty":0.00000000},{"price":5716.47,"qty":7.25344515},{"price":5713.96,"qty":0.20887355}],"checksum":593801953,"timestamp":"2024-06-01T17:52:00.171148Z"}]}
{"channel":"book","type":"update","data":[{"symbol":"ETH/AUD","bids":[{"price":5709.31,"qty":1.94176174}],"asks":[],"checksum":3883420428,"timestamp":"2024-06-01T17:52:00.176406Z"}]}
{"channel":"book","type":"update","data":[{"symbol":"ETH/AUD","bids":[{"price":5709.21,"qty":0.00000000},{"price":5705.30,"qty":1.04071206}],"asks":[],"checksum":290239809,"timestamp":"2024-06-01T17:52:00.208004Z"}]}
{"channel":"book","type":"update","data":[{"symbol":"ETH/AUD","bids":[{"price":5705.30,"qty":0.00000000},{"price":5705.25,"qty":1.60677000}],"asks":[],"checksum":488522187,"timestamp":"2024-06-01T17:52:00.208208Z"}]}
{"channel":"book","type":"update","data":[{"symbol":"ETH/AUD","bids":[{"price":5705.33,"qty":0.52679557}],"asks":[],"checksum":531883893,"timestamp":"2024-06-01T17:52:00.209787Z"}]}
{"channel":"book","type":"update","data":[{"symbol":"ETH/AUD","bids":[{"price":5705.31,"qty":0.00000000},{"price":5705.25,"qty":1.60677000},{"price":5705.34,"qty":0.52360000}],"asks":[],"checksum":564385165,"timestamp":"2024-06-01T17:52:00.213287Z"}]}
{"channel":"book","type":"update","data":[{"symbol":"ETH/AUD","bids":[],"asks":[{"price":5716.08,"qty":0.00000000},{"price":5716.47,"qty":7.25344515}],"checksum":2240903866,"timestamp":"2024-06-01T17:52:00.213397Z"}]}
{"channel":"book","type":"update","data":[{"symbol":"ETH/AUD","bids":[],"asks":[{"price":5716.44,"qty":0.00000000},{"price":5719.71,"qty":0.20717085}],"checksum":1403434886,"timestamp":"2024-06-01T17:52:00.213476Z"}]}
{"channel":"book","type":"update","data":[{"symbol":"ETH/AUD","bids":[{"price":5709.29,"qty":0.00000000},{"price":5705.25,"qty":1.60677000}],"asks":[],"checksum":2699575003,"timestamp":"2024-06-01T17:52:00.214336Z"}]}
{"channel":"book","type":"update","data":[{"symbol":"ETH/AUD","bids":[],"asks":[{"price":5716.44,"qty":8.29839823}],"checksum":847353326,"timestamp":"2024-06-01T17:52:00.218516Z"}]}
{"channel":"book","type":"update","data":[{"symbol":"ETH/AUD","bids":[],"asks":[{"price":5716.04,"qty":3.64783859}],"checksum":1781285434,"timestamp":"2024-06-01T17:52:00.218648Z"}]}
{"channel":"book","type":"update","data":[{"symbol":"ETH/AUD","bids":[],"asks":[{"price":5716.45,"qty":0.00000000},{"price":5716.47,"qty":7.25344515}],"checksum":86923618,"timestamp":"2024-06-01T17:52:00.249172Z"}]}
{"channel":"book","type":"update","data":[{"symbol":"ETH/AUD","bids":[],"asks":[{"price":5716.05,"qty":0.00000000},{"price":5719.71,"qty":0.20717085},{"price":5716.03,"qty":0.52360000}],"checksum":3116898310,"timestamp":"2024-06-01T17:52:00.252628Z"}]}
{"channel":"book","type":"update","data":[{"symbol":"ETH/AUD","bids":[],"asks":[{"price":5716.02,"qty":0.83372964}],"checksum":2757028764,"timestamp":"2024-06-01T17:52:00.400538Z"}]}
{"channel":"book","type":"update","data":[{"symbol":"ETH/AUD","bids":[{"price":5709.30,"qty":0.00000000},{"price":5703.36,"qty":0.74672423},{"price":5709.32,"qty":0.07347674}],"asks":[],"checksum":1650530059,"timestamp":"2024-06-01T17:52:00.427404Z"}]}
{"channel":"book","type":"update","data":[{"symbol":"ETH/AUD","bids":[{"price":5705.32,"qty":0.00000000},{"price":5703.36,"qty":0.74672423}],"asks":[],"checksum":3592635386,"timestamp":"2024-06-01T17:52:00.762523Z"}]}
{"channel":"book","type":"update","data":[{"symbol":"ETH/AUD","bids":[{"price":5709.24,"qty":0.00000000},{"price":5703.22,"qty":0.11200000}],"asks":[],"checksum":987551225,"timestamp":"2024-06-01T17:52:00.762860Z"}]}
{"channel":"book","type":"update","data":[{"symbol":"ETH/AUD","bids":[{"price":5705.35,"qty":0.02068590}],"asks":[],"checksum":3036497782,"timestamp":"2024-06-01T17:52:00.763472Z"}]}
{"channel":"book","type":"update","data":[{"symbol":"ETH/AUD","bids":[{"price":5709.31,"qty":0.90387105},{"price":5709.33,"qty":1.03789512}],"asks":[],"checksum":3985835844,"timestamp":"2024-06-01T17:52:00.866427Z"}]}
{"channel":"book","type":"update","data":[{"symbol":"ETH/AUD","bids":[{"price":5709.34,"qty":0.90387105}],"asks":[],"checksum":1933065713,"timestamp":"2024-06-01T17:52:01.175232Z"}]}
{"channel":"book","type":"update","data":[{"symbol":"ETH/AUD","bids":[],"asks":[{"price":5713.95,"qty":0.90387105}],"checksum":1854321009,"timestamp":"2024-06-01T17:52:01.175302Z"}]}
{"channel":"book","type":"update","data":[{"symbol":"ETH/AUD","bids":[{"price":5709.31,"qty":0.00000000},{"price":5705.25,"qty":1.60677000}],"asks":[],"checksum":2362153917,"timestamp":"2024-06-01T17:52:01.180024Z"}]}
{"channel":"book","type":"update","data":[{"symbol":"ETH/AUD","bids":[],"asks":[{"price":5713.99,"qty":0.00000000},{"price":5716.44,"qty":8.29839823}],"checksum":2295059024,"timestamp":"2024-06-01T17:52:01.180098Z"}]}
{"channel":"book","type":"update","data":[{"symbol":"ETH/AUD","bids":[{"price":5709.32,"qty":0.00000000},{"price":5703.36,"qty":0.74672423},{"price":5709.35,"qty":0.07347674}],"asks":[],"checksum":708720551,"timestamp":"2024-06-01T17:52:01.192255Z"}]}
{"channel":"book","type":"update","data":[{"symbol":"ETH/AUD","bids":[],"asks":[{"price":5716.03,"qty":0.00000000},{"price":5716.47,"qty":7.25344515},{"price":5716.01,"qty":0.52360000}],"checksum":482945467,"timestamp":"2024-06-01T17:52:01.194149Z"}]}
{"channel":"book","type":"update","data":[{"symbol":"ETH/AUD","bids":[{"price":5709.33,"qty":0.00000000},{"price":5703.36,"qty":0.74672423},{"price":5709.36,"qty":1.03788965}],"asks":[],"checksum":2530473360,"timestamp":"2024-06-01T17:52:01.521236Z"}]}
{"channel":"book","type":"update","data":[{"symbol":"ETH/AUD","bids":[],"asks":[{"price":5713.96,"qty":0.00000000},{"price":5716.47,"qty":7.25344515},{"price":5713.94,"qty":0.20887864}],"checksum":3671782625,"timestamp":"2024-06-01T17:52:01.521368Z"}]}
{"channel":"book","type":"update","data":[{"symbol":"ETH/AUD","bids":[{"price":5709.35,"qty":0.00000000},{"price":5703.36,"qty":0.74672423},{"price":5709.37,"qty":0.07347674}],"asks":[],"checksum":2801500653,"timestamp":"2024-06-01T17:52:01.832130Z"}]}
{"channel":"book","type":"update","data":[{"symbol":"ETH/AUD","bids":[],"asks":[{"price":5716.06,"qty":0.00000000},{"price":5716.47,"qty":7.25344515}],"checksum":2435545261,"timestamp":"2024-06-01T17:52:02.033727Z"}]}
{"channel":"book","type":"update","data":[{"symbol":"ETH/AUD","bids":[],"asks":[{"price":5716.00,"qty":0.08774326}],"checksum":2540347532,"timestamp":"2024-06-01T17:52:02.035292Z"}]}
{"channel":"book","type":"update","data":[{"symbol":"ETH/AUD","bids":[],"asks":[{"price":5716.01,"qty":0.00000000},{"price":5716.47,"qty":7.25344515},{"price":5715.99,"qty":0.52360000}],"checksum":3907053317,"timestamp":"2024-06-01T17:52:02.038654Z"}]}
{"channel":"book","type":"update","data":[{"symbol":"ETH/AUD","bids":[{"price":5709.36,"qty":0.00000000},{"price":5703.36,"qty":0.74672423},{"price":5709.38,"qty":1.03788601}],"asks":[],"checksum":3447966630,"timestamp":"2024-06-01T17:52:02.160912Z"}]}
{"channel":"book","type":"update","data":[{"symbol":"ETH/AUD","bids":[{"price":5708.78,"qty":0.00000000},{"price":5703.36,"qty":0.74672423}],"asks":[],"checksum":200714311,"timestamp":"2024-06-01T17:52:02.163636Z"}]}
{"channel":"book","type":"update","data":[{"symbol":"ETH/AUD","bids":[{"price":5709.39,"qty":0.90387105}],"asks":[],"checksum":2439112803,"timestamp":"2024-06-01T17:52:02.166483Z"}]}
{"channel":"book","type":"update","data":[{"symbol":"ETH/AUD","bids":[{"price":5709.38,"qty":4.36916448}],"asks":[],"checksum":2957540918,"timestamp":"2024-06-01T17:52:02.166642Z"}]}
{"channel":"book","type":"update","data":[{"symbol":"ETH/AUD","bids":[{"price":5709.37,"qty":0.00000000},{"price":5703.36,"qty":0.74672423},{"price":5709.39,"qty":0.97734779}],"asks":[],"checksum":768589331,"timestamp":"2024-06-01T17:52:02.168593Z"}]}
{"channel":"book","type":"update","data":[{"symbol":"ETH/AUD","bids":[{"price":5709.34,"qty":0.00000000},{"price":5703.22,"qty":0.11200000}],"asks":[],"checksum":1803408200,"timestamp":"2024-06-01T17:52:02.175352Z"}]}
{"channel":"book","type":"update","data":[{"symbol":"ETH/AUD","bids":[],"asks":[{"price":5716.02,"qty":0.00000000},{"price":5716.47,"qty":7.25344515}],"checksum":938462106,"timestamp":"2024-06-01T17:52:02.234912Z"}]}
{"channel":"book","type":"update","data":[{"symbol":"ETH/AUD","bids":[],"asks":[{"price":5716.43,"qty":0.83372964}],"checksum":1665161633,"timestamp":"2024-06-01T17:52:02.272759Z"}]}
{"channel":"book","type":"update","data":[{"symbol":"ETH/AUD","bids":[],"asks":[{"price":5716.44,"qty":0.00000000},{"price":5716.47,"qty":7.25344515}],"checksum":502561754,"timestamp":"2024-06-01T17:52:02.615330Z"}]}
{"channel":"book","type":"update","data":[{"symbol":"ETH/AUD","bids":[],"asks":[{"price":5716.04,"qty":0.00000000},{"price":5719.71,"qty":0.20717085}],"checksum":2075278359,"timestamp":"2024-06-01T17:52:02.615452Z"}]}
{"channel":"book","type":"update","data":[{"symbol":"ETH/AUD","bids":[],"asks":[{"price":5715.98,"qty":3.64783997}],"checksum":973980763,"timestamp":"2024-06-01T17:52:02.617891Z"}]}
{"channel":"book","type":"update","data":[{"symbol":"ETH/AUD","bids":[],"asks":[{"price":5716.42,"qty":8.29839822}],"checksum":1957384197,"timestamp":"2024-06-01T17:52:02.617966Z"}]}
{"channel":"book","type":"update","data":[{"symbol":"ETH/AUD","bids":[],"asks":[{"price":5715.99,"qty":0.00000000},{"price":5716.47,"qty":7.25344515},{"price":5715.97,"qty":0.52360000}],"checksum":2973818753,"timestamp":"2024-06-01T17:52:02.621314Z"}]}
{"channel":"book","type":"update","data":[{"symbol":"ETH/AUD","bids":[{"price":5709.38,"qty":3.33127847},{"price":5709.40,"qty":1.03788237}],"asks":[],"checksum":1133791213,"timestamp":"2024-06-01T17:52:02.834861Z"}]}
{"channel":"book","type":"update","data":[{"symbol":"ETH/AUD","bids":[{"price":5709.39,"qty":0.90387105},{"price":5709.41,"qty":0.07347674}],"asks":[],"checksum":1154534736,"timestamp":"2024-06-01T17:52:02.871458Z"}]}
{"channel":"book","type":"update","data":[{"symbol":"ETH/AUD","bids":[{"price":5709.42,"qty":0.90387105}],"asks":[],"checksum":19234251,"timestamp":"2024-06-01T17:52:03.176081Z"}]}
{"channel":"book","type":"update","data":[{"symbol":"ETH/AUD","bids":[{"price":5705.33,"qty":0.00000000},{"price":5705.25,"qty":1.60677000}],"asks":[],"checksum":426104140,"timestamp":"2024-06-01T17:52:03.233804Z"}]}
{"channel":"book","type":"update","data":[{"symbol":"ETH/AUD","bids":[{"price":5705.36,"qty":0.52679346}],"asks":[],"checksum":2968965758,"timestamp":"2024-06-01T17:52:03.234256Z"}]}
{"channel":"book","type":"update","data":[{"symbol":"ETH/AUD","bids":[{"price":5705.34,"qty":0.00000000},{"price":5705.25,"qty":1.60677000},{"price":5705.37,"qty":0.52360000}],"asks":[],"checksum":898798194,"timestamp":"2024-06-01T17:52:03.237329Z"}]}
{"channel":"book","type":"update","data":[{"symbol":"ETH/AUD","bids":[{"price":5709.40,"qty":0.00000000},{"price":5705.25,"qty":1.60677000},{"price":5709.43,"qty":1.03787671}],"asks":[],"checksum":3889768190,"timestamp":"2024-06-01T17:52:03.465909Z"}]}
{"channel":"book","type":"update","data":[{"symbol":"ETH/AUD","bids":[{"price":5709.39,"qty":0.00000000},{"price":5705.25,"qty":1.60677000}],"asks":[],"checksum":1784356536,"timestamp":"2024-06-01T17:52:03.471264Z"}]}
{"channel":"book","type":"update","data":[{"symbol":"ETH/AUD","bids":[{"price":5709.41,"qty":0.00000000},{"price":5703.38,"qty":0.74672161},{"price":5709.44,"qty":0.07347674}],"asks":[],"checksum":2432957843,"timestamp":"2024-06-01T17:52:03.479138Z"}]}
{"channel":"book","type":"update","data":[{"symbol":"ETH/AUD","bids":[{"price":5705.35,"qty":0.00000000},{"price":5703.38,"qty":0.74672161}],"asks":[],"checksum":2936086312,"timestamp":"2024-06-01T17:52:03.739142Z"}]}
{"channel":"book","type":"update","data":[{"symbol":"ETH/AUD","bids":[{"price":5703.39,"qty":0.02562133}],"asks":[],"checksum":644100164,"timestamp":"2024-06-01T17:52:03.740521Z"}]}
{"channel":"book","type":"update","data":[{"symbol":"ETH/AUD","bids":[{"price":5705.38,"qty":0.02068590}],"asks":[],"checksum":3224896376,"timestamp":"2024-06-01T17:52:03.740557Z"}]}
{"channel":"book","type":"update","data":[{"symbol":"ETH/AUD","bids":[],"asks":[{"price":5713.97,"qty":0.00000000},{"price":5716.47,"qty":7.25344515},{"price":5713.93,"qty":0.01292326}],"checksum":3495447652,"timestamp":"2024-06-01T17:52:04.056431Z"}]}
{"channel":"book","type":"update","data":[{"symbol":"ETH/AUD","bids":[],"asks":[{"price":5713.92,"qty":0.90387105}],"checksum":3487427463,"timestamp":"2024-06-01T17:52:04.062448Z"}]}
{"channel":"book","type":"update","data":[{"symbol":"ETH/AUD","bids":[{"price":5709.45,"qty":0.90387105}],"asks":[],"checksum":2546725760,"timestamp":"2024-06-01T17:52:04.062733Z"}]}
{"channel":"book","type":"update","data":[{"symbol":"ETH/AUD","bids":[],"asks":[{"price":5713.94,"qty":0.00000000},{"price":5716.43,"qty":0.83372964},{"price":5713.91,"qty":0.20805782}],"checksum":3017981722,"timestamp":"2024-06-01T17:52:04.120246Z"}]}
{"channel":"book","type":"update","data":[{"symbol":"ETH/AUD","bids":[{"price":5709.43,"qty":0.00000000},{"price":5705.25,"qty":1.60677000},{"price":5709.46,"qty":1.03787076}],"asks":[],"checksum":2795812411,"timestamp":"2024-06-01T17:52:04.120350Z"}]}
{"channel":"book","type":"update","data":[{"symbol":"ETH/AUD","bids":[{"price":5709.42,"qty":0.00000000},{"price":5705.25,"qty":1.60677000}],"asks":[],"checksum":230859254,"timestamp":"2024-06-01T17:52:04.126017Z"}]}
{"channel":"book","type":"update","data":[{"symbol":"ETH/AUD","bids":[],"asks":[{"price":5713.95,"qty":0.00000000},{"price":5716.43,"qty":0.83372964}],"checksum":4184381354,"timestamp":"2024-06-01T17:52:04.126063Z"}]}
{"channel":"book","type":"update","data":[{"symbol":"ETH/AUD","bids":[],"asks":[{"price":5716.00,"qty":0.00000000},{"price":5716.47,"qty":7.25344515}],"checksum":434767720,"timestamp":"2024-06-01T17:52:04.301762Z"}]}
{"channel":"book","type":"update","data":[{"symbol":"ETH/AUD","bids":[],"asks":[{"price":5715.96,"qty":0.08754012}],"checksum":1744078000,"timestamp":"2024-06-01T17:52:04.303649Z"}]}
{"channel":"book","type":"update","data":[{"symbol":"ETH/AUD","bids":[],"asks":[{"price":5715.97,"qty":0.00000000},{"price":5716.47,"qty":7.25344515},{"price":5715.95,"qty":0.52360000}],"checksum":606905274,"timestamp":"2024-06-01T17:52:04.306915Z"}]}
{"channel":"book","type":"update","data":[{"symbol":"ETH/AUD","bids":[{"price":5709.44,"qty":0.00000000},{"price":5703.39,"qty":0.02562133},{"price":5709.47,"qty":0.07347674}],"asks":[],"checksum":145164108,"timestamp":"2024-06-01T17:52:04.515379Z"}]}
{"channel":"book","type":"update","data":[{"symbol":"ETH/AUD","bids":[{"price":5709.46,"qty":0.00000000},{"price":5703.39,"qty":0.02562133},{"price":5709.48,"qty":1.03786692}],"asks":[],"checksum":2317230936,"timestamp":"2024-06-01T17:52:04.771891Z"}]}
{"channel":"book","type":"update","data":[{"symbol":"ETH/AUD","bids":[],"asks":[{"price":5716.42,"qty":19.47949958}],"checksum":476650405,"timestamp":"2024-06-01T17:52:04.781222Z"}]}
{"channel":"book","type":"update","data":[{"symbol":"ETH/AUD","bids":[],"asks":[{"price":5716.42,"qty":11.18110136}],"checksum":3129398824,"timestamp":"2024-06-01T17:52:04.986231Z"}]}
{"channel":"book","type":"update","data":[{"symbol":"ETH/AUD","bids":[],"asks":[{"price":5715.98,"qty":0.00000000},{"price":5719.71,"qty":0.20717085}],"checksum":3036750388,"timestamp":"2024-06-01T17:52:04.986346Z"}]}
{"channel":"book","type":"update","data":[{"symbol":"ETH/AUD","bids":[],"asks":[{"price":5715.94,"qty":3.12762462}],"checksum":3775684149,"timestamp":"2024-06-01T17:52:04.991898Z"}]}
{"channel":"book","type":"update","data":[{"symbol":"ETH/AUD","bids":[],"asks":[{"price":5716.42,"qty":20.52137156}],"checksum":3438872760,"timestamp":"2024-06-01T17:52:04.991950Z"}]}
{"channel":"book","type":"update","data":[{"symbol":"ETH/AUD","bids":[],"asks":[{"price":5715.95,"qty":0.00000000},{"price":5719.71,"qty":0.20717085},{"price":5715.93,"qty":0.52360000}],"checksum":519000791,"timestamp":"2024-06-01T17:52:04.995188Z"}]}
{"channel":"book","type":"update","data":[{"symbol":"ETH/AUD","bids":[{"price":5709.47,"qty":0.00000000},{"price":5703.39,"qty":0.02562133},{"price":5709.49,"qty":0.07347674}],"asks":[],"checksum":3078195832,"timestamp":"2024-06-01T17:52:05.163351Z"}]}
{"channel":"book","type":"update","data":[{"symbol":"ETH/AUD","bids":[{"price":5709.50,"qty":0.90387105}],"asks":[],"checksum":1484438134,"timestamp":"2024-06-01T17:52:05.168490Z"}]}
{"channel":"book","type":"update","data":[{"symbol":"ETH/AUD","bids":[{"price":5709.45,"qty":0.00000000},{"price":5705.25,"qty":1.60677000}],"asks":[],"checksum":1964485440,"timestamp":"2024-06-01T17:52:05.177492Z"}]}
{"channel":"book","type":"update","data":[{"symbol":"ETH/AUD","bids":[{"price":5709.48,"qty":0.00000000},{"price":5703.39,"qty":0.02562133},{"price":5709.51,"qty":1.03786132}],"asks":[],"checksum":681902158,"timestamp":"2024-06-01T17:52:05.394712Z"}]}
{"channel":"book","type":"update","data":[{"symbol":"ETH/AUD","bids":[],"asks":[{"price":5716.43,"qty":0.00000000},{"price":5719.71,"qty":0.20717085}],"checksum":3541524497,"timestamp":"2024-06-01T17:52:05.433687Z"}]}
{"channel":"book","type":"update","data":[{"symbol":"ETH/AUD","bids":[],"asks":[{"price":5716.41,"qty":0.83372964}],"checksum":3354089547,"timestamp":"2024-06-01T17:52:05.469852Z"}]}
{"channel":"book","type":"update","data":[{"symbol":"ETH/AUD","bids":[{"price":5709.49,"qty":0.00000000},{"price":5703.39,"qty":0.02562133},{"price":5709.52,"qty":0.07347674}],"asks":[],"checksum":1017180195,"timestamp":"2024-06-01T17:52:05.803724Z"}]}
{"channel":"book","type":"update","data":[{"symbol":"ETH/AUD","bids":[{"price":5709.51,"qty":0.00000000},{"price":5703.39,"qty":0.02562133},{"price":5709.53,"qty":1.03785764}],"asks":[],"checksum":1552336610,"timestamp":"2024-06-01T17:52:06.042136Z"}]}
{"channel":"book","type":"update","data":[{"symbol":"ETH/AUD","bids":[{"price":5709.54,"qty":0.90387105}],"asks":[],"checksum":777037980,"timestamp":"2024-06-01T17:52:06.047578Z"}]}
{"channel":"book","type":"update","data":[{"symbol":"ETH/AUD","bids":[{"price":5709.50,"qty":0.00000000},{"price":5705.25,"qty":1.60677000}],"asks":[],"checksum":872562648,"timestamp":"2024-06-01T17:52:06.177150Z"}]}
{"channel":"book","type":"update","data":[{"symbol":"ETH/AUD","bids":[{"price":5705.36,"qty":0.00000000},{"price":5703.39,"qty":0.02562133}],"asks":[],"checksum":2663613395,"timestamp":"2024-06-01T17:52:06.229659Z"}]}
{"channel":"book","type":"update","data":[{"symbol":"ETH/AUD","bids":[{"price":5705.39,"qty":0.52680944}],"asks":[],"checksum":3236356574,"timestamp":"2024-06-01T17:52:06.231020Z"}]}
{"channel":"book","type":"update","data":[{"symbol":"ETH/AUD","bids":[{"price":5705.37,"qty":0.00000000},{"price":5703.39,"qty":0.02562133},{"price":5705.26,"qty":0.52360000}],"asks":[],"checksum":3829929207,"timestamp":"2024-06-01T17:52:06.232640Z"}]}
{"channel":"book","type":"update","data":[{"symbol":"ETH/AUD","bids":[{"price":5709.52,"qty":0.00000000},{"price":5703.39,"qty":0.02562133},{"price":5709.55,"qty":0.07347674}],"asks":[],"checksum":481485027,"timestamp":"2024-06-01T17:52:06.264968Z"}]}
{"channel":"book","type":"update","data":[{"symbol":"ETH/AUD","bids":[{"price":5705.26,"qty":0.00000000},{"price":5703.39,"qty":0.02562133}],"asks":[],"checksum":213633175,"timestamp":"2024-06-01T17:52:06.270811Z"}]}
{"channel":"book","type":"update","data":[{"symbol":"ETH/AUD","bids":[{"price":5709.53,"qty":0.00000000},{"price":5703.38,"qty":0.74672161},{"price":5709.56,"qty":1.03784556}],"asks":[],"checksum":422365948,"timestamp":"2024-06-01T17:52:06.651937Z"}]}
{"channel":"book","type":"update","data":[{"symbol":"ETH/AUD","bids":[{"price":5705.38,"qty":0.00000000},{"price":5703.38,"qty":0.74672161}],"asks":[],"checksum":3917821000,"timestamp":"2024-06-01T17:52:06.660744Z"}]}
{"channel":"book","type":"update","data":[{"symbol":"ETH/AUD","bids":[{"price":5703.39,"qty":0.00000000},{"price":5703.22,"qty":0.11200000}],"asks":[],"checksum":2270587003,"timestamp":"2024-06-01T17:52:06.661056Z"}]}
{"channel":"book","type":"update","data":[{"symbol":"ETH/AUD","bids":[],"asks":[{"price":5715.96,"qty":0.00000000},{"price":5719.71,"qty":0.20717085}],"checksum":299081765,"timestamp":"2024-06-01T17:52:06.695475Z"}]}
{"channel":"book","type":"update","data":[{"symbol":"ETH/AUD","bids":[],"asks":[{"price":5715.92,"qty":0.08479787}],"checksum":1991789454,"timestamp":"2024-06-01T17:52:06.698350Z"}]}
{"channel":"book","type":"update","data":[{"symbol":"ETH/AUD","bids":[],"asks":[{"price":5715.93,"qty":0.00000000},{"price":5719.71,"qty":0.20717085},{"price":5715.91,"qty":0.52360000}],"checksum":854912893,"timestamp":"2024-06-01T17:52:06.701585Z"}]}
{"channel":"book","type":"update","data":[{"symbol":"ETH/AUD","bids":[{"price":5705.00,"qty":0.52360000}],"asks":[],"checksum":625458,"timestamp":"2024-06-01T17:52:06.785802Z"}]}
{"channel":"book","type":"update","data":[{"symbol":"ETH/AUD","bids":[{"price":5709.55,"qty":0.00000000},{"price":5703.22,"qty":0.11200000},{"price":5709.57,"qty":0.07347674}],"asks":[],"checksum":3938518409,"timestamp":"2024-06-01T17:52:07.117995Z"}]}
{"channel":"book","type":"update","data":[{"symbol":"ETH/AUD","bids":[],"asks":[{"price":5713.90,"qty":0.90387105}],"checksum":946693926,"timestamp":"2024-06-01T17:52:07.126032Z"}]}
{"channel":"book","type":"update","data":[{"symbol":"ETH/AUD","bids":[{"price":5709.58,"qty":0.90387105}],"asks":[],"checksum":1479893327,"timestamp":"2024-06-01T17:52:07.126144Z"}]}
{"channel":"book","type":"update","data":[{"symbol":"ETH/AUD","bids":[{"price":5709.54,"qty":0.00000000},{"price":5703.38,"qty":0.74672161}],"asks":[],"checksum":1237731117,"timestamp":"2024-06-01T17:52:07.176543Z"}]}
{"channel":"book","type":"update","data":[{"symbol":"ETH/AUD","bids":[],"asks":[{"price":5713.92,"qty":0.00000000},{"price":5716.42,"qty":20.52137156}],"checksum":2265636976,"timestamp":"2024-06-01T17:52:07.176586Z"}]}
{"channel":"book","type":"update","data":[{"symbol":"ETH/AUD","bids":[{"price":5709.56,"qty":0.00000000},{"price":5703.22,"qty":0.11200000},{"price":5709.59,"qty":1.03783754}],"asks":[],"checksum":3412201966,"timestamp":"2024-06-01T17:52:07.288518Z"}]}
{"channel":"book","type":"update","data":[{"symbol":"ETH/AUD","bids":[],"asks":[{"price":5713.91,"qty":0.00000000},{"price":5719.71,"qty":0.20717085},{"price":5713.89,"qty":0.20805439}],"checksum":2261989912,"timestamp":"2024-06-01T17:52:07.288645Z"}]}
{"channel":"book","type":"update","data":[{"symbol":"ETH/AUD","bids":[{"price":5705.00,"qty":0.00000000},{"price":5703.22,"qty":0.11200000},{"price":5705.40,"qty":0.52360000}],"asks":[],"checksum":96562392,"timestamp":"2024-06-01T17:52:07.291836Z"}]}
{"channel":"book","type":"update","data":[{"symbol":"ETH/AUD","bids":[],"asks":[{"price":5715.94,"qty":0.00000000},{"price":5719.71,"qty":0.20717085}],"checksum":1577347546,"timestamp":"2024-06-01T17:52:07.405481Z"}]}
{"channel":"book","type":"update","data":[{"symbol":"ETH/AUD","bids":[],"asks":[{"price":5716.42,"qty":11.18110136}],"checksum":3441451793,"timestamp":"2024-06-01T17:52:07.405724Z"}]}
{"channel":"book","type":"update","data":[{"symbol":"ETH/AUD","bids":[],"asks":[{"price":5716.40,"qty":8.81704802}],"checksum":4010279128,"timestamp":"2024-06-01T17:52:07.408327Z"}]}
{"channel":"book","type":"update","data":[{"symbol":"ETH/AUD","bids":[],"asks":[{"price":5715.90,"qty":3.64785034}],"checksum":3601377740,"timestamp":"2024-06-01T17:52:07.408353Z"}]}
{"channel":"book","type":"update","data":[{"symbol":"ETH/AUD","bids":[],"asks":[{"price":5715.91,"qty":0.00000000},{"price":5716.42,"qty":11.18110136},{"price":5715.89,"qty":0.52360000}],"checksum":1773523184,"timestamp":"2024-06-01T17:52:07.411379Z"}]}
{"channel":"book","type":"update","data":[{"symbol":"ETH/AUD","bids":[{"price":5709.57,"qty":0.00000000},{"price":5703.22,"qty":0.11200000},{"price":5709.60,"qty":0.07347674}],"asks":[],"checksum":846906159,"timestamp":"2024-06-01T17:52:07.424855Z"}]}
{"channel":"book","type":"update","data":[{"symbol":"ETH/AUD","bids":[{"price":5709.59,"qty":0.00000000},{"price":5703.22,"qty":0.11200000},{"price":5709.61,"qty":1.03783353}],"asks":[],"checksum":2025200307,"timestamp":"2024-06-01T17:52:07.917540Z"}]}
{"channel":"book","type":"update","data":[{"symbol":"ETH/AUD","bids":[{"price":5709.62,"qty":0.90387105}],"asks":[],"checksum":1913610824,"timestamp":"2024-06-01T17:52:07.923034Z"}]}
{"channel":"book","type":"update","data":[{"symbol":"ETH/AUD","bids":[{"price":5709.58,"qty":0.00000000},{"price":5703.38,"qty":0.74672161}],"asks":[],"checksum":1936936406,"timestamp":"2024-06-01T17:52:08.175547Z"}]}
{"channel":"book","type":"update","data":[{"symbol":"ETH/AUD","bids":[{"price":5709.60,"qty":0.00000000},{"price":5703.22,"qty":0.11200000},{"price":5709.63,"qty":0.07347674}],"asks":[],"checksum":2772149273,"timestamp":"2024-06-01T17:52:08.214311Z"}]}
{"channel":"book","type":"update","data":[{"symbol":"ETH/AUD","bids":[],"asks":[{"price":5716.41,"qty":0.00000000},{"price":5716.42,"qty":11.18110136}],"checksum":825450060,"timestamp":"2024-06-01T17:52:08.482401Z"}]}
{"channel":"book","type":"update","data":[{"symbol":"ETH/AUD","bids":[],"asks":[{"price":5715.88,"qty":0.83372964}],"checksum":192884489,"timestamp":"2024-06-01T17:52:08.514226Z"}]}
{"channel":"book","type":"update","data":[{"symbol":"ETH/AUD","bids":[],"asks":[{"price":5715.89,"qty":0.00000000},{"price":5716.42,"qty":11.18110136},{"price":5715.87,"qty":0.52360000}],"checksum":4258659939,"timestamp":"2024-06-01T17:52:08.517087Z"}]}
{"channel":"book","type":"update","data":[{"symbol":"ETH/AUD","bids":[{"price":5709.61,"qty":0.00000000},{"price":5703.22,"qty":0.11200000},{"price":5709.64,"qty":1.03782786}],"asks":[],"checksum":384530935,"timestamp":"2024-06-01T17:52:08.578648Z"}]}
{"channel":"book","type":"update","data":[{"symbol":"ETH/AUD","bids":[{"price":5709.63,"qty":0.00000000},{"price":5703.22,"qty":0.11200000},{"price":5709.65,"qty":0.07347674}],"asks":[],"checksum":3421383176,"timestamp":"2024-06-01T17:52:08.614873Z"}]}
{"channel":"book","type":"update","data":[{"symbol":"ETH/AUD","bids":[{"price":5709.20,"qty":0.00000000},{"price":5703.22,"qty":0.11200000},{"price":5709.66,"qty":0.06658000}],"asks":[],"checksum":3120065368,"timestamp":"2024-06-01T17:52:08.795387Z"}]}
{"channel":"book","type":"update","data":[{"symbol":"ETH/AUD","bids":[],"asks":[{"price":5715.92,"qty":0.00000000},{"price":5716.42,"qty":11.18110136}],"checksum":3747943344,"timestamp":"2024-06-01T17:52:09.066915Z"}]}
{"channel":"book","type":"update","data":[{"symbol":"ETH/AUD","bids":[],"asks":[{"price":5715.86,"qty":0.09058742}],"checksum":166069841,"timestamp":"2024-06-01T17:52:09.070162Z"}]}
{"channel":"book","type":"update","data":[{"symbol":"ETH/AUD","bids":[],"asks":[{"price":5715.87,"qty":0.00000000},{"price":5716.42,"qty":11.18110136},{"price":5715.85,"qty":0.52360000}],"checksum":2630158440,"timestamp":"2024-06-01T17:52:09.073470Z"}]}
{"channel":"book","type":"update","data":[{"symbol":"ETH/AUD","bids":[{"price":5709.67,"qty":0.90387105}],"asks":[],"checksum":1291996371,"timestamp":"2024-06-01T17:52:09.175511Z"}]}
{"channel":"book","type":"update","data":[{"symbol":"ETH/AUD","bids":[{"price":5709.62,"qty":0.00000000},{"price":5703.38,"qty":0.74672161}],"asks":[],"checksum":2094355768,"timestamp":"2024-06-01T17:52:09.182653Z"}]}
{"channel":"book","type":"update","data":[{"symbol":"ETH/AUD","bids":[{"price":5709.64,"qty":0.00000000},{"price":5703.22,"qty":0.11200000},{"price":5709.67,"qty":1.94168828}],"asks":[],"checksum":2160908307,"timestamp":"2024-06-01T17:52:09.192650Z"}]}
{"channel":"book","type":"update","data":[{"symbol":"ETH/AUD","bids":[{"price":5709.65,"qty":0.00000000},{"price":5702.48,"qty":0.04124445},{"price":5709.68,"qty":0.07347674}],"asks":[],"checksum":4281354789,"timestamp":"2024-06-01T17:52:09.195155Z"}]}
{"channel":"book","type":"update","data":[{"symbol":"ETH/AUD","bids":[{"price":5705.39,"qty":0.00000000},{"price":5702.48,"qty":0.04124445}],"asks":[],"checksum":2822537515,"timestamp":"2024-06-01T17:52:09.211126Z"}]}
{"channel":"book","type":"update","data":[{"symbol":"ETH/AUD","bids":[{"price":5705.41,"qty":0.52680528}],"asks":[],"checksum":1499868636,"timestamp":"2024-06-01T17:52:09.212029Z"}]}
{"channel":"book","type":"update","data":[{"symbol":"ETH/AUD","bids":[{"price":5705.40,"qty":0.00000000},{"price":5702.49,"qty":6.68126968},{"price":5705.42,"qty":0.52360000}],"asks":[],"checksum":115575443,"timestamp":"2024-06-01T17:52:09.215031Z"}]}
{"channel":"book","type":"update","data":[{"symbol":"ETH/AUD","bids":[{"price":5705.43,"qty":0.01040764}],"asks":[],"checksum":1041871452,"timestamp":"2024-06-01T17:52:09.641249Z"}]}
{"channel":"book","type":"update","data":[{"symbol":"ETH/AUD","bids":[],"asks":[{"price":5713.93,"qty":0.00000000},{"price":5716.42,"qty":11.18110136},{"price":5713.88,"qty":0.01292326}],"checksum":14275245,"timestamp":"2024-06-01T17:52:09.743638Z"}]}
{"channel":"book","type":"update","data":[{"symbol":"ETH/AUD","bids":[{"price":5709.67,"qty":0.90387105},{"price":5709.69,"qty":1.03781343}],"asks":[],"checksum":1111027401,"timestamp":"2024-06-01T17:52:09.767652Z"}]}
{"channel":"book","type":"update","data":[{"symbol":"ETH/AUD","bids":[],"asks":[{"price":5716.40,"qty":0.00000000},{"price":5716.42,"qty":11.18110136}],"checksum":2157103550,"timestamp":"2024-06-01T17:52:09.771058Z"}]}
{"channel":"book","type":"update","data":[{"symbol":"ETH/AUD","bids":[],"asks":[{"price":5715.90,"qty":0.00000000},{"price":5719.71,"qty":0.20717085}],"checksum":2472564585,"timestamp":"2024-06-01T17:52:09.771432Z"}]}
{"channel":"book","type":"update","data":[{"symbol":"ETH/AUD","bids":[],"asks":[{"price":5715.84,"qty":10.93029001}],"checksum":4093725081,"timestamp":"2024-06-01T17:52:09.776824Z"}]}
{"channel":"book","type":"update","data":[{"symbol":"ETH/AUD","bids":[],"asks":[{"price":5716.41,"qty":2.06037602}],"checksum":678957701,"timestamp":"2024-06-01T17:52:09.776957Z"}]}
{"channel":"book","type":"update","data":[{"symbol":"ETH/AUD","bids":[],"asks":[{"price":5715.85,"qty":0.00000000},{"price":5716.42,"qty":11.18110136},{"price":5715.83,"qty":0.52360000}],"checksum":1204279504,"timestamp":"2024-06-01T17:52:09.779879Z"}]}
{"channel":"book","type":"update","data":[{"symbol":"ETH/AUD","bids":[{"price":5709.70,"qty":0.90387105}],"asks":[],"checksum":2022609353,"timestamp":"2024-06-01T17:52:10.179266Z"}]}
{"channel":"book","type":"update","data":[{"symbol":"ETH/AUD","bids":[],"asks":[{"price":5713.87,"qty":0.90387105}],"checksum":1691389941,"timestamp":"2024-06-01T17:52:10.179337Z"}]}
{"channel":"book","type":"update","data":[{"symbol":"ETH/AUD","bids":[{"price":5709.67,"qty":0.00000000},{"price":5705.25,"qty":1.60677000}],"asks":[],"checksum":1761135746,"timestamp":"2024-06-01T17:52:10.189001Z"}]}
{"channel":"book","type":"update","data":[{"symbol":"ETH/AUD","bids":[],"asks":[{"price":5713.90,"qty":0.00000000},{"price":5716.41,"qty":2.06037602}],"checksum":556620824,"timestamp":"2024-06-01T17:52:10.189035Z"}]}
{"channel":"book","type":"update","data":[{"symbol":"ETH/AUD","bids":[{"price":5709.69,"qty":0.00000000},{"price":5703.38,"qty":0.74672161},{"price":5709.71,"qty":1.03777986}],"asks":[],"checksum":2951236016,"timestamp":"2024-06-01T17:52:10.372096Z"}]}
{"channel":"book","type":"update","data":[{"symbol":"ETH/AUD","bids":[],"asks":[{"price":5713.89,"qty":0.00000000},{"price":5716.42,"qty":11.18110136},{"price":5713.86,"qty":0.20816298}],"checksum":2731781808,"timestamp":"2024-06-01T17:52:10.372136Z"}]}
{"channel":"book","type":"update","data":[{"symbol":"ETH/AUD","bids":[{"price":5709.68,"qty":0.00000000},{"price":5703.38,"qty":0.74672161},{"price":5709.72,"qty":0.07347674}],"asks":[],"checksum":765523597,"timestamp":"2024-06-01T17:52:10.383087Z"}]}
{"channel":"book","type":"update","data":[{"symbol":"ETH/AUD","bids":[{"price":5709.71,"qty":0.00000000},{"price":5703.38,"qty":0.74672161},{"price":5709.73,"qty":1.03777285}],"asks":[],"checksum":3488090132,"timestamp":"2024-06-01T17:52:10.970915Z"}]}
{"channel":"book","type":"update","data":[{"symbol":"ETH/AUD","bids":[{"price":5709.74,"qty":0.90387105}],"asks":[],"checksum":1216185718,"timestamp":"2024-06-01T17:52:10.976304Z"}]}
{"channel":"book","type":"update","data":[{"symbol":"ETH/AUD","bids":[{"price":5709.72,"qty":0.00000000},{"price":5705.25,"qty":1.60677000},{"price":5709.75,"qty":0.07347674}],"asks":[],"checksum":2165520884,"timestamp":"2024-06-01T17:52:10.990324Z"}]}
{"channel":"book","type":"update","data":[{"symbol":"ETH/AUD","bids":[{"price":5709.74,"qty":0.00000000},{"price":5705.25,"qty":1.60677000}],"asks":[],"checksum":838974662,"timestamp":"2024-06-01T17:52:11.177074Z"}]}
{"channel":"book","type":"update","data":[{"symbol":"ETH/AUD","bids":[],"asks":[{"price":5715.86,"qty":0.00000000},{"price":5716.42,"qty":11.18110136}],"checksum":2570595716,"timestamp":"2024-06-01T17:52:11.367111Z"}]}
{"channel":"book","type":"update","data":[{"symbol":"ETH/AUD","bids":[],"asks":[{"price":5715.82,"qty":0.09658013}],"checksum":2417018891,"timestamp":"2024-06-01T17:52:11.368854Z"}]}
{"channel":"book","type":"update","data":[{"symbol":"ETH/AUD","bids":[],"asks":[{"price":5715.83,"qty":0.00000000},{"price":5716.42,"qty":11.18110136},{"price":5715.81,"qty":0.52360000}],"checksum":1267069221,"timestamp":"2024-06-01T17:52:11.371839Z"}]}
{"channel":"book","type":"update","data":[{"symbol":"ETH/AUD","bids":[],"asks":[{"price":5715.88,"qty":0.00000000},{"price":5716.42,"qty":11.18110136}],"checksum":1727655800,"timestamp":"2024-06-01T17:52:11.586231Z"}]}
{"channel":"book","type":"update","data":[{"symbol":"ETH/AUD","bids":[],"asks":[{"price":5713.88,"qty":0.00000000},{"price":5719.71,"qty":0.20717085},{"price":5713.85,"qty":0.01292326}],"checksum":3015435787,"timestamp":"2024-06-01T17:52:11.599197Z"}]}
{"channel":"book","type":"update","data":[{"symbol":"ETH/AUD","bids":[{"price":5709.73,"qty":0.00000000},{"price":5703.38,"qty":0.74672161},{"price":5709.76,"qty":1.03776248}],"asks":[],"checksum":1491604867,"timestamp":"2024-06-01T17:52:11.609847Z"}]}
{"channel":"book","type":"update","data":[{"symbol":"ETH/AUD","bids":[],"asks":[{"price":5715.80,"qty":0.83372964}],"checksum":2230951664,"timestamp":"2024-06-01T17:52:11.619403Z"}]}
{"channel":"book","type":"update","data":[{"symbol":"ETH/AUD","bids":[],"asks":[{"price":5715.84,"qty":0.00000000},{"price":5716.42,"qty":11.18110136}],"checksum":1987567644,"timestamp":"2024-06-01T17:52:12.167391Z"}]}
{"channel":"book","type":"update","data":[{"symbol":"ETH/AUD","bids":[],"asks":[{"price":5715.81,"qty":0.00000000},{"price":5719.71,"qty":0.20717085},{"price":5715.79,"qty":0.52360000}],"checksum":1811981602,"timestamp":"2024-06-01T17:52:12.170574Z"}]}
{"channel":"book","type":"update","data":[{"symbol":"ETH/AUD","bids":[],"asks":[{"price":5715.79,"qty":11.45389354}],"checksum":778521701,"timestamp":"2024-06-01T17:52:12.172654Z"}]}
{"channel":"book","type":"update","data":[{"symbol":"ETH/AUD","bids":[{"price":5709.77,"qty":0.90387105}],"asks":[],"checksum":1455919298,"timestamp":"2024-06-01T17:52:12.176029Z"}]}
{"channel":"book","type":"update","data":[{"symbol":"ETH/AUD","bids":[{"price":5709.75,"qty":0.00000000},{"price":5705.25,"qty":1.60677000},{"price":5709.77,"qty":0.97734779}],"asks":[],"checksum":2480518341,"timestamp":"2024-06-01T17:52:12.179326Z"}]}
{"channel":"book","type":"update","data":[{"symbol":"ETH/AUD","bids":[{"price":5709.70,"qty":0.00000000},{"price":5703.38,"qty":0.74672161}],"asks":[],"checksum":2382680366,"timestamp":"2024-06-01T17:52:12.181196Z"}]}
{"channel":"book","type":"update","data":[{"symbol":"ETH/AUD","bids":[],"asks":[{"price":5713.86,"qty":0.00000000},{"price":5719.71,"qty":0.20717085},{"price":5713.84,"qty":0.20816025}],"checksum":3167251789,"timestamp":"2024-06-01T17:52:12.194367Z"}]}
{"channel":"book","type":"update","data":[{"symbol":"ETH/AUD","bids":[{"price":5705.41,"qty":0.00000000},{"price":5703.22,"qty":0.11200000}],"asks":[],"checksum":3749563029,"timestamp":"2024-06-01T17:52:12.224294Z"}]}
{"channel":"book","type":"update","data":[{"symbol":"ETH/AUD","bids":[{"price":5705.42,"qty":0.00000000},{"price":5702.50,"qty":0.03080695},{"price":5705.26,"qty":0.52360000}],"asks":[],"checksum":2124258087,"timestamp":"2024-06-01T17:52:12.227218Z"}]}
{"channel":"book","type":"update","data":[{"symbol":"ETH/AUD","bids":[{"price":5705.43,"qty":0.00000000},{"price":5702.47,"qty":7.20823578}],"asks":[],"checksum":4177526029,"timestamp":"2024-06-01T17:52:12.669933Z"}]}
{"channel":"book","type":"update","data":[{"symbol":"ETH/AUD","bids":[{"price":5705.27,"qty":0.00526817}],"asks":[],"checksum":3906195576,"timestamp":"2024-06-01T17:52:12.670706Z"}]}
{"channel":"book","type":"update","data":[{"symbol":"ETH/AUD","bids":[{"price":5709.77,"qty":0.90387105},{"price":5709.78,"qty":0.07347674}],"asks":[],"checksum":3316498856,"timestamp":"2024-06-01T17:52:12.703521Z"}]}
{"channel":"book","type":"update","data":[{"symbol":"ETH/AUD","bids":[{"price":5709.76,"qty":0.00000000},{"price":5703.22,"qty":0.11200000},{"price":5709.79,"qty":1.03775677}],"asks":[],"checksum":1556345187,"timestamp":"2024-06-01T17:52:12.815588Z"}]}
{"channel":"book","type":"update","data":[{"symbol":"ETH/AUD","bids":[],"asks":[{"price":5713.83,"qty":0.90387105}],"checksum":1510393916,"timestamp":"2024-06-01T17:52:13.180352Z"}]}
{"channel":"book","type":"update","data":[{"symbol":"ETH/AUD","bids":[{"price":5709.80,"qty":0.90387105}],"asks":[],"checksum":1417230012,"timestamp":"2024-06-01T17:52:13.180368Z"}]}
{"channel":"book","type":"update","data":[{"symbol":"ETH/AUD","bids":[],"asks":[{"price":5713.87,"qty":0.00000000},{"price":5716.42,"qty":11.18110136}],"checksum":2007968105,"timestamp":"2024-06-01T17:52:13.186282Z"}]}
{"channel":"book","type":"update","data":[{"symbol":"ETH/AUD","bids":[{"price":5709.77,"qty":0.00000000},{"price":5703.38,"qty":0.74672161}],"asks":[],"checksum":3693258559,"timestamp":"2024-06-01T17:52:13.186299Z"}]}
{"channel":"book","type":"update","data":[{"symbol":"ETH/AUD","bids":[{"price":5709.79,"qty":0.00000000},{"price":5703.22,"qty":0.11200000},{"price":5709.81,"qty":1.03775303}],"asks":[],"checksum":2899104373,"timestamp":"2024-06-01T17:52:13.396931Z"}]}
{"channel":"book","type":"update","data":[{"symbol":"ETH/AUD","bids":[],"asks":[{"price":5713.84,"qty":0.00000000},{"price":5719.71,"qty":0.20717085},{"price":5713.82,"qty":0.20816496}],"checksum":1685911517,"timestamp":"2024-06-01T17:52:13.397048Z"}]}
{"channel":"book","type":"update","data":[{"symbol":"ETH/AUD","bids":[{"price":5709.78,"qty":0.00000000},{"price":5703.22,"qty":0.11200000},{"price":5709.82,"qty":0.07347674}],"asks":[],"checksum":365071524,"timestamp":"2024-06-01T17:52:13.404278Z"}]}
{"channel":"book","type":"update","data":[{"symbol":"ETH/AUD","bids":[],"asks":[{"price":5715.82,"qty":0.00000000},{"price":5719.71,"qty":0.20717085}],"checksum":1309264976,"timestamp":"2024-06-01T17:52:13.754540Z"}]}
{"channel":"book","type":"update","data":[{"symbol":"ETH/AUD","bids":[],"asks":[{"price":5715.78,"qty":0.08977490}],"checksum":3027776905,"timestamp":"2024-06-01T17:52:13.756550Z"}]}
{"channel":"book","type":"update","data":[{"symbol":"ETH/AUD","bids":[],"asks":[{"price":5715.79,"qty":10.93029354},{"price":5715.77,"qty":0.52360000}],"checksum":1741322386,"timestamp":"2024-06-01T17:52:13.759627Z"}]}
{"channel":"book","type":"update","data":[{"symbol":"ETH/AUD","bids":[{"price":5709.81,"qty":0.00000000},{"price":5703.22,"qty":0.11200000},{"price":5709.83,"qty":1.03774936}],"asks":[],"checksum":2150550038,"timestamp":"2024-06-01T17:52:13.965053Z"}]}
{"channel":"book","type":"update","data":[{"symbol":"ETH/AUD","bids":[{"price":5709.84,"qty":0.90387105}],"asks":[],"checksum":4292208783,"timestamp":"2024-06-01T17:52:13.970470Z"}]}
{"channel":"book","type":"update","data":[{"symbol":"ETH/AUD","bids":[{"price":5709.82,"qty":0.00000000},{"price":5703.38,"qty":0.74672161},{"price":5709.85,"qty":0.07347674}],"asks":[],"checksum":4037390280,"timestamp":"2024-06-01T17:52:13.982847Z"}]}
{"channel":"book","type":"update","data":[{"symbol":"ETH/AUD","bids":[{"price":5709.84,"qty":0.00000000},{"price":5703.38,"qty":0.74672161}],"asks":[],"checksum":1195318275,"timestamp":"2024-06-01T17:52:14.177343Z"}]}
{"channel":"book","type":"update","data":[{"symbol":"ETH/AUD","bids":[],"asks":[{"price":5715.80,"qty":0.00000000},{"price":5716.42,"qty":11.18110136}],"checksum":507053919,"timestamp":"2024-06-01T17:52:14.475892Z"}]}
{"channel":"book","type":"update","data":[{"symbol":"ETH/AUD","bids":[],"asks":[{"price":5713.85,"qty":0.00000000},{"price":5719.71,"qty":0.20717085},{"price":5713.81,"qty":0.01292326}],"checksum":487891785,"timestamp":"2024-06-01T17:52:14.501600Z"}]}
{"channel":"book","type":"update","data":[{"symbol":"ETH/AUD","bids":[],"asks":[{"price":5713.82,"qty":0.00000000},{"price":5719.71,"qty":0.20717085},{"price":5713.80,"qty":0.20816443}],"checksum":2846238041,"timestamp":"2024-06-01T17:52:14.561754Z"}]}
{"channel":"book","type":"update","data":[{"symbol":"ETH/AUD","bids":[],"asks":[{"price":5716.40,"qty":0.83372964}],"checksum":3848442294,"timestamp":"2024-06-01T17:52:14.593801Z"}]}
{"channel":"book","type":"update","data":[{"symbol":"ETH/AUD","bids":[],"asks":[{"price":5716.41,"qty":0.00000000},{"price":5716.42,"qty":11.18110136}],"checksum":1322784610,"timestamp":"2024-06-01T17:52:14.645351Z"}]}
{"channel":"book","type":"update","data":[{"symbol":"ETH/AUD","bids":[],"asks":[{"price":5715.79,"qty":0.00000000},{"price":5719.71,"qty":0.20717085}],"checksum":1467446548,"timestamp":"2024-06-01T17:52:14.645693Z"}]}
{"channel":"book","type":"update","data":[{"symbol":"ETH/AUD","bids":[],"asks":[{"price":5715.76,"qty":9.88994589}],"checksum":3666244608,"timestamp":"2024-06-01T17:52:14.651009Z"}]}
{"channel":"book","type":"update","data":[{"symbol":"ETH/AUD","bids":[],"asks":[{"price":5716.41,"qty":2.57800993}],"checksum":608982841,"timestamp":"2024-06-01T17:52:14.651046Z"}]}
{"channel":"book","type":"update","data":[{"symbol":"ETH/AUD","bids":[],"asks":[{"price":5715.77,"qty":0.00000000},{"price":5716.42,"qty":11.18110136},{"price":5715.75,"qty":0.52360000}],"checksum":1464679862,"timestamp":"2024-06-01T17:52:14.654086Z"}]}
{"channel":"book","type":"update","data":[{"symbol":"ETH/AUD","bids":[{"price":5709.83,"qty":0.00000000},{"price":5703.22,"qty":0.11200000},{"price":5709.86,"qty":1.03774387}],"asks":[],"checksum":3569917846,"timestamp":"2024-06-01T17:52:15.127380Z"}]}
{"channel":"book","type":"update","data":[{"symbol":"ETH/AUD","bids":[{"price":5709.87,"qty":0.90387105}],"asks":[],"checksum":2069970276,"timestamp":"2024-06-01T17:52:15.133101Z"}]}
{"channel":"book","type":"update","data":[{"symbol":"ETH/AUD","bids":[{"price":5709.85,"qty":0.00000000},{"price":5703.38,"qty":0.74672161},{"price":5709.88,"qty":0.07347674}],"asks":[],"checksum":3094566840,"timestamp":"2024-06-01T17:52:15.144523Z"}]}
{"channel":"book","type":"update","data":[{"symbol":"ETH/AUD","bids":[{"price":5709.87,"qty":0.00000000},{"price":5703.38,"qty":0.74672161}],"asks":[],"checksum":4268391300,"timestamp":"2024-06-01T17:52:15.176715Z"}]}
{"channel":"book","type":"update","data":[{"symbol":"ETH/AUD","bids":[{"price":5705.27,"qty":0.53208520}],"asks":[],"checksum":1283154433,"timestamp":"2024-06-01T17:52:15.230784Z"}]}
{"channel":"book","type":"update","data":[{"symbol":"ETH/AUD","bids":[{"price":5705.26,"qty":0.00000000},{"price":5703.22,"qty":0.11200000},{"price":5705.28,"qty":0.52360000}],"asks":[],"checksum":870073790,"timestamp":"2024-06-01T17:52:15.233959Z"}]}
{"channel":"book","type":"update","data":[{"symbol":"ETH/AUD","bids":[],"asks":[{"price":5716.40,"qty":0.00000000},{"price":5716.84,"qty":6.22832015}],"checksum":790037425,"timestamp":"2024-06-01T17:52:15.533819Z"}]}
{"channel":"book","type":"update","data":[{"symbol":"ETH/AUD","bids":[],"asks":[{"price":5716.53,"qty":0.83372964}],"checksum":3526453284,"timestamp":"2024-06-01T17:52:15.566455Z"}]}
{"channel":"book","type":"update","data":[{"symbol":"ETH/AUD","bids":[],"asks":[{"price":5714.15,"qty":0.00000000},{"price":5716.84,"qty":6.22832015},{"price":5714.61,"qty":0.06654800}],"checksum":3079529567,"timestamp":"2024-06-01T17:52:15.578365Z"}]}
{"channel":"book","type":"update","data":[{"symbol":"ETH/AUD","bids":[{"price":5705.27,"qty":0.52681703}],"asks":[],"checksum":1857553436,"timestamp":"2024-06-01T17:52:15.605679Z"}]}
{"channel":"book","type":"update","data":[{"symbol":"ETH/AUD","bids":[{"price":5705.29,"qty":0.04634470}],"asks":[],"checksum":26681034,"timestamp":"2024-06-01T17:52:15.607267Z"}]}
{"channel":"book","type":"update","data":[{"symbol":"ETH/AUD","bids":[],"asks":[{"price":5713.81,"qty":0.00000000},{"price":5716.84,"qty":6.22832015},{"price":5713.79,"qty":0.01292326}],"checksum":3426139993,"timestamp":"2024-06-01T17:52:15.610260Z"}]}
{"channel":"book","type":"update","data":[{"symbol":"ETH/AUD","bids":[],"asks":[{"price":5715.78,"qty":0.00000000},{"price":5716.84,"qty":6.22832015}],"checksum":1531928051,"timestamp":"2024-06-01T17:52:15.712368Z"}]}
{"channel":"book","type":"update","data":[{"symbol":"ETH/AUD","bids":[],"asks":[{"price":5713.80,"qty":0.00000000},{"price":5719.71,"qty":0.20717085},{"price":5713.78,"qty":0.20543318}],"checksum":2598494525,"timestamp":"2024-06-01T17:52:15.726245Z"}]}
{"channel":"book","type":"update","data":[{"symbol":"ETH/AUD","bids":[{"price":5709.86,"qty":0.00000000},{"price":5703.38,"qty":0.74672161},{"price":5709.89,"qty":1.03773792}],"asks":[],"checksum":3303246723,"timestamp":"2024-06-01T17:52:15.726278Z"}]}
{"channel":"book","type":"update","data":[{"symbol":"ETH/AUD","bids":[],"asks":[{"price":5716.53,"qty":0.00000000},{"price":5719.71,"qty":0.20717085}],"checksum":3686811806,"timestamp":"2024-06-01T17:52:15.737209Z"}]}
{"channel":"book","type":"update","data":[{"symbol":"ETH/AUD","bids":[],"asks":[{"price":5716.83,"qty":0.83372964}],"checksum":2005429996,"timestamp":"2024-06-01T17:52:15.768447Z"}]}
{"channel":"book","type":"update","data":[{"symbol":"ETH/AUD","bids":[],"asks":[{"price":5715.74,"qty":0.06316257}],"checksum":3341309608,"timestamp":"2024-06-01T17:52:16.165392Z"}]}
{"channel":"book","type":"update","data":[{"symbol":"ETH/AUD","bids":[{"price":5709.90,"qty":0.90387105}],"asks":[],"checksum":1171252903,"timestamp":"2024-06-01T17:52:16.175832Z"}]}
{"channel":"book","type":"update","data":[{"symbol":"ETH/AUD","bids":[],"asks":[{"price":5713.77,"qty":0.90387105}],"checksum":1169596658,"timestamp":"2024-06-01T17:52:16.175848Z"}]}
{"channel":"book","type":"update","data":[{"symbol":"ETH/AUD","bids":[{"price":5709.80,"qty":0.00000000},{"price":5705.25,"qty":1.60677000}],"asks":[],"checksum":3839893310,"timestamp":"2024-06-01T17:52:16.181484Z"}]}
{"channel":"book","type":"update","data":[{"symbol":"ETH/AUD","bids":[],"asks":[{"price":5713.83,"qty":0.00000000},{"price":5716.83,"qty":0.83372964}],"checksum":1807967697,"timestamp":"2024-06-01T17:52:16.181711Z"}]}
{"channel":"book","type":"update","data":[{"symbol":"ETH/AUD","bids":[{"price":5709.88,"qty":0.00000000},{"price":5703.38,"qty":0.74672161},{"price":5709.91,"qty":0.07347674}],"asks":[],"checksum":946973701,"timestamp":"2024-06-01T17:52:16.190214Z"}]}
{"channel":"book","type":"update","data":[{"symbol":"ETH/AUD","bids":[{"price":5709.89,"qty":0.00000000},{"price":5703.38,"qty":0.74672161},{"price":5709.92,"qty":1.03773233}],"asks":[],"checksum":3962807699,"timestamp":"2024-06-01T17:52:16.302862Z"}]}
{"channel":"book","type":"update","data":[{"symbol":"ETH/AUD","bids":[],"asks":[{"price":5713.78,"qty":0.00000000},{"price":5716.84,"qty":6.22832015},{"price":5713.76,"qty":0.20543317}],"checksum":3410269517,"timestamp":"2024-06-01T17:52:16.302956Z"}]}
{"channel":"book","type":"update","data":[{"symbol":"ETH/AUD","bids":[{"price":5709.91,"qty":0.00000000},{"price":5703.38,"qty":0.74672161},{"price":5709.93,"qty":0.07347674}],"asks":[],"checksum":2025216638,"timestamp":"2024-06-01T17:52:16.917729Z"}]}
{"channel":"book","type":"update","data":[{"symbol":"ETH/AUD","bids":[],"asks":[{"price":5713.75,"qty":0.90387105}],"checksum":3144328245,"timestamp":"2024-06-01T17:52:16.923156Z"}]}
{"channel":"book","type":"update","data":[{"symbol":"ETH/AUD","bids":[{"price":5709.92,"qty":0.00000000},{"price":5703.38,"qty":0.74672161},{"price":5709.94,"qty":1.03773847}],"asks":[],"checksum":75366685,"timestamp":"2024-06-01T17:52:16.965464Z"}]}
{"channel":"book","type":"update","data":[{"symbol":"ETH/AUD","bids":[],"asks":[{"price":5713.77,"qty":0.00000000},{"price":5716.83,"qty":0.83372964}],"checksum":3827379223,"timestamp":"2024-06-01T17:52:16.971303Z"}]}
{"channel":"book","type":"update","data":[{"symbol":"ETH/AUD","bids":[],"asks":[{"price":5716.41,"qty":0.00000000},{"price":5716.84,"qty":6.22832015}],"checksum":2233880731,"timestamp":"2024-06-01T17:52:17.027846Z"}]}
{"channel":"book","type":"update","data":[{"symbol":"ETH/AUD","bids":[],"asks":[{"price":5715.76,"qty":0.00000000},{"price":5719.71,"qty":0.20717085}],"checksum":497212053,"timestamp":"2024-06-01T17:52:17.027992Z"}]}
{"channel":"book","type":"update","data":[{"symbol":"ETH/AUD","bids":[],"asks":[{"price":5716.82,"qty":11.97055685}],"checksum":3467898143,"timestamp":"2024-06-01T17:52:17.033784Z"}]}
{"channel":"book","type":"update","data":[{"symbol":"ETH/AUD","bids":[],"asks":[{"price":5715.75,"qty":0.00000000},{"price":5719.71,"qty":0.20717085},{"price":5716.81,"qty":0.52360000}],"checksum":2568100833,"timestamp":"2024-06-01T17:52:17.036590Z"}]}
{"channel":"book","type":"update","data":[{"symbol":"ETH/AUD","bids":[{"price":5709.95,"qty":0.00989179}],"asks":[],"checksum":2511595360,"timestamp":"2024-06-01T17:52:17.190021Z"}]}
{"channel":"book","type":"update","data":[{"symbol":"ETH/AUD","bids":[{"price":5709.38,"qty":0.00000000},{"price":5705.25,"qty":1.60677000}],"asks":[],"checksum":1407630761,"timestamp":"2024-06-01T17:52:17.192934Z"}]}
{"channel":"book","type":"update","data":[{"symbol":"ETH/AUD","bids":[{"price":5709.95,"qty":3.34083714}],"asks":[],"checksum":1314107506,"timestamp":"2024-06-01T17:52:17.197610Z"}]}
{"channel":"book","type":"update","data":[{"symbol":"ETH/AUD","bids":[{"price":5709.15,"qty":0.00000000},{"price":5703.38,"qty":0.74672161}],"asks":[],"checksum":1210658558,"timestamp":"2024-06-01T17:52:17.362281Z"}]}
{"channel":"book","type":"update","data":[{"symbol":"ETH/AUD","bids":[{"price":5709.93,"qty":0.00000000},{"price":5703.22,"qty":0.11200000},{"price":5709.96,"qty":0.07347674}],"asks":[],"checksum":4066315115,"timestamp":"2024-06-01T17:52:17.379866Z"}]}
{"channel":"book","type":"update","data":[{"symbol":"ETH/AUD","bids":[],"asks":[{"price":5713.76,"qty":0.00000000},{"price":5719.71,"qty":0.20717085},{"price":5713.74,"qty":0.20544602}],"checksum":573506826,"timestamp":"2024-06-01T17:52:17.570689Z"}]}
{"channel":"book","type":"update","data":[{"symbol":"ETH/AUD","bids":[{"price":5709.94,"qty":0.00000000},{"price":5703.22,"qty":0.11200000},{"price":5709.97,"qty":1.03773364}],"asks":[],"checksum":2856181378,"timestamp":"2024-06-01T17:52:17.570741Z"}]}
{"channel":"book","type":"update","data":[{"symbol":"ETH/AUD","bids":[{"price":5709.98,"qty":0.90387105}],"asks":[],"checksum":618675050,"timestamp":"2024-06-01T17:52:18.175732Z"}]}
{"channel":"book","type":"update","data":[{"symbol":"ETH/AUD","bids":[{"price":5709.90,"qty":0.00000000},{"price":5703.38,"qty":0.74672161}],"asks":[],"checksum":2694361977,"timestamp":"2024-06-01T17:52:18.180162Z"}]}
{"channel":"book","type":"update","data":[{"symbol":"ETH/AUD","bids":[{"price":5709.96,"qty":0.00000000},{"price":5703.22,"qty":0.11200000},{"price":5709.99,"qty":0.07347674}],"asks":[],"checksum":4047555692,"timestamp":"2024-06-01T17:52:18.199638Z"}]}
{"channel":"book","type":"update","data":[{"symbol":"ETH/AUD","bids":[{"price":5705.27,"qty":0.00000000},{"price":5703.22,"qty":0.11200000}],"asks":[],"checksum":441262992,"timestamp":"2024-06-01T17:52:18.223178Z"}]}
{"channel":"book","type":"update","data":[{"symbol":"ETH/AUD","bids":[{"price":5705.30,"qty":1.55451652}],"asks":[],"checksum":1002474658,"timestamp":"2024-06-01T17:52:18.224631Z"}]}
{"channel":"book","type":"update","data":[{"symbol":"ETH/AUD","bids":[{"price":5703.39,"qty":3.09617304}],"asks":[],"checksum":3174979666,"timestamp":"2024-06-01T17:52:18.224718Z"}]}
{"channel":"book","type":"update","data":[{"symbol":"ETH/AUD","bids":[{"price":5705.28,"qty":0.00000000},{"price":5703.38,"qty":0.74672161},{"price":5705.26,"qty":0.52360000}],"asks":[],"checksum":3634507886,"timestamp":"2024-06-01T17:52:18.226240Z"}]}
{"channel":"book","type":"update","data":[{"symbol":"ETH/AUD","bids":[{"price":5709.97,"qty":0.00000000},{"price":5703.38,"qty":0.74672161},{"price":5709.99,"qty":1.11120716}],"asks":[],"checksum":2468911619,"timestamp":"2024-06-01T17:52:18.232582Z"}]}
{"channel":"book","type":"update","data":[{"symbol":"ETH/AUD","bids":[{"price":5703.38,"qty":0.00000000},{"price":5703.22,"qty":0.11200000}],"asks":[],"checksum":3736401449,"timestamp":"2024-06-01T17:52:18.254085Z"}]}
{"channel":"book","type":"update","data":[{"symbol":"ETH/AUD","bids":[{"price":5703.40,"qty":0.74671900}],"asks":[],"checksum":6283025,"timestamp":"2024-06-01T17:52:18.254152Z"}]}
{"channel":"book","type":"update","data":[{"symbol":"ETH/AUD","bids":[],"asks":[{"price":5715.74,"qty":0.00000000},{"price":5719.71,"qty":0.20717085}],"checksum":2807985901,"timestamp":"2024-06-01T17:52:18.498887Z"}]}
{"channel":"book","type":"update","data":[{"symbol":"ETH/AUD","bids":[],"asks":[{"price":5716.80,"qty":0.10247051}],"checksum":1653336896,"timestamp":"2024-06-01T17:52:18.501291Z"}]}
{"channel":"book","type":"update","data":[{"symbol":"ETH/AUD","bids":[],"asks":[{"price":5716.81,"qty":0.00000000},{"price":5719.71,"qty":0.20717085},{"price":5716.79,"qty":0.52360000}],"checksum":109129068,"timestamp":"2024-06-01T17:52:18.504597Z"}]}
{"channel":"book","type":"update","data":[{"symbol":"ETH/AUD","bids":[],"asks":[{"price":5713.79,"qty":0.00000000},{"price":5719.71,"qty":0.20717085},{"price":5713.73,"qty":0.01292326}],"checksum":1290839849,"timestamp":"2024-06-01T17:52:18.507834Z"}]}
{"channel":"book","type":"update","data":[{"symbol":"ETH/AUD","bids":[{"price":5705.29,"qty":0.00000000},{"price":5703.22,"qty":0.11200000}],"asks":[],"checksum":987268622,"timestamp":"2024-06-01T17:52:18.607171Z"}]}
{"channel":"book","type":"update","data":[{"symbol":"ETH/AUD","bids":[{"price":5705.31,"qty":0.04637946}],"asks":[],"checksum":3872703890,"timestamp":"2024-06-01T17:52:18.607675Z"}]}
{"channel":"book","type":"update","data":[{"symbol":"ETH/AUD","bids":[],"asks":[{"price":5716.83,"qty":0.00000000},{"price":5719.71,"qty":0.20717085}],"checksum":4242717977,"timestamp":"2024-06-01T17:52:18.807283Z"}]}
{"channel":"book","type":"update","data":[{"symbol":"ETH/AUD","bids":[{"price":5705.26,"qty":0.00000000},{"price":5703.22,"qty":0.11200000},{"price":5705.31,"qty":0.56997946}],"asks":[],"checksum":3437291817,"timestamp":"2024-06-01T17:52:18.810422Z"}]}
{"channel":"book","type":"update","data":[{"symbol":"ETH/AUD","bids":[],"asks":[{"price":5716.78,"qty":0.83372964}],"checksum":2054493112,"timestamp":"2024-06-01T17:52:18.838936Z"}]}
{"channel":"book","type":"update","data":[{"symbol":"ETH/AUD","bids":[{"price":5709.99,"qty":0.07347674},{"price":5710.00,"qty":1.03772860}],"asks":[],"checksum":3568041389,"timestamp":"2024-06-01T17:52:18.864157Z"}]}
{"channel":"book","type":"update","data":[{"symbol":"ETH/AUD","bids":[],"asks":[{"price":5713.74,"qty":0.00000000},{"price":5719.71,"qty":0.20717085},{"price":5713.72,"qty":0.20544770}],"checksum":1022196550,"timestamp":"2024-06-01T17:52:18.864262Z"}]}
{"channel":"book","type":"update","data":[{"symbol":"ETH/AUD","bids":[],"asks":[{"price":5716.79,"qty":0.00000000},{"price":5719.71,"qty":0.20717085},{"price":5716.77,"qty":0.52360000}],"checksum":3884864731,"timestamp":"2024-06-01T17:52:19.043593Z"}]}
{"channel":"book","type":"update","data":[{"symbol":"ETH/AUD","bids":[],"asks":[{"price":5713.71,"qty":0.90387105}],"checksum":1778797523,"timestamp":"2024-06-01T17:52:19.176367Z"}]}
{"channel":"book","type":"update","data":[{"symbol":"ETH/AUD","bids":[{"price":5710.01,"qty":0.90387105}],"asks":[],"checksum":3379582457,"timestamp":"2024-06-01T17:52:19.176522Z"}]}
{"channel":"book","type":"update","data":[{"symbol":"ETH/AUD","bids":[],"asks":[{"price":5713.75,"qty":0.00000000},{"price":5716.84,"qty":6.22832015}],"checksum":1495005667,"timestamp":"2024-06-01T17:52:19.181640Z"}]}
{"channel":"book","type":"update","data":[{"symbol":"ETH/AUD","bids":[{"price":5709.98,"qty":0.00000000},{"price":5703.39,"qty":3.09617304}],"asks":[],"checksum":3254176051,"timestamp":"2024-06-01T17:52:19.181670Z"}]}
{"channel":"book","type":"update","data":[{"symbol":"ETH/AUD","bids":[{"price":5709.99,"qty":0.00000000},{"price":5703.22,"qty":0.11200000},{"price":5710.02,"qty":0.07347674}],"asks":[],"checksum":2410824191,"timestamp":"2024-06-01T17:52:19.212316Z"}]}
{"channel":"book","type":"update","data":[{"symbol":"ETH/AUD","bids":[],"asks":[{"price":5716.82,"qty":0.00000000},{"price":5719.71,"qty":0.20717085}],"checksum":3677058672,"timestamp":"2024-06-01T17:52:19.428879Z"}]}
{"channel":"book","type":"update","data":[{"symbol":"ETH/AUD","bids":[],"asks":[{"price":5716.76,"qty":13.01093118}],"checksum":2131091128,"timestamp":"2024-06-01T17:52:19.433913Z"}]}
{"channel":"book","type":"update","data":[{"symbol":"ETH/AUD","bids":[{"price":5710.00,"qty":0.00000000},{"price":5703.22,"qty":0.11200000},{"price":5710.03,"qty":1.03772182}],"asks":[],"checksum":2359463967,"timestamp":"2024-06-01T17:52:19.491535Z"}]}
{"channel":"book","type":"update","data":[{"symbol":"ETH/AUD","bids":[],"asks":[{"price":5713.72,"qty":0.00000000},{"price":5719.71,"qty":0.20717085},{"price":5713.70,"qty":0.20544757}],"checksum":3436949268,"timestamp":"2024-06-01T17:52:19.491632Z"}]}
{"channel":"book","type":"update","data":[{"symbol":"ETH/AUD","bids":[{"price":5710.02,"qty":0.00000000},{"price":5703.22,"qty":0.11200000},{"price":5709.67,"qty":0.07347674}],"asks":[],"checksum":808232280,"timestamp":"2024-06-01T17:52:19.732510Z"}]}
{"channel":"book","type":"update","data":[{"symbol":"ETH/AUD","bids":[],"asks":[{"price":5716.77,"qty":0.00000000},{"price":5719.71,"qty":0.20717085},{"price":5716.75,"qty":0.52360000}],"checksum":1780506176,"timestamp":"2024-06-01T17:52:19.735546Z"}]}
{"channel":"book","type":"update","data":[{"symbol":"ETH/AUD","bids":[{"price":5710.03,"qty":0.00000000},{"price":5703.22,"qty":0.11200000},{"price":5710.02,"qty":1.03772350}],"asks":[],"checksum":585414035,"timestamp":"2024-06-01T17:52:19.797358Z"}]}
{"channel":"book","type":"update","data":[{"symbol":"ETH/AUD","bids":[],"asks":[{"price":5713.69,"qty":0.90387105}],"checksum":1191411441,"timestamp":"2024-06-01T17:52:20.175815Z"}]}
{"channel":"book","type":"update","data":[{"symbol":"ETH/AUD","bids":[],"asks":[{"price":5713.70,"qty":0.00000000},{"price":5716.84,"qty":6.22832015},{"price":5713.68,"qty":0.20545256}],"checksum":4264624079,"timestamp":"2024-06-01T17:52:20.236381Z"}]}
{"channel":"book","type":"update","data":[{"symbol":"ETH/AUD","bids":[],"asks":[{"price":5713.71,"qty":0.00000000},{"price":5716.84,"qty":6.22832015}],"checksum":2416656995,"timestamp":"2024-06-01T17:52:20.241803Z"}]}
{"channel":"book","type":"update","data":[{"symbol":"ETH/AUD","bids":[],"asks":[{"price":5713.73,"qty":0.00000000},{"price":5719.71,"qty":0.20717085},{"price":5713.67,"qty":0.01292326}],"checksum":3514184179,"timestamp":"2024-06-01T17:52:20.257608Z"}]}
{"channel":"book","type":"update","data":[{"symbol":"ETH/AUD","bids":[],"asks":[{"price":5716.80,"qty":0.00000000},{"price":5719.71,"qty":0.20717085}],"checksum":1149910363,"timestamp":"2024-06-01T17:52:20.860884Z"}]}
{"channel":"book","type":"update","data":[{"symbol":"ETH/AUD","bids":[],"asks":[{"price":5716.74,"qty":0.09952502}],"checksum":9756305,"timestamp":"2024-06-01T17:52:20.864103Z"}]}
{"channel":"book","type":"update","data":[{"symbol":"ETH/AUD","bids":[],"asks":[{"price":5716.75,"qty":0.00000000},{"price":5719.71,"qty":0.20717085},{"price":5716.73,"qty":0.52360000}],"checksum":2744775494,"timestamp":"2024-06-01T17:52:20.867322Z"}]}
{"channel":"book","type":"update","data":[{"symbol":"ETH/AUD","bids":[],"asks":[{"price":5713.68,"qty":0.00000000},{"price":5719.71,"qty":0.20717085},{"price":5713.66,"qty":0.20545256}],"checksum":625782269,"timestamp":"2024-06-01T17:52:20.910733Z"}]}
{"channel":"book","type":"update","data":[{"symbol":"ETH/AUD","bids":[],"asks":[{"price":5713.65,"qty":0.90387105}],"checksum":3831365845,"timestamp":"2024-06-01T17:52:20.916270Z"}]}
{"channel":"book","type":"update","data":[{"symbol":"ETH/AUD","bids":[],"asks":[{"price":5713.67,"qty":0.00000000},{"price":5716.84,"qty":6.22832015},{"price":5713.64,"qty":0.01292326}],"checksum":2489223200,"timestamp":"2024-06-01T17:52:20.930194Z"}]}
{"channel":"book","type":"update","data":[{"symbol":"ETH/AUD","bids":[],"asks":[{"price":5713.69,"qty":0.00000000},{"price":5716.84,"qty":6.22832015}],"checksum":1652202596,"timestamp":"2024-06-01T17:52:21.178794Z"}]}
{"channel":"book","type":"update","data":[{"symbol":"ETH/AUD","bids":[{"price":5705.30,"qty":0.00000000},{"price":5703.22,"qty":0.11200000}],"asks":[],"checksum":1602744656,"timestamp":"2024-06-01T17:52:21.222739Z"}]}
{"channel":"book","type":"update","data":[{"symbol":"ETH/AUD","bids":[{"price":5703.39,"qty":0.00000000},{"price":5702.47,"qty":3.55924648}],"asks":[],"checksum":2782324358,"timestamp":"2024-06-01T17:52:21.222749Z"}]}
{"channel":"book","type":"update","data":[{"symbol":"ETH/AUD","bids":[{"price":5702.47,"qty":0.00000000},{"price":5702.46,"qty":2.35323000}],"asks":[],"checksum":3380001319,"timestamp":"2024-06-01T17:52:21.222937Z"}]}
{"channel":"book","type":"update","data":[{"symbol":"ETH/AUD","bids":[{"price":5703.41,"qty":2.58229773}],"asks":[],"checksum":3355187100,"timestamp":"2024-06-01T17:52:21.224675Z"}]}
{"channel":"book","type":"update","data":[{"symbol":"ETH/AUD","bids":[{"price":5705.32,"qty":2.06841020}],"asks":[],"checksum":1451284978,"timestamp":"2024-06-01T17:52:21.224850Z"}]}
{"channel":"book","type":"update","data":[{"symbol":"ETH/AUD","bids":[{"price":5705.31,"qty":0.04637946},{"price":5705.26,"qty":0.52360000}],"asks":[],"checksum":1992037224,"timestamp":"2024-06-01T17:52:21.225679Z"}]}
{"channel":"book","type":"update","data":[{"symbol":"ETH/AUD","bids":[{"price":5703.42,"qty":0.74671637}],"asks":[],"checksum":927822487,"timestamp":"2024-06-01T17:52:21.244646Z"}]}
{"channel":"book","type":"update","data":[{"symbol":"ETH/AUD","bids":[{"price":5705.31,"qty":0.00000000},{"price":5703.41,"qty":2.58229773}],"asks":[],"checksum":1787274999,"timestamp":"2024-06-01T17:52:21.557638Z"}]}
{"channel":"book","type":"update","data":[{"symbol":"ETH/AUD","bids":[{"price":5705.33,"qty":0.04702047}],"asks":[],"checksum":1452093214,"timestamp":"2024-06-01T17:52:21.558439Z"}]}
{"channel":"book","type":"update","data":[{"symbol":"ETH/AUD","bids":[{"price":5709.67,"qty":0.00000000},{"price":5703.41,"qty":2.58229773},{"price":5710.03,"qty":0.07347674}],"asks":[],"checksum":3143603780,"timestamp":"2024-06-01T17:52:21.568760Z"}]}
{"channel":"book","type":"update","data":[{"symbol":"ETH/AUD","bids":[{"price":5710.02,"qty":0.00000000},{"price":5703.41,"qty":2.58229773},{"price":5710.04,"qty":1.03773414}],"asks":[],"checksum":2231380133,"timestamp":"2024-06-01T17:52:21.618239Z"}]}
{"channel":"book","type":"update","data":[{"symbol":"ETH/AUD","bids":[],"asks":[{"price":5713.66,"qty":0.00000000},{"price":5719.71,"qty":0.20717085},{"price":5713.63,"qty":0.20545300}],"checksum":3637685089,"timestamp":"2024-06-01T17:52:21.618328Z"}]}
{"channel":"book","type":"update","data":[{"symbol":"ETH/AUD","bids":[],"asks":[{"price":5716.76,"qty":0.00000000},{"price":5719.71,"qty":0.20717085}],"checksum":331104730,"timestamp":"2024-06-01T17:52:21.848110Z"}]}
{"channel":"book","type":"update","data":[{"symbol":"ETH/AUD","bids":[{"price":5705.26,"qty":0.00000000},{"price":5703.41,"qty":2.58229773},{"price":5705.33,"qty":0.57062047}],"asks":[],"checksum":548274465,"timestamp":"2024-06-01T17:52:21.851322Z"}]}
{"channel":"book","type":"update","data":[{"symbol":"ETH/AUD","bids":[],"asks":[{"price":5716.72,"qty":12.19001672}],"checksum":1640986790,"timestamp":"2024-06-01T17:52:21.852604Z"}]}
{"channel":"book","type":"update","data":[{"symbol":"ETH/AUD","bids":[],"asks":[{"price":5716.73,"qty":0.00000000},{"price":5719.71,"qty":0.20717085},{"price":5716.71,"qty":0.52360000}],"checksum":2081553640,"timestamp":"2024-06-01T17:52:21.856000Z"}]}
{"channel":"book","type":"update","data":[{"symbol":"ETH/AUD","bids":[{"price":5710.03,"qty":0.00000000},{"price":5703.22,"qty":0.11200000}],"asks":[],"checksum":3598721749,"timestamp":"2024-06-01T17:52:21.874580Z"}]}
{"channel":"book","type":"update","data":[{"symbol":"ETH/AUD","bids":[],"asks":[{"price":5716.78,"qty":0.00000000},{"price":5719.71,"qty":0.20717085}],"checksum":3703730605,"timestamp":"2024-06-01T17:52:21.882831Z"}]}
{"channel":"book","type":"update","data":[{"symbol":"ETH/AUD","bids":[],"asks":[{"price":5716.70,"qty":0.83372964}],"checksum":1483238724,"timestamp":"2024-06-01T17:52:21.914306Z"}]}
{"channel":"book","type":"update","data":[{"symbol":"ETH/AUD","bids":[{"price":5710.04,"qty":0.00000000},{"price":5702.47,"qty":3.05039144},{"price":5710.02,"qty":1.03773785}],"asks":[],"checksum":957922851,"timestamp":"2024-06-01T17:52:21.995231Z"}]}
{"channel":"book","type":"update","data":[{"symbol":"ETH/AUD","bids":[],"asks":[{"price":5713.62,"qty":0.90387105}],"checksum":3657089539,"timestamp":"2024-06-01T17:52:22.001890Z"}]}
{"channel":"book","type":"update","data":[{"symbol":"ETH/AUD","bids":[{"price":5710.03,"qty":0.90387105}],"asks":[],"checksum":148278191,"timestamp":"2024-06-01T17:52:22.001979Z"}]}
{"channel":"book","type":"update","data":[{"symbol":"ETH/AUD","bids":[{"price":5710.05,"qty":0.02240961}],"asks":[],"checksum":3628387252,"timestamp":"2024-06-01T17:52:22.016718Z"}]}
{"channel":"book","type":"update","data":[{"symbol":"ETH/AUD","bids":[],"asks":[{"price":5713.65,"qty":0.00000000},{"price":5716.84,"qty":6.22832015}],"checksum":2009904781,"timestamp":"2024-06-01T17:52:22.179199Z"}]}
{"channel":"book","type":"update","data":[{"symbol":"ETH/AUD","bids":[{"price":5710.01,"qty":0.00000000},{"price":5703.41,"qty":2.58229773}],"asks":[],"checksum":3476350723,"timestamp":"2024-06-01T17:52:22.179395Z"}]}
{"channel":"book","type":"update","data":[{"symbol":"ETH/AUD","bids":[{"price":5709.95,"qty":3.33094535}],"asks":[],"checksum":1878996351,"timestamp":"2024-06-01T17:52:22.182315Z"}]}
{"channel":"book","type":"update","data":[{"symbol":"ETH/AUD","bids":[{"price":5710.02,"qty":0.00000000},{"price":5703.22,"qty":0.11200000},{"price":5710.06,"qty":1.03773058}],"asks":[],"checksum":1644665733,"timestamp":"2024-06-01T17:52:22.321429Z"}]}
{"channel":"book","type":"update","data":[{"symbol":"ETH/AUD","bids":[{"price":5710.07,"qty":0.07347674}],"asks":[],"checksum":1970937522,"timestamp":"2024-06-01T17:52:22.333921Z"}]}
{"channel":"book","type":"update","data":[{"symbol":"ETH/AUD","bids":[],"asks":[{"price":5713.64,"qty":0.00000000},{"price":5719.71,"qty":0.20717085},{"price":5713.61,"qty":0.01292326}],"checksum":3415712152,"timestamp":"2024-06-01T17:52:22.971312Z"}]}
{"channel":"book","type":"update","data":[{"symbol":"ETH/AUD","bids":[],"asks":[{"price":5716.71,"qty":0.00000000},{"price":5719.71,"qty":0.20717085},{"price":5716.69,"qty":0.52360000}],"checksum":3906177122,"timestamp":"2024-06-01T17:52:22.974207Z"}]}
{"channel":"book","type":"update","data":[{"symbol":"ETH/AUD","bids":[{"price":5710.08,"qty":0.90387105}],"asks":[],"checksum":2929023187,"timestamp":"2024-06-01T17:52:22.976762Z"}]}
{"channel":"book","type":"update","data":[{"symbol":"ETH/AUD","bids":[],"asks":[{"price":5713.63,"qty":0.00000000},{"price":5719.71,"qty":0.20717085},{"price":5713.61,"qty":0.21837636}],"checksum":660078316,"timestamp":"2024-06-01T17:52:23.010129Z"}]}
{"channel":"book","type":"update","data":[{"symbol":"ETH/AUD","bids":[{"price":5710.06,"qty":0.00000000},{"price":5703.42,"qty":0.74671637},{"price":5710.08,"qty":1.94157163}],"asks":[],"checksum":3970373844,"timestamp":"2024-06-01T17:52:23.010232Z"}]}
{"channel":"book","type":"update","data":[{"symbol":"ETH/AUD","bids":[{"price":5710.03,"qty":0.00000000},{"price":5703.41,"qty":2.58229773}],"asks":[],"checksum":756989202,"timestamp":"2024-06-01T17:52:23.016121Z"}]}
{"channel":"book","type":"update","data":[{"symbol":"ETH/AUD","bids":[],"asks":[{"price":5716.74,"qty":0.00000000},{"price":5719.72,"qty":0.08600000}],"checksum":4127834801,"timestamp":"2024-06-01T17:52:23.070442Z"}]}
{"channel":"book","type":"update","data":[{"symbol":"ETH/AUD","bids":[],"asks":[{"price":5716.69,"qty":0.61662442}],"checksum":2858583106,"timestamp":"2024-06-01T17:52:23.071916Z"}]}
{"channel":"book","type":"update","data":[{"symbol":"ETH/AUD","bids":[{"price":5710.07,"qty":0.00000000},{"price":5703.22,"qty":0.11200000},{"price":5710.09,"qty":0.07347674}],"asks":[],"checksum":2269347519,"timestamp":"2024-06-01T17:52:23.489597Z"}]}
{"channel":"book","type":"update","data":[{"symbol":"ETH/AUD","bids":[],"asks":[{"price":5713.61,"qty":0.01292326},{"price":5713.60,"qty":0.20550270}],"checksum":323779539,"timestamp":"2024-06-01T17:52:23.777807Z"}]}
{"channel":"book","type":"update","data":[{"symbol":"ETH/AUD","bids":[{"price":5710.08,"qty":0.90387105},{"price":5710.10,"qty":1.03768942}],"asks":[],"checksum":2542032501,"timestamp":"2024-06-01T17:52:23.777866Z"}]}
{"channel":"book","type":"update","data":[{"symbol":"ETH/AUD","bids":[{"price":5710.09,"qty":0.00000000},{"price":5703.41,"qty":2.58229773},{"price":5710.11,"qty":0.07347674}],"asks":[],"checksum":3871761546,"timestamp":"2024-06-01T17:52:24.098022Z"}]}
{"channel":"book","type":"update","data":[{"symbol":"ETH/AUD","bids":[{"price":5710.12,"qty":0.90387105}],"asks":[],"checksum":1111161180,"timestamp":"2024-06-01T17:52:24.104017Z"}]}
{"channel":"book","type":"update","data":[{"symbol":"ETH/AUD","bids":[{"price":5710.08,"qty":0.00000000},{"price":5703.42,"qty":0.74671637}],"asks":[],"checksum":3894168485,"timestamp":"2024-06-01T17:52:24.178035Z"}]}
{"channel":"book","type":"update","data":[{"symbol":"ETH/AUD","bids":[{"price":5705.32,"qty":0.00000000},{"price":5703.22,"qty":0.11200000}],"asks":[],"checksum":3275768207,"timestamp":"2024-06-01T17:52:24.210611Z"}]}
{"channel":"book","type":"update","data":[{"symbol":"ETH/AUD","bids":[{"price":5705.34,"qty":2.58221681}],"asks":[],"checksum":2445389880,"timestamp":"2024-06-01T17:52:24.211299Z"}]}
{"channel":"book","type":"update","data":[{"symbol":"ETH/AUD","bids":[{"price":5705.33,"qty":0.04702047},{"price":5705.35,"qty":0.52360000}],"asks":[],"checksum":1007469260,"timestamp":"2024-06-01T17:52:24.214294Z"}]}
{"channel":"book","type":"update","data":[{"symbol":"ETH/AUD","bids":[],"asks":[{"price":5716.72,"qty":0.00000000},{"price":5719.72,"qty":0.08600000}],"checksum":3788661500,"timestamp":"2024-06-01T17:52:24.254313Z"}]}
{"channel":"book","type":"update","data":[{"symbol":"ETH/AUD","bids":[],"asks":[{"price":5716.83,"qty":10.93020843}],"checksum":246916899,"timestamp":"2024-06-01T17:52:24.259025Z"}]}
{"channel":"book","type":"update","data":[{"symbol":"ETH/AUD","bids":[{"price":5709.66,"qty":0.00000000},{"price":5703.42,"qty":0.74671637},{"price":5710.12,"qty":0.97044705}],"asks":[],"checksum":1805331866,"timestamp":"2024-06-01T17:52:24.272695Z"}]}
{"channel":"book","type":"update","data":[{"symbol":"ETH/AUD","bids":[],"asks":[{"price":5716.84,"qty":0.00000000},{"price":5719.72,"qty":0.08600000}],"checksum":2130515885,"timestamp":"2024-06-01T17:52:24.400789Z"}]}
{"channel":"book","type":"update","data":[{"symbol":"ETH/AUD","bids":[],"asks":[{"price":5717.11,"qty":11.18077799}],"checksum":2286414740,"timestamp":"2024-06-01T17:52:24.404632Z"}]}
{"channel":"book","type":"update","data":[{"symbol":"ETH/AUD","bids":[],"asks":[{"price":5716.70,"qty":0.00000000},{"price":5719.72,"qty":0.08600000}],"checksum":732858938,"timestamp":"2024-06-01T17:52:24.504296Z"}]}
{"channel":"book","type":"update","data":[{"symbol":"ETH/AUD","bids":[{"price":5705.33,"qty":0.00000000},{"price":5703.22,"qty":0.11200000}],"asks":[],"checksum":836798733,"timestamp":"2024-06-01T17:52:24.515633Z"}]}
{"channel":"book","type":"update","data":[{"symbol":"ETH/AUD","bids":[{"price":5705.36,"qty":0.05247925}],"asks":[],"checksum":1846233992,"timestamp":"2024-06-01T17:52:24.517181Z"}]}
{"channel":"book","type":"update","data":[{"symbol":"ETH/AUD","bids":[{"price":5710.10,"qty":0.00000000},{"price":5703.22,"qty":0.11200000},{"price":5710.13,"qty":1.03768339}],"asks":[],"checksum":1656150699,"timestamp":"2024-06-01T17:52:24.530566Z"}]}
{"channel":"book","type":"update","data":[{"symbol":"ETH/AUD","bids":[],"asks":[{"price":5717.10,"qty":0.83372964}],"checksum":3487247704,"timestamp":"2024-06-01T17:52:24.537307Z"}]}
{"channel":"book","type":"update","data":[{"symbol":"ETH/AUD","bids":[{"price":5710.11,"qty":0.00000000},{"price":5703.22,"qty":0.11200000},{"price":5710.14,"qty":0.07347674}],"asks":[],"checksum":1352750482,"timestamp":"2024-06-01T17:52:24.569359Z"}]}
{"channel":"book","type":"update","data":[{"symbol":"ETH/AUD","bids":[{"price":5710.15,"qty":0.90387105}],"asks":[],"checksum":519584223,"timestamp":"2024-06-01T17:52:25.176670Z"}]}
{"channel":"book","type":"update","data":[{"symbol":"ETH/AUD","bids":[],"asks":[{"price":5713.59,"qty":0.90387105}],"checksum":1024467116,"timestamp":"2024-06-01T17:52:25.176765Z"}]}
{"channel":"book","type":"update","data":[{"symbol":"ETH/AUD","bids":[],"asks":[{"price":5713.62,"qty":0.00000000},{"price":5719.71,"qty":0.20717085}],"checksum":3005531597,"timestamp":"2024-06-01T17:52:25.191175Z"}]}
{"channel":"book","type":"update","data":[{"symbol":"ETH/AUD","bids":[{"price":5710.12,"qty":0.06657600}],"asks":[],"checksum":452945936,"timestamp":"2024-06-01T17:52:25.191369Z"}]}
{"channel":"book","type":"update","data":[{"symbol":"ETH/AUD","bids":[{"price":5710.14,"qty":0.00000000},{"price":5703.42,"qty":0.74671637},{"price":5710.16,"qty":0.07347674}],"asks":[],"checksum":2901000778,"timestamp":"2024-06-01T17:52:25.207758Z"}]}
{"channel":"book","type":"update","data":[{"symbol":"ETH/AUD","bids":[],"asks":[{"price":5713.60,"qty":0.00000000},{"price":5719.72,"qty":0.08600000},{"price":5713.58,"qty":0.20551042}],"checksum":3108769920,"timestamp":"2024-06-01T17:52:25.224926Z"}]}
{"channel":"book","type":"update","data":[{"symbol":"ETH/AUD","bids":[{"price":5710.13,"qty":0.00000000},{"price":5703.42,"qty":0.74671637},{"price":5710.16,"qty":1.11115788}],"asks":[],"checksum":3113375229,"timestamp":"2024-06-01T17:52:25.224990Z"}]}
{"channel":"book","type":"update","data":[{"symbol":"ETH/AUD","bids":[],"asks":[{"price":5716.69,"qty":0.52360000}],"checksum":284520289,"timestamp":"2024-06-01T17:52:25.484661Z"}]}
{"channel":"book","type":"update","data":[{"symbol":"ETH/AUD","bids":[],"asks":[{"price":5716.68,"qty":0.06702224}],"checksum":1043942460,"timestamp":"2024-06-01T17:52:25.486416Z"}]}
{"channel":"book","type":"update","data":[{"symbol":"ETH/AUD","bids":[],"asks":[{"price":5716.82,"qty":0.03220106}],"checksum":668625787,"timestamp":"2024-06-01T17:52:25.486570Z"}]}
{"channel":"book","type":"update","data":[{"symbol":"ETH/AUD","bids":[],"asks":[{"price":5716.69,"qty":0.00000000},{"price":5717.11,"qty":11.18077799},{"price":5716.82,"qty":0.55580106}],"checksum":890174363,"timestamp":"2024-06-01T17:52:25.487819Z"}]}
{"channel":"book","type":"update","data":[{"symbol":"ETH/AUD","bids":[{"price":5710.16,"qty":1.03768114},{"price":5710.17,"qty":0.07347674}],"asks":[],"checksum":3408973657,"timestamp":"2024-06-01T17:52:25.847354Z"}]}
{"channel":"book","type":"update","data":[{"symbol":"ETH/AUD","bids":[{"price":5710.16,"qty":0.00000000},{"price":5703.42,"qty":0.74671637},{"price":5710.18,"qty":1.03767747}],"asks":[],"checksum":2040584165,"timestamp":"2024-06-01T17:52:25.908093Z"}]}
{"channel":"book","type":"update","data":[{"symbol":"ETH/AUD","bids":[],"asks":[{"price":5713.57,"qty":0.90387105}],"checksum":1487587777,"timestamp":"2024-06-01T17:52:25.913574Z"}]}
{"channel":"book","type":"update","data":[{"symbol":"ETH/AUD","bids":[],"asks":[{"price":5713.59,"qty":0.00000000},{"price":5717.11,"qty":11.18077799}],"checksum":911534422,"timestamp":"2024-06-01T17:52:26.175941Z"}]}
{"channel":"book","type":"update","data":[{"symbol":"ETH/AUD","bids":[{"price":5710.17,"qty":0.00000000},{"price":5703.42,"qty":0.74671637},{"price":5710.19,"qty":0.07347674}],"asks":[],"checksum":2690242809,"timestamp":"2024-06-01T17:52:26.485567Z"}]}
{"channel":"book","type":"update","data":[{"symbol":"ETH/AUD","bids":[{"price":5710.18,"qty":0.00000000},{"price":5703.42,"qty":0.74671637},{"price":5710.20,"qty":1.03767856}],"asks":[],"checksum":1249124112,"timestamp":"2024-06-01T17:52:26.632990Z"}]}
{"channel":"book","type":"update","data":[{"symbol":"ETH/AUD","bids":[],"asks":[{"price":5716.83,"qty":0.00000000},{"price":5719.71,"qty":0.01496843}],"checksum":4097762603,"timestamp":"2024-06-01T17:52:26.639385Z"}]}
{"channel":"book","type":"update","data":[{"symbol":"ETH/AUD","bids":[],"asks":[{"price":5716.82,"qty":0.03220106},{"price":5717.09,"qty":0.52360000}],"checksum":26183561,"timestamp":"2024-06-01T17:52:26.643002Z"}]}
{"channel":"book","type":"update","data":[{"symbol":"ETH/AUD","bids":[],"asks":[{"price":5717.09,"qty":5.17316192}],"checksum":1278981522,"timestamp":"2024-06-01T17:52:26.644414Z"}]}
{"channel":"book","type":"update","data":[{"symbol":"ETH/AUD","bids":[],"asks":[{"price":5716.81,"qty":7.80916577}],"checksum":662993124,"timestamp":"2024-06-01T17:52:26.644577Z"}]}
{"channel":"book","type":"update","data":[{"symbol":"ETH/AUD","bids":[{"price":5710.19,"qty":0.00000000},{"price":5703.42,"qty":0.74671637},{"price":5710.21,"qty":0.07347674}],"asks":[],"checksum":2617452589,"timestamp":"2024-06-01T17:52:26.972264Z"}]}
{"channel":"book","type":"update","data":[{"symbol":"ETH/AUD","bids":[{"price":5710.22,"qty":0.90387105}],"asks":[],"checksum":3026736855,"timestamp":"2024-06-01T17:52:26.977559Z"}]}
{"channel":"book","type":"update","data":[{"symbol":"ETH/AUD","bids":[{"price":5710.15,"qty":0.00000000},{"price":5705.25,"qty":1.60677000}],"asks":[],"checksum":1767667769,"timestamp":"2024-06-01T17:52:27.176207Z"}]}
{"channel":"book","type":"update","data":[{"symbol":"ETH/AUD","bids":[],"asks":[{"price":5717.09,"qty":4.64956192},{"price":5716.80,"qty":0.52360000}],"checksum":730121640,"timestamp":"2024-06-01T17:52:27.179090Z"}]}
{"channel":"book","type":"update","data":[{"symbol":"ETH/AUD","bids":[{"price":5705.34,"qty":0.00000000},{"price":5703.42,"qty":0.74671637}],"asks":[],"checksum":3356556546,"timestamp":"2024-06-01T17:52:27.225485Z"}]}
{"channel":"book","type":"update","data":[{"symbol":"ETH/AUD","bids":[{"price":5705.37,"qty":2.06834482}],"asks":[],"checksum":209227660,"timestamp":"2024-06-01T17:52:27.227793Z"}]}
{"channel":"book","type":"update","data":[{"symbol":"ETH/AUD","bids":[{"price":5705.35,"qty":0.00000000},{"price":5703.43,"qty":2.58221611},{"price":5705.26,"qty":0.52360000}],"asks":[],"checksum":4058887850,"timestamp":"2024-06-01T17:52:27.228327Z"}]}
{"channel":"book","type":"update","data":[{"symbol":"ETH/AUD","bids":[{"price":5710.20,"qty":0.00000000},{"price":5703.44,"qty":0.74671376},{"price":5710.23,"qty":1.03767328}],"asks":[],"checksum":2425259907,"timestamp":"2024-06-01T17:52:27.318124Z"}]}
{"channel":"book","type":"update","data":[{"symbol":"ETH/AUD","bids":[],"asks":[{"price":5713.58,"qty":0.00000000},{"price":5717.10,"qty":0.83372964},{"price":5713.56,"qty":0.20551041}],"checksum":2946395030,"timestamp":"2024-06-01T17:52:27.318198Z"}]}
{"channel":"book","type":"update","data":[{"symbol":"ETH/AUD","bids":[{"price":5705.36,"qty":0.00000000},{"price":5703.44,"qty":0.74671376}],"asks":[],"checksum":2548838641,"timestamp":"2024-06-01T17:52:27.492689Z"}]}
{"channel":"book","type":"update","data":[{"symbol":"ETH/AUD","bids":[{"price":5705.38,"qty":0.05247923}],"asks":[],"checksum":2240261248,"timestamp":"2024-06-01T17:52:27.492730Z"}]}
{"channel":"book","type":"update","data":[{"symbol":"ETH/AUD","bids":[{"price":5710.21,"qty":0.00000000},{"price":5703.44,"qty":0.74671376},{"price":5710.24,"qty":0.07347674}],"asks":[],"checksum":3746796798,"timestamp":"2024-06-01T17:52:27.523123Z"}]}
{"channel":"book","type":"update","data":[{"symbol":"ETH/AUD","bids":[],"asks":[{"price":5716.67,"qty":0.83372964}],"checksum":3078100596,"timestamp":"2024-06-01T17:52:27.618991Z"}]}
{"channel":"book","type":"update","data":[{"symbol":"ETH/AUD","bids":[],"asks":[{"price":5716.82,"qty":0.00000000},{"price":5717.09,"qty":4.64956192}],"checksum":3736162979,"timestamp":"2024-06-01T17:52:27.799256Z"}]}
{"channel":"book","type":"update","data":[{"symbol":"ETH/AUD","bids":[],"asks":[{"price":5716.68,"qty":0.00000000},{"price":5717.11,"qty":11.18077799}],"checksum":2778759191,"timestamp":"2024-06-01T17:52:27.799403Z"}]}
{"channel":"book","type":"update","data":[{"symbol":"ETH/AUD","bids":[],"asks":[{"price":5716.79,"qty":0.09302431}],"checksum":1747963367,"timestamp":"2024-06-01T17:52:27.800884Z"}]}
{"channel":"book","type":"update","data":[{"symbol":"ETH/AUD","bids":[],"asks":[{"price":5716.80,"qty":0.00000000},{"price":5717.11,"qty":11.18077799},{"price":5716.66,"qty":0.52360000}],"checksum":1127540994,"timestamp":"2024-06-01T17:52:27.802698Z"}]}
{"channel":"book","type":"update","data":[{"symbol":"ETH/AUD","bids":[{"price":5705.26,"qty":0.00000000},{"price":5703.44,"qty":0.74671376},{"price":5705.38,"qty":0.57607923}],"asks":[],"checksum":3182296666,"timestamp":"2024-06-01T17:52:27.802849Z"}]}
{"channel":"book","type":"update","data":[{"symbol":"ETH/AUD","bids":[{"price":5710.23,"qty":0.00000000},{"price":5703.43,"qty":2.58221611},{"price":5710.25,"qty":1.03766973}],"asks":[],"checksum":124140472,"timestamp":"2024-06-01T17:52:28.072832Z"}]}
{"channel":"book","type":"update","data":[{"symbol":"ETH/AUD","bids":[{"price":5710.26,"qty":0.90387105}],"asks":[],"checksum":2470110635,"timestamp":"2024-06-01T17:52:28.079570Z"}]}
{"channel":"book","type":"update","data":[{"symbol":"ETH/AUD","bids":[],"asks":[{"price":5713.55,"qty":0.90387105}],"checksum":314427164,"timestamp":"2024-06-01T17:52:28.079593Z"}]}
{"channel":"book","type":"update","data":[{"symbol":"ETH/AUD","bids":[{"price":5710.24,"qty":0.00000000},{"price":5703.44,"qty":0.74671376},{"price":5710.27,"qty":0.07347674}],"asks":[],"checksum":401082394,"timestamp":"2024-06-01T17:52:28.103410Z"}]}
{"channel":"book","type":"update","data":[{"symbol":"ETH/AUD","bids":[],"asks":[{"price":5713.57,"qty":0.00000000},{"price":5717.09,"qty":4.64956192}],"checksum":904180355,"timestamp":"2024-06-01T17:52:28.176162Z"}]}
{"channel":"book","type":"update","data":[{"symbol":"ETH/AUD","bids":[{"price":5710.22,"qty":0.00000000},{"price":5703.44,"qty":0.74671376}],"asks":[],"checksum":3023282585,"timestamp":"2024-06-01T17:52:28.176264Z"}]}
{"channel":"book","type":"update","data":[{"symbol":"ETH/AUD","bids":[],"asks":[{"price":5713.61,"qty":0.00000000},{"price":5717.11,"qty":11.18077799},{"price":5713.54,"qty":0.01292326}],"checksum":3214281474,"timestamp":"2024-06-01T17:52:28.512482Z"}]}
{"channel":"book","type":"update","data":[{"symbol":"ETH/AUD","bids":[],"asks":[{"price":5713.56,"qty":0.00000000},{"price":5717.11,"qty":11.18077799},{"price":5713.53,"qty":0.20551358}],"checksum":219856773,"timestamp":"2024-06-01T17:52:28.783518Z"}]}
{"channel":"book","type":"update","data":[{"symbol":"ETH/AUD","bids":[{"price":5710.25,"qty":0.00000000},{"price":5703.43,"qty":2.58221611},{"price":5710.28,"qty":1.03766431}],"asks":[],"checksum":2159806934,"timestamp":"2024-06-01T17:52:28.783567Z"}]}
{"channel":"book","type":"update","data":[{"symbol":"ETH/AUD","bids":[],"asks":[{"price":5717.09,"qty":0.00000000},{"price":5717.11,"qty":11.18077799}],"checksum":69468929,"timestamp":"2024-06-01T17:52:29.098685Z"}]}
{"channel":"book","type":"update","data":[{"symbol":"ETH/AUD","bids":[],"asks":[{"price":5716.81,"qty":0.00000000},{"price":5719.71,"qty":0.20717085}],"checksum":3508527911,"timestamp":"2024-06-01T17:52:29.098899Z"}]}
{"channel":"book","type":"update","data":[{"symbol":"ETH/AUD","bids":[],"asks":[{"price":5716.65,"qty":11.96522221}],"checksum":1821132570,"timestamp":"2024-06-01T17:52:29.103741Z"}]}
{"channel":"book","type":"update","data":[{"symbol":"ETH/AUD","bids":[],"asks":[{"price":5716.66,"qty":0.00000000},{"price":5719.71,"qty":0.20717085},{"price":5716.64,"qty":0.52360000}],"checksum":1288647736,"timestamp":"2024-06-01T17:52:29.106512Z"}]}
{"channel":"book","type":"update","data":[{"symbol":"ETH/AUD","bids":[{"price":5710.29,"qty":0.90387105}],"asks":[],"checksum":4034194081,"timestamp":"2024-06-01T17:52:29.176753Z"}]}
{"channel":"book","type":"update","data":[{"symbol":"ETH/AUD","bids":[{"price":5710.26,"qty":0.00000000},{"price":5703.44,"qty":0.74671376}],"asks":[],"checksum":976970898,"timestamp":"2024-06-01T17:52:29.182229Z"}]}
{"channel":"book","type":"update","data":[{"symbol":"ETH/AUD","bids":[{"price":5710.27,"qty":0.00000000},{"price":5703.43,"qty":2.58221611},{"price":5710.30,"qty":0.07347674}],"asks":[],"checksum":907866226,"timestamp":"2024-06-01T17:52:29.184325Z"}]}
{"channel":"book","type":"update","data":[{"symbol":"ETH/AUD","bids":[{"price":5710.28,"qty":0.00000000},{"price":5703.43,"qty":2.58221611},{"price":5710.31,"qty":1.03766113}],"asks":[],"checksum":1310734371,"timestamp":"2024-06-01T17:52:29.484518Z"}]}
{"channel":"book","type":"update","data":[{"symbol":"ETH/AUD","bids":[],"asks":[{"price":5717.11,"qty":0.00000000},{"price":5719.71,"qty":0.20717085}],"checksum":3433826487,"timestamp":"2024-06-01T17:52:29.634138Z"}]}
{"channel":"book","type":"update","data":[{"symbol":"ETH/AUD","bids":[],"asks":[{"price":5717.23,"qty":11.18066040}],"checksum":761313219,"timestamp":"2024-06-01T17:52:29.638954Z"}]}
{"channel":"book","type":"update","data":[{"symbol":"ETH/AUD","bids":[{"price":5710.30,"qty":0.00000000},{"price":5703.43,"qty":2.58221611},{"price":5710.32,"qty":0.07347674}],"asks":[],"checksum":1127578603,"timestamp":"2024-06-01T17:52:29.975751Z"}]}
{"channel":"book","type":"update","data":[{"symbol":"ETH/AUD","bids":[{"price":5710.33,"qty":0.90387105}],"asks":[],"checksum":1319852196,"timestamp":"2024-06-01T17:52:29.980875Z"}]}
{"channel":"book","type":"update","data":[{"symbol":"ETH/AUD","bids":[{"price":5705.39,"qty":0.74645855}],"asks":[],"checksum":2641795596,"timestamp":"2024-06-01T17:52:30.106495Z"}]}
{"channel":"book","type":"update","data":[{"symbol":"ETH/AUD","bids":[{"price":5705.38,"qty":0.05247923},{"price":5705.40,"qty":0.52360000}],"asks":[],"checksum":81887605,"timestamp":"2024-06-01T17:52:30.109555Z"}]}
{"channel":"book","type":"update","data":[{"symbol":"ETH/AUD","bids":[],"asks":[{"price":5716.67,"qty":0.00000000},{"price":5719.71,"qty":0.20717085}],"checksum":356893108,"timestamp":"2024-06-01T17:52:30.113098Z"}]}
{"channel":"book","type":"update","data":[{"symbol":"ETH/AUD","bids":[],"asks":[{"price":5716.79,"qty":0.00000000},{"price":5719.72,"qty":0.08600000}],"checksum":898516027,"timestamp":"2024-06-01T17:52:30.147136Z"}]}
{"channel":"book","type":"update","data":[{"symbol":"ETH/AUD","bids":[],"asks":[{"price":5717.22,"qty":0.83372964}],"checksum":3354142231,"timestamp":"2024-06-01T17:52:30.149198Z"}]}
{"channel":"book","type":"update","data":[{"symbol":"ETH/AUD","bids":[],"asks":[{"price":5716.63,"qty":0.09068811}],"checksum":325866773,"timestamp":"2024-06-01T17:52:30.149750Z"}]}
{"channel":"book","type":"update","data":[{"symbol":"ETH/AUD","bids":[],"asks":[{"price":5716.64,"qty":0.00000000},{"price":5719.71,"qty":0.20717085},{"price":5716.62,"qty":0.52360000}],"checksum":2430556829,"timestamp":"2024-06-01T17:52:30.152993Z"}]}
{"channel":"book","type":"update","data":[{"symbol":"ETH/AUD","bids":[{"price":5710.29,"qty":0.00000000},{"price":5705.37,"qty":2.06834482}],"asks":[],"checksum":2373926071,"timestamp":"2024-06-01T17:52:30.176175Z"}]}
{"channel":"book","type":"update","data":[{"symbol":"ETH/AUD","bids":[{"price":5705.37,"qty":0.00000000},{"price":5705.25,"qty":1.60677000}],"asks":[],"checksum":685185172,"timestamp":"2024-06-01T17:52:30.208662Z"}]}
{"channel":"book","type":"update","data":[{"symbol":"ETH/AUD","bids":[{"price":5705.39,"qty":3.32863459}],"asks":[],"checksum":2785800846,"timestamp":"2024-06-01T17:52:30.209136Z"}]}
{"channel":"book","type":"update","data":[{"symbol":"ETH/AUD","bids":[{"price":5705.39,"qty":2.58217604}],"asks":[],"checksum":1822072586,"timestamp":"2024-06-01T17:52:30.220527Z"}]}
{"channel":"book","type":"update","data":[{"symbol":"ETH/AUD","bids":[{"price":5705.41,"qty":0.74645594}],"asks":[],"checksum":2000246121,"timestamp":"2024-06-01T17:52:30.220786Z"}]}
{"channel":"book","type":"update","data":[{"symbol":"ETH/AUD","bids":[{"price":5710.31,"qty":0.00000000},{"price":5705.25,"qty":1.60677000},{"price":5710.34,"qty":1.03765567}],"asks":[],"checksum":3538627539,"timestamp":"2024-06-01T17:52:30.223586Z"}]}
{"channel":"book","type":"update","data":[{"symbol":"ETH/AUD","bids":[{"price":5705.38,"qty":0.00000000},{"price":5705.25,"qty":1.60677000}],"asks":[],"checksum":3867321837,"timestamp":"2024-06-01T17:52:30.477323Z"}]}
{"channel":"book","type":"update","data":[{"symbol":"ETH/AUD","bids":[{"price":5705.42,"qty":0.05585065}],"asks":[],"checksum":3150638197,"timestamp":"2024-06-01T17:52:30.477901Z"}]}
{"channel":"book","type":"update","data":[{"symbol":"ETH/AUD","bids":[{"price":5710.32,"qty":0.00000000},{"price":5705.25,"qty":1.60677000},{"price":5710.35,"qty":0.07347674}],"asks":[],"checksum":1057433791,"timestamp":"2024-06-01T17:52:30.498061Z"}]}
{"channel":"book","type":"update","data":[{"symbol":"ETH/AUD","bids":[],"asks":[{"price":5714.61,"qty":0.00000000},{"price":5719.71,"qty":0.20717085},{"price":5715.29,"qty":0.06653900}],"checksum":849763812,"timestamp":"2024-06-01T17:52:30.521665Z"}]}
{"channel":"book","type":"update","data":[{"symbol":"ETH/AUD","bids":[{"price":5705.40,"qty":0.00000000},{"price":5705.25,"qty":1.60677000},{"price":5705.42,"qty":0.57945065}],"asks":[],"checksum":3470446780,"timestamp":"2024-06-01T17:52:30.653825Z"}]}
{"channel":"book","type":"update","data":[{"symbol":"ETH/AUD","bids":[],"asks":[{"price":5717.23,"qty":0.00000000},{"price":5719.71,"qty":0.01496843}],"checksum":3536934813,"timestamp":"2024-06-01T17:52:30.782445Z"}]}
{"channel":"book","type":"update","data":[{"symbol":"ETH/AUD","bids":[],"asks":[{"price":5717.35,"qty":11.18062120}],"checksum":2266956478,"timestamp":"2024-06-01T17:52:30.788553Z"}]}
{"channel":"book","type":"update","data":[{"symbol":"ETH/AUD","bids":[],"asks":[{"price":5717.34,"qty":0.00775211}],"checksum":3251528525,"timestamp":"2024-06-01T17:52:30.799737Z"}]}
{"channel":"book","type":"update","data":[{"symbol":"ETH/AUD","bids":[],"asks":[{"price":5713.55,"qty":0.00000000},{"price":5717.35,"qty":11.18062120}],"checksum":2870999506,"timestamp":"2024-06-01T17:52:30.809630Z"}]}
{"channel":"book","type":"update","data":[{"symbol":"ETH/AUD","bids":[],"asks":[{"price":5717.35,"qty":0.00000000},{"price":5719.72,"qty":0.08600000}],"checksum":2878104332,"timestamp":"2024-06-01T17:52:30.811223Z"}]}
{"channel":"book","type":"update","data":[{"symbol":"ETH/AUD","bids":[],"asks":[{"price":5717.52,"qty":10.59484515}],"checksum":241617058,"timestamp":"2024-06-01T17:52:30.816425Z"}]}
{"channel":"book","type":"update","data":[{"symbol":"ETH/AUD","bids":[],"asks":[{"price":5717.34,"qty":0.00000000},{"price":5719.72,"qty":0.08600000}],"checksum":1593839164,"timestamp":"2024-06-01T17:52:30.833192Z"}]}
{"channel":"book","type":"update","data":[{"symbol":"ETH/AUD","bids":[],"asks":[{"price":5717.51,"qty":0.00775188}],"checksum":2147017666,"timestamp":"2024-06-01T17:52:30.833287Z"}]}
{"channel":"book","type":"update","data":[{"symbol":"ETH/AUD","bids":[],"asks":[{"price":5717.52,"qty":0.00000000},{"price":5719.72,"qty":0.08600000}],"checksum":1599271986,"timestamp":"2024-06-01T17:52:30.845772Z"}]}
{"channel":"book","type":"update","data":[{"symbol":"ETH/AUD","bids":[],"asks":[{"price":5717.71,"qty":11.18062120}],"checksum":1774195530,"timestamp":"2024-06-01T17:52:30.849580Z"}]}
{"channel":"book","type":"update","data":[{"symbol":"ETH/AUD","bids":[],"asks":[{"price":5717.51,"qty":0.00000000},{"price":5719.72,"qty":0.08600000}],"checksum":1509772708,"timestamp":"2024-06-01T17:52:30.859981Z"}]}
{"channel":"book","type":"update","data":[{"symbol":"ETH/AUD","bids":[],"asks":[{"price":5717.70,"qty":0.00775163}],"checksum":1268098040,"timestamp":"2024-06-01T17:52:30.859995Z"}]}
{"channel":"book","type":"update","data":[{"symbol":"ETH/AUD","bids":[],"asks":[{"price":5713.53,"qty":0.00000000},{"price":5719.72,"qty":0.08600000},{"price":5715.28,"qty":0.20551290}],"checksum":1251969385,"timestamp":"2024-06-01T17:52:30.862031Z"}]}
{"channel":"book","type":"update","data":[{"symbol":"ETH/AUD","bids":[{"price":5710.34,"qty":0.00000000},{"price":5703.22,"qty":0.11200000},{"price":5710.36,"qty":1.03764434}],"asks":[],"checksum":1986026535,"timestamp":"2024-06-01T17:52:30.919378Z"}]}
{"channel":"book","type":"update","data":[{"symbol":"ETH/AUD","bids":[],"asks":[{"price":5715.28,"qty":0.00000000},{"price":5719.72,"qty":0.08600000},{"price":5716.61,"qty":0.20551290}],"checksum":890475957,"timestamp":"2024-06-01T17:52:30.919476Z"}]}
{"channel":"book","type":"update","data":[{"symbol":"ETH/AUD","bids":[],"asks":[{"price":5716.62,"qty":0.00000000},{"price":5719.72,"qty":0.08600000},{"price":5716.60,"qty":0.52360000}],"checksum":2611950997,"timestamp":"2024-06-01T17:52:30.922608Z"}]}
{"channel":"book","type":"update","data":[{"symbol":"ETH/AUD","bids":[],"asks":[{"price":5717.22,"qty":0.00000000},{"price":5719.72,"qty":0.08600000}],"checksum":2633075113,"timestamp":"2024-06-01T17:52:30.923460Z"}]}
{"channel":"book","type":"update","data":[{"symbol":"ETH/AUD","bids":[],"asks":[{"price":5714.46,"qty":0.90387105}],"checksum":4118129576,"timestamp":"2024-06-01T17:52:30.924735Z"}]}
{"channel":"book","type":"update","data":[{"symbol":"ETH/AUD","bids":[{"price":5710.37,"qty":0.90387105}],"asks":[],"checksum":2349369256,"timestamp":"2024-06-01T17:52:30.924758Z"}]}
{"channel":"book","type":"update","data":[{"symbol":"ETH/AUD","bids":[],"asks":[{"price":5715.29,"qty":0.00000000},{"price":5719.72,"qty":0.08600000},{"price":5716.43,"qty":0.06653100}],"checksum":3116173741,"timestamp":"2024-06-01T17:52:30.925198Z"}]}
{"channel":"book","type":"update","data":[{"symbol":"ETH/AUD","bids":[],"asks":[{"price":5716.63,"qty":0.00000000},{"price":5719.72,"qty":0.08600000}],"checksum":2790815145,"timestamp":"2024-06-01T17:52:30.930321Z"}]}
{"channel":"book","type":"update","data":[{"symbol":"ETH/AUD","bids":[{"price":5710.35,"qty":0.00000000},{"price":5705.25,"qty":1.60677000},{"price":5710.38,"qty":0.07347674}],"asks":[],"checksum":2223037995,"timestamp":"2024-06-01T17:52:30.992216Z"}]}
{"channel":"book","type":"update","data":[{"symbol":"ETH/AUD","bids":[{"price":5710.37,"qty":0.00000000},{"price":5705.25,"qty":1.60677000}],"asks":[],"checksum":1371763646,"timestamp":"2024-06-01T17:52:30.996105Z"}]}
{"channel":"book","type":"update","data":[{"symbol":"ETH/AUD","bids":[{"price":5710.33,"qty":0.00000000},{"price":5703.22,"qty":0.11200000}],"asks":[],"checksum":3614785641,"timestamp":"2024-06-01T17:52:30.996166Z"}]}
{"channel":"book","type":"update","data":[{"symbol":"ETH/AUD","bids":[],"asks":[{"price":5717.70,"qty":0.00000000},{"price":5719.79,"qty":1.60677000}],"checksum":3868240467,"timestamp":"2024-06-01T17:52:31.022376Z"}]}
{"channel":"book","type":"update","data":[{"symbol":"ETH/AUD","bids":[],"asks":[{"price":5717.70,"qty":0.20717085}],"checksum":3006985934,"timestamp":"2024-06-01T17:52:31.022720Z"}]}
{"channel":"book","type":"update","data":[{"symbol":"ETH/AUD","bids":[{"price":5709.95,"qty":0.00000000},{"price":5702.47,"qty":4.60670436}],"asks":[],"checksum":2031031443,"timestamp":"2024-06-01T17:52:31.027979Z"}]}
{"channel":"book","type":"update","data":[{"symbol":"ETH/AUD","bids":[{"price":5705.41,"qty":0.00000000},{"price":5702.46,"qty":2.35323000}],"asks":[],"checksum":4288466539,"timestamp":"2024-06-01T17:52:31.038903Z"}]}
{"channel":"book","type":"update","data":[{"symbol":"ETH/AUD","bids":[{"price":5710.15,"qty":1.28790996}],"asks":[],"checksum":1735956938,"timestamp":"2024-06-01T17:52:31.041387Z"}]}
{"channel":"book","type":"update","data":[{"symbol":"ETH/AUD","bids":[{"price":5705.43,"qty":0.74645331}],"asks":[],"checksum":3335391095,"timestamp":"2024-06-01T17:52:31.053646Z"}]}
{"channel":"book","type":"update","data":[{"symbol":"ETH/AUD","bids":[{"price":5705.43,"qty":0.00000000},{"price":5702.47,"qty":4.60670436}],"asks":[],"checksum":1735956938,"timestamp":"2024-06-01T17:52:31.090191Z"}]}
{"channel":"book","type":"update","data":[{"symbol":"ETH/AUD","bids":[],"asks":[{"price":5716.55,"qty":0.09600000}],"checksum":3438932773,"timestamp":"2024-06-01T17:52:31.095333Z"}]}
{"channel":"book","type":"update","data":[{"symbol":"ETH/AUD","bids":[{"price":5705.43,"qty":0.65649719}],"asks":[],"checksum":3305037581,"timestamp":"2024-06-01T17:52:31.095409Z"}]}
{"channel":"book","type":"update","data":[{"symbol":"ETH/AUD","bids":[{"price":5710.15,"qty":0.00000000},{"price":5702.47,"qty":4.60670436}],"asks":[],"checksum":3791734996,"timestamp":"2024-06-01T17:52:31.096684Z"}]}
{"channel":"book","type":"update","data":[{"symbol":"ETH/AUD","bids":[{"price":5703.22,"qty":0.00000000},{"price":5702.46,"qty":2.35323000}],"asks":[],"checksum":3112576118,"timestamp":"2024-06-01T17:52:31.098762Z"}]}
{"channel":"book","type":"update","data":[{"symbol":"ETH/AUD","bids":[{"price":5705.26,"qty":0.54649719}],"asks":[],"checksum":942925229,"timestamp":"2024-06-01T17:52:31.109175Z"}]}
{"channel":"book","type":"update","data":[{"symbol":"ETH/AUD","bids":[{"price":5705.43,"qty":0.00000000},{"price":5702.46,"qty":2.35323000}],"asks":[],"checksum":208669647,"timestamp":"2024-06-01T17:52:31.110423Z"}]}
{"channel":"book","type":"update","data":[{"symbol":"ETH/AUD","bids":[{"price":5709.84,"qty":3.06458702}],"asks":[],"checksum":2974599783,"timestamp":"2024-06-01T17:52:31.116615Z"}]}
{"channel":"book","type":"update","data":[{"symbol":"ETH/AUD","bids":[{"price":5705.26,"qty":0.75299438}],"asks":[],"checksum":704170452,"timestamp":"2024-06-01T17:52:31.125642Z"}]}
{"channel":"book","type":"update","data":[{"symbol":"ETH/AUD","bids":[{"price":5705.26,"qty":0.20649719}],"asks":[],"checksum":3376898548,"timestamp":"2024-06-01T17:52:31.127489Z"}]}
{"channel":"book","type":"update","data":[{"symbol":"ETH/AUD","bids":[{"price":5709.84,"qty":0.00000000},{"price":5702.46,"qty":2.35323000}],"asks":[],"checksum":3544771132,"timestamp":"2024-06-01T17:52:31.129717Z"}]}
{"channel":"book","type":"update","data":[{"symbol":"ETH/AUD","bids":[{"price":5709.54,"qty":3.06474832}],"asks":[],"checksum":3734780961,"timestamp":"2024-06-01T17:52:31.138651Z"}]}
{"channel":"book","type":"update","data":[{"symbol":"ETH/AUD","bids":[{"price":5702.48,"qty":0.74683947}],"asks":[],"checksum":14055515,"timestamp":"2024-06-01T17:52:31.158050Z"}]}
{"channel":"book","type":"update","data":[{"symbol":"ETH/AUD","bids":[{"price":5705.26,"qty":0.00000000},{"price":5702.47,"qty":4.60670436}],"asks":[],"checksum":126883334,"timestamp":"2024-06-01T17:52:31.159072Z"}]}
{"channel":"book","type":"update","data":[{"symbol":"ETH/AUD","bids":[{"price":5710.36,"qty":0.00000000},{"price":5702.46,"qty":2.35323000},{"price":5705.43,"qty":1.03853879}],"asks":[],"checksum":1868718952,"timestamp":"2024-06-01T17:52:31.201592Z"}]}
{"channel":"book","type":"update","data":[{"symbol":"ETH/AUD","bids":[{"price":5709.54,"qty":0.00000000},{"price":5702.46,"qty":2.35323000}],"asks":[],"checksum":855479066,"timestamp":"2024-06-01T17:52:31.208092Z"}]}
{"channel":"book","type":"update","data":[{"symbol":"ETH/AUD","bids":[{"price":5705.42,"qty":0.05585065},{"price":5705.44,"qty":0.52360000}],"asks":[],"checksum":889183177,"timestamp":"2024-06-01T17:52:31.223727Z"}]}
{"channel":"book","type":"update","data":[{"symbol":"ETH/AUD","bids":[{"price":5708.34,"qty":3.06539370}],"asks":[],"checksum":2615607972,"timestamp":"2024-06-01T17:52:31.225383Z"}]}
{"channel":"book","type":"update","data":[{"symbol":"ETH/AUD","bids":[],"asks":[{"price":5716.42,"qty":0.83372964}],"checksum":3936850399,"timestamp":"2024-06-01T17:52:31.245449Z"}]}
{"channel":"book","type":"update","data":[{"symbol":"ETH/AUD","bids":[],"asks":[{"price":5716.60,"qty":0.00000000},{"price":5717.71,"qty":11.18062120},{"price":5714.45,"qty":0.52360000}],"checksum":874372167,"timestamp":"2024-06-01T17:52:31.435249Z"}]}
{"channel":"book","type":"update","data":[{"symbol":"ETH/AUD","bids":[{"price":5710.12,"qty":0.00000000},{"price":5702.47,"qty":4.60670436},{"price":5709.49,"qty":0.06657800}],"asks":[],"checksum":1874446165,"timestamp":"2024-06-01T17:52:31.523830Z"}]}
{"channel":"book","type":"update","data":[{"symbol":"ETH/AUD","bids":[{"price":5705.44,"qty":0.54766309}],"asks":[],"checksum":606398334,"timestamp":"2024-06-01T17:52:31.556360Z"}]}
{"channel":"book","type":"update","data":[{"symbol":"ETH/AUD","bids":[{"price":5702.48,"qty":0.00000000},{"price":5702.47,"qty":4.60670436}],"asks":[],"checksum":2512132857,"timestamp":"2024-06-01T17:52:31.614616Z"}]}
{"channel":"book","type":"update","data":[{"symbol":"ETH/AUD","bids":[],"asks":[{"price":5716.61,"qty":0.00000000},{"price":5717.71,"qty":11.18062120},{"price":5714.44,"qty":0.20551418}],"checksum":1555849499,"timestamp":"2024-06-01T17:52:31.634119Z"}]}
{"channel":"book","type":"update","data":[{"symbol":"ETH/AUD","bids":[{"price":5705.43,"qty":0.00000000},{"price":5702.46,"qty":2.35323000},{"price":5708.35,"qty":1.03800721}],"asks":[],"checksum":2380971469,"timestamp":"2024-06-01T17:52:31.634164Z"}]}
{"channel":"book","type":"update","data":[{"symbol":"ETH/AUD","bids":[{"price":5702.48,"qty":0.74683947}],"asks":[],"checksum":3317998761,"timestamp":"2024-06-01T17:52:31.684608Z"}]}
{"channel":"book","type":"update","data":[{"symbol":"ETH/AUD","bids":[{"price":5710.05,"qty":0.00000000},{"price":5702.47,"qty":4.60670436}],"asks":[],"checksum":2613677995,"timestamp":"2024-06-01T17:52:31.727480Z"}]}
{"channel":"book","type":"update","data":[{"symbol":"ETH/AUD","bids":[{"price":5710.38,"qty":0.00000000},{"price":5702.46,"qty":2.35323000},{"price":5708.36,"qty":0.07347674}],"asks":[],"checksum":1887305711,"timestamp":"2024-06-01T17:52:31.777241Z"}]}
{"channel":"book","type":"update","data":[{"symbol":"ETH/AUD","bids":[],"asks":[{"price":5717.70,"qty":0.22017828}],"checksum":278424927,"timestamp":"2024-06-01T17:52:31.891612Z"}]}
{"channel":"book","type":"update","data":[{"symbol":"ETH/AUD","bids":[],"asks":[{"price":5717.70,"qty":0.01300743}],"checksum":3993907808,"timestamp":"2024-06-01T17:52:31.891711Z"}]}
{"channel":"book","type":"update","data":[{"symbol":"ETH/AUD","bids":[],"asks":[{"price":5713.53,"qty":0.90387105}],"checksum":2470469865,"timestamp":"2024-06-01T17:52:32.176945Z"}]}
{"channel":"book","type":"update","data":[{"symbol":"ETH/AUD","bids":[],"asks":[{"price":5714.45,"qty":0.00000000},{"price":5717.70,"qty":0.01300743},{"price":5714.43,"qty":0.52360000}],"checksum":426088260,"timestamp":"2024-06-01T17:52:32.179971Z"}]}
{"channel":"book","type":"update","data":[{"symbol":"ETH/AUD","bids":[],"asks":[{"price":5714.46,"qty":0.00000000},{"price":5717.70,"qty":0.01300743}],"checksum":2431104975,"timestamp":"2024-06-01T17:52:32.182439Z"}]}
{"channel":"book","type":"update","data":[{"symbol":"ETH/AUD","bids":[],"asks":[{"price":5716.43,"qty":0.00000000},{"price":5717.71,"qty":11.18062120},{"price":5713.53,"qty":0.97042505}],"checksum":3314778022,"timestamp":"2024-06-01T17:52:32.196491Z"}]}
{"channel":"book","type":"update","data":[{"symbol":"ETH/AUD","bids":[],"asks":[{"price":5713.54,"qty":0.00000000},{"price":5719.72,"qty":0.08600000},{"price":5713.52,"qty":0.01292326}],"checksum":3904839739,"timestamp":"2024-06-01T17:52:32.205536Z"}]}
{"channel":"book","type":"update","data":[{"symbol":"ETH/AUD","bids":[],"asks":[{"price":5714.43,"qty":0.00000000},{"price":5719.72,"qty":0.08600000}],"checksum":2083624836,"timestamp":"2024-06-01T17:52:32.333294Z"}]}
{"channel":"book","type":"update","data":[{"symbol":"ETH/AUD","bids":[{"price":5705.44,"qty":0.02406309},{"price":5705.40,"qty":0.52360000}],"asks":[],"checksum":381501560,"timestamp":"2024-06-01T17:52:32.333373Z"}]}
{"channel":"book","type":"update","data":[{"symbol":"ETH/AUD","bids":[],"asks":[{"price":5717.70,"qty":0.00000000},{"price":5719.79,"qty":1.60677000}],"checksum":3868383459,"timestamp":"2024-06-01T17:52:32.341241Z"}]}
{"channel":"book","type":"update","data":[{"symbol":"ETH/AUD","bids":[],"asks":[{"price":5717.70,"qty":0.10300678}],"checksum":3342534867,"timestamp":"2024-06-01T17:52:32.341622Z"}]}
{"channel":"book","type":"update","data":[{"symbol":"ETH/AUD","bids":[],"asks":[{"price":5717.70,"qty":0.00000000},{"price":5719.79,"qty":1.60677000}],"checksum":3868383459,"timestamp":"2024-06-01T17:52:32.426759Z"}]}
{"channel":"book","type":"update","data":[{"symbol":"ETH/AUD","bids":[],"asks":[{"price":5717.70,"qty":0.10300543}],"checksum":2462671117,"timestamp":"2024-06-01T17:52:32.426924Z"}]}
{"channel":"book","type":"update","data":[{"symbol":"ETH/AUD","bids":[],"asks":[{"price":5714.44,"qty":0.00000000},{"price":5719.79,"qty":1.60677000},{"price":5713.51,"qty":0.20551408}],"checksum":938535103,"timestamp":"2024-06-01T17:52:32.447994Z"}]}
{"channel":"book","type":"update","data":[{"symbol":"ETH/AUD","bids":[{"price":5708.35,"qty":0.00000000},{"price":5702.47,"qty":4.60670436},{"price":5709.50,"qty":1.03779774}],"asks":[],"checksum":3281857026,"timestamp":"2024-06-01T17:52:32.448042Z"}]}
{"channel":"book","type":"update","data":[{"symbol":"ETH/AUD","bids":[],"asks":[{"price":5716.41,"qty":0.08973579}],"checksum":3152575536,"timestamp":"2024-06-01T17:52:32.535051Z"}]}
{"channel":"book","type":"update","data":[{"symbol":"ETH/AUD","bids":[],"asks":[{"price":5713.71,"qty":0.52360000}],"checksum":1279400152,"timestamp":"2024-06-01T17:52:32.820681Z"}]}
{"channel":"book","type":"update","data":[{"symbol":"ETH/AUD","bids":[{"price":5708.36,"qty":0.00000000},{"price":5702.47,"qty":4.60670436},{"price":5709.51,"qty":0.07347674}],"asks":[],"checksum":1394997797,"timestamp":"2024-06-01T17:52:32.849125Z"}]}
{"channel":"book","type":"update","data":[{"symbol":"ETH/AUD","bids":[],"asks":[{"price":5713.50,"qty":0.90387105}],"checksum":3845310032,"timestamp":"2024-06-01T17:52:33.176393Z"}]}
{"channel":"book","type":"update","data":[{"symbol":"ETH/AUD","bids":[],"asks":[{"price":5713.53,"qty":0.06655400}],"checksum":2519445584,"timestamp":"2024-06-01T17:52:33.182761Z"}]}
{"channel":"book","type":"update","data":[{"symbol":"ETH/AUD","bids":[{"price":5705.39,"qty":0.00000000},{"price":5702.47,"qty":4.60670436}],"asks":[],"checksum":2831634832,"timestamp":"2024-06-01T17:52:33.219200Z"}]}
{"channel":"book","type":"update","data":[{"symbol":"ETH/AUD","bids":[{"price":5702.47,"qty":0.00000000},{"price":5702.46,"qty":2.35323000}],"asks":[],"checksum":1628999136,"timestamp":"2024-06-01T17:52:33.219240Z"}]}
{"channel":"book","type":"update","data":[{"symbol":"ETH/AUD","bids":[{"price":5702.49,"qty":7.54633327}],"asks":[],"checksum":774912160,"timestamp":"2024-06-01T17:52:33.220010Z"}]}
{"channel":"book","type":"update","data":[{"symbol":"ETH/AUD","bids":[{"price":5702.48,"qty":0.00000000},{"price":5702.46,"qty":2.35323000}],"asks":[],"checksum":1023552901,"timestamp":"2024-06-01T17:52:33.223263Z"}]}
{"channel":"book","type":"update","data":[{"symbol":"ETH/AUD","bids":[{"price":5702.50,"qty":0.74683684}],"asks":[],"checksum":1141683217,"timestamp":"2024-06-01T17:52:33.223309Z"}]}
{"channel":"book","type":"update","data":[{"symbol":"ETH/AUD","bids":[],"asks":[{"price":5713.51,"qty":0.00000000},{"price":5717.70,"qty":0.10300543},{"price":5713.49,"qty":0.20538251}],"checksum":1535037072,"timestamp":"2024-06-01T17:52:33.233502Z"}]}
{"channel":"book","type":"update","data":[{"symbol":"ETH/AUD","bids":[{"price":5709.51,"qty":0.00000000},{"price":5702.46,"qty":2.35323000},{"price":5708.35,"qty":0.07347674}],"asks":[],"checksum":2385654307,"timestamp":"2024-06-01T17:52:33.280822Z"}]}
{"channel":"book","type":"update","data":[{"symbol":"ETH/AUD","bids":[{"price":5709.50,"qty":0.00000000},{"price":5702.46,"qty":2.35323000},{"price":5708.36,"qty":1.03803024}],"asks":[],"checksum":4290276539,"timestamp":"2024-06-01T17:52:33.335288Z"}]}
{"channel":"book","type":"update","data":[{"symbol":"ETH/AUD","bids":[{"price":5705.40,"qty":0.00000000},{"price":5702.46,"qty":2.35323000},{"price":5705.26,"qty":0.52360000}],"asks":[],"checksum":667369160,"timestamp":"2024-06-01T17:52:33.338221Z"}]}
{"channel":"book","type":"update","data":[{"symbol":"ETH/AUD","bids":[{"price":5705.42,"qty":0.00000000},{"price":5702.46,"qty":2.35323000}],"asks":[],"checksum":620787462,"timestamp":"2024-06-01T17:52:33.441502Z"}]}
{"channel":"book","type":"update","data":[{"symbol":"ETH/AUD","bids":[{"price":5702.50,"qty":0.79836655}],"asks":[],"checksum":886805757,"timestamp":"2024-06-01T17:52:33.442431Z"}]}
{"channel":"book","type":"update","data":[{"symbol":"ETH/AUD","bids":[{"price":5708.35,"qty":0.00000000},{"price":5700.21,"qty":5.07672000},{"price":5708.37,"qty":0.07347674}],"asks":[],"checksum":983062272,"timestamp":"2024-06-01T17:52:34.071356Z"}]}
{"channel":"book","type":"update","data":[{"symbol":"ETH/AUD","bids":[{"price":5708.44,"qty":0.90387105}],"asks":[],"checksum":2896782902,"timestamp":"2024-06-01T17:52:34.076487Z"}]}
{"channel":"book","type":"update","data":[{"symbol":"ETH/AUD","bids":[],"asks":[{"price":5713.48,"qty":0.90387105}],"checksum":421202790,"timestamp":"2024-06-01T17:52:34.076568Z"}]}
{"channel":"book","type":"update","data":[{"symbol":"ETH/AUD","bids":[{"price":5708.36,"qty":0.00000000},{"price":5702.46,"qty":2.35323000},{"price":5709.50,"qty":1.03782351}],"asks":[],"checksum":314336299,"timestamp":"2024-06-01T17:52:34.137331Z"}]}
{"channel":"book","type":"update","data":[{"symbol":"ETH/AUD","bids":[],"asks":[{"price":5713.49,"qty":0.00000000},{"price":5716.65,"qty":11.96522221},{"price":5713.47,"qty":0.20538278}],"checksum":951723304,"timestamp":"2024-06-01T17:52:34.137409Z"}]}
{"channel":"book","type":"update","data":[{"symbol":"ETH/AUD","bids":[],"asks":[{"price":5713.50,"qty":0.00000000},{"price":5717.70,"qty":0.20717085}],"checksum":219682967,"timestamp":"2024-06-01T17:52:34.142291Z"}]}
{"channel":"book","type":"update","data":[{"symbol":"ETH/AUD","bids":[],"asks":[{"price":5716.40,"qty":2.60756908}],"checksum":120355673,"timestamp":"2024-06-01T17:52:34.144570Z"}]}
{"channel":"book","type":"update","data":[{"symbol":"ETH/AUD","bids":[],"asks":[{"price":5713.71,"qty":0.00000000},{"price":5717.68,"qty":0.20717085},{"price":5716.39,"qty":0.52360000}],"checksum":3878493149,"timestamp":"2024-06-01T17:52:34.252793Z"}]}
{"channel":"book","type":"update","data":[{"symbol":"ETH/AUD","bids":[],"asks":[{"price":5716.42,"qty":0.00000000},{"price":5717.68,"qty":0.20717085}],"checksum":2703501276,"timestamp":"2024-06-01T17:52:34.336463Z"}]}
{"channel":"book","type":"update","data":[{"symbol":"ETH/AUD","bids":[],"asks":[{"price":5716.38,"qty":0.83372964}],"checksum":2886464720,"timestamp":"2024-06-01T17:52:34.369263Z"}]}
{"channel":"book","type":"update","data":[{"symbol":"ETH/AUD","bids":[{"price":5708.37,"qty":0.00000000},{"price":5702.46,"qty":2.35323000},{"price":5708.45,"qty":0.07347674}],"asks":[],"checksum":1201336944,"timestamp":"2024-06-01T17:52:34.445203Z"}]}
{"channel":"book","type":"update","data":[{"symbol":"ETH/AUD","bids":[],"asks":[{"price":5716.41,"qty":0.00000000},{"price":5717.68,"qty":0.20717085}],"checksum":3654611873,"timestamp":"2024-06-01T17:52:34.936910Z"}]}
{"channel":"book","type":"update","data":[{"symbol":"ETH/AUD","bids":[],"asks":[{"price":5716.37,"qty":0.08449379}],"checksum":1545518893,"timestamp":"2024-06-01T17:52:34.938412Z"}]}
{"channel":"book","type":"update","data":[{"symbol":"ETH/AUD","bids":[],"asks":[{"price":5716.39,"qty":0.00000000},{"price":5717.68,"qty":0.20717085},{"price":5716.37,"qty":0.60809379}],"checksum":2345633085,"timestamp":"2024-06-01T17:52:34.943791Z"}]}
{"channel":"book","type":"update","data":[{"symbol":"ETH/AUD","bids":[],"asks":[{"price":5713.52,"qty":0.00000000},{"price":5717.69,"qty":10.90231450},{"price":5713.46,"qty":0.01292326}],"checksum":1050675698,"timestamp":"2024-06-01T17:52:35.058030Z"}]}
{"channel":"book","type":"update","data":[{"symbol":"ETH/AUD","bids":[],"asks":[{"price":5713.45,"qty":0.90387105}],"checksum":2554502074,"timestamp":"2024-06-01T17:52:35.063834Z"}]}
{"channel":"book","type":"update","data":[{"symbol":"ETH/AUD","bids":[],"asks":[{"price":5713.47,"qty":0.00000000},{"price":5717.68,"qty":0.20717085},{"price":5713.44,"qty":0.20537914}],"checksum":3320267180,"timestamp":"2024-06-01T17:52:35.115019Z"}]}
{"channel":"book","type":"update","data":[{"symbol":"ETH/AUD","bids":[],"asks":[{"price":5713.48,"qty":0.00000000},{"price":5717.68,"qty":0.20717085}],"checksum":2287036454,"timestamp":"2024-06-01T17:52:35.120251Z"}]}
{"channel":"book","type":"update","data":[{"symbol":"ETH/AUD","bids":[],"asks":[{"price":5713.46,"qty":0.00000000},{"price":5717.69,"qty":10.90231450},{"price":5713.43,"qty":0.01292326}],"checksum":879806557,"timestamp":"2024-06-01T17:52:35.639456Z"}]}
{"channel":"book","type":"update","data":[{"symbol":"ETH/AUD","bids":[],"asks":[{"price":5713.44,"qty":0.00000000},{"price":5717.69,"qty":10.90231450},{"price":5713.42,"qty":0.20537926}],"checksum":1133840376,"timestamp":"2024-06-01T17:52:35.863341Z"}]}
{"channel":"book","type":"update","data":[{"symbol":"ETH/AUD","bids":[],"asks":[{"price":5713.41,"qty":0.90387105}],"checksum":1618432436,"timestamp":"2024-06-01T17:52:36.178860Z"}]}
{"channel":"book","type":"update","data":[{"symbol":"ETH/AUD","bids":[],"asks":[{"price":5713.45,"qty":0.00000000},{"price":5717.68,"qty":0.20717085}],"checksum":351963646,"timestamp":"2024-06-01T17:52:36.183615Z"}]}
{"channel":"book","type":"update","data":[{"symbol":"ETH/AUD","bids":[],"asks":[{"price":5713.43,"qty":0.00000000},{"price":5717.69,"qty":10.90231450},{"price":5713.40,"qty":0.01292326}],"checksum":3727733061,"timestamp":"2024-06-01T17:52:36.186706Z"}]}
{"channel":"book","type":"update","data":[{"symbol":"ETH/AUD","bids":[{"price":5702.49,"qty":0.00000000},{"price":5702.46,"qty":2.35323000}],"asks":[],"checksum":3322764495,"timestamp":"2024-06-01T17:52:36.234136Z"}]}
{"channel":"book","type":"update","data":[{"symbol":"ETH/AUD","bids":[{"price":5702.51,"qty":6.93647608}],"asks":[],"checksum":2420635683,"timestamp":"2024-06-01T17:52:36.235441Z"}]}
{"channel":"book","type":"update","data":[{"symbol":"ETH/AUD","bids":[{"price":5702.50,"qty":0.05152971}],"asks":[],"checksum":3645194473,"timestamp":"2024-06-01T17:52:36.245803Z"}]}
{"channel":"book","type":"update","data":[{"symbol":"ETH/AUD","bids":[{"price":5702.52,"qty":0.74683422}],"asks":[],"checksum":1013124940,"timestamp":"2024-06-01T17:52:36.245925Z"}]}
{"channel":"book","type":"update","data":[{"symbol":"ETH/AUD","bids":[{"price":5702.51,"qty":6.98286934}],"asks":[],"checksum":4051618577,"timestamp":"2024-06-01T17:52:36.353320Z"}]}
{"channel":"book","type":"update","data":[{"symbol":"ETH/AUD","bids":[],"asks":[{"price":5716.40,"qty":0.00000000},{"price":5717.71,"qty":11.18062120}],"checksum":384289877,"timestamp":"2024-06-01T17:52:36.476608Z"}]}
{"channel":"book","type":"update","data":[{"symbol":"ETH/AUD","bids":[],"asks":[{"price":5716.36,"qty":5.72865327}],"checksum":3421117690,"timestamp":"2024-06-01T17:52:36.480109Z"}]}
{"channel":"book","type":"update","data":[{"symbol":"ETH/AUD","bids":[],"asks":[{"price":5717.67,"qty":8.79977573}],"checksum":3818675362,"timestamp":"2024-06-01T17:52:36.480369Z"}]}
{"channel":"book","type":"update","data":[{"symbol":"ETH/AUD","bids":[],"asks":[{"price":5716.37,"qty":0.08449379},{"price":5716.35,"qty":0.52360000}],"checksum":2092191314,"timestamp":"2024-06-01T17:52:36.483875Z"}]}
{"channel":"book","type":"update","data":[{"symbol":"ETH/AUD","bids":[],"asks":[{"price":5713.42,"qty":0.00000000},{"price":5717.66,"qty":0.20717085},{"price":5713.39,"qty":0.20537178}],"checksum":449810820,"timestamp":"2024-06-01T17:52:36.645785Z"}]}
{"channel":"book","type":"update","data":[{"symbol":"ETH/AUD","bids":[],"asks":[{"price":5713.40,"qty":0.00000000},{"price":5717.66,"qty":0.20717085},{"price":5713.38,"qty":0.01292326}],"checksum":299700453,"timestamp":"2024-06-01T17:52:36.987029Z"}]}
{"channel":"book","type":"update","data":[{"symbol":"ETH/AUD","bids":[],"asks":[{"price":5713.37,"qty":0.90387105}],"checksum":2085832146,"timestamp":"2024-06-01T17:52:36.993744Z"}]}
{"channel":"book","type":"update","data":[{"symbol":"ETH/AUD","bids":[],"asks":[{"price":5716.37,"qty":0.00000000},{"price":5716.55,"qty":0.09600000}],"checksum":1120291420,"timestamp":"2024-06-01T17:52:37.134299Z"}]}
{"channel":"book","type":"update","data":[{"symbol":"ETH/AUD","bids":[],"asks":[{"price":5716.34,"qty":0.10033924}],"checksum":188261019,"timestamp":"2024-06-01T17:52:37.136267Z"}]}
{"channel":"book","type":"update","data":[{"symbol":"ETH/AUD","bids":[],"asks":[{"price":5716.35,"qty":0.00000000},{"price":5716.55,"qty":0.09600000},{"price":5716.33,"qty":0.52360000}],"checksum":2447055240,"timestamp":"2024-06-01T17:52:37.139493Z"}]}
{"channel":"book","type":"update","data":[{"symbol":"ETH/AUD","bids":[],"asks":[{"price":5713.41,"qty":0.00000000},{"price":5716.55,"qty":0.09600000}],"checksum":3071675444,"timestamp":"2024-06-01T17:52:37.177046Z"}]}
{"channel":"book","type":"update","data":[{"symbol":"ETH/AUD","bids":[],"asks":[{"price":5713.39,"qty":0.00000000},{"price":5717.66,"qty":0.20717085},{"price":5713.36,"qty":0.20537155}],"checksum":3316317433,"timestamp":"2024-06-01T17:52:37.379477Z"}]}
{"channel":"book","type":"update","data":[{"symbol":"ETH/AUD","bids":[],"asks":[{"price":5713.35,"qty":0.90387105}],"checksum":4207441038,"timestamp":"2024-06-01T17:52:37.384918Z"}]}
{"channel":"book","type":"update","data":[{"symbol":"ETH/AUD","bids":[],"asks":[{"price":5713.38,"qty":0.00000000},{"price":5716.55,"qty":0.09600000},{"price":5713.34,"qty":0.01292326}],"checksum":1730470528,"timestamp":"2024-06-01T17:52:37.415288Z"}]}
{"channel":"book","type":"update","data":[{"symbol":"ETH/AUD","bids":[],"asks":[{"price":5716.38,"qty":0.00000000},{"price":5716.55,"qty":0.09600000}],"checksum":491949906,"timestamp":"2024-06-01T17:52:37.416782Z"}]}
{"channel":"book","type":"update","data":[{"symbol":"ETH/AUD","bids":[],"asks":[{"price":5713.37,"qty":0.00000000},{"price":5717.66,"qty":0.20717085}],"checksum":3848091798,"timestamp":"2024-06-01T17:52:37.420259Z"}]}
{"channel":"book","type":"update","data":[{"symbol":"ETH/AUD","bids":[],"asks":[{"price":5714.70,"qty":0.83372964}],"checksum":1777845419,"timestamp":"2024-06-01T17:52:37.447792Z"}]}
{"channel":"book","type":"update","data":[{"symbol":"ETH/AUD","bids":[],"asks":[{"price":5714.70,"qty":0.00000000},{"price":5717.66,"qty":0.20717085}],"checksum":3848091798,"timestamp":"2024-06-01T17:52:37.625738Z"}]}
{"channel":"book","type":"update","data":[{"symbol":"ETH/AUD","bids":[],"asks":[{"price":5716.32,"qty":0.83372964}],"checksum":935736276,"timestamp":"2024-06-01T17:52:37.656860Z"}]}
{"channel":"book","type":"update","data":[{"symbol":"ETH/AUD","bids":[],"asks":[{"price":5716.33,"qty":0.00000000},{"price":5717.66,"qty":0.20717085},{"price":5716.31,"qty":0.52360000}],"checksum":603035781,"timestamp":"2024-06-01T17:52:37.659817Z"}]}
{"channel":"book","type":"update","data":[{"symbol":"ETH/AUD","bids":[],"asks":[{"price":5713.35,"qty":0.00000000},{"price":5717.66,"qty":0.20717085}],"checksum":3373919987,"timestamp":"2024-06-01T17:52:37.984636Z"}]}
{"channel":"book","type":"update","data":[{"symbol":"ETH/AUD","bids":[],"asks":[{"price":5717.66,"qty":0.21492253}],"checksum":4236122402,"timestamp":"2024-06-01T17:52:37.989211Z"}]}
{"channel":"book","type":"update","data":[{"symbol":"ETH/AUD","bids":[{"price":5709.51,"qty":0.90387105}],"asks":[],"checksum":4208325757,"timestamp":"2024-06-01T17:52:37.991370Z"}]}
{"channel":"book","type":"update","data":[{"symbol":"ETH/AUD","bids":[],"asks":[{"price":5717.66,"qty":0.00775168}],"checksum":1748860672,"timestamp":"2024-06-01T17:52:37.991753Z"}]}
{"channel":"book","type":"update","data":[{"symbol":"ETH/AUD","bids":[{"price":5708.45,"qty":0.00000000},{"price":5702.51,"qty":6.98286934},{"price":5709.52,"qty":0.07347674}],"asks":[],"checksum":3920918487,"timestamp":"2024-06-01T17:52:38.026507Z"}]}
{"channel":"book","type":"update","data":[{"symbol":"ETH/AUD","bids":[],"asks":[{"price":5713.36,"qty":0.00000000},{"price":5717.67,"qty":8.79977573},{"price":5716.30,"qty":0.20537149}],"checksum":3271842590,"timestamp":"2024-06-01T17:52:38.029560Z"}]}
{"channel":"book","type":"update","data":[{"symbol":"ETH/AUD","bids":[],"asks":[{"price":5716.55,"qty":0.00000000},{"price":5717.67,"qty":8.79977573}],"checksum":3222041527,"timestamp":"2024-06-01T17:52:38.040888Z"}]}
{"channel":"book","type":"update","data":[{"symbol":"ETH/AUD","bids":[{"price":5703.14,"qty":0.09000000}],"asks":[],"checksum":3293226923,"timestamp":"2024-06-01T17:52:38.053674Z"}]}
{"channel":"book","type":"update","data":[{"symbol":"ETH/AUD","bids":[{"price":5708.44,"qty":0.00000000},{"price":5702.52,"qty":0.74683422}],"asks":[],"checksum":2607145686,"timestamp":"2024-06-01T17:52:38.059280Z"}]}
{"channel":"book","type":"update","data":[{"symbol":"ETH/AUD","bids":[{"price":5709.50,"qty":0.00000000},{"price":5702.51,"qty":6.98286934},{"price":5709.53,"qty":1.03782089}],"asks":[],"checksum":4078570612,"timestamp":"2024-06-01T17:52:38.090358Z"}]}
{"channel":"book","type":"update","data":[{"symbol":"ETH/AUD","bids":[],"asks":[{"price":5713.53,"qty":0.00000000},{"price":5717.71,"qty":11.18062120},{"price":5714.23,"qty":0.06655200}],"checksum":3120703488,"timestamp":"2024-06-01T17:52:38.135879Z"}]}
{"channel":"book","type":"update","data":[{"symbol":"ETH/AUD","bids":[],"asks":[{"price":5716.32,"qty":0.00000000},{"price":5717.71,"qty":11.18062120}],"checksum":4006597586,"timestamp":"2024-06-01T17:52:38.136874Z"}]}
{"channel":"book","type":"update","data":[{"symbol":"ETH/AUD","bids":[],"asks":[{"price":5717.65,"qty":0.83372964}],"checksum":3028270655,"timestamp":"2024-06-01T17:52:38.169813Z"}]}
{"channel":"book","type":"update","data":[{"symbol":"ETH/AUD","bids":[],"asks":[{"price":5716.31,"qty":0.00000000},{"price":5717.71,"qty":11.18062120},{"price":5716.29,"qty":0.52360000}],"checksum":1244990559,"timestamp":"2024-06-01T17:52:38.173086Z"}]}
{"channel":"book","type":"update","data":[{"symbol":"ETH/AUD","bids":[],"asks":[{"price":5716.29,"qty":0.00000000},{"price":5717.71,"qty":11.18062120}],"checksum":112827552,"timestamp":"2024-06-01T17:52:38.357340Z"}]}
{"channel":"book","type":"update","data":[{"symbol":"ETH/AUD","bids":[],"asks":[{"price":5716.30,"qty":0.00000000},{"price":5719.72,"qty":0.08600000},{"price":5716.33,"qty":0.20544796}],"checksum":1298472780,"timestamp":"2024-06-01T17:52:38.400576Z"}]}
{"channel":"book","type":"update","data":[{"symbol":"ETH/AUD","bids":[{"price":5709.52,"qty":0.00000000},{"price":5702.51,"qty":6.98286934},{"price":5709.54,"qty":0.07347674}],"asks":[],"checksum":2945556262,"timestamp":"2024-06-01T17:52:38.730652Z"}]}
{"channel":"book","type":"update","data":[{"symbol":"ETH/AUD","bids":[],"asks":[{"price":5716.55,"qty":0.52360000}],"checksum":3357428065,"timestamp":"2024-06-01T17:52:38.733947Z"}]}
{"channel":"book","type":"update","data":[{"symbol":"ETH/AUD","bids":[],"asks":[{"price":5714.23,"qty":0.00000000},{"price":5717.71,"qty":11.18062120},{"price":5714.73,"qty":0.06654500}],"checksum":2656257355,"timestamp":"2024-06-01T17:52:38.750390Z"}]}
{"channel":"book","type":"update","data":[{"symbol":"ETH/AUD","bids":[{"price":5709.53,"qty":0.00000000},{"price":5702.51,"qty":6.98286934},{"price":5709.55,"qty":1.03780291}],"asks":[],"checksum":1720337371,"timestamp":"2024-06-01T17:52:38.842061Z"}]}
{"channel":"book","type":"update","data":[{"symbol":"ETH/AUD","bids":[],"asks":[{"price":5717.67,"qty":0.00000000},{"price":5717.71,"qty":11.18062120}],"checksum":4191784781,"timestamp":"2024-06-01T17:52:38.897820Z"}]}
{"channel":"book","type":"update","data":[{"symbol":"ETH/AUD","bids":[],"asks":[{"price":5716.36,"qty":0.00000000},{"price":5719.72,"qty":0.08600000}],"checksum":2131835269,"timestamp":"2024-06-01T17:52:38.897973Z"}]}
{"channel":"book","type":"update","data":[{"symbol":"ETH/AUD","bids":[],"asks":[{"price":5717.64,"qty":12.49076156}],"checksum":1367083582,"timestamp":"2024-06-01T17:52:38.902713Z"}]}
{"channel":"book","type":"update","data":[{"symbol":"ETH/AUD","bids":[],"asks":[{"price":5717.66,"qty":0.00000000},{"price":5719.72,"qty":0.08600000}],"checksum":2573662230,"timestamp":"2024-06-01T17:52:38.904552Z"}]}
{"channel":"book","type":"update","data":[{"symbol":"ETH/AUD","bids":[],"asks":[{"price":5717.64,"qty":12.49851327}],"checksum":80734207,"timestamp":"2024-06-01T17:52:38.904618Z"}]}
{"channel":"book","type":"update","data":[{"symbol":"ETH/AUD","bids":[{"price":5709.56,"qty":0.90387105}],"asks":[],"checksum":4082992855,"timestamp":"2024-06-01T17:52:39.175490Z"}]}
{"channel":"book","type":"update","data":[{"symbol":"ETH/AUD","bids":[{"price":5709.54,"qty":0.00000000},{"price":5702.52,"qty":0.74683422},{"price":5709.57,"qty":0.07347674}],"asks":[],"checksum":3633065423,"timestamp":"2024-06-01T17:52:39.188386Z"}]}
{"channel":"book","type":"update","data":[{"symbol":"ETH/AUD","bids":[{"price":5703.15,"qty":0.74675173}],"asks":[],"checksum":2370554938,"timestamp":"2024-06-01T17:52:39.263083Z"}]}
{"channel":"book","type":"update","data":[{"symbol":"ETH/AUD","bids":[],"asks":[{"price":5716.55,"qty":0.00000000},{"price":5719.79,"qty":1.60677000},{"price":5716.32,"qty":0.52360000}],"checksum":3188238222,"timestamp":"2024-06-01T17:52:39.399889Z"}]}
{"channel":"book","type":"update","data":[{"symbol":"ETH/AUD","bids":[{"price":5709.51,"qty":0.00000000},{"price":5703.14,"qty":0.09000000}],"asks":[],"checksum":2646787353,"timestamp":"2024-06-01T17:52:39.405274Z"}]}
{"channel":"book","type":"update","data":[{"symbol":"ETH/AUD","bids":[],"asks":[{"price":5716.34,"qty":0.00000000},{"price":5719.79,"qty":1.60677000}],"checksum":2696401997,"timestamp":"2024-06-01T17:52:39.479995Z"}]}
{"channel":"book","type":"update","data":[{"symbol":"ETH/AUD","bids":[],"asks":[{"price":5716.32,"qty":0.52886752}],"checksum":3299381831,"timestamp":"2024-06-01T17:52:39.482085Z"}]}
{"channel":"book","type":"update","data":[{"symbol":"ETH/AUD","bids":[],"asks":[{"price":5717.63,"qty":0.09750778}],"checksum":3522675546,"timestamp":"2024-06-01T17:52:39.482218Z"}]}
{"channel":"book","type":"update","data":[{"symbol":"ETH/AUD","bids":[],"asks":[{"price":5717.62,"qty":0.00775173}],"checksum":2867834984,"timestamp":"2024-06-01T17:52:39.513549Z"}]}
{"channel":"book","type":"update","data":[{"symbol":"ETH/AUD","bids":[],"asks":[{"price":5717.64,"qty":12.49076156}],"checksum":3939287609,"timestamp":"2024-06-01T17:52:39.513573Z"}]}
{"channel":"book","type":"update","data":[{"symbol":"ETH/AUD","bids":[{"price":5705.26,"qty":0.00000000},{"price":5702.53,"qty":7.77274151},{"price":5708.35,"qty":0.52360000}],"asks":[],"checksum":1584563884,"timestamp":"2024-06-01T17:52:39.582378Z"}]}
{"channel":"book","type":"update","data":[{"symbol":"ETH/AUD","bids":[{"price":5709.55,"qty":0.00000000},{"price":5702.53,"qty":7.77274151},{"price":5709.58,"qty":1.03779638}],"asks":[],"checksum":2222488880,"timestamp":"2024-06-01T17:52:39.600068Z"}]}
{"channel":"book","type":"update","data":[{"symbol":"ETH/AUD","bids":[],"asks":[{"price":5716.33,"qty":0.00000000},{"price":5719.72,"qty":0.08600000},{"price":5716.31,"qty":0.20545999}],"checksum":125009797,"timestamp":"2024-06-01T17:52:39.600247Z"}]}
{"channel":"book","type":"update","data":[{"symbol":"ETH/AUD","bids":[{"price":5708.35,"qty":0.00000000},{"price":5702.53,"qty":7.77274151}],"asks":[],"checksum":1985818764,"timestamp":"2024-06-01T17:52:39.756520Z"}]}
{"channel":"book","type":"update","data":[{"symbol":"ETH/AUD","bids":[{"price":5709.57,"qty":0.00000000},{"price":5702.46,"qty":2.35323000},{"price":5709.59,"qty":0.07347674}],"asks":[],"checksum":1979125026,"timestamp":"2024-06-01T17:52:39.774131Z"}]}
{"channel":"book","type":"update","data":[{"symbol":"ETH/AUD","bids":[],"asks":[{"price":5716.32,"qty":0.00526752},{"price":5716.30,"qty":0.52360000}],"checksum":366014200,"timestamp":"2024-06-01T17:52:39.912224Z"}]}
{"channel":"book","type":"update","data":[{"symbol":"ETH/AUD","bids":[{"price":5709.60,"qty":0.90387105}],"asks":[],"checksum":602205132,"timestamp":"2024-06-01T17:52:39.917437Z"}]}
{"channel":"book","type":"update","data":[{"symbol":"ETH/AUD","bids":[],"asks":[{"price":5713.33,"qty":0.90387105}],"checksum":573992872,"timestamp":"2024-06-01T17:52:39.917507Z"}]}
{"channel":"book","type":"update","data":[{"symbol":"ETH/AUD","bids":[{"price":5709.56,"qty":0.00000000},{"price":5702.53,"qty":7.77274151}],"asks":[],"checksum":2785278138,"timestamp":"2024-06-01T17:52:40.177191Z"}]}
{"channel":"book","type":"update","data":[{"symbol":"ETH/AUD","bids":[{"price":5704.96,"qty":0.52360000}],"asks":[],"checksum":2394846479,"timestamp":"2024-06-01T17:52:40.180040Z"}]}
{"channel":"book","type":"update","data":[{"symbol":"ETH/AUD","bids":[{"price":5709.58,"qty":0.00000000},{"price":5702.53,"qty":7.77274151},{"price":5709.61,"qty":1.03779060}],"asks":[],"checksum":3496560794,"timestamp":"2024-06-01T17:52:40.344498Z"}]}
{"channel":"book","type":"update","data":[{"symbol":"ETH/AUD","bids":[],"asks":[{"price":5716.31,"qty":0.00000000},{"price":5717.65,"qty":0.83372964},{"price":5713.32,"qty":0.20545994}],"checksum":1110869983,"timestamp":"2024-06-01T17:52:40.344665Z"}]}
{"channel":"book","type":"update","data":[{"symbol":"ETH/AUD","bids":[],"asks":[{"price":5714.73,"qty":0.00000000},{"price":5717.65,"qty":0.83372964},{"price":5714.16,"qty":0.06654900}],"checksum":3924326251,"timestamp":"2024-06-01T17:52:40.351674Z"}]}
{"channel":"book","type":"update","data":[{"symbol":"ETH/AUD","bids":[{"price":5709.59,"qty":0.00000000},{"price":5702.53,"qty":7.77274151},{"price":5709.62,"qty":0.07347674}],"asks":[],"checksum":2501468118,"timestamp":"2024-06-01T17:52:40.353939Z"}]}
{"channel":"book","type":"update","data":[{"symbol":"ETH/AUD","bids":[],"asks":[{"price":5713.34,"qty":0.00000000},{"price":5717.65,"qty":0.83372964},{"price":5713.31,"qty":0.01292326}],"checksum":439465805,"timestamp":"2024-06-01T17:52:40.990647Z"}]}
{"channel":"book","type":"update","data":[{"symbol":"ETH/AUD","bids":[],"asks":[{"price":5716.30,"qty":0.00000000},{"price":5717.65,"qty":0.83372964},{"price":5717.62,"qty":0.53135173}],"checksum":17971751,"timestamp":"2024-06-01T17:52:40.994041Z"}]}
{"channel":"book","type":"update","data":[{"symbol":"ETH/AUD","bids":[{"price":5709.63,"qty":0.90387105}],"asks":[],"checksum":3019822677,"timestamp":"2024-06-01T17:52:40.996269Z"}]}
{"channel":"book","type":"update","data":[{"symbol":"ETH/AUD","bids":[{"price":5704.96,"qty":0.00000000},{"price":5703.14,"qty":0.09000000},{"price":5705.26,"qty":0.52360000}],"asks":[],"checksum":1430491576,"timestamp":"2024-06-01T17:52:41.003940Z"}]}
{"channel":"book","type":"update","data":[{"symbol":"ETH/AUD","bids":[{"price":5709.61,"qty":0.00000000},{"price":5703.14,"qty":0.09000000},{"price":5709.64,"qty":1.03777554}],"asks":[],"checksum":2377132273,"timestamp":"2024-06-01T17:52:41.071978Z"}]}
{"channel":"book","type":"update","data":[{"symbol":"ETH/AUD","bids":[],"asks":[{"price":5713.32,"qty":0.00000000},{"price":5717.71,"qty":11.18062120},{"price":5713.30,"qty":0.20550235}],"checksum":4268728187,"timestamp":"2024-06-01T17:52:41.072029Z"}]}
{"channel":"book","type":"update","data":[{"symbol":"ETH/AUD","bids":[{"price":5709.60,"qty":0.00000000},{"price":5703.14,"qty":0.09000000}],"asks":[],"checksum":3350813673,"timestamp":"2024-06-01T17:52:41.078681Z"}]}
{"channel":"book","type":"update","data":[{"symbol":"ETH/AUD","bids":[{"price":5709.62,"qty":0.00000000},{"price":5702.53,"qty":7.77274151},{"price":5709.65,"qty":0.07347674}],"asks":[],"checksum":1306039887,"timestamp":"2024-06-01T17:52:41.419181Z"}]}
{"channel":"book","type":"update","data":[{"symbol":"ETH/AUD","bids":[],"asks":[{"price":5717.64,"qty":0.00000000},{"price":5717.71,"qty":11.18062120}],"checksum":1447658903,"timestamp":"2024-06-01T17:52:41.445265Z"}]}
{"channel":"book","type":"update","data":[{"symbol":"ETH/AUD","bids":[],"asks":[{"price":5717.61,"qty":13.53111200}],"checksum":1217845350,"timestamp":"2024-06-01T17:52:41.448186Z"}]}
{"channel":"book","type":"update","data":[{"symbol":"ETH/AUD","bids":[],"asks":[{"price":5717.62,"qty":0.52360000}],"checksum":315355072,"timestamp":"2024-06-01T17:52:41.459112Z"}]}
{"channel":"book","type":"update","data":[{"symbol":"ETH/AUD","bids":[],"asks":[{"price":5717.60,"qty":0.00775176}],"checksum":3769591748,"timestamp":"2024-06-01T17:52:41.459229Z"}]}
{"channel":"book","type":"update","data":[{"symbol":"ETH/AUD","bids":[],"asks":[{"price":5717.59,"qty":0.83372964}],"checksum":3443288545,"timestamp":"2024-06-01T17:52:41.492289Z"}]}
{"channel":"book","type":"update","data":[{"symbol":"ETH/AUD","bids":[],"asks":[{"price":5717.62,"qty":0.00000000},{"price":5717.63,"qty":0.09750778},{"price":5717.58,"qty":0.52360000}],"checksum":386233355,"timestamp":"2024-06-01T17:52:41.495389Z"}]}
{"channel":"book","type":"update","data":[{"symbol":"ETH/AUD","bids":[],"asks":[{"price":5717.57,"qty":0.00775180}],"checksum":1609707840,"timestamp":"2024-06-01T17:52:41.517116Z"}]}
{"channel":"book","type":"update","data":[{"symbol":"ETH/AUD","bids":[],"asks":[{"price":5717.60,"qty":0.00000000},{"price":5717.61,"qty":13.53111200}],"checksum":877575650,"timestamp":"2024-06-01T17:52:41.517164Z"}]}
{"channel":"book","type":"update","data":[{"symbol":"ETH/AUD","bids":[],"asks":[{"price":5716.32,"qty":0.00000000},{"price":5717.63,"qty":0.09750778}],"checksum":399224375,"timestamp":"2024-06-01T17:52:41.854191Z"}]}
{"channel":"book","type":"update","data":[{"symbol":"ETH/AUD","bids":[],"asks":[{"price":5717.63,"qty":0.00000000},{"price":5717.71,"qty":11.18062120}],"checksum":129507404,"timestamp":"2024-06-01T17:52:41.854354Z"}]}
{"channel":"book","type":"update","data":[{"symbol":"ETH/AUD","bids":[],"asks":[{"price":5717.56,"qty":0.00526766}],"checksum":3336606125,"timestamp":"2024-06-01T17:52:41.855944Z"}]}
{"channel":"book","type":"update","data":[{"symbol":"ETH/AUD","bids":[],"asks":[{"price":5717.57,"qty":0.10373602}],"checksum":1449356921,"timestamp":"2024-06-01T17:52:41.856006Z"}]}
{"channel":"book","type":"update","data":[{"symbol":"ETH/AUD","bids":[{"price":5709.64,"qty":0.00000000},{"price":5702.53,"qty":7.77274151},{"price":5709.66,"qty":1.03777183}],"asks":[],"checksum":1727926825,"timestamp":"2024-06-01T17:52:41.873257Z"}]}
{"channel":"book","type":"update","data":[{"symbol":"ETH/AUD","bids":[{"price":5709.67,"qty":0.90387105}],"asks":[],"checksum":2080741833,"timestamp":"2024-06-01T17:52:42.175751Z"}]}
{"channel":"book","type":"update","data":[{"symbol":"ETH/AUD","bids":[],"asks":[{"price":5717.58,"qty":0.00000000},{"price":5717.71,"qty":11.18062120},{"price":5717.56,"qty":0.52886766}],"checksum":2302906149,"timestamp":"2024-06-01T17:52:42.179539Z"}]}
{"channel":"book","type":"update","data":[{"symbol":"ETH/AUD","bids":[],"asks":[{"price":5717.57,"qty":0.09598422}],"checksum":690785225,"timestamp":"2024-06-01T17:52:42.186487Z"}]}
{"channel":"book","type":"update","data":[{"symbol":"ETH/AUD","bids":[],"asks":[{"price":5717.55,"qty":0.00775183}],"checksum":2980866585,"timestamp":"2024-06-01T17:52:42.187011Z"}]}
{"channel":"book","type":"update","data":[{"symbol":"ETH/AUD","bids":[{"price":5709.65,"qty":0.00000000},{"price":5703.14,"qty":0.09000000},{"price":5709.68,"qty":0.07347674}],"asks":[],"checksum":306978697,"timestamp":"2024-06-01T17:52:42.211993Z"}]}
{"channel":"book","type":"update","data":[{"symbol":"ETH/AUD","bids":[{"price":5709.63,"qty":0.00000000},{"price":5703.14,"qty":0.09000000}],"asks":[],"checksum":3085298299,"timestamp":"2024-06-01T17:52:42.216987Z"}]}
{"channel":"book","type":"update","data":[{"symbol":"ETH/AUD","bids":[{"price":5705.27,"qty":0.52676573}],"asks":[],"checksum":3097956875,"timestamp":"2024-06-01T17:52:42.253564Z"}]}
{"channel":"book","type":"update","data":[{"symbol":"ETH/AUD","bids":[{"price":5703.16,"qty":7.06619708}],"asks":[],"checksum":3528626745,"timestamp":"2024-06-01T17:52:42.253767Z"}]}
{"channel":"book","type":"update","data":[{"symbol":"ETH/AUD","bids":[{"price":5705.26,"qty":0.00000000},{"price":5703.15,"qty":0.74675173},{"price":5705.28,"qty":0.52360000}],"asks":[],"checksum":4143984267,"timestamp":"2024-06-01T17:52:42.256444Z"}]}
{"channel":"book","type":"update","data":[{"symbol":"ETH/AUD","bids":[{"price":5703.17,"qty":0.74674910}],"asks":[],"checksum":3536054494,"timestamp":"2024-06-01T17:52:42.275973Z"}]}
{"channel":"book","type":"update","data":[{"symbol":"ETH/AUD","bids":[{"price":5705.27,"qty":0.53203339}],"asks":[],"checksum":4026099518,"timestamp":"2024-06-01T17:52:42.289952Z"}]}
{"channel":"book","type":"update","data":[{"symbol":"ETH/AUD","bids":[],"asks":[{"price":5713.31,"qty":0.00000000},{"price":5717.71,"qty":11.18062120},{"price":5713.29,"qty":0.01292326}],"checksum":973825258,"timestamp":"2024-06-01T17:52:42.609463Z"}]}
{"channel":"book","type":"update","data":[{"symbol":"ETH/AUD","bids":[{"price":5709.66,"qty":0.00000000},{"price":5703.16,"qty":7.12047832},{"price":5709.69,"qty":1.03776633}],"asks":[],"checksum":1204385118,"timestamp":"2024-06-01T17:52:42.628760Z"}]}
{"channel":"book","type":"update","data":[{"symbol":"ETH/AUD","bids":[],"asks":[{"price":5713.28,"qty":0.90387105}],"checksum":1812755062,"timestamp":"2024-06-01T17:52:43.178504Z"}]}
{"channel":"book","type":"update","data":[{"symbol":"ETH/AUD","bids":[{"price":5709.70,"qty":0.90387105}],"asks":[],"checksum":4074627131,"timestamp":"2024-06-01T17:52:43.178593Z"}]}
{"channel":"book","type":"update","data":[{"symbol":"ETH/AUD","bids":[],"asks":[{"price":5713.33,"qty":0.00000000},{"price":5717.61,"qty":13.53111200}],"checksum":3554523012,"timestamp":"2024-06-01T17:52:43.185396Z"}]}
{"channel":"book","type":"update","data":[{"symbol":"ETH/AUD","bids":[{"price":5709.67,"qty":0.00000000},{"price":5703.17,"qty":0.74674910}],"asks":[],"checksum":3882792592,"timestamp":"2024-06-01T17:52:43.185419Z"}]}
{"channel":"book","type":"update","data":[{"symbol":"ETH/AUD","bids":[{"price":5709.68,"qty":0.00000000},{"price":5703.16,"qty":7.12047832},{"price":5709.71,"qty":0.07347674}],"asks":[],"checksum":1243754303,"timestamp":"2024-06-01T17:52:43.186529Z"}]}
{"channel":"book","type":"update","data":[{"symbol":"ETH/AUD","bids":[{"price":5709.69,"qty":0.00000000},{"price":5703.16,"qty":7.12047832},{"price":5709.72,"qty":1.03776216}],"asks":[],"checksum":3123669717,"timestamp":"2024-06-01T17:52:43.344359Z"}]}
{"channel":"book","type":"update","data":[{"symbol":"ETH/AUD","bids":[],"asks":[{"price":5713.30,"qty":0.00000000},{"price":5717.71,"qty":11.18062120},{"price":5713.27,"qty":0.20550251}],"checksum":27610298,"timestamp":"2024-06-01T17:52:43.344436Z"}]}
{"channel":"book","type":"update","data":[{"symbol":"ETH/AUD","bids":[{"price":5709.71,"qty":0.00000000},{"price":5703.16,"qty":7.12047832},{"price":5709.73,"qty":0.07347674}],"asks":[],"checksum":927487264,"timestamp":"2024-06-01T17:52:43.855189Z"}]}
{"channel":"book","type":"update","data":[{"symbol":"ETH/AUD","bids":[],"asks":[{"price":5717.61,"qty":0.00000000},{"price":5717.71,"qty":11.18062120}],"checksum":1806323379,"timestamp":"2024-06-01T17:52:43.856670Z"}]}
{"channel":"book","type":"update","data":[{"symbol":"ETH/AUD","bids":[],"asks":[{"price":5717.55,"qty":12.06772715}],"checksum":3230195489,"timestamp":"2024-06-01T17:52:43.861329Z"}]}
{"channel":"book","type":"update","data":[{"symbol":"ETH/AUD","bids":[],"asks":[{"price":5717.56,"qty":0.00526766},{"price":5717.54,"qty":0.52360000}],"checksum":1707529274,"timestamp":"2024-06-01T17:52:43.864437Z"}]}
{"channel":"book","type":"update","data":[{"symbol":"ETH/AUD","bids":[],"asks":[{"price":5717.55,"qty":12.05997532}],"checksum":3382717181,"timestamp":"2024-06-01T17:52:43.889096Z"}]}
{"channel":"book","type":"update","data":[{"symbol":"ETH/AUD","bids":[],"asks":[{"price":5717.53,"qty":0.00775186}],"checksum":3057647558,"timestamp":"2024-06-01T17:52:43.889305Z"}]}
{"channel":"book","type":"update","data":[{"symbol":"ETH/AUD","bids":[{"price":5709.72,"qty":0.00000000},{"price":5703.16,"qty":7.12047832},{"price":5709.74,"qty":1.03775849}],"asks":[],"checksum":667907539,"timestamp":"2024-06-01T17:52:44.121213Z"}]}
{"channel":"book","type":"update","data":[{"symbol":"ETH/AUD","bids":[{"price":5709.75,"qty":0.90387105}],"asks":[],"checksum":1034742610,"timestamp":"2024-06-01T17:52:44.126793Z"}]}
{"channel":"book","type":"update","data":[{"symbol":"ETH/AUD","bids":[],"asks":[{"price":5717.57,"qty":0.00000000},{"price":5717.59,"qty":0.83372964}],"checksum":2681090494,"timestamp":"2024-06-01T17:52:44.166387Z"}]}
{"channel":"book","type":"update","data":[{"symbol":"ETH/AUD","bids":[],"asks":[{"price":5717.56,"qty":0.00000000},{"price":5717.71,"qty":11.18062120}],"checksum":1086504803,"timestamp":"2024-06-01T17:52:44.166413Z"}]}
{"channel":"book","type":"update","data":[{"symbol":"ETH/AUD","bids":[],"asks":[{"price":5717.53,"qty":0.10900371}],"checksum":654085696,"timestamp":"2024-06-01T17:52:44.167976Z"}]}
{"channel":"book","type":"update","data":[{"symbol":"ETH/AUD","bids":[{"price":5709.70,"qty":0.00000000},{"price":5703.17,"qty":0.74674910}],"asks":[],"checksum":409905536,"timestamp":"2024-06-01T17:52:44.179241Z"}]}
{"channel":"book","type":"update","data":[{"symbol":"ETH/AUD","bids":[],"asks":[{"price":5717.54,"qty":0.00000000},{"price":5719.72,"qty":0.08600000},{"price":5717.52,"qty":0.52360000}],"checksum":156936336,"timestamp":"2024-06-01T17:52:44.377205Z"}]}
{"channel":"book","type":"update","data":[{"symbol":"ETH/AUD","bids":[],"asks":[{"price":5717.51,"qty":0.00775188}],"checksum":3230083662,"timestamp":"2024-06-01T17:52:44.403395Z"}]}
{"channel":"book","type":"update","data":[{"symbol":"ETH/AUD","bids":[],"asks":[{"price":5717.53,"qty":0.10125185}],"checksum":1201649933,"timestamp":"2024-06-01T17:52:44.403416Z"}]}
{"channel":"book","type":"update","data":[{"symbol":"ETH/AUD","bids":[{"price":5709.73,"qty":0.00000000},{"price":5703.16,"qty":7.12047832},{"price":5709.76,"qty":0.07347674}],"asks":[],"checksum":1227066711,"timestamp":"2024-06-01T17:52:44.406761Z"}]}
{"channel":"book","type":"update","data":[{"symbol":"ETH/AUD","bids":[],"asks":[{"price":5717.59,"qty":0.00000000},{"price":5717.71,"qty":11.18062120}],"checksum":3397373401,"timestamp":"2024-06-01T17:52:44.572232Z"}]}
{"channel":"book","type":"update","data":[{"symbol":"ETH/AUD","bids":[],"asks":[{"price":5717.50,"qty":0.83372964}],"checksum":620489374,"timestamp":"2024-06-01T17:52:44.604439Z"}]}
{"channel":"book","type":"update","data":[{"symbol":"ETH/AUD","bids":[],"asks":[{"price":5717.51,"qty":0.00000000},{"price":5717.71,"qty":11.18062120}],"checksum":3012606510,"timestamp":"2024-06-01T17:52:44.608867Z"}]}
{"channel":"book","type":"update","data":[{"symbol":"ETH/AUD","bids":[],"asks":[{"price":5717.49,"qty":0.00775191}],"checksum":775786312,"timestamp":"2024-06-01T17:52:44.608920Z"}]}
{"channel":"book","type":"update","data":[{"symbol":"ETH/AUD","bids":[{"price":5709.74,"qty":0.00000000},{"price":5703.16,"qty":7.12047832},{"price":5709.77,"qty":1.03774920}],"asks":[],"checksum":2736296528,"timestamp":"2024-06-01T17:52:44.855602Z"}]}
{"channel":"book","type":"update","data":[{"symbol":"ETH/AUD","bids":[{"price":5709.76,"qty":0.00000000},{"price":5703.16,"qty":7.12047832},{"price":5709.78,"qty":0.07347674}],"asks":[],"checksum":2223914435,"timestamp":"2024-06-01T17:52:45.045855Z"}]}
{"channel":"book","type":"update","data":[{"symbol":"ETH/AUD","bids":[],"asks":[{"price":5717.52,"qty":0.00000000},{"price":5717.71,"qty":11.18062120},{"price":5717.49,"qty":0.53135191}],"checksum":2720066299,"timestamp":"2024-06-01T17:52:45.048939Z"}]}
{"channel":"book","type":"update","data":[{"symbol":"ETH/AUD","bids":[{"price":5709.79,"qty":0.90387105}],"asks":[],"checksum":3251906677,"timestamp":"2024-06-01T17:52:45.051402Z"}]}
{"channel":"book","type":"update","data":[{"symbol":"ETH/AUD","bids":[{"price":5709.75,"qty":0.00000000},{"price":5703.17,"qty":0.74674910}],"asks":[],"checksum":851540873,"timestamp":"2024-06-01T17:52:45.176933Z"}]}
{"channel":"book","type":"update","data":[{"symbol":"ETH/AUD","bids":[{"price":5705.27,"qty":0.00526766}],"asks":[],"checksum":2800348158,"timestamp":"2024-06-01T17:52:45.198644Z"}]}
{"channel":"book","type":"update","data":[{"symbol":"ETH/AUD","bids":[{"price":5705.29,"qty":0.52676214}],"asks":[],"checksum":3685015824,"timestamp":"2024-06-01T17:52:45.199939Z"}]}
{"channel":"book","type":"update","data":[{"symbol":"ETH/AUD","bids":[{"price":5705.28,"qty":0.00000000},{"price":5703.18,"qty":7.06614888},{"price":5705.26,"qty":0.52360000}],"asks":[],"checksum":2875998150,"timestamp":"2024-06-01T17:52:45.201496Z"}]}
{"channel":"book","type":"update","data":[{"symbol":"ETH/AUD","bids":[{"price":5705.27,"qty":0.00000000},{"price":5703.19,"qty":0.74674649}],"asks":[],"checksum":2948416684,"timestamp":"2024-06-01T17:52:45.256488Z"}]}
{"channel":"book","type":"update","data":[{"symbol":"ETH/AUD","bids":[{"price":5705.29,"qty":0.54230780}],"asks":[],"checksum":1206144789,"timestamp":"2024-06-01T17:52:45.257375Z"}]}
{"channel":"book","type":"update","data":[{"symbol":"ETH/AUD","bids":[{"price":5709.77,"qty":0.00000000},{"price":5703.18,"qty":7.10718072},{"price":5709.80,"qty":1.03774348}],"asks":[],"checksum":1190211489,"timestamp":"2024-06-01T17:52:45.548998Z"}]}
{"channel":"book","type":"update","data":[{"symbol":"ETH/AUD","bids":[{"price":5709.78,"qty":0.00000000},{"price":5703.18,"qty":7.10718072},{"price":5709.81,"qty":0.07347674}],"asks":[],"checksum":613891651,"timestamp":"2024-06-01T17:52:45.566007Z"}]}
{"channel":"book","type":"update","data":[{"symbol":"ETH/AUD","bids":[{"price":5705.26,"qty":0.00000000},{"price":5703.18,"qty":7.10718072},{"price":5705.30,"qty":0.52360000}],"asks":[],"checksum":1203864988,"timestamp":"2024-06-01T17:52:45.706015Z"}]}
{"channel":"book","type":"update","data":[{"symbol":"ETH/AUD","bids":[],"asks":[{"price":5713.29,"qty":0.00000000},{"price":5719.72,"qty":0.08600000},{"price":5713.26,"qty":0.01292326}],"checksum":2022779539,"timestamp":"2024-06-01T17:52:46.085047Z"}]}
{"channel":"book","type":"update","data":[{"symbol":"ETH/AUD","bids":[],"asks":[{"price":5717.71,"qty":0.00000000},{"price":5719.72,"qty":0.08600000}],"checksum":865731393,"timestamp":"2024-06-01T17:52:46.087894Z"}]}
{"channel":"book","type":"update","data":[{"symbol":"ETH/AUD","bids":[],"asks":[{"price":5713.25,"qty":0.90387105}],"checksum":507684018,"timestamp":"2024-06-01T17:52:46.090460Z"}]}
{"channel":"book","type":"update","data":[{"symbol":"ETH/AUD","bids":[{"price":5709.82,"qty":0.90387105}],"asks":[],"checksum":4102343058,"timestamp":"2024-06-01T17:52:46.090551Z"}]}
{"channel":"book","type":"update","data":[{"symbol":"ETH/AUD","bids":[],"asks":[{"price":5716.75,"qty":8.50567015}],"checksum":1292125047,"timestamp":"2024-06-01T17:52:46.090679Z"}]}
{"channel":"book","type":"update","data":[{"symbol":"ETH/AUD","bids":[],"asks":[{"price":5717.49,"qty":0.00775191},{"price":5716.74,"qty":0.52360000}],"checksum":584211380,"timestamp":"2024-06-01T17:52:46.093845Z"}]}
{"channel":"book","type":"update","data":[{"symbol":"ETH/AUD","bids":[{"price":5709.79,"qty":0.00000000},{"price":5703.19,"qty":0.74674649}],"asks":[],"checksum":700027925,"timestamp":"2024-06-01T17:52:46.174977Z"}]}
{"channel":"book","type":"update","data":[{"symbol":"ETH/AUD","bids":[],"asks":[{"price":5713.28,"qty":0.00000000},{"price":5717.53,"qty":0.10125185}],"checksum":2589260931,"timestamp":"2024-06-01T17:52:46.175109Z"}]}
{"channel":"book","type":"update","data":[{"symbol":"ETH/AUD","bids":[{"price":5709.80,"qty":0.00000000},{"price":5703.18,"qty":7.10718072},{"price":5709.83,"qty":1.03773792}],"asks":[],"checksum":593512164,"timestamp":"2024-06-01T17:52:46.277831Z"}]}
{"channel":"book","type":"update","data":[{"symbol":"ETH/AUD","bids":[],"asks":[{"price":5713.27,"qty":0.00000000},{"price":5717.55,"qty":12.05997532},{"price":5713.24,"qty":0.20551098}],"checksum":1560583349,"timestamp":"2024-06-01T17:52:46.277933Z"}]}
{"channel":"book","type":"update","data":[{"symbol":"ETH/AUD","bids":[{"price":5708.34,"qty":0.00000000},{"price":5703.18,"qty":7.10718072}],"asks":[],"checksum":1656660321,"timestamp":"2024-06-01T17:52:46.281062Z"}]}
{"channel":"book","type":"update","data":[{"symbol":"ETH/AUD","bids":[{"price":5709.83,"qty":4.10233300}],"asks":[],"checksum":2478806906,"timestamp":"2024-06-01T17:52:46.284119Z"}]}
{"channel":"book","type":"update","data":[{"symbol":"ETH/AUD","bids":[],"asks":[{"price":5717.48,"qty":13.12471303}],"checksum":3973792931,"timestamp":"2024-06-01T17:52:46.312663Z"}]}
{"channel":"book","type":"update","data":[{"symbol":"ETH/AUD","bids":[],"asks":[{"price":5717.49,"qty":0.00000000},{"price":5717.53,"qty":0.10125185}],"checksum":1267325409,"timestamp":"2024-06-01T17:52:46.315993Z"}]}
{"channel":"book","type":"update","data":[{"symbol":"ETH/AUD","bids":[],"asks":[{"price":5717.47,"qty":0.00775194}],"checksum":1998355227,"timestamp":"2024-06-01T17:52:46.316020Z"}]}
{"channel":"book","type":"update","data":[{"symbol":"ETH/AUD","bids":[],"asks":[{"price":5716.73,"qty":0.07535125}],"checksum":1379192762,"timestamp":"2024-06-01T17:52:46.520137Z"}]}
{"channel":"book","type":"update","data":[{"symbol":"ETH/AUD","bids":[],"asks":[{"price":5713.26,"qty":0.00000000},{"price":5717.50,"qty":0.83372964},{"price":5713.23,"qty":0.01292326}],"checksum":3091230360,"timestamp":"2024-06-01T17:52:46.848557Z"}]}
{"channel":"book","type":"update","data":[{"symbol":"ETH/AUD","bids":[{"price":5709.83,"qty":3.06459508},{"price":5709.84,"qty":1.03773485}],"asks":[],"checksum":298673326,"timestamp":"2024-06-01T17:52:46.989392Z"}]}
{"channel":"book","type":"update","data":[{"symbol":"ETH/AUD","bids":[],"asks":[{"price":5713.24,"qty":0.00000000},{"price":5717.50,"qty":0.83372964},{"price":5713.22,"qty":0.20550494}],"checksum":7829179,"timestamp":"2024-06-01T17:52:46.989483Z"}]}
{"channel":"book","type":"update","data":[{"symbol":"ETH/AUD","bids":[{"price":5709.85,"qty":0.90387105}],"asks":[],"checksum":2218852990,"timestamp":"2024-06-01T17:52:46.994719Z"}]}
{"channel":"book","type":"update","data":[{"symbol":"ETH/AUD","bids":[{"price":5709.82,"qty":0.00000000},{"price":5703.19,"qty":0.74674649}],"asks":[],"checksum":2123026229,"timestamp":"2024-06-01T17:52:47.178604Z"}]}
{"channel":"book","type":"update","data":[{"symbol":"ETH/AUD","bids":[{"price":5709.81,"qty":0.00000000},{"price":5703.18,"qty":7.10718072},{"price":5709.86,"qty":0.07347674}],"asks":[],"checksum":3448945213,"timestamp":"2024-06-01T17:52:47.517578Z"}]}
{"channel":"book","type":"update","data":[{"symbol":"ETH/AUD","bids":[{"price":5709.84,"qty":0.00000000},{"price":5703.18,"qty":7.10718072},{"price":5709.87,"qty":1.03772831}],"asks":[],"checksum":1519072525,"timestamp":"2024-06-01T17:52:47.700654Z"}]}
{"channel":"book","type":"update","data":[{"symbol":"ETH/AUD","bids":[],"asks":[{"price":5716.75,"qty":0.00000000},{"price":5719.72,"qty":0.08600000}],"checksum":1954811380,"timestamp":"2024-06-01T17:52:47.746164Z"}]}
{"channel":"book","type":"update","data":[{"symbol":"ETH/AUD","bids":[],"asks":[{"price":5714.16,"qty":0.00000000},{"price":5719.79,"qty":1.60677000},{"price":5714.77,"qty":0.06654300}],"checksum":546038829,"timestamp":"2024-06-01T17:52:47.748717Z"}]}
