{"channel":"book","type":"update","data":[{"symbol":"ETH/EUR","bids":[{"price":3501.44,"qty":0.00000000},{"price":3501.18,"qty":1.35346404}],"asks":[],"checksum":4231672012,"timestamp":"2024-06-01T17:52:44.840292Z"}]}
{"channel":"book","type":"update","data":[{"symbol":"ETH/EUR","bids":[{"price":3501.65,"qty":27.93022738}],"asks":[],"checksum":2658910152,"timestamp":"2024-06-01T17:52:44.840324Z"}]}
{"channel":"book","type":"update","data":[{"symbol":"ETH/EUR","bids":[],"asks":[{"price":3501.94,"qty":26.32812646}],"checksum":3443020146,"timestamp":"2024-06-01T17:52:44.842401Z"}]}
{"channel":"book","type":"update","data":[{"symbol":"ETH/EUR","bids":[],"asks":[{"price":3502.02,"qty":26.32746927}],"checksum":3644032832,"timestamp":"2024-06-01T17:52:44.842497Z"}]}
{"channel":"book","type":"update","data":[{"symbol":"ETH/EUR","bids":[],"asks":[{"price":3501.94,"qty":0.00000000},{"price":3502.61,"qty":0.77800000}],"checksum":3114222162,"timestamp":"2024-06-01T17:52:45.219916Z"}]}
{"channel":"book","type":"update","data":[{"symbol":"ETH/EUR","bids":[],"asks":[{"price":3501.96,"qty":26.32794961}],"checksum":1751850211,"timestamp":"2024-06-01T17:52:45.224429Z"}]}
{"channel":"book","type":"update","data":[{"symbol":"ETH/EUR","bids":[{"price":3501.65,"qty":1.60000000}],"asks":[],"checksum":3315788519,"timestamp":"2024-06-01T17:52:45.234407Z"}]}
{"channel":"book","type":"update","data":[{"symbol":"ETH/EUR","bids":[],"asks":[{"price":3501.96,"qty":0.00000000},{"price":3502.61,"qty":0.77800000}],"checksum":2325457475,"timestamp":"2024-06-01T17:52:45.240555Z"}]}
{"channel":"book","type":"update","data":[{"symbol":"ETH/EUR","bids":[],"asks":[{"price":3501.95,"qty":26.32804376}],"checksum":1662490130,"timestamp":"2024-06-01T17:52:45.285077Z"}]}
{"channel":"book","type":"update","data":[{"symbol":"ETH/EUR","bids":[],"asks":[{"price":3501.95,"qty":0.00000000},{"price":3502.61,"qty":0.77800000}],"checksum":2325457475,"timestamp":"2024-06-01T17:52:45.319909Z"}]}
{"channel":"book","type":"update","data":[{"symbol":"ETH/EUR","bids":[],"asks":[{"price":3502.01,"qty":26.32754445}],"checksum":2318467845,"timestamp":"2024-06-01T17:52:45.453943Z"}]}
{"channel":"book","type":"update","data":[{"symbol":"ETH/EUR","bids":[],"asks":[{"price":3502.01,"qty":0.00000000},{"price":3502.61,"qty":0.77800000}],"checksum":2325457475,"timestamp":"2024-06-01T17:52:45.458348Z"}]}
{"channel":"book","type":"update","data":[{"symbol":"ETH/EUR","bids":[{"price":3501.68,"qty":0.00000000},{"price":3501.16,"qty":15.80353051},{"price":3501.66,"qty":0.02855193}],"asks":[],"checksum":1609414882,"timestamp":"2024-06-01T17:52:45.795180Z"}]}
{"channel":"book","type":"update","data":[{"symbol":"ETH/EUR","bids":[],"asks":[{"price":3502.20,"qty":0.00000000},{"price":3502.63,"qty":0.72912968},{"price":3502.59,"qty":0.00757526}],"checksum":969501950,"timestamp":"2024-06-01T17:52:45.795215Z"}]}
{"channel":"book","type":"update","data":[{"symbol":"ETH/EUR","bids":[],"asks":[{"price":3501.95,"qty":26.32800692}],"checksum":3110000800,"timestamp":"2024-06-01T17:52:46.110427Z"}]}
{"channel":"book","type":"update","data":[{"symbol":"ETH/EUR","bids":[],"asks":[{"price":3501.95,"qty":0.00000000},{"price":3502.61,"qty":0.77800000}],"checksum":969501950,"timestamp":"2024-06-01T17:52:46.160965Z"}]}
{"channel":"book","type":"update","data":[{"symbol":"ETH/EUR","bids":[],"asks":[{"price":3502.02,"qty":0.00000000},{"price":3502.63,"qty":0.72912968}],"checksum":1058660830,"timestamp":"2024-06-01T17:52:46.166927Z"}]}
{"channel":"book","type":"update","data":[{"symbol":"ETH/EUR","bids":[],"asks":[{"price":3501.90,"qty":26.32838810}],"checksum":3400577593,"timestamp":"2024-06-01T17:52:46.171120Z"}]}
{"channel":"book","type":"update","data":[{"symbol":"ETH/EUR","bids":[],"asks":[{"price":3502.01,"qty":26.32754445}],"checksum":2492535682,"timestamp":"2024-06-01T17:52:46.171277Z"}]}
{"channel":"book","type":"update","data":[{"symbol":"ETH/EUR","bids":[{"price":3501.60,"qty":29.67059172}],"asks":[],"checksum":1249603246,"timestamp":"2024-06-01T17:52:46.171303Z"}]}
{"channel":"book","type":"update","data":[{"symbol":"ETH/EUR","bids":[],"asks":[{"price":3502.60,"qty":0.00000000},{"price":3502.61,"qty":0.77800000}],"checksum":350956978,"timestamp":"2024-06-01T17:52:46.207083Z"}]}
{"channel":"book","type":"update","data":[{"symbol":"ETH/EUR","bids":[],"asks":[{"price":3502.43,"qty":26.32439750}],"checksum":3819311749,"timestamp":"2024-06-01T17:52:46.212416Z"}]}
{"channel":"book","type":"update","data":[{"symbol":"ETH/EUR","bids":[{"price":3501.60,"qty":26.33059172}],"asks":[],"checksum":1832532406,"timestamp":"2024-06-01T17:52:46.217402Z"}]}
{"channel":"book","type":"update","data":[{"symbol":"ETH/EUR","bids":[{"price":3501.60,"qty":0.00000000},{"price":3501.16,"qty":15.80353051}],"asks":[],"checksum":3407531655,"timestamp":"2024-06-01T17:52:46.229818Z"}]}
{"channel":"book","type":"update","data":[{"symbol":"ETH/EUR","bids":[{"price":3501.61,"qty":26.33050222}],"asks":[],"checksum":846373214,"timestamp":"2024-06-01T17:52:46.233671Z"}]}
{"channel":"book","type":"update","data":[{"symbol":"ETH/EUR","bids":[],"asks":[{"price":3501.90,"qty":0.00000000},{"price":3502.61,"qty":0.77800000}],"checksum":3509069545,"timestamp":"2024-06-01T17:52:46.283234Z"}]}
{"channel":"book","type":"update","data":[{"symbol":"ETH/EUR","bids":[],"asks":[{"price":3502.01,"qty":0.00000000},{"price":3502.63,"qty":0.72912968}],"checksum":327383661,"timestamp":"2024-06-01T17:52:46.287435Z"}]}
{"channel":"book","type":"update","data":[{"symbol":"ETH/EUR","bids":[],"asks":[{"price":3501.89,"qty":26.32849110}],"checksum":3727783726,"timestamp":"2024-06-01T17:52:46.291375Z"}]}
{"channel":"book","type":"update","data":[{"symbol":"ETH/EUR","bids":[],"asks":[{"price":3501.89,"qty":0.00000000},{"price":3502.63,"qty":0.72912968}],"checksum":327383661,"timestamp":"2024-06-01T17:52:46.691762Z"}]}
{"channel":"book","type":"update","data":[{"symbol":"ETH/EUR","bids":[{"price":3501.61,"qty":0.00000000},{"price":3501.16,"qty":15.80353051}],"asks":[],"checksum":3941275060,"timestamp":"2024-06-01T17:52:46.691931Z"}]}
{"channel":"book","type":"update","data":[{"symbol":"ETH/EUR","bids":[],"asks":[{"price":3501.94,"qty":26.32812773}],"checksum":3827960068,"timestamp":"2024-06-01T17:52:46.697085Z"}]}
{"channel":"book","type":"update","data":[{"symbol":"ETH/EUR","bids":[{"price":3501.64,"qty":26.33029453}],"asks":[],"checksum":3029481089,"timestamp":"2024-06-01T17:52:46.697176Z"}]}
{"channel":"book","type":"update","data":[{"symbol":"ETH/EUR","bids":[],"asks":[{"price":3502.00,"qty":26.32761963}],"checksum":760425058,"timestamp":"2024-06-01T17:52:46.697189Z"}]}
{"channel":"book","type":"update","data":[{"symbol":"ETH/EUR","bids":[],"asks":[{"price":3501.94,"qty":0.00000000},{"price":3502.61,"qty":0.77800000}],"checksum":1792157568,"timestamp":"2024-06-01T17:52:46.747934Z"}]}
{"channel":"book","type":"update","data":[{"symbol":"ETH/EUR","bids":[],"asks":[{"price":3501.93,"qty":26.32820147}],"checksum":2275499438,"timestamp":"2024-06-01T17:52:46.752480Z"}]}
{"channel":"book","type":"update","data":[{"symbol":"ETH/EUR","bids":[],"asks":[{"price":3501.93,"qty":0.00000000},{"price":3502.61,"qty":0.77800000}],"checksum":1792157568,"timestamp":"2024-06-01T17:52:46.765086Z"}]}
{"channel":"book","type":"update","data":[{"symbol":"ETH/EUR","bids":[],"asks":[{"price":3502.59,"qty":0.00000000},{"price":3502.63,"qty":0.72912968},{"price":3502.20,"qty":0.00757474}],"checksum":310852773,"timestamp":"2024-06-01T17:52:46.894943Z"}]}
{"channel":"book","type":"update","data":[{"symbol":"ETH/EUR","bids":[{"price":3501.64,"qty":0.00000000},{"price":3501.16,"qty":15.80353051}],"asks":[],"checksum":1111425824,"timestamp":"2024-06-01T17:52:46.994366Z"}]}
{"channel":"book","type":"update","data":[{"symbol":"ETH/EUR","bids":[],"asks":[{"price":3501.99,"qty":26.32769481}],"checksum":1618104347,"timestamp":"2024-06-01T17:52:46.998202Z"}]}
{"channel":"book","type":"update","data":[{"symbol":"ETH/EUR","bids":[{"price":3501.66,"qty":26.35869550}],"asks":[],"checksum":3058223803,"timestamp":"2024-06-01T17:52:46.998315Z"}]}
{"channel":"book","type":"update","data":[{"symbol":"ETH/EUR","bids":[],"asks":[{"price":3501.99,"qty":0.00000000},{"price":3502.61,"qty":0.77800000}],"checksum":126743378,"timestamp":"2024-06-01T17:52:47.002736Z"}]}
{"channel":"book","type":"update","data":[{"symbol":"ETH/EUR","bids":[{"price":3501.66,"qty":0.02855193}],"asks":[],"checksum":1111425824,"timestamp":"2024-06-01T17:52:47.285251Z"}]}
{"channel":"book","type":"update","data":[{"symbol":"ETH/EUR","bids":[],"asks":[{"price":3501.94,"qty":26.32814524}],"checksum":2702916280,"timestamp":"2024-06-01T17:52:47.289535Z"}]}
{"channel":"book","type":"update","data":[{"symbol":"ETH/EUR","bids":[],"asks":[{"price":3501.94,"qty":0.00000000},{"price":3502.61,"qty":0.77800000}],"checksum":1111425824,"timestamp":"2024-06-01T17:52:47.312272Z"}]}
{"channel":"book","type":"update","data":[{"symbol":"ETH/EUR","bids":[],"asks":[{"price":3502.00,"qty":0.00000000},{"price":3502.63,"qty":0.72912968}],"checksum":282821842,"timestamp":"2024-06-01T17:52:47.316907Z"}]}
{"channel":"book","type":"update","data":[{"symbol":"ETH/EUR","bids":[],"asks":[{"price":3501.99,"qty":26.32769481}],"checksum":677110315,"timestamp":"2024-06-01T17:52:47.321952Z"}]}
{"channel":"book","type":"update","data":[{"symbol":"ETH/EUR","bids":[],"asks":[{"price":3502.20,"qty":0.00000000},{"price":3502.63,"qty":0.72912968},{"price":3502.42,"qty":0.00757474}],"checksum":2232750008,"timestamp":"2024-06-01T17:52:47.339734Z"}]}
{"channel":"book","type":"update","data":[{"symbol":"ETH/EUR","bids":[],"asks":[{"price":3501.98,"qty":26.32776999}],"checksum":1969459382,"timestamp":"2024-06-01T17:52:47.350451Z"}]}
{"channel":"book","type":"update","data":[{"symbol":"ETH/EUR","bids":[],"asks":[{"price":3501.98,"qty":0.00000000},{"price":3502.61,"qty":0.77800000}],"checksum":2232750008,"timestamp":"2024-06-01T17:52:47.354971Z"}]}
{"channel":"book","type":"update","data":[{"symbol":"ETH/EUR","bids":[],"asks":[{"price":3501.92,"qty":26.32822946}],"checksum":3025246585,"timestamp":"2024-06-01T17:52:47.408279Z"}]}
{"channel":"book","type":"update","data":[{"symbol":"ETH/EUR","bids":[],"asks":[{"price":3501.92,"qty":0.00000000},{"price":3502.61,"qty":0.77800000}],"checksum":2232750008,"timestamp":"2024-06-01T17:52:47.618158Z"}]}
{"channel":"book","type":"update","data":[{"symbol":"ETH/EUR","bids":[],"asks":[{"price":3501.98,"qty":26.32781363}],"checksum":1676142204,"timestamp":"2024-06-01T17:52:47.625900Z"}]}
{"channel":"book","type":"update","data":[{"symbol":"ETH/EUR","bids":[],"asks":[{"price":3501.98,"qty":0.00000000},{"price":3502.61,"qty":0.77800000}],"checksum":2232750008,"timestamp":"2024-06-01T17:52:47.630206Z"}]}
{"channel":"book","type":"update","data":[{"symbol":"ETH/EUR","bids":[],"asks":[{"price":3501.99,"qty":0.00000000},{"price":3502.63,"qty":0.72912968}],"checksum":2205515281,"timestamp":"2024-06-01T17:52:47.723707Z"}]}
{"channel":"book","type":"update","data":[{"symbol":"ETH/EUR","bids":[{"price":3501.37,"qty":0.00000000},{"price":3501.10,"qty":0.84644082}],"asks":[],"checksum":2714205296,"timestamp":"2024-06-01T17:52:47.723751Z"}]}
{"channel":"book","type":"update","data":[{"symbol":"ETH/EUR","bids":[],"asks":[{"price":3502.21,"qty":0.00000000},{"price":3502.83,"qty":0.00220000}],"checksum":3252890768,"timestamp":"2024-06-01T17:52:47.727868Z"}]}
{"channel":"book","type":"update","data":[{"symbol":"ETH/EUR","bids":[{"price":3501.59,"qty":0.00000000},{"price":3500.94,"qty":0.66220830}],"asks":[],"checksum":3374229407,"timestamp":"2024-06-01T17:52:47.727881Z"}]}
{"channel":"book","type":"update","data":[{"symbol":"ETH/EUR","bids":[],"asks":[{"price":3502.43,"qty":27.92439750}],"checksum":334832154,"timestamp":"2024-06-01T17:52:47.730885Z"}]}
{"channel":"book","type":"update","data":[{"symbol":"ETH/EUR","bids":[{"price":3501.44,"qty":1.60000000}],"asks":[],"checksum":3102430174,"timestamp":"2024-06-01T17:52:47.730902Z"}]}
{"channel":"book","type":"update","data":[{"symbol":"ETH/EUR","bids":[{"price":3501.65,"qty":0.00000000},{"price":3500.94,"qty":0.66220830}],"asks":[],"checksum":2226973870,"timestamp":"2024-06-01T17:52:47.730914Z"}]}
{"channel":"book","type":"update","data":[{"symbol":"ETH/EUR","bids":[],"asks":[{"price":3502.45,"qty":0.00220000}],"checksum":3837855079,"timestamp":"2024-06-01T17:52:47.730925Z"}]}
{"channel":"book","type":"update","data":[{"symbol":"ETH/EUR","bids":[],"asks":[{"price":3502.01,"qty":26.32755864}],"checksum":515041952,"timestamp":"2024-06-01T17:52:47.732437Z"}]}
{"channel":"book","type":"update","data":[{"symbol":"ETH/EUR","bids":[],"asks":[{"price":3502.30,"qty":26.32538542}],"checksum":2834941721,"timestamp":"2024-06-01T17:52:47.732527Z"}]}
{"channel":"book","type":"update","data":[{"symbol":"ETH/EUR","bids":[],"asks":[{"price":3502.01,"qty":0.00000000},{"price":3502.63,"qty":0.72912968}],"checksum":1240679363,"timestamp":"2024-06-01T17:52:47.737969Z"}]}
{"channel":"book","type":"update","data":[{"symbol":"ETH/EUR","bids":[],"asks":[{"price":3502.44,"qty":0.00000000},{"price":3502.83,"qty":0.00220000}],"checksum":3610170879,"timestamp":"2024-06-01T17:52:47.744794Z"}]}
{"channel":"book","type":"update","data":[{"symbol":"ETH/EUR","bids":[],"asks":[{"price":3502.43,"qty":1.60000000}],"checksum":27313641,"timestamp":"2024-06-01T17:52:47.744982Z"}]}
{"channel":"book","type":"update","data":[{"symbol":"ETH/EUR","bids":[],"asks":[{"price":3502.63,"qty":0.00000000},{"price":3503.02,"qty":0.84644082}],"checksum":1278402357,"timestamp":"2024-06-01T17:52:47.746762Z"}]}
{"channel":"book","type":"update","data":[{"symbol":"ETH/EUR","bids":[],"asks":[{"price":3502.62,"qty":26.32296824}],"checksum":1111518309,"timestamp":"2024-06-01T17:52:47.752373Z"}]}
{"channel":"book","type":"update","data":[{"symbol":"ETH/EUR","bids":[],"asks":[{"price":3502.30,"qty":0.00000000},{"price":3503.02,"qty":0.84644082}],"checksum":3838849677,"timestamp":"2024-06-01T17:52:47.752398Z"}]}
{"channel":"book","type":"update","data":[{"symbol":"ETH/EUR","bids":[{"price":3501.67,"qty":2.63500000}],"asks":[],"checksum":3088592838,"timestamp":"2024-06-01T17:52:47.753631Z"}]}
{"channel":"book","type":"update","data":[{"symbol":"ETH/EUR","bids":[{"price":3501.44,"qty":0.00000000},{"price":3500.94,"qty":0.66220830}],"asks":[],"checksum":3767089690,"timestamp":"2024-06-01T17:52:47.756159Z"}]}
{"channel":"book","type":"update","data":[{"symbol":"ETH/EUR","bids":[{"price":3501.73,"qty":1.60000000}],"asks":[],"checksum":2476850642,"timestamp":"2024-06-01T17:52:47.756276Z"}]}
{"channel":"book","type":"update","data":[{"symbol":"ETH/EUR","bids":[],"asks":[{"price":3502.22,"qty":26.41158706}],"checksum":3313869121,"timestamp":"2024-06-01T17:52:47.756354Z"}]}
{"channel":"book","type":"update","data":[{"symbol":"ETH/EUR","bids":[],"asks":[{"price":3502.82,"qty":0.63146286}],"checksum":3997576535,"timestamp":"2024-06-01T17:52:47.757307Z"}]}
{"channel":"book","type":"update","data":[{"symbol":"ETH/EUR","bids":[],"asks":[{"price":3502.14,"qty":26.32660668}],"checksum":403470744,"timestamp":"2024-06-01T17:52:47.785946Z"}]}
{"channel":"book","type":"update","data":[{"symbol":"ETH/EUR","bids":[],"asks":[{"price":3502.14,"qty":0.00000000},{"price":3502.83,"qty":0.00220000}],"checksum":3997576535,"timestamp":"2024-06-01T17:52:47.866016Z"}]}
{"channel":"book","type":"update","data":[{"symbol":"ETH/EUR","bids":[],"asks":[{"price":3502.19,"qty":26.32620822}],"checksum":3365711239,"timestamp":"2024-06-01T17:52:47.869348Z"}]}
{"channel":"book","type":"update","data":[{"symbol":"ETH/EUR","bids":[{"price":3501.66,"qty":0.00000000},{"price":3500.94,"qty":0.66220830},{"price":3501.74,"qty":0.02854956}],"asks":[],"checksum":3297079878,"timestamp":"2024-06-01T17:52:47.974001Z"}]}
{"channel":"book","type":"update","data":[{"symbol":"ETH/EUR","bids":[],"asks":[{"price":3502.42,"qty":0.00000000},{"price":3502.83,"qty":0.00220000},{"price":3502.60,"qty":0.00757473}],"checksum":3437079178,"timestamp":"2024-06-01T17:52:47.974144Z"}]}
{"channel":"book","type":"update","data":[{"symbol":"ETH/EUR","bids":[],"asks":[{"price":3502.22,"qty":26.32601406},{"price":3502.62,"qty":26.40854324}],"checksum":4034659598,"timestamp":"2024-06-01T17:52:48.006537Z"}]}
{"channel":"book","type":"update","data":[{"symbol":"ETH/EUR","bids":[],"asks":[{"price":3502.39,"qty":26.32470113}],"checksum":515148525,"timestamp":"2024-06-01T17:52:48.081157Z"}]}
{"channel":"book","type":"update","data":[{"symbol":"ETH/EUR","bids":[{"price":3501.39,"qty":4.00000000}],"asks":[],"checksum":2667821188,"timestamp":"2024-06-01T17:52:48.170071Z"}]}
{"channel":"book","type":"update","data":[{"symbol":"ETH/EUR","bids":[],"asks":[{"price":3502.19,"qty":0.00000000},{"price":3502.82,"qty":0.63146286}],"checksum":2170552367,"timestamp":"2024-06-01T17:52:48.195003Z"}]}
{"channel":"book","type":"update","data":[{"symbol":"ETH/EUR","bids":[],"asks":[{"price":3502.15,"qty":26.32650346}],"checksum":1110170047,"timestamp":"2024-06-01T17:52:48.199775Z"}]}
{"channel":"book","type":"update","data":[{"symbol":"ETH/EUR","bids":[],"asks":[{"price":3502.15,"qty":0.00000000},{"price":3502.82,"qty":0.63146286}],"checksum":2170552367,"timestamp":"2024-06-01T17:52:48.202744Z"}]}
{"channel":"book","type":"update","data":[{"symbol":"ETH/EUR","bids":[],"asks":[{"price":3502.15,"qty":26.32653241}],"checksum":659509993,"timestamp":"2024-06-01T17:52:48.266440Z"}]}
{"channel":"book","type":"update","data":[{"symbol":"ETH/EUR","bids":[{"price":3501.83,"qty":26.32884438}],"asks":[],"checksum":860833624,"timestamp":"2024-06-01T17:52:48.266617Z"}]}
{"channel":"book","type":"update","data":[{"symbol":"ETH/EUR","bids":[{"price":3501.27,"qty":0.00000000},{"price":3501.16,"qty":15.80353051}],"asks":[],"checksum":1395865772,"timestamp":"2024-06-01T17:52:48.354833Z"}]}
{"channel":"book","type":"update","data":[{"symbol":"ETH/EUR","bids":[{"price":3501.83,"qty":0.00000000},{"price":3501.10,"qty":0.84644082}],"asks":[],"checksum":3789688139,"timestamp":"2024-06-01T17:52:48.394510Z"}]}
{"channel":"book","type":"update","data":[{"symbol":"ETH/EUR","bids":[],"asks":[{"price":3502.15,"qty":0.00000000},{"price":3502.82,"qty":0.63146286}],"checksum":1927785710,"timestamp":"2024-06-01T17:52:48.394640Z"}]}
{"channel":"book","type":"update","data":[{"symbol":"ETH/EUR","bids":[],"asks":[{"price":3502.14,"qty":26.32660610}],"checksum":1218585550,"timestamp":"2024-06-01T17:52:48.399188Z"}]}
{"channel":"book","type":"update","data":[{"symbol":"ETH/EUR","bids":[{"price":3501.81,"qty":26.32904440}],"asks":[],"checksum":4084869243,"timestamp":"2024-06-01T17:52:48.399267Z"}]}
{"channel":"book","type":"update","data":[{"symbol":"ETH/EUR","bids":[{"price":3501.26,"qty":26.33316494}],"asks":[],"checksum":3544031285,"timestamp":"2024-06-01T17:52:48.399334Z"}]}
{"channel":"book","type":"update","data":[{"symbol":"ETH/EUR","bids":[{"price":3501.75,"qty":26.32949924}],"asks":[],"checksum":4156768715,"timestamp":"2024-06-01T17:52:48.399402Z"}]}
{"channel":"book","type":"update","data":[{"symbol":"ETH/EUR","bids":[{"price":3501.81,"qty":0.00000000},{"price":3501.18,"qty":1.35346404}],"asks":[],"checksum":4074772958,"timestamp":"2024-06-01T17:52:48.478038Z"}]}
{"channel":"book","type":"update","data":[{"symbol":"ETH/EUR","bids":[{"price":3501.82,"qty":26.32894439}],"asks":[],"checksum":3698438268,"timestamp":"2024-06-01T17:52:48.482338Z"}]}
{"channel":"book","type":"update","data":[{"symbol":"ETH/EUR","bids":[{"price":3501.84,"qty":2.93500000}],"asks":[],"checksum":1172507209,"timestamp":"2024-06-01T17:52:48.545490Z"}]}
{"channel":"book","type":"update","data":[{"symbol":"ETH/EUR","bids":[{"price":3501.67,"qty":0.00000000},{"price":3501.23,"qty":0.08558900}],"asks":[],"checksum":1401277022,"timestamp":"2024-06-01T17:52:48.575290Z"}]}
{"channel":"book","type":"update","data":[{"symbol":"ETH/EUR","bids":[{"price":3501.73,"qty":0.00000000},{"price":3501.18,"qty":1.35346404}],"asks":[],"checksum":4007423032,"timestamp":"2024-06-01T17:52:48.632515Z"}]}
{"channel":"book","type":"update","data":[{"symbol":"ETH/EUR","bids":[],"asks":[{"price":3502.14,"qty":0.00000000},{"price":3502.82,"qty":0.63146286}],"checksum":1815878521,"timestamp":"2024-06-01T17:52:48.693917Z"}]}
{"channel":"book","type":"update","data":[{"symbol":"ETH/EUR","bids":[],"asks":[{"price":3502.16,"qty":26.32645193}],"checksum":437940975,"timestamp":"2024-06-01T17:52:48.698677Z"}]}
{"channel":"book","type":"update","data":[{"symbol":"ETH/EUR","bids":[],"asks":[{"price":3502.16,"qty":0.00000000},{"price":3502.82,"qty":0.63146286}],"checksum":1815878521,"timestamp":"2024-06-01T17:52:48.706642Z"}]}
{"channel":"book","type":"update","data":[{"symbol":"ETH/EUR","bids":[{"price":3501.36,"qty":0.00000000},{"price":3501.16,"qty":15.80353051}],"asks":[],"checksum":3728714158,"timestamp":"2024-06-01T17:52:48.808760Z"}]}
{"channel":"book","type":"update","data":[{"symbol":"ETH/EUR","bids":[{"price":3501.16,"qty":0.00000000},{"price":3501.10,"qty":0.84644082}],"asks":[],"checksum":2139589721,"timestamp":"2024-06-01T17:52:48.808772Z"}]}
{"channel":"book","type":"update","data":[{"symbol":"ETH/EUR","bids":[{"price":3501.82,"qty":0.00000000},{"price":3501.07,"qty":6.00000000}],"asks":[],"checksum":1135755585,"timestamp":"2024-06-01T17:52:48.823863Z"}]}
{"channel":"book","type":"update","data":[{"symbol":"ETH/EUR","bids":[],"asks":[{"price":3502.18,"qty":26.32629249}],"checksum":1474605155,"timestamp":"2024-06-01T17:52:48.827458Z"}]}
{"channel":"book","type":"update","data":[{"symbol":"ETH/EUR","bids":[{"price":3501.75,"qty":0.00000000},{"price":3500.94,"qty":0.66220830}],"asks":[],"checksum":3836128009,"timestamp":"2024-06-01T17:52:48.839583Z"}]}
{"channel":"book","type":"update","data":[{"symbol":"ETH/EUR","bids":[{"price":3501.45,"qty":1.60000000}],"asks":[],"checksum":2768941666,"timestamp":"2024-06-01T17:52:48.843060Z"}]}
{"channel":"book","type":"update","data":[{"symbol":"ETH/EUR","bids":[{"price":3501.46,"qty":2.60000000}],"asks":[],"checksum":100828239,"timestamp":"2024-06-01T17:52:48.991050Z"}]}
{"channel":"book","type":"update","data":[{"symbol":"ETH/EUR","bids":[{"price":3501.45,"qty":0.00000000},{"price":3501.07,"qty":6.00000000}],"asks":[],"checksum":4136344437,"timestamp":"2024-06-01T17:52:48.993839Z"}]}
{"channel":"book","type":"update","data":[{"symbol":"ETH/EUR","bids":[{"price":3501.52,"qty":1.60000000}],"asks":[],"checksum":3209818459,"timestamp":"2024-06-01T17:52:48.993861Z"}]}
{"channel":"book","type":"update","data":[{"symbol":"ETH/EUR","bids":[{"price":3501.46,"qty":0.00000000},{"price":3501.07,"qty":6.00000000}],"asks":[],"checksum":1850261163,"timestamp":"2024-06-01T17:52:49.018225Z"}]}
{"channel":"book","type":"update","data":[{"symbol":"ETH/EUR","bids":[],"asks":[{"price":3502.39,"qty":0.00000000},{"price":3502.82,"qty":0.63146286}],"checksum":672704666,"timestamp":"2024-06-01T17:52:49.027297Z"}]}
{"channel":"book","type":"update","data":[{"symbol":"ETH/EUR","bids":[],"asks":[{"price":3502.22,"qty":0.00000000},{"price":3502.83,"qty":0.00220000}],"checksum":92548782,"timestamp":"2024-06-01T17:52:49.027336Z"}]}
{"channel":"book","type":"update","data":[{"symbol":"ETH/EUR","bids":[],"asks":[{"price":3501.99,"qty":26.32770529}],"checksum":2987429378,"timestamp":"2024-06-01T17:52:49.031338Z"}]}
{"channel":"book","type":"update","data":[{"symbol":"ETH/EUR","bids":[],"asks":[{"price":3501.99,"qty":0.00000000},{"price":3502.83,"qty":0.00220000}],"checksum":92548782,"timestamp":"2024-06-01T17:52:49.036681Z"}]}
{"channel":"book","type":"update","data":[{"symbol":"ETH/EUR","bids":[],"asks":[{"price":3502.62,"qty":0.08557500}],"checksum":2821843685,"timestamp":"2024-06-01T17:52:49.036823Z"}]}
{"channel":"book","type":"update","data":[{"symbol":"ETH/EUR","bids":[],"asks":[{"price":3502.18,"qty":0.00000000},{"price":3502.94,"qty":1.06800000}],"checksum":3435191632,"timestamp":"2024-06-01T17:52:49.042885Z"}]}
{"channel":"book","type":"update","data":[{"symbol":"ETH/EUR","bids":[{"price":3501.18,"qty":0.00000000},{"price":3500.94,"qty":0.66220830}],"asks":[],"checksum":4185869489,"timestamp":"2024-06-01T17:52:49.044419Z"}]}
{"channel":"book","type":"update","data":[{"symbol":"ETH/EUR","bids":[],"asks":[{"price":3502.07,"qty":26.32709339}],"checksum":2201693228,"timestamp":"2024-06-01T17:52:49.048268Z"}]}
{"channel":"book","type":"update","data":[{"symbol":"ETH/EUR","bids":[],"asks":[{"price":3501.98,"qty":26.32776999}],"checksum":4222665934,"timestamp":"2024-06-01T17:52:49.048390Z"}]}
{"channel":"book","type":"update","data":[{"symbol":"ETH/EUR","bids":[],"asks":[{"price":3502.42,"qty":26.32447427}],"checksum":525401748,"timestamp":"2024-06-01T17:52:49.048456Z"}]}
{"channel":"book","type":"update","data":[{"symbol":"ETH/EUR","bids":[],"asks":[{"price":3501.98,"qty":0.00000000},{"price":3502.82,"qty":0.63146286}],"checksum":1454297861,"timestamp":"2024-06-01T17:52:49.055616Z"}]}
{"channel":"book","type":"update","data":[{"symbol":"ETH/EUR","bids":[],"asks":[{"price":3502.07,"qty":0.00000000},{"price":3502.83,"qty":0.00220000}],"checksum":1464759248,"timestamp":"2024-06-01T17:52:49.062286Z"}]}
{"channel":"book","type":"update","data":[{"symbol":"ETH/EUR","bids":[],"asks":[{"price":3502.43,"qty":0.00000000},{"price":3502.94,"qty":1.06800000}],"checksum":2851217706,"timestamp":"2024-06-01T17:52:49.065151Z"}]}
{"channel":"book","type":"update","data":[{"symbol":"ETH/EUR","bids":[],"asks":[{"price":3502.36,"qty":1.60000000}],"checksum":4138566818,"timestamp":"2024-06-01T17:52:49.065527Z"}]}
{"channel":"book","type":"update","data":[{"symbol":"ETH/EUR","bids":[],"asks":[{"price":3502.41,"qty":0.72912968}],"checksum":1240058986,"timestamp":"2024-06-01T17:52:49.066731Z"}]}
{"channel":"book","type":"update","data":[{"symbol":"ETH/EUR","bids":[{"price":3501.74,"qty":0.00000000},{"price":3500.87,"qty":5.13432261},{"price":3501.85,"qty":0.02854741}],"asks":[],"checksum":1945782431,"timestamp":"2024-06-01T17:52:49.079567Z"}]}
{"channel":"book","type":"update","data":[{"symbol":"ETH/EUR","bids":[],"asks":[{"price":3501.87,"qty":26.32866473}],"checksum":3566584437,"timestamp":"2024-06-01T17:52:49.135325Z"}]}
{"channel":"book","type":"update","data":[{"symbol":"ETH/EUR","bids":[{"price":3501.52,"qty":0.00000000},{"price":3500.87,"qty":5.13432261}],"asks":[],"checksum":2478640035,"timestamp":"2024-06-01T17:52:49.138694Z"}]}
{"channel":"book","type":"update","data":[{"symbol":"ETH/EUR","bids":[{"price":3501.38,"qty":3.60000000}],"asks":[],"checksum":3263595976,"timestamp":"2024-06-01T17:52:49.140461Z"}]}
{"channel":"book","type":"update","data":[{"symbol":"ETH/EUR","bids":[{"price":3501.23,"qty":0.00000000},{"price":3500.73,"qty":1.31740156}],"asks":[],"checksum":4157279508,"timestamp":"2024-06-01T17:52:49.181743Z"}]}
{"channel":"book","type":"update","data":[{"symbol":"ETH/EUR","bids":[{"price":3501.19,"qty":1.35346018}],"asks":[],"checksum":795123611,"timestamp":"2024-06-01T17:52:49.182327Z"}]}
{"channel":"book","type":"update","data":[{"symbol":"ETH/EUR","bids":[],"asks":[{"price":3502.62,"qty":0.00000000},{"price":3502.83,"qty":0.00220000},{"price":3502.22,"qty":0.08557900}],"checksum":1242216350,"timestamp":"2024-06-01T17:52:49.199134Z"}]}
{"channel":"book","type":"update","data":[{"symbol":"ETH/EUR","bids":[{"price":3501.38,"qty":2.00000000}],"asks":[],"checksum":3322149614,"timestamp":"2024-06-01T17:52:49.199798Z"}]}
{"channel":"book","type":"update","data":[{"symbol":"ETH/EUR","bids":[{"price":3501.40,"qty":1.60000000}],"asks":[],"checksum":4248764152,"timestamp":"2024-06-01T17:52:49.199853Z"}]}
{"channel":"book","type":"update","data":[{"symbol":"ETH/EUR","bids":[],"asks":[{"price":3501.87,"qty":0.00000000},{"price":3502.83,"qty":0.00220000}],"checksum":65345001,"timestamp":"2024-06-01T17:52:49.220716Z"}]}
{"channel":"book","type":"update","data":[{"symbol":"ETH/EUR","bids":[],"asks":[{"price":3502.21,"qty":0.60400144}],"checksum":3102763098,"timestamp":"2024-06-01T17:52:49.225049Z"}]}
{"channel":"book","type":"update","data":[{"symbol":"ETH/EUR","bids":[],"asks":[{"price":3501.87,"qty":26.32865608}],"checksum":4209676835,"timestamp":"2024-06-01T17:52:49.225381Z"}]}
{"channel":"book","type":"update","data":[{"symbol":"ETH/EUR","bids":[],"asks":[{"price":3501.87,"qty":0.00000000},{"price":3502.61,"qty":0.77800000}],"checksum":3102763098,"timestamp":"2024-06-01T17:52:49.377502Z"}]}
{"channel":"book","type":"update","data":[{"symbol":"ETH/EUR","bids":[],"asks":[{"price":3501.97,"qty":26.32784517}],"checksum":1673051573,"timestamp":"2024-06-01T17:52:49.382909Z"}]}
{"channel":"book","type":"update","data":[{"symbol":"ETH/EUR","bids":[],"asks":[{"price":3501.90,"qty":26.32839974}],"checksum":3338530509,"timestamp":"2024-06-01T17:52:49.382959Z"}]}
{"channel":"book","type":"update","data":[{"symbol":"ETH/EUR","bids":[],"asks":[{"price":3502.08,"qty":26.32927400}],"checksum":1810601646,"timestamp":"2024-06-01T17:52:49.382971Z"}]}
{"channel":"book","type":"update","data":[{"symbol":"ETH/EUR","bids":[],"asks":[{"price":3501.90,"qty":0.00000000},{"price":3502.60,"qty":0.00757473}],"checksum":1585295125,"timestamp":"2024-06-01T17:52:49.388371Z"}]}
{"channel":"book","type":"update","data":[{"symbol":"ETH/EUR","bids":[],"asks":[{"price":3501.97,"qty":0.00000000},{"price":3502.61,"qty":0.77800000}],"checksum":3680267924,"timestamp":"2024-06-01T17:52:49.441354Z"}]}
{"channel":"book","type":"update","data":[{"symbol":"ETH/EUR","bids":[],"asks":[{"price":3501.88,"qty":26.32858590}],"checksum":2817619426,"timestamp":"2024-06-01T17:52:49.446056Z"}]}
{"channel":"book","type":"update","data":[{"symbol":"ETH/EUR","bids":[],"asks":[{"price":3501.88,"qty":0.00000000},{"price":3502.61,"qty":0.77800000}],"checksum":3680267924,"timestamp":"2024-06-01T17:52:49.527774Z"}]}
{"channel":"book","type":"update","data":[{"symbol":"ETH/EUR","bids":[],"asks":[{"price":3501.86,"qty":26.32867218}],"checksum":3149268852,"timestamp":"2024-06-01T17:52:49.534225Z"}]}
{"channel":"book","type":"update","data":[{"symbol":"ETH/EUR","bids":[],"asks":[{"price":3502.60,"qty":0.00000000},{"price":3502.61,"qty":0.77800000}],"checksum":2023808047,"timestamp":"2024-06-01T17:52:49.593593Z"}]}
{"channel":"book","type":"update","data":[{"symbol":"ETH/EUR","bids":[],"asks":[{"price":3501.91,"qty":26.32829667}],"checksum":2625915660,"timestamp":"2024-06-01T17:52:49.843304Z"}]}
{"channel":"book","type":"update","data":[{"symbol":"ETH/EUR","bids":[{"price":3501.57,"qty":26.33081941}],"asks":[],"checksum":2809375526,"timestamp":"2024-06-01T17:52:49.843407Z"}]}
{"channel":"book","type":"update","data":[{"symbol":"ETH/EUR","bids":[{"price":3501.57,"qty":0.00000000},{"price":3501.06,"qty":26.33463077}],"asks":[],"checksum":2065453478,"timestamp":"2024-06-01T17:52:49.997029Z"}]}
{"channel":"book","type":"update","data":[{"symbol":"ETH/EUR","bids":[],"asks":[{"price":3502.42,"qty":0.00000000},{"price":3502.61,"qty":0.77800000}],"checksum":3408834915,"timestamp":"2024-06-01T17:52:49.997147Z"}]}
{"channel":"book","type":"update","data":[{"symbol":"ETH/EUR","bids":[{"price":3501.07,"qty":0.00000000},{"price":3500.87,"qty":5.13432261}],"asks":[],"checksum":3734611142,"timestamp":"2024-06-01T17:52:50.002268Z"}]}
{"channel":"book","type":"update","data":[{"symbol":"ETH/EUR","bids":[{"price":3501.37,"qty":26.33229605}],"asks":[],"checksum":2341696820,"timestamp":"2024-06-01T17:52:50.002765Z"}]}
{"channel":"book","type":"update","data":[{"symbol":"ETH/EUR","bids":[{"price":3501.19,"qty":0.00000000},{"price":3500.87,"qty":5.13432261}],"asks":[],"checksum":2951114253,"timestamp":"2024-06-01T17:52:50.015815Z"}]}
{"channel":"book","type":"update","data":[{"symbol":"ETH/EUR","bids":[{"price":3501.26,"qty":0.00000000},{"price":3500.73,"qty":1.31740156}],"asks":[],"checksum":3466017790,"timestamp":"2024-06-01T17:52:50.017938Z"}]}
{"channel":"book","type":"update","data":[{"symbol":"ETH/EUR","bids":[],"asks":[{"price":3502.08,"qty":0.00220000}],"checksum":294395328,"timestamp":"2024-06-01T17:52:50.018095Z"}]}
{"channel":"book","type":"update","data":[{"symbol":"ETH/EUR","bids":[],"asks":[{"price":3502.27,"qty":26.32566378}],"checksum":4167602476,"timestamp":"2024-06-01T17:52:50.023874Z"}]}
{"channel":"book","type":"update","data":[{"symbol":"ETH/EUR","bids":[],"asks":[{"price":3501.86,"qty":52.65734436}],"checksum":1521784538,"timestamp":"2024-06-01T17:52:50.024057Z"}]}
{"channel":"book","type":"update","data":[{"symbol":"ETH/EUR","bids":[{"price":3501.39,"qty":0.00000000},{"price":3500.70,"qty":0.08559600}],"asks":[],"checksum":706752286,"timestamp":"2024-06-01T17:52:50.037370Z"}]}
{"channel":"book","type":"update","data":[{"symbol":"ETH/EUR","bids":[{"price":3501.06,"qty":0.00000000},{"price":3500.56,"qty":1.31740156}],"asks":[],"checksum":592065679,"timestamp":"2024-06-01T17:52:50.045238Z"}]}
{"channel":"book","type":"update","data":[{"symbol":"ETH/EUR","bids":[{"price":3501.18,"qty":26.33377432}],"asks":[],"checksum":1998857509,"timestamp":"2024-06-01T17:52:50.050245Z"}]}
{"channel":"book","type":"update","data":[{"symbol":"ETH/EUR","bids":[{"price":3501.44,"qty":26.33180384}],"asks":[],"checksum":3618894660,"timestamp":"2024-06-01T17:52:50.054448Z"}]}
{"channel":"book","type":"update","data":[{"symbol":"ETH/EUR","bids":[{"price":3501.44,"qty":0.00000000},{"price":3500.70,"qty":0.08559600}],"asks":[],"checksum":1998857509,"timestamp":"2024-06-01T17:52:50.072757Z"}]}
{"channel":"book","type":"update","data":[{"symbol":"ETH/EUR","bids":[{"price":3501.40,"qty":0.00000000},{"price":3500.56,"qty":1.31740156}],"asks":[],"checksum":2702621311,"timestamp":"2024-06-01T17:52:50.100947Z"}]}
{"channel":"book","type":"update","data":[{"symbol":"ETH/EUR","bids":[{"price":3500.74,"qty":0.61147913}],"asks":[],"checksum":2667270063,"timestamp":"2024-06-01T17:52:50.104580Z"}]}
{"channel":"book","type":"update","data":[{"symbol":"ETH/EUR","bids":[{"price":3501.84,"qty":0.00000000},{"price":3500.56,"qty":1.31740156}],"asks":[],"checksum":993684121,"timestamp":"2024-06-01T17:52:50.109503Z"}]}
{"channel":"book","type":"update","data":[{"symbol":"ETH/EUR","bids":[{"price":3501.30,"qty":26.33286229}],"asks":[],"checksum":72267945,"timestamp":"2024-06-01T17:52:50.113863Z"}]}
{"channel":"book","type":"update","data":[{"symbol":"ETH/EUR","bids":[{"price":3501.06,"qty":1.35351043}],"asks":[],"checksum":3044631274,"timestamp":"2024-06-01T17:52:50.143769Z"}]}
{"channel":"book","type":"update","data":[{"symbol":"ETH/EUR","bids":[{"price":3501.85,"qty":0.00000000},{"price":3500.70,"qty":0.08559600},{"price":3501.39,"qty":0.02855533}],"asks":[],"checksum":2521113739,"timestamp":"2024-06-01T17:52:50.161190Z"}]}
{"channel":"book","type":"update","data":[{"symbol":"ETH/EUR","bids":[],"asks":[{"price":3501.86,"qty":26.32867218}],"checksum":882451325,"timestamp":"2024-06-01T17:52:50.165441Z"}]}
{"channel":"book","type":"update","data":[{"symbol":"ETH/EUR","bids":[],"asks":[{"price":3501.70,"qty":26.32991216}],"checksum":2078939954,"timestamp":"2024-06-01T17:52:50.169676Z"}]}
{"channel":"book","type":"update","data":[{"symbol":"ETH/EUR","bids":[],"asks":[{"price":3501.86,"qty":0.00000000},{"price":3502.57,"qty":0.00220000}],"checksum":2491088764,"timestamp":"2024-06-01T17:52:50.174953Z"}]}
{"channel":"book","type":"update","data":[{"symbol":"ETH/EUR","bids":[],"asks":[{"price":3501.85,"qty":26.32874736}],"checksum":3905726978,"timestamp":"2024-06-01T17:52:50.178553Z"}]}
{"channel":"book","type":"update","data":[{"symbol":"ETH/EUR","bids":[{"price":3501.37,"qty":0.00000000},{"price":3500.70,"qty":0.08559600}],"asks":[],"checksum":2887111792,"timestamp":"2024-06-01T17:52:50.265216Z"}]}
{"channel":"book","type":"update","data":[{"symbol":"ETH/EUR","bids":[{"price":3501.38,"qty":28.33222933}],"asks":[],"checksum":1625009490,"timestamp":"2024-06-01T17:52:50.268969Z"}]}
{"channel":"book","type":"update","data":[{"symbol":"ETH/EUR","bids":[{"price":3501.31,"qty":2.00000000}],"asks":[],"checksum":539246834,"timestamp":"2024-06-01T17:52:50.270692Z"}]}
{"channel":"book","type":"update","data":[{"symbol":"ETH/EUR","bids":[{"price":3501.38,"qty":26.33222933}],"asks":[],"checksum":3921997541,"timestamp":"2024-06-01T17:52:50.270801Z"}]}
{"channel":"book","type":"update","data":[{"symbol":"ETH/EUR","bids":[{"price":3500.73,"qty":0.00000000},{"price":3500.70,"qty":0.08559600}],"asks":[],"checksum":3850872728,"timestamp":"2024-06-01T17:52:50.288444Z"}]}
{"channel":"book","type":"update","data":[{"symbol":"ETH/EUR","bids":[],"asks":[{"price":3501.85,"qty":0.00000000},{"price":3502.57,"qty":0.00220000}],"checksum":4017003401,"timestamp":"2024-06-01T17:52:50.332049Z"}]}
{"channel":"book","type":"update","data":[{"symbol":"ETH/EUR","bids":[{"price":3501.38,"qty":0.00000000},{"price":3500.56,"qty":1.31740156}],"asks":[],"checksum":2653179006,"timestamp":"2024-06-01T17:52:50.332143Z"}]}
{"channel":"book","type":"update","data":[{"symbol":"ETH/EUR","bids":[],"asks":[{"price":3501.69,"qty":26.33000244}],"checksum":1340563611,"timestamp":"2024-06-01T17:52:50.336587Z"}]}
{"channel":"book","type":"update","data":[{"symbol":"ETH/EUR","bids":[{"price":3501.36,"qty":26.33240764}],"asks":[],"checksum":2018361066,"timestamp":"2024-06-01T17:52:50.336604Z"}]}
{"channel":"book","type":"update","data":[{"symbol":"ETH/EUR","bids":[{"price":3501.39,"qty":2.02855533}],"asks":[],"checksum":1328788040,"timestamp":"2024-06-01T17:52:50.337427Z"}]}
{"channel":"book","type":"update","data":[{"symbol":"ETH/EUR","bids":[{"price":3501.06,"qty":0.00000000},{"price":3500.56,"qty":1.31740156}],"asks":[],"checksum":1068224539,"timestamp":"2024-06-01T17:52:50.351554Z"}]}
{"channel":"book","type":"update","data":[{"symbol":"ETH/EUR","bids":[],"asks":[{"price":3501.69,"qty":0.00000000},{"price":3502.57,"qty":0.00220000}],"checksum":2883467813,"timestamp":"2024-06-01T17:52:50.365931Z"}]}
{"channel":"book","type":"update","data":[{"symbol":"ETH/EUR","bids":[{"price":3501.36,"qty":27.93240764}],"asks":[],"checksum":317279973,"timestamp":"2024-06-01T17:52:50.369026Z"}]}
{"channel":"book","type":"update","data":[{"symbol":"ETH/EUR","bids":[{"price":3501.31,"qty":0.00000000},{"price":3500.54,"qty":0.72912968}],"asks":[],"checksum":3090756774,"timestamp":"2024-06-01T17:52:50.371386Z"}]}
{"channel":"book","type":"update","data":[{"symbol":"ETH/EUR","bids":[{"price":3501.36,"qty":1.60000000}],"asks":[],"checksum":631325911,"timestamp":"2024-06-01T17:52:50.388690Z"}]}
{"channel":"book","type":"update","data":[{"symbol":"ETH/EUR","bids":[],"asks":[{"price":3501.67,"qty":26.33016035}],"checksum":188690658,"timestamp":"2024-06-01T17:52:50.393004Z"}]}
{"channel":"book","type":"update","data":[{"symbol":"ETH/EUR","bids":[],"asks":[{"price":3501.67,"qty":0.00000000},{"price":3502.57,"qty":0.00220000}],"checksum":631325911,"timestamp":"2024-06-01T17:52:50.410684Z"}]}
{"channel":"book","type":"update","data":[{"symbol":"ETH/EUR","bids":[{"price":3501.18,"qty":0.00000000},{"price":3500.40,"qty":0.52710000}],"asks":[],"checksum":2755574923,"timestamp":"2024-06-01T17:52:50.410759Z"}]}
{"channel":"book","type":"update","data":[{"symbol":"ETH/EUR","bids":[{"price":3500.40,"qty":0.00000000},{"price":3500.39,"qty":1.49780000}],"asks":[],"checksum":1991118454,"timestamp":"2024-06-01T17:52:50.412936Z"}]}
{"channel":"book","type":"update","data":[{"symbol":"ETH/EUR","bids":[{"price":3500.87,"qty":0.00000000},{"price":3500.15,"qty":3.01305282}],"asks":[],"checksum":4217774998,"timestamp":"2024-06-01T17:52:50.446452Z"}]}
{"channel":"book","type":"update","data":[{"symbol":"ETH/EUR","bids":[{"price":3501.39,"qty":0.02855533}],"asks":[],"checksum":3712763489,"timestamp":"2024-06-01T17:52:50.447238Z"}]}
{"channel":"book","type":"update","data":[{"symbol":"ETH/EUR","bids":[{"price":3501.36,"qty":0.00000000},{"price":3500.11,"qty":1.05310694}],"asks":[],"checksum":1435235957,"timestamp":"2024-06-01T17:52:50.449297Z"}]}
{"channel":"book","type":"update","data":[{"symbol":"ETH/EUR","bids":[{"price":3500.41,"qty":1.31690885}],"asks":[],"checksum":2837261710,"timestamp":"2024-06-01T17:52:50.450474Z"}]}
{"channel":"book","type":"update","data":[{"symbol":"ETH/EUR","bids":[],"asks":[{"price":3501.70,"qty":0.00000000},{"price":3502.60,"qty":0.00756961}],"checksum":348644103,"timestamp":"2024-06-01T17:52:50.450751Z"}]}
{"channel":"book","type":"update","data":[{"symbol":"ETH/EUR","bids":[{"price":3500.69,"qty":6.92318992}],"asks":[],"checksum":1467313737,"timestamp":"2024-06-01T17:52:50.451029Z"}]}
{"channel":"book","type":"update","data":[{"symbol":"ETH/EUR","bids":[{"price":3501.10,"qty":0.00000000},{"price":3500.15,"qty":3.01305282}],"asks":[],"checksum":624226695,"timestamp":"2024-06-01T17:52:50.452949Z"}]}
{"channel":"book","type":"update","data":[{"symbol":"ETH/EUR","bids":[],"asks":[{"price":3501.59,"qty":26.33070383}],"checksum":2179139720,"timestamp":"2024-06-01T17:52:50.453978Z"}]}
{"channel":"book","type":"update","data":[{"symbol":"ETH/EUR","bids":[],"asks":[{"price":3501.91,"qty":0.00000000},{"price":3502.60,"qty":0.00756961}],"checksum":2049897020,"timestamp":"2024-06-01T17:52:50.455137Z"}]}
{"channel":"book","type":"update","data":[{"symbol":"ETH/EUR","bids":[],"asks":[{"price":3501.67,"qty":26.33013146}],"checksum":2416418729,"timestamp":"2024-06-01T17:52:50.458472Z"}]}
{"channel":"book","type":"update","data":[{"symbol":"ETH/EUR","bids":[],"asks":[{"price":3501.90,"qty":26.32837144}],"checksum":101575101,"timestamp":"2024-06-01T17:52:50.458548Z"}]}
{"channel":"book","type":"update","data":[{"symbol":"ETH/EUR","bids":[{"price":3501.30,"qty":0.00000000},{"price":3500.11,"qty":1.05310694}],"asks":[],"checksum":2468271537,"timestamp":"2024-06-01T17:52:50.465796Z"}]}
{"channel":"book","type":"update","data":[{"symbol":"ETH/EUR","bids":[],"asks":[{"price":3501.59,"qty":0.00000000},{"price":3502.57,"qty":0.00220000}],"checksum":3197143892,"timestamp":"2024-06-01T17:52:50.465896Z"}]}
{"channel":"book","type":"update","data":[{"symbol":"ETH/EUR","bids":[],"asks":[{"price":3502.27,"qty":0.00000000},{"price":3502.60,"qty":0.00756961}],"checksum":3106774840,"timestamp":"2024-06-01T17:52:50.465907Z"}]}
{"channel":"book","type":"update","data":[{"symbol":"ETH/EUR","bids":[{"price":3500.80,"qty":1.60000000}],"asks":[],"checksum":3360634709,"timestamp":"2024-06-01T17:52:50.468800Z"}]}
{"channel":"book","type":"update","data":[{"symbol":"ETH/EUR","bids":[{"price":3500.85,"qty":1.35359162}],"asks":[],"checksum":2245409534,"timestamp":"2024-06-01T17:52:50.472038Z"}]}
{"channel":"book","type":"update","data":[{"symbol":"ETH/EUR","bids":[],"asks":[{"price":3501.67,"qty":0.00000000},{"price":3502.61,"qty":0.77800000}],"checksum":2117345267,"timestamp":"2024-06-01T17:52:50.472808Z"}]}
{"channel":"book","type":"update","data":[{"symbol":"ETH/EUR","bids":[],"asks":[{"price":3502.36,"qty":0.00000000},{"price":3502.83,"qty":0.00220000}],"checksum":974513515,"timestamp":"2024-06-01T17:52:50.475470Z"}]}
{"channel":"book","type":"update","data":[{"symbol":"ETH/EUR","bids":[],"asks":[{"price":3501.87,"qty":1.60000000}],"checksum":755158636,"timestamp":"2024-06-01T17:52:50.475731Z"}]}
{"channel":"book","type":"update","data":[{"symbol":"ETH/EUR","bids":[],"asks":[{"price":3501.90,"qty":0.00000000},{"price":3502.83,"qty":0.00220000}],"checksum":1077720698,"timestamp":"2024-06-01T17:52:50.477228Z"}]}
{"channel":"book","type":"update","data":[{"symbol":"ETH/EUR","bids":[],"asks":[{"price":3502.60,"qty":3.96056961}],"checksum":2299339752,"timestamp":"2024-06-01T17:52:50.479003Z"}]}
{"channel":"book","type":"update","data":[{"symbol":"ETH/EUR","bids":[{"price":3500.85,"qty":0.00000000},{"price":3500.15,"qty":3.01305282}],"asks":[],"checksum":3298045507,"timestamp":"2024-06-01T17:52:50.479435Z"}]}
{"channel":"book","type":"update","data":[{"symbol":"ETH/EUR","bids":[],"asks":[{"price":3501.87,"qty":0.00000000},{"price":3502.94,"qty":1.06800000}],"checksum":630983995,"timestamp":"2024-06-01T17:52:50.480009Z"}]}
{"channel":"book","type":"update","data":[{"symbol":"ETH/EUR","bids":[{"price":3501.39,"qty":0.00000000},{"price":3500.11,"qty":1.05310694},{"price":3501.31,"qty":0.02855668}],"asks":[],"checksum":1868460476,"timestamp":"2024-06-01T17:52:50.489475Z"}]}
{"channel":"book","type":"update","data":[{"symbol":"ETH/EUR","bids":[{"price":3500.39,"qty":0.49780000}],"asks":[],"checksum":1806463506,"timestamp":"2024-06-01T17:52:50.517261Z"}]}
{"channel":"book","type":"update","data":[{"symbol":"ETH/EUR","bids":[],"asks":[{"price":3501.53,"qty":26.33122235}],"checksum":1137887805,"timestamp":"2024-06-01T17:52:50.517795Z"}]}
{"channel":"book","type":"update","data":[{"symbol":"ETH/EUR","bids":[],"asks":[{"price":3502.07,"qty":26.32709339}],"checksum":3803450127,"timestamp":"2024-06-01T17:52:50.523972Z"}]}
{"channel":"book","type":"update","data":[{"symbol":"ETH/EUR","bids":[{"price":3500.39,"qty":0.00000000},{"price":3500.11,"qty":1.05310694}],"asks":[],"checksum":1431882667,"timestamp":"2024-06-01T17:52:50.540674Z"}]}
{"channel":"book","type":"update","data":[{"symbol":"ETH/EUR","bids":[{"price":3500.77,"qty":1.35362256}],"asks":[],"checksum":1688743812,"timestamp":"2024-06-01T17:52:50.605900Z"}]}
{"channel":"book","type":"update","data":[{"symbol":"ETH/EUR","bids":[{"price":3500.78,"qty":2.00000000}],"asks":[],"checksum":988146042,"timestamp":"2024-06-01T17:52:50.610882Z"}]}
{"channel":"book","type":"update","data":[{"symbol":"ETH/EUR","bids":[{"price":3500.71,"qty":0.84644082}],"asks":[],"checksum":1831490027,"timestamp":"2024-06-01T17:52:50.611146Z"}]}
{"channel":"book","type":"update","data":[{"symbol":"ETH/EUR","bids":[],"asks":[{"price":3501.52,"qty":2.00000000}],"checksum":1158681732,"timestamp":"2024-06-01T17:52:50.657998Z"}]}
{"channel":"book","type":"update","data":[{"symbol":"ETH/EUR","bids":[],"asks":[{"price":3501.60,"qty":26.33068156}],"checksum":3255218724,"timestamp":"2024-06-01T17:52:50.671404Z"}]}
{"channel":"book","type":"update","data":[{"symbol":"ETH/EUR","bids":[{"price":3500.75,"qty":4.00000000}],"asks":[],"checksum":1916825702,"timestamp":"2024-06-01T17:52:50.719515Z"}]}
{"channel":"book","type":"update","data":[{"symbol":"ETH/EUR","bids":[{"price":3500.77,"qty":0.00000000},{"price":3500.54,"qty":0.72912968}],"asks":[],"checksum":3328828868,"timestamp":"2024-06-01T17:52:50.756962Z"}]}
{"channel":"book","type":"update","data":[{"symbol":"ETH/EUR","bids":[],"asks":[{"price":3501.53,"qty":0.00000000},{"price":3502.60,"qty":3.96056961}],"checksum":3273939060,"timestamp":"2024-06-01T17:52:50.782372Z"}]}
{"channel":"book","type":"update","data":[{"symbol":"ETH/EUR","bids":[],"asks":[{"price":3501.78,"qty":26.32928939}],"checksum":774287136,"timestamp":"2024-06-01T17:52:50.786361Z"}]}
{"channel":"book","type":"update","data":[{"symbol":"ETH/EUR","bids":[],"asks":[{"price":3501.55,"qty":26.33104908}],"checksum":3726426062,"timestamp":"2024-06-01T17:52:50.786387Z"}]}
{"channel":"book","type":"update","data":[{"symbol":"ETH/EUR","bids":[],"asks":[{"price":3502.22,"qty":0.00000000},{"price":3502.57,"qty":0.00220000},{"price":3501.86,"qty":0.08558600}],"checksum":3568274621,"timestamp":"2024-06-01T17:52:50.883180Z"}]}
{"channel":"book","type":"update","data":[{"symbol":"ETH/EUR","bids":[{"price":3500.69,"qty":8.27684341}],"asks":[],"checksum":621027589,"timestamp":"2024-06-01T17:52:50.957602Z"}]}
{"channel":"book","type":"update","data":[{"symbol":"ETH/EUR","bids":[{"price":3500.69,"qty":6.92318992}],"asks":[],"checksum":3568274621,"timestamp":"2024-06-01T17:52:50.966226Z"}]}
{"channel":"book","type":"update","data":[{"symbol":"ETH/EUR","bids":[],"asks":[{"price":3501.55,"qty":0.00000000},{"price":3502.57,"qty":0.00220000}],"checksum":1016425373,"timestamp":"2024-06-01T17:52:50.966586Z"}]}
{"channel":"book","type":"update","data":[{"symbol":"ETH/EUR","bids":[],"asks":[{"price":3501.52,"qty":28.33127640}],"checksum":4094099042,"timestamp":"2024-06-01T17:52:50.971445Z"}]}
{"channel":"book","type":"update","data":[{"symbol":"ETH/EUR","bids":[],"asks":[{"price":3501.52,"qty":2.00000000}],"checksum":1016425373,"timestamp":"2024-06-01T17:52:51.016999Z"}]}
{"channel":"book","type":"update","data":[{"symbol":"ETH/EUR","bids":[{"price":3500.68,"qty":1.35365736}],"asks":[],"checksum":699638750,"timestamp":"2024-06-01T17:52:51.087591Z"}]}
{"channel":"book","type":"update","data":[{"symbol":"ETH/EUR","bids":[{"price":3501.31,"qty":0.00000000},{"price":3500.54,"qty":0.72912968},{"price":3500.81,"qty":0.02856076}],"asks":[],"checksum":2588496810,"timestamp":"2024-06-01T17:52:51.166297Z"}]}
{"channel":"book","type":"update","data":[{"symbol":"ETH/EUR","bids":[],"asks":[{"price":3502.56,"qty":0.00756812}],"checksum":981282530,"timestamp":"2024-06-01T17:52:51.166431Z"}]}
{"channel":"book","type":"update","data":[{"symbol":"ETH/EUR","bids":[],"asks":[{"price":3501.51,"qty":26.33135989}],"checksum":3155698800,"timestamp":"2024-06-01T17:52:51.171398Z"}]}
{"channel":"book","type":"update","data":[{"symbol":"ETH/EUR","bids":[{"price":3500.82,"qty":0.84644082}],"asks":[],"checksum":1988805840,"timestamp":"2024-06-01T17:52:51.171839Z"}]}
{"channel":"book","type":"update","data":[{"symbol":"ETH/EUR","bids":[],"asks":[{"price":3501.50,"qty":2.00000000}],"checksum":696565835,"timestamp":"2024-06-01T17:52:51.224907Z"}]}
{"channel":"book","type":"update","data":[{"symbol":"ETH/EUR","bids":[],"asks":[{"price":3501.52,"qty":0.00000000},{"price":3502.45,"qty":0.00220000}],"checksum":1160287119,"timestamp":"2024-06-01T17:52:51.225068Z"}]}
{"channel":"book","type":"update","data":[{"symbol":"ETH/EUR","bids":[{"price":3500.81,"qty":2.02856076}],"asks":[],"checksum":245817075,"timestamp":"2024-06-01T17:52:51.229923Z"}]}
{"channel":"book","type":"update","data":[{"symbol":"ETH/EUR","bids":[{"price":3500.71,"qty":0.00000000},{"price":3500.56,"qty":1.31740156}],"asks":[],"checksum":2336506281,"timestamp":"2024-06-01T17:52:51.230268Z"}]}
{"channel":"book","type":"update","data":[{"symbol":"ETH/EUR","bids":[{"price":3500.80,"qty":0.00000000},{"price":3500.54,"qty":0.72912968}],"asks":[],"checksum":3499531894,"timestamp":"2024-06-01T17:52:51.232581Z"}]}
{"channel":"book","type":"update","data":[{"symbol":"ETH/EUR","bids":[{"price":3500.88,"qty":1.60000000}],"asks":[],"checksum":2654961207,"timestamp":"2024-06-01T17:52:51.232592Z"}]}
{"channel":"book","type":"update","data":[{"symbol":"ETH/EUR","bids":[{"price":3500.82,"qty":1.19126651}],"asks":[],"checksum":120829529,"timestamp":"2024-06-01T17:52:51.318914Z"}]}
{"channel":"book","type":"update","data":[{"symbol":"ETH/EUR","bids":[{"price":3500.89,"qty":0.84644082}],"asks":[],"checksum":2728745132,"timestamp":"2024-06-01T17:52:51.325512Z"}]}
{"channel":"book","type":"update","data":[{"symbol":"ETH/EUR","bids":[{"price":3500.81,"qty":0.02856076}],"asks":[],"checksum":4112924428,"timestamp":"2024-06-01T17:52:51.326331Z"}]}
{"channel":"book","type":"update","data":[{"symbol":"ETH/EUR","bids":[{"price":3500.82,"qty":1.51905352}],"asks":[],"checksum":615540764,"timestamp":"2024-06-01T17:52:51.327077Z"}]}
{"channel":"book","type":"update","data":[{"symbol":"ETH/EUR","bids":[{"price":3500.94,"qty":26.33554834}],"asks":[],"checksum":3489998610,"timestamp":"2024-06-01T17:52:51.485669Z"}]}
{"channel":"book","type":"update","data":[{"symbol":"ETH/EUR","bids":[{"price":3501.21,"qty":26.33348596}],"asks":[],"checksum":2804838650,"timestamp":"2024-06-01T17:52:51.485758Z"}]}
{"channel":"book","type":"update","data":[{"symbol":"ETH/EUR","bids":[{"price":3500.88,"qty":0.00000000},{"price":3500.69,"qty":6.92318992}],"asks":[],"checksum":4088976950,"timestamp":"2024-06-01T17:52:51.488542Z"}]}
{"channel":"book","type":"update","data":[{"symbol":"ETH/EUR","bids":[{"price":3501.00,"qty":1.60000000}],"asks":[],"checksum":1543939042,"timestamp":"2024-06-01T17:52:51.488884Z"}]}
{"channel":"book","type":"update","data":[{"symbol":"ETH/EUR","bids":[{"price":3500.95,"qty":6.00000000}],"asks":[],"checksum":4109365932,"timestamp":"2024-06-01T17:52:51.490025Z"}]}
{"channel":"book","type":"update","data":[{"symbol":"ETH/EUR","bids":[{"price":3500.95,"qty":8.00000000}],"asks":[],"checksum":1532726588,"timestamp":"2024-06-01T17:52:51.490638Z"}]}
{"channel":"book","type":"update","data":[{"symbol":"ETH/EUR","bids":[{"price":3500.89,"qty":0.00000000},{"price":3500.70,"qty":0.08559600}],"asks":[],"checksum":2456047691,"timestamp":"2024-06-01T17:52:51.490893Z"}]}
{"channel":"book","type":"update","data":[{"symbol":"ETH/EUR","bids":[{"price":3500.94,"qty":0.00000000},{"price":3500.69,"qty":6.92318992}],"asks":[],"checksum":2730545651,"timestamp":"2024-06-01T17:52:51.491791Z"}]}
{"channel":"book","type":"update","data":[{"symbol":"ETH/EUR","bids":[{"price":3501.14,"qty":26.33405714}],"asks":[],"checksum":3058995598,"timestamp":"2024-06-01T17:52:51.495407Z"}]}
{"channel":"book","type":"update","data":[{"symbol":"ETH/EUR","bids":[{"price":3501.22,"qty":2.77000000}],"asks":[],"checksum":663543583,"timestamp":"2024-06-01T17:52:51.580183Z"}]}
{"channel":"book","type":"update","data":[{"symbol":"ETH/EUR","bids":[{"price":3500.95,"qty":6.00000000}],"asks":[],"checksum":1217742190,"timestamp":"2024-06-01T17:52:51.591188Z"}]}
{"channel":"book","type":"update","data":[{"symbol":"ETH/EUR","bids":[],"asks":[{"price":3501.51,"qty":0.00000000},{"price":3502.51,"qty":3.01305282}],"checksum":2668777438,"timestamp":"2024-06-01T17:52:51.593578Z"}]}
{"channel":"book","type":"update","data":[{"symbol":"ETH/EUR","bids":[{"price":3501.21,"qty":0.00000000},{"price":3500.70,"qty":0.08559600}],"asks":[],"checksum":114299393,"timestamp":"2024-06-01T17:52:51.593688Z"}]}
{"channel":"book","type":"update","data":[{"symbol":"ETH/EUR","bids":[{"price":3501.22,"qty":29.10344755}],"asks":[],"checksum":2391505214,"timestamp":"2024-06-01T17:52:51.597751Z"}]}
{"channel":"book","type":"update","data":[{"symbol":"ETH/EUR","bids":[],"asks":[{"price":3501.53,"qty":26.33119670}],"checksum":1814520059,"timestamp":"2024-06-01T17:52:51.597838Z"}]}
{"channel":"book","type":"update","data":[{"symbol":"ETH/EUR","bids":[],"asks":[{"price":3501.50,"qty":0.00000000},{"price":3502.51,"qty":3.01305282}],"checksum":2963231101,"timestamp":"2024-06-01T17:52:51.917331Z"}]}
{"channel":"book","type":"update","data":[{"symbol":"ETH/EUR","bids":[{"price":3501.22,"qty":2.77000000}],"asks":[],"checksum":2089781990,"timestamp":"2024-06-01T17:52:51.947852Z"}]}
{"channel":"book","type":"update","data":[{"symbol":"ETH/EUR","bids":[],"asks":[{"price":3501.53,"qty":0.00000000},{"price":3502.56,"qty":0.00756812}],"checksum":3355769075,"timestamp":"2024-06-01T17:52:51.947862Z"}]}
{"channel":"book","type":"update","data":[{"symbol":"ETH/EUR","bids":[],"asks":[{"price":3501.60,"qty":0.00000000},{"price":3502.57,"qty":0.00220000}],"checksum":1605143350,"timestamp":"2024-06-01T17:52:51.955746Z"}]}
{"channel":"book","type":"update","data":[{"symbol":"ETH/EUR","bids":[{"price":3501.14,"qty":0.00000000},{"price":3500.69,"qty":6.92318992}],"asks":[],"checksum":2323998107,"timestamp":"2024-06-01T17:52:51.955755Z"}]}
{"channel":"book","type":"update","data":[{"symbol":"ETH/EUR","bids":[],"asks":[{"price":3501.78,"qty":0.00000000},{"price":3502.61,"qty":0.77800000}],"checksum":2400530703,"timestamp":"2024-06-01T17:52:51.958628Z"}]}
{"channel":"book","type":"update","data":[{"symbol":"ETH/EUR","bids":[{"price":3500.74,"qty":0.00000000},{"price":3500.68,"qty":1.35365736}],"asks":[],"checksum":2116403535,"timestamp":"2024-06-01T17:52:51.962134Z"}]}
{"channel":"book","type":"update","data":[{"symbol":"ETH/EUR","bids":[],"asks":[{"price":3502.21,"qty":0.00000000},{"price":3502.83,"qty":0.00220000}],"checksum":3977714013,"timestamp":"2024-06-01T17:52:51.962800Z"}]}
{"channel":"book","type":"update","data":[{"symbol":"ETH/EUR","bids":[],"asks":[{"price":3501.67,"qty":26.33017570}],"checksum":134324290,"timestamp":"2024-06-01T17:52:51.967873Z"}]}
{"channel":"book","type":"update","data":[{"symbol":"ETH/EUR","bids":[],"asks":[{"price":3501.85,"qty":26.32874736}],"checksum":508771670,"timestamp":"2024-06-01T17:52:51.968014Z"}]}
{"channel":"book","type":"update","data":[{"symbol":"ETH/EUR","bids":[{"price":3501.33,"qty":26.33260187}],"asks":[],"checksum":2907137121,"timestamp":"2024-06-01T17:52:51.968065Z"}]}
{"channel":"book","type":"update","data":[{"symbol":"ETH/EUR","bids":[{"price":3501.09,"qty":26.33440411}],"asks":[],"checksum":2226949585,"timestamp":"2024-06-01T17:52:51.968101Z"}]}
{"channel":"book","type":"update","data":[{"symbol":"ETH/EUR","bids":[],"asks":[{"price":3501.88,"qty":26.32857197}],"checksum":3990594636,"timestamp":"2024-06-01T17:52:51.968187Z"}]}
{"channel":"book","type":"update","data":[{"symbol":"ETH/EUR","bids":[{"price":3501.09,"qty":0.00000000},{"price":3500.69,"qty":6.92318992}],"asks":[],"checksum":3433826290,"timestamp":"2024-06-01T17:52:51.977362Z"}]}
{"channel":"book","type":"update","data":[{"symbol":"ETH/EUR","bids":[],"asks":[{"price":3501.67,"qty":0.00000000},{"price":3502.57,"qty":0.00220000}],"checksum":678891104,"timestamp":"2024-06-01T17:52:51.977413Z"}]}
{"channel":"book","type":"update","data":[{"symbol":"ETH/EUR","bids":[],"asks":[{"price":3501.88,"qty":0.00000000},{"price":3502.61,"qty":0.77800000}],"checksum":2575725712,"timestamp":"2024-06-01T17:52:51.977487Z"}]}
{"channel":"book","type":"update","data":[{"symbol":"ETH/EUR","bids":[{"price":3501.33,"qty":0.00000000},{"price":3500.68,"qty":1.35365736}],"asks":[],"checksum":2979672127,"timestamp":"2024-06-01T17:52:51.977544Z"}]}
{"channel":"book","type":"update","data":[{"symbol":"ETH/EUR","bids":[],"asks":[{"price":3502.26,"qty":26.32568644}],"checksum":2991044344,"timestamp":"2024-06-01T17:52:51.983759Z"}]}
{"channel":"book","type":"update","data":[{"symbol":"ETH/EUR","bids":[{"price":3501.55,"qty":26.33097131}],"asks":[],"checksum":2467696695,"timestamp":"2024-06-01T17:52:52.047237Z"}]}
{"channel":"book","type":"update","data":[{"symbol":"ETH/EUR","bids":[],"asks":[{"price":3501.85,"qty":0.00000000},{"price":3502.61,"qty":0.77800000}],"checksum":3860827711,"timestamp":"2024-06-01T17:52:52.048996Z"}]}
{"channel":"book","type":"update","data":[{"symbol":"ETH/EUR","bids":[{"price":3501.55,"qty":0.00000000},{"price":3500.68,"qty":1.35365736}],"asks":[],"checksum":3514442298,"timestamp":"2024-06-01T17:52:52.051466Z"}]}
{"channel":"book","type":"update","data":[{"symbol":"ETH/EUR","bids":[],"asks":[{"price":3501.87,"qty":26.32861579}],"checksum":4182952129,"timestamp":"2024-06-01T17:52:52.055671Z"}]}
{"channel":"book","type":"update","data":[{"symbol":"ETH/EUR","bids":[{"price":3501.49,"qty":26.33141368}],"asks":[],"checksum":2514146064,"timestamp":"2024-06-01T17:52:52.055767Z"}]}
{"channel":"book","type":"update","data":[{"symbol":"ETH/EUR","bids":[{"price":3501.49,"qty":0.00000000},{"price":3500.68,"qty":1.35365736}],"asks":[],"checksum":4182952129,"timestamp":"2024-06-01T17:52:52.059904Z"}]}
{"channel":"book","type":"update","data":[{"symbol":"ETH/EUR","bids":[{"price":3501.01,"qty":0.66501790}],"asks":[],"checksum":479548503,"timestamp":"2024-06-01T17:52:52.063751Z"}]}
{"channel":"book","type":"update","data":[{"symbol":"ETH/EUR","bids":[],"asks":[{"price":3501.87,"qty":0.00000000},{"price":3502.60,"qty":0.65105882}],"checksum":1555013715,"timestamp":"2024-06-01T17:52:52.074480Z"}]}
{"channel":"book","type":"update","data":[{"symbol":"ETH/EUR","bids":[{"price":3500.70,"qty":0.00000000},{"price":3500.68,"qty":1.35365736},{"price":3501.07,"qty":0.08559100}],"asks":[],"checksum":1530036146,"timestamp":"2024-06-01T17:52:52.127716Z"}]}
{"channel":"book","type":"update","data":[{"symbol":"ETH/EUR","bids":[],"asks":[{"price":3501.86,"qty":0.00000000},{"price":3502.61,"qty":0.77800000},{"price":3502.40,"qty":0.08557500}],"checksum":613897683,"timestamp":"2024-06-01T17:52:52.149085Z"}]}
{"channel":"book","type":"update","data":[{"symbol":"ETH/EUR","bids":[],"asks":[{"price":3502.26,"qty":0.00000000},{"price":3502.61,"qty":0.77800000}],"checksum":848734104,"timestamp":"2024-06-01T17:52:52.150232Z"}]}
{"channel":"book","type":"update","data":[{"symbol":"ETH/EUR","bids":[{"price":3501.59,"qty":26.33063177}],"asks":[],"checksum":1712200197,"timestamp":"2024-06-01T17:52:52.154265Z"}]}
{"channel":"book","type":"update","data":[{"symbol":"ETH/EUR","bids":[],"asks":[{"price":3502.06,"qty":26.32716857}],"checksum":2757227769,"timestamp":"2024-06-01T17:52:52.154345Z"}]}
{"channel":"book","type":"update","data":[{"symbol":"ETH/EUR","bids":[{"price":3501.23,"qty":1.10000000}],"asks":[],"checksum":2532281444,"timestamp":"2024-06-01T17:52:52.160093Z"}]}
{"channel":"book","type":"update","data":[{"symbol":"ETH/EUR","bids":[],"asks":[{"price":3502.06,"qty":0.00000000},{"price":3502.61,"qty":0.77800000}],"checksum":1421238936,"timestamp":"2024-06-01T17:52:52.160410Z"}]}
{"channel":"book","type":"update","data":[{"symbol":"ETH/EUR","bids":[{"price":3501.59,"qty":0.00000000},{"price":3500.75,"qty":4.00000000}],"asks":[],"checksum":729819916,"timestamp":"2024-06-01T17:52:52.160552Z"}]}
{"channel":"book","type":"update","data":[{"symbol":"ETH/EUR","bids":[],"asks":[{"price":3502.05,"qty":26.32724374}],"checksum":906489084,"timestamp":"2024-06-01T17:52:52.163919Z"}]}
{"channel":"book","type":"update","data":[{"symbol":"ETH/EUR","bids":[],"asks":[{"price":3502.05,"qty":0.00000000},{"price":3502.61,"qty":0.77800000}],"checksum":729819916,"timestamp":"2024-06-01T17:52:52.170798Z"}]}
{"channel":"book","type":"update","data":[{"symbol":"ETH/EUR","bids":[{"price":3501.22,"qty":0.00000000},{"price":3500.69,"qty":6.92318992}],"asks":[],"checksum":3654216347,"timestamp":"2024-06-01T17:52:52.180346Z"}]}
{"channel":"book","type":"update","data":[{"symbol":"ETH/EUR","bids":[],"asks":[{"price":3502.06,"qty":2.00000000}],"checksum":2488663282,"timestamp":"2024-06-01T17:52:52.213774Z"}]}
{"channel":"book","type":"update","data":[{"symbol":"ETH/EUR","bids":[{"price":3501.60,"qty":26.33058966}],"asks":[],"checksum":3652410739,"timestamp":"2024-06-01T17:52:52.218347Z"}]}
{"channel":"book","type":"update","data":[{"symbol":"ETH/EUR","bids":[],"asks":[{"price":3501.91,"qty":26.32836918}],"checksum":481121761,"timestamp":"2024-06-01T17:52:52.218416Z"}]}
{"channel":"book","type":"update","data":[{"symbol":"ETH/EUR","bids":[{"price":3501.01,"qty":2.66501790}],"asks":[],"checksum":3502264694,"timestamp":"2024-06-01T17:52:52.219058Z"}]}
{"channel":"book","type":"update","data":[{"symbol":"ETH/EUR","bids":[{"price":3500.81,"qty":0.00000000},{"price":3500.69,"qty":6.92318992},{"price":3501.24,"qty":0.02855728}],"asks":[],"checksum":4292743305,"timestamp":"2024-06-01T17:52:52.261603Z"}]}
{"channel":"book","type":"update","data":[{"symbol":"ETH/EUR","bids":[],"asks":[{"price":3502.56,"qty":0.00000000},{"price":3502.60,"qty":0.65105882},{"price":3502.06,"qty":2.00756813}],"checksum":151744187,"timestamp":"2024-06-01T17:52:52.261875Z"}]}
{"channel":"book","type":"update","data":[{"symbol":"ETH/EUR","bids":[{"price":3501.01,"qty":0.66501790}],"asks":[],"checksum":711427973,"timestamp":"2024-06-01T17:52:52.267422Z"}]}
{"channel":"book","type":"update","data":[{"symbol":"ETH/EUR","bids":[],"asks":[{"price":3502.06,"qty":2.00000000},{"price":3502.59,"qty":0.00756752}],"checksum":3097887189,"timestamp":"2024-06-01T17:52:52.317627Z"}]}
{"channel":"book","type":"update","data":[{"symbol":"ETH/EUR","bids":[{"price":3501.60,"qty":0.00000000},{"price":3500.69,"qty":6.92318992}],"asks":[],"checksum":2208939264,"timestamp":"2024-06-01T17:52:52.450661Z"}]}
{"channel":"book","type":"update","data":[{"symbol":"ETH/EUR","bids":[],"asks":[{"price":3502.18,"qty":26.32627448}],"checksum":189692349,"timestamp":"2024-06-01T17:52:52.455285Z"}]}
{"channel":"book","type":"update","data":[{"symbol":"ETH/EUR","bids":[{"price":3501.01,"qty":2.66501790}],"asks":[],"checksum":2868182083,"timestamp":"2024-06-01T17:52:52.456688Z"}]}
{"channel":"book","type":"update","data":[{"symbol":"ETH/EUR","bids":[],"asks":[{"price":3501.91,"qty":0.00000000},{"price":3502.59,"qty":0.00756752}],"checksum":2346414649,"timestamp":"2024-06-01T17:52:52.469414Z"}]}
{"channel":"book","type":"update","data":[{"symbol":"ETH/EUR","bids":[],"asks":[{"price":3502.07,"qty":0.00000000},{"price":3502.60,"qty":0.65105882}],"checksum":904985083,"timestamp":"2024-06-01T17:52:52.477156Z"}]}
{"channel":"book","type":"update","data":[{"symbol":"ETH/EUR","bids":[],"asks":[{"price":3501.93,"qty":26.32817271}],"checksum":1274836364,"timestamp":"2024-06-01T17:52:52.480821Z"}]}
{"channel":"book","type":"update","data":[{"symbol":"ETH/EUR","bids":[],"asks":[{"price":3502.05,"qty":26.32724374}],"checksum":4072392840,"timestamp":"2024-06-01T17:52:52.480901Z"}]}
{"channel":"book","type":"update","data":[{"symbol":"ETH/EUR","bids":[],"asks":[{"price":3502.43,"qty":26.32439478}],"checksum":1564309891,"timestamp":"2024-06-01T17:52:52.485392Z"}]}
{"channel":"book","type":"update","data":[{"symbol":"ETH/EUR","bids":[],"asks":[{"price":3502.06,"qty":0.00000000},{"price":3502.57,"qty":0.00220000}],"checksum":4175484491,"timestamp":"2024-06-01T17:52:52.559472Z"}]}
{"channel":"book","type":"update","data":[{"symbol":"ETH/EUR","bids":[],"asks":[{"price":3501.92,"qty":2.00000000}],"checksum":668601934,"timestamp":"2024-06-01T17:52:52.559624Z"}]}
{"channel":"book","type":"update","data":[{"symbol":"ETH/EUR","bids":[{"price":3500.78,"qty":0.00000000},{"price":3500.68,"qty":1.35365736}],"asks":[],"checksum":1669238446,"timestamp":"2024-06-01T17:52:52.564754Z"}]}
{"channel":"book","type":"update","data":[{"symbol":"ETH/EUR","bids":[],"asks":[{"price":3502.05,"qty":0.00000000},{"price":3502.57,"qty":0.00220000}],"checksum":1086405952,"timestamp":"2024-06-01T17:52:52.618554Z"}]}
{"channel":"book","type":"update","data":[{"symbol":"ETH/EUR","bids":[],"asks":[{"price":3501.92,"qty":28.32827119}],"checksum":1468595301,"timestamp":"2024-06-01T17:52:52.624538Z"}]}
{"channel":"book","type":"update","data":[{"symbol":"ETH/EUR","bids":[{"price":3501.25,"qty":4.00000000}],"asks":[],"checksum":3809161552,"timestamp":"2024-06-01T17:52:52.893351Z"}]}
{"channel":"book","type":"update","data":[{"symbol":"ETH/EUR","bids":[],"asks":[{"price":3501.92,"qty":2.00000000}],"checksum":4098027637,"timestamp":"2024-06-01T17:52:52.950252Z"}]}
{"channel":"book","type":"update","data":[{"symbol":"ETH/EUR","bids":[],"asks":[{"price":3501.91,"qty":26.32833699}],"checksum":1614220641,"timestamp":"2024-06-01T17:52:52.953752Z"}]}
{"channel":"book","type":"update","data":[{"symbol":"ETH/EUR","bids":[{"price":3500.95,"qty":0.00000000},{"price":3500.68,"qty":1.35365736}],"asks":[],"checksum":2408536506,"timestamp":"2024-06-01T17:52:52.955371Z"}]}
{"channel":"book","type":"update","data":[{"symbol":"ETH/EUR","bids":[],"asks":[{"price":3501.92,"qty":0.00000000},{"price":3502.57,"qty":0.00220000}],"checksum":1285090643,"timestamp":"2024-06-01T17:52:52.996115Z"}]}
{"channel":"book","type":"update","data":[{"symbol":"ETH/EUR","bids":[],"asks":[{"price":3501.90,"qty":2.00000000}],"checksum":3373072018,"timestamp":"2024-06-01T17:52:52.996344Z"}]}
{"channel":"book","type":"update","data":[{"symbol":"ETH/EUR","bids":[{"price":3500.75,"qty":0.00000000},{"price":3500.56,"qty":1.31740156}],"asks":[],"checksum":898527271,"timestamp":"2024-06-01T17:52:53.073086Z"}]}
{"channel":"book","type":"update","data":[{"symbol":"ETH/EUR","bids":[{"price":3501.23,"qty":0.00000000},{"price":3500.54,"qty":0.72912968}],"asks":[],"checksum":3275303326,"timestamp":"2024-06-01T17:52:53.197345Z"}]}
{"channel":"book","type":"update","data":[{"symbol":"ETH/EUR","bids":[],"asks":[{"price":3502.17,"qty":0.00756753}],"checksum":1969244860,"timestamp":"2024-06-01T17:52:53.346104Z"}]}
{"channel":"book","type":"update","data":[{"symbol":"ETH/EUR","bids":[{"price":3501.24,"qty":0.00000000},{"price":3500.41,"qty":1.84400885},{"price":3501.26,"qty":0.02856220}],"asks":[],"checksum":3882899943,"timestamp":"2024-06-01T17:52:53.346163Z"}]}
{"channel":"book","type":"update","data":[{"symbol":"ETH/EUR","bids":[{"price":3501.00,"qty":0.00000000},{"price":3500.41,"qty":1.84400885}],"asks":[],"checksum":2681321722,"timestamp":"2024-06-01T17:52:53.447665Z"}]}
{"channel":"book","type":"update","data":[{"symbol":"ETH/EUR","bids":[{"price":3501.32,"qty":1.60000000}],"asks":[],"checksum":3410073067,"timestamp":"2024-06-01T17:52:53.447740Z"}]}
{"channel":"book","type":"update","data":[{"symbol":"ETH/EUR","bids":[{"price":3500.82,"qty":1.19126651}],"asks":[],"checksum":3730043497,"timestamp":"2024-06-01T17:52:53.489773Z"}]}
{"channel":"book","type":"update","data":[{"symbol":"ETH/EUR","bids":[{"price":3500.82,"qty":0.84644082}],"asks":[],"checksum":3242294303,"timestamp":"2024-06-01T17:52:53.493604Z"}]}
{"channel":"book","type":"update","data":[{"symbol":"ETH/EUR","bids":[],"asks":[{"price":3501.91,"qty":0.00000000},{"price":3502.51,"qty":3.01305282}],"checksum":2907518636,"timestamp":"2024-06-01T17:52:53.529615Z"}]}
{"channel":"book","type":"update","data":[{"symbol":"ETH/EUR","bids":[],"asks":[{"price":3501.95,"qty":26.32803113}],"checksum":242043079,"timestamp":"2024-06-01T17:52:53.533396Z"}]}
{"channel":"book","type":"update","data":[{"symbol":"ETH/EUR","bids":[{"price":3501.12,"qty":26.33417586}],"asks":[],"checksum":934918448,"timestamp":"2024-06-01T17:52:53.533448Z"}]}
{"channel":"book","type":"update","data":[{"symbol":"ETH/EUR","bids":[{"price":3501.66,"qty":26.33010093}],"asks":[],"checksum":2210699776,"timestamp":"2024-06-01T17:52:53.533461Z"}]}
{"channel":"book","type":"update","data":[{"symbol":"ETH/EUR","bids":[],"asks":[{"price":3501.90,"qty":0.00000000},{"price":3502.51,"qty":3.01305282}],"checksum":1815871772,"timestamp":"2024-06-01T17:52:53.552601Z"}]}
{"channel":"book","type":"update","data":[{"symbol":"ETH/EUR","bids":[],"asks":[{"price":3502.41,"qty":0.00000000},{"price":3502.57,"qty":0.00220000}],"checksum":1231669855,"timestamp":"2024-06-01T17:52:53.581829Z"}]}
{"channel":"book","type":"update","data":[{"symbol":"ETH/EUR","bids":[],"asks":[{"price":3501.93,"qty":0.00000000},{"price":3502.60,"qty":0.65105882}],"checksum":3741352219,"timestamp":"2024-06-01T17:52:53.588366Z"}]}
{"channel":"book","type":"update","data":[{"symbol":"ETH/EUR","bids":[],"asks":[{"price":3501.95,"qty":0.00000000},{"price":3502.61,"qty":0.77800000}],"checksum":3450111025,"timestamp":"2024-06-01T17:52:53.588518Z"}]}
{"channel":"book","type":"update","data":[{"symbol":"ETH/EUR","bids":[],"asks":[{"price":3502.18,"qty":0.00000000},{"price":3502.83,"qty":0.00220000}],"checksum":2124163797,"timestamp":"2024-06-01T17:52:53.595116Z"}]}
{"channel":"book","type":"update","data":[{"symbol":"ETH/EUR","bids":[{"price":3501.12,"qty":0.00000000},{"price":3500.56,"qty":1.31740156}],"asks":[],"checksum":2536038966,"timestamp":"2024-06-01T17:52:53.595252Z"}]}
{"channel":"book","type":"update","data":[{"symbol":"ETH/EUR","bids":[{"price":3500.90,"qty":0.72912968}],"asks":[],"checksum":3716007533,"timestamp":"2024-06-01T17:52:53.599077Z"}]}
{"channel":"book","type":"update","data":[{"symbol":"ETH/EUR","bids":[],"asks":[{"price":3502.60,"qty":0.00000000},{"price":3503.02,"qty":0.84644082}],"checksum":3073128355,"timestamp":"2024-06-01T17:52:53.599447Z"}]}
{"channel":"book","type":"update","data":[{"symbol":"ETH/EUR","bids":[],"asks":[{"price":3502.34,"qty":1.60000000}],"checksum":2354740069,"timestamp":"2024-06-01T17:52:53.602383Z"}]}
{"channel":"book","type":"update","data":[{"symbol":"ETH/EUR","bids":[],"asks":[{"price":3502.21,"qty":26.32611492}],"checksum":4265345998,"timestamp":"2024-06-01T17:52:53.606271Z"}]}
{"channel":"book","type":"update","data":[{"symbol":"ETH/EUR","bids":[{"price":3501.67,"qty":26.33010077}],"asks":[],"checksum":1526212184,"timestamp":"2024-06-01T17:52:53.606384Z"}]}
{"channel":"book","type":"update","data":[{"symbol":"ETH/EUR","bids":[],"asks":[{"price":3502.28,"qty":26.32555473}],"checksum":2325522687,"timestamp":"2024-06-01T17:52:53.606455Z"}]}
{"channel":"book","type":"update","data":[{"symbol":"ETH/EUR","bids":[{"price":3501.67,"qty":52.66020154}],"asks":[],"checksum":161108825,"timestamp":"2024-06-01T17:52:53.606606Z"}]}
{"channel":"book","type":"update","data":[{"symbol":"ETH/EUR","bids":[{"price":3501.32,"qty":0.00000000},{"price":3500.68,"qty":1.35365736}],"asks":[],"checksum":4021697988,"timestamp":"2024-06-01T17:52:53.611005Z"}]}
{"channel":"book","type":"update","data":[{"symbol":"ETH/EUR","bids":[{"price":3501.67,"qty":54.26020154}],"asks":[],"checksum":3296757284,"timestamp":"2024-06-01T17:52:53.611170Z"}]}
{"channel":"book","type":"update","data":[{"symbol":"ETH/EUR","bids":[{"price":3501.67,"qty":27.93010077}],"asks":[],"checksum":470274180,"timestamp":"2024-06-01T17:52:53.615215Z"}]}
{"channel":"book","type":"update","data":[{"symbol":"ETH/EUR","bids":[],"asks":[{"price":3502.28,"qty":0.00000000},{"price":3502.61,"qty":0.77800000}],"checksum":3429064227,"timestamp":"2024-06-01T17:52:53.615277Z"}]}
{"channel":"book","type":"update","data":[{"symbol":"ETH/EUR","bids":[{"price":3501.67,"qty":1.60000000}],"asks":[],"checksum":187397956,"timestamp":"2024-06-01T17:52:53.615331Z"}]}
{"channel":"book","type":"update","data":[{"symbol":"ETH/EUR","bids":[],"asks":[{"price":3502.17,"qty":26.33394730}],"checksum":1381057724,"timestamp":"2024-06-01T17:52:53.679342Z"}]}
{"channel":"book","type":"update","data":[{"symbol":"ETH/EUR","bids":[{"price":3501.85,"qty":26.32869737}],"asks":[],"checksum":3920537306,"timestamp":"2024-06-01T17:52:53.679495Z"}]}
{"channel":"book","type":"update","data":[{"symbol":"ETH/EUR","bids":[{"price":3501.45,"qty":26.33170128}],"asks":[],"checksum":2034610439,"timestamp":"2024-06-01T17:52:53.679510Z"}]}
{"channel":"book","type":"update","data":[{"symbol":"ETH/EUR","bids":[],"asks":[{"price":3502.34,"qty":0.00000000},{"price":3502.70,"qty":26.32240873}],"checksum":3524457797,"timestamp":"2024-06-01T17:52:53.682277Z"}]}
{"channel":"book","type":"update","data":[{"symbol":"ETH/EUR","bids":[],"asks":[{"price":3502.17,"qty":0.00756753}],"checksum":763243110,"timestamp":"2024-06-01T17:52:53.686393Z"}]}
{"channel":"book","type":"update","data":[{"symbol":"ETH/EUR","bids":[{"price":3501.85,"qty":0.00000000},{"price":3500.69,"qty":6.92318992}],"asks":[],"checksum":88743465,"timestamp":"2024-06-01T17:52:53.686527Z"}]}
{"channel":"book","type":"update","data":[{"symbol":"ETH/EUR","bids":[],"asks":[{"price":3502.19,"qty":26.32624070}],"checksum":1480700021,"timestamp":"2024-06-01T17:52:53.763050Z"}]}
{"channel":"book","type":"update","data":[{"symbol":"ETH/EUR","bids":[{"price":3501.68,"qty":26.33002557}],"asks":[],"checksum":3087454463,"timestamp":"2024-06-01T17:52:53.763186Z"}]}
{"channel":"book","type":"update","data":[{"symbol":"ETH/EUR","bids":[{"price":3501.68,"qty":0.00000000},{"price":3500.69,"qty":6.92318992}],"asks":[],"checksum":1480700021,"timestamp":"2024-06-01T17:52:53.767770Z"}]}
{"channel":"book","type":"update","data":[{"symbol":"ETH/EUR","bids":[],"asks":[{"price":3502.18,"qty":2.00000000}],"checksum":1986715101,"timestamp":"2024-06-01T17:52:53.803787Z"}]}
{"channel":"book","type":"update","data":[{"symbol":"ETH/EUR","bids":[],"asks":[{"price":3502.19,"qty":0.00000000},{"price":3502.61,"qty":0.77800000}],"checksum":3704609674,"timestamp":"2024-06-01T17:52:53.806732Z"}]}
{"channel":"book","type":"update","data":[{"symbol":"ETH/EUR","bids":[{"price":3501.77,"qty":26.32931228}],"asks":[],"checksum":679418945,"timestamp":"2024-06-01T17:52:53.811367Z"}]}
{"channel":"book","type":"update","data":[{"symbol":"ETH/EUR","bids":[],"asks":[{"price":3502.18,"qty":0.00000000},{"price":3502.70,"qty":26.32240873}],"checksum":1736010710,"timestamp":"2024-06-01T17:52:53.813912Z"}]}
{"channel":"book","type":"update","data":[{"symbol":"ETH/EUR","bids":[{"price":3501.67,"qty":0.00000000},{"price":3500.69,"qty":6.92318992}],"asks":[],"checksum":2084128243,"timestamp":"2024-06-01T17:52:53.813951Z"}]}
{"channel":"book","type":"update","data":[{"symbol":"ETH/EUR","bids":[{"price":3501.78,"qty":1.60000000}],"asks":[],"checksum":2254043892,"timestamp":"2024-06-01T17:52:53.814101Z"}]}
{"channel":"book","type":"update","data":[{"symbol":"ETH/EUR","bids":[{"price":3501.68,"qty":26.33002557}],"asks":[],"checksum":2019477413,"timestamp":"2024-06-01T17:52:53.815689Z"}]}
{"channel":"book","type":"update","data":[{"symbol":"ETH/EUR","bids":[],"asks":[{"price":3502.17,"qty":26.33393315}],"checksum":1494544629,"timestamp":"2024-06-01T17:52:53.815757Z"}]}
{"channel":"book","type":"update","data":[{"symbol":"ETH/EUR","bids":[{"price":3501.68,"qty":0.00000000},{"price":3500.82,"qty":0.84644082}],"asks":[],"checksum":2443688044,"timestamp":"2024-06-01T17:52:53.819223Z"}]}
{"channel":"book","type":"update","data":[{"symbol":"ETH/EUR","bids":[{"price":3501.07,"qty":0.00000000},{"price":3500.69,"qty":6.92318992},{"price":3501.47,"qty":0.08558500}],"asks":[],"checksum":2915755,"timestamp":"2024-06-01T17:52:53.853766Z"}]}
{"channel":"book","type":"update","data":[{"symbol":"ETH/EUR","bids":[{"price":3501.77,"qty":0.00000000},{"price":3500.69,"qty":6.92318992}],"asks":[],"checksum":4119014254,"timestamp":"2024-06-01T17:52:53.888884Z"}]}
{"channel":"book","type":"update","data":[{"symbol":"ETH/EUR","bids":[{"price":3501.84,"qty":26.32874794}],"asks":[],"checksum":3105007894,"timestamp":"2024-06-01T17:52:53.889166Z"}]}
{"channel":"book","type":"update","data":[{"symbol":"ETH/EUR","bids":[],"asks":[{"price":3502.17,"qty":0.00756753}],"checksum":2934762382,"timestamp":"2024-06-01T17:52:53.900483Z"}]}
{"channel":"book","type":"update","data":[{"symbol":"ETH/EUR","bids":[],"asks":[{"price":3502.16,"qty":26.32646917}],"checksum":2945105022,"timestamp":"2024-06-01T17:52:53.903920Z"}]}
{"channel":"book","type":"update","data":[{"symbol":"ETH/EUR","bids":[{"price":3501.87,"qty":26.32855385}],"asks":[],"checksum":4087189618,"timestamp":"2024-06-01T17:52:54.048481Z"}]}
{"channel":"book","type":"update","data":[{"symbol":"ETH/EUR","bids":[{"price":3501.87,"qty":0.00000000},{"price":3500.82,"qty":0.84644082}],"asks":[],"checksum":2945105022,"timestamp":"2024-06-01T17:52:54.087991Z"}]}
{"channel":"book","type":"update","data":[{"symbol":"ETH/EUR","bids":[],"asks":[{"price":3502.16,"qty":0.00000000},{"price":3502.70,"qty":26.32240873}],"checksum":2934762382,"timestamp":"2024-06-01T17:52:54.088166Z"}]}
{"channel":"book","type":"update","data":[{"symbol":"ETH/EUR","bids":[],"asks":[{"price":3502.16,"qty":26.32642820}],"checksum":977131383,"timestamp":"2024-06-01T17:52:54.092944Z"}]}
{"channel":"book","type":"update","data":[{"symbol":"ETH/EUR","bids":[],"asks":[{"price":3502.16,"qty":0.00000000},{"price":3502.70,"qty":26.32240873}],"checksum":2934762382,"timestamp":"2024-06-01T17:52:54.100834Z"}]}
{"channel":"book","type":"update","data":[{"symbol":"ETH/EUR","bids":[],"asks":[{"price":3502.18,"qty":26.32626767}],"checksum":2398454948,"timestamp":"2024-06-01T17:52:54.148678Z"}]}
{"channel":"book","type":"update","data":[{"symbol":"ETH/EUR","bids":[],"asks":[{"price":3502.18,"qty":0.00000000},{"price":3502.70,"qty":26.32240873}],"checksum":2934762382,"timestamp":"2024-06-01T17:52:54.154919Z"}]}
{"channel":"book","type":"update","data":[{"symbol":"ETH/EUR","bids":[],"asks":[{"price":3502.19,"qty":26.32622030}],"checksum":3804995703,"timestamp":"2024-06-01T17:52:54.242141Z"}]}
{"channel":"book","type":"update","data":[{"symbol":"ETH/EUR","bids":[],"asks":[{"price":3502.19,"qty":0.00000000},{"price":3502.70,"qty":26.32240873}],"checksum":2934762382,"timestamp":"2024-06-01T17:52:54.256166Z"}]}
{"channel":"book","type":"update","data":[{"symbol":"ETH/EUR","bids":[],"asks":[{"price":3502.14,"qty":26.32661241}],"checksum":4039377527,"timestamp":"2024-06-01T17:52:54.302878Z"}]}
{"channel":"book","type":"update","data":[{"symbol":"ETH/EUR","bids":[],"asks":[{"price":3502.14,"qty":0.00000000},{"price":3502.70,"qty":26.32240873}],"checksum":2934762382,"timestamp":"2024-06-01T17:52:54.306745Z"}]}
{"channel":"book","type":"update","data":[{"symbol":"ETH/EUR","bids":[],"asks":[{"price":3502.17,"qty":0.00000000},{"price":3502.83,"qty":0.00220000},{"price":3502.42,"qty":0.00756627}],"checksum":3899878138,"timestamp":"2024-06-01T17:52:54.357526Z"}]}
{"channel":"book","type":"update","data":[{"symbol":"ETH/EUR","bids":[],"asks":[{"price":3502.14,"qty":26.32659466}],"checksum":2888234009,"timestamp":"2024-06-01T17:52:54.442047Z"}]}
{"channel":"book","type":"update","data":[{"symbol":"ETH/EUR","bids":[],"asks":[{"price":3502.14,"qty":0.00000000},{"price":3502.70,"qty":26.32240873}],"checksum":3899878138,"timestamp":"2024-06-01T17:52:54.454412Z"}]}
{"channel":"book","type":"update","data":[{"symbol":"ETH/EUR","bids":[{"price":3501.26,"qty":0.00000000},{"price":3500.69,"qty":6.92318992},{"price":3501.85,"qty":0.02855789}],"asks":[],"checksum":3893381596,"timestamp":"2024-06-01T17:52:54.458553Z"}]}
{"channel":"book","type":"update","data":[{"symbol":"ETH/EUR","bids":[{"price":3501.66,"qty":0.00000000},{"price":3500.69,"qty":6.92318992}],"asks":[],"checksum":3181533539,"timestamp":"2024-06-01T17:52:54.458841Z"}]}
{"channel":"book","type":"update","data":[{"symbol":"ETH/EUR","bids":[{"price":3501.78,"qty":0.00000000},{"price":3500.68,"qty":1.35365736}],"asks":[],"checksum":3566347378,"timestamp":"2024-06-01T17:52:54.461553Z"}]}
{"channel":"book","type":"update","data":[{"symbol":"ETH/EUR","bids":[],"asks":[{"price":3502.16,"qty":26.32648939}],"checksum":1249885919,"timestamp":"2024-06-01T17:52:54.583829Z"}]}
{"channel":"book","type":"update","data":[{"symbol":"ETH/EUR","bids":[],"asks":[{"price":3502.16,"qty":0.00000000},{"price":3502.70,"qty":26.32240873}],"checksum":3566347378,"timestamp":"2024-06-01T17:52:54.696660Z"}]}
{"channel":"book","type":"update","data":[{"symbol":"ETH/EUR","bids":[],"asks":[{"price":3502.15,"qty":26.32653998}],"checksum":877736230,"timestamp":"2024-06-01T17:52:54.700289Z"}]}
{"channel":"book","type":"update","data":[{"symbol":"ETH/EUR","bids":[],"asks":[{"price":3502.15,"qty":0.00000000},{"price":3502.70,"qty":26.32240873}],"checksum":3566347378,"timestamp":"2024-06-01T17:52:55.287813Z"}]}
{"channel":"book","type":"update","data":[{"symbol":"ETH/EUR","bids":[{"price":3501.90,"qty":26.32837098}],"asks":[],"checksum":1489473571,"timestamp":"2024-06-01T17:52:55.292039Z"}]}
{"channel":"book","type":"update","data":[{"symbol":"ETH/EUR","bids":[],"asks":[{"price":3502.19,"qty":26.32625613}],"checksum":3212722827,"timestamp":"2024-06-01T17:52:55.292071Z"}]}
{"channel":"book","type":"update","data":[{"symbol":"ETH/EUR","bids":[{"price":3501.57,"qty":26.33080798}],"asks":[],"checksum":2539866362,"timestamp":"2024-06-01T17:52:55.292175Z"}]}
{"channel":"book","type":"update","data":[{"symbol":"ETH/EUR","bids":[{"price":3501.90,"qty":0.00000000},{"price":3500.69,"qty":6.92318992}],"asks":[],"checksum":1462129311,"timestamp":"2024-06-01T17:52:55.302176Z"}]}
{"channel":"book","type":"update","data":[{"symbol":"ETH/EUR","bids":[],"asks":[{"price":3502.19,"qty":0.00000000},{"price":3502.70,"qty":26.32240873}],"checksum":2963243063,"timestamp":"2024-06-01T17:52:55.376932Z"}]}
{"channel":"book","type":"update","data":[{"symbol":"ETH/EUR","bids":[],"asks":[{"price":3502.18,"qty":26.32629956}],"checksum":4151977776,"timestamp":"2024-06-01T17:52:55.380935Z"}]}
{"channel":"book","type":"update","data":[{"symbol":"ETH/EUR","bids":[{"price":3501.86,"qty":26.32867218}],"asks":[],"checksum":3629881714,"timestamp":"2024-06-01T17:52:55.381148Z"}]}
{"channel":"book","type":"update","data":[{"symbol":"ETH/EUR","bids":[{"price":3501.86,"qty":0.00000000},{"price":3500.69,"qty":6.92318992}],"asks":[],"checksum":4151977776,"timestamp":"2024-06-01T17:52:55.386288Z"}]}
{"channel":"book","type":"update","data":[{"symbol":"ETH/EUR","bids":[{"price":3501.91,"qty":2.46000000}],"asks":[],"checksum":2384647850,"timestamp":"2024-06-01T17:52:55.396877Z"}]}
{"channel":"book","type":"update","data":[{"symbol":"ETH/EUR","bids":[],"asks":[{"price":3502.18,"qty":0.00000000},{"price":3502.70,"qty":26.32240873}],"checksum":3385291181,"timestamp":"2024-06-01T17:52:55.500645Z"}]}
{"channel":"book","type":"update","data":[{"symbol":"ETH/EUR","bids":[],"asks":[{"price":3502.16,"qty":26.32643377}],"checksum":2880434265,"timestamp":"2024-06-01T17:52:55.504595Z"}]}
{"channel":"book","type":"update","data":[{"symbol":"ETH/EUR","bids":[{"price":3501.88,"qty":26.32850849}],"asks":[],"checksum":1097200708,"timestamp":"2024-06-01T17:52:55.504660Z"}]}
{"channel":"book","type":"update","data":[{"symbol":"ETH/EUR","bids":[{"price":3501.88,"qty":0.00000000},{"price":3500.82,"qty":0.84644082}],"asks":[],"checksum":2880434265,"timestamp":"2024-06-01T17:52:55.561211Z"}]}
{"channel":"book","type":"update","data":[{"symbol":"ETH/EUR","bids":[{"price":3501.84,"qty":0.00000000},{"price":3500.69,"qty":6.92318992}],"asks":[],"checksum":66154292,"timestamp":"2024-06-01T17:52:55.561284Z"}]}
{"channel":"book","type":"update","data":[{"symbol":"ETH/EUR","bids":[],"asks":[{"price":3502.16,"qty":0.00000000},{"price":3502.83,"qty":0.00220000}],"checksum":4094409019,"timestamp":"2024-06-01T17:52:55.561320Z"}]}
{"channel":"book","type":"update","data":[{"symbol":"ETH/EUR","bids":[{"price":3501.57,"qty":0.00000000},{"price":3500.68,"qty":1.35365736}],"asks":[],"checksum":1149655838,"timestamp":"2024-06-01T17:52:55.561384Z"}]}
{"channel":"book","type":"update","data":[{"symbol":"ETH/EUR","bids":[{"price":3501.63,"qty":1.60000000}],"asks":[],"checksum":2639865082,"timestamp":"2024-06-01T17:52:55.564420Z"}]}
{"channel":"book","type":"update","data":[{"symbol":"ETH/EUR","bids":[{"price":3501.85,"qty":0.00000000},{"price":3500.68,"qty":1.35365736},{"price":3501.92,"qty":0.02855438}],"asks":[],"checksum":395105402,"timestamp":"2024-06-01T17:52:55.564749Z"}]}
{"channel":"book","type":"update","data":[{"symbol":"ETH/EUR","bids":[],"asks":[{"price":3502.01,"qty":26.32761439}],"checksum":195498876,"timestamp":"2024-06-01T17:52:55.566325Z"}]}
{"channel":"book","type":"update","data":[{"symbol":"ETH/EUR","bids":[],"asks":[{"price":3502.01,"qty":0.00000000},{"price":3502.83,"qty":0.00220000}],"checksum":395105402,"timestamp":"2024-06-01T17:52:55.570730Z"}]}
{"channel":"book","type":"update","data":[{"symbol":"ETH/EUR","bids":[],"asks":[{"price":3502.07,"qty":26.32709339}],"checksum":329182465,"timestamp":"2024-06-01T17:52:55.591246Z"}]}
{"channel":"book","type":"update","data":[{"symbol":"ETH/EUR","bids":[{"price":3501.63,"qty":0.00000000},{"price":3500.56,"qty":1.31740156}],"asks":[],"checksum":1031658036,"timestamp":"2024-06-01T17:52:55.632256Z"}]}
{"channel":"book","type":"update","data":[{"symbol":"ETH/EUR","bids":[],"asks":[{"price":3502.07,"qty":0.00000000},{"price":3502.83,"qty":0.00220000}],"checksum":963633999,"timestamp":"2024-06-01T17:52:55.634071Z"}]}
{"channel":"book","type":"update","data":[{"symbol":"ETH/EUR","bids":[],"asks":[{"price":3502.42,"qty":0.00000000},{"price":3502.96,"qty":0.65105882},{"price":3502.82,"qty":0.00755884}],"checksum":82303490,"timestamp":"2024-06-01T17:52:55.635561Z"}]}
{"channel":"book","type":"update","data":[{"symbol":"ETH/EUR","bids":[],"asks":[{"price":3501.98,"qty":26.32778839}],"checksum":1322061084,"timestamp":"2024-06-01T17:52:55.638158Z"}]}
{"channel":"book","type":"update","data":[{"symbol":"ETH/EUR","bids":[],"asks":[{"price":3502.00,"qty":26.32764247}],"checksum":3776209394,"timestamp":"2024-06-01T17:52:55.703780Z"}]}
{"channel":"book","type":"update","data":[{"symbol":"ETH/EUR","bids":[{"price":3501.12,"qty":1.35348724}],"asks":[],"checksum":4164658423,"timestamp":"2024-06-01T17:52:55.705258Z"}]}
{"channel":"book","type":"update","data":[{"symbol":"ETH/EUR","bids":[],"asks":[{"price":3502.20,"qty":0.65371472}],"checksum":111418796,"timestamp":"2024-06-01T17:52:55.832524Z"}]}
{"channel":"book","type":"update","data":[{"symbol":"ETH/EUR","bids":[],"asks":[{"price":3501.98,"qty":0.00000000},{"price":3502.61,"qty":0.77800000}],"checksum":2742796335,"timestamp":"2024-06-01T17:52:56.131645Z"}]}
{"channel":"book","type":"update","data":[{"symbol":"ETH/EUR","bids":[{"price":3501.05,"qty":6.00000000}],"asks":[],"checksum":2680338356,"timestamp":"2024-06-01T17:52:56.134718Z"}]}
{"channel":"book","type":"update","data":[{"symbol":"ETH/EUR","bids":[],"asks":[{"price":3501.97,"qty":26.32787167}],"checksum":3429282535,"timestamp":"2024-06-01T17:52:56.136560Z"}]}
{"channel":"book","type":"update","data":[{"symbol":"ETH/EUR","bids":[{"price":3501.92,"qty":0.00000000},{"price":3500.69,"qty":6.92318992},{"price":3501.91,"qty":2.45735445}],"asks":[],"checksum":3807283426,"timestamp":"2024-06-01T17:52:56.143970Z"}]}
{"channel":"book","type":"update","data":[{"symbol":"ETH/EUR","bids":[{"price":3501.91,"qty":0.00000000},{"price":3500.56,"qty":1.31740156}],"asks":[],"checksum":1272285530,"timestamp":"2024-06-01T17:52:56.227515Z"}]}
{"channel":"book","type":"update","data":[{"symbol":"ETH/EUR","bids":[{"price":3501.48,"qty":0.02856269}],"asks":[],"checksum":100263067,"timestamp":"2024-06-01T17:52:56.622849Z"}]}
{"channel":"book","type":"update","data":[{"symbol":"ETH/EUR","bids":[],"asks":[{"price":3502.42,"qty":0.00802971}],"checksum":2819630920,"timestamp":"2024-06-01T17:52:56.623095Z"}]}
{"channel":"book","type":"update","data":[{"symbol":"ETH/EUR","bids":[{"price":3501.49,"qty":26.33145431}],"asks":[],"checksum":2104762700,"timestamp":"2024-06-01T17:52:56.628628Z"}]}
{"channel":"book","type":"update","data":[{"symbol":"ETH/EUR","bids":[{"price":3501.49,"qty":0.00000000},{"price":3500.69,"qty":6.92318992}],"asks":[],"checksum":2819630920,"timestamp":"2024-06-01T17:52:56.633070Z"}]}
{"channel":"book","type":"update","data":[{"symbol":"ETH/EUR","bids":[{"price":3501.20,"qty":26.33356689}],"asks":[],"checksum":1021969410,"timestamp":"2024-06-01T17:52:56.638106Z"}]}
{"channel":"book","type":"update","data":[{"symbol":"ETH/EUR","bids":[{"price":3501.68,"qty":26.33001646}],"asks":[],"checksum":2928034932,"timestamp":"2024-06-01T17:52:56.690929Z"}]}
{"channel":"book","type":"update","data":[{"symbol":"ETH/EUR","bids":[{"price":3501.49,"qty":26.33145431}],"asks":[],"checksum":1422633193,"timestamp":"2024-06-01T17:52:56.693769Z"}]}
{"channel":"book","type":"update","data":[{"symbol":"ETH/EUR","bids":[{"price":3501.68,"qty":0.00000000},{"price":3500.90,"qty":0.72912968}],"asks":[],"checksum":3610102028,"timestamp":"2024-06-01T17:52:56.696683Z"}]}
{"channel":"book","type":"update","data":[{"symbol":"ETH/EUR","bids":[],"asks":[{"price":3501.97,"qty":0.00000000},{"price":3502.57,"qty":0.00220000}],"checksum":1768243840,"timestamp":"2024-06-01T17:52:56.696710Z"}]}
{"channel":"book","type":"update","data":[{"symbol":"ETH/EUR","bids":[{"price":3501.49,"qty":0.00000000},{"price":3500.82,"qty":0.84644082}],"asks":[],"checksum":3466533994,"timestamp":"2024-06-01T17:52:56.696737Z"}]}
{"channel":"book","type":"update","data":[{"symbol":"ETH/EUR","bids":[],"asks":[{"price":3501.95,"qty":26.32805395}],"checksum":3769880504,"timestamp":"2024-06-01T17:52:56.702109Z"}]}
{"channel":"book","type":"update","data":[{"symbol":"ETH/EUR","bids":[{"price":3501.66,"qty":26.33013227}],"asks":[],"checksum":14972553,"timestamp":"2024-06-01T17:52:56.780476Z"}]}
{"channel":"book","type":"update","data":[{"symbol":"ETH/EUR","bids":[{"price":3501.49,"qty":2.88000000}],"asks":[],"checksum":1737276298,"timestamp":"2024-06-01T17:52:56.796098Z"}]}
{"channel":"book","type":"update","data":[{"symbol":"ETH/EUR","bids":[{"price":3501.50,"qty":0.34482569}],"asks":[],"checksum":3185166993,"timestamp":"2024-06-01T17:52:56.848855Z"}]}
{"channel":"book","type":"update","data":[{"symbol":"ETH/EUR","bids":[{"price":3501.50,"qty":0.67261270}],"asks":[],"checksum":3776467608,"timestamp":"2024-06-01T17:52:56.854099Z"}]}
{"channel":"book","type":"update","data":[{"symbol":"ETH/EUR","bids":[{"price":3501.66,"qty":0.00000000},{"price":3501.01,"qty":2.00000000}],"asks":[],"checksum":2702523200,"timestamp":"2024-06-01T17:52:57.154816Z"}]}
{"channel":"book","type":"update","data":[{"symbol":"ETH/EUR","bids":[],"asks":[{"price":3501.95,"qty":0.00000000},{"price":3502.57,"qty":0.00220000}],"checksum":3387335787,"timestamp":"2024-06-01T17:52:57.154901Z"}]}
{"channel":"book","type":"update","data":[{"symbol":"ETH/EUR","bids":[],"asks":[{"price":3502.43,"qty":0.00000000},{"price":3502.61,"qty":0.77800000}],"checksum":3888907058,"timestamp":"2024-06-01T17:52:57.154912Z"}]}
{"channel":"book","type":"update","data":[{"symbol":"ETH/EUR","bids":[{"price":3501.45,"qty":0.00000000},{"price":3500.82,"qty":0.84644082}],"asks":[],"checksum":638486284,"timestamp":"2024-06-01T17:52:57.156052Z"}]}
{"channel":"book","type":"update","data":[{"symbol":"ETH/EUR","bids":[],"asks":[{"price":3502.44,"qty":0.72912968}],"checksum":3341157567,"timestamp":"2024-06-01T17:52:57.159710Z"}]}
{"channel":"book","type":"update","data":[{"symbol":"ETH/EUR","bids":[],"asks":[{"price":3502.00,"qty":0.00000000},{"price":3502.61,"qty":0.77800000}],"checksum":3514815908,"timestamp":"2024-06-01T17:52:57.163820Z"}]}
{"channel":"book","type":"update","data":[{"symbol":"ETH/EUR","bids":[],"asks":[{"price":3501.67,"qty":26.33011837}],"checksum":2356255172,"timestamp":"2024-06-01T17:52:57.169252Z"}]}
{"channel":"book","type":"update","data":[{"symbol":"ETH/EUR","bids":[{"price":3501.36,"qty":26.33237035}],"asks":[],"checksum":2295020226,"timestamp":"2024-06-01T17:52:57.169293Z"}]}
{"channel":"book","type":"update","data":[{"symbol":"ETH/EUR","bids":[],"asks":[{"price":3501.99,"qty":26.32769481}],"checksum":889834853,"timestamp":"2024-06-01T17:52:57.169385Z"}]}
{"channel":"book","type":"update","data":[{"symbol":"ETH/EUR","bids":[{"price":3501.11,"qty":26.33430905}],"asks":[],"checksum":802416716,"timestamp":"2024-06-01T17:52:57.169525Z"}]}
{"channel":"book","type":"update","data":[{"symbol":"ETH/EUR","bids":[],"asks":[{"price":3501.75,"qty":26.32955486}],"checksum":3295436999,"timestamp":"2024-06-01T17:52:57.174988Z"}]}
{"channel":"book","type":"update","data":[{"symbol":"ETH/EUR","bids":[{"price":3501.12,"qty":0.00000000},{"price":3501.01,"qty":2.00000000}],"asks":[],"checksum":1458015127,"timestamp":"2024-06-01T17:52:57.176965Z"}]}
{"channel":"book","type":"update","data":[{"symbol":"ETH/EUR","bids":[],"asks":[{"price":3502.42,"qty":0.00000000},{"price":3502.51,"qty":3.01305282}],"checksum":4259732107,"timestamp":"2024-06-01T17:52:57.193994Z"}]}
{"channel":"book","type":"update","data":[{"symbol":"ETH/EUR","bids":[{"price":3501.20,"qty":0.00000000},{"price":3500.90,"qty":26.33587310}],"asks":[],"checksum":1677053964,"timestamp":"2024-06-01T17:52:57.204488Z"}]}
{"channel":"book","type":"update","data":[{"symbol":"ETH/EUR","bids":[],"asks":[{"price":3501.67,"qty":0.00000000},{"price":3502.57,"qty":0.00220000}],"checksum":2552710883,"timestamp":"2024-06-01T17:52:57.204526Z"}]}
{"channel":"book","type":"update","data":[{"symbol":"ETH/EUR","bids":[],"asks":[{"price":3501.69,"qty":26.32999204}],"checksum":1726167973,"timestamp":"2024-06-01T17:52:57.232280Z"}]}
{"channel":"book","type":"update","data":[{"symbol":"ETH/EUR","bids":[{"price":3501.38,"qty":26.33225065}],"asks":[],"checksum":4235397949,"timestamp":"2024-06-01T17:52:57.232395Z"}]}
{"channel":"book","type":"update","data":[{"symbol":"ETH/EUR","bids":[{"price":3501.49,"qty":0.00000000},{"price":3500.90,"qty":26.33587310}],"asks":[],"checksum":1235121028,"timestamp":"2024-06-01T17:52:57.287331Z"}]}
{"channel":"book","type":"update","data":[{"symbol":"ETH/EUR","bids":[{"price":3501.39,"qty":2.00000000}],"asks":[],"checksum":23730177,"timestamp":"2024-06-01T17:52:57.293281Z"}]}
{"channel":"book","type":"update","data":[{"symbol":"ETH/EUR","bids":[{"price":3501.05,"qty":7.35351430}],"asks":[],"checksum":1650978301,"timestamp":"2024-06-01T17:52:57.297178Z"}]}
{"channel":"book","type":"update","data":[{"symbol":"ETH/EUR","bids":[{"price":3501.50,"qty":0.34482569}],"asks":[],"checksum":3062183871,"timestamp":"2024-06-01T17:52:57.310815Z"}]}
{"channel":"book","type":"update","data":[{"symbol":"ETH/EUR","bids":[],"asks":[{"price":3502.40,"qty":0.00000000},{"price":3502.57,"qty":0.00220000},{"price":3502.04,"qty":0.08558200}],"checksum":2935758316,"timestamp":"2024-06-01T17:52:57.334666Z"}]}
{"channel":"book","type":"update","data":[{"symbol":"ETH/EUR","bids":[{"price":3501.01,"qty":0.00000000},{"price":3500.90,"qty":26.33587310}],"asks":[],"checksum":4130519196,"timestamp":"2024-06-01T17:52:57.339665Z"}]}
{"channel":"book","type":"update","data":[{"symbol":"ETH/EUR","bids":[{"price":3501.38,"qty":0.00000000},{"price":3500.83,"qty":0.63806404}],"asks":[],"checksum":2257980400,"timestamp":"2024-06-01T17:52:57.501639Z"}]}
{"channel":"book","type":"update","data":[{"symbol":"ETH/EUR","bids":[{"price":3501.39,"qty":28.33218038}],"asks":[],"checksum":1171033900,"timestamp":"2024-06-01T17:52:57.505255Z"}]}
{"channel":"book","type":"update","data":[{"symbol":"ETH/EUR","bids":[{"price":3501.39,"qty":2.00000000}],"asks":[],"checksum":2257980400,"timestamp":"2024-06-01T17:52:57.610953Z"}]}
{"channel":"book","type":"update","data":[{"symbol":"ETH/EUR","bids":[],"asks":[{"price":3501.69,"qty":0.00000000},{"price":3502.57,"qty":0.00220000}],"checksum":316696723,"timestamp":"2024-06-01T17:52:57.654912Z"}]}
{"channel":"book","type":"update","data":[{"symbol":"ETH/EUR","bids":[],"asks":[{"price":3501.75,"qty":0.00000000},{"price":3502.61,"qty":0.77800000}],"checksum":3613743710,"timestamp":"2024-06-01T17:52:57.659331Z"}]}
{"channel":"book","type":"update","data":[{"symbol":"ETH/EUR","bids":[],"asks":[{"price":3501.99,"qty":0.00000000},{"price":3502.82,"qty":0.00802971}],"checksum":1705618514,"timestamp":"2024-06-01T17:52:57.664167Z"}]}
{"channel":"book","type":"update","data":[{"symbol":"ETH/EUR","bids":[],"asks":[{"price":3501.66,"qty":26.33018680}],"checksum":189025552,"timestamp":"2024-06-01T17:52:57.664200Z"}]}
{"channel":"book","type":"update","data":[{"symbol":"ETH/EUR","bids":[],"asks":[{"price":3501.66,"qty":0.00000000},{"price":3502.82,"qty":0.00802971}],"checksum":1705618514,"timestamp":"2024-06-01T17:52:57.669644Z"}]}
{"channel":"book","type":"update","data":[{"symbol":"ETH/EUR","bids":[],"asks":[{"price":3501.98,"qty":26.32776999}],"checksum":1180887184,"timestamp":"2024-06-01T17:52:57.674692Z"}]}
{"channel":"book","type":"update","data":[{"symbol":"ETH/EUR","bids":[],"asks":[{"price":3501.98,"qty":0.00000000},{"price":3502.82,"qty":0.00802971}],"checksum":1705618514,"timestamp":"2024-06-01T17:52:57.679338Z"}]}
{"channel":"book","type":"update","data":[{"symbol":"ETH/EUR","bids":[],"asks":[{"price":3502.82,"qty":0.00000000},{"price":3502.83,"qty":0.00220000},{"price":3502.50,"qty":0.00802971}],"checksum":4195066926,"timestamp":"2024-06-01T17:52:57.681892Z"}]}
{"channel":"book","type":"update","data":[{"symbol":"ETH/EUR","bids":[{"price":3501.48,"qty":0.00000000},{"price":3500.82,"qty":0.84644082},{"price":3501.51,"qty":0.02854585}],"asks":[],"checksum":568923652,"timestamp":"2024-06-01T17:52:57.681973Z"}]}
{"channel":"book","type":"update","data":[{"symbol":"ETH/EUR","bids":[],"asks":[{"price":3501.97,"qty":26.32784517}],"checksum":3171231397,"timestamp":"2024-06-01T17:52:57.683189Z"}]}
{"channel":"book","type":"update","data":[{"symbol":"ETH/EUR","bids":[],"asks":[{"price":3501.97,"qty":0.00000000},{"price":3502.61,"qty":0.77800000}],"checksum":568923652,"timestamp":"2024-06-01T17:52:57.687589Z"}]}
{"channel":"book","type":"update","data":[{"symbol":"ETH/EUR","bids":[],"asks":[{"price":3502.03,"qty":26.32739410}],"checksum":2196914778,"timestamp":"2024-06-01T17:52:57.715445Z"}]}
{"channel":"book","type":"update","data":[{"symbol":"ETH/EUR","bids":[],"asks":[{"price":3502.03,"qty":0.00000000},{"price":3502.61,"qty":0.77800000}],"checksum":568923652,"timestamp":"2024-06-01T17:52:57.719825Z"}]}
{"channel":"book","type":"update","data":[{"symbol":"ETH/EUR","bids":[{"price":3501.05,"qty":6.00000000}],"asks":[],"checksum":3650648507,"timestamp":"2024-06-01T17:52:57.732776Z"}]}
{"channel":"book","type":"update","data":[{"symbol":"ETH/EUR","bids":[],"asks":[{"price":3502.50,"qty":0.00000000},{"price":3502.83,"qty":0.00220000},{"price":3502.60,"qty":0.00802971}],"checksum":3732082471,"timestamp":"2024-06-01T17:52:57.772637Z"}]}
{"channel":"book","type":"update","data":[{"symbol":"ETH/EUR","bids":[],"asks":[{"price":3502.14,"qty":1.60000000}],"checksum":3606849820,"timestamp":"2024-06-01T17:52:57.807913Z"}]}
{"channel":"book","type":"update","data":[{"symbol":"ETH/EUR","bids":[],"asks":[{"price":3502.03,"qty":26.32739410}],"checksum":2525343318,"timestamp":"2024-06-01T17:52:57.811135Z"}]}
{"channel":"book","type":"update","data":[{"symbol":"ETH/EUR","bids":[],"asks":[{"price":3502.03,"qty":0.00000000},{"price":3502.60,"qty":0.00802971}],"checksum":3606849820,"timestamp":"2024-06-01T17:52:57.815714Z"}]}
{"channel":"book","type":"update","data":[{"symbol":"ETH/EUR","bids":[{"price":3501.01,"qty":1.35352976}],"asks":[],"checksum":3048991727,"timestamp":"2024-06-01T17:52:57.858926Z"}]}
{"channel":"book","type":"update","data":[{"symbol":"ETH/EUR","bids":[],"asks":[{"price":3502.03,"qty":26.32739410}],"checksum":603077350,"timestamp":"2024-06-01T17:52:57.879717Z"}]}
{"channel":"book","type":"update","data":[{"symbol":"ETH/EUR","bids":[],"asks":[{"price":3502.03,"qty":0.00000000},{"price":3502.60,"qty":0.00802971}],"checksum":3048991727,"timestamp":"2024-06-01T17:52:57.884579Z"}]}
{"channel":"book","type":"update","data":[{"symbol":"ETH/EUR","bids":[],"asks":[{"price":3501.75,"qty":26.32950222}],"checksum":3344942615,"timestamp":"2024-06-01T17:52:57.891524Z"}]}
{"channel":"book","type":"update","data":[{"symbol":"ETH/EUR","bids":[],"asks":[{"price":3501.75,"qty":0.00000000},{"price":3502.60,"qty":0.00802971}],"checksum":3048991727,"timestamp":"2024-06-01T17:52:57.959630Z"}]}
{"channel":"book","type":"update","data":[{"symbol":"ETH/EUR","bids":[{"price":3501.36,"qty":0.00000000},{"price":3500.83,"qty":0.63806404}],"asks":[],"checksum":350329415,"timestamp":"2024-06-01T17:52:57.959798Z"}]}
{"channel":"book","type":"update","data":[{"symbol":"ETH/EUR","bids":[],"asks":[{"price":3501.66,"qty":26.33022203}],"checksum":265072796,"timestamp":"2024-06-01T17:52:57.969626Z"}]}
{"channel":"book","type":"update","data":[{"symbol":"ETH/EUR","bids":[],"asks":[{"price":3501.66,"qty":0.00000000},{"price":3502.60,"qty":0.00802971}],"checksum":350329415,"timestamp":"2024-06-01T17:52:58.023549Z"}]}
{"channel":"book","type":"update","data":[{"symbol":"ETH/EUR","bids":[{"price":3501.27,"qty":1.60000000}],"asks":[],"checksum":3368192008,"timestamp":"2024-06-01T17:52:58.026403Z"}]}
{"channel":"book","type":"update","data":[{"symbol":"ETH/EUR","bids":[],"asks":[{"price":3501.64,"qty":26.33033258}],"checksum":2914857798,"timestamp":"2024-06-01T17:52:58.028076Z"}]}
{"channel":"book","type":"update","data":[{"symbol":"ETH/EUR","bids":[{"price":3501.05,"qty":0.00000000},{"price":3500.83,"qty":0.63806404}],"asks":[],"checksum":2287283564,"timestamp":"2024-06-01T17:52:58.028324Z"}]}
{"channel":"book","type":"update","data":[{"symbol":"ETH/EUR","bids":[],"asks":[{"price":3501.64,"qty":0.00000000},{"price":3502.60,"qty":0.00802971}],"checksum":1194829108,"timestamp":"2024-06-01T17:52:58.117253Z"}]}
{"channel":"book","type":"update","data":[{"symbol":"ETH/EUR","bids":[],"asks":[{"price":3501.96,"qty":26.32792035}],"checksum":1358170646,"timestamp":"2024-06-01T17:52:58.122427Z"}]}
{"channel":"book","type":"update","data":[{"symbol":"ETH/EUR","bids":[],"asks":[{"price":3502.03,"qty":26.32739410}],"checksum":3654737826,"timestamp":"2024-06-01T17:52:58.122453Z"}]}
{"channel":"book","type":"update","data":[{"symbol":"ETH/EUR","bids":[],"asks":[{"price":3501.62,"qty":26.33048206}],"checksum":3710252486,"timestamp":"2024-06-01T17:52:58.122510Z"}]}
{"channel":"book","type":"update","data":[{"symbol":"ETH/EUR","bids":[],"asks":[{"price":3502.14,"qty":0.00000000},{"price":3502.51,"qty":3.01305282}],"checksum":1627748633,"timestamp":"2024-06-01T17:52:58.126566Z"}]}
{"channel":"book","type":"update","data":[{"symbol":"ETH/EUR","bids":[],"asks":[{"price":3501.95,"qty":1.60000000}],"checksum":3458576299,"timestamp":"2024-06-01T17:52:58.126661Z"}]}
{"channel":"book","type":"update","data":[{"symbol":"ETH/EUR","bids":[],"asks":[{"price":3502.03,"qty":0.00000000},{"price":3502.51,"qty":3.01305282}],"checksum":3957106417,"timestamp":"2024-06-01T17:52:58.130635Z"}]}
{"channel":"book","type":"update","data":[{"symbol":"ETH/EUR","bids":[],"asks":[{"price":3501.96,"qty":0.00000000},{"price":3502.57,"qty":0.00220000}],"checksum":1985323643,"timestamp":"2024-06-01T17:52:58.130648Z"}]}
{"channel":"book","type":"update","data":[{"symbol":"ETH/EUR","bids":[],"asks":[{"price":3501.62,"qty":0.00000000},{"price":3502.60,"qty":0.00802971}],"checksum":1192912514,"timestamp":"2024-06-01T17:52:58.162881Z"}]}
{"channel":"book","type":"update","data":[{"symbol":"ETH/EUR","bids":[],"asks":[{"price":3501.59,"qty":26.33073211}],"checksum":2111366774,"timestamp":"2024-06-01T17:52:58.203887Z"}]}
{"channel":"book","type":"update","data":[{"symbol":"ETH/EUR","bids":[{"price":3501.52,"qty":1.20500000}],"asks":[],"checksum":2700313051,"timestamp":"2024-06-01T17:52:58.278604Z"}]}
{"channel":"book","type":"update","data":[{"symbol":"ETH/EUR","bids":[],"asks":[{"price":3501.59,"qty":0.00000000},{"price":3502.60,"qty":0.00802971}],"checksum":437876062,"timestamp":"2024-06-01T17:52:58.499715Z"}]}
{"channel":"book","type":"update","data":[{"symbol":"ETH/EUR","bids":[{"price":3501.39,"qty":0.00000000},{"price":3500.83,"qty":0.63806404}],"asks":[],"checksum":237366835,"timestamp":"2024-06-01T17:52:58.505201Z"}]}
{"channel":"book","type":"update","data":[{"symbol":"ETH/EUR","bids":[],"asks":[{"price":3501.67,"qty":26.33016859}],"checksum":22140911,"timestamp":"2024-06-01T17:52:58.505757Z"}]}
{"channel":"book","type":"update","data":[{"symbol":"ETH/EUR","bids":[],"asks":[{"price":3501.63,"qty":26.33043469}],"checksum":253215770,"timestamp":"2024-06-01T17:52:58.505866Z"}]}
{"channel":"book","type":"update","data":[{"symbol":"ETH/EUR","bids":[],"asks":[{"price":3501.94,"qty":26.32807071}],"checksum":2825020157,"timestamp":"2024-06-01T17:52:58.505882Z"}]}
{"channel":"book","type":"update","data":[{"symbol":"ETH/EUR","bids":[{"price":3501.27,"qty":0.00000000},{"price":3500.82,"qty":0.84644082}],"asks":[],"checksum":3284584422,"timestamp":"2024-06-01T17:52:58.508694Z"}]}
{"channel":"book","type":"update","data":[{"symbol":"ETH/EUR","bids":[],"asks":[{"price":3501.63,"qty":0.00000000},{"price":3502.51,"qty":3.01305282}],"checksum":2169459935,"timestamp":"2024-06-01T17:52:58.512262Z"}]}
{"channel":"book","type":"update","data":[{"symbol":"ETH/EUR","bids":[],"asks":[{"price":3501.67,"qty":0.00000000},{"price":3502.57,"qty":0.00220000}],"checksum":2838685266,"timestamp":"2024-06-01T17:52:58.512323Z"}]}
{"channel":"book","type":"update","data":[{"symbol":"ETH/EUR","bids":[],"asks":[{"price":3501.94,"qty":0.00000000},{"price":3502.60,"qty":0.00802971}],"checksum":941452867,"timestamp":"2024-06-01T17:52:58.519700Z"}]}
{"channel":"book","type":"update","data":[{"symbol":"ETH/EUR","bids":[{"price":3501.32,"qty":26.33267574}],"asks":[],"checksum":1121706214,"timestamp":"2024-06-01T17:52:58.524130Z"}]}
{"channel":"book","type":"update","data":[{"symbol":"ETH/EUR","bids":[{"price":3501.32,"qty":0.00000000},{"price":3500.82,"qty":0.84644082}],"asks":[],"checksum":941452867,"timestamp":"2024-06-01T17:52:58.555269Z"}]}
{"channel":"book","type":"update","data":[{"symbol":"ETH/EUR","bids":[{"price":3501.26,"qty":2.00000000}],"asks":[],"checksum":2406186297,"timestamp":"2024-06-01T17:52:58.561314Z"}]}
{"channel":"book","type":"update","data":[{"symbol":"ETH/EUR","bids":[],"asks":[{"price":3501.61,"qty":26.33056366}],"checksum":1487507499,"timestamp":"2024-06-01T17:52:58.572580Z"}]}
{"channel":"book","type":"update","data":[{"symbol":"ETH/EUR","bids":[{"price":3501.31,"qty":26.33280472}],"asks":[],"checksum":199277375,"timestamp":"2024-06-01T17:52:58.576779Z"}]}
{"channel":"book","type":"update","data":[{"symbol":"ETH/EUR","bids":[{"price":3501.31,"qty":0.00000000},{"price":3500.83,"qty":0.63806404}],"asks":[],"checksum":1487507499,"timestamp":"2024-06-01T17:52:58.591889Z"}]}
{"channel":"book","type":"update","data":[{"symbol":"ETH/EUR","bids":[],"asks":[{"price":3501.61,"qty":0.00000000},{"price":3502.60,"qty":0.00802971}],"checksum":2406186297,"timestamp":"2024-06-01T17:52:58.591922Z"}]}
{"channel":"book","type":"update","data":[{"symbol":"ETH/EUR","bids":[{"price":3501.53,"qty":1.45500000}],"asks":[],"checksum":100459322,"timestamp":"2024-06-01T17:52:58.615396Z"}]}
{"channel":"book","type":"update","data":[{"symbol":"ETH/EUR","bids":[],"asks":[{"price":3501.65,"qty":26.33028204}],"checksum":1923079763,"timestamp":"2024-06-01T17:52:58.643932Z"}]}
{"channel":"book","type":"update","data":[{"symbol":"ETH/EUR","bids":[{"price":3501.34,"qty":26.33252307}],"asks":[],"checksum":2879817674,"timestamp":"2024-06-01T17:52:58.644062Z"}]}
{"channel":"book","type":"update","data":[{"symbol":"ETH/EUR","bids":[],"asks":[{"price":3501.65,"qty":0.00000000},{"price":3502.60,"qty":0.00802971}],"checksum":3703945891,"timestamp":"2024-06-01T17:52:58.661348Z"}]}
{"channel":"book","type":"update","data":[{"symbol":"ETH/EUR","bids":[{"price":3501.34,"qty":0.00000000},{"price":3500.90,"qty":26.33587310}],"asks":[],"checksum":100459322,"timestamp":"2024-06-01T17:52:58.661362Z"}]}
{"channel":"book","type":"update","data":[{"symbol":"ETH/EUR","bids":[{"price":3501.52,"qty":0.00000000},{"price":3500.83,"qty":0.63806404}],"asks":[],"checksum":3143266922,"timestamp":"2024-06-01T17:52:58.689874Z"}]}
{"channel":"book","type":"update","data":[{"symbol":"ETH/EUR","bids":[{"price":3501.33,"qty":26.33261125}],"asks":[],"checksum":126784128,"timestamp":"2024-06-01T17:52:58.698242Z"}]}
{"channel":"book","type":"update","data":[{"symbol":"ETH/EUR","bids":[],"asks":[{"price":3501.65,"qty":26.33030486}],"checksum":212117758,"timestamp":"2024-06-01T17:52:58.732181Z"}]}
{"channel":"book","type":"update","data":[{"symbol":"ETH/EUR","bids":[{"price":3501.27,"qty":26.33307093}],"asks":[],"checksum":2600172113,"timestamp":"2024-06-01T17:52:58.732283Z"}]}
{"channel":"book","type":"update","data":[{"symbol":"ETH/EUR","bids":[],"asks":[{"price":3501.72,"qty":26.32974510}],"checksum":1412433236,"timestamp":"2024-06-01T17:52:58.732389Z"}]}
{"channel":"book","type":"update","data":[{"symbol":"ETH/EUR","bids":[{"price":3501.34,"qty":2.00000000}],"asks":[],"checksum":4079823733,"timestamp":"2024-06-01T17:52:58.737089Z"}]}
{"channel":"book","type":"update","data":[{"symbol":"ETH/EUR","bids":[{"price":3501.51,"qty":0.00000000},{"price":3501.01,"qty":1.35352976},{"price":3501.54,"qty":0.02854600}],"asks":[],"checksum":2706226383,"timestamp":"2024-06-01T17:52:58.761463Z"}]}
{"channel":"book","type":"update","data":[{"symbol":"ETH/EUR","bids":[],"asks":[{"price":3502.19,"qty":0.00802864}],"checksum":3326972712,"timestamp":"2024-06-01T17:52:58.761600Z"}]}
{"channel":"book","type":"update","data":[{"symbol":"ETH/EUR","bids":[{"price":3501.53,"qty":0.00000000},{"price":3501.01,"qty":1.35352976}],"asks":[],"checksum":4072894547,"timestamp":"2024-06-01T17:52:58.771764Z"}]}
{"channel":"book","type":"update","data":[{"symbol":"ETH/EUR","bids":[{"price":3501.26,"qty":0.00000000},{"price":3500.90,"qty":26.33587310}],"asks":[],"checksum":3561802490,"timestamp":"2024-06-01T17:52:58.776937Z"}]}
{"channel":"book","type":"update","data":[{"symbol":"ETH/EUR","bids":[],"asks":[{"price":3501.65,"qty":0.00000000},{"price":3502.51,"qty":3.01305282}],"checksum":1963291080,"timestamp":"2024-06-01T17:52:58.809427Z"}]}
{"channel":"book","type":"update","data":[{"symbol":"ETH/EUR","bids":[],"asks":[{"price":3501.72,"qty":0.00000000},{"price":3502.57,"qty":0.00220000}],"checksum":2827643474,"timestamp":"2024-06-01T17:52:58.814120Z"}]}
{"channel":"book","type":"update","data":[{"symbol":"ETH/EUR","bids":[],"asks":[{"price":3501.63,"qty":26.33044699}],"checksum":1724604926,"timestamp":"2024-06-01T17:52:58.818936Z"}]}
{"channel":"book","type":"update","data":[{"symbol":"ETH/EUR","bids":[],"asks":[{"price":3501.94,"qty":26.32807071}],"checksum":253278371,"timestamp":"2024-06-01T17:52:58.824013Z"}]}
{"channel":"book","type":"update","data":[{"symbol":"ETH/EUR","bids":[],"asks":[{"price":3501.94,"qty":0.00000000},{"price":3502.51,"qty":3.01305282}],"checksum":1724604926,"timestamp":"2024-06-01T17:52:58.827515Z"}]}
{"channel":"book","type":"update","data":[{"symbol":"ETH/EUR","bids":[],"asks":[{"price":3501.63,"qty":0.00000000},{"price":3502.57,"qty":0.00220000}],"checksum":2827643474,"timestamp":"2024-06-01T17:52:58.899742Z"}]}
{"channel":"book","type":"update","data":[{"symbol":"ETH/EUR","bids":[],"asks":[{"price":3501.65,"qty":26.33027591}],"checksum":2079336386,"timestamp":"2024-06-01T17:52:58.904711Z"}]}
{"channel":"book","type":"update","data":[{"symbol":"ETH/EUR","bids":[{"price":3501.33,"qty":0.00000000},{"price":3500.83,"qty":0.63806404}],"asks":[],"checksum":498396725,"timestamp":"2024-06-01T17:52:58.912557Z"}]}
{"channel":"book","type":"update","data":[{"symbol":"ETH/EUR","bids":[],"asks":[{"price":3501.65,"qty":0.00000000},{"price":3502.57,"qty":0.00220000}],"checksum":405195038,"timestamp":"2024-06-01T17:52:58.912701Z"}]}
{"channel":"book","type":"update","data":[{"symbol":"ETH/EUR","bids":[{"price":3501.30,"qty":1.60000000}],"asks":[],"checksum":3144222237,"timestamp":"2024-06-01T17:52:58.915651Z"}]}
{"channel":"book","type":"update","data":[{"symbol":"ETH/EUR","bids":[{"price":3501.34,"qty":28.33257440}],"asks":[],"checksum":3168007837,"timestamp":"2024-06-01T17:52:58.919085Z"}]}
{"channel":"book","type":"update","data":[{"symbol":"ETH/EUR","bids":[],"asks":[{"price":3501.74,"qty":26.32962140}],"checksum":908369811,"timestamp":"2024-06-01T17:52:58.940604Z"}]}
{"channel":"book","type":"update","data":[{"symbol":"ETH/EUR","bids":[{"price":3501.50,"qty":0.00000000},{"price":3500.83,"qty":0.63806404}],"asks":[],"checksum":507671460,"timestamp":"2024-06-01T17:52:59.022487Z"}]}
{"channel":"book","type":"update","data":[{"symbol":"ETH/EUR","bids":[{"price":3501.35,"qty":6.00000000}],"asks":[],"checksum":3491326993,"timestamp":"2024-06-01T17:52:59.027781Z"}]}
{"channel":"book","type":"update","data":[{"symbol":"ETH/EUR","bids":[{"price":3501.34,"qty":2.00000000}],"asks":[],"checksum":2003199817,"timestamp":"2024-06-01T17:52:59.110493Z"}]}
{"channel":"book","type":"update","data":[{"symbol":"ETH/EUR","bids":[],"asks":[{"price":3501.73,"qty":26.32964962}],"checksum":750765955,"timestamp":"2024-06-01T17:52:59.114340Z"}]}
{"channel":"book","type":"update","data":[{"symbol":"ETH/EUR","bids":[{"price":3501.35,"qty":32.33245331}],"asks":[],"checksum":87032273,"timestamp":"2024-06-01T17:52:59.114583Z"}]}
{"channel":"book","type":"update","data":[{"symbol":"ETH/EUR","bids":[{"price":3501.35,"qty":26.33245331}],"asks":[],"checksum":3784736691,"timestamp":"2024-06-01T17:52:59.115345Z"}]}
{"channel":"book","type":"update","data":[{"symbol":"ETH/EUR","bids":[{"price":3501.36,"qty":2.00000000}],"asks":[],"checksum":764565892,"timestamp":"2024-06-01T17:52:59.116039Z"}]}
{"channel":"book","type":"update","data":[{"symbol":"ETH/EUR","bids":[],"asks":[{"price":3501.73,"qty":0.00000000},{"price":3502.51,"qty":3.01305282}],"checksum":1984690510,"timestamp":"2024-06-01T17:52:59.118872Z"}]}
{"channel":"book","type":"update","data":[{"symbol":"ETH/EUR","bids":[{"price":3501.34,"qty":0.00000000},{"price":3500.90,"qty":26.33587310}],"asks":[],"checksum":1613942478,"timestamp":"2024-06-01T17:52:59.132753Z"}]}
{"channel":"book","type":"update","data":[{"symbol":"ETH/EUR","bids":[],"asks":[{"price":3501.74,"qty":0.00000000},{"price":3502.57,"qty":0.00220000}],"checksum":2264929440,"timestamp":"2024-06-01T17:52:59.237474Z"}]}
{"channel":"book","type":"update","data":[{"symbol":"ETH/EUR","bids":[],"asks":[{"price":3501.65,"qty":26.33028865}],"checksum":1069559673,"timestamp":"2024-06-01T17:52:59.242305Z"}]}
{"channel":"book","type":"update","data":[{"symbol":"ETH/EUR","bids":[],"asks":[{"price":3501.93,"qty":26.32814589}],"checksum":457334368,"timestamp":"2024-06-01T17:52:59.242497Z"}]}
{"channel":"book","type":"update","data":[{"symbol":"ETH/EUR","bids":[{"price":3501.35,"qty":0.00000000},{"price":3500.83,"qty":0.63806404}],"asks":[],"checksum":4150359801,"timestamp":"2024-06-01T17:52:59.494265Z"}]}
{"channel":"book","type":"update","data":[{"symbol":"ETH/EUR","bids":[],"asks":[{"price":3501.72,"qty":26.32972889}],"checksum":2761139623,"timestamp":"2024-06-01T17:52:59.498439Z"}]}
{"channel":"book","type":"update","data":[{"symbol":"ETH/EUR","bids":[],"asks":[{"price":3501.65,"qty":0.00000000},{"price":3502.45,"qty":0.00220000}],"checksum":3983353848,"timestamp":"2024-06-01T17:52:59.667731Z"}]}
{"channel":"book","type":"update","data":[{"symbol":"ETH/EUR","bids":[],"asks":[{"price":3501.72,"qty":0.00000000},{"price":3502.51,"qty":3.01305282}],"checksum":1675874394,"timestamp":"2024-06-01T17:52:59.673354Z"}]}
{"channel":"book","type":"update","data":[{"symbol":"ETH/EUR","bids":[],"asks":[{"price":3501.64,"qty":26.33039515}],"checksum":899184660,"timestamp":"2024-06-01T17:52:59.673509Z"}]}
{"channel":"book","type":"update","data":[{"symbol":"ETH/EUR","bids":[],"asks":[{"price":3501.71,"qty":26.32980000}],"checksum":4023312064,"timestamp":"2024-06-01T17:52:59.701697Z"}]}
{"channel":"book","type":"update","data":[{"symbol":"ETH/EUR","bids":[],"asks":[{"price":3502.19,"qty":0.00000000},{"price":3502.45,"qty":0.00220000}],"checksum":2236727276,"timestamp":"2024-06-01T17:52:59.717511Z"}]}
{"channel":"book","type":"update","data":[{"symbol":"ETH/EUR","bids":[],"asks":[{"price":3501.64,"qty":0.00000000},{"price":3502.50,"qty":0.00802867}],"checksum":1085611189,"timestamp":"2024-06-01T17:52:59.717604Z"}]}
{"channel":"book","type":"update","data":[{"symbol":"ETH/EUR","bids":[],"asks":[{"price":3501.70,"qty":26.32987519}],"checksum":3976174473,"timestamp":"2024-06-01T17:52:59.768397Z"}]}
{"channel":"book","type":"update","data":[{"symbol":"ETH/EUR","bids":[],"asks":[{"price":3501.70,"qty":0.00000000},{"price":3502.50,"qty":0.00802867}],"checksum":1085611189,"timestamp":"2024-06-01T17:52:59.773284Z"}]}
{"channel":"book","type":"update","data":[{"symbol":"ETH/EUR","bids":[{"price":3501.25,"qty":0.00000000},{"price":3500.82,"qty":0.84644082}],"asks":[],"checksum":1192483349,"timestamp":"2024-06-01T17:52:59.825152Z"}]}
{"channel":"book","type":"update","data":[{"symbol":"ETH/EUR","bids":[{"price":3501.54,"qty":0.00000000},{"price":3500.69,"qty":6.92318992},{"price":3501.48,"qty":0.02854650}],"asks":[],"checksum":3211341009,"timestamp":"2024-06-01T17:52:59.860490Z"}]}
