{"channel":"book","type":"snapshot","data":[{"symbol":"ETH/USD","bids":[{"price":3794.52,"qty":233.69647159},{"price":3794.45,"qty":2.18000000},{"price":3794.44,"qty":0.26346643},{"price":3794.34,"qty":0.75711813},{"price":3794.33,"qty":3.95290248},{"price":3794.30,"qty":6.93000000},{"price":3794.16,"qty":0.06693358},{"price":3794.15,"qty":7.20000000},{"price":3794.14,"qty":3.00000000},{"price":3793.99,"qty":2.45696258}],"asks":[{"price":3794.53,"qty":0.55000000},{"price":3796.18,"qty":10.81226191},{"price":3796.35,"qty":0.52698006},{"price":3796.43,"qty":3.00000000},{"price":3796.57,"qty":2.18000000},{"price":3796.69,"qty":26.33879670},{"price":3796.74,"qty":26.49350915},{"price":3796.83,"qty":3.00000000},{"price":3796.98,"qty":4.46738069},{"price":3796.99,"qty":26.33667130}],"checksum":281140094}]}
{"channel":"book","type":"update","data":[{"symbol":"ETH/USD","bids":[],"asks":[{"price":3796.43,"qty":0.00000000},{"price":3797.16,"qty":0.79183092}],"checksum":2185894680,"timestamp":"2024-06-01T17:51:49.658219Z"}]}
{"channel":"book","type":"update","data":[{"symbol":"ETH/USD","bids":[],"asks":[{"price":3796.43,"qty":3.00000000}],"checksum":281140094,"timestamp":"2024-06-01T17:51:49.670034Z"}]}
{"channel":"book","type":"update","data":[{"symbol":"ETH/USD","bids":[],"asks":[{"price":3796.98,"qty":0.16128069},{"price":3796.68,"qty":4.30610000}],"checksum":2269396830,"timestamp":"2024-06-01T17:51:49.671821Z"}]}
{"channel":"book","type":"update","data":[{"symbol":"ETH/USD","bids":[{"price":3794.52,"qty":230.29271213}],"asks":[],"checksum":2572932146,"timestamp":"2024-06-01T17:51:49.698535Z"}]}
{"channel":"book","type":"update","data":[{"symbol":"ETH/USD","bids":[{"price":3794.52,"qty":230.39271213}],"asks":[],"checksum":2629559847,"timestamp":"2024-06-01T17:51:49.720016Z"}]}
{"channel":"book","type":"update","data":[{"symbol":"ETH/USD","bids":[],"asks":[{"price":3796.93,"qty":0.77000000}],"checksum":476595342,"timestamp":"2024-06-01T17:51:49.738779Z"}]}
{"channel":"book","type":"update","data":[{"symbol":"ETH/USD","bids":[{"price":3794.35,"qty":0.00936948}],"asks":[],"checksum":3688356903,"timestamp":"2024-06-01T17:51:49.778568Z"}]}
{"channel":"book","type":"update","data":[{"symbol":"ETH/USD","bids":[{"price":3794.52,"qty":233.79647159}],"asks":[],"checksum":2590652912,"timestamp":"2024-06-01T17:51:49.820649Z"}]}
{"channel":"book","type":"update","data":[{"symbol":"ETH/USD","bids":[],"asks":[{"price":3796.17,"qty":0.79971616}],"checksum":1401133663,"timestamp":"2024-06-01T17:51:49.824768Z"}]}
{"channel":"book","type":"update","data":[{"symbol":"ETH/USD","bids":[],"asks":[{"price":3796.57,"qty":0.00000000},{"price":3796.93,"qty":0.77000000}],"checksum":4075735074,"timestamp":"2024-06-01T17:51:49.922087Z"}]}
{"channel":"book","type":"update","data":[{"symbol":"ETH/USD","bids":[],"asks":[{"price":3796.18,"qty":0.00000000},{"price":3796.99,"qty":26.33667130}],"checksum":91377220,"timestamp":"2024-06-01T17:51:49.933373Z"}]}
{"channel":"book","type":"update","data":[{"symbol":"ETH/USD","bids":[],"asks":[{"price":3796.69,"qty":0.00000000},{"price":3797.11,"qty":10.81226191}],"checksum":3206462098,"timestamp":"2024-06-01T17:51:49.946426Z"}]}
{"channel":"book","type":"update","data":[{"symbol":"ETH/USD","bids":[],"asks":[{"price":3796.72,"qty":26.33859084}],"checksum":1085176405,"timestamp":"2024-06-01T17:51:49.952431Z"}]}
{"channel":"book","type":"update","data":[{"symbol":"ETH/USD","bids":[],"asks":[{"price":3796.72,"qty":0.00000000},{"price":3797.11,"qty":10.81226191}],"checksum":3206462098,"timestamp":"2024-06-01T17:51:49.996171Z"}]}
{"channel":"book","type":"update","data":[{"symbol":"ETH/USD","bids":[],"asks":[{"price":3796.73,"qty":26.33848285}],"checksum":2028369467,"timestamp":"2024-06-01T17:51:50.064302Z"}]}
{"channel":"book","type":"update","data":[{"symbol":"ETH/USD","bids":[],"asks":[{"price":3796.73,"qty":0.00000000},{"price":3797.11,"qty":10.81226191}],"checksum":3206462098,"timestamp":"2024-06-01T17:51:50.077578Z"}]}
{"channel":"book","type":"update","data":[{"symbol":"ETH/USD","bids":[],"asks":[{"price":3796.69,"qty":26.33877407}],"checksum":1341945496,"timestamp":"2024-06-01T17:51:50.174793Z"}]}
{"channel":"book","type":"update","data":[{"symbol":"ETH/USD","bids":[],"asks":[{"price":3796.69,"qty":0.00000000},{"price":3797.11,"qty":10.81226191}],"checksum":3206462098,"timestamp":"2024-06-01T17:51:50.178795Z"}]}
{"channel":"book","type":"update","data":[{"symbol":"ETH/USD","bids":[],"asks":[{"price":3796.69,"qty":26.33875520}],"checksum":323787638,"timestamp":"2024-06-01T17:51:50.271224Z"}]}
{"channel":"book","type":"update","data":[{"symbol":"ETH/USD","bids":[],"asks":[{"price":3796.69,"qty":0.00000000},{"price":3797.11,"qty":10.81226191}],"checksum":3206462098,"timestamp":"2024-06-01T17:51:50.618774Z"}]}
{"channel":"book","type":"update","data":[{"symbol":"ETH/USD","bids":[],"asks":[{"price":3796.65,"qty":26.33907159}],"checksum":3425963754,"timestamp":"2024-06-01T17:51:50.622808Z"}]}
{"channel":"book","type":"update","data":[{"symbol":"ETH/USD","bids":[],"asks":[{"price":3796.68,"qty":0.00000000},{"price":3797.11,"qty":10.81226191},{"price":3796.64,"qty":4.30610000}],"checksum":872259970,"timestamp":"2024-06-01T17:51:50.626384Z"}]}
{"channel":"book","type":"update","data":[{"symbol":"ETH/USD","bids":[],"asks":[{"price":3796.65,"qty":0.00000000},{"price":3797.11,"qty":10.81226191}],"checksum":995061518,"timestamp":"2024-06-01T17:51:50.694963Z"}]}
{"channel":"book","type":"update","data":[{"symbol":"ETH/USD","bids":[],"asks":[{"price":3796.63,"qty":26.33917475}],"checksum":4016584661,"timestamp":"2024-06-01T17:51:50.700092Z"}]}
{"channel":"book","type":"update","data":[{"symbol":"ETH/USD","bids":[],"asks":[{"price":3796.64,"qty":0.00000000},{"price":3797.11,"qty":10.81226191},{"price":3796.62,"qty":4.30610000}],"checksum":860096027,"timestamp":"2024-06-01T17:51:50.703255Z"}]}
{"channel":"book","type":"update","data":[{"symbol":"ETH/USD","bids":[],"asks":[{"price":3796.63,"qty":0.00000000},{"price":3797.11,"qty":10.81226191}],"checksum":2036827584,"timestamp":"2024-06-01T17:51:50.851791Z"}]}
{"channel":"book","type":"update","data":[{"symbol":"ETH/USD","bids":[],"asks":[{"price":3796.62,"qty":0.00000000},{"price":3797.18,"qty":29.65660522},{"price":3796.73,"qty":4.30610000}],"checksum":2652244824,"timestamp":"2024-06-01T17:51:50.855190Z"}]}
{"channel":"book","type":"update","data":[{"symbol":"ETH/USD","bids":[],"asks":[{"price":3796.65,"qty":26.33902594}],"checksum":3208854623,"timestamp":"2024-06-01T17:51:50.855940Z"}]}
{"channel":"book","type":"update","data":[{"symbol":"ETH/USD","bids":[],"asks":[{"price":3796.73,"qty":0.00000000},{"price":3797.11,"qty":10.81226191},{"price":3796.64,"qty":4.30610000}],"checksum":181005584,"timestamp":"2024-06-01T17:51:50.886238Z"}]}
{"channel":"book","type":"update","data":[{"symbol":"ETH/USD","bids":[],"asks":[{"price":3796.65,"qty":0.00000000},{"price":3797.11,"qty":10.81226191}],"checksum":995061518,"timestamp":"2024-06-01T17:51:51.118994Z"}]}
{"channel":"book","type":"update","data":[{"symbol":"ETH/USD","bids":[],"asks":[{"price":3796.67,"qty":26.33890741}],"checksum":4160336397,"timestamp":"2024-06-01T17:51:51.125976Z"}]}
{"channel":"book","type":"update","data":[{"symbol":"ETH/USD","bids":[],"asks":[{"price":3796.67,"qty":0.00000000},{"price":3797.11,"qty":10.81226191}],"checksum":995061518,"timestamp":"2024-06-01T17:51:51.214358Z"}]}
{"channel":"book","type":"update","data":[{"symbol":"ETH/USD","bids":[],"asks":[{"price":3796.69,"qty":26.33874411}],"checksum":2961669309,"timestamp":"2024-06-01T17:51:51.219394Z"}]}
{"channel":"book","type":"update","data":[{"symbol":"ETH/USD","bids":[],"asks":[{"price":3796.93,"qty":0.00000000},{"price":3797.11,"qty":10.81226191},{"price":3796.82,"qty":0.77000000}],"checksum":3584238833,"timestamp":"2024-06-01T17:51:51.276929Z"}]}
{"channel":"book","type":"update","data":[{"symbol":"ETH/USD","bids":[],"asks":[{"price":3796.82,"qty":1.54000000}],"checksum":3173093595,"timestamp":"2024-06-01T17:51:51.279886Z"}]}
{"channel":"book","type":"update","data":[{"symbol":"ETH/USD","bids":[],"asks":[{"price":3796.69,"qty":0.00000000},{"price":3797.11,"qty":10.81226191}],"checksum":1992024246,"timestamp":"2024-06-01T17:51:51.284369Z"}]}
{"channel":"book","type":"update","data":[{"symbol":"ETH/USD","bids":[],"asks":[{"price":3796.72,"qty":26.33858589}],"checksum":830886921,"timestamp":"2024-06-01T17:51:51.290160Z"}]}
{"channel":"book","type":"update","data":[{"symbol":"ETH/USD","bids":[],"asks":[{"price":3796.43,"qty":0.00000000},{"price":3797.11,"qty":10.81226191}],"checksum":3997167005,"timestamp":"2024-06-01T17:51:51.334679Z"}]}
{"channel":"book","type":"update","data":[{"symbol":"ETH/USD","bids":[],"asks":[{"price":3796.72,"qty":0.00000000},{"price":3797.18,"qty":29.65660522}],"checksum":2031627336,"timestamp":"2024-06-01T17:51:51.560752Z"}]}
{"channel":"book","type":"update","data":[{"symbol":"ETH/USD","bids":[],"asks":[{"price":3796.68,"qty":26.33884938}],"checksum":3790426535,"timestamp":"2024-06-01T17:51:51.564741Z"}]}
{"channel":"book","type":"update","data":[{"symbol":"ETH/USD","bids":[],"asks":[{"price":3796.82,"qty":0.77000000}],"checksum":2961138956,"timestamp":"2024-06-01T17:51:51.565435Z"}]}
{"channel":"book","type":"update","data":[{"symbol":"ETH/USD","bids":[],"asks":[{"price":3796.82,"qty":0.00000000},{"price":3797.18,"qty":29.65660522}],"checksum":1119203628,"timestamp":"2024-06-01T17:51:51.568688Z"}]}
{"channel":"book","type":"update","data":[{"symbol":"ETH/USD","bids":[],"asks":[{"price":3796.74,"qty":0.15510000}],"checksum":412009748,"timestamp":"2024-06-01T17:51:51.574558Z"}]}
{"channel":"book","type":"update","data":[{"symbol":"ETH/USD","bids":[],"asks":[{"price":3796.68,"qty":0.00000000},{"price":3797.19,"qty":26.33530541}],"checksum":2130491471,"timestamp":"2024-06-01T17:51:51.574573Z"}]}
{"channel":"book","type":"update","data":[{"symbol":"ETH/USD","bids":[],"asks":[{"price":3797.19,"qty":0.00000000},{"price":3797.21,"qty":3.00000000}],"checksum":1268212706,"timestamp":"2024-06-01T17:51:51.578019Z"}]}
{"channel":"book","type":"update","data":[{"symbol":"ETH/USD","bids":[],"asks":[{"price":3796.64,"qty":0.00000000},{"price":3797.22,"qty":2.18000000},{"price":3796.98,"qty":4.30610000}],"checksum":3791743968,"timestamp":"2024-06-01T17:51:51.578412Z"}]}
{"channel":"book","type":"update","data":[{"symbol":"ETH/USD","bids":[],"asks":[{"price":3796.78,"qty":26.33817436}],"checksum":960654472,"timestamp":"2024-06-01T17:51:51.633375Z"}]}
{"channel":"book","type":"update","data":[{"symbol":"ETH/USD","bids":[],"asks":[{"price":3796.98,"qty":0.00000000},{"price":3797.21,"qty":3.00000000},{"price":3796.77,"qty":4.30610000}],"checksum":2562000345,"timestamp":"2024-06-01T17:51:51.636946Z"}]}
{"channel":"book","type":"update","data":[{"symbol":"ETH/USD","bids":[],"asks":[{"price":3796.78,"qty":0.00000000},{"price":3797.21,"qty":3.00000000}],"checksum":26709713,"timestamp":"2024-06-01T17:51:51.680996Z"}]}
{"channel":"book","type":"update","data":[{"symbol":"ETH/USD","bids":[],"asks":[{"price":3796.77,"qty":0.00000000},{"price":3797.22,"qty":2.18000000},{"price":3796.98,"qty":4.30610000}],"checksum":3791743968,"timestamp":"2024-06-01T17:51:51.684685Z"}]}
{"channel":"book","type":"update","data":[{"symbol":"ETH/USD","bids":[],"asks":[{"price":3796.80,"qty":26.33800842}],"checksum":1146102414,"timestamp":"2024-06-01T17:51:51.686526Z"}]}
{"channel":"book","type":"update","data":[{"symbol":"ETH/USD","bids":[],"asks":[{"price":3796.92,"qty":0.77000000}],"checksum":493611635,"timestamp":"2024-06-01T17:51:51.730930Z"}]}
{"channel":"book","type":"update","data":[{"symbol":"ETH/USD","bids":[],"asks":[{"price":3796.98,"qty":0.00000000},{"price":3797.18,"qty":29.65660522},{"price":3796.79,"qty":4.30610000}],"checksum":2938346316,"timestamp":"2024-06-01T17:51:51.734074Z"}]}
{"channel":"book","type":"update","data":[{"symbol":"ETH/USD","bids":[],"asks":[{"price":3796.80,"qty":0.00000000},{"price":3797.18,"qty":29.65660522}],"checksum":460110543,"timestamp":"2024-06-01T17:51:51.807707Z"}]}
{"channel":"book","type":"update","data":[{"symbol":"ETH/USD","bids":[],"asks":[{"price":3796.79,"qty":30.64417954}],"checksum":1544328244,"timestamp":"2024-06-01T17:51:51.814369Z"}]}
{"channel":"book","type":"update","data":[{"symbol":"ETH/USD","bids":[],"asks":[{"price":3796.79,"qty":26.33807954},{"price":3796.78,"qty":4.30610000}],"checksum":1536154241,"timestamp":"2024-06-01T17:51:51.817422Z"}]}
{"channel":"book","type":"update","data":[{"symbol":"ETH/USD","bids":[],"asks":[{"price":3796.79,"qty":0.00000000},{"price":3797.18,"qty":29.65660522}],"checksum":73438738,"timestamp":"2024-06-01T17:51:51.912310Z"}]}
{"channel":"book","type":"update","data":[{"symbol":"ETH/USD","bids":[],"asks":[{"price":3796.78,"qty":30.64425127}],"checksum":3182440562,"timestamp":"2024-06-01T17:51:51.917930Z"}]}
{"channel":"book","type":"update","data":[{"symbol":"ETH/USD","bids":[],"asks":[{"price":3796.78,"qty":26.33815127},{"price":3796.77,"qty":4.30610000}],"checksum":864157081,"timestamp":"2024-06-01T17:51:51.921105Z"}]}
{"channel":"book","type":"update","data":[{"symbol":"ETH/USD","bids":[],"asks":[{"price":3796.78,"qty":0.00000000},{"price":3797.18,"qty":29.65660522}],"checksum":2703570665,"timestamp":"2024-06-01T17:51:51.997939Z"}]}
{"channel":"book","type":"update","data":[{"symbol":"ETH/USD","bids":[],"asks":[{"price":3796.77,"qty":0.00000000},{"price":3797.21,"qty":3.00000000},{"price":3796.98,"qty":4.30610000}],"checksum":1344723674,"timestamp":"2024-06-01T17:51:52.001411Z"}]}
{"channel":"book","type":"update","data":[{"symbol":"ETH/USD","bids":[],"asks":[{"price":3796.77,"qty":26.33823177}],"checksum":2693511906,"timestamp":"2024-06-01T17:51:52.003166Z"}]}
{"channel":"book","type":"update","data":[{"symbol":"ETH/USD","bids":[],"asks":[{"price":3796.98,"qty":0.00000000},{"price":3797.18,"qty":29.65660522},{"price":3796.76,"qty":4.30610000}],"checksum":1138432239,"timestamp":"2024-06-01T17:51:52.030974Z"}]}
{"channel":"book","type":"update","data":[{"symbol":"ETH/USD","bids":[],"asks":[{"price":3796.92,"qty":0.00000000},{"price":3797.18,"qty":29.65660522},{"price":3796.82,"qty":0.77000000}],"checksum":4000963847,"timestamp":"2024-06-01T17:51:52.034745Z"}]}
{"channel":"book","type":"update","data":[{"symbol":"ETH/USD","bids":[],"asks":[{"price":3796.82,"qty":1.54000000}],"checksum":1986104983,"timestamp":"2024-06-01T17:51:52.038107Z"}]}
{"channel":"book","type":"update","data":[{"symbol":"ETH/USD","bids":[],"asks":[{"price":3796.77,"qty":0.00000000},{"price":3797.18,"qty":29.65660522}],"checksum":954153410,"timestamp":"2024-06-01T17:51:52.060155Z"}]}
{"channel":"book","type":"update","data":[{"symbol":"ETH/USD","bids":[],"asks":[{"price":3796.76,"qty":0.00000000},{"price":3797.21,"qty":3.00000000},{"price":3796.98,"qty":4.30610000}],"checksum":4055107397,"timestamp":"2024-06-01T17:51:52.063663Z"}]}
{"channel":"book","type":"update","data":[{"symbol":"ETH/USD","bids":[],"asks":[{"price":3796.76,"qty":26.33829499}],"checksum":4220258475,"timestamp":"2024-06-01T17:51:52.064656Z"}]}
{"channel":"book","type":"update","data":[{"symbol":"ETH/USD","bids":[],"asks":[{"price":3796.82,"qty":0.77000000}],"checksum":725962168,"timestamp":"2024-06-01T17:51:52.114900Z"}]}
{"channel":"book","type":"update","data":[{"symbol":"ETH/USD","bids":[],"asks":[{"price":3796.98,"qty":0.00000000},{"price":3797.18,"qty":29.65660522},{"price":3796.75,"qty":4.30610000}],"checksum":196863281,"timestamp":"2024-06-01T17:51:52.118250Z"}]}
{"channel":"book","type":"update","data":[{"symbol":"ETH/USD","bids":[],"asks":[{"price":3796.75,"qty":30.64445820}],"checksum":167956211,"timestamp":"2024-06-01T17:51:52.180285Z"}]}
{"channel":"book","type":"update","data":[{"symbol":"ETH/USD","bids":[],"asks":[{"price":3796.75,"qty":26.33835820},{"price":3796.74,"qty":4.46120000}],"checksum":2574594900,"timestamp":"2024-06-01T17:51:52.183893Z"}]}
{"channel":"book","type":"update","data":[{"symbol":"ETH/USD","bids":[],"asks":[{"price":3796.75,"qty":0.00000000},{"price":3797.18,"qty":29.65660522}],"checksum":3903208037,"timestamp":"2024-06-01T17:51:52.330935Z"}]}
{"channel":"book","type":"update","data":[{"symbol":"ETH/USD","bids":[],"asks":[{"price":3796.73,"qty":26.33846883}],"checksum":434768176,"timestamp":"2024-06-01T17:51:52.335369Z"}]}
{"channel":"book","type":"update","data":[{"symbol":"ETH/USD","bids":[],"asks":[{"price":3796.74,"qty":0.15510000},{"price":3796.72,"qty":4.30610000}],"checksum":2886173462,"timestamp":"2024-06-01T17:51:52.338485Z"}]}
{"channel":"book","type":"update","data":[{"symbol":"ETH/USD","bids":[],"asks":[{"price":3796.73,"qty":0.00000000},{"price":3797.11,"qty":10.81226191}],"checksum":3637662525,"timestamp":"2024-06-01T17:51:52.577597Z"}]}
{"channel":"book","type":"update","data":[{"symbol":"ETH/USD","bids":[],"asks":[{"price":3796.76,"qty":0.00000000},{"price":3797.18,"qty":29.65660522}],"checksum":373378597,"timestamp":"2024-06-01T17:51:52.578523Z"}]}
{"channel":"book","type":"update","data":[{"symbol":"ETH/USD","bids":[],"asks":[{"price":3796.85,"qty":26.33768204}],"checksum":2618364767,"timestamp":"2024-06-01T17:51:52.583302Z"}]}
{"channel":"book","type":"update","data":[{"symbol":"ETH/USD","bids":[],"asks":[{"price":3796.73,"qty":26.33850092}],"checksum":2076216804,"timestamp":"2024-06-01T17:51:52.583554Z"}]}
{"channel":"book","type":"update","data":[{"symbol":"ETH/USD","bids":[{"price":3794.40,"qty":0.29493501}],"asks":[],"checksum":981395939,"timestamp":"2024-06-01T17:51:52.679134Z"}]}
{"channel":"book","type":"update","data":[{"symbol":"ETH/USD","bids":[],"asks":[{"price":3796.73,"qty":0.00000000},{"price":3797.11,"qty":10.81226191}],"checksum":1405965805,"timestamp":"2024-06-01T17:51:52.736622Z"}]}
{"channel":"book","type":"update","data":[{"symbol":"ETH/USD","bids":[],"asks":[{"price":3796.75,"qty":26.33834025}],"checksum":4253860403,"timestamp":"2024-06-01T17:51:52.740576Z"}]}
{"channel":"book","type":"update","data":[{"symbol":"ETH/USD","bids":[{"price":3794.32,"qty":5.26600000}],"asks":[],"checksum":1321107783,"timestamp":"2024-06-01T17:51:53.168569Z"}]}
{"channel":"book","type":"update","data":[{"symbol":"ETH/USD","bids":[],"asks":[{"price":3796.75,"qty":0.00000000},{"price":3797.11,"qty":10.81226191}],"checksum":3774813849,"timestamp":"2024-06-01T17:51:53.207409Z"}]}
{"channel":"book","type":"update","data":[{"symbol":"ETH/USD","bids":[],"asks":[{"price":3796.85,"qty":0.00000000},{"price":3797.21,"qty":3.00000000}],"checksum":3270830456,"timestamp":"2024-06-01T17:51:53.212048Z"}]}
{"channel":"book","type":"update","data":[{"symbol":"ETH/USD","bids":[],"asks":[{"price":3796.72,"qty":0.00000000},{"price":3797.22,"qty":2.18000000},{"price":3796.98,"qty":4.30610000}],"checksum":3665918793,"timestamp":"2024-06-01T17:51:53.218946Z"}]}
{"channel":"book","type":"update","data":[{"symbol":"ETH/USD","bids":[],"asks":[{"price":3796.71,"qty":26.33861931}],"checksum":3095901527,"timestamp":"2024-06-01T17:51:53.219912Z"}]}
{"channel":"book","type":"update","data":[{"symbol":"ETH/USD","bids":[],"asks":[{"price":3796.71,"qty":0.00000000},{"price":3797.21,"qty":3.00000000}],"checksum":3665918793,"timestamp":"2024-06-01T17:51:53.344540Z"}]}
{"channel":"book","type":"update","data":[{"symbol":"ETH/USD","bids":[],"asks":[{"price":3796.73,"qty":26.33846405}],"checksum":3845945310,"timestamp":"2024-06-01T17:51:53.349243Z"}]}
{"channel":"book","type":"update","data":[{"symbol":"ETH/USD","bids":[],"asks":[{"price":3796.98,"qty":0.00000000},{"price":3797.21,"qty":3.00000000},{"price":3796.72,"qty":4.30610000}],"checksum":3548934126,"timestamp":"2024-06-01T17:51:53.797079Z"}]}
{"channel":"book","type":"update","data":[{"symbol":"ETH/USD","bids":[],"asks":[{"price":3796.73,"qty":0.00000000},{"price":3797.21,"qty":3.00000000}],"checksum":3270830456,"timestamp":"2024-06-01T17:51:53.809699Z"}]}
{"channel":"book","type":"update","data":[{"symbol":"ETH/USD","bids":[],"asks":[{"price":3796.72,"qty":30.64466627}],"checksum":3203156,"timestamp":"2024-06-01T17:51:53.813771Z"}]}
{"channel":"book","type":"update","data":[{"symbol":"ETH/USD","bids":[],"asks":[{"price":3796.72,"qty":4.30610000}],"checksum":3270830456,"timestamp":"2024-06-01T17:51:53.866291Z"}]}
{"channel":"book","type":"update","data":[{"symbol":"ETH/USD","bids":[{"price":3794.45,"qty":0.00000000},{"price":3794.15,"qty":7.20000000}],"asks":[],"checksum":766903755,"timestamp":"2024-06-01T17:51:53.866433Z"}]}
{"channel":"book","type":"update","data":[{"symbol":"ETH/USD","bids":[],"asks":[{"price":3796.72,"qty":0.00000000},{"price":3797.22,"qty":2.18000000},{"price":3796.98,"qty":4.30610000}],"checksum":902010874,"timestamp":"2024-06-01T17:51:53.869922Z"}]}
{"channel":"book","type":"update","data":[{"symbol":"ETH/USD","bids":[],"asks":[{"price":3796.70,"qty":26.33866900}],"checksum":4084481552,"timestamp":"2024-06-01T17:51:53.870584Z"}]}
{"channel":"book","type":"update","data":[{"symbol":"ETH/USD","bids":[],"asks":[{"price":3796.70,"qty":0.00000000},{"price":3797.21,"qty":3.00000000}],"checksum":902010874,"timestamp":"2024-06-01T17:51:53.875448Z"}]}
{"channel":"book","type":"update","data":[{"symbol":"ETH/USD","bids":[],"asks":[{"price":3797.20,"qty":26.33520687}],"checksum":3105835230,"timestamp":"2024-06-01T17:51:53.879730Z"}]}
{"channel":"book","type":"update","data":[{"symbol":"ETH/USD","bids":[],"asks":[{"price":3796.99,"qty":0.00000000},{"price":3797.21,"qty":3.00000000}],"checksum":1907415875,"timestamp":"2024-06-01T17:51:53.886973Z"}]}
{"channel":"book","type":"update","data":[{"symbol":"ETH/USD","bids":[],"asks":[{"price":3796.87,"qty":26.33754028}],"checksum":1571533171,"timestamp":"2024-06-01T17:51:53.890824Z"}]}
{"channel":"book","type":"update","data":[{"symbol":"ETH/USD","bids":[{"price":3794.52,"qty":233.02647159}],"asks":[],"checksum":2497999629,"timestamp":"2024-06-01T17:51:53.958939Z"}]}
{"channel":"book","type":"update","data":[{"symbol":"ETH/USD","bids":[{"price":3794.30,"qty":6.16000000}],"asks":[],"checksum":2738914889,"timestamp":"2024-06-01T17:51:53.961812Z"}]}
{"channel":"book","type":"update","data":[{"symbol":"ETH/USD","bids":[{"price":3794.30,"qty":0.00000000},{"price":3794.14,"qty":3.00000000}],"asks":[],"checksum":4169310069,"timestamp":"2024-06-01T17:51:53.961954Z"}]}
{"channel":"book","type":"update","data":[{"symbol":"ETH/USD","bids":[{"price":3794.52,"qty":235.18047159}],"asks":[],"checksum":1368440402,"timestamp":"2024-06-01T17:51:53.965197Z"}]}
{"channel":"book","type":"update","data":[{"symbol":"ETH/USD","bids":[],"asks":[{"price":3796.64,"qty":26.33910667}],"checksum":800561816,"timestamp":"2024-06-01T17:51:54.114498Z"}]}
{"channel":"book","type":"update","data":[{"symbol":"ETH/USD","bids":[],"asks":[{"price":3796.64,"qty":0.00000000},{"price":3797.20,"qty":26.33520687}],"checksum":1368440402,"timestamp":"2024-06-01T17:51:54.128720Z"}]}
{"channel":"book","type":"update","data":[{"symbol":"ETH/USD","bids":[{"price":3794.15,"qty":0.00000000},{"price":3793.99,"qty":2.45696258},{"price":3794.35,"qty":7.20936948}],"asks":[],"checksum":3479380010,"timestamp":"2024-06-01T17:51:54.154812Z"}]}
{"channel":"book","type":"update","data":[{"symbol":"ETH/USD","bids":[{"price":3794.52,"qty":235.95047159},{"price":3794.30,"qty":0.77000000},{"price":3794.30,"qty":6.93000000}],"asks":[],"checksum":4055215906,"timestamp":"2024-06-01T17:51:54.179523Z"}]}
{"channel":"book","type":"update","data":[{"symbol":"ETH/USD","bids":[],"asks":[{"price":3796.65,"qty":26.33907489}],"checksum":330054626,"timestamp":"2024-06-01T17:51:54.185918Z"}]}
{"channel":"book","type":"update","data":[{"symbol":"ETH/USD","bids":[{"price":3794.35,"qty":7.20000000},{"price":3794.36,"qty":0.00936630}],"asks":[],"checksum":713928570,"timestamp":"2024-06-01T17:51:54.206201Z"}]}
{"channel":"book","type":"update","data":[{"symbol":"ETH/USD","bids":[],"asks":[{"price":3796.65,"qty":0.00000000},{"price":3797.20,"qty":26.33520687}],"checksum":3627865052,"timestamp":"2024-06-01T17:51:54.229256Z"}]}
{"channel":"book","type":"update","data":[{"symbol":"ETH/USD","bids":[],"asks":[{"price":3796.96,"qty":26.33688372}],"checksum":2349317442,"timestamp":"2024-06-01T17:51:54.236609Z"}]}
{"channel":"book","type":"update","data":[{"symbol":"ETH/USD","bids":[],"asks":[{"price":3796.67,"qty":26.33888804}],"checksum":510396460,"timestamp":"2024-06-01T17:51:54.236765Z"}]}
{"channel":"book","type":"update","data":[{"symbol":"ETH/USD","bids":[],"asks":[{"price":3796.87,"qty":0.00000000},{"price":3797.11,"qty":10.81226191}],"checksum":235406524,"timestamp":"2024-06-01T17:51:54.240798Z"}]}
{"channel":"book","type":"update","data":[{"symbol":"ETH/USD","bids":[],"asks":[{"price":3796.76,"qty":26.33830548}],"checksum":2947263853,"timestamp":"2024-06-01T17:51:54.245266Z"}]}
{"channel":"book","type":"update","data":[{"symbol":"ETH/USD","bids":[],"asks":[{"price":3796.67,"qty":0.00000000},{"price":3797.11,"qty":10.81226191}],"checksum":609618409,"timestamp":"2024-06-01T17:51:54.366762Z"}]}
{"channel":"book","type":"update","data":[{"symbol":"ETH/USD","bids":[],"asks":[{"price":3796.66,"qty":26.33897496}],"checksum":1491906579,"timestamp":"2024-06-01T17:51:54.370879Z"}]}
{"channel":"book","type":"update","data":[{"symbol":"ETH/USD","bids":[],"asks":[{"price":3796.66,"qty":0.00000000},{"price":3797.11,"qty":10.81226191}],"checksum":609618409,"timestamp":"2024-06-01T17:51:54.450210Z"}]}
{"channel":"book","type":"update","data":[{"symbol":"ETH/USD","bids":[],"asks":[{"price":3796.64,"qty":26.33909876}],"checksum":2738520441,"timestamp":"2024-06-01T17:51:54.455600Z"}]}
{"channel":"book","type":"update","data":[{"symbol":"ETH/USD","bids":[],"asks":[{"price":3796.64,"qty":0.00000000},{"price":3797.11,"qty":10.81226191}],"checksum":609618409,"timestamp":"2024-06-01T17:51:54.742330Z"}]}
{"channel":"book","type":"update","data":[{"symbol":"ETH/USD","bids":[],"asks":[{"price":3796.68,"qty":26.33886535}],"checksum":44349857,"timestamp":"2024-06-01T17:51:54.747690Z"}]}
{"channel":"book","type":"update","data":[{"symbol":"ETH/USD","bids":[],"asks":[{"price":3796.98,"qty":0.00000000},{"price":3797.11,"qty":10.81226191},{"price":3796.67,"qty":4.30610000}],"checksum":1734996384,"timestamp":"2024-06-01T17:51:54.887016Z"}]}
{"channel":"book","type":"update","data":[{"symbol":"ETH/USD","bids":[],"asks":[{"price":3796.68,"qty":0.00000000},{"price":3797.11,"qty":10.81226191}],"checksum":3983809467,"timestamp":"2024-06-01T17:51:54.903783Z"}]}
{"channel":"book","type":"update","data":[{"symbol":"ETH/USD","bids":[],"asks":[{"price":3796.67,"qty":30.64503008}],"checksum":877229358,"timestamp":"2024-06-01T17:51:54.907759Z"}]}
{"channel":"book","type":"update","data":[{"symbol":"ETH/USD","bids":[],"asks":[{"price":3796.67,"qty":4.30610000}],"checksum":3983809467,"timestamp":"2024-06-01T17:51:54.923485Z"}]}
{"channel":"book","type":"update","data":[{"symbol":"ETH/USD","bids":[],"asks":[{"price":3796.82,"qty":0.00000000},{"price":3797.20,"qty":26.33520687}],"checksum":1869656496,"timestamp":"2024-06-01T17:51:54.965550Z"}]}
{"channel":"book","type":"update","data":[{"symbol":"ETH/USD","bids":[],"asks":[{"price":3796.67,"qty":30.64497740}],"checksum":2746040817,"timestamp":"2024-06-01T17:51:54.974171Z"}]}
{"channel":"book","type":"update","data":[{"symbol":"ETH/USD","bids":[],"asks":[{"price":3796.67,"qty":4.30610000}],"checksum":1869656496,"timestamp":"2024-06-01T17:51:55.010367Z"}]}
{"channel":"book","type":"update","data":[{"symbol":"ETH/USD","bids":[],"asks":[{"price":3796.68,"qty":26.33882790}],"checksum":2220263661,"timestamp":"2024-06-01T17:51:55.028966Z"}]}
{"channel":"book","type":"update","data":[{"symbol":"ETH/USD","bids":[],"asks":[{"price":3796.78,"qty":0.77000000}],"checksum":981993403,"timestamp":"2024-06-01T17:51:55.185714Z"}]}
{"channel":"book","type":"update","data":[{"symbol":"ETH/USD","bids":[{"price":3794.52,"qty":235.18047159}],"asks":[],"checksum":4023494135,"timestamp":"2024-06-01T17:51:55.220609Z"}]}
{"channel":"book","type":"update","data":[{"symbol":"ETH/USD","bids":[{"price":3794.30,"qty":6.16000000}],"asks":[],"checksum":3785981086,"timestamp":"2024-06-01T17:51:55.223578Z"}]}
{"channel":"book","type":"update","data":[{"symbol":"ETH/USD","bids":[{"price":3794.30,"qty":0.00000000},{"price":3794.14,"qty":3.00000000}],"asks":[],"checksum":3198185767,"timestamp":"2024-06-01T17:51:55.223634Z"}]}
{"channel":"book","type":"update","data":[{"symbol":"ETH/USD","bids":[],"asks":[{"price":3796.76,"qty":0.00000000},{"price":3797.11,"qty":10.81226191}],"checksum":147646815,"timestamp":"2024-06-01T17:51:55.251025Z"}]}
{"channel":"book","type":"update","data":[{"symbol":"ETH/USD","bids":[],"asks":[{"price":3796.64,"qty":26.33911501}],"checksum":2871804450,"timestamp":"2024-06-01T17:51:55.255307Z"}]}
{"channel":"book","type":"update","data":[{"symbol":"ETH/USD","bids":[],"asks":[{"price":3796.64,"qty":0.00000000},{"price":3797.11,"qty":10.81226191}],"checksum":147646815,"timestamp":"2024-06-01T17:51:55.273398Z"}]}
{"channel":"book","type":"update","data":[{"symbol":"ETH/USD","bids":[{"price":3794.52,"qty":235.95047159},{"price":3794.30,"qty":0.77000000},{"price":3794.30,"qty":6.93000000}],"asks":[],"checksum":2363793347,"timestamp":"2024-06-01T17:51:55.386185Z"}]}
{"channel":"book","type":"update","data":[{"symbol":"ETH/USD","bids":[],"asks":[{"price":3796.66,"qty":26.33896750}],"checksum":3147024893,"timestamp":"2024-06-01T17:51:55.402398Z"}]}
{"channel":"book","type":"update","data":[{"symbol":"ETH/USD","bids":[],"asks":[{"price":3796.66,"qty":0.00000000},{"price":3797.11,"qty":10.81226191}],"checksum":2363793347,"timestamp":"2024-06-01T17:51:55.460176Z"}]}
{"channel":"book","type":"update","data":[{"symbol":"ETH/USD","bids":[],"asks":[{"price":3796.65,"qty":26.33904389}],"checksum":3482417217,"timestamp":"2024-06-01T17:51:55.464372Z"}]}
{"channel":"book","type":"update","data":[{"symbol":"ETH/USD","bids":[],"asks":[{"price":3796.65,"qty":0.00000000},{"price":3797.11,"qty":10.81226191}],"checksum":2363793347,"timestamp":"2024-06-01T17:51:55.585637Z"}]}
{"channel":"book","type":"update","data":[{"symbol":"ETH/USD","bids":[],"asks":[{"price":3796.67,"qty":30.64500955}],"checksum":3827101452,"timestamp":"2024-06-01T17:51:55.589860Z"}]}
{"channel":"book","type":"update","data":[{"symbol":"ETH/USD","bids":[],"asks":[{"price":3796.67,"qty":26.33890955},{"price":3796.66,"qty":4.30610000}],"checksum":4009484232,"timestamp":"2024-06-01T17:51:55.874154Z"}]}
{"channel":"book","type":"update","data":[{"symbol":"ETH/USD","bids":[],"asks":[{"price":3796.67,"qty":0.00000000},{"price":3797.11,"qty":10.81226191}],"checksum":2745971456,"timestamp":"2024-06-01T17:51:55.923507Z"}]}
{"channel":"book","type":"update","data":[{"symbol":"ETH/USD","bids":[],"asks":[{"price":3796.65,"qty":26.33901081}],"checksum":3499837308,"timestamp":"2024-06-01T17:51:55.928060Z"}]}
{"channel":"book","type":"update","data":[{"symbol":"ETH/USD","bids":[],"asks":[{"price":3796.78,"qty":0.00000000},{"price":3797.11,"qty":10.81226191}],"checksum":1982948071,"timestamp":"2024-06-01T17:51:55.947919Z"}]}
{"channel":"book","type":"update","data":[{"symbol":"ETH/USD","bids":[],"asks":[{"price":3796.74,"qty":0.00000000},{"price":3797.20,"qty":26.33520687}],"checksum":3469221062,"timestamp":"2024-06-01T17:51:55.958264Z"}]}
{"channel":"book","type":"update","data":[{"symbol":"ETH/USD","bids":[],"asks":[{"price":3796.65,"qty":0.00000000},{"price":3797.21,"qty":3.00000000}],"checksum":888513877,"timestamp":"2024-06-01T17:51:55.964915Z"}]}
{"channel":"book","type":"update","data":[{"symbol":"ETH/USD","bids":[],"asks":[{"price":3796.68,"qty":0.00000000},{"price":3797.22,"qty":2.18000000}],"checksum":2847699574,"timestamp":"2024-06-01T17:51:55.964976Z"}]}
{"channel":"book","type":"update","data":[{"symbol":"ETH/USD","bids":[],"asks":[{"price":3796.73,"qty":26.33851627}],"checksum":2803502097,"timestamp":"2024-06-01T17:51:55.979948Z"}]}
{"channel":"book","type":"update","data":[{"symbol":"ETH/USD","bids":[],"asks":[{"price":3796.81,"qty":26.33793828}],"checksum":2443699684,"timestamp":"2024-06-01T17:51:55.980041Z"}]}
{"channel":"book","type":"update","data":[{"symbol":"ETH/USD","bids":[],"asks":[{"price":3796.73,"qty":0.00000000},{"price":3797.21,"qty":3.00000000}],"checksum":1110266449,"timestamp":"2024-06-01T17:51:55.984991Z"}]}
{"channel":"book","type":"update","data":[{"symbol":"ETH/USD","bids":[],"asks":[{"price":3796.74,"qty":26.33845182}],"checksum":726794898,"timestamp":"2024-06-01T17:51:56.162467Z"}]}
{"channel":"book","type":"update","data":[{"symbol":"ETH/USD","bids":[],"asks":[{"price":3796.82,"qty":0.77000000}],"checksum":2853559179,"timestamp":"2024-06-01T17:51:56.186022Z"}]}
{"channel":"book","type":"update","data":[{"symbol":"ETH/USD","bids":[],"asks":[{"price":3796.74,"qty":0.00000000},{"price":3797.20,"qty":26.33520687}],"checksum":1038612114,"timestamp":"2024-06-01T17:51:56.262181Z"}]}
{"channel":"book","type":"update","data":[{"symbol":"ETH/USD","bids":[],"asks":[{"price":3796.73,"qty":26.33848606}],"checksum":3414608080,"timestamp":"2024-06-01T17:51:56.266615Z"}]}
{"channel":"book","type":"update","data":[{"symbol":"ETH/USD","bids":[],"asks":[{"price":3796.82,"qty":0.00000000},{"price":3797.20,"qty":26.33520687},{"price":3796.64,"qty":0.77000000}],"checksum":3494249364,"timestamp":"2024-06-01T17:51:56.276920Z"}]}
{"channel":"book","type":"update","data":[{"symbol":"ETH/USD","bids":[{"price":3794.52,"qty":233.79647159}],"asks":[],"checksum":1698841217,"timestamp":"2024-06-01T17:51:56.278603Z"}]}
{"channel":"book","type":"update","data":[{"symbol":"ETH/USD","bids":[],"asks":[{"price":3796.64,"qty":1.54000000}],"checksum":2679601897,"timestamp":"2024-06-01T17:51:56.279475Z"}]}
{"channel":"book","type":"update","data":[{"symbol":"ETH/USD","bids":[],"asks":[{"price":3796.64,"qty":0.77000000}],"checksum":1698841217,"timestamp":"2024-06-01T17:51:56.279486Z"}]}
{"channel":"book","type":"update","data":[{"symbol":"ETH/USD","bids":[],"asks":[{"price":3796.73,"qty":0.00000000},{"price":3797.20,"qty":26.33520687}],"checksum":179281136,"timestamp":"2024-06-01T17:51:56.281350Z"}]}
{"channel":"book","type":"update","data":[{"symbol":"ETH/USD","bids":[],"asks":[{"price":3797.20,"qty":0.00000000},{"price":3797.21,"qty":3.00000000}],"checksum":4112705367,"timestamp":"2024-06-01T17:51:56.281368Z"}]}
{"channel":"book","type":"update","data":[{"symbol":"ETH/USD","bids":[],"asks":[{"price":3796.81,"qty":0.00000000},{"price":3797.22,"qty":2.18000000}],"checksum":3319941028,"timestamp":"2024-06-01T17:51:56.281472Z"}]}
{"channel":"book","type":"update","data":[{"symbol":"ETH/USD","bids":[],"asks":[{"price":3796.58,"qty":26.33952893}],"checksum":3287670876,"timestamp":"2024-06-01T17:51:56.292142Z"}]}
{"channel":"book","type":"update","data":[{"symbol":"ETH/USD","bids":[],"asks":[{"price":3796.47,"qty":26.34030019}],"checksum":4224328729,"timestamp":"2024-06-01T17:51:56.302688Z"}]}
{"channel":"book","type":"update","data":[{"symbol":"ETH/USD","bids":[{"price":3794.52,"qty":230.39271213}],"asks":[],"checksum":1112904626,"timestamp":"2024-06-01T17:51:56.306627Z"}]}
{"channel":"book","type":"update","data":[{"symbol":"ETH/USD","bids":[],"asks":[{"price":3796.47,"qty":0.00000000},{"price":3797.21,"qty":3.00000000}],"checksum":2053789687,"timestamp":"2024-06-01T17:51:56.314347Z"}]}
{"channel":"book","type":"update","data":[{"symbol":"ETH/USD","bids":[],"asks":[{"price":3796.64,"qty":0.00000000},{"price":3797.22,"qty":2.18000000},{"price":3796.49,"qty":0.77000000}],"checksum":1698264467,"timestamp":"2024-06-01T17:51:56.316797Z"}]}
{"channel":"book","type":"update","data":[{"symbol":"ETH/USD","bids":[],"asks":[{"price":3796.32,"qty":26.34134039}],"checksum":2649570853,"timestamp":"2024-06-01T17:51:56.318623Z"}]}
{"channel":"book","type":"update","data":[{"symbol":"ETH/USD","bids":[],"asks":[{"price":3796.49,"qty":1.54000000}],"checksum":4190873427,"timestamp":"2024-06-01T17:51:56.319800Z"}]}
{"channel":"book","type":"update","data":[{"symbol":"ETH/USD","bids":[],"asks":[{"price":3796.43,"qty":3.00000000}],"checksum":1512593383,"timestamp":"2024-06-01T17:51:56.322418Z"}]}
{"channel":"book","type":"update","data":[{"symbol":"ETH/USD","bids":[{"price":3794.16,"qty":0.00000000},{"price":3794.14,"qty":3.00000000}],"asks":[],"checksum":3105529638,"timestamp":"2024-06-01T17:51:56.344142Z"}]}
{"channel":"book","type":"update","data":[{"symbol":"ETH/USD","bids":[{"price":3794.52,"qty":232.54571213}],"asks":[],"checksum":4098162405,"timestamp":"2024-06-01T17:51:56.377480Z"}]}
{"channel":"book","type":"update","data":[{"symbol":"ETH/USD","bids":[],"asks":[{"price":3796.32,"qty":0.00000000},{"price":3797.11,"qty":10.81226191}],"checksum":3445878477,"timestamp":"2024-06-01T17:51:56.379279Z"}]}
{"channel":"book","type":"update","data":[{"symbol":"ETH/USD","bids":[],"asks":[{"price":3796.34,"qty":26.34118772}],"checksum":3902602241,"timestamp":"2024-06-01T17:51:56.383707Z"}]}
{"channel":"book","type":"update","data":[{"symbol":"ETH/USD","bids":[],"asks":[{"price":3796.34,"qty":0.00000000},{"price":3797.11,"qty":10.81226191}],"checksum":3445878477,"timestamp":"2024-06-01T17:51:56.388119Z"}]}
{"channel":"book","type":"update","data":[{"symbol":"ETH/USD","bids":[{"price":3794.52,"qty":235.94947159}],"asks":[],"checksum":2843475042,"timestamp":"2024-06-01T17:51:56.428377Z"}]}
{"channel":"book","type":"update","data":[{"symbol":"ETH/USD","bids":[],"asks":[{"price":3796.49,"qty":0.77000000}],"checksum":3052550457,"timestamp":"2024-06-01T17:51:56.487530Z"}]}
{"channel":"book","type":"update","data":[{"symbol":"ETH/USD","bids":[{"price":3794.52,"qty":235.68600516}],"asks":[],"checksum":3965623599,"timestamp":"2024-06-01T17:51:56.643570Z"}]}
{"channel":"book","type":"update","data":[{"symbol":"ETH/USD","bids":[{"price":3794.44,"qty":0.00000000},{"price":3794.08,"qty":0.06693358}],"asks":[],"checksum":746759208,"timestamp":"2024-06-01T17:51:56.643796Z"}]}
{"channel":"book","type":"update","data":[{"symbol":"ETH/USD","bids":[],"asks":[{"price":3796.31,"qty":26.34140710}],"checksum":3064422568,"timestamp":"2024-06-01T17:51:56.749037Z"}]}
{"channel":"book","type":"update","data":[{"symbol":"ETH/USD","bids":[{"price":3794.52,"qty":219.87801949}],"asks":[],"checksum":2729275487,"timestamp":"2024-06-01T17:51:56.752644Z"}]}
{"channel":"book","type":"update","data":[{"symbol":"ETH/USD","bids":[],"asks":[{"price":3796.31,"qty":0.00000000},{"price":3797.11,"qty":10.81226191}],"checksum":948483295,"timestamp":"2024-06-01T17:51:56.781078Z"}]}
{"channel":"book","type":"update","data":[{"symbol":"ETH/USD","bids":[],"asks":[{"price":3796.66,"qty":0.00000000},{"price":3797.21,"qty":3.00000000},{"price":3796.95,"qty":4.30610000}],"checksum":390795167,"timestamp":"2024-06-01T17:51:56.785356Z"}]}
{"channel":"book","type":"update","data":[{"symbol":"ETH/USD","bids":[],"asks":[{"price":3796.28,"qty":26.34160730}],"checksum":1917179162,"timestamp":"2024-06-01T17:51:56.803201Z"}]}
{"channel":"book","type":"update","data":[{"symbol":"ETH/USD","bids":[],"asks":[{"price":3796.28,"qty":0.00000000},{"price":3797.11,"qty":10.81226191}],"checksum":390795167,"timestamp":"2024-06-01T17:51:56.841337Z"}]}
{"channel":"book","type":"update","data":[{"symbol":"ETH/USD","bids":[],"asks":[{"price":3796.49,"qty":0.00000000},{"price":3797.21,"qty":3.00000000}],"checksum":2826902569,"timestamp":"2024-06-01T17:51:56.924980Z"}]}
{"channel":"book","type":"update","data":[{"symbol":"ETH/USD","bids":[],"asks":[{"price":3796.33,"qty":26.34125379}],"checksum":2938249706,"timestamp":"2024-06-01T17:51:56.938759Z"}]}
{"channel":"book","type":"update","data":[{"symbol":"ETH/USD","bids":[],"asks":[{"price":3796.33,"qty":0.00000000},{"price":3797.21,"qty":3.00000000}],"checksum":2826902569,"timestamp":"2024-06-01T17:51:56.951591Z"}]}
{"channel":"book","type":"update","data":[{"symbol":"ETH/USD","bids":[],"asks":[{"price":3796.44,"qty":26.34046895}],"checksum":3901946506,"timestamp":"2024-06-01T17:51:56.956810Z"}]}
{"channel":"book","type":"update","data":[{"symbol":"ETH/USD","bids":[],"asks":[{"price":3796.37,"qty":26.34098044}],"checksum":3057597417,"timestamp":"2024-06-01T17:51:56.990753Z"}]}
{"channel":"book","type":"update","data":[{"symbol":"ETH/USD","bids":[],"asks":[{"price":3796.95,"qty":0.00000000},{"price":3797.11,"qty":10.81226191}],"checksum":2851281774,"timestamp":"2024-06-01T17:51:56.994086Z"}]}
{"channel":"book","type":"update","data":[{"symbol":"ETH/USD","bids":[],"asks":[{"price":3796.37,"qty":0.00000000},{"price":3797.21,"qty":3.00000000}],"checksum":3455281077,"timestamp":"2024-06-01T17:51:57.051501Z"}]}
{"channel":"book","type":"update","data":[{"symbol":"ETH/USD","bids":[],"asks":[{"price":3796.36,"qty":26.34104893}],"checksum":81607385,"timestamp":"2024-06-01T17:51:57.056910Z"}]}
{"channel":"book","type":"update","data":[{"symbol":"ETH/USD","bids":[],"asks":[{"price":3796.36,"qty":0.00000000},{"price":3797.21,"qty":3.00000000}],"checksum":3455281077,"timestamp":"2024-06-01T17:51:57.119256Z"}]}
{"channel":"book","type":"update","data":[{"symbol":"ETH/USD","bids":[],"asks":[{"price":3796.35,"qty":26.86813172}],"checksum":2024100478,"timestamp":"2024-06-01T17:51:57.123517Z"}]}
{"channel":"book","type":"update","data":[{"symbol":"ETH/USD","bids":[],"asks":[{"price":3796.48,"qty":0.77000000}],"checksum":564390825,"timestamp":"2024-06-01T17:51:57.186599Z"}]}
{"channel":"book","type":"update","data":[{"symbol":"ETH/USD","bids":[],"asks":[{"price":3796.35,"qty":0.52698006}],"checksum":2807632148,"timestamp":"2024-06-01T17:51:57.193273Z"}]}
{"channel":"book","type":"update","data":[{"symbol":"ETH/USD","bids":[],"asks":[{"price":3796.33,"qty":26.34128864}],"checksum":2644464399,"timestamp":"2024-06-01T17:51:57.198461Z"}]}
{"channel":"book","type":"update","data":[{"symbol":"ETH/USD","bids":[],"asks":[{"price":3796.33,"qty":0.00000000},{"price":3797.11,"qty":10.81226191}],"checksum":2807632148,"timestamp":"2024-06-01T17:51:57.238791Z"}]}
{"channel":"book","type":"update","data":[{"symbol":"ETH/USD","bids":[],"asks":[{"price":3796.32,"qty":26.34134396}],"checksum":4133950961,"timestamp":"2024-06-01T17:51:57.249111Z"}]}
{"channel":"book","type":"update","data":[{"symbol":"ETH/USD","bids":[],"asks":[{"price":3796.32,"qty":0.00000000},{"price":3797.11,"qty":10.81226191}],"checksum":2807632148,"timestamp":"2024-06-01T17:51:57.452009Z"}]}
{"channel":"book","type":"update","data":[{"symbol":"ETH/USD","bids":[],"asks":[{"price":3796.34,"qty":26.34117274}],"checksum":3234194989,"timestamp":"2024-06-01T17:51:57.456378Z"}]}
{"channel":"book","type":"update","data":[{"symbol":"ETH/USD","bids":[],"asks":[{"price":3796.44,"qty":0.00000000},{"price":3797.11,"qty":10.81226191}],"checksum":1479266988,"timestamp":"2024-06-01T17:51:57.483836Z"}]}
{"channel":"book","type":"update","data":[{"symbol":"ETH/USD","bids":[],"asks":[{"price":3796.43,"qty":29.34053938}],"checksum":462288181,"timestamp":"2024-06-01T17:51:57.613136Z"}]}
{"channel":"book","type":"update","data":[{"symbol":"ETH/USD","bids":[],"asks":[{"price":3796.34,"qty":0.00000000},{"price":3797.21,"qty":3.00000000}],"checksum":4114569354,"timestamp":"2024-06-01T17:51:57.689714Z"}]}
{"channel":"book","type":"update","data":[{"symbol":"ETH/USD","bids":[],"asks":[{"price":3796.32,"qty":26.34132723}],"checksum":2712043813,"timestamp":"2024-06-01T17:51:57.694302Z"}]}
{"channel":"book","type":"update","data":[{"symbol":"ETH/USD","bids":[],"asks":[{"price":3796.32,"qty":0.00000000},{"price":3797.21,"qty":3.00000000}],"checksum":4114569354,"timestamp":"2024-06-01T17:51:57.951952Z"}]}
{"channel":"book","type":"update","data":[{"symbol":"ETH/USD","bids":[],"asks":[{"price":3796.31,"qty":26.34142938}],"checksum":2199754497,"timestamp":"2024-06-01T17:51:57.956053Z"}]}
{"channel":"book","type":"update","data":[{"symbol":"ETH/USD","bids":[],"asks":[{"price":3796.31,"qty":0.00000000},{"price":3797.21,"qty":3.00000000}],"checksum":4114569354,"timestamp":"2024-06-01T17:51:57.980365Z"}]}
{"channel":"book","type":"update","data":[{"symbol":"ETH/USD","bids":[],"asks":[{"price":3796.48,"qty":0.00000000},{"price":3797.22,"qty":2.18000000},{"price":3796.39,"qty":0.77000000}],"checksum":78683143,"timestamp":"2024-06-01T17:51:58.278388Z"}]}
{"channel":"book","type":"update","data":[{"symbol":"ETH/USD","bids":[],"asks":[{"price":3796.39,"qty":1.54000000}],"checksum":468199618,"timestamp":"2024-06-01T17:51:58.281569Z"}]}
{"channel":"book","type":"update","data":[{"symbol":"ETH/USD","bids":[],"asks":[{"price":3796.43,"qty":3.00000000}],"checksum":2039371081,"timestamp":"2024-06-01T17:51:58.364062Z"}]}
{"channel":"book","type":"update","data":[{"symbol":"ETH/USD","bids":[],"asks":[{"price":3796.28,"qty":26.34158775}],"checksum":1123337516,"timestamp":"2024-06-01T17:51:58.368545Z"}]}
{"channel":"book","type":"update","data":[{"symbol":"ETH/USD","bids":[],"asks":[{"price":3796.39,"qty":0.77000000}],"checksum":3142357253,"timestamp":"2024-06-01T17:51:59.171169Z"}]}
{"channel":"book","type":"update","data":[{"symbol":"ETH/USD","bids":[],"asks":[{"price":3796.39,"qty":0.00000000},{"price":3797.21,"qty":3.00000000}],"checksum":815163487,"timestamp":"2024-06-01T17:51:59.174171Z"}]}
{"channel":"book","type":"update","data":[{"symbol":"ETH/USD","bids":[],"asks":[{"price":3796.28,"qty":0.00000000},{"price":3797.22,"qty":2.18000000}],"checksum":940449975,"timestamp":"2024-06-01T17:51:59.178118Z"}]}
{"channel":"book","type":"update","data":[{"symbol":"ETH/USD","bids":[],"asks":[{"price":3796.95,"qty":4.30610000}],"checksum":2826902569,"timestamp":"2024-06-01T17:51:59.181606Z"}]}
{"channel":"book","type":"update","data":[{"symbol":"ETH/USD","bids":[],"asks":[{"price":3796.30,"qty":26.34147943}],"checksum":2742542832,"timestamp":"2024-06-01T17:51:59.182990Z"}]}
{"channel":"book","type":"update","data":[{"symbol":"ETH/USD","bids":[],"asks":[{"price":3796.44,"qty":0.77000000}],"checksum":3543951408,"timestamp":"2024-06-01T17:51:59.278065Z"}]}
{"channel":"book","type":"update","data":[{"symbol":"ETH/USD","bids":[],"asks":[{"price":3796.30,"qty":0.00000000},{"price":3797.11,"qty":10.81226191}],"checksum":2350315230,"timestamp":"2024-06-01T17:51:59.486744Z"}]}
{"channel":"book","type":"update","data":[{"symbol":"ETH/USD","bids":[],"asks":[{"price":3796.42,"qty":26.34067102}],"checksum":3515337359,"timestamp":"2024-06-01T17:51:59.490960Z"}]}
{"channel":"book","type":"update","data":[{"symbol":"ETH/USD","bids":[],"asks":[{"price":3796.32,"qty":26.34132535}],"checksum":1810472059,"timestamp":"2024-06-01T17:51:59.491024Z"}]}
{"channel":"book","type":"update","data":[{"symbol":"ETH/USD","bids":[{"price":3794.52,"qty":219.87269342}],"asks":[],"checksum":1753888187,"timestamp":"2024-06-01T17:51:59.722166Z"}]}
{"channel":"book","type":"update","data":[{"symbol":"ETH/USD","bids":[],"asks":[{"price":3796.95,"qty":0.00000000},{"price":3796.96,"qty":26.33688372}],"checksum":1978498026,"timestamp":"2024-06-01T17:51:59.810694Z"}]}
{"channel":"book","type":"update","data":[{"symbol":"ETH/USD","bids":[],"asks":[{"price":3796.44,"qty":0.00000000},{"price":3797.11,"qty":10.81226191},{"price":3796.60,"qty":0.77000000}],"checksum":2944389149,"timestamp":"2024-06-01T17:52:00.005601Z"}]}
{"channel":"book","type":"update","data":[{"symbol":"ETH/USD","bids":[],"asks":[{"price":3796.32,"qty":0.00000000},{"price":3797.11,"qty":10.81226191}],"checksum":4293026578,"timestamp":"2024-06-01T17:52:00.008105Z"}]}
{"channel":"book","type":"update","data":[{"symbol":"ETH/USD","bids":[],"asks":[{"price":3796.60,"qty":1.54000000}],"checksum":1942751931,"timestamp":"2024-06-01T17:52:00.008603Z"}]}
{"channel":"book","type":"update","data":[{"symbol":"ETH/USD","bids":[],"asks":[{"price":3796.31,"qty":26.34142956}],"checksum":2565996821,"timestamp":"2024-06-01T17:52:00.012405Z"}]}
{"channel":"book","type":"update","data":[{"symbol":"ETH/USD","bids":[],"asks":[{"price":3796.60,"qty":0.77000000}],"checksum":1796505105,"timestamp":"2024-06-01T17:52:00.046184Z"}]}
{"channel":"book","type":"update","data":[{"symbol":"ETH/USD","bids":[],"asks":[{"price":3796.31,"qty":0.00000000},{"price":3797.11,"qty":10.81226191}],"checksum":4293026578,"timestamp":"2024-06-01T17:52:00.139030Z"}]}
{"channel":"book","type":"update","data":[{"symbol":"ETH/USD","bids":[],"asks":[{"price":3796.30,"qty":26.34147378}],"checksum":2871484778,"timestamp":"2024-06-01T17:52:00.144176Z"}]}
{"channel":"book","type":"update","data":[{"symbol":"ETH/USD","bids":[],"asks":[{"price":3796.30,"qty":0.00000000},{"price":3797.11,"qty":10.81226191}],"checksum":4293026578,"timestamp":"2024-06-01T17:52:00.304728Z"}]}
{"channel":"book","type":"update","data":[{"symbol":"ETH/USD","bids":[],"asks":[{"price":3796.32,"qty":26.34133784}],"checksum":1808135124,"timestamp":"2024-06-01T17:52:00.309001Z"}]}
{"channel":"book","type":"update","data":[{"symbol":"ETH/USD","bids":[],"asks":[{"price":3796.32,"qty":0.00000000},{"price":3797.11,"qty":10.81226191}],"checksum":4293026578,"timestamp":"2024-06-01T17:52:00.371845Z"}]}
{"channel":"book","type":"update","data":[{"symbol":"ETH/USD","bids":[],"asks":[{"price":3796.34,"qty":26.34116662}],"checksum":1720590071,"timestamp":"2024-06-01T17:52:00.376167Z"}]}
{"channel":"book","type":"update","data":[{"symbol":"ETH/USD","bids":[],"asks":[{"price":3796.34,"qty":0.00000000},{"price":3797.11,"qty":10.81226191}],"checksum":4293026578,"timestamp":"2024-06-01T17:52:00.441009Z"}]}
{"channel":"book","type":"update","data":[{"symbol":"ETH/USD","bids":[],"asks":[{"price":3796.42,"qty":0.00000000},{"price":3797.21,"qty":3.00000000}],"checksum":3645532047,"timestamp":"2024-06-01T17:52:00.451158Z"}]}
{"channel":"book","type":"update","data":[{"symbol":"ETH/USD","bids":[],"asks":[{"price":3796.36,"qty":26.34103227}],"checksum":2859019068,"timestamp":"2024-06-01T17:52:00.451230Z"}]}
{"channel":"book","type":"update","data":[{"symbol":"ETH/USD","bids":[],"asks":[{"price":3796.36,"qty":0.00000000},{"price":3797.21,"qty":3.00000000}],"checksum":3645532047,"timestamp":"2024-06-01T17:52:00.456132Z"}]}
{"channel":"book","type":"update","data":[{"symbol":"ETH/USD","bids":[],"asks":[{"price":3796.72,"qty":26.33855996}],"checksum":310261360,"timestamp":"2024-06-01T17:52:00.460005Z"}]}
{"channel":"book","type":"update","data":[{"symbol":"ETH/USD","bids":[],"asks":[{"price":3796.58,"qty":0.00000000},{"price":3797.21,"qty":3.00000000}],"checksum":2856119372,"timestamp":"2024-06-01T17:52:00.504006Z"}]}
{"channel":"book","type":"update","data":[{"symbol":"ETH/USD","bids":[],"asks":[{"price":3796.44,"qty":26.34050548}],"checksum":1906021966,"timestamp":"2024-06-01T17:52:00.508326Z"}]}
{"channel":"book","type":"update","data":[{"symbol":"ETH/USD","bids":[],"asks":[{"price":3796.44,"qty":0.00000000},{"price":3797.21,"qty":3.00000000}],"checksum":2856119372,"timestamp":"2024-06-01T17:52:00.540653Z"}]}
{"channel":"book","type":"update","data":[{"symbol":"ETH/USD","bids":[],"asks":[{"price":3796.42,"qty":26.34065826}],"checksum":556869504,"timestamp":"2024-06-01T17:52:00.589842Z"}]}
{"channel":"book","type":"update","data":[{"symbol":"ETH/USD","bids":[],"asks":[{"price":3796.42,"qty":0.00000000},{"price":3797.21,"qty":3.00000000}],"checksum":2856119372,"timestamp":"2024-06-01T17:52:00.669590Z"}]}
{"channel":"book","type":"update","data":[{"symbol":"ETH/USD","bids":[],"asks":[{"price":3796.40,"qty":26.34078206}],"checksum":3493168549,"timestamp":"2024-06-01T17:52:00.673403Z"}]}
{"channel":"book","type":"update","data":[{"symbol":"ETH/USD","bids":[],"asks":[{"price":3796.40,"qty":0.00000000},{"price":3797.21,"qty":3.00000000}],"checksum":2856119372,"timestamp":"2024-06-01T17:52:01.029293Z"}]}
{"channel":"book","type":"update","data":[{"symbol":"ETH/USD","bids":[],"asks":[{"price":3796.71,"qty":4.30610000}],"checksum":3800066792,"timestamp":"2024-06-01T17:52:01.032732Z"}]}
{"channel":"book","type":"update","data":[{"symbol":"ETH/USD","bids":[],"asks":[{"price":3796.38,"qty":26.34091377}],"checksum":2732593115,"timestamp":"2024-06-01T17:52:01.033784Z"}]}
{"channel":"book","type":"update","data":[{"symbol":"ETH/USD","bids":[],"asks":[{"price":3796.38,"qty":0.00000000},{"price":3797.11,"qty":10.81226191}],"checksum":3800066792,"timestamp":"2024-06-01T17:52:01.175327Z"}]}
{"channel":"book","type":"update","data":[{"symbol":"ETH/USD","bids":[],"asks":[{"price":3796.33,"qty":26.34123577}],"checksum":1959860042,"timestamp":"2024-06-01T17:52:01.182708Z"}]}
{"channel":"book","type":"update","data":[{"symbol":"ETH/USD","bids":[],"asks":[{"price":3796.33,"qty":0.00000000},{"price":3797.11,"qty":10.81226191}],"checksum":3800066792,"timestamp":"2024-06-01T17:52:01.271108Z"}]}
{"channel":"book","type":"update","data":[{"symbol":"ETH/USD","bids":[],"asks":[{"price":3796.36,"qty":26.34106191}],"checksum":1312272620,"timestamp":"2024-06-01T17:52:01.275546Z"}]}
{"channel":"book","type":"update","data":[{"symbol":"ETH/USD","bids":[],"asks":[{"price":3796.36,"qty":0.00000000},{"price":3797.11,"qty":10.81226191}],"checksum":3800066792,"timestamp":"2024-06-01T17:52:01.322564Z"}]}
{"channel":"book","type":"update","data":[{"symbol":"ETH/USD","bids":[],"asks":[{"price":3796.34,"qty":26.34117782}],"checksum":3070801332,"timestamp":"2024-06-01T17:52:01.326845Z"}]}
{"channel":"book","type":"update","data":[{"symbol":"ETH/USD","bids":[],"asks":[{"price":3796.34,"qty":0.00000000},{"price":3797.11,"qty":10.81226191}],"checksum":3800066792,"timestamp":"2024-06-01T17:52:01.473856Z"}]}
{"channel":"book","type":"update","data":[{"symbol":"ETH/USD","bids":[],"asks":[{"price":3796.37,"qty":26.34097235}],"checksum":2574857528,"timestamp":"2024-06-01T17:52:01.477953Z"}]}
{"channel":"book","type":"update","data":[{"symbol":"ETH/USD","bids":[],"asks":[{"price":3796.37,"qty":0.00000000},{"price":3797.11,"qty":10.81226191}],"checksum":3800066792,"timestamp":"2024-06-01T17:52:01.820856Z"}]}
{"channel":"book","type":"update","data":[{"symbol":"ETH/USD","bids":[],"asks":[{"price":3796.72,"qty":0.00000000},{"price":3797.21,"qty":3.00000000}],"checksum":679852831,"timestamp":"2024-06-01T17:52:01.826526Z"}]}
{"channel":"book","type":"update","data":[{"symbol":"ETH/USD","bids":[],"asks":[{"price":3796.71,"qty":0.00000000},{"price":3797.22,"qty":2.18000000}],"checksum":4103050761,"timestamp":"2024-06-01T17:52:01.830071Z"}]}
{"channel":"book","type":"update","data":[{"symbol":"ETH/USD","bids":[],"asks":[{"price":3796.60,"qty":27.10941663}],"checksum":2633196726,"timestamp":"2024-06-01T17:52:01.830846Z"}]}
{"channel":"book","type":"update","data":[{"symbol":"ETH/USD","bids":[],"asks":[{"price":3796.33,"qty":26.34129635}],"checksum":1148628992,"timestamp":"2024-06-01T17:52:01.830931Z"}]}
{"channel":"book","type":"update","data":[{"symbol":"ETH/USD","bids":[],"asks":[{"price":3796.31,"qty":26.34137123}],"checksum":2148983929,"timestamp":"2024-06-01T17:52:02.055786Z"}]}
{"channel":"book","type":"update","data":[{"symbol":"ETH/USD","bids":[],"asks":[{"price":3796.31,"qty":0.00000000},{"price":3797.21,"qty":3.00000000}],"checksum":1148628992,"timestamp":"2024-06-01T17:52:02.186775Z"}]}
{"channel":"book","type":"update","data":[{"symbol":"ETH/USD","bids":[],"asks":[{"price":3796.29,"qty":26.34152703}],"checksum":3542362276,"timestamp":"2024-06-01T17:52:02.191350Z"}]}
{"channel":"book","type":"update","data":[{"symbol":"ETH/USD","bids":[],"asks":[{"price":3796.29,"qty":0.00000000},{"price":3797.21,"qty":3.00000000}],"checksum":1148628992,"timestamp":"2024-06-01T17:52:02.223292Z"}]}
{"channel":"book","type":"update","data":[{"symbol":"ETH/USD","bids":[],"asks":[{"price":3796.36,"qty":26.34107394}],"checksum":2169447475,"timestamp":"2024-06-01T17:52:02.264779Z"}]}
{"channel":"book","type":"update","data":[{"symbol":"ETH/USD","bids":[],"asks":[{"price":3796.33,"qty":0.00000000},{"price":3797.21,"qty":3.00000000}],"checksum":924062807,"timestamp":"2024-06-01T17:52:02.288120Z"}]}
{"channel":"book","type":"update","data":[{"symbol":"ETH/USD","bids":[],"asks":[{"price":3796.45,"qty":26.34045512}],"checksum":769194123,"timestamp":"2024-06-01T17:52:02.292354Z"}]}
{"channel":"book","type":"update","data":[{"symbol":"ETH/USD","bids":[],"asks":[{"price":3796.60,"qty":26.33941663}],"checksum":537763476,"timestamp":"2024-06-01T17:52:02.316668Z"}]}
{"channel":"book","type":"update","data":[{"symbol":"ETH/USD","bids":[],"asks":[{"price":3796.36,"qty":0.00000000},{"price":3797.21,"qty":3.00000000}],"checksum":3176446123,"timestamp":"2024-06-01T17:52:02.323478Z"}]}
{"channel":"book","type":"update","data":[{"symbol":"ETH/USD","bids":[],"asks":[{"price":3796.42,"qty":26.34064333}],"checksum":1530380447,"timestamp":"2024-06-01T17:52:02.327882Z"}]}
{"channel":"book","type":"update","data":[{"symbol":"ETH/USD","bids":[],"asks":[{"price":3796.42,"qty":0.00000000},{"price":3797.21,"qty":3.00000000}],"checksum":3176446123,"timestamp":"2024-06-01T17:52:02.502427Z"}]}
{"channel":"book","type":"update","data":[{"symbol":"ETH/USD","bids":[],"asks":[{"price":3796.41,"qty":26.34074079}],"checksum":3554749546,"timestamp":"2024-06-01T17:52:02.508206Z"}]}
{"channel":"book","type":"update","data":[{"symbol":"ETH/USD","bids":[],"asks":[{"price":3796.60,"qty":27.10941663}],"checksum":3727968885,"timestamp":"2024-06-01T17:52:02.513756Z"}]}
{"channel":"book","type":"update","data":[{"symbol":"ETH/USD","bids":[],"asks":[{"price":3796.41,"qty":0.00000000},{"price":3797.21,"qty":3.00000000}],"checksum":4089544829,"timestamp":"2024-06-01T17:52:02.561473Z"}]}
{"channel":"book","type":"update","data":[{"symbol":"ETH/USD","bids":[],"asks":[{"price":3796.40,"qty":26.34077504}],"checksum":1056578633,"timestamp":"2024-06-01T17:52:02.565529Z"}]}
{"channel":"book","type":"update","data":[{"symbol":"ETH/USD","bids":[],"asks":[{"price":3796.40,"qty":0.00000000},{"price":3797.21,"qty":3.00000000}],"checksum":4089544829,"timestamp":"2024-06-01T17:52:02.577336Z"}]}
{"channel":"book","type":"update","data":[{"symbol":"ETH/USD","bids":[],"asks":[{"price":3796.41,"qty":26.34070655}],"checksum":4020986145,"timestamp":"2024-06-01T17:52:02.730721Z"}]}
{"channel":"book","type":"update","data":[{"symbol":"ETH/USD","bids":[],"asks":[{"price":3796.40,"qty":4.30610000}],"checksum":1935588776,"timestamp":"2024-06-01T17:52:02.796059Z"}]}
{"channel":"book","type":"update","data":[{"symbol":"ETH/USD","bids":[],"asks":[{"price":3796.41,"qty":0.00000000},{"price":3797.11,"qty":10.81226191}],"checksum":573545510,"timestamp":"2024-06-01T17:52:02.956149Z"}]}
{"channel":"book","type":"update","data":[{"symbol":"ETH/USD","bids":[],"asks":[{"price":3796.39,"qty":26.34085406}],"checksum":138928299,"timestamp":"2024-06-01T17:52:02.960835Z"}]}
{"channel":"book","type":"update","data":[{"symbol":"ETH/USD","bids":[],"asks":[{"price":3796.40,"qty":0.00000000},{"price":3797.11,"qty":10.81226191},{"price":3796.38,"qty":4.30610000}],"checksum":1073270320,"timestamp":"2024-06-01T17:52:02.965132Z"}]}
{"channel":"book","type":"update","data":[{"symbol":"ETH/USD","bids":[],"asks":[{"price":3796.39,"qty":0.00000000},{"price":3797.11,"qty":10.81226191}],"checksum":4081339917,"timestamp":"2024-06-01T17:52:03.010495Z"}]}
{"channel":"book","type":"update","data":[{"symbol":"ETH/USD","bids":[],"asks":[{"price":3796.60,"qty":26.33941663}],"checksum":4270925842,"timestamp":"2024-06-01T17:52:03.013917Z"}]}
{"channel":"book","type":"update","data":[{"symbol":"ETH/USD","bids":[],"asks":[{"price":3796.73,"qty":26.33852102}],"checksum":2222122357,"timestamp":"2024-06-01T17:52:03.015024Z"}]}
{"channel":"book","type":"update","data":[{"symbol":"ETH/USD","bids":[],"asks":[{"price":3796.45,"qty":0.00000000},{"price":3797.11,"qty":10.81226191}],"checksum":606451800,"timestamp":"2024-06-01T17:52:03.112486Z"}]}
{"channel":"book","type":"update","data":[{"symbol":"ETH/USD","bids":[],"asks":[{"price":3796.53,"qty":26.33988630}],"checksum":1532846361,"timestamp":"2024-06-01T17:52:03.116923Z"}]}
{"channel":"book","type":"update","data":[{"symbol":"ETH/USD","bids":[],"asks":[{"price":3796.53,"qty":0.00000000},{"price":3797.11,"qty":10.81226191}],"checksum":606451800,"timestamp":"2024-06-01T17:52:03.127666Z"}]}
{"channel":"book","type":"update","data":[{"symbol":"ETH/USD","bids":[],"asks":[{"price":3796.60,"qty":0.00000000},{"price":3797.21,"qty":3.00000000}],"checksum":2161716225,"timestamp":"2024-06-01T17:52:03.134153Z"}]}
{"channel":"book","type":"update","data":[{"symbol":"ETH/USD","bids":[],"asks":[{"price":3796.69,"qty":0.77000000}],"checksum":1152773153,"timestamp":"2024-06-01T17:52:03.154566Z"}]}
{"channel":"book","type":"update","data":[{"symbol":"ETH/USD","bids":[],"asks":[{"price":3796.51,"qty":26.34000665}],"checksum":314273080,"timestamp":"2024-06-01T17:52:03.392231Z"}]}
{"channel":"book","type":"update","data":[{"symbol":"ETH/USD","bids":[],"asks":[{"price":3796.51,"qty":0.00000000},{"price":3797.11,"qty":10.81226191}],"checksum":1152773153,"timestamp":"2024-06-01T17:52:03.488668Z"}]}
{"channel":"book","type":"update","data":[{"symbol":"ETH/USD","bids":[],"asks":[{"price":3796.50,"qty":26.34011201}],"checksum":568653478,"timestamp":"2024-06-01T17:52:03.493086Z"}]}
{"channel":"book","type":"update","data":[{"symbol":"ETH/USD","bids":[],"asks":[{"price":3796.50,"qty":0.00000000},{"price":3797.11,"qty":10.81226191}],"checksum":1152773153,"timestamp":"2024-06-01T17:52:03.689105Z"}]}
{"channel":"book","type":"update","data":[{"symbol":"ETH/USD","bids":[],"asks":[{"price":3796.62,"qty":26.33927656}],"checksum":131589179,"timestamp":"2024-06-01T17:52:03.693657Z"}]}
{"channel":"book","type":"update","data":[{"symbol":"ETH/USD","bids":[],"asks":[{"price":3796.52,"qty":26.33993899}],"checksum":2148914654,"timestamp":"2024-06-01T17:52:03.693782Z"}]}
{"channel":"book","type":"update","data":[{"symbol":"ETH/USD","bids":[],"asks":[{"price":3796.73,"qty":0.00000000},{"price":3796.96,"qty":26.33688372}],"checksum":222553598,"timestamp":"2024-06-01T17:52:03.772646Z"}]}
{"channel":"book","type":"update","data":[{"symbol":"ETH/USD","bids":[],"asks":[{"price":3796.52,"qty":0.00000000},{"price":3797.11,"qty":10.81226191}],"checksum":2100570460,"timestamp":"2024-06-01T17:52:03.772720Z"}]}
{"channel":"book","type":"update","data":[{"symbol":"ETH/USD","bids":[],"asks":[{"price":3796.38,"qty":0.00000000},{"price":3797.21,"qty":3.00000000},{"price":3796.51,"qty":4.30610000}],"checksum":2649233476,"timestamp":"2024-06-01T17:52:03.776171Z"}]}
{"channel":"book","type":"update","data":[{"symbol":"ETH/USD","bids":[],"asks":[{"price":3796.58,"qty":26.33953372}],"checksum":1372731773,"timestamp":"2024-06-01T17:52:03.777347Z"}]}
{"channel":"book","type":"update","data":[{"symbol":"ETH/USD","bids":[],"asks":[{"price":3796.96,"qty":0.00000000},{"price":3797.11,"qty":10.81226191}],"checksum":3357993972,"timestamp":"2024-06-01T17:52:03.831102Z"}]}
{"channel":"book","type":"update","data":[{"symbol":"ETH/USD","bids":[],"asks":[{"price":3796.58,"qty":0.00000000},{"price":3797.14,"qty":26.33567838}],"checksum":138620801,"timestamp":"2024-06-01T17:52:03.831190Z"}]}
{"channel":"book","type":"update","data":[{"symbol":"ETH/USD","bids":[],"asks":[{"price":3796.84,"qty":26.33771296}],"checksum":652825438,"timestamp":"2024-06-01T17:52:03.835964Z"}]}
{"channel":"book","type":"update","data":[{"symbol":"ETH/USD","bids":[],"asks":[{"price":3796.57,"qty":26.33959957}],"checksum":1563020922,"timestamp":"2024-06-01T17:52:03.836119Z"}]}
{"channel":"book","type":"update","data":[{"symbol":"ETH/USD","bids":[],"asks":[{"price":3796.57,"qty":0.00000000},{"price":3797.11,"qty":10.81226191}],"checksum":652825438,"timestamp":"2024-06-01T17:52:03.882297Z"}]}
{"channel":"book","type":"update","data":[{"symbol":"ETH/USD","bids":[],"asks":[{"price":3796.56,"qty":26.33968123}],"checksum":1772481522,"timestamp":"2024-06-01T17:52:03.889194Z"}]}
{"channel":"book","type":"update","data":[{"symbol":"ETH/USD","bids":[],"asks":[{"price":3796.62,"qty":0.00000000},{"price":3797.11,"qty":10.81226191}],"checksum":4232226742,"timestamp":"2024-06-01T17:52:03.928479Z"}]}
{"channel":"book","type":"update","data":[{"symbol":"ETH/USD","bids":[],"asks":[{"price":3796.49,"qty":26.34014353}],"checksum":1361273109,"timestamp":"2024-06-01T17:52:04.004065Z"}]}
{"channel":"book","type":"update","data":[{"symbol":"ETH/USD","bids":[],"asks":[{"price":3796.49,"qty":0.00000000},{"price":3797.11,"qty":10.81226191}],"checksum":4232226742,"timestamp":"2024-06-01T17:52:04.048206Z"}]}
{"channel":"book","type":"update","data":[{"symbol":"ETH/USD","bids":[],"asks":[{"price":3796.47,"qty":26.34030685}],"checksum":152559670,"timestamp":"2024-06-01T17:52:04.060477Z"}]}
{"channel":"book","type":"update","data":[{"symbol":"ETH/USD","bids":[],"asks":[{"price":3796.47,"qty":0.00000000},{"price":3797.11,"qty":10.81226191}],"checksum":4232226742,"timestamp":"2024-06-01T17:52:04.105232Z"}]}
{"channel":"book","type":"update","data":[{"symbol":"ETH/USD","bids":[],"asks":[{"price":3796.48,"qty":26.34021992}],"checksum":2012716319,"timestamp":"2024-06-01T17:52:04.351685Z"}]}
{"channel":"book","type":"update","data":[{"symbol":"ETH/USD","bids":[],"asks":[{"price":3796.69,"qty":0.00000000},{"price":3797.11,"qty":10.81226191}],"checksum":2116519239,"timestamp":"2024-06-01T17:52:04.430940Z"}]}
{"channel":"book","type":"update","data":[{"symbol":"ETH/USD","bids":[],"asks":[{"price":3796.48,"qty":0.00000000},{"price":3797.14,"qty":26.33567838}],"checksum":1744283318,"timestamp":"2024-06-01T17:52:04.487257Z"}]}
{"channel":"book","type":"update","data":[{"symbol":"ETH/USD","bids":[],"asks":[{"price":3796.50,"qty":26.34007241}],"checksum":286417564,"timestamp":"2024-06-01T17:52:04.491875Z"}]}
{"channel":"book","type":"update","data":[{"symbol":"ETH/USD","bids":[{"price":3794.32,"qty":0.00000000},{"price":3793.99,"qty":2.45696258}],"asks":[],"checksum":3536840268,"timestamp":"2024-06-01T17:52:04.595463Z"}]}
{"channel":"book","type":"update","data":[{"symbol":"ETH/USD","bids":[],"asks":[{"price":3796.65,"qty":0.77000000}],"checksum":1782046028,"timestamp":"2024-06-01T17:52:04.597374Z"}]}
{"channel":"book","type":"update","data":[{"symbol":"ETH/USD","bids":[{"price":3794.09,"qty":5.26500000}],"asks":[],"checksum":2416435441,"timestamp":"2024-06-01T17:52:04.597974Z"}]}
{"channel":"book","type":"update","data":[{"symbol":"ETH/USD","bids":[],"asks":[{"price":3796.50,"qty":0.00000000},{"price":3797.11,"qty":10.81226191}],"checksum":1272463088,"timestamp":"2024-06-01T17:52:04.700581Z"}]}
{"channel":"book","type":"update","data":[{"symbol":"ETH/USD","bids":[],"asks":[{"price":3796.48,"qty":26.34021992}],"checksum":1695411875,"timestamp":"2024-06-01T17:52:04.706615Z"}]}
{"channel":"book","type":"update","data":[{"symbol":"ETH/USD","bids":[],"asks":[{"price":3796.51,"qty":0.00000000},{"price":3797.11,"qty":10.81226191},{"price":3796.47,"qty":4.30610000}],"checksum":1562118696,"timestamp":"2024-06-01T17:52:04.942792Z"}]}
{"channel":"book","type":"update","data":[{"symbol":"ETH/USD","bids":[],"asks":[{"price":3796.48,"qty":0.00000000},{"price":3797.11,"qty":10.81226191}],"checksum":4052579963,"timestamp":"2024-06-01T17:52:05.077330Z"}]}
{"channel":"book","type":"update","data":[{"symbol":"ETH/USD","bids":[],"asks":[{"price":3796.50,"qty":26.34009061}],"checksum":2539632558,"timestamp":"2024-06-01T17:52:05.081414Z"}]}
{"channel":"book","type":"update","data":[{"symbol":"ETH/USD","bids":[{"price":3794.52,"qty":217.71969342}],"asks":[],"checksum":2754236328,"timestamp":"2024-06-01T17:52:05.402602Z"}]}
{"channel":"book","type":"update","data":[{"symbol":"ETH/USD","bids":[{"price":3794.34,"qty":0.00000000},{"price":3793.99,"qty":2.45696258}],"asks":[],"checksum":2076814212,"timestamp":"2024-06-01T17:52:05.404910Z"}]}
{"channel":"book","type":"update","data":[{"symbol":"ETH/USD","bids":[],"asks":[{"price":3796.65,"qty":0.00000000},{"price":3797.11,"qty":10.81226191},{"price":3796.47,"qty":5.07610000}],"checksum":4288008818,"timestamp":"2024-06-01T17:52:05.405914Z"}]}
{"channel":"book","type":"update","data":[{"symbol":"ETH/USD","bids":[],"asks":[{"price":3796.47,"qty":5.84610000}],"checksum":1890102329,"timestamp":"2024-06-01T17:52:05.407969Z"}]}
{"channel":"book","type":"update","data":[{"symbol":"ETH/USD","bids":[],"asks":[{"price":3796.56,"qty":0.00000000},{"price":3797.14,"qty":26.33567838}],"checksum":771149861,"timestamp":"2024-06-01T17:52:05.415031Z"}]}
{"channel":"book","type":"update","data":[{"symbol":"ETH/USD","bids":[],"asks":[{"price":3796.50,"qty":0.00000000},{"price":3797.21,"qty":3.00000000}],"checksum":1396759557,"timestamp":"2024-06-01T17:52:05.415082Z"}]}
{"channel":"book","type":"update","data":[{"symbol":"ETH/USD","bids":[],"asks":[{"price":3797.14,"qty":0.00000000},{"price":3797.22,"qty":2.18000000}],"checksum":2361889256,"timestamp":"2024-06-01T17:52:05.415099Z"}]}
{"channel":"book","type":"update","data":[{"symbol":"ETH/USD","bids":[],"asks":[{"price":3796.84,"qty":0.00000000},{"price":3797.29,"qty":10.43462302}],"checksum":3466174220,"timestamp":"2024-06-01T17:52:05.416706Z"}]}
{"channel":"book","type":"update","data":[{"symbol":"ETH/USD","bids":[],"asks":[{"price":3796.11,"qty":26.34278749}],"checksum":2189489302,"timestamp":"2024-06-01T17:52:05.426449Z"}]}
{"channel":"book","type":"update","data":[{"symbol":"ETH/USD","bids":[],"asks":[{"price":3796.67,"qty":26.33892113}],"checksum":1128473521,"timestamp":"2024-06-01T17:52:05.426506Z"}]}
{"channel":"book","type":"update","data":[{"symbol":"ETH/USD","bids":[{"price":3794.52,"qty":214.31593396}],"asks":[],"checksum":705870557,"timestamp":"2024-06-01T17:52:05.430675Z"}]}
{"channel":"book","type":"update","data":[{"symbol":"ETH/USD","bids":[],"asks":[{"price":3796.11,"qty":0.00000000},{"price":3797.22,"qty":2.18000000}],"checksum":3195851067,"timestamp":"2024-06-01T17:52:05.434497Z"}]}
{"channel":"book","type":"update","data":[{"symbol":"ETH/USD","bids":[],"asks":[{"price":3796.47,"qty":5.07610000},{"price":3796.33,"qty":0.77000000}],"checksum":3088643958,"timestamp":"2024-06-01T17:52:05.447225Z"}]}
{"channel":"book","type":"update","data":[{"symbol":"ETH/USD","bids":[{"price":3794.08,"qty":0.00000000},{"price":3793.93,"qty":0.39456778}],"asks":[],"checksum":2941563267,"timestamp":"2024-06-01T17:52:05.449033Z"}]}
{"channel":"book","type":"update","data":[{"symbol":"ETH/USD","bids":[],"asks":[{"price":3796.47,"qty":4.30610000}],"checksum":2851702829,"timestamp":"2024-06-01T17:52:05.450314Z"}]}
{"channel":"book","type":"update","data":[{"symbol":"ETH/USD","bids":[{"price":3793.94,"qty":0.76996747}],"asks":[],"checksum":2103847802,"timestamp":"2024-06-01T17:52:05.454212Z"}]}
{"channel":"book","type":"update","data":[{"symbol":"ETH/USD","bids":[{"price":3794.08,"qty":0.06693358}],"asks":[],"checksum":2744403507,"timestamp":"2024-06-01T17:52:05.491999Z"}]}
{"channel":"book","type":"update","data":[{"symbol":"ETH/USD","bids":[],"asks":[{"price":3796.18,"qty":26.34232410}],"checksum":3027826947,"timestamp":"2024-06-01T17:52:05.492783Z"}]}
{"channel":"book","type":"update","data":[{"symbol":"ETH/USD","bids":[],"asks":[{"price":3796.18,"qty":0.00000000},{"price":3797.21,"qty":3.00000000}],"checksum":2744403507,"timestamp":"2024-06-01T17:52:05.496819Z"}]}
{"channel":"book","type":"update","data":[{"symbol":"ETH/USD","bids":[{"price":3794.52,"qty":216.46893396}],"asks":[],"checksum":4265772710,"timestamp":"2024-06-01T17:52:05.501331Z"}]}
{"channel":"book","type":"update","data":[{"symbol":"ETH/USD","bids":[{"price":3794.52,"qty":215.69893396}],"asks":[],"checksum":579707660,"timestamp":"2024-06-01T17:52:05.513794Z"}]}
{"channel":"book","type":"update","data":[{"symbol":"ETH/USD","bids":[{"price":3794.52,"qty":216.46893396}],"asks":[],"checksum":4265772710,"timestamp":"2024-06-01T17:52:05.532301Z"}]}
{"channel":"book","type":"update","data":[{"symbol":"ETH/USD","bids":[],"asks":[{"price":3796.18,"qty":26.34230039}],"checksum":1653158968,"timestamp":"2024-06-01T17:52:05.546213Z"}]}
{"channel":"book","type":"update","data":[{"symbol":"ETH/USD","bids":[{"price":3794.52,"qty":219.87269342}],"asks":[],"checksum":3210657036,"timestamp":"2024-06-01T17:52:05.562723Z"}]}
{"channel":"book","type":"update","data":[{"symbol":"ETH/USD","bids":[],"asks":[{"price":3796.33,"qty":0.00000000},{"price":3797.21,"qty":3.00000000}],"checksum":841359781,"timestamp":"2024-06-01T17:52:05.588316Z"}]}
{"channel":"book","type":"update","data":[{"symbol":"ETH/USD","bids":[],"asks":[{"price":3796.18,"qty":0.00000000},{"price":3797.22,"qty":2.18000000}],"checksum":3171487599,"timestamp":"2024-06-01T17:52:05.707968Z"}]}
{"channel":"book","type":"update","data":[{"symbol":"ETH/USD","bids":[],"asks":[{"price":3796.31,"qty":0.77000000}],"checksum":1605399014,"timestamp":"2024-06-01T17:52:05.711501Z"}]}
{"channel":"book","type":"update","data":[{"symbol":"ETH/USD","bids":[],"asks":[{"price":3796.20,"qty":26.34214233}],"checksum":1349753668,"timestamp":"2024-06-01T17:52:05.712797Z"}]}
{"channel":"book","type":"update","data":[{"symbol":"ETH/USD","bids":[],"asks":[{"price":3796.47,"qty":0.00000000},{"price":3797.21,"qty":3.00000000}],"checksum":956170822,"timestamp":"2024-06-01T17:52:05.786484Z"}]}
{"channel":"book","type":"update","data":[{"symbol":"ETH/USD","bids":[],"asks":[{"price":3796.20,"qty":0.00000000},{"price":3797.22,"qty":2.18000000}],"checksum":1409603009,"timestamp":"2024-06-01T17:52:05.908403Z"}]}
{"channel":"book","type":"update","data":[{"symbol":"ETH/USD","bids":[],"asks":[{"price":3796.16,"qty":26.34242420}],"checksum":482491230,"timestamp":"2024-06-01T17:52:05.913947Z"}]}
{"channel":"book","type":"update","data":[{"symbol":"ETH/USD","bids":[],"asks":[{"price":3796.16,"qty":0.00000000},{"price":3797.22,"qty":2.18000000}],"checksum":1409603009,"timestamp":"2024-06-01T17:52:05.993981Z"}]}
{"channel":"book","type":"update","data":[{"symbol":"ETH/USD","bids":[],"asks":[{"price":3796.18,"qty":26.34229512}],"checksum":1652624304,"timestamp":"2024-06-01T17:52:05.998024Z"}]}
{"channel":"book","type":"update","data":[{"symbol":"ETH/USD","bids":[],"asks":[{"price":3796.18,"qty":0.00000000},{"price":3797.22,"qty":2.18000000}],"checksum":1409603009,"timestamp":"2024-06-01T17:52:06.045583Z"}]}
{"channel":"book","type":"update","data":[{"symbol":"ETH/USD","bids":[],"asks":[{"price":3796.17,"qty":27.14210348}],"checksum":3636799349,"timestamp":"2024-06-01T17:52:06.049992Z"}]}
{"channel":"book","type":"update","data":[{"symbol":"ETH/USD","bids":[],"asks":[{"price":3796.17,"qty":0.79971616}],"checksum":1409603009,"timestamp":"2024-06-01T17:52:06.078376Z"}]}
{"channel":"book","type":"update","data":[{"symbol":"ETH/USD","bids":[{"price":3794.35,"qty":0.00000000},{"price":3793.94,"qty":0.76996747},{"price":3794.15,"qty":7.20000000}],"asks":[],"checksum":4050600831,"timestamp":"2024-06-01T17:52:06.156540Z"}]}
{"channel":"book","type":"update","data":[{"symbol":"ETH/USD","bids":[{"price":3794.52,"qty":219.77269342}],"asks":[],"checksum":3526073180,"timestamp":"2024-06-01T17:52:06.176832Z"}]}
{"channel":"book","type":"update","data":[{"symbol":"ETH/USD","bids":[{"price":3794.36,"qty":0.00000000},{"price":3793.94,"qty":0.76996747},{"price":3794.34,"qty":0.00937289}],"asks":[],"checksum":2868863464,"timestamp":"2024-06-01T17:52:06.211241Z"}]}
{"channel":"book","type":"update","data":[{"symbol":"ETH/USD","bids":[],"asks":[{"price":3796.17,"qty":27.14207086}],"checksum":2339106375,"timestamp":"2024-06-01T17:52:06.228541Z"}]}
{"channel":"book","type":"update","data":[{"symbol":"ETH/USD","bids":[],"asks":[{"price":3796.17,"qty":0.79971616}],"checksum":2868863464,"timestamp":"2024-06-01T17:52:06.259977Z"}]}
{"channel":"book","type":"update","data":[{"symbol":"ETH/USD","bids":[{"price":3794.51,"qty":0.10000000}],"asks":[],"checksum":1503126985,"timestamp":"2024-06-01T17:52:06.361801Z"}]}
{"channel":"book","type":"update","data":[{"symbol":"ETH/USD","bids":[],"asks":[{"price":3796.14,"qty":26.34260760}],"checksum":2655317557,"timestamp":"2024-06-01T17:52:06.411069Z"}]}
{"channel":"book","type":"update","data":[{"symbol":"ETH/USD","bids":[{"price":3794.40,"qty":0.00000000},{"price":3793.99,"qty":2.45696258}],"asks":[],"checksum":2382449982,"timestamp":"2024-06-01T17:52:06.558996Z"}]}
{"channel":"book","type":"update","data":[{"symbol":"ETH/USD","bids":[],"asks":[{"price":3796.14,"qty":0.00000000},{"price":3797.22,"qty":2.18000000}],"checksum":986521602,"timestamp":"2024-06-01T17:52:06.591110Z"}]}
{"channel":"book","type":"update","data":[{"symbol":"ETH/USD","bids":[],"asks":[{"price":3796.19,"qty":26.34225174}],"checksum":2085186563,"timestamp":"2024-06-01T17:52:06.595706Z"}]}
{"channel":"book","type":"update","data":[{"symbol":"ETH/USD","bids":[],"asks":[{"price":3796.19,"qty":0.00000000},{"price":3797.22,"qty":2.18000000}],"checksum":986521602,"timestamp":"2024-06-01T17:52:06.639223Z"}]}
{"channel":"book","type":"update","data":[{"symbol":"ETH/USD","bids":[{"price":3794.07,"qty":0.29493501}],"asks":[],"checksum":445416630,"timestamp":"2024-06-01T17:52:06.662116Z"}]}
{"channel":"book","type":"update","data":[{"symbol":"ETH/USD","bids":[],"asks":[{"price":3796.18,"qty":26.34228738}],"checksum":2670301131,"timestamp":"2024-06-01T17:52:07.561843Z"}]}
{"channel":"book","type":"update","data":[{"symbol":"ETH/USD","bids":[{"price":3794.51,"qty":0.00000000},{"price":3793.99,"qty":2.45696258}],"asks":[],"checksum":3556491893,"timestamp":"2024-06-01T17:52:07.752359Z"}]}
{"channel":"book","type":"update","data":[{"symbol":"ETH/USD","bids":[{"price":3794.50,"qty":0.10000000}],"asks":[],"checksum":671187016,"timestamp":"2024-06-01T17:52:07.929448Z"}]}
{"channel":"book","type":"update","data":[{"symbol":"ETH/USD","bids":[{"price":3794.52,"qty":217.61969342}],"asks":[],"checksum":3112881347,"timestamp":"2024-06-01T17:52:08.192878Z"}]}
{"channel":"book","type":"update","data":[{"symbol":"ETH/USD","bids":[],"asks":[{"price":3796.18,"qty":0.00000000},{"price":3797.22,"qty":2.18000000}],"checksum":1009764286,"timestamp":"2024-06-01T17:52:08.267279Z"}]}
{"channel":"book","type":"update","data":[{"symbol":"ETH/USD","bids":[],"asks":[{"price":3796.17,"qty":27.14208322}],"checksum":3929838485,"timestamp":"2024-06-01T17:52:08.273962Z"}]}
{"channel":"book","type":"update","data":[{"symbol":"ETH/USD","bids":[{"price":3794.52,"qty":219.77269342}],"asks":[],"checksum":2075647774,"timestamp":"2024-06-01T17:52:08.291711Z"}]}
{"channel":"book","type":"update","data":[{"symbol":"ETH/USD","bids":[],"asks":[{"price":3796.17,"qty":0.79971616}],"checksum":2913241909,"timestamp":"2024-06-01T17:52:08.308068Z"}]}
{"channel":"book","type":"update","data":[{"symbol":"ETH/USD","bids":[],"asks":[{"price":3796.18,"qty":26.34227222}],"checksum":2379475530,"timestamp":"2024-06-01T17:52:08.354213Z"}]}
{"channel":"book","type":"update","data":[{"symbol":"ETH/USD","bids":[],"asks":[{"price":3796.18,"qty":0.00000000},{"price":3797.22,"qty":2.18000000}],"checksum":2913241909,"timestamp":"2024-06-01T17:52:08.439000Z"}]}
{"channel":"book","type":"update","data":[{"symbol":"ETH/USD","bids":[],"asks":[{"price":3796.17,"qty":27.14208322}],"checksum":2075647774,"timestamp":"2024-06-01T17:52:08.443528Z"}]}
{"channel":"book","type":"update","data":[{"symbol":"ETH/USD","bids":[],"asks":[{"price":3796.17,"qty":0.79971616}],"checksum":2913241909,"timestamp":"2024-06-01T17:52:08.626666Z"}]}
{"channel":"book","type":"update","data":[{"symbol":"ETH/USD","bids":[],"asks":[{"price":3796.20,"qty":26.34216951}],"checksum":1376821490,"timestamp":"2024-06-01T17:52:08.631260Z"}]}
{"channel":"book","type":"update","data":[{"symbol":"ETH/USD","bids":[],"asks":[{"price":3796.20,"qty":0.00000000},{"price":3797.22,"qty":2.18000000}],"checksum":2913241909,"timestamp":"2024-06-01T17:52:08.703868Z"}]}
{"channel":"book","type":"update","data":[{"symbol":"ETH/USD","bids":[],"asks":[{"price":3796.18,"qty":26.34229596}],"checksum":3555162062,"timestamp":"2024-06-01T17:52:08.708289Z"}]}
{"channel":"book","type":"update","data":[{"symbol":"ETH/USD","bids":[],"asks":[{"price":3796.18,"qty":0.00000000},{"price":3797.22,"qty":2.18000000}],"checksum":2913241909,"timestamp":"2024-06-01T17:52:08.872360Z"}]}
{"channel":"book","type":"update","data":[{"symbol":"ETH/USD","bids":[],"asks":[{"price":3796.21,"qty":26.34212938}],"checksum":2121735581,"timestamp":"2024-06-01T17:52:08.876486Z"}]}
{"channel":"book","type":"update","data":[{"symbol":"ETH/USD","bids":[],"asks":[{"price":3796.21,"qty":0.00000000},{"price":3797.22,"qty":2.18000000}],"checksum":2913241909,"timestamp":"2024-06-01T17:52:08.892801Z"}]}
{"channel":"book","type":"update","data":[{"symbol":"ETH/USD","bids":[],"asks":[{"price":3794.53,"qty":0.00000000},{"price":3797.29,"qty":10.43462302}],"checksum":623531953,"timestamp":"2024-06-01T17:52:09.107385Z"}]}
{"channel":"book","type":"update","data":[{"symbol":"ETH/USD","bids":[{"price":3794.52,"qty":216.47269342}],"asks":[],"checksum":1202583324,"timestamp":"2024-06-01T17:52:09.110538Z"}]}
{"channel":"book","type":"update","data":[{"symbol":"ETH/USD","bids":[{"price":3794.63,"qty":3.30000000}],"asks":[],"checksum":2244704728,"timestamp":"2024-06-01T17:52:09.110641Z"}]}
{"channel":"book","type":"update","data":[{"symbol":"ETH/USD","bids":[],"asks":[{"price":3796.57,"qty":3.30000000}],"checksum":815268786,"timestamp":"2024-06-01T17:52:09.111165Z"}]}
{"channel":"book","type":"update","data":[{"symbol":"ETH/USD","bids":[{"price":3794.70,"qty":3.00000000}],"asks":[],"checksum":3878741386,"timestamp":"2024-06-01T17:52:09.111313Z"}]}
{"channel":"book","type":"update","data":[{"symbol":"ETH/USD","bids":[{"price":3794.53,"qty":3.95144465}],"asks":[],"checksum":124249291,"timestamp":"2024-06-01T17:52:09.111701Z"}]}
{"channel":"book","type":"update","data":[{"symbol":"ETH/USD","bids":[{"price":3794.52,"qty":215.47269342}],"asks":[],"checksum":2915165759,"timestamp":"2024-06-01T17:52:09.111747Z"}]}
{"channel":"book","type":"update","data":[{"symbol":"ETH/USD","bids":[{"price":3794.52,"qty":214.94561754},{"price":3794.53,"qty":4.47851914}],"asks":[],"checksum":336564614,"timestamp":"2024-06-01T17:52:09.111858Z"}]}
{"channel":"book","type":"update","data":[{"symbol":"ETH/USD","bids":[],"asks":[{"price":3796.72,"qty":0.72912968}],"checksum":2157166152,"timestamp":"2024-06-01T17:52:09.111880Z"}]}
{"channel":"book","type":"update","data":[{"symbol":"ETH/USD","bids":[{"price":3794.53,"qty":5.20764882}],"asks":[],"checksum":3122584026,"timestamp":"2024-06-01T17:52:09.111971Z"}]}
{"channel":"book","type":"update","data":[{"symbol":"ETH/USD","bids":[],"asks":[{"price":3796.35,"qty":0.00000000},{"price":3797.22,"qty":2.18000000},{"price":3796.16,"qty":0.52684818}],"checksum":3223915973,"timestamp":"2024-06-01T17:52:09.112125Z"}]}
{"channel":"book","type":"update","data":[{"symbol":"ETH/USD","bids":[{"price":3794.52,"qty":188.59182313}],"asks":[],"checksum":610917050,"timestamp":"2024-06-01T17:52:09.113547Z"}]}
{"channel":"book","type":"update","data":[{"symbol":"ETH/USD","bids":[{"price":3794.52,"qty":162.23802872}],"asks":[],"checksum":2987422321,"timestamp":"2024-06-01T17:52:09.113564Z"}]}
{"channel":"book","type":"update","data":[{"symbol":"ETH/USD","bids":[{"price":3794.52,"qty":135.88423431}],"asks":[],"checksum":212533991,"timestamp":"2024-06-01T17:52:09.113574Z"}]}
{"channel":"book","type":"update","data":[{"symbol":"ETH/USD","bids":[{"price":3794.52,"qty":109.53043990}],"asks":[],"checksum":497484367,"timestamp":"2024-06-01T17:52:09.113583Z"}]}
{"channel":"book","type":"update","data":[{"symbol":"ETH/USD","bids":[{"price":3794.52,"qty":104.25943990},{"price":3794.64,"qty":5.27100000}],"asks":[],"checksum":1299280423,"timestamp":"2024-06-01T17:52:09.114734Z"}]}
{"channel":"book","type":"update","data":[{"symbol":"ETH/USD","bids":[{"price":3794.52,"qty":100.30679782}],"asks":[],"checksum":2791345463,"timestamp":"2024-06-01T17:52:09.115309Z"}]}
{"channel":"book","type":"update","data":[{"symbol":"ETH/USD","bids":[{"price":3794.52,"qty":96.35779782},{"price":3794.64,"qty":9.22000000}],"asks":[],"checksum":3458069929,"timestamp":"2024-06-01T17:52:09.116509Z"}]}
{"channel":"book","type":"update","data":[{"symbol":"ETH/USD","bids":[{"price":3795.00,"qty":3.00000000}],"asks":[],"checksum":1483538092,"timestamp":"2024-06-01T17:52:09.116635Z"}]}
{"channel":"book","type":"update","data":[{"symbol":"ETH/USD","bids":[{"price":3794.63,"qty":0.00000000},{"price":3794.15,"qty":7.20000000}],"asks":[],"checksum":3533068357,"timestamp":"2024-06-01T17:52:09.117563Z"}]}
{"channel":"book","type":"update","data":[{"symbol":"ETH/USD","bids":[{"price":3794.81,"qty":3.30000000}],"asks":[],"checksum":994489439,"timestamp":"2024-06-01T17:52:09.117623Z"}]}
{"channel":"book","type":"update","data":[{"symbol":"ETH/USD","bids":[{"price":3794.64,"qty":13.17144465}],"asks":[],"checksum":2831549705,"timestamp":"2024-06-01T17:52:09.117663Z"}]}
{"channel":"book","type":"update","data":[{"symbol":"ETH/USD","bids":[{"price":3794.53,"qty":4.68057433},{"price":3794.71,"qty":0.52704949}],"asks":[],"checksum":575353791,"timestamp":"2024-06-01T17:52:09.117871Z"}]}
{"channel":"book","type":"update","data":[{"symbol":"ETH/USD","bids":[],"asks":[{"price":3796.16,"qty":0.00000000},{"price":3797.22,"qty":2.18000000},{"price":3796.15,"qty":0.52684957}],"checksum":636587771,"timestamp":"2024-06-01T17:52:09.117981Z"}]}
{"channel":"book","type":"update","data":[{"symbol":"ETH/USD","bids":[],"asks":[{"price":3795.98,"qty":3.00000000}],"checksum":4258796899,"timestamp":"2024-06-01T17:52:09.120038Z"}]}
{"channel":"book","type":"update","data":[{"symbol":"ETH/USD","bids":[{"price":3794.53,"qty":0.72912968}],"asks":[],"checksum":2509378563,"timestamp":"2024-06-01T17:52:09.121032Z"}]}
{"channel":"book","type":"update","data":[{"symbol":"ETH/USD","bids":[],"asks":[{"price":3796.20,"qty":26.34219788}],"checksum":1016241751,"timestamp":"2024-06-01T17:52:09.121629Z"}]}
{"channel":"book","type":"update","data":[{"symbol":"ETH/USD","bids":[{"price":3795.91,"qty":26.34411434}],"asks":[],"checksum":2080142716,"timestamp":"2024-06-01T17:52:09.121648Z"}]}
{"channel":"book","type":"update","data":[{"symbol":"ETH/USD","bids":[{"price":3794.71,"qty":26.87949174}],"asks":[],"checksum":1697155702,"timestamp":"2024-06-01T17:52:09.121743Z"}]}
{"channel":"book","type":"update","data":[{"symbol":"ETH/USD","bids":[{"price":3794.71,"qty":53.23193399}],"asks":[],"checksum":878864182,"timestamp":"2024-06-01T17:52:09.121848Z"}]}
{"channel":"book","type":"update","data":[{"symbol":"ETH/USD","bids":[{"price":3794.71,"qty":79.58437624}],"asks":[],"checksum":529879021,"timestamp":"2024-06-01T17:52:09.121916Z"}]}
{"channel":"book","type":"update","data":[{"symbol":"ETH/USD","bids":[{"price":3794.52,"qty":93.35779782}],"asks":[],"checksum":1485900679,"timestamp":"2024-06-01T17:52:09.122098Z"}]}
{"channel":"book","type":"update","data":[{"symbol":"ETH/USD","bids":[{"price":3795.00,"qty":6.00000000}],"asks":[],"checksum":3778578652,"timestamp":"2024-06-01T17:52:09.122114Z"}]}
{"channel":"book","type":"update","data":[{"symbol":"ETH/USD","bids":[{"price":3794.71,"qty":79.05732675},{"price":3795.01,"qty":0.52700783}],"asks":[],"checksum":1555874445,"timestamp":"2024-06-01T17:52:09.122676Z"}]}
{"channel":"book","type":"update","data":[{"symbol":"ETH/USD","bids":[],"asks":[{"price":3796.15,"qty":0.00000000},{"price":3797.11,"qty":10.81226191},{"price":3796.14,"qty":0.52685095}],"checksum":815232753,"timestamp":"2024-06-01T17:52:09.122694Z"}]}
{"channel":"book","type":"update","data":[{"symbol":"ETH/USD","bids":[],"asks":[{"price":3796.17,"qty":0.00000000},{"price":3797.11,"qty":10.81226191}],"checksum":4202058528,"timestamp":"2024-06-01T17:52:09.125496Z"}]}
{"channel":"book","type":"update","data":[{"symbol":"ETH/USD","bids":[{"price":3795.01,"qty":0.00000000},{"price":3794.34,"qty":0.00937289},{"price":3795.97,"qty":0.52687455}],"asks":[],"checksum":3946034909,"timestamp":"2024-06-01T17:52:09.127356Z"}]}
{"channel":"book","type":"update","data":[{"symbol":"ETH/USD","bids":[{"price":3794.71,"qty":52.70488450}],"asks":[],"checksum":2453551756,"timestamp":"2024-06-01T17:52:09.127616Z"}]}
{"channel":"book","type":"update","data":[{"symbol":"ETH/USD","bids":[{"price":3794.71,"qty":26.35244225}],"asks":[],"checksum":574178073,"timestamp":"2024-06-01T17:52:09.127640Z"}]}
{"channel":"book","type":"update","data":[{"symbol":"ETH/USD","bids":[{"price":3794.71,"qty":0.00000000},{"price":3794.34,"qty":0.00937289}],"asks":[],"checksum":2002710077,"timestamp":"2024-06-01T17:52:09.127685Z"}]}
{"channel":"book","type":"update","data":[{"symbol":"ETH/USD","bids":[],"asks":[{"price":3796.14,"qty":0.00000000},{"price":3797.21,"qty":3.00000000}],"checksum":3579239679,"timestamp":"2024-06-01T17:52:09.128323Z"}]}
{"channel":"book","type":"update","data":[{"symbol":"ETH/USD","bids":[{"price":3794.64,"qty":15.84144465}],"asks":[],"checksum":3181827574,"timestamp":"2024-06-01T17:52:09.141500Z"}]}
{"channel":"book","type":"update","data":[{"symbol":"ETH/USD","bids":[{"price":3794.34,"qty":0.00000000},{"price":3794.33,"qty":3.95290248},{"price":3795.01,"qty":0.00936992}],"asks":[],"checksum":1598022718,"timestamp":"2024-06-01T17:52:09.169297Z"}]}
{"channel":"book","type":"update","data":[{"symbol":"ETH/USD","bids":[{"price":3794.64,"qty":13.17144465}],"asks":[],"checksum":2531672554,"timestamp":"2024-06-01T17:52:09.170843Z"}]}
{"channel":"book","type":"update","data":[{"symbol":"ETH/USD","bids":[{"price":3794.53,"qty":0.00000000},{"price":3794.33,"qty":3.95290248}],"asks":[],"checksum":4038274605,"timestamp":"2024-06-01T17:52:09.173181Z"}]}
{"channel":"book","type":"update","data":[{"symbol":"ETH/USD","bids":[{"price":3794.50,"qty":0.00000000},{"price":3794.30,"qty":6.93000000}],"asks":[],"checksum":1997744753,"timestamp":"2024-06-01T17:52:09.180295Z"}]}
{"channel":"book","type":"update","data":[{"symbol":"ETH/USD","bids":[],"asks":[{"price":3796.20,"qty":0.00000000},{"price":3797.22,"qty":2.18000000}],"checksum":969825165,"timestamp":"2024-06-01T17:52:09.190739Z"}]}
{"channel":"book","type":"update","data":[{"symbol":"ETH/USD","bids":[{"price":3795.91,"qty":0.00000000},{"price":3794.15,"qty":7.20000000}],"asks":[],"checksum":1274317547,"timestamp":"2024-06-01T17:52:09.190803Z"}]}
{"channel":"book","type":"update","data":[{"symbol":"ETH/USD","bids":[{"price":3794.81,"qty":0.00000000},{"price":3794.14,"qty":3.00000000}],"asks":[],"checksum":3950824864,"timestamp":"2024-06-01T17:52:09.193738Z"}]}
{"channel":"book","type":"update","data":[{"symbol":"ETH/USD","bids":[{"price":3795.07,"qty":3.30000000}],"asks":[],"checksum":310235459,"timestamp":"2024-06-01T17:52:09.194112Z"}]}
{"channel":"book","type":"update","data":[{"symbol":"ETH/USD","bids":[{"price":3795.97,"qty":0.00000000},{"price":3794.14,"qty":3.00000000}],"asks":[],"checksum":3760043087,"timestamp":"2024-06-01T17:52:09.195178Z"}]}
{"channel":"book","type":"update","data":[{"symbol":"ETH/USD","bids":[{"price":3795.88,"qty":26.34432510}],"asks":[],"checksum":3816099785,"timestamp":"2024-06-01T17:52:09.195595Z"}]}
{"channel":"book","type":"update","data":[{"symbol":"ETH/USD","bids":[],"asks":[{"price":3796.17,"qty":26.34240874}],"checksum":854116506,"timestamp":"2024-06-01T17:52:09.195714Z"}]}
{"channel":"book","type":"update","data":[{"symbol":"ETH/USD","bids":[],"asks":[{"price":3795.97,"qty":0.77390109}],"checksum":4172689202,"timestamp":"2024-06-01T17:52:09.198796Z"}]}
{"channel":"book","type":"update","data":[{"symbol":"ETH/USD","bids":[{"price":3795.19,"qty":3.00000000}],"asks":[],"checksum":3395699279,"timestamp":"2024-06-01T17:52:09.199070Z"}]}
{"channel":"book","type":"update","data":[{"symbol":"ETH/USD","bids":[{"price":3794.70,"qty":0.00000000},{"price":3794.15,"qty":7.20000000}],"asks":[],"checksum":836509052,"timestamp":"2024-06-01T17:52:09.199380Z"}]}
{"channel":"book","type":"update","data":[{"symbol":"ETH/USD","bids":[{"price":3795.88,"qty":0.00000000},{"price":3794.14,"qty":3.00000000}],"asks":[],"checksum":3054078450,"timestamp":"2024-06-01T17:52:09.200869Z"}]}
{"channel":"book","type":"update","data":[{"symbol":"ETH/USD","bids":[],"asks":[{"price":3795.92,"qty":3.00000000}],"checksum":216508578,"timestamp":"2024-06-01T17:52:09.202272Z"}]}
{"channel":"book","type":"update","data":[{"symbol":"ETH/USD","bids":[{"price":3794.52,"qty":89.95403836}],"asks":[],"checksum":4214900234,"timestamp":"2024-06-01T17:52:09.204608Z"}]}
{"channel":"book","type":"update","data":[{"symbol":"ETH/USD","bids":[],"asks":[{"price":3795.96,"qty":0.52687594}],"checksum":978296605,"timestamp":"2024-06-01T17:52:09.204687Z"}]}
{"channel":"book","type":"update","data":[{"symbol":"ETH/USD","bids":[{"price":3795.20,"qty":0.52698145}],"asks":[],"checksum":3485729729,"timestamp":"2024-06-01T17:52:09.207743Z"}]}
{"channel":"book","type":"update","data":[{"symbol":"ETH/USD","bids":[],"asks":[{"price":3795.96,"qty":0.00000000},{"price":3796.83,"qty":3.00000000},{"price":3795.92,"qty":3.52688149}],"checksum":4209570862,"timestamp":"2024-06-01T17:52:09.209140Z"}]}
{"channel":"book","type":"update","data":[{"symbol":"ETH/USD","bids":[{"price":3795.20,"qty":0.00000000},{"price":3794.14,"qty":3.00000000},{"price":3795.21,"qty":0.52698006}],"asks":[],"checksum":507376471,"timestamp":"2024-06-01T17:52:09.211600Z"}]}
{"channel":"book","type":"update","data":[{"symbol":"ETH/USD","bids":[{"price":3795.21,"qty":0.00000000},{"price":3794.14,"qty":3.00000000},{"price":3795.22,"qty":0.52697867}],"asks":[],"checksum":4273862784,"timestamp":"2024-06-01T17:52:09.216062Z"}]}
{"channel":"book","type":"update","data":[{"symbol":"ETH/USD","bids":[],"asks":[{"price":3796.17,"qty":0.00000000},{"price":3797.11,"qty":10.81226191}],"checksum":2327641513,"timestamp":"2024-06-01T17:52:09.216485Z"}]}
{"channel":"book","type":"update","data":[{"symbol":"ETH/USD","bids":[{"price":3795.19,"qty":0.00000000},{"price":3794.14,"qty":3.00000000}],"asks":[],"checksum":4271484262,"timestamp":"2024-06-01T17:52:09.220078Z"}]}
{"channel":"book","type":"update","data":[{"symbol":"ETH/USD","bids":[{"price":3795.22,"qty":0.00000000},{"price":3794.09,"qty":5.26500000},{"price":3795.23,"qty":0.52697728}],"asks":[],"checksum":588127512,"timestamp":"2024-06-01T17:52:09.220503Z"}]}
{"channel":"book","type":"update","data":[{"symbol":"ETH/USD","bids":[],"asks":[{"price":3795.92,"qty":3.00000000}],"checksum":48649929,"timestamp":"2024-06-01T17:52:09.220583Z"}]}
{"channel":"book","type":"update","data":[{"symbol":"ETH/USD","bids":[{"price":3795.08,"qty":5.99000000}],"asks":[],"checksum":2563447634,"timestamp":"2024-06-01T17:52:09.221394Z"}]}
{"channel":"book","type":"update","data":[{"symbol":"ETH/USD","bids":[{"price":3794.52,"qty":81.66403836}],"asks":[],"checksum":3438201849,"timestamp":"2024-06-01T17:52:09.223139Z"}]}
{"channel":"book","type":"update","data":[{"symbol":"ETH/USD","bids":[{"price":3795.23,"qty":0.00000000},{"price":3794.14,"qty":3.00000000},{"price":3795.24,"qty":0.52697589}],"asks":[],"checksum":206716094,"timestamp":"2024-06-01T17:52:09.224886Z"}]}
{"channel":"book","type":"update","data":[{"symbol":"ETH/USD","bids":[{"price":3795.24,"qty":0.00000000},{"price":3794.14,"qty":3.00000000},{"price":3795.25,"qty":0.52697450}],"asks":[],"checksum":153303829,"timestamp":"2024-06-01T17:52:09.228893Z"}]}
{"channel":"book","type":"update","data":[{"symbol":"ETH/USD","bids":[{"price":3795.25,"qty":0.00000000},{"price":3794.14,"qty":3.00000000},{"price":3795.26,"qty":0.52697311}],"asks":[],"checksum":371297727,"timestamp":"2024-06-01T17:52:09.232914Z"}]}
{"channel":"book","type":"update","data":[{"symbol":"ETH/USD","bids":[{"price":3795.08,"qty":0.00000000},{"price":3794.14,"qty":3.00000000}],"asks":[],"checksum":4123772350,"timestamp":"2024-06-01T17:52:09.248533Z"}]}
{"channel":"book","type":"update","data":[{"symbol":"ETH/USD","bids":[{"price":3795.24,"qty":3.18000000}],"asks":[],"checksum":2077441290,"timestamp":"2024-06-01T17:52:09.251446Z"}]}
{"channel":"book","type":"update","data":[{"symbol":"ETH/USD","bids":[],"asks":[{"price":3796.16,"qty":26.34243371}],"checksum":4216546685,"timestamp":"2024-06-01T17:52:09.263795Z"}]}
{"channel":"book","type":"update","data":[{"symbol":"ETH/USD","bids":[{"price":3795.88,"qty":26.34433828}],"asks":[],"checksum":4220077257,"timestamp":"2024-06-01T17:52:09.263856Z"}]}
{"channel":"book","type":"update","data":[{"symbol":"ETH/USD","bids":[],"asks":[{"price":3795.97,"qty":0.00000000},{"price":3797.11,"qty":10.81226191}],"checksum":40435268,"timestamp":"2024-06-01T17:52:09.267566Z"}]}
{"channel":"book","type":"update","data":[{"symbol":"ETH/USD","bids":[],"asks":[{"price":3795.98,"qty":0.00000000},{"price":3797.21,"qty":3.00000000}],"checksum":2903618731,"timestamp":"2024-06-01T17:52:09.271691Z"}]}
{"channel":"book","type":"update","data":[{"symbol":"ETH/USD","bids":[{"price":3794.52,"qty":80.89403836},{"price":3795.78,"qty":0.77000000}],"asks":[],"checksum":3726144131,"timestamp":"2024-06-01T17:52:09.280004Z"}]}
{"channel":"book","type":"update","data":[{"symbol":"ETH/USD","bids":[{"price":3795.24,"qty":0.00000000},{"price":3794.30,"qty":6.93000000}],"asks":[],"checksum":3179765357,"timestamp":"2024-06-01T17:52:09.282862Z"}]}
{"channel":"book","type":"update","data":[{"symbol":"ETH/USD","bids":[{"price":3795.78,"qty":1.54000000}],"asks":[],"checksum":282056340,"timestamp":"2024-06-01T17:52:09.283176Z"}]}
{"channel":"book","type":"update","data":[{"symbol":"ETH/USD","bids":[{"price":3795.01,"qty":0.00000000},{"price":3794.15,"qty":7.20000000},{"price":3795.26,"qty":0.53634241}],"asks":[],"checksum":1907194416,"timestamp":"2024-06-01T17:52:09.285803Z"}]}
{"channel":"book","type":"update","data":[{"symbol":"ETH/USD","bids":[{"price":3795.88,"qty":0.00000000},{"price":3794.14,"qty":3.00000000}],"asks":[],"checksum":3597548913,"timestamp":"2024-06-01T17:52:09.322484Z"}]}
{"channel":"book","type":"update","data":[{"symbol":"ETH/USD","bids":[{"price":3795.53,"qty":3.40285372}],"asks":[],"checksum":3248006896,"timestamp":"2024-06-01T17:52:09.323029Z"}]}
{"channel":"book","type":"update","data":[{"symbol":"ETH/USD","bids":[{"price":3795.78,"qty":0.77000000}],"asks":[],"checksum":853023427,"timestamp":"2024-06-01T17:52:09.326376Z"}]}
{"channel":"book","type":"update","data":[{"symbol":"ETH/USD","bids":[],"asks":[{"price":3796.16,"qty":0.00000000},{"price":3797.22,"qty":2.18000000}],"checksum":2760264579,"timestamp":"2024-06-01T17:52:09.328653Z"}]}
{"channel":"book","type":"update","data":[{"symbol":"ETH/USD","bids":[{"price":3795.26,"qty":0.52697311},{"price":3795.89,"qty":0.00936775}],"asks":[],"checksum":46743935,"timestamp":"2024-06-01T17:52:09.332483Z"}]}
{"channel":"book","type":"update","data":[{"symbol":"ETH/USD","bids":[],"asks":[{"price":3796.18,"qty":26.34229409}],"checksum":884752348,"timestamp":"2024-06-01T17:52:09.333082Z"}]}
{"channel":"book","type":"update","data":[{"symbol":"ETH/USD","bids":[{"price":3795.80,"qty":26.34487667}],"asks":[],"checksum":2777452351,"timestamp":"2024-06-01T17:52:09.333101Z"}]}
{"channel":"book","type":"update","data":[{"symbol":"ETH/USD","bids":[{"price":3795.89,"qty":26.35359537}],"asks":[],"checksum":181431790,"timestamp":"2024-06-01T17:52:09.333222Z"}]}
{"channel":"book","type":"update","data":[{"symbol":"ETH/USD","bids":[],"asks":[{"price":3796.18,"qty":0.00000000},{"price":3797.22,"qty":2.18000000}],"checksum":1838245065,"timestamp":"2024-06-01T17:52:09.354010Z"}]}
{"channel":"book","type":"update","data":[{"symbol":"ETH/USD","bids":[],"asks":[{"price":3795.91,"qty":0.77390109}],"checksum":449818721,"timestamp":"2024-06-01T17:52:09.383758Z"}]}
{"channel":"book","type":"update","data":[{"symbol":"ETH/USD","bids":[{"price":3795.89,"qty":26.34422762},{"price":3795.90,"qty":0.00936773}],"asks":[],"checksum":1980941842,"timestamp":"2024-06-01T17:52:09.389619Z"}]}
{"channel":"book","type":"update","data":[{"symbol":"ETH/USD","bids":[{"price":3795.89,"qty":0.00000000},{"price":3794.33,"qty":3.95290248}],"asks":[],"checksum":3110226674,"timestamp":"2024-06-01T17:52:09.392234Z"}]}
{"channel":"book","type":"update","data":[{"symbol":"ETH/USD","bids":[],"asks":[{"price":3796.15,"qty":26.34250747}],"checksum":3162457312,"timestamp":"2024-06-01T17:52:09.396527Z"}]}
{"channel":"book","type":"update","data":[{"symbol":"ETH/USD","bids":[{"price":3795.87,"qty":26.34441204}],"asks":[],"checksum":3653963376,"timestamp":"2024-06-01T17:52:09.396609Z"}]}
{"channel":"book","type":"update","data":[{"symbol":"ETH/USD","bids":[],"asks":[{"price":3795.92,"qty":0.00000000},{"price":3797.21,"qty":3.00000000}],"checksum":1808290479,"timestamp":"2024-06-01T17:52:09.399924Z"}]}
{"channel":"book","type":"update","data":[{"symbol":"ETH/USD","bids":[],"asks":[{"price":3796.15,"qty":0.00000000},{"price":3797.22,"qty":2.18000000}],"checksum":629339622,"timestamp":"2024-06-01T17:52:09.404342Z"}]}
{"channel":"book","type":"update","data":[{"symbol":"ETH/USD","bids":[{"price":3795.87,"qty":0.00000000},{"price":3794.33,"qty":3.95290248}],"asks":[],"checksum":1275899579,"timestamp":"2024-06-01T17:52:09.404398Z"}]}
{"channel":"book","type":"update","data":[{"symbol":"ETH/USD","bids":[{"price":3794.52,"qty":54.55185053}],"asks":[],"checksum":1851480657,"timestamp":"2024-06-01T17:52:09.440371Z"}]}
{"channel":"book","type":"update","data":[{"symbol":"ETH/USD","bids":[{"price":3794.34,"qty":26.34227483}],"asks":[],"checksum":3942017763,"timestamp":"2024-06-01T17:52:09.440683Z"}]}
{"channel":"book","type":"update","data":[{"symbol":"ETH/USD","bids":[],"asks":[{"price":3796.19,"qty":26.34223416}],"checksum":190669694,"timestamp":"2024-06-01T17:52:09.456645Z"}]}
{"channel":"book","type":"update","data":[{"symbol":"ETH/USD","bids":[{"price":3795.89,"qty":26.34424607}],"asks":[],"checksum":1779545125,"timestamp":"2024-06-01T17:52:09.456661Z"}]}
{"channel":"book","type":"update","data":[{"symbol":"ETH/USD","bids":[{"price":3795.61,"qty":26.34620285}],"asks":[],"checksum":1179837143,"timestamp":"2024-06-01T17:52:09.456778Z"}]}
{"channel":"book","type":"update","data":[{"symbol":"ETH/USD","bids":[{"price":3795.90,"qty":0.00000000},{"price":3794.52,"qty":54.55185053},{"price":3795.81,"qty":0.00936795}],"asks":[],"checksum":910897667,"timestamp":"2024-06-01T17:52:09.461810Z"}]}
{"channel":"book","type":"update","data":[{"symbol":"ETH/USD","bids":[{"price":3795.81,"qty":0.00000000},{"price":3794.52,"qty":54.55185053},{"price":3795.90,"qty":0.00936773}],"asks":[],"checksum":1179837143,"timestamp":"2024-06-01T17:52:09.533479Z"}]}
{"channel":"book","type":"update","data":[{"symbol":"ETH/USD","bids":[],"asks":[{"price":3796.66,"qty":2.08733494}],"checksum":371639030,"timestamp":"2024-06-01T17:52:09.775923Z"}]}
{"channel":"book","type":"update","data":[{"symbol":"ETH/USD","bids":[],"asks":[{"price":3797.10,"qty":26.01533100}],"checksum":353125240,"timestamp":"2024-06-01T17:52:09.775975Z"}]}
{"channel":"book","type":"update","data":[{"symbol":"ETH/USD","bids":[],"asks":[{"price":3796.19,"qty":0.00000000},{"price":3797.11,"qty":10.81226191}],"checksum":2112334049,"timestamp":"2024-06-01T17:52:09.806264Z"}]}
{"channel":"book","type":"update","data":[{"symbol":"ETH/USD","bids":[{"price":3795.27,"qty":3.95144465}],"asks":[],"checksum":3608098340,"timestamp":"2024-06-01T17:52:09.810435Z"}]}
{"channel":"book","type":"update","data":[{"symbol":"ETH/USD","bids":[{"price":3795.08,"qty":3.95144465}],"asks":[],"checksum":1538047964,"timestamp":"2024-06-01T17:52:09.811422Z"}]}
{"channel":"book","type":"update","data":[{"symbol":"ETH/USD","bids":[],"asks":[{"price":3796.21,"qty":26.34208730}],"checksum":262076568,"timestamp":"2024-06-01T17:52:09.812738Z"}]}
{"channel":"book","type":"update","data":[{"symbol":"ETH/USD","bids":[{"price":3795.34,"qty":26.34804937}],"asks":[],"checksum":3813147422,"timestamp":"2024-06-01T17:52:09.812856Z"}]}
{"channel":"book","type":"update","data":[{"symbol":"ETH/USD","bids":[{"price":3795.89,"qty":0.00000000},{"price":3795.07,"qty":3.30000000}],"asks":[],"checksum":51202554,"timestamp":"2024-06-01T17:52:09.871731Z"}]}
{"channel":"book","type":"update","data":[{"symbol":"ETH/USD","bids":[],"asks":[{"price":3796.14,"qty":26.34258256}],"checksum":98316690,"timestamp":"2024-06-01T17:52:09.876050Z"}]}
{"channel":"book","type":"update","data":[{"symbol":"ETH/USD","bids":[{"price":3795.84,"qty":26.34462064}],"asks":[],"checksum":85164130,"timestamp":"2024-06-01T17:52:09.876127Z"}]}
{"channel":"book","type":"update","data":[{"symbol":"ETH/USD","bids":[{"price":3795.84,"qty":0.00000000},{"price":3795.07,"qty":3.30000000}],"asks":[],"checksum":98316690,"timestamp":"2024-06-01T17:52:09.902968Z"}]}
{"channel":"book","type":"update","data":[{"symbol":"ETH/USD","bids":[{"price":3795.90,"qty":0.00000000},{"price":3795.00,"qty":6.00000000},{"price":3795.85,"qty":0.00936785}],"asks":[],"checksum":2551316746,"timestamp":"2024-06-01T17:52:09.926023Z"}]}
{"channel":"book","type":"update","data":[{"symbol":"ETH/USD","bids":[],"asks":[{"price":3796.14,"qty":0.00000000},{"price":3797.10,"qty":26.01533100}],"checksum":2663610722,"timestamp":"2024-06-01T17:52:09.931014Z"}]}
{"channel":"book","type":"update","data":[{"symbol":"ETH/USD","bids":[],"asks":[{"price":3796.17,"qty":26.34240869}],"checksum":2240366807,"timestamp":"2024-06-01T17:52:09.935006Z"}]}
{"channel":"book","type":"update","data":[{"symbol":"ETH/USD","bids":[{"price":3795.86,"qty":26.34444676}],"asks":[],"checksum":954192219,"timestamp":"2024-06-01T17:52:09.935062Z"}]}
{"channel":"book","type":"update","data":[{"symbol":"ETH/USD","bids":[{"price":3795.86,"qty":25.79444676}],"asks":[],"checksum":1390696198,"timestamp":"2024-06-01T17:52:09.970899Z"}]}
{"channel":"book","type":"update","data":[{"symbol":"ETH/USD","bids":[{"price":3795.86,"qty":0.00000000},{"price":3795.07,"qty":3.30000000}],"asks":[],"checksum":2240366807,"timestamp":"2024-06-01T17:52:09.974249Z"}]}
{"channel":"book","type":"update","data":[{"symbol":"ETH/USD","bids":[],"asks":[{"price":3795.91,"qty":3.77390109}],"checksum":4075941171,"timestamp":"2024-06-01T17:52:09.978357Z"}]}
{"channel":"book","type":"update","data":[{"symbol":"ETH/USD","bids":[],"asks":[{"price":3796.17,"qty":0.00000000},{"price":3797.10,"qty":26.01533100}],"checksum":3921403014,"timestamp":"2024-06-01T17:52:09.986612Z"}]}
{"channel":"book","type":"update","data":[{"symbol":"ETH/USD","bids":[],"asks":[{"price":3796.19,"qty":26.34223921}],"checksum":3634112839,"timestamp":"2024-06-01T17:52:09.991731Z"}]}
{"channel":"book","type":"update","data":[{"symbol":"ETH/USD","bids":[{"price":3795.88,"qty":26.34428839}],"asks":[],"checksum":103086582,"timestamp":"2024-06-01T17:52:09.991855Z"}]}
{"channel":"book","type":"update","data":[{"symbol":"ETH/USD","bids":[{"price":3795.85,"qty":0.00000000},{"price":3795.07,"qty":3.30000000},{"price":3795.87,"qty":0.00936780}],"asks":[],"checksum":3428139221,"timestamp":"2024-06-01T17:52:09.993017Z"}]}
{"channel":"book","type":"update","data":[{"symbol":"ETH/USD","bids":[],"asks":[{"price":3795.91,"qty":0.77390109}],"checksum":1799691793,"timestamp":"2024-06-01T17:52:09.995150Z"}]}
{"channel":"book","type":"update","data":[{"symbol":"ETH/USD","bids":[{"price":3795.88,"qty":0.00000000},{"price":3795.07,"qty":3.30000000}],"asks":[],"checksum":1834883362,"timestamp":"2024-06-01T17:52:10.000072Z"}]}
{"channel":"book","type":"update","data":[{"symbol":"ETH/USD","bids":[{"price":3795.26,"qty":0.00000000},{"price":3795.00,"qty":6.00000000},{"price":3795.90,"qty":0.52688426}],"asks":[],"checksum":747204830,"timestamp":"2024-06-01T17:52:10.001933Z"}]}
{"channel":"book","type":"update","data":[{"symbol":"ETH/USD","bids":[{"price":3795.87,"qty":0.00000000},{"price":3795.00,"qty":6.00000000},{"price":3795.81,"qty":0.00936795}],"asks":[],"checksum":1749023695,"timestamp":"2024-06-01T17:52:10.062660Z"}]}
{"channel":"book","type":"update","data":[{"symbol":"ETH/USD","bids":[],"asks":[{"price":3796.19,"qty":0.00000000},{"price":3797.10,"qty":26.01533100}],"checksum":1494748686,"timestamp":"2024-06-01T17:52:10.122203Z"}]}
{"channel":"book","type":"update","data":[{"symbol":"ETH/USD","bids":[{"price":3795.86,"qty":26.34442539}],"asks":[],"checksum":1995447492,"timestamp":"2024-06-01T17:52:10.126849Z"}]}
{"channel":"book","type":"update","data":[{"symbol":"ETH/USD","bids":[],"asks":[{"price":3796.17,"qty":26.34237620}],"checksum":227638773,"timestamp":"2024-06-01T17:52:10.126904Z"}]}
{"channel":"book","type":"update","data":[{"symbol":"ETH/USD","bids":[{"price":3795.81,"qty":0.00000000},{"price":3795.07,"qty":3.30000000},{"price":3795.82,"qty":0.00936792}],"asks":[],"checksum":2986297766,"timestamp":"2024-06-01T17:52:10.132099Z"}]}
{"channel":"book","type":"update","data":[{"symbol":"ETH/USD","bids":[{"price":3795.82,"qty":0.00000000},{"price":3795.07,"qty":3.30000000},{"price":3795.87,"qty":0.00936780}],"asks":[],"checksum":1898572054,"timestamp":"2024-06-01T17:52:10.204981Z"}]}
{"channel":"book","type":"update","data":[{"symbol":"ETH/USD","bids":[],"asks":[{"price":3796.17,"qty":0.00000000},{"price":3797.10,"qty":26.01533100}],"checksum":172525607,"timestamp":"2024-06-01T17:52:10.230588Z"}]}
{"channel":"book","type":"update","data":[{"symbol":"ETH/USD","bids":[],"asks":[{"price":3796.15,"qty":26.34251845}],"checksum":317182488,"timestamp":"2024-06-01T17:52:10.236708Z"}]}
{"channel":"book","type":"update","data":[{"symbol":"ETH/USD","bids":[{"price":3795.87,"qty":0.00000000},{"price":3795.07,"qty":3.30000000},{"price":3795.88,"qty":0.00936666}],"asks":[],"checksum":2001779043,"timestamp":"2024-06-01T17:52:10.281659Z"}]}
{"channel":"book","type":"update","data":[{"symbol":"ETH/USD","bids":[],"asks":[{"price":3796.15,"qty":0.00000000},{"price":3797.10,"qty":26.01533100}],"checksum":1879040860,"timestamp":"2024-06-01T17:52:10.292807Z"}]}
{"channel":"book","type":"update","data":[{"symbol":"ETH/USD","bids":[{"price":3795.86,"qty":0.00000000},{"price":3795.07,"qty":3.30000000}],"asks":[],"checksum":438057031,"timestamp":"2024-06-01T17:52:10.292931Z"}]}
{"channel":"book","type":"update","data":[{"symbol":"ETH/USD","bids":[],"asks":[{"price":3796.17,"qty":26.34235132}],"checksum":304771442,"timestamp":"2024-06-01T17:52:10.297310Z"}]}
{"channel":"book","type":"update","data":[{"symbol":"ETH/USD","bids":[{"price":3795.87,"qty":26.34438587}],"asks":[],"checksum":1936431313,"timestamp":"2024-06-01T17:52:10.297333Z"}]}
{"channel":"book","type":"update","data":[{"symbol":"ETH/USD","bids":[],"asks":[{"price":3796.17,"qty":0.00000000},{"price":3797.10,"qty":26.01533100}],"checksum":634415803,"timestamp":"2024-06-01T17:52:10.302143Z"}]}
{"channel":"book","type":"update","data":[{"symbol":"ETH/USD","bids":[{"price":3795.87,"qty":0.00000000},{"price":3795.07,"qty":3.30000000}],"asks":[],"checksum":438057031,"timestamp":"2024-06-01T17:52:10.315493Z"}]}
{"channel":"book","type":"update","data":[{"symbol":"ETH/USD","bids":[{"price":3795.88,"qty":0.00000000},{"price":3795.00,"qty":6.00000000},{"price":3795.81,"qty":0.00936683}],"asks":[],"checksum":2837297186,"timestamp":"2024-06-01T17:52:10.350814Z"}]}
{"channel":"book","type":"update","data":[{"symbol":"ETH/USD","bids":[{"price":3795.81,"qty":0.00000000},{"price":3795.00,"qty":6.00000000},{"price":3795.82,"qty":0.00936681}],"asks":[],"checksum":124322817,"timestamp":"2024-06-01T17:52:10.413997Z"}]}
{"channel":"book","type":"update","data":[{"symbol":"ETH/USD","bids":[],"asks":[{"price":3796.15,"qty":26.34251201}],"checksum":4195598629,"timestamp":"2024-06-01T17:52:10.495351Z"}]}
{"channel":"book","type":"update","data":[{"symbol":"ETH/USD","bids":[{"price":3795.86,"qty":26.34445700}],"asks":[],"checksum":2065660638,"timestamp":"2024-06-01T17:52:10.495400Z"}]}
{"channel":"book","type":"update","data":[{"symbol":"ETH/USD","bids":[{"price":3795.82,"qty":0.00000000},{"price":3795.07,"qty":3.30000000},{"price":3795.83,"qty":0.00936679}],"asks":[],"checksum":726369087,"timestamp":"2024-06-01T17:52:10.533275Z"}]}
{"channel":"book","type":"update","data":[{"symbol":"ETH/USD","bids":[],"asks":[{"price":3796.15,"qty":0.00000000},{"price":3797.10,"qty":26.01533100}],"checksum":397745451,"timestamp":"2024-06-01T17:52:10.579518Z"}]}
{"channel":"book","type":"update","data":[{"symbol":"ETH/USD","bids":[],"asks":[{"price":3796.17,"qty":26.34236449}],"checksum":4086090633,"timestamp":"2024-06-01T17:52:10.583802Z"}]}
{"channel":"book","type":"update","data":[{"symbol":"ETH/USD","bids":[{"price":3795.83,"qty":0.00000000},{"price":3795.07,"qty":3.30000000},{"price":3795.87,"qty":0.00936670}],"asks":[],"checksum":1712410150,"timestamp":"2024-06-01T17:52:10.685325Z"}]}
{"channel":"book","type":"update","data":[{"symbol":"ETH/USD","bids":[{"price":3795.86,"qty":0.00000000},{"price":3795.07,"qty":3.30000000}],"asks":[],"checksum":722630178,"timestamp":"2024-06-01T17:52:10.876786Z"}]}
{"channel":"book","type":"update","data":[{"symbol":"ETH/USD","bids":[],"asks":[{"price":3796.48,"qty":26.34019133}],"checksum":3233944524,"timestamp":"2024-06-01T17:52:10.881890Z"}]}
{"channel":"book","type":"update","data":[{"symbol":"ETH/USD","bids":[{"price":3795.88,"qty":26.34431992}],"asks":[],"checksum":3609494780,"timestamp":"2024-06-01T17:52:10.882042Z"}]}
{"channel":"book","type":"update","data":[{"symbol":"ETH/USD","bids":[],"asks":[{"price":3796.17,"qty":0.00000000},{"price":3796.83,"qty":3.00000000}],"checksum":3700443031,"timestamp":"2024-06-01T17:52:10.922876Z"}]}
{"channel":"book","type":"update","data":[{"symbol":"ETH/USD","bids":[{"price":3795.88,"qty":0.00000000},{"price":3795.07,"qty":3.30000000}],"asks":[],"checksum":2950584579,"timestamp":"2024-06-01T17:52:10.922928Z"}]}
{"channel":"book","type":"update","data":[{"symbol":"ETH/USD","bids":[{"price":3795.87,"qty":0.00000000},{"price":3795.00,"qty":6.00000000},{"price":3795.81,"qty":0.00936686}],"asks":[],"checksum":483591619,"timestamp":"2024-06-01T17:52:10.927374Z"}]}
{"channel":"book","type":"update","data":[{"symbol":"ETH/USD","bids":[{"price":3795.87,"qty":26.34439369}],"asks":[],"checksum":144528555,"timestamp":"2024-06-01T17:52:10.945120Z"}]}
{"channel":"book","type":"update","data":[{"symbol":"ETH/USD","bids":[],"asks":[{"price":3796.16,"qty":26.34244389}],"checksum":742584925,"timestamp":"2024-06-01T17:52:10.945235Z"}]}
{"channel":"book","type":"update","data":[{"symbol":"ETH/USD","bids":[{"price":3795.87,"qty":0.00000000},{"price":3795.07,"qty":3.30000000}],"asks":[],"checksum":2010535216,"timestamp":"2024-06-01T17:52:10.964830Z"}]}
{"channel":"book","type":"update","data":[{"symbol":"ETH/USD","bids":[],"asks":[{"price":3796.16,"qty":0.00000000},{"price":3796.83,"qty":3.00000000}],"checksum":483591619,"timestamp":"2024-06-01T17:52:10.964864Z"}]}
{"channel":"book","type":"update","data":[{"symbol":"ETH/USD","bids":[],"asks":[{"price":3796.16,"qty":26.34243863}],"checksum":182195915,"timestamp":"2024-06-01T17:52:11.068245Z"}]}
{"channel":"book","type":"update","data":[{"symbol":"ETH/USD","bids":[{"price":3795.86,"qty":26.34445955}],"asks":[],"checksum":3025881847,"timestamp":"2024-06-01T17:52:11.068265Z"}]}
{"channel":"book","type":"update","data":[{"symbol":"ETH/USD","bids":[{"price":3795.81,"qty":0.00000000},{"price":3795.07,"qty":3.30000000},{"price":3795.87,"qty":0.00936671}],"asks":[],"checksum":3787408788,"timestamp":"2024-06-01T17:52:11.147052Z"}]}
{"channel":"book","type":"update","data":[{"symbol":"ETH/USD","bids":[],"asks":[{"price":3796.16,"qty":0.00000000},{"price":3796.83,"qty":3.00000000}],"checksum":4017275573,"timestamp":"2024-06-01T17:52:11.226644Z"}]}
{"channel":"book","type":"update","data":[{"symbol":"ETH/USD","bids":[],"asks":[{"price":3796.15,"qty":26.34253873}],"checksum":302086517,"timestamp":"2024-06-01T17:52:11.230661Z"}]}
{"channel":"book","type":"update","data":[{"symbol":"ETH/USD","bids":[{"price":3795.12,"qty":2.15300000}],"asks":[],"checksum":371217091,"timestamp":"2024-06-01T17:52:11.293221Z"}]}
{"channel":"book","type":"update","data":[{"symbol":"ETH/USD","bids":[],"asks":[{"price":3796.15,"qty":0.00000000},{"price":3796.83,"qty":3.00000000}],"checksum":3948144899,"timestamp":"2024-06-01T17:52:11.438116Z"}]}
{"channel":"book","type":"update","data":[{"symbol":"ETH/USD","bids":[{"price":3795.86,"qty":0.00000000},{"price":3795.08,"qty":3.95144465}],"asks":[],"checksum":4125771815,"timestamp":"2024-06-01T17:52:11.438236Z"}]}
{"channel":"book","type":"update","data":[{"symbol":"ETH/USD","bids":[],"asks":[{"price":3796.17,"qty":26.34235387}],"checksum":699117772,"timestamp":"2024-06-01T17:52:11.442535Z"}]}
{"channel":"book","type":"update","data":[{"symbol":"ETH/USD","bids":[{"price":3795.87,"qty":26.35372626}],"asks":[],"checksum":2917849780,"timestamp":"2024-06-01T17:52:11.442630Z"}]}
{"channel":"book","type":"update","data":[{"symbol":"ETH/USD","bids":[{"price":3795.87,"qty":26.34435955},{"price":3795.88,"qty":0.00936669}],"asks":[],"checksum":1470837641,"timestamp":"2024-06-01T17:52:11.492304Z"}]}
{"channel":"book","type":"update","data":[{"symbol":"ETH/USD","bids":[{"price":3795.87,"qty":0.00000000},{"price":3795.08,"qty":3.95144465}],"asks":[],"checksum":2461603186,"timestamp":"2024-06-01T17:52:11.508016Z"}]}
{"channel":"book","type":"update","data":[{"symbol":"ETH/USD","bids":[{"price":3795.88,"qty":26.35365510}],"asks":[],"checksum":1083578518,"timestamp":"2024-06-01T17:52:11.512486Z"}]}
{"channel":"book","type":"update","data":[{"symbol":"ETH/USD","bids":[{"price":3795.88,"qty":26.34428841},{"price":3795.81,"qty":0.00936687}],"asks":[],"checksum":3229712740,"timestamp":"2024-06-01T17:52:11.561412Z"}]}
{"channel":"book","type":"update","data":[{"symbol":"ETH/USD","bids":[{"price":3795.88,"qty":0.00000000},{"price":3795.08,"qty":3.95144465}],"asks":[],"checksum":2594630668,"timestamp":"2024-06-01T17:52:11.608834Z"}]}
{"channel":"book","type":"update","data":[{"symbol":"ETH/USD","bids":[],"asks":[{"price":3796.17,"qty":0.00000000},{"price":3796.83,"qty":3.00000000}],"checksum":1189549287,"timestamp":"2024-06-01T17:52:11.608963Z"}]}
{"channel":"book","type":"update","data":[{"symbol":"ETH/USD","bids":[{"price":3795.90,"qty":26.87109775}],"asks":[],"checksum":2962374531,"timestamp":"2024-06-01T17:52:11.614124Z"}]}
{"channel":"book","type":"update","data":[{"symbol":"ETH/USD","bids":[],"asks":[{"price":3796.19,"qty":26.34220108}],"checksum":386602476,"timestamp":"2024-06-01T17:52:11.614264Z"}]}
{"channel":"book","type":"update","data":[{"symbol":"ETH/USD","bids":[],"asks":[{"price":3796.19,"qty":0.00000000},{"price":3796.83,"qty":3.00000000}],"checksum":2962374531,"timestamp":"2024-06-01T17:52:11.681086Z"}]}
{"channel":"book","type":"update","data":[{"symbol":"ETH/USD","bids":[{"price":3795.90,"qty":0.52688426}],"asks":[],"checksum":1189549287,"timestamp":"2024-06-01T17:52:11.681280Z"}]}
{"channel":"book","type":"update","data":[{"symbol":"ETH/USD","bids":[],"asks":[{"price":3796.17,"qty":26.34234070}],"checksum":2235470251,"timestamp":"2024-06-01T17:52:11.686011Z"}]}
{"channel":"book","type":"update","data":[{"symbol":"ETH/USD","bids":[{"price":3795.88,"qty":26.34434667}],"asks":[],"checksum":2666418418,"timestamp":"2024-06-01T17:52:11.686043Z"}]}
{"channel":"book","type":"update","data":[{"symbol":"ETH/USD","bids":[{"price":3795.81,"qty":0.00000000},{"price":3795.08,"qty":3.95144465},{"price":3795.89,"qty":0.00936667}],"asks":[],"checksum":1480515831,"timestamp":"2024-06-01T17:52:11.735744Z"}]}
{"channel":"book","type":"update","data":[{"symbol":"ETH/USD","bids":[],"asks":[{"price":3796.17,"qty":0.00000000},{"price":3796.83,"qty":3.00000000}],"checksum":664220873,"timestamp":"2024-06-01T17:52:12.047451Z"}]}
{"channel":"book","type":"update","data":[{"symbol":"ETH/USD","bids":[],"asks":[{"price":3796.16,"qty":26.34245817}],"checksum":2123887578,"timestamp":"2024-06-01T17:52:12.051946Z"}]}
{"channel":"book","type":"update","data":[{"symbol":"ETH/USD","bids":[{"price":3795.52,"qty":3.00000000}],"asks":[],"checksum":2054243850,"timestamp":"2024-06-01T17:52:12.144500Z"}]}
{"channel":"book","type":"update","data":[{"symbol":"ETH/USD","bids":[],"asks":[{"price":3796.16,"qty":0.00000000},{"price":3796.83,"qty":3.00000000}],"checksum":594641177,"timestamp":"2024-06-01T17:52:12.145285Z"}]}
{"channel":"book","type":"update","data":[{"symbol":"ETH/USD","bids":[{"price":3795.88,"qty":0.00000000},{"price":3795.12,"qty":2.15300000}],"asks":[],"checksum":694014146,"timestamp":"2024-06-01T17:52:12.145445Z"}]}
{"channel":"book","type":"update","data":[{"symbol":"ETH/USD","bids":[{"price":3795.90,"qty":26.87109775}],"asks":[],"checksum":3744005030,"timestamp":"2024-06-01T17:52:12.150070Z"}]}
{"channel":"book","type":"update","data":[{"symbol":"ETH/USD","bids":[],"asks":[{"price":3796.19,"qty":26.34221845}],"checksum":2068881814,"timestamp":"2024-06-01T17:52:12.150114Z"}]}
{"channel":"book","type":"update","data":[{"symbol":"ETH/USD","bids":[],"asks":[{"price":3796.66,"qty":0.00000000},{"price":3796.83,"qty":3.00000000}],"checksum":1217445675,"timestamp":"2024-06-01T17:52:12.166679Z"}]}
{"channel":"book","type":"update","data":[{"symbol":"ETH/USD","bids":[{"price":3795.89,"qty":0.00000000},{"price":3795.08,"qty":3.95144465},{"price":3795.81,"qty":0.00936900}],"asks":[],"checksum":180312027,"timestamp":"2024-06-01T17:52:12.206235Z"}]}
{"channel":"book","type":"update","data":[{"symbol":"ETH/USD","bids":[],"asks":[{"price":3796.19,"qty":0.00000000},{"price":3797.11,"qty":10.81226191}],"checksum":1504156444,"timestamp":"2024-06-01T17:52:12.252926Z"}]}
{"channel":"book","type":"update","data":[{"symbol":"ETH/USD","bids":[],"asks":[{"price":3796.18,"qty":26.34232382}],"checksum":521233217,"timestamp":"2024-06-01T17:52:12.256910Z"}]}
{"channel":"book","type":"update","data":[{"symbol":"ETH/USD","bids":[{"price":3795.90,"qty":0.52688426}],"asks":[],"checksum":3998615200,"timestamp":"2024-06-01T17:52:12.311931Z"}]}
{"channel":"book","type":"update","data":[{"symbol":"ETH/USD","bids":[{"price":3795.89,"qty":26.34422296}],"asks":[],"checksum":1349470131,"timestamp":"2024-06-01T17:52:12.316945Z"}]}
{"channel":"book","type":"update","data":[{"symbol":"ETH/USD","bids":[{"price":3795.52,"qty":0.00000000},{"price":3795.12,"qty":2.15300000}],"asks":[],"checksum":1418326627,"timestamp":"2024-06-01T17:52:12.329767Z"}]}
{"channel":"book","type":"update","data":[{"symbol":"ETH/USD","bids":[],"asks":[{"price":3796.18,"qty":0.00000000},{"price":3797.11,"qty":10.81226191}],"checksum":2345653964,"timestamp":"2024-06-01T17:52:12.333576Z"}]}
{"channel":"book","type":"update","data":[{"symbol":"ETH/USD","bids":[],"asks":[{"price":3796.17,"qty":26.34236334}],"checksum":3533631616,"timestamp":"2024-06-01T17:52:12.337980Z"}]}
{"channel":"book","type":"update","data":[{"symbol":"ETH/USD","bids":[{"price":3795.89,"qty":0.00000000},{"price":3795.08,"qty":3.95144465}],"asks":[],"checksum":1338364063,"timestamp":"2024-06-01T17:52:12.347595Z"}]}
{"channel":"book","type":"update","data":[{"symbol":"ETH/USD","bids":[],"asks":[{"price":3796.17,"qty":0.00000000},{"price":3797.11,"qty":10.81226191}],"checksum":2917043171,"timestamp":"2024-06-01T17:52:12.347661Z"}]}
{"channel":"book","type":"update","data":[{"symbol":"ETH/USD","bids":[{"price":3795.12,"qty":0.00000000},{"price":3795.07,"qty":3.30000000}],"asks":[],"checksum":1086494020,"timestamp":"2024-06-01T17:52:12.470198Z"}]}
{"channel":"book","type":"update","data":[{"symbol":"ETH/USD","bids":[],"asks":[{"price":3796.15,"qty":26.34251876}],"checksum":2200599678,"timestamp":"2024-06-01T17:52:12.494515Z"}]}
{"channel":"book","type":"update","data":[{"symbol":"ETH/USD","bids":[{"price":3795.87,"qty":26.34441940}],"asks":[],"checksum":220669996,"timestamp":"2024-06-01T17:52:12.494744Z"}]}
{"channel":"book","type":"update","data":[{"symbol":"ETH/USD","bids":[{"price":3795.87,"qty":0.00000000},{"price":3795.07,"qty":3.30000000}],"asks":[],"checksum":2200599678,"timestamp":"2024-06-01T17:52:12.523969Z"}]}
{"channel":"book","type":"update","data":[{"symbol":"ETH/USD","bids":[],"asks":[{"price":3796.15,"qty":0.00000000},{"price":3797.11,"qty":10.81226191}],"checksum":1086494020,"timestamp":"2024-06-01T17:52:12.523992Z"}]}
{"channel":"book","type":"update","data":[{"symbol":"ETH/USD","bids":[{"price":3795.81,"qty":0.00000000},{"price":3795.00,"qty":6.00000000},{"price":3795.88,"qty":0.00936883}],"asks":[],"checksum":2493989031,"timestamp":"2024-06-01T17:52:12.562333Z"}]}
{"channel":"book","type":"update","data":[{"symbol":"ETH/USD","bids":[{"price":3795.09,"qty":2.15300000}],"asks":[],"checksum":2269175155,"timestamp":"2024-06-01T17:52:12.568747Z"}]}
{"channel":"book","type":"update","data":[{"symbol":"ETH/USD","bids":[{"price":3795.86,"qty":26.34445892}],"asks":[],"checksum":3235978535,"timestamp":"2024-06-01T17:52:12.596337Z"}]}
{"channel":"book","type":"update","data":[{"symbol":"ETH/USD","bids":[],"asks":[{"price":3796.14,"qty":26.34257409}],"checksum":661290467,"timestamp":"2024-06-01T17:52:12.596516Z"}]}
{"channel":"book","type":"update","data":[{"symbol":"ETH/USD","bids":[{"price":3795.88,"qty":0.00000000},{"price":3795.08,"qty":3.95144465},{"price":3795.81,"qty":0.00936900}],"asks":[],"checksum":370445618,"timestamp":"2024-06-01T17:52:12.617124Z"}]}
{"channel":"book","type":"update","data":[{"symbol":"ETH/USD","bids":[{"price":3795.86,"qty":0.00000000},{"price":3795.08,"qty":3.95144465}],"asks":[],"checksum":1617480606,"timestamp":"2024-06-01T17:52:12.629634Z"}]}
{"channel":"book","type":"update","data":[{"symbol":"ETH/USD","bids":[],"asks":[{"price":3796.14,"qty":0.00000000},{"price":3797.11,"qty":10.81226191}],"checksum":1394935952,"timestamp":"2024-06-01T17:52:12.629704Z"}]}
{"channel":"book","type":"update","data":[{"symbol":"ETH/USD","bids":[],"asks":[{"price":3796.16,"qty":26.34244237}],"checksum":1229252444,"timestamp":"2024-06-01T17:52:12.693696Z"}]}
{"channel":"book","type":"update","data":[{"symbol":"ETH/USD","bids":[{"price":3795.88,"qty":26.34432719}],"asks":[],"checksum":3633708044,"timestamp":"2024-06-01T17:52:12.693711Z"}]}
{"channel":"book","type":"update","data":[{"symbol":"ETH/USD","bids":[],"asks":[{"price":3796.16,"qty":0.00000000},{"price":3797.11,"qty":10.81226191}],"checksum":1247613816,"timestamp":"2024-06-01T17:52:12.768798Z"}]}
{"channel":"book","type":"update","data":[{"symbol":"ETH/USD","bids":[{"price":3795.88,"qty":0.00000000},{"price":3795.08,"qty":3.95144465}],"asks":[],"checksum":1394935952,"timestamp":"2024-06-01T17:52:12.768907Z"}]}
{"channel":"book","type":"update","data":[{"symbol":"ETH/USD","bids":[{"price":3795.90,"qty":26.87109775}],"asks":[],"checksum":3256875392,"timestamp":"2024-06-01T17:52:12.774592Z"}]}
{"channel":"book","type":"update","data":[{"symbol":"ETH/USD","bids":[],"asks":[{"price":3796.19,"qty":26.34221845}],"checksum":2433168711,"timestamp":"2024-06-01T17:52:12.774622Z"}]}
{"channel":"book","type":"update","data":[{"symbol":"ETH/USD","bids":[{"price":3795.81,"qty":0.00000000},{"price":3795.07,"qty":3.30000000},{"price":3795.89,"qty":0.00936880}],"asks":[],"checksum":4169689219,"timestamp":"2024-06-01T17:52:12.827709Z"}]}
{"channel":"book","type":"update","data":[{"symbol":"ETH/USD","bids":[{"price":3795.89,"qty":0.00000000},{"price":3795.07,"qty":3.30000000},{"price":3795.81,"qty":0.00936900}],"asks":[],"checksum":2433168711,"timestamp":"2024-06-01T17:52:12.882889Z"}]}
{"channel":"book","type":"update","data":[{"symbol":"ETH/USD","bids":[{"price":3795.90,"qty":0.52688426}],"asks":[],"checksum":3723469759,"timestamp":"2024-06-01T17:52:13.107783Z"}]}
{"channel":"book","type":"update","data":[{"symbol":"ETH/USD","bids":[],"asks":[{"price":3796.19,"qty":0.00000000},{"price":3797.11,"qty":10.81226191}],"checksum":1394935952,"timestamp":"2024-06-01T17:52:13.107804Z"}]}
{"channel":"book","type":"update","data":[{"symbol":"ETH/USD","bids":[{"price":3795.87,"qty":26.34439365}],"asks":[],"checksum":3800996511,"timestamp":"2024-06-01T17:52:13.112617Z"}]}
{"channel":"book","type":"update","data":[{"symbol":"ETH/USD","bids":[],"asks":[{"price":3796.16,"qty":26.34244083}],"checksum":4147507658,"timestamp":"2024-06-01T17:52:13.112664Z"}]}
{"channel":"book","type":"update","data":[{"symbol":"ETH/USD","bids":[{"price":3795.81,"qty":0.00000000},{"price":3795.08,"qty":3.95144465},{"price":3795.88,"qty":0.00936883}],"asks":[],"checksum":113538236,"timestamp":"2024-06-01T17:52:13.184842Z"}]}
{"channel":"book","type":"update","data":[{"symbol":"ETH/USD","bids":[],"asks":[{"price":3796.16,"qty":0.00000000},{"price":3797.11,"qty":10.81226191}],"checksum":327098345,"timestamp":"2024-06-01T17:52:13.231021Z"}]}
{"channel":"book","type":"update","data":[{"symbol":"ETH/USD","bids":[{"price":3795.87,"qty":0.00000000},{"price":3795.08,"qty":3.95144465}],"asks":[],"checksum":2269175155,"timestamp":"2024-06-01T17:52:13.231052Z"}]}
{"channel":"book","type":"update","data":[{"symbol":"ETH/USD","bids":[],"asks":[{"price":3796.19,"qty":26.34221164}],"checksum":3015591706,"timestamp":"2024-06-01T17:52:13.235230Z"}]}
{"channel":"book","type":"update","data":[{"symbol":"ETH/USD","bids":[{"price":3795.90,"qty":26.87109775}],"asks":[],"checksum":2996810281,"timestamp":"2024-06-01T17:52:13.235311Z"}]}
{"channel":"book","type":"update","data":[{"symbol":"ETH/USD","bids":[{"price":3795.88,"qty":0.00000000},{"price":3795.07,"qty":3.30000000},{"price":3795.81,"qty":0.00936900}],"asks":[],"checksum":1727686602,"timestamp":"2024-06-01T17:52:13.294214Z"}]}
{"channel":"book","type":"update","data":[{"symbol":"ETH/USD","bids":[{"price":3795.90,"qty":0.52688426}],"asks":[],"checksum":1742443257,"timestamp":"2024-06-01T17:52:13.585348Z"}]}
{"channel":"book","type":"update","data":[{"symbol":"ETH/USD","bids":[],"asks":[{"price":3796.19,"qty":0.00000000},{"price":3797.11,"qty":10.81226191}],"checksum":1394935952,"timestamp":"2024-06-01T17:52:13.585401Z"}]}
{"channel":"book","type":"update","data":[{"symbol":"ETH/USD","bids":[{"price":3795.88,"qty":26.34430671}],"asks":[],"checksum":1053020604,"timestamp":"2024-06-01T17:52:13.590629Z"}]}
{"channel":"book","type":"update","data":[{"symbol":"ETH/USD","bids":[],"asks":[{"price":3796.17,"qty":26.34235389}],"checksum":1084658713,"timestamp":"2024-06-01T17:52:13.590669Z"}]}
{"channel":"book","type":"update","data":[{"symbol":"ETH/USD","bids":[{"price":3795.88,"qty":0.00000000},{"price":3795.08,"qty":3.95144465}],"asks":[],"checksum":2266763421,"timestamp":"2024-06-01T17:52:13.638800Z"}]}
{"channel":"book","type":"update","data":[{"symbol":"ETH/USD","bids":[{"price":3795.89,"qty":26.34421977}],"asks":[],"checksum":1192470745,"timestamp":"2024-06-01T17:52:13.643252Z"}]}
{"channel":"book","type":"update","data":[{"symbol":"ETH/USD","bids":[{"price":3795.81,"qty":0.00000000},{"price":3795.08,"qty":3.95144465},{"price":3795.89,"qty":26.35359078}],"asks":[],"checksum":3909883224,"timestamp":"2024-06-01T17:52:13.650001Z"}]}
{"channel":"book","type":"update","data":[{"symbol":"ETH/USD","bids":[],"asks":[{"price":3796.17,"qty":0.00000000},{"price":3797.11,"qty":10.81226191}],"checksum":2255070266,"timestamp":"2024-06-01T17:52:13.685364Z"}]}
{"channel":"book","type":"update","data":[{"symbol":"ETH/USD","bids":[],"asks":[{"price":3796.19,"qty":26.34221164}],"checksum":2605193491,"timestamp":"2024-06-01T17:52:13.690264Z"}]}
{"channel":"book","type":"update","data":[{"symbol":"ETH/USD","bids":[{"price":3795.52,"qty":3.00000000}],"asks":[],"checksum":966680504,"timestamp":"2024-06-01T17:52:14.015146Z"}]}
{"channel":"book","type":"update","data":[{"symbol":"ETH/USD","bids":[],"asks":[{"price":3796.43,"qty":0.00000000},{"price":3797.11,"qty":10.81226191}],"checksum":1333728410,"timestamp":"2024-06-01T17:52:14.016509Z"}]}
{"channel":"book","type":"update","data":[{"symbol":"ETH/USD","bids":[{"price":3795.89,"qty":26.34421977},{"price":3795.90,"qty":0.53625525}],"asks":[],"checksum":4152318229,"timestamp":"2024-06-01T17:52:14.040769Z"}]}
{"channel":"book","type":"update","data":[{"symbol":"ETH/USD","bids":[],"asks":[{"price":3796.19,"qty":0.00000000},{"price":3797.21,"qty":3.00000000}],"checksum":3400376113,"timestamp":"2024-06-01T17:52:14.051104Z"}]}
{"channel":"book","type":"update","data":[{"symbol":"ETH/USD","bids":[],"asks":[{"price":3796.21,"qty":0.00000000},{"price":3797.22,"qty":2.18000000}],"checksum":4018833831,"timestamp":"2024-06-01T17:52:14.051212Z"}]}
{"channel":"book","type":"update","data":[{"symbol":"ETH/USD","bids":[],"asks":[{"price":3796.28,"qty":26.34160438}],"checksum":3516460602,"timestamp":"2024-06-01T17:52:14.056083Z"}]}
{"channel":"book","type":"update","data":[{"symbol":"ETH/USD","bids":[],"asks":[{"price":3796.36,"qty":26.34106791}],"checksum":3530535760,"timestamp":"2024-06-01T17:52:14.056117Z"}]}
{"channel":"book","type":"update","data":[{"symbol":"ETH/USD","bids":[{"price":3795.61,"qty":0.00000000},{"price":3795.08,"qty":3.95144465}],"asks":[],"checksum":2870013501,"timestamp":"2024-06-01T17:52:14.117156Z"}]}
{"channel":"book","type":"update","data":[{"symbol":"ETH/USD","bids":[],"asks":[{"price":3796.67,"qty":0.00000000},{"price":3797.21,"qty":3.00000000}],"checksum":925780363,"timestamp":"2024-06-01T17:52:14.117182Z"}]}
{"channel":"book","type":"update","data":[{"symbol":"ETH/USD","bids":[],"asks":[{"price":3796.28,"qty":0.00000000},{"price":3797.22,"qty":2.18000000}],"checksum":810433311,"timestamp":"2024-06-01T17:52:14.117197Z"}]}
{"channel":"book","type":"update","data":[{"symbol":"ETH/USD","bids":[{"price":3795.74,"qty":26.34528770}],"asks":[],"checksum":2497676681,"timestamp":"2024-06-01T17:52:14.122450Z"}]}
{"channel":"book","type":"update","data":[{"symbol":"ETH/USD","bids":[],"asks":[{"price":3796.85,"qty":26.33763003}],"checksum":668076464,"timestamp":"2024-06-01T17:52:14.122518Z"}]}
{"channel":"book","type":"update","data":[{"symbol":"ETH/USD","bids":[],"asks":[{"price":3796.31,"qty":27.11143579}],"checksum":1484259254,"timestamp":"2024-06-01T17:52:14.122588Z"}]}
{"channel":"book","type":"update","data":[{"symbol":"ETH/USD","bids":[],"asks":[{"price":3796.31,"qty":0.77000000}],"checksum":668076464,"timestamp":"2024-06-01T17:52:14.136296Z"}]}
{"channel":"book","type":"update","data":[{"symbol":"ETH/USD","bids":[],"asks":[{"price":3796.31,"qty":0.00000000},{"price":3797.22,"qty":2.18000000},{"price":3796.42,"qty":0.77000000}],"checksum":147229425,"timestamp":"2024-06-01T17:52:14.192966Z"}]}
{"channel":"book","type":"update","data":[{"symbol":"ETH/USD","bids":[],"asks":[{"price":3796.42,"qty":1.54000000}],"checksum":675512757,"timestamp":"2024-06-01T17:52:14.193108Z"}]}
{"channel":"book","type":"update","data":[{"symbol":"ETH/USD","bids":[],"asks":[{"price":3796.29,"qty":26.34151219}],"checksum":3545950556,"timestamp":"2024-06-01T17:52:14.202489Z"}]}
{"channel":"book","type":"update","data":[{"symbol":"ETH/USD","bids":[],"asks":[{"price":3796.48,"qty":0.00000000},{"price":3797.21,"qty":3.00000000}],"checksum":2592562118,"timestamp":"2024-06-01T17:52:14.208795Z"}]}
{"channel":"book","type":"update","data":[{"symbol":"ETH/USD","bids":[],"asks":[{"price":3796.29,"qty":0.00000000},{"price":3797.22,"qty":2.18000000}],"checksum":3925394688,"timestamp":"2024-06-01T17:52:14.208931Z"}]}
{"channel":"book","type":"update","data":[{"symbol":"ETH/USD","bids":[],"asks":[{"price":3796.61,"qty":26.33933286}],"checksum":1303635411,"timestamp":"2024-06-01T17:52:14.213051Z"}]}
{"channel":"book","type":"update","data":[{"symbol":"ETH/USD","bids":[],"asks":[{"price":3796.30,"qty":26.34148137}],"checksum":28271279,"timestamp":"2024-06-01T17:52:14.295052Z"}]}
{"channel":"book","type":"update","data":[{"symbol":"ETH/USD","bids":[],"asks":[{"price":3796.30,"qty":0.00000000},{"price":3797.21,"qty":3.00000000}],"checksum":1303635411,"timestamp":"2024-06-01T17:52:14.321056Z"}]}
{"channel":"book","type":"update","data":[{"symbol":"ETH/USD","bids":[],"asks":[{"price":3796.32,"qty":26.34133649}],"checksum":2268993675,"timestamp":"2024-06-01T17:52:14.377417Z"}]}
{"channel":"book","type":"update","data":[{"symbol":"ETH/USD","bids":[],"asks":[{"price":3796.32,"qty":0.00000000},{"price":3797.21,"qty":3.00000000}],"checksum":1303635411,"timestamp":"2024-06-01T17:52:14.475218Z"}]}
{"channel":"book","type":"update","data":[{"symbol":"ETH/USD","bids":[],"asks":[{"price":3796.30,"qty":26.34147347}],"checksum":261002323,"timestamp":"2024-06-01T17:52:14.480401Z"}]}
{"channel":"book","type":"update","data":[{"symbol":"ETH/USD","bids":[],"asks":[{"price":3796.30,"qty":0.00000000},{"price":3797.21,"qty":3.00000000}],"checksum":1303635411,"timestamp":"2024-06-01T17:52:14.567757Z"}]}
{"channel":"book","type":"update","data":[{"symbol":"ETH/USD","bids":[],"asks":[{"price":3796.28,"qty":26.34160518}],"checksum":3233388370,"timestamp":"2024-06-01T17:52:14.572477Z"}]}
{"channel":"book","type":"update","data":[{"symbol":"ETH/USD","bids":[],"asks":[{"price":3796.28,"qty":0.00000000},{"price":3797.21,"qty":3.00000000}],"checksum":1303635411,"timestamp":"2024-06-01T17:52:14.653874Z"}]}
{"channel":"book","type":"update","data":[{"symbol":"ETH/USD","bids":[],"asks":[{"price":3796.31,"qty":26.34141288}],"checksum":3306879751,"timestamp":"2024-06-01T17:52:14.658863Z"}]}
{"channel":"book","type":"update","data":[{"symbol":"ETH/USD","bids":[{"price":3795.54,"qty":3.95144465}],"asks":[],"checksum":2207319361,"timestamp":"2024-06-01T17:52:14.688214Z"}]}
{"channel":"book","type":"update","data":[{"symbol":"ETH/USD","bids":[],"asks":[{"price":3796.31,"qty":0.00000000},{"price":3797.21,"qty":3.00000000}],"checksum":188226453,"timestamp":"2024-06-01T17:52:14.688474Z"}]}
{"channel":"book","type":"update","data":[{"symbol":"ETH/USD","bids":[{"price":3795.27,"qty":0.00000000},{"price":3795.09,"qty":2.15300000}],"asks":[],"checksum":2668688984,"timestamp":"2024-06-01T17:52:14.692230Z"}]}
{"channel":"book","type":"update","data":[{"symbol":"ETH/USD","bids":[{"price":3795.78,"qty":0.00000000},{"price":3795.08,"qty":3.95144465},{"price":3795.89,"qty":27.11421977}],"asks":[],"checksum":3858645070,"timestamp":"2024-06-01T17:52:14.700530Z"}]}
{"channel":"book","type":"update","data":[{"symbol":"ETH/USD","bids":[],"asks":[{"price":3796.57,"qty":0.00000000},{"price":3797.22,"qty":2.18000000}],"checksum":3178177344,"timestamp":"2024-06-01T17:52:14.703463Z"}]}
{"channel":"book","type":"update","data":[{"symbol":"ETH/USD","bids":[],"asks":[{"price":3796.42,"qty":0.77000000}],"checksum":3439207362,"timestamp":"2024-06-01T17:52:14.703527Z"}]}
{"channel":"book","type":"update","data":[{"symbol":"ETH/USD","bids":[{"price":3795.89,"qty":27.88421977}],"asks":[],"checksum":552752714,"timestamp":"2024-06-01T17:52:14.703614Z"}]}
{"channel":"book","type":"update","data":[{"symbol":"ETH/USD","bids":[],"asks":[{"price":3796.32,"qty":26.34133649}],"checksum":2467260465,"timestamp":"2024-06-01T17:52:14.782977Z"}]}
{"channel":"book","type":"update","data":[{"symbol":"ETH/USD","bids":[],"asks":[{"price":3796.32,"qty":0.00000000},{"price":3797.22,"qty":2.18000000}],"checksum":552752714,"timestamp":"2024-06-01T17:52:14.787233Z"}]}
{"channel":"book","type":"update","data":[{"symbol":"ETH/USD","bids":[],"asks":[{"price":3796.28,"qty":26.34159237}],"checksum":3764137094,"timestamp":"2024-06-01T17:52:14.875822Z"}]}
{"channel":"book","type":"update","data":[{"symbol":"ETH/USD","bids":[],"asks":[{"price":3796.28,"qty":0.00000000},{"price":3797.22,"qty":2.18000000}],"checksum":552752714,"timestamp":"2024-06-01T17:52:14.905066Z"}]}
{"channel":"book","type":"update","data":[{"symbol":"ETH/USD","bids":[{"price":3795.09,"qty":0.00000000},{"price":3795.07,"qty":3.30000000}],"asks":[],"checksum":857066398,"timestamp":"2024-06-01T17:52:15.047294Z"}]}
{"channel":"book","type":"update","data":[{"symbol":"ETH/USD","bids":[],"asks":[{"price":3796.29,"qty":26.34156307}],"checksum":2139833476,"timestamp":"2024-06-01T17:52:15.106748Z"}]}
{"channel":"book","type":"update","data":[{"symbol":"ETH/USD","bids":[{"price":3795.12,"qty":2.15300000}],"asks":[],"checksum":2459392547,"timestamp":"2024-06-01T17:52:15.146039Z"}]}
{"channel":"book","type":"update","data":[{"symbol":"ETH/USD","bids":[],"asks":[{"price":3796.29,"qty":0.00000000},{"price":3797.22,"qty":2.18000000}],"checksum":3725186361,"timestamp":"2024-06-01T17:52:15.146952Z"}]}
{"channel":"book","type":"update","data":[{"symbol":"ETH/USD","bids":[],"asks":[{"price":3796.42,"qty":0.00000000},{"price":3797.29,"qty":10.43462302}],"checksum":1378169583,"timestamp":"2024-06-01T17:52:15.315723Z"}]}
{"channel":"book","type":"update","data":[{"symbol":"ETH/USD","bids":[{"price":3795.89,"qty":27.11421977}],"asks":[],"checksum":3190376295,"timestamp":"2024-06-01T17:52:15.345579Z"}]}
{"channel":"book","type":"update","data":[{"symbol":"ETH/USD","bids":[],"asks":[{"price":3796.83,"qty":0.00000000},{"price":3797.38,"qty":0.52688149}],"checksum":673523960,"timestamp":"2024-06-01T17:52:15.355482Z"}]}
{"channel":"book","type":"update","data":[{"symbol":"ETH/USD","bids":[{"price":3795.90,"qty":3.53625525}],"asks":[],"checksum":932887177,"timestamp":"2024-06-01T17:52:15.355821Z"}]}
{"channel":"book","type":"update","data":[{"symbol":"ETH/USD","bids":[{"price":3795.90,"qty":6.53625525}],"asks":[],"checksum":1433422394,"timestamp":"2024-06-01T17:52:15.356051Z"}]}
{"channel":"book","type":"update","data":[{"symbol":"ETH/USD","bids":[],"asks":[{"price":3797.29,"qty":0.00000000},{"price":3797.58,"qty":72.31080496},{"price":3797.37,"qty":10.43462302}],"checksum":3816626467,"timestamp":"2024-06-01T17:52:15.359093Z"}]}
{"channel":"book","type":"update","data":[{"symbol":"ETH/USD","bids":[],"asks":[{"price":3796.33,"qty":26.34123468}],"checksum":970533010,"timestamp":"2024-06-01T17:52:15.364850Z"}]}
{"channel":"book","type":"update","data":[{"symbol":"ETH/USD","bids":[],"asks":[{"price":3796.36,"qty":0.00000000},{"price":3797.38,"qty":0.52688149}],"checksum":3266797937,"timestamp":"2024-06-01T17:52:15.366519Z"}]}
{"channel":"book","type":"update","data":[{"symbol":"ETH/USD","bids":[{"price":3795.34,"qty":0.00000000},{"price":3795.07,"qty":3.30000000}],"asks":[],"checksum":3940457764,"timestamp":"2024-06-01T17:52:15.366582Z"}]}
{"channel":"book","type":"update","data":[{"symbol":"ETH/USD","bids":[],"asks":[{"price":3796.33,"qty":0.00000000},{"price":3797.58,"qty":72.31080496}],"checksum":1312697178,"timestamp":"2024-06-01T17:52:15.370116Z"}]}
{"channel":"book","type":"update","data":[{"symbol":"ETH/USD","bids":[],"asks":[{"price":3796.72,"qty":0.00000000},{"price":3797.59,"qty":3.00000000}],"checksum":343415316,"timestamp":"2024-06-01T17:52:15.370604Z"}]}
{"channel":"book","type":"update","data":[{"symbol":"ETH/USD","bids":[],"asks":[{"price":3796.61,"qty":0.00000000},{"price":3797.63,"qty":1.23711630}],"checksum":998194325,"timestamp":"2024-06-01T17:52:15.376850Z"}]}
{"channel":"book","type":"update","data":[{"symbol":"ETH/USD","bids":[{"price":3795.75,"qty":3.95144465}],"asks":[],"checksum":2062768034,"timestamp":"2024-06-01T17:52:15.380856Z"}]}
{"channel":"book","type":"update","data":[{"symbol":"ETH/USD","bids":[{"price":3795.90,"qty":32.88046874}],"asks":[],"checksum":15752651,"timestamp":"2024-06-01T17:52:15.383888Z"}]}
{"channel":"book","type":"update","data":[{"symbol":"ETH/USD","bids":[],"asks":[{"price":3797.07,"qty":26.33610970}],"checksum":3857357228,"timestamp":"2024-06-01T17:52:15.383938Z"}]}
{"channel":"book","type":"update","data":[{"symbol":"ETH/USD","bids":[{"price":3795.54,"qty":0.00000000},{"price":3795.07,"qty":3.30000000}],"asks":[],"checksum":3846965970,"timestamp":"2024-06-01T17:52:15.384578Z"}]}
{"channel":"book","type":"update","data":[{"symbol":"ETH/USD","bids":[],"asks":[{"price":3797.37,"qty":0.00000000},{"price":3797.63,"qty":1.23711630}],"checksum":4255666114,"timestamp":"2024-06-01T17:52:15.384888Z"}]}
{"channel":"book","type":"update","data":[{"symbol":"ETH/USD","bids":[{"price":3795.90,"qty":46.04980109}],"asks":[],"checksum":3924046080,"timestamp":"2024-06-01T17:52:15.391463Z"}]}
{"channel":"book","type":"update","data":[{"symbol":"ETH/USD","bids":[],"asks":[{"price":3796.85,"qty":0.00000000},{"price":3797.64,"qty":133.17114255}],"checksum":631300693,"timestamp":"2024-06-01T17:52:15.397910Z"}]}
{"channel":"book","type":"update","data":[{"symbol":"ETH/USD","bids":[],"asks":[{"price":3797.57,"qty":4.30610000}],"checksum":4267915367,"timestamp":"2024-06-01T17:52:15.401853Z"}]}
{"channel":"book","type":"update","data":[{"symbol":"ETH/USD","bids":[],"asks":[{"price":3796.77,"qty":26.33818062}],"checksum":1304960132,"timestamp":"2024-06-01T17:52:15.411645Z"}]}
{"channel":"book","type":"update","data":[{"symbol":"ETH/USD","bids":[{"price":3795.32,"qty":0.06693358}],"asks":[],"checksum":3211044698,"timestamp":"2024-06-01T17:52:15.415989Z"}]}
{"channel":"book","type":"update","data":[{"symbol":"ETH/USD","bids":[],"asks":[{"price":3796.77,"qty":0.00000000},{"price":3797.63,"qty":1.23711630}],"checksum":917490863,"timestamp":"2024-06-01T17:52:15.452461Z"}]}
{"channel":"book","type":"update","data":[{"symbol":"ETH/USD","bids":[{"price":3795.90,"qty":61.85557968}],"asks":[],"checksum":1040041785,"timestamp":"2024-06-01T17:52:15.459712Z"}]}
{"channel":"book","type":"update","data":[{"symbol":"ETH/USD","bids":[],"asks":[{"price":3796.79,"qty":26.33804837}],"checksum":1266187750,"timestamp":"2024-06-01T17:52:15.481539Z"}]}
{"channel":"book","type":"update","data":[{"symbol":"ETH/USD","bids":[],"asks":[{"price":3796.87,"qty":26.33751303}],"checksum":875464176,"timestamp":"2024-06-01T17:52:15.481631Z"}]}
{"channel":"book","type":"update","data":[{"symbol":"ETH/USD","bids":[],"asks":[{"price":3797.57,"qty":0.00000000},{"price":3797.59,"qty":3.00000000}],"checksum":1126129202,"timestamp":"2024-06-01T17:52:15.484957Z"}]}
{"channel":"book","type":"update","data":[{"symbol":"ETH/USD","bids":[{"price":3795.90,"qty":66.21557968}],"asks":[],"checksum":3517088882,"timestamp":"2024-06-01T17:52:15.500218Z"}]}
{"channel":"book","type":"update","data":[{"symbol":"ETH/USD","bids":[],"asks":[{"price":3797.31,"qty":0.72912968}],"checksum":1023386340,"timestamp":"2024-06-01T17:52:15.504876Z"}]}
{"channel":"book","type":"update","data":[{"symbol":"ETH/USD","bids":[],"asks":[{"price":3797.07,"qty":27.10610970}],"checksum":1267879081,"timestamp":"2024-06-01T17:52:15.512152Z"}]}
{"channel":"book","type":"update","data":[{"symbol":"ETH/USD","bids":[],"asks":[{"price":3796.79,"qty":0.00000000},{"price":3797.59,"qty":3.00000000}],"checksum":3354442670,"timestamp":"2024-06-01T17:52:15.535835Z"}]}
{"channel":"book","type":"update","data":[{"symbol":"ETH/USD","bids":[],"asks":[{"price":3796.77,"qty":26.33821676}],"checksum":1985551694,"timestamp":"2024-06-01T17:52:15.540370Z"}]}
{"channel":"book","type":"update","data":[{"symbol":"ETH/USD","bids":[],"asks":[{"price":3796.77,"qty":0.00000000},{"price":3797.59,"qty":3.00000000}],"checksum":3354442670,"timestamp":"2024-06-01T17:52:15.583970Z"}]}
{"channel":"book","type":"update","data":[{"symbol":"ETH/USD","bids":[],"asks":[{"price":3796.79,"qty":26.33808396}],"checksum":888669371,"timestamp":"2024-06-01T17:52:15.742569Z"}]}
{"channel":"book","type":"update","data":[{"symbol":"ETH/USD","bids":[],"asks":[{"price":3796.79,"qty":0.00000000},{"price":3797.59,"qty":3.00000000}],"checksum":3354442670,"timestamp":"2024-06-01T17:52:15.774393Z"}]}
{"channel":"book","type":"update","data":[{"symbol":"ETH/USD","bids":[{"price":3795.90,"qty":63.21557968}],"asks":[],"checksum":636791430,"timestamp":"2024-06-01T17:52:15.775189Z"}]}
{"channel":"book","type":"update","data":[{"symbol":"ETH/USD","bids":[{"price":3795.90,"qty":60.21557968}],"asks":[],"checksum":3441928097,"timestamp":"2024-06-01T17:52:15.777958Z"}]}
{"channel":"book","type":"update","data":[{"symbol":"ETH/USD","bids":[],"asks":[{"price":3796.82,"qty":26.33789538}],"checksum":1281505616,"timestamp":"2024-06-01T17:52:15.877181Z"}]}
{"channel":"book","type":"update","data":[{"symbol":"ETH/USD","bids":[],"asks":[{"price":3796.82,"qty":0.00000000},{"price":3797.59,"qty":3.00000000}],"checksum":3441928097,"timestamp":"2024-06-01T17:52:16.013203Z"}]}
{"channel":"book","type":"update","data":[{"symbol":"ETH/USD","bids":[{"price":3795.90,"qty":64.16702433}],"asks":[],"checksum":2961484942,"timestamp":"2024-06-01T17:52:16.017500Z"}]}
{"channel":"book","type":"update","data":[{"symbol":"ETH/USD","bids":[],"asks":[{"price":3796.81,"qty":26.33795596}],"checksum":2677737022,"timestamp":"2024-06-01T17:52:16.018725Z"}]}
{"channel":"book","type":"update","data":[{"symbol":"ETH/USD","bids":[],"asks":[{"price":3797.25,"qty":26.33489739}],"checksum":951249030,"timestamp":"2024-06-01T17:52:16.018741Z"}]}
{"channel":"book","type":"update","data":[{"symbol":"ETH/USD","bids":[{"price":3795.75,"qty":0.00000000},{"price":3795.07,"qty":3.30000000}],"asks":[],"checksum":4204724040,"timestamp":"2024-06-01T17:52:16.021203Z"}]}
{"channel":"book","type":"update","data":[{"symbol":"ETH/USD","bids":[{"price":3795.90,"qty":67.16702433}],"asks":[],"checksum":307098223,"timestamp":"2024-06-01T17:52:16.133926Z"}]}
{"channel":"book","type":"update","data":[{"symbol":"ETH/USD","bids":[{"price":3795.90,"qty":70.16702433}],"asks":[],"checksum":596260703,"timestamp":"2024-06-01T17:52:16.169525Z"}]}
{"channel":"book","type":"update","data":[{"symbol":"ETH/USD","bids":[],"asks":[{"price":3796.81,"qty":0.00000000},{"price":3797.57,"qty":0.77557879}],"checksum":1363910417,"timestamp":"2024-06-01T17:52:16.176010Z"}]}
{"channel":"book","type":"update","data":[{"symbol":"ETH/USD","bids":[],"asks":[{"price":3796.80,"qty":26.33800600}],"checksum":2156760308,"timestamp":"2024-06-01T17:52:16.181509Z"}]}
{"channel":"book","type":"update","data":[{"symbol":"ETH/USD","bids":[{"price":3795.90,"qty":67.16702433}],"asks":[],"checksum":2974435780,"timestamp":"2024-06-01T17:52:16.183951Z"}]}
{"channel":"book","type":"update","data":[{"symbol":"ETH/USD","bids":[],"asks":[{"price":3796.80,"qty":0.00000000},{"price":3797.57,"qty":0.77557879}],"checksum":1619810849,"timestamp":"2024-06-01T17:52:16.236619Z"}]}
{"channel":"book","type":"update","data":[{"symbol":"ETH/USD","bids":[],"asks":[{"price":3796.79,"qty":26.33810345}],"checksum":528870614,"timestamp":"2024-06-01T17:52:16.241194Z"}]}
{"channel":"book","type":"update","data":[{"symbol":"ETH/USD","bids":[],"asks":[{"price":3797.07,"qty":26.33610970},{"price":3796.96,"qty":0.77000000}],"checksum":2993517229,"timestamp":"2024-06-01T17:52:16.281936Z"}]}
{"channel":"book","type":"update","data":[{"symbol":"ETH/USD","bids":[],"asks":[{"price":3796.96,"qty":1.54000000}],"checksum":358877435,"timestamp":"2024-06-01T17:52:16.284892Z"}]}
{"channel":"book","type":"update","data":[{"symbol":"ETH/USD","bids":[{"price":3795.90,"qty":70.16702433}],"asks":[],"checksum":614714827,"timestamp":"2024-06-01T17:52:16.287779Z"}]}
{"channel":"book","type":"update","data":[{"symbol":"ETH/USD","bids":[],"asks":[{"price":3796.96,"qty":0.77000000}],"checksum":2209003421,"timestamp":"2024-06-01T17:52:16.306269Z"}]}
{"channel":"book","type":"update","data":[{"symbol":"ETH/USD","bids":[],"asks":[{"price":3796.79,"qty":0.00000000},{"price":3797.38,"qty":0.52688149}],"checksum":2231060115,"timestamp":"2024-06-01T17:52:16.374435Z"}]}
{"channel":"book","type":"update","data":[{"symbol":"ETH/USD","bids":[],"asks":[{"price":3796.81,"qty":26.33792435}],"checksum":3787269791,"timestamp":"2024-06-01T17:52:16.379192Z"}]}
{"channel":"book","type":"update","data":[{"symbol":"ETH/USD","bids":[],"asks":[{"price":3796.81,"qty":0.00000000},{"price":3797.38,"qty":0.52688149}],"checksum":2231060115,"timestamp":"2024-06-01T17:52:16.430285Z"}]}
{"channel":"book","type":"update","data":[{"symbol":"ETH/USD","bids":[],"asks":[{"price":3796.83,"qty":26.33779529}],"checksum":3054578530,"timestamp":"2024-06-01T17:52:16.434181Z"}]}
{"channel":"book","type":"update","data":[{"symbol":"ETH/USD","bids":[],"asks":[{"price":3797.22,"qty":0.00000000},{"price":3797.38,"qty":0.52688149}],"checksum":410828858,"timestamp":"2024-06-01T17:52:16.500927Z"}]}
{"channel":"book","type":"update","data":[{"symbol":"ETH/USD","bids":[],"asks":[{"price":3796.96,"qty":0.00000000},{"price":3797.57,"qty":0.77557879}],"checksum":3070430798,"timestamp":"2024-06-01T17:52:16.544611Z"}]}
{"channel":"book","type":"update","data":[{"symbol":"ETH/USD","bids":[{"price":3795.90,"qty":70.17219703}],"asks":[],"checksum":1867570838,"timestamp":"2024-06-01T17:52:16.548948Z"}]}
{"channel":"book","type":"update","data":[{"symbol":"ETH/USD","bids":[],"asks":[{"price":3796.83,"qty":0.00000000},{"price":3797.58,"qty":72.31080496}],"checksum":940184896,"timestamp":"2024-06-01T17:52:16.584454Z"}]}
{"channel":"book","type":"update","data":[{"symbol":"ETH/USD","bids":[],"asks":[{"price":3796.86,"qty":26.33758766}],"checksum":958780479,"timestamp":"2024-06-01T17:52:16.589195Z"}]}
{"channel":"book","type":"update","data":[{"symbol":"ETH/USD","bids":[],"asks":[{"price":3797.42,"qty":2.15300000}],"checksum":3643684081,"timestamp":"2024-06-01T17:52:16.599557Z"}]}
{"channel":"book","type":"update","data":[{"symbol":"ETH/USD","bids":[],"asks":[{"price":3797.01,"qty":0.77000000}],"checksum":2815044702,"timestamp":"2024-06-01T17:52:16.640785Z"}]}
{"channel":"book","type":"update","data":[{"symbol":"ETH/USD","bids":[],"asks":[{"price":3796.84,"qty":0.02631803}],"checksum":1445116132,"timestamp":"2024-06-01T17:52:16.918825Z"}]}
{"channel":"book","type":"update","data":[{"symbol":"ETH/USD","bids":[{"price":3795.71,"qty":3.95144465}],"asks":[],"checksum":162350031,"timestamp":"2024-06-01T17:52:16.923026Z"}]}
{"channel":"book","type":"update","data":[{"symbol":"ETH/USD","bids":[{"price":3795.08,"qty":0.00000000},{"price":3795.07,"qty":3.30000000}],"asks":[],"checksum":2883138250,"timestamp":"2024-06-01T17:52:16.926768Z"}]}
{"channel":"book","type":"update","data":[{"symbol":"ETH/USD","bids":[],"asks":[{"price":3796.86,"qty":0.00000000},{"price":3797.38,"qty":0.52688149}],"checksum":2359353417,"timestamp":"2024-06-01T17:52:17.184807Z"}]}
{"channel":"book","type":"update","data":[{"symbol":"ETH/USD","bids":[],"asks":[{"price":3796.85,"qty":26.33767996}],"checksum":1046731011,"timestamp":"2024-06-01T17:52:17.188802Z"}]}
{"channel":"book","type":"update","data":[{"symbol":"ETH/USD","bids":[],"asks":[{"price":3796.85,"qty":0.00000000},{"price":3797.38,"qty":0.52688149}],"checksum":2359353417,"timestamp":"2024-06-01T17:52:17.538067Z"}]}
{"channel":"book","type":"update","data":[{"symbol":"ETH/USD","bids":[],"asks":[{"price":3796.84,"qty":26.36405806}],"checksum":1273565584,"timestamp":"2024-06-01T17:52:17.545332Z"}]}
{"channel":"book","type":"update","data":[{"symbol":"ETH/USD","bids":[],"asks":[{"price":3797.01,"qty":0.00000000},{"price":3797.42,"qty":2.15300000}],"checksum":2228126736,"timestamp":"2024-06-01T17:52:17.679431Z"}]}
{"channel":"book","type":"update","data":[{"symbol":"ETH/USD","bids":[],"asks":[{"price":3796.84,"qty":0.02631803}],"checksum":2064033681,"timestamp":"2024-06-01T17:52:17.730139Z"}]}
{"channel":"book","type":"update","data":[{"symbol":"ETH/USD","bids":[],"asks":[{"price":3796.95,"qty":26.33694019}],"checksum":1045488988,"timestamp":"2024-06-01T17:52:17.735482Z"}]}
{"channel":"book","type":"update","data":[{"symbol":"ETH/USD","bids":[],"asks":[{"price":3796.87,"qty":0.00000000},{"price":3797.42,"qty":2.15300000}],"checksum":4271268009,"timestamp":"2024-06-01T17:52:17.739975Z"}]}
{"channel":"book","type":"update","data":[{"symbol":"ETH/USD","bids":[],"asks":[{"price":3796.83,"qty":26.33780810}],"checksum":3144211613,"timestamp":"2024-06-01T17:52:17.745711Z"}]}
{"channel":"book","type":"update","data":[{"symbol":"ETH/USD","bids":[],"asks":[{"price":3797.00,"qty":0.77000000}],"checksum":3316921327,"timestamp":"2024-06-01T17:52:17.828380Z"}]}
{"channel":"book","type":"update","data":[{"symbol":"ETH/USD","bids":[{"price":3795.90,"qty":67.17219703}],"asks":[],"checksum":4101240543,"timestamp":"2024-06-01T17:52:18.006776Z"}]}
{"channel":"book","type":"update","data":[{"symbol":"ETH/USD","bids":[{"price":3795.90,"qty":70.17219703}],"asks":[],"checksum":3316921327,"timestamp":"2024-06-01T17:52:18.056319Z"}]}
{"channel":"book","type":"update","data":[{"symbol":"ETH/USD","bids":[],"asks":[{"price":3796.83,"qty":0.00000000},{"price":3797.38,"qty":0.52688149}],"checksum":2058287224,"timestamp":"2024-06-01T17:52:18.063040Z"}]}
{"channel":"book","type":"update","data":[{"symbol":"ETH/USD","bids":[],"asks":[{"price":3796.82,"qty":26.33786868}],"checksum":2067824547,"timestamp":"2024-06-01T17:52:18.067879Z"}]}
{"channel":"book","type":"update","data":[{"symbol":"ETH/USD","bids":[{"price":3795.90,"qty":67.17219703}],"asks":[],"checksum":1250409107,"timestamp":"2024-06-01T17:52:18.068297Z"}]}
{"channel":"book","type":"update","data":[{"symbol":"ETH/USD","bids":[{"price":3795.90,"qty":64.17219703}],"asks":[],"checksum":2723461044,"timestamp":"2024-06-01T17:52:18.188178Z"}]}
{"channel":"book","type":"update","data":[{"symbol":"ETH/USD","bids":[{"price":3795.90,"qty":67.17219703}],"asks":[],"checksum":1250409107,"timestamp":"2024-06-01T17:52:18.211538Z"}]}
{"channel":"book","type":"update","data":[{"symbol":"ETH/USD","bids":[{"price":3795.90,"qty":64.17219703}],"asks":[],"checksum":2723461044,"timestamp":"2024-06-01T17:52:18.248038Z"}]}
{"channel":"book","type":"update","data":[{"symbol":"ETH/USD","bids":[{"price":3795.89,"qty":26.34421977}],"asks":[],"checksum":3286319210,"timestamp":"2024-06-01T17:52:18.253463Z"}]}
{"channel":"book","type":"update","data":[{"symbol":"ETH/USD","bids":[],"asks":[{"price":3796.95,"qty":0.00000000},{"price":3797.38,"qty":0.52688149}],"checksum":97285568,"timestamp":"2024-06-01T17:52:18.258480Z"}]}
{"channel":"book","type":"update","data":[{"symbol":"ETH/USD","bids":[],"asks":[{"price":3797.07,"qty":0.00000000},{"price":3797.42,"qty":2.15300000}],"checksum":4112103717,"timestamp":"2024-06-01T17:52:18.258579Z"}]}
{"channel":"book","type":"update","data":[{"symbol":"ETH/USD","bids":[],"asks":[{"price":3796.82,"qty":0.00000000},{"price":3797.57,"qty":0.77557879}],"checksum":2655910709,"timestamp":"2024-06-01T17:52:18.259296Z"}]}
{"channel":"book","type":"update","data":[{"symbol":"ETH/USD","bids":[],"asks":[{"price":3796.95,"qty":26.33695483}],"checksum":3249227175,"timestamp":"2024-06-01T17:52:18.263849Z"}]}
{"channel":"book","type":"update","data":[{"symbol":"ETH/USD","bids":[],"asks":[{"price":3796.59,"qty":26.33947783}],"checksum":1828264798,"timestamp":"2024-06-01T17:52:18.263959Z"}]}
{"channel":"book","type":"update","data":[{"symbol":"ETH/USD","bids":[],"asks":[{"price":3796.67,"qty":3.00000000}],"checksum":364704359,"timestamp":"2024-06-01T17:52:18.269652Z"}]}
{"channel":"book","type":"update","data":[{"symbol":"ETH/USD","bids":[],"asks":[{"price":3797.00,"qty":0.00000000},{"price":3797.38,"qty":0.52688149},{"price":3796.90,"qty":0.77000000}],"checksum":3320188517,"timestamp":"2024-06-01T17:52:18.271162Z"}]}
{"channel":"book","type":"update","data":[{"symbol":"ETH/USD","bids":[],"asks":[{"price":3796.90,"qty":1.54000000}],"checksum":1637758934,"timestamp":"2024-06-01T17:52:18.271211Z"}]}
{"channel":"book","type":"update","data":[{"symbol":"ETH/USD","bids":[],"asks":[{"price":3796.59,"qty":0.00000000},{"price":3797.38,"qty":0.52688149}],"checksum":649011999,"timestamp":"2024-06-01T17:52:18.271898Z"}]}
{"channel":"book","type":"update","data":[{"symbol":"ETH/USD","bids":[{"price":3795.90,"qty":51.00286468}],"asks":[],"checksum":1381326799,"timestamp":"2024-06-01T17:52:18.275374Z"}]}
{"channel":"book","type":"update","data":[{"symbol":"ETH/USD","bids":[{"price":3795.53,"qty":0.00000000},{"price":3795.04,"qty":2.45696258}],"asks":[],"checksum":3342040936,"timestamp":"2024-06-01T17:52:18.276965Z"}]}
{"channel":"book","type":"update","data":[{"symbol":"ETH/USD","bids":[{"price":3795.32,"qty":0.00000000},{"price":3795.01,"qty":27.06796471}],"asks":[],"checksum":1524244340,"timestamp":"2024-06-01T17:52:18.294594Z"}]}
{"channel":"book","type":"update","data":[{"symbol":"ETH/USD","bids":[],"asks":[{"price":3796.90,"qty":0.77000000},{"price":3796.81,"qty":0.77000000}],"checksum":1761831971,"timestamp":"2024-06-01T17:52:18.298927Z"}]}
{"channel":"book","type":"update","data":[{"symbol":"ETH/USD","bids":[],"asks":[{"price":3796.90,"qty":0.00000000},{"price":3797.38,"qty":0.52688149}],"checksum":690650791,"timestamp":"2024-06-01T17:52:18.299115Z"}]}
{"channel":"book","type":"update","data":[{"symbol":"ETH/USD","bids":[{"price":3795.01,"qty":0.72912968}],"asks":[],"checksum":3660739144,"timestamp":"2024-06-01T17:52:18.360036Z"}]}
{"channel":"book","type":"update","data":[{"symbol":"ETH/USD","bids":[{"price":3795.90,"qty":51.77286468}],"asks":[],"checksum":2041491945,"timestamp":"2024-06-01T17:52:18.368891Z"}]}
{"channel":"book","type":"update","data":[{"symbol":"ETH/USD","bids":[],"asks":[{"price":3796.60,"qty":26.33935750}],"checksum":2114565348,"timestamp":"2024-06-01T17:52:18.380034Z"}]}
{"channel":"book","type":"update","data":[{"symbol":"ETH/USD","bids":[{"price":3795.79,"qty":3.40262063}],"asks":[],"checksum":2424166204,"timestamp":"2024-06-01T17:52:18.396562Z"}]}
{"channel":"book","type":"update","data":[{"symbol":"ETH/USD","bids":[],"asks":[{"price":3796.60,"qty":0.00000000},{"price":3797.38,"qty":0.52688149}],"checksum":4006284420,"timestamp":"2024-06-01T17:52:18.428409Z"}]}
{"channel":"book","type":"update","data":[{"symbol":"ETH/USD","bids":[],"asks":[{"price":3796.62,"qty":26.33922053}],"checksum":1884119080,"timestamp":"2024-06-01T17:52:18.435305Z"}]}
{"channel":"book","type":"update","data":[{"symbol":"ETH/USD","bids":[{"price":3795.90,"qty":51.00286468}],"asks":[],"checksum":3510595477,"timestamp":"2024-06-01T17:52:18.437051Z"}]}
{"channel":"book","type":"update","data":[{"symbol":"ETH/USD","bids":[{"price":3795.90,"qty":51.77286468}],"asks":[],"checksum":1884119080,"timestamp":"2024-06-01T17:52:18.602583Z"}]}
{"channel":"book","type":"update","data":[{"symbol":"ETH/USD","bids":[{"price":3795.12,"qty":0.00000000},{"price":3795.01,"qty":0.72912968}],"asks":[],"checksum":623828267,"timestamp":"2024-06-01T17:52:18.712694Z"}]}
{"channel":"book","type":"update","data":[{"symbol":"ETH/USD","bids":[{"price":3795.53,"qty":2.15300000}],"asks":[],"checksum":3799076944,"timestamp":"2024-06-01T17:52:18.714970Z"}]}
{"channel":"book","type":"update","data":[{"symbol":"ETH/USD","bids":[],"asks":[{"price":3796.62,"qty":0.00000000},{"price":3797.38,"qty":0.52688149}],"checksum":2096577788,"timestamp":"2024-06-01T17:52:18.754087Z"}]}
{"channel":"book","type":"update","data":[{"symbol":"ETH/USD","bids":[],"asks":[{"price":3796.59,"qty":26.33948298}],"checksum":1830637034,"timestamp":"2024-06-01T17:52:18.758643Z"}]}
{"channel":"book","type":"update","data":[{"symbol":"ETH/USD","bids":[],"asks":[{"price":3796.67,"qty":0.00000000},{"price":3797.38,"qty":0.52688149}],"checksum":3313655576,"timestamp":"2024-06-01T17:52:18.893143Z"}]}
{"channel":"book","type":"update","data":[{"symbol":"ETH/USD","bids":[],"asks":[{"price":3796.67,"qty":3.00000000}],"checksum":1830637034,"timestamp":"2024-06-01T17:52:18.900743Z"}]}
{"channel":"book","type":"update","data":[{"symbol":"ETH/USD","bids":[],"asks":[{"price":3796.59,"qty":0.00000000},{"price":3797.38,"qty":0.52688149}],"checksum":2096577788,"timestamp":"2024-06-01T17:52:19.020540Z"}]}
{"channel":"book","type":"update","data":[{"symbol":"ETH/USD","bids":[],"asks":[{"price":3796.62,"qty":26.33923538}],"checksum":2824482362,"timestamp":"2024-06-01T17:52:19.025263Z"}]}
{"channel":"book","type":"update","data":[{"symbol":"ETH/USD","bids":[],"asks":[{"price":3796.62,"qty":0.00000000},{"price":3797.38,"qty":0.52688149}],"checksum":2096577788,"timestamp":"2024-06-01T17:52:19.201271Z"}]}
{"channel":"book","type":"update","data":[{"symbol":"ETH/USD","bids":[],"asks":[{"price":3796.59,"qty":26.33948283}],"checksum":3328663288,"timestamp":"2024-06-01T17:52:19.205659Z"}]}
{"channel":"book","type":"update","data":[{"symbol":"ETH/USD","bids":[],"asks":[{"price":3796.59,"qty":0.00000000},{"price":3797.38,"qty":0.52688149}],"checksum":2096577788,"timestamp":"2024-06-01T17:52:19.234696Z"}]}
{"channel":"book","type":"update","data":[{"symbol":"ETH/USD","bids":[],"asks":[{"price":3796.95,"qty":0.00000000},{"price":3797.42,"qty":2.15300000}],"checksum":4283678935,"timestamp":"2024-06-01T17:52:19.297331Z"}]}
{"channel":"book","type":"update","data":[{"symbol":"ETH/USD","bids":[],"asks":[{"price":3796.55,"qty":26.33970673}],"checksum":1428225611,"timestamp":"2024-06-01T17:52:19.301869Z"}]}
{"channel":"book","type":"update","data":[{"symbol":"ETH/USD","bids":[],"asks":[{"price":3796.82,"qty":26.33784009}],"checksum":1185824079,"timestamp":"2024-06-01T17:52:19.302039Z"}]}
{"channel":"book","type":"update","data":[{"symbol":"ETH/USD","bids":[],"asks":[{"price":3796.55,"qty":0.00000000},{"price":3797.38,"qty":0.52688149}],"checksum":2322477895,"timestamp":"2024-06-01T17:52:19.324601Z"}]}
{"channel":"book","type":"update","data":[{"symbol":"ETH/USD","bids":[],"asks":[{"price":3796.58,"qty":26.33949600}],"checksum":2802784660,"timestamp":"2024-06-01T17:52:19.382376Z"}]}
{"channel":"book","type":"update","data":[{"symbol":"ETH/USD","bids":[],"asks":[{"price":3796.58,"qty":0.00000000},{"price":3797.38,"qty":0.52688149}],"checksum":2322477895,"timestamp":"2024-06-01T17:52:19.386208Z"}]}
{"channel":"book","type":"update","data":[{"symbol":"ETH/USD","bids":[],"asks":[{"price":3796.69,"qty":26.33874335}],"checksum":438616958,"timestamp":"2024-06-01T17:52:19.390669Z"}]}
{"channel":"book","type":"update","data":[{"symbol":"ETH/USD","bids":[],"asks":[{"price":3796.62,"qty":26.33926931}],"checksum":3914598757,"timestamp":"2024-06-01T17:52:19.501721Z"}]}
{"channel":"book","type":"update","data":[{"symbol":"ETH/USD","bids":[],"asks":[{"price":3796.67,"qty":0.00000000},{"price":3797.31,"qty":0.72912968}],"checksum":1625752229,"timestamp":"2024-06-01T17:52:19.760545Z"}]}
{"channel":"book","type":"update","data":[{"symbol":"ETH/USD","bids":[],"asks":[{"price":3796.62,"qty":0.00000000},{"price":3797.38,"qty":0.52688149}],"checksum":349929237,"timestamp":"2024-06-01T17:52:19.910500Z"}]}
{"channel":"book","type":"update","data":[{"symbol":"ETH/USD","bids":[],"asks":[{"price":3796.61,"qty":26.33931386}],"checksum":756742678,"timestamp":"2024-06-01T17:52:19.914903Z"}]}
{"channel":"book","type":"update","data":[{"symbol":"ETH/USD","bids":[],"asks":[{"price":3796.67,"qty":3.00000000}],"checksum":3144750763,"timestamp":"2024-06-01T17:52:19.971458Z"}]}
{"channel":"book","type":"update","data":[{"symbol":"ETH/USD","bids":[],"asks":[{"price":3796.61,"qty":0.00000000},{"price":3797.31,"qty":0.72912968}],"checksum":438616958,"timestamp":"2024-06-01T17:52:19.977781Z"}]}
{"channel":"book","type":"update","data":[{"symbol":"ETH/USD","bids":[],"asks":[{"price":3796.60,"qty":26.33938498}],"checksum":3167419954,"timestamp":"2024-06-01T17:52:19.982902Z"}]}
{"channel":"book","type":"update","data":[{"symbol":"ETH/USD","bids":[],"asks":[{"price":3796.60,"qty":0.00000000},{"price":3797.31,"qty":0.72912968}],"checksum":438616958,"timestamp":"2024-06-01T17:52:20.133539Z"}]}
{"channel":"book","type":"update","data":[{"symbol":"ETH/USD","bids":[],"asks":[{"price":3796.59,"qty":26.33945868}],"checksum":2516767078,"timestamp":"2024-06-01T17:52:20.137334Z"}]}
{"channel":"book","type":"update","data":[{"symbol":"ETH/USD","bids":[],"asks":[{"price":3796.59,"qty":0.00000000},{"price":3797.31,"qty":0.72912968}],"checksum":438616958,"timestamp":"2024-06-01T17:52:20.180037Z"}]}
{"channel":"book","type":"update","data":[{"symbol":"ETH/USD","bids":[],"asks":[{"price":3796.63,"qty":26.33917947}],"checksum":3992167114,"timestamp":"2024-06-01T17:52:20.269384Z"}]}
{"channel":"book","type":"update","data":[{"symbol":"ETH/USD","bids":[],"asks":[{"price":3796.67,"qty":0.00000000},{"price":3797.31,"qty":0.72912968}],"checksum":476756003,"timestamp":"2024-06-01T17:52:20.272084Z"}]}
{"channel":"book","type":"update","data":[{"symbol":"ETH/USD","bids":[],"asks":[{"price":3796.63,"qty":0.00000000},{"price":3797.38,"qty":0.52688149}],"checksum":349929237,"timestamp":"2024-06-01T17:52:20.273583Z"}]}
{"channel":"book","type":"update","data":[{"symbol":"ETH/USD","bids":[],"asks":[{"price":3796.82,"qty":0.00000000},{"price":3797.42,"qty":2.15300000}],"checksum":780808656,"timestamp":"2024-06-01T17:52:20.305838Z"}]}
{"channel":"book","type":"update","data":[{"symbol":"ETH/USD","bids":[],"asks":[{"price":3796.95,"qty":26.33696785}],"checksum":3719330502,"timestamp":"2024-06-01T17:52:20.310783Z"}]}
{"channel":"book","type":"update","data":[{"symbol":"ETH/USD","bids":[],"asks":[{"price":3796.66,"qty":26.33900299}],"checksum":1126494235,"timestamp":"2024-06-01T17:52:20.350108Z"}]}
{"channel":"book","type":"update","data":[{"symbol":"ETH/USD","bids":[{"price":3795.90,"qty":54.77286468}],"asks":[],"checksum":1959369799,"timestamp":"2024-06-01T17:52:20.392152Z"}]}
{"channel":"book","type":"update","data":[{"symbol":"ETH/USD","bids":[{"price":3795.90,"qty":57.77286468}],"asks":[],"checksum":3502094924,"timestamp":"2024-06-01T17:52:20.393041Z"}]}
{"channel":"book","type":"update","data":[{"symbol":"ETH/USD","bids":[],"asks":[{"price":3796.81,"qty":0.00000000},{"price":3797.38,"qty":0.52688149},{"price":3796.90,"qty":0.77000000}],"checksum":3446847766,"timestamp":"2024-06-01T17:52:20.410562Z"}]}
{"channel":"book","type":"update","data":[{"symbol":"ETH/USD","bids":[],"asks":[{"price":3796.90,"qty":1.54000000}],"checksum":3500927278,"timestamp":"2024-06-01T17:52:20.413963Z"}]}
{"channel":"book","type":"update","data":[{"symbol":"ETH/USD","bids":[{"price":3795.90,"qty":54.77286468}],"asks":[],"checksum":1960824613,"timestamp":"2024-06-01T17:52:20.545634Z"}]}
{"channel":"book","type":"update","data":[{"symbol":"ETH/USD","bids":[{"price":3795.05,"qty":0.77949990}],"asks":[],"checksum":2596550213,"timestamp":"2024-06-01T17:52:20.548973Z"}]}
{"channel":"book","type":"update","data":[{"symbol":"ETH/USD","bids":[],"asks":[{"price":3796.90,"qty":0.77000000}],"checksum":4102318677,"timestamp":"2024-06-01T17:52:20.555389Z"}]}
{"channel":"book","type":"update","data":[{"symbol":"ETH/USD","bids":[{"price":3795.90,"qty":57.77286468}],"asks":[],"checksum":1365642291,"timestamp":"2024-06-01T17:52:20.655300Z"}]}
{"channel":"book","type":"update","data":[{"symbol":"ETH/USD","bids":[{"price":3795.05,"qty":0.00000000},{"price":3795.04,"qty":2.45696258}],"asks":[],"checksum":3446847766,"timestamp":"2024-06-01T17:52:20.657205Z"}]}
{"channel":"book","type":"update","data":[{"symbol":"ETH/USD","bids":[],"asks":[{"price":3796.90,"qty":0.00000000},{"price":3797.38,"qty":0.52688149}],"checksum":3771800186,"timestamp":"2024-06-01T17:52:20.657604Z"}]}
{"channel":"book","type":"update","data":[{"symbol":"ETH/USD","bids":[{"price":3795.90,"qty":63.04386468}],"asks":[],"checksum":2831560187,"timestamp":"2024-06-01T17:52:20.661713Z"}]}
{"channel":"book","type":"update","data":[{"symbol":"ETH/USD","bids":[],"asks":[{"price":3795.91,"qty":0.00000000},{"price":3797.42,"qty":2.15300000}],"checksum":1206015596,"timestamp":"2024-06-01T17:52:20.662202Z"}]}
{"channel":"book","type":"update","data":[{"symbol":"ETH/USD","bids":[],"asks":[{"price":3796.69,"qty":0.00000000},{"price":3797.59,"qty":3.00000000}],"checksum":2257844658,"timestamp":"2024-06-01T17:52:20.663697Z"}]}
{"channel":"book","type":"update","data":[{"symbol":"ETH/USD","bids":[],"asks":[{"price":3796.66,"qty":0.00000000},{"price":3797.72,"qty":4.53808791}],"checksum":2480554583,"timestamp":"2024-06-01T17:52:20.663747Z"}]}
{"channel":"book","type":"update","data":[{"symbol":"ETH/USD","bids":[{"price":3796.08,"qty":3.00000000}],"asks":[],"checksum":1046288339,"timestamp":"2024-06-01T17:52:20.665679Z"}]}
{"channel":"book","type":"update","data":[{"symbol":"ETH/USD","bids":[{"price":3795.08,"qty":0.77949990}],"asks":[],"checksum":3793921421,"timestamp":"2024-06-01T17:52:20.666334Z"}]}
{"channel":"book","type":"update","data":[{"symbol":"ETH/USD","bids":[],"asks":[{"price":3796.65,"qty":0.82961421}],"checksum":2968050395,"timestamp":"2024-06-01T17:52:20.666593Z"}]}
{"channel":"book","type":"update","data":[{"symbol":"ETH/USD","bids":[{"price":3795.90,"qty":62.51698042},{"price":3795.91,"qty":0.52688288}],"asks":[],"checksum":2504941447,"timestamp":"2024-06-01T17:52:20.666965Z"}]}
{"channel":"book","type":"update","data":[{"symbol":"ETH/USD","bids":[{"price":3795.91,"qty":16.33053827}],"asks":[],"checksum":167169001,"timestamp":"2024-06-01T17:52:20.667029Z"}]}
{"channel":"book","type":"update","data":[{"symbol":"ETH/USD","bids":[{"price":3795.90,"qty":61.74698042},{"price":3796.24,"qty":0.77000000}],"asks":[],"checksum":3009814416,"timestamp":"2024-06-01T17:52:20.667079Z"}]}
{"channel":"book","type":"update","data":[{"symbol":"ETH/USD","bids":[{"price":3795.91,"qty":20.28145212}],"asks":[],"checksum":1872170784,"timestamp":"2024-06-01T17:52:20.667383Z"}]}
{"channel":"book","type":"update","data":[{"symbol":"ETH/USD","bids":[],"asks":[{"price":3797.38,"qty":0.00000000},{"price":3797.72,"qty":4.53808791},{"price":3796.65,"qty":1.35639439}],"checksum":4290753529,"timestamp":"2024-06-01T17:52:20.667472Z"}]}
{"channel":"book","type":"update","data":[{"symbol":"ETH/USD","bids":[],"asks":[{"price":3797.11,"qty":0.00000000},{"price":3797.86,"qty":0.68782190}],"checksum":1149130890,"timestamp":"2024-06-01T17:52:20.667565Z"}]}
{"channel":"book","type":"update","data":[{"symbol":"ETH/USD","bids":[{"price":3796.24,"qty":1.54000000}],"asks":[],"checksum":1282560714,"timestamp":"2024-06-01T17:52:20.667731Z"}]}
{"channel":"book","type":"update","data":[{"symbol":"ETH/USD","bids":[{"price":3796.24,"qty":0.77000000}],"asks":[],"checksum":1149130890,"timestamp":"2024-06-01T17:52:20.667772Z"}]}
{"channel":"book","type":"update","data":[{"symbol":"ETH/USD","bids":[{"price":3795.63,"qty":7.25300727}],"asks":[],"checksum":2962857347,"timestamp":"2024-06-01T17:52:20.668958Z"}]}
{"channel":"book","type":"update","data":[{"symbol":"ETH/USD","bids":[],"asks":[{"price":3796.81,"qty":3.00000000}],"checksum":2840165225,"timestamp":"2024-06-01T17:52:20.669933Z"}]}
{"channel":"book","type":"update","data":[{"symbol":"ETH/USD","bids":[{"price":3795.91,"qty":19.75456924},{"price":3796.09,"qty":0.52685789}],"asks":[],"checksum":3124502817,"timestamp":"2024-06-01T17:52:20.671391Z"}]}
{"channel":"book","type":"update","data":[{"symbol":"ETH/USD","bids":[{"price":3795.90,"qty":57.79553577}],"asks":[],"checksum":1120526098,"timestamp":"2024-06-01T17:52:20.671435Z"}]}
{"channel":"book","type":"update","data":[{"symbol":"ETH/USD","bids":[],"asks":[{"price":3796.65,"qty":0.82961421},{"price":3796.83,"qty":0.52675521}],"checksum":259265317,"timestamp":"2024-06-01T17:52:20.672641Z"}]}
{"channel":"book","type":"update","data":[{"symbol":"ETH/USD","bids":[{"price":3796.09,"qty":0.00000000},{"price":3795.63,"qty":7.25300727},{"price":3796.25,"qty":0.52683569}],"asks":[],"checksum":764724494,"timestamp":"2024-06-01T17:52:20.675677Z"}]}
{"channel":"book","type":"update","data":[{"symbol":"ETH/USD","bids":[],"asks":[{"price":3796.81,"qty":0.00000000},{"price":3797.72,"qty":4.53808791}],"checksum":182855541,"timestamp":"2024-06-01T17:52:20.677399Z"}]}
{"channel":"book","type":"update","data":[{"symbol":"ETH/USD","bids":[{"price":3795.90,"qty":31.45132228}],"asks":[],"checksum":3188984051,"timestamp":"2024-06-01T17:52:20.679016Z"}]}
{"channel":"book","type":"update","data":[{"symbol":"ETH/USD","bids":[{"price":3795.89,"qty":0.00000000},{"price":3795.63,"qty":7.25300727}],"asks":[],"checksum":268420119,"timestamp":"2024-06-01T17:52:20.679093Z"}]}
{"channel":"book","type":"update","data":[{"symbol":"ETH/USD","bids":[{"price":3795.74,"qty":0.00000000},{"price":3795.53,"qty":2.15300000}],"asks":[],"checksum":3595467070,"timestamp":"2024-06-01T17:52:20.679147Z"}]}
{"channel":"book","type":"update","data":[{"symbol":"ETH/USD","bids":[{"price":3795.80,"qty":0.00000000},{"price":3795.52,"qty":3.00000000}],"asks":[],"checksum":3867692143,"timestamp":"2024-06-01T17:52:20.679218Z"}]}
{"channel":"book","type":"update","data":[{"symbol":"ETH/USD","bids":[],"asks":[{"price":3797.25,"qty":0.00000000},{"price":3797.86,"qty":0.68782190}],"checksum":2566539005,"timestamp":"2024-06-01T17:52:20.681661Z"}]}
{"channel":"book","type":"update","data":[{"symbol":"ETH/USD","bids":[],"asks":[{"price":3796.86,"qty":26.33755334}],"checksum":2006676750,"timestamp":"2024-06-01T17:52:20.686080Z"}]}
{"channel":"book","type":"update","data":[{"symbol":"ETH/USD","bids":[],"asks":[{"price":3797.13,"qty":26.33571583}],"checksum":2732614857,"timestamp":"2024-06-01T17:52:20.686119Z"}]}
{"channel":"book","type":"update","data":[{"symbol":"ETH/USD","bids":[{"price":3796.02,"qty":26.34333923}],"asks":[],"checksum":1568011933,"timestamp":"2024-06-01T17:52:20.686133Z"}]}
{"channel":"book","type":"update","data":[{"symbol":"ETH/USD","bids":[{"price":3796.55,"qty":26.33964340}],"asks":[],"checksum":2915394869,"timestamp":"2024-06-01T17:52:20.686145Z"}]}
{"channel":"book","type":"update","data":[{"symbol":"ETH/USD","bids":[{"price":3796.28,"qty":26.34151016}],"asks":[],"checksum":1358843385,"timestamp":"2024-06-01T17:52:20.686169Z"}]}
{"channel":"book","type":"update","data":[{"symbol":"ETH/USD","bids":[],"asks":[{"price":3797.48,"qty":26.33325861}],"checksum":825041399,"timestamp":"2024-06-01T17:52:20.686227Z"}]}
{"channel":"book","type":"update","data":[{"symbol":"ETH/USD","bids":[{"price":3796.03,"qty":0.00515068}],"asks":[],"checksum":2286297340,"timestamp":"2024-06-01T17:52:20.690497Z"}]}
{"channel":"book","type":"update","data":[{"symbol":"ETH/USD","bids":[{"price":3795.90,"qty":31.44614958}],"asks":[],"checksum":2094969054,"timestamp":"2024-06-01T17:52:20.690520Z"}]}
{"channel":"book","type":"update","data":[{"symbol":"ETH/USD","bids":[],"asks":[{"price":3796.83,"qty":0.00000000},{"price":3797.59,"qty":3.00000000},{"price":3796.65,"qty":1.35639439}],"checksum":537049419,"timestamp":"2024-06-01T17:52:20.690679Z"}]}
{"channel":"book","type":"update","data":[{"symbol":"ETH/USD","bids":[{"price":3796.47,"qty":26.34021153}],"asks":[],"checksum":3893180041,"timestamp":"2024-06-01T17:52:20.692424Z"}]}
{"channel":"book","type":"update","data":[{"symbol":"ETH/USD","bids":[],"asks":[{"price":3796.65,"qty":0.82961421}],"checksum":3505362941,"timestamp":"2024-06-01T17:52:20.695603Z"}]}
{"channel":"book","type":"update","data":[{"symbol":"ETH/USD","bids":[{"price":3796.24,"qty":0.00000000},{"price":3795.79,"qty":3.40262063},{"price":3796.33,"qty":0.77000000}],"asks":[],"checksum":4043722874,"timestamp":"2024-06-01T17:52:20.695620Z"}]}
{"channel":"book","type":"update","data":[{"symbol":"ETH/USD","bids":[{"price":3795.90,"qty":27.08614958}],"asks":[],"checksum":775169600,"timestamp":"2024-06-01T17:52:20.697046Z"}]}
{"channel":"book","type":"update","data":[{"symbol":"ETH/USD","bids":[{"price":3796.55,"qty":0.00000000},{"price":3795.79,"qty":3.40262063}],"asks":[],"checksum":1200207085,"timestamp":"2024-06-01T17:52:20.697688Z"}]}
{"channel":"book","type":"update","data":[{"symbol":"ETH/USD","bids":[{"price":3796.33,"qty":1.54000000}],"asks":[],"checksum":3047157185,"timestamp":"2024-06-01T17:52:20.701187Z"}]}
{"channel":"book","type":"update","data":[{"symbol":"ETH/USD","bids":[{"price":3796.47,"qty":0.00000000},{"price":3795.71,"qty":3.95144465}],"asks":[],"checksum":1284087721,"timestamp":"2024-06-01T17:52:20.705153Z"}]}
{"channel":"book","type":"update","data":[{"symbol":"ETH/USD","bids":[],"asks":[{"price":3796.86,"qty":0.00000000},{"price":3797.86,"qty":0.68782190}],"checksum":1060121727,"timestamp":"2024-06-01T17:52:20.708275Z"}]}
{"channel":"book","type":"update","data":[{"symbol":"ETH/USD","bids":[],"asks":[{"price":3796.95,"qty":0.00000000},{"price":3797.90,"qty":0.52678018}],"checksum":539114930,"timestamp":"2024-06-01T17:52:20.711363Z"}]}
{"channel":"book","type":"update","data":[{"symbol":"ETH/USD","bids":[{"price":3795.90,"qty":27.07677859},{"price":3796.25,"qty":0.53620489}],"asks":[],"checksum":786324432,"timestamp":"2024-06-01T17:52:20.713987Z"}]}
{"channel":"book","type":"update","data":[{"symbol":"ETH/USD","bids":[],"asks":[{"price":3796.82,"qty":26.33785097}],"checksum":1246197842,"timestamp":"2024-06-01T17:52:20.752392Z"}]}
{"channel":"book","type":"update","data":[{"symbol":"ETH/USD","bids":[{"price":3796.51,"qty":26.33993315}],"asks":[],"checksum":2769751826,"timestamp":"2024-06-01T17:52:20.756730Z"}]}
{"channel":"book","type":"update","data":[{"symbol":"ETH/USD","bids":[],"asks":[{"price":3796.92,"qty":0.77000000}],"checksum":605798556,"timestamp":"2024-06-01T17:52:20.760673Z"}]}
{"channel":"book","type":"update","data":[{"symbol":"ETH/USD","bids":[{"price":3796.52,"qty":0.00543677}],"asks":[],"checksum":2988742885,"timestamp":"2024-06-01T17:52:20.770730Z"}]}
{"channel":"book","type":"update","data":[{"symbol":"ETH/USD","bids":[{"price":3796.03,"qty":0.00000000},{"price":3795.79,"qty":3.40262063}],"asks":[],"checksum":3298451585,"timestamp":"2024-06-01T17:52:20.770767Z"}]}
{"channel":"book","type":"update","data":[{"symbol":"ETH/USD","bids":[{"price":3796.25,"qty":0.52683569},{"price":3796.34,"qty":0.00936898}],"asks":[],"checksum":1641962149,"timestamp":"2024-06-01T17:52:20.776126Z"}]}
{"channel":"book","type":"update","data":[{"symbol":"ETH/USD","bids":[{"price":3795.91,"qty":20.09961856}],"asks":[],"checksum":2710867565,"timestamp":"2024-06-01T17:52:20.819039Z"}]}
{"channel":"book","type":"update","data":[{"symbol":"ETH/USD","bids":[{"price":3795.91,"qty":20.44364496}],"asks":[],"checksum":330124961,"timestamp":"2024-06-01T17:52:20.820907Z"}]}
{"channel":"book","type":"update","data":[{"symbol":"ETH/USD","bids":[{"price":3796.34,"qty":0.00000000},{"price":3795.79,"qty":3.40262063},{"price":3796.53,"qty":0.00936851}],"asks":[],"checksum":3466161721,"timestamp":"2024-06-01T17:52:20.834341Z"}]}
{"channel":"book","type":"update","data":[{"symbol":"ETH/USD","bids":[],"asks":[{"price":3796.82,"qty":0.00000000},{"price":3797.81,"qty":4.53808791}],"checksum":2790082084,"timestamp":"2024-06-01T17:52:21.251162Z"}]}
{"channel":"book","type":"update","data":[{"symbol":"ETH/USD","bids":[],"asks":[{"price":3796.84,"qty":26.36403467}],"checksum":4288475289,"timestamp":"2024-06-01T17:52:21.255800Z"}]}
{"channel":"book","type":"update","data":[{"symbol":"ETH/USD","bids":[{"price":3796.55,"qty":26.33963550}],"asks":[],"checksum":900675203,"timestamp":"2024-06-01T17:52:21.255852Z"}]}
{"channel":"book","type":"update","data":[{"symbol":"ETH/USD","bids":[{"price":3796.55,"qty":0.00000000},{"price":3795.90,"qty":27.07677859}],"asks":[],"checksum":4288475289,"timestamp":"2024-06-01T17:52:21.283778Z"}]}
{"channel":"book","type":"update","data":[{"symbol":"ETH/USD","bids":[{"price":3796.53,"qty":0.00000000},{"price":3795.79,"qty":3.40262063},{"price":3796.56,"qty":0.00936844}],"asks":[],"checksum":210080270,"timestamp":"2024-06-01T17:52:21.326301Z"}]}
{"channel":"book","type":"update","data":[{"symbol":"ETH/USD","bids":[],"asks":[{"price":3796.87,"qty":26.33754544}],"checksum":4293708889,"timestamp":"2024-06-01T17:52:21.326500Z"}]}
{"channel":"book","type":"update","data":[{"symbol":"ETH/USD","bids":[{"price":3796.55,"qty":26.33969871}],"asks":[],"checksum":786139335,"timestamp":"2024-06-01T17:52:21.326609Z"}]}
{"channel":"book","type":"update","data":[{"symbol":"ETH/USD","bids":[{"price":3796.56,"qty":0.00000000},{"price":3795.90,"qty":27.07677859},{"price":3796.53,"qty":0.00936851}],"asks":[],"checksum":4117098826,"timestamp":"2024-06-01T17:52:21.381042Z"}]}
{"channel":"book","type":"update","data":[{"symbol":"ETH/USD","bids":[{"price":3796.53,"qty":0.00000000},{"price":3795.90,"qty":27.07677859},{"price":3796.56,"qty":0.00936844}],"asks":[],"checksum":786139335,"timestamp":"2024-06-01T17:52:21.433989Z"}]}
{"channel":"book","type":"update","data":[{"symbol":"ETH/USD","bids":[{"price":3796.56,"qty":0.00000000},{"price":3795.90,"qty":27.07677859},{"price":3796.57,"qty":0.00936841}],"asks":[],"checksum":1579462166,"timestamp":"2024-06-01T17:52:21.497960Z"}]}
{"channel":"book","type":"update","data":[{"symbol":"ETH/USD","bids":[{"price":3796.55,"qty":0.00000000},{"price":3795.90,"qty":27.07677859}],"asks":[],"checksum":2400447112,"timestamp":"2024-06-01T17:52:21.550850Z"}]}
{"channel":"book","type":"update","data":[{"symbol":"ETH/USD","bids":[{"price":3796.57,"qty":0.00000000},{"price":3795.79,"qty":3.40262063},{"price":3796.56,"qty":0.00936844}],"asks":[],"checksum":4293708889,"timestamp":"2024-06-01T17:52:21.551841Z"}]}
{"channel":"book","type":"update","data":[{"symbol":"ETH/USD","bids":[{"price":3796.53,"qty":26.33981725}],"asks":[],"checksum":1652958359,"timestamp":"2024-06-01T17:52:21.554860Z"}]}
{"channel":"book","type":"update","data":[{"symbol":"ETH/USD","bids":[{"price":3796.56,"qty":0.00000000},{"price":3795.90,"qty":27.07677859},{"price":3796.57,"qty":0.00936841}],"asks":[],"checksum":309920326,"timestamp":"2024-06-01T17:52:21.607301Z"}]}
{"channel":"book","type":"update","data":[{"symbol":"ETH/USD","bids":[{"price":3796.57,"qty":0.00000000},{"price":3795.90,"qty":27.07677859},{"price":3796.54,"qty":0.00936849}],"asks":[],"checksum":655714945,"timestamp":"2024-06-01T17:52:21.651670Z"}]}
{"channel":"book","type":"update","data":[{"symbol":"ETH/USD","bids":[{"price":3796.53,"qty":0.00000000},{"price":3795.90,"qty":27.07677859}],"asks":[],"checksum":3128918607,"timestamp":"2024-06-01T17:52:21.661275Z"}]}
{"channel":"book","type":"update","data":[{"symbol":"ETH/USD","bids":[{"price":3796.54,"qty":26.34909618}],"asks":[],"checksum":1964326021,"timestamp":"2024-06-01T17:52:21.666172Z"}]}
{"channel":"book","type":"update","data":[{"symbol":"ETH/USD","bids":[],"asks":[{"price":3796.92,"qty":0.00000000},{"price":3797.81,"qty":4.53808791}],"checksum":2197310906,"timestamp":"2024-06-01T17:52:21.776703Z"}]}
{"channel":"book","type":"update","data":[{"symbol":"ETH/USD","bids":[{"price":3796.54,"qty":0.00936849}],"asks":[],"checksum":2273536135,"timestamp":"2024-06-01T17:52:21.794083Z"}]}
{"channel":"book","type":"update","data":[{"symbol":"ETH/USD","bids":[{"price":3796.54,"qty":0.00000000},{"price":3795.79,"qty":3.40262063},{"price":3796.55,"qty":0.00936846}],"asks":[],"checksum":3405455764,"timestamp":"2024-06-01T17:52:21.796799Z"}]}
{"channel":"book","type":"update","data":[{"symbol":"ETH/USD","bids":[{"price":3796.55,"qty":26.34902441}],"asks":[],"checksum":3533963955,"timestamp":"2024-06-01T17:52:21.798481Z"}]}
{"channel":"book","type":"update","data":[{"symbol":"ETH/USD","bids":[{"price":3796.55,"qty":0.00936846}],"asks":[],"checksum":3405455764,"timestamp":"2024-06-01T17:52:21.826571Z"}]}
{"channel":"book","type":"update","data":[{"symbol":"ETH/USD","bids":[{"price":3796.55,"qty":0.00000000},{"price":3795.79,"qty":3.40262063},{"price":3796.53,"qty":0.00936851}],"asks":[],"checksum":822690822,"timestamp":"2024-06-01T17:52:21.864645Z"}]}
{"channel":"book","type":"update","data":[{"symbol":"ETH/USD","bids":[{"price":3796.54,"qty":26.33977252}],"asks":[],"checksum":1109654851,"timestamp":"2024-06-01T17:52:21.870137Z"}]}
{"channel":"book","type":"update","data":[{"symbol":"ETH/USD","bids":[{"price":3796.54,"qty":0.00000000},{"price":3795.90,"qty":27.07677859}],"asks":[],"checksum":822690822,"timestamp":"2024-06-01T17:52:21.874846Z"}]}
{"channel":"book","type":"update","data":[{"symbol":"ETH/USD","bids":[],"asks":[{"price":3797.21,"qty":0.00000000},{"price":3797.90,"qty":0.52678018}],"checksum":1306313229,"timestamp":"2024-06-01T17:52:21.878023Z"}]}
{"channel":"book","type":"update","data":[{"symbol":"ETH/USD","bids":[],"asks":[{"price":3796.84,"qty":0.02631803}],"checksum":4166376586,"timestamp":"2024-06-01T17:52:21.886288Z"}]}
{"channel":"book","type":"update","data":[{"symbol":"ETH/USD","bids":[],"asks":[{"price":3796.86,"qty":26.33758126}],"checksum":457788289,"timestamp":"2024-06-01T17:52:21.891086Z"}]}
{"channel":"book","type":"update","data":[{"symbol":"ETH/USD","bids":[],"asks":[{"price":3796.91,"qty":0.77000000}],"checksum":2962248787,"timestamp":"2024-06-01T17:52:21.893593Z"}]}
{"channel":"book","type":"update","data":[{"symbol":"ETH/USD","bids":[{"price":3796.33,"qty":0.77000000}],"asks":[],"checksum":2575646630,"timestamp":"2024-06-01T17:52:22.076088Z"}]}
{"channel":"book","type":"update","data":[{"symbol":"ETH/USD","bids":[],"asks":[{"price":3796.91,"qty":0.00000000},{"price":3797.81,"qty":4.53808791},{"price":3797.01,"qty":0.77000000}],"checksum":3382664818,"timestamp":"2024-06-01T17:52:22.077956Z"}]}
{"channel":"book","type":"update","data":[{"symbol":"ETH/USD","bids":[],"asks":[{"price":3797.01,"qty":1.54000000}],"checksum":2366337978,"timestamp":"2024-06-01T17:52:22.078171Z"}]}
{"channel":"book","type":"update","data":[{"symbol":"ETH/USD","bids":[],"asks":[{"price":3796.84,"qty":0.00000000},{"price":3797.81,"qty":4.53808791}],"checksum":262262030,"timestamp":"2024-06-01T17:52:22.087233Z"}]}
{"channel":"book","type":"update","data":[{"symbol":"ETH/USD","bids":[],"asks":[{"price":3796.87,"qty":0.00000000},{"price":3797.90,"qty":0.52678018}],"checksum":348094136,"timestamp":"2024-06-01T17:52:22.098237Z"}]}
{"channel":"book","type":"update","data":[{"symbol":"ETH/USD","bids":[{"price":3796.51,"qty":0.00000000},{"price":3795.79,"qty":3.40262063}],"asks":[],"checksum":1545907716,"timestamp":"2024-06-01T17:52:22.098280Z"}]}
{"channel":"book","type":"update","data":[{"symbol":"ETH/USD","bids":[],"asks":[{"price":3796.86,"qty":0.00000000},{"price":3797.95,"qty":0.84574642}],"checksum":1154155799,"timestamp":"2024-06-01T17:52:22.098301Z"}]}
{"channel":"book","type":"update","data":[{"symbol":"ETH/USD","bids":[{"price":3796.29,"qty":0.00527129}],"asks":[],"checksum":3013697172,"timestamp":"2024-06-01T17:52:22.103273Z"}]}
{"channel":"book","type":"update","data":[{"symbol":"ETH/USD","bids":[],"asks":[{"price":3796.91,"qty":26.33723623}],"checksum":1036929676,"timestamp":"2024-06-01T17:52:22.103498Z"}]}
{"channel":"book","type":"update","data":[{"symbol":"ETH/USD","bids":[{"price":3796.61,"qty":26.33926611}],"asks":[],"checksum":3833369703,"timestamp":"2024-06-01T17:52:22.103623Z"}]}
{"channel":"book","type":"update","data":[{"symbol":"ETH/USD","bids":[],"asks":[{"price":3796.99,"qty":26.33669714}],"checksum":2115429057,"timestamp":"2024-06-01T17:52:22.103769Z"}]}
{"channel":"book","type":"update","data":[{"symbol":"ETH/USD","bids":[{"price":3796.52,"qty":0.00000000},{"price":3795.90,"qty":27.07677859}],"asks":[],"checksum":3392923202,"timestamp":"2024-06-01T17:52:22.104149Z"}]}
{"channel":"book","type":"update","data":[{"symbol":"ETH/USD","bids":[],"asks":[{"price":3796.91,"qty":0.00000000},{"price":3797.90,"qty":0.52678018}],"checksum":1361964936,"timestamp":"2024-06-01T17:52:22.125774Z"}]}
{"channel":"book","type":"update","data":[{"symbol":"ETH/USD","bids":[{"price":3796.53,"qty":0.00000000},{"price":3795.79,"qty":3.40262063},{"price":3796.62,"qty":0.00936829}],"asks":[],"checksum":1279833494,"timestamp":"2024-06-01T17:52:22.168333Z"}]}
{"channel":"book","type":"update","data":[{"symbol":"ETH/USD","bids":[{"price":3796.61,"qty":0.00000000},{"price":3795.79,"qty":3.40262063}],"asks":[],"checksum":1743613035,"timestamp":"2024-06-01T17:52:22.178126Z"}]}
{"channel":"book","type":"update","data":[{"symbol":"ETH/USD","bids":[],"asks":[{"price":3796.89,"qty":26.33737319}],"checksum":1547042060,"timestamp":"2024-06-01T17:52:22.183303Z"}]}
{"channel":"book","type":"update","data":[{"symbol":"ETH/USD","bids":[{"price":3796.59,"qty":26.33940308}],"asks":[],"checksum":1246620089,"timestamp":"2024-06-01T17:52:22.183322Z"}]}
{"channel":"book","type":"update","data":[{"symbol":"ETH/USD","bids":[{"price":3796.62,"qty":0.00000000},{"price":3795.79,"qty":3.40262063},{"price":3796.60,"qty":0.00936834}],"asks":[],"checksum":3065009054,"timestamp":"2024-06-01T17:52:22.245082Z"}]}
{"channel":"book","type":"update","data":[{"symbol":"ETH/USD","bids":[],"asks":[{"price":3796.98,"qty":0.02631833}],"checksum":590263078,"timestamp":"2024-06-01T17:52:22.347023Z"}]}
{"channel":"book","type":"update","data":[{"symbol":"ETH/USD","bids":[],"asks":[{"price":3796.89,"qty":0.00000000},{"price":3797.81,"qty":4.53808791}],"checksum":3461287746,"timestamp":"2024-06-01T17:52:22.349744Z"}]}
{"channel":"book","type":"update","data":[{"symbol":"ETH/USD","bids":[],"asks":[{"price":3796.88,"qty":26.33747027}],"checksum":2720366597,"timestamp":"2024-06-01T17:52:22.353964Z"}]}
{"channel":"book","type":"update","data":[{"symbol":"ETH/USD","bids":[{"price":3796.56,"qty":26.33956639}],"asks":[],"checksum":2885926761,"timestamp":"2024-06-01T17:52:22.353995Z"}]}
{"channel":"book","type":"update","data":[{"symbol":"ETH/USD","bids":[{"price":3796.59,"qty":0.00000000},{"price":3795.90,"qty":27.07677859}],"asks":[],"checksum":3128024240,"timestamp":"2024-06-01T17:52:22.366447Z"}]}
{"channel":"book","type":"update","data":[{"symbol":"ETH/USD","bids":[],"asks":[{"price":3796.99,"qty":0.00000000},{"price":3797.81,"qty":4.53808791}],"checksum":35583614,"timestamp":"2024-06-01T17:52:22.366587Z"}]}
{"channel":"book","type":"update","data":[{"symbol":"ETH/USD","bids":[{"price":3796.46,"qty":26.34026359}],"asks":[],"checksum":1490937736,"timestamp":"2024-06-01T17:52:22.370814Z"}]}
{"channel":"book","type":"update","data":[{"symbol":"ETH/USD","bids":[{"price":3796.60,"qty":0.00000000},{"price":3795.90,"qty":27.07677859},{"price":3796.57,"qty":0.00936853}],"asks":[],"checksum":1061910436,"timestamp":"2024-06-01T17:52:22.436677Z"}]}
{"channel":"book","type":"update","data":[{"symbol":"ETH/USD","bids":[],"asks":[{"price":3796.87,"qty":26.33751241}],"checksum":709251098,"timestamp":"2024-06-01T17:52:22.461555Z"}]}
{"channel":"book","type":"update","data":[{"symbol":"ETH/USD","bids":[],"asks":[{"price":3796.86,"qty":0.80000000}],"checksum":2814228353,"timestamp":"2024-06-01T17:52:22.574918Z"}]}
{"channel":"book","type":"update","data":[{"symbol":"ETH/USD","bids":[{"price":3796.29,"qty":0.00000000},{"price":3795.90,"qty":27.07677859}],"asks":[],"checksum":126804294,"timestamp":"2024-06-01T17:52:22.579073Z"}]}
{"channel":"book","type":"update","data":[{"symbol":"ETH/USD","bids":[{"price":3796.56,"qty":26.34483768}],"asks":[],"checksum":2964738596,"timestamp":"2024-06-01T17:52:22.579142Z"}]}
{"channel":"book","type":"update","data":[{"symbol":"ETH/USD","bids":[{"price":3796.33,"qty":0.00000000},{"price":3795.79,"qty":3.40262063},{"price":3796.43,"qty":0.77000000}],"asks":[],"checksum":2327149397,"timestamp":"2024-06-01T17:52:22.603394Z"}]}
{"channel":"book","type":"update","data":[{"symbol":"ETH/USD","bids":[{"price":3796.43,"qty":1.54000000}],"asks":[],"checksum":2486683569,"timestamp":"2024-06-01T17:52:22.606368Z"}]}
{"channel":"book","type":"update","data":[{"symbol":"ETH/USD","bids":[{"price":3796.29,"qty":15.80365539}],"asks":[],"checksum":3062805216,"timestamp":"2024-06-01T17:52:22.688316Z"}]}
{"channel":"book","type":"update","data":[{"symbol":"ETH/USD","bids":[],"asks":[{"price":3797.01,"qty":0.77000000}],"checksum":3712172491,"timestamp":"2024-06-01T17:52:22.707842Z"}]}
{"channel":"book","type":"update","data":[{"symbol":"ETH/USD","bids":[],"asks":[{"price":3797.01,"qty":0.00000000},{"price":3797.59,"qty":3.00000000}],"checksum":596722903,"timestamp":"2024-06-01T17:52:22.710481Z"}]}
{"channel":"book","type":"update","data":[{"symbol":"ETH/USD","bids":[{"price":3796.56,"qty":0.00527129}],"asks":[],"checksum":4221679090,"timestamp":"2024-06-01T17:52:22.755625Z"}]}
{"channel":"book","type":"update","data":[{"symbol":"ETH/USD","bids":[{"price":3796.57,"qty":26.34888096}],"asks":[],"checksum":854472880,"timestamp":"2024-06-01T17:52:22.759560Z"}]}
{"channel":"book","type":"update","data":[{"symbol":"ETH/USD","bids":[{"price":3796.57,"qty":0.00936853}],"asks":[],"checksum":4221679090,"timestamp":"2024-06-01T17:52:22.787700Z"}]}
{"channel":"book","type":"update","data":[{"symbol":"ETH/USD","bids":[{"price":3796.56,"qty":0.00000000},{"price":3795.90,"qty":11.27100000}],"asks":[],"checksum":3192720657,"timestamp":"2024-06-01T17:52:22.796670Z"}]}
{"channel":"book","type":"update","data":[{"symbol":"ETH/USD","bids":[{"price":3796.47,"qty":0.00534931}],"asks":[],"checksum":263342306,"timestamp":"2024-06-01T17:52:22.796923Z"}]}
{"channel":"book","type":"update","data":[{"symbol":"ETH/USD","bids":[{"price":3796.57,"qty":0.00000000},{"price":3795.90,"qty":11.27100000},{"price":3796.47,"qty":0.01471810}],"asks":[],"checksum":3022027823,"timestamp":"2024-06-01T17:52:22.803332Z"}]}
{"channel":"book","type":"update","data":[{"symbol":"ETH/USD","bids":[],"asks":[{"price":3797.04,"qty":0.77000000}],"checksum":1027994899,"timestamp":"2024-06-01T17:52:22.807989Z"}]}
{"channel":"book","type":"update","data":[{"symbol":"ETH/USD","bids":[{"price":3796.46,"qty":0.00000000},{"price":3795.79,"qty":3.40262063}],"asks":[],"checksum":2108581323,"timestamp":"2024-06-01T17:52:22.808635Z"}]}
{"channel":"book","type":"update","data":[{"symbol":"ETH/USD","bids":[{"price":3796.58,"qty":26.33943078}],"asks":[],"checksum":2782590465,"timestamp":"2024-06-01T17:52:22.812572Z"}]}
{"channel":"book","type":"update","data":[{"symbol":"ETH/USD","bids":[{"price":3796.48,"qty":26.34018880}],"asks":[],"checksum":700911370,"timestamp":"2024-06-01T17:52:22.812712Z"}]}
{"channel":"book","type":"update","data":[{"symbol":"ETH/USD","bids":[{"price":3796.43,"qty":0.77000000}],"asks":[],"checksum":1582645570,"timestamp":"2024-06-01T17:52:22.829782Z"}]}
{"channel":"book","type":"update","data":[{"symbol":"ETH/USD","bids":[{"price":3795.91,"qty":20.09961856}],"asks":[],"checksum":2283948868,"timestamp":"2024-06-01T17:52:22.976598Z"}]}
{"channel":"book","type":"update","data":[{"symbol":"ETH/USD","bids":[{"price":3795.91,"qty":19.75456924}],"asks":[],"checksum":3300387098,"timestamp":"2024-06-01T17:52:22.985254Z"}]}
{"channel":"book","type":"update","data":[{"symbol":"ETH/USD","bids":[{"price":3796.58,"qty":0.00000000},{"price":3795.90,"qty":11.27100000}],"asks":[],"checksum":2562419000,"timestamp":"2024-06-01T17:52:23.037481Z"}]}
{"channel":"book","type":"update","data":[{"symbol":"ETH/USD","bids":[],"asks":[{"price":3796.87,"qty":0.00000000},{"price":3797.59,"qty":3.00000000}],"checksum":2148906734,"timestamp":"2024-06-01T17:52:23.037735Z"}]}
{"channel":"book","type":"update","data":[{"symbol":"ETH/USD","bids":[],"asks":[{"price":3796.86,"qty":27.13759948}],"checksum":767186049,"timestamp":"2024-06-01T17:52:23.043047Z"}]}
{"channel":"book","type":"update","data":[{"symbol":"ETH/USD","bids":[{"price":3796.56,"qty":26.33960726}],"asks":[],"checksum":843488856,"timestamp":"2024-06-01T17:52:23.043062Z"}]}
{"channel":"book","type":"update","data":[{"symbol":"ETH/USD","bids":[{"price":3796.56,"qty":26.34495884}],"asks":[],"checksum":535447242,"timestamp":"2024-06-01T17:52:23.141636Z"}]}
{"channel":"book","type":"update","data":[{"symbol":"ETH/USD","bids":[{"price":3796.47,"qty":0.00936879}],"asks":[],"checksum":302830788,"timestamp":"2024-06-01T17:52:23.143691Z"}]}
{"channel":"book","type":"update","data":[{"symbol":"ETH/USD","bids":[{"price":3796.47,"qty":0.00000000},{"price":3795.90,"qty":11.27100000},{"price":3796.57,"qty":0.00936855}],"asks":[],"checksum":2252438315,"timestamp":"2024-06-01T17:52:23.158046Z"}]}
{"channel":"book","type":"update","data":[{"symbol":"ETH/USD","bids":[],"asks":[{"price":3797.04,"qty":0.00000000},{"price":3797.81,"qty":4.53808791}],"checksum":1245485661,"timestamp":"2024-06-01T17:52:23.241054Z"}]}
{"channel":"book","type":"update","data":[{"symbol":"ETH/USD","bids":[{"price":3796.56,"qty":0.00535158}],"asks":[],"checksum":708094511,"timestamp":"2024-06-01T17:52:23.248734Z"}]}
{"channel":"book","type":"update","data":[{"symbol":"ETH/USD","bids":[{"price":3796.57,"qty":26.34889511}],"asks":[],"checksum":2537261780,"timestamp":"2024-06-01T17:52:23.253188Z"}]}
{"channel":"book","type":"update","data":[{"symbol":"ETH/USD","bids":[{"price":3796.57,"qty":0.00936855}],"asks":[],"checksum":708094511,"timestamp":"2024-06-01T17:52:23.276056Z"}]}
{"channel":"book","type":"update","data":[{"symbol":"ETH/USD","bids":[],"asks":[{"price":3796.86,"qty":0.80000000}],"checksum":2283922583,"timestamp":"2024-06-01T17:52:23.276100Z"}]}
{"channel":"book","type":"update","data":[{"symbol":"ETH/USD","bids":[],"asks":[{"price":3796.88,"qty":0.00000000},{"price":3797.90,"qty":0.52678018}],"checksum":2228676395,"timestamp":"2024-06-01T17:52:23.276202Z"}]}
{"channel":"book","type":"update","data":[{"symbol":"ETH/USD","bids":[{"price":3796.48,"qty":0.00000000},{"price":3795.90,"qty":11.27100000}],"asks":[],"checksum":3103121594,"timestamp":"2024-06-01T17:52:23.276926Z"}]}
{"channel":"book","type":"update","data":[{"symbol":"ETH/USD","bids":[],"asks":[{"price":3796.94,"qty":26.33706218}],"checksum":2906826571,"timestamp":"2024-06-01T17:52:23.282625Z"}]}
