{"channel":"book","type":"snapshot","data":[{"symbol":"ETH/GBP","bids":[{"price":2978.02,"qty":0.08559200},{"price":2977.72,"qty":13.17356104},{"price":2976.96,"qty":1.31769183},{"price":2976.70,"qty":5.37531359},{"price":2976.22,"qty":1.31801952},{"price":2975.82,"qty":1.31819699},{"price":2975.02,"qty":1.34000000},{"price":2975.01,"qty":1.31855212},{"price":2974.50,"qty":0.27200000},{"price":2973.19,"qty":0.14113766}],"asks":[{"price":2978.41,"qty":7.80930568},{"price":2978.85,"qty":13.16863349},{"price":2978.90,"qty":0.06973500},{"price":2979.30,"qty":20.68787922},{"price":2979.48,"qty":5.71477015},{"price":2979.53,"qty":1.31655968},{"price":2980.02,"qty":0.94850883},{"price":2980.18,"qty":1.00000000},{"price":2980.19,"qty":2.94416492},{"price":2980.20,"qty":1.31626615}],"checksum":1077149158}]}
{"channel":"book","type":"update","data":[{"symbol":"ETH/GBP","bids":[],"asks":[{"price":2978.42,"qty":6.58525695}],"checksum":1748364159,"timestamp":"2024-06-01T17:51:48.527512Z"}]}
{"channel":"book","type":"update","data":[{"symbol":"ETH/GBP","bids":[{"price":2978.03,"qty":6.58611345}],"asks":[],"checksum":2975310331,"timestamp":"2024-06-01T17:51:48.527658Z"}]}
{"channel":"book","type":"update","data":[{"symbol":"ETH/GBP","bids":[{"price":2978.03,"qty":0.00000000},{"price":2973.19,"qty":0.14113766}],"asks":[],"checksum":1748364159,"timestamp":"2024-06-01T17:51:48.532454Z"}]}
{"channel":"book","type":"update","data":[{"symbol":"ETH/GBP","bids":[],"asks":[{"price":2978.42,"qty":0.00000000},{"price":2980.20,"qty":1.31626615}],"checksum":1077149158,"timestamp":"2024-06-01T17:51:48.608063Z"}]}
{"channel":"book","type":"update","data":[{"symbol":"ETH/GBP","bids":[{"price":2978.03,"qty":6.58611345}],"asks":[],"checksum":950832141,"timestamp":"2024-06-01T17:51:48.657528Z"}]}
{"channel":"book","type":"update","data":[{"symbol":"ETH/GBP","bids":[],"asks":[{"price":2978.39,"qty":6.58532412}],"checksum":3669919343,"timestamp":"2024-06-01T17:51:48.657585Z"}]}
{"channel":"book","type":"update","data":[{"symbol":"ETH/GBP","bids":[{"price":2978.03,"qty":0.00000000},{"price":2973.19,"qty":0.14113766}],"asks":[],"checksum":3930295087,"timestamp":"2024-06-01T17:51:48.663073Z"}]}
{"channel":"book","type":"update","data":[{"symbol":"ETH/GBP","bids":[{"price":2978.14,"qty":6.58585555}],"asks":[],"checksum":1960983574,"timestamp":"2024-06-01T17:51:48.816650Z"}]}
{"channel":"book","type":"update","data":[{"symbol":"ETH/GBP","bids":[{"price":2978.14,"qty":0.00000000},{"price":2973.19,"qty":0.14113766}],"asks":[],"checksum":3930295087,"timestamp":"2024-06-01T17:51:49.579937Z"}]}
{"channel":"book","type":"update","data":[{"symbol":"ETH/GBP","bids":[],"asks":[{"price":2978.39,"qty":0.00000000},{"price":2980.20,"qty":1.31626615}],"checksum":1077149158,"timestamp":"2024-06-01T17:51:49.580024Z"}]}
{"channel":"book","type":"update","data":[{"symbol":"ETH/GBP","bids":[],"asks":[{"price":2979.48,"qty":0.00000000},{"price":2980.34,"qty":0.27479325}],"checksum":2198697217,"timestamp":"2024-06-01T17:51:49.583123Z"}]}
{"channel":"book","type":"update","data":[{"symbol":"ETH/GBP","bids":[{"price":2976.70,"qty":0.00000000},{"price":2973.18,"qty":0.27800000}],"asks":[],"checksum":1833215473,"timestamp":"2024-06-01T17:51:49.583154Z"}]}
{"channel":"book","type":"update","data":[{"symbol":"ETH/GBP","bids":[],"asks":[{"price":2980.18,"qty":0.00000000},{"price":2980.76,"qty":1.31601441}],"checksum":1289473638,"timestamp":"2024-06-01T17:51:49.584648Z"}]}
{"channel":"book","type":"update","data":[{"symbol":"ETH/GBP","bids":[{"price":2977.10,"qty":5.37459136}],"asks":[],"checksum":1996143950,"timestamp":"2024-06-01T17:51:49.587120Z"}]}
{"channel":"book","type":"update","data":[{"symbol":"ETH/GBP","bids":[],"asks":[{"price":2979.65,"qty":4.75472015}],"checksum":2720449255,"timestamp":"2024-06-01T17:51:49.587287Z"}]}
{"channel":"book","type":"update","data":[{"symbol":"ETH/GBP","bids":[],"asks":[{"price":2979.53,"qty":0.00000000},{"price":2980.76,"qty":1.31601441}],"checksum":3556655421,"timestamp":"2024-06-01T17:51:49.590236Z"}]}
{"channel":"book","type":"update","data":[{"symbol":"ETH/GBP","bids":[],"asks":[{"price":2978.85,"qty":0.00000000},{"price":2980.95,"qty":0.22400000}],"checksum":312778085,"timestamp":"2024-06-01T17:51:49.590246Z"}]}
{"channel":"book","type":"update","data":[{"symbol":"ETH/GBP","bids":[{"price":2977.72,"qty":0.00000000},{"price":2973.18,"qty":0.27800000}],"asks":[],"checksum":2257568877,"timestamp":"2024-06-01T17:51:49.590267Z"}]}
{"channel":"book","type":"update","data":[{"symbol":"ETH/GBP","bids":[{"price":2977.74,"qty":0.31000000}],"asks":[],"checksum":4130439228,"timestamp":"2024-06-01T17:51:49.591226Z"}]}
{"channel":"book","type":"update","data":[{"symbol":"ETH/GBP","bids":[{"price":2977.74,"qty":0.00000000},{"price":2973.18,"qty":0.27800000}],"asks":[],"checksum":2257568877,"timestamp":"2024-06-01T17:51:49.594537Z"}]}
{"channel":"book","type":"update","data":[{"symbol":"ETH/GBP","bids":[],"asks":[{"price":2978.55,"qty":6.58498258}],"checksum":2759730099,"timestamp":"2024-06-01T17:51:49.597979Z"}]}
{"channel":"book","type":"update","data":[{"symbol":"ETH/GBP","bids":[],"asks":[{"price":2979.00,"qty":13.16794718}],"checksum":3990506995,"timestamp":"2024-06-01T17:51:49.598050Z"}]}
{"channel":"book","type":"update","data":[{"symbol":"ETH/GBP","bids":[],"asks":[{"price":2979.77,"qty":1.31645482}],"checksum":2057696656,"timestamp":"2024-06-01T17:51:49.598102Z"}]}
{"channel":"book","type":"update","data":[{"symbol":"ETH/GBP","bids":[{"price":2978.31,"qty":6.58549065}],"asks":[],"checksum":3499110131,"timestamp":"2024-06-01T17:51:49.598140Z"}]}
{"channel":"book","type":"update","data":[{"symbol":"ETH/GBP","bids":[{"price":2977.85,"qty":13.17299121}],"asks":[],"checksum":174173838,"timestamp":"2024-06-01T17:51:49.598290Z"}]}
{"channel":"book","type":"update","data":[{"symbol":"ETH/GBP","bids":[],"asks":[{"price":2979.65,"qty":0.00000000},{"price":2980.34,"qty":0.27479325}],"checksum":1543502587,"timestamp":"2024-06-01T17:51:49.598904Z"}]}
{"channel":"book","type":"update","data":[{"symbol":"ETH/GBP","bids":[],"asks":[{"price":2980.20,"qty":0.00000000},{"price":2980.76,"qty":1.31601441}],"checksum":131523965,"timestamp":"2024-06-01T17:51:49.601755Z"}]}
{"channel":"book","type":"update","data":[{"symbol":"ETH/GBP","bids":[],"asks":[{"price":2979.70,"qty":4.52264515}],"checksum":1732795130,"timestamp":"2024-06-01T17:51:49.603088Z"}]}
{"channel":"book","type":"update","data":[{"symbol":"ETH/GBP","bids":[],"asks":[{"price":2978.55,"qty":0.00000000},{"price":2980.76,"qty":1.31601441}],"checksum":3665758308,"timestamp":"2024-06-01T17:51:49.616454Z"}]}
{"channel":"book","type":"update","data":[{"symbol":"ETH/GBP","bids":[{"price":2978.31,"qty":0.00000000},{"price":2973.19,"qty":0.14113766}],"asks":[],"checksum":476152449,"timestamp":"2024-06-01T17:51:49.616464Z"}]}
{"channel":"book","type":"update","data":[{"symbol":"ETH/GBP","bids":[{"price":2977.85,"qty":0.00000000},{"price":2973.18,"qty":0.27800000}],"asks":[],"checksum":3230465745,"timestamp":"2024-06-01T17:51:49.616642Z"}]}
{"channel":"book","type":"update","data":[{"symbol":"ETH/GBP","bids":[],"asks":[{"price":2979.30,"qty":20.66471692}],"checksum":900365762,"timestamp":"2024-06-01T17:51:49.619798Z"}]}
{"channel":"book","type":"update","data":[{"symbol":"ETH/GBP","bids":[],"asks":[{"price":2978.99,"qty":0.01263373}],"checksum":837153140,"timestamp":"2024-06-01T17:51:49.620240Z"}]}
{"channel":"book","type":"update","data":[{"symbol":"ETH/GBP","bids":[],"asks":[{"price":2980.01,"qty":0.20717085}],"checksum":1658585839,"timestamp":"2024-06-01T17:51:49.642326Z"}]}
{"channel":"book","type":"update","data":[{"symbol":"ETH/GBP","bids":[],"asks":[{"price":2978.99,"qty":0.00000000},{"price":2980.34,"qty":0.27479325}],"checksum":946386676,"timestamp":"2024-06-01T17:51:49.642636Z"}]}
{"channel":"book","type":"update","data":[{"symbol":"ETH/GBP","bids":[],"asks":[{"price":2979.70,"qty":0.00000000},{"price":2980.76,"qty":1.31601441}],"checksum":3830374058,"timestamp":"2024-06-01T17:51:49.684287Z"}]}
{"channel":"book","type":"update","data":[{"symbol":"ETH/GBP","bids":[],"asks":[{"price":2979.00,"qty":0.00000000},{"price":2980.95,"qty":0.22400000}],"checksum":1583876285,"timestamp":"2024-06-01T17:51:49.686554Z"}]}
{"channel":"book","type":"update","data":[{"symbol":"ETH/GBP","bids":[{"price":2976.96,"qty":0.00000000},{"price":2972.96,"qty":0.27482948}],"asks":[],"checksum":4106261877,"timestamp":"2024-06-01T17:51:49.686605Z"}]}
{"channel":"book","type":"update","data":[{"symbol":"ETH/GBP","bids":[],"asks":[{"price":2979.87,"qty":7.25344515}],"checksum":4145250523,"timestamp":"2024-06-01T17:51:49.689611Z"}]}
{"channel":"book","type":"update","data":[{"symbol":"ETH/GBP","bids":[{"price":2977.18,"qty":1.31759845}],"asks":[],"checksum":1842517932,"timestamp":"2024-06-01T17:51:49.693890Z"}]}
{"channel":"book","type":"update","data":[{"symbol":"ETH/GBP","bids":[{"price":2978.03,"qty":6.58611345}],"asks":[],"checksum":1456906392,"timestamp":"2024-06-01T17:51:49.699510Z"}]}
{"channel":"book","type":"update","data":[{"symbol":"ETH/GBP","bids":[],"asks":[{"price":2978.61,"qty":6.58484207}],"checksum":2663301944,"timestamp":"2024-06-01T17:51:49.699568Z"}]}
{"channel":"book","type":"update","data":[{"symbol":"ETH/GBP","bids":[],"asks":[{"price":2980.34,"qty":0.00000000},{"price":2980.76,"qty":1.31601441}],"checksum":3821859506,"timestamp":"2024-06-01T17:51:49.703043Z"}]}
{"channel":"book","type":"update","data":[{"symbol":"ETH/GBP","bids":[{"price":2978.03,"qty":0.00000000},{"price":2973.18,"qty":0.27800000}],"asks":[],"checksum":2807008273,"timestamp":"2024-06-01T17:51:49.707489Z"}]}
{"channel":"book","type":"update","data":[{"symbol":"ETH/GBP","bids":[],"asks":[{"price":2978.90,"qty":0.00000000},{"price":2980.95,"qty":0.22400000},{"price":2979.27,"qty":0.06978200}],"checksum":1098804535,"timestamp":"2024-06-01T17:51:49.767551Z"}]}
{"channel":"book","type":"update","data":[{"symbol":"ETH/GBP","bids":[{"price":2978.02,"qty":0.00000000},{"price":2972.96,"qty":0.27482948},{"price":2978.32,"qty":0.08559100}],"asks":[],"checksum":1554666305,"timestamp":"2024-06-01T17:51:49.799041Z"}]}
{"channel":"book","type":"update","data":[{"symbol":"ETH/GBP","bids":[{"price":2977.26,"qty":0.31000000}],"asks":[],"checksum":1508645005,"timestamp":"2024-06-01T17:51:49.802129Z"}]}
{"channel":"book","type":"update","data":[{"symbol":"ETH/GBP","bids":[],"asks":[{"price":2979.06,"qty":13.16769603}],"checksum":1608519855,"timestamp":"2024-06-01T17:51:49.807342Z"}]}
{"channel":"book","type":"update","data":[{"symbol":"ETH/GBP","bids":[{"price":2977.90,"qty":13.17277436}],"asks":[],"checksum":1461668861,"timestamp":"2024-06-01T17:51:49.807374Z"}]}
{"channel":"book","type":"update","data":[{"symbol":"ETH/GBP","bids":[{"price":2978.38,"qty":6.58533437}],"asks":[],"checksum":1522274761,"timestamp":"2024-06-01T17:51:49.807414Z"}]}
{"channel":"book","type":"update","data":[{"symbol":"ETH/GBP","bids":[{"price":2977.93,"qty":0.31000000}],"asks":[],"checksum":275195144,"timestamp":"2024-06-01T17:51:49.810649Z"}]}
{"channel":"book","type":"update","data":[{"symbol":"ETH/GBP","bids":[{"price":2977.26,"qty":0.00000000},{"price":2975.01,"qty":1.31855212}],"asks":[],"checksum":2017348173,"timestamp":"2024-06-01T17:51:49.810687Z"}]}
{"channel":"book","type":"update","data":[{"symbol":"ETH/GBP","bids":[],"asks":[{"price":2978.41,"qty":0.00000000},{"price":2980.76,"qty":1.31601441}],"checksum":4118792584,"timestamp":"2024-06-01T17:51:49.820410Z"}]}
{"channel":"book","type":"update","data":[{"symbol":"ETH/GBP","bids":[{"price":2977.90,"qty":0.00000000},{"price":2974.50,"qty":0.27200000}],"asks":[],"checksum":3687930452,"timestamp":"2024-06-01T17:51:49.946075Z"}]}
{"channel":"book","type":"update","data":[{"symbol":"ETH/GBP","bids":[{"price":2978.38,"qty":0.00000000},{"price":2973.19,"qty":0.14113766}],"asks":[],"checksum":968409718,"timestamp":"2024-06-01T17:51:49.946090Z"}]}
{"channel":"book","type":"update","data":[{"symbol":"ETH/GBP","bids":[],"asks":[{"price":2978.61,"qty":0.00000000},{"price":2980.95,"qty":0.22400000}],"checksum":1838038138,"timestamp":"2024-06-01T17:51:49.946191Z"}]}
{"channel":"book","type":"update","data":[{"symbol":"ETH/GBP","bids":[{"price":2977.93,"qty":0.00000000},{"price":2973.18,"qty":0.27800000}],"asks":[],"checksum":3253683297,"timestamp":"2024-06-01T17:51:49.948920Z"}]}
{"channel":"book","type":"update","data":[{"symbol":"ETH/GBP","bids":[{"price":2977.26,"qty":0.31000000}],"asks":[],"checksum":3299413933,"timestamp":"2024-06-01T17:51:49.949298Z"}]}
{"channel":"book","type":"update","data":[{"symbol":"ETH/GBP","bids":[{"price":2978.39,"qty":6.58530937}],"asks":[],"checksum":905075622,"timestamp":"2024-06-01T17:51:49.952851Z"}]}
{"channel":"book","type":"update","data":[{"symbol":"ETH/GBP","bids":[],"asks":[{"price":2978.63,"qty":6.58479497}],"checksum":958190223,"timestamp":"2024-06-01T17:51:49.952983Z"}]}
{"channel":"book","type":"update","data":[{"symbol":"ETH/GBP","bids":[],"asks":[{"price":2978.63,"qty":0.00000000},{"price":2980.95,"qty":0.22400000}],"checksum":905075622,"timestamp":"2024-06-01T17:51:50.027977Z"}]}
{"channel":"book","type":"update","data":[{"symbol":"ETH/GBP","bids":[{"price":2978.39,"qty":0.00000000},{"price":2973.19,"qty":0.14113766}],"asks":[],"checksum":3299413933,"timestamp":"2024-06-01T17:51:50.028002Z"}]}
{"channel":"book","type":"update","data":[{"symbol":"ETH/GBP","bids":[{"price":2977.95,"qty":13.17255197}],"asks":[],"checksum":2823607036,"timestamp":"2024-06-01T17:51:50.033896Z"}]}
{"channel":"book","type":"update","data":[{"symbol":"ETH/GBP","bids":[],"asks":[{"price":2980.01,"qty":0.00000000},{"price":2981.15,"qty":1.41091270}],"checksum":1075415085,"timestamp":"2024-06-01T17:51:50.036828Z"}]}
{"channel":"book","type":"update","data":[{"symbol":"ETH/GBP","bids":[],"asks":[{"price":2979.86,"qty":0.20717085}],"checksum":265971618,"timestamp":"2024-06-01T17:51:50.037228Z"}]}
{"channel":"book","type":"update","data":[{"symbol":"ETH/GBP","bids":[],"asks":[{"price":2978.64,"qty":6.58477521}],"checksum":2590779093,"timestamp":"2024-06-01T17:51:50.064406Z"}]}
{"channel":"book","type":"update","data":[{"symbol":"ETH/GBP","bids":[{"price":2978.40,"qty":6.58527645}],"asks":[],"checksum":1256400641,"timestamp":"2024-06-01T17:51:50.064435Z"}]}
{"channel":"book","type":"update","data":[{"symbol":"ETH/GBP","bids":[{"price":2978.40,"qty":0.00000000},{"price":2974.50,"qty":0.27200000}],"asks":[],"checksum":2590779093,"timestamp":"2024-06-01T17:51:50.077197Z"}]}
{"channel":"book","type":"update","data":[{"symbol":"ETH/GBP","bids":[],"asks":[{"price":2978.64,"qty":0.00000000},{"price":2980.95,"qty":0.22400000}],"checksum":265971618,"timestamp":"2024-06-01T17:51:50.077267Z"}]}
{"channel":"book","type":"update","data":[{"symbol":"ETH/GBP","bids":[],"asks":[{"price":2980.93,"qty":0.27473522}],"checksum":3883334574,"timestamp":"2024-06-01T17:51:50.143787Z"}]}
{"channel":"book","type":"update","data":[{"symbol":"ETH/GBP","bids":[{"price":2978.41,"qty":6.58527151}],"asks":[],"checksum":4113934914,"timestamp":"2024-06-01T17:51:50.166094Z"}]}
{"channel":"book","type":"update","data":[{"symbol":"ETH/GBP","bids":[],"asks":[{"price":2979.05,"qty":6.58385842}],"checksum":2547374926,"timestamp":"2024-06-01T17:51:50.166124Z"}]}
{"channel":"book","type":"update","data":[{"symbol":"ETH/GBP","bids":[],"asks":[{"price":2979.05,"qty":0.00000000},{"price":2980.93,"qty":0.27473522}],"checksum":4113934914,"timestamp":"2024-06-01T17:51:50.174003Z"}]}
{"channel":"book","type":"update","data":[{"symbol":"ETH/GBP","bids":[{"price":2978.41,"qty":0.00000000},{"price":2974.50,"qty":0.27200000}],"asks":[],"checksum":3883334574,"timestamp":"2024-06-01T17:51:50.174766Z"}]}
{"channel":"book","type":"update","data":[{"symbol":"ETH/GBP","bids":[],"asks":[{"price":2979.06,"qty":0.00000000},{"price":2980.95,"qty":0.22400000}],"checksum":851435413,"timestamp":"2024-06-01T17:51:50.270857Z"}]}
{"channel":"book","type":"update","data":[{"symbol":"ETH/GBP","bids":[],"asks":[{"price":2980.02,"qty":0.00000000},{"price":2981.15,"qty":1.41091270}],"checksum":796147750,"timestamp":"2024-06-01T17:51:50.273698Z"}]}
{"channel":"book","type":"update","data":[{"symbol":"ETH/GBP","bids":[],"asks":[{"price":2978.61,"qty":6.58483606}],"checksum":4216855942,"timestamp":"2024-06-01T17:51:50.275862Z"}]}
{"channel":"book","type":"update","data":[{"symbol":"ETH/GBP","bids":[],"asks":[{"price":2979.26,"qty":13.16678869}],"checksum":1714945003,"timestamp":"2024-06-01T17:51:50.275984Z"}]}
{"channel":"book","type":"update","data":[{"symbol":"ETH/GBP","bids":[{"price":2978.37,"qty":6.58533973}],"asks":[],"checksum":3467941586,"timestamp":"2024-06-01T17:51:50.276060Z"}]}
{"channel":"book","type":"update","data":[{"symbol":"ETH/GBP","bids":[],"asks":[{"price":2979.26,"qty":0.00000000},{"price":2980.95,"qty":0.22400000}],"checksum":4247446737,"timestamp":"2024-06-01T17:51:50.281250Z"}]}
{"channel":"book","type":"update","data":[{"symbol":"ETH/GBP","bids":[{"price":2978.37,"qty":0.00000000},{"price":2974.50,"qty":0.27200000}],"asks":[],"checksum":4216855942,"timestamp":"2024-06-01T17:51:50.327059Z"}]}
{"channel":"book","type":"update","data":[{"symbol":"ETH/GBP","bids":[],"asks":[{"price":2979.05,"qty":13.16775683}],"checksum":2770834797,"timestamp":"2024-06-01T17:51:50.478106Z"}]}
{"channel":"book","type":"update","data":[{"symbol":"ETH/GBP","bids":[{"price":2978.39,"qty":6.58530878}],"asks":[],"checksum":4014325408,"timestamp":"2024-06-01T17:51:50.478531Z"}]}
{"channel":"book","type":"update","data":[{"symbol":"ETH/GBP","bids":[],"asks":[{"price":2978.61,"qty":0.00000000},{"price":2980.95,"qty":0.22400000}],"checksum":1257826776,"timestamp":"2024-06-01T17:51:50.618852Z"}]}
{"channel":"book","type":"update","data":[{"symbol":"ETH/GBP","bids":[{"price":2978.39,"qty":0.00000000},{"price":2974.50,"qty":0.27200000}],"asks":[],"checksum":314934858,"timestamp":"2024-06-01T17:51:50.620075Z"}]}
{"channel":"book","type":"update","data":[{"symbol":"ETH/GBP","bids":[],"asks":[{"price":2979.05,"qty":0.00000000},{"price":2981.04,"qty":0.94850883}],"checksum":3333763178,"timestamp":"2024-06-01T17:51:50.624481Z"}]}
{"channel":"book","type":"update","data":[{"symbol":"ETH/GBP","bids":[],"asks":[{"price":2978.58,"qty":6.58491516}],"checksum":2010129028,"timestamp":"2024-06-01T17:51:50.629805Z"}]}
{"channel":"book","type":"update","data":[{"symbol":"ETH/GBP","bids":[{"price":2978.35,"qty":6.58539342}],"asks":[],"checksum":2428259512,"timestamp":"2024-06-01T17:51:50.630057Z"}]}
{"channel":"book","type":"update","data":[{"symbol":"ETH/GBP","bids":[{"price":2978.35,"qty":0.00000000},{"price":2974.50,"qty":0.27200000}],"asks":[],"checksum":2010129028,"timestamp":"2024-06-01T17:51:50.647453Z"}]}
{"channel":"book","type":"update","data":[{"symbol":"ETH/GBP","bids":[],"asks":[{"price":2979.01,"qty":13.16790053}],"checksum":1090993858,"timestamp":"2024-06-01T17:51:50.682654Z"}]}
{"channel":"book","type":"update","data":[{"symbol":"ETH/GBP","bids":[],"asks":[{"price":2978.58,"qty":0.00000000},{"price":2980.95,"qty":0.22400000}],"checksum":3828569357,"timestamp":"2024-06-01T17:51:50.693952Z"}]}
{"channel":"book","type":"update","data":[{"symbol":"ETH/GBP","bids":[],"asks":[{"price":2979.01,"qty":0.00000000},{"price":2981.04,"qty":0.94850883}],"checksum":3333763178,"timestamp":"2024-06-01T17:51:50.701490Z"}]}
{"channel":"book","type":"update","data":[{"symbol":"ETH/GBP","bids":[{"price":2978.35,"qty":6.58540275}],"asks":[],"checksum":1602090926,"timestamp":"2024-06-01T17:51:50.764086Z"}]}
{"channel":"book","type":"update","data":[{"symbol":"ETH/GBP","bids":[],"asks":[{"price":2978.57,"qty":6.58494095}],"checksum":4291343181,"timestamp":"2024-06-01T17:51:50.764114Z"}]}
{"channel":"book","type":"update","data":[{"symbol":"ETH/GBP","bids":[],"asks":[{"price":2978.57,"qty":0.00000000},{"price":2981.04,"qty":0.94850883}],"checksum":1602090926,"timestamp":"2024-06-01T17:51:50.884350Z"}]}
{"channel":"book","type":"update","data":[{"symbol":"ETH/GBP","bids":[{"price":2978.35,"qty":0.00000000},{"price":2974.50,"qty":0.27200000}],"asks":[],"checksum":3333763178,"timestamp":"2024-06-01T17:51:50.884394Z"}]}
{"channel":"book","type":"update","data":[{"symbol":"ETH/GBP","bids":[],"asks":[{"price":2978.59,"qty":6.58489387}],"checksum":21143320,"timestamp":"2024-06-01T17:51:50.889506Z"}]}
{"channel":"book","type":"update","data":[{"symbol":"ETH/GBP","bids":[{"price":2978.36,"qty":6.58537411}],"asks":[],"checksum":3010085042,"timestamp":"2024-06-01T17:51:50.889641Z"}]}
{"channel":"book","type":"update","data":[{"symbol":"ETH/GBP","bids":[],"asks":[{"price":2979.26,"qty":13.16678869}],"checksum":2497904835,"timestamp":"2024-06-01T17:51:50.889678Z"}]}
{"channel":"book","type":"update","data":[{"symbol":"ETH/GBP","bids":[],"asks":[{"price":2980.82,"qty":1.00000000}],"checksum":3800620921,"timestamp":"2024-06-01T17:51:50.890871Z"}]}
{"channel":"book","type":"update","data":[{"symbol":"ETH/GBP","bids":[],"asks":[{"price":2979.26,"qty":0.00000000},{"price":2980.93,"qty":0.27473522}],"checksum":1130232636,"timestamp":"2024-06-01T17:51:50.894953Z"}]}
{"channel":"book","type":"update","data":[{"symbol":"ETH/GBP","bids":[{"price":2978.36,"qty":0.00000000},{"price":2974.50,"qty":0.27200000}],"asks":[],"checksum":963270024,"timestamp":"2024-06-01T17:51:51.118534Z"}]}
{"channel":"book","type":"update","data":[{"symbol":"ETH/GBP","bids":[{"price":2978.37,"qty":6.58535436}],"asks":[],"checksum":789338357,"timestamp":"2024-06-01T17:51:51.126228Z"}]}
{"channel":"book","type":"update","data":[{"symbol":"ETH/GBP","bids":[],"asks":[{"price":2979.02,"qty":13.16785370}],"checksum":1692381241,"timestamp":"2024-06-01T17:51:51.126247Z"}]}
{"channel":"book","type":"update","data":[{"symbol":"ETH/GBP","bids":[],"asks":[{"price":2978.59,"qty":0.00000000},{"price":2980.93,"qty":0.27473522}],"checksum":629908186,"timestamp":"2024-06-01T17:51:51.214378Z"}]}
{"channel":"book","type":"update","data":[{"symbol":"ETH/GBP","bids":[{"price":2978.37,"qty":0.00000000},{"price":2974.50,"qty":0.27200000}],"asks":[],"checksum":3191758086,"timestamp":"2024-06-01T17:51:51.214510Z"}]}
{"channel":"book","type":"update","data":[{"symbol":"ETH/GBP","bids":[],"asks":[{"price":2979.01,"qty":6.58394682}],"checksum":3112073063,"timestamp":"2024-06-01T17:51:51.219856Z"}]}
{"channel":"book","type":"update","data":[{"symbol":"ETH/GBP","bids":[],"asks":[{"price":2979.01,"qty":0.00000000},{"price":2980.93,"qty":0.27473522}],"checksum":3191758086,"timestamp":"2024-06-01T17:51:51.224310Z"}]}
{"channel":"book","type":"update","data":[{"symbol":"ETH/GBP","bids":[{"price":2978.39,"qty":6.58531639}],"asks":[],"checksum":3143964467,"timestamp":"2024-06-01T17:51:51.230146Z"}]}
{"channel":"book","type":"update","data":[{"symbol":"ETH/GBP","bids":[{"price":2978.39,"qty":0.00000000},{"price":2974.50,"qty":0.27200000}],"asks":[],"checksum":3191758086,"timestamp":"2024-06-01T17:51:51.284070Z"}]}
{"channel":"book","type":"update","data":[{"symbol":"ETH/GBP","bids":[],"asks":[{"price":2978.64,"qty":6.58478122}],"checksum":309318169,"timestamp":"2024-06-01T17:51:51.361067Z"}]}
{"channel":"book","type":"update","data":[{"symbol":"ETH/GBP","bids":[{"price":2978.40,"qty":6.58527468}],"asks":[],"checksum":2365535727,"timestamp":"2024-06-01T17:51:51.361089Z"}]}
{"channel":"book","type":"update","data":[{"symbol":"ETH/GBP","bids":[],"asks":[{"price":2978.64,"qty":0.00000000},{"price":2980.93,"qty":0.27473522}],"checksum":22768021,"timestamp":"2024-06-01T17:51:51.428644Z"}]}
{"channel":"book","type":"update","data":[{"symbol":"ETH/GBP","bids":[{"price":2978.40,"qty":0.00000000},{"price":2974.50,"qty":0.27200000}],"asks":[],"checksum":3191758086,"timestamp":"2024-06-01T17:51:51.560705Z"}]}
{"channel":"book","type":"update","data":[{"symbol":"ETH/GBP","bids":[{"price":2978.33,"qty":6.58545004}],"asks":[],"checksum":2683461091,"timestamp":"2024-06-01T17:51:51.565411Z"}]}
{"channel":"book","type":"update","data":[{"symbol":"ETH/GBP","bids":[],"asks":[{"price":2978.60,"qty":6.58485960}],"checksum":4195369402,"timestamp":"2024-06-01T17:51:51.565470Z"}]}
{"channel":"book","type":"update","data":[{"symbol":"ETH/GBP","bids":[],"asks":[{"price":2978.60,"qty":0.00000000},{"price":2980.93,"qty":0.27473522}],"checksum":2683461091,"timestamp":"2024-06-01T17:51:51.570545Z"}]}
{"channel":"book","type":"update","data":[{"symbol":"ETH/GBP","bids":[{"price":2978.33,"qty":0.00000000},{"price":2974.50,"qty":0.27200000}],"asks":[],"checksum":3191758086,"timestamp":"2024-06-01T17:51:51.570638Z"}]}
{"channel":"book","type":"update","data":[{"symbol":"ETH/GBP","bids":[],"asks":[{"price":2979.02,"qty":0.00000000},{"price":2980.95,"qty":0.22400000}],"checksum":3792710521,"timestamp":"2024-06-01T17:51:51.576868Z"}]}
{"channel":"book","type":"update","data":[{"symbol":"ETH/GBP","bids":[{"price":2977.95,"qty":0.00000000},{"price":2973.19,"qty":0.14113766}],"asks":[],"checksum":1273539770,"timestamp":"2024-06-01T17:51:51.576989Z"}]}
{"channel":"book","type":"update","data":[{"symbol":"ETH/GBP","bids":[{"price":2977.99,"qty":13.17236120}],"asks":[],"checksum":438087301,"timestamp":"2024-06-01T17:51:51.585247Z"}]}
{"channel":"book","type":"update","data":[{"symbol":"ETH/GBP","bids":[],"asks":[{"price":2979.26,"qty":13.16678869}],"checksum":4229313903,"timestamp":"2024-06-01T17:51:51.585285Z"}]}
{"channel":"book","type":"update","data":[{"symbol":"ETH/GBP","bids":[],"asks":[{"price":2979.26,"qty":0.00000000},{"price":2980.95,"qty":0.22400000}],"checksum":438087301,"timestamp":"2024-06-01T17:51:51.590057Z"}]}
{"channel":"book","type":"update","data":[{"symbol":"ETH/GBP","bids":[{"price":2978.44,"qty":6.58519741}],"asks":[],"checksum":3906572508,"timestamp":"2024-06-01T17:51:51.670762Z"}]}
{"channel":"book","type":"update","data":[{"symbol":"ETH/GBP","bids":[],"asks":[{"price":2979.26,"qty":6.58339434}],"checksum":1307215485,"timestamp":"2024-06-01T17:51:51.670818Z"}]}
{"channel":"book","type":"update","data":[{"symbol":"ETH/GBP","bids":[],"asks":[{"price":2979.26,"qty":0.00000000},{"price":2980.95,"qty":0.22400000}],"checksum":3906572508,"timestamp":"2024-06-01T17:51:51.678788Z"}]}
{"channel":"book","type":"update","data":[{"symbol":"ETH/GBP","bids":[{"price":2978.44,"qty":0.00000000},{"price":2974.50,"qty":0.27200000}],"asks":[],"checksum":438087301,"timestamp":"2024-06-01T17:51:51.681012Z"}]}
{"channel":"book","type":"update","data":[{"symbol":"ETH/GBP","bids":[{"price":2978.33,"qty":6.58545004}],"asks":[],"checksum":1210617131,"timestamp":"2024-06-01T17:51:51.807900Z"}]}
{"channel":"book","type":"update","data":[{"symbol":"ETH/GBP","bids":[],"asks":[{"price":2978.69,"qty":6.58465626}],"checksum":4254334541,"timestamp":"2024-06-01T17:51:51.807928Z"}]}
{"channel":"book","type":"update","data":[{"symbol":"ETH/GBP","bids":[],"asks":[{"price":2979.26,"qty":13.16678869}],"checksum":1818074592,"timestamp":"2024-06-01T17:51:51.808009Z"}]}
{"channel":"book","type":"update","data":[{"symbol":"ETH/GBP","bids":[],"asks":[{"price":2979.26,"qty":0.00000000},{"price":2980.93,"qty":0.27473522}],"checksum":4254334541,"timestamp":"2024-06-01T17:51:51.814108Z"}]}
{"channel":"book","type":"update","data":[{"symbol":"ETH/GBP","bids":[{"price":2978.33,"qty":0.00000000},{"price":2974.50,"qty":0.27200000}],"asks":[],"checksum":1906374968,"timestamp":"2024-06-01T17:51:51.814129Z"}]}
{"channel":"book","type":"update","data":[{"symbol":"ETH/GBP","bids":[],"asks":[{"price":2978.69,"qty":0.00000000},{"price":2980.95,"qty":0.22400000}],"checksum":438087301,"timestamp":"2024-06-01T17:51:51.912054Z"}]}
{"channel":"book","type":"update","data":[{"symbol":"ETH/GBP","bids":[],"asks":[{"price":2978.68,"qty":6.58468143}],"checksum":482739424,"timestamp":"2024-06-01T17:51:51.917555Z"}]}
{"channel":"book","type":"update","data":[{"symbol":"ETH/GBP","bids":[{"price":2978.43,"qty":6.58521240}],"asks":[],"checksum":1080133227,"timestamp":"2024-06-01T17:51:51.917627Z"}]}
{"channel":"book","type":"update","data":[{"symbol":"ETH/GBP","bids":[{"price":2978.43,"qty":0.00000000},{"price":2974.50,"qty":0.27200000}],"asks":[],"checksum":482739424,"timestamp":"2024-06-01T17:51:51.983908Z"}]}
{"channel":"book","type":"update","data":[{"symbol":"ETH/GBP","bids":[],"asks":[{"price":2978.68,"qty":0.00000000},{"price":2980.95,"qty":0.22400000}],"checksum":438087301,"timestamp":"2024-06-01T17:51:51.997478Z"}]}
{"channel":"book","type":"update","data":[{"symbol":"ETH/GBP","bids":[],"asks":[{"price":2978.67,"qty":6.58470156}],"checksum":2163672646,"timestamp":"2024-06-01T17:51:52.053405Z"}]}
{"channel":"book","type":"update","data":[{"symbol":"ETH/GBP","bids":[{"price":2978.42,"qty":6.58523433}],"asks":[],"checksum":1547699719,"timestamp":"2024-06-01T17:51:52.053492Z"}]}
{"channel":"book","type":"update","data":[{"symbol":"ETH/GBP","bids":[],"asks":[{"price":2979.26,"qty":13.16678869}],"checksum":1116082912,"timestamp":"2024-06-01T17:51:52.053510Z"}]}
{"channel":"book","type":"update","data":[{"symbol":"ETH/GBP","bids":[],"asks":[{"price":2979.26,"qty":0.00000000},{"price":2980.93,"qty":0.27473522}],"checksum":1547699719,"timestamp":"2024-06-01T17:51:52.059914Z"}]}
{"channel":"book","type":"update","data":[{"symbol":"ETH/GBP","bids":[],"asks":[{"price":2978.67,"qty":0.00000000},{"price":2980.95,"qty":0.22400000}],"checksum":1589083813,"timestamp":"2024-06-01T17:51:52.080480Z"}]}
{"channel":"book","type":"update","data":[{"symbol":"ETH/GBP","bids":[{"price":2978.42,"qty":0.00000000},{"price":2974.50,"qty":0.27200000}],"asks":[],"checksum":438087301,"timestamp":"2024-06-01T17:51:52.085778Z"}]}
{"channel":"book","type":"update","data":[{"symbol":"ETH/GBP","bids":[],"asks":[{"price":2978.66,"qty":6.58474239}],"checksum":3407996208,"timestamp":"2024-06-01T17:51:52.154429Z"}]}
{"channel":"book","type":"update","data":[{"symbol":"ETH/GBP","bids":[{"price":2978.33,"qty":6.58545004}],"asks":[],"checksum":4092786531,"timestamp":"2024-06-01T17:51:52.154456Z"}]}
{"channel":"book","type":"update","data":[{"symbol":"ETH/GBP","bids":[{"price":2978.33,"qty":0.00000000},{"price":2974.50,"qty":0.27200000}],"asks":[],"checksum":3407996208,"timestamp":"2024-06-01T17:51:52.159880Z"}]}
{"channel":"book","type":"update","data":[{"symbol":"ETH/GBP","bids":[],"asks":[{"price":2978.66,"qty":0.00000000},{"price":2980.95,"qty":0.22400000}],"checksum":438087301,"timestamp":"2024-06-01T17:51:52.330313Z"}]}
{"channel":"book","type":"update","data":[{"symbol":"ETH/GBP","bids":[{"price":2978.39,"qty":6.58531233}],"asks":[],"checksum":62664650,"timestamp":"2024-06-01T17:51:52.335747Z"}]}
{"channel":"book","type":"update","data":[{"symbol":"ETH/GBP","bids":[],"asks":[{"price":2978.65,"qty":6.58476083}],"checksum":2330050356,"timestamp":"2024-06-01T17:51:52.335792Z"}]}
{"channel":"book","type":"update","data":[{"symbol":"ETH/GBP","bids":[],"asks":[{"price":2979.26,"qty":13.16678869}],"checksum":2807214135,"timestamp":"2024-06-01T17:51:52.335883Z"}]}
{"channel":"book","type":"update","data":[{"symbol":"ETH/GBP","bids":[],"asks":[{"price":2979.26,"qty":0.00000000},{"price":2980.93,"qty":0.27473522}],"checksum":2330050356,"timestamp":"2024-06-01T17:51:52.341731Z"}]}
{"channel":"book","type":"update","data":[{"symbol":"ETH/GBP","bids":[],"asks":[{"price":2978.65,"qty":0.00000000},{"price":2980.95,"qty":0.22400000}],"checksum":62664650,"timestamp":"2024-06-01T17:51:52.530478Z"}]}
{"channel":"book","type":"update","data":[{"symbol":"ETH/GBP","bids":[],"asks":[{"price":2978.64,"qty":6.58477825}],"checksum":2022286069,"timestamp":"2024-06-01T17:51:52.535123Z"}]}
{"channel":"book","type":"update","data":[{"symbol":"ETH/GBP","bids":[],"asks":[{"price":2979.26,"qty":13.16678869}],"checksum":381012105,"timestamp":"2024-06-01T17:51:52.539590Z"}]}
{"channel":"book","type":"update","data":[{"symbol":"ETH/GBP","bids":[],"asks":[{"price":2979.26,"qty":0.00000000},{"price":2980.93,"qty":0.27473522}],"checksum":2022286069,"timestamp":"2024-06-01T17:51:52.542951Z"}]}
{"channel":"book","type":"update","data":[{"symbol":"ETH/GBP","bids":[],"asks":[{"price":2978.64,"qty":0.00000000},{"price":2980.95,"qty":0.22400000}],"checksum":62664650,"timestamp":"2024-06-01T17:51:52.571567Z"}]}
{"channel":"book","type":"update","data":[{"symbol":"ETH/GBP","bids":[{"price":2978.39,"qty":0.00000000},{"price":2974.50,"qty":0.27200000}],"asks":[],"checksum":438087301,"timestamp":"2024-06-01T17:51:52.571579Z"}]}
{"channel":"book","type":"update","data":[{"symbol":"ETH/GBP","bids":[{"price":2978.42,"qty":6.58524491}],"asks":[],"checksum":705951813,"timestamp":"2024-06-01T17:51:52.578152Z"}]}
{"channel":"book","type":"update","data":[{"symbol":"ETH/GBP","bids":[{"price":2978.42,"qty":0.00000000},{"price":2974.50,"qty":0.27200000}],"asks":[],"checksum":438087301,"timestamp":"2024-06-01T17:51:52.583237Z"}]}
{"channel":"book","type":"update","data":[{"symbol":"ETH/GBP","bids":[],"asks":[{"price":2979.26,"qty":6.58339434}],"checksum":599745698,"timestamp":"2024-06-01T17:51:52.650149Z"}]}
{"channel":"book","type":"update","data":[{"symbol":"ETH/GBP","bids":[],"asks":[{"price":2979.26,"qty":0.00000000},{"price":2980.95,"qty":0.22400000}],"checksum":438087301,"timestamp":"2024-06-01T17:51:52.655764Z"}]}
{"channel":"book","type":"update","data":[{"symbol":"ETH/GBP","bids":[{"price":2978.41,"qty":6.58526467}],"asks":[],"checksum":1055825778,"timestamp":"2024-06-01T17:51:52.683281Z"}]}
{"channel":"book","type":"update","data":[{"symbol":"ETH/GBP","bids":[{"price":2978.41,"qty":0.00000000},{"price":2974.50,"qty":0.27200000}],"asks":[],"checksum":438087301,"timestamp":"2024-06-01T17:51:52.687935Z"}]}
{"channel":"book","type":"update","data":[{"symbol":"ETH/GBP","bids":[],"asks":[{"price":2978.66,"qty":6.58472868}],"checksum":2979237692,"timestamp":"2024-06-01T17:51:52.753746Z"}]}
{"channel":"book","type":"update","data":[{"symbol":"ETH/GBP","bids":[],"asks":[{"price":2979.10,"qty":13.16752337}],"checksum":3124168539,"timestamp":"2024-06-01T17:51:52.753876Z"}]}
{"channel":"book","type":"update","data":[{"symbol":"ETH/GBP","bids":[],"asks":[{"price":2978.66,"qty":0.00000000},{"price":2980.93,"qty":0.27473522}],"checksum":2593704406,"timestamp":"2024-06-01T17:51:52.761732Z"}]}
{"channel":"book","type":"update","data":[{"symbol":"ETH/GBP","bids":[],"asks":[{"price":2979.10,"qty":0.00000000},{"price":2980.95,"qty":0.22400000}],"checksum":438087301,"timestamp":"2024-06-01T17:51:52.766335Z"}]}
{"channel":"book","type":"update","data":[{"symbol":"ETH/GBP","bids":[{"price":2978.41,"qty":6.58526422}],"asks":[],"checksum":4228721316,"timestamp":"2024-06-01T17:51:52.805393Z"}]}
{"channel":"book","type":"update","data":[{"symbol":"ETH/GBP","bids":[],"asks":[{"price":2978.65,"qty":6.58474646}],"checksum":1007575748,"timestamp":"2024-06-01T17:51:52.864473Z"}]}
{"channel":"book","type":"update","data":[{"symbol":"ETH/GBP","bids":[],"asks":[{"price":2979.30,"qty":0.00000000},{"price":2980.95,"qty":0.22400000}],"checksum":3061561120,"timestamp":"2024-06-01T17:51:53.037681Z"}]}
{"channel":"book","type":"update","data":[{"symbol":"ETH/GBP","bids":[],"asks":[{"price":2980.75,"qty":26.85092774}],"checksum":580920357,"timestamp":"2024-06-01T17:51:53.042272Z"}]}
{"channel":"book","type":"update","data":[{"symbol":"ETH/GBP","bids":[],"asks":[{"price":2979.76,"qty":8.32935010}],"checksum":21112413,"timestamp":"2024-06-01T17:51:53.042288Z"}]}
{"channel":"book","type":"update","data":[{"symbol":"ETH/GBP","bids":[],"asks":[{"price":2978.65,"qty":0.00000000},{"price":2980.93,"qty":0.27473522}],"checksum":3322740761,"timestamp":"2024-06-01T17:51:53.211819Z"}]}
{"channel":"book","type":"update","data":[{"symbol":"ETH/GBP","bids":[{"price":2978.41,"qty":0.00000000},{"price":2974.50,"qty":0.27200000}],"asks":[],"checksum":2942819812,"timestamp":"2024-06-01T17:51:53.212006Z"}]}
{"channel":"book","type":"update","data":[{"symbol":"ETH/GBP","bids":[],"asks":[{"price":2978.63,"qty":6.58479845}],"checksum":977642167,"timestamp":"2024-06-01T17:51:53.216371Z"}]}
{"channel":"book","type":"update","data":[{"symbol":"ETH/GBP","bids":[{"price":2978.39,"qty":6.58530836}],"asks":[],"checksum":2162543845,"timestamp":"2024-06-01T17:51:53.216492Z"}]}
{"channel":"book","type":"update","data":[{"symbol":"ETH/GBP","bids":[],"asks":[{"price":2979.09,"qty":13.16755892}],"checksum":4067764854,"timestamp":"2024-06-01T17:51:53.216581Z"}]}
{"channel":"book","type":"update","data":[{"symbol":"ETH/GBP","bids":[],"asks":[{"price":2979.09,"qty":0.00000000},{"price":2980.82,"qty":1.00000000}],"checksum":2162543845,"timestamp":"2024-06-01T17:51:53.221947Z"}]}
{"channel":"book","type":"update","data":[{"symbol":"ETH/GBP","bids":[{"price":2978.39,"qty":0.00000000},{"price":2974.50,"qty":0.27200000}],"asks":[],"checksum":977642167,"timestamp":"2024-06-01T17:51:53.342841Z"}]}
{"channel":"book","type":"update","data":[{"symbol":"ETH/GBP","bids":[],"asks":[{"price":2978.63,"qty":0.00000000},{"price":2980.93,"qty":0.27473522}],"checksum":2942819812,"timestamp":"2024-06-01T17:51:53.342873Z"}]}
{"channel":"book","type":"update","data":[{"symbol":"ETH/GBP","bids":[],"asks":[{"price":2978.67,"qty":6.58471679}],"checksum":1149627020,"timestamp":"2024-06-01T17:51:53.349774Z"}]}
{"channel":"book","type":"update","data":[{"symbol":"ETH/GBP","bids":[{"price":2978.43,"qty":6.58522670}],"asks":[],"checksum":880462570,"timestamp":"2024-06-01T17:51:53.349853Z"}]}
{"channel":"book","type":"update","data":[{"symbol":"ETH/GBP","bids":[{"price":2978.43,"qty":0.00000000},{"price":2974.50,"qty":0.27200000}],"asks":[],"checksum":1149627020,"timestamp":"2024-06-01T17:51:53.354920Z"}]}
{"channel":"book","type":"update","data":[{"symbol":"ETH/GBP","bids":[],"asks":[{"price":2978.67,"qty":0.00000000},{"price":2980.93,"qty":0.27473522}],"checksum":2942819812,"timestamp":"2024-06-01T17:51:53.366475Z"}]}
{"channel":"book","type":"update","data":[{"symbol":"ETH/GBP","bids":[],"asks":[{"price":2979.26,"qty":13.16678869}],"checksum":3084084226,"timestamp":"2024-06-01T17:51:53.437839Z"}]}
{"channel":"book","type":"update","data":[{"symbol":"ETH/GBP","bids":[],"asks":[{"price":2979.26,"qty":0.00000000},{"price":2980.93,"qty":0.27473522}],"checksum":2942819812,"timestamp":"2024-06-01T17:51:53.442832Z"}]}
{"channel":"book","type":"update","data":[{"symbol":"ETH/GBP","bids":[],"asks":[{"price":2978.65,"qty":6.58474497}],"checksum":4174123800,"timestamp":"2024-06-01T17:51:53.454321Z"}]}
{"channel":"book","type":"update","data":[{"symbol":"ETH/GBP","bids":[{"price":2978.41,"qty":6.58526391}],"asks":[],"checksum":274930018,"timestamp":"2024-06-01T17:51:53.454405Z"}]}
{"channel":"book","type":"update","data":[{"symbol":"ETH/GBP","bids":[],"asks":[{"price":2978.65,"qty":0.00000000},{"price":2980.93,"qty":0.27473522}],"checksum":2755595419,"timestamp":"2024-06-01T17:51:53.694123Z"}]}
{"channel":"book","type":"update","data":[{"symbol":"ETH/GBP","bids":[],"asks":[{"price":2979.68,"qty":0.31000000}],"checksum":2877375965,"timestamp":"2024-06-01T17:51:53.696921Z"}]}
{"channel":"book","type":"update","data":[{"symbol":"ETH/GBP","bids":[],"asks":[{"price":2978.64,"qty":6.58477167}],"checksum":3849197498,"timestamp":"2024-06-01T17:51:53.698688Z"}]}
{"channel":"book","type":"update","data":[{"symbol":"ETH/GBP","bids":[],"asks":[{"price":2979.26,"qty":13.16678869}],"checksum":2211966935,"timestamp":"2024-06-01T17:51:53.698892Z"}]}
{"channel":"book","type":"update","data":[{"symbol":"ETH/GBP","bids":[],"asks":[{"price":2979.26,"qty":0.00000000},{"price":2980.76,"qty":1.31601441}],"checksum":3849197498,"timestamp":"2024-06-01T17:51:53.705500Z"}]}
{"channel":"book","type":"update","data":[{"symbol":"ETH/GBP","bids":[{"price":2978.41,"qty":0.00000000},{"price":2974.50,"qty":0.27200000}],"asks":[],"checksum":4194737231,"timestamp":"2024-06-01T17:51:53.866255Z"}]}
{"channel":"book","type":"update","data":[{"symbol":"ETH/GBP","bids":[],"asks":[{"price":2978.64,"qty":0.00000000},{"price":2980.82,"qty":1.00000000}],"checksum":299347885,"timestamp":"2024-06-01T17:51:53.866268Z"}]}
{"channel":"book","type":"update","data":[{"symbol":"ETH/GBP","bids":[],"asks":[{"price":2979.27,"qty":0.00000000},{"price":2980.93,"qty":0.27473522},{"price":2979.67,"qty":0.06979000}],"checksum":1693412174,"timestamp":"2024-06-01T17:51:53.870264Z"}]}
{"channel":"book","type":"update","data":[{"symbol":"ETH/GBP","bids":[],"asks":[{"price":2979.26,"qty":6.58339434}],"checksum":1156968461,"timestamp":"2024-06-01T17:51:53.871217Z"}]}
{"channel":"book","type":"update","data":[{"symbol":"ETH/GBP","bids":[{"price":2978.39,"qty":6.58530245}],"asks":[],"checksum":2160677002,"timestamp":"2024-06-01T17:51:53.871267Z"}]}
{"channel":"book","type":"update","data":[{"symbol":"ETH/GBP","bids":[],"asks":[{"price":2979.64,"qty":1.31704884}],"checksum":929504884,"timestamp":"2024-06-01T17:51:53.873189Z"}]}
{"channel":"book","type":"update","data":[{"symbol":"ETH/GBP","bids":[{"price":2977.99,"qty":0.00000000},{"price":2974.50,"qty":0.27200000}],"asks":[],"checksum":1023160343,"timestamp":"2024-06-01T17:51:53.876351Z"}]}
{"channel":"book","type":"update","data":[{"symbol":"ETH/GBP","bids":[{"price":2978.39,"qty":0.00000000},{"price":2973.19,"qty":0.14113766}],"asks":[],"checksum":3623977308,"timestamp":"2024-06-01T17:51:53.876606Z"}]}
{"channel":"book","type":"update","data":[{"symbol":"ETH/GBP","bids":[],"asks":[{"price":2979.26,"qty":0.00000000},{"price":2980.76,"qty":1.31601441}],"checksum":3133889750,"timestamp":"2024-06-01T17:51:53.876662Z"}]}
{"channel":"book","type":"update","data":[{"symbol":"ETH/GBP","bids":[{"price":2977.90,"qty":13.17277592}],"asks":[],"checksum":3779033646,"timestamp":"2024-06-01T17:51:53.881439Z"}]}
{"channel":"book","type":"update","data":[{"symbol":"ETH/GBP","bids":[],"asks":[{"price":2979.63,"qty":13.16516782}],"checksum":3803026747,"timestamp":"2024-06-01T17:51:53.910104Z"}]}
{"channel":"book","type":"update","data":[{"symbol":"ETH/GBP","bids":[],"asks":[{"price":2979.60,"qty":1.31709421}],"checksum":119624828,"timestamp":"2024-06-01T17:51:53.913118Z"}]}
{"channel":"book","type":"update","data":[{"symbol":"ETH/GBP","bids":[],"asks":[{"price":2979.64,"qty":0.00000000},{"price":2980.75,"qty":26.85092774}],"checksum":1235402780,"timestamp":"2024-06-01T17:51:53.915897Z"}]}
{"channel":"book","type":"update","data":[{"symbol":"ETH/GBP","bids":[],"asks":[{"price":2979.63,"qty":0.00000000},{"price":2980.76,"qty":1.31601441}],"checksum":4079714310,"timestamp":"2024-06-01T17:51:53.917993Z"}]}
{"channel":"book","type":"update","data":[{"symbol":"ETH/GBP","bids":[{"price":2978.33,"qty":6.58544356}],"asks":[],"checksum":2456014245,"timestamp":"2024-06-01T17:51:54.007459Z"}]}
{"channel":"book","type":"update","data":[{"symbol":"ETH/GBP","bids":[],"asks":[{"price":2978.56,"qty":6.58494563}],"checksum":3209622238,"timestamp":"2024-06-01T17:51:54.007615Z"}]}
{"channel":"book","type":"update","data":[{"symbol":"ETH/GBP","bids":[{"price":2978.33,"qty":0.00000000},{"price":2974.50,"qty":0.27200000}],"asks":[],"checksum":3707467513,"timestamp":"2024-06-01T17:51:54.185327Z"}]}
{"channel":"book","type":"update","data":[{"symbol":"ETH/GBP","bids":[],"asks":[{"price":2978.56,"qty":0.00000000},{"price":2980.76,"qty":1.31601441}],"checksum":4079714310,"timestamp":"2024-06-01T17:51:54.185341Z"}]}
{"channel":"book","type":"update","data":[{"symbol":"ETH/GBP","bids":[],"asks":[{"price":2980.19,"qty":0.00000000},{"price":2980.82,"qty":1.00000000}],"checksum":2195405622,"timestamp":"2024-06-01T17:51:54.191127Z"}]}
{"channel":"book","type":"update","data":[{"symbol":"ETH/GBP","bids":[],"asks":[{"price":2979.59,"qty":13.16534279}],"checksum":2433933756,"timestamp":"2024-06-01T17:51:54.191968Z"}]}
{"channel":"book","type":"update","data":[{"symbol":"ETH/GBP","bids":[{"price":2978.36,"qty":6.58537594}],"asks":[],"checksum":1960355185,"timestamp":"2024-06-01T17:51:54.192099Z"}]}
{"channel":"book","type":"update","data":[{"symbol":"ETH/GBP","bids":[],"asks":[{"price":2978.60,"qty":6.58486594}],"checksum":2960463167,"timestamp":"2024-06-01T17:51:54.192170Z"}]}
{"channel":"book","type":"update","data":[{"symbol":"ETH/GBP","bids":[],"asks":[{"price":2979.56,"qty":1.31710018}],"checksum":1414104876,"timestamp":"2024-06-01T17:51:54.194981Z"}]}
{"channel":"book","type":"update","data":[{"symbol":"ETH/GBP","bids":[],"asks":[{"price":2979.60,"qty":0.00000000},{"price":2980.75,"qty":26.85092774}],"checksum":72843518,"timestamp":"2024-06-01T17:51:54.195139Z"}]}
{"channel":"book","type":"update","data":[{"symbol":"ETH/GBP","bids":[],"asks":[{"price":2978.60,"qty":0.00000000},{"price":2980.76,"qty":1.31601441}],"checksum":2365052057,"timestamp":"2024-06-01T17:51:54.197607Z"}]}
{"channel":"book","type":"update","data":[{"symbol":"ETH/GBP","bids":[],"asks":[{"price":2979.59,"qty":0.00000000},{"price":2980.82,"qty":1.00000000}],"checksum":3845891543,"timestamp":"2024-06-01T17:51:54.197740Z"}]}
{"channel":"book","type":"update","data":[{"symbol":"ETH/GBP","bids":[{"price":2978.36,"qty":0.00000000},{"price":2974.50,"qty":0.27200000}],"asks":[],"checksum":377409778,"timestamp":"2024-06-01T17:51:54.228903Z"}]}
{"channel":"book","type":"update","data":[{"symbol":"ETH/GBP","bids":[],"asks":[{"price":2978.60,"qty":6.58485672}],"checksum":721981737,"timestamp":"2024-06-01T17:51:54.340068Z"}]}
{"channel":"book","type":"update","data":[{"symbol":"ETH/GBP","bids":[{"price":2978.33,"qty":6.58544474}],"asks":[],"checksum":2580917227,"timestamp":"2024-06-01T17:51:54.340184Z"}]}
{"channel":"book","type":"update","data":[{"symbol":"ETH/GBP","bids":[{"price":2978.33,"qty":0.00000000},{"price":2974.50,"qty":0.27200000}],"asks":[],"checksum":721981737,"timestamp":"2024-06-01T17:51:54.345057Z"}]}
{"channel":"book","type":"update","data":[{"symbol":"ETH/GBP","bids":[],"asks":[{"price":2978.60,"qty":0.00000000},{"price":2980.82,"qty":1.00000000}],"checksum":377409778,"timestamp":"2024-06-01T17:51:54.366330Z"}]}
{"channel":"book","type":"update","data":[{"symbol":"ETH/GBP","bids":[],"asks":[{"price":2979.55,"qty":13.16551777}],"checksum":3089752181,"timestamp":"2024-06-01T17:51:54.406505Z"}]}
{"channel":"book","type":"update","data":[{"symbol":"ETH/GBP","bids":[],"asks":[{"price":2979.52,"qty":1.31709382}],"checksum":242041644,"timestamp":"2024-06-01T17:51:54.409402Z"}]}
{"channel":"book","type":"update","data":[{"symbol":"ETH/GBP","bids":[],"asks":[{"price":2979.55,"qty":0.00000000},{"price":2980.76,"qty":1.31601441}],"checksum":840235583,"timestamp":"2024-06-01T17:51:54.410621Z"}]}
{"channel":"book","type":"update","data":[{"symbol":"ETH/GBP","bids":[],"asks":[{"price":2979.56,"qty":0.00000000},{"price":2980.82,"qty":1.00000000}],"checksum":2624189488,"timestamp":"2024-06-01T17:51:54.412301Z"}]}
{"channel":"book","type":"update","data":[{"symbol":"ETH/GBP","bids":[],"asks":[{"price":2978.58,"qty":6.58491863}],"checksum":527902119,"timestamp":"2024-06-01T17:51:54.449790Z"}]}
{"channel":"book","type":"update","data":[{"symbol":"ETH/GBP","bids":[{"price":2978.33,"qty":6.58544562}],"asks":[],"checksum":695454995,"timestamp":"2024-06-01T17:51:54.449824Z"}]}
{"channel":"book","type":"update","data":[{"symbol":"ETH/GBP","bids":[],"asks":[{"price":2978.58,"qty":0.00000000},{"price":2980.82,"qty":1.00000000}],"checksum":1201394981,"timestamp":"2024-06-01T17:51:54.487450Z"}]}
{"channel":"book","type":"update","data":[{"symbol":"ETH/GBP","bids":[{"price":2978.33,"qty":0.00000000},{"price":2974.50,"qty":0.27200000}],"asks":[],"checksum":2624189488,"timestamp":"2024-06-01T17:51:54.534264Z"}]}
{"channel":"book","type":"update","data":[{"symbol":"ETH/GBP","bids":[],"asks":[{"price":2978.58,"qty":6.58490941}],"checksum":3143852797,"timestamp":"2024-06-01T17:51:54.584367Z"}]}
{"channel":"book","type":"update","data":[{"symbol":"ETH/GBP","bids":[{"price":2978.34,"qty":6.58541878}],"asks":[],"checksum":3900179954,"timestamp":"2024-06-01T17:51:54.584518Z"}]}
{"channel":"book","type":"update","data":[{"symbol":"ETH/GBP","bids":[],"asks":[{"price":2978.58,"qty":0.00000000},{"price":2980.82,"qty":1.00000000}],"checksum":227193193,"timestamp":"2024-06-01T17:51:54.741772Z"}]}
{"channel":"book","type":"update","data":[{"symbol":"ETH/GBP","bids":[{"price":2978.34,"qty":0.00000000},{"price":2974.50,"qty":0.27200000}],"asks":[],"checksum":2624189488,"timestamp":"2024-06-01T17:51:54.741852Z"}]}
{"channel":"book","type":"update","data":[{"symbol":"ETH/GBP","bids":[{"price":2978.36,"qty":6.58536807}],"asks":[],"checksum":785422479,"timestamp":"2024-06-01T17:51:54.747675Z"}]}
{"channel":"book","type":"update","data":[{"symbol":"ETH/GBP","bids":[],"asks":[{"price":2978.60,"qty":6.58486027}],"checksum":833104777,"timestamp":"2024-06-01T17:51:54.747706Z"}]}
{"channel":"book","type":"update","data":[{"symbol":"ETH/GBP","bids":[],"asks":[{"price":2979.51,"qty":13.16569275}],"checksum":1261782454,"timestamp":"2024-06-01T17:51:54.747730Z"}]}
{"channel":"book","type":"update","data":[{"symbol":"ETH/GBP","bids":[],"asks":[{"price":2979.51,"qty":0.00000000},{"price":2980.76,"qty":1.31601441}],"checksum":833104777,"timestamp":"2024-06-01T17:51:54.754072Z"}]}
{"channel":"book","type":"update","data":[{"symbol":"ETH/GBP","bids":[{"price":2978.36,"qty":0.00000000},{"price":2974.50,"qty":0.27200000}],"asks":[],"checksum":1046060259,"timestamp":"2024-06-01T17:51:54.853322Z"}]}
{"channel":"book","type":"update","data":[{"symbol":"ETH/GBP","bids":[{"price":2978.37,"qty":6.58535490}],"asks":[],"checksum":987332524,"timestamp":"2024-06-01T17:51:54.858635Z"}]}
{"channel":"book","type":"update","data":[{"symbol":"ETH/GBP","bids":[{"price":2978.37,"qty":0.00000000},{"price":2974.50,"qty":0.27200000}],"asks":[],"checksum":1046060259,"timestamp":"2024-06-01T17:51:54.925505Z"}]}
{"channel":"book","type":"update","data":[{"symbol":"ETH/GBP","bids":[],"asks":[{"price":2978.60,"qty":0.00000000},{"price":2980.82,"qty":1.00000000}],"checksum":2624189488,"timestamp":"2024-06-01T17:51:54.925559Z"}]}
{"channel":"book","type":"update","data":[{"symbol":"ETH/GBP","bids":[],"asks":[{"price":2978.62,"qty":6.58482706}],"checksum":1527379752,"timestamp":"2024-06-01T17:51:54.931204Z"}]}
{"channel":"book","type":"update","data":[{"symbol":"ETH/GBP","bids":[],"asks":[{"price":2978.62,"qty":0.00000000},{"price":2980.82,"qty":1.00000000}],"checksum":2624189488,"timestamp":"2024-06-01T17:51:54.962602Z"}]}
{"channel":"book","type":"update","data":[{"symbol":"ETH/GBP","bids":[],"asks":[{"price":2979.51,"qty":13.16569275}],"checksum":3827944339,"timestamp":"2024-06-01T17:51:54.967591Z"}]}
{"channel":"book","type":"update","data":[{"symbol":"ETH/GBP","bids":[{"price":2978.38,"qty":6.58532845}],"asks":[],"checksum":4272675741,"timestamp":"2024-06-01T17:51:54.967698Z"}]}
{"channel":"book","type":"update","data":[{"symbol":"ETH/GBP","bids":[],"asks":[{"price":2979.50,"qty":1.31706991}],"checksum":1756390848,"timestamp":"2024-06-01T17:51:54.970538Z"}]}
{"channel":"book","type":"update","data":[{"symbol":"ETH/GBP","bids":[],"asks":[{"price":2979.52,"qty":0.00000000},{"price":2980.76,"qty":1.31601441}],"checksum":1686005302,"timestamp":"2024-06-01T17:51:54.970561Z"}]}
{"channel":"book","type":"update","data":[{"symbol":"ETH/GBP","bids":[],"asks":[{"price":2979.51,"qty":0.00000000},{"price":2980.82,"qty":1.00000000}],"checksum":1488842585,"timestamp":"2024-06-01T17:51:54.974825Z"}]}
{"channel":"book","type":"update","data":[{"symbol":"ETH/GBP","bids":[{"price":2978.38,"qty":0.00000000},{"price":2974.50,"qty":0.27200000}],"asks":[],"checksum":1313499190,"timestamp":"2024-06-01T17:51:54.974911Z"}]}
{"channel":"book","type":"update","data":[{"symbol":"ETH/GBP","bids":[],"asks":[{"price":2978.57,"qty":6.58492269}],"checksum":4053375893,"timestamp":"2024-06-01T17:51:55.251093Z"}]}
{"channel":"book","type":"update","data":[{"symbol":"ETH/GBP","bids":[{"price":2978.33,"qty":6.58544606}],"asks":[],"checksum":2874409326,"timestamp":"2024-06-01T17:51:55.251180Z"}]}
{"channel":"book","type":"update","data":[{"symbol":"ETH/GBP","bids":[],"asks":[{"price":2979.49,"qty":13.16578024}],"checksum":1661647139,"timestamp":"2024-06-01T17:51:55.251245Z"}]}
{"channel":"book","type":"update","data":[{"symbol":"ETH/GBP","bids":[],"asks":[{"price":2979.49,"qty":0.00000000},{"price":2980.76,"qty":1.31601441}],"checksum":2874409326,"timestamp":"2024-06-01T17:51:55.256379Z"}]}
{"channel":"book","type":"update","data":[{"symbol":"ETH/GBP","bids":[],"asks":[{"price":2978.57,"qty":0.00000000},{"price":2980.82,"qty":1.00000000}],"checksum":3828621519,"timestamp":"2024-06-01T17:51:55.273465Z"}]}
{"channel":"book","type":"update","data":[{"symbol":"ETH/GBP","bids":[{"price":2978.33,"qty":0.00000000},{"price":2974.50,"qty":0.27200000}],"asks":[],"checksum":1313499190,"timestamp":"2024-06-01T17:51:55.273570Z"}]}
{"channel":"book","type":"update","data":[{"symbol":"ETH/GBP","bids":[],"asks":[{"price":2978.58,"qty":6.58490425}],"checksum":3420155624,"timestamp":"2024-06-01T17:51:55.356374Z"}]}
{"channel":"book","type":"update","data":[{"symbol":"ETH/GBP","bids":[{"price":2978.33,"qty":6.58544606}],"asks":[],"checksum":2245676570,"timestamp":"2024-06-01T17:51:55.356393Z"}]}
{"channel":"book","type":"update","data":[{"symbol":"ETH/GBP","bids":[{"price":2978.33,"qty":0.00000000},{"price":2974.50,"qty":0.27200000}],"asks":[],"checksum":3420155624,"timestamp":"2024-06-01T17:51:55.402169Z"}]}
{"channel":"book","type":"update","data":[{"symbol":"ETH/GBP","bids":[],"asks":[{"price":2979.76,"qty":0.00000000},{"price":2980.82,"qty":1.00000000}],"checksum":2222208701,"timestamp":"2024-06-01T17:51:55.471123Z"}]}
{"channel":"book","type":"update","data":[{"symbol":"ETH/GBP","bids":[],"asks":[{"price":2980.75,"qty":0.00000000},{"price":2980.92,"qty":2.94416492}],"checksum":1521772901,"timestamp":"2024-06-01T17:51:55.471184Z"}]}
{"channel":"book","type":"update","data":[{"symbol":"ETH/GBP","bids":[],"asks":[{"price":2979.49,"qty":7.28900238}],"checksum":2921891275,"timestamp":"2024-06-01T17:51:55.475756Z"}]}
{"channel":"book","type":"update","data":[{"symbol":"ETH/GBP","bids":[],"asks":[{"price":2980.75,"qty":29.97857468}],"checksum":376097917,"timestamp":"2024-06-01T17:51:55.475827Z"}]}
{"channel":"book","type":"update","data":[{"symbol":"ETH/GBP","bids":[{"price":2978.35,"qty":6.58540352}],"asks":[],"checksum":439286413,"timestamp":"2024-06-01T17:51:55.509729Z"}]}
{"channel":"book","type":"update","data":[{"symbol":"ETH/GBP","bids":[],"asks":[{"price":2979.02,"qty":13.16787445}],"checksum":898572194,"timestamp":"2024-06-01T17:51:55.509761Z"}]}
{"channel":"book","type":"update","data":[{"symbol":"ETH/GBP","bids":[],"asks":[{"price":2978.58,"qty":0.00000000},{"price":2980.76,"qty":1.31601441}],"checksum":3552299719,"timestamp":"2024-06-01T17:51:55.584889Z"}]}
{"channel":"book","type":"update","data":[{"symbol":"ETH/GBP","bids":[],"asks":[{"price":2978.60,"qty":6.58487132}],"checksum":2472880537,"timestamp":"2024-06-01T17:51:55.589488Z"}]}
{"channel":"book","type":"update","data":[{"symbol":"ETH/GBP","bids":[],"asks":[{"price":2978.60,"qty":0.00000000},{"price":2980.76,"qty":1.31601441}],"checksum":3552299719,"timestamp":"2024-06-01T17:51:55.619283Z"}]}
{"channel":"book","type":"update","data":[{"symbol":"ETH/GBP","bids":[],"asks":[{"price":2979.67,"qty":0.00000000},{"price":2980.82,"qty":1.00000000},{"price":2979.16,"qty":0.06978500}],"checksum":870123031,"timestamp":"2024-06-01T17:51:55.684538Z"}]}
{"channel":"book","type":"update","data":[{"symbol":"ETH/GBP","bids":[{"price":2978.35,"qty":0.00000000},{"price":2974.50,"qty":0.27200000}],"asks":[],"checksum":1012911620,"timestamp":"2024-06-01T17:51:55.690234Z"}]}
{"channel":"book","type":"update","data":[{"symbol":"ETH/GBP","bids":[],"asks":[{"price":2978.60,"qty":6.58486671}],"checksum":1639961208,"timestamp":"2024-06-01T17:51:55.695022Z"}]}
{"channel":"book","type":"update","data":[{"symbol":"ETH/GBP","bids":[{"price":2978.36,"qty":6.58538113}],"asks":[],"checksum":1899994293,"timestamp":"2024-06-01T17:51:55.695048Z"}]}
{"channel":"book","type":"update","data":[{"symbol":"ETH/GBP","bids":[{"price":2978.36,"qty":0.00000000},{"price":2974.50,"qty":0.27200000}],"asks":[],"checksum":1639961208,"timestamp":"2024-06-01T17:51:55.707205Z"}]}
{"channel":"book","type":"update","data":[{"symbol":"ETH/GBP","bids":[{"price":2978.33,"qty":6.58545004}],"asks":[],"checksum":1765964185,"timestamp":"2024-06-01T17:51:55.901349Z"}]}
{"channel":"book","type":"update","data":[{"symbol":"ETH/GBP","bids":[{"price":2978.33,"qty":0.00000000},{"price":2974.50,"qty":0.27200000}],"asks":[],"checksum":1639961208,"timestamp":"2024-06-01T17:51:55.905727Z"}]}
{"channel":"book","type":"update","data":[{"symbol":"ETH/GBP","bids":[],"asks":[{"price":2978.60,"qty":0.00000000},{"price":2980.76,"qty":1.31601441}],"checksum":1012911620,"timestamp":"2024-06-01T17:51:55.908978Z"}]}
{"channel":"book","type":"update","data":[{"symbol":"ETH/GBP","bids":[],"asks":[{"price":2978.59,"qty":6.58488412}],"checksum":1842739245,"timestamp":"2024-06-01T17:51:55.913016Z"}]}
{"channel":"book","type":"update","data":[{"symbol":"ETH/GBP","bids":[],"asks":[{"price":2978.59,"qty":0.00000000},{"price":2980.76,"qty":1.31601441}],"checksum":1012911620,"timestamp":"2024-06-01T17:51:55.934041Z"}]}
{"channel":"book","type":"update","data":[{"symbol":"ETH/GBP","bids":[],"asks":[{"price":2979.02,"qty":0.00000000},{"price":2980.82,"qty":1.00000000}],"checksum":2746780694,"timestamp":"2024-06-01T17:51:55.959311Z"}]}
{"channel":"book","type":"update","data":[{"symbol":"ETH/GBP","bids":[{"price":2977.90,"qty":0.00000000},{"price":2973.19,"qty":0.14113766}],"asks":[],"checksum":1631031294,"timestamp":"2024-06-01T17:51:55.959334Z"}]}
{"channel":"book","type":"update","data":[{"symbol":"ETH/GBP","bids":[{"price":2977.99,"qty":13.17239230}],"asks":[],"checksum":2128961919,"timestamp":"2024-06-01T17:51:55.964237Z"}]}
{"channel":"book","type":"update","data":[{"symbol":"ETH/GBP","bids":[],"asks":[{"price":2979.10,"qty":13.16750796}],"checksum":2040170021,"timestamp":"2024-06-01T17:51:55.964330Z"}]}
{"channel":"book","type":"update","data":[{"symbol":"ETH/GBP","bids":[],"asks":[{"price":2979.10,"qty":0.00000000},{"price":2980.82,"qty":1.00000000}],"checksum":2128961919,"timestamp":"2024-06-01T17:51:55.973011Z"}]}
{"channel":"book","type":"update","data":[{"symbol":"ETH/GBP","bids":[],"asks":[{"price":2979.15,"qty":6.58363742}],"checksum":2436091418,"timestamp":"2024-06-01T17:51:56.040042Z"}]}
{"channel":"book","type":"update","data":[{"symbol":"ETH/GBP","bids":[{"price":2978.40,"qty":6.58528529}],"asks":[],"checksum":3031760109,"timestamp":"2024-06-01T17:51:56.040143Z"}]}
{"channel":"book","type":"update","data":[{"symbol":"ETH/GBP","bids":[],"asks":[{"price":2979.15,"qty":0.00000000},{"price":2980.82,"qty":1.00000000}],"checksum":2307112853,"timestamp":"2024-06-01T17:51:56.044720Z"}]}
{"channel":"book","type":"update","data":[{"symbol":"ETH/GBP","bids":[{"price":2978.40,"qty":0.00000000},{"price":2974.50,"qty":0.27200000}],"asks":[],"checksum":2128961919,"timestamp":"2024-06-01T17:51:56.150827Z"}]}
{"channel":"book","type":"update","data":[{"symbol":"ETH/GBP","bids":[],"asks":[{"price":2978.63,"qty":6.58479310}],"checksum":2347383648,"timestamp":"2024-06-01T17:51:56.150946Z"}]}
{"channel":"book","type":"update","data":[{"symbol":"ETH/GBP","bids":[],"asks":[{"price":2978.63,"qty":0.00000000},{"price":2980.82,"qty":1.00000000}],"checksum":2128961919,"timestamp":"2024-06-01T17:51:56.156118Z"}]}
{"channel":"book","type":"update","data":[{"symbol":"ETH/GBP","bids":[],"asks":[{"price":2979.16,"qty":0.00000000},{"price":2980.92,"qty":2.94416492},{"price":2979.48,"qty":0.06980600}],"checksum":1157481815,"timestamp":"2024-06-01T17:51:56.156425Z"}]}
{"channel":"book","type":"update","data":[{"symbol":"ETH/GBP","bids":[{"price":2978.41,"qty":6.58526761}],"asks":[],"checksum":3826449544,"timestamp":"2024-06-01T17:51:56.162146Z"}]}
{"channel":"book","type":"update","data":[{"symbol":"ETH/GBP","bids":[{"price":2978.41,"qty":0.00000000},{"price":2974.50,"qty":0.27200000}],"asks":[],"checksum":1157481815,"timestamp":"2024-06-01T17:51:56.166690Z"}]}
{"channel":"book","type":"update","data":[{"symbol":"ETH/GBP","bids":[],"asks":[{"price":2979.47,"qty":13.16586376}],"checksum":2374250956,"timestamp":"2024-06-01T17:51:56.171302Z"}]}
{"channel":"book","type":"update","data":[{"symbol":"ETH/GBP","bids":[],"asks":[{"price":2979.47,"qty":0.00000000},{"price":2980.82,"qty":1.00000000}],"checksum":1157481815,"timestamp":"2024-06-01T17:51:56.175760Z"}]}
{"channel":"book","type":"update","data":[{"symbol":"ETH/GBP","bids":[],"asks":[{"price":2978.65,"qty":6.58474964}],"checksum":1429893638,"timestamp":"2024-06-01T17:51:56.259581Z"}]}
{"channel":"book","type":"update","data":[{"symbol":"ETH/GBP","bids":[{"price":2978.41,"qty":6.58525180}],"asks":[],"checksum":310365739,"timestamp":"2024-06-01T17:51:56.264949Z"}]}
{"channel":"book","type":"update","data":[{"symbol":"ETH/GBP","bids":[],"asks":[{"price":2978.65,"qty":0.00000000},{"price":2980.82,"qty":1.00000000}],"checksum":235038974,"timestamp":"2024-06-01T17:51:56.272181Z"}]}
{"channel":"book","type":"update","data":[{"symbol":"ETH/GBP","bids":[{"price":2978.41,"qty":0.00000000},{"price":2974.50,"qty":0.27200000}],"asks":[],"checksum":1157481815,"timestamp":"2024-06-01T17:51:56.278718Z"}]}
{"channel":"book","type":"update","data":[{"symbol":"ETH/GBP","bids":[{"price":2977.99,"qty":0.00000000},{"price":2973.19,"qty":0.14113766}],"asks":[],"checksum":4082739348,"timestamp":"2024-06-01T17:51:56.280887Z"}]}
{"channel":"book","type":"update","data":[{"symbol":"ETH/GBP","bids":[],"asks":[{"price":2980.76,"qty":0.00000000},{"price":2980.92,"qty":2.94416492}],"checksum":3965699570,"timestamp":"2024-06-01T17:51:56.280918Z"}]}
{"channel":"book","type":"update","data":[{"symbol":"ETH/GBP","bids":[{"price":2977.18,"qty":0.00000000},{"price":2973.18,"qty":0.27800000}],"asks":[],"checksum":3371191693,"timestamp":"2024-06-01T17:51:56.285974Z"}]}
{"channel":"book","type":"update","data":[{"symbol":"ETH/GBP","bids":[],"asks":[{"price":2979.77,"qty":0.00000000},{"price":2980.93,"qty":0.27473522}],"checksum":1670521514,"timestamp":"2024-06-01T17:51:56.291174Z"}]}
{"channel":"book","type":"update","data":[{"symbol":"ETH/GBP","bids":[],"asks":[{"price":2979.55,"qty":1.31655249}],"checksum":325475319,"timestamp":"2024-06-01T17:51:56.295625Z"}]}
{"channel":"book","type":"update","data":[{"symbol":"ETH/GBP","bids":[{"price":2977.68,"qty":13.17376123}],"asks":[],"checksum":2145005249,"timestamp":"2024-06-01T17:51:56.295649Z"}]}
{"channel":"book","type":"update","data":[{"symbol":"ETH/GBP","bids":[],"asks":[{"price":2980.34,"qty":1.31620491}],"checksum":2596617042,"timestamp":"2024-06-01T17:51:56.295773Z"}]}
{"channel":"book","type":"update","data":[{"symbol":"ETH/GBP","bids":[{"price":2976.94,"qty":1.31770228}],"asks":[],"checksum":1142798699,"timestamp":"2024-06-01T17:51:56.295863Z"}]}
{"channel":"book","type":"update","data":[{"symbol":"ETH/GBP","bids":[],"asks":[{"price":2979.45,"qty":1.31715138}],"checksum":1449068638,"timestamp":"2024-06-01T17:51:56.300395Z"}]}
{"channel":"book","type":"update","data":[{"symbol":"ETH/GBP","bids":[],"asks":[{"price":2979.50,"qty":0.00000000},{"price":2980.82,"qty":1.00000000}],"checksum":1001900456,"timestamp":"2024-06-01T17:51:56.300450Z"}]}
{"channel":"book","type":"update","data":[{"symbol":"ETH/GBP","bids":[{"price":2978.11,"qty":6.58592439}],"asks":[],"checksum":1831136022,"timestamp":"2024-06-01T17:51:56.380227Z"}]}
{"channel":"book","type":"update","data":[{"symbol":"ETH/GBP","bids":[],"asks":[{"price":2978.34,"qty":6.58543643}],"checksum":3850244461,"timestamp":"2024-06-01T17:51:56.380245Z"}]}
{"channel":"book","type":"update","data":[{"symbol":"ETH/GBP","bids":[],"asks":[{"price":2979.44,"qty":13.16599898}],"checksum":2920335932,"timestamp":"2024-06-01T17:51:56.380371Z"}]}
{"channel":"book","type":"update","data":[{"symbol":"ETH/GBP","bids":[],"asks":[{"price":2979.44,"qty":0.00000000},{"price":2980.75,"qty":29.97857468}],"checksum":3850244461,"timestamp":"2024-06-01T17:51:56.385152Z"}]}
{"channel":"book","type":"update","data":[{"symbol":"ETH/GBP","bids":[{"price":2978.11,"qty":0.00000000},{"price":2974.50,"qty":0.27200000}],"asks":[],"checksum":1763136624,"timestamp":"2024-06-01T17:51:56.387126Z"}]}
{"channel":"book","type":"update","data":[{"symbol":"ETH/GBP","bids":[{"price":2978.32,"qty":0.00000000},{"price":2973.19,"qty":0.14113766},{"price":2978.00,"qty":0.08559800}],"asks":[],"checksum":1136347795,"timestamp":"2024-06-01T17:51:56.427995Z"}]}
{"channel":"book","type":"update","data":[{"symbol":"ETH/GBP","bids":[],"asks":[{"price":2978.34,"qty":0.00000000},{"price":2980.82,"qty":1.00000000}],"checksum":287037259,"timestamp":"2024-06-01T17:51:56.432684Z"}]}
{"channel":"book","type":"update","data":[{"symbol":"ETH/GBP","bids":[{"price":2978.01,"qty":6.58614773}],"asks":[],"checksum":1674151880,"timestamp":"2024-06-01T17:51:56.490065Z"}]}
{"channel":"book","type":"update","data":[{"symbol":"ETH/GBP","bids":[],"asks":[{"price":2978.33,"qty":6.58545794}],"checksum":1721005527,"timestamp":"2024-06-01T17:51:56.490114Z"}]}
{"channel":"book","type":"update","data":[{"symbol":"ETH/GBP","bids":[{"price":2978.01,"qty":0.00000000},{"price":2974.50,"qty":0.27200000}],"asks":[],"checksum":1287576460,"timestamp":"2024-06-01T17:51:56.495878Z"}]}
{"channel":"book","type":"update","data":[{"symbol":"ETH/GBP","bids":[{"price":2978.01,"qty":6.58615768}],"asks":[],"checksum":1245754804,"timestamp":"2024-06-01T17:51:56.595412Z"}]}
{"channel":"book","type":"update","data":[{"symbol":"ETH/GBP","bids":[],"asks":[{"price":2978.77,"qty":13.16898167}],"checksum":200067193,"timestamp":"2024-06-01T17:51:56.595496Z"}]}
{"channel":"book","type":"update","data":[{"symbol":"ETH/GBP","bids":[{"price":2978.01,"qty":0.00000000},{"price":2974.50,"qty":0.27200000}],"asks":[],"checksum":3837359655,"timestamp":"2024-06-01T17:51:56.600514Z"}]}
{"channel":"book","type":"update","data":[{"symbol":"ETH/GBP","bids":[],"asks":[{"price":2978.33,"qty":0.00000000},{"price":2980.75,"qty":29.97857468}],"checksum":1028042401,"timestamp":"2024-06-01T17:51:56.725723Z"}]}
{"channel":"book","type":"update","data":[{"symbol":"ETH/GBP","bids":[],"asks":[{"price":2978.32,"qty":6.58548660}],"checksum":508466235,"timestamp":"2024-06-01T17:51:56.730377Z"}]}
{"channel":"book","type":"update","data":[{"symbol":"ETH/GBP","bids":[{"price":2978.10,"qty":6.58595619}],"asks":[],"checksum":1398350855,"timestamp":"2024-06-01T17:51:56.730407Z"}]}
{"channel":"book","type":"update","data":[{"symbol":"ETH/GBP","bids":[],"asks":[{"price":2978.77,"qty":0.00000000},{"price":2980.75,"qty":29.97857468}],"checksum":318069194,"timestamp":"2024-06-01T17:51:56.730572Z"}]}
{"channel":"book","type":"update","data":[{"symbol":"ETH/GBP","bids":[],"asks":[{"price":2978.32,"qty":0.00000000},{"price":2980.82,"qty":1.00000000}],"checksum":55771256,"timestamp":"2024-06-01T17:51:56.779020Z"}]}
{"channel":"book","type":"update","data":[{"symbol":"ETH/GBP","bids":[{"price":2978.10,"qty":0.00000000},{"price":2974.50,"qty":0.27200000}],"asks":[],"checksum":287037259,"timestamp":"2024-06-01T17:51:56.779140Z"}]}
{"channel":"book","type":"update","data":[{"symbol":"ETH/GBP","bids":[],"asks":[{"price":2979.44,"qty":13.16601312}],"checksum":1920164677,"timestamp":"2024-06-01T17:51:56.798605Z"}]}
{"channel":"book","type":"update","data":[{"symbol":"ETH/GBP","bids":[],"asks":[{"price":2979.41,"qty":1.31719833}],"checksum":1403136602,"timestamp":"2024-06-01T17:51:56.801513Z"}]}
{"channel":"book","type":"update","data":[{"symbol":"ETH/GBP","bids":[],"asks":[{"price":2979.44,"qty":0.00000000},{"price":2980.75,"qty":29.97857468}],"checksum":2738470438,"timestamp":"2024-06-01T17:51:56.804242Z"}]}
{"channel":"book","type":"update","data":[{"symbol":"ETH/GBP","bids":[],"asks":[{"price":2979.45,"qty":0.00000000},{"price":2980.82,"qty":1.00000000}],"checksum":1449396764,"timestamp":"2024-06-01T17:51:56.804440Z"}]}
{"channel":"book","type":"update","data":[{"symbol":"ETH/GBP","bids":[],"asks":[{"price":2979.40,"qty":6.58309405}],"checksum":2088734324,"timestamp":"2024-06-01T17:51:56.841354Z"}]}
{"channel":"book","type":"update","data":[{"symbol":"ETH/GBP","bids":[{"price":2978.08,"qty":6.58598164}],"asks":[],"checksum":3379990522,"timestamp":"2024-06-01T17:51:56.841463Z"}]}
{"channel":"book","type":"update","data":[{"symbol":"ETH/GBP","bids":[],"asks":[{"price":2979.37,"qty":1.31719141}],"checksum":424947379,"timestamp":"2024-06-01T17:51:56.844504Z"}]}
{"channel":"book","type":"update","data":[{"symbol":"ETH/GBP","bids":[],"asks":[{"price":2979.40,"qty":0.00000000},{"price":2980.75,"qty":29.97857468}],"checksum":1057012552,"timestamp":"2024-06-01T17:51:56.847179Z"}]}
{"channel":"book","type":"update","data":[{"symbol":"ETH/GBP","bids":[],"asks":[{"price":2979.41,"qty":0.00000000},{"price":2980.82,"qty":1.00000000}],"checksum":153890407,"timestamp":"2024-06-01T17:51:56.847324Z"}]}
{"channel":"book","type":"update","data":[{"symbol":"ETH/GBP","bids":[{"price":2978.08,"qty":0.00000000},{"price":2974.50,"qty":0.27200000}],"asks":[],"checksum":2628959755,"timestamp":"2024-06-01T17:51:56.939237Z"}]}
{"channel":"book","type":"update","data":[{"symbol":"ETH/GBP","bids":[],"asks":[{"price":2978.33,"qty":6.58545749}],"checksum":4116557594,"timestamp":"2024-06-01T17:51:56.943975Z"}]}
{"channel":"book","type":"update","data":[{"symbol":"ETH/GBP","bids":[{"price":2978.10,"qty":6.58593686}],"asks":[],"checksum":91885659,"timestamp":"2024-06-01T17:51:56.944033Z"}]}
{"channel":"book","type":"update","data":[{"symbol":"ETH/GBP","bids":[],"asks":[{"price":2978.33,"qty":0.00000000},{"price":2980.82,"qty":1.00000000}],"checksum":1873010616,"timestamp":"2024-06-01T17:51:56.952490Z"}]}
{"channel":"book","type":"update","data":[{"symbol":"ETH/GBP","bids":[{"price":2978.10,"qty":0.00000000},{"price":2974.50,"qty":0.27200000}],"asks":[],"checksum":2628959755,"timestamp":"2024-06-01T17:51:56.952577Z"}]}
{"channel":"book","type":"update","data":[{"symbol":"ETH/GBP","bids":[],"asks":[{"price":2978.80,"qty":13.16886255}],"checksum":4291397075,"timestamp":"2024-06-01T17:51:57.004512Z"}]}
{"channel":"book","type":"update","data":[{"symbol":"ETH/GBP","bids":[],"asks":[{"price":2978.80,"qty":0.00000000},{"price":2980.82,"qty":1.00000000}],"checksum":2628959755,"timestamp":"2024-06-01T17:51:57.051826Z"}]}
{"channel":"book","type":"update","data":[{"symbol":"ETH/GBP","bids":[{"price":2978.13,"qty":6.58587773}],"asks":[],"checksum":1706972151,"timestamp":"2024-06-01T17:51:57.056773Z"}]}
{"channel":"book","type":"update","data":[{"symbol":"ETH/GBP","bids":[],"asks":[{"price":2978.36,"qty":6.58539837}],"checksum":1847000627,"timestamp":"2024-06-01T17:51:57.056799Z"}]}
{"channel":"book","type":"update","data":[{"symbol":"ETH/GBP","bids":[],"asks":[{"price":2978.36,"qty":0.00000000},{"price":2980.82,"qty":1.00000000}],"checksum":1706972151,"timestamp":"2024-06-01T17:51:57.081285Z"}]}
{"channel":"book","type":"update","data":[{"symbol":"ETH/GBP","bids":[{"price":2978.13,"qty":0.00000000},{"price":2974.50,"qty":0.27200000}],"asks":[],"checksum":2628959755,"timestamp":"2024-06-01T17:51:57.192705Z"}]}
{"channel":"book","type":"update","data":[{"symbol":"ETH/GBP","bids":[{"price":2978.10,"qty":6.58594557}],"asks":[],"checksum":785924636,"timestamp":"2024-06-01T17:51:57.197949Z"}]}
{"channel":"book","type":"update","data":[{"symbol":"ETH/GBP","bids":[],"asks":[{"price":2978.33,"qty":6.58546620}],"checksum":231212458,"timestamp":"2024-06-01T17:51:57.198030Z"}]}
{"channel":"book","type":"update","data":[{"symbol":"ETH/GBP","bids":[],"asks":[{"price":2978.33,"qty":0.00000000},{"price":2980.82,"qty":1.00000000}],"checksum":785924636,"timestamp":"2024-06-01T17:51:57.238345Z"}]}
{"channel":"book","type":"update","data":[{"symbol":"ETH/GBP","bids":[{"price":2978.10,"qty":0.00000000},{"price":2974.50,"qty":0.27200000}],"asks":[],"checksum":2628959755,"timestamp":"2024-06-01T17:51:57.238509Z"}]}
{"channel":"book","type":"update","data":[{"symbol":"ETH/GBP","bids":[],"asks":[{"price":2979.36,"qty":13.16636311}],"checksum":922866640,"timestamp":"2024-06-01T17:51:57.243148Z"}]}
{"channel":"book","type":"update","data":[{"symbol":"ETH/GBP","bids":[],"asks":[{"price":2979.33,"qty":1.31717731}],"checksum":115604637,"timestamp":"2024-06-01T17:51:57.246620Z"}]}
{"channel":"book","type":"update","data":[{"symbol":"ETH/GBP","bids":[],"asks":[{"price":2979.37,"qty":0.00000000},{"price":2980.75,"qty":29.97857468}],"checksum":3736777421,"timestamp":"2024-06-01T17:51:57.249651Z"}]}
{"channel":"book","type":"update","data":[{"symbol":"ETH/GBP","bids":[],"asks":[{"price":2979.36,"qty":0.00000000},{"price":2980.82,"qty":1.00000000}],"checksum":4057607659,"timestamp":"2024-06-01T17:51:57.250533Z"}]}
{"channel":"book","type":"update","data":[{"symbol":"ETH/GBP","bids":[],"asks":[{"price":2978.32,"qty":6.58548859}],"checksum":322372556,"timestamp":"2024-06-01T17:51:57.299743Z"}]}
{"channel":"book","type":"update","data":[{"symbol":"ETH/GBP","bids":[{"price":2978.09,"qty":6.58596072}],"asks":[],"checksum":1269226427,"timestamp":"2024-06-01T17:51:57.299805Z"}]}
{"channel":"book","type":"update","data":[{"symbol":"ETH/GBP","bids":[{"price":2978.09,"qty":0.00000000},{"price":2974.50,"qty":0.27200000}],"asks":[],"checksum":322372556,"timestamp":"2024-06-01T17:51:57.351427Z"}]}
{"channel":"book","type":"update","data":[{"symbol":"ETH/GBP","bids":[],"asks":[{"price":2978.32,"qty":0.00000000},{"price":2980.82,"qty":1.00000000}],"checksum":4057607659,"timestamp":"2024-06-01T17:51:57.375607Z"}]}
{"channel":"book","type":"update","data":[{"symbol":"ETH/GBP","bids":[],"asks":[{"price":2979.32,"qty":6.58326905}],"checksum":1139789160,"timestamp":"2024-06-01T17:51:57.452303Z"}]}
{"channel":"book","type":"update","data":[{"symbol":"ETH/GBP","bids":[{"price":2978.11,"qty":6.58592449}],"asks":[],"checksum":2277733084,"timestamp":"2024-06-01T17:51:57.452424Z"}]}
{"channel":"book","type":"update","data":[{"symbol":"ETH/GBP","bids":[],"asks":[{"price":2979.32,"qty":19.74980716}],"checksum":3742116448,"timestamp":"2024-06-01T17:51:57.452443Z"}]}
{"channel":"book","type":"update","data":[{"symbol":"ETH/GBP","bids":[],"asks":[{"price":2979.29,"qty":1.31717478}],"checksum":1382083526,"timestamp":"2024-06-01T17:51:57.455101Z"}]}
{"channel":"book","type":"update","data":[{"symbol":"ETH/GBP","bids":[],"asks":[{"price":2979.33,"qty":0.00000000},{"price":2980.75,"qty":29.97857468}],"checksum":2980984183,"timestamp":"2024-06-01T17:51:57.455164Z"}]}
{"channel":"book","type":"update","data":[{"symbol":"ETH/GBP","bids":[],"asks":[{"price":2979.32,"qty":13.16653811}],"checksum":2118612780,"timestamp":"2024-06-01T17:51:57.461153Z"}]}
{"channel":"book","type":"update","data":[{"symbol":"ETH/GBP","bids":[],"asks":[{"price":2979.32,"qty":0.00000000},{"price":2980.82,"qty":1.00000000}],"checksum":3168916145,"timestamp":"2024-06-01T17:51:57.461162Z"}]}
{"channel":"book","type":"update","data":[{"symbol":"ETH/GBP","bids":[{"price":2978.11,"qty":0.00000000},{"price":2974.50,"qty":0.27200000}],"asks":[],"checksum":258959432,"timestamp":"2024-06-01T17:51:57.483458Z"}]}
{"channel":"book","type":"update","data":[{"symbol":"ETH/GBP","bids":[],"asks":[{"price":2979.28,"qty":6.58335656}],"checksum":2216606430,"timestamp":"2024-06-01T17:51:57.585159Z"}]}
{"channel":"book","type":"update","data":[{"symbol":"ETH/GBP","bids":[{"price":2978.09,"qty":6.58598036}],"asks":[],"checksum":332578979,"timestamp":"2024-06-01T17:51:57.585253Z"}]}
{"channel":"book","type":"update","data":[{"symbol":"ETH/GBP","bids":[],"asks":[{"price":2979.26,"qty":1.31717758}],"checksum":535281125,"timestamp":"2024-06-01T17:51:57.588170Z"}]}
{"channel":"book","type":"update","data":[{"symbol":"ETH/GBP","bids":[],"asks":[{"price":2979.29,"qty":0.00000000},{"price":2980.75,"qty":29.97857468}],"checksum":2107841361,"timestamp":"2024-06-01T17:51:57.588253Z"}]}
{"channel":"book","type":"update","data":[{"symbol":"ETH/GBP","bids":[],"asks":[{"price":2979.28,"qty":0.00000000},{"price":2980.82,"qty":1.00000000}],"checksum":879815734,"timestamp":"2024-06-01T17:51:57.590524Z"}]}
{"channel":"book","type":"update","data":[{"symbol":"ETH/GBP","bids":[{"price":2978.09,"qty":0.00000000},{"price":2974.50,"qty":0.27200000}],"asks":[],"checksum":611550639,"timestamp":"2024-06-01T17:51:57.590638Z"}]}
{"channel":"book","type":"update","data":[{"symbol":"ETH/GBP","bids":[],"asks":[{"price":2978.78,"qty":13.16894863}],"checksum":3790133259,"timestamp":"2024-06-01T17:51:57.663455Z"}]}
{"channel":"book","type":"update","data":[{"symbol":"ETH/GBP","bids":[],"asks":[{"price":2978.78,"qty":0.00000000},{"price":2980.82,"qty":1.00000000}],"checksum":611550639,"timestamp":"2024-06-01T17:51:57.687394Z"}]}
{"channel":"book","type":"update","data":[{"symbol":"ETH/GBP","bids":[],"asks":[{"price":2979.25,"qty":6.58342219}],"checksum":3258755500,"timestamp":"2024-06-01T17:51:57.692125Z"}]}
{"channel":"book","type":"update","data":[{"symbol":"ETH/GBP","bids":[{"price":2978.10,"qty":6.58595645}],"asks":[],"checksum":1281496079,"timestamp":"2024-06-01T17:51:57.692272Z"}]}
{"channel":"book","type":"update","data":[{"symbol":"ETH/GBP","bids":[],"asks":[{"price":2979.25,"qty":0.00000000},{"price":2980.82,"qty":1.00000000}],"checksum":3582790297,"timestamp":"2024-06-01T17:51:57.699422Z"}]}
{"channel":"book","type":"update","data":[{"symbol":"ETH/GBP","bids":[],"asks":[{"price":2979.68,"qty":0.00000000},{"price":2980.92,"qty":2.94416492}],"checksum":2259827169,"timestamp":"2024-06-01T17:51:57.702023Z"}]}
{"channel":"book","type":"update","data":[{"symbol":"ETH/GBP","bids":[],"asks":[{"price":2979.18,"qty":0.31000000}],"checksum":3873137164,"timestamp":"2024-06-01T17:51:57.702198Z"}]}
{"channel":"book","type":"update","data":[{"symbol":"ETH/GBP","bids":[],"asks":[{"price":2979.49,"qty":0.00000000},{"price":2980.92,"qty":2.94416492}],"checksum":1778048786,"timestamp":"2024-06-01T17:51:57.800950Z"}]}
{"channel":"book","type":"update","data":[{"symbol":"ETH/GBP","bids":[],"asks":[{"price":2980.75,"qty":0.00000000},{"price":2980.93,"qty":0.27473522}],"checksum":3520650258,"timestamp":"2024-06-01T17:51:57.801132Z"}]}
{"channel":"book","type":"update","data":[{"symbol":"ETH/GBP","bids":[],"asks":[{"price":2979.28,"qty":7.28904645}],"checksum":2709084126,"timestamp":"2024-06-01T17:51:57.805637Z"}]}
{"channel":"book","type":"update","data":[{"symbol":"ETH/GBP","bids":[],"asks":[{"price":2980.81,"qty":27.91108561}],"checksum":1900929766,"timestamp":"2024-06-01T17:51:57.805686Z"}]}
{"channel":"book","type":"update","data":[{"symbol":"ETH/GBP","bids":[],"asks":[{"price":2979.17,"qty":1.31721754}],"checksum":888964100,"timestamp":"2024-06-01T17:51:57.936154Z"}]}
{"channel":"book","type":"update","data":[{"symbol":"ETH/GBP","bids":[],"asks":[{"price":2979.26,"qty":0.00000000},{"price":2980.82,"qty":1.00000000}],"checksum":3366326940,"timestamp":"2024-06-01T17:51:57.938742Z"}]}
{"channel":"book","type":"update","data":[{"symbol":"ETH/GBP","bids":[],"asks":[{"price":2978.32,"qty":6.58548508}],"checksum":1300511377,"timestamp":"2024-06-01T17:51:57.940920Z"}]}
{"channel":"book","type":"update","data":[{"symbol":"ETH/GBP","bids":[],"asks":[{"price":2979.16,"qty":13.16723375}],"checksum":1638742225,"timestamp":"2024-06-01T17:51:57.940940Z"}]}
{"channel":"book","type":"update","data":[{"symbol":"ETH/GBP","bids":[],"asks":[{"price":2979.16,"qty":0.00000000},{"price":2980.81,"qty":27.91108561}],"checksum":1300511377,"timestamp":"2024-06-01T17:51:57.945643Z"}]}
{"channel":"book","type":"update","data":[{"symbol":"ETH/GBP","bids":[],"asks":[{"price":2978.32,"qty":0.00000000},{"price":2980.82,"qty":1.00000000}],"checksum":3366326940,"timestamp":"2024-06-01T17:51:57.950766Z"}]}
{"channel":"book","type":"update","data":[{"symbol":"ETH/GBP","bids":[],"asks":[{"price":2979.48,"qty":0.00000000},{"price":2980.92,"qty":2.94416492},{"price":2979.17,"qty":1.38697154}],"checksum":1074460886,"timestamp":"2024-06-01T17:51:57.978338Z"}]}
{"channel":"book","type":"update","data":[{"symbol":"ETH/GBP","bids":[{"price":2978.10,"qty":0.00000000},{"price":2974.50,"qty":0.27200000}],"asks":[],"checksum":483084391,"timestamp":"2024-06-01T17:51:57.980089Z"}]}
{"channel":"book","type":"update","data":[{"symbol":"ETH/GBP","bids":[{"price":2978.08,"qty":6.58598926}],"asks":[],"checksum":635192580,"timestamp":"2024-06-01T17:51:57.984592Z"}]}
{"channel":"book","type":"update","data":[{"symbol":"ETH/GBP","bids":[],"asks":[{"price":2979.16,"qty":6.58361731}],"checksum":2535426858,"timestamp":"2024-06-01T17:51:58.061837Z"}]}
{"channel":"book","type":"update","data":[{"symbol":"ETH/GBP","bids":[],"asks":[{"price":2979.16,"qty":0.00000000},{"price":2980.92,"qty":2.94416492}],"checksum":635192580,"timestamp":"2024-06-01T17:51:58.066400Z"}]}
{"channel":"book","type":"update","data":[{"symbol":"ETH/GBP","bids":[],"asks":[{"price":2979.15,"qty":13.16727839}],"checksum":409615408,"timestamp":"2024-06-01T17:51:58.316796Z"}]}
{"channel":"book","type":"update","data":[{"symbol":"ETH/GBP","bids":[],"asks":[{"price":2979.16,"qty":6.58361731}],"checksum":3580480415,"timestamp":"2024-06-01T17:51:58.316893Z"}]}
{"channel":"book","type":"update","data":[{"symbol":"ETH/GBP","bids":[],"asks":[{"price":2979.15,"qty":0.00000000},{"price":2980.82,"qty":1.00000000}],"checksum":2535426858,"timestamp":"2024-06-01T17:51:58.321839Z"}]}
{"channel":"book","type":"update","data":[{"symbol":"ETH/GBP","bids":[],"asks":[{"price":2979.16,"qty":0.00000000},{"price":2980.92,"qty":2.94416492}],"checksum":635192580,"timestamp":"2024-06-01T17:51:58.322042Z"}]}
{"channel":"book","type":"update","data":[{"symbol":"ETH/GBP","bids":[{"price":2978.08,"qty":0.00000000},{"price":2974.50,"qty":0.27200000}],"asks":[],"checksum":483084391,"timestamp":"2024-06-01T17:51:58.388182Z"}]}
{"channel":"book","type":"update","data":[{"symbol":"ETH/GBP","bids":[{"price":2978.06,"qty":6.58603120}],"asks":[],"checksum":6558925,"timestamp":"2024-06-01T17:51:58.392316Z"}]}
{"channel":"book","type":"update","data":[{"symbol":"ETH/GBP","bids":[{"price":2978.06,"qty":0.00000000},{"price":2974.50,"qty":0.27200000}],"asks":[],"checksum":483084391,"timestamp":"2024-06-01T17:51:58.434530Z"}]}
{"channel":"book","type":"update","data":[{"symbol":"ETH/GBP","bids":[],"asks":[{"price":2978.29,"qty":6.58554098}],"checksum":1542282056,"timestamp":"2024-06-01T17:51:58.439323Z"}]}
{"channel":"book","type":"update","data":[{"symbol":"ETH/GBP","bids":[{"price":2978.01,"qty":6.58615768}],"asks":[],"checksum":3596542109,"timestamp":"2024-06-01T17:51:58.589076Z"}]}
{"channel":"book","type":"update","data":[{"symbol":"ETH/GBP","bids":[],"asks":[{"price":2978.73,"qty":13.16915263}],"checksum":3851035087,"timestamp":"2024-06-01T17:51:58.589191Z"}]}
{"channel":"book","type":"update","data":[{"symbol":"ETH/GBP","bids":[{"price":2978.01,"qty":0.00000000},{"price":2974.50,"qty":0.27200000}],"asks":[],"checksum":2352081957,"timestamp":"2024-06-01T17:51:58.594288Z"}]}
{"channel":"book","type":"update","data":[{"symbol":"ETH/GBP","bids":[{"price":2978.01,"qty":6.58615768}],"asks":[],"checksum":3851035087,"timestamp":"2024-06-01T17:51:58.739454Z"}]}
{"channel":"book","type":"update","data":[{"symbol":"ETH/GBP","bids":[{"price":2978.01,"qty":0.00000000},{"price":2974.50,"qty":0.27200000}],"asks":[],"checksum":2352081957,"timestamp":"2024-06-01T17:51:58.744171Z"}]}
{"channel":"book","type":"update","data":[{"symbol":"ETH/GBP","bids":[],"asks":[{"price":2979.86,"qty":0.00000000},{"price":2980.82,"qty":1.00000000}],"checksum":2069088056,"timestamp":"2024-06-01T17:51:58.785181Z"}]}
{"channel":"book","type":"update","data":[{"symbol":"ETH/GBP","bids":[],"asks":[{"price":2980.80,"qty":0.20717085}],"checksum":3641482143,"timestamp":"2024-06-01T17:51:58.785369Z"}]}
{"channel":"book","type":"update","data":[{"symbol":"ETH/GBP","bids":[],"asks":[{"price":2978.29,"qty":0.00000000},{"price":2980.82,"qty":1.00000000}],"checksum":2167227409,"timestamp":"2024-06-01T17:51:59.118708Z"}]}
{"channel":"book","type":"update","data":[{"symbol":"ETH/GBP","bids":[],"asks":[{"price":2978.31,"qty":6.58551028}],"checksum":3822931185,"timestamp":"2024-06-01T17:51:59.123243Z"}]}
{"channel":"book","type":"update","data":[{"symbol":"ETH/GBP","bids":[{"price":2978.08,"qty":6.58598690}],"asks":[],"checksum":3686665134,"timestamp":"2024-06-01T17:51:59.123406Z"}]}
{"channel":"book","type":"update","data":[{"symbol":"ETH/GBP","bids":[{"price":2978.08,"qty":0.00000000},{"price":2974.50,"qty":0.27200000}],"asks":[],"checksum":3822931185,"timestamp":"2024-06-01T17:51:59.136089Z"}]}
{"channel":"book","type":"update","data":[{"symbol":"ETH/GBP","bids":[],"asks":[{"price":2978.31,"qty":0.00000000},{"price":2980.82,"qty":1.00000000}],"checksum":2167227409,"timestamp":"2024-06-01T17:51:59.197004Z"}]}
{"channel":"book","type":"update","data":[{"symbol":"ETH/GBP","bids":[{"price":2978.10,"qty":6.58595199}],"asks":[],"checksum":4161499987,"timestamp":"2024-06-01T17:51:59.230869Z"}]}
{"channel":"book","type":"update","data":[{"symbol":"ETH/GBP","bids":[],"asks":[{"price":2978.32,"qty":6.58547999}],"checksum":1326206209,"timestamp":"2024-06-01T17:51:59.230915Z"}]}
{"channel":"book","type":"update","data":[{"symbol":"ETH/GBP","bids":[],"asks":[{"price":2979.17,"qty":1.31721754},{"price":2978.85,"qty":0.06980000}],"checksum":3600991191,"timestamp":"2024-06-01T17:51:59.272688Z"}]}
{"channel":"book","type":"update","data":[{"symbol":"ETH/GBP","bids":[],"asks":[{"price":2978.32,"qty":0.00000000},{"price":2980.81,"qty":27.91108561}],"checksum":598094367,"timestamp":"2024-06-01T17:51:59.296274Z"}]}
{"channel":"book","type":"update","data":[{"symbol":"ETH/GBP","bids":[{"price":2978.10,"qty":0.00000000},{"price":2974.50,"qty":0.27200000}],"asks":[],"checksum":2544229947,"timestamp":"2024-06-01T17:51:59.296306Z"}]}
{"channel":"book","type":"update","data":[{"symbol":"ETH/GBP","bids":[],"asks":[{"price":2978.31,"qty":6.58550502}],"checksum":3962026161,"timestamp":"2024-06-01T17:51:59.337219Z"}]}
{"channel":"book","type":"update","data":[{"symbol":"ETH/GBP","bids":[{"price":2978.01,"qty":6.58615768}],"asks":[],"checksum":310927558,"timestamp":"2024-06-01T17:51:59.337334Z"}]}
{"channel":"book","type":"update","data":[{"symbol":"ETH/GBP","bids":[{"price":2978.01,"qty":0.00000000},{"price":2974.50,"qty":0.27200000}],"asks":[],"checksum":3962026161,"timestamp":"2024-06-01T17:51:59.342355Z"}]}
{"channel":"book","type":"update","data":[{"symbol":"ETH/GBP","bids":[],"asks":[{"price":2978.31,"qty":0.00000000},{"price":2980.81,"qty":27.91108561}],"checksum":2544229947,"timestamp":"2024-06-01T17:51:59.454055Z"}]}
{"channel":"book","type":"update","data":[{"symbol":"ETH/GBP","bids":[],"asks":[{"price":2978.33,"qty":6.58545476}],"checksum":1357668215,"timestamp":"2024-06-01T17:51:59.458551Z"}]}
{"channel":"book","type":"update","data":[{"symbol":"ETH/GBP","bids":[{"price":2978.10,"qty":6.58595694}],"asks":[],"checksum":4179896635,"timestamp":"2024-06-01T17:51:59.458597Z"}]}
{"channel":"book","type":"update","data":[{"symbol":"ETH/GBP","bids":[{"price":2978.10,"qty":0.00000000},{"price":2974.50,"qty":0.27200000}],"asks":[],"checksum":1357668215,"timestamp":"2024-06-01T17:51:59.486455Z"}]}
{"channel":"book","type":"update","data":[{"symbol":"ETH/GBP","bids":[{"price":2978.01,"qty":6.58615768}],"asks":[],"checksum":1614007460,"timestamp":"2024-06-01T17:51:59.640448Z"}]}
{"channel":"book","type":"update","data":[{"symbol":"ETH/GBP","bids":[{"price":2978.01,"qty":0.00000000},{"price":2974.50,"qty":0.27200000}],"asks":[],"checksum":1357668215,"timestamp":"2024-06-01T17:51:59.644922Z"}]}
{"channel":"book","type":"update","data":[{"symbol":"ETH/GBP","bids":[],"asks":[{"price":2978.33,"qty":0.00000000},{"price":2980.81,"qty":27.91108561}],"checksum":2544229947,"timestamp":"2024-06-01T17:51:59.962772Z"}]}
{"channel":"book","type":"update","data":[{"symbol":"ETH/GBP","bids":[],"asks":[{"price":2978.32,"qty":6.58547772}],"checksum":720683810,"timestamp":"2024-06-01T17:51:59.966737Z"}]}
{"channel":"book","type":"update","data":[{"symbol":"ETH/GBP","bids":[{"price":2978.10,"qty":6.58594310}],"asks":[],"checksum":49098922,"timestamp":"2024-06-01T17:51:59.966826Z"}]}
{"channel":"book","type":"update","data":[{"symbol":"ETH/GBP","bids":[],"asks":[{"price":2978.32,"qty":0.00000000},{"price":2980.81,"qty":27.91108561}],"checksum":1715194231,"timestamp":"2024-06-01T17:52:00.007967Z"}]}
{"channel":"book","type":"update","data":[{"symbol":"ETH/GBP","bids":[],"asks":[{"price":2980.79,"qty":2.94416492}],"checksum":3541526573,"timestamp":"2024-06-01T17:52:00.078804Z"}]}
{"channel":"book","type":"update","data":[{"symbol":"ETH/GBP","bids":[{"price":2978.10,"qty":0.00000000},{"price":2974.50,"qty":0.27200000}],"asks":[],"checksum":1808512390,"timestamp":"2024-06-01T17:52:00.138610Z"}]}
{"channel":"book","type":"update","data":[{"symbol":"ETH/GBP","bids":[{"price":2978.08,"qty":6.58598554}],"asks":[],"checksum":2698307506,"timestamp":"2024-06-01T17:52:00.143211Z"}]}
{"channel":"book","type":"update","data":[{"symbol":"ETH/GBP","bids":[],"asks":[{"price":2978.31,"qty":6.58550143}],"checksum":527172596,"timestamp":"2024-06-01T17:52:00.143246Z"}]}
{"channel":"book","type":"update","data":[{"symbol":"ETH/GBP","bids":[{"price":2978.08,"qty":0.00000000},{"price":2974.50,"qty":0.27200000}],"asks":[],"checksum":55502261,"timestamp":"2024-06-01T17:52:00.183290Z"}]}
{"channel":"book","type":"update","data":[{"symbol":"ETH/GBP","bids":[],"asks":[{"price":2979.28,"qty":0.00000000},{"price":2980.80,"qty":0.20717085}],"checksum":1140660455,"timestamp":"2024-06-01T17:52:00.213239Z"}]}
{"channel":"book","type":"update","data":[{"symbol":"ETH/GBP","bids":[],"asks":[{"price":2979.86,"qty":15.09166298}],"checksum":146559836,"timestamp":"2024-06-01T17:52:00.218256Z"}]}
{"channel":"book","type":"update","data":[{"symbol":"ETH/GBP","bids":[],"asks":[{"price":2978.31,"qty":0.00000000},{"price":2980.80,"qty":0.20717085}],"checksum":1762154848,"timestamp":"2024-06-01T17:52:00.274535Z"}]}
{"channel":"book","type":"update","data":[{"symbol":"ETH/GBP","bids":[{"price":2978.08,"qty":6.58599213}],"asks":[],"checksum":136330948,"timestamp":"2024-06-01T17:52:00.279028Z"}]}
{"channel":"book","type":"update","data":[{"symbol":"ETH/GBP","bids":[],"asks":[{"price":2978.30,"qty":6.58551902}],"checksum":525416807,"timestamp":"2024-06-01T17:52:00.279173Z"}]}
{"channel":"book","type":"update","data":[{"symbol":"ETH/GBP","bids":[{"price":2978.08,"qty":0.00000000},{"price":2974.50,"qty":0.27200000}],"asks":[],"checksum":2947660286,"timestamp":"2024-06-01T17:52:00.301513Z"}]}
{"channel":"book","type":"update","data":[{"symbol":"ETH/GBP","bids":[],"asks":[{"price":2978.30,"qty":0.00000000},{"price":2980.80,"qty":0.20717085}],"checksum":1762154848,"timestamp":"2024-06-01T17:52:00.301525Z"}]}
{"channel":"book","type":"update","data":[{"symbol":"ETH/GBP","bids":[],"asks":[{"price":2978.72,"qty":6.58458782}],"checksum":3785432224,"timestamp":"2024-06-01T17:52:00.387465Z"}]}
{"channel":"book","type":"update","data":[{"symbol":"ETH/GBP","bids":[{"price":2978.12,"qty":6.58590880}],"asks":[],"checksum":736195967,"timestamp":"2024-06-01T17:52:00.387648Z"}]}
{"channel":"book","type":"update","data":[{"symbol":"ETH/GBP","bids":[],"asks":[{"price":2978.72,"qty":0.00000000},{"price":2980.80,"qty":0.20717085}],"checksum":2953649802,"timestamp":"2024-06-01T17:52:00.392479Z"}]}
{"channel":"book","type":"update","data":[{"symbol":"ETH/GBP","bids":[{"price":2978.12,"qty":0.00000000},{"price":2974.50,"qty":0.27200000}],"asks":[],"checksum":1762154848,"timestamp":"2024-06-01T17:52:00.440630Z"}]}
{"channel":"book","type":"update","data":[{"symbol":"ETH/GBP","bids":[],"asks":[{"price":2978.73,"qty":0.00000000},{"price":2980.82,"qty":1.00000000}],"checksum":3118840788,"timestamp":"2024-06-01T17:52:00.440645Z"}]}
{"channel":"book","type":"update","data":[{"symbol":"ETH/GBP","bids":[{"price":2977.68,"qty":0.00000000},{"price":2973.19,"qty":0.14113766}],"asks":[],"checksum":2815759200,"timestamp":"2024-06-01T17:52:00.448800Z"}]}
{"channel":"book","type":"update","data":[{"symbol":"ETH/GBP","bids":[],"asks":[{"price":2978.86,"qty":13.16856791}],"checksum":1899725113,"timestamp":"2024-06-01T17:52:00.453195Z"}]}
{"channel":"book","type":"update","data":[{"symbol":"ETH/GBP","bids":[{"price":2977.73,"qty":13.17352224}],"asks":[],"checksum":3160095846,"timestamp":"2024-06-01T17:52:00.453209Z"}]}
{"channel":"book","type":"update","data":[{"symbol":"ETH/GBP","bids":[],"asks":[{"price":2978.42,"qty":6.58526250}],"checksum":1473096033,"timestamp":"2024-06-01T17:52:00.490223Z"}]}
{"channel":"book","type":"update","data":[{"symbol":"ETH/GBP","bids":[{"price":2978.19,"qty":6.58574046}],"asks":[],"checksum":396699568,"timestamp":"2024-06-01T17:52:00.490377Z"}]}
{"channel":"book","type":"update","data":[{"symbol":"ETH/GBP","bids":[],"asks":[{"price":2978.42,"qty":0.00000000},{"price":2980.80,"qty":0.20717085}],"checksum":2301240454,"timestamp":"2024-06-01T17:52:00.512210Z"}]}
{"channel":"book","type":"update","data":[{"symbol":"ETH/GBP","bids":[],"asks":[{"price":2978.86,"qty":0.00000000},{"price":2980.82,"qty":1.00000000}],"checksum":4001502856,"timestamp":"2024-06-01T17:52:00.536766Z"}]}
{"channel":"book","type":"update","data":[{"symbol":"ETH/GBP","bids":[{"price":2978.19,"qty":0.00000000},{"price":2974.50,"qty":0.27200000}],"asks":[],"checksum":3374579453,"timestamp":"2024-06-01T17:52:00.588909Z"}]}
{"channel":"book","type":"update","data":[{"symbol":"ETH/GBP","bids":[],"asks":[{"price":2978.40,"qty":6.58530004}],"checksum":3797022788,"timestamp":"2024-06-01T17:52:00.594456Z"}]}
{"channel":"book","type":"update","data":[{"symbol":"ETH/GBP","bids":[{"price":2978.17,"qty":6.58578656}],"asks":[],"checksum":2051369347,"timestamp":"2024-06-01T17:52:00.594596Z"}]}
{"channel":"book","type":"update","data":[{"symbol":"ETH/GBP","bids":[{"price":2978.17,"qty":0.00000000},{"price":2974.50,"qty":0.27200000}],"asks":[],"checksum":3797022788,"timestamp":"2024-06-01T17:52:00.610128Z"}]}
{"channel":"book","type":"update","data":[{"symbol":"ETH/GBP","bids":[],"asks":[{"price":2978.85,"qty":0.00000000},{"price":2980.82,"qty":1.00000000},{"price":2979.16,"qty":0.06973700}],"checksum":1668790438,"timestamp":"2024-06-01T17:52:00.623924Z"}]}
{"channel":"book","type":"update","data":[{"symbol":"ETH/GBP","bids":[],"asks":[{"price":2978.84,"qty":13.16864513}],"checksum":1959741683,"timestamp":"2024-06-01T17:52:00.661430Z"}]}
{"channel":"book","type":"update","data":[{"symbol":"ETH/GBP","bids":[],"asks":[{"price":2978.40,"qty":0.00000000},{"price":2980.80,"qty":0.20717085}],"checksum":3289246626,"timestamp":"2024-06-01T17:52:00.669749Z"}]}
{"channel":"book","type":"update","data":[{"symbol":"ETH/GBP","bids":[],"asks":[{"price":2978.84,"qty":0.00000000},{"price":2980.82,"qty":1.00000000}],"checksum":3294411362,"timestamp":"2024-06-01T17:52:00.673936Z"}]}
{"channel":"book","type":"update","data":[{"symbol":"ETH/GBP","bids":[],"asks":[{"price":2978.39,"qty":6.58532770}],"checksum":2237407336,"timestamp":"2024-06-01T17:52:00.703238Z"}]}
{"channel":"book","type":"update","data":[{"symbol":"ETH/GBP","bids":[{"price":2978.16,"qty":6.58580566}],"asks":[],"checksum":2238374288,"timestamp":"2024-06-01T17:52:00.703278Z"}]}
{"channel":"book","type":"update","data":[{"symbol":"ETH/GBP","bids":[],"asks":[{"price":2978.39,"qty":0.00000000},{"price":2980.82,"qty":1.00000000}],"checksum":1711147028,"timestamp":"2024-06-01T17:52:00.720426Z"}]}
{"channel":"book","type":"update","data":[{"symbol":"ETH/GBP","bids":[],"asks":[{"price":2978.38,"qty":6.58534811}],"checksum":3586331543,"timestamp":"2024-06-01T17:52:00.843359Z"}]}
{"channel":"book","type":"update","data":[{"symbol":"ETH/GBP","bids":[{"price":2978.16,"qty":0.00000000},{"price":2974.50,"qty":0.27200000}],"asks":[],"checksum":702487320,"timestamp":"2024-06-01T17:52:00.988624Z"}]}
{"channel":"book","type":"update","data":[{"symbol":"ETH/GBP","bids":[],"asks":[{"price":2978.82,"qty":13.16877467}],"checksum":1855914776,"timestamp":"2024-06-01T17:52:00.993159Z"}]}
{"channel":"book","type":"update","data":[{"symbol":"ETH/GBP","bids":[{"price":2978.17,"qty":6.58579959}],"asks":[],"checksum":66621775,"timestamp":"2024-06-01T17:52:00.993374Z"}]}
{"channel":"book","type":"update","data":[{"symbol":"ETH/GBP","bids":[{"price":2978.17,"qty":0.00000000},{"price":2974.50,"qty":0.27200000}],"asks":[],"checksum":1855914776,"timestamp":"2024-06-01T17:52:01.028815Z"}]}
{"channel":"book","type":"update","data":[{"symbol":"ETH/GBP","bids":[],"asks":[{"price":2978.38,"qty":0.00000000},{"price":2980.80,"qty":0.20717085}],"checksum":238673070,"timestamp":"2024-06-01T17:52:01.030199Z"}]}
{"channel":"book","type":"update","data":[{"symbol":"ETH/GBP","bids":[],"asks":[{"price":2978.37,"qty":6.58537248}],"checksum":2805526003,"timestamp":"2024-06-01T17:52:01.034971Z"}]}
{"channel":"book","type":"update","data":[{"symbol":"ETH/GBP","bids":[],"asks":[{"price":2978.82,"qty":0.00000000},{"price":2980.80,"qty":0.20717085}],"checksum":915353911,"timestamp":"2024-06-01T17:52:01.035093Z"}]}
{"channel":"book","type":"update","data":[{"symbol":"ETH/GBP","bids":[],"asks":[{"price":2978.37,"qty":0.00000000},{"price":2980.82,"qty":1.00000000}],"checksum":3294411362,"timestamp":"2024-06-01T17:52:01.175792Z"}]}
{"channel":"book","type":"update","data":[{"symbol":"ETH/GBP","bids":[{"price":2978.12,"qty":6.58591080}],"asks":[],"checksum":2089474910,"timestamp":"2024-06-01T17:52:01.181492Z"}]}
{"channel":"book","type":"update","data":[{"symbol":"ETH/GBP","bids":[],"asks":[{"price":2979.15,"qty":6.58364096}],"checksum":2651658928,"timestamp":"2024-06-01T17:52:01.181554Z"}]}
{"channel":"book","type":"update","data":[{"symbol":"ETH/GBP","bids":[],"asks":[{"price":2979.15,"qty":0.00000000},{"price":2980.82,"qty":1.00000000}],"checksum":2089474910,"timestamp":"2024-06-01T17:52:01.185914Z"}]}
{"channel":"book","type":"update","data":[{"symbol":"ETH/GBP","bids":[],"asks":[{"price":2979.15,"qty":13.16727662}],"checksum":1492955017,"timestamp":"2024-06-01T17:52:01.197399Z"}]}
{"channel":"book","type":"update","data":[{"symbol":"ETH/GBP","bids":[],"asks":[{"price":2979.15,"qty":0.00000000},{"price":2980.82,"qty":1.00000000}],"checksum":2089474910,"timestamp":"2024-06-01T17:52:01.201986Z"}]}
{"channel":"book","type":"update","data":[{"symbol":"ETH/GBP","bids":[{"price":2978.12,"qty":0.00000000},{"price":2974.50,"qty":0.27200000}],"asks":[],"checksum":3294411362,"timestamp":"2024-06-01T17:52:01.271235Z"}]}
{"channel":"book","type":"update","data":[{"symbol":"ETH/GBP","bids":[{"price":2978.13,"qty":6.58588248}],"asks":[],"checksum":2888632666,"timestamp":"2024-06-01T17:52:01.308355Z"}]}
{"channel":"book","type":"update","data":[{"symbol":"ETH/GBP","bids":[],"asks":[{"price":2978.35,"qty":6.58540952}],"checksum":1793402063,"timestamp":"2024-06-01T17:52:01.308775Z"}]}
{"channel":"book","type":"update","data":[{"symbol":"ETH/GBP","bids":[],"asks":[{"price":2978.35,"qty":0.00000000},{"price":2980.82,"qty":1.00000000}],"checksum":2888632666,"timestamp":"2024-06-01T17:52:01.322063Z"}]}
{"channel":"book","type":"update","data":[{"symbol":"ETH/GBP","bids":[],"asks":[{"price":2979.15,"qty":13.16727618}],"checksum":2753909624,"timestamp":"2024-06-01T17:52:01.398267Z"}]}
{"channel":"book","type":"update","data":[{"symbol":"ETH/GBP","bids":[],"asks":[{"price":2979.15,"qty":0.00000000},{"price":2980.82,"qty":1.00000000}],"checksum":2888632666,"timestamp":"2024-06-01T17:52:01.402721Z"}]}
{"channel":"book","type":"update","data":[{"symbol":"ETH/GBP","bids":[],"asks":[{"price":2978.34,"qty":6.58543323}],"checksum":431423049,"timestamp":"2024-06-01T17:52:01.442380Z"}]}
{"channel":"book","type":"update","data":[{"symbol":"ETH/GBP","bids":[{"price":2978.13,"qty":0.00000000},{"price":2974.50,"qty":0.27200000}],"asks":[],"checksum":2405734623,"timestamp":"2024-06-01T17:52:01.473396Z"}]}
{"channel":"book","type":"update","data":[{"symbol":"ETH/GBP","bids":[],"asks":[{"price":2978.34,"qty":0.00000000},{"price":2980.82,"qty":1.00000000}],"checksum":3294411362,"timestamp":"2024-06-01T17:52:01.473485Z"}]}
{"channel":"book","type":"update","data":[{"symbol":"ETH/GBP","bids":[{"price":2978.14,"qty":6.58586009}],"asks":[],"checksum":210291802,"timestamp":"2024-06-01T17:52:01.478836Z"}]}
{"channel":"book","type":"update","data":[{"symbol":"ETH/GBP","bids":[],"asks":[{"price":2978.37,"qty":6.58538054}],"checksum":556062267,"timestamp":"2024-06-01T17:52:01.547446Z"}]}
{"channel":"book","type":"update","data":[{"symbol":"ETH/GBP","bids":[],"asks":[{"price":2978.37,"qty":0.00000000},{"price":2980.82,"qty":1.00000000}],"checksum":210291802,"timestamp":"2024-06-01T17:52:01.713397Z"}]}
{"channel":"book","type":"update","data":[{"symbol":"ETH/GBP","bids":[],"asks":[{"price":2978.36,"qty":6.58538778}],"checksum":3186416374,"timestamp":"2024-06-01T17:52:01.718104Z"}]}
{"channel":"book","type":"update","data":[{"symbol":"ETH/GBP","bids":[],"asks":[{"price":2979.15,"qty":13.16727574}],"checksum":906747985,"timestamp":"2024-06-01T17:52:01.718229Z"}]}
{"channel":"book","type":"update","data":[{"symbol":"ETH/GBP","bids":[],"asks":[{"price":2979.15,"qty":0.00000000},{"price":2980.80,"qty":0.20717085}],"checksum":3186416374,"timestamp":"2024-06-01T17:52:01.722864Z"}]}
{"channel":"book","type":"update","data":[{"symbol":"ETH/GBP","bids":[{"price":2978.14,"qty":0.00000000},{"price":2974.50,"qty":0.27200000}],"asks":[],"checksum":2879599193,"timestamp":"2024-06-01T17:52:01.820040Z"}]}
{"channel":"book","type":"update","data":[{"symbol":"ETH/GBP","bids":[],"asks":[{"price":2978.36,"qty":0.00000000},{"price":2980.82,"qty":1.00000000}],"checksum":3294411362,"timestamp":"2024-06-01T17:52:01.820094Z"}]}
{"channel":"book","type":"update","data":[{"symbol":"ETH/GBP","bids":[{"price":2977.73,"qty":0.00000000},{"price":2973.19,"qty":0.14113766}],"asks":[],"checksum":1050528057,"timestamp":"2024-06-01T17:52:01.826413Z"}]}
{"channel":"book","type":"update","data":[{"symbol":"ETH/GBP","bids":[],"asks":[{"price":2978.34,"qty":6.58543059}],"checksum":217180439,"timestamp":"2024-06-01T17:52:01.826425Z"}]}
{"channel":"book","type":"update","data":[{"symbol":"ETH/GBP","bids":[{"price":2978.01,"qty":6.58615414}],"asks":[],"checksum":839105777,"timestamp":"2024-06-01T17:52:01.826438Z"}]}
{"channel":"book","type":"update","data":[{"symbol":"ETH/GBP","bids":[],"asks":[{"price":2978.34,"qty":0.00000000},{"price":2980.82,"qty":1.00000000}],"checksum":4008172830,"timestamp":"2024-06-01T17:52:01.831683Z"}]}
{"channel":"book","type":"update","data":[{"symbol":"ETH/GBP","bids":[{"price":2978.01,"qty":0.00000000},{"price":2973.19,"qty":0.14113766}],"asks":[],"checksum":1050528057,"timestamp":"2024-06-01T17:52:01.831887Z"}]}
{"channel":"book","type":"update","data":[{"symbol":"ETH/GBP","bids":[{"price":2977.67,"qty":13.17381533}],"asks":[],"checksum":13350640,"timestamp":"2024-06-01T17:52:01.836779Z"}]}
{"channel":"book","type":"update","data":[{"symbol":"ETH/GBP","bids":[],"asks":[{"price":2979.15,"qty":13.16728192}],"checksum":4238440342,"timestamp":"2024-06-01T17:52:01.921224Z"}]}
{"channel":"book","type":"update","data":[{"symbol":"ETH/GBP","bids":[],"asks":[{"price":2979.15,"qty":0.00000000},{"price":2980.82,"qty":1.00000000}],"checksum":13350640,"timestamp":"2024-06-01T17:52:01.925779Z"}]}
{"channel":"book","type":"update","data":[{"symbol":"ETH/GBP","bids":[{"price":2978.11,"qty":6.58593216}],"asks":[],"checksum":4072414351,"timestamp":"2024-06-01T17:52:01.930025Z"}]}
{"channel":"book","type":"update","data":[{"symbol":"ETH/GBP","bids":[],"asks":[{"price":2978.33,"qty":6.58546813}],"checksum":2794318508,"timestamp":"2024-06-01T17:52:01.930117Z"}]}
{"channel":"book","type":"update","data":[{"symbol":"ETH/GBP","bids":[],"asks":[{"price":2978.33,"qty":0.00000000},{"price":2980.82,"qty":1.00000000}],"checksum":4072414351,"timestamp":"2024-06-01T17:52:01.936383Z"}]}
{"channel":"book","type":"update","data":[{"symbol":"ETH/GBP","bids":[],"asks":[{"price":2978.32,"qty":6.58548685}],"checksum":2392566562,"timestamp":"2024-06-01T17:52:02.055523Z"}]}
{"channel":"book","type":"update","data":[{"symbol":"ETH/GBP","bids":[{"price":2978.11,"qty":0.00000000},{"price":2974.50,"qty":0.27200000}],"asks":[],"checksum":4220759102,"timestamp":"2024-06-01T17:52:02.060673Z"}]}
{"channel":"book","type":"update","data":[{"symbol":"ETH/GBP","bids":[{"price":2978.09,"qty":6.58596703}],"asks":[],"checksum":3812203524,"timestamp":"2024-06-01T17:52:02.064424Z"}]}
{"channel":"book","type":"update","data":[{"symbol":"ETH/GBP","bids":[{"price":2978.09,"qty":0.00000000},{"price":2974.50,"qty":0.27200000}],"asks":[],"checksum":4220759102,"timestamp":"2024-06-01T17:52:02.128574Z"}]}
{"channel":"book","type":"update","data":[{"symbol":"ETH/GBP","bids":[],"asks":[{"price":2978.75,"qty":13.16907221}],"checksum":2877296677,"timestamp":"2024-06-01T17:52:02.132785Z"}]}
{"channel":"book","type":"update","data":[{"symbol":"ETH/GBP","bids":[],"asks":[{"price":2978.32,"qty":0.00000000},{"price":2980.80,"qty":0.20717085}],"checksum":1019032400,"timestamp":"2024-06-01T17:52:02.177900Z"}]}
{"channel":"book","type":"update","data":[{"symbol":"ETH/GBP","bids":[],"asks":[{"price":2978.31,"qty":6.58550736}],"checksum":372198313,"timestamp":"2024-06-01T17:52:02.183094Z"}]}
{"channel":"book","type":"update","data":[{"symbol":"ETH/GBP","bids":[{"price":2978.08,"qty":6.58599039}],"asks":[],"checksum":688197891,"timestamp":"2024-06-01T17:52:02.183172Z"}]}
{"channel":"book","type":"update","data":[{"symbol":"ETH/GBP","bids":[],"asks":[{"price":2978.75,"qty":0.00000000},{"price":2980.80,"qty":0.20717085}],"checksum":1428831219,"timestamp":"2024-06-01T17:52:02.183284Z"}]}
{"channel":"book","type":"update","data":[{"symbol":"ETH/GBP","bids":[],"asks":[{"price":2978.31,"qty":0.00000000},{"price":2980.82,"qty":1.00000000}],"checksum":1000610990,"timestamp":"2024-06-01T17:52:02.188387Z"}]}
{"channel":"book","type":"update","data":[{"symbol":"ETH/GBP","bids":[{"price":2978.08,"qty":0.00000000},{"price":2974.50,"qty":0.27200000}],"asks":[],"checksum":13350640,"timestamp":"2024-06-01T17:52:02.188425Z"}]}
{"channel":"book","type":"update","data":[{"symbol":"ETH/GBP","bids":[],"asks":[{"price":2979.15,"qty":6.58364096}],"checksum":1064324153,"timestamp":"2024-06-01T17:52:02.288258Z"}]}
{"channel":"book","type":"update","data":[{"symbol":"ETH/GBP","bids":[{"price":2978.13,"qty":6.58587677}],"asks":[],"checksum":3496549060,"timestamp":"2024-06-01T17:52:02.288274Z"}]}
{"channel":"book","type":"update","data":[{"symbol":"ETH/GBP","bids":[],"asks":[{"price":2979.15,"qty":0.00000000},{"price":2980.82,"qty":1.00000000}],"checksum":854514474,"timestamp":"2024-06-01T17:52:02.293163Z"}]}
{"channel":"book","type":"update","data":[{"symbol":"ETH/GBP","bids":[{"price":2978.13,"qty":0.00000000},{"price":2974.50,"qty":0.27200000}],"asks":[],"checksum":13350640,"timestamp":"2024-06-01T17:52:02.303061Z"}]}
{"channel":"book","type":"update","data":[{"symbol":"ETH/GBP","bids":[{"price":2977.67,"qty":0.00000000},{"price":2973.19,"qty":0.14113766}],"asks":[],"checksum":1050528057,"timestamp":"2024-06-01T17:52:02.321976Z"}]}
{"channel":"book","type":"update","data":[{"symbol":"ETH/GBP","bids":[{"price":2977.74,"qty":13.17349539}],"asks":[],"checksum":1816779968,"timestamp":"2024-06-01T17:52:02.325875Z"}]}
{"channel":"book","type":"update","data":[{"symbol":"ETH/GBP","bids":[],"asks":[{"price":2978.40,"qty":6.58530487}],"checksum":2349732261,"timestamp":"2024-06-01T17:52:02.401422Z"}]}
{"channel":"book","type":"update","data":[{"symbol":"ETH/GBP","bids":[{"price":2978.17,"qty":6.58578820}],"asks":[],"checksum":220701423,"timestamp":"2024-06-01T17:52:02.401576Z"}]}
{"channel":"book","type":"update","data":[{"symbol":"ETH/GBP","bids":[],"asks":[{"price":2979.15,"qty":13.16728192}],"checksum":4268822094,"timestamp":"2024-06-01T17:52:02.401652Z"}]}
{"channel":"book","type":"update","data":[{"symbol":"ETH/GBP","bids":[],"asks":[{"price":2979.15,"qty":0.00000000},{"price":2980.80,"qty":0.20717085}],"checksum":220701423,"timestamp":"2024-06-01T17:52:02.406496Z"}]}
{"channel":"book","type":"update","data":[{"symbol":"ETH/GBP","bids":[],"asks":[{"price":2978.40,"qty":0.00000000},{"price":2980.82,"qty":1.00000000}],"checksum":807366901,"timestamp":"2024-06-01T17:52:02.450828Z"}]}
{"channel":"book","type":"update","data":[{"symbol":"ETH/GBP","bids":[],"asks":[{"price":2978.39,"qty":6.58532923}],"checksum":2379011339,"timestamp":"2024-06-01T17:52:02.501708Z"}]}
{"channel":"book","type":"update","data":[{"symbol":"ETH/GBP","bids":[],"asks":[{"price":2979.86,"qty":0.00000000},{"price":2980.82,"qty":1.00000000}],"checksum":658090197,"timestamp":"2024-06-01T17:52:02.614939Z"}]}
{"channel":"book","type":"update","data":[{"symbol":"ETH/GBP","bids":[],"asks":[{"price":2979.15,"qty":6.76888298}],"checksum":3137003665,"timestamp":"2024-06-01T17:52:02.617453Z"}]}
{"channel":"book","type":"update","data":[{"symbol":"ETH/GBP","bids":[{"price":2978.17,"qty":0.00000000},{"price":2974.50,"qty":0.27200000}],"asks":[],"checksum":3960493275,"timestamp":"2024-06-01T17:52:02.955684Z"}]}
{"channel":"book","type":"update","data":[{"symbol":"ETH/GBP","bids":[],"asks":[{"price":2978.39,"qty":0.00000000},{"price":2980.82,"qty":1.00000000}],"checksum":595850123,"timestamp":"2024-06-01T17:52:02.955705Z"}]}
{"channel":"book","type":"update","data":[{"symbol":"ETH/GBP","bids":[],"asks":[{"price":2979.07,"qty":0.31000000}],"checksum":2819145315,"timestamp":"2024-06-01T17:52:02.959011Z"}]}
{"channel":"book","type":"update","data":[{"symbol":"ETH/GBP","bids":[],"asks":[{"price":2979.18,"qty":0.00000000},{"price":2980.82,"qty":1.00000000}],"checksum":3942000962,"timestamp":"2024-06-01T17:52:02.959033Z"}]}
{"channel":"book","type":"update","data":[{"symbol":"ETH/GBP","bids":[{"price":2977.26,"qty":0.00000000},{"price":2973.19,"qty":0.14113766}],"asks":[],"checksum":2053159020,"timestamp":"2024-06-01T17:52:02.959044Z"}]}
{"channel":"book","type":"update","data":[{"symbol":"ETH/GBP","bids":[{"price":2977.82,"qty":0.31000000}],"asks":[],"checksum":2768345868,"timestamp":"2024-06-01T17:52:02.960010Z"}]}
{"channel":"book","type":"update","data":[{"symbol":"ETH/GBP","bids":[],"asks":[{"price":2978.38,"qty":6.58535755}],"checksum":3130276631,"timestamp":"2024-06-01T17:52:02.961746Z"}]}
{"channel":"book","type":"update","data":[{"symbol":"ETH/GBP","bids":[{"price":2978.16,"qty":6.58581455}],"asks":[],"checksum":1122609671,"timestamp":"2024-06-01T17:52:02.961794Z"}]}
{"channel":"book","type":"update","data":[{"symbol":"ETH/GBP","bids":[],"asks":[{"price":2978.82,"qty":13.16873991}],"checksum":604302376,"timestamp":"2024-06-01T17:52:02.961816Z"}]}
{"channel":"book","type":"update","data":[{"symbol":"ETH/GBP","bids":[],"asks":[{"price":2978.38,"qty":0.00000000},{"price":2980.80,"qty":0.20717085}],"checksum":2308237569,"timestamp":"2024-06-01T17:52:02.966117Z"}]}
{"channel":"book","type":"update","data":[{"symbol":"ETH/GBP","bids":[{"price":2978.16,"qty":0.00000000},{"price":2974.50,"qty":0.27200000}],"asks":[],"checksum":2791616935,"timestamp":"2024-06-01T17:52:03.010323Z"}]}
{"channel":"book","type":"update","data":[{"symbol":"ETH/GBP","bids":[],"asks":[{"price":2979.17,"qty":0.00000000},{"price":2980.82,"qty":1.00000000}],"checksum":843446842,"timestamp":"2024-06-01T17:52:03.029813Z"}]}
{"channel":"book","type":"update","data":[{"symbol":"ETH/GBP","bids":[],"asks":[{"price":2978.82,"qty":0.00000000},{"price":2980.93,"qty":0.27473522}],"checksum":2089454435,"timestamp":"2024-06-01T17:52:03.111029Z"}]}
{"channel":"book","type":"update","data":[{"symbol":"ETH/GBP","bids":[{"price":2977.74,"qty":0.00000000},{"price":2973.19,"qty":0.14113766}],"asks":[],"checksum":1539706654,"timestamp":"2024-06-01T17:52:03.111047Z"}]}
{"channel":"book","type":"update","data":[{"symbol":"ETH/GBP","bids":[{"price":2977.82,"qty":0.00000000},{"price":2973.18,"qty":0.27800000}],"asks":[],"checksum":2998367410,"timestamp":"2024-06-01T17:52:03.113948Z"}]}
{"channel":"book","type":"update","data":[{"symbol":"ETH/GBP","bids":[{"price":2977.18,"qty":0.31000000}],"asks":[],"checksum":2224379139,"timestamp":"2024-06-01T17:52:03.114346Z"}]}
{"channel":"book","type":"update","data":[{"symbol":"ETH/GBP","bids":[{"price":2978.26,"qty":6.58560160}],"asks":[],"checksum":758232367,"timestamp":"2024-06-01T17:52:03.115951Z"}]}
{"channel":"book","type":"update","data":[{"symbol":"ETH/GBP","bids":[{"price":2977.82,"qty":13.17312214}],"asks":[],"checksum":1833478831,"timestamp":"2024-06-01T17:52:03.115973Z"}]}
{"channel":"book","type":"update","data":[{"symbol":"ETH/GBP","bids":[],"asks":[{"price":2978.49,"qty":6.58511592}],"checksum":2659922814,"timestamp":"2024-06-01T17:52:03.116141Z"}]}
{"channel":"book","type":"update","data":[{"symbol":"ETH/GBP","bids":[],"asks":[{"price":2978.49,"qty":0.00000000},{"price":2980.93,"qty":0.27473522}],"checksum":1833478831,"timestamp":"2024-06-01T17:52:03.127346Z"}]}
{"channel":"book","type":"update","data":[{"symbol":"ETH/GBP","bids":[{"price":2978.26,"qty":0.00000000},{"price":2974.50,"qty":0.27200000}],"asks":[],"checksum":1955512623,"timestamp":"2024-06-01T17:52:03.127397Z"}]}
{"channel":"book","type":"update","data":[{"symbol":"ETH/GBP","bids":[{"price":2977.82,"qty":0.00000000},{"price":2973.19,"qty":0.14113766}],"asks":[],"checksum":2224379139,"timestamp":"2024-06-01T17:52:03.134057Z"}]}
{"channel":"book","type":"update","data":[{"symbol":"ETH/GBP","bids":[],"asks":[{"price":2979.06,"qty":13.16767574}],"checksum":1444417664,"timestamp":"2024-06-01T17:52:03.172066Z"}]}
{"channel":"book","type":"update","data":[{"symbol":"ETH/GBP","bids":[],"asks":[{"price":2979.06,"qty":0.00000000},{"price":2980.93,"qty":0.27473522}],"checksum":2224379139,"timestamp":"2024-06-01T17:52:03.177954Z"}]}
{"channel":"book","type":"update","data":[{"symbol":"ETH/GBP","bids":[{"price":2978.01,"qty":6.58615613}],"asks":[],"checksum":1785169088,"timestamp":"2024-06-01T17:52:03.254572Z"}]}
{"channel":"book","type":"update","data":[{"symbol":"ETH/GBP","bids":[],"asks":[{"price":2978.46,"qty":6.58516976}],"checksum":3605797232,"timestamp":"2024-06-01T17:52:03.254687Z"}]}
{"channel":"book","type":"update","data":[{"symbol":"ETH/GBP","bids":[{"price":2978.01,"qty":0.00000000},{"price":2973.19,"qty":0.14113766}],"asks":[],"checksum":1770782642,"timestamp":"2024-06-01T17:52:03.262148Z"}]}
{"channel":"book","type":"update","data":[{"symbol":"ETH/GBP","bids":[],"asks":[{"price":2978.89,"qty":13.16843416}],"checksum":3580685195,"timestamp":"2024-06-01T17:52:03.375560Z"}]}
{"channel":"book","type":"update","data":[{"symbol":"ETH/GBP","bids":[{"price":2978.24,"qty":6.58563045}],"asks":[],"checksum":3199353530,"timestamp":"2024-06-01T17:52:03.375649Z"}]}
{"channel":"book","type":"update","data":[{"symbol":"ETH/GBP","bids":[{"price":2977.81,"qty":13.17317029}],"asks":[],"checksum":2725756846,"timestamp":"2024-06-01T17:52:03.375707Z"}]}
{"channel":"book","type":"update","data":[{"symbol":"ETH/GBP","bids":[{"price":2978.24,"qty":0.00000000},{"price":2974.50,"qty":0.27200000}],"asks":[],"checksum":2385155881,"timestamp":"2024-06-01T17:52:03.391349Z"}]}
{"channel":"book","type":"update","data":[{"symbol":"ETH/GBP","bids":[{"price":2977.18,"qty":0.00000000},{"price":2973.19,"qty":0.14113766}],"asks":[],"checksum":760099516,"timestamp":"2024-06-01T17:52:03.394059Z"}]}
{"channel":"book","type":"update","data":[{"symbol":"ETH/GBP","bids":[{"price":2977.89,"qty":0.31000000}],"asks":[],"checksum":876416475,"timestamp":"2024-06-01T17:52:03.394170Z"}]}
{"channel":"book","type":"update","data":[{"symbol":"ETH/GBP","bids":[{"price":2978.01,"qty":6.58615768}],"asks":[],"checksum":2252942514,"timestamp":"2024-06-01T17:52:03.488591Z"}]}
{"channel":"book","type":"update","data":[{"symbol":"ETH/GBP","bids":[{"price":2978.01,"qty":0.00000000},{"price":2974.50,"qty":0.27200000}],"asks":[],"checksum":876416475,"timestamp":"2024-06-01T17:52:03.493136Z"}]}
{"channel":"book","type":"update","data":[{"symbol":"ETH/GBP","bids":[],"asks":[{"price":2978.46,"qty":0.00000000},{"price":2980.82,"qty":1.00000000}],"checksum":3101287688,"timestamp":"2024-06-01T17:52:03.609022Z"}]}
{"channel":"book","type":"update","data":[{"symbol":"ETH/GBP","bids":[{"price":2978.25,"qty":6.58561465}],"asks":[],"checksum":2206059899,"timestamp":"2024-06-01T17:52:03.613444Z"}]}
{"channel":"book","type":"update","data":[{"symbol":"ETH/GBP","bids":[],"asks":[{"price":2978.48,"qty":6.58513707}],"checksum":4212986464,"timestamp":"2024-06-01T17:52:03.613490Z"}]}
{"channel":"book","type":"update","data":[{"symbol":"ETH/GBP","bids":[],"asks":[{"price":2978.48,"qty":0.00000000},{"price":2980.82,"qty":1.00000000}],"checksum":2206059899,"timestamp":"2024-06-01T17:52:03.628463Z"}]}
{"channel":"book","type":"update","data":[{"symbol":"ETH/GBP","bids":[{"price":2978.25,"qty":0.00000000},{"price":2974.50,"qty":0.27200000}],"asks":[],"checksum":3101287688,"timestamp":"2024-06-01T17:52:03.688811Z"}]}
{"channel":"book","type":"update","data":[{"symbol":"ETH/GBP","bids":[{"price":2978.26,"qty":6.58559005}],"asks":[],"checksum":3854553675,"timestamp":"2024-06-01T17:52:03.738168Z"}]}
{"channel":"book","type":"update","data":[{"symbol":"ETH/GBP","bids":[],"asks":[{"price":2978.48,"qty":6.58512038}],"checksum":3510093255,"timestamp":"2024-06-01T17:52:03.738331Z"}]}
{"channel":"book","type":"update","data":[{"symbol":"ETH/GBP","bids":[{"price":2978.26,"qty":0.00000000},{"price":2974.50,"qty":0.27200000}],"asks":[],"checksum":1578603873,"timestamp":"2024-06-01T17:52:03.772429Z"}]}
{"channel":"book","type":"update","data":[{"symbol":"ETH/GBP","bids":[],"asks":[{"price":2978.48,"qty":0.00000000},{"price":2980.82,"qty":1.00000000}],"checksum":3101287688,"timestamp":"2024-06-01T17:52:03.772464Z"}]}
{"channel":"book","type":"update","data":[{"symbol":"ETH/GBP","bids":[{"price":2977.81,"qty":0.00000000},{"price":2973.19,"qty":0.14113766}],"asks":[],"checksum":317639143,"timestamp":"2024-06-01T17:52:03.772494Z"}]}
{"channel":"book","type":"update","data":[{"symbol":"ETH/GBP","bids":[],"asks":[{"price":2978.89,"qty":0.00000000},{"price":2980.93,"qty":0.27473522}],"checksum":252500356,"timestamp":"2024-06-01T17:52:03.772624Z"}]}
{"channel":"book","type":"update","data":[{"symbol":"ETH/GBP","bids":[],"asks":[{"price":2979.07,"qty":0.00000000},{"price":2980.95,"qty":0.22400000}],"checksum":2271200480,"timestamp":"2024-06-01T17:52:03.775514Z"}]}
{"channel":"book","type":"update","data":[{"symbol":"ETH/GBP","bids":[{"price":2977.89,"qty":0.00000000},{"price":2973.18,"qty":0.27800000}],"asks":[],"checksum":988047830,"timestamp":"2024-06-01T17:52:03.775542Z"}]}
{"channel":"book","type":"update","data":[{"symbol":"ETH/GBP","bids":[],"asks":[{"price":2978.84,"qty":0.31000000}],"checksum":3770852807,"timestamp":"2024-06-01T17:52:03.775791Z"}]}
{"channel":"book","type":"update","data":[{"symbol":"ETH/GBP","bids":[{"price":2977.18,"qty":0.31000000}],"asks":[],"checksum":3605038198,"timestamp":"2024-06-01T17:52:03.775830Z"}]}
{"channel":"book","type":"update","data":[{"symbol":"ETH/GBP","bids":[],"asks":[{"price":2978.96,"qty":13.16812783}],"checksum":725159244,"timestamp":"2024-06-01T17:52:03.778344Z"}]}
{"channel":"book","type":"update","data":[{"symbol":"ETH/GBP","bids":[{"price":2977.86,"qty":13.17295452}],"asks":[],"checksum":4024592163,"timestamp":"2024-06-01T17:52:03.778656Z"}]}
{"channel":"book","type":"update","data":[{"symbol":"ETH/GBP","bids":[],"asks":[{"price":2978.51,"qty":6.58505806}],"checksum":1523761762,"timestamp":"2024-06-01T17:52:03.839546Z"}]}
{"channel":"book","type":"update","data":[{"symbol":"ETH/GBP","bids":[{"price":2978.28,"qty":6.58554348}],"asks":[],"checksum":1490066720,"timestamp":"2024-06-01T17:52:03.839575Z"}]}
{"channel":"book","type":"update","data":[{"symbol":"ETH/GBP","bids":[{"price":2977.86,"qty":0.00000000},{"price":2974.50,"qty":0.27200000}],"asks":[],"checksum":3171429459,"timestamp":"2024-06-01T17:52:03.928295Z"}]}
{"channel":"book","type":"update","data":[{"symbol":"ETH/GBP","bids":[{"price":2978.28,"qty":0.00000000},{"price":2973.19,"qty":0.14113766}],"asks":[],"checksum":2493558342,"timestamp":"2024-06-01T17:52:03.928322Z"}]}
{"channel":"book","type":"update","data":[{"symbol":"ETH/GBP","bids":[],"asks":[{"price":2978.96,"qty":0.00000000},{"price":2980.82,"qty":1.00000000}],"checksum":3690135690,"timestamp":"2024-06-01T17:52:03.928330Z"}]}
{"channel":"book","type":"update","data":[{"symbol":"ETH/GBP","bids":[],"asks":[{"price":2978.51,"qty":0.00000000},{"price":2980.93,"qty":0.27473522}],"checksum":3605038198,"timestamp":"2024-06-01T17:52:03.928465Z"}]}
{"channel":"book","type":"update","data":[{"symbol":"ETH/GBP","bids":[],"asks":[{"price":2978.83,"qty":6.58434467}],"checksum":3229863487,"timestamp":"2024-06-01T17:52:03.939879Z"}]}
{"channel":"book","type":"update","data":[{"symbol":"ETH/GBP","bids":[{"price":2978.22,"qty":6.58567811}],"asks":[],"checksum":2205876536,"timestamp":"2024-06-01T17:52:03.939990Z"}]}
{"channel":"book","type":"update","data":[{"symbol":"ETH/GBP","bids":[],"asks":[{"price":2978.83,"qty":0.00000000},{"price":2980.93,"qty":0.27473522}],"checksum":2355993414,"timestamp":"2024-06-01T17:52:03.944628Z"}]}
{"channel":"book","type":"update","data":[{"symbol":"ETH/GBP","bids":[{"price":2978.22,"qty":0.00000000},{"price":2973.19,"qty":0.14113766}],"asks":[],"checksum":3605038198,"timestamp":"2024-06-01T17:52:03.976234Z"}]}
{"channel":"book","type":"update","data":[{"symbol":"ETH/GBP","bids":[{"price":2977.80,"qty":13.17324039}],"asks":[],"checksum":3126124473,"timestamp":"2024-06-01T17:52:03.980883Z"}]}
{"channel":"book","type":"update","data":[{"symbol":"ETH/GBP","bids":[],"asks":[{"price":2978.90,"qty":13.16841360}],"checksum":3159235507,"timestamp":"2024-06-01T17:52:03.980945Z"}]}
{"channel":"book","type":"update","data":[{"symbol":"ETH/GBP","bids":[],"asks":[{"price":2978.84,"qty":0.00000000},{"price":2980.93,"qty":0.27473522}],"checksum":2346047584,"timestamp":"2024-06-01T17:52:03.983580Z"}]}
{"channel":"book","type":"update","data":[{"symbol":"ETH/GBP","bids":[],"asks":[{"price":2978.90,"qty":0.00000000},{"price":2980.95,"qty":0.22400000}],"checksum":2069866516,"timestamp":"2024-06-01T17:52:03.987774Z"}]}
{"channel":"book","type":"update","data":[{"symbol":"ETH/GBP","bids":[],"asks":[{"price":2978.45,"qty":6.58519999}],"checksum":1606092354,"timestamp":"2024-06-01T17:52:04.048188Z"}]}
{"channel":"book","type":"update","data":[{"symbol":"ETH/GBP","bids":[{"price":2978.01,"qty":6.58615436}],"asks":[],"checksum":447857498,"timestamp":"2024-06-01T17:52:04.048313Z"}]}
{"channel":"book","type":"update","data":[{"symbol":"ETH/GBP","bids":[{"price":2977.18,"qty":0.00000000},{"price":2974.50,"qty":0.27200000}],"asks":[],"checksum":3756705357,"timestamp":"2024-06-01T17:52:04.050844Z"}]}
{"channel":"book","type":"update","data":[{"symbol":"ETH/GBP","bids":[{"price":2977.88,"qty":0.31000000}],"asks":[],"checksum":3548475640,"timestamp":"2024-06-01T17:52:04.051030Z"}]}
{"channel":"book","type":"update","data":[{"symbol":"ETH/GBP","bids":[{"price":2977.88,"qty":0.00000000},{"price":2974.50,"qty":0.27200000}],"asks":[],"checksum":3756705357,"timestamp":"2024-06-01T17:52:04.051134Z"}]}
{"channel":"book","type":"update","data":[{"symbol":"ETH/GBP","bids":[{"price":2978.04,"qty":0.31000000}],"asks":[],"checksum":2498294049,"timestamp":"2024-06-01T17:52:04.051311Z"}]}
{"channel":"book","type":"update","data":[{"symbol":"ETH/GBP","bids":[{"price":2978.01,"qty":0.00000000},{"price":2974.50,"qty":0.27200000}],"asks":[],"checksum":3504710793,"timestamp":"2024-06-01T17:52:04.060700Z"}]}
{"channel":"book","type":"update","data":[{"symbol":"ETH/GBP","bids":[],"asks":[{"price":2978.45,"qty":0.00000000},{"price":2980.95,"qty":0.22400000}],"checksum":4093709023,"timestamp":"2024-06-01T17:52:04.060846Z"}]}
{"channel":"book","type":"update","data":[{"symbol":"ETH/GBP","bids":[],"asks":[{"price":2979.14,"qty":6.58366195}],"checksum":1388452701,"timestamp":"2024-06-01T17:52:04.192302Z"}]}
{"channel":"book","type":"update","data":[{"symbol":"ETH/GBP","bids":[],"asks":[{"price":2979.14,"qty":19.75098586}],"checksum":793433982,"timestamp":"2024-06-01T17:52:04.192372Z"}]}
{"channel":"book","type":"update","data":[{"symbol":"ETH/GBP","bids":[{"price":2978.21,"qty":6.58570876}],"asks":[],"checksum":2096668524,"timestamp":"2024-06-01T17:52:04.192454Z"}]}
{"channel":"book","type":"update","data":[{"symbol":"ETH/GBP","bids":[],"asks":[{"price":2979.12,"qty":0.31000000}],"checksum":2255660132,"timestamp":"2024-06-01T17:52:04.195521Z"}]}
{"channel":"book","type":"update","data":[{"symbol":"ETH/GBP","bids":[],"asks":[{"price":2979.14,"qty":13.16732391}],"checksum":763335813,"timestamp":"2024-06-01T17:52:04.197881Z"}]}
{"channel":"book","type":"update","data":[{"symbol":"ETH/GBP","bids":[],"asks":[{"price":2979.14,"qty":0.00000000},{"price":2980.93,"qty":0.27473522}],"checksum":1561726394,"timestamp":"2024-06-01T17:52:04.197957Z"}]}
{"channel":"book","type":"update","data":[{"symbol":"ETH/GBP","bids":[{"price":2978.21,"qty":0.00000000},{"price":2974.50,"qty":0.27200000}],"asks":[],"checksum":1965864010,"timestamp":"2024-06-01T17:52:04.226152Z"}]}
{"channel":"book","type":"update","data":[{"symbol":"ETH/GBP","bids":[],"asks":[{"price":2978.44,"qty":6.58522106}],"checksum":31311104,"timestamp":"2024-06-01T17:52:04.313613Z"}]}
{"channel":"book","type":"update","data":[{"symbol":"ETH/GBP","bids":[{"price":2978.21,"qty":6.58569690}],"asks":[],"checksum":1443767046,"timestamp":"2024-06-01T17:52:04.313774Z"}]}
{"channel":"book","type":"update","data":[{"symbol":"ETH/GBP","bids":[{"price":2978.21,"qty":0.00000000},{"price":2974.50,"qty":0.27200000}],"asks":[],"checksum":31311104,"timestamp":"2024-06-01T17:52:04.318534Z"}]}
{"channel":"book","type":"update","data":[{"symbol":"ETH/GBP","bids":[],"asks":[{"price":2978.44,"qty":0.00000000},{"price":2980.93,"qty":0.27473522}],"checksum":1965864010,"timestamp":"2024-06-01T17:52:04.462994Z"}]}
{"channel":"book","type":"update","data":[{"symbol":"ETH/GBP","bids":[{"price":2978.23,"qty":6.58565805}],"asks":[],"checksum":198573366,"timestamp":"2024-06-01T17:52:04.467838Z"}]}
{"channel":"book","type":"update","data":[{"symbol":"ETH/GBP","bids":[],"asks":[{"price":2978.46,"qty":6.58518221}],"checksum":2697202389,"timestamp":"2024-06-01T17:52:04.467896Z"}]}
{"channel":"book","type":"update","data":[{"symbol":"ETH/GBP","bids":[],"asks":[{"price":2979.11,"qty":13.16745518}],"checksum":2694043460,"timestamp":"2024-06-01T17:52:04.468243Z"}]}
{"channel":"book","type":"update","data":[{"symbol":"ETH/GBP","bids":[],"asks":[{"price":2979.11,"qty":0.00000000},{"price":2980.82,"qty":1.00000000}],"checksum":2697202389,"timestamp":"2024-06-01T17:52:04.472633Z"}]}
{"channel":"book","type":"update","data":[{"symbol":"ETH/GBP","bids":[{"price":2978.23,"qty":0.00000000},{"price":2974.50,"qty":0.27200000}],"asks":[],"checksum":3051753061,"timestamp":"2024-06-01T17:52:04.486255Z"}]}
{"channel":"book","type":"update","data":[{"symbol":"ETH/GBP","bids":[{"price":2978.05,"qty":6.58606922}],"asks":[],"checksum":4252957609,"timestamp":"2024-06-01T17:52:04.636051Z"}]}
{"channel":"book","type":"update","data":[{"symbol":"ETH/GBP","bids":[{"price":2977.10,"qty":0.00000000},{"price":2974.50,"qty":0.27200000}],"asks":[],"checksum":3393816596,"timestamp":"2024-06-01T17:52:04.638815Z"}]}
{"channel":"book","type":"update","data":[{"symbol":"ETH/GBP","bids":[{"price":2978.05,"qty":0.00000000},{"price":2973.19,"qty":0.14113766}],"asks":[],"checksum":107169661,"timestamp":"2024-06-01T17:52:04.640436Z"}]}
{"channel":"book","type":"update","data":[{"symbol":"ETH/GBP","bids":[{"price":2977.34,"qty":5.37415812}],"asks":[],"checksum":4167801696,"timestamp":"2024-06-01T17:52:04.641804Z"}]}
{"channel":"book","type":"update","data":[{"symbol":"ETH/GBP","bids":[],"asks":[{"price":2978.46,"qty":0.00000000},{"price":2980.93,"qty":0.27473522}],"checksum":950083919,"timestamp":"2024-06-01T17:52:04.699416Z"}]}
{"channel":"book","type":"update","data":[{"symbol":"ETH/GBP","bids":[],"asks":[{"price":2978.45,"qty":6.58519933}],"checksum":1759404098,"timestamp":"2024-06-01T17:52:04.706396Z"}]}
{"channel":"book","type":"update","data":[{"symbol":"ETH/GBP","bids":[],"asks":[{"price":2978.89,"qty":13.16843666}],"checksum":1611544726,"timestamp":"2024-06-01T17:52:04.706539Z"}]}
{"channel":"book","type":"update","data":[{"symbol":"ETH/GBP","bids":[],"asks":[{"price":2978.89,"qty":0.00000000},{"price":2980.82,"qty":1.00000000}],"checksum":1759404098,"timestamp":"2024-06-01T17:52:04.711649Z"}]}
{"channel":"book","type":"update","data":[{"symbol":"ETH/GBP","bids":[{"price":2978.23,"qty":6.58566397}],"asks":[],"checksum":251664057,"timestamp":"2024-06-01T17:52:04.800470Z"}]}
{"channel":"book","type":"update","data":[{"symbol":"ETH/GBP","bids":[{"price":2978.23,"qty":0.00000000},{"price":2974.50,"qty":0.27200000}],"asks":[],"checksum":1759404098,"timestamp":"2024-06-01T17:52:04.930261Z"}]}
{"channel":"book","type":"update","data":[{"symbol":"ETH/GBP","bids":[{"price":2978.24,"qty":6.58564415}],"asks":[],"checksum":994723330,"timestamp":"2024-06-01T17:52:04.934570Z"}]}
{"channel":"book","type":"update","data":[{"symbol":"ETH/GBP","bids":[],"asks":[{"price":2978.88,"qty":13.16847090}],"checksum":3061769505,"timestamp":"2024-06-01T17:52:04.934611Z"}]}
{"channel":"book","type":"update","data":[{"symbol":"ETH/GBP","bids":[],"asks":[{"price":2979.15,"qty":0.00000000},{"price":2980.82,"qty":1.00000000}],"checksum":1599597219,"timestamp":"2024-06-01T17:52:04.985609Z"}]}
{"channel":"book","type":"update","data":[{"symbol":"ETH/GBP","bids":[],"asks":[{"price":2979.54,"qty":0.52675535}],"checksum":2259346416,"timestamp":"2024-06-01T17:52:04.991189Z"}]}
{"channel":"book","type":"update","data":[{"symbol":"ETH/GBP","bids":[],"asks":[{"price":2980.78,"qty":35.37182219}],"checksum":3187687649,"timestamp":"2024-06-01T17:52:04.991246Z"}]}
{"channel":"book","type":"update","data":[{"symbol":"ETH/GBP","bids":[],"asks":[{"price":2980.77,"qty":0.20717085}],"checksum":300522632,"timestamp":"2024-06-01T17:52:04.997723Z"}]}
{"channel":"book","type":"update","data":[{"symbol":"ETH/GBP","bids":[{"price":2978.24,"qty":0.00000000},{"price":2974.50,"qty":0.27200000}],"asks":[],"checksum":2754576057,"timestamp":"2024-06-01T17:52:05.010846Z"}]}
{"channel":"book","type":"update","data":[{"symbol":"ETH/GBP","bids":[{"price":2978.23,"qty":6.58566523}],"asks":[],"checksum":4081002346,"timestamp":"2024-06-01T17:52:05.035799Z"}]}
{"channel":"book","type":"update","data":[{"symbol":"ETH/GBP","bids":[{"price":2978.23,"qty":0.00000000},{"price":2974.50,"qty":0.27200000}],"asks":[],"checksum":2754576057,"timestamp":"2024-06-01T17:52:05.076647Z"}]}
{"channel":"book","type":"update","data":[{"symbol":"ETH/GBP","bids":[],"asks":[{"price":2978.45,"qty":0.00000000},{"price":2980.79,"qty":2.94416492}],"checksum":3754564321,"timestamp":"2024-06-01T17:52:05.092115Z"}]}
{"channel":"book","type":"update","data":[{"symbol":"ETH/GBP","bids":[],"asks":[{"price":2978.47,"qty":6.58515975}],"checksum":2671864743,"timestamp":"2024-06-01T17:52:05.096901Z"}]}
{"channel":"book","type":"update","data":[{"symbol":"ETH/GBP","bids":[],"asks":[{"price":2978.47,"qty":0.00000000},{"price":2980.79,"qty":2.94416492}],"checksum":3754564321,"timestamp":"2024-06-01T17:52:05.156830Z"}]}
{"channel":"book","type":"update","data":[{"symbol":"ETH/GBP","bids":[{"price":2978.24,"qty":6.58564284}],"asks":[],"checksum":891889074,"timestamp":"2024-06-01T17:52:05.161017Z"}]}
{"channel":"book","type":"update","data":[{"symbol":"ETH/GBP","bids":[],"asks":[{"price":2978.46,"qty":6.58516502}],"checksum":1115451234,"timestamp":"2024-06-01T17:52:05.198323Z"}]}
{"channel":"book","type":"update","data":[{"symbol":"ETH/GBP","bids":[{"price":2978.24,"qty":0.00000000},{"price":2974.50,"qty":0.27200000}],"asks":[],"checksum":2377145568,"timestamp":"2024-06-01T17:52:05.312224Z"}]}
{"channel":"book","type":"update","data":[{"symbol":"ETH/GBP","bids":[{"price":2978.25,"qty":6.58561715}],"asks":[],"checksum":843822245,"timestamp":"2024-06-01T17:52:05.316429Z"}]}
{"channel":"book","type":"update","data":[{"symbol":"ETH/GBP","bids":[{"price":2977.80,"qty":0.00000000},{"price":2974.50,"qty":0.27200000}],"asks":[],"checksum":3041194667,"timestamp":"2024-06-01T17:52:05.412474Z"}]}
{"channel":"book","type":"update","data":[{"symbol":"ETH/GBP","bids":[{"price":2978.25,"qty":0.00000000},{"price":2973.19,"qty":0.14113766}],"asks":[],"checksum":467744869,"timestamp":"2024-06-01T17:52:05.412520Z"}]}
{"channel":"book","type":"update","data":[{"symbol":"ETH/GBP","bids":[],"asks":[{"price":2978.88,"qty":0.00000000},{"price":2980.79,"qty":2.94416492}],"checksum":2676506520,"timestamp":"2024-06-01T17:52:05.412639Z"}]}
{"channel":"book","type":"update","data":[{"symbol":"ETH/GBP","bids":[{"price":2975.82,"qty":0.00000000},{"price":2973.18,"qty":0.27800000}],"asks":[],"checksum":2743729664,"timestamp":"2024-06-01T17:52:05.412697Z"}]}
{"channel":"book","type":"update","data":[{"symbol":"ETH/GBP","bids":[],"asks":[{"price":2978.46,"qty":0.00000000},{"price":2980.82,"qty":1.00000000}],"checksum":3698124050,"timestamp":"2024-06-01T17:52:05.412766Z"}]}
{"channel":"book","type":"update","data":[{"symbol":"ETH/GBP","bids":[{"price":2976.94,"qty":0.00000000},{"price":2972.96,"qty":0.27482948}],"asks":[],"checksum":1747589421,"timestamp":"2024-06-01T17:52:05.413955Z"}]}
{"channel":"book","type":"update","data":[{"symbol":"ETH/GBP","bids":[{"price":2978.04,"qty":0.00000000},{"price":2972.33,"qty":0.34530000}],"asks":[],"checksum":3417326730,"timestamp":"2024-06-01T17:52:05.415107Z"}]}
{"channel":"book","type":"update","data":[{"symbol":"ETH/GBP","bids":[{"price":2977.42,"qty":0.31000000}],"asks":[],"checksum":994814313,"timestamp":"2024-06-01T17:52:05.415605Z"}]}
{"channel":"book","type":"update","data":[{"symbol":"ETH/GBP","bids":[],"asks":[{"price":2978.15,"qty":6.58584893}],"checksum":2285507337,"timestamp":"2024-06-01T17:52:05.419622Z"}]}
{"channel":"book","type":"update","data":[{"symbol":"ETH/GBP","bids":[{"price":2977.51,"qty":13.17450389}],"asks":[],"checksum":2222063715,"timestamp":"2024-06-01T17:52:05.419695Z"}]}
{"channel":"book","type":"update","data":[{"symbol":"ETH/GBP","bids":[],"asks":[{"price":2979.11,"qty":13.16745518}],"checksum":1940760334,"timestamp":"2024-06-01T17:52:05.419722Z"}]}
{"channel":"book","type":"update","data":[{"symbol":"ETH/GBP","bids":[{"price":2977.91,"qty":6.58636530}],"asks":[],"checksum":1793183759,"timestamp":"2024-06-01T17:52:05.419753Z"}]}
{"channel":"book","type":"update","data":[{"symbol":"ETH/GBP","bids":[{"price":2974.40,"qty":1.31882650}],"asks":[],"checksum":3678242646,"timestamp":"2024-06-01T17:52:05.419888Z"}]}
{"channel":"book","type":"update","data":[{"symbol":"ETH/GBP","bids":[{"price":2976.70,"qty":1.31780948}],"asks":[],"checksum":228847376,"timestamp":"2024-06-01T17:52:05.419982Z"}]}
{"channel":"book","type":"update","data":[{"symbol":"ETH/GBP","bids":[{"price":2977.42,"qty":0.00000000},{"price":2974.40,"qty":1.31882650}],"asks":[],"checksum":3166337270,"timestamp":"2024-06-01T17:52:05.422963Z"}]}
{"channel":"book","type":"update","data":[{"symbol":"ETH/GBP","bids":[{"price":2977.59,"qty":0.31000000}],"asks":[],"checksum":3189237051,"timestamp":"2024-06-01T17:52:05.423182Z"}]}
{"channel":"book","type":"update","data":[{"symbol":"ETH/GBP","bids":[{"price":2977.96,"qty":0.31000000}],"asks":[],"checksum":3093735099,"timestamp":"2024-06-01T17:52:05.423378Z"}]}
{"channel":"book","type":"update","data":[{"symbol":"ETH/GBP","bids":[],"asks":[{"price":2979.11,"qty":0.00000000},{"price":2980.79,"qty":2.94416492}],"checksum":545747653,"timestamp":"2024-06-01T17:52:05.425680Z"}]}
{"channel":"book","type":"update","data":[{"symbol":"ETH/GBP","bids":[{"price":2977.59,"qty":0.00000000},{"price":2974.50,"qty":0.27200000}],"asks":[],"checksum":284669649,"timestamp":"2024-06-01T17:52:05.427928Z"}]}
{"channel":"book","type":"update","data":[{"symbol":"ETH/GBP","bids":[{"price":2977.91,"qty":0.00000000},{"price":2974.40,"qty":1.31882650}],"asks":[],"checksum":3697693596,"timestamp":"2024-06-01T17:52:05.430637Z"}]}
{"channel":"book","type":"update","data":[{"symbol":"ETH/GBP","bids":[],"asks":[{"price":2978.15,"qty":0.00000000},{"price":2980.82,"qty":1.00000000}],"checksum":1271231960,"timestamp":"2024-06-01T17:52:05.430716Z"}]}
{"channel":"book","type":"update","data":[{"symbol":"ETH/GBP","bids":[{"price":2977.96,"qty":0.00000000},{"price":2973.19,"qty":0.14113766}],"asks":[],"checksum":640349594,"timestamp":"2024-06-01T17:52:05.433916Z"}]}
{"channel":"book","type":"update","data":[{"symbol":"ETH/GBP","bids":[],"asks":[{"price":2979.09,"qty":1.31750155}],"checksum":4175371786,"timestamp":"2024-06-01T17:52:05.434230Z"}]}
{"channel":"book","type":"update","data":[{"symbol":"ETH/GBP","bids":[{"price":2977.51,"qty":0.00000000},{"price":2973.18,"qty":0.27800000}],"asks":[],"checksum":2456709032,"timestamp":"2024-06-01T17:52:05.459353Z"}]}
{"channel":"book","type":"update","data":[{"symbol":"ETH/GBP","bids":[],"asks":[{"price":2978.22,"qty":6.58571200}],"checksum":874051046,"timestamp":"2024-06-01T17:52:05.544523Z"}]}
{"channel":"book","type":"update","data":[{"symbol":"ETH/GBP","bids":[{"price":2977.99,"qty":6.58620046}],"asks":[],"checksum":3405704499,"timestamp":"2024-06-01T17:52:05.544555Z"}]}
{"channel":"book","type":"update","data":[{"symbol":"ETH/GBP","bids":[],"asks":[{"price":2978.22,"qty":0.00000000},{"price":2980.79,"qty":2.94416492}],"checksum":1530722102,"timestamp":"2024-06-01T17:52:05.549924Z"}]}
{"channel":"book","type":"update","data":[{"symbol":"ETH/GBP","bids":[],"asks":[{"price":2978.66,"qty":13.16947285}],"checksum":696405820,"timestamp":"2024-06-01T17:52:05.621994Z"}]}
{"channel":"book","type":"update","data":[{"symbol":"ETH/GBP","bids":[{"price":2977.56,"qty":13.17428493}],"asks":[],"checksum":1621894959,"timestamp":"2024-06-01T17:52:05.622037Z"}]}
{"channel":"book","type":"update","data":[{"symbol":"ETH/GBP","bids":[],"asks":[{"price":2978.22,"qty":6.58569883}],"checksum":1598315024,"timestamp":"2024-06-01T17:52:05.645915Z"}]}
{"channel":"book","type":"update","data":[{"symbol":"ETH/GBP","bids":[{"price":2977.99,"qty":0.00000000},{"price":2973.19,"qty":0.14113766}],"asks":[],"checksum":1132432200,"timestamp":"2024-06-01T17:52:05.769086Z"}]}
{"channel":"book","type":"update","data":[{"symbol":"ETH/GBP","bids":[{"price":2977.64,"qty":0.31000000}],"asks":[],"checksum":3413558318,"timestamp":"2024-06-01T17:52:05.771860Z"}]}
{"channel":"book","type":"update","data":[{"symbol":"ETH/GBP","bids":[{"price":2978.00,"qty":6.67177074}],"asks":[],"checksum":4286921766,"timestamp":"2024-06-01T17:52:05.773234Z"}]}
{"channel":"book","type":"update","data":[{"symbol":"ETH/GBP","bids":[],"asks":[{"price":2978.22,"qty":0.00000000},{"price":2980.78,"qty":35.37182219}],"checksum":1239218534,"timestamp":"2024-06-01T17:52:05.799003Z"}]}
{"channel":"book","type":"update","data":[{"symbol":"ETH/GBP","bids":[],"asks":[{"price":2978.24,"qty":6.58565734}],"checksum":1821526925,"timestamp":"2024-06-01T17:52:05.806566Z"}]}
{"channel":"book","type":"update","data":[{"symbol":"ETH/GBP","bids":[],"asks":[{"price":2978.24,"qty":0.00000000},{"price":2980.78,"qty":35.37182219}],"checksum":1239218534,"timestamp":"2024-06-01T17:52:05.909687Z"}]}
{"channel":"book","type":"update","data":[{"symbol":"ETH/GBP","bids":[{"price":2978.00,"qty":0.08559800}],"asks":[],"checksum":2517444232,"timestamp":"2024-06-01T17:52:05.909850Z"}]}
{"channel":"book","type":"update","data":[{"symbol":"ETH/GBP","bids":[],"asks":[{"price":2978.66,"qty":0.00000000},{"price":2980.79,"qty":2.94416492}],"checksum":1990881582,"timestamp":"2024-06-01T17:52:05.916397Z"}]}
{"channel":"book","type":"update","data":[{"symbol":"ETH/GBP","bids":[],"asks":[{"price":2979.12,"qty":0.00000000},{"price":2980.82,"qty":1.00000000}],"checksum":307654351,"timestamp":"2024-06-01T17:52:05.918981Z"}]}
{"channel":"book","type":"update","data":[{"symbol":"ETH/GBP","bids":[],"asks":[{"price":2979.01,"qty":0.31000000}],"checksum":1426806806,"timestamp":"2024-06-01T17:52:05.919251Z"}]}
{"channel":"book","type":"update","data":[{"symbol":"ETH/GBP","bids":[],"asks":[{"price":2978.20,"qty":6.58575020}],"checksum":352325109,"timestamp":"2024-06-01T17:52:05.921244Z"}]}
{"channel":"book","type":"update","data":[{"symbol":"ETH/GBP","bids":[{"price":2977.96,"qty":6.58625243}],"asks":[],"checksum":3182903913,"timestamp":"2024-06-01T17:52:05.921393Z"}]}
{"channel":"book","type":"update","data":[{"symbol":"ETH/GBP","bids":[],"asks":[{"price":2978.65,"qty":13.16948513}],"checksum":3824725654,"timestamp":"2024-06-01T17:52:05.921412Z"}]}
{"channel":"book","type":"update","data":[{"symbol":"ETH/GBP","bids":[],"asks":[{"price":2978.65,"qty":0.00000000},{"price":2980.78,"qty":35.37182219}],"checksum":3182903913,"timestamp":"2024-06-01T17:52:05.925844Z"}]}
{"channel":"book","type":"update","data":[{"symbol":"ETH/GBP","bids":[],"asks":[{"price":2979.16,"qty":0.00000000},{"price":2980.79,"qty":2.94416492},{"price":2978.80,"qty":0.06973600}],"checksum":3904673876,"timestamp":"2024-06-01T17:52:05.944905Z"}]}
{"channel":"book","type":"update","data":[{"symbol":"ETH/GBP","bids":[],"asks":[{"price":2980.33,"qty":2.94416492}],"checksum":3760412855,"timestamp":"2024-06-01T17:52:05.962699Z"}]}
{"channel":"book","type":"update","data":[{"symbol":"ETH/GBP","bids":[{"price":2977.96,"qty":0.00000000},{"price":2974.40,"qty":1.31882650}],"asks":[],"checksum":1217664811,"timestamp":"2024-06-01T17:52:05.965353Z"}]}
{"channel":"book","type":"update","data":[{"symbol":"ETH/GBP","bids":[],"asks":[{"price":2978.20,"qty":0.00000000},{"price":2980.78,"qty":35.37182219}],"checksum":1588881267,"timestamp":"2024-06-01T17:52:06.077773Z"}]}
{"channel":"book","type":"update","data":[{"symbol":"ETH/GBP","bids":[],"asks":[{"price":2978.19,"qty":6.58576641}],"checksum":3505796049,"timestamp":"2024-06-01T17:52:06.082581Z"}]}
{"channel":"book","type":"update","data":[{"symbol":"ETH/GBP","bids":[{"price":2977.98,"qty":6.58622016}],"asks":[],"checksum":2721110656,"timestamp":"2024-06-01T17:52:06.082743Z"}]}
{"channel":"book","type":"update","data":[{"symbol":"ETH/GBP","bids":[],"asks":[{"price":2978.19,"qty":0.00000000},{"price":2980.78,"qty":35.37182219}],"checksum":745704994,"timestamp":"2024-06-01T17:52:06.227916Z"}]}
{"channel":"book","type":"update","data":[{"symbol":"ETH/GBP","bids":[],"asks":[{"price":2978.63,"qty":13.16960799}],"checksum":1631663580,"timestamp":"2024-06-01T17:52:06.232586Z"}]}
{"channel":"book","type":"update","data":[{"symbol":"ETH/GBP","bids":[],"asks":[{"price":2978.20,"qty":6.58575127}],"checksum":2960195142,"timestamp":"2024-06-01T17:52:06.232600Z"}]}
{"channel":"book","type":"update","data":[{"symbol":"ETH/GBP","bids":[],"asks":[{"price":2978.20,"qty":0.00000000},{"price":2980.77,"qty":0.20717085}],"checksum":1631663580,"timestamp":"2024-06-01T17:52:06.258416Z"}]}
{"channel":"book","type":"update","data":[{"symbol":"ETH/GBP","bids":[],"asks":[{"price":2978.63,"qty":0.00000000},{"price":2980.78,"qty":35.37182219}],"checksum":745704994,"timestamp":"2024-06-01T17:52:06.408398Z"}]}
{"channel":"book","type":"update","data":[{"symbol":"ETH/GBP","bids":[{"price":2977.98,"qty":0.00000000},{"price":2974.40,"qty":1.31882650}],"asks":[],"checksum":1588881267,"timestamp":"2024-06-01T17:52:06.408439Z"}]}
{"channel":"book","type":"update","data":[{"symbol":"ETH/GBP","bids":[],"asks":[{"price":2978.18,"qty":6.58579605}],"checksum":78809103,"timestamp":"2024-06-01T17:52:06.413395Z"}]}
{"channel":"book","type":"update","data":[{"symbol":"ETH/GBP","bids":[{"price":2977.95,"qty":6.58627115}],"asks":[],"checksum":1609292829,"timestamp":"2024-06-01T17:52:06.413535Z"}]}
{"channel":"book","type":"update","data":[{"symbol":"ETH/GBP","bids":[{"price":2977.95,"qty":0.00000000},{"price":2974.40,"qty":1.31882650}],"asks":[],"checksum":78809103,"timestamp":"2024-06-01T17:52:06.458094Z"}]}
{"channel":"book","type":"update","data":[{"symbol":"ETH/GBP","bids":[],"asks":[{"price":2978.61,"qty":13.16968307}],"checksum":2776808684,"timestamp":"2024-06-01T17:52:06.462515Z"}]}
{"channel":"book","type":"update","data":[{"symbol":"ETH/GBP","bids":[],"asks":[{"price":2978.18,"qty":0.00000000},{"price":2980.77,"qty":0.20717085}],"checksum":2030331447,"timestamp":"2024-06-01T17:52:06.590852Z"}]}
{"channel":"book","type":"update","data":[{"symbol":"ETH/GBP","bids":[],"asks":[{"price":2978.22,"qty":6.58570709}],"checksum":4135599778,"timestamp":"2024-06-01T17:52:06.595475Z"}]}
{"channel":"book","type":"update","data":[{"symbol":"ETH/GBP","bids":[{"price":2977.99,"qty":6.58618621}],"asks":[],"checksum":3443468909,"timestamp":"2024-06-01T17:52:06.595660Z"}]}
{"channel":"book","type":"update","data":[{"symbol":"ETH/GBP","bids":[{"price":2977.99,"qty":0.00000000},{"price":2974.40,"qty":1.31882650}],"asks":[],"checksum":4135599778,"timestamp":"2024-06-01T17:52:06.638593Z"}]}
{"channel":"book","type":"update","data":[{"symbol":"ETH/GBP","bids":[],"asks":[{"price":2978.22,"qty":0.00000000},{"price":2980.77,"qty":0.20717085}],"checksum":2030331447,"timestamp":"2024-06-01T17:52:06.638785Z"}]}
{"channel":"book","type":"update","data":[{"symbol":"ETH/GBP","bids":[{"price":2977.97,"qty":6.58622639}],"asks":[],"checksum":2764389006,"timestamp":"2024-06-01T17:52:07.246075Z"}]}
{"channel":"book","type":"update","data":[{"symbol":"ETH/GBP","bids":[],"asks":[{"price":2978.60,"qty":6.58485310}],"checksum":2767198656,"timestamp":"2024-06-01T17:52:07.246096Z"}]}
{"channel":"book","type":"update","data":[{"symbol":"ETH/GBP","bids":[],"asks":[{"price":2978.60,"qty":0.00000000},{"price":2980.77,"qty":0.20717085}],"checksum":2764389006,"timestamp":"2024-06-01T17:52:07.250640Z"}]}
{"channel":"book","type":"update","data":[{"symbol":"ETH/GBP","bids":[],"asks":[{"price":2979.54,"qty":0.00000000},{"price":2980.78,"qty":35.37182219}],"checksum":1862613044,"timestamp":"2024-06-01T17:52:07.405100Z"}]}
{"channel":"book","type":"update","data":[{"symbol":"ETH/GBP","bids":[],"asks":[{"price":2980.78,"qty":0.00000000},{"price":2980.82,"qty":1.00000000}],"checksum":446103877,"timestamp":"2024-06-01T17:52:07.405111Z"}]}
{"channel":"book","type":"update","data":[{"symbol":"ETH/GBP","bids":[],"asks":[{"price":2979.86,"qty":18.09940779}],"checksum":3011892502,"timestamp":"2024-06-01T17:52:07.407891Z"}]}
{"channel":"book","type":"update","data":[{"symbol":"ETH/GBP","bids":[],"asks":[{"price":2978.60,"qty":6.76889332}],"checksum":3239911406,"timestamp":"2024-06-01T17:52:07.407904Z"}]}
{"channel":"book","type":"update","data":[{"symbol":"ETH/GBP","bids":[{"price":2977.97,"qty":0.00000000},{"price":2974.40,"qty":1.31882650}],"asks":[],"checksum":484197207,"timestamp":"2024-06-01T17:52:07.445810Z"}]}
{"channel":"book","type":"update","data":[{"symbol":"ETH/GBP","bids":[{"price":2977.98,"qty":6.58622186}],"asks":[],"checksum":501748212,"timestamp":"2024-06-01T17:52:07.450045Z"}]}
{"channel":"book","type":"update","data":[{"symbol":"ETH/GBP","bids":[],"asks":[{"price":2978.20,"qty":6.58575099}],"checksum":1353263311,"timestamp":"2024-06-01T17:52:07.450122Z"}]}
{"channel":"book","type":"update","data":[{"symbol":"ETH/GBP","bids":[{"price":2977.98,"qty":0.00000000},{"price":2974.40,"qty":1.31882650}],"asks":[],"checksum":1369274988,"timestamp":"2024-06-01T17:52:07.559820Z"}]}
{"channel":"book","type":"update","data":[{"symbol":"ETH/GBP","bids":[{"price":2977.99,"qty":6.58620012}],"asks":[],"checksum":3253598,"timestamp":"2024-06-01T17:52:07.563830Z"}]}
{"channel":"book","type":"update","data":[{"symbol":"ETH/GBP","bids":[],"asks":[{"price":2978.20,"qty":0.00000000},{"price":2980.34,"qty":1.31620491}],"checksum":1299225701,"timestamp":"2024-06-01T17:52:07.731547Z"}]}
{"channel":"book","type":"update","data":[{"symbol":"ETH/GBP","bids":[],"asks":[{"price":2978.22,"qty":6.58570151}],"checksum":1080513674,"timestamp":"2024-06-01T17:52:07.735626Z"}]}
{"channel":"book","type":"update","data":[{"symbol":"ETH/GBP","bids":[{"price":2977.99,"qty":0.00000000},{"price":2974.40,"qty":1.31882650}],"asks":[],"checksum":298552248,"timestamp":"2024-06-01T17:52:07.773923Z"}]}
{"channel":"book","type":"update","data":[{"symbol":"ETH/GBP","bids":[{"price":2978.00,"qty":6.67177573}],"asks":[],"checksum":2170838102,"timestamp":"2024-06-01T17:52:07.779012Z"}]}
{"channel":"book","type":"update","data":[{"symbol":"ETH/GBP","bids":[{"price":2978.00,"qty":0.08559800}],"asks":[],"checksum":298552248,"timestamp":"2024-06-01T17:52:08.062695Z"}]}
{"channel":"book","type":"update","data":[{"symbol":"ETH/GBP","bids":[],"asks":[{"price":2978.22,"qty":0.00000000},{"price":2980.34,"qty":1.31620491}],"checksum":484197207,"timestamp":"2024-06-01T17:52:08.062804Z"}]}
{"channel":"book","type":"update","data":[{"symbol":"ETH/GBP","bids":[],"asks":[{"price":2978.59,"qty":6.58487520}],"checksum":2906087068,"timestamp":"2024-06-01T17:52:08.068332Z"}]}
{"channel":"book","type":"update","data":[{"symbol":"ETH/GBP","bids":[{"price":2977.99,"qty":6.58619683}],"asks":[],"checksum":3490422406,"timestamp":"2024-06-01T17:52:08.068529Z"}]}
{"channel":"book","type":"update","data":[{"symbol":"ETH/GBP","bids":[],"asks":[{"price":2978.59,"qty":0.00000000},{"price":2980.34,"qty":1.31620491}],"checksum":1642103629,"timestamp":"2024-06-01T17:52:08.072585Z"}]}
{"channel":"book","type":"update","data":[{"symbol":"ETH/GBP","bids":[],"asks":[{"price":2978.21,"qty":6.58571958}],"checksum":3998539710,"timestamp":"2024-06-01T17:52:08.195495Z"}]}
{"channel":"book","type":"update","data":[{"symbol":"ETH/GBP","bids":[],"asks":[{"price":2978.21,"qty":0.00000000},{"price":2980.34,"qty":1.31620491}],"checksum":1642103629,"timestamp":"2024-06-01T17:52:08.271936Z"}]}
{"channel":"book","type":"update","data":[{"symbol":"ETH/GBP","bids":[{"price":2977.99,"qty":0.00000000},{"price":2974.40,"qty":1.31882650}],"asks":[],"checksum":484197207,"timestamp":"2024-06-01T17:52:08.307970Z"}]}
{"channel":"book","type":"update","data":[{"symbol":"ETH/GBP","bids":[],"asks":[{"price":2978.20,"qty":6.58574975}],"checksum":2919627387,"timestamp":"2024-06-01T17:52:08.312229Z"}]}
{"channel":"book","type":"update","data":[{"symbol":"ETH/GBP","bids":[{"price":2977.97,"qty":6.58623252}],"asks":[],"checksum":3233748101,"timestamp":"2024-06-01T17:52:08.312371Z"}]}
{"channel":"book","type":"update","data":[{"symbol":"ETH/GBP","bids":[{"price":2977.97,"qty":0.00000000},{"price":2974.40,"qty":1.31882650}],"asks":[],"checksum":2919627387,"timestamp":"2024-06-01T17:52:08.320878Z"}]}
{"channel":"book","type":"update","data":[{"symbol":"ETH/GBP","bids":[],"asks":[{"price":2978.20,"qty":0.00000000},{"price":2980.34,"qty":1.31620491}],"checksum":484197207,"timestamp":"2024-06-01T17:52:08.353545Z"}]}
{"channel":"book","type":"update","data":[{"symbol":"ETH/GBP","bids":[],"asks":[{"price":2978.59,"qty":6.58487520}],"checksum":2906087068,"timestamp":"2024-06-01T17:52:08.456137Z"}]}
{"channel":"book","type":"update","data":[{"symbol":"ETH/GBP","bids":[{"price":2977.99,"qty":6.58619564}],"asks":[],"checksum":4171901879,"timestamp":"2024-06-01T17:52:08.456188Z"}]}
{"channel":"book","type":"update","data":[{"symbol":"ETH/GBP","bids":[],"asks":[{"price":2978.59,"qty":0.00000000},{"price":2980.34,"qty":1.31620491}],"checksum":1229010556,"timestamp":"2024-06-01T17:52:08.466043Z"}]}
{"channel":"book","type":"update","data":[{"symbol":"ETH/GBP","bids":[{"price":2977.99,"qty":0.00000000},{"price":2974.40,"qty":1.31882650}],"asks":[],"checksum":484197207,"timestamp":"2024-06-01T17:52:08.626272Z"}]}
{"channel":"book","type":"update","data":[{"symbol":"ETH/GBP","bids":[{"price":2978.00,"qty":6.67176412}],"asks":[],"checksum":3927932311,"timestamp":"2024-06-01T17:52:08.630056Z"}]}
{"channel":"book","type":"update","data":[{"symbol":"ETH/GBP","bids":[],"asks":[{"price":2978.59,"qty":6.58487520}],"checksum":2702683680,"timestamp":"2024-06-01T17:52:08.630121Z"}]}
{"channel":"book","type":"update","data":[{"symbol":"ETH/GBP","bids":[],"asks":[{"price":2978.59,"qty":0.00000000},{"price":2980.34,"qty":1.31620491}],"checksum":3927932311,"timestamp":"2024-06-01T17:52:08.634581Z"}]}
{"channel":"book","type":"update","data":[{"symbol":"ETH/GBP","bids":[],"asks":[{"price":2978.22,"qty":6.58569691}],"checksum":1513827671,"timestamp":"2024-06-01T17:52:08.815813Z"}]}
{"channel":"book","type":"update","data":[{"symbol":"ETH/GBP","bids":[{"price":2978.00,"qty":0.08559800}],"asks":[],"checksum":9136193,"timestamp":"2024-06-01T17:52:09.190355Z"}]}
{"channel":"book","type":"update","data":[{"symbol":"ETH/GBP","bids":[],"asks":[{"price":2978.22,"qty":0.00000000},{"price":2980.34,"qty":1.31620491}],"checksum":484197207,"timestamp":"2024-06-01T17:52:09.190463Z"}]}
{"channel":"book","type":"update","data":[{"symbol":"ETH/GBP","bids":[{"price":2977.97,"qty":6.58622544}],"asks":[],"checksum":2770342174,"timestamp":"2024-06-01T17:52:09.195248Z"}]}
{"channel":"book","type":"update","data":[{"symbol":"ETH/GBP","bids":[],"asks":[{"price":2978.20,"qty":6.58574634}],"checksum":165848005,"timestamp":"2024-06-01T17:52:09.195388Z"}]}
{"channel":"book","type":"update","data":[{"symbol":"ETH/GBP","bids":[],"asks":[{"price":2978.20,"qty":0.00000000},{"price":2980.34,"qty":1.31620491}],"checksum":2770342174,"timestamp":"2024-06-01T17:52:09.200051Z"}]}
{"channel":"book","type":"update","data":[{"symbol":"ETH/GBP","bids":[{"price":2977.97,"qty":0.00000000},{"price":2974.40,"qty":1.31882650}],"asks":[],"checksum":484197207,"timestamp":"2024-06-01T17:52:09.200069Z"}]}
{"channel":"book","type":"update","data":[{"symbol":"ETH/GBP","bids":[{"price":2977.98,"qty":6.58620239}],"asks":[],"checksum":987946342,"timestamp":"2024-06-01T17:52:09.323161Z"}]}
{"channel":"book","type":"update","data":[{"symbol":"ETH/GBP","bids":[],"asks":[{"price":2978.59,"qty":6.58487520}],"checksum":2332672173,"timestamp":"2024-06-01T17:52:09.323578Z"}]}
{"channel":"book","type":"update","data":[{"symbol":"ETH/GBP","bids":[],"asks":[{"price":2978.59,"qty":0.00000000},{"price":2980.34,"qty":1.31620491}],"checksum":987946342,"timestamp":"2024-06-01T17:52:09.327983Z"}]}
{"channel":"book","type":"update","data":[{"symbol":"ETH/GBP","bids":[{"price":2977.98,"qty":0.00000000},{"price":2974.40,"qty":1.31882650}],"asks":[],"checksum":484197207,"timestamp":"2024-06-01T17:52:09.328186Z"}]}
{"channel":"book","type":"update","data":[{"symbol":"ETH/GBP","bids":[{"price":2977.99,"qty":6.58618285}],"asks":[],"checksum":1053887985,"timestamp":"2024-06-01T17:52:09.456120Z"}]}
{"channel":"book","type":"update","data":[{"symbol":"ETH/GBP","bids":[],"asks":[{"price":2978.59,"qty":6.58487520}],"checksum":2402947130,"timestamp":"2024-06-01T17:52:09.456219Z"}]}
{"channel":"book","type":"update","data":[{"symbol":"ETH/GBP","bids":[],"asks":[{"price":2978.59,"qty":0.00000000},{"price":2980.34,"qty":1.31620491}],"checksum":1053887985,"timestamp":"2024-06-01T17:52:09.460670Z"}]}
{"channel":"book","type":"update","data":[{"symbol":"ETH/GBP","bids":[{"price":2977.99,"qty":0.00000000},{"price":2974.40,"qty":1.31882650}],"asks":[],"checksum":484197207,"timestamp":"2024-06-01T17:52:09.624907Z"}]}
{"channel":"book","type":"update","data":[{"symbol":"ETH/GBP","bids":[],"asks":[{"price":2978.22,"qty":6.58570269}],"checksum":3723991601,"timestamp":"2024-06-01T17:52:09.629134Z"}]}
{"channel":"book","type":"update","data":[{"symbol":"ETH/GBP","bids":[{"price":2978.00,"qty":6.67177162}],"asks":[],"checksum":1691775661,"timestamp":"2024-06-01T17:52:09.629228Z"}]}
{"channel":"book","type":"update","data":[{"symbol":"ETH/GBP","bids":[],"asks":[{"price":2978.22,"qty":0.00000000},{"price":2980.34,"qty":1.31620491}],"checksum":2826835415,"timestamp":"2024-06-01T17:52:09.651021Z"}]}
{"channel":"book","type":"update","data":[{"symbol":"ETH/GBP","bids":[],"asks":[{"price":2978.61,"qty":0.00000000},{"price":2980.81,"qty":0.01189229}],"checksum":1728161869,"timestamp":"2024-06-01T17:52:09.651115Z"}]}
{"channel":"book","type":"update","data":[{"symbol":"ETH/GBP","bids":[{"price":2978.00,"qty":0.08559800}],"asks":[],"checksum":2397359087,"timestamp":"2024-06-01T17:52:09.651188Z"}]}
{"channel":"book","type":"update","data":[{"symbol":"ETH/GBP","bids":[],"asks":[{"price":2978.68,"qty":13.16938690}],"checksum":3796045718,"timestamp":"2024-06-01T17:52:09.655986Z"}]}
{"channel":"book","type":"update","data":[{"symbol":"ETH/GBP","bids":[],"asks":[{"price":2979.86,"qty":0.00000000},{"price":2980.81,"qty":0.01189229}],"checksum":3123714081,"timestamp":"2024-06-01T17:52:09.770725Z"}]}
{"channel":"book","type":"update","data":[{"symbol":"ETH/GBP","bids":[],"asks":[{"price":2979.86,"qty":24.30492496}],"checksum":1047733773,"timestamp":"2024-06-01T17:52:09.776457Z"}]}
{"channel":"book","type":"update","data":[{"symbol":"ETH/GBP","bids":[],"asks":[{"price":2978.24,"qty":6.58566597}],"checksum":3668935826,"timestamp":"2024-06-01T17:52:09.805911Z"}]}
{"channel":"book","type":"update","data":[{"symbol":"ETH/GBP","bids":[{"price":2978.00,"qty":6.67177350}],"asks":[],"checksum":3551666794,"timestamp":"2024-06-01T17:52:09.806070Z"}]}
{"channel":"book","type":"update","data":[{"symbol":"ETH/GBP","bids":[{"price":2978.00,"qty":0.08559800}],"asks":[],"checksum":3668935826,"timestamp":"2024-06-01T17:52:09.870189Z"}]}
{"channel":"book","type":"update","data":[{"symbol":"ETH/GBP","bids":[],"asks":[{"price":2978.24,"qty":0.00000000},{"price":2980.34,"qty":1.31620491}],"checksum":1047733773,"timestamp":"2024-06-01T17:52:09.870215Z"}]}
{"channel":"book","type":"update","data":[{"symbol":"ETH/GBP","bids":[],"asks":[{"price":2978.68,"qty":0.00000000},{"price":2980.81,"qty":0.01189229}],"checksum":2510238259,"timestamp":"2024-06-01T17:52:09.870384Z"}]}
{"channel":"book","type":"update","data":[{"symbol":"ETH/GBP","bids":[],"asks":[{"price":2978.61,"qty":13.16967171}],"checksum":1258567752,"timestamp":"2024-06-01T17:52:09.875149Z"}]}
{"channel":"book","type":"update","data":[{"symbol":"ETH/GBP","bids":[{"price":2977.95,"qty":6.58628352}],"asks":[],"checksum":2940546132,"timestamp":"2024-06-01T17:52:09.922991Z"}]}
{"channel":"book","type":"update","data":[{"symbol":"ETH/GBP","bids":[],"asks":[{"price":2978.20,"qty":6.58575884}],"checksum":978726594,"timestamp":"2024-06-01T17:52:09.923021Z"}]}
{"channel":"book","type":"update","data":[{"symbol":"ETH/GBP","bids":[{"price":2977.95,"qty":0.00000000},{"price":2974.40,"qty":1.31882650}],"asks":[],"checksum":3726064350,"timestamp":"2024-06-01T17:52:09.929386Z"}]}
{"channel":"book","type":"update","data":[{"symbol":"ETH/GBP","bids":[],"asks":[{"price":2978.20,"qty":0.00000000},{"price":2980.34,"qty":1.31620491}],"checksum":1258567752,"timestamp":"2024-06-01T17:52:09.986240Z"}]}
{"channel":"book","type":"update","data":[{"symbol":"ETH/GBP","bids":[],"asks":[{"price":2978.21,"qty":6.58572371}],"checksum":2158599022,"timestamp":"2024-06-01T17:52:10.121995Z"}]}
{"channel":"book","type":"update","data":[{"symbol":"ETH/GBP","bids":[{"price":2977.98,"qty":6.58621626}],"asks":[],"checksum":3607886436,"timestamp":"2024-06-01T17:52:10.122184Z"}]}
{"channel":"book","type":"update","data":[{"symbol":"ETH/GBP","bids":[{"price":2977.98,"qty":0.00000000},{"price":2974.40,"qty":1.31882650}],"asks":[],"checksum":2158599022,"timestamp":"2024-06-01T17:52:10.126351Z"}]}
{"channel":"book","type":"update","data":[{"symbol":"ETH/GBP","bids":[],"asks":[{"price":2978.21,"qty":0.00000000},{"price":2980.34,"qty":1.31620491}],"checksum":1258567752,"timestamp":"2024-06-01T17:52:10.196411Z"}]}
{"channel":"book","type":"update","data":[{"symbol":"ETH/GBP","bids":[],"asks":[{"price":2978.19,"qty":6.58577377}],"checksum":2445466234,"timestamp":"2024-06-01T17:52:10.230375Z"}]}
{"channel":"book","type":"update","data":[{"symbol":"ETH/GBP","bids":[{"price":2977.95,"qty":6.58628608}],"asks":[],"checksum":2615879172,"timestamp":"2024-06-01T17:52:10.230414Z"}]}
{"channel":"book","type":"update","data":[{"symbol":"ETH/GBP","bids":[{"price":2977.95,"qty":0.00000000},{"price":2974.40,"qty":1.31882650}],"asks":[],"checksum":2445466234,"timestamp":"2024-06-01T17:52:10.236937Z"}]}
{"channel":"book","type":"update","data":[{"symbol":"ETH/GBP","bids":[],"asks":[{"price":2978.19,"qty":0.00000000},{"price":2980.34,"qty":1.31620491}],"checksum":1258567752,"timestamp":"2024-06-01T17:52:10.293495Z"}]}
{"channel":"book","type":"update","data":[{"symbol":"ETH/GBP","bids":[],"asks":[{"price":2978.59,"qty":6.58487520}],"checksum":130113836,"timestamp":"2024-06-01T17:52:10.477005Z"}]}
{"channel":"book","type":"update","data":[{"symbol":"ETH/GBP","bids":[{"price":2977.96,"qty":6.58626698}],"asks":[],"checksum":1293515245,"timestamp":"2024-06-01T17:52:10.477023Z"}]}
{"channel":"book","type":"update","data":[{"symbol":"ETH/GBP","bids":[],"asks":[{"price":2978.59,"qty":0.00000000},{"price":2980.34,"qty":1.31620491}],"checksum":31203465,"timestamp":"2024-06-01T17:52:10.481480Z"}]}
{"channel":"book","type":"update","data":[{"symbol":"ETH/GBP","bids":[{"price":2977.96,"qty":0.00000000},{"price":2974.40,"qty":1.31882650}],"asks":[],"checksum":1258567752,"timestamp":"2024-06-01T17:52:10.579139Z"}]}
{"channel":"book","type":"update","data":[{"symbol":"ETH/GBP","bids":[],"asks":[{"price":2978.59,"qty":6.58487520}],"checksum":130113836,"timestamp":"2024-06-01T17:52:10.583274Z"}]}
{"channel":"book","type":"update","data":[{"symbol":"ETH/GBP","bids":[{"price":2977.97,"qty":6.58624468}],"asks":[],"checksum":1460767499,"timestamp":"2024-06-01T17:52:10.583398Z"}]}
{"channel":"book","type":"update","data":[{"symbol":"ETH/GBP","bids":[],"asks":[{"price":2978.59,"qty":0.00000000},{"price":2980.34,"qty":1.31620491}],"checksum":466932335,"timestamp":"2024-06-01T17:52:10.588096Z"}]}
{"channel":"book","type":"update","data":[{"symbol":"ETH/GBP","bids":[],"asks":[{"price":2978.59,"qty":6.58487520}],"checksum":1460767499,"timestamp":"2024-06-01T17:52:10.876620Z"}]}
{"channel":"book","type":"update","data":[{"symbol":"ETH/GBP","bids":[],"asks":[{"price":2978.59,"qty":0.00000000},{"price":2980.34,"qty":1.31620491}],"checksum":466932335,"timestamp":"2024-06-01T17:52:10.882009Z"}]}
{"channel":"book","type":"update","data":[{"symbol":"ETH/GBP","bids":[{"price":2977.97,"qty":0.00000000},{"price":2974.40,"qty":1.31882650}],"asks":[],"checksum":1258567752,"timestamp":"2024-06-01T17:52:10.964666Z"}]}
{"channel":"book","type":"update","data":[{"symbol":"ETH/GBP","bids":[{"price":2977.99,"qty":6.58619582}],"asks":[],"checksum":3283343440,"timestamp":"2024-06-01T17:52:10.968638Z"}]}
{"channel":"book","type":"update","data":[{"symbol":"ETH/GBP","bids":[],"asks":[{"price":2978.22,"qty":6.58571232}],"checksum":1443202968,"timestamp":"2024-06-01T17:52:11.006395Z"}]}
{"channel":"book","type":"update","data":[{"symbol":"ETH/GBP","bids":[{"price":2977.99,"qty":0.00000000},{"price":2974.40,"qty":1.31882650}],"asks":[],"checksum":3736233856,"timestamp":"2024-06-01T17:52:11.067748Z"}]}
{"channel":"book","type":"update","data":[{"symbol":"ETH/GBP","bids":[],"asks":[{"price":2978.22,"qty":0.00000000},{"price":2980.34,"qty":1.31620491}],"checksum":1258567752,"timestamp":"2024-06-01T17:52:11.067760Z"}]}
{"channel":"book","type":"update","data":[{"symbol":"ETH/GBP","bids":[{"price":2977.96,"qty":6.58625905}],"asks":[],"checksum":593558215,"timestamp":"2024-06-01T17:52:11.072305Z"}]}
{"channel":"book","type":"update","data":[{"symbol":"ETH/GBP","bids":[],"asks":[{"price":2978.59,"qty":6.58487520}],"checksum":1873126307,"timestamp":"2024-06-01T17:52:11.298205Z"}]}
{"channel":"book","type":"update","data":[{"symbol":"ETH/GBP","bids":[],"asks":[{"price":2978.59,"qty":0.00000000},{"price":2980.34,"qty":1.31620491}],"checksum":593558215,"timestamp":"2024-06-01T17:52:11.302952Z"}]}
{"channel":"book","type":"update","data":[{"symbol":"ETH/GBP","bids":[{"price":2977.96,"qty":0.00000000},{"price":2974.40,"qty":1.31882650}],"asks":[],"checksum":1258567752,"timestamp":"2024-06-01T17:52:11.331225Z"}]}
{"channel":"book","type":"update","data":[{"symbol":"ETH/GBP","bids":[{"price":2977.97,"qty":6.58624459}],"asks":[],"checksum":1690058679,"timestamp":"2024-06-01T17:52:11.335543Z"}]}
{"channel":"book","type":"update","data":[{"symbol":"ETH/GBP","bids":[{"price":2977.97,"qty":0.00000000},{"price":2974.40,"qty":1.31882650}],"asks":[],"checksum":1258567752,"timestamp":"2024-06-01T17:52:11.507200Z"}]}
{"channel":"book","type":"update","data":[{"symbol":"ETH/GBP","bids":[],"asks":[{"price":2978.59,"qty":6.58487520}],"checksum":130113836,"timestamp":"2024-06-01T17:52:11.511760Z"}]}
{"channel":"book","type":"update","data":[{"symbol":"ETH/GBP","bids":[{"price":2977.98,"qty":6.58621627}],"asks":[],"checksum":3245207271,"timestamp":"2024-06-01T17:52:11.511976Z"}]}
{"channel":"book","type":"update","data":[{"symbol":"ETH/GBP","bids":[],"asks":[{"price":2978.59,"qty":0.00000000},{"price":2980.34,"qty":1.31620491}],"checksum":2376644483,"timestamp":"2024-06-01T17:52:11.516913Z"}]}
{"channel":"book","type":"update","data":[{"symbol":"ETH/GBP","bids":[{"price":2977.98,"qty":0.00000000},{"price":2974.40,"qty":1.31882650}],"asks":[],"checksum":1258567752,"timestamp":"2024-06-01T17:52:11.608490Z"}]}
{"channel":"book","type":"update","data":[{"symbol":"ETH/GBP","bids":[],"asks":[{"price":2978.22,"qty":6.58569442}],"checksum":4177468545,"timestamp":"2024-06-01T17:52:11.612955Z"}]}
{"channel":"book","type":"update","data":[{"symbol":"ETH/GBP","bids":[{"price":2977.99,"qty":6.58619592}],"asks":[],"checksum":2629435473,"timestamp":"2024-06-01T17:52:11.613144Z"}]}
{"channel":"book","type":"update","data":[{"symbol":"ETH/GBP","bids":[{"price":2977.99,"qty":0.00000000},{"price":2974.40,"qty":1.31882650}],"asks":[],"checksum":4177468545,"timestamp":"2024-06-01T17:52:11.681052Z"}]}
{"channel":"book","type":"update","data":[{"symbol":"ETH/GBP","bids":[],"asks":[{"price":2978.22,"qty":0.00000000},{"price":2980.34,"qty":1.31620491}],"checksum":1258567752,"timestamp":"2024-06-01T17:52:11.681114Z"}]}
{"channel":"book","type":"update","data":[{"symbol":"ETH/GBP","bids":[],"asks":[{"price":2980.33,"qty":0.00000000},{"price":2980.82,"qty":1.00000000}],"checksum":3788484438,"timestamp":"2024-06-01T17:52:11.844802Z"}]}
{"channel":"book","type":"update","data":[{"symbol":"ETH/GBP","bids":[],"asks":[{"price":2980.32,"qty":2.94416492}],"checksum":3147721956,"timestamp":"2024-06-01T17:52:11.847568Z"}]}
{"channel":"book","type":"update","data":[{"symbol":"ETH/GBP","bids":[],"asks":[{"price":2978.20,"qty":6.58575870}],"checksum":2810462481,"timestamp":"2024-06-01T17:52:12.047535Z"}]}
{"channel":"book","type":"update","data":[{"symbol":"ETH/GBP","bids":[{"price":2977.96,"qty":6.58625128}],"asks":[],"checksum":1463326385,"timestamp":"2024-06-01T17:52:12.047622Z"}]}
{"channel":"book","type":"update","data":[{"symbol":"ETH/GBP","bids":[{"price":2977.96,"qty":0.00000000},{"price":2974.40,"qty":1.31882650}],"asks":[],"checksum":2810462481,"timestamp":"2024-06-01T17:52:12.140880Z"}]}
{"channel":"book","type":"update","data":[{"symbol":"ETH/GBP","bids":[],"asks":[{"price":2978.20,"qty":0.00000000},{"price":2980.34,"qty":1.31620491}],"checksum":3147721956,"timestamp":"2024-06-01T17:52:12.144838Z"}]}
{"channel":"book","type":"update","data":[{"symbol":"ETH/GBP","bids":[],"asks":[{"price":2978.22,"qty":6.58569876}],"checksum":1945807867,"timestamp":"2024-06-01T17:52:12.149792Z"}]}
{"channel":"book","type":"update","data":[{"symbol":"ETH/GBP","bids":[{"price":2977.99,"qty":6.58619134}],"asks":[],"checksum":4150343297,"timestamp":"2024-06-01T17:52:12.149842Z"}]}
{"channel":"book","type":"update","data":[{"symbol":"ETH/GBP","bids":[],"asks":[{"price":2978.60,"qty":0.00000000},{"price":2980.34,"qty":1.31620491}],"checksum":3616655147,"timestamp":"2024-06-01T17:52:12.166833Z"}]}
{"channel":"book","type":"update","data":[{"symbol":"ETH/GBP","bids":[],"asks":[{"price":2979.86,"qty":0.00000000},{"price":2980.82,"qty":1.00000000}],"checksum":4081211581,"timestamp":"2024-06-01T17:52:12.166948Z"}]}
{"channel":"book","type":"update","data":[{"symbol":"ETH/GBP","bids":[],"asks":[{"price":2978.60,"qty":6.24872911}],"checksum":349469027,"timestamp":"2024-06-01T17:52:12.171649Z"}]}
{"channel":"book","type":"update","data":[{"symbol":"ETH/GBP","bids":[],"asks":[{"price":2979.86,"qty":22.24733670}],"checksum":4164709688,"timestamp":"2024-06-01T17:52:12.171814Z"}]}
{"channel":"book","type":"update","data":[{"symbol":"ETH/GBP","bids":[],"asks":[{"price":2978.22,"qty":0.00000000},{"price":2980.34,"qty":1.31620491}],"checksum":2673250197,"timestamp":"2024-06-01T17:52:12.252363Z"}]}
{"channel":"book","type":"update","data":[{"symbol":"ETH/GBP","bids":[],"asks":[{"price":2978.59,"qty":6.58487520}],"checksum":4255874984,"timestamp":"2024-06-01T17:52:12.257308Z"}]}
{"channel":"book","type":"update","data":[{"symbol":"ETH/GBP","bids":[],"asks":[{"price":2978.59,"qty":0.00000000},{"price":2980.34,"qty":1.31620491}],"checksum":2673250197,"timestamp":"2024-06-01T17:52:12.261950Z"}]}
{"channel":"book","type":"update","data":[{"symbol":"ETH/GBP","bids":[{"price":2977.99,"qty":0.00000000},{"price":2974.40,"qty":1.31882650}],"asks":[],"checksum":466424559,"timestamp":"2024-06-01T17:52:12.311039Z"}]}
{"channel":"book","type":"update","data":[{"symbol":"ETH/GBP","bids":[{"price":2977.99,"qty":6.58619990}],"asks":[],"checksum":3481462961,"timestamp":"2024-06-01T17:52:12.314480Z"}]}
{"channel":"book","type":"update","data":[{"symbol":"ETH/GBP","bids":[{"price":2977.99,"qty":0.00000000},{"price":2974.40,"qty":1.31882650}],"asks":[],"checksum":466424559,"timestamp":"2024-06-01T17:52:12.320713Z"}]}
{"channel":"book","type":"update","data":[{"symbol":"ETH/GBP","bids":[],"asks":[{"price":2978.59,"qty":6.58487520}],"checksum":2033246930,"timestamp":"2024-06-01T17:52:12.496230Z"}]}
{"channel":"book","type":"update","data":[{"symbol":"ETH/GBP","bids":[{"price":2977.97,"qty":6.58623518}],"asks":[],"checksum":3838209595,"timestamp":"2024-06-01T17:52:12.496313Z"}]}
{"channel":"book","type":"update","data":[{"symbol":"ETH/GBP","bids":[],"asks":[{"price":2978.59,"qty":0.00000000},{"price":2980.34,"qty":1.31620491}],"checksum":2252054022,"timestamp":"2024-06-01T17:52:12.500663Z"}]}
{"channel":"book","type":"update","data":[{"symbol":"ETH/GBP","bids":[{"price":2977.97,"qty":0.00000000},{"price":2974.40,"qty":1.31882650}],"asks":[],"checksum":466424559,"timestamp":"2024-06-01T17:52:12.523584Z"}]}
{"channel":"book","type":"update","data":[{"symbol":"ETH/GBP","bids":[{"price":2977.96,"qty":6.58625889}],"asks":[],"checksum":2521842963,"timestamp":"2024-06-01T17:52:12.615996Z"}]}
{"channel":"book","type":"update","data":[{"symbol":"ETH/GBP","bids":[],"asks":[{"price":2978.19,"qty":6.58577187}],"checksum":154742262,"timestamp":"2024-06-01T17:52:12.616142Z"}]}
{"channel":"book","type":"update","data":[{"symbol":"ETH/GBP","bids":[{"price":2977.96,"qty":0.00000000},{"price":2974.40,"qty":1.31882650}],"asks":[],"checksum":2225371658,"timestamp":"2024-06-01T17:52:12.628737Z"}]}
{"channel":"book","type":"update","data":[{"symbol":"ETH/GBP","bids":[],"asks":[{"price":2978.19,"qty":0.00000000},{"price":2980.34,"qty":1.31620491}],"checksum":466424559,"timestamp":"2024-06-01T17:52:12.768346Z"}]}
{"channel":"book","type":"update","data":[{"symbol":"ETH/GBP","bids":[],"asks":[{"price":2978.22,"qty":6.58569876}],"checksum":2091380802,"timestamp":"2024-06-01T17:52:12.773795Z"}]}
{"channel":"book","type":"update","data":[{"symbol":"ETH/GBP","bids":[{"price":2977.99,"qty":6.58618578}],"asks":[],"checksum":135898219,"timestamp":"2024-06-01T17:52:12.773832Z"}]}
{"channel":"book","type":"update","data":[{"symbol":"ETH/GBP","bids":[{"price":2977.99,"qty":0.00000000},{"price":2974.40,"qty":1.31882650}],"asks":[],"checksum":2091380802,"timestamp":"2024-06-01T17:52:13.107532Z"}]}
{"channel":"book","type":"update","data":[{"symbol":"ETH/GBP","bids":[],"asks":[{"price":2978.22,"qty":0.00000000},{"price":2980.34,"qty":1.31620491}],"checksum":466424559,"timestamp":"2024-06-01T17:52:13.107633Z"}]}
{"channel":"book","type":"update","data":[{"symbol":"ETH/GBP","bids":[],"asks":[{"price":2978.20,"qty":6.58575436}],"checksum":432991772,"timestamp":"2024-06-01T17:52:13.112960Z"}]}
{"channel":"book","type":"update","data":[{"symbol":"ETH/GBP","bids":[{"price":2977.97,"qty":6.58624258}],"asks":[],"checksum":1853069988,"timestamp":"2024-06-01T17:52:13.113129Z"}]}
{"channel":"book","type":"update","data":[{"symbol":"ETH/GBP","bids":[{"price":2977.97,"qty":0.00000000},{"price":2974.40,"qty":1.31882650}],"asks":[],"checksum":432991772,"timestamp":"2024-06-01T17:52:13.230169Z"}]}
{"channel":"book","type":"update","data":[{"symbol":"ETH/GBP","bids":[],"asks":[{"price":2978.20,"qty":0.00000000},{"price":2980.34,"qty":1.31620491}],"checksum":466424559,"timestamp":"2024-06-01T17:52:13.230252Z"}]}
{"channel":"book","type":"update","data":[{"symbol":"ETH/GBP","bids":[],"asks":[{"price":2978.22,"qty":6.58569706}],"checksum":3850010396,"timestamp":"2024-06-01T17:52:13.235244Z"}]}
{"channel":"book","type":"update","data":[{"symbol":"ETH/GBP","bids":[{"price":2977.99,"qty":6.58618527}],"asks":[],"checksum":1787088660,"timestamp":"2024-06-01T17:52:13.235332Z"}]}
{"channel":"book","type":"update","data":[{"symbol":"ETH/GBP","bids":[{"price":2977.99,"qty":0.00000000},{"price":2974.40,"qty":1.31882650}],"asks":[],"checksum":3850010396,"timestamp":"2024-06-01T17:52:13.258994Z"}]}
{"channel":"book","type":"update","data":[{"symbol":"ETH/GBP","bids":[],"asks":[{"price":2978.22,"qty":0.00000000},{"price":2980.34,"qty":1.31620491}],"checksum":466424559,"timestamp":"2024-06-01T17:52:13.584464Z"}]}
{"channel":"book","type":"update","data":[{"symbol":"ETH/GBP","bids":[],"asks":[{"price":2978.21,"qty":6.58573263}],"checksum":738354822,"timestamp":"2024-06-01T17:52:13.589261Z"}]}
{"channel":"book","type":"update","data":[{"symbol":"ETH/GBP","bids":[{"price":2977.98,"qty":6.58620306}],"asks":[],"checksum":1670554779,"timestamp":"2024-06-01T17:52:13.589533Z"}]}
{"channel":"book","type":"update","data":[{"symbol":"ETH/GBP","bids":[{"price":2977.98,"qty":0.00000000},{"price":2974.40,"qty":1.31882650}],"asks":[],"checksum":738354822,"timestamp":"2024-06-01T17:52:13.639558Z"}]}
{"channel":"book","type":"update","data":[{"symbol":"ETH/GBP","bids":[],"asks":[{"price":2978.21,"qty":0.00000000},{"price":2980.34,"qty":1.31620491}],"checksum":466424559,"timestamp":"2024-06-01T17:52:13.818090Z"}]}
{"channel":"book","type":"update","data":[{"symbol":"ETH/GBP","bids":[{"price":2977.99,"qty":6.58619910}],"asks":[],"checksum":3318814709,"timestamp":"2024-06-01T17:52:13.823139Z"}]}
{"channel":"book","type":"update","data":[{"symbol":"ETH/GBP","bids":[],"asks":[{"price":2978.23,"qty":6.58569161}],"checksum":2220345565,"timestamp":"2024-06-01T17:52:13.823186Z"}]}
{"channel":"book","type":"update","data":[{"symbol":"ETH/GBP","bids":[{"price":2977.99,"qty":0.00000000},{"price":2974.40,"qty":1.31882650}],"asks":[],"checksum":1514917319,"timestamp":"2024-06-01T17:52:14.017814Z"}]}
{"channel":"book","type":"update","data":[{"symbol":"ETH/GBP","bids":[],"asks":[{"price":2978.23,"qty":0.00000000},{"price":2980.34,"qty":1.31620491}],"checksum":466424559,"timestamp":"2024-06-01T17:52:14.017848Z"}]}
{"channel":"book","type":"update","data":[{"symbol":"ETH/GBP","bids":[],"asks":[{"price":2978.61,"qty":0.00000000},{"price":2980.82,"qty":1.00000000}],"checksum":3241687027,"timestamp":"2024-06-01T17:52:14.017931Z"}]}
{"channel":"book","type":"update","data":[{"symbol":"ETH/GBP","bids":[],"asks":[{"price":2978.68,"qty":13.16939037}],"checksum":753198196,"timestamp":"2024-06-01T17:52:14.022769Z"}]}
{"channel":"book","type":"update","data":[{"symbol":"ETH/GBP","bids":[],"asks":[{"price":2978.25,"qty":6.58564666}],"checksum":718885369,"timestamp":"2024-06-01T17:52:14.022828Z"}]}
{"channel":"book","type":"update","data":[{"symbol":"ETH/GBP","bids":[{"price":2978.01,"qty":6.58615768}],"asks":[],"checksum":2960506704,"timestamp":"2024-06-01T17:52:14.022878Z"}]}
{"channel":"book","type":"update","data":[{"symbol":"ETH/GBP","bids":[{"price":2978.01,"qty":0.00000000},{"price":2974.40,"qty":1.31882650}],"asks":[],"checksum":718885369,"timestamp":"2024-06-01T17:52:14.050253Z"}]}
{"channel":"book","type":"update","data":[{"symbol":"ETH/GBP","bids":[],"asks":[{"price":2978.25,"qty":0.00000000},{"price":2980.34,"qty":1.31620491}],"checksum":753198196,"timestamp":"2024-06-01T17:52:14.050286Z"}]}
{"channel":"book","type":"update","data":[{"symbol":"ETH/GBP","bids":[{"price":2977.56,"qty":0.00000000},{"price":2973.93,"qty":0.27474654}],"asks":[],"checksum":4048947310,"timestamp":"2024-06-01T17:52:14.050460Z"}]}
{"channel":"book","type":"update","data":[{"symbol":"ETH/GBP","bids":[],"asks":[{"price":2979.01,"qty":0.00000000},{"price":2980.82,"qty":1.00000000}],"checksum":1374168334,"timestamp":"2024-06-01T17:52:14.053405Z"}]}
{"channel":"book","type":"update","data":[{"symbol":"ETH/GBP","bids":[{"price":2977.64,"qty":0.00000000},{"price":2973.19,"qty":0.14113766}],"asks":[],"checksum":1243719146,"timestamp":"2024-06-01T17:52:14.053556Z"}]}
{"channel":"book","type":"update","data":[{"symbol":"ETH/GBP","bids":[{"price":2977.42,"qty":0.31000000}],"asks":[],"checksum":1375088837,"timestamp":"2024-06-01T17:52:14.053656Z"}]}
{"channel":"book","type":"update","data":[{"symbol":"ETH/GBP","bids":[],"asks":[{"price":2978.59,"qty":0.31000000}],"checksum":2510257524,"timestamp":"2024-06-01T17:52:14.053691Z"}]}
{"channel":"book","type":"update","data":[{"symbol":"ETH/GBP","bids":[{"price":2977.63,"qty":13.17399031}],"asks":[],"checksum":3727200785,"timestamp":"2024-06-01T17:52:14.055734Z"}]}
{"channel":"book","type":"update","data":[{"symbol":"ETH/GBP","bids":[{"price":2977.42,"qty":0.00000000},{"price":2973.93,"qty":0.27474654}],"asks":[],"checksum":1784635217,"timestamp":"2024-06-01T17:52:14.058463Z"}]}
{"channel":"book","type":"update","data":[{"symbol":"ETH/GBP","bids":[{"price":2977.71,"qty":0.31000000}],"asks":[],"checksum":1910997653,"timestamp":"2024-06-01T17:52:14.058585Z"}]}
{"channel":"book","type":"update","data":[{"symbol":"ETH/GBP","bids":[],"asks":[{"price":2978.68,"qty":0.00000000},{"price":2980.82,"qty":1.00000000}],"checksum":469421752,"timestamp":"2024-06-01T17:52:14.116670Z"}]}
{"channel":"book","type":"update","data":[{"symbol":"ETH/GBP","bids":[],"asks":[{"price":2978.59,"qty":0.00000000},{"price":2980.92,"qty":0.20717085}],"checksum":2229718584,"timestamp":"2024-06-01T17:52:14.119327Z"}]}
{"channel":"book","type":"update","data":[{"symbol":"ETH/GBP","bids":[],"asks":[{"price":2978.31,"qty":6.58550309}],"checksum":2803871856,"timestamp":"2024-06-01T17:52:14.124055Z"}]}
{"channel":"book","type":"update","data":[{"symbol":"ETH/GBP","bids":[{"price":2978.08,"qty":6.58600132}],"asks":[],"checksum":2076023633,"timestamp":"2024-06-01T17:52:14.124279Z"}]}
{"channel":"book","type":"update","data":[{"symbol":"ETH/GBP","bids":[],"asks":[{"price":2978.31,"qty":0.00000000},{"price":2980.92,"qty":0.20717085}],"checksum":1480910105,"timestamp":"2024-06-01T17:52:14.135426Z"}]}
{"channel":"book","type":"update","data":[{"symbol":"ETH/GBP","bids":[{"price":2978.08,"qty":0.00000000},{"price":2974.40,"qty":1.31882650}],"asks":[],"checksum":2229718584,"timestamp":"2024-06-01T17:52:14.155815Z"}]}
{"channel":"book","type":"update","data":[{"symbol":"ETH/GBP","bids":[],"asks":[{"price":2979.09,"qty":0.00000000},{"price":2980.93,"qty":0.27473522}],"checksum":3830206184,"timestamp":"2024-06-01T17:52:14.190307Z"}]}
{"channel":"book","type":"update","data":[{"symbol":"ETH/GBP","bids":[],"asks":[{"price":2978.74,"qty":13.16910326}],"checksum":4252333418,"timestamp":"2024-06-01T17:52:14.233776Z"}]}
{"channel":"book","type":"update","data":[{"symbol":"ETH/GBP","bids":[],"asks":[{"price":2978.31,"qty":6.58549539}],"checksum":1398909249,"timestamp":"2024-06-01T17:52:14.233819Z"}]}
{"channel":"book","type":"update","data":[{"symbol":"ETH/GBP","bids":[{"price":2978.07,"qty":6.58600575}],"asks":[],"checksum":1258167589,"timestamp":"2024-06-01T17:52:14.233856Z"}]}
{"channel":"book","type":"update","data":[{"symbol":"ETH/GBP","bids":[],"asks":[{"price":2978.31,"qty":0.00000000},{"price":2980.92,"qty":0.20717085}],"checksum":3840590094,"timestamp":"2024-06-01T17:52:14.314221Z"}]}
{"channel":"book","type":"update","data":[{"symbol":"ETH/GBP","bids":[{"price":2978.07,"qty":0.00000000},{"price":2974.40,"qty":1.31882650}],"asks":[],"checksum":4252333418,"timestamp":"2024-06-01T17:52:14.347469Z"}]}
{"channel":"book","type":"update","data":[{"symbol":"ETH/GBP","bids":[{"price":2978.05,"qty":6.58605120}],"asks":[],"checksum":562098946,"timestamp":"2024-06-01T17:52:14.351923Z"}]}
{"channel":"book","type":"update","data":[{"symbol":"ETH/GBP","bids":[],"asks":[{"price":2978.29,"qty":6.58554083}],"checksum":4062989938,"timestamp":"2024-06-01T17:52:14.352129Z"}]}
{"channel":"book","type":"update","data":[{"symbol":"ETH/GBP","bids":[{"price":2978.05,"qty":0.00000000},{"price":2974.40,"qty":1.31882650}],"asks":[],"checksum":786024474,"timestamp":"2024-06-01T17:52:14.357338Z"}]}
{"channel":"book","type":"update","data":[{"symbol":"ETH/GBP","bids":[],"asks":[{"price":2978.29,"qty":0.00000000},{"price":2980.92,"qty":0.20717085}],"checksum":4252333418,"timestamp":"2024-06-01T17:52:14.357411Z"}]}
{"channel":"book","type":"update","data":[{"symbol":"ETH/GBP","bids":[],"asks":[{"price":2978.31,"qty":6.58551251}],"checksum":1778120635,"timestamp":"2024-06-01T17:52:14.474767Z"}]}
{"channel":"book","type":"update","data":[{"symbol":"ETH/GBP","bids":[{"price":2978.01,"qty":6.58615768}],"asks":[],"checksum":1698780153,"timestamp":"2024-06-01T17:52:14.474854Z"}]}
{"channel":"book","type":"update","data":[{"symbol":"ETH/GBP","bids":[{"price":2978.01,"qty":0.00000000},{"price":2974.40,"qty":1.31882650}],"asks":[],"checksum":1778120635,"timestamp":"2024-06-01T17:52:14.480653Z"}]}
{"channel":"book","type":"update","data":[{"symbol":"ETH/GBP","bids":[],"asks":[{"price":2978.31,"qty":0.00000000},{"price":2980.92,"qty":0.20717085}],"checksum":4252333418,"timestamp":"2024-06-01T17:52:14.495001Z"}]}
{"channel":"book","type":"update","data":[{"symbol":"ETH/GBP","bids":[],"asks":[{"price":2979.86,"qty":0.00000000},{"price":2980.93,"qty":0.27473522}],"checksum":439821259,"timestamp":"2024-06-01T17:52:14.645034Z"}]}
{"channel":"book","type":"update","data":[{"symbol":"ETH/GBP","bids":[],"asks":[{"price":2978.60,"qty":0.00000000},{"price":2980.95,"qty":0.22400000}],"checksum":1870049709,"timestamp":"2024-06-01T17:52:14.645051Z"}]}
{"channel":"book","type":"update","data":[{"symbol":"ETH/GBP","bids":[],"asks":[{"price":2978.74,"qty":0.00000000},{"price":2981.04,"qty":0.94850883}],"checksum":1001080479,"timestamp":"2024-06-01T17:52:14.650351Z"}]}
{"channel":"book","type":"update","data":[{"symbol":"ETH/GBP","bids":[],"asks":[{"price":2978.30,"qty":3.12768616}],"checksum":3889665330,"timestamp":"2024-06-01T17:52:14.650467Z"}]}
{"channel":"book","type":"update","data":[{"symbol":"ETH/GBP","bids":[],"asks":[{"price":2979.86,"qty":18.68053932}],"checksum":433076645,"timestamp":"2024-06-01T17:52:14.650702Z"}]}
{"channel":"book","type":"update","data":[{"symbol":"ETH/GBP","bids":[],"asks":[{"price":2979.47,"qty":0.31000000}],"checksum":3546975989,"timestamp":"2024-06-01T17:52:14.653434Z"}]}
{"channel":"book","type":"update","data":[{"symbol":"ETH/GBP","bids":[],"asks":[{"price":2978.73,"qty":6.58456571}],"checksum":3885255344,"timestamp":"2024-06-01T17:52:14.655153Z"}]}
{"channel":"book","type":"update","data":[{"symbol":"ETH/GBP","bids":[{"price":2978.07,"qty":6.58600773}],"asks":[],"checksum":2174388637,"timestamp":"2024-06-01T17:52:14.655258Z"}]}
{"channel":"book","type":"update","data":[{"symbol":"ETH/GBP","bids":[],"asks":[{"price":2978.73,"qty":19.75369714}],"checksum":2262967200,"timestamp":"2024-06-01T17:52:14.655340Z"}]}
{"channel":"book","type":"update","data":[{"symbol":"ETH/GBP","bids":[],"asks":[{"price":2978.73,"qty":6.58456571}],"checksum":2174388637,"timestamp":"2024-06-01T17:52:14.659902Z"}]}
{"channel":"book","type":"update","data":[{"symbol":"ETH/GBP","bids":[{"price":2978.07,"qty":0.00000000},{"price":2974.40,"qty":1.31882650}],"asks":[],"checksum":3885255344,"timestamp":"2024-06-01T17:52:14.670985Z"}]}
{"channel":"book","type":"update","data":[{"symbol":"ETH/GBP","bids":[{"price":2978.01,"qty":6.58615768}],"asks":[],"checksum":3945721586,"timestamp":"2024-06-01T17:52:14.781110Z"}]}
{"channel":"book","type":"update","data":[{"symbol":"ETH/GBP","bids":[],"asks":[{"price":2978.32,"qty":6.58547827}],"checksum":2486306001,"timestamp":"2024-06-01T17:52:14.781210Z"}]}
{"channel":"book","type":"update","data":[{"symbol":"ETH/GBP","bids":[{"price":2978.01,"qty":0.00000000},{"price":2974.40,"qty":1.31882650}],"asks":[],"checksum":2559090835,"timestamp":"2024-06-01T17:52:14.786125Z"}]}
{"channel":"book","type":"update","data":[{"symbol":"ETH/GBP","bids":[],"asks":[{"price":2978.32,"qty":0.00000000},{"price":2980.82,"qty":1.00000000}],"checksum":3885255344,"timestamp":"2024-06-01T17:52:14.786212Z"}]}
{"channel":"book","type":"update","data":[{"symbol":"ETH/GBP","bids":[],"asks":[{"price":2978.31,"qty":6.58550536}],"checksum":4099338018,"timestamp":"2024-06-01T17:52:14.904810Z"}]}
{"channel":"book","type":"update","data":[{"symbol":"ETH/GBP","bids":[{"price":2978.07,"qty":6.58601291}],"asks":[],"checksum":3361030902,"timestamp":"2024-06-01T17:52:14.904941Z"}]}
{"channel":"book","type":"update","data":[{"symbol":"ETH/GBP","bids":[],"asks":[{"price":2978.31,"qty":0.00000000},{"price":2980.82,"qty":1.00000000}],"checksum":3684165476,"timestamp":"2024-06-01T17:52:14.909495Z"}]}
{"channel":"book","type":"update","data":[{"symbol":"ETH/GBP","bids":[{"price":2978.07,"qty":0.00000000},{"price":2974.40,"qty":1.31882650}],"asks":[],"checksum":3885255344,"timestamp":"2024-06-01T17:52:14.909584Z"}]}
{"channel":"book","type":"update","data":[{"symbol":"ETH/GBP","bids":[],"asks":[{"price":2978.30,"qty":9.71322107}],"checksum":1078877102,"timestamp":"2024-06-01T17:52:15.106482Z"}]}
{"channel":"book","type":"update","data":[{"symbol":"ETH/GBP","bids":[{"price":2978.01,"qty":6.58615768}],"asks":[],"checksum":1291124716,"timestamp":"2024-06-01T17:52:15.106558Z"}]}
{"channel":"book","type":"update","data":[{"symbol":"ETH/GBP","bids":[{"price":2978.01,"qty":0.00000000},{"price":2974.40,"qty":1.31882650}],"asks":[],"checksum":1078877102,"timestamp":"2024-06-01T17:52:15.111199Z"}]}
{"channel":"book","type":"update","data":[{"symbol":"ETH/GBP","bids":[],"asks":[{"price":2978.30,"qty":3.12768616}],"checksum":3885255344,"timestamp":"2024-06-01T17:52:15.145948Z"}]}
{"channel":"book","type":"update","data":[{"symbol":"ETH/GBP","bids":[],"asks":[{"price":2978.33,"qty":6.58545281}],"checksum":540009108,"timestamp":"2024-06-01T17:52:15.361665Z"}]}
{"channel":"book","type":"update","data":[{"symbol":"ETH/GBP","bids":[{"price":2978.09,"qty":6.58597947}],"asks":[],"checksum":4135092770,"timestamp":"2024-06-01T17:52:15.361772Z"}]}
{"channel":"book","type":"update","data":[{"symbol":"ETH/GBP","bids":[{"price":2977.63,"qty":0.00000000},{"price":2974.40,"qty":1.31882650}],"asks":[],"checksum":1515491767,"timestamp":"2024-06-01T17:52:15.363378Z"}]}
{"channel":"book","type":"update","data":[{"symbol":"ETH/GBP","bids":[{"price":2976.70,"qty":0.00000000},{"price":2973.93,"qty":0.27474654}],"asks":[],"checksum":2370562355,"timestamp":"2024-06-01T17:52:15.363398Z"}]}
{"channel":"book","type":"update","data":[{"symbol":"ETH/GBP","bids":[],"asks":[{"price":2978.73,"qty":0.00000000},{"price":2980.82,"qty":1.00000000}],"checksum":4009192602,"timestamp":"2024-06-01T17:52:15.363416Z"}]}
{"channel":"book","type":"update","data":[{"symbol":"ETH/GBP","bids":[{"price":2977.71,"qty":0.00000000},{"price":2973.19,"qty":0.14113766}],"asks":[],"checksum":1608259314,"timestamp":"2024-06-01T17:52:15.366853Z"}]}
{"channel":"book","type":"update","data":[{"symbol":"ETH/GBP","bids":[{"price":2978.09,"qty":0.00000000},{"price":2973.18,"qty":0.27800000}],"asks":[],"checksum":1711198430,"timestamp":"2024-06-01T17:52:15.367620Z"}]}
{"channel":"book","type":"update","data":[{"symbol":"ETH/GBP","bids":[],"asks":[{"price":2978.33,"qty":0.00000000},{"price":2980.92,"qty":0.20717085}],"checksum":2948437669,"timestamp":"2024-06-01T17:52:15.367709Z"}]}
{"channel":"book","type":"update","data":[{"symbol":"ETH/GBP","bids":[{"price":2977.42,"qty":0.31000000}],"asks":[],"checksum":1345209899,"timestamp":"2024-06-01T17:52:15.371028Z"}]}
{"channel":"book","type":"update","data":[{"symbol":"ETH/GBP","bids":[],"asks":[{"price":2978.91,"qty":13.16834309}],"checksum":3072394239,"timestamp":"2024-06-01T17:52:15.374505Z"}]}
{"channel":"book","type":"update","data":[{"symbol":"ETH/GBP","bids":[{"price":2977.79,"qty":13.17326992}],"asks":[],"checksum":2367048204,"timestamp":"2024-06-01T17:52:15.374712Z"}]}
{"channel":"book","type":"update","data":[{"symbol":"ETH/GBP","bids":[{"price":2976.94,"qty":1.31770078}],"asks":[],"checksum":286708843,"timestamp":"2024-06-01T17:52:15.374783Z"}]}
{"channel":"book","type":"update","data":[{"symbol":"ETH/GBP","bids":[],"asks":[{"price":2979.55,"qty":0.00000000},{"price":2980.92,"qty":0.20717085}],"checksum":3528689275,"timestamp":"2024-06-01T17:52:15.376083Z"}]}
{"channel":"book","type":"update","data":[{"symbol":"ETH/GBP","bids":[{"price":2977.42,"qty":0.00000000},{"price":2973.93,"qty":0.27474654}],"asks":[],"checksum":2028067317,"timestamp":"2024-06-01T17:52:15.378141Z"}]}
{"channel":"book","type":"update","data":[{"symbol":"ETH/GBP","bids":[{"price":2977.85,"qty":0.31000000}],"asks":[],"checksum":1660921725,"timestamp":"2024-06-01T17:52:15.378961Z"}]}
{"channel":"book","type":"update","data":[{"symbol":"ETH/GBP","bids":[],"asks":[{"price":2979.47,"qty":0.00000000},{"price":2980.93,"qty":0.27473522}],"checksum":4095551342,"timestamp":"2024-06-01T17:52:15.379303Z"}]}
{"channel":"book","type":"update","data":[{"symbol":"ETH/GBP","bids":[],"asks":[{"price":2978.91,"qty":0.00000000},{"price":2980.95,"qty":0.22400000}],"checksum":1878327153,"timestamp":"2024-06-01T17:52:15.383501Z"}]}
{"channel":"book","type":"update","data":[{"symbol":"ETH/GBP","bids":[{"price":2977.79,"qty":0.00000000},{"price":2973.93,"qty":0.27474654}],"asks":[],"checksum":3472194333,"timestamp":"2024-06-01T17:52:15.383759Z"}]}
{"channel":"book","type":"update","data":[{"symbol":"ETH/GBP","bids":[{"price":2976.94,"qty":0.00000000},{"price":2973.19,"qty":0.14113766}],"asks":[],"checksum":1424981425,"timestamp":"2024-06-01T17:52:15.386750Z"}]}
{"channel":"book","type":"update","data":[{"symbol":"ETH/GBP","bids":[{"price":2974.40,"qty":0.00000000},{"price":2973.18,"qty":0.27800000}],"asks":[],"checksum":2552918989,"timestamp":"2024-06-01T17:52:15.386770Z"}]}
{"channel":"book","type":"update","data":[{"symbol":"ETH/GBP","bids":[{"price":2977.85,"qty":0.00000000},{"price":2972.46,"qty":0.34530000}],"asks":[],"checksum":2739795201,"timestamp":"2024-06-01T17:52:15.387838Z"}]}
{"channel":"book","type":"update","data":[{"symbol":"ETH/GBP","bids":[{"price":2977.42,"qty":0.31000000}],"asks":[],"checksum":3621034990,"timestamp":"2024-06-01T17:52:15.389202Z"}]}
{"channel":"book","type":"update","data":[{"symbol":"ETH/GBP","bids":[],"asks":[{"price":2979.81,"qty":1.31643750}],"checksum":2361898079,"timestamp":"2024-06-01T17:52:15.394183Z"}]}
{"channel":"book","type":"update","data":[{"symbol":"ETH/GBP","bids":[{"price":2975.83,"qty":1.31819587}],"asks":[],"checksum":3502895272,"timestamp":"2024-06-01T17:52:15.394286Z"}]}
{"channel":"book","type":"update","data":[{"symbol":"ETH/GBP","bids":[],"asks":[{"price":2979.87,"qty":0.00000000},{"price":2980.95,"qty":0.22400000}],"checksum":2250952923,"timestamp":"2024-06-01T17:52:15.408121Z"}]}
{"channel":"book","type":"update","data":[{"symbol":"ETH/GBP","bids":[],"asks":[{"price":2980.11,"qty":5.74014515}],"checksum":2773019529,"timestamp":"2024-06-01T17:52:15.411874Z"}]}
{"channel":"book","type":"update","data":[{"symbol":"ETH/GBP","bids":[],"asks":[{"price":2978.69,"qty":6.58465586}],"checksum":1146889947,"timestamp":"2024-06-01T17:52:15.481783Z"}]}
{"channel":"book","type":"update","data":[{"symbol":"ETH/GBP","bids":[{"price":2978.29,"qty":6.58553849}],"asks":[],"checksum":1201987240,"timestamp":"2024-06-01T17:52:15.481803Z"}]}
{"channel":"book","type":"update","data":[{"symbol":"ETH/GBP","bids":[],"asks":[{"price":2978.80,"qty":0.00000000},{"price":2980.93,"qty":0.27473522},{"price":2979.20,"qty":0.06971900}],"checksum":3268788116,"timestamp":"2024-06-01T17:52:15.513683Z"}]}
{"channel":"book","type":"update","data":[{"symbol":"ETH/GBP","bids":[],"asks":[{"price":2978.30,"qty":0.00000000},{"price":2980.93,"qty":0.27473522}],"checksum":3215705163,"timestamp":"2024-06-01T17:52:15.516286Z"}]}
{"channel":"book","type":"update","data":[{"symbol":"ETH/GBP","bids":[{"price":2978.29,"qty":0.00000000},{"price":2973.19,"qty":0.14113766}],"asks":[],"checksum":703114246,"timestamp":"2024-06-01T17:52:15.521037Z"}]}
{"channel":"book","type":"update","data":[{"symbol":"ETH/GBP","bids":[],"asks":[{"price":2978.69,"qty":0.00000000},{"price":2980.95,"qty":0.22400000}],"checksum":1816024849,"timestamp":"2024-06-01T17:52:15.534315Z"}]}
{"channel":"book","type":"update","data":[{"symbol":"ETH/GBP","bids":[],"asks":[{"price":2979.12,"qty":0.31000000}],"checksum":1203363187,"timestamp":"2024-06-01T17:52:15.537005Z"}]}
{"channel":"book","type":"update","data":[{"symbol":"ETH/GBP","bids":[],"asks":[{"price":2979.11,"qty":13.16745695}],"checksum":2944172533,"timestamp":"2024-06-01T17:52:15.579482Z"}]}
{"channel":"book","type":"update","data":[{"symbol":"ETH/GBP","bids":[{"price":2978.01,"qty":13.17231536}],"asks":[],"checksum":1011546156,"timestamp":"2024-06-01T17:52:15.579702Z"}]}
{"channel":"book","type":"update","data":[{"symbol":"ETH/GBP","bids":[],"asks":[{"price":2979.12,"qty":0.00000000},{"price":2980.93,"qty":0.27473522}],"checksum":2292289703,"timestamp":"2024-06-01T17:52:15.581971Z"}]}
{"channel":"book","type":"update","data":[{"symbol":"ETH/GBP","bids":[],"asks":[{"price":2979.05,"qty":0.31000000}],"checksum":3821157212,"timestamp":"2024-06-01T17:52:15.582477Z"}]}
{"channel":"book","type":"update","data":[{"symbol":"ETH/GBP","bids":[{"price":2977.42,"qty":0.00000000},{"price":2973.19,"qty":0.14113766}],"asks":[],"checksum":3245776335,"timestamp":"2024-06-01T17:52:15.582489Z"}]}
{"channel":"book","type":"update","data":[{"symbol":"ETH/GBP","bids":[{"price":2978.09,"qty":0.31000000}],"asks":[],"checksum":3136506808,"timestamp":"2024-06-01T17:52:15.582522Z"}]}
{"channel":"book","type":"update","data":[{"symbol":"ETH/GBP","bids":[{"price":2978.01,"qty":0.00000000},{"price":2973.19,"qty":0.14113766}],"asks":[],"checksum":2006487138,"timestamp":"2024-06-01T17:52:15.584931Z"}]}
{"channel":"book","type":"update","data":[{"symbol":"ETH/GBP","bids":[],"asks":[{"price":2978.71,"qty":6.58462817}],"checksum":1118255295,"timestamp":"2024-06-01T17:52:15.589197Z"}]}
{"channel":"book","type":"update","data":[{"symbol":"ETH/GBP","bids":[{"price":2978.49,"qty":6.58509383}],"asks":[],"checksum":3233771788,"timestamp":"2024-06-01T17:52:15.589330Z"}]}
{"channel":"book","type":"update","data":[{"symbol":"ETH/GBP","bids":[{"price":2978.09,"qty":0.00000000},{"price":2973.19,"qty":0.14113766}],"asks":[],"checksum":416672405,"timestamp":"2024-06-01T17:52:15.592105Z"}]}
{"channel":"book","type":"update","data":[{"symbol":"ETH/GBP","bids":[{"price":2977.42,"qty":0.31000000}],"asks":[],"checksum":979454982,"timestamp":"2024-06-01T17:52:15.592153Z"}]}
{"channel":"book","type":"update","data":[{"symbol":"ETH/GBP","bids":[{"price":2978.00,"qty":0.00000000},{"price":2973.19,"qty":0.14113766},{"price":2978.30,"qty":0.08558500}],"asks":[],"checksum":3464937387,"timestamp":"2024-06-01T17:52:15.696722Z"}]}
{"channel":"book","type":"update","data":[{"symbol":"ETH/GBP","bids":[{"price":2975.62,"qty":0.21200000}],"asks":[],"checksum":2128359160,"timestamp":"2024-06-01T17:52:15.705367Z"}]}
{"channel":"book","type":"update","data":[{"symbol":"ETH/GBP","bids":[],"asks":[{"price":2978.71,"qty":0.00000000},{"price":2980.92,"qty":0.20717085}],"checksum":2257305401,"timestamp":"2024-06-01T17:52:15.717151Z"}]}
{"channel":"book","type":"update","data":[{"symbol":"ETH/GBP","bids":[],"asks":[{"price":2978.70,"qty":6.58463583}],"checksum":510902251,"timestamp":"2024-06-01T17:52:15.722503Z"}]}
{"channel":"book","type":"update","data":[{"symbol":"ETH/GBP","bids":[{"price":2978.49,"qty":0.00000000},{"price":2973.93,"qty":0.27474654}],"asks":[],"checksum":4008114115,"timestamp":"2024-06-01T17:52:15.737223Z"}]}
{"channel":"book","type":"update","data":[{"symbol":"ETH/GBP","bids":[{"price":2978.47,"qty":6.58512916}],"asks":[],"checksum":715609459,"timestamp":"2024-06-01T17:52:15.742962Z"}]}
{"channel":"book","type":"update","data":[{"symbol":"ETH/GBP","bids":[],"asks":[{"price":2978.70,"qty":0.00000000},{"price":2980.92,"qty":0.20717085}],"checksum":2992592289,"timestamp":"2024-06-01T17:52:15.743068Z"}]}
{"channel":"book","type":"update","data":[{"symbol":"ETH/GBP","bids":[{"price":2978.47,"qty":0.00000000},{"price":2973.93,"qty":0.27474654}],"asks":[],"checksum":3301349761,"timestamp":"2024-06-01T17:52:15.747889Z"}]}
{"channel":"book","type":"update","data":[{"symbol":"ETH/GBP","bids":[{"price":2978.02,"qty":13.17226671}],"asks":[],"checksum":3498070277,"timestamp":"2024-06-01T17:52:15.794224Z"}]}
{"channel":"book","type":"update","data":[{"symbol":"ETH/GBP","bids":[{"price":2977.42,"qty":0.00000000},{"price":2973.93,"qty":0.27474654}],"asks":[],"checksum":3860712771,"timestamp":"2024-06-01T17:52:15.796757Z"}]}
{"channel":"book","type":"update","data":[{"symbol":"ETH/GBP","bids":[{"price":2978.10,"qty":0.31000000}],"asks":[],"checksum":1620292572,"timestamp":"2024-06-01T17:52:15.797653Z"}]}
{"channel":"book","type":"update","data":[{"symbol":"ETH/GBP","bids":[],"asks":[{"price":2979.04,"qty":6.58388052}],"checksum":1866118739,"timestamp":"2024-06-01T17:52:15.837815Z"}]}
{"channel":"book","type":"update","data":[{"symbol":"ETH/GBP","bids":[],"asks":[{"price":2979.04,"qty":0.00000000},{"price":2980.92,"qty":0.20717085}],"checksum":1620292572,"timestamp":"2024-06-01T17:52:15.842583Z"}]}
{"channel":"book","type":"update","data":[{"symbol":"ETH/GBP","bids":[{"price":2978.46,"qty":6.58515682}],"asks":[],"checksum":1912431510,"timestamp":"2024-06-01T17:52:15.847235Z"}]}
{"channel":"book","type":"update","data":[{"symbol":"ETH/GBP","bids":[{"price":2978.46,"qty":0.00000000},{"price":2974.50,"qty":0.27200000}],"asks":[],"checksum":1620292572,"timestamp":"2024-06-01T17:52:15.851702Z"}]}
{"channel":"book","type":"update","data":[{"symbol":"ETH/GBP","bids":[{"price":2978.47,"qty":6.58511994}],"asks":[],"checksum":2786366,"timestamp":"2024-06-01T17:52:16.013368Z"}]}
{"channel":"book","type":"update","data":[{"symbol":"ETH/GBP","bids":[],"asks":[{"price":2978.71,"qty":6.58461238}],"checksum":2387020697,"timestamp":"2024-06-01T17:52:16.013566Z"}]}
{"channel":"book","type":"update","data":[{"symbol":"ETH/GBP","bids":[],"asks":[{"price":2978.71,"qty":0.00000000},{"price":2980.92,"qty":0.20717085}],"checksum":2786366,"timestamp":"2024-06-01T17:52:16.175578Z"}]}
{"channel":"book","type":"update","data":[{"symbol":"ETH/GBP","bids":[],"asks":[{"price":2979.05,"qty":0.00000000},{"price":2980.93,"qty":0.27473522}],"checksum":707709953,"timestamp":"2024-06-01T17:52:16.178204Z"}]}
{"channel":"book","type":"update","data":[{"symbol":"ETH/GBP","bids":[],"asks":[{"price":2978.70,"qty":6.58464531}],"checksum":2416116527,"timestamp":"2024-06-01T17:52:16.181527Z"}]}
{"channel":"book","type":"update","data":[{"symbol":"ETH/GBP","bids":[],"asks":[{"price":2978.70,"qty":0.00000000},{"price":2980.93,"qty":0.27473522}],"checksum":707709953,"timestamp":"2024-06-01T17:52:16.236107Z"}]}
{"channel":"book","type":"update","data":[{"symbol":"ETH/GBP","bids":[],"asks":[{"price":2978.69,"qty":6.58465782}],"checksum":2494355604,"timestamp":"2024-06-01T17:52:16.285821Z"}]}
{"channel":"book","type":"update","data":[{"symbol":"ETH/GBP","bids":[],"asks":[{"price":2978.69,"qty":0.00000000},{"price":2980.93,"qty":0.27473522}],"checksum":707709953,"timestamp":"2024-06-01T17:52:16.371778Z"}]}
{"channel":"book","type":"update","data":[{"symbol":"ETH/GBP","bids":[{"price":2978.47,"qty":0.00000000},{"price":2974.50,"qty":0.27200000}],"asks":[],"checksum":200284199,"timestamp":"2024-06-01T17:52:16.371960Z"}]}
