{"channel":"book","type":"snapshot","data":[{"symbol":"ETH/JPY","bids":[{"price":595175,"qty":0.20904656},{"price":595174,"qty":0.25315739},{"price":595172,"qty":3.91411465},{"price":595171,"qty":0.97883433},{"price":595089,"qty":0.00312806},{"price":594901,"qty":4.10464164},{"price":594809,"qty":21.56993727},{"price":594026,"qty":7.38926496},{"price":594023,"qty":21.57720109},{"price":593794,"qty":20.30632296}],"asks":[{"price":597785,"qty":0.18037684},{"price":598130,"qty":0.00360488},{"price":598714,"qty":0.00737190},{"price":598715,"qty":0.20717085},{"price":598718,"qty":4.10464164},{"price":599604,"qty":3.77368091},{"price":599605,"qty":0.02861615},{"price":599616,"qty":7.38926496},{"price":599916,"qty":20.30632296},{"price":600308,"qty":21.60207835}],"checksum":1770341203}]}
{"channel":"book","type":"update","data":[{"symbol":"ETH/JPY","bids":[{"price":594026,"qty":0.00000000},{"price":591104,"qty":10.17338388}],"asks":[],"checksum":1999423743,"timestamp":"2024-06-01T17:51:42.363391Z"}]}
{"channel":"book","type":"update","data":[{"symbol":"ETH/JPY","bids":[{"price":591112,"qty":15.24971184}],"asks":[],"checksum":3538764939,"timestamp":"2024-06-01T17:51:42.365927Z"}]}
{"channel":"book","type":"update","data":[{"symbol":"ETH/JPY","bids":[{"price":594027,"qty":7.38926496}],"asks":[],"checksum":3367815101,"timestamp":"2024-06-01T17:51:42.366253Z"}]}
{"channel":"book","type":"update","data":[{"symbol":"ETH/JPY","bids":[{"price":595174,"qty":0.00000000},{"price":591112,"qty":15.24971184}],"asks":[],"checksum":4292225447,"timestamp":"2024-06-01T17:51:42.396784Z"}]}
{"channel":"book","type":"update","data":[{"symbol":"ETH/JPY","bids":[{"price":595176,"qty":0.25315750}],"asks":[],"checksum":3023519810,"timestamp":"2024-06-01T17:51:42.427799Z"}]}
{"channel":"book","type":"update","data":[{"symbol":"ETH/JPY","bids":[{"price":595175,"qty":0.00000000},{"price":591112,"qty":15.24971184}],"asks":[],"checksum":4261976944,"timestamp":"2024-06-01T17:51:42.447289Z"}]}
{"channel":"book","type":"update","data":[{"symbol":"ETH/JPY","bids":[{"price":595177,"qty":0.20904586}],"asks":[],"checksum":3666503375,"timestamp":"2024-06-01T17:51:42.447367Z"}]}
{"channel":"book","type":"update","data":[{"symbol":"ETH/JPY","bids":[{"price":595171,"qty":0.00000000},{"price":591112,"qty":15.24971184}],"asks":[],"checksum":369003696,"timestamp":"2024-06-01T17:51:42.953550Z"}]}
{"channel":"book","type":"update","data":[{"symbol":"ETH/JPY","bids":[{"price":595177,"qty":1.18798237}],"asks":[],"checksum":3856550216,"timestamp":"2024-06-01T17:51:42.993790Z"}]}
{"channel":"book","type":"update","data":[{"symbol":"ETH/JPY","bids":[{"price":595172,"qty":0.00000000},{"price":591104,"qty":10.17338388},{"price":595178,"qty":3.88601587}],"asks":[],"checksum":2356812026,"timestamp":"2024-06-01T17:51:43.038834Z"}]}
{"channel":"book","type":"update","data":[{"symbol":"ETH/JPY","bids":[{"price":595177,"qty":0.97893651}],"asks":[],"checksum":1495874228,"timestamp":"2024-06-01T17:51:43.054698Z"}]}
{"channel":"book","type":"update","data":[{"symbol":"ETH/JPY","bids":[{"price":595179,"qty":0.20904516}],"asks":[],"checksum":3217816394,"timestamp":"2024-06-01T17:51:43.054889Z"}]}
{"channel":"book","type":"update","data":[{"symbol":"ETH/JPY","bids":[],"asks":[{"price":599605,"qty":0.00000000},{"price":608675,"qty":0.51500211},{"price":599603,"qty":0.02861625}],"checksum":4209980007,"timestamp":"2024-06-01T17:51:44.098730Z"}]}
{"channel":"book","type":"update","data":[{"symbol":"ETH/JPY","bids":[],"asks":[{"price":599604,"qty":0.00000000},{"price":608675,"qty":0.51500211},{"price":599602,"qty":3.77900394}],"checksum":8852161,"timestamp":"2024-06-01T17:51:44.162521Z"}]}
{"channel":"book","type":"update","data":[{"symbol":"ETH/JPY","bids":[{"price":595176,"qty":0.00000000},{"price":591112,"qty":15.24971184}],"asks":[],"checksum":845555444,"timestamp":"2024-06-01T17:51:45.882280Z"}]}
{"channel":"book","type":"update","data":[{"symbol":"ETH/JPY","bids":[{"price":595180,"qty":0.25315744}],"asks":[],"checksum":863806421,"timestamp":"2024-06-01T17:51:46.282159Z"}]}
{"channel":"book","type":"update","data":[{"symbol":"ETH/JPY","bids":[{"price":595181,"qty":0.20904445}],"asks":[],"checksum":1701409190,"timestamp":"2024-06-01T17:51:46.300620Z"}]}
{"channel":"book","type":"update","data":[{"symbol":"ETH/JPY","bids":[{"price":595179,"qty":0.00000000},{"price":593794,"qty":20.30632296}],"asks":[],"checksum":1177319982,"timestamp":"2024-06-01T17:51:46.300739Z"}]}
{"channel":"book","type":"update","data":[{"symbol":"ETH/JPY","bids":[],"asks":[{"price":599603,"qty":0.00000000},{"price":608675,"qty":0.51500211},{"price":599601,"qty":0.02861634}],"checksum":2699431078,"timestamp":"2024-06-01T17:51:46.488597Z"}]}
{"channel":"book","type":"update","data":[{"symbol":"ETH/JPY","bids":[],"asks":[{"price":599602,"qty":0.00000000},{"price":608675,"qty":0.51500211},{"price":599600,"qty":3.81971256}],"checksum":4198058738,"timestamp":"2024-06-01T17:51:46.537104Z"}]}
{"channel":"book","type":"update","data":[{"symbol":"ETH/JPY","bids":[{"price":594809,"qty":0.00000000},{"price":591112,"qty":15.24971184}],"asks":[],"checksum":192441813,"timestamp":"2024-06-01T17:51:48.093209Z"}]}
{"channel":"book","type":"update","data":[{"symbol":"ETH/JPY","bids":[{"price":595177,"qty":0.00000000},{"price":591104,"qty":10.17338388}],"asks":[],"checksum":65785553,"timestamp":"2024-06-01T17:51:48.093221Z"}]}
{"channel":"book","type":"update","data":[{"symbol":"ETH/JPY","bids":[{"price":595181,"qty":1.18780918}],"asks":[],"checksum":3577325556,"timestamp":"2024-06-01T17:51:48.133421Z"}]}
{"channel":"book","type":"update","data":[{"symbol":"ETH/JPY","bids":[{"price":594949,"qty":21.56230001}],"asks":[],"checksum":2430880094,"timestamp":"2024-06-01T17:51:48.133480Z"}]}
{"channel":"book","type":"update","data":[{"symbol":"ETH/JPY","bids":[{"price":595178,"qty":0.00000000},{"price":591104,"qty":10.17338388},{"price":595182,"qty":4.00545657}],"asks":[],"checksum":1669130159,"timestamp":"2024-06-01T17:51:48.176980Z"}]}
{"channel":"book","type":"update","data":[{"symbol":"ETH/JPY","bids":[{"price":595183,"qty":0.20904375}],"asks":[],"checksum":2684795522,"timestamp":"2024-06-01T17:51:48.183844Z"}]}
{"channel":"book","type":"update","data":[{"symbol":"ETH/JPY","bids":[{"price":595181,"qty":0.97876473}],"asks":[],"checksum":731129186,"timestamp":"2024-06-01T17:51:48.183869Z"}]}
{"channel":"book","type":"update","data":[{"symbol":"ETH/JPY","bids":[{"price":594027,"qty":0.00000000},{"price":591112,"qty":15.24971184}],"asks":[],"checksum":3294798636,"timestamp":"2024-06-01T17:51:48.246507Z"}]}
{"channel":"book","type":"update","data":[{"symbol":"ETH/JPY","bids":[{"price":594901,"qty":0.00000000},{"price":591104,"qty":10.17338388}],"asks":[],"checksum":2891019262,"timestamp":"2024-06-01T17:51:48.246564Z"}]}
{"channel":"book","type":"update","data":[{"symbol":"ETH/JPY","bids":[],"asks":[{"price":598718,"qty":0.00000000},{"price":608674,"qty":0.51499705}],"checksum":291658424,"timestamp":"2024-06-01T17:51:48.246738Z"}]}
{"channel":"book","type":"update","data":[{"symbol":"ETH/JPY","bids":[{"price":591112,"qty":0.00000000},{"price":591065,"qty":0.05332854}],"asks":[],"checksum":2961587430,"timestamp":"2024-06-01T17:51:48.246819Z"}]}
{"channel":"book","type":"update","data":[{"symbol":"ETH/JPY","bids":[{"price":594028,"qty":7.38926496}],"asks":[],"checksum":124166675,"timestamp":"2024-06-01T17:51:48.249226Z"}]}
{"channel":"book","type":"update","data":[{"symbol":"ETH/JPY","bids":[],"asks":[{"price":608673,"qty":10.17338388}],"checksum":2458632752,"timestamp":"2024-06-01T17:51:48.249321Z"}]}
{"channel":"book","type":"update","data":[{"symbol":"ETH/JPY","bids":[],"asks":[{"price":608673,"qty":25.42309572}],"checksum":3713335242,"timestamp":"2024-06-01T17:51:48.249387Z"}]}
{"channel":"book","type":"update","data":[{"symbol":"ETH/JPY","bids":[{"price":591113,"qty":15.24971184}],"asks":[],"checksum":3105598590,"timestamp":"2024-06-01T17:51:48.249462Z"}]}
{"channel":"book","type":"update","data":[{"symbol":"ETH/JPY","bids":[],"asks":[{"price":608673,"qty":35.59647960}],"checksum":1489716251,"timestamp":"2024-06-01T17:51:48.249487Z"}]}
{"channel":"book","type":"update","data":[{"symbol":"ETH/JPY","bids":[{"price":595204,"qty":4.10464164}],"asks":[],"checksum":1052739668,"timestamp":"2024-06-01T17:51:48.249501Z"}]}
{"channel":"book","type":"update","data":[{"symbol":"ETH/JPY","bids":[],"asks":[{"price":598954,"qty":4.10464164}],"checksum":587879301,"timestamp":"2024-06-01T17:51:48.249873Z"}]}
{"channel":"book","type":"update","data":[{"symbol":"ETH/JPY","bids":[{"price":595205,"qty":0.20903602}],"asks":[],"checksum":128109994,"timestamp":"2024-06-01T17:51:48.258929Z"}]}
{"channel":"book","type":"update","data":[{"symbol":"ETH/JPY","bids":[{"price":595183,"qty":0.00000000},{"price":593794,"qty":20.30632296}],"asks":[],"checksum":1542729683,"timestamp":"2024-06-01T17:51:48.259029Z"}]}
{"channel":"book","type":"update","data":[{"symbol":"ETH/JPY","bids":[{"price":595182,"qty":0.00000000},{"price":591113,"qty":15.24971184},{"price":595205,"qty":4.08338815}],"asks":[],"checksum":1602301747,"timestamp":"2024-06-01T17:51:48.295433Z"}]}
{"channel":"book","type":"update","data":[{"symbol":"ETH/JPY","bids":[],"asks":[{"price":599600,"qty":0.00000000},{"price":608673,"qty":35.59647960},{"price":598953,"qty":2.17855264}],"checksum":3437864952,"timestamp":"2024-06-01T17:51:48.331442Z"}]}
{"channel":"book","type":"update","data":[{"symbol":"ETH/JPY","bids":[],"asks":[{"price":599601,"qty":0.00000000},{"price":608673,"qty":35.59647960},{"price":599615,"qty":0.02861568}],"checksum":4075563469,"timestamp":"2024-06-01T17:51:48.878662Z"}]}
{"channel":"book","type":"update","data":[{"symbol":"ETH/JPY","bids":[{"price":594028,"qty":0.00000000},{"price":591104,"qty":10.17338388}],"asks":[],"checksum":3524791399,"timestamp":"2024-06-01T17:51:49.610103Z"}]}
{"channel":"book","type":"update","data":[{"symbol":"ETH/JPY","bids":[{"price":591113,"qty":0.00000000},{"price":591065,"qty":0.05332854}],"asks":[],"checksum":3588754503,"timestamp":"2024-06-01T17:51:49.610199Z"}]}
{"channel":"book","type":"update","data":[{"symbol":"ETH/JPY","bids":[{"price":591114,"qty":15.24971184}],"asks":[],"checksum":13454049,"timestamp":"2024-06-01T17:51:49.612983Z"}]}
{"channel":"book","type":"update","data":[{"symbol":"ETH/JPY","bids":[{"price":594029,"qty":7.38926496}],"asks":[],"checksum":2433758173,"timestamp":"2024-06-01T17:51:49.613266Z"}]}
{"channel":"book","type":"update","data":[{"symbol":"ETH/JPY","bids":[{"price":595180,"qty":0.00000000},{"price":591104,"qty":10.17338388}],"asks":[],"checksum":3480406350,"timestamp":"2024-06-01T17:51:49.650737Z"}]}
{"channel":"book","type":"update","data":[{"symbol":"ETH/JPY","bids":[{"price":595181,"qty":0.00000000},{"price":591065,"qty":0.05332854}],"asks":[],"checksum":3153319514,"timestamp":"2024-06-01T17:51:52.747847Z"}]}
{"channel":"book","type":"update","data":[{"symbol":"ETH/JPY","bids":[{"price":595205,"qty":5.06184075}],"asks":[],"checksum":1870230489,"timestamp":"2024-06-01T17:51:52.793370Z"}]}
{"channel":"book","type":"update","data":[{"symbol":"ETH/JPY","bids":[{"price":595206,"qty":0.25315745}],"asks":[],"checksum":2098344712,"timestamp":"2024-06-01T17:51:52.922973Z"}]}
{"channel":"book","type":"update","data":[{"symbol":"ETH/JPY","bids":[{"price":595205,"qty":4.85280473}],"asks":[],"checksum":2986167477,"timestamp":"2024-06-01T17:51:52.932923Z"}]}
{"channel":"book","type":"update","data":[{"symbol":"ETH/JPY","bids":[{"price":595207,"qty":0.20903532}],"asks":[],"checksum":4185989924,"timestamp":"2024-06-01T17:51:52.933032Z"}]}
{"channel":"book","type":"update","data":[{"symbol":"ETH/JPY","bids":[{"price":595205,"qty":0.97845260},{"price":595208,"qty":4.00566601}],"asks":[],"checksum":3631209619,"timestamp":"2024-06-01T17:51:52.995109Z"}]}
{"channel":"book","type":"update","data":[{"symbol":"ETH/JPY","bids":[{"price":595207,"qty":0.00000000},{"price":591114,"qty":15.24971184}],"asks":[],"checksum":1761656994,"timestamp":"2024-06-01T17:51:53.019414Z"}]}
{"channel":"book","type":"update","data":[{"symbol":"ETH/JPY","bids":[{"price":595209,"qty":0.20903462}],"asks":[],"checksum":465275694,"timestamp":"2024-06-01T17:51:53.019581Z"}]}
{"channel":"book","type":"update","data":[{"symbol":"ETH/JPY","bids":[],"asks":[{"price":598130,"qty":0.00000000},{"price":608672,"qty":35.59647960}],"checksum":914724668,"timestamp":"2024-06-01T17:51:54.121754Z"}]}
{"channel":"book","type":"update","data":[{"symbol":"ETH/JPY","bids":[],"asks":[{"price":608672,"qty":20.34676776}],"checksum":33431314,"timestamp":"2024-06-01T17:51:54.130993Z"}]}
{"channel":"book","type":"update","data":[{"symbol":"ETH/JPY","bids":[{"price":594029,"qty":0.00000000},{"price":591104,"qty":10.17338388}],"asks":[],"checksum":765049118,"timestamp":"2024-06-01T17:51:54.131038Z"}]}
{"channel":"book","type":"update","data":[{"symbol":"ETH/JPY","bids":[],"asks":[{"price":608672,"qty":10.17338388}],"checksum":1601641158,"timestamp":"2024-06-01T17:51:54.131125Z"}]}
{"channel":"book","type":"update","data":[{"symbol":"ETH/JPY","bids":[],"asks":[{"price":608672,"qty":0.00000000},{"price":608674,"qty":0.51499705}],"checksum":629104503,"timestamp":"2024-06-01T17:51:54.131152Z"}]}
{"channel":"book","type":"update","data":[{"symbol":"ETH/JPY","bids":[{"price":594030,"qty":7.38926496}],"asks":[],"checksum":1704205821,"timestamp":"2024-06-01T17:51:54.133695Z"}]}
{"channel":"book","type":"update","data":[{"symbol":"ETH/JPY","bids":[],"asks":[{"price":608671,"qty":10.17338388}],"checksum":3852569354,"timestamp":"2024-06-01T17:51:54.133722Z"}]}
{"channel":"book","type":"update","data":[{"symbol":"ETH/JPY","bids":[],"asks":[{"price":608671,"qty":25.42309572}],"checksum":3849200553,"timestamp":"2024-06-01T17:51:54.133796Z"}]}
{"channel":"book","type":"update","data":[{"symbol":"ETH/JPY","bids":[],"asks":[{"price":608671,"qty":35.59647960}],"checksum":991846114,"timestamp":"2024-06-01T17:51:54.133863Z"}]}
{"channel":"book","type":"update","data":[{"symbol":"ETH/JPY","bids":[],"asks":[{"price":597946,"qty":0.00359405}],"checksum":299582222,"timestamp":"2024-06-01T17:51:54.218991Z"}]}
{"channel":"book","type":"update","data":[{"symbol":"ETH/JPY","bids":[{"price":595206,"qty":0.00000000},{"price":591115,"qty":15.24971184}],"asks":[],"checksum":900334093,"timestamp":"2024-06-01T17:51:56.154175Z"}]}
{"channel":"book","type":"update","data":[{"symbol":"ETH/JPY","bids":[{"price":595210,"qty":0.25315744}],"asks":[],"checksum":2219952805,"timestamp":"2024-06-01T17:51:56.186387Z"}]}
{"channel":"book","type":"update","data":[{"symbol":"ETH/JPY","bids":[{"price":595209,"qty":0.00000000},{"price":591115,"qty":15.24971184}],"asks":[],"checksum":1999115749,"timestamp":"2024-06-01T17:51:56.196841Z"}]}
{"channel":"book","type":"update","data":[{"symbol":"ETH/JPY","bids":[{"price":595211,"qty":0.20903392}],"asks":[],"checksum":300773051,"timestamp":"2024-06-01T17:51:56.196919Z"}]}
{"channel":"book","type":"update","data":[{"symbol":"ETH/JPY","bids":[],"asks":[{"price":598953,"qty":0.00000000},{"price":608671,"qty":35.59647960},{"price":598953,"qty":2.03842031}],"checksum":147978026,"timestamp":"2024-06-01T17:51:56.742486Z"}]}
{"channel":"book","type":"update","data":[{"symbol":"ETH/JPY","bids":[{"price":595205,"qty":0.00000000},{"price":591115,"qty":15.24971184}],"asks":[],"checksum":2912120157,"timestamp":"2024-06-01T17:51:58.142667Z"}]}
{"channel":"book","type":"update","data":[{"symbol":"ETH/JPY","bids":[{"price":595089,"qty":0.00000000},{"price":591104,"qty":10.17338388}],"asks":[],"checksum":2350656507,"timestamp":"2024-06-01T17:51:58.171385Z"}]}
{"channel":"book","type":"update","data":[{"symbol":"ETH/JPY","bids":[{"price":595211,"qty":1.18756468}],"asks":[],"checksum":2290383808,"timestamp":"2024-06-01T17:51:58.183056Z"}]}
{"channel":"book","type":"update","data":[{"symbol":"ETH/JPY","bids":[{"price":595208,"qty":0.00000000},{"price":591065,"qty":0.05332854},{"price":595212,"qty":3.88060861}],"asks":[],"checksum":2539930184,"timestamp":"2024-06-01T17:51:58.241484Z"}]}
{"channel":"book","type":"update","data":[{"symbol":"ETH/JPY","bids":[{"price":595119,"qty":0.00312048}],"asks":[],"checksum":2167120399,"timestamp":"2024-06-01T17:51:58.246600Z"}]}
{"channel":"book","type":"update","data":[{"symbol":"ETH/JPY","bids":[{"price":595211,"qty":0.97853076}],"asks":[],"checksum":1033985924,"timestamp":"2024-06-01T17:51:58.276156Z"}]}
{"channel":"book","type":"update","data":[{"symbol":"ETH/JPY","bids":[{"price":595213,"qty":0.20903322}],"asks":[],"checksum":3757998379,"timestamp":"2024-06-01T17:51:58.276196Z"}]}
{"channel":"book","type":"update","data":[{"symbol":"ETH/JPY","bids":[{"price":595210,"qty":0.00000000},{"price":591115,"qty":15.24971184}],"asks":[],"checksum":1703046000,"timestamp":"2024-06-01T17:51:59.287437Z"}]}
{"channel":"book","type":"update","data":[{"symbol":"ETH/JPY","bids":[{"price":595214,"qty":0.25315745}],"asks":[],"checksum":2166147178,"timestamp":"2024-06-01T17:51:59.322581Z"}]}
{"channel":"book","type":"update","data":[{"symbol":"ETH/JPY","bids":[{"price":595213,"qty":0.00000000},{"price":591115,"qty":15.24971184}],"asks":[],"checksum":468751525,"timestamp":"2024-06-01T17:51:59.332212Z"}]}
{"channel":"book","type":"update","data":[{"symbol":"ETH/JPY","bids":[{"price":595215,"qty":0.20903251}],"asks":[],"checksum":894312774,"timestamp":"2024-06-01T17:51:59.332397Z"}]}
{"channel":"book","type":"update","data":[{"symbol":"ETH/JPY","bids":[{"price":594030,"qty":0.00000000},{"price":591104,"qty":10.17338388}],"asks":[],"checksum":2040328015,"timestamp":"2024-06-01T17:52:00.015683Z"}]}
{"channel":"book","type":"update","data":[{"symbol":"ETH/JPY","bids":[{"price":591116,"qty":15.24971184}],"asks":[],"checksum":1820594361,"timestamp":"2024-06-01T17:52:00.018284Z"}]}
{"channel":"book","type":"update","data":[{"symbol":"ETH/JPY","bids":[{"price":594031,"qty":7.38926496}],"asks":[],"checksum":2490869160,"timestamp":"2024-06-01T17:52:00.018323Z"}]}
{"channel":"book","type":"update","data":[{"symbol":"ETH/JPY","bids":[{"price":595214,"qty":0.00000000},{"price":591116,"qty":15.24971184}],"asks":[],"checksum":1692293009,"timestamp":"2024-06-01T17:52:02.957090Z"}]}
{"channel":"book","type":"update","data":[{"symbol":"ETH/JPY","bids":[{"price":595216,"qty":0.25315748}],"asks":[],"checksum":681323199,"timestamp":"2024-06-01T17:52:02.989134Z"}]}
{"channel":"book","type":"update","data":[{"symbol":"ETH/JPY","bids":[{"price":595215,"qty":0.00000000},{"price":591116,"qty":15.24971184}],"asks":[],"checksum":1720068430,"timestamp":"2024-06-01T17:52:03.005195Z"}]}
{"channel":"book","type":"update","data":[{"symbol":"ETH/JPY","bids":[{"price":595217,"qty":0.20903181}],"asks":[],"checksum":2824123758,"timestamp":"2024-06-01T17:52:03.005269Z"}]}
{"channel":"book","type":"update","data":[{"symbol":"ETH/JPY","bids":[{"price":595211,"qty":0.00000000},{"price":591116,"qty":15.24971184}],"asks":[],"checksum":299316280,"timestamp":"2024-06-01T17:52:03.491310Z"}]}
{"channel":"book","type":"update","data":[{"symbol":"ETH/JPY","bids":[{"price":595217,"qty":1.18752795}],"asks":[],"checksum":3524578462,"timestamp":"2024-06-01T17:52:03.531487Z"}]}
{"channel":"book","type":"update","data":[{"symbol":"ETH/JPY","bids":[{"price":595212,"qty":0.00000000},{"price":591104,"qty":10.17338388},{"price":595218,"qty":3.80560843}],"asks":[],"checksum":1907542196,"timestamp":"2024-06-01T17:52:03.579802Z"}]}
{"channel":"book","type":"update","data":[{"symbol":"ETH/JPY","bids":[{"price":595219,"qty":0.20903111}],"asks":[],"checksum":1177453728,"timestamp":"2024-06-01T17:52:03.597957Z"}]}
{"channel":"book","type":"update","data":[{"symbol":"ETH/JPY","bids":[{"price":595217,"qty":0.97849614}],"asks":[],"checksum":1383499705,"timestamp":"2024-06-01T17:52:03.598135Z"}]}
{"channel":"book","type":"update","data":[{"symbol":"ETH/JPY","bids":[],"asks":[{"price":598953,"qty":0.00000000},{"price":608669,"qty":35.59647960},{"price":598953,"qty":2.03345525}],"checksum":2909565254,"timestamp":"2024-06-01T17:52:04.791380Z"}]}
{"channel":"book","type":"update","data":[{"symbol":"ETH/JPY","bids":[{"price":594031,"qty":0.00000000},{"price":591116,"qty":15.24971184}],"asks":[],"checksum":722453522,"timestamp":"2024-06-01T17:52:05.899838Z"}]}
{"channel":"book","type":"update","data":[{"symbol":"ETH/JPY","bids":[{"price":591116,"qty":0.00000000},{"price":591104,"qty":10.17338388}],"asks":[],"checksum":1041710052,"timestamp":"2024-06-01T17:52:05.899958Z"}]}
{"channel":"book","type":"update","data":[{"symbol":"ETH/JPY","bids":[{"price":594032,"qty":7.38926496}],"asks":[],"checksum":2505570869,"timestamp":"2024-06-01T17:52:05.902584Z"}]}
{"channel":"book","type":"update","data":[{"symbol":"ETH/JPY","bids":[{"price":595216,"qty":0.00000000},{"price":591117,"qty":15.24971184}],"asks":[],"checksum":5634239,"timestamp":"2024-06-01T17:52:06.849864Z"}]}
{"channel":"book","type":"update","data":[{"symbol":"ETH/JPY","bids":[{"price":595220,"qty":0.25315742}],"asks":[],"checksum":888820332,"timestamp":"2024-06-01T17:52:06.882562Z"}]}
{"channel":"book","type":"update","data":[{"symbol":"ETH/JPY","bids":[{"price":595219,"qty":0.00000000},{"price":591117,"qty":15.24971184}],"asks":[],"checksum":1131512338,"timestamp":"2024-06-01T17:52:06.890764Z"}]}
{"channel":"book","type":"update","data":[{"symbol":"ETH/JPY","bids":[{"price":595221,"qty":0.20903041}],"asks":[],"checksum":1076392903,"timestamp":"2024-06-01T17:52:06.890775Z"}]}
{"channel":"book","type":"update","data":[{"symbol":"ETH/JPY","bids":[],"asks":[{"price":598715,"qty":0.00000000},{"price":608668,"qty":35.59647960}],"checksum":685320956,"timestamp":"2024-06-01T17:52:09.121814Z"}]}
{"channel":"book","type":"update","data":[{"symbol":"ETH/JPY","bids":[],"asks":[{"price":598952,"qty":0.20717085}],"checksum":2353433796,"timestamp":"2024-06-01T17:52:09.121882Z"}]}
{"channel":"book","type":"update","data":[{"symbol":"ETH/JPY","bids":[{"price":595217,"qty":0.00000000},{"price":591117,"qty":15.24971184}],"asks":[],"checksum":450480405,"timestamp":"2024-06-01T17:52:09.886805Z"}]}
{"channel":"book","type":"update","data":[{"symbol":"ETH/JPY","bids":[{"price":595220,"qty":0.00000000},{"price":591104,"qty":10.17338388}],"asks":[],"checksum":1117060976,"timestamp":"2024-06-01T17:52:09.900628Z"}]}
{"channel":"book","type":"update","data":[{"symbol":"ETH/JPY","bids":[{"price":595221,"qty":1.18759399}],"asks":[],"checksum":1978230088,"timestamp":"2024-06-01T17:52:09.927084Z"}]}
{"channel":"book","type":"update","data":[{"symbol":"ETH/JPY","bids":[{"price":595218,"qty":0.00000000},{"price":591065,"qty":0.05332854},{"price":595222,"qty":3.68378094}],"asks":[],"checksum":2153037874,"timestamp":"2024-06-01T17:52:09.982974Z"}]}
{"channel":"book","type":"update","data":[{"symbol":"ETH/JPY","bids":[{"price":595223,"qty":0.20902970}],"asks":[],"checksum":1150143644,"timestamp":"2024-06-01T17:52:10.006752Z"}]}
{"channel":"book","type":"update","data":[{"symbol":"ETH/JPY","bids":[{"price":595221,"qty":0.97856358}],"asks":[],"checksum":385089960,"timestamp":"2024-06-01T17:52:10.006786Z"}]}
{"channel":"book","type":"update","data":[{"symbol":"ETH/JPY","bids":[{"price":595224,"qty":0.25315741}],"asks":[],"checksum":1114613241,"timestamp":"2024-06-01T17:52:10.148653Z"}]}
{"channel":"book","type":"update","data":[{"symbol":"ETH/JPY","bids":[{"price":595225,"qty":0.20902900}],"asks":[],"checksum":731316120,"timestamp":"2024-06-01T17:52:10.168497Z"}]}
{"channel":"book","type":"update","data":[{"symbol":"ETH/JPY","bids":[{"price":595223,"qty":0.00000000},{"price":593794,"qty":20.30632296}],"asks":[],"checksum":519994518,"timestamp":"2024-06-01T17:52:10.168533Z"}]}
{"channel":"book","type":"update","data":[{"symbol":"ETH/JPY","bids":[{"price":594032,"qty":0.00000000},{"price":591104,"qty":10.17338388}],"asks":[],"checksum":1900240944,"timestamp":"2024-06-01T17:52:11.784937Z"}]}
{"channel":"book","type":"update","data":[{"symbol":"ETH/JPY","bids":[{"price":591118,"qty":15.24971184}],"asks":[],"checksum":908965056,"timestamp":"2024-06-01T17:52:11.787515Z"}]}
{"channel":"book","type":"update","data":[{"symbol":"ETH/JPY","bids":[{"price":594033,"qty":7.38926496}],"asks":[],"checksum":3217553528,"timestamp":"2024-06-01T17:52:11.787670Z"}]}
{"channel":"book","type":"update","data":[{"symbol":"ETH/JPY","bids":[{"price":595224,"qty":0.00000000},{"price":591118,"qty":15.24971184}],"asks":[],"checksum":3155481031,"timestamp":"2024-06-01T17:52:14.155468Z"}]}
{"channel":"book","type":"update","data":[{"symbol":"ETH/JPY","bids":[{"price":595226,"qty":0.25315742}],"asks":[],"checksum":3664794451,"timestamp":"2024-06-01T17:52:14.186879Z"}]}
{"channel":"book","type":"update","data":[{"symbol":"ETH/JPY","bids":[{"price":595225,"qty":0.00000000},{"price":591118,"qty":15.24971184}],"asks":[],"checksum":1357264327,"timestamp":"2024-06-01T17:52:14.193410Z"}]}
{"channel":"book","type":"update","data":[{"symbol":"ETH/JPY","bids":[{"price":595227,"qty":0.20902830}],"asks":[],"checksum":3879096035,"timestamp":"2024-06-01T17:52:14.193427Z"}]}
{"channel":"book","type":"update","data":[{"symbol":"ETH/JPY","bids":[{"price":595221,"qty":0.00000000},{"price":591118,"qty":15.24971184}],"asks":[],"checksum":2372872110,"timestamp":"2024-06-01T17:52:15.578876Z"}]}
{"channel":"book","type":"update","data":[{"symbol":"ETH/JPY","bids":[{"price":595227,"qty":1.18711570}],"asks":[],"checksum":3910684913,"timestamp":"2024-06-01T17:52:15.619024Z"}]}
{"channel":"book","type":"update","data":[{"symbol":"ETH/JPY","bids":[{"price":595222,"qty":0.00000000},{"price":591104,"qty":10.17338388},{"price":595228,"qty":3.79081989}],"asks":[],"checksum":2418935997,"timestamp":"2024-06-01T17:52:15.665157Z"}]}
{"channel":"book","type":"update","data":[{"symbol":"ETH/JPY","bids":[{"price":595227,"qty":0.97808740}],"asks":[],"checksum":712679100,"timestamp":"2024-06-01T17:52:15.676985Z"}]}
{"channel":"book","type":"update","data":[{"symbol":"ETH/JPY","bids":[{"price":595229,"qty":0.20902760}],"asks":[],"checksum":1807616316,"timestamp":"2024-06-01T17:52:15.677049Z"}]}
{"channel":"book","type":"update","data":[{"symbol":"ETH/JPY","bids":[],"asks":[{"price":598953,"qty":0.00000000},{"price":608667,"qty":0.49039636},{"price":598953,"qty":1.96019508}],"checksum":4289018407,"timestamp":"2024-06-01T17:52:15.930564Z"}]}
{"channel":"book","type":"update","data":[{"symbol":"ETH/JPY","bids":[{"price":594033,"qty":0.00000000},{"price":591118,"qty":15.24971184}],"asks":[],"checksum":3451492967,"timestamp":"2024-06-01T17:52:17.668612Z"}]}
{"channel":"book","type":"update","data":[{"symbol":"ETH/JPY","bids":[{"price":591118,"qty":0.00000000},{"price":591104,"qty":10.17338388}],"asks":[],"checksum":2329366167,"timestamp":"2024-06-01T17:52:17.668912Z"}]}
{"channel":"book","type":"update","data":[{"symbol":"ETH/JPY","bids":[{"price":594034,"qty":7.38926496}],"asks":[],"checksum":787195951,"timestamp":"2024-06-01T17:52:17.671426Z"}]}
{"channel":"book","type":"update","data":[{"symbol":"ETH/JPY","bids":[{"price":595226,"qty":0.00000000},{"price":591119,"qty":15.24971184}],"asks":[],"checksum":3192903374,"timestamp":"2024-06-01T17:52:17.699731Z"}]}
{"channel":"book","type":"update","data":[{"symbol":"ETH/JPY","bids":[{"price":595230,"qty":0.25315750}],"asks":[],"checksum":2746790935,"timestamp":"2024-06-01T17:52:17.731301Z"}]}
{"channel":"book","type":"update","data":[{"symbol":"ETH/JPY","bids":[{"price":595231,"qty":0.20902689}],"asks":[],"checksum":3984997485,"timestamp":"2024-06-01T17:52:17.748320Z"}]}
{"channel":"book","type":"update","data":[{"symbol":"ETH/JPY","bids":[{"price":595229,"qty":0.00000000},{"price":593794,"qty":20.30632296}],"asks":[],"checksum":2643032328,"timestamp":"2024-06-01T17:52:17.748483Z"}]}
{"channel":"book","type":"update","data":[{"symbol":"ETH/JPY","bids":[],"asks":[{"price":597785,"qty":0.00000000},{"price":608666,"qty":35.59647960}],"checksum":571392165,"timestamp":"2024-06-01T17:52:20.693738Z"}]}
{"channel":"book","type":"update","data":[{"symbol":"ETH/JPY","bids":[],"asks":[{"price":597944,"qty":0.18037684}],"checksum":2086322944,"timestamp":"2024-06-01T17:52:20.699843Z"}]}
{"channel":"book","type":"update","data":[{"symbol":"ETH/JPY","bids":[{"price":595230,"qty":0.00000000},{"price":591119,"qty":15.24971184}],"asks":[],"checksum":2253525302,"timestamp":"2024-06-01T17:52:20.754624Z"}]}
{"channel":"book","type":"update","data":[{"symbol":"ETH/JPY","bids":[{"price":595227,"qty":0.00000000},{"price":591104,"qty":10.17338388}],"asks":[],"checksum":1260415378,"timestamp":"2024-06-01T17:52:21.205023Z"}]}
{"channel":"book","type":"update","data":[{"symbol":"ETH/JPY","bids":[{"price":595231,"qty":1.18714172}],"asks":[],"checksum":3941973305,"timestamp":"2024-06-01T17:52:21.245287Z"}]}
{"channel":"book","type":"update","data":[{"symbol":"ETH/JPY","bids":[{"price":595232,"qty":0.25315744}],"asks":[],"checksum":4291928548,"timestamp":"2024-06-01T17:52:21.247475Z"}]}
{"channel":"book","type":"update","data":[{"symbol":"ETH/JPY","bids":[{"price":595231,"qty":0.97811483}],"asks":[],"checksum":264957233,"timestamp":"2024-06-01T17:52:21.261131Z"}]}
{"channel":"book","type":"update","data":[{"symbol":"ETH/JPY","bids":[{"price":595233,"qty":0.20902619}],"asks":[],"checksum":2995491874,"timestamp":"2024-06-01T17:52:21.261305Z"}]}
{"channel":"book","type":"update","data":[{"symbol":"ETH/JPY","bids":[{"price":595228,"qty":0.00000000},{"price":591119,"qty":15.24971184},{"price":595232,"qty":4.20565694}],"asks":[],"checksum":2450103657,"timestamp":"2024-06-01T17:52:21.290122Z"}]}
{"channel":"book","type":"update","data":[{"symbol":"ETH/JPY","bids":[{"price":595232,"qty":0.25315744},{"price":595233,"qty":4.13276082}],"asks":[],"checksum":1216883081,"timestamp":"2024-06-01T17:52:21.861977Z"}]}
{"channel":"book","type":"update","data":[{"symbol":"ETH/JPY","bids":[{"price":591119,"qty":0.00000000},{"price":591104,"qty":10.17338388}],"asks":[],"checksum":3462931129,"timestamp":"2024-06-01T17:52:23.553618Z"}]}
{"channel":"book","type":"update","data":[{"symbol":"ETH/JPY","bids":[{"price":594034,"qty":0.00000000},{"price":591065,"qty":0.05332854}],"asks":[],"checksum":4285482661,"timestamp":"2024-06-01T17:52:23.553661Z"}]}
{"channel":"book","type":"update","data":[{"symbol":"ETH/JPY","bids":[{"price":594035,"qty":7.38926496}],"asks":[],"checksum":2226072874,"timestamp":"2024-06-01T17:52:23.556309Z"}]}
{"channel":"book","type":"update","data":[{"symbol":"ETH/JPY","bids":[{"price":591120,"qty":15.24971184}],"asks":[],"checksum":245156463,"timestamp":"2024-06-01T17:52:23.556487Z"}]}
{"channel":"book","type":"update","data":[{"symbol":"ETH/JPY","bids":[{"price":595232,"qty":0.00000000},{"price":591104,"qty":10.17338388}],"asks":[],"checksum":598207806,"timestamp":"2024-06-01T17:52:24.504513Z"}]}
{"channel":"book","type":"update","data":[{"symbol":"ETH/JPY","bids":[],"asks":[{"price":598714,"qty":0.00000000},{"price":608665,"qty":35.59647960}],"checksum":470384804,"timestamp":"2024-06-01T17:52:24.504722Z"}]}
{"channel":"book","type":"update","data":[{"symbol":"ETH/JPY","bids":[{"price":595234,"qty":0.25315744}],"asks":[],"checksum":322748237,"timestamp":"2024-06-01T17:52:24.537476Z"}]}
{"channel":"book","type":"update","data":[{"symbol":"ETH/JPY","bids":[{"price":595233,"qty":3.92373463}],"asks":[],"checksum":3914438398,"timestamp":"2024-06-01T17:52:24.565445Z"}]}
{"channel":"book","type":"update","data":[{"symbol":"ETH/JPY","bids":[{"price":595235,"qty":0.20902549}],"asks":[],"checksum":2276159045,"timestamp":"2024-06-01T17:52:24.565734Z"}]}
{"channel":"book","type":"update","data":[{"symbol":"ETH/JPY","bids":[],"asks":[{"price":598951,"qty":0.00737190}],"checksum":4035956235,"timestamp":"2024-06-01T17:52:27.168411Z"}]}
{"channel":"book","type":"update","data":[{"symbol":"ETH/JPY","bids":[{"price":595231,"qty":0.00000000},{"price":591120,"qty":15.24971184}],"asks":[],"checksum":680437568,"timestamp":"2024-06-01T17:52:27.201517Z"}]}
{"channel":"book","type":"update","data":[{"symbol":"ETH/JPY","bids":[{"price":595235,"qty":1.18737368}],"asks":[],"checksum":1185627503,"timestamp":"2024-06-01T17:52:27.241673Z"}]}
{"channel":"book","type":"update","data":[{"symbol":"ETH/JPY","bids":[{"price":595233,"qty":0.00000000},{"price":591104,"qty":10.17338388},{"price":595236,"qty":3.97051002}],"asks":[],"checksum":620912026,"timestamp":"2024-06-01T17:52:27.290451Z"}]}
{"channel":"book","type":"update","data":[{"symbol":"ETH/JPY","bids":[{"price":595237,"qty":0.20902479}],"asks":[],"checksum":3243206768,"timestamp":"2024-06-01T17:52:27.299857Z"}]}
{"channel":"book","type":"update","data":[{"symbol":"ETH/JPY","bids":[{"price":595235,"qty":0.97834819}],"asks":[],"checksum":661203283,"timestamp":"2024-06-01T17:52:27.299987Z"}]}
{"channel":"book","type":"update","data":[{"symbol":"ETH/JPY","bids":[{"price":594035,"qty":0.00000000},{"price":591104,"qty":10.17338388}],"asks":[],"checksum":2491287546,"timestamp":"2024-06-01T17:52:29.439045Z"}]}
{"channel":"book","type":"update","data":[{"symbol":"ETH/JPY","bids":[{"price":591121,"qty":15.24971184}],"asks":[],"checksum":3754114943,"timestamp":"2024-06-01T17:52:29.441740Z"}]}
{"channel":"book","type":"update","data":[{"symbol":"ETH/JPY","bids":[{"price":594036,"qty":7.38926496}],"asks":[],"checksum":525509152,"timestamp":"2024-06-01T17:52:29.441763Z"}]}
{"channel":"book","type":"update","data":[{"symbol":"ETH/JPY","bids":[],"asks":[{"price":598953,"qty":0.00000000},{"price":608664,"qty":0.49039391},{"price":599614,"qty":3.19458072}],"checksum":762828122,"timestamp":"2024-06-01T17:52:29.952975Z"}]}
{"channel":"book","type":"update","data":[{"symbol":"ETH/JPY","bids":[{"price":595234,"qty":0.00000000},{"price":591121,"qty":15.24971184}],"asks":[],"checksum":2179617618,"timestamp":"2024-06-01T17:52:30.923614Z"}]}
{"channel":"book","type":"update","data":[{"symbol":"ETH/JPY","bids":[{"price":591121,"qty":0.00000000},{"price":591104,"qty":10.17338388}],"asks":[],"checksum":3394726871,"timestamp":"2024-06-01T17:52:31.476852Z"}]}
{"channel":"book","type":"update","data":[{"symbol":"ETH/JPY","bids":[{"price":594036,"qty":0.00000000},{"price":591065,"qty":0.05332854}],"asks":[],"checksum":2784095367,"timestamp":"2024-06-01T17:52:31.476895Z"}]}
{"channel":"book","type":"update","data":[{"symbol":"ETH/JPY","bids":[{"price":591105,"qty":15.24971184}],"asks":[],"checksum":3293471137,"timestamp":"2024-06-01T17:52:31.479602Z"}]}
{"channel":"book","type":"update","data":[{"symbol":"ETH/JPY","bids":[{"price":594024,"qty":7.38926496}],"asks":[],"checksum":566928536,"timestamp":"2024-06-01T17:52:31.479838Z"}]}
{"channel":"book","type":"update","data":[{"symbol":"ETH/JPY","bids":[{"price":595235,"qty":0.00000000},{"price":591104,"qty":10.17338388}],"asks":[],"checksum":2762673116,"timestamp":"2024-06-01T17:52:31.916771Z"}]}
{"channel":"book","type":"update","data":[{"symbol":"ETH/JPY","bids":[{"price":595237,"qty":1.18888272}],"asks":[],"checksum":3027185887,"timestamp":"2024-06-01T17:52:31.956971Z"}]}
{"channel":"book","type":"update","data":[{"symbol":"ETH/JPY","bids":[],"asks":[{"price":599615,"qty":0.00000000},{"price":608664,"qty":36.08687351},{"price":599613,"qty":0.02861577}],"checksum":4054967176,"timestamp":"2024-06-01T17:52:31.964182Z"}]}
{"channel":"book","type":"update","data":[{"symbol":"ETH/JPY","bids":[{"price":595236,"qty":0.00000000},{"price":591065,"qty":0.05332854},{"price":595238,"qty":3.45318341}],"asks":[],"checksum":3788893260,"timestamp":"2024-06-01T17:52:32.229838Z"}]}
{"channel":"book","type":"update","data":[{"symbol":"ETH/JPY","bids":[],"asks":[{"price":599614,"qty":0.00000000},{"price":608664,"qty":36.08687351},{"price":598950,"qty":2.08749406}],"checksum":2431023908,"timestamp":"2024-06-01T17:52:32.229964Z"}]}
{"channel":"book","type":"update","data":[{"symbol":"ETH/JPY","bids":[],"asks":[{"price":599613,"qty":0.00000000},{"price":608664,"qty":36.08687351},{"price":599615,"qty":0.02861568}],"checksum":2616548616,"timestamp":"2024-06-01T17:52:32.238545Z"}]}
{"channel":"book","type":"update","data":[{"symbol":"ETH/JPY","bids":[],"asks":[{"price":598952,"qty":0.00000000},{"price":608664,"qty":36.08687351}],"checksum":960698742,"timestamp":"2024-06-01T17:52:32.242295Z"}]}
{"channel":"book","type":"update","data":[{"symbol":"ETH/JPY","bids":[],"asks":[{"price":598949,"qty":0.20717085}],"checksum":4206880103,"timestamp":"2024-06-01T17:52:32.242324Z"}]}
{"channel":"book","type":"update","data":[{"symbol":"ETH/JPY","bids":[{"price":595237,"qty":0.97985793}],"asks":[],"checksum":3146204543,"timestamp":"2024-06-01T17:52:32.242503Z"}]}
{"channel":"book","type":"update","data":[{"symbol":"ETH/JPY","bids":[{"price":595239,"qty":0.20902408}],"asks":[],"checksum":410966727,"timestamp":"2024-06-01T17:52:32.242524Z"}]}
{"channel":"book","type":"update","data":[{"symbol":"ETH/JPY","bids":[{"price":595239,"qty":0.46218150}],"asks":[],"checksum":1613956126,"timestamp":"2024-06-01T17:52:32.261334Z"}]}
{"channel":"book","type":"update","data":[{"symbol":"ETH/JPY","bids":[{"price":594949,"qty":0.00000000},{"price":591104,"qty":10.17338388}],"asks":[],"checksum":1773237923,"timestamp":"2024-06-01T17:52:32.559037Z"}]}
{"channel":"book","type":"update","data":[{"symbol":"ETH/JPY","bids":[{"price":594871,"qty":21.58016998}],"asks":[],"checksum":4104808154,"timestamp":"2024-06-01T17:52:32.599166Z"}]}
{"channel":"book","type":"update","data":[{"symbol":"ETH/JPY","bids":[],"asks":[{"price":599499,"qty":21.60066263}],"checksum":2636569776,"timestamp":"2024-06-01T17:52:33.726670Z"}]}
{"channel":"book","type":"update","data":[{"symbol":"ETH/JPY","bids":[{"price":594024,"qty":0.00000000},{"price":591104,"qty":10.17338388}],"asks":[],"checksum":4047971619,"timestamp":"2024-06-01T17:52:35.323954Z"}]}
{"channel":"book","type":"update","data":[{"symbol":"ETH/JPY","bids":[{"price":591105,"qty":0.00000000},{"price":591065,"qty":0.05332854}],"asks":[],"checksum":990556572,"timestamp":"2024-06-01T17:52:35.324029Z"}]}
{"channel":"book","type":"update","data":[{"symbol":"ETH/JPY","bids":[{"price":594025,"qty":7.38926496}],"asks":[],"checksum":3233679035,"timestamp":"2024-06-01T17:52:35.326624Z"}]}
{"channel":"book","type":"update","data":[{"symbol":"ETH/JPY","bids":[{"price":591106,"qty":15.24971184}],"asks":[],"checksum":1308865826,"timestamp":"2024-06-01T17:52:35.327104Z"}]}
{"channel":"book","type":"update","data":[{"symbol":"ETH/JPY","bids":[],"asks":[{"price":598951,"qty":0.00000000},{"price":600308,"qty":21.60207835}],"checksum":1040154129,"timestamp":"2024-06-01T17:52:35.358117Z"}]}
{"channel":"book","type":"update","data":[{"symbol":"ETH/JPY","bids":[],"asks":[{"price":598948,"qty":0.00737190}],"checksum":2895374143,"timestamp":"2024-06-01T17:52:35.389061Z"}]}
{"channel":"book","type":"update","data":[{"symbol":"ETH/JPY","bids":[],"asks":[{"price":599615,"qty":0.00000000},{"price":600308,"qty":21.60207835},{"price":599498,"qty":0.02862126}],"checksum":3736221417,"timestamp":"2024-06-01T17:52:35.392351Z"}]}
{"channel":"book","type":"update","data":[{"symbol":"ETH/JPY","bids":[{"price":594023,"qty":0.00000000},{"price":591104,"qty":10.17338388}],"asks":[],"checksum":4048223207,"timestamp":"2024-06-01T17:52:36.634867Z"}]}
{"channel":"book","type":"update","data":[{"symbol":"ETH/JPY","bids":[{"price":594069,"qty":21.58601015}],"asks":[],"checksum":2997553282,"timestamp":"2024-06-01T17:52:36.675191Z"}]}
{"channel":"book","type":"update","data":[{"symbol":"ETH/JPY","bids":[{"price":595237,"qty":0.00000000},{"price":591104,"qty":10.17338388}],"asks":[],"checksum":1522584170,"timestamp":"2024-06-01T17:52:37.813345Z"}]}
{"channel":"book","type":"update","data":[{"symbol":"ETH/JPY","bids":[{"price":595239,"qty":1.44207293}],"asks":[],"checksum":3910319354,"timestamp":"2024-06-01T17:52:37.853526Z"}]}
{"channel":"book","type":"update","data":[{"symbol":"ETH/JPY","bids":[{"price":595238,"qty":0.00000000},{"price":591065,"qty":0.05332854},{"price":595240,"qty":3.45318341}],"asks":[],"checksum":778456432,"timestamp":"2024-06-01T17:52:37.901738Z"}]}
{"channel":"book","type":"update","data":[{"symbol":"ETH/JPY","bids":[{"price":595239,"qty":1.23304885}],"asks":[],"checksum":2186326397,"timestamp":"2024-06-01T17:52:37.909889Z"}]}
{"channel":"book","type":"update","data":[{"symbol":"ETH/JPY","bids":[{"price":595241,"qty":0.20902340}],"asks":[],"checksum":712997801,"timestamp":"2024-06-01T17:52:37.909981Z"}]}
{"channel":"book","type":"update","data":[{"symbol":"ETH/JPY","bids":[{"price":591106,"qty":0.00000000},{"price":591104,"qty":10.17338388}],"asks":[],"checksum":2764228656,"timestamp":"2024-06-01T17:52:37.969001Z"}]}
{"channel":"book","type":"update","data":[{"symbol":"ETH/JPY","bids":[{"price":595204,"qty":0.00000000},{"price":591065,"qty":0.05332854}],"asks":[],"checksum":3331363318,"timestamp":"2024-06-01T17:52:37.969157Z"}]}
{"channel":"book","type":"update","data":[{"symbol":"ETH/JPY","bids":[{"price":591107,"qty":15.24971184}],"asks":[],"checksum":3963683666,"timestamp":"2024-06-01T17:52:37.971827Z"}]}
{"channel":"book","type":"update","data":[{"symbol":"ETH/JPY","bids":[{"price":594875,"qty":4.10464164}],"asks":[],"checksum":823714668,"timestamp":"2024-06-01T17:52:37.971953Z"}]}
{"channel":"book","type":"update","data":[{"symbol":"ETH/JPY","bids":[],"asks":[{"price":598954,"qty":0.00000000},{"price":600308,"qty":21.60207835}],"checksum":2430273297,"timestamp":"2024-06-01T17:52:37.993039Z"}]}
{"channel":"book","type":"update","data":[{"symbol":"ETH/JPY","bids":[],"asks":[{"price":599244,"qty":4.10464164}],"checksum":332879645,"timestamp":"2024-06-01T17:52:37.996054Z"}]}
{"channel":"book","type":"update","data":[{"symbol":"ETH/JPY","bids":[{"price":591107,"qty":0.00000000},{"price":591104,"qty":10.17338388}],"asks":[],"checksum":1558461252,"timestamp":"2024-06-01T17:52:38.000523Z"}]}
{"channel":"book","type":"update","data":[{"symbol":"ETH/JPY","bids":[{"price":591105,"qty":15.24971184}],"asks":[],"checksum":1270607580,"timestamp":"2024-06-01T17:52:38.010039Z"}]}
{"channel":"book","type":"update","data":[{"symbol":"ETH/JPY","bids":[{"price":595239,"qty":0.97989143}],"asks":[],"checksum":1787564059,"timestamp":"2024-06-01T17:52:38.507958Z"}]}
{"channel":"book","type":"update","data":[{"symbol":"ETH/JPY","bids":[{"price":595242,"qty":0.25315749}],"asks":[],"checksum":2770703706,"timestamp":"2024-06-01T17:52:38.659048Z"}]}
{"channel":"book","type":"update","data":[{"symbol":"ETH/JPY","bids":[{"price":595241,"qty":0.00000000},{"price":591105,"qty":15.24971184}],"asks":[],"checksum":1035895580,"timestamp":"2024-06-01T17:52:38.681904Z"}]}
{"channel":"book","type":"update","data":[{"symbol":"ETH/JPY","bids":[{"price":595243,"qty":0.20902268}],"asks":[],"checksum":1054785197,"timestamp":"2024-06-01T17:52:38.682115Z"}]}
{"channel":"book","type":"update","data":[{"symbol":"ETH/JPY","bids":[{"price":595239,"qty":0.00000000},{"price":591106,"qty":15.24971184}],"asks":[],"checksum":2815903407,"timestamp":"2024-06-01T17:52:42.781007Z"}]}
{"channel":"book","type":"update","data":[{"symbol":"ETH/JPY","bids":[{"price":595243,"qty":1.18831880}],"asks":[],"checksum":3600697445,"timestamp":"2024-06-01T17:52:42.821291Z"}]}
{"channel":"book","type":"update","data":[{"symbol":"ETH/JPY","bids":[{"price":595242,"qty":0.00000000},{"price":591104,"qty":10.17338388}],"asks":[],"checksum":139638650,"timestamp":"2024-06-01T17:52:42.853764Z"}]}
{"channel":"book","type":"update","data":[{"symbol":"ETH/JPY","bids":[{"price":595240,"qty":0.00000000},{"price":591065,"qty":0.05332854},{"price":595244,"qty":4.01651296}],"asks":[],"checksum":1914183523,"timestamp":"2024-06-01T17:52:42.884974Z"}]}
{"channel":"book","type":"update","data":[{"symbol":"ETH/JPY","bids":[{"price":595244,"qty":4.26967042}],"asks":[],"checksum":1652757182,"timestamp":"2024-06-01T17:52:42.889043Z"}]}
{"channel":"book","type":"update","data":[{"symbol":"ETH/JPY","bids":[{"price":595243,"qty":0.97929612}],"asks":[],"checksum":2672773642,"timestamp":"2024-06-01T17:52:42.906612Z"}]}
{"channel":"book","type":"update","data":[{"symbol":"ETH/JPY","bids":[{"price":595245,"qty":0.20902198}],"asks":[],"checksum":3130011463,"timestamp":"2024-06-01T17:52:42.906927Z"}]}
{"channel":"book","type":"update","data":[{"symbol":"ETH/JPY","bids":[{"price":595244,"qty":0.25315746},{"price":595245,"qty":4.21831877}],"asks":[],"checksum":1255542266,"timestamp":"2024-06-01T17:52:42.939544Z"}]}
{"channel":"book","type":"update","data":[{"symbol":"ETH/JPY","bids":[{"price":595245,"qty":0.20902198},{"price":595246,"qty":4.00734414}],"asks":[],"checksum":1097341390,"timestamp":"2024-06-01T17:52:42.981135Z"}]}
{"channel":"book","type":"update","data":[{"symbol":"ETH/JPY","bids":[{"price":595247,"qty":0.20902129}],"asks":[],"checksum":1375782726,"timestamp":"2024-06-01T17:52:43.003783Z"}]}
{"channel":"book","type":"update","data":[{"symbol":"ETH/JPY","bids":[{"price":595245,"qty":0.00000000},{"price":593794,"qty":20.30632296}],"asks":[],"checksum":799216369,"timestamp":"2024-06-01T17:52:43.003817Z"}]}
{"channel":"book","type":"update","data":[{"symbol":"ETH/JPY","bids":[{"price":594025,"qty":0.00000000},{"price":591106,"qty":15.24971184}],"asks":[],"checksum":3751509043,"timestamp":"2024-06-01T17:52:44.150312Z"}]}
{"channel":"book","type":"update","data":[{"symbol":"ETH/JPY","bids":[{"price":594875,"qty":0.00000000},{"price":591104,"qty":10.17338388}],"asks":[],"checksum":685842109,"timestamp":"2024-06-01T17:52:44.150425Z"}]}
{"channel":"book","type":"update","data":[{"symbol":"ETH/JPY","bids":[{"price":591106,"qty":0.00000000},{"price":591065,"qty":0.05332854}],"asks":[],"checksum":246234235,"timestamp":"2024-06-01T17:52:44.150761Z"}]}
{"channel":"book","type":"update","data":[{"symbol":"ETH/JPY","bids":[{"price":594070,"qty":7.38926496}],"asks":[],"checksum":1559620322,"timestamp":"2024-06-01T17:52:44.152963Z"}]}
{"channel":"book","type":"update","data":[{"symbol":"ETH/JPY","bids":[{"price":591107,"qty":15.24971184}],"asks":[],"checksum":331777723,"timestamp":"2024-06-01T17:52:44.153540Z"}]}
{"channel":"book","type":"update","data":[{"symbol":"ETH/JPY","bids":[{"price":595336,"qty":4.10464164}],"asks":[],"checksum":455574323,"timestamp":"2024-06-01T17:52:44.153570Z"}]}
{"channel":"book","type":"update","data":[{"symbol":"ETH/JPY","bids":[{"price":595247,"qty":0.00000000},{"price":591107,"qty":15.24971184}],"asks":[],"checksum":524795134,"timestamp":"2024-06-01T17:52:44.177079Z"}]}
{"channel":"book","type":"update","data":[{"symbol":"ETH/JPY","bids":[{"price":595337,"qty":0.20898968}],"asks":[],"checksum":1339430073,"timestamp":"2024-06-01T17:52:44.177159Z"}]}
{"channel":"book","type":"update","data":[{"symbol":"ETH/JPY","bids":[{"price":595246,"qty":0.00000000},{"price":591107,"qty":15.24971184},{"price":595337,"qty":3.91564963}],"asks":[],"checksum":3708042488,"timestamp":"2024-06-01T17:52:44.214104Z"}]}
{"channel":"book","type":"update","data":[{"symbol":"ETH/JPY","bids":[{"price":595337,"qty":0.20898968},{"price":595338,"qty":3.70219882}],"asks":[],"checksum":369973696,"timestamp":"2024-06-01T17:52:44.266766Z"}]}
{"channel":"book","type":"update","data":[{"symbol":"ETH/JPY","bids":[{"price":595337,"qty":0.00000000},{"price":591107,"qty":15.24971184}],"asks":[],"checksum":1520434879,"timestamp":"2024-06-01T17:52:44.292776Z"}]}
{"channel":"book","type":"update","data":[{"symbol":"ETH/JPY","bids":[{"price":595339,"qty":0.20898898}],"asks":[],"checksum":1954261479,"timestamp":"2024-06-01T17:52:44.292805Z"}]}
{"channel":"book","type":"update","data":[{"symbol":"ETH/JPY","bids":[{"price":595244,"qty":0.00000000},{"price":591107,"qty":15.24971184}],"asks":[],"checksum":168305943,"timestamp":"2024-06-01T17:52:46.304248Z"}]}
{"channel":"book","type":"update","data":[{"symbol":"ETH/JPY","bids":[{"price":595340,"qty":0.25315735}],"asks":[],"checksum":3561456732,"timestamp":"2024-06-01T17:52:46.336288Z"}]}
{"channel":"book","type":"update","data":[{"symbol":"ETH/JPY","bids":[{"price":595341,"qty":0.20898828}],"asks":[],"checksum":3734609732,"timestamp":"2024-06-01T17:52:46.350991Z"}]}
{"channel":"book","type":"update","data":[{"symbol":"ETH/JPY","bids":[{"price":595339,"qty":0.00000000},{"price":593794,"qty":20.30632296}],"asks":[],"checksum":4073479234,"timestamp":"2024-06-01T17:52:46.351017Z"}]}
{"channel":"book","type":"update","data":[{"symbol":"ETH/JPY","bids":[{"price":595243,"qty":0.00000000},{"price":591107,"qty":15.24971184}],"asks":[],"checksum":876143278,"timestamp":"2024-06-01T17:52:48.143820Z"}]}
{"channel":"book","type":"update","data":[{"symbol":"ETH/JPY","bids":[{"price":595341,"qty":1.18804309}],"asks":[],"checksum":332889823,"timestamp":"2024-06-01T17:52:48.258246Z"}]}
{"channel":"book","type":"update","data":[{"symbol":"ETH/JPY","bids":[{"price":595338,"qty":0.00000000},{"price":591104,"qty":10.17338388},{"price":595342,"qty":3.80756947}],"asks":[],"checksum":1051994615,"timestamp":"2024-06-01T17:52:48.330511Z"}]}
{"channel":"book","type":"update","data":[{"symbol":"ETH/JPY","bids":[{"price":595341,"qty":0.97905481}],"asks":[],"checksum":3193074482,"timestamp":"2024-06-01T17:52:48.356350Z"}]}
