{"channel":"book","type":"update","data":[{"symbol":"ETH/USD","bids":[],"asks":[{"price":3796.97,"qty":26.33679437}],"checksum":726948854,"timestamp":"2024-06-01T17:52:23.282717Z"}]}
{"channel":"book","type":"update","data":[{"symbol":"ETH/USD","bids":[{"price":3796.56,"qty":0.00000000},{"price":3795.79,"qty":3.40262063}],"asks":[],"checksum":2324912595,"timestamp":"2024-06-01T17:52:23.294197Z"}]}
{"channel":"book","type":"update","data":[{"symbol":"ETH/USD","bids":[{"price":3796.30,"qty":0.00526368}],"asks":[],"checksum":3131649753,"timestamp":"2024-06-01T17:52:23.294359Z"}]}
{"channel":"book","type":"update","data":[{"symbol":"ETH/USD","bids":[],"asks":[{"price":3796.94,"qty":0.00000000},{"price":3797.81,"qty":4.53808791}],"checksum":1061997979,"timestamp":"2024-06-01T17:52:23.299175Z"}]}
{"channel":"book","type":"update","data":[{"symbol":"ETH/USD","bids":[],"asks":[{"price":3797.23,"qty":26.33498783}],"checksum":4276979900,"timestamp":"2024-06-01T17:52:23.307799Z"}]}
{"channel":"book","type":"update","data":[{"symbol":"ETH/USD","bids":[{"price":3796.64,"qty":26.33907876}],"asks":[],"checksum":3553556620,"timestamp":"2024-06-01T17:52:23.307990Z"}]}
{"channel":"book","type":"update","data":[{"symbol":"ETH/USD","bids":[{"price":3796.57,"qty":0.00000000},{"price":3795.90,"qty":11.27100000},{"price":3796.44,"qty":0.00936888}],"asks":[],"checksum":3569081770,"timestamp":"2024-06-01T17:52:23.332839Z"}]}
{"channel":"book","type":"update","data":[{"symbol":"ETH/USD","bids":[],"asks":[{"price":3796.98,"qty":0.79631833}],"checksum":1288610306,"timestamp":"2024-06-01T17:52:23.370591Z"}]}
{"channel":"book","type":"update","data":[{"symbol":"ETH/USD","bids":[],"asks":[{"price":3797.13,"qty":0.00000000},{"price":3797.81,"qty":4.53808791}],"checksum":1542947678,"timestamp":"2024-06-01T17:52:23.392977Z"}]}
{"channel":"book","type":"update","data":[{"symbol":"ETH/USD","bids":[{"price":3796.61,"qty":26.33926053}],"asks":[],"checksum":634006053,"timestamp":"2024-06-01T17:52:23.397907Z"}]}
{"channel":"book","type":"update","data":[{"symbol":"ETH/USD","bids":[],"asks":[{"price":3796.96,"qty":26.33689640}],"checksum":3205433629,"timestamp":"2024-06-01T17:52:23.397984Z"}]}
{"channel":"book","type":"update","data":[{"symbol":"ETH/USD","bids":[{"price":3796.44,"qty":0.00000000},{"price":3795.91,"qty":19.75456924},{"price":3796.30,"qty":0.01463290}],"asks":[],"checksum":1462801249,"timestamp":"2024-06-01T17:52:23.398059Z"}]}
{"channel":"book","type":"update","data":[{"symbol":"ETH/USD","bids":[],"asks":[{"price":3796.96,"qty":0.00000000},{"price":3797.81,"qty":4.53808791}],"checksum":1747736269,"timestamp":"2024-06-01T17:52:23.418380Z"}]}
{"channel":"book","type":"update","data":[{"symbol":"ETH/USD","bids":[],"asks":[{"price":3796.98,"qty":0.02631833}],"checksum":331538063,"timestamp":"2024-06-01T17:52:23.450346Z"}]}
{"channel":"book","type":"update","data":[{"symbol":"ETH/USD","bids":[{"price":3796.30,"qty":0.00526368},{"price":3796.62,"qty":0.00936843}],"asks":[],"checksum":96832335,"timestamp":"2024-06-01T17:52:23.462808Z"}]}
{"channel":"book","type":"update","data":[{"symbol":"ETH/USD","bids":[{"price":3796.28,"qty":0.00000000},{"price":3795.91,"qty":19.75456924}],"asks":[],"checksum":1464423707,"timestamp":"2024-06-01T17:52:23.531246Z"}]}
{"channel":"book","type":"update","data":[{"symbol":"ETH/USD","bids":[],"asks":[{"price":3796.97,"qty":0.00000000},{"price":3797.90,"qty":0.52678018}],"checksum":866959120,"timestamp":"2024-06-01T17:52:23.531256Z"}]}
{"channel":"book","type":"update","data":[{"symbol":"ETH/USD","bids":[],"asks":[{"price":3796.86,"qty":0.00000000},{"price":3797.95,"qty":0.84574642}],"checksum":1514541497,"timestamp":"2024-06-01T17:52:23.535430Z"}]}
{"channel":"book","type":"update","data":[{"symbol":"ETH/USD","bids":[],"asks":[{"price":3797.02,"qty":26.33644314}],"checksum":4148598260,"timestamp":"2024-06-01T17:52:23.538934Z"}]}
{"channel":"book","type":"update","data":[{"symbol":"ETH/USD","bids":[{"price":3796.41,"qty":26.34062365}],"asks":[],"checksum":2802646951,"timestamp":"2024-06-01T17:52:23.538984Z"}]}
{"channel":"book","type":"update","data":[{"symbol":"ETH/USD","bids":[],"asks":[{"price":3797.10,"qty":26.33590406}],"checksum":4202686030,"timestamp":"2024-06-01T17:52:23.539009Z"}]}
{"channel":"book","type":"update","data":[{"symbol":"ETH/USD","bids":[],"asks":[{"price":3797.81,"qty":0.00000000},{"price":3797.90,"qty":0.52678018}],"checksum":3455473716,"timestamp":"2024-06-01T17:52:23.555120Z"}]}
{"channel":"book","type":"update","data":[{"symbol":"ETH/USD","bids":[],"asks":[{"price":3797.02,"qty":0.00000000},{"price":3797.95,"qty":0.84574642}],"checksum":108615923,"timestamp":"2024-06-01T17:52:23.582391Z"}]}
{"channel":"book","type":"update","data":[{"symbol":"ETH/USD","bids":[{"price":3796.61,"qty":0.00000000},{"price":3795.91,"qty":19.75456924}],"asks":[],"checksum":2021607263,"timestamp":"2024-06-01T17:52:23.582565Z"}]}
{"channel":"book","type":"update","data":[{"symbol":"ETH/USD","bids":[{"price":3796.64,"qty":52.67815752}],"asks":[],"checksum":1065908351,"timestamp":"2024-06-01T17:52:23.589148Z"}]}
{"channel":"book","type":"update","data":[{"symbol":"ETH/USD","bids":[],"asks":[{"price":3797.04,"qty":26.33632736}],"checksum":3684249389,"timestamp":"2024-06-01T17:52:23.593986Z"}]}
{"channel":"book","type":"update","data":[{"symbol":"ETH/USD","bids":[{"price":3796.62,"qty":0.00000000},{"price":3795.90,"qty":11.27100000},{"price":3796.44,"qty":0.00936888}],"asks":[],"checksum":4056265287,"timestamp":"2024-06-01T17:52:23.645119Z"}]}
{"channel":"book","type":"update","data":[{"symbol":"ETH/USD","bids":[],"asks":[{"price":3797.01,"qty":0.77000000}],"checksum":4012972723,"timestamp":"2024-06-01T17:52:23.682726Z"}]}
{"channel":"book","type":"update","data":[{"symbol":"ETH/USD","bids":[{"price":3796.42,"qty":0.00512397}],"asks":[],"checksum":2726297370,"timestamp":"2024-06-01T17:52:23.744472Z"}]}
{"channel":"book","type":"update","data":[{"symbol":"ETH/USD","bids":[{"price":3796.30,"qty":0.00000000},{"price":3795.91,"qty":19.75456924}],"asks":[],"checksum":204415187,"timestamp":"2024-06-01T17:52:23.745330Z"}]}
{"channel":"book","type":"update","data":[{"symbol":"ETH/USD","bids":[],"asks":[{"price":3797.04,"qty":0.00000000},{"price":3797.90,"qty":0.52678018}],"checksum":3418808416,"timestamp":"2024-06-01T17:52:23.757577Z"}]}
{"channel":"book","type":"update","data":[{"symbol":"ETH/USD","bids":[],"asks":[{"price":3797.02,"qty":26.33644653}],"checksum":1596189563,"timestamp":"2024-06-01T17:52:23.762356Z"}]}
{"channel":"book","type":"update","data":[{"symbol":"ETH/USD","bids":[],"asks":[{"price":3796.98,"qty":0.00000000},{"price":3797.90,"qty":0.52678018}],"checksum":3693989698,"timestamp":"2024-06-01T17:52:23.791292Z"}]}
{"channel":"book","type":"update","data":[{"symbol":"ETH/USD","bids":[],"asks":[{"price":3797.02,"qty":0.00000000},{"price":3797.95,"qty":0.84574642}],"checksum":712561809,"timestamp":"2024-06-01T17:52:23.927108Z"}]}
{"channel":"book","type":"update","data":[{"symbol":"ETH/USD","bids":[],"asks":[{"price":3797.01,"qty":27.10654773}],"checksum":3808180659,"timestamp":"2024-06-01T17:52:23.931800Z"}]}
{"channel":"book","type":"update","data":[{"symbol":"ETH/USD","bids":[],"asks":[{"price":3797.01,"qty":0.77000000}],"checksum":712561809,"timestamp":"2024-06-01T17:52:23.935811Z"}]}
{"channel":"book","type":"update","data":[{"symbol":"ETH/USD","bids":[{"price":3796.25,"qty":0.00000000},{"price":3795.90,"qty":11.27100000},{"price":3796.64,"qty":53.20493909}],"asks":[],"checksum":2797949578,"timestamp":"2024-06-01T17:52:24.001580Z"}]}
{"channel":"book","type":"update","data":[{"symbol":"ETH/USD","bids":[],"asks":[{"price":3796.98,"qty":0.02631754}],"checksum":737105694,"timestamp":"2024-06-01T17:52:24.049761Z"}]}
{"channel":"book","type":"update","data":[{"symbol":"ETH/USD","bids":[],"asks":[{"price":3797.10,"qty":0.00000000},{"price":3797.95,"qty":0.84574642}],"checksum":1680151434,"timestamp":"2024-06-01T17:52:24.215801Z"}]}
{"channel":"book","type":"update","data":[{"symbol":"ETH/USD","bids":[],"asks":[{"price":3796.97,"qty":26.33682164}],"checksum":894070563,"timestamp":"2024-06-01T17:52:24.220154Z"}]}
{"channel":"book","type":"update","data":[{"symbol":"ETH/USD","bids":[{"price":3796.64,"qty":26.86586033}],"asks":[],"checksum":2190191688,"timestamp":"2024-06-01T17:52:24.370213Z"}]}
{"channel":"book","type":"update","data":[{"symbol":"ETH/USD","bids":[],"asks":[{"price":3796.97,"qty":0.00000000},{"price":3797.95,"qty":0.84574642}],"checksum":3554988257,"timestamp":"2024-06-01T17:52:24.370227Z"}]}
{"channel":"book","type":"update","data":[{"symbol":"ETH/USD","bids":[{"price":3796.64,"qty":0.52678157}],"asks":[],"checksum":1482708412,"timestamp":"2024-06-01T17:52:24.370350Z"}]}
{"channel":"book","type":"update","data":[{"symbol":"ETH/USD","bids":[],"asks":[{"price":3796.89,"qty":26.33735851}],"checksum":4265906813,"timestamp":"2024-06-01T17:52:24.375239Z"}]}
{"channel":"book","type":"update","data":[{"symbol":"ETH/USD","bids":[{"price":3796.62,"qty":26.33917785}],"asks":[],"checksum":2905380854,"timestamp":"2024-06-01T17:52:24.375296Z"}]}
{"channel":"book","type":"update","data":[{"symbol":"ETH/USD","bids":[],"asks":[{"price":3797.01,"qty":0.00000000},{"price":3797.97,"qty":3.00000000}],"checksum":1990294662,"timestamp":"2024-06-01T17:52:24.400289Z"}]}
{"channel":"book","type":"update","data":[{"symbol":"ETH/USD","bids":[{"price":3796.62,"qty":0.00000000},{"price":3795.90,"qty":11.27100000}],"asks":[],"checksum":633960717,"timestamp":"2024-06-01T17:52:24.404238Z"}]}
{"channel":"book","type":"update","data":[{"symbol":"ETH/USD","bids":[],"asks":[{"price":3796.89,"qty":0.00000000},{"price":3798.02,"qty":0.01092321}],"checksum":3507965801,"timestamp":"2024-06-01T17:52:24.404385Z"}]}
{"channel":"book","type":"update","data":[{"symbol":"ETH/USD","bids":[{"price":3796.44,"qty":0.00000000},{"price":3795.79,"qty":3.40262063},{"price":3796.63,"qty":0.00936789}],"asks":[],"checksum":4206443657,"timestamp":"2024-06-01T17:52:24.426909Z"}]}
{"channel":"book","type":"update","data":[{"symbol":"ETH/USD","bids":[{"price":3796.63,"qty":0.00000000},{"price":3795.79,"qty":3.40262063},{"price":3796.44,"qty":0.00936836}],"asks":[],"checksum":3535371650,"timestamp":"2024-06-01T17:52:24.497025Z"}]}
{"channel":"book","type":"update","data":[{"symbol":"ETH/USD","bids":[],"asks":[{"price":3797.02,"qty":0.80000000}],"checksum":1754713798,"timestamp":"2024-06-01T17:52:24.552545Z"}]}
{"channel":"book","type":"update","data":[{"symbol":"ETH/USD","bids":[],"asks":[{"price":3797.05,"qty":0.77000000}],"checksum":31963884,"timestamp":"2024-06-01T17:52:24.603749Z"}]}
{"channel":"book","type":"update","data":[{"symbol":"ETH/USD","bids":[{"price":3796.44,"qty":0.00000000},{"price":3795.79,"qty":3.40262063},{"price":3796.45,"qty":0.00936834}],"asks":[],"checksum":3285072226,"timestamp":"2024-06-01T17:52:24.822731Z"}]}
{"channel":"book","type":"update","data":[{"symbol":"ETH/USD","bids":[{"price":3796.64,"qty":26.86586033}],"asks":[],"checksum":3979403959,"timestamp":"2024-06-01T17:52:24.921475Z"}]}
{"channel":"book","type":"update","data":[{"symbol":"ETH/USD","bids":[],"asks":[{"price":3796.95,"qty":26.33695589}],"checksum":1981311152,"timestamp":"2024-06-01T17:52:24.921511Z"}]}
{"channel":"book","type":"update","data":[{"symbol":"ETH/USD","bids":[{"price":3796.64,"qty":26.87108920}],"asks":[],"checksum":3461766942,"timestamp":"2024-06-01T17:52:24.926328Z"}]}
{"channel":"book","type":"update","data":[{"symbol":"ETH/USD","bids":[{"price":3796.42,"qty":0.00000000},{"price":3795.79,"qty":3.40262063}],"asks":[],"checksum":3583035913,"timestamp":"2024-06-01T17:52:24.926617Z"}]}
{"channel":"book","type":"update","data":[{"symbol":"ETH/USD","bids":[],"asks":[{"price":3796.95,"qty":0.00000000},{"price":3797.90,"qty":0.52678018}],"checksum":604374060,"timestamp":"2024-06-01T17:52:24.969986Z"}]}
{"channel":"book","type":"update","data":[{"symbol":"ETH/USD","bids":[],"asks":[{"price":3796.94,"qty":26.33702700}],"checksum":709033710,"timestamp":"2024-06-01T17:52:24.974972Z"}]}
{"channel":"book","type":"update","data":[{"symbol":"ETH/USD","bids":[{"price":3796.59,"qty":26.33940174}],"asks":[],"checksum":1809552817,"timestamp":"2024-06-01T17:52:24.975147Z"}]}
{"channel":"book","type":"update","data":[{"symbol":"ETH/USD","bids":[{"price":3796.45,"qty":0.00000000},{"price":3795.79,"qty":3.40262063},{"price":3796.44,"qty":0.00936836}],"asks":[],"checksum":3754079628,"timestamp":"2024-06-01T17:52:25.001734Z"}]}
{"channel":"book","type":"update","data":[{"symbol":"ETH/USD","bids":[{"price":3796.44,"qty":0.00000000},{"price":3795.79,"qty":3.40262063},{"price":3796.60,"qty":0.00936797}],"asks":[],"checksum":2199047531,"timestamp":"2024-06-01T17:52:25.293182Z"}]}
{"channel":"book","type":"update","data":[{"symbol":"ETH/USD","bids":[],"asks":[{"price":3796.94,"qty":0.00000000},{"price":3797.90,"qty":0.52678018}],"checksum":4134939149,"timestamp":"2024-06-01T17:52:25.370374Z"}]}
{"channel":"book","type":"update","data":[{"symbol":"ETH/USD","bids":[],"asks":[{"price":3796.97,"qty":26.33683651}],"checksum":3599113144,"timestamp":"2024-06-01T17:52:25.374941Z"}]}
{"channel":"book","type":"update","data":[{"symbol":"ETH/USD","bids":[{"price":3796.43,"qty":0.00000000},{"price":3795.79,"qty":3.40262063},{"price":3796.55,"qty":0.77000000}],"asks":[],"checksum":599243219,"timestamp":"2024-06-01T17:52:25.376936Z"}]}
{"channel":"book","type":"update","data":[{"symbol":"ETH/USD","bids":[{"price":3796.55,"qty":1.54000000}],"asks":[],"checksum":3199461171,"timestamp":"2024-06-01T17:52:25.379374Z"}]}
{"channel":"book","type":"update","data":[{"symbol":"ETH/USD","bids":[],"asks":[{"price":3797.15,"qty":0.77000000}],"checksum":1814518297,"timestamp":"2024-06-01T17:52:25.379462Z"}]}
{"channel":"book","type":"update","data":[{"symbol":"ETH/USD","bids":[],"asks":[{"price":3797.05,"qty":0.00000000},{"price":3797.59,"qty":3.00000000},{"price":3797.15,"qty":1.54000000}],"checksum":125443793,"timestamp":"2024-06-01T17:52:25.379713Z"}]}
{"channel":"book","type":"update","data":[{"symbol":"ETH/USD","bids":[{"price":3796.30,"qty":3.95083060}],"asks":[],"checksum":3110800715,"timestamp":"2024-06-01T17:52:25.391835Z"}]}
{"channel":"book","type":"update","data":[{"symbol":"ETH/USD","bids":[{"price":3795.91,"qty":15.80365539}],"asks":[],"checksum":4075262538,"timestamp":"2024-06-01T17:52:25.395441Z"}]}
{"channel":"book","type":"update","data":[{"symbol":"ETH/USD","bids":[],"asks":[{"price":3796.97,"qty":0.00000000},{"price":3797.90,"qty":0.52678018}],"checksum":1696494599,"timestamp":"2024-06-01T17:52:25.399468Z"}]}
{"channel":"book","type":"update","data":[{"symbol":"ETH/USD","bids":[{"price":3796.11,"qty":3.95083060}],"asks":[],"checksum":2306148876,"timestamp":"2024-06-01T17:52:25.403226Z"}]}
{"channel":"book","type":"update","data":[{"symbol":"ETH/USD","bids":[],"asks":[{"price":3796.92,"qty":26.33717169}],"checksum":2029645691,"timestamp":"2024-06-01T17:52:25.441969Z"}]}
{"channel":"book","type":"update","data":[{"symbol":"ETH/USD","bids":[],"asks":[{"price":3796.98,"qty":0.00000000},{"price":3797.90,"qty":0.52678018}],"checksum":4075991773,"timestamp":"2024-06-01T17:52:25.468142Z"}]}
{"channel":"book","type":"update","data":[{"symbol":"ETH/USD","bids":[{"price":3796.55,"qty":0.77000000}],"asks":[],"checksum":891387151,"timestamp":"2024-06-01T17:52:25.499866Z"}]}
{"channel":"book","type":"update","data":[{"symbol":"ETH/USD","bids":[],"asks":[{"price":3797.15,"qty":0.77000000}],"checksum":2929400672,"timestamp":"2024-06-01T17:52:25.502775Z"}]}
{"channel":"book","type":"update","data":[{"symbol":"ETH/USD","bids":[{"price":3796.55,"qty":0.00000000},{"price":3795.91,"qty":15.80365539},{"price":3796.44,"qty":0.77000000}],"asks":[],"checksum":279455974,"timestamp":"2024-06-01T17:52:25.604384Z"}]}
{"channel":"book","type":"update","data":[{"symbol":"ETH/USD","bids":[{"price":3796.44,"qty":1.54000000}],"asks":[],"checksum":721510740,"timestamp":"2024-06-01T17:52:25.607554Z"}]}
{"channel":"book","type":"update","data":[{"symbol":"ETH/USD","bids":[],"asks":[{"price":3797.04,"qty":0.77000000}],"checksum":3336829146,"timestamp":"2024-06-01T17:52:25.607614Z"}]}
{"channel":"book","type":"update","data":[{"symbol":"ETH/USD","bids":[],"asks":[{"price":3797.15,"qty":0.00000000},{"price":3797.90,"qty":0.52678018},{"price":3797.04,"qty":1.54000000}],"checksum":567711362,"timestamp":"2024-06-01T17:52:25.607629Z"}]}
{"channel":"book","type":"update","data":[{"symbol":"ETH/USD","bids":[{"price":3796.64,"qty":0.53201044}],"asks":[],"checksum":1147686471,"timestamp":"2024-06-01T17:52:25.699909Z"}]}
{"channel":"book","type":"update","data":[{"symbol":"ETH/USD","bids":[],"asks":[{"price":3797.00,"qty":26.33662148}],"checksum":2759831847,"timestamp":"2024-06-01T17:52:25.705192Z"}]}
{"channel":"book","type":"update","data":[{"symbol":"ETH/USD","bids":[{"price":3796.62,"qty":26.33920212}],"asks":[],"checksum":1680683457,"timestamp":"2024-06-01T17:52:25.705322Z"}]}
{"channel":"book","type":"update","data":[{"symbol":"ETH/USD","bids":[{"price":3796.60,"qty":0.00000000},{"price":3796.02,"qty":26.34333923},{"price":3796.63,"qty":0.00936789}],"asks":[],"checksum":3770168711,"timestamp":"2024-06-01T17:52:25.763017Z"}]}
{"channel":"book","type":"update","data":[{"symbol":"ETH/USD","bids":[{"price":3796.62,"qty":0.00000000},{"price":3796.02,"qty":26.34333923}],"asks":[],"checksum":1059329223,"timestamp":"2024-06-01T17:52:25.786227Z"}]}
{"channel":"book","type":"update","data":[{"symbol":"ETH/USD","bids":[{"price":3796.64,"qty":26.87108920}],"asks":[],"checksum":4067579743,"timestamp":"2024-06-01T17:52:25.790706Z"}]}
{"channel":"book","type":"update","data":[{"symbol":"ETH/USD","bids":[],"asks":[{"price":3796.92,"qty":0.00000000},{"price":3797.90,"qty":0.52678018}],"checksum":2725553477,"timestamp":"2024-06-01T17:52:25.804122Z"}]}
{"channel":"book","type":"update","data":[{"symbol":"ETH/USD","bids":[],"asks":[{"price":3796.94,"qty":26.33704000}],"checksum":491522124,"timestamp":"2024-06-01T17:52:25.808820Z"}]}
{"channel":"book","type":"update","data":[{"symbol":"ETH/USD","bids":[{"price":3796.63,"qty":0.00000000},{"price":3795.91,"qty":15.80365539},{"price":3796.60,"qty":0.00936797}],"asks":[],"checksum":2249698732,"timestamp":"2024-06-01T17:52:25.852812Z"}]}
{"channel":"book","type":"update","data":[{"symbol":"ETH/USD","bids":[],"asks":[{"price":3797.02,"qty":0.00000000},{"price":3797.90,"qty":0.52678018}],"checksum":1842425138,"timestamp":"2024-06-01T17:52:25.917229Z"}]}
{"channel":"book","type":"update","data":[{"symbol":"ETH/USD","bids":[],"asks":[{"price":3796.94,"qty":0.00000000},{"price":3797.97,"qty":3.00000000}],"checksum":577554120,"timestamp":"2024-06-01T17:52:26.006025Z"}]}
{"channel":"book","type":"update","data":[{"symbol":"ETH/USD","bids":[],"asks":[{"price":3796.93,"qty":26.33710590}],"checksum":16984261,"timestamp":"2024-06-01T17:52:26.010629Z"}]}
{"channel":"book","type":"update","data":[{"symbol":"ETH/USD","bids":[],"asks":[{"price":3796.93,"qty":0.00000000},{"price":3797.97,"qty":3.00000000}],"checksum":577554120,"timestamp":"2024-06-01T17:52:26.056325Z"}]}
{"channel":"book","type":"update","data":[{"symbol":"ETH/USD","bids":[],"asks":[{"price":3796.92,"qty":26.33718492}],"checksum":188782443,"timestamp":"2024-06-01T17:52:26.061812Z"}]}
{"channel":"book","type":"update","data":[{"symbol":"ETH/USD","bids":[{"price":3796.64,"qty":0.53201044}],"asks":[],"checksum":3620395739,"timestamp":"2024-06-01T17:52:26.338899Z"}]}
{"channel":"book","type":"update","data":[{"symbol":"ETH/USD","bids":[{"price":3796.62,"qty":26.33921185}],"asks":[],"checksum":1848648927,"timestamp":"2024-06-01T17:52:26.343290Z"}]}
{"channel":"book","type":"update","data":[{"symbol":"ETH/USD","bids":[{"price":3796.60,"qty":0.00000000},{"price":3796.02,"qty":26.34333923},{"price":3796.63,"qty":0.00936866}],"asks":[],"checksum":3727368612,"timestamp":"2024-06-01T17:52:26.388591Z"}]}
{"channel":"book","type":"update","data":[{"symbol":"ETH/USD","bids":[],"asks":[{"price":3796.92,"qty":0.00000000},{"price":3797.97,"qty":3.00000000}],"checksum":1238634483,"timestamp":"2024-06-01T17:52:26.399303Z"}]}
{"channel":"book","type":"update","data":[{"symbol":"ETH/USD","bids":[],"asks":[{"price":3796.90,"qty":26.33728092}],"checksum":2747532203,"timestamp":"2024-06-01T17:52:26.406263Z"}]}
{"channel":"book","type":"update","data":[{"symbol":"ETH/USD","bids":[],"asks":[{"price":3796.90,"qty":0.00000000},{"price":3797.97,"qty":3.00000000}],"checksum":1238634483,"timestamp":"2024-06-01T17:52:26.650658Z"}]}
{"channel":"book","type":"update","data":[{"symbol":"ETH/USD","bids":[],"asks":[{"price":3796.92,"qty":26.33714981}],"checksum":65161758,"timestamp":"2024-06-01T17:52:26.656160Z"}]}
{"channel":"book","type":"update","data":[{"symbol":"ETH/USD","bids":[{"price":3796.62,"qty":0.00000000},{"price":3796.02,"qty":26.34333923}],"asks":[],"checksum":3057402294,"timestamp":"2024-06-01T17:52:26.680684Z"}]}
{"channel":"book","type":"update","data":[{"symbol":"ETH/USD","bids":[{"price":3796.63,"qty":26.34846607}],"asks":[],"checksum":3891092116,"timestamp":"2024-06-01T17:52:26.684654Z"}]}
{"channel":"book","type":"update","data":[{"symbol":"ETH/USD","bids":[{"price":3796.63,"qty":26.33909741},{"price":3796.64,"qty":0.54137908}],"asks":[],"checksum":2636363720,"timestamp":"2024-06-01T17:52:26.862329Z"}]}
{"channel":"book","type":"update","data":[{"symbol":"ETH/USD","bids":[{"price":3796.30,"qty":0.00000000},{"price":3795.91,"qty":15.80365539}],"asks":[],"checksum":2324695041,"timestamp":"2024-06-01T17:52:26.888786Z"}]}
{"channel":"book","type":"update","data":[{"symbol":"ETH/USD","bids":[],"asks":[{"price":3796.92,"qty":0.00000000},{"price":3797.97,"qty":3.00000000}],"checksum":3698236877,"timestamp":"2024-06-01T17:52:27.117272Z"}]}
{"channel":"book","type":"update","data":[{"symbol":"ETH/USD","bids":[],"asks":[{"price":3796.95,"qty":26.33694609}],"checksum":4248698088,"timestamp":"2024-06-01T17:52:27.121539Z"}]}
{"channel":"book","type":"update","data":[{"symbol":"ETH/USD","bids":[],"asks":[{"price":3796.95,"qty":0.00000000},{"price":3797.97,"qty":3.00000000}],"checksum":3698236877,"timestamp":"2024-06-01T17:52:27.189950Z"}]}
{"channel":"book","type":"update","data":[{"symbol":"ETH/USD","bids":[],"asks":[{"price":3796.93,"qty":26.33707515}],"checksum":396033520,"timestamp":"2024-06-01T17:52:27.194524Z"}]}
{"channel":"book","type":"update","data":[{"symbol":"ETH/USD","bids":[{"price":3796.30,"qty":3.95083060}],"asks":[],"checksum":1168238925,"timestamp":"2024-06-01T17:52:27.289111Z"}]}
{"channel":"book","type":"update","data":[{"symbol":"ETH/USD","bids":[{"price":3796.59,"qty":42.14247438}],"asks":[],"checksum":1371150136,"timestamp":"2024-06-01T17:52:27.289378Z"}]}
{"channel":"book","type":"update","data":[{"symbol":"ETH/USD","bids":[],"asks":[{"price":3796.93,"qty":0.00000000},{"price":3797.97,"qty":3.00000000}],"checksum":3295258248,"timestamp":"2024-06-01T17:52:27.401465Z"}]}
{"channel":"book","type":"update","data":[{"symbol":"ETH/USD","bids":[],"asks":[{"price":3796.92,"qty":26.33718074}],"checksum":3441830081,"timestamp":"2024-06-01T17:52:27.406548Z"}]}
{"channel":"book","type":"update","data":[{"symbol":"ETH/USD","bids":[{"price":3796.44,"qty":0.77000000}],"asks":[],"checksum":1421720745,"timestamp":"2024-06-01T17:52:27.604393Z"}]}
{"channel":"book","type":"update","data":[{"symbol":"ETH/USD","bids":[],"asks":[{"price":3797.04,"qty":0.77000000}],"checksum":4220088002,"timestamp":"2024-06-01T17:52:27.607401Z"}]}
{"channel":"book","type":"update","data":[{"symbol":"ETH/USD","bids":[],"asks":[{"price":3796.92,"qty":0.00000000},{"price":3797.97,"qty":3.00000000}],"checksum":354227559,"timestamp":"2024-06-01T17:52:27.914160Z"}]}
{"channel":"book","type":"update","data":[{"symbol":"ETH/USD","bids":[],"asks":[{"price":3796.91,"qty":26.33724659}],"checksum":946000846,"timestamp":"2024-06-01T17:52:27.918273Z"}]}
{"channel":"book","type":"update","data":[{"symbol":"ETH/USD","bids":[],"asks":[{"price":3796.91,"qty":0.00000000},{"price":3797.97,"qty":3.00000000}],"checksum":354227559,"timestamp":"2024-06-01T17:52:28.061457Z"}]}
{"channel":"book","type":"update","data":[{"symbol":"ETH/USD","bids":[],"asks":[{"price":3796.93,"qty":26.33710852}],"checksum":3273617637,"timestamp":"2024-06-01T17:52:28.065808Z"}]}
{"channel":"book","type":"update","data":[{"symbol":"ETH/USD","bids":[],"asks":[{"price":3796.93,"qty":0.00000000},{"price":3797.97,"qty":3.00000000}],"checksum":354227559,"timestamp":"2024-06-01T17:52:28.270692Z"}]}
{"channel":"book","type":"update","data":[{"symbol":"ETH/USD","bids":[{"price":3796.03,"qty":0.76629138}],"asks":[],"checksum":290308750,"timestamp":"2024-06-01T17:52:28.273031Z"}]}
{"channel":"book","type":"update","data":[{"symbol":"ETH/USD","bids":[],"asks":[{"price":3796.92,"qty":26.33716647}],"checksum":1392084321,"timestamp":"2024-06-01T17:52:28.275007Z"}]}
{"channel":"book","type":"update","data":[{"symbol":"ETH/USD","bids":[],"asks":[{"price":3796.92,"qty":0.00000000},{"price":3797.97,"qty":3.00000000}],"checksum":290308750,"timestamp":"2024-06-01T17:52:28.578108Z"}]}
{"channel":"book","type":"update","data":[{"symbol":"ETH/USD","bids":[],"asks":[{"price":3796.94,"qty":26.33702927}],"checksum":2394731124,"timestamp":"2024-06-01T17:52:28.582479Z"}]}
{"channel":"book","type":"update","data":[{"symbol":"ETH/USD","bids":[],"asks":[{"price":3797.04,"qty":0.00000000},{"price":3797.97,"qty":3.00000000}],"checksum":1947378793,"timestamp":"2024-06-01T17:52:28.590268Z"}]}
{"channel":"book","type":"update","data":[{"symbol":"ETH/USD","bids":[],"asks":[{"price":3797.03,"qty":0.77000000}],"checksum":3154021342,"timestamp":"2024-06-01T17:52:28.744013Z"}]}
{"channel":"book","type":"update","data":[{"symbol":"ETH/USD","bids":[],"asks":[{"price":3796.94,"qty":0.00000000},{"price":3797.97,"qty":3.00000000}],"checksum":3839602621,"timestamp":"2024-06-01T17:52:29.283085Z"}]}
{"channel":"book","type":"update","data":[{"symbol":"ETH/USD","bids":[],"asks":[{"price":3796.91,"qty":26.33721020}],"checksum":637505066,"timestamp":"2024-06-01T17:52:29.287674Z"}]}
{"channel":"book","type":"update","data":[{"symbol":"ETH/USD","bids":[],"asks":[{"price":3797.03,"qty":0.00000000},{"price":3797.97,"qty":3.00000000},{"price":3797.12,"qty":0.77000000}],"checksum":2943889675,"timestamp":"2024-06-01T17:52:29.387226Z"}]}
{"channel":"book","type":"update","data":[{"symbol":"ETH/USD","bids":[],"asks":[{"price":3797.12,"qty":1.54000000}],"checksum":340905910,"timestamp":"2024-06-01T17:52:29.391330Z"}]}
{"channel":"book","type":"update","data":[{"symbol":"ETH/USD","bids":[],"asks":[{"price":3797.12,"qty":0.77000000}],"checksum":2943889675,"timestamp":"2024-06-01T17:52:29.401685Z"}]}
{"channel":"book","type":"update","data":[{"symbol":"ETH/USD","bids":[],"asks":[{"price":3797.12,"qty":0.00000000},{"price":3797.97,"qty":3.00000000}],"checksum":3462173545,"timestamp":"2024-06-01T17:52:29.403567Z"}]}
{"channel":"book","type":"update","data":[{"symbol":"ETH/USD","bids":[],"asks":[{"price":3796.91,"qty":0.00000000},{"price":3798.02,"qty":0.01092321}],"checksum":716611087,"timestamp":"2024-06-01T17:52:29.562657Z"}]}
{"channel":"book","type":"update","data":[{"symbol":"ETH/USD","bids":[],"asks":[{"price":3796.93,"qty":26.33706943}],"checksum":480832133,"timestamp":"2024-06-01T17:52:29.567487Z"}]}
{"channel":"book","type":"update","data":[{"symbol":"ETH/USD","bids":[{"price":3796.44,"qty":0.00000000},{"price":3796.02,"qty":26.34333923},{"price":3796.55,"qty":0.77000000}],"asks":[],"checksum":3892075559,"timestamp":"2024-06-01T17:52:29.664539Z"}]}
{"channel":"book","type":"update","data":[{"symbol":"ETH/USD","bids":[{"price":3796.55,"qty":1.54000000}],"asks":[],"checksum":257202269,"timestamp":"2024-06-01T17:52:29.669771Z"}]}
{"channel":"book","type":"update","data":[{"symbol":"ETH/USD","bids":[],"asks":[{"price":3797.16,"qty":0.77000000}],"checksum":806037252,"timestamp":"2024-06-01T17:52:29.670031Z"}]}
{"channel":"book","type":"update","data":[{"symbol":"ETH/USD","bids":[],"asks":[{"price":3797.16,"qty":0.00000000},{"price":3797.97,"qty":3.00000000}],"checksum":257202269,"timestamp":"2024-06-01T17:52:29.672709Z"}]}
{"channel":"book","type":"update","data":[{"symbol":"ETH/USD","bids":[{"price":3796.55,"qty":0.77000000}],"asks":[],"checksum":3892075559,"timestamp":"2024-06-01T17:52:29.725462Z"}]}
{"channel":"book","type":"update","data":[{"symbol":"ETH/USD","bids":[],"asks":[{"price":3796.93,"qty":0.00000000},{"price":3798.02,"qty":0.01092321}],"checksum":3521259693,"timestamp":"2024-06-01T17:52:29.806909Z"}]}
{"channel":"book","type":"update","data":[{"symbol":"ETH/USD","bids":[],"asks":[{"price":3796.97,"qty":26.33681867}],"checksum":606033747,"timestamp":"2024-06-01T17:52:29.811813Z"}]}
{"channel":"book","type":"update","data":[{"symbol":"ETH/USD","bids":[{"price":3796.55,"qty":0.00000000},{"price":3796.02,"qty":26.34333923},{"price":3796.45,"qty":0.77000000}],"asks":[],"checksum":2866030444,"timestamp":"2024-06-01T17:52:29.824496Z"}]}
{"channel":"book","type":"update","data":[{"symbol":"ETH/USD","bids":[{"price":3796.45,"qty":1.54000000}],"asks":[],"checksum":3994495038,"timestamp":"2024-06-01T17:52:29.827591Z"}]}
{"channel":"book","type":"update","data":[{"symbol":"ETH/USD","bids":[],"asks":[{"price":3797.05,"qty":0.77000000}],"checksum":2547483352,"timestamp":"2024-06-01T17:52:29.827689Z"}]}
{"channel":"book","type":"update","data":[{"symbol":"ETH/USD","bids":[],"asks":[{"price":3797.05,"qty":0.00000000},{"price":3797.97,"qty":3.00000000}],"checksum":3994495038,"timestamp":"2024-06-01T17:52:29.833608Z"}]}
{"channel":"book","type":"update","data":[{"symbol":"ETH/USD","bids":[],"asks":[{"price":3797.05,"qty":0.77000000}],"checksum":2547483352,"timestamp":"2024-06-01T17:52:29.838667Z"}]}
{"channel":"book","type":"update","data":[{"symbol":"ETH/USD","bids":[{"price":3796.45,"qty":0.77000000}],"asks":[],"checksum":3066455397,"timestamp":"2024-06-01T17:52:30.195861Z"}]}
{"channel":"book","type":"update","data":[{"symbol":"ETH/USD","bids":[],"asks":[{"price":3796.97,"qty":0.00000000},{"price":3797.97,"qty":3.00000000}],"checksum":2362689667,"timestamp":"2024-06-01T17:52:30.221789Z"}]}
{"channel":"book","type":"update","data":[{"symbol":"ETH/USD","bids":[],"asks":[{"price":3797.03,"qty":26.33639801}],"checksum":707357323,"timestamp":"2024-06-01T17:52:30.226839Z"}]}
{"channel":"book","type":"update","data":[{"symbol":"ETH/USD","bids":[],"asks":[{"price":3797.31,"qty":0.00000000},{"price":3797.97,"qty":3.00000000}],"checksum":2910130100,"timestamp":"2024-06-01T17:52:30.231792Z"}]}
{"channel":"book","type":"update","data":[{"symbol":"ETH/USD","bids":[],"asks":[{"price":3797.71,"qty":0.72912968}],"checksum":2634828804,"timestamp":"2024-06-01T17:52:30.231824Z"}]}
{"channel":"book","type":"update","data":[{"symbol":"ETH/USD","bids":[],"asks":[{"price":3797.00,"qty":0.00000000},{"price":3797.97,"qty":3.00000000}],"checksum":2478806616,"timestamp":"2024-06-01T17:52:30.264844Z"}]}
{"channel":"book","type":"update","data":[{"symbol":"ETH/USD","bids":[],"asks":[{"price":3797.03,"qty":0.00000000},{"price":3798.02,"qty":0.01092321}],"checksum":4038112459,"timestamp":"2024-06-01T17:52:30.264860Z"}]}
{"channel":"book","type":"update","data":[{"symbol":"ETH/USD","bids":[{"price":3796.19,"qty":26.34214115}],"asks":[],"checksum":2644451561,"timestamp":"2024-06-01T17:52:30.270458Z"}]}
{"channel":"book","type":"update","data":[{"symbol":"ETH/USD","bids":[],"asks":[{"price":3797.34,"qty":26.33429275}],"checksum":1842816586,"timestamp":"2024-06-01T17:52:30.270523Z"}]}
{"channel":"book","type":"update","data":[{"symbol":"ETH/USD","bids":[{"price":3796.64,"qty":3.54137908}],"asks":[],"checksum":582471457,"timestamp":"2024-06-01T17:52:30.304373Z"}]}
{"channel":"book","type":"update","data":[{"symbol":"ETH/USD","bids":[{"price":3796.45,"qty":0.00000000},{"price":3796.03,"qty":0.76629138},{"price":3796.58,"qty":0.77000000}],"asks":[],"checksum":2644791039,"timestamp":"2024-06-01T17:52:30.305610Z"}]}
{"channel":"book","type":"update","data":[{"symbol":"ETH/USD","bids":[{"price":3796.58,"qty":1.54000000}],"asks":[],"checksum":901598657,"timestamp":"2024-06-01T17:52:30.308717Z"}]}
{"channel":"book","type":"update","data":[{"symbol":"ETH/USD","bids":[],"asks":[{"price":3797.05,"qty":0.00000000},{"price":3798.02,"qty":0.01092321},{"price":3797.17,"qty":0.77000000}],"checksum":2975812292,"timestamp":"2024-06-01T17:52:30.308867Z"}]}
{"channel":"book","type":"update","data":[{"symbol":"ETH/USD","bids":[{"price":3796.58,"qty":0.77000000}],"asks":[],"checksum":3252852204,"timestamp":"2024-06-01T17:52:30.309154Z"}]}
{"channel":"book","type":"update","data":[{"symbol":"ETH/USD","bids":[],"asks":[{"price":3797.17,"qty":0.00000000},{"price":3798.02,"qty":0.01092321}],"checksum":3907596257,"timestamp":"2024-06-01T17:52:30.318169Z"}]}
{"channel":"book","type":"update","data":[{"symbol":"ETH/USD","bids":[],"asks":[{"price":3797.23,"qty":0.00000000},{"price":3798.03,"qty":0.01091807}],"checksum":2314772847,"timestamp":"2024-06-01T17:52:30.319503Z"}]}
{"channel":"book","type":"update","data":[{"symbol":"ETH/USD","bids":[],"asks":[{"price":3797.06,"qty":26.33620987}],"checksum":1707909072,"timestamp":"2024-06-01T17:52:30.323808Z"}]}
{"channel":"book","type":"update","data":[{"symbol":"ETH/USD","bids":[],"asks":[{"price":3797.22,"qty":0.77000000}],"checksum":3836425079,"timestamp":"2024-06-01T17:52:30.351745Z"}]}
{"channel":"book","type":"update","data":[{"symbol":"ETH/USD","bids":[],"asks":[{"price":3797.06,"qty":0.00000000},{"price":3798.02,"qty":0.01092321}],"checksum":2281969507,"timestamp":"2024-06-01T17:52:30.367736Z"}]}
{"channel":"book","type":"update","data":[{"symbol":"ETH/USD","bids":[{"price":3796.64,"qty":0.54137908}],"asks":[],"checksum":2830136009,"timestamp":"2024-06-01T17:52:30.397011Z"}]}
{"channel":"book","type":"update","data":[{"symbol":"ETH/USD","bids":[],"asks":[{"price":3797.17,"qty":26.33546922}],"checksum":1926907753,"timestamp":"2024-06-01T17:52:30.413221Z"}]}
{"channel":"book","type":"update","data":[{"symbol":"ETH/USD","bids":[],"asks":[{"price":3797.07,"qty":26.33611506}],"checksum":4244305361,"timestamp":"2024-06-01T17:52:30.413449Z"}]}
{"channel":"book","type":"update","data":[{"symbol":"ETH/USD","bids":[],"asks":[{"price":3797.07,"qty":0.00000000},{"price":3797.97,"qty":3.00000000}],"checksum":1926907753,"timestamp":"2024-06-01T17:52:30.422386Z"}]}
{"channel":"book","type":"update","data":[{"symbol":"ETH/USD","bids":[{"price":3796.41,"qty":0.00000000},{"price":3796.03,"qty":0.76629138}],"asks":[],"checksum":1137770275,"timestamp":"2024-06-01T17:52:30.422443Z"}]}
{"channel":"book","type":"update","data":[{"symbol":"ETH/USD","bids":[{"price":3796.64,"qty":16.34382741}],"asks":[],"checksum":1842346381,"timestamp":"2024-06-01T17:52:30.427814Z"}]}
{"channel":"book","type":"update","data":[{"symbol":"ETH/USD","bids":[{"price":3796.54,"qty":26.33970430}],"asks":[],"checksum":820906013,"timestamp":"2024-06-01T17:52:30.428090Z"}]}
{"channel":"book","type":"update","data":[{"symbol":"ETH/USD","bids":[{"price":3796.29,"qty":0.00000000},{"price":3796.03,"qty":0.76629138}],"asks":[],"checksum":2600303926,"timestamp":"2024-06-01T17:52:30.432424Z"}]}
{"channel":"book","type":"update","data":[{"symbol":"ETH/USD","bids":[],"asks":[{"price":3797.09,"qty":26.33599433}],"checksum":1383886277,"timestamp":"2024-06-01T17:52:30.472846Z"}]}
{"channel":"book","type":"update","data":[{"symbol":"ETH/USD","bids":[],"asks":[{"price":3797.42,"qty":0.00000000},{"price":3797.97,"qty":3.00000000}],"checksum":218034142,"timestamp":"2024-06-01T17:52:30.763341Z"}]}
{"channel":"book","type":"update","data":[{"symbol":"ETH/USD","bids":[],"asks":[{"price":3796.65,"qty":0.00000000},{"price":3798.02,"qty":0.01092321}],"checksum":2047312591,"timestamp":"2024-06-01T17:52:30.764275Z"}]}
{"channel":"book","type":"update","data":[{"symbol":"ETH/USD","bids":[{"price":3796.64,"qty":19.34382741}],"asks":[],"checksum":637499378,"timestamp":"2024-06-01T17:52:30.764344Z"}]}
{"channel":"book","type":"update","data":[{"symbol":"ETH/USD","bids":[{"price":3796.64,"qty":22.34382741}],"asks":[],"checksum":2289707533,"timestamp":"2024-06-01T17:52:30.764852Z"}]}
{"channel":"book","type":"update","data":[{"symbol":"ETH/USD","bids":[],"asks":[{"price":3797.22,"qty":0.00000000},{"price":3798.03,"qty":0.01091807}],"checksum":1932281967,"timestamp":"2024-06-01T17:52:30.765152Z"}]}
{"channel":"book","type":"update","data":[{"symbol":"ETH/USD","bids":[],"asks":[{"price":3797.59,"qty":0.00000000},{"price":3798.07,"qty":1.30862124}],"checksum":2295657672,"timestamp":"2024-06-01T17:52:30.766297Z"}]}
{"channel":"book","type":"update","data":[{"symbol":"ETH/USD","bids":[],"asks":[{"price":3797.71,"qty":0.00000000},{"price":3798.08,"qty":68.14933373}],"checksum":2952421849,"timestamp":"2024-06-01T17:52:30.766979Z"}]}
{"channel":"book","type":"update","data":[{"symbol":"ETH/USD","bids":[{"price":3796.08,"qty":0.00000000},{"price":3795.90,"qty":8.27100000}],"asks":[],"checksum":1288816109,"timestamp":"2024-06-01T17:52:30.767827Z"}]}
{"channel":"book","type":"update","data":[{"symbol":"ETH/USD","bids":[{"price":3796.77,"qty":3.00000000}],"asks":[],"checksum":3878286198,"timestamp":"2024-06-01T17:52:30.767842Z"}]}
{"channel":"book","type":"update","data":[{"symbol":"ETH/USD","bids":[],"asks":[{"price":3797.47,"qty":0.81285127}],"checksum":2664430539,"timestamp":"2024-06-01T17:52:30.767866Z"}]}
{"channel":"book","type":"update","data":[{"symbol":"ETH/USD","bids":[{"price":3796.64,"qty":21.81704584},{"price":3796.65,"qty":0.52678018}],"asks":[],"checksum":3809823585,"timestamp":"2024-06-01T17:52:30.769163Z"}]}
{"channel":"book","type":"update","data":[{"symbol":"ETH/USD","bids":[],"asks":[{"price":3797.48,"qty":0.00000000},{"price":3798.08,"qty":68.14933373}],"checksum":2300514370,"timestamp":"2024-06-01T17:52:30.775386Z"}]}
{"channel":"book","type":"update","data":[{"symbol":"ETH/USD","bids":[{"price":3796.63,"qty":0.00000000},{"price":3796.03,"qty":0.76629138}],"asks":[],"checksum":3639324429,"timestamp":"2024-06-01T17:52:30.775396Z"}]}
{"channel":"book","type":"update","data":[{"symbol":"ETH/USD","bids":[],"asks":[{"price":3797.09,"qty":0.00000000},{"price":3798.09,"qty":10.81226191}],"checksum":1842459782,"timestamp":"2024-06-01T17:52:30.775437Z"}]}
{"channel":"book","type":"update","data":[{"symbol":"ETH/USD","bids":[{"price":3796.59,"qty":15.80307264}],"asks":[],"checksum":3303364965,"timestamp":"2024-06-01T17:52:30.775635Z"}]}
{"channel":"book","type":"update","data":[{"symbol":"ETH/USD","bids":[{"price":3796.54,"qty":0.00000000},{"price":3795.90,"qty":8.27100000}],"asks":[],"checksum":1118307059,"timestamp":"2024-06-01T17:52:30.778871Z"}]}
{"channel":"book","type":"update","data":[{"symbol":"ETH/USD","bids":[],"asks":[{"price":3797.34,"qty":0.00000000},{"price":3798.12,"qty":0.15000000}],"checksum":3967175542,"timestamp":"2024-06-01T17:52:30.779763Z"}]}
{"channel":"book","type":"update","data":[{"symbol":"ETH/USD","bids":[{"price":3796.19,"qty":0.00000000},{"price":3795.79,"qty":3.40262063}],"asks":[],"checksum":2091513030,"timestamp":"2024-06-01T17:52:30.779782Z"}]}
{"channel":"book","type":"update","data":[{"symbol":"ETH/USD","bids":[],"asks":[{"price":3797.17,"qty":0.00000000},{"price":3798.15,"qty":0.00985404}],"checksum":676231588,"timestamp":"2024-06-01T17:52:30.779792Z"}]}
{"channel":"book","type":"update","data":[{"symbol":"ETH/USD","bids":[],"asks":[{"price":3797.88,"qty":3.30000000}],"checksum":1828477632,"timestamp":"2024-06-01T17:52:30.784656Z"}]}
{"channel":"book","type":"update","data":[{"symbol":"ETH/USD","bids":[{"price":3797.08,"qty":26.33602663}],"asks":[],"checksum":3974285538,"timestamp":"2024-06-01T17:52:30.787946Z"}]}
{"channel":"book","type":"update","data":[{"symbol":"ETH/USD","bids":[],"asks":[{"price":3797.54,"qty":26.33283805}],"checksum":3178780878,"timestamp":"2024-06-01T17:52:30.787958Z"}]}
{"channel":"book","type":"update","data":[{"symbol":"ETH/USD","bids":[],"asks":[{"price":3797.81,"qty":26.33097717}],"checksum":125565161,"timestamp":"2024-06-01T17:52:30.788005Z"}]}
{"channel":"book","type":"update","data":[{"symbol":"ETH/USD","bids":[],"asks":[{"price":3797.66,"qty":26.33204758}],"checksum":3465077148,"timestamp":"2024-06-01T17:52:30.788026Z"}]}
{"channel":"book","type":"update","data":[{"symbol":"ETH/USD","bids":[{"price":3797.16,"qty":26.33547177}],"asks":[],"checksum":488095584,"timestamp":"2024-06-01T17:52:30.788039Z"}]}
{"channel":"book","type":"update","data":[{"symbol":"ETH/USD","bids":[],"asks":[{"price":3797.90,"qty":0.00000000},{"price":3798.08,"qty":68.14933373},{"price":3797.47,"qty":1.33951770}],"checksum":2679067490,"timestamp":"2024-06-01T17:52:30.791029Z"}]}
{"channel":"book","type":"update","data":[{"symbol":"ETH/USD","bids":[{"price":3796.58,"qty":0.00000000},{"price":3795.90,"qty":8.27100000},{"price":3796.79,"qty":0.77000000}],"asks":[],"checksum":2843111094,"timestamp":"2024-06-01T17:52:30.791720Z"}]}
{"channel":"book","type":"update","data":[{"symbol":"ETH/USD","bids":[{"price":3796.78,"qty":0.05267543}],"asks":[],"checksum":3324462645,"timestamp":"2024-06-01T17:52:30.792767Z"}]}
{"channel":"book","type":"update","data":[{"symbol":"ETH/USD","bids":[{"price":3796.78,"qty":0.05786342}],"asks":[],"checksum":2862896187,"timestamp":"2024-06-01T17:52:30.794336Z"}]}
{"channel":"book","type":"update","data":[{"symbol":"ETH/USD","bids":[{"price":3796.64,"qty":21.81181697}],"asks":[],"checksum":3623365496,"timestamp":"2024-06-01T17:52:30.794376Z"}]}
{"channel":"book","type":"update","data":[{"symbol":"ETH/USD","bids":[{"price":3796.66,"qty":3.95061208}],"asks":[],"checksum":1349764379,"timestamp":"2024-06-01T17:52:30.794655Z"}]}
{"channel":"book","type":"update","data":[{"symbol":"ETH/USD","bids":[{"price":3796.79,"qty":1.54000000}],"asks":[],"checksum":3180940723,"timestamp":"2024-06-01T17:52:30.794733Z"}]}
{"channel":"book","type":"update","data":[{"symbol":"ETH/USD","bids":[{"price":3796.79,"qty":0.77000000}],"asks":[],"checksum":1349764379,"timestamp":"2024-06-01T17:52:30.794823Z"}]}
{"channel":"book","type":"update","data":[{"symbol":"ETH/USD","bids":[{"price":3796.78,"qty":0.00518799}],"asks":[],"checksum":2554536569,"timestamp":"2024-06-01T17:52:30.795823Z"}]}
{"channel":"book","type":"update","data":[{"symbol":"ETH/USD","bids":[],"asks":[{"price":3797.47,"qty":0.81285127},{"price":3797.46,"qty":0.52666782}],"checksum":852968805,"timestamp":"2024-06-01T17:52:30.796925Z"}]}
{"channel":"book","type":"update","data":[{"symbol":"ETH/USD","bids":[{"price":3796.30,"qty":0.00000000},{"price":3796.11,"qty":3.95083060}],"asks":[],"checksum":2239338394,"timestamp":"2024-06-01T17:52:30.798888Z"}]}
{"channel":"book","type":"update","data":[{"symbol":"ETH/USD","bids":[],"asks":[{"price":3797.46,"qty":1.52666782}],"checksum":940936432,"timestamp":"2024-06-01T17:52:30.799800Z"}]}
{"channel":"book","type":"update","data":[{"symbol":"ETH/USD","bids":[{"price":3797.08,"qty":0.00000000},{"price":3796.03,"qty":0.76629138}],"asks":[],"checksum":3206348446,"timestamp":"2024-06-01T17:52:30.800708Z"}]}
{"channel":"book","type":"update","data":[{"symbol":"ETH/USD","bids":[{"price":3797.16,"qty":0.00000000},{"price":3795.90,"qty":8.27100000}],"asks":[],"checksum":4116648969,"timestamp":"2024-06-01T17:52:30.800902Z"}]}
{"channel":"book","type":"update","data":[{"symbol":"ETH/USD","bids":[],"asks":[{"price":3797.54,"qty":0.00000000},{"price":3798.08,"qty":68.14933373}],"checksum":4260555483,"timestamp":"2024-06-01T17:52:30.800971Z"}]}
{"channel":"book","type":"update","data":[{"symbol":"ETH/USD","bids":[],"asks":[{"price":3797.66,"qty":0.00000000},{"price":3798.09,"qty":10.81226191}],"checksum":2858324649,"timestamp":"2024-06-01T17:52:30.801038Z"}]}
{"channel":"book","type":"update","data":[{"symbol":"ETH/USD","bids":[{"price":3795.93,"qty":0.72912968}],"asks":[],"checksum":2085230033,"timestamp":"2024-06-01T17:52:30.802753Z"}]}
{"channel":"book","type":"update","data":[{"symbol":"ETH/USD","bids":[{"price":3796.80,"qty":0.05266961}],"asks":[],"checksum":3018599050,"timestamp":"2024-06-01T17:52:30.807005Z"}]}
{"channel":"book","type":"update","data":[{"symbol":"ETH/USD","bids":[],"asks":[{"price":3797.47,"qty":0.00000000},{"price":3798.12,"qty":0.15000000}],"checksum":4291788011,"timestamp":"2024-06-01T17:52:30.807275Z"}]}
{"channel":"book","type":"update","data":[{"symbol":"ETH/USD","bids":[{"price":3796.79,"qty":0.00000000},{"price":3795.93,"qty":0.72912968},{"price":3796.97,"qty":0.77000000}],"asks":[],"checksum":621040700,"timestamp":"2024-06-01T17:52:30.807314Z"}]}
{"channel":"book","type":"update","data":[{"symbol":"ETH/USD","bids":[{"price":3796.64,"qty":21.80244833},{"price":3796.78,"qty":0.01455545}],"asks":[],"checksum":2859443364,"timestamp":"2024-06-01T17:52:30.808066Z"}]}
{"channel":"book","type":"update","data":[{"symbol":"ETH/USD","bids":[{"price":3796.78,"qty":26.35266300}],"asks":[],"checksum":4006736526,"timestamp":"2024-06-01T17:52:30.808417Z"}]}
{"channel":"book","type":"update","data":[{"symbol":"ETH/USD","bids":[],"asks":[{"price":3797.46,"qty":1.00000000},{"price":3797.45,"qty":0.52666921}],"checksum":1464073028,"timestamp":"2024-06-01T17:52:30.809110Z"}]}
{"channel":"book","type":"update","data":[{"symbol":"ETH/USD","bids":[{"price":3796.97,"qty":1.54000000}],"asks":[],"checksum":249613660,"timestamp":"2024-06-01T17:52:30.811021Z"}]}
{"channel":"book","type":"update","data":[{"symbol":"ETH/USD","bids":[{"price":3796.64,"qty":18.80244833}],"asks":[],"checksum":1684864106,"timestamp":"2024-06-01T17:52:30.811159Z"}]}
{"channel":"book","type":"update","data":[{"symbol":"ETH/USD","bids":[{"price":3796.97,"qty":0.77000000}],"asks":[],"checksum":1037027954,"timestamp":"2024-06-01T17:52:30.812346Z"}]}
{"channel":"book","type":"update","data":[{"symbol":"ETH/USD","bids":[{"price":3796.84,"qty":3.00000000}],"asks":[],"checksum":3693437578,"timestamp":"2024-06-01T17:52:30.813361Z"}]}
{"channel":"book","type":"update","data":[{"symbol":"ETH/USD","bids":[{"price":3796.80,"qty":0.00000000},{"price":3796.03,"qty":0.76629138}],"asks":[],"checksum":2393701701,"timestamp":"2024-06-01T17:52:30.814488Z"}]}
{"channel":"book","type":"update","data":[{"symbol":"ETH/USD","bids":[],"asks":[{"price":3797.45,"qty":0.00000000},{"price":3798.12,"qty":0.15000000}],"checksum":2022594671,"timestamp":"2024-06-01T17:52:30.814731Z"}]}
{"channel":"book","type":"update","data":[{"symbol":"ETH/USD","bids":[{"price":3796.79,"qty":0.05266963}],"asks":[],"checksum":779289916,"timestamp":"2024-06-01T17:52:30.817608Z"}]}
{"channel":"book","type":"update","data":[{"symbol":"ETH/USD","bids":[{"price":3796.85,"qty":0.05266963}],"asks":[],"checksum":3159698665,"timestamp":"2024-06-01T17:52:30.818269Z"}]}
{"channel":"book","type":"update","data":[{"symbol":"ETH/USD","bids":[{"price":3796.79,"qty":0.00000000},{"price":3796.11,"qty":3.95083060}],"asks":[],"checksum":2358161088,"timestamp":"2024-06-01T17:52:30.821053Z"}]}
{"channel":"book","type":"update","data":[{"symbol":"ETH/USD","bids":[],"asks":[{"price":3797.81,"qty":0.00000000},{"price":3798.15,"qty":0.00985404}],"checksum":198125776,"timestamp":"2024-06-01T17:52:30.824184Z"}]}
{"channel":"book","type":"update","data":[{"symbol":"ETH/USD","bids":[],"asks":[{"price":3797.46,"qty":0.00000000},{"price":3798.19,"qty":0.19621000}],"checksum":4213328791,"timestamp":"2024-06-01T17:52:30.830652Z"}]}
{"channel":"book","type":"update","data":[{"symbol":"ETH/USD","bids":[],"asks":[{"price":3797.80,"qty":1.00000000}],"checksum":3509420684,"timestamp":"2024-06-01T17:52:30.830916Z"}]}
{"channel":"book","type":"update","data":[{"symbol":"ETH/USD","bids":[],"asks":[{"price":3797.87,"qty":0.81285127}],"checksum":1162430592,"timestamp":"2024-06-01T17:52:30.834079Z"}]}
{"channel":"book","type":"update","data":[{"symbol":"ETH/USD","bids":[],"asks":[{"price":3798.09,"qty":0.00000000},{"price":3798.15,"qty":0.00985404}],"checksum":4247391793,"timestamp":"2024-06-01T17:52:30.834312Z"}]}
{"channel":"book","type":"update","data":[{"symbol":"ETH/USD","bids":[],"asks":[{"price":3797.70,"qty":3.00000000}],"checksum":1224543188,"timestamp":"2024-06-01T17:52:30.834396Z"}]}
{"channel":"book","type":"update","data":[{"symbol":"ETH/USD","bids":[{"price":3796.84,"qty":0.00000000},{"price":3796.03,"qty":0.76629138}],"asks":[],"checksum":347839066,"timestamp":"2024-06-01T17:52:30.835231Z"}]}
{"channel":"book","type":"update","data":[{"symbol":"ETH/USD","bids":[],"asks":[{"price":3797.87,"qty":1.33946223}],"checksum":274911772,"timestamp":"2024-06-01T17:52:30.836078Z"}]}
{"channel":"book","type":"update","data":[{"symbol":"ETH/USD","bids":[{"price":3797.13,"qty":26.33563045}],"asks":[],"checksum":2859066096,"timestamp":"2024-06-01T17:52:30.836918Z"}]}
{"channel":"book","type":"update","data":[{"symbol":"ETH/USD","bids":[],"asks":[{"price":3797.87,"qty":27.67001066}],"checksum":3775217249,"timestamp":"2024-06-01T17:52:30.836931Z"}]}
{"channel":"book","type":"update","data":[{"symbol":"ETH/USD","bids":[],"asks":[{"price":3797.43,"qty":26.33364722}],"checksum":1322685141,"timestamp":"2024-06-01T17:52:30.836948Z"}]}
{"channel":"book","type":"update","data":[{"symbol":"ETH/USD","bids":[{"price":3796.85,"qty":0.00000000},{"price":3796.03,"qty":0.76629138}],"asks":[],"checksum":597318437,"timestamp":"2024-06-01T17:52:30.840620Z"}]}
{"channel":"book","type":"update","data":[{"symbol":"ETH/USD","bids":[],"asks":[{"price":3797.87,"qty":27.14339970},{"price":3797.69,"qty":0.52663592}],"checksum":104789050,"timestamp":"2024-06-01T17:52:30.840862Z"}]}
{"channel":"book","type":"update","data":[{"symbol":"ETH/USD","bids":[],"asks":[{"price":3797.87,"qty":0.81285127}],"checksum":3571120329,"timestamp":"2024-06-01T17:52:30.845286Z"}]}
{"channel":"book","type":"update","data":[{"symbol":"ETH/USD","bids":[{"price":3797.13,"qty":0.00000000},{"price":3795.93,"qty":0.72912968}],"asks":[],"checksum":578567136,"timestamp":"2024-06-01T17:52:30.845294Z"}]}
{"channel":"book","type":"update","data":[{"symbol":"ETH/USD","bids":[],"asks":[{"price":3797.43,"qty":0.00000000},{"price":3798.08,"qty":68.14933373}],"checksum":3971663377,"timestamp":"2024-06-01T17:52:30.845467Z"}]}
{"channel":"book","type":"update","data":[{"symbol":"ETH/USD","bids":[],"asks":[{"price":3797.87,"qty":0.00000000},{"price":3798.12,"qty":0.15000000}],"checksum":2336631714,"timestamp":"2024-06-01T17:52:30.849254Z"}]}
{"channel":"book","type":"update","data":[{"symbol":"ETH/USD","bids":[],"asks":[{"price":3797.69,"qty":0.00000000},{"price":3798.15,"qty":0.00985404},{"price":3797.68,"qty":0.52663731}],"checksum":2701459598,"timestamp":"2024-06-01T17:52:30.852626Z"}]}
{"channel":"book","type":"update","data":[{"symbol":"ETH/USD","bids":[],"asks":[{"price":3797.68,"qty":0.00000000},{"price":3798.15,"qty":0.00985404}],"checksum":1568291644,"timestamp":"2024-06-01T17:52:30.858116Z"}]}
{"channel":"book","type":"update","data":[{"symbol":"ETH/USD","bids":[],"asks":[{"price":3798.02,"qty":2.14892321}],"checksum":261143098,"timestamp":"2024-06-01T17:52:30.863895Z"}]}
{"channel":"book","type":"update","data":[{"symbol":"ETH/USD","bids":[],"asks":[{"price":3797.69,"qty":1.00000000}],"checksum":1979792126,"timestamp":"2024-06-01T17:52:30.865415Z"}]}
{"channel":"book","type":"update","data":[{"symbol":"ETH/USD","bids":[],"asks":[{"price":3797.53,"qty":3.00000000}],"checksum":2269539024,"timestamp":"2024-06-01T17:52:30.870931Z"}]}
{"channel":"book","type":"update","data":[{"symbol":"ETH/USD","bids":[{"price":3797.11,"qty":26.33581218}],"asks":[],"checksum":1397386492,"timestamp":"2024-06-01T17:52:30.886365Z"}]}
{"channel":"book","type":"update","data":[{"symbol":"ETH/USD","bids":[],"asks":[{"price":3797.41,"qty":26.33375695}],"checksum":3641718083,"timestamp":"2024-06-01T17:52:30.886480Z"}]}
{"channel":"book","type":"update","data":[{"symbol":"ETH/USD","bids":[],"asks":[{"price":3797.88,"qty":0.00000000},{"price":3798.08,"qty":68.14933373}],"checksum":214596422,"timestamp":"2024-06-01T17:52:30.889028Z"}]}
{"channel":"book","type":"update","data":[{"symbol":"ETH/USD","bids":[],"asks":[{"price":3797.41,"qty":0.00000000},{"price":3798.12,"qty":0.15000000}],"checksum":2665051034,"timestamp":"2024-06-01T17:52:30.895467Z"}]}
{"channel":"book","type":"update","data":[{"symbol":"ETH/USD","bids":[{"price":3796.77,"qty":0.00000000},{"price":3795.93,"qty":0.72912968}],"asks":[],"checksum":966179661,"timestamp":"2024-06-01T17:52:30.896967Z"}]}
{"channel":"book","type":"update","data":[{"symbol":"ETH/USD","bids":[{"price":3797.11,"qty":0.00000000},{"price":3795.90,"qty":8.27100000}],"asks":[],"checksum":4082689887,"timestamp":"2024-06-01T17:52:30.898137Z"}]}
{"channel":"book","type":"update","data":[{"symbol":"ETH/USD","bids":[],"asks":[{"price":3797.69,"qty":0.00000000},{"price":3798.15,"qty":0.00985404}],"checksum":1472490641,"timestamp":"2024-06-01T17:52:30.901795Z"}]}
{"channel":"book","type":"update","data":[{"symbol":"ETH/USD","bids":[],"asks":[{"price":3797.70,"qty":0.00000000},{"price":3798.19,"qty":0.19621000}],"checksum":3885243170,"timestamp":"2024-06-01T17:52:30.906685Z"}]}
{"channel":"book","type":"update","data":[{"symbol":"ETH/USD","bids":[{"price":3797.06,"qty":26.33610715}],"asks":[],"checksum":437891192,"timestamp":"2024-06-01T17:52:30.938963Z"}]}
{"channel":"book","type":"update","data":[{"symbol":"ETH/USD","bids":[],"asks":[{"price":3797.36,"qty":26.33409140}],"checksum":563310697,"timestamp":"2024-06-01T17:52:30.939017Z"}]}
{"channel":"book","type":"update","data":[{"symbol":"ETH/USD","bids":[{"price":3797.06,"qty":0.00000000},{"price":3795.90,"qty":8.27100000}],"asks":[],"checksum":57983490,"timestamp":"2024-06-01T17:52:30.944699Z"}]}
{"channel":"book","type":"update","data":[{"symbol":"ETH/USD","bids":[],"asks":[{"price":3797.36,"qty":0.00000000},{"price":3798.19,"qty":0.19621000}],"checksum":3885243170,"timestamp":"2024-06-01T17:52:30.944795Z"}]}
{"channel":"book","type":"update","data":[{"symbol":"ETH/USD","bids":[],"asks":[{"price":3798.03,"qty":3.31091807}],"checksum":2561220933,"timestamp":"2024-06-01T17:52:30.949390Z"}]}
{"channel":"book","type":"update","data":[{"symbol":"ETH/USD","bids":[],"asks":[{"price":3797.52,"qty":0.81285127}],"checksum":1568106396,"timestamp":"2024-06-01T17:52:30.951801Z"}]}
{"channel":"book","type":"update","data":[{"symbol":"ETH/USD","bids":[],"asks":[{"price":3797.47,"qty":3.00000000}],"checksum":1767633444,"timestamp":"2024-06-01T17:52:30.955835Z"}]}
{"channel":"book","type":"update","data":[{"symbol":"ETH/USD","bids":[],"asks":[{"price":3797.59,"qty":0.77000000}],"checksum":3704665119,"timestamp":"2024-06-01T17:52:30.969558Z"}]}
{"channel":"book","type":"update","data":[{"symbol":"ETH/USD","bids":[],"asks":[{"price":3797.47,"qty":6.00000000}],"checksum":2394014532,"timestamp":"2024-06-01T17:52:30.980518Z"}]}
{"channel":"book","type":"update","data":[{"symbol":"ETH/USD","bids":[{"price":3796.64,"qty":15.80244833}],"asks":[],"checksum":2731533234,"timestamp":"2024-06-01T17:52:30.981038Z"}]}
{"channel":"book","type":"update","data":[{"symbol":"ETH/USD","bids":[{"price":3796.03,"qty":0.00000000},{"price":3795.70,"qty":26.34558513}],"asks":[],"checksum":737982937,"timestamp":"2024-06-01T17:52:30.982145Z"}]}
{"channel":"book","type":"update","data":[{"symbol":"ETH/USD","bids":[],"asks":[{"price":3797.52,"qty":0.00000000},{"price":3798.12,"qty":0.15000000}],"checksum":2211083733,"timestamp":"2024-06-01T17:52:30.982796Z"}]}
{"channel":"book","type":"update","data":[{"symbol":"ETH/USD","bids":[{"price":3795.90,"qty":5.27100000}],"asks":[],"checksum":4059511959,"timestamp":"2024-06-01T17:52:30.985892Z"}]}
{"channel":"book","type":"update","data":[{"symbol":"ETH/USD","bids":[{"price":3795.93,"qty":0.00000000},{"price":3795.63,"qty":7.25300727}],"asks":[],"checksum":1031765456,"timestamp":"2024-06-01T17:52:30.988503Z"}]}
{"channel":"book","type":"update","data":[{"symbol":"ETH/USD","bids":[{"price":3796.66,"qty":0.00000000},{"price":3795.50,"qty":0.29493501}],"asks":[],"checksum":575604857,"timestamp":"2024-06-01T17:52:30.989796Z"}]}
{"channel":"book","type":"update","data":[{"symbol":"ETH/USD","bids":[{"price":3796.98,"qty":26.33672023}],"asks":[],"checksum":35585265,"timestamp":"2024-06-01T17:52:30.990026Z"}]}
{"channel":"book","type":"update","data":[{"symbol":"ETH/USD","bids":[],"asks":[{"price":3797.86,"qty":26.34317571}],"checksum":2372703849,"timestamp":"2024-06-01T17:52:30.990297Z"}]}
{"channel":"book","type":"update","data":[{"symbol":"ETH/USD","bids":[{"price":3795.90,"qty":0.00000000},{"price":3795.50,"qty":0.29493501}],"asks":[],"checksum":4089911342,"timestamp":"2024-06-01T17:52:30.990672Z"}]}
{"channel":"book","type":"update","data":[{"symbol":"ETH/USD","bids":[{"price":3795.63,"qty":0.00000000},{"price":3795.49,"qty":1.00700000}],"asks":[],"checksum":2628535459,"timestamp":"2024-06-01T17:52:30.991363Z"}]}
{"channel":"book","type":"update","data":[{"symbol":"ETH/USD","bids":[],"asks":[{"price":3798.07,"qty":0.00000000},{"price":3798.12,"qty":0.15000000}],"checksum":185784100,"timestamp":"2024-06-01T17:52:30.993745Z"}]}
{"channel":"book","type":"update","data":[{"symbol":"ETH/USD","bids":[{"price":3795.70,"qty":0.00000000},{"price":3795.45,"qty":2.45696258}],"asks":[],"checksum":338600666,"timestamp":"2024-06-01T17:52:30.993758Z"}]}
{"channel":"book","type":"update","data":[{"symbol":"ETH/USD","bids":[],"asks":[{"price":3798.03,"qty":0.01091807}],"checksum":4217553451,"timestamp":"2024-06-01T17:52:30.993871Z"}]}
{"channel":"book","type":"update","data":[{"symbol":"ETH/USD","bids":[],"asks":[{"price":3797.96,"qty":3.30000000}],"checksum":2286132402,"timestamp":"2024-06-01T17:52:30.993962Z"}]}
{"channel":"book","type":"update","data":[{"symbol":"ETH/USD","bids":[{"price":3795.68,"qty":5.27100000}],"asks":[],"checksum":1300312950,"timestamp":"2024-06-01T17:52:30.994850Z"}]}
{"channel":"book","type":"update","data":[{"symbol":"ETH/USD","bids":[{"price":3796.57,"qty":3.40192157}],"asks":[],"checksum":2403938386,"timestamp":"2024-06-01T17:52:30.994976Z"}]}
{"channel":"book","type":"update","data":[{"symbol":"ETH/USD","bids":[],"asks":[{"price":3797.86,"qty":0.00000000},{"price":3798.12,"qty":0.15000000}],"checksum":2035732262,"timestamp":"2024-06-01T17:52:30.995902Z"}]}
{"channel":"book","type":"update","data":[{"symbol":"ETH/USD","bids":[{"price":3796.78,"qty":0.01455545}],"asks":[],"checksum":1749990443,"timestamp":"2024-06-01T17:52:30.997040Z"}]}
{"channel":"book","type":"update","data":[{"symbol":"ETH/USD","bids":[{"price":3796.97,"qty":0.00000000},{"price":3795.49,"qty":1.00700000}],"asks":[],"checksum":2496461882,"timestamp":"2024-06-01T17:52:30.997540Z"}]}
{"channel":"book","type":"update","data":[{"symbol":"ETH/USD","bids":[],"asks":[{"price":3797.59,"qty":0.00000000},{"price":3798.15,"qty":0.00985404},{"price":3797.46,"qty":0.77000000}],"checksum":1327908061,"timestamp":"2024-06-01T17:52:30.997915Z"}]}
{"channel":"book","type":"update","data":[{"symbol":"ETH/USD","bids":[],"asks":[{"price":3797.46,"qty":1.54000000}],"checksum":126827741,"timestamp":"2024-06-01T17:52:30.997969Z"}]}
{"channel":"book","type":"update","data":[{"symbol":"ETH/USD","bids":[],"asks":[{"price":3797.46,"qty":0.77000000}],"checksum":1327908061,"timestamp":"2024-06-01T17:52:31.000671Z"}]}
{"channel":"book","type":"update","data":[{"symbol":"ETH/USD","bids":[],"asks":[{"price":3797.46,"qty":0.00000000},{"price":3798.15,"qty":0.00985404}],"checksum":3138265476,"timestamp":"2024-06-01T17:52:31.000888Z"}]}
{"channel":"book","type":"update","data":[{"symbol":"ETH/USD","bids":[{"price":3796.65,"qty":0.00000000},{"price":3795.45,"qty":2.45696258},{"price":3796.99,"qty":0.52673301}],"asks":[],"checksum":320216027,"timestamp":"2024-06-01T17:52:31.001612Z"}]}
{"channel":"book","type":"update","data":[{"symbol":"ETH/USD","bids":[],"asks":[{"price":3797.09,"qty":3.00000000}],"checksum":2710735719,"timestamp":"2024-06-01T17:52:31.002216Z"}]}
{"channel":"book","type":"update","data":[{"symbol":"ETH/USD","bids":[],"asks":[{"price":3797.53,"qty":0.00000000},{"price":3798.15,"qty":0.00985404}],"checksum":1438804271,"timestamp":"2024-06-01T17:52:31.003047Z"}]}
{"channel":"book","type":"update","data":[{"symbol":"ETH/USD","bids":[{"price":3796.98,"qty":0.00000000},{"price":3795.45,"qty":2.45696258}],"asks":[],"checksum":922512843,"timestamp":"2024-06-01T17:52:31.003316Z"}]}
{"channel":"book","type":"update","data":[{"symbol":"ETH/USD","bids":[{"price":3796.64,"qty":0.00000000},{"price":3795.37,"qty":7.25350413}],"asks":[],"checksum":4221240949,"timestamp":"2024-06-01T17:52:31.003703Z"}]}
{"channel":"book","type":"update","data":[{"symbol":"ETH/USD","bids":[],"asks":[{"price":3797.28,"qty":3.00000000}],"checksum":1143581932,"timestamp":"2024-06-01T17:52:31.003798Z"}]}
{"channel":"book","type":"update","data":[{"symbol":"ETH/USD","bids":[{"price":3796.11,"qty":0.00000000},{"price":3795.36,"qty":9.17870569}],"asks":[],"checksum":666956654,"timestamp":"2024-06-01T17:52:31.004292Z"}]}
{"channel":"book","type":"update","data":[{"symbol":"ETH/USD","bids":[{"price":3795.68,"qty":0.00000000},{"price":3795.16,"qty":7.20000000}],"asks":[],"checksum":677986493,"timestamp":"2024-06-01T17:52:31.005791Z"}]}
{"channel":"book","type":"update","data":[{"symbol":"ETH/USD","bids":[],"asks":[{"price":3797.45,"qty":0.72912968}],"checksum":24058818,"timestamp":"2024-06-01T17:52:31.005900Z"}]}
{"channel":"book","type":"update","data":[{"symbol":"ETH/USD","bids":[{"price":3796.57,"qty":0.00000000},{"price":3795.07,"qty":3.30000000}],"asks":[],"checksum":2858956490,"timestamp":"2024-06-01T17:52:31.006776Z"}]}
{"channel":"book","type":"update","data":[{"symbol":"ETH/USD","bids":[],"asks":[{"price":3798.02,"qty":0.01092321}],"checksum":1451674134,"timestamp":"2024-06-01T17:52:31.007047Z"}]}
{"channel":"book","type":"update","data":[{"symbol":"ETH/USD","bids":[],"asks":[{"price":3797.47,"qty":3.00000000}],"checksum":2054621473,"timestamp":"2024-06-01T17:52:31.007528Z"}]}
{"channel":"book","type":"update","data":[{"symbol":"ETH/USD","bids":[{"price":3796.59,"qty":0.00000000},{"price":3795.00,"qty":3.00000000}],"asks":[],"checksum":342515396,"timestamp":"2024-06-01T17:52:31.007600Z"}]}
{"channel":"book","type":"update","data":[{"symbol":"ETH/USD","bids":[],"asks":[{"price":3797.09,"qty":6.00000000}],"checksum":1200440050,"timestamp":"2024-06-01T17:52:31.007740Z"}]}
{"channel":"book","type":"update","data":[{"symbol":"ETH/USD","bids":[],"asks":[{"price":3797.45,"qty":1.72912968}],"checksum":3270143083,"timestamp":"2024-06-01T17:52:31.008383Z"}]}
{"channel":"book","type":"update","data":[{"symbol":"ETH/USD","bids":[{"price":3795.37,"qty":0.00000000},{"price":3794.93,"qty":0.06693358}],"asks":[],"checksum":471531541,"timestamp":"2024-06-01T17:52:31.008631Z"}]}
{"channel":"book","type":"update","data":[{"symbol":"ETH/USD","bids":[],"asks":[{"price":3797.08,"qty":0.81285127}],"checksum":2320606711,"timestamp":"2024-06-01T17:52:31.009877Z"}]}
{"channel":"book","type":"update","data":[{"symbol":"ETH/USD","bids":[],"asks":[{"price":3797.00,"qty":13.17092698}],"checksum":2695917120,"timestamp":"2024-06-01T17:52:31.010921Z"}]}
{"channel":"book","type":"update","data":[{"symbol":"ETH/USD","bids":[],"asks":[{"price":3797.96,"qty":0.00000000},{"price":3798.03,"qty":0.01091807}],"checksum":3933363189,"timestamp":"2024-06-01T17:52:31.010990Z"}]}
{"channel":"book","type":"update","data":[{"symbol":"ETH/USD","bids":[],"asks":[{"price":3797.08,"qty":2.95085127}],"checksum":2287751256,"timestamp":"2024-06-01T17:52:31.011188Z"}]}
{"channel":"book","type":"update","data":[{"symbol":"ETH/USD","bids":[],"asks":[{"price":3797.69,"qty":3.30000000}],"checksum":183362638,"timestamp":"2024-06-01T17:52:31.011357Z"}]}
{"channel":"book","type":"update","data":[{"symbol":"ETH/USD","bids":[{"price":3796.99,"qty":0.00000000},{"price":3794.64,"qty":3.94900000},{"price":3795.71,"qty":0.52673301}],"asks":[],"checksum":1646775668,"timestamp":"2024-06-01T17:52:31.011975Z"}]}
{"channel":"book","type":"update","data":[{"symbol":"ETH/USD","bids":[],"asks":[{"price":3797.28,"qty":0.00000000},{"price":3798.03,"qty":0.01091807}],"checksum":3327332609,"timestamp":"2024-06-01T17:52:31.013381Z"}]}
{"channel":"book","type":"update","data":[{"symbol":"ETH/USD","bids":[{"price":3795.07,"qty":0.00000000},{"price":3794.64,"qty":3.94900000}],"asks":[],"checksum":422177329,"timestamp":"2024-06-01T17:52:31.014154Z"}]}
{"channel":"book","type":"update","data":[{"symbol":"ETH/USD","bids":[],"asks":[{"price":3797.69,"qty":0.00000000},{"price":3798.08,"qty":68.14933373}],"checksum":9345821,"timestamp":"2024-06-01T17:52:31.014217Z"}]}
{"channel":"book","type":"update","data":[{"symbol":"ETH/USD","bids":[{"price":3795.61,"qty":3.30000000}],"asks":[],"checksum":3340321288,"timestamp":"2024-06-01T17:52:31.014483Z"}]}
{"channel":"book","type":"update","data":[{"symbol":"ETH/USD","bids":[],"asks":[{"price":3797.36,"qty":3.30000000}],"checksum":1181895694,"timestamp":"2024-06-01T17:52:31.014517Z"}]}
{"channel":"book","type":"update","data":[{"symbol":"ETH/USD","bids":[{"price":3796.60,"qty":0.00519645}],"asks":[],"checksum":1418177186,"timestamp":"2024-06-01T17:52:31.015496Z"}]}
{"channel":"book","type":"update","data":[{"symbol":"ETH/USD","bids":[{"price":3795.00,"qty":0.00000000},{"price":3794.93,"qty":0.06693358}],"asks":[],"checksum":211135150,"timestamp":"2024-06-01T17:52:31.015867Z"}]}
{"channel":"book","type":"update","data":[{"symbol":"ETH/USD","bids":[{"price":3796.78,"qty":0.00936746}],"asks":[],"checksum":4144094242,"timestamp":"2024-06-01T17:52:31.017210Z"}]}
{"channel":"book","type":"update","data":[{"symbol":"ETH/USD","bids":[],"asks":[{"price":3797.00,"qty":16.17092698}],"checksum":2599467358,"timestamp":"2024-06-01T17:52:31.017316Z"}]}
{"channel":"book","type":"update","data":[{"symbol":"ETH/USD","bids":[{"price":3795.71,"qty":0.00000000},{"price":3794.64,"qty":3.94900000}],"asks":[],"checksum":3595640155,"timestamp":"2024-06-01T17:52:31.018846Z"}]}
{"channel":"book","type":"update","data":[{"symbol":"ETH/USD","bids":[{"price":3794.64,"qty":0.00000000},{"price":3794.59,"qty":1.04500000},{"price":3794.60,"qty":3.94900000}],"asks":[],"checksum":3753557281,"timestamp":"2024-06-01T17:52:31.019954Z"}]}
{"channel":"book","type":"update","data":[{"symbol":"ETH/USD","bids":[{"price":3795.12,"qty":7.25398195}],"asks":[],"checksum":1697885532,"timestamp":"2024-06-01T17:52:31.027254Z"}]}
{"channel":"book","type":"update","data":[{"symbol":"ETH/USD","bids":[{"price":3795.12,"qty":0.00000000},{"price":3794.60,"qty":3.94900000}],"asks":[],"checksum":3753557281,"timestamp":"2024-06-01T17:52:31.027764Z"}]}
{"channel":"book","type":"update","data":[{"symbol":"ETH/USD","bids":[],"asks":[{"price":3797.08,"qty":2.13800000}],"checksum":2937174871,"timestamp":"2024-06-01T17:52:31.028960Z"}]}
{"channel":"book","type":"update","data":[{"symbol":"ETH/USD","bids":[{"price":3796.60,"qty":0.00000000},{"price":3794.59,"qty":1.04500000}],"asks":[],"checksum":343946605,"timestamp":"2024-06-01T17:52:31.033425Z"}]}
{"channel":"book","type":"update","data":[{"symbol":"ETH/USD","bids":[],"asks":[{"price":3797.36,"qty":0.00000000},{"price":3798.08,"qty":68.14933373}],"checksum":2151201015,"timestamp":"2024-06-01T17:52:31.035160Z"}]}
{"channel":"book","type":"update","data":[{"symbol":"ETH/USD","bids":[],"asks":[{"price":3796.98,"qty":3.30000000}],"checksum":2924110576,"timestamp":"2024-06-01T17:52:31.035669Z"}]}
{"channel":"book","type":"update","data":[{"symbol":"ETH/USD","bids":[{"price":3795.05,"qty":0.13123394}],"asks":[],"checksum":2940585891,"timestamp":"2024-06-01T17:52:31.041291Z"}]}
{"channel":"book","type":"update","data":[{"symbol":"ETH/USD","bids":[],"asks":[{"price":3796.80,"qty":3.00000000}],"checksum":2708656341,"timestamp":"2024-06-01T17:52:31.043879Z"}]}
{"channel":"book","type":"update","data":[{"symbol":"ETH/USD","bids":[],"asks":[{"price":3797.09,"qty":3.00000000}],"checksum":1181943452,"timestamp":"2024-06-01T17:52:31.044407Z"}]}
{"channel":"book","type":"update","data":[{"symbol":"ETH/USD","bids":[{"price":3794.60,"qty":0.00000000},{"price":3794.59,"qty":1.04500000}],"asks":[],"checksum":1711257729,"timestamp":"2024-06-01T17:52:31.045233Z"}]}
{"channel":"book","type":"update","data":[{"symbol":"ETH/USD","bids":[{"price":3795.50,"qty":0.00000000},{"price":3794.52,"qty":3.05759107}],"asks":[],"checksum":885544258,"timestamp":"2024-06-01T17:52:31.049108Z"}]}
{"channel":"book","type":"update","data":[{"symbol":"ETH/USD","bids":[],"asks":[{"price":3797.00,"qty":3.00000000}],"checksum":1176688780,"timestamp":"2024-06-01T17:52:31.050975Z"}]}
{"channel":"book","type":"update","data":[{"symbol":"ETH/USD","bids":[],"asks":[{"price":3796.79,"qty":13.17811996}],"checksum":351541658,"timestamp":"2024-06-01T17:52:31.051117Z"}]}
{"channel":"book","type":"update","data":[{"symbol":"ETH/USD","bids":[{"price":3795.49,"qty":0.00000000},{"price":3794.43,"qty":0.52673301}],"asks":[],"checksum":3280154306,"timestamp":"2024-06-01T17:52:31.051738Z"}]}
{"channel":"book","type":"update","data":[{"symbol":"ETH/USD","bids":[{"price":3794.93,"qty":0.00000000},{"price":3794.28,"qty":4.74778469}],"asks":[],"checksum":2658904339,"timestamp":"2024-06-01T17:52:31.052142Z"}]}
{"channel":"book","type":"update","data":[{"symbol":"ETH/USD","bids":[{"price":3795.61,"qty":0.00000000},{"price":3794.15,"qty":0.81017075}],"asks":[],"checksum":1044761179,"timestamp":"2024-06-01T17:52:31.053956Z"}]}
{"channel":"book","type":"update","data":[{"symbol":"ETH/USD","bids":[],"asks":[{"price":3797.45,"qty":0.72912968}],"checksum":868718569,"timestamp":"2024-06-01T17:52:31.054094Z"}]}
{"channel":"book","type":"update","data":[{"symbol":"ETH/USD","bids":[{"price":3795.23,"qty":3.30000000}],"asks":[],"checksum":3401631768,"timestamp":"2024-06-01T17:52:31.059606Z"}]}
{"channel":"book","type":"update","data":[{"symbol":"ETH/USD","bids":[],"asks":[{"price":3797.45,"qty":1.57487610}],"checksum":1867853103,"timestamp":"2024-06-01T17:52:31.061521Z"}]}
{"channel":"book","type":"update","data":[{"symbol":"ETH/USD","bids":[],"asks":[{"price":3797.00,"qty":0.00000000},{"price":3798.02,"qty":0.01092321}],"checksum":429449321,"timestamp":"2024-06-01T17:52:31.062190Z"}]}
{"channel":"book","type":"update","data":[{"symbol":"ETH/USD","bids":[{"price":3795.37,"qty":0.00506754}],"asks":[],"checksum":3056713959,"timestamp":"2024-06-01T17:52:31.066646Z"}]}
{"channel":"book","type":"update","data":[{"symbol":"ETH/USD","bids":[],"asks":[{"price":3796.98,"qty":4.18220674}],"checksum":625275964,"timestamp":"2024-06-01T17:52:31.068062Z"}]}
{"channel":"book","type":"update","data":[{"symbol":"ETH/USD","bids":[],"asks":[{"price":3796.98,"qty":4.96396081}],"checksum":954046120,"timestamp":"2024-06-01T17:52:31.068666Z"}]}
{"channel":"book","type":"update","data":[{"symbol":"ETH/USD","bids":[],"asks":[{"price":3797.69,"qty":0.10000000}],"checksum":1513052344,"timestamp":"2024-06-01T17:52:31.072738Z"}]}
{"channel":"book","type":"update","data":[{"symbol":"ETH/USD","bids":[{"price":3795.23,"qty":0.00000000},{"price":3794.28,"qty":4.74778469}],"asks":[],"checksum":803728391,"timestamp":"2024-06-01T17:52:31.074507Z"}]}
{"channel":"book","type":"update","data":[{"symbol":"ETH/USD","bids":[],"asks":[{"price":3796.79,"qty":16.17811996}],"checksum":2070473461,"timestamp":"2024-06-01T17:52:31.075485Z"}]}
{"channel":"book","type":"update","data":[{"symbol":"ETH/USD","bids":[],"asks":[{"price":3796.79,"qty":16.90724964}],"checksum":2981689081,"timestamp":"2024-06-01T17:52:31.076974Z"}]}
{"channel":"book","type":"update","data":[{"symbol":"ETH/USD","bids":[],"asks":[{"price":3796.97,"qty":0.81285127}],"checksum":2138965223,"timestamp":"2024-06-01T17:52:31.078764Z"}]}
{"channel":"book","type":"update","data":[{"symbol":"ETH/USD","bids":[{"price":3794.59,"qty":0.00000000},{"price":3794.15,"qty":0.81017075}],"asks":[],"checksum":2241077479,"timestamp":"2024-06-01T17:52:31.081295Z"}]}
{"channel":"book","type":"update","data":[{"symbol":"ETH/USD","bids":[{"price":3795.36,"qty":0.00000000},{"price":3794.14,"qty":3.00000000}],"asks":[],"checksum":3591255828,"timestamp":"2024-06-01T17:52:31.082519Z"}]}
{"channel":"book","type":"update","data":[{"symbol":"ETH/USD","bids":[],"asks":[{"price":3797.64,"qty":0.75100000}],"checksum":861532904,"timestamp":"2024-06-01T17:52:31.083667Z"}]}
{"channel":"book","type":"update","data":[{"symbol":"ETH/USD","bids":[{"price":3795.45,"qty":0.00000000},{"price":3793.84,"qty":12.32000000}],"asks":[],"checksum":3854487471,"timestamp":"2024-06-01T17:52:31.086280Z"}]}
{"channel":"book","type":"update","data":[{"symbol":"ETH/USD","bids":[],"asks":[{"price":3796.79,"qty":17.90724964}],"checksum":2063358773,"timestamp":"2024-06-01T17:52:31.088777Z"}]}
{"channel":"book","type":"update","data":[{"symbol":"ETH/USD","bids":[{"price":3794.15,"qty":0.00000000},{"price":3793.80,"qty":1.05333443}],"asks":[],"checksum":246094079,"timestamp":"2024-06-01T17:52:31.089133Z"}]}
{"channel":"book","type":"update","data":[{"symbol":"ETH/USD","bids":[],"asks":[{"price":3796.98,"qty":5.82902672}],"checksum":3478593905,"timestamp":"2024-06-01T17:52:31.091118Z"}]}
{"channel":"book","type":"update","data":[{"symbol":"ETH/USD","bids":[],"asks":[{"price":3796.79,"qty":44.24528782}],"checksum":1861562468,"timestamp":"2024-06-01T17:52:31.094621Z"}]}
{"channel":"book","type":"update","data":[{"symbol":"ETH/USD","bids":[],"asks":[{"price":3796.79,"qty":70.58332600}],"checksum":2404870271,"timestamp":"2024-06-01T17:52:31.094887Z"}]}
{"channel":"book","type":"update","data":[{"symbol":"ETH/USD","bids":[{"price":3794.60,"qty":26.35318442}],"asks":[],"checksum":2804800616,"timestamp":"2024-06-01T17:52:31.095031Z"}]}
{"channel":"book","type":"update","data":[{"symbol":"ETH/USD","bids":[{"price":3795.00,"qty":26.35040321}],"asks":[],"checksum":2436191107,"timestamp":"2024-06-01T17:52:31.095274Z"}]}
{"channel":"book","type":"update","data":[{"symbol":"ETH/USD","bids":[{"price":3795.05,"qty":0.00000000},{"price":3793.84,"qty":12.32000000}],"asks":[],"checksum":912428504,"timestamp":"2024-06-01T17:52:31.096006Z"}]}
{"channel":"book","type":"update","data":[{"symbol":"ETH/USD","bids":[],"asks":[{"price":3797.45,"qty":0.84574642}],"checksum":1076726585,"timestamp":"2024-06-01T17:52:31.101079Z"}]}
{"channel":"book","type":"update","data":[{"symbol":"ETH/USD","bids":[{"price":3794.63,"qty":3.30000000}],"asks":[],"checksum":1833603908,"timestamp":"2024-06-01T17:52:31.102663Z"}]}
{"channel":"book","type":"update","data":[{"symbol":"ETH/USD","bids":[{"price":3794.85,"qty":2.50583392}],"asks":[],"checksum":925923648,"timestamp":"2024-06-01T17:52:31.107034Z"}]}
{"channel":"book","type":"update","data":[{"symbol":"ETH/USD","bids":[{"price":3795.37,"qty":0.00000000},{"price":3794.14,"qty":3.00000000}],"asks":[],"checksum":2874520177,"timestamp":"2024-06-01T17:52:31.108373Z"}]}
{"channel":"book","type":"update","data":[{"symbol":"ETH/USD","bids":[{"price":3794.29,"qty":0.00552252}],"asks":[],"checksum":2934770722,"timestamp":"2024-06-01T17:52:31.116910Z"}]}
{"channel":"book","type":"update","data":[{"symbol":"ETH/USD","bids":[],"asks":[{"price":3797.46,"qty":0.00547591}],"checksum":644375278,"timestamp":"2024-06-01T17:52:31.119318Z"}]}
{"channel":"book","type":"update","data":[{"symbol":"ETH/USD","bids":[{"price":3795.00,"qty":0.00000000},{"price":3794.14,"qty":3.00000000}],"asks":[],"checksum":1519322757,"timestamp":"2024-06-01T17:52:31.126487Z"}]}
{"channel":"book","type":"update","data":[{"symbol":"ETH/USD","bids":[{"price":3794.60,"qty":0.00000000},{"price":3793.84,"qty":12.32000000}],"asks":[],"checksum":1183921867,"timestamp":"2024-06-01T17:52:31.126496Z"}]}
{"channel":"book","type":"update","data":[{"symbol":"ETH/USD","bids":[{"price":3794.85,"qty":0.00000000},{"price":3793.80,"qty":1.05333443}],"asks":[],"checksum":1493876380,"timestamp":"2024-06-01T17:52:31.129658Z"}]}
{"channel":"book","type":"update","data":[{"symbol":"ETH/USD","bids":[{"price":3794.29,"qty":0.00000000},{"price":3793.72,"qty":3.00000000}],"asks":[],"checksum":1078205228,"timestamp":"2024-06-01T17:52:31.135526Z"}]}
{"channel":"book","type":"update","data":[{"symbol":"ETH/USD","bids":[{"price":3796.78,"qty":0.00000000},{"price":3793.25,"qty":3.00000000},{"price":3795.46,"qty":0.00936890}],"asks":[],"checksum":3671872947,"timestamp":"2024-06-01T17:52:31.135634Z"}]}
{"channel":"book","type":"update","data":[{"symbol":"ETH/USD","bids":[{"price":3794.65,"qty":4.78133390}],"asks":[],"checksum":2806553344,"timestamp":"2024-06-01T17:52:31.138518Z"}]}
{"channel":"book","type":"update","data":[{"symbol":"ETH/USD","bids":[],"asks":[{"price":3797.00,"qty":0.06693358}],"checksum":1516788093,"timestamp":"2024-06-01T17:52:31.143735Z"}]}
{"channel":"book","type":"update","data":[{"symbol":"ETH/USD","bids":[],"asks":[{"price":3796.79,"qty":73.00107533}],"checksum":824002068,"timestamp":"2024-06-01T17:52:31.146753Z"}]}
{"channel":"book","type":"update","data":[{"symbol":"ETH/USD","bids":[],"asks":[{"price":3796.79,"qty":74.55485081}],"checksum":3379496216,"timestamp":"2024-06-01T17:52:31.148386Z"}]}
{"channel":"book","type":"update","data":[{"symbol":"ETH/USD","bids":[],"asks":[{"price":3796.80,"qty":3.09000000}],"checksum":1537709212,"timestamp":"2024-06-01T17:52:31.148540Z"}]}
{"channel":"book","type":"update","data":[{"symbol":"ETH/USD","bids":[{"price":3794.83,"qty":2.45696258}],"asks":[],"checksum":236936985,"timestamp":"2024-06-01T17:52:31.156013Z"}]}
{"channel":"book","type":"update","data":[{"symbol":"ETH/USD","bids":[],"asks":[{"price":3796.79,"qty":100.89288899}],"checksum":4168648623,"timestamp":"2024-06-01T17:52:31.156414Z"}]}
{"channel":"book","type":"update","data":[{"symbol":"ETH/USD","bids":[{"price":3794.84,"qty":26.35155874}],"asks":[],"checksum":286566284,"timestamp":"2024-06-01T17:52:31.156582Z"}]}
{"channel":"book","type":"update","data":[{"symbol":"ETH/USD","bids":[{"price":3794.73,"qty":26.35227854}],"asks":[],"checksum":3673329126,"timestamp":"2024-06-01T17:52:31.156662Z"}]}
{"channel":"book","type":"update","data":[{"symbol":"ETH/USD","bids":[],"asks":[{"price":3796.42,"qty":3.00000000}],"checksum":1012879823,"timestamp":"2024-06-01T17:52:31.156676Z"}]}
{"channel":"book","type":"update","data":[{"symbol":"ETH/USD","bids":[],"asks":[{"price":3796.98,"qty":2.52902672}],"checksum":411930982,"timestamp":"2024-06-01T17:52:31.156811Z"}]}
{"channel":"book","type":"update","data":[{"symbol":"ETH/USD","bids":[],"asks":[{"price":3796.61,"qty":3.00000000}],"checksum":384450862,"timestamp":"2024-06-01T17:52:31.156858Z"}]}
{"channel":"book","type":"update","data":[{"symbol":"ETH/USD","bids":[],"asks":[{"price":3796.80,"qty":0.09000000}],"checksum":946909560,"timestamp":"2024-06-01T17:52:31.156967Z"}]}
{"channel":"book","type":"update","data":[{"symbol":"ETH/USD","bids":[],"asks":[{"price":3796.68,"qty":3.30000000}],"checksum":1900754216,"timestamp":"2024-06-01T17:52:31.158034Z"}]}
{"channel":"book","type":"update","data":[{"symbol":"ETH/USD","bids":[],"asks":[{"price":3796.79,"qty":74.55485081}],"checksum":26383195,"timestamp":"2024-06-01T17:52:31.159151Z"}]}
{"channel":"book","type":"update","data":[{"symbol":"ETH/USD","bids":[],"asks":[{"price":3796.79,"qty":48.21681263}],"checksum":3735117172,"timestamp":"2024-06-01T17:52:31.159269Z"}]}
{"channel":"book","type":"update","data":[{"symbol":"ETH/USD","bids":[],"asks":[{"price":3796.79,"qty":53.48181263}],"checksum":397563540,"timestamp":"2024-06-01T17:52:31.162329Z"}]}
{"channel":"book","type":"update","data":[{"symbol":"ETH/USD","bids":[{"price":3795.16,"qty":0.00000000},{"price":3794.14,"qty":3.00000000}],"asks":[],"checksum":3340936517,"timestamp":"2024-06-01T17:52:31.163578Z"}]}
{"channel":"book","type":"update","data":[{"symbol":"ETH/USD","bids":[],"asks":[{"price":3795.47,"qty":0.77000000}],"checksum":3629871033,"timestamp":"2024-06-01T17:52:31.165603Z"}]}
{"channel":"book","type":"update","data":[{"symbol":"ETH/USD","bids":[],"asks":[{"price":3796.98,"qty":1.64681998}],"checksum":2947618574,"timestamp":"2024-06-01T17:52:31.165618Z"}]}
{"channel":"book","type":"update","data":[{"symbol":"ETH/USD","bids":[],"asks":[{"price":3796.98,"qty":0.86506591}],"checksum":3043785100,"timestamp":"2024-06-01T17:52:31.165795Z"}]}
{"channel":"book","type":"update","data":[{"symbol":"ETH/USD","bids":[],"asks":[{"price":3796.78,"qty":0.72912968}],"checksum":3333010809,"timestamp":"2024-06-01T17:52:31.166527Z"}]}
{"channel":"book","type":"update","data":[{"symbol":"ETH/USD","bids":[{"price":3794.53,"qty":0.00524346}],"asks":[],"checksum":4106141314,"timestamp":"2024-06-01T17:52:31.168824Z"}]}
{"channel":"book","type":"update","data":[{"symbol":"ETH/USD","bids":[],"asks":[{"price":3796.97,"qty":6.18285127}],"checksum":2597551051,"timestamp":"2024-06-01T17:52:31.175876Z"}]}
{"channel":"book","type":"update","data":[{"symbol":"ETH/USD","bids":[],"asks":[{"price":3796.61,"qty":0.00000000},{"price":3797.08,"qty":2.14347786}],"checksum":4166360308,"timestamp":"2024-06-01T17:52:31.180194Z"}]}
{"channel":"book","type":"update","data":[{"symbol":"ETH/USD","bids":[],"asks":[{"price":3796.68,"qty":0.00000000},{"price":3797.09,"qty":3.00000000}],"checksum":4059909547,"timestamp":"2024-06-01T17:52:31.180235Z"}]}
{"channel":"book","type":"update","data":[{"symbol":"ETH/USD","bids":[],"asks":[{"price":3796.79,"qty":50.48181263}],"checksum":1777162923,"timestamp":"2024-06-01T17:52:31.180398Z"}]}
{"channel":"book","type":"update","data":[{"symbol":"ETH/USD","bids":[],"asks":[{"price":3796.31,"qty":3.30000000}],"checksum":812430130,"timestamp":"2024-06-01T17:52:31.180976Z"}]}
{"channel":"book","type":"update","data":[{"symbol":"ETH/USD","bids":[{"price":3794.53,"qty":0.00000000},{"price":3794.14,"qty":3.00000000}],"asks":[],"checksum":3733227032,"timestamp":"2024-06-01T17:52:31.182519Z"}]}
{"channel":"book","type":"update","data":[{"symbol":"ETH/USD","bids":[],"asks":[{"price":3796.79,"qty":24.14377445}],"checksum":1452528182,"timestamp":"2024-06-01T17:52:31.182817Z"}]}
{"channel":"book","type":"update","data":[{"symbol":"ETH/USD","bids":[{"price":3794.84,"qty":0.00000000},{"price":3793.84,"qty":12.32000000}],"asks":[],"checksum":3729268159,"timestamp":"2024-06-01T17:52:31.182866Z"}]}
{"channel":"book","type":"update","data":[{"symbol":"ETH/USD","bids":[{"price":3794.73,"qty":0.00000000},{"price":3793.80,"qty":1.05333443}],"asks":[],"checksum":617111896,"timestamp":"2024-06-01T17:52:31.182894Z"}]}
{"channel":"book","type":"update","data":[{"symbol":"ETH/USD","bids":[],"asks":[{"price":3796.42,"qty":6.00000000}],"checksum":1691671357,"timestamp":"2024-06-01T17:52:31.187367Z"}]}
{"channel":"book","type":"update","data":[{"symbol":"ETH/USD","bids":[],"asks":[{"price":3796.79,"qty":23.41464477}],"checksum":1670197170,"timestamp":"2024-06-01T17:52:31.191892Z"}]}
{"channel":"book","type":"update","data":[{"symbol":"ETH/USD","bids":[],"asks":[{"price":3796.97,"qty":5.37000000}],"checksum":3261152341,"timestamp":"2024-06-01T17:52:31.195034Z"}]}
{"channel":"book","type":"update","data":[{"symbol":"ETH/USD","bids":[],"asks":[{"price":3796.98,"qty":0.00000000},{"price":3797.09,"qty":3.00000000}],"checksum":140205449,"timestamp":"2024-06-01T17:52:31.197045Z"}]}
{"channel":"book","type":"update","data":[{"symbol":"ETH/USD","bids":[],"asks":[{"price":3796.79,"qty":26.25858391}],"checksum":2356870112,"timestamp":"2024-06-01T17:52:31.197143Z"}]}
{"channel":"book","type":"update","data":[{"symbol":"ETH/USD","bids":[],"asks":[{"price":3797.08,"qty":0.00547786}],"checksum":3318553793,"timestamp":"2024-06-01T17:52:31.198245Z"}]}
{"channel":"book","type":"update","data":[{"symbol":"ETH/USD","bids":[],"asks":[{"price":3797.07,"qty":0.30203318}],"checksum":82517015,"timestamp":"2024-06-01T17:52:31.198532Z"}]}
{"channel":"book","type":"update","data":[{"symbol":"ETH/USD","bids":[],"asks":[{"price":3796.99,"qty":0.32778701}],"checksum":4206442523,"timestamp":"2024-06-01T17:52:31.200206Z"}]}
{"channel":"book","type":"update","data":[{"symbol":"ETH/USD","bids":[],"asks":[{"price":3795.47,"qty":2.90800000}],"checksum":1213269939,"timestamp":"2024-06-01T17:52:31.201288Z"}]}
{"channel":"book","type":"update","data":[{"symbol":"ETH/USD","bids":[],"asks":[{"price":3795.47,"qty":5.90800000}],"checksum":3846657119,"timestamp":"2024-06-01T17:52:31.204923Z"}]}
{"channel":"book","type":"update","data":[{"symbol":"ETH/USD","bids":[],"asks":[{"price":3795.47,"qty":32.25519810}],"checksum":1454661793,"timestamp":"2024-06-01T17:52:31.205487Z"}]}
{"channel":"book","type":"update","data":[{"symbol":"ETH/USD","bids":[{"price":3794.55,"qty":26.35352375}],"asks":[],"checksum":3133135293,"timestamp":"2024-06-01T17:52:31.205599Z"}]}
{"channel":"book","type":"update","data":[{"symbol":"ETH/USD","bids":[],"asks":[{"price":3796.97,"qty":0.00000000},{"price":3797.08,"qty":0.00547786}],"checksum":2535417675,"timestamp":"2024-06-01T17:52:31.206730Z"}]}
{"channel":"book","type":"update","data":[{"symbol":"ETH/USD","bids":[{"price":3794.65,"qty":0.00000000},{"price":3793.80,"qty":1.05333443}],"asks":[],"checksum":2173795698,"timestamp":"2024-06-01T17:52:31.207929Z"}]}
{"channel":"book","type":"update","data":[{"symbol":"ETH/USD","bids":[],"asks":[{"price":3795.47,"qty":35.25519810}],"checksum":3955138102,"timestamp":"2024-06-01T17:52:31.208162Z"}]}
{"channel":"book","type":"update","data":[{"symbol":"ETH/USD","bids":[],"asks":[{"price":3796.79,"qty":33.01858391}],"checksum":891987207,"timestamp":"2024-06-01T17:52:31.209636Z"}]}
{"channel":"book","type":"update","data":[{"symbol":"ETH/USD","bids":[],"asks":[{"price":3795.47,"qty":32.25519810}],"checksum":1594181187,"timestamp":"2024-06-01T17:52:31.212413Z"}]}
{"channel":"book","type":"update","data":[{"symbol":"ETH/USD","bids":[{"price":3794.63,"qty":0.00000000},{"price":3793.72,"qty":3.00000000}],"asks":[],"checksum":52579465,"timestamp":"2024-06-01T17:52:31.219483Z"}]}
{"channel":"book","type":"update","data":[{"symbol":"ETH/USD","bids":[{"price":3795.46,"qty":0.00000000},{"price":3793.25,"qty":3.00000000},{"price":3795.17,"qty":0.00936961}],"asks":[],"checksum":3325968325,"timestamp":"2024-06-01T17:52:31.219749Z"}]}
{"channel":"book","type":"update","data":[{"symbol":"ETH/USD","bids":[],"asks":[{"price":3795.47,"qty":35.25519810}],"checksum":2886851713,"timestamp":"2024-06-01T17:52:31.222023Z"}]}
{"channel":"book","type":"update","data":[{"symbol":"ETH/USD","bids":[],"asks":[{"price":3796.00,"qty":0.72912968}],"checksum":4089197453,"timestamp":"2024-06-01T17:52:31.222899Z"}]}
{"channel":"book","type":"update","data":[{"symbol":"ETH/USD","bids":[{"price":3793.85,"qty":5.08658474}],"asks":[],"checksum":296657818,"timestamp":"2024-06-01T17:52:31.225113Z"}]}
{"channel":"book","type":"update","data":[{"symbol":"ETH/USD","bids":[],"asks":[{"price":3796.96,"qty":0.00521455}],"checksum":2099775183,"timestamp":"2024-06-01T17:52:31.226328Z"}]}
{"channel":"book","type":"update","data":[{"symbol":"ETH/USD","bids":[],"asks":[{"price":3795.47,"qty":48.43154446}],"checksum":682096613,"timestamp":"2024-06-01T17:52:31.227652Z"}]}
{"channel":"book","type":"update","data":[{"symbol":"ETH/USD","bids":[],"asks":[{"price":3796.79,"qty":19.84046395}],"checksum":1505453659,"timestamp":"2024-06-01T17:52:31.227743Z"}]}
{"channel":"book","type":"update","data":[{"symbol":"ETH/USD","bids":[{"price":3793.99,"qty":0.77000000}],"asks":[],"checksum":2103373257,"timestamp":"2024-06-01T17:52:31.232863Z"}]}
{"channel":"book","type":"update","data":[{"symbol":"ETH/USD","bids":[],"asks":[{"price":3796.79,"qty":20.68621037}],"checksum":3148651968,"timestamp":"2024-06-01T17:52:31.232988Z"}]}
{"channel":"book","type":"update","data":[{"symbol":"ETH/USD","bids":[{"price":3794.52,"qty":0.05759107}],"asks":[],"checksum":2304522688,"timestamp":"2024-06-01T17:52:31.233395Z"}]}
{"channel":"book","type":"update","data":[{"symbol":"ETH/USD","bids":[],"asks":[{"price":3795.29,"qty":3.00000000}],"checksum":3360270037,"timestamp":"2024-06-01T17:52:31.233610Z"}]}
{"channel":"book","type":"update","data":[{"symbol":"ETH/USD","bids":[],"asks":[{"price":3796.42,"qty":3.00000000}],"checksum":1439932835,"timestamp":"2024-06-01T17:52:31.233942Z"}]}
{"channel":"book","type":"update","data":[{"symbol":"ETH/USD","bids":[],"asks":[{"price":3796.96,"qty":0.00000000},{"price":3797.00,"qty":0.06693358}],"checksum":801074896,"timestamp":"2024-06-01T17:52:31.234086Z"}]}
{"channel":"book","type":"update","data":[{"symbol":"ETH/USD","bids":[{"price":3794.53,"qty":0.00515731}],"asks":[],"checksum":136012608,"timestamp":"2024-06-01T17:52:31.234253Z"}]}
{"channel":"book","type":"update","data":[{"symbol":"ETH/USD","bids":[{"price":3793.99,"qty":0.00000000},{"price":3793.84,"qty":12.32000000}],"asks":[],"checksum":1100245967,"timestamp":"2024-06-01T17:52:31.236413Z"}]}
{"channel":"book","type":"update","data":[{"symbol":"ETH/USD","bids":[],"asks":[{"price":3797.00,"qty":0.00000000},{"price":3797.07,"qty":0.30203318}],"checksum":1128722195,"timestamp":"2024-06-01T17:52:31.239823Z"}]}
{"channel":"book","type":"update","data":[{"symbol":"ETH/USD","bids":[],"asks":[{"price":3795.47,"qty":47.66154446}],"checksum":825216599,"timestamp":"2024-06-01T17:52:31.240561Z"}]}
{"channel":"book","type":"update","data":[{"symbol":"ETH/USD","bids":[],"asks":[{"price":3796.80,"qty":0.00000000},{"price":3797.09,"qty":3.00000000}],"checksum":713686345,"timestamp":"2024-06-01T17:52:31.241573Z"}]}
{"channel":"book","type":"update","data":[{"symbol":"ETH/USD","bids":[],"asks":[{"price":3795.18,"qty":0.77000000}],"checksum":795544602,"timestamp":"2024-06-01T17:52:31.241871Z"}]}
{"channel":"book","type":"update","data":[{"symbol":"ETH/USD","bids":[],"asks":[{"price":3796.79,"qty":18.26846104}],"checksum":4185396741,"timestamp":"2024-06-01T17:52:31.245037Z"}]}
{"channel":"book","type":"update","data":[{"symbol":"ETH/USD","bids":[],"asks":[{"price":3795.47,"qty":21.31434636}],"checksum":2031398581,"timestamp":"2024-06-01T17:52:31.245265Z"}]}
{"channel":"book","type":"update","data":[{"symbol":"ETH/USD","bids":[{"price":3794.55,"qty":0.00000000},{"price":3793.80,"qty":1.05333443}],"asks":[],"checksum":482022573,"timestamp":"2024-06-01T17:52:31.245301Z"}]}
{"channel":"book","type":"update","data":[{"symbol":"ETH/USD","bids":[],"asks":[{"price":3795.47,"qty":18.31434636}],"checksum":115035830,"timestamp":"2024-06-01T17:52:31.245510Z"}]}
{"channel":"book","type":"update","data":[{"symbol":"ETH/USD","bids":[],"asks":[{"price":3796.79,"qty":16.71468556}],"checksum":2498570135,"timestamp":"2024-06-01T17:52:31.245629Z"}]}
{"channel":"book","type":"update","data":[{"symbol":"ETH/USD","bids":[],"asks":[{"price":3795.29,"qty":6.00000000}],"checksum":599699187,"timestamp":"2024-06-01T17:52:31.249410Z"}]}
{"channel":"book","type":"update","data":[{"symbol":"ETH/USD","bids":[],"asks":[{"price":3795.47,"qty":19.31434636}],"checksum":4144392169,"timestamp":"2024-06-01T17:52:31.252032Z"}]}
{"channel":"book","type":"update","data":[{"symbol":"ETH/USD","bids":[],"asks":[{"price":3795.18,"qty":3.77000000}],"checksum":1724985887,"timestamp":"2024-06-01T17:52:31.252995Z"}]}
{"channel":"book","type":"update","data":[{"symbol":"ETH/USD","bids":[],"asks":[{"price":3795.29,"qty":3.00000000}],"checksum":3515005819,"timestamp":"2024-06-01T17:52:31.253430Z"}]}
{"channel":"book","type":"update","data":[{"symbol":"ETH/USD","bids":[],"asks":[{"price":3795.47,"qty":16.31434636}],"checksum":2152241515,"timestamp":"2024-06-01T17:52:31.253611Z"}]}
{"channel":"book","type":"update","data":[{"symbol":"ETH/USD","bids":[],"asks":[{"price":3796.78,"qty":0.00000000},{"price":3797.09,"qty":3.00000000}],"checksum":152643259,"timestamp":"2024-06-01T17:52:31.253854Z"}]}
{"channel":"book","type":"update","data":[{"symbol":"ETH/USD","bids":[],"asks":[{"price":3795.29,"qty":0.00000000},{"price":3797.45,"qty":0.94574642}],"checksum":2420105552,"timestamp":"2024-06-01T17:52:31.259427Z"}]}
{"channel":"book","type":"update","data":[{"symbol":"ETH/USD","bids":[],"asks":[{"price":3796.31,"qty":0.00000000},{"price":3797.47,"qty":3.00000000}],"checksum":1138138697,"timestamp":"2024-06-01T17:52:31.261739Z"}]}
{"channel":"book","type":"update","data":[{"symbol":"ETH/USD","bids":[{"price":3794.53,"qty":0.00000000},{"price":3793.72,"qty":3.00000000}],"asks":[],"checksum":2542549821,"timestamp":"2024-06-01T17:52:31.264679Z"}]}
{"channel":"book","type":"update","data":[{"symbol":"ETH/USD","bids":[],"asks":[{"price":3795.46,"qty":3.30000000}],"checksum":3593011450,"timestamp":"2024-06-01T17:52:31.265273Z"}]}
{"channel":"book","type":"update","data":[{"symbol":"ETH/USD","bids":[],"asks":[{"price":3797.45,"qty":0.10000000}],"checksum":923992131,"timestamp":"2024-06-01T17:52:31.265751Z"}]}
{"channel":"book","type":"update","data":[{"symbol":"ETH/USD","bids":[{"price":3793.85,"qty":12.28658474}],"asks":[],"checksum":1519656036,"timestamp":"2024-06-01T17:52:31.267350Z"}]}
{"channel":"book","type":"update","data":[{"symbol":"ETH/USD","bids":[{"price":3793.86,"qty":0.00523308}],"asks":[],"checksum":1217361635,"timestamp":"2024-06-01T17:52:31.268816Z"}]}
{"channel":"book","type":"update","data":[{"symbol":"ETH/USD","bids":[],"asks":[{"price":3795.18,"qty":6.77000000}],"checksum":469790737,"timestamp":"2024-06-01T17:52:31.269041Z"}]}
{"channel":"book","type":"update","data":[{"symbol":"ETH/USD","bids":[{"price":3793.84,"qty":0.00000000},{"price":3793.72,"qty":3.00000000}],"asks":[],"checksum":3954174330,"timestamp":"2024-06-01T17:52:31.270775Z"}]}
{"channel":"book","type":"update","data":[{"symbol":"ETH/USD","bids":[],"asks":[{"price":3797.08,"qty":0.00534482}],"checksum":3860876859,"timestamp":"2024-06-01T17:52:31.276171Z"}]}
{"channel":"book","type":"update","data":[{"symbol":"ETH/USD","bids":[{"price":3794.14,"qty":29.35636820}],"asks":[],"checksum":2255462501,"timestamp":"2024-06-01T17:52:31.276604Z"}]}
{"channel":"book","type":"update","data":[{"symbol":"ETH/USD","bids":[],"asks":[{"price":3795.18,"qty":33.11921136}],"checksum":1436369827,"timestamp":"2024-06-01T17:52:31.276630Z"}]}
{"channel":"book","type":"update","data":[{"symbol":"ETH/USD","bids":[{"price":3793.86,"qty":0.00000000},{"price":3793.25,"qty":3.00000000}],"asks":[],"checksum":3909772034,"timestamp":"2024-06-01T17:52:31.276787Z"}]}
{"channel":"book","type":"update","data":[{"symbol":"ETH/USD","bids":[],"asks":[{"price":3796.75,"qty":5.27100000}],"checksum":1577055382,"timestamp":"2024-06-01T17:52:31.277126Z"}]}
{"channel":"book","type":"update","data":[{"symbol":"ETH/USD","bids":[],"asks":[{"price":3795.18,"qty":46.29647087}],"checksum":2794890190,"timestamp":"2024-06-01T17:52:31.282356Z"}]}
{"channel":"book","type":"update","data":[{"symbol":"ETH/USD","bids":[],"asks":[{"price":3795.47,"qty":3.13800000}],"checksum":4211131010,"timestamp":"2024-06-01T17:52:31.282802Z"}]}
{"channel":"book","type":"update","data":[{"symbol":"ETH/USD","bids":[{"price":3794.14,"qty":3.00000000}],"asks":[],"checksum":60816164,"timestamp":"2024-06-01T17:52:31.283188Z"}]}
{"channel":"book","type":"update","data":[{"symbol":"ETH/USD","bids":[],"asks":[{"price":3796.78,"qty":2.63600000}],"checksum":3394546311,"timestamp":"2024-06-01T17:52:31.283284Z"}]}
{"channel":"book","type":"update","data":[{"symbol":"ETH/USD","bids":[],"asks":[{"price":3796.79,"qty":15.71468556}],"checksum":24646600,"timestamp":"2024-06-01T17:52:31.285081Z"}]}
{"channel":"book","type":"update","data":[{"symbol":"ETH/USD","bids":[{"price":3793.80,"qty":0.00000000},{"price":3792.92,"qty":0.42520158}],"asks":[],"checksum":2566529749,"timestamp":"2024-06-01T17:52:31.287297Z"}]}
{"channel":"book","type":"update","data":[{"symbol":"ETH/USD","bids":[],"asks":[{"price":3795.41,"qty":26.34768211}],"checksum":3344423210,"timestamp":"2024-06-01T17:52:31.288531Z"}]}
{"channel":"book","type":"update","data":[{"symbol":"ETH/USD","bids":[{"price":3792.93,"qty":26.35210146}],"asks":[],"checksum":1113503402,"timestamp":"2024-06-01T17:52:31.293645Z"}]}
{"channel":"book","type":"update","data":[{"symbol":"ETH/USD","bids":[],"asks":[{"price":3796.79,"qty":42.06678702}],"checksum":512488368,"timestamp":"2024-06-01T17:52:31.293755Z"}]}
{"channel":"book","type":"update","data":[{"symbol":"ETH/USD","bids":[{"price":3793.76,"qty":3.95211095}],"asks":[],"checksum":1726094925,"timestamp":"2024-06-01T17:52:31.296295Z"}]}
{"channel":"book","type":"update","data":[{"symbol":"ETH/USD","bids":[{"price":3793.57,"qty":3.95211095}],"asks":[],"checksum":1877430119,"timestamp":"2024-06-01T17:52:31.297033Z"}]}
{"channel":"book","type":"update","data":[{"symbol":"ETH/USD","bids":[],"asks":[{"price":3795.45,"qty":0.81285127}],"checksum":4273937332,"timestamp":"2024-06-01T17:52:31.299287Z"}]}
{"channel":"book","type":"update","data":[{"symbol":"ETH/USD","bids":[],"asks":[{"price":3795.18,"qty":43.29647087}],"checksum":104900675,"timestamp":"2024-06-01T17:52:31.304577Z"}]}
{"channel":"book","type":"update","data":[{"symbol":"ETH/USD","bids":[{"price":3794.83,"qty":0.00000000},{"price":3793.25,"qty":3.00000000}],"asks":[],"checksum":3351464225,"timestamp":"2024-06-01T17:52:31.306612Z"}]}
{"channel":"book","type":"update","data":[{"symbol":"ETH/USD","bids":[{"price":3795.17,"qty":0.00000000},{"price":3792.93,"qty":26.35210146},{"price":3794.84,"qty":0.00937043}],"asks":[],"checksum":4246847116,"timestamp":"2024-06-01T17:52:31.310214Z"}]}
{"channel":"book","type":"update","data":[{"symbol":"ETH/USD","bids":[],"asks":[{"price":3795.05,"qty":3.00000000}],"checksum":1085205286,"timestamp":"2024-06-01T17:52:31.317768Z"}]}
{"channel":"book","type":"update","data":[{"symbol":"ETH/USD","bids":[],"asks":[{"price":3795.18,"qty":16.94725951}],"checksum":2518760117,"timestamp":"2024-06-01T17:52:31.318687Z"}]}
{"channel":"book","type":"update","data":[{"symbol":"ETH/USD","bids":[],"asks":[{"price":3794.91,"qty":26.35114550}],"checksum":1183198454,"timestamp":"2024-06-01T17:52:31.318743Z"}]}
{"channel":"book","type":"update","data":[{"symbol":"ETH/USD","bids":[],"asks":[{"price":3795.18,"qty":17.94725951}],"checksum":1233825258,"timestamp":"2024-06-01T17:52:31.319022Z"}]}
{"channel":"book","type":"update","data":[{"symbol":"ETH/USD","bids":[],"asks":[{"price":3795.18,"qty":17.17725951}],"checksum":2741992382,"timestamp":"2024-06-01T17:52:31.319811Z"}]}
{"channel":"book","type":"update","data":[{"symbol":"ETH/USD","bids":[{"price":3793.77,"qty":0.00520865}],"asks":[],"checksum":28354528,"timestamp":"2024-06-01T17:52:31.319997Z"}]}
{"channel":"book","type":"update","data":[{"symbol":"ETH/USD","bids":[],"asks":[{"price":3794.85,"qty":0.77000000}],"checksum":2421152452,"timestamp":"2024-06-01T17:52:31.323142Z"}]}
{"channel":"book","type":"update","data":[{"symbol":"ETH/USD","bids":[],"asks":[{"price":3795.45,"qty":0.00000000},{"price":3796.75,"qty":5.27100000}],"checksum":4232826722,"timestamp":"2024-06-01T17:52:31.324794Z"}]}
{"channel":"book","type":"update","data":[{"symbol":"ETH/USD","bids":[],"asks":[{"price":3794.91,"qty":0.00000000},{"price":3796.78,"qty":2.63600000}],"checksum":2512281818,"timestamp":"2024-06-01T17:52:31.326334Z"}]}
{"channel":"book","type":"update","data":[{"symbol":"ETH/USD","bids":[],"asks":[{"price":3796.41,"qty":0.84574642}],"checksum":9542448,"timestamp":"2024-06-01T17:52:31.327211Z"}]}
{"channel":"book","type":"update","data":[{"symbol":"ETH/USD","bids":[],"asks":[{"price":3795.29,"qty":3.00000000}],"checksum":2460883389,"timestamp":"2024-06-01T17:52:31.327254Z"}]}
{"channel":"book","type":"update","data":[{"symbol":"ETH/USD","bids":[],"asks":[{"price":3794.85,"qty":0.00000000},{"price":3796.75,"qty":5.27100000}],"checksum":1675748772,"timestamp":"2024-06-01T17:52:31.328876Z"}]}
{"channel":"book","type":"update","data":[{"symbol":"ETH/USD","bids":[{"price":3794.11,"qty":26.35663936}],"asks":[],"checksum":1485442143,"timestamp":"2024-06-01T17:52:31.331089Z"}]}
{"channel":"book","type":"update","data":[{"symbol":"ETH/USD","bids":[],"asks":[{"price":3794.85,"qty":26.35150269}],"checksum":1497660876,"timestamp":"2024-06-01T17:52:31.331114Z"}]}
{"channel":"book","type":"update","data":[{"symbol":"ETH/USD","bids":[],"asks":[{"price":3795.05,"qty":0.00000000},{"price":3796.75,"qty":5.27100000}],"checksum":2729409182,"timestamp":"2024-06-01T17:52:31.331458Z"}]}
{"channel":"book","type":"update","data":[{"symbol":"ETH/USD","bids":[],"asks":[{"price":3795.29,"qty":0.00000000},{"price":3796.78,"qty":2.63600000}],"checksum":3521739020,"timestamp":"2024-06-01T17:52:31.333277Z"}]}
{"channel":"book","type":"update","data":[{"symbol":"ETH/USD","bids":[],"asks":[{"price":3795.23,"qty":3.00000000}],"checksum":3651037252,"timestamp":"2024-06-01T17:52:31.339579Z"}]}
{"channel":"book","type":"update","data":[{"symbol":"ETH/USD","bids":[{"price":3794.11,"qty":0.00000000},{"price":3793.57,"qty":3.95211095}],"asks":[],"checksum":3381867376,"timestamp":"2024-06-01T17:52:31.340979Z"}]}
{"channel":"book","type":"update","data":[{"symbol":"ETH/USD","bids":[],"asks":[{"price":3795.47,"qty":2.13800000}],"checksum":798508204,"timestamp":"2024-06-01T17:52:31.350625Z"}]}
{"channel":"book","type":"update","data":[{"symbol":"ETH/USD","bids":[],"asks":[{"price":3795.23,"qty":0.00000000},{"price":3796.78,"qty":2.63600000}],"checksum":2576870270,"timestamp":"2024-06-01T17:52:31.366266Z"}]}
{"channel":"book","type":"update","data":[{"symbol":"ETH/USD","bids":[{"price":3794.84,"qty":0.00000000},{"price":3793.25,"qty":3.00000000},{"price":3794.53,"qty":0.00937119}],"asks":[],"checksum":2923459652,"timestamp":"2024-06-01T17:52:31.369131Z"}]}
{"channel":"book","type":"update","data":[{"symbol":"ETH/USD","bids":[],"asks":[{"price":3794.85,"qty":0.00000000},{"price":3796.79,"qty":41.22104060}],"checksum":2392718403,"timestamp":"2024-06-01T17:52:31.375027Z"}]}
{"channel":"book","type":"update","data":[{"symbol":"ETH/USD","bids":[{"price":3793.92,"qty":0.77000000}],"asks":[],"checksum":1641578913,"timestamp":"2024-06-01T17:52:31.379616Z"}]}
{"channel":"book","type":"update","data":[{"symbol":"ETH/USD","bids":[],"asks":[{"price":3794.84,"qty":26.35157213}],"checksum":3753555987,"timestamp":"2024-06-01T17:52:31.381409Z"}]}
{"channel":"book","type":"update","data":[{"symbol":"ETH/USD","bids":[{"price":3794.17,"qty":26.35617545}],"asks":[],"checksum":607459614,"timestamp":"2024-06-01T17:52:31.381425Z"}]}
{"channel":"book","type":"update","data":[{"symbol":"ETH/USD","bids":[],"asks":[{"price":3795.18,"qty":14.17725951}],"checksum":2872948377,"timestamp":"2024-06-01T17:52:31.386355Z"}]}
{"channel":"book","type":"update","data":[{"symbol":"ETH/USD","bids":[],"asks":[{"price":3794.84,"qty":0.00000000},{"price":3796.79,"qty":41.22104060}],"checksum":2255052714,"timestamp":"2024-06-01T17:52:31.387016Z"}]}
{"channel":"book","type":"update","data":[{"symbol":"ETH/USD","bids":[],"asks":[{"price":3795.46,"qty":0.00000000},{"price":3796.95,"qty":0.41184735}],"checksum":3322299554,"timestamp":"2024-06-01T17:52:31.390315Z"}]}
{"channel":"book","type":"update","data":[{"symbol":"ETH/USD","bids":[],"asks":[{"price":3795.40,"qty":3.30000000}],"checksum":1840341314,"timestamp":"2024-06-01T17:52:31.390438Z"}]}
{"channel":"book","type":"update","data":[{"symbol":"ETH/USD","bids":[{"price":3794.17,"qty":0.00000000},{"price":3793.72,"qty":3.00000000}],"asks":[],"checksum":847620597,"timestamp":"2024-06-01T17:52:31.392272Z"}]}
{"channel":"book","type":"update","data":[{"symbol":"ETH/USD","bids":[],"asks":[{"price":3795.18,"qty":17.17725951}],"checksum":3083884132,"timestamp":"2024-06-01T17:52:31.394494Z"}]}
{"channel":"book","type":"update","data":[{"symbol":"ETH/USD","bids":[],"asks":[{"price":3795.17,"qty":3.00000000}],"checksum":2495994951,"timestamp":"2024-06-01T17:52:31.395125Z"}]}
{"channel":"book","type":"update","data":[{"symbol":"ETH/USD","bids":[],"asks":[{"price":3795.17,"qty":0.00000000},{"price":3796.79,"qty":41.22104060}],"checksum":3083884132,"timestamp":"2024-06-01T17:52:31.400364Z"}]}
{"channel":"book","type":"update","data":[{"symbol":"ETH/USD","bids":[],"asks":[{"price":3795.18,"qty":14.17725951}],"checksum":847620597,"timestamp":"2024-06-01T17:52:31.402504Z"}]}
{"channel":"book","type":"update","data":[{"symbol":"ETH/USD","bids":[],"asks":[{"price":3796.41,"qty":9.01574642}],"checksum":2408109212,"timestamp":"2024-06-01T17:52:31.402974Z"}]}
{"channel":"book","type":"update","data":[{"symbol":"ETH/USD","bids":[{"price":3794.55,"qty":3.00000000}],"asks":[],"checksum":2959588378,"timestamp":"2024-06-01T17:52:31.404217Z"}]}
{"channel":"book","type":"update","data":[{"symbol":"ETH/USD","bids":[{"price":3793.99,"qty":26.35746151}],"asks":[],"checksum":2807246721,"timestamp":"2024-06-01T17:52:31.408149Z"}]}
{"channel":"book","type":"update","data":[{"symbol":"ETH/USD","bids":[{"price":3794.55,"qty":6.00000000}],"asks":[],"checksum":1695983123,"timestamp":"2024-06-01T17:52:31.408294Z"}]}
{"channel":"book","type":"update","data":[{"symbol":"ETH/USD","bids":[],"asks":[{"price":3796.79,"qty":34.46104060}],"checksum":409680967,"timestamp":"2024-06-01T17:52:31.408837Z"}]}
{"channel":"book","type":"update","data":[{"symbol":"ETH/USD","bids":[],"asks":[{"price":3795.56,"qty":3.00000000}],"checksum":2435632871,"timestamp":"2024-06-01T17:52:31.411324Z"}]}
{"channel":"book","type":"update","data":[{"symbol":"ETH/USD","bids":[],"asks":[{"price":3795.17,"qty":0.81285127}],"checksum":86785997,"timestamp":"2024-06-01T17:52:31.427745Z"}]}
{"channel":"book","type":"update","data":[{"symbol":"ETH/USD","bids":[],"asks":[{"price":3795.56,"qty":0.00000000},{"price":3796.78,"qty":2.63600000}],"checksum":4270408217,"timestamp":"2024-06-01T17:52:31.431538Z"}]}
{"channel":"book","type":"update","data":[{"symbol":"ETH/USD","bids":[],"asks":[{"price":3794.75,"qty":26.35220951}],"checksum":1648938074,"timestamp":"2024-06-01T17:52:31.431597Z"}]}
{"channel":"book","type":"update","data":[{"symbol":"ETH/USD","bids":[{"price":3794.07,"qty":26.35685427}],"asks":[],"checksum":2493290059,"timestamp":"2024-06-01T17:52:31.431678Z"}]}
{"channel":"book","type":"update","data":[{"symbol":"ETH/USD","bids":[],"asks":[{"price":3794.56,"qty":0.77000000}],"checksum":864219408,"timestamp":"2024-06-01T17:52:31.432214Z"}]}
{"channel":"book","type":"update","data":[{"symbol":"ETH/USD","bids":[],"asks":[{"price":3795.47,"qty":4.25382355}],"checksum":1185566250,"timestamp":"2024-06-01T17:52:31.432350Z"}]}
{"channel":"book","type":"update","data":[{"symbol":"ETH/USD","bids":[],"asks":[{"price":3796.41,"qty":0.84574642}],"checksum":3906311788,"timestamp":"2024-06-01T17:52:31.432861Z"}]}
{"channel":"book","type":"update","data":[{"symbol":"ETH/USD","bids":[],"asks":[{"price":3795.17,"qty":0.00000000},{"price":3796.75,"qty":5.27100000}],"checksum":2660286940,"timestamp":"2024-06-01T17:52:31.436249Z"}]}
{"channel":"book","type":"update","data":[{"symbol":"ETH/USD","bids":[],"asks":[{"price":3795.55,"qty":3.00000000}],"checksum":664942473,"timestamp":"2024-06-01T17:52:31.436321Z"}]}
{"channel":"book","type":"update","data":[{"symbol":"ETH/USD","bids":[{"price":3794.07,"qty":0.00000000},{"price":3793.77,"qty":0.00520865}],"asks":[],"checksum":4253189728,"timestamp":"2024-06-01T17:52:31.439782Z"}]}
{"channel":"book","type":"update","data":[{"symbol":"ETH/USD","bids":[],"asks":[{"price":3794.75,"qty":0.00000000},{"price":3796.75,"qty":5.27100000}],"checksum":4220236125,"timestamp":"2024-06-01T17:52:31.439797Z"}]}
{"channel":"book","type":"update","data":[{"symbol":"ETH/USD","bids":[{"price":3794.43,"qty":0.00000000},{"price":3793.76,"qty":3.95211095}],"asks":[],"checksum":2143741225,"timestamp":"2024-06-01T17:52:31.448413Z"}]}
{"channel":"book","type":"update","data":[{"symbol":"ETH/USD","bids":[{"price":3793.78,"qty":26.35888266}],"asks":[],"checksum":3505241577,"timestamp":"2024-06-01T17:52:31.466155Z"}]}
{"channel":"book","type":"update","data":[{"symbol":"ETH/USD","bids":[],"asks":[{"price":3795.09,"qty":26.34986175}],"checksum":3835431291,"timestamp":"2024-06-01T17:52:31.466210Z"}]}
{"channel":"book","type":"update","data":[{"symbol":"ETH/USD","bids":[],"asks":[{"price":3795.08,"qty":2.40000000}],"checksum":2191745410,"timestamp":"2024-06-01T17:52:31.474583Z"}]}
{"channel":"book","type":"update","data":[{"symbol":"ETH/USD","bids":[{"price":3793.99,"qty":0.00000000},{"price":3793.76,"qty":3.95211095}],"asks":[],"checksum":343121831,"timestamp":"2024-06-01T17:52:31.475572Z"}]}
{"channel":"book","type":"update","data":[{"symbol":"ETH/USD","bids":[],"asks":[{"price":3795.09,"qty":0.00000000},{"price":3796.42,"qty":3.00000000}],"checksum":1584548395,"timestamp":"2024-06-01T17:52:31.475615Z"}]}
{"channel":"book","type":"update","data":[{"symbol":"ETH/USD","bids":[{"price":3794.53,"qty":0.00000000},{"price":3793.72,"qty":3.00000000},{"price":3794.29,"qty":0.00937179}],"asks":[],"checksum":459978956,"timestamp":"2024-06-01T17:52:31.482101Z"}]}
{"channel":"book","type":"update","data":[{"symbol":"ETH/USD","bids":[],"asks":[{"price":3795.16,"qty":1.00000000}],"checksum":1328735302,"timestamp":"2024-06-01T17:52:31.483985Z"}]}
{"channel":"book","type":"update","data":[{"symbol":"ETH/USD","bids":[],"asks":[{"price":3795.41,"qty":0.00000000},{"price":3796.42,"qty":3.00000000}],"checksum":2335261750,"timestamp":"2024-06-01T17:52:31.492125Z"}]}
{"channel":"book","type":"update","data":[{"symbol":"ETH/USD","bids":[{"price":3793.92,"qty":0.00000000},{"price":3793.72,"qty":3.00000000}],"asks":[],"checksum":2072596598,"timestamp":"2024-06-01T17:52:31.493291Z"}]}
{"channel":"book","type":"update","data":[{"symbol":"ETH/USD","bids":[{"price":3793.78,"qty":0.00000000},{"price":3793.57,"qty":3.95211095}],"asks":[],"checksum":1133666400,"timestamp":"2024-06-01T17:52:31.498453Z"}]}
{"channel":"book","type":"update","data":[{"symbol":"ETH/USD","bids":[{"price":3793.93,"qty":26.35787003}],"asks":[],"checksum":605190103,"timestamp":"2024-06-01T17:52:31.504478Z"}]}
{"channel":"book","type":"update","data":[{"symbol":"ETH/USD","bids":[],"asks":[{"price":3794.63,"qty":26.35308951}],"checksum":1434757150,"timestamp":"2024-06-01T17:52:31.504529Z"}]}
{"channel":"book","type":"update","data":[{"symbol":"ETH/USD","bids":[],"asks":[{"price":3795.60,"qty":0.72912968}],"checksum":2675086729,"timestamp":"2024-06-01T17:52:31.509693Z"}]}
{"channel":"book","type":"update","data":[{"symbol":"ETH/USD","bids":[],"asks":[{"price":3794.63,"qty":0.00000000},{"price":3796.41,"qty":0.84574642}],"checksum":812256806,"timestamp":"2024-06-01T17:52:31.517883Z"}]}
{"channel":"book","type":"update","data":[{"symbol":"ETH/USD","bids":[{"price":3793.93,"qty":0.00000000},{"price":3793.57,"qty":3.95211095}],"asks":[],"checksum":985128572,"timestamp":"2024-06-01T17:52:31.517921Z"}]}
{"channel":"book","type":"update","data":[{"symbol":"ETH/USD","bids":[],"asks":[{"price":3795.16,"qty":0.00000000},{"price":3796.42,"qty":3.00000000}],"checksum":4069408022,"timestamp":"2024-06-01T17:52:31.519683Z"}]}
{"channel":"book","type":"update","data":[{"symbol":"ETH/USD","bids":[{"price":3793.75,"qty":3.94900000}],"asks":[],"checksum":3675494325,"timestamp":"2024-06-01T17:52:31.521154Z"}]}
{"channel":"book","type":"update","data":[{"symbol":"ETH/USD","bids":[{"price":3794.55,"qty":3.00000000}],"asks":[],"checksum":3318751316,"timestamp":"2024-06-01T17:52:31.529079Z"}]}
{"channel":"book","type":"update","data":[{"symbol":"ETH/USD","bids":[{"price":3794.55,"qty":0.00000000},{"price":3793.57,"qty":3.95211095}],"asks":[],"checksum":3989399005,"timestamp":"2024-06-01T17:52:31.531707Z"}]}
{"channel":"book","type":"update","data":[{"symbol":"ETH/USD","bids":[],"asks":[{"price":3795.07,"qty":0.81285127}],"checksum":3428554788,"timestamp":"2024-06-01T17:52:31.534819Z"}]}
{"channel":"book","type":"update","data":[{"symbol":"ETH/USD","bids":[],"asks":[{"price":3795.47,"qty":2.13800000}],"checksum":2962490358,"timestamp":"2024-06-01T17:52:31.535306Z"}]}
{"channel":"book","type":"update","data":[{"symbol":"ETH/USD","bids":[{"price":3793.98,"qty":26.35748779}],"asks":[],"checksum":1104838764,"timestamp":"2024-06-01T17:52:31.558506Z"}]}
{"channel":"book","type":"update","data":[{"symbol":"ETH/USD","bids":[],"asks":[{"price":3794.66,"qty":26.35288657}],"checksum":2782271166,"timestamp":"2024-06-01T17:52:31.559204Z"}]}
{"channel":"book","type":"update","data":[{"symbol":"ETH/USD","bids":[],"asks":[{"price":3794.56,"qty":0.00000000},{"price":3796.41,"qty":0.84574642}],"checksum":3245155320,"timestamp":"2024-06-01T17:52:31.561067Z"}]}
{"channel":"book","type":"update","data":[{"symbol":"ETH/USD","bids":[],"asks":[{"price":3796.00,"qty":0.00000000},{"price":3796.42,"qty":3.00000000}],"checksum":79946896,"timestamp":"2024-06-01T17:52:31.563384Z"}]}
{"channel":"book","type":"update","data":[{"symbol":"ETH/USD","bids":[{"price":3794.52,"qty":3.05759107}],"asks":[],"checksum":2484284025,"timestamp":"2024-06-01T17:52:31.572976Z"}]}
{"channel":"book","type":"update","data":[{"symbol":"ETH/USD","bids":[{"price":3794.52,"qty":6.05759107}],"asks":[],"checksum":2514107269,"timestamp":"2024-06-01T17:52:31.573324Z"}]}
{"channel":"book","type":"update","data":[{"symbol":"ETH/USD","bids":[{"price":3793.85,"qty":5.08658474}],"asks":[],"checksum":3579407974,"timestamp":"2024-06-01T17:52:31.574020Z"}]}
{"channel":"book","type":"update","data":[{"symbol":"ETH/USD","bids":[],"asks":[{"price":3794.66,"qty":0.00000000},{"price":3796.64,"qty":0.91400000}],"checksum":3906658442,"timestamp":"2024-06-01T17:52:31.578100Z"}]}
{"channel":"book","type":"update","data":[{"symbol":"ETH/USD","bids":[{"price":3793.98,"qty":0.00000000},{"price":3793.57,"qty":3.95211095}],"asks":[],"checksum":2996807757,"timestamp":"2024-06-01T17:52:31.578163Z"}]}
{"channel":"book","type":"update","data":[{"symbol":"ETH/USD","bids":[],"asks":[{"price":3795.55,"qty":0.00000000},{"price":3796.75,"qty":5.27100000}],"checksum":787050139,"timestamp":"2024-06-01T17:52:31.580133Z"}]}
{"channel":"book","type":"update","data":[{"symbol":"ETH/USD","bids":[],"asks":[{"price":3794.82,"qty":26.35171106}],"checksum":3643904553,"timestamp":"2024-06-01T17:52:31.585230Z"}]}
{"channel":"book","type":"update","data":[{"symbol":"ETH/USD","bids":[],"asks":[{"price":3794.82,"qty":0.00000000},{"price":3796.75,"qty":5.27100000}],"checksum":787050139,"timestamp":"2024-06-01T17:52:31.591489Z"}]}
{"channel":"book","type":"update","data":[{"symbol":"ETH/USD","bids":[{"price":3793.85,"qty":8.38658474}],"asks":[],"checksum":3554285888,"timestamp":"2024-06-01T17:52:31.594695Z"}]}
{"channel":"book","type":"update","data":[{"symbol":"ETH/USD","bids":[{"price":3793.97,"qty":0.77000000}],"asks":[],"checksum":2067356822,"timestamp":"2024-06-01T17:52:31.595669Z"}]}
{"channel":"book","type":"update","data":[{"symbol":"ETH/USD","bids":[],"asks":[{"price":3794.76,"qty":26.35219081}],"checksum":1235593811,"timestamp":"2024-06-01T17:52:31.607816Z"}]}
{"channel":"book","type":"update","data":[{"symbol":"ETH/USD","bids":[{"price":3794.06,"qty":26.35692366}],"asks":[],"checksum":73652666,"timestamp":"2024-06-01T17:52:31.607844Z"}]}
{"channel":"book","type":"update","data":[{"symbol":"ETH/USD","bids":[{"price":3794.52,"qty":3.05759107}],"asks":[],"checksum":3547384035,"timestamp":"2024-06-01T17:52:31.611734Z"}]}
{"channel":"book","type":"update","data":[{"symbol":"ETH/USD","bids":[{"price":3794.53,"qty":3.00000000}],"asks":[],"checksum":1654429167,"timestamp":"2024-06-01T17:52:31.614599Z"}]}
{"channel":"book","type":"update","data":[{"symbol":"ETH/USD","bids":[{"price":3794.06,"qty":0.00000000},{"price":3793.75,"qty":3.94900000}],"asks":[],"checksum":2886482606,"timestamp":"2024-06-01T17:52:31.616200Z"}]}
{"channel":"book","type":"update","data":[{"symbol":"ETH/USD","bids":[],"asks":[{"price":3794.76,"qty":0.00000000},{"price":3796.75,"qty":5.27100000}],"checksum":2660289643,"timestamp":"2024-06-01T17:52:31.616216Z"}]}
{"channel":"book","type":"update","data":[{"symbol":"ETH/USD","bids":[{"price":3794.53,"qty":0.00000000},{"price":3793.72,"qty":3.00000000}],"asks":[],"checksum":1710943095,"timestamp":"2024-06-01T17:52:31.618476Z"}]}
{"channel":"book","type":"update","data":[{"symbol":"ETH/USD","bids":[{"price":3794.53,"qty":3.00000000}],"asks":[],"checksum":2660289643,"timestamp":"2024-06-01T17:52:31.618605Z"}]}
{"channel":"book","type":"update","data":[{"symbol":"ETH/USD","bids":[{"price":3793.97,"qty":0.00000000},{"price":3793.72,"qty":3.00000000},{"price":3794.07,"qty":0.77000000}],"asks":[],"checksum":1111085530,"timestamp":"2024-06-01T17:52:31.618659Z"}]}
{"channel":"book","type":"update","data":[{"symbol":"ETH/USD","bids":[{"price":3794.53,"qty":6.00000000}],"asks":[],"checksum":1559914043,"timestamp":"2024-06-01T17:52:31.621201Z"}]}
{"channel":"book","type":"update","data":[{"symbol":"ETH/USD","bids":[{"price":3794.07,"qty":0.00000000},{"price":3793.72,"qty":3.00000000},{"price":3794.16,"qty":0.77000000}],"asks":[],"checksum":169856903,"timestamp":"2024-06-01T17:52:31.626960Z"}]}
{"channel":"book","type":"update","data":[{"symbol":"ETH/USD","bids":[{"price":3794.16,"qty":0.00000000},{"price":3793.72,"qty":3.00000000}],"asks":[],"checksum":4265377619,"timestamp":"2024-06-01T17:52:31.630255Z"}]}
{"channel":"book","type":"update","data":[{"symbol":"ETH/USD","bids":[{"price":3794.25,"qty":0.77000000}],"asks":[],"checksum":1015984028,"timestamp":"2024-06-01T17:52:31.630404Z"}]}
{"channel":"book","type":"update","data":[{"symbol":"ETH/USD","bids":[],"asks":[{"price":3794.61,"qty":0.09000000}],"checksum":437916045,"timestamp":"2024-06-01T17:52:31.631668Z"}]}
{"channel":"book","type":"update","data":[{"symbol":"ETH/USD","bids":[],"asks":[{"price":3795.47,"qty":0.00000000},{"price":3796.75,"qty":5.27100000}],"checksum":127659734,"timestamp":"2024-06-01T17:52:31.642910Z"}]}
{"channel":"book","type":"update","data":[{"symbol":"ETH/USD","bids":[{"price":3794.53,"qty":11.69000000}],"asks":[],"checksum":1951918364,"timestamp":"2024-06-01T17:52:31.643129Z"}]}
{"channel":"book","type":"update","data":[{"symbol":"ETH/USD","bids":[],"asks":[{"price":3795.08,"qty":0.00000000},{"price":3796.78,"qty":2.63600000}],"checksum":1818949733,"timestamp":"2024-06-01T17:52:31.653458Z"}]}
{"channel":"book","type":"update","data":[{"symbol":"ETH/USD","bids":[{"price":3794.56,"qty":2.94000000}],"asks":[],"checksum":2825142235,"timestamp":"2024-06-01T17:52:31.655673Z"}]}
{"channel":"book","type":"update","data":[{"symbol":"ETH/USD","bids":[{"price":3794.25,"qty":0.00000000},{"price":3793.75,"qty":3.94900000},{"price":3794.36,"qty":0.77000000}],"asks":[],"checksum":1907183863,"timestamp":"2024-06-01T17:52:31.655691Z"}]}
{"channel":"book","type":"update","data":[{"symbol":"ETH/USD","bids":[],"asks":[{"price":3795.18,"qty":13.17725951}],"checksum":389479411,"timestamp":"2024-06-01T17:52:31.657556Z"}]}
{"channel":"book","type":"update","data":[{"symbol":"ETH/USD","bids":[{"price":3794.54,"qty":0.05270227}],"asks":[],"checksum":1677040395,"timestamp":"2024-06-01T17:52:31.658706Z"}]}
{"channel":"book","type":"update","data":[{"symbol":"ETH/USD","bids":[],"asks":[{"price":3795.37,"qty":0.06693358}],"checksum":945870902,"timestamp":"2024-06-01T17:52:31.658992Z"}]}
{"channel":"book","type":"update","data":[{"symbol":"ETH/USD","bids":[{"price":3794.57,"qty":0.05270098}],"asks":[],"checksum":511270999,"timestamp":"2024-06-01T17:52:31.659024Z"}]}
{"channel":"book","type":"update","data":[{"symbol":"ETH/USD","bids":[{"price":3794.36,"qty":0.00000000},{"price":3793.77,"qty":0.00520865}],"asks":[],"checksum":3762762097,"timestamp":"2024-06-01T17:52:31.659854Z"}]}
{"channel":"book","type":"update","data":[{"symbol":"ETH/USD","bids":[{"price":3794.60,"qty":3.00000000}],"asks":[],"checksum":4193436705,"timestamp":"2024-06-01T17:52:31.660258Z"}]}
{"channel":"book","type":"update","data":[{"symbol":"ETH/USD","bids":[{"price":3794.52,"qty":0.05759107}],"asks":[],"checksum":638916398,"timestamp":"2024-06-01T17:52:31.660628Z"}]}
{"channel":"book","type":"update","data":[{"symbol":"ETH/USD","bids":[{"price":3794.34,"qty":26.35500792}],"asks":[],"checksum":1052910819,"timestamp":"2024-06-01T17:52:31.661571Z"}]}
{"channel":"book","type":"update","data":[{"symbol":"ETH/USD","bids":[{"price":3794.54,"qty":0.00000000},{"price":3793.85,"qty":8.38658474}],"asks":[],"checksum":3159989966,"timestamp":"2024-06-01T17:52:31.661666Z"}]}
{"channel":"book","type":"update","data":[{"symbol":"ETH/USD","bids":[],"asks":[{"price":3795.05,"qty":26.35012066}],"checksum":4007930949,"timestamp":"2024-06-01T17:52:31.661783Z"}]}
{"channel":"book","type":"update","data":[{"symbol":"ETH/USD","bids":[{"price":3794.57,"qty":0.00000000},{"price":3793.77,"qty":0.00520865}],"asks":[],"checksum":2143695292,"timestamp":"2024-06-01T17:52:31.662599Z"}]}
{"channel":"book","type":"update","data":[{"symbol":"ETH/USD","bids":[{"price":3794.58,"qty":0.05270098}],"asks":[],"checksum":64822110,"timestamp":"2024-06-01T17:52:31.662883Z"}]}
{"channel":"book","type":"update","data":[{"symbol":"ETH/USD","bids":[{"price":3794.40,"qty":0.77000000}],"asks":[],"checksum":1782366157,"timestamp":"2024-06-01T17:52:31.663038Z"}]}
{"channel":"book","type":"update","data":[{"symbol":"ETH/USD","bids":[],"asks":[{"price":3795.18,"qty":0.00000000},{"price":3796.75,"qty":5.27100000}],"checksum":2480765503,"timestamp":"2024-06-01T17:52:31.663531Z"}]}
{"channel":"book","type":"update","data":[{"symbol":"ETH/USD","bids":[{"price":3794.58,"qty":0.00000000},{"price":3793.85,"qty":8.38658474}],"asks":[],"checksum":509827564,"timestamp":"2024-06-01T17:52:31.665211Z"}]}
{"channel":"book","type":"update","data":[{"symbol":"ETH/USD","bids":[{"price":3794.34,"qty":0.00000000},{"price":3793.77,"qty":0.00520865}],"asks":[],"checksum":1343552682,"timestamp":"2024-06-01T17:52:31.668819Z"}]}
{"channel":"book","type":"update","data":[{"symbol":"ETH/USD","bids":[],"asks":[{"price":3795.05,"qty":0.00000000},{"price":3796.78,"qty":2.63600000}],"checksum":3551982359,"timestamp":"2024-06-01T17:52:31.668844Z"}]}
{"channel":"book","type":"update","data":[{"symbol":"ETH/USD","bids":[],"asks":[{"price":3795.40,"qty":0.00000000},{"price":3796.79,"qty":5.26500000}],"checksum":3743225879,"timestamp":"2024-06-01T17:52:31.672228Z"}]}
{"channel":"book","type":"update","data":[{"symbol":"ETH/USD","bids":[],"asks":[{"price":3796.30,"qty":3.30000000}],"checksum":2801419929,"timestamp":"2024-06-01T17:52:31.672260Z"}]}
{"channel":"book","type":"update","data":[{"symbol":"ETH/USD","bids":[{"price":3794.53,"qty":6.00000000}],"asks":[],"checksum":2924508150,"timestamp":"2024-06-01T17:52:31.673027Z"}]}
{"channel":"book","type":"update","data":[{"symbol":"ETH/USD","bids":[{"price":3794.28,"qty":0.00000000},{"price":3793.76,"qty":3.95211095}],"asks":[],"checksum":1335655587,"timestamp":"2024-06-01T17:52:31.674649Z"}]}
{"channel":"book","type":"update","data":[{"symbol":"ETH/USD","bids":[{"price":3794.40,"qty":0.00000000},{"price":3793.75,"qty":3.94900000}],"asks":[],"checksum":1554335577,"timestamp":"2024-06-01T17:52:31.676102Z"}]}
{"channel":"book","type":"update","data":[{"symbol":"ETH/USD","bids":[{"price":3793.85,"qty":5.08658474}],"asks":[],"checksum":3101874571,"timestamp":"2024-06-01T17:52:31.680426Z"}]}
{"channel":"book","type":"update","data":[{"symbol":"ETH/USD","bids":[{"price":3794.32,"qty":3.30000000}],"asks":[],"checksum":2673169087,"timestamp":"2024-06-01T17:52:31.680464Z"}]}
{"channel":"book","type":"update","data":[{"symbol":"ETH/USD","bids":[{"price":3794.52,"qty":0.82759107}],"asks":[],"checksum":2364530993,"timestamp":"2024-06-01T17:52:31.680954Z"}]}
{"channel":"book","type":"update","data":[{"symbol":"ETH/USD","bids":[],"asks":[{"price":3795.16,"qty":26.34937234}],"checksum":3701920646,"timestamp":"2024-06-01T17:52:31.711037Z"}]}
{"channel":"book","type":"update","data":[{"symbol":"ETH/USD","bids":[{"price":3794.48,"qty":26.35404812}],"asks":[],"checksum":310680664,"timestamp":"2024-06-01T17:52:31.711121Z"}]}
{"channel":"book","type":"update","data":[{"symbol":"ETH/USD","bids":[],"asks":[{"price":3795.60,"qty":0.00000000},{"price":3796.78,"qty":2.63600000}],"checksum":277135186,"timestamp":"2024-06-01T17:52:31.714245Z"}]}
{"channel":"book","type":"update","data":[{"symbol":"ETH/USD","bids":[],"asks":[{"price":3795.16,"qty":0.00000000},{"price":3796.79,"qty":5.36500000}],"checksum":2600949574,"timestamp":"2024-06-01T17:52:31.716347Z"}]}
{"channel":"book","type":"update","data":[{"symbol":"ETH/USD","bids":[{"price":3794.32,"qty":0.00000000},{"price":3793.76,"qty":3.95211095}],"asks":[],"checksum":3117137627,"timestamp":"2024-06-01T17:52:31.719187Z"}]}
{"channel":"book","type":"update","data":[{"symbol":"ETH/USD","bids":[{"price":3794.49,"qty":3.30000000}],"asks":[],"checksum":2631297269,"timestamp":"2024-06-01T17:52:31.720220Z"}]}
{"channel":"book","type":"update","data":[{"symbol":"ETH/USD","bids":[{"price":3794.49,"qty":0.00000000},{"price":3793.76,"qty":3.95211095}],"asks":[],"checksum":3117137627,"timestamp":"2024-06-01T17:52:31.728998Z"}]}
{"channel":"book","type":"update","data":[{"symbol":"ETH/USD","bids":[{"price":3794.54,"qty":3.30000000}],"asks":[],"checksum":3384616272,"timestamp":"2024-06-01T17:52:31.729289Z"}]}
{"channel":"book","type":"update","data":[{"symbol":"ETH/USD","bids":[],"asks":[{"price":3794.61,"qty":0.00000000},{"price":3796.86,"qty":4.00000000}],"checksum":3229531884,"timestamp":"2024-06-01T17:52:31.730147Z"}]}
{"channel":"book","type":"update","data":[{"symbol":"ETH/USD","bids":[],"asks":[{"price":3796.75,"qty":0.00000000},{"price":3796.95,"qty":0.41184735}],"checksum":3982028778,"timestamp":"2024-06-01T17:52:31.731694Z"}]}
{"channel":"book","type":"update","data":[{"symbol":"ETH/USD","bids":[{"price":3794.61,"qty":0.05269966}],"asks":[],"checksum":1967872621,"timestamp":"2024-06-01T17:52:31.733688Z"}]}
{"channel":"book","type":"update","data":[{"symbol":"ETH/USD","bids":[{"price":3794.98,"qty":3.00000000}],"asks":[],"checksum":3089386730,"timestamp":"2024-06-01T17:52:31.737526Z"}]}
{"channel":"book","type":"update","data":[{"symbol":"ETH/USD","bids":[{"price":3794.61,"qty":0.00000000},{"price":3793.85,"qty":5.08658474}],"asks":[],"checksum":1484521663,"timestamp":"2024-06-01T17:52:31.741165Z"}]}
{"channel":"book","type":"update","data":[{"symbol":"ETH/USD","bids":[],"asks":[{"price":3795.06,"qty":2.13800000}],"checksum":2722622900,"timestamp":"2024-06-01T17:52:31.741210Z"}]}
{"channel":"book","type":"update","data":[{"symbol":"ETH/USD","bids":[{"price":3794.53,"qty":3.00000000}],"asks":[],"checksum":2750424394,"timestamp":"2024-06-01T17:52:31.741518Z"}]}
{"channel":"book","type":"update","data":[{"symbol":"ETH/USD","bids":[{"price":3794.98,"qty":6.00000000}],"asks":[],"checksum":402281068,"timestamp":"2024-06-01T17:52:31.741532Z"}]}
{"channel":"book","type":"update","data":[{"symbol":"ETH/USD","bids":[{"price":3794.52,"qty":0.05759107}],"asks":[],"checksum":1100095360,"timestamp":"2024-06-01T17:52:31.744644Z"}]}
{"channel":"book","type":"update","data":[{"symbol":"ETH/USD","bids":[{"price":3794.60,"qty":0.00000000},{"price":3793.77,"qty":0.81537940}],"asks":[],"checksum":1941740381,"timestamp":"2024-06-01T17:52:31.745417Z"}]}
{"channel":"book","type":"update","data":[{"symbol":"ETH/USD","bids":[{"price":3794.85,"qty":0.77000000}],"asks":[],"checksum":1593140191,"timestamp":"2024-06-01T17:52:31.747959Z"}]}
{"channel":"book","type":"update","data":[{"symbol":"ETH/USD","bids":[],"asks":[{"price":3796.86,"qty":0.00000000},{"price":3796.95,"qty":0.41184735}],"checksum":3756292202,"timestamp":"2024-06-01T17:52:31.751984Z"}]}
{"channel":"book","type":"update","data":[{"symbol":"ETH/USD","bids":[],"asks":[{"price":3795.06,"qty":0.00000000},{"price":3796.99,"qty":0.32778701}],"checksum":950682852,"timestamp":"2024-06-01T17:52:31.752479Z"}]}
{"channel":"book","type":"update","data":[{"symbol":"ETH/USD","bids":[],"asks":[{"price":3795.37,"qty":0.00000000},{"price":3797.07,"qty":0.30203318}],"checksum":2853975834,"timestamp":"2024-06-01T17:52:31.753081Z"}]}
{"channel":"book","type":"update","data":[{"symbol":"ETH/USD","bids":[],"asks":[{"price":3795.25,"qty":26.34876931}],"checksum":938285795,"timestamp":"2024-06-01T17:52:31.761741Z"}]}
{"channel":"book","type":"update","data":[{"symbol":"ETH/USD","bids":[{"price":3794.58,"qty":26.35335404}],"asks":[],"checksum":2753609972,"timestamp":"2024-06-01T17:52:31.761756Z"}]}
{"channel":"book","type":"update","data":[{"symbol":"ETH/USD","bids":[],"asks":[{"price":3796.41,"qty":0.00000000},{"price":3797.07,"qty":0.30203318}],"checksum":417142101,"timestamp":"2024-06-01T17:52:31.765182Z"}]}
{"channel":"book","type":"update","data":[{"symbol":"ETH/USD","bids":[],"asks":[{"price":3796.64,"qty":0.00000000},{"price":3797.09,"qty":3.00000000}],"checksum":1991632901,"timestamp":"2024-06-01T17:52:31.765939Z"}]}
{"channel":"book","type":"update","data":[{"symbol":"ETH/USD","bids":[],"asks":[{"price":3795.55,"qty":26.34667926}],"checksum":777499001,"timestamp":"2024-06-01T17:52:31.767225Z"}]}
{"channel":"book","type":"update","data":[{"symbol":"ETH/USD","bids":[{"price":3794.18,"qty":26.35615192}],"asks":[],"checksum":1974494194,"timestamp":"2024-06-01T17:52:31.767282Z"}]}
{"channel":"book","type":"update","data":[{"symbol":"ETH/USD","bids":[{"price":3794.85,"qty":0.00000000},{"price":3794.14,"qty":3.00000000}],"asks":[],"checksum":3248226365,"timestamp":"2024-06-01T17:52:31.767742Z"}]}
{"channel":"book","type":"update","data":[{"symbol":"ETH/USD","bids":[{"price":3794.58,"qty":0.00000000},{"price":3793.85,"qty":5.08658474}],"asks":[],"checksum":1313339989,"timestamp":"2024-06-01T17:52:31.769422Z"}]}
{"channel":"book","type":"update","data":[{"symbol":"ETH/USD","bids":[{"price":3794.98,"qty":6.77000000}],"asks":[],"checksum":2375974000,"timestamp":"2024-06-01T17:52:31.770932Z"}]}
{"channel":"book","type":"update","data":[{"symbol":"ETH/USD","bids":[{"price":3795.06,"qty":3.00000000}],"asks":[],"checksum":3618098505,"timestamp":"2024-06-01T17:52:31.774808Z"}]}
{"channel":"book","type":"update","data":[{"symbol":"ETH/USD","bids":[{"price":3794.29,"qty":0.00000000},{"price":3793.85,"qty":5.08658474},{"price":3794.62,"qty":0.00937097}],"asks":[],"checksum":1388301108,"timestamp":"2024-06-01T17:52:31.781509Z"}]}
{"channel":"book","type":"update","data":[{"symbol":"ETH/USD","bids":[],"asks":[{"price":3796.78,"qty":0.00000000},{"price":3797.09,"qty":3.00000000}],"checksum":3975910947,"timestamp":"2024-06-01T17:52:31.782861Z"}]}
{"channel":"book","type":"update","data":[{"symbol":"ETH/USD","bids":[{"price":3794.18,"qty":0.00000000},{"price":3793.85,"qty":5.08658474}],"asks":[],"checksum":4172171660,"timestamp":"2024-06-01T17:52:31.783210Z"}]}
{"channel":"book","type":"update","data":[{"symbol":"ETH/USD","bids":[],"asks":[{"price":3795.25,"qty":0.00000000},{"price":3797.44,"qty":4.30610000}],"checksum":3053537083,"timestamp":"2024-06-01T17:52:31.783227Z"}]}
{"channel":"book","type":"update","data":[{"symbol":"ETH/USD","bids":[],"asks":[{"price":3795.55,"qty":0.00000000},{"price":3797.45,"qty":26.34783542}],"checksum":1134664360,"timestamp":"2024-06-01T17:52:31.783271Z"}]}
{"channel":"book","type":"update","data":[{"symbol":"ETH/USD","bids":[],"asks":[{"price":3797.09,"qty":5.63600000}],"checksum":269513435,"timestamp":"2024-06-01T17:52:31.788146Z"}]}
{"channel":"book","type":"update","data":[{"symbol":"ETH/USD","bids":[{"price":3794.56,"qty":3.28420830}],"asks":[],"checksum":3942320200,"timestamp":"2024-06-01T17:52:31.790940Z"}]}
{"channel":"book","type":"update","data":[{"symbol":"ETH/USD","bids":[],"asks":[{"price":3795.42,"qty":26.34757050}],"checksum":2191979297,"timestamp":"2024-06-01T17:52:31.791659Z"}]}
{"channel":"book","type":"update","data":[{"symbol":"ETH/USD","bids":[],"asks":[{"price":3796.98,"qty":26.33676463}],"checksum":2811527356,"timestamp":"2024-06-01T17:52:31.791876Z"}]}
{"channel":"book","type":"update","data":[{"symbol":"ETH/USD","bids":[],"asks":[{"price":3795.85,"qty":26.34462427}],"checksum":2936473426,"timestamp":"2024-06-01T17:52:31.791929Z"}]}
{"channel":"book","type":"update","data":[{"symbol":"ETH/USD","bids":[{"price":3794.65,"qty":1.00000000}],"asks":[],"checksum":972477284,"timestamp":"2024-06-01T17:52:31.795447Z"}]}
{"channel":"book","type":"update","data":[{"symbol":"ETH/USD","bids":[{"price":3794.63,"qty":3.95275665}],"asks":[],"checksum":2516780939,"timestamp":"2024-06-01T17:52:31.795962Z"}]}
{"channel":"book","type":"update","data":[{"symbol":"ETH/USD","bids":[],"asks":[{"price":3795.85,"qty":0.00000000},{"price":3797.09,"qty":5.63600000}],"checksum":2660270181,"timestamp":"2024-06-01T17:52:31.797138Z"}]}
{"channel":"book","type":"update","data":[{"symbol":"ETH/USD","bids":[{"price":3794.56,"qty":0.34420830}],"asks":[],"checksum":233635160,"timestamp":"2024-06-01T17:52:31.798972Z"}]}
{"channel":"book","type":"update","data":[{"symbol":"ETH/USD","bids":[{"price":3794.57,"qty":2.74000000}],"asks":[],"checksum":263810286,"timestamp":"2024-06-01T17:52:31.799323Z"}]}
{"channel":"book","type":"update","data":[{"symbol":"ETH/USD","bids":[{"price":3794.57,"qty":0.00000000},{"price":3794.48,"qty":26.35404812}],"asks":[],"checksum":233635160,"timestamp":"2024-06-01T17:52:31.833248Z"}]}
{"channel":"book","type":"update","data":[{"symbol":"ETH/USD","bids":[],"asks":[{"price":3795.45,"qty":26.34738999}],"checksum":4161945656,"timestamp":"2024-06-01T17:52:31.836792Z"}]}
{"channel":"book","type":"update","data":[{"symbol":"ETH/USD","bids":[{"price":3794.75,"qty":26.35217500}],"asks":[],"checksum":245669715,"timestamp":"2024-06-01T17:52:31.836833Z"}]}
{"channel":"book","type":"update","data":[{"symbol":"ETH/USD","bids":[{"price":3794.60,"qty":1.03350978}],"asks":[],"checksum":3155452820,"timestamp":"2024-06-01T17:52:31.837562Z"}]}
{"channel":"book","type":"update","data":[{"symbol":"ETH/USD","bids":[],"asks":[{"price":3795.42,"qty":0.00000000},{"price":3797.09,"qty":5.63600000}],"checksum":2313627387,"timestamp":"2024-06-01T17:52:31.840259Z"}]}
{"channel":"book","type":"update","data":[{"symbol":"ETH/USD","bids":[],"asks":[{"price":3796.34,"qty":0.72912968}],"checksum":1202491947,"timestamp":"2024-06-01T17:52:31.841085Z"}]}
{"channel":"book","type":"update","data":[{"symbol":"ETH/USD","bids":[],"asks":[{"price":3795.78,"qty":0.77000000}],"checksum":2438722045,"timestamp":"2024-06-01T17:52:31.842068Z"}]}
{"channel":"book","type":"update","data":[{"symbol":"ETH/USD","bids":[],"asks":[{"price":3795.45,"qty":0.00000000},{"price":3797.07,"qty":0.30203318}],"checksum":3082974154,"timestamp":"2024-06-01T17:52:31.843270Z"}]}
{"channel":"book","type":"update","data":[{"symbol":"ETH/USD","bids":[{"price":3794.75,"qty":0.00000000},{"price":3794.52,"qty":0.05759107}],"asks":[],"checksum":3841026534,"timestamp":"2024-06-01T17:52:31.843320Z"}]}
{"channel":"book","type":"update","data":[{"symbol":"ETH/USD","bids":[],"asks":[{"price":3796.19,"qty":0.06693358}],"checksum":2863827002,"timestamp":"2024-06-01T17:52:31.847796Z"}]}
{"channel":"book","type":"update","data":[{"symbol":"ETH/USD","bids":[],"asks":[{"price":3796.79,"qty":5.26500000}],"checksum":3443858508,"timestamp":"2024-06-01T17:52:31.871815Z"}]}
{"channel":"book","type":"update","data":[{"symbol":"ETH/USD","bids":[],"asks":[{"price":3795.78,"qty":0.00000000},{"price":3797.07,"qty":0.30203318},{"price":3795.90,"qty":0.77000000}],"checksum":601676727,"timestamp":"2024-06-01T17:52:31.886922Z"}]}
{"channel":"book","type":"update","data":[{"symbol":"ETH/USD","bids":[],"asks":[{"price":3795.07,"qty":0.00000000},{"price":3797.07,"qty":0.30203318}],"checksum":175749137,"timestamp":"2024-06-01T17:52:31.887696Z"}]}
{"channel":"book","type":"update","data":[{"symbol":"ETH/USD","bids":[{"price":3795.07,"qty":0.05269460}],"asks":[],"checksum":2015079460,"timestamp":"2024-06-01T17:52:31.891633Z"}]}
{"channel":"book","type":"update","data":[{"symbol":"ETH/USD","bids":[],"asks":[{"price":3796.18,"qty":0.81285127}],"checksum":2949184206,"timestamp":"2024-06-01T17:52:31.891800Z"}]}
{"channel":"book","type":"update","data":[{"symbol":"ETH/USD","bids":[{"price":3794.86,"qty":26.35138972}],"asks":[],"checksum":2577689925,"timestamp":"2024-06-01T17:52:31.892996Z"}]}
{"channel":"book","type":"update","data":[{"symbol":"ETH/USD","bids":[],"asks":[{"price":3795.89,"qty":26.34428289}],"checksum":3680553969,"timestamp":"2024-06-01T17:52:31.893028Z"}]}
{"channel":"book","type":"update","data":[{"symbol":"ETH/USD","bids":[],"asks":[{"price":3796.42,"qty":0.00000000},{"price":3796.99,"qty":0.32778701}],"checksum":4208365935,"timestamp":"2024-06-01T17:52:31.895108Z"}]}
{"channel":"book","type":"update","data":[{"symbol":"ETH/USD","bids":[{"price":3795.37,"qty":3.00000000}],"asks":[],"checksum":1297578622,"timestamp":"2024-06-01T17:52:31.895614Z"}]}
{"channel":"book","type":"update","data":[{"symbol":"ETH/USD","bids":[{"price":3795.07,"qty":0.00000000},{"price":3794.54,"qty":3.30000000}],"asks":[],"checksum":1609827457,"timestamp":"2024-06-01T17:52:31.899133Z"}]}
{"channel":"book","type":"update","data":[{"symbol":"ETH/USD","bids":[{"price":3795.37,"qty":6.00000000}],"asks":[],"checksum":3959321511,"timestamp":"2024-06-01T17:52:31.899324Z"}]}
{"channel":"book","type":"update","data":[{"symbol":"ETH/USD","bids":[{"price":3795.37,"qty":3.00000000}],"asks":[],"checksum":1609827457,"timestamp":"2024-06-01T17:52:31.899603Z"}]}
{"channel":"book","type":"update","data":[{"symbol":"ETH/USD","bids":[],"asks":[{"price":3796.65,"qty":3.00000000}],"checksum":1762657448,"timestamp":"2024-06-01T17:52:31.899760Z"}]}
{"channel":"book","type":"update","data":[{"symbol":"ETH/USD","bids":[{"price":3794.98,"qty":3.77000000}],"asks":[],"checksum":3368459389,"timestamp":"2024-06-01T17:52:31.899815Z"}]}
{"channel":"book","type":"update","data":[{"symbol":"ETH/USD","bids":[],"asks":[{"price":3795.89,"qty":0.00000000},{"price":3796.99,"qty":0.32778701}],"checksum":8224028,"timestamp":"2024-06-01T17:52:31.900335Z"}]}
{"channel":"book","type":"update","data":[{"symbol":"ETH/USD","bids":[{"price":3794.86,"qty":0.00000000},{"price":3794.53,"qty":3.00000000}],"asks":[],"checksum":2139691469,"timestamp":"2024-06-01T17:52:31.900412Z"}]}
{"channel":"book","type":"update","data":[{"symbol":"ETH/USD","bids":[{"price":3795.37,"qty":6.00000000}],"asks":[],"checksum":2118125617,"timestamp":"2024-06-01T17:52:31.903157Z"}]}
{"channel":"book","type":"update","data":[{"symbol":"ETH/USD","bids":[{"price":3795.06,"qty":0.00000000},{"price":3794.52,"qty":0.05759107}],"asks":[],"checksum":1239753185,"timestamp":"2024-06-01T17:52:31.903471Z"}]}
{"channel":"book","type":"update","data":[{"symbol":"ETH/USD","bids":[],"asks":[{"price":3795.89,"qty":2.13800000}],"checksum":4083792819,"timestamp":"2024-06-01T17:52:31.912557Z"}]}
{"channel":"book","type":"update","data":[{"symbol":"ETH/USD","bids":[{"price":3795.37,"qty":3.00000000}],"asks":[],"checksum":612018922,"timestamp":"2024-06-01T17:52:31.916553Z"}]}
{"channel":"book","type":"update","data":[{"symbol":"ETH/USD","bids":[],"asks":[{"price":3795.38,"qty":0.09000000}],"checksum":2203705261,"timestamp":"2024-06-01T17:52:31.917007Z"}]}
{"channel":"book","type":"update","data":[{"symbol":"ETH/USD","bids":[],"asks":[{"price":3795.89,"qty":0.00000000},{"price":3796.98,"qty":26.33676463}],"checksum":612656235,"timestamp":"2024-06-01T17:52:31.923367Z"}]}
{"channel":"book","type":"update","data":[{"symbol":"ETH/USD","bids":[{"price":3795.37,"qty":6.00000000}],"asks":[],"checksum":4086789426,"timestamp":"2024-06-01T17:52:31.925236Z"}]}
{"channel":"book","type":"update","data":[{"symbol":"ETH/USD","bids":[],"asks":[{"price":3795.88,"qty":1.00000000}],"checksum":2647795071,"timestamp":"2024-06-01T17:52:31.925903Z"}]}
{"channel":"book","type":"update","data":[{"symbol":"ETH/USD","bids":[{"price":3794.98,"qty":3.00000000}],"asks":[],"checksum":717618236,"timestamp":"2024-06-01T17:52:31.928993Z"}]}
{"channel":"book","type":"update","data":[{"symbol":"ETH/USD","bids":[{"price":3794.60,"qty":0.00000000},{"price":3794.48,"qty":26.35404812}],"asks":[],"checksum":1020247789,"timestamp":"2024-06-01T17:52:31.940974Z"}]}
{"channel":"book","type":"update","data":[{"symbol":"ETH/USD","bids":[{"price":3795.06,"qty":0.84197644}],"asks":[],"checksum":2459404352,"timestamp":"2024-06-01T17:52:31.941010Z"}]}
{"channel":"book","type":"update","data":[{"symbol":"ETH/USD","bids":[],"asks":[{"price":3796.19,"qty":0.00000000},{"price":3796.98,"qty":26.33676463}],"checksum":1567774395,"timestamp":"2024-06-01T17:52:31.941491Z"}]}
{"channel":"book","type":"update","data":[{"symbol":"ETH/USD","bids":[{"price":3794.93,"qty":26.35092078}],"asks":[],"checksum":4080677391,"timestamp":"2024-06-01T17:52:31.977447Z"}]}
{"channel":"book","type":"update","data":[{"symbol":"ETH/USD","bids":[],"asks":[{"price":3795.59,"qty":26.34638336}],"checksum":2045283748,"timestamp":"2024-06-01T17:52:31.977474Z"}]}
{"channel":"book","type":"update","data":[{"symbol":"ETH/USD","bids":[{"price":3794.56,"qty":0.00000000},{"price":3794.52,"qty":0.05759107}],"asks":[],"checksum":1549487516,"timestamp":"2024-06-01T17:52:31.981572Z"}]}
{"channel":"book","type":"update","data":[{"symbol":"ETH/USD","bids":[{"price":3794.65,"qty":0.00000000},{"price":3794.44,"qty":3.95275665}],"asks":[],"checksum":1329721489,"timestamp":"2024-06-01T17:52:31.982267Z"}]}
{"channel":"book","type":"update","data":[{"symbol":"ETH/USD","bids":[{"price":3795.06,"qty":1.84197644}],"asks":[],"checksum":2788238833,"timestamp":"2024-06-01T17:52:31.984099Z"}]}
{"channel":"book","type":"update","data":[{"symbol":"ETH/USD","bids":[],"asks":[{"price":3795.59,"qty":0.00000000},{"price":3796.98,"qty":26.33676463}],"checksum":753113690,"timestamp":"2024-06-01T17:52:31.999811Z"}]}
{"channel":"book","type":"update","data":[{"symbol":"ETH/USD","bids":[{"price":3794.93,"qty":0.00000000},{"price":3794.14,"qty":3.00000000}],"asks":[],"checksum":1276373844,"timestamp":"2024-06-01T17:52:31.999871Z"}]}
{"channel":"book","type":"update","data":[{"symbol":"ETH/USD","bids":[{"price":3794.81,"qty":5.27100000}],"asks":[],"checksum":4157668100,"timestamp":"2024-06-01T17:52:32.002996Z"}]}
{"channel":"book","type":"update","data":[{"symbol":"ETH/USD","bids":[],"asks":[{"price":3796.98,"qty":0.00000000},{"price":3796.99,"qty":0.32778701}],"checksum":3505867557,"timestamp":"2024-06-01T17:52:32.003072Z"}]}
{"channel":"book","type":"update","data":[{"symbol":"ETH/USD","bids":[{"price":3794.64,"qty":0.81017075}],"asks":[],"checksum":1471321620,"timestamp":"2024-06-01T17:52:32.003116Z"}]}
{"channel":"book","type":"update","data":[{"symbol":"ETH/USD","bids":[],"asks":[{"price":3795.66,"qty":26.34593515}],"checksum":299313424,"timestamp":"2024-06-01T17:52:32.007108Z"}]}
{"channel":"book","type":"update","data":[{"symbol":"ETH/USD","bids":[{"price":3795.37,"qty":3.00000000}],"asks":[],"checksum":3334748233,"timestamp":"2024-06-01T17:52:32.014364Z"}]}
{"channel":"book","type":"update","data":[{"symbol":"ETH/USD","bids":[],"asks":[{"price":3795.78,"qty":2.13800000}],"checksum":2527187114,"timestamp":"2024-06-01T17:52:32.021848Z"}]}
{"channel":"book","type":"update","data":[{"symbol":"ETH/USD","bids":[{"price":3794.55,"qty":3.94900000}],"asks":[],"checksum":1510686084,"timestamp":"2024-06-01T17:52:32.024782Z"}]}
{"channel":"book","type":"update","data":[{"symbol":"ETH/USD","bids":[],"asks":[{"price":3795.66,"qty":0.00000000},{"price":3796.95,"qty":0.41184735}],"checksum":3575213081,"timestamp":"2024-06-01T17:52:32.032978Z"}]}
{"channel":"book","type":"update","data":[{"symbol":"ETH/USD","bids":[{"price":3795.37,"qty":0.00000000},{"price":3794.52,"qty":0.05759107}],"asks":[],"checksum":327945664,"timestamp":"2024-06-01T17:52:32.034246Z"}]}
{"channel":"book","type":"update","data":[{"symbol":"ETH/USD","bids":[],"asks":[{"price":3796.53,"qty":0.06693358}],"checksum":2339559092,"timestamp":"2024-06-01T17:52:32.035902Z"}]}
{"channel":"book","type":"update","data":[{"symbol":"ETH/USD","bids":[{"price":3795.22,"qty":3.00000000}],"asks":[],"checksum":1826022392,"timestamp":"2024-06-01T17:52:32.037567Z"}]}
{"channel":"book","type":"update","data":[{"symbol":"ETH/USD","bids":[{"price":3795.07,"qty":0.05269465}],"asks":[],"checksum":3327142026,"timestamp":"2024-06-01T17:52:32.037920Z"}]}
{"channel":"book","type":"update","data":[{"symbol":"ETH/USD","bids":[{"price":3795.02,"qty":26.35025659}],"asks":[],"checksum":1945915171,"timestamp":"2024-06-01T17:52:32.039105Z"}]}
{"channel":"book","type":"update","data":[{"symbol":"ETH/USD","bids":[],"asks":[{"price":3795.70,"qty":26.34561174}],"checksum":1441231017,"timestamp":"2024-06-01T17:52:32.039122Z"}]}
{"channel":"book","type":"update","data":[{"symbol":"ETH/USD","bids":[{"price":3795.07,"qty":0.00000000},{"price":3794.54,"qty":3.30000000}],"asks":[],"checksum":3674793719,"timestamp":"2024-06-01T17:52:32.041203Z"}]}
{"channel":"book","type":"update","data":[{"symbol":"ETH/USD","bids":[{"price":3795.06,"qty":1.00000000}],"asks":[],"checksum":3676720869,"timestamp":"2024-06-01T17:52:32.045631Z"}]}
{"channel":"book","type":"update","data":[{"symbol":"ETH/USD","bids":[{"price":3795.02,"qty":0.00000000},{"price":3794.53,"qty":3.00000000}],"asks":[],"checksum":1328906489,"timestamp":"2024-06-01T17:52:32.052453Z"}]}
{"channel":"book","type":"update","data":[{"symbol":"ETH/USD","bids":[{"price":3795.06,"qty":0.00000000},{"price":3794.52,"qty":0.05759107}],"asks":[],"checksum":1694441888,"timestamp":"2024-06-01T17:52:32.086072Z"}]}
{"channel":"book","type":"update","data":[{"symbol":"ETH/USD","bids":[{"price":3794.77,"qty":3.40353522}],"asks":[],"checksum":48347572,"timestamp":"2024-06-01T17:52:32.099902Z"}]}
{"channel":"book","type":"update","data":[{"symbol":"ETH/USD","bids":[],"asks":[{"price":3796.18,"qty":0.00000000},{"price":3796.79,"qty":5.26500000}],"checksum":3496113388,"timestamp":"2024-06-01T17:52:32.110219Z"}]}
{"channel":"book","type":"update","data":[{"symbol":"ETH/USD","bids":[],"asks":[{"price":3795.70,"qty":0.00000000},{"price":3796.95,"qty":0.41184735}],"checksum":1605483575,"timestamp":"2024-06-01T17:52:32.138754Z"}]}
{"channel":"book","type":"update","data":[{"symbol":"ETH/USD","bids":[],"asks":[{"price":3795.60,"qty":26.34631258}],"checksum":1912324211,"timestamp":"2024-06-01T17:52:32.143124Z"}]}
{"channel":"book","type":"update","data":[{"symbol":"ETH/USD","bids":[],"asks":[{"price":3796.00,"qty":26.34356936}],"checksum":2800941599,"timestamp":"2024-06-01T17:52:32.143140Z"}]}
{"channel":"book","type":"update","data":[{"symbol":"ETH/USD","bids":[{"price":3795.04,"qty":26.35012813}],"asks":[],"checksum":3598256310,"timestamp":"2024-06-01T17:52:32.143358Z"}]}
{"channel":"book","type":"update","data":[{"symbol":"ETH/USD","bids":[{"price":3794.63,"qty":30.30578099}],"asks":[],"checksum":2373411309,"timestamp":"2024-06-01T17:52:32.143370Z"}]}
{"channel":"book","type":"update","data":[{"symbol":"ETH/USD","bids":[{"price":3795.04,"qty":0.00000000},{"price":3794.53,"qty":3.00000000}],"asks":[],"checksum":1926251242,"timestamp":"2024-06-01T17:52:32.149829Z"}]}
{"channel":"book","type":"update","data":[{"symbol":"ETH/USD","bids":[],"asks":[{"price":3795.60,"qty":0.00000000},{"price":3796.79,"qty":5.26500000}],"checksum":3427936030,"timestamp":"2024-06-01T17:52:32.160585Z"}]}
{"channel":"book","type":"update","data":[{"symbol":"ETH/USD","bids":[{"price":3794.62,"qty":0.00000000},{"price":3794.52,"qty":0.05759107},{"price":3795.23,"qty":0.00936947}],"asks":[],"checksum":2194977589,"timestamp":"2024-06-01T17:52:32.178304Z"}]}
{"channel":"book","type":"update","data":[{"symbol":"ETH/USD","bids":[{"price":3795.25,"qty":0.77000000}],"asks":[],"checksum":713504301,"timestamp":"2024-06-01T17:52:32.182735Z"}]}
{"channel":"book","type":"update","data":[{"symbol":"ETH/USD","bids":[{"price":3795.34,"qty":3.00000000}],"asks":[],"checksum":1389437340,"timestamp":"2024-06-01T17:52:32.186553Z"}]}
{"channel":"book","type":"update","data":[{"symbol":"ETH/USD","bids":[],"asks":[{"price":3795.58,"qty":26.34649429}],"checksum":1037359112,"timestamp":"2024-06-01T17:52:32.205352Z"}]}
{"channel":"book","type":"update","data":[{"symbol":"ETH/USD","bids":[{"price":3795.01,"qty":26.35033665}],"asks":[],"checksum":454819126,"timestamp":"2024-06-01T17:52:32.205510Z"}]}
{"channel":"book","type":"update","data":[{"symbol":"ETH/USD","bids":[{"price":3795.01,"qty":0.00000000},{"price":3794.55,"qty":3.94900000}],"asks":[],"checksum":1037359112,"timestamp":"2024-06-01T17:52:32.217037Z"}]}
{"channel":"book","type":"update","data":[{"symbol":"ETH/USD","bids":[],"asks":[{"price":3795.57,"qty":0.81285127}],"checksum":77667212,"timestamp":"2024-06-01T17:52:32.220185Z"}]}
{"channel":"book","type":"update","data":[{"symbol":"ETH/USD","bids":[],"asks":[{"price":3795.58,"qty":0.00000000},{"price":3796.65,"qty":3.00000000}],"checksum":566791511,"timestamp":"2024-06-01T17:52:32.285838Z"}]}
{"channel":"book","type":"update","data":[{"symbol":"ETH/USD","bids":[],"asks":[{"price":3795.60,"qty":26.34630985}],"checksum":1943269384,"timestamp":"2024-06-01T17:52:32.290519Z"}]}
{"channel":"book","type":"update","data":[{"symbol":"ETH/USD","bids":[{"price":3795.04,"qty":26.35011521}],"asks":[],"checksum":290281320,"timestamp":"2024-06-01T17:52:32.290567Z"}]}
{"channel":"book","type":"update","data":[{"symbol":"ETH/USD","bids":[],"asks":[{"price":3796.25,"qty":26.34179701}],"checksum":3894871008,"timestamp":"2024-06-01T17:52:32.295506Z"}]}
{"channel":"book","type":"update","data":[{"symbol":"ETH/USD","bids":[],"asks":[{"price":3795.90,"qty":0.00000000},{"price":3796.53,"qty":0.06693358}],"checksum":1873449847,"timestamp":"2024-06-01T17:52:32.316536Z"}]}
{"channel":"book","type":"update","data":[{"symbol":"ETH/USD","bids":[{"price":3795.04,"qty":0.00000000},{"price":3794.55,"qty":3.94900000}],"asks":[],"checksum":627790341,"timestamp":"2024-06-01T17:52:32.344567Z"}]}
{"channel":"book","type":"update","data":[{"symbol":"ETH/USD","bids":[],"asks":[{"price":3795.60,"qty":0.00000000},{"price":3796.65,"qty":3.00000000}],"checksum":1290188265,"timestamp":"2024-06-01T17:52:32.344599Z"}]}
{"channel":"book","type":"update","data":[{"symbol":"ETH/USD","bids":[{"price":3794.63,"qty":3.95275665}],"asks":[],"checksum":3281413810,"timestamp":"2024-06-01T17:52:32.348706Z"}]}
{"channel":"book","type":"update","data":[{"symbol":"ETH/USD","bids":[{"price":3794.99,"qty":3.95275665}],"asks":[],"checksum":2555387033,"timestamp":"2024-06-01T17:52:32.349161Z"}]}
{"channel":"book","type":"update","data":[{"symbol":"ETH/USD","bids":[{"price":3795.07,"qty":26.34997291}],"asks":[],"checksum":2593713678,"timestamp":"2024-06-01T17:52:32.353420Z"}]}
{"channel":"book","type":"update","data":[{"symbol":"ETH/USD","bids":[],"asks":[{"price":3795.62,"qty":26.34616757}],"checksum":1118551784,"timestamp":"2024-06-01T17:52:32.353460Z"}]}
{"channel":"book","type":"update","data":[{"symbol":"ETH/USD","bids":[],"asks":[{"price":3795.84,"qty":0.77000000}],"checksum":558467318,"timestamp":"2024-06-01T17:52:32.502471Z"}]}
{"channel":"book","type":"update","data":[{"symbol":"ETH/USD","bids":[],"asks":[{"price":3795.62,"qty":0.00000000},{"price":3796.53,"qty":0.06693358}],"checksum":1826633949,"timestamp":"2024-06-01T17:52:32.560887Z"}]}
{"channel":"book","type":"update","data":[{"symbol":"ETH/USD","bids":[{"price":3794.77,"qty":29.75557735}],"asks":[],"checksum":2233374921,"timestamp":"2024-06-01T17:52:32.565315Z"}]}
{"channel":"book","type":"update","data":[{"symbol":"ETH/USD","bids":[{"price":3794.95,"qty":26.35076001}],"asks":[],"checksum":238047302,"timestamp":"2024-06-01T17:52:32.565332Z"}]}
{"channel":"book","type":"update","data":[{"symbol":"ETH/USD","bids":[],"asks":[{"price":3795.61,"qty":26.34627033}],"checksum":3707686746,"timestamp":"2024-06-01T17:52:32.565360Z"}]}
{"channel":"book","type":"update","data":[{"symbol":"ETH/USD","bids":[{"price":3795.25,"qty":0.00000000},{"price":3794.64,"qty":0.81017075},{"price":3795.06,"qty":0.77000000}],"asks":[],"checksum":3738904895,"timestamp":"2024-06-01T17:52:32.580910Z"}]}
{"channel":"book","type":"update","data":[{"symbol":"ETH/USD","bids":[],"asks":[{"price":3795.84,"qty":0.00000000},{"price":3796.53,"qty":0.06693358}],"checksum":3697923273,"timestamp":"2024-06-01T17:52:32.584056Z"}]}
{"channel":"book","type":"update","data":[{"symbol":"ETH/USD","bids":[{"price":3795.07,"qty":0.00000000},{"price":3794.64,"qty":0.81017075}],"asks":[],"checksum":2546936960,"timestamp":"2024-06-01T17:52:32.594574Z"}]}
{"channel":"book","type":"update","data":[{"symbol":"ETH/USD","bids":[{"price":3795.23,"qty":0.00000000},{"price":3794.55,"qty":3.94900000},{"price":3795.35,"qty":0.00936917}],"asks":[],"checksum":4118474308,"timestamp":"2024-06-01T17:52:32.598326Z"}]}
{"channel":"book","type":"update","data":[{"symbol":"ETH/USD","bids":[{"price":3795.22,"qty":0.00000000},{"price":3794.55,"qty":3.94900000}],"asks":[],"checksum":3496734907,"timestamp":"2024-06-01T17:52:32.603108Z"}]}
{"channel":"book","type":"update","data":[{"symbol":"ETH/USD","bids":[{"price":3795.37,"qty":3.00000000}],"asks":[],"checksum":3330148557,"timestamp":"2024-06-01T17:52:32.607115Z"}]}
{"channel":"book","type":"update","data":[{"symbol":"ETH/USD","bids":[{"price":3795.37,"qty":0.00000000},{"price":3794.55,"qty":3.94900000}],"asks":[],"checksum":3496734907,"timestamp":"2024-06-01T17:52:32.610839Z"}]}
{"channel":"book","type":"update","data":[{"symbol":"ETH/USD","bids":[{"price":3795.37,"qty":3.00000000}],"asks":[],"checksum":3330148557,"timestamp":"2024-06-01T17:52:32.611249Z"}]}
{"channel":"book","type":"update","data":[{"symbol":"ETH/USD","bids":[{"price":3795.37,"qty":6.00000000}],"asks":[],"checksum":1920237547,"timestamp":"2024-06-01T17:52:32.613967Z"}]}
{"channel":"book","type":"update","data":[{"symbol":"ETH/USD","bids":[{"price":3795.37,"qty":3.00000000}],"asks":[],"checksum":3330148557,"timestamp":"2024-06-01T17:52:32.617981Z"}]}
{"channel":"book","type":"update","data":[{"symbol":"ETH/USD","bids":[],"asks":[{"price":3795.61,"qty":0.00000000},{"price":3796.65,"qty":3.00000000}],"checksum":3241047076,"timestamp":"2024-06-01T17:52:32.626019Z"}]}
{"channel":"book","type":"update","data":[{"symbol":"ETH/USD","bids":[{"price":3795.01,"qty":26.35035767}],"asks":[],"checksum":2539822572,"timestamp":"2024-06-01T17:52:32.630277Z"}]}
{"channel":"book","type":"update","data":[{"symbol":"ETH/USD","bids":[],"asks":[{"price":3795.57,"qty":27.15940352}],"checksum":955057973,"timestamp":"2024-06-01T17:52:32.630312Z"}]}
{"channel":"book","type":"update","data":[{"symbol":"ETH/USD","bids":[{"price":3795.37,"qty":0.00000000},{"price":3794.64,"qty":0.81017075}],"asks":[],"checksum":3399663803,"timestamp":"2024-06-01T17:52:32.633677Z"}]}
{"channel":"book","type":"update","data":[{"symbol":"ETH/USD","bids":[{"price":3795.34,"qty":0.00000000},{"price":3794.55,"qty":3.94900000}],"asks":[],"checksum":2716418628,"timestamp":"2024-06-01T17:52:32.657356Z"}]}
{"channel":"book","type":"update","data":[{"symbol":"ETH/USD","bids":[{"price":3795.35,"qty":0.00000000},{"price":3794.54,"qty":3.30000000},{"price":3795.07,"qty":0.00937058}],"asks":[],"checksum":1161960890,"timestamp":"2024-06-01T17:52:32.707505Z"}]}
{"channel":"book","type":"update","data":[{"symbol":"ETH/USD","bids":[{"price":3795.25,"qty":3.00000000}],"asks":[],"checksum":218283541,"timestamp":"2024-06-01T17:52:32.711445Z"}]}
{"channel":"book","type":"update","data":[{"symbol":"ETH/USD","bids":[],"asks":[{"price":3795.57,"qty":0.81285127}],"checksum":2290297788,"timestamp":"2024-06-01T17:52:32.715962Z"}]}
{"channel":"book","type":"update","data":[{"symbol":"ETH/USD","bids":[{"price":3795.01,"qty":0.00000000},{"price":3794.55,"qty":3.94900000}],"asks":[],"checksum":2699925033,"timestamp":"2024-06-01T17:52:32.715978Z"}]}
{"channel":"book","type":"update","data":[{"symbol":"ETH/USD","bids":[],"asks":[{"price":3795.59,"qty":26.34638626}],"checksum":1259754335,"timestamp":"2024-06-01T17:52:32.720587Z"}]}
{"channel":"book","type":"update","data":[{"symbol":"ETH/USD","bids":[{"price":3795.03,"qty":26.35019164}],"asks":[],"checksum":2518411187,"timestamp":"2024-06-01T17:52:32.720613Z"}]}
{"channel":"book","type":"update","data":[{"symbol":"ETH/USD","bids":[],"asks":[{"price":3796.14,"qty":3.00000000}],"checksum":3930638194,"timestamp":"2024-06-01T17:52:32.808249Z"}]}
{"channel":"book","type":"update","data":[{"symbol":"ETH/USD","bids":[{"price":3794.87,"qty":3.95191312}],"asks":[],"checksum":536351584,"timestamp":"2024-06-01T17:52:32.856804Z"}]}
{"channel":"book","type":"update","data":[{"symbol":"ETH/USD","bids":[],"asks":[{"price":3795.59,"qty":0.00000000},{"price":3796.53,"qty":0.06693358}],"checksum":1165942496,"timestamp":"2024-06-01T17:52:32.861194Z"}]}
{"channel":"book","type":"update","data":[{"symbol":"ETH/USD","bids":[],"asks":[{"price":3795.57,"qty":27.15937718}],"checksum":3160133683,"timestamp":"2024-06-01T17:52:32.866748Z"}]}
{"channel":"book","type":"update","data":[{"symbol":"ETH/USD","bids":[{"price":3795.03,"qty":0.00000000},{"price":3794.64,"qty":0.81017075}],"asks":[],"checksum":2778563406,"timestamp":"2024-06-01T17:52:32.903570Z"}]}
{"channel":"book","type":"update","data":[{"symbol":"ETH/USD","bids":[],"asks":[{"price":3796.00,"qty":0.00000000},{"price":3796.65,"qty":3.00000000}],"checksum":3578023464,"timestamp":"2024-06-01T17:52:32.903615Z"}]}
{"channel":"book","type":"update","data":[{"symbol":"ETH/USD","bids":[],"asks":[{"price":3795.57,"qty":0.81285127}],"checksum":1650086016,"timestamp":"2024-06-01T17:52:32.903626Z"}]}
{"channel":"book","type":"update","data":[{"symbol":"ETH/USD","bids":[{"price":3794.99,"qty":30.30324345}],"asks":[],"checksum":1867991817,"timestamp":"2024-06-01T17:52:32.908791Z"}]}
{"channel":"book","type":"update","data":[{"symbol":"ETH/USD","bids":[],"asks":[{"price":3795.85,"qty":26.34457831}],"checksum":848314787,"timestamp":"2024-06-01T17:52:32.908836Z"}]}
{"channel":"book","type":"update","data":[{"symbol":"ETH/USD","bids":[{"price":3794.99,"qty":3.95275665}],"asks":[],"checksum":3444308090,"timestamp":"2024-06-01T17:52:32.914290Z"}]}
{"channel":"book","type":"update","data":[{"symbol":"ETH/USD","bids":[],"asks":[{"price":3795.57,"qty":27.15937454}],"checksum":850934102,"timestamp":"2024-06-01T17:52:32.919141Z"}]}
{"channel":"book","type":"update","data":[{"symbol":"ETH/USD","bids":[],"asks":[{"price":3795.71,"qty":0.77000000}],"checksum":116401588,"timestamp":"2024-06-01T17:52:32.929177Z"}]}
{"channel":"book","type":"update","data":[{"symbol":"ETH/USD","bids":[{"price":3795.25,"qty":0.00000000},{"price":3794.55,"qty":3.94900000}],"asks":[],"checksum":1447600095,"timestamp":"2024-06-01T17:52:32.999182Z"}]}
{"channel":"book","type":"update","data":[{"symbol":"ETH/USD","bids":[{"price":3795.11,"qty":3.00000000}],"asks":[],"checksum":832294649,"timestamp":"2024-06-01T17:52:33.003198Z"}]}
{"channel":"book","type":"update","data":[{"symbol":"ETH/USD","bids":[{"price":3794.97,"qty":26.35062384}],"asks":[],"checksum":2834224294,"timestamp":"2024-06-01T17:52:33.005959Z"}]}
{"channel":"book","type":"update","data":[{"symbol":"ETH/USD","bids":[],"asks":[{"price":3795.53,"qty":26.34681838}],"checksum":378849885,"timestamp":"2024-06-01T17:52:33.006021Z"}]}
{"channel":"book","type":"update","data":[{"symbol":"ETH/USD","bids":[{"price":3795.07,"qty":0.00000000},{"price":3794.64,"qty":0.81017075},{"price":3795.12,"qty":0.00937045}],"asks":[],"checksum":1073486034,"timestamp":"2024-06-01T17:52:33.056294Z"}]}
{"channel":"book","type":"update","data":[{"symbol":"ETH/USD","bids":[{"price":3794.97,"qty":0.00000000},{"price":3794.64,"qty":0.81017075}],"asks":[],"checksum":2651547782,"timestamp":"2024-06-01T17:52:33.117691Z"}]}
{"channel":"book","type":"update","data":[{"symbol":"ETH/USD","bids":[{"price":3795.01,"qty":26.35034976}],"asks":[],"checksum":1800927408,"timestamp":"2024-06-01T17:52:33.122930Z"}]}
{"channel":"book","type":"update","data":[{"symbol":"ETH/USD","bids":[],"asks":[{"price":3796.14,"qty":0.00000000},{"price":3796.34,"qty":0.72912968}],"checksum":2111368872,"timestamp":"2024-06-01T17:52:33.170221Z"}]}
{"channel":"book","type":"update","data":[{"symbol":"ETH/USD","bids":[{"price":3795.01,"qty":0.00000000},{"price":3794.64,"qty":0.81017075}],"asks":[],"checksum":610116878,"timestamp":"2024-06-01T17:52:33.171376Z"}]}
{"channel":"book","type":"update","data":[{"symbol":"ETH/USD","bids":[],"asks":[{"price":3795.53,"qty":0.00000000},{"price":3796.53,"qty":0.06693358}],"checksum":3833186995,"timestamp":"2024-06-01T17:52:33.171506Z"}]}
{"channel":"book","type":"update","data":[{"symbol":"ETH/USD","bids":[{"price":3795.02,"qty":26.35026918}],"asks":[],"checksum":2814481592,"timestamp":"2024-06-01T17:52:33.176110Z"}]}
{"channel":"book","type":"update","data":[{"symbol":"ETH/USD","bids":[],"asks":[{"price":3795.67,"qty":26.34584449}],"checksum":443633605,"timestamp":"2024-06-01T17:52:33.176234Z"}]}
{"channel":"book","type":"update","data":[{"symbol":"ETH/USD","bids":[],"asks":[{"price":3796.14,"qty":3.00000000}],"checksum":12692952,"timestamp":"2024-06-01T17:52:33.191400Z"}]}
{"channel":"book","type":"update","data":[{"symbol":"ETH/USD","bids":[],"asks":[{"price":3795.67,"qty":0.00000000},{"price":3796.34,"qty":0.72912968}],"checksum":2203250755,"timestamp":"2024-06-01T17:52:33.192839Z"}]}
{"channel":"book","type":"update","data":[{"symbol":"ETH/USD","bids":[{"price":3795.02,"qty":0.00000000},{"price":3794.64,"qty":0.81017075}],"asks":[],"checksum":560305090,"timestamp":"2024-06-01T17:52:33.192862Z"}]}
{"channel":"book","type":"update","data":[{"symbol":"ETH/USD","bids":[],"asks":[{"price":3795.47,"qty":26.34725425}],"checksum":649217874,"timestamp":"2024-06-01T17:52:33.197585Z"}]}
{"channel":"book","type":"update","data":[{"symbol":"ETH/USD","bids":[],"asks":[{"price":3795.47,"qty":0.00000000},{"price":3796.34,"qty":0.72912968}],"checksum":560305090,"timestamp":"2024-06-01T17:52:33.248014Z"}]}
{"channel":"book","type":"update","data":[{"symbol":"ETH/USD","bids":[],"asks":[{"price":3796.25,"qty":0.00000000},{"price":3796.53,"qty":0.06693358}],"checksum":2440619669,"timestamp":"2024-06-01T17:52:33.248064Z"}]}
{"channel":"book","type":"update","data":[{"symbol":"ETH/USD","bids":[],"asks":[{"price":3795.44,"qty":26.34744925}],"checksum":2163134257,"timestamp":"2024-06-01T17:52:33.252796Z"}]}
{"channel":"book","type":"update","data":[{"symbol":"ETH/USD","bids":[],"asks":[{"price":3796.05,"qty":26.34320783}],"checksum":1848015983,"timestamp":"2024-06-01T17:52:33.252897Z"}]}
{"channel":"book","type":"update","data":[{"symbol":"ETH/USD","bids":[{"price":3795.02,"qty":26.35029627}],"asks":[],"checksum":3663096345,"timestamp":"2024-06-01T17:52:33.252939Z"}]}
{"channel":"book","type":"update","data":[{"symbol":"ETH/USD","bids":[],"asks":[{"price":3795.44,"qty":0.00000000},{"price":3796.34,"qty":0.72912968}],"checksum":2624590340,"timestamp":"2024-06-01T17:52:33.425325Z"}]}
{"channel":"book","type":"update","data":[{"symbol":"ETH/USD","bids":[{"price":3795.02,"qty":0.00000000},{"price":3794.72,"qty":1.16226117}],"asks":[],"checksum":4027007946,"timestamp":"2024-06-01T17:52:33.425337Z"}]}
{"channel":"book","type":"update","data":[{"symbol":"ETH/USD","bids":[],"asks":[{"price":3795.48,"qty":26.34719101}],"checksum":1338609531,"timestamp":"2024-06-01T17:52:33.430573Z"}]}
{"channel":"book","type":"update","data":[{"symbol":"ETH/USD","bids":[{"price":3795.06,"qty":27.12003800}],"asks":[],"checksum":270293664,"timestamp":"2024-06-01T17:52:33.430672Z"}]}
{"channel":"book","type":"update","data":[{"symbol":"ETH/USD","bids":[],"asks":[{"price":3795.48,"qty":0.00000000},{"price":3796.34,"qty":0.72912968}],"checksum":2131817484,"timestamp":"2024-06-01T17:52:33.448341Z"}]}
{"channel":"book","type":"update","data":[{"symbol":"ETH/USD","bids":[{"price":3795.06,"qty":0.77000000}],"asks":[],"checksum":4027007946,"timestamp":"2024-06-01T17:52:33.607329Z"}]}
{"channel":"book","type":"update","data":[{"symbol":"ETH/USD","bids":[{"price":3795.07,"qty":26.34992732}],"asks":[],"checksum":3843149017,"timestamp":"2024-06-01T17:52:33.612032Z"}]}
{"channel":"book","type":"update","data":[{"symbol":"ETH/USD","bids":[],"asks":[{"price":3795.49,"qty":26.34708035}],"checksum":3014202606,"timestamp":"2024-06-01T17:52:33.612071Z"}]}
{"channel":"book","type":"update","data":[{"symbol":"ETH/USD","bids":[],"asks":[{"price":3795.49,"qty":0.00000000},{"price":3796.34,"qty":0.72912968}],"checksum":3843149017,"timestamp":"2024-06-01T17:52:33.661388Z"}]}
{"channel":"book","type":"update","data":[{"symbol":"ETH/USD","bids":[],"asks":[{"price":3795.48,"qty":26.34717520}],"checksum":1911142854,"timestamp":"2024-06-01T17:52:33.667491Z"}]}
{"channel":"book","type":"update","data":[{"symbol":"ETH/USD","bids":[],"asks":[{"price":3795.48,"qty":0.00000000},{"price":3796.34,"qty":0.72912968}],"checksum":3843149017,"timestamp":"2024-06-01T17:52:33.739412Z"}]}
{"channel":"book","type":"update","data":[{"symbol":"ETH/USD","bids":[{"price":3795.07,"qty":0.00000000},{"price":3794.64,"qty":0.81017075}],"asks":[],"checksum":2008056268,"timestamp":"2024-06-01T17:52:33.739517Z"}]}
{"channel":"book","type":"update","data":[{"symbol":"ETH/USD","bids":[],"asks":[{"price":3795.46,"qty":26.34728587}],"checksum":3602384204,"timestamp":"2024-06-01T17:52:33.744230Z"}]}
{"channel":"book","type":"update","data":[{"symbol":"ETH/USD","bids":[{"price":3795.04,"qty":26.35013287}],"asks":[],"checksum":3613516912,"timestamp":"2024-06-01T17:52:33.744247Z"}]}
{"channel":"book","type":"update","data":[{"symbol":"ETH/USD","bids":[{"price":3795.04,"qty":0.00000000},{"price":3794.64,"qty":0.81017075}],"asks":[],"checksum":3602384204,"timestamp":"2024-06-01T17:52:33.948549Z"}]}
{"channel":"book","type":"update","data":[{"symbol":"ETH/USD","bids":[{"price":3795.05,"qty":26.35004854}],"asks":[],"checksum":3648705047,"timestamp":"2024-06-01T17:52:33.952782Z"}]}
{"channel":"book","type":"update","data":[{"symbol":"ETH/USD","bids":[],"asks":[{"price":3795.46,"qty":0.00000000},{"price":3796.34,"qty":0.72912968}],"checksum":137145453,"timestamp":"2024-06-01T17:52:34.175026Z"}]}
{"channel":"book","type":"update","data":[{"symbol":"ETH/USD","bids":[{"price":3795.05,"qty":0.00000000},{"price":3794.64,"qty":0.81017075}],"asks":[],"checksum":2008056268,"timestamp":"2024-06-01T17:52:34.175050Z"}]}
{"channel":"book","type":"update","data":[{"symbol":"ETH/USD","bids":[{"price":3795.06,"qty":27.11998141}],"asks":[],"checksum":2443419651,"timestamp":"2024-06-01T17:52:34.179651Z"}]}
{"channel":"book","type":"update","data":[{"symbol":"ETH/USD","bids":[],"asks":[{"price":3795.48,"qty":26.34713443}],"checksum":2223399596,"timestamp":"2024-06-01T17:52:34.179675Z"}]}
{"channel":"book","type":"update","data":[{"symbol":"ETH/USD","bids":[],"asks":[{"price":3795.85,"qty":0.00000000},{"price":3796.34,"qty":0.72912968}],"checksum":3237833627,"timestamp":"2024-06-01T17:52:34.240587Z"}]}
{"channel":"book","type":"update","data":[{"symbol":"ETH/USD","bids":[],"asks":[{"price":3795.40,"qty":26.34772604}],"checksum":1657591429,"timestamp":"2024-06-01T17:52:34.244958Z"}]}
{"channel":"book","type":"update","data":[{"symbol":"ETH/USD","bids":[],"asks":[{"price":3795.40,"qty":0.00000000},{"price":3796.34,"qty":0.72912968}],"checksum":3237833627,"timestamp":"2024-06-01T17:52:34.305868Z"}]}
{"channel":"book","type":"update","data":[{"symbol":"ETH/USD","bids":[],"asks":[{"price":3795.38,"qty":26.43788678}],"checksum":2536579029,"timestamp":"2024-06-01T17:52:34.310892Z"}]}
{"channel":"book","type":"update","data":[{"symbol":"ETH/USD","bids":[{"price":3795.11,"qty":0.00000000},{"price":3794.55,"qty":3.94900000}],"asks":[],"checksum":1101236254,"timestamp":"2024-06-01T17:52:34.373141Z"}]}
{"channel":"book","type":"update","data":[{"symbol":"ETH/USD","bids":[],"asks":[{"price":3795.38,"qty":0.09000000}],"checksum":376437840,"timestamp":"2024-06-01T17:52:34.376041Z"}]}
{"channel":"book","type":"update","data":[{"symbol":"ETH/USD","bids":[{"price":3795.06,"qty":0.77000000}],"asks":[],"checksum":1091534071,"timestamp":"2024-06-01T17:52:34.380300Z"}]}
{"channel":"book","type":"update","data":[{"symbol":"ETH/USD","bids":[],"asks":[{"price":3795.48,"qty":0.00000000},{"price":3796.53,"qty":0.06693358}],"checksum":259724209,"timestamp":"2024-06-01T17:52:34.384432Z"}]}
{"channel":"book","type":"update","data":[{"symbol":"ETH/USD","bids":[{"price":3794.95,"qty":0.00000000},{"price":3794.54,"qty":3.30000000}],"asks":[],"checksum":2171186780,"timestamp":"2024-06-01T17:52:34.387335Z"}]}
{"channel":"book","type":"update","data":[{"symbol":"ETH/USD","bids":[],"asks":[{"price":3796.05,"qty":0.00000000},{"price":3796.65,"qty":3.00000000}],"checksum":1977407714,"timestamp":"2024-06-01T17:52:34.387385Z"}]}
{"channel":"book","type":"update","data":[{"symbol":"ETH/USD","bids":[{"price":3794.81,"qty":0.00000000},{"price":3794.53,"qty":3.00000000},{"price":3794.78,"qty":5.27100000}],"asks":[],"checksum":2254295884,"timestamp":"2024-06-01T17:52:34.390467Z"}]}
{"channel":"book","type":"update","data":[{"symbol":"ETH/USD","bids":[{"price":3794.77,"qty":3.40353522}],"asks":[],"checksum":2314515542,"timestamp":"2024-06-01T17:52:34.390572Z"}]}
{"channel":"book","type":"update","data":[{"symbol":"ETH/USD","bids":[],"asks":[{"price":3795.25,"qty":26.34875819}],"checksum":3938776925,"timestamp":"2024-06-01T17:52:34.394713Z"}]}
{"channel":"book","type":"update","data":[{"symbol":"ETH/USD","bids":[{"price":3794.65,"qty":26.35286645}],"asks":[],"checksum":2603989790,"timestamp":"2024-06-01T17:52:34.394728Z"}]}
{"channel":"book","type":"update","data":[{"symbol":"ETH/USD","bids":[],"asks":[{"price":3795.85,"qty":26.34458647}],"checksum":442642835,"timestamp":"2024-06-01T17:52:34.394747Z"}]}
{"channel":"book","type":"update","data":[{"symbol":"ETH/USD","bids":[{"price":3794.94,"qty":26.35084085}],"asks":[],"checksum":1876723671,"timestamp":"2024-06-01T17:52:34.394866Z"}]}
{"channel":"book","type":"update","data":[{"symbol":"ETH/USD","bids":[{"price":3794.98,"qty":0.00000000},{"price":3794.55,"qty":3.94900000}],"asks":[],"checksum":1796418118,"timestamp":"2024-06-01T17:52:34.398023Z"}]}
{"channel":"book","type":"update","data":[{"symbol":"ETH/USD","bids":[],"asks":[{"price":3795.38,"qty":0.00000000},{"price":3796.53,"qty":0.06693358}],"checksum":3564703004,"timestamp":"2024-06-01T17:52:34.399081Z"}]}
{"channel":"book","type":"update","data":[{"symbol":"ETH/USD","bids":[{"price":3795.12,"qty":0.00000000},{"price":3794.54,"qty":3.30000000},{"price":3795.07,"qty":0.00937023}],"asks":[],"checksum":4294457348,"timestamp":"2024-06-01T17:52:34.426801Z"}]}
{"channel":"book","type":"update","data":[{"symbol":"ETH/USD","bids":[],"asks":[{"price":3795.25,"qty":0.00000000},{"price":3796.65,"qty":3.00000000}],"checksum":3396149915,"timestamp":"2024-06-01T17:52:34.426853Z"}]}
{"channel":"book","type":"update","data":[{"symbol":"ETH/USD","bids":[],"asks":[{"price":3795.57,"qty":0.81285127}],"checksum":2174042296,"timestamp":"2024-06-01T17:52:34.432164Z"}]}
{"channel":"book","type":"update","data":[{"symbol":"ETH/USD","bids":[],"asks":[{"price":3795.56,"qty":26.34657336}],"checksum":1945107405,"timestamp":"2024-06-01T17:52:34.436676Z"}]}
{"channel":"book","type":"update","data":[{"symbol":"ETH/USD","bids":[],"asks":[{"price":3795.56,"qty":52.69314672}],"checksum":886475703,"timestamp":"2024-06-01T17:52:34.436695Z"}]}
{"channel":"book","type":"update","data":[{"symbol":"ETH/USD","bids":[],"asks":[{"price":3795.55,"qty":2.00000000}],"checksum":1067003282,"timestamp":"2024-06-01T17:52:34.441023Z"}]}
{"channel":"book","type":"update","data":[{"symbol":"ETH/USD","bids":[],"asks":[{"price":3795.56,"qty":26.34657336}],"checksum":3560950053,"timestamp":"2024-06-01T17:52:34.441728Z"}]}
{"channel":"book","type":"update","data":[{"symbol":"ETH/USD","bids":[],"asks":[{"price":3795.56,"qty":0.00000000},{"price":3796.53,"qty":0.06693358}],"checksum":1206579238,"timestamp":"2024-06-01T17:52:34.445877Z"}]}
{"channel":"book","type":"update","data":[{"symbol":"ETH/USD","bids":[{"price":3795.13,"qty":0.32778701}],"asks":[],"checksum":93448452,"timestamp":"2024-06-01T17:52:34.448066Z"}]}
{"channel":"book","type":"update","data":[{"symbol":"ETH/USD","bids":[],"asks":[{"price":3795.24,"qty":26.34880036}],"checksum":2174894097,"timestamp":"2024-06-01T17:52:34.451345Z"}]}
{"channel":"book","type":"update","data":[{"symbol":"ETH/USD","bids":[{"price":3794.92,"qty":26.35095417}],"asks":[],"checksum":2030552262,"timestamp":"2024-06-01T17:52:34.451390Z"}]}
{"channel":"book","type":"update","data":[{"symbol":"ETH/USD","bids":[{"price":3794.94,"qty":0.00000000},{"price":3794.64,"qty":0.81017075}],"asks":[],"checksum":3231483407,"timestamp":"2024-06-01T17:52:34.478637Z"}]}
{"channel":"book","type":"update","data":[{"symbol":"ETH/USD","bids":[{"price":3794.92,"qty":0.00000000},{"price":3794.55,"qty":3.94900000}],"asks":[],"checksum":1791286161,"timestamp":"2024-06-01T17:52:34.478783Z"}]}
{"channel":"book","type":"update","data":[{"symbol":"ETH/USD","bids":[{"price":3794.79,"qty":26.35191480}],"asks":[],"checksum":1517397083,"timestamp":"2024-06-01T17:52:34.483271Z"}]}
{"channel":"book","type":"update","data":[{"symbol":"ETH/USD","bids":[{"price":3794.99,"qty":0.00000000},{"price":3794.55,"qty":3.94900000}],"asks":[],"checksum":4081454687,"timestamp":"2024-06-01T17:52:34.488294Z"}]}
{"channel":"book","type":"update","data":[{"symbol":"ETH/USD","bids":[],"asks":[{"price":3795.19,"qty":26.34919829}],"checksum":1382029115,"timestamp":"2024-06-01T17:52:34.506602Z"}]}
{"channel":"book","type":"update","data":[{"symbol":"ETH/USD","bids":[{"price":3794.87,"qty":30.30322180}],"asks":[],"checksum":4257870698,"timestamp":"2024-06-01T17:52:34.506675Z"}]}
{"channel":"book","type":"update","data":[{"symbol":"ETH/USD","bids":[{"price":3794.61,"qty":3.95191312}],"asks":[],"checksum":1729845224,"timestamp":"2024-06-01T17:52:34.510639Z"}]}
{"channel":"book","type":"update","data":[{"symbol":"ETH/USD","bids":[{"price":3795.06,"qty":0.00000000},{"price":3794.55,"qty":3.94900000},{"price":3794.95,"qty":0.77000000}],"asks":[],"checksum":2412064842,"timestamp":"2024-06-01T17:52:34.511559Z"}]}
{"channel":"book","type":"update","data":[{"symbol":"ETH/USD","bids":[{"price":3794.69,"qty":3.95191312}],"asks":[],"checksum":216357177,"timestamp":"2024-06-01T17:52:34.511615Z"}]}
{"channel":"book","type":"update","data":[{"symbol":"ETH/USD","bids":[],"asks":[{"price":3795.19,"qty":0.00000000},{"price":3796.34,"qty":0.72912968}],"checksum":1184619105,"timestamp":"2024-06-01T17:52:34.512720Z"}]}
{"channel":"book","type":"update","data":[{"symbol":"ETH/USD","bids":[{"price":3794.87,"qty":3.95191312}],"asks":[],"checksum":2349290217,"timestamp":"2024-06-01T17:52:34.512734Z"}]}
{"channel":"book","type":"update","data":[{"symbol":"ETH/USD","bids":[],"asks":[{"price":3795.71,"qty":0.00000000},{"price":3796.53,"qty":0.06693358},{"price":3795.59,"qty":0.77000000}],"checksum":699827708,"timestamp":"2024-06-01T17:52:34.514627Z"}]}
{"channel":"book","type":"update","data":[{"symbol":"ETH/USD","bids":[],"asks":[{"price":3795.23,"qty":26.34886423}],"checksum":3544837373,"timestamp":"2024-06-01T17:52:34.560613Z"}]}
{"channel":"book","type":"update","data":[{"symbol":"ETH/USD","bids":[{"price":3794.87,"qty":30.30326134}],"asks":[],"checksum":1329477815,"timestamp":"2024-06-01T17:52:34.561244Z"}]}
{"channel":"book","type":"update","data":[{"symbol":"ETH/USD","bids":[],"asks":[{"price":3795.23,"qty":0.00000000},{"price":3796.34,"qty":0.72912968}],"checksum":952366920,"timestamp":"2024-06-01T17:52:34.566042Z"}]}
{"channel":"book","type":"update","data":[{"symbol":"ETH/USD","bids":[{"price":3794.87,"qty":3.95191312}],"asks":[],"checksum":699827708,"timestamp":"2024-06-01T17:52:34.598413Z"}]}
{"channel":"book","type":"update","data":[{"symbol":"ETH/USD","bids":[{"price":3794.91,"qty":26.35102404}],"asks":[],"checksum":3278141759,"timestamp":"2024-06-01T17:52:34.682097Z"}]}
{"channel":"book","type":"update","data":[{"symbol":"ETH/USD","bids":[],"asks":[{"price":3795.57,"qty":0.00000000},{"price":3796.53,"qty":0.06693358}],"checksum":2419408772,"timestamp":"2024-06-01T17:52:34.682111Z"}]}
{"channel":"book","type":"update","data":[{"symbol":"ETH/USD","bids":[],"asks":[{"price":3795.22,"qty":26.34897956}],"checksum":451710658,"timestamp":"2024-06-01T17:52:34.682194Z"}]}
{"channel":"book","type":"update","data":[{"symbol":"ETH/USD","bids":[{"price":3794.91,"qty":0.00000000},{"price":3794.64,"qty":0.81017075}],"asks":[],"checksum":1517183620,"timestamp":"2024-06-01T17:52:34.720829Z"}]}
{"channel":"book","type":"update","data":[{"symbol":"ETH/USD","bids":[],"asks":[{"price":3795.23,"qty":0.79086016}],"checksum":2837439863,"timestamp":"2024-06-01T17:52:34.802429Z"}]}
{"channel":"book","type":"update","data":[{"symbol":"ETH/USD","bids":[],"asks":[{"price":3795.55,"qty":0.00000000},{"price":3796.34,"qty":0.72912968}],"checksum":492489235,"timestamp":"2024-06-01T17:52:34.816079Z"}]}
{"channel":"book","type":"update","data":[{"symbol":"ETH/USD","bids":[{"price":3795.07,"qty":0.00000000},{"price":3794.55,"qty":3.94900000},{"price":3795.14,"qty":0.00937006}],"asks":[],"checksum":3133262070,"timestamp":"2024-06-01T17:52:34.837990Z"}]}
{"channel":"book","type":"update","data":[{"symbol":"ETH/USD","bids":[{"price":3794.95,"qty":0.00000000},{"price":3794.55,"qty":3.94900000}],"asks":[],"checksum":24421046,"timestamp":"2024-06-01T17:52:34.865169Z"}]}
{"channel":"book","type":"update","data":[{"symbol":"ETH/USD","bids":[],"asks":[{"price":3795.22,"qty":0.00000000},{"price":3796.53,"qty":0.06693358}],"checksum":3683022486,"timestamp":"2024-06-01T17:52:34.873599Z"}]}
{"channel":"book","type":"update","data":[{"symbol":"ETH/USD","bids":[{"price":3794.65,"qty":0.00000000},{"price":3794.54,"qty":3.30000000}],"asks":[],"checksum":2248284599,"timestamp":"2024-06-01T17:52:34.874433Z"}]}
{"channel":"book","type":"update","data":[{"symbol":"ETH/USD","bids":[],"asks":[{"price":3795.20,"qty":26.34911842}],"checksum":3260346124,"timestamp":"2024-06-01T17:52:34.882935Z"}]}
{"channel":"book","type":"update","data":[{"symbol":"ETH/USD","bids":[],"asks":[{"price":3795.54,"qty":26.34671219}],"checksum":1647520447,"timestamp":"2024-06-01T17:52:34.882953Z"}]}
{"channel":"book","type":"update","data":[{"symbol":"ETH/USD","bids":[{"price":3794.87,"qty":30.30323440}],"asks":[],"checksum":55104445,"timestamp":"2024-06-01T17:52:34.882993Z"}]}
{"channel":"book","type":"update","data":[{"symbol":"ETH/USD","bids":[{"price":3794.57,"qty":26.35338564}],"asks":[],"checksum":2136441974,"timestamp":"2024-06-01T17:52:34.883042Z"}]}
{"channel":"book","type":"update","data":[{"symbol":"ETH/USD","bids":[{"price":3794.88,"qty":1.00000000}],"asks":[],"checksum":2888419698,"timestamp":"2024-06-01T17:52:34.884205Z"}]}
{"channel":"book","type":"update","data":[{"symbol":"ETH/USD","bids":[],"asks":[{"price":3795.20,"qty":0.00000000},{"price":3796.34,"qty":0.72912968}],"checksum":367622860,"timestamp":"2024-06-01T17:52:34.905497Z"}]}
{"channel":"book","type":"update","data":[{"symbol":"ETH/USD","bids":[{"price":3794.87,"qty":3.95191312}],"asks":[],"checksum":2854778385,"timestamp":"2024-06-01T17:52:34.907680Z"}]}
{"channel":"book","type":"update","data":[{"symbol":"ETH/USD","bids":[{"price":3794.78,"qty":0.00000000},{"price":3794.55,"qty":3.94900000},{"price":3794.80,"qty":5.27100000}],"asks":[],"checksum":3021481951,"timestamp":"2024-06-01T17:52:34.910698Z"}]}
{"channel":"book","type":"update","data":[{"symbol":"ETH/USD","bids":[],"asks":[{"price":3795.22,"qty":26.34898139}],"checksum":4227482518,"timestamp":"2024-06-01T17:52:35.016402Z"}]}
{"channel":"book","type":"update","data":[{"symbol":"ETH/USD","bids":[{"price":3794.90,"qty":26.35111307}],"asks":[],"checksum":2362279405,"timestamp":"2024-06-01T17:52:35.016507Z"}]}
{"channel":"book","type":"update","data":[{"symbol":"ETH/USD","bids":[],"asks":[{"price":3795.21,"qty":2.00000000}],"checksum":208342671,"timestamp":"2024-06-01T17:52:35.106366Z"}]}
{"channel":"book","type":"update","data":[{"symbol":"ETH/USD","bids":[{"price":3794.86,"qty":0.77000000}],"asks":[],"checksum":1761067541,"timestamp":"2024-06-01T17:52:35.115694Z"}]}
{"channel":"book","type":"update","data":[{"symbol":"ETH/USD","bids":[],"asks":[{"price":3795.23,"qty":0.00000000},{"price":3796.30,"qty":3.30000000}],"checksum":2086511157,"timestamp":"2024-06-01T17:52:35.170971Z"}]}
{"channel":"book","type":"update","data":[{"symbol":"ETH/USD","bids":[{"price":3795.15,"qty":0.34420830}],"asks":[],"checksum":1332552200,"timestamp":"2024-06-01T17:52:35.203319Z"}]}
{"channel":"book","type":"update","data":[{"symbol":"ETH/USD","bids":[{"price":3794.90,"qty":0.00000000},{"price":3794.69,"qty":3.95191312}],"asks":[],"checksum":1645531291,"timestamp":"2024-06-01T17:52:35.233745Z"}]}
{"channel":"book","type":"update","data":[{"symbol":"ETH/USD","bids":[{"price":3794.91,"qty":26.35104192}],"asks":[],"checksum":3438243731,"timestamp":"2024-06-01T17:52:35.237874Z"}]}
{"channel":"book","type":"update","data":[{"symbol":"ETH/USD","bids":[{"price":3795.14,"qty":0.00000000},{"price":3794.69,"qty":3.95191312},{"price":3795.16,"qty":0.00937000}],"asks":[],"checksum":644882572,"timestamp":"2024-06-01T17:52:35.281489Z"}]}
{"channel":"book","type":"update","data":[{"symbol":"ETH/USD","bids":[],"asks":[{"price":3795.20,"qty":0.79086016}],"checksum":1077478962,"timestamp":"2024-06-01T17:52:35.284757Z"}]}
{"channel":"book","type":"update","data":[{"symbol":"ETH/USD","bids":[],"asks":[{"price":3795.20,"qty":0.00000000},{"price":3796.30,"qty":3.30000000}],"checksum":644882572,"timestamp":"2024-06-01T17:52:35.321402Z"}]}
{"channel":"book","type":"update","data":[{"symbol":"ETH/USD","bids":[{"price":3794.91,"qty":0.00000000},{"price":3794.69,"qty":3.95191312}],"asks":[],"checksum":672986655,"timestamp":"2024-06-01T17:52:35.351146Z"}]}
{"channel":"book","type":"update","data":[{"symbol":"ETH/USD","bids":[{"price":3794.93,"qty":26.35094647}],"asks":[],"checksum":359101500,"timestamp":"2024-06-01T17:52:35.356243Z"}]}
{"channel":"book","type":"update","data":[{"symbol":"ETH/USD","bids":[{"price":3794.93,"qty":0.00000000},{"price":3794.69,"qty":3.95191312}],"asks":[],"checksum":672986655,"timestamp":"2024-06-01T17:52:35.405918Z"}]}
{"channel":"book","type":"update","data":[{"symbol":"ETH/USD","bids":[],"asks":[{"price":3795.22,"qty":0.00000000},{"price":3796.34,"qty":0.72912968}],"checksum":1877667031,"timestamp":"2024-06-01T17:52:35.405975Z"}]}
{"channel":"book","type":"update","data":[{"symbol":"ETH/USD","bids":[],"asks":[{"price":3795.53,"qty":0.81183460}],"checksum":2405694379,"timestamp":"2024-06-01T17:52:35.409392Z"}]}
{"channel":"book","type":"update","data":[{"symbol":"ETH/USD","bids":[{"price":3794.79,"qty":0.00000000},{"price":3794.64,"qty":0.81017075}],"asks":[],"checksum":2574328125,"timestamp":"2024-06-01T17:52:35.410744Z"}]}
{"channel":"book","type":"update","data":[{"symbol":"ETH/USD","bids":[],"asks":[{"price":3795.32,"qty":26.34824537}],"checksum":557784810,"timestamp":"2024-06-01T17:52:35.414904Z"}]}
{"channel":"book","type":"update","data":[{"symbol":"ETH/USD","bids":[{"price":3794.93,"qty":26.35092538}],"asks":[],"checksum":1522249834,"timestamp":"2024-06-01T17:52:35.414951Z"}]}
{"channel":"book","type":"update","data":[{"symbol":"ETH/USD","bids":[{"price":3794.93,"qty":0.00000000},{"price":3794.64,"qty":0.81017075}],"asks":[],"checksum":557784810,"timestamp":"2024-06-01T17:52:35.505990Z"}]}
{"channel":"book","type":"update","data":[{"symbol":"ETH/USD","bids":[],"asks":[{"price":3795.24,"qty":0.00000000},{"price":3796.30,"qty":3.30000000}],"checksum":3604005112,"timestamp":"2024-06-01T17:52:35.506131Z"}]}
{"channel":"book","type":"update","data":[{"symbol":"ETH/USD","bids":[],"asks":[{"price":3795.53,"qty":0.00000000},{"price":3796.34,"qty":0.72912968}],"checksum":2614677059,"timestamp":"2024-06-01T17:52:35.509461Z"}]}
{"channel":"book","type":"update","data":[{"symbol":"ETH/USD","bids":[],"asks":[{"price":3795.21,"qty":28.34905487}],"checksum":3881350255,"timestamp":"2024-06-01T17:52:35.511917Z"}]}
{"channel":"book","type":"update","data":[{"symbol":"ETH/USD","bids":[{"price":3794.90,"qty":26.35113862}],"asks":[],"checksum":3683553275,"timestamp":"2024-06-01T17:52:35.512101Z"}]}
{"channel":"book","type":"update","data":[{"symbol":"ETH/USD","bids":[{"price":3794.90,"qty":0.00000000},{"price":3794.64,"qty":0.81017075}],"asks":[],"checksum":3881350255,"timestamp":"2024-06-01T17:52:35.526944Z"}]}
{"channel":"book","type":"update","data":[{"symbol":"ETH/USD","bids":[],"asks":[{"price":3795.32,"qty":0.00000000},{"price":3796.53,"qty":0.06693358}],"checksum":1947475525,"timestamp":"2024-06-01T17:52:35.527034Z"}]}
{"channel":"book","type":"update","data":[{"symbol":"ETH/USD","bids":[],"asks":[{"price":3795.20,"qty":26.34907251}],"checksum":1872214804,"timestamp":"2024-06-01T17:52:35.700117Z"}]}
{"channel":"book","type":"update","data":[{"symbol":"ETH/USD","bids":[{"price":3794.88,"qty":27.35128381}],"asks":[],"checksum":286002302,"timestamp":"2024-06-01T17:52:35.700385Z"}]}
{"channel":"book","type":"update","data":[{"symbol":"ETH/USD","bids":[],"asks":[{"price":3795.53,"qty":0.81183460}],"checksum":1307733620,"timestamp":"2024-06-01T17:52:35.703581Z"}]}
{"channel":"book","type":"update","data":[{"symbol":"ETH/USD","bids":[],"asks":[{"price":3795.20,"qty":0.00000000},{"price":3796.34,"qty":0.72912968}],"checksum":2116695466,"timestamp":"2024-06-01T17:52:35.705754Z"}]}
{"channel":"book","type":"update","data":[{"symbol":"ETH/USD","bids":[],"asks":[{"price":3795.59,"qty":0.00000000},{"price":3796.53,"qty":0.06693358},{"price":3795.46,"qty":0.77000000}],"checksum":1257367668,"timestamp":"2024-06-01T17:52:35.746357Z"}]}
{"channel":"book","type":"update","data":[{"symbol":"ETH/USD","bids":[],"asks":[{"price":3795.20,"qty":26.34907251}],"checksum":879201425,"timestamp":"2024-06-01T17:52:35.788153Z"}]}
{"channel":"book","type":"update","data":[{"symbol":"ETH/USD","bids":[{"price":3794.85,"qty":26.35144234}],"asks":[],"checksum":4047407377,"timestamp":"2024-06-01T17:52:35.788195Z"}]}
{"channel":"book","type":"update","data":[{"symbol":"ETH/USD","bids":[],"asks":[{"price":3795.53,"qty":0.00000000},{"price":3796.34,"qty":0.72912968}],"checksum":3432645436,"timestamp":"2024-06-01T17:52:35.844847Z"}]}
{"channel":"book","type":"update","data":[{"symbol":"ETH/USD","bids":[],"asks":[{"price":3795.20,"qty":0.00000000},{"price":3796.53,"qty":0.06693358}],"checksum":524165801,"timestamp":"2024-06-01T17:52:35.851016Z"}]}
{"channel":"book","type":"update","data":[{"symbol":"ETH/USD","bids":[{"price":3794.88,"qty":1.00000000}],"asks":[],"checksum":825039755,"timestamp":"2024-06-01T17:52:35.851172Z"}]}
{"channel":"book","type":"update","data":[{"symbol":"ETH/USD","bids":[],"asks":[{"price":3795.24,"qty":26.34884986}],"checksum":1069114185,"timestamp":"2024-06-01T17:52:35.856110Z"}]}
{"channel":"book","type":"update","data":[{"symbol":"ETH/USD","bids":[{"price":3794.91,"qty":26.35102858}],"asks":[],"checksum":1379288828,"timestamp":"2024-06-01T17:52:35.856246Z"}]}
{"channel":"book","type":"update","data":[{"symbol":"ETH/USD","bids":[],"asks":[{"price":3795.21,"qty":2.00000000}],"checksum":1527376728,"timestamp":"2024-06-01T17:52:36.019368Z"}]}
{"channel":"book","type":"update","data":[{"symbol":"ETH/USD","bids":[{"price":3794.91,"qty":0.00000000},{"price":3794.69,"qty":3.95191312}],"asks":[],"checksum":3059280965,"timestamp":"2024-06-01T17:52:36.019388Z"}]}
{"channel":"book","type":"update","data":[{"symbol":"ETH/USD","bids":[],"asks":[{"price":3795.53,"qty":0.81183460}],"checksum":3393656352,"timestamp":"2024-06-01T17:52:36.022523Z"}]}
{"channel":"book","type":"update","data":[{"symbol":"ETH/USD","bids":[{"price":3794.77,"qty":29.75558314}],"asks":[],"checksum":1321386890,"timestamp":"2024-06-01T17:52:36.024027Z"}]}
{"channel":"book","type":"update","data":[{"symbol":"ETH/USD","bids":[],"asks":[{"price":3795.18,"qty":26.34924464}],"checksum":1526173512,"timestamp":"2024-06-01T17:52:36.024116Z"}]}
{"channel":"book","type":"update","data":[{"symbol":"ETH/USD","bids":[],"asks":[{"price":3795.46,"qty":0.00000000},{"price":3796.30,"qty":3.30000000}],"checksum":822924420,"timestamp":"2024-06-01T17:52:36.156907Z"}]}
{"channel":"book","type":"update","data":[{"symbol":"ETH/USD","bids":[{"price":3794.85,"qty":0.00000000},{"price":3794.64,"qty":0.81017075}],"asks":[],"checksum":824415004,"timestamp":"2024-06-01T17:52:36.170888Z"}]}
{"channel":"book","type":"update","data":[{"symbol":"ETH/USD","bids":[],"asks":[{"price":3795.18,"qty":0.00000000},{"price":3796.34,"qty":0.72912968}],"checksum":2069874979,"timestamp":"2024-06-01T17:52:36.171023Z"}]}
{"channel":"book","type":"update","data":[{"symbol":"ETH/USD","bids":[{"price":3794.80,"qty":0.00000000},{"price":3794.58,"qty":3.94900000},{"price":3794.78,"qty":5.27100000}],"asks":[],"checksum":208712319,"timestamp":"2024-06-01T17:52:36.174334Z"}]}
{"channel":"book","type":"update","data":[{"symbol":"ETH/USD","bids":[],"asks":[{"price":3795.21,"qty":28.34904699}],"checksum":3467648663,"timestamp":"2024-06-01T17:52:36.176106Z"}]}
{"channel":"book","type":"update","data":[{"symbol":"ETH/USD","bids":[{"price":3794.88,"qty":27.35127190}],"asks":[],"checksum":1574266848,"timestamp":"2024-06-01T17:52:36.176134Z"}]}
{"channel":"book","type":"update","data":[{"symbol":"ETH/USD","bids":[{"price":3794.88,"qty":1.00000000}],"asks":[],"checksum":3467648663,"timestamp":"2024-06-01T17:52:36.185643Z"}]}
{"channel":"book","type":"update","data":[{"symbol":"ETH/USD","bids":[],"asks":[{"price":3795.21,"qty":2.00000000}],"checksum":208712319,"timestamp":"2024-06-01T17:52:36.185666Z"}]}
{"channel":"book","type":"update","data":[{"symbol":"ETH/USD","bids":[{"price":3794.77,"qty":3.40353522}],"asks":[],"checksum":2802233818,"timestamp":"2024-06-01T17:52:36.270332Z"}]}
{"channel":"book","type":"update","data":[{"symbol":"ETH/USD","bids":[],"asks":[{"price":3795.24,"qty":0.00000000},{"price":3796.53,"qty":0.06693358}],"checksum":539326607,"timestamp":"2024-06-01T17:52:36.272035Z"}]}
{"channel":"book","type":"update","data":[{"symbol":"ETH/USD","bids":[],"asks":[{"price":3795.21,"qty":28.34904436}],"checksum":3290556645,"timestamp":"2024-06-01T17:52:36.276219Z"}]}
{"channel":"book","type":"update","data":[{"symbol":"ETH/USD","bids":[{"price":3794.91,"qty":26.35105842}],"asks":[],"checksum":3453500490,"timestamp":"2024-06-01T17:52:36.276345Z"}]}
{"channel":"book","type":"update","data":[{"symbol":"ETH/USD","bids":[],"asks":[{"price":3795.32,"qty":26.34825525}],"checksum":3209672161,"timestamp":"2024-06-01T17:52:36.276464Z"}]}
{"channel":"book","type":"update","data":[{"symbol":"ETH/USD","bids":[{"price":3794.91,"qty":0.00000000},{"price":3794.64,"qty":0.81017075}],"asks":[],"checksum":2501033962,"timestamp":"2024-06-01T17:52:36.283547Z"}]}
{"channel":"book","type":"update","data":[{"symbol":"ETH/USD","bids":[],"asks":[{"price":3795.21,"qty":2.00000000}],"checksum":2793324539,"timestamp":"2024-06-01T17:52:36.283675Z"}]}
{"channel":"book","type":"update","data":[{"symbol":"ETH/USD","bids":[],"asks":[{"price":3795.46,"qty":0.77000000}],"checksum":353577775,"timestamp":"2024-06-01T17:52:36.285795Z"}]}
{"channel":"book","type":"update","data":[{"symbol":"ETH/USD","bids":[],"asks":[{"price":3795.32,"qty":0.00000000},{"price":3796.34,"qty":0.72912968}],"checksum":1114090513,"timestamp":"2024-06-01T17:52:36.286792Z"}]}
{"channel":"book","type":"update","data":[{"symbol":"ETH/USD","bids":[{"price":3794.77,"qty":29.75553043}],"asks":[],"checksum":2123633284,"timestamp":"2024-06-01T17:52:36.290556Z"}]}
{"channel":"book","type":"update","data":[{"symbol":"ETH/USD","bids":[],"asks":[{"price":3795.54,"qty":0.00000000},{"price":3796.53,"qty":0.06693358}],"checksum":4052869018,"timestamp":"2024-06-01T17:52:36.331404Z"}]}
{"channel":"book","type":"update","data":[{"symbol":"ETH/USD","bids":[],"asks":[{"price":3795.18,"qty":26.34927363}],"checksum":1093957237,"timestamp":"2024-06-01T17:52:36.338352Z"}]}
{"channel":"book","type":"update","data":[{"symbol":"ETH/USD","bids":[{"price":3794.82,"qty":26.35169730}],"asks":[],"checksum":3876759627,"timestamp":"2024-06-01T17:52:36.338580Z"}]}
{"channel":"book","type":"update","data":[{"symbol":"ETH/USD","bids":[],"asks":[{"price":3795.41,"qty":26.34763132}],"checksum":1931784879,"timestamp":"2024-06-01T17:52:36.338593Z"}]}
{"channel":"book","type":"update","data":[{"symbol":"ETH/USD","bids":[],"asks":[{"price":3795.18,"qty":0.00000000},{"price":3796.34,"qty":0.72912968}],"checksum":1817098329,"timestamp":"2024-06-01T17:52:36.357397Z"}]}
{"channel":"book","type":"update","data":[{"symbol":"ETH/USD","bids":[{"price":3794.82,"qty":0.00000000},{"price":3794.64,"qty":0.81017075}],"asks":[],"checksum":1370896572,"timestamp":"2024-06-01T17:52:36.357450Z"}]}
{"channel":"book","type":"update","data":[{"symbol":"ETH/USD","bids":[],"asks":[{"price":3795.85,"qty":0.00000000},{"price":3796.53,"qty":0.06693358}],"checksum":1103636760,"timestamp":"2024-06-01T17:52:36.357458Z"}]}
{"channel":"book","type":"update","data":[{"symbol":"ETH/USD","bids":[{"price":3794.77,"qty":3.40353522}],"asks":[],"checksum":2874863031,"timestamp":"2024-06-01T17:52:36.357466Z"}]}
{"channel":"book","type":"update","data":[{"symbol":"ETH/USD","bids":[],"asks":[{"price":3795.64,"qty":26.34603525}],"checksum":133012568,"timestamp":"2024-06-01T17:52:36.362966Z"}]}
{"channel":"book","type":"update","data":[{"symbol":"ETH/USD","bids":[{"price":3794.75,"qty":26.35218133}],"asks":[],"checksum":871818038,"timestamp":"2024-06-01T17:52:36.417632Z"}]}
{"channel":"book","type":"update","data":[{"symbol":"ETH/USD","bids":[{"price":3794.75,"qty":0.00000000},{"price":3794.64,"qty":0.81017075}],"asks":[],"checksum":133012568,"timestamp":"2024-06-01T17:52:36.435231Z"}]}
{"channel":"book","type":"update","data":[{"symbol":"ETH/USD","bids":[],"asks":[{"price":3795.17,"qty":26.34928079}],"checksum":3710580720,"timestamp":"2024-06-01T17:52:36.485721Z"}]}
{"channel":"book","type":"update","data":[{"symbol":"ETH/USD","bids":[{"price":3794.72,"qty":26.35234828}],"asks":[],"checksum":1492275742,"timestamp":"2024-06-01T17:52:36.485882Z"}]}
{"channel":"book","type":"update","data":[{"symbol":"ETH/USD","bids":[{"price":3794.71,"qty":26.35241468}],"asks":[],"checksum":1239616676,"timestamp":"2024-06-01T17:52:36.549300Z"}]}
{"channel":"book","type":"update","data":[{"symbol":"ETH/USD","bids":[{"price":3794.72,"qty":0.00000000},{"price":3794.69,"qty":3.95191312}],"asks":[],"checksum":446351882,"timestamp":"2024-06-01T17:52:36.562249Z"}]}
{"channel":"book","type":"update","data":[{"symbol":"ETH/USD","bids":[{"price":3795.13,"qty":0.00000000},{"price":3794.64,"qty":0.81017075}],"asks":[],"checksum":1850470651,"timestamp":"2024-06-01T17:52:36.604752Z"}]}
{"channel":"book","type":"update","data":[{"symbol":"ETH/USD","bids":[{"price":3794.73,"qty":26.35228788}],"asks":[],"checksum":2237623046,"timestamp":"2024-06-01T17:52:36.609361Z"}]}
{"channel":"book","type":"update","data":[{"symbol":"ETH/USD","bids":[{"price":3794.73,"qty":0.00000000},{"price":3794.64,"qty":0.81017075}],"asks":[],"checksum":1850470651,"timestamp":"2024-06-01T17:52:36.614406Z"}]}
{"channel":"book","type":"update","data":[{"symbol":"ETH/USD","bids":[],"asks":[{"price":3795.17,"qty":0.00000000},{"price":3796.34,"qty":0.72912968}],"checksum":3539313677,"timestamp":"2024-06-01T17:52:36.647564Z"}]}
{"channel":"book","type":"update","data":[{"symbol":"ETH/USD","bids":[{"price":3794.71,"qty":0.00000000},{"price":3794.55,"qty":3.94900000}],"asks":[],"checksum":3372407392,"timestamp":"2024-06-01T17:52:36.647744Z"}]}
{"channel":"book","type":"update","data":[{"symbol":"ETH/USD","bids":[],"asks":[{"price":3795.64,"qty":0.00000000},{"price":3796.53,"qty":0.06693358}],"checksum":4179333880,"timestamp":"2024-06-01T17:52:36.650533Z"}]}
{"channel":"book","type":"update","data":[{"symbol":"ETH/USD","bids":[],"asks":[{"price":3795.23,"qty":26.34889846}],"checksum":2177104953,"timestamp":"2024-06-01T17:52:36.654164Z"}]}
{"channel":"book","type":"update","data":[{"symbol":"ETH/USD","bids":[],"asks":[{"price":3795.23,"qty":0.00000000},{"price":3796.53,"qty":0.06693358}],"checksum":4179333880,"timestamp":"2024-06-01T17:52:36.676311Z"}]}
{"channel":"book","type":"update","data":[{"symbol":"ETH/USD","bids":[{"price":3794.56,"qty":26.35345192}],"asks":[],"checksum":1501334288,"timestamp":"2024-06-01T17:52:36.685516Z"}]}
{"channel":"book","type":"update","data":[{"symbol":"ETH/USD","bids":[{"price":3794.86,"qty":27.12138615}],"asks":[],"checksum":2387368231,"timestamp":"2024-06-01T17:52:36.685680Z"}]}
{"channel":"book","type":"update","data":[{"symbol":"ETH/USD","bids":[{"price":3794.86,"qty":0.77000000}],"asks":[],"checksum":1501334288,"timestamp":"2024-06-01T17:52:36.707450Z"}]}
{"channel":"book","type":"update","data":[{"symbol":"ETH/USD","bids":[],"asks":[{"price":3795.17,"qty":26.34928079}],"checksum":2977277509,"timestamp":"2024-06-01T17:52:36.712242Z"}]}
{"channel":"book","type":"update","data":[{"symbol":"ETH/USD","bids":[],"asks":[{"price":3795.17,"qty":0.00000000},{"price":3796.53,"qty":0.06693358}],"checksum":1501334288,"timestamp":"2024-06-01T17:52:36.751723Z"}]}
{"channel":"book","type":"update","data":[{"symbol":"ETH/USD","bids":[{"price":3794.84,"qty":26.35153950}],"asks":[],"checksum":768062360,"timestamp":"2024-06-01T17:52:36.756545Z"}]}
{"channel":"book","type":"update","data":[{"symbol":"ETH/USD","bids":[{"price":3794.84,"qty":0.00000000},{"price":3794.56,"qty":26.35345192}],"asks":[],"checksum":1501334288,"timestamp":"2024-06-01T17:52:36.762710Z"}]}
{"channel":"book","type":"update","data":[{"symbol":"ETH/USD","bids":[],"asks":[{"price":3795.17,"qty":26.34928079}],"checksum":2977277509,"timestamp":"2024-06-01T17:52:36.767082Z"}]}
{"channel":"book","type":"update","data":[{"symbol":"ETH/USD","bids":[{"price":3794.86,"qty":0.00000000},{"price":3794.55,"qty":3.94900000}],"asks":[],"checksum":1673486635,"timestamp":"2024-06-01T17:52:36.808880Z"}]}
{"channel":"book","type":"update","data":[{"symbol":"ETH/USD","bids":[{"price":3794.68,"qty":26.35265817}],"asks":[],"checksum":2437356297,"timestamp":"2024-06-01T17:52:36.831897Z"}]}
{"channel":"book","type":"update","data":[{"symbol":"ETH/USD","bids":[],"asks":[{"price":3795.24,"qty":26.34886420}],"checksum":2067288784,"timestamp":"2024-06-01T17:52:36.831956Z"}]}
{"channel":"book","type":"update","data":[{"symbol":"ETH/USD","bids":[{"price":3794.78,"qty":31.62296647}],"asks":[],"checksum":1018571297,"timestamp":"2024-06-01T17:52:36.832120Z"}]}
{"channel":"book","type":"update","data":[{"symbol":"ETH/USD","bids":[{"price":3794.78,"qty":26.35196647}],"asks":[],"checksum":3998687498,"timestamp":"2024-06-01T17:52:36.840777Z"}]}
{"channel":"book","type":"update","data":[{"symbol":"ETH/USD","bids":[{"price":3794.62,"qty":5.27100000}],"asks":[],"checksum":3877123026,"timestamp":"2024-06-01T17:52:36.845920Z"}]}
{"channel":"book","type":"update","data":[{"symbol":"ETH/USD","bids":[],"asks":[{"price":3795.24,"qty":0.00000000},{"price":3796.34,"qty":0.72912968}],"checksum":224885259,"timestamp":"2024-06-01T17:52:36.846104Z"}]}
{"channel":"book","type":"update","data":[{"symbol":"ETH/USD","bids":[{"price":3794.78,"qty":0.00000000},{"price":3794.56,"qty":26.35345192}],"asks":[],"checksum":792100310,"timestamp":"2024-06-01T17:52:36.846313Z"}]}
{"channel":"book","type":"update","data":[{"symbol":"ETH/USD","bids":[{"price":3794.68,"qty":0.00000000},{"price":3794.55,"qty":3.94900000}],"asks":[],"checksum":4130138840,"timestamp":"2024-06-01T17:52:36.848633Z"}]}
{"channel":"book","type":"update","data":[{"symbol":"ETH/USD","bids":[],"asks":[{"price":3795.41,"qty":0.00000000},{"price":3796.53,"qty":0.06693358}],"checksum":1109737969,"timestamp":"2024-06-01T17:52:36.851504Z"}]}
{"channel":"book","type":"update","data":[{"symbol":"ETH/USD","bids":[],"asks":[{"price":3795.17,"qty":52.69856158}],"checksum":606353297,"timestamp":"2024-06-01T17:52:36.856373Z"}]}
{"channel":"book","type":"update","data":[{"symbol":"ETH/USD","bids":[],"asks":[{"price":3795.27,"qty":26.34858967}],"checksum":1911267453,"timestamp":"2024-06-01T17:52:36.856554Z"}]}
{"channel":"book","type":"update","data":[{"symbol":"ETH/USD","bids":[{"price":3794.64,"qty":0.00000000},{"price":3794.54,"qty":3.30000000}],"asks":[],"checksum":2822036851,"timestamp":"2024-06-01T17:52:36.860106Z"}]}
{"channel":"book","type":"update","data":[{"symbol":"ETH/USD","bids":[{"price":3794.77,"qty":0.00000000},{"price":3794.53,"qty":3.00000000}],"asks":[],"checksum":3295564183,"timestamp":"2024-06-01T17:52:36.864013Z"}]}
