{"channel":"book","type":"update","data":[{"symbol":"ETH/USDT","bids":[{"price":3799.11,"qty":0.00000000},{"price":3798.55,"qty":0.31046272}],"asks":[],"checksum":1474174444,"timestamp":"2024-06-01T17:52:49.107217Z"}]}
{"channel":"book","type":"update","data":[{"symbol":"ETH/USDT","bids":[],"asks":[{"price":3799.88,"qty":0.00000000},{"price":3800.65,"qty":0.73120000}],"checksum":367221785,"timestamp":"2024-06-01T17:52:49.109579Z"}]}
{"channel":"book","type":"update","data":[{"symbol":"ETH/USDT","bids":[],"asks":[{"price":3799.85,"qty":1.46240000}],"checksum":1018476404,"timestamp":"2024-06-01T17:52:49.109979Z"}]}
{"channel":"book","type":"update","data":[{"symbol":"ETH/USDT","bids":[],"asks":[{"price":3799.85,"qty":0.73120000}],"checksum":367221785,"timestamp":"2024-06-01T17:52:49.110022Z"}]}
{"channel":"book","type":"update","data":[{"symbol":"ETH/USDT","bids":[],"asks":[{"price":3799.84,"qty":0.72912968}],"checksum":3178944990,"timestamp":"2024-06-01T17:52:49.110447Z"}]}
{"channel":"book","type":"update","data":[{"symbol":"ETH/USDT","bids":[{"price":3798.79,"qty":0.00000000},{"price":3798.46,"qty":8.85019210}],"asks":[],"checksum":712315469,"timestamp":"2024-06-01T17:52:49.110559Z"}]}
{"channel":"book","type":"update","data":[{"symbol":"ETH/USDT","bids":[{"price":3799.13,"qty":0.25000000}],"asks":[],"checksum":3779390770,"timestamp":"2024-06-01T17:52:49.110955Z"}]}
{"channel":"book","type":"update","data":[{"symbol":"ETH/USDT","bids":[],"asks":[{"price":3799.85,"qty":1.46240000}],"checksum":2941679026,"timestamp":"2024-06-01T17:52:49.112998Z"}]}
{"channel":"book","type":"update","data":[{"symbol":"ETH/USDT","bids":[],"asks":[{"price":3799.85,"qty":0.73120000}],"checksum":3779390770,"timestamp":"2024-06-01T17:52:49.116263Z"}]}
{"channel":"book","type":"update","data":[{"symbol":"ETH/USDT","bids":[{"price":3799.10,"qty":0.45000000}],"asks":[],"checksum":2188049568,"timestamp":"2024-06-01T17:52:49.116613Z"}]}
{"channel":"book","type":"update","data":[{"symbol":"ETH/USDT","bids":[{"price":3799.12,"qty":1.46690885}],"asks":[],"checksum":1829305171,"timestamp":"2024-06-01T17:52:49.117541Z"}]}
{"channel":"book","type":"update","data":[{"symbol":"ETH/USDT","bids":[],"asks":[{"price":3799.85,"qty":0.00000000},{"price":3800.65,"qty":0.73120000}],"checksum":838856108,"timestamp":"2024-06-01T17:52:49.118220Z"}]}
{"channel":"book","type":"update","data":[{"symbol":"ETH/USDT","bids":[],"asks":[{"price":3799.84,"qty":1.46032968}],"checksum":4291848830,"timestamp":"2024-06-01T17:52:49.122138Z"}]}
{"channel":"book","type":"update","data":[{"symbol":"ETH/USDT","bids":[{"price":3799.12,"qty":1.31690885}],"asks":[],"checksum":280128909,"timestamp":"2024-06-01T17:52:49.147445Z"}]}
{"channel":"book","type":"update","data":[{"symbol":"ETH/USDT","bids":[{"price":3799.10,"qty":0.00000000},{"price":3798.55,"qty":0.31046272}],"asks":[],"checksum":1939635231,"timestamp":"2024-06-01T17:52:49.151882Z"}]}
{"channel":"book","type":"update","data":[{"symbol":"ETH/USDT","bids":[],"asks":[{"price":3800.21,"qty":0.00000000},{"price":3800.89,"qty":2.63310660}],"checksum":875820794,"timestamp":"2024-06-01T17:52:49.152228Z"}]}
{"channel":"book","type":"update","data":[{"symbol":"ETH/USDT","bids":[{"price":3799.09,"qty":0.00000000},{"price":3798.46,"qty":8.85019210}],"asks":[],"checksum":960839409,"timestamp":"2024-06-01T17:52:49.152554Z"}]}
{"channel":"book","type":"update","data":[{"symbol":"ETH/USDT","bids":[],"asks":[{"price":3799.84,"qty":0.72912968}],"checksum":4187439552,"timestamp":"2024-06-01T17:52:49.160860Z"}]}
{"channel":"book","type":"update","data":[{"symbol":"ETH/USDT","bids":[{"price":3799.14,"qty":0.73120000}],"asks":[],"checksum":3953849791,"timestamp":"2024-06-01T17:52:49.161422Z"}]}
{"channel":"book","type":"update","data":[{"symbol":"ETH/USDT","bids":[{"price":3799.14,"qty":0.00000000},{"price":3798.46,"qty":8.85019210}],"asks":[],"checksum":4187439552,"timestamp":"2024-06-01T17:52:49.174210Z"}]}
{"channel":"book","type":"update","data":[{"symbol":"ETH/USDT","bids":[],"asks":[{"price":3799.83,"qty":0.73120000}],"checksum":373602381,"timestamp":"2024-06-01T17:52:49.174328Z"}]}
{"channel":"book","type":"update","data":[{"symbol":"ETH/USDT","bids":[],"asks":[{"price":3799.83,"qty":0.00000000},{"price":3800.89,"qty":2.63310660}],"checksum":4187439552,"timestamp":"2024-06-01T17:52:49.178551Z"}]}
{"channel":"book","type":"update","data":[{"symbol":"ETH/USDT","bids":[],"asks":[{"price":3799.83,"qty":0.73120000}],"checksum":373602381,"timestamp":"2024-06-01T17:52:49.186660Z"}]}
{"channel":"book","type":"update","data":[{"symbol":"ETH/USDT","bids":[],"asks":[{"price":3799.83,"qty":0.00000000},{"price":3800.89,"qty":2.63310660}],"checksum":4187439552,"timestamp":"2024-06-01T17:52:49.189654Z"}]}
{"channel":"book","type":"update","data":[{"symbol":"ETH/USDT","bids":[],"asks":[{"price":3799.83,"qty":0.73120000}],"checksum":373602381,"timestamp":"2024-06-01T17:52:49.197084Z"}]}
{"channel":"book","type":"update","data":[{"symbol":"ETH/USDT","bids":[],"asks":[{"price":3799.83,"qty":0.00000000},{"price":3800.89,"qty":2.63310660}],"checksum":4187439552,"timestamp":"2024-06-01T17:52:49.200814Z"}]}
{"channel":"book","type":"update","data":[{"symbol":"ETH/USDT","bids":[],"asks":[{"price":3799.84,"qty":1.46032968}],"checksum":960839409,"timestamp":"2024-06-01T17:52:49.206720Z"}]}
{"channel":"book","type":"update","data":[{"symbol":"ETH/USDT","bids":[{"price":3799.13,"qty":0.98120000}],"asks":[],"checksum":1878413309,"timestamp":"2024-06-01T17:52:49.209995Z"}]}
{"channel":"book","type":"update","data":[{"symbol":"ETH/USDT","bids":[],"asks":[{"price":3799.84,"qty":0.72912968}],"checksum":2938384588,"timestamp":"2024-06-01T17:52:49.212013Z"}]}
{"channel":"book","type":"update","data":[{"symbol":"ETH/USDT","bids":[{"price":3798.55,"qty":0.00000000},{"price":3798.42,"qty":0.44053478}],"asks":[],"checksum":3866991510,"timestamp":"2024-06-01T17:52:49.221339Z"}]}
{"channel":"book","type":"update","data":[{"symbol":"ETH/USDT","bids":[],"asks":[{"price":3799.84,"qty":1.46032968}],"checksum":649061543,"timestamp":"2024-06-01T17:52:49.242262Z"}]}
{"channel":"book","type":"update","data":[{"symbol":"ETH/USDT","bids":[{"price":3799.14,"qty":0.73120000}],"asks":[],"checksum":4133088461,"timestamp":"2024-06-01T17:52:49.283659Z"}]}
{"channel":"book","type":"update","data":[{"symbol":"ETH/USDT","bids":[],"asks":[{"price":3799.84,"qty":0.72912968}],"checksum":915117052,"timestamp":"2024-06-01T17:52:49.283969Z"}]}
{"channel":"book","type":"update","data":[{"symbol":"ETH/USDT","bids":[{"price":3799.13,"qty":1.32120000}],"asks":[],"checksum":2059629588,"timestamp":"2024-06-01T17:52:49.356130Z"}]}
{"channel":"book","type":"update","data":[{"symbol":"ETH/USDT","bids":[{"price":3799.14,"qty":1.46240000}],"asks":[],"checksum":336950676,"timestamp":"2024-06-01T17:52:49.372469Z"}]}
{"channel":"book","type":"update","data":[{"symbol":"ETH/USDT","bids":[{"price":3799.13,"qty":0.98120000}],"asks":[],"checksum":2341270635,"timestamp":"2024-06-01T17:52:49.406464Z"}]}
{"channel":"book","type":"update","data":[{"symbol":"ETH/USDT","bids":[{"price":3799.14,"qty":1.80240000}],"asks":[],"checksum":2680205510,"timestamp":"2024-06-01T17:52:49.406622Z"}]}
{"channel":"book","type":"update","data":[{"symbol":"ETH/USDT","bids":[{"price":3799.14,"qty":1.07120000}],"asks":[],"checksum":4121863867,"timestamp":"2024-06-01T17:52:49.445312Z"}]}
{"channel":"book","type":"update","data":[{"symbol":"ETH/USDT","bids":[],"asks":[{"price":3799.84,"qty":0.00000000},{"price":3800.94,"qty":0.84627249}],"checksum":2618973783,"timestamp":"2024-06-01T17:52:49.449511Z"}]}
{"channel":"book","type":"update","data":[{"symbol":"ETH/USDT","bids":[],"asks":[{"price":3800.12,"qty":0.72912968}],"checksum":1222035805,"timestamp":"2024-06-01T17:52:49.449546Z"}]}
{"channel":"book","type":"update","data":[{"symbol":"ETH/USDT","bids":[{"price":3799.14,"qty":0.73120000}],"asks":[],"checksum":4078332172,"timestamp":"2024-06-01T17:52:49.452215Z"}]}
{"channel":"book","type":"update","data":[{"symbol":"ETH/USDT","bids":[{"price":3799.15,"qty":0.34000000}],"asks":[],"checksum":1558746186,"timestamp":"2024-06-01T17:52:49.452402Z"}]}
{"channel":"book","type":"update","data":[{"symbol":"ETH/USDT","bids":[{"price":3799.13,"qty":0.25000000}],"asks":[],"checksum":1422269247,"timestamp":"2024-06-01T17:52:49.455919Z"}]}
{"channel":"book","type":"update","data":[{"symbol":"ETH/USDT","bids":[{"price":3799.15,"qty":1.07120000}],"asks":[],"checksum":1752107547,"timestamp":"2024-06-01T17:52:49.456756Z"}]}
{"channel":"book","type":"update","data":[{"symbol":"ETH/USDT","bids":[{"price":3799.14,"qty":0.00000000},{"price":3798.46,"qty":8.85019210}],"asks":[],"checksum":404518305,"timestamp":"2024-06-01T17:52:49.459410Z"}]}
{"channel":"book","type":"update","data":[{"symbol":"ETH/USDT","bids":[{"price":3799.16,"qty":0.73120000}],"asks":[],"checksum":148279775,"timestamp":"2024-06-01T17:52:49.460970Z"}]}
{"channel":"book","type":"update","data":[{"symbol":"ETH/USDT","bids":[{"price":3798.80,"qty":0.00000000},{"price":3798.46,"qty":8.85019210}],"asks":[],"checksum":57031489,"timestamp":"2024-06-01T17:52:49.519504Z"}]}
{"channel":"book","type":"update","data":[{"symbol":"ETH/USDT","bids":[{"price":3798.53,"qty":0.19731456}],"asks":[],"checksum":273369238,"timestamp":"2024-06-01T17:52:49.560845Z"}]}
{"channel":"book","type":"update","data":[{"symbol":"ETH/USDT","bids":[{"price":3799.17,"qty":0.25000000}],"asks":[],"checksum":1735348968,"timestamp":"2024-06-01T17:52:49.588891Z"}]}
{"channel":"book","type":"update","data":[{"symbol":"ETH/USDT","bids":[{"price":3799.13,"qty":0.00000000},{"price":3798.53,"qty":0.19731456}],"asks":[],"checksum":285569854,"timestamp":"2024-06-01T17:52:49.594120Z"}]}
{"channel":"book","type":"update","data":[{"symbol":"ETH/USDT","bids":[{"price":3799.17,"qty":0.98120000}],"asks":[],"checksum":1203110450,"timestamp":"2024-06-01T17:52:49.594373Z"}]}
{"channel":"book","type":"update","data":[{"symbol":"ETH/USDT","bids":[{"price":3799.15,"qty":0.34000000}],"asks":[],"checksum":2140613845,"timestamp":"2024-06-01T17:52:49.595150Z"}]}
{"channel":"book","type":"update","data":[{"symbol":"ETH/USDT","bids":[{"price":3799.16,"qty":0.00000000},{"price":3798.46,"qty":8.85019210}],"asks":[],"checksum":1811235246,"timestamp":"2024-06-01T17:52:49.598032Z"}]}
{"channel":"book","type":"update","data":[{"symbol":"ETH/USDT","bids":[{"price":3799.18,"qty":0.73120000}],"asks":[],"checksum":1220705932,"timestamp":"2024-06-01T17:52:49.601898Z"}]}
{"channel":"book","type":"update","data":[{"symbol":"ETH/USDT","bids":[],"asks":[{"price":3799.89,"qty":0.73541065}],"checksum":1333153824,"timestamp":"2024-06-01T17:52:49.701807Z"}]}
{"channel":"book","type":"update","data":[{"symbol":"ETH/USDT","bids":[],"asks":[{"price":3799.88,"qty":0.72912968}],"checksum":1382768142,"timestamp":"2024-06-01T17:52:49.706223Z"}]}
{"channel":"book","type":"update","data":[{"symbol":"ETH/USDT","bids":[],"asks":[{"price":3799.89,"qty":0.00421065}],"checksum":1421060782,"timestamp":"2024-06-01T17:52:49.709905Z"}]}
{"channel":"book","type":"update","data":[{"symbol":"ETH/USDT","bids":[{"price":3799.18,"qty":0.00000000},{"price":3798.46,"qty":8.85019210}],"asks":[],"checksum":3196678558,"timestamp":"2024-06-01T17:52:49.735099Z"}]}
{"channel":"book","type":"update","data":[{"symbol":"ETH/USDT","bids":[],"asks":[{"price":3799.88,"qty":1.46032968}],"checksum":803179574,"timestamp":"2024-06-01T17:52:49.735592Z"}]}
{"channel":"book","type":"update","data":[{"symbol":"ETH/USDT","bids":[],"asks":[{"price":3799.88,"qty":0.72912968}],"checksum":3196678558,"timestamp":"2024-06-01T17:52:49.738706Z"}]}
{"channel":"book","type":"update","data":[{"symbol":"ETH/USDT","bids":[],"asks":[{"price":3799.88,"qty":0.00000000},{"price":3800.89,"qty":2.63310660}],"checksum":1811235246,"timestamp":"2024-06-01T17:52:49.739031Z"}]}
{"channel":"book","type":"update","data":[{"symbol":"ETH/USDT","bids":[{"price":3799.17,"qty":0.25000000}],"asks":[],"checksum":1028010146,"timestamp":"2024-06-01T17:52:49.745634Z"}]}
{"channel":"book","type":"update","data":[{"symbol":"ETH/USDT","bids":[],"asks":[{"price":3799.87,"qty":0.73120000}],"checksum":2856024083,"timestamp":"2024-06-01T17:52:49.746203Z"}]}
{"channel":"book","type":"update","data":[{"symbol":"ETH/USDT","bids":[],"asks":[{"price":3799.87,"qty":0.00000000},{"price":3800.89,"qty":2.63310660}],"checksum":1028010146,"timestamp":"2024-06-01T17:52:49.749918Z"}]}
{"channel":"book","type":"update","data":[{"symbol":"ETH/USDT","bids":[],"asks":[{"price":3799.88,"qty":0.73120000}],"checksum":472438679,"timestamp":"2024-06-01T17:52:49.756182Z"}]}
{"channel":"book","type":"update","data":[{"symbol":"ETH/USDT","bids":[],"asks":[{"price":3799.88,"qty":0.00000000},{"price":3800.89,"qty":2.63310660}],"checksum":1028010146,"timestamp":"2024-06-01T17:52:49.760052Z"}]}
{"channel":"book","type":"update","data":[{"symbol":"ETH/USDT","bids":[],"asks":[{"price":3799.88,"qty":0.73120000}],"checksum":472438679,"timestamp":"2024-06-01T17:52:49.767068Z"}]}
{"channel":"book","type":"update","data":[{"symbol":"ETH/USDT","bids":[],"asks":[{"price":3799.88,"qty":0.00000000},{"price":3800.89,"qty":2.63310660}],"checksum":1028010146,"timestamp":"2024-06-01T17:52:49.770544Z"}]}
{"channel":"book","type":"update","data":[{"symbol":"ETH/USDT","bids":[],"asks":[{"price":3799.87,"qty":0.72912968}],"checksum":1579790102,"timestamp":"2024-06-01T17:52:49.771343Z"}]}
{"channel":"book","type":"update","data":[{"symbol":"ETH/USDT","bids":[],"asks":[{"price":3799.86,"qty":0.73120000}],"checksum":4176089109,"timestamp":"2024-06-01T17:52:49.785033Z"}]}
{"channel":"book","type":"update","data":[{"symbol":"ETH/USDT","bids":[],"asks":[{"price":3799.86,"qty":0.00000000},{"price":3800.65,"qty":0.73120000}],"checksum":1579790102,"timestamp":"2024-06-01T17:52:49.788629Z"}]}
{"channel":"book","type":"update","data":[{"symbol":"ETH/USDT","bids":[],"asks":[{"price":3799.87,"qty":1.46032968}],"checksum":2467277228,"timestamp":"2024-06-01T17:52:49.842502Z"}]}
{"channel":"book","type":"update","data":[{"symbol":"ETH/USDT","bids":[],"asks":[{"price":3799.87,"qty":0.73120000}],"checksum":2856024083,"timestamp":"2024-06-01T17:52:49.847448Z"}]}
{"channel":"book","type":"update","data":[{"symbol":"ETH/USDT","bids":[],"asks":[{"price":3799.87,"qty":1.46240000}],"checksum":1162510328,"timestamp":"2024-06-01T17:52:49.986763Z"}]}
{"channel":"book","type":"update","data":[{"symbol":"ETH/USDT","bids":[{"price":3799.12,"qty":0.00000000},{"price":3798.42,"qty":0.44053478}],"asks":[],"checksum":1366534209,"timestamp":"2024-06-01T17:52:49.993365Z"}]}
{"channel":"book","type":"update","data":[{"symbol":"ETH/USDT","bids":[],"asks":[{"price":3800.22,"qty":0.00000000},{"price":3800.89,"qty":2.63310660}],"checksum":58029095,"timestamp":"2024-06-01T17:52:49.997003Z"}]}
{"channel":"book","type":"update","data":[{"symbol":"ETH/USDT","bids":[{"price":3798.78,"qty":0.00000000},{"price":3798.26,"qty":2.20193358}],"asks":[],"checksum":3669742291,"timestamp":"2024-06-01T17:52:49.997072Z"}]}
{"channel":"book","type":"update","data":[{"symbol":"ETH/USDT","bids":[],"asks":[{"price":3799.86,"qty":2.63382042}],"checksum":277292972,"timestamp":"2024-06-01T17:52:50.002244Z"}]}
{"channel":"book","type":"update","data":[{"symbol":"ETH/USDT","bids":[{"price":3798.29,"qty":2.63490482}],"asks":[],"checksum":1180882893,"timestamp":"2024-06-01T17:52:50.002328Z"}]}
{"channel":"book","type":"update","data":[{"symbol":"ETH/USDT","bids":[{"price":3799.15,"qty":0.00000000},{"price":3798.26,"qty":2.20193358}],"asks":[],"checksum":385627841,"timestamp":"2024-06-01T17:52:50.004957Z"}]}
{"channel":"book","type":"update","data":[{"symbol":"ETH/USDT","bids":[],"asks":[{"price":3799.87,"qty":0.73120000}],"checksum":1335991283,"timestamp":"2024-06-01T17:52:50.005804Z"}]}
{"channel":"book","type":"update","data":[{"symbol":"ETH/USDT","bids":[],"asks":[{"price":3799.86,"qty":3.36502042}],"checksum":3740549829,"timestamp":"2024-06-01T17:52:50.006316Z"}]}
{"channel":"book","type":"update","data":[{"symbol":"ETH/USDT","bids":[],"asks":[{"price":3799.85,"qty":0.73120000}],"checksum":3975990333,"timestamp":"2024-06-01T17:52:50.006654Z"}]}
{"channel":"book","type":"update","data":[{"symbol":"ETH/USDT","bids":[],"asks":[{"price":3799.86,"qty":0.73120000}],"checksum":610485385,"timestamp":"2024-06-01T17:52:50.011316Z"}]}
{"channel":"book","type":"update","data":[{"symbol":"ETH/USDT","bids":[],"asks":[{"price":3799.86,"qty":0.00000000},{"price":3800.65,"qty":0.73120000}],"checksum":252501080,"timestamp":"2024-06-01T17:52:50.016355Z"}]}
{"channel":"book","type":"update","data":[{"symbol":"ETH/USDT","bids":[],"asks":[{"price":3799.84,"qty":0.72912968}],"checksum":1706922794,"timestamp":"2024-06-01T17:52:50.020940Z"}]}
{"channel":"book","type":"update","data":[{"symbol":"ETH/USDT","bids":[],"asks":[{"price":3799.81,"qty":0.73120000}],"checksum":1739279338,"timestamp":"2024-06-01T17:52:50.024213Z"}]}
{"channel":"book","type":"update","data":[{"symbol":"ETH/USDT","bids":[{"price":3798.53,"qty":0.00000000},{"price":3798.13,"qty":0.73120000}],"asks":[],"checksum":2807597963,"timestamp":"2024-06-01T17:52:50.078594Z"}]}
{"channel":"book","type":"update","data":[{"symbol":"ETH/USDT","bids":[{"price":3798.26,"qty":2.13500000}],"asks":[],"checksum":2036090331,"timestamp":"2024-06-01T17:52:50.084681Z"}]}
{"channel":"book","type":"update","data":[{"symbol":"ETH/USDT","bids":[{"price":3798.26,"qty":2.20193358}],"asks":[],"checksum":2807597963,"timestamp":"2024-06-01T17:52:50.088404Z"}]}
{"channel":"book","type":"update","data":[{"symbol":"ETH/USDT","bids":[],"asks":[{"price":3800.12,"qty":0.00000000},{"price":3800.57,"qty":0.25000000}],"checksum":3061775819,"timestamp":"2024-06-01T17:52:50.088517Z"}]}
{"channel":"book","type":"update","data":[{"symbol":"ETH/USDT","bids":[{"price":3798.56,"qty":0.19731105}],"asks":[],"checksum":2321302112,"timestamp":"2024-06-01T17:52:50.119001Z"}]}
{"channel":"book","type":"update","data":[{"symbol":"ETH/USDT","bids":[{"price":3799.08,"qty":0.00000000},{"price":3798.13,"qty":0.73120000}],"asks":[],"checksum":315469017,"timestamp":"2024-06-01T17:52:50.288315Z"}]}
{"channel":"book","type":"update","data":[{"symbol":"ETH/USDT","bids":[{"price":3798.69,"qty":0.34000000}],"asks":[],"checksum":2792743817,"timestamp":"2024-06-01T17:52:50.291402Z"}]}
{"channel":"book","type":"update","data":[{"symbol":"ETH/USDT","bids":[],"asks":[{"price":3799.80,"qty":0.72912968}],"checksum":1425306198,"timestamp":"2024-06-01T17:52:50.293244Z"}]}
{"channel":"book","type":"update","data":[{"symbol":"ETH/USDT","bids":[{"price":3799.17,"qty":0.00000000},{"price":3798.13,"qty":0.73120000}],"asks":[],"checksum":2795271207,"timestamp":"2024-06-01T17:52:50.293669Z"}]}
{"channel":"book","type":"update","data":[{"symbol":"ETH/USDT","bids":[{"price":3798.61,"qty":0.00000000},{"price":3798.12,"qty":2.79800000}],"asks":[],"checksum":259235098,"timestamp":"2024-06-01T17:52:50.293924Z"}]}
{"channel":"book","type":"update","data":[{"symbol":"ETH/USDT","bids":[],"asks":[{"price":3799.85,"qty":0.00000000},{"price":3800.57,"qty":0.25000000}],"checksum":2403793543,"timestamp":"2024-06-01T17:52:50.296508Z"}]}
{"channel":"book","type":"update","data":[{"symbol":"ETH/USDT","bids":[],"asks":[{"price":3799.70,"qty":0.73120000}],"checksum":3749764214,"timestamp":"2024-06-01T17:52:50.297324Z"}]}
{"channel":"book","type":"update","data":[{"symbol":"ETH/USDT","bids":[{"price":3798.87,"qty":0.73120000}],"asks":[],"checksum":3585023061,"timestamp":"2024-06-01T17:52:50.297532Z"}]}
{"channel":"book","type":"update","data":[{"symbol":"ETH/USDT","bids":[{"price":3798.69,"qty":0.00000000},{"price":3798.12,"qty":2.79800000}],"asks":[],"checksum":473211680,"timestamp":"2024-06-01T17:52:50.300117Z"}]}
{"channel":"book","type":"update","data":[{"symbol":"ETH/USDT","bids":[{"price":3798.89,"qty":0.34000000}],"asks":[],"checksum":1047557757,"timestamp":"2024-06-01T17:52:50.300360Z"}]}
{"channel":"book","type":"update","data":[{"symbol":"ETH/USDT","bids":[{"price":3798.92,"qty":0.73120000}],"asks":[],"checksum":288017404,"timestamp":"2024-06-01T17:52:50.307972Z"}]}
{"channel":"book","type":"update","data":[{"symbol":"ETH/USDT","bids":[{"price":3798.26,"qty":0.06693358}],"asks":[],"checksum":364979399,"timestamp":"2024-06-01T17:52:50.310996Z"}]}
{"channel":"book","type":"update","data":[{"symbol":"ETH/USDT","bids":[{"price":3798.92,"qty":0.00000000},{"price":3798.13,"qty":0.73120000}],"asks":[],"checksum":4243388446,"timestamp":"2024-06-01T17:52:50.311130Z"}]}
{"channel":"book","type":"update","data":[{"symbol":"ETH/USDT","bids":[{"price":3798.70,"qty":0.28000000}],"asks":[],"checksum":1234424588,"timestamp":"2024-06-01T17:52:50.329330Z"}]}
{"channel":"book","type":"update","data":[{"symbol":"ETH/USDT","bids":[],"asks":[{"price":3799.80,"qty":0.00000000},{"price":3800.57,"qty":0.25000000}],"checksum":619176622,"timestamp":"2024-06-01T17:52:50.333070Z"}]}
{"channel":"book","type":"update","data":[{"symbol":"ETH/USDT","bids":[{"price":3798.90,"qty":0.84627249}],"asks":[],"checksum":1057393245,"timestamp":"2024-06-01T17:52:50.334546Z"}]}
{"channel":"book","type":"update","data":[{"symbol":"ETH/USDT","bids":[{"price":3798.89,"qty":0.00000000},{"price":3798.26,"qty":0.06693358}],"asks":[],"checksum":1445969733,"timestamp":"2024-06-01T17:52:50.337234Z"}]}
{"channel":"book","type":"update","data":[{"symbol":"ETH/USDT","bids":[{"price":3798.92,"qty":0.34000000}],"asks":[],"checksum":648894047,"timestamp":"2024-06-01T17:52:50.337293Z"}]}
{"channel":"book","type":"update","data":[{"symbol":"ETH/USDT","bids":[],"asks":[{"price":3799.81,"qty":0.00000000},{"price":3800.65,"qty":0.73120000}],"checksum":514042605,"timestamp":"2024-06-01T17:52:50.337493Z"}]}
{"channel":"book","type":"update","data":[{"symbol":"ETH/USDT","bids":[{"price":3798.70,"qty":0.00000000},{"price":3798.26,"qty":0.06693358}],"asks":[],"checksum":3242882346,"timestamp":"2024-06-01T17:52:50.359591Z"}]}
{"channel":"book","type":"update","data":[{"symbol":"ETH/USDT","bids":[],"asks":[{"price":3799.69,"qty":0.72912968}],"checksum":1168658348,"timestamp":"2024-06-01T17:52:50.363502Z"}]}
{"channel":"book","type":"update","data":[{"symbol":"ETH/USDT","bids":[{"price":3798.90,"qty":0.00000000},{"price":3798.13,"qty":0.73120000}],"asks":[],"checksum":319840653,"timestamp":"2024-06-01T17:52:50.364711Z"}]}
{"channel":"book","type":"update","data":[{"symbol":"ETH/USDT","bids":[{"price":3798.93,"qty":0.84627249}],"asks":[],"checksum":1637307266,"timestamp":"2024-06-01T17:52:50.364871Z"}]}
{"channel":"book","type":"update","data":[{"symbol":"ETH/USDT","bids":[],"asks":[{"price":3799.66,"qty":0.73120000}],"checksum":2959437830,"timestamp":"2024-06-01T17:52:50.366755Z"}]}
{"channel":"book","type":"update","data":[{"symbol":"ETH/USDT","bids":[{"price":3798.87,"qty":0.00000000},{"price":3798.13,"qty":0.73120000}],"asks":[],"checksum":1905756852,"timestamp":"2024-06-01T17:52:50.391699Z"}]}
{"channel":"book","type":"update","data":[{"symbol":"ETH/USDT","bids":[{"price":3798.92,"qty":0.00000000},{"price":3798.12,"qty":2.79800000}],"asks":[],"checksum":1309079760,"timestamp":"2024-06-01T17:52:50.395149Z"}]}
{"channel":"book","type":"update","data":[{"symbol":"ETH/USDT","bids":[{"price":3798.68,"qty":0.34000000}],"asks":[],"checksum":4225197995,"timestamp":"2024-06-01T17:52:50.395348Z"}]}
{"channel":"book","type":"update","data":[{"symbol":"ETH/USDT","bids":[],"asks":[{"price":3799.69,"qty":0.00000000},{"price":3800.57,"qty":0.25000000}],"checksum":2430720395,"timestamp":"2024-06-01T17:52:50.396323Z"}]}
{"channel":"book","type":"update","data":[{"symbol":"ETH/USDT","bids":[{"price":3798.60,"qty":0.00000000},{"price":3798.12,"qty":2.79800000}],"asks":[],"checksum":4112614416,"timestamp":"2024-06-01T17:52:50.399375Z"}]}
{"channel":"book","type":"update","data":[{"symbol":"ETH/USDT","bids":[],"asks":[{"price":3799.70,"qty":0.00000000},{"price":3800.65,"qty":0.73120000}],"checksum":4000326046,"timestamp":"2024-06-01T17:52:50.402388Z"}]}
{"channel":"book","type":"update","data":[{"symbol":"ETH/USDT","bids":[],"asks":[{"price":3799.66,"qty":0.00000000},{"price":3800.89,"qty":2.63310660}],"checksum":29375527,"timestamp":"2024-06-01T17:52:50.405239Z"}]}
{"channel":"book","type":"update","data":[{"symbol":"ETH/USDT","bids":[],"asks":[{"price":3799.80,"qty":2.63386201}],"checksum":1404780201,"timestamp":"2024-06-01T17:52:50.407259Z"}]}
{"channel":"book","type":"update","data":[{"symbol":"ETH/USDT","bids":[],"asks":[{"price":3799.61,"qty":0.73120000}],"checksum":1628086886,"timestamp":"2024-06-01T17:52:50.408737Z"}]}
{"channel":"book","type":"update","data":[{"symbol":"ETH/USDT","bids":[{"price":3798.13,"qty":2.93520000}],"asks":[],"checksum":2094374061,"timestamp":"2024-06-01T17:52:50.408945Z"}]}
{"channel":"book","type":"update","data":[{"symbol":"ETH/USDT","bids":[{"price":3798.93,"qty":0.00000000},{"price":3798.02,"qty":0.28507811}],"asks":[],"checksum":3023680282,"timestamp":"2024-06-01T17:52:50.447601Z"}]}
{"channel":"book","type":"update","data":[{"symbol":"ETH/USDT","bids":[{"price":3798.46,"qty":0.00000000},{"price":3797.85,"qty":0.72912968}],"asks":[],"checksum":3139792368,"timestamp":"2024-06-01T17:52:50.448982Z"}]}
{"channel":"book","type":"update","data":[{"symbol":"ETH/USDT","bids":[{"price":3798.92,"qty":1.31690885}],"asks":[],"checksum":1179529197,"timestamp":"2024-06-01T17:52:50.449340Z"}]}
{"channel":"book","type":"update","data":[{"symbol":"ETH/USDT","bids":[{"price":3798.13,"qty":0.73120000}],"asks":[],"checksum":2957635012,"timestamp":"2024-06-01T17:52:50.449539Z"}]}
{"channel":"book","type":"update","data":[{"symbol":"ETH/USDT","bids":[{"price":3798.73,"qty":1.31690885}],"asks":[],"checksum":2674237587,"timestamp":"2024-06-01T17:52:50.450000Z"}]}
{"channel":"book","type":"update","data":[{"symbol":"ETH/USDT","bids":[{"price":3798.59,"qty":0.00000000},{"price":3798.02,"qty":0.28507811}],"asks":[],"checksum":199567423,"timestamp":"2024-06-01T17:52:50.450842Z"}]}
{"channel":"book","type":"update","data":[{"symbol":"ETH/USDT","bids":[{"price":3798.27,"qty":10.85468559}],"asks":[],"checksum":1293931869,"timestamp":"2024-06-01T17:52:50.453566Z"}]}
{"channel":"book","type":"update","data":[{"symbol":"ETH/USDT","bids":[{"price":3798.54,"qty":0.73120000}],"asks":[],"checksum":1650196455,"timestamp":"2024-06-01T17:52:50.454250Z"}]}
{"channel":"book","type":"update","data":[{"symbol":"ETH/USDT","bids":[{"price":3798.42,"qty":0.00000000},{"price":3798.12,"qty":2.79800000}],"asks":[],"checksum":2808723697,"timestamp":"2024-06-01T17:52:50.517346Z"}]}
{"channel":"book","type":"update","data":[{"symbol":"ETH/USDT","bids":[],"asks":[{"price":3799.60,"qty":0.72912968}],"checksum":296198642,"timestamp":"2024-06-01T17:52:50.588389Z"}]}
{"channel":"book","type":"update","data":[{"symbol":"ETH/USDT","bids":[{"price":3798.93,"qty":0.25000000}],"asks":[],"checksum":2467242475,"timestamp":"2024-06-01T17:52:50.589177Z"}]}
{"channel":"book","type":"update","data":[{"symbol":"ETH/USDT","bids":[],"asks":[{"price":3799.53,"qty":0.73120000}],"checksum":72592246,"timestamp":"2024-06-01T17:52:50.592099Z"}]}
{"channel":"book","type":"update","data":[{"symbol":"ETH/USDT","bids":[{"price":3798.46,"qty":0.84627249}],"asks":[],"checksum":3278648499,"timestamp":"2024-06-01T17:52:50.593530Z"}]}
{"channel":"book","type":"update","data":[{"symbol":"ETH/USDT","bids":[{"price":3798.56,"qty":0.00000000},{"price":3798.13,"qty":0.73120000}],"asks":[],"checksum":3081207379,"timestamp":"2024-06-01T17:52:50.634357Z"}]}
{"channel":"book","type":"update","data":[{"symbol":"ETH/USDT","bids":[],"asks":[{"price":3799.60,"qty":0.00000000},{"price":3800.53,"qty":0.74200000}],"checksum":3652587263,"timestamp":"2024-06-01T17:52:50.638405Z"}]}
{"channel":"book","type":"update","data":[{"symbol":"ETH/USDT","bids":[],"asks":[{"price":3799.61,"qty":0.00000000},{"price":3800.57,"qty":0.25000000}],"checksum":3543118994,"timestamp":"2024-06-01T17:52:50.643505Z"}]}
{"channel":"book","type":"update","data":[{"symbol":"ETH/USDT","bids":[{"price":3798.46,"qty":1.04360764}],"asks":[],"checksum":49822790,"timestamp":"2024-06-01T17:52:50.674829Z"}]}
{"channel":"book","type":"update","data":[{"symbol":"ETH/USDT","bids":[],"asks":[{"price":3799.52,"qty":0.72912968}],"checksum":1900885461,"timestamp":"2024-06-01T17:52:51.091219Z"}]}
{"channel":"book","type":"update","data":[{"symbol":"ETH/USDT","bids":[],"asks":[{"price":3799.46,"qty":0.73120000}],"checksum":4126712565,"timestamp":"2024-06-01T17:52:51.094777Z"}]}
{"channel":"book","type":"update","data":[{"symbol":"ETH/USDT","bids":[{"price":3798.54,"qty":0.00000000},{"price":3798.12,"qty":2.79800000}],"asks":[],"checksum":1716295100,"timestamp":"2024-06-01T17:52:51.094827Z"}]}
{"channel":"book","type":"update","data":[{"symbol":"ETH/USDT","bids":[{"price":3798.74,"qty":5.00000000}],"asks":[],"checksum":2190398725,"timestamp":"2024-06-01T17:52:51.096056Z"}]}
{"channel":"book","type":"update","data":[{"symbol":"ETH/USDT","bids":[],"asks":[{"price":3799.42,"qty":0.73120000}],"checksum":552239495,"timestamp":"2024-06-01T17:52:51.097916Z"}]}
{"channel":"book","type":"update","data":[{"symbol":"ETH/USDT","bids":[{"price":3798.55,"qty":0.73120000}],"asks":[],"checksum":4140554177,"timestamp":"2024-06-01T17:52:51.100110Z"}]}
{"channel":"book","type":"update","data":[{"symbol":"ETH/USDT","bids":[],"asks":[{"price":3799.42,"qty":0.00000000},{"price":3800.47,"qty":2.13500000}],"checksum":1420788547,"timestamp":"2024-06-01T17:52:51.101696Z"}]}
{"channel":"book","type":"update","data":[{"symbol":"ETH/USDT","bids":[{"price":3798.55,"qty":0.00000000},{"price":3798.13,"qty":0.73120000}],"asks":[],"checksum":2190398725,"timestamp":"2024-06-01T17:52:51.102843Z"}]}
{"channel":"book","type":"update","data":[{"symbol":"ETH/USDT","bids":[],"asks":[{"price":3799.46,"qty":1.46240000}],"checksum":2932041725,"timestamp":"2024-06-01T17:52:51.106871Z"}]}
{"channel":"book","type":"update","data":[{"symbol":"ETH/USDT","bids":[{"price":3798.55,"qty":0.73120000}],"asks":[],"checksum":2028089787,"timestamp":"2024-06-01T17:52:51.110190Z"}]}
{"channel":"book","type":"update","data":[{"symbol":"ETH/USDT","bids":[{"price":3798.46,"qty":0.84627249}],"asks":[],"checksum":3595181664,"timestamp":"2024-06-01T17:52:51.128617Z"}]}
{"channel":"book","type":"update","data":[{"symbol":"ETH/USDT","bids":[{"price":3798.38,"qty":0.19733896}],"asks":[],"checksum":917276195,"timestamp":"2024-06-01T17:52:51.169355Z"}]}
{"channel":"book","type":"update","data":[{"symbol":"ETH/USDT","bids":[],"asks":[{"price":3799.52,"qty":0.00000000},{"price":3800.53,"qty":0.74200000}],"checksum":3417324042,"timestamp":"2024-06-01T17:52:51.588570Z"}]}
{"channel":"book","type":"update","data":[{"symbol":"ETH/USDT","bids":[{"price":3798.38,"qty":0.00000000},{"price":3798.26,"qty":0.06693358}],"asks":[],"checksum":2819575162,"timestamp":"2024-06-01T17:52:51.693509Z"}]}
{"channel":"book","type":"update","data":[{"symbol":"ETH/USDT","bids":[{"price":3798.36,"qty":0.19734191}],"asks":[],"checksum":2223471372,"timestamp":"2024-06-01T17:52:51.733888Z"}]}
{"channel":"book","type":"update","data":[{"symbol":"ETH/USDT","bids":[],"asks":[{"price":3800.47,"qty":0.00000000},{"price":3800.57,"qty":0.25000000}],"checksum":1291723248,"timestamp":"2024-06-01T17:52:51.925087Z"}]}
{"channel":"book","type":"update","data":[{"symbol":"ETH/USDT","bids":[],"asks":[{"price":3799.46,"qty":0.73120000}],"checksum":3637662286,"timestamp":"2024-06-01T17:52:51.939886Z"}]}
{"channel":"book","type":"update","data":[{"symbol":"ETH/USDT","bids":[],"asks":[{"price":3799.46,"qty":0.00000000},{"price":3800.65,"qty":0.73120000}],"checksum":669546733,"timestamp":"2024-06-01T17:52:51.941470Z"}]}
{"channel":"book","type":"update","data":[{"symbol":"ETH/USDT","bids":[],"asks":[{"price":3799.53,"qty":0.00000000},{"price":3800.89,"qty":2.63310660}],"checksum":1823245866,"timestamp":"2024-06-01T17:52:51.941879Z"}]}
{"channel":"book","type":"update","data":[{"symbol":"ETH/USDT","bids":[{"price":3798.96,"qty":0.73120000}],"asks":[],"checksum":2385447323,"timestamp":"2024-06-01T17:52:51.941920Z"}]}
{"channel":"book","type":"update","data":[{"symbol":"ETH/USDT","bids":[{"price":3798.94,"qty":0.73120000}],"asks":[],"checksum":2835352563,"timestamp":"2024-06-01T17:52:51.942053Z"}]}
{"channel":"book","type":"update","data":[{"symbol":"ETH/USDT","bids":[],"asks":[{"price":3799.87,"qty":0.00000000},{"price":3800.94,"qty":0.84627249}],"checksum":4087352574,"timestamp":"2024-06-01T17:52:51.942191Z"}]}
{"channel":"book","type":"update","data":[{"symbol":"ETH/USDT","bids":[],"asks":[{"price":3799.79,"qty":0.73120000}],"checksum":1934036766,"timestamp":"2024-06-01T17:52:51.947606Z"}]}
{"channel":"book","type":"update","data":[{"symbol":"ETH/USDT","bids":[{"price":3798.94,"qty":0.00000000},{"price":3798.29,"qty":2.63490482}],"asks":[],"checksum":1347342426,"timestamp":"2024-06-01T17:52:51.947768Z"}]}
{"channel":"book","type":"update","data":[{"symbol":"ETH/USDT","bids":[],"asks":[{"price":3799.75,"qty":0.73120000}],"checksum":2224104170,"timestamp":"2024-06-01T17:52:51.947874Z"}]}
{"channel":"book","type":"update","data":[{"symbol":"ETH/USDT","bids":[{"price":3798.96,"qty":1.46240000}],"asks":[],"checksum":613760375,"timestamp":"2024-06-01T17:52:51.950639Z"}]}
{"channel":"book","type":"update","data":[{"symbol":"ETH/USDT","bids":[],"asks":[{"price":3799.79,"qty":0.00000000},{"price":3800.89,"qty":2.63310660}],"checksum":3410763878,"timestamp":"2024-06-01T17:52:51.951191Z"}]}
{"channel":"book","type":"update","data":[{"symbol":"ETH/USDT","bids":[],"asks":[{"price":3799.75,"qty":0.00000000},{"price":3800.94,"qty":0.84627249}],"checksum":676819896,"timestamp":"2024-06-01T17:52:51.951688Z"}]}
{"channel":"book","type":"update","data":[{"symbol":"ETH/USDT","bids":[{"price":3798.96,"qty":0.73120000}],"asks":[],"checksum":4039431457,"timestamp":"2024-06-01T17:52:51.955535Z"}]}
{"channel":"book","type":"update","data":[{"symbol":"ETH/USDT","bids":[],"asks":[{"price":3799.79,"qty":0.73120000}],"checksum":1347342426,"timestamp":"2024-06-01T17:52:51.957444Z"}]}
{"channel":"book","type":"update","data":[{"symbol":"ETH/USDT","bids":[{"price":3798.96,"qty":1.46240000}],"asks":[],"checksum":4011872521,"timestamp":"2024-06-01T17:52:51.959387Z"}]}
{"channel":"book","type":"update","data":[{"symbol":"ETH/USDT","bids":[],"asks":[{"price":3799.79,"qty":0.00000000},{"price":3800.94,"qty":0.84627249}],"checksum":676819896,"timestamp":"2024-06-01T17:52:51.961127Z"}]}
{"channel":"book","type":"update","data":[{"symbol":"ETH/USDT","bids":[],"asks":[{"price":3799.80,"qty":0.00000000},{"price":3801.01,"qty":0.06693358}],"checksum":4251295981,"timestamp":"2024-06-01T17:52:51.962742Z"}]}
{"channel":"book","type":"update","data":[{"symbol":"ETH/USDT","bids":[{"price":3799.01,"qty":0.34000000}],"asks":[],"checksum":61752597,"timestamp":"2024-06-01T17:52:51.965879Z"}]}
{"channel":"book","type":"update","data":[{"symbol":"ETH/USDT","bids":[{"price":3798.68,"qty":0.00000000},{"price":3798.29,"qty":2.63490482}],"asks":[],"checksum":3211262315,"timestamp":"2024-06-01T17:52:51.966203Z"}]}
{"channel":"book","type":"update","data":[{"symbol":"ETH/USDT","bids":[],"asks":[{"price":3799.78,"qty":2.63387607}],"checksum":2362632433,"timestamp":"2024-06-01T17:52:51.968305Z"}]}
{"channel":"book","type":"update","data":[{"symbol":"ETH/USDT","bids":[{"price":3799.16,"qty":0.73120000}],"asks":[],"checksum":2329398873,"timestamp":"2024-06-01T17:52:51.969852Z"}]}
{"channel":"book","type":"update","data":[{"symbol":"ETH/USDT","bids":[],"asks":[{"price":3799.77,"qty":0.72912968}],"checksum":2164213116,"timestamp":"2024-06-01T17:52:51.974438Z"}]}
{"channel":"book","type":"update","data":[{"symbol":"ETH/USDT","bids":[{"price":3799.17,"qty":0.25000000}],"asks":[],"checksum":3890100927,"timestamp":"2024-06-01T17:52:51.974829Z"}]}
{"channel":"book","type":"update","data":[{"symbol":"ETH/USDT","bids":[{"price":3799.17,"qty":0.98120000}],"asks":[],"checksum":3882554762,"timestamp":"2024-06-01T17:52:51.986127Z"}]}
{"channel":"book","type":"update","data":[{"symbol":"ETH/USDT","bids":[{"price":3798.96,"qty":0.73120000}],"asks":[],"checksum":1997922364,"timestamp":"2024-06-01T17:52:51.986614Z"}]}
{"channel":"book","type":"update","data":[{"symbol":"ETH/USDT","bids":[{"price":3799.16,"qty":0.00000000},{"price":3798.36,"qty":0.19734191}],"asks":[],"checksum":3134663402,"timestamp":"2024-06-01T17:52:51.988018Z"}]}
{"channel":"book","type":"update","data":[{"symbol":"ETH/USDT","bids":[{"price":3799.18,"qty":0.73120000}],"asks":[],"checksum":4202449367,"timestamp":"2024-06-01T17:52:51.991910Z"}]}
{"channel":"book","type":"update","data":[{"symbol":"ETH/USDT","bids":[{"price":3799.18,"qty":0.00000000},{"price":3798.36,"qty":0.19734191}],"asks":[],"checksum":3134663402,"timestamp":"2024-06-01T17:52:51.999474Z"}]}
{"channel":"book","type":"update","data":[{"symbol":"ETH/USDT","bids":[{"price":3798.93,"qty":0.00000000},{"price":3798.29,"qty":2.63490482}],"asks":[],"checksum":497700323,"timestamp":"2024-06-01T17:52:52.005945Z"}]}
{"channel":"book","type":"update","data":[{"symbol":"ETH/USDT","bids":[],"asks":[{"price":3799.84,"qty":0.00000000},{"price":3800.94,"qty":0.84627249}],"checksum":1650891481,"timestamp":"2024-06-01T17:52:52.010107Z"}]}
{"channel":"book","type":"update","data":[{"symbol":"ETH/USDT","bids":[{"price":3799.18,"qty":0.73120000}],"asks":[],"checksum":4237008383,"timestamp":"2024-06-01T17:52:52.017373Z"}]}
{"channel":"book","type":"update","data":[{"symbol":"ETH/USDT","bids":[],"asks":[{"price":3800.56,"qty":2.20400000}],"checksum":4162105765,"timestamp":"2024-06-01T17:52:52.023801Z"}]}
{"channel":"book","type":"update","data":[{"symbol":"ETH/USDT","bids":[{"price":3799.18,"qty":0.00000000},{"price":3798.29,"qty":2.63490482}],"asks":[],"checksum":3923557663,"timestamp":"2024-06-01T17:52:52.077086Z"}]}
{"channel":"book","type":"update","data":[{"symbol":"ETH/USDT","bids":[{"price":3799.18,"qty":0.73120000}],"asks":[],"checksum":4162105765,"timestamp":"2024-06-01T17:52:52.102957Z"}]}
{"channel":"book","type":"update","data":[{"symbol":"ETH/USDT","bids":[{"price":3799.18,"qty":0.00000000},{"price":3798.29,"qty":2.63490482}],"asks":[],"checksum":3923557663,"timestamp":"2024-06-01T17:52:52.212097Z"}]}
{"channel":"book","type":"update","data":[{"symbol":"ETH/USDT","bids":[{"price":3799.17,"qty":0.25000000}],"asks":[],"checksum":3916010026,"timestamp":"2024-06-01T17:52:52.230148Z"}]}
{"channel":"book","type":"update","data":[{"symbol":"ETH/USDT","bids":[{"price":3798.36,"qty":0.00000000},{"price":3798.27,"qty":10.85468559}],"asks":[],"checksum":691245796,"timestamp":"2024-06-01T17:52:52.251510Z"}]}
{"channel":"book","type":"update","data":[{"symbol":"ETH/USDT","bids":[{"price":3798.59,"qty":0.19730998}],"asks":[],"checksum":2041563742,"timestamp":"2024-06-01T17:52:52.291629Z"}]}
{"channel":"book","type":"update","data":[{"symbol":"ETH/USDT","bids":[{"price":3799.17,"qty":0.00000000},{"price":3798.27,"qty":10.85468559}],"asks":[],"checksum":3280242740,"timestamp":"2024-06-01T17:52:52.586433Z"}]}
{"channel":"book","type":"update","data":[{"symbol":"ETH/USDT","bids":[{"price":3799.02,"qty":0.25000000}],"asks":[],"checksum":102184134,"timestamp":"2024-06-01T17:52:52.586526Z"}]}
{"channel":"book","type":"update","data":[{"symbol":"ETH/USDT","bids":[{"price":3799.12,"qty":0.73120000}],"asks":[],"checksum":1041073165,"timestamp":"2024-06-01T17:52:52.590383Z"}]}
{"channel":"book","type":"update","data":[{"symbol":"ETH/USDT","bids":[{"price":3799.01,"qty":0.00000000},{"price":3798.29,"qty":2.63490482}],"asks":[],"checksum":1012910731,"timestamp":"2024-06-01T17:52:52.645908Z"}]}
{"channel":"book","type":"update","data":[{"symbol":"ETH/USDT","bids":[{"price":3799.13,"qty":0.34000000}],"asks":[],"checksum":1286163749,"timestamp":"2024-06-01T17:52:52.646083Z"}]}
{"channel":"book","type":"update","data":[{"symbol":"ETH/USDT","bids":[{"price":3799.13,"qty":0.59000000}],"asks":[],"checksum":3138804632,"timestamp":"2024-06-01T17:52:52.651649Z"}]}
{"channel":"book","type":"update","data":[{"symbol":"ETH/USDT","bids":[{"price":3799.13,"qty":1.32120000}],"asks":[],"checksum":1416117086,"timestamp":"2024-06-01T17:52:52.731572Z"}]}
{"channel":"book","type":"update","data":[{"symbol":"ETH/USDT","bids":[{"price":3799.12,"qty":0.00000000},{"price":3798.29,"qty":2.63490482}],"asks":[],"checksum":1627841537,"timestamp":"2024-06-01T17:52:52.732792Z"}]}
{"channel":"book","type":"update","data":[{"symbol":"ETH/USDT","bids":[{"price":3799.02,"qty":0.00000000},{"price":3798.27,"qty":10.85468559}],"asks":[],"checksum":2080741109,"timestamp":"2024-06-01T17:52:52.735971Z"}]}
{"channel":"book","type":"update","data":[{"symbol":"ETH/USDT","bids":[{"price":3799.14,"qty":0.73120000}],"asks":[],"checksum":628400825,"timestamp":"2024-06-01T17:52:52.777650Z"}]}
{"channel":"book","type":"update","data":[{"symbol":"ETH/USDT","bids":[{"price":3798.59,"qty":0.00000000},{"price":3798.27,"qty":10.85468559}],"asks":[],"checksum":2070233726,"timestamp":"2024-06-01T17:52:52.824767Z"}]}
{"channel":"book","type":"update","data":[{"symbol":"ETH/USDT","bids":[{"price":3798.64,"qty":0.19729558}],"asks":[],"checksum":1897948856,"timestamp":"2024-06-01T17:52:52.993097Z"}]}
{"channel":"book","type":"update","data":[{"symbol":"ETH/USDT","bids":[{"price":3799.15,"qty":1.31702332}],"asks":[],"checksum":569664014,"timestamp":"2024-06-01T17:52:53.136363Z"}]}
{"channel":"book","type":"update","data":[{"symbol":"ETH/USDT","bids":[{"price":3798.92,"qty":0.00000000},{"price":3798.29,"qty":2.63490482}],"asks":[],"checksum":560221145,"timestamp":"2024-06-01T17:52:53.139986Z"}]}
{"channel":"book","type":"update","data":[{"symbol":"ETH/USDT","bids":[{"price":3799.13,"qty":0.59000000}],"asks":[],"checksum":467421434,"timestamp":"2024-06-01T17:52:53.277599Z"}]}
{"channel":"book","type":"update","data":[{"symbol":"ETH/USDT","bids":[{"price":3799.15,"qty":2.04822332}],"asks":[],"checksum":1790513623,"timestamp":"2024-06-01T17:52:53.278279Z"}]}
{"channel":"book","type":"update","data":[{"symbol":"ETH/USDT","bids":[{"price":3799.15,"qty":1.31702332}],"asks":[],"checksum":467421434,"timestamp":"2024-06-01T17:52:53.382197Z"}]}
{"channel":"book","type":"update","data":[{"symbol":"ETH/USDT","bids":[{"price":3799.14,"qty":0.00000000},{"price":3798.27,"qty":10.85468559}],"asks":[],"checksum":3014620625,"timestamp":"2024-06-01T17:52:53.382713Z"}]}
{"channel":"book","type":"update","data":[{"symbol":"ETH/USDT","bids":[{"price":3798.64,"qty":0.00000000},{"price":3798.26,"qty":0.06693358}],"asks":[],"checksum":2235995132,"timestamp":"2024-06-01T17:52:53.442542Z"}]}
{"channel":"book","type":"update","data":[{"symbol":"ETH/USDT","bids":[{"price":3798.65,"qty":0.19729539}],"asks":[],"checksum":3416247231,"timestamp":"2024-06-01T17:52:53.482763Z"}]}
{"channel":"book","type":"update","data":[{"symbol":"ETH/USDT","bids":[],"asks":[{"price":3800.56,"qty":0.00000000},{"price":3800.94,"qty":0.84627249}],"checksum":4080371110,"timestamp":"2024-06-01T17:52:53.559999Z"}]}
{"channel":"book","type":"update","data":[{"symbol":"ETH/USDT","bids":[{"price":3799.15,"qty":2.04822332}],"asks":[],"checksum":3249031036,"timestamp":"2024-06-01T17:52:53.577267Z"}]}
{"channel":"book","type":"update","data":[{"symbol":"ETH/USDT","bids":[{"price":3799.33,"qty":0.73120000}],"asks":[],"checksum":1104693939,"timestamp":"2024-06-01T17:52:53.578100Z"}]}
{"channel":"book","type":"update","data":[{"symbol":"ETH/USDT","bids":[{"price":3799.35,"qty":0.73120000}],"asks":[],"checksum":3248155619,"timestamp":"2024-06-01T17:52:53.578676Z"}]}
{"channel":"book","type":"update","data":[{"symbol":"ETH/USDT","bids":[],"asks":[{"price":3799.77,"qty":0.00000000},{"price":3801.01,"qty":0.06693358}],"checksum":3470148817,"timestamp":"2024-06-01T17:52:53.579375Z"}]}
{"channel":"book","type":"update","data":[{"symbol":"ETH/USDT","bids":[{"price":3799.13,"qty":0.25000000}],"asks":[],"checksum":1454032568,"timestamp":"2024-06-01T17:52:53.580824Z"}]}
{"channel":"book","type":"update","data":[{"symbol":"ETH/USDT","bids":[{"price":3799.16,"qty":0.34000000}],"asks":[],"checksum":1343146969,"timestamp":"2024-06-01T17:52:53.580854Z"}]}
{"channel":"book","type":"update","data":[{"symbol":"ETH/USDT","bids":[],"asks":[{"price":3800.27,"qty":0.00000000},{"price":3801.13,"qty":0.41805062}],"checksum":845020674,"timestamp":"2024-06-01T17:52:53.581557Z"}]}
{"channel":"book","type":"update","data":[{"symbol":"ETH/USDT","bids":[{"price":3799.35,"qty":1.46240000}],"asks":[],"checksum":3622243835,"timestamp":"2024-06-01T17:52:53.582220Z"}]}
{"channel":"book","type":"update","data":[{"symbol":"ETH/USDT","bids":[{"price":3799.15,"qty":1.31702332}],"asks":[],"checksum":3084710199,"timestamp":"2024-06-01T17:52:53.582539Z"}]}
{"channel":"book","type":"update","data":[{"symbol":"ETH/USDT","bids":[{"price":3799.35,"qty":0.73120000}],"asks":[],"checksum":1382417102,"timestamp":"2024-06-01T17:52:53.582612Z"}]}
{"channel":"book","type":"update","data":[{"symbol":"ETH/USDT","bids":[{"price":3799.33,"qty":0.00000000},{"price":3798.46,"qty":0.84627249}],"asks":[],"checksum":893876888,"timestamp":"2024-06-01T17:52:53.583017Z"}]}
{"channel":"book","type":"update","data":[{"symbol":"ETH/USDT","bids":[],"asks":[{"price":3800.13,"qty":0.00000000},{"price":3801.14,"qty":39.01967070}],"checksum":1170021081,"timestamp":"2024-06-01T17:52:53.584237Z"}]}
{"channel":"book","type":"update","data":[{"symbol":"ETH/USDT","bids":[{"price":3799.40,"qty":0.73120000}],"asks":[],"checksum":256439426,"timestamp":"2024-06-01T17:52:53.585902Z"}]}
{"channel":"book","type":"update","data":[{"symbol":"ETH/USDT","bids":[{"price":3799.35,"qty":1.46240000}],"asks":[],"checksum":2860888032,"timestamp":"2024-06-01T17:52:53.586333Z"}]}
{"channel":"book","type":"update","data":[{"symbol":"ETH/USDT","bids":[],"asks":[{"price":3800.16,"qty":0.73120000}],"checksum":3256514326,"timestamp":"2024-06-01T17:52:53.586512Z"}]}
{"channel":"book","type":"update","data":[{"symbol":"ETH/USDT","bids":[{"price":3798.74,"qty":7.79800000}],"asks":[],"checksum":3587240407,"timestamp":"2024-06-01T17:52:53.586525Z"}]}
{"channel":"book","type":"update","data":[{"symbol":"ETH/USDT","bids":[{"price":3799.35,"qty":0.73120000}],"asks":[],"checksum":1525251217,"timestamp":"2024-06-01T17:52:53.586622Z"}]}
{"channel":"book","type":"update","data":[{"symbol":"ETH/USDT","bids":[],"asks":[{"price":3799.78,"qty":0.00000000},{"price":3801.14,"qty":39.01967070}],"checksum":1188825125,"timestamp":"2024-06-01T17:52:53.589664Z"}]}
{"channel":"book","type":"update","data":[{"symbol":"ETH/USDT","bids":[{"price":3799.36,"qty":1.31702332}],"asks":[],"checksum":897291817,"timestamp":"2024-06-01T17:52:53.589955Z"}]}
{"channel":"book","type":"update","data":[{"symbol":"ETH/USDT","bids":[{"price":3799.35,"qty":0.00000000},{"price":3798.55,"qty":0.73120000}],"asks":[],"checksum":3309049392,"timestamp":"2024-06-01T17:52:53.590174Z"}]}
{"channel":"book","type":"update","data":[{"symbol":"ETH/USDT","bids":[],"asks":[{"price":3800.16,"qty":0.00000000},{"price":3801.15,"qty":0.73120000}],"checksum":1190550618,"timestamp":"2024-06-01T17:52:53.590534Z"}]}
{"channel":"book","type":"update","data":[{"symbol":"ETH/USDT","bids":[{"price":3799.15,"qty":0.00000000},{"price":3798.46,"qty":0.84627249}],"asks":[],"checksum":2362864900,"timestamp":"2024-06-01T17:52:53.591320Z"}]}
{"channel":"book","type":"update","data":[{"symbol":"ETH/USDT","bids":[],"asks":[{"price":3800.45,"qty":0.34000000}],"checksum":575782768,"timestamp":"2024-06-01T17:52:53.593413Z"}]}
{"channel":"book","type":"update","data":[{"symbol":"ETH/USDT","bids":[],"asks":[{"price":3800.17,"qty":2.63360719}],"checksum":3337062955,"timestamp":"2024-06-01T17:52:53.595962Z"}]}
