{"channel":"book","type":"update","data":[{"symbol":"ETH/USD","bids":[],"asks":[{"price":3795.60,"qty":26.34630079}],"checksum":1955930186,"timestamp":"2024-06-01T17:52:36.872937Z"}]}
{"channel":"book","type":"update","data":[{"symbol":"ETH/USD","bids":[],"asks":[{"price":3795.55,"qty":3.00000000}],"checksum":2219365840,"timestamp":"2024-06-01T17:52:36.883217Z"}]}
{"channel":"book","type":"update","data":[{"symbol":"ETH/USD","bids":[{"price":3794.70,"qty":26.35250562}],"asks":[],"checksum":1193499715,"timestamp":"2024-06-01T17:52:36.883979Z"}]}
{"channel":"book","type":"update","data":[{"symbol":"ETH/USD","bids":[{"price":3794.70,"qty":0.00000000},{"price":3794.53,"qty":3.00000000}],"asks":[],"checksum":2219365840,"timestamp":"2024-06-01T17:52:36.889839Z"}]}
{"channel":"book","type":"update","data":[{"symbol":"ETH/USD","bids":[{"price":3794.56,"qty":0.00000000},{"price":3794.52,"qty":0.05759107}],"asks":[],"checksum":2329009232,"timestamp":"2024-06-01T17:52:36.901070Z"}]}
{"channel":"book","type":"update","data":[{"symbol":"ETH/USD","bids":[{"price":3794.87,"qty":0.00000000},{"price":3794.23,"qty":0.77955047}],"asks":[],"checksum":4026683479,"timestamp":"2024-06-01T17:52:36.982377Z"}]}
{"channel":"book","type":"update","data":[{"symbol":"ETH/USD","bids":[{"price":3794.54,"qty":0.00000000},{"price":3794.22,"qty":26.35583514}],"asks":[],"checksum":3352457364,"timestamp":"2024-06-01T17:52:36.985139Z"}]}
{"channel":"book","type":"update","data":[{"symbol":"ETH/USD","bids":[{"price":3794.88,"qty":0.00000000},{"price":3794.14,"qty":3.00000000}],"asks":[],"checksum":499759356,"timestamp":"2024-06-01T17:52:36.986816Z"}]}
{"channel":"book","type":"update","data":[{"symbol":"ETH/USD","bids":[{"price":3794.44,"qty":3.95207972}],"asks":[],"checksum":1991970820,"timestamp":"2024-06-01T17:52:36.990983Z"}]}
{"channel":"book","type":"update","data":[{"symbol":"ETH/USD","bids":[{"price":3794.69,"qty":7.35552010}],"asks":[],"checksum":3811860971,"timestamp":"2024-06-01T17:52:36.994067Z"}]}
{"channel":"book","type":"update","data":[{"symbol":"ETH/USD","bids":[{"price":3794.76,"qty":0.77000000}],"asks":[],"checksum":370683508,"timestamp":"2024-06-01T17:52:37.005088Z"}]}
{"channel":"book","type":"update","data":[{"symbol":"ETH/USD","bids":[],"asks":[{"price":3795.55,"qty":0.00000000},{"price":3796.30,"qty":3.30000000}],"checksum":3901366765,"timestamp":"2024-06-01T17:52:37.161095Z"}]}
{"channel":"book","type":"update","data":[{"symbol":"ETH/USD","bids":[],"asks":[{"price":3795.46,"qty":0.00000000},{"price":3796.34,"qty":0.72912968},{"price":3795.33,"qty":0.77000000}],"checksum":2415174951,"timestamp":"2024-06-01T17:52:37.285762Z"}]}
{"channel":"book","type":"update","data":[{"symbol":"ETH/USD","bids":[{"price":3794.48,"qty":0.84574642}],"asks":[],"checksum":3801331727,"timestamp":"2024-06-01T17:52:37.291874Z"}]}
{"channel":"book","type":"update","data":[{"symbol":"ETH/USD","bids":[{"price":3794.67,"qty":26.35268710}],"asks":[],"checksum":4109552737,"timestamp":"2024-06-01T17:52:37.349877Z"}]}
{"channel":"book","type":"update","data":[{"symbol":"ETH/USD","bids":[{"price":3795.15,"qty":0.00000000},{"price":3794.44,"qty":3.95207972}],"asks":[],"checksum":1053749174,"timestamp":"2024-06-01T17:52:37.361992Z"}]}
{"channel":"book","type":"update","data":[{"symbol":"ETH/USD","bids":[],"asks":[{"price":3795.55,"qty":3.00000000}],"checksum":250756582,"timestamp":"2024-06-01T17:52:37.365517Z"}]}
{"channel":"book","type":"update","data":[{"symbol":"ETH/USD","bids":[{"price":3794.67,"qty":0.00000000},{"price":3794.36,"qty":26.35487304}],"asks":[],"checksum":3862289320,"timestamp":"2024-06-01T17:52:37.368269Z"}]}
{"channel":"book","type":"update","data":[{"symbol":"ETH/USD","bids":[],"asks":[{"price":3795.21,"qty":0.00000000},{"price":3796.30,"qty":3.30000000}],"checksum":2724373849,"timestamp":"2024-06-01T17:52:37.381603Z"}]}
{"channel":"book","type":"update","data":[{"symbol":"ETH/USD","bids":[],"asks":[{"price":3795.55,"qty":0.00000000},{"price":3796.34,"qty":0.72912968}],"checksum":2376256284,"timestamp":"2024-06-01T17:52:37.400352Z"}]}
{"channel":"book","type":"update","data":[{"symbol":"ETH/USD","bids":[{"price":3794.68,"qty":26.35265382}],"asks":[],"checksum":4016808303,"timestamp":"2024-06-01T17:52:37.400979Z"}]}
{"channel":"book","type":"update","data":[{"symbol":"ETH/USD","bids":[{"price":3795.16,"qty":0.00000000},{"price":3794.36,"qty":26.35487304},{"price":3794.77,"qty":0.00937117}],"asks":[],"checksum":4244842099,"timestamp":"2024-06-01T17:52:37.423975Z"}]}
{"channel":"book","type":"update","data":[{"symbol":"ETH/USD","bids":[],"asks":[{"price":3795.53,"qty":0.00000000},{"price":3796.53,"qty":0.06693358}],"checksum":1639198022,"timestamp":"2024-06-01T17:52:37.427381Z"}]}
{"channel":"book","type":"update","data":[{"symbol":"ETH/USD","bids":[],"asks":[{"price":3795.17,"qty":26.34928079}],"checksum":744508776,"timestamp":"2024-06-01T17:52:37.429106Z"}]}
{"channel":"book","type":"update","data":[{"symbol":"ETH/USD","bids":[{"price":3794.78,"qty":3.95207972}],"asks":[],"checksum":2829873811,"timestamp":"2024-06-01T17:52:37.433130Z"}]}
{"channel":"book","type":"update","data":[{"symbol":"ETH/USD","bids":[],"asks":[{"price":3795.04,"qty":26.35022025}],"checksum":3955782356,"timestamp":"2024-06-01T17:52:37.433809Z"}]}
{"channel":"book","type":"update","data":[{"symbol":"ETH/USD","bids":[{"price":3794.48,"qty":0.00000000},{"price":3794.44,"qty":3.95207972}],"asks":[],"checksum":4038212656,"timestamp":"2024-06-01T17:52:37.434811Z"}]}
{"channel":"book","type":"update","data":[{"symbol":"ETH/USD","bids":[],"asks":[{"price":3795.17,"qty":0.00000000},{"price":3796.53,"qty":0.06693358}],"checksum":255525930,"timestamp":"2024-06-01T17:52:37.435696Z"}]}
{"channel":"book","type":"update","data":[{"symbol":"ETH/USD","bids":[{"price":3794.44,"qty":0.00000000},{"price":3794.36,"qty":26.35487304}],"asks":[],"checksum":4217651944,"timestamp":"2024-06-01T17:52:37.436775Z"}]}
{"channel":"book","type":"update","data":[{"symbol":"ETH/USD","bids":[{"price":3794.79,"qty":3.00000000}],"asks":[],"checksum":560129437,"timestamp":"2024-06-01T17:52:37.436926Z"}]}
{"channel":"book","type":"update","data":[{"symbol":"ETH/USD","bids":[],"asks":[{"price":3795.16,"qty":26.34935022}],"checksum":1591595827,"timestamp":"2024-06-01T17:52:37.439835Z"}]}
{"channel":"book","type":"update","data":[{"symbol":"ETH/USD","bids":[{"price":3794.79,"qty":0.00000000},{"price":3794.36,"qty":26.35487304}],"asks":[],"checksum":3396694833,"timestamp":"2024-06-01T17:52:37.481572Z"}]}
{"channel":"book","type":"update","data":[{"symbol":"ETH/USD","bids":[],"asks":[{"price":3795.16,"qty":0.00000000},{"price":3796.53,"qty":0.06693358}],"checksum":4217651944,"timestamp":"2024-06-01T17:52:37.517956Z"}]}
{"channel":"book","type":"update","data":[{"symbol":"ETH/USD","bids":[{"price":3794.68,"qty":0.00000000},{"price":3794.23,"qty":0.77955047}],"asks":[],"checksum":44463342,"timestamp":"2024-06-01T17:52:37.518039Z"}]}
{"channel":"book","type":"update","data":[{"symbol":"ETH/USD","bids":[{"price":3794.66,"qty":26.35279088}],"asks":[],"checksum":547073397,"timestamp":"2024-06-01T17:52:37.522916Z"}]}
{"channel":"book","type":"update","data":[{"symbol":"ETH/USD","bids":[],"asks":[{"price":3795.00,"qty":26.35052391}],"checksum":3892906775,"timestamp":"2024-06-01T17:52:37.522932Z"}]}
{"channel":"book","type":"update","data":[{"symbol":"ETH/USD","bids":[{"price":3794.79,"qty":0.84574642}],"asks":[],"checksum":2100451674,"timestamp":"2024-06-01T17:52:37.523769Z"}]}
{"channel":"book","type":"update","data":[{"symbol":"ETH/USD","bids":[],"asks":[{"price":3795.26,"qty":0.81183460}],"checksum":1434786757,"timestamp":"2024-06-01T17:52:37.539477Z"}]}
{"channel":"book","type":"update","data":[{"symbol":"ETH/USD","bids":[{"price":3794.80,"qty":1.00000000}],"asks":[],"checksum":364211881,"timestamp":"2024-06-01T17:52:37.600848Z"}]}
{"channel":"book","type":"update","data":[{"symbol":"ETH/USD","bids":[{"price":3794.81,"qty":5.70000000}],"asks":[],"checksum":2287330898,"timestamp":"2024-06-01T17:52:37.630219Z"}]}
{"channel":"book","type":"update","data":[{"symbol":"ETH/USD","bids":[{"price":3794.77,"qty":0.00000000},{"price":3794.53,"qty":3.00000000},{"price":3794.82,"qty":0.00937104}],"asks":[],"checksum":2535049113,"timestamp":"2024-06-01T17:52:37.681744Z"}]}
{"channel":"book","type":"update","data":[{"symbol":"ETH/USD","bids":[{"price":3794.81,"qty":0.00000000},{"price":3794.53,"qty":3.00000000}],"asks":[],"checksum":313086093,"timestamp":"2024-06-01T17:52:37.713272Z"}]}
{"channel":"book","type":"update","data":[{"symbol":"ETH/USD","bids":[{"price":3794.82,"qty":0.00000000},{"price":3794.52,"qty":0.05759107},{"price":3794.81,"qty":0.00937107}],"asks":[],"checksum":259878651,"timestamp":"2024-06-01T17:52:37.757227Z"}]}
{"channel":"book","type":"update","data":[{"symbol":"ETH/USD","bids":[{"price":3794.82,"qty":0.34420830}],"asks":[],"checksum":2794728905,"timestamp":"2024-06-01T17:52:37.799104Z"}]}
{"channel":"book","type":"update","data":[{"symbol":"ETH/USD","bids":[{"price":3794.76,"qty":0.00000000},{"price":3794.53,"qty":3.00000000}],"asks":[],"checksum":4214842888,"timestamp":"2024-06-01T17:52:37.813632Z"}]}
{"channel":"book","type":"update","data":[{"symbol":"ETH/USD","bids":[{"price":3794.69,"qty":3.95191312}],"asks":[],"checksum":193957736,"timestamp":"2024-06-01T17:52:37.828487Z"}]}
{"channel":"book","type":"update","data":[{"symbol":"ETH/USD","bids":[{"price":3794.66,"qty":0.00000000},{"price":3794.52,"qty":0.05759107}],"asks":[],"checksum":3729229809,"timestamp":"2024-06-01T17:52:37.841630Z"}]}
{"channel":"book","type":"update","data":[{"symbol":"ETH/USD","bids":[],"asks":[{"price":3795.00,"qty":0.00000000},{"price":3796.34,"qty":0.72912968}],"checksum":2894508904,"timestamp":"2024-06-01T17:52:37.841718Z"}]}
{"channel":"book","type":"update","data":[{"symbol":"ETH/USD","bids":[{"price":3794.55,"qty":0.00000000},{"price":3794.36,"qty":26.35487304},{"price":3794.54,"qty":3.94900000}],"asks":[],"checksum":554585738,"timestamp":"2024-06-01T17:52:37.844763Z"}]}
{"channel":"book","type":"update","data":[{"symbol":"ETH/USD","bids":[{"price":3794.53,"qty":0.00000000},{"price":3794.36,"qty":26.35487304}],"asks":[],"checksum":1792819974,"timestamp":"2024-06-01T17:52:37.845059Z"}]}
{"channel":"book","type":"update","data":[{"symbol":"ETH/USD","bids":[],"asks":[{"price":3795.04,"qty":0.00000000},{"price":3796.53,"qty":0.06693358}],"checksum":606815019,"timestamp":"2024-06-01T17:52:37.848726Z"}]}
{"channel":"book","type":"update","data":[{"symbol":"ETH/USD","bids":[],"asks":[{"price":3795.27,"qty":0.00000000},{"price":3796.55,"qty":10.81226191}],"checksum":3377904776,"timestamp":"2024-06-01T17:52:37.853889Z"}]}
{"channel":"book","type":"update","data":[{"symbol":"ETH/USD","bids":[],"asks":[{"price":3795.26,"qty":1.33880771}],"checksum":4248918387,"timestamp":"2024-06-01T17:52:37.854510Z"}]}
{"channel":"book","type":"update","data":[{"symbol":"ETH/USD","bids":[],"asks":[{"price":3795.26,"qty":0.81183460}],"checksum":3377904776,"timestamp":"2024-06-01T17:52:37.858820Z"}]}
{"channel":"book","type":"update","data":[{"symbol":"ETH/USD","bids":[],"asks":[{"price":3795.25,"qty":26.34872538}],"checksum":279192866,"timestamp":"2024-06-01T17:52:37.858917Z"}]}
{"channel":"book","type":"update","data":[{"symbol":"ETH/USD","bids":[],"asks":[{"price":3794.94,"qty":26.35092138}],"checksum":2516154192,"timestamp":"2024-06-01T17:52:37.858975Z"}]}
{"channel":"book","type":"update","data":[{"symbol":"ETH/USD","bids":[],"asks":[{"price":3795.25,"qty":52.69745076}],"checksum":534739823,"timestamp":"2024-06-01T17:52:37.859115Z"}]}
{"channel":"book","type":"update","data":[{"symbol":"ETH/USD","bids":[{"price":3794.54,"qty":30.30265162}],"asks":[],"checksum":512188949,"timestamp":"2024-06-01T17:52:37.859142Z"}]}
{"channel":"book","type":"update","data":[{"symbol":"ETH/USD","bids":[{"price":3794.60,"qty":26.35320867}],"asks":[],"checksum":361535268,"timestamp":"2024-06-01T17:52:37.859167Z"}]}
{"channel":"book","type":"update","data":[{"symbol":"ETH/USD","bids":[],"asks":[{"price":3795.25,"qty":55.09745076}],"checksum":825572370,"timestamp":"2024-06-01T17:52:37.861569Z"}]}
{"channel":"book","type":"update","data":[{"symbol":"ETH/USD","bids":[],"asks":[{"price":3795.25,"qty":28.74872538}],"checksum":1192583960,"timestamp":"2024-06-01T17:52:37.866677Z"}]}
{"channel":"book","type":"update","data":[{"symbol":"ETH/USD","bids":[],"asks":[{"price":3795.25,"qty":2.40000000}],"checksum":1398336712,"timestamp":"2024-06-01T17:52:37.867103Z"}]}
{"channel":"book","type":"update","data":[{"symbol":"ETH/USD","bids":[{"price":3794.69,"qty":4.72191312}],"asks":[],"checksum":453294442,"timestamp":"2024-06-01T17:52:37.933359Z"}]}
{"channel":"book","type":"update","data":[{"symbol":"ETH/USD","bids":[],"asks":[{"price":3795.25,"qty":0.00000000},{"price":3796.53,"qty":0.06693358}],"checksum":3832940660,"timestamp":"2024-06-01T17:52:37.944251Z"}]}
{"channel":"book","type":"update","data":[{"symbol":"ETH/USD","bids":[],"asks":[{"price":3795.78,"qty":0.00000000},{"price":3796.55,"qty":10.81226191}],"checksum":1452051902,"timestamp":"2024-06-01T17:52:37.951152Z"}]}
{"channel":"book","type":"update","data":[{"symbol":"ETH/USD","bids":[{"price":3794.55,"qty":3.40373255}],"asks":[],"checksum":4133878199,"timestamp":"2024-06-01T17:52:37.958403Z"}]}
{"channel":"book","type":"update","data":[{"symbol":"ETH/USD","bids":[],"asks":[{"price":3795.33,"qty":0.00000000},{"price":3796.65,"qty":3.00000000}],"checksum":1888563247,"timestamp":"2024-06-01T17:52:37.961528Z"}]}
{"channel":"book","type":"update","data":[{"symbol":"ETH/USD","bids":[{"price":3794.69,"qty":3.95191312},{"price":3794.84,"qty":0.77000000}],"asks":[],"checksum":1547426998,"timestamp":"2024-06-01T17:52:37.965731Z"}]}
{"channel":"book","type":"update","data":[{"symbol":"ETH/USD","bids":[{"price":3794.85,"qty":3.00000000}],"asks":[],"checksum":3030516052,"timestamp":"2024-06-01T17:52:37.967777Z"}]}
{"channel":"book","type":"update","data":[{"symbol":"ETH/USD","bids":[{"price":3794.84,"qty":3.77000000}],"asks":[],"checksum":1095132415,"timestamp":"2024-06-01T17:52:37.968139Z"}]}
{"channel":"book","type":"update","data":[{"symbol":"ETH/USD","bids":[],"asks":[{"price":3796.55,"qty":0.00000000},{"price":3796.67,"qty":0.52697311}],"checksum":3841700858,"timestamp":"2024-06-01T17:52:37.968884Z"}]}
{"channel":"book","type":"update","data":[{"symbol":"ETH/USD","bids":[],"asks":[{"price":3796.14,"qty":0.00000000},{"price":3796.70,"qty":4.30610000}],"checksum":1129414721,"timestamp":"2024-06-01T17:52:37.970418Z"}]}
{"channel":"book","type":"update","data":[{"symbol":"ETH/USD","bids":[],"asks":[{"price":3795.26,"qty":0.00000000},{"price":3796.71,"qty":26.33862449}],"checksum":4275834917,"timestamp":"2024-06-01T17:52:37.971027Z"}]}
{"channel":"book","type":"update","data":[{"symbol":"ETH/USD","bids":[{"price":3794.85,"qty":6.00000000}],"asks":[],"checksum":4279566809,"timestamp":"2024-06-01T17:52:37.971280Z"}]}
{"channel":"book","type":"update","data":[{"symbol":"ETH/USD","bids":[{"price":3794.84,"qty":0.77000000}],"asks":[],"checksum":3973527334,"timestamp":"2024-06-01T17:52:37.971762Z"}]}
{"channel":"book","type":"update","data":[{"symbol":"ETH/USD","bids":[{"price":3794.84,"qty":0.00000000},{"price":3794.55,"qty":3.40373255}],"asks":[],"checksum":301178505,"timestamp":"2024-06-01T17:52:37.972127Z"}]}
{"channel":"book","type":"update","data":[{"symbol":"ETH/USD","bids":[],"asks":[{"price":3795.88,"qty":0.00000000},{"price":3796.87,"qty":10.43462302}],"checksum":2409150409,"timestamp":"2024-06-01T17:52:37.972979Z"}]}
{"channel":"book","type":"update","data":[{"symbol":"ETH/USD","bids":[],"asks":[{"price":3796.34,"qty":0.00000000},{"price":3796.95,"qty":0.41184735}],"checksum":3896760883,"timestamp":"2024-06-01T17:52:37.976556Z"}]}
{"channel":"book","type":"update","data":[{"symbol":"ETH/USD","bids":[],"asks":[{"price":3796.65,"qty":0.00000000},{"price":3796.99,"qty":14.57160749}],"checksum":117811477,"timestamp":"2024-06-01T17:52:37.979518Z"}]}
{"channel":"book","type":"update","data":[{"symbol":"ETH/USD","bids":[{"price":3794.62,"qty":0.00000000},{"price":3794.54,"qty":30.30265162},{"price":3794.81,"qty":5.28037107}],"asks":[],"checksum":523873652,"timestamp":"2024-06-01T17:52:37.981074Z"}]}
{"channel":"book","type":"update","data":[{"symbol":"ETH/USD","bids":[],"asks":[{"price":3794.94,"qty":0.00000000},{"price":3797.09,"qty":3.00000000}],"checksum":650876601,"timestamp":"2024-06-01T17:52:37.981803Z"}]}
{"channel":"book","type":"update","data":[{"symbol":"ETH/USD","bids":[{"price":3794.60,"qty":0.00000000},{"price":3794.52,"qty":0.05759107}],"asks":[],"checksum":1564199691,"timestamp":"2024-06-01T17:52:37.981945Z"}]}
{"channel":"book","type":"update","data":[{"symbol":"ETH/USD","bids":[],"asks":[{"price":3795.60,"qty":0.00000000},{"price":3797.34,"qty":10.81226191}],"checksum":2541166666,"timestamp":"2024-06-01T17:52:37.982008Z"}]}
{"channel":"book","type":"update","data":[{"symbol":"ETH/USD","bids":[{"price":3794.54,"qty":3.94900000}],"asks":[],"checksum":3817818990,"timestamp":"2024-06-01T17:52:37.982037Z"}]}
{"channel":"book","type":"update","data":[{"symbol":"ETH/USD","bids":[{"price":3794.81,"qty":31.62053487}],"asks":[],"checksum":1085215597,"timestamp":"2024-06-01T17:52:37.984743Z"}]}
{"channel":"book","type":"update","data":[{"symbol":"ETH/USD","bids":[{"price":3794.86,"qty":3.95220467}],"asks":[],"checksum":3744990927,"timestamp":"2024-06-01T17:52:37.985288Z"}]}
{"channel":"book","type":"update","data":[{"symbol":"ETH/USD","bids":[],"asks":[{"price":3796.71,"qty":0.00000000},{"price":3797.35,"qty":1.03800000}],"checksum":1400356562,"timestamp":"2024-06-01T17:52:37.985744Z"}]}
{"channel":"book","type":"update","data":[{"symbol":"ETH/USD","bids":[{"price":3795.59,"qty":0.77000000}],"asks":[],"checksum":1376992947,"timestamp":"2024-06-01T17:52:37.986056Z"}]}
{"channel":"book","type":"update","data":[{"symbol":"ETH/USD","bids":[{"price":3795.59,"qty":0.00000000},{"price":3794.54,"qty":3.94900000},{"price":3795.71,"qty":0.77000000}],"asks":[],"checksum":3631981515,"timestamp":"2024-06-01T17:52:37.986901Z"}]}
{"channel":"book","type":"update","data":[{"symbol":"ETH/USD","bids":[{"price":3794.78,"qty":0.00000000},{"price":3794.54,"qty":3.94900000}],"asks":[],"checksum":4288351695,"timestamp":"2024-06-01T17:52:37.988088Z"}]}
{"channel":"book","type":"update","data":[{"symbol":"ETH/USD","bids":[],"asks":[{"price":3796.94,"qty":0.81183460}],"checksum":1679817426,"timestamp":"2024-06-01T17:52:37.988436Z"}]}
{"channel":"book","type":"update","data":[{"symbol":"ETH/USD","bids":[],"asks":[{"price":3797.34,"qty":0.00000000},{"price":3797.35,"qty":1.03800000}],"checksum":423476618,"timestamp":"2024-06-01T17:52:37.988713Z"}]}
{"channel":"book","type":"update","data":[{"symbol":"ETH/USD","bids":[{"price":3795.04,"qty":3.00000000}],"asks":[],"checksum":3431414421,"timestamp":"2024-06-01T17:52:37.989569Z"}]}
{"channel":"book","type":"update","data":[{"symbol":"ETH/USD","bids":[{"price":3795.23,"qty":3.00000000}],"asks":[],"checksum":3106298049,"timestamp":"2024-06-01T17:52:37.990021Z"}]}
{"channel":"book","type":"update","data":[{"symbol":"ETH/USD","bids":[{"price":3794.85,"qty":3.00000000}],"asks":[],"checksum":2795954119,"timestamp":"2024-06-01T17:52:37.990379Z"}]}
{"channel":"book","type":"update","data":[{"symbol":"ETH/USD","bids":[{"price":3795.72,"qty":3.00000000}],"asks":[],"checksum":472334832,"timestamp":"2024-06-01T17:52:37.990566Z"}]}
{"channel":"book","type":"update","data":[{"symbol":"ETH/USD","bids":[{"price":3795.77,"qty":3.00000000}],"asks":[],"checksum":532413742,"timestamp":"2024-06-01T17:52:37.990650Z"}]}
{"channel":"book","type":"update","data":[{"symbol":"ETH/USD","bids":[{"price":3795.71,"qty":0.00000000},{"price":3794.79,"qty":0.84574642},{"price":3795.60,"qty":0.77000000}],"asks":[],"checksum":581646343,"timestamp":"2024-06-01T17:52:37.995700Z"}]}
{"channel":"book","type":"update","data":[{"symbol":"ETH/USD","bids":[],"asks":[{"price":3795.78,"qty":0.09000000}],"checksum":1051056178,"timestamp":"2024-06-01T17:52:38.002311Z"}]}
{"channel":"book","type":"update","data":[{"symbol":"ETH/USD","bids":[],"asks":[{"price":3796.30,"qty":0.00000000},{"price":3797.35,"qty":1.03800000}],"checksum":2640221761,"timestamp":"2024-06-01T17:52:38.004849Z"}]}
{"channel":"book","type":"update","data":[{"symbol":"ETH/USD","bids":[{"price":3795.60,"qty":0.00000000},{"price":3794.79,"qty":0.84574642},{"price":3795.72,"qty":3.77000000}],"asks":[],"checksum":4048504310,"timestamp":"2024-06-01T17:52:38.005158Z"}]}
{"channel":"book","type":"update","data":[{"symbol":"ETH/USD","bids":[{"price":3794.81,"qty":31.61116380},{"price":3794.83,"qty":0.00937102}],"asks":[],"checksum":967859183,"timestamp":"2024-06-01T17:52:38.010910Z"}]}
{"channel":"book","type":"update","data":[{"symbol":"ETH/USD","bids":[{"price":3795.77,"qty":16.16663683}],"asks":[],"checksum":716266829,"timestamp":"2024-06-01T17:52:38.011850Z"}]}
{"channel":"book","type":"update","data":[{"symbol":"ETH/USD","bids":[],"asks":[{"price":3796.18,"qty":26.34228008}],"checksum":1074715247,"timestamp":"2024-06-01T17:52:38.013449Z"}]}
{"channel":"book","type":"update","data":[{"symbol":"ETH/USD","bids":[{"price":3795.73,"qty":26.34533681}],"asks":[],"checksum":3057597748,"timestamp":"2024-06-01T17:52:38.013500Z"}]}
{"channel":"book","type":"update","data":[{"symbol":"ETH/USD","bids":[],"asks":[{"price":3796.40,"qty":26.34080223}],"checksum":3294388200,"timestamp":"2024-06-01T17:52:38.013516Z"}]}
{"channel":"book","type":"update","data":[{"symbol":"ETH/USD","bids":[{"price":3795.34,"qty":26.34805595}],"asks":[],"checksum":2794912200,"timestamp":"2024-06-01T17:52:38.013766Z"}]}
{"channel":"book","type":"update","data":[{"symbol":"ETH/USD","bids":[],"asks":[{"price":3796.53,"qty":0.00000000},{"price":3797.09,"qty":3.00000000}],"checksum":372522151,"timestamp":"2024-06-01T17:52:38.017792Z"}]}
{"channel":"book","type":"update","data":[{"symbol":"ETH/USD","bids":[],"asks":[{"price":3796.29,"qty":5.41000000}],"checksum":3240535232,"timestamp":"2024-06-01T17:52:38.026769Z"}]}
{"channel":"book","type":"update","data":[{"symbol":"ETH/USD","bids":[{"price":3795.73,"qty":0.00000000},{"price":3794.81,"qty":31.61116380}],"asks":[],"checksum":440456900,"timestamp":"2024-06-01T17:52:38.030850Z"}]}
{"channel":"book","type":"update","data":[{"symbol":"ETH/USD","bids":[],"asks":[{"price":3796.18,"qty":0.00000000},{"price":3797.09,"qty":3.00000000}],"checksum":25556384,"timestamp":"2024-06-01T17:52:38.030955Z"}]}
{"channel":"book","type":"update","data":[{"symbol":"ETH/USD","bids":[],"asks":[{"price":3796.40,"qty":0.00000000},{"price":3797.35,"qty":1.03800000}],"checksum":2088176717,"timestamp":"2024-06-01T17:52:38.031191Z"}]}
{"channel":"book","type":"update","data":[{"symbol":"ETH/USD","bids":[],"asks":[{"price":3796.87,"qty":0.00000000},{"price":3797.46,"qty":1.05328308},{"price":3797.45,"qty":10.43462302}],"checksum":715690717,"timestamp":"2024-06-01T17:52:38.035363Z"}]}
{"channel":"book","type":"update","data":[{"symbol":"ETH/USD","bids":[{"price":3794.93,"qty":0.72912968}],"asks":[],"checksum":1842409327,"timestamp":"2024-06-01T17:52:38.040001Z"}]}
{"channel":"book","type":"update","data":[{"symbol":"ETH/USD","bids":[],"asks":[{"price":3796.29,"qty":0.00000000},{"price":3797.46,"qty":1.05328308}],"checksum":3351350225,"timestamp":"2024-06-01T17:52:38.058048Z"}]}
{"channel":"book","type":"update","data":[{"symbol":"ETH/USD","bids":[{"price":3795.77,"qty":42.51175257}],"asks":[],"checksum":4267179140,"timestamp":"2024-06-01T17:52:38.066151Z"}]}
{"channel":"book","type":"update","data":[{"symbol":"ETH/USD","bids":[],"asks":[{"price":3796.25,"qty":26.34184316}],"checksum":1445006535,"timestamp":"2024-06-01T17:52:38.066167Z"}]}
{"channel":"book","type":"update","data":[{"symbol":"ETH/USD","bids":[{"price":3795.77,"qty":68.85686831}],"asks":[],"checksum":2387881141,"timestamp":"2024-06-01T17:52:38.066478Z"}]}
{"channel":"book","type":"update","data":[{"symbol":"ETH/USD","bids":[],"asks":[{"price":3796.25,"qty":0.00000000},{"price":3797.47,"qty":3.00000000}],"checksum":57521782,"timestamp":"2024-06-01T17:52:38.071240Z"}]}
{"channel":"book","type":"update","data":[{"symbol":"ETH/USD","bids":[{"price":3794.85,"qty":5.13800000}],"asks":[],"checksum":1396381810,"timestamp":"2024-06-01T17:52:38.089957Z"}]}
{"channel":"book","type":"update","data":[{"symbol":"ETH/USD","bids":[{"price":3795.35,"qty":0.77955047}],"asks":[],"checksum":976263219,"timestamp":"2024-06-01T17:52:38.090455Z"}]}
{"channel":"book","type":"update","data":[{"symbol":"ETH/USD","bids":[{"price":3795.77,"qty":69.85686831}],"asks":[],"checksum":1474862314,"timestamp":"2024-06-01T17:52:38.102490Z"}]}
{"channel":"book","type":"update","data":[{"symbol":"ETH/USD","bids":[],"asks":[{"price":3796.69,"qty":0.77000000}],"checksum":2501949564,"timestamp":"2024-06-01T17:52:38.104481Z"}]}
{"channel":"book","type":"update","data":[{"symbol":"ETH/USD","bids":[],"asks":[{"price":3797.22,"qty":0.72912968}],"checksum":3876837242,"timestamp":"2024-06-01T17:52:38.109622Z"}]}
{"channel":"book","type":"update","data":[{"symbol":"ETH/USD","bids":[],"asks":[{"price":3796.27,"qty":26.34166702}],"checksum":3264277943,"timestamp":"2024-06-01T17:52:38.126276Z"}]}
{"channel":"book","type":"update","data":[{"symbol":"ETH/USD","bids":[],"asks":[{"price":3795.78,"qty":0.00000000},{"price":3797.35,"qty":1.03800000}],"checksum":3296375972,"timestamp":"2024-06-01T17:52:38.132991Z"}]}
{"channel":"book","type":"update","data":[{"symbol":"ETH/USD","bids":[{"price":3795.77,"qty":43.51175257}],"asks":[],"checksum":470783190,"timestamp":"2024-06-01T17:52:38.142342Z"}]}
{"channel":"book","type":"update","data":[{"symbol":"ETH/USD","bids":[{"price":3795.86,"qty":26.34444760}],"asks":[],"checksum":1337191681,"timestamp":"2024-06-01T17:52:38.146911Z"}]}
{"channel":"book","type":"update","data":[{"symbol":"ETH/USD","bids":[{"price":3795.04,"qty":0.00000000},{"price":3794.83,"qty":0.00937102}],"asks":[],"checksum":1644589575,"timestamp":"2024-06-01T17:52:38.150584Z"}]}
{"channel":"book","type":"update","data":[{"symbol":"ETH/USD","bids":[{"price":3795.87,"qty":3.00000000}],"asks":[],"checksum":2359600996,"timestamp":"2024-06-01T17:52:38.150651Z"}]}
{"channel":"book","type":"update","data":[{"symbol":"ETH/USD","bids":[{"price":3795.87,"qty":0.00000000},{"price":3794.83,"qty":0.00937102}],"asks":[],"checksum":1644589575,"timestamp":"2024-06-01T17:52:38.175478Z"}]}
{"channel":"book","type":"update","data":[{"symbol":"ETH/USD","bids":[],"asks":[{"price":3797.35,"qty":0.00000000},{"price":3797.45,"qty":10.43462302}],"checksum":2819303376,"timestamp":"2024-06-01T17:52:38.178841Z"}]}
{"channel":"book","type":"update","data":[{"symbol":"ETH/USD","bids":[],"asks":[{"price":3796.27,"qty":0.00000000},{"price":3797.47,"qty":3.00000000}],"checksum":3658205482,"timestamp":"2024-06-01T17:52:38.182511Z"}]}
{"channel":"book","type":"update","data":[{"symbol":"ETH/USD","bids":[{"price":3795.86,"qty":0.00000000},{"price":3794.82,"qty":0.34420830}],"asks":[],"checksum":805845969,"timestamp":"2024-06-01T17:52:38.182544Z"}]}
{"channel":"book","type":"update","data":[{"symbol":"ETH/USD","bids":[],"asks":[{"price":3796.54,"qty":3.00000000}],"checksum":1357741127,"timestamp":"2024-06-01T17:52:38.186497Z"}]}
{"channel":"book","type":"update","data":[{"symbol":"ETH/USD","bids":[{"price":3795.77,"qty":17.16663683}],"asks":[],"checksum":3307858852,"timestamp":"2024-06-01T17:52:38.194220Z"}]}
{"channel":"book","type":"update","data":[{"symbol":"ETH/USD","bids":[],"asks":[{"price":3796.39,"qty":26.34084754}],"checksum":2384808289,"timestamp":"2024-06-01T17:52:38.198358Z"}]}
{"channel":"book","type":"update","data":[{"symbol":"ETH/USD","bids":[{"price":3795.87,"qty":26.34442170}],"asks":[],"checksum":3076399171,"timestamp":"2024-06-01T17:52:38.198423Z"}]}
{"channel":"book","type":"update","data":[{"symbol":"ETH/USD","bids":[],"asks":[{"price":3796.47,"qty":26.34025991}],"checksum":3168138513,"timestamp":"2024-06-01T17:52:38.198535Z"}]}
{"channel":"book","type":"update","data":[{"symbol":"ETH/USD","bids":[],"asks":[{"price":3796.67,"qty":26.86585054}],"checksum":4075495601,"timestamp":"2024-06-01T17:52:38.198575Z"}]}
{"channel":"book","type":"update","data":[{"symbol":"ETH/USD","bids":[{"price":3795.72,"qty":3.00000000}],"asks":[],"checksum":4218041827,"timestamp":"2024-06-01T17:52:38.200944Z"}]}
{"channel":"book","type":"update","data":[{"symbol":"ETH/USD","bids":[{"price":3795.77,"qty":14.16663683}],"asks":[],"checksum":2687013105,"timestamp":"2024-06-01T17:52:38.201467Z"}]}
{"channel":"book","type":"update","data":[{"symbol":"ETH/USD","bids":[{"price":3795.72,"qty":0.00000000},{"price":3794.82,"qty":0.34420830}],"asks":[],"checksum":1633243605,"timestamp":"2024-06-01T17:52:38.201657Z"}]}
{"channel":"book","type":"update","data":[{"symbol":"ETH/USD","bids":[{"price":3796.02,"qty":0.77000000}],"asks":[],"checksum":2830744400,"timestamp":"2024-06-01T17:52:38.204625Z"}]}
{"channel":"book","type":"update","data":[{"symbol":"ETH/USD","bids":[{"price":3795.56,"qty":0.84574642}],"asks":[],"checksum":1862148285,"timestamp":"2024-06-01T17:52:38.211113Z"}]}
{"channel":"book","type":"update","data":[{"symbol":"ETH/USD","bids":[{"price":3795.64,"qty":3.00000000}],"asks":[],"checksum":1373358583,"timestamp":"2024-06-01T17:52:38.212201Z"}]}
{"channel":"book","type":"update","data":[{"symbol":"ETH/USD","bids":[],"asks":[{"price":3796.39,"qty":26.43084754}],"checksum":4119295141,"timestamp":"2024-06-01T17:52:38.218362Z"}]}
{"channel":"book","type":"update","data":[{"symbol":"ETH/USD","bids":[],"asks":[{"price":3796.39,"qty":0.09000000}],"checksum":2538210246,"timestamp":"2024-06-01T17:52:38.219423Z"}]}
{"channel":"book","type":"update","data":[{"symbol":"ETH/USD","bids":[],"asks":[{"price":3796.95,"qty":0.00000000},{"price":3797.22,"qty":0.72912968}],"checksum":1998239032,"timestamp":"2024-06-01T17:52:38.239037Z"}]}
{"channel":"book","type":"update","data":[{"symbol":"ETH/USD","bids":[],"asks":[{"price":3796.69,"qty":0.00000000},{"price":3797.45,"qty":10.43462302}],"checksum":2586771097,"timestamp":"2024-06-01T17:52:38.258882Z"}]}
{"channel":"book","type":"update","data":[{"symbol":"ETH/USD","bids":[],"asks":[{"price":3796.41,"qty":26.34073956}],"checksum":2635636036,"timestamp":"2024-06-01T17:52:38.268652Z"}]}
{"channel":"book","type":"update","data":[{"symbol":"ETH/USD","bids":[{"price":3795.78,"qty":26.34504634}],"asks":[],"checksum":2680135412,"timestamp":"2024-06-01T17:52:38.268682Z"}]}
{"channel":"book","type":"update","data":[{"symbol":"ETH/USD","bids":[{"price":3795.53,"qty":3.40285372}],"asks":[],"checksum":3990398348,"timestamp":"2024-06-01T17:52:38.278917Z"}]}
{"channel":"book","type":"update","data":[{"symbol":"ETH/USD","bids":[],"asks":[{"price":3796.41,"qty":0.00000000},{"price":3797.45,"qty":10.43462302}],"checksum":234170634,"timestamp":"2024-06-01T17:52:38.294895Z"}]}
{"channel":"book","type":"update","data":[{"symbol":"ETH/USD","bids":[{"price":3795.87,"qty":0.00000000},{"price":3794.93,"qty":0.72912968}],"asks":[],"checksum":2016067452,"timestamp":"2024-06-01T17:52:38.356917Z"}]}
{"channel":"book","type":"update","data":[{"symbol":"ETH/USD","bids":[{"price":3795.51,"qty":26.34687750}],"asks":[],"checksum":2950038979,"timestamp":"2024-06-01T17:52:38.362109Z"}]}
{"channel":"book","type":"update","data":[{"symbol":"ETH/USD","bids":[],"asks":[{"price":3796.42,"qty":26.34063156}],"checksum":922994838,"timestamp":"2024-06-01T17:52:38.362123Z"}]}
{"channel":"book","type":"update","data":[{"symbol":"ETH/USD","bids":[{"price":3795.89,"qty":26.34422986}],"asks":[],"checksum":380539918,"timestamp":"2024-06-01T17:52:38.362343Z"}]}
{"channel":"book","type":"update","data":[{"symbol":"ETH/USD","bids":[],"asks":[{"price":3796.54,"qty":0.00000000},{"price":3797.45,"qty":10.43462302}],"checksum":3685442857,"timestamp":"2024-06-01T17:52:38.364895Z"}]}
{"channel":"book","type":"update","data":[{"symbol":"ETH/USD","bids":[],"asks":[{"price":3796.59,"qty":0.77000000}],"checksum":2898751349,"timestamp":"2024-06-01T17:52:38.376335Z"}]}
{"channel":"book","type":"update","data":[{"symbol":"ETH/USD","bids":[{"price":3796.03,"qty":0.00936847}],"asks":[],"checksum":823275932,"timestamp":"2024-06-01T17:52:38.388771Z"}]}
{"channel":"book","type":"update","data":[{"symbol":"ETH/USD","bids":[{"price":3795.35,"qty":0.00000000},{"price":3795.34,"qty":26.34805595}],"asks":[],"checksum":2500401206,"timestamp":"2024-06-01T17:52:38.392325Z"}]}
{"channel":"book","type":"update","data":[{"symbol":"ETH/USD","bids":[],"asks":[{"price":3796.41,"qty":1.40000000}],"checksum":2078625549,"timestamp":"2024-06-01T17:52:38.396528Z"}]}
{"channel":"book","type":"update","data":[{"symbol":"ETH/USD","bids":[{"price":3795.51,"qty":0.00000000},{"price":3795.23,"qty":3.00000000}],"asks":[],"checksum":2428827741,"timestamp":"2024-06-01T17:52:38.411125Z"}]}
{"channel":"book","type":"update","data":[{"symbol":"ETH/USD","bids":[],"asks":[{"price":3796.42,"qty":0.00000000},{"price":3797.22,"qty":0.72912968}],"checksum":2705503821,"timestamp":"2024-06-01T17:52:38.413853Z"}]}
{"channel":"book","type":"update","data":[{"symbol":"ETH/USD","bids":[{"price":3796.02,"qty":27.11333456}],"asks":[],"checksum":2682361205,"timestamp":"2024-06-01T17:52:38.418677Z"}]}
{"channel":"book","type":"update","data":[{"symbol":"ETH/USD","bids":[],"asks":[{"price":3796.46,"qty":26.34038543}],"checksum":1231230108,"timestamp":"2024-06-01T17:52:38.418732Z"}]}
{"channel":"book","type":"update","data":[{"symbol":"ETH/USD","bids":[],"asks":[{"price":3796.46,"qty":0.00000000},{"price":3797.22,"qty":0.72912968}],"checksum":2682361205,"timestamp":"2024-06-01T17:52:38.474518Z"}]}
{"channel":"book","type":"update","data":[{"symbol":"ETH/USD","bids":[{"price":3795.77,"qty":13.16663683}],"asks":[],"checksum":3264934233,"timestamp":"2024-06-01T17:52:38.478550Z"}]}
{"channel":"book","type":"update","data":[{"symbol":"ETH/USD","bids":[],"asks":[{"price":3796.45,"qty":26.34044075}],"checksum":1585883164,"timestamp":"2024-06-01T17:52:38.479197Z"}]}
{"channel":"book","type":"update","data":[{"symbol":"ETH/USD","bids":[{"price":3795.90,"qty":0.82846651}],"asks":[],"checksum":787436474,"timestamp":"2024-06-01T17:52:38.494167Z"}]}
{"channel":"book","type":"update","data":[{"symbol":"ETH/USD","bids":[],"asks":[{"price":3796.45,"qty":0.00000000},{"price":3797.22,"qty":0.72912968}],"checksum":1001439102,"timestamp":"2024-06-01T17:52:38.501978Z"}]}
{"channel":"book","type":"update","data":[{"symbol":"ETH/USD","bids":[{"price":3796.02,"qty":0.77000000}],"asks":[],"checksum":4142161049,"timestamp":"2024-06-01T17:52:38.549880Z"}]}
{"channel":"book","type":"update","data":[{"symbol":"ETH/USD","bids":[{"price":3795.91,"qty":3.95220467}],"asks":[],"checksum":3235226205,"timestamp":"2024-06-01T17:52:38.553980Z"}]}
{"channel":"book","type":"update","data":[{"symbol":"ETH/USD","bids":[{"price":3796.03,"qty":1.00936847}],"asks":[],"checksum":1496372096,"timestamp":"2024-06-01T17:52:38.554112Z"}]}
{"channel":"book","type":"update","data":[{"symbol":"ETH/USD","bids":[{"price":3796.00,"qty":26.34351107}],"asks":[],"checksum":1795054275,"timestamp":"2024-06-01T17:52:38.554922Z"}]}
{"channel":"book","type":"update","data":[{"symbol":"ETH/USD","bids":[{"price":3795.72,"qty":3.95220467}],"asks":[],"checksum":3839345598,"timestamp":"2024-06-01T17:52:38.554940Z"}]}
{"channel":"book","type":"update","data":[{"symbol":"ETH/USD","bids":[],"asks":[{"price":3796.87,"qty":26.33751664}],"checksum":2417041407,"timestamp":"2024-06-01T17:52:38.554992Z"}]}
{"channel":"book","type":"update","data":[{"symbol":"ETH/USD","bids":[],"asks":[{"price":3796.44,"qty":26.34052241}],"checksum":106621028,"timestamp":"2024-06-01T17:52:38.555023Z"}]}
{"channel":"book","type":"update","data":[{"symbol":"ETH/USD","bids":[],"asks":[{"price":3796.59,"qty":0.00000000},{"price":3797.09,"qty":3.00000000}],"checksum":376209952,"timestamp":"2024-06-01T17:52:38.595074Z"}]}
{"channel":"book","type":"update","data":[{"symbol":"ETH/USD","bids":[],"asks":[{"price":3796.41,"qty":0.00000000},{"price":3797.22,"qty":0.72912968}],"checksum":4159201785,"timestamp":"2024-06-01T17:52:38.598758Z"}]}
{"channel":"book","type":"update","data":[{"symbol":"ETH/USD","bids":[{"price":3795.73,"qty":15.80765248}],"asks":[],"checksum":3285620137,"timestamp":"2024-06-01T17:52:38.599212Z"}]}
{"channel":"book","type":"update","data":[{"symbol":"ETH/USD","bids":[{"price":3795.89,"qty":0.00000000},{"price":3795.64,"qty":3.00000000}],"asks":[],"checksum":1800219573,"timestamp":"2024-06-01T17:52:38.603129Z"}]}
{"channel":"book","type":"update","data":[{"symbol":"ETH/USD","bids":[],"asks":[{"price":3796.44,"qty":0.00000000},{"price":3797.40,"qty":0.41184731}],"checksum":1045109103,"timestamp":"2024-06-01T17:52:38.603139Z"}]}
{"channel":"book","type":"update","data":[{"symbol":"ETH/USD","bids":[{"price":3796.00,"qty":0.00000000},{"price":3795.56,"qty":0.84574642}],"asks":[],"checksum":3222032633,"timestamp":"2024-06-01T17:52:38.603229Z"}]}
{"channel":"book","type":"update","data":[{"symbol":"ETH/USD","bids":[],"asks":[{"price":3796.47,"qty":0.00000000},{"price":3797.45,"qty":10.43462302}],"checksum":2167839541,"timestamp":"2024-06-01T17:52:38.603268Z"}]}
{"channel":"book","type":"update","data":[{"symbol":"ETH/USD","bids":[{"price":3795.79,"qty":5.27100000}],"asks":[],"checksum":3277690988,"timestamp":"2024-06-01T17:52:38.607053Z"}]}
{"channel":"book","type":"update","data":[{"symbol":"ETH/USD","bids":[],"asks":[{"price":3796.67,"qty":0.52697311}],"checksum":3012220531,"timestamp":"2024-06-01T17:52:38.611688Z"}]}
{"channel":"book","type":"update","data":[{"symbol":"ETH/USD","bids":[],"asks":[{"price":3796.49,"qty":26.34017959}],"checksum":2340861176,"timestamp":"2024-06-01T17:52:38.615599Z"}]}
{"channel":"book","type":"update","data":[{"symbol":"ETH/USD","bids":[{"price":3796.06,"qty":26.34304310}],"asks":[],"checksum":3034778916,"timestamp":"2024-06-01T17:52:38.615779Z"}]}
{"channel":"book","type":"update","data":[{"symbol":"ETH/USD","bids":[],"asks":[{"price":3796.49,"qty":0.00000000},{"price":3797.45,"qty":10.43462302}],"checksum":3467729902,"timestamp":"2024-06-01T17:52:38.629057Z"}]}
{"channel":"book","type":"update","data":[{"symbol":"ETH/USD","bids":[{"price":3796.06,"qty":0.00000000},{"price":3795.64,"qty":3.00000000}],"asks":[],"checksum":3012220531,"timestamp":"2024-06-01T17:52:38.629103Z"}]}
{"channel":"book","type":"update","data":[{"symbol":"ETH/USD","bids":[],"asks":[{"price":3796.70,"qty":5.07610000}],"checksum":3957724264,"timestamp":"2024-06-01T17:52:38.696131Z"}]}
{"channel":"book","type":"update","data":[{"symbol":"ETH/USD","bids":[],"asks":[{"price":3796.49,"qty":26.34014769}],"checksum":501175983,"timestamp":"2024-06-01T17:52:38.700709Z"}]}
{"channel":"book","type":"update","data":[{"symbol":"ETH/USD","bids":[{"price":3796.10,"qty":26.34282552}],"asks":[],"checksum":1196355661,"timestamp":"2024-06-01T17:52:38.700809Z"}]}
{"channel":"book","type":"update","data":[{"symbol":"ETH/USD","bids":[],"asks":[{"price":3796.49,"qty":0.00000000},{"price":3797.45,"qty":10.43462302}],"checksum":1119395356,"timestamp":"2024-06-01T17:52:38.727962Z"}]}
{"channel":"book","type":"update","data":[{"symbol":"ETH/USD","bids":[{"price":3796.03,"qty":1.00000000},{"price":3796.04,"qty":0.00936846}],"asks":[],"checksum":3369108301,"timestamp":"2024-06-01T17:52:38.730251Z"}]}
{"channel":"book","type":"update","data":[{"symbol":"ETH/USD","bids":[],"asks":[{"price":3796.67,"qty":0.00000000},{"price":3797.47,"qty":3.00000000}],"checksum":1949012813,"timestamp":"2024-06-01T17:52:38.732244Z"}]}
{"channel":"book","type":"update","data":[{"symbol":"ETH/USD","bids":[],"asks":[{"price":3797.40,"qty":0.00000000},{"price":3797.49,"qty":2.13800000}],"checksum":248412867,"timestamp":"2024-06-01T17:52:38.750995Z"}]}
{"channel":"book","type":"update","data":[{"symbol":"ETH/USD","bids":[{"price":3796.10,"qty":0.00000000},{"price":3795.72,"qty":3.95220467}],"asks":[],"checksum":4044219004,"timestamp":"2024-06-01T17:52:38.875197Z"}]}
{"channel":"book","type":"update","data":[{"symbol":"ETH/USD","bids":[{"price":3796.15,"qty":26.34246722}],"asks":[],"checksum":2597010438,"timestamp":"2024-06-01T17:52:38.881072Z"}]}
{"channel":"book","type":"update","data":[{"symbol":"ETH/USD","bids":[],"asks":[{"price":3796.64,"qty":26.33908067}],"checksum":3472126185,"timestamp":"2024-06-01T17:52:38.881131Z"}]}
{"channel":"book","type":"update","data":[{"symbol":"ETH/USD","bids":[{"price":3796.05,"qty":26.34317250}],"asks":[],"checksum":1254401969,"timestamp":"2024-06-01T17:52:38.881197Z"}]}
{"channel":"book","type":"update","data":[{"symbol":"ETH/USD","bids":[],"asks":[{"price":3796.54,"qty":26.33981344}],"checksum":86206281,"timestamp":"2024-06-01T17:52:38.881227Z"}]}
{"channel":"book","type":"update","data":[{"symbol":"ETH/USD","bids":[],"asks":[{"price":3796.99,"qty":0.00000000},{"price":3797.47,"qty":3.00000000}],"checksum":158145891,"timestamp":"2024-06-01T17:52:38.897349Z"}]}
{"channel":"book","type":"update","data":[{"symbol":"ETH/USD","bids":[],"asks":[{"price":3796.70,"qty":0.77000000}],"checksum":2362610292,"timestamp":"2024-06-01T17:52:38.941361Z"}]}
{"channel":"book","type":"update","data":[{"symbol":"ETH/USD","bids":[{"price":3796.15,"qty":0.00000000},{"price":3795.73,"qty":15.80765248}],"asks":[],"checksum":2130401593,"timestamp":"2024-06-01T17:52:38.968590Z"}]}
{"channel":"book","type":"update","data":[{"symbol":"ETH/USD","bids":[],"asks":[{"price":3796.54,"qty":0.00000000},{"price":3797.49,"qty":2.13800000}],"checksum":1032066337,"timestamp":"2024-06-01T17:52:38.976642Z"}]}
{"channel":"book","type":"update","data":[{"symbol":"ETH/USD","bids":[],"asks":[{"price":3796.53,"qty":26.33988954}],"checksum":1438461700,"timestamp":"2024-06-01T17:52:38.980760Z"}]}
{"channel":"book","type":"update","data":[{"symbol":"ETH/USD","bids":[{"price":3796.12,"qty":26.34266217}],"asks":[],"checksum":3973483456,"timestamp":"2024-06-01T17:52:38.980832Z"}]}
{"channel":"book","type":"update","data":[{"symbol":"ETH/USD","bids":[],"asks":[{"price":3796.70,"qty":0.00000000},{"price":3797.49,"qty":2.13800000},{"price":3796.58,"qty":0.77000000}],"checksum":910460342,"timestamp":"2024-06-01T17:52:39.046035Z"}]}
{"channel":"book","type":"update","data":[{"symbol":"ETH/USD","bids":[{"price":3796.03,"qty":0.00000000},{"price":3795.73,"qty":15.80765248}],"asks":[],"checksum":360385136,"timestamp":"2024-06-01T17:52:39.050241Z"}]}
{"channel":"book","type":"update","data":[{"symbol":"ETH/USD","bids":[{"price":3796.04,"qty":0.00000000},{"price":3795.72,"qty":3.95220467},{"price":3796.13,"qty":0.00936824}],"asks":[],"checksum":1120657615,"timestamp":"2024-06-01T17:52:39.099272Z"}]}
{"channel":"book","type":"update","data":[{"symbol":"ETH/USD","bids":[],"asks":[{"price":3796.53,"qty":0.00000000},{"price":3797.49,"qty":2.13800000}],"checksum":1183836766,"timestamp":"2024-06-01T17:52:39.101366Z"}]}
{"channel":"book","type":"update","data":[{"symbol":"ETH/USD","bids":[{"price":3796.12,"qty":0.00000000},{"price":3795.72,"qty":3.95220467}],"asks":[],"checksum":2714924531,"timestamp":"2024-06-01T17:52:39.106754Z"}]}
{"channel":"book","type":"update","data":[{"symbol":"ETH/USD","bids":[{"price":3796.14,"qty":26.34254795}],"asks":[],"checksum":3486070380,"timestamp":"2024-06-01T17:52:39.111467Z"}]}
{"channel":"book","type":"update","data":[{"symbol":"ETH/USD","bids":[],"asks":[{"price":3796.55,"qty":26.33971482}],"checksum":1569055614,"timestamp":"2024-06-01T17:52:39.111599Z"}]}
{"channel":"book","type":"update","data":[{"symbol":"ETH/USD","bids":[],"asks":[{"price":3797.14,"qty":26.33567113}],"checksum":2620189543,"timestamp":"2024-06-01T17:52:39.111631Z"}]}
{"channel":"book","type":"update","data":[{"symbol":"ETH/USD","bids":[],"asks":[{"price":3796.55,"qty":0.00000000},{"price":3797.47,"qty":3.00000000}],"checksum":1734382769,"timestamp":"2024-06-01T17:52:39.130166Z"}]}
{"channel":"book","type":"update","data":[{"symbol":"ETH/USD","bids":[{"price":3796.14,"qty":0.00000000},{"price":3795.72,"qty":3.95220467}],"asks":[],"checksum":1873804638,"timestamp":"2024-06-01T17:52:39.130253Z"}]}
{"channel":"book","type":"update","data":[{"symbol":"ETH/USD","bids":[{"price":3796.13,"qty":0.00000000},{"price":3795.64,"qty":3.00000000},{"price":3796.06,"qty":0.00936841}],"asks":[],"checksum":1087997869,"timestamp":"2024-06-01T17:52:39.155262Z"}]}
{"channel":"book","type":"update","data":[{"symbol":"ETH/USD","bids":[{"price":3796.05,"qty":0.00000000},{"price":3795.64,"qty":3.00000000}],"asks":[],"checksum":41492722,"timestamp":"2024-06-01T17:52:39.160009Z"}]}
{"channel":"book","type":"update","data":[{"symbol":"ETH/USD","bids":[],"asks":[{"price":3796.58,"qty":27.10954197}],"checksum":3902041195,"timestamp":"2024-06-01T17:52:39.164497Z"}]}
{"channel":"book","type":"update","data":[{"symbol":"ETH/USD","bids":[{"price":3796.07,"qty":26.34303371}],"asks":[],"checksum":2928126605,"timestamp":"2024-06-01T17:52:39.164576Z"}]}
{"channel":"book","type":"update","data":[{"symbol":"ETH/USD","bids":[{"price":3796.15,"qty":26.34243824}],"asks":[],"checksum":3117165945,"timestamp":"2024-06-01T17:52:39.164694Z"}]}
{"channel":"book","type":"update","data":[{"symbol":"ETH/USD","bids":[],"asks":[{"price":3796.58,"qty":0.77000000}],"checksum":1713765244,"timestamp":"2024-06-01T17:52:39.207427Z"}]}
{"channel":"book","type":"update","data":[{"symbol":"ETH/USD","bids":[{"price":3796.15,"qty":0.00000000},{"price":3795.72,"qty":3.95220467}],"asks":[],"checksum":666790945,"timestamp":"2024-06-01T17:52:39.207443Z"}]}
{"channel":"book","type":"update","data":[{"symbol":"ETH/USD","bids":[],"asks":[{"price":3796.54,"qty":26.33977717}],"checksum":1211653041,"timestamp":"2024-06-01T17:52:39.252974Z"}]}
{"channel":"book","type":"update","data":[{"symbol":"ETH/USD","bids":[{"price":3796.08,"qty":26.34296432}],"asks":[],"checksum":297349775,"timestamp":"2024-06-01T17:52:39.252993Z"}]}
{"channel":"book","type":"update","data":[{"symbol":"ETH/USD","bids":[{"price":3796.08,"qty":0.00000000},{"price":3795.72,"qty":3.95220467}],"asks":[],"checksum":1211653041,"timestamp":"2024-06-01T17:52:39.257820Z"}]}
{"channel":"book","type":"update","data":[{"symbol":"ETH/USD","bids":[{"price":3796.02,"qty":0.00000000},{"price":3795.64,"qty":3.00000000}],"asks":[],"checksum":4065279403,"timestamp":"2024-06-01T17:52:39.395322Z"}]}
{"channel":"book","type":"update","data":[{"symbol":"ETH/USD","bids":[],"asks":[{"price":3796.58,"qty":0.00000000},{"price":3797.47,"qty":3.00000000},{"price":3797.12,"qty":1.85000000}],"checksum":2624797793,"timestamp":"2024-06-01T17:52:39.398451Z"}]}
{"channel":"book","type":"update","data":[{"symbol":"ETH/USD","bids":[{"price":3796.12,"qty":26.34264637}],"asks":[],"checksum":2910612627,"timestamp":"2024-06-01T17:52:39.425990Z"}]}
{"channel":"book","type":"update","data":[{"symbol":"ETH/USD","bids":[{"price":3795.78,"qty":0.00000000},{"price":3795.64,"qty":3.00000000}],"asks":[],"checksum":3115599244,"timestamp":"2024-06-01T17:52:39.439144Z"}]}
{"channel":"book","type":"update","data":[{"symbol":"ETH/USD","bids":[],"asks":[{"price":3796.54,"qty":0.00000000},{"price":3797.47,"qty":3.00000000}],"checksum":2966918471,"timestamp":"2024-06-01T17:52:39.479276Z"}]}
{"channel":"book","type":"update","data":[{"symbol":"ETH/USD","bids":[{"price":3796.12,"qty":0.00000000},{"price":3795.57,"qty":1.85000000}],"asks":[],"checksum":1643943214,"timestamp":"2024-06-01T17:52:39.479311Z"}]}
{"channel":"book","type":"update","data":[{"symbol":"ETH/USD","bids":[],"asks":[{"price":3796.58,"qty":26.33955361}],"checksum":3645244454,"timestamp":"2024-06-01T17:52:39.486916Z"}]}
{"channel":"book","type":"update","data":[{"symbol":"ETH/USD","bids":[{"price":3796.13,"qty":26.34261734}],"asks":[],"checksum":1174698497,"timestamp":"2024-06-01T17:52:39.487060Z"}]}
{"channel":"book","type":"update","data":[{"symbol":"ETH/USD","bids":[{"price":3796.23,"qty":26.34185603}],"asks":[],"checksum":608264206,"timestamp":"2024-06-01T17:52:39.487109Z"}]}
{"channel":"book","type":"update","data":[{"symbol":"ETH/USD","bids":[{"price":3796.06,"qty":0.00000000},{"price":3795.64,"qty":3.00000000},{"price":3796.13,"qty":26.35198558}],"asks":[],"checksum":365560135,"timestamp":"2024-06-01T17:52:39.509535Z"}]}
{"channel":"book","type":"update","data":[{"symbol":"ETH/USD","bids":[{"price":3796.07,"qty":0.00000000},{"price":3795.57,"qty":1.85000000}],"asks":[],"checksum":2635015729,"timestamp":"2024-06-01T17:52:39.535402Z"}]}
{"channel":"book","type":"update","data":[{"symbol":"ETH/USD","bids":[],"asks":[{"price":3796.58,"qty":0.00000000},{"price":3797.47,"qty":3.00000000}],"checksum":2147131797,"timestamp":"2024-06-01T17:52:39.535469Z"}]}
{"channel":"book","type":"update","data":[{"symbol":"ETH/USD","bids":[],"asks":[{"price":3797.45,"qty":0.00000000},{"price":3797.49,"qty":2.13800000}],"checksum":2611322647,"timestamp":"2024-06-01T17:52:39.538930Z"}]}
{"channel":"book","type":"update","data":[{"symbol":"ETH/USD","bids":[{"price":3795.93,"qty":26.34395809}],"asks":[],"checksum":1126617746,"timestamp":"2024-06-01T17:52:39.540712Z"}]}
{"channel":"book","type":"update","data":[{"symbol":"ETH/USD","bids":[],"asks":[{"price":3796.57,"qty":26.33960892}],"checksum":3199789487,"timestamp":"2024-06-01T17:52:39.540907Z"}]}
{"channel":"book","type":"update","data":[{"symbol":"ETH/USD","bids":[],"asks":[{"price":3796.57,"qty":0.00000000},{"price":3797.49,"qty":2.13800000}],"checksum":1126617746,"timestamp":"2024-06-01T17:52:39.629828Z"}]}
{"channel":"book","type":"update","data":[{"symbol":"ETH/USD","bids":[{"price":3796.23,"qty":0.00000000},{"price":3795.57,"qty":1.85000000}],"asks":[],"checksum":776782560,"timestamp":"2024-06-01T17:52:39.630034Z"}]}
{"channel":"book","type":"update","data":[{"symbol":"ETH/USD","bids":[],"asks":[{"price":3796.55,"qty":26.33972481}],"checksum":109240446,"timestamp":"2024-06-01T17:52:39.635118Z"}]}
{"channel":"book","type":"update","data":[{"symbol":"ETH/USD","bids":[{"price":3796.20,"qty":26.34208347}],"asks":[],"checksum":93345874,"timestamp":"2024-06-01T17:52:39.635177Z"}]}
{"channel":"book","type":"update","data":[{"symbol":"ETH/USD","bids":[{"price":3796.24,"qty":0.32778701}],"asks":[],"checksum":2963600235,"timestamp":"2024-06-01T17:52:39.757330Z"}]}
{"channel":"book","type":"update","data":[{"symbol":"ETH/USD","bids":[],"asks":[{"price":3796.55,"qty":0.00000000},{"price":3797.49,"qty":2.13800000}],"checksum":2557137397,"timestamp":"2024-06-01T17:52:39.877877Z"}]}
{"channel":"book","type":"update","data":[{"symbol":"ETH/USD","bids":[{"price":3796.20,"qty":0.00000000},{"price":3795.64,"qty":3.00000000}],"asks":[],"checksum":4046284494,"timestamp":"2024-06-01T17:52:39.878018Z"}]}
{"channel":"book","type":"update","data":[{"symbol":"ETH/USD","bids":[{"price":3795.94,"qty":15.80353051}],"asks":[],"checksum":1609369361,"timestamp":"2024-06-01T17:52:39.882181Z"}]}
{"channel":"book","type":"update","data":[{"symbol":"ETH/USD","bids":[],"asks":[{"price":3796.59,"qty":26.33948847}],"checksum":3422682585,"timestamp":"2024-06-01T17:52:39.883263Z"}]}
{"channel":"book","type":"update","data":[{"symbol":"ETH/USD","bids":[{"price":3796.22,"qty":26.34194623}],"asks":[],"checksum":2847221773,"timestamp":"2024-06-01T17:52:39.883289Z"}]}
{"channel":"book","type":"update","data":[{"symbol":"ETH/USD","bids":[{"price":3796.13,"qty":26.34261734},{"price":3796.25,"qty":0.00936794}],"asks":[],"checksum":1830435492,"timestamp":"2024-06-01T17:52:39.903525Z"}]}
{"channel":"book","type":"update","data":[{"symbol":"ETH/USD","bids":[],"asks":[{"price":3796.59,"qty":0.00000000},{"price":3797.49,"qty":2.13800000}],"checksum":3867934785,"timestamp":"2024-06-01T17:52:39.959506Z"}]}
{"channel":"book","type":"update","data":[{"symbol":"ETH/USD","bids":[{"price":3796.13,"qty":0.00000000},{"price":3795.73,"qty":15.80765248}],"asks":[],"checksum":895375359,"timestamp":"2024-06-01T17:52:39.959611Z"}]}
{"channel":"book","type":"update","data":[{"symbol":"ETH/USD","bids":[{"price":3796.26,"qty":26.34171526}],"asks":[],"checksum":3835551920,"timestamp":"2024-06-01T17:52:39.964846Z"}]}
{"channel":"book","type":"update","data":[{"symbol":"ETH/USD","bids":[],"asks":[{"price":3796.74,"qty":26.33843201}],"checksum":350934998,"timestamp":"2024-06-01T17:52:39.965020Z"}]}
{"channel":"book","type":"update","data":[{"symbol":"ETH/USD","bids":[{"price":3796.26,"qty":0.00000000},{"price":3795.73,"qty":15.80765248}],"asks":[],"checksum":3307823257,"timestamp":"2024-06-01T17:52:39.970061Z"}]}
{"channel":"book","type":"update","data":[{"symbol":"ETH/USD","bids":[{"price":3796.26,"qty":26.34171526}],"asks":[],"checksum":350934998,"timestamp":"2024-06-01T17:52:40.055081Z"}]}
{"channel":"book","type":"update","data":[{"symbol":"ETH/USD","bids":[{"price":3796.26,"qty":0.00000000},{"price":3795.73,"qty":15.80765248}],"asks":[],"checksum":3307823257,"timestamp":"2024-06-01T17:52:40.060254Z"}]}
{"channel":"book","type":"update","data":[{"symbol":"ETH/USD","bids":[],"asks":[{"price":3796.64,"qty":0.00000000},{"price":3797.49,"qty":2.13800000}],"checksum":515891640,"timestamp":"2024-06-01T17:52:40.203177Z"}]}
{"channel":"book","type":"update","data":[{"symbol":"ETH/USD","bids":[{"price":3796.27,"qty":26.34160113}],"asks":[],"checksum":254720737,"timestamp":"2024-06-01T17:52:40.207419Z"}]}
{"channel":"book","type":"update","data":[{"symbol":"ETH/USD","bids":[],"asks":[{"price":3796.63,"qty":26.33918818}],"checksum":987572435,"timestamp":"2024-06-01T17:52:40.207597Z"}]}
{"channel":"book","type":"update","data":[{"symbol":"ETH/USD","bids":[{"price":3796.25,"qty":0.00000000},{"price":3795.73,"qty":15.80765248},{"price":3796.28,"qty":0.00936644}],"asks":[],"checksum":2592740444,"timestamp":"2024-06-01T17:52:40.332436Z"}]}
{"channel":"book","type":"update","data":[{"symbol":"ETH/USD","bids":[],"asks":[{"price":3796.63,"qty":0.00000000},{"price":3797.49,"qty":2.13800000}],"checksum":2943977070,"timestamp":"2024-06-01T17:52:40.374198Z"}]}
{"channel":"book","type":"update","data":[{"symbol":"ETH/USD","bids":[],"asks":[{"price":3796.62,"qty":26.33926193}],"checksum":1057464234,"timestamp":"2024-06-01T17:52:40.378961Z"}]}
{"channel":"book","type":"update","data":[{"symbol":"ETH/USD","bids":[{"price":3796.28,"qty":0.35357474}],"asks":[],"checksum":64731253,"timestamp":"2024-06-01T17:52:40.453497Z"}]}
{"channel":"book","type":"update","data":[{"symbol":"ETH/USD","bids":[{"price":3796.27,"qty":0.00000000},{"price":3795.73,"qty":15.80765248}],"asks":[],"checksum":3648296290,"timestamp":"2024-06-01T17:52:40.478128Z"}]}
{"channel":"book","type":"update","data":[{"symbol":"ETH/USD","bids":[{"price":3796.29,"qty":26.34150710}],"asks":[],"checksum":2974158065,"timestamp":"2024-06-01T17:52:40.483440Z"}]}
{"channel":"book","type":"update","data":[{"symbol":"ETH/USD","bids":[{"price":3796.29,"qty":0.00000000},{"price":3795.73,"qty":15.80765248}],"asks":[],"checksum":3648296290,"timestamp":"2024-06-01T17:52:40.518107Z"}]}
{"channel":"book","type":"update","data":[{"symbol":"ETH/USD","bids":[{"price":3796.28,"qty":0.34420830},{"price":3796.29,"qty":0.00936641}],"asks":[],"checksum":2439723403,"timestamp":"2024-06-01T17:52:40.719923Z"}]}
{"channel":"book","type":"update","data":[{"symbol":"ETH/USD","bids":[{"price":3795.79,"qty":0.00000000},{"price":3795.73,"qty":15.80765248}],"asks":[],"checksum":1095244084,"timestamp":"2024-06-01T17:52:40.778315Z"}]}
{"channel":"book","type":"update","data":[{"symbol":"ETH/USD","bids":[{"price":3795.90,"qty":0.00000000},{"price":3795.72,"qty":30.29763040}],"asks":[],"checksum":2016314416,"timestamp":"2024-06-01T17:52:40.779364Z"}]}
{"channel":"book","type":"update","data":[{"symbol":"ETH/USD","bids":[{"price":3795.91,"qty":0.00000000},{"price":3795.64,"qty":3.00000000}],"asks":[],"checksum":161876757,"timestamp":"2024-06-01T17:52:40.785531Z"}]}
{"channel":"book","type":"update","data":[{"symbol":"ETH/USD","bids":[],"asks":[{"price":3796.39,"qty":3.09000000}],"checksum":1844421909,"timestamp":"2024-06-01T17:52:40.785577Z"}]}
{"channel":"book","type":"update","data":[{"symbol":"ETH/USD","bids":[{"price":3796.22,"qty":0.00000000},{"price":3795.59,"qty":5.27100000}],"asks":[],"checksum":2611635753,"timestamp":"2024-06-01T17:52:40.787185Z"}]}
{"channel":"book","type":"update","data":[{"symbol":"ETH/USD","bids":[],"asks":[{"price":3796.62,"qty":0.00000000},{"price":3797.49,"qty":2.13800000}],"checksum":755244866,"timestamp":"2024-06-01T17:52:40.787214Z"}]}
{"channel":"book","type":"update","data":[{"symbol":"ETH/USD","bids":[],"asks":[{"price":3796.87,"qty":0.00000000},{"price":3797.91,"qty":10.43462302}],"checksum":53366584,"timestamp":"2024-06-01T17:52:40.787317Z"}]}
{"channel":"book","type":"update","data":[{"symbol":"ETH/USD","bids":[],"asks":[{"price":3796.39,"qty":0.09000000}],"checksum":133754766,"timestamp":"2024-06-01T17:52:40.788980Z"}]}
{"channel":"book","type":"update","data":[{"symbol":"ETH/USD","bids":[{"price":3795.64,"qty":0.00000000},{"price":3795.56,"qty":0.84574642}],"asks":[],"checksum":3203490879,"timestamp":"2024-06-01T17:52:40.790635Z"}]}
{"channel":"book","type":"update","data":[{"symbol":"ETH/USD","bids":[{"price":3795.59,"qty":9.22320467}],"asks":[],"checksum":919941347,"timestamp":"2024-06-01T17:52:40.793215Z"}]}
{"channel":"book","type":"update","data":[{"symbol":"ETH/USD","bids":[],"asks":[{"price":3796.44,"qty":26.34051703}],"checksum":2522798317,"timestamp":"2024-06-01T17:52:40.793228Z"}]}
{"channel":"book","type":"update","data":[{"symbol":"ETH/USD","bids":[{"price":3796.12,"qty":26.34265785}],"asks":[],"checksum":3251492752,"timestamp":"2024-06-01T17:52:40.793242Z"}]}
{"channel":"book","type":"update","data":[{"symbol":"ETH/USD","bids":[{"price":3796.07,"qty":26.34302039}],"asks":[],"checksum":2704043315,"timestamp":"2024-06-01T17:52:40.793255Z"}]}
{"channel":"book","type":"update","data":[{"symbol":"ETH/USD","bids":[],"asks":[{"price":3796.34,"qty":3.00000000}],"checksum":2286190746,"timestamp":"2024-06-01T17:52:40.793275Z"}]}
{"channel":"book","type":"update","data":[{"symbol":"ETH/USD","bids":[],"asks":[{"price":3796.34,"qty":0.00000000},{"price":3797.49,"qty":2.13800000}],"checksum":2704043315,"timestamp":"2024-06-01T17:52:40.797071Z"}]}
{"channel":"book","type":"update","data":[{"symbol":"ETH/USD","bids":[],"asks":[{"price":3796.39,"qty":0.00000000},{"price":3797.91,"qty":10.43462302}],"checksum":2445306775,"timestamp":"2024-06-01T17:52:40.798557Z"}]}
{"channel":"book","type":"update","data":[{"symbol":"ETH/USD","bids":[{"price":3795.77,"qty":0.00000000},{"price":3795.59,"qty":9.22320467}],"asks":[],"checksum":1583679825,"timestamp":"2024-06-01T17:52:40.810289Z"}]}
{"channel":"book","type":"update","data":[{"symbol":"ETH/USD","bids":[],"asks":[{"price":3796.44,"qty":29.34051703}],"checksum":1497803720,"timestamp":"2024-06-01T17:52:40.815783Z"}]}
{"channel":"book","type":"update","data":[{"symbol":"ETH/USD","bids":[],"asks":[{"price":3797.12,"qty":0.00000000},{"price":3797.94,"qty":0.52697311},{"price":3796.88,"qty":1.85000000}],"checksum":1336026745,"timestamp":"2024-06-01T17:52:40.826727Z"}]}
{"channel":"book","type":"update","data":[{"symbol":"ETH/USD","bids":[],"asks":[{"price":3796.43,"qty":3.00000000}],"checksum":162461829,"timestamp":"2024-06-01T17:52:40.828197Z"}]}
{"channel":"book","type":"update","data":[{"symbol":"ETH/USD","bids":[],"asks":[{"price":3796.43,"qty":6.00000000}],"checksum":3181339853,"timestamp":"2024-06-01T17:52:40.851679Z"}]}
{"channel":"book","type":"update","data":[{"symbol":"ETH/USD","bids":[],"asks":[{"price":3796.43,"qty":3.00000000}],"checksum":162461829,"timestamp":"2024-06-01T17:52:40.860267Z"}]}
{"channel":"book","type":"update","data":[{"symbol":"ETH/USD","bids":[{"price":3796.12,"qty":0.00000000},{"price":3795.56,"qty":0.84574642}],"asks":[],"checksum":2154354656,"timestamp":"2024-06-01T17:52:40.874433Z"}]}
{"channel":"book","type":"update","data":[{"symbol":"ETH/USD","bids":[],"asks":[{"price":3796.42,"qty":26.34060509}],"checksum":1313252620,"timestamp":"2024-06-01T17:52:40.878868Z"}]}
{"channel":"book","type":"update","data":[{"symbol":"ETH/USD","bids":[],"asks":[{"price":3796.31,"qty":3.00000000}],"checksum":535642764,"timestamp":"2024-06-01T17:52:40.882285Z"}]}
{"channel":"book","type":"update","data":[{"symbol":"ETH/USD","bids":[],"asks":[{"price":3796.44,"qty":26.34051703}],"checksum":3419323796,"timestamp":"2024-06-01T17:52:40.882459Z"}]}
{"channel":"book","type":"update","data":[{"symbol":"ETH/USD","bids":[],"asks":[{"price":3796.42,"qty":0.00000000},{"price":3797.47,"qty":3.00000000}],"checksum":3995625472,"timestamp":"2024-06-01T17:52:40.883316Z"}]}
{"channel":"book","type":"update","data":[{"symbol":"ETH/USD","bids":[],"asks":[{"price":3796.39,"qty":0.09000000}],"checksum":2890509174,"timestamp":"2024-06-01T17:52:40.886593Z"}]}
{"channel":"book","type":"update","data":[{"symbol":"ETH/USD","bids":[],"asks":[{"price":3796.69,"qty":3.00000000}],"checksum":1082826848,"timestamp":"2024-06-01T17:52:40.886705Z"}]}
{"channel":"book","type":"update","data":[{"symbol":"ETH/USD","bids":[],"asks":[{"price":3796.43,"qty":0.00000000},{"price":3797.22,"qty":0.72912968}],"checksum":1272043294,"timestamp":"2024-06-01T17:52:40.886932Z"}]}
{"channel":"book","type":"update","data":[{"symbol":"ETH/USD","bids":[{"price":3795.94,"qty":19.75573518}],"asks":[],"checksum":2080565020,"timestamp":"2024-06-01T17:52:40.887727Z"}]}
{"channel":"book","type":"update","data":[{"symbol":"ETH/USD","bids":[{"price":3795.94,"qty":15.80353051}],"asks":[],"checksum":1272043294,"timestamp":"2024-06-01T17:52:40.891847Z"}]}
{"channel":"book","type":"update","data":[{"symbol":"ETH/USD","bids":[],"asks":[{"price":3797.14,"qty":0.00000000},{"price":3797.47,"qty":3.00000000}],"checksum":1665129886,"timestamp":"2024-06-01T17:52:40.908204Z"}]}
{"channel":"book","type":"update","data":[{"symbol":"ETH/USD","bids":[{"price":3796.07,"qty":0.00000000},{"price":3795.32,"qty":1.85000000}],"asks":[],"checksum":1906025032,"timestamp":"2024-06-01T17:52:40.908290Z"}]}
{"channel":"book","type":"update","data":[{"symbol":"ETH/USD","bids":[{"price":3796.04,"qty":26.34321393}],"asks":[],"checksum":2443197551,"timestamp":"2024-06-01T17:52:40.912820Z"}]}
{"channel":"book","type":"update","data":[{"symbol":"ETH/USD","bids":[],"asks":[{"price":3796.96,"qty":26.33690998}],"checksum":798885280,"timestamp":"2024-06-01T17:52:40.912864Z"}]}
{"channel":"book","type":"update","data":[{"symbol":"ETH/USD","bids":[{"price":3795.64,"qty":3.40275510}],"asks":[],"checksum":4228719059,"timestamp":"2024-06-01T17:52:40.949660Z"}]}
{"channel":"book","type":"update","data":[{"symbol":"ETH/USD","bids":[],"asks":[{"price":3796.31,"qty":0.00000000},{"price":3797.47,"qty":3.00000000}],"checksum":1710314783,"timestamp":"2024-06-01T17:52:40.968411Z"}]}
{"channel":"book","type":"update","data":[{"symbol":"ETH/USD","bids":[{"price":3796.04,"qty":0.00000000},{"price":3795.56,"qty":0.84574642}],"asks":[],"checksum":363196363,"timestamp":"2024-06-01T17:52:40.971097Z"}]}
{"channel":"book","type":"update","data":[{"symbol":"ETH/USD","bids":[],"asks":[{"price":3796.39,"qty":3.09000000}],"checksum":4268513089,"timestamp":"2024-06-01T17:52:40.974400Z"}]}
{"channel":"book","type":"update","data":[{"symbol":"ETH/USD","bids":[],"asks":[{"price":3796.35,"qty":26.34113743}],"checksum":2598818483,"timestamp":"2024-06-01T17:52:40.975427Z"}]}
{"channel":"book","type":"update","data":[{"symbol":"ETH/USD","bids":[{"price":3796.02,"qty":26.34336673}],"asks":[],"checksum":3540329030,"timestamp":"2024-06-01T17:52:40.975518Z"}]}
{"channel":"book","type":"update","data":[{"symbol":"ETH/USD","bids":[],"asks":[{"price":3796.39,"qty":3.00000000}],"checksum":1424921936,"timestamp":"2024-06-01T17:52:40.979272Z"}]}
{"channel":"book","type":"update","data":[{"symbol":"ETH/USD","bids":[{"price":3796.02,"qty":0.00000000},{"price":3795.56,"qty":0.84574642}],"asks":[],"checksum":3978907963,"timestamp":"2024-06-01T17:52:40.989691Z"}]}
{"channel":"book","type":"update","data":[{"symbol":"ETH/USD","bids":[],"asks":[{"price":3796.35,"qty":0.00000000},{"price":3797.47,"qty":3.00000000}],"checksum":3929385142,"timestamp":"2024-06-01T17:52:41.041343Z"}]}
{"channel":"book","type":"update","data":[{"symbol":"ETH/USD","bids":[],"asks":[{"price":3796.37,"qty":26.34095948}],"checksum":2387211595,"timestamp":"2024-06-01T17:52:41.045902Z"}]}
{"channel":"book","type":"update","data":[{"symbol":"ETH/USD","bids":[{"price":3796.04,"qty":26.34323434}],"asks":[],"checksum":641767119,"timestamp":"2024-06-01T17:52:41.045941Z"}]}
{"channel":"book","type":"update","data":[{"symbol":"ETH/USD","bids":[{"price":3795.74,"qty":0.00537780}],"asks":[],"checksum":1245091669,"timestamp":"2024-06-01T17:52:41.053364Z"}]}
{"channel":"book","type":"update","data":[{"symbol":"ETH/USD","bids":[{"price":3796.04,"qty":0.00000000},{"price":3795.59,"qty":9.22320467}],"asks":[],"checksum":620069396,"timestamp":"2024-06-01T17:52:41.073062Z"}]}
{"channel":"book","type":"update","data":[{"symbol":"ETH/USD","bids":[],"asks":[{"price":3796.39,"qty":0.00000000},{"price":3797.47,"qty":3.00000000}],"checksum":2403226701,"timestamp":"2024-06-01T17:52:41.076648Z"}]}
{"channel":"book","type":"update","data":[{"symbol":"ETH/USD","bids":[],"asks":[{"price":3796.37,"qty":0.00000000},{"price":3797.49,"qty":2.13800000}],"checksum":831312165,"timestamp":"2024-06-01T17:52:41.094187Z"}]}
{"channel":"book","type":"update","data":[{"symbol":"ETH/USD","bids":[],"asks":[{"price":3796.39,"qty":26.34081460}],"checksum":3280978711,"timestamp":"2024-06-01T17:52:41.099700Z"}]}
{"channel":"book","type":"update","data":[{"symbol":"ETH/USD","bids":[{"price":3796.07,"qty":26.34302094}],"asks":[],"checksum":3681156929,"timestamp":"2024-06-01T17:52:41.099764Z"}]}
{"channel":"book","type":"update","data":[{"symbol":"ETH/USD","bids":[],"asks":[{"price":3796.44,"qty":29.34051703}],"checksum":3421096546,"timestamp":"2024-06-01T17:52:41.103510Z"}]}
{"channel":"book","type":"update","data":[{"symbol":"ETH/USD","bids":[],"asks":[{"price":3796.39,"qty":29.34081460}],"checksum":1028281231,"timestamp":"2024-06-01T17:52:41.124176Z"}]}
{"channel":"book","type":"update","data":[{"symbol":"ETH/USD","bids":[{"price":3795.93,"qty":0.00000000},{"price":3795.59,"qty":9.22320467}],"asks":[],"checksum":2717238447,"timestamp":"2024-06-01T17:52:41.124414Z"}]}
{"channel":"book","type":"update","data":[{"symbol":"ETH/USD","bids":[],"asks":[{"price":3796.38,"qty":3.00000000}],"checksum":3085886983,"timestamp":"2024-06-01T17:52:41.128303Z"}]}
{"channel":"book","type":"update","data":[{"symbol":"ETH/USD","bids":[],"asks":[{"price":3796.44,"qty":26.34051703}],"checksum":1245726281,"timestamp":"2024-06-01T17:52:41.130165Z"}]}
{"channel":"book","type":"update","data":[{"symbol":"ETH/USD","bids":[],"asks":[{"price":3796.38,"qty":0.00000000},{"price":3797.47,"qty":3.00000000}],"checksum":4223319349,"timestamp":"2024-06-01T17:52:41.316605Z"}]}
{"channel":"book","type":"update","data":[{"symbol":"ETH/USD","bids":[],"asks":[{"price":3796.39,"qty":26.34081460}],"checksum":3775204320,"timestamp":"2024-06-01T17:52:41.320667Z"}]}
{"channel":"book","type":"update","data":[{"symbol":"ETH/USD","bids":[],"asks":[{"price":3796.39,"qty":0.00000000},{"price":3797.49,"qty":2.13800000}],"checksum":319166930,"timestamp":"2024-06-01T17:52:41.350243Z"}]}
{"channel":"book","type":"update","data":[{"symbol":"ETH/USD","bids":[],"asks":[{"price":3796.38,"qty":26.34094631}],"checksum":1018722125,"timestamp":"2024-06-01T17:52:41.355139Z"}]}
{"channel":"book","type":"update","data":[{"symbol":"ETH/USD","bids":[{"price":3796.05,"qty":26.34315267}],"asks":[],"checksum":655937012,"timestamp":"2024-06-01T17:52:41.355255Z"}]}
{"channel":"book","type":"update","data":[{"symbol":"ETH/USD","bids":[],"asks":[{"price":3796.37,"qty":2.40000000}],"checksum":188095333,"timestamp":"2024-06-01T17:52:41.363130Z"}]}
{"channel":"book","type":"update","data":[{"symbol":"ETH/USD","bids":[],"asks":[{"price":3796.38,"qty":0.00000000},{"price":3797.47,"qty":3.00000000}],"checksum":2591912538,"timestamp":"2024-06-01T17:52:41.731922Z"}]}
{"channel":"book","type":"update","data":[{"symbol":"ETH/USD","bids":[],"asks":[{"price":3796.42,"qty":26.34067348}],"checksum":1701525003,"timestamp":"2024-06-01T17:52:41.736213Z"}]}
{"channel":"book","type":"update","data":[{"symbol":"ETH/USD","bids":[{"price":3796.07,"qty":0.00000000},{"price":3795.59,"qty":9.22320467}],"asks":[],"checksum":1914260338,"timestamp":"2024-06-01T17:52:41.792404Z"}]}
{"channel":"book","type":"update","data":[{"symbol":"ETH/USD","bids":[{"price":3796.06,"qty":26.34305224}],"asks":[],"checksum":3793349591,"timestamp":"2024-06-01T17:52:41.796412Z"}]}
{"channel":"book","type":"update","data":[{"symbol":"ETH/USD","bids":[{"price":3796.06,"qty":0.00000000},{"price":3795.59,"qty":9.22320467}],"asks":[],"checksum":1914260338,"timestamp":"2024-06-01T17:52:41.900366Z"}]}
{"channel":"book","type":"update","data":[{"symbol":"ETH/USD","bids":[{"price":3796.08,"qty":26.34293896}],"asks":[],"checksum":1364626655,"timestamp":"2024-06-01T17:52:41.904570Z"}]}
{"channel":"book","type":"update","data":[{"symbol":"ETH/USD","bids":[{"price":3796.24,"qty":0.00000000},{"price":3795.59,"qty":9.22320467}],"asks":[],"checksum":3217261594,"timestamp":"2024-06-01T17:52:41.914392Z"}]}
{"channel":"book","type":"update","data":[{"symbol":"ETH/USD","bids":[],"asks":[{"price":3796.69,"qty":0.00000000},{"price":3797.47,"qty":3.00000000}],"checksum":2537912175,"timestamp":"2024-06-01T17:52:42.303582Z"}]}
{"channel":"book","type":"update","data":[{"symbol":"ETH/USD","bids":[{"price":3796.08,"qty":0.00000000},{"price":3795.58,"qty":0.34420830}],"asks":[],"checksum":2624462091,"timestamp":"2024-06-01T17:52:42.313176Z"}]}
{"channel":"book","type":"update","data":[{"symbol":"ETH/USD","bids":[{"price":3796.09,"qty":26.34282567}],"asks":[],"checksum":536281154,"timestamp":"2024-06-01T17:52:42.317270Z"}]}
{"channel":"book","type":"update","data":[{"symbol":"ETH/USD","bids":[{"price":3796.09,"qty":0.00000000},{"price":3795.58,"qty":0.34420830}],"asks":[],"checksum":2624462091,"timestamp":"2024-06-01T17:52:42.343598Z"}]}
{"channel":"book","type":"update","data":[{"symbol":"ETH/USD","bids":[],"asks":[{"price":3796.42,"qty":0.00000000},{"price":3797.49,"qty":2.13800000}],"checksum":656219000,"timestamp":"2024-06-01T17:52:42.343608Z"}]}
{"channel":"book","type":"update","data":[{"symbol":"ETH/USD","bids":[{"price":3796.06,"qty":1.00000000}],"asks":[],"checksum":2382193498,"timestamp":"2024-06-01T17:52:42.348288Z"}]}
{"channel":"book","type":"update","data":[{"symbol":"ETH/USD","bids":[],"asks":[{"price":3796.47,"qty":26.34029963}],"checksum":41896793,"timestamp":"2024-06-01T17:52:42.348857Z"}]}
{"channel":"book","type":"update","data":[{"symbol":"ETH/USD","bids":[{"price":3796.09,"qty":26.34286657}],"asks":[],"checksum":2466272111,"timestamp":"2024-06-01T17:52:42.475190Z"}]}
{"channel":"book","type":"update","data":[{"symbol":"ETH/USD","bids":[],"asks":[{"price":3796.88,"qty":0.00000000},{"price":3797.49,"qty":2.13800000}],"checksum":4246668009,"timestamp":"2024-06-01T17:52:42.514355Z"}]}
{"channel":"book","type":"update","data":[{"symbol":"ETH/USD","bids":[{"price":3796.09,"qty":0.00000000},{"price":3795.59,"qty":9.22320467}],"asks":[],"checksum":1982343886,"timestamp":"2024-06-01T17:52:42.520002Z"}]}
{"channel":"book","type":"update","data":[{"symbol":"ETH/USD","bids":[{"price":3796.11,"qty":26.34273221}],"asks":[],"checksum":1441497740,"timestamp":"2024-06-01T17:52:42.524982Z"}]}
{"channel":"book","type":"update","data":[{"symbol":"ETH/USD","bids":[],"asks":[{"price":3796.44,"qty":0.00000000},{"price":3797.71,"qty":10.43462302}],"checksum":4181961138,"timestamp":"2024-06-01T17:52:42.547064Z"}]}
{"channel":"book","type":"update","data":[{"symbol":"ETH/USD","bids":[{"price":3796.11,"qty":0.00000000},{"price":3795.59,"qty":9.22320467}],"asks":[],"checksum":1660572901,"timestamp":"2024-06-01T17:52:42.547146Z"}]}
{"channel":"book","type":"update","data":[{"symbol":"ETH/USD","bids":[],"asks":[{"price":3796.57,"qty":26.33962772}],"checksum":4242567310,"timestamp":"2024-06-01T17:52:42.553984Z"}]}
{"channel":"book","type":"update","data":[{"symbol":"ETH/USD","bids":[{"price":3795.72,"qty":3.95220467}],"asks":[],"checksum":57164470,"timestamp":"2024-06-01T17:52:42.554145Z"}]}
{"channel":"book","type":"update","data":[{"symbol":"ETH/USD","bids":[{"price":3795.86,"qty":26.34442955}],"asks":[],"checksum":1029937080,"timestamp":"2024-06-01T17:52:42.558875Z"}]}
{"channel":"book","type":"update","data":[{"symbol":"ETH/USD","bids":[{"price":3796.28,"qty":0.00000000},{"price":3795.59,"qty":9.22320467}],"asks":[],"checksum":1406633707,"timestamp":"2024-06-01T17:52:42.610357Z"}]}
{"channel":"book","type":"update","data":[{"symbol":"ETH/USD","bids":[{"price":3796.29,"qty":0.00000000},{"price":3795.58,"qty":0.34420830},{"price":3796.07,"qty":0.00936805}],"asks":[],"checksum":3428728529,"timestamp":"2024-06-01T17:52:42.675395Z"}]}
{"channel":"book","type":"update","data":[{"symbol":"ETH/USD","bids":[],"asks":[{"price":3797.00,"qty":1.85000000}],"checksum":1754688314,"timestamp":"2024-06-01T17:52:42.679503Z"}]}
{"channel":"book","type":"update","data":[{"symbol":"ETH/USD","bids":[{"price":3796.08,"qty":0.52685928}],"asks":[],"checksum":388627301,"timestamp":"2024-06-01T17:52:42.679772Z"}]}
{"channel":"book","type":"update","data":[{"symbol":"ETH/USD","bids":[{"price":3796.08,"qty":26.86982360}],"asks":[],"checksum":2546469390,"timestamp":"2024-06-01T17:52:42.680880Z"}]}
{"channel":"book","type":"update","data":[{"symbol":"ETH/USD","bids":[{"price":3795.69,"qty":3.00000000}],"asks":[],"checksum":832238023,"timestamp":"2024-06-01T17:52:42.682871Z"}]}
{"channel":"book","type":"update","data":[{"symbol":"ETH/USD","bids":[{"price":3796.09,"qty":15.80353051}],"asks":[],"checksum":787234898,"timestamp":"2024-06-01T17:52:42.683808Z"}]}
{"channel":"book","type":"update","data":[{"symbol":"ETH/USD","bids":[{"price":3796.08,"qty":0.52685928}],"asks":[],"checksum":2035009334,"timestamp":"2024-06-01T17:52:42.684697Z"}]}
{"channel":"book","type":"update","data":[{"symbol":"ETH/USD","bids":[{"price":3795.73,"qty":0.00000000},{"price":3795.69,"qty":3.00000000}],"asks":[],"checksum":1332900029,"timestamp":"2024-06-01T17:52:42.687535Z"}]}
{"channel":"book","type":"update","data":[{"symbol":"ETH/USD","bids":[{"price":3796.15,"qty":26.34243810}],"asks":[],"checksum":2342713819,"timestamp":"2024-06-01T17:52:42.743233Z"}]}
{"channel":"book","type":"update","data":[{"symbol":"ETH/USD","bids":[{"price":3796.07,"qty":0.00000000},{"price":3795.69,"qty":3.00000000},{"price":3796.16,"qty":0.00936783}],"asks":[],"checksum":2095620905,"timestamp":"2024-06-01T17:52:42.968896Z"}]}
{"channel":"book","type":"update","data":[{"symbol":"ETH/USD","bids":[{"price":3796.08,"qty":0.00000000},{"price":3795.69,"qty":3.00000000},{"price":3796.17,"qty":0.52684679}],"asks":[],"checksum":3324527980,"timestamp":"2024-06-01T17:52:43.001470Z"}]}
{"channel":"book","type":"update","data":[{"symbol":"ETH/USD","bids":[],"asks":[{"price":3796.37,"qty":0.00000000},{"price":3797.49,"qty":2.13800000}],"checksum":557997333,"timestamp":"2024-06-01T17:52:43.070183Z"}]}
{"channel":"book","type":"update","data":[{"symbol":"ETH/USD","bids":[{"price":3795.95,"qty":3.95105954}],"asks":[],"checksum":3427231399,"timestamp":"2024-06-01T17:52:43.075910Z"}]}
{"channel":"book","type":"update","data":[{"symbol":"ETH/USD","bids":[{"price":3796.15,"qty":0.00000000},{"price":3795.72,"qty":3.95220467}],"asks":[],"checksum":1940259980,"timestamp":"2024-06-01T17:52:43.080386Z"}]}
{"channel":"book","type":"update","data":[{"symbol":"ETH/USD","bids":[],"asks":[{"price":3796.57,"qty":0.00000000},{"price":3797.91,"qty":10.43462302}],"checksum":3638851666,"timestamp":"2024-06-01T17:52:43.080500Z"}]}
{"channel":"book","type":"update","data":[{"symbol":"ETH/USD","bids":[],"asks":[{"price":3796.47,"qty":0.00000000},{"price":3797.94,"qty":0.52697311}],"checksum":421383776,"timestamp":"2024-06-01T17:52:43.080509Z"}]}
{"channel":"book","type":"update","data":[{"symbol":"ETH/USD","bids":[],"asks":[{"price":3797.94,"qty":0.00000000},{"price":3797.97,"qty":3.00000000},{"price":3796.73,"qty":0.52676908}],"checksum":2352339430,"timestamp":"2024-06-01T17:52:43.085317Z"}]}
{"channel":"book","type":"update","data":[{"symbol":"ETH/USD","bids":[],"asks":[{"price":3796.74,"qty":0.00000000},{"price":3797.97,"qty":3.00000000}],"checksum":2893456715,"timestamp":"2024-06-01T17:52:43.090758Z"}]}
{"channel":"book","type":"update","data":[{"symbol":"ETH/USD","bids":[],"asks":[{"price":3796.63,"qty":26.33915818}],"checksum":2276251195,"timestamp":"2024-06-01T17:52:43.094960Z"}]}
{"channel":"book","type":"update","data":[{"symbol":"ETH/USD","bids":[{"price":3796.29,"qty":26.34143897}],"asks":[],"checksum":1030428256,"timestamp":"2024-06-01T17:52:43.094976Z"}]}
{"channel":"book","type":"update","data":[{"symbol":"ETH/USD","bids":[],"asks":[{"price":3796.72,"qty":26.33852377}],"checksum":1376559382,"timestamp":"2024-06-01T17:52:43.094999Z"}]}
{"channel":"book","type":"update","data":[{"symbol":"ETH/USD","bids":[],"asks":[{"price":3797.22,"qty":27.06421348}],"checksum":1975620506,"timestamp":"2024-06-01T17:52:43.095117Z"}]}
{"channel":"book","type":"update","data":[{"symbol":"ETH/USD","bids":[{"price":3796.18,"qty":26.34227038}],"asks":[],"checksum":345534450,"timestamp":"2024-06-01T17:52:43.095159Z"}]}
{"channel":"book","type":"update","data":[{"symbol":"ETH/USD","bids":[],"asks":[{"price":3796.63,"qty":0.00000000},{"price":3797.91,"qty":10.43462302}],"checksum":2817461289,"timestamp":"2024-06-01T17:52:43.102629Z"}]}
{"channel":"book","type":"update","data":[{"symbol":"ETH/USD","bids":[{"price":3796.18,"qty":0.00000000},{"price":3795.74,"qty":0.00537780}],"asks":[],"checksum":4280945020,"timestamp":"2024-06-01T17:52:43.108730Z"}]}
{"channel":"book","type":"update","data":[{"symbol":"ETH/USD","bids":[],"asks":[{"price":3796.72,"qty":0.00000000},{"price":3797.97,"qty":3.00000000}],"checksum":2579002941,"timestamp":"2024-06-01T17:52:43.108765Z"}]}
{"channel":"book","type":"update","data":[{"symbol":"ETH/USD","bids":[{"price":3796.32,"qty":26.34123602}],"asks":[],"checksum":1253105842,"timestamp":"2024-06-01T17:52:43.150846Z"}]}
{"channel":"book","type":"update","data":[{"symbol":"ETH/USD","bids":[],"asks":[{"price":3796.64,"qty":26.33913025}],"checksum":2399659159,"timestamp":"2024-06-01T17:52:43.150868Z"}]}
{"channel":"book","type":"update","data":[{"symbol":"ETH/USD","bids":[],"asks":[{"price":3796.73,"qty":0.00000000},{"price":3797.97,"qty":3.00000000}],"checksum":3198089827,"timestamp":"2024-06-01T17:52:43.154686Z"}]}
{"channel":"book","type":"update","data":[{"symbol":"ETH/USD","bids":[{"price":3796.18,"qty":0.76217069}],"asks":[],"checksum":1253441286,"timestamp":"2024-06-01T17:52:43.200837Z"}]}
{"channel":"book","type":"update","data":[{"symbol":"ETH/USD","bids":[{"price":3796.18,"qty":1.10637899}],"asks":[],"checksum":1637107547,"timestamp":"2024-06-01T17:52:43.226771Z"}]}
{"channel":"book","type":"update","data":[{"symbol":"ETH/USD","bids":[{"price":3796.16,"qty":0.00000000},{"price":3795.86,"qty":26.34442955},{"price":3796.33,"qty":0.00936741}],"asks":[],"checksum":1294590847,"timestamp":"2024-06-01T17:52:43.300071Z"}]}
{"channel":"book","type":"update","data":[{"symbol":"ETH/USD","bids":[],"asks":[{"price":3796.64,"qty":0.00000000},{"price":3798.01,"qty":0.52676908}],"checksum":1751240315,"timestamp":"2024-06-01T17:52:43.385149Z"}]}
{"channel":"book","type":"update","data":[{"symbol":"ETH/USD","bids":[{"price":3796.32,"qty":0.00000000},{"price":3795.86,"qty":26.34442955}],"asks":[],"checksum":2220278931,"timestamp":"2024-06-01T17:52:43.385187Z"}]}
{"channel":"book","type":"update","data":[{"symbol":"ETH/USD","bids":[],"asks":[{"price":3796.76,"qty":3.00000000}],"checksum":1330684904,"timestamp":"2024-06-01T17:52:43.388929Z"}]}
{"channel":"book","type":"update","data":[{"symbol":"ETH/USD","bids":[],"asks":[{"price":3796.65,"qty":26.33902696}],"checksum":1914531822,"timestamp":"2024-06-01T17:52:43.391177Z"}]}
{"channel":"book","type":"update","data":[{"symbol":"ETH/USD","bids":[{"price":3796.34,"qty":26.34116017}],"asks":[],"checksum":2754413222,"timestamp":"2024-06-01T17:52:43.391293Z"}]}
{"channel":"book","type":"update","data":[{"symbol":"ETH/USD","bids":[],"asks":[{"price":3796.93,"qty":26.33706705}],"checksum":2022375193,"timestamp":"2024-06-01T17:52:43.391306Z"}]}
{"channel":"book","type":"update","data":[{"symbol":"ETH/USD","bids":[],"asks":[{"price":3796.96,"qty":0.00000000},{"price":3797.91,"qty":10.43462302}],"checksum":356715019,"timestamp":"2024-06-01T17:52:43.393385Z"}]}
{"channel":"book","type":"update","data":[{"symbol":"ETH/USD","bids":[],"asks":[{"price":3796.63,"qty":3.00000000}],"checksum":1411999810,"timestamp":"2024-06-01T17:52:43.536704Z"}]}
{"channel":"book","type":"update","data":[{"symbol":"ETH/USD","bids":[],"asks":[{"price":3797.00,"qty":0.00000000},{"price":3797.91,"qty":10.43462302}],"checksum":28786730,"timestamp":"2024-06-01T17:52:43.542715Z"}]}
{"channel":"book","type":"update","data":[{"symbol":"ETH/USD","bids":[{"price":3796.34,"qty":0.00000000},{"price":3795.86,"qty":26.34442955}],"asks":[],"checksum":3615960418,"timestamp":"2024-06-01T17:52:43.544705Z"}]}
{"channel":"book","type":"update","data":[{"symbol":"ETH/USD","bids":[{"price":3796.29,"qty":0.00000000},{"price":3795.74,"qty":0.00537780}],"asks":[],"checksum":1915799820,"timestamp":"2024-06-01T17:52:43.544880Z"}]}
{"channel":"book","type":"update","data":[{"symbol":"ETH/USD","bids":[{"price":3795.86,"qty":0.00000000},{"price":3795.72,"qty":3.95220467}],"asks":[],"checksum":1982089742,"timestamp":"2024-06-01T17:52:43.545040Z"}]}
{"channel":"book","type":"update","data":[{"symbol":"ETH/USD","bids":[],"asks":[{"price":3796.56,"qty":26.33966705}],"checksum":536336186,"timestamp":"2024-06-01T17:52:43.551649Z"}]}
{"channel":"book","type":"update","data":[{"symbol":"ETH/USD","bids":[{"price":3796.21,"qty":26.34201798}],"asks":[],"checksum":3118803179,"timestamp":"2024-06-01T17:52:43.551737Z"}]}
{"channel":"book","type":"update","data":[{"symbol":"ETH/USD","bids":[{"price":3796.24,"qty":26.34178956}],"asks":[],"checksum":2446235469,"timestamp":"2024-06-01T17:52:43.551822Z"}]}
{"channel":"book","type":"update","data":[{"symbol":"ETH/USD","bids":[],"asks":[{"price":3796.51,"qty":3.00000000}],"checksum":4122963635,"timestamp":"2024-06-01T17:52:43.555084Z"}]}
{"channel":"book","type":"update","data":[{"symbol":"ETH/USD","bids":[],"asks":[{"price":3796.76,"qty":0.00000000},{"price":3797.49,"qty":2.13800000}],"checksum":1798147222,"timestamp":"2024-06-01T17:52:43.555540Z"}]}
{"channel":"book","type":"update","data":[{"symbol":"ETH/USD","bids":[{"price":3796.24,"qty":0.00000000},{"price":3795.74,"qty":0.00537780}],"asks":[],"checksum":1645971235,"timestamp":"2024-06-01T17:52:43.561618Z"}]}
{"channel":"book","type":"update","data":[{"symbol":"ETH/USD","bids":[],"asks":[{"price":3796.93,"qty":0.00000000},{"price":3797.91,"qty":10.43462302}],"checksum":2624458313,"timestamp":"2024-06-01T17:52:43.561642Z"}]}
{"channel":"book","type":"update","data":[{"symbol":"ETH/USD","bids":[],"asks":[{"price":3796.65,"qty":0.00000000},{"price":3797.97,"qty":3.00000000}],"checksum":3809371563,"timestamp":"2024-06-01T17:52:43.561683Z"}]}
{"channel":"book","type":"update","data":[{"symbol":"ETH/USD","bids":[],"asks":[{"price":3796.56,"qty":0.00000000},{"price":3798.01,"qty":0.52676908}],"checksum":2223493770,"timestamp":"2024-06-01T17:52:43.561694Z"}]}
{"channel":"book","type":"update","data":[{"symbol":"ETH/USD","bids":[],"asks":[{"price":3796.51,"qty":0.00000000},{"price":3798.02,"qty":0.01092321}],"checksum":411193343,"timestamp":"2024-06-01T17:52:43.565228Z"}]}
{"channel":"book","type":"update","data":[{"symbol":"ETH/USD","bids":[{"price":3795.92,"qty":26.34402851}],"asks":[],"checksum":1984210038,"timestamp":"2024-06-01T17:52:43.566266Z"}]}
{"channel":"book","type":"update","data":[{"symbol":"ETH/USD","bids":[],"asks":[{"price":3796.79,"qty":26.33804183}],"checksum":2449530499,"timestamp":"2024-06-01T17:52:43.566337Z"}]}
{"channel":"book","type":"update","data":[{"symbol":"ETH/USD","bids":[{"price":3796.05,"qty":0.00000000},{"price":3795.74,"qty":0.00537780}],"asks":[],"checksum":4146774414,"timestamp":"2024-06-01T17:52:43.593815Z"}]}
{"channel":"book","type":"update","data":[{"symbol":"ETH/USD","bids":[{"price":3796.33,"qty":0.00000000},{"price":3795.72,"qty":3.95220467},{"price":3796.22,"qty":0.00936768}],"asks":[],"checksum":1779850903,"timestamp":"2024-06-01T17:52:43.604785Z"}]}
{"channel":"book","type":"update","data":[{"symbol":"ETH/USD","bids":[],"asks":[{"price":3797.10,"qty":1.85000000}],"checksum":564799925,"timestamp":"2024-06-01T17:52:43.672503Z"}]}
{"channel":"book","type":"update","data":[{"symbol":"ETH/USD","bids":[{"price":3796.22,"qty":0.00000000},{"price":3795.72,"qty":3.95220467},{"price":3796.23,"qty":0.00936765}],"asks":[],"checksum":2499818017,"timestamp":"2024-06-01T17:52:43.673332Z"}]}
{"channel":"book","type":"update","data":[{"symbol":"ETH/USD","bids":[],"asks":[{"price":3797.49,"qty":0.00000000},{"price":3798.01,"qty":0.52676908}],"checksum":886855486,"timestamp":"2024-06-01T17:52:43.717519Z"}]}
{"channel":"book","type":"update","data":[{"symbol":"ETH/USD","bids":[{"price":3796.23,"qty":0.00000000},{"price":3795.72,"qty":3.95220467},{"price":3796.22,"qty":0.00936768}],"asks":[],"checksum":2155236522,"timestamp":"2024-06-01T17:52:43.739868Z"}]}
{"channel":"book","type":"update","data":[{"symbol":"ETH/USD","bids":[{"price":3795.77,"qty":3.40263856}],"asks":[],"checksum":602948353,"timestamp":"2024-06-01T17:52:43.746742Z"}]}
{"channel":"book","type":"update","data":[{"symbol":"ETH/USD","bids":[{"price":3796.25,"qty":26.34171551}],"asks":[],"checksum":1362809866,"timestamp":"2024-06-01T17:52:43.786773Z"}]}
{"channel":"book","type":"update","data":[{"symbol":"ETH/USD","bids":[],"asks":[{"price":3796.53,"qty":26.33990676}],"checksum":1551302073,"timestamp":"2024-06-01T17:52:43.786819Z"}]}
{"channel":"book","type":"update","data":[{"symbol":"ETH/USD","bids":[{"price":3796.25,"qty":0.00000000},{"price":3795.77,"qty":3.40263856}],"asks":[],"checksum":45338251,"timestamp":"2024-06-01T17:52:43.794203Z"}]}
{"channel":"book","type":"update","data":[{"symbol":"ETH/USD","bids":[],"asks":[{"price":3796.53,"qty":0.00000000},{"price":3798.01,"qty":0.52676908}],"checksum":602948353,"timestamp":"2024-06-01T17:52:43.794307Z"}]}
{"channel":"book","type":"update","data":[{"symbol":"ETH/USD","bids":[],"asks":[{"price":3796.68,"qty":26.33885833}],"checksum":4162813632,"timestamp":"2024-06-01T17:52:43.799643Z"}]}
{"channel":"book","type":"update","data":[{"symbol":"ETH/USD","bids":[],"asks":[{"price":3797.09,"qty":5.13800000}],"checksum":509341575,"timestamp":"2024-06-01T17:52:43.816145Z"}]}
{"channel":"book","type":"update","data":[{"symbol":"ETH/USD","bids":[],"asks":[{"price":3796.68,"qty":0.00000000},{"price":3798.01,"qty":0.52676908}],"checksum":848994579,"timestamp":"2024-06-01T17:52:43.836266Z"}]}
{"channel":"book","type":"update","data":[{"symbol":"ETH/USD","bids":[{"price":3796.23,"qty":26.34192343}],"asks":[],"checksum":2971988064,"timestamp":"2024-06-01T17:52:43.840890Z"}]}
{"channel":"book","type":"update","data":[{"symbol":"ETH/USD","bids":[],"asks":[{"price":3796.56,"qty":26.33968788}],"checksum":1062451768,"timestamp":"2024-06-01T17:52:43.840941Z"}]}
{"channel":"book","type":"update","data":[{"symbol":"ETH/USD","bids":[{"price":3796.23,"qty":0.00000000},{"price":3795.77,"qty":3.40263856}],"asks":[],"checksum":4215210126,"timestamp":"2024-06-01T17:52:43.846680Z"}]}
{"channel":"book","type":"update","data":[{"symbol":"ETH/USD","bids":[],"asks":[{"price":3796.62,"qty":26.33921751}],"checksum":2143173922,"timestamp":"2024-06-01T17:52:43.962522Z"}]}
{"channel":"book","type":"update","data":[{"symbol":"ETH/USD","bids":[],"asks":[{"price":3796.56,"qty":0.00000000},{"price":3797.97,"qty":3.00000000}],"checksum":4211359117,"timestamp":"2024-06-01T17:52:43.962637Z"}]}
{"channel":"book","type":"update","data":[{"symbol":"ETH/USD","bids":[{"price":3796.26,"qty":26.34167072}],"asks":[],"checksum":1307114556,"timestamp":"2024-06-01T17:52:43.962647Z"}]}
{"channel":"book","type":"update","data":[{"symbol":"ETH/USD","bids":[],"asks":[{"price":3796.60,"qty":3.00000000}],"checksum":1675807187,"timestamp":"2024-06-01T17:52:43.966994Z"}]}
{"channel":"book","type":"update","data":[{"symbol":"ETH/USD","bids":[{"price":3796.26,"qty":0.00000000},{"price":3795.77,"qty":3.40263856}],"asks":[],"checksum":1161581552,"timestamp":"2024-06-01T17:52:43.968084Z"}]}
{"channel":"book","type":"update","data":[{"symbol":"ETH/USD","bids":[{"price":3796.22,"qty":0.00000000},{"price":3795.74,"qty":0.00537780},{"price":3796.27,"qty":0.00936756}],"asks":[],"checksum":571568997,"timestamp":"2024-06-01T17:52:44.011482Z"}]}
{"channel":"book","type":"update","data":[{"symbol":"ETH/USD","bids":[{"price":3796.27,"qty":0.00000000},{"price":3795.74,"qty":0.00537780},{"price":3796.22,"qty":0.00936768}],"asks":[],"checksum":1161581552,"timestamp":"2024-06-01T17:52:44.054980Z"}]}
{"channel":"book","type":"update","data":[{"symbol":"ETH/USD","bids":[{"price":3796.22,"qty":26.35129250}],"asks":[],"checksum":2256882864,"timestamp":"2024-06-01T17:52:44.085718Z"}]}
{"channel":"book","type":"update","data":[{"symbol":"ETH/USD","bids":[],"asks":[{"price":3796.59,"qty":26.33949296}],"checksum":1531880619,"timestamp":"2024-06-01T17:52:44.085870Z"}]}
{"channel":"book","type":"update","data":[{"symbol":"ETH/USD","bids":[],"asks":[{"price":3796.63,"qty":0.00000000},{"price":3797.91,"qty":10.43462302}],"checksum":3598795418,"timestamp":"2024-06-01T17:52:44.089321Z"}]}
{"channel":"book","type":"update","data":[{"symbol":"ETH/USD","bids":[],"asks":[{"price":3796.58,"qty":3.00000000}],"checksum":4070801072,"timestamp":"2024-06-01T17:52:44.089420Z"}]}
{"channel":"book","type":"update","data":[{"symbol":"ETH/USD","bids":[],"asks":[{"price":3796.59,"qty":0.00000000},{"price":3797.91,"qty":10.43462302}],"checksum":3375558867,"timestamp":"2024-06-01T17:52:44.091989Z"}]}
{"channel":"book","type":"update","data":[{"symbol":"ETH/USD","bids":[],"asks":[{"price":3796.60,"qty":0.00000000},{"price":3797.97,"qty":3.00000000}],"checksum":1876110785,"timestamp":"2024-06-01T17:52:44.096611Z"}]}
{"channel":"book","type":"update","data":[{"symbol":"ETH/USD","bids":[],"asks":[{"price":3796.55,"qty":26.33974847}],"checksum":204476687,"timestamp":"2024-06-01T17:52:44.281493Z"}]}
{"channel":"book","type":"update","data":[{"symbol":"ETH/USD","bids":[{"price":3796.21,"qty":0.00000000},{"price":3795.74,"qty":0.00537780}],"asks":[],"checksum":3121396888,"timestamp":"2024-06-01T17:52:44.281516Z"}]}
{"channel":"book","type":"update","data":[{"symbol":"ETH/USD","bids":[{"price":3796.22,"qty":0.00936768}],"asks":[],"checksum":3041763951,"timestamp":"2024-06-01T17:52:44.281609Z"}]}
{"channel":"book","type":"update","data":[{"symbol":"ETH/USD","bids":[],"asks":[{"price":3796.55,"qty":29.33974847}],"checksum":1795202867,"timestamp":"2024-06-01T17:52:44.285347Z"}]}
{"channel":"book","type":"update","data":[{"symbol":"ETH/USD","bids":[],"asks":[{"price":3796.54,"qty":3.00000000}],"checksum":4241687466,"timestamp":"2024-06-01T17:52:44.285558Z"}]}
{"channel":"book","type":"update","data":[{"symbol":"ETH/USD","bids":[],"asks":[{"price":3796.58,"qty":0.00000000},{"price":3797.91,"qty":10.43462302}],"checksum":2354392249,"timestamp":"2024-06-01T17:52:44.286024Z"}]}
{"channel":"book","type":"update","data":[{"symbol":"ETH/USD","bids":[{"price":3796.08,"qty":26.34293368}],"asks":[],"checksum":708679960,"timestamp":"2024-06-01T17:52:44.288239Z"}]}
{"channel":"book","type":"update","data":[{"symbol":"ETH/USD","bids":[{"price":3796.17,"qty":26.86913054}],"asks":[],"checksum":1908802589,"timestamp":"2024-06-01T17:52:44.288320Z"}]}
{"channel":"book","type":"update","data":[{"symbol":"ETH/USD","bids":[],"asks":[{"price":3796.53,"qty":2.40000000}],"checksum":2607131888,"timestamp":"2024-06-01T17:52:44.329588Z"}]}
{"channel":"book","type":"update","data":[{"symbol":"ETH/USD","bids":[],"asks":[{"price":3796.53,"qty":5.40000000}],"checksum":3551705594,"timestamp":"2024-06-01T17:52:44.333345Z"}]}
{"channel":"book","type":"update","data":[{"symbol":"ETH/USD","bids":[],"asks":[{"price":3796.55,"qty":26.33974847}],"checksum":1002200633,"timestamp":"2024-06-01T17:52:44.333667Z"}]}
{"channel":"book","type":"update","data":[{"symbol":"ETH/USD","bids":[],"asks":[{"price":3796.54,"qty":0.00000000},{"price":3797.91,"qty":10.43462302}],"checksum":2050011802,"timestamp":"2024-06-01T17:52:44.334490Z"}]}
{"channel":"book","type":"update","data":[{"symbol":"ETH/USD","bids":[{"price":3796.22,"qty":0.00000000},{"price":3795.74,"qty":0.00537780},{"price":3796.19,"qty":0.00936628}],"asks":[],"checksum":3163361639,"timestamp":"2024-06-01T17:52:44.351750Z"}]}
{"channel":"book","type":"update","data":[{"symbol":"ETH/USD","bids":[],"asks":[{"price":3796.53,"qty":2.40000000}],"checksum":1544564588,"timestamp":"2024-06-01T17:52:44.376009Z"}]}
{"channel":"book","type":"update","data":[{"symbol":"ETH/USD","bids":[{"price":3796.19,"qty":0.00000000},{"price":3795.74,"qty":0.00537780},{"price":3796.20,"qty":0.00936626}],"asks":[],"checksum":4173680942,"timestamp":"2024-06-01T17:52:44.433480Z"}]}
{"channel":"book","type":"update","data":[{"symbol":"ETH/USD","bids":[],"asks":[{"price":3796.55,"qty":0.00000000},{"price":3797.97,"qty":3.00000000}],"checksum":2519498027,"timestamp":"2024-06-01T17:52:44.447322Z"}]}
{"channel":"book","type":"update","data":[{"symbol":"ETH/USD","bids":[{"price":3796.08,"qty":0.00000000},{"price":3795.74,"qty":0.00537780}],"asks":[],"checksum":2570051669,"timestamp":"2024-06-01T17:52:44.447534Z"}]}
{"channel":"book","type":"update","data":[{"symbol":"ETH/USD","bids":[],"asks":[{"price":3796.59,"qty":26.33948589}],"checksum":1041738503,"timestamp":"2024-06-01T17:52:44.452223Z"}]}
{"channel":"book","type":"update","data":[{"symbol":"ETH/USD","bids":[{"price":3796.21,"qty":26.34206221}],"asks":[],"checksum":964889727,"timestamp":"2024-06-01T17:52:44.452381Z"}]}
{"channel":"book","type":"update","data":[{"symbol":"ETH/USD","bids":[],"asks":[{"price":3796.59,"qty":0.00000000},{"price":3797.97,"qty":3.00000000}],"checksum":2070225863,"timestamp":"2024-06-01T17:52:44.498675Z"}]}
{"channel":"book","type":"update","data":[{"symbol":"ETH/USD","bids":[],"asks":[{"price":3796.57,"qty":26.33956755}],"checksum":2798659059,"timestamp":"2024-06-01T17:52:44.503353Z"}]}
{"channel":"book","type":"update","data":[{"symbol":"ETH/USD","bids":[],"asks":[{"price":3796.57,"qty":0.00000000},{"price":3797.97,"qty":3.00000000}],"checksum":2070225863,"timestamp":"2024-06-01T17:52:44.663525Z"}]}
{"channel":"book","type":"update","data":[{"symbol":"ETH/USD","bids":[],"asks":[{"price":3797.91,"qty":0.00000000},{"price":3798.01,"qty":0.52676908},{"price":3797.96,"qty":10.43462302}],"checksum":1270373550,"timestamp":"2024-06-01T17:52:44.667000Z"}]}
{"channel":"book","type":"update","data":[{"symbol":"ETH/USD","bids":[],"asks":[{"price":3796.53,"qty":28.73989786}],"checksum":2814851453,"timestamp":"2024-06-01T17:52:44.667746Z"}]}
{"channel":"book","type":"update","data":[{"symbol":"ETH/USD","bids":[],"asks":[{"price":3796.53,"qty":2.40000000}],"checksum":1270373550,"timestamp":"2024-06-01T17:52:44.744887Z"}]}
{"channel":"book","type":"update","data":[{"symbol":"ETH/USD","bids":[{"price":3796.21,"qty":0.00000000},{"price":3795.74,"qty":0.00537780}],"asks":[],"checksum":1263601642,"timestamp":"2024-06-01T17:52:44.744909Z"}]}
{"channel":"book","type":"update","data":[{"symbol":"ETH/USD","bids":[],"asks":[{"price":3796.52,"qty":26.33996899}],"checksum":2486437755,"timestamp":"2024-06-01T17:52:44.750045Z"}]}
{"channel":"book","type":"update","data":[{"symbol":"ETH/USD","bids":[{"price":3796.19,"qty":26.34218145}],"asks":[],"checksum":405361712,"timestamp":"2024-06-01T17:52:44.750163Z"}]}
{"channel":"book","type":"update","data":[{"symbol":"ETH/USD","bids":[{"price":3796.21,"qty":15.80353051}],"asks":[],"checksum":390690746,"timestamp":"2024-06-01T17:52:44.791090Z"}]}
{"channel":"book","type":"update","data":[{"symbol":"ETH/USD","bids":[{"price":3795.94,"qty":0.00000000},{"price":3795.77,"qty":3.40263856}],"asks":[],"checksum":1146652184,"timestamp":"2024-06-01T17:52:44.794595Z"}]}
{"channel":"book","type":"update","data":[{"symbol":"ETH/USD","bids":[],"asks":[{"price":3796.52,"qty":0.00000000},{"price":3797.97,"qty":3.00000000}],"checksum":1329746046,"timestamp":"2024-06-01T17:52:44.835430Z"}]}
{"channel":"book","type":"update","data":[{"symbol":"ETH/USD","bids":[],"asks":[{"price":3796.50,"qty":26.34007962}],"checksum":1354960335,"timestamp":"2024-06-01T17:52:44.840748Z"}]}
{"channel":"book","type":"update","data":[{"symbol":"ETH/USD","bids":[],"asks":[{"price":3796.49,"qty":2.40000000}],"checksum":404699814,"timestamp":"2024-06-01T17:52:44.864076Z"}]}
{"channel":"book","type":"update","data":[{"symbol":"ETH/USD","bids":[],"asks":[{"price":3796.53,"qty":0.00000000},{"price":3797.96,"qty":10.43462302}],"checksum":3674384474,"timestamp":"2024-06-01T17:52:44.864097Z"}]}
{"channel":"book","type":"update","data":[{"symbol":"ETH/USD","bids":[{"price":3796.20,"qty":0.00000000},{"price":3795.74,"qty":0.00537780},{"price":3796.22,"qty":0.00936621}],"asks":[],"checksum":1652431165,"timestamp":"2024-06-01T17:52:44.953424Z"}]}
{"channel":"book","type":"update","data":[{"symbol":"ETH/USD","bids":[{"price":3796.22,"qty":0.33715322}],"asks":[],"checksum":2093449371,"timestamp":"2024-06-01T17:52:45.058673Z"}]}
{"channel":"book","type":"update","data":[{"symbol":"ETH/USD","bids":[],"asks":[{"price":3796.50,"qty":0.00000000},{"price":3797.97,"qty":3.00000000}],"checksum":2888648271,"timestamp":"2024-06-01T17:52:45.220700Z"}]}
{"channel":"book","type":"update","data":[{"symbol":"ETH/USD","bids":[],"asks":[{"price":3796.53,"qty":26.33990262}],"checksum":1791520227,"timestamp":"2024-06-01T17:52:45.224922Z"}]}
{"channel":"book","type":"update","data":[{"symbol":"ETH/USD","bids":[{"price":3796.19,"qty":0.00000000},{"price":3795.74,"qty":0.00537780}],"asks":[],"checksum":1285894296,"timestamp":"2024-06-01T17:52:45.235314Z"}]}
{"channel":"book","type":"update","data":[{"symbol":"ETH/USD","bids":[{"price":3796.22,"qty":26.67913182}],"asks":[],"checksum":94515676,"timestamp":"2024-06-01T17:52:45.241338Z"}]}
{"channel":"book","type":"update","data":[{"symbol":"ETH/USD","bids":[],"asks":[{"price":3796.53,"qty":0.00000000},{"price":3797.97,"qty":3.00000000}],"checksum":2484682458,"timestamp":"2024-06-01T17:52:45.246605Z"}]}
{"channel":"book","type":"update","data":[{"symbol":"ETH/USD","bids":[{"price":3796.22,"qty":0.33715322}],"asks":[],"checksum":1339800884,"timestamp":"2024-06-01T17:52:45.254940Z"}]}
{"channel":"book","type":"update","data":[{"symbol":"ETH/USD","bids":[],"asks":[{"price":3796.52,"qty":26.33996847}],"checksum":1253394017,"timestamp":"2024-06-01T17:52:45.277038Z"}]}
{"channel":"book","type":"update","data":[{"symbol":"ETH/USD","bids":[],"asks":[{"price":3796.52,"qty":0.00000000},{"price":3797.97,"qty":3.00000000}],"checksum":1339800884,"timestamp":"2024-06-01T17:52:45.324438Z"}]}
{"channel":"book","type":"update","data":[{"symbol":"ETH/USD","bids":[{"price":3796.19,"qty":26.34214984}],"asks":[],"checksum":2671016702,"timestamp":"2024-06-01T17:52:45.328943Z"}]}
{"channel":"book","type":"update","data":[{"symbol":"ETH/USD","bids":[],"asks":[{"price":3796.50,"qty":26.34005743}],"checksum":3228763474,"timestamp":"2024-06-01T17:52:45.328963Z"}]}
{"channel":"book","type":"update","data":[{"symbol":"ETH/USD","bids":[{"price":3796.18,"qty":0.76217069}],"asks":[],"checksum":1557068720,"timestamp":"2024-06-01T17:52:45.384690Z"}]}
{"channel":"book","type":"update","data":[{"symbol":"ETH/USD","bids":[{"price":3796.22,"qty":0.32778701},{"price":3796.23,"qty":0.00936618}],"asks":[],"checksum":2991555791,"timestamp":"2024-06-01T17:52:45.438628Z"}]}
{"channel":"book","type":"update","data":[{"symbol":"ETH/USD","bids":[{"price":3796.24,"qty":0.34420830}],"asks":[],"checksum":1363108072,"timestamp":"2024-06-01T17:52:46.072267Z"}]}
{"channel":"book","type":"update","data":[{"symbol":"ETH/USD","bids":[{"price":3796.23,"qty":0.00000000},{"price":3795.92,"qty":26.34402851},{"price":3796.25,"qty":0.00936613}],"asks":[],"checksum":3031411913,"timestamp":"2024-06-01T17:52:46.122618Z"}]}
{"channel":"book","type":"update","data":[{"symbol":"ETH/USD","bids":[],"asks":[{"price":3796.50,"qty":0.00000000},{"price":3797.97,"qty":3.00000000}],"checksum":335067847,"timestamp":"2024-06-01T17:52:46.161258Z"}]}
{"channel":"book","type":"update","data":[{"symbol":"ETH/USD","bids":[{"price":3796.19,"qty":0.00000000},{"price":3795.92,"qty":26.34402851}],"asks":[],"checksum":1231508903,"timestamp":"2024-06-01T17:52:46.166001Z"}]}
{"channel":"book","type":"update","data":[{"symbol":"ETH/USD","bids":[],"asks":[{"price":3796.62,"qty":0.00000000},{"price":3798.01,"qty":0.52676908}],"checksum":4009399595,"timestamp":"2024-06-01T17:52:46.166021Z"}]}
{"channel":"book","type":"update","data":[{"symbol":"ETH/USD","bids":[{"price":3796.17,"qty":0.52684679}],"asks":[],"checksum":2679594181,"timestamp":"2024-06-01T17:52:46.166274Z"}]}
{"channel":"book","type":"update","data":[{"symbol":"ETH/USD","bids":[{"price":3796.14,"qty":26.34254609}],"asks":[],"checksum":2067350015,"timestamp":"2024-06-01T17:52:46.170538Z"}]}
{"channel":"book","type":"update","data":[{"symbol":"ETH/USD","bids":[],"asks":[{"price":3796.46,"qty":26.34034149}],"checksum":3474367586,"timestamp":"2024-06-01T17:52:46.170553Z"}]}
{"channel":"book","type":"update","data":[{"symbol":"ETH/USD","bids":[{"price":3796.05,"qty":26.34315651}],"asks":[],"checksum":2256521529,"timestamp":"2024-06-01T17:52:46.170705Z"}]}
{"channel":"book","type":"update","data":[{"symbol":"ETH/USD","bids":[],"asks":[{"price":3797.22,"qty":0.72912968}],"checksum":2098093141,"timestamp":"2024-06-01T17:52:46.207847Z"}]}
{"channel":"book","type":"update","data":[{"symbol":"ETH/USD","bids":[],"asks":[{"price":3797.04,"qty":26.33634910}],"checksum":1390656541,"timestamp":"2024-06-01T17:52:46.213810Z"}]}
{"channel":"book","type":"update","data":[{"symbol":"ETH/USD","bids":[],"asks":[{"price":3797.96,"qty":0.00000000},{"price":3797.97,"qty":3.00000000},{"price":3797.91,"qty":10.43462302}],"checksum":2769214543,"timestamp":"2024-06-01T17:52:46.216891Z"}]}
{"channel":"book","type":"update","data":[{"symbol":"ETH/USD","bids":[],"asks":[{"price":3796.45,"qty":3.00000000}],"checksum":2820627599,"timestamp":"2024-06-01T17:52:46.239857Z"}]}
{"channel":"book","type":"update","data":[{"symbol":"ETH/USD","bids":[],"asks":[{"price":3796.46,"qty":0.00000000},{"price":3797.91,"qty":10.43462302}],"checksum":2775494763,"timestamp":"2024-06-01T17:52:46.283840Z"}]}
{"channel":"book","type":"update","data":[{"symbol":"ETH/USD","bids":[],"asks":[{"price":3796.45,"qty":29.34044455}],"checksum":3191101212,"timestamp":"2024-06-01T17:52:46.288063Z"}]}
{"channel":"book","type":"update","data":[{"symbol":"ETH/USD","bids":[],"asks":[{"price":3796.49,"qty":0.00000000},{"price":3797.97,"qty":3.00000000}],"checksum":2672158332,"timestamp":"2024-06-01T17:52:46.307248Z"}]}
{"channel":"book","type":"update","data":[{"symbol":"ETH/USD","bids":[],"asks":[{"price":3796.44,"qty":2.40000000}],"checksum":3338246770,"timestamp":"2024-06-01T17:52:46.307314Z"}]}
{"channel":"book","type":"update","data":[{"symbol":"ETH/USD","bids":[],"asks":[{"price":3796.44,"qty":5.40000000}],"checksum":1568924631,"timestamp":"2024-06-01T17:52:46.358056Z"}]}
{"channel":"book","type":"update","data":[{"symbol":"ETH/USD","bids":[],"asks":[{"price":3796.44,"qty":2.40000000}],"checksum":3338246770,"timestamp":"2024-06-01T17:52:46.546812Z"}]}
{"channel":"book","type":"update","data":[{"symbol":"ETH/USD","bids":[],"asks":[{"price":3796.45,"qty":26.34044455}],"checksum":1687055157,"timestamp":"2024-06-01T17:52:46.549958Z"}]}
{"channel":"book","type":"update","data":[{"symbol":"ETH/USD","bids":[{"price":3796.05,"qty":0.00000000},{"price":3795.95,"qty":3.95105954}],"asks":[],"checksum":2261695659,"timestamp":"2024-06-01T17:52:46.691509Z"}]}
{"channel":"book","type":"update","data":[{"symbol":"ETH/USD","bids":[],"asks":[{"price":3796.45,"qty":0.00000000},{"price":3797.97,"qty":3.00000000}],"checksum":2498220172,"timestamp":"2024-06-01T17:52:46.691617Z"}]}
{"channel":"book","type":"update","data":[{"symbol":"ETH/USD","bids":[],"asks":[{"price":3796.49,"qty":26.34016236}],"checksum":2698158382,"timestamp":"2024-06-01T17:52:46.696192Z"}]}
{"channel":"book","type":"update","data":[{"symbol":"ETH/USD","bids":[],"asks":[{"price":3796.58,"qty":26.33949686}],"checksum":2867376373,"timestamp":"2024-06-01T17:52:46.696211Z"}]}
{"channel":"book","type":"update","data":[{"symbol":"ETH/USD","bids":[{"price":3796.18,"qty":27.10441933}],"asks":[],"checksum":445184863,"timestamp":"2024-06-01T17:52:46.696317Z"}]}
{"channel":"book","type":"update","data":[{"symbol":"ETH/USD","bids":[{"price":3796.18,"qty":0.76217069}],"asks":[],"checksum":2867376373,"timestamp":"2024-06-01T17:52:46.994593Z"}]}
{"channel":"book","type":"update","data":[{"symbol":"ETH/USD","bids":[],"asks":[{"price":3796.49,"qty":0.00000000},{"price":3797.91,"qty":10.43462302}],"checksum":4105435094,"timestamp":"2024-06-01T17:52:46.994657Z"}]}
{"channel":"book","type":"update","data":[{"symbol":"ETH/USD","bids":[{"price":3796.26,"qty":15.80386352}],"asks":[],"checksum":1144315291,"timestamp":"2024-06-01T17:52:46.999087Z"}]}
{"channel":"book","type":"update","data":[{"symbol":"ETH/USD","bids":[],"asks":[{"price":3796.51,"qty":26.33999657}],"checksum":1438986838,"timestamp":"2024-06-01T17:52:46.999335Z"}]}
{"channel":"book","type":"update","data":[{"symbol":"ETH/USD","bids":[{"price":3796.20,"qty":26.34209753}],"asks":[],"checksum":3609303392,"timestamp":"2024-06-01T17:52:46.999408Z"}]}
{"channel":"book","type":"update","data":[{"symbol":"ETH/USD","bids":[{"price":3796.17,"qty":0.00000000},{"price":3796.06,"qty":1.00000000},{"price":3796.43,"qty":0.52681071}],"asks":[],"checksum":3199648729,"timestamp":"2024-06-01T17:52:47.001597Z"}]}
{"channel":"book","type":"update","data":[{"symbol":"ETH/USD","bids":[{"price":3796.09,"qty":0.00000000},{"price":3796.06,"qty":1.00000000}],"asks":[],"checksum":988766943,"timestamp":"2024-06-01T17:52:47.003041Z"}]}
{"channel":"book","type":"update","data":[{"symbol":"ETH/USD","bids":[{"price":3796.25,"qty":0.00000000},{"price":3795.95,"qty":3.95105954},{"price":3796.27,"qty":0.00936605}],"asks":[],"checksum":631682596,"timestamp":"2024-06-01T17:52:47.055925Z"}]}
{"channel":"book","type":"update","data":[{"symbol":"ETH/USD","bids":[{"price":3796.22,"qty":0.00000000},{"price":3795.95,"qty":3.95105954}],"asks":[],"checksum":3052022244,"timestamp":"2024-06-01T17:52:47.216908Z"}]}
{"channel":"book","type":"update","data":[{"symbol":"ETH/USD","bids":[{"price":3796.20,"qty":0.00000000},{"price":3795.92,"qty":26.34402851}],"asks":[],"checksum":846839629,"timestamp":"2024-06-01T17:52:47.284994Z"}]}
{"channel":"book","type":"update","data":[{"symbol":"ETH/USD","bids":[],"asks":[{"price":3796.51,"qty":0.00000000},{"price":3797.91,"qty":10.43462302}],"checksum":3619549359,"timestamp":"2024-06-01T17:52:47.285074Z"}]}
{"channel":"book","type":"update","data":[{"symbol":"ETH/USD","bids":[],"asks":[{"price":3796.50,"qty":26.34009829}],"checksum":1201829476,"timestamp":"2024-06-01T17:52:47.289975Z"}]}
{"channel":"book","type":"update","data":[{"symbol":"ETH/USD","bids":[{"price":3796.18,"qty":27.10441231}],"asks":[],"checksum":2991080076,"timestamp":"2024-06-01T17:52:47.290074Z"}]}
{"channel":"book","type":"update","data":[{"symbol":"ETH/USD","bids":[],"asks":[{"price":3796.50,"qty":0.00000000},{"price":3797.91,"qty":10.43462302}],"checksum":2661153283,"timestamp":"2024-06-01T17:52:47.312168Z"}]}
{"channel":"book","type":"update","data":[{"symbol":"ETH/USD","bids":[{"price":3796.18,"qty":0.76217069}],"asks":[],"checksum":3619549359,"timestamp":"2024-06-01T17:52:47.314362Z"}]}
{"channel":"book","type":"update","data":[{"symbol":"ETH/USD","bids":[],"asks":[{"price":3796.47,"qty":26.34032220}],"checksum":1757032701,"timestamp":"2024-06-01T17:52:47.366469Z"}]}
{"channel":"book","type":"update","data":[{"symbol":"ETH/USD","bids":[{"price":3796.17,"qty":26.34232592}],"asks":[],"checksum":2473181872,"timestamp":"2024-06-01T17:52:47.366508Z"}]}
{"channel":"book","type":"update","data":[{"symbol":"ETH/USD","bids":[{"price":3796.43,"qty":0.00000000},{"price":3795.92,"qty":26.34402851}],"asks":[],"checksum":834424138,"timestamp":"2024-06-01T17:52:47.370554Z"}]}
{"channel":"book","type":"update","data":[{"symbol":"ETH/USD","bids":[],"asks":[{"price":3796.47,"qty":0.00000000},{"price":3797.91,"qty":10.43462302}],"checksum":575999787,"timestamp":"2024-06-01T17:52:47.370657Z"}]}
{"channel":"book","type":"update","data":[{"symbol":"ETH/USD","bids":[],"asks":[{"price":3796.44,"qty":0.00000000},{"price":3797.97,"qty":3.00000000}],"checksum":1989148786,"timestamp":"2024-06-01T17:52:47.616295Z"}]}
{"channel":"book","type":"update","data":[{"symbol":"ETH/USD","bids":[{"price":3796.17,"qty":0.00000000},{"price":3795.77,"qty":3.40263856}],"asks":[],"checksum":2473356237,"timestamp":"2024-06-01T17:52:47.616733Z"}]}
{"channel":"book","type":"update","data":[{"symbol":"ETH/USD","bids":[{"price":3796.23,"qty":26.34190969}],"asks":[],"checksum":3953639138,"timestamp":"2024-06-01T17:52:47.625946Z"}]}
{"channel":"book","type":"update","data":[{"symbol":"ETH/USD","bids":[],"asks":[{"price":3796.55,"qty":26.33976638}],"checksum":1761465503,"timestamp":"2024-06-01T17:52:47.626010Z"}]}
{"channel":"book","type":"update","data":[{"symbol":"ETH/USD","bids":[],"asks":[{"price":3796.55,"qty":0.00000000},{"price":3797.97,"qty":3.00000000}],"checksum":3953639138,"timestamp":"2024-06-01T17:52:47.632185Z"}]}
{"channel":"book","type":"update","data":[{"symbol":"ETH/USD","bids":[{"price":3796.23,"qty":0.00000000},{"price":3795.77,"qty":3.40263856}],"asks":[],"checksum":2473356237,"timestamp":"2024-06-01T17:52:47.632289Z"}]}
{"channel":"book","type":"update","data":[{"symbol":"ETH/USD","bids":[],"asks":[{"price":3796.55,"qty":26.33976028}],"checksum":794134662,"timestamp":"2024-06-01T17:52:47.683607Z"}]}
{"channel":"book","type":"update","data":[{"symbol":"ETH/USD","bids":[{"price":3796.23,"qty":26.34190969}],"asks":[],"checksum":169156377,"timestamp":"2024-06-01T17:52:47.683786Z"}]}
{"channel":"book","type":"update","data":[{"symbol":"ETH/USD","bids":[{"price":3796.28,"qty":0.32778701}],"asks":[],"checksum":3677735728,"timestamp":"2024-06-01T17:52:47.686142Z"}]}
{"channel":"book","type":"update","data":[{"symbol":"ETH/USD","bids":[],"asks":[{"price":3796.55,"qty":0.00000000},{"price":3797.97,"qty":3.00000000}],"checksum":2220202625,"timestamp":"2024-06-01T17:52:47.698421Z"}]}
{"channel":"book","type":"update","data":[{"symbol":"ETH/USD","bids":[],"asks":[{"price":3797.09,"qty":3.00000000}],"checksum":1229959281,"timestamp":"2024-06-01T17:52:47.699043Z"}]}
{"channel":"book","type":"update","data":[{"symbol":"ETH/USD","bids":[{"price":3796.14,"qty":0.00000000},{"price":3795.92,"qty":26.34402851}],"asks":[],"checksum":3813015185,"timestamp":"2024-06-01T17:52:47.723695Z"}]}
{"channel":"book","type":"update","data":[{"symbol":"ETH/USD","bids":[],"asks":[{"price":3796.58,"qty":0.00000000},{"price":3798.01,"qty":0.52676908}],"checksum":1977116274,"timestamp":"2024-06-01T17:52:47.723764Z"}]}
{"channel":"book","type":"update","data":[{"symbol":"ETH/USD","bids":[],"asks":[{"price":3796.79,"qty":0.00000000},{"price":3798.02,"qty":0.01092321}],"checksum":3155462846,"timestamp":"2024-06-01T17:52:47.726978Z"}]}
{"channel":"book","type":"update","data":[{"symbol":"ETH/USD","bids":[],"asks":[{"price":3797.91,"qty":0.00000000},{"price":3798.03,"qty":0.01091807},{"price":3797.96,"qty":10.43462302}],"checksum":3356516898,"timestamp":"2024-06-01T17:52:47.727124Z"}]}
{"channel":"book","type":"update","data":[{"symbol":"ETH/USD","bids":[],"asks":[{"price":3796.79,"qty":3.00000000}],"checksum":2689122695,"timestamp":"2024-06-01T17:52:47.728274Z"}]}
{"channel":"book","type":"update","data":[{"symbol":"ETH/USD","bids":[],"asks":[{"price":3796.78,"qty":3.00000000}],"checksum":424991105,"timestamp":"2024-06-01T17:52:47.728382Z"}]}
{"channel":"book","type":"update","data":[{"symbol":"ETH/USD","bids":[],"asks":[{"price":3796.79,"qty":0.00000000},{"price":3798.01,"qty":0.52676908}],"checksum":1805480938,"timestamp":"2024-06-01T17:52:47.731333Z"}]}
{"channel":"book","type":"update","data":[{"symbol":"ETH/USD","bids":[],"asks":[{"price":3796.58,"qty":26.33954275}],"checksum":3820602273,"timestamp":"2024-06-01T17:52:47.734941Z"}]}
{"channel":"book","type":"update","data":[{"symbol":"ETH/USD","bids":[],"asks":[{"price":3796.78,"qty":29.33810755}],"checksum":2821454691,"timestamp":"2024-06-01T17:52:47.735097Z"}]}
{"channel":"book","type":"update","data":[{"symbol":"ETH/USD","bids":[{"price":3796.27,"qty":26.35098625}],"asks":[],"checksum":911054564,"timestamp":"2024-06-01T17:52:47.735133Z"}]}
{"channel":"book","type":"update","data":[{"symbol":"ETH/USD","bids":[],"asks":[{"price":3796.90,"qty":26.33733710}],"checksum":1904878736,"timestamp":"2024-06-01T17:52:47.735146Z"}]}
{"channel":"book","type":"update","data":[{"symbol":"ETH/USD","bids":[],"asks":[{"price":3797.09,"qty":0.00000000},{"price":3797.97,"qty":3.00000000}],"checksum":2427860445,"timestamp":"2024-06-01T17:52:47.738556Z"}]}
{"channel":"book","type":"update","data":[{"symbol":"ETH/USD","bids":[],"asks":[{"price":3796.78,"qty":26.33810755}],"checksum":2301649144,"timestamp":"2024-06-01T17:52:47.738642Z"}]}
{"channel":"book","type":"update","data":[{"symbol":"ETH/USD","bids":[],"asks":[{"price":3797.10,"qty":0.00000000},{"price":3798.01,"qty":0.52676908}],"checksum":1784108897,"timestamp":"2024-06-01T17:52:47.742621Z"}]}
{"channel":"book","type":"update","data":[{"symbol":"ETH/USD","bids":[],"asks":[{"price":3796.78,"qty":0.00000000},{"price":3798.02,"qty":0.01092321}],"checksum":4293171804,"timestamp":"2024-06-01T17:52:47.743720Z"}]}
{"channel":"book","type":"update","data":[{"symbol":"ETH/USD","bids":[{"price":3796.27,"qty":0.00936605}],"asks":[],"checksum":3896704464,"timestamp":"2024-06-01T17:52:47.743782Z"}]}
{"channel":"book","type":"update","data":[{"symbol":"ETH/USD","bids":[],"asks":[{"price":3796.58,"qty":0.00000000},{"price":3798.03,"qty":0.01091807}],"checksum":3074660831,"timestamp":"2024-06-01T17:52:47.743872Z"}]}
{"channel":"book","type":"update","data":[{"symbol":"ETH/USD","bids":[{"price":3796.18,"qty":0.00000000},{"price":3795.77,"qty":3.40263856}],"asks":[],"checksum":4096051536,"timestamp":"2024-06-01T17:52:47.744379Z"}]}
{"channel":"book","type":"update","data":[{"symbol":"ETH/USD","bids":[],"asks":[{"price":3796.94,"qty":0.00000000},{"price":3798.06,"qty":26.32929898}],"checksum":1863563659,"timestamp":"2024-06-01T17:52:47.744403Z"}]}
{"channel":"book","type":"update","data":[{"symbol":"ETH/USD","bids":[{"price":3795.92,"qty":0.00000000},{"price":3795.74,"qty":0.00537780}],"asks":[],"checksum":327955754,"timestamp":"2024-06-01T17:52:47.745219Z"}]}
{"channel":"book","type":"update","data":[{"symbol":"ETH/USD","bids":[{"price":3796.23,"qty":0.00000000},{"price":3795.72,"qty":3.95220467}],"asks":[],"checksum":1281334469,"timestamp":"2024-06-01T17:52:47.745227Z"}]}
{"channel":"book","type":"update","data":[{"symbol":"ETH/USD","bids":[],"asks":[{"price":3797.04,"qty":0.00000000},{"price":3798.12,"qty":0.15000000}],"checksum":2549054424,"timestamp":"2024-06-01T17:52:47.745234Z"}]}
{"channel":"book","type":"update","data":[{"symbol":"ETH/USD","bids":[{"price":3796.27,"qty":0.00000000},{"price":3795.67,"qty":3.00000000},{"price":3796.29,"qty":0.00936600}],"asks":[],"checksum":2562596884,"timestamp":"2024-06-01T17:52:47.745799Z"}]}
{"channel":"book","type":"update","data":[{"symbol":"ETH/USD","bids":[],"asks":[{"price":3797.22,"qty":0.00000000},{"price":3798.15,"qty":0.00985404}],"checksum":2376181249,"timestamp":"2024-06-01T17:52:47.746741Z"}]}
{"channel":"book","type":"update","data":[{"symbol":"ETH/USD","bids":[],"asks":[{"price":3797.95,"qty":4.30610000}],"checksum":984582275,"timestamp":"2024-06-01T17:52:47.748447Z"}]}
{"channel":"book","type":"update","data":[{"symbol":"ETH/USD","bids":[],"asks":[{"price":3796.90,"qty":0.00000000},{"price":3798.15,"qty":0.00985404}],"checksum":394334194,"timestamp":"2024-06-01T17:52:47.756626Z"}]}
{"channel":"book","type":"update","data":[{"symbol":"ETH/USD","bids":[],"asks":[{"price":3798.06,"qty":0.00000000},{"price":3798.18,"qty":1.05303757}],"checksum":1595444100,"timestamp":"2024-06-01T17:52:47.756708Z"}]}
{"channel":"book","type":"update","data":[{"symbol":"ETH/USD","bids":[],"asks":[{"price":3797.84,"qty":3.30000000}],"checksum":2856696533,"timestamp":"2024-06-01T17:52:47.760518Z"}]}
{"channel":"book","type":"update","data":[{"symbol":"ETH/USD","bids":[],"asks":[{"price":3797.47,"qty":6.00000000}],"checksum":3350519721,"timestamp":"2024-06-01T17:52:47.760722Z"}]}
{"channel":"book","type":"update","data":[{"symbol":"ETH/USD","bids":[{"price":3795.78,"qty":0.76333374}],"asks":[],"checksum":1828195020,"timestamp":"2024-06-01T17:52:47.761418Z"}]}
{"channel":"book","type":"update","data":[{"symbol":"ETH/USD","bids":[],"asks":[{"price":3797.46,"qty":1.00000000}],"checksum":2941491134,"timestamp":"2024-06-01T17:52:47.761433Z"}]}
{"channel":"book","type":"update","data":[{"symbol":"ETH/USD","bids":[],"asks":[{"price":3797.94,"qty":0.75770796}],"checksum":1911032000,"timestamp":"2024-06-01T17:52:47.761665Z"}]}
{"channel":"book","type":"update","data":[{"symbol":"ETH/USD","bids":[{"price":3796.06,"qty":27.34307450}],"asks":[],"checksum":3424267761,"timestamp":"2024-06-01T17:52:47.763055Z"}]}
{"channel":"book","type":"update","data":[{"symbol":"ETH/USD","bids":[],"asks":[{"price":3797.46,"qty":27.33340374}],"checksum":938007307,"timestamp":"2024-06-01T17:52:47.763109Z"}]}
{"channel":"book","type":"update","data":[{"symbol":"ETH/USD","bids":[{"price":3795.86,"qty":26.34448434}],"asks":[],"checksum":1520996544,"timestamp":"2024-06-01T17:52:47.763177Z"}]}
{"channel":"book","type":"update","data":[{"symbol":"ETH/USD","bids":[],"asks":[{"price":3797.28,"qty":3.00000000}],"checksum":2505107168,"timestamp":"2024-06-01T17:52:47.765640Z"}]}
{"channel":"book","type":"update","data":[{"symbol":"ETH/USD","bids":[],"asks":[{"price":3797.46,"qty":1.00000000}],"checksum":1223859022,"timestamp":"2024-06-01T17:52:47.772177Z"}]}
{"channel":"book","type":"update","data":[{"symbol":"ETH/USD","bids":[{"price":3795.87,"qty":0.00548922}],"asks":[],"checksum":2045277811,"timestamp":"2024-06-01T17:52:47.772725Z"}]}
{"channel":"book","type":"update","data":[{"symbol":"ETH/USD","bids":[],"asks":[{"price":3797.95,"qty":0.00000000},{"price":3798.03,"qty":0.01091807}],"checksum":2658579764,"timestamp":"2024-06-01T17:52:47.787116Z"}]}
{"channel":"book","type":"update","data":[{"symbol":"ETH/USD","bids":[{"price":3796.41,"qty":26.34063383}],"asks":[],"checksum":4117246317,"timestamp":"2024-06-01T17:52:47.794991Z"}]}
{"channel":"book","type":"update","data":[{"symbol":"ETH/USD","bids":[],"asks":[{"price":3797.40,"qty":2.13800000}],"checksum":2041497753,"timestamp":"2024-06-01T17:52:47.797604Z"}]}
{"channel":"book","type":"update","data":[{"symbol":"ETH/USD","bids":[],"asks":[{"price":3797.27,"qty":1.00000000}],"checksum":1790996367,"timestamp":"2024-06-01T17:52:47.800855Z"}]}
{"channel":"book","type":"update","data":[{"symbol":"ETH/USD","bids":[],"asks":[{"price":3796.72,"qty":26.33855586}],"checksum":2850912302,"timestamp":"2024-06-01T17:52:47.801117Z"}]}
{"channel":"book","type":"update","data":[{"symbol":"ETH/USD","bids":[],"asks":[{"price":3797.34,"qty":1.85000000}],"checksum":71890749,"timestamp":"2024-06-01T17:52:47.801202Z"}]}
{"channel":"book","type":"update","data":[{"symbol":"ETH/USD","bids":[],"asks":[{"price":3797.94,"qty":0.00000000},{"price":3797.97,"qty":3.00000000}],"checksum":778456747,"timestamp":"2024-06-01T17:52:47.804247Z"}]}
{"channel":"book","type":"update","data":[{"symbol":"ETH/USD","bids":[],"asks":[{"price":3797.09,"qty":3.00000000}],"checksum":4022913118,"timestamp":"2024-06-01T17:52:47.804542Z"}]}
{"channel":"book","type":"update","data":[{"symbol":"ETH/USD","bids":[],"asks":[{"price":3797.47,"qty":3.00000000}],"checksum":3493416580,"timestamp":"2024-06-01T17:52:47.804924Z"}]}
{"channel":"book","type":"update","data":[{"symbol":"ETH/USD","bids":[],"asks":[{"price":3796.72,"qty":0.00000000},{"price":3797.97,"qty":3.00000000}],"checksum":2090137583,"timestamp":"2024-06-01T17:52:47.866156Z"}]}
{"channel":"book","type":"update","data":[{"symbol":"ETH/USD","bids":[],"asks":[{"price":3797.27,"qty":0.00000000},{"price":3798.01,"qty":0.52676908}],"checksum":376948847,"timestamp":"2024-06-01T17:52:47.870316Z"}]}
{"channel":"book","type":"update","data":[{"symbol":"ETH/USD","bids":[],"asks":[{"price":3796.78,"qty":26.33816004}],"checksum":2108579177,"timestamp":"2024-06-01T17:52:47.871395Z"}]}
{"channel":"book","type":"update","data":[{"symbol":"ETH/USD","bids":[{"price":3796.30,"qty":26.34143771}],"asks":[],"checksum":224447607,"timestamp":"2024-06-01T17:52:47.871415Z"}]}
{"channel":"book","type":"update","data":[{"symbol":"ETH/USD","bids":[],"asks":[{"price":3797.64,"qty":0.72912968}],"checksum":1563875309,"timestamp":"2024-06-01T17:52:47.871904Z"}]}
{"channel":"book","type":"update","data":[{"symbol":"ETH/USD","bids":[],"asks":[{"price":3797.09,"qty":6.00000000}],"checksum":3831904563,"timestamp":"2024-06-01T17:52:47.873711Z"}]}
{"channel":"book","type":"update","data":[{"symbol":"ETH/USD","bids":[],"asks":[{"price":3797.28,"qty":0.00000000},{"price":3797.97,"qty":3.00000000}],"checksum":3885220142,"timestamp":"2024-06-01T17:52:47.873894Z"}]}
{"channel":"book","type":"update","data":[{"symbol":"ETH/USD","bids":[],"asks":[{"price":3796.77,"qty":2.40000000}],"checksum":1630197083,"timestamp":"2024-06-01T17:52:47.975707Z"}]}
{"channel":"book","type":"update","data":[{"symbol":"ETH/USD","bids":[],"asks":[{"price":3797.08,"qty":0.75770796}],"checksum":153662711,"timestamp":"2024-06-01T17:52:48.040762Z"}]}
{"channel":"book","type":"update","data":[{"symbol":"ETH/USD","bids":[{"price":3796.31,"qty":0.76333374}],"asks":[],"checksum":2177905199,"timestamp":"2024-06-01T17:52:48.142525Z"}]}
{"channel":"book","type":"update","data":[{"symbol":"ETH/USD","bids":[{"price":3796.41,"qty":0.00000000},{"price":3795.87,"qty":0.00548922}],"asks":[],"checksum":2286595978,"timestamp":"2024-06-01T17:52:48.177162Z"}]}
{"channel":"book","type":"update","data":[{"symbol":"ETH/USD","bids":[{"price":3796.30,"qty":0.00000000},{"price":3795.86,"qty":26.34448434}],"asks":[],"checksum":4169416340,"timestamp":"2024-06-01T17:52:48.182418Z"}]}
{"channel":"book","type":"update","data":[{"symbol":"ETH/USD","bids":[{"price":3796.43,"qty":26.34051147}],"asks":[],"checksum":345207747,"timestamp":"2024-06-01T17:52:48.187044Z"}]}
{"channel":"book","type":"update","data":[{"symbol":"ETH/USD","bids":[],"asks":[{"price":3797.08,"qty":27.09373459}],"checksum":2274679676,"timestamp":"2024-06-01T17:52:48.187120Z"}]}
{"channel":"book","type":"update","data":[{"symbol":"ETH/USD","bids":[],"asks":[{"price":3796.86,"qty":26.33758114}],"checksum":1584013035,"timestamp":"2024-06-01T17:52:48.187648Z"}]}
{"channel":"book","type":"update","data":[{"symbol":"ETH/USD","bids":[{"price":3796.05,"qty":3.00000000}],"asks":[],"checksum":1681333314,"timestamp":"2024-06-01T17:52:48.192702Z"}]}
{"channel":"book","type":"update","data":[{"symbol":"ETH/USD","bids":[],"asks":[{"price":3796.86,"qty":0.00000000},{"price":3797.84,"qty":3.30000000}],"checksum":1893945086,"timestamp":"2024-06-01T17:52:48.194810Z"}]}
{"channel":"book","type":"update","data":[{"symbol":"ETH/USD","bids":[{"price":3796.43,"qty":0.00000000},{"price":3795.87,"qty":0.00548922}],"asks":[],"checksum":477040898,"timestamp":"2024-06-01T17:52:48.194907Z"}]}
{"channel":"book","type":"update","data":[{"symbol":"ETH/USD","bids":[],"asks":[{"price":3796.77,"qty":5.40000000}],"checksum":1522734569,"timestamp":"2024-06-01T17:52:48.198180Z"}]}
{"channel":"book","type":"update","data":[{"symbol":"ETH/USD","bids":[{"price":3796.05,"qty":0.00000000},{"price":3795.86,"qty":26.34448434}],"asks":[],"checksum":1545404895,"timestamp":"2024-06-01T17:52:48.199147Z"}]}
{"channel":"book","type":"update","data":[{"symbol":"ETH/USD","bids":[],"asks":[{"price":3796.71,"qty":26.33862944}],"checksum":1900422623,"timestamp":"2024-06-01T17:52:48.201282Z"}]}
{"channel":"book","type":"update","data":[{"symbol":"ETH/USD","bids":[],"asks":[{"price":3796.71,"qty":0.00000000},{"price":3797.84,"qty":3.30000000}],"checksum":1545404895,"timestamp":"2024-06-01T17:52:48.206155Z"}]}
{"channel":"book","type":"update","data":[{"symbol":"ETH/USD","bids":[],"asks":[{"price":3796.76,"qty":3.00000000}],"checksum":287855882,"timestamp":"2024-06-01T17:52:48.209893Z"}]}
{"channel":"book","type":"update","data":[{"symbol":"ETH/USD","bids":[],"asks":[{"price":3797.09,"qty":3.00000000}],"checksum":3456545197,"timestamp":"2024-06-01T17:52:48.210333Z"}]}
{"channel":"book","type":"update","data":[{"symbol":"ETH/USD","bids":[{"price":3796.29,"qty":0.00000000},{"price":3795.82,"qty":3.70000000},{"price":3796.42,"qty":0.00936568}],"asks":[],"checksum":1564449441,"timestamp":"2024-06-01T17:52:48.216555Z"}]}
{"channel":"book","type":"update","data":[{"symbol":"ETH/USD","bids":[{"price":3796.24,"qty":0.00000000},{"price":3795.82,"qty":3.70000000}],"asks":[],"checksum":4042131380,"timestamp":"2024-06-01T17:52:48.228803Z"}]}
{"channel":"book","type":"update","data":[{"symbol":"ETH/USD","bids":[{"price":3796.38,"qty":26.34087673}],"asks":[],"checksum":4149241642,"timestamp":"2024-06-01T17:52:48.243420Z"}]}
{"channel":"book","type":"update","data":[{"symbol":"ETH/USD","bids":[],"asks":[{"price":3796.75,"qty":2.40000000}],"checksum":1031927915,"timestamp":"2024-06-01T17:52:48.285068Z"}]}
{"channel":"book","type":"update","data":[{"symbol":"ETH/USD","bids":[],"asks":[{"price":3796.77,"qty":3.00000000}],"checksum":1307212712,"timestamp":"2024-06-01T17:52:48.285100Z"}]}
{"channel":"book","type":"update","data":[{"symbol":"ETH/USD","bids":[{"price":3796.42,"qty":0.00000000},{"price":3795.82,"qty":3.70000000},{"price":3796.32,"qty":0.00936593}],"asks":[],"checksum":1231952112,"timestamp":"2024-06-01T17:52:48.285701Z"}]}
{"channel":"book","type":"update","data":[{"symbol":"ETH/USD","bids":[],"asks":[{"price":3796.77,"qty":0.00000000},{"price":3797.64,"qty":0.72912968}],"checksum":1901922328,"timestamp":"2024-06-01T17:52:48.288400Z"}]}
{"channel":"book","type":"update","data":[{"symbol":"ETH/USD","bids":[],"asks":[{"price":3796.69,"qty":3.00000000}],"checksum":1573087363,"timestamp":"2024-06-01T17:52:48.289036Z"}]}
{"channel":"book","type":"update","data":[{"symbol":"ETH/USD","bids":[{"price":3796.38,"qty":0.00000000},{"price":3795.82,"qty":3.70000000}],"asks":[],"checksum":3715287696,"timestamp":"2024-06-01T17:52:48.394816Z"}]}
{"channel":"book","type":"update","data":[{"symbol":"ETH/USD","bids":[],"asks":[{"price":3797.29,"qty":26.33458773}],"checksum":2355649692,"timestamp":"2024-06-01T17:52:48.399492Z"}]}
{"channel":"book","type":"update","data":[{"symbol":"ETH/USD","bids":[{"price":3796.36,"qty":26.34099791}],"asks":[],"checksum":2881109421,"timestamp":"2024-06-01T17:52:48.399523Z"}]}
{"channel":"book","type":"update","data":[{"symbol":"ETH/USD","bids":[],"asks":[{"price":3796.72,"qty":26.33855832}],"checksum":1444121897,"timestamp":"2024-06-01T17:52:48.399538Z"}]}
{"channel":"book","type":"update","data":[{"symbol":"ETH/USD","bids":[],"asks":[{"price":3796.69,"qty":0.00000000},{"price":3797.46,"qty":1.00000000}],"checksum":2467828627,"timestamp":"2024-06-01T17:52:48.403378Z"}]}
{"channel":"book","type":"update","data":[{"symbol":"ETH/USD","bids":[{"price":3796.36,"qty":0.00000000},{"price":3795.82,"qty":3.70000000}],"asks":[],"checksum":4135888446,"timestamp":"2024-06-01T17:52:48.478305Z"}]}
{"channel":"book","type":"update","data":[{"symbol":"ETH/USD","bids":[{"price":3796.37,"qty":26.34089781}],"asks":[],"checksum":3859061088,"timestamp":"2024-06-01T17:52:48.483396Z"}]}
{"channel":"book","type":"update","data":[{"symbol":"ETH/USD","bids":[],"asks":[{"price":3796.72,"qty":29.33855832}],"checksum":2215102850,"timestamp":"2024-06-01T17:52:48.506515Z"}]}
{"channel":"book","type":"update","data":[{"symbol":"ETH/USD","bids":[],"asks":[{"price":3796.71,"qty":2.40000000}],"checksum":3086129509,"timestamp":"2024-06-01T17:52:48.563988Z"}]}
{"channel":"book","type":"update","data":[{"symbol":"ETH/USD","bids":[],"asks":[{"price":3796.75,"qty":0.00000000},{"price":3797.46,"qty":1.00000000}],"checksum":1616084114,"timestamp":"2024-06-01T17:52:48.564560Z"}]}
{"channel":"book","type":"update","data":[{"symbol":"ETH/USD","bids":[],"asks":[{"price":3796.71,"qty":5.40000000}],"checksum":2600101596,"timestamp":"2024-06-01T17:52:48.583227Z"}]}
{"channel":"book","type":"update","data":[{"symbol":"ETH/USD","bids":[],"asks":[{"price":3796.76,"qty":0.00000000},{"price":3797.47,"qty":3.00000000}],"checksum":1700624052,"timestamp":"2024-06-01T17:52:48.586352Z"}]}
{"channel":"book","type":"update","data":[{"symbol":"ETH/USD","bids":[{"price":3796.32,"qty":0.00000000},{"price":3795.82,"qty":3.70000000},{"price":3796.38,"qty":0.00936671}],"asks":[],"checksum":2602031809,"timestamp":"2024-06-01T17:52:48.639645Z"}]}
{"channel":"book","type":"update","data":[{"symbol":"ETH/USD","bids":[],"asks":[{"price":3796.72,"qty":3.00000000}],"checksum":506889531,"timestamp":"2024-06-01T17:52:48.693812Z"}]}
{"channel":"book","type":"update","data":[{"symbol":"ETH/USD","bids":[{"price":3796.37,"qty":0.00000000},{"price":3795.82,"qty":3.70000000}],"asks":[],"checksum":276295593,"timestamp":"2024-06-01T17:52:48.694018Z"}]}
{"channel":"book","type":"update","data":[{"symbol":"ETH/USD","bids":[],"asks":[{"price":3796.74,"qty":26.33840402}],"checksum":3372778869,"timestamp":"2024-06-01T17:52:48.698579Z"}]}
{"channel":"book","type":"update","data":[{"symbol":"ETH/USD","bids":[{"price":3796.38,"qty":26.35021447}],"asks":[],"checksum":1928353327,"timestamp":"2024-06-01T17:52:48.698741Z"}]}
{"channel":"book","type":"update","data":[{"symbol":"ETH/USD","bids":[],"asks":[{"price":3796.74,"qty":0.00000000},{"price":3797.47,"qty":3.00000000}],"checksum":211423665,"timestamp":"2024-06-01T17:52:48.706423Z"}]}
{"channel":"book","type":"update","data":[{"symbol":"ETH/USD","bids":[{"price":3796.38,"qty":0.00936671}],"asks":[],"checksum":276295593,"timestamp":"2024-06-01T17:52:48.706434Z"}]}
{"channel":"book","type":"update","data":[{"symbol":"ETH/USD","bids":[],"asks":[{"price":3796.70,"qty":3.00000000}],"checksum":4294293431,"timestamp":"2024-06-01T17:52:48.746830Z"}]}
{"channel":"book","type":"update","data":[{"symbol":"ETH/USD","bids":[],"asks":[{"price":3796.72,"qty":0.00000000},{"price":3797.47,"qty":3.00000000}],"checksum":3732809905,"timestamp":"2024-06-01T17:52:48.747387Z"}]}
{"channel":"book","type":"update","data":[{"symbol":"ETH/USD","bids":[{"price":3796.38,"qty":0.00000000},{"price":3795.77,"qty":3.40263856},{"price":3796.32,"qty":0.00936686}],"asks":[],"checksum":1375609082,"timestamp":"2024-06-01T17:52:48.766073Z"}]}
{"channel":"book","type":"update","data":[{"symbol":"ETH/USD","bids":[{"price":3796.38,"qty":0.34420830}],"asks":[],"checksum":532036901,"timestamp":"2024-06-01T17:52:48.788743Z"}]}
{"channel":"book","type":"update","data":[{"symbol":"ETH/USD","bids":[],"asks":[{"price":3796.77,"qty":26.33824438}],"checksum":1156273253,"timestamp":"2024-06-01T17:52:48.824664Z"}]}
{"channel":"book","type":"update","data":[{"symbol":"ETH/USD","bids":[{"price":3796.39,"qty":26.34081324}],"asks":[],"checksum":1995194242,"timestamp":"2024-06-01T17:52:48.824806Z"}]}
{"channel":"book","type":"update","data":[{"symbol":"ETH/USD","bids":[],"asks":[{"price":3796.77,"qty":0.00000000},{"price":3797.47,"qty":3.00000000}],"checksum":766596802,"timestamp":"2024-06-01T17:52:48.888338Z"}]}
{"channel":"book","type":"update","data":[{"symbol":"ETH/USD","bids":[],"asks":[{"price":3796.76,"qty":26.33828652}],"checksum":1319630006,"timestamp":"2024-06-01T17:52:48.892777Z"}]}
{"channel":"book","type":"update","data":[{"symbol":"ETH/USD","bids":[{"price":3796.40,"qty":26.34074386}],"asks":[],"checksum":3218837309,"timestamp":"2024-06-01T17:52:48.892862Z"}]}
{"channel":"book","type":"update","data":[{"symbol":"ETH/USD","bids":[{"price":3796.40,"qty":0.00000000},{"price":3795.87,"qty":0.00548922}],"asks":[],"checksum":1319630006,"timestamp":"2024-06-01T17:52:48.897704Z"}]}
{"channel":"book","type":"update","data":[{"symbol":"ETH/USD","bids":[],"asks":[{"price":3796.69,"qty":2.40000000}],"checksum":3186526998,"timestamp":"2024-06-01T17:52:48.995292Z"}]}
{"channel":"book","type":"update","data":[{"symbol":"ETH/USD","bids":[],"asks":[{"price":3796.71,"qty":3.00000000}],"checksum":3448047829,"timestamp":"2024-06-01T17:52:48.995846Z"}]}
{"channel":"book","type":"update","data":[{"symbol":"ETH/USD","bids":[],"asks":[{"price":3796.71,"qty":0.00000000},{"price":3797.46,"qty":1.00000000}],"checksum":1982473638,"timestamp":"2024-06-01T17:52:49.001337Z"}]}
{"channel":"book","type":"update","data":[{"symbol":"ETH/USD","bids":[],"asks":[{"price":3796.69,"qty":5.40000000}],"checksum":3981466627,"timestamp":"2024-06-01T17:52:49.007911Z"}]}
{"channel":"book","type":"update","data":[{"symbol":"ETH/USD","bids":[],"asks":[{"price":3796.70,"qty":0.00000000},{"price":3797.47,"qty":3.00000000}],"checksum":690487604,"timestamp":"2024-06-01T17:52:49.009503Z"}]}
{"channel":"book","type":"update","data":[{"symbol":"ETH/USD","bids":[],"asks":[{"price":3796.68,"qty":3.00000000}],"checksum":193986408,"timestamp":"2024-06-01T17:52:49.013481Z"}]}
{"channel":"book","type":"update","data":[{"symbol":"ETH/USD","bids":[],"asks":[{"price":3796.69,"qty":8.40000000}],"checksum":1880445657,"timestamp":"2024-06-01T17:52:49.016658Z"}]}
{"channel":"book","type":"update","data":[{"symbol":"ETH/USD","bids":[{"price":3796.31,"qty":0.00000000},{"price":3795.86,"qty":26.34448434}],"asks":[],"checksum":972229299,"timestamp":"2024-06-01T17:52:49.016688Z"}]}
{"channel":"book","type":"update","data":[{"symbol":"ETH/USD","bids":[],"asks":[{"price":3797.34,"qty":0.00000000},{"price":3797.47,"qty":3.00000000},{"price":3797.08,"qty":28.94373459}],"checksum":1313128289,"timestamp":"2024-06-01T17:52:49.017000Z"}]}
{"channel":"book","type":"update","data":[{"symbol":"ETH/USD","bids":[],"asks":[{"price":3797.08,"qty":2.60770796}],"checksum":3611987028,"timestamp":"2024-06-01T17:52:49.026566Z"}]}
{"channel":"book","type":"update","data":[{"symbol":"ETH/USD","bids":[{"price":3796.39,"qty":0.00000000},{"price":3795.77,"qty":3.40263856}],"asks":[],"checksum":2557149173,"timestamp":"2024-06-01T17:52:49.026581Z"}]}
{"channel":"book","type":"update","data":[{"symbol":"ETH/USD","bids":[],"asks":[{"price":3796.76,"qty":0.00000000},{"price":3797.64,"qty":0.72912968}],"checksum":2539188811,"timestamp":"2024-06-01T17:52:49.026631Z"}]}
{"channel":"book","type":"update","data":[{"symbol":"ETH/USD","bids":[],"asks":[{"price":3796.56,"qty":26.33965781}],"checksum":283993408,"timestamp":"2024-06-01T17:52:49.032246Z"}]}
{"channel":"book","type":"update","data":[{"symbol":"ETH/USD","bids":[{"price":3796.23,"qty":26.34187683}],"asks":[],"checksum":3822662468,"timestamp":"2024-06-01T17:52:49.032394Z"}]}
{"channel":"book","type":"update","data":[{"symbol":"ETH/USD","bids":[{"price":3796.26,"qty":42.14556963}],"asks":[],"checksum":3948052187,"timestamp":"2024-06-01T17:52:49.032536Z"}]}
{"channel":"book","type":"update","data":[{"symbol":"ETH/USD","bids":[],"asks":[{"price":3797.29,"qty":0.00000000},{"price":3797.64,"qty":0.72912968}],"checksum":3911497583,"timestamp":"2024-06-01T17:52:49.035165Z"}]}
{"channel":"book","type":"update","data":[{"symbol":"ETH/USD","bids":[],"asks":[{"price":3796.39,"qty":3.00000000}],"checksum":3824869597,"timestamp":"2024-06-01T17:52:49.035635Z"}]}
{"channel":"book","type":"update","data":[{"symbol":"ETH/USD","bids":[],"asks":[{"price":3796.69,"qty":5.40000000}],"checksum":73110194,"timestamp":"2024-06-01T17:52:49.035683Z"}]}
{"channel":"book","type":"update","data":[{"symbol":"ETH/USD","bids":[],"asks":[{"price":3796.56,"qty":0.00000000},{"price":3797.64,"qty":0.72912968}],"checksum":692841397,"timestamp":"2024-06-01T17:52:49.037904Z"}]}
{"channel":"book","type":"update","data":[{"symbol":"ETH/USD","bids":[{"price":3796.23,"qty":0.00000000},{"price":3795.77,"qty":3.40263856}],"asks":[],"checksum":955719345,"timestamp":"2024-06-01T17:52:49.037939Z"}]}
{"channel":"book","type":"update","data":[{"symbol":"ETH/USD","bids":[{"price":3796.26,"qty":15.80386352}],"asks":[],"checksum":3733433596,"timestamp":"2024-06-01T17:52:49.037981Z"}]}
{"channel":"book","type":"update","data":[{"symbol":"ETH/USD","bids":[],"asks":[{"price":3796.68,"qty":0.00000000},{"price":3797.84,"qty":3.30000000}],"checksum":3237087935,"timestamp":"2024-06-01T17:52:49.042184Z"}]}
{"channel":"book","type":"update","data":[{"symbol":"ETH/USD","bids":[{"price":3796.06,"qty":1.00000000}],"asks":[],"checksum":4238150694,"timestamp":"2024-06-01T17:52:49.043830Z"}]}
{"channel":"book","type":"update","data":[{"symbol":"ETH/USD","bids":[],"asks":[{"price":3796.78,"qty":0.00000000},{"price":3797.95,"qty":4.30610000}],"checksum":98521054,"timestamp":"2024-06-01T17:52:49.043935Z"}]}
{"channel":"book","type":"update","data":[{"symbol":"ETH/USD","bids":[{"price":3795.86,"qty":0.00000000},{"price":3795.72,"qty":3.95220467}],"asks":[],"checksum":2463424428,"timestamp":"2024-06-01T17:52:49.045295Z"}]}
{"channel":"book","type":"update","data":[{"symbol":"ETH/USD","bids":[],"asks":[{"price":3797.84,"qty":0.00000000},{"price":3797.96,"qty":10.43462302}],"checksum":720483556,"timestamp":"2024-06-01T17:52:49.047368Z"}]}
{"channel":"book","type":"update","data":[{"symbol":"ETH/USD","bids":[{"price":3796.21,"qty":0.00000000},{"price":3795.64,"qty":5.08418593}],"asks":[],"checksum":857824998,"timestamp":"2024-06-01T17:52:49.047711Z"}]}
{"channel":"book","type":"update","data":[{"symbol":"ETH/USD","bids":[{"price":3796.26,"qty":0.00000000},{"price":3795.59,"qty":5.27100000}],"asks":[],"checksum":1416604997,"timestamp":"2024-06-01T17:52:49.047720Z"}]}
{"channel":"book","type":"update","data":[{"symbol":"ETH/USD","bids":[],"asks":[{"price":3797.35,"qty":3.30000000}],"checksum":3973446541,"timestamp":"2024-06-01T17:52:49.047762Z"}]}
{"channel":"book","type":"update","data":[{"symbol":"ETH/USD","bids":[],"asks":[{"price":3797.94,"qty":2.63600000}],"checksum":135162005,"timestamp":"2024-06-01T17:52:49.048357Z"}]}
{"channel":"book","type":"update","data":[{"symbol":"ETH/USD","bids":[{"price":3795.78,"qty":0.00509959}],"asks":[],"checksum":2823462720,"timestamp":"2024-06-01T17:52:49.050060Z"}]}
{"channel":"book","type":"update","data":[{"symbol":"ETH/USD","bids":[{"price":3795.77,"qty":0.00000000},{"price":3795.59,"qty":5.27100000}],"asks":[],"checksum":200878460,"timestamp":"2024-06-01T17:52:49.050431Z"}]}
{"channel":"book","type":"update","data":[{"symbol":"ETH/USD","bids":[],"asks":[{"price":3796.55,"qty":26.33970315}],"checksum":2970773357,"timestamp":"2024-06-01T17:52:49.050567Z"}]}
{"channel":"book","type":"update","data":[{"symbol":"ETH/USD","bids":[],"asks":[{"price":3797.03,"qty":26.33642532}],"checksum":1940774244,"timestamp":"2024-06-01T17:52:49.050616Z"}]}
{"channel":"book","type":"update","data":[{"symbol":"ETH/USD","bids":[{"price":3795.87,"qty":0.00000000},{"price":3795.58,"qty":0.34420830}],"asks":[],"checksum":2180433336,"timestamp":"2024-06-01T17:52:49.050633Z"}]}
{"channel":"book","type":"update","data":[{"symbol":"ETH/USD","bids":[{"price":3795.74,"qty":26.34526232}],"asks":[],"checksum":2638466208,"timestamp":"2024-06-01T17:52:49.050717Z"}]}
{"channel":"book","type":"update","data":[{"symbol":"ETH/USD","bids":[{"price":3795.59,"qty":0.00000000},{"price":3795.58,"qty":0.34420830}],"asks":[],"checksum":3357498728,"timestamp":"2024-06-01T17:52:49.052489Z"}]}
{"channel":"book","type":"update","data":[{"symbol":"ETH/USD","bids":[],"asks":[{"price":3796.44,"qty":26.34053207}],"checksum":2819652231,"timestamp":"2024-06-01T17:52:49.084678Z"}]}
{"channel":"book","type":"update","data":[{"symbol":"ETH/USD","bids":[],"asks":[{"price":3796.72,"qty":26.33855763}],"checksum":3372393245,"timestamp":"2024-06-01T17:52:49.084745Z"}]}
{"channel":"book","type":"update","data":[{"symbol":"ETH/USD","bids":[{"price":3796.12,"qty":26.34266842}],"asks":[],"checksum":1342839270,"timestamp":"2024-06-01T17:52:49.084893Z"}]}
{"channel":"book","type":"update","data":[{"symbol":"ETH/USD","bids":[{"price":3796.12,"qty":0.00000000},{"price":3795.62,"qty":3.00000000}],"asks":[],"checksum":3823852231,"timestamp":"2024-06-01T17:52:49.088953Z"}]}
{"channel":"book","type":"update","data":[{"symbol":"ETH/USD","bids":[],"asks":[{"price":3797.25,"qty":0.72912968}],"checksum":1373493994,"timestamp":"2024-06-01T17:52:49.092386Z"}]}
{"channel":"book","type":"update","data":[{"symbol":"ETH/USD","bids":[{"price":3796.32,"qty":0.00000000},{"price":3795.58,"qty":0.34420830},{"price":3796.29,"qty":0.00936693}],"asks":[],"checksum":3392960085,"timestamp":"2024-06-01T17:52:49.092672Z"}]}
{"channel":"book","type":"update","data":[{"symbol":"ETH/USD","bids":[{"price":3795.95,"qty":0.00000000},{"price":3795.58,"qty":0.34420830}],"asks":[],"checksum":209515156,"timestamp":"2024-06-01T17:52:49.092865Z"}]}
{"channel":"book","type":"update","data":[{"symbol":"ETH/USD","bids":[],"asks":[{"price":3797.08,"qty":1.85000000}],"checksum":3737636432,"timestamp":"2024-06-01T17:52:49.101045Z"}]}
{"channel":"book","type":"update","data":[{"symbol":"ETH/USD","bids":[],"asks":[{"price":3796.99,"qty":0.06693358}],"checksum":1744542883,"timestamp":"2024-06-01T17:52:49.108615Z"}]}
{"channel":"book","type":"update","data":[{"symbol":"ETH/USD","bids":[],"asks":[{"price":3796.44,"qty":0.00000000},{"price":3797.35,"qty":3.30000000}],"checksum":1502259821,"timestamp":"2024-06-01T17:52:49.118461Z"}]}
{"channel":"book","type":"update","data":[{"symbol":"ETH/USD","bids":[{"price":3795.74,"qty":0.00000000},{"price":3795.57,"qty":5.27100000}],"asks":[],"checksum":3587525754,"timestamp":"2024-06-01T17:52:49.118543Z"}]}
{"channel":"book","type":"update","data":[{"symbol":"ETH/USD","bids":[{"price":3795.60,"qty":3.95072654}],"asks":[],"checksum":959295978,"timestamp":"2024-06-01T17:52:49.122621Z"}]}
{"channel":"book","type":"update","data":[{"symbol":"ETH/USD","bids":[{"price":3796.08,"qty":26.34293361}],"asks":[],"checksum":2410475782,"timestamp":"2024-06-01T17:52:49.135406Z"}]}
{"channel":"book","type":"update","data":[{"symbol":"ETH/USD","bids":[],"asks":[{"price":3796.42,"qty":26.34061772}],"checksum":1837701790,"timestamp":"2024-06-01T17:52:49.135455Z"}]}
{"channel":"book","type":"update","data":[{"symbol":"ETH/USD","bids":[{"price":3796.29,"qty":0.00000000},{"price":3795.58,"qty":0.34420830},{"price":3796.30,"qty":0.00936691}],"asks":[],"checksum":3953533234,"timestamp":"2024-06-01T17:52:49.163585Z"}]}
{"channel":"book","type":"update","data":[{"symbol":"ETH/USD","bids":[],"asks":[{"price":3796.39,"qty":0.00000000},{"price":3797.35,"qty":3.30000000}],"checksum":1951135975,"timestamp":"2024-06-01T17:52:49.164085Z"}]}
{"channel":"book","type":"update","data":[{"symbol":"ETH/USD","bids":[],"asks":[{"price":3796.69,"qty":2.40000000}],"checksum":1933616981,"timestamp":"2024-06-01T17:52:49.167319Z"}]}
{"channel":"book","type":"update","data":[{"symbol":"ETH/USD","bids":[{"price":3796.38,"qty":0.00000000},{"price":3795.58,"qty":0.34420830}],"asks":[],"checksum":2119554712,"timestamp":"2024-06-01T17:52:49.170762Z"}]}
{"channel":"book","type":"update","data":[{"symbol":"ETH/USD","bids":[{"price":3796.08,"qty":0.00000000},{"price":3795.57,"qty":5.27100000}],"asks":[],"checksum":4082905509,"timestamp":"2024-06-01T17:52:49.171257Z"}]}
{"channel":"book","type":"update","data":[{"symbol":"ETH/USD","bids":[{"price":3796.28,"qty":0.00000000},{"price":3795.56,"qty":0.84574642}],"asks":[],"checksum":2651345300,"timestamp":"2024-06-01T17:52:49.182033Z"}]}
{"channel":"book","type":"update","data":[{"symbol":"ETH/USD","bids":[{"price":3795.78,"qty":3.40772918}],"asks":[],"checksum":2440141808,"timestamp":"2024-06-01T17:52:49.182388Z"}]}
{"channel":"book","type":"update","data":[{"symbol":"ETH/USD","bids":[],"asks":[{"price":3796.41,"qty":3.00000000}],"checksum":1384004208,"timestamp":"2024-06-01T17:52:49.185534Z"}]}
{"channel":"book","type":"update","data":[{"symbol":"ETH/USD","bids":[{"price":3795.62,"qty":0.00000000},{"price":3795.55,"qty":26.34658644}],"asks":[],"checksum":4053332057,"timestamp":"2024-06-01T17:52:49.188676Z"}]}
{"channel":"book","type":"update","data":[{"symbol":"ETH/USD","bids":[],"asks":[{"price":3796.68,"qty":0.75770796}],"checksum":97710918,"timestamp":"2024-06-01T17:52:49.206777Z"}]}
{"channel":"book","type":"update","data":[{"symbol":"ETH/USD","bids":[{"price":3796.06,"qty":0.00000000},{"price":3795.28,"qty":2.13800000}],"asks":[],"checksum":3487329042,"timestamp":"2024-06-01T17:52:49.211286Z"}]}
{"channel":"book","type":"update","data":[{"symbol":"ETH/USD","bids":[{"price":3796.30,"qty":0.00000000},{"price":3795.25,"qty":0.76333374},{"price":3796.29,"qty":0.00936693}],"asks":[],"checksum":3268726104,"timestamp":"2024-06-01T17:52:49.211906Z"}]}
{"channel":"book","type":"update","data":[{"symbol":"ETH/USD","bids":[],"asks":[{"price":3796.99,"qty":0.00000000},{"price":3797.25,"qty":0.72912968}],"checksum":1174789450,"timestamp":"2024-06-01T17:52:49.215196Z"}]}
{"channel":"book","type":"update","data":[{"symbol":"ETH/USD","bids":[{"price":3796.29,"qty":0.00000000},{"price":3795.25,"qty":0.76333374},{"price":3796.07,"qty":0.00936748}],"asks":[],"checksum":1229357229,"timestamp":"2024-06-01T17:52:49.259711Z"}]}
{"channel":"book","type":"update","data":[{"symbol":"ETH/USD","bids":[],"asks":[{"price":3796.69,"qty":0.00000000},{"price":3797.35,"qty":3.30000000}],"checksum":3335036000,"timestamp":"2024-06-01T17:52:49.273949Z"}]}
{"channel":"book","type":"update","data":[{"symbol":"ETH/USD","bids":[],"asks":[{"price":3796.40,"qty":2.40000000}],"checksum":161253689,"timestamp":"2024-06-01T17:52:49.274023Z"}]}
{"channel":"book","type":"update","data":[{"symbol":"ETH/USD","bids":[],"asks":[{"price":3796.38,"qty":3.00000000}],"checksum":3692657710,"timestamp":"2024-06-01T17:52:49.278121Z"}]}
{"channel":"book","type":"update","data":[{"symbol":"ETH/USD","bids":[{"price":3795.40,"qty":1.85000000}],"asks":[],"checksum":2386191904,"timestamp":"2024-06-01T17:52:49.287939Z"}]}
{"channel":"book","type":"update","data":[{"symbol":"ETH/USD","bids":[],"asks":[{"price":3796.38,"qty":0.00000000},{"price":3797.18,"qty":0.06693358}],"checksum":2398518081,"timestamp":"2024-06-01T17:52:49.316477Z"}]}
{"channel":"book","type":"update","data":[{"symbol":"ETH/USD","bids":[{"price":3796.07,"qty":0.00000000},{"price":3795.28,"qty":2.13800000},{"price":3795.79,"qty":0.00936817}],"asks":[],"checksum":901958878,"timestamp":"2024-06-01T17:52:49.316680Z"}]}
{"channel":"book","type":"update","data":[{"symbol":"ETH/USD","bids":[{"price":3796.09,"qty":26.34283351}],"asks":[],"checksum":4273552490,"timestamp":"2024-06-01T17:52:49.322158Z"}]}
{"channel":"book","type":"update","data":[{"symbol":"ETH/USD","bids":[],"asks":[{"price":3796.41,"qty":0.00000000},{"price":3797.25,"qty":0.72912968}],"checksum":3927051259,"timestamp":"2024-06-01T17:52:49.324501Z"}]}
{"channel":"book","type":"update","data":[{"symbol":"ETH/USD","bids":[{"price":3796.01,"qty":26.34339992}],"asks":[],"checksum":321377415,"timestamp":"2024-06-01T17:52:49.327090Z"}]}
{"channel":"book","type":"update","data":[{"symbol":"ETH/USD","bids":[{"price":3795.71,"qty":3.00000000}],"asks":[],"checksum":392278009,"timestamp":"2024-06-01T17:52:49.331380Z"}]}
{"channel":"book","type":"update","data":[{"symbol":"ETH/USD","bids":[{"price":3795.79,"qty":5.65936817}],"asks":[],"checksum":691812490,"timestamp":"2024-06-01T17:52:49.348489Z"}]}
{"channel":"book","type":"update","data":[{"symbol":"ETH/USD","bids":[],"asks":[{"price":3796.42,"qty":0.00000000},{"price":3797.35,"qty":3.30000000}],"checksum":1852823516,"timestamp":"2024-06-01T17:52:49.376557Z"}]}
{"channel":"book","type":"update","data":[{"symbol":"ETH/USD","bids":[{"price":3796.01,"qty":0.00000000},{"price":3795.56,"qty":0.84574642}],"asks":[],"checksum":1756207464,"timestamp":"2024-06-01T17:52:49.376667Z"}]}
{"channel":"book","type":"update","data":[{"symbol":"ETH/USD","bids":[{"price":3795.79,"qty":0.00936817}],"asks":[],"checksum":3031542381,"timestamp":"2024-06-01T17:52:49.377886Z"}]}
{"channel":"book","type":"update","data":[{"symbol":"ETH/USD","bids":[{"price":3795.80,"qty":26.34490752}],"asks":[],"checksum":3774565100,"timestamp":"2024-06-01T17:52:49.381758Z"}]}
{"channel":"book","type":"update","data":[{"symbol":"ETH/USD","bids":[],"asks":[{"price":3796.46,"qty":26.34035258}],"checksum":1175121539,"timestamp":"2024-06-01T17:52:49.381797Z"}]}
{"channel":"book","type":"update","data":[{"symbol":"ETH/USD","bids":[{"price":3796.15,"qty":26.34246097}],"asks":[],"checksum":461840713,"timestamp":"2024-06-01T17:52:49.381903Z"}]}
{"channel":"book","type":"update","data":[{"symbol":"ETH/USD","bids":[{"price":3796.15,"qty":0.00000000},{"price":3795.57,"qty":5.27100000}],"asks":[],"checksum":1175121539,"timestamp":"2024-06-01T17:52:49.438710Z"}]}
{"channel":"book","type":"update","data":[{"symbol":"ETH/USD","bids":[],"asks":[{"price":3796.46,"qty":0.00000000},{"price":3797.35,"qty":3.30000000}],"checksum":3774565100,"timestamp":"2024-06-01T17:52:49.438999Z"}]}
{"channel":"book","type":"update","data":[{"symbol":"ETH/USD","bids":[{"price":3795.71,"qty":0.00000000},{"price":3795.56,"qty":0.84574642}],"asks":[],"checksum":3952450579,"timestamp":"2024-06-01T17:52:49.442869Z"}]}
{"channel":"book","type":"update","data":[{"symbol":"ETH/USD","bids":[],"asks":[{"price":3796.43,"qty":26.34053881}],"checksum":715463563,"timestamp":"2024-06-01T17:52:49.444587Z"}]}
{"channel":"book","type":"update","data":[{"symbol":"ETH/USD","bids":[{"price":3796.10,"qty":26.34276860}],"asks":[],"checksum":1029780504,"timestamp":"2024-06-01T17:52:49.444602Z"}]}
{"channel":"book","type":"update","data":[{"symbol":"ETH/USD","bids":[{"price":3795.71,"qty":3.00000000}],"asks":[],"checksum":2359400689,"timestamp":"2024-06-01T17:52:49.447786Z"}]}
{"channel":"book","type":"update","data":[{"symbol":"ETH/USD","bids":[],"asks":[{"price":3796.43,"qty":0.00000000},{"price":3797.35,"qty":3.30000000}],"checksum":1189433168,"timestamp":"2024-06-01T17:52:49.527764Z"}]}
{"channel":"book","type":"update","data":[{"symbol":"ETH/USD","bids":[],"asks":[{"price":3796.41,"qty":26.34068106}],"checksum":604449441,"timestamp":"2024-06-01T17:52:49.532940Z"}]}
{"channel":"book","type":"update","data":[{"symbol":"ETH/USD","bids":[{"price":3796.10,"qty":0.00000000},{"price":3795.57,"qty":5.27100000}],"asks":[],"checksum":3749930160,"timestamp":"2024-06-01T17:52:49.535590Z"}]}
{"channel":"book","type":"update","data":[{"symbol":"ETH/USD","bids":[],"asks":[{"price":3796.55,"qty":0.00000000},{"price":3797.35,"qty":3.30000000}],"checksum":435660097,"timestamp":"2024-06-01T17:52:49.536441Z"}]}
{"channel":"book","type":"update","data":[{"symbol":"ETH/USD","bids":[{"price":3795.71,"qty":0.00000000},{"price":3795.56,"qty":0.84574642}],"asks":[],"checksum":1587895951,"timestamp":"2024-06-01T17:52:49.538993Z"}]}
{"channel":"book","type":"update","data":[{"symbol":"ETH/USD","bids":[{"price":3796.07,"qty":26.34300570}],"asks":[],"checksum":3714725749,"timestamp":"2024-06-01T17:52:49.540872Z"}]}
{"channel":"book","type":"update","data":[{"symbol":"ETH/USD","bids":[{"price":3795.71,"qty":3.00000000}],"asks":[],"checksum":1823120284,"timestamp":"2024-06-01T17:52:49.542967Z"}]}
{"channel":"book","type":"update","data":[{"symbol":"ETH/USD","bids":[{"price":3795.81,"qty":0.76333374}],"asks":[],"checksum":1388240114,"timestamp":"2024-06-01T17:52:49.543393Z"}]}
{"channel":"book","type":"update","data":[{"symbol":"ETH/USD","bids":[{"price":3795.79,"qty":0.00000000},{"price":3795.58,"qty":0.34420830},{"price":3796.10,"qty":0.00936740}],"asks":[],"checksum":2282857923,"timestamp":"2024-06-01T17:52:49.671129Z"}]}
{"channel":"book","type":"update","data":[{"symbol":"ETH/USD","bids":[{"price":3795.71,"qty":0.00000000},{"price":3795.58,"qty":0.34420830}],"asks":[],"checksum":2972419379,"timestamp":"2024-06-01T17:52:49.674304Z"}]}
{"channel":"book","type":"update","data":[{"symbol":"ETH/USD","bids":[{"price":3795.72,"qty":6.95220467}],"asks":[],"checksum":4024496695,"timestamp":"2024-06-01T17:52:49.679888Z"}]}
{"channel":"book","type":"update","data":[{"symbol":"ETH/USD","bids":[{"price":3796.11,"qty":0.32778701}],"asks":[],"checksum":2759005666,"timestamp":"2024-06-01T17:52:49.691093Z"}]}
{"channel":"book","type":"update","data":[{"symbol":"ETH/USD","bids":[{"price":3795.72,"qty":3.95220467}],"asks":[],"checksum":196032174,"timestamp":"2024-06-01T17:52:49.694394Z"}]}
{"channel":"book","type":"update","data":[{"symbol":"ETH/USD","bids":[{"price":3795.73,"qty":3.00000000}],"asks":[],"checksum":3371386389,"timestamp":"2024-06-01T17:52:49.697298Z"}]}
{"channel":"book","type":"update","data":[{"symbol":"ETH/USD","bids":[{"price":3796.11,"qty":0.67199531}],"asks":[],"checksum":833115364,"timestamp":"2024-06-01T17:52:49.697551Z"}]}
{"channel":"book","type":"update","data":[{"symbol":"ETH/USD","bids":[{"price":3796.09,"qty":0.00000000},{"price":3795.60,"qty":3.95072654}],"asks":[],"checksum":11174755,"timestamp":"2024-06-01T17:52:49.842731Z"}]}
{"channel":"book","type":"update","data":[{"symbol":"ETH/USD","bids":[],"asks":[{"price":3796.39,"qty":26.34081324}],"checksum":1045951723,"timestamp":"2024-06-01T17:52:49.847411Z"}]}
{"channel":"book","type":"update","data":[{"symbol":"ETH/USD","bids":[{"price":3796.10,"qty":26.35214083}],"asks":[],"checksum":3873727816,"timestamp":"2024-06-01T17:52:49.847562Z"}]}
{"channel":"book","type":"update","data":[{"symbol":"ETH/USD","bids":[{"price":3795.73,"qty":0.00000000},{"price":3795.58,"qty":0.34420830}],"asks":[],"checksum":1241107749,"timestamp":"2024-06-01T17:52:49.850766Z"}]}
{"channel":"book","type":"update","data":[{"symbol":"ETH/USD","bids":[{"price":3795.73,"qty":3.00000000}],"asks":[],"checksum":3873727816,"timestamp":"2024-06-01T17:52:49.853220Z"}]}
{"channel":"book","type":"update","data":[{"symbol":"ETH/USD","bids":[],"asks":[{"price":3796.38,"qty":2.40000000}],"checksum":2528384620,"timestamp":"2024-06-01T17:52:49.975919Z"}]}
{"channel":"book","type":"update","data":[{"symbol":"ETH/USD","bids":[],"asks":[{"price":3796.40,"qty":0.00000000},{"price":3797.25,"qty":0.72912968}],"checksum":1587643570,"timestamp":"2024-06-01T17:52:49.976724Z"}]}
{"channel":"book","type":"update","data":[{"symbol":"ETH/USD","bids":[{"price":3795.73,"qty":0.00000000},{"price":3795.58,"qty":0.34420830}],"asks":[],"checksum":2981967890,"timestamp":"2024-06-01T17:52:49.979536Z"}]}
{"channel":"book","type":"update","data":[{"symbol":"ETH/USD","bids":[{"price":3795.73,"qty":3.00000000}],"asks":[],"checksum":1587643570,"timestamp":"2024-06-01T17:52:49.984748Z"}]}
{"channel":"book","type":"update","data":[{"symbol":"ETH/USD","bids":[{"price":3795.73,"qty":0.00000000},{"price":3795.58,"qty":0.34420830}],"asks":[],"checksum":2981967890,"timestamp":"2024-06-01T17:52:49.988107Z"}]}
{"channel":"book","type":"update","data":[{"symbol":"ETH/USD","bids":[{"price":3795.81,"qty":0.00000000},{"price":3795.57,"qty":5.27100000}],"asks":[],"checksum":1121945100,"timestamp":"2024-06-01T17:52:49.988660Z"}]}
{"channel":"book","type":"update","data":[{"symbol":"ETH/USD","bids":[{"price":3795.57,"qty":0.00000000},{"price":3795.56,"qty":0.84574642}],"asks":[],"checksum":1323253745,"timestamp":"2024-06-01T17:52:49.988849Z"}]}
{"channel":"book","type":"update","data":[{"symbol":"ETH/USD","bids":[],"asks":[{"price":3796.38,"qty":5.40000000}],"checksum":3908571887,"timestamp":"2024-06-01T17:52:49.990599Z"}]}
{"channel":"book","type":"update","data":[{"symbol":"ETH/USD","bids":[],"asks":[{"price":3796.33,"qty":3.00000000}],"checksum":1436507789,"timestamp":"2024-06-01T17:52:49.993825Z"}]}
{"channel":"book","type":"update","data":[{"symbol":"ETH/USD","bids":[{"price":3796.10,"qty":0.00936740}],"asks":[],"checksum":88466639,"timestamp":"2024-06-01T17:52:49.996650Z"}]}
{"channel":"book","type":"update","data":[{"symbol":"ETH/USD","bids":[],"asks":[{"price":3796.39,"qty":0.00000000},{"price":3797.25,"qty":0.72912968}],"checksum":2659090718,"timestamp":"2024-06-01T17:52:49.996672Z"}]}
{"channel":"book","type":"update","data":[{"symbol":"ETH/USD","bids":[{"price":3796.07,"qty":0.00000000},{"price":3795.55,"qty":26.34658644}],"asks":[],"checksum":3075793885,"timestamp":"2024-06-01T17:52:49.996746Z"}]}
{"channel":"book","type":"update","data":[{"symbol":"ETH/USD","bids":[],"asks":[{"price":3797.03,"qty":0.00000000},{"price":3797.35,"qty":3.30000000}],"checksum":2382006056,"timestamp":"2024-06-01T17:52:49.996856Z"}]}
{"channel":"book","type":"update","data":[{"symbol":"ETH/USD","bids":[],"asks":[{"price":3796.71,"qty":3.00000000}],"checksum":4207133246,"timestamp":"2024-06-01T17:52:49.998596Z"}]}
{"channel":"book","type":"update","data":[{"symbol":"ETH/USD","bids":[],"asks":[{"price":3796.32,"qty":26.34129894}],"checksum":3590113854,"timestamp":"2024-06-01T17:52:50.002792Z"}]}
{"channel":"book","type":"update","data":[{"symbol":"ETH/USD","bids":[{"price":3795.89,"qty":26.34425074}],"asks":[],"checksum":1066072978,"timestamp":"2024-06-01T17:52:50.002894Z"}]}
{"channel":"book","type":"update","data":[{"symbol":"ETH/USD","bids":[],"asks":[{"price":3796.32,"qty":52.68259788}],"checksum":3172074146,"timestamp":"2024-06-01T17:52:50.002921Z"}]}
{"channel":"book","type":"update","data":[{"symbol":"ETH/USD","bids":[],"asks":[{"price":3796.23,"qty":3.00000000}],"checksum":1293115897,"timestamp":"2024-06-01T17:52:50.007162Z"}]}
{"channel":"book","type":"update","data":[{"symbol":"ETH/USD","bids":[],"asks":[{"price":3796.38,"qty":2.40000000}],"checksum":1121936267,"timestamp":"2024-06-01T17:52:50.007568Z"}]}
{"channel":"book","type":"update","data":[{"symbol":"ETH/USD","bids":[],"asks":[{"price":3796.32,"qty":26.34129894}],"checksum":3450569490,"timestamp":"2024-06-01T17:52:50.009258Z"}]}
{"channel":"book","type":"update","data":[{"symbol":"ETH/USD","bids":[{"price":3795.80,"qty":0.00000000},{"price":3795.55,"qty":26.34658644}],"asks":[],"checksum":867276540,"timestamp":"2024-06-01T17:52:50.018537Z"}]}
{"channel":"book","type":"update","data":[{"symbol":"ETH/USD","bids":[],"asks":[{"price":3796.41,"qty":0.00000000},{"price":3797.18,"qty":0.06693358}],"checksum":1975744565,"timestamp":"2024-06-01T17:52:50.018554Z"}]}
{"channel":"book","type":"update","data":[{"symbol":"ETH/USD","bids":[{"price":3795.78,"qty":0.00509959}],"asks":[],"checksum":1320731030,"timestamp":"2024-06-01T17:52:50.020296Z"}]}
{"channel":"book","type":"update","data":[{"symbol":"ETH/USD","bids":[],"asks":[{"price":3796.56,"qty":26.33965020}],"checksum":2579559,"timestamp":"2024-06-01T17:52:50.023044Z"}]}
{"channel":"book","type":"update","data":[{"symbol":"ETH/USD","bids":[{"price":3795.55,"qty":0.00000000},{"price":3795.40,"qty":1.85000000}],"asks":[],"checksum":1013804536,"timestamp":"2024-06-01T17:52:50.044962Z"}]}
{"channel":"book","type":"update","data":[{"symbol":"ETH/USD","bids":[],"asks":[{"price":3796.23,"qty":0.00000000},{"price":3797.18,"qty":0.06693358}],"checksum":1419974260,"timestamp":"2024-06-01T17:52:50.045284Z"}]}
{"channel":"book","type":"update","data":[{"symbol":"ETH/USD","bids":[],"asks":[{"price":3796.27,"qty":3.00000000}],"checksum":2612725121,"timestamp":"2024-06-01T17:52:50.049886Z"}]}
{"channel":"book","type":"update","data":[{"symbol":"ETH/USD","bids":[{"price":3795.68,"qty":26.34572945}],"asks":[],"checksum":1979684961,"timestamp":"2024-06-01T17:52:50.050733Z"}]}
{"channel":"book","type":"update","data":[{"symbol":"ETH/USD","bids":[],"asks":[{"price":3796.31,"qty":26.34141842}],"checksum":3144361798,"timestamp":"2024-06-01T17:52:50.055901Z"}]}
{"channel":"book","type":"update","data":[{"symbol":"ETH/USD","bids":[{"price":3795.96,"qty":26.34375809}],"asks":[],"checksum":2441586730,"timestamp":"2024-06-01T17:52:50.055955Z"}]}
{"channel":"book","type":"update","data":[{"symbol":"ETH/USD","bids":[],"asks":[{"price":3796.31,"qty":0.00000000},{"price":3797.09,"qty":3.00000000}],"checksum":278690502,"timestamp":"2024-06-01T17:52:50.065919Z"}]}
{"channel":"book","type":"update","data":[{"symbol":"ETH/USD","bids":[{"price":3795.96,"qty":0.00000000},{"price":3795.56,"qty":0.84574642}],"asks":[],"checksum":1979684961,"timestamp":"2024-06-01T17:52:50.072670Z"}]}
{"channel":"book","type":"update","data":[{"symbol":"ETH/USD","bids":[{"price":3795.58,"qty":0.00000000},{"price":3795.40,"qty":1.85000000}],"asks":[],"checksum":4129128233,"timestamp":"2024-06-01T17:52:50.077348Z"}]}
{"channel":"book","type":"update","data":[{"symbol":"ETH/USD","bids":[{"price":3795.81,"qty":26.34481717}],"asks":[],"checksum":202246165,"timestamp":"2024-06-01T17:52:50.114256Z"}]}
{"channel":"book","type":"update","data":[{"symbol":"ETH/USD","bids":[],"asks":[{"price":3796.25,"qty":26.34182616}],"checksum":25049418,"timestamp":"2024-06-01T17:52:50.114338Z"}]}
{"channel":"book","type":"update","data":[{"symbol":"ETH/USD","bids":[{"price":3795.64,"qty":8.48694103}],"asks":[],"checksum":170345868,"timestamp":"2024-06-01T17:52:50.144569Z"}]}
{"channel":"book","type":"update","data":[{"symbol":"ETH/USD","bids":[],"asks":[{"price":3796.38,"qty":0.00000000},{"price":3797.09,"qty":3.00000000}],"checksum":3190249737,"timestamp":"2024-06-01T17:52:50.262706Z"}]}
{"channel":"book","type":"update","data":[{"symbol":"ETH/USD","bids":[],"asks":[{"price":3796.24,"qty":2.40000000}],"checksum":3145409096,"timestamp":"2024-06-01T17:52:50.262732Z"}]}
{"channel":"book","type":"update","data":[{"symbol":"ETH/USD","bids":[],"asks":[{"price":3796.68,"qty":0.00000000},{"price":3797.09,"qty":3.00000000}],"checksum":562242208,"timestamp":"2024-06-01T17:52:50.266059Z"}]}
{"channel":"book","type":"update","data":[{"symbol":"ETH/USD","bids":[],"asks":[{"price":3796.23,"qty":3.00000000}],"checksum":3490513680,"timestamp":"2024-06-01T17:52:50.310242Z"}]}
{"channel":"book","type":"update","data":[{"symbol":"ETH/USD","bids":[],"asks":[{"price":3796.33,"qty":0.00000000},{"price":3797.09,"qty":3.00000000}],"checksum":4136186614,"timestamp":"2024-06-01T17:52:50.311016Z"}]}
{"channel":"book","type":"update","data":[{"symbol":"ETH/USD","bids":[],"asks":[{"price":3796.25,"qty":0.00000000},{"price":3797.18,"qty":0.06693358}],"checksum":3732804501,"timestamp":"2024-06-01T17:52:50.316477Z"}]}
{"channel":"book","type":"update","data":[{"symbol":"ETH/USD","bids":[{"price":3796.10,"qty":0.00000000},{"price":3795.40,"qty":1.85000000},{"price":3796.12,"qty":0.00936735}],"asks":[],"checksum":801815137,"timestamp":"2024-06-01T17:52:50.318730Z"}]}
{"channel":"book","type":"update","data":[{"symbol":"ETH/USD","bids":[],"asks":[{"price":3796.24,"qty":28.74192171}],"checksum":2100310289,"timestamp":"2024-06-01T17:52:50.321443Z"}]}
{"channel":"book","type":"update","data":[{"symbol":"ETH/USD","bids":[],"asks":[{"price":3796.24,"qty":2.40000000}],"checksum":801815137,"timestamp":"2024-06-01T17:52:50.331916Z"}]}
{"channel":"book","type":"update","data":[{"symbol":"ETH/USD","bids":[{"price":3795.64,"qty":5.08418593}],"asks":[],"checksum":613664423,"timestamp":"2024-06-01T17:52:50.350196Z"}]}
{"channel":"book","type":"update","data":[{"symbol":"ETH/USD","bids":[{"price":3795.89,"qty":0.00000000},{"price":3795.40,"qty":1.85000000}],"asks":[],"checksum":1429715407,"timestamp":"2024-06-01T17:52:50.365979Z"}]}
{"channel":"book","type":"update","data":[{"symbol":"ETH/USD","bids":[],"asks":[{"price":3796.23,"qty":3.75770796}],"checksum":619513187,"timestamp":"2024-06-01T17:52:50.369792Z"}]}
{"channel":"book","type":"update","data":[{"symbol":"ETH/USD","bids":[{"price":3795.86,"qty":26.34443871}],"asks":[],"checksum":2788299630,"timestamp":"2024-06-01T17:52:50.372309Z"}]}
{"channel":"book","type":"update","data":[{"symbol":"ETH/USD","bids":[],"asks":[{"price":3796.22,"qty":26.34203236}],"checksum":1633871080,"timestamp":"2024-06-01T17:52:50.377068Z"}]}
{"channel":"book","type":"update","data":[{"symbol":"ETH/USD","bids":[],"asks":[{"price":3796.21,"qty":3.00000000}],"checksum":1519383420,"timestamp":"2024-06-01T17:52:50.380471Z"}]}
{"channel":"book","type":"update","data":[{"symbol":"ETH/USD","bids":[],"asks":[{"price":3796.27,"qty":0.00000000},{"price":3797.09,"qty":3.00000000}],"checksum":3529820879,"timestamp":"2024-06-01T17:52:50.380787Z"}]}
{"channel":"book","type":"update","data":[{"symbol":"ETH/USD","bids":[{"price":3795.86,"qty":0.00000000},{"price":3795.40,"qty":1.85000000}],"asks":[],"checksum":3286646496,"timestamp":"2024-06-01T17:52:50.385407Z"}]}
{"channel":"book","type":"update","data":[{"symbol":"ETH/USD","bids":[],"asks":[{"price":3796.22,"qty":0.00000000},{"price":3797.18,"qty":0.06693358}],"checksum":2004593082,"timestamp":"2024-06-01T17:52:50.388651Z"}]}
{"channel":"book","type":"update","data":[{"symbol":"ETH/USD","bids":[],"asks":[{"price":3796.32,"qty":0.00000000},{"price":3797.25,"qty":0.72912968}],"checksum":3170024316,"timestamp":"2024-06-01T17:52:50.409894Z"}]}
{"channel":"book","type":"update","data":[{"symbol":"ETH/USD","bids":[{"price":3795.68,"qty":0.00000000},{"price":3795.31,"qty":26.34825768}],"asks":[],"checksum":1115834201,"timestamp":"2024-06-01T17:52:50.409904Z"}]}
{"channel":"book","type":"update","data":[{"symbol":"ETH/USD","bids":[{"price":3795.54,"qty":26.34664416}],"asks":[],"checksum":2939196673,"timestamp":"2024-06-01T17:52:50.414237Z"}]}
{"channel":"book","type":"update","data":[{"symbol":"ETH/USD","bids":[],"asks":[{"price":3797.08,"qty":0.00000000},{"price":3797.35,"qty":3.30000000},{"price":3796.80,"qty":1.85000000}],"checksum":1614273478,"timestamp":"2024-06-01T17:52:50.415113Z"}]}
{"channel":"book","type":"update","data":[{"symbol":"ETH/USD","bids":[],"asks":[{"price":3796.80,"qty":3.70000000}],"checksum":2276346008,"timestamp":"2024-06-01T17:52:50.418262Z"}]}
{"channel":"book","type":"update","data":[{"symbol":"ETH/USD","bids":[{"price":3795.64,"qty":0.00000000},{"price":3795.31,"qty":26.34825768}],"asks":[],"checksum":1940540075,"timestamp":"2024-06-01T17:52:50.448747Z"}]}
{"channel":"book","type":"update","data":[{"symbol":"ETH/USD","bids":[{"price":3795.72,"qty":0.00000000},{"price":3795.29,"qty":5.27100000}],"asks":[],"checksum":2408611569,"timestamp":"2024-06-01T17:52:50.450921Z"}]}
{"channel":"book","type":"update","data":[{"symbol":"ETH/USD","bids":[],"asks":[{"price":3796.56,"qty":0.00000000},{"price":3797.35,"qty":3.30000000}],"checksum":2744774787,"timestamp":"2024-06-01T17:52:50.451267Z"}]}
{"channel":"book","type":"update","data":[{"symbol":"ETH/USD","bids":[{"price":3795.45,"qty":6.38468581}],"asks":[],"checksum":4061076675,"timestamp":"2024-06-01T17:52:50.453524Z"}]}
{"channel":"book","type":"update","data":[{"symbol":"ETH/USD","bids":[{"price":3795.38,"qty":3.95072654}],"asks":[],"checksum":4099378530,"timestamp":"2024-06-01T17:52:50.455929Z"}]}
{"channel":"book","type":"update","data":[{"symbol":"ETH/USD","bids":[],"asks":[{"price":3796.13,"qty":26.34261734}],"checksum":3058654073,"timestamp":"2024-06-01T17:52:50.456222Z"}]}
{"channel":"book","type":"update","data":[{"symbol":"ETH/USD","bids":[{"price":3795.83,"qty":26.34467846}],"asks":[],"checksum":1217830661,"timestamp":"2024-06-01T17:52:50.456296Z"}]}
{"channel":"book","type":"update","data":[{"symbol":"ETH/USD","bids":[],"asks":[{"price":3796.41,"qty":26.34069244}],"checksum":383328549,"timestamp":"2024-06-01T17:52:50.456431Z"}]}
{"channel":"book","type":"update","data":[{"symbol":"ETH/USD","bids":[],"asks":[{"price":3796.13,"qty":29.34261734}],"checksum":3299406717,"timestamp":"2024-06-01T17:52:50.459556Z"}]}
{"channel":"book","type":"update","data":[{"symbol":"ETH/USD","bids":[],"asks":[{"price":3796.23,"qty":0.75770796}],"checksum":983290650,"timestamp":"2024-06-01T17:52:50.459961Z"}]}
{"channel":"book","type":"update","data":[{"symbol":"ETH/USD","bids":[{"price":3795.81,"qty":0.00000000},{"price":3795.38,"qty":3.95072654}],"asks":[],"checksum":3758776494,"timestamp":"2024-06-01T17:52:50.465952Z"}]}
{"channel":"book","type":"update","data":[{"symbol":"ETH/USD","bids":[{"price":3795.83,"qty":0.00000000},{"price":3795.31,"qty":26.34825768}],"asks":[],"checksum":1626435137,"timestamp":"2024-06-01T17:52:50.465966Z"}]}
{"channel":"book","type":"update","data":[{"symbol":"ETH/USD","bids":[{"price":3795.42,"qty":3.40295234}],"asks":[],"checksum":302322621,"timestamp":"2024-06-01T17:52:50.468355Z"}]}
{"channel":"book","type":"update","data":[{"symbol":"ETH/USD","bids":[{"price":3795.78,"qty":0.00000000},{"price":3795.31,"qty":26.34825768}],"asks":[],"checksum":569170259,"timestamp":"2024-06-01T17:52:50.470412Z"}]}
{"channel":"book","type":"update","data":[{"symbol":"ETH/USD","bids":[{"price":3795.61,"qty":0.00509359}],"asks":[],"checksum":303950978,"timestamp":"2024-06-01T17:52:50.470529Z"}]}
{"channel":"book","type":"update","data":[{"symbol":"ETH/USD","bids":[{"price":3795.67,"qty":26.34575158}],"asks":[],"checksum":297028074,"timestamp":"2024-06-01T17:52:50.472917Z"}]}
{"channel":"book","type":"update","data":[{"symbol":"ETH/USD","bids":[{"price":3795.42,"qty":0.00000000},{"price":3795.38,"qty":3.95072654}],"asks":[],"checksum":218533476,"timestamp":"2024-06-01T17:52:50.476231Z"}]}
{"channel":"book","type":"update","data":[{"symbol":"ETH/USD","bids":[],"asks":[{"price":3796.13,"qty":26.34261734}],"checksum":2253135786,"timestamp":"2024-06-01T17:52:50.502748Z"}]}
{"channel":"book","type":"update","data":[{"symbol":"ETH/USD","bids":[],"asks":[{"price":3796.13,"qty":52.68523468}],"checksum":4020160290,"timestamp":"2024-06-01T17:52:50.518172Z"}]}
{"channel":"book","type":"update","data":[{"symbol":"ETH/USD","bids":[{"price":3795.72,"qty":26.34540547}],"asks":[],"checksum":125311598,"timestamp":"2024-06-01T17:52:50.518429Z"}]}
{"channel":"book","type":"update","data":[{"symbol":"ETH/USD","bids":[],"asks":[{"price":3796.24,"qty":0.00000000},{"price":3797.25,"qty":0.72912968}],"checksum":2642775567,"timestamp":"2024-06-01T17:52:50.527383Z"}]}
{"channel":"book","type":"update","data":[{"symbol":"ETH/USD","bids":[{"price":3796.11,"qty":0.32778701}],"asks":[],"checksum":13938228,"timestamp":"2024-06-01T17:52:50.529144Z"}]}
{"channel":"book","type":"update","data":[{"symbol":"ETH/USD","bids":[{"price":3796.11,"qty":0.00000000},{"price":3795.38,"qty":3.95072654}],"asks":[],"checksum":2116888806,"timestamp":"2024-06-01T17:52:50.531439Z"}]}
{"channel":"book","type":"update","data":[{"symbol":"ETH/USD","bids":[],"asks":[{"price":3796.13,"qty":55.68523468}],"checksum":3147283017,"timestamp":"2024-06-01T17:52:50.552721Z"}]}
{"channel":"book","type":"update","data":[{"symbol":"ETH/USD","bids":[{"price":3796.12,"qty":0.00000000},{"price":3795.31,"qty":26.34825768},{"price":3795.73,"qty":0.00936926}],"asks":[],"checksum":3076098982,"timestamp":"2024-06-01T17:52:50.590142Z"}]}
{"channel":"book","type":"update","data":[{"symbol":"ETH/USD","bids":[],"asks":[{"price":3796.23,"qty":0.00000000},{"price":3797.35,"qty":3.30000000}],"checksum":2799019041,"timestamp":"2024-06-01T17:52:50.593674Z"}]}
{"channel":"book","type":"update","data":[{"symbol":"ETH/USD","bids":[],"asks":[{"price":3796.13,"qty":29.34261734}],"checksum":1230656485,"timestamp":"2024-06-01T17:52:50.594827Z"}]}
{"channel":"book","type":"update","data":[{"symbol":"ETH/USD","bids":[{"price":3795.56,"qty":0.00000000},{"price":3795.31,"qty":26.34825768}],"asks":[],"checksum":611202866,"timestamp":"2024-06-01T17:52:50.595436Z"}]}
{"channel":"book","type":"update","data":[{"symbol":"ETH/USD","bids":[{"price":3795.33,"qty":3.40303303}],"asks":[],"checksum":466763669,"timestamp":"2024-06-01T17:52:50.598200Z"}]}
{"channel":"book","type":"update","data":[{"symbol":"ETH/USD","bids":[],"asks":[{"price":3796.06,"qty":26.34316103}],"checksum":4183438556,"timestamp":"2024-06-01T17:52:50.598956Z"}]}
{"channel":"book","type":"update","data":[{"symbol":"ETH/USD","bids":[],"asks":[{"price":3796.13,"qty":26.34261734}],"checksum":2736082246,"timestamp":"2024-06-01T17:52:50.645660Z"}]}
{"channel":"book","type":"update","data":[{"symbol":"ETH/USD","bids":[{"price":3795.72,"qty":0.00000000},{"price":3795.31,"qty":26.34825768}],"asks":[],"checksum":4166036763,"timestamp":"2024-06-01T17:52:50.671803Z"}]}
{"channel":"book","type":"update","data":[{"symbol":"ETH/USD","bids":[{"price":3795.73,"qty":26.35470622}],"asks":[],"checksum":123168302,"timestamp":"2024-06-01T17:52:50.677815Z"}]}
{"channel":"book","type":"update","data":[{"symbol":"ETH/USD","bids":[{"price":3795.73,"qty":0.00936926}],"asks":[],"checksum":4166036763,"timestamp":"2024-06-01T17:52:50.699071Z"}]}
{"channel":"book","type":"update","data":[{"symbol":"ETH/USD","bids":[],"asks":[{"price":3796.05,"qty":0.77968154}],"checksum":427517555,"timestamp":"2024-06-01T17:52:50.703617Z"}]}
{"channel":"book","type":"update","data":[{"symbol":"ETH/USD","bids":[{"price":3795.73,"qty":0.00000000},{"price":3795.29,"qty":5.27100000},{"price":3795.68,"qty":0.00936938}],"asks":[],"checksum":1287869446,"timestamp":"2024-06-01T17:52:50.746452Z"}]}
{"channel":"book","type":"update","data":[{"symbol":"ETH/USD","bids":[{"price":3795.69,"qty":26.34567101}],"asks":[],"checksum":2955800152,"timestamp":"2024-06-01T17:52:50.752201Z"}]}
{"channel":"book","type":"update","data":[{"symbol":"ETH/USD","bids":[{"price":3795.33,"qty":0.00000000},{"price":3795.31,"qty":26.34825768}],"asks":[],"checksum":3239081710,"timestamp":"2024-06-01T17:52:50.756335Z"}]}
{"channel":"book","type":"update","data":[{"symbol":"ETH/USD","bids":[{"price":3795.69,"qty":0.00000000},{"price":3795.29,"qty":5.27100000}],"asks":[],"checksum":40233984,"timestamp":"2024-06-01T17:52:50.756674Z"}]}
{"channel":"book","type":"update","data":[{"symbol":"ETH/USD","bids":[],"asks":[{"price":3796.06,"qty":0.00000000},{"price":3797.25,"qty":0.72912968}],"checksum":4202893886,"timestamp":"2024-06-01T17:52:50.834960Z"}]}
{"channel":"book","type":"update","data":[{"symbol":"ETH/USD","bids":[],"asks":[{"price":3796.08,"qty":26.34297442}],"checksum":3945490196,"timestamp":"2024-06-01T17:52:50.841628Z"}]}
{"channel":"book","type":"update","data":[{"symbol":"ETH/USD","bids":[{"price":3795.74,"qty":26.34532072}],"asks":[],"checksum":2989785024,"timestamp":"2024-06-01T17:52:50.841762Z"}]}
{"channel":"book","type":"update","data":[{"symbol":"ETH/USD","bids":[{"price":3795.40,"qty":0.00000000},{"price":3795.29,"qty":5.27100000}],"asks":[],"checksum":1576143152,"timestamp":"2024-06-01T17:52:50.855160Z"}]}
{"channel":"book","type":"update","data":[{"symbol":"ETH/USD","bids":[{"price":3795.74,"qty":0.00000000},{"price":3795.24,"qty":3.94900000}],"asks":[],"checksum":812332180,"timestamp":"2024-06-01T17:52:50.862639Z"}]}
{"channel":"book","type":"update","data":[{"symbol":"ETH/USD","bids":[{"price":3795.68,"qty":0.00000000},{"price":3795.23,"qty":3.00000000},{"price":3795.75,"qty":0.00936921}],"asks":[],"checksum":4078250164,"timestamp":"2024-06-01T17:52:50.899259Z"}]}
{"channel":"book","type":"update","data":[{"symbol":"ETH/USD","bids":[{"price":3795.76,"qty":26.34512606}],"asks":[],"checksum":3786487869,"timestamp":"2024-06-01T17:52:50.899931Z"}]}
{"channel":"book","type":"update","data":[{"symbol":"ETH/USD","bids":[{"price":3795.75,"qty":0.00000000},{"price":3795.24,"qty":7.35211373},{"price":3795.68,"qty":0.00936938}],"asks":[],"checksum":2459393995,"timestamp":"2024-06-01T17:52:50.954502Z"}]}
{"channel":"book","type":"update","data":[{"symbol":"ETH/USD","bids":[],"asks":[{"price":3796.08,"qty":0.00000000},{"price":3797.25,"qty":0.72912968}],"checksum":1228750440,"timestamp":"2024-06-01T17:52:50.966740Z"}]}
{"channel":"book","type":"update","data":[{"symbol":"ETH/USD","bids":[{"price":3795.76,"qty":0.00000000},{"price":3795.24,"qty":3.94900000}],"asks":[],"checksum":566444478,"timestamp":"2024-06-01T17:52:50.966749Z"}]}
{"channel":"book","type":"update","data":[{"symbol":"ETH/USD","bids":[{"price":3795.73,"qty":26.34538426}],"asks":[],"checksum":3182357897,"timestamp":"2024-06-01T17:52:50.973181Z"}]}
{"channel":"book","type":"update","data":[{"symbol":"ETH/USD","bids":[],"asks":[{"price":3796.05,"qty":27.12291248}],"checksum":1168738324,"timestamp":"2024-06-01T17:52:50.973196Z"}]}
{"channel":"book","type":"update","data":[{"symbol":"ETH/USD","bids":[],"asks":[{"price":3796.05,"qty":0.77968154}],"checksum":3182357897,"timestamp":"2024-06-01T17:52:51.016618Z"}]}
{"channel":"book","type":"update","data":[{"symbol":"ETH/USD","bids":[{"price":3795.73,"qty":0.00000000},{"price":3795.24,"qty":3.94900000}],"asks":[],"checksum":566444478,"timestamp":"2024-06-01T17:52:51.016690Z"}]}
{"channel":"book","type":"update","data":[{"symbol":"ETH/USD","bids":[{"price":3795.54,"qty":0.00000000},{"price":3795.23,"qty":3.00000000}],"asks":[],"checksum":444623213,"timestamp":"2024-06-01T17:52:51.016760Z"}]}
{"channel":"book","type":"update","data":[{"symbol":"ETH/USD","bids":[{"price":3795.74,"qty":1.00000000}],"asks":[],"checksum":3720632943,"timestamp":"2024-06-01T17:52:51.021259Z"}]}
{"channel":"book","type":"update","data":[{"symbol":"ETH/USD","bids":[{"price":3795.70,"qty":26.34555594}],"asks":[],"checksum":4115606601,"timestamp":"2024-06-01T17:52:51.027015Z"}]}
{"channel":"book","type":"update","data":[{"symbol":"ETH/USD","bids":[],"asks":[{"price":3796.03,"qty":26.34331446}],"checksum":1397569541,"timestamp":"2024-06-01T17:52:51.027044Z"}]}
{"channel":"book","type":"update","data":[{"symbol":"ETH/USD","bids":[],"asks":[{"price":3796.05,"qty":0.00000000},{"price":3797.25,"qty":0.72912968}],"checksum":3967288018,"timestamp":"2024-06-01T17:52:51.086822Z"}]}
{"channel":"book","type":"update","data":[{"symbol":"ETH/USD","bids":[{"price":3795.74,"qty":0.00000000},{"price":3795.24,"qty":7.35211373}],"asks":[],"checksum":1665821752,"timestamp":"2024-06-01T17:52:51.091354Z"}]}
{"channel":"book","type":"update","data":[{"symbol":"ETH/USD","bids":[{"price":3795.71,"qty":1.00000000}],"asks":[],"checksum":1052872024,"timestamp":"2024-06-01T17:52:51.091532Z"}]}
{"channel":"book","type":"update","data":[{"symbol":"ETH/USD","bids":[],"asks":[{"price":3796.02,"qty":0.77968154}],"checksum":2352555949,"timestamp":"2024-06-01T17:52:51.248352Z"}]}
{"channel":"book","type":"update","data":[{"symbol":"ETH/USD","bids":[{"price":3795.29,"qty":0.00000000},{"price":3795.24,"qty":7.35211373}],"asks":[],"checksum":3678589043,"timestamp":"2024-06-01T17:52:51.380603Z"}]}
{"channel":"book","type":"update","data":[{"symbol":"ETH/USD","bids":[{"price":3795.31,"qty":0.00000000},{"price":3795.23,"qty":3.00000000}],"asks":[],"checksum":275524911,"timestamp":"2024-06-01T17:52:51.485811Z"}]}
{"channel":"book","type":"update","data":[{"symbol":"ETH/USD","bids":[{"price":3795.70,"qty":0.00000000},{"price":3795.20,"qty":0.52681071}],"asks":[],"checksum":455991962,"timestamp":"2024-06-01T17:52:51.485835Z"}]}
{"channel":"book","type":"update","data":[{"symbol":"ETH/USD","bids":[],"asks":[{"price":3796.03,"qty":0.00000000},{"price":3797.25,"qty":0.72912968}],"checksum":2792746242,"timestamp":"2024-06-01T17:52:51.485981Z"}]}
{"channel":"book","type":"update","data":[{"symbol":"ETH/USD","bids":[{"price":3795.27,"qty":5.27100000}],"asks":[],"checksum":3733610801,"timestamp":"2024-06-01T17:52:51.489449Z"}]}
{"channel":"book","type":"update","data":[{"symbol":"ETH/USD","bids":[{"price":3795.71,"qty":0.00000000},{"price":3795.20,"qty":0.52681071}],"asks":[],"checksum":1803383414,"timestamp":"2024-06-01T17:52:51.491030Z"}]}
{"channel":"book","type":"update","data":[{"symbol":"ETH/USD","bids":[{"price":3795.68,"qty":1.00936938}],"asks":[],"checksum":3075876333,"timestamp":"2024-06-01T17:52:51.491175Z"}]}
{"channel":"book","type":"update","data":[{"symbol":"ETH/USD","bids":[{"price":3795.72,"qty":26.34546278}],"asks":[],"checksum":1268496709,"timestamp":"2024-06-01T17:52:51.491196Z"}]}
{"channel":"book","type":"update","data":[{"symbol":"ETH/USD","bids":[],"asks":[{"price":3796.05,"qty":26.34319854}],"checksum":4158150748,"timestamp":"2024-06-01T17:52:51.491209Z"}]}
{"channel":"book","type":"update","data":[{"symbol":"ETH/USD","bids":[{"price":3795.44,"qty":26.34740347}],"asks":[],"checksum":313467896,"timestamp":"2024-06-01T17:52:51.491235Z"}]}
{"channel":"book","type":"update","data":[{"symbol":"ETH/USD","bids":[{"price":3795.68,"qty":1.00000000},{"price":3795.73,"qty":0.00936926}],"asks":[],"checksum":892624755,"timestamp":"2024-06-01T17:52:51.589406Z"}]}
{"channel":"book","type":"update","data":[{"symbol":"ETH/USD","bids":[],"asks":[{"price":3796.21,"qty":0.00000000},{"price":3797.25,"qty":0.72912968}],"checksum":1617476011,"timestamp":"2024-06-01T17:52:51.941954Z"}]}
{"channel":"book","type":"update","data":[{"symbol":"ETH/USD","bids":[{"price":3795.73,"qty":3.00936926}],"asks":[],"checksum":872372016,"timestamp":"2024-06-01T17:52:51.942975Z"}]}
{"channel":"book","type":"update","data":[{"symbol":"ETH/USD","bids":[{"price":3795.74,"qty":3.00000000}],"asks":[],"checksum":951604751,"timestamp":"2024-06-01T17:52:51.943382Z"}]}
{"channel":"book","type":"update","data":[{"symbol":"ETH/USD","bids":[],"asks":[{"price":3796.80,"qty":1.85000000}],"checksum":4101966403,"timestamp":"2024-06-01T17:52:51.945302Z"}]}
{"channel":"book","type":"update","data":[{"symbol":"ETH/USD","bids":[],"asks":[{"price":3796.71,"qty":0.00000000},{"price":3797.35,"qty":3.30000000}],"checksum":4037083479,"timestamp":"2024-06-01T17:52:51.946583Z"}]}
{"channel":"book","type":"update","data":[{"symbol":"ETH/USD","bids":[],"asks":[{"price":3796.80,"qty":0.00000000},{"price":3797.42,"qty":10.43462302}],"checksum":73401618,"timestamp":"2024-06-01T17:52:51.948058Z"}]}
{"channel":"book","type":"update","data":[{"symbol":"ETH/USD","bids":[{"price":3795.72,"qty":0.00000000},{"price":3795.27,"qty":5.27100000}],"asks":[],"checksum":1269450591,"timestamp":"2024-06-01T17:52:51.948487Z"}]}
{"channel":"book","type":"update","data":[{"symbol":"ETH/USD","bids":[],"asks":[{"price":3796.05,"qty":0.00000000},{"price":3797.46,"qty":1.00000000}],"checksum":1275421360,"timestamp":"2024-06-01T17:52:51.948537Z"}]}
{"channel":"book","type":"update","data":[{"symbol":"ETH/USD","bids":[],"asks":[{"price":3796.13,"qty":0.00000000},{"price":3797.47,"qty":3.00000000}],"checksum":1076957807,"timestamp":"2024-06-01T17:52:51.955922Z"}]}
{"channel":"book","type":"update","data":[{"symbol":"ETH/USD","bids":[{"price":3795.67,"qty":0.00000000},{"price":3795.24,"qty":7.35211373}],"asks":[],"checksum":1092230541,"timestamp":"2024-06-01T17:52:51.956071Z"}]}
{"channel":"book","type":"update","data":[{"symbol":"ETH/USD","bids":[{"price":3795.40,"qty":1.85000000}],"asks":[],"checksum":430394883,"timestamp":"2024-06-01T17:52:51.956718Z"}]}
{"channel":"book","type":"update","data":[{"symbol":"ETH/USD","bids":[{"price":3795.44,"qty":0.00000000},{"price":3795.24,"qty":7.35211373}],"asks":[],"checksum":2889771865,"timestamp":"2024-06-01T17:52:51.958168Z"}]}
{"channel":"book","type":"update","data":[{"symbol":"ETH/USD","bids":[{"price":3795.61,"qty":0.00000000},{"price":3795.23,"qty":3.00000000}],"asks":[],"checksum":451648706,"timestamp":"2024-06-01T17:52:51.961319Z"}]}
{"channel":"book","type":"update","data":[{"symbol":"ETH/USD","bids":[{"price":3795.46,"qty":0.00501309}],"asks":[],"checksum":2935004723,"timestamp":"2024-06-01T17:52:51.961443Z"}]}
{"channel":"book","type":"update","data":[{"symbol":"ETH/USD","bids":[{"price":3795.24,"qty":3.40311373},{"price":3795.28,"qty":3.94900000}],"asks":[],"checksum":3757226556,"timestamp":"2024-06-01T17:52:51.961486Z"}]}
{"channel":"book","type":"update","data":[{"symbol":"ETH/USD","bids":[],"asks":[{"price":3796.21,"qty":26.34212968}],"checksum":620584960,"timestamp":"2024-06-01T17:52:51.963129Z"}]}
{"channel":"book","type":"update","data":[{"symbol":"ETH/USD","bids":[{"price":3795.85,"qty":26.34453688}],"asks":[],"checksum":1453827519,"timestamp":"2024-06-01T17:52:51.963152Z"}]}
{"channel":"book","type":"update","data":[{"symbol":"ETH/USD","bids":[{"price":3795.59,"qty":26.34636001}],"asks":[],"checksum":4294773197,"timestamp":"2024-06-01T17:52:51.963276Z"}]}
{"channel":"book","type":"update","data":[{"symbol":"ETH/USD","bids":[{"price":3795.98,"qty":3.00000000}],"asks":[],"checksum":3211053734,"timestamp":"2024-06-01T17:52:51.967479Z"}]}
{"channel":"book","type":"update","data":[{"symbol":"ETH/USD","bids":[],"asks":[{"price":3796.21,"qty":0.00000000},{"price":3797.47,"qty":3.00000000}],"checksum":2861659036,"timestamp":"2024-06-01T17:52:51.969708Z"}]}
{"channel":"book","type":"update","data":[{"symbol":"ETH/USD","bids":[{"price":3795.85,"qty":0.00000000},{"price":3795.38,"qty":3.95072654}],"asks":[],"checksum":4211023752,"timestamp":"2024-06-01T17:52:51.969779Z"}]}
{"channel":"book","type":"update","data":[{"symbol":"ETH/USD","bids":[{"price":3795.74,"qty":0.00000000},{"price":3795.28,"qty":3.94900000}],"asks":[],"checksum":276265911,"timestamp":"2024-06-01T17:52:51.974005Z"}]}
{"channel":"book","type":"update","data":[{"symbol":"ETH/USD","bids":[],"asks":[{"price":3797.44,"qty":10.81226191}],"checksum":68917405,"timestamp":"2024-06-01T17:52:51.974257Z"}]}
{"channel":"book","type":"update","data":[{"symbol":"ETH/USD","bids":[],"asks":[{"price":3796.53,"qty":26.33985450}],"checksum":1740628681,"timestamp":"2024-06-01T17:52:51.976684Z"}]}
{"channel":"book","type":"update","data":[{"symbol":"ETH/USD","bids":[],"asks":[{"price":3796.53,"qty":0.00000000},{"price":3797.46,"qty":1.00000000}],"checksum":68917405,"timestamp":"2024-06-01T17:52:51.982051Z"}]}
{"channel":"book","type":"update","data":[{"symbol":"ETH/USD","bids":[{"price":3795.46,"qty":0.00000000},{"price":3795.27,"qty":5.27100000}],"asks":[],"checksum":1195308596,"timestamp":"2024-06-01T17:52:51.987419Z"}]}
{"channel":"book","type":"update","data":[{"symbol":"ETH/USD","bids":[],"asks":[{"price":3796.93,"qty":26.33707975}],"checksum":867674056,"timestamp":"2024-06-01T17:52:51.988784Z"}]}
{"channel":"book","type":"update","data":[{"symbol":"ETH/USD","bids":[],"asks":[{"price":3797.18,"qty":0.00000000},{"price":3797.46,"qty":1.00000000}],"checksum":3056869036,"timestamp":"2024-06-01T17:52:51.996256Z"}]}
{"channel":"book","type":"update","data":[{"symbol":"ETH/USD","bids":[{"price":3795.40,"qty":0.00000000},{"price":3795.24,"qty":3.40311373},{"price":3795.65,"qty":1.85000000}],"asks":[],"checksum":2367645335,"timestamp":"2024-06-01T17:52:52.017767Z"}]}
{"channel":"book","type":"update","data":[{"symbol":"ETH/USD","bids":[{"price":3795.65,"qty":3.70000000}],"asks":[],"checksum":499529086,"timestamp":"2024-06-01T17:52:52.019463Z"}]}
{"channel":"book","type":"update","data":[{"symbol":"ETH/USD","bids":[{"price":3795.60,"qty":3.95587791}],"asks":[],"checksum":3529005173,"timestamp":"2024-06-01T17:52:52.020528Z"}]}
{"channel":"book","type":"update","data":[{"symbol":"ETH/USD","bids":[],"asks":[{"price":3796.50,"qty":26.34009739}],"checksum":3405434967,"timestamp":"2024-06-01T17:52:52.047696Z"}]}
{"channel":"book","type":"update","data":[{"symbol":"ETH/USD","bids":[{"price":3796.01,"qty":26.34345009}],"asks":[],"checksum":1401904389,"timestamp":"2024-06-01T17:52:52.047903Z"}]}
{"channel":"book","type":"update","data":[{"symbol":"ETH/USD","bids":[{"price":3795.98,"qty":0.00000000},{"price":3795.27,"qty":5.27100000}],"asks":[],"checksum":3936371317,"timestamp":"2024-06-01T17:52:52.051078Z"}]}
{"channel":"book","type":"update","data":[{"symbol":"ETH/USD","bids":[],"asks":[{"price":3796.41,"qty":0.00000000},{"price":3797.46,"qty":1.00000000}],"checksum":3042606495,"timestamp":"2024-06-01T17:52:52.051628Z"}]}
{"channel":"book","type":"update","data":[{"symbol":"ETH/USD","bids":[],"asks":[{"price":3796.43,"qty":26.34056883}],"checksum":3397094608,"timestamp":"2024-06-01T17:52:52.056454Z"}]}
{"channel":"book","type":"update","data":[{"symbol":"ETH/USD","bids":[],"asks":[{"price":3796.02,"qty":0.00000000},{"price":3797.46,"qty":1.00000000}],"checksum":3075320133,"timestamp":"2024-06-01T17:52:52.074489Z"}]}
{"channel":"book","type":"update","data":[{"symbol":"ETH/USD","bids":[],"asks":[{"price":3796.43,"qty":0.00000000},{"price":3797.47,"qty":3.00000000}],"checksum":1716145594,"timestamp":"2024-06-01T17:52:52.074899Z"}]}
{"channel":"book","type":"update","data":[{"symbol":"ETH/USD","bids":[],"asks":[{"price":3796.92,"qty":0.77968154}],"checksum":3246341213,"timestamp":"2024-06-01T17:52:52.078416Z"}]}
{"channel":"book","type":"update","data":[{"symbol":"ETH/USD","bids":[{"price":3796.01,"qty":0.00000000},{"price":3795.24,"qty":3.40311373}],"asks":[],"checksum":1829938708,"timestamp":"2024-06-01T17:52:52.080727Z"}]}
{"channel":"book","type":"update","data":[{"symbol":"ETH/USD","bids":[{"price":3795.59,"qty":29.64636001}],"asks":[],"checksum":2456242565,"timestamp":"2024-06-01T17:52:52.083563Z"}]}
{"channel":"book","type":"update","data":[{"symbol":"ETH/USD","bids":[{"price":3795.74,"qty":3.95072654}],"asks":[],"checksum":1324177593,"timestamp":"2024-06-01T17:52:52.084432Z"}]}
{"channel":"book","type":"update","data":[{"symbol":"ETH/USD","bids":[],"asks":[{"price":3796.49,"qty":0.52680238}],"checksum":743557403,"timestamp":"2024-06-01T17:52:52.084841Z"}]}
{"channel":"book","type":"update","data":[{"symbol":"ETH/USD","bids":[{"price":3795.91,"qty":3.00000000}],"asks":[],"checksum":1307368949,"timestamp":"2024-06-01T17:52:52.084914Z"}]}
{"channel":"book","type":"update","data":[{"symbol":"ETH/USD","bids":[{"price":3795.59,"qty":26.34636001}],"asks":[],"checksum":443726659,"timestamp":"2024-06-01T17:52:52.084957Z"}]}
{"channel":"book","type":"update","data":[{"symbol":"ETH/USD","bids":[{"price":3795.60,"qty":7.25587791}],"asks":[],"checksum":511386318,"timestamp":"2024-06-01T17:52:52.085152Z"}]}
{"channel":"book","type":"update","data":[{"symbol":"ETH/USD","bids":[{"price":3795.74,"qty":30.29605050}],"asks":[],"checksum":1757875966,"timestamp":"2024-06-01T17:52:52.085590Z"}]}
{"channel":"book","type":"update","data":[{"symbol":"ETH/USD","bids":[{"price":3795.60,"qty":3.95587791}],"asks":[],"checksum":1825478515,"timestamp":"2024-06-01T17:52:52.087740Z"}]}
{"channel":"book","type":"update","data":[{"symbol":"ETH/USD","bids":[{"price":3795.61,"qty":3.30000000}],"asks":[],"checksum":3363188976,"timestamp":"2024-06-01T17:52:52.087983Z"}]}
{"channel":"book","type":"update","data":[{"symbol":"ETH/USD","bids":[{"price":3795.38,"qty":0.00000000},{"price":3795.28,"qty":3.94900000}],"asks":[],"checksum":3997101369,"timestamp":"2024-06-01T17:52:52.088131Z"}]}
{"channel":"book","type":"update","data":[{"symbol":"ETH/USD","bids":[{"price":3795.74,"qty":3.95072654}],"asks":[],"checksum":2558705929,"timestamp":"2024-06-01T17:52:52.091602Z"}]}
{"channel":"book","type":"update","data":[{"symbol":"ETH/USD","bids":[],"asks":[{"price":3797.21,"qty":1.85000000}],"checksum":2188641561,"timestamp":"2024-06-01T17:52:52.095538Z"}]}
{"channel":"book","type":"update","data":[{"symbol":"ETH/USD","bids":[{"price":3795.74,"qty":6.58072654}],"asks":[],"checksum":2296450947,"timestamp":"2024-06-01T17:52:52.110767Z"}]}
{"channel":"book","type":"update","data":[{"symbol":"ETH/USD","bids":[],"asks":[{"price":3796.45,"qty":26.34045898}],"checksum":304068863,"timestamp":"2024-06-01T17:52:52.126960Z"}]}
{"channel":"book","type":"update","data":[{"symbol":"ETH/USD","bids":[{"price":3796.11,"qty":26.34272261}],"asks":[],"checksum":1064358165,"timestamp":"2024-06-01T17:52:52.132027Z"}]}
{"channel":"book","type":"update","data":[{"symbol":"ETH/USD","bids":[],"asks":[{"price":3796.49,"qty":0.00000000},{"price":3797.42,"qty":10.43462302}],"checksum":1205726288,"timestamp":"2024-06-01T17:52:52.135863Z"}]}
{"channel":"book","type":"update","data":[{"symbol":"ETH/USD","bids":[{"price":3795.74,"qty":3.95072654}],"asks":[],"checksum":102789410,"timestamp":"2024-06-01T17:52:52.137988Z"}]}
{"channel":"book","type":"update","data":[{"symbol":"ETH/USD","bids":[],"asks":[{"price":3796.45,"qty":0.00000000},{"price":3797.44,"qty":10.81226191}],"checksum":2904066696,"timestamp":"2024-06-01T17:52:52.161079Z"}]}
{"channel":"book","type":"update","data":[{"symbol":"ETH/USD","bids":[],"asks":[{"price":3796.46,"qty":26.34036678}],"checksum":130136319,"timestamp":"2024-06-01T17:52:52.236842Z"}]}
{"channel":"book","type":"update","data":[{"symbol":"ETH/USD","bids":[{"price":3796.13,"qty":26.34258562}],"asks":[],"checksum":1107268091,"timestamp":"2024-06-01T17:52:52.236894Z"}]}
{"channel":"book","type":"update","data":[{"symbol":"ETH/USD","bids":[{"price":3796.12,"qty":0.75061161}],"asks":[],"checksum":4202185012,"timestamp":"2024-06-01T17:52:52.240046Z"}]}
{"channel":"book","type":"update","data":[{"symbol":"ETH/USD","bids":[{"price":3795.91,"qty":0.00000000},{"price":3795.59,"qty":26.34636001}],"asks":[],"checksum":4168397724,"timestamp":"2024-06-01T17:52:52.240064Z"}]}
{"channel":"book","type":"update","data":[{"symbol":"ETH/USD","bids":[{"price":3795.73,"qty":3.00000000},{"price":3796.14,"qty":0.00936763}],"asks":[],"checksum":3882459789,"timestamp":"2024-06-01T17:52:52.284132Z"}]}
{"channel":"book","type":"update","data":[{"symbol":"ETH/USD","bids":[{"price":3796.13,"qty":0.00000000},{"price":3795.59,"qty":26.34636001}],"asks":[],"checksum":4151023649,"timestamp":"2024-06-01T17:52:52.450821Z"}]}
{"channel":"book","type":"update","data":[{"symbol":"ETH/USD","bids":[],"asks":[{"price":3796.46,"qty":0.00000000},{"price":3797.44,"qty":10.81226191}],"checksum":3055433364,"timestamp":"2024-06-01T17:52:52.450841Z"}]}
{"channel":"book","type":"update","data":[{"symbol":"ETH/USD","bids":[],"asks":[{"price":3797.42,"qty":0.00000000},{"price":3797.46,"qty":1.00000000}],"checksum":709748912,"timestamp":"2024-06-01T17:52:52.454321Z"}]}
{"channel":"book","type":"update","data":[{"symbol":"ETH/USD","bids":[],"asks":[{"price":3796.49,"qty":26.34018067}],"checksum":4039316518,"timestamp":"2024-06-01T17:52:52.456084Z"}]}
{"channel":"book","type":"update","data":[{"symbol":"ETH/USD","bids":[{"price":3796.15,"qty":26.34247856}],"asks":[],"checksum":1667361410,"timestamp":"2024-06-01T17:52:52.456242Z"}]}
{"channel":"book","type":"update","data":[{"symbol":"ETH/USD","bids":[{"price":3795.92,"qty":26.34407469}],"asks":[],"checksum":2203024603,"timestamp":"2024-06-01T17:52:52.456259Z"}]}
{"channel":"book","type":"update","data":[{"symbol":"ETH/USD","bids":[{"price":3796.14,"qty":0.00000000},{"price":3795.60,"qty":3.95587791},{"price":3796.13,"qty":0.00936765}],"asks":[],"checksum":3518704324,"timestamp":"2024-06-01T17:52:52.494974Z"}]}
{"channel":"book","type":"update","data":[{"symbol":"ETH/USD","bids":[],"asks":[{"price":3796.49,"qty":0.00000000},{"price":3797.46,"qty":1.00000000}],"checksum":3356332617,"timestamp":"2024-06-01T17:52:52.618722Z"}]}
{"channel":"book","type":"update","data":[{"symbol":"ETH/USD","bids":[],"asks":[{"price":3796.48,"qty":26.34022392}],"checksum":3084536271,"timestamp":"2024-06-01T17:52:52.625028Z"}]}
{"channel":"book","type":"update","data":[{"symbol":"ETH/USD","bids":[{"price":3796.12,"qty":0.00000000},{"price":3795.60,"qty":3.95587791}],"asks":[],"checksum":1910179761,"timestamp":"2024-06-01T17:52:52.885469Z"}]}
{"channel":"book","type":"update","data":[{"symbol":"ETH/USD","bids":[{"price":3795.75,"qty":0.75061161}],"asks":[],"checksum":2622927048,"timestamp":"2024-06-01T17:52:52.889374Z"}]}
{"channel":"book","type":"update","data":[{"symbol":"ETH/USD","bids":[{"price":3796.13,"qty":0.00000000},{"price":3795.60,"qty":3.95587791},{"price":3796.16,"qty":0.00936758}],"asks":[],"checksum":765635940,"timestamp":"2024-06-01T17:52:52.933883Z"}]}
{"channel":"book","type":"update","data":[{"symbol":"ETH/USD","bids":[],"asks":[{"price":3796.48,"qty":0.00000000},{"price":3797.46,"qty":1.00000000}],"checksum":1383429858,"timestamp":"2024-06-01T17:52:52.948212Z"}]}
{"channel":"book","type":"update","data":[{"symbol":"ETH/USD","bids":[{"price":3796.15,"qty":0.00000000},{"price":3795.60,"qty":3.95587791}],"asks":[],"checksum":2178105365,"timestamp":"2024-06-01T17:52:52.948292Z"}]}
{"channel":"book","type":"update","data":[{"symbol":"ETH/USD","bids":[],"asks":[{"price":3796.49,"qty":26.34011942}],"checksum":2578480901,"timestamp":"2024-06-01T17:52:52.953320Z"}]}
{"channel":"book","type":"update","data":[{"symbol":"ETH/USD","bids":[{"price":3796.14,"qty":26.34251186}],"asks":[],"checksum":146494202,"timestamp":"2024-06-01T17:52:52.953443Z"}]}
{"channel":"book","type":"update","data":[{"symbol":"ETH/USD","bids":[{"price":3796.14,"qty":0.00000000},{"price":3795.60,"qty":3.95587791}],"asks":[],"checksum":2578480901,"timestamp":"2024-06-01T17:52:52.972635Z"}]}
{"channel":"book","type":"update","data":[{"symbol":"ETH/USD","bids":[{"price":3796.16,"qty":0.00000000},{"price":3795.59,"qty":26.34636001},{"price":3796.15,"qty":0.00936760}],"asks":[],"checksum":1459755722,"timestamp":"2024-06-01T17:52:53.007584Z"}]}
{"channel":"book","type":"update","data":[{"symbol":"ETH/USD","bids":[{"price":3796.15,"qty":0.00000000},{"price":3795.59,"qty":26.34636001},{"price":3796.12,"qty":0.00936767}],"asks":[],"checksum":581560495,"timestamp":"2024-06-01T17:52:53.061754Z"}]}
{"channel":"book","type":"update","data":[{"symbol":"ETH/USD","bids":[{"price":3796.13,"qty":26.34261734}],"asks":[],"checksum":51629545,"timestamp":"2024-06-01T17:52:53.361805Z"}]}
{"channel":"book","type":"update","data":[{"symbol":"ETH/USD","bids":[{"price":3796.13,"qty":0.00000000},{"price":3795.60,"qty":3.95587791}],"asks":[],"checksum":581560495,"timestamp":"2024-06-01T17:52:53.366785Z"}]}
{"channel":"book","type":"update","data":[{"symbol":"ETH/USD","bids":[{"price":3796.21,"qty":26.34205439}],"asks":[],"checksum":2086950136,"timestamp":"2024-06-01T17:52:53.488348Z"}]}
{"channel":"book","type":"update","data":[{"symbol":"ETH/USD","bids":[{"price":3796.21,"qty":29.34205439}],"asks":[],"checksum":3504325159,"timestamp":"2024-06-01T17:52:53.582364Z"}]}
{"channel":"book","type":"update","data":[{"symbol":"ETH/USD","bids":[],"asks":[{"price":3797.09,"qty":0.00000000},{"price":3797.46,"qty":1.00000000}],"checksum":526276888,"timestamp":"2024-06-01T17:52:53.582416Z"}]}
{"channel":"book","type":"update","data":[{"symbol":"ETH/USD","bids":[{"price":3796.21,"qty":32.34205439}],"asks":[],"checksum":1492584170,"timestamp":"2024-06-01T17:52:53.582441Z"}]}
{"channel":"book","type":"update","data":[{"symbol":"ETH/USD","bids":[{"price":3796.26,"qty":3.00000000}],"asks":[],"checksum":1977885696,"timestamp":"2024-06-01T17:52:53.582925Z"}]}
{"channel":"book","type":"update","data":[{"symbol":"ETH/USD","bids":[{"price":3795.93,"qty":3.95106995}],"asks":[],"checksum":2245396931,"timestamp":"2024-06-01T17:52:53.584756Z"}]}
{"channel":"book","type":"update","data":[{"symbol":"ETH/USD","bids":[],"asks":[{"price":3796.92,"qty":0.00000000},{"price":3797.47,"qty":3.00000000}],"checksum":1876874929,"timestamp":"2024-06-01T17:52:53.585623Z"}]}
{"channel":"book","type":"update","data":[{"symbol":"ETH/USD","bids":[],"asks":[{"price":3797.21,"qty":0.00000000},{"price":3797.69,"qty":22.89428196}],"checksum":3881153510,"timestamp":"2024-06-01T17:52:53.588029Z"}]}
{"channel":"book","type":"update","data":[{"symbol":"ETH/USD","bids":[{"price":3795.74,"qty":0.00000000},{"price":3795.65,"qty":3.70000000}],"asks":[],"checksum":2021847567,"timestamp":"2024-06-01T17:52:53.589182Z"}]}
{"channel":"book","type":"update","data":[{"symbol":"ETH/USD","bids":[],"asks":[{"price":3796.50,"qty":0.00000000},{"price":3797.71,"qty":10.43462302}],"checksum":3743997134,"timestamp":"2024-06-01T17:52:53.591852Z"}]}
{"channel":"book","type":"update","data":[{"symbol":"ETH/USD","bids":[{"price":3796.11,"qty":0.00000000},{"price":3795.61,"qty":3.30000000}],"asks":[],"checksum":3477215457,"timestamp":"2024-06-01T17:52:53.591971Z"}]}
